{"event_at":"2026-07-27T05:32:04.952000Z","event_fingerprint":"7fdabd23eb8408505f3cf2b3dd5f47569e9951573c97f31fbf58e8fb0f51a433","payload":{"connection_id":"efc69d3132f1467b8e898a382b23ac0d","event_at":"2026-07-27T05:32:04.952000Z","event_type":"price_change","frame_hash":"66dc1b24db45f07f8d9b090b3c6bc690cf614a414492491540a7ed631c992d65","frame_index":0,"kind":"data","monotonic_ns":232308193020958,"payload":{"event_type":"price_change","market":"0x3b40066b5cf3871a2f6237c5628bd8092a206aa998558ac5ec13c4483e31e160","price_changes":[{"asset_id":"14766054693214075530629349735273995982307625376442606753688071083149620216746","best_ask":"0.46","best_bid":"0.45","hash":"7717759cc01d0b1410c6a88563da90cf670b35d1","price":"0.41","side":"BUY","size":"94.34"},{"asset_id":"110216635572655435074987471276357323571387854733835379371586402147734167783946","best_ask":"0.55","best_bid":"0.54","hash":"088f23a48098466e79b980930bada08ffd7e21bf","price":"0.59","side":"SELL","size":"94.34"}],"timestamp":"1785130324952"},"payload_hash":"186e502e0afd3dbc668ced456e2dd94bcc698307cf48185235be409a25945af8","raw_frame":"{\"market\":\"0x3b40066b5cf3871a2f6237c5628bd8092a206aa998558ac5ec13c4483e31e160\", \"price_changes\":[{\"asset_id\":\"14766054693214075530629349735273995982307625376442606753688071083149620216746\", \"price\":\"0.41\", \"size\":\"94.34\", \"side\":\"BUY\", \"hash\":\"7717759cc01d0b1410c6a88563da90cf670b35d1\", \"best_bid\":\"0.45\", \"best_ask\":\"0.46\"}, {\"asset_id\":\"110216635572655435074987471276357323571387854733835379371586402147734167783946\", \"price\":\"0.59\", \"size\":\"94.34\", \"side\":\"SELL\", \"hash\":\"088f23a48098466e79b980930bada08ffd7e21bf\", \"best_bid\":\"0.54\", \"best_ask\":\"0.55\"}], \"timestamp\":\"1785130324952\", \"event_type\":\"price_change\"}","received_at":"2026-07-27T05:32:04.955680Z","schema_version":"clob-market-ws.price_change.v1","sequence":null,"server_hash":null,"server_timestamp":"1785130324952","session_id":"502006c5cfcd437296561ea750c9ec8b","source":"clob_market_ws"},"received_at":"2026-07-27T05:32:04.955680Z","record_id":"6e934fad8b9d931908f899a591c142475ae0614d9e0952f027c254aa5aa14ea5","schema_fingerprint":"4aa3821a28b0b7c2400bc59aba4bcc0a76e971dadd19610d3ad38c768e124dc7","schema_version":"edge-lab-recorder.raw.v1","sequence":null,"source":"clob_market_ws"}
{"event_at":"2026-07-27T05:32:04.952000Z","event_fingerprint":"7e102deded51c5886d76b232e6526adf5412f87a061fb75ace60257b928e80b9","payload":{"connection_id":"efc69d3132f1467b8e898a382b23ac0d","event_at":"2026-07-27T05:32:04.952000Z","event_type":"price_change","frame_hash":"e872d9bb98e5749f60bba2f5b9690375e97c2ae4fd727357136bf61f5952020a","frame_index":0,"kind":"data","monotonic_ns":232308204998250,"payload":{"event_type":"price_change","market":"0x3b40066b5cf3871a2f6237c5628bd8092a206aa998558ac5ec13c4483e31e160","price_changes":[{"asset_id":"14766054693214075530629349735273995982307625376442606753688071083149620216746","best_ask":"0.46","best_bid":"0.45","hash":"7717759cc01d0b1410c6a88563da90cf670b35d1","price":"0.43","side":"BUY","size":"17.24"},{"asset_id":"110216635572655435074987471276357323571387854733835379371586402147734167783946","best_ask":"0.55","best_bid":"0.54","hash":"088f23a48098466e79b980930bada08ffd7e21bf","price":"0.57","side":"SELL","size":"17.24"}],"timestamp":"1785130324952"},"payload_hash":"1ee988912d2f8e4162f9a7e0c1bdabedd09b41bc9d8953313b09ec93be4bb9bb","raw_frame":"{\"market\":\"0x3b40066b5cf3871a2f6237c5628bd8092a206aa998558ac5ec13c4483e31e160\", \"price_changes\":[{\"asset_id\":\"14766054693214075530629349735273995982307625376442606753688071083149620216746\", \"price\":\"0.43\", \"size\":\"17.24\", \"side\":\"BUY\", \"hash\":\"7717759cc01d0b1410c6a88563da90cf670b35d1\", \"best_bid\":\"0.45\", \"best_ask\":\"0.46\"}, {\"asset_id\":\"110216635572655435074987471276357323571387854733835379371586402147734167783946\", \"price\":\"0.57\", \"size\":\"17.24\", \"side\":\"SELL\", \"hash\":\"088f23a48098466e79b980930bada08ffd7e21bf\", \"best_bid\":\"0.54\", \"best_ask\":\"0.55\"}], \"timestamp\":\"1785130324952\", \"event_type\":\"price_change\"}","received_at":"2026-07-27T05:32:04.967657Z","schema_version":"clob-market-ws.price_change.v1","sequence":null,"server_hash":null,"server_timestamp":"1785130324952","session_id":"502006c5cfcd437296561ea750c9ec8b","source":"clob_market_ws"},"received_at":"2026-07-27T05:32:04.967657Z","record_id":"726bb7e8221721a1cbd0ef05607e7a48eff5f6d57b6964b020023fbb49db48d0","schema_fingerprint":"4aa3821a28b0b7c2400bc59aba4bcc0a76e971dadd19610d3ad38c768e124dc7","schema_version":"edge-lab-recorder.raw.v1","sequence":null,"source":"clob_market_ws"}
{"event_at":"2026-07-27T05:32:04.952000Z","event_fingerprint":"06179c8290063fc6d167a0342e99766b830618ca9d25c3bfa8524e02b2e9ebe2","payload":{"connection_id":"efc69d3132f1467b8e898a382b23ac0d","event_at":"2026-07-27T05:32:04.952000Z","event_type":"price_change","frame_hash":"74d48c3078cb97cb6266e63b2f16ad9b67162059caf574992218e92e27fec91d","frame_index":0,"kind":"data","monotonic_ns":232308212035291,"payload":{"event_type":"price_change","market":"0x3b40066b5cf3871a2f6237c5628bd8092a206aa998558ac5ec13c4483e31e160","price_changes":[{"asset_id":"110216635572655435074987471276357323571387854733835379371586402147734167783946","best_ask":"0.55","best_bid":"0.54","hash":"088f23a48098466e79b980930bada08ffd7e21bf","price":"0.47","side":"BUY","size":"45.03"},{"asset_id":"14766054693214075530629349735273995982307625376442606753688071083149620216746","best_ask":"0.46","best_bid":"0.45","hash":"7717759cc01d0b1410c6a88563da90cf670b35d1","price":"0.53","side":"SELL","size":"45.03"}],"timestamp":"1785130324952"},"payload_hash":"6811bd0a6ac7a00cd62f57993370c8eb27ca901190bbfec110b3a86b77a14254","raw_frame":"{\"market\":\"0x3b40066b5cf3871a2f6237c5628bd8092a206aa998558ac5ec13c4483e31e160\", \"price_changes\":[{\"asset_id\":\"110216635572655435074987471276357323571387854733835379371586402147734167783946\", \"price\":\"0.47\", \"size\":\"45.03\", \"side\":\"BUY\", \"hash\":\"088f23a48098466e79b980930bada08ffd7e21bf\", \"best_bid\":\"0.54\", \"best_ask\":\"0.55\"}, {\"asset_id\":\"14766054693214075530629349735273995982307625376442606753688071083149620216746\", \"price\":\"0.53\", \"size\":\"45.03\", \"side\":\"SELL\", \"hash\":\"7717759cc01d0b1410c6a88563da90cf670b35d1\", \"best_bid\":\"0.45\", \"best_ask\":\"0.46\"}], \"timestamp\":\"1785130324952\", \"event_type\":\"price_change\"}","received_at":"2026-07-27T05:32:04.974693Z","schema_version":"clob-market-ws.price_change.v1","sequence":null,"server_hash":null,"server_timestamp":"1785130324952","session_id":"502006c5cfcd437296561ea750c9ec8b","source":"clob_market_ws"},"received_at":"2026-07-27T05:32:04.974693Z","record_id":"1a3b86df9b1463d3a5badad225902afcd41068e3b304bcd671685f65c2a64cae","schema_fingerprint":"4aa3821a28b0b7c2400bc59aba4bcc0a76e971dadd19610d3ad38c768e124dc7","schema_version":"edge-lab-recorder.raw.v1","sequence":null,"source":"clob_market_ws"}
{"event_at":"2026-07-27T05:32:04.955000Z","event_fingerprint":"e9011dd5935a6d3269875d93945e495a155916e9dfdbaaa63e4fdcff3ab6e35a","payload":{"connection_id":"efc69d3132f1467b8e898a382b23ac0d","event_at":"2026-07-27T05:32:04.955000Z","event_type":"price_change","frame_hash":"5241763bd4c5d679adc714ad893b90ae43fd90a76e9ceca6c2c9f05a873621ce","frame_index":0,"kind":"data","monotonic_ns":232308216483833,"payload":{"event_type":"price_change","market":"0x3b40066b5cf3871a2f6237c5628bd8092a206aa998558ac5ec13c4483e31e160","price_changes":[{"asset_id":"14766054693214075530629349735273995982307625376442606753688071083149620216746","best_ask":"0.46","best_bid":"0.45","hash":"48565288b1b73ea78d5f117cc5ea0b768a55d8bd","price":"0.45","side":"BUY","size":"41.4"},{"asset_id":"110216635572655435074987471276357323571387854733835379371586402147734167783946","best_ask":"0.55","best_bid":"0.54","hash":"478edfab35058521c5dccfe21366e9cae7a0d69c","price":"0.55","side":"SELL","size":"41.4"}],"timestamp":"1785130324955"},"payload_hash":"668afd91a492ada73ce9c4369432a6864fe17d08752e2b07b644f5359c18d709","raw_frame":"{\"market\":\"0x3b40066b5cf3871a2f6237c5628bd8092a206aa998558ac5ec13c4483e31e160\", \"price_changes\":[{\"asset_id\":\"14766054693214075530629349735273995982307625376442606753688071083149620216746\", \"price\":\"0.45\", \"size\":\"41.4\", \"side\":\"BUY\", \"hash\":\"48565288b1b73ea78d5f117cc5ea0b768a55d8bd\", \"best_bid\":\"0.45\", \"best_ask\":\"0.46\"}, {\"asset_id\":\"110216635572655435074987471276357323571387854733835379371586402147734167783946\", \"price\":\"0.55\", \"size\":\"41.4\", \"side\":\"SELL\", \"hash\":\"478edfab35058521c5dccfe21366e9cae7a0d69c\", \"best_bid\":\"0.54\", \"best_ask\":\"0.55\"}], \"timestamp\":\"1785130324955\", \"event_type\":\"price_change\"}","received_at":"2026-07-27T05:32:04.979142Z","schema_version":"clob-market-ws.price_change.v1","sequence":null,"server_hash":null,"server_timestamp":"1785130324955","session_id":"502006c5cfcd437296561ea750c9ec8b","source":"clob_market_ws"},"received_at":"2026-07-27T05:32:04.979142Z","record_id":"3809cd7756e062638d0a1e74ce78f0cb56915606d5c32b292afe9b857cc010df","schema_fingerprint":"4aa3821a28b0b7c2400bc59aba4bcc0a76e971dadd19610d3ad38c768e124dc7","schema_version":"edge-lab-recorder.raw.v1","sequence":null,"source":"clob_market_ws"}
{"event_at":"2026-07-27T05:32:04.956000Z","event_fingerprint":"6e2ad3a4df7eca394fbdce1083473363a2f62cf50f795a3731a7db4a1ba9d629","payload":{"connection_id":"efc69d3132f1467b8e898a382b23ac0d","event_at":"2026-07-27T05:32:04.956000Z","event_type":"price_change","frame_hash":"b2442dd94023d3afd6d1e5d412f37150bd0cfd8754b0e591b974b2b823b9b2b5","frame_index":0,"kind":"data","monotonic_ns":232308218781583,"payload":{"event_type":"price_change","market":"0x3b40066b5cf3871a2f6237c5628bd8092a206aa998558ac5ec13c4483e31e160","price_changes":[{"asset_id":"110216635572655435074987471276357323571387854733835379371586402147734167783946","best_ask":"0.55","best_bid":"0.54","hash":"1918ecf0f473462777fdfe10533b4831dc77c860","price":"0.48","side":"BUY","size":"153.01"},{"asset_id":"14766054693214075530629349735273995982307625376442606753688071083149620216746","best_ask":"0.46","best_bid":"0.45","hash":"5c535d914c950bb88952713d1932166f60e9acf9","price":"0.52","side":"SELL","size":"153.01"}],"timestamp":"1785130324956"},"payload_hash":"183f6313e4cec77392d2dc821ea2fa42debb7809706ffaf9d6a1fbc9d2b019cc","raw_frame":"{\"market\":\"0x3b40066b5cf3871a2f6237c5628bd8092a206aa998558ac5ec13c4483e31e160\", \"price_changes\":[{\"asset_id\":\"110216635572655435074987471276357323571387854733835379371586402147734167783946\", \"price\":\"0.48\", \"size\":\"153.01\", \"side\":\"BUY\", \"hash\":\"1918ecf0f473462777fdfe10533b4831dc77c860\", \"best_bid\":\"0.54\", \"best_ask\":\"0.55\"}, {\"asset_id\":\"14766054693214075530629349735273995982307625376442606753688071083149620216746\", \"price\":\"0.52\", \"size\":\"153.01\", \"side\":\"SELL\", \"hash\":\"5c535d914c950bb88952713d1932166f60e9acf9\", \"best_bid\":\"0.45\", \"best_ask\":\"0.46\"}], \"timestamp\":\"1785130324956\", \"event_type\":\"price_change\"}","received_at":"2026-07-27T05:32:04.981446Z","schema_version":"clob-market-ws.price_change.v1","sequence":null,"server_hash":null,"server_timestamp":"1785130324956","session_id":"502006c5cfcd437296561ea750c9ec8b","source":"clob_market_ws"},"received_at":"2026-07-27T05:32:04.981446Z","record_id":"1ee7fb7e5cd88cefb5e312ab7b8dd00b804de2b0936020568b9caf11033de9c7","schema_fingerprint":"4aa3821a28b0b7c2400bc59aba4bcc0a76e971dadd19610d3ad38c768e124dc7","schema_version":"edge-lab-recorder.raw.v1","sequence":null,"source":"clob_market_ws"}
{"event_at":"2026-07-27T05:32:04.957000Z","event_fingerprint":"33ea5bdb528ac2ab281ad8e279f50f4e44e7c3915d07eb797f38b608ffbeba33","payload":{"connection_id":"efc69d3132f1467b8e898a382b23ac0d","event_at":"2026-07-27T05:32:04.957000Z","event_type":"price_change","frame_hash":"91555c37044cd69c12f9f79312ac51c2f443d0088476a7bc3c4052a8adc86d7b","frame_index":0,"kind":"data","monotonic_ns":232308222792208,"payload":{"event_type":"price_change","market":"0x3b40066b5cf3871a2f6237c5628bd8092a206aa998558ac5ec13c4483e31e160","price_changes":[{"asset_id":"14766054693214075530629349735273995982307625376442606753688071083149620216746","best_ask":"0.46","best_bid":"0.45","hash":"afbcc8de8430efbdf10025f99a55f9d8667d4bd7","price":"0.44","side":"BUY","size":"15"},{"asset_id":"110216635572655435074987471276357323571387854733835379371586402147734167783946","best_ask":"0.55","best_bid":"0.54","hash":"ff14bc98726c28ebe1b2668b524b8cb89962ab65","price":"0.56","side":"SELL","size":"15"}],"timestamp":"1785130324957"},"payload_hash":"27e5a6b7b8d3dcbc8200bfb828cfb68a050987643f89fa93dfe88a4766cb652d","raw_frame":"{\"market\":\"0x3b40066b5cf3871a2f6237c5628bd8092a206aa998558ac5ec13c4483e31e160\", \"price_changes\":[{\"asset_id\":\"14766054693214075530629349735273995982307625376442606753688071083149620216746\", \"price\":\"0.44\", \"size\":\"15\", \"side\":\"BUY\", \"hash\":\"afbcc8de8430efbdf10025f99a55f9d8667d4bd7\", \"best_bid\":\"0.45\", \"best_ask\":\"0.46\"}, {\"asset_id\":\"110216635572655435074987471276357323571387854733835379371586402147734167783946\", \"price\":\"0.56\", \"size\":\"15\", \"side\":\"SELL\", \"hash\":\"ff14bc98726c28ebe1b2668b524b8cb89962ab65\", \"best_bid\":\"0.54\", \"best_ask\":\"0.55\"}], \"timestamp\":\"1785130324957\", \"event_type\":\"price_change\"}","received_at":"2026-07-27T05:32:04.985450Z","schema_version":"clob-market-ws.price_change.v1","sequence":null,"server_hash":null,"server_timestamp":"1785130324957","session_id":"502006c5cfcd437296561ea750c9ec8b","source":"clob_market_ws"},"received_at":"2026-07-27T05:32:04.985450Z","record_id":"642b2a144dcbda6dfd51013949d7bba85722fcb2b12e6232fb8b93c49f760aef","schema_fingerprint":"4aa3821a28b0b7c2400bc59aba4bcc0a76e971dadd19610d3ad38c768e124dc7","schema_version":"edge-lab-recorder.raw.v1","sequence":null,"source":"clob_market_ws"}
{"event_at":"2026-07-27T05:32:04.958000Z","event_fingerprint":"6f6d27665e4a9a84282edb74f70df093ff17ed270e3a9b0ed94d180beb663e34","payload":{"connection_id":"efc69d3132f1467b8e898a382b23ac0d","event_at":"2026-07-27T05:32:04.958000Z","event_type":"price_change","frame_hash":"83732e27c038b057443eeb5c0fb29c6487871244d8a0a8230d384592ebf78f82","frame_index":0,"kind":"data","monotonic_ns":232308227281375,"payload":{"event_type":"price_change","market":"0x3b40066b5cf3871a2f6237c5628bd8092a206aa998558ac5ec13c4483e31e160","price_changes":[{"asset_id":"14766054693214075530629349735273995982307625376442606753688071083149620216746","best_ask":"0.46","best_bid":"0.45","hash":"25e8eab3f586061c8043423d9a921cc231963d1a","price":"0.4","side":"BUY","size":"222.45"},{"asset_id":"110216635572655435074987471276357323571387854733835379371586402147734167783946","best_ask":"0.55","best_bid":"0.54","hash":"e7bc15b6e9d8b86bf39ddc079daf38e6100f1956","price":"0.6","side":"SELL","size":"222.45"}],"timestamp":"1785130324958"},"payload_hash":"2788dcfd7f13ae49e8dc1e8a601dc7251212deb1236e9fa38e3afb332ee095eb","raw_frame":"{\"market\":\"0x3b40066b5cf3871a2f6237c5628bd8092a206aa998558ac5ec13c4483e31e160\", \"price_changes\":[{\"asset_id\":\"14766054693214075530629349735273995982307625376442606753688071083149620216746\", \"price\":\"0.4\", \"size\":\"222.45\", \"side\":\"BUY\", \"hash\":\"25e8eab3f586061c8043423d9a921cc231963d1a\", \"best_bid\":\"0.45\", \"best_ask\":\"0.46\"}, {\"asset_id\":\"110216635572655435074987471276357323571387854733835379371586402147734167783946\", \"price\":\"0.6\", \"size\":\"222.45\", \"side\":\"SELL\", \"hash\":\"e7bc15b6e9d8b86bf39ddc079daf38e6100f1956\", \"best_bid\":\"0.54\", \"best_ask\":\"0.55\"}], \"timestamp\":\"1785130324958\", \"event_type\":\"price_change\"}","received_at":"2026-07-27T05:32:04.989939Z","schema_version":"clob-market-ws.price_change.v1","sequence":null,"server_hash":null,"server_timestamp":"1785130324958","session_id":"502006c5cfcd437296561ea750c9ec8b","source":"clob_market_ws"},"received_at":"2026-07-27T05:32:04.989939Z","record_id":"2263e64acd8f399fb9ad0cbc33314e0d7d03226d6e85e47ff51bc0b2f1a38919","schema_fingerprint":"4aa3821a28b0b7c2400bc59aba4bcc0a76e971dadd19610d3ad38c768e124dc7","schema_version":"edge-lab-recorder.raw.v1","sequence":null,"source":"clob_market_ws"}
{"event_at":"2026-07-27T05:32:04.959000Z","event_fingerprint":"60d115600b75f9be3306227c3dd021f32a1b8bbf2ae68aa42beaa71566fcad60","payload":{"connection_id":"efc69d3132f1467b8e898a382b23ac0d","event_at":"2026-07-27T05:32:04.959000Z","event_type":"price_change","frame_hash":"cda709bb0f84de407e27d1fcc7b04e436cebb59caad2d288565ce5ae2c881cfe","frame_index":0,"kind":"data","monotonic_ns":232308232957875,"payload":{"event_type":"price_change","market":"0x3b40066b5cf3871a2f6237c5628bd8092a206aa998558ac5ec13c4483e31e160","price_changes":[{"asset_id":"14766054693214075530629349735273995982307625376442606753688071083149620216746","best_ask":"0.46","best_bid":"0.45","hash":"010d15d37e0071eb3e28ce3a4ccca59ee96d22ff","price":"0.42","side":"BUY","size":"29.29"},{"asset_id":"110216635572655435074987471276357323571387854733835379371586402147734167783946","best_ask":"0.55","best_bid":"0.54","hash":"a233ea790b965d3d782e9e1ea54c59cbcf014b28","price":"0.58","side":"SELL","size":"29.29"}],"timestamp":"1785130324959"},"payload_hash":"4706088a0718a7a2bd2409148d7a000dead3541139dd8bd5f7b5aa536ba6693a","raw_frame":"{\"market\":\"0x3b40066b5cf3871a2f6237c5628bd8092a206aa998558ac5ec13c4483e31e160\", \"price_changes\":[{\"asset_id\":\"14766054693214075530629349735273995982307625376442606753688071083149620216746\", \"price\":\"0.42\", \"size\":\"29.29\", \"side\":\"BUY\", \"hash\":\"010d15d37e0071eb3e28ce3a4ccca59ee96d22ff\", \"best_bid\":\"0.45\", \"best_ask\":\"0.46\"}, {\"asset_id\":\"110216635572655435074987471276357323571387854733835379371586402147734167783946\", \"price\":\"0.58\", \"size\":\"29.29\", \"side\":\"SELL\", \"hash\":\"a233ea790b965d3d782e9e1ea54c59cbcf014b28\", \"best_bid\":\"0.54\", \"best_ask\":\"0.55\"}], \"timestamp\":\"1785130324959\", \"event_type\":\"price_change\"}","received_at":"2026-07-27T05:32:04.995616Z","schema_version":"clob-market-ws.price_change.v1","sequence":null,"server_hash":null,"server_timestamp":"1785130324959","session_id":"502006c5cfcd437296561ea750c9ec8b","source":"clob_market_ws"},"received_at":"2026-07-27T05:32:04.995616Z","record_id":"85a097c16ea0a6eb8e4796ef2eb803b94b34a0a8643388d83163ee4ec2b6281d","schema_fingerprint":"4aa3821a28b0b7c2400bc59aba4bcc0a76e971dadd19610d3ad38c768e124dc7","schema_version":"edge-lab-recorder.raw.v1","sequence":null,"source":"clob_market_ws"}
{"event_at":"2026-07-27T05:32:04.959000Z","event_fingerprint":"47b3a29476d8ce499446d3a21e3967de873c8813f17c0679715df12f65a46204","payload":{"connection_id":"efc69d3132f1467b8e898a382b23ac0d","event_at":"2026-07-27T05:32:04.959000Z","event_type":"price_change","frame_hash":"df8913f2cbe5f49d5bb1142786e93ccb7e9a12f3d3c11a0be2a671181556f379","frame_index":0,"kind":"data","monotonic_ns":232308234968375,"payload":{"event_type":"price_change","market":"0x3b40066b5cf3871a2f6237c5628bd8092a206aa998558ac5ec13c4483e31e160","price_changes":[{"asset_id":"110216635572655435074987471276357323571387854733835379371586402147734167783946","best_ask":"0.55","best_bid":"0.54","hash":"cffe307a0b5a12626671e71526bc76fb73d3e344","price":"0.03","side":"BUY","size":"781.43"},{"asset_id":"14766054693214075530629349735273995982307625376442606753688071083149620216746","best_ask":"0.46","best_bid":"0.45","hash":"4da95a0ca3aaf6cc1af4d7b3d819852f85de305e","price":"0.97","side":"SELL","size":"781.43"}],"timestamp":"1785130324959"},"payload_hash":"82a8ae1b2f23d63a0d68adf5be8052c79a1139f01bdb9d0ce7ae0ec7e63c72b9","raw_frame":"{\"market\":\"0x3b40066b5cf3871a2f6237c5628bd8092a206aa998558ac5ec13c4483e31e160\", \"price_changes\":[{\"asset_id\":\"110216635572655435074987471276357323571387854733835379371586402147734167783946\", \"price\":\"0.03\", \"size\":\"781.43\", \"side\":\"BUY\", \"hash\":\"cffe307a0b5a12626671e71526bc76fb73d3e344\", \"best_bid\":\"0.54\", \"best_ask\":\"0.55\"}, {\"asset_id\":\"14766054693214075530629349735273995982307625376442606753688071083149620216746\", \"price\":\"0.97\", \"size\":\"781.43\", \"side\":\"SELL\", \"hash\":\"4da95a0ca3aaf6cc1af4d7b3d819852f85de305e\", \"best_bid\":\"0.45\", \"best_ask\":\"0.46\"}], \"timestamp\":\"1785130324959\", \"event_type\":\"price_change\"}","received_at":"2026-07-27T05:32:04.997633Z","schema_version":"clob-market-ws.price_change.v1","sequence":null,"server_hash":null,"server_timestamp":"1785130324959","session_id":"502006c5cfcd437296561ea750c9ec8b","source":"clob_market_ws"},"received_at":"2026-07-27T05:32:04.997633Z","record_id":"b12d95fb2844a82c3d2c6c0150872070c19c69f0f025a5144cab113d75385021","schema_fingerprint":"4aa3821a28b0b7c2400bc59aba4bcc0a76e971dadd19610d3ad38c768e124dc7","schema_version":"edge-lab-recorder.raw.v1","sequence":null,"source":"clob_market_ws"}
{"event_at":"2026-07-27T05:32:04.960000Z","event_fingerprint":"4a2d43690e11361a2521850337c2f3aeb0c15633cbfd28c338acf87b55fc3bd0","payload":{"connection_id":"efc69d3132f1467b8e898a382b23ac0d","event_at":"2026-07-27T05:32:04.960000Z","event_type":"price_change","frame_hash":"0d5ea9dcbd00950ece9bef3f575830b762e77c7203b611081e12787ae084aeef","frame_index":0,"kind":"data","monotonic_ns":232308238765958,"payload":{"event_type":"price_change","market":"0x3b40066b5cf3871a2f6237c5628bd8092a206aa998558ac5ec13c4483e31e160","price_changes":[{"asset_id":"110216635572655435074987471276357323571387854733835379371586402147734167783946","best_ask":"0.55","best_bid":"0.54","hash":"82ce2d0aee202da8a3bed90bc63c846fca20a43d","price":"0.5","side":"BUY","size":"77.4"},{"asset_id":"14766054693214075530629349735273995982307625376442606753688071083149620216746","best_ask":"0.46","best_bid":"0.45","hash":"c797ea58fca7b94f0c2be14fcd623c4c2964b980","price":"0.5","side":"SELL","size":"77.4"}],"timestamp":"1785130324960"},"payload_hash":"d46135927391c8f2d404a333230864980a2fd771b853575912278272a0c2ced1","raw_frame":"{\"market\":\"0x3b40066b5cf3871a2f6237c5628bd8092a206aa998558ac5ec13c4483e31e160\", \"price_changes\":[{\"asset_id\":\"110216635572655435074987471276357323571387854733835379371586402147734167783946\", \"price\":\"0.5\", \"size\":\"77.4\", \"side\":\"BUY\", \"hash\":\"82ce2d0aee202da8a3bed90bc63c846fca20a43d\", \"best_bid\":\"0.54\", \"best_ask\":\"0.55\"}, {\"asset_id\":\"14766054693214075530629349735273995982307625376442606753688071083149620216746\", \"price\":\"0.5\", \"size\":\"77.4\", \"side\":\"SELL\", \"hash\":\"c797ea58fca7b94f0c2be14fcd623c4c2964b980\", \"best_bid\":\"0.45\", \"best_ask\":\"0.46\"}], \"timestamp\":\"1785130324960\", \"event_type\":\"price_change\"}","received_at":"2026-07-27T05:32:05.001423Z","schema_version":"clob-market-ws.price_change.v1","sequence":null,"server_hash":null,"server_timestamp":"1785130324960","session_id":"502006c5cfcd437296561ea750c9ec8b","source":"clob_market_ws"},"received_at":"2026-07-27T05:32:05.001423Z","record_id":"fbc4fb135731b73ca4523fea3e5b8f72b435f964ec325af68b81fa9641ae60f1","schema_fingerprint":"4aa3821a28b0b7c2400bc59aba4bcc0a76e971dadd19610d3ad38c768e124dc7","schema_version":"edge-lab-recorder.raw.v1","sequence":null,"source":"clob_market_ws"}
{"event_at":"2026-07-27T05:32:04.972000Z","event_fingerprint":"76a0a16eddba4ff398c704216b07f874ff8a2ffad09e11df63d3a6dc7f0c1f16","payload":{"connection_id":"efc69d3132f1467b8e898a382b23ac0d","event_at":"2026-07-27T05:32:04.972000Z","event_type":"price_change","frame_hash":"2f7408cf6b9f0a0964777c2d9415589427f8af2d98e52e0332ddc7fe46f722fb","frame_index":0,"kind":"data","monotonic_ns":232308244073583,"payload":{"event_type":"price_change","market":"0x3b40066b5cf3871a2f6237c5628bd8092a206aa998558ac5ec13c4483e31e160","price_changes":[{"asset_id":"14766054693214075530629349735273995982307625376442606753688071083149620216746","best_ask":"0.46","best_bid":"0.45","hash":"e0a14002f5de4293c7d3579acdcf4ed13483ca9b","price":"0.4","side":"BUY","size":"210"},{"asset_id":"110216635572655435074987471276357323571387854733835379371586402147734167783946","best_ask":"0.55","best_bid":"0.54","hash":"ad181b501a8f56e586b457b60a77a272e1eee7ba","price":"0.6","side":"SELL","size":"210"}],"timestamp":"1785130324972"},"payload_hash":"253434e82dd33b96100a80e7002bab44c141b0b7f07fe583d7a28bdd0586236b","raw_frame":"{\"market\":\"0x3b40066b5cf3871a2f6237c5628bd8092a206aa998558ac5ec13c4483e31e160\", \"price_changes\":[{\"asset_id\":\"14766054693214075530629349735273995982307625376442606753688071083149620216746\", \"price\":\"0.4\", \"size\":\"210\", \"side\":\"BUY\", \"hash\":\"e0a14002f5de4293c7d3579acdcf4ed13483ca9b\", \"best_bid\":\"0.45\", \"best_ask\":\"0.46\"}, {\"asset_id\":\"110216635572655435074987471276357323571387854733835379371586402147734167783946\", \"price\":\"0.6\", \"size\":\"210\", \"side\":\"SELL\", \"hash\":\"ad181b501a8f56e586b457b60a77a272e1eee7ba\", \"best_bid\":\"0.54\", \"best_ask\":\"0.55\"}], \"timestamp\":\"1785130324972\", \"event_type\":\"price_change\"}","received_at":"2026-07-27T05:32:05.006729Z","schema_version":"clob-market-ws.price_change.v1","sequence":null,"server_hash":null,"server_timestamp":"1785130324972","session_id":"502006c5cfcd437296561ea750c9ec8b","source":"clob_market_ws"},"received_at":"2026-07-27T05:32:05.006729Z","record_id":"cff02b82541dc517f9a4e41936ba704ec8dc951eb0990bc1d3d2b5a4d17b9ae8","schema_fingerprint":"4aa3821a28b0b7c2400bc59aba4bcc0a76e971dadd19610d3ad38c768e124dc7","schema_version":"edge-lab-recorder.raw.v1","sequence":null,"source":"clob_market_ws"}
{"event_at":"2026-07-27T05:32:04.972000Z","event_fingerprint":"33654055aa050a793af4a7d452009818970742d2fa298b2527e9e2097fdf1a94","payload":{"connection_id":"efc69d3132f1467b8e898a382b23ac0d","event_at":"2026-07-27T05:32:04.972000Z","event_type":"price_change","frame_hash":"6764442bfb47cbf2d1ac1ebc40862038590020746bacb059c01cbeeb57f28396","frame_index":0,"kind":"data","monotonic_ns":232308251154416,"payload":{"event_type":"price_change","market":"0x3b40066b5cf3871a2f6237c5628bd8092a206aa998558ac5ec13c4483e31e160","price_changes":[{"asset_id":"110216635572655435074987471276357323571387854733835379371586402147734167783946","best_ask":"0.55","best_bid":"0.54","hash":"ad181b501a8f56e586b457b60a77a272e1eee7ba","price":"0.49","side":"BUY","size":"92.6"},{"asset_id":"14766054693214075530629349735273995982307625376442606753688071083149620216746","best_ask":"0.46","best_bid":"0.45","hash":"e0a14002f5de4293c7d3579acdcf4ed13483ca9b","price":"0.51","side":"SELL","size":"92.6"}],"timestamp":"1785130324972"},"payload_hash":"9929b97bab2b782a2f4c6312bb0ea75e681caa1c21d2b81629f0e239dcddf1ee","raw_frame":"{\"market\":\"0x3b40066b5cf3871a2f6237c5628bd8092a206aa998558ac5ec13c4483e31e160\", \"price_changes\":[{\"asset_id\":\"110216635572655435074987471276357323571387854733835379371586402147734167783946\", \"price\":\"0.49\", \"size\":\"92.6\", \"side\":\"BUY\", \"hash\":\"ad181b501a8f56e586b457b60a77a272e1eee7ba\", \"best_bid\":\"0.54\", \"best_ask\":\"0.55\"}, {\"asset_id\":\"14766054693214075530629349735273995982307625376442606753688071083149620216746\", \"price\":\"0.51\", \"size\":\"92.6\", \"side\":\"SELL\", \"hash\":\"e0a14002f5de4293c7d3579acdcf4ed13483ca9b\", \"best_bid\":\"0.45\", \"best_ask\":\"0.46\"}], \"timestamp\":\"1785130324972\", \"event_type\":\"price_change\"}","received_at":"2026-07-27T05:32:05.013819Z","schema_version":"clob-market-ws.price_change.v1","sequence":null,"server_hash":null,"server_timestamp":"1785130324972","session_id":"502006c5cfcd437296561ea750c9ec8b","source":"clob_market_ws"},"received_at":"2026-07-27T05:32:05.013819Z","record_id":"79d9b265f59948beca87286864ad2f9c4bb4877f1a958943daac38b70f385b1d","schema_fingerprint":"4aa3821a28b0b7c2400bc59aba4bcc0a76e971dadd19610d3ad38c768e124dc7","schema_version":"edge-lab-recorder.raw.v1","sequence":null,"source":"clob_market_ws"}
{"event_at":"2026-07-27T05:32:04.972000Z","event_fingerprint":"60cc8b14d112bd83e1718052b0b71dba753ff470a1cdea7ce70aaa25ab62f2cf","payload":{"connection_id":"efc69d3132f1467b8e898a382b23ac0d","event_at":"2026-07-27T05:32:04.972000Z","event_type":"price_change","frame_hash":"5cc4de86c8e54886b264168ee7eedcfda97088926721de672285cf9dfde3c04b","frame_index":0,"kind":"data","monotonic_ns":232308255181625,"payload":{"event_type":"price_change","market":"0x3b40066b5cf3871a2f6237c5628bd8092a206aa998558ac5ec13c4483e31e160","price_changes":[{"asset_id":"110216635572655435074987471276357323571387854733835379371586402147734167783946","best_ask":"0.55","best_bid":"0.54","hash":"ad181b501a8f56e586b457b60a77a272e1eee7ba","price":"0.5","side":"BUY","size":"65.4"},{"asset_id":"14766054693214075530629349735273995982307625376442606753688071083149620216746","best_ask":"0.46","best_bid":"0.45","hash":"e0a14002f5de4293c7d3579acdcf4ed13483ca9b","price":"0.5","side":"SELL","size":"65.4"}],"timestamp":"1785130324972"},"payload_hash":"7e3b82a4438e5a8c525dad984136f456d5b29163c35e2d2dad83f1da081893d1","raw_frame":"{\"market\":\"0x3b40066b5cf3871a2f6237c5628bd8092a206aa998558ac5ec13c4483e31e160\", \"price_changes\":[{\"asset_id\":\"110216635572655435074987471276357323571387854733835379371586402147734167783946\", \"price\":\"0.5\", \"size\":\"65.4\", \"side\":\"BUY\", \"hash\":\"ad181b501a8f56e586b457b60a77a272e1eee7ba\", \"best_bid\":\"0.54\", \"best_ask\":\"0.55\"}, {\"asset_id\":\"14766054693214075530629349735273995982307625376442606753688071083149620216746\", \"price\":\"0.5\", \"size\":\"65.4\", \"side\":\"SELL\", \"hash\":\"e0a14002f5de4293c7d3579acdcf4ed13483ca9b\", \"best_bid\":\"0.45\", \"best_ask\":\"0.46\"}], \"timestamp\":\"1785130324972\", \"event_type\":\"price_change\"}","received_at":"2026-07-27T05:32:05.017841Z","schema_version":"clob-market-ws.price_change.v1","sequence":null,"server_hash":null,"server_timestamp":"1785130324972","session_id":"502006c5cfcd437296561ea750c9ec8b","source":"clob_market_ws"},"received_at":"2026-07-27T05:32:05.017841Z","record_id":"0cd48bd43db4e9adcda5d235e4e9640f56bad9f20ed3194aae458cf927f578d2","schema_fingerprint":"4aa3821a28b0b7c2400bc59aba4bcc0a76e971dadd19610d3ad38c768e124dc7","schema_version":"edge-lab-recorder.raw.v1","sequence":null,"source":"clob_market_ws"}
{"event_at":"2026-07-27T05:32:04.976000Z","event_fingerprint":"d171bedc5ee3411355da396eced5170635b5d0082d7d9823e0579e73a1a5ee63","payload":{"connection_id":"efc69d3132f1467b8e898a382b23ac0d","event_at":"2026-07-27T05:32:04.976000Z","event_type":"price_change","frame_hash":"1e9586c9c18958df74b8b86f0c0f1e35f4266d9e0e8204ac6f93fa608a37d21c","frame_index":0,"kind":"data","monotonic_ns":232308258283625,"payload":{"event_type":"price_change","market":"0x3b40066b5cf3871a2f6237c5628bd8092a206aa998558ac5ec13c4483e31e160","price_changes":[{"asset_id":"14766054693214075530629349735273995982307625376442606753688071083149620216746","best_ask":"0.46","best_bid":"0.45","hash":"c451707525db15593fc44033add102c1fcb0bb10","price":"0.51","side":"SELL","size":"67.6"},{"asset_id":"110216635572655435074987471276357323571387854733835379371586402147734167783946","best_ask":"0.55","best_bid":"0.54","hash":"473a4bc30ddc499df277990c2ce58a3335d49ae6","price":"0.49","side":"BUY","size":"67.6"}],"timestamp":"1785130324976"},"payload_hash":"8281e7c5f31b1200daad30522ec55be4c074ce41a1d43faec8dfda1ada6bf2e1","raw_frame":"{\"market\":\"0x3b40066b5cf3871a2f6237c5628bd8092a206aa998558ac5ec13c4483e31e160\", \"price_changes\":[{\"asset_id\":\"14766054693214075530629349735273995982307625376442606753688071083149620216746\", \"price\":\"0.51\", \"size\":\"67.6\", \"side\":\"SELL\", \"hash\":\"c451707525db15593fc44033add102c1fcb0bb10\", \"best_bid\":\"0.45\", \"best_ask\":\"0.46\"}, {\"asset_id\":\"110216635572655435074987471276357323571387854733835379371586402147734167783946\", \"price\":\"0.49\", \"size\":\"67.6\", \"side\":\"BUY\", \"hash\":\"473a4bc30ddc499df277990c2ce58a3335d49ae6\", \"best_bid\":\"0.54\", \"best_ask\":\"0.55\"}], \"timestamp\":\"1785130324976\", \"event_type\":\"price_change\"}","received_at":"2026-07-27T05:32:05.020942Z","schema_version":"clob-market-ws.price_change.v1","sequence":null,"server_hash":null,"server_timestamp":"1785130324976","session_id":"502006c5cfcd437296561ea750c9ec8b","source":"clob_market_ws"},"received_at":"2026-07-27T05:32:05.020942Z","record_id":"bbce4f97ac4f0210b1cdb7731332565637aae544b8c08b1c5a6967f6523efb78","schema_fingerprint":"4aa3821a28b0b7c2400bc59aba4bcc0a76e971dadd19610d3ad38c768e124dc7","schema_version":"edge-lab-recorder.raw.v1","sequence":null,"source":"clob_market_ws"}
{"event_at":"2026-07-27T05:32:04.977000Z","event_fingerprint":"67b28598af0ac65ea0d90fd98929a578d307d4003d806499c63c99b67b50c0c0","payload":{"connection_id":"efc69d3132f1467b8e898a382b23ac0d","event_at":"2026-07-27T05:32:04.977000Z","event_type":"price_change","frame_hash":"f2d937e3020ac13c63f53e3b5d16849f149c2a8a2ca593b26fd1a911238e0e4d","frame_index":0,"kind":"data","monotonic_ns":232308262908041,"payload":{"event_type":"price_change","market":"0x3b40066b5cf3871a2f6237c5628bd8092a206aa998558ac5ec13c4483e31e160","price_changes":[{"asset_id":"110216635572655435074987471276357323571387854733835379371586402147734167783946","best_ask":"0.55","best_bid":"0.54","hash":"440c8a9d76188f782f131580d6aedacc314061bb","price":"0.49","side":"BUY","size":"42.6"},{"asset_id":"14766054693214075530629349735273995982307625376442606753688071083149620216746","best_ask":"0.46","best_bid":"0.45","hash":"e36f0c08da6efd3b1327dbfd7ceed10817195c20","price":"0.51","side":"SELL","size":"42.6"}],"timestamp":"1785130324977"},"payload_hash":"2af2316d5661d5526374ff87394cbf9537eb9df0df343492f2fc3f1dc2a47a51","raw_frame":"{\"market\":\"0x3b40066b5cf3871a2f6237c5628bd8092a206aa998558ac5ec13c4483e31e160\", \"price_changes\":[{\"asset_id\":\"110216635572655435074987471276357323571387854733835379371586402147734167783946\", \"price\":\"0.49\", \"size\":\"42.6\", \"side\":\"BUY\", \"hash\":\"440c8a9d76188f782f131580d6aedacc314061bb\", \"best_bid\":\"0.54\", \"best_ask\":\"0.55\"}, {\"asset_id\":\"14766054693214075530629349735273995982307625376442606753688071083149620216746\", \"price\":\"0.51\", \"size\":\"42.6\", \"side\":\"SELL\", \"hash\":\"e36f0c08da6efd3b1327dbfd7ceed10817195c20\", \"best_bid\":\"0.45\", \"best_ask\":\"0.46\"}], \"timestamp\":\"1785130324977\", \"event_type\":\"price_change\"}","received_at":"2026-07-27T05:32:05.025567Z","schema_version":"clob-market-ws.price_change.v1","sequence":null,"server_hash":null,"server_timestamp":"1785130324977","session_id":"502006c5cfcd437296561ea750c9ec8b","source":"clob_market_ws"},"received_at":"2026-07-27T05:32:05.025567Z","record_id":"bc872f3dec6ffbc1d6d9766ae6a23055bfa38e6719bc1c6e0963d29d8923a671","schema_fingerprint":"4aa3821a28b0b7c2400bc59aba4bcc0a76e971dadd19610d3ad38c768e124dc7","schema_version":"edge-lab-recorder.raw.v1","sequence":null,"source":"clob_market_ws"}
{"event_at":"2026-07-27T05:32:04.982000Z","event_fingerprint":"ff8fc4d492ec331dae2a65babb3103a6692443f76ce586ed35e312d40aedd65b","payload":{"connection_id":"efc69d3132f1467b8e898a382b23ac0d","event_at":"2026-07-27T05:32:04.982000Z","event_type":"price_change","frame_hash":"1e62fac585dff00f42d968d11f74d3ddad55bd5c1725b085cecd7fd18d114b97","frame_index":0,"kind":"data","monotonic_ns":232308267234208,"payload":{"event_type":"price_change","market":"0x3b40066b5cf3871a2f6237c5628bd8092a206aa998558ac5ec13c4483e31e160","price_changes":[{"asset_id":"110216635572655435074987471276357323571387854733835379371586402147734167783946","best_ask":"0.55","best_bid":"0.54","hash":"ab2326dc66cb037a83d3b1947a7563ca3265efd8","price":"0.45","side":"BUY","size":"180.1"},{"asset_id":"14766054693214075530629349735273995982307625376442606753688071083149620216746","best_ask":"0.46","best_bid":"0.45","hash":"efa8ddf7ac43445debcf9ed107cf6fab90d4b3bd","price":"0.55","side":"SELL","size":"180.1"}],"timestamp":"1785130324982"},"payload_hash":"c3b21972a1c08f2f6ab9ca42bbf7c7bedfe565464d048db42c5abfb0ba2cc862","raw_frame":"{\"market\":\"0x3b40066b5cf3871a2f6237c5628bd8092a206aa998558ac5ec13c4483e31e160\", \"price_changes\":[{\"asset_id\":\"110216635572655435074987471276357323571387854733835379371586402147734167783946\", \"price\":\"0.45\", \"size\":\"180.1\", \"side\":\"BUY\", \"hash\":\"ab2326dc66cb037a83d3b1947a7563ca3265efd8\", \"best_bid\":\"0.54\", \"best_ask\":\"0.55\"}, {\"asset_id\":\"14766054693214075530629349735273995982307625376442606753688071083149620216746\", \"price\":\"0.55\", \"size\":\"180.1\", \"side\":\"SELL\", \"hash\":\"efa8ddf7ac43445debcf9ed107cf6fab90d4b3bd\", \"best_bid\":\"0.45\", \"best_ask\":\"0.46\"}], \"timestamp\":\"1785130324982\", \"event_type\":\"price_change\"}","received_at":"2026-07-27T05:32:05.029893Z","schema_version":"clob-market-ws.price_change.v1","sequence":null,"server_hash":null,"server_timestamp":"1785130324982","session_id":"502006c5cfcd437296561ea750c9ec8b","source":"clob_market_ws"},"received_at":"2026-07-27T05:32:05.029893Z","record_id":"1ff7b0bcb6925eae925a84d721f6b50dd145a8ee4130bbc52058998890484684","schema_fingerprint":"4aa3821a28b0b7c2400bc59aba4bcc0a76e971dadd19610d3ad38c768e124dc7","schema_version":"edge-lab-recorder.raw.v1","sequence":null,"source":"clob_market_ws"}
{"event_at":"2026-07-27T05:32:04.983000Z","event_fingerprint":"77c968eccf3bba822a15cb2b66c6e27a63918e267c4e4b642f41eb048c135689","payload":{"connection_id":"efc69d3132f1467b8e898a382b23ac0d","event_at":"2026-07-27T05:32:04.983000Z","event_type":"price_change","frame_hash":"23cf9df0a54f3f162e700cd519d708acc341bd94442fea45bf74374df69ddeb5","frame_index":0,"kind":"data","monotonic_ns":232308269221625,"payload":{"event_type":"price_change","market":"0x3b40066b5cf3871a2f6237c5628bd8092a206aa998558ac5ec13c4483e31e160","price_changes":[{"asset_id":"14766054693214075530629349735273995982307625376442606753688071083149620216746","best_ask":"0.46","best_bid":"0.45","hash":"d7449292113c11ddfa52f72c7686e9a863980f20","price":"0.44","side":"BUY","size":"27.15"},{"asset_id":"110216635572655435074987471276357323571387854733835379371586402147734167783946","best_ask":"0.55","best_bid":"0.54","hash":"3e1f4f901e055a04cf3411f1252faa1f4c19ae0a","price":"0.56","side":"SELL","size":"27.15"}],"timestamp":"1785130324983"},"payload_hash":"86511f794f56cc690ca4702ea6e2c316d11a1de4d9a99d636795277617a1027d","raw_frame":"{\"market\":\"0x3b40066b5cf3871a2f6237c5628bd8092a206aa998558ac5ec13c4483e31e160\", \"price_changes\":[{\"asset_id\":\"14766054693214075530629349735273995982307625376442606753688071083149620216746\", \"price\":\"0.44\", \"size\":\"27.15\", \"side\":\"BUY\", \"hash\":\"d7449292113c11ddfa52f72c7686e9a863980f20\", \"best_bid\":\"0.45\", \"best_ask\":\"0.46\"}, {\"asset_id\":\"110216635572655435074987471276357323571387854733835379371586402147734167783946\", \"price\":\"0.56\", \"size\":\"27.15\", \"side\":\"SELL\", \"hash\":\"3e1f4f901e055a04cf3411f1252faa1f4c19ae0a\", \"best_bid\":\"0.54\", \"best_ask\":\"0.55\"}], \"timestamp\":\"1785130324983\", \"event_type\":\"price_change\"}","received_at":"2026-07-27T05:32:05.031881Z","schema_version":"clob-market-ws.price_change.v1","sequence":null,"server_hash":null,"server_timestamp":"1785130324983","session_id":"502006c5cfcd437296561ea750c9ec8b","source":"clob_market_ws"},"received_at":"2026-07-27T05:32:05.031881Z","record_id":"21a3c2932e25e418a447c63662fed852a1caa2e1c967a316f5f61cbf2a90eff2","schema_fingerprint":"4aa3821a28b0b7c2400bc59aba4bcc0a76e971dadd19610d3ad38c768e124dc7","schema_version":"edge-lab-recorder.raw.v1","sequence":null,"source":"clob_market_ws"}
{"event_at":"2026-07-27T05:32:04.984000Z","event_fingerprint":"00112ed52411e89cb44851cf1ebe03e89ec6f0c08c54922fe849d75a9a02a28c","payload":{"connection_id":"efc69d3132f1467b8e898a382b23ac0d","event_at":"2026-07-27T05:32:04.984000Z","event_type":"price_change","frame_hash":"234b22c86e487feb9989a16fa4d5bfa65b472324c40d6f410099af89834a6a3d","frame_index":0,"kind":"data","monotonic_ns":232308273411833,"payload":{"event_type":"price_change","market":"0x3b40066b5cf3871a2f6237c5628bd8092a206aa998558ac5ec13c4483e31e160","price_changes":[{"asset_id":"110216635572655435074987471276357323571387854733835379371586402147734167783946","best_ask":"0.55","best_bid":"0.54","hash":"d7507a2cb4a613badbf88b772041e4f109df20f2","price":"0.46","side":"BUY","size":"157.06"},{"asset_id":"14766054693214075530629349735273995982307625376442606753688071083149620216746","best_ask":"0.46","best_bid":"0.45","hash":"720610f9d3eb2f0f700de3b37e985429df230cb9","price":"0.54","side":"SELL","size":"157.06"}],"timestamp":"1785130324984"},"payload_hash":"7b0203b5c4210e7c63b92cf823a3199a33aae86f3cad514f1a2432e623c2cc82","raw_frame":"{\"market\":\"0x3b40066b5cf3871a2f6237c5628bd8092a206aa998558ac5ec13c4483e31e160\", \"price_changes\":[{\"asset_id\":\"110216635572655435074987471276357323571387854733835379371586402147734167783946\", \"price\":\"0.46\", \"size\":\"157.06\", \"side\":\"BUY\", \"hash\":\"d7507a2cb4a613badbf88b772041e4f109df20f2\", \"best_bid\":\"0.54\", \"best_ask\":\"0.55\"}, {\"asset_id\":\"14766054693214075530629349735273995982307625376442606753688071083149620216746\", \"price\":\"0.54\", \"size\":\"157.06\", \"side\":\"SELL\", \"hash\":\"720610f9d3eb2f0f700de3b37e985429df230cb9\", \"best_bid\":\"0.45\", \"best_ask\":\"0.46\"}], \"timestamp\":\"1785130324984\", \"event_type\":\"price_change\"}","received_at":"2026-07-27T05:32:05.036072Z","schema_version":"clob-market-ws.price_change.v1","sequence":null,"server_hash":null,"server_timestamp":"1785130324984","session_id":"502006c5cfcd437296561ea750c9ec8b","source":"clob_market_ws"},"received_at":"2026-07-27T05:32:05.036072Z","record_id":"7ce578bdd3b17fc1cfc4097578745d37a3f0b46a6233bc80839730ab83d7a159","schema_fingerprint":"4aa3821a28b0b7c2400bc59aba4bcc0a76e971dadd19610d3ad38c768e124dc7","schema_version":"edge-lab-recorder.raw.v1","sequence":null,"source":"clob_market_ws"}
{"event_at":"2026-07-27T05:32:05.001000Z","event_fingerprint":"d37f929d318a67c47d1ed6e5a81a5ad61b4eff31a98ad4c92f59ca2b6c6ba967","payload":{"connection_id":"efc69d3132f1467b8e898a382b23ac0d","event_at":"2026-07-27T05:32:05.001000Z","event_type":"price_change","frame_hash":"bc8fe5eadb6cc39d75748b4019217055c856cc7fbeabca4d9a7e94ef2ef0d35d","frame_index":0,"kind":"data","monotonic_ns":232308277976041,"payload":{"event_type":"price_change","market":"0x3b40066b5cf3871a2f6237c5628bd8092a206aa998558ac5ec13c4483e31e160","price_changes":[{"asset_id":"110216635572655435074987471276357323571387854733835379371586402147734167783946","best_ask":"0.55","best_bid":"0.54","hash":"e7879910e4e72e7d02b0c07305021a2cb13073e7","price":"0.55","side":"SELL","size":"46.4"},{"asset_id":"14766054693214075530629349735273995982307625376442606753688071083149620216746","best_ask":"0.46","best_bid":"0.45","hash":"f13a381db009c7f10f4a482a14d634be6b978172","price":"0.45","side":"BUY","size":"46.4"}],"timestamp":"1785130325001"},"payload_hash":"2f42a1216074fbc73d222f7b58dca9b0b85180ea1e09cbe28e81f0265f195abb","raw_frame":"{\"market\":\"0x3b40066b5cf3871a2f6237c5628bd8092a206aa998558ac5ec13c4483e31e160\", \"price_changes\":[{\"asset_id\":\"110216635572655435074987471276357323571387854733835379371586402147734167783946\", \"price\":\"0.55\", \"size\":\"46.4\", \"side\":\"SELL\", \"hash\":\"e7879910e4e72e7d02b0c07305021a2cb13073e7\", \"best_bid\":\"0.54\", \"best_ask\":\"0.55\"}, {\"asset_id\":\"14766054693214075530629349735273995982307625376442606753688071083149620216746\", \"price\":\"0.45\", \"size\":\"46.4\", \"side\":\"BUY\", \"hash\":\"f13a381db009c7f10f4a482a14d634be6b978172\", \"best_bid\":\"0.45\", \"best_ask\":\"0.46\"}], \"timestamp\":\"1785130325001\", \"event_type\":\"price_change\"}","received_at":"2026-07-27T05:32:05.040631Z","schema_version":"clob-market-ws.price_change.v1","sequence":null,"server_hash":null,"server_timestamp":"1785130325001","session_id":"502006c5cfcd437296561ea750c9ec8b","source":"clob_market_ws"},"received_at":"2026-07-27T05:32:05.040631Z","record_id":"74b393072cb96a4756e2bae6548e184ec1df9034b5cd5fb2a6233cc97c52af29","schema_fingerprint":"4aa3821a28b0b7c2400bc59aba4bcc0a76e971dadd19610d3ad38c768e124dc7","schema_version":"edge-lab-recorder.raw.v1","sequence":null,"source":"clob_market_ws"}
{"event_at":"2026-07-27T05:32:05.002000Z","event_fingerprint":"4c7af44573e9b4761a1d52db5c5b57d75c74067738d5c2374baacad14bde1b55","payload":{"connection_id":"efc69d3132f1467b8e898a382b23ac0d","event_at":"2026-07-27T05:32:05.002000Z","event_type":"price_change","frame_hash":"f04722ca297612186f434e58924a1a1ae7593889ae7176ca1df7c5e7752c42be","frame_index":0,"kind":"data","monotonic_ns":232308282553125,"payload":{"event_type":"price_change","market":"0x3b40066b5cf3871a2f6237c5628bd8092a206aa998558ac5ec13c4483e31e160","price_changes":[{"asset_id":"110216635572655435074987471276357323571387854733835379371586402147734167783946","best_ask":"0.55","best_bid":"0.54","hash":"281537cb3f8930029a9e96ad82e5af1a938aa285","price":"0.48","side":"BUY","size":"178.01"},{"asset_id":"14766054693214075530629349735273995982307625376442606753688071083149620216746","best_ask":"0.46","best_bid":"0.45","hash":"a9a48e6a077a30eea334ebb7f8a02d215ed14298","price":"0.52","side":"SELL","size":"178.01"}],"timestamp":"1785130325002"},"payload_hash":"9c5dca62c00909c3decdbefe167bed3871410832007d281aca06d8abac1c1a12","raw_frame":"{\"market\":\"0x3b40066b5cf3871a2f6237c5628bd8092a206aa998558ac5ec13c4483e31e160\", \"price_changes\":[{\"asset_id\":\"110216635572655435074987471276357323571387854733835379371586402147734167783946\", \"price\":\"0.48\", \"size\":\"178.01\", \"side\":\"BUY\", \"hash\":\"281537cb3f8930029a9e96ad82e5af1a938aa285\", \"best_bid\":\"0.54\", \"best_ask\":\"0.55\"}, {\"asset_id\":\"14766054693214075530629349735273995982307625376442606753688071083149620216746\", \"price\":\"0.52\", \"size\":\"178.01\", \"side\":\"SELL\", \"hash\":\"a9a48e6a077a30eea334ebb7f8a02d215ed14298\", \"best_bid\":\"0.45\", \"best_ask\":\"0.46\"}], \"timestamp\":\"1785130325002\", \"event_type\":\"price_change\"}","received_at":"2026-07-27T05:32:05.045212Z","schema_version":"clob-market-ws.price_change.v1","sequence":null,"server_hash":null,"server_timestamp":"1785130325002","session_id":"502006c5cfcd437296561ea750c9ec8b","source":"clob_market_ws"},"received_at":"2026-07-27T05:32:05.045212Z","record_id":"11b886fa28f23dff07d90bc70150dfdecf51f14c892fbb2800a90d4cd46c6fc2","schema_fingerprint":"4aa3821a28b0b7c2400bc59aba4bcc0a76e971dadd19610d3ad38c768e124dc7","schema_version":"edge-lab-recorder.raw.v1","sequence":null,"source":"clob_market_ws"}
{"event_at":"2026-07-27T05:32:05.003000Z","event_fingerprint":"d9ff6aed735809b458aaf9fc31f23b3cb825579ce97e3d968a55062db17322a4","payload":{"connection_id":"efc69d3132f1467b8e898a382b23ac0d","event_at":"2026-07-27T05:32:05.003000Z","event_type":"price_change","frame_hash":"96acd33fd40202b55ca0ce35b0afab310051a18ded8b397264f678cea8a27ccf","frame_index":0,"kind":"data","monotonic_ns":232308286135916,"payload":{"event_type":"price_change","market":"0x3b40066b5cf3871a2f6237c5628bd8092a206aa998558ac5ec13c4483e31e160","price_changes":[{"asset_id":"14766054693214075530629349735273995982307625376442606753688071083149620216746","best_ask":"0.46","best_bid":"0.45","hash":"e64a89f7225e422f1eb4ae4becca99957488f4ce","price":"0.52","side":"SELL","size":"203.01"},{"asset_id":"110216635572655435074987471276357323571387854733835379371586402147734167783946","best_ask":"0.55","best_bid":"0.54","hash":"8880e32525d38405ba1603d244a45e910ce8c162","price":"0.48","side":"BUY","size":"203.01"}],"timestamp":"1785130325003"},"payload_hash":"73d18568998b7599aa85f489e0d22518e526f318a21d4511c907f1a8eca312a3","raw_frame":"{\"market\":\"0x3b40066b5cf3871a2f6237c5628bd8092a206aa998558ac5ec13c4483e31e160\", \"price_changes\":[{\"asset_id\":\"14766054693214075530629349735273995982307625376442606753688071083149620216746\", \"price\":\"0.52\", \"size\":\"203.01\", \"side\":\"SELL\", \"hash\":\"e64a89f7225e422f1eb4ae4becca99957488f4ce\", \"best_bid\":\"0.45\", \"best_ask\":\"0.46\"}, {\"asset_id\":\"110216635572655435074987471276357323571387854733835379371586402147734167783946\", \"price\":\"0.48\", \"size\":\"203.01\", \"side\":\"BUY\", \"hash\":\"8880e32525d38405ba1603d244a45e910ce8c162\", \"best_bid\":\"0.54\", \"best_ask\":\"0.55\"}], \"timestamp\":\"1785130325003\", \"event_type\":\"price_change\"}","received_at":"2026-07-27T05:32:05.048796Z","schema_version":"clob-market-ws.price_change.v1","sequence":null,"server_hash":null,"server_timestamp":"1785130325003","session_id":"502006c5cfcd437296561ea750c9ec8b","source":"clob_market_ws"},"received_at":"2026-07-27T05:32:05.048796Z","record_id":"d61895b6c0349a47479acd713419f4e6a903782f35f1c44523ad0aa4f4f40344","schema_fingerprint":"4aa3821a28b0b7c2400bc59aba4bcc0a76e971dadd19610d3ad38c768e124dc7","schema_version":"edge-lab-recorder.raw.v1","sequence":null,"source":"clob_market_ws"}
{"event_at":"2026-07-27T05:32:05.018000Z","event_fingerprint":"37cd1437913239cb87ef66edbf71afac32f8a95ebfb2249173ca480f796c0e1c","payload":{"connection_id":"efc69d3132f1467b8e898a382b23ac0d","event_at":"2026-07-27T05:32:05.018000Z","event_type":"price_change","frame_hash":"20c02d3512a3052bb03172d77b7d9a2a3c0ae900eef35ecab25300e18a0b4fef","frame_index":0,"kind":"data","monotonic_ns":232308290568666,"payload":{"event_type":"price_change","market":"0x3b40066b5cf3871a2f6237c5628bd8092a206aa998558ac5ec13c4483e31e160","price_changes":[{"asset_id":"110216635572655435074987471276357323571387854733835379371586402147734167783946","best_ask":"0.55","best_bid":"0.54","hash":"dc91161ebbf0558bac8a494fac1a391746792353","price":"0.03","side":"BUY","size":"776.43"},{"asset_id":"14766054693214075530629349735273995982307625376442606753688071083149620216746","best_ask":"0.46","best_bid":"0.45","hash":"b03b0a0dad9793bc991b69cadbd23fa08cdd52d1","price":"0.97","side":"SELL","size":"776.43"}],"timestamp":"1785130325018"},"payload_hash":"e3c30d650b2f222a9e669e6a70234974faf98464afcd1075d4b14b04746a7ced","raw_frame":"{\"market\":\"0x3b40066b5cf3871a2f6237c5628bd8092a206aa998558ac5ec13c4483e31e160\", \"price_changes\":[{\"asset_id\":\"110216635572655435074987471276357323571387854733835379371586402147734167783946\", \"price\":\"0.03\", \"size\":\"776.43\", \"side\":\"BUY\", \"hash\":\"dc91161ebbf0558bac8a494fac1a391746792353\", \"best_bid\":\"0.54\", \"best_ask\":\"0.55\"}, {\"asset_id\":\"14766054693214075530629349735273995982307625376442606753688071083149620216746\", \"price\":\"0.97\", \"size\":\"776.43\", \"side\":\"SELL\", \"hash\":\"b03b0a0dad9793bc991b69cadbd23fa08cdd52d1\", \"best_bid\":\"0.45\", \"best_ask\":\"0.46\"}], \"timestamp\":\"1785130325018\", \"event_type\":\"price_change\"}","received_at":"2026-07-27T05:32:05.053229Z","schema_version":"clob-market-ws.price_change.v1","sequence":null,"server_hash":null,"server_timestamp":"1785130325018","session_id":"502006c5cfcd437296561ea750c9ec8b","source":"clob_market_ws"},"received_at":"2026-07-27T05:32:05.053229Z","record_id":"575f216956de9b069e49c8a707357a0880e1087536324d56d5c999ec66760209","schema_fingerprint":"4aa3821a28b0b7c2400bc59aba4bcc0a76e971dadd19610d3ad38c768e124dc7","schema_version":"edge-lab-recorder.raw.v1","sequence":null,"source":"clob_market_ws"}
{"event_at":"2026-07-27T05:32:05.019000Z","event_fingerprint":"99d79fa627e4382293ef1c527579492fb07a50fcd7f8fb297463b2689275ff5c","payload":{"connection_id":"efc69d3132f1467b8e898a382b23ac0d","event_at":"2026-07-27T05:32:05.019000Z","event_type":"price_change","frame_hash":"daf5ae770a608c6dd4ac760ef06e09db73edd1fd299a9ced4faefdbbc6e4af8a","frame_index":0,"kind":"data","monotonic_ns":232308292862250,"payload":{"event_type":"price_change","market":"0x3b40066b5cf3871a2f6237c5628bd8092a206aa998558ac5ec13c4483e31e160","price_changes":[{"asset_id":"14766054693214075530629349735273995982307625376442606753688071083149620216746","best_ask":"0.46","best_bid":"0.45","hash":"2c7711a54f663f40862ce97178f3089d46083eed","price":"0.01","side":"BUY","size":"7878.02"},{"asset_id":"110216635572655435074987471276357323571387854733835379371586402147734167783946","best_ask":"0.55","best_bid":"0.54","hash":"cb12cd6495c4f82204cd872cefd47c492637d0f0","price":"0.99","side":"SELL","size":"7878.02"}],"timestamp":"1785130325019"},"payload_hash":"225aa4e4564fc84be43657c1c3fd730353747a494b53129c53fea240b231958c","raw_frame":"{\"market\":\"0x3b40066b5cf3871a2f6237c5628bd8092a206aa998558ac5ec13c4483e31e160\", \"price_changes\":[{\"asset_id\":\"14766054693214075530629349735273995982307625376442606753688071083149620216746\", \"price\":\"0.01\", \"size\":\"7878.02\", \"side\":\"BUY\", \"hash\":\"2c7711a54f663f40862ce97178f3089d46083eed\", \"best_bid\":\"0.45\", \"best_ask\":\"0.46\"}, {\"asset_id\":\"110216635572655435074987471276357323571387854733835379371586402147734167783946\", \"price\":\"0.99\", \"size\":\"7878.02\", \"side\":\"SELL\", \"hash\":\"cb12cd6495c4f82204cd872cefd47c492637d0f0\", \"best_bid\":\"0.54\", \"best_ask\":\"0.55\"}], \"timestamp\":\"1785130325019\", \"event_type\":\"price_change\"}","received_at":"2026-07-27T05:32:05.055521Z","schema_version":"clob-market-ws.price_change.v1","sequence":null,"server_hash":null,"server_timestamp":"1785130325019","session_id":"502006c5cfcd437296561ea750c9ec8b","source":"clob_market_ws"},"received_at":"2026-07-27T05:32:05.055521Z","record_id":"4fb00d07418263fb66f2f0d07b0ccfaa9c6f357fe1563b8195e972761bd2d970","schema_fingerprint":"4aa3821a28b0b7c2400bc59aba4bcc0a76e971dadd19610d3ad38c768e124dc7","schema_version":"edge-lab-recorder.raw.v1","sequence":null,"source":"clob_market_ws"}
{"event_at":"2026-07-27T05:32:05.021000Z","event_fingerprint":"b7a7dd5e9d4f7aeb54bb6b5214608d18af2f4558c0063dc1db104149084a1c65","payload":{"connection_id":"efc69d3132f1467b8e898a382b23ac0d","event_at":"2026-07-27T05:32:05.021000Z","event_type":"price_change","frame_hash":"27d7d65d15991001f39ed5aa1cf61f8c5828b26825ee5a5212833dc6b3c446db","frame_index":0,"kind":"data","monotonic_ns":232308298885083,"payload":{"event_type":"price_change","market":"0x3b40066b5cf3871a2f6237c5628bd8092a206aa998558ac5ec13c4483e31e160","price_changes":[{"asset_id":"110216635572655435074987471276357323571387854733835379371586402147734167783946","best_ask":"0.55","best_bid":"0.54","hash":"e67a8dd097309f2569d6ccf13f2e80b01c12782f","price":"0.41","side":"BUY","size":"220.4"},{"asset_id":"14766054693214075530629349735273995982307625376442606753688071083149620216746","best_ask":"0.46","best_bid":"0.45","hash":"c3de0bd32ac67be4c23d2bf7b01d61cbd9390d5f","price":"0.59","side":"SELL","size":"220.4"}],"timestamp":"1785130325021"},"payload_hash":"3f193d669e4d377cbc78109db380cd835b42b6ebd6808220fa3354e2dde4b1f5","raw_frame":"{\"market\":\"0x3b40066b5cf3871a2f6237c5628bd8092a206aa998558ac5ec13c4483e31e160\", \"price_changes\":[{\"asset_id\":\"110216635572655435074987471276357323571387854733835379371586402147734167783946\", \"price\":\"0.41\", \"size\":\"220.4\", \"side\":\"BUY\", \"hash\":\"e67a8dd097309f2569d6ccf13f2e80b01c12782f\", \"best_bid\":\"0.54\", \"best_ask\":\"0.55\"}, {\"asset_id\":\"14766054693214075530629349735273995982307625376442606753688071083149620216746\", \"price\":\"0.59\", \"size\":\"220.4\", \"side\":\"SELL\", \"hash\":\"c3de0bd32ac67be4c23d2bf7b01d61cbd9390d5f\", \"best_bid\":\"0.45\", \"best_ask\":\"0.46\"}], \"timestamp\":\"1785130325021\", \"event_type\":\"price_change\"}","received_at":"2026-07-27T05:32:05.061545Z","schema_version":"clob-market-ws.price_change.v1","sequence":null,"server_hash":null,"server_timestamp":"1785130325021","session_id":"502006c5cfcd437296561ea750c9ec8b","source":"clob_market_ws"},"received_at":"2026-07-27T05:32:05.061545Z","record_id":"7e37eace9069b6ee9f7baf6ac9b8f5442a030e8bb753d3ff77a937d4370aa76a","schema_fingerprint":"4aa3821a28b0b7c2400bc59aba4bcc0a76e971dadd19610d3ad38c768e124dc7","schema_version":"edge-lab-recorder.raw.v1","sequence":null,"source":"clob_market_ws"}
{"event_at":"2026-07-27T05:32:05.022000Z","event_fingerprint":"713b4a48c938379ce187654051b0e0222a6e68d1a99839f12524be059aabf01b","payload":{"connection_id":"efc69d3132f1467b8e898a382b23ac0d","event_at":"2026-07-27T05:32:05.022000Z","event_type":"price_change","frame_hash":"ab1cdf9d38dc4195152c1e6ec2c040264fa50938055855d7f827b4fda4fab94f","frame_index":0,"kind":"data","monotonic_ns":232308301299500,"payload":{"event_type":"price_change","market":"0x3b40066b5cf3871a2f6237c5628bd8092a206aa998558ac5ec13c4483e31e160","price_changes":[{"asset_id":"110216635572655435074987471276357323571387854733835379371586402147734167783946","best_ask":"0.55","best_bid":"0.54","hash":"639627e0f283a0758e12f23fccaa19fdd38d3037","price":"0.44","side":"BUY","size":"185.21"},{"asset_id":"14766054693214075530629349735273995982307625376442606753688071083149620216746","best_ask":"0.46","best_bid":"0.45","hash":"f482dfdbd464f143df459e5ece3ca2547f13ceff","price":"0.56","side":"SELL","size":"185.21"}],"timestamp":"1785130325022"},"payload_hash":"84312b008d9147f41c22212dc686ebfceade637476dfdce64727307e5949a578","raw_frame":"{\"market\":\"0x3b40066b5cf3871a2f6237c5628bd8092a206aa998558ac5ec13c4483e31e160\", \"price_changes\":[{\"asset_id\":\"110216635572655435074987471276357323571387854733835379371586402147734167783946\", \"price\":\"0.44\", \"size\":\"185.21\", \"side\":\"BUY\", \"hash\":\"639627e0f283a0758e12f23fccaa19fdd38d3037\", \"best_bid\":\"0.54\", \"best_ask\":\"0.55\"}, {\"asset_id\":\"14766054693214075530629349735273995982307625376442606753688071083149620216746\", \"price\":\"0.56\", \"size\":\"185.21\", \"side\":\"SELL\", \"hash\":\"f482dfdbd464f143df459e5ece3ca2547f13ceff\", \"best_bid\":\"0.45\", \"best_ask\":\"0.46\"}], \"timestamp\":\"1785130325022\", \"event_type\":\"price_change\"}","received_at":"2026-07-27T05:32:05.063957Z","schema_version":"clob-market-ws.price_change.v1","sequence":null,"server_hash":null,"server_timestamp":"1785130325022","session_id":"502006c5cfcd437296561ea750c9ec8b","source":"clob_market_ws"},"received_at":"2026-07-27T05:32:05.063957Z","record_id":"7a54e4c0882cb3de020735f1ea559ef3940da339b9ce1301cc613077e9a22030","schema_fingerprint":"4aa3821a28b0b7c2400bc59aba4bcc0a76e971dadd19610d3ad38c768e124dc7","schema_version":"edge-lab-recorder.raw.v1","sequence":null,"source":"clob_market_ws"}
{"event_at":"2026-07-27T05:32:05.022000Z","event_fingerprint":"fcdd8c11698ffed1ab76ea89ae5ad2cc934f1c9f53955bc415e2db5cfc51a766","payload":{"connection_id":"efc69d3132f1467b8e898a382b23ac0d","event_at":"2026-07-27T05:32:05.022000Z","event_type":"price_change","frame_hash":"2580d52eb444d1e2bb57f8e3eee16280b15c0b269b4e2c5930b4245e112dc7fe","frame_index":0,"kind":"data","monotonic_ns":232308305917875,"payload":{"event_type":"price_change","market":"0x3b40066b5cf3871a2f6237c5628bd8092a206aa998558ac5ec13c4483e31e160","price_changes":[{"asset_id":"14766054693214075530629349735273995982307625376442606753688071083149620216746","best_ask":"0.46","best_bid":"0.45","hash":"97ef403863c63ec62cdca7a43db426d39d304230","price":"0.01","side":"BUY","size":"7883.02"},{"asset_id":"110216635572655435074987471276357323571387854733835379371586402147734167783946","best_ask":"0.55","best_bid":"0.54","hash":"f1f78e4561eab0a9eab82476a4e0016bba49cb65","price":"0.99","side":"SELL","size":"7883.02"}],"timestamp":"1785130325022"},"payload_hash":"1ba7398c6d4e50d0ddb0be7f9c6dc47f61c0d44380afbec6dc9c155e508b9a3d","raw_frame":"{\"market\":\"0x3b40066b5cf3871a2f6237c5628bd8092a206aa998558ac5ec13c4483e31e160\", \"price_changes\":[{\"asset_id\":\"14766054693214075530629349735273995982307625376442606753688071083149620216746\", \"price\":\"0.01\", \"size\":\"7883.02\", \"side\":\"BUY\", \"hash\":\"97ef403863c63ec62cdca7a43db426d39d304230\", \"best_bid\":\"0.45\", \"best_ask\":\"0.46\"}, {\"asset_id\":\"110216635572655435074987471276357323571387854733835379371586402147734167783946\", \"price\":\"0.99\", \"size\":\"7883.02\", \"side\":\"SELL\", \"hash\":\"f1f78e4561eab0a9eab82476a4e0016bba49cb65\", \"best_bid\":\"0.54\", \"best_ask\":\"0.55\"}], \"timestamp\":\"1785130325022\", \"event_type\":\"price_change\"}","received_at":"2026-07-27T05:32:05.068578Z","schema_version":"clob-market-ws.price_change.v1","sequence":null,"server_hash":null,"server_timestamp":"1785130325022","session_id":"502006c5cfcd437296561ea750c9ec8b","source":"clob_market_ws"},"received_at":"2026-07-27T05:32:05.068578Z","record_id":"9f88c9539bc61e01d30429910c50148ccddadd6c5f65d82ad9b9df4488931bd4","schema_fingerprint":"4aa3821a28b0b7c2400bc59aba4bcc0a76e971dadd19610d3ad38c768e124dc7","schema_version":"edge-lab-recorder.raw.v1","sequence":null,"source":"clob_market_ws"}
{"event_at":"2026-07-27T05:32:05.023000Z","event_fingerprint":"bc1c7531c23351ad0e27b036d422b8519afdd838c0fba355bf6a2c97f9c8943c","payload":{"connection_id":"efc69d3132f1467b8e898a382b23ac0d","event_at":"2026-07-27T05:32:05.023000Z","event_type":"price_change","frame_hash":"98ef970f2ff2498af5908cb1e579f08a3dc1f988c14331bf14e1b91527f1975b","frame_index":0,"kind":"data","monotonic_ns":232308310482125,"payload":{"event_type":"price_change","market":"0x3b40066b5cf3871a2f6237c5628bd8092a206aa998558ac5ec13c4483e31e160","price_changes":[{"asset_id":"110216635572655435074987471276357323571387854733835379371586402147734167783946","best_ask":"0.55","best_bid":"0.54","hash":"76b7a0771d23f875d2be504fec0c7588ff7a6efe","price":"0.41","side":"BUY","size":"190.4"},{"asset_id":"14766054693214075530629349735273995982307625376442606753688071083149620216746","best_ask":"0.46","best_bid":"0.45","hash":"fb4f2e53d751b7b4755c18b93c9bd00d990f4301","price":"0.59","side":"SELL","size":"190.4"}],"timestamp":"1785130325023"},"payload_hash":"00fd335116f714ab813b2fcca8ccfe2c92b141aa1dc17f671dbb579687dfd805","raw_frame":"{\"market\":\"0x3b40066b5cf3871a2f6237c5628bd8092a206aa998558ac5ec13c4483e31e160\", \"price_changes\":[{\"asset_id\":\"110216635572655435074987471276357323571387854733835379371586402147734167783946\", \"price\":\"0.41\", \"size\":\"190.4\", \"side\":\"BUY\", \"hash\":\"76b7a0771d23f875d2be504fec0c7588ff7a6efe\", \"best_bid\":\"0.54\", \"best_ask\":\"0.55\"}, {\"asset_id\":\"14766054693214075530629349735273995982307625376442606753688071083149620216746\", \"price\":\"0.59\", \"size\":\"190.4\", \"side\":\"SELL\", \"hash\":\"fb4f2e53d751b7b4755c18b93c9bd00d990f4301\", \"best_bid\":\"0.45\", \"best_ask\":\"0.46\"}], \"timestamp\":\"1785130325023\", \"event_type\":\"price_change\"}","received_at":"2026-07-27T05:32:05.073141Z","schema_version":"clob-market-ws.price_change.v1","sequence":null,"server_hash":null,"server_timestamp":"1785130325023","session_id":"502006c5cfcd437296561ea750c9ec8b","source":"clob_market_ws"},"received_at":"2026-07-27T05:32:05.073141Z","record_id":"54c7ec7e9e62d2a261448382dc9e0399e3d4743a92c2f55f9757caaf99b09028","schema_fingerprint":"4aa3821a28b0b7c2400bc59aba4bcc0a76e971dadd19610d3ad38c768e124dc7","schema_version":"edge-lab-recorder.raw.v1","sequence":null,"source":"clob_market_ws"}
{"event_at":"2026-07-27T05:32:05.023000Z","event_fingerprint":"817cf955bad9d9394deee586d13159193e074322957ba73db3864e94b94eb116","payload":{"connection_id":"efc69d3132f1467b8e898a382b23ac0d","event_at":"2026-07-27T05:32:05.023000Z","event_type":"price_change","frame_hash":"7dac73d37931d8ee8611c054b39d9808e0ad03de0a78082bbe105b15a8f2318d","frame_index":0,"kind":"data","monotonic_ns":232308314845500,"payload":{"event_type":"price_change","market":"0x3b40066b5cf3871a2f6237c5628bd8092a206aa998558ac5ec13c4483e31e160","price_changes":[{"asset_id":"110216635572655435074987471276357323571387854733835379371586402147734167783946","best_ask":"0.55","best_bid":"0.54","hash":"cfe7d3a54ed209ddb440b9fcca76c4d4f5788e1a","price":"0.44","side":"BUY","size":"155.21"},{"asset_id":"14766054693214075530629349735273995982307625376442606753688071083149620216746","best_ask":"0.46","best_bid":"0.45","hash":"d5f1dc7bdac9b07f1bfe0f0c4f6533ba8de7255d","price":"0.56","side":"SELL","size":"155.21"}],"timestamp":"1785130325023"},"payload_hash":"43581effb9f4ed565a9da5af43aa076f674acb971e3c0ca9fe6420f85ffb415a","raw_frame":"{\"market\":\"0x3b40066b5cf3871a2f6237c5628bd8092a206aa998558ac5ec13c4483e31e160\", \"price_changes\":[{\"asset_id\":\"110216635572655435074987471276357323571387854733835379371586402147734167783946\", \"price\":\"0.44\", \"size\":\"155.21\", \"side\":\"BUY\", \"hash\":\"cfe7d3a54ed209ddb440b9fcca76c4d4f5788e1a\", \"best_bid\":\"0.54\", \"best_ask\":\"0.55\"}, {\"asset_id\":\"14766054693214075530629349735273995982307625376442606753688071083149620216746\", \"price\":\"0.56\", \"size\":\"155.21\", \"side\":\"SELL\", \"hash\":\"d5f1dc7bdac9b07f1bfe0f0c4f6533ba8de7255d\", \"best_bid\":\"0.45\", \"best_ask\":\"0.46\"}], \"timestamp\":\"1785130325023\", \"event_type\":\"price_change\"}","received_at":"2026-07-27T05:32:05.077505Z","schema_version":"clob-market-ws.price_change.v1","sequence":null,"server_hash":null,"server_timestamp":"1785130325023","session_id":"502006c5cfcd437296561ea750c9ec8b","source":"clob_market_ws"},"received_at":"2026-07-27T05:32:05.077505Z","record_id":"31e7c571e3e8b7806e0c02e69f6e79113e9a3872a7e2567d3b57764e8b88df1e","schema_fingerprint":"4aa3821a28b0b7c2400bc59aba4bcc0a76e971dadd19610d3ad38c768e124dc7","schema_version":"edge-lab-recorder.raw.v1","sequence":null,"source":"clob_market_ws"}
{"event_at":"2026-07-27T05:32:05.024000Z","event_fingerprint":"a963b19ebd5e977d559815947297268977b35f2865d62579051dd5cb27c02cfa","payload":{"connection_id":"efc69d3132f1467b8e898a382b23ac0d","event_at":"2026-07-27T05:32:05.024000Z","event_type":"price_change","frame_hash":"1f53b87100ccd83329fb753c9c1e080e4bf9bdfd5295dab11173d2df4a95ff2b","frame_index":0,"kind":"data","monotonic_ns":232308318249250,"payload":{"event_type":"price_change","market":"0x3b40066b5cf3871a2f6237c5628bd8092a206aa998558ac5ec13c4483e31e160","price_changes":[{"asset_id":"110216635572655435074987471276357323571387854733835379371586402147734167783946","best_ask":"0.55","best_bid":"0.54","hash":"58afed3f27b4154ff54beba4bbe3cf74efb37a54","price":"0.44","side":"BUY","size":"137.21"},{"asset_id":"14766054693214075530629349735273995982307625376442606753688071083149620216746","best_ask":"0.46","best_bid":"0.45","hash":"955a8bca280dfedda58be317b9f4aa01ea9da583","price":"0.56","side":"SELL","size":"137.21"}],"timestamp":"1785130325024"},"payload_hash":"011c0ef940118e0460a35f4a09f3867b3bbd42263602154878fb7b5dd42000ae","raw_frame":"{\"market\":\"0x3b40066b5cf3871a2f6237c5628bd8092a206aa998558ac5ec13c4483e31e160\", \"price_changes\":[{\"asset_id\":\"110216635572655435074987471276357323571387854733835379371586402147734167783946\", \"price\":\"0.44\", \"size\":\"137.21\", \"side\":\"BUY\", \"hash\":\"58afed3f27b4154ff54beba4bbe3cf74efb37a54\", \"best_bid\":\"0.54\", \"best_ask\":\"0.55\"}, {\"asset_id\":\"14766054693214075530629349735273995982307625376442606753688071083149620216746\", \"price\":\"0.56\", \"size\":\"137.21\", \"side\":\"SELL\", \"hash\":\"955a8bca280dfedda58be317b9f4aa01ea9da583\", \"best_bid\":\"0.45\", \"best_ask\":\"0.46\"}], \"timestamp\":\"1785130325024\", \"event_type\":\"price_change\"}","received_at":"2026-07-27T05:32:05.080907Z","schema_version":"clob-market-ws.price_change.v1","sequence":null,"server_hash":null,"server_timestamp":"1785130325024","session_id":"502006c5cfcd437296561ea750c9ec8b","source":"clob_market_ws"},"received_at":"2026-07-27T05:32:05.080907Z","record_id":"a6519a2fb9f61fc0dc70d1196ead282d0390ba27fcd3ef5061ab7344593b7e00","schema_fingerprint":"4aa3821a28b0b7c2400bc59aba4bcc0a76e971dadd19610d3ad38c768e124dc7","schema_version":"edge-lab-recorder.raw.v1","sequence":null,"source":"clob_market_ws"}
{"event_at":"2026-07-27T05:32:05.030000Z","event_fingerprint":"0ce2fa2ddffcbb42ed782b1c48a6acea4e855848465b546297ff42dd470f0a92","payload":{"connection_id":"efc69d3132f1467b8e898a382b23ac0d","event_at":"2026-07-27T05:32:05.030000Z","event_type":"price_change","frame_hash":"02d3b3b3022b1d32b4b91afa2695ed56f7f8f6668d57725f72ae29715fa8d358","frame_index":0,"kind":"data","monotonic_ns":232308322659333,"payload":{"event_type":"price_change","market":"0x3b40066b5cf3871a2f6237c5628bd8092a206aa998558ac5ec13c4483e31e160","price_changes":[{"asset_id":"110216635572655435074987471276357323571387854733835379371586402147734167783946","best_ask":"0.55","best_bid":"0.54","hash":"3a690438cc697969ec2de253fb59c18174b8bb00","price":"0.41","side":"BUY","size":"160.4"},{"asset_id":"14766054693214075530629349735273995982307625376442606753688071083149620216746","best_ask":"0.46","best_bid":"0.45","hash":"eaf9c0c9ff123c02cf45bcfac49a4752f645e22d","price":"0.59","side":"SELL","size":"160.4"}],"timestamp":"1785130325030"},"payload_hash":"c2ba0d4ad49518eb0cc0a303a24e964e6140a9c9f802bcf242ac5c1324f792a8","raw_frame":"{\"market\":\"0x3b40066b5cf3871a2f6237c5628bd8092a206aa998558ac5ec13c4483e31e160\", \"price_changes\":[{\"asset_id\":\"110216635572655435074987471276357323571387854733835379371586402147734167783946\", \"price\":\"0.41\", \"size\":\"160.4\", \"side\":\"BUY\", \"hash\":\"3a690438cc697969ec2de253fb59c18174b8bb00\", \"best_bid\":\"0.54\", \"best_ask\":\"0.55\"}, {\"asset_id\":\"14766054693214075530629349735273995982307625376442606753688071083149620216746\", \"price\":\"0.59\", \"size\":\"160.4\", \"side\":\"SELL\", \"hash\":\"eaf9c0c9ff123c02cf45bcfac49a4752f645e22d\", \"best_bid\":\"0.45\", \"best_ask\":\"0.46\"}], \"timestamp\":\"1785130325030\", \"event_type\":\"price_change\"}","received_at":"2026-07-27T05:32:05.085315Z","schema_version":"clob-market-ws.price_change.v1","sequence":null,"server_hash":null,"server_timestamp":"1785130325030","session_id":"502006c5cfcd437296561ea750c9ec8b","source":"clob_market_ws"},"received_at":"2026-07-27T05:32:05.085315Z","record_id":"b180bc22243bf67b3a6ba1b9e2d604d2f2da9f3da8ccbd8cfb951a5660968699","schema_fingerprint":"4aa3821a28b0b7c2400bc59aba4bcc0a76e971dadd19610d3ad38c768e124dc7","schema_version":"edge-lab-recorder.raw.v1","sequence":null,"source":"clob_market_ws"}
{"event_at":"2026-07-27T05:32:05.047000Z","event_fingerprint":"447b4d661dfbb44e12b7cf839ebbd88e563235b2d0e8562e27eb04f7951ea754","payload":{"connection_id":"efc69d3132f1467b8e898a382b23ac0d","event_at":"2026-07-27T05:32:05.047000Z","event_type":"price_change","frame_hash":"b127ea7970d4c850629f37d2093b1af892583d982547f1b1e5420db4ff5199bf","frame_index":0,"kind":"data","monotonic_ns":232308326170083,"payload":{"event_type":"price_change","market":"0x3b40066b5cf3871a2f6237c5628bd8092a206aa998558ac5ec13c4483e31e160","price_changes":[{"asset_id":"14766054693214075530629349735273995982307625376442606753688071083149620216746","best_ask":"0.46","best_bid":"0.45","hash":"d44f2163983bc49751a39a91d3b06d30f159359b","price":"0.01","side":"BUY","size":"7878.02"},{"asset_id":"110216635572655435074987471276357323571387854733835379371586402147734167783946","best_ask":"0.55","best_bid":"0.54","hash":"e00ec437490e10d0254e3bdb6217a205ea9993cb","price":"0.99","side":"SELL","size":"7878.02"}],"timestamp":"1785130325047"},"payload_hash":"5b4d73c09d283f28469fa444ec81b7bc48b18999fd8308a5d2a63b6970d8cee7","raw_frame":"{\"market\":\"0x3b40066b5cf3871a2f6237c5628bd8092a206aa998558ac5ec13c4483e31e160\", \"price_changes\":[{\"asset_id\":\"14766054693214075530629349735273995982307625376442606753688071083149620216746\", \"price\":\"0.01\", \"size\":\"7878.02\", \"side\":\"BUY\", \"hash\":\"d44f2163983bc49751a39a91d3b06d30f159359b\", \"best_bid\":\"0.45\", \"best_ask\":\"0.46\"}, {\"asset_id\":\"110216635572655435074987471276357323571387854733835379371586402147734167783946\", \"price\":\"0.99\", \"size\":\"7878.02\", \"side\":\"SELL\", \"hash\":\"e00ec437490e10d0254e3bdb6217a205ea9993cb\", \"best_bid\":\"0.54\", \"best_ask\":\"0.55\"}], \"timestamp\":\"1785130325047\", \"event_type\":\"price_change\"}","received_at":"2026-07-27T05:32:05.088830Z","schema_version":"clob-market-ws.price_change.v1","sequence":null,"server_hash":null,"server_timestamp":"1785130325047","session_id":"502006c5cfcd437296561ea750c9ec8b","source":"clob_market_ws"},"received_at":"2026-07-27T05:32:05.088830Z","record_id":"913bbed1da20e8a8b4b6e2446e691c347901de8b0d10b755f2b3e00fce413b7d","schema_fingerprint":"4aa3821a28b0b7c2400bc59aba4bcc0a76e971dadd19610d3ad38c768e124dc7","schema_version":"edge-lab-recorder.raw.v1","sequence":null,"source":"clob_market_ws"}
{"event_at":"2026-07-27T05:32:05.048000Z","event_fingerprint":"41c9c49aa65d9d68629a8743b67698b4c4eec53c502e7b54ff7b1fecb43112ff","payload":{"connection_id":"efc69d3132f1467b8e898a382b23ac0d","event_at":"2026-07-27T05:32:05.048000Z","event_type":"price_change","frame_hash":"5abc8e56fb9ace3df75bbb9e2c9802186bab202606f3a6e27d02adfc56c10e7a","frame_index":0,"kind":"data","monotonic_ns":232308329109625,"payload":{"event_type":"price_change","market":"0x3b40066b5cf3871a2f6237c5628bd8092a206aa998558ac5ec13c4483e31e160","price_changes":[{"asset_id":"110216635572655435074987471276357323571387854733835379371586402147734167783946","best_ask":"0.55","best_bid":"0.54","hash":"6b32ed4423e59da3e23e88daf1fc3e8b5abc018d","price":"0.4","side":"BUY","size":"220.5"},{"asset_id":"14766054693214075530629349735273995982307625376442606753688071083149620216746","best_ask":"0.46","best_bid":"0.45","hash":"3decc81e163436c40c5a32994c830e7da5d26245","price":"0.6","side":"SELL","size":"220.5"}],"timestamp":"1785130325048"},"payload_hash":"63a4edfa9b027d92511c58f6954a7a8255c7d04a0c68371e6b79774fdbec5fb5","raw_frame":"{\"market\":\"0x3b40066b5cf3871a2f6237c5628bd8092a206aa998558ac5ec13c4483e31e160\", \"price_changes\":[{\"asset_id\":\"110216635572655435074987471276357323571387854733835379371586402147734167783946\", \"price\":\"0.4\", \"size\":\"220.5\", \"side\":\"BUY\", \"hash\":\"6b32ed4423e59da3e23e88daf1fc3e8b5abc018d\", \"best_bid\":\"0.54\", \"best_ask\":\"0.55\"}, {\"asset_id\":\"14766054693214075530629349735273995982307625376442606753688071083149620216746\", \"price\":\"0.6\", \"size\":\"220.5\", \"side\":\"SELL\", \"hash\":\"3decc81e163436c40c5a32994c830e7da5d26245\", \"best_bid\":\"0.45\", \"best_ask\":\"0.46\"}], \"timestamp\":\"1785130325048\", \"event_type\":\"price_change\"}","received_at":"2026-07-27T05:32:05.091770Z","schema_version":"clob-market-ws.price_change.v1","sequence":null,"server_hash":null,"server_timestamp":"1785130325048","session_id":"502006c5cfcd437296561ea750c9ec8b","source":"clob_market_ws"},"received_at":"2026-07-27T05:32:05.091770Z","record_id":"971cf6bde795979f3817b8b987e8efbcfbd98229b44953afffc2d6a4bf939bef","schema_fingerprint":"4aa3821a28b0b7c2400bc59aba4bcc0a76e971dadd19610d3ad38c768e124dc7","schema_version":"edge-lab-recorder.raw.v1","sequence":null,"source":"clob_market_ws"}
{"event_at":"2026-07-27T05:32:05.051000Z","event_fingerprint":"62d974cf9448d5c75a64884c81a8b837049e91039907bab2d2b8bc0944460dea","payload":{"connection_id":"efc69d3132f1467b8e898a382b23ac0d","event_at":"2026-07-27T05:32:05.051000Z","event_type":"price_change","frame_hash":"92160d4539e85bc6d37d7959300b5599cf3543cbfac8186b4cccdf942fd5f3e7","frame_index":0,"kind":"data","monotonic_ns":232308333491166,"payload":{"event_type":"price_change","market":"0x3b40066b5cf3871a2f6237c5628bd8092a206aa998558ac5ec13c4483e31e160","price_changes":[{"asset_id":"110216635572655435074987471276357323571387854733835379371586402147734167783946","best_ask":"0.55","best_bid":"0.54","hash":"78588bfc689c4565815e56d84e8bf82080d0d91f","price":"0.01","side":"BUY","size":"7848.02"},{"asset_id":"14766054693214075530629349735273995982307625376442606753688071083149620216746","best_ask":"0.46","best_bid":"0.45","hash":"234551c3746d0e93060fc4bb2f299543ead112c0","price":"0.99","side":"SELL","size":"7848.02"}],"timestamp":"1785130325051"},"payload_hash":"2575ef4061fdfb75d152bc0f6edb87ded33c690b14bce6c9f046ed1777bac51c","raw_frame":"{\"market\":\"0x3b40066b5cf3871a2f6237c5628bd8092a206aa998558ac5ec13c4483e31e160\", \"price_changes\":[{\"asset_id\":\"110216635572655435074987471276357323571387854733835379371586402147734167783946\", \"price\":\"0.01\", \"size\":\"7848.02\", \"side\":\"BUY\", \"hash\":\"78588bfc689c4565815e56d84e8bf82080d0d91f\", \"best_bid\":\"0.54\", \"best_ask\":\"0.55\"}, {\"asset_id\":\"14766054693214075530629349735273995982307625376442606753688071083149620216746\", \"price\":\"0.99\", \"size\":\"7848.02\", \"side\":\"SELL\", \"hash\":\"234551c3746d0e93060fc4bb2f299543ead112c0\", \"best_bid\":\"0.45\", \"best_ask\":\"0.46\"}], \"timestamp\":\"1785130325051\", \"event_type\":\"price_change\"}","received_at":"2026-07-27T05:32:05.096151Z","schema_version":"clob-market-ws.price_change.v1","sequence":null,"server_hash":null,"server_timestamp":"1785130325051","session_id":"502006c5cfcd437296561ea750c9ec8b","source":"clob_market_ws"},"received_at":"2026-07-27T05:32:05.096151Z","record_id":"d38ffb60126c2667ea995c9b4daeec578668aeec4576f7fc8b1ca54cf82e1836","schema_fingerprint":"4aa3821a28b0b7c2400bc59aba4bcc0a76e971dadd19610d3ad38c768e124dc7","schema_version":"edge-lab-recorder.raw.v1","sequence":null,"source":"clob_market_ws"}
{"event_at":"2026-07-27T05:32:05.053000Z","event_fingerprint":"e70586ff29901ecbe70eac0aab1ed0304b6866cdbf32f99a7d4076cac221c8c7","payload":{"connection_id":"efc69d3132f1467b8e898a382b23ac0d","event_at":"2026-07-27T05:32:05.053000Z","event_type":"price_change","frame_hash":"2504fd7e3810b1f3d00eead09d48369147506c9725fcbbe476d0e8045e25fdda","frame_index":0,"kind":"data","monotonic_ns":232308335497625,"payload":{"event_type":"price_change","market":"0x3b40066b5cf3871a2f6237c5628bd8092a206aa998558ac5ec13c4483e31e160","price_changes":[{"asset_id":"110216635572655435074987471276357323571387854733835379371586402147734167783946","best_ask":"0.55","best_bid":"0.54","hash":"2b4fd15791043d5939930e120d9b243e418a8842","price":"0.43","side":"BUY","size":"173"},{"asset_id":"14766054693214075530629349735273995982307625376442606753688071083149620216746","best_ask":"0.46","best_bid":"0.45","hash":"75ce6f6baa7acd56c46deee5f03e9f8f0fbb9327","price":"0.57","side":"SELL","size":"173"}],"timestamp":"1785130325053"},"payload_hash":"d23463143ff37c61947b4931fc9b135b61007d750470aa9650649551501f0eba","raw_frame":"{\"market\":\"0x3b40066b5cf3871a2f6237c5628bd8092a206aa998558ac5ec13c4483e31e160\", \"price_changes\":[{\"asset_id\":\"110216635572655435074987471276357323571387854733835379371586402147734167783946\", \"price\":\"0.43\", \"size\":\"173\", \"side\":\"BUY\", \"hash\":\"2b4fd15791043d5939930e120d9b243e418a8842\", \"best_bid\":\"0.54\", \"best_ask\":\"0.55\"}, {\"asset_id\":\"14766054693214075530629349735273995982307625376442606753688071083149620216746\", \"price\":\"0.57\", \"size\":\"173\", \"side\":\"SELL\", \"hash\":\"75ce6f6baa7acd56c46deee5f03e9f8f0fbb9327\", \"best_bid\":\"0.45\", \"best_ask\":\"0.46\"}], \"timestamp\":\"1785130325053\", \"event_type\":\"price_change\"}","received_at":"2026-07-27T05:32:05.098157Z","schema_version":"clob-market-ws.price_change.v1","sequence":null,"server_hash":null,"server_timestamp":"1785130325053","session_id":"502006c5cfcd437296561ea750c9ec8b","source":"clob_market_ws"},"received_at":"2026-07-27T05:32:05.098157Z","record_id":"cd01a28c6a0565ab42e9ce8933b0965b9b5b46fffe01d46e8d3978fb87946b3e","schema_fingerprint":"4aa3821a28b0b7c2400bc59aba4bcc0a76e971dadd19610d3ad38c768e124dc7","schema_version":"edge-lab-recorder.raw.v1","sequence":null,"source":"clob_market_ws"}
{"event_at":"2026-07-27T05:32:05.054000Z","event_fingerprint":"02f5543d39bd9c14646d7a5e844eaafda45ddf2d50d58a86a42155d02585957a","payload":{"connection_id":"efc69d3132f1467b8e898a382b23ac0d","event_at":"2026-07-27T05:32:05.054000Z","event_type":"price_change","frame_hash":"1943306fdee73ba7d0aa42dc1d694bcd62743945d9997b452bd060366100d6e4","frame_index":0,"kind":"data","monotonic_ns":232308339810375,"payload":{"event_type":"price_change","market":"0x3b40066b5cf3871a2f6237c5628bd8092a206aa998558ac5ec13c4483e31e160","price_changes":[{"asset_id":"110216635572655435074987471276357323571387854733835379371586402147734167783946","best_ask":"0.55","best_bid":"0.54","hash":"7fe23b8585f534f7797bb9743c20b2998dce29cb","price":"0.43","side":"BUY","size":"191"},{"asset_id":"14766054693214075530629349735273995982307625376442606753688071083149620216746","best_ask":"0.46","best_bid":"0.45","hash":"a61c140dc8e87681b0c5831b9031f86d8e0d7cf8","price":"0.57","side":"SELL","size":"191"}],"timestamp":"1785130325054"},"payload_hash":"fca68b1b8e3df3968d4c82f4b0564ded020f81d5d6e55c596c89b328bdc43862","raw_frame":"{\"market\":\"0x3b40066b5cf3871a2f6237c5628bd8092a206aa998558ac5ec13c4483e31e160\", \"price_changes\":[{\"asset_id\":\"110216635572655435074987471276357323571387854733835379371586402147734167783946\", \"price\":\"0.43\", \"size\":\"191\", \"side\":\"BUY\", \"hash\":\"7fe23b8585f534f7797bb9743c20b2998dce29cb\", \"best_bid\":\"0.54\", \"best_ask\":\"0.55\"}, {\"asset_id\":\"14766054693214075530629349735273995982307625376442606753688071083149620216746\", \"price\":\"0.57\", \"size\":\"191\", \"side\":\"SELL\", \"hash\":\"a61c140dc8e87681b0c5831b9031f86d8e0d7cf8\", \"best_bid\":\"0.45\", \"best_ask\":\"0.46\"}], \"timestamp\":\"1785130325054\", \"event_type\":\"price_change\"}","received_at":"2026-07-27T05:32:05.102470Z","schema_version":"clob-market-ws.price_change.v1","sequence":null,"server_hash":null,"server_timestamp":"1785130325054","session_id":"502006c5cfcd437296561ea750c9ec8b","source":"clob_market_ws"},"received_at":"2026-07-27T05:32:05.102470Z","record_id":"bef4c66b65b3c7a1b7be3c9f286be081afc5e858945b316dd02d62b118e53ef4","schema_fingerprint":"4aa3821a28b0b7c2400bc59aba4bcc0a76e971dadd19610d3ad38c768e124dc7","schema_version":"edge-lab-recorder.raw.v1","sequence":null,"source":"clob_market_ws"}
{"event_at":"2026-07-27T05:32:05.055000Z","event_fingerprint":"897aa536ba4f9cd1116e7440ec38b8b5aaf6369e30211f3acf5c08e3f5ca44ff","payload":{"connection_id":"efc69d3132f1467b8e898a382b23ac0d","event_at":"2026-07-27T05:32:05.055000Z","event_type":"price_change","frame_hash":"ed92bb8ccd89aa1af86edc8c6831d00389fe07ef887165f786017d3242fa78a1","frame_index":0,"kind":"data","monotonic_ns":232308346525666,"payload":{"event_type":"price_change","market":"0x3b40066b5cf3871a2f6237c5628bd8092a206aa998558ac5ec13c4483e31e160","price_changes":[{"asset_id":"110216635572655435074987471276357323571387854733835379371586402147734167783946","best_ask":"0.55","best_bid":"0.54","hash":"589bd3ade7bf3ae21044fa63a9dff5a807f0f54f","price":"0.4","side":"BUY","size":"250.5"},{"asset_id":"14766054693214075530629349735273995982307625376442606753688071083149620216746","best_ask":"0.46","best_bid":"0.45","hash":"7bc5befb7e5997ccc7a7fe7d98c0dd1c0f22589b","price":"0.6","side":"SELL","size":"250.5"}],"timestamp":"1785130325055"},"payload_hash":"ab83c46687bc51cc982ecf2be66d4f3b9ccd4710e9e33afc8aebc40c444a760b","raw_frame":"{\"market\":\"0x3b40066b5cf3871a2f6237c5628bd8092a206aa998558ac5ec13c4483e31e160\", \"price_changes\":[{\"asset_id\":\"110216635572655435074987471276357323571387854733835379371586402147734167783946\", \"price\":\"0.4\", \"size\":\"250.5\", \"side\":\"BUY\", \"hash\":\"589bd3ade7bf3ae21044fa63a9dff5a807f0f54f\", \"best_bid\":\"0.54\", \"best_ask\":\"0.55\"}, {\"asset_id\":\"14766054693214075530629349735273995982307625376442606753688071083149620216746\", \"price\":\"0.6\", \"size\":\"250.5\", \"side\":\"SELL\", \"hash\":\"7bc5befb7e5997ccc7a7fe7d98c0dd1c0f22589b\", \"best_bid\":\"0.45\", \"best_ask\":\"0.46\"}], \"timestamp\":\"1785130325055\", \"event_type\":\"price_change\"}","received_at":"2026-07-27T05:32:05.109189Z","schema_version":"clob-market-ws.price_change.v1","sequence":null,"server_hash":null,"server_timestamp":"1785130325055","session_id":"502006c5cfcd437296561ea750c9ec8b","source":"clob_market_ws"},"received_at":"2026-07-27T05:32:05.109189Z","record_id":"511e333f331277b704620f262e96237eb4276d70a87eadb6df3dc7e86077a2f0","schema_fingerprint":"4aa3821a28b0b7c2400bc59aba4bcc0a76e971dadd19610d3ad38c768e124dc7","schema_version":"edge-lab-recorder.raw.v1","sequence":null,"source":"clob_market_ws"}
{"event_at":"2026-07-27T05:32:05.056000Z","event_fingerprint":"a5b8f0de565edfe40498b0b46c11e0888b719a94867cdd43cd4d7d9342306c42","payload":{"connection_id":"efc69d3132f1467b8e898a382b23ac0d","event_at":"2026-07-27T05:32:05.056000Z","event_type":"price_change","frame_hash":"3a0e2287114286f7bcf779932da0e6c82757fb1badf17a34dfe2b3ba1b732720","frame_index":0,"kind":"data","monotonic_ns":232308349978708,"payload":{"event_type":"price_change","market":"0x3b40066b5cf3871a2f6237c5628bd8092a206aa998558ac5ec13c4483e31e160","price_changes":[{"asset_id":"110216635572655435074987471276357323571387854733835379371586402147734167783946","best_ask":"0.55","best_bid":"0.54","hash":"8a10fd604850eff663d875f90d21512295be9bc4","price":"0.4","side":"BUY","size":"280.5"},{"asset_id":"14766054693214075530629349735273995982307625376442606753688071083149620216746","best_ask":"0.46","best_bid":"0.45","hash":"355888b25b1803ebe3314a52d4f94b69cb1aae95","price":"0.6","side":"SELL","size":"280.5"}],"timestamp":"1785130325056"},"payload_hash":"9cde44327cb793862f9037a33a4eeb3b2f8562d15b8f2cf7bce50f3b7ea137b7","raw_frame":"{\"market\":\"0x3b40066b5cf3871a2f6237c5628bd8092a206aa998558ac5ec13c4483e31e160\", \"price_changes\":[{\"asset_id\":\"110216635572655435074987471276357323571387854733835379371586402147734167783946\", \"price\":\"0.4\", \"size\":\"280.5\", \"side\":\"BUY\", \"hash\":\"8a10fd604850eff663d875f90d21512295be9bc4\", \"best_bid\":\"0.54\", \"best_ask\":\"0.55\"}, {\"asset_id\":\"14766054693214075530629349735273995982307625376442606753688071083149620216746\", \"price\":\"0.6\", \"size\":\"280.5\", \"side\":\"SELL\", \"hash\":\"355888b25b1803ebe3314a52d4f94b69cb1aae95\", \"best_bid\":\"0.45\", \"best_ask\":\"0.46\"}], \"timestamp\":\"1785130325056\", \"event_type\":\"price_change\"}","received_at":"2026-07-27T05:32:05.112642Z","schema_version":"clob-market-ws.price_change.v1","sequence":null,"server_hash":null,"server_timestamp":"1785130325056","session_id":"502006c5cfcd437296561ea750c9ec8b","source":"clob_market_ws"},"received_at":"2026-07-27T05:32:05.112642Z","record_id":"3b0d052ff242def7efc85764f98084a75d15c1de6d1765adbd31e171e9cbe4f7","schema_fingerprint":"4aa3821a28b0b7c2400bc59aba4bcc0a76e971dadd19610d3ad38c768e124dc7","schema_version":"edge-lab-recorder.raw.v1","sequence":null,"source":"clob_market_ws"}
{"event_at":"2026-07-27T05:32:05.056000Z","event_fingerprint":"ed82f6675c1b481d01ea8d43fa79b81564215936e6b44f9e99d70ce9abd80335","payload":{"connection_id":"efc69d3132f1467b8e898a382b23ac0d","event_at":"2026-07-27T05:32:05.056000Z","event_type":"price_change","frame_hash":"0b664569da63c78063c2dca5c66c677906e2f15ee0437331498af7b3aaf15638","frame_index":0,"kind":"data","monotonic_ns":232308352117791,"payload":{"event_type":"price_change","market":"0x3b40066b5cf3871a2f6237c5628bd8092a206aa998558ac5ec13c4483e31e160","price_changes":[{"asset_id":"14766054693214075530629349735273995982307625376442606753688071083149620216746","best_ask":"0.46","best_bid":"0.45","hash":"abdd35a6086fe69a8356d2e2e96c09ba10bb22a3","price":"0.01","side":"BUY","size":"7873.02"},{"asset_id":"110216635572655435074987471276357323571387854733835379371586402147734167783946","best_ask":"0.55","best_bid":"0.54","hash":"422835bd006e2ef978bd5aadf668cc15fc6e9b7b","price":"0.99","side":"SELL","size":"7873.02"}],"timestamp":"1785130325056"},"payload_hash":"32563e22ac21978bd385a2cce76c45e076e887be92ab7f49e2b822c4f6bbfcb0","raw_frame":"{\"market\":\"0x3b40066b5cf3871a2f6237c5628bd8092a206aa998558ac5ec13c4483e31e160\", \"price_changes\":[{\"asset_id\":\"14766054693214075530629349735273995982307625376442606753688071083149620216746\", \"price\":\"0.01\", \"size\":\"7873.02\", \"side\":\"BUY\", \"hash\":\"abdd35a6086fe69a8356d2e2e96c09ba10bb22a3\", \"best_bid\":\"0.45\", \"best_ask\":\"0.46\"}, {\"asset_id\":\"110216635572655435074987471276357323571387854733835379371586402147734167783946\", \"price\":\"0.99\", \"size\":\"7873.02\", \"side\":\"SELL\", \"hash\":\"422835bd006e2ef978bd5aadf668cc15fc6e9b7b\", \"best_bid\":\"0.54\", \"best_ask\":\"0.55\"}], \"timestamp\":\"1785130325056\", \"event_type\":\"price_change\"}","received_at":"2026-07-27T05:32:05.114776Z","schema_version":"clob-market-ws.price_change.v1","sequence":null,"server_hash":null,"server_timestamp":"1785130325056","session_id":"502006c5cfcd437296561ea750c9ec8b","source":"clob_market_ws"},"received_at":"2026-07-27T05:32:05.114776Z","record_id":"171f4d817b34ef8c76b44b9c40dd6f4c597d249842afff332cf6537cefe543ca","schema_fingerprint":"4aa3821a28b0b7c2400bc59aba4bcc0a76e971dadd19610d3ad38c768e124dc7","schema_version":"edge-lab-recorder.raw.v1","sequence":null,"source":"clob_market_ws"}
{"event_at":"2026-07-27T05:32:05.069000Z","event_fingerprint":"321c1f7c7ae4ca8c563f8a2b24fa69618fa458f38168b68b0c6040b3c25f4eef","payload":{"connection_id":"efc69d3132f1467b8e898a382b23ac0d","event_at":"2026-07-27T05:32:05.069000Z","event_type":"price_change","frame_hash":"bd38487805293371fbe0142f05d216f46719bca54b3bab44f456eef38f91afa0","frame_index":0,"kind":"data","monotonic_ns":232308362698416,"payload":{"event_type":"price_change","market":"0x3b40066b5cf3871a2f6237c5628bd8092a206aa998558ac5ec13c4483e31e160","price_changes":[{"asset_id":"110216635572655435074987471276357323571387854733835379371586402147734167783946","best_ask":"0.55","best_bid":"0.54","hash":"aed5d60820c98ae2c6d3ee0e5d9820662d56d3ba","price":"0.01","side":"BUY","size":"7843.02"},{"asset_id":"14766054693214075530629349735273995982307625376442606753688071083149620216746","best_ask":"0.46","best_bid":"0.45","hash":"f47fd67cff3f7175db48b76aed4a652728ae14ca","price":"0.99","side":"SELL","size":"7843.02"}],"timestamp":"1785130325069"},"payload_hash":"0891a7ccd95c92a507eb6bf5d1776ade4713833ebef954ed60ab8c8b37d5a7a6","raw_frame":"{\"market\":\"0x3b40066b5cf3871a2f6237c5628bd8092a206aa998558ac5ec13c4483e31e160\", \"price_changes\":[{\"asset_id\":\"110216635572655435074987471276357323571387854733835379371586402147734167783946\", \"price\":\"0.01\", \"size\":\"7843.02\", \"side\":\"BUY\", \"hash\":\"aed5d60820c98ae2c6d3ee0e5d9820662d56d3ba\", \"best_bid\":\"0.54\", \"best_ask\":\"0.55\"}, {\"asset_id\":\"14766054693214075530629349735273995982307625376442606753688071083149620216746\", \"price\":\"0.99\", \"size\":\"7843.02\", \"side\":\"SELL\", \"hash\":\"f47fd67cff3f7175db48b76aed4a652728ae14ca\", \"best_bid\":\"0.45\", \"best_ask\":\"0.46\"}], \"timestamp\":\"1785130325069\", \"event_type\":\"price_change\"}","received_at":"2026-07-27T05:32:05.125363Z","schema_version":"clob-market-ws.price_change.v1","sequence":null,"server_hash":null,"server_timestamp":"1785130325069","session_id":"502006c5cfcd437296561ea750c9ec8b","source":"clob_market_ws"},"received_at":"2026-07-27T05:32:05.125363Z","record_id":"be0b598993f5b2ce1aecdd6ef3be1e79320a9fcc3a9864e4aa28114d8a95307b","schema_fingerprint":"4aa3821a28b0b7c2400bc59aba4bcc0a76e971dadd19610d3ad38c768e124dc7","schema_version":"edge-lab-recorder.raw.v1","sequence":null,"source":"clob_market_ws"}
{"event_at":"2026-07-27T05:32:05.074000Z","event_fingerprint":"7e05b19c08f47228bf9cbe036447ac0beb8acad90f8f0fe30ea14aea01f41649","payload":{"connection_id":"efc69d3132f1467b8e898a382b23ac0d","event_at":"2026-07-27T05:32:05.074000Z","event_type":"price_change","frame_hash":"91e1a0ab8cdffbcd74372a963cad9d4db55fb8ec7e8ede1bb996acac0df492e9","frame_index":0,"kind":"data","monotonic_ns":232308366212458,"payload":{"event_type":"price_change","market":"0x3b40066b5cf3871a2f6237c5628bd8092a206aa998558ac5ec13c4483e31e160","price_changes":[{"asset_id":"110216635572655435074987471276357323571387854733835379371586402147734167783946","best_ask":"0.55","best_bid":"0.54","hash":"39ab5a83d41c4039e99c9c13c36cb5c558e85d77","price":"0.43","side":"BUY","size":"221"},{"asset_id":"14766054693214075530629349735273995982307625376442606753688071083149620216746","best_ask":"0.46","best_bid":"0.45","hash":"2fa2fbd912db043313f2b96931a1f6b6e9081178","price":"0.57","side":"SELL","size":"221"}],"timestamp":"1785130325074"},"payload_hash":"57f5340b5e38dc125c3074bb9d29f7247bf3dd61cf5152c087ca8d2c35e43dab","raw_frame":"{\"market\":\"0x3b40066b5cf3871a2f6237c5628bd8092a206aa998558ac5ec13c4483e31e160\", \"price_changes\":[{\"asset_id\":\"110216635572655435074987471276357323571387854733835379371586402147734167783946\", \"price\":\"0.43\", \"size\":\"221\", \"side\":\"BUY\", \"hash\":\"39ab5a83d41c4039e99c9c13c36cb5c558e85d77\", \"best_bid\":\"0.54\", \"best_ask\":\"0.55\"}, {\"asset_id\":\"14766054693214075530629349735273995982307625376442606753688071083149620216746\", \"price\":\"0.57\", \"size\":\"221\", \"side\":\"SELL\", \"hash\":\"2fa2fbd912db043313f2b96931a1f6b6e9081178\", \"best_bid\":\"0.45\", \"best_ask\":\"0.46\"}], \"timestamp\":\"1785130325074\", \"event_type\":\"price_change\"}","received_at":"2026-07-27T05:32:05.128872Z","schema_version":"clob-market-ws.price_change.v1","sequence":null,"server_hash":null,"server_timestamp":"1785130325074","session_id":"502006c5cfcd437296561ea750c9ec8b","source":"clob_market_ws"},"received_at":"2026-07-27T05:32:05.128872Z","record_id":"29618c7f29639825fea99f4cf642f5574ba0e564e45d8ed71dea08a18826583f","schema_fingerprint":"4aa3821a28b0b7c2400bc59aba4bcc0a76e971dadd19610d3ad38c768e124dc7","schema_version":"edge-lab-recorder.raw.v1","sequence":null,"source":"clob_market_ws"}
{"event_at":"2026-07-27T05:32:05.079000Z","event_fingerprint":"63a0a6ee65afb4711fc5e7f58caa8479653e5dc20bc49fd59473995385155ab2","payload":{"connection_id":"efc69d3132f1467b8e898a382b23ac0d","event_at":"2026-07-27T05:32:05.079000Z","event_type":"price_change","frame_hash":"df888073ef9ec8235d78f3a173a05819e10090804743255d7dde7bc886021b90","frame_index":0,"kind":"data","monotonic_ns":232308369082250,"payload":{"event_type":"price_change","market":"0x3b40066b5cf3871a2f6237c5628bd8092a206aa998558ac5ec13c4483e31e160","price_changes":[{"asset_id":"110216635572655435074987471276357323571387854733835379371586402147734167783946","best_ask":"0.55","best_bid":"0.54","hash":"ed79bebe3483e523437f239442f492cb59b341cb","price":"0.5","side":"BUY","size":"59.4"},{"asset_id":"14766054693214075530629349735273995982307625376442606753688071083149620216746","best_ask":"0.46","best_bid":"0.45","hash":"925198e2968d508bcf04c8e73fd418b42823932b","price":"0.5","side":"SELL","size":"59.4"}],"timestamp":"1785130325079"},"payload_hash":"d65d1842a85f4338bc3ddb79cc2c5b0b5e6c02b2de6be9d3387ea610a4a50663","raw_frame":"{\"market\":\"0x3b40066b5cf3871a2f6237c5628bd8092a206aa998558ac5ec13c4483e31e160\", \"price_changes\":[{\"asset_id\":\"110216635572655435074987471276357323571387854733835379371586402147734167783946\", \"price\":\"0.5\", \"size\":\"59.4\", \"side\":\"BUY\", \"hash\":\"ed79bebe3483e523437f239442f492cb59b341cb\", \"best_bid\":\"0.54\", \"best_ask\":\"0.55\"}, {\"asset_id\":\"14766054693214075530629349735273995982307625376442606753688071083149620216746\", \"price\":\"0.5\", \"size\":\"59.4\", \"side\":\"SELL\", \"hash\":\"925198e2968d508bcf04c8e73fd418b42823932b\", \"best_bid\":\"0.45\", \"best_ask\":\"0.46\"}], \"timestamp\":\"1785130325079\", \"event_type\":\"price_change\"}","received_at":"2026-07-27T05:32:05.131742Z","schema_version":"clob-market-ws.price_change.v1","sequence":null,"server_hash":null,"server_timestamp":"1785130325079","session_id":"502006c5cfcd437296561ea750c9ec8b","source":"clob_market_ws"},"received_at":"2026-07-27T05:32:05.131742Z","record_id":"9cb3a63b23c31d09e4e41f67e11fd4eba13a71ee469e2e322cc792d7421015a7","schema_fingerprint":"4aa3821a28b0b7c2400bc59aba4bcc0a76e971dadd19610d3ad38c768e124dc7","schema_version":"edge-lab-recorder.raw.v1","sequence":null,"source":"clob_market_ws"}
{"event_at":"2026-07-27T05:32:05.084000Z","event_fingerprint":"2a91d05bdb62c7eed16400c9725dafb0eea6668f9dfef6cfe3cfb3686c3bf767","payload":{"connection_id":"efc69d3132f1467b8e898a382b23ac0d","event_at":"2026-07-27T05:32:05.084000Z","event_type":"price_change","frame_hash":"db74aed2bf3eb40bbc4bbe246d4743505e15b06797257c5aba39859da884ff8e","frame_index":0,"kind":"data","monotonic_ns":232308373428791,"payload":{"event_type":"price_change","market":"0x3b40066b5cf3871a2f6237c5628bd8092a206aa998558ac5ec13c4483e31e160","price_changes":[{"asset_id":"14766054693214075530629349735273995982307625376442606753688071083149620216746","best_ask":"0.46","best_bid":"0.45","hash":"9c3817083c09d606dc98f32e0996eddccac83a7f","price":"0.5","side":"SELL","size":"66.4"},{"asset_id":"110216635572655435074987471276357323571387854733835379371586402147734167783946","best_ask":"0.55","best_bid":"0.54","hash":"4ebf6ce884c6b1002478f5bef5015ded365f0d2f","price":"0.5","side":"BUY","size":"66.4"}],"timestamp":"1785130325084"},"payload_hash":"c5394535fa9e6223af5c3aebf011637539e5da1f570018d61c1c2a9e1b6976e9","raw_frame":"{\"market\":\"0x3b40066b5cf3871a2f6237c5628bd8092a206aa998558ac5ec13c4483e31e160\", \"price_changes\":[{\"asset_id\":\"14766054693214075530629349735273995982307625376442606753688071083149620216746\", \"price\":\"0.5\", \"size\":\"66.4\", \"side\":\"SELL\", \"hash\":\"9c3817083c09d606dc98f32e0996eddccac83a7f\", \"best_bid\":\"0.45\", \"best_ask\":\"0.46\"}, {\"asset_id\":\"110216635572655435074987471276357323571387854733835379371586402147734167783946\", \"price\":\"0.5\", \"size\":\"66.4\", \"side\":\"BUY\", \"hash\":\"4ebf6ce884c6b1002478f5bef5015ded365f0d2f\", \"best_bid\":\"0.54\", \"best_ask\":\"0.55\"}], \"timestamp\":\"1785130325084\", \"event_type\":\"price_change\"}","received_at":"2026-07-27T05:32:05.136086Z","schema_version":"clob-market-ws.price_change.v1","sequence":null,"server_hash":null,"server_timestamp":"1785130325084","session_id":"502006c5cfcd437296561ea750c9ec8b","source":"clob_market_ws"},"received_at":"2026-07-27T05:32:05.136086Z","record_id":"b7e3a56230270cb7de0956fae4cb0710f39779f8fcd96a37146a546e85a633dc","schema_fingerprint":"4aa3821a28b0b7c2400bc59aba4bcc0a76e971dadd19610d3ad38c768e124dc7","schema_version":"edge-lab-recorder.raw.v1","sequence":null,"source":"clob_market_ws"}
{"event_at":"2026-07-27T05:32:05.103000Z","event_fingerprint":"e917522df0c319eb30a690ab55a5c495a412d99108d7317165dcb6a80c1244e0","payload":{"connection_id":"efc69d3132f1467b8e898a382b23ac0d","event_at":"2026-07-27T05:32:05.103000Z","event_type":"price_change","frame_hash":"eb1e5c9d915b17aa57550127664141c8c153814e1a6bf1080d751cd9e50169a7","frame_index":0,"kind":"data","monotonic_ns":232308377850958,"payload":{"event_type":"price_change","market":"0x3b40066b5cf3871a2f6237c5628bd8092a206aa998558ac5ec13c4483e31e160","price_changes":[{"asset_id":"110216635572655435074987471276357323571387854733835379371586402147734167783946","best_ask":"0.55","best_bid":"0.54","hash":"0543ff9bb6cf51016eb04f8c3b1e34cf4e427bd2","price":"0.04","side":"BUY","size":"633.09"},{"asset_id":"14766054693214075530629349735273995982307625376442606753688071083149620216746","best_ask":"0.46","best_bid":"0.45","hash":"d017d780629c25efc4b006620e332de3933bd41d","price":"0.96","side":"SELL","size":"633.09"}],"timestamp":"1785130325103"},"payload_hash":"6b8b8e40ae254cd60486b3f052c58dee21fbb334009c33a8d0ba449b3891e03d","raw_frame":"{\"market\":\"0x3b40066b5cf3871a2f6237c5628bd8092a206aa998558ac5ec13c4483e31e160\", \"price_changes\":[{\"asset_id\":\"110216635572655435074987471276357323571387854733835379371586402147734167783946\", \"price\":\"0.04\", \"size\":\"633.09\", \"side\":\"BUY\", \"hash\":\"0543ff9bb6cf51016eb04f8c3b1e34cf4e427bd2\", \"best_bid\":\"0.54\", \"best_ask\":\"0.55\"}, {\"asset_id\":\"14766054693214075530629349735273995982307625376442606753688071083149620216746\", \"price\":\"0.96\", \"size\":\"633.09\", \"side\":\"SELL\", \"hash\":\"d017d780629c25efc4b006620e332de3933bd41d\", \"best_bid\":\"0.45\", \"best_ask\":\"0.46\"}], \"timestamp\":\"1785130325103\", \"event_type\":\"price_change\"}","received_at":"2026-07-27T05:32:05.140508Z","schema_version":"clob-market-ws.price_change.v1","sequence":null,"server_hash":null,"server_timestamp":"1785130325103","session_id":"502006c5cfcd437296561ea750c9ec8b","source":"clob_market_ws"},"received_at":"2026-07-27T05:32:05.140508Z","record_id":"0d5a005ec60e5caa37262ee36da47706a4211e981e9990e8a905e0d3d1540f7b","schema_fingerprint":"4aa3821a28b0b7c2400bc59aba4bcc0a76e971dadd19610d3ad38c768e124dc7","schema_version":"edge-lab-recorder.raw.v1","sequence":null,"source":"clob_market_ws"}
{"event_at":"2026-07-27T05:32:05.162000Z","event_fingerprint":"b74747229bc79519ba01595d7b6c6353e4e56c0144f7828a19a663b60283dc56","payload":{"connection_id":"efc69d3132f1467b8e898a382b23ac0d","event_at":"2026-07-27T05:32:05.162000Z","event_type":"price_change","frame_hash":"313b8006054f69adc4593782ed67c1464abfd1ae53d6a22a369e83697d68d3b4","frame_index":0,"kind":"data","monotonic_ns":232308384343166,"payload":{"event_type":"price_change","market":"0x3b40066b5cf3871a2f6237c5628bd8092a206aa998558ac5ec13c4483e31e160","price_changes":[{"asset_id":"110216635572655435074987471276357323571387854733835379371586402147734167783946","best_ask":"0.55","best_bid":"0.54","hash":"361d08e6effb5fa87f35768b3027e304f69c5b53","price":"0.04","side":"BUY","size":"628.09"},{"asset_id":"14766054693214075530629349735273995982307625376442606753688071083149620216746","best_ask":"0.46","best_bid":"0.45","hash":"b4384881d3c74bb5d1623a13ea1df08c1ec519bf","price":"0.96","side":"SELL","size":"628.09"}],"timestamp":"1785130325162"},"payload_hash":"f1bbf2147a44cffa5c38a3ce320bc766bb05890ce014bc83970bf4cc559adc81","raw_frame":"{\"market\":\"0x3b40066b5cf3871a2f6237c5628bd8092a206aa998558ac5ec13c4483e31e160\", \"price_changes\":[{\"asset_id\":\"110216635572655435074987471276357323571387854733835379371586402147734167783946\", \"price\":\"0.04\", \"size\":\"628.09\", \"side\":\"BUY\", \"hash\":\"361d08e6effb5fa87f35768b3027e304f69c5b53\", \"best_bid\":\"0.54\", \"best_ask\":\"0.55\"}, {\"asset_id\":\"14766054693214075530629349735273995982307625376442606753688071083149620216746\", \"price\":\"0.96\", \"size\":\"628.09\", \"side\":\"SELL\", \"hash\":\"b4384881d3c74bb5d1623a13ea1df08c1ec519bf\", \"best_bid\":\"0.45\", \"best_ask\":\"0.46\"}], \"timestamp\":\"1785130325162\", \"event_type\":\"price_change\"}","received_at":"2026-07-27T05:32:05.147009Z","schema_version":"clob-market-ws.price_change.v1","sequence":null,"server_hash":null,"server_timestamp":"1785130325162","session_id":"502006c5cfcd437296561ea750c9ec8b","source":"clob_market_ws"},"received_at":"2026-07-27T05:32:05.147009Z","record_id":"b8f5900b8b882cb139fbec76fa4e140a76e07dc11dc637aa59b62382af7db1ba","schema_fingerprint":"4aa3821a28b0b7c2400bc59aba4bcc0a76e971dadd19610d3ad38c768e124dc7","schema_version":"edge-lab-recorder.raw.v1","sequence":null,"source":"clob_market_ws"}
{"event_at":"2026-07-27T05:32:05.187000Z","event_fingerprint":"4618a5237d79c041927d53d799019ae606c2a58bb78defa80343e09c1ab1a550","payload":{"connection_id":"efc69d3132f1467b8e898a382b23ac0d","event_at":"2026-07-27T05:32:05.187000Z","event_type":"price_change","frame_hash":"56f18a2673a20f0299dbf2b812b1e64b25d7cfd9e54a799bb910a4a9c52d00ae","frame_index":0,"kind":"data","monotonic_ns":232308386913166,"payload":{"event_type":"price_change","market":"0x3b40066b5cf3871a2f6237c5628bd8092a206aa998558ac5ec13c4483e31e160","price_changes":[{"asset_id":"110216635572655435074987471276357323571387854733835379371586402147734167783946","best_ask":"0.55","best_bid":"0.54","hash":"70a302f6a6d95eab0d29f7030fb2f26d41dfe1ed","price":"0.5","side":"BUY","size":"72.4"},{"asset_id":"14766054693214075530629349735273995982307625376442606753688071083149620216746","best_ask":"0.46","best_bid":"0.45","hash":"19b2eb37c8673f56e0463db8787d27d9e38d2e99","price":"0.5","side":"SELL","size":"72.4"}],"timestamp":"1785130325187"},"payload_hash":"145f1c667fcf9d8e783669b97e539558c247818c20ffa32c29de2c31d8e951b8","raw_frame":"{\"market\":\"0x3b40066b5cf3871a2f6237c5628bd8092a206aa998558ac5ec13c4483e31e160\", \"price_changes\":[{\"asset_id\":\"110216635572655435074987471276357323571387854733835379371586402147734167783946\", \"price\":\"0.5\", \"size\":\"72.4\", \"side\":\"BUY\", \"hash\":\"70a302f6a6d95eab0d29f7030fb2f26d41dfe1ed\", \"best_bid\":\"0.54\", \"best_ask\":\"0.55\"}, {\"asset_id\":\"14766054693214075530629349735273995982307625376442606753688071083149620216746\", \"price\":\"0.5\", \"size\":\"72.4\", \"side\":\"SELL\", \"hash\":\"19b2eb37c8673f56e0463db8787d27d9e38d2e99\", \"best_bid\":\"0.45\", \"best_ask\":\"0.46\"}], \"timestamp\":\"1785130325187\", \"event_type\":\"price_change\"}","received_at":"2026-07-27T05:32:05.149574Z","schema_version":"clob-market-ws.price_change.v1","sequence":null,"server_hash":null,"server_timestamp":"1785130325187","session_id":"502006c5cfcd437296561ea750c9ec8b","source":"clob_market_ws"},"received_at":"2026-07-27T05:32:05.149574Z","record_id":"d60b87a92cf8951cdfcf81bc87fee8e05283054e334bf87583d2fae140e29a4f","schema_fingerprint":"4aa3821a28b0b7c2400bc59aba4bcc0a76e971dadd19610d3ad38c768e124dc7","schema_version":"edge-lab-recorder.raw.v1","sequence":null,"source":"clob_market_ws"}
{"event_at":"2026-07-27T05:32:05.233000Z","event_fingerprint":"3c1809aed850dc15b8d007119661876d7af225ca411f512df46c8c57704cc634","payload":{"connection_id":"efc69d3132f1467b8e898a382b23ac0d","event_at":"2026-07-27T05:32:05.233000Z","event_type":"price_change","frame_hash":"12ee59e7a13a7dd5752a7d451807ef8b428eeb94b76fcc3982dbffbce98df2a6","frame_index":0,"kind":"data","monotonic_ns":232308433775833,"payload":{"event_type":"price_change","market":"0x3b40066b5cf3871a2f6237c5628bd8092a206aa998558ac5ec13c4483e31e160","price_changes":[{"asset_id":"110216635572655435074987471276357323571387854733835379371586402147734167783946","best_ask":"0.55","best_bid":"0.54","hash":"547ca6f3adaeb7be490290fd855460feee82a097","price":"0.55","side":"SELL","size":"41.4"},{"asset_id":"14766054693214075530629349735273995982307625376442606753688071083149620216746","best_ask":"0.46","best_bid":"0.45","hash":"f47573bdbf5fdc67190ae7dd49dacd58ea27ba96","price":"0.45","side":"BUY","size":"41.4"}],"timestamp":"1785130325233"},"payload_hash":"051e81a3d4d0af74ff775cf9bab5c269509b5553b0654069df8b868c3a676df9","raw_frame":"{\"market\":\"0x3b40066b5cf3871a2f6237c5628bd8092a206aa998558ac5ec13c4483e31e160\", \"price_changes\":[{\"asset_id\":\"110216635572655435074987471276357323571387854733835379371586402147734167783946\", \"price\":\"0.55\", \"size\":\"41.4\", \"side\":\"SELL\", \"hash\":\"547ca6f3adaeb7be490290fd855460feee82a097\", \"best_bid\":\"0.54\", \"best_ask\":\"0.55\"}, {\"asset_id\":\"14766054693214075530629349735273995982307625376442606753688071083149620216746\", \"price\":\"0.45\", \"size\":\"41.4\", \"side\":\"BUY\", \"hash\":\"f47573bdbf5fdc67190ae7dd49dacd58ea27ba96\", \"best_bid\":\"0.45\", \"best_ask\":\"0.46\"}], \"timestamp\":\"1785130325233\", \"event_type\":\"price_change\"}","received_at":"2026-07-27T05:32:05.196435Z","schema_version":"clob-market-ws.price_change.v1","sequence":null,"server_hash":null,"server_timestamp":"1785130325233","session_id":"502006c5cfcd437296561ea750c9ec8b","source":"clob_market_ws"},"received_at":"2026-07-27T05:32:05.196435Z","record_id":"845f48e4cd05e23c3d5eb5421639e95babdc0ea6e69f39ba4fe983fda7e396b3","schema_fingerprint":"4aa3821a28b0b7c2400bc59aba4bcc0a76e971dadd19610d3ad38c768e124dc7","schema_version":"edge-lab-recorder.raw.v1","sequence":null,"source":"clob_market_ws"}
{"event_at":"2026-07-27T05:32:05.256000Z","event_fingerprint":"4531a694caa2adf9f92e664cc335988b3289023688144659567ce8a0f03e63a5","payload":{"connection_id":"efc69d3132f1467b8e898a382b23ac0d","event_at":"2026-07-27T05:32:05.256000Z","event_type":"price_change","frame_hash":"979740d681d3bfe101c1b0941ba7efbc749b02f802a4dbceb2224f03703be000","frame_index":0,"kind":"data","monotonic_ns":232308454259500,"payload":{"event_type":"price_change","market":"0x3b40066b5cf3871a2f6237c5628bd8092a206aa998558ac5ec13c4483e31e160","price_changes":[{"asset_id":"110216635572655435074987471276357323571387854733835379371586402147734167783946","best_ask":"0.55","best_bid":"0.54","hash":"bbc31f626c6e0b7b18fd6a5d0177999e218b6a7b","price":"0.01","side":"BUY","size":"7848.02"},{"asset_id":"14766054693214075530629349735273995982307625376442606753688071083149620216746","best_ask":"0.46","best_bid":"0.45","hash":"81a9ba4759d1d956f8d808bd2bc4e04f6b67f123","price":"0.99","side":"SELL","size":"7848.02"}],"timestamp":"1785130325256"},"payload_hash":"e8cf7ba324944acc7d3277e66077ac1c1d7de9a9eadf53fad59c2dfc98e9bc42","raw_frame":"{\"market\":\"0x3b40066b5cf3871a2f6237c5628bd8092a206aa998558ac5ec13c4483e31e160\", \"price_changes\":[{\"asset_id\":\"110216635572655435074987471276357323571387854733835379371586402147734167783946\", \"price\":\"0.01\", \"size\":\"7848.02\", \"side\":\"BUY\", \"hash\":\"bbc31f626c6e0b7b18fd6a5d0177999e218b6a7b\", \"best_bid\":\"0.54\", \"best_ask\":\"0.55\"}, {\"asset_id\":\"14766054693214075530629349735273995982307625376442606753688071083149620216746\", \"price\":\"0.99\", \"size\":\"7848.02\", \"side\":\"SELL\", \"hash\":\"81a9ba4759d1d956f8d808bd2bc4e04f6b67f123\", \"best_bid\":\"0.45\", \"best_ask\":\"0.46\"}], \"timestamp\":\"1785130325256\", \"event_type\":\"price_change\"}","received_at":"2026-07-27T05:32:05.216925Z","schema_version":"clob-market-ws.price_change.v1","sequence":null,"server_hash":null,"server_timestamp":"1785130325256","session_id":"502006c5cfcd437296561ea750c9ec8b","source":"clob_market_ws"},"received_at":"2026-07-27T05:32:05.216925Z","record_id":"b08c335e3fdc25f5965eb395e36cef0bf6740c8406a50702f61fcfa5e23c80fb","schema_fingerprint":"4aa3821a28b0b7c2400bc59aba4bcc0a76e971dadd19610d3ad38c768e124dc7","schema_version":"edge-lab-recorder.raw.v1","sequence":null,"source":"clob_market_ws"}
{"event_at":null,"event_fingerprint":"d8602083d0882474786ceab514d80b43977d146f59c2405987c319eccaf66ed6","payload":{"connection_id":"efc69d3132f1467b8e898a382b23ac0d","detail":{"interval_seconds":10.0,"message":"PING"},"event_type":"heartbeat","kind":"lifecycle","monotonic_ns":232308469617458,"received_at":"2026-07-27T05:32:05.232283Z","schema_version":"edge-lab-recorder.lifecycle.v1","session_id":"502006c5cfcd437296561ea750c9ec8b","source":"clob_market_ws"},"received_at":"2026-07-27T05:32:05.232283Z","record_id":"1eb647a7c369616a50b4fbb8a90692dc304963f2dc3870ae4e8880e768d453a1","schema_fingerprint":"cb8aa3aa4cb168a4b724fd9077bee6ecfb9bc586c57cfdf0ab89f00d82045e3c","schema_version":"edge-lab-recorder.raw.v1","sequence":null,"source":"clob_market_ws"}
{"event_at":"2026-07-27T05:32:05.274000Z","event_fingerprint":"14775792fbaf601280406e3dc3c3d57b7db7e6c9d79a492dce24cdd7f5c3871f","payload":{"connection_id":"efc69d3132f1467b8e898a382b23ac0d","event_at":"2026-07-27T05:32:05.274000Z","event_type":"price_change","frame_hash":"b1836f48ce74f3093f428b2e778b17fb92de33b7ae690852f92b3b2aeb404ff0","frame_index":0,"kind":"data","monotonic_ns":232308472960583,"payload":{"event_type":"price_change","market":"0x3b40066b5cf3871a2f6237c5628bd8092a206aa998558ac5ec13c4483e31e160","price_changes":[{"asset_id":"110216635572655435074987471276357323571387854733835379371586402147734167783946","best_ask":"0.55","best_bid":"0.54","hash":"57d5d9dea48f25986a567a3a0d834164c478b1a6","price":"0.43","side":"BUY","size":"191"},{"asset_id":"14766054693214075530629349735273995982307625376442606753688071083149620216746","best_ask":"0.46","best_bid":"0.45","hash":"2c4add153606d6740a20292be6c49ce92cbe147d","price":"0.57","side":"SELL","size":"191"}],"timestamp":"1785130325274"},"payload_hash":"6d366fc45191034871598fe5746f8257528f1a08ff7cc95f04ce3cf99d172335","raw_frame":"{\"market\":\"0x3b40066b5cf3871a2f6237c5628bd8092a206aa998558ac5ec13c4483e31e160\", \"price_changes\":[{\"asset_id\":\"110216635572655435074987471276357323571387854733835379371586402147734167783946\", \"price\":\"0.43\", \"size\":\"191\", \"side\":\"BUY\", \"hash\":\"57d5d9dea48f25986a567a3a0d834164c478b1a6\", \"best_bid\":\"0.54\", \"best_ask\":\"0.55\"}, {\"asset_id\":\"14766054693214075530629349735273995982307625376442606753688071083149620216746\", \"price\":\"0.57\", \"size\":\"191\", \"side\":\"SELL\", \"hash\":\"2c4add153606d6740a20292be6c49ce92cbe147d\", \"best_bid\":\"0.45\", \"best_ask\":\"0.46\"}], \"timestamp\":\"1785130325274\", \"event_type\":\"price_change\"}","received_at":"2026-07-27T05:32:05.235624Z","schema_version":"clob-market-ws.price_change.v1","sequence":null,"server_hash":null,"server_timestamp":"1785130325274","session_id":"502006c5cfcd437296561ea750c9ec8b","source":"clob_market_ws"},"received_at":"2026-07-27T05:32:05.235624Z","record_id":"7b8d1507097821a93dd1e59fd624cb70b50fb93fe2c2b194ff2220fb1ca96cb0","schema_fingerprint":"4aa3821a28b0b7c2400bc59aba4bcc0a76e971dadd19610d3ad38c768e124dc7","schema_version":"edge-lab-recorder.raw.v1","sequence":null,"source":"clob_market_ws"}
{"event_at":"2026-07-27T05:32:05.274000Z","event_fingerprint":"12cd5bbf319f41454251234bd0c9011b8d501b80484857a34c01df31c8c6201b","payload":{"connection_id":"efc69d3132f1467b8e898a382b23ac0d","event_at":"2026-07-27T05:32:05.274000Z","event_type":"price_change","frame_hash":"c40596fb39e953303e4b65040e22173c73a094a20a5e4b78a70a077c0de23aed","frame_index":0,"kind":"data","monotonic_ns":232308474214000,"payload":{"event_type":"price_change","market":"0x3b40066b5cf3871a2f6237c5628bd8092a206aa998558ac5ec13c4483e31e160","price_changes":[{"asset_id":"110216635572655435074987471276357323571387854733835379371586402147734167783946","best_ask":"0.55","best_bid":"0.54","hash":"371bea94511bd594ee9cd95278c85bb567f3e1c4","price":"0.4","side":"BUY","size":"250.5"},{"asset_id":"14766054693214075530629349735273995982307625376442606753688071083149620216746","best_ask":"0.46","best_bid":"0.45","hash":"9abf03c1719ef6b333e170b0f85366fcd1af435a","price":"0.6","side":"SELL","size":"250.5"}],"timestamp":"1785130325274"},"payload_hash":"2a79c4d2776287dd005e890c2b6d41b44b212e03f55889c235d275ae2bdc5994","raw_frame":"{\"market\":\"0x3b40066b5cf3871a2f6237c5628bd8092a206aa998558ac5ec13c4483e31e160\", \"price_changes\":[{\"asset_id\":\"110216635572655435074987471276357323571387854733835379371586402147734167783946\", \"price\":\"0.4\", \"size\":\"250.5\", \"side\":\"BUY\", \"hash\":\"371bea94511bd594ee9cd95278c85bb567f3e1c4\", \"best_bid\":\"0.54\", \"best_ask\":\"0.55\"}, {\"asset_id\":\"14766054693214075530629349735273995982307625376442606753688071083149620216746\", \"price\":\"0.6\", \"size\":\"250.5\", \"side\":\"SELL\", \"hash\":\"9abf03c1719ef6b333e170b0f85366fcd1af435a\", \"best_bid\":\"0.45\", \"best_ask\":\"0.46\"}], \"timestamp\":\"1785130325274\", \"event_type\":\"price_change\"}","received_at":"2026-07-27T05:32:05.236880Z","schema_version":"clob-market-ws.price_change.v1","sequence":null,"server_hash":null,"server_timestamp":"1785130325274","session_id":"502006c5cfcd437296561ea750c9ec8b","source":"clob_market_ws"},"received_at":"2026-07-27T05:32:05.236880Z","record_id":"f3fb476d7a603ecdd8ba7c4fe7707f3a4449362a66f45826d4c3e93dd9d3102f","schema_fingerprint":"4aa3821a28b0b7c2400bc59aba4bcc0a76e971dadd19610d3ad38c768e124dc7","schema_version":"edge-lab-recorder.raw.v1","sequence":null,"source":"clob_market_ws"}
{"event_at":"2026-07-27T05:32:05.275000Z","event_fingerprint":"e3224bc5fa30f53bf687a9799649f9829dfed3b428d98ba0561c5842e0689b0f","payload":{"connection_id":"efc69d3132f1467b8e898a382b23ac0d","event_at":"2026-07-27T05:32:05.275000Z","event_type":"price_change","frame_hash":"b59b225c1f52edbdf3b30831d2ea5850f5649dcd265f2f9a3575e6b5f01c79f5","frame_index":0,"kind":"data","monotonic_ns":232308476027875,"payload":{"event_type":"price_change","market":"0x3b40066b5cf3871a2f6237c5628bd8092a206aa998558ac5ec13c4483e31e160","price_changes":[{"asset_id":"110216635572655435074987471276357323571387854733835379371586402147734167783946","best_ask":"0.55","best_bid":"0.54","hash":"ddaab8240e48f48e5dfa1d998247fdbc8fe72efa","price":"0.4","side":"BUY","size":"220.5"},{"asset_id":"14766054693214075530629349735273995982307625376442606753688071083149620216746","best_ask":"0.46","best_bid":"0.45","hash":"552849805814ebb3d38ff560b5b81006ab94d23d","price":"0.6","side":"SELL","size":"220.5"}],"timestamp":"1785130325275"},"payload_hash":"3c4e246a475cb091e2d8f5597a9f54b4c7818b6cacb000b26c342baf1e263519","raw_frame":"{\"market\":\"0x3b40066b5cf3871a2f6237c5628bd8092a206aa998558ac5ec13c4483e31e160\", \"price_changes\":[{\"asset_id\":\"110216635572655435074987471276357323571387854733835379371586402147734167783946\", \"price\":\"0.4\", \"size\":\"220.5\", \"side\":\"BUY\", \"hash\":\"ddaab8240e48f48e5dfa1d998247fdbc8fe72efa\", \"best_bid\":\"0.54\", \"best_ask\":\"0.55\"}, {\"asset_id\":\"14766054693214075530629349735273995982307625376442606753688071083149620216746\", \"price\":\"0.6\", \"size\":\"220.5\", \"side\":\"SELL\", \"hash\":\"552849805814ebb3d38ff560b5b81006ab94d23d\", \"best_bid\":\"0.45\", \"best_ask\":\"0.46\"}], \"timestamp\":\"1785130325275\", \"event_type\":\"price_change\"}","received_at":"2026-07-27T05:32:05.238693Z","schema_version":"clob-market-ws.price_change.v1","sequence":null,"server_hash":null,"server_timestamp":"1785130325275","session_id":"502006c5cfcd437296561ea750c9ec8b","source":"clob_market_ws"},"received_at":"2026-07-27T05:32:05.238693Z","record_id":"cc4ea87cab008f531d5ab588940f68cce11751045ae961e2b8d5dc85ba8eea30","schema_fingerprint":"4aa3821a28b0b7c2400bc59aba4bcc0a76e971dadd19610d3ad38c768e124dc7","schema_version":"edge-lab-recorder.raw.v1","sequence":null,"source":"clob_market_ws"}
{"event_at":"2026-07-27T05:32:05.277000Z","event_fingerprint":"ed0b3c83c06119d162fa69d6d9e774156dfcf90817f8d390b3350dabb7561665","payload":{"connection_id":"efc69d3132f1467b8e898a382b23ac0d","event_at":"2026-07-27T05:32:05.277000Z","event_type":"price_change","frame_hash":"95d789a33940518c52cd87858a2803d4ad27c3b6c1c4d16bbc9860a47c71383f","frame_index":0,"kind":"data","monotonic_ns":232308478440875,"payload":{"event_type":"price_change","market":"0x3b40066b5cf3871a2f6237c5628bd8092a206aa998558ac5ec13c4483e31e160","price_changes":[{"asset_id":"110216635572655435074987471276357323571387854733835379371586402147734167783946","best_ask":"0.55","best_bid":"0.54","hash":"bc71bdf71e85cdd17433b74f7c65e3c7acd273c8","price":"0.43","side":"BUY","size":"173"},{"asset_id":"14766054693214075530629349735273995982307625376442606753688071083149620216746","best_ask":"0.46","best_bid":"0.45","hash":"0de3f53c589a5ec34ed0d126a28c4d5465bf977f","price":"0.57","side":"SELL","size":"173"}],"timestamp":"1785130325277"},"payload_hash":"93a14b88c2bc7a538803eff50f5a0172694ec6747235c7b5a1f77b5e49fcd938","raw_frame":"{\"market\":\"0x3b40066b5cf3871a2f6237c5628bd8092a206aa998558ac5ec13c4483e31e160\", \"price_changes\":[{\"asset_id\":\"110216635572655435074987471276357323571387854733835379371586402147734167783946\", \"price\":\"0.43\", \"size\":\"173\", \"side\":\"BUY\", \"hash\":\"bc71bdf71e85cdd17433b74f7c65e3c7acd273c8\", \"best_bid\":\"0.54\", \"best_ask\":\"0.55\"}, {\"asset_id\":\"14766054693214075530629349735273995982307625376442606753688071083149620216746\", \"price\":\"0.57\", \"size\":\"173\", \"side\":\"SELL\", \"hash\":\"0de3f53c589a5ec34ed0d126a28c4d5465bf977f\", \"best_bid\":\"0.45\", \"best_ask\":\"0.46\"}], \"timestamp\":\"1785130325277\", \"event_type\":\"price_change\"}","received_at":"2026-07-27T05:32:05.241106Z","schema_version":"clob-market-ws.price_change.v1","sequence":null,"server_hash":null,"server_timestamp":"1785130325277","session_id":"502006c5cfcd437296561ea750c9ec8b","source":"clob_market_ws"},"received_at":"2026-07-27T05:32:05.241106Z","record_id":"5a519ff646ac0d6b883ec3f756c019d373e03e6c1319bacd943e04eaa6d26fe6","schema_fingerprint":"4aa3821a28b0b7c2400bc59aba4bcc0a76e971dadd19610d3ad38c768e124dc7","schema_version":"edge-lab-recorder.raw.v1","sequence":null,"source":"clob_market_ws"}
{"event_at":"2026-07-27T05:32:05.278000Z","event_fingerprint":"263816b049ad694b2f996bca347f344dc29eca7d091cde26f824465ac2df5c7c","payload":{"connection_id":"efc69d3132f1467b8e898a382b23ac0d","event_at":"2026-07-27T05:32:05.278000Z","event_type":"price_change","frame_hash":"dbf05341e4967dea1c79813ebc93e9eac560cec1481063aef261741167130fef","frame_index":0,"kind":"data","monotonic_ns":232308480344166,"payload":{"event_type":"price_change","market":"0x3b40066b5cf3871a2f6237c5628bd8092a206aa998558ac5ec13c4483e31e160","price_changes":[{"asset_id":"110216635572655435074987471276357323571387854733835379371586402147734167783946","best_ask":"0.55","best_bid":"0.54","hash":"3843c1cf547b7cdafc75b1f1d36761eb1be2dc15","price":"0.4","side":"BUY","size":"190.5"},{"asset_id":"14766054693214075530629349735273995982307625376442606753688071083149620216746","best_ask":"0.46","best_bid":"0.45","hash":"629274b2c2010a26de99d109bc0356badc5de69a","price":"0.6","side":"SELL","size":"190.5"}],"timestamp":"1785130325278"},"payload_hash":"b9c35032038a03e9d21c53ea65151c9f0e7431dd4e23068061742937feffe1f2","raw_frame":"{\"market\":\"0x3b40066b5cf3871a2f6237c5628bd8092a206aa998558ac5ec13c4483e31e160\", \"price_changes\":[{\"asset_id\":\"110216635572655435074987471276357323571387854733835379371586402147734167783946\", \"price\":\"0.4\", \"size\":\"190.5\", \"side\":\"BUY\", \"hash\":\"3843c1cf547b7cdafc75b1f1d36761eb1be2dc15\", \"best_bid\":\"0.54\", \"best_ask\":\"0.55\"}, {\"asset_id\":\"14766054693214075530629349735273995982307625376442606753688071083149620216746\", \"price\":\"0.6\", \"size\":\"190.5\", \"side\":\"SELL\", \"hash\":\"629274b2c2010a26de99d109bc0356badc5de69a\", \"best_bid\":\"0.45\", \"best_ask\":\"0.46\"}], \"timestamp\":\"1785130325278\", \"event_type\":\"price_change\"}","received_at":"2026-07-27T05:32:05.243009Z","schema_version":"clob-market-ws.price_change.v1","sequence":null,"server_hash":null,"server_timestamp":"1785130325278","session_id":"502006c5cfcd437296561ea750c9ec8b","source":"clob_market_ws"},"received_at":"2026-07-27T05:32:05.243009Z","record_id":"07f9d541d8a677152ee39b1ad0d037acdc912612651f60ca5562b3940157c26a","schema_fingerprint":"4aa3821a28b0b7c2400bc59aba4bcc0a76e971dadd19610d3ad38c768e124dc7","schema_version":"edge-lab-recorder.raw.v1","sequence":null,"source":"clob_market_ws"}
{"event_at":"2026-07-27T05:32:05.281000Z","event_fingerprint":"7592a3febe5674b7408899db33c86edc4f6b5daa9fc1237427063900bdb5ab7e","payload":{"connection_id":"efc69d3132f1467b8e898a382b23ac0d","event_at":"2026-07-27T05:32:05.281000Z","event_type":"price_change","frame_hash":"2a86135740842befe46033553c21359e0ddf9b9249c9f095d88eca0e30915b33","frame_index":0,"kind":"data","monotonic_ns":232308482161750,"payload":{"event_type":"price_change","market":"0x3b40066b5cf3871a2f6237c5628bd8092a206aa998558ac5ec13c4483e31e160","price_changes":[{"asset_id":"110216635572655435074987471276357323571387854733835379371586402147734167783946","best_ask":"0.55","best_bid":"0.54","hash":"9c07dde2219f5ee841c8f9e7b56d62731e529284","price":"0.43","side":"BUY","size":"143"},{"asset_id":"14766054693214075530629349735273995982307625376442606753688071083149620216746","best_ask":"0.46","best_bid":"0.45","hash":"ee53f1d22976dc42b5f6cb21b8b1d2340f24cc68","price":"0.57","side":"SELL","size":"143"}],"timestamp":"1785130325281"},"payload_hash":"c13da9f0190992ce009df52e8cb460906ba69fc729d10d15270eb4726b92ccf3","raw_frame":"{\"market\":\"0x3b40066b5cf3871a2f6237c5628bd8092a206aa998558ac5ec13c4483e31e160\", \"price_changes\":[{\"asset_id\":\"110216635572655435074987471276357323571387854733835379371586402147734167783946\", \"price\":\"0.43\", \"size\":\"143\", \"side\":\"BUY\", \"hash\":\"9c07dde2219f5ee841c8f9e7b56d62731e529284\", \"best_bid\":\"0.54\", \"best_ask\":\"0.55\"}, {\"asset_id\":\"14766054693214075530629349735273995982307625376442606753688071083149620216746\", \"price\":\"0.57\", \"size\":\"143\", \"side\":\"SELL\", \"hash\":\"ee53f1d22976dc42b5f6cb21b8b1d2340f24cc68\", \"best_bid\":\"0.45\", \"best_ask\":\"0.46\"}], \"timestamp\":\"1785130325281\", \"event_type\":\"price_change\"}","received_at":"2026-07-27T05:32:05.244821Z","schema_version":"clob-market-ws.price_change.v1","sequence":null,"server_hash":null,"server_timestamp":"1785130325281","session_id":"502006c5cfcd437296561ea750c9ec8b","source":"clob_market_ws"},"received_at":"2026-07-27T05:32:05.244821Z","record_id":"21864e9557c5d6a4bb624e632bab239461a4f4ba403afd9425ad75a548f2d882","schema_fingerprint":"4aa3821a28b0b7c2400bc59aba4bcc0a76e971dadd19610d3ad38c768e124dc7","schema_version":"edge-lab-recorder.raw.v1","sequence":null,"source":"clob_market_ws"}
{"event_at":"2026-07-27T05:32:05.283000Z","event_fingerprint":"0826bf4208e4a0aa47b5ebca89a4dc4f732ad4aab2ff0c35e7932906f47ad9b7","payload":{"connection_id":"efc69d3132f1467b8e898a382b23ac0d","event_at":"2026-07-27T05:32:05.283000Z","event_type":"price_change","frame_hash":"f3083ee0de14335e71775f7f57258adf2bedbbc27ea7c68e67e9b6acb64adcce","frame_index":0,"kind":"data","monotonic_ns":232308484814000,"payload":{"event_type":"price_change","market":"0x3b40066b5cf3871a2f6237c5628bd8092a206aa998558ac5ec13c4483e31e160","price_changes":[{"asset_id":"110216635572655435074987471276357323571387854733835379371586402147734167783946","best_ask":"0.55","best_bid":"0.54","hash":"72988a3e0f8147d057d81a2141db50bf2d6ae6d9","price":"0.53","side":"BUY","size":"42.6"},{"asset_id":"14766054693214075530629349735273995982307625376442606753688071083149620216746","best_ask":"0.46","best_bid":"0.45","hash":"e0b047f92df554aa24e8c14bc5a92b85bc4fe2a3","price":"0.47","side":"SELL","size":"42.6"}],"timestamp":"1785130325283"},"payload_hash":"b429ad90cb06abde9b25d1f64a2a78ffa5fd366209fe3bc1a331bdb1dbafd25b","raw_frame":"{\"market\":\"0x3b40066b5cf3871a2f6237c5628bd8092a206aa998558ac5ec13c4483e31e160\", \"price_changes\":[{\"asset_id\":\"110216635572655435074987471276357323571387854733835379371586402147734167783946\", \"price\":\"0.53\", \"size\":\"42.6\", \"side\":\"BUY\", \"hash\":\"72988a3e0f8147d057d81a2141db50bf2d6ae6d9\", \"best_bid\":\"0.54\", \"best_ask\":\"0.55\"}, {\"asset_id\":\"14766054693214075530629349735273995982307625376442606753688071083149620216746\", \"price\":\"0.47\", \"size\":\"42.6\", \"side\":\"SELL\", \"hash\":\"e0b047f92df554aa24e8c14bc5a92b85bc4fe2a3\", \"best_bid\":\"0.45\", \"best_ask\":\"0.46\"}], \"timestamp\":\"1785130325283\", \"event_type\":\"price_change\"}","received_at":"2026-07-27T05:32:05.247480Z","schema_version":"clob-market-ws.price_change.v1","sequence":null,"server_hash":null,"server_timestamp":"1785130325283","session_id":"502006c5cfcd437296561ea750c9ec8b","source":"clob_market_ws"},"received_at":"2026-07-27T05:32:05.247480Z","record_id":"fd01b77fcecb682af72cc859059a03d891b36b33cd6dcfc8e3a81b5b3ad1bf67","schema_fingerprint":"4aa3821a28b0b7c2400bc59aba4bcc0a76e971dadd19610d3ad38c768e124dc7","schema_version":"edge-lab-recorder.raw.v1","sequence":null,"source":"clob_market_ws"}
{"event_at":"2026-07-27T05:32:05.287000Z","event_fingerprint":"75a828e4aed7e22597017c5ee3134f3f333bf24db9755e8f3a457ee4f73bc9f1","payload":{"connection_id":"efc69d3132f1467b8e898a382b23ac0d","event_at":"2026-07-27T05:32:05.287000Z","event_type":"price_change","frame_hash":"4ab599fdc5c79be38075e322c77e4c38cab0070bf67100e7e28ebabcd79ea213","frame_index":0,"kind":"data","monotonic_ns":232308486759125,"payload":{"event_type":"price_change","market":"0x3b40066b5cf3871a2f6237c5628bd8092a206aa998558ac5ec13c4483e31e160","price_changes":[{"asset_id":"14766054693214075530629349735273995982307625376442606753688071083149620216746","best_ask":"0.46","best_bid":"0.45","hash":"3d15964114abcb7a1adbf91465adeadae6156b47","price":"0.42","side":"BUY","size":"299.29"},{"asset_id":"110216635572655435074987471276357323571387854733835379371586402147734167783946","best_ask":"0.55","best_bid":"0.54","hash":"2b700f2b1722d7df6dc5194c6015120339912822","price":"0.58","side":"SELL","size":"299.29"}],"timestamp":"1785130325287"},"payload_hash":"f933a1e000397eb8f402798d8d5fcdc21046d16730ca8da12e4c260b152d7b13","raw_frame":"{\"market\":\"0x3b40066b5cf3871a2f6237c5628bd8092a206aa998558ac5ec13c4483e31e160\", \"price_changes\":[{\"asset_id\":\"14766054693214075530629349735273995982307625376442606753688071083149620216746\", \"price\":\"0.42\", \"size\":\"299.29\", \"side\":\"BUY\", \"hash\":\"3d15964114abcb7a1adbf91465adeadae6156b47\", \"best_bid\":\"0.45\", \"best_ask\":\"0.46\"}, {\"asset_id\":\"110216635572655435074987471276357323571387854733835379371586402147734167783946\", \"price\":\"0.58\", \"size\":\"299.29\", \"side\":\"SELL\", \"hash\":\"2b700f2b1722d7df6dc5194c6015120339912822\", \"best_bid\":\"0.54\", \"best_ask\":\"0.55\"}], \"timestamp\":\"1785130325287\", \"event_type\":\"price_change\"}","received_at":"2026-07-27T05:32:05.249425Z","schema_version":"clob-market-ws.price_change.v1","sequence":null,"server_hash":null,"server_timestamp":"1785130325287","session_id":"502006c5cfcd437296561ea750c9ec8b","source":"clob_market_ws"},"received_at":"2026-07-27T05:32:05.249425Z","record_id":"134fd63a2f62eebc43281465d75e1c2ec71721700dcb9e046361bd075b207935","schema_fingerprint":"4aa3821a28b0b7c2400bc59aba4bcc0a76e971dadd19610d3ad38c768e124dc7","schema_version":"edge-lab-recorder.raw.v1","sequence":null,"source":"clob_market_ws"}
{"event_at":"2026-07-27T05:32:05.291000Z","event_fingerprint":"dde1c383c373d47b155e1cde00bdc28a5cbc07b8347be16adab58a52d444ffe5","payload":{"connection_id":"efc69d3132f1467b8e898a382b23ac0d","event_at":"2026-07-27T05:32:05.291000Z","event_type":"price_change","frame_hash":"9f488d8d7217a7e0c3d4c91600e309043bbe764bb6bfe56acfa48e2e19a859e5","frame_index":0,"kind":"data","monotonic_ns":232308490077750,"payload":{"event_type":"price_change","market":"0x3b40066b5cf3871a2f6237c5628bd8092a206aa998558ac5ec13c4483e31e160","price_changes":[{"asset_id":"110216635572655435074987471276357323571387854733835379371586402147734167783946","best_ask":"0.55","best_bid":"0.54","hash":"99fab7ab6b89eab528ba5dae3fa3ec398b3d8598","price":"0.48","side":"BUY","size":"195.01"},{"asset_id":"14766054693214075530629349735273995982307625376442606753688071083149620216746","best_ask":"0.46","best_bid":"0.45","hash":"198468fd187eb7885fdae6c1d5d508b863e540ef","price":"0.52","side":"SELL","size":"195.01"}],"timestamp":"1785130325291"},"payload_hash":"d551c58afe41293acda1abd049bf1edd5006f32fe2ffdd71aa87c8cedae5485f","raw_frame":"{\"market\":\"0x3b40066b5cf3871a2f6237c5628bd8092a206aa998558ac5ec13c4483e31e160\", \"price_changes\":[{\"asset_id\":\"110216635572655435074987471276357323571387854733835379371586402147734167783946\", \"price\":\"0.48\", \"size\":\"195.01\", \"side\":\"BUY\", \"hash\":\"99fab7ab6b89eab528ba5dae3fa3ec398b3d8598\", \"best_bid\":\"0.54\", \"best_ask\":\"0.55\"}, {\"asset_id\":\"14766054693214075530629349735273995982307625376442606753688071083149620216746\", \"price\":\"0.52\", \"size\":\"195.01\", \"side\":\"SELL\", \"hash\":\"198468fd187eb7885fdae6c1d5d508b863e540ef\", \"best_bid\":\"0.45\", \"best_ask\":\"0.46\"}], \"timestamp\":\"1785130325291\", \"event_type\":\"price_change\"}","received_at":"2026-07-27T05:32:05.252743Z","schema_version":"clob-market-ws.price_change.v1","sequence":null,"server_hash":null,"server_timestamp":"1785130325291","session_id":"502006c5cfcd437296561ea750c9ec8b","source":"clob_market_ws"},"received_at":"2026-07-27T05:32:05.252743Z","record_id":"83f3c5e6163614e963e564d22937807cb0351387b9bd2fc99bcc4e011bb325b1","schema_fingerprint":"4aa3821a28b0b7c2400bc59aba4bcc0a76e971dadd19610d3ad38c768e124dc7","schema_version":"edge-lab-recorder.raw.v1","sequence":null,"source":"clob_market_ws"}
{"event_at":"2026-07-27T05:32:05.292000Z","event_fingerprint":"d367fe5edf084ce84605d2afa6d209a417d327a752a530573bd070efcefe9285","payload":{"connection_id":"efc69d3132f1467b8e898a382b23ac0d","event_at":"2026-07-27T05:32:05.292000Z","event_type":"price_change","frame_hash":"0ba29921216f7a47c66f65c552097fea390ff15619e5cba13625252e0efedfee","frame_index":0,"kind":"data","monotonic_ns":232308491719958,"payload":{"event_type":"price_change","market":"0x3b40066b5cf3871a2f6237c5628bd8092a206aa998558ac5ec13c4483e31e160","price_changes":[{"asset_id":"110216635572655435074987471276357323571387854733835379371586402147734167783946","best_ask":"0.55","best_bid":"0.54","hash":"ce90048ae372678fe283f82ed61f71e481336445","price":"0.49","side":"BUY","size":"47.6"},{"asset_id":"14766054693214075530629349735273995982307625376442606753688071083149620216746","best_ask":"0.46","best_bid":"0.45","hash":"58251cff9ed27e83afee79e9607b9a2c8ce6a9fb","price":"0.51","side":"SELL","size":"47.6"}],"timestamp":"1785130325292"},"payload_hash":"dadea8d4cbffd1ec797429b53b0cc330e99e5bde61ccb24541b56afab61d78f4","raw_frame":"{\"market\":\"0x3b40066b5cf3871a2f6237c5628bd8092a206aa998558ac5ec13c4483e31e160\", \"price_changes\":[{\"asset_id\":\"110216635572655435074987471276357323571387854733835379371586402147734167783946\", \"price\":\"0.49\", \"size\":\"47.6\", \"side\":\"BUY\", \"hash\":\"ce90048ae372678fe283f82ed61f71e481336445\", \"best_bid\":\"0.54\", \"best_ask\":\"0.55\"}, {\"asset_id\":\"14766054693214075530629349735273995982307625376442606753688071083149620216746\", \"price\":\"0.51\", \"size\":\"47.6\", \"side\":\"SELL\", \"hash\":\"58251cff9ed27e83afee79e9607b9a2c8ce6a9fb\", \"best_bid\":\"0.45\", \"best_ask\":\"0.46\"}], \"timestamp\":\"1785130325292\", \"event_type\":\"price_change\"}","received_at":"2026-07-27T05:32:05.254385Z","schema_version":"clob-market-ws.price_change.v1","sequence":null,"server_hash":null,"server_timestamp":"1785130325292","session_id":"502006c5cfcd437296561ea750c9ec8b","source":"clob_market_ws"},"received_at":"2026-07-27T05:32:05.254385Z","record_id":"f304c64729667643393b0119540e5c77793cb70a2cbf3b6ba1eee03353038e43","schema_fingerprint":"4aa3821a28b0b7c2400bc59aba4bcc0a76e971dadd19610d3ad38c768e124dc7","schema_version":"edge-lab-recorder.raw.v1","sequence":null,"source":"clob_market_ws"}
{"event_at":"2026-07-27T05:32:05.293000Z","event_fingerprint":"b2f1129c34e66c05f52392c4300ba85df60371005cdc35b27be51347db23721a","payload":{"connection_id":"efc69d3132f1467b8e898a382b23ac0d","event_at":"2026-07-27T05:32:05.293000Z","event_type":"price_change","frame_hash":"828df628dde948ac6af9e56c620a1af794d8ec1e13d7a379f7a70d61549b3b05","frame_index":0,"kind":"data","monotonic_ns":232308494151833,"payload":{"event_type":"price_change","market":"0x3b40066b5cf3871a2f6237c5628bd8092a206aa998558ac5ec13c4483e31e160","price_changes":[{"asset_id":"14766054693214075530629349735273995982307625376442606753688071083149620216746","best_ask":"0.46","best_bid":"0.45","hash":"d9545878404bc7370c9662c22ce1d067fb568766","price":"0.42","side":"BUY","size":"395.29"},{"asset_id":"110216635572655435074987471276357323571387854733835379371586402147734167783946","best_ask":"0.55","best_bid":"0.54","hash":"247516737e4e87dfb8e946f043c5551e9038ea10","price":"0.58","side":"SELL","size":"395.29"}],"timestamp":"1785130325293"},"payload_hash":"1ca658f70cdf5f3aafe8150a756fb21a52097db0e3972d83335da403305710e0","raw_frame":"{\"market\":\"0x3b40066b5cf3871a2f6237c5628bd8092a206aa998558ac5ec13c4483e31e160\", \"price_changes\":[{\"asset_id\":\"14766054693214075530629349735273995982307625376442606753688071083149620216746\", \"price\":\"0.42\", \"size\":\"395.29\", \"side\":\"BUY\", \"hash\":\"d9545878404bc7370c9662c22ce1d067fb568766\", \"best_bid\":\"0.45\", \"best_ask\":\"0.46\"}, {\"asset_id\":\"110216635572655435074987471276357323571387854733835379371586402147734167783946\", \"price\":\"0.58\", \"size\":\"395.29\", \"side\":\"SELL\", \"hash\":\"247516737e4e87dfb8e946f043c5551e9038ea10\", \"best_bid\":\"0.54\", \"best_ask\":\"0.55\"}], \"timestamp\":\"1785130325293\", \"event_type\":\"price_change\"}","received_at":"2026-07-27T05:32:05.256817Z","schema_version":"clob-market-ws.price_change.v1","sequence":null,"server_hash":null,"server_timestamp":"1785130325293","session_id":"502006c5cfcd437296561ea750c9ec8b","source":"clob_market_ws"},"received_at":"2026-07-27T05:32:05.256817Z","record_id":"bb49af8ec755ddd4e6b9518a5bde8d8d739d9f3bfa640bbdacaaed1f551ef474","schema_fingerprint":"4aa3821a28b0b7c2400bc59aba4bcc0a76e971dadd19610d3ad38c768e124dc7","schema_version":"edge-lab-recorder.raw.v1","sequence":null,"source":"clob_market_ws"}
{"event_at":"2026-07-27T05:32:05.296000Z","event_fingerprint":"93ab74c4c64067b37d8fd3e1e711cde49a29cf430142855dc4b1009b196275a4","payload":{"connection_id":"efc69d3132f1467b8e898a382b23ac0d","event_at":"2026-07-27T05:32:05.296000Z","event_type":"price_change","frame_hash":"7b120d1f228b2abb85fea1e4b6332adb31bfc2074cead4fa2eb6bf242947b48e","frame_index":0,"kind":"data","monotonic_ns":232308495808666,"payload":{"event_type":"price_change","market":"0x3b40066b5cf3871a2f6237c5628bd8092a206aa998558ac5ec13c4483e31e160","price_changes":[{"asset_id":"110216635572655435074987471276357323571387854733835379371586402147734167783946","best_ask":"0.55","best_bid":"0.54","hash":"139919b54d05e74086e5792214147faffba2c0be","price":"0.47","side":"BUY","size":"52.03"},{"asset_id":"14766054693214075530629349735273995982307625376442606753688071083149620216746","best_ask":"0.46","best_bid":"0.45","hash":"2369424e989c3104209e031b2f5fa76b5c0275fb","price":"0.53","side":"SELL","size":"52.03"}],"timestamp":"1785130325296"},"payload_hash":"d4ab200fab2648eeb6870c6f98e590876ec40a19516eed36e45c539e57de31d3","raw_frame":"{\"market\":\"0x3b40066b5cf3871a2f6237c5628bd8092a206aa998558ac5ec13c4483e31e160\", \"price_changes\":[{\"asset_id\":\"110216635572655435074987471276357323571387854733835379371586402147734167783946\", \"price\":\"0.47\", \"size\":\"52.03\", \"side\":\"BUY\", \"hash\":\"139919b54d05e74086e5792214147faffba2c0be\", \"best_bid\":\"0.54\", \"best_ask\":\"0.55\"}, {\"asset_id\":\"14766054693214075530629349735273995982307625376442606753688071083149620216746\", \"price\":\"0.53\", \"size\":\"52.03\", \"side\":\"SELL\", \"hash\":\"2369424e989c3104209e031b2f5fa76b5c0275fb\", \"best_bid\":\"0.45\", \"best_ask\":\"0.46\"}], \"timestamp\":\"1785130325296\", \"event_type\":\"price_change\"}","received_at":"2026-07-27T05:32:05.258474Z","schema_version":"clob-market-ws.price_change.v1","sequence":null,"server_hash":null,"server_timestamp":"1785130325296","session_id":"502006c5cfcd437296561ea750c9ec8b","source":"clob_market_ws"},"received_at":"2026-07-27T05:32:05.258474Z","record_id":"6c8b15595a902cffaa30b2f6e799dba1ddd704eb1efa7be28c9ef07d989acd43","schema_fingerprint":"4aa3821a28b0b7c2400bc59aba4bcc0a76e971dadd19610d3ad38c768e124dc7","schema_version":"edge-lab-recorder.raw.v1","sequence":null,"source":"clob_market_ws"}
{"event_at":"2026-07-27T05:32:05.301000Z","event_fingerprint":"fcc580d5deffe2845fe7540063ba501a2deca10bd01430145c2a5ed163a350ae","payload":{"connection_id":"efc69d3132f1467b8e898a382b23ac0d","event_at":"2026-07-27T05:32:05.301000Z","event_type":"price_change","frame_hash":"cf2dca9dfdc630d44e02ac5b1b0826254ec962b8c72f9a46a5a2fae3723382df","frame_index":0,"kind":"data","monotonic_ns":232308503568958,"payload":{"event_type":"price_change","market":"0x3b40066b5cf3871a2f6237c5628bd8092a206aa998558ac5ec13c4483e31e160","price_changes":[{"asset_id":"110216635572655435074987471276357323571387854733835379371586402147734167783946","best_ask":"0.55","best_bid":"0.54","hash":"79c894b84183a4e1593895a157f964364683a464","price":"0.41","side":"BUY","size":"190.4"},{"asset_id":"14766054693214075530629349735273995982307625376442606753688071083149620216746","best_ask":"0.46","best_bid":"0.45","hash":"a594d70a5cc055b8ec7511a031e84e4b8a8e007a","price":"0.59","side":"SELL","size":"190.4"}],"timestamp":"1785130325301"},"payload_hash":"161053cf54ebbd26a437f869dfbb23057536635113dbc1ceac2320e361c5bd63","raw_frame":"{\"market\":\"0x3b40066b5cf3871a2f6237c5628bd8092a206aa998558ac5ec13c4483e31e160\", \"price_changes\":[{\"asset_id\":\"110216635572655435074987471276357323571387854733835379371586402147734167783946\", \"price\":\"0.41\", \"size\":\"190.4\", \"side\":\"BUY\", \"hash\":\"79c894b84183a4e1593895a157f964364683a464\", \"best_bid\":\"0.54\", \"best_ask\":\"0.55\"}, {\"asset_id\":\"14766054693214075530629349735273995982307625376442606753688071083149620216746\", \"price\":\"0.59\", \"size\":\"190.4\", \"side\":\"SELL\", \"hash\":\"a594d70a5cc055b8ec7511a031e84e4b8a8e007a\", \"best_bid\":\"0.45\", \"best_ask\":\"0.46\"}], \"timestamp\":\"1785130325301\", \"event_type\":\"price_change\"}","received_at":"2026-07-27T05:32:05.266233Z","schema_version":"clob-market-ws.price_change.v1","sequence":null,"server_hash":null,"server_timestamp":"1785130325301","session_id":"502006c5cfcd437296561ea750c9ec8b","source":"clob_market_ws"},"received_at":"2026-07-27T05:32:05.266233Z","record_id":"11b8127356b32a77c8f701ed647f217517c2f0d76c7ce36461c7e5644ca48ddd","schema_fingerprint":"4aa3821a28b0b7c2400bc59aba4bcc0a76e971dadd19610d3ad38c768e124dc7","schema_version":"edge-lab-recorder.raw.v1","sequence":null,"source":"clob_market_ws"}
{"event_at":"2026-07-27T05:32:05.303000Z","event_fingerprint":"4171b1dfafad27fe3065af43d79639603ab60ea1563bf9e590ac1ab73eedf400","payload":{"connection_id":"efc69d3132f1467b8e898a382b23ac0d","event_at":"2026-07-27T05:32:05.303000Z","event_type":"price_change","frame_hash":"ec5c39ba2d5c2204cba2f42746dbd55d1aaed5d158ee1e9707a65105839f6a66","frame_index":0,"kind":"data","monotonic_ns":232308505537208,"payload":{"event_type":"price_change","market":"0x3b40066b5cf3871a2f6237c5628bd8092a206aa998558ac5ec13c4483e31e160","price_changes":[{"asset_id":"110216635572655435074987471276357323571387854733835379371586402147734167783946","best_ask":"0.55","best_bid":"0.54","hash":"aed8b8d731e0b87b06b0b31ee5dd9c8cc60d0386","price":"0.44","side":"BUY","size":"167.21"},{"asset_id":"14766054693214075530629349735273995982307625376442606753688071083149620216746","best_ask":"0.46","best_bid":"0.45","hash":"20482087c264bb0635cd64f866a7aec1f688baee","price":"0.56","side":"SELL","size":"167.21"}],"timestamp":"1785130325303"},"payload_hash":"c00c13e2ebd2bdc8627c40c339bb3bfffe6ab8fc5774ba3a166a6e019e737201","raw_frame":"{\"market\":\"0x3b40066b5cf3871a2f6237c5628bd8092a206aa998558ac5ec13c4483e31e160\", \"price_changes\":[{\"asset_id\":\"110216635572655435074987471276357323571387854733835379371586402147734167783946\", \"price\":\"0.44\", \"size\":\"167.21\", \"side\":\"BUY\", \"hash\":\"aed8b8d731e0b87b06b0b31ee5dd9c8cc60d0386\", \"best_bid\":\"0.54\", \"best_ask\":\"0.55\"}, {\"asset_id\":\"14766054693214075530629349735273995982307625376442606753688071083149620216746\", \"price\":\"0.56\", \"size\":\"167.21\", \"side\":\"SELL\", \"hash\":\"20482087c264bb0635cd64f866a7aec1f688baee\", \"best_bid\":\"0.45\", \"best_ask\":\"0.46\"}], \"timestamp\":\"1785130325303\", \"event_type\":\"price_change\"}","received_at":"2026-07-27T05:32:05.268201Z","schema_version":"clob-market-ws.price_change.v1","sequence":null,"server_hash":null,"server_timestamp":"1785130325303","session_id":"502006c5cfcd437296561ea750c9ec8b","source":"clob_market_ws"},"received_at":"2026-07-27T05:32:05.268201Z","record_id":"ba02e89977fb0142cebfa8898a1b62469369e2d6a923d929205febe18b24554b","schema_fingerprint":"4aa3821a28b0b7c2400bc59aba4bcc0a76e971dadd19610d3ad38c768e124dc7","schema_version":"edge-lab-recorder.raw.v1","sequence":null,"source":"clob_market_ws"}
{"event_at":"2026-07-27T05:32:05.305000Z","event_fingerprint":"f8955cceaf99360b349d626fb29bb89803005d62ce71d341b6e228a8d221f959","payload":{"connection_id":"efc69d3132f1467b8e898a382b23ac0d","event_at":"2026-07-27T05:32:05.305000Z","event_type":"price_change","frame_hash":"b4e0c413092856eba8b37e826afa078704d99d90d402c33411d6f9bb690ba830","frame_index":0,"kind":"data","monotonic_ns":232308507947791,"payload":{"event_type":"price_change","market":"0x3b40066b5cf3871a2f6237c5628bd8092a206aa998558ac5ec13c4483e31e160","price_changes":[{"asset_id":"110216635572655435074987471276357323571387854733835379371586402147734167783946","best_ask":"0.55","best_bid":"0.54","hash":"f1205deadac88112034bf9d92dc98b58a93272c8","price":"0.41","side":"BUY","size":"220.4"},{"asset_id":"14766054693214075530629349735273995982307625376442606753688071083149620216746","best_ask":"0.46","best_bid":"0.45","hash":"5cdc311de3acac7d16e31cb331e4c480cb5e77c9","price":"0.59","side":"SELL","size":"220.4"}],"timestamp":"1785130325305"},"payload_hash":"ce5adebe9de822ec1090924dcbdcb6742d85d65f61a66c61cff6ee182673aeb7","raw_frame":"{\"market\":\"0x3b40066b5cf3871a2f6237c5628bd8092a206aa998558ac5ec13c4483e31e160\", \"price_changes\":[{\"asset_id\":\"110216635572655435074987471276357323571387854733835379371586402147734167783946\", \"price\":\"0.41\", \"size\":\"220.4\", \"side\":\"BUY\", \"hash\":\"f1205deadac88112034bf9d92dc98b58a93272c8\", \"best_bid\":\"0.54\", \"best_ask\":\"0.55\"}, {\"asset_id\":\"14766054693214075530629349735273995982307625376442606753688071083149620216746\", \"price\":\"0.59\", \"size\":\"220.4\", \"side\":\"SELL\", \"hash\":\"5cdc311de3acac7d16e31cb331e4c480cb5e77c9\", \"best_bid\":\"0.45\", \"best_ask\":\"0.46\"}], \"timestamp\":\"1785130325305\", \"event_type\":\"price_change\"}","received_at":"2026-07-27T05:32:05.270609Z","schema_version":"clob-market-ws.price_change.v1","sequence":null,"server_hash":null,"server_timestamp":"1785130325305","session_id":"502006c5cfcd437296561ea750c9ec8b","source":"clob_market_ws"},"received_at":"2026-07-27T05:32:05.270609Z","record_id":"61e59d4ee9e03145e10a1d0df877d8abe1495bb4f9d16c7971d23f3dca674347","schema_fingerprint":"4aa3821a28b0b7c2400bc59aba4bcc0a76e971dadd19610d3ad38c768e124dc7","schema_version":"edge-lab-recorder.raw.v1","sequence":null,"source":"clob_market_ws"}
{"event_at":"2026-07-27T05:32:05.307000Z","event_fingerprint":"122ee72be4cec06d72aa84f90726c9a4a7c48efec022bc2d6bcc9f327773828a","payload":{"connection_id":"efc69d3132f1467b8e898a382b23ac0d","event_at":"2026-07-27T05:32:05.307000Z","event_type":"price_change","frame_hash":"262a42ee4602a7f9e9469dac347d4c527a543f449991baed69fb49ff94effa1d","frame_index":0,"kind":"data","monotonic_ns":232308510494375,"payload":{"event_type":"price_change","market":"0x3b40066b5cf3871a2f6237c5628bd8092a206aa998558ac5ec13c4483e31e160","price_changes":[{"asset_id":"110216635572655435074987471276357323571387854733835379371586402147734167783946","best_ask":"0.55","best_bid":"0.54","hash":"85d13f250dfc97f726b6d7ee157e70a9a7ce55af","price":"0.01","side":"BUY","size":"7843.02"},{"asset_id":"14766054693214075530629349735273995982307625376442606753688071083149620216746","best_ask":"0.46","best_bid":"0.45","hash":"959d3b270835dbf606ce1041305bdf8b90c1d160","price":"0.99","side":"SELL","size":"7843.02"}],"timestamp":"1785130325307"},"payload_hash":"bcdce2ed902f9a24f9b4ee79adfa4f4dfe1f9d3460a2bd14dbdda13860cb6972","raw_frame":"{\"market\":\"0x3b40066b5cf3871a2f6237c5628bd8092a206aa998558ac5ec13c4483e31e160\", \"price_changes\":[{\"asset_id\":\"110216635572655435074987471276357323571387854733835379371586402147734167783946\", \"price\":\"0.01\", \"size\":\"7843.02\", \"side\":\"BUY\", \"hash\":\"85d13f250dfc97f726b6d7ee157e70a9a7ce55af\", \"best_bid\":\"0.54\", \"best_ask\":\"0.55\"}, {\"asset_id\":\"14766054693214075530629349735273995982307625376442606753688071083149620216746\", \"price\":\"0.99\", \"size\":\"7843.02\", \"side\":\"SELL\", \"hash\":\"959d3b270835dbf606ce1041305bdf8b90c1d160\", \"best_bid\":\"0.45\", \"best_ask\":\"0.46\"}], \"timestamp\":\"1785130325307\", \"event_type\":\"price_change\"}","received_at":"2026-07-27T05:32:05.273157Z","schema_version":"clob-market-ws.price_change.v1","sequence":null,"server_hash":null,"server_timestamp":"1785130325307","session_id":"502006c5cfcd437296561ea750c9ec8b","source":"clob_market_ws"},"received_at":"2026-07-27T05:32:05.273157Z","record_id":"4f26ff5c6dd1278ac287610b23e1dcedc65971d512eb546caf186c61c1edc91b","schema_fingerprint":"4aa3821a28b0b7c2400bc59aba4bcc0a76e971dadd19610d3ad38c768e124dc7","schema_version":"edge-lab-recorder.raw.v1","sequence":null,"source":"clob_market_ws"}
{"event_at":"2026-07-27T05:32:05.325000Z","event_fingerprint":"c5f88e47eb1564728c38323b751576ed33f9bb08417ee804f6fea61ddb174f7f","payload":{"connection_id":"efc69d3132f1467b8e898a382b23ac0d","event_at":"2026-07-27T05:32:05.325000Z","event_type":"price_change","frame_hash":"96a0bd70a58e2c53050d1aff61c531e34910dadae0c93586eb953a6333b01ea2","frame_index":0,"kind":"data","monotonic_ns":232308524739083,"payload":{"event_type":"price_change","market":"0x3b40066b5cf3871a2f6237c5628bd8092a206aa998558ac5ec13c4483e31e160","price_changes":[{"asset_id":"110216635572655435074987471276357323571387854733835379371586402147734167783946","best_ask":"0.55","best_bid":"0.54","hash":"6cbfe5eea5a211d85928aac2a3e62a278d5b82dd","price":"0.44","side":"BUY","size":"197.21"},{"asset_id":"14766054693214075530629349735273995982307625376442606753688071083149620216746","best_ask":"0.46","best_bid":"0.45","hash":"477ad262a2f207e6c16ac927612e8b92866dccc3","price":"0.56","side":"SELL","size":"197.21"}],"timestamp":"1785130325325"},"payload_hash":"fa2a1f7cb1158f956b4c77aa9c798a9c6af8fca927d67f8db90347a6f9ed1b41","raw_frame":"{\"market\":\"0x3b40066b5cf3871a2f6237c5628bd8092a206aa998558ac5ec13c4483e31e160\", \"price_changes\":[{\"asset_id\":\"110216635572655435074987471276357323571387854733835379371586402147734167783946\", \"price\":\"0.44\", \"size\":\"197.21\", \"side\":\"BUY\", \"hash\":\"6cbfe5eea5a211d85928aac2a3e62a278d5b82dd\", \"best_bid\":\"0.54\", \"best_ask\":\"0.55\"}, {\"asset_id\":\"14766054693214075530629349735273995982307625376442606753688071083149620216746\", \"price\":\"0.56\", \"size\":\"197.21\", \"side\":\"SELL\", \"hash\":\"477ad262a2f207e6c16ac927612e8b92866dccc3\", \"best_bid\":\"0.45\", \"best_ask\":\"0.46\"}], \"timestamp\":\"1785130325325\", \"event_type\":\"price_change\"}","received_at":"2026-07-27T05:32:05.287400Z","schema_version":"clob-market-ws.price_change.v1","sequence":null,"server_hash":null,"server_timestamp":"1785130325325","session_id":"502006c5cfcd437296561ea750c9ec8b","source":"clob_market_ws"},"received_at":"2026-07-27T05:32:05.287400Z","record_id":"07295d7e517ef7d7546b4f558636c84652bdcee581f046fa43b39e39bc20f1af","schema_fingerprint":"4aa3821a28b0b7c2400bc59aba4bcc0a76e971dadd19610d3ad38c768e124dc7","schema_version":"edge-lab-recorder.raw.v1","sequence":null,"source":"clob_market_ws"}
{"event_at":"2026-07-27T05:32:05.326000Z","event_fingerprint":"4ea2d31441352d76e2e49a2c3bdf340282271c0331b67a279fb55d2118dcf200","payload":{"connection_id":"efc69d3132f1467b8e898a382b23ac0d","event_at":"2026-07-27T05:32:05.326000Z","event_type":"price_change","frame_hash":"14031005554b1964b5d7585bd14cc5e9eba726f4e326c61e886de4010335bcec","frame_index":0,"kind":"data","monotonic_ns":232308530059666,"payload":{"event_type":"price_change","market":"0x3b40066b5cf3871a2f6237c5628bd8092a206aa998558ac5ec13c4483e31e160","price_changes":[{"asset_id":"110216635572655435074987471276357323571387854733835379371586402147734167783946","best_ask":"0.55","best_bid":"0.54","hash":"ab7801c2aa54b944c4c2bddbf289bb81b85f7d23","price":"0.41","side":"BUY","size":"250.4"},{"asset_id":"14766054693214075530629349735273995982307625376442606753688071083149620216746","best_ask":"0.46","best_bid":"0.45","hash":"c45f40950155e34061286e154be8eda7a7200c22","price":"0.59","side":"SELL","size":"250.4"}],"timestamp":"1785130325326"},"payload_hash":"de2594a94c75357103b145491fd08e7eeb6649ba3f638caafbf9dfc3225d08fa","raw_frame":"{\"market\":\"0x3b40066b5cf3871a2f6237c5628bd8092a206aa998558ac5ec13c4483e31e160\", \"price_changes\":[{\"asset_id\":\"110216635572655435074987471276357323571387854733835379371586402147734167783946\", \"price\":\"0.41\", \"size\":\"250.4\", \"side\":\"BUY\", \"hash\":\"ab7801c2aa54b944c4c2bddbf289bb81b85f7d23\", \"best_bid\":\"0.54\", \"best_ask\":\"0.55\"}, {\"asset_id\":\"14766054693214075530629349735273995982307625376442606753688071083149620216746\", \"price\":\"0.59\", \"size\":\"250.4\", \"side\":\"SELL\", \"hash\":\"c45f40950155e34061286e154be8eda7a7200c22\", \"best_bid\":\"0.45\", \"best_ask\":\"0.46\"}], \"timestamp\":\"1785130325326\", \"event_type\":\"price_change\"}","received_at":"2026-07-27T05:32:05.292720Z","schema_version":"clob-market-ws.price_change.v1","sequence":null,"server_hash":null,"server_timestamp":"1785130325326","session_id":"502006c5cfcd437296561ea750c9ec8b","source":"clob_market_ws"},"received_at":"2026-07-27T05:32:05.292720Z","record_id":"8f5c50351938b2771dec882ffbe50d0b2e43aa10fee6e230fd10e2a0817ec274","schema_fingerprint":"4aa3821a28b0b7c2400bc59aba4bcc0a76e971dadd19610d3ad38c768e124dc7","schema_version":"edge-lab-recorder.raw.v1","sequence":null,"source":"clob_market_ws"}
{"event_at":"2026-07-27T05:32:05.333000Z","event_fingerprint":"92243cd1864308e3b9cc1bf73646a456196da4b7b2bf852340cfe7e7302274c5","payload":{"connection_id":"efc69d3132f1467b8e898a382b23ac0d","event_at":"2026-07-27T05:32:05.333000Z","event_type":"price_change","frame_hash":"9b409ca43372aba93c302153746ac67fb407f516c960ceadea5990b289b34173","frame_index":0,"kind":"data","monotonic_ns":232308533082083,"payload":{"event_type":"price_change","market":"0x3b40066b5cf3871a2f6237c5628bd8092a206aa998558ac5ec13c4483e31e160","price_changes":[{"asset_id":"110216635572655435074987471276357323571387854733835379371586402147734167783946","best_ask":"0.55","best_bid":"0.54","hash":"cf52278772a648d3f52259783e4e6d95bf28dc9d","price":"0.01","side":"BUY","size":"7848.02"},{"asset_id":"14766054693214075530629349735273995982307625376442606753688071083149620216746","best_ask":"0.46","best_bid":"0.45","hash":"2d02ad1e7e7e9614def250fb434cdcfdf8b943f3","price":"0.99","side":"SELL","size":"7848.02"}],"timestamp":"1785130325333"},"payload_hash":"d834b971afdb44db35be173fb7baed8494db12ede96193662e545c616074eb10","raw_frame":"{\"market\":\"0x3b40066b5cf3871a2f6237c5628bd8092a206aa998558ac5ec13c4483e31e160\", \"price_changes\":[{\"asset_id\":\"110216635572655435074987471276357323571387854733835379371586402147734167783946\", \"price\":\"0.01\", \"size\":\"7848.02\", \"side\":\"BUY\", \"hash\":\"cf52278772a648d3f52259783e4e6d95bf28dc9d\", \"best_bid\":\"0.54\", \"best_ask\":\"0.55\"}, {\"asset_id\":\"14766054693214075530629349735273995982307625376442606753688071083149620216746\", \"price\":\"0.99\", \"size\":\"7848.02\", \"side\":\"SELL\", \"hash\":\"2d02ad1e7e7e9614def250fb434cdcfdf8b943f3\", \"best_bid\":\"0.45\", \"best_ask\":\"0.46\"}], \"timestamp\":\"1785130325333\", \"event_type\":\"price_change\"}","received_at":"2026-07-27T05:32:05.295749Z","schema_version":"clob-market-ws.price_change.v1","sequence":null,"server_hash":null,"server_timestamp":"1785130325333","session_id":"502006c5cfcd437296561ea750c9ec8b","source":"clob_market_ws"},"received_at":"2026-07-27T05:32:05.295749Z","record_id":"df49b5c1359730b3d6a37b90d5fddd74adbf2b405aa5583b9b292ba114dfa3e9","schema_fingerprint":"4aa3821a28b0b7c2400bc59aba4bcc0a76e971dadd19610d3ad38c768e124dc7","schema_version":"edge-lab-recorder.raw.v1","sequence":null,"source":"clob_market_ws"}
{"event_at":"2026-07-27T05:32:05.354000Z","event_fingerprint":"062557b4606a2fff80463fb9510240ab6d795033059462c6d5a7b0fc4066cddd","payload":{"connection_id":"efc69d3132f1467b8e898a382b23ac0d","event_at":"2026-07-27T05:32:05.354000Z","event_type":"price_change","frame_hash":"7770012496a033837dda9bbde07d670d9b5fda71af1a1d9b88034f547a16abc5","frame_index":0,"kind":"data","monotonic_ns":232308551386291,"payload":{"event_type":"price_change","market":"0x3b40066b5cf3871a2f6237c5628bd8092a206aa998558ac5ec13c4483e31e160","price_changes":[{"asset_id":"110216635572655435074987471276357323571387854733835379371586402147734167783946","best_ask":"0.55","best_bid":"0.54","hash":"c796bab3c0dde0b381c93f4e2dd0eff73097baf5","price":"0.01","side":"BUY","size":"7843.02"},{"asset_id":"14766054693214075530629349735273995982307625376442606753688071083149620216746","best_ask":"0.46","best_bid":"0.45","hash":"edea84ab035e37221a544c0ba67d4c7d42ac7c51","price":"0.99","side":"SELL","size":"7843.02"}],"timestamp":"1785130325354"},"payload_hash":"c9334ce071efd64cf2b518106509a297dcc1382592803e73dad5a6d18eeab205","raw_frame":"{\"market\":\"0x3b40066b5cf3871a2f6237c5628bd8092a206aa998558ac5ec13c4483e31e160\", \"price_changes\":[{\"asset_id\":\"110216635572655435074987471276357323571387854733835379371586402147734167783946\", \"price\":\"0.01\", \"size\":\"7843.02\", \"side\":\"BUY\", \"hash\":\"c796bab3c0dde0b381c93f4e2dd0eff73097baf5\", \"best_bid\":\"0.54\", \"best_ask\":\"0.55\"}, {\"asset_id\":\"14766054693214075530629349735273995982307625376442606753688071083149620216746\", \"price\":\"0.99\", \"size\":\"7843.02\", \"side\":\"SELL\", \"hash\":\"edea84ab035e37221a544c0ba67d4c7d42ac7c51\", \"best_bid\":\"0.45\", \"best_ask\":\"0.46\"}], \"timestamp\":\"1785130325354\", \"event_type\":\"price_change\"}","received_at":"2026-07-27T05:32:05.314053Z","schema_version":"clob-market-ws.price_change.v1","sequence":null,"server_hash":null,"server_timestamp":"1785130325354","session_id":"502006c5cfcd437296561ea750c9ec8b","source":"clob_market_ws"},"received_at":"2026-07-27T05:32:05.314053Z","record_id":"e9b64c82b5e9e00b92e5f85707202df909ba76b52f8f3801a8bd672e6b562604","schema_fingerprint":"4aa3821a28b0b7c2400bc59aba4bcc0a76e971dadd19610d3ad38c768e124dc7","schema_version":"edge-lab-recorder.raw.v1","sequence":null,"source":"clob_market_ws"}
{"event_at":"2026-07-27T05:32:05.359000Z","event_fingerprint":"af3063dcffd463648bfe45153b076d9cc541d682a51ea3277a7cb515dc27c5ff","payload":{"connection_id":"efc69d3132f1467b8e898a382b23ac0d","event_at":"2026-07-27T05:32:05.359000Z","event_type":"price_change","frame_hash":"19d618c9bec816892e0d737a240c7c93c4ee9320c8d22a5f97df57a04a35d4a0","frame_index":0,"kind":"data","monotonic_ns":232308557450125,"payload":{"event_type":"price_change","market":"0x3b40066b5cf3871a2f6237c5628bd8092a206aa998558ac5ec13c4483e31e160","price_changes":[{"asset_id":"110216635572655435074987471276357323571387854733835379371586402147734167783946","best_ask":"0.55","best_bid":"0.54","hash":"41bb4871f2ed1a7fec7fecbfc789769630264057","price":"0.44","side":"BUY","size":"215.21"},{"asset_id":"14766054693214075530629349735273995982307625376442606753688071083149620216746","best_ask":"0.46","best_bid":"0.45","hash":"a7a349f3d4c28382e610b7c78af5f32a04bc1d98","price":"0.56","side":"SELL","size":"215.21"}],"timestamp":"1785130325359"},"payload_hash":"4ef33a17cee7b3e1ef0b2f394c69bc8d7e15b4cb3f7c79ae1029e4c1d3a5268e","raw_frame":"{\"market\":\"0x3b40066b5cf3871a2f6237c5628bd8092a206aa998558ac5ec13c4483e31e160\", \"price_changes\":[{\"asset_id\":\"110216635572655435074987471276357323571387854733835379371586402147734167783946\", \"price\":\"0.44\", \"size\":\"215.21\", \"side\":\"BUY\", \"hash\":\"41bb4871f2ed1a7fec7fecbfc789769630264057\", \"best_bid\":\"0.54\", \"best_ask\":\"0.55\"}, {\"asset_id\":\"14766054693214075530629349735273995982307625376442606753688071083149620216746\", \"price\":\"0.56\", \"size\":\"215.21\", \"side\":\"SELL\", \"hash\":\"a7a349f3d4c28382e610b7c78af5f32a04bc1d98\", \"best_bid\":\"0.45\", \"best_ask\":\"0.46\"}], \"timestamp\":\"1785130325359\", \"event_type\":\"price_change\"}","received_at":"2026-07-27T05:32:05.320111Z","schema_version":"clob-market-ws.price_change.v1","sequence":null,"server_hash":null,"server_timestamp":"1785130325359","session_id":"502006c5cfcd437296561ea750c9ec8b","source":"clob_market_ws"},"received_at":"2026-07-27T05:32:05.320111Z","record_id":"ac5e4ea4502c8dd3685ccf9a845fc349422a413e8ce69a7ef6debae34a621768","schema_fingerprint":"4aa3821a28b0b7c2400bc59aba4bcc0a76e971dadd19610d3ad38c768e124dc7","schema_version":"edge-lab-recorder.raw.v1","sequence":null,"source":"clob_market_ws"}
{"event_at":"2026-07-27T05:32:05.388000Z","event_fingerprint":"fbad52c023f610cfc8a9001f4f2dcbdc8101535c6d827607441387a1f533177d","payload":{"connection_id":"efc69d3132f1467b8e898a382b23ac0d","event_at":"2026-07-27T05:32:05.388000Z","event_type":"price_change","frame_hash":"4e39e90c8477beeb725395869182ffe2de5b8c81832cd16a225a34d3a8ec9507","frame_index":0,"kind":"data","monotonic_ns":232308590244291,"payload":{"event_type":"price_change","market":"0x3b40066b5cf3871a2f6237c5628bd8092a206aa998558ac5ec13c4483e31e160","price_changes":[{"asset_id":"110216635572655435074987471276357323571387854733835379371586402147734167783946","best_ask":"0.55","best_bid":"0.54","hash":"d40e6d5850bc22f874a97d968f81931baac8143c","price":"0.04","side":"BUY","size":"633.09"},{"asset_id":"14766054693214075530629349735273995982307625376442606753688071083149620216746","best_ask":"0.46","best_bid":"0.45","hash":"83bae3b1715aaa99e8dfc5ba2ea8d61e3805fe1c","price":"0.96","side":"SELL","size":"633.09"}],"timestamp":"1785130325388"},"payload_hash":"7c6cc4a3420fc9fbe8fcf6016f35eba192a8d21b686acae0817d56213868396b","raw_frame":"{\"market\":\"0x3b40066b5cf3871a2f6237c5628bd8092a206aa998558ac5ec13c4483e31e160\", \"price_changes\":[{\"asset_id\":\"110216635572655435074987471276357323571387854733835379371586402147734167783946\", \"price\":\"0.04\", \"size\":\"633.09\", \"side\":\"BUY\", \"hash\":\"d40e6d5850bc22f874a97d968f81931baac8143c\", \"best_bid\":\"0.54\", \"best_ask\":\"0.55\"}, {\"asset_id\":\"14766054693214075530629349735273995982307625376442606753688071083149620216746\", \"price\":\"0.96\", \"size\":\"633.09\", \"side\":\"SELL\", \"hash\":\"83bae3b1715aaa99e8dfc5ba2ea8d61e3805fe1c\", \"best_bid\":\"0.45\", \"best_ask\":\"0.46\"}], \"timestamp\":\"1785130325388\", \"event_type\":\"price_change\"}","received_at":"2026-07-27T05:32:05.352905Z","schema_version":"clob-market-ws.price_change.v1","sequence":null,"server_hash":null,"server_timestamp":"1785130325388","session_id":"502006c5cfcd437296561ea750c9ec8b","source":"clob_market_ws"},"received_at":"2026-07-27T05:32:05.352905Z","record_id":"f0ffffcc9b02af2b8054b9982ac26fdae6c1b9be72e8d14c7f1e4666e5df5659","schema_fingerprint":"4aa3821a28b0b7c2400bc59aba4bcc0a76e971dadd19610d3ad38c768e124dc7","schema_version":"edge-lab-recorder.raw.v1","sequence":null,"source":"clob_market_ws"}
{"event_at":"2026-07-27T05:32:05.435000Z","event_fingerprint":"436ac7c1fc05489769a23f7e7bd6ee3f085ea70c2cdc4907685ffe4291b60028","payload":{"connection_id":"efc69d3132f1467b8e898a382b23ac0d","event_at":"2026-07-27T05:32:05.435000Z","event_type":"price_change","frame_hash":"fbe9cd93b297307dd2ab40f26f208a73620ad9c30f69d85515ecd25b822f1f84","frame_index":0,"kind":"data","monotonic_ns":232308634321916,"payload":{"event_type":"price_change","market":"0x3b40066b5cf3871a2f6237c5628bd8092a206aa998558ac5ec13c4483e31e160","price_changes":[{"asset_id":"110216635572655435074987471276357323571387854733835379371586402147734167783946","best_ask":"0.55","best_bid":"0.54","hash":"41a20da522afc167570d15956e74f698fa754e75","price":"0.53","side":"BUY","size":"312.6"},{"asset_id":"14766054693214075530629349735273995982307625376442606753688071083149620216746","best_ask":"0.46","best_bid":"0.45","hash":"c8706656d5941c6d0dc6a77979c0335fc88f5b6c","price":"0.47","side":"SELL","size":"312.6"}],"timestamp":"1785130325435"},"payload_hash":"abcfbaaf15a6ea45a8689982631e81916db31d08e18ba7e9b8dabc05c5e9348b","raw_frame":"{\"market\":\"0x3b40066b5cf3871a2f6237c5628bd8092a206aa998558ac5ec13c4483e31e160\", \"price_changes\":[{\"asset_id\":\"110216635572655435074987471276357323571387854733835379371586402147734167783946\", \"price\":\"0.53\", \"size\":\"312.6\", \"side\":\"BUY\", \"hash\":\"41a20da522afc167570d15956e74f698fa754e75\", \"best_bid\":\"0.54\", \"best_ask\":\"0.55\"}, {\"asset_id\":\"14766054693214075530629349735273995982307625376442606753688071083149620216746\", \"price\":\"0.47\", \"size\":\"312.6\", \"side\":\"SELL\", \"hash\":\"c8706656d5941c6d0dc6a77979c0335fc88f5b6c\", \"best_bid\":\"0.45\", \"best_ask\":\"0.46\"}], \"timestamp\":\"1785130325435\", \"event_type\":\"price_change\"}","received_at":"2026-07-27T05:32:05.396989Z","schema_version":"clob-market-ws.price_change.v1","sequence":null,"server_hash":null,"server_timestamp":"1785130325435","session_id":"502006c5cfcd437296561ea750c9ec8b","source":"clob_market_ws"},"received_at":"2026-07-27T05:32:05.396989Z","record_id":"21970269d5c9b242869c67ae7dd0dc03a44522a5dfe15fbd2bbd1316266792d1","schema_fingerprint":"4aa3821a28b0b7c2400bc59aba4bcc0a76e971dadd19610d3ad38c768e124dc7","schema_version":"edge-lab-recorder.raw.v1","sequence":null,"source":"clob_market_ws"}
{"event_at":"2026-07-27T05:32:05.452000Z","event_fingerprint":"4723cbbd4d53ac677225ecd1c2d029f13ae4891715022002f771418744913b8d","payload":{"connection_id":"efc69d3132f1467b8e898a382b23ac0d","event_at":"2026-07-27T05:32:05.452000Z","event_type":"price_change","frame_hash":"db272a749e34b4d3a37768aa6bf0650a44e119aec22157c77b915804a8d392f9","frame_index":0,"kind":"data","monotonic_ns":232308652438625,"payload":{"event_type":"price_change","market":"0x3b40066b5cf3871a2f6237c5628bd8092a206aa998558ac5ec13c4483e31e160","price_changes":[{"asset_id":"110216635572655435074987471276357323571387854733835379371586402147734167783946","best_ask":"0.55","best_bid":"0.54","hash":"c492f31f68ab592fc7b472f14bca305910032602","price":"0.01","side":"BUY","size":"7848.02"},{"asset_id":"14766054693214075530629349735273995982307625376442606753688071083149620216746","best_ask":"0.46","best_bid":"0.45","hash":"1801217b604ee73db7caa65a30184e600353675b","price":"0.99","side":"SELL","size":"7848.02"}],"timestamp":"1785130325452"},"payload_hash":"6196c537ccbec3d74484a91942456d6957f037c8b1f098fedf6671a795cd6f9d","raw_frame":"{\"market\":\"0x3b40066b5cf3871a2f6237c5628bd8092a206aa998558ac5ec13c4483e31e160\", \"price_changes\":[{\"asset_id\":\"110216635572655435074987471276357323571387854733835379371586402147734167783946\", \"price\":\"0.01\", \"size\":\"7848.02\", \"side\":\"BUY\", \"hash\":\"c492f31f68ab592fc7b472f14bca305910032602\", \"best_bid\":\"0.54\", \"best_ask\":\"0.55\"}, {\"asset_id\":\"14766054693214075530629349735273995982307625376442606753688071083149620216746\", \"price\":\"0.99\", \"size\":\"7848.02\", \"side\":\"SELL\", \"hash\":\"1801217b604ee73db7caa65a30184e600353675b\", \"best_bid\":\"0.45\", \"best_ask\":\"0.46\"}], \"timestamp\":\"1785130325452\", \"event_type\":\"price_change\"}","received_at":"2026-07-27T05:32:05.415099Z","schema_version":"clob-market-ws.price_change.v1","sequence":null,"server_hash":null,"server_timestamp":"1785130325452","session_id":"502006c5cfcd437296561ea750c9ec8b","source":"clob_market_ws"},"received_at":"2026-07-27T05:32:05.415099Z","record_id":"5b26e2adfd20244ecc0a00ce7c686867aed211501a302e9fa016e1257a84bb2c","schema_fingerprint":"4aa3821a28b0b7c2400bc59aba4bcc0a76e971dadd19610d3ad38c768e124dc7","schema_version":"edge-lab-recorder.raw.v1","sequence":null,"source":"clob_market_ws"}
{"event_at":"2026-07-27T05:32:05.462000Z","event_fingerprint":"76100ee2c3f822c36426930ba4b9274bc67195be3bfaa69ddd48657f9a554b66","payload":{"connection_id":"efc69d3132f1467b8e898a382b23ac0d","event_at":"2026-07-27T05:32:05.462000Z","event_type":"price_change","frame_hash":"cf7f71c3cfe290c927d591915fbbaee4420e5a8fe1c555e699838b0a31e25e0e","frame_index":0,"kind":"data","monotonic_ns":232308661806833,"payload":{"event_type":"price_change","market":"0x3b40066b5cf3871a2f6237c5628bd8092a206aa998558ac5ec13c4483e31e160","price_changes":[{"asset_id":"110216635572655435074987471276357323571387854733835379371586402147734167783946","best_ask":"0.55","best_bid":"0.54","hash":"077c68fc90c47c74c6769c80c081a79e81c5d7f8","price":"0.04","side":"BUY","size":"628.09"},{"asset_id":"14766054693214075530629349735273995982307625376442606753688071083149620216746","best_ask":"0.46","best_bid":"0.45","hash":"62b69b193caf4f4123951778e9bb52e7c1d55ae4","price":"0.96","side":"SELL","size":"628.09"}],"timestamp":"1785130325462"},"payload_hash":"8f9ef4b92e878fa6d8a0dec329ed4af040d3c1f1af5a6d95d249ca2e23db382a","raw_frame":"{\"market\":\"0x3b40066b5cf3871a2f6237c5628bd8092a206aa998558ac5ec13c4483e31e160\", \"price_changes\":[{\"asset_id\":\"110216635572655435074987471276357323571387854733835379371586402147734167783946\", \"price\":\"0.04\", \"size\":\"628.09\", \"side\":\"BUY\", \"hash\":\"077c68fc90c47c74c6769c80c081a79e81c5d7f8\", \"best_bid\":\"0.54\", \"best_ask\":\"0.55\"}, {\"asset_id\":\"14766054693214075530629349735273995982307625376442606753688071083149620216746\", \"price\":\"0.96\", \"size\":\"628.09\", \"side\":\"SELL\", \"hash\":\"62b69b193caf4f4123951778e9bb52e7c1d55ae4\", \"best_bid\":\"0.45\", \"best_ask\":\"0.46\"}], \"timestamp\":\"1785130325462\", \"event_type\":\"price_change\"}","received_at":"2026-07-27T05:32:05.424467Z","schema_version":"clob-market-ws.price_change.v1","sequence":null,"server_hash":null,"server_timestamp":"1785130325462","session_id":"502006c5cfcd437296561ea750c9ec8b","source":"clob_market_ws"},"received_at":"2026-07-27T05:32:05.424467Z","record_id":"da32c8fc61a3e497cf1a8989bf69e5cb09ef9640b571b6d4246b75a53cf41ffe","schema_fingerprint":"4aa3821a28b0b7c2400bc59aba4bcc0a76e971dadd19610d3ad38c768e124dc7","schema_version":"edge-lab-recorder.raw.v1","sequence":null,"source":"clob_market_ws"}
{"event_at":"2026-07-27T05:32:05.471000Z","event_fingerprint":"8362b776f24d4f9dc37bde5c8001594ff67f825d58d0d3c30161178eab08c2e3","payload":{"connection_id":"efc69d3132f1467b8e898a382b23ac0d","event_at":"2026-07-27T05:32:05.471000Z","event_type":"price_change","frame_hash":"c5489494c0040719e414b729d842d317a2bd750e87f065d76210fbd098d4e50d","frame_index":0,"kind":"data","monotonic_ns":232308672005541,"payload":{"event_type":"price_change","market":"0x3b40066b5cf3871a2f6237c5628bd8092a206aa998558ac5ec13c4483e31e160","price_changes":[{"asset_id":"110216635572655435074987471276357323571387854733835379371586402147734167783946","best_ask":"0.55","best_bid":"0.54","hash":"8d55eb88277a6df8e3b3b742320e9b5fb6915805","price":"0.01","side":"BUY","size":"7843.02"},{"asset_id":"14766054693214075530629349735273995982307625376442606753688071083149620216746","best_ask":"0.46","best_bid":"0.45","hash":"3d4b376b8388fb0a2c675d8efdf562f4969f6857","price":"0.99","side":"SELL","size":"7843.02"}],"timestamp":"1785130325471"},"payload_hash":"cc14d5c62aa9fb9c2a663f0dcd2c59e3d3ecab1ec945d7b3aad65428ce9bb737","raw_frame":"{\"market\":\"0x3b40066b5cf3871a2f6237c5628bd8092a206aa998558ac5ec13c4483e31e160\", \"price_changes\":[{\"asset_id\":\"110216635572655435074987471276357323571387854733835379371586402147734167783946\", \"price\":\"0.01\", \"size\":\"7843.02\", \"side\":\"BUY\", \"hash\":\"8d55eb88277a6df8e3b3b742320e9b5fb6915805\", \"best_bid\":\"0.54\", \"best_ask\":\"0.55\"}, {\"asset_id\":\"14766054693214075530629349735273995982307625376442606753688071083149620216746\", \"price\":\"0.99\", \"size\":\"7843.02\", \"side\":\"SELL\", \"hash\":\"3d4b376b8388fb0a2c675d8efdf562f4969f6857\", \"best_bid\":\"0.45\", \"best_ask\":\"0.46\"}], \"timestamp\":\"1785130325471\", \"event_type\":\"price_change\"}","received_at":"2026-07-27T05:32:05.434668Z","schema_version":"clob-market-ws.price_change.v1","sequence":null,"server_hash":null,"server_timestamp":"1785130325471","session_id":"502006c5cfcd437296561ea750c9ec8b","source":"clob_market_ws"},"received_at":"2026-07-27T05:32:05.434668Z","record_id":"248e41e7a48584ff1219c96778bd0d8ca3b3deb8d2c301b514da2ac229323c22","schema_fingerprint":"4aa3821a28b0b7c2400bc59aba4bcc0a76e971dadd19610d3ad38c768e124dc7","schema_version":"edge-lab-recorder.raw.v1","sequence":null,"source":"clob_market_ws"}
{"event_at":null,"event_fingerprint":"f00f65b3ee8231a843744842713ec6f45a0cf20bdabaceb3430be7ab489fae82","payload":{"connection_id":"efc69d3132f1467b8e898a382b23ac0d","event_type":"heartbeat_ack","frame_hash":"95784973cc639977bff93619700168505cb8f7855e44fa643d34622a43706c87","kind":"lifecycle","monotonic_ns":232308675377416,"raw_frame":"PONG","received_at":"2026-07-27T05:32:05.438040Z","schema_version":"edge-lab-recorder.heartbeat-ack.v1","session_id":"502006c5cfcd437296561ea750c9ec8b","source":"clob_market_ws"},"received_at":"2026-07-27T05:32:05.438040Z","record_id":"283c38b68bb0a96f028d90422cf389a8cfae88fe3a436eba1d4cf3a7cca280d0","schema_fingerprint":"c14ee1aab3ca674ee738e5268877b544d74c41ad3c427cedc09236467dc68ba1","schema_version":"edge-lab-recorder.raw.v1","sequence":null,"source":"clob_market_ws"}
{"event_at":"2026-07-27T05:32:05.479000Z","event_fingerprint":"f108c2aff95718919e325f6630ea0e7dae04c22e4538fbac7922f54c038b2431","payload":{"connection_id":"efc69d3132f1467b8e898a382b23ac0d","event_at":"2026-07-27T05:32:05.479000Z","event_type":"price_change","frame_hash":"6ccc968c5436e5666616adf6dc7be23ea47c236b9e20955ea6652968933d0387","frame_index":0,"kind":"data","monotonic_ns":232308679256583,"payload":{"event_type":"price_change","market":"0x3b40066b5cf3871a2f6237c5628bd8092a206aa998558ac5ec13c4483e31e160","price_changes":[{"asset_id":"14766054693214075530629349735273995982307625376442606753688071083149620216746","best_ask":"0.46","best_bid":"0.45","hash":"4c3c5229a0bb2c63063029500ec1bd4fec469932","price":"0.52","side":"SELL","size":"170.01"},{"asset_id":"110216635572655435074987471276357323571387854733835379371586402147734167783946","best_ask":"0.55","best_bid":"0.54","hash":"ab03b1357e5e487417cf74f1d9e58849cd3b2a7b","price":"0.48","side":"BUY","size":"170.01"}],"timestamp":"1785130325479"},"payload_hash":"92f2e4df8d5ec6a8ec4d18602b470277f3064291fcec9c583f8c0610471950e7","raw_frame":"{\"market\":\"0x3b40066b5cf3871a2f6237c5628bd8092a206aa998558ac5ec13c4483e31e160\", \"price_changes\":[{\"asset_id\":\"14766054693214075530629349735273995982307625376442606753688071083149620216746\", \"price\":\"0.52\", \"size\":\"170.01\", \"side\":\"SELL\", \"hash\":\"4c3c5229a0bb2c63063029500ec1bd4fec469932\", \"best_bid\":\"0.45\", \"best_ask\":\"0.46\"}, {\"asset_id\":\"110216635572655435074987471276357323571387854733835379371586402147734167783946\", \"price\":\"0.48\", \"size\":\"170.01\", \"side\":\"BUY\", \"hash\":\"ab03b1357e5e487417cf74f1d9e58849cd3b2a7b\", \"best_bid\":\"0.54\", \"best_ask\":\"0.55\"}], \"timestamp\":\"1785130325479\", \"event_type\":\"price_change\"}","received_at":"2026-07-27T05:32:05.441919Z","schema_version":"clob-market-ws.price_change.v1","sequence":null,"server_hash":null,"server_timestamp":"1785130325479","session_id":"502006c5cfcd437296561ea750c9ec8b","source":"clob_market_ws"},"received_at":"2026-07-27T05:32:05.441919Z","record_id":"bdb6f29091e9b43ed9d53b8c319c5fcabe8cf020a96f6d149a37f197b26786df","schema_fingerprint":"4aa3821a28b0b7c2400bc59aba4bcc0a76e971dadd19610d3ad38c768e124dc7","schema_version":"edge-lab-recorder.raw.v1","sequence":null,"source":"clob_market_ws"}
{"event_at":"2026-07-27T05:32:05.481000Z","event_fingerprint":"f82e1525eb4c9bf9dcc3adb21ff2825b5c20095451ae2ef60e2c912cc80e9412","payload":{"connection_id":"efc69d3132f1467b8e898a382b23ac0d","event_at":"2026-07-27T05:32:05.481000Z","event_type":"price_change","frame_hash":"d87a26e86b120140e62385a45f9f2bbf4dd6d52054ca9acfe019bd0e1c1616d9","frame_index":0,"kind":"data","monotonic_ns":232308683140083,"payload":{"event_type":"price_change","market":"0x3b40066b5cf3871a2f6237c5628bd8092a206aa998558ac5ec13c4483e31e160","price_changes":[{"asset_id":"110216635572655435074987471276357323571387854733835379371586402147734167783946","best_ask":"0.55","best_bid":"0.54","hash":"db7a3ee631298351870d71706673615b6ed104a9","price":"0.48","side":"BUY","size":"145.01"},{"asset_id":"14766054693214075530629349735273995982307625376442606753688071083149620216746","best_ask":"0.46","best_bid":"0.45","hash":"6497de2955b6c907592192338f396ffafb287482","price":"0.52","side":"SELL","size":"145.01"}],"timestamp":"1785130325481"},"payload_hash":"2727a27b9ca738df01be803edd730227a3c0e7f90e42620a8e22c74a0854660b","raw_frame":"{\"market\":\"0x3b40066b5cf3871a2f6237c5628bd8092a206aa998558ac5ec13c4483e31e160\", \"price_changes\":[{\"asset_id\":\"110216635572655435074987471276357323571387854733835379371586402147734167783946\", \"price\":\"0.48\", \"size\":\"145.01\", \"side\":\"BUY\", \"hash\":\"db7a3ee631298351870d71706673615b6ed104a9\", \"best_bid\":\"0.54\", \"best_ask\":\"0.55\"}, {\"asset_id\":\"14766054693214075530629349735273995982307625376442606753688071083149620216746\", \"price\":\"0.52\", \"size\":\"145.01\", \"side\":\"SELL\", \"hash\":\"6497de2955b6c907592192338f396ffafb287482\", \"best_bid\":\"0.45\", \"best_ask\":\"0.46\"}], \"timestamp\":\"1785130325481\", \"event_type\":\"price_change\"}","received_at":"2026-07-27T05:32:05.445802Z","schema_version":"clob-market-ws.price_change.v1","sequence":null,"server_hash":null,"server_timestamp":"1785130325481","session_id":"502006c5cfcd437296561ea750c9ec8b","source":"clob_market_ws"},"received_at":"2026-07-27T05:32:05.445802Z","record_id":"6228396356ea918491b0cd46cae434cfe7c8652a9c6808b1b5f3d3b4dd0a4983","schema_fingerprint":"4aa3821a28b0b7c2400bc59aba4bcc0a76e971dadd19610d3ad38c768e124dc7","schema_version":"edge-lab-recorder.raw.v1","sequence":null,"source":"clob_market_ws"}
{"event_at":"2026-07-27T05:32:05.503000Z","event_fingerprint":"2a852921bd28788ee9b069de2ad26d35e668989c306d25a8dd2cfa0ab845b0b6","payload":{"connection_id":"efc69d3132f1467b8e898a382b23ac0d","event_at":"2026-07-27T05:32:05.503000Z","event_type":"price_change","frame_hash":"c4e2a12a4e8aee6d7c3d5bf09e4b72c8fb373e7df2ecc3e0851326099dbf740c","frame_index":0,"kind":"data","monotonic_ns":232308711754291,"payload":{"event_type":"price_change","market":"0x3b40066b5cf3871a2f6237c5628bd8092a206aa998558ac5ec13c4483e31e160","price_changes":[{"asset_id":"14766054693214075530629349735273995982307625376442606753688071083149620216746","best_ask":"0.46","best_bid":"0.45","hash":"979cd0b424f6d7e8ff7b77a80b004d1e906b3ff6","price":"0.51","side":"SELL","size":"72.6"},{"asset_id":"110216635572655435074987471276357323571387854733835379371586402147734167783946","best_ask":"0.55","best_bid":"0.54","hash":"ea9b8084cc4e8c24076c865769e8f47a0c8724f6","price":"0.49","side":"BUY","size":"72.6"}],"timestamp":"1785130325503"},"payload_hash":"1a1dc88c977276fea57c21dcd5b02e5e2bd9ad831fea47ff44b54298d013ccbb","raw_frame":"{\"market\":\"0x3b40066b5cf3871a2f6237c5628bd8092a206aa998558ac5ec13c4483e31e160\", \"price_changes\":[{\"asset_id\":\"14766054693214075530629349735273995982307625376442606753688071083149620216746\", \"price\":\"0.51\", \"size\":\"72.6\", \"side\":\"SELL\", \"hash\":\"979cd0b424f6d7e8ff7b77a80b004d1e906b3ff6\", \"best_bid\":\"0.45\", \"best_ask\":\"0.46\"}, {\"asset_id\":\"110216635572655435074987471276357323571387854733835379371586402147734167783946\", \"price\":\"0.49\", \"size\":\"72.6\", \"side\":\"BUY\", \"hash\":\"ea9b8084cc4e8c24076c865769e8f47a0c8724f6\", \"best_bid\":\"0.54\", \"best_ask\":\"0.55\"}], \"timestamp\":\"1785130325503\", \"event_type\":\"price_change\"}","received_at":"2026-07-27T05:32:05.474414Z","schema_version":"clob-market-ws.price_change.v1","sequence":null,"server_hash":null,"server_timestamp":"1785130325503","session_id":"502006c5cfcd437296561ea750c9ec8b","source":"clob_market_ws"},"received_at":"2026-07-27T05:32:05.474414Z","record_id":"c6e9f0f2edf42940b9cefd4709c196dc7aeb731ae09ba3547073fda5ee06afeb","schema_fingerprint":"4aa3821a28b0b7c2400bc59aba4bcc0a76e971dadd19610d3ad38c768e124dc7","schema_version":"edge-lab-recorder.raw.v1","sequence":null,"source":"clob_market_ws"}
{"event_at":"2026-07-27T05:32:05.504000Z","event_fingerprint":"fcbde0bd59f4138b32053398eb2ad0bd956bb664bae38fe1dfd8b5141af53922","payload":{"connection_id":"efc69d3132f1467b8e898a382b23ac0d","event_at":"2026-07-27T05:32:05.504000Z","event_type":"price_change","frame_hash":"7ea9599022ccfffe1ce385308e637be794ec826c2785b325fac262a4965f9f6a","frame_index":0,"kind":"data","monotonic_ns":232308717097083,"payload":{"event_type":"price_change","market":"0x3b40066b5cf3871a2f6237c5628bd8092a206aa998558ac5ec13c4483e31e160","price_changes":[{"asset_id":"110216635572655435074987471276357323571387854733835379371586402147734167783946","best_ask":"0.55","best_bid":"0.54","hash":"4d9719b015dc71a6f16247a7daa48c427cd720ea","price":"0.49","side":"BUY","size":"97.6"},{"asset_id":"14766054693214075530629349735273995982307625376442606753688071083149620216746","best_ask":"0.46","best_bid":"0.45","hash":"cca5a7f768d548d7882871a0b7b7652165fa4a7d","price":"0.51","side":"SELL","size":"97.6"}],"timestamp":"1785130325504"},"payload_hash":"0553ae8ca8d6216ad3c326c759834e293d114836aae4cac4ab326463a5293062","raw_frame":"{\"market\":\"0x3b40066b5cf3871a2f6237c5628bd8092a206aa998558ac5ec13c4483e31e160\", \"price_changes\":[{\"asset_id\":\"110216635572655435074987471276357323571387854733835379371586402147734167783946\", \"price\":\"0.49\", \"size\":\"97.6\", \"side\":\"BUY\", \"hash\":\"4d9719b015dc71a6f16247a7daa48c427cd720ea\", \"best_bid\":\"0.54\", \"best_ask\":\"0.55\"}, {\"asset_id\":\"14766054693214075530629349735273995982307625376442606753688071083149620216746\", \"price\":\"0.51\", \"size\":\"97.6\", \"side\":\"SELL\", \"hash\":\"cca5a7f768d548d7882871a0b7b7652165fa4a7d\", \"best_bid\":\"0.45\", \"best_ask\":\"0.46\"}], \"timestamp\":\"1785130325504\", \"event_type\":\"price_change\"}","received_at":"2026-07-27T05:32:05.479760Z","schema_version":"clob-market-ws.price_change.v1","sequence":null,"server_hash":null,"server_timestamp":"1785130325504","session_id":"502006c5cfcd437296561ea750c9ec8b","source":"clob_market_ws"},"received_at":"2026-07-27T05:32:05.479760Z","record_id":"6e0d192a75404ae23453f118be8b1c8f99160c6bec15f434c5fcce2e28a3239d","schema_fingerprint":"4aa3821a28b0b7c2400bc59aba4bcc0a76e971dadd19610d3ad38c768e124dc7","schema_version":"edge-lab-recorder.raw.v1","sequence":null,"source":"clob_market_ws"}
{"event_at":"2026-07-27T05:32:05.520000Z","event_fingerprint":"d4d94ae54a848dd19fd2a71fe18a246c0cd5412784eff0cf1a99238b60cb2c41","payload":{"connection_id":"efc69d3132f1467b8e898a382b23ac0d","event_at":"2026-07-27T05:32:05.520000Z","event_type":"price_change","frame_hash":"2f75d82f1f4994f0c1317724ab25d9fcb38da4d1b906d0de3efadee904144976","frame_index":0,"kind":"data","monotonic_ns":232308724646833,"payload":{"event_type":"price_change","market":"0x3b40066b5cf3871a2f6237c5628bd8092a206aa998558ac5ec13c4483e31e160","price_changes":[{"asset_id":"14766054693214075530629349735273995982307625376442606753688071083149620216746","best_ask":"0.46","best_bid":"0.45","hash":"83cb81c332cea5500358cd29d17631086e334f31","price":"0.45","side":"BUY","size":"36.4"},{"asset_id":"110216635572655435074987471276357323571387854733835379371586402147734167783946","best_ask":"0.55","best_bid":"0.54","hash":"ba63dcef98eca7e432f1d458e0d11c8a09ac3ac2","price":"0.55","side":"SELL","size":"36.4"}],"timestamp":"1785130325520"},"payload_hash":"83ff8e84717a175ca56d6499b2221e73b95d6ecd669ba5630f12fb1ed2e77441","raw_frame":"{\"market\":\"0x3b40066b5cf3871a2f6237c5628bd8092a206aa998558ac5ec13c4483e31e160\", \"price_changes\":[{\"asset_id\":\"14766054693214075530629349735273995982307625376442606753688071083149620216746\", \"price\":\"0.45\", \"size\":\"36.4\", \"side\":\"BUY\", \"hash\":\"83cb81c332cea5500358cd29d17631086e334f31\", \"best_bid\":\"0.45\", \"best_ask\":\"0.46\"}, {\"asset_id\":\"110216635572655435074987471276357323571387854733835379371586402147734167783946\", \"price\":\"0.55\", \"size\":\"36.4\", \"side\":\"SELL\", \"hash\":\"ba63dcef98eca7e432f1d458e0d11c8a09ac3ac2\", \"best_bid\":\"0.54\", \"best_ask\":\"0.55\"}], \"timestamp\":\"1785130325520\", \"event_type\":\"price_change\"}","received_at":"2026-07-27T05:32:05.487309Z","schema_version":"clob-market-ws.price_change.v1","sequence":null,"server_hash":null,"server_timestamp":"1785130325520","session_id":"502006c5cfcd437296561ea750c9ec8b","source":"clob_market_ws"},"received_at":"2026-07-27T05:32:05.487309Z","record_id":"a746910c817a8a6fdcb3ad99c0ecf4eab91df73dbfce92c719559add17714175","schema_fingerprint":"4aa3821a28b0b7c2400bc59aba4bcc0a76e971dadd19610d3ad38c768e124dc7","schema_version":"edge-lab-recorder.raw.v1","sequence":null,"source":"clob_market_ws"}
{"event_at":"2026-07-27T05:32:05.551000Z","event_fingerprint":"855db79abb9195292260c3618b3e196ddcb5d05c3f88be1897c5c80e154548e8","payload":{"connection_id":"efc69d3132f1467b8e898a382b23ac0d","event_at":"2026-07-27T05:32:05.551000Z","event_type":"price_change","frame_hash":"fd583b7e41c3df184c15f50ccdfec14b7d065c26321742c989cbf13c6c544a21","frame_index":0,"kind":"data","monotonic_ns":232308751420375,"payload":{"event_type":"price_change","market":"0x3b40066b5cf3871a2f6237c5628bd8092a206aa998558ac5ec13c4483e31e160","price_changes":[{"asset_id":"110216635572655435074987471276357323571387854733835379371586402147734167783946","best_ask":"0.55","best_bid":"0.54","hash":"f68eed0d2aedfd3f236fa7adc79924a2d3f31e58","price":"0.01","side":"BUY","size":"7848.02"},{"asset_id":"14766054693214075530629349735273995982307625376442606753688071083149620216746","best_ask":"0.46","best_bid":"0.45","hash":"398427524c83d36182149f26fb5eb076a9a87c65","price":"0.99","side":"SELL","size":"7848.02"}],"timestamp":"1785130325551"},"payload_hash":"f502dee32001e3d8bf4181156d0730f8397b9c7ca64512ebb218efb45bc52dde","raw_frame":"{\"market\":\"0x3b40066b5cf3871a2f6237c5628bd8092a206aa998558ac5ec13c4483e31e160\", \"price_changes\":[{\"asset_id\":\"110216635572655435074987471276357323571387854733835379371586402147734167783946\", \"price\":\"0.01\", \"size\":\"7848.02\", \"side\":\"BUY\", \"hash\":\"f68eed0d2aedfd3f236fa7adc79924a2d3f31e58\", \"best_bid\":\"0.54\", \"best_ask\":\"0.55\"}, {\"asset_id\":\"14766054693214075530629349735273995982307625376442606753688071083149620216746\", \"price\":\"0.99\", \"size\":\"7848.02\", \"side\":\"SELL\", \"hash\":\"398427524c83d36182149f26fb5eb076a9a87c65\", \"best_bid\":\"0.45\", \"best_ask\":\"0.46\"}], \"timestamp\":\"1785130325551\", \"event_type\":\"price_change\"}","received_at":"2026-07-27T05:32:05.514086Z","schema_version":"clob-market-ws.price_change.v1","sequence":null,"server_hash":null,"server_timestamp":"1785130325551","session_id":"502006c5cfcd437296561ea750c9ec8b","source":"clob_market_ws"},"received_at":"2026-07-27T05:32:05.514086Z","record_id":"a84b7f635e8bafca484134c7f5d5efc812f7bd0e6075ab8f6ff97dfe3b771b18","schema_fingerprint":"4aa3821a28b0b7c2400bc59aba4bcc0a76e971dadd19610d3ad38c768e124dc7","schema_version":"edge-lab-recorder.raw.v1","sequence":null,"source":"clob_market_ws"}
{"event_at":"2026-07-27T05:32:05.575000Z","event_fingerprint":"745c8fb255a1e0f8395b0bf7134bbfbdeb000630a2351fce83db965e888aca75","payload":{"connection_id":"efc69d3132f1467b8e898a382b23ac0d","event_at":"2026-07-27T05:32:05.575000Z","event_type":"price_change","frame_hash":"75e255ed4ee9d3e1b96d9457e46f6bb63a60eb08db273d41d13b333f63471e8a","frame_index":0,"kind":"data","monotonic_ns":232308773354541,"payload":{"event_type":"price_change","market":"0x3b40066b5cf3871a2f6237c5628bd8092a206aa998558ac5ec13c4483e31e160","price_changes":[{"asset_id":"110216635572655435074987471276357323571387854733835379371586402147734167783946","best_ask":"0.55","best_bid":"0.54","hash":"8fe6f9d7017445162490577426350fb8d4803fe6","price":"0.45","side":"BUY","size":"168"},{"asset_id":"14766054693214075530629349735273995982307625376442606753688071083149620216746","best_ask":"0.46","best_bid":"0.45","hash":"f8832ef62546410ce953b0abe2e14599384e7d85","price":"0.55","side":"SELL","size":"168"}],"timestamp":"1785130325575"},"payload_hash":"081d32c56c7bbf84d6b99e22922ad7136b41df19529cbe3bc2ab61fc64dbd4ac","raw_frame":"{\"market\":\"0x3b40066b5cf3871a2f6237c5628bd8092a206aa998558ac5ec13c4483e31e160\", \"price_changes\":[{\"asset_id\":\"110216635572655435074987471276357323571387854733835379371586402147734167783946\", \"price\":\"0.45\", \"size\":\"168\", \"side\":\"BUY\", \"hash\":\"8fe6f9d7017445162490577426350fb8d4803fe6\", \"best_bid\":\"0.54\", \"best_ask\":\"0.55\"}, {\"asset_id\":\"14766054693214075530629349735273995982307625376442606753688071083149620216746\", \"price\":\"0.55\", \"size\":\"168\", \"side\":\"SELL\", \"hash\":\"f8832ef62546410ce953b0abe2e14599384e7d85\", \"best_bid\":\"0.45\", \"best_ask\":\"0.46\"}], \"timestamp\":\"1785130325575\", \"event_type\":\"price_change\"}","received_at":"2026-07-27T05:32:05.536016Z","schema_version":"clob-market-ws.price_change.v1","sequence":null,"server_hash":null,"server_timestamp":"1785130325575","session_id":"502006c5cfcd437296561ea750c9ec8b","source":"clob_market_ws"},"received_at":"2026-07-27T05:32:05.536016Z","record_id":"5c3ac5b9f39712fe65720ab19af9e45347804777d99a37b0e771088b3d891dfb","schema_fingerprint":"4aa3821a28b0b7c2400bc59aba4bcc0a76e971dadd19610d3ad38c768e124dc7","schema_version":"edge-lab-recorder.raw.v1","sequence":null,"source":"clob_market_ws"}
{"event_at":"2026-07-27T05:32:05.579000Z","event_fingerprint":"90cb3c64e2447a6bb40e19c1b4944d4cd1d6af79d62b9cb3495822eb709747f0","payload":{"connection_id":"efc69d3132f1467b8e898a382b23ac0d","event_at":"2026-07-27T05:32:05.579000Z","event_type":"price_change","frame_hash":"5c1330682f580a9e1f09a28364318541f02a34cfa15ddcedcd2a2a81a9f573fb","frame_index":0,"kind":"data","monotonic_ns":232308778827583,"payload":{"event_type":"price_change","market":"0x3b40066b5cf3871a2f6237c5628bd8092a206aa998558ac5ec13c4483e31e160","price_changes":[{"asset_id":"110216635572655435074987471276357323571387854733835379371586402147734167783946","best_ask":"0.55","best_bid":"0.54","hash":"bad7d3237f97fdcb817b9a9c0c31f5f2f5881caf","price":"0.49","side":"BUY","size":"109.6"},{"asset_id":"14766054693214075530629349735273995982307625376442606753688071083149620216746","best_ask":"0.46","best_bid":"0.45","hash":"3f26dd58a6ff98f0e2a10e8aae4e99269f63c9cd","price":"0.51","side":"SELL","size":"109.6"}],"timestamp":"1785130325579"},"payload_hash":"57e10b8ffca9c3956051b55eb4cd3d32fd1ec2966756c9e2f7eac472ef2079c0","raw_frame":"{\"market\":\"0x3b40066b5cf3871a2f6237c5628bd8092a206aa998558ac5ec13c4483e31e160\", \"price_changes\":[{\"asset_id\":\"110216635572655435074987471276357323571387854733835379371586402147734167783946\", \"price\":\"0.49\", \"size\":\"109.6\", \"side\":\"BUY\", \"hash\":\"bad7d3237f97fdcb817b9a9c0c31f5f2f5881caf\", \"best_bid\":\"0.54\", \"best_ask\":\"0.55\"}, {\"asset_id\":\"14766054693214075530629349735273995982307625376442606753688071083149620216746\", \"price\":\"0.51\", \"size\":\"109.6\", \"side\":\"SELL\", \"hash\":\"3f26dd58a6ff98f0e2a10e8aae4e99269f63c9cd\", \"best_bid\":\"0.45\", \"best_ask\":\"0.46\"}], \"timestamp\":\"1785130325579\", \"event_type\":\"price_change\"}","received_at":"2026-07-27T05:32:05.541484Z","schema_version":"clob-market-ws.price_change.v1","sequence":null,"server_hash":null,"server_timestamp":"1785130325579","session_id":"502006c5cfcd437296561ea750c9ec8b","source":"clob_market_ws"},"received_at":"2026-07-27T05:32:05.541484Z","record_id":"0b4ec9cf42d2e7b5bfbc24a5fa59118467101ba83b0164dc6e6951ab131d42c1","schema_fingerprint":"4aa3821a28b0b7c2400bc59aba4bcc0a76e971dadd19610d3ad38c768e124dc7","schema_version":"edge-lab-recorder.raw.v1","sequence":null,"source":"clob_market_ws"}
{"event_at":"2026-07-27T05:32:05.607000Z","event_fingerprint":"9c164c68966e173a201d4b70d67816569acee225b1250d4b51a32eb0c67e6d3b","payload":{"connection_id":"efc69d3132f1467b8e898a382b23ac0d","event_at":"2026-07-27T05:32:05.607000Z","event_type":"price_change","frame_hash":"38b58911ea5bc1314c12ff6c4854659fd2748ce6b9e9a2b33ac709659213dc9e","frame_index":0,"kind":"data","monotonic_ns":232308806769416,"payload":{"event_type":"price_change","market":"0x3b40066b5cf3871a2f6237c5628bd8092a206aa998558ac5ec13c4483e31e160","price_changes":[{"asset_id":"110216635572655435074987471276357323571387854733835379371586402147734167783946","best_ask":"0.55","best_bid":"0.54","hash":"500c78dc3fff36872191e4d90abcc6fa585b5a23","price":"0.01","side":"BUY","size":"7843.02"},{"asset_id":"14766054693214075530629349735273995982307625376442606753688071083149620216746","best_ask":"0.46","best_bid":"0.45","hash":"eb22469d0a03ce99c4b0a4f5d0bed5c6052b39be","price":"0.99","side":"SELL","size":"7843.02"}],"timestamp":"1785130325607"},"payload_hash":"54b1d4adc314a7dc243898aee0f5ac0e5e9aa7ea548da15959a28bccb6fb6164","raw_frame":"{\"market\":\"0x3b40066b5cf3871a2f6237c5628bd8092a206aa998558ac5ec13c4483e31e160\", \"price_changes\":[{\"asset_id\":\"110216635572655435074987471276357323571387854733835379371586402147734167783946\", \"price\":\"0.01\", \"size\":\"7843.02\", \"side\":\"BUY\", \"hash\":\"500c78dc3fff36872191e4d90abcc6fa585b5a23\", \"best_bid\":\"0.54\", \"best_ask\":\"0.55\"}, {\"asset_id\":\"14766054693214075530629349735273995982307625376442606753688071083149620216746\", \"price\":\"0.99\", \"size\":\"7843.02\", \"side\":\"SELL\", \"hash\":\"eb22469d0a03ce99c4b0a4f5d0bed5c6052b39be\", \"best_bid\":\"0.45\", \"best_ask\":\"0.46\"}], \"timestamp\":\"1785130325607\", \"event_type\":\"price_change\"}","received_at":"2026-07-27T05:32:05.569432Z","schema_version":"clob-market-ws.price_change.v1","sequence":null,"server_hash":null,"server_timestamp":"1785130325607","session_id":"502006c5cfcd437296561ea750c9ec8b","source":"clob_market_ws"},"received_at":"2026-07-27T05:32:05.569432Z","record_id":"f59aa8a0c84933a1b1a9d51c29a1cda2ec13deef48fa419dff4f30035cd350c4","schema_fingerprint":"4aa3821a28b0b7c2400bc59aba4bcc0a76e971dadd19610d3ad38c768e124dc7","schema_version":"edge-lab-recorder.raw.v1","sequence":null,"source":"clob_market_ws"}
{"event_at":"2026-07-27T05:32:05.678000Z","event_fingerprint":"89da7c691a784780726d5ac0f6b5daf4c47c896c0577b26f6d16f287e537a2c4","payload":{"connection_id":"efc69d3132f1467b8e898a382b23ac0d","event_at":"2026-07-27T05:32:05.678000Z","event_type":"price_change","frame_hash":"4143d17472e0337f582ad2e76008b39ffa4b6057cc85216d1ef37eeb0cdbcfbe","frame_index":0,"kind":"data","monotonic_ns":232308876807708,"payload":{"event_type":"price_change","market":"0x3b40066b5cf3871a2f6237c5628bd8092a206aa998558ac5ec13c4483e31e160","price_changes":[{"asset_id":"110216635572655435074987471276357323571387854733835379371586402147734167783946","best_ask":"0.55","best_bid":"0.54","hash":"ce4145f18c04d7d41aeb035edf24cdeb49348eaf","price":"0.49","side":"BUY","size":"84.6"},{"asset_id":"14766054693214075530629349735273995982307625376442606753688071083149620216746","best_ask":"0.46","best_bid":"0.45","hash":"5c8fcb6451e86a21ceb2e1e729915e69f6e5ea1c","price":"0.51","side":"SELL","size":"84.6"}],"timestamp":"1785130325678"},"payload_hash":"141bc97fe525b6a08d9fbb9829da44c0a025120c1e1b5e442c518d36fb66a952","raw_frame":"{\"market\":\"0x3b40066b5cf3871a2f6237c5628bd8092a206aa998558ac5ec13c4483e31e160\", \"price_changes\":[{\"asset_id\":\"110216635572655435074987471276357323571387854733835379371586402147734167783946\", \"price\":\"0.49\", \"size\":\"84.6\", \"side\":\"BUY\", \"hash\":\"ce4145f18c04d7d41aeb035edf24cdeb49348eaf\", \"best_bid\":\"0.54\", \"best_ask\":\"0.55\"}, {\"asset_id\":\"14766054693214075530629349735273995982307625376442606753688071083149620216746\", \"price\":\"0.51\", \"size\":\"84.6\", \"side\":\"SELL\", \"hash\":\"5c8fcb6451e86a21ceb2e1e729915e69f6e5ea1c\", \"best_bid\":\"0.45\", \"best_ask\":\"0.46\"}], \"timestamp\":\"1785130325678\", \"event_type\":\"price_change\"}","received_at":"2026-07-27T05:32:05.639471Z","schema_version":"clob-market-ws.price_change.v1","sequence":null,"server_hash":null,"server_timestamp":"1785130325678","session_id":"502006c5cfcd437296561ea750c9ec8b","source":"clob_market_ws"},"received_at":"2026-07-27T05:32:05.639471Z","record_id":"4f13564305c877a50056e7c9978e1f520cb4e2276bcfb463601e939e52e6f892","schema_fingerprint":"4aa3821a28b0b7c2400bc59aba4bcc0a76e971dadd19610d3ad38c768e124dc7","schema_version":"edge-lab-recorder.raw.v1","sequence":null,"source":"clob_market_ws"}
{"event_at":"2026-07-27T05:32:05.680000Z","event_fingerprint":"eb984fcbb3577c35520fda4c450ba24baa896a15041bebe46df4591b4f40ba67","payload":{"connection_id":"efc69d3132f1467b8e898a382b23ac0d","event_at":"2026-07-27T05:32:05.680000Z","event_type":"price_change","frame_hash":"b572b150fb8bbd964ea3fd1f874d5e794f05155b2193d77df63769402e5c6c2b","frame_index":0,"kind":"data","monotonic_ns":232308880779541,"payload":{"event_type":"price_change","market":"0x3b40066b5cf3871a2f6237c5628bd8092a206aa998558ac5ec13c4483e31e160","price_changes":[{"asset_id":"14766054693214075530629349735273995982307625376442606753688071083149620216746","best_ask":"0.46","best_bid":"0.45","hash":"f99a16c3cc03d3aef2d1a33efd9c742fad52d24f","price":"0.51","side":"SELL","size":"59.6"},{"asset_id":"110216635572655435074987471276357323571387854733835379371586402147734167783946","best_ask":"0.55","best_bid":"0.54","hash":"0a43ce6ab27751323f22cec5d0fa61ed04763f4f","price":"0.49","side":"BUY","size":"59.6"}],"timestamp":"1785130325680"},"payload_hash":"1e51929b47b148b61152b4c56cbb6e345576a90e9f505765477b3ce1dcfd383e","raw_frame":"{\"market\":\"0x3b40066b5cf3871a2f6237c5628bd8092a206aa998558ac5ec13c4483e31e160\", \"price_changes\":[{\"asset_id\":\"14766054693214075530629349735273995982307625376442606753688071083149620216746\", \"price\":\"0.51\", \"size\":\"59.6\", \"side\":\"SELL\", \"hash\":\"f99a16c3cc03d3aef2d1a33efd9c742fad52d24f\", \"best_bid\":\"0.45\", \"best_ask\":\"0.46\"}, {\"asset_id\":\"110216635572655435074987471276357323571387854733835379371586402147734167783946\", \"price\":\"0.49\", \"size\":\"59.6\", \"side\":\"BUY\", \"hash\":\"0a43ce6ab27751323f22cec5d0fa61ed04763f4f\", \"best_bid\":\"0.54\", \"best_ask\":\"0.55\"}], \"timestamp\":\"1785130325680\", \"event_type\":\"price_change\"}","received_at":"2026-07-27T05:32:05.643443Z","schema_version":"clob-market-ws.price_change.v1","sequence":null,"server_hash":null,"server_timestamp":"1785130325680","session_id":"502006c5cfcd437296561ea750c9ec8b","source":"clob_market_ws"},"received_at":"2026-07-27T05:32:05.643443Z","record_id":"a8d10ae40a62879e2eb3624ed6d7e950c852cbb11b7d437e67d7977de6fd4857","schema_fingerprint":"4aa3821a28b0b7c2400bc59aba4bcc0a76e971dadd19610d3ad38c768e124dc7","schema_version":"edge-lab-recorder.raw.v1","sequence":null,"source":"clob_market_ws"}
{"event_at":"2026-07-27T05:32:05.692000Z","event_fingerprint":"fa61364ecb481e4a6b4c1de0d08329365938916603186021784f525db43b5d93","payload":{"connection_id":"efc69d3132f1467b8e898a382b23ac0d","event_at":"2026-07-27T05:32:05.692000Z","event_type":"price_change","frame_hash":"03acce457a2d0bedf3be51cdff7fd81742e2bc44f41005b889056cb6be8f7ec7","frame_index":0,"kind":"data","monotonic_ns":232308893408291,"payload":{"event_type":"price_change","market":"0x3b40066b5cf3871a2f6237c5628bd8092a206aa998558ac5ec13c4483e31e160","price_changes":[{"asset_id":"110216635572655435074987471276357323571387854733835379371586402147734167783946","best_ask":"0.55","best_bid":"0.54","hash":"e8bf59992efc7f17db5ec60162cd3b6c501aa35f","price":"0.47","side":"BUY","size":"45.03"},{"asset_id":"14766054693214075530629349735273995982307625376442606753688071083149620216746","best_ask":"0.46","best_bid":"0.45","hash":"5890da4d5a01856d8dbc2c34ecfd5a33de1d866e","price":"0.53","side":"SELL","size":"45.03"}],"timestamp":"1785130325692"},"payload_hash":"b77ce0552241e1f697e6ec307e5af320065d1eb90d4837164126a9dcf6455d6b","raw_frame":"{\"market\":\"0x3b40066b5cf3871a2f6237c5628bd8092a206aa998558ac5ec13c4483e31e160\", \"price_changes\":[{\"asset_id\":\"110216635572655435074987471276357323571387854733835379371586402147734167783946\", \"price\":\"0.47\", \"size\":\"45.03\", \"side\":\"BUY\", \"hash\":\"e8bf59992efc7f17db5ec60162cd3b6c501aa35f\", \"best_bid\":\"0.54\", \"best_ask\":\"0.55\"}, {\"asset_id\":\"14766054693214075530629349735273995982307625376442606753688071083149620216746\", \"price\":\"0.53\", \"size\":\"45.03\", \"side\":\"SELL\", \"hash\":\"5890da4d5a01856d8dbc2c34ecfd5a33de1d866e\", \"best_bid\":\"0.45\", \"best_ask\":\"0.46\"}], \"timestamp\":\"1785130325692\", \"event_type\":\"price_change\"}","received_at":"2026-07-27T05:32:05.656071Z","schema_version":"clob-market-ws.price_change.v1","sequence":null,"server_hash":null,"server_timestamp":"1785130325692","session_id":"502006c5cfcd437296561ea750c9ec8b","source":"clob_market_ws"},"received_at":"2026-07-27T05:32:05.656071Z","record_id":"32d196dd77cfbf7be447b60119dd105ce98d1056780ca919c7769231961299ce","schema_fingerprint":"4aa3821a28b0b7c2400bc59aba4bcc0a76e971dadd19610d3ad38c768e124dc7","schema_version":"edge-lab-recorder.raw.v1","sequence":null,"source":"clob_market_ws"}
