{"event_at":"2026-07-27T05:42:11.686000Z","event_fingerprint":"d7acd0fa9dd864500a8918ada7f248215dbed7e89fce2aa2787729b34d0b54a4","payload":{"connection_id":"efc69d3132f1467b8e898a382b23ac0d","event_at":"2026-07-27T05:42:11.686000Z","event_type":"price_change","frame_hash":"0ff5a969eeab7f472f49389df964bad94c5ae18060fc45e48c60a912c3f7db44","frame_index":0,"kind":"data","monotonic_ns":232915198705208,"payload":{"event_type":"price_change","market":"0x3b40066b5cf3871a2f6237c5628bd8092a206aa998558ac5ec13c4483e31e160","price_changes":[{"asset_id":"14766054693214075530629349735273995982307625376442606753688071083149620216746","best_ask":"0.74","best_bid":"0.73","hash":"93c6357747f74ad2508f872f8489fb8ee438d29e","price":"0.62","side":"BUY","size":"68"},{"asset_id":"110216635572655435074987471276357323571387854733835379371586402147734167783946","best_ask":"0.27","best_bid":"0.26","hash":"74d039efcdab7b5f0fac1dfea7336797c443ac3f","price":"0.38","side":"SELL","size":"68"}],"timestamp":"1785130931686"},"payload_hash":"45c14ccb7650c1075bee6e65364634be6a2a8fd36121537eaef0b90858eb5f89","raw_frame":"{\"market\":\"0x3b40066b5cf3871a2f6237c5628bd8092a206aa998558ac5ec13c4483e31e160\", \"price_changes\":[{\"asset_id\":\"14766054693214075530629349735273995982307625376442606753688071083149620216746\", \"price\":\"0.62\", \"size\":\"68\", \"side\":\"BUY\", \"hash\":\"93c6357747f74ad2508f872f8489fb8ee438d29e\", \"best_bid\":\"0.73\", \"best_ask\":\"0.74\"}, {\"asset_id\":\"110216635572655435074987471276357323571387854733835379371586402147734167783946\", \"price\":\"0.38\", \"size\":\"68\", \"side\":\"SELL\", \"hash\":\"74d039efcdab7b5f0fac1dfea7336797c443ac3f\", \"best_bid\":\"0.26\", \"best_ask\":\"0.27\"}], \"timestamp\":\"1785130931686\", \"event_type\":\"price_change\"}","received_at":"2026-07-27T05:42:11.965581Z","schema_version":"clob-market-ws.price_change.v1","sequence":null,"server_hash":null,"server_timestamp":"1785130931686","session_id":"502006c5cfcd437296561ea750c9ec8b","source":"clob_market_ws"},"received_at":"2026-07-27T05:42:11.965581Z","record_id":"7e3fb44c095ec2134a8d0d8feadc50fcc41daaaf24bfcb553be4ddbb6b970fd2","schema_fingerprint":"4aa3821a28b0b7c2400bc59aba4bcc0a76e971dadd19610d3ad38c768e124dc7","schema_version":"edge-lab-recorder.raw.v1","sequence":null,"source":"clob_market_ws"}
{"event_at":"2026-07-27T05:42:11.689000Z","event_fingerprint":"57bcd2e4b7e8d67a4d3f198430b8ff45d349c9d97de17508518354484d01a2f5","payload":{"connection_id":"efc69d3132f1467b8e898a382b23ac0d","event_at":"2026-07-27T05:42:11.689000Z","event_type":"price_change","frame_hash":"94526de0b37d836fc9b109269fb09708caf2473e497a75ba01ae9c58579f89fb","frame_index":0,"kind":"data","monotonic_ns":232915208824583,"payload":{"event_type":"price_change","market":"0x3b40066b5cf3871a2f6237c5628bd8092a206aa998558ac5ec13c4483e31e160","price_changes":[{"asset_id":"110216635572655435074987471276357323571387854733835379371586402147734167783946","best_ask":"0.27","best_bid":"0.26","hash":"8083da4684d4ce9e59bbf734a09562ea1a1b2b77","price":"0.23","side":"BUY","size":"59.4"},{"asset_id":"14766054693214075530629349735273995982307625376442606753688071083149620216746","best_ask":"0.74","best_bid":"0.73","hash":"f9d4d5ddd51afb361b554213e5a6924d5e1e9ff7","price":"0.77","side":"SELL","size":"59.4"}],"timestamp":"1785130931689"},"payload_hash":"58741f77be0bfdc79e7dc06634cecdc4b3430f3faa128e886fbd2bf2f98509ca","raw_frame":"{\"market\":\"0x3b40066b5cf3871a2f6237c5628bd8092a206aa998558ac5ec13c4483e31e160\", \"price_changes\":[{\"asset_id\":\"110216635572655435074987471276357323571387854733835379371586402147734167783946\", \"price\":\"0.23\", \"size\":\"59.4\", \"side\":\"BUY\", \"hash\":\"8083da4684d4ce9e59bbf734a09562ea1a1b2b77\", \"best_bid\":\"0.26\", \"best_ask\":\"0.27\"}, {\"asset_id\":\"14766054693214075530629349735273995982307625376442606753688071083149620216746\", \"price\":\"0.77\", \"size\":\"59.4\", \"side\":\"SELL\", \"hash\":\"f9d4d5ddd51afb361b554213e5a6924d5e1e9ff7\", \"best_bid\":\"0.73\", \"best_ask\":\"0.74\"}], \"timestamp\":\"1785130931689\", \"event_type\":\"price_change\"}","received_at":"2026-07-27T05:42:11.975701Z","schema_version":"clob-market-ws.price_change.v1","sequence":null,"server_hash":null,"server_timestamp":"1785130931689","session_id":"502006c5cfcd437296561ea750c9ec8b","source":"clob_market_ws"},"received_at":"2026-07-27T05:42:11.975701Z","record_id":"85ac2a148045a89186ebc2fb5a5ab85d6787e2ab864889984d50c3c4d6c1c752","schema_fingerprint":"4aa3821a28b0b7c2400bc59aba4bcc0a76e971dadd19610d3ad38c768e124dc7","schema_version":"edge-lab-recorder.raw.v1","sequence":null,"source":"clob_market_ws"}
{"event_at":"2026-07-27T05:42:11.693000Z","event_fingerprint":"b4ddb967c24b643e92a38e4c5660aa6274a30e31e6c2c1ca564405a302463355","payload":{"connection_id":"efc69d3132f1467b8e898a382b23ac0d","event_at":"2026-07-27T05:42:11.693000Z","event_type":"price_change","frame_hash":"4371d313f5ffe3fbcc00b70e6cfbd70065d556dffd57052949a96a76dcb68e61","frame_index":0,"kind":"data","monotonic_ns":232915211706666,"payload":{"event_type":"price_change","market":"0x3b40066b5cf3871a2f6237c5628bd8092a206aa998558ac5ec13c4483e31e160","price_changes":[{"asset_id":"14766054693214075530629349735273995982307625376442606753688071083149620216746","best_ask":"0.74","best_bid":"0.73","hash":"48d93fb5cf72a4d9647705314a1046c1e538202e","price":"0.73","side":"BUY","size":"102"},{"asset_id":"110216635572655435074987471276357323571387854733835379371586402147734167783946","best_ask":"0.27","best_bid":"0.26","hash":"c1b87cdb1f353ad59d814a08bfbcd118bcdda28a","price":"0.27","side":"SELL","size":"102"}],"timestamp":"1785130931693"},"payload_hash":"07f1555ca77553e1a686c23a527f03024c7b6a3b4b105828b702437b4b16a83a","raw_frame":"{\"market\":\"0x3b40066b5cf3871a2f6237c5628bd8092a206aa998558ac5ec13c4483e31e160\", \"price_changes\":[{\"asset_id\":\"14766054693214075530629349735273995982307625376442606753688071083149620216746\", \"price\":\"0.73\", \"size\":\"102\", \"side\":\"BUY\", \"hash\":\"48d93fb5cf72a4d9647705314a1046c1e538202e\", \"best_bid\":\"0.73\", \"best_ask\":\"0.74\"}, {\"asset_id\":\"110216635572655435074987471276357323571387854733835379371586402147734167783946\", \"price\":\"0.27\", \"size\":\"102\", \"side\":\"SELL\", \"hash\":\"c1b87cdb1f353ad59d814a08bfbcd118bcdda28a\", \"best_bid\":\"0.26\", \"best_ask\":\"0.27\"}], \"timestamp\":\"1785130931693\", \"event_type\":\"price_change\"}","received_at":"2026-07-27T05:42:11.978583Z","schema_version":"clob-market-ws.price_change.v1","sequence":null,"server_hash":null,"server_timestamp":"1785130931693","session_id":"502006c5cfcd437296561ea750c9ec8b","source":"clob_market_ws"},"received_at":"2026-07-27T05:42:11.978583Z","record_id":"e3fa0a030a75830916f15dfb5d069109123c41d19188cd858a2867b1372f58b7","schema_fingerprint":"4aa3821a28b0b7c2400bc59aba4bcc0a76e971dadd19610d3ad38c768e124dc7","schema_version":"edge-lab-recorder.raw.v1","sequence":null,"source":"clob_market_ws"}
{"event_at":"2026-07-27T05:42:11.693000Z","event_fingerprint":"0d65cdf626b9e76fcd0ab5620ea5482688020aea3d63b22c8af21c3671b2a196","payload":{"connection_id":"efc69d3132f1467b8e898a382b23ac0d","event_at":"2026-07-27T05:42:11.693000Z","event_type":"price_change","frame_hash":"cf47feefe32c81dc4ee7456360285e3dbbd1330f3c31f9c8566b38885aa984f7","frame_index":0,"kind":"data","monotonic_ns":232915215115458,"payload":{"event_type":"price_change","market":"0x3b40066b5cf3871a2f6237c5628bd8092a206aa998558ac5ec13c4483e31e160","price_changes":[{"asset_id":"110216635572655435074987471276357323571387854733835379371586402147734167783946","best_ask":"0.27","best_bid":"0.26","hash":"5cefb104007643f16f5bbdf163417fabb480cb92","price":"0.24","side":"BUY","size":"33"},{"asset_id":"14766054693214075530629349735273995982307625376442606753688071083149620216746","best_ask":"0.74","best_bid":"0.73","hash":"1f650a9335abcb444a731c7fa7912b62179ce7eb","price":"0.76","side":"SELL","size":"33"}],"timestamp":"1785130931693"},"payload_hash":"bf9e20bf9093e4e20951b93f9bc7e9fd259942fa0e022de6244a32f419debc19","raw_frame":"{\"market\":\"0x3b40066b5cf3871a2f6237c5628bd8092a206aa998558ac5ec13c4483e31e160\", \"price_changes\":[{\"asset_id\":\"110216635572655435074987471276357323571387854733835379371586402147734167783946\", \"price\":\"0.24\", \"size\":\"33\", \"side\":\"BUY\", \"hash\":\"5cefb104007643f16f5bbdf163417fabb480cb92\", \"best_bid\":\"0.26\", \"best_ask\":\"0.27\"}, {\"asset_id\":\"14766054693214075530629349735273995982307625376442606753688071083149620216746\", \"price\":\"0.76\", \"size\":\"33\", \"side\":\"SELL\", \"hash\":\"1f650a9335abcb444a731c7fa7912b62179ce7eb\", \"best_bid\":\"0.73\", \"best_ask\":\"0.74\"}], \"timestamp\":\"1785130931693\", \"event_type\":\"price_change\"}","received_at":"2026-07-27T05:42:11.981991Z","schema_version":"clob-market-ws.price_change.v1","sequence":null,"server_hash":null,"server_timestamp":"1785130931693","session_id":"502006c5cfcd437296561ea750c9ec8b","source":"clob_market_ws"},"received_at":"2026-07-27T05:42:11.981991Z","record_id":"920090edcad14b083526235c4130dca05a6d8e26eff581708a3918ef4247ed89","schema_fingerprint":"4aa3821a28b0b7c2400bc59aba4bcc0a76e971dadd19610d3ad38c768e124dc7","schema_version":"edge-lab-recorder.raw.v1","sequence":null,"source":"clob_market_ws"}
{"event_at":"2026-07-27T05:42:11.695000Z","event_fingerprint":"87c99b8cc931d3d4581e438e6b3d8376f29eb711cffc0ba385e230ba4bd1ac87","payload":{"connection_id":"efc69d3132f1467b8e898a382b23ac0d","event_at":"2026-07-27T05:42:11.695000Z","event_type":"price_change","frame_hash":"a97436274147db60111b0f6aa17df2b0dbe7146a6e4f224fbad58deb558d40af","frame_index":0,"kind":"data","monotonic_ns":232915218170833,"payload":{"event_type":"price_change","market":"0x3b40066b5cf3871a2f6237c5628bd8092a206aa998558ac5ec13c4483e31e160","price_changes":[{"asset_id":"14766054693214075530629349735273995982307625376442606753688071083149620216746","best_ask":"0.74","best_bid":"0.73","hash":"620eb0067a6a9fd84496bd808fdc176b9748ecdd","price":"0.78","side":"SELL","size":"94.4"},{"asset_id":"110216635572655435074987471276357323571387854733835379371586402147734167783946","best_ask":"0.27","best_bid":"0.26","hash":"3937152485e69b4dd3bb6d94c38526c322a74c1a","price":"0.22","side":"BUY","size":"94.4"}],"timestamp":"1785130931695"},"payload_hash":"9ce61332c879534ae22274afebb397fb9ed9ae3d8d9dcaa7cfedb7e4497c881b","raw_frame":"{\"market\":\"0x3b40066b5cf3871a2f6237c5628bd8092a206aa998558ac5ec13c4483e31e160\", \"price_changes\":[{\"asset_id\":\"14766054693214075530629349735273995982307625376442606753688071083149620216746\", \"price\":\"0.78\", \"size\":\"94.4\", \"side\":\"SELL\", \"hash\":\"620eb0067a6a9fd84496bd808fdc176b9748ecdd\", \"best_bid\":\"0.73\", \"best_ask\":\"0.74\"}, {\"asset_id\":\"110216635572655435074987471276357323571387854733835379371586402147734167783946\", \"price\":\"0.22\", \"size\":\"94.4\", \"side\":\"BUY\", \"hash\":\"3937152485e69b4dd3bb6d94c38526c322a74c1a\", \"best_bid\":\"0.26\", \"best_ask\":\"0.27\"}], \"timestamp\":\"1785130931695\", \"event_type\":\"price_change\"}","received_at":"2026-07-27T05:42:11.985047Z","schema_version":"clob-market-ws.price_change.v1","sequence":null,"server_hash":null,"server_timestamp":"1785130931695","session_id":"502006c5cfcd437296561ea750c9ec8b","source":"clob_market_ws"},"received_at":"2026-07-27T05:42:11.985047Z","record_id":"f4e94026c5d536b1501056406e116b4081b25ca3c2a7daf87d93ca2ef4c3212f","schema_fingerprint":"4aa3821a28b0b7c2400bc59aba4bcc0a76e971dadd19610d3ad38c768e124dc7","schema_version":"edge-lab-recorder.raw.v1","sequence":null,"source":"clob_market_ws"}
{"event_at":"2026-07-27T05:42:11.695000Z","event_fingerprint":"73f94fb7f7f050e4c3d91c51336ff76a61adeb14e6cab126f799a70829a8ffcb","payload":{"connection_id":"efc69d3132f1467b8e898a382b23ac0d","event_at":"2026-07-27T05:42:11.695000Z","event_type":"price_change","frame_hash":"be8694d5786b8377d1173b6d14bf2d5bb54a949a4c9aa92f82092c7ef2565256","frame_index":0,"kind":"data","monotonic_ns":232915221003958,"payload":{"event_type":"price_change","market":"0x3b40066b5cf3871a2f6237c5628bd8092a206aa998558ac5ec13c4483e31e160","price_changes":[{"asset_id":"110216635572655435074987471276357323571387854733835379371586402147734167783946","best_ask":"0.27","best_bid":"0.26","hash":"435f4a2fc63aea5653f6262ce289e8cec81d57c9","price":"0.22","side":"BUY","size":"69.4"},{"asset_id":"14766054693214075530629349735273995982307625376442606753688071083149620216746","best_ask":"0.74","best_bid":"0.73","hash":"9be9177838a74700bc7c4169440d74f935bcce7e","price":"0.78","side":"SELL","size":"69.4"}],"timestamp":"1785130931695"},"payload_hash":"3c055937cb53460509f37687e62e7a6d43329a773a33ce64c60915bfb05fb785","raw_frame":"{\"market\":\"0x3b40066b5cf3871a2f6237c5628bd8092a206aa998558ac5ec13c4483e31e160\", \"price_changes\":[{\"asset_id\":\"110216635572655435074987471276357323571387854733835379371586402147734167783946\", \"price\":\"0.22\", \"size\":\"69.4\", \"side\":\"BUY\", \"hash\":\"435f4a2fc63aea5653f6262ce289e8cec81d57c9\", \"best_bid\":\"0.26\", \"best_ask\":\"0.27\"}, {\"asset_id\":\"14766054693214075530629349735273995982307625376442606753688071083149620216746\", \"price\":\"0.78\", \"size\":\"69.4\", \"side\":\"SELL\", \"hash\":\"9be9177838a74700bc7c4169440d74f935bcce7e\", \"best_bid\":\"0.73\", \"best_ask\":\"0.74\"}], \"timestamp\":\"1785130931695\", \"event_type\":\"price_change\"}","received_at":"2026-07-27T05:42:11.987879Z","schema_version":"clob-market-ws.price_change.v1","sequence":null,"server_hash":null,"server_timestamp":"1785130931695","session_id":"502006c5cfcd437296561ea750c9ec8b","source":"clob_market_ws"},"received_at":"2026-07-27T05:42:11.987879Z","record_id":"9040da2b4f931dbb4933ad050e6bb0a2b4273d32d58fc5a4acc8f51dc2cb00fa","schema_fingerprint":"4aa3821a28b0b7c2400bc59aba4bcc0a76e971dadd19610d3ad38c768e124dc7","schema_version":"edge-lab-recorder.raw.v1","sequence":null,"source":"clob_market_ws"}
{"event_at":"2026-07-27T05:42:11.696000Z","event_fingerprint":"9a30d12639e3cb6404c18c6a3c536cfabf77912fe20757ff4d1ccc6ac5dfc1a1","payload":{"connection_id":"efc69d3132f1467b8e898a382b23ac0d","event_at":"2026-07-27T05:42:11.696000Z","event_type":"price_change","frame_hash":"a824a6d853756cf9069578ccfced67bd96dfca1dd0cb1e5772f95eca432e3b7b","frame_index":0,"kind":"data","monotonic_ns":232915223964125,"payload":{"event_type":"price_change","market":"0x3b40066b5cf3871a2f6237c5628bd8092a206aa998558ac5ec13c4483e31e160","price_changes":[{"asset_id":"110216635572655435074987471276357323571387854733835379371586402147734167783946","best_ask":"0.27","best_bid":"0.26","hash":"d92d5307290b3eaaa350a8d8f1508f7ef4fd1857","price":"0.25","side":"BUY","size":"42.6"},{"asset_id":"14766054693214075530629349735273995982307625376442606753688071083149620216746","best_ask":"0.74","best_bid":"0.73","hash":"94209f3bc25f5563d98374b2e0d293f09c1fafcf","price":"0.75","side":"SELL","size":"42.6"}],"timestamp":"1785130931696"},"payload_hash":"cb3056a52eb88038d0f3a9ea2cdff524384f9e40d80dc429dff315e5f9e63c10","raw_frame":"{\"market\":\"0x3b40066b5cf3871a2f6237c5628bd8092a206aa998558ac5ec13c4483e31e160\", \"price_changes\":[{\"asset_id\":\"110216635572655435074987471276357323571387854733835379371586402147734167783946\", \"price\":\"0.25\", \"size\":\"42.6\", \"side\":\"BUY\", \"hash\":\"d92d5307290b3eaaa350a8d8f1508f7ef4fd1857\", \"best_bid\":\"0.26\", \"best_ask\":\"0.27\"}, {\"asset_id\":\"14766054693214075530629349735273995982307625376442606753688071083149620216746\", \"price\":\"0.75\", \"size\":\"42.6\", \"side\":\"SELL\", \"hash\":\"94209f3bc25f5563d98374b2e0d293f09c1fafcf\", \"best_bid\":\"0.73\", \"best_ask\":\"0.74\"}], \"timestamp\":\"1785130931696\", \"event_type\":\"price_change\"}","received_at":"2026-07-27T05:42:11.990841Z","schema_version":"clob-market-ws.price_change.v1","sequence":null,"server_hash":null,"server_timestamp":"1785130931696","session_id":"502006c5cfcd437296561ea750c9ec8b","source":"clob_market_ws"},"received_at":"2026-07-27T05:42:11.990841Z","record_id":"93390c858e3648c5d225cfd11b3e3ee636347336960a9769be17c0fdbf933e90","schema_fingerprint":"4aa3821a28b0b7c2400bc59aba4bcc0a76e971dadd19610d3ad38c768e124dc7","schema_version":"edge-lab-recorder.raw.v1","sequence":null,"source":"clob_market_ws"}
{"event_at":"2026-07-27T05:42:11.697000Z","event_fingerprint":"a4df45ada6dd69d87267a303d34e3a67369e48fdddbcc3148b7f326be6056f5f","payload":{"connection_id":"efc69d3132f1467b8e898a382b23ac0d","event_at":"2026-07-27T05:42:11.697000Z","event_type":"price_change","frame_hash":"008b82eb58b3d5bb95ab9521357973d4d161e64c9dd397898a61f36bc3a42d41","frame_index":0,"kind":"data","monotonic_ns":232915226826125,"payload":{"event_type":"price_change","market":"0x3b40066b5cf3871a2f6237c5628bd8092a206aa998558ac5ec13c4483e31e160","price_changes":[{"asset_id":"14766054693214075530629349735273995982307625376442606753688071083149620216746","best_ask":"0.74","best_bid":"0.73","hash":"26d07b9d573396b01b0328d2f91ab35028ec3591","price":"0.72","side":"BUY","size":"9.6"},{"asset_id":"110216635572655435074987471276357323571387854733835379371586402147734167783946","best_ask":"0.27","best_bid":"0.26","hash":"5ea636a12d94d85a324d3f509962bba114ba1be5","price":"0.28","side":"SELL","size":"9.6"}],"timestamp":"1785130931697"},"payload_hash":"572768e34d6ad16fa44a87f831abf21d25daffabd2405dee5d3e4e7860ea55ea","raw_frame":"{\"market\":\"0x3b40066b5cf3871a2f6237c5628bd8092a206aa998558ac5ec13c4483e31e160\", \"price_changes\":[{\"asset_id\":\"14766054693214075530629349735273995982307625376442606753688071083149620216746\", \"price\":\"0.72\", \"size\":\"9.6\", \"side\":\"BUY\", \"hash\":\"26d07b9d573396b01b0328d2f91ab35028ec3591\", \"best_bid\":\"0.73\", \"best_ask\":\"0.74\"}, {\"asset_id\":\"110216635572655435074987471276357323571387854733835379371586402147734167783946\", \"price\":\"0.28\", \"size\":\"9.6\", \"side\":\"SELL\", \"hash\":\"5ea636a12d94d85a324d3f509962bba114ba1be5\", \"best_bid\":\"0.26\", \"best_ask\":\"0.27\"}], \"timestamp\":\"1785130931697\", \"event_type\":\"price_change\"}","received_at":"2026-07-27T05:42:11.993703Z","schema_version":"clob-market-ws.price_change.v1","sequence":null,"server_hash":null,"server_timestamp":"1785130931697","session_id":"502006c5cfcd437296561ea750c9ec8b","source":"clob_market_ws"},"received_at":"2026-07-27T05:42:11.993703Z","record_id":"37d091d123fa9a188c5f43a4949c6a87739cfbd96f06ad612e777351ae5b7536","schema_fingerprint":"4aa3821a28b0b7c2400bc59aba4bcc0a76e971dadd19610d3ad38c768e124dc7","schema_version":"edge-lab-recorder.raw.v1","sequence":null,"source":"clob_market_ws"}
{"event_at":"2026-07-27T05:42:11.700000Z","event_fingerprint":"f7caadc78b5830a0a9430d031367110be4951a4884df7b133a9a73d2a0354b52","payload":{"connection_id":"efc69d3132f1467b8e898a382b23ac0d","event_at":"2026-07-27T05:42:11.700000Z","event_type":"price_change","frame_hash":"43dcef9a4ebc67dd70e051d96a9572d2be084dd35b0d145590b26ec8b96f120b","frame_index":0,"kind":"data","monotonic_ns":232915229919708,"payload":{"event_type":"price_change","market":"0x3b40066b5cf3871a2f6237c5628bd8092a206aa998558ac5ec13c4483e31e160","price_changes":[{"asset_id":"110216635572655435074987471276357323571387854733835379371586402147734167783946","best_ask":"0.27","best_bid":"0.26","hash":"3037038c1a5d5901094f716cfd4a509fdd4ed23a","price":"0.19","side":"BUY","size":"51.6"},{"asset_id":"14766054693214075530629349735273995982307625376442606753688071083149620216746","best_ask":"0.74","best_bid":"0.73","hash":"1ffb9517949d622ee7ca673ed07735304f7f992b","price":"0.81","side":"SELL","size":"51.6"}],"timestamp":"1785130931700"},"payload_hash":"812bdbc767c7a70153e962deeb0bb71db8596d823d1617e19d5f246fcb979e8a","raw_frame":"{\"market\":\"0x3b40066b5cf3871a2f6237c5628bd8092a206aa998558ac5ec13c4483e31e160\", \"price_changes\":[{\"asset_id\":\"110216635572655435074987471276357323571387854733835379371586402147734167783946\", \"price\":\"0.19\", \"size\":\"51.6\", \"side\":\"BUY\", \"hash\":\"3037038c1a5d5901094f716cfd4a509fdd4ed23a\", \"best_bid\":\"0.26\", \"best_ask\":\"0.27\"}, {\"asset_id\":\"14766054693214075530629349735273995982307625376442606753688071083149620216746\", \"price\":\"0.81\", \"size\":\"51.6\", \"side\":\"SELL\", \"hash\":\"1ffb9517949d622ee7ca673ed07735304f7f992b\", \"best_bid\":\"0.73\", \"best_ask\":\"0.74\"}], \"timestamp\":\"1785130931700\", \"event_type\":\"price_change\"}","received_at":"2026-07-27T05:42:11.996791Z","schema_version":"clob-market-ws.price_change.v1","sequence":null,"server_hash":null,"server_timestamp":"1785130931700","session_id":"502006c5cfcd437296561ea750c9ec8b","source":"clob_market_ws"},"received_at":"2026-07-27T05:42:11.996791Z","record_id":"794411594f9b809fbba3f233b0c221eb7df61b19acc7e65cfc197eb1edb3202a","schema_fingerprint":"4aa3821a28b0b7c2400bc59aba4bcc0a76e971dadd19610d3ad38c768e124dc7","schema_version":"edge-lab-recorder.raw.v1","sequence":null,"source":"clob_market_ws"}
{"event_at":"2026-07-27T05:42:11.702000Z","event_fingerprint":"f18e87c6a6d9cd903f1268f53dfe705ec43d0357683763ea17e31c484411524c","payload":{"connection_id":"efc69d3132f1467b8e898a382b23ac0d","event_at":"2026-07-27T05:42:11.702000Z","event_type":"price_change","frame_hash":"430cb585488311b771583f8e1318517cac70212b850a5b34c310c5b12b11b379","frame_index":0,"kind":"data","monotonic_ns":232915231673916,"payload":{"event_type":"price_change","market":"0x3b40066b5cf3871a2f6237c5628bd8092a206aa998558ac5ec13c4483e31e160","price_changes":[{"asset_id":"110216635572655435074987471276357323571387854733835379371586402147734167783946","best_ask":"0.27","best_bid":"0.26","hash":"3c873d6936fa8321da7e34a243143410d16d72ab","price":"0.2","side":"BUY","size":"320.76"},{"asset_id":"14766054693214075530629349735273995982307625376442606753688071083149620216746","best_ask":"0.74","best_bid":"0.73","hash":"e526f1b004e5186df6dff1183dfe3edc9f59bb76","price":"0.8","side":"SELL","size":"320.76"}],"timestamp":"1785130931702"},"payload_hash":"9f9b801b2b23303468705461b8250a796d6305a2e61fb0bb4a6b5d36d86f3f31","raw_frame":"{\"market\":\"0x3b40066b5cf3871a2f6237c5628bd8092a206aa998558ac5ec13c4483e31e160\", \"price_changes\":[{\"asset_id\":\"110216635572655435074987471276357323571387854733835379371586402147734167783946\", \"price\":\"0.2\", \"size\":\"320.76\", \"side\":\"BUY\", \"hash\":\"3c873d6936fa8321da7e34a243143410d16d72ab\", \"best_bid\":\"0.26\", \"best_ask\":\"0.27\"}, {\"asset_id\":\"14766054693214075530629349735273995982307625376442606753688071083149620216746\", \"price\":\"0.8\", \"size\":\"320.76\", \"side\":\"SELL\", \"hash\":\"e526f1b004e5186df6dff1183dfe3edc9f59bb76\", \"best_bid\":\"0.73\", \"best_ask\":\"0.74\"}], \"timestamp\":\"1785130931702\", \"event_type\":\"price_change\"}","received_at":"2026-07-27T05:42:11.998556Z","schema_version":"clob-market-ws.price_change.v1","sequence":null,"server_hash":null,"server_timestamp":"1785130931702","session_id":"502006c5cfcd437296561ea750c9ec8b","source":"clob_market_ws"},"received_at":"2026-07-27T05:42:11.998556Z","record_id":"a5c9c99b489cc6a9a9ab16bd85e94eec84539f7b331b61747eda071c6400016d","schema_fingerprint":"4aa3821a28b0b7c2400bc59aba4bcc0a76e971dadd19610d3ad38c768e124dc7","schema_version":"edge-lab-recorder.raw.v1","sequence":null,"source":"clob_market_ws"}
{"event_at":"2026-07-27T05:42:11.706000Z","event_fingerprint":"b3671e534d235a34648dd9d1f593646eaf68e4165500f43153797410d4c86bd9","payload":{"connection_id":"efc69d3132f1467b8e898a382b23ac0d","event_at":"2026-07-27T05:42:11.706000Z","event_type":"price_change","frame_hash":"a78d9dc060045ebfe2ddce692295a64ec6e6b52e464d5b74ca9e946abdd04c34","frame_index":0,"kind":"data","monotonic_ns":232915234675208,"payload":{"event_type":"price_change","market":"0x3b40066b5cf3871a2f6237c5628bd8092a206aa998558ac5ec13c4483e31e160","price_changes":[{"asset_id":"14766054693214075530629349735273995982307625376442606753688071083149620216746","best_ask":"0.74","best_bid":"0.73","hash":"7bff99a7001bcc92ecf3c84a1603740c6f901eef","price":"0.73","side":"BUY","size":"112"},{"asset_id":"110216635572655435074987471276357323571387854733835379371586402147734167783946","best_ask":"0.27","best_bid":"0.26","hash":"c7fe0782b73fab2883ddcfa780b15a7f52d1d620","price":"0.27","side":"SELL","size":"112"}],"timestamp":"1785130931706"},"payload_hash":"2a0868ed96a328902d724e208ecfbf537c1cc251e7dab2253c6aa1ccbf171a68","raw_frame":"{\"market\":\"0x3b40066b5cf3871a2f6237c5628bd8092a206aa998558ac5ec13c4483e31e160\", \"price_changes\":[{\"asset_id\":\"14766054693214075530629349735273995982307625376442606753688071083149620216746\", \"price\":\"0.73\", \"size\":\"112\", \"side\":\"BUY\", \"hash\":\"7bff99a7001bcc92ecf3c84a1603740c6f901eef\", \"best_bid\":\"0.73\", \"best_ask\":\"0.74\"}, {\"asset_id\":\"110216635572655435074987471276357323571387854733835379371586402147734167783946\", \"price\":\"0.27\", \"size\":\"112\", \"side\":\"SELL\", \"hash\":\"c7fe0782b73fab2883ddcfa780b15a7f52d1d620\", \"best_bid\":\"0.26\", \"best_ask\":\"0.27\"}], \"timestamp\":\"1785130931706\", \"event_type\":\"price_change\"}","received_at":"2026-07-27T05:42:12.001552Z","schema_version":"clob-market-ws.price_change.v1","sequence":null,"server_hash":null,"server_timestamp":"1785130931706","session_id":"502006c5cfcd437296561ea750c9ec8b","source":"clob_market_ws"},"received_at":"2026-07-27T05:42:12.001552Z","record_id":"a1e7628b5d792094619312fdfa47544037cfc146e6b572f1bd824249ba014b1f","schema_fingerprint":"4aa3821a28b0b7c2400bc59aba4bcc0a76e971dadd19610d3ad38c768e124dc7","schema_version":"edge-lab-recorder.raw.v1","sequence":null,"source":"clob_market_ws"}
{"event_at":"2026-07-27T05:42:11.713000Z","event_fingerprint":"ebe4c27dee924f96abd93f118cf151ec3c0c64bc62c485764c4a10c4bb963035","payload":{"connection_id":"efc69d3132f1467b8e898a382b23ac0d","event_at":"2026-07-27T05:42:11.713000Z","event_type":"price_change","frame_hash":"ba85f379d4b99886711a12af3d405d7354178746b68d205c1a631b72654c0f17","frame_index":0,"kind":"data","monotonic_ns":232915237500250,"payload":{"event_type":"price_change","market":"0x3b40066b5cf3871a2f6237c5628bd8092a206aa998558ac5ec13c4483e31e160","price_changes":[{"asset_id":"110216635572655435074987471276357323571387854733835379371586402147734167783946","best_ask":"0.27","best_bid":"0.26","hash":"24bdd05324f18dd591606c0854d02aba6a11ee39","price":"0.26","side":"BUY","size":"39"},{"asset_id":"14766054693214075530629349735273995982307625376442606753688071083149620216746","best_ask":"0.74","best_bid":"0.73","hash":"97e9de9c484b1474bff9822f8af3ce0669ed116b","price":"0.74","side":"SELL","size":"39"}],"timestamp":"1785130931713"},"payload_hash":"3fa391f7dca49a55125a5ab697a6dd54e1604c096d2f4e98b6cab7f83d6b149e","raw_frame":"{\"market\":\"0x3b40066b5cf3871a2f6237c5628bd8092a206aa998558ac5ec13c4483e31e160\", \"price_changes\":[{\"asset_id\":\"110216635572655435074987471276357323571387854733835379371586402147734167783946\", \"price\":\"0.26\", \"size\":\"39\", \"side\":\"BUY\", \"hash\":\"24bdd05324f18dd591606c0854d02aba6a11ee39\", \"best_bid\":\"0.26\", \"best_ask\":\"0.27\"}, {\"asset_id\":\"14766054693214075530629349735273995982307625376442606753688071083149620216746\", \"price\":\"0.74\", \"size\":\"39\", \"side\":\"SELL\", \"hash\":\"97e9de9c484b1474bff9822f8af3ce0669ed116b\", \"best_bid\":\"0.73\", \"best_ask\":\"0.74\"}], \"timestamp\":\"1785130931713\", \"event_type\":\"price_change\"}","received_at":"2026-07-27T05:42:12.004377Z","schema_version":"clob-market-ws.price_change.v1","sequence":null,"server_hash":null,"server_timestamp":"1785130931713","session_id":"502006c5cfcd437296561ea750c9ec8b","source":"clob_market_ws"},"received_at":"2026-07-27T05:42:12.004377Z","record_id":"9a1e7e5c93c396392b6ed6a161101bad041fe07b536bc547a5e1035107cc69cc","schema_fingerprint":"4aa3821a28b0b7c2400bc59aba4bcc0a76e971dadd19610d3ad38c768e124dc7","schema_version":"edge-lab-recorder.raw.v1","sequence":null,"source":"clob_market_ws"}
{"event_at":"2026-07-27T05:42:11.716000Z","event_fingerprint":"0abe8686a826c0ee79075edfd143654dfd8be2011539569432c441554831419e","payload":{"connection_id":"efc69d3132f1467b8e898a382b23ac0d","event_at":"2026-07-27T05:42:11.716000Z","event_type":"price_change","frame_hash":"8c28f293ad083196b220c9368b68c7a9e81227a5001fd6b38702c4bf3eb0335a","frame_index":0,"kind":"data","monotonic_ns":232915240529500,"payload":{"event_type":"price_change","market":"0x3b40066b5cf3871a2f6237c5628bd8092a206aa998558ac5ec13c4483e31e160","price_changes":[{"asset_id":"14766054693214075530629349735273995982307625376442606753688071083149620216746","best_ask":"0.74","best_bid":"0.73","hash":"1342185d6de1bce81781aa9ea45563beaa9f62ee","price":"0.01","side":"BUY","size":"5330.02"},{"asset_id":"110216635572655435074987471276357323571387854733835379371586402147734167783946","best_ask":"0.27","best_bid":"0.26","hash":"83934aff587d683f0c900016904273e812e18890","price":"0.99","side":"SELL","size":"5330.02"}],"timestamp":"1785130931716"},"payload_hash":"a6a063ff98b73e7f35e833398e23d129f0e7cef2a6d8f0970256548865530e0a","raw_frame":"{\"market\":\"0x3b40066b5cf3871a2f6237c5628bd8092a206aa998558ac5ec13c4483e31e160\", \"price_changes\":[{\"asset_id\":\"14766054693214075530629349735273995982307625376442606753688071083149620216746\", \"price\":\"0.01\", \"size\":\"5330.02\", \"side\":\"BUY\", \"hash\":\"1342185d6de1bce81781aa9ea45563beaa9f62ee\", \"best_bid\":\"0.73\", \"best_ask\":\"0.74\"}, {\"asset_id\":\"110216635572655435074987471276357323571387854733835379371586402147734167783946\", \"price\":\"0.99\", \"size\":\"5330.02\", \"side\":\"SELL\", \"hash\":\"83934aff587d683f0c900016904273e812e18890\", \"best_bid\":\"0.26\", \"best_ask\":\"0.27\"}], \"timestamp\":\"1785130931716\", \"event_type\":\"price_change\"}","received_at":"2026-07-27T05:42:12.007406Z","schema_version":"clob-market-ws.price_change.v1","sequence":null,"server_hash":null,"server_timestamp":"1785130931716","session_id":"502006c5cfcd437296561ea750c9ec8b","source":"clob_market_ws"},"received_at":"2026-07-27T05:42:12.007406Z","record_id":"7234668b67a440f7786b897051222f92ca45dfcd7ed80e7811d60f2622d6354a","schema_fingerprint":"4aa3821a28b0b7c2400bc59aba4bcc0a76e971dadd19610d3ad38c768e124dc7","schema_version":"edge-lab-recorder.raw.v1","sequence":null,"source":"clob_market_ws"}
{"event_at":"2026-07-27T05:42:11.725000Z","event_fingerprint":"1b6b06c314a308d25002d0b4cd0491346416a1490390fe49a573a03cb9e8f3ee","payload":{"connection_id":"efc69d3132f1467b8e898a382b23ac0d","event_at":"2026-07-27T05:42:11.725000Z","event_type":"price_change","frame_hash":"eced3b8b044574d0bf83ff8535c6858fa2aa78b06db042e4dd3fb6a4fe189293","frame_index":0,"kind":"data","monotonic_ns":232915244071916,"payload":{"event_type":"price_change","market":"0x3b40066b5cf3871a2f6237c5628bd8092a206aa998558ac5ec13c4483e31e160","price_changes":[{"asset_id":"14766054693214075530629349735273995982307625376442606753688071083149620216746","best_ask":"0.74","best_bid":"0.73","hash":"13a86986efa6003599329e0ff6a76f67c21f20cb","price":"0.83","side":"SELL","size":"183.99"},{"asset_id":"110216635572655435074987471276357323571387854733835379371586402147734167783946","best_ask":"0.27","best_bid":"0.26","hash":"e0c54b0d85682947dee16d8449814dade23c763d","price":"0.17","side":"BUY","size":"183.99"}],"timestamp":"1785130931725"},"payload_hash":"f05f83fb25fac94be44ad14733bff9dbf8c38ae96d9b914c30187b6e352bfd7c","raw_frame":"{\"market\":\"0x3b40066b5cf3871a2f6237c5628bd8092a206aa998558ac5ec13c4483e31e160\", \"price_changes\":[{\"asset_id\":\"14766054693214075530629349735273995982307625376442606753688071083149620216746\", \"price\":\"0.83\", \"size\":\"183.99\", \"side\":\"SELL\", \"hash\":\"13a86986efa6003599329e0ff6a76f67c21f20cb\", \"best_bid\":\"0.73\", \"best_ask\":\"0.74\"}, {\"asset_id\":\"110216635572655435074987471276357323571387854733835379371586402147734167783946\", \"price\":\"0.17\", \"size\":\"183.99\", \"side\":\"BUY\", \"hash\":\"e0c54b0d85682947dee16d8449814dade23c763d\", \"best_bid\":\"0.26\", \"best_ask\":\"0.27\"}], \"timestamp\":\"1785130931725\", \"event_type\":\"price_change\"}","received_at":"2026-07-27T05:42:12.010949Z","schema_version":"clob-market-ws.price_change.v1","sequence":null,"server_hash":null,"server_timestamp":"1785130931725","session_id":"502006c5cfcd437296561ea750c9ec8b","source":"clob_market_ws"},"received_at":"2026-07-27T05:42:12.010949Z","record_id":"8f178c1e9c0c093d6c66ea36c7d4d9e4a43a41b83207fcaee6da930f914fe699","schema_fingerprint":"4aa3821a28b0b7c2400bc59aba4bcc0a76e971dadd19610d3ad38c768e124dc7","schema_version":"edge-lab-recorder.raw.v1","sequence":null,"source":"clob_market_ws"}
{"event_at":"2026-07-27T05:42:11.750000Z","event_fingerprint":"de8c6668aab7ebd6fa36667d9a8b8e751fafade2ce69f9b7d3b9cd370042f7d3","payload":{"connection_id":"efc69d3132f1467b8e898a382b23ac0d","event_at":"2026-07-27T05:42:11.750000Z","event_type":"price_change","frame_hash":"db0d13967116060d1f383106d6733457adf1b846e677245d2c70926972222667","frame_index":0,"kind":"data","monotonic_ns":232915246275333,"payload":{"event_type":"price_change","market":"0x3b40066b5cf3871a2f6237c5628bd8092a206aa998558ac5ec13c4483e31e160","price_changes":[{"asset_id":"110216635572655435074987471276357323571387854733835379371586402147734167783946","best_ask":"0.27","best_bid":"0.26","hash":"977766efe173cf9460775f9f617c0c9dc046875c","price":"0.22","side":"BUY","size":"59.4"},{"asset_id":"14766054693214075530629349735273995982307625376442606753688071083149620216746","best_ask":"0.74","best_bid":"0.73","hash":"00530832d3ebf40a7e0361ad3b9d61a56b203b28","price":"0.78","side":"SELL","size":"59.4"}],"timestamp":"1785130931750"},"payload_hash":"20bfcada1acba8236495f35ce6e1e46b81ee10864ea6077d9c320961844029d1","raw_frame":"{\"market\":\"0x3b40066b5cf3871a2f6237c5628bd8092a206aa998558ac5ec13c4483e31e160\", \"price_changes\":[{\"asset_id\":\"110216635572655435074987471276357323571387854733835379371586402147734167783946\", \"price\":\"0.22\", \"size\":\"59.4\", \"side\":\"BUY\", \"hash\":\"977766efe173cf9460775f9f617c0c9dc046875c\", \"best_bid\":\"0.26\", \"best_ask\":\"0.27\"}, {\"asset_id\":\"14766054693214075530629349735273995982307625376442606753688071083149620216746\", \"price\":\"0.78\", \"size\":\"59.4\", \"side\":\"SELL\", \"hash\":\"00530832d3ebf40a7e0361ad3b9d61a56b203b28\", \"best_bid\":\"0.73\", \"best_ask\":\"0.74\"}], \"timestamp\":\"1785130931750\", \"event_type\":\"price_change\"}","received_at":"2026-07-27T05:42:12.013151Z","schema_version":"clob-market-ws.price_change.v1","sequence":null,"server_hash":null,"server_timestamp":"1785130931750","session_id":"502006c5cfcd437296561ea750c9ec8b","source":"clob_market_ws"},"received_at":"2026-07-27T05:42:12.013151Z","record_id":"2c54c9466fa5bc98a049321970af44a11dedc209ad32f9bdb2712661c43d4dc6","schema_fingerprint":"4aa3821a28b0b7c2400bc59aba4bcc0a76e971dadd19610d3ad38c768e124dc7","schema_version":"edge-lab-recorder.raw.v1","sequence":null,"source":"clob_market_ws"}
{"event_at":"2026-07-27T05:42:11.752000Z","event_fingerprint":"788c768627f48b611651843dbda8b6eca4021602e132942b8e98f0eaa62f3d01","payload":{"connection_id":"efc69d3132f1467b8e898a382b23ac0d","event_at":"2026-07-27T05:42:11.752000Z","event_type":"price_change","frame_hash":"2eff8441a7f214057941062fc4db47fcd770ea18ab4013b081bf0ca98a2f369a","frame_index":0,"kind":"data","monotonic_ns":232915248220875,"payload":{"event_type":"price_change","market":"0x3b40066b5cf3871a2f6237c5628bd8092a206aa998558ac5ec13c4483e31e160","price_changes":[{"asset_id":"14766054693214075530629349735273995982307625376442606753688071083149620216746","best_ask":"0.74","best_bid":"0.73","hash":"5cfa8b2f63170d3e87da7ff0ca0ec56bcd3c29a0","price":"0.01","side":"BUY","size":"5335.02"},{"asset_id":"110216635572655435074987471276357323571387854733835379371586402147734167783946","best_ask":"0.27","best_bid":"0.26","hash":"c070a881594f06a08df13ca88f8a18312ba347a7","price":"0.99","side":"SELL","size":"5335.02"}],"timestamp":"1785130931752"},"payload_hash":"1d11eda49b71575fca8fcba481bbe87e1766994506ddc6c9fc8b2641e5878e83","raw_frame":"{\"market\":\"0x3b40066b5cf3871a2f6237c5628bd8092a206aa998558ac5ec13c4483e31e160\", \"price_changes\":[{\"asset_id\":\"14766054693214075530629349735273995982307625376442606753688071083149620216746\", \"price\":\"0.01\", \"size\":\"5335.02\", \"side\":\"BUY\", \"hash\":\"5cfa8b2f63170d3e87da7ff0ca0ec56bcd3c29a0\", \"best_bid\":\"0.73\", \"best_ask\":\"0.74\"}, {\"asset_id\":\"110216635572655435074987471276357323571387854733835379371586402147734167783946\", \"price\":\"0.99\", \"size\":\"5335.02\", \"side\":\"SELL\", \"hash\":\"c070a881594f06a08df13ca88f8a18312ba347a7\", \"best_bid\":\"0.26\", \"best_ask\":\"0.27\"}], \"timestamp\":\"1785130931752\", \"event_type\":\"price_change\"}","received_at":"2026-07-27T05:42:12.015104Z","schema_version":"clob-market-ws.price_change.v1","sequence":null,"server_hash":null,"server_timestamp":"1785130931752","session_id":"502006c5cfcd437296561ea750c9ec8b","source":"clob_market_ws"},"received_at":"2026-07-27T05:42:12.015104Z","record_id":"3ff27bd4d0402c996f02e5b289ea714de454a39d2588ac69271eba5f97fff23a","schema_fingerprint":"4aa3821a28b0b7c2400bc59aba4bcc0a76e971dadd19610d3ad38c768e124dc7","schema_version":"edge-lab-recorder.raw.v1","sequence":null,"source":"clob_market_ws"}
{"event_at":"2026-07-27T05:42:11.763000Z","event_fingerprint":"dc33e65e3c727104e05dbdfc41e103b08f1267572a4232956d1cd69e78626829","payload":{"connection_id":"efc69d3132f1467b8e898a382b23ac0d","event_at":"2026-07-27T05:42:11.763000Z","event_type":"price_change","frame_hash":"e2b686baea7e4620f2dd4daf94b9e700a27cbb921eb623d3ff92a7fbbbd88ea5","frame_index":0,"kind":"data","monotonic_ns":232915250261791,"payload":{"event_type":"price_change","market":"0x3b40066b5cf3871a2f6237c5628bd8092a206aa998558ac5ec13c4483e31e160","price_changes":[{"asset_id":"14766054693214075530629349735273995982307625376442606753688071083149620216746","best_ask":"0.74","best_bid":"0.73","hash":"8e9ca7c3df57b0046be40bf97dc501881b4f0d52","price":"0.48","side":"BUY","size":"176.88"},{"asset_id":"110216635572655435074987471276357323571387854733835379371586402147734167783946","best_ask":"0.27","best_bid":"0.26","hash":"bd813b1f1d9d2e7847fdaf3350bd732e1958cab9","price":"0.52","side":"SELL","size":"176.88"}],"timestamp":"1785130931763"},"payload_hash":"214a4196e66f625d3a601b6cbdba4bcd50c3364f4f977bbe83e3e1d0f35efc3d","raw_frame":"{\"market\":\"0x3b40066b5cf3871a2f6237c5628bd8092a206aa998558ac5ec13c4483e31e160\", \"price_changes\":[{\"asset_id\":\"14766054693214075530629349735273995982307625376442606753688071083149620216746\", \"price\":\"0.48\", \"size\":\"176.88\", \"side\":\"BUY\", \"hash\":\"8e9ca7c3df57b0046be40bf97dc501881b4f0d52\", \"best_bid\":\"0.73\", \"best_ask\":\"0.74\"}, {\"asset_id\":\"110216635572655435074987471276357323571387854733835379371586402147734167783946\", \"price\":\"0.52\", \"size\":\"176.88\", \"side\":\"SELL\", \"hash\":\"bd813b1f1d9d2e7847fdaf3350bd732e1958cab9\", \"best_bid\":\"0.26\", \"best_ask\":\"0.27\"}], \"timestamp\":\"1785130931763\", \"event_type\":\"price_change\"}","received_at":"2026-07-27T05:42:12.017138Z","schema_version":"clob-market-ws.price_change.v1","sequence":null,"server_hash":null,"server_timestamp":"1785130931763","session_id":"502006c5cfcd437296561ea750c9ec8b","source":"clob_market_ws"},"received_at":"2026-07-27T05:42:12.017138Z","record_id":"b106f02059bb90e1bbb55ec2fc3ce9785c12fd43c253364236f1f7a61c77c919","schema_fingerprint":"4aa3821a28b0b7c2400bc59aba4bcc0a76e971dadd19610d3ad38c768e124dc7","schema_version":"edge-lab-recorder.raw.v1","sequence":null,"source":"clob_market_ws"}
{"event_at":"2026-07-27T05:42:11.770000Z","event_fingerprint":"7f58d64a312e815233ded82c27861e03db96726b564e5befa1169b8ce84135c0","payload":{"connection_id":"efc69d3132f1467b8e898a382b23ac0d","event_at":"2026-07-27T05:42:11.770000Z","event_type":"price_change","frame_hash":"a11ce9fc89638de11bd62fb2c9c9432aee534c3dfffafe88d84851f3e3dc46c2","frame_index":0,"kind":"data","monotonic_ns":232915253104750,"payload":{"event_type":"price_change","market":"0x3b40066b5cf3871a2f6237c5628bd8092a206aa998558ac5ec13c4483e31e160","price_changes":[{"asset_id":"110216635572655435074987471276357323571387854733835379371586402147734167783946","best_ask":"0.27","best_bid":"0.26","hash":"f47135e09e1b7bef4174a137ac59e26f0514c02b","price":"0.27","side":"SELL","size":"119"},{"asset_id":"14766054693214075530629349735273995982307625376442606753688071083149620216746","best_ask":"0.74","best_bid":"0.73","hash":"09d7be7b801d49edad7e737336830c5389b16a57","price":"0.73","side":"BUY","size":"119"}],"timestamp":"1785130931770"},"payload_hash":"982ff8ea82bfb319c98e189336e72bd9d09c24760c610f4f5ddfbd87bf3b499d","raw_frame":"{\"market\":\"0x3b40066b5cf3871a2f6237c5628bd8092a206aa998558ac5ec13c4483e31e160\", \"price_changes\":[{\"asset_id\":\"110216635572655435074987471276357323571387854733835379371586402147734167783946\", \"price\":\"0.27\", \"size\":\"119\", \"side\":\"SELL\", \"hash\":\"f47135e09e1b7bef4174a137ac59e26f0514c02b\", \"best_bid\":\"0.26\", \"best_ask\":\"0.27\"}, {\"asset_id\":\"14766054693214075530629349735273995982307625376442606753688071083149620216746\", \"price\":\"0.73\", \"size\":\"119\", \"side\":\"BUY\", \"hash\":\"09d7be7b801d49edad7e737336830c5389b16a57\", \"best_bid\":\"0.73\", \"best_ask\":\"0.74\"}], \"timestamp\":\"1785130931770\", \"event_type\":\"price_change\"}","received_at":"2026-07-27T05:42:12.019981Z","schema_version":"clob-market-ws.price_change.v1","sequence":null,"server_hash":null,"server_timestamp":"1785130931770","session_id":"502006c5cfcd437296561ea750c9ec8b","source":"clob_market_ws"},"received_at":"2026-07-27T05:42:12.019981Z","record_id":"4996e439e5e54c4e905cfb3d1bcc778f4ca956ab7abd2aec1db51cb67814b0fc","schema_fingerprint":"4aa3821a28b0b7c2400bc59aba4bcc0a76e971dadd19610d3ad38c768e124dc7","schema_version":"edge-lab-recorder.raw.v1","sequence":null,"source":"clob_market_ws"}
{"event_at":"2026-07-27T05:42:11.775000Z","event_fingerprint":"825a80618ada1ec7d5514d03ee01f16c8501670f0644dc0a66046912a45fce65","payload":{"connection_id":"efc69d3132f1467b8e898a382b23ac0d","event_at":"2026-07-27T05:42:11.775000Z","event_type":"price_change","frame_hash":"2f4ee45b7263aee073ad141c288f117b83824ca873ba390263a67710e984199f","frame_index":0,"kind":"data","monotonic_ns":232915255909750,"payload":{"event_type":"price_change","market":"0x3b40066b5cf3871a2f6237c5628bd8092a206aa998558ac5ec13c4483e31e160","price_changes":[{"asset_id":"110216635572655435074987471276357323571387854733835379371586402147734167783946","best_ask":"0.27","best_bid":"0.26","hash":"3a72c67b8c0ad89f164720052ca69b7367535dc7","price":"0.19","side":"BUY","size":"61.6"},{"asset_id":"14766054693214075530629349735273995982307625376442606753688071083149620216746","best_ask":"0.74","best_bid":"0.73","hash":"8a411025bd330c8f9c4502e11079f31cd7bb9a92","price":"0.81","side":"SELL","size":"61.6"}],"timestamp":"1785130931775"},"payload_hash":"337c2fcadb73e8dea737d1cd87555cf1c14af0a0dd9afa53326138368e01dd37","raw_frame":"{\"market\":\"0x3b40066b5cf3871a2f6237c5628bd8092a206aa998558ac5ec13c4483e31e160\", \"price_changes\":[{\"asset_id\":\"110216635572655435074987471276357323571387854733835379371586402147734167783946\", \"price\":\"0.19\", \"size\":\"61.6\", \"side\":\"BUY\", \"hash\":\"3a72c67b8c0ad89f164720052ca69b7367535dc7\", \"best_bid\":\"0.26\", \"best_ask\":\"0.27\"}, {\"asset_id\":\"14766054693214075530629349735273995982307625376442606753688071083149620216746\", \"price\":\"0.81\", \"size\":\"61.6\", \"side\":\"SELL\", \"hash\":\"8a411025bd330c8f9c4502e11079f31cd7bb9a92\", \"best_bid\":\"0.73\", \"best_ask\":\"0.74\"}], \"timestamp\":\"1785130931775\", \"event_type\":\"price_change\"}","received_at":"2026-07-27T05:42:12.022787Z","schema_version":"clob-market-ws.price_change.v1","sequence":null,"server_hash":null,"server_timestamp":"1785130931775","session_id":"502006c5cfcd437296561ea750c9ec8b","source":"clob_market_ws"},"received_at":"2026-07-27T05:42:12.022787Z","record_id":"e1f94714caa5af2fcb0a727b7d72fde3255b251ba38d0172cf0279f664694bf1","schema_fingerprint":"4aa3821a28b0b7c2400bc59aba4bcc0a76e971dadd19610d3ad38c768e124dc7","schema_version":"edge-lab-recorder.raw.v1","sequence":null,"source":"clob_market_ws"}
{"event_at":"2026-07-27T05:42:11.776000Z","event_fingerprint":"86fc0b6216e0ff05fece66461eed5a5766acd98d464d1ac795811fa1a63f6b1f","payload":{"connection_id":"efc69d3132f1467b8e898a382b23ac0d","event_at":"2026-07-27T05:42:11.776000Z","event_type":"price_change","frame_hash":"dfc115d42442252742f42b70f0e0ef4836aae1f017fcfdeb7ca261df4caeca2a","frame_index":0,"kind":"data","monotonic_ns":232915258816125,"payload":{"event_type":"price_change","market":"0x3b40066b5cf3871a2f6237c5628bd8092a206aa998558ac5ec13c4483e31e160","price_changes":[{"asset_id":"14766054693214075530629349735273995982307625376442606753688071083149620216746","best_ask":"0.74","best_bid":"0.73","hash":"9dcb73e0c4d711fac81fdc0913247dfcac6e85e6","price":"0.59","side":"BUY","size":"38"},{"asset_id":"110216635572655435074987471276357323571387854733835379371586402147734167783946","best_ask":"0.27","best_bid":"0.26","hash":"5e7835f2b82370f432f296406c4e2751562f1fd9","price":"0.41","side":"SELL","size":"38"}],"timestamp":"1785130931776"},"payload_hash":"8cf8df37c657b8a72a1ef562ee34c181786d80f9c3d0f8689a3cf4c43d2f8789","raw_frame":"{\"market\":\"0x3b40066b5cf3871a2f6237c5628bd8092a206aa998558ac5ec13c4483e31e160\", \"price_changes\":[{\"asset_id\":\"14766054693214075530629349735273995982307625376442606753688071083149620216746\", \"price\":\"0.59\", \"size\":\"38\", \"side\":\"BUY\", \"hash\":\"9dcb73e0c4d711fac81fdc0913247dfcac6e85e6\", \"best_bid\":\"0.73\", \"best_ask\":\"0.74\"}, {\"asset_id\":\"110216635572655435074987471276357323571387854733835379371586402147734167783946\", \"price\":\"0.41\", \"size\":\"38\", \"side\":\"SELL\", \"hash\":\"5e7835f2b82370f432f296406c4e2751562f1fd9\", \"best_bid\":\"0.26\", \"best_ask\":\"0.27\"}], \"timestamp\":\"1785130931776\", \"event_type\":\"price_change\"}","received_at":"2026-07-27T05:42:12.025693Z","schema_version":"clob-market-ws.price_change.v1","sequence":null,"server_hash":null,"server_timestamp":"1785130931776","session_id":"502006c5cfcd437296561ea750c9ec8b","source":"clob_market_ws"},"received_at":"2026-07-27T05:42:12.025693Z","record_id":"91d24a93292834d69725c0c7caeb1640fc0883f57835d88d47544f460229fdb4","schema_fingerprint":"4aa3821a28b0b7c2400bc59aba4bcc0a76e971dadd19610d3ad38c768e124dc7","schema_version":"edge-lab-recorder.raw.v1","sequence":null,"source":"clob_market_ws"}
{"event_at":"2026-07-27T05:42:11.776000Z","event_fingerprint":"c524084ad6bc0b17155a0c46d0ce1adc7285e35e8cfca34150f105cbfaa2ceea","payload":{"connection_id":"efc69d3132f1467b8e898a382b23ac0d","event_at":"2026-07-27T05:42:11.776000Z","event_type":"price_change","frame_hash":"a1aa53cb142acd0a80ca4fd9095b38528801d00d5e54492d8b62f2086070ebc2","frame_index":0,"kind":"data","monotonic_ns":232915262036333,"payload":{"event_type":"price_change","market":"0x3b40066b5cf3871a2f6237c5628bd8092a206aa998558ac5ec13c4483e31e160","price_changes":[{"asset_id":"14766054693214075530629349735273995982307625376442606753688071083149620216746","best_ask":"0.74","best_bid":"0.73","hash":"3542f1e49c4de23f398f18e022cd58ee5fad0b80","price":"0.63","side":"BUY","size":"50.65"},{"asset_id":"110216635572655435074987471276357323571387854733835379371586402147734167783946","best_ask":"0.27","best_bid":"0.26","hash":"47677a18465fbaa4075ba0feff82befd08bc17bb","price":"0.37","side":"SELL","size":"50.65"}],"timestamp":"1785130931776"},"payload_hash":"549c96def9bd354fea75fdc97247ad8f26176fbe3ed28ecf0fe7408b6d1d4a64","raw_frame":"{\"market\":\"0x3b40066b5cf3871a2f6237c5628bd8092a206aa998558ac5ec13c4483e31e160\", \"price_changes\":[{\"asset_id\":\"14766054693214075530629349735273995982307625376442606753688071083149620216746\", \"price\":\"0.63\", \"size\":\"50.65\", \"side\":\"BUY\", \"hash\":\"3542f1e49c4de23f398f18e022cd58ee5fad0b80\", \"best_bid\":\"0.73\", \"best_ask\":\"0.74\"}, {\"asset_id\":\"110216635572655435074987471276357323571387854733835379371586402147734167783946\", \"price\":\"0.37\", \"size\":\"50.65\", \"side\":\"SELL\", \"hash\":\"47677a18465fbaa4075ba0feff82befd08bc17bb\", \"best_bid\":\"0.26\", \"best_ask\":\"0.27\"}], \"timestamp\":\"1785130931776\", \"event_type\":\"price_change\"}","received_at":"2026-07-27T05:42:12.028914Z","schema_version":"clob-market-ws.price_change.v1","sequence":null,"server_hash":null,"server_timestamp":"1785130931776","session_id":"502006c5cfcd437296561ea750c9ec8b","source":"clob_market_ws"},"received_at":"2026-07-27T05:42:12.028914Z","record_id":"941983b04e7bdc47a1b71c9f08f8dca294b42b9f15676ed9b690cd85ae164f0a","schema_fingerprint":"4aa3821a28b0b7c2400bc59aba4bcc0a76e971dadd19610d3ad38c768e124dc7","schema_version":"edge-lab-recorder.raw.v1","sequence":null,"source":"clob_market_ws"}
{"event_at":"2026-07-27T05:42:11.783000Z","event_fingerprint":"35451d3f7abaac38fff9acef25c724088a3ebaf6873f5132262f2c7d2a021c66","payload":{"connection_id":"efc69d3132f1467b8e898a382b23ac0d","event_at":"2026-07-27T05:42:11.783000Z","event_type":"price_change","frame_hash":"bb062c3d2f910020ffc10db298a60244d86242eec2802912e4ad84c44c80ba54","frame_index":0,"kind":"data","monotonic_ns":232915264510875,"payload":{"event_type":"price_change","market":"0x3b40066b5cf3871a2f6237c5628bd8092a206aa998558ac5ec13c4483e31e160","price_changes":[{"asset_id":"14766054693214075530629349735273995982307625376442606753688071083149620216746","best_ask":"0.74","best_bid":"0.73","hash":"9c9f4f233174806941fa9241b8d464d6818f6021","price":"0.62","side":"BUY","size":"38"},{"asset_id":"110216635572655435074987471276357323571387854733835379371586402147734167783946","best_ask":"0.27","best_bid":"0.26","hash":"4950dc19c242424255ab96ab448c44003a987ac6","price":"0.38","side":"SELL","size":"38"}],"timestamp":"1785130931783"},"payload_hash":"e6ab6ba2811d13892e1a03c21abb0c597992e0d8ba8b890a3d7563d26d4ed181","raw_frame":"{\"market\":\"0x3b40066b5cf3871a2f6237c5628bd8092a206aa998558ac5ec13c4483e31e160\", \"price_changes\":[{\"asset_id\":\"14766054693214075530629349735273995982307625376442606753688071083149620216746\", \"price\":\"0.62\", \"size\":\"38\", \"side\":\"BUY\", \"hash\":\"9c9f4f233174806941fa9241b8d464d6818f6021\", \"best_bid\":\"0.73\", \"best_ask\":\"0.74\"}, {\"asset_id\":\"110216635572655435074987471276357323571387854733835379371586402147734167783946\", \"price\":\"0.38\", \"size\":\"38\", \"side\":\"SELL\", \"hash\":\"4950dc19c242424255ab96ab448c44003a987ac6\", \"best_bid\":\"0.26\", \"best_ask\":\"0.27\"}], \"timestamp\":\"1785130931783\", \"event_type\":\"price_change\"}","received_at":"2026-07-27T05:42:12.031393Z","schema_version":"clob-market-ws.price_change.v1","sequence":null,"server_hash":null,"server_timestamp":"1785130931783","session_id":"502006c5cfcd437296561ea750c9ec8b","source":"clob_market_ws"},"received_at":"2026-07-27T05:42:12.031393Z","record_id":"f2f39110c326352ba373b4ac49bb86cc4148ff198adcc628eb553c5f54bd1dff","schema_fingerprint":"4aa3821a28b0b7c2400bc59aba4bcc0a76e971dadd19610d3ad38c768e124dc7","schema_version":"edge-lab-recorder.raw.v1","sequence":null,"source":"clob_market_ws"}
{"event_at":"2026-07-27T05:42:11.784000Z","event_fingerprint":"bc6a01212b6790a6df2be1d24d839005fa68e6e885d352f0d3148d1febfd5508","payload":{"connection_id":"efc69d3132f1467b8e898a382b23ac0d","event_at":"2026-07-27T05:42:11.784000Z","event_type":"price_change","frame_hash":"166948bee68c758396dd89547cea7399fb408c27153c0d8d0943e543f2ddf876","frame_index":0,"kind":"data","monotonic_ns":232915267375000,"payload":{"event_type":"price_change","market":"0x3b40066b5cf3871a2f6237c5628bd8092a206aa998558ac5ec13c4483e31e160","price_changes":[{"asset_id":"14766054693214075530629349735273995982307625376442606753688071083149620216746","best_ask":"0.74","best_bid":"0.73","hash":"e4e12c7dc1fdf797217627a170b9fdedc5cbb8b9","price":"0.51","side":"BUY","size":"38"},{"asset_id":"110216635572655435074987471276357323571387854733835379371586402147734167783946","best_ask":"0.27","best_bid":"0.26","hash":"897fa7948b769de3428526b779a20fe5d2a869ad","price":"0.49","side":"SELL","size":"38"}],"timestamp":"1785130931784"},"payload_hash":"8839decb94637df67f8fb73d2204b9b2f0668a322e89d9c7e6c179d113cb3701","raw_frame":"{\"market\":\"0x3b40066b5cf3871a2f6237c5628bd8092a206aa998558ac5ec13c4483e31e160\", \"price_changes\":[{\"asset_id\":\"14766054693214075530629349735273995982307625376442606753688071083149620216746\", \"price\":\"0.51\", \"size\":\"38\", \"side\":\"BUY\", \"hash\":\"e4e12c7dc1fdf797217627a170b9fdedc5cbb8b9\", \"best_bid\":\"0.73\", \"best_ask\":\"0.74\"}, {\"asset_id\":\"110216635572655435074987471276357323571387854733835379371586402147734167783946\", \"price\":\"0.49\", \"size\":\"38\", \"side\":\"SELL\", \"hash\":\"897fa7948b769de3428526b779a20fe5d2a869ad\", \"best_bid\":\"0.26\", \"best_ask\":\"0.27\"}], \"timestamp\":\"1785130931784\", \"event_type\":\"price_change\"}","received_at":"2026-07-27T05:42:12.034252Z","schema_version":"clob-market-ws.price_change.v1","sequence":null,"server_hash":null,"server_timestamp":"1785130931784","session_id":"502006c5cfcd437296561ea750c9ec8b","source":"clob_market_ws"},"received_at":"2026-07-27T05:42:12.034252Z","record_id":"03023d413d3afba466c3cdf849580037e35314da50046ca817772f76f6db98c6","schema_fingerprint":"4aa3821a28b0b7c2400bc59aba4bcc0a76e971dadd19610d3ad38c768e124dc7","schema_version":"edge-lab-recorder.raw.v1","sequence":null,"source":"clob_market_ws"}
{"event_at":"2026-07-27T05:42:11.799000Z","event_fingerprint":"7085ecd7f179213d93f3a8bcbeac8f1357d980a466fa209b2b74135910b34671","payload":{"connection_id":"efc69d3132f1467b8e898a382b23ac0d","event_at":"2026-07-27T05:42:11.799000Z","event_type":"price_change","frame_hash":"30233471773c7a90f3062e6653b505e77199cdfbdf306a002b4a3885d9242f63","frame_index":0,"kind":"data","monotonic_ns":232915270200333,"payload":{"event_type":"price_change","market":"0x3b40066b5cf3871a2f6237c5628bd8092a206aa998558ac5ec13c4483e31e160","price_changes":[{"asset_id":"110216635572655435074987471276357323571387854733835379371586402147734167783946","best_ask":"0.27","best_bid":"0.26","hash":"cc200cef336b10790336d5578fcaca7f8728c0a9","price":"0.26","side":"BUY","size":"64"},{"asset_id":"14766054693214075530629349735273995982307625376442606753688071083149620216746","best_ask":"0.74","best_bid":"0.73","hash":"3d2e145c0d2d472b49301f057ee3ae05663c10f3","price":"0.74","side":"SELL","size":"64"}],"timestamp":"1785130931799"},"payload_hash":"0c400e646af7f4d5e004d6821c5bd9debb47612ee749f9696de06639ac77fccd","raw_frame":"{\"market\":\"0x3b40066b5cf3871a2f6237c5628bd8092a206aa998558ac5ec13c4483e31e160\", \"price_changes\":[{\"asset_id\":\"110216635572655435074987471276357323571387854733835379371586402147734167783946\", \"price\":\"0.26\", \"size\":\"64\", \"side\":\"BUY\", \"hash\":\"cc200cef336b10790336d5578fcaca7f8728c0a9\", \"best_bid\":\"0.26\", \"best_ask\":\"0.27\"}, {\"asset_id\":\"14766054693214075530629349735273995982307625376442606753688071083149620216746\", \"price\":\"0.74\", \"size\":\"64\", \"side\":\"SELL\", \"hash\":\"3d2e145c0d2d472b49301f057ee3ae05663c10f3\", \"best_bid\":\"0.73\", \"best_ask\":\"0.74\"}], \"timestamp\":\"1785130931799\", \"event_type\":\"price_change\"}","received_at":"2026-07-27T05:42:12.037078Z","schema_version":"clob-market-ws.price_change.v1","sequence":null,"server_hash":null,"server_timestamp":"1785130931799","session_id":"502006c5cfcd437296561ea750c9ec8b","source":"clob_market_ws"},"received_at":"2026-07-27T05:42:12.037078Z","record_id":"afde980de4bd027e321f6225a9692863ae9053de55388238f841c69793da1c91","schema_fingerprint":"4aa3821a28b0b7c2400bc59aba4bcc0a76e971dadd19610d3ad38c768e124dc7","schema_version":"edge-lab-recorder.raw.v1","sequence":null,"source":"clob_market_ws"}
{"event_at":"2026-07-27T05:42:11.804000Z","event_fingerprint":"4c3e05024e65b2b2247839c7304629f111d5a345eeff0052f93f9f41ac5f1012","payload":{"connection_id":"efc69d3132f1467b8e898a382b23ac0d","event_at":"2026-07-27T05:42:11.804000Z","event_type":"price_change","frame_hash":"cd84b4b8ef9617d1e5d311cec2774eea465b9218537cb7534dacf836f484a300","frame_index":0,"kind":"data","monotonic_ns":232915273142416,"payload":{"event_type":"price_change","market":"0x3b40066b5cf3871a2f6237c5628bd8092a206aa998558ac5ec13c4483e31e160","price_changes":[{"asset_id":"14766054693214075530629349735273995982307625376442606753688071083149620216746","best_ask":"0.74","best_bid":"0.73","hash":"ad88756b0121fe91e537a09d7f159973be088508","price":"0.61","side":"BUY","size":"98"},{"asset_id":"110216635572655435074987471276357323571387854733835379371586402147734167783946","best_ask":"0.27","best_bid":"0.26","hash":"68d7cb833af32b38a1f6de748abcc28250fd8144","price":"0.39","side":"SELL","size":"98"}],"timestamp":"1785130931804"},"payload_hash":"5fde4935b708f73088cd85f50626de673845842990eb76d9d634da7226f8065f","raw_frame":"{\"market\":\"0x3b40066b5cf3871a2f6237c5628bd8092a206aa998558ac5ec13c4483e31e160\", \"price_changes\":[{\"asset_id\":\"14766054693214075530629349735273995982307625376442606753688071083149620216746\", \"price\":\"0.61\", \"size\":\"98\", \"side\":\"BUY\", \"hash\":\"ad88756b0121fe91e537a09d7f159973be088508\", \"best_bid\":\"0.73\", \"best_ask\":\"0.74\"}, {\"asset_id\":\"110216635572655435074987471276357323571387854733835379371586402147734167783946\", \"price\":\"0.39\", \"size\":\"98\", \"side\":\"SELL\", \"hash\":\"68d7cb833af32b38a1f6de748abcc28250fd8144\", \"best_bid\":\"0.26\", \"best_ask\":\"0.27\"}], \"timestamp\":\"1785130931804\", \"event_type\":\"price_change\"}","received_at":"2026-07-27T05:42:12.040019Z","schema_version":"clob-market-ws.price_change.v1","sequence":null,"server_hash":null,"server_timestamp":"1785130931804","session_id":"502006c5cfcd437296561ea750c9ec8b","source":"clob_market_ws"},"received_at":"2026-07-27T05:42:12.040019Z","record_id":"2ffca2530a456e99aad1af8527b15d63091fde23650b45d33614582883389f88","schema_fingerprint":"4aa3821a28b0b7c2400bc59aba4bcc0a76e971dadd19610d3ad38c768e124dc7","schema_version":"edge-lab-recorder.raw.v1","sequence":null,"source":"clob_market_ws"}
{"event_at":"2026-07-27T05:42:11.806000Z","event_fingerprint":"22ef2e988a7d0eb5d86969e258a10f1837dce352f5951dc0d1e48d415952eb41","payload":{"connection_id":"efc69d3132f1467b8e898a382b23ac0d","event_at":"2026-07-27T05:42:11.806000Z","event_type":"price_change","frame_hash":"bca4d4fdc45778f455d02f473ca6279063d532d590d016d1cdffede0f608d251","frame_index":0,"kind":"data","monotonic_ns":232915275951208,"payload":{"event_type":"price_change","market":"0x3b40066b5cf3871a2f6237c5628bd8092a206aa998558ac5ec13c4483e31e160","price_changes":[{"asset_id":"14766054693214075530629349735273995982307625376442606753688071083149620216746","best_ask":"0.74","best_bid":"0.73","hash":"234f7bc50ab5358f508c164ec171b46b5a06cec7","price":"0.57","side":"BUY","size":"68"},{"asset_id":"110216635572655435074987471276357323571387854733835379371586402147734167783946","best_ask":"0.27","best_bid":"0.26","hash":"282fce1f224087c499cd52295a2d7528bf6626e3","price":"0.43","side":"SELL","size":"68"}],"timestamp":"1785130931806"},"payload_hash":"a23530ea88fa61799e0949c6d4247b0a2708b4f7478d39924b941348fb4bf735","raw_frame":"{\"market\":\"0x3b40066b5cf3871a2f6237c5628bd8092a206aa998558ac5ec13c4483e31e160\", \"price_changes\":[{\"asset_id\":\"14766054693214075530629349735273995982307625376442606753688071083149620216746\", \"price\":\"0.57\", \"size\":\"68\", \"side\":\"BUY\", \"hash\":\"234f7bc50ab5358f508c164ec171b46b5a06cec7\", \"best_bid\":\"0.73\", \"best_ask\":\"0.74\"}, {\"asset_id\":\"110216635572655435074987471276357323571387854733835379371586402147734167783946\", \"price\":\"0.43\", \"size\":\"68\", \"side\":\"SELL\", \"hash\":\"282fce1f224087c499cd52295a2d7528bf6626e3\", \"best_bid\":\"0.26\", \"best_ask\":\"0.27\"}], \"timestamp\":\"1785130931806\", \"event_type\":\"price_change\"}","received_at":"2026-07-27T05:42:12.042828Z","schema_version":"clob-market-ws.price_change.v1","sequence":null,"server_hash":null,"server_timestamp":"1785130931806","session_id":"502006c5cfcd437296561ea750c9ec8b","source":"clob_market_ws"},"received_at":"2026-07-27T05:42:12.042828Z","record_id":"10c264e1a8026cbaefedfc8d94c9fc01a547f3c2ae76cd61e9d4bc4df5469f68","schema_fingerprint":"4aa3821a28b0b7c2400bc59aba4bcc0a76e971dadd19610d3ad38c768e124dc7","schema_version":"edge-lab-recorder.raw.v1","sequence":null,"source":"clob_market_ws"}
{"event_at":"2026-07-27T05:42:11.808000Z","event_fingerprint":"5195c69d9663905119e7cc759d06cb95e6c07fef6b0abbf2b82dbcea33317c2a","payload":{"connection_id":"efc69d3132f1467b8e898a382b23ac0d","event_at":"2026-07-27T05:42:11.808000Z","event_type":"price_change","frame_hash":"82d5d6f3e15eea1064752b61fddb71c08cfee2729c29cf6209e066115818bc03","frame_index":0,"kind":"data","monotonic_ns":232915278784750,"payload":{"event_type":"price_change","market":"0x3b40066b5cf3871a2f6237c5628bd8092a206aa998558ac5ec13c4483e31e160","price_changes":[{"asset_id":"14766054693214075530629349735273995982307625376442606753688071083149620216746","best_ask":"0.74","best_bid":"0.73","hash":"26663efead6fcb466d3be19d3cfec936498d06fb","price":"0.01","side":"BUY","size":"5330.02"},{"asset_id":"110216635572655435074987471276357323571387854733835379371586402147734167783946","best_ask":"0.27","best_bid":"0.26","hash":"430a43f03d9e0c005532ef45f78049d903b1e8c1","price":"0.99","side":"SELL","size":"5330.02"}],"timestamp":"1785130931808"},"payload_hash":"b69bca51b75fe1f5e33d138912b96a098e31019130c09391ce6ec5f332340d0e","raw_frame":"{\"market\":\"0x3b40066b5cf3871a2f6237c5628bd8092a206aa998558ac5ec13c4483e31e160\", \"price_changes\":[{\"asset_id\":\"14766054693214075530629349735273995982307625376442606753688071083149620216746\", \"price\":\"0.01\", \"size\":\"5330.02\", \"side\":\"BUY\", \"hash\":\"26663efead6fcb466d3be19d3cfec936498d06fb\", \"best_bid\":\"0.73\", \"best_ask\":\"0.74\"}, {\"asset_id\":\"110216635572655435074987471276357323571387854733835379371586402147734167783946\", \"price\":\"0.99\", \"size\":\"5330.02\", \"side\":\"SELL\", \"hash\":\"430a43f03d9e0c005532ef45f78049d903b1e8c1\", \"best_bid\":\"0.26\", \"best_ask\":\"0.27\"}], \"timestamp\":\"1785130931808\", \"event_type\":\"price_change\"}","received_at":"2026-07-27T05:42:12.045662Z","schema_version":"clob-market-ws.price_change.v1","sequence":null,"server_hash":null,"server_timestamp":"1785130931808","session_id":"502006c5cfcd437296561ea750c9ec8b","source":"clob_market_ws"},"received_at":"2026-07-27T05:42:12.045662Z","record_id":"ef7f9ca66edb0ad055c809ad8fcd1400fd982af5cdb5e6147a421d9a5a437fdb","schema_fingerprint":"4aa3821a28b0b7c2400bc59aba4bcc0a76e971dadd19610d3ad38c768e124dc7","schema_version":"edge-lab-recorder.raw.v1","sequence":null,"source":"clob_market_ws"}
{"event_at":"2026-07-27T05:42:11.810000Z","event_fingerprint":"e2cd01b58b50775005117411910c0d9a99ced0ff663ab141f9318c793478742f","payload":{"connection_id":"efc69d3132f1467b8e898a382b23ac0d","event_at":"2026-07-27T05:42:11.810000Z","event_type":"price_change","frame_hash":"589ef7cd16e809da120169467e695e53a3e2c0ad5faee9b1e39a21ac2983c751","frame_index":0,"kind":"data","monotonic_ns":232915281238000,"payload":{"event_type":"price_change","market":"0x3b40066b5cf3871a2f6237c5628bd8092a206aa998558ac5ec13c4483e31e160","price_changes":[{"asset_id":"14766054693214075530629349735273995982307625376442606753688071083149620216746","best_ask":"0.74","best_bid":"0.73","hash":"706cd18880c485b500357225fd5644301c7c1d52","price":"0.74","side":"SELL","size":"89"},{"asset_id":"110216635572655435074987471276357323571387854733835379371586402147734167783946","best_ask":"0.27","best_bid":"0.26","hash":"af0f762da0bf52ea55f98c20a800d5896bde64c5","price":"0.26","side":"BUY","size":"89"}],"timestamp":"1785130931810"},"payload_hash":"8df63091e7ea7604ee560fd2397af125f2dbd4ed20ac77e3899d4e238b883759","raw_frame":"{\"market\":\"0x3b40066b5cf3871a2f6237c5628bd8092a206aa998558ac5ec13c4483e31e160\", \"price_changes\":[{\"asset_id\":\"14766054693214075530629349735273995982307625376442606753688071083149620216746\", \"price\":\"0.74\", \"size\":\"89\", \"side\":\"SELL\", \"hash\":\"706cd18880c485b500357225fd5644301c7c1d52\", \"best_bid\":\"0.73\", \"best_ask\":\"0.74\"}, {\"asset_id\":\"110216635572655435074987471276357323571387854733835379371586402147734167783946\", \"price\":\"0.26\", \"size\":\"89\", \"side\":\"BUY\", \"hash\":\"af0f762da0bf52ea55f98c20a800d5896bde64c5\", \"best_bid\":\"0.26\", \"best_ask\":\"0.27\"}], \"timestamp\":\"1785130931810\", \"event_type\":\"price_change\"}","received_at":"2026-07-27T05:42:12.048121Z","schema_version":"clob-market-ws.price_change.v1","sequence":null,"server_hash":null,"server_timestamp":"1785130931810","session_id":"502006c5cfcd437296561ea750c9ec8b","source":"clob_market_ws"},"received_at":"2026-07-27T05:42:12.048121Z","record_id":"8167f53e6761b573a94f8148465a8e803c6cd07db29e6c2098713cc69710c1d3","schema_fingerprint":"4aa3821a28b0b7c2400bc59aba4bcc0a76e971dadd19610d3ad38c768e124dc7","schema_version":"edge-lab-recorder.raw.v1","sequence":null,"source":"clob_market_ws"}
{"event_at":"2026-07-27T05:42:11.812000Z","event_fingerprint":"78a51e98285db2588d40fa01e6efa5749dcc63addeed929ebfdc695864be0322","payload":{"connection_id":"efc69d3132f1467b8e898a382b23ac0d","event_at":"2026-07-27T05:42:11.812000Z","event_type":"price_change","frame_hash":"afa48622d07696b4958fbf557d9167efedbdff5d6b42bea04dddf2c747f99315","frame_index":0,"kind":"data","monotonic_ns":232915283335333,"payload":{"event_type":"price_change","market":"0x3b40066b5cf3871a2f6237c5628bd8092a206aa998558ac5ec13c4483e31e160","price_changes":[{"asset_id":"14766054693214075530629349735273995982307625376442606753688071083149620216746","best_ask":"0.74","best_bid":"0.73","hash":"13347ca1fd7f22f6699923d87e5ea3eb58b661a1","price":"0.6","side":"BUY","size":"68"},{"asset_id":"110216635572655435074987471276357323571387854733835379371586402147734167783946","best_ask":"0.27","best_bid":"0.26","hash":"b12ddd9406df657c76a9bb3d1072349547eb9f03","price":"0.4","side":"SELL","size":"68"}],"timestamp":"1785130931812"},"payload_hash":"9470b03fb5e8b2b05b53fba968e59e271813fe260d151beb69361ac5a6364443","raw_frame":"{\"market\":\"0x3b40066b5cf3871a2f6237c5628bd8092a206aa998558ac5ec13c4483e31e160\", \"price_changes\":[{\"asset_id\":\"14766054693214075530629349735273995982307625376442606753688071083149620216746\", \"price\":\"0.6\", \"size\":\"68\", \"side\":\"BUY\", \"hash\":\"13347ca1fd7f22f6699923d87e5ea3eb58b661a1\", \"best_bid\":\"0.73\", \"best_ask\":\"0.74\"}, {\"asset_id\":\"110216635572655435074987471276357323571387854733835379371586402147734167783946\", \"price\":\"0.4\", \"size\":\"68\", \"side\":\"SELL\", \"hash\":\"b12ddd9406df657c76a9bb3d1072349547eb9f03\", \"best_bid\":\"0.26\", \"best_ask\":\"0.27\"}], \"timestamp\":\"1785130931812\", \"event_type\":\"price_change\"}","received_at":"2026-07-27T05:42:12.050212Z","schema_version":"clob-market-ws.price_change.v1","sequence":null,"server_hash":null,"server_timestamp":"1785130931812","session_id":"502006c5cfcd437296561ea750c9ec8b","source":"clob_market_ws"},"received_at":"2026-07-27T05:42:12.050212Z","record_id":"cf34119ea18a019cc0a229d71da9bbf68a7f594ff3a3504f7910adf5713f55eb","schema_fingerprint":"4aa3821a28b0b7c2400bc59aba4bcc0a76e971dadd19610d3ad38c768e124dc7","schema_version":"edge-lab-recorder.raw.v1","sequence":null,"source":"clob_market_ws"}
{"event_at":"2026-07-27T05:42:11.826000Z","event_fingerprint":"6f6b6d0866826524fb31e15b166e43c42062e5c05b011b742349eb4f459c3c1a","payload":{"connection_id":"efc69d3132f1467b8e898a382b23ac0d","event_at":"2026-07-27T05:42:11.826000Z","event_type":"price_change","frame_hash":"de9b090a930742c259035eedb274cc63246bf2b2245f2fd50e4cecb0f264814b","frame_index":0,"kind":"data","monotonic_ns":232915286200500,"payload":{"event_type":"price_change","market":"0x3b40066b5cf3871a2f6237c5628bd8092a206aa998558ac5ec13c4483e31e160","price_changes":[{"asset_id":"14766054693214075530629349735273995982307625376442606753688071083149620216746","best_ask":"0.74","best_bid":"0.73","hash":"c9dfbcb9adfee4c366ad9f3264a7bfb94da9f910","price":"0.83","side":"SELL","size":"175.95"},{"asset_id":"110216635572655435074987471276357323571387854733835379371586402147734167783946","best_ask":"0.27","best_bid":"0.26","hash":"684fda60cb2630628efce429fcebfcc7265305f9","price":"0.17","side":"BUY","size":"175.95"}],"timestamp":"1785130931826"},"payload_hash":"078ee5bd74557e196f43e78566cc61b87198bffe720a122eb987c8ec242ae4a8","raw_frame":"{\"market\":\"0x3b40066b5cf3871a2f6237c5628bd8092a206aa998558ac5ec13c4483e31e160\", \"price_changes\":[{\"asset_id\":\"14766054693214075530629349735273995982307625376442606753688071083149620216746\", \"price\":\"0.83\", \"size\":\"175.95\", \"side\":\"SELL\", \"hash\":\"c9dfbcb9adfee4c366ad9f3264a7bfb94da9f910\", \"best_bid\":\"0.73\", \"best_ask\":\"0.74\"}, {\"asset_id\":\"110216635572655435074987471276357323571387854733835379371586402147734167783946\", \"price\":\"0.17\", \"size\":\"175.95\", \"side\":\"BUY\", \"hash\":\"684fda60cb2630628efce429fcebfcc7265305f9\", \"best_bid\":\"0.26\", \"best_ask\":\"0.27\"}], \"timestamp\":\"1785130931826\", \"event_type\":\"price_change\"}","received_at":"2026-07-27T05:42:12.053078Z","schema_version":"clob-market-ws.price_change.v1","sequence":null,"server_hash":null,"server_timestamp":"1785130931826","session_id":"502006c5cfcd437296561ea750c9ec8b","source":"clob_market_ws"},"received_at":"2026-07-27T05:42:12.053078Z","record_id":"7b10a081a9e24c8431da23ea1747e58309a42dcadc1deb08a10544c6ef96d215","schema_fingerprint":"4aa3821a28b0b7c2400bc59aba4bcc0a76e971dadd19610d3ad38c768e124dc7","schema_version":"edge-lab-recorder.raw.v1","sequence":null,"source":"clob_market_ws"}
{"event_at":"2026-07-27T05:42:11.833000Z","event_fingerprint":"cd18cb959f05a44e672df17e59c438eceb004d0f98196e2e198c961f368baef5","payload":{"connection_id":"efc69d3132f1467b8e898a382b23ac0d","event_at":"2026-07-27T05:42:11.833000Z","event_type":"price_change","frame_hash":"880ac93ef937be4404de78e5c79033cfa7af47b5bdf1744722a8700868f539f2","frame_index":0,"kind":"data","monotonic_ns":232915289074208,"payload":{"event_type":"price_change","market":"0x3b40066b5cf3871a2f6237c5628bd8092a206aa998558ac5ec13c4483e31e160","price_changes":[{"asset_id":"14766054693214075530629349735273995982307625376442606753688071083149620216746","best_ask":"0.74","best_bid":"0.73","hash":"e09179a2dd3303a0b37e477d8c3dbaf0dc2847d6","price":"0.52","side":"BUY","size":"73.2"},{"asset_id":"110216635572655435074987471276357323571387854733835379371586402147734167783946","best_ask":"0.27","best_bid":"0.26","hash":"b7be41a4fb55d0f96f3ee97d0463d830f520f8fe","price":"0.48","side":"SELL","size":"73.2"}],"timestamp":"1785130931833"},"payload_hash":"7d7eb741ff71af6ac0cdea4b20f11ba4e8c858c27e238d3a2e9c5d4ef0d71a93","raw_frame":"{\"market\":\"0x3b40066b5cf3871a2f6237c5628bd8092a206aa998558ac5ec13c4483e31e160\", \"price_changes\":[{\"asset_id\":\"14766054693214075530629349735273995982307625376442606753688071083149620216746\", \"price\":\"0.52\", \"size\":\"73.2\", \"side\":\"BUY\", \"hash\":\"e09179a2dd3303a0b37e477d8c3dbaf0dc2847d6\", \"best_bid\":\"0.73\", \"best_ask\":\"0.74\"}, {\"asset_id\":\"110216635572655435074987471276357323571387854733835379371586402147734167783946\", \"price\":\"0.48\", \"size\":\"73.2\", \"side\":\"SELL\", \"hash\":\"b7be41a4fb55d0f96f3ee97d0463d830f520f8fe\", \"best_bid\":\"0.26\", \"best_ask\":\"0.27\"}], \"timestamp\":\"1785130931833\", \"event_type\":\"price_change\"}","received_at":"2026-07-27T05:42:12.055952Z","schema_version":"clob-market-ws.price_change.v1","sequence":null,"server_hash":null,"server_timestamp":"1785130931833","session_id":"502006c5cfcd437296561ea750c9ec8b","source":"clob_market_ws"},"received_at":"2026-07-27T05:42:12.055952Z","record_id":"5c95284ec322d17a98c48bac6240f51f2771933b7c2b5b6fa162f03c006169a4","schema_fingerprint":"4aa3821a28b0b7c2400bc59aba4bcc0a76e971dadd19610d3ad38c768e124dc7","schema_version":"edge-lab-recorder.raw.v1","sequence":null,"source":"clob_market_ws"}
{"event_at":"2026-07-27T05:42:11.894000Z","event_fingerprint":"389356039c7a88b812cdd8f6b81f4b7fb9c27f948a7cf633589f0e115e0e54c3","payload":{"connection_id":"efc69d3132f1467b8e898a382b23ac0d","event_at":"2026-07-27T05:42:11.894000Z","event_type":"price_change","frame_hash":"7834e3ec7fbc80e3da86e05bea0e7b5886b46561985886d0b53cbe2f9c930681","frame_index":0,"kind":"data","monotonic_ns":232915291873791,"payload":{"event_type":"price_change","market":"0x3b40066b5cf3871a2f6237c5628bd8092a206aa998558ac5ec13c4483e31e160","price_changes":[{"asset_id":"14766054693214075530629349735273995982307625376442606753688071083149620216746","best_ask":"0.74","best_bid":"0.73","hash":"cf6d1dd677ed45fcf4cee3b6b7711a649bb96a65","price":"0.48","side":"BUY","size":"246.32"},{"asset_id":"110216635572655435074987471276357323571387854733835379371586402147734167783946","best_ask":"0.27","best_bid":"0.26","hash":"b316bd2e1afb6b709055dba7b2df49b27bbd2472","price":"0.52","side":"SELL","size":"246.32"}],"timestamp":"1785130931894"},"payload_hash":"9a678c20cb11a1c0a409aaa6a2fad6b0d632f8b1c8eb129786f6f2710376ce61","raw_frame":"{\"market\":\"0x3b40066b5cf3871a2f6237c5628bd8092a206aa998558ac5ec13c4483e31e160\", \"price_changes\":[{\"asset_id\":\"14766054693214075530629349735273995982307625376442606753688071083149620216746\", \"price\":\"0.48\", \"size\":\"246.32\", \"side\":\"BUY\", \"hash\":\"cf6d1dd677ed45fcf4cee3b6b7711a649bb96a65\", \"best_bid\":\"0.73\", \"best_ask\":\"0.74\"}, {\"asset_id\":\"110216635572655435074987471276357323571387854733835379371586402147734167783946\", \"price\":\"0.52\", \"size\":\"246.32\", \"side\":\"SELL\", \"hash\":\"b316bd2e1afb6b709055dba7b2df49b27bbd2472\", \"best_bid\":\"0.26\", \"best_ask\":\"0.27\"}], \"timestamp\":\"1785130931894\", \"event_type\":\"price_change\"}","received_at":"2026-07-27T05:42:12.058752Z","schema_version":"clob-market-ws.price_change.v1","sequence":null,"server_hash":null,"server_timestamp":"1785130931894","session_id":"502006c5cfcd437296561ea750c9ec8b","source":"clob_market_ws"},"received_at":"2026-07-27T05:42:12.058752Z","record_id":"a0a85e5f18cacf21f795f02a1ecc55c00c20ad92602ca0b96d1ae8a99fb370ee","schema_fingerprint":"4aa3821a28b0b7c2400bc59aba4bcc0a76e971dadd19610d3ad38c768e124dc7","schema_version":"edge-lab-recorder.raw.v1","sequence":null,"source":"clob_market_ws"}
{"event_at":"2026-07-27T05:42:11.924000Z","event_fingerprint":"d068476a5493a75e834fa87c03861d49f45550d1bcb468985aa3568d05da05f7","payload":{"connection_id":"efc69d3132f1467b8e898a382b23ac0d","event_at":"2026-07-27T05:42:11.924000Z","event_type":"price_change","frame_hash":"6735f3a5c67b782d8df7b34b710dcb08fd152fd68854753644acef5f78535edd","frame_index":0,"kind":"data","monotonic_ns":232915294694666,"payload":{"event_type":"price_change","market":"0x3b40066b5cf3871a2f6237c5628bd8092a206aa998558ac5ec13c4483e31e160","price_changes":[{"asset_id":"14766054693214075530629349735273995982307625376442606753688071083149620216746","best_ask":"0.74","best_bid":"0.73","hash":"55050236f09542fbd07ca5388c7f732b9d211f91","price":"0.01","side":"BUY","size":"5335.02"},{"asset_id":"110216635572655435074987471276357323571387854733835379371586402147734167783946","best_ask":"0.27","best_bid":"0.26","hash":"7e097e3b5355e5592e6da79333d5301f8b9c9e23","price":"0.99","side":"SELL","size":"5335.02"}],"timestamp":"1785130931924"},"payload_hash":"e823b74717dac40e3dd932dbd8c1d632ef13508327d7be4747648758f8e9e50d","raw_frame":"{\"market\":\"0x3b40066b5cf3871a2f6237c5628bd8092a206aa998558ac5ec13c4483e31e160\", \"price_changes\":[{\"asset_id\":\"14766054693214075530629349735273995982307625376442606753688071083149620216746\", \"price\":\"0.01\", \"size\":\"5335.02\", \"side\":\"BUY\", \"hash\":\"55050236f09542fbd07ca5388c7f732b9d211f91\", \"best_bid\":\"0.73\", \"best_ask\":\"0.74\"}, {\"asset_id\":\"110216635572655435074987471276357323571387854733835379371586402147734167783946\", \"price\":\"0.99\", \"size\":\"5335.02\", \"side\":\"SELL\", \"hash\":\"7e097e3b5355e5592e6da79333d5301f8b9c9e23\", \"best_bid\":\"0.26\", \"best_ask\":\"0.27\"}], \"timestamp\":\"1785130931924\", \"event_type\":\"price_change\"}","received_at":"2026-07-27T05:42:12.061573Z","schema_version":"clob-market-ws.price_change.v1","sequence":null,"server_hash":null,"server_timestamp":"1785130931924","session_id":"502006c5cfcd437296561ea750c9ec8b","source":"clob_market_ws"},"received_at":"2026-07-27T05:42:12.061573Z","record_id":"b197337c0be4d996845b4c3fb380ec541659af6cda18f4b4dc996e9642b80d29","schema_fingerprint":"4aa3821a28b0b7c2400bc59aba4bcc0a76e971dadd19610d3ad38c768e124dc7","schema_version":"edge-lab-recorder.raw.v1","sequence":null,"source":"clob_market_ws"}
{"event_at":"2026-07-27T05:42:11.931000Z","event_fingerprint":"cfec46dca1c7efc29db597a9a7fb917479ae9126036227babb54b7ce09657fe4","payload":{"connection_id":"efc69d3132f1467b8e898a382b23ac0d","event_at":"2026-07-27T05:42:11.931000Z","event_type":"price_change","frame_hash":"07c40978246377c507c413d65d78cd8ef85800dff53b0e92e00ab914a26521ec","frame_index":0,"kind":"data","monotonic_ns":232915297656666,"payload":{"event_type":"price_change","market":"0x3b40066b5cf3871a2f6237c5628bd8092a206aa998558ac5ec13c4483e31e160","price_changes":[{"asset_id":"14766054693214075530629349735273995982307625376442606753688071083149620216746","best_ask":"0.74","best_bid":"0.73","hash":"3271122a3992e303307303cec8badb3ce21962fa","price":"0.83","side":"SELL","size":"183.99"},{"asset_id":"110216635572655435074987471276357323571387854733835379371586402147734167783946","best_ask":"0.27","best_bid":"0.26","hash":"e01d4967bd3bf0b40879a4ce6b244fbafab060bc","price":"0.17","side":"BUY","size":"183.99"}],"timestamp":"1785130931931"},"payload_hash":"7d2b7fe22753915b93b1169df55e47bed1db01f783e1184a2f63f0720e3f084a","raw_frame":"{\"market\":\"0x3b40066b5cf3871a2f6237c5628bd8092a206aa998558ac5ec13c4483e31e160\", \"price_changes\":[{\"asset_id\":\"14766054693214075530629349735273995982307625376442606753688071083149620216746\", \"price\":\"0.83\", \"size\":\"183.99\", \"side\":\"SELL\", \"hash\":\"3271122a3992e303307303cec8badb3ce21962fa\", \"best_bid\":\"0.73\", \"best_ask\":\"0.74\"}, {\"asset_id\":\"110216635572655435074987471276357323571387854733835379371586402147734167783946\", \"price\":\"0.17\", \"size\":\"183.99\", \"side\":\"BUY\", \"hash\":\"e01d4967bd3bf0b40879a4ce6b244fbafab060bc\", \"best_bid\":\"0.26\", \"best_ask\":\"0.27\"}], \"timestamp\":\"1785130931931\", \"event_type\":\"price_change\"}","received_at":"2026-07-27T05:42:12.064538Z","schema_version":"clob-market-ws.price_change.v1","sequence":null,"server_hash":null,"server_timestamp":"1785130931931","session_id":"502006c5cfcd437296561ea750c9ec8b","source":"clob_market_ws"},"received_at":"2026-07-27T05:42:12.064538Z","record_id":"f15b399ac3e405dc90ba44f9237bc8c1f7ed5a1bf6c380219849ebc396f2555a","schema_fingerprint":"4aa3821a28b0b7c2400bc59aba4bcc0a76e971dadd19610d3ad38c768e124dc7","schema_version":"edge-lab-recorder.raw.v1","sequence":null,"source":"clob_market_ws"}
{"event_at":"2026-07-27T05:42:12.022000Z","event_fingerprint":"53556096e9aae0b773df9040cfe8130c8ec787772f20fb003993445318179c86","payload":{"connection_id":"efc69d3132f1467b8e898a382b23ac0d","event_at":"2026-07-27T05:42:12.022000Z","event_type":"price_change","frame_hash":"5474ac980516f0e5b2e41cd66a6b1b7cb07185007f984827144f2698d4ab95e5","frame_index":0,"kind":"data","monotonic_ns":232915299059291,"payload":{"event_type":"price_change","market":"0x3b40066b5cf3871a2f6237c5628bd8092a206aa998558ac5ec13c4483e31e160","price_changes":[{"asset_id":"110216635572655435074987471276357323571387854733835379371586402147734167783946","best_ask":"0.27","best_bid":"0.26","hash":"deaeed36514487ff558dadd1359bd13afc32230f","price":"0.01","side":"BUY","size":"5437.45"},{"asset_id":"14766054693214075530629349735273995982307625376442606753688071083149620216746","best_ask":"0.74","best_bid":"0.73","hash":"5a3fbd8b231442af20b3386762210c2f1bc45dc5","price":"0.99","side":"SELL","size":"5437.45"}],"timestamp":"1785130932022"},"payload_hash":"2025af7e47f722b2dacd58daf447076e4542dd4a98c17428a463842a323eff66","raw_frame":"{\"market\":\"0x3b40066b5cf3871a2f6237c5628bd8092a206aa998558ac5ec13c4483e31e160\", \"price_changes\":[{\"asset_id\":\"110216635572655435074987471276357323571387854733835379371586402147734167783946\", \"price\":\"0.01\", \"size\":\"5437.45\", \"side\":\"BUY\", \"hash\":\"deaeed36514487ff558dadd1359bd13afc32230f\", \"best_bid\":\"0.26\", \"best_ask\":\"0.27\"}, {\"asset_id\":\"14766054693214075530629349735273995982307625376442606753688071083149620216746\", \"price\":\"0.99\", \"size\":\"5437.45\", \"side\":\"SELL\", \"hash\":\"5a3fbd8b231442af20b3386762210c2f1bc45dc5\", \"best_bid\":\"0.73\", \"best_ask\":\"0.74\"}], \"timestamp\":\"1785130932022\", \"event_type\":\"price_change\"}","received_at":"2026-07-27T05:42:12.065934Z","schema_version":"clob-market-ws.price_change.v1","sequence":null,"server_hash":null,"server_timestamp":"1785130932022","session_id":"502006c5cfcd437296561ea750c9ec8b","source":"clob_market_ws"},"received_at":"2026-07-27T05:42:12.065934Z","record_id":"9eda35e3ddb6ddbe6503834c4f5a2a79e80e8cf2e06097b7e70e78825280f943","schema_fingerprint":"4aa3821a28b0b7c2400bc59aba4bcc0a76e971dadd19610d3ad38c768e124dc7","schema_version":"edge-lab-recorder.raw.v1","sequence":null,"source":"clob_market_ws"}
{"event_at":"2026-07-27T05:42:12.028000Z","event_fingerprint":"e9f4caa1713587bb5b65140889539c98bc0ea1d1d9f3909c1c04a8403905571a","payload":{"connection_id":"efc69d3132f1467b8e898a382b23ac0d","event_at":"2026-07-27T05:42:12.028000Z","event_type":"price_change","frame_hash":"410ecf92fd1091431d271b0f213d420e20ecb4d748edac2696c03b930ceef318","frame_index":0,"kind":"data","monotonic_ns":232915302009625,"payload":{"event_type":"price_change","market":"0x3b40066b5cf3871a2f6237c5628bd8092a206aa998558ac5ec13c4483e31e160","price_changes":[{"asset_id":"110216635572655435074987471276357323571387854733835379371586402147734167783946","best_ask":"0.27","best_bid":"0.26","hash":"12e4f053563ceea085729ba80169c30a3a830f95","price":"0.01","side":"BUY","size":"5442.45"},{"asset_id":"14766054693214075530629349735273995982307625376442606753688071083149620216746","best_ask":"0.74","best_bid":"0.73","hash":"f8be85917ef01746a0d44f63ba5d31b7f406ea5e","price":"0.99","side":"SELL","size":"5442.45"}],"timestamp":"1785130932028"},"payload_hash":"80f7d49d0703b080b678a198505e1ae4f045debcf71ef66da8be538aaf845689","raw_frame":"{\"market\":\"0x3b40066b5cf3871a2f6237c5628bd8092a206aa998558ac5ec13c4483e31e160\", \"price_changes\":[{\"asset_id\":\"110216635572655435074987471276357323571387854733835379371586402147734167783946\", \"price\":\"0.01\", \"size\":\"5442.45\", \"side\":\"BUY\", \"hash\":\"12e4f053563ceea085729ba80169c30a3a830f95\", \"best_bid\":\"0.26\", \"best_ask\":\"0.27\"}, {\"asset_id\":\"14766054693214075530629349735273995982307625376442606753688071083149620216746\", \"price\":\"0.99\", \"size\":\"5442.45\", \"side\":\"SELL\", \"hash\":\"f8be85917ef01746a0d44f63ba5d31b7f406ea5e\", \"best_bid\":\"0.73\", \"best_ask\":\"0.74\"}], \"timestamp\":\"1785130932028\", \"event_type\":\"price_change\"}","received_at":"2026-07-27T05:42:12.068887Z","schema_version":"clob-market-ws.price_change.v1","sequence":null,"server_hash":null,"server_timestamp":"1785130932028","session_id":"502006c5cfcd437296561ea750c9ec8b","source":"clob_market_ws"},"received_at":"2026-07-27T05:42:12.068887Z","record_id":"6560568f66c57c4cc6a7985292d1b521db93c1ca4b81b23a3a039c8990669160","schema_fingerprint":"4aa3821a28b0b7c2400bc59aba4bcc0a76e971dadd19610d3ad38c768e124dc7","schema_version":"edge-lab-recorder.raw.v1","sequence":null,"source":"clob_market_ws"}
{"event_at":"2026-07-27T05:42:12.036000Z","event_fingerprint":"d08cb8704116885b578013eb8f5e2e9094d665ae95e62b7fd1f1401cdece974c","payload":{"connection_id":"efc69d3132f1467b8e898a382b23ac0d","event_at":"2026-07-27T05:42:12.036000Z","event_type":"price_change","frame_hash":"232490d4d7514e0d099edc4695b75c4a38254320a2971f9ffec4ec60c2012148","frame_index":0,"kind":"data","monotonic_ns":232915305000541,"payload":{"event_type":"price_change","market":"0x3b40066b5cf3871a2f6237c5628bd8092a206aa998558ac5ec13c4483e31e160","price_changes":[{"asset_id":"14766054693214075530629349735273995982307625376442606753688071083149620216746","best_ask":"0.74","best_bid":"0.73","hash":"b03dc81cdd2787798ab472f0ff8d9cbfcb4472af","price":"0.83","side":"SELL","size":"175.95"},{"asset_id":"110216635572655435074987471276357323571387854733835379371586402147734167783946","best_ask":"0.27","best_bid":"0.26","hash":"48f5f1b49d6033acae5a6d6d18849edc9f7db214","price":"0.17","side":"BUY","size":"175.95"}],"timestamp":"1785130932036"},"payload_hash":"831a2b7e0f1fefd866a7218d273994348b476d16510f8264bb66dc57d34cadeb","raw_frame":"{\"market\":\"0x3b40066b5cf3871a2f6237c5628bd8092a206aa998558ac5ec13c4483e31e160\", \"price_changes\":[{\"asset_id\":\"14766054693214075530629349735273995982307625376442606753688071083149620216746\", \"price\":\"0.83\", \"size\":\"175.95\", \"side\":\"SELL\", \"hash\":\"b03dc81cdd2787798ab472f0ff8d9cbfcb4472af\", \"best_bid\":\"0.73\", \"best_ask\":\"0.74\"}, {\"asset_id\":\"110216635572655435074987471276357323571387854733835379371586402147734167783946\", \"price\":\"0.17\", \"size\":\"175.95\", \"side\":\"BUY\", \"hash\":\"48f5f1b49d6033acae5a6d6d18849edc9f7db214\", \"best_bid\":\"0.26\", \"best_ask\":\"0.27\"}], \"timestamp\":\"1785130932036\", \"event_type\":\"price_change\"}","received_at":"2026-07-27T05:42:12.071878Z","schema_version":"clob-market-ws.price_change.v1","sequence":null,"server_hash":null,"server_timestamp":"1785130932036","session_id":"502006c5cfcd437296561ea750c9ec8b","source":"clob_market_ws"},"received_at":"2026-07-27T05:42:12.071878Z","record_id":"24d89bcc81675b04f609755aae9db711ed07d398838420aac7d2f844eb48156e","schema_fingerprint":"4aa3821a28b0b7c2400bc59aba4bcc0a76e971dadd19610d3ad38c768e124dc7","schema_version":"edge-lab-recorder.raw.v1","sequence":null,"source":"clob_market_ws"}
{"event_at":"2026-07-27T05:42:12.050000Z","event_fingerprint":"eea52b0ba8a7daa8a33b752a1d5ffa288d611feb4c705bfcacb4123835c92545","payload":{"connection_id":"efc69d3132f1467b8e898a382b23ac0d","event_at":"2026-07-27T05:42:12.050000Z","event_type":"price_change","frame_hash":"ca643ff4d74cf37abfdb94651c06583c8c766ef4e19fba1d306d8c54d4362168","frame_index":0,"kind":"data","monotonic_ns":232915308003083,"payload":{"event_type":"price_change","market":"0x3b40066b5cf3871a2f6237c5628bd8092a206aa998558ac5ec13c4483e31e160","price_changes":[{"asset_id":"110216635572655435074987471276357323571387854733835379371586402147734167783946","best_ask":"0.27","best_bid":"0.26","hash":"ee29a9380a94737a776242d145da819f6d2714b7","price":"0.01","side":"BUY","size":"5437.45"},{"asset_id":"14766054693214075530629349735273995982307625376442606753688071083149620216746","best_ask":"0.74","best_bid":"0.73","hash":"67ae7a17af4d476e13fb614215283ba181ea7f3c","price":"0.99","side":"SELL","size":"5437.45"}],"timestamp":"1785130932050"},"payload_hash":"1d21193f77a083385396337a4513229a366e21235ed39b6ad8735748f43af784","raw_frame":"{\"market\":\"0x3b40066b5cf3871a2f6237c5628bd8092a206aa998558ac5ec13c4483e31e160\", \"price_changes\":[{\"asset_id\":\"110216635572655435074987471276357323571387854733835379371586402147734167783946\", \"price\":\"0.01\", \"size\":\"5437.45\", \"side\":\"BUY\", \"hash\":\"ee29a9380a94737a776242d145da819f6d2714b7\", \"best_bid\":\"0.26\", \"best_ask\":\"0.27\"}, {\"asset_id\":\"14766054693214075530629349735273995982307625376442606753688071083149620216746\", \"price\":\"0.99\", \"size\":\"5437.45\", \"side\":\"SELL\", \"hash\":\"67ae7a17af4d476e13fb614215283ba181ea7f3c\", \"best_bid\":\"0.73\", \"best_ask\":\"0.74\"}], \"timestamp\":\"1785130932050\", \"event_type\":\"price_change\"}","received_at":"2026-07-27T05:42:12.074880Z","schema_version":"clob-market-ws.price_change.v1","sequence":null,"server_hash":null,"server_timestamp":"1785130932050","session_id":"502006c5cfcd437296561ea750c9ec8b","source":"clob_market_ws"},"received_at":"2026-07-27T05:42:12.074880Z","record_id":"ba3f540aaeea299a421f3b4a0ce4f0eb9e4cc097958d33aa637bde1df583936c","schema_fingerprint":"4aa3821a28b0b7c2400bc59aba4bcc0a76e971dadd19610d3ad38c768e124dc7","schema_version":"edge-lab-recorder.raw.v1","sequence":null,"source":"clob_market_ws"}
{"event_at":"2026-07-27T05:42:12.052000Z","event_fingerprint":"3890f509394d08dbda94164f9982f84f2e5427ce30978d9d88b02afab3c31432","payload":{"connection_id":"efc69d3132f1467b8e898a382b23ac0d","event_at":"2026-07-27T05:42:12.052000Z","event_type":"price_change","frame_hash":"5377e510f54638313ff2a4c40e1342e97f8830a8fa17acdcb19ccc692a356721","frame_index":0,"kind":"data","monotonic_ns":232915310946208,"payload":{"event_type":"price_change","market":"0x3b40066b5cf3871a2f6237c5628bd8092a206aa998558ac5ec13c4483e31e160","price_changes":[{"asset_id":"14766054693214075530629349735273995982307625376442606753688071083149620216746","best_ask":"0.74","best_bid":"0.73","hash":"10d1d61c0156211354e3e55e1b934cb45f674479","price":"0.01","side":"BUY","size":"5340.02"},{"asset_id":"110216635572655435074987471276357323571387854733835379371586402147734167783946","best_ask":"0.27","best_bid":"0.26","hash":"7e6f030e2d4da2da6eff7329dfb02e4df99fffa4","price":"0.99","side":"SELL","size":"5340.02"}],"timestamp":"1785130932052"},"payload_hash":"b620db7965dc6b1abe186bbc166000776596db767213868dcbfb6efd7c2c1c64","raw_frame":"{\"market\":\"0x3b40066b5cf3871a2f6237c5628bd8092a206aa998558ac5ec13c4483e31e160\", \"price_changes\":[{\"asset_id\":\"14766054693214075530629349735273995982307625376442606753688071083149620216746\", \"price\":\"0.01\", \"size\":\"5340.02\", \"side\":\"BUY\", \"hash\":\"10d1d61c0156211354e3e55e1b934cb45f674479\", \"best_bid\":\"0.73\", \"best_ask\":\"0.74\"}, {\"asset_id\":\"110216635572655435074987471276357323571387854733835379371586402147734167783946\", \"price\":\"0.99\", \"size\":\"5340.02\", \"side\":\"SELL\", \"hash\":\"7e6f030e2d4da2da6eff7329dfb02e4df99fffa4\", \"best_bid\":\"0.26\", \"best_ask\":\"0.27\"}], \"timestamp\":\"1785130932052\", \"event_type\":\"price_change\"}","received_at":"2026-07-27T05:42:12.077824Z","schema_version":"clob-market-ws.price_change.v1","sequence":null,"server_hash":null,"server_timestamp":"1785130932052","session_id":"502006c5cfcd437296561ea750c9ec8b","source":"clob_market_ws"},"received_at":"2026-07-27T05:42:12.077824Z","record_id":"7a1ccd90e6fd467b07bae9881fd8317e6345d3e55f48c1fe255c14955232fa83","schema_fingerprint":"4aa3821a28b0b7c2400bc59aba4bcc0a76e971dadd19610d3ad38c768e124dc7","schema_version":"edge-lab-recorder.raw.v1","sequence":null,"source":"clob_market_ws"}
{"event_at":"2026-07-27T05:42:12.053000Z","event_fingerprint":"aad593352c8f2a4f17eba2c1c21d979596bbf535914e48fbde0690c7d6e257e8","payload":{"connection_id":"efc69d3132f1467b8e898a382b23ac0d","event_at":"2026-07-27T05:42:12.053000Z","event_type":"price_change","frame_hash":"c90ab4b0b10c85c318ecbadd24df02656c70e7c8e1d6adb49eb1ea2805c8a4dc","frame_index":0,"kind":"data","monotonic_ns":232915313780708,"payload":{"event_type":"price_change","market":"0x3b40066b5cf3871a2f6237c5628bd8092a206aa998558ac5ec13c4483e31e160","price_changes":[{"asset_id":"14766054693214075530629349735273995982307625376442606753688071083149620216746","best_ask":"0.74","best_bid":"0.73","hash":"cd8992eb9c2ad77719b8932763d0f246666afdf8","price":"0.01","side":"BUY","size":"5335.02"},{"asset_id":"110216635572655435074987471276357323571387854733835379371586402147734167783946","best_ask":"0.27","best_bid":"0.26","hash":"e308b58c3401d431c08186958fddb7c5262044a8","price":"0.99","side":"SELL","size":"5335.02"}],"timestamp":"1785130932053"},"payload_hash":"d000b440fac85d7cf3e161f5f268ea558dd2a880a079ae2ee2cb5ff425d232f6","raw_frame":"{\"market\":\"0x3b40066b5cf3871a2f6237c5628bd8092a206aa998558ac5ec13c4483e31e160\", \"price_changes\":[{\"asset_id\":\"14766054693214075530629349735273995982307625376442606753688071083149620216746\", \"price\":\"0.01\", \"size\":\"5335.02\", \"side\":\"BUY\", \"hash\":\"cd8992eb9c2ad77719b8932763d0f246666afdf8\", \"best_bid\":\"0.73\", \"best_ask\":\"0.74\"}, {\"asset_id\":\"110216635572655435074987471276357323571387854733835379371586402147734167783946\", \"price\":\"0.99\", \"size\":\"5335.02\", \"side\":\"SELL\", \"hash\":\"e308b58c3401d431c08186958fddb7c5262044a8\", \"best_bid\":\"0.26\", \"best_ask\":\"0.27\"}], \"timestamp\":\"1785130932053\", \"event_type\":\"price_change\"}","received_at":"2026-07-27T05:42:12.080657Z","schema_version":"clob-market-ws.price_change.v1","sequence":null,"server_hash":null,"server_timestamp":"1785130932053","session_id":"502006c5cfcd437296561ea750c9ec8b","source":"clob_market_ws"},"received_at":"2026-07-27T05:42:12.080657Z","record_id":"92e7343d8945638992dcf0508f79d94f89fb9d195af94d8ef93a58aac031f7b7","schema_fingerprint":"4aa3821a28b0b7c2400bc59aba4bcc0a76e971dadd19610d3ad38c768e124dc7","schema_version":"edge-lab-recorder.raw.v1","sequence":null,"source":"clob_market_ws"}
{"event_at":"2026-07-27T05:42:12.074000Z","event_fingerprint":"82440df3d86c0ae76d25ea9298fd399444221477e86c88a28c6dfc726da4481e","payload":{"connection_id":"efc69d3132f1467b8e898a382b23ac0d","event_at":"2026-07-27T05:42:12.074000Z","event_type":"price_change","frame_hash":"e3cdeb06cf4ab3eb21fbc93e88f02635920be54fad1033fc78f94dc93d02c0c5","frame_index":0,"kind":"data","monotonic_ns":232915315136125,"payload":{"event_type":"price_change","market":"0x3b40066b5cf3871a2f6237c5628bd8092a206aa998558ac5ec13c4483e31e160","price_changes":[{"asset_id":"14766054693214075530629349735273995982307625376442606753688071083149620216746","best_ask":"0.74","best_bid":"0.73","hash":"11708cd3b2b60dbe9c2b118452bb3c6ae5d41f8c","price":"0.01","side":"BUY","size":"5330.02"},{"asset_id":"110216635572655435074987471276357323571387854733835379371586402147734167783946","best_ask":"0.27","best_bid":"0.26","hash":"5845536c3f45f534e3073a05d36b8978f184e020","price":"0.99","side":"SELL","size":"5330.02"}],"timestamp":"1785130932074"},"payload_hash":"a5ce61d7f224583c655a8324bfaca21283463159aaad562f9cb95ca16d6d7cdd","raw_frame":"{\"market\":\"0x3b40066b5cf3871a2f6237c5628bd8092a206aa998558ac5ec13c4483e31e160\", \"price_changes\":[{\"asset_id\":\"14766054693214075530629349735273995982307625376442606753688071083149620216746\", \"price\":\"0.01\", \"size\":\"5330.02\", \"side\":\"BUY\", \"hash\":\"11708cd3b2b60dbe9c2b118452bb3c6ae5d41f8c\", \"best_bid\":\"0.73\", \"best_ask\":\"0.74\"}, {\"asset_id\":\"110216635572655435074987471276357323571387854733835379371586402147734167783946\", \"price\":\"0.99\", \"size\":\"5330.02\", \"side\":\"SELL\", \"hash\":\"5845536c3f45f534e3073a05d36b8978f184e020\", \"best_bid\":\"0.26\", \"best_ask\":\"0.27\"}], \"timestamp\":\"1785130932074\", \"event_type\":\"price_change\"}","received_at":"2026-07-27T05:42:12.082019Z","schema_version":"clob-market-ws.price_change.v1","sequence":null,"server_hash":null,"server_timestamp":"1785130932074","session_id":"502006c5cfcd437296561ea750c9ec8b","source":"clob_market_ws"},"received_at":"2026-07-27T05:42:12.082019Z","record_id":"f30f97db7be0fa1f5271fd6c0f16b109443df59ef116bfca50d582c3161a41f2","schema_fingerprint":"4aa3821a28b0b7c2400bc59aba4bcc0a76e971dadd19610d3ad38c768e124dc7","schema_version":"edge-lab-recorder.raw.v1","sequence":null,"source":"clob_market_ws"}
{"event_at":"2026-07-27T05:42:12.104000Z","event_fingerprint":"742b8c4b7b6be6c0f51a01faabffe55abe06eea7121f652ad1bd7eee0ad5150e","payload":{"connection_id":"efc69d3132f1467b8e898a382b23ac0d","event_at":"2026-07-27T05:42:12.104000Z","event_type":"price_change","frame_hash":"0c68c4fec804ca8a9fc776939992ed3337ab86a63f1811763347b823d918a532","frame_index":0,"kind":"data","monotonic_ns":232915317592291,"payload":{"event_type":"price_change","market":"0x3b40066b5cf3871a2f6237c5628bd8092a206aa998558ac5ec13c4483e31e160","price_changes":[{"asset_id":"110216635572655435074987471276357323571387854733835379371586402147734167783946","best_ask":"0.27","best_bid":"0.26","hash":"77aa5dc8ed477d9bc4799419379699d00ae41722","price":"0.19","side":"BUY","size":"51.6"},{"asset_id":"14766054693214075530629349735273995982307625376442606753688071083149620216746","best_ask":"0.74","best_bid":"0.73","hash":"ab4cf00ade05d9d72ad2993e9d1d284954dc6fb4","price":"0.81","side":"SELL","size":"51.6"}],"timestamp":"1785130932104"},"payload_hash":"15cef033ab9c6701071ae762fbd25e86c415e20c113991c3f5f59d12dc396cd8","raw_frame":"{\"market\":\"0x3b40066b5cf3871a2f6237c5628bd8092a206aa998558ac5ec13c4483e31e160\", \"price_changes\":[{\"asset_id\":\"110216635572655435074987471276357323571387854733835379371586402147734167783946\", \"price\":\"0.19\", \"size\":\"51.6\", \"side\":\"BUY\", \"hash\":\"77aa5dc8ed477d9bc4799419379699d00ae41722\", \"best_bid\":\"0.26\", \"best_ask\":\"0.27\"}, {\"asset_id\":\"14766054693214075530629349735273995982307625376442606753688071083149620216746\", \"price\":\"0.81\", \"size\":\"51.6\", \"side\":\"SELL\", \"hash\":\"ab4cf00ade05d9d72ad2993e9d1d284954dc6fb4\", \"best_bid\":\"0.73\", \"best_ask\":\"0.74\"}], \"timestamp\":\"1785130932104\", \"event_type\":\"price_change\"}","received_at":"2026-07-27T05:42:12.084469Z","schema_version":"clob-market-ws.price_change.v1","sequence":null,"server_hash":null,"server_timestamp":"1785130932104","session_id":"502006c5cfcd437296561ea750c9ec8b","source":"clob_market_ws"},"received_at":"2026-07-27T05:42:12.084469Z","record_id":"810b3323a9b6dc0bf37388a7cb27aee670a7184cde6ebf7e03c70a8fa894b2c5","schema_fingerprint":"4aa3821a28b0b7c2400bc59aba4bcc0a76e971dadd19610d3ad38c768e124dc7","schema_version":"edge-lab-recorder.raw.v1","sequence":null,"source":"clob_market_ws"}
{"event_at":"2026-07-27T05:42:12.104000Z","event_fingerprint":"d11d1eedf80af629185bc2c1ecebc017f167155a0235d0349b4e190dd6c9e3d9","payload":{"connection_id":"efc69d3132f1467b8e898a382b23ac0d","event_at":"2026-07-27T05:42:12.104000Z","event_type":"price_change","frame_hash":"b32a195274c5131474dff4500f48cdc002faffb00c62e27fcb11dc30f4a21942","frame_index":0,"kind":"data","monotonic_ns":232915320594750,"payload":{"event_type":"price_change","market":"0x3b40066b5cf3871a2f6237c5628bd8092a206aa998558ac5ec13c4483e31e160","price_changes":[{"asset_id":"14766054693214075530629349735273995982307625376442606753688071083149620216746","best_ask":"0.74","best_bid":"0.73","hash":"de6817e395597897755dd914be25b151a53df14d","price":"0.73","side":"BUY","size":"109"},{"asset_id":"110216635572655435074987471276357323571387854733835379371586402147734167783946","best_ask":"0.27","best_bid":"0.26","hash":"e80c6526374589561558c8f8c47e8041c6bc8a16","price":"0.27","side":"SELL","size":"109"}],"timestamp":"1785130932104"},"payload_hash":"3444c1cb635d7f7735730ccdcecda06783075e09f5760accef4b7550ebdf07b2","raw_frame":"{\"market\":\"0x3b40066b5cf3871a2f6237c5628bd8092a206aa998558ac5ec13c4483e31e160\", \"price_changes\":[{\"asset_id\":\"14766054693214075530629349735273995982307625376442606753688071083149620216746\", \"price\":\"0.73\", \"size\":\"109\", \"side\":\"BUY\", \"hash\":\"de6817e395597897755dd914be25b151a53df14d\", \"best_bid\":\"0.73\", \"best_ask\":\"0.74\"}, {\"asset_id\":\"110216635572655435074987471276357323571387854733835379371586402147734167783946\", \"price\":\"0.27\", \"size\":\"109\", \"side\":\"SELL\", \"hash\":\"e80c6526374589561558c8f8c47e8041c6bc8a16\", \"best_bid\":\"0.26\", \"best_ask\":\"0.27\"}], \"timestamp\":\"1785130932104\", \"event_type\":\"price_change\"}","received_at":"2026-07-27T05:42:12.087472Z","schema_version":"clob-market-ws.price_change.v1","sequence":null,"server_hash":null,"server_timestamp":"1785130932104","session_id":"502006c5cfcd437296561ea750c9ec8b","source":"clob_market_ws"},"received_at":"2026-07-27T05:42:12.087472Z","record_id":"23786a7e477a7dd1b5dce4490bb1dc0732b64e2b771fabb73b5c952075ae1b22","schema_fingerprint":"4aa3821a28b0b7c2400bc59aba4bcc0a76e971dadd19610d3ad38c768e124dc7","schema_version":"edge-lab-recorder.raw.v1","sequence":null,"source":"clob_market_ws"}
{"event_at":"2026-07-27T05:42:12.126000Z","event_fingerprint":"f2194988545685cc5f0fa6d963efd9e27a4bbf562c84057eb85e2437a41e9da1","payload":{"connection_id":"efc69d3132f1467b8e898a382b23ac0d","event_at":"2026-07-27T05:42:12.126000Z","event_type":"price_change","frame_hash":"b27ab2303a4145cfc6b1a3ad1e4a49e40fbd4d59a01f26f6fd2fff2ca7656d1a","frame_index":0,"kind":"data","monotonic_ns":232915323531541,"payload":{"event_type":"price_change","market":"0x3b40066b5cf3871a2f6237c5628bd8092a206aa998558ac5ec13c4483e31e160","price_changes":[{"asset_id":"110216635572655435074987471276357323571387854733835379371586402147734167783946","best_ask":"0.27","best_bid":"0.26","hash":"f814ea03ce2d634669a67fb49c267ddc2e98d0f6","price":"0.26","side":"BUY","size":"99"},{"asset_id":"14766054693214075530629349735273995982307625376442606753688071083149620216746","best_ask":"0.74","best_bid":"0.73","hash":"96ddadacfeb32b6b190c03d68881c5c693cdf2dc","price":"0.74","side":"SELL","size":"99"}],"timestamp":"1785130932126"},"payload_hash":"924215fae72ae8cbde1a159f86ddde4529b7d954f8546ce59fb09b64b92c5c18","raw_frame":"{\"market\":\"0x3b40066b5cf3871a2f6237c5628bd8092a206aa998558ac5ec13c4483e31e160\", \"price_changes\":[{\"asset_id\":\"110216635572655435074987471276357323571387854733835379371586402147734167783946\", \"price\":\"0.26\", \"size\":\"99\", \"side\":\"BUY\", \"hash\":\"f814ea03ce2d634669a67fb49c267ddc2e98d0f6\", \"best_bid\":\"0.26\", \"best_ask\":\"0.27\"}, {\"asset_id\":\"14766054693214075530629349735273995982307625376442606753688071083149620216746\", \"price\":\"0.74\", \"size\":\"99\", \"side\":\"SELL\", \"hash\":\"96ddadacfeb32b6b190c03d68881c5c693cdf2dc\", \"best_bid\":\"0.73\", \"best_ask\":\"0.74\"}], \"timestamp\":\"1785130932126\", \"event_type\":\"price_change\"}","received_at":"2026-07-27T05:42:12.090409Z","schema_version":"clob-market-ws.price_change.v1","sequence":null,"server_hash":null,"server_timestamp":"1785130932126","session_id":"502006c5cfcd437296561ea750c9ec8b","source":"clob_market_ws"},"received_at":"2026-07-27T05:42:12.090409Z","record_id":"5ea25b4175ab696218485307a5a822374b84a64e89a9fb22f401cc97d8af10ec","schema_fingerprint":"4aa3821a28b0b7c2400bc59aba4bcc0a76e971dadd19610d3ad38c768e124dc7","schema_version":"edge-lab-recorder.raw.v1","sequence":null,"source":"clob_market_ws"}
{"event_at":"2026-07-27T05:42:12.128000Z","event_fingerprint":"39e23702ad28c85adec08f4779b4d4d307989b366383a13d3b22755c7ad07117","payload":{"connection_id":"efc69d3132f1467b8e898a382b23ac0d","event_at":"2026-07-27T05:42:12.128000Z","event_type":"price_change","frame_hash":"93140b00738bc679886713da495eea078544413fe9c7ab76ad8c8dfcbc9cc511","frame_index":0,"kind":"data","monotonic_ns":232915326585583,"payload":{"event_type":"price_change","market":"0x3b40066b5cf3871a2f6237c5628bd8092a206aa998558ac5ec13c4483e31e160","price_changes":[{"asset_id":"14766054693214075530629349735273995982307625376442606753688071083149620216746","best_ask":"0.74","best_bid":"0.73","hash":"c19a66ba71c44cb3ad78a001632b7bd014bc0444","price":"0.67","side":"BUY","size":"129"},{"asset_id":"110216635572655435074987471276357323571387854733835379371586402147734167783946","best_ask":"0.27","best_bid":"0.26","hash":"88f6e504b8298f5fdb60cb0ce3035dd8d712dee9","price":"0.33","side":"SELL","size":"129"}],"timestamp":"1785130932128"},"payload_hash":"29f371489a2b5bef990266d132aabf75dfbd8d6b87f703e00d5a0e56428810ef","raw_frame":"{\"market\":\"0x3b40066b5cf3871a2f6237c5628bd8092a206aa998558ac5ec13c4483e31e160\", \"price_changes\":[{\"asset_id\":\"14766054693214075530629349735273995982307625376442606753688071083149620216746\", \"price\":\"0.67\", \"size\":\"129\", \"side\":\"BUY\", \"hash\":\"c19a66ba71c44cb3ad78a001632b7bd014bc0444\", \"best_bid\":\"0.73\", \"best_ask\":\"0.74\"}, {\"asset_id\":\"110216635572655435074987471276357323571387854733835379371586402147734167783946\", \"price\":\"0.33\", \"size\":\"129\", \"side\":\"SELL\", \"hash\":\"88f6e504b8298f5fdb60cb0ce3035dd8d712dee9\", \"best_bid\":\"0.26\", \"best_ask\":\"0.27\"}], \"timestamp\":\"1785130932128\", \"event_type\":\"price_change\"}","received_at":"2026-07-27T05:42:12.093463Z","schema_version":"clob-market-ws.price_change.v1","sequence":null,"server_hash":null,"server_timestamp":"1785130932128","session_id":"502006c5cfcd437296561ea750c9ec8b","source":"clob_market_ws"},"received_at":"2026-07-27T05:42:12.093463Z","record_id":"38374eb86c97c78641c06870e11d08ecaf6f81e655afe0d9a7f83de02261f2fd","schema_fingerprint":"4aa3821a28b0b7c2400bc59aba4bcc0a76e971dadd19610d3ad38c768e124dc7","schema_version":"edge-lab-recorder.raw.v1","sequence":null,"source":"clob_market_ws"}
{"event_at":"2026-07-27T05:42:12.128000Z","event_fingerprint":"3115a0c9b3fe611e8ed1ee5e360d495245ebdacd2383acd6bf5c4b1bc6a0f253","payload":{"connection_id":"efc69d3132f1467b8e898a382b23ac0d","event_at":"2026-07-27T05:42:12.128000Z","event_type":"price_change","frame_hash":"c42ba73bbcb13f2e5fee7ae1b5b79c3689c2c9ecbed214149858e4ba77125d90","frame_index":0,"kind":"data","monotonic_ns":232915329421833,"payload":{"event_type":"price_change","market":"0x3b40066b5cf3871a2f6237c5628bd8092a206aa998558ac5ec13c4483e31e160","price_changes":[{"asset_id":"110216635572655435074987471276357323571387854733835379371586402147734167783946","best_ask":"0.27","best_bid":"0.26","hash":"d738424e0d0b36b26ab238e02aabe6a211f81c51","price":"0.01","side":"BUY","size":"5432.45"},{"asset_id":"14766054693214075530629349735273995982307625376442606753688071083149620216746","best_ask":"0.74","best_bid":"0.73","hash":"161424f0b72712136701d939ff1a01a1d2d654a3","price":"0.99","side":"SELL","size":"5432.45"}],"timestamp":"1785130932128"},"payload_hash":"079ec4b48e346ccbd3084ace147df8c94d76ba817ecfffd3eb6465632921daaa","raw_frame":"{\"market\":\"0x3b40066b5cf3871a2f6237c5628bd8092a206aa998558ac5ec13c4483e31e160\", \"price_changes\":[{\"asset_id\":\"110216635572655435074987471276357323571387854733835379371586402147734167783946\", \"price\":\"0.01\", \"size\":\"5432.45\", \"side\":\"BUY\", \"hash\":\"d738424e0d0b36b26ab238e02aabe6a211f81c51\", \"best_bid\":\"0.26\", \"best_ask\":\"0.27\"}, {\"asset_id\":\"14766054693214075530629349735273995982307625376442606753688071083149620216746\", \"price\":\"0.99\", \"size\":\"5432.45\", \"side\":\"SELL\", \"hash\":\"161424f0b72712136701d939ff1a01a1d2d654a3\", \"best_bid\":\"0.73\", \"best_ask\":\"0.74\"}], \"timestamp\":\"1785130932128\", \"event_type\":\"price_change\"}","received_at":"2026-07-27T05:42:12.096299Z","schema_version":"clob-market-ws.price_change.v1","sequence":null,"server_hash":null,"server_timestamp":"1785130932128","session_id":"502006c5cfcd437296561ea750c9ec8b","source":"clob_market_ws"},"received_at":"2026-07-27T05:42:12.096299Z","record_id":"f5b0c941a1f7222776936d2dfb157bfe570a3e4cff996e794de5698b801e6aae","schema_fingerprint":"4aa3821a28b0b7c2400bc59aba4bcc0a76e971dadd19610d3ad38c768e124dc7","schema_version":"edge-lab-recorder.raw.v1","sequence":null,"source":"clob_market_ws"}
{"event_at":"2026-07-27T05:42:12.134000Z","event_fingerprint":"0d74fe4ee0ca930102cd9d0c1892906550ebe2ea273ea600696c544d9956ca2c","payload":{"connection_id":"efc69d3132f1467b8e898a382b23ac0d","event_at":"2026-07-27T05:42:12.134000Z","event_type":"price_change","frame_hash":"a1e1636e4bb5a2ac001fff51f37c4358c8d0e029fac02b53ac822a4cde28879f","frame_index":0,"kind":"data","monotonic_ns":232915331270666,"payload":{"event_type":"price_change","market":"0x3b40066b5cf3871a2f6237c5628bd8092a206aa998558ac5ec13c4483e31e160","price_changes":[{"asset_id":"14766054693214075530629349735273995982307625376442606753688071083149620216746","best_ask":"0.74","best_bid":"0.73","hash":"ec7307b1b76695f6bb521c7ac0a9a1dd0a098753","price":"0.02","side":"BUY","size":"557"},{"asset_id":"110216635572655435074987471276357323571387854733835379371586402147734167783946","best_ask":"0.27","best_bid":"0.26","hash":"e9a4812ea476fb32a1603ba2539d8f6c7cae20f5","price":"0.98","side":"SELL","size":"557"}],"timestamp":"1785130932134"},"payload_hash":"9f140916d1fbac354db075d76b0d16b18548bbc333078406cb593a84ea1688d3","raw_frame":"{\"market\":\"0x3b40066b5cf3871a2f6237c5628bd8092a206aa998558ac5ec13c4483e31e160\", \"price_changes\":[{\"asset_id\":\"14766054693214075530629349735273995982307625376442606753688071083149620216746\", \"price\":\"0.02\", \"size\":\"557\", \"side\":\"BUY\", \"hash\":\"ec7307b1b76695f6bb521c7ac0a9a1dd0a098753\", \"best_bid\":\"0.73\", \"best_ask\":\"0.74\"}, {\"asset_id\":\"110216635572655435074987471276357323571387854733835379371586402147734167783946\", \"price\":\"0.98\", \"size\":\"557\", \"side\":\"SELL\", \"hash\":\"e9a4812ea476fb32a1603ba2539d8f6c7cae20f5\", \"best_bid\":\"0.26\", \"best_ask\":\"0.27\"}], \"timestamp\":\"1785130932134\", \"event_type\":\"price_change\"}","received_at":"2026-07-27T05:42:12.098154Z","schema_version":"clob-market-ws.price_change.v1","sequence":null,"server_hash":null,"server_timestamp":"1785130932134","session_id":"502006c5cfcd437296561ea750c9ec8b","source":"clob_market_ws"},"received_at":"2026-07-27T05:42:12.098154Z","record_id":"d282dd33f5574ae4edb7dbabf3eb6077b888277f40a9767dbad90200d1ee6499","schema_fingerprint":"4aa3821a28b0b7c2400bc59aba4bcc0a76e971dadd19610d3ad38c768e124dc7","schema_version":"edge-lab-recorder.raw.v1","sequence":null,"source":"clob_market_ws"}
{"event_at":"2026-07-27T05:42:12.134000Z","event_fingerprint":"f9ab2ea546d202988df69fa041b66e10a1df4a5fedec6dd9309bf5b7d2d63e8f","payload":{"connection_id":"efc69d3132f1467b8e898a382b23ac0d","event_at":"2026-07-27T05:42:12.134000Z","event_type":"price_change","frame_hash":"3d8b4a0a51a013865c043dc00af487fadd46207350cc4b223ccde03b60768080","frame_index":0,"kind":"data","monotonic_ns":232915334439166,"payload":{"event_type":"price_change","market":"0x3b40066b5cf3871a2f6237c5628bd8092a206aa998558ac5ec13c4483e31e160","price_changes":[{"asset_id":"14766054693214075530629349735273995982307625376442606753688071083149620216746","best_ask":"0.74","best_bid":"0.73","hash":"a58aeb63d8087562a78036cad2a1941573c40a00","price":"0.48","side":"BUY","size":"176.88"},{"asset_id":"110216635572655435074987471276357323571387854733835379371586402147734167783946","best_ask":"0.27","best_bid":"0.26","hash":"a0a77b0a93eaa9130950ce6a73f005692d5887ff","price":"0.52","side":"SELL","size":"176.88"}],"timestamp":"1785130932134"},"payload_hash":"06989d7b6fb5fe3fdb0fc9aee80ad72dc282db2be3e3ba7f0bfcc1e2db8af21a","raw_frame":"{\"market\":\"0x3b40066b5cf3871a2f6237c5628bd8092a206aa998558ac5ec13c4483e31e160\", \"price_changes\":[{\"asset_id\":\"14766054693214075530629349735273995982307625376442606753688071083149620216746\", \"price\":\"0.48\", \"size\":\"176.88\", \"side\":\"BUY\", \"hash\":\"a58aeb63d8087562a78036cad2a1941573c40a00\", \"best_bid\":\"0.73\", \"best_ask\":\"0.74\"}, {\"asset_id\":\"110216635572655435074987471276357323571387854733835379371586402147734167783946\", \"price\":\"0.52\", \"size\":\"176.88\", \"side\":\"SELL\", \"hash\":\"a0a77b0a93eaa9130950ce6a73f005692d5887ff\", \"best_bid\":\"0.26\", \"best_ask\":\"0.27\"}], \"timestamp\":\"1785130932134\", \"event_type\":\"price_change\"}","received_at":"2026-07-27T05:42:12.101317Z","schema_version":"clob-market-ws.price_change.v1","sequence":null,"server_hash":null,"server_timestamp":"1785130932134","session_id":"502006c5cfcd437296561ea750c9ec8b","source":"clob_market_ws"},"received_at":"2026-07-27T05:42:12.101317Z","record_id":"a651c90c9dd950151a0341076317ce98299c03aa55f980400e7fb795e70c8c8a","schema_fingerprint":"4aa3821a28b0b7c2400bc59aba4bcc0a76e971dadd19610d3ad38c768e124dc7","schema_version":"edge-lab-recorder.raw.v1","sequence":null,"source":"clob_market_ws"}
{"event_at":"2026-07-27T05:42:12.137000Z","event_fingerprint":"9044ee08db9efb0be27e551c0ca1d6250ba9a3b733876727e60eada33dc905a0","payload":{"connection_id":"efc69d3132f1467b8e898a382b23ac0d","event_at":"2026-07-27T05:42:12.137000Z","event_type":"price_change","frame_hash":"4a2d6f9c5149aa36d23ddfd98201c17842e4bea7defaa45eb685da2746a4c623","frame_index":0,"kind":"data","monotonic_ns":232915338099916,"payload":{"event_type":"price_change","market":"0x3b40066b5cf3871a2f6237c5628bd8092a206aa998558ac5ec13c4483e31e160","price_changes":[{"asset_id":"14766054693214075530629349735273995982307625376442606753688071083149620216746","best_ask":"0.74","best_bid":"0.73","hash":"a7a7ef17629e88fde008671a63f96b7c01042d4d","price":"0.48","side":"BUY","size":"107.44"},{"asset_id":"110216635572655435074987471276357323571387854733835379371586402147734167783946","best_ask":"0.27","best_bid":"0.26","hash":"d0fdbbe41eb7402e0ced74863f85cb85e3328b3b","price":"0.52","side":"SELL","size":"107.44"}],"timestamp":"1785130932137"},"payload_hash":"472c67df91a7e8f28e00d6e16c224c26bd26b50868b4862059fe15a27f88bc38","raw_frame":"{\"market\":\"0x3b40066b5cf3871a2f6237c5628bd8092a206aa998558ac5ec13c4483e31e160\", \"price_changes\":[{\"asset_id\":\"14766054693214075530629349735273995982307625376442606753688071083149620216746\", \"price\":\"0.48\", \"size\":\"107.44\", \"side\":\"BUY\", \"hash\":\"a7a7ef17629e88fde008671a63f96b7c01042d4d\", \"best_bid\":\"0.73\", \"best_ask\":\"0.74\"}, {\"asset_id\":\"110216635572655435074987471276357323571387854733835379371586402147734167783946\", \"price\":\"0.52\", \"size\":\"107.44\", \"side\":\"SELL\", \"hash\":\"d0fdbbe41eb7402e0ced74863f85cb85e3328b3b\", \"best_bid\":\"0.26\", \"best_ask\":\"0.27\"}], \"timestamp\":\"1785130932137\", \"event_type\":\"price_change\"}","received_at":"2026-07-27T05:42:12.104978Z","schema_version":"clob-market-ws.price_change.v1","sequence":null,"server_hash":null,"server_timestamp":"1785130932137","session_id":"502006c5cfcd437296561ea750c9ec8b","source":"clob_market_ws"},"received_at":"2026-07-27T05:42:12.104978Z","record_id":"91c676f02d880b0f650cc96f1dc963f753478648c8197d858b1dd49e9d778d52","schema_fingerprint":"4aa3821a28b0b7c2400bc59aba4bcc0a76e971dadd19610d3ad38c768e124dc7","schema_version":"edge-lab-recorder.raw.v1","sequence":null,"source":"clob_market_ws"}
{"event_at":"2026-07-27T05:42:12.145000Z","event_fingerprint":"e7299aa69c366540f8fab93f3e61a269a36550b6abe69048147155af63e92480","payload":{"connection_id":"efc69d3132f1467b8e898a382b23ac0d","event_at":"2026-07-27T05:42:12.145000Z","event_type":"price_change","frame_hash":"ca5572a53ccb1bab269f848fe4781d6d6da6d750be809230aea2200db0630aad","frame_index":0,"kind":"data","monotonic_ns":232915343513125,"payload":{"event_type":"price_change","market":"0x3b40066b5cf3871a2f6237c5628bd8092a206aa998558ac5ec13c4483e31e160","price_changes":[{"asset_id":"14766054693214075530629349735273995982307625376442606753688071083149620216746","best_ask":"0.74","best_bid":"0.73","hash":"da6beb4787530d8159b8abc013bbf6771b8bb2e6","price":"0.48","side":"BUY","size":"38"},{"asset_id":"110216635572655435074987471276357323571387854733835379371586402147734167783946","best_ask":"0.27","best_bid":"0.26","hash":"f138f4cac918e95b02fb015623080b55338d417f","price":"0.52","side":"SELL","size":"38"}],"timestamp":"1785130932145"},"payload_hash":"602908a2e8c5a4c43e2f969d0d67d8fabcf6469827a7365bd10d8f91b89e5279","raw_frame":"{\"market\":\"0x3b40066b5cf3871a2f6237c5628bd8092a206aa998558ac5ec13c4483e31e160\", \"price_changes\":[{\"asset_id\":\"14766054693214075530629349735273995982307625376442606753688071083149620216746\", \"price\":\"0.48\", \"size\":\"38\", \"side\":\"BUY\", \"hash\":\"da6beb4787530d8159b8abc013bbf6771b8bb2e6\", \"best_bid\":\"0.73\", \"best_ask\":\"0.74\"}, {\"asset_id\":\"110216635572655435074987471276357323571387854733835379371586402147734167783946\", \"price\":\"0.52\", \"size\":\"38\", \"side\":\"SELL\", \"hash\":\"f138f4cac918e95b02fb015623080b55338d417f\", \"best_bid\":\"0.26\", \"best_ask\":\"0.27\"}], \"timestamp\":\"1785130932145\", \"event_type\":\"price_change\"}","received_at":"2026-07-27T05:42:12.110390Z","schema_version":"clob-market-ws.price_change.v1","sequence":null,"server_hash":null,"server_timestamp":"1785130932145","session_id":"502006c5cfcd437296561ea750c9ec8b","source":"clob_market_ws"},"received_at":"2026-07-27T05:42:12.110390Z","record_id":"c7d00ae5c2d138f745d2f9e21dab12f15df49f614f9b17b9929e363d795561dd","schema_fingerprint":"4aa3821a28b0b7c2400bc59aba4bcc0a76e971dadd19610d3ad38c768e124dc7","schema_version":"edge-lab-recorder.raw.v1","sequence":null,"source":"clob_market_ws"}
{"event_at":"2026-07-27T05:42:12.151000Z","event_fingerprint":"c9c87135e21993d19385701cc24015d723431826b2311e3129f514654e03ce33","payload":{"connection_id":"efc69d3132f1467b8e898a382b23ac0d","event_at":"2026-07-27T05:42:12.151000Z","event_type":"price_change","frame_hash":"55c4f6650076a58c8156d66723d528ec8f5983cf99d202ea799bd92e8bfa6f57","frame_index":0,"kind":"data","monotonic_ns":232915346334708,"payload":{"event_type":"price_change","market":"0x3b40066b5cf3871a2f6237c5628bd8092a206aa998558ac5ec13c4483e31e160","price_changes":[{"asset_id":"14766054693214075530629349735273995982307625376442606753688071083149620216746","best_ask":"0.74","best_bid":"0.73","hash":"3a5d542dbb5916bf35d0146ab317b5d44b9b0b19","price":"0.01","side":"BUY","size":"5335.02"},{"asset_id":"110216635572655435074987471276357323571387854733835379371586402147734167783946","best_ask":"0.27","best_bid":"0.26","hash":"b2a19f50edeb876e07c7f7e15d416ee967438a08","price":"0.99","side":"SELL","size":"5335.02"}],"timestamp":"1785130932151"},"payload_hash":"662edadfd15e852a89f88bcdf75f0c5b666b36c90c321fbbc1bfef4963c54bf7","raw_frame":"{\"market\":\"0x3b40066b5cf3871a2f6237c5628bd8092a206aa998558ac5ec13c4483e31e160\", \"price_changes\":[{\"asset_id\":\"14766054693214075530629349735273995982307625376442606753688071083149620216746\", \"price\":\"0.01\", \"size\":\"5335.02\", \"side\":\"BUY\", \"hash\":\"3a5d542dbb5916bf35d0146ab317b5d44b9b0b19\", \"best_bid\":\"0.73\", \"best_ask\":\"0.74\"}, {\"asset_id\":\"110216635572655435074987471276357323571387854733835379371586402147734167783946\", \"price\":\"0.99\", \"size\":\"5335.02\", \"side\":\"SELL\", \"hash\":\"b2a19f50edeb876e07c7f7e15d416ee967438a08\", \"best_bid\":\"0.26\", \"best_ask\":\"0.27\"}], \"timestamp\":\"1785130932151\", \"event_type\":\"price_change\"}","received_at":"2026-07-27T05:42:12.113212Z","schema_version":"clob-market-ws.price_change.v1","sequence":null,"server_hash":null,"server_timestamp":"1785130932151","session_id":"502006c5cfcd437296561ea750c9ec8b","source":"clob_market_ws"},"received_at":"2026-07-27T05:42:12.113212Z","record_id":"2cc22cea1adf29aafb0c2b2bf0447ef5ea155a403325c73e15cb4852731a8362","schema_fingerprint":"4aa3821a28b0b7c2400bc59aba4bcc0a76e971dadd19610d3ad38c768e124dc7","schema_version":"edge-lab-recorder.raw.v1","sequence":null,"source":"clob_market_ws"}
{"event_at":"2026-07-27T05:42:12.159000Z","event_fingerprint":"0cc99dfa605ca17d60e3eddcde95f05413a3510ebc22598408f49d7338e5896c","payload":{"connection_id":"efc69d3132f1467b8e898a382b23ac0d","event_at":"2026-07-27T05:42:12.159000Z","event_type":"price_change","frame_hash":"038c6475ab3f6597c37193404aa00f5c40913e88a873bfebec23105bb2e02cf9","frame_index":0,"kind":"data","monotonic_ns":232915352390375,"payload":{"event_type":"price_change","market":"0x3b40066b5cf3871a2f6237c5628bd8092a206aa998558ac5ec13c4483e31e160","price_changes":[{"asset_id":"110216635572655435074987471276357323571387854733835379371586402147734167783946","best_ask":"0.27","best_bid":"0.26","hash":"7ef9f688ce2dc122cc51ab809b24f21d3dcde956","price":"0.11","side":"BUY","size":"91"},{"asset_id":"14766054693214075530629349735273995982307625376442606753688071083149620216746","best_ask":"0.74","best_bid":"0.73","hash":"0c9b883cf220df0eda37fbe41544a9d9f4ac57d4","price":"0.89","side":"SELL","size":"91"}],"timestamp":"1785130932159"},"payload_hash":"8e2788eabe4ee450673910cc53544f8729ba3baec058f060613f2c4c7411eef4","raw_frame":"{\"market\":\"0x3b40066b5cf3871a2f6237c5628bd8092a206aa998558ac5ec13c4483e31e160\", \"price_changes\":[{\"asset_id\":\"110216635572655435074987471276357323571387854733835379371586402147734167783946\", \"price\":\"0.11\", \"size\":\"91\", \"side\":\"BUY\", \"hash\":\"7ef9f688ce2dc122cc51ab809b24f21d3dcde956\", \"best_bid\":\"0.26\", \"best_ask\":\"0.27\"}, {\"asset_id\":\"14766054693214075530629349735273995982307625376442606753688071083149620216746\", \"price\":\"0.89\", \"size\":\"91\", \"side\":\"SELL\", \"hash\":\"0c9b883cf220df0eda37fbe41544a9d9f4ac57d4\", \"best_bid\":\"0.73\", \"best_ask\":\"0.74\"}], \"timestamp\":\"1785130932159\", \"event_type\":\"price_change\"}","received_at":"2026-07-27T05:42:12.119268Z","schema_version":"clob-market-ws.price_change.v1","sequence":null,"server_hash":null,"server_timestamp":"1785130932159","session_id":"502006c5cfcd437296561ea750c9ec8b","source":"clob_market_ws"},"received_at":"2026-07-27T05:42:12.119268Z","record_id":"eb6dd452ed82c111694812704132c63afa294867db9ecb9f316c62415e3c06bc","schema_fingerprint":"4aa3821a28b0b7c2400bc59aba4bcc0a76e971dadd19610d3ad38c768e124dc7","schema_version":"edge-lab-recorder.raw.v1","sequence":null,"source":"clob_market_ws"}
{"event_at":"2026-07-27T05:42:12.160000Z","event_fingerprint":"aba041cd02f2d26e358b1ddc2ba8371e38e82be00d373357bcb6d232133f22f5","payload":{"connection_id":"efc69d3132f1467b8e898a382b23ac0d","event_at":"2026-07-27T05:42:12.160000Z","event_type":"price_change","frame_hash":"419a0e51321847ab31057014befe46bde8f18f7413de5f31fbc130abee097ead","frame_index":0,"kind":"data","monotonic_ns":232915354801500,"payload":{"event_type":"price_change","market":"0x3b40066b5cf3871a2f6237c5628bd8092a206aa998558ac5ec13c4483e31e160","price_changes":[{"asset_id":"14766054693214075530629349735273995982307625376442606753688071083149620216746","best_ask":"0.74","best_bid":"0.73","hash":"338c444d57f6a1eb4f699e647295291a63734e92","price":"0.83","side":"SELL","size":"183.99"},{"asset_id":"110216635572655435074987471276357323571387854733835379371586402147734167783946","best_ask":"0.27","best_bid":"0.26","hash":"c659bdce7de109424f080d98cd787923f7ece4a9","price":"0.17","side":"BUY","size":"183.99"}],"timestamp":"1785130932160"},"payload_hash":"80efe73e8e0d3296f567c69d40b13cbb3d5e801eecb7dc7ebae2f8f2f080bcb9","raw_frame":"{\"market\":\"0x3b40066b5cf3871a2f6237c5628bd8092a206aa998558ac5ec13c4483e31e160\", \"price_changes\":[{\"asset_id\":\"14766054693214075530629349735273995982307625376442606753688071083149620216746\", \"price\":\"0.83\", \"size\":\"183.99\", \"side\":\"SELL\", \"hash\":\"338c444d57f6a1eb4f699e647295291a63734e92\", \"best_bid\":\"0.73\", \"best_ask\":\"0.74\"}, {\"asset_id\":\"110216635572655435074987471276357323571387854733835379371586402147734167783946\", \"price\":\"0.17\", \"size\":\"183.99\", \"side\":\"BUY\", \"hash\":\"c659bdce7de109424f080d98cd787923f7ece4a9\", \"best_bid\":\"0.26\", \"best_ask\":\"0.27\"}], \"timestamp\":\"1785130932160\", \"event_type\":\"price_change\"}","received_at":"2026-07-27T05:42:12.121678Z","schema_version":"clob-market-ws.price_change.v1","sequence":null,"server_hash":null,"server_timestamp":"1785130932160","session_id":"502006c5cfcd437296561ea750c9ec8b","source":"clob_market_ws"},"received_at":"2026-07-27T05:42:12.121678Z","record_id":"4c325a59c0c74e211134b44f8af03dfbcdc746d4b6b052b63f01edcbce7f8bb6","schema_fingerprint":"4aa3821a28b0b7c2400bc59aba4bcc0a76e971dadd19610d3ad38c768e124dc7","schema_version":"edge-lab-recorder.raw.v1","sequence":null,"source":"clob_market_ws"}
{"event_at":"2026-07-27T05:42:12.162000Z","event_fingerprint":"2336adae04b1ffc5a576b05b2429879dcb19439bb72123cbc6a702a826f12087","payload":{"connection_id":"efc69d3132f1467b8e898a382b23ac0d","event_at":"2026-07-27T05:42:12.162000Z","event_type":"price_change","frame_hash":"6e45930b383b33df953412c1082f3092b7669daa4fd2de4caebafb7c5551b1cf","frame_index":0,"kind":"data","monotonic_ns":232915357929625,"payload":{"event_type":"price_change","market":"0x3b40066b5cf3871a2f6237c5628bd8092a206aa998558ac5ec13c4483e31e160","price_changes":[{"asset_id":"14766054693214075530629349735273995982307625376442606753688071083149620216746","best_ask":"0.74","best_bid":"0.73","hash":"efb926e3a005da9e162e778ee89443e928baab66","price":"0.51","side":"BUY","size":"103.35"},{"asset_id":"110216635572655435074987471276357323571387854733835379371586402147734167783946","best_ask":"0.27","best_bid":"0.26","hash":"7cc0f04169ec1a006cfd226b9292dc40b1e89e68","price":"0.49","side":"SELL","size":"103.35"}],"timestamp":"1785130932162"},"payload_hash":"0964a44dd2f27b7dfea72ed8a8a787180dc9318550b370ca826968d1b99fa1f2","raw_frame":"{\"market\":\"0x3b40066b5cf3871a2f6237c5628bd8092a206aa998558ac5ec13c4483e31e160\", \"price_changes\":[{\"asset_id\":\"14766054693214075530629349735273995982307625376442606753688071083149620216746\", \"price\":\"0.51\", \"size\":\"103.35\", \"side\":\"BUY\", \"hash\":\"efb926e3a005da9e162e778ee89443e928baab66\", \"best_bid\":\"0.73\", \"best_ask\":\"0.74\"}, {\"asset_id\":\"110216635572655435074987471276357323571387854733835379371586402147734167783946\", \"price\":\"0.49\", \"size\":\"103.35\", \"side\":\"SELL\", \"hash\":\"7cc0f04169ec1a006cfd226b9292dc40b1e89e68\", \"best_bid\":\"0.26\", \"best_ask\":\"0.27\"}], \"timestamp\":\"1785130932162\", \"event_type\":\"price_change\"}","received_at":"2026-07-27T05:42:12.124807Z","schema_version":"clob-market-ws.price_change.v1","sequence":null,"server_hash":null,"server_timestamp":"1785130932162","session_id":"502006c5cfcd437296561ea750c9ec8b","source":"clob_market_ws"},"received_at":"2026-07-27T05:42:12.124807Z","record_id":"44fd0c431d3492786ec8e60eaa385d69b19a4b8aafdec969d53305042d87716b","schema_fingerprint":"4aa3821a28b0b7c2400bc59aba4bcc0a76e971dadd19610d3ad38c768e124dc7","schema_version":"edge-lab-recorder.raw.v1","sequence":null,"source":"clob_market_ws"}
{"event_at":"2026-07-27T05:42:12.163000Z","event_fingerprint":"567b08303d6ce9b65ef9d25455e468bf5aba1647d2136140dba6aec5ffb24301","payload":{"connection_id":"efc69d3132f1467b8e898a382b23ac0d","event_at":"2026-07-27T05:42:12.163000Z","event_type":"price_change","frame_hash":"bf030f6f77f17c4fbacc58709048cff9e94329dbdb7a47d64ada66e4cb5a1ac1","frame_index":0,"kind":"data","monotonic_ns":232915360771250,"payload":{"event_type":"price_change","market":"0x3b40066b5cf3871a2f6237c5628bd8092a206aa998558ac5ec13c4483e31e160","price_changes":[{"asset_id":"110216635572655435074987471276357323571387854733835379371586402147734167783946","best_ask":"0.27","best_bid":"0.26","hash":"9535bee71986c3aecdce366dcc77641a0de6bb03","price":"0.18","side":"BUY","size":"79.4"},{"asset_id":"14766054693214075530629349735273995982307625376442606753688071083149620216746","best_ask":"0.74","best_bid":"0.73","hash":"c04c131f64e6170412bb35fcf7a9283b32522001","price":"0.82","side":"SELL","size":"79.4"}],"timestamp":"1785130932163"},"payload_hash":"e049c1973887eba8504d32c0f7471d7bd108ee1761a5c3418a50a160a980cc0e","raw_frame":"{\"market\":\"0x3b40066b5cf3871a2f6237c5628bd8092a206aa998558ac5ec13c4483e31e160\", \"price_changes\":[{\"asset_id\":\"110216635572655435074987471276357323571387854733835379371586402147734167783946\", \"price\":\"0.18\", \"size\":\"79.4\", \"side\":\"BUY\", \"hash\":\"9535bee71986c3aecdce366dcc77641a0de6bb03\", \"best_bid\":\"0.26\", \"best_ask\":\"0.27\"}, {\"asset_id\":\"14766054693214075530629349735273995982307625376442606753688071083149620216746\", \"price\":\"0.82\", \"size\":\"79.4\", \"side\":\"SELL\", \"hash\":\"c04c131f64e6170412bb35fcf7a9283b32522001\", \"best_bid\":\"0.73\", \"best_ask\":\"0.74\"}], \"timestamp\":\"1785130932163\", \"event_type\":\"price_change\"}","received_at":"2026-07-27T05:42:12.127649Z","schema_version":"clob-market-ws.price_change.v1","sequence":null,"server_hash":null,"server_timestamp":"1785130932163","session_id":"502006c5cfcd437296561ea750c9ec8b","source":"clob_market_ws"},"received_at":"2026-07-27T05:42:12.127649Z","record_id":"fd79fe89cb1b8c084a44e974bd577ef7a752279a3012861fd53a8ec08a0a8665","schema_fingerprint":"4aa3821a28b0b7c2400bc59aba4bcc0a76e971dadd19610d3ad38c768e124dc7","schema_version":"edge-lab-recorder.raw.v1","sequence":null,"source":"clob_market_ws"}
{"event_at":"2026-07-27T05:42:12.174000Z","event_fingerprint":"a04ea1df9387c11a2e7ae708492baf6c0a3bd6bbd84465a01ccec7b34bd9b20b","payload":{"connection_id":"efc69d3132f1467b8e898a382b23ac0d","event_at":"2026-07-27T05:42:12.174000Z","event_type":"price_change","frame_hash":"c725e1e866022f2cf32b56c7f73db88123e6b5b03e655d623a7212fa3edc036f","frame_index":0,"kind":"data","monotonic_ns":232915365158250,"payload":{"event_type":"price_change","market":"0x3b40066b5cf3871a2f6237c5628bd8092a206aa998558ac5ec13c4483e31e160","price_changes":[{"asset_id":"14766054693214075530629349735273995982307625376442606753688071083149620216746","best_ask":"0.74","best_bid":"0.73","hash":"56fa05923f0acc1415ad0474de7f169ffb2ece92","price":"0.62","side":"BUY","size":"50.51"},{"asset_id":"110216635572655435074987471276357323571387854733835379371586402147734167783946","best_ask":"0.27","best_bid":"0.26","hash":"d14cecf31d687feda31563bc9f3cc44c375c9aa8","price":"0.38","side":"SELL","size":"50.51"}],"timestamp":"1785130932174"},"payload_hash":"8de595d971dc5ea1d0a2408863f47a689be2ea2ab2be88101105e6149cbcf651","raw_frame":"{\"market\":\"0x3b40066b5cf3871a2f6237c5628bd8092a206aa998558ac5ec13c4483e31e160\", \"price_changes\":[{\"asset_id\":\"14766054693214075530629349735273995982307625376442606753688071083149620216746\", \"price\":\"0.62\", \"size\":\"50.51\", \"side\":\"BUY\", \"hash\":\"56fa05923f0acc1415ad0474de7f169ffb2ece92\", \"best_bid\":\"0.73\", \"best_ask\":\"0.74\"}, {\"asset_id\":\"110216635572655435074987471276357323571387854733835379371586402147734167783946\", \"price\":\"0.38\", \"size\":\"50.51\", \"side\":\"SELL\", \"hash\":\"d14cecf31d687feda31563bc9f3cc44c375c9aa8\", \"best_bid\":\"0.26\", \"best_ask\":\"0.27\"}], \"timestamp\":\"1785130932174\", \"event_type\":\"price_change\"}","received_at":"2026-07-27T05:42:12.132041Z","schema_version":"clob-market-ws.price_change.v1","sequence":null,"server_hash":null,"server_timestamp":"1785130932174","session_id":"502006c5cfcd437296561ea750c9ec8b","source":"clob_market_ws"},"received_at":"2026-07-27T05:42:12.132041Z","record_id":"c5325ac4a7b52f42c9dd9237ad4482a14252a02a281130556481454ab67bdd13","schema_fingerprint":"4aa3821a28b0b7c2400bc59aba4bcc0a76e971dadd19610d3ad38c768e124dc7","schema_version":"edge-lab-recorder.raw.v1","sequence":null,"source":"clob_market_ws"}
{"event_at":"2026-07-27T05:42:12.174000Z","event_fingerprint":"8374c667414604b9e5b451e495c123944e11716e05b2d620c27e40cb42b36fc9","payload":{"connection_id":"efc69d3132f1467b8e898a382b23ac0d","event_at":"2026-07-27T05:42:12.174000Z","event_type":"price_change","frame_hash":"eddfb8fb497b4db8869c62ca15682e5f67db4ae55d8133f688917ce3765b4d14","frame_index":0,"kind":"data","monotonic_ns":232915367877375,"payload":{"event_type":"price_change","market":"0x3b40066b5cf3871a2f6237c5628bd8092a206aa998558ac5ec13c4483e31e160","price_changes":[{"asset_id":"14766054693214075530629349735273995982307625376442606753688071083149620216746","best_ask":"0.74","best_bid":"0.73","hash":"9950131bbf9387712812f56f82f8c27f7292bfe3","price":"0.65","side":"BUY","size":"60.86"},{"asset_id":"110216635572655435074987471276357323571387854733835379371586402147734167783946","best_ask":"0.27","best_bid":"0.26","hash":"fd714c12b4db16cda0a5caadb7e4aa93fcf4910f","price":"0.35","side":"SELL","size":"60.86"}],"timestamp":"1785130932174"},"payload_hash":"9b7990adef97bd822d2cac4d4638d385c89f3785971d480a29aacbed04f57587","raw_frame":"{\"market\":\"0x3b40066b5cf3871a2f6237c5628bd8092a206aa998558ac5ec13c4483e31e160\", \"price_changes\":[{\"asset_id\":\"14766054693214075530629349735273995982307625376442606753688071083149620216746\", \"price\":\"0.65\", \"size\":\"60.86\", \"side\":\"BUY\", \"hash\":\"9950131bbf9387712812f56f82f8c27f7292bfe3\", \"best_bid\":\"0.73\", \"best_ask\":\"0.74\"}, {\"asset_id\":\"110216635572655435074987471276357323571387854733835379371586402147734167783946\", \"price\":\"0.35\", \"size\":\"60.86\", \"side\":\"SELL\", \"hash\":\"fd714c12b4db16cda0a5caadb7e4aa93fcf4910f\", \"best_bid\":\"0.26\", \"best_ask\":\"0.27\"}], \"timestamp\":\"1785130932174\", \"event_type\":\"price_change\"}","received_at":"2026-07-27T05:42:12.134754Z","schema_version":"clob-market-ws.price_change.v1","sequence":null,"server_hash":null,"server_timestamp":"1785130932174","session_id":"502006c5cfcd437296561ea750c9ec8b","source":"clob_market_ws"},"received_at":"2026-07-27T05:42:12.134754Z","record_id":"468639650c320c4dea818ac5627a001ec87dc896780b89ee54ebde08d11840f1","schema_fingerprint":"4aa3821a28b0b7c2400bc59aba4bcc0a76e971dadd19610d3ad38c768e124dc7","schema_version":"edge-lab-recorder.raw.v1","sequence":null,"source":"clob_market_ws"}
{"event_at":"2026-07-27T05:42:12.175000Z","event_fingerprint":"9a3e316ea4e72eeb172ee61ecd0b25952389b21742693bbf91ea0a039cc34c24","payload":{"connection_id":"efc69d3132f1467b8e898a382b23ac0d","event_at":"2026-07-27T05:42:12.175000Z","event_type":"price_change","frame_hash":"0a1a1ea1e04e1d76a716d609c9ff1ddd233e23f4001ac7671aa38d488d7f2fcd","frame_index":0,"kind":"data","monotonic_ns":232915370854125,"payload":{"event_type":"price_change","market":"0x3b40066b5cf3871a2f6237c5628bd8092a206aa998558ac5ec13c4483e31e160","price_changes":[{"asset_id":"110216635572655435074987471276357323571387854733835379371586402147734167783946","best_ask":"0.27","best_bid":"0.26","hash":"307ec675be130a8a48fc741ee65a7e13011f9b3f","price":"0.22","side":"BUY","size":"76.33"},{"asset_id":"14766054693214075530629349735273995982307625376442606753688071083149620216746","best_ask":"0.74","best_bid":"0.73","hash":"327ac2acce3ae9f980471590ef67c9b25b410a14","price":"0.78","side":"SELL","size":"76.33"}],"timestamp":"1785130932175"},"payload_hash":"802b30e81deb33780fd03e64ba05e4ac62d685fe31f9415f81d776f96fe695c8","raw_frame":"{\"market\":\"0x3b40066b5cf3871a2f6237c5628bd8092a206aa998558ac5ec13c4483e31e160\", \"price_changes\":[{\"asset_id\":\"110216635572655435074987471276357323571387854733835379371586402147734167783946\", \"price\":\"0.22\", \"size\":\"76.33\", \"side\":\"BUY\", \"hash\":\"307ec675be130a8a48fc741ee65a7e13011f9b3f\", \"best_bid\":\"0.26\", \"best_ask\":\"0.27\"}, {\"asset_id\":\"14766054693214075530629349735273995982307625376442606753688071083149620216746\", \"price\":\"0.78\", \"size\":\"76.33\", \"side\":\"SELL\", \"hash\":\"327ac2acce3ae9f980471590ef67c9b25b410a14\", \"best_bid\":\"0.73\", \"best_ask\":\"0.74\"}], \"timestamp\":\"1785130932175\", \"event_type\":\"price_change\"}","received_at":"2026-07-27T05:42:12.137732Z","schema_version":"clob-market-ws.price_change.v1","sequence":null,"server_hash":null,"server_timestamp":"1785130932175","session_id":"502006c5cfcd437296561ea750c9ec8b","source":"clob_market_ws"},"received_at":"2026-07-27T05:42:12.137732Z","record_id":"6e1f7ef0f1c36d96c028a0269974e950ea151e73fe76b1f56b35fc663fe8d631","schema_fingerprint":"4aa3821a28b0b7c2400bc59aba4bcc0a76e971dadd19610d3ad38c768e124dc7","schema_version":"edge-lab-recorder.raw.v1","sequence":null,"source":"clob_market_ws"}
{"event_at":"2026-07-27T05:42:12.179000Z","event_fingerprint":"29d6eea03b3104279b6aa750ff4c7884f8314c97482b9c199dba2ba69bb08d23","payload":{"connection_id":"efc69d3132f1467b8e898a382b23ac0d","event_at":"2026-07-27T05:42:12.179000Z","event_type":"price_change","frame_hash":"322069cb07bbef09216d87ee9149a2ad5db2b08fad7bb25eea9f007fbb1d3053","frame_index":0,"kind":"data","monotonic_ns":232915373784333,"payload":{"event_type":"price_change","market":"0x3b40066b5cf3871a2f6237c5628bd8092a206aa998558ac5ec13c4483e31e160","price_changes":[{"asset_id":"14766054693214075530629349735273995982307625376442606753688071083149620216746","best_ask":"0.74","best_bid":"0.73","hash":"198e5ccf5fe2de5b94adf37b0587b7f86d6c55a5","price":"0.01","side":"BUY","size":"5330.02"},{"asset_id":"110216635572655435074987471276357323571387854733835379371586402147734167783946","best_ask":"0.27","best_bid":"0.26","hash":"27223cb7faf89a3d4a9db5a6b84f179cdb4631ff","price":"0.99","side":"SELL","size":"5330.02"}],"timestamp":"1785130932179"},"payload_hash":"f32b09e26d1439d4af6987ffa591d9a505d2db332158fa76206929497e814751","raw_frame":"{\"market\":\"0x3b40066b5cf3871a2f6237c5628bd8092a206aa998558ac5ec13c4483e31e160\", \"price_changes\":[{\"asset_id\":\"14766054693214075530629349735273995982307625376442606753688071083149620216746\", \"price\":\"0.01\", \"size\":\"5330.02\", \"side\":\"BUY\", \"hash\":\"198e5ccf5fe2de5b94adf37b0587b7f86d6c55a5\", \"best_bid\":\"0.73\", \"best_ask\":\"0.74\"}, {\"asset_id\":\"110216635572655435074987471276357323571387854733835379371586402147734167783946\", \"price\":\"0.99\", \"size\":\"5330.02\", \"side\":\"SELL\", \"hash\":\"27223cb7faf89a3d4a9db5a6b84f179cdb4631ff\", \"best_bid\":\"0.26\", \"best_ask\":\"0.27\"}], \"timestamp\":\"1785130932179\", \"event_type\":\"price_change\"}","received_at":"2026-07-27T05:42:12.140662Z","schema_version":"clob-market-ws.price_change.v1","sequence":null,"server_hash":null,"server_timestamp":"1785130932179","session_id":"502006c5cfcd437296561ea750c9ec8b","source":"clob_market_ws"},"received_at":"2026-07-27T05:42:12.140662Z","record_id":"39053d961d74631a1938a9cb36bed357471499b9315d773e243d9dca2d600c33","schema_fingerprint":"4aa3821a28b0b7c2400bc59aba4bcc0a76e971dadd19610d3ad38c768e124dc7","schema_version":"edge-lab-recorder.raw.v1","sequence":null,"source":"clob_market_ws"}
{"event_at":"2026-07-27T05:42:12.189000Z","event_fingerprint":"dc12bcd5a37cfaa4a0509c9894a20d3cbeafa0e05b750ba44ba8e8c1a2c2396a","payload":{"connection_id":"efc69d3132f1467b8e898a382b23ac0d","event_at":"2026-07-27T05:42:12.189000Z","event_type":"price_change","frame_hash":"d9af4e3a7cadcd49356f0403a30f55b9377651377ab9101115848eb5ae3a97e8","frame_index":0,"kind":"data","monotonic_ns":232915379682416,"payload":{"event_type":"price_change","market":"0x3b40066b5cf3871a2f6237c5628bd8092a206aa998558ac5ec13c4483e31e160","price_changes":[{"asset_id":"14766054693214075530629349735273995982307625376442606753688071083149620216746","best_ask":"0.74","best_bid":"0.73","hash":"fb7876e3f3c44ecd5a514fb109db3d3a64a97c87","price":"0.02","side":"BUY","size":"552"},{"asset_id":"110216635572655435074987471276357323571387854733835379371586402147734167783946","best_ask":"0.27","best_bid":"0.26","hash":"0a8eb2a980ddd32fd8b745e2c1baecbc01050e78","price":"0.98","side":"SELL","size":"552"}],"timestamp":"1785130932189"},"payload_hash":"0c6748b6f779c497c5df2f499d6bcfff15580107d9f82bd415480ea09d86328c","raw_frame":"{\"market\":\"0x3b40066b5cf3871a2f6237c5628bd8092a206aa998558ac5ec13c4483e31e160\", \"price_changes\":[{\"asset_id\":\"14766054693214075530629349735273995982307625376442606753688071083149620216746\", \"price\":\"0.02\", \"size\":\"552\", \"side\":\"BUY\", \"hash\":\"fb7876e3f3c44ecd5a514fb109db3d3a64a97c87\", \"best_bid\":\"0.73\", \"best_ask\":\"0.74\"}, {\"asset_id\":\"110216635572655435074987471276357323571387854733835379371586402147734167783946\", \"price\":\"0.98\", \"size\":\"552\", \"side\":\"SELL\", \"hash\":\"0a8eb2a980ddd32fd8b745e2c1baecbc01050e78\", \"best_bid\":\"0.26\", \"best_ask\":\"0.27\"}], \"timestamp\":\"1785130932189\", \"event_type\":\"price_change\"}","received_at":"2026-07-27T05:42:12.146559Z","schema_version":"clob-market-ws.price_change.v1","sequence":null,"server_hash":null,"server_timestamp":"1785130932189","session_id":"502006c5cfcd437296561ea750c9ec8b","source":"clob_market_ws"},"received_at":"2026-07-27T05:42:12.146559Z","record_id":"986ff2d67dfb8801c09416ec7af072947fec8bc810ac2e24eeaae9d47f4c1168","schema_fingerprint":"4aa3821a28b0b7c2400bc59aba4bcc0a76e971dadd19610d3ad38c768e124dc7","schema_version":"edge-lab-recorder.raw.v1","sequence":null,"source":"clob_market_ws"}
{"event_at":"2026-07-27T05:42:12.291000Z","event_fingerprint":"dfb5cf2d604520dc4ed276d57d64a08602e2c1777ab5aad49e42bafadf4649ce","payload":{"connection_id":"efc69d3132f1467b8e898a382b23ac0d","event_at":"2026-07-27T05:42:12.291000Z","event_type":"price_change","frame_hash":"ef0cb185c24af8ff3ea24ecb4078bd319830e27985382b5fba582afba3a76510","frame_index":0,"kind":"data","monotonic_ns":232915483403333,"payload":{"event_type":"price_change","market":"0x3b40066b5cf3871a2f6237c5628bd8092a206aa998558ac5ec13c4483e31e160","price_changes":[{"asset_id":"14766054693214075530629349735273995982307625376442606753688071083149620216746","best_ask":"0.74","best_bid":"0.73","hash":"03938a710345cc8f2677b04ad0fb308692338ee4","price":"0.51","side":"BUY","size":"168.7"},{"asset_id":"110216635572655435074987471276357323571387854733835379371586402147734167783946","best_ask":"0.27","best_bid":"0.26","hash":"20013ca54413e97cd4724dbc846470a5c0cc0cd0","price":"0.49","side":"SELL","size":"168.7"}],"timestamp":"1785130932291"},"payload_hash":"069b7e9952cd42e607d2efaf36f0c5ef4850f66f1f32d0a729982e1b9b192ee1","raw_frame":"{\"market\":\"0x3b40066b5cf3871a2f6237c5628bd8092a206aa998558ac5ec13c4483e31e160\", \"price_changes\":[{\"asset_id\":\"14766054693214075530629349735273995982307625376442606753688071083149620216746\", \"price\":\"0.51\", \"size\":\"168.7\", \"side\":\"BUY\", \"hash\":\"03938a710345cc8f2677b04ad0fb308692338ee4\", \"best_bid\":\"0.73\", \"best_ask\":\"0.74\"}, {\"asset_id\":\"110216635572655435074987471276357323571387854733835379371586402147734167783946\", \"price\":\"0.49\", \"size\":\"168.7\", \"side\":\"SELL\", \"hash\":\"20013ca54413e97cd4724dbc846470a5c0cc0cd0\", \"best_bid\":\"0.26\", \"best_ask\":\"0.27\"}], \"timestamp\":\"1785130932291\", \"event_type\":\"price_change\"}","received_at":"2026-07-27T05:42:12.250281Z","schema_version":"clob-market-ws.price_change.v1","sequence":null,"server_hash":null,"server_timestamp":"1785130932291","session_id":"502006c5cfcd437296561ea750c9ec8b","source":"clob_market_ws"},"received_at":"2026-07-27T05:42:12.250281Z","record_id":"38cee32465ba917a468662b04aa5dd2d641ca7078e1df246b6e0d3b299f3380e","schema_fingerprint":"4aa3821a28b0b7c2400bc59aba4bcc0a76e971dadd19610d3ad38c768e124dc7","schema_version":"edge-lab-recorder.raw.v1","sequence":null,"source":"clob_market_ws"}
{"event_at":"2026-07-27T05:42:12.320000Z","event_fingerprint":"254104d13b437a59d0eb50015ab235110a8c18ce1b00fbd8aeeffdeaeaedc728","payload":{"connection_id":"efc69d3132f1467b8e898a382b23ac0d","event_at":"2026-07-27T05:42:12.320000Z","event_type":"price_change","frame_hash":"867144adedce3d0f076d4dd3479edaf8120d716da2558c08d73504c5f7519238","frame_index":0,"kind":"data","monotonic_ns":232915512944583,"payload":{"event_type":"price_change","market":"0x3b40066b5cf3871a2f6237c5628bd8092a206aa998558ac5ec13c4483e31e160","price_changes":[{"asset_id":"14766054693214075530629349735273995982307625376442606753688071083149620216746","best_ask":"0.74","best_bid":"0.73","hash":"119ee8491b3505e7c4c12707e1c4756aeb72fdf2","price":"0.02","side":"BUY","size":"557"},{"asset_id":"110216635572655435074987471276357323571387854733835379371586402147734167783946","best_ask":"0.27","best_bid":"0.26","hash":"6037847b5639700f6df0177a8c53a4cf145ed269","price":"0.98","side":"SELL","size":"557"}],"timestamp":"1785130932320"},"payload_hash":"7cc2ea242cbccd08ddd64c2082d0c6c5accf64557efe81d464ed13098a9c9e3d","raw_frame":"{\"market\":\"0x3b40066b5cf3871a2f6237c5628bd8092a206aa998558ac5ec13c4483e31e160\", \"price_changes\":[{\"asset_id\":\"14766054693214075530629349735273995982307625376442606753688071083149620216746\", \"price\":\"0.02\", \"size\":\"557\", \"side\":\"BUY\", \"hash\":\"119ee8491b3505e7c4c12707e1c4756aeb72fdf2\", \"best_bid\":\"0.73\", \"best_ask\":\"0.74\"}, {\"asset_id\":\"110216635572655435074987471276357323571387854733835379371586402147734167783946\", \"price\":\"0.98\", \"size\":\"557\", \"side\":\"SELL\", \"hash\":\"6037847b5639700f6df0177a8c53a4cf145ed269\", \"best_bid\":\"0.26\", \"best_ask\":\"0.27\"}], \"timestamp\":\"1785130932320\", \"event_type\":\"price_change\"}","received_at":"2026-07-27T05:42:12.279817Z","schema_version":"clob-market-ws.price_change.v1","sequence":null,"server_hash":null,"server_timestamp":"1785130932320","session_id":"502006c5cfcd437296561ea750c9ec8b","source":"clob_market_ws"},"received_at":"2026-07-27T05:42:12.279817Z","record_id":"69f4d3dff2fc60a1d2b1c5a4303afef66a68cab411f808ff74a11caf21bd7f66","schema_fingerprint":"4aa3821a28b0b7c2400bc59aba4bcc0a76e971dadd19610d3ad38c768e124dc7","schema_version":"edge-lab-recorder.raw.v1","sequence":null,"source":"clob_market_ws"}
{"event_at":"2026-07-27T05:42:12.333000Z","event_fingerprint":"f600447e45c6a619b2edd0f2051a953afd228d01e4ab212eb522e28ce697a4e9","payload":{"connection_id":"efc69d3132f1467b8e898a382b23ac0d","event_at":"2026-07-27T05:42:12.333000Z","event_type":"price_change","frame_hash":"b53a4af1bc1e87f4a5a6570d48436a9a66d13a50e895ef78f48aa7ec2247ee11","frame_index":0,"kind":"data","monotonic_ns":232915529019916,"payload":{"event_type":"price_change","market":"0x3b40066b5cf3871a2f6237c5628bd8092a206aa998558ac5ec13c4483e31e160","price_changes":[{"asset_id":"110216635572655435074987471276357323571387854733835379371586402147734167783946","best_ask":"0.27","best_bid":"0.26","hash":"8ea62b9c304019a557ae35c527070c40ae03dad5","price":"0.1","side":"BUY","size":"116.44"},{"asset_id":"14766054693214075530629349735273995982307625376442606753688071083149620216746","best_ask":"0.74","best_bid":"0.73","hash":"f75e2596b3a541cb04b63cc85764ed828710ef5d","price":"0.9","side":"SELL","size":"116.44"}],"timestamp":"1785130932333"},"payload_hash":"5ba05a3a73abb38fbe32ad543f098d79c77f593c3a16bf1d5c9ed027cfa3337e","raw_frame":"{\"market\":\"0x3b40066b5cf3871a2f6237c5628bd8092a206aa998558ac5ec13c4483e31e160\", \"price_changes\":[{\"asset_id\":\"110216635572655435074987471276357323571387854733835379371586402147734167783946\", \"price\":\"0.1\", \"size\":\"116.44\", \"side\":\"BUY\", \"hash\":\"8ea62b9c304019a557ae35c527070c40ae03dad5\", \"best_bid\":\"0.26\", \"best_ask\":\"0.27\"}, {\"asset_id\":\"14766054693214075530629349735273995982307625376442606753688071083149620216746\", \"price\":\"0.9\", \"size\":\"116.44\", \"side\":\"SELL\", \"hash\":\"f75e2596b3a541cb04b63cc85764ed828710ef5d\", \"best_bid\":\"0.73\", \"best_ask\":\"0.74\"}], \"timestamp\":\"1785130932333\", \"event_type\":\"price_change\"}","received_at":"2026-07-27T05:42:12.295898Z","schema_version":"clob-market-ws.price_change.v1","sequence":null,"server_hash":null,"server_timestamp":"1785130932333","session_id":"502006c5cfcd437296561ea750c9ec8b","source":"clob_market_ws"},"received_at":"2026-07-27T05:42:12.295898Z","record_id":"c3433c6bb1aa641fa55a6c74b0f1b3aaf901657032c4d26f8d8d893e58ee50f1","schema_fingerprint":"4aa3821a28b0b7c2400bc59aba4bcc0a76e971dadd19610d3ad38c768e124dc7","schema_version":"edge-lab-recorder.raw.v1","sequence":null,"source":"clob_market_ws"}
{"event_at":"2026-07-27T05:42:12.366000Z","event_fingerprint":"586bbea39ff3ec87d022c2ecc124c8a3c6f7346961f71126c6cf4ea3edadbff5","payload":{"connection_id":"efc69d3132f1467b8e898a382b23ac0d","event_at":"2026-07-27T05:42:12.366000Z","event_type":"price_change","frame_hash":"476666cb606369cd442111cce5c5c7a878b8935cd2afd2769b18879cbde2f197","frame_index":0,"kind":"data","monotonic_ns":232915559058291,"payload":{"event_type":"price_change","market":"0x3b40066b5cf3871a2f6237c5628bd8092a206aa998558ac5ec13c4483e31e160","price_changes":[{"asset_id":"14766054693214075530629349735273995982307625376442606753688071083149620216746","best_ask":"0.74","best_bid":"0.73","hash":"4c5d9559f03c73a2dd3bf0059dc8a4ba2f4b2054","price":"0.83","side":"SELL","size":"175.95"},{"asset_id":"110216635572655435074987471276357323571387854733835379371586402147734167783946","best_ask":"0.27","best_bid":"0.26","hash":"0753f28e97b5b2fe25a07be218bf5404417815d3","price":"0.17","side":"BUY","size":"175.95"}],"timestamp":"1785130932366"},"payload_hash":"bc63e6c085ff00672018da22bb7a95f808e50dfdd3a95fc4b77ceaca11f13ecd","raw_frame":"{\"market\":\"0x3b40066b5cf3871a2f6237c5628bd8092a206aa998558ac5ec13c4483e31e160\", \"price_changes\":[{\"asset_id\":\"14766054693214075530629349735273995982307625376442606753688071083149620216746\", \"price\":\"0.83\", \"size\":\"175.95\", \"side\":\"SELL\", \"hash\":\"4c5d9559f03c73a2dd3bf0059dc8a4ba2f4b2054\", \"best_bid\":\"0.73\", \"best_ask\":\"0.74\"}, {\"asset_id\":\"110216635572655435074987471276357323571387854733835379371586402147734167783946\", \"price\":\"0.17\", \"size\":\"175.95\", \"side\":\"BUY\", \"hash\":\"0753f28e97b5b2fe25a07be218bf5404417815d3\", \"best_bid\":\"0.26\", \"best_ask\":\"0.27\"}], \"timestamp\":\"1785130932366\", \"event_type\":\"price_change\"}","received_at":"2026-07-27T05:42:12.325936Z","schema_version":"clob-market-ws.price_change.v1","sequence":null,"server_hash":null,"server_timestamp":"1785130932366","session_id":"502006c5cfcd437296561ea750c9ec8b","source":"clob_market_ws"},"received_at":"2026-07-27T05:42:12.325936Z","record_id":"bae5512d1bb6ebfbe7f2f2bb864062fcbdfbb8f3938d177e970b3f216b8f0f2a","schema_fingerprint":"4aa3821a28b0b7c2400bc59aba4bcc0a76e971dadd19610d3ad38c768e124dc7","schema_version":"edge-lab-recorder.raw.v1","sequence":null,"source":"clob_market_ws"}
{"event_at":"2026-07-27T05:42:12.396000Z","event_fingerprint":"375b774a41264585db630e16fa43059a3601f6d0926ddd6a2331b2d706261496","payload":{"connection_id":"efc69d3132f1467b8e898a382b23ac0d","event_at":"2026-07-27T05:42:12.396000Z","event_type":"price_change","frame_hash":"6ffc3dc1529646f37d17fcdcc7a6d578c13291c5e141889dc485d0146379d39e","frame_index":0,"kind":"data","monotonic_ns":232915588068416,"payload":{"event_type":"price_change","market":"0x3b40066b5cf3871a2f6237c5628bd8092a206aa998558ac5ec13c4483e31e160","price_changes":[{"asset_id":"14766054693214075530629349735273995982307625376442606753688071083149620216746","best_ask":"0.74","best_bid":"0.73","hash":"178e57418c1deb1cc65b117fc91ad0cdf6ac2d24","price":"0.02","side":"BUY","size":"552"},{"asset_id":"110216635572655435074987471276357323571387854733835379371586402147734167783946","best_ask":"0.27","best_bid":"0.26","hash":"22fffe3576e7e22317e101f7f82c1032d115b8bd","price":"0.98","side":"SELL","size":"552"}],"timestamp":"1785130932396"},"payload_hash":"4111543329d81db188a501ad2fb44cf71e9335575d23a7e37565591d3b3eb781","raw_frame":"{\"market\":\"0x3b40066b5cf3871a2f6237c5628bd8092a206aa998558ac5ec13c4483e31e160\", \"price_changes\":[{\"asset_id\":\"14766054693214075530629349735273995982307625376442606753688071083149620216746\", \"price\":\"0.02\", \"size\":\"552\", \"side\":\"BUY\", \"hash\":\"178e57418c1deb1cc65b117fc91ad0cdf6ac2d24\", \"best_bid\":\"0.73\", \"best_ask\":\"0.74\"}, {\"asset_id\":\"110216635572655435074987471276357323571387854733835379371586402147734167783946\", \"price\":\"0.98\", \"size\":\"552\", \"side\":\"SELL\", \"hash\":\"22fffe3576e7e22317e101f7f82c1032d115b8bd\", \"best_bid\":\"0.26\", \"best_ask\":\"0.27\"}], \"timestamp\":\"1785130932396\", \"event_type\":\"price_change\"}","received_at":"2026-07-27T05:42:12.354948Z","schema_version":"clob-market-ws.price_change.v1","sequence":null,"server_hash":null,"server_timestamp":"1785130932396","session_id":"502006c5cfcd437296561ea750c9ec8b","source":"clob_market_ws"},"received_at":"2026-07-27T05:42:12.354948Z","record_id":"794c16ffed8d243ea68b6d77b3bca83aedfa6bb169c9666142f914884eadafbd","schema_fingerprint":"4aa3821a28b0b7c2400bc59aba4bcc0a76e971dadd19610d3ad38c768e124dc7","schema_version":"edge-lab-recorder.raw.v1","sequence":null,"source":"clob_market_ws"}
{"event_at":"2026-07-27T05:42:12.420000Z","event_fingerprint":"3fe6d85ee2d1d496f7977295b587aed0084abb91344edf61ea7569f27cb2acda","payload":{"connection_id":"efc69d3132f1467b8e898a382b23ac0d","event_at":"2026-07-27T05:42:12.420000Z","event_type":"price_change","frame_hash":"01e22813211530c65abc14f41a450f3a527f2377cbbc267bcbff27b3536f35ca","frame_index":0,"kind":"data","monotonic_ns":232915618246250,"payload":{"event_type":"price_change","market":"0x3b40066b5cf3871a2f6237c5628bd8092a206aa998558ac5ec13c4483e31e160","price_changes":[{"asset_id":"14766054693214075530629349735273995982307625376442606753688071083149620216746","best_ask":"0.74","best_bid":"0.73","hash":"0cd1d1dd7354498663cda32f05458c903fb6ff20","price":"0.51","side":"BUY","size":"234.05"},{"asset_id":"110216635572655435074987471276357323571387854733835379371586402147734167783946","best_ask":"0.27","best_bid":"0.26","hash":"dbc0e2b0d304a5537f784d899b9358ff28990c34","price":"0.49","side":"SELL","size":"234.05"}],"timestamp":"1785130932420"},"payload_hash":"15bde227f3010b85f46f2b0fcb5bbf9d8062ce1e4ee9940f41ef44eea40057da","raw_frame":"{\"market\":\"0x3b40066b5cf3871a2f6237c5628bd8092a206aa998558ac5ec13c4483e31e160\", \"price_changes\":[{\"asset_id\":\"14766054693214075530629349735273995982307625376442606753688071083149620216746\", \"price\":\"0.51\", \"size\":\"234.05\", \"side\":\"BUY\", \"hash\":\"0cd1d1dd7354498663cda32f05458c903fb6ff20\", \"best_bid\":\"0.73\", \"best_ask\":\"0.74\"}, {\"asset_id\":\"110216635572655435074987471276357323571387854733835379371586402147734167783946\", \"price\":\"0.49\", \"size\":\"234.05\", \"side\":\"SELL\", \"hash\":\"dbc0e2b0d304a5537f784d899b9358ff28990c34\", \"best_bid\":\"0.26\", \"best_ask\":\"0.27\"}], \"timestamp\":\"1785130932420\", \"event_type\":\"price_change\"}","received_at":"2026-07-27T05:42:12.385124Z","schema_version":"clob-market-ws.price_change.v1","sequence":null,"server_hash":null,"server_timestamp":"1785130932420","session_id":"502006c5cfcd437296561ea750c9ec8b","source":"clob_market_ws"},"received_at":"2026-07-27T05:42:12.385124Z","record_id":"7220d2e82fd25341c55d687f26bbfd6df4735c94a4159d311f7d8a7538ae57a0","schema_fingerprint":"4aa3821a28b0b7c2400bc59aba4bcc0a76e971dadd19610d3ad38c768e124dc7","schema_version":"edge-lab-recorder.raw.v1","sequence":null,"source":"clob_market_ws"}
{"event_at":"2026-07-27T05:42:12.428000Z","event_fingerprint":"62235b6844078569f87ec32cb5e6fce421080ec7f96ef99ec57bd7a396b1b388","payload":{"connection_id":"efc69d3132f1467b8e898a382b23ac0d","event_at":"2026-07-27T05:42:12.428000Z","event_type":"price_change","frame_hash":"5d3eda140e1c9a1d0015c97cac7f1de53b7d4132630f01b0a7557dd522f5af0e","frame_index":0,"kind":"data","monotonic_ns":232915621289208,"payload":{"event_type":"price_change","market":"0x3b40066b5cf3871a2f6237c5628bd8092a206aa998558ac5ec13c4483e31e160","price_changes":[{"asset_id":"14766054693214075530629349735273995982307625376442606753688071083149620216746","best_ask":"0.74","best_bid":"0.73","hash":"c1cb3e3957c89fa6a665ad2b7b97bfae0c1a75fe","price":"0.65","side":"BUY","size":"50.86"},{"asset_id":"110216635572655435074987471276357323571387854733835379371586402147734167783946","best_ask":"0.27","best_bid":"0.26","hash":"5a275b501a40e20279b7840372487f6353b67d5e","price":"0.35","side":"SELL","size":"50.86"}],"timestamp":"1785130932428"},"payload_hash":"8f5d3442a7110617b94e236aaf9c9e7425fafd48546f88e81b32334f1b61457e","raw_frame":"{\"market\":\"0x3b40066b5cf3871a2f6237c5628bd8092a206aa998558ac5ec13c4483e31e160\", \"price_changes\":[{\"asset_id\":\"14766054693214075530629349735273995982307625376442606753688071083149620216746\", \"price\":\"0.65\", \"size\":\"50.86\", \"side\":\"BUY\", \"hash\":\"c1cb3e3957c89fa6a665ad2b7b97bfae0c1a75fe\", \"best_bid\":\"0.73\", \"best_ask\":\"0.74\"}, {\"asset_id\":\"110216635572655435074987471276357323571387854733835379371586402147734167783946\", \"price\":\"0.35\", \"size\":\"50.86\", \"side\":\"SELL\", \"hash\":\"5a275b501a40e20279b7840372487f6353b67d5e\", \"best_bid\":\"0.26\", \"best_ask\":\"0.27\"}], \"timestamp\":\"1785130932428\", \"event_type\":\"price_change\"}","received_at":"2026-07-27T05:42:12.388168Z","schema_version":"clob-market-ws.price_change.v1","sequence":null,"server_hash":null,"server_timestamp":"1785130932428","session_id":"502006c5cfcd437296561ea750c9ec8b","source":"clob_market_ws"},"received_at":"2026-07-27T05:42:12.388168Z","record_id":"e0fd63ed7ff2762802f90371889a4bb6e5b715d5ae6fa41ea160fc2d5b627109","schema_fingerprint":"4aa3821a28b0b7c2400bc59aba4bcc0a76e971dadd19610d3ad38c768e124dc7","schema_version":"edge-lab-recorder.raw.v1","sequence":null,"source":"clob_market_ws"}
{"event_at":"2026-07-27T05:42:12.438000Z","event_fingerprint":"3004135caeaf7db1358fd1c86fc608e6c111559ff96e397823fea68f39d6596e","payload":{"connection_id":"efc69d3132f1467b8e898a382b23ac0d","event_at":"2026-07-27T05:42:12.438000Z","event_type":"price_change","frame_hash":"00a904f13bc5d05d4276480f533bb5602f3c0e93fceeb02dfda515ff27733b04","frame_index":0,"kind":"data","monotonic_ns":232915630434791,"payload":{"event_type":"price_change","market":"0x3b40066b5cf3871a2f6237c5628bd8092a206aa998558ac5ec13c4483e31e160","price_changes":[{"asset_id":"110216635572655435074987471276357323571387854733835379371586402147734167783946","best_ask":"0.27","best_bid":"0.26","hash":"48cf9a5bf0f9369fee352c4d8dc51c281648e5ac","price":"0.26","side":"BUY","size":"93"},{"asset_id":"14766054693214075530629349735273995982307625376442606753688071083149620216746","best_ask":"0.74","best_bid":"0.73","hash":"2280f29ae3bd9d6d80af9f05b1edeb4478f51256","price":"0.74","side":"SELL","size":"93"}],"timestamp":"1785130932438"},"payload_hash":"f1642e44f0b02bbb3c34fc870cb86648ce3317610bd2246ec3f2a646cf75f0ea","raw_frame":"{\"market\":\"0x3b40066b5cf3871a2f6237c5628bd8092a206aa998558ac5ec13c4483e31e160\", \"price_changes\":[{\"asset_id\":\"110216635572655435074987471276357323571387854733835379371586402147734167783946\", \"price\":\"0.26\", \"size\":\"93\", \"side\":\"BUY\", \"hash\":\"48cf9a5bf0f9369fee352c4d8dc51c281648e5ac\", \"best_bid\":\"0.26\", \"best_ask\":\"0.27\"}, {\"asset_id\":\"14766054693214075530629349735273995982307625376442606753688071083149620216746\", \"price\":\"0.74\", \"size\":\"93\", \"side\":\"SELL\", \"hash\":\"2280f29ae3bd9d6d80af9f05b1edeb4478f51256\", \"best_bid\":\"0.73\", \"best_ask\":\"0.74\"}], \"timestamp\":\"1785130932438\", \"event_type\":\"price_change\"}","received_at":"2026-07-27T05:42:12.397314Z","schema_version":"clob-market-ws.price_change.v1","sequence":null,"server_hash":null,"server_timestamp":"1785130932438","session_id":"502006c5cfcd437296561ea750c9ec8b","source":"clob_market_ws"},"received_at":"2026-07-27T05:42:12.397314Z","record_id":"ad192b91102e7d9bfd4955d70dc482a976b09a040b7ddfd754503c434d3c54cc","schema_fingerprint":"4aa3821a28b0b7c2400bc59aba4bcc0a76e971dadd19610d3ad38c768e124dc7","schema_version":"edge-lab-recorder.raw.v1","sequence":null,"source":"clob_market_ws"}
{"event_at":"2026-07-27T05:42:12.450000Z","event_fingerprint":"957191898432e4ee483560ad3d6fa383269bc5d335aa5ae6b56601452a022a82","payload":{"connection_id":"efc69d3132f1467b8e898a382b23ac0d","event_at":"2026-07-27T05:42:12.450000Z","event_type":"price_change","frame_hash":"6bfb96423ccd26f0e0fad49a18a488e77bc5f3514e209aa6e6af37d290f29ccb","frame_index":0,"kind":"data","monotonic_ns":232915641808375,"payload":{"event_type":"price_change","market":"0x3b40066b5cf3871a2f6237c5628bd8092a206aa998558ac5ec13c4483e31e160","price_changes":[{"asset_id":"14766054693214075530629349735273995982307625376442606753688071083149620216746","best_ask":"0.74","best_bid":"0.73","hash":"60f95b8626d267da594260d5e078cdb1c03d1181","price":"0.01","side":"BUY","size":"5335.02"},{"asset_id":"110216635572655435074987471276357323571387854733835379371586402147734167783946","best_ask":"0.27","best_bid":"0.26","hash":"579fece114affe7fb52614e73e6f8fbbaa57d16f","price":"0.99","side":"SELL","size":"5335.02"}],"timestamp":"1785130932450"},"payload_hash":"d77d36bf712f8f5a92dc403e2f9edf74e945dc2d1922f253b3debad3b37dd3d9","raw_frame":"{\"market\":\"0x3b40066b5cf3871a2f6237c5628bd8092a206aa998558ac5ec13c4483e31e160\", \"price_changes\":[{\"asset_id\":\"14766054693214075530629349735273995982307625376442606753688071083149620216746\", \"price\":\"0.01\", \"size\":\"5335.02\", \"side\":\"BUY\", \"hash\":\"60f95b8626d267da594260d5e078cdb1c03d1181\", \"best_bid\":\"0.73\", \"best_ask\":\"0.74\"}, {\"asset_id\":\"110216635572655435074987471276357323571387854733835379371586402147734167783946\", \"price\":\"0.99\", \"size\":\"5335.02\", \"side\":\"SELL\", \"hash\":\"579fece114affe7fb52614e73e6f8fbbaa57d16f\", \"best_bid\":\"0.26\", \"best_ask\":\"0.27\"}], \"timestamp\":\"1785130932450\", \"event_type\":\"price_change\"}","received_at":"2026-07-27T05:42:12.408687Z","schema_version":"clob-market-ws.price_change.v1","sequence":null,"server_hash":null,"server_timestamp":"1785130932450","session_id":"502006c5cfcd437296561ea750c9ec8b","source":"clob_market_ws"},"received_at":"2026-07-27T05:42:12.408687Z","record_id":"a4101e0fe196e0aff8eb703b01e381b63cc02dce3b2948c7f1440d8ff5a423a7","schema_fingerprint":"4aa3821a28b0b7c2400bc59aba4bcc0a76e971dadd19610d3ad38c768e124dc7","schema_version":"edge-lab-recorder.raw.v1","sequence":null,"source":"clob_market_ws"}
{"event_at":"2026-07-27T05:42:12.455000Z","event_fingerprint":"39aa4075dbbc19a8c7d410ce320a9ad7abeb889c0003eb22e20948b25f8dab97","payload":{"connection_id":"efc69d3132f1467b8e898a382b23ac0d","event_at":"2026-07-27T05:42:12.455000Z","event_type":"price_change","frame_hash":"57350545a24405cbcae184f46b479dc138515b61dccc119cebecd7b6d4c4c53c","frame_index":0,"kind":"data","monotonic_ns":232915646365041,"payload":{"event_type":"price_change","market":"0x3b40066b5cf3871a2f6237c5628bd8092a206aa998558ac5ec13c4483e31e160","price_changes":[{"asset_id":"14766054693214075530629349735273995982307625376442606753688071083149620216746","best_ask":"0.74","best_bid":"0.73","hash":"5f1bede432dd5f2b6ff5e7279d672713313c5167","price":"0.66","side":"BUY","size":"49"},{"asset_id":"110216635572655435074987471276357323571387854733835379371586402147734167783946","best_ask":"0.27","best_bid":"0.26","hash":"c92e3183deb2331da342ea9b9f1ad830b7658a1c","price":"0.34","side":"SELL","size":"49"}],"timestamp":"1785130932455"},"payload_hash":"6541b0b4bd1ac7efcb5537a09421e4319019a82f4cfa0635d5d0023201ced946","raw_frame":"{\"market\":\"0x3b40066b5cf3871a2f6237c5628bd8092a206aa998558ac5ec13c4483e31e160\", \"price_changes\":[{\"asset_id\":\"14766054693214075530629349735273995982307625376442606753688071083149620216746\", \"price\":\"0.66\", \"size\":\"49\", \"side\":\"BUY\", \"hash\":\"5f1bede432dd5f2b6ff5e7279d672713313c5167\", \"best_bid\":\"0.73\", \"best_ask\":\"0.74\"}, {\"asset_id\":\"110216635572655435074987471276357323571387854733835379371586402147734167783946\", \"price\":\"0.34\", \"size\":\"49\", \"side\":\"SELL\", \"hash\":\"c92e3183deb2331da342ea9b9f1ad830b7658a1c\", \"best_bid\":\"0.26\", \"best_ask\":\"0.27\"}], \"timestamp\":\"1785130932455\", \"event_type\":\"price_change\"}","received_at":"2026-07-27T05:42:12.413245Z","schema_version":"clob-market-ws.price_change.v1","sequence":null,"server_hash":null,"server_timestamp":"1785130932455","session_id":"502006c5cfcd437296561ea750c9ec8b","source":"clob_market_ws"},"received_at":"2026-07-27T05:42:12.413245Z","record_id":"7e7d924a1c0d943020c6d5ed71967fe4d492bed866778865da5eeb01c0e91746","schema_fingerprint":"4aa3821a28b0b7c2400bc59aba4bcc0a76e971dadd19610d3ad38c768e124dc7","schema_version":"edge-lab-recorder.raw.v1","sequence":null,"source":"clob_market_ws"}
{"event_at":"2026-07-27T05:42:12.471000Z","event_fingerprint":"400b6a934762bdb355dccf4003d0662ab722ebf5ba3cf2678459bb5b7e6495c1","payload":{"connection_id":"efc69d3132f1467b8e898a382b23ac0d","event_at":"2026-07-27T05:42:12.471000Z","event_type":"price_change","frame_hash":"e5d1d71c1c8493d64b36bd25e012c8a4ad9112be6123b54596e20349b132e54d","frame_index":0,"kind":"data","monotonic_ns":232915665713375,"payload":{"event_type":"price_change","market":"0x3b40066b5cf3871a2f6237c5628bd8092a206aa998558ac5ec13c4483e31e160","price_changes":[{"asset_id":"14766054693214075530629349735273995982307625376442606753688071083149620216746","best_ask":"0.74","best_bid":"0.73","hash":"740199d6d48ffdc696720bd7ee6f9f6eb165534a","price":"0.01","side":"BUY","size":"5330.02"},{"asset_id":"110216635572655435074987471276357323571387854733835379371586402147734167783946","best_ask":"0.27","best_bid":"0.26","hash":"c86341a5c215bd0065fb94a8f2a187572d8ffa47","price":"0.99","side":"SELL","size":"5330.02"}],"timestamp":"1785130932471"},"payload_hash":"5422689a7f93e557561d209e24d7b03af2106af8ebcc3f6e73eb8f9b4f74cf74","raw_frame":"{\"market\":\"0x3b40066b5cf3871a2f6237c5628bd8092a206aa998558ac5ec13c4483e31e160\", \"price_changes\":[{\"asset_id\":\"14766054693214075530629349735273995982307625376442606753688071083149620216746\", \"price\":\"0.01\", \"size\":\"5330.02\", \"side\":\"BUY\", \"hash\":\"740199d6d48ffdc696720bd7ee6f9f6eb165534a\", \"best_bid\":\"0.73\", \"best_ask\":\"0.74\"}, {\"asset_id\":\"110216635572655435074987471276357323571387854733835379371586402147734167783946\", \"price\":\"0.99\", \"size\":\"5330.02\", \"side\":\"SELL\", \"hash\":\"c86341a5c215bd0065fb94a8f2a187572d8ffa47\", \"best_bid\":\"0.26\", \"best_ask\":\"0.27\"}], \"timestamp\":\"1785130932471\", \"event_type\":\"price_change\"}","received_at":"2026-07-27T05:42:12.432592Z","schema_version":"clob-market-ws.price_change.v1","sequence":null,"server_hash":null,"server_timestamp":"1785130932471","session_id":"502006c5cfcd437296561ea750c9ec8b","source":"clob_market_ws"},"received_at":"2026-07-27T05:42:12.432592Z","record_id":"cf94fc3d12ab50b65f835d3fff8525ed9c95842cefe976a9233163f4a718d500","schema_fingerprint":"4aa3821a28b0b7c2400bc59aba4bcc0a76e971dadd19610d3ad38c768e124dc7","schema_version":"edge-lab-recorder.raw.v1","sequence":null,"source":"clob_market_ws"}
{"event_at":"2026-07-27T05:42:12.482000Z","event_fingerprint":"c2a457651d8a096c5e83ea1bf61ae057ddfacab3989fc6b612a5ea208ff6fdf5","payload":{"connection_id":"efc69d3132f1467b8e898a382b23ac0d","event_at":"2026-07-27T05:42:12.482000Z","event_type":"price_change","frame_hash":"bc87153d62e3afd41800b6c29c676f29cdab3e885d2c247e185d1e9e660aaf3e","frame_index":0,"kind":"data","monotonic_ns":232915675020000,"payload":{"event_type":"price_change","market":"0x3b40066b5cf3871a2f6237c5628bd8092a206aa998558ac5ec13c4483e31e160","price_changes":[{"asset_id":"14766054693214075530629349735273995982307625376442606753688071083149620216746","best_ask":"0.74","best_bid":"0.73","hash":"bc70d59a13ae091e09f9334c227ba22adedca3ce","price":"0.02","side":"BUY","size":"557"},{"asset_id":"110216635572655435074987471276357323571387854733835379371586402147734167783946","best_ask":"0.27","best_bid":"0.26","hash":"f70d86782e2b603f642308ae64eb6723dff3f8e1","price":"0.98","side":"SELL","size":"557"}],"timestamp":"1785130932482"},"payload_hash":"4527a4bde80b73343fa82454f4046189a17c48471cd58f561f8704b35a4acf83","raw_frame":"{\"market\":\"0x3b40066b5cf3871a2f6237c5628bd8092a206aa998558ac5ec13c4483e31e160\", \"price_changes\":[{\"asset_id\":\"14766054693214075530629349735273995982307625376442606753688071083149620216746\", \"price\":\"0.02\", \"size\":\"557\", \"side\":\"BUY\", \"hash\":\"bc70d59a13ae091e09f9334c227ba22adedca3ce\", \"best_bid\":\"0.73\", \"best_ask\":\"0.74\"}, {\"asset_id\":\"110216635572655435074987471276357323571387854733835379371586402147734167783946\", \"price\":\"0.98\", \"size\":\"557\", \"side\":\"SELL\", \"hash\":\"f70d86782e2b603f642308ae64eb6723dff3f8e1\", \"best_bid\":\"0.26\", \"best_ask\":\"0.27\"}], \"timestamp\":\"1785130932482\", \"event_type\":\"price_change\"}","received_at":"2026-07-27T05:42:12.441899Z","schema_version":"clob-market-ws.price_change.v1","sequence":null,"server_hash":null,"server_timestamp":"1785130932482","session_id":"502006c5cfcd437296561ea750c9ec8b","source":"clob_market_ws"},"received_at":"2026-07-27T05:42:12.441899Z","record_id":"e07a4b232ee3d9fe6c535610a74fe38762ef57c98f2ada8a7d1ee21cc6e88888","schema_fingerprint":"4aa3821a28b0b7c2400bc59aba4bcc0a76e971dadd19610d3ad38c768e124dc7","schema_version":"edge-lab-recorder.raw.v1","sequence":null,"source":"clob_market_ws"}
{"event_at":"2026-07-27T05:42:12.486000Z","event_fingerprint":"4f3c58bb24dde99dffd5a1834539c8762c28b5a46e015834aaefe670603ee440","payload":{"connection_id":"efc69d3132f1467b8e898a382b23ac0d","event_at":"2026-07-27T05:42:12.486000Z","event_type":"price_change","frame_hash":"acde212e0d53e11e44df8013c3de914e5dd9cc1086cc5b832d88ad88b5e0ee7f","frame_index":0,"kind":"data","monotonic_ns":232915678019458,"payload":{"event_type":"price_change","market":"0x3b40066b5cf3871a2f6237c5628bd8092a206aa998558ac5ec13c4483e31e160","price_changes":[{"asset_id":"14766054693214075530629349735273995982307625376442606753688071083149620216746","best_ask":"0.74","best_bid":"0.73","hash":"132d8ac2b63dd7669bca18399c1a68e45f5a85da","price":"0.82","side":"SELL","size":"87.44"},{"asset_id":"110216635572655435074987471276357323571387854733835379371586402147734167783946","best_ask":"0.27","best_bid":"0.26","hash":"954159af4cf147ff3f789fff06ce3e4b15af8d0f","price":"0.18","side":"BUY","size":"87.44"}],"timestamp":"1785130932486"},"payload_hash":"62cf3aae5ba617515a7e499c36861f4e7711e2947d95ffdb5a52dac649885d3f","raw_frame":"{\"market\":\"0x3b40066b5cf3871a2f6237c5628bd8092a206aa998558ac5ec13c4483e31e160\", \"price_changes\":[{\"asset_id\":\"14766054693214075530629349735273995982307625376442606753688071083149620216746\", \"price\":\"0.82\", \"size\":\"87.44\", \"side\":\"SELL\", \"hash\":\"132d8ac2b63dd7669bca18399c1a68e45f5a85da\", \"best_bid\":\"0.73\", \"best_ask\":\"0.74\"}, {\"asset_id\":\"110216635572655435074987471276357323571387854733835379371586402147734167783946\", \"price\":\"0.18\", \"size\":\"87.44\", \"side\":\"BUY\", \"hash\":\"954159af4cf147ff3f789fff06ce3e4b15af8d0f\", \"best_bid\":\"0.26\", \"best_ask\":\"0.27\"}], \"timestamp\":\"1785130932486\", \"event_type\":\"price_change\"}","received_at":"2026-07-27T05:42:12.444899Z","schema_version":"clob-market-ws.price_change.v1","sequence":null,"server_hash":null,"server_timestamp":"1785130932486","session_id":"502006c5cfcd437296561ea750c9ec8b","source":"clob_market_ws"},"received_at":"2026-07-27T05:42:12.444899Z","record_id":"12686eb16cd81cfb34a34b7b105801bf34935f77b0861a0d7b010ffffd5932b5","schema_fingerprint":"4aa3821a28b0b7c2400bc59aba4bcc0a76e971dadd19610d3ad38c768e124dc7","schema_version":"edge-lab-recorder.raw.v1","sequence":null,"source":"clob_market_ws"}
{"event_at":"2026-07-27T05:42:12.557000Z","event_fingerprint":"17a58cccf992aefb220a1e6abd5c341e1106f2e88fddc2922d92cbd4ad855ebf","payload":{"connection_id":"efc69d3132f1467b8e898a382b23ac0d","event_at":"2026-07-27T05:42:12.557000Z","event_type":"price_change","frame_hash":"833e67b54e0fc9bd3027cf835794bbb04c469ee9691ffb4588073cd3b9683eb0","frame_index":0,"kind":"data","monotonic_ns":232915748251250,"payload":{"event_type":"price_change","market":"0x3b40066b5cf3871a2f6237c5628bd8092a206aa998558ac5ec13c4483e31e160","price_changes":[{"asset_id":"14766054693214075530629349735273995982307625376442606753688071083149620216746","best_ask":"0.74","best_bid":"0.73","hash":"6f38043a680dc6ac6e83c150c0e1c13ef4ebc98f","price":"0.02","side":"BUY","size":"552"},{"asset_id":"110216635572655435074987471276357323571387854733835379371586402147734167783946","best_ask":"0.27","best_bid":"0.26","hash":"6a77a7b9ad542d1d3b59e3e49c8bd7b45696bb9a","price":"0.98","side":"SELL","size":"552"}],"timestamp":"1785130932557"},"payload_hash":"2a49a1f35848a04e1d019349b10afa011d10f977d9805f5be18526f7256bdf9f","raw_frame":"{\"market\":\"0x3b40066b5cf3871a2f6237c5628bd8092a206aa998558ac5ec13c4483e31e160\", \"price_changes\":[{\"asset_id\":\"14766054693214075530629349735273995982307625376442606753688071083149620216746\", \"price\":\"0.02\", \"size\":\"552\", \"side\":\"BUY\", \"hash\":\"6f38043a680dc6ac6e83c150c0e1c13ef4ebc98f\", \"best_bid\":\"0.73\", \"best_ask\":\"0.74\"}, {\"asset_id\":\"110216635572655435074987471276357323571387854733835379371586402147734167783946\", \"price\":\"0.98\", \"size\":\"552\", \"side\":\"SELL\", \"hash\":\"6a77a7b9ad542d1d3b59e3e49c8bd7b45696bb9a\", \"best_bid\":\"0.26\", \"best_ask\":\"0.27\"}], \"timestamp\":\"1785130932557\", \"event_type\":\"price_change\"}","received_at":"2026-07-27T05:42:12.515126Z","schema_version":"clob-market-ws.price_change.v1","sequence":null,"server_hash":null,"server_timestamp":"1785130932557","session_id":"502006c5cfcd437296561ea750c9ec8b","source":"clob_market_ws"},"received_at":"2026-07-27T05:42:12.515126Z","record_id":"c75bc04110fe0d004d463e7525f9830b31e35951535ccb2805013a9f8c29fc23","schema_fingerprint":"4aa3821a28b0b7c2400bc59aba4bcc0a76e971dadd19610d3ad38c768e124dc7","schema_version":"edge-lab-recorder.raw.v1","sequence":null,"source":"clob_market_ws"}
{"event_at":"2026-07-27T05:42:12.618000Z","event_fingerprint":"6e44dfa294e5298e6095f13e03245674550296d926df4d094f374a5ebbf7d7b1","payload":{"connection_id":"efc69d3132f1467b8e898a382b23ac0d","event_at":"2026-07-27T05:42:12.618000Z","event_type":"price_change","frame_hash":"9f13fe9da7b5ede765b9e8b344248caf81b361785c2a1d5fae0ae561a3c9d7cf","frame_index":0,"kind":"data","monotonic_ns":232915810103833,"payload":{"event_type":"price_change","market":"0x3b40066b5cf3871a2f6237c5628bd8092a206aa998558ac5ec13c4483e31e160","price_changes":[{"asset_id":"14766054693214075530629349735273995982307625376442606753688071083149620216746","best_ask":"0.74","best_bid":"0.73","hash":"c8b628de2acbdf3aea2044258ba82b15064af3a1","price":"0.82","side":"SELL","size":"79.4"},{"asset_id":"110216635572655435074987471276357323571387854733835379371586402147734167783946","best_ask":"0.27","best_bid":"0.26","hash":"f97472f6d2d4abf5b92a4cbdbcb179fa14601667","price":"0.18","side":"BUY","size":"79.4"}],"timestamp":"1785130932618"},"payload_hash":"7208fc21d7956d55c0de81c58076f7a6afe7f920ce74831b510b807b9ffd25ef","raw_frame":"{\"market\":\"0x3b40066b5cf3871a2f6237c5628bd8092a206aa998558ac5ec13c4483e31e160\", \"price_changes\":[{\"asset_id\":\"14766054693214075530629349735273995982307625376442606753688071083149620216746\", \"price\":\"0.82\", \"size\":\"79.4\", \"side\":\"SELL\", \"hash\":\"c8b628de2acbdf3aea2044258ba82b15064af3a1\", \"best_bid\":\"0.73\", \"best_ask\":\"0.74\"}, {\"asset_id\":\"110216635572655435074987471276357323571387854733835379371586402147734167783946\", \"price\":\"0.18\", \"size\":\"79.4\", \"side\":\"BUY\", \"hash\":\"f97472f6d2d4abf5b92a4cbdbcb179fa14601667\", \"best_bid\":\"0.26\", \"best_ask\":\"0.27\"}], \"timestamp\":\"1785130932618\", \"event_type\":\"price_change\"}","received_at":"2026-07-27T05:42:12.576982Z","schema_version":"clob-market-ws.price_change.v1","sequence":null,"server_hash":null,"server_timestamp":"1785130932618","session_id":"502006c5cfcd437296561ea750c9ec8b","source":"clob_market_ws"},"received_at":"2026-07-27T05:42:12.576982Z","record_id":"d3ba7b99122511dab71395a17bdfdf95bcc2922375e8894595ee0c478a94269d","schema_fingerprint":"4aa3821a28b0b7c2400bc59aba4bcc0a76e971dadd19610d3ad38c768e124dc7","schema_version":"edge-lab-recorder.raw.v1","sequence":null,"source":"clob_market_ws"}
{"event_at":"2026-07-27T05:42:12.628000Z","event_fingerprint":"083d64bde8686995e6d38d00bc677d8da3f85ae56fc39cce289d96f1f635bf32","payload":{"connection_id":"efc69d3132f1467b8e898a382b23ac0d","event_at":"2026-07-27T05:42:12.628000Z","event_type":"price_change","frame_hash":"b86489cd949eb682fa4335f9a9fa7b485432afaf54db9f422fc039aaeb2ddd31","frame_index":0,"kind":"data","monotonic_ns":232915819466250,"payload":{"event_type":"price_change","market":"0x3b40066b5cf3871a2f6237c5628bd8092a206aa998558ac5ec13c4483e31e160","price_changes":[{"asset_id":"110216635572655435074987471276357323571387854733835379371586402147734167783946","best_ask":"0.27","best_bid":"0.26","hash":"b999125d8509e0fba0011610cf1bd5687207b53e","price":"0.18","side":"BUY","size":"84.4"},{"asset_id":"14766054693214075530629349735273995982307625376442606753688071083149620216746","best_ask":"0.74","best_bid":"0.73","hash":"b6fdc41853231539d4c1dad8e1dbbbb478ebf37c","price":"0.82","side":"SELL","size":"84.4"}],"timestamp":"1785130932628"},"payload_hash":"acb528938e5f1768db111e8981f256189e1e6fb52a6bbf05f197cc9362ba50c2","raw_frame":"{\"market\":\"0x3b40066b5cf3871a2f6237c5628bd8092a206aa998558ac5ec13c4483e31e160\", \"price_changes\":[{\"asset_id\":\"110216635572655435074987471276357323571387854733835379371586402147734167783946\", \"price\":\"0.18\", \"size\":\"84.4\", \"side\":\"BUY\", \"hash\":\"b999125d8509e0fba0011610cf1bd5687207b53e\", \"best_bid\":\"0.26\", \"best_ask\":\"0.27\"}, {\"asset_id\":\"14766054693214075530629349735273995982307625376442606753688071083149620216746\", \"price\":\"0.82\", \"size\":\"84.4\", \"side\":\"SELL\", \"hash\":\"b6fdc41853231539d4c1dad8e1dbbbb478ebf37c\", \"best_bid\":\"0.73\", \"best_ask\":\"0.74\"}], \"timestamp\":\"1785130932628\", \"event_type\":\"price_change\"}","received_at":"2026-07-27T05:42:12.586346Z","schema_version":"clob-market-ws.price_change.v1","sequence":null,"server_hash":null,"server_timestamp":"1785130932628","session_id":"502006c5cfcd437296561ea750c9ec8b","source":"clob_market_ws"},"received_at":"2026-07-27T05:42:12.586346Z","record_id":"d1b8881bcff89aa10840f98c1ad8b4831c861f2adfaf6b38fddcfff24df59729","schema_fingerprint":"4aa3821a28b0b7c2400bc59aba4bcc0a76e971dadd19610d3ad38c768e124dc7","schema_version":"edge-lab-recorder.raw.v1","sequence":null,"source":"clob_market_ws"}
{"event_at":"2026-07-27T05:42:12.649000Z","event_fingerprint":"c7c1bdc217231e35d76a0cec67037edab21e637cc03c0c34b3f26161fbfb8aff","payload":{"connection_id":"efc69d3132f1467b8e898a382b23ac0d","event_at":"2026-07-27T05:42:12.649000Z","event_type":"price_change","frame_hash":"d4695fa8b1e62b1c3f8786796749bd9c717c5fc65042a93d8cc597ee2de008a0","frame_index":0,"kind":"data","monotonic_ns":232915840531666,"payload":{"event_type":"price_change","market":"0x3b40066b5cf3871a2f6237c5628bd8092a206aa998558ac5ec13c4483e31e160","price_changes":[{"asset_id":"14766054693214075530629349735273995982307625376442606753688071083149620216746","best_ask":"0.74","best_bid":"0.73","hash":"24e97383e09dd00d30a183d10144a95ab2156454","price":"0.04","side":"BUY","size":"568"},{"asset_id":"110216635572655435074987471276357323571387854733835379371586402147734167783946","best_ask":"0.27","best_bid":"0.26","hash":"940f80281fda259ff9ada76c137a69b39e46de1e","price":"0.96","side":"SELL","size":"568"}],"timestamp":"1785130932649"},"payload_hash":"bce07b508e6c9f680a0d2a5b42d7b82a98da93fa4f6db6fee0d0e9661361be16","raw_frame":"{\"market\":\"0x3b40066b5cf3871a2f6237c5628bd8092a206aa998558ac5ec13c4483e31e160\", \"price_changes\":[{\"asset_id\":\"14766054693214075530629349735273995982307625376442606753688071083149620216746\", \"price\":\"0.04\", \"size\":\"568\", \"side\":\"BUY\", \"hash\":\"24e97383e09dd00d30a183d10144a95ab2156454\", \"best_bid\":\"0.73\", \"best_ask\":\"0.74\"}, {\"asset_id\":\"110216635572655435074987471276357323571387854733835379371586402147734167783946\", \"price\":\"0.96\", \"size\":\"568\", \"side\":\"SELL\", \"hash\":\"940f80281fda259ff9ada76c137a69b39e46de1e\", \"best_bid\":\"0.26\", \"best_ask\":\"0.27\"}], \"timestamp\":\"1785130932649\", \"event_type\":\"price_change\"}","received_at":"2026-07-27T05:42:12.607410Z","schema_version":"clob-market-ws.price_change.v1","sequence":null,"server_hash":null,"server_timestamp":"1785130932649","session_id":"502006c5cfcd437296561ea750c9ec8b","source":"clob_market_ws"},"received_at":"2026-07-27T05:42:12.607410Z","record_id":"7c8b9620f9c4dc534b534f685f069a3adfdc4059852200348d180c93c4489871","schema_fingerprint":"4aa3821a28b0b7c2400bc59aba4bcc0a76e971dadd19610d3ad38c768e124dc7","schema_version":"edge-lab-recorder.raw.v1","sequence":null,"source":"clob_market_ws"}
{"event_at":"2026-07-27T05:42:12.673000Z","event_fingerprint":"29f799bae406829c63fcefc7a8459dbb7e43d632a7ac077b0316458b923f4d81","payload":{"connection_id":"efc69d3132f1467b8e898a382b23ac0d","event_at":"2026-07-27T05:42:12.673000Z","event_type":"price_change","frame_hash":"080f9bceaefd72ff3d9d97250316ed1d0c8f87ba56cf88e302b38f9f01bd1ec5","frame_index":0,"kind":"data","monotonic_ns":232915864895041,"payload":{"event_type":"price_change","market":"0x3b40066b5cf3871a2f6237c5628bd8092a206aa998558ac5ec13c4483e31e160","price_changes":[{"asset_id":"14766054693214075530629349735273995982307625376442606753688071083149620216746","best_ask":"0.74","best_bid":"0.73","hash":"0297f21186ca42560bab02b439d4e8e141114308","price":"0.01","side":"BUY","size":"5335.02"},{"asset_id":"110216635572655435074987471276357323571387854733835379371586402147734167783946","best_ask":"0.27","best_bid":"0.26","hash":"19c0cfb6d80229731bc6c7e4d04e4b50616762b6","price":"0.99","side":"SELL","size":"5335.02"}],"timestamp":"1785130932673"},"payload_hash":"1229edf702914d31729e25d340065d18f18eb7ae20755453f35c1e06172c7aab","raw_frame":"{\"market\":\"0x3b40066b5cf3871a2f6237c5628bd8092a206aa998558ac5ec13c4483e31e160\", \"price_changes\":[{\"asset_id\":\"14766054693214075530629349735273995982307625376442606753688071083149620216746\", \"price\":\"0.01\", \"size\":\"5335.02\", \"side\":\"BUY\", \"hash\":\"0297f21186ca42560bab02b439d4e8e141114308\", \"best_bid\":\"0.73\", \"best_ask\":\"0.74\"}, {\"asset_id\":\"110216635572655435074987471276357323571387854733835379371586402147734167783946\", \"price\":\"0.99\", \"size\":\"5335.02\", \"side\":\"SELL\", \"hash\":\"19c0cfb6d80229731bc6c7e4d04e4b50616762b6\", \"best_bid\":\"0.26\", \"best_ask\":\"0.27\"}], \"timestamp\":\"1785130932673\", \"event_type\":\"price_change\"}","received_at":"2026-07-27T05:42:12.631773Z","schema_version":"clob-market-ws.price_change.v1","sequence":null,"server_hash":null,"server_timestamp":"1785130932673","session_id":"502006c5cfcd437296561ea750c9ec8b","source":"clob_market_ws"},"received_at":"2026-07-27T05:42:12.631773Z","record_id":"9ff66de6714376705eba4746704106bae5f5da080854b1ee13760dc39a7fa9b3","schema_fingerprint":"4aa3821a28b0b7c2400bc59aba4bcc0a76e971dadd19610d3ad38c768e124dc7","schema_version":"edge-lab-recorder.raw.v1","sequence":null,"source":"clob_market_ws"}
{"event_at":"2026-07-27T05:42:12.703000Z","event_fingerprint":"9553d285628dfd37c108f554e0db73147702c66523ea27b3e71cab0eac7fd8a2","payload":{"connection_id":"efc69d3132f1467b8e898a382b23ac0d","event_at":"2026-07-27T05:42:12.703000Z","event_type":"price_change","frame_hash":"980da57f63dc8012a6515df0180cff4d4a0f27e098430145155d4b84c3937e5e","frame_index":0,"kind":"data","monotonic_ns":232915896110833,"payload":{"event_type":"price_change","market":"0x3b40066b5cf3871a2f6237c5628bd8092a206aa998558ac5ec13c4483e31e160","price_changes":[{"asset_id":"14766054693214075530629349735273995982307625376442606753688071083149620216746","best_ask":"0.74","best_bid":"0.73","hash":"a54c6a71f220792d3148f9efb5ba44fc5238bafb","price":"0.01","side":"BUY","size":"5330.02"},{"asset_id":"110216635572655435074987471276357323571387854733835379371586402147734167783946","best_ask":"0.27","best_bid":"0.26","hash":"367df2e8646de31b1ddf9bdccf885e46905cd86b","price":"0.99","side":"SELL","size":"5330.02"}],"timestamp":"1785130932703"},"payload_hash":"059060d68418ae9fd65a53fe884f7cd6f4029d9b1f7b675d3e9ce5d70dfc61ab","raw_frame":"{\"market\":\"0x3b40066b5cf3871a2f6237c5628bd8092a206aa998558ac5ec13c4483e31e160\", \"price_changes\":[{\"asset_id\":\"14766054693214075530629349735273995982307625376442606753688071083149620216746\", \"price\":\"0.01\", \"size\":\"5330.02\", \"side\":\"BUY\", \"hash\":\"a54c6a71f220792d3148f9efb5ba44fc5238bafb\", \"best_bid\":\"0.73\", \"best_ask\":\"0.74\"}, {\"asset_id\":\"110216635572655435074987471276357323571387854733835379371586402147734167783946\", \"price\":\"0.99\", \"size\":\"5330.02\", \"side\":\"SELL\", \"hash\":\"367df2e8646de31b1ddf9bdccf885e46905cd86b\", \"best_bid\":\"0.26\", \"best_ask\":\"0.27\"}], \"timestamp\":\"1785130932703\", \"event_type\":\"price_change\"}","received_at":"2026-07-27T05:42:12.662989Z","schema_version":"clob-market-ws.price_change.v1","sequence":null,"server_hash":null,"server_timestamp":"1785130932703","session_id":"502006c5cfcd437296561ea750c9ec8b","source":"clob_market_ws"},"received_at":"2026-07-27T05:42:12.662989Z","record_id":"10bb1887a806a401a43d26effa64627603afb86e367e38fc4fc4cf7327c01b93","schema_fingerprint":"4aa3821a28b0b7c2400bc59aba4bcc0a76e971dadd19610d3ad38c768e124dc7","schema_version":"edge-lab-recorder.raw.v1","sequence":null,"source":"clob_market_ws"}
{"event_at":"2026-07-27T05:42:12.713000Z","event_fingerprint":"f9c614a599b5f6cd5d3593c1fb7cf89940b83363b5075ad71380e208bb4551ce","payload":{"connection_id":"efc69d3132f1467b8e898a382b23ac0d","event_at":"2026-07-27T05:42:12.713000Z","event_type":"price_change","frame_hash":"9ff790b26de9ed20fcea5e02cdb564a2602ec0bd0579daed9f77c2564f39c5de","frame_index":0,"kind":"data","monotonic_ns":232915904527750,"payload":{"event_type":"price_change","market":"0x3b40066b5cf3871a2f6237c5628bd8092a206aa998558ac5ec13c4483e31e160","price_changes":[{"asset_id":"14766054693214075530629349735273995982307625376442606753688071083149620216746","best_ask":"0.74","best_bid":"0.73","hash":"da8af50d8bd5802ea7ff1a6aaa5f6f91c9b5924d","price":"0.04","side":"BUY","size":"563"},{"asset_id":"110216635572655435074987471276357323571387854733835379371586402147734167783946","best_ask":"0.27","best_bid":"0.26","hash":"3f32d3e2a6bbee6489abd255e80edb0421f5f256","price":"0.96","side":"SELL","size":"563"}],"timestamp":"1785130932713"},"payload_hash":"c27a5daf9829a763b68efe9ec316a55705e3897cc470176a92858a861e5aa8a4","raw_frame":"{\"market\":\"0x3b40066b5cf3871a2f6237c5628bd8092a206aa998558ac5ec13c4483e31e160\", \"price_changes\":[{\"asset_id\":\"14766054693214075530629349735273995982307625376442606753688071083149620216746\", \"price\":\"0.04\", \"size\":\"563\", \"side\":\"BUY\", \"hash\":\"da8af50d8bd5802ea7ff1a6aaa5f6f91c9b5924d\", \"best_bid\":\"0.73\", \"best_ask\":\"0.74\"}, {\"asset_id\":\"110216635572655435074987471276357323571387854733835379371586402147734167783946\", \"price\":\"0.96\", \"size\":\"563\", \"side\":\"SELL\", \"hash\":\"3f32d3e2a6bbee6489abd255e80edb0421f5f256\", \"best_bid\":\"0.26\", \"best_ask\":\"0.27\"}], \"timestamp\":\"1785130932713\", \"event_type\":\"price_change\"}","received_at":"2026-07-27T05:42:12.671406Z","schema_version":"clob-market-ws.price_change.v1","sequence":null,"server_hash":null,"server_timestamp":"1785130932713","session_id":"502006c5cfcd437296561ea750c9ec8b","source":"clob_market_ws"},"received_at":"2026-07-27T05:42:12.671406Z","record_id":"dbf9d8e860ae2b24b33f574078a7d7213eb118becb96621506c63bbe258ade39","schema_fingerprint":"4aa3821a28b0b7c2400bc59aba4bcc0a76e971dadd19610d3ad38c768e124dc7","schema_version":"edge-lab-recorder.raw.v1","sequence":null,"source":"clob_market_ws"}
{"event_at":"2026-07-27T05:42:12.727000Z","event_fingerprint":"011b1cd51afbf5d0a0c676030f7b7d9f1b100126517519f6c27e05e49f6bb558","payload":{"connection_id":"efc69d3132f1467b8e898a382b23ac0d","event_at":"2026-07-27T05:42:12.727000Z","event_type":"price_change","frame_hash":"2cf20f26e006f8672e61a695a2f222a2f1587c0454e7b03bb4f8bfe5e787fb48","frame_index":0,"kind":"data","monotonic_ns":232915918593500,"payload":{"event_type":"price_change","market":"0x3b40066b5cf3871a2f6237c5628bd8092a206aa998558ac5ec13c4483e31e160","price_changes":[{"asset_id":"110216635572655435074987471276357323571387854733835379371586402147734167783946","best_ask":"0.27","best_bid":"0.26","hash":"2ea61bef8453198c9de5fb10091793f3632105dd","price":"0.18","side":"BUY","size":"79.4"},{"asset_id":"14766054693214075530629349735273995982307625376442606753688071083149620216746","best_ask":"0.74","best_bid":"0.73","hash":"8d828aae1ef40f9ae61b7d0abd12ce036da8b90f","price":"0.82","side":"SELL","size":"79.4"}],"timestamp":"1785130932727"},"payload_hash":"1ee7e443112e3f114ef65934ca5663bc4353f03cf28740d7bb4533b4872c1658","raw_frame":"{\"market\":\"0x3b40066b5cf3871a2f6237c5628bd8092a206aa998558ac5ec13c4483e31e160\", \"price_changes\":[{\"asset_id\":\"110216635572655435074987471276357323571387854733835379371586402147734167783946\", \"price\":\"0.18\", \"size\":\"79.4\", \"side\":\"BUY\", \"hash\":\"2ea61bef8453198c9de5fb10091793f3632105dd\", \"best_bid\":\"0.26\", \"best_ask\":\"0.27\"}, {\"asset_id\":\"14766054693214075530629349735273995982307625376442606753688071083149620216746\", \"price\":\"0.82\", \"size\":\"79.4\", \"side\":\"SELL\", \"hash\":\"8d828aae1ef40f9ae61b7d0abd12ce036da8b90f\", \"best_bid\":\"0.73\", \"best_ask\":\"0.74\"}], \"timestamp\":\"1785130932727\", \"event_type\":\"price_change\"}","received_at":"2026-07-27T05:42:12.685474Z","schema_version":"clob-market-ws.price_change.v1","sequence":null,"server_hash":null,"server_timestamp":"1785130932727","session_id":"502006c5cfcd437296561ea750c9ec8b","source":"clob_market_ws"},"received_at":"2026-07-27T05:42:12.685474Z","record_id":"947fc8d7e69f6de11a5581fb1c3734aa937d81a33efa25121d03a13f633280e1","schema_fingerprint":"4aa3821a28b0b7c2400bc59aba4bcc0a76e971dadd19610d3ad38c768e124dc7","schema_version":"edge-lab-recorder.raw.v1","sequence":null,"source":"clob_market_ws"}
{"event_at":"2026-07-27T05:42:12.732000Z","event_fingerprint":"22a8561dc4c82a9e91bb815a2d67050be09e30266d1e2615fa480c3f57c0c0f8","payload":{"connection_id":"efc69d3132f1467b8e898a382b23ac0d","event_at":"2026-07-27T05:42:12.732000Z","event_type":"price_change","frame_hash":"1b1ac69f8fc32f269325783280e7f4eae47d23b892352fecf2dad78e57d9b6c1","frame_index":0,"kind":"data","monotonic_ns":232915927394458,"payload":{"event_type":"price_change","market":"0x3b40066b5cf3871a2f6237c5628bd8092a206aa998558ac5ec13c4483e31e160","price_changes":[{"asset_id":"14766054693214075530629349735273995982307625376442606753688071083149620216746","best_ask":"0.74","best_bid":"0.73","hash":"940c4e1160ee5f01f9b0f5e91a42e6e8cb88fd60","price":"0.82","side":"SELL","size":"84.4"},{"asset_id":"110216635572655435074987471276357323571387854733835379371586402147734167783946","best_ask":"0.27","best_bid":"0.26","hash":"04314dc1df0de631113f2a055d3e7ee376ef0f68","price":"0.18","side":"BUY","size":"84.4"}],"timestamp":"1785130932732"},"payload_hash":"5938d4df76e1e2885e686f1b71bbc92b58d79b80b67f05a1bd4523369efbb1ea","raw_frame":"{\"market\":\"0x3b40066b5cf3871a2f6237c5628bd8092a206aa998558ac5ec13c4483e31e160\", \"price_changes\":[{\"asset_id\":\"14766054693214075530629349735273995982307625376442606753688071083149620216746\", \"price\":\"0.82\", \"size\":\"84.4\", \"side\":\"SELL\", \"hash\":\"940c4e1160ee5f01f9b0f5e91a42e6e8cb88fd60\", \"best_bid\":\"0.73\", \"best_ask\":\"0.74\"}, {\"asset_id\":\"110216635572655435074987471276357323571387854733835379371586402147734167783946\", \"price\":\"0.18\", \"size\":\"84.4\", \"side\":\"BUY\", \"hash\":\"04314dc1df0de631113f2a055d3e7ee376ef0f68\", \"best_bid\":\"0.26\", \"best_ask\":\"0.27\"}], \"timestamp\":\"1785130932732\", \"event_type\":\"price_change\"}","received_at":"2026-07-27T05:42:12.694269Z","schema_version":"clob-market-ws.price_change.v1","sequence":null,"server_hash":null,"server_timestamp":"1785130932732","session_id":"502006c5cfcd437296561ea750c9ec8b","source":"clob_market_ws"},"received_at":"2026-07-27T05:42:12.694269Z","record_id":"e36c6d5577448cd14320aaffa3ddb39ee36ba8b6405acbc4aa2baf4f5458f3db","schema_fingerprint":"4aa3821a28b0b7c2400bc59aba4bcc0a76e971dadd19610d3ad38c768e124dc7","schema_version":"edge-lab-recorder.raw.v1","sequence":null,"source":"clob_market_ws"}
{"event_at":"2026-07-27T05:42:12.845000Z","event_fingerprint":"04b1eced89127291f8ee391e5a2a88e12cd89b4f950ec7b8a2376f3788d0dfa6","payload":{"connection_id":"efc69d3132f1467b8e898a382b23ac0d","event_at":"2026-07-27T05:42:12.845000Z","event_type":"price_change","frame_hash":"8530ca3f4c91c21a20ca9983878aeb8a526ffd33910949adf129304abc821772","frame_index":0,"kind":"data","monotonic_ns":232916036680958,"payload":{"event_type":"price_change","market":"0x3b40066b5cf3871a2f6237c5628bd8092a206aa998558ac5ec13c4483e31e160","price_changes":[{"asset_id":"14766054693214075530629349735273995982307625376442606753688071083149620216746","best_ask":"0.74","best_bid":"0.73","hash":"98e2d14d8360a9b269769a7dd64c1f081dfcae84","price":"0.52","side":"BUY","size":"68"},{"asset_id":"110216635572655435074987471276357323571387854733835379371586402147734167783946","best_ask":"0.27","best_bid":"0.26","hash":"756634485ce5017dc1b899f3e6a0a5dca3f280fa","price":"0.48","side":"SELL","size":"68"}],"timestamp":"1785130932845"},"payload_hash":"b5b5e24904eb3ced0dd48e5c381a84c81fda9ea4097e9fb04a6e41df4c7de645","raw_frame":"{\"market\":\"0x3b40066b5cf3871a2f6237c5628bd8092a206aa998558ac5ec13c4483e31e160\", \"price_changes\":[{\"asset_id\":\"14766054693214075530629349735273995982307625376442606753688071083149620216746\", \"price\":\"0.52\", \"size\":\"68\", \"side\":\"BUY\", \"hash\":\"98e2d14d8360a9b269769a7dd64c1f081dfcae84\", \"best_bid\":\"0.73\", \"best_ask\":\"0.74\"}, {\"asset_id\":\"110216635572655435074987471276357323571387854733835379371586402147734167783946\", \"price\":\"0.48\", \"size\":\"68\", \"side\":\"SELL\", \"hash\":\"756634485ce5017dc1b899f3e6a0a5dca3f280fa\", \"best_bid\":\"0.26\", \"best_ask\":\"0.27\"}], \"timestamp\":\"1785130932845\", \"event_type\":\"price_change\"}","received_at":"2026-07-27T05:42:12.803557Z","schema_version":"clob-market-ws.price_change.v1","sequence":null,"server_hash":null,"server_timestamp":"1785130932845","session_id":"502006c5cfcd437296561ea750c9ec8b","source":"clob_market_ws"},"received_at":"2026-07-27T05:42:12.803557Z","record_id":"27994f1eb9c025532be779ad2033740fe6e59c04d7bc4e664e431e966faf6533","schema_fingerprint":"4aa3821a28b0b7c2400bc59aba4bcc0a76e971dadd19610d3ad38c768e124dc7","schema_version":"edge-lab-recorder.raw.v1","sequence":null,"source":"clob_market_ws"}
{"event_at":"2026-07-27T05:42:12.847000Z","event_fingerprint":"997387c78f4b5c1aec9872ba6919d36c8237f28306934dc6fda620e1757ae01e","payload":{"connection_id":"efc69d3132f1467b8e898a382b23ac0d","event_at":"2026-07-27T05:42:12.847000Z","event_type":"price_change","frame_hash":"8fd078139563933d773db87c4f0a806a0e83400070b8ddb947e22c03478cdb08","frame_index":0,"kind":"data","monotonic_ns":232916038840250,"payload":{"event_type":"price_change","market":"0x3b40066b5cf3871a2f6237c5628bd8092a206aa998558ac5ec13c4483e31e160","price_changes":[{"asset_id":"110216635572655435074987471276357323571387854733835379371586402147734167783946","best_ask":"0.27","best_bid":"0.26","hash":"7c7e60cb5eecb4a688f4fcc7843c7c17d0aca47d","price":"0.1","side":"BUY","size":"102"},{"asset_id":"14766054693214075530629349735273995982307625376442606753688071083149620216746","best_ask":"0.74","best_bid":"0.73","hash":"596741078d32ee87bc8bb28a4693e65c1a6cf002","price":"0.9","side":"SELL","size":"102"}],"timestamp":"1785130932847"},"payload_hash":"6a39a5a501426f7e5ef9d33abb996ae148d2acc2d0368c2e95d7223d7bfbf794","raw_frame":"{\"market\":\"0x3b40066b5cf3871a2f6237c5628bd8092a206aa998558ac5ec13c4483e31e160\", \"price_changes\":[{\"asset_id\":\"110216635572655435074987471276357323571387854733835379371586402147734167783946\", \"price\":\"0.1\", \"size\":\"102\", \"side\":\"BUY\", \"hash\":\"7c7e60cb5eecb4a688f4fcc7843c7c17d0aca47d\", \"best_bid\":\"0.26\", \"best_ask\":\"0.27\"}, {\"asset_id\":\"14766054693214075530629349735273995982307625376442606753688071083149620216746\", \"price\":\"0.9\", \"size\":\"102\", \"side\":\"SELL\", \"hash\":\"596741078d32ee87bc8bb28a4693e65c1a6cf002\", \"best_bid\":\"0.73\", \"best_ask\":\"0.74\"}], \"timestamp\":\"1785130932847\", \"event_type\":\"price_change\"}","received_at":"2026-07-27T05:42:12.805720Z","schema_version":"clob-market-ws.price_change.v1","sequence":null,"server_hash":null,"server_timestamp":"1785130932847","session_id":"502006c5cfcd437296561ea750c9ec8b","source":"clob_market_ws"},"received_at":"2026-07-27T05:42:12.805720Z","record_id":"1596f07081096f3e16c5305f90fac8d8bd856c0152ca4ed30356195bb4aa895c","schema_fingerprint":"4aa3821a28b0b7c2400bc59aba4bcc0a76e971dadd19610d3ad38c768e124dc7","schema_version":"edge-lab-recorder.raw.v1","sequence":null,"source":"clob_market_ws"}
{"event_at":"2026-07-27T05:42:12.852000Z","event_fingerprint":"3f097bb99997d215f4af91b3624267d49cebb3f80996d642d114292056b66daa","payload":{"connection_id":"efc69d3132f1467b8e898a382b23ac0d","event_at":"2026-07-27T05:42:12.852000Z","event_type":"price_change","frame_hash":"e482b286e901bf2f405b2b248909a951435870c658feeec0649f23ac75414dce","frame_index":0,"kind":"data","monotonic_ns":232916043650125,"payload":{"event_type":"price_change","market":"0x3b40066b5cf3871a2f6237c5628bd8092a206aa998558ac5ec13c4483e31e160","price_changes":[{"asset_id":"14766054693214075530629349735273995982307625376442606753688071083149620216746","best_ask":"0.74","best_bid":"0.73","hash":"f17227f238219213d9fc532728031861c6ee578d","price":"0.01","side":"BUY","size":"5335.02"},{"asset_id":"110216635572655435074987471276357323571387854733835379371586402147734167783946","best_ask":"0.27","best_bid":"0.26","hash":"e38b905f15bc7163d05e1a77ede4183aa17134d8","price":"0.99","side":"SELL","size":"5335.02"}],"timestamp":"1785130932852"},"payload_hash":"52633a4c07ea42057cc33374f74b63b73a968d2bcf50d81401b54f9276fdc7b5","raw_frame":"{\"market\":\"0x3b40066b5cf3871a2f6237c5628bd8092a206aa998558ac5ec13c4483e31e160\", \"price_changes\":[{\"asset_id\":\"14766054693214075530629349735273995982307625376442606753688071083149620216746\", \"price\":\"0.01\", \"size\":\"5335.02\", \"side\":\"BUY\", \"hash\":\"f17227f238219213d9fc532728031861c6ee578d\", \"best_bid\":\"0.73\", \"best_ask\":\"0.74\"}, {\"asset_id\":\"110216635572655435074987471276357323571387854733835379371586402147734167783946\", \"price\":\"0.99\", \"size\":\"5335.02\", \"side\":\"SELL\", \"hash\":\"e38b905f15bc7163d05e1a77ede4183aa17134d8\", \"best_bid\":\"0.26\", \"best_ask\":\"0.27\"}], \"timestamp\":\"1785130932852\", \"event_type\":\"price_change\"}","received_at":"2026-07-27T05:42:12.810528Z","schema_version":"clob-market-ws.price_change.v1","sequence":null,"server_hash":null,"server_timestamp":"1785130932852","session_id":"502006c5cfcd437296561ea750c9ec8b","source":"clob_market_ws"},"received_at":"2026-07-27T05:42:12.810528Z","record_id":"554444e1d24eac71b08a7c4a7dbea3686838b52c77b77d5a48c61c93ec1200f7","schema_fingerprint":"4aa3821a28b0b7c2400bc59aba4bcc0a76e971dadd19610d3ad38c768e124dc7","schema_version":"edge-lab-recorder.raw.v1","sequence":null,"source":"clob_market_ws"}
