{"event_at":"2026-07-27T05:35:17.182000Z","event_fingerprint":"b0358b3889a80546dc717cd3332ba0b3851640eb3b08c514b265c37ef805a3bb","payload":{"connection_id":"efc69d3132f1467b8e898a382b23ac0d","event_at":"2026-07-27T05:35:17.182000Z","event_type":"price_change","frame_hash":"0748f752543251a25309a47d5597d7429ba9907986fe9f016dfdc905a792d7b4","frame_index":0,"kind":"data","monotonic_ns":232501570147375,"payload":{"event_type":"price_change","market":"0x3b40066b5cf3871a2f6237c5628bd8092a206aa998558ac5ec13c4483e31e160","price_changes":[{"asset_id":"110216635572655435074987471276357323571387854733835379371586402147734167783946","best_ask":"0.6","best_bid":"0.59","hash":"8b9bfbe02b4bf16e479057280282e732640d1a28","price":"0.54","side":"BUY","size":"186.04"},{"asset_id":"14766054693214075530629349735273995982307625376442606753688071083149620216746","best_ask":"0.41","best_bid":"0.4","hash":"e24ed8e0aca25143492b0cb142b39ffbff00b1e0","price":"0.46","side":"SELL","size":"186.04"}],"timestamp":"1785130517182"},"payload_hash":"451d4abc91152bbb4d4e089a2f175b96b0bce94ddfe73150d683f575a56e3e15","raw_frame":"{\"market\":\"0x3b40066b5cf3871a2f6237c5628bd8092a206aa998558ac5ec13c4483e31e160\", \"price_changes\":[{\"asset_id\":\"110216635572655435074987471276357323571387854733835379371586402147734167783946\", \"price\":\"0.54\", \"size\":\"186.04\", \"side\":\"BUY\", \"hash\":\"8b9bfbe02b4bf16e479057280282e732640d1a28\", \"best_bid\":\"0.59\", \"best_ask\":\"0.6\"}, {\"asset_id\":\"14766054693214075530629349735273995982307625376442606753688071083149620216746\", \"price\":\"0.46\", \"size\":\"186.04\", \"side\":\"SELL\", \"hash\":\"e24ed8e0aca25143492b0cb142b39ffbff00b1e0\", \"best_bid\":\"0.4\", \"best_ask\":\"0.41\"}], \"timestamp\":\"1785130517182\", \"event_type\":\"price_change\"}","received_at":"2026-07-27T05:35:18.334151Z","schema_version":"clob-market-ws.price_change.v1","sequence":null,"server_hash":null,"server_timestamp":"1785130517182","session_id":"502006c5cfcd437296561ea750c9ec8b","source":"clob_market_ws"},"received_at":"2026-07-27T05:35:18.334151Z","record_id":"b12184d0f32d2ad9a3ba1cf599292228ed787b4a662b6e77b3f1c2b923a26025","schema_fingerprint":"4aa3821a28b0b7c2400bc59aba4bcc0a76e971dadd19610d3ad38c768e124dc7","schema_version":"edge-lab-recorder.raw.v1","sequence":null,"source":"clob_market_ws"}
{"event_at":"2026-07-27T05:35:17.184000Z","event_fingerprint":"d538518dfd46927f13028a0046ec5a2dc511221a9b3fc5f62a8f385bbd8780cc","payload":{"connection_id":"efc69d3132f1467b8e898a382b23ac0d","event_at":"2026-07-27T05:35:17.184000Z","event_type":"price_change","frame_hash":"012f8512823f8c21f0143786c53024b74811ce2796e7bfc50b85097def6fa44e","frame_index":0,"kind":"data","monotonic_ns":232501591908541,"payload":{"event_type":"price_change","market":"0x3b40066b5cf3871a2f6237c5628bd8092a206aa998558ac5ec13c4483e31e160","price_changes":[{"asset_id":"14766054693214075530629349735273995982307625376442606753688071083149620216746","best_ask":"0.41","best_bid":"0.4","hash":"b447c048690d64c00adb210498ab8d0fd1d320ba","price":"0.4","side":"BUY","size":"54"},{"asset_id":"110216635572655435074987471276357323571387854733835379371586402147734167783946","best_ask":"0.6","best_bid":"0.59","hash":"390018a16c8799b556fe428b02be4c4956fb92db","price":"0.6","side":"SELL","size":"54"}],"timestamp":"1785130517184"},"payload_hash":"e405180686977bfe21e9c6909fe23cb4992bf1a46ee771d4e736dd1bdb489580","raw_frame":"{\"market\":\"0x3b40066b5cf3871a2f6237c5628bd8092a206aa998558ac5ec13c4483e31e160\", \"price_changes\":[{\"asset_id\":\"14766054693214075530629349735273995982307625376442606753688071083149620216746\", \"price\":\"0.4\", \"size\":\"54\", \"side\":\"BUY\", \"hash\":\"b447c048690d64c00adb210498ab8d0fd1d320ba\", \"best_bid\":\"0.4\", \"best_ask\":\"0.41\"}, {\"asset_id\":\"110216635572655435074987471276357323571387854733835379371586402147734167783946\", \"price\":\"0.6\", \"size\":\"54\", \"side\":\"SELL\", \"hash\":\"390018a16c8799b556fe428b02be4c4956fb92db\", \"best_bid\":\"0.59\", \"best_ask\":\"0.6\"}], \"timestamp\":\"1785130517184\", \"event_type\":\"price_change\"}","received_at":"2026-07-27T05:35:18.355905Z","schema_version":"clob-market-ws.price_change.v1","sequence":null,"server_hash":null,"server_timestamp":"1785130517184","session_id":"502006c5cfcd437296561ea750c9ec8b","source":"clob_market_ws"},"received_at":"2026-07-27T05:35:18.355905Z","record_id":"5eeba06ed10dca2c08810ee8d0be443393028affd2bef0f0e035713856c62a4a","schema_fingerprint":"4aa3821a28b0b7c2400bc59aba4bcc0a76e971dadd19610d3ad38c768e124dc7","schema_version":"edge-lab-recorder.raw.v1","sequence":null,"source":"clob_market_ws"}
{"event_at":"2026-07-27T05:35:17.189000Z","event_fingerprint":"68f5b653702cc3a5b1d01596638bce8aec93dac9519480e6bfe20c47c9fe07f8","payload":{"connection_id":"efc69d3132f1467b8e898a382b23ac0d","event_at":"2026-07-27T05:35:17.189000Z","event_type":"price_change","frame_hash":"6808daf36162f54f33e7ad626f2a3221ba7af0a40b7cfdce5f204df22da3fd6b","frame_index":0,"kind":"data","monotonic_ns":232501600551666,"payload":{"event_type":"price_change","market":"0x3b40066b5cf3871a2f6237c5628bd8092a206aa998558ac5ec13c4483e31e160","price_changes":[{"asset_id":"14766054693214075530629349735273995982307625376442606753688071083149620216746","best_ask":"0.41","best_bid":"0.4","hash":"e9f4ba3bf0b0afa45fa0990d07fd12441893cd0c","price":"0.38","side":"BUY","size":"170.4"},{"asset_id":"110216635572655435074987471276357323571387854733835379371586402147734167783946","best_ask":"0.6","best_bid":"0.59","hash":"726f12dcac2e22b84428a7338e724e4c764e06d0","price":"0.62","side":"SELL","size":"170.4"}],"timestamp":"1785130517189"},"payload_hash":"48d13c4a27756a8544ef258e63f1f8ebf315a370dfb317874a84ab75a7134f57","raw_frame":"{\"market\":\"0x3b40066b5cf3871a2f6237c5628bd8092a206aa998558ac5ec13c4483e31e160\", \"price_changes\":[{\"asset_id\":\"14766054693214075530629349735273995982307625376442606753688071083149620216746\", \"price\":\"0.38\", \"size\":\"170.4\", \"side\":\"BUY\", \"hash\":\"e9f4ba3bf0b0afa45fa0990d07fd12441893cd0c\", \"best_bid\":\"0.4\", \"best_ask\":\"0.41\"}, {\"asset_id\":\"110216635572655435074987471276357323571387854733835379371586402147734167783946\", \"price\":\"0.62\", \"size\":\"170.4\", \"side\":\"SELL\", \"hash\":\"726f12dcac2e22b84428a7338e724e4c764e06d0\", \"best_bid\":\"0.59\", \"best_ask\":\"0.6\"}], \"timestamp\":\"1785130517189\", \"event_type\":\"price_change\"}","received_at":"2026-07-27T05:35:18.364559Z","schema_version":"clob-market-ws.price_change.v1","sequence":null,"server_hash":null,"server_timestamp":"1785130517189","session_id":"502006c5cfcd437296561ea750c9ec8b","source":"clob_market_ws"},"received_at":"2026-07-27T05:35:18.364559Z","record_id":"0af8fc7ff31ba835fc76e533a850a3ad5753d103cc8b4575b279e262c35459e1","schema_fingerprint":"4aa3821a28b0b7c2400bc59aba4bcc0a76e971dadd19610d3ad38c768e124dc7","schema_version":"edge-lab-recorder.raw.v1","sequence":null,"source":"clob_market_ws"}
{"event_at":"2026-07-27T05:35:17.190000Z","event_fingerprint":"3f345311ebf817b4bfa59560a65d2eed22806c4afb6777e85abd64ef27820610","payload":{"connection_id":"efc69d3132f1467b8e898a382b23ac0d","event_at":"2026-07-27T05:35:17.190000Z","event_type":"price_change","frame_hash":"1a167a0a34c6e5bc754846ebfcd1fda97bcdc5da1a0086c952b64f08c0e1bf83","frame_index":0,"kind":"data","monotonic_ns":232501611905791,"payload":{"event_type":"price_change","market":"0x3b40066b5cf3871a2f6237c5628bd8092a206aa998558ac5ec13c4483e31e160","price_changes":[{"asset_id":"110216635572655435074987471276357323571387854733835379371586402147734167783946","best_ask":"0.6","best_bid":"0.59","hash":"499e27a0ee61c70ff94df2cfa9e3c4a94de07976","price":"0.6","side":"SELL","size":"59"},{"asset_id":"14766054693214075530629349735273995982307625376442606753688071083149620216746","best_ask":"0.41","best_bid":"0.4","hash":"c1dfc2f9859946bf568841a907d44802df40286a","price":"0.4","side":"BUY","size":"59"}],"timestamp":"1785130517190"},"payload_hash":"fdc24e3027102d0bf9703eb87a634ee7cd725a9a0e6fc49e7d8098cdb222d138","raw_frame":"{\"market\":\"0x3b40066b5cf3871a2f6237c5628bd8092a206aa998558ac5ec13c4483e31e160\", \"price_changes\":[{\"asset_id\":\"110216635572655435074987471276357323571387854733835379371586402147734167783946\", \"price\":\"0.6\", \"size\":\"59\", \"side\":\"SELL\", \"hash\":\"499e27a0ee61c70ff94df2cfa9e3c4a94de07976\", \"best_bid\":\"0.59\", \"best_ask\":\"0.6\"}, {\"asset_id\":\"14766054693214075530629349735273995982307625376442606753688071083149620216746\", \"price\":\"0.4\", \"size\":\"59\", \"side\":\"BUY\", \"hash\":\"c1dfc2f9859946bf568841a907d44802df40286a\", \"best_bid\":\"0.4\", \"best_ask\":\"0.41\"}], \"timestamp\":\"1785130517190\", \"event_type\":\"price_change\"}","received_at":"2026-07-27T05:35:18.375907Z","schema_version":"clob-market-ws.price_change.v1","sequence":null,"server_hash":null,"server_timestamp":"1785130517190","session_id":"502006c5cfcd437296561ea750c9ec8b","source":"clob_market_ws"},"received_at":"2026-07-27T05:35:18.375907Z","record_id":"d9d332fc787b69c42f5e3abd5872b1e2991be2888fdf6125ab608ab28c926135","schema_fingerprint":"4aa3821a28b0b7c2400bc59aba4bcc0a76e971dadd19610d3ad38c768e124dc7","schema_version":"edge-lab-recorder.raw.v1","sequence":null,"source":"clob_market_ws"}
{"event_at":"2026-07-27T05:35:17.191000Z","event_fingerprint":"44b4e496861aacec7df1fcbdcda61c8e1f6a8378f22a185724997d5ec3a47ed0","payload":{"connection_id":"efc69d3132f1467b8e898a382b23ac0d","event_at":"2026-07-27T05:35:17.191000Z","event_type":"price_change","frame_hash":"6fcd4f31fa10c4ed8494c6f7436b61bf4c1c91e47f124c3c07680b12fca3f904","frame_index":0,"kind":"data","monotonic_ns":232501619890083,"payload":{"event_type":"price_change","market":"0x3b40066b5cf3871a2f6237c5628bd8092a206aa998558ac5ec13c4483e31e160","price_changes":[{"asset_id":"14766054693214075530629349735273995982307625376442606753688071083149620216746","best_ask":"0.41","best_bid":"0.4","hash":"e63bce6ce1f32989302b4919a3d8ec88e4271eeb","price":"0.37","side":"BUY","size":"329.4"},{"asset_id":"110216635572655435074987471276357323571387854733835379371586402147734167783946","best_ask":"0.6","best_bid":"0.59","hash":"0681e5209d3801ad2792622d3e530047d64efa41","price":"0.63","side":"SELL","size":"329.4"}],"timestamp":"1785130517191"},"payload_hash":"206fd3324f35ca007cfaf7250ddca6ae7dab9b5d3155234f412254438e484c7a","raw_frame":"{\"market\":\"0x3b40066b5cf3871a2f6237c5628bd8092a206aa998558ac5ec13c4483e31e160\", \"price_changes\":[{\"asset_id\":\"14766054693214075530629349735273995982307625376442606753688071083149620216746\", \"price\":\"0.37\", \"size\":\"329.4\", \"side\":\"BUY\", \"hash\":\"e63bce6ce1f32989302b4919a3d8ec88e4271eeb\", \"best_bid\":\"0.4\", \"best_ask\":\"0.41\"}, {\"asset_id\":\"110216635572655435074987471276357323571387854733835379371586402147734167783946\", \"price\":\"0.63\", \"size\":\"329.4\", \"side\":\"SELL\", \"hash\":\"0681e5209d3801ad2792622d3e530047d64efa41\", \"best_bid\":\"0.59\", \"best_ask\":\"0.6\"}], \"timestamp\":\"1785130517191\", \"event_type\":\"price_change\"}","received_at":"2026-07-27T05:35:18.383893Z","schema_version":"clob-market-ws.price_change.v1","sequence":null,"server_hash":null,"server_timestamp":"1785130517191","session_id":"502006c5cfcd437296561ea750c9ec8b","source":"clob_market_ws"},"received_at":"2026-07-27T05:35:18.383893Z","record_id":"0ce40c332cec92724e954da740fdbb9beaff62bc7db4d6de4582cc6bf9427878","schema_fingerprint":"4aa3821a28b0b7c2400bc59aba4bcc0a76e971dadd19610d3ad38c768e124dc7","schema_version":"edge-lab-recorder.raw.v1","sequence":null,"source":"clob_market_ws"}
{"event_at":"2026-07-27T05:35:17.193000Z","event_fingerprint":"f2cea2dfd1359e11f730488fd3e50700b69cc09ace628dbe0c3b688efe303772","payload":{"connection_id":"efc69d3132f1467b8e898a382b23ac0d","event_at":"2026-07-27T05:35:17.193000Z","event_type":"price_change","frame_hash":"c3a74723032bf0c2d87a216f54a9df55b95934962e6b6a22bf35e0a9a5e5e7ae","frame_index":0,"kind":"data","monotonic_ns":232501629126416,"payload":{"event_type":"price_change","market":"0x3b40066b5cf3871a2f6237c5628bd8092a206aa998558ac5ec13c4483e31e160","price_changes":[{"asset_id":"14766054693214075530629349735273995982307625376442606753688071083149620216746","best_ask":"0.41","best_bid":"0.4","hash":"5ac68e90d31c7af111310c6e382b712d46516119","price":"0.34","side":"BUY","size":"108"},{"asset_id":"110216635572655435074987471276357323571387854733835379371586402147734167783946","best_ask":"0.6","best_bid":"0.59","hash":"43c7305f655bd988534eef88e9e833417d72f8df","price":"0.66","side":"SELL","size":"108"}],"timestamp":"1785130517193"},"payload_hash":"27ad3f61d4cd661ed2708534e2a1034a51e6a902ab72aaef4b5c22d2af1adce3","raw_frame":"{\"market\":\"0x3b40066b5cf3871a2f6237c5628bd8092a206aa998558ac5ec13c4483e31e160\", \"price_changes\":[{\"asset_id\":\"14766054693214075530629349735273995982307625376442606753688071083149620216746\", \"price\":\"0.34\", \"size\":\"108\", \"side\":\"BUY\", \"hash\":\"5ac68e90d31c7af111310c6e382b712d46516119\", \"best_bid\":\"0.4\", \"best_ask\":\"0.41\"}, {\"asset_id\":\"110216635572655435074987471276357323571387854733835379371586402147734167783946\", \"price\":\"0.66\", \"size\":\"108\", \"side\":\"SELL\", \"hash\":\"43c7305f655bd988534eef88e9e833417d72f8df\", \"best_bid\":\"0.59\", \"best_ask\":\"0.6\"}], \"timestamp\":\"1785130517193\", \"event_type\":\"price_change\"}","received_at":"2026-07-27T05:35:18.393130Z","schema_version":"clob-market-ws.price_change.v1","sequence":null,"server_hash":null,"server_timestamp":"1785130517193","session_id":"502006c5cfcd437296561ea750c9ec8b","source":"clob_market_ws"},"received_at":"2026-07-27T05:35:18.393130Z","record_id":"8bbe841e3fe266757b05a9ccab199e49deaa2e22d8b448d71be8cf159f57833c","schema_fingerprint":"4aa3821a28b0b7c2400bc59aba4bcc0a76e971dadd19610d3ad38c768e124dc7","schema_version":"edge-lab-recorder.raw.v1","sequence":null,"source":"clob_market_ws"}
{"event_at":"2026-07-27T05:35:17.193000Z","event_fingerprint":"c05c19ca205f8e8b07d3b5bfb15a34f2daa41ccd187ba9ae7649b04dab23ab6b","payload":{"connection_id":"efc69d3132f1467b8e898a382b23ac0d","event_at":"2026-07-27T05:35:17.193000Z","event_type":"price_change","frame_hash":"0d107986ef4a1da8e272c584d6f3218df5292427a30e428d8f71af6f70c9205d","frame_index":0,"kind":"data","monotonic_ns":232501634587666,"payload":{"event_type":"price_change","market":"0x3b40066b5cf3871a2f6237c5628bd8092a206aa998558ac5ec13c4483e31e160","price_changes":[{"asset_id":"14766054693214075530629349735273995982307625376442606753688071083149620216746","best_ask":"0.41","best_bid":"0.4","hash":"5c56c9241aedcab157bc5bfe55093db1f91d60b2","price":"0.4","side":"BUY","size":"65"},{"asset_id":"110216635572655435074987471276357323571387854733835379371586402147734167783946","best_ask":"0.6","best_bid":"0.59","hash":"fde525719f233801bb286788a71b95ac51afb6f5","price":"0.6","side":"SELL","size":"65"}],"timestamp":"1785130517193"},"payload_hash":"1434f01a9966e15b585dd24cddc79cb93f332af9d94421d8593bee68e177735a","raw_frame":"{\"market\":\"0x3b40066b5cf3871a2f6237c5628bd8092a206aa998558ac5ec13c4483e31e160\", \"price_changes\":[{\"asset_id\":\"14766054693214075530629349735273995982307625376442606753688071083149620216746\", \"price\":\"0.4\", \"size\":\"65\", \"side\":\"BUY\", \"hash\":\"5c56c9241aedcab157bc5bfe55093db1f91d60b2\", \"best_bid\":\"0.4\", \"best_ask\":\"0.41\"}, {\"asset_id\":\"110216635572655435074987471276357323571387854733835379371586402147734167783946\", \"price\":\"0.6\", \"size\":\"65\", \"side\":\"SELL\", \"hash\":\"fde525719f233801bb286788a71b95ac51afb6f5\", \"best_bid\":\"0.59\", \"best_ask\":\"0.6\"}], \"timestamp\":\"1785130517193\", \"event_type\":\"price_change\"}","received_at":"2026-07-27T05:35:18.398590Z","schema_version":"clob-market-ws.price_change.v1","sequence":null,"server_hash":null,"server_timestamp":"1785130517193","session_id":"502006c5cfcd437296561ea750c9ec8b","source":"clob_market_ws"},"received_at":"2026-07-27T05:35:18.398590Z","record_id":"9bc57332dad7c89d1f56a50c22615b1e90475a204d79a9c3656679df55ff75e2","schema_fingerprint":"4aa3821a28b0b7c2400bc59aba4bcc0a76e971dadd19610d3ad38c768e124dc7","schema_version":"edge-lab-recorder.raw.v1","sequence":null,"source":"clob_market_ws"}
{"event_at":"2026-07-27T05:35:17.194000Z","event_fingerprint":"89e9d82261fcfee1b43cfbc2a30752efb55c1c49071c2884add798fbc663d280","payload":{"connection_id":"efc69d3132f1467b8e898a382b23ac0d","event_at":"2026-07-27T05:35:17.194000Z","event_type":"price_change","frame_hash":"d3688a6427c751bd1a00873a6a5715122689209fe3879ad2c04b6e95628eab6c","frame_index":0,"kind":"data","monotonic_ns":232501644087708,"payload":{"event_type":"price_change","market":"0x3b40066b5cf3871a2f6237c5628bd8092a206aa998558ac5ec13c4483e31e160","price_changes":[{"asset_id":"110216635572655435074987471276357323571387854733835379371586402147734167783946","best_ask":"0.6","best_bid":"0.59","hash":"0280eb70828891638821b0bc6392156df719eefc","price":"0.59","side":"BUY","size":"38.6"},{"asset_id":"14766054693214075530629349735273995982307625376442606753688071083149620216746","best_ask":"0.41","best_bid":"0.4","hash":"1b104f34bbd47241be691ecb6b6bd50221e7e3ad","price":"0.41","side":"SELL","size":"38.6"}],"timestamp":"1785130517194"},"payload_hash":"1d4b5ad54dbb4b658c7badbe0f802ee5d4f02e5f6b1990e997f221f323e4091f","raw_frame":"{\"market\":\"0x3b40066b5cf3871a2f6237c5628bd8092a206aa998558ac5ec13c4483e31e160\", \"price_changes\":[{\"asset_id\":\"110216635572655435074987471276357323571387854733835379371586402147734167783946\", \"price\":\"0.59\", \"size\":\"38.6\", \"side\":\"BUY\", \"hash\":\"0280eb70828891638821b0bc6392156df719eefc\", \"best_bid\":\"0.59\", \"best_ask\":\"0.6\"}, {\"asset_id\":\"14766054693214075530629349735273995982307625376442606753688071083149620216746\", \"price\":\"0.41\", \"size\":\"38.6\", \"side\":\"SELL\", \"hash\":\"1b104f34bbd47241be691ecb6b6bd50221e7e3ad\", \"best_bid\":\"0.4\", \"best_ask\":\"0.41\"}], \"timestamp\":\"1785130517194\", \"event_type\":\"price_change\"}","received_at":"2026-07-27T05:35:18.408090Z","schema_version":"clob-market-ws.price_change.v1","sequence":null,"server_hash":null,"server_timestamp":"1785130517194","session_id":"502006c5cfcd437296561ea750c9ec8b","source":"clob_market_ws"},"received_at":"2026-07-27T05:35:18.408090Z","record_id":"68a32758830c1c3168156e3a0ecad45cc0c9612e228be9ad5e07e1503a817fa3","schema_fingerprint":"4aa3821a28b0b7c2400bc59aba4bcc0a76e971dadd19610d3ad38c768e124dc7","schema_version":"edge-lab-recorder.raw.v1","sequence":null,"source":"clob_market_ws"}
{"event_at":"2026-07-27T05:35:17.194000Z","event_fingerprint":"91ec6bb5f444da66725a805841d27e27b85c52fa7e231e1c09f8f007354e40f7","payload":{"connection_id":"efc69d3132f1467b8e898a382b23ac0d","event_at":"2026-07-27T05:35:17.194000Z","event_type":"price_change","frame_hash":"aeaeeb3453c8f685589996b017dc0de451ba2dd2c2df78012890f318f2324495","frame_index":0,"kind":"data","monotonic_ns":232501652258000,"payload":{"event_type":"price_change","market":"0x3b40066b5cf3871a2f6237c5628bd8092a206aa998558ac5ec13c4483e31e160","price_changes":[{"asset_id":"110216635572655435074987471276357323571387854733835379371586402147734167783946","best_ask":"0.6","best_bid":"0.59","hash":"cc70e895371dfa525b9d495f13ee8a10c96dd374","price":"0.59","side":"BUY","size":"16.6"},{"asset_id":"14766054693214075530629349735273995982307625376442606753688071083149620216746","best_ask":"0.41","best_bid":"0.4","hash":"3a63612a563a07088a3f9061e78e573bea901f91","price":"0.41","side":"SELL","size":"16.6"}],"timestamp":"1785130517194"},"payload_hash":"b243f6d5a896ff6b44e9478f8e5558f8c360c911645b34c5320ca8bb157df89b","raw_frame":"{\"market\":\"0x3b40066b5cf3871a2f6237c5628bd8092a206aa998558ac5ec13c4483e31e160\", \"price_changes\":[{\"asset_id\":\"110216635572655435074987471276357323571387854733835379371586402147734167783946\", \"price\":\"0.59\", \"size\":\"16.6\", \"side\":\"BUY\", \"hash\":\"cc70e895371dfa525b9d495f13ee8a10c96dd374\", \"best_bid\":\"0.59\", \"best_ask\":\"0.6\"}, {\"asset_id\":\"14766054693214075530629349735273995982307625376442606753688071083149620216746\", \"price\":\"0.41\", \"size\":\"16.6\", \"side\":\"SELL\", \"hash\":\"3a63612a563a07088a3f9061e78e573bea901f91\", \"best_bid\":\"0.4\", \"best_ask\":\"0.41\"}], \"timestamp\":\"1785130517194\", \"event_type\":\"price_change\"}","received_at":"2026-07-27T05:35:18.416261Z","schema_version":"clob-market-ws.price_change.v1","sequence":null,"server_hash":null,"server_timestamp":"1785130517194","session_id":"502006c5cfcd437296561ea750c9ec8b","source":"clob_market_ws"},"received_at":"2026-07-27T05:35:18.416261Z","record_id":"c0f87ce3423323625fb897da0980e050a319714644c1be185e50d9df830ff1f8","schema_fingerprint":"4aa3821a28b0b7c2400bc59aba4bcc0a76e971dadd19610d3ad38c768e124dc7","schema_version":"edge-lab-recorder.raw.v1","sequence":null,"source":"clob_market_ws"}
{"event_at":"2026-07-27T05:35:17.195000Z","event_fingerprint":"934cd8f365f12c3f40e407719a9ced9c66fcc674e99e2810ef282a2f4677c6a8","payload":{"connection_id":"efc69d3132f1467b8e898a382b23ac0d","event_at":"2026-07-27T05:35:17.195000Z","event_type":"price_change","frame_hash":"a1e4341ce2b0dd297123b5dcf6f24aa9cae93b312654ac4c89e3fe569dbf2bb3","frame_index":0,"kind":"data","monotonic_ns":232501664302208,"payload":{"event_type":"price_change","market":"0x3b40066b5cf3871a2f6237c5628bd8092a206aa998558ac5ec13c4483e31e160","price_changes":[{"asset_id":"110216635572655435074987471276357323571387854733835379371586402147734167783946","best_ask":"0.6","best_bid":"0.59","hash":"561f757eefe32fb4eab719a522a500e4163ce47d","price":"0.58","side":"BUY","size":"27.8"},{"asset_id":"14766054693214075530629349735273995982307625376442606753688071083149620216746","best_ask":"0.41","best_bid":"0.4","hash":"4b15866360345ed3dd9da64e81bb87f3f5ca022a","price":"0.42","side":"SELL","size":"27.8"}],"timestamp":"1785130517195"},"payload_hash":"75b94a601db5e728cca0a32412717f9d0edf55e0210d65da8ae5d07fe22ee522","raw_frame":"{\"market\":\"0x3b40066b5cf3871a2f6237c5628bd8092a206aa998558ac5ec13c4483e31e160\", \"price_changes\":[{\"asset_id\":\"110216635572655435074987471276357323571387854733835379371586402147734167783946\", \"price\":\"0.58\", \"size\":\"27.8\", \"side\":\"BUY\", \"hash\":\"561f757eefe32fb4eab719a522a500e4163ce47d\", \"best_bid\":\"0.59\", \"best_ask\":\"0.6\"}, {\"asset_id\":\"14766054693214075530629349735273995982307625376442606753688071083149620216746\", \"price\":\"0.42\", \"size\":\"27.8\", \"side\":\"SELL\", \"hash\":\"4b15866360345ed3dd9da64e81bb87f3f5ca022a\", \"best_bid\":\"0.4\", \"best_ask\":\"0.41\"}], \"timestamp\":\"1785130517195\", \"event_type\":\"price_change\"}","received_at":"2026-07-27T05:35:18.428305Z","schema_version":"clob-market-ws.price_change.v1","sequence":null,"server_hash":null,"server_timestamp":"1785130517195","session_id":"502006c5cfcd437296561ea750c9ec8b","source":"clob_market_ws"},"received_at":"2026-07-27T05:35:18.428305Z","record_id":"821b914c8bef8cf6f92406e99c269cd08c5028d5c684308d2ef29421589b6a07","schema_fingerprint":"4aa3821a28b0b7c2400bc59aba4bcc0a76e971dadd19610d3ad38c768e124dc7","schema_version":"edge-lab-recorder.raw.v1","sequence":null,"source":"clob_market_ws"}
{"event_at":"2026-07-27T05:35:17.196000Z","event_fingerprint":"8882612d6a529b3635bd61af2adde4788af18191ab89110a4a6b02b2cafa0c63","payload":{"connection_id":"efc69d3132f1467b8e898a382b23ac0d","event_at":"2026-07-27T05:35:17.196000Z","event_type":"price_change","frame_hash":"7598645db9d3b7cac6faa9879a695dccdbff63d47419a404cfb3199bbc466150","frame_index":0,"kind":"data","monotonic_ns":232501671057291,"payload":{"event_type":"price_change","market":"0x3b40066b5cf3871a2f6237c5628bd8092a206aa998558ac5ec13c4483e31e160","price_changes":[{"asset_id":"110216635572655435074987471276357323571387854733835379371586402147734167783946","best_ask":"0.6","best_bid":"0.59","hash":"b28961bb8eb14f2da99b1c566e5d99d9ce71fa30","price":"0.57","side":"BUY","size":"52.2"},{"asset_id":"14766054693214075530629349735273995982307625376442606753688071083149620216746","best_ask":"0.41","best_bid":"0.4","hash":"60eb44f25e76f3b775005376be565e1a7710e59b","price":"0.43","side":"SELL","size":"52.2"}],"timestamp":"1785130517196"},"payload_hash":"d4a84dd3a217a3f3e9ccb740164436b0a62c23f62ae6787dcd8162b58130e7a2","raw_frame":"{\"market\":\"0x3b40066b5cf3871a2f6237c5628bd8092a206aa998558ac5ec13c4483e31e160\", \"price_changes\":[{\"asset_id\":\"110216635572655435074987471276357323571387854733835379371586402147734167783946\", \"price\":\"0.57\", \"size\":\"52.2\", \"side\":\"BUY\", \"hash\":\"b28961bb8eb14f2da99b1c566e5d99d9ce71fa30\", \"best_bid\":\"0.59\", \"best_ask\":\"0.6\"}, {\"asset_id\":\"14766054693214075530629349735273995982307625376442606753688071083149620216746\", \"price\":\"0.43\", \"size\":\"52.2\", \"side\":\"SELL\", \"hash\":\"60eb44f25e76f3b775005376be565e1a7710e59b\", \"best_bid\":\"0.4\", \"best_ask\":\"0.41\"}], \"timestamp\":\"1785130517196\", \"event_type\":\"price_change\"}","received_at":"2026-07-27T05:35:18.435061Z","schema_version":"clob-market-ws.price_change.v1","sequence":null,"server_hash":null,"server_timestamp":"1785130517196","session_id":"502006c5cfcd437296561ea750c9ec8b","source":"clob_market_ws"},"received_at":"2026-07-27T05:35:18.435061Z","record_id":"52020eb7eba572d0c2a485c3e8af54d63737841002ab8d66b727540a64477332","schema_fingerprint":"4aa3821a28b0b7c2400bc59aba4bcc0a76e971dadd19610d3ad38c768e124dc7","schema_version":"edge-lab-recorder.raw.v1","sequence":null,"source":"clob_market_ws"}
{"event_at":"2026-07-27T05:35:17.196000Z","event_fingerprint":"18c1b1590979b14b9478c445d03526884c16d175685b28b6705c9b2e937dec6a","payload":{"connection_id":"efc69d3132f1467b8e898a382b23ac0d","event_at":"2026-07-27T05:35:17.196000Z","event_type":"price_change","frame_hash":"844df8fc0cde74810456b2fd53daf5aba8503942266aa5f6dc568b223944cf34","frame_index":0,"kind":"data","monotonic_ns":232501680914375,"payload":{"event_type":"price_change","market":"0x3b40066b5cf3871a2f6237c5628bd8092a206aa998558ac5ec13c4483e31e160","price_changes":[{"asset_id":"110216635572655435074987471276357323571387854733835379371586402147734167783946","best_ask":"0.6","best_bid":"0.59","hash":"fb9125e0b39145642e0a80d2a8f7325eb4bcd8d9","price":"0.57","side":"BUY","size":"30.2"},{"asset_id":"14766054693214075530629349735273995982307625376442606753688071083149620216746","best_ask":"0.41","best_bid":"0.4","hash":"73f49cdd5acd5d22e0775d27d24a781c007fe5ab","price":"0.43","side":"SELL","size":"30.2"}],"timestamp":"1785130517196"},"payload_hash":"bebe137eb16a390f618265dea7e2fb069740ec9ea5356ecceb50082e126b9558","raw_frame":"{\"market\":\"0x3b40066b5cf3871a2f6237c5628bd8092a206aa998558ac5ec13c4483e31e160\", \"price_changes\":[{\"asset_id\":\"110216635572655435074987471276357323571387854733835379371586402147734167783946\", \"price\":\"0.57\", \"size\":\"30.2\", \"side\":\"BUY\", \"hash\":\"fb9125e0b39145642e0a80d2a8f7325eb4bcd8d9\", \"best_bid\":\"0.59\", \"best_ask\":\"0.6\"}, {\"asset_id\":\"14766054693214075530629349735273995982307625376442606753688071083149620216746\", \"price\":\"0.43\", \"size\":\"30.2\", \"side\":\"SELL\", \"hash\":\"73f49cdd5acd5d22e0775d27d24a781c007fe5ab\", \"best_bid\":\"0.4\", \"best_ask\":\"0.41\"}], \"timestamp\":\"1785130517196\", \"event_type\":\"price_change\"}","received_at":"2026-07-27T05:35:18.444914Z","schema_version":"clob-market-ws.price_change.v1","sequence":null,"server_hash":null,"server_timestamp":"1785130517196","session_id":"502006c5cfcd437296561ea750c9ec8b","source":"clob_market_ws"},"received_at":"2026-07-27T05:35:18.444914Z","record_id":"67b912cce5576ef18c90e3085d737bc4511b642e93d0801ee9f7c7b5ef776f87","schema_fingerprint":"4aa3821a28b0b7c2400bc59aba4bcc0a76e971dadd19610d3ad38c768e124dc7","schema_version":"edge-lab-recorder.raw.v1","sequence":null,"source":"clob_market_ws"}
