{"event_at":"2026-07-27T05:38:16.442000Z","event_fingerprint":"acce196be296b05f648a65c4e2606a9c809f649bdd63362d7c92543ebfec65ca","payload":{"connection_id":"efc69d3132f1467b8e898a382b23ac0d","event_at":"2026-07-27T05:38:16.442000Z","event_type":"price_change","frame_hash":"ea4f8f031da02f798c0cf48e1d90dc4ab34443d619afa5eba0dd115101e96093","frame_index":0,"kind":"data","monotonic_ns":232680652759250,"payload":{"event_type":"price_change","market":"0x3b40066b5cf3871a2f6237c5628bd8092a206aa998558ac5ec13c4483e31e160","price_changes":[{"asset_id":"14766054693214075530629349735273995982307625376442606753688071083149620216746","best_ask":"0.38","best_bid":"0.37","hash":"aab427bc5cfe75db674cf2ffdbc37656a07ff20a","price":"0.36","side":"BUY","size":"435.4"},{"asset_id":"110216635572655435074987471276357323571387854733835379371586402147734167783946","best_ask":"0.63","best_bid":"0.62","hash":"f6ea0936702b8233b838aa5451b3aa72b42fbef3","price":"0.64","side":"SELL","size":"435.4"}],"timestamp":"1785130696442"},"payload_hash":"dfa5fc47b29ef9a4579d8e928ab2e3c37306bf24e892eeeb7b5e5c973a2dde5c","raw_frame":"{\"market\":\"0x3b40066b5cf3871a2f6237c5628bd8092a206aa998558ac5ec13c4483e31e160\", \"price_changes\":[{\"asset_id\":\"14766054693214075530629349735273995982307625376442606753688071083149620216746\", \"price\":\"0.36\", \"size\":\"435.4\", \"side\":\"BUY\", \"hash\":\"aab427bc5cfe75db674cf2ffdbc37656a07ff20a\", \"best_bid\":\"0.37\", \"best_ask\":\"0.38\"}, {\"asset_id\":\"110216635572655435074987471276357323571387854733835379371586402147734167783946\", \"price\":\"0.64\", \"size\":\"435.4\", \"side\":\"SELL\", \"hash\":\"f6ea0936702b8233b838aa5451b3aa72b42fbef3\", \"best_bid\":\"0.62\", \"best_ask\":\"0.63\"}], \"timestamp\":\"1785130696442\", \"event_type\":\"price_change\"}","received_at":"2026-07-27T05:38:17.418003Z","schema_version":"clob-market-ws.price_change.v1","sequence":null,"server_hash":null,"server_timestamp":"1785130696442","session_id":"502006c5cfcd437296561ea750c9ec8b","source":"clob_market_ws"},"received_at":"2026-07-27T05:38:17.418003Z","record_id":"2f714948cacd0c3c3a5ebe79a89701557e6db8f615783dc3665985e22dddd994","schema_fingerprint":"4aa3821a28b0b7c2400bc59aba4bcc0a76e971dadd19610d3ad38c768e124dc7","schema_version":"edge-lab-recorder.raw.v1","sequence":null,"source":"clob_market_ws"}
{"event_at":"2026-07-27T05:38:16.442000Z","event_fingerprint":"14f64392a78a3b823bab4e20774c69807c4cc754ae0f09f9912d5b19bb739a14","payload":{"connection_id":"efc69d3132f1467b8e898a382b23ac0d","event_at":"2026-07-27T05:38:16.442000Z","event_type":"price_change","frame_hash":"15400cbe6ddf47f6c72a069d264d71e3b3775a35512e4617f7d655b747452981","frame_index":0,"kind":"data","monotonic_ns":232680665071208,"payload":{"event_type":"price_change","market":"0x3b40066b5cf3871a2f6237c5628bd8092a206aa998558ac5ec13c4483e31e160","price_changes":[{"asset_id":"110216635572655435074987471276357323571387854733835379371586402147734167783946","best_ask":"0.63","best_bid":"0.62","hash":"bfd22f856cd48d184bf852a2284c8b840fb7d0e2","price":"0.51","side":"BUY","size":"78"},{"asset_id":"14766054693214075530629349735273995982307625376442606753688071083149620216746","best_ask":"0.38","best_bid":"0.37","hash":"21deec48c0feb1145084cb2a078c682bc853fa0f","price":"0.49","side":"SELL","size":"78"}],"timestamp":"1785130696442"},"payload_hash":"8c800fd8295f41902c34fa13c33218f8876f73256b4e9619e968ad85d234944c","raw_frame":"{\"market\":\"0x3b40066b5cf3871a2f6237c5628bd8092a206aa998558ac5ec13c4483e31e160\", \"price_changes\":[{\"asset_id\":\"110216635572655435074987471276357323571387854733835379371586402147734167783946\", \"price\":\"0.51\", \"size\":\"78\", \"side\":\"BUY\", \"hash\":\"bfd22f856cd48d184bf852a2284c8b840fb7d0e2\", \"best_bid\":\"0.62\", \"best_ask\":\"0.63\"}, {\"asset_id\":\"14766054693214075530629349735273995982307625376442606753688071083149620216746\", \"price\":\"0.49\", \"size\":\"78\", \"side\":\"SELL\", \"hash\":\"21deec48c0feb1145084cb2a078c682bc853fa0f\", \"best_bid\":\"0.37\", \"best_ask\":\"0.38\"}], \"timestamp\":\"1785130696442\", \"event_type\":\"price_change\"}","received_at":"2026-07-27T05:38:17.430324Z","schema_version":"clob-market-ws.price_change.v1","sequence":null,"server_hash":null,"server_timestamp":"1785130696442","session_id":"502006c5cfcd437296561ea750c9ec8b","source":"clob_market_ws"},"received_at":"2026-07-27T05:38:17.430324Z","record_id":"f68b89ada9e7938d14d5052e10e787b74c1e997fc3f6dc4fee30c1e0b8865523","schema_fingerprint":"4aa3821a28b0b7c2400bc59aba4bcc0a76e971dadd19610d3ad38c768e124dc7","schema_version":"edge-lab-recorder.raw.v1","sequence":null,"source":"clob_market_ws"}
{"event_at":"2026-07-27T05:38:16.442000Z","event_fingerprint":"ca22b3cb8abee13a32000c44a633188b38a3594e0839c6fcbb71c0f7ee7d1137","payload":{"connection_id":"efc69d3132f1467b8e898a382b23ac0d","event_at":"2026-07-27T05:38:16.442000Z","event_type":"price_change","frame_hash":"669599a30aa2cc1dd3d93e32d5587c399d40f70ad61f0099df83a2a7197dfdbb","frame_index":0,"kind":"data","monotonic_ns":232680668281416,"payload":{"event_type":"price_change","market":"0x3b40066b5cf3871a2f6237c5628bd8092a206aa998558ac5ec13c4483e31e160","price_changes":[{"asset_id":"110216635572655435074987471276357323571387854733835379371586402147734167783946","best_ask":"0.63","best_bid":"0.62","hash":"a3e41df1986c53d3a51cc5f5decfbcf698559d88","price":"0.41","side":"BUY","size":"213"},{"asset_id":"14766054693214075530629349735273995982307625376442606753688071083149620216746","best_ask":"0.38","best_bid":"0.37","hash":"54566c97a983cd67e74b0f2aad1749eb08aa63b1","price":"0.59","side":"SELL","size":"213"}],"timestamp":"1785130696442"},"payload_hash":"3393e4c1470a82a0f71c25a9ca06d16dae2680f4e0094133fcfd64901ca3f2ed","raw_frame":"{\"market\":\"0x3b40066b5cf3871a2f6237c5628bd8092a206aa998558ac5ec13c4483e31e160\", \"price_changes\":[{\"asset_id\":\"110216635572655435074987471276357323571387854733835379371586402147734167783946\", \"price\":\"0.41\", \"size\":\"213\", \"side\":\"BUY\", \"hash\":\"a3e41df1986c53d3a51cc5f5decfbcf698559d88\", \"best_bid\":\"0.62\", \"best_ask\":\"0.63\"}, {\"asset_id\":\"14766054693214075530629349735273995982307625376442606753688071083149620216746\", \"price\":\"0.59\", \"size\":\"213\", \"side\":\"SELL\", \"hash\":\"54566c97a983cd67e74b0f2aad1749eb08aa63b1\", \"best_bid\":\"0.37\", \"best_ask\":\"0.38\"}], \"timestamp\":\"1785130696442\", \"event_type\":\"price_change\"}","received_at":"2026-07-27T05:38:17.433529Z","schema_version":"clob-market-ws.price_change.v1","sequence":null,"server_hash":null,"server_timestamp":"1785130696442","session_id":"502006c5cfcd437296561ea750c9ec8b","source":"clob_market_ws"},"received_at":"2026-07-27T05:38:17.433529Z","record_id":"839d0adf8cb28862c50441208547bfd31dedcde897979e3eff932cb7a99a0786","schema_fingerprint":"4aa3821a28b0b7c2400bc59aba4bcc0a76e971dadd19610d3ad38c768e124dc7","schema_version":"edge-lab-recorder.raw.v1","sequence":null,"source":"clob_market_ws"}
{"event_at":"2026-07-27T05:38:16.443000Z","event_fingerprint":"da40173c7dd6feea8deda8cf2dca2c8a0d038151c3c1f3ae968a4a1c02d00f94","payload":{"connection_id":"efc69d3132f1467b8e898a382b23ac0d","event_at":"2026-07-27T05:38:16.443000Z","event_type":"price_change","frame_hash":"338f4508b4522d7f399c17f39a4e2656d088a4006748cfa278bb1e773e29a60a","frame_index":0,"kind":"data","monotonic_ns":232680673179125,"payload":{"event_type":"price_change","market":"0x3b40066b5cf3871a2f6237c5628bd8092a206aa998558ac5ec13c4483e31e160","price_changes":[{"asset_id":"14766054693214075530629349735273995982307625376442606753688071083149620216746","best_ask":"0.38","best_bid":"0.37","hash":"b598cd0d0079003953b1f1d82dff56dcb25ab047","price":"0.31","side":"BUY","size":"97.4"},{"asset_id":"110216635572655435074987471276357323571387854733835379371586402147734167783946","best_ask":"0.63","best_bid":"0.62","hash":"f5b8854d9892cb1a5d1c0b80036a2dc78e8af3fe","price":"0.69","side":"SELL","size":"97.4"}],"timestamp":"1785130696443"},"payload_hash":"250ef5fdd99295b84a3e33615001407bb1a122272c3a62a6b78d26c8d06a94bc","raw_frame":"{\"market\":\"0x3b40066b5cf3871a2f6237c5628bd8092a206aa998558ac5ec13c4483e31e160\", \"price_changes\":[{\"asset_id\":\"14766054693214075530629349735273995982307625376442606753688071083149620216746\", \"price\":\"0.31\", \"size\":\"97.4\", \"side\":\"BUY\", \"hash\":\"b598cd0d0079003953b1f1d82dff56dcb25ab047\", \"best_bid\":\"0.37\", \"best_ask\":\"0.38\"}, {\"asset_id\":\"110216635572655435074987471276357323571387854733835379371586402147734167783946\", \"price\":\"0.69\", \"size\":\"97.4\", \"side\":\"SELL\", \"hash\":\"f5b8854d9892cb1a5d1c0b80036a2dc78e8af3fe\", \"best_bid\":\"0.62\", \"best_ask\":\"0.63\"}], \"timestamp\":\"1785130696443\", \"event_type\":\"price_change\"}","received_at":"2026-07-27T05:38:17.438427Z","schema_version":"clob-market-ws.price_change.v1","sequence":null,"server_hash":null,"server_timestamp":"1785130696443","session_id":"502006c5cfcd437296561ea750c9ec8b","source":"clob_market_ws"},"received_at":"2026-07-27T05:38:17.438427Z","record_id":"3ea0ce6af48b8d5e2557c288944638579d266f44cb71af297ea0eb38cbdc6a08","schema_fingerprint":"4aa3821a28b0b7c2400bc59aba4bcc0a76e971dadd19610d3ad38c768e124dc7","schema_version":"edge-lab-recorder.raw.v1","sequence":null,"source":"clob_market_ws"}
{"event_at":"2026-07-27T05:38:16.446000Z","event_fingerprint":"3544d7e3dd54a6c818940e5b77a317a9859f13a589af0bf2cd127ceb7165b9e0","payload":{"connection_id":"efc69d3132f1467b8e898a382b23ac0d","event_at":"2026-07-27T05:38:16.446000Z","event_type":"price_change","frame_hash":"c7eb883d8cd509b7b4027fa9febf52c66f289eef798192ebdb62c7c9d31d56b4","frame_index":0,"kind":"data","monotonic_ns":232680677435125,"payload":{"event_type":"price_change","market":"0x3b40066b5cf3871a2f6237c5628bd8092a206aa998558ac5ec13c4483e31e160","price_changes":[{"asset_id":"14766054693214075530629349735273995982307625376442606753688071083149620216746","best_ask":"0.38","best_bid":"0.37","hash":"a56dec099ad41cfec4749a0bbe2fa7e784c790f4","price":"0.28","side":"BUY","size":"253.9"},{"asset_id":"110216635572655435074987471276357323571387854733835379371586402147734167783946","best_ask":"0.63","best_bid":"0.62","hash":"47b4675664f8fffde0da0a4aa44c9774a2f2817d","price":"0.72","side":"SELL","size":"253.9"}],"timestamp":"1785130696446"},"payload_hash":"dfbf5f15a5fe3421295a56f869a52b275fd8c669c4b2c60f4f8e81a470f082dc","raw_frame":"{\"market\":\"0x3b40066b5cf3871a2f6237c5628bd8092a206aa998558ac5ec13c4483e31e160\", \"price_changes\":[{\"asset_id\":\"14766054693214075530629349735273995982307625376442606753688071083149620216746\", \"price\":\"0.28\", \"size\":\"253.9\", \"side\":\"BUY\", \"hash\":\"a56dec099ad41cfec4749a0bbe2fa7e784c790f4\", \"best_bid\":\"0.37\", \"best_ask\":\"0.38\"}, {\"asset_id\":\"110216635572655435074987471276357323571387854733835379371586402147734167783946\", \"price\":\"0.72\", \"size\":\"253.9\", \"side\":\"SELL\", \"hash\":\"47b4675664f8fffde0da0a4aa44c9774a2f2817d\", \"best_bid\":\"0.62\", \"best_ask\":\"0.63\"}], \"timestamp\":\"1785130696446\", \"event_type\":\"price_change\"}","received_at":"2026-07-27T05:38:17.442676Z","schema_version":"clob-market-ws.price_change.v1","sequence":null,"server_hash":null,"server_timestamp":"1785130696446","session_id":"502006c5cfcd437296561ea750c9ec8b","source":"clob_market_ws"},"received_at":"2026-07-27T05:38:17.442676Z","record_id":"16e410daea724a88ffcb26313bc9b4c75dac3380d728e4cf53a4061961e4c595","schema_fingerprint":"4aa3821a28b0b7c2400bc59aba4bcc0a76e971dadd19610d3ad38c768e124dc7","schema_version":"edge-lab-recorder.raw.v1","sequence":null,"source":"clob_market_ws"}
{"event_at":"2026-07-27T05:38:16.447000Z","event_fingerprint":"2b021d55d62a871872082cb5d8f2f0c4af4fa8f240184346e6b1726e433fb0a4","payload":{"connection_id":"efc69d3132f1467b8e898a382b23ac0d","event_at":"2026-07-27T05:38:16.447000Z","event_type":"price_change","frame_hash":"63b86c04d3697f565e0edca6dd6565d68927bec08a4447b8398944a58435b6b1","frame_index":0,"kind":"data","monotonic_ns":232680681239458,"payload":{"event_type":"price_change","market":"0x3b40066b5cf3871a2f6237c5628bd8092a206aa998558ac5ec13c4483e31e160","price_changes":[{"asset_id":"110216635572655435074987471276357323571387854733835379371586402147734167783946","best_ask":"0.63","best_bid":"0.62","hash":"654467a52a8ed67ad26d53c27a89352b7b2f060e","price":"0.58","side":"BUY","size":"45"},{"asset_id":"14766054693214075530629349735273995982307625376442606753688071083149620216746","best_ask":"0.38","best_bid":"0.37","hash":"7a126bb0430f9fb115527cefad2acf8bbc8f39c8","price":"0.42","side":"SELL","size":"45"}],"timestamp":"1785130696447"},"payload_hash":"48a224a172416504d37f352c4825149bed094a160d2ce3dc97000c3ce347f07e","raw_frame":"{\"market\":\"0x3b40066b5cf3871a2f6237c5628bd8092a206aa998558ac5ec13c4483e31e160\", \"price_changes\":[{\"asset_id\":\"110216635572655435074987471276357323571387854733835379371586402147734167783946\", \"price\":\"0.58\", \"size\":\"45\", \"side\":\"BUY\", \"hash\":\"654467a52a8ed67ad26d53c27a89352b7b2f060e\", \"best_bid\":\"0.62\", \"best_ask\":\"0.63\"}, {\"asset_id\":\"14766054693214075530629349735273995982307625376442606753688071083149620216746\", \"price\":\"0.42\", \"size\":\"45\", \"side\":\"SELL\", \"hash\":\"7a126bb0430f9fb115527cefad2acf8bbc8f39c8\", \"best_bid\":\"0.37\", \"best_ask\":\"0.38\"}], \"timestamp\":\"1785130696447\", \"event_type\":\"price_change\"}","received_at":"2026-07-27T05:38:17.446485Z","schema_version":"clob-market-ws.price_change.v1","sequence":null,"server_hash":null,"server_timestamp":"1785130696447","session_id":"502006c5cfcd437296561ea750c9ec8b","source":"clob_market_ws"},"received_at":"2026-07-27T05:38:17.446485Z","record_id":"8dc812e49cb9fd690439c5e747e264b8f75d1372bc139188b927c26fe953b265","schema_fingerprint":"4aa3821a28b0b7c2400bc59aba4bcc0a76e971dadd19610d3ad38c768e124dc7","schema_version":"edge-lab-recorder.raw.v1","sequence":null,"source":"clob_market_ws"}
{"event_at":"2026-07-27T05:38:16.448000Z","event_fingerprint":"884158554330d1eb88e4d108536d568a8062972be30d262553bf369b7c0fb3be","payload":{"connection_id":"efc69d3132f1467b8e898a382b23ac0d","event_at":"2026-07-27T05:38:16.448000Z","event_type":"price_change","frame_hash":"15ce6a1c983b0ae9d24ce4d5fa790fae21eee9aa8f464c3472e9f49c31359965","frame_index":0,"kind":"data","monotonic_ns":232680685304083,"payload":{"event_type":"price_change","market":"0x3b40066b5cf3871a2f6237c5628bd8092a206aa998558ac5ec13c4483e31e160","price_changes":[{"asset_id":"14766054693214075530629349735273995982307625376442606753688071083149620216746","best_ask":"0.38","best_bid":"0.37","hash":"7c7b0be712bb5b229e9e05ac0664b5b8debc7453","price":"0.4","side":"SELL","size":"50"},{"asset_id":"110216635572655435074987471276357323571387854733835379371586402147734167783946","best_ask":"0.63","best_bid":"0.62","hash":"1b649153aadbc96029a7c45d049850da541cfe16","price":"0.6","side":"BUY","size":"50"}],"timestamp":"1785130696448"},"payload_hash":"2b1a96e9880dc468f938022d69571508dbae04d303d1b1ab3b5fabfe9a78e15d","raw_frame":"{\"market\":\"0x3b40066b5cf3871a2f6237c5628bd8092a206aa998558ac5ec13c4483e31e160\", \"price_changes\":[{\"asset_id\":\"14766054693214075530629349735273995982307625376442606753688071083149620216746\", \"price\":\"0.4\", \"size\":\"50\", \"side\":\"SELL\", \"hash\":\"7c7b0be712bb5b229e9e05ac0664b5b8debc7453\", \"best_bid\":\"0.37\", \"best_ask\":\"0.38\"}, {\"asset_id\":\"110216635572655435074987471276357323571387854733835379371586402147734167783946\", \"price\":\"0.6\", \"size\":\"50\", \"side\":\"BUY\", \"hash\":\"1b649153aadbc96029a7c45d049850da541cfe16\", \"best_bid\":\"0.62\", \"best_ask\":\"0.63\"}], \"timestamp\":\"1785130696448\", \"event_type\":\"price_change\"}","received_at":"2026-07-27T05:38:17.450551Z","schema_version":"clob-market-ws.price_change.v1","sequence":null,"server_hash":null,"server_timestamp":"1785130696448","session_id":"502006c5cfcd437296561ea750c9ec8b","source":"clob_market_ws"},"received_at":"2026-07-27T05:38:17.450551Z","record_id":"220ec8bcda1100a45d6e9d7f7dd942954162aa23f3e899459d28fff30de9463b","schema_fingerprint":"4aa3821a28b0b7c2400bc59aba4bcc0a76e971dadd19610d3ad38c768e124dc7","schema_version":"edge-lab-recorder.raw.v1","sequence":null,"source":"clob_market_ws"}
{"event_at":"2026-07-27T05:38:16.449000Z","event_fingerprint":"6cdd1d13d4107dd87404df4f8d76642b9128f95e23d024c39b319db91fd18556","payload":{"connection_id":"efc69d3132f1467b8e898a382b23ac0d","event_at":"2026-07-27T05:38:16.449000Z","event_type":"price_change","frame_hash":"f8f5516a3ea5a2e427c36e129dfe051e98ac81cce6dc8f4dcc6607741e42dff0","frame_index":0,"kind":"data","monotonic_ns":232680689491208,"payload":{"event_type":"price_change","market":"0x3b40066b5cf3871a2f6237c5628bd8092a206aa998558ac5ec13c4483e31e160","price_changes":[{"asset_id":"110216635572655435074987471276357323571387854733835379371586402147734167783946","best_ask":"0.63","best_bid":"0.62","hash":"28771cae7de4c99b97cdbe9e73982297c6004a0f","price":"0.41","side":"BUY","size":"131.7"},{"asset_id":"14766054693214075530629349735273995982307625376442606753688071083149620216746","best_ask":"0.38","best_bid":"0.37","hash":"529596bfb173b299beffd4d2c2584c73d09fc2ad","price":"0.59","side":"SELL","size":"131.7"}],"timestamp":"1785130696449"},"payload_hash":"5d7fdd314fa7ea3c45899b3220a4114a346c0556f33f4a7aef313924cba1ad9f","raw_frame":"{\"market\":\"0x3b40066b5cf3871a2f6237c5628bd8092a206aa998558ac5ec13c4483e31e160\", \"price_changes\":[{\"asset_id\":\"110216635572655435074987471276357323571387854733835379371586402147734167783946\", \"price\":\"0.41\", \"size\":\"131.7\", \"side\":\"BUY\", \"hash\":\"28771cae7de4c99b97cdbe9e73982297c6004a0f\", \"best_bid\":\"0.62\", \"best_ask\":\"0.63\"}, {\"asset_id\":\"14766054693214075530629349735273995982307625376442606753688071083149620216746\", \"price\":\"0.59\", \"size\":\"131.7\", \"side\":\"SELL\", \"hash\":\"529596bfb173b299beffd4d2c2584c73d09fc2ad\", \"best_bid\":\"0.37\", \"best_ask\":\"0.38\"}], \"timestamp\":\"1785130696449\", \"event_type\":\"price_change\"}","received_at":"2026-07-27T05:38:17.454739Z","schema_version":"clob-market-ws.price_change.v1","sequence":null,"server_hash":null,"server_timestamp":"1785130696449","session_id":"502006c5cfcd437296561ea750c9ec8b","source":"clob_market_ws"},"received_at":"2026-07-27T05:38:17.454739Z","record_id":"5f2d828be41d7ad49af3f0f9b6a8520a0e281db31e1e2f8e19af4b7cdc631c61","schema_fingerprint":"4aa3821a28b0b7c2400bc59aba4bcc0a76e971dadd19610d3ad38c768e124dc7","schema_version":"edge-lab-recorder.raw.v1","sequence":null,"source":"clob_market_ws"}
{"event_at":"2026-07-27T05:38:16.449000Z","event_fingerprint":"f137bb5835059ec9106848bb7f6475ea5ae50814c0f999c8b6010a4450d3756e","payload":{"connection_id":"efc69d3132f1467b8e898a382b23ac0d","event_at":"2026-07-27T05:38:16.449000Z","event_type":"price_change","frame_hash":"23034deb7944312fcccd59415a446a2843a4daa4e473541b631ce065d86eded3","frame_index":0,"kind":"data","monotonic_ns":232680694416291,"payload":{"event_type":"price_change","market":"0x3b40066b5cf3871a2f6237c5628bd8092a206aa998558ac5ec13c4483e31e160","price_changes":[{"asset_id":"14766054693214075530629349735273995982307625376442606753688071083149620216746","best_ask":"0.38","best_bid":"0.37","hash":"896e9d98e2c5a4fa22d6374d0148270e55c535ce","price":"0.32","side":"BUY","size":"50.6"},{"asset_id":"110216635572655435074987471276357323571387854733835379371586402147734167783946","best_ask":"0.63","best_bid":"0.62","hash":"db4507f0fed351a484478416fffc56c4b3554472","price":"0.68","side":"SELL","size":"50.6"}],"timestamp":"1785130696449"},"payload_hash":"27d891adf07147101665c68d75343661c77c24178bcc8d998f7779afb6a8dae1","raw_frame":"{\"market\":\"0x3b40066b5cf3871a2f6237c5628bd8092a206aa998558ac5ec13c4483e31e160\", \"price_changes\":[{\"asset_id\":\"14766054693214075530629349735273995982307625376442606753688071083149620216746\", \"price\":\"0.32\", \"size\":\"50.6\", \"side\":\"BUY\", \"hash\":\"896e9d98e2c5a4fa22d6374d0148270e55c535ce\", \"best_bid\":\"0.37\", \"best_ask\":\"0.38\"}, {\"asset_id\":\"110216635572655435074987471276357323571387854733835379371586402147734167783946\", \"price\":\"0.68\", \"size\":\"50.6\", \"side\":\"SELL\", \"hash\":\"db4507f0fed351a484478416fffc56c4b3554472\", \"best_bid\":\"0.62\", \"best_ask\":\"0.63\"}], \"timestamp\":\"1785130696449\", \"event_type\":\"price_change\"}","received_at":"2026-07-27T05:38:17.459664Z","schema_version":"clob-market-ws.price_change.v1","sequence":null,"server_hash":null,"server_timestamp":"1785130696449","session_id":"502006c5cfcd437296561ea750c9ec8b","source":"clob_market_ws"},"received_at":"2026-07-27T05:38:17.459664Z","record_id":"60a5ddd1105058611322149f846fefaf1e75b13a6e39e621012374542e550a52","schema_fingerprint":"4aa3821a28b0b7c2400bc59aba4bcc0a76e971dadd19610d3ad38c768e124dc7","schema_version":"edge-lab-recorder.raw.v1","sequence":null,"source":"clob_market_ws"}
{"event_at":"2026-07-27T05:38:16.462000Z","event_fingerprint":"11961aef54de6184a4bb98bbfa271831621fbe085a0d8bc20a1299f4a90ceffc","payload":{"connection_id":"efc69d3132f1467b8e898a382b23ac0d","event_at":"2026-07-27T05:38:16.462000Z","event_type":"price_change","frame_hash":"9241d5bdd182e4caa53d20a285a655975d28160b658fdb7f8d7625b2c07d4a8c","frame_index":0,"kind":"data","monotonic_ns":232680697615541,"payload":{"event_type":"price_change","market":"0x3b40066b5cf3871a2f6237c5628bd8092a206aa998558ac5ec13c4483e31e160","price_changes":[{"asset_id":"14766054693214075530629349735273995982307625376442606753688071083149620216746","best_ask":"0.38","best_bid":"0.37","hash":"d0a2fc3d05bcbcbc7f1376376aa7a573175c01e7","price":"0.3","side":"BUY","size":"47"},{"asset_id":"110216635572655435074987471276357323571387854733835379371586402147734167783946","best_ask":"0.63","best_bid":"0.62","hash":"c2ff3f5c09d96b79393dcaddac0fca69bee24c3d","price":"0.7","side":"SELL","size":"47"}],"timestamp":"1785130696462"},"payload_hash":"4e5c9e93468349c2efc5ed049cc93890b4162de8b4f1ddd5e95a6d6d2a55c5b2","raw_frame":"{\"market\":\"0x3b40066b5cf3871a2f6237c5628bd8092a206aa998558ac5ec13c4483e31e160\", \"price_changes\":[{\"asset_id\":\"14766054693214075530629349735273995982307625376442606753688071083149620216746\", \"price\":\"0.3\", \"size\":\"47\", \"side\":\"BUY\", \"hash\":\"d0a2fc3d05bcbcbc7f1376376aa7a573175c01e7\", \"best_bid\":\"0.37\", \"best_ask\":\"0.38\"}, {\"asset_id\":\"110216635572655435074987471276357323571387854733835379371586402147734167783946\", \"price\":\"0.7\", \"size\":\"47\", \"side\":\"SELL\", \"hash\":\"c2ff3f5c09d96b79393dcaddac0fca69bee24c3d\", \"best_bid\":\"0.62\", \"best_ask\":\"0.63\"}], \"timestamp\":\"1785130696462\", \"event_type\":\"price_change\"}","received_at":"2026-07-27T05:38:17.462868Z","schema_version":"clob-market-ws.price_change.v1","sequence":null,"server_hash":null,"server_timestamp":"1785130696462","session_id":"502006c5cfcd437296561ea750c9ec8b","source":"clob_market_ws"},"received_at":"2026-07-27T05:38:17.462868Z","record_id":"ac35f0963d0dda6886951eccfcb65128fc3829d87414debb895cdea47a3da824","schema_fingerprint":"4aa3821a28b0b7c2400bc59aba4bcc0a76e971dadd19610d3ad38c768e124dc7","schema_version":"edge-lab-recorder.raw.v1","sequence":null,"source":"clob_market_ws"}
{"event_at":"2026-07-27T05:38:16.463000Z","event_fingerprint":"468ac6f1861c0adf2ed3ec80872b4749e873c99ffd1ea57ad0d2e33eced64969","payload":{"connection_id":"efc69d3132f1467b8e898a382b23ac0d","event_at":"2026-07-27T05:38:16.463000Z","event_type":"price_change","frame_hash":"7cc4f6c2cf83a6ab529111c74aca2e8f079f76e709f5631faabb66fbf5906ce2","frame_index":0,"kind":"data","monotonic_ns":232680700279125,"payload":{"event_type":"price_change","market":"0x3b40066b5cf3871a2f6237c5628bd8092a206aa998558ac5ec13c4483e31e160","price_changes":[{"asset_id":"110216635572655435074987471276357323571387854733835379371586402147734167783946","best_ask":"0.63","best_bid":"0.62","hash":"779129398a0ba13fcbbca4a5479f3d171f4d76db","price":"0.52","side":"BUY","size":"48"},{"asset_id":"14766054693214075530629349735273995982307625376442606753688071083149620216746","best_ask":"0.38","best_bid":"0.37","hash":"cf3481c102856ab215f26b810f5b9546337cb6c7","price":"0.48","side":"SELL","size":"48"}],"timestamp":"1785130696463"},"payload_hash":"b3402e53763e0a130abba44ac731cc01ebf80b8604003670009f7db1e14b55fc","raw_frame":"{\"market\":\"0x3b40066b5cf3871a2f6237c5628bd8092a206aa998558ac5ec13c4483e31e160\", \"price_changes\":[{\"asset_id\":\"110216635572655435074987471276357323571387854733835379371586402147734167783946\", \"price\":\"0.52\", \"size\":\"48\", \"side\":\"BUY\", \"hash\":\"779129398a0ba13fcbbca4a5479f3d171f4d76db\", \"best_bid\":\"0.62\", \"best_ask\":\"0.63\"}, {\"asset_id\":\"14766054693214075530629349735273995982307625376442606753688071083149620216746\", \"price\":\"0.48\", \"size\":\"48\", \"side\":\"SELL\", \"hash\":\"cf3481c102856ab215f26b810f5b9546337cb6c7\", \"best_bid\":\"0.37\", \"best_ask\":\"0.38\"}], \"timestamp\":\"1785130696463\", \"event_type\":\"price_change\"}","received_at":"2026-07-27T05:38:17.465527Z","schema_version":"clob-market-ws.price_change.v1","sequence":null,"server_hash":null,"server_timestamp":"1785130696463","session_id":"502006c5cfcd437296561ea750c9ec8b","source":"clob_market_ws"},"received_at":"2026-07-27T05:38:17.465527Z","record_id":"558f07de729f4d983a5e2ff309f1ecc6fe98c5b8f6ddc2615963d3015f04ea18","schema_fingerprint":"4aa3821a28b0b7c2400bc59aba4bcc0a76e971dadd19610d3ad38c768e124dc7","schema_version":"edge-lab-recorder.raw.v1","sequence":null,"source":"clob_market_ws"}
{"event_at":"2026-07-27T05:38:16.463000Z","event_fingerprint":"0701d14978ea50abf4bdee9a29e5c628151276c32e22d228920ed1701648b9e0","payload":{"connection_id":"efc69d3132f1467b8e898a382b23ac0d","event_at":"2026-07-27T05:38:16.463000Z","event_type":"best_bid_ask","frame_hash":"f2ee1f4075334ad801de065b1c25ccccb4233e641924c8252ddd943b35054656","frame_index":0,"kind":"data","monotonic_ns":232680705291625,"payload":{"asset_id":"14766054693214075530629349735273995982307625376442606753688071083149620216746","best_ask":"0.39","best_bid":"0.37","event_type":"best_bid_ask","market":"0x3b40066b5cf3871a2f6237c5628bd8092a206aa998558ac5ec13c4483e31e160","spread":"0.02","timestamp":"1785130696463"},"payload_hash":"0565c104762c3a286a391f50a73670f8d60b4cd955b3e7130f8b8a8392f49507","raw_frame":"{\"market\":\"0x3b40066b5cf3871a2f6237c5628bd8092a206aa998558ac5ec13c4483e31e160\", \"asset_id\":\"14766054693214075530629349735273995982307625376442606753688071083149620216746\", \"best_bid\":\"0.37\", \"best_ask\":\"0.39\", \"spread\":\"0.02\", \"timestamp\":\"1785130696463\", \"event_type\":\"best_bid_ask\"}","received_at":"2026-07-27T05:38:17.470540Z","schema_version":"clob-market-ws.best_bid_ask.v1","sequence":null,"server_hash":null,"server_timestamp":"1785130696463","session_id":"502006c5cfcd437296561ea750c9ec8b","source":"clob_market_ws"},"received_at":"2026-07-27T05:38:17.470540Z","record_id":"f73fb295d76c917d113a8fde311945f04683cede1a059280fb98051aa60ae909","schema_fingerprint":"8488399f31b0337811b13b266be932db7062827c2470b78bd8e9e99bab51d17d","schema_version":"edge-lab-recorder.raw.v1","sequence":null,"source":"clob_market_ws"}
{"event_at":"2026-07-27T05:38:16.463000Z","event_fingerprint":"b96d076b46cf33f2fc8f55792ecb7507063ad1a4bd1322e04e4cabeeeb8df3fe","payload":{"connection_id":"efc69d3132f1467b8e898a382b23ac0d","event_at":"2026-07-27T05:38:16.463000Z","event_type":"best_bid_ask","frame_hash":"cb999dd7272619a315b25a3ca3de558983f9a8c77280123a77ff4a4656b25828","frame_index":0,"kind":"data","monotonic_ns":232680709439833,"payload":{"asset_id":"110216635572655435074987471276357323571387854733835379371586402147734167783946","best_ask":"0.63","best_bid":"0.61","event_type":"best_bid_ask","market":"0x3b40066b5cf3871a2f6237c5628bd8092a206aa998558ac5ec13c4483e31e160","spread":"0.02","timestamp":"1785130696463"},"payload_hash":"4d0c4bbf1fc986a08b387870373fd0a88c06d233099236e2fe4e6793e08a875a","raw_frame":"{\"market\":\"0x3b40066b5cf3871a2f6237c5628bd8092a206aa998558ac5ec13c4483e31e160\", \"asset_id\":\"110216635572655435074987471276357323571387854733835379371586402147734167783946\", \"best_bid\":\"0.61\", \"best_ask\":\"0.63\", \"spread\":\"0.02\", \"timestamp\":\"1785130696463\", \"event_type\":\"best_bid_ask\"}","received_at":"2026-07-27T05:38:17.474687Z","schema_version":"clob-market-ws.best_bid_ask.v1","sequence":null,"server_hash":null,"server_timestamp":"1785130696463","session_id":"502006c5cfcd437296561ea750c9ec8b","source":"clob_market_ws"},"received_at":"2026-07-27T05:38:17.474687Z","record_id":"48f2312636ccbd70ce6656a5673446da7ebcff7eb9076dd8fa0f4ba35e24b050","schema_fingerprint":"8488399f31b0337811b13b266be932db7062827c2470b78bd8e9e99bab51d17d","schema_version":"edge-lab-recorder.raw.v1","sequence":null,"source":"clob_market_ws"}
{"event_at":"2026-07-27T05:38:16.463000Z","event_fingerprint":"08eacc3392c00cb3ed972397e417938d52de094ad237f539204cf4834a8edb1c","payload":{"connection_id":"efc69d3132f1467b8e898a382b23ac0d","event_at":"2026-07-27T05:38:16.463000Z","event_type":"price_change","frame_hash":"b9d39cc1a943c5a5d7845dc2e7a4526b607125513d5fbcf75157e115d364e8be","frame_index":0,"kind":"data","monotonic_ns":232680714108000,"payload":{"event_type":"price_change","market":"0x3b40066b5cf3871a2f6237c5628bd8092a206aa998558ac5ec13c4483e31e160","price_changes":[{"asset_id":"110216635572655435074987471276357323571387854733835379371586402147734167783946","best_ask":"0.63","best_bid":"0.61","hash":"f7ad8e86524c1754eeef97bf428566bd0bd44d2a","price":"0.62","side":"BUY","size":"0"},{"asset_id":"14766054693214075530629349735273995982307625376442606753688071083149620216746","best_ask":"0.39","best_bid":"0.37","hash":"1ef39f31940ff5bc2d694faef712a64c39029875","price":"0.38","side":"SELL","size":"0"}],"timestamp":"1785130696463"},"payload_hash":"6f6902d5d7d08fc397d8c368faf74c0a6a375d08081da8c2242e75087da2a06c","raw_frame":"{\"market\":\"0x3b40066b5cf3871a2f6237c5628bd8092a206aa998558ac5ec13c4483e31e160\", \"price_changes\":[{\"asset_id\":\"110216635572655435074987471276357323571387854733835379371586402147734167783946\", \"price\":\"0.62\", \"size\":\"0\", \"side\":\"BUY\", \"hash\":\"f7ad8e86524c1754eeef97bf428566bd0bd44d2a\", \"best_bid\":\"0.61\", \"best_ask\":\"0.63\"}, {\"asset_id\":\"14766054693214075530629349735273995982307625376442606753688071083149620216746\", \"price\":\"0.38\", \"size\":\"0\", \"side\":\"SELL\", \"hash\":\"1ef39f31940ff5bc2d694faef712a64c39029875\", \"best_bid\":\"0.37\", \"best_ask\":\"0.39\"}], \"timestamp\":\"1785130696463\", \"event_type\":\"price_change\"}","received_at":"2026-07-27T05:38:17.479355Z","schema_version":"clob-market-ws.price_change.v1","sequence":null,"server_hash":null,"server_timestamp":"1785130696463","session_id":"502006c5cfcd437296561ea750c9ec8b","source":"clob_market_ws"},"received_at":"2026-07-27T05:38:17.479355Z","record_id":"95cbd758441bff53e05471d2570a52afab3b03864b732fbc7757f908885cc8a3","schema_fingerprint":"4aa3821a28b0b7c2400bc59aba4bcc0a76e971dadd19610d3ad38c768e124dc7","schema_version":"edge-lab-recorder.raw.v1","sequence":null,"source":"clob_market_ws"}
{"event_at":"2026-07-27T05:38:16.463000Z","event_fingerprint":"c66aae2c455d3e8a284a1ad9aba7dcbc8443e9c03a78fc5a8fbd3812a138da4a","payload":{"connection_id":"efc69d3132f1467b8e898a382b23ac0d","event_at":"2026-07-27T05:38:16.463000Z","event_type":"price_change","frame_hash":"b22ba4d240e68b8b6a264ed398b3143ab0a13b40fd28ac7b279ebffba06415ed","frame_index":0,"kind":"data","monotonic_ns":232680716310583,"payload":{"event_type":"price_change","market":"0x3b40066b5cf3871a2f6237c5628bd8092a206aa998558ac5ec13c4483e31e160","price_changes":[{"asset_id":"14766054693214075530629349735273995982307625376442606753688071083149620216746","best_ask":"0.39","best_bid":"0.37","hash":"f611480e1058f6f8292bdacfd421a3dbf4a7de14","price":"0.36","side":"BUY","size":"425.4"},{"asset_id":"110216635572655435074987471276357323571387854733835379371586402147734167783946","best_ask":"0.63","best_bid":"0.61","hash":"95293e6846dc9bafb84a6cc0255b4135153c2363","price":"0.64","side":"SELL","size":"425.4"}],"timestamp":"1785130696463"},"payload_hash":"999256d3dc0333d81577fbf321d566fe57b95d35c970b81308165663c0f1d036","raw_frame":"{\"market\":\"0x3b40066b5cf3871a2f6237c5628bd8092a206aa998558ac5ec13c4483e31e160\", \"price_changes\":[{\"asset_id\":\"14766054693214075530629349735273995982307625376442606753688071083149620216746\", \"price\":\"0.36\", \"size\":\"425.4\", \"side\":\"BUY\", \"hash\":\"f611480e1058f6f8292bdacfd421a3dbf4a7de14\", \"best_bid\":\"0.37\", \"best_ask\":\"0.39\"}, {\"asset_id\":\"110216635572655435074987471276357323571387854733835379371586402147734167783946\", \"price\":\"0.64\", \"size\":\"425.4\", \"side\":\"SELL\", \"hash\":\"95293e6846dc9bafb84a6cc0255b4135153c2363\", \"best_bid\":\"0.61\", \"best_ask\":\"0.63\"}], \"timestamp\":\"1785130696463\", \"event_type\":\"price_change\"}","received_at":"2026-07-27T05:38:17.481564Z","schema_version":"clob-market-ws.price_change.v1","sequence":null,"server_hash":null,"server_timestamp":"1785130696463","session_id":"502006c5cfcd437296561ea750c9ec8b","source":"clob_market_ws"},"received_at":"2026-07-27T05:38:17.481564Z","record_id":"3f03775d62101bbed443b1f157c3c07493ae34d55e714affc36be2a63e67d104","schema_fingerprint":"4aa3821a28b0b7c2400bc59aba4bcc0a76e971dadd19610d3ad38c768e124dc7","schema_version":"edge-lab-recorder.raw.v1","sequence":null,"source":"clob_market_ws"}
