{"event_at":"2026-07-27T05:42:59.431000Z","event_fingerprint":"2d88322f0af406edf924889a13d2c088ce115656cb480343f41ad0c395a8bb35","payload":{"connection_id":"efc69d3132f1467b8e898a382b23ac0d","event_at":"2026-07-27T05:42:59.431000Z","event_type":"price_change","frame_hash":"ee8202142d2cb97b3ce1438105c49efbc6b557ae21b1a0aaa217d645dc137b87","frame_index":0,"kind":"data","monotonic_ns":232962704575375,"payload":{"event_type":"price_change","market":"0x3b40066b5cf3871a2f6237c5628bd8092a206aa998558ac5ec13c4483e31e160","price_changes":[{"asset_id":"110216635572655435074987471276357323571387854733835379371586402147734167783946","best_ask":"0.42","best_bid":"0.41","hash":"f2748f3b6a83619a8eb3fd78d7e6ee9193230278","price":"0.33","side":"BUY","size":"33.73"},{"asset_id":"14766054693214075530629349735273995982307625376442606753688071083149620216746","best_ask":"0.59","best_bid":"0.58","hash":"2fd06092b36d42bedc72032a848cc15544e2376b","price":"0.67","side":"SELL","size":"33.73"}],"timestamp":"1785130979431"},"payload_hash":"a4e4c8d821c0edbd8df6ef9e0d21409a0d9c8370d9e8d169f42977ccf493dcab","raw_frame":"{\"market\":\"0x3b40066b5cf3871a2f6237c5628bd8092a206aa998558ac5ec13c4483e31e160\", \"price_changes\":[{\"asset_id\":\"110216635572655435074987471276357323571387854733835379371586402147734167783946\", \"price\":\"0.33\", \"size\":\"33.73\", \"side\":\"BUY\", \"hash\":\"f2748f3b6a83619a8eb3fd78d7e6ee9193230278\", \"best_bid\":\"0.41\", \"best_ask\":\"0.42\"}, {\"asset_id\":\"14766054693214075530629349735273995982307625376442606753688071083149620216746\", \"price\":\"0.67\", \"size\":\"33.73\", \"side\":\"SELL\", \"hash\":\"2fd06092b36d42bedc72032a848cc15544e2376b\", \"best_bid\":\"0.58\", \"best_ask\":\"0.59\"}], \"timestamp\":\"1785130979431\", \"event_type\":\"price_change\"}","received_at":"2026-07-27T05:42:59.471779Z","schema_version":"clob-market-ws.price_change.v1","sequence":null,"server_hash":null,"server_timestamp":"1785130979431","session_id":"502006c5cfcd437296561ea750c9ec8b","source":"clob_market_ws"},"received_at":"2026-07-27T05:42:59.471779Z","record_id":"d6b7299298699fbe43823248a51a4bb3a189bb9e9c9aa348b763c70a4eb37762","schema_fingerprint":"4aa3821a28b0b7c2400bc59aba4bcc0a76e971dadd19610d3ad38c768e124dc7","schema_version":"edge-lab-recorder.raw.v1","sequence":null,"source":"clob_market_ws"}
{"event_at":"2026-07-27T05:42:59.431000Z","event_fingerprint":"12aa257c86fed02d5389b25c4c37856d96987a02b5fbe1a47c06b17ee8b5a6a0","payload":{"connection_id":"efc69d3132f1467b8e898a382b23ac0d","event_at":"2026-07-27T05:42:59.431000Z","event_type":"price_change","frame_hash":"d0acfa6119067dfd9b5bac99b6841e0f699f0eb9ae86af6b807597966824feca","frame_index":0,"kind":"data","monotonic_ns":232962710666875,"payload":{"event_type":"price_change","market":"0x3b40066b5cf3871a2f6237c5628bd8092a206aa998558ac5ec13c4483e31e160","price_changes":[{"asset_id":"14766054693214075530629349735273995982307625376442606753688071083149620216746","best_ask":"0.59","best_bid":"0.58","hash":"ef25e2abcf25f01b37acf293c07151c187b96925","price":"0.57","side":"BUY","size":"449"},{"asset_id":"110216635572655435074987471276357323571387854733835379371586402147734167783946","best_ask":"0.42","best_bid":"0.41","hash":"67452903ff4b3f3ef7ce659fb795d94c764c2c86","price":"0.43","side":"SELL","size":"449"}],"timestamp":"1785130979431"},"payload_hash":"e2021fe4879c9fc0960a0b17f0ab6440b9d60cd1096dd7bdb50daf810a2acaf3","raw_frame":"{\"market\":\"0x3b40066b5cf3871a2f6237c5628bd8092a206aa998558ac5ec13c4483e31e160\", \"price_changes\":[{\"asset_id\":\"14766054693214075530629349735273995982307625376442606753688071083149620216746\", \"price\":\"0.57\", \"size\":\"449\", \"side\":\"BUY\", \"hash\":\"ef25e2abcf25f01b37acf293c07151c187b96925\", \"best_bid\":\"0.58\", \"best_ask\":\"0.59\"}, {\"asset_id\":\"110216635572655435074987471276357323571387854733835379371586402147734167783946\", \"price\":\"0.43\", \"size\":\"449\", \"side\":\"SELL\", \"hash\":\"67452903ff4b3f3ef7ce659fb795d94c764c2c86\", \"best_bid\":\"0.41\", \"best_ask\":\"0.42\"}], \"timestamp\":\"1785130979431\", \"event_type\":\"price_change\"}","received_at":"2026-07-27T05:42:59.477873Z","schema_version":"clob-market-ws.price_change.v1","sequence":null,"server_hash":null,"server_timestamp":"1785130979431","session_id":"502006c5cfcd437296561ea750c9ec8b","source":"clob_market_ws"},"received_at":"2026-07-27T05:42:59.477873Z","record_id":"d7c7c20974320ca7dd272afe71bf5b5531c5362c1c16d3c898e8eba20e6dc41c","schema_fingerprint":"4aa3821a28b0b7c2400bc59aba4bcc0a76e971dadd19610d3ad38c768e124dc7","schema_version":"edge-lab-recorder.raw.v1","sequence":null,"source":"clob_market_ws"}
{"event_at":"2026-07-27T05:42:59.433000Z","event_fingerprint":"d0554c78ea30c822c657d1340c3e1a2076e7a26f28684b9828fed380ed80adcb","payload":{"connection_id":"efc69d3132f1467b8e898a382b23ac0d","event_at":"2026-07-27T05:42:59.433000Z","event_type":"price_change","frame_hash":"823050a1f1e7b56f722e22333df4c3a6b66968912bfc8d0804748f5abe65c29a","frame_index":0,"kind":"data","monotonic_ns":232962713041833,"payload":{"event_type":"price_change","market":"0x3b40066b5cf3871a2f6237c5628bd8092a206aa998558ac5ec13c4483e31e160","price_changes":[{"asset_id":"110216635572655435074987471276357323571387854733835379371586402147734167783946","best_ask":"0.42","best_bid":"0.41","hash":"89f374290598d57f410e24e6af0e31d69bb34180","price":"0.36","side":"BUY","size":"8"},{"asset_id":"14766054693214075530629349735273995982307625376442606753688071083149620216746","best_ask":"0.59","best_bid":"0.58","hash":"189cbd825463da0f6e807fb1a0cbaa224386ee68","price":"0.64","side":"SELL","size":"8"}],"timestamp":"1785130979433"},"payload_hash":"ae954bcbf08d105658de7af178e5b71311b84a10224f24400b2ec61d56fc6fc3","raw_frame":"{\"market\":\"0x3b40066b5cf3871a2f6237c5628bd8092a206aa998558ac5ec13c4483e31e160\", \"price_changes\":[{\"asset_id\":\"110216635572655435074987471276357323571387854733835379371586402147734167783946\", \"price\":\"0.36\", \"size\":\"8\", \"side\":\"BUY\", \"hash\":\"89f374290598d57f410e24e6af0e31d69bb34180\", \"best_bid\":\"0.41\", \"best_ask\":\"0.42\"}, {\"asset_id\":\"14766054693214075530629349735273995982307625376442606753688071083149620216746\", \"price\":\"0.64\", \"size\":\"8\", \"side\":\"SELL\", \"hash\":\"189cbd825463da0f6e807fb1a0cbaa224386ee68\", \"best_bid\":\"0.58\", \"best_ask\":\"0.59\"}], \"timestamp\":\"1785130979433\", \"event_type\":\"price_change\"}","received_at":"2026-07-27T05:42:59.480245Z","schema_version":"clob-market-ws.price_change.v1","sequence":null,"server_hash":null,"server_timestamp":"1785130979433","session_id":"502006c5cfcd437296561ea750c9ec8b","source":"clob_market_ws"},"received_at":"2026-07-27T05:42:59.480245Z","record_id":"caf998decb685352e3842843c0b492d7472531f0ecd9621e6a560122806e32ec","schema_fingerprint":"4aa3821a28b0b7c2400bc59aba4bcc0a76e971dadd19610d3ad38c768e124dc7","schema_version":"edge-lab-recorder.raw.v1","sequence":null,"source":"clob_market_ws"}
{"event_at":"2026-07-27T05:42:59.433000Z","event_fingerprint":"23a5d6a339af91729f890c31496ed3e74111dea7a00adc045ed2fa443c6fff79","payload":{"connection_id":"efc69d3132f1467b8e898a382b23ac0d","event_at":"2026-07-27T05:42:59.433000Z","event_type":"price_change","frame_hash":"6ae8df4449d32213a26e12f755457595bacfc498ac20b4dc1d8f110d4340fc39","frame_index":0,"kind":"data","monotonic_ns":232962715726500,"payload":{"event_type":"price_change","market":"0x3b40066b5cf3871a2f6237c5628bd8092a206aa998558ac5ec13c4483e31e160","price_changes":[{"asset_id":"110216635572655435074987471276357323571387854733835379371586402147734167783946","best_ask":"0.42","best_bid":"0.41","hash":"168e44ed19ebefe4d3db8a4c79653dc837b81717","price":"0.35","side":"BUY","size":"0"},{"asset_id":"14766054693214075530629349735273995982307625376442606753688071083149620216746","best_ask":"0.59","best_bid":"0.58","hash":"7936f2a8dc317b49ff2a1167a28dc0a6f1d47a27","price":"0.65","side":"SELL","size":"0"}],"timestamp":"1785130979433"},"payload_hash":"30ec390464b649557d7f5cbc16bef39ff8063efddd863cf7a3a4dc83f3215855","raw_frame":"{\"market\":\"0x3b40066b5cf3871a2f6237c5628bd8092a206aa998558ac5ec13c4483e31e160\", \"price_changes\":[{\"asset_id\":\"110216635572655435074987471276357323571387854733835379371586402147734167783946\", \"price\":\"0.35\", \"size\":\"0\", \"side\":\"BUY\", \"hash\":\"168e44ed19ebefe4d3db8a4c79653dc837b81717\", \"best_bid\":\"0.41\", \"best_ask\":\"0.42\"}, {\"asset_id\":\"14766054693214075530629349735273995982307625376442606753688071083149620216746\", \"price\":\"0.65\", \"size\":\"0\", \"side\":\"SELL\", \"hash\":\"7936f2a8dc317b49ff2a1167a28dc0a6f1d47a27\", \"best_bid\":\"0.58\", \"best_ask\":\"0.59\"}], \"timestamp\":\"1785130979433\", \"event_type\":\"price_change\"}","received_at":"2026-07-27T05:42:59.482931Z","schema_version":"clob-market-ws.price_change.v1","sequence":null,"server_hash":null,"server_timestamp":"1785130979433","session_id":"502006c5cfcd437296561ea750c9ec8b","source":"clob_market_ws"},"received_at":"2026-07-27T05:42:59.482931Z","record_id":"f79ffe7b27a0137f312981a02fad0739c130213a24ffc516f05f68c09a468a4c","schema_fingerprint":"4aa3821a28b0b7c2400bc59aba4bcc0a76e971dadd19610d3ad38c768e124dc7","schema_version":"edge-lab-recorder.raw.v1","sequence":null,"source":"clob_market_ws"}
{"event_at":"2026-07-27T05:42:59.481000Z","event_fingerprint":"b02dc74d047d10792774e9268c0dda5c5005e2bf5099bfd57be88d472a9c579a","payload":{"connection_id":"efc69d3132f1467b8e898a382b23ac0d","event_at":"2026-07-27T05:42:59.481000Z","event_type":"price_change","frame_hash":"70784a16631699b79be874f4eb013e8d8499bda656dc1117ec35a53cfcf644dc","frame_index":0,"kind":"data","monotonic_ns":232962718262833,"payload":{"event_type":"price_change","market":"0x3b40066b5cf3871a2f6237c5628bd8092a206aa998558ac5ec13c4483e31e160","price_changes":[{"asset_id":"14766054693214075530629349735273995982307625376442606753688071083149620216746","best_ask":"0.59","best_bid":"0.58","hash":"6a19ec55dadf1b3810f5f1ed010cca535969073f","price":"0.59","side":"SELL","size":"16"},{"asset_id":"110216635572655435074987471276357323571387854733835379371586402147734167783946","best_ask":"0.42","best_bid":"0.41","hash":"7f92b53fb5fd44c8c741b36749910d9f0486ee9e","price":"0.41","side":"BUY","size":"16"}],"timestamp":"1785130979481"},"payload_hash":"dad5ae1ef1838f21c4a1e5976e3c8dc7aa481ca80f9b461a536c45b4072108b6","raw_frame":"{\"market\":\"0x3b40066b5cf3871a2f6237c5628bd8092a206aa998558ac5ec13c4483e31e160\", \"price_changes\":[{\"asset_id\":\"14766054693214075530629349735273995982307625376442606753688071083149620216746\", \"price\":\"0.59\", \"size\":\"16\", \"side\":\"SELL\", \"hash\":\"6a19ec55dadf1b3810f5f1ed010cca535969073f\", \"best_bid\":\"0.58\", \"best_ask\":\"0.59\"}, {\"asset_id\":\"110216635572655435074987471276357323571387854733835379371586402147734167783946\", \"price\":\"0.41\", \"size\":\"16\", \"side\":\"BUY\", \"hash\":\"7f92b53fb5fd44c8c741b36749910d9f0486ee9e\", \"best_bid\":\"0.41\", \"best_ask\":\"0.42\"}], \"timestamp\":\"1785130979481\", \"event_type\":\"price_change\"}","received_at":"2026-07-27T05:42:59.485470Z","schema_version":"clob-market-ws.price_change.v1","sequence":null,"server_hash":null,"server_timestamp":"1785130979481","session_id":"502006c5cfcd437296561ea750c9ec8b","source":"clob_market_ws"},"received_at":"2026-07-27T05:42:59.485470Z","record_id":"7a51807e7721dbac6bed90fb4025faf786933b139d19486222259260514aaea8","schema_fingerprint":"4aa3821a28b0b7c2400bc59aba4bcc0a76e971dadd19610d3ad38c768e124dc7","schema_version":"edge-lab-recorder.raw.v1","sequence":null,"source":"clob_market_ws"}
{"event_at":"2026-07-27T05:42:59.499000Z","event_fingerprint":"f6a3a064cddf7329ab88930154d30375d6994d7e659c6e895042ca00cfe059a0","payload":{"connection_id":"efc69d3132f1467b8e898a382b23ac0d","event_at":"2026-07-27T05:42:59.499000Z","event_type":"price_change","frame_hash":"870b5dbc185aecd17cdeff28a059358a83e80e8f60703784d4baf3b80c86e41b","frame_index":0,"kind":"data","monotonic_ns":232962721917166,"payload":{"event_type":"price_change","market":"0x3b40066b5cf3871a2f6237c5628bd8092a206aa998558ac5ec13c4483e31e160","price_changes":[{"asset_id":"110216635572655435074987471276357323571387854733835379371586402147734167783946","best_ask":"0.42","best_bid":"0.41","hash":"d030894f299df07262a5535f19037ee702d34a7d","price":"0.41","side":"BUY","size":"6"},{"asset_id":"14766054693214075530629349735273995982307625376442606753688071083149620216746","best_ask":"0.59","best_bid":"0.58","hash":"bbd3f852a709a734283b2ca6fd2ed386d3a13831","price":"0.59","side":"SELL","size":"6"}],"timestamp":"1785130979499"},"payload_hash":"858e9e37609e44a31a88617366310859fdc78a8d84dd5a0864d9b63e0b8da72e","raw_frame":"{\"market\":\"0x3b40066b5cf3871a2f6237c5628bd8092a206aa998558ac5ec13c4483e31e160\", \"price_changes\":[{\"asset_id\":\"110216635572655435074987471276357323571387854733835379371586402147734167783946\", \"price\":\"0.41\", \"size\":\"6\", \"side\":\"BUY\", \"hash\":\"d030894f299df07262a5535f19037ee702d34a7d\", \"best_bid\":\"0.41\", \"best_ask\":\"0.42\"}, {\"asset_id\":\"14766054693214075530629349735273995982307625376442606753688071083149620216746\", \"price\":\"0.59\", \"size\":\"6\", \"side\":\"SELL\", \"hash\":\"bbd3f852a709a734283b2ca6fd2ed386d3a13831\", \"best_bid\":\"0.58\", \"best_ask\":\"0.59\"}], \"timestamp\":\"1785130979499\", \"event_type\":\"price_change\"}","received_at":"2026-07-27T05:42:59.489123Z","schema_version":"clob-market-ws.price_change.v1","sequence":null,"server_hash":null,"server_timestamp":"1785130979499","session_id":"502006c5cfcd437296561ea750c9ec8b","source":"clob_market_ws"},"received_at":"2026-07-27T05:42:59.489123Z","record_id":"8da5ea18a1868ce10f266f0e7d3320653f1609b8002ccaca594f20ad72776792","schema_fingerprint":"4aa3821a28b0b7c2400bc59aba4bcc0a76e971dadd19610d3ad38c768e124dc7","schema_version":"edge-lab-recorder.raw.v1","sequence":null,"source":"clob_market_ws"}
{"event_at":"2026-07-27T05:42:59.505000Z","event_fingerprint":"0728cfdb6907fd7c887ccb52a683e013f4b728e24de580eb54b4bdf81b1a1816","payload":{"connection_id":"efc69d3132f1467b8e898a382b23ac0d","event_at":"2026-07-27T05:42:59.505000Z","event_type":"price_change","frame_hash":"4b01a196d4ad4fc7c2599db7f10d2264c6b8bac4d4b4330d2070dc55d4eb8795","frame_index":0,"kind":"data","monotonic_ns":232962724238333,"payload":{"event_type":"price_change","market":"0x3b40066b5cf3871a2f6237c5628bd8092a206aa998558ac5ec13c4483e31e160","price_changes":[{"asset_id":"14766054693214075530629349735273995982307625376442606753688071083149620216746","best_ask":"0.59","best_bid":"0.58","hash":"08d305e3a7ca02222232b6d315d00d95ccaf12dc","price":"0.57","side":"BUY","size":"424"},{"asset_id":"110216635572655435074987471276357323571387854733835379371586402147734167783946","best_ask":"0.42","best_bid":"0.41","hash":"3f7c49b51447d47f6d8c43822e68b865d369f583","price":"0.43","side":"SELL","size":"424"}],"timestamp":"1785130979505"},"payload_hash":"4684623e77589cec1a33ed76d2d5245cae5c59d140d57b6544583a7969a4a052","raw_frame":"{\"market\":\"0x3b40066b5cf3871a2f6237c5628bd8092a206aa998558ac5ec13c4483e31e160\", \"price_changes\":[{\"asset_id\":\"14766054693214075530629349735273995982307625376442606753688071083149620216746\", \"price\":\"0.57\", \"size\":\"424\", \"side\":\"BUY\", \"hash\":\"08d305e3a7ca02222232b6d315d00d95ccaf12dc\", \"best_bid\":\"0.58\", \"best_ask\":\"0.59\"}, {\"asset_id\":\"110216635572655435074987471276357323571387854733835379371586402147734167783946\", \"price\":\"0.43\", \"size\":\"424\", \"side\":\"SELL\", \"hash\":\"3f7c49b51447d47f6d8c43822e68b865d369f583\", \"best_bid\":\"0.41\", \"best_ask\":\"0.42\"}], \"timestamp\":\"1785130979505\", \"event_type\":\"price_change\"}","received_at":"2026-07-27T05:42:59.491446Z","schema_version":"clob-market-ws.price_change.v1","sequence":null,"server_hash":null,"server_timestamp":"1785130979505","session_id":"502006c5cfcd437296561ea750c9ec8b","source":"clob_market_ws"},"received_at":"2026-07-27T05:42:59.491446Z","record_id":"15463edb7afcaa982e6e39749682948d5ff81cee80d4a19cd8278ff10cfed8b2","schema_fingerprint":"4aa3821a28b0b7c2400bc59aba4bcc0a76e971dadd19610d3ad38c768e124dc7","schema_version":"edge-lab-recorder.raw.v1","sequence":null,"source":"clob_market_ws"}
{"event_at":"2026-07-27T05:42:59.506000Z","event_fingerprint":"b141e5210f6df7c4c5b0f90f0c9c6b4329fff3ae01c5a9e561654c04b3d7b26a","payload":{"connection_id":"efc69d3132f1467b8e898a382b23ac0d","event_at":"2026-07-27T05:42:59.506000Z","event_type":"price_change","frame_hash":"5e53c315ac2d22a8ab6e7b6becb23d0be6ab5c2acd20cfd7368bdb03113bd7d8","frame_index":0,"kind":"data","monotonic_ns":232962727841625,"payload":{"event_type":"price_change","market":"0x3b40066b5cf3871a2f6237c5628bd8092a206aa998558ac5ec13c4483e31e160","price_changes":[{"asset_id":"110216635572655435074987471276357323571387854733835379371586402147734167783946","best_ask":"0.42","best_bid":"0.41","hash":"2cc228b19cd110d9219de76419b3bab640276b65","price":"0.43","side":"SELL","size":"399"},{"asset_id":"14766054693214075530629349735273995982307625376442606753688071083149620216746","best_ask":"0.59","best_bid":"0.58","hash":"8509fa2ae65707a0b78eac64e2163112b0002731","price":"0.57","side":"BUY","size":"399"}],"timestamp":"1785130979506"},"payload_hash":"5af94e5c221d57d730290838f49f5874dc687c79dd24eb4f8c11a6e818046ee3","raw_frame":"{\"market\":\"0x3b40066b5cf3871a2f6237c5628bd8092a206aa998558ac5ec13c4483e31e160\", \"price_changes\":[{\"asset_id\":\"110216635572655435074987471276357323571387854733835379371586402147734167783946\", \"price\":\"0.43\", \"size\":\"399\", \"side\":\"SELL\", \"hash\":\"2cc228b19cd110d9219de76419b3bab640276b65\", \"best_bid\":\"0.41\", \"best_ask\":\"0.42\"}, {\"asset_id\":\"14766054693214075530629349735273995982307625376442606753688071083149620216746\", \"price\":\"0.57\", \"size\":\"399\", \"side\":\"BUY\", \"hash\":\"8509fa2ae65707a0b78eac64e2163112b0002731\", \"best_bid\":\"0.58\", \"best_ask\":\"0.59\"}], \"timestamp\":\"1785130979506\", \"event_type\":\"price_change\"}","received_at":"2026-07-27T05:42:59.495046Z","schema_version":"clob-market-ws.price_change.v1","sequence":null,"server_hash":null,"server_timestamp":"1785130979506","session_id":"502006c5cfcd437296561ea750c9ec8b","source":"clob_market_ws"},"received_at":"2026-07-27T05:42:59.495046Z","record_id":"4e8186a34480c249dd135f6c522338ada8dbd3f5a00a32960a8b791cb1661767","schema_fingerprint":"4aa3821a28b0b7c2400bc59aba4bcc0a76e971dadd19610d3ad38c768e124dc7","schema_version":"edge-lab-recorder.raw.v1","sequence":null,"source":"clob_market_ws"}
{"event_at":"2026-07-27T05:42:59.509000Z","event_fingerprint":"b9a4dd7eb287a8758a2455787310205d529d9c03e1c4fc533bef5e0eddabce53","payload":{"connection_id":"efc69d3132f1467b8e898a382b23ac0d","event_at":"2026-07-27T05:42:59.509000Z","event_type":"price_change","frame_hash":"1a517065af1faef6a42a0574503638c0e7cf273ac661f7c694429dfe05077a84","frame_index":0,"kind":"data","monotonic_ns":232962729608833,"payload":{"event_type":"price_change","market":"0x3b40066b5cf3871a2f6237c5628bd8092a206aa998558ac5ec13c4483e31e160","price_changes":[{"asset_id":"14766054693214075530629349735273995982307625376442606753688071083149620216746","best_ask":"0.59","best_bid":"0.58","hash":"9a3ac06c5d7a56be944a520ce7c76a5e488f164e","price":"0.03","side":"BUY","size":"537"},{"asset_id":"110216635572655435074987471276357323571387854733835379371586402147734167783946","best_ask":"0.42","best_bid":"0.41","hash":"da6323b6ad9d9bd9a7b0159e0ce2d9ef31deb256","price":"0.97","side":"SELL","size":"537"}],"timestamp":"1785130979509"},"payload_hash":"74412eec6968715acddff61f5de2ef5679f1a37d0f820e15bf922b371db66dda","raw_frame":"{\"market\":\"0x3b40066b5cf3871a2f6237c5628bd8092a206aa998558ac5ec13c4483e31e160\", \"price_changes\":[{\"asset_id\":\"14766054693214075530629349735273995982307625376442606753688071083149620216746\", \"price\":\"0.03\", \"size\":\"537\", \"side\":\"BUY\", \"hash\":\"9a3ac06c5d7a56be944a520ce7c76a5e488f164e\", \"best_bid\":\"0.58\", \"best_ask\":\"0.59\"}, {\"asset_id\":\"110216635572655435074987471276357323571387854733835379371586402147734167783946\", \"price\":\"0.97\", \"size\":\"537\", \"side\":\"SELL\", \"hash\":\"da6323b6ad9d9bd9a7b0159e0ce2d9ef31deb256\", \"best_bid\":\"0.41\", \"best_ask\":\"0.42\"}], \"timestamp\":\"1785130979509\", \"event_type\":\"price_change\"}","received_at":"2026-07-27T05:42:59.496814Z","schema_version":"clob-market-ws.price_change.v1","sequence":null,"server_hash":null,"server_timestamp":"1785130979509","session_id":"502006c5cfcd437296561ea750c9ec8b","source":"clob_market_ws"},"received_at":"2026-07-27T05:42:59.496814Z","record_id":"bbd9dc738b290e3535306680d65039918b6bd5adcfd16f35c55f7a7522c8e9c2","schema_fingerprint":"4aa3821a28b0b7c2400bc59aba4bcc0a76e971dadd19610d3ad38c768e124dc7","schema_version":"edge-lab-recorder.raw.v1","sequence":null,"source":"clob_market_ws"}
{"event_at":"2026-07-27T05:42:59.521000Z","event_fingerprint":"370ef62f1d4d164e5d0b2ccb2de8e817e1a7f1e594411ae9c9bced5288ded88d","payload":{"connection_id":"efc69d3132f1467b8e898a382b23ac0d","event_at":"2026-07-27T05:42:59.521000Z","event_type":"price_change","frame_hash":"2ac0b355a2edb5726af094c86cca11dc72038d248c74bfdac34765b1f43e11d1","frame_index":0,"kind":"data","monotonic_ns":232962731474250,"payload":{"event_type":"price_change","market":"0x3b40066b5cf3871a2f6237c5628bd8092a206aa998558ac5ec13c4483e31e160","price_changes":[{"asset_id":"14766054693214075530629349735273995982307625376442606753688071083149620216746","best_ask":"0.59","best_bid":"0.58","hash":"511538bc086ad9b0a34cd0a457ce4e310e6ad45d","price":"0.59","side":"SELL","size":"15"},{"asset_id":"110216635572655435074987471276357323571387854733835379371586402147734167783946","best_ask":"0.42","best_bid":"0.41","hash":"793838247e7c62227828ad0e110a26eeffae2f88","price":"0.41","side":"BUY","size":"15"}],"timestamp":"1785130979521"},"payload_hash":"77257f487bf6788164e3b36091fa2b236f3ee9653d1c0baf7c7c8d9671bd53be","raw_frame":"{\"market\":\"0x3b40066b5cf3871a2f6237c5628bd8092a206aa998558ac5ec13c4483e31e160\", \"price_changes\":[{\"asset_id\":\"14766054693214075530629349735273995982307625376442606753688071083149620216746\", \"price\":\"0.59\", \"size\":\"15\", \"side\":\"SELL\", \"hash\":\"511538bc086ad9b0a34cd0a457ce4e310e6ad45d\", \"best_bid\":\"0.58\", \"best_ask\":\"0.59\"}, {\"asset_id\":\"110216635572655435074987471276357323571387854733835379371586402147734167783946\", \"price\":\"0.41\", \"size\":\"15\", \"side\":\"BUY\", \"hash\":\"793838247e7c62227828ad0e110a26eeffae2f88\", \"best_bid\":\"0.41\", \"best_ask\":\"0.42\"}], \"timestamp\":\"1785130979521\", \"event_type\":\"price_change\"}","received_at":"2026-07-27T05:42:59.498677Z","schema_version":"clob-market-ws.price_change.v1","sequence":null,"server_hash":null,"server_timestamp":"1785130979521","session_id":"502006c5cfcd437296561ea750c9ec8b","source":"clob_market_ws"},"received_at":"2026-07-27T05:42:59.498677Z","record_id":"267e1e1d1de0ac699f9d304b5f99944da744e2f860296a6b9f94537fcedf7fc1","schema_fingerprint":"4aa3821a28b0b7c2400bc59aba4bcc0a76e971dadd19610d3ad38c768e124dc7","schema_version":"edge-lab-recorder.raw.v1","sequence":null,"source":"clob_market_ws"}
{"event_at":"2026-07-27T05:42:59.522000Z","event_fingerprint":"95a28dce9ccf057222ac3e9fb87a1bca1ef166006bc1b1bc5fbcd7e50c880da9","payload":{"connection_id":"efc69d3132f1467b8e898a382b23ac0d","event_at":"2026-07-27T05:42:59.522000Z","event_type":"price_change","frame_hash":"941a4a8f366a13b0e949765e5bc758dc410a6114870c5fe94f8c431264c60b9a","frame_index":0,"kind":"data","monotonic_ns":232962733171583,"payload":{"event_type":"price_change","market":"0x3b40066b5cf3871a2f6237c5628bd8092a206aa998558ac5ec13c4483e31e160","price_changes":[{"asset_id":"110216635572655435074987471276357323571387854733835379371586402147734167783946","best_ask":"0.42","best_bid":"0.41","hash":"70ada593ed2c6c773e6c2c647485e7deb61b097d","price":"0.35","side":"BUY","size":"10"},{"asset_id":"14766054693214075530629349735273995982307625376442606753688071083149620216746","best_ask":"0.59","best_bid":"0.58","hash":"d791dcf14dcc08942907d79782d37f04150b0606","price":"0.65","side":"SELL","size":"10"}],"timestamp":"1785130979522"},"payload_hash":"6b127261dcd18faf399773a192ee9bdaf600937d7830f7ec255d203055457452","raw_frame":"{\"market\":\"0x3b40066b5cf3871a2f6237c5628bd8092a206aa998558ac5ec13c4483e31e160\", \"price_changes\":[{\"asset_id\":\"110216635572655435074987471276357323571387854733835379371586402147734167783946\", \"price\":\"0.35\", \"size\":\"10\", \"side\":\"BUY\", \"hash\":\"70ada593ed2c6c773e6c2c647485e7deb61b097d\", \"best_bid\":\"0.41\", \"best_ask\":\"0.42\"}, {\"asset_id\":\"14766054693214075530629349735273995982307625376442606753688071083149620216746\", \"price\":\"0.65\", \"size\":\"10\", \"side\":\"SELL\", \"hash\":\"d791dcf14dcc08942907d79782d37f04150b0606\", \"best_bid\":\"0.58\", \"best_ask\":\"0.59\"}], \"timestamp\":\"1785130979522\", \"event_type\":\"price_change\"}","received_at":"2026-07-27T05:42:59.500378Z","schema_version":"clob-market-ws.price_change.v1","sequence":null,"server_hash":null,"server_timestamp":"1785130979522","session_id":"502006c5cfcd437296561ea750c9ec8b","source":"clob_market_ws"},"received_at":"2026-07-27T05:42:59.500378Z","record_id":"dc9de35ae7b169a94576018fed8601376a91603546e5d473e986975787c18723","schema_fingerprint":"4aa3821a28b0b7c2400bc59aba4bcc0a76e971dadd19610d3ad38c768e124dc7","schema_version":"edge-lab-recorder.raw.v1","sequence":null,"source":"clob_market_ws"}
{"event_at":"2026-07-27T05:42:59.551000Z","event_fingerprint":"bc45e65cfe8a9ac329ef93fd539c75442e4716ba063048c57e5fe8b1e20ad40d","payload":{"connection_id":"efc69d3132f1467b8e898a382b23ac0d","event_at":"2026-07-27T05:42:59.551000Z","event_type":"price_change","frame_hash":"f6660b6d2d3d977d86508d7df551f669c0682e4624ea87f8409fa89db78f0381","frame_index":0,"kind":"data","monotonic_ns":232962744383375,"payload":{"event_type":"price_change","market":"0x3b40066b5cf3871a2f6237c5628bd8092a206aa998558ac5ec13c4483e31e160","price_changes":[{"asset_id":"110216635572655435074987471276357323571387854733835379371586402147734167783946","best_ask":"0.42","best_bid":"0.41","hash":"a9d39e0712b43ec484be6e3725d3cfa4fa717f06","price":"0.33","side":"BUY","size":"23.73"},{"asset_id":"14766054693214075530629349735273995982307625376442606753688071083149620216746","best_ask":"0.59","best_bid":"0.58","hash":"ddde719cfb098ec67c90bbff8c5bea89aee919f4","price":"0.67","side":"SELL","size":"23.73"}],"timestamp":"1785130979551"},"payload_hash":"470218ee5022c203d9c58ae2c89bb5b93c869df386a72efe96a19d0f85ee4053","raw_frame":"{\"market\":\"0x3b40066b5cf3871a2f6237c5628bd8092a206aa998558ac5ec13c4483e31e160\", \"price_changes\":[{\"asset_id\":\"110216635572655435074987471276357323571387854733835379371586402147734167783946\", \"price\":\"0.33\", \"size\":\"23.73\", \"side\":\"BUY\", \"hash\":\"a9d39e0712b43ec484be6e3725d3cfa4fa717f06\", \"best_bid\":\"0.41\", \"best_ask\":\"0.42\"}, {\"asset_id\":\"14766054693214075530629349735273995982307625376442606753688071083149620216746\", \"price\":\"0.67\", \"size\":\"23.73\", \"side\":\"SELL\", \"hash\":\"ddde719cfb098ec67c90bbff8c5bea89aee919f4\", \"best_bid\":\"0.58\", \"best_ask\":\"0.59\"}], \"timestamp\":\"1785130979551\", \"event_type\":\"price_change\"}","received_at":"2026-07-27T05:42:59.511587Z","schema_version":"clob-market-ws.price_change.v1","sequence":null,"server_hash":null,"server_timestamp":"1785130979551","session_id":"502006c5cfcd437296561ea750c9ec8b","source":"clob_market_ws"},"received_at":"2026-07-27T05:42:59.511587Z","record_id":"fcaf8167622f024b5fc71f7575c3258902ebd7088ffe5cb4f865dafbe90d3777","schema_fingerprint":"4aa3821a28b0b7c2400bc59aba4bcc0a76e971dadd19610d3ad38c768e124dc7","schema_version":"edge-lab-recorder.raw.v1","sequence":null,"source":"clob_market_ws"}
{"event_at":"2026-07-27T05:42:59.557000Z","event_fingerprint":"2e33ca52f9e2a38463a60c20dede21f4827e94e7fba188966d2f979366a475f2","payload":{"connection_id":"efc69d3132f1467b8e898a382b23ac0d","event_at":"2026-07-27T05:42:59.557000Z","event_type":"price_change","frame_hash":"7bafbf1b6e5c4340af689105d2a70151c9d11525426751a0e936be521f4ff92f","frame_index":0,"kind":"data","monotonic_ns":232962752160708,"payload":{"event_type":"price_change","market":"0x3b40066b5cf3871a2f6237c5628bd8092a206aa998558ac5ec13c4483e31e160","price_changes":[{"asset_id":"14766054693214075530629349735273995982307625376442606753688071083149620216746","best_ask":"0.59","best_bid":"0.58","hash":"8bf3535354bb01d2ec3b78e0b729d5d7390fa76c","price":"0.67","side":"SELL","size":"31.77"},{"asset_id":"110216635572655435074987471276357323571387854733835379371586402147734167783946","best_ask":"0.42","best_bid":"0.41","hash":"916f4e4cd5ad783f7274472187c21b3191544eb2","price":"0.33","side":"BUY","size":"31.77"}],"timestamp":"1785130979557"},"payload_hash":"2360a5d53fa6e8b6751e8a602af300c7f9afe1f9e10544ecb810f0db0594aa4d","raw_frame":"{\"market\":\"0x3b40066b5cf3871a2f6237c5628bd8092a206aa998558ac5ec13c4483e31e160\", \"price_changes\":[{\"asset_id\":\"14766054693214075530629349735273995982307625376442606753688071083149620216746\", \"price\":\"0.67\", \"size\":\"31.77\", \"side\":\"SELL\", \"hash\":\"8bf3535354bb01d2ec3b78e0b729d5d7390fa76c\", \"best_bid\":\"0.58\", \"best_ask\":\"0.59\"}, {\"asset_id\":\"110216635572655435074987471276357323571387854733835379371586402147734167783946\", \"price\":\"0.33\", \"size\":\"31.77\", \"side\":\"BUY\", \"hash\":\"916f4e4cd5ad783f7274472187c21b3191544eb2\", \"best_bid\":\"0.41\", \"best_ask\":\"0.42\"}], \"timestamp\":\"1785130979557\", \"event_type\":\"price_change\"}","received_at":"2026-07-27T05:42:59.519364Z","schema_version":"clob-market-ws.price_change.v1","sequence":null,"server_hash":null,"server_timestamp":"1785130979557","session_id":"502006c5cfcd437296561ea750c9ec8b","source":"clob_market_ws"},"received_at":"2026-07-27T05:42:59.519364Z","record_id":"f1a3fdd559b7fe5f1bd14e075e84991c1a2496a11116daaca67b517fe5595725","schema_fingerprint":"4aa3821a28b0b7c2400bc59aba4bcc0a76e971dadd19610d3ad38c768e124dc7","schema_version":"edge-lab-recorder.raw.v1","sequence":null,"source":"clob_market_ws"}
{"event_at":"2026-07-27T05:42:59.580000Z","event_fingerprint":"3ac3c7f2a56967168c4bfbe9cb392ecabc40c5ec348f34a851bebea53cca8d01","payload":{"connection_id":"efc69d3132f1467b8e898a382b23ac0d","event_at":"2026-07-27T05:42:59.580000Z","event_type":"price_change","frame_hash":"0076f3a5b2659202445039e8b8fadee5454296a7dffc73ee30584b9e373afefa","frame_index":0,"kind":"data","monotonic_ns":232962775748833,"payload":{"event_type":"price_change","market":"0x3b40066b5cf3871a2f6237c5628bd8092a206aa998558ac5ec13c4483e31e160","price_changes":[{"asset_id":"110216635572655435074987471276357323571387854733835379371586402147734167783946","best_ask":"0.42","best_bid":"0.41","hash":"c36624330433f1a27adf750db5a7ec0f4e00b9bc","price":"0.32","side":"BUY","size":"57"},{"asset_id":"14766054693214075530629349735273995982307625376442606753688071083149620216746","best_ask":"0.59","best_bid":"0.58","hash":"192c16892b0a8e7a5ee763051d8c9d6c6e321be5","price":"0.68","side":"SELL","size":"57"}],"timestamp":"1785130979580"},"payload_hash":"118a338e819032e93e0357ad6a60ffbbd28463a43689ccf435068c9763ccfb12","raw_frame":"{\"market\":\"0x3b40066b5cf3871a2f6237c5628bd8092a206aa998558ac5ec13c4483e31e160\", \"price_changes\":[{\"asset_id\":\"110216635572655435074987471276357323571387854733835379371586402147734167783946\", \"price\":\"0.32\", \"size\":\"57\", \"side\":\"BUY\", \"hash\":\"c36624330433f1a27adf750db5a7ec0f4e00b9bc\", \"best_bid\":\"0.41\", \"best_ask\":\"0.42\"}, {\"asset_id\":\"14766054693214075530629349735273995982307625376442606753688071083149620216746\", \"price\":\"0.68\", \"size\":\"57\", \"side\":\"SELL\", \"hash\":\"192c16892b0a8e7a5ee763051d8c9d6c6e321be5\", \"best_bid\":\"0.58\", \"best_ask\":\"0.59\"}], \"timestamp\":\"1785130979580\", \"event_type\":\"price_change\"}","received_at":"2026-07-27T05:42:59.542955Z","schema_version":"clob-market-ws.price_change.v1","sequence":null,"server_hash":null,"server_timestamp":"1785130979580","session_id":"502006c5cfcd437296561ea750c9ec8b","source":"clob_market_ws"},"received_at":"2026-07-27T05:42:59.542955Z","record_id":"f7d9e81dfd6e5b3fd3f88a61d5eeced848067fef4519845bcdcbe1af03b2c933","schema_fingerprint":"4aa3821a28b0b7c2400bc59aba4bcc0a76e971dadd19610d3ad38c768e124dc7","schema_version":"edge-lab-recorder.raw.v1","sequence":null,"source":"clob_market_ws"}
{"event_at":"2026-07-27T05:42:59.581000Z","event_fingerprint":"bc75dae301b5eaf00211a5b9f74ba87b61e5b79372b7218703e4f916c0f7d9ca","payload":{"connection_id":"efc69d3132f1467b8e898a382b23ac0d","event_at":"2026-07-27T05:42:59.581000Z","event_type":"price_change","frame_hash":"f93fad2f71a75bde1d32380efa112a5cf0f6745b0babaf60fe53323d8d9e8f09","frame_index":0,"kind":"data","monotonic_ns":232962777368833,"payload":{"event_type":"price_change","market":"0x3b40066b5cf3871a2f6237c5628bd8092a206aa998558ac5ec13c4483e31e160","price_changes":[{"asset_id":"14766054693214075530629349735273995982307625376442606753688071083149620216746","best_ask":"0.59","best_bid":"0.58","hash":"7b78465fd1983fe136605af8a96369ef43180e54","price":"0.03","side":"BUY","size":"532"},{"asset_id":"110216635572655435074987471276357323571387854733835379371586402147734167783946","best_ask":"0.42","best_bid":"0.41","hash":"cea72ac9d1488fb3f4a11776c84fafc806b9c3a1","price":"0.97","side":"SELL","size":"532"}],"timestamp":"1785130979581"},"payload_hash":"18e4dd96b25673be6ce5187db5018428a52c749a198bdf909a3dfd1ae59f201b","raw_frame":"{\"market\":\"0x3b40066b5cf3871a2f6237c5628bd8092a206aa998558ac5ec13c4483e31e160\", \"price_changes\":[{\"asset_id\":\"14766054693214075530629349735273995982307625376442606753688071083149620216746\", \"price\":\"0.03\", \"size\":\"532\", \"side\":\"BUY\", \"hash\":\"7b78465fd1983fe136605af8a96369ef43180e54\", \"best_bid\":\"0.58\", \"best_ask\":\"0.59\"}, {\"asset_id\":\"110216635572655435074987471276357323571387854733835379371586402147734167783946\", \"price\":\"0.97\", \"size\":\"532\", \"side\":\"SELL\", \"hash\":\"cea72ac9d1488fb3f4a11776c84fafc806b9c3a1\", \"best_bid\":\"0.41\", \"best_ask\":\"0.42\"}], \"timestamp\":\"1785130979581\", \"event_type\":\"price_change\"}","received_at":"2026-07-27T05:42:59.544576Z","schema_version":"clob-market-ws.price_change.v1","sequence":null,"server_hash":null,"server_timestamp":"1785130979581","session_id":"502006c5cfcd437296561ea750c9ec8b","source":"clob_market_ws"},"received_at":"2026-07-27T05:42:59.544576Z","record_id":"dd07203448ee8f0ecc775631c5a98ef5f273f939438719c744b9cc0205f0d819","schema_fingerprint":"4aa3821a28b0b7c2400bc59aba4bcc0a76e971dadd19610d3ad38c768e124dc7","schema_version":"edge-lab-recorder.raw.v1","sequence":null,"source":"clob_market_ws"}
{"event_at":"2026-07-27T05:42:59.611000Z","event_fingerprint":"12f7ea040b940109ae2a5d4d0382ae5fa3ab70f9c018d2ee7fe0d405b17d4170","payload":{"connection_id":"efc69d3132f1467b8e898a382b23ac0d","event_at":"2026-07-27T05:42:59.611000Z","event_type":"price_change","frame_hash":"2e8e04a1f84ac40ffcd68df6e4fe68e8e4a4b8befa096ea7db986b3ae816bc9d","frame_index":0,"kind":"data","monotonic_ns":232962803684916,"payload":{"event_type":"price_change","market":"0x3b40066b5cf3871a2f6237c5628bd8092a206aa998558ac5ec13c4483e31e160","price_changes":[{"asset_id":"110216635572655435074987471276357323571387854733835379371586402147734167783946","best_ask":"0.42","best_bid":"0.41","hash":"da6c0baff63159df8dcb5d7cf66aa542573ddbdb","price":"0.43","side":"SELL","size":"424"},{"asset_id":"14766054693214075530629349735273995982307625376442606753688071083149620216746","best_ask":"0.59","best_bid":"0.58","hash":"b6262fe1b98dbd36218175c14a14a1e3b42b86de","price":"0.57","side":"BUY","size":"424"}],"timestamp":"1785130979611"},"payload_hash":"84c1e33f3cffa6c9b3fb8b22da5222fb47e100fb90401b95436c97ee5fbed4c6","raw_frame":"{\"market\":\"0x3b40066b5cf3871a2f6237c5628bd8092a206aa998558ac5ec13c4483e31e160\", \"price_changes\":[{\"asset_id\":\"110216635572655435074987471276357323571387854733835379371586402147734167783946\", \"price\":\"0.43\", \"size\":\"424\", \"side\":\"SELL\", \"hash\":\"da6c0baff63159df8dcb5d7cf66aa542573ddbdb\", \"best_bid\":\"0.41\", \"best_ask\":\"0.42\"}, {\"asset_id\":\"14766054693214075530629349735273995982307625376442606753688071083149620216746\", \"price\":\"0.57\", \"size\":\"424\", \"side\":\"BUY\", \"hash\":\"b6262fe1b98dbd36218175c14a14a1e3b42b86de\", \"best_bid\":\"0.58\", \"best_ask\":\"0.59\"}], \"timestamp\":\"1785130979611\", \"event_type\":\"price_change\"}","received_at":"2026-07-27T05:42:59.570892Z","schema_version":"clob-market-ws.price_change.v1","sequence":null,"server_hash":null,"server_timestamp":"1785130979611","session_id":"502006c5cfcd437296561ea750c9ec8b","source":"clob_market_ws"},"received_at":"2026-07-27T05:42:59.570892Z","record_id":"cc06198f5cb0e021c13617d310e5e58104b1cb6525361c023b86dac84c68e89f","schema_fingerprint":"4aa3821a28b0b7c2400bc59aba4bcc0a76e971dadd19610d3ad38c768e124dc7","schema_version":"edge-lab-recorder.raw.v1","sequence":null,"source":"clob_market_ws"}
{"event_at":"2026-07-27T05:42:59.613000Z","event_fingerprint":"e3bccda75864667817d6259fd265dc2022377440ec192262fd07bc60d044941a","payload":{"connection_id":"efc69d3132f1467b8e898a382b23ac0d","event_at":"2026-07-27T05:42:59.613000Z","event_type":"price_change","frame_hash":"f7d032fdfae99c349cc5c2bebf14836487e4b033c04c2c83bcd035ee4f855ec3","frame_index":0,"kind":"data","monotonic_ns":232962806770166,"payload":{"event_type":"price_change","market":"0x3b40066b5cf3871a2f6237c5628bd8092a206aa998558ac5ec13c4483e31e160","price_changes":[{"asset_id":"14766054693214075530629349735273995982307625376442606753688071083149620216746","best_ask":"0.59","best_bid":"0.58","hash":"75889cbdf527a978f2d69aa47875560371cb739a","price":"0.57","side":"BUY","size":"449"},{"asset_id":"110216635572655435074987471276357323571387854733835379371586402147734167783946","best_ask":"0.42","best_bid":"0.41","hash":"ee172d8a5932942802c54a6efcdd14ee204e3a9b","price":"0.43","side":"SELL","size":"449"}],"timestamp":"1785130979613"},"payload_hash":"b83fdf2b333cdc3e18a43224b9ead5d6f6b028e77e0114ba5777bed4fda688c7","raw_frame":"{\"market\":\"0x3b40066b5cf3871a2f6237c5628bd8092a206aa998558ac5ec13c4483e31e160\", \"price_changes\":[{\"asset_id\":\"14766054693214075530629349735273995982307625376442606753688071083149620216746\", \"price\":\"0.57\", \"size\":\"449\", \"side\":\"BUY\", \"hash\":\"75889cbdf527a978f2d69aa47875560371cb739a\", \"best_bid\":\"0.58\", \"best_ask\":\"0.59\"}, {\"asset_id\":\"110216635572655435074987471276357323571387854733835379371586402147734167783946\", \"price\":\"0.43\", \"size\":\"449\", \"side\":\"SELL\", \"hash\":\"ee172d8a5932942802c54a6efcdd14ee204e3a9b\", \"best_bid\":\"0.41\", \"best_ask\":\"0.42\"}], \"timestamp\":\"1785130979613\", \"event_type\":\"price_change\"}","received_at":"2026-07-27T05:42:59.573977Z","schema_version":"clob-market-ws.price_change.v1","sequence":null,"server_hash":null,"server_timestamp":"1785130979613","session_id":"502006c5cfcd437296561ea750c9ec8b","source":"clob_market_ws"},"received_at":"2026-07-27T05:42:59.573977Z","record_id":"9957fa297df456e0a9b3c72061fd3e4b3b37ffec00360a212e0792ee5a390412","schema_fingerprint":"4aa3821a28b0b7c2400bc59aba4bcc0a76e971dadd19610d3ad38c768e124dc7","schema_version":"edge-lab-recorder.raw.v1","sequence":null,"source":"clob_market_ws"}
{"event_at":"2026-07-27T05:42:59.651000Z","event_fingerprint":"08439de9452378fe6100222244bc76213f7af9eb20c9237b20b1eb771950e71f","payload":{"connection_id":"efc69d3132f1467b8e898a382b23ac0d","event_at":"2026-07-27T05:42:59.651000Z","event_type":"price_change","frame_hash":"b63f55072533a62e3a4abddf1d3e1bc3059a44286bd15f974938e46ab70874c9","frame_index":0,"kind":"data","monotonic_ns":232962842747791,"payload":{"event_type":"price_change","market":"0x3b40066b5cf3871a2f6237c5628bd8092a206aa998558ac5ec13c4483e31e160","price_changes":[{"asset_id":"14766054693214075530629349735273995982307625376442606753688071083149620216746","best_ask":"0.59","best_bid":"0.58","hash":"cbbc16d1cad90fd3bad42c06a4255a59509ab579","price":"0.01","side":"BUY","size":"5335.02"},{"asset_id":"110216635572655435074987471276357323571387854733835379371586402147734167783946","best_ask":"0.42","best_bid":"0.41","hash":"302ec12cd56bde4629185ee8f1e0e2dca4e3c1da","price":"0.99","side":"SELL","size":"5335.02"}],"timestamp":"1785130979651"},"payload_hash":"4a5c93ff57bb9bdcf2bf36b2744c06d44413e34251857b666d6b81f2c642a5cb","raw_frame":"{\"market\":\"0x3b40066b5cf3871a2f6237c5628bd8092a206aa998558ac5ec13c4483e31e160\", \"price_changes\":[{\"asset_id\":\"14766054693214075530629349735273995982307625376442606753688071083149620216746\", \"price\":\"0.01\", \"size\":\"5335.02\", \"side\":\"BUY\", \"hash\":\"cbbc16d1cad90fd3bad42c06a4255a59509ab579\", \"best_bid\":\"0.58\", \"best_ask\":\"0.59\"}, {\"asset_id\":\"110216635572655435074987471276357323571387854733835379371586402147734167783946\", \"price\":\"0.99\", \"size\":\"5335.02\", \"side\":\"SELL\", \"hash\":\"302ec12cd56bde4629185ee8f1e0e2dca4e3c1da\", \"best_bid\":\"0.41\", \"best_ask\":\"0.42\"}], \"timestamp\":\"1785130979651\", \"event_type\":\"price_change\"}","received_at":"2026-07-27T05:42:59.609954Z","schema_version":"clob-market-ws.price_change.v1","sequence":null,"server_hash":null,"server_timestamp":"1785130979651","session_id":"502006c5cfcd437296561ea750c9ec8b","source":"clob_market_ws"},"received_at":"2026-07-27T05:42:59.609954Z","record_id":"6b6b42636a05256c011f4b38ab0ab4b792d495cd251462c7f2d6acb43c24a867","schema_fingerprint":"4aa3821a28b0b7c2400bc59aba4bcc0a76e971dadd19610d3ad38c768e124dc7","schema_version":"edge-lab-recorder.raw.v1","sequence":null,"source":"clob_market_ws"}
{"event_at":"2026-07-27T05:42:59.654000Z","event_fingerprint":"c5405e6655075bf15d8961c6fb5f752f248ec89faf768cb65f970e231ad62358","payload":{"connection_id":"efc69d3132f1467b8e898a382b23ac0d","event_at":"2026-07-27T05:42:59.654000Z","event_type":"price_change","frame_hash":"10cff42994fd7fe14d36553d5a72f5e73430bd3799a70485fbd9c91148c5f3e7","frame_index":0,"kind":"data","monotonic_ns":232962845712333,"payload":{"event_type":"price_change","market":"0x3b40066b5cf3871a2f6237c5628bd8092a206aa998558ac5ec13c4483e31e160","price_changes":[{"asset_id":"110216635572655435074987471276357323571387854733835379371586402147734167783946","best_ask":"0.42","best_bid":"0.41","hash":"f08107129759f5c29fb3ca006e5a2cfd612897a3","price":"0.32","side":"BUY","size":"47"},{"asset_id":"14766054693214075530629349735273995982307625376442606753688071083149620216746","best_ask":"0.59","best_bid":"0.58","hash":"235c26ffeefa69af2dbd0a44305491ddae703352","price":"0.68","side":"SELL","size":"47"}],"timestamp":"1785130979654"},"payload_hash":"7b273dafd00b69a87db9403b0b0744a6214dfa78a67cc8926d68f3cf12c126b7","raw_frame":"{\"market\":\"0x3b40066b5cf3871a2f6237c5628bd8092a206aa998558ac5ec13c4483e31e160\", \"price_changes\":[{\"asset_id\":\"110216635572655435074987471276357323571387854733835379371586402147734167783946\", \"price\":\"0.32\", \"size\":\"47\", \"side\":\"BUY\", \"hash\":\"f08107129759f5c29fb3ca006e5a2cfd612897a3\", \"best_bid\":\"0.41\", \"best_ask\":\"0.42\"}, {\"asset_id\":\"14766054693214075530629349735273995982307625376442606753688071083149620216746\", \"price\":\"0.68\", \"size\":\"47\", \"side\":\"SELL\", \"hash\":\"235c26ffeefa69af2dbd0a44305491ddae703352\", \"best_bid\":\"0.58\", \"best_ask\":\"0.59\"}], \"timestamp\":\"1785130979654\", \"event_type\":\"price_change\"}","received_at":"2026-07-27T05:42:59.612919Z","schema_version":"clob-market-ws.price_change.v1","sequence":null,"server_hash":null,"server_timestamp":"1785130979654","session_id":"502006c5cfcd437296561ea750c9ec8b","source":"clob_market_ws"},"received_at":"2026-07-27T05:42:59.612919Z","record_id":"2240d7d95f3fce7aa2ada6942461feb1a7c16f3ba9c875f4910efdd18c657257","schema_fingerprint":"4aa3821a28b0b7c2400bc59aba4bcc0a76e971dadd19610d3ad38c768e124dc7","schema_version":"edge-lab-recorder.raw.v1","sequence":null,"source":"clob_market_ws"}
{"event_at":"2026-07-27T05:42:59.655000Z","event_fingerprint":"d29e8591aa812cbaa11c0059235b0f7ef62d8131f392c58d805a5c348f175a3e","payload":{"connection_id":"efc69d3132f1467b8e898a382b23ac0d","event_at":"2026-07-27T05:42:59.655000Z","event_type":"price_change","frame_hash":"ed67652a17aabe6793487c9cba4bebe3eefbe1a3e2458f19e88a5300bb47ecdd","frame_index":0,"kind":"data","monotonic_ns":232962847234208,"payload":{"event_type":"price_change","market":"0x3b40066b5cf3871a2f6237c5628bd8092a206aa998558ac5ec13c4483e31e160","price_changes":[{"asset_id":"14766054693214075530629349735273995982307625376442606753688071083149620216746","best_ask":"0.59","best_bid":"0.58","hash":"a859aa2d54bc6b8f34ee3cb53f2a1f581074dbab","price":"0.67","side":"SELL","size":"23.73"},{"asset_id":"110216635572655435074987471276357323571387854733835379371586402147734167783946","best_ask":"0.42","best_bid":"0.41","hash":"bf490238373bed2f92cc07b02b383708c1ef3026","price":"0.33","side":"BUY","size":"23.73"}],"timestamp":"1785130979655"},"payload_hash":"aff5f42f76d9b556b22e1e7c27b527fe5d6bbcf14f8d3581e7b725840d80c0e7","raw_frame":"{\"market\":\"0x3b40066b5cf3871a2f6237c5628bd8092a206aa998558ac5ec13c4483e31e160\", \"price_changes\":[{\"asset_id\":\"14766054693214075530629349735273995982307625376442606753688071083149620216746\", \"price\":\"0.67\", \"size\":\"23.73\", \"side\":\"SELL\", \"hash\":\"a859aa2d54bc6b8f34ee3cb53f2a1f581074dbab\", \"best_bid\":\"0.58\", \"best_ask\":\"0.59\"}, {\"asset_id\":\"110216635572655435074987471276357323571387854733835379371586402147734167783946\", \"price\":\"0.33\", \"size\":\"23.73\", \"side\":\"BUY\", \"hash\":\"bf490238373bed2f92cc07b02b383708c1ef3026\", \"best_bid\":\"0.41\", \"best_ask\":\"0.42\"}], \"timestamp\":\"1785130979655\", \"event_type\":\"price_change\"}","received_at":"2026-07-27T05:42:59.614442Z","schema_version":"clob-market-ws.price_change.v1","sequence":null,"server_hash":null,"server_timestamp":"1785130979655","session_id":"502006c5cfcd437296561ea750c9ec8b","source":"clob_market_ws"},"received_at":"2026-07-27T05:42:59.614442Z","record_id":"4fa3423acc61aa32162434334cc99667eee07c8f623b1c34d184251f02a10477","schema_fingerprint":"4aa3821a28b0b7c2400bc59aba4bcc0a76e971dadd19610d3ad38c768e124dc7","schema_version":"edge-lab-recorder.raw.v1","sequence":null,"source":"clob_market_ws"}
{"event_at":"2026-07-27T05:42:59.670000Z","event_fingerprint":"5f2b3c7f2e7b2fddf0c409eb4b12e4401cdd0ed3a55c25c1d78c5127ca4fc05d","payload":{"connection_id":"efc69d3132f1467b8e898a382b23ac0d","event_at":"2026-07-27T05:42:59.670000Z","event_type":"price_change","frame_hash":"267f5783dd5a50bf66647383a6b7422d140963ffd1c9d8296c5030bc72e29511","frame_index":0,"kind":"data","monotonic_ns":232962865362291,"payload":{"event_type":"price_change","market":"0x3b40066b5cf3871a2f6237c5628bd8092a206aa998558ac5ec13c4483e31e160","price_changes":[{"asset_id":"14766054693214075530629349735273995982307625376442606753688071083149620216746","best_ask":"0.59","best_bid":"0.58","hash":"204cf0066ef12c0fefa36ea068cc030114de1f70","price":"0.01","side":"BUY","size":"5330.02"},{"asset_id":"110216635572655435074987471276357323571387854733835379371586402147734167783946","best_ask":"0.42","best_bid":"0.41","hash":"1aa73ac29b5dc5b723f854f77f148696f40ce1c4","price":"0.99","side":"SELL","size":"5330.02"}],"timestamp":"1785130979670"},"payload_hash":"772ecbaffb416087689479233a2ba89206cc0cab4f276c04abf24933e32ad63a","raw_frame":"{\"market\":\"0x3b40066b5cf3871a2f6237c5628bd8092a206aa998558ac5ec13c4483e31e160\", \"price_changes\":[{\"asset_id\":\"14766054693214075530629349735273995982307625376442606753688071083149620216746\", \"price\":\"0.01\", \"size\":\"5330.02\", \"side\":\"BUY\", \"hash\":\"204cf0066ef12c0fefa36ea068cc030114de1f70\", \"best_bid\":\"0.58\", \"best_ask\":\"0.59\"}, {\"asset_id\":\"110216635572655435074987471276357323571387854733835379371586402147734167783946\", \"price\":\"0.99\", \"size\":\"5330.02\", \"side\":\"SELL\", \"hash\":\"1aa73ac29b5dc5b723f854f77f148696f40ce1c4\", \"best_bid\":\"0.41\", \"best_ask\":\"0.42\"}], \"timestamp\":\"1785130979670\", \"event_type\":\"price_change\"}","received_at":"2026-07-27T05:42:59.632569Z","schema_version":"clob-market-ws.price_change.v1","sequence":null,"server_hash":null,"server_timestamp":"1785130979670","session_id":"502006c5cfcd437296561ea750c9ec8b","source":"clob_market_ws"},"received_at":"2026-07-27T05:42:59.632569Z","record_id":"1edc989292a21d758a666dbf3046d2bb929f6bbc74471c0bd3e4d7bc9981a5ec","schema_fingerprint":"4aa3821a28b0b7c2400bc59aba4bcc0a76e971dadd19610d3ad38c768e124dc7","schema_version":"edge-lab-recorder.raw.v1","sequence":null,"source":"clob_market_ws"}
{"event_at":"2026-07-27T05:42:59.678000Z","event_fingerprint":"5067ab4bd410c1e88711fe645109d3c53a247ef4b112988f12b357f78c33ed00","payload":{"connection_id":"efc69d3132f1467b8e898a382b23ac0d","event_at":"2026-07-27T05:42:59.678000Z","event_type":"price_change","frame_hash":"5dc91079a91a6532ce5e3cbe4fa26296b5a420ed2b87d02198205e3225752bc5","frame_index":0,"kind":"data","monotonic_ns":232962870216708,"payload":{"event_type":"price_change","market":"0x3b40066b5cf3871a2f6237c5628bd8092a206aa998558ac5ec13c4483e31e160","price_changes":[{"asset_id":"14766054693214075530629349735273995982307625376442606753688071083149620216746","best_ask":"0.59","best_bid":"0.58","hash":"32c6f7c65b05cd02cf0481c4e57367b43e833dfa","price":"0.01","side":"BUY","size":"5335.02"},{"asset_id":"110216635572655435074987471276357323571387854733835379371586402147734167783946","best_ask":"0.42","best_bid":"0.41","hash":"ca09d49e995da13eeab6a7e66ac69dc0a052fc75","price":"0.99","side":"SELL","size":"5335.02"}],"timestamp":"1785130979678"},"payload_hash":"aefcab1886e138366ab48541e3b004421e908a103dc3046a4aba9503bdb7faa7","raw_frame":"{\"market\":\"0x3b40066b5cf3871a2f6237c5628bd8092a206aa998558ac5ec13c4483e31e160\", \"price_changes\":[{\"asset_id\":\"14766054693214075530629349735273995982307625376442606753688071083149620216746\", \"price\":\"0.01\", \"size\":\"5335.02\", \"side\":\"BUY\", \"hash\":\"32c6f7c65b05cd02cf0481c4e57367b43e833dfa\", \"best_bid\":\"0.58\", \"best_ask\":\"0.59\"}, {\"asset_id\":\"110216635572655435074987471276357323571387854733835379371586402147734167783946\", \"price\":\"0.99\", \"size\":\"5335.02\", \"side\":\"SELL\", \"hash\":\"ca09d49e995da13eeab6a7e66ac69dc0a052fc75\", \"best_bid\":\"0.41\", \"best_ask\":\"0.42\"}], \"timestamp\":\"1785130979678\", \"event_type\":\"price_change\"}","received_at":"2026-07-27T05:42:59.637424Z","schema_version":"clob-market-ws.price_change.v1","sequence":null,"server_hash":null,"server_timestamp":"1785130979678","session_id":"502006c5cfcd437296561ea750c9ec8b","source":"clob_market_ws"},"received_at":"2026-07-27T05:42:59.637424Z","record_id":"1c279c98d00001172170102b4590fbcb62b3312a745ead2dbbca17e2bd032351","schema_fingerprint":"4aa3821a28b0b7c2400bc59aba4bcc0a76e971dadd19610d3ad38c768e124dc7","schema_version":"edge-lab-recorder.raw.v1","sequence":null,"source":"clob_market_ws"}
{"event_at":"2026-07-27T05:42:59.681000Z","event_fingerprint":"b6bcbeb1cad9cc6e06bb4747deb71a3d056a69945603f3a13e8d81b7b333afff","payload":{"connection_id":"efc69d3132f1467b8e898a382b23ac0d","event_at":"2026-07-27T05:42:59.681000Z","event_type":"price_change","frame_hash":"b57f8f346dfd6bc21b71ac4fda5a112ce03c2aa90defaca0b941428b3e090b04","frame_index":0,"kind":"data","monotonic_ns":232962874587166,"payload":{"event_type":"price_change","market":"0x3b40066b5cf3871a2f6237c5628bd8092a206aa998558ac5ec13c4483e31e160","price_changes":[{"asset_id":"14766054693214075530629349735273995982307625376442606753688071083149620216746","best_ask":"0.59","best_bid":"0.58","hash":"21a55f66ec671373858738d9eb25481fd55a418d","price":"0.04","side":"BUY","size":"568"},{"asset_id":"110216635572655435074987471276357323571387854733835379371586402147734167783946","best_ask":"0.42","best_bid":"0.41","hash":"bb3327b3c2bb4c1dad27b7ffbdc672e800a6af03","price":"0.96","side":"SELL","size":"568"}],"timestamp":"1785130979681"},"payload_hash":"760dbf4dd34edd2f512520310142c2093982c871467df3b92696b3672bfaee0e","raw_frame":"{\"market\":\"0x3b40066b5cf3871a2f6237c5628bd8092a206aa998558ac5ec13c4483e31e160\", \"price_changes\":[{\"asset_id\":\"14766054693214075530629349735273995982307625376442606753688071083149620216746\", \"price\":\"0.04\", \"size\":\"568\", \"side\":\"BUY\", \"hash\":\"21a55f66ec671373858738d9eb25481fd55a418d\", \"best_bid\":\"0.58\", \"best_ask\":\"0.59\"}, {\"asset_id\":\"110216635572655435074987471276357323571387854733835379371586402147734167783946\", \"price\":\"0.96\", \"size\":\"568\", \"side\":\"SELL\", \"hash\":\"bb3327b3c2bb4c1dad27b7ffbdc672e800a6af03\", \"best_bid\":\"0.41\", \"best_ask\":\"0.42\"}], \"timestamp\":\"1785130979681\", \"event_type\":\"price_change\"}","received_at":"2026-07-27T05:42:59.641792Z","schema_version":"clob-market-ws.price_change.v1","sequence":null,"server_hash":null,"server_timestamp":"1785130979681","session_id":"502006c5cfcd437296561ea750c9ec8b","source":"clob_market_ws"},"received_at":"2026-07-27T05:42:59.641792Z","record_id":"ff737536f0ccf224941962eae7b3676a3202b0e3719469125d2374da7be8bafd","schema_fingerprint":"4aa3821a28b0b7c2400bc59aba4bcc0a76e971dadd19610d3ad38c768e124dc7","schema_version":"edge-lab-recorder.raw.v1","sequence":null,"source":"clob_market_ws"}
{"event_at":"2026-07-27T05:42:59.683000Z","event_fingerprint":"3afe00228857ff2b36daf7ce77323701ebd923084eaa6cae66f157184e1f7688","payload":{"connection_id":"efc69d3132f1467b8e898a382b23ac0d","event_at":"2026-07-27T05:42:59.683000Z","event_type":"price_change","frame_hash":"0df319e88a5e5bcbbfa96169e932053c7f8bbab10e8444d7d45f6c28bb77b0a9","frame_index":0,"kind":"data","monotonic_ns":232962877500375,"payload":{"event_type":"price_change","market":"0x3b40066b5cf3871a2f6237c5628bd8092a206aa998558ac5ec13c4483e31e160","price_changes":[{"asset_id":"110216635572655435074987471276357323571387854733835379371586402147734167783946","best_ask":"0.42","best_bid":"0.41","hash":"603ff704589052bc3ba489d5c968c796c2c8ef09","price":"0.33","side":"BUY","size":"33.73"},{"asset_id":"14766054693214075530629349735273995982307625376442606753688071083149620216746","best_ask":"0.59","best_bid":"0.58","hash":"a5ac5d3eeda491698b1a84115916b6d62e1de27b","price":"0.67","side":"SELL","size":"33.73"}],"timestamp":"1785130979683"},"payload_hash":"933b852aaed98e7365170913776ff858fda98692bde9ba755c97d253e7e2b17a","raw_frame":"{\"market\":\"0x3b40066b5cf3871a2f6237c5628bd8092a206aa998558ac5ec13c4483e31e160\", \"price_changes\":[{\"asset_id\":\"110216635572655435074987471276357323571387854733835379371586402147734167783946\", \"price\":\"0.33\", \"size\":\"33.73\", \"side\":\"BUY\", \"hash\":\"603ff704589052bc3ba489d5c968c796c2c8ef09\", \"best_bid\":\"0.41\", \"best_ask\":\"0.42\"}, {\"asset_id\":\"14766054693214075530629349735273995982307625376442606753688071083149620216746\", \"price\":\"0.67\", \"size\":\"33.73\", \"side\":\"SELL\", \"hash\":\"a5ac5d3eeda491698b1a84115916b6d62e1de27b\", \"best_bid\":\"0.58\", \"best_ask\":\"0.59\"}], \"timestamp\":\"1785130979683\", \"event_type\":\"price_change\"}","received_at":"2026-07-27T05:42:59.644708Z","schema_version":"clob-market-ws.price_change.v1","sequence":null,"server_hash":null,"server_timestamp":"1785130979683","session_id":"502006c5cfcd437296561ea750c9ec8b","source":"clob_market_ws"},"received_at":"2026-07-27T05:42:59.644708Z","record_id":"d05e9fc479abd3f8edf2a009d323a3fd895c7d0460904cc441e5e0644600ed8f","schema_fingerprint":"4aa3821a28b0b7c2400bc59aba4bcc0a76e971dadd19610d3ad38c768e124dc7","schema_version":"edge-lab-recorder.raw.v1","sequence":null,"source":"clob_market_ws"}
{"event_at":"2026-07-27T05:42:59.708000Z","event_fingerprint":"98b9ecf1a0d4de043e3630770346776b83b1445b1613572fd860d7bc5a8ef159","payload":{"connection_id":"efc69d3132f1467b8e898a382b23ac0d","event_at":"2026-07-27T05:42:59.708000Z","event_type":"price_change","frame_hash":"d670681d9fe95d8560393056f0595e29a2aea479e5943effc2fd29127db986d9","frame_index":0,"kind":"data","monotonic_ns":232962898642875,"payload":{"event_type":"price_change","market":"0x3b40066b5cf3871a2f6237c5628bd8092a206aa998558ac5ec13c4483e31e160","price_changes":[{"asset_id":"110216635572655435074987471276357323571387854733835379371586402147734167783946","best_ask":"0.42","best_bid":"0.41","hash":"5e36a62f5d1ff7307d984db683fde2bbce39b353","price":"0.43","side":"SELL","size":"424"},{"asset_id":"14766054693214075530629349735273995982307625376442606753688071083149620216746","best_ask":"0.59","best_bid":"0.58","hash":"b785250295c9fd56eb2226044acc86a43b4cc36c","price":"0.57","side":"BUY","size":"424"}],"timestamp":"1785130979708"},"payload_hash":"540b706c5898abc2548664da630031effcd9caa7fe244c6033dfbf56f28b817b","raw_frame":"{\"market\":\"0x3b40066b5cf3871a2f6237c5628bd8092a206aa998558ac5ec13c4483e31e160\", \"price_changes\":[{\"asset_id\":\"110216635572655435074987471276357323571387854733835379371586402147734167783946\", \"price\":\"0.43\", \"size\":\"424\", \"side\":\"SELL\", \"hash\":\"5e36a62f5d1ff7307d984db683fde2bbce39b353\", \"best_bid\":\"0.41\", \"best_ask\":\"0.42\"}, {\"asset_id\":\"14766054693214075530629349735273995982307625376442606753688071083149620216746\", \"price\":\"0.57\", \"size\":\"424\", \"side\":\"BUY\", \"hash\":\"b785250295c9fd56eb2226044acc86a43b4cc36c\", \"best_bid\":\"0.58\", \"best_ask\":\"0.59\"}], \"timestamp\":\"1785130979708\", \"event_type\":\"price_change\"}","received_at":"2026-07-27T05:42:59.665849Z","schema_version":"clob-market-ws.price_change.v1","sequence":null,"server_hash":null,"server_timestamp":"1785130979708","session_id":"502006c5cfcd437296561ea750c9ec8b","source":"clob_market_ws"},"received_at":"2026-07-27T05:42:59.665849Z","record_id":"984aa0891c089ddb42dc2ae09d5c5aa28dc0b73a4217f7e7770e4743d4128e6a","schema_fingerprint":"4aa3821a28b0b7c2400bc59aba4bcc0a76e971dadd19610d3ad38c768e124dc7","schema_version":"edge-lab-recorder.raw.v1","sequence":null,"source":"clob_market_ws"}
{"event_at":"2026-07-27T05:42:59.712000Z","event_fingerprint":"de1d6336c7f0551394a46023ee8576a8175bfb4f43281153cf386ff1c8444b85","payload":{"connection_id":"efc69d3132f1467b8e898a382b23ac0d","event_at":"2026-07-27T05:42:59.712000Z","event_type":"price_change","frame_hash":"d4fcd5b7e44ecc60b07238f60e2feff4e0a31d8bddaa17f5f960f848759525b7","frame_index":0,"kind":"data","monotonic_ns":232962901910541,"payload":{"event_type":"price_change","market":"0x3b40066b5cf3871a2f6237c5628bd8092a206aa998558ac5ec13c4483e31e160","price_changes":[{"asset_id":"14766054693214075530629349735273995982307625376442606753688071083149620216746","best_ask":"0.59","best_bid":"0.58","hash":"df06989ce0a683c44688ff7f1f9d491ac6920c82","price":"0.01","side":"BUY","size":"5330.02"},{"asset_id":"110216635572655435074987471276357323571387854733835379371586402147734167783946","best_ask":"0.42","best_bid":"0.41","hash":"ebf622c3ae9eded306dc2771642e88efb6221c54","price":"0.99","side":"SELL","size":"5330.02"}],"timestamp":"1785130979712"},"payload_hash":"6ce00f319b403ae7c6f35d6d289803e451ba63a5fb918b152f898866c46aedb9","raw_frame":"{\"market\":\"0x3b40066b5cf3871a2f6237c5628bd8092a206aa998558ac5ec13c4483e31e160\", \"price_changes\":[{\"asset_id\":\"14766054693214075530629349735273995982307625376442606753688071083149620216746\", \"price\":\"0.01\", \"size\":\"5330.02\", \"side\":\"BUY\", \"hash\":\"df06989ce0a683c44688ff7f1f9d491ac6920c82\", \"best_bid\":\"0.58\", \"best_ask\":\"0.59\"}, {\"asset_id\":\"110216635572655435074987471276357323571387854733835379371586402147734167783946\", \"price\":\"0.99\", \"size\":\"5330.02\", \"side\":\"SELL\", \"hash\":\"ebf622c3ae9eded306dc2771642e88efb6221c54\", \"best_bid\":\"0.41\", \"best_ask\":\"0.42\"}], \"timestamp\":\"1785130979712\", \"event_type\":\"price_change\"}","received_at":"2026-07-27T05:42:59.669117Z","schema_version":"clob-market-ws.price_change.v1","sequence":null,"server_hash":null,"server_timestamp":"1785130979712","session_id":"502006c5cfcd437296561ea750c9ec8b","source":"clob_market_ws"},"received_at":"2026-07-27T05:42:59.669117Z","record_id":"feeca823f3f8f7b9cd47cfb324138479aa7c24fdcac1819bb2fc57542c741479","schema_fingerprint":"4aa3821a28b0b7c2400bc59aba4bcc0a76e971dadd19610d3ad38c768e124dc7","schema_version":"edge-lab-recorder.raw.v1","sequence":null,"source":"clob_market_ws"}
{"event_at":"2026-07-27T05:42:59.712000Z","event_fingerprint":"7d4e6ada08d51f247ef79ad28839da32b0399c9ec9680040acfd29b974daf778","payload":{"connection_id":"efc69d3132f1467b8e898a382b23ac0d","event_at":"2026-07-27T05:42:59.712000Z","event_type":"price_change","frame_hash":"f2e5919d48d9c0b2ac9de26530f0554076cd3120b195f0557f7cfbe71e83a3cc","frame_index":0,"kind":"data","monotonic_ns":232962904137541,"payload":{"event_type":"price_change","market":"0x3b40066b5cf3871a2f6237c5628bd8092a206aa998558ac5ec13c4483e31e160","price_changes":[{"asset_id":"14766054693214075530629349735273995982307625376442606753688071083149620216746","best_ask":"0.59","best_bid":"0.58","hash":"8ad75f17a6436a2ffdcb9b5b427b6975104e1822","price":"0.57","side":"BUY","size":"399"},{"asset_id":"110216635572655435074987471276357323571387854733835379371586402147734167783946","best_ask":"0.42","best_bid":"0.41","hash":"dd35bd1de4de488fcf2984709d7192d69b60ea58","price":"0.43","side":"SELL","size":"399"}],"timestamp":"1785130979712"},"payload_hash":"ad9a3081886717e0541e3ee488f8958d112978b4e950f02ecfac796542fb4097","raw_frame":"{\"market\":\"0x3b40066b5cf3871a2f6237c5628bd8092a206aa998558ac5ec13c4483e31e160\", \"price_changes\":[{\"asset_id\":\"14766054693214075530629349735273995982307625376442606753688071083149620216746\", \"price\":\"0.57\", \"size\":\"399\", \"side\":\"BUY\", \"hash\":\"8ad75f17a6436a2ffdcb9b5b427b6975104e1822\", \"best_bid\":\"0.58\", \"best_ask\":\"0.59\"}, {\"asset_id\":\"110216635572655435074987471276357323571387854733835379371586402147734167783946\", \"price\":\"0.43\", \"size\":\"399\", \"side\":\"SELL\", \"hash\":\"dd35bd1de4de488fcf2984709d7192d69b60ea58\", \"best_bid\":\"0.41\", \"best_ask\":\"0.42\"}], \"timestamp\":\"1785130979712\", \"event_type\":\"price_change\"}","received_at":"2026-07-27T05:42:59.671342Z","schema_version":"clob-market-ws.price_change.v1","sequence":null,"server_hash":null,"server_timestamp":"1785130979712","session_id":"502006c5cfcd437296561ea750c9ec8b","source":"clob_market_ws"},"received_at":"2026-07-27T05:42:59.671342Z","record_id":"41da472667f429f0844de15f465e86454cffe46c7b38159041a0e014c402b531","schema_fingerprint":"4aa3821a28b0b7c2400bc59aba4bcc0a76e971dadd19610d3ad38c768e124dc7","schema_version":"edge-lab-recorder.raw.v1","sequence":null,"source":"clob_market_ws"}
{"event_at":"2026-07-27T05:42:59.739000Z","event_fingerprint":"29d29b394c951db92a127564a762b13706c1e017511ff3ec03be42563e8bc230","payload":{"connection_id":"efc69d3132f1467b8e898a382b23ac0d","event_at":"2026-07-27T05:42:59.739000Z","event_type":"price_change","frame_hash":"5728e0923df9026f2b455f958716ed777ad4570079dee46275ed11bca1528d42","frame_index":0,"kind":"data","monotonic_ns":232962929116458,"payload":{"event_type":"price_change","market":"0x3b40066b5cf3871a2f6237c5628bd8092a206aa998558ac5ec13c4483e31e160","price_changes":[{"asset_id":"14766054693214075530629349735273995982307625376442606753688071083149620216746","best_ask":"0.59","best_bid":"0.58","hash":"a5007c9bfb37557b529f59daac93cab24a895f15","price":"0.04","side":"BUY","size":"563"},{"asset_id":"110216635572655435074987471276357323571387854733835379371586402147734167783946","best_ask":"0.42","best_bid":"0.41","hash":"356ff546f0cc88fb04aa88645a7002f02078a33d","price":"0.96","side":"SELL","size":"563"}],"timestamp":"1785130979739"},"payload_hash":"ef911fd05e90501a881aff196f2f7f64e9745038b5abd5086df2148a7a5e3b5e","raw_frame":"{\"market\":\"0x3b40066b5cf3871a2f6237c5628bd8092a206aa998558ac5ec13c4483e31e160\", \"price_changes\":[{\"asset_id\":\"14766054693214075530629349735273995982307625376442606753688071083149620216746\", \"price\":\"0.04\", \"size\":\"563\", \"side\":\"BUY\", \"hash\":\"a5007c9bfb37557b529f59daac93cab24a895f15\", \"best_bid\":\"0.58\", \"best_ask\":\"0.59\"}, {\"asset_id\":\"110216635572655435074987471276357323571387854733835379371586402147734167783946\", \"price\":\"0.96\", \"size\":\"563\", \"side\":\"SELL\", \"hash\":\"356ff546f0cc88fb04aa88645a7002f02078a33d\", \"best_bid\":\"0.41\", \"best_ask\":\"0.42\"}], \"timestamp\":\"1785130979739\", \"event_type\":\"price_change\"}","received_at":"2026-07-27T05:42:59.696323Z","schema_version":"clob-market-ws.price_change.v1","sequence":null,"server_hash":null,"server_timestamp":"1785130979739","session_id":"502006c5cfcd437296561ea750c9ec8b","source":"clob_market_ws"},"received_at":"2026-07-27T05:42:59.696323Z","record_id":"613f0fc4831e96b66579cb1eee629ccb2a7c9b9539d7e0e0382d643a28b2a747","schema_fingerprint":"4aa3821a28b0b7c2400bc59aba4bcc0a76e971dadd19610d3ad38c768e124dc7","schema_version":"edge-lab-recorder.raw.v1","sequence":null,"source":"clob_market_ws"}
{"event_at":"2026-07-27T05:42:59.754000Z","event_fingerprint":"6f3cd5001a383cf71a04ddbd4344723093ca41abd0035eaa264b5078047a6b42","payload":{"connection_id":"efc69d3132f1467b8e898a382b23ac0d","event_at":"2026-07-27T05:42:59.754000Z","event_type":"price_change","frame_hash":"31f91394979f2726daa1b99db0ce1662879cb80d321671445577f8734c1a1549","frame_index":0,"kind":"data","monotonic_ns":232962945882958,"payload":{"event_type":"price_change","market":"0x3b40066b5cf3871a2f6237c5628bd8092a206aa998558ac5ec13c4483e31e160","price_changes":[{"asset_id":"110216635572655435074987471276357323571387854733835379371586402147734167783946","best_ask":"0.42","best_bid":"0.41","hash":"2901c7d55118926c310e84d6d3edacbf6502fe7a","price":"0.18","side":"BUY","size":"161.4"},{"asset_id":"14766054693214075530629349735273995982307625376442606753688071083149620216746","best_ask":"0.59","best_bid":"0.58","hash":"40316e8fde1490b833163a3f20773ea79c2a35fb","price":"0.82","side":"SELL","size":"161.4"}],"timestamp":"1785130979754"},"payload_hash":"177c276e34847b189c3c0883ddc736b8a7079cf518304b1159d984af1d585b80","raw_frame":"{\"market\":\"0x3b40066b5cf3871a2f6237c5628bd8092a206aa998558ac5ec13c4483e31e160\", \"price_changes\":[{\"asset_id\":\"110216635572655435074987471276357323571387854733835379371586402147734167783946\", \"price\":\"0.18\", \"size\":\"161.4\", \"side\":\"BUY\", \"hash\":\"2901c7d55118926c310e84d6d3edacbf6502fe7a\", \"best_bid\":\"0.41\", \"best_ask\":\"0.42\"}, {\"asset_id\":\"14766054693214075530629349735273995982307625376442606753688071083149620216746\", \"price\":\"0.82\", \"size\":\"161.4\", \"side\":\"SELL\", \"hash\":\"40316e8fde1490b833163a3f20773ea79c2a35fb\", \"best_bid\":\"0.58\", \"best_ask\":\"0.59\"}], \"timestamp\":\"1785130979754\", \"event_type\":\"price_change\"}","received_at":"2026-07-27T05:42:59.713089Z","schema_version":"clob-market-ws.price_change.v1","sequence":null,"server_hash":null,"server_timestamp":"1785130979754","session_id":"502006c5cfcd437296561ea750c9ec8b","source":"clob_market_ws"},"received_at":"2026-07-27T05:42:59.713089Z","record_id":"b30112161459780c2ced60fb12cf3d358d67f0e0172b5bf5a7ecb2b518843ff3","schema_fingerprint":"4aa3821a28b0b7c2400bc59aba4bcc0a76e971dadd19610d3ad38c768e124dc7","schema_version":"edge-lab-recorder.raw.v1","sequence":null,"source":"clob_market_ws"}
{"event_at":"2026-07-27T05:42:59.771000Z","event_fingerprint":"a3c5a32665461b9dff8b9ae839c0e004252de730da680298a1c2e277a4bfe961","payload":{"connection_id":"efc69d3132f1467b8e898a382b23ac0d","event_at":"2026-07-27T05:42:59.771000Z","event_type":"price_change","frame_hash":"e237b73207d894f1224cb46681dd7649f8d6191c803c8959c8798b4ce3a6c74c","frame_index":0,"kind":"data","monotonic_ns":232962963171500,"payload":{"event_type":"price_change","market":"0x3b40066b5cf3871a2f6237c5628bd8092a206aa998558ac5ec13c4483e31e160","price_changes":[{"asset_id":"14766054693214075530629349735273995982307625376442606753688071083149620216746","best_ask":"0.59","best_bid":"0.58","hash":"ec65b6f201a2779fb4f32fea404735fc59b8abab","price":"0.67","side":"SELL","size":"41.77"},{"asset_id":"110216635572655435074987471276357323571387854733835379371586402147734167783946","best_ask":"0.42","best_bid":"0.41","hash":"6f551da8f80e0ecc95d0d244a19e5859c233e115","price":"0.33","side":"BUY","size":"41.77"}],"timestamp":"1785130979771"},"payload_hash":"c597c920c8f146fac613452767574bb50cca617b6aff6e00e5872842d103ce3b","raw_frame":"{\"market\":\"0x3b40066b5cf3871a2f6237c5628bd8092a206aa998558ac5ec13c4483e31e160\", \"price_changes\":[{\"asset_id\":\"14766054693214075530629349735273995982307625376442606753688071083149620216746\", \"price\":\"0.67\", \"size\":\"41.77\", \"side\":\"SELL\", \"hash\":\"ec65b6f201a2779fb4f32fea404735fc59b8abab\", \"best_bid\":\"0.58\", \"best_ask\":\"0.59\"}, {\"asset_id\":\"110216635572655435074987471276357323571387854733835379371586402147734167783946\", \"price\":\"0.33\", \"size\":\"41.77\", \"side\":\"BUY\", \"hash\":\"6f551da8f80e0ecc95d0d244a19e5859c233e115\", \"best_bid\":\"0.41\", \"best_ask\":\"0.42\"}], \"timestamp\":\"1785130979771\", \"event_type\":\"price_change\"}","received_at":"2026-07-27T05:42:59.730378Z","schema_version":"clob-market-ws.price_change.v1","sequence":null,"server_hash":null,"server_timestamp":"1785130979771","session_id":"502006c5cfcd437296561ea750c9ec8b","source":"clob_market_ws"},"received_at":"2026-07-27T05:42:59.730378Z","record_id":"804460e0dcb336e68074238b2f98e8e3af4831ebaf3b76fa5f6f0dc1b4f7e82d","schema_fingerprint":"4aa3821a28b0b7c2400bc59aba4bcc0a76e971dadd19610d3ad38c768e124dc7","schema_version":"edge-lab-recorder.raw.v1","sequence":null,"source":"clob_market_ws"}
{"event_at":"2026-07-27T05:42:59.809000Z","event_fingerprint":"dcc5b708a3a9c761013b19169b2f3adb5a2bfc2522ae725c6abab751c20cfca3","payload":{"connection_id":"efc69d3132f1467b8e898a382b23ac0d","event_at":"2026-07-27T05:42:59.809000Z","event_type":"price_change","frame_hash":"a8beec7b7966c8240148e3317e49b3389c161ac5e877164b487f4ddc363061b1","frame_index":0,"kind":"data","monotonic_ns":232962999499250,"payload":{"event_type":"price_change","market":"0x3b40066b5cf3871a2f6237c5628bd8092a206aa998558ac5ec13c4483e31e160","price_changes":[{"asset_id":"110216635572655435074987471276357323571387854733835379371586402147734167783946","best_ask":"0.42","best_bid":"0.41","hash":"266357ced502133fae8e2f97871dac6fb4427610","price":"0.19","side":"BUY","size":"75.44"},{"asset_id":"14766054693214075530629349735273995982307625376442606753688071083149620216746","best_ask":"0.59","best_bid":"0.58","hash":"3cb77df474c7147f38ccb285e85f47ee028d87e6","price":"0.81","side":"SELL","size":"75.44"}],"timestamp":"1785130979809"},"payload_hash":"cf5483f02e18373638a8e226236a2f6c7d38847d8352f5cdb7e3975d290eb0fc","raw_frame":"{\"market\":\"0x3b40066b5cf3871a2f6237c5628bd8092a206aa998558ac5ec13c4483e31e160\", \"price_changes\":[{\"asset_id\":\"110216635572655435074987471276357323571387854733835379371586402147734167783946\", \"price\":\"0.19\", \"size\":\"75.44\", \"side\":\"BUY\", \"hash\":\"266357ced502133fae8e2f97871dac6fb4427610\", \"best_bid\":\"0.41\", \"best_ask\":\"0.42\"}, {\"asset_id\":\"14766054693214075530629349735273995982307625376442606753688071083149620216746\", \"price\":\"0.81\", \"size\":\"75.44\", \"side\":\"SELL\", \"hash\":\"3cb77df474c7147f38ccb285e85f47ee028d87e6\", \"best_bid\":\"0.58\", \"best_ask\":\"0.59\"}], \"timestamp\":\"1785130979809\", \"event_type\":\"price_change\"}","received_at":"2026-07-27T05:42:59.766706Z","schema_version":"clob-market-ws.price_change.v1","sequence":null,"server_hash":null,"server_timestamp":"1785130979809","session_id":"502006c5cfcd437296561ea750c9ec8b","source":"clob_market_ws"},"received_at":"2026-07-27T05:42:59.766706Z","record_id":"c332a2644a3e22a919eb92fecb38912d1e14a3e682ad8d807709de72bf4b67ee","schema_fingerprint":"4aa3821a28b0b7c2400bc59aba4bcc0a76e971dadd19610d3ad38c768e124dc7","schema_version":"edge-lab-recorder.raw.v1","sequence":null,"source":"clob_market_ws"}
{"event_at":"2026-07-27T05:42:59.819000Z","event_fingerprint":"67d1b49e5cedc9ed229ddda5f8335ed0aae9653fd24ac6adc6390929361a9a87","payload":{"connection_id":"efc69d3132f1467b8e898a382b23ac0d","event_at":"2026-07-27T05:42:59.819000Z","event_type":"price_change","frame_hash":"c43582b001e82cbe935332ba933709ab7b695336eff20c62411b4b2d1520aeb0","frame_index":0,"kind":"data","monotonic_ns":232963009781041,"payload":{"event_type":"price_change","market":"0x3b40066b5cf3871a2f6237c5628bd8092a206aa998558ac5ec13c4483e31e160","price_changes":[{"asset_id":"14766054693214075530629349735273995982307625376442606753688071083149620216746","best_ask":"0.59","best_bid":"0.58","hash":"aaa859a7179b48f38e1604456879a6c23fa2b8e8","price":"0.36","side":"BUY","size":"43.64"},{"asset_id":"110216635572655435074987471276357323571387854733835379371586402147734167783946","best_ask":"0.42","best_bid":"0.41","hash":"652994c20299689662366dc5d8ec9fa827c27480","price":"0.64","side":"SELL","size":"43.64"}],"timestamp":"1785130979819"},"payload_hash":"1530cdd115cb1d27e32470f9ae9a4b85d06cf37b32c03bbd6cd4f7063a05407c","raw_frame":"{\"market\":\"0x3b40066b5cf3871a2f6237c5628bd8092a206aa998558ac5ec13c4483e31e160\", \"price_changes\":[{\"asset_id\":\"14766054693214075530629349735273995982307625376442606753688071083149620216746\", \"price\":\"0.36\", \"size\":\"43.64\", \"side\":\"BUY\", \"hash\":\"aaa859a7179b48f38e1604456879a6c23fa2b8e8\", \"best_bid\":\"0.58\", \"best_ask\":\"0.59\"}, {\"asset_id\":\"110216635572655435074987471276357323571387854733835379371586402147734167783946\", \"price\":\"0.64\", \"size\":\"43.64\", \"side\":\"SELL\", \"hash\":\"652994c20299689662366dc5d8ec9fa827c27480\", \"best_bid\":\"0.41\", \"best_ask\":\"0.42\"}], \"timestamp\":\"1785130979819\", \"event_type\":\"price_change\"}","received_at":"2026-07-27T05:42:59.776988Z","schema_version":"clob-market-ws.price_change.v1","sequence":null,"server_hash":null,"server_timestamp":"1785130979819","session_id":"502006c5cfcd437296561ea750c9ec8b","source":"clob_market_ws"},"received_at":"2026-07-27T05:42:59.776988Z","record_id":"43b540ebc41175c095fc1729e0d397e85d2ecacc12710c7f584f496ac7b7562b","schema_fingerprint":"4aa3821a28b0b7c2400bc59aba4bcc0a76e971dadd19610d3ad38c768e124dc7","schema_version":"edge-lab-recorder.raw.v1","sequence":null,"source":"clob_market_ws"}
{"event_at":"2026-07-27T05:42:59.838000Z","event_fingerprint":"ce0c8d27f6869fef2109290ba64c00fb7e576ddd52844fc03f2ac4c8720e02f5","payload":{"connection_id":"efc69d3132f1467b8e898a382b23ac0d","event_at":"2026-07-27T05:42:59.838000Z","event_type":"price_change","frame_hash":"518dcac0dd2c70770b4a48073641bce653a2eb580c5565779edcdd91fc5eaf5a","frame_index":0,"kind":"data","monotonic_ns":232963029530916,"payload":{"event_type":"price_change","market":"0x3b40066b5cf3871a2f6237c5628bd8092a206aa998558ac5ec13c4483e31e160","price_changes":[{"asset_id":"14766054693214075530629349735273995982307625376442606753688071083149620216746","best_ask":"0.59","best_bid":"0.58","hash":"680b5e4ce8c3901bbd0b5d63ac685d510ce942a2","price":"0.01","side":"BUY","size":"5335.02"},{"asset_id":"110216635572655435074987471276357323571387854733835379371586402147734167783946","best_ask":"0.42","best_bid":"0.41","hash":"37e94bb3c07c7341bda55db2b8c46a5cfe4bcdfb","price":"0.99","side":"SELL","size":"5335.02"}],"timestamp":"1785130979838"},"payload_hash":"964e0bb974ae5041db2d02bdedcaa9e15784733985d4b4cc051d872250a34a95","raw_frame":"{\"market\":\"0x3b40066b5cf3871a2f6237c5628bd8092a206aa998558ac5ec13c4483e31e160\", \"price_changes\":[{\"asset_id\":\"14766054693214075530629349735273995982307625376442606753688071083149620216746\", \"price\":\"0.01\", \"size\":\"5335.02\", \"side\":\"BUY\", \"hash\":\"680b5e4ce8c3901bbd0b5d63ac685d510ce942a2\", \"best_bid\":\"0.58\", \"best_ask\":\"0.59\"}, {\"asset_id\":\"110216635572655435074987471276357323571387854733835379371586402147734167783946\", \"price\":\"0.99\", \"size\":\"5335.02\", \"side\":\"SELL\", \"hash\":\"37e94bb3c07c7341bda55db2b8c46a5cfe4bcdfb\", \"best_bid\":\"0.41\", \"best_ask\":\"0.42\"}], \"timestamp\":\"1785130979838\", \"event_type\":\"price_change\"}","received_at":"2026-07-27T05:42:59.796745Z","schema_version":"clob-market-ws.price_change.v1","sequence":null,"server_hash":null,"server_timestamp":"1785130979838","session_id":"502006c5cfcd437296561ea750c9ec8b","source":"clob_market_ws"},"received_at":"2026-07-27T05:42:59.796745Z","record_id":"bf07bd1052763b02af4fd1e03fd1c25bfe6213b481a8418cfa1f9e47b241119b","schema_fingerprint":"4aa3821a28b0b7c2400bc59aba4bcc0a76e971dadd19610d3ad38c768e124dc7","schema_version":"edge-lab-recorder.raw.v1","sequence":null,"source":"clob_market_ws"}
{"event_at":"2026-07-27T05:42:59.942000Z","event_fingerprint":"4d0c1561a38ade884e848b8959800dd5b1a0c1b383e2ade7392032b102af9f0d","payload":{"connection_id":"efc69d3132f1467b8e898a382b23ac0d","event_at":"2026-07-27T05:42:59.942000Z","event_type":"price_change","frame_hash":"7a1887b6834da790aa5496b9b53882db6f589f0856b81deabdb45070aa600444","frame_index":0,"kind":"data","monotonic_ns":232963133222583,"payload":{"event_type":"price_change","market":"0x3b40066b5cf3871a2f6237c5628bd8092a206aa998558ac5ec13c4483e31e160","price_changes":[{"asset_id":"14766054693214075530629349735273995982307625376442606753688071083149620216746","best_ask":"0.59","best_bid":"0.58","hash":"92b3a9a1d7bca5a24f7710eeaf8c1699a87b3161","price":"0.67","side":"SELL","size":"33.73"},{"asset_id":"110216635572655435074987471276357323571387854733835379371586402147734167783946","best_ask":"0.42","best_bid":"0.41","hash":"fa7a171703dc6c68dc26a0db54cdd1c978698ac2","price":"0.33","side":"BUY","size":"33.73"}],"timestamp":"1785130979942"},"payload_hash":"8df8f1854a6a723cb9c3d8b783132b743f4003dda259c445fb57211d6f38c8d5","raw_frame":"{\"market\":\"0x3b40066b5cf3871a2f6237c5628bd8092a206aa998558ac5ec13c4483e31e160\", \"price_changes\":[{\"asset_id\":\"14766054693214075530629349735273995982307625376442606753688071083149620216746\", \"price\":\"0.67\", \"size\":\"33.73\", \"side\":\"SELL\", \"hash\":\"92b3a9a1d7bca5a24f7710eeaf8c1699a87b3161\", \"best_bid\":\"0.58\", \"best_ask\":\"0.59\"}, {\"asset_id\":\"110216635572655435074987471276357323571387854733835379371586402147734167783946\", \"price\":\"0.33\", \"size\":\"33.73\", \"side\":\"BUY\", \"hash\":\"fa7a171703dc6c68dc26a0db54cdd1c978698ac2\", \"best_bid\":\"0.41\", \"best_ask\":\"0.42\"}], \"timestamp\":\"1785130979942\", \"event_type\":\"price_change\"}","received_at":"2026-07-27T05:42:59.900429Z","schema_version":"clob-market-ws.price_change.v1","sequence":null,"server_hash":null,"server_timestamp":"1785130979942","session_id":"502006c5cfcd437296561ea750c9ec8b","source":"clob_market_ws"},"received_at":"2026-07-27T05:42:59.900429Z","record_id":"92cec3a7a7842198432c8cb4cf29438f82d43a0e121318f51937be9e44cfccfc","schema_fingerprint":"4aa3821a28b0b7c2400bc59aba4bcc0a76e971dadd19610d3ad38c768e124dc7","schema_version":"edge-lab-recorder.raw.v1","sequence":null,"source":"clob_market_ws"}
{"event_at":"2026-07-27T05:42:59.957000Z","event_fingerprint":"521ffd27dbcc8c2dac4fe1bfce418250cc74bfe950653c245a50eeec74365d16","payload":{"connection_id":"efc69d3132f1467b8e898a382b23ac0d","event_at":"2026-07-27T05:42:59.957000Z","event_type":"price_change","frame_hash":"5e4311ecbd0ea6eb82c9985efaf32844fd1bcaf382d28d9d4362e1c11b498141","frame_index":0,"kind":"data","monotonic_ns":232963155448208,"payload":{"event_type":"price_change","market":"0x3b40066b5cf3871a2f6237c5628bd8092a206aa998558ac5ec13c4483e31e160","price_changes":[{"asset_id":"14766054693214075530629349735273995982307625376442606753688071083149620216746","best_ask":"0.59","best_bid":"0.58","hash":"9170c8d6376ab0e97118de4780c0a221f4efd95b","price":"0.01","side":"BUY","size":"5330.02"},{"asset_id":"110216635572655435074987471276357323571387854733835379371586402147734167783946","best_ask":"0.42","best_bid":"0.41","hash":"d8748f958892a90ab801d7572a167f50d6e4c4c5","price":"0.99","side":"SELL","size":"5330.02"}],"timestamp":"1785130979957"},"payload_hash":"f487322a7397462ab6e3686ce4bc8245e70b8ce7bafd396830b7f09bcb5ace5a","raw_frame":"{\"market\":\"0x3b40066b5cf3871a2f6237c5628bd8092a206aa998558ac5ec13c4483e31e160\", \"price_changes\":[{\"asset_id\":\"14766054693214075530629349735273995982307625376442606753688071083149620216746\", \"price\":\"0.01\", \"size\":\"5330.02\", \"side\":\"BUY\", \"hash\":\"9170c8d6376ab0e97118de4780c0a221f4efd95b\", \"best_bid\":\"0.58\", \"best_ask\":\"0.59\"}, {\"asset_id\":\"110216635572655435074987471276357323571387854733835379371586402147734167783946\", \"price\":\"0.99\", \"size\":\"5330.02\", \"side\":\"SELL\", \"hash\":\"d8748f958892a90ab801d7572a167f50d6e4c4c5\", \"best_bid\":\"0.41\", \"best_ask\":\"0.42\"}], \"timestamp\":\"1785130979957\", \"event_type\":\"price_change\"}","received_at":"2026-07-27T05:42:59.922658Z","schema_version":"clob-market-ws.price_change.v1","sequence":null,"server_hash":null,"server_timestamp":"1785130979957","session_id":"502006c5cfcd437296561ea750c9ec8b","source":"clob_market_ws"},"received_at":"2026-07-27T05:42:59.922658Z","record_id":"d1046aece5160d7016f3cc8ecf5f46a769ce3bcd8115a62d60c038c995c6d108","schema_fingerprint":"4aa3821a28b0b7c2400bc59aba4bcc0a76e971dadd19610d3ad38c768e124dc7","schema_version":"edge-lab-recorder.raw.v1","sequence":null,"source":"clob_market_ws"}
{"event_at":"2026-07-27T05:43:00.012000Z","event_fingerprint":"5f18db49b4baeb560a92dc382a458eb747f922e72933baa1876518ae43b220ab","payload":{"connection_id":"efc69d3132f1467b8e898a382b23ac0d","event_at":"2026-07-27T05:43:00.012000Z","event_type":"price_change","frame_hash":"647167b41b62037ab5eb49410e70bd7cfda3db332a894166364ee73e626c1370","frame_index":0,"kind":"data","monotonic_ns":232963204021666,"payload":{"event_type":"price_change","market":"0x3b40066b5cf3871a2f6237c5628bd8092a206aa998558ac5ec13c4483e31e160","price_changes":[{"asset_id":"14766054693214075530629349735273995982307625376442606753688071083149620216746","best_ask":"0.59","best_bid":"0.58","hash":"60b0a5c07e51f778dbcbe48e7fcf357c405c1c97","price":"0.56","side":"BUY","size":"58"},{"asset_id":"110216635572655435074987471276357323571387854733835379371586402147734167783946","best_ask":"0.42","best_bid":"0.41","hash":"69bfc6cac08f140206b01665c19eba4d5e1ec58e","price":"0.44","side":"SELL","size":"58"}],"timestamp":"1785130980012"},"payload_hash":"52c598585d2f69d6c2ab999bade9f234e35506760c51d20b0272feb625c85496","raw_frame":"{\"market\":\"0x3b40066b5cf3871a2f6237c5628bd8092a206aa998558ac5ec13c4483e31e160\", \"price_changes\":[{\"asset_id\":\"14766054693214075530629349735273995982307625376442606753688071083149620216746\", \"price\":\"0.56\", \"size\":\"58\", \"side\":\"BUY\", \"hash\":\"60b0a5c07e51f778dbcbe48e7fcf357c405c1c97\", \"best_bid\":\"0.58\", \"best_ask\":\"0.59\"}, {\"asset_id\":\"110216635572655435074987471276357323571387854733835379371586402147734167783946\", \"price\":\"0.44\", \"size\":\"58\", \"side\":\"SELL\", \"hash\":\"69bfc6cac08f140206b01665c19eba4d5e1ec58e\", \"best_bid\":\"0.41\", \"best_ask\":\"0.42\"}], \"timestamp\":\"1785130980012\", \"event_type\":\"price_change\"}","received_at":"2026-07-27T05:42:59.971231Z","schema_version":"clob-market-ws.price_change.v1","sequence":null,"server_hash":null,"server_timestamp":"1785130980012","session_id":"502006c5cfcd437296561ea750c9ec8b","source":"clob_market_ws"},"received_at":"2026-07-27T05:42:59.971231Z","record_id":"bb315a8a250cf5cd9caf5fd9a1f6102708812d1f75a6c7bec5f0a79e52de79a0","schema_fingerprint":"4aa3821a28b0b7c2400bc59aba4bcc0a76e971dadd19610d3ad38c768e124dc7","schema_version":"edge-lab-recorder.raw.v1","sequence":null,"source":"clob_market_ws"}
{"event_at":"2026-07-27T05:43:00.013000Z","event_fingerprint":"3d1927b55f78742bf9535b8244480910b4f869bbe997ce2b2fcc1e7fdcb1f0b5","payload":{"connection_id":"efc69d3132f1467b8e898a382b23ac0d","event_at":"2026-07-27T05:43:00.013000Z","event_type":"price_change","frame_hash":"b438c58f91e359bf6ca4fc576ace8af3bce447f0cce1fa1ccfdd542022a106f7","frame_index":0,"kind":"data","monotonic_ns":232963206790708,"payload":{"event_type":"price_change","market":"0x3b40066b5cf3871a2f6237c5628bd8092a206aa998558ac5ec13c4483e31e160","price_changes":[{"asset_id":"110216635572655435074987471276357323571387854733835379371586402147734167783946","best_ask":"0.42","best_bid":"0.41","hash":"028b241f284eade35d15accb8a7f47d720d58e8b","price":"0.44","side":"SELL","size":"83"},{"asset_id":"14766054693214075530629349735273995982307625376442606753688071083149620216746","best_ask":"0.59","best_bid":"0.58","hash":"32d6757d22b439029d65cde604da56cf0b021787","price":"0.56","side":"BUY","size":"83"}],"timestamp":"1785130980013"},"payload_hash":"6b45e34c5aa01aa6f5e1613362adde22ad1ce669f04b70026a9c2f534503d599","raw_frame":"{\"market\":\"0x3b40066b5cf3871a2f6237c5628bd8092a206aa998558ac5ec13c4483e31e160\", \"price_changes\":[{\"asset_id\":\"110216635572655435074987471276357323571387854733835379371586402147734167783946\", \"price\":\"0.44\", \"size\":\"83\", \"side\":\"SELL\", \"hash\":\"028b241f284eade35d15accb8a7f47d720d58e8b\", \"best_bid\":\"0.41\", \"best_ask\":\"0.42\"}, {\"asset_id\":\"14766054693214075530629349735273995982307625376442606753688071083149620216746\", \"price\":\"0.56\", \"size\":\"83\", \"side\":\"BUY\", \"hash\":\"32d6757d22b439029d65cde604da56cf0b021787\", \"best_bid\":\"0.58\", \"best_ask\":\"0.59\"}], \"timestamp\":\"1785130980013\", \"event_type\":\"price_change\"}","received_at":"2026-07-27T05:42:59.974001Z","schema_version":"clob-market-ws.price_change.v1","sequence":null,"server_hash":null,"server_timestamp":"1785130980013","session_id":"502006c5cfcd437296561ea750c9ec8b","source":"clob_market_ws"},"received_at":"2026-07-27T05:42:59.974001Z","record_id":"ed6a2098c378c4efacb2c92c9542e2567c0c01475b825c17bbdca07e810c8d8d","schema_fingerprint":"4aa3821a28b0b7c2400bc59aba4bcc0a76e971dadd19610d3ad38c768e124dc7","schema_version":"edge-lab-recorder.raw.v1","sequence":null,"source":"clob_market_ws"}
{"event_at":"2026-07-27T05:43:00.016000Z","event_fingerprint":"b06a4c9cd54d36527ca6832d5b317fcf93755c2ab02e4e6e0c82afe0dd3deb94","payload":{"connection_id":"efc69d3132f1467b8e898a382b23ac0d","event_at":"2026-07-27T05:43:00.016000Z","event_type":"price_change","frame_hash":"2c2d9fc773a3c3bcbcf99cc8d887b7ada4a33084bea0b35fe62d9277673e751e","frame_index":0,"kind":"data","monotonic_ns":232963209193458,"payload":{"event_type":"price_change","market":"0x3b40066b5cf3871a2f6237c5628bd8092a206aa998558ac5ec13c4483e31e160","price_changes":[{"asset_id":"110216635572655435074987471276357323571387854733835379371586402147734167783946","best_ask":"0.42","best_bid":"0.41","hash":"0ca39f7c5bef734f265ac301cb75f9177cd9c23c","price":"0.38","side":"BUY","size":"0"},{"asset_id":"14766054693214075530629349735273995982307625376442606753688071083149620216746","best_ask":"0.59","best_bid":"0.58","hash":"0f4400ee3a4d546b26df1f2dd5f6e0b0597af913","price":"0.62","side":"SELL","size":"0"}],"timestamp":"1785130980016"},"payload_hash":"7a410bfd1da2b55c6a4c0ec8ebf1ccd30702989a18c13d1987d73755ee284311","raw_frame":"{\"market\":\"0x3b40066b5cf3871a2f6237c5628bd8092a206aa998558ac5ec13c4483e31e160\", \"price_changes\":[{\"asset_id\":\"110216635572655435074987471276357323571387854733835379371586402147734167783946\", \"price\":\"0.38\", \"size\":\"0\", \"side\":\"BUY\", \"hash\":\"0ca39f7c5bef734f265ac301cb75f9177cd9c23c\", \"best_bid\":\"0.41\", \"best_ask\":\"0.42\"}, {\"asset_id\":\"14766054693214075530629349735273995982307625376442606753688071083149620216746\", \"price\":\"0.62\", \"size\":\"0\", \"side\":\"SELL\", \"hash\":\"0f4400ee3a4d546b26df1f2dd5f6e0b0597af913\", \"best_bid\":\"0.58\", \"best_ask\":\"0.59\"}], \"timestamp\":\"1785130980016\", \"event_type\":\"price_change\"}","received_at":"2026-07-27T05:42:59.976402Z","schema_version":"clob-market-ws.price_change.v1","sequence":null,"server_hash":null,"server_timestamp":"1785130980016","session_id":"502006c5cfcd437296561ea750c9ec8b","source":"clob_market_ws"},"received_at":"2026-07-27T05:42:59.976402Z","record_id":"ce40d3eb451aed1c223860330c4718fd025ffd31d1cb937052750fe111d46df9","schema_fingerprint":"4aa3821a28b0b7c2400bc59aba4bcc0a76e971dadd19610d3ad38c768e124dc7","schema_version":"edge-lab-recorder.raw.v1","sequence":null,"source":"clob_market_ws"}
{"event_at":"2026-07-27T05:43:00.023000Z","event_fingerprint":"26d04e64e7e2bc3cbc21cc79a562097366a4cca3c32f0e892da2d9c750417792","payload":{"connection_id":"efc69d3132f1467b8e898a382b23ac0d","event_at":"2026-07-27T05:43:00.023000Z","event_type":"price_change","frame_hash":"8bc3c26332f74232c47d76fd51f48656eb05dddd302378703aff283032ef7c72","frame_index":0,"kind":"data","monotonic_ns":232963217368875,"payload":{"event_type":"price_change","market":"0x3b40066b5cf3871a2f6237c5628bd8092a206aa998558ac5ec13c4483e31e160","price_changes":[{"asset_id":"110216635572655435074987471276357323571387854733835379371586402147734167783946","best_ask":"0.42","best_bid":"0.41","hash":"348c6732f47c493c4f5b1d450dd75650d4811d28","price":"0.01","side":"BUY","size":"5337.45"},{"asset_id":"14766054693214075530629349735273995982307625376442606753688071083149620216746","best_ask":"0.59","best_bid":"0.58","hash":"928d65c606ff3d1de74e6716eb50daf23dc00585","price":"0.99","side":"SELL","size":"5337.45"}],"timestamp":"1785130980023"},"payload_hash":"5b46f14bb4e729e7f75d5167c76760a9cae63f634d73bbce5c3b1b5177e048e4","raw_frame":"{\"market\":\"0x3b40066b5cf3871a2f6237c5628bd8092a206aa998558ac5ec13c4483e31e160\", \"price_changes\":[{\"asset_id\":\"110216635572655435074987471276357323571387854733835379371586402147734167783946\", \"price\":\"0.01\", \"size\":\"5337.45\", \"side\":\"BUY\", \"hash\":\"348c6732f47c493c4f5b1d450dd75650d4811d28\", \"best_bid\":\"0.41\", \"best_ask\":\"0.42\"}, {\"asset_id\":\"14766054693214075530629349735273995982307625376442606753688071083149620216746\", \"price\":\"0.99\", \"size\":\"5337.45\", \"side\":\"SELL\", \"hash\":\"928d65c606ff3d1de74e6716eb50daf23dc00585\", \"best_bid\":\"0.58\", \"best_ask\":\"0.59\"}], \"timestamp\":\"1785130980023\", \"event_type\":\"price_change\"}","received_at":"2026-07-27T05:42:59.984578Z","schema_version":"clob-market-ws.price_change.v1","sequence":null,"server_hash":null,"server_timestamp":"1785130980023","session_id":"502006c5cfcd437296561ea750c9ec8b","source":"clob_market_ws"},"received_at":"2026-07-27T05:42:59.984578Z","record_id":"7beefb5b43d707289a1bcfe194e69a8267a2063bd438f24fd5cc84dd467e82f3","schema_fingerprint":"4aa3821a28b0b7c2400bc59aba4bcc0a76e971dadd19610d3ad38c768e124dc7","schema_version":"edge-lab-recorder.raw.v1","sequence":null,"source":"clob_market_ws"}
{"event_at":"2026-07-27T05:43:00.025000Z","event_fingerprint":"6beaba7d9941c455c8f8f11a154f1de88d1e6c5db5ad6688c678a62c85f2c7ef","payload":{"connection_id":"efc69d3132f1467b8e898a382b23ac0d","event_at":"2026-07-27T05:43:00.025000Z","event_type":"price_change","frame_hash":"96e7febf945577218556e5afcee62b1f7b98595ddb95503fdea449fddb060b9d","frame_index":0,"kind":"data","monotonic_ns":232963220869666,"payload":{"event_type":"price_change","market":"0x3b40066b5cf3871a2f6237c5628bd8092a206aa998558ac5ec13c4483e31e160","price_changes":[{"asset_id":"110216635572655435074987471276357323571387854733835379371586402147734167783946","best_ask":"0.42","best_bid":"0.41","hash":"27c9a914a63bc6188322fe0816bb25bc4ac8e8f3","price":"0.25","side":"BUY","size":"105.63"},{"asset_id":"14766054693214075530629349735273995982307625376442606753688071083149620216746","best_ask":"0.59","best_bid":"0.58","hash":"5092723a78d694fc36ee8051fc65bc217b6d03a7","price":"0.75","side":"SELL","size":"105.63"}],"timestamp":"1785130980025"},"payload_hash":"665f16c1fab2ae91fcaa0b3d4390eeec07d1f9f3993ffed1b260c934d6f559f5","raw_frame":"{\"market\":\"0x3b40066b5cf3871a2f6237c5628bd8092a206aa998558ac5ec13c4483e31e160\", \"price_changes\":[{\"asset_id\":\"110216635572655435074987471276357323571387854733835379371586402147734167783946\", \"price\":\"0.25\", \"size\":\"105.63\", \"side\":\"BUY\", \"hash\":\"27c9a914a63bc6188322fe0816bb25bc4ac8e8f3\", \"best_bid\":\"0.41\", \"best_ask\":\"0.42\"}, {\"asset_id\":\"14766054693214075530629349735273995982307625376442606753688071083149620216746\", \"price\":\"0.75\", \"size\":\"105.63\", \"side\":\"SELL\", \"hash\":\"5092723a78d694fc36ee8051fc65bc217b6d03a7\", \"best_bid\":\"0.58\", \"best_ask\":\"0.59\"}], \"timestamp\":\"1785130980025\", \"event_type\":\"price_change\"}","received_at":"2026-07-27T05:42:59.988079Z","schema_version":"clob-market-ws.price_change.v1","sequence":null,"server_hash":null,"server_timestamp":"1785130980025","session_id":"502006c5cfcd437296561ea750c9ec8b","source":"clob_market_ws"},"received_at":"2026-07-27T05:42:59.988079Z","record_id":"8df550b24e18d6a8e0b85c99bb57154e742687bcf3239866815d2231658c8a6e","schema_fingerprint":"4aa3821a28b0b7c2400bc59aba4bcc0a76e971dadd19610d3ad38c768e124dc7","schema_version":"edge-lab-recorder.raw.v1","sequence":null,"source":"clob_market_ws"}
{"event_at":"2026-07-27T05:43:00.029000Z","event_fingerprint":"01d1e285fc0abd867176b7198108ecbfbd64b6fc32e16c1fa248557b99212f8b","payload":{"connection_id":"efc69d3132f1467b8e898a382b23ac0d","event_at":"2026-07-27T05:43:00.029000Z","event_type":"price_change","frame_hash":"43dec21f465a91c816b8d8852f0fd9ec3cd558ba956b4bee79fc6c9e054fad11","frame_index":0,"kind":"data","monotonic_ns":232963225073500,"payload":{"event_type":"price_change","market":"0x3b40066b5cf3871a2f6237c5628bd8092a206aa998558ac5ec13c4483e31e160","price_changes":[{"asset_id":"110216635572655435074987471276357323571387854733835379371586402147734167783946","best_ask":"0.42","best_bid":"0.41","hash":"7020d2a644e4a7f3dc9b8c32f7d40fb898b21db6","price":"0.01","side":"BUY","size":"5342.45"},{"asset_id":"14766054693214075530629349735273995982307625376442606753688071083149620216746","best_ask":"0.59","best_bid":"0.58","hash":"e35de7a48f68cebbc40962e17bc23c257da26ba2","price":"0.99","side":"SELL","size":"5342.45"}],"timestamp":"1785130980029"},"payload_hash":"8f973156482d1dce55bcee1c43ee1f5cfad7130374e62836039d5caf2027b7fe","raw_frame":"{\"market\":\"0x3b40066b5cf3871a2f6237c5628bd8092a206aa998558ac5ec13c4483e31e160\", \"price_changes\":[{\"asset_id\":\"110216635572655435074987471276357323571387854733835379371586402147734167783946\", \"price\":\"0.01\", \"size\":\"5342.45\", \"side\":\"BUY\", \"hash\":\"7020d2a644e4a7f3dc9b8c32f7d40fb898b21db6\", \"best_bid\":\"0.41\", \"best_ask\":\"0.42\"}, {\"asset_id\":\"14766054693214075530629349735273995982307625376442606753688071083149620216746\", \"price\":\"0.99\", \"size\":\"5342.45\", \"side\":\"SELL\", \"hash\":\"e35de7a48f68cebbc40962e17bc23c257da26ba2\", \"best_bid\":\"0.58\", \"best_ask\":\"0.59\"}], \"timestamp\":\"1785130980029\", \"event_type\":\"price_change\"}","received_at":"2026-07-27T05:42:59.992284Z","schema_version":"clob-market-ws.price_change.v1","sequence":null,"server_hash":null,"server_timestamp":"1785130980029","session_id":"502006c5cfcd437296561ea750c9ec8b","source":"clob_market_ws"},"received_at":"2026-07-27T05:42:59.992284Z","record_id":"03df635bc4b235fda2b187972c02ff1de6485d9e90aae60632c859ab58a5ba6d","schema_fingerprint":"4aa3821a28b0b7c2400bc59aba4bcc0a76e971dadd19610d3ad38c768e124dc7","schema_version":"edge-lab-recorder.raw.v1","sequence":null,"source":"clob_market_ws"}
{"event_at":"2026-07-27T05:43:00.040000Z","event_fingerprint":"0bc2fad1c71e5c5dd901bc2cb84a0c2222bcb9bd20e2ab84892306036bd201e9","payload":{"connection_id":"efc69d3132f1467b8e898a382b23ac0d","event_at":"2026-07-27T05:43:00.040000Z","event_type":"price_change","frame_hash":"38bd7c7e641d8f8f1e5b41614f9850b720c81ec11f134dace66bd3a01adbd1e6","frame_index":0,"kind":"data","monotonic_ns":232963232280583,"payload":{"event_type":"price_change","market":"0x3b40066b5cf3871a2f6237c5628bd8092a206aa998558ac5ec13c4483e31e160","price_changes":[{"asset_id":"110216635572655435074987471276357323571387854733835379371586402147734167783946","best_ask":"0.42","best_bid":"0.41","hash":"74fcecdbab734b29b2c6f9144164c6826470c202","price":"0.39","side":"BUY","size":"25"},{"asset_id":"14766054693214075530629349735273995982307625376442606753688071083149620216746","best_ask":"0.59","best_bid":"0.58","hash":"a3151a19fbcf8710586d17b0e54311e97f754d98","price":"0.61","side":"SELL","size":"25"}],"timestamp":"1785130980040"},"payload_hash":"510c805fc23a514434a164656c3a641275c53679c499d36376a7b61f00ad504a","raw_frame":"{\"market\":\"0x3b40066b5cf3871a2f6237c5628bd8092a206aa998558ac5ec13c4483e31e160\", \"price_changes\":[{\"asset_id\":\"110216635572655435074987471276357323571387854733835379371586402147734167783946\", \"price\":\"0.39\", \"size\":\"25\", \"side\":\"BUY\", \"hash\":\"74fcecdbab734b29b2c6f9144164c6826470c202\", \"best_bid\":\"0.41\", \"best_ask\":\"0.42\"}, {\"asset_id\":\"14766054693214075530629349735273995982307625376442606753688071083149620216746\", \"price\":\"0.61\", \"size\":\"25\", \"side\":\"SELL\", \"hash\":\"a3151a19fbcf8710586d17b0e54311e97f754d98\", \"best_bid\":\"0.58\", \"best_ask\":\"0.59\"}], \"timestamp\":\"1785130980040\", \"event_type\":\"price_change\"}","received_at":"2026-07-27T05:42:59.999489Z","schema_version":"clob-market-ws.price_change.v1","sequence":null,"server_hash":null,"server_timestamp":"1785130980040","session_id":"502006c5cfcd437296561ea750c9ec8b","source":"clob_market_ws"},"received_at":"2026-07-27T05:42:59.999489Z","record_id":"4a71580e06d4630946f5ea15e4d7f784b06d416e2a5aa184d1f00f44565fc124","schema_fingerprint":"4aa3821a28b0b7c2400bc59aba4bcc0a76e971dadd19610d3ad38c768e124dc7","schema_version":"edge-lab-recorder.raw.v1","sequence":null,"source":"clob_market_ws"}
{"event_at":"2026-07-27T05:43:00.052000Z","event_fingerprint":"97914ceb56ec756a5a89ee83931241afabca89c8440755da02dceca021428cc1","payload":{"connection_id":"efc69d3132f1467b8e898a382b23ac0d","event_at":"2026-07-27T05:43:00.052000Z","event_type":"price_change","frame_hash":"a6eabd09dee0472b4460f512694c351fd477447d15ebbc601c937fae919a5dff","frame_index":0,"kind":"data","monotonic_ns":232963248816000,"payload":{"event_type":"price_change","market":"0x3b40066b5cf3871a2f6237c5628bd8092a206aa998558ac5ec13c4483e31e160","price_changes":[{"asset_id":"14766054693214075530629349735273995982307625376442606753688071083149620216746","best_ask":"0.59","best_bid":"0.58","hash":"e2276e47d8409f37d545f2099efb2261bd840c3f","price":"0.01","side":"BUY","size":"5335.02"},{"asset_id":"110216635572655435074987471276357323571387854733835379371586402147734167783946","best_ask":"0.42","best_bid":"0.41","hash":"37a1472186024138cb1d3f527dda7df3779c47f5","price":"0.99","side":"SELL","size":"5335.02"}],"timestamp":"1785130980052"},"payload_hash":"baa2fcb87aecbf157275059ee7325ac534004a741b5017bcabf9a5ead67c08b6","raw_frame":"{\"market\":\"0x3b40066b5cf3871a2f6237c5628bd8092a206aa998558ac5ec13c4483e31e160\", \"price_changes\":[{\"asset_id\":\"14766054693214075530629349735273995982307625376442606753688071083149620216746\", \"price\":\"0.01\", \"size\":\"5335.02\", \"side\":\"BUY\", \"hash\":\"e2276e47d8409f37d545f2099efb2261bd840c3f\", \"best_bid\":\"0.58\", \"best_ask\":\"0.59\"}, {\"asset_id\":\"110216635572655435074987471276357323571387854733835379371586402147734167783946\", \"price\":\"0.99\", \"size\":\"5335.02\", \"side\":\"SELL\", \"hash\":\"37a1472186024138cb1d3f527dda7df3779c47f5\", \"best_bid\":\"0.41\", \"best_ask\":\"0.42\"}], \"timestamp\":\"1785130980052\", \"event_type\":\"price_change\"}","received_at":"2026-07-27T05:43:00.016025Z","schema_version":"clob-market-ws.price_change.v1","sequence":null,"server_hash":null,"server_timestamp":"1785130980052","session_id":"502006c5cfcd437296561ea750c9ec8b","source":"clob_market_ws"},"received_at":"2026-07-27T05:43:00.016025Z","record_id":"1d632980f3d50cb89a40abb421aad53b6cf044273a492ca57702b538c8bb81df","schema_fingerprint":"4aa3821a28b0b7c2400bc59aba4bcc0a76e971dadd19610d3ad38c768e124dc7","schema_version":"edge-lab-recorder.raw.v1","sequence":null,"source":"clob_market_ws"}
{"event_at":"2026-07-27T05:43:00.060000Z","event_fingerprint":"e7ed9ae56d7fed43fba69a11d66b7f41cf1eef3706deb6560c2dcbef9610e90e","payload":{"connection_id":"efc69d3132f1467b8e898a382b23ac0d","event_at":"2026-07-27T05:43:00.060000Z","event_type":"price_change","frame_hash":"abb5975738c05534f89b6c487b97409b96616c46db636a29ad4d13b51115aaa5","frame_index":0,"kind":"data","monotonic_ns":232963255595791,"payload":{"event_type":"price_change","market":"0x3b40066b5cf3871a2f6237c5628bd8092a206aa998558ac5ec13c4483e31e160","price_changes":[{"asset_id":"14766054693214075530629349735273995982307625376442606753688071083149620216746","best_ask":"0.59","best_bid":"0.58","hash":"702b262c24a00c4687d8d9ceb474de8c26c3a4cc","price":"0.02","side":"BUY","size":"557"},{"asset_id":"110216635572655435074987471276357323571387854733835379371586402147734167783946","best_ask":"0.42","best_bid":"0.41","hash":"e682b2f75609dca92627eec64229d63ba3763719","price":"0.98","side":"SELL","size":"557"}],"timestamp":"1785130980060"},"payload_hash":"a94197575b8bd07417b225095a21cca33ab48be4737ac4c1aee69d5d9448b2ce","raw_frame":"{\"market\":\"0x3b40066b5cf3871a2f6237c5628bd8092a206aa998558ac5ec13c4483e31e160\", \"price_changes\":[{\"asset_id\":\"14766054693214075530629349735273995982307625376442606753688071083149620216746\", \"price\":\"0.02\", \"size\":\"557\", \"side\":\"BUY\", \"hash\":\"702b262c24a00c4687d8d9ceb474de8c26c3a4cc\", \"best_bid\":\"0.58\", \"best_ask\":\"0.59\"}, {\"asset_id\":\"110216635572655435074987471276357323571387854733835379371586402147734167783946\", \"price\":\"0.98\", \"size\":\"557\", \"side\":\"SELL\", \"hash\":\"e682b2f75609dca92627eec64229d63ba3763719\", \"best_bid\":\"0.41\", \"best_ask\":\"0.42\"}], \"timestamp\":\"1785130980060\", \"event_type\":\"price_change\"}","received_at":"2026-07-27T05:43:00.022811Z","schema_version":"clob-market-ws.price_change.v1","sequence":null,"server_hash":null,"server_timestamp":"1785130980060","session_id":"502006c5cfcd437296561ea750c9ec8b","source":"clob_market_ws"},"received_at":"2026-07-27T05:43:00.022811Z","record_id":"35f732403b9b51b94c8f73c2bda509fba7753e2a558c9f592d90fff441b4647b","schema_fingerprint":"4aa3821a28b0b7c2400bc59aba4bcc0a76e971dadd19610d3ad38c768e124dc7","schema_version":"edge-lab-recorder.raw.v1","sequence":null,"source":"clob_market_ws"}
{"event_at":"2026-07-27T05:43:00.065000Z","event_fingerprint":"402ace9f6224554ef8ba25b49bae547fa64a7d4365b3caf5d856cd31578fd450","payload":{"connection_id":"efc69d3132f1467b8e898a382b23ac0d","event_at":"2026-07-27T05:43:00.065000Z","event_type":"price_change","frame_hash":"e15ad9b32e1cdec38f28a344703856989546836ac759a3f512de2451bb5a0839","frame_index":0,"kind":"data","monotonic_ns":232963259112916,"payload":{"event_type":"price_change","market":"0x3b40066b5cf3871a2f6237c5628bd8092a206aa998558ac5ec13c4483e31e160","price_changes":[{"asset_id":"110216635572655435074987471276357323571387854733835379371586402147734167783946","best_ask":"0.42","best_bid":"0.41","hash":"c7e0c3743bf392e9bc5dc96a6e0525c413fdd837","price":"0.01","side":"BUY","size":"5337.45"},{"asset_id":"14766054693214075530629349735273995982307625376442606753688071083149620216746","best_ask":"0.59","best_bid":"0.58","hash":"630c3d7af6dccc8d48c734b0c6af11dab623dd4b","price":"0.99","side":"SELL","size":"5337.45"}],"timestamp":"1785130980065"},"payload_hash":"14be58584a53dc39841224e051df558c0cff218dfe74e9ad8d778f27330c3354","raw_frame":"{\"market\":\"0x3b40066b5cf3871a2f6237c5628bd8092a206aa998558ac5ec13c4483e31e160\", \"price_changes\":[{\"asset_id\":\"110216635572655435074987471276357323571387854733835379371586402147734167783946\", \"price\":\"0.01\", \"size\":\"5337.45\", \"side\":\"BUY\", \"hash\":\"c7e0c3743bf392e9bc5dc96a6e0525c413fdd837\", \"best_bid\":\"0.41\", \"best_ask\":\"0.42\"}, {\"asset_id\":\"14766054693214075530629349735273995982307625376442606753688071083149620216746\", \"price\":\"0.99\", \"size\":\"5337.45\", \"side\":\"SELL\", \"hash\":\"630c3d7af6dccc8d48c734b0c6af11dab623dd4b\", \"best_bid\":\"0.58\", \"best_ask\":\"0.59\"}], \"timestamp\":\"1785130980065\", \"event_type\":\"price_change\"}","received_at":"2026-07-27T05:43:00.026328Z","schema_version":"clob-market-ws.price_change.v1","sequence":null,"server_hash":null,"server_timestamp":"1785130980065","session_id":"502006c5cfcd437296561ea750c9ec8b","source":"clob_market_ws"},"received_at":"2026-07-27T05:43:00.026328Z","record_id":"6f4be8fa882d386bac648cd128c03f4abc535e1e919cdfa29112acea7e2d780e","schema_fingerprint":"4aa3821a28b0b7c2400bc59aba4bcc0a76e971dadd19610d3ad38c768e124dc7","schema_version":"edge-lab-recorder.raw.v1","sequence":null,"source":"clob_market_ws"}
{"event_at":"2026-07-27T05:43:00.071000Z","event_fingerprint":"7bebe1567d3be35703d0594a4c89d6c485ec153e323e5dc633f3cfcaba40b261","payload":{"connection_id":"efc69d3132f1467b8e898a382b23ac0d","event_at":"2026-07-27T05:43:00.071000Z","event_type":"price_change","frame_hash":"a19a043f6b7c2d9740a0b4c820c885c686b48a759642809cd2626b1363556fbd","frame_index":0,"kind":"data","monotonic_ns":232963265008583,"payload":{"event_type":"price_change","market":"0x3b40066b5cf3871a2f6237c5628bd8092a206aa998558ac5ec13c4483e31e160","price_changes":[{"asset_id":"14766054693214075530629349735273995982307625376442606753688071083149620216746","best_ask":"0.59","best_bid":"0.58","hash":"04d825cd1a3fdd962b5860cb36bfa4a7ef44e682","price":"0.67","side":"SELL","size":"41.77"},{"asset_id":"110216635572655435074987471276357323571387854733835379371586402147734167783946","best_ask":"0.42","best_bid":"0.41","hash":"5934bf0ec891022723faa3c3726c460d17448eb5","price":"0.33","side":"BUY","size":"41.77"}],"timestamp":"1785130980071"},"payload_hash":"ac354964f2ff729df142d4b86e05c6f736e4df9f44af99757adecac0dcd0a160","raw_frame":"{\"market\":\"0x3b40066b5cf3871a2f6237c5628bd8092a206aa998558ac5ec13c4483e31e160\", \"price_changes\":[{\"asset_id\":\"14766054693214075530629349735273995982307625376442606753688071083149620216746\", \"price\":\"0.67\", \"size\":\"41.77\", \"side\":\"SELL\", \"hash\":\"04d825cd1a3fdd962b5860cb36bfa4a7ef44e682\", \"best_bid\":\"0.58\", \"best_ask\":\"0.59\"}, {\"asset_id\":\"110216635572655435074987471276357323571387854733835379371586402147734167783946\", \"price\":\"0.33\", \"size\":\"41.77\", \"side\":\"BUY\", \"hash\":\"5934bf0ec891022723faa3c3726c460d17448eb5\", \"best_bid\":\"0.41\", \"best_ask\":\"0.42\"}], \"timestamp\":\"1785130980071\", \"event_type\":\"price_change\"}","received_at":"2026-07-27T05:43:00.032223Z","schema_version":"clob-market-ws.price_change.v1","sequence":null,"server_hash":null,"server_timestamp":"1785130980071","session_id":"502006c5cfcd437296561ea750c9ec8b","source":"clob_market_ws"},"received_at":"2026-07-27T05:43:00.032223Z","record_id":"784ea883baf4013992907aea9bc5704b3e99845cb9ca6af0b28399d62e40a7a7","schema_fingerprint":"4aa3821a28b0b7c2400bc59aba4bcc0a76e971dadd19610d3ad38c768e124dc7","schema_version":"edge-lab-recorder.raw.v1","sequence":null,"source":"clob_market_ws"}
{"event_at":"2026-07-27T05:43:00.072000Z","event_fingerprint":"41a4a04ac471c1e142edd281bc9edee4e5695fa7a0d4e0e7a3667f797622c27a","payload":{"connection_id":"efc69d3132f1467b8e898a382b23ac0d","event_at":"2026-07-27T05:43:00.072000Z","event_type":"price_change","frame_hash":"38e4c2eef5218fb43886bed3237279d1b87c674868d20b4d12f501be2d79a3cc","frame_index":0,"kind":"data","monotonic_ns":232963265721750,"payload":{"event_type":"price_change","market":"0x3b40066b5cf3871a2f6237c5628bd8092a206aa998558ac5ec13c4483e31e160","price_changes":[{"asset_id":"14766054693214075530629349735273995982307625376442606753688071083149620216746","best_ask":"0.59","best_bid":"0.58","hash":"fb801acfc14fdb26b17241dfbba76f2dbf81fbef","price":"0.01","side":"BUY","size":"5330.02"},{"asset_id":"110216635572655435074987471276357323571387854733835379371586402147734167783946","best_ask":"0.42","best_bid":"0.41","hash":"a06f5af422fd81a53efe5ef2de927f91a4fca67b","price":"0.99","side":"SELL","size":"5330.02"}],"timestamp":"1785130980072"},"payload_hash":"638ca13840c3570de0ca85604b67d6d93154c62ac9f93be431b9a6930c6d6ef1","raw_frame":"{\"market\":\"0x3b40066b5cf3871a2f6237c5628bd8092a206aa998558ac5ec13c4483e31e160\", \"price_changes\":[{\"asset_id\":\"14766054693214075530629349735273995982307625376442606753688071083149620216746\", \"price\":\"0.01\", \"size\":\"5330.02\", \"side\":\"BUY\", \"hash\":\"fb801acfc14fdb26b17241dfbba76f2dbf81fbef\", \"best_bid\":\"0.58\", \"best_ask\":\"0.59\"}, {\"asset_id\":\"110216635572655435074987471276357323571387854733835379371586402147734167783946\", \"price\":\"0.99\", \"size\":\"5330.02\", \"side\":\"SELL\", \"hash\":\"a06f5af422fd81a53efe5ef2de927f91a4fca67b\", \"best_bid\":\"0.41\", \"best_ask\":\"0.42\"}], \"timestamp\":\"1785130980072\", \"event_type\":\"price_change\"}","received_at":"2026-07-27T05:43:00.032937Z","schema_version":"clob-market-ws.price_change.v1","sequence":null,"server_hash":null,"server_timestamp":"1785130980072","session_id":"502006c5cfcd437296561ea750c9ec8b","source":"clob_market_ws"},"received_at":"2026-07-27T05:43:00.032937Z","record_id":"5d3f1fb149f35a9b380d761890a568b39b98a11e561c41322d254116cf9b4029","schema_fingerprint":"4aa3821a28b0b7c2400bc59aba4bcc0a76e971dadd19610d3ad38c768e124dc7","schema_version":"edge-lab-recorder.raw.v1","sequence":null,"source":"clob_market_ws"}
{"event_at":"2026-07-27T05:43:00.116000Z","event_fingerprint":"b22fc8671d35142e02f53aaa98eb03ee4213efd5dc562cf7e352bd44a75b3c16","payload":{"connection_id":"efc69d3132f1467b8e898a382b23ac0d","event_at":"2026-07-27T05:43:00.116000Z","event_type":"price_change","frame_hash":"62e545fa9e2599f08853d94aa40df643115ce9d0da96d9681cc9a2ef9ba2d099","frame_index":0,"kind":"data","monotonic_ns":232963307043541,"payload":{"event_type":"price_change","market":"0x3b40066b5cf3871a2f6237c5628bd8092a206aa998558ac5ec13c4483e31e160","price_changes":[{"asset_id":"14766054693214075530629349735273995982307625376442606753688071083149620216746","best_ask":"0.59","best_bid":"0.58","hash":"9486ea72fbb2d674623a29e2cc3f44f156061e16","price":"0.02","side":"BUY","size":"552"},{"asset_id":"110216635572655435074987471276357323571387854733835379371586402147734167783946","best_ask":"0.42","best_bid":"0.41","hash":"e79244f17543c0844a6a18cf1fc0c9e1401a344a","price":"0.98","side":"SELL","size":"552"}],"timestamp":"1785130980116"},"payload_hash":"b40c6fd54994f76965dd408fd65975152f3e6dff54a01a6fcf664a4d3dffbb3d","raw_frame":"{\"market\":\"0x3b40066b5cf3871a2f6237c5628bd8092a206aa998558ac5ec13c4483e31e160\", \"price_changes\":[{\"asset_id\":\"14766054693214075530629349735273995982307625376442606753688071083149620216746\", \"price\":\"0.02\", \"size\":\"552\", \"side\":\"BUY\", \"hash\":\"9486ea72fbb2d674623a29e2cc3f44f156061e16\", \"best_bid\":\"0.58\", \"best_ask\":\"0.59\"}, {\"asset_id\":\"110216635572655435074987471276357323571387854733835379371586402147734167783946\", \"price\":\"0.98\", \"size\":\"552\", \"side\":\"SELL\", \"hash\":\"e79244f17543c0844a6a18cf1fc0c9e1401a344a\", \"best_bid\":\"0.41\", \"best_ask\":\"0.42\"}], \"timestamp\":\"1785130980116\", \"event_type\":\"price_change\"}","received_at":"2026-07-27T05:43:00.074251Z","schema_version":"clob-market-ws.price_change.v1","sequence":null,"server_hash":null,"server_timestamp":"1785130980116","session_id":"502006c5cfcd437296561ea750c9ec8b","source":"clob_market_ws"},"received_at":"2026-07-27T05:43:00.074251Z","record_id":"5e6a1e8b85e71445e8fa82c9ccc47a54cf414883cd278b97fb9e71de177e108b","schema_fingerprint":"4aa3821a28b0b7c2400bc59aba4bcc0a76e971dadd19610d3ad38c768e124dc7","schema_version":"edge-lab-recorder.raw.v1","sequence":null,"source":"clob_market_ws"}
{"event_at":"2026-07-27T05:43:00.120000Z","event_fingerprint":"6c869852bef1f5f375dc5519baf9f711c6187ced24de660f470b043913359e34","payload":{"connection_id":"efc69d3132f1467b8e898a382b23ac0d","event_at":"2026-07-27T05:43:00.120000Z","event_type":"price_change","frame_hash":"833364053720bccfdd4db707c4b5634a2a23fd2da33591daf3fc83ae34877335","frame_index":0,"kind":"data","monotonic_ns":232963313300666,"payload":{"event_type":"price_change","market":"0x3b40066b5cf3871a2f6237c5628bd8092a206aa998558ac5ec13c4483e31e160","price_changes":[{"asset_id":"110216635572655435074987471276357323571387854733835379371586402147734167783946","best_ask":"0.42","best_bid":"0.41","hash":"1972adfa14abcbca27d10968c856f0ac34b58a1b","price":"0.01","side":"BUY","size":"5332.45"},{"asset_id":"14766054693214075530629349735273995982307625376442606753688071083149620216746","best_ask":"0.59","best_bid":"0.58","hash":"437aa11056831e873daf9eba85e05cc28043996c","price":"0.99","side":"SELL","size":"5332.45"}],"timestamp":"1785130980120"},"payload_hash":"cc41026100557c07ffc3be1d24222f1aee72159148c6e41feba94755be69a18d","raw_frame":"{\"market\":\"0x3b40066b5cf3871a2f6237c5628bd8092a206aa998558ac5ec13c4483e31e160\", \"price_changes\":[{\"asset_id\":\"110216635572655435074987471276357323571387854733835379371586402147734167783946\", \"price\":\"0.01\", \"size\":\"5332.45\", \"side\":\"BUY\", \"hash\":\"1972adfa14abcbca27d10968c856f0ac34b58a1b\", \"best_bid\":\"0.41\", \"best_ask\":\"0.42\"}, {\"asset_id\":\"14766054693214075530629349735273995982307625376442606753688071083149620216746\", \"price\":\"0.99\", \"size\":\"5332.45\", \"side\":\"SELL\", \"hash\":\"437aa11056831e873daf9eba85e05cc28043996c\", \"best_bid\":\"0.58\", \"best_ask\":\"0.59\"}], \"timestamp\":\"1785130980120\", \"event_type\":\"price_change\"}","received_at":"2026-07-27T05:43:00.080507Z","schema_version":"clob-market-ws.price_change.v1","sequence":null,"server_hash":null,"server_timestamp":"1785130980120","session_id":"502006c5cfcd437296561ea750c9ec8b","source":"clob_market_ws"},"received_at":"2026-07-27T05:43:00.080507Z","record_id":"c82837959fd2dfc0adfcb274efbfd14393992a21fd9de4944ab12e348a5887f0","schema_fingerprint":"4aa3821a28b0b7c2400bc59aba4bcc0a76e971dadd19610d3ad38c768e124dc7","schema_version":"edge-lab-recorder.raw.v1","sequence":null,"source":"clob_market_ws"}
{"event_at":"2026-07-27T05:43:00.144000Z","event_fingerprint":"45ed65e68a3794ff5607d126ed933543fe163f07288741d7678e4a10236cb701","payload":{"connection_id":"efc69d3132f1467b8e898a382b23ac0d","event_at":"2026-07-27T05:43:00.144000Z","event_type":"price_change","frame_hash":"0cf25cd35be3507ba6e3a948cad6a8636ccf4016f8d85ded9e43e9b0b46c6b86","frame_index":0,"kind":"data","monotonic_ns":232963335733833,"payload":{"event_type":"price_change","market":"0x3b40066b5cf3871a2f6237c5628bd8092a206aa998558ac5ec13c4483e31e160","price_changes":[{"asset_id":"110216635572655435074987471276357323571387854733835379371586402147734167783946","best_ask":"0.42","best_bid":"0.41","hash":"40cf921b2e40b5b73583b7a9127f280fb5c1651c","price":"0.25","side":"BUY","size":"85.63"},{"asset_id":"14766054693214075530629349735273995982307625376442606753688071083149620216746","best_ask":"0.59","best_bid":"0.58","hash":"7a490b177717dab3b7da0f0cb9c4b8625441b35c","price":"0.75","side":"SELL","size":"85.63"}],"timestamp":"1785130980144"},"payload_hash":"5098139ba4e88ef7ab125c0135b6c2d257d1a978eaa31de8b559339c6c937d6d","raw_frame":"{\"market\":\"0x3b40066b5cf3871a2f6237c5628bd8092a206aa998558ac5ec13c4483e31e160\", \"price_changes\":[{\"asset_id\":\"110216635572655435074987471276357323571387854733835379371586402147734167783946\", \"price\":\"0.25\", \"size\":\"85.63\", \"side\":\"BUY\", \"hash\":\"40cf921b2e40b5b73583b7a9127f280fb5c1651c\", \"best_bid\":\"0.41\", \"best_ask\":\"0.42\"}, {\"asset_id\":\"14766054693214075530629349735273995982307625376442606753688071083149620216746\", \"price\":\"0.75\", \"size\":\"85.63\", \"side\":\"SELL\", \"hash\":\"7a490b177717dab3b7da0f0cb9c4b8625441b35c\", \"best_bid\":\"0.58\", \"best_ask\":\"0.59\"}], \"timestamp\":\"1785130980144\", \"event_type\":\"price_change\"}","received_at":"2026-07-27T05:43:00.102942Z","schema_version":"clob-market-ws.price_change.v1","sequence":null,"server_hash":null,"server_timestamp":"1785130980144","session_id":"502006c5cfcd437296561ea750c9ec8b","source":"clob_market_ws"},"received_at":"2026-07-27T05:43:00.102942Z","record_id":"94c918164fc741096ea5f6db09764d1fc2de533bd4e57201e535d733fad3f0e0","schema_fingerprint":"4aa3821a28b0b7c2400bc59aba4bcc0a76e971dadd19610d3ad38c768e124dc7","schema_version":"edge-lab-recorder.raw.v1","sequence":null,"source":"clob_market_ws"}
{"event_at":"2026-07-27T05:43:00.162000Z","event_fingerprint":"e194f84073d2257ae324966740a9816f83483392261254df7ce8a4e9233a3149","payload":{"connection_id":"efc69d3132f1467b8e898a382b23ac0d","event_at":"2026-07-27T05:43:00.162000Z","event_type":"price_change","frame_hash":"7387c3032f0cf7a0672dfb0f24ce95f6a50a259cbd4cee0a89840913a50e1ddf","frame_index":0,"kind":"data","monotonic_ns":232963353540291,"payload":{"event_type":"price_change","market":"0x3b40066b5cf3871a2f6237c5628bd8092a206aa998558ac5ec13c4483e31e160","price_changes":[{"asset_id":"14766054693214075530629349735273995982307625376442606753688071083149620216746","best_ask":"0.59","best_bid":"0.58","hash":"26d529ba203f6e556c25f4cec89dc99b5cd5d1f4","price":"0.01","side":"BUY","size":"5335.02"},{"asset_id":"110216635572655435074987471276357323571387854733835379371586402147734167783946","best_ask":"0.42","best_bid":"0.41","hash":"62ec2a8d826bf5ef276bae3153b45bfcbbf9bcf5","price":"0.99","side":"SELL","size":"5335.02"}],"timestamp":"1785130980162"},"payload_hash":"cf9c4b8d69d16e4a29bb4c4ef9c40512684d9e4791b59bfa1860a776109ff41b","raw_frame":"{\"market\":\"0x3b40066b5cf3871a2f6237c5628bd8092a206aa998558ac5ec13c4483e31e160\", \"price_changes\":[{\"asset_id\":\"14766054693214075530629349735273995982307625376442606753688071083149620216746\", \"price\":\"0.01\", \"size\":\"5335.02\", \"side\":\"BUY\", \"hash\":\"26d529ba203f6e556c25f4cec89dc99b5cd5d1f4\", \"best_bid\":\"0.58\", \"best_ask\":\"0.59\"}, {\"asset_id\":\"110216635572655435074987471276357323571387854733835379371586402147734167783946\", \"price\":\"0.99\", \"size\":\"5335.02\", \"side\":\"SELL\", \"hash\":\"62ec2a8d826bf5ef276bae3153b45bfcbbf9bcf5\", \"best_bid\":\"0.41\", \"best_ask\":\"0.42\"}], \"timestamp\":\"1785130980162\", \"event_type\":\"price_change\"}","received_at":"2026-07-27T05:43:00.120752Z","schema_version":"clob-market-ws.price_change.v1","sequence":null,"server_hash":null,"server_timestamp":"1785130980162","session_id":"502006c5cfcd437296561ea750c9ec8b","source":"clob_market_ws"},"received_at":"2026-07-27T05:43:00.120752Z","record_id":"2221ccaf9bc964f0bfe43ea502ecae96c6e715c72e9e705c7e0931d611812ab5","schema_fingerprint":"4aa3821a28b0b7c2400bc59aba4bcc0a76e971dadd19610d3ad38c768e124dc7","schema_version":"edge-lab-recorder.raw.v1","sequence":null,"source":"clob_market_ws"}
{"event_at":"2026-07-27T05:43:00.173000Z","event_fingerprint":"e038ee1b6a1531ed6a39f5d494a295bc9a7a781122fe78c4b0e2893b2f5e742e","payload":{"connection_id":"efc69d3132f1467b8e898a382b23ac0d","event_at":"2026-07-27T05:43:00.173000Z","event_type":"price_change","frame_hash":"c33773ee45c7d9b68a27ec526b565324e970c6f94cd3a75f77e991245aee1332","frame_index":0,"kind":"data","monotonic_ns":232963365539125,"payload":{"event_type":"price_change","market":"0x3b40066b5cf3871a2f6237c5628bd8092a206aa998558ac5ec13c4483e31e160","price_changes":[{"asset_id":"14766054693214075530629349735273995982307625376442606753688071083149620216746","best_ask":"0.59","best_bid":"0.58","hash":"993a315a08df925f209bbc298ca20c10f681270f","price":"0.67","side":"SELL","size":"33.73"},{"asset_id":"110216635572655435074987471276357323571387854733835379371586402147734167783946","best_ask":"0.42","best_bid":"0.41","hash":"7329db99413b54d4663255460dbc3325076c3901","price":"0.33","side":"BUY","size":"33.73"}],"timestamp":"1785130980173"},"payload_hash":"af0948a1d149bcacd1a5ec731c3e8242f719784d4200cca03b5684cd39caf3a8","raw_frame":"{\"market\":\"0x3b40066b5cf3871a2f6237c5628bd8092a206aa998558ac5ec13c4483e31e160\", \"price_changes\":[{\"asset_id\":\"14766054693214075530629349735273995982307625376442606753688071083149620216746\", \"price\":\"0.67\", \"size\":\"33.73\", \"side\":\"SELL\", \"hash\":\"993a315a08df925f209bbc298ca20c10f681270f\", \"best_bid\":\"0.58\", \"best_ask\":\"0.59\"}, {\"asset_id\":\"110216635572655435074987471276357323571387854733835379371586402147734167783946\", \"price\":\"0.33\", \"size\":\"33.73\", \"side\":\"BUY\", \"hash\":\"7329db99413b54d4663255460dbc3325076c3901\", \"best_bid\":\"0.41\", \"best_ask\":\"0.42\"}], \"timestamp\":\"1785130980173\", \"event_type\":\"price_change\"}","received_at":"2026-07-27T05:43:00.132754Z","schema_version":"clob-market-ws.price_change.v1","sequence":null,"server_hash":null,"server_timestamp":"1785130980173","session_id":"502006c5cfcd437296561ea750c9ec8b","source":"clob_market_ws"},"received_at":"2026-07-27T05:43:00.132754Z","record_id":"2b1071a1f96c1e8bdd3510e4cf500606ae9d252bbe905c4dd4c1e55ab4606d28","schema_fingerprint":"4aa3821a28b0b7c2400bc59aba4bcc0a76e971dadd19610d3ad38c768e124dc7","schema_version":"edge-lab-recorder.raw.v1","sequence":null,"source":"clob_market_ws"}
{"event_at":"2026-07-27T05:43:00.183000Z","event_fingerprint":"34415102bf6662df7c3c5c51a3c11ea21a213d604e987101973a610a271bedbf","payload":{"connection_id":"efc69d3132f1467b8e898a382b23ac0d","event_at":"2026-07-27T05:43:00.183000Z","event_type":"price_change","frame_hash":"84cab32d15ac9b2fc36e0903ff42be071839e91b9d7675e6f03a7c20f254f69f","frame_index":0,"kind":"data","monotonic_ns":232963377401416,"payload":{"event_type":"price_change","market":"0x3b40066b5cf3871a2f6237c5628bd8092a206aa998558ac5ec13c4483e31e160","price_changes":[{"asset_id":"14766054693214075530629349735273995982307625376442606753688071083149620216746","best_ask":"0.59","best_bid":"0.58","hash":"f3c8264342974fc3afbcdb2624bdffbbfb7bf4c4","price":"0.01","side":"BUY","size":"5330.02"},{"asset_id":"110216635572655435074987471276357323571387854733835379371586402147734167783946","best_ask":"0.42","best_bid":"0.41","hash":"a9f3939eb66270af21ae5478341ec95bf04a8a64","price":"0.99","side":"SELL","size":"5330.02"}],"timestamp":"1785130980183"},"payload_hash":"d5b0499d74ae18c17afa0a8ae4feaf9d26f9c29067b1f4f8322d2cced91ec23b","raw_frame":"{\"market\":\"0x3b40066b5cf3871a2f6237c5628bd8092a206aa998558ac5ec13c4483e31e160\", \"price_changes\":[{\"asset_id\":\"14766054693214075530629349735273995982307625376442606753688071083149620216746\", \"price\":\"0.01\", \"size\":\"5330.02\", \"side\":\"BUY\", \"hash\":\"f3c8264342974fc3afbcdb2624bdffbbfb7bf4c4\", \"best_bid\":\"0.58\", \"best_ask\":\"0.59\"}, {\"asset_id\":\"110216635572655435074987471276357323571387854733835379371586402147734167783946\", \"price\":\"0.99\", \"size\":\"5330.02\", \"side\":\"SELL\", \"hash\":\"a9f3939eb66270af21ae5478341ec95bf04a8a64\", \"best_bid\":\"0.41\", \"best_ask\":\"0.42\"}], \"timestamp\":\"1785130980183\", \"event_type\":\"price_change\"}","received_at":"2026-07-27T05:43:00.144607Z","schema_version":"clob-market-ws.price_change.v1","sequence":null,"server_hash":null,"server_timestamp":"1785130980183","session_id":"502006c5cfcd437296561ea750c9ec8b","source":"clob_market_ws"},"received_at":"2026-07-27T05:43:00.144607Z","record_id":"61e41161fa4d7a9137694dc10cc4d5960a1b9a31240e99ae87c928dab20a87dc","schema_fingerprint":"4aa3821a28b0b7c2400bc59aba4bcc0a76e971dadd19610d3ad38c768e124dc7","schema_version":"edge-lab-recorder.raw.v1","sequence":null,"source":"clob_market_ws"}
{"event_at":"2026-07-27T05:43:00.206000Z","event_fingerprint":"dbd182d688b6db3f68b2ab18b1b3db9d6381c50c654507dd126cc185a3a01c1b","payload":{"connection_id":"efc69d3132f1467b8e898a382b23ac0d","event_at":"2026-07-27T05:43:00.206000Z","event_type":"price_change","frame_hash":"05f470fed1e749f14690003614128b4df163e5890af886ac71d0f1ab3f94ae4e","frame_index":0,"kind":"data","monotonic_ns":232963399357000,"payload":{"event_type":"price_change","market":"0x3b40066b5cf3871a2f6237c5628bd8092a206aa998558ac5ec13c4483e31e160","price_changes":[{"asset_id":"110216635572655435074987471276357323571387854733835379371586402147734167783946","best_ask":"0.42","best_bid":"0.41","hash":"18a5e2f594650e7ff46a5c3501159f54abf2f248","price":"0.44","side":"SELL","size":"58"},{"asset_id":"14766054693214075530629349735273995982307625376442606753688071083149620216746","best_ask":"0.59","best_bid":"0.58","hash":"d502dcdb22fffda9b5c835e18929ab21507f0893","price":"0.56","side":"BUY","size":"58"}],"timestamp":"1785130980206"},"payload_hash":"aec89c8ada641d362132d81ebe502bb5453e94c76ce886c32bb83889bd599e45","raw_frame":"{\"market\":\"0x3b40066b5cf3871a2f6237c5628bd8092a206aa998558ac5ec13c4483e31e160\", \"price_changes\":[{\"asset_id\":\"110216635572655435074987471276357323571387854733835379371586402147734167783946\", \"price\":\"0.44\", \"size\":\"58\", \"side\":\"SELL\", \"hash\":\"18a5e2f594650e7ff46a5c3501159f54abf2f248\", \"best_bid\":\"0.41\", \"best_ask\":\"0.42\"}, {\"asset_id\":\"14766054693214075530629349735273995982307625376442606753688071083149620216746\", \"price\":\"0.56\", \"size\":\"58\", \"side\":\"BUY\", \"hash\":\"d502dcdb22fffda9b5c835e18929ab21507f0893\", \"best_bid\":\"0.58\", \"best_ask\":\"0.59\"}], \"timestamp\":\"1785130980206\", \"event_type\":\"price_change\"}","received_at":"2026-07-27T05:43:00.166559Z","schema_version":"clob-market-ws.price_change.v1","sequence":null,"server_hash":null,"server_timestamp":"1785130980206","session_id":"502006c5cfcd437296561ea750c9ec8b","source":"clob_market_ws"},"received_at":"2026-07-27T05:43:00.166559Z","record_id":"05bf401b0ad9af4bc2ea9ac6aba3546680bd61bb1e3642402cafbd22765c40fe","schema_fingerprint":"4aa3821a28b0b7c2400bc59aba4bcc0a76e971dadd19610d3ad38c768e124dc7","schema_version":"edge-lab-recorder.raw.v1","sequence":null,"source":"clob_market_ws"}
{"event_at":"2026-07-27T05:43:00.207000Z","event_fingerprint":"ef4aec9e30b8d94f780e7eb37b1631fbd4dc7b3e4eacafcc31097164b95fc829","payload":{"connection_id":"efc69d3132f1467b8e898a382b23ac0d","event_at":"2026-07-27T05:43:00.207000Z","event_type":"price_change","frame_hash":"f821bac557daab8284fb8bd060aa29908a4e85a94ead343bab3e95b94e1d0310","frame_index":0,"kind":"data","monotonic_ns":232963401157708,"payload":{"event_type":"price_change","market":"0x3b40066b5cf3871a2f6237c5628bd8092a206aa998558ac5ec13c4483e31e160","price_changes":[{"asset_id":"110216635572655435074987471276357323571387854733835379371586402147734167783946","best_ask":"0.42","best_bid":"0.41","hash":"d364d71371a4801afb052dd79cf25dca3bb8db91","price":"0.39","side":"BUY","size":"0"},{"asset_id":"14766054693214075530629349735273995982307625376442606753688071083149620216746","best_ask":"0.59","best_bid":"0.58","hash":"a6bfd8dd2dd2c663577114772441edba7003cd1a","price":"0.61","side":"SELL","size":"0"}],"timestamp":"1785130980207"},"payload_hash":"164d88eb9cbccf6fdbb6f248bfb9b7faef2e706c950166483262eb87a7ba9b3f","raw_frame":"{\"market\":\"0x3b40066b5cf3871a2f6237c5628bd8092a206aa998558ac5ec13c4483e31e160\", \"price_changes\":[{\"asset_id\":\"110216635572655435074987471276357323571387854733835379371586402147734167783946\", \"price\":\"0.39\", \"size\":\"0\", \"side\":\"BUY\", \"hash\":\"d364d71371a4801afb052dd79cf25dca3bb8db91\", \"best_bid\":\"0.41\", \"best_ask\":\"0.42\"}, {\"asset_id\":\"14766054693214075530629349735273995982307625376442606753688071083149620216746\", \"price\":\"0.61\", \"size\":\"0\", \"side\":\"SELL\", \"hash\":\"a6bfd8dd2dd2c663577114772441edba7003cd1a\", \"best_bid\":\"0.58\", \"best_ask\":\"0.59\"}], \"timestamp\":\"1785130980207\", \"event_type\":\"price_change\"}","received_at":"2026-07-27T05:43:00.168374Z","schema_version":"clob-market-ws.price_change.v1","sequence":null,"server_hash":null,"server_timestamp":"1785130980207","session_id":"502006c5cfcd437296561ea750c9ec8b","source":"clob_market_ws"},"received_at":"2026-07-27T05:43:00.168374Z","record_id":"6102bc8a5021bbf6bafcb71ac5fb070103248c0fd550e8778ba081f0ce6b2f01","schema_fingerprint":"4aa3821a28b0b7c2400bc59aba4bcc0a76e971dadd19610d3ad38c768e124dc7","schema_version":"edge-lab-recorder.raw.v1","sequence":null,"source":"clob_market_ws"}
{"event_at":"2026-07-27T05:43:00.208000Z","event_fingerprint":"b4b1145f1afccc021790577f82be88f2604ce6d43b540afab0b4f89d1e598b52","payload":{"connection_id":"efc69d3132f1467b8e898a382b23ac0d","event_at":"2026-07-27T05:43:00.208000Z","event_type":"price_change","frame_hash":"a8caa58527d4ebdb0a02126081883c04fc4b9908718e2ff0491229b595f15c27","frame_index":0,"kind":"data","monotonic_ns":232963401955000,"payload":{"event_type":"price_change","market":"0x3b40066b5cf3871a2f6237c5628bd8092a206aa998558ac5ec13c4483e31e160","price_changes":[{"asset_id":"14766054693214075530629349735273995982307625376442606753688071083149620216746","best_ask":"0.59","best_bid":"0.58","hash":"bad3e1a4a74be3780ab58c3b012d55ca2d98fc8f","price":"0.56","side":"BUY","size":"33"},{"asset_id":"110216635572655435074987471276357323571387854733835379371586402147734167783946","best_ask":"0.42","best_bid":"0.41","hash":"159606b5784b30bb81ac2f43ddb7cbad607ce7ba","price":"0.44","side":"SELL","size":"33"}],"timestamp":"1785130980208"},"payload_hash":"985be833c56fb5fe4bed4a8aa37e3816b99efb2da1797156516f8704dc44908b","raw_frame":"{\"market\":\"0x3b40066b5cf3871a2f6237c5628bd8092a206aa998558ac5ec13c4483e31e160\", \"price_changes\":[{\"asset_id\":\"14766054693214075530629349735273995982307625376442606753688071083149620216746\", \"price\":\"0.56\", \"size\":\"33\", \"side\":\"BUY\", \"hash\":\"bad3e1a4a74be3780ab58c3b012d55ca2d98fc8f\", \"best_bid\":\"0.58\", \"best_ask\":\"0.59\"}, {\"asset_id\":\"110216635572655435074987471276357323571387854733835379371586402147734167783946\", \"price\":\"0.44\", \"size\":\"33\", \"side\":\"SELL\", \"hash\":\"159606b5784b30bb81ac2f43ddb7cbad607ce7ba\", \"best_bid\":\"0.41\", \"best_ask\":\"0.42\"}], \"timestamp\":\"1785130980208\", \"event_type\":\"price_change\"}","received_at":"2026-07-27T05:43:00.169171Z","schema_version":"clob-market-ws.price_change.v1","sequence":null,"server_hash":null,"server_timestamp":"1785130980208","session_id":"502006c5cfcd437296561ea750c9ec8b","source":"clob_market_ws"},"received_at":"2026-07-27T05:43:00.169171Z","record_id":"6bd31a2a653e8f9b4804be47bb83976a66366511857ce500b8ee1290565c6c35","schema_fingerprint":"4aa3821a28b0b7c2400bc59aba4bcc0a76e971dadd19610d3ad38c768e124dc7","schema_version":"edge-lab-recorder.raw.v1","sequence":null,"source":"clob_market_ws"}
{"event_at":"2026-07-27T05:43:00.232000Z","event_fingerprint":"2e2686fe58794520138edccb0074ac9596ec1817033fb10bedb869e7abcdd5b8","payload":{"connection_id":"efc69d3132f1467b8e898a382b23ac0d","event_at":"2026-07-27T05:43:00.232000Z","event_type":"price_change","frame_hash":"8003fa5643c57016dc169ddd1ac1dbd0f216ee5d013fee1c2d06c3f1f6f8378b","frame_index":0,"kind":"data","monotonic_ns":232963426486875,"payload":{"event_type":"price_change","market":"0x3b40066b5cf3871a2f6237c5628bd8092a206aa998558ac5ec13c4483e31e160","price_changes":[{"asset_id":"110216635572655435074987471276357323571387854733835379371586402147734167783946","best_ask":"0.42","best_bid":"0.41","hash":"967a1fec1d6dc000abc3091146891864757e460e","price":"0.38","side":"BUY","size":"25"},{"asset_id":"14766054693214075530629349735273995982307625376442606753688071083149620216746","best_ask":"0.59","best_bid":"0.58","hash":"4387c4d95ab2c426551ad7c937c126145297e095","price":"0.62","side":"SELL","size":"25"}],"timestamp":"1785130980232"},"payload_hash":"d9a09b44929abfc5778515e961a888c7c5035af8b2b50f977a501036ce3e941d","raw_frame":"{\"market\":\"0x3b40066b5cf3871a2f6237c5628bd8092a206aa998558ac5ec13c4483e31e160\", \"price_changes\":[{\"asset_id\":\"110216635572655435074987471276357323571387854733835379371586402147734167783946\", \"price\":\"0.38\", \"size\":\"25\", \"side\":\"BUY\", \"hash\":\"967a1fec1d6dc000abc3091146891864757e460e\", \"best_bid\":\"0.41\", \"best_ask\":\"0.42\"}, {\"asset_id\":\"14766054693214075530629349735273995982307625376442606753688071083149620216746\", \"price\":\"0.62\", \"size\":\"25\", \"side\":\"SELL\", \"hash\":\"4387c4d95ab2c426551ad7c937c126145297e095\", \"best_bid\":\"0.58\", \"best_ask\":\"0.59\"}], \"timestamp\":\"1785130980232\", \"event_type\":\"price_change\"}","received_at":"2026-07-27T05:43:00.193697Z","schema_version":"clob-market-ws.price_change.v1","sequence":null,"server_hash":null,"server_timestamp":"1785130980232","session_id":"502006c5cfcd437296561ea750c9ec8b","source":"clob_market_ws"},"received_at":"2026-07-27T05:43:00.193697Z","record_id":"99ac938f8c726f87d2955a5ff0726268fef83a8a02215139fc1d012b5acb671e","schema_fingerprint":"4aa3821a28b0b7c2400bc59aba4bcc0a76e971dadd19610d3ad38c768e124dc7","schema_version":"edge-lab-recorder.raw.v1","sequence":null,"source":"clob_market_ws"}
{"event_at":"2026-07-27T05:43:00.232000Z","event_fingerprint":"f135ba52f0f83e1c631b00f22573d9c97331a66142bcc0865814cf2d1224533e","payload":{"connection_id":"efc69d3132f1467b8e898a382b23ac0d","event_at":"2026-07-27T05:43:00.232000Z","event_type":"price_change","frame_hash":"47da0ec8c4d6083e6e92f1c1b8f31bd85e1859727abc9b10b432ec3b3ca9c8b1","frame_index":0,"kind":"data","monotonic_ns":232963429274750,"payload":{"event_type":"price_change","market":"0x3b40066b5cf3871a2f6237c5628bd8092a206aa998558ac5ec13c4483e31e160","price_changes":[{"asset_id":"14766054693214075530629349735273995982307625376442606753688071083149620216746","best_ask":"0.59","best_bid":"0.58","hash":"00a88be3e364b7226284723b8f77267ddc0dc828","price":"0.57","side":"BUY","size":"424"},{"asset_id":"110216635572655435074987471276357323571387854733835379371586402147734167783946","best_ask":"0.42","best_bid":"0.41","hash":"49f17b366de55153196a1808985a59895c510c99","price":"0.43","side":"SELL","size":"424"}],"timestamp":"1785130980232"},"payload_hash":"d199a5a2e289028184db798c4f19d330a0edb76cb6156380892cdb6957ba4c4a","raw_frame":"{\"market\":\"0x3b40066b5cf3871a2f6237c5628bd8092a206aa998558ac5ec13c4483e31e160\", \"price_changes\":[{\"asset_id\":\"14766054693214075530629349735273995982307625376442606753688071083149620216746\", \"price\":\"0.57\", \"size\":\"424\", \"side\":\"BUY\", \"hash\":\"00a88be3e364b7226284723b8f77267ddc0dc828\", \"best_bid\":\"0.58\", \"best_ask\":\"0.59\"}, {\"asset_id\":\"110216635572655435074987471276357323571387854733835379371586402147734167783946\", \"price\":\"0.43\", \"size\":\"424\", \"side\":\"SELL\", \"hash\":\"49f17b366de55153196a1808985a59895c510c99\", \"best_bid\":\"0.41\", \"best_ask\":\"0.42\"}], \"timestamp\":\"1785130980232\", \"event_type\":\"price_change\"}","received_at":"2026-07-27T05:43:00.196489Z","schema_version":"clob-market-ws.price_change.v1","sequence":null,"server_hash":null,"server_timestamp":"1785130980232","session_id":"502006c5cfcd437296561ea750c9ec8b","source":"clob_market_ws"},"received_at":"2026-07-27T05:43:00.196489Z","record_id":"529bb2b1c38151fa18962ec3cb466fbde36487eaf16991ba61888192bdaeb45a","schema_fingerprint":"4aa3821a28b0b7c2400bc59aba4bcc0a76e971dadd19610d3ad38c768e124dc7","schema_version":"edge-lab-recorder.raw.v1","sequence":null,"source":"clob_market_ws"}
{"event_at":"2026-07-27T05:43:00.234000Z","event_fingerprint":"efedd1b4d9a6ee99d45d68c843a2bb3e0fdd2a22ace9fb844fcc56975115f9da","payload":{"connection_id":"efc69d3132f1467b8e898a382b23ac0d","event_at":"2026-07-27T05:43:00.234000Z","event_type":"price_change","frame_hash":"e753772725739a7e63e36908226117b2109ee7cfdce6dd892e8725c04d28c7e2","frame_index":0,"kind":"data","monotonic_ns":232963431271291,"payload":{"event_type":"price_change","market":"0x3b40066b5cf3871a2f6237c5628bd8092a206aa998558ac5ec13c4483e31e160","price_changes":[{"asset_id":"110216635572655435074987471276357323571387854733835379371586402147734167783946","best_ask":"0.42","best_bid":"0.41","hash":"4611441e9bda3fa97f79626528defa1424311082","price":"0.43","side":"SELL","size":"449"},{"asset_id":"14766054693214075530629349735273995982307625376442606753688071083149620216746","best_ask":"0.59","best_bid":"0.58","hash":"481efbac080b0906f6268b1f7d2da2308fc2bcb6","price":"0.57","side":"BUY","size":"449"}],"timestamp":"1785130980234"},"payload_hash":"e171fe26c82185da5255e7faed154d1c99e06d15efdb49e17637a85384d19079","raw_frame":"{\"market\":\"0x3b40066b5cf3871a2f6237c5628bd8092a206aa998558ac5ec13c4483e31e160\", \"price_changes\":[{\"asset_id\":\"110216635572655435074987471276357323571387854733835379371586402147734167783946\", \"price\":\"0.43\", \"size\":\"449\", \"side\":\"SELL\", \"hash\":\"4611441e9bda3fa97f79626528defa1424311082\", \"best_bid\":\"0.41\", \"best_ask\":\"0.42\"}, {\"asset_id\":\"14766054693214075530629349735273995982307625376442606753688071083149620216746\", \"price\":\"0.57\", \"size\":\"449\", \"side\":\"BUY\", \"hash\":\"481efbac080b0906f6268b1f7d2da2308fc2bcb6\", \"best_bid\":\"0.58\", \"best_ask\":\"0.59\"}], \"timestamp\":\"1785130980234\", \"event_type\":\"price_change\"}","received_at":"2026-07-27T05:43:00.198489Z","schema_version":"clob-market-ws.price_change.v1","sequence":null,"server_hash":null,"server_timestamp":"1785130980234","session_id":"502006c5cfcd437296561ea750c9ec8b","source":"clob_market_ws"},"received_at":"2026-07-27T05:43:00.198489Z","record_id":"0c4583b61f7246efe60f7d88a25e82e315e11bb44479aeb11d2d86331b42153d","schema_fingerprint":"4aa3821a28b0b7c2400bc59aba4bcc0a76e971dadd19610d3ad38c768e124dc7","schema_version":"edge-lab-recorder.raw.v1","sequence":null,"source":"clob_market_ws"}
{"event_at":"2026-07-27T05:43:00.258000Z","event_fingerprint":"b1e24483fe2aafc7a095341d8c97e813399b48175974d822d388f67e5a4f23b3","payload":{"connection_id":"efc69d3132f1467b8e898a382b23ac0d","event_at":"2026-07-27T05:43:00.258000Z","event_type":"price_change","frame_hash":"3435c9a23adfaded0b93abb069ad0921e80d313c583343df6dc5c7435093459e","frame_index":0,"kind":"data","monotonic_ns":232963453177750,"payload":{"event_type":"price_change","market":"0x3b40066b5cf3871a2f6237c5628bd8092a206aa998558ac5ec13c4483e31e160","price_changes":[{"asset_id":"14766054693214075530629349735273995982307625376442606753688071083149620216746","best_ask":"0.59","best_bid":"0.58","hash":"6272727f9ec9b60ce0f0bb7ae4ab1019810d5933","price":"0.02","side":"BUY","size":"557"},{"asset_id":"110216635572655435074987471276357323571387854733835379371586402147734167783946","best_ask":"0.42","best_bid":"0.41","hash":"0ade85c5d81cd257e8c328a9f6048df784d135cf","price":"0.98","side":"SELL","size":"557"}],"timestamp":"1785130980258"},"payload_hash":"02c9198fe3743270970891ae028e5b3189e01686fa1f28a265896c0a93187fac","raw_frame":"{\"market\":\"0x3b40066b5cf3871a2f6237c5628bd8092a206aa998558ac5ec13c4483e31e160\", \"price_changes\":[{\"asset_id\":\"14766054693214075530629349735273995982307625376442606753688071083149620216746\", \"price\":\"0.02\", \"size\":\"557\", \"side\":\"BUY\", \"hash\":\"6272727f9ec9b60ce0f0bb7ae4ab1019810d5933\", \"best_bid\":\"0.58\", \"best_ask\":\"0.59\"}, {\"asset_id\":\"110216635572655435074987471276357323571387854733835379371586402147734167783946\", \"price\":\"0.98\", \"size\":\"557\", \"side\":\"SELL\", \"hash\":\"0ade85c5d81cd257e8c328a9f6048df784d135cf\", \"best_bid\":\"0.41\", \"best_ask\":\"0.42\"}], \"timestamp\":\"1785130980258\", \"event_type\":\"price_change\"}","received_at":"2026-07-27T05:43:00.220384Z","schema_version":"clob-market-ws.price_change.v1","sequence":null,"server_hash":null,"server_timestamp":"1785130980258","session_id":"502006c5cfcd437296561ea750c9ec8b","source":"clob_market_ws"},"received_at":"2026-07-27T05:43:00.220384Z","record_id":"af57dc69878de796128e87992bc88c40fc0a9f5db969f76e2f24c38e4ee27358","schema_fingerprint":"4aa3821a28b0b7c2400bc59aba4bcc0a76e971dadd19610d3ad38c768e124dc7","schema_version":"edge-lab-recorder.raw.v1","sequence":null,"source":"clob_market_ws"}
{"event_at":"2026-07-27T05:43:00.284000Z","event_fingerprint":"1aa817207bc333653c8f47b43ac91ed40345b3ad96ef2f7dc634cd9031d95527","payload":{"connection_id":"efc69d3132f1467b8e898a382b23ac0d","event_at":"2026-07-27T05:43:00.284000Z","event_type":"price_change","frame_hash":"cae1e4aa50d939dc41d573735d533e1ccfe0fd6301e0a72deee80cd2253649a8","frame_index":0,"kind":"data","monotonic_ns":232963478271833,"payload":{"event_type":"price_change","market":"0x3b40066b5cf3871a2f6237c5628bd8092a206aa998558ac5ec13c4483e31e160","price_changes":[{"asset_id":"110216635572655435074987471276357323571387854733835379371586402147734167783946","best_ask":"0.42","best_bid":"0.41","hash":"dbcb491d8f24df6b637a05f9c5acacc03c864b24","price":"0.33","side":"BUY","size":"22.78"},{"asset_id":"14766054693214075530629349735273995982307625376442606753688071083149620216746","best_ask":"0.59","best_bid":"0.58","hash":"acb7c553d148ef67bc49046c89e79bcf6c1093ea","price":"0.67","side":"SELL","size":"22.78"}],"timestamp":"1785130980284"},"payload_hash":"c34ece69c1637cb5224bd0a086421cab659810c57d456822dff2e0ea65a5d8eb","raw_frame":"{\"market\":\"0x3b40066b5cf3871a2f6237c5628bd8092a206aa998558ac5ec13c4483e31e160\", \"price_changes\":[{\"asset_id\":\"110216635572655435074987471276357323571387854733835379371586402147734167783946\", \"price\":\"0.33\", \"size\":\"22.78\", \"side\":\"BUY\", \"hash\":\"dbcb491d8f24df6b637a05f9c5acacc03c864b24\", \"best_bid\":\"0.41\", \"best_ask\":\"0.42\"}, {\"asset_id\":\"14766054693214075530629349735273995982307625376442606753688071083149620216746\", \"price\":\"0.67\", \"size\":\"22.78\", \"side\":\"SELL\", \"hash\":\"acb7c553d148ef67bc49046c89e79bcf6c1093ea\", \"best_bid\":\"0.58\", \"best_ask\":\"0.59\"}], \"timestamp\":\"1785130980284\", \"event_type\":\"price_change\"}","received_at":"2026-07-27T05:43:00.245482Z","schema_version":"clob-market-ws.price_change.v1","sequence":null,"server_hash":null,"server_timestamp":"1785130980284","session_id":"502006c5cfcd437296561ea750c9ec8b","source":"clob_market_ws"},"received_at":"2026-07-27T05:43:00.245482Z","record_id":"29dcbcf70fc4d81e4c90903db6c831686bb288d13cbeeee22264c8e58acc07ff","schema_fingerprint":"4aa3821a28b0b7c2400bc59aba4bcc0a76e971dadd19610d3ad38c768e124dc7","schema_version":"edge-lab-recorder.raw.v1","sequence":null,"source":"clob_market_ws"}
{"event_at":"2026-07-27T05:43:00.293000Z","event_fingerprint":"27ae2751a6ec7448c68b0fa7e6087dbba7510a4334d18618110330098f075d9b","payload":{"connection_id":"efc69d3132f1467b8e898a382b23ac0d","event_at":"2026-07-27T05:43:00.293000Z","event_type":"price_change","frame_hash":"f001c70f54b8b8b531476480cbd4f13267136651896a8b41c44fbe8ce2ecd839","frame_index":0,"kind":"data","monotonic_ns":232963484554375,"payload":{"event_type":"price_change","market":"0x3b40066b5cf3871a2f6237c5628bd8092a206aa998558ac5ec13c4483e31e160","price_changes":[{"asset_id":"14766054693214075530629349735273995982307625376442606753688071083149620216746","best_ask":"0.59","best_bid":"0.58","hash":"36f01d53dcb0436a5d2f17442a04e7a87515bdcb","price":"0.67","side":"SELL","size":"29.78"},{"asset_id":"110216635572655435074987471276357323571387854733835379371586402147734167783946","best_ask":"0.42","best_bid":"0.41","hash":"5e7c4ca0e088431858d0b4dad29eb31bc1f32fc8","price":"0.33","side":"BUY","size":"29.78"}],"timestamp":"1785130980293"},"payload_hash":"802bc8aa790b97d0a0c35e4ebdda7ebe16a67b68a68252754c5915e23988a81c","raw_frame":"{\"market\":\"0x3b40066b5cf3871a2f6237c5628bd8092a206aa998558ac5ec13c4483e31e160\", \"price_changes\":[{\"asset_id\":\"14766054693214075530629349735273995982307625376442606753688071083149620216746\", \"price\":\"0.67\", \"size\":\"29.78\", \"side\":\"SELL\", \"hash\":\"36f01d53dcb0436a5d2f17442a04e7a87515bdcb\", \"best_bid\":\"0.58\", \"best_ask\":\"0.59\"}, {\"asset_id\":\"110216635572655435074987471276357323571387854733835379371586402147734167783946\", \"price\":\"0.33\", \"size\":\"29.78\", \"side\":\"BUY\", \"hash\":\"5e7c4ca0e088431858d0b4dad29eb31bc1f32fc8\", \"best_bid\":\"0.41\", \"best_ask\":\"0.42\"}], \"timestamp\":\"1785130980293\", \"event_type\":\"price_change\"}","received_at":"2026-07-27T05:43:00.251766Z","schema_version":"clob-market-ws.price_change.v1","sequence":null,"server_hash":null,"server_timestamp":"1785130980293","session_id":"502006c5cfcd437296561ea750c9ec8b","source":"clob_market_ws"},"received_at":"2026-07-27T05:43:00.251766Z","record_id":"2a920a4423ef381b251f40f84945bc81f0e6cc0604b09e4266e99e2ca20c6d32","schema_fingerprint":"4aa3821a28b0b7c2400bc59aba4bcc0a76e971dadd19610d3ad38c768e124dc7","schema_version":"edge-lab-recorder.raw.v1","sequence":null,"source":"clob_market_ws"}
{"event_at":"2026-07-27T05:43:00.306000Z","event_fingerprint":"f05c56a4bf7cd372c8b5db6c46a0c667dcfd89bc78d2e568a0be02fae7769538","payload":{"connection_id":"efc69d3132f1467b8e898a382b23ac0d","event_at":"2026-07-27T05:43:00.306000Z","event_type":"price_change","frame_hash":"9fede916b3dafacd9c86cbf7706ab1d98220c7b14f664eedda6ced0f7d9ad156","frame_index":0,"kind":"data","monotonic_ns":232963496561333,"payload":{"event_type":"price_change","market":"0x3b40066b5cf3871a2f6237c5628bd8092a206aa998558ac5ec13c4483e31e160","price_changes":[{"asset_id":"110216635572655435074987471276357323571387854733835379371586402147734167783946","best_ask":"0.42","best_bid":"0.41","hash":"3b7db559ae72487729dab1f3a4dbcc22d1aa2a29","price":"0.38","side":"BUY","size":"0"},{"asset_id":"14766054693214075530629349735273995982307625376442606753688071083149620216746","best_ask":"0.59","best_bid":"0.58","hash":"881ad606f9c463a43bd491d7c3ba7e44f8a9875a","price":"0.62","side":"SELL","size":"0"}],"timestamp":"1785130980306"},"payload_hash":"eb779682da875e5ddf109b8caeb2ff581844d1abcd38dcb59311a505d569349a","raw_frame":"{\"market\":\"0x3b40066b5cf3871a2f6237c5628bd8092a206aa998558ac5ec13c4483e31e160\", \"price_changes\":[{\"asset_id\":\"110216635572655435074987471276357323571387854733835379371586402147734167783946\", \"price\":\"0.38\", \"size\":\"0\", \"side\":\"BUY\", \"hash\":\"3b7db559ae72487729dab1f3a4dbcc22d1aa2a29\", \"best_bid\":\"0.41\", \"best_ask\":\"0.42\"}, {\"asset_id\":\"14766054693214075530629349735273995982307625376442606753688071083149620216746\", \"price\":\"0.62\", \"size\":\"0\", \"side\":\"SELL\", \"hash\":\"881ad606f9c463a43bd491d7c3ba7e44f8a9875a\", \"best_bid\":\"0.58\", \"best_ask\":\"0.59\"}], \"timestamp\":\"1785130980306\", \"event_type\":\"price_change\"}","received_at":"2026-07-27T05:43:00.263773Z","schema_version":"clob-market-ws.price_change.v1","sequence":null,"server_hash":null,"server_timestamp":"1785130980306","session_id":"502006c5cfcd437296561ea750c9ec8b","source":"clob_market_ws"},"received_at":"2026-07-27T05:43:00.263773Z","record_id":"7c4ca95bd4967727b3135fef93731ffe09e3084c26591cb31ef5cff52249d9d7","schema_fingerprint":"4aa3821a28b0b7c2400bc59aba4bcc0a76e971dadd19610d3ad38c768e124dc7","schema_version":"edge-lab-recorder.raw.v1","sequence":null,"source":"clob_market_ws"}
{"event_at":"2026-07-27T05:43:00.309000Z","event_fingerprint":"c734a3c545d9afdef881e18a13830b338a8b08ad053ade0231bdca5cc9d49dcc","payload":{"connection_id":"efc69d3132f1467b8e898a382b23ac0d","event_at":"2026-07-27T05:43:00.309000Z","event_type":"price_change","frame_hash":"6e2c6041e736457eb64043bba41ca4703466bb296109daf55aaf9b6330892dae","frame_index":0,"kind":"data","monotonic_ns":232963500745083,"payload":{"event_type":"price_change","market":"0x3b40066b5cf3871a2f6237c5628bd8092a206aa998558ac5ec13c4483e31e160","price_changes":[{"asset_id":"14766054693214075530629349735273995982307625376442606753688071083149620216746","best_ask":"0.59","best_bid":"0.58","hash":"8429fb37ac30ab5a237bb74f4387e92b0bea79d3","price":"0.57","side":"BUY","size":"424"},{"asset_id":"110216635572655435074987471276357323571387854733835379371586402147734167783946","best_ask":"0.42","best_bid":"0.41","hash":"231aab5b7eb965c007857e74aaecb141197e7473","price":"0.43","side":"SELL","size":"424"}],"timestamp":"1785130980309"},"payload_hash":"6d079dc6458131e2180bb137027f399b3692021d25f0129c9d3eb6529afb0c76","raw_frame":"{\"market\":\"0x3b40066b5cf3871a2f6237c5628bd8092a206aa998558ac5ec13c4483e31e160\", \"price_changes\":[{\"asset_id\":\"14766054693214075530629349735273995982307625376442606753688071083149620216746\", \"price\":\"0.57\", \"size\":\"424\", \"side\":\"BUY\", \"hash\":\"8429fb37ac30ab5a237bb74f4387e92b0bea79d3\", \"best_bid\":\"0.58\", \"best_ask\":\"0.59\"}, {\"asset_id\":\"110216635572655435074987471276357323571387854733835379371586402147734167783946\", \"price\":\"0.43\", \"size\":\"424\", \"side\":\"SELL\", \"hash\":\"231aab5b7eb965c007857e74aaecb141197e7473\", \"best_bid\":\"0.41\", \"best_ask\":\"0.42\"}], \"timestamp\":\"1785130980309\", \"event_type\":\"price_change\"}","received_at":"2026-07-27T05:43:00.267956Z","schema_version":"clob-market-ws.price_change.v1","sequence":null,"server_hash":null,"server_timestamp":"1785130980309","session_id":"502006c5cfcd437296561ea750c9ec8b","source":"clob_market_ws"},"received_at":"2026-07-27T05:43:00.267956Z","record_id":"626177a4516d9ce762a150b82a2714ceadcc4abd098dc8671d2c3f7148550cb4","schema_fingerprint":"4aa3821a28b0b7c2400bc59aba4bcc0a76e971dadd19610d3ad38c768e124dc7","schema_version":"edge-lab-recorder.raw.v1","sequence":null,"source":"clob_market_ws"}
{"event_at":"2026-07-27T05:43:00.312000Z","event_fingerprint":"1d3938f754c87ca7ff61642ead95502495123d74f1e6414a89dd402b8a30d275","payload":{"connection_id":"efc69d3132f1467b8e898a382b23ac0d","event_at":"2026-07-27T05:43:00.312000Z","event_type":"price_change","frame_hash":"19696ca11862216ad7aceccfe4346e5d8181a84d967892d18bff9aedcf6b378f","frame_index":0,"kind":"data","monotonic_ns":232963504045250,"payload":{"event_type":"price_change","market":"0x3b40066b5cf3871a2f6237c5628bd8092a206aa998558ac5ec13c4483e31e160","price_changes":[{"asset_id":"14766054693214075530629349735273995982307625376442606753688071083149620216746","best_ask":"0.59","best_bid":"0.58","hash":"a28a616e718ae42766c682c71a0c225b658f0caa","price":"0.02","side":"BUY","size":"552"},{"asset_id":"110216635572655435074987471276357323571387854733835379371586402147734167783946","best_ask":"0.42","best_bid":"0.41","hash":"bcd61a775314ff07cebb0b81187c77d937233a5b","price":"0.98","side":"SELL","size":"552"}],"timestamp":"1785130980312"},"payload_hash":"f8af6a695b9b1eb6870ec125bac8623b59d79a5f8a00753db1e2c944d0ef7f0b","raw_frame":"{\"market\":\"0x3b40066b5cf3871a2f6237c5628bd8092a206aa998558ac5ec13c4483e31e160\", \"price_changes\":[{\"asset_id\":\"14766054693214075530629349735273995982307625376442606753688071083149620216746\", \"price\":\"0.02\", \"size\":\"552\", \"side\":\"BUY\", \"hash\":\"a28a616e718ae42766c682c71a0c225b658f0caa\", \"best_bid\":\"0.58\", \"best_ask\":\"0.59\"}, {\"asset_id\":\"110216635572655435074987471276357323571387854733835379371586402147734167783946\", \"price\":\"0.98\", \"size\":\"552\", \"side\":\"SELL\", \"hash\":\"bcd61a775314ff07cebb0b81187c77d937233a5b\", \"best_bid\":\"0.41\", \"best_ask\":\"0.42\"}], \"timestamp\":\"1785130980312\", \"event_type\":\"price_change\"}","received_at":"2026-07-27T05:43:00.271257Z","schema_version":"clob-market-ws.price_change.v1","sequence":null,"server_hash":null,"server_timestamp":"1785130980312","session_id":"502006c5cfcd437296561ea750c9ec8b","source":"clob_market_ws"},"received_at":"2026-07-27T05:43:00.271257Z","record_id":"c3b59aa0f72abec6acb94432b5cff375d746512effb18f68bb270f76e2d370f4","schema_fingerprint":"4aa3821a28b0b7c2400bc59aba4bcc0a76e971dadd19610d3ad38c768e124dc7","schema_version":"edge-lab-recorder.raw.v1","sequence":null,"source":"clob_market_ws"}
{"event_at":"2026-07-27T05:43:00.314000Z","event_fingerprint":"adc25558db9813e75c2cc8f9c978dc03dbdddf889f38a59aa7d826bfa2a03163","payload":{"connection_id":"efc69d3132f1467b8e898a382b23ac0d","event_at":"2026-07-27T05:43:00.314000Z","event_type":"price_change","frame_hash":"43bc03fffb9bb92920a27b09f53faf9d7ff415833721b4a17ed53cb60e2c23cd","frame_index":0,"kind":"data","monotonic_ns":232963507866833,"payload":{"event_type":"price_change","market":"0x3b40066b5cf3871a2f6237c5628bd8092a206aa998558ac5ec13c4483e31e160","price_changes":[{"asset_id":"110216635572655435074987471276357323571387854733835379371586402147734167783946","best_ask":"0.42","best_bid":"0.41","hash":"c016b88876a891baa21eaa776a8a4d33f5b83ccb","price":"0.33","side":"BUY","size":"39.73"},{"asset_id":"14766054693214075530629349735273995982307625376442606753688071083149620216746","best_ask":"0.59","best_bid":"0.58","hash":"83f6cc28973938a2ba49ab5fec8a48c754d8e2cc","price":"0.67","side":"SELL","size":"39.73"}],"timestamp":"1785130980314"},"payload_hash":"68a0db2f5095e66636ead68f4a8c92a0c0787d778b839788950ae5dbcb7db0b1","raw_frame":"{\"market\":\"0x3b40066b5cf3871a2f6237c5628bd8092a206aa998558ac5ec13c4483e31e160\", \"price_changes\":[{\"asset_id\":\"110216635572655435074987471276357323571387854733835379371586402147734167783946\", \"price\":\"0.33\", \"size\":\"39.73\", \"side\":\"BUY\", \"hash\":\"c016b88876a891baa21eaa776a8a4d33f5b83ccb\", \"best_bid\":\"0.41\", \"best_ask\":\"0.42\"}, {\"asset_id\":\"14766054693214075530629349735273995982307625376442606753688071083149620216746\", \"price\":\"0.67\", \"size\":\"39.73\", \"side\":\"SELL\", \"hash\":\"83f6cc28973938a2ba49ab5fec8a48c754d8e2cc\", \"best_bid\":\"0.58\", \"best_ask\":\"0.59\"}], \"timestamp\":\"1785130980314\", \"event_type\":\"price_change\"}","received_at":"2026-07-27T05:43:00.275071Z","schema_version":"clob-market-ws.price_change.v1","sequence":null,"server_hash":null,"server_timestamp":"1785130980314","session_id":"502006c5cfcd437296561ea750c9ec8b","source":"clob_market_ws"},"received_at":"2026-07-27T05:43:00.275071Z","record_id":"00215942b9be2382625d0d53365f39dae055f8b20d409187498e8fa79a610c2e","schema_fingerprint":"4aa3821a28b0b7c2400bc59aba4bcc0a76e971dadd19610d3ad38c768e124dc7","schema_version":"edge-lab-recorder.raw.v1","sequence":null,"source":"clob_market_ws"}
{"event_at":"2026-07-27T05:43:00.316000Z","event_fingerprint":"5bdd2a9b4ef762604273db2b53df53bb15a86ff40961ea39335f5029cfaf9517","payload":{"connection_id":"efc69d3132f1467b8e898a382b23ac0d","event_at":"2026-07-27T05:43:00.316000Z","event_type":"price_change","frame_hash":"8bb9ac45f0c23b01fcc0f5a10f66542b72a01ffdbd247ec566b2f2a17e346f11","frame_index":0,"kind":"data","monotonic_ns":232963510877916,"payload":{"event_type":"price_change","market":"0x3b40066b5cf3871a2f6237c5628bd8092a206aa998558ac5ec13c4483e31e160","price_changes":[{"asset_id":"110216635572655435074987471276357323571387854733835379371586402147734167783946","best_ask":"0.42","best_bid":"0.41","hash":"300374dae67d91bb182be85a222b279dd8f8abcc","price":"0.43","side":"SELL","size":"399"},{"asset_id":"14766054693214075530629349735273995982307625376442606753688071083149620216746","best_ask":"0.59","best_bid":"0.58","hash":"2b1b822d199382a112fceafb99161078296dbfac","price":"0.57","side":"BUY","size":"399"}],"timestamp":"1785130980316"},"payload_hash":"79f02e32fbb3fd13bb4fee49bcd4412956e8ec17b5d9287af03b839751f6f5e9","raw_frame":"{\"market\":\"0x3b40066b5cf3871a2f6237c5628bd8092a206aa998558ac5ec13c4483e31e160\", \"price_changes\":[{\"asset_id\":\"110216635572655435074987471276357323571387854733835379371586402147734167783946\", \"price\":\"0.43\", \"size\":\"399\", \"side\":\"SELL\", \"hash\":\"300374dae67d91bb182be85a222b279dd8f8abcc\", \"best_bid\":\"0.41\", \"best_ask\":\"0.42\"}, {\"asset_id\":\"14766054693214075530629349735273995982307625376442606753688071083149620216746\", \"price\":\"0.57\", \"size\":\"399\", \"side\":\"BUY\", \"hash\":\"2b1b822d199382a112fceafb99161078296dbfac\", \"best_bid\":\"0.58\", \"best_ask\":\"0.59\"}], \"timestamp\":\"1785130980316\", \"event_type\":\"price_change\"}","received_at":"2026-07-27T05:43:00.278090Z","schema_version":"clob-market-ws.price_change.v1","sequence":null,"server_hash":null,"server_timestamp":"1785130980316","session_id":"502006c5cfcd437296561ea750c9ec8b","source":"clob_market_ws"},"received_at":"2026-07-27T05:43:00.278090Z","record_id":"d1d6ae5c61a83fb2b4a2b326c7eafdf0767d6b8f705115dcf21b65d25812855f","schema_fingerprint":"4aa3821a28b0b7c2400bc59aba4bcc0a76e971dadd19610d3ad38c768e124dc7","schema_version":"edge-lab-recorder.raw.v1","sequence":null,"source":"clob_market_ws"}
{"event_at":"2026-07-27T05:43:00.451000Z","event_fingerprint":"1ea88f5bb2258a99016d2d8f3db05f6f5c30b3c299bbdf8b0d32a69ca938811d","payload":{"connection_id":"efc69d3132f1467b8e898a382b23ac0d","event_at":"2026-07-27T05:43:00.451000Z","event_type":"price_change","frame_hash":"13c4e1ee2ca66deed670ea6edc5923817b3c5f25c6a6b3ab479277b8485d3d53","frame_index":0,"kind":"data","monotonic_ns":232963648282125,"payload":{"event_type":"price_change","market":"0x3b40066b5cf3871a2f6237c5628bd8092a206aa998558ac5ec13c4483e31e160","price_changes":[{"asset_id":"14766054693214075530629349735273995982307625376442606753688071083149620216746","best_ask":"0.59","best_bid":"0.58","hash":"85a6bad514a11d2b6f867d44b013b2d3d2c250f9","price":"0.01","side":"BUY","size":"5335.02"},{"asset_id":"110216635572655435074987471276357323571387854733835379371586402147734167783946","best_ask":"0.42","best_bid":"0.41","hash":"e18f222ee18128e8579b843b4badecd0d06239d2","price":"0.99","side":"SELL","size":"5335.02"}],"timestamp":"1785130980451"},"payload_hash":"ea226ee12d104cc276a315197d92364c7d820323699d5356b43be28470ea4925","raw_frame":"{\"market\":\"0x3b40066b5cf3871a2f6237c5628bd8092a206aa998558ac5ec13c4483e31e160\", \"price_changes\":[{\"asset_id\":\"14766054693214075530629349735273995982307625376442606753688071083149620216746\", \"price\":\"0.01\", \"size\":\"5335.02\", \"side\":\"BUY\", \"hash\":\"85a6bad514a11d2b6f867d44b013b2d3d2c250f9\", \"best_bid\":\"0.58\", \"best_ask\":\"0.59\"}, {\"asset_id\":\"110216635572655435074987471276357323571387854733835379371586402147734167783946\", \"price\":\"0.99\", \"size\":\"5335.02\", \"side\":\"SELL\", \"hash\":\"e18f222ee18128e8579b843b4badecd0d06239d2\", \"best_bid\":\"0.41\", \"best_ask\":\"0.42\"}], \"timestamp\":\"1785130980451\", \"event_type\":\"price_change\"}","received_at":"2026-07-27T05:43:00.415492Z","schema_version":"clob-market-ws.price_change.v1","sequence":null,"server_hash":null,"server_timestamp":"1785130980451","session_id":"502006c5cfcd437296561ea750c9ec8b","source":"clob_market_ws"},"received_at":"2026-07-27T05:43:00.415492Z","record_id":"157c1f34375b427352dd81b036957521caded73c7895fd714578c9339f64376d","schema_fingerprint":"4aa3821a28b0b7c2400bc59aba4bcc0a76e971dadd19610d3ad38c768e124dc7","schema_version":"edge-lab-recorder.raw.v1","sequence":null,"source":"clob_market_ws"}
{"event_at":"2026-07-27T05:43:00.459000Z","event_fingerprint":"2631ab8fa7af466badd898286487f3cdee00d7dbbc233d6ad2955be12cc1aab1","payload":{"connection_id":"efc69d3132f1467b8e898a382b23ac0d","event_at":"2026-07-27T05:43:00.459000Z","event_type":"price_change","frame_hash":"be0361ee3274b4821fa8dc5e2479701298bde3fc928155feadcea8cbed752d61","frame_index":0,"kind":"data","monotonic_ns":232963650264458,"payload":{"event_type":"price_change","market":"0x3b40066b5cf3871a2f6237c5628bd8092a206aa998558ac5ec13c4483e31e160","price_changes":[{"asset_id":"14766054693214075530629349735273995982307625376442606753688071083149620216746","best_ask":"0.59","best_bid":"0.58","hash":"c7ba768eb1f1258534c0b24c268db81ad9290f89","price":"0.03","side":"BUY","size":"537"},{"asset_id":"110216635572655435074987471276357323571387854733835379371586402147734167783946","best_ask":"0.42","best_bid":"0.41","hash":"c0c50a4b56f1cb67115a605b74ba6e879863b1fc","price":"0.97","side":"SELL","size":"537"}],"timestamp":"1785130980459"},"payload_hash":"0873051fbef5965a7186d9173271b7936bbdf6abd000def9be12becf2070e67e","raw_frame":"{\"market\":\"0x3b40066b5cf3871a2f6237c5628bd8092a206aa998558ac5ec13c4483e31e160\", \"price_changes\":[{\"asset_id\":\"14766054693214075530629349735273995982307625376442606753688071083149620216746\", \"price\":\"0.03\", \"size\":\"537\", \"side\":\"BUY\", \"hash\":\"c7ba768eb1f1258534c0b24c268db81ad9290f89\", \"best_bid\":\"0.58\", \"best_ask\":\"0.59\"}, {\"asset_id\":\"110216635572655435074987471276357323571387854733835379371586402147734167783946\", \"price\":\"0.97\", \"size\":\"537\", \"side\":\"SELL\", \"hash\":\"c0c50a4b56f1cb67115a605b74ba6e879863b1fc\", \"best_bid\":\"0.41\", \"best_ask\":\"0.42\"}], \"timestamp\":\"1785130980459\", \"event_type\":\"price_change\"}","received_at":"2026-07-27T05:43:00.417476Z","schema_version":"clob-market-ws.price_change.v1","sequence":null,"server_hash":null,"server_timestamp":"1785130980459","session_id":"502006c5cfcd437296561ea750c9ec8b","source":"clob_market_ws"},"received_at":"2026-07-27T05:43:00.417476Z","record_id":"25ee1a80cdfc8b0194bafe15b96f5551467c357ac5d5ad97aa1317871d66e9e3","schema_fingerprint":"4aa3821a28b0b7c2400bc59aba4bcc0a76e971dadd19610d3ad38c768e124dc7","schema_version":"edge-lab-recorder.raw.v1","sequence":null,"source":"clob_market_ws"}
{"event_at":"2026-07-27T05:43:00.470000Z","event_fingerprint":"31da7052d9452719996adcc1a7ca4742269017fc1535d46f3604066188450910","payload":{"connection_id":"efc69d3132f1467b8e898a382b23ac0d","event_at":"2026-07-27T05:43:00.470000Z","event_type":"price_change","frame_hash":"fc1ebe347ae353195b7ccdde539186acd679aef3c97cde8970342ff9454973a1","frame_index":0,"kind":"data","monotonic_ns":232963660291416,"payload":{"event_type":"price_change","market":"0x3b40066b5cf3871a2f6237c5628bd8092a206aa998558ac5ec13c4483e31e160","price_changes":[{"asset_id":"110216635572655435074987471276357323571387854733835379371586402147734167783946","best_ask":"0.42","best_bid":"0.41","hash":"134eadc2ee0b08af5fcf9cbdfa3b6a5bfd1a4479","price":"0.33","side":"BUY","size":"29.73"},{"asset_id":"14766054693214075530629349735273995982307625376442606753688071083149620216746","best_ask":"0.59","best_bid":"0.58","hash":"760a6a5eb430a7b0f130a3ab0872049e18467ff9","price":"0.67","side":"SELL","size":"29.73"}],"timestamp":"1785130980470"},"payload_hash":"b3dd67fc6130efb9c29e011a016b0845eb2a47cd6a0b7a53ebae3092dbdbe32d","raw_frame":"{\"market\":\"0x3b40066b5cf3871a2f6237c5628bd8092a206aa998558ac5ec13c4483e31e160\", \"price_changes\":[{\"asset_id\":\"110216635572655435074987471276357323571387854733835379371586402147734167783946\", \"price\":\"0.33\", \"size\":\"29.73\", \"side\":\"BUY\", \"hash\":\"134eadc2ee0b08af5fcf9cbdfa3b6a5bfd1a4479\", \"best_bid\":\"0.41\", \"best_ask\":\"0.42\"}, {\"asset_id\":\"14766054693214075530629349735273995982307625376442606753688071083149620216746\", \"price\":\"0.67\", \"size\":\"29.73\", \"side\":\"SELL\", \"hash\":\"760a6a5eb430a7b0f130a3ab0872049e18467ff9\", \"best_bid\":\"0.58\", \"best_ask\":\"0.59\"}], \"timestamp\":\"1785130980470\", \"event_type\":\"price_change\"}","received_at":"2026-07-27T05:43:00.427500Z","schema_version":"clob-market-ws.price_change.v1","sequence":null,"server_hash":null,"server_timestamp":"1785130980470","session_id":"502006c5cfcd437296561ea750c9ec8b","source":"clob_market_ws"},"received_at":"2026-07-27T05:43:00.427500Z","record_id":"8f41ae43e005475fa0ed6f31b3c0b5a1a3068d1810cf63bd54929c97e2daee45","schema_fingerprint":"4aa3821a28b0b7c2400bc59aba4bcc0a76e971dadd19610d3ad38c768e124dc7","schema_version":"edge-lab-recorder.raw.v1","sequence":null,"source":"clob_market_ws"}
{"event_at":"2026-07-27T05:43:00.472000Z","event_fingerprint":"05aca8d469954b091cf5e07e5f97ec3335c4e81cb6701fc7a12b88cf01bfd84f","payload":{"connection_id":"efc69d3132f1467b8e898a382b23ac0d","event_at":"2026-07-27T05:43:00.472000Z","event_type":"price_change","frame_hash":"5a793e286174c93fbdcdee150915d090b35b476a42f15018ef46bb7db56ae8ca","frame_index":0,"kind":"data","monotonic_ns":232963663569333,"payload":{"event_type":"price_change","market":"0x3b40066b5cf3871a2f6237c5628bd8092a206aa998558ac5ec13c4483e31e160","price_changes":[{"asset_id":"14766054693214075530629349735273995982307625376442606753688071083149620216746","best_ask":"0.59","best_bid":"0.58","hash":"14027a6470ff97672fadca23bba212256671d3c0","price":"0.01","side":"BUY","size":"5330.02"},{"asset_id":"110216635572655435074987471276357323571387854733835379371586402147734167783946","best_ask":"0.42","best_bid":"0.41","hash":"9efb7bcbf75d00ec2bcdb9dff988a4e2e5e7999b","price":"0.99","side":"SELL","size":"5330.02"}],"timestamp":"1785130980472"},"payload_hash":"fa8acf7028bce2e6c4eece2d384c82ee0d4ca7763d310c28b91e37b5e1f074a1","raw_frame":"{\"market\":\"0x3b40066b5cf3871a2f6237c5628bd8092a206aa998558ac5ec13c4483e31e160\", \"price_changes\":[{\"asset_id\":\"14766054693214075530629349735273995982307625376442606753688071083149620216746\", \"price\":\"0.01\", \"size\":\"5330.02\", \"side\":\"BUY\", \"hash\":\"14027a6470ff97672fadca23bba212256671d3c0\", \"best_bid\":\"0.58\", \"best_ask\":\"0.59\"}, {\"asset_id\":\"110216635572655435074987471276357323571387854733835379371586402147734167783946\", \"price\":\"0.99\", \"size\":\"5330.02\", \"side\":\"SELL\", \"hash\":\"9efb7bcbf75d00ec2bcdb9dff988a4e2e5e7999b\", \"best_bid\":\"0.41\", \"best_ask\":\"0.42\"}], \"timestamp\":\"1785130980472\", \"event_type\":\"price_change\"}","received_at":"2026-07-27T05:43:00.430782Z","schema_version":"clob-market-ws.price_change.v1","sequence":null,"server_hash":null,"server_timestamp":"1785130980472","session_id":"502006c5cfcd437296561ea750c9ec8b","source":"clob_market_ws"},"received_at":"2026-07-27T05:43:00.430782Z","record_id":"9177ec1ddc6bafc11bbf4070ddaa316c0a2ddbf162bc61a8b7317a6938331c89","schema_fingerprint":"4aa3821a28b0b7c2400bc59aba4bcc0a76e971dadd19610d3ad38c768e124dc7","schema_version":"edge-lab-recorder.raw.v1","sequence":null,"source":"clob_market_ws"}
{"event_at":"2026-07-27T05:43:00.491000Z","event_fingerprint":"2b492303c8802744ca6cccf27d9dc638a6dd4be731fbcb21ee1adf3424725593","payload":{"connection_id":"efc69d3132f1467b8e898a382b23ac0d","event_at":"2026-07-27T05:43:00.491000Z","event_type":"price_change","frame_hash":"2fdcf11ce6d82cb15fa4200490f444cf2281d71e24dd01ccf3907b8a87817b4e","frame_index":0,"kind":"data","monotonic_ns":232963684227625,"payload":{"event_type":"price_change","market":"0x3b40066b5cf3871a2f6237c5628bd8092a206aa998558ac5ec13c4483e31e160","price_changes":[{"asset_id":"110216635572655435074987471276357323571387854733835379371586402147734167783946","best_ask":"0.42","best_bid":"0.41","hash":"9e4f6fafd4c9ee809e707b68eb403b79f64b2613","price":"0.41","side":"BUY","size":"9"},{"asset_id":"14766054693214075530629349735273995982307625376442606753688071083149620216746","best_ask":"0.59","best_bid":"0.58","hash":"8fe529cc653fb1051191a97019ccd81235348800","price":"0.59","side":"SELL","size":"9"}],"timestamp":"1785130980491"},"payload_hash":"7f22c3e7b5e97e4a56f9ca849cd2d1ff39ca4a62c695c9e34315802c06d6ca77","raw_frame":"{\"market\":\"0x3b40066b5cf3871a2f6237c5628bd8092a206aa998558ac5ec13c4483e31e160\", \"price_changes\":[{\"asset_id\":\"110216635572655435074987471276357323571387854733835379371586402147734167783946\", \"price\":\"0.41\", \"size\":\"9\", \"side\":\"BUY\", \"hash\":\"9e4f6fafd4c9ee809e707b68eb403b79f64b2613\", \"best_bid\":\"0.41\", \"best_ask\":\"0.42\"}, {\"asset_id\":\"14766054693214075530629349735273995982307625376442606753688071083149620216746\", \"price\":\"0.59\", \"size\":\"9\", \"side\":\"SELL\", \"hash\":\"8fe529cc653fb1051191a97019ccd81235348800\", \"best_bid\":\"0.58\", \"best_ask\":\"0.59\"}], \"timestamp\":\"1785130980491\", \"event_type\":\"price_change\"}","received_at":"2026-07-27T05:43:00.451439Z","schema_version":"clob-market-ws.price_change.v1","sequence":null,"server_hash":null,"server_timestamp":"1785130980491","session_id":"502006c5cfcd437296561ea750c9ec8b","source":"clob_market_ws"},"received_at":"2026-07-27T05:43:00.451439Z","record_id":"3e1fb2ee858560b9a977dfcb91df3d915bec93a7b095fba99b0f92c3b8ec2c85","schema_fingerprint":"4aa3821a28b0b7c2400bc59aba4bcc0a76e971dadd19610d3ad38c768e124dc7","schema_version":"edge-lab-recorder.raw.v1","sequence":null,"source":"clob_market_ws"}
{"event_at":"2026-07-27T05:43:00.496000Z","event_fingerprint":"17a8b877dc9611f214c7434f4353688874ae25b249e23180565462a0e95aa09e","payload":{"connection_id":"efc69d3132f1467b8e898a382b23ac0d","event_at":"2026-07-27T05:43:00.496000Z","event_type":"price_change","frame_hash":"88b7f16707132de527a0357583d58f5b8b6eeda9c4cc879dcfa969731234e45d","frame_index":0,"kind":"data","monotonic_ns":232963688014541,"payload":{"event_type":"price_change","market":"0x3b40066b5cf3871a2f6237c5628bd8092a206aa998558ac5ec13c4483e31e160","price_changes":[{"asset_id":"110216635572655435074987471276357323571387854733835379371586402147734167783946","best_ask":"0.42","best_bid":"0.41","hash":"e62e218ba6c0e9b908c672f22cdebb1a1091fa85","price":"0.32","side":"BUY","size":"57"},{"asset_id":"14766054693214075530629349735273995982307625376442606753688071083149620216746","best_ask":"0.59","best_bid":"0.58","hash":"db88ed6021b029698a5b9eed8bf9c08f3294ebd5","price":"0.68","side":"SELL","size":"57"}],"timestamp":"1785130980496"},"payload_hash":"58afe9eeaa335708166165ff2c7a523807d9058574bb313e4e7788d2fbf8a19a","raw_frame":"{\"market\":\"0x3b40066b5cf3871a2f6237c5628bd8092a206aa998558ac5ec13c4483e31e160\", \"price_changes\":[{\"asset_id\":\"110216635572655435074987471276357323571387854733835379371586402147734167783946\", \"price\":\"0.32\", \"size\":\"57\", \"side\":\"BUY\", \"hash\":\"e62e218ba6c0e9b908c672f22cdebb1a1091fa85\", \"best_bid\":\"0.41\", \"best_ask\":\"0.42\"}, {\"asset_id\":\"14766054693214075530629349735273995982307625376442606753688071083149620216746\", \"price\":\"0.68\", \"size\":\"57\", \"side\":\"SELL\", \"hash\":\"db88ed6021b029698a5b9eed8bf9c08f3294ebd5\", \"best_bid\":\"0.58\", \"best_ask\":\"0.59\"}], \"timestamp\":\"1785130980496\", \"event_type\":\"price_change\"}","received_at":"2026-07-27T05:43:00.455224Z","schema_version":"clob-market-ws.price_change.v1","sequence":null,"server_hash":null,"server_timestamp":"1785130980496","session_id":"502006c5cfcd437296561ea750c9ec8b","source":"clob_market_ws"},"received_at":"2026-07-27T05:43:00.455224Z","record_id":"5129361cd3c909cff92d89530d2897d69b1b4b623469b135992b3174def65a1e","schema_fingerprint":"4aa3821a28b0b7c2400bc59aba4bcc0a76e971dadd19610d3ad38c768e124dc7","schema_version":"edge-lab-recorder.raw.v1","sequence":null,"source":"clob_market_ws"}
{"event_at":"2026-07-27T05:43:00.513000Z","event_fingerprint":"4935bde91367553100af164d8c1083f5226cdfde439abc3128514fe249369b05","payload":{"connection_id":"efc69d3132f1467b8e898a382b23ac0d","event_at":"2026-07-27T05:43:00.513000Z","event_type":"price_change","frame_hash":"2021c40eb97c8e33839fb960d7c3e43bf9e55414bc7e784dcf4efea3e9bc0c54","frame_index":0,"kind":"data","monotonic_ns":232963705347500,"payload":{"event_type":"price_change","market":"0x3b40066b5cf3871a2f6237c5628bd8092a206aa998558ac5ec13c4483e31e160","price_changes":[{"asset_id":"110216635572655435074987471276357323571387854733835379371586402147734167783946","best_ask":"0.42","best_bid":"0.41","hash":"789a55a18045188263c6a6a3d0dcb899348f0caa","price":"0.38","side":"BUY","size":"25"},{"asset_id":"14766054693214075530629349735273995982307625376442606753688071083149620216746","best_ask":"0.59","best_bid":"0.58","hash":"948e5ef1aa79c122f1fe5371bb1a1dd33a2ea06d","price":"0.62","side":"SELL","size":"25"}],"timestamp":"1785130980513"},"payload_hash":"a8dea8552eb6b953225c9c91d6cb6a818b8cd467a5548753255b5c81facea6e8","raw_frame":"{\"market\":\"0x3b40066b5cf3871a2f6237c5628bd8092a206aa998558ac5ec13c4483e31e160\", \"price_changes\":[{\"asset_id\":\"110216635572655435074987471276357323571387854733835379371586402147734167783946\", \"price\":\"0.38\", \"size\":\"25\", \"side\":\"BUY\", \"hash\":\"789a55a18045188263c6a6a3d0dcb899348f0caa\", \"best_bid\":\"0.41\", \"best_ask\":\"0.42\"}, {\"asset_id\":\"14766054693214075530629349735273995982307625376442606753688071083149620216746\", \"price\":\"0.62\", \"size\":\"25\", \"side\":\"SELL\", \"hash\":\"948e5ef1aa79c122f1fe5371bb1a1dd33a2ea06d\", \"best_bid\":\"0.58\", \"best_ask\":\"0.59\"}], \"timestamp\":\"1785130980513\", \"event_type\":\"price_change\"}","received_at":"2026-07-27T05:43:00.472559Z","schema_version":"clob-market-ws.price_change.v1","sequence":null,"server_hash":null,"server_timestamp":"1785130980513","session_id":"502006c5cfcd437296561ea750c9ec8b","source":"clob_market_ws"},"received_at":"2026-07-27T05:43:00.472559Z","record_id":"12cb5ccc780dba140ec10f06c1d853d5110aceb516f41e17ccc0ea434a2a0484","schema_fingerprint":"4aa3821a28b0b7c2400bc59aba4bcc0a76e971dadd19610d3ad38c768e124dc7","schema_version":"edge-lab-recorder.raw.v1","sequence":null,"source":"clob_market_ws"}
{"event_at":"2026-07-27T05:43:00.513000Z","event_fingerprint":"93a9cbee364cd4d59ede7076739128f172d5cd25b1e64b44f85d4121c0f82a77","payload":{"connection_id":"efc69d3132f1467b8e898a382b23ac0d","event_at":"2026-07-27T05:43:00.513000Z","event_type":"price_change","frame_hash":"952180ee730af9f8db015e5817b0676913924af83e59e1d2996a5b468c64f751","frame_index":0,"kind":"data","monotonic_ns":232963708411333,"payload":{"event_type":"price_change","market":"0x3b40066b5cf3871a2f6237c5628bd8092a206aa998558ac5ec13c4483e31e160","price_changes":[{"asset_id":"110216635572655435074987471276357323571387854733835379371586402147734167783946","best_ask":"0.42","best_bid":"0.41","hash":"2fe1afc7ee4f127d8d0b613a543edf518e80d89f","price":"0.43","side":"SELL","size":"424"},{"asset_id":"14766054693214075530629349735273995982307625376442606753688071083149620216746","best_ask":"0.59","best_bid":"0.58","hash":"8886ad5dc451580ad352ca908b48f90f8cded92d","price":"0.57","side":"BUY","size":"424"}],"timestamp":"1785130980513"},"payload_hash":"1ddc0b592955b0b4a39fa3bc6bdb7f429399b0283e3c0502860319754208f6ca","raw_frame":"{\"market\":\"0x3b40066b5cf3871a2f6237c5628bd8092a206aa998558ac5ec13c4483e31e160\", \"price_changes\":[{\"asset_id\":\"110216635572655435074987471276357323571387854733835379371586402147734167783946\", \"price\":\"0.43\", \"size\":\"424\", \"side\":\"SELL\", \"hash\":\"2fe1afc7ee4f127d8d0b613a543edf518e80d89f\", \"best_bid\":\"0.41\", \"best_ask\":\"0.42\"}, {\"asset_id\":\"14766054693214075530629349735273995982307625376442606753688071083149620216746\", \"price\":\"0.57\", \"size\":\"424\", \"side\":\"BUY\", \"hash\":\"8886ad5dc451580ad352ca908b48f90f8cded92d\", \"best_bid\":\"0.58\", \"best_ask\":\"0.59\"}], \"timestamp\":\"1785130980513\", \"event_type\":\"price_change\"}","received_at":"2026-07-27T05:43:00.475624Z","schema_version":"clob-market-ws.price_change.v1","sequence":null,"server_hash":null,"server_timestamp":"1785130980513","session_id":"502006c5cfcd437296561ea750c9ec8b","source":"clob_market_ws"},"received_at":"2026-07-27T05:43:00.475624Z","record_id":"e5a40de6d3781ccba01ec7b2f1d8f7b45f4b04dae913be0529d3d5bcb7a6e6f0","schema_fingerprint":"4aa3821a28b0b7c2400bc59aba4bcc0a76e971dadd19610d3ad38c768e124dc7","schema_version":"edge-lab-recorder.raw.v1","sequence":null,"source":"clob_market_ws"}
{"event_at":"2026-07-27T05:43:00.514000Z","event_fingerprint":"78f11319ec6be9722f080a206a589c0fef5ae8fa813b442cac45882e52df84e2","payload":{"connection_id":"efc69d3132f1467b8e898a382b23ac0d","event_at":"2026-07-27T05:43:00.514000Z","event_type":"price_change","frame_hash":"3e4e7191f973df8b59dc6167050edc0c4702e92d67f4af8643ffd266a5469d7e","frame_index":0,"kind":"data","monotonic_ns":232963710102625,"payload":{"event_type":"price_change","market":"0x3b40066b5cf3871a2f6237c5628bd8092a206aa998558ac5ec13c4483e31e160","price_changes":[{"asset_id":"14766054693214075530629349735273995982307625376442606753688071083149620216746","best_ask":"0.59","best_bid":"0.58","hash":"e0c24ebeaf87ca43834134f59c2862031635b134","price":"0.57","side":"BUY","size":"449"},{"asset_id":"110216635572655435074987471276357323571387854733835379371586402147734167783946","best_ask":"0.42","best_bid":"0.41","hash":"294b4a1623715fce8b3dbc20860168ecce23fe32","price":"0.43","side":"SELL","size":"449"}],"timestamp":"1785130980514"},"payload_hash":"961fe60836341df07e79de68423d0309818238810f8c3868bff09e7636d8936f","raw_frame":"{\"market\":\"0x3b40066b5cf3871a2f6237c5628bd8092a206aa998558ac5ec13c4483e31e160\", \"price_changes\":[{\"asset_id\":\"14766054693214075530629349735273995982307625376442606753688071083149620216746\", \"price\":\"0.57\", \"size\":\"449\", \"side\":\"BUY\", \"hash\":\"e0c24ebeaf87ca43834134f59c2862031635b134\", \"best_bid\":\"0.58\", \"best_ask\":\"0.59\"}, {\"asset_id\":\"110216635572655435074987471276357323571387854733835379371586402147734167783946\", \"price\":\"0.43\", \"size\":\"449\", \"side\":\"SELL\", \"hash\":\"294b4a1623715fce8b3dbc20860168ecce23fe32\", \"best_bid\":\"0.41\", \"best_ask\":\"0.42\"}], \"timestamp\":\"1785130980514\", \"event_type\":\"price_change\"}","received_at":"2026-07-27T05:43:00.477316Z","schema_version":"clob-market-ws.price_change.v1","sequence":null,"server_hash":null,"server_timestamp":"1785130980514","session_id":"502006c5cfcd437296561ea750c9ec8b","source":"clob_market_ws"},"received_at":"2026-07-27T05:43:00.477316Z","record_id":"2a859d6312a044a09d1d76ca4dd18798f3eb55736730cb46b6cc1399bae280a2","schema_fingerprint":"4aa3821a28b0b7c2400bc59aba4bcc0a76e971dadd19610d3ad38c768e124dc7","schema_version":"edge-lab-recorder.raw.v1","sequence":null,"source":"clob_market_ws"}
{"event_at":"2026-07-27T05:43:00.523000Z","event_fingerprint":"5cedfaf01ed01cb608ff72d4113e71baeba5cd18badd0fe1d6f38a9f915e1bd5","payload":{"connection_id":"efc69d3132f1467b8e898a382b23ac0d","event_at":"2026-07-27T05:43:00.523000Z","event_type":"price_change","frame_hash":"ecb255e1d1d56f294f953319536976e3d6ca5ba7de02852607cae8a34aabc9e6","frame_index":0,"kind":"data","monotonic_ns":232963714685958,"payload":{"event_type":"price_change","market":"0x3b40066b5cf3871a2f6237c5628bd8092a206aa998558ac5ec13c4483e31e160","price_changes":[{"asset_id":"14766054693214075530629349735273995982307625376442606753688071083149620216746","best_ask":"0.59","best_bid":"0.58","hash":"32b875be2c68771fffe04df50f3a3ac6d14e830f","price":"0.03","side":"BUY","size":"532"},{"asset_id":"110216635572655435074987471276357323571387854733835379371586402147734167783946","best_ask":"0.42","best_bid":"0.41","hash":"a787a62b7de6f243d39a144cdc10787c11525616","price":"0.97","side":"SELL","size":"532"}],"timestamp":"1785130980523"},"payload_hash":"1885781cee2e86be4a75630f836d585eb724f62aaf09b2bbe7d36c18600ece7b","raw_frame":"{\"market\":\"0x3b40066b5cf3871a2f6237c5628bd8092a206aa998558ac5ec13c4483e31e160\", \"price_changes\":[{\"asset_id\":\"14766054693214075530629349735273995982307625376442606753688071083149620216746\", \"price\":\"0.03\", \"size\":\"532\", \"side\":\"BUY\", \"hash\":\"32b875be2c68771fffe04df50f3a3ac6d14e830f\", \"best_bid\":\"0.58\", \"best_ask\":\"0.59\"}, {\"asset_id\":\"110216635572655435074987471276357323571387854733835379371586402147734167783946\", \"price\":\"0.97\", \"size\":\"532\", \"side\":\"SELL\", \"hash\":\"a787a62b7de6f243d39a144cdc10787c11525616\", \"best_bid\":\"0.41\", \"best_ask\":\"0.42\"}], \"timestamp\":\"1785130980523\", \"event_type\":\"price_change\"}","received_at":"2026-07-27T05:43:00.481898Z","schema_version":"clob-market-ws.price_change.v1","sequence":null,"server_hash":null,"server_timestamp":"1785130980523","session_id":"502006c5cfcd437296561ea750c9ec8b","source":"clob_market_ws"},"received_at":"2026-07-27T05:43:00.481898Z","record_id":"7c8b4088092362c31afc9d20644c356fbfc01b5a5ca378ba7175953bb8095320","schema_fingerprint":"4aa3821a28b0b7c2400bc59aba4bcc0a76e971dadd19610d3ad38c768e124dc7","schema_version":"edge-lab-recorder.raw.v1","sequence":null,"source":"clob_market_ws"}
{"event_at":"2026-07-27T05:43:00.576000Z","event_fingerprint":"9a3139dc1124ecfe7f6cbab52d2cf030adac993760163de468affdd855d33321","payload":{"connection_id":"efc69d3132f1467b8e898a382b23ac0d","event_at":"2026-07-27T05:43:00.576000Z","event_type":"price_change","frame_hash":"501e6fe67ae525c3558f286b59589540963388e569ca90a3d9319c9a3f5bb3c9","frame_index":0,"kind":"data","monotonic_ns":232963769359000,"payload":{"event_type":"price_change","market":"0x3b40066b5cf3871a2f6237c5628bd8092a206aa998558ac5ec13c4483e31e160","price_changes":[{"asset_id":"14766054693214075530629349735273995982307625376442606753688071083149620216746","best_ask":"0.59","best_bid":"0.58","hash":"0df8631d802dbc2b91e22b9b457c2328578aaaea","price":"0.67","side":"SELL","size":"22.73"},{"asset_id":"110216635572655435074987471276357323571387854733835379371586402147734167783946","best_ask":"0.42","best_bid":"0.41","hash":"9639da14e9aef63cf7e2b3a6ad5947977608f3bf","price":"0.33","side":"BUY","size":"22.73"}],"timestamp":"1785130980576"},"payload_hash":"0572f29d950f5ff772c3c1a6593a3284525220f4b57a3f4ec796b9a4e2fb8e99","raw_frame":"{\"market\":\"0x3b40066b5cf3871a2f6237c5628bd8092a206aa998558ac5ec13c4483e31e160\", \"price_changes\":[{\"asset_id\":\"14766054693214075530629349735273995982307625376442606753688071083149620216746\", \"price\":\"0.67\", \"size\":\"22.73\", \"side\":\"SELL\", \"hash\":\"0df8631d802dbc2b91e22b9b457c2328578aaaea\", \"best_bid\":\"0.58\", \"best_ask\":\"0.59\"}, {\"asset_id\":\"110216635572655435074987471276357323571387854733835379371586402147734167783946\", \"price\":\"0.33\", \"size\":\"22.73\", \"side\":\"BUY\", \"hash\":\"9639da14e9aef63cf7e2b3a6ad5947977608f3bf\", \"best_bid\":\"0.41\", \"best_ask\":\"0.42\"}], \"timestamp\":\"1785130980576\", \"event_type\":\"price_change\"}","received_at":"2026-07-27T05:43:00.536562Z","schema_version":"clob-market-ws.price_change.v1","sequence":null,"server_hash":null,"server_timestamp":"1785130980576","session_id":"502006c5cfcd437296561ea750c9ec8b","source":"clob_market_ws"},"received_at":"2026-07-27T05:43:00.536562Z","record_id":"d24fdad5cea24df176de6ce199c16efa500b664bd33cbbd3892e90a190c1a211","schema_fingerprint":"4aa3821a28b0b7c2400bc59aba4bcc0a76e971dadd19610d3ad38c768e124dc7","schema_version":"edge-lab-recorder.raw.v1","sequence":null,"source":"clob_market_ws"}
{"event_at":"2026-07-27T05:43:00.579000Z","event_fingerprint":"f3c61d3b456ef334b5e4a02a7ddf316678cd5ce8fc268372e019f6c4502b341d","payload":{"connection_id":"efc69d3132f1467b8e898a382b23ac0d","event_at":"2026-07-27T05:43:00.579000Z","event_type":"price_change","frame_hash":"99575ee155c76fc1aacda34770442c2af8e5b8f950421c632fef9067b0e16197","frame_index":0,"kind":"data","monotonic_ns":232963772259458,"payload":{"event_type":"price_change","market":"0x3b40066b5cf3871a2f6237c5628bd8092a206aa998558ac5ec13c4483e31e160","price_changes":[{"asset_id":"110216635572655435074987471276357323571387854733835379371586402147734167783946","best_ask":"0.42","best_bid":"0.41","hash":"a97d15803791977bd25feb0c370f50b753807d79","price":"0.33","side":"BUY","size":"12.78"},{"asset_id":"14766054693214075530629349735273995982307625376442606753688071083149620216746","best_ask":"0.59","best_bid":"0.58","hash":"ec244ee6d7ed1dac1d91b470c810f5426b70e237","price":"0.67","side":"SELL","size":"12.78"}],"timestamp":"1785130980579"},"payload_hash":"d864b901dcdc2bcbc05014cc7b34b621b2bb68c348f9944ed0fa28e6b5b99b9f","raw_frame":"{\"market\":\"0x3b40066b5cf3871a2f6237c5628bd8092a206aa998558ac5ec13c4483e31e160\", \"price_changes\":[{\"asset_id\":\"110216635572655435074987471276357323571387854733835379371586402147734167783946\", \"price\":\"0.33\", \"size\":\"12.78\", \"side\":\"BUY\", \"hash\":\"a97d15803791977bd25feb0c370f50b753807d79\", \"best_bid\":\"0.41\", \"best_ask\":\"0.42\"}, {\"asset_id\":\"14766054693214075530629349735273995982307625376442606753688071083149620216746\", \"price\":\"0.67\", \"size\":\"12.78\", \"side\":\"SELL\", \"hash\":\"ec244ee6d7ed1dac1d91b470c810f5426b70e237\", \"best_bid\":\"0.58\", \"best_ask\":\"0.59\"}], \"timestamp\":\"1785130980579\", \"event_type\":\"price_change\"}","received_at":"2026-07-27T05:43:00.539473Z","schema_version":"clob-market-ws.price_change.v1","sequence":null,"server_hash":null,"server_timestamp":"1785130980579","session_id":"502006c5cfcd437296561ea750c9ec8b","source":"clob_market_ws"},"received_at":"2026-07-27T05:43:00.539473Z","record_id":"97ddd78938f2fae0d68f8225e55f01619041759dd78677623ed7cb5920d60cc2","schema_fingerprint":"4aa3821a28b0b7c2400bc59aba4bcc0a76e971dadd19610d3ad38c768e124dc7","schema_version":"edge-lab-recorder.raw.v1","sequence":null,"source":"clob_market_ws"}
{"event_at":"2026-07-27T05:43:00.605000Z","event_fingerprint":"65a3f542059fe622f489d4171e07f54a57f71693dd42d633d3e042bbf82018bb","payload":{"connection_id":"efc69d3132f1467b8e898a382b23ac0d","event_at":"2026-07-27T05:43:00.605000Z","event_type":"price_change","frame_hash":"5c31171a5bb67a3e151286d3756adb1ded6b8ded89e59e8b5b3c81f70eb136fd","frame_index":0,"kind":"data","monotonic_ns":232963797287333,"payload":{"event_type":"price_change","market":"0x3b40066b5cf3871a2f6237c5628bd8092a206aa998558ac5ec13c4483e31e160","price_changes":[{"asset_id":"14766054693214075530629349735273995982307625376442606753688071083149620216746","best_ask":"0.59","best_bid":"0.58","hash":"bf5ee00cd432007af7b90044e67945afd75566a0","price":"0.04","side":"BUY","size":"568"},{"asset_id":"110216635572655435074987471276357323571387854733835379371586402147734167783946","best_ask":"0.42","best_bid":"0.41","hash":"574884f37b07844b33d9f6aa89dac1c83bb4f32e","price":"0.96","side":"SELL","size":"568"}],"timestamp":"1785130980605"},"payload_hash":"8081d100daff2a02930addc3e25956d26ddaa6fc228b22c27d58170932da526c","raw_frame":"{\"market\":\"0x3b40066b5cf3871a2f6237c5628bd8092a206aa998558ac5ec13c4483e31e160\", \"price_changes\":[{\"asset_id\":\"14766054693214075530629349735273995982307625376442606753688071083149620216746\", \"price\":\"0.04\", \"size\":\"568\", \"side\":\"BUY\", \"hash\":\"bf5ee00cd432007af7b90044e67945afd75566a0\", \"best_bid\":\"0.58\", \"best_ask\":\"0.59\"}, {\"asset_id\":\"110216635572655435074987471276357323571387854733835379371586402147734167783946\", \"price\":\"0.96\", \"size\":\"568\", \"side\":\"SELL\", \"hash\":\"574884f37b07844b33d9f6aa89dac1c83bb4f32e\", \"best_bid\":\"0.41\", \"best_ask\":\"0.42\"}], \"timestamp\":\"1785130980605\", \"event_type\":\"price_change\"}","received_at":"2026-07-27T05:43:00.564501Z","schema_version":"clob-market-ws.price_change.v1","sequence":null,"server_hash":null,"server_timestamp":"1785130980605","session_id":"502006c5cfcd437296561ea750c9ec8b","source":"clob_market_ws"},"received_at":"2026-07-27T05:43:00.564501Z","record_id":"b063027bf0e6a731d69bf62e2dd4df9f0f4ba0c508256663871a28c5216a9495","schema_fingerprint":"4aa3821a28b0b7c2400bc59aba4bcc0a76e971dadd19610d3ad38c768e124dc7","schema_version":"edge-lab-recorder.raw.v1","sequence":null,"source":"clob_market_ws"}
{"event_at":"2026-07-27T05:43:00.640000Z","event_fingerprint":"79b5b6fe212d56cde709429732b680b20a04d60f2e7f992625ac45d04e76e580","payload":{"connection_id":"efc69d3132f1467b8e898a382b23ac0d","event_at":"2026-07-27T05:43:00.640000Z","event_type":"best_bid_ask","frame_hash":"e916758e411e15d47d63fdfd70ff2471c23ba6e048f7269d9876a82ce5a7de5c","frame_index":0,"kind":"data","monotonic_ns":232963830901166,"payload":{"asset_id":"14766054693214075530629349735273995982307625376442606753688071083149620216746","best_ask":"0.59","best_bid":"0.57","event_type":"best_bid_ask","market":"0x3b40066b5cf3871a2f6237c5628bd8092a206aa998558ac5ec13c4483e31e160","spread":"0.02","timestamp":"1785130980640"},"payload_hash":"af7e3f0cf9baa540c73f1bde95803e72a4b13ed500dd1dff5071557e8f80fd42","raw_frame":"{\"market\":\"0x3b40066b5cf3871a2f6237c5628bd8092a206aa998558ac5ec13c4483e31e160\", \"asset_id\":\"14766054693214075530629349735273995982307625376442606753688071083149620216746\", \"best_bid\":\"0.57\", \"best_ask\":\"0.59\", \"spread\":\"0.02\", \"timestamp\":\"1785130980640\", \"event_type\":\"best_bid_ask\"}","received_at":"2026-07-27T05:43:00.598120Z","schema_version":"clob-market-ws.best_bid_ask.v1","sequence":null,"server_hash":null,"server_timestamp":"1785130980640","session_id":"502006c5cfcd437296561ea750c9ec8b","source":"clob_market_ws"},"received_at":"2026-07-27T05:43:00.598120Z","record_id":"96d668fbd1bb32ef4c518b70b5e478e4d15601d9f6ae395a1feb0d56f3f50ad3","schema_fingerprint":"8488399f31b0337811b13b266be932db7062827c2470b78bd8e9e99bab51d17d","schema_version":"edge-lab-recorder.raw.v1","sequence":null,"source":"clob_market_ws"}
{"event_at":"2026-07-27T05:43:00.640000Z","event_fingerprint":"b521ab49e1b4592a49eec0eae5c46a5b62f1ebf27f70af04f495dd2307cdf524","payload":{"connection_id":"efc69d3132f1467b8e898a382b23ac0d","event_at":"2026-07-27T05:43:00.640000Z","event_type":"best_bid_ask","frame_hash":"58e242b154d1069cd0291271d3707ba69458f2fa30e8a9a052ed5de6473b1003","frame_index":0,"kind":"data","monotonic_ns":232963831301500,"payload":{"asset_id":"110216635572655435074987471276357323571387854733835379371586402147734167783946","best_ask":"0.43","best_bid":"0.41","event_type":"best_bid_ask","market":"0x3b40066b5cf3871a2f6237c5628bd8092a206aa998558ac5ec13c4483e31e160","spread":"0.02","timestamp":"1785130980640"},"payload_hash":"0a62d92e6755e7a8abe7de9540e1d7d628f529badcbb39ca24bddf411559b06a","raw_frame":"{\"market\":\"0x3b40066b5cf3871a2f6237c5628bd8092a206aa998558ac5ec13c4483e31e160\", \"asset_id\":\"110216635572655435074987471276357323571387854733835379371586402147734167783946\", \"best_bid\":\"0.41\", \"best_ask\":\"0.43\", \"spread\":\"0.02\", \"timestamp\":\"1785130980640\", \"event_type\":\"best_bid_ask\"}","received_at":"2026-07-27T05:43:00.598521Z","schema_version":"clob-market-ws.best_bid_ask.v1","sequence":null,"server_hash":null,"server_timestamp":"1785130980640","session_id":"502006c5cfcd437296561ea750c9ec8b","source":"clob_market_ws"},"received_at":"2026-07-27T05:43:00.598521Z","record_id":"37a5d1e80279dc41329070a59cc7f30e2ef74074b44a910251f17d54e2569603","schema_fingerprint":"8488399f31b0337811b13b266be932db7062827c2470b78bd8e9e99bab51d17d","schema_version":"edge-lab-recorder.raw.v1","sequence":null,"source":"clob_market_ws"}
{"event_at":"2026-07-27T05:43:00.640000Z","event_fingerprint":"355d006f9e86c6689c7644e342cfe8389c10688b0933771aa15e42236eb13c25","payload":{"connection_id":"efc69d3132f1467b8e898a382b23ac0d","event_at":"2026-07-27T05:43:00.640000Z","event_type":"price_change","frame_hash":"3f02e40c04555a09489bbd0b81404e0bee94c11c59d36d41df52606577590414","frame_index":0,"kind":"data","monotonic_ns":232963832012250,"payload":{"event_type":"price_change","market":"0x3b40066b5cf3871a2f6237c5628bd8092a206aa998558ac5ec13c4483e31e160","price_changes":[{"asset_id":"14766054693214075530629349735273995982307625376442606753688071083149620216746","best_ask":"0.59","best_bid":"0.57","hash":"f33d6169e7b297edf195dc5c80c60ff3f9f95765","price":"0.58","side":"BUY","size":"0"},{"asset_id":"110216635572655435074987471276357323571387854733835379371586402147734167783946","best_ask":"0.43","best_bid":"0.41","hash":"2dac7d123fd94572880b9013f8381d5c7ea4c235","price":"0.42","side":"SELL","size":"0"}],"timestamp":"1785130980640"},"payload_hash":"11f8075548f837a2b893a9ddc19aba9f1a963e8b7124c1debedb7b5a6efb1378","raw_frame":"{\"market\":\"0x3b40066b5cf3871a2f6237c5628bd8092a206aa998558ac5ec13c4483e31e160\", \"price_changes\":[{\"asset_id\":\"14766054693214075530629349735273995982307625376442606753688071083149620216746\", \"price\":\"0.58\", \"size\":\"0\", \"side\":\"BUY\", \"hash\":\"f33d6169e7b297edf195dc5c80c60ff3f9f95765\", \"best_bid\":\"0.57\", \"best_ask\":\"0.59\"}, {\"asset_id\":\"110216635572655435074987471276357323571387854733835379371586402147734167783946\", \"price\":\"0.42\", \"size\":\"0\", \"side\":\"SELL\", \"hash\":\"2dac7d123fd94572880b9013f8381d5c7ea4c235\", \"best_bid\":\"0.41\", \"best_ask\":\"0.43\"}], \"timestamp\":\"1785130980640\", \"event_type\":\"price_change\"}","received_at":"2026-07-27T05:43:00.599226Z","schema_version":"clob-market-ws.price_change.v1","sequence":null,"server_hash":null,"server_timestamp":"1785130980640","session_id":"502006c5cfcd437296561ea750c9ec8b","source":"clob_market_ws"},"received_at":"2026-07-27T05:43:00.599226Z","record_id":"7d3e0b8937168c68b7930a40c47a179428e485215f257ff63ea10188ed81b997","schema_fingerprint":"4aa3821a28b0b7c2400bc59aba4bcc0a76e971dadd19610d3ad38c768e124dc7","schema_version":"edge-lab-recorder.raw.v1","sequence":null,"source":"clob_market_ws"}
