{"event_at":"2026-07-27T05:36:50.753000Z","event_fingerprint":"e79b1a95cea5e43b8c705d884ca7b73b72ce84486765c9dea5f3f2103db4f7ac","payload":{"connection_id":"efc69d3132f1467b8e898a382b23ac0d","event_at":"2026-07-27T05:36:50.753000Z","event_type":"price_change","frame_hash":"8bb80acb61452b669aec234359f06af7463765e175d6ba417dffe4c7fa34c930","frame_index":0,"kind":"data","monotonic_ns":232594331712750,"payload":{"event_type":"price_change","market":"0x3b40066b5cf3871a2f6237c5628bd8092a206aa998558ac5ec13c4483e31e160","price_changes":[{"asset_id":"110216635572655435074987471276357323571387854733835379371586402147734167783946","best_ask":"0.64","best_bid":"0.61","hash":"4e374287cc35460916e28584ccdefb8370d31927","price":"0.59","side":"BUY","size":"38"},{"asset_id":"14766054693214075530629349735273995982307625376442606753688071083149620216746","best_ask":"0.39","best_bid":"0.36","hash":"24b678426ef5cbc01bf9522ae7b0197889ef9fd9","price":"0.41","side":"SELL","size":"38"}],"timestamp":"1785130610753"},"payload_hash":"7375089eeafdde0a06bc0b8bbf718da5e30d377101ce0239bf8110678486e3be","raw_frame":"{\"market\":\"0x3b40066b5cf3871a2f6237c5628bd8092a206aa998558ac5ec13c4483e31e160\", \"price_changes\":[{\"asset_id\":\"110216635572655435074987471276357323571387854733835379371586402147734167783946\", \"price\":\"0.59\", \"size\":\"38\", \"side\":\"BUY\", \"hash\":\"4e374287cc35460916e28584ccdefb8370d31927\", \"best_bid\":\"0.61\", \"best_ask\":\"0.64\"}, {\"asset_id\":\"14766054693214075530629349735273995982307625376442606753688071083149620216746\", \"price\":\"0.41\", \"size\":\"38\", \"side\":\"SELL\", \"hash\":\"24b678426ef5cbc01bf9522ae7b0197889ef9fd9\", \"best_bid\":\"0.36\", \"best_ask\":\"0.39\"}], \"timestamp\":\"1785130610753\", \"event_type\":\"price_change\"}","received_at":"2026-07-27T05:36:51.096359Z","schema_version":"clob-market-ws.price_change.v1","sequence":null,"server_hash":null,"server_timestamp":"1785130610753","session_id":"502006c5cfcd437296561ea750c9ec8b","source":"clob_market_ws"},"received_at":"2026-07-27T05:36:51.096359Z","record_id":"10b26d6608c67f29c617897b1077583870bb593138c47fafaedf61f739914a6a","schema_fingerprint":"4aa3821a28b0b7c2400bc59aba4bcc0a76e971dadd19610d3ad38c768e124dc7","schema_version":"edge-lab-recorder.raw.v1","sequence":null,"source":"clob_market_ws"}
{"event_at":"2026-07-27T05:36:50.754000Z","event_fingerprint":"0fa24b074a24963d650badc91b09925d2d844c255836aafe61613e5836e35390","payload":{"connection_id":"efc69d3132f1467b8e898a382b23ac0d","event_at":"2026-07-27T05:36:50.754000Z","event_type":"price_change","frame_hash":"e05ac7ee40abbfc03d9973fc3b47137b19c689c2be0b88a48e34d0caa06f490a","frame_index":0,"kind":"data","monotonic_ns":232594337379250,"payload":{"event_type":"price_change","market":"0x3b40066b5cf3871a2f6237c5628bd8092a206aa998558ac5ec13c4483e31e160","price_changes":[{"asset_id":"14766054693214075530629349735273995982307625376442606753688071083149620216746","best_ask":"0.39","best_bid":"0.36","hash":"446d4c84ae748aee18b0842f335416976e11c038","price":"0.29","side":"BUY","size":"214.81"},{"asset_id":"110216635572655435074987471276357323571387854733835379371586402147734167783946","best_ask":"0.64","best_bid":"0.61","hash":"d6fd429ce9c8d9fc36660108286c7b03654dcbc6","price":"0.71","side":"SELL","size":"214.81"}],"timestamp":"1785130610754"},"payload_hash":"eb891fbadb7ded6c7001608caf9ecb5b47d1c88c35f01df5db493def2304566e","raw_frame":"{\"market\":\"0x3b40066b5cf3871a2f6237c5628bd8092a206aa998558ac5ec13c4483e31e160\", \"price_changes\":[{\"asset_id\":\"14766054693214075530629349735273995982307625376442606753688071083149620216746\", \"price\":\"0.29\", \"size\":\"214.81\", \"side\":\"BUY\", \"hash\":\"446d4c84ae748aee18b0842f335416976e11c038\", \"best_bid\":\"0.36\", \"best_ask\":\"0.39\"}, {\"asset_id\":\"110216635572655435074987471276357323571387854733835379371586402147734167783946\", \"price\":\"0.71\", \"size\":\"214.81\", \"side\":\"SELL\", \"hash\":\"d6fd429ce9c8d9fc36660108286c7b03654dcbc6\", \"best_bid\":\"0.61\", \"best_ask\":\"0.64\"}], \"timestamp\":\"1785130610754\", \"event_type\":\"price_change\"}","received_at":"2026-07-27T05:36:51.102026Z","schema_version":"clob-market-ws.price_change.v1","sequence":null,"server_hash":null,"server_timestamp":"1785130610754","session_id":"502006c5cfcd437296561ea750c9ec8b","source":"clob_market_ws"},"received_at":"2026-07-27T05:36:51.102026Z","record_id":"1611828ea0eedf3bede2197ecb2fdfd9b7e9124582629fd3e3f4c75146413320","schema_fingerprint":"4aa3821a28b0b7c2400bc59aba4bcc0a76e971dadd19610d3ad38c768e124dc7","schema_version":"edge-lab-recorder.raw.v1","sequence":null,"source":"clob_market_ws"}
{"event_at":"2026-07-27T05:36:50.754000Z","event_fingerprint":"f71d8a58cc01a300fc14e4f9767cbc5c1308ca3c26d0d5c4dd87e81b8ddd6195","payload":{"connection_id":"efc69d3132f1467b8e898a382b23ac0d","event_at":"2026-07-27T05:36:50.754000Z","event_type":"price_change","frame_hash":"d38b94a102a95b7d509265837747fd145b27f0832ee113d260a6f0f782eb5294","frame_index":0,"kind":"data","monotonic_ns":232594340393291,"payload":{"event_type":"price_change","market":"0x3b40066b5cf3871a2f6237c5628bd8092a206aa998558ac5ec13c4483e31e160","price_changes":[{"asset_id":"14766054693214075530629349735273995982307625376442606753688071083149620216746","best_ask":"0.39","best_bid":"0.36","hash":"4c1be22693cad1040b9370ecdf98fd13666fcb6b","price":"0.27","side":"BUY","size":"411.1"},{"asset_id":"110216635572655435074987471276357323571387854733835379371586402147734167783946","best_ask":"0.64","best_bid":"0.61","hash":"029d47003f8416af4d46f30e6145db60dd94aee6","price":"0.73","side":"SELL","size":"411.1"}],"timestamp":"1785130610754"},"payload_hash":"707d4a0b6c64b0b57ce692fa50a0d6799bd6434084c4d8742507da0dba12c698","raw_frame":"{\"market\":\"0x3b40066b5cf3871a2f6237c5628bd8092a206aa998558ac5ec13c4483e31e160\", \"price_changes\":[{\"asset_id\":\"14766054693214075530629349735273995982307625376442606753688071083149620216746\", \"price\":\"0.27\", \"size\":\"411.1\", \"side\":\"BUY\", \"hash\":\"4c1be22693cad1040b9370ecdf98fd13666fcb6b\", \"best_bid\":\"0.36\", \"best_ask\":\"0.39\"}, {\"asset_id\":\"110216635572655435074987471276357323571387854733835379371586402147734167783946\", \"price\":\"0.73\", \"size\":\"411.1\", \"side\":\"SELL\", \"hash\":\"029d47003f8416af4d46f30e6145db60dd94aee6\", \"best_bid\":\"0.61\", \"best_ask\":\"0.64\"}], \"timestamp\":\"1785130610754\", \"event_type\":\"price_change\"}","received_at":"2026-07-27T05:36:51.105040Z","schema_version":"clob-market-ws.price_change.v1","sequence":null,"server_hash":null,"server_timestamp":"1785130610754","session_id":"502006c5cfcd437296561ea750c9ec8b","source":"clob_market_ws"},"received_at":"2026-07-27T05:36:51.105040Z","record_id":"66e7de7645273e9b9d8fdb31c19838ceb1160fb4a1d9a86376108139dd832dc1","schema_fingerprint":"4aa3821a28b0b7c2400bc59aba4bcc0a76e971dadd19610d3ad38c768e124dc7","schema_version":"edge-lab-recorder.raw.v1","sequence":null,"source":"clob_market_ws"}
{"event_at":"2026-07-27T05:36:50.755000Z","event_fingerprint":"208a8acb1f416b5d317ea2443d40073ddf5292a1a122b905a62fef73959599a5","payload":{"connection_id":"efc69d3132f1467b8e898a382b23ac0d","event_at":"2026-07-27T05:36:50.755000Z","event_type":"best_bid_ask","frame_hash":"a3acb7dc43133ae75acee445ca2b7af7cf8f1996aacc52460530ca0e2ca89f1d","frame_index":0,"kind":"data","monotonic_ns":232594343478083,"payload":{"asset_id":"14766054693214075530629349735273995982307625376442606753688071083149620216746","best_ask":"0.37","best_bid":"0.36","event_type":"best_bid_ask","market":"0x3b40066b5cf3871a2f6237c5628bd8092a206aa998558ac5ec13c4483e31e160","spread":"0.01","timestamp":"1785130610755"},"payload_hash":"c02a5abda4bab5b8e69de689a8fb10168a2c373d137269fbe35350caf3a781d7","raw_frame":"{\"market\":\"0x3b40066b5cf3871a2f6237c5628bd8092a206aa998558ac5ec13c4483e31e160\", \"asset_id\":\"14766054693214075530629349735273995982307625376442606753688071083149620216746\", \"best_bid\":\"0.36\", \"best_ask\":\"0.37\", \"spread\":\"0.01\", \"timestamp\":\"1785130610755\", \"event_type\":\"best_bid_ask\"}","received_at":"2026-07-27T05:36:51.108124Z","schema_version":"clob-market-ws.best_bid_ask.v1","sequence":null,"server_hash":null,"server_timestamp":"1785130610755","session_id":"502006c5cfcd437296561ea750c9ec8b","source":"clob_market_ws"},"received_at":"2026-07-27T05:36:51.108124Z","record_id":"6c9dbc4fc2f6f7d9b95b1b0b9b155d2a29170133de3bbcd51f5fec4208861b93","schema_fingerprint":"8488399f31b0337811b13b266be932db7062827c2470b78bd8e9e99bab51d17d","schema_version":"edge-lab-recorder.raw.v1","sequence":null,"source":"clob_market_ws"}
{"event_at":"2026-07-27T05:36:50.755000Z","event_fingerprint":"4ece59a0d3db992b84ab3a195caebb3af85e3cb8123d167ce9484ef33be73226","payload":{"connection_id":"efc69d3132f1467b8e898a382b23ac0d","event_at":"2026-07-27T05:36:50.755000Z","event_type":"best_bid_ask","frame_hash":"f37c957b331f1e7b8871115c3ffdcb6eae7f9318a945f18b5ed1b8ffb7dda023","frame_index":0,"kind":"data","monotonic_ns":232594345407208,"payload":{"asset_id":"110216635572655435074987471276357323571387854733835379371586402147734167783946","best_ask":"0.64","best_bid":"0.63","event_type":"best_bid_ask","market":"0x3b40066b5cf3871a2f6237c5628bd8092a206aa998558ac5ec13c4483e31e160","spread":"0.01","timestamp":"1785130610755"},"payload_hash":"a0f742304cf29590cf38d5ce124524d37cfc94bd14007c7ceff4590fb5331059","raw_frame":"{\"market\":\"0x3b40066b5cf3871a2f6237c5628bd8092a206aa998558ac5ec13c4483e31e160\", \"asset_id\":\"110216635572655435074987471276357323571387854733835379371586402147734167783946\", \"best_bid\":\"0.63\", \"best_ask\":\"0.64\", \"spread\":\"0.01\", \"timestamp\":\"1785130610755\", \"event_type\":\"best_bid_ask\"}","received_at":"2026-07-27T05:36:51.110055Z","schema_version":"clob-market-ws.best_bid_ask.v1","sequence":null,"server_hash":null,"server_timestamp":"1785130610755","session_id":"502006c5cfcd437296561ea750c9ec8b","source":"clob_market_ws"},"received_at":"2026-07-27T05:36:51.110055Z","record_id":"823d29ff0192340db255766e42cec9f541b07560b756a01e5c414433fd60035c","schema_fingerprint":"8488399f31b0337811b13b266be932db7062827c2470b78bd8e9e99bab51d17d","schema_version":"edge-lab-recorder.raw.v1","sequence":null,"source":"clob_market_ws"}
{"event_at":"2026-07-27T05:36:50.755000Z","event_fingerprint":"ef582b12f2e2931066045136ec8e1a99e65e1ffdbe542fcdef3921dc7f74970c","payload":{"connection_id":"efc69d3132f1467b8e898a382b23ac0d","event_at":"2026-07-27T05:36:50.755000Z","event_type":"price_change","frame_hash":"01988a0e8a1bd650c8b07ad6a5b2a24a7cf9c34954b3e891396809e27397e94a","frame_index":0,"kind":"data","monotonic_ns":232594348658041,"payload":{"event_type":"price_change","market":"0x3b40066b5cf3871a2f6237c5628bd8092a206aa998558ac5ec13c4483e31e160","price_changes":[{"asset_id":"110216635572655435074987471276357323571387854733835379371586402147734167783946","best_ask":"0.64","best_bid":"0.63","hash":"de7c357eccd2615786445b30c5210c8f7b9f3567","price":"0.63","side":"BUY","size":"11"},{"asset_id":"14766054693214075530629349735273995982307625376442606753688071083149620216746","best_ask":"0.37","best_bid":"0.36","hash":"0f51029709b4c9b3a2a11dea5d35add161f0312f","price":"0.37","side":"SELL","size":"11"}],"timestamp":"1785130610755"},"payload_hash":"9d31aae3d9d285332aed42a2aa7e9fd68b59314999630d20efddcd9c88770079","raw_frame":"{\"market\":\"0x3b40066b5cf3871a2f6237c5628bd8092a206aa998558ac5ec13c4483e31e160\", \"price_changes\":[{\"asset_id\":\"110216635572655435074987471276357323571387854733835379371586402147734167783946\", \"price\":\"0.63\", \"size\":\"11\", \"side\":\"BUY\", \"hash\":\"de7c357eccd2615786445b30c5210c8f7b9f3567\", \"best_bid\":\"0.63\", \"best_ask\":\"0.64\"}, {\"asset_id\":\"14766054693214075530629349735273995982307625376442606753688071083149620216746\", \"price\":\"0.37\", \"size\":\"11\", \"side\":\"SELL\", \"hash\":\"0f51029709b4c9b3a2a11dea5d35add161f0312f\", \"best_bid\":\"0.36\", \"best_ask\":\"0.37\"}], \"timestamp\":\"1785130610755\", \"event_type\":\"price_change\"}","received_at":"2026-07-27T05:36:51.113305Z","schema_version":"clob-market-ws.price_change.v1","sequence":null,"server_hash":null,"server_timestamp":"1785130610755","session_id":"502006c5cfcd437296561ea750c9ec8b","source":"clob_market_ws"},"received_at":"2026-07-27T05:36:51.113305Z","record_id":"4f6107350d4b4c749025e5f79573988c737e334517616cb0067c99da824e4b5f","schema_fingerprint":"4aa3821a28b0b7c2400bc59aba4bcc0a76e971dadd19610d3ad38c768e124dc7","schema_version":"edge-lab-recorder.raw.v1","sequence":null,"source":"clob_market_ws"}
{"event_at":"2026-07-27T05:36:50.756000Z","event_fingerprint":"5ba3bea2128361a8f2e6af964b538aecca673b027b5bf513f215e004a2a8df3e","payload":{"connection_id":"efc69d3132f1467b8e898a382b23ac0d","event_at":"2026-07-27T05:36:50.756000Z","event_type":"price_change","frame_hash":"84a2b57828417935f3ba7d6533a1f19718da7aa63e43f2ebed0236bbfdc0ff64","frame_index":0,"kind":"data","monotonic_ns":232594350094791,"payload":{"event_type":"price_change","market":"0x3b40066b5cf3871a2f6237c5628bd8092a206aa998558ac5ec13c4483e31e160","price_changes":[{"asset_id":"14766054693214075530629349735273995982307625376442606753688071083149620216746","best_ask":"0.37","best_bid":"0.36","hash":"aed218f89718314a6d79c66c19151a62a6b0ad66","price":"0.43","side":"SELL","size":"50.6"},{"asset_id":"110216635572655435074987471276357323571387854733835379371586402147734167783946","best_ask":"0.64","best_bid":"0.63","hash":"b6b8477c882995c7c974988dcadfe6c8d6c052e8","price":"0.57","side":"BUY","size":"50.6"}],"timestamp":"1785130610756"},"payload_hash":"ceafa483e6c47f876bd692a17c89fd84619d74aec63184a18cb261fad73b55ee","raw_frame":"{\"market\":\"0x3b40066b5cf3871a2f6237c5628bd8092a206aa998558ac5ec13c4483e31e160\", \"price_changes\":[{\"asset_id\":\"14766054693214075530629349735273995982307625376442606753688071083149620216746\", \"price\":\"0.43\", \"size\":\"50.6\", \"side\":\"SELL\", \"hash\":\"aed218f89718314a6d79c66c19151a62a6b0ad66\", \"best_bid\":\"0.36\", \"best_ask\":\"0.37\"}, {\"asset_id\":\"110216635572655435074987471276357323571387854733835379371586402147734167783946\", \"price\":\"0.57\", \"size\":\"50.6\", \"side\":\"BUY\", \"hash\":\"b6b8477c882995c7c974988dcadfe6c8d6c052e8\", \"best_bid\":\"0.63\", \"best_ask\":\"0.64\"}], \"timestamp\":\"1785130610756\", \"event_type\":\"price_change\"}","received_at":"2026-07-27T05:36:51.114748Z","schema_version":"clob-market-ws.price_change.v1","sequence":null,"server_hash":null,"server_timestamp":"1785130610756","session_id":"502006c5cfcd437296561ea750c9ec8b","source":"clob_market_ws"},"received_at":"2026-07-27T05:36:51.114748Z","record_id":"63ad994536eb813edf4638d6e2336f6877748086ae98313dcb1123ebfa97508b","schema_fingerprint":"4aa3821a28b0b7c2400bc59aba4bcc0a76e971dadd19610d3ad38c768e124dc7","schema_version":"edge-lab-recorder.raw.v1","sequence":null,"source":"clob_market_ws"}
{"event_at":"2026-07-27T05:36:50.756000Z","event_fingerprint":"6074ba2ee90ca96aff89b57d43bf824dc5d0702d1b6cfebafb61ba87f9ec1c9c","payload":{"connection_id":"efc69d3132f1467b8e898a382b23ac0d","event_at":"2026-07-27T05:36:50.756000Z","event_type":"price_change","frame_hash":"5f0251dade4a0ae1e80312b8f3938af5b5a2c64708e21f94a31a144e4f71521e","frame_index":0,"kind":"data","monotonic_ns":232594351863000,"payload":{"event_type":"price_change","market":"0x3b40066b5cf3871a2f6237c5628bd8092a206aa998558ac5ec13c4483e31e160","price_changes":[{"asset_id":"110216635572655435074987471276357323571387854733835379371586402147734167783946","best_ask":"0.64","best_bid":"0.63","hash":"bdaaed2cce0986b0a2390e8f3c81ed9945f3d5ed","price":"0.58","side":"BUY","size":"84.4"},{"asset_id":"14766054693214075530629349735273995982307625376442606753688071083149620216746","best_ask":"0.37","best_bid":"0.36","hash":"58c9220aa7a0941fcc00191ca3e8adba28ab5605","price":"0.42","side":"SELL","size":"84.4"}],"timestamp":"1785130610756"},"payload_hash":"6c46b870dd29d3fa27bbd6693f9151fa068499d88c32a5387a07d781bdd5d55f","raw_frame":"{\"market\":\"0x3b40066b5cf3871a2f6237c5628bd8092a206aa998558ac5ec13c4483e31e160\", \"price_changes\":[{\"asset_id\":\"110216635572655435074987471276357323571387854733835379371586402147734167783946\", \"price\":\"0.58\", \"size\":\"84.4\", \"side\":\"BUY\", \"hash\":\"bdaaed2cce0986b0a2390e8f3c81ed9945f3d5ed\", \"best_bid\":\"0.63\", \"best_ask\":\"0.64\"}, {\"asset_id\":\"14766054693214075530629349735273995982307625376442606753688071083149620216746\", \"price\":\"0.42\", \"size\":\"84.4\", \"side\":\"SELL\", \"hash\":\"58c9220aa7a0941fcc00191ca3e8adba28ab5605\", \"best_bid\":\"0.36\", \"best_ask\":\"0.37\"}], \"timestamp\":\"1785130610756\", \"event_type\":\"price_change\"}","received_at":"2026-07-27T05:36:51.116509Z","schema_version":"clob-market-ws.price_change.v1","sequence":null,"server_hash":null,"server_timestamp":"1785130610756","session_id":"502006c5cfcd437296561ea750c9ec8b","source":"clob_market_ws"},"received_at":"2026-07-27T05:36:51.116509Z","record_id":"5f9a39c474aa92b26c716495b3e98390837b3773dec12f94d54d4f31036a1cce","schema_fingerprint":"4aa3821a28b0b7c2400bc59aba4bcc0a76e971dadd19610d3ad38c768e124dc7","schema_version":"edge-lab-recorder.raw.v1","sequence":null,"source":"clob_market_ws"}
{"event_at":"2026-07-27T05:36:50.758000Z","event_fingerprint":"75a61cbd1889e6def06e039109671e2d3f5f8bf4e2a85b0baaab19bcd228cc40","payload":{"connection_id":"efc69d3132f1467b8e898a382b23ac0d","event_at":"2026-07-27T05:36:50.758000Z","event_type":"price_change","frame_hash":"cd2a9f4c9645497f3da8af034c581730b5faeb1fbe7dd73160b297c0d8d5986d","frame_index":0,"kind":"data","monotonic_ns":232594355476958,"payload":{"event_type":"price_change","market":"0x3b40066b5cf3871a2f6237c5628bd8092a206aa998558ac5ec13c4483e31e160","price_changes":[{"asset_id":"14766054693214075530629349735273995982307625376442606753688071083149620216746","best_ask":"0.37","best_bid":"0.36","hash":"7814839bc7fbb5055d29b36c11e2a1bf7f935eac","price":"0.44","side":"SELL","size":"40"},{"asset_id":"110216635572655435074987471276357323571387854733835379371586402147734167783946","best_ask":"0.64","best_bid":"0.63","hash":"d3d958b4bdb6bd0a81a9c6b753d7f5cb9b1f7510","price":"0.56","side":"BUY","size":"40"}],"timestamp":"1785130610758"},"payload_hash":"9864805d517c778a835b50e31eb6c9202b45a17f71ff12ca09161dfc3200388c","raw_frame":"{\"market\":\"0x3b40066b5cf3871a2f6237c5628bd8092a206aa998558ac5ec13c4483e31e160\", \"price_changes\":[{\"asset_id\":\"14766054693214075530629349735273995982307625376442606753688071083149620216746\", \"price\":\"0.44\", \"size\":\"40\", \"side\":\"SELL\", \"hash\":\"7814839bc7fbb5055d29b36c11e2a1bf7f935eac\", \"best_bid\":\"0.36\", \"best_ask\":\"0.37\"}, {\"asset_id\":\"110216635572655435074987471276357323571387854733835379371586402147734167783946\", \"price\":\"0.56\", \"size\":\"40\", \"side\":\"BUY\", \"hash\":\"d3d958b4bdb6bd0a81a9c6b753d7f5cb9b1f7510\", \"best_bid\":\"0.63\", \"best_ask\":\"0.64\"}], \"timestamp\":\"1785130610758\", \"event_type\":\"price_change\"}","received_at":"2026-07-27T05:36:51.120123Z","schema_version":"clob-market-ws.price_change.v1","sequence":null,"server_hash":null,"server_timestamp":"1785130610758","session_id":"502006c5cfcd437296561ea750c9ec8b","source":"clob_market_ws"},"received_at":"2026-07-27T05:36:51.120123Z","record_id":"953d1a7ba0d1019326fc15c25f0ea332436c92b177af251df826e242d9c797d9","schema_fingerprint":"4aa3821a28b0b7c2400bc59aba4bcc0a76e971dadd19610d3ad38c768e124dc7","schema_version":"edge-lab-recorder.raw.v1","sequence":null,"source":"clob_market_ws"}
{"event_at":"2026-07-27T05:36:50.759000Z","event_fingerprint":"beda8f3883b05df0ba22c239940553581acf44e9a7960a9fc7d17d674ddd343a","payload":{"connection_id":"efc69d3132f1467b8e898a382b23ac0d","event_at":"2026-07-27T05:36:50.759000Z","event_type":"price_change","frame_hash":"4527433644b1cb30236027421f05589c7d6046dfab7c1f3cdb4c841d6b8b9447","frame_index":0,"kind":"data","monotonic_ns":232594357826625,"payload":{"event_type":"price_change","market":"0x3b40066b5cf3871a2f6237c5628bd8092a206aa998558ac5ec13c4483e31e160","price_changes":[{"asset_id":"14766054693214075530629349735273995982307625376442606753688071083149620216746","best_ask":"0.37","best_bid":"0.36","hash":"74436955f5082c995569d9ad204a5a98239b3ff6","price":"0.27","side":"BUY","size":"287.65"},{"asset_id":"110216635572655435074987471276357323571387854733835379371586402147734167783946","best_ask":"0.64","best_bid":"0.63","hash":"8eb988c2808eedb23e599e2cd5176e9fef33605b","price":"0.73","side":"SELL","size":"287.65"}],"timestamp":"1785130610759"},"payload_hash":"76bfaa96a8b6ea26ebea436b86a1ae0c8c46fe705a372b712e79e27fc9103931","raw_frame":"{\"market\":\"0x3b40066b5cf3871a2f6237c5628bd8092a206aa998558ac5ec13c4483e31e160\", \"price_changes\":[{\"asset_id\":\"14766054693214075530629349735273995982307625376442606753688071083149620216746\", \"price\":\"0.27\", \"size\":\"287.65\", \"side\":\"BUY\", \"hash\":\"74436955f5082c995569d9ad204a5a98239b3ff6\", \"best_bid\":\"0.36\", \"best_ask\":\"0.37\"}, {\"asset_id\":\"110216635572655435074987471276357323571387854733835379371586402147734167783946\", \"price\":\"0.73\", \"size\":\"287.65\", \"side\":\"SELL\", \"hash\":\"8eb988c2808eedb23e599e2cd5176e9fef33605b\", \"best_bid\":\"0.63\", \"best_ask\":\"0.64\"}], \"timestamp\":\"1785130610759\", \"event_type\":\"price_change\"}","received_at":"2026-07-27T05:36:51.122474Z","schema_version":"clob-market-ws.price_change.v1","sequence":null,"server_hash":null,"server_timestamp":"1785130610759","session_id":"502006c5cfcd437296561ea750c9ec8b","source":"clob_market_ws"},"received_at":"2026-07-27T05:36:51.122474Z","record_id":"0119566651547c01c65af128203f5fec6f09216bd02d2116ec9a68277c1532da","schema_fingerprint":"4aa3821a28b0b7c2400bc59aba4bcc0a76e971dadd19610d3ad38c768e124dc7","schema_version":"edge-lab-recorder.raw.v1","sequence":null,"source":"clob_market_ws"}
{"event_at":"2026-07-27T05:36:50.759000Z","event_fingerprint":"eca46d6e61d0dcf5e65f116ce0d452889a37383baa6fb52ae88582b5376dd91e","payload":{"connection_id":"efc69d3132f1467b8e898a382b23ac0d","event_at":"2026-07-27T05:36:50.759000Z","event_type":"price_change","frame_hash":"54b4ec763d0b24dea48fdfe2494db6eb5e9eadb099fc3887242e03a0e405a4dd","frame_index":0,"kind":"data","monotonic_ns":232594360079416,"payload":{"event_type":"price_change","market":"0x3b40066b5cf3871a2f6237c5628bd8092a206aa998558ac5ec13c4483e31e160","price_changes":[{"asset_id":"14766054693214075530629349735273995982307625376442606753688071083149620216746","best_ask":"0.37","best_bid":"0.36","hash":"f93f17c7533ad8d11b3128f656cf689ccd6e1cfa","price":"0.31","side":"BUY","size":"189.75"},{"asset_id":"110216635572655435074987471276357323571387854733835379371586402147734167783946","best_ask":"0.64","best_bid":"0.63","hash":"aa089574891158feb291e66f41c72f927f406757","price":"0.69","side":"SELL","size":"189.75"}],"timestamp":"1785130610759"},"payload_hash":"979906ddc74a03cee0979f2d39c8fb41a0933e8b2bb696ae5bd36dda9af7109b","raw_frame":"{\"market\":\"0x3b40066b5cf3871a2f6237c5628bd8092a206aa998558ac5ec13c4483e31e160\", \"price_changes\":[{\"asset_id\":\"14766054693214075530629349735273995982307625376442606753688071083149620216746\", \"price\":\"0.31\", \"size\":\"189.75\", \"side\":\"BUY\", \"hash\":\"f93f17c7533ad8d11b3128f656cf689ccd6e1cfa\", \"best_bid\":\"0.36\", \"best_ask\":\"0.37\"}, {\"asset_id\":\"110216635572655435074987471276357323571387854733835379371586402147734167783946\", \"price\":\"0.69\", \"size\":\"189.75\", \"side\":\"SELL\", \"hash\":\"aa089574891158feb291e66f41c72f927f406757\", \"best_bid\":\"0.63\", \"best_ask\":\"0.64\"}], \"timestamp\":\"1785130610759\", \"event_type\":\"price_change\"}","received_at":"2026-07-27T05:36:51.124726Z","schema_version":"clob-market-ws.price_change.v1","sequence":null,"server_hash":null,"server_timestamp":"1785130610759","session_id":"502006c5cfcd437296561ea750c9ec8b","source":"clob_market_ws"},"received_at":"2026-07-27T05:36:51.124726Z","record_id":"45d89c69bf8ff86eca2c55d4e08c7a3f74d05d9247ea48cb2ed8ee682663ed1b","schema_fingerprint":"4aa3821a28b0b7c2400bc59aba4bcc0a76e971dadd19610d3ad38c768e124dc7","schema_version":"edge-lab-recorder.raw.v1","sequence":null,"source":"clob_market_ws"}
{"event_at":"2026-07-27T05:36:50.759000Z","event_fingerprint":"30d12dc8cdde4c52a0877762d536c53788accc084923edb1da65d89990862960","payload":{"connection_id":"efc69d3132f1467b8e898a382b23ac0d","event_at":"2026-07-27T05:36:50.759000Z","event_type":"price_change","frame_hash":"acc2b7cc588596e3eb38e168762600142756ff52f9b7684773ac909eb5b90adf","frame_index":0,"kind":"data","monotonic_ns":232594363025333,"payload":{"event_type":"price_change","market":"0x3b40066b5cf3871a2f6237c5628bd8092a206aa998558ac5ec13c4483e31e160","price_changes":[{"asset_id":"14766054693214075530629349735273995982307625376442606753688071083149620216746","best_ask":"0.37","best_bid":"0.36","hash":"f93f17c7533ad8d11b3128f656cf689ccd6e1cfa","price":"0.32","side":"BUY","size":"46"},{"asset_id":"110216635572655435074987471276357323571387854733835379371586402147734167783946","best_ask":"0.64","best_bid":"0.63","hash":"aa089574891158feb291e66f41c72f927f406757","price":"0.68","side":"SELL","size":"46"}],"timestamp":"1785130610759"},"payload_hash":"697ed6ca61e12c6b1ecbef245e151ee4e0592be6acbff548b124dbb89d3bbbb1","raw_frame":"{\"market\":\"0x3b40066b5cf3871a2f6237c5628bd8092a206aa998558ac5ec13c4483e31e160\", \"price_changes\":[{\"asset_id\":\"14766054693214075530629349735273995982307625376442606753688071083149620216746\", \"price\":\"0.32\", \"size\":\"46\", \"side\":\"BUY\", \"hash\":\"f93f17c7533ad8d11b3128f656cf689ccd6e1cfa\", \"best_bid\":\"0.36\", \"best_ask\":\"0.37\"}, {\"asset_id\":\"110216635572655435074987471276357323571387854733835379371586402147734167783946\", \"price\":\"0.68\", \"size\":\"46\", \"side\":\"SELL\", \"hash\":\"aa089574891158feb291e66f41c72f927f406757\", \"best_bid\":\"0.63\", \"best_ask\":\"0.64\"}], \"timestamp\":\"1785130610759\", \"event_type\":\"price_change\"}","received_at":"2026-07-27T05:36:51.127673Z","schema_version":"clob-market-ws.price_change.v1","sequence":null,"server_hash":null,"server_timestamp":"1785130610759","session_id":"502006c5cfcd437296561ea750c9ec8b","source":"clob_market_ws"},"received_at":"2026-07-27T05:36:51.127673Z","record_id":"63a94df1f5234d8bcba4f173bc0ab8090c66d321abbbdcc61f56b803a168bde0","schema_fingerprint":"4aa3821a28b0b7c2400bc59aba4bcc0a76e971dadd19610d3ad38c768e124dc7","schema_version":"edge-lab-recorder.raw.v1","sequence":null,"source":"clob_market_ws"}
{"event_at":"2026-07-27T05:36:50.759000Z","event_fingerprint":"666fa07ffe244120adfff8cc73bbf02a9e619875d406efa82925d15d2712859d","payload":{"connection_id":"efc69d3132f1467b8e898a382b23ac0d","event_at":"2026-07-27T05:36:50.759000Z","event_type":"price_change","frame_hash":"65b90b24b40e33a4b634700a81bb97721ccf685480bf4d1f327776badf437e4b","frame_index":0,"kind":"data","monotonic_ns":232594365899958,"payload":{"event_type":"price_change","market":"0x3b40066b5cf3871a2f6237c5628bd8092a206aa998558ac5ec13c4483e31e160","price_changes":[{"asset_id":"110216635572655435074987471276357323571387854733835379371586402147734167783946","best_ask":"0.64","best_bid":"0.63","hash":"af968480e3f3c87828349c736fab034a9bf59f7c","price":"0.47","side":"BUY","size":"161.11"},{"asset_id":"14766054693214075530629349735273995982307625376442606753688071083149620216746","best_ask":"0.37","best_bid":"0.36","hash":"6e8ee419642896fca7fa37e9f90012a627918afb","price":"0.53","side":"SELL","size":"161.11"}],"timestamp":"1785130610759"},"payload_hash":"7f494903e1214486024fcf11f4983a643e2e378695cfa25ef13ac3ec0852cfbb","raw_frame":"{\"market\":\"0x3b40066b5cf3871a2f6237c5628bd8092a206aa998558ac5ec13c4483e31e160\", \"price_changes\":[{\"asset_id\":\"110216635572655435074987471276357323571387854733835379371586402147734167783946\", \"price\":\"0.47\", \"size\":\"161.11\", \"side\":\"BUY\", \"hash\":\"af968480e3f3c87828349c736fab034a9bf59f7c\", \"best_bid\":\"0.63\", \"best_ask\":\"0.64\"}, {\"asset_id\":\"14766054693214075530629349735273995982307625376442606753688071083149620216746\", \"price\":\"0.53\", \"size\":\"161.11\", \"side\":\"SELL\", \"hash\":\"6e8ee419642896fca7fa37e9f90012a627918afb\", \"best_bid\":\"0.36\", \"best_ask\":\"0.37\"}], \"timestamp\":\"1785130610759\", \"event_type\":\"price_change\"}","received_at":"2026-07-27T05:36:51.130547Z","schema_version":"clob-market-ws.price_change.v1","sequence":null,"server_hash":null,"server_timestamp":"1785130610759","session_id":"502006c5cfcd437296561ea750c9ec8b","source":"clob_market_ws"},"received_at":"2026-07-27T05:36:51.130547Z","record_id":"10e0a698a3b8ba384ee4b8d2ac468db005389585404dd6bcb931ba8a15cd6bd3","schema_fingerprint":"4aa3821a28b0b7c2400bc59aba4bcc0a76e971dadd19610d3ad38c768e124dc7","schema_version":"edge-lab-recorder.raw.v1","sequence":null,"source":"clob_market_ws"}
{"event_at":"2026-07-27T05:36:50.760000Z","event_fingerprint":"2a3b36b2db41b026cfd9bdb919a3fee20fd60a8089b4a4d3dc1c7cfb93fc3457","payload":{"connection_id":"efc69d3132f1467b8e898a382b23ac0d","event_at":"2026-07-27T05:36:50.760000Z","event_type":"price_change","frame_hash":"f8dc666f7f2086c9c4a8d6edac0eaed120ade79d14f2f0e5bb4031c599a14ebe","frame_index":0,"kind":"data","monotonic_ns":232594367556583,"payload":{"event_type":"price_change","market":"0x3b40066b5cf3871a2f6237c5628bd8092a206aa998558ac5ec13c4483e31e160","price_changes":[{"asset_id":"110216635572655435074987471276357323571387854733835379371586402147734167783946","best_ask":"0.64","best_bid":"0.63","hash":"0273c4218f1516ec7bc578723807c18f6fc32f8b","price":"0.62","side":"BUY","size":"11"},{"asset_id":"14766054693214075530629349735273995982307625376442606753688071083149620216746","best_ask":"0.37","best_bid":"0.36","hash":"f5e1f37a3d00843ff5213ce941f145cbcf5c42de","price":"0.38","side":"SELL","size":"11"}],"timestamp":"1785130610760"},"payload_hash":"997644ef8fedf647f500086432943705485257a6553520a02d57ce6d54376d2f","raw_frame":"{\"market\":\"0x3b40066b5cf3871a2f6237c5628bd8092a206aa998558ac5ec13c4483e31e160\", \"price_changes\":[{\"asset_id\":\"110216635572655435074987471276357323571387854733835379371586402147734167783946\", \"price\":\"0.62\", \"size\":\"11\", \"side\":\"BUY\", \"hash\":\"0273c4218f1516ec7bc578723807c18f6fc32f8b\", \"best_bid\":\"0.63\", \"best_ask\":\"0.64\"}, {\"asset_id\":\"14766054693214075530629349735273995982307625376442606753688071083149620216746\", \"price\":\"0.38\", \"size\":\"11\", \"side\":\"SELL\", \"hash\":\"f5e1f37a3d00843ff5213ce941f145cbcf5c42de\", \"best_bid\":\"0.36\", \"best_ask\":\"0.37\"}], \"timestamp\":\"1785130610760\", \"event_type\":\"price_change\"}","received_at":"2026-07-27T05:36:51.132202Z","schema_version":"clob-market-ws.price_change.v1","sequence":null,"server_hash":null,"server_timestamp":"1785130610760","session_id":"502006c5cfcd437296561ea750c9ec8b","source":"clob_market_ws"},"received_at":"2026-07-27T05:36:51.132202Z","record_id":"e1ecec34cd22fd0aeb468498fe2bdd11284a66698229d3888c526b4c495a1781","schema_fingerprint":"4aa3821a28b0b7c2400bc59aba4bcc0a76e971dadd19610d3ad38c768e124dc7","schema_version":"edge-lab-recorder.raw.v1","sequence":null,"source":"clob_market_ws"}
