{"event_at":"2026-07-27T05:32:45.161000Z","event_fingerprint":"b4e56c0439ec10f7426669e618c6fc6b3eb9e151ae0ef84b4313bd32e19a7b46","payload":{"connection_id":"efc69d3132f1467b8e898a382b23ac0d","event_at":"2026-07-27T05:32:45.161000Z","event_type":"price_change","frame_hash":"fbec3b316054cf374bfbc10d166ffd74eab9995f143c11f4b544ff38834fb173","frame_index":0,"kind":"data","monotonic_ns":232348359907625,"payload":{"event_type":"price_change","market":"0x3b40066b5cf3871a2f6237c5628bd8092a206aa998558ac5ec13c4483e31e160","price_changes":[{"asset_id":"14766054693214075530629349735273995982307625376442606753688071083149620216746","best_ask":"0.53","best_bid":"0.52","hash":"a1b52fb19cfc70838f616c58433f09f99d019765","price":"0.03","side":"BUY","size":"618.1"},{"asset_id":"110216635572655435074987471276357323571387854733835379371586402147734167783946","best_ask":"0.48","best_bid":"0.47","hash":"b44c47d38a11e402d077e14ebc02c7e1e844ca39","price":"0.97","side":"SELL","size":"618.1"}],"timestamp":"1785130365161"},"payload_hash":"7c32ceb44a15943791d7c52783bd6270b8f0a6d2eaf0e0e67c0f7bc08630101c","raw_frame":"{\"market\":\"0x3b40066b5cf3871a2f6237c5628bd8092a206aa998558ac5ec13c4483e31e160\", \"price_changes\":[{\"asset_id\":\"14766054693214075530629349735273995982307625376442606753688071083149620216746\", \"price\":\"0.03\", \"size\":\"618.1\", \"side\":\"BUY\", \"hash\":\"a1b52fb19cfc70838f616c58433f09f99d019765\", \"best_bid\":\"0.52\", \"best_ask\":\"0.53\"}, {\"asset_id\":\"110216635572655435074987471276357323571387854733835379371586402147734167783946\", \"price\":\"0.97\", \"size\":\"618.1\", \"side\":\"SELL\", \"hash\":\"b44c47d38a11e402d077e14ebc02c7e1e844ca39\", \"best_bid\":\"0.47\", \"best_ask\":\"0.48\"}], \"timestamp\":\"1785130365161\", \"event_type\":\"price_change\"}","received_at":"2026-07-27T05:32:45.122851Z","schema_version":"clob-market-ws.price_change.v1","sequence":null,"server_hash":null,"server_timestamp":"1785130365161","session_id":"502006c5cfcd437296561ea750c9ec8b","source":"clob_market_ws"},"received_at":"2026-07-27T05:32:45.122851Z","record_id":"24b7aa7e658a47a1796db625abb8da9a7ec6003cbddb07419ef40be6435a1140","schema_fingerprint":"4aa3821a28b0b7c2400bc59aba4bcc0a76e971dadd19610d3ad38c768e124dc7","schema_version":"edge-lab-recorder.raw.v1","sequence":null,"source":"clob_market_ws"}
{"event_at":"2026-07-27T05:32:45.172000Z","event_fingerprint":"5a18705372c1710e64f77f34ad39585859990786783645e700db2f90a9bf0dbe","payload":{"connection_id":"efc69d3132f1467b8e898a382b23ac0d","event_at":"2026-07-27T05:32:45.172000Z","event_type":"price_change","frame_hash":"b3b621c1ce2c620634b9e9fe8069b9232e371ca73d904c49ce705906ae2b801e","frame_index":0,"kind":"data","monotonic_ns":232348372385500,"payload":{"event_type":"price_change","market":"0x3b40066b5cf3871a2f6237c5628bd8092a206aa998558ac5ec13c4483e31e160","price_changes":[{"asset_id":"110216635572655435074987471276357323571387854733835379371586402147734167783946","best_ask":"0.48","best_bid":"0.47","hash":"6e32ab8950ef29fb7a368850d79f2bfafc1fa500","price":"0.44","side":"BUY","size":"44.4"},{"asset_id":"14766054693214075530629349735273995982307625376442606753688071083149620216746","best_ask":"0.53","best_bid":"0.52","hash":"7ea06f74f32ff8872fe601e39ebf4ed299020623","price":"0.56","side":"SELL","size":"44.4"}],"timestamp":"1785130365172"},"payload_hash":"a33373a25047fdaa03fbf58a8a6df7e1ae7fbfde9cd9eb8fea5233d8954c881f","raw_frame":"{\"market\":\"0x3b40066b5cf3871a2f6237c5628bd8092a206aa998558ac5ec13c4483e31e160\", \"price_changes\":[{\"asset_id\":\"110216635572655435074987471276357323571387854733835379371586402147734167783946\", \"price\":\"0.44\", \"size\":\"44.4\", \"side\":\"BUY\", \"hash\":\"6e32ab8950ef29fb7a368850d79f2bfafc1fa500\", \"best_bid\":\"0.47\", \"best_ask\":\"0.48\"}, {\"asset_id\":\"14766054693214075530629349735273995982307625376442606753688071083149620216746\", \"price\":\"0.56\", \"size\":\"44.4\", \"side\":\"SELL\", \"hash\":\"7ea06f74f32ff8872fe601e39ebf4ed299020623\", \"best_bid\":\"0.52\", \"best_ask\":\"0.53\"}], \"timestamp\":\"1785130365172\", \"event_type\":\"price_change\"}","received_at":"2026-07-27T05:32:45.135323Z","schema_version":"clob-market-ws.price_change.v1","sequence":null,"server_hash":null,"server_timestamp":"1785130365172","session_id":"502006c5cfcd437296561ea750c9ec8b","source":"clob_market_ws"},"received_at":"2026-07-27T05:32:45.135323Z","record_id":"558c8b819114da39ebb3d54a0681e051277199f8e49b6c5231c8632296a7d2a7","schema_fingerprint":"4aa3821a28b0b7c2400bc59aba4bcc0a76e971dadd19610d3ad38c768e124dc7","schema_version":"edge-lab-recorder.raw.v1","sequence":null,"source":"clob_market_ws"}
{"event_at":"2026-07-27T05:32:45.175000Z","event_fingerprint":"43e3f8ea745a06dcc30a50bc6ae148e145c1e5968fb4b36d3aeab494af8bb8c1","payload":{"connection_id":"efc69d3132f1467b8e898a382b23ac0d","event_at":"2026-07-27T05:32:45.175000Z","event_type":"price_change","frame_hash":"ed7723f6682cf49b188efa7251eabfba2bc7dff7fa1f5a1db6712fb56b79f12f","frame_index":0,"kind":"data","monotonic_ns":232348375266208,"payload":{"event_type":"price_change","market":"0x3b40066b5cf3871a2f6237c5628bd8092a206aa998558ac5ec13c4483e31e160","price_changes":[{"asset_id":"110216635572655435074987471276357323571387854733835379371586402147734167783946","best_ask":"0.48","best_bid":"0.47","hash":"fc3a4ac51a4b370d4237e651bc6079e24a4f97e0","price":"0.42","side":"BUY","size":"80.28"},{"asset_id":"14766054693214075530629349735273995982307625376442606753688071083149620216746","best_ask":"0.53","best_bid":"0.52","hash":"6f847b36eb7510b2931b8af253892d03b78dc61e","price":"0.58","side":"SELL","size":"80.28"}],"timestamp":"1785130365175"},"payload_hash":"a2c2b9aeeedad16949eb62d8566ef5e590b3c48761adf71908b4e5abae972a1c","raw_frame":"{\"market\":\"0x3b40066b5cf3871a2f6237c5628bd8092a206aa998558ac5ec13c4483e31e160\", \"price_changes\":[{\"asset_id\":\"110216635572655435074987471276357323571387854733835379371586402147734167783946\", \"price\":\"0.42\", \"size\":\"80.28\", \"side\":\"BUY\", \"hash\":\"fc3a4ac51a4b370d4237e651bc6079e24a4f97e0\", \"best_bid\":\"0.47\", \"best_ask\":\"0.48\"}, {\"asset_id\":\"14766054693214075530629349735273995982307625376442606753688071083149620216746\", \"price\":\"0.58\", \"size\":\"80.28\", \"side\":\"SELL\", \"hash\":\"6f847b36eb7510b2931b8af253892d03b78dc61e\", \"best_bid\":\"0.52\", \"best_ask\":\"0.53\"}], \"timestamp\":\"1785130365175\", \"event_type\":\"price_change\"}","received_at":"2026-07-27T05:32:45.138200Z","schema_version":"clob-market-ws.price_change.v1","sequence":null,"server_hash":null,"server_timestamp":"1785130365175","session_id":"502006c5cfcd437296561ea750c9ec8b","source":"clob_market_ws"},"received_at":"2026-07-27T05:32:45.138200Z","record_id":"f668bc00953f03b520bad89a4a0a6d8b926124f95b5a54fdc595d96263fa9334","schema_fingerprint":"4aa3821a28b0b7c2400bc59aba4bcc0a76e971dadd19610d3ad38c768e124dc7","schema_version":"edge-lab-recorder.raw.v1","sequence":null,"source":"clob_market_ws"}
{"event_at":"2026-07-27T05:32:45.181000Z","event_fingerprint":"db8e21914969c0d6cd0d857c64d2b4ea1327b82b365f9c34144ecc0cf05e039e","payload":{"connection_id":"efc69d3132f1467b8e898a382b23ac0d","event_at":"2026-07-27T05:32:45.181000Z","event_type":"price_change","frame_hash":"b73b5249d412a78b43ac14b39c00c22a9e399c9fc23b5495cd355dcd2a016f9a","frame_index":0,"kind":"data","monotonic_ns":232348379537583,"payload":{"event_type":"price_change","market":"0x3b40066b5cf3871a2f6237c5628bd8092a206aa998558ac5ec13c4483e31e160","price_changes":[{"asset_id":"110216635572655435074987471276357323571387854733835379371586402147734167783946","best_ask":"0.48","best_bid":"0.47","hash":"2964d8d1cad70538831e7cb04c272eed230b5e66","price":"0.43","side":"BUY","size":"58.21"},{"asset_id":"14766054693214075530629349735273995982307625376442606753688071083149620216746","best_ask":"0.53","best_bid":"0.52","hash":"4ac498202fdb78a81b887d849c33c40c52a01855","price":"0.57","side":"SELL","size":"58.21"}],"timestamp":"1785130365181"},"payload_hash":"1eaf0b0421aaa0c219e14489dd867c31e0aaecab5a1e19bd37bf0eab3962493b","raw_frame":"{\"market\":\"0x3b40066b5cf3871a2f6237c5628bd8092a206aa998558ac5ec13c4483e31e160\", \"price_changes\":[{\"asset_id\":\"110216635572655435074987471276357323571387854733835379371586402147734167783946\", \"price\":\"0.43\", \"size\":\"58.21\", \"side\":\"BUY\", \"hash\":\"2964d8d1cad70538831e7cb04c272eed230b5e66\", \"best_bid\":\"0.47\", \"best_ask\":\"0.48\"}, {\"asset_id\":\"14766054693214075530629349735273995982307625376442606753688071083149620216746\", \"price\":\"0.57\", \"size\":\"58.21\", \"side\":\"SELL\", \"hash\":\"4ac498202fdb78a81b887d849c33c40c52a01855\", \"best_bid\":\"0.52\", \"best_ask\":\"0.53\"}], \"timestamp\":\"1785130365181\", \"event_type\":\"price_change\"}","received_at":"2026-07-27T05:32:45.142475Z","schema_version":"clob-market-ws.price_change.v1","sequence":null,"server_hash":null,"server_timestamp":"1785130365181","session_id":"502006c5cfcd437296561ea750c9ec8b","source":"clob_market_ws"},"received_at":"2026-07-27T05:32:45.142475Z","record_id":"2368cbdc2706b077752bb37c5e4e63f99eabbc1547114600b1979cb236571ac5","schema_fingerprint":"4aa3821a28b0b7c2400bc59aba4bcc0a76e971dadd19610d3ad38c768e124dc7","schema_version":"edge-lab-recorder.raw.v1","sequence":null,"source":"clob_market_ws"}
{"event_at":"2026-07-27T05:32:45.212000Z","event_fingerprint":"a96fc3f6619cecb3692acfb880e7bc3d190ec18f430e62d8905dd2dd7c36bb61","payload":{"connection_id":"efc69d3132f1467b8e898a382b23ac0d","event_at":"2026-07-27T05:32:45.212000Z","event_type":"price_change","frame_hash":"5794ab2abc84fee78f916bc17d8824422e8ab7516deabd5dc73b56d073923e5e","frame_index":0,"kind":"data","monotonic_ns":232348410227541,"payload":{"event_type":"price_change","market":"0x3b40066b5cf3871a2f6237c5628bd8092a206aa998558ac5ec13c4483e31e160","price_changes":[{"asset_id":"14766054693214075530629349735273995982307625376442606753688071083149620216746","best_ask":"0.53","best_bid":"0.52","hash":"90c0985fc17e32b8ba9fde6160d038a5d1e3bbce","price":"0.03","side":"BUY","size":"613.1"},{"asset_id":"110216635572655435074987471276357323571387854733835379371586402147734167783946","best_ask":"0.48","best_bid":"0.47","hash":"a92860608f3446ba97c8f3e8ceb9814cdc0f1625","price":"0.97","side":"SELL","size":"613.1"}],"timestamp":"1785130365212"},"payload_hash":"ee4e5d1b858c04f2ae1595681262e2144d7f5181f72e5d12dda2837368ca2f90","raw_frame":"{\"market\":\"0x3b40066b5cf3871a2f6237c5628bd8092a206aa998558ac5ec13c4483e31e160\", \"price_changes\":[{\"asset_id\":\"14766054693214075530629349735273995982307625376442606753688071083149620216746\", \"price\":\"0.03\", \"size\":\"613.1\", \"side\":\"BUY\", \"hash\":\"90c0985fc17e32b8ba9fde6160d038a5d1e3bbce\", \"best_bid\":\"0.52\", \"best_ask\":\"0.53\"}, {\"asset_id\":\"110216635572655435074987471276357323571387854733835379371586402147734167783946\", \"price\":\"0.97\", \"size\":\"613.1\", \"side\":\"SELL\", \"hash\":\"a92860608f3446ba97c8f3e8ceb9814cdc0f1625\", \"best_bid\":\"0.47\", \"best_ask\":\"0.48\"}], \"timestamp\":\"1785130365212\", \"event_type\":\"price_change\"}","received_at":"2026-07-27T05:32:45.173164Z","schema_version":"clob-market-ws.price_change.v1","sequence":null,"server_hash":null,"server_timestamp":"1785130365212","session_id":"502006c5cfcd437296561ea750c9ec8b","source":"clob_market_ws"},"received_at":"2026-07-27T05:32:45.173164Z","record_id":"422ee2820bf03be016d28d6fa81ebf2764c58a9e16ace3483af21c83ca6d0d3f","schema_fingerprint":"4aa3821a28b0b7c2400bc59aba4bcc0a76e971dadd19610d3ad38c768e124dc7","schema_version":"edge-lab-recorder.raw.v1","sequence":null,"source":"clob_market_ws"}
{"event_at":"2026-07-27T05:32:45.252000Z","event_fingerprint":"630c06a3f53bc774cf4b3b1a0f0d88e6e45282e17ae8b65e6aab02e5499f6d60","payload":{"connection_id":"efc69d3132f1467b8e898a382b23ac0d","event_at":"2026-07-27T05:32:45.252000Z","event_type":"price_change","frame_hash":"935652f7f5b680bb29196b9fd5935f04afe8aec8b141c7d6d8574a32b9ae50b8","frame_index":0,"kind":"data","monotonic_ns":232348448035541,"payload":{"event_type":"price_change","market":"0x3b40066b5cf3871a2f6237c5628bd8092a206aa998558ac5ec13c4483e31e160","price_changes":[{"asset_id":"14766054693214075530629349735273995982307625376442606753688071083149620216746","best_ask":"0.53","best_bid":"0.52","hash":"0dbc3fe728b2c859d7409e5b2ad25ff091ffbbb4","price":"0.01","side":"BUY","size":"7878.02"},{"asset_id":"110216635572655435074987471276357323571387854733835379371586402147734167783946","best_ask":"0.48","best_bid":"0.47","hash":"c91b77c237e2e1352d21132bcf9962a178c4150b","price":"0.99","side":"SELL","size":"7878.02"}],"timestamp":"1785130365252"},"payload_hash":"d96c6eaa8814acb29e13e828a0b71cc2f403b67c2a2aa4b9b97fe5ab59e8f7e4","raw_frame":"{\"market\":\"0x3b40066b5cf3871a2f6237c5628bd8092a206aa998558ac5ec13c4483e31e160\", \"price_changes\":[{\"asset_id\":\"14766054693214075530629349735273995982307625376442606753688071083149620216746\", \"price\":\"0.01\", \"size\":\"7878.02\", \"side\":\"BUY\", \"hash\":\"0dbc3fe728b2c859d7409e5b2ad25ff091ffbbb4\", \"best_bid\":\"0.52\", \"best_ask\":\"0.53\"}, {\"asset_id\":\"110216635572655435074987471276357323571387854733835379371586402147734167783946\", \"price\":\"0.99\", \"size\":\"7878.02\", \"side\":\"SELL\", \"hash\":\"c91b77c237e2e1352d21132bcf9962a178c4150b\", \"best_bid\":\"0.47\", \"best_ask\":\"0.48\"}], \"timestamp\":\"1785130365252\", \"event_type\":\"price_change\"}","received_at":"2026-07-27T05:32:45.210971Z","schema_version":"clob-market-ws.price_change.v1","sequence":null,"server_hash":null,"server_timestamp":"1785130365252","session_id":"502006c5cfcd437296561ea750c9ec8b","source":"clob_market_ws"},"received_at":"2026-07-27T05:32:45.210971Z","record_id":"4af696f29c2d91455da8e3985b1b9aaa730330b415f7e8a72259bd3db81cb406","schema_fingerprint":"4aa3821a28b0b7c2400bc59aba4bcc0a76e971dadd19610d3ad38c768e124dc7","schema_version":"edge-lab-recorder.raw.v1","sequence":null,"source":"clob_market_ws"}
{"event_at":"2026-07-27T05:32:45.273000Z","event_fingerprint":"ed6422856e64a7e275be91eba324e3f1e53acbf914ded59d935bc80c7251a6a1","payload":{"connection_id":"efc69d3132f1467b8e898a382b23ac0d","event_at":"2026-07-27T05:32:45.273000Z","event_type":"price_change","frame_hash":"fed6ed0015d4715ed1cae3a0c1ca56186eac4b31357bb111efbb03683b2db1d7","frame_index":0,"kind":"data","monotonic_ns":232348470623500,"payload":{"event_type":"price_change","market":"0x3b40066b5cf3871a2f6237c5628bd8092a206aa998558ac5ec13c4483e31e160","price_changes":[{"asset_id":"14766054693214075530629349735273995982307625376442606753688071083149620216746","best_ask":"0.53","best_bid":"0.52","hash":"b9cd6b51b0e754f596add76a3b122682fcaa0367","price":"0.01","side":"BUY","size":"7873.02"},{"asset_id":"110216635572655435074987471276357323571387854733835379371586402147734167783946","best_ask":"0.48","best_bid":"0.47","hash":"5c618cd4c871b5652bba60215f59035a0a12eda7","price":"0.99","side":"SELL","size":"7873.02"}],"timestamp":"1785130365273"},"payload_hash":"0f798c7d80ea4a4499ea4f64a374a583281b6865c908d65252d6b3ca26a9eccd","raw_frame":"{\"market\":\"0x3b40066b5cf3871a2f6237c5628bd8092a206aa998558ac5ec13c4483e31e160\", \"price_changes\":[{\"asset_id\":\"14766054693214075530629349735273995982307625376442606753688071083149620216746\", \"price\":\"0.01\", \"size\":\"7873.02\", \"side\":\"BUY\", \"hash\":\"b9cd6b51b0e754f596add76a3b122682fcaa0367\", \"best_bid\":\"0.52\", \"best_ask\":\"0.53\"}, {\"asset_id\":\"110216635572655435074987471276357323571387854733835379371586402147734167783946\", \"price\":\"0.99\", \"size\":\"7873.02\", \"side\":\"SELL\", \"hash\":\"5c618cd4c871b5652bba60215f59035a0a12eda7\", \"best_bid\":\"0.47\", \"best_ask\":\"0.48\"}], \"timestamp\":\"1785130365273\", \"event_type\":\"price_change\"}","received_at":"2026-07-27T05:32:45.233561Z","schema_version":"clob-market-ws.price_change.v1","sequence":null,"server_hash":null,"server_timestamp":"1785130365273","session_id":"502006c5cfcd437296561ea750c9ec8b","source":"clob_market_ws"},"received_at":"2026-07-27T05:32:45.233561Z","record_id":"20aef8c9b0c4099953289d79b569d7b66e8e6a1360b2c82098d335e9b0512653","schema_fingerprint":"4aa3821a28b0b7c2400bc59aba4bcc0a76e971dadd19610d3ad38c768e124dc7","schema_version":"edge-lab-recorder.raw.v1","sequence":null,"source":"clob_market_ws"}
{"event_at":"2026-07-27T05:32:45.283000Z","event_fingerprint":"7ba282b4425b9505ba34ccd0843db1bad86becca921abe6ffc426f3888099fe1","payload":{"connection_id":"efc69d3132f1467b8e898a382b23ac0d","event_at":"2026-07-27T05:32:45.283000Z","event_type":"price_change","frame_hash":"146c6b261c2ff40affbb8dd2211a298b8dd1eda624d3bc3ce3bb152ee63e84be","frame_index":0,"kind":"data","monotonic_ns":232348482436458,"payload":{"event_type":"price_change","market":"0x3b40066b5cf3871a2f6237c5628bd8092a206aa998558ac5ec13c4483e31e160","price_changes":[{"asset_id":"110216635572655435074987471276357323571387854733835379371586402147734167783946","best_ask":"0.48","best_bid":"0.47","hash":"defda2365ac9181f9f86dae6247edb38dfa79d7d","price":"0.43","side":"BUY","size":"50.21"},{"asset_id":"14766054693214075530629349735273995982307625376442606753688071083149620216746","best_ask":"0.53","best_bid":"0.52","hash":"9f77498cf7013bdc54ada2f9a93849f268061e9b","price":"0.57","side":"SELL","size":"50.21"}],"timestamp":"1785130365283"},"payload_hash":"16e4dd03866e9eb33a859e7afba250f322a57e750d5e2eb208772a42848e5895","raw_frame":"{\"market\":\"0x3b40066b5cf3871a2f6237c5628bd8092a206aa998558ac5ec13c4483e31e160\", \"price_changes\":[{\"asset_id\":\"110216635572655435074987471276357323571387854733835379371586402147734167783946\", \"price\":\"0.43\", \"size\":\"50.21\", \"side\":\"BUY\", \"hash\":\"defda2365ac9181f9f86dae6247edb38dfa79d7d\", \"best_bid\":\"0.47\", \"best_ask\":\"0.48\"}, {\"asset_id\":\"14766054693214075530629349735273995982307625376442606753688071083149620216746\", \"price\":\"0.57\", \"size\":\"50.21\", \"side\":\"SELL\", \"hash\":\"9f77498cf7013bdc54ada2f9a93849f268061e9b\", \"best_bid\":\"0.52\", \"best_ask\":\"0.53\"}], \"timestamp\":\"1785130365283\", \"event_type\":\"price_change\"}","received_at":"2026-07-27T05:32:45.245375Z","schema_version":"clob-market-ws.price_change.v1","sequence":null,"server_hash":null,"server_timestamp":"1785130365283","session_id":"502006c5cfcd437296561ea750c9ec8b","source":"clob_market_ws"},"received_at":"2026-07-27T05:32:45.245375Z","record_id":"7ba8a5f28ddc7a03137b7f2c54fde61476a632b40dd65550011aee241ba564bb","schema_fingerprint":"4aa3821a28b0b7c2400bc59aba4bcc0a76e971dadd19610d3ad38c768e124dc7","schema_version":"edge-lab-recorder.raw.v1","sequence":null,"source":"clob_market_ws"}
{"event_at":"2026-07-27T05:32:45.294000Z","event_fingerprint":"0eb19ce4fae5f0e7aa6952dc6ef733b89a7f8f54d8ddbfdc2120bbe6d2409f48","payload":{"connection_id":"efc69d3132f1467b8e898a382b23ac0d","event_at":"2026-07-27T05:32:45.294000Z","event_type":"price_change","frame_hash":"03093e031bf3fcc717983779c108144942a755052834067121b9d561194d0f0f","frame_index":0,"kind":"data","monotonic_ns":232348493901083,"payload":{"event_type":"price_change","market":"0x3b40066b5cf3871a2f6237c5628bd8092a206aa998558ac5ec13c4483e31e160","price_changes":[{"asset_id":"110216635572655435074987471276357323571387854733835379371586402147734167783946","best_ask":"0.48","best_bid":"0.47","hash":"683a5359c495caec84cf60497fe8c2ca65880755","price":"0.32","side":"BUY","size":"465.28"},{"asset_id":"14766054693214075530629349735273995982307625376442606753688071083149620216746","best_ask":"0.53","best_bid":"0.52","hash":"58273cc5d9f6f29a10ab262b7a9f7d44ae1fcd98","price":"0.68","side":"SELL","size":"465.28"}],"timestamp":"1785130365294"},"payload_hash":"46a6592f483faf6781b92e999dd00aaa2bf0cd1a0ad4abfa703b55df7df52062","raw_frame":"{\"market\":\"0x3b40066b5cf3871a2f6237c5628bd8092a206aa998558ac5ec13c4483e31e160\", \"price_changes\":[{\"asset_id\":\"110216635572655435074987471276357323571387854733835379371586402147734167783946\", \"price\":\"0.32\", \"size\":\"465.28\", \"side\":\"BUY\", \"hash\":\"683a5359c495caec84cf60497fe8c2ca65880755\", \"best_bid\":\"0.47\", \"best_ask\":\"0.48\"}, {\"asset_id\":\"14766054693214075530629349735273995982307625376442606753688071083149620216746\", \"price\":\"0.68\", \"size\":\"465.28\", \"side\":\"SELL\", \"hash\":\"58273cc5d9f6f29a10ab262b7a9f7d44ae1fcd98\", \"best_bid\":\"0.52\", \"best_ask\":\"0.53\"}], \"timestamp\":\"1785130365294\", \"event_type\":\"price_change\"}","received_at":"2026-07-27T05:32:45.256840Z","schema_version":"clob-market-ws.price_change.v1","sequence":null,"server_hash":null,"server_timestamp":"1785130365294","session_id":"502006c5cfcd437296561ea750c9ec8b","source":"clob_market_ws"},"received_at":"2026-07-27T05:32:45.256840Z","record_id":"c88147fb58400b1646e4127ef07a28b01fedd2b61407535fcd10668f2268e3e7","schema_fingerprint":"4aa3821a28b0b7c2400bc59aba4bcc0a76e971dadd19610d3ad38c768e124dc7","schema_version":"edge-lab-recorder.raw.v1","sequence":null,"source":"clob_market_ws"}
{"event_at":"2026-07-27T05:32:45.295000Z","event_fingerprint":"ea9363d25ff08eb0c81b7d1d83e8f7253068d88246dbf1fe1f8535e17e0ea55b","payload":{"connection_id":"efc69d3132f1467b8e898a382b23ac0d","event_at":"2026-07-27T05:32:45.295000Z","event_type":"price_change","frame_hash":"4e508a090af8f825006687ab27ba07257dae078dc34177d2d988dd9a4e36de53","frame_index":0,"kind":"data","monotonic_ns":232348497958250,"payload":{"event_type":"price_change","market":"0x3b40066b5cf3871a2f6237c5628bd8092a206aa998558ac5ec13c4483e31e160","price_changes":[{"asset_id":"110216635572655435074987471276357323571387854733835379371586402147734167783946","best_ask":"0.48","best_bid":"0.47","hash":"44125e32261dec013422a7f23a427cc337db1ca3","price":"0.35","side":"BUY","size":"248"},{"asset_id":"14766054693214075530629349735273995982307625376442606753688071083149620216746","best_ask":"0.53","best_bid":"0.52","hash":"b6e41241997fc62301bb12785ed88cc237f81ad8","price":"0.65","side":"SELL","size":"248"}],"timestamp":"1785130365295"},"payload_hash":"e2843208a930de34f86bbfc0643a57be0e6e7f00bb9477b2b9fa19e52cec544b","raw_frame":"{\"market\":\"0x3b40066b5cf3871a2f6237c5628bd8092a206aa998558ac5ec13c4483e31e160\", \"price_changes\":[{\"asset_id\":\"110216635572655435074987471276357323571387854733835379371586402147734167783946\", \"price\":\"0.35\", \"size\":\"248\", \"side\":\"BUY\", \"hash\":\"44125e32261dec013422a7f23a427cc337db1ca3\", \"best_bid\":\"0.47\", \"best_ask\":\"0.48\"}, {\"asset_id\":\"14766054693214075530629349735273995982307625376442606753688071083149620216746\", \"price\":\"0.65\", \"size\":\"248\", \"side\":\"SELL\", \"hash\":\"b6e41241997fc62301bb12785ed88cc237f81ad8\", \"best_bid\":\"0.52\", \"best_ask\":\"0.53\"}], \"timestamp\":\"1785130365295\", \"event_type\":\"price_change\"}","received_at":"2026-07-27T05:32:45.260897Z","schema_version":"clob-market-ws.price_change.v1","sequence":null,"server_hash":null,"server_timestamp":"1785130365295","session_id":"502006c5cfcd437296561ea750c9ec8b","source":"clob_market_ws"},"received_at":"2026-07-27T05:32:45.260897Z","record_id":"0fe14ad04dfb8ee653debc61168a76bc59742fe63cb68ada4d1a987b38b422d7","schema_fingerprint":"4aa3821a28b0b7c2400bc59aba4bcc0a76e971dadd19610d3ad38c768e124dc7","schema_version":"edge-lab-recorder.raw.v1","sequence":null,"source":"clob_market_ws"}
{"event_at":"2026-07-27T05:32:45.296000Z","event_fingerprint":"a05b3edec88eef141defcb0ce59cd35dc4442095d3b35c370944c7e2ed71c320","payload":{"connection_id":"efc69d3132f1467b8e898a382b23ac0d","event_at":"2026-07-27T05:32:45.296000Z","event_type":"price_change","frame_hash":"606b7131ccc63f5dacf455438724fe50dd6111e943093f7e5296f5157c248654","frame_index":0,"kind":"data","monotonic_ns":232348500259208,"payload":{"event_type":"price_change","market":"0x3b40066b5cf3871a2f6237c5628bd8092a206aa998558ac5ec13c4483e31e160","price_changes":[{"asset_id":"110216635572655435074987471276357323571387854733835379371586402147734167783946","best_ask":"0.48","best_bid":"0.47","hash":"fa30fc6072a4c62c934a45d83ad1b26e99d0d712","price":"0.33","side":"BUY","size":"187.6"},{"asset_id":"14766054693214075530629349735273995982307625376442606753688071083149620216746","best_ask":"0.53","best_bid":"0.52","hash":"e3c625fef30276d4325a6f315be2e9a02de6502a","price":"0.67","side":"SELL","size":"187.6"}],"timestamp":"1785130365296"},"payload_hash":"9fbf5d9f172f511744badb413b7fa70111002289ebc64e0c521db1dc2ced0aa8","raw_frame":"{\"market\":\"0x3b40066b5cf3871a2f6237c5628bd8092a206aa998558ac5ec13c4483e31e160\", \"price_changes\":[{\"asset_id\":\"110216635572655435074987471276357323571387854733835379371586402147734167783946\", \"price\":\"0.33\", \"size\":\"187.6\", \"side\":\"BUY\", \"hash\":\"fa30fc6072a4c62c934a45d83ad1b26e99d0d712\", \"best_bid\":\"0.47\", \"best_ask\":\"0.48\"}, {\"asset_id\":\"14766054693214075530629349735273995982307625376442606753688071083149620216746\", \"price\":\"0.67\", \"size\":\"187.6\", \"side\":\"SELL\", \"hash\":\"e3c625fef30276d4325a6f315be2e9a02de6502a\", \"best_bid\":\"0.52\", \"best_ask\":\"0.53\"}], \"timestamp\":\"1785130365296\", \"event_type\":\"price_change\"}","received_at":"2026-07-27T05:32:45.263199Z","schema_version":"clob-market-ws.price_change.v1","sequence":null,"server_hash":null,"server_timestamp":"1785130365296","session_id":"502006c5cfcd437296561ea750c9ec8b","source":"clob_market_ws"},"received_at":"2026-07-27T05:32:45.263199Z","record_id":"79104a894c454c6a94890dc59bdd042b0554268350c053e65181da0d18119a01","schema_fingerprint":"4aa3821a28b0b7c2400bc59aba4bcc0a76e971dadd19610d3ad38c768e124dc7","schema_version":"edge-lab-recorder.raw.v1","sequence":null,"source":"clob_market_ws"}
{"event_at":"2026-07-27T05:32:45.297000Z","event_fingerprint":"a99ba528f6bb526e28534a240da3f08492e1da7ff13e6833245f1e0cdfc6a3ac","payload":{"connection_id":"efc69d3132f1467b8e898a382b23ac0d","event_at":"2026-07-27T05:32:45.297000Z","event_type":"price_change","frame_hash":"78c2cb752907b6fc1c94b262c40979497643259d25195569a47b10c2f671f504","frame_index":0,"kind":"data","monotonic_ns":232348502468333,"payload":{"event_type":"price_change","market":"0x3b40066b5cf3871a2f6237c5628bd8092a206aa998558ac5ec13c4483e31e160","price_changes":[{"asset_id":"14766054693214075530629349735273995982307625376442606753688071083149620216746","best_ask":"0.53","best_bid":"0.52","hash":"0984987e627037ba0c505e83b8c6ac4064c27868","price":"0.42","side":"BUY","size":"146"},{"asset_id":"110216635572655435074987471276357323571387854733835379371586402147734167783946","best_ask":"0.48","best_bid":"0.47","hash":"68a159770f66f8a51527cc57c7a6ffb53cb16786","price":"0.58","side":"SELL","size":"146"}],"timestamp":"1785130365297"},"payload_hash":"7698da95f8634335161be8c1d9a361d858871d7e0974ed20477f51d2914f8cf7","raw_frame":"{\"market\":\"0x3b40066b5cf3871a2f6237c5628bd8092a206aa998558ac5ec13c4483e31e160\", \"price_changes\":[{\"asset_id\":\"14766054693214075530629349735273995982307625376442606753688071083149620216746\", \"price\":\"0.42\", \"size\":\"146\", \"side\":\"BUY\", \"hash\":\"0984987e627037ba0c505e83b8c6ac4064c27868\", \"best_bid\":\"0.52\", \"best_ask\":\"0.53\"}, {\"asset_id\":\"110216635572655435074987471276357323571387854733835379371586402147734167783946\", \"price\":\"0.58\", \"size\":\"146\", \"side\":\"SELL\", \"hash\":\"68a159770f66f8a51527cc57c7a6ffb53cb16786\", \"best_bid\":\"0.47\", \"best_ask\":\"0.48\"}], \"timestamp\":\"1785130365297\", \"event_type\":\"price_change\"}","received_at":"2026-07-27T05:32:45.265407Z","schema_version":"clob-market-ws.price_change.v1","sequence":null,"server_hash":null,"server_timestamp":"1785130365297","session_id":"502006c5cfcd437296561ea750c9ec8b","source":"clob_market_ws"},"received_at":"2026-07-27T05:32:45.265407Z","record_id":"39d188c92de0e854d20abd867ad0c3b1b7d8639428b9fb68dfb28ccf1f55163a","schema_fingerprint":"4aa3821a28b0b7c2400bc59aba4bcc0a76e971dadd19610d3ad38c768e124dc7","schema_version":"edge-lab-recorder.raw.v1","sequence":null,"source":"clob_market_ws"}
{"event_at":"2026-07-27T05:32:45.297000Z","event_fingerprint":"4f9e16f29a985a7a835c44dfc24c22be7fdcfbf7e227ae74b2658ea5b0b254b6","payload":{"connection_id":"efc69d3132f1467b8e898a382b23ac0d","event_at":"2026-07-27T05:32:45.297000Z","event_type":"price_change","frame_hash":"25080fcc3cbcc8b7d10e20f4146c3a92cd5edfe79cbd81a679b4113d0e5d2caa","frame_index":0,"kind":"data","monotonic_ns":232348506856166,"payload":{"event_type":"price_change","market":"0x3b40066b5cf3871a2f6237c5628bd8092a206aa998558ac5ec13c4483e31e160","price_changes":[{"asset_id":"110216635572655435074987471276357323571387854733835379371586402147734167783946","best_ask":"0.48","best_bid":"0.47","hash":"fadba643c068484b0696068ba22a4f8dcd5bd916","price":"0.42","side":"BUY","size":"88.28"},{"asset_id":"14766054693214075530629349735273995982307625376442606753688071083149620216746","best_ask":"0.53","best_bid":"0.52","hash":"15da3acf7bfd941583ae8d84f0da72f2e218222b","price":"0.58","side":"SELL","size":"88.28"}],"timestamp":"1785130365297"},"payload_hash":"705d7a9e99731f38989f1a06b13c100932d253d5f4f930bf956f87bdf21f7413","raw_frame":"{\"market\":\"0x3b40066b5cf3871a2f6237c5628bd8092a206aa998558ac5ec13c4483e31e160\", \"price_changes\":[{\"asset_id\":\"110216635572655435074987471276357323571387854733835379371586402147734167783946\", \"price\":\"0.42\", \"size\":\"88.28\", \"side\":\"BUY\", \"hash\":\"fadba643c068484b0696068ba22a4f8dcd5bd916\", \"best_bid\":\"0.47\", \"best_ask\":\"0.48\"}, {\"asset_id\":\"14766054693214075530629349735273995982307625376442606753688071083149620216746\", \"price\":\"0.58\", \"size\":\"88.28\", \"side\":\"SELL\", \"hash\":\"15da3acf7bfd941583ae8d84f0da72f2e218222b\", \"best_bid\":\"0.52\", \"best_ask\":\"0.53\"}], \"timestamp\":\"1785130365297\", \"event_type\":\"price_change\"}","received_at":"2026-07-27T05:32:45.269795Z","schema_version":"clob-market-ws.price_change.v1","sequence":null,"server_hash":null,"server_timestamp":"1785130365297","session_id":"502006c5cfcd437296561ea750c9ec8b","source":"clob_market_ws"},"received_at":"2026-07-27T05:32:45.269795Z","record_id":"253b46d0909930c314a455fdf14c907c76cf7015cc36725b522678cd7861d8de","schema_fingerprint":"4aa3821a28b0b7c2400bc59aba4bcc0a76e971dadd19610d3ad38c768e124dc7","schema_version":"edge-lab-recorder.raw.v1","sequence":null,"source":"clob_market_ws"}
{"event_at":null,"event_fingerprint":"902d9d8669c7d8c09ebb8e4e144750aa1d2c05c7f3510fb04e39a3ff86858bed","payload":{"connection_id":"efc69d3132f1467b8e898a382b23ac0d","detail":{"interval_seconds":10.0,"message":"PING"},"event_type":"heartbeat","kind":"lifecycle","monotonic_ns":232348509111541,"received_at":"2026-07-27T05:32:45.272049Z","schema_version":"edge-lab-recorder.lifecycle.v1","session_id":"502006c5cfcd437296561ea750c9ec8b","source":"clob_market_ws"},"received_at":"2026-07-27T05:32:45.272049Z","record_id":"f38469fdf037819306ea208f9f3e85175d2418166b26f2b550aa192efb8360d8","schema_fingerprint":"cb8aa3aa4cb168a4b724fd9077bee6ecfb9bc586c57cfdf0ab89f00d82045e3c","schema_version":"edge-lab-recorder.raw.v1","sequence":null,"source":"clob_market_ws"}
{"event_at":"2026-07-27T05:32:45.298000Z","event_fingerprint":"6421c11c53450eedce7343c1ec80a52ae9f9bef7963eb0049109d81e4722f306","payload":{"connection_id":"efc69d3132f1467b8e898a382b23ac0d","event_at":"2026-07-27T05:32:45.298000Z","event_type":"price_change","frame_hash":"2927a6dbaf9406cab376a1df7d0f60e5652d7abb3e9bb42f3136a609c854de8d","frame_index":0,"kind":"data","monotonic_ns":232348510935500,"payload":{"event_type":"price_change","market":"0x3b40066b5cf3871a2f6237c5628bd8092a206aa998558ac5ec13c4483e31e160","price_changes":[{"asset_id":"110216635572655435074987471276357323571387854733835379371586402147734167783946","best_ask":"0.48","best_bid":"0.47","hash":"539de86bfdf9f5d878718f5640902cb1c59e5d5d","price":"0.36","side":"BUY","size":"168"},{"asset_id":"14766054693214075530629349735273995982307625376442606753688071083149620216746","best_ask":"0.53","best_bid":"0.52","hash":"f9b56bbaf9f4fa7bba578f02f749c8130e70fbf3","price":"0.64","side":"SELL","size":"168"}],"timestamp":"1785130365298"},"payload_hash":"d1efd29d89ae0a352f12f205d0df62e1e8597be833e1b998f3786a3e1b0f250c","raw_frame":"{\"market\":\"0x3b40066b5cf3871a2f6237c5628bd8092a206aa998558ac5ec13c4483e31e160\", \"price_changes\":[{\"asset_id\":\"110216635572655435074987471276357323571387854733835379371586402147734167783946\", \"price\":\"0.36\", \"size\":\"168\", \"side\":\"BUY\", \"hash\":\"539de86bfdf9f5d878718f5640902cb1c59e5d5d\", \"best_bid\":\"0.47\", \"best_ask\":\"0.48\"}, {\"asset_id\":\"14766054693214075530629349735273995982307625376442606753688071083149620216746\", \"price\":\"0.64\", \"size\":\"168\", \"side\":\"SELL\", \"hash\":\"f9b56bbaf9f4fa7bba578f02f749c8130e70fbf3\", \"best_bid\":\"0.52\", \"best_ask\":\"0.53\"}], \"timestamp\":\"1785130365298\", \"event_type\":\"price_change\"}","received_at":"2026-07-27T05:32:45.273873Z","schema_version":"clob-market-ws.price_change.v1","sequence":null,"server_hash":null,"server_timestamp":"1785130365298","session_id":"502006c5cfcd437296561ea750c9ec8b","source":"clob_market_ws"},"received_at":"2026-07-27T05:32:45.273873Z","record_id":"17cd741b127a836983d3ec5ced4e185a93f9a4445b1603bdbaa26789649c9d8f","schema_fingerprint":"4aa3821a28b0b7c2400bc59aba4bcc0a76e971dadd19610d3ad38c768e124dc7","schema_version":"edge-lab-recorder.raw.v1","sequence":null,"source":"clob_market_ws"}
{"event_at":"2026-07-27T05:32:45.299000Z","event_fingerprint":"1fae40b2ba081b3aaf3da2a56fbad735ff15b1286959e1be0a0949ee96db5e1f","payload":{"connection_id":"efc69d3132f1467b8e898a382b23ac0d","event_at":"2026-07-27T05:32:45.299000Z","event_type":"price_change","frame_hash":"89781a37a8d5059539b5e4c2538fd07c5f3041d9325b8b64598eb59b6b816a2b","frame_index":0,"kind":"data","monotonic_ns":232348517126166,"payload":{"event_type":"price_change","market":"0x3b40066b5cf3871a2f6237c5628bd8092a206aa998558ac5ec13c4483e31e160","price_changes":[{"asset_id":"110216635572655435074987471276357323571387854733835379371586402147734167783946","best_ask":"0.48","best_bid":"0.47","hash":"9cb11873d688cf10c67e3d6f89d1601025b12b11","price":"0.44","side":"BUY","size":"49.4"},{"asset_id":"14766054693214075530629349735273995982307625376442606753688071083149620216746","best_ask":"0.53","best_bid":"0.52","hash":"1ecc5b3f8b1fcb195bf626ceb668e134f3fb3812","price":"0.56","side":"SELL","size":"49.4"}],"timestamp":"1785130365299"},"payload_hash":"0eca4f77cbbc7781d46569b686e037714192c55546c40fb1632c1e93191fe593","raw_frame":"{\"market\":\"0x3b40066b5cf3871a2f6237c5628bd8092a206aa998558ac5ec13c4483e31e160\", \"price_changes\":[{\"asset_id\":\"110216635572655435074987471276357323571387854733835379371586402147734167783946\", \"price\":\"0.44\", \"size\":\"49.4\", \"side\":\"BUY\", \"hash\":\"9cb11873d688cf10c67e3d6f89d1601025b12b11\", \"best_bid\":\"0.47\", \"best_ask\":\"0.48\"}, {\"asset_id\":\"14766054693214075530629349735273995982307625376442606753688071083149620216746\", \"price\":\"0.56\", \"size\":\"49.4\", \"side\":\"SELL\", \"hash\":\"1ecc5b3f8b1fcb195bf626ceb668e134f3fb3812\", \"best_bid\":\"0.52\", \"best_ask\":\"0.53\"}], \"timestamp\":\"1785130365299\", \"event_type\":\"price_change\"}","received_at":"2026-07-27T05:32:45.280065Z","schema_version":"clob-market-ws.price_change.v1","sequence":null,"server_hash":null,"server_timestamp":"1785130365299","session_id":"502006c5cfcd437296561ea750c9ec8b","source":"clob_market_ws"},"received_at":"2026-07-27T05:32:45.280065Z","record_id":"6777239602118e069b8e83cc6d794effcf27db3050a43648057f6d9e2f593309","schema_fingerprint":"4aa3821a28b0b7c2400bc59aba4bcc0a76e971dadd19610d3ad38c768e124dc7","schema_version":"edge-lab-recorder.raw.v1","sequence":null,"source":"clob_market_ws"}
{"event_at":"2026-07-27T05:32:45.300000Z","event_fingerprint":"8dfda0f1078657826f76e351c1b1892f357226b4efb0963a668565451838748b","payload":{"connection_id":"efc69d3132f1467b8e898a382b23ac0d","event_at":"2026-07-27T05:32:45.300000Z","event_type":"price_change","frame_hash":"63629c3607e41a559a454281568ceda255f29b1975d242d83b459243406d802b","frame_index":0,"kind":"data","monotonic_ns":232348518361833,"payload":{"event_type":"price_change","market":"0x3b40066b5cf3871a2f6237c5628bd8092a206aa998558ac5ec13c4483e31e160","price_changes":[{"asset_id":"110216635572655435074987471276357323571387854733835379371586402147734167783946","best_ask":"0.48","best_bid":"0.47","hash":"fe68ddbdf6b89f437e4313ba48cb055ef04da5e7","price":"0.34","side":"BUY","size":"179"},{"asset_id":"14766054693214075530629349735273995982307625376442606753688071083149620216746","best_ask":"0.53","best_bid":"0.52","hash":"74acdecf038497c1f40c02f6de2d5f43f3ad43c7","price":"0.66","side":"SELL","size":"179"}],"timestamp":"1785130365300"},"payload_hash":"3b6204a0c23b1673ae1837568d434d1441cc7436840ddcc28ca8a23c5abba5af","raw_frame":"{\"market\":\"0x3b40066b5cf3871a2f6237c5628bd8092a206aa998558ac5ec13c4483e31e160\", \"price_changes\":[{\"asset_id\":\"110216635572655435074987471276357323571387854733835379371586402147734167783946\", \"price\":\"0.34\", \"size\":\"179\", \"side\":\"BUY\", \"hash\":\"fe68ddbdf6b89f437e4313ba48cb055ef04da5e7\", \"best_bid\":\"0.47\", \"best_ask\":\"0.48\"}, {\"asset_id\":\"14766054693214075530629349735273995982307625376442606753688071083149620216746\", \"price\":\"0.66\", \"size\":\"179\", \"side\":\"SELL\", \"hash\":\"74acdecf038497c1f40c02f6de2d5f43f3ad43c7\", \"best_bid\":\"0.52\", \"best_ask\":\"0.53\"}], \"timestamp\":\"1785130365300\", \"event_type\":\"price_change\"}","received_at":"2026-07-27T05:32:45.281301Z","schema_version":"clob-market-ws.price_change.v1","sequence":null,"server_hash":null,"server_timestamp":"1785130365300","session_id":"502006c5cfcd437296561ea750c9ec8b","source":"clob_market_ws"},"received_at":"2026-07-27T05:32:45.281301Z","record_id":"d0017152279a4b06fe0ab89e0bb92a8faef240f032b96a66ef0171587c151ee9","schema_fingerprint":"4aa3821a28b0b7c2400bc59aba4bcc0a76e971dadd19610d3ad38c768e124dc7","schema_version":"edge-lab-recorder.raw.v1","sequence":null,"source":"clob_market_ws"}
{"event_at":"2026-07-27T05:32:45.303000Z","event_fingerprint":"36f26168c7123c6063b8eeb8f1c6a8a2ca9fa27c097cf1fe6ada92b3d94529c3","payload":{"connection_id":"efc69d3132f1467b8e898a382b23ac0d","event_at":"2026-07-27T05:32:45.303000Z","event_type":"price_change","frame_hash":"85b5d8ed13e58847f095c2b131ad9c21079fc06f9b04fab626a87807e8b4b66b","frame_index":0,"kind":"data","monotonic_ns":232348519638541,"payload":{"event_type":"price_change","market":"0x3b40066b5cf3871a2f6237c5628bd8092a206aa998558ac5ec13c4483e31e160","price_changes":[{"asset_id":"14766054693214075530629349735273995982307625376442606753688071083149620216746","best_ask":"0.53","best_bid":"0.52","hash":"96fe745b7d67521a333f0c712490edea6735e349","price":"0.02","side":"BUY","size":"728.1"},{"asset_id":"110216635572655435074987471276357323571387854733835379371586402147734167783946","best_ask":"0.48","best_bid":"0.47","hash":"017c7ae7667f44c41f2fe838f5e71f69584f9b9c","price":"0.98","side":"SELL","size":"728.1"}],"timestamp":"1785130365303"},"payload_hash":"ea9eab538996d61cfa540646f03b354450ba5e4643b8ce2002d68c86d8185515","raw_frame":"{\"market\":\"0x3b40066b5cf3871a2f6237c5628bd8092a206aa998558ac5ec13c4483e31e160\", \"price_changes\":[{\"asset_id\":\"14766054693214075530629349735273995982307625376442606753688071083149620216746\", \"price\":\"0.02\", \"size\":\"728.1\", \"side\":\"BUY\", \"hash\":\"96fe745b7d67521a333f0c712490edea6735e349\", \"best_bid\":\"0.52\", \"best_ask\":\"0.53\"}, {\"asset_id\":\"110216635572655435074987471276357323571387854733835379371586402147734167783946\", \"price\":\"0.98\", \"size\":\"728.1\", \"side\":\"SELL\", \"hash\":\"017c7ae7667f44c41f2fe838f5e71f69584f9b9c\", \"best_bid\":\"0.47\", \"best_ask\":\"0.48\"}], \"timestamp\":\"1785130365303\", \"event_type\":\"price_change\"}","received_at":"2026-07-27T05:32:45.282583Z","schema_version":"clob-market-ws.price_change.v1","sequence":null,"server_hash":null,"server_timestamp":"1785130365303","session_id":"502006c5cfcd437296561ea750c9ec8b","source":"clob_market_ws"},"received_at":"2026-07-27T05:32:45.282583Z","record_id":"621af1f945060f5751532006eed2c60a6f0514bf69b6f57d73268a8ca6646116","schema_fingerprint":"4aa3821a28b0b7c2400bc59aba4bcc0a76e971dadd19610d3ad38c768e124dc7","schema_version":"edge-lab-recorder.raw.v1","sequence":null,"source":"clob_market_ws"}
{"event_at":"2026-07-27T05:32:45.357000Z","event_fingerprint":"659dfb7b3862fb290083b2f244de5b8c01d5a1f467869324034c66e152235eb2","payload":{"connection_id":"efc69d3132f1467b8e898a382b23ac0d","event_at":"2026-07-27T05:32:45.357000Z","event_type":"price_change","frame_hash":"869afbe6f526cabf3007f317db6d4f037deddc058b2aa1052ca44ed606f8f493","frame_index":0,"kind":"data","monotonic_ns":232348555394458,"payload":{"event_type":"price_change","market":"0x3b40066b5cf3871a2f6237c5628bd8092a206aa998558ac5ec13c4483e31e160","price_changes":[{"asset_id":"14766054693214075530629349735273995982307625376442606753688071083149620216746","best_ask":"0.53","best_bid":"0.52","hash":"6f063143554a9f63d205f41ecd92d76014bc33b8","price":"0.02","side":"BUY","size":"723.1"},{"asset_id":"110216635572655435074987471276357323571387854733835379371586402147734167783946","best_ask":"0.48","best_bid":"0.47","hash":"4a0b02d4294624eeb332652a5076f4ae3ad5b6c2","price":"0.98","side":"SELL","size":"723.1"}],"timestamp":"1785130365357"},"payload_hash":"61c0a76952e3534b559064574a0909336d58bf01b9a7ed09df7669eba3647e17","raw_frame":"{\"market\":\"0x3b40066b5cf3871a2f6237c5628bd8092a206aa998558ac5ec13c4483e31e160\", \"price_changes\":[{\"asset_id\":\"14766054693214075530629349735273995982307625376442606753688071083149620216746\", \"price\":\"0.02\", \"size\":\"723.1\", \"side\":\"BUY\", \"hash\":\"6f063143554a9f63d205f41ecd92d76014bc33b8\", \"best_bid\":\"0.52\", \"best_ask\":\"0.53\"}, {\"asset_id\":\"110216635572655435074987471276357323571387854733835379371586402147734167783946\", \"price\":\"0.98\", \"size\":\"723.1\", \"side\":\"SELL\", \"hash\":\"4a0b02d4294624eeb332652a5076f4ae3ad5b6c2\", \"best_bid\":\"0.47\", \"best_ask\":\"0.48\"}], \"timestamp\":\"1785130365357\", \"event_type\":\"price_change\"}","received_at":"2026-07-27T05:32:45.318334Z","schema_version":"clob-market-ws.price_change.v1","sequence":null,"server_hash":null,"server_timestamp":"1785130365357","session_id":"502006c5cfcd437296561ea750c9ec8b","source":"clob_market_ws"},"received_at":"2026-07-27T05:32:45.318334Z","record_id":"ca684ee0970e577361d69d11f2975f79abffed885a09f1db1dd0fed3c4315449","schema_fingerprint":"4aa3821a28b0b7c2400bc59aba4bcc0a76e971dadd19610d3ad38c768e124dc7","schema_version":"edge-lab-recorder.raw.v1","sequence":null,"source":"clob_market_ws"}
{"event_at":"2026-07-27T05:32:45.359000Z","event_fingerprint":"d05a0f20c69a4dfbc01876a423c86aa27dbaf8a923e09b87a49dcf4de06fb0e7","payload":{"connection_id":"efc69d3132f1467b8e898a382b23ac0d","event_at":"2026-07-27T05:32:45.359000Z","event_type":"price_change","frame_hash":"ea971491678e1bb96199bc6e5547cc6462a15ed8d6d04568897bef48eb2d9293","frame_index":0,"kind":"data","monotonic_ns":232348559962708,"payload":{"event_type":"price_change","market":"0x3b40066b5cf3871a2f6237c5628bd8092a206aa998558ac5ec13c4483e31e160","price_changes":[{"asset_id":"14766054693214075530629349735273995982307625376442606753688071083149620216746","best_ask":"0.53","best_bid":"0.52","hash":"69b6cc874c26571b03724a8567b7937487aad2d6","price":"0.01","side":"BUY","size":"7878.02"},{"asset_id":"110216635572655435074987471276357323571387854733835379371586402147734167783946","best_ask":"0.48","best_bid":"0.47","hash":"f037bf694e6a211dc6f4f7282a1fe72f1ede47db","price":"0.99","side":"SELL","size":"7878.02"}],"timestamp":"1785130365359"},"payload_hash":"c1f9cafa5872541afdb20f873b55b3ab89f022957e49df5b3143edc51f4184b3","raw_frame":"{\"market\":\"0x3b40066b5cf3871a2f6237c5628bd8092a206aa998558ac5ec13c4483e31e160\", \"price_changes\":[{\"asset_id\":\"14766054693214075530629349735273995982307625376442606753688071083149620216746\", \"price\":\"0.01\", \"size\":\"7878.02\", \"side\":\"BUY\", \"hash\":\"69b6cc874c26571b03724a8567b7937487aad2d6\", \"best_bid\":\"0.52\", \"best_ask\":\"0.53\"}, {\"asset_id\":\"110216635572655435074987471276357323571387854733835379371586402147734167783946\", \"price\":\"0.99\", \"size\":\"7878.02\", \"side\":\"SELL\", \"hash\":\"f037bf694e6a211dc6f4f7282a1fe72f1ede47db\", \"best_bid\":\"0.47\", \"best_ask\":\"0.48\"}], \"timestamp\":\"1785130365359\", \"event_type\":\"price_change\"}","received_at":"2026-07-27T05:32:45.322902Z","schema_version":"clob-market-ws.price_change.v1","sequence":null,"server_hash":null,"server_timestamp":"1785130365359","session_id":"502006c5cfcd437296561ea750c9ec8b","source":"clob_market_ws"},"received_at":"2026-07-27T05:32:45.322902Z","record_id":"62c07ea03e83921616740e081f460afb7b81018c3a2017c1b00b8e1c6e1c988c","schema_fingerprint":"4aa3821a28b0b7c2400bc59aba4bcc0a76e971dadd19610d3ad38c768e124dc7","schema_version":"edge-lab-recorder.raw.v1","sequence":null,"source":"clob_market_ws"}
{"event_at":"2026-07-27T05:32:45.385000Z","event_fingerprint":"009873d7cc49b21871f97910f990831a4feed42b00956d7fe70f008fb8f1daa4","payload":{"connection_id":"efc69d3132f1467b8e898a382b23ac0d","event_at":"2026-07-27T05:32:45.385000Z","event_type":"price_change","frame_hash":"868727d09a09036bea08a6a4ff240cfeef698c7e2f5d9936f9b408a4c368e73c","frame_index":0,"kind":"data","monotonic_ns":232348582856500,"payload":{"event_type":"price_change","market":"0x3b40066b5cf3871a2f6237c5628bd8092a206aa998558ac5ec13c4483e31e160","price_changes":[{"asset_id":"14766054693214075530629349735273995982307625376442606753688071083149620216746","best_ask":"0.53","best_bid":"0.52","hash":"48e88da373916225827ce0b70541f9558e57c07a","price":"0.01","side":"BUY","size":"7873.02"},{"asset_id":"110216635572655435074987471276357323571387854733835379371586402147734167783946","best_ask":"0.48","best_bid":"0.47","hash":"a89e6f0f9d18f132aa40023207b3cfc6ce2a0429","price":"0.99","side":"SELL","size":"7873.02"}],"timestamp":"1785130365385"},"payload_hash":"004910cc5a698eee61938ee9d7185165b22baeac4292d9a343f4b8d1330b8cbe","raw_frame":"{\"market\":\"0x3b40066b5cf3871a2f6237c5628bd8092a206aa998558ac5ec13c4483e31e160\", \"price_changes\":[{\"asset_id\":\"14766054693214075530629349735273995982307625376442606753688071083149620216746\", \"price\":\"0.01\", \"size\":\"7873.02\", \"side\":\"BUY\", \"hash\":\"48e88da373916225827ce0b70541f9558e57c07a\", \"best_bid\":\"0.52\", \"best_ask\":\"0.53\"}, {\"asset_id\":\"110216635572655435074987471276357323571387854733835379371586402147734167783946\", \"price\":\"0.99\", \"size\":\"7873.02\", \"side\":\"SELL\", \"hash\":\"a89e6f0f9d18f132aa40023207b3cfc6ce2a0429\", \"best_bid\":\"0.47\", \"best_ask\":\"0.48\"}], \"timestamp\":\"1785130365385\", \"event_type\":\"price_change\"}","received_at":"2026-07-27T05:32:45.345795Z","schema_version":"clob-market-ws.price_change.v1","sequence":null,"server_hash":null,"server_timestamp":"1785130365385","session_id":"502006c5cfcd437296561ea750c9ec8b","source":"clob_market_ws"},"received_at":"2026-07-27T05:32:45.345795Z","record_id":"2d3db0a9482087f4cd2648266688015b589dad63fe5f8f7802b0ef1ba9b034f8","schema_fingerprint":"4aa3821a28b0b7c2400bc59aba4bcc0a76e971dadd19610d3ad38c768e124dc7","schema_version":"edge-lab-recorder.raw.v1","sequence":null,"source":"clob_market_ws"}
{"event_at":"2026-07-27T05:32:45.421000Z","event_fingerprint":"95a3b9adfd5f6c7cc95cb5d03949d08296dc242257ea3170873eaa86d42c887c","payload":{"connection_id":"efc69d3132f1467b8e898a382b23ac0d","event_at":"2026-07-27T05:32:45.421000Z","event_type":"price_change","frame_hash":"c3cdb2fedcd445f1bd15a98fb7f28c415fb69ff22481dc675ef0b67c32a43b50","frame_index":0,"kind":"data","monotonic_ns":232348624120625,"payload":{"event_type":"price_change","market":"0x3b40066b5cf3871a2f6237c5628bd8092a206aa998558ac5ec13c4483e31e160","price_changes":[{"asset_id":"110216635572655435074987471276357323571387854733835379371586402147734167783946","best_ask":"0.48","best_bid":"0.47","hash":"fb837e4f785bbb01ab088faaeab1bfc1aff2ee31","price":"0.42","side":"BUY","size":"80.28"},{"asset_id":"14766054693214075530629349735273995982307625376442606753688071083149620216746","best_ask":"0.53","best_bid":"0.52","hash":"92f842153cf22fb1e99727c65ec0eebe34c13d10","price":"0.58","side":"SELL","size":"80.28"}],"timestamp":"1785130365421"},"payload_hash":"ea5b6f01187919a4c2674a28e210f0f16fa064797bcd5518b0b16bf539fd17c0","raw_frame":"{\"market\":\"0x3b40066b5cf3871a2f6237c5628bd8092a206aa998558ac5ec13c4483e31e160\", \"price_changes\":[{\"asset_id\":\"110216635572655435074987471276357323571387854733835379371586402147734167783946\", \"price\":\"0.42\", \"size\":\"80.28\", \"side\":\"BUY\", \"hash\":\"fb837e4f785bbb01ab088faaeab1bfc1aff2ee31\", \"best_bid\":\"0.47\", \"best_ask\":\"0.48\"}, {\"asset_id\":\"14766054693214075530629349735273995982307625376442606753688071083149620216746\", \"price\":\"0.58\", \"size\":\"80.28\", \"side\":\"SELL\", \"hash\":\"92f842153cf22fb1e99727c65ec0eebe34c13d10\", \"best_bid\":\"0.52\", \"best_ask\":\"0.53\"}], \"timestamp\":\"1785130365421\", \"event_type\":\"price_change\"}","received_at":"2026-07-27T05:32:45.387054Z","schema_version":"clob-market-ws.price_change.v1","sequence":null,"server_hash":null,"server_timestamp":"1785130365421","session_id":"502006c5cfcd437296561ea750c9ec8b","source":"clob_market_ws"},"received_at":"2026-07-27T05:32:45.387054Z","record_id":"90b467d0f7caff31230f71d33ed07990ef972085a988fd11ebe12988289a9661","schema_fingerprint":"4aa3821a28b0b7c2400bc59aba4bcc0a76e971dadd19610d3ad38c768e124dc7","schema_version":"edge-lab-recorder.raw.v1","sequence":null,"source":"clob_market_ws"}
{"event_at":"2026-07-27T05:32:45.427000Z","event_fingerprint":"6368244f087444699eff93d56653dada86691776b2efb188fcb312e1871d192e","payload":{"connection_id":"efc69d3132f1467b8e898a382b23ac0d","event_at":"2026-07-27T05:32:45.427000Z","event_type":"price_change","frame_hash":"e649e9187854491023ed57109642f252baf7a0a67925546189408feca11e22d1","frame_index":0,"kind":"data","monotonic_ns":232348627297250,"payload":{"event_type":"price_change","market":"0x3b40066b5cf3871a2f6237c5628bd8092a206aa998558ac5ec13c4483e31e160","price_changes":[{"asset_id":"110216635572655435074987471276357323571387854733835379371586402147734167783946","best_ask":"0.48","best_bid":"0.47","hash":"0dde40ef3dd4b7055fb5f0616cda996aa4ddc998","price":"0.44","side":"BUY","size":"44.4"},{"asset_id":"14766054693214075530629349735273995982307625376442606753688071083149620216746","best_ask":"0.53","best_bid":"0.52","hash":"c3eee68abfcf9a261fb44aa77b9f3004038f76c5","price":"0.56","side":"SELL","size":"44.4"}],"timestamp":"1785130365427"},"payload_hash":"19f95440cb35512d1ced23da73c4b87358fde81bc431f14493306c277e6c3bb4","raw_frame":"{\"market\":\"0x3b40066b5cf3871a2f6237c5628bd8092a206aa998558ac5ec13c4483e31e160\", \"price_changes\":[{\"asset_id\":\"110216635572655435074987471276357323571387854733835379371586402147734167783946\", \"price\":\"0.44\", \"size\":\"44.4\", \"side\":\"BUY\", \"hash\":\"0dde40ef3dd4b7055fb5f0616cda996aa4ddc998\", \"best_bid\":\"0.47\", \"best_ask\":\"0.48\"}, {\"asset_id\":\"14766054693214075530629349735273995982307625376442606753688071083149620216746\", \"price\":\"0.56\", \"size\":\"44.4\", \"side\":\"SELL\", \"hash\":\"c3eee68abfcf9a261fb44aa77b9f3004038f76c5\", \"best_bid\":\"0.52\", \"best_ask\":\"0.53\"}], \"timestamp\":\"1785130365427\", \"event_type\":\"price_change\"}","received_at":"2026-07-27T05:32:45.390235Z","schema_version":"clob-market-ws.price_change.v1","sequence":null,"server_hash":null,"server_timestamp":"1785130365427","session_id":"502006c5cfcd437296561ea750c9ec8b","source":"clob_market_ws"},"received_at":"2026-07-27T05:32:45.390235Z","record_id":"9c37ef05eed88fb07ad1debd6a7efd7c4855926717beb9b16eb7135933ec00d7","schema_fingerprint":"4aa3821a28b0b7c2400bc59aba4bcc0a76e971dadd19610d3ad38c768e124dc7","schema_version":"edge-lab-recorder.raw.v1","sequence":null,"source":"clob_market_ws"}
{"event_at":"2026-07-27T05:32:45.429000Z","event_fingerprint":"ef013a14178c18d90dd1041fdc1831f214b9f09628d1185dbfe40ab341fe3138","payload":{"connection_id":"efc69d3132f1467b8e898a382b23ac0d","event_at":"2026-07-27T05:32:45.429000Z","event_type":"price_change","frame_hash":"282d0315c16a735859464a7f1e10a53f7c57f8656804ad7833ea38e1671f9f8c","frame_index":0,"kind":"data","monotonic_ns":232348630633041,"payload":{"event_type":"price_change","market":"0x3b40066b5cf3871a2f6237c5628bd8092a206aa998558ac5ec13c4483e31e160","price_changes":[{"asset_id":"110216635572655435074987471276357323571387854733835379371586402147734167783946","best_ask":"0.48","best_bid":"0.47","hash":"aced00e3539a76522b4c3c21719ab2823ccd35bf","price":"0.43","side":"BUY","size":"58.21"},{"asset_id":"14766054693214075530629349735273995982307625376442606753688071083149620216746","best_ask":"0.53","best_bid":"0.52","hash":"c621fa79b97e76c730fc5dbff3b113fab2fa6edc","price":"0.57","side":"SELL","size":"58.21"}],"timestamp":"1785130365429"},"payload_hash":"3aadc0160acb19bcef5c8848be184b19b405b1d564fcc10c40a63c54e9f47c3c","raw_frame":"{\"market\":\"0x3b40066b5cf3871a2f6237c5628bd8092a206aa998558ac5ec13c4483e31e160\", \"price_changes\":[{\"asset_id\":\"110216635572655435074987471276357323571387854733835379371586402147734167783946\", \"price\":\"0.43\", \"size\":\"58.21\", \"side\":\"BUY\", \"hash\":\"aced00e3539a76522b4c3c21719ab2823ccd35bf\", \"best_bid\":\"0.47\", \"best_ask\":\"0.48\"}, {\"asset_id\":\"14766054693214075530629349735273995982307625376442606753688071083149620216746\", \"price\":\"0.57\", \"size\":\"58.21\", \"side\":\"SELL\", \"hash\":\"c621fa79b97e76c730fc5dbff3b113fab2fa6edc\", \"best_bid\":\"0.52\", \"best_ask\":\"0.53\"}], \"timestamp\":\"1785130365429\", \"event_type\":\"price_change\"}","received_at":"2026-07-27T05:32:45.393571Z","schema_version":"clob-market-ws.price_change.v1","sequence":null,"server_hash":null,"server_timestamp":"1785130365429","session_id":"502006c5cfcd437296561ea750c9ec8b","source":"clob_market_ws"},"received_at":"2026-07-27T05:32:45.393571Z","record_id":"8d1713439507e37bb67bb8b5b79ae7663a4a9b89a724f1f703f6e40732be78f1","schema_fingerprint":"4aa3821a28b0b7c2400bc59aba4bcc0a76e971dadd19610d3ad38c768e124dc7","schema_version":"edge-lab-recorder.raw.v1","sequence":null,"source":"clob_market_ws"}
{"event_at":"2026-07-27T05:32:45.449000Z","event_fingerprint":"3006746dfed757ba7d375de9cddfb0115dbe2af467e43d81f80b6f319ded31e9","payload":{"connection_id":"efc69d3132f1467b8e898a382b23ac0d","event_at":"2026-07-27T05:32:45.449000Z","event_type":"price_change","frame_hash":"110130ebec6de5851f2ca9ddb35ae409068c1aa35adb0591546750171c3dc9db","frame_index":0,"kind":"data","monotonic_ns":232348647239333,"payload":{"event_type":"price_change","market":"0x3b40066b5cf3871a2f6237c5628bd8092a206aa998558ac5ec13c4483e31e160","price_changes":[{"asset_id":"14766054693214075530629349735273995982307625376442606753688071083149620216746","best_ask":"0.53","best_bid":"0.52","hash":"b58fce931b62891c2777fe6eccfe4de0fbbf4f97","price":"0.03","side":"BUY","size":"618.1"},{"asset_id":"110216635572655435074987471276357323571387854733835379371586402147734167783946","best_ask":"0.48","best_bid":"0.47","hash":"cd67b27f2a3e6b0892d6100fe779ed50abfd6a66","price":"0.97","side":"SELL","size":"618.1"}],"timestamp":"1785130365449"},"payload_hash":"9fd54e9795c8bf5613e3d4492cb1056c3f188cba4214b878f49c55d3296c106a","raw_frame":"{\"market\":\"0x3b40066b5cf3871a2f6237c5628bd8092a206aa998558ac5ec13c4483e31e160\", \"price_changes\":[{\"asset_id\":\"14766054693214075530629349735273995982307625376442606753688071083149620216746\", \"price\":\"0.03\", \"size\":\"618.1\", \"side\":\"BUY\", \"hash\":\"b58fce931b62891c2777fe6eccfe4de0fbbf4f97\", \"best_bid\":\"0.52\", \"best_ask\":\"0.53\"}, {\"asset_id\":\"110216635572655435074987471276357323571387854733835379371586402147734167783946\", \"price\":\"0.97\", \"size\":\"618.1\", \"side\":\"SELL\", \"hash\":\"cd67b27f2a3e6b0892d6100fe779ed50abfd6a66\", \"best_bid\":\"0.47\", \"best_ask\":\"0.48\"}], \"timestamp\":\"1785130365449\", \"event_type\":\"price_change\"}","received_at":"2026-07-27T05:32:45.410178Z","schema_version":"clob-market-ws.price_change.v1","sequence":null,"server_hash":null,"server_timestamp":"1785130365449","session_id":"502006c5cfcd437296561ea750c9ec8b","source":"clob_market_ws"},"received_at":"2026-07-27T05:32:45.410178Z","record_id":"03d545ac1cbdf0b4aab9210b2a63a1b4554d90970c339d0b6684e8eb17ed2696","schema_fingerprint":"4aa3821a28b0b7c2400bc59aba4bcc0a76e971dadd19610d3ad38c768e124dc7","schema_version":"edge-lab-recorder.raw.v1","sequence":null,"source":"clob_market_ws"}
{"event_at":null,"event_fingerprint":"d5e16fcedc1ae96b62dea9af273d1600590e966f504a9049b93066c152c92633","payload":{"connection_id":"efc69d3132f1467b8e898a382b23ac0d","event_type":"heartbeat_ack","frame_hash":"95784973cc639977bff93619700168505cb8f7855e44fa643d34622a43706c87","kind":"lifecycle","monotonic_ns":232348709852958,"raw_frame":"PONG","received_at":"2026-07-27T05:32:45.472791Z","schema_version":"edge-lab-recorder.heartbeat-ack.v1","session_id":"502006c5cfcd437296561ea750c9ec8b","source":"clob_market_ws"},"received_at":"2026-07-27T05:32:45.472791Z","record_id":"862753c012a7beac061c16d74850b1f66028a5bb0af2bbbdb07bbf98489ffe7b","schema_fingerprint":"c14ee1aab3ca674ee738e5268877b544d74c41ad3c427cedc09236467dc68ba1","schema_version":"edge-lab-recorder.raw.v1","sequence":null,"source":"clob_market_ws"}
{"event_at":"2026-07-27T05:32:45.551000Z","event_fingerprint":"7fdd157c938a46fcf147f11f43e78a940990b1ab9c62a9451947b3b52f542307","payload":{"connection_id":"efc69d3132f1467b8e898a382b23ac0d","event_at":"2026-07-27T05:32:45.551000Z","event_type":"price_change","frame_hash":"404bec1f5adc6514bc106b44f0217817b2651709b51e259219566531b45f833b","frame_index":0,"kind":"data","monotonic_ns":232348749649583,"payload":{"event_type":"price_change","market":"0x3b40066b5cf3871a2f6237c5628bd8092a206aa998558ac5ec13c4483e31e160","price_changes":[{"asset_id":"14766054693214075530629349735273995982307625376442606753688071083149620216746","best_ask":"0.53","best_bid":"0.52","hash":"4760b76ec9e662e17fe02abb85b77e70ef50c4d9","price":"0.67","side":"SELL","size":"192.6"},{"asset_id":"110216635572655435074987471276357323571387854733835379371586402147734167783946","best_ask":"0.48","best_bid":"0.47","hash":"d42a3da758df130a055b5f25af8e9cbb56b398d2","price":"0.33","side":"BUY","size":"192.6"}],"timestamp":"1785130365551"},"payload_hash":"bbd10dc9ef869b198ca53e005fe3b915da081978f8c4d8858c8be9ae5c17cd4e","raw_frame":"{\"market\":\"0x3b40066b5cf3871a2f6237c5628bd8092a206aa998558ac5ec13c4483e31e160\", \"price_changes\":[{\"asset_id\":\"14766054693214075530629349735273995982307625376442606753688071083149620216746\", \"price\":\"0.67\", \"size\":\"192.6\", \"side\":\"SELL\", \"hash\":\"4760b76ec9e662e17fe02abb85b77e70ef50c4d9\", \"best_bid\":\"0.52\", \"best_ask\":\"0.53\"}, {\"asset_id\":\"110216635572655435074987471276357323571387854733835379371586402147734167783946\", \"price\":\"0.33\", \"size\":\"192.6\", \"side\":\"BUY\", \"hash\":\"d42a3da758df130a055b5f25af8e9cbb56b398d2\", \"best_bid\":\"0.47\", \"best_ask\":\"0.48\"}], \"timestamp\":\"1785130365551\", \"event_type\":\"price_change\"}","received_at":"2026-07-27T05:32:45.512589Z","schema_version":"clob-market-ws.price_change.v1","sequence":null,"server_hash":null,"server_timestamp":"1785130365551","session_id":"502006c5cfcd437296561ea750c9ec8b","source":"clob_market_ws"},"received_at":"2026-07-27T05:32:45.512589Z","record_id":"da546f98f4599c612519df54826a15b4e73497b943616d06f5295fe82f75e4ad","schema_fingerprint":"4aa3821a28b0b7c2400bc59aba4bcc0a76e971dadd19610d3ad38c768e124dc7","schema_version":"edge-lab-recorder.raw.v1","sequence":null,"source":"clob_market_ws"}
{"event_at":"2026-07-27T05:32:45.556000Z","event_fingerprint":"5cff4422ada55aed4ff04acc21c887cba3a845359e024d9f172ccf7bbb92eb8c","payload":{"connection_id":"efc69d3132f1467b8e898a382b23ac0d","event_at":"2026-07-27T05:32:45.556000Z","event_type":"price_change","frame_hash":"af6c838f1de8de7832de185359c07610c441c47f75c3147d2116f75eb3b884d4","frame_index":0,"kind":"data","monotonic_ns":232348753685458,"payload":{"event_type":"price_change","market":"0x3b40066b5cf3871a2f6237c5628bd8092a206aa998558ac5ec13c4483e31e160","price_changes":[{"asset_id":"14766054693214075530629349735273995982307625376442606753688071083149620216746","best_ask":"0.53","best_bid":"0.52","hash":"9b7e7b532281b833576c709b9eb2548fd6d51c10","price":"0.03","side":"BUY","size":"613.1"},{"asset_id":"110216635572655435074987471276357323571387854733835379371586402147734167783946","best_ask":"0.48","best_bid":"0.47","hash":"6dcdab083563d91f4092f10f1e07d8338c38f2c7","price":"0.97","side":"SELL","size":"613.1"}],"timestamp":"1785130365556"},"payload_hash":"240bb9a9b7139d900b477bf9b83517c8c1b48b68ee781587898441b3886ae4bc","raw_frame":"{\"market\":\"0x3b40066b5cf3871a2f6237c5628bd8092a206aa998558ac5ec13c4483e31e160\", \"price_changes\":[{\"asset_id\":\"14766054693214075530629349735273995982307625376442606753688071083149620216746\", \"price\":\"0.03\", \"size\":\"613.1\", \"side\":\"BUY\", \"hash\":\"9b7e7b532281b833576c709b9eb2548fd6d51c10\", \"best_bid\":\"0.52\", \"best_ask\":\"0.53\"}, {\"asset_id\":\"110216635572655435074987471276357323571387854733835379371586402147734167783946\", \"price\":\"0.97\", \"size\":\"613.1\", \"side\":\"SELL\", \"hash\":\"6dcdab083563d91f4092f10f1e07d8338c38f2c7\", \"best_bid\":\"0.47\", \"best_ask\":\"0.48\"}], \"timestamp\":\"1785130365556\", \"event_type\":\"price_change\"}","received_at":"2026-07-27T05:32:45.516625Z","schema_version":"clob-market-ws.price_change.v1","sequence":null,"server_hash":null,"server_timestamp":"1785130365556","session_id":"502006c5cfcd437296561ea750c9ec8b","source":"clob_market_ws"},"received_at":"2026-07-27T05:32:45.516625Z","record_id":"f7b6ae693965efc847f9b5154648607e6a9c8746a158823637e67fdfa054f572","schema_fingerprint":"4aa3821a28b0b7c2400bc59aba4bcc0a76e971dadd19610d3ad38c768e124dc7","schema_version":"edge-lab-recorder.raw.v1","sequence":null,"source":"clob_market_ws"}
{"event_at":"2026-07-27T05:32:45.653000Z","event_fingerprint":"7bbe43dbe6702a0fb4fe05a2f1cae351edc84fa022758bb883871c75a74c3206","payload":{"connection_id":"efc69d3132f1467b8e898a382b23ac0d","event_at":"2026-07-27T05:32:45.653000Z","event_type":"price_change","frame_hash":"fe778f9da1c8768c1c83cba48ff4cef3fe5bb4765d7fcce2b46b934bb3dc39f9","frame_index":0,"kind":"data","monotonic_ns":232348850772000,"payload":{"event_type":"price_change","market":"0x3b40066b5cf3871a2f6237c5628bd8092a206aa998558ac5ec13c4483e31e160","price_changes":[{"asset_id":"14766054693214075530629349735273995982307625376442606753688071083149620216746","best_ask":"0.53","best_bid":"0.52","hash":"5cd4f245ff6adb5de6ff91bbcd0a30dd28888fce","price":"0.01","side":"BUY","size":"7878.02"},{"asset_id":"110216635572655435074987471276357323571387854733835379371586402147734167783946","best_ask":"0.48","best_bid":"0.47","hash":"b12f230f620391bb729e0ba7423a3af2b694ea48","price":"0.99","side":"SELL","size":"7878.02"}],"timestamp":"1785130365653"},"payload_hash":"dfb812b24ed1aa949f0c5a917aa1b7377cc7a919f91782908fddf33eddc03fb1","raw_frame":"{\"market\":\"0x3b40066b5cf3871a2f6237c5628bd8092a206aa998558ac5ec13c4483e31e160\", \"price_changes\":[{\"asset_id\":\"14766054693214075530629349735273995982307625376442606753688071083149620216746\", \"price\":\"0.01\", \"size\":\"7878.02\", \"side\":\"BUY\", \"hash\":\"5cd4f245ff6adb5de6ff91bbcd0a30dd28888fce\", \"best_bid\":\"0.52\", \"best_ask\":\"0.53\"}, {\"asset_id\":\"110216635572655435074987471276357323571387854733835379371586402147734167783946\", \"price\":\"0.99\", \"size\":\"7878.02\", \"side\":\"SELL\", \"hash\":\"b12f230f620391bb729e0ba7423a3af2b694ea48\", \"best_bid\":\"0.47\", \"best_ask\":\"0.48\"}], \"timestamp\":\"1785130365653\", \"event_type\":\"price_change\"}","received_at":"2026-07-27T05:32:45.613719Z","schema_version":"clob-market-ws.price_change.v1","sequence":null,"server_hash":null,"server_timestamp":"1785130365653","session_id":"502006c5cfcd437296561ea750c9ec8b","source":"clob_market_ws"},"received_at":"2026-07-27T05:32:45.613719Z","record_id":"eb1b257eefae439d13baabf8d6bdfedd27fcb6caaaef958424641d868b0f52f8","schema_fingerprint":"4aa3821a28b0b7c2400bc59aba4bcc0a76e971dadd19610d3ad38c768e124dc7","schema_version":"edge-lab-recorder.raw.v1","sequence":null,"source":"clob_market_ws"}
{"event_at":"2026-07-27T05:32:45.659000Z","event_fingerprint":"b8377ce4df43724f70ec43cc40491b1014e0d132b6c080459ae9983613b0dcbd","payload":{"connection_id":"efc69d3132f1467b8e898a382b23ac0d","event_at":"2026-07-27T05:32:45.659000Z","event_type":"price_change","frame_hash":"0326fc77931fcb67b08b65d94f10dc7182a1ed8cb41c21c924d2b1a858ba3b03","frame_index":0,"kind":"data","monotonic_ns":232348856978791,"payload":{"event_type":"price_change","market":"0x3b40066b5cf3871a2f6237c5628bd8092a206aa998558ac5ec13c4483e31e160","price_changes":[{"asset_id":"14766054693214075530629349735273995982307625376442606753688071083149620216746","best_ask":"0.53","best_bid":"0.52","hash":"0e208b0bda7dffac3e866a16d986158b816abebc","price":"0.02","side":"BUY","size":"728.1"},{"asset_id":"110216635572655435074987471276357323571387854733835379371586402147734167783946","best_ask":"0.48","best_bid":"0.47","hash":"c02ddb1fbcafdd40a0220a0c37a34722f3a7b2f0","price":"0.98","side":"SELL","size":"728.1"}],"timestamp":"1785130365659"},"payload_hash":"40df4065ef3519a641f37d83965236b0097f7b7db606c45200a6c5cf7e3a42cb","raw_frame":"{\"market\":\"0x3b40066b5cf3871a2f6237c5628bd8092a206aa998558ac5ec13c4483e31e160\", \"price_changes\":[{\"asset_id\":\"14766054693214075530629349735273995982307625376442606753688071083149620216746\", \"price\":\"0.02\", \"size\":\"728.1\", \"side\":\"BUY\", \"hash\":\"0e208b0bda7dffac3e866a16d986158b816abebc\", \"best_bid\":\"0.52\", \"best_ask\":\"0.53\"}, {\"asset_id\":\"110216635572655435074987471276357323571387854733835379371586402147734167783946\", \"price\":\"0.98\", \"size\":\"728.1\", \"side\":\"SELL\", \"hash\":\"c02ddb1fbcafdd40a0220a0c37a34722f3a7b2f0\", \"best_bid\":\"0.47\", \"best_ask\":\"0.48\"}], \"timestamp\":\"1785130365659\", \"event_type\":\"price_change\"}","received_at":"2026-07-27T05:32:45.619920Z","schema_version":"clob-market-ws.price_change.v1","sequence":null,"server_hash":null,"server_timestamp":"1785130365659","session_id":"502006c5cfcd437296561ea750c9ec8b","source":"clob_market_ws"},"received_at":"2026-07-27T05:32:45.619920Z","record_id":"ca93ededfb398d3a40312bcba725999f93c2068d0737a1425c06c19d1ff3f7bf","schema_fingerprint":"4aa3821a28b0b7c2400bc59aba4bcc0a76e971dadd19610d3ad38c768e124dc7","schema_version":"edge-lab-recorder.raw.v1","sequence":null,"source":"clob_market_ws"}
{"event_at":"2026-07-27T05:32:45.671000Z","event_fingerprint":"89a6c70c983a257559e792027d9dec0372914eb3d6bbac7b3a4804dc7f53b854","payload":{"connection_id":"efc69d3132f1467b8e898a382b23ac0d","event_at":"2026-07-27T05:32:45.671000Z","event_type":"price_change","frame_hash":"e5f641bda09f42fefdacd77644a7a6f38b1a1967e794af3513e9883d1d41ee66","frame_index":0,"kind":"data","monotonic_ns":232348867471041,"payload":{"event_type":"price_change","market":"0x3b40066b5cf3871a2f6237c5628bd8092a206aa998558ac5ec13c4483e31e160","price_changes":[{"asset_id":"14766054693214075530629349735273995982307625376442606753688071083149620216746","best_ask":"0.53","best_bid":"0.52","hash":"b8c9304517154dcbc77c74e6e0c6742b26bd83f6","price":"0.01","side":"BUY","size":"7873.02"},{"asset_id":"110216635572655435074987471276357323571387854733835379371586402147734167783946","best_ask":"0.48","best_bid":"0.47","hash":"95191ecd9202535d5aa27cdb9617a1604bc499d7","price":"0.99","side":"SELL","size":"7873.02"}],"timestamp":"1785130365671"},"payload_hash":"ddff64acf7162b043b87a07899ed0aebd51adad88529c9d308b4d8bd7d8e677d","raw_frame":"{\"market\":\"0x3b40066b5cf3871a2f6237c5628bd8092a206aa998558ac5ec13c4483e31e160\", \"price_changes\":[{\"asset_id\":\"14766054693214075530629349735273995982307625376442606753688071083149620216746\", \"price\":\"0.01\", \"size\":\"7873.02\", \"side\":\"BUY\", \"hash\":\"b8c9304517154dcbc77c74e6e0c6742b26bd83f6\", \"best_bid\":\"0.52\", \"best_ask\":\"0.53\"}, {\"asset_id\":\"110216635572655435074987471276357323571387854733835379371586402147734167783946\", \"price\":\"0.99\", \"size\":\"7873.02\", \"side\":\"SELL\", \"hash\":\"95191ecd9202535d5aa27cdb9617a1604bc499d7\", \"best_bid\":\"0.47\", \"best_ask\":\"0.48\"}], \"timestamp\":\"1785130365671\", \"event_type\":\"price_change\"}","received_at":"2026-07-27T05:32:45.630416Z","schema_version":"clob-market-ws.price_change.v1","sequence":null,"server_hash":null,"server_timestamp":"1785130365671","session_id":"502006c5cfcd437296561ea750c9ec8b","source":"clob_market_ws"},"received_at":"2026-07-27T05:32:45.630416Z","record_id":"360e8e50dd9027deca1ca0491f6776f9f1910a01d965d77c209c35774e4e41fc","schema_fingerprint":"4aa3821a28b0b7c2400bc59aba4bcc0a76e971dadd19610d3ad38c768e124dc7","schema_version":"edge-lab-recorder.raw.v1","sequence":null,"source":"clob_market_ws"}
{"event_at":"2026-07-27T05:32:45.759000Z","event_fingerprint":"d85f4b6957a054fccad1c89a049641ab1d29637000ebee196ed72b24f6401cdf","payload":{"connection_id":"efc69d3132f1467b8e898a382b23ac0d","event_at":"2026-07-27T05:32:45.759000Z","event_type":"price_change","frame_hash":"a6a2c3d2c774bf42198bfd8746add31a61b6bfb7484936c98eb0b4411b0b814f","frame_index":0,"kind":"data","monotonic_ns":232348957973750,"payload":{"event_type":"price_change","market":"0x3b40066b5cf3871a2f6237c5628bd8092a206aa998558ac5ec13c4483e31e160","price_changes":[{"asset_id":"14766054693214075530629349735273995982307625376442606753688071083149620216746","best_ask":"0.53","best_bid":"0.52","hash":"6d28f99209a70cd7a21ee3d6305b6204407226f2","price":"0.02","side":"BUY","size":"723.1"},{"asset_id":"110216635572655435074987471276357323571387854733835379371586402147734167783946","best_ask":"0.48","best_bid":"0.47","hash":"33bdca5c438f3a34302e202932791e730c53262f","price":"0.98","side":"SELL","size":"723.1"}],"timestamp":"1785130365759"},"payload_hash":"8aff964f79888e8224865b1dd1c671107f3fb5554787c7882e99ac5dfae99709","raw_frame":"{\"market\":\"0x3b40066b5cf3871a2f6237c5628bd8092a206aa998558ac5ec13c4483e31e160\", \"price_changes\":[{\"asset_id\":\"14766054693214075530629349735273995982307625376442606753688071083149620216746\", \"price\":\"0.02\", \"size\":\"723.1\", \"side\":\"BUY\", \"hash\":\"6d28f99209a70cd7a21ee3d6305b6204407226f2\", \"best_bid\":\"0.52\", \"best_ask\":\"0.53\"}, {\"asset_id\":\"110216635572655435074987471276357323571387854733835379371586402147734167783946\", \"price\":\"0.98\", \"size\":\"723.1\", \"side\":\"SELL\", \"hash\":\"33bdca5c438f3a34302e202932791e730c53262f\", \"best_bid\":\"0.47\", \"best_ask\":\"0.48\"}], \"timestamp\":\"1785130365759\", \"event_type\":\"price_change\"}","received_at":"2026-07-27T05:32:45.720915Z","schema_version":"clob-market-ws.price_change.v1","sequence":null,"server_hash":null,"server_timestamp":"1785130365759","session_id":"502006c5cfcd437296561ea750c9ec8b","source":"clob_market_ws"},"received_at":"2026-07-27T05:32:45.720915Z","record_id":"17346a04a6cb7333ca93b31aeaed8b58e4fd896460b5f8891f33cc6d1e6fb5f4","schema_fingerprint":"4aa3821a28b0b7c2400bc59aba4bcc0a76e971dadd19610d3ad38c768e124dc7","schema_version":"edge-lab-recorder.raw.v1","sequence":null,"source":"clob_market_ws"}
{"event_at":"2026-07-27T05:32:45.856000Z","event_fingerprint":"1e9036b79c41e2d2e1a70f4fafee6c429bc44a55656199f1965b5e3d137eef0b","payload":{"connection_id":"efc69d3132f1467b8e898a382b23ac0d","event_at":"2026-07-27T05:32:45.856000Z","event_type":"price_change","frame_hash":"9f3e71b4dfc2db4131f0610c1e99c8ad46010725a0b41513d6b9bdab190cb74c","frame_index":0,"kind":"data","monotonic_ns":232349053353125,"payload":{"event_type":"price_change","market":"0x3b40066b5cf3871a2f6237c5628bd8092a206aa998558ac5ec13c4483e31e160","price_changes":[{"asset_id":"14766054693214075530629349735273995982307625376442606753688071083149620216746","best_ask":"0.53","best_bid":"0.52","hash":"19e7f0a238068ab3e80aa8c65d534e7fa99777a8","price":"0.01","side":"BUY","size":"7878.02"},{"asset_id":"110216635572655435074987471276357323571387854733835379371586402147734167783946","best_ask":"0.48","best_bid":"0.47","hash":"cecc44c7258089d62c904ee1de6ae2ac708fa4af","price":"0.99","side":"SELL","size":"7878.02"}],"timestamp":"1785130365856"},"payload_hash":"393690049d496a74e27422fb52cd6b26ac0970f42f6517b31368134fb4db6bd0","raw_frame":"{\"market\":\"0x3b40066b5cf3871a2f6237c5628bd8092a206aa998558ac5ec13c4483e31e160\", \"price_changes\":[{\"asset_id\":\"14766054693214075530629349735273995982307625376442606753688071083149620216746\", \"price\":\"0.01\", \"size\":\"7878.02\", \"side\":\"BUY\", \"hash\":\"19e7f0a238068ab3e80aa8c65d534e7fa99777a8\", \"best_bid\":\"0.52\", \"best_ask\":\"0.53\"}, {\"asset_id\":\"110216635572655435074987471276357323571387854733835379371586402147734167783946\", \"price\":\"0.99\", \"size\":\"7878.02\", \"side\":\"SELL\", \"hash\":\"cecc44c7258089d62c904ee1de6ae2ac708fa4af\", \"best_bid\":\"0.47\", \"best_ask\":\"0.48\"}], \"timestamp\":\"1785130365856\", \"event_type\":\"price_change\"}","received_at":"2026-07-27T05:32:45.816296Z","schema_version":"clob-market-ws.price_change.v1","sequence":null,"server_hash":null,"server_timestamp":"1785130365856","session_id":"502006c5cfcd437296561ea750c9ec8b","source":"clob_market_ws"},"received_at":"2026-07-27T05:32:45.816296Z","record_id":"18107bd498c6ee80e6d289bc31859e883417449ab03e0b6ba0b5564aa4e7b77b","schema_fingerprint":"4aa3821a28b0b7c2400bc59aba4bcc0a76e971dadd19610d3ad38c768e124dc7","schema_version":"edge-lab-recorder.raw.v1","sequence":null,"source":"clob_market_ws"}
{"event_at":"2026-07-27T05:32:45.860000Z","event_fingerprint":"d0d4da1202e0da4a7bb6609c60ca4280c81924f1565242e9a5877a12e803b052","payload":{"connection_id":"efc69d3132f1467b8e898a382b23ac0d","event_at":"2026-07-27T05:32:45.860000Z","event_type":"price_change","frame_hash":"a94b00f84868f57c637280816e6e493d006e2977d7f312c2e2017f098982e91a","frame_index":0,"kind":"data","monotonic_ns":232349058643875,"payload":{"event_type":"price_change","market":"0x3b40066b5cf3871a2f6237c5628bd8092a206aa998558ac5ec13c4483e31e160","price_changes":[{"asset_id":"14766054693214075530629349735273995982307625376442606753688071083149620216746","best_ask":"0.53","best_bid":"0.52","hash":"3e1775fb12b2f224588268f555339554c381ee93","price":"0.01","side":"BUY","size":"7883.02"},{"asset_id":"110216635572655435074987471276357323571387854733835379371586402147734167783946","best_ask":"0.48","best_bid":"0.47","hash":"08661d627bf6d02167b1b5ce0ce7f0c33323d940","price":"0.99","side":"SELL","size":"7883.02"}],"timestamp":"1785130365860"},"payload_hash":"3b720906bdcbfaf0dc9829701cd701edd63a61c534f3dbba8ca4ac39dab90402","raw_frame":"{\"market\":\"0x3b40066b5cf3871a2f6237c5628bd8092a206aa998558ac5ec13c4483e31e160\", \"price_changes\":[{\"asset_id\":\"14766054693214075530629349735273995982307625376442606753688071083149620216746\", \"price\":\"0.01\", \"size\":\"7883.02\", \"side\":\"BUY\", \"hash\":\"3e1775fb12b2f224588268f555339554c381ee93\", \"best_bid\":\"0.52\", \"best_ask\":\"0.53\"}, {\"asset_id\":\"110216635572655435074987471276357323571387854733835379371586402147734167783946\", \"price\":\"0.99\", \"size\":\"7883.02\", \"side\":\"SELL\", \"hash\":\"08661d627bf6d02167b1b5ce0ce7f0c33323d940\", \"best_bid\":\"0.47\", \"best_ask\":\"0.48\"}], \"timestamp\":\"1785130365860\", \"event_type\":\"price_change\"}","received_at":"2026-07-27T05:32:45.821586Z","schema_version":"clob-market-ws.price_change.v1","sequence":null,"server_hash":null,"server_timestamp":"1785130365860","session_id":"502006c5cfcd437296561ea750c9ec8b","source":"clob_market_ws"},"received_at":"2026-07-27T05:32:45.821586Z","record_id":"8e7a687053df2b9568116a7bd5735a51d0137434f3de55c47ddaf5f3754c0e18","schema_fingerprint":"4aa3821a28b0b7c2400bc59aba4bcc0a76e971dadd19610d3ad38c768e124dc7","schema_version":"edge-lab-recorder.raw.v1","sequence":null,"source":"clob_market_ws"}
{"event_at":"2026-07-27T05:32:45.881000Z","event_fingerprint":"648c684c53933402a8ec4dc564b799f1d5703c6ba5248206f53b6f96960292d1","payload":{"connection_id":"efc69d3132f1467b8e898a382b23ac0d","event_at":"2026-07-27T05:32:45.881000Z","event_type":"price_change","frame_hash":"de55f139d54ad745a29dd1859d76b2a9882b379e931c360842db182077c10484","frame_index":0,"kind":"data","monotonic_ns":232349081046791,"payload":{"event_type":"price_change","market":"0x3b40066b5cf3871a2f6237c5628bd8092a206aa998558ac5ec13c4483e31e160","price_changes":[{"asset_id":"14766054693214075530629349735273995982307625376442606753688071083149620216746","best_ask":"0.53","best_bid":"0.52","hash":"9a4bf13ceaacaccf0450daf303e81994bf218fbd","price":"0.01","side":"BUY","size":"7878.02"},{"asset_id":"110216635572655435074987471276357323571387854733835379371586402147734167783946","best_ask":"0.48","best_bid":"0.47","hash":"567a5f32166b6fd020519e88b089ea5a23860fdc","price":"0.99","side":"SELL","size":"7878.02"}],"timestamp":"1785130365881"},"payload_hash":"29da541fad78ba3cd2ce014c5f508556563fc013aabf910fe97db36964ea13e9","raw_frame":"{\"market\":\"0x3b40066b5cf3871a2f6237c5628bd8092a206aa998558ac5ec13c4483e31e160\", \"price_changes\":[{\"asset_id\":\"14766054693214075530629349735273995982307625376442606753688071083149620216746\", \"price\":\"0.01\", \"size\":\"7878.02\", \"side\":\"BUY\", \"hash\":\"9a4bf13ceaacaccf0450daf303e81994bf218fbd\", \"best_bid\":\"0.52\", \"best_ask\":\"0.53\"}, {\"asset_id\":\"110216635572655435074987471276357323571387854733835379371586402147734167783946\", \"price\":\"0.99\", \"size\":\"7878.02\", \"side\":\"SELL\", \"hash\":\"567a5f32166b6fd020519e88b089ea5a23860fdc\", \"best_bid\":\"0.47\", \"best_ask\":\"0.48\"}], \"timestamp\":\"1785130365881\", \"event_type\":\"price_change\"}","received_at":"2026-07-27T05:32:45.843990Z","schema_version":"clob-market-ws.price_change.v1","sequence":null,"server_hash":null,"server_timestamp":"1785130365881","session_id":"502006c5cfcd437296561ea750c9ec8b","source":"clob_market_ws"},"received_at":"2026-07-27T05:32:45.843990Z","record_id":"c16b08bef7746444fc27bd680f3973a4c041b401e374426f8c14c466ec68f7c2","schema_fingerprint":"4aa3821a28b0b7c2400bc59aba4bcc0a76e971dadd19610d3ad38c768e124dc7","schema_version":"edge-lab-recorder.raw.v1","sequence":null,"source":"clob_market_ws"}
{"event_at":"2026-07-27T05:32:45.910000Z","event_fingerprint":"5b7f01625339719635667b509db4413d2e917b5946d8e568d69150abdf52581c","payload":{"connection_id":"efc69d3132f1467b8e898a382b23ac0d","event_at":"2026-07-27T05:32:45.910000Z","event_type":"price_change","frame_hash":"268f37d59b21df566ebb0fac321c895ff8059a906a57e6b830d3f40305e95218","frame_index":0,"kind":"data","monotonic_ns":232349108952333,"payload":{"event_type":"price_change","market":"0x3b40066b5cf3871a2f6237c5628bd8092a206aa998558ac5ec13c4483e31e160","price_changes":[{"asset_id":"14766054693214075530629349735273995982307625376442606753688071083149620216746","best_ask":"0.53","best_bid":"0.52","hash":"ce52c60fccfdf1e2958aeda15e1b36122a888076","price":"0.01","side":"BUY","size":"7873.02"},{"asset_id":"110216635572655435074987471276357323571387854733835379371586402147734167783946","best_ask":"0.48","best_bid":"0.47","hash":"f2c40141518299adddc08b81abe3c7575c3a2f29","price":"0.99","side":"SELL","size":"7873.02"}],"timestamp":"1785130365910"},"payload_hash":"8671d59a033a1c29e3166154d88878394a836ebc8a08e7465c41dd7e31538855","raw_frame":"{\"market\":\"0x3b40066b5cf3871a2f6237c5628bd8092a206aa998558ac5ec13c4483e31e160\", \"price_changes\":[{\"asset_id\":\"14766054693214075530629349735273995982307625376442606753688071083149620216746\", \"price\":\"0.01\", \"size\":\"7873.02\", \"side\":\"BUY\", \"hash\":\"ce52c60fccfdf1e2958aeda15e1b36122a888076\", \"best_bid\":\"0.52\", \"best_ask\":\"0.53\"}, {\"asset_id\":\"110216635572655435074987471276357323571387854733835379371586402147734167783946\", \"price\":\"0.99\", \"size\":\"7873.02\", \"side\":\"SELL\", \"hash\":\"f2c40141518299adddc08b81abe3c7575c3a2f29\", \"best_bid\":\"0.47\", \"best_ask\":\"0.48\"}], \"timestamp\":\"1785130365910\", \"event_type\":\"price_change\"}","received_at":"2026-07-27T05:32:45.871895Z","schema_version":"clob-market-ws.price_change.v1","sequence":null,"server_hash":null,"server_timestamp":"1785130365910","session_id":"502006c5cfcd437296561ea750c9ec8b","source":"clob_market_ws"},"received_at":"2026-07-27T05:32:45.871895Z","record_id":"1bb2810ccba366c3edead3461495a569f05f4e2828cac2724ffe08eee91dc0cc","schema_fingerprint":"4aa3821a28b0b7c2400bc59aba4bcc0a76e971dadd19610d3ad38c768e124dc7","schema_version":"edge-lab-recorder.raw.v1","sequence":null,"source":"clob_market_ws"}
{"event_at":"2026-07-27T05:32:45.923000Z","event_fingerprint":"d2c2a350d127ae0681c57506b775a8d6b0e20ba68f4cfb7726c7d3166a16e2d6","payload":{"connection_id":"efc69d3132f1467b8e898a382b23ac0d","event_at":"2026-07-27T05:32:45.923000Z","event_type":"price_change","frame_hash":"888e4735a90bfa6fea491fb4638a6cd12b5201c5433d5fe5b724872d2fc7c435","frame_index":0,"kind":"data","monotonic_ns":232349120864666,"payload":{"event_type":"price_change","market":"0x3b40066b5cf3871a2f6237c5628bd8092a206aa998558ac5ec13c4483e31e160","price_changes":[{"asset_id":"14766054693214075530629349735273995982307625376442606753688071083149620216746","best_ask":"0.53","best_bid":"0.52","hash":"b6b976aedc1652f55142c4f3c05f3374c42ecf8c","price":"0.41","side":"BUY","size":"158.4"},{"asset_id":"110216635572655435074987471276357323571387854733835379371586402147734167783946","best_ask":"0.48","best_bid":"0.47","hash":"86148967b45d920453943113878a304ed4d5fc4e","price":"0.59","side":"SELL","size":"158.4"}],"timestamp":"1785130365923"},"payload_hash":"2de8a38873ce94123feac0d6adf82dec3b128c074b20435b1fd35cf4c23aec28","raw_frame":"{\"market\":\"0x3b40066b5cf3871a2f6237c5628bd8092a206aa998558ac5ec13c4483e31e160\", \"price_changes\":[{\"asset_id\":\"14766054693214075530629349735273995982307625376442606753688071083149620216746\", \"price\":\"0.41\", \"size\":\"158.4\", \"side\":\"BUY\", \"hash\":\"b6b976aedc1652f55142c4f3c05f3374c42ecf8c\", \"best_bid\":\"0.52\", \"best_ask\":\"0.53\"}, {\"asset_id\":\"110216635572655435074987471276357323571387854733835379371586402147734167783946\", \"price\":\"0.59\", \"size\":\"158.4\", \"side\":\"SELL\", \"hash\":\"86148967b45d920453943113878a304ed4d5fc4e\", \"best_bid\":\"0.47\", \"best_ask\":\"0.48\"}], \"timestamp\":\"1785130365923\", \"event_type\":\"price_change\"}","received_at":"2026-07-27T05:32:45.883808Z","schema_version":"clob-market-ws.price_change.v1","sequence":null,"server_hash":null,"server_timestamp":"1785130365923","session_id":"502006c5cfcd437296561ea750c9ec8b","source":"clob_market_ws"},"received_at":"2026-07-27T05:32:45.883808Z","record_id":"85451f91aed473e060410abd5b5cc27937aca44d2bde132b61ad407e3da6d629","schema_fingerprint":"4aa3821a28b0b7c2400bc59aba4bcc0a76e971dadd19610d3ad38c768e124dc7","schema_version":"edge-lab-recorder.raw.v1","sequence":null,"source":"clob_market_ws"}
{"event_at":"2026-07-27T05:32:45.924000Z","event_fingerprint":"7bad40c03a5ed5d83878bf56027672fe6fcfa443780940e307f41d645a8a128d","payload":{"connection_id":"efc69d3132f1467b8e898a382b23ac0d","event_at":"2026-07-27T05:32:45.924000Z","event_type":"price_change","frame_hash":"2eaba2b02b422b6d0babe3846a31b2bd899aaebbb728c363d928409e1461f27f","frame_index":0,"kind":"data","monotonic_ns":232349123909125,"payload":{"event_type":"price_change","market":"0x3b40066b5cf3871a2f6237c5628bd8092a206aa998558ac5ec13c4483e31e160","price_changes":[{"asset_id":"14766054693214075530629349735273995982307625376442606753688071083149620216746","best_ask":"0.53","best_bid":"0.52","hash":"45f5329a9bb2f05c09afc76c2cf4f1c1598acd77","price":"0.42","side":"BUY","size":"246"},{"asset_id":"110216635572655435074987471276357323571387854733835379371586402147734167783946","best_ask":"0.48","best_bid":"0.47","hash":"c9d2fb58b2d02ef26175a564e5767af7de766ddd","price":"0.58","side":"SELL","size":"246"}],"timestamp":"1785130365924"},"payload_hash":"0c1fc9fdd2e11e0acd0d2b1fc716506706465d5b59c2991f60c6b6f9613b7320","raw_frame":"{\"market\":\"0x3b40066b5cf3871a2f6237c5628bd8092a206aa998558ac5ec13c4483e31e160\", \"price_changes\":[{\"asset_id\":\"14766054693214075530629349735273995982307625376442606753688071083149620216746\", \"price\":\"0.42\", \"size\":\"246\", \"side\":\"BUY\", \"hash\":\"45f5329a9bb2f05c09afc76c2cf4f1c1598acd77\", \"best_bid\":\"0.52\", \"best_ask\":\"0.53\"}, {\"asset_id\":\"110216635572655435074987471276357323571387854733835379371586402147734167783946\", \"price\":\"0.58\", \"size\":\"246\", \"side\":\"SELL\", \"hash\":\"c9d2fb58b2d02ef26175a564e5767af7de766ddd\", \"best_bid\":\"0.47\", \"best_ask\":\"0.48\"}], \"timestamp\":\"1785130365924\", \"event_type\":\"price_change\"}","received_at":"2026-07-27T05:32:45.886852Z","schema_version":"clob-market-ws.price_change.v1","sequence":null,"server_hash":null,"server_timestamp":"1785130365924","session_id":"502006c5cfcd437296561ea750c9ec8b","source":"clob_market_ws"},"received_at":"2026-07-27T05:32:45.886852Z","record_id":"2d7f1a39c28381799b2b5d6a4f51d1c2a053ef5c0c7797e2fd85bb24dd481293","schema_fingerprint":"4aa3821a28b0b7c2400bc59aba4bcc0a76e971dadd19610d3ad38c768e124dc7","schema_version":"edge-lab-recorder.raw.v1","sequence":null,"source":"clob_market_ws"}
{"event_at":"2026-07-27T05:32:45.926000Z","event_fingerprint":"cfff51a8c169fc00f54dafc30d0422a9b9f23c1c996b3942256bc4b73828c95e","payload":{"connection_id":"efc69d3132f1467b8e898a382b23ac0d","event_at":"2026-07-27T05:32:45.926000Z","event_type":"price_change","frame_hash":"191311da50a5fbbc65c786e93e71259bad22eb1e9a344836ac119b2682ddbf08","frame_index":0,"kind":"data","monotonic_ns":232349126865666,"payload":{"event_type":"price_change","market":"0x3b40066b5cf3871a2f6237c5628bd8092a206aa998558ac5ec13c4483e31e160","price_changes":[{"asset_id":"110216635572655435074987471276357323571387854733835379371586402147734167783946","best_ask":"0.48","best_bid":"0.47","hash":"83acb51ed5dd56e68c67e0ecf2da4970aef11ad2","price":"0.36","side":"BUY","size":"268"},{"asset_id":"14766054693214075530629349735273995982307625376442606753688071083149620216746","best_ask":"0.53","best_bid":"0.52","hash":"23302909343c35b4b1d4809bae2fa142a25d585d","price":"0.64","side":"SELL","size":"268"}],"timestamp":"1785130365926"},"payload_hash":"f6d1d857271ace3cfd24c1a70ee6092db926210dd7428c78ddbdf4179a8d73a8","raw_frame":"{\"market\":\"0x3b40066b5cf3871a2f6237c5628bd8092a206aa998558ac5ec13c4483e31e160\", \"price_changes\":[{\"asset_id\":\"110216635572655435074987471276357323571387854733835379371586402147734167783946\", \"price\":\"0.36\", \"size\":\"268\", \"side\":\"BUY\", \"hash\":\"83acb51ed5dd56e68c67e0ecf2da4970aef11ad2\", \"best_bid\":\"0.47\", \"best_ask\":\"0.48\"}, {\"asset_id\":\"14766054693214075530629349735273995982307625376442606753688071083149620216746\", \"price\":\"0.64\", \"size\":\"268\", \"side\":\"SELL\", \"hash\":\"23302909343c35b4b1d4809bae2fa142a25d585d\", \"best_bid\":\"0.52\", \"best_ask\":\"0.53\"}], \"timestamp\":\"1785130365926\", \"event_type\":\"price_change\"}","received_at":"2026-07-27T05:32:45.889808Z","schema_version":"clob-market-ws.price_change.v1","sequence":null,"server_hash":null,"server_timestamp":"1785130365926","session_id":"502006c5cfcd437296561ea750c9ec8b","source":"clob_market_ws"},"received_at":"2026-07-27T05:32:45.889808Z","record_id":"79f1a13f93f5daf2b154cfdd04abc2ed0d1f77d628249fdc3ac46aab20b1f9bf","schema_fingerprint":"4aa3821a28b0b7c2400bc59aba4bcc0a76e971dadd19610d3ad38c768e124dc7","schema_version":"edge-lab-recorder.raw.v1","sequence":null,"source":"clob_market_ws"}
{"event_at":"2026-07-27T05:32:46.019000Z","event_fingerprint":"b241791313c8946d5048c34f1692f74bc4add6456dfadd9537e6d3e279013e6c","payload":{"connection_id":"efc69d3132f1467b8e898a382b23ac0d","event_at":"2026-07-27T05:32:46.019000Z","event_type":"price_change","frame_hash":"7da674afb10476d81244be4c10615af3aeecf125fb572b6edeae623a964f8c81","frame_index":0,"kind":"data","monotonic_ns":232349216325458,"payload":{"event_type":"price_change","market":"0x3b40066b5cf3871a2f6237c5628bd8092a206aa998558ac5ec13c4483e31e160","price_changes":[{"asset_id":"110216635572655435074987471276357323571387854733835379371586402147734167783946","best_ask":"0.48","best_bid":"0.47","hash":"ce9d22a740e25258a62440e18c81fb505917183a","price":"0.01","side":"BUY","size":"7848.02"},{"asset_id":"14766054693214075530629349735273995982307625376442606753688071083149620216746","best_ask":"0.53","best_bid":"0.52","hash":"298a4851d3c286118f5a7c2c3d36bc8539ac96bf","price":"0.99","side":"SELL","size":"7848.02"}],"timestamp":"1785130366019"},"payload_hash":"eead10bd90e4a2dc5adda5f3bf533ed5f2c31d61e9828c859b6dc8b4e5c50d78","raw_frame":"{\"market\":\"0x3b40066b5cf3871a2f6237c5628bd8092a206aa998558ac5ec13c4483e31e160\", \"price_changes\":[{\"asset_id\":\"110216635572655435074987471276357323571387854733835379371586402147734167783946\", \"price\":\"0.01\", \"size\":\"7848.02\", \"side\":\"BUY\", \"hash\":\"ce9d22a740e25258a62440e18c81fb505917183a\", \"best_bid\":\"0.47\", \"best_ask\":\"0.48\"}, {\"asset_id\":\"14766054693214075530629349735273995982307625376442606753688071083149620216746\", \"price\":\"0.99\", \"size\":\"7848.02\", \"side\":\"SELL\", \"hash\":\"298a4851d3c286118f5a7c2c3d36bc8539ac96bf\", \"best_bid\":\"0.52\", \"best_ask\":\"0.53\"}], \"timestamp\":\"1785130366019\", \"event_type\":\"price_change\"}","received_at":"2026-07-27T05:32:45.979269Z","schema_version":"clob-market-ws.price_change.v1","sequence":null,"server_hash":null,"server_timestamp":"1785130366019","session_id":"502006c5cfcd437296561ea750c9ec8b","source":"clob_market_ws"},"received_at":"2026-07-27T05:32:45.979269Z","record_id":"01562c7892bdeaccc79f8c9e91dbf0466f89d9ee387bf058c3f6d95dd28f008f","schema_fingerprint":"4aa3821a28b0b7c2400bc59aba4bcc0a76e971dadd19610d3ad38c768e124dc7","schema_version":"edge-lab-recorder.raw.v1","sequence":null,"source":"clob_market_ws"}
{"event_at":"2026-07-27T05:32:46.031000Z","event_fingerprint":"03000996c04d935b7d1742c03b78f35be9bf59f4f5d74ef26b44faf5ebe14360","payload":{"connection_id":"efc69d3132f1467b8e898a382b23ac0d","event_at":"2026-07-27T05:32:46.031000Z","event_type":"price_change","frame_hash":"fadfc35c98df38c854b80271ae432c239b75b18db4addd245be93274412ba2cd","frame_index":0,"kind":"data","monotonic_ns":232349228346875,"payload":{"event_type":"price_change","market":"0x3b40066b5cf3871a2f6237c5628bd8092a206aa998558ac5ec13c4483e31e160","price_changes":[{"asset_id":"110216635572655435074987471276357323571387854733835379371586402147734167783946","best_ask":"0.48","best_bid":"0.47","hash":"0f932f22fc210c3faad9e0a5a440d3472312ffcb","price":"0.01","side":"BUY","size":"7853.02"},{"asset_id":"14766054693214075530629349735273995982307625376442606753688071083149620216746","best_ask":"0.53","best_bid":"0.52","hash":"31edc7cead532072d99a9b9c1ff3b0513aa84898","price":"0.99","side":"SELL","size":"7853.02"}],"timestamp":"1785130366031"},"payload_hash":"568b2441202fb58461e46250e8f7dacde10717974cf3bb7b64c37a6fab25ff3c","raw_frame":"{\"market\":\"0x3b40066b5cf3871a2f6237c5628bd8092a206aa998558ac5ec13c4483e31e160\", \"price_changes\":[{\"asset_id\":\"110216635572655435074987471276357323571387854733835379371586402147734167783946\", \"price\":\"0.01\", \"size\":\"7853.02\", \"side\":\"BUY\", \"hash\":\"0f932f22fc210c3faad9e0a5a440d3472312ffcb\", \"best_bid\":\"0.47\", \"best_ask\":\"0.48\"}, {\"asset_id\":\"14766054693214075530629349735273995982307625376442606753688071083149620216746\", \"price\":\"0.99\", \"size\":\"7853.02\", \"side\":\"SELL\", \"hash\":\"31edc7cead532072d99a9b9c1ff3b0513aa84898\", \"best_bid\":\"0.52\", \"best_ask\":\"0.53\"}], \"timestamp\":\"1785130366031\", \"event_type\":\"price_change\"}","received_at":"2026-07-27T05:32:45.991289Z","schema_version":"clob-market-ws.price_change.v1","sequence":null,"server_hash":null,"server_timestamp":"1785130366031","session_id":"502006c5cfcd437296561ea750c9ec8b","source":"clob_market_ws"},"received_at":"2026-07-27T05:32:45.991289Z","record_id":"6137650d509d0678b7e2b9a79b8d82d056bd490ecc02e09f97e5e1e83ca90599","schema_fingerprint":"4aa3821a28b0b7c2400bc59aba4bcc0a76e971dadd19610d3ad38c768e124dc7","schema_version":"edge-lab-recorder.raw.v1","sequence":null,"source":"clob_market_ws"}
{"event_at":"2026-07-27T05:32:46.049000Z","event_fingerprint":"af9c454a63c6d4a85cb3d7a8e5003ff7f6c8f768fab57fe6c9f848c060a2b46d","payload":{"connection_id":"efc69d3132f1467b8e898a382b23ac0d","event_at":"2026-07-27T05:32:46.049000Z","event_type":"price_change","frame_hash":"07e240bf8d732f10bf7df8917b19958ae899e8de6d97497c00bf9d81bb9960f6","frame_index":0,"kind":"data","monotonic_ns":232349249196083,"payload":{"event_type":"price_change","market":"0x3b40066b5cf3871a2f6237c5628bd8092a206aa998558ac5ec13c4483e31e160","price_changes":[{"asset_id":"14766054693214075530629349735273995982307625376442606753688071083149620216746","best_ask":"0.53","best_bid":"0.52","hash":"b603c8480aa772fe8c4855f27bc39f7bb1fb59a9","price":"0.03","side":"BUY","size":"618.1"},{"asset_id":"110216635572655435074987471276357323571387854733835379371586402147734167783946","best_ask":"0.48","best_bid":"0.47","hash":"8b94a1aaee99ebf9ab3578a3723359cb2632026f","price":"0.97","side":"SELL","size":"618.1"}],"timestamp":"1785130366049"},"payload_hash":"c13aa1481b81bc84812b0f1f403d8ea711d0cb4df8fcad95ba5f10ebd3ea9884","raw_frame":"{\"market\":\"0x3b40066b5cf3871a2f6237c5628bd8092a206aa998558ac5ec13c4483e31e160\", \"price_changes\":[{\"asset_id\":\"14766054693214075530629349735273995982307625376442606753688071083149620216746\", \"price\":\"0.03\", \"size\":\"618.1\", \"side\":\"BUY\", \"hash\":\"b603c8480aa772fe8c4855f27bc39f7bb1fb59a9\", \"best_bid\":\"0.52\", \"best_ask\":\"0.53\"}, {\"asset_id\":\"110216635572655435074987471276357323571387854733835379371586402147734167783946\", \"price\":\"0.97\", \"size\":\"618.1\", \"side\":\"SELL\", \"hash\":\"8b94a1aaee99ebf9ab3578a3723359cb2632026f\", \"best_bid\":\"0.47\", \"best_ask\":\"0.48\"}], \"timestamp\":\"1785130366049\", \"event_type\":\"price_change\"}","received_at":"2026-07-27T05:32:46.012139Z","schema_version":"clob-market-ws.price_change.v1","sequence":null,"server_hash":null,"server_timestamp":"1785130366049","session_id":"502006c5cfcd437296561ea750c9ec8b","source":"clob_market_ws"},"received_at":"2026-07-27T05:32:46.012139Z","record_id":"83ca915d16e789a975250bd4b956d0c04460fcca4846184752cabbf276f6d641","schema_fingerprint":"4aa3821a28b0b7c2400bc59aba4bcc0a76e971dadd19610d3ad38c768e124dc7","schema_version":"edge-lab-recorder.raw.v1","sequence":null,"source":"clob_market_ws"}
{"event_at":"2026-07-27T05:32:46.053000Z","event_fingerprint":"0acc8acd31d09fc8fd24d688d90cc901e9ff31ef6488ba2acb6d9d4eaf17566a","payload":{"connection_id":"efc69d3132f1467b8e898a382b23ac0d","event_at":"2026-07-27T05:32:46.053000Z","event_type":"price_change","frame_hash":"7401fb9ca55dc673c504fb7bd1a4e525fdb6b7b9bd27d3a2703c5df160d56db7","frame_index":0,"kind":"data","monotonic_ns":232349257531750,"payload":{"event_type":"price_change","market":"0x3b40066b5cf3871a2f6237c5628bd8092a206aa998558ac5ec13c4483e31e160","price_changes":[{"asset_id":"14766054693214075530629349735273995982307625376442606753688071083149620216746","best_ask":"0.53","best_bid":"0.52","hash":"ea8facb7cda5bb8343ba7427f64589431299a71e","price":"0.01","side":"BUY","size":"7878.02"},{"asset_id":"110216635572655435074987471276357323571387854733835379371586402147734167783946","best_ask":"0.48","best_bid":"0.47","hash":"c81bd939380dc2b651efc37ae9f48af6e859d423","price":"0.99","side":"SELL","size":"7878.02"}],"timestamp":"1785130366053"},"payload_hash":"f1def4aafda3f8204211dd8e18c60fc195c9ad2dd2c039742f49040736130107","raw_frame":"{\"market\":\"0x3b40066b5cf3871a2f6237c5628bd8092a206aa998558ac5ec13c4483e31e160\", \"price_changes\":[{\"asset_id\":\"14766054693214075530629349735273995982307625376442606753688071083149620216746\", \"price\":\"0.01\", \"size\":\"7878.02\", \"side\":\"BUY\", \"hash\":\"ea8facb7cda5bb8343ba7427f64589431299a71e\", \"best_bid\":\"0.52\", \"best_ask\":\"0.53\"}, {\"asset_id\":\"110216635572655435074987471276357323571387854733835379371586402147734167783946\", \"price\":\"0.99\", \"size\":\"7878.02\", \"side\":\"SELL\", \"hash\":\"c81bd939380dc2b651efc37ae9f48af6e859d423\", \"best_bid\":\"0.47\", \"best_ask\":\"0.48\"}], \"timestamp\":\"1785130366053\", \"event_type\":\"price_change\"}","received_at":"2026-07-27T05:32:46.020476Z","schema_version":"clob-market-ws.price_change.v1","sequence":null,"server_hash":null,"server_timestamp":"1785130366053","session_id":"502006c5cfcd437296561ea750c9ec8b","source":"clob_market_ws"},"received_at":"2026-07-27T05:32:46.020476Z","record_id":"5842ea1c98b0708c1bad47f2b202c65fcae42f0d0ce1495222e309ee3a210aba","schema_fingerprint":"4aa3821a28b0b7c2400bc59aba4bcc0a76e971dadd19610d3ad38c768e124dc7","schema_version":"edge-lab-recorder.raw.v1","sequence":null,"source":"clob_market_ws"}
{"event_at":"2026-07-27T05:32:46.053000Z","event_fingerprint":"793d4831d1281917a2b3759bec067e8f543bc27e63d6261827571bf9fdbec7a1","payload":{"connection_id":"efc69d3132f1467b8e898a382b23ac0d","event_at":"2026-07-27T05:32:46.053000Z","event_type":"price_change","frame_hash":"3e152ea1418563ad25389d143b403d5d81f576142595f80427f4b72aa4f67484","frame_index":0,"kind":"data","monotonic_ns":232349260441875,"payload":{"event_type":"price_change","market":"0x3b40066b5cf3871a2f6237c5628bd8092a206aa998558ac5ec13c4483e31e160","price_changes":[{"asset_id":"110216635572655435074987471276357323571387854733835379371586402147734167783946","best_ask":"0.48","best_bid":"0.47","hash":"437366b04c21ef14b1fe73b40658383eb5672ce8","price":"0.01","side":"BUY","size":"7848.02"},{"asset_id":"14766054693214075530629349735273995982307625376442606753688071083149620216746","best_ask":"0.53","best_bid":"0.52","hash":"739e8d12f09eda831fcc6f7a735c20dc0191ec9c","price":"0.99","side":"SELL","size":"7848.02"}],"timestamp":"1785130366053"},"payload_hash":"3329767e4f36322c682b0dc36f8d9bac7a1341e4d6643a563323c84ec409edd5","raw_frame":"{\"market\":\"0x3b40066b5cf3871a2f6237c5628bd8092a206aa998558ac5ec13c4483e31e160\", \"price_changes\":[{\"asset_id\":\"110216635572655435074987471276357323571387854733835379371586402147734167783946\", \"price\":\"0.01\", \"size\":\"7848.02\", \"side\":\"BUY\", \"hash\":\"437366b04c21ef14b1fe73b40658383eb5672ce8\", \"best_bid\":\"0.47\", \"best_ask\":\"0.48\"}, {\"asset_id\":\"14766054693214075530629349735273995982307625376442606753688071083149620216746\", \"price\":\"0.99\", \"size\":\"7848.02\", \"side\":\"SELL\", \"hash\":\"739e8d12f09eda831fcc6f7a735c20dc0191ec9c\", \"best_bid\":\"0.52\", \"best_ask\":\"0.53\"}], \"timestamp\":\"1785130366053\", \"event_type\":\"price_change\"}","received_at":"2026-07-27T05:32:46.023386Z","schema_version":"clob-market-ws.price_change.v1","sequence":null,"server_hash":null,"server_timestamp":"1785130366053","session_id":"502006c5cfcd437296561ea750c9ec8b","source":"clob_market_ws"},"received_at":"2026-07-27T05:32:46.023386Z","record_id":"ac7461085082cb4ee36350fba42b7f93cbdaddb818004bffb76eac48ac57a9a4","schema_fingerprint":"4aa3821a28b0b7c2400bc59aba4bcc0a76e971dadd19610d3ad38c768e124dc7","schema_version":"edge-lab-recorder.raw.v1","sequence":null,"source":"clob_market_ws"}
{"event_at":"2026-07-27T05:32:46.059000Z","event_fingerprint":"1915a2ec92f7788408f2ab316da10c9b97cf45af90f3acf1cd93a62c919f7a4d","payload":{"connection_id":"efc69d3132f1467b8e898a382b23ac0d","event_at":"2026-07-27T05:32:46.059000Z","event_type":"price_change","frame_hash":"761ef5ad4d6e4725c436d0ffa24ac53bb9e183ee332ff97301ef18850cdd102d","frame_index":0,"kind":"data","monotonic_ns":232349263989125,"payload":{"event_type":"price_change","market":"0x3b40066b5cf3871a2f6237c5628bd8092a206aa998558ac5ec13c4483e31e160","price_changes":[{"asset_id":"110216635572655435074987471276357323571387854733835379371586402147734167783946","best_ask":"0.48","best_bid":"0.47","hash":"1e24ee89377b8730caeadea0ca4401740e7789cf","price":"0.01","side":"BUY","size":"7843.02"},{"asset_id":"14766054693214075530629349735273995982307625376442606753688071083149620216746","best_ask":"0.53","best_bid":"0.52","hash":"d479c601acc5889cb6154fd7484084d784c40db0","price":"0.99","side":"SELL","size":"7843.02"}],"timestamp":"1785130366059"},"payload_hash":"bd952e08de2d0e40a0e5f8564951eb82e09fe2c3b9c6f5e6a9af6cc2c03e820b","raw_frame":"{\"market\":\"0x3b40066b5cf3871a2f6237c5628bd8092a206aa998558ac5ec13c4483e31e160\", \"price_changes\":[{\"asset_id\":\"110216635572655435074987471276357323571387854733835379371586402147734167783946\", \"price\":\"0.01\", \"size\":\"7843.02\", \"side\":\"BUY\", \"hash\":\"1e24ee89377b8730caeadea0ca4401740e7789cf\", \"best_bid\":\"0.47\", \"best_ask\":\"0.48\"}, {\"asset_id\":\"14766054693214075530629349735273995982307625376442606753688071083149620216746\", \"price\":\"0.99\", \"size\":\"7843.02\", \"side\":\"SELL\", \"hash\":\"d479c601acc5889cb6154fd7484084d784c40db0\", \"best_bid\":\"0.52\", \"best_ask\":\"0.53\"}], \"timestamp\":\"1785130366059\", \"event_type\":\"price_change\"}","received_at":"2026-07-27T05:32:46.026934Z","schema_version":"clob-market-ws.price_change.v1","sequence":null,"server_hash":null,"server_timestamp":"1785130366059","session_id":"502006c5cfcd437296561ea750c9ec8b","source":"clob_market_ws"},"received_at":"2026-07-27T05:32:46.026934Z","record_id":"f45f177483cf37ca13cb1344ece17395367ab0285140b27ac72eb40decb936bc","schema_fingerprint":"4aa3821a28b0b7c2400bc59aba4bcc0a76e971dadd19610d3ad38c768e124dc7","schema_version":"edge-lab-recorder.raw.v1","sequence":null,"source":"clob_market_ws"}
{"event_at":"2026-07-27T05:32:46.073000Z","event_fingerprint":"45e44530bd9d89cb546626a502aac9e327d8f4f5992497ea7bae605b5343d53d","payload":{"connection_id":"efc69d3132f1467b8e898a382b23ac0d","event_at":"2026-07-27T05:32:46.073000Z","event_type":"price_change","frame_hash":"673501b0f539eafed9d38ecff910947cde508da2f84594de58472851e9c309f5","frame_index":0,"kind":"data","monotonic_ns":232349273180708,"payload":{"event_type":"price_change","market":"0x3b40066b5cf3871a2f6237c5628bd8092a206aa998558ac5ec13c4483e31e160","price_changes":[{"asset_id":"14766054693214075530629349735273995982307625376442606753688071083149620216746","best_ask":"0.53","best_bid":"0.52","hash":"b153d86318ed3100f1e1f8b3d1ff3992b119cb1f","price":"0.01","side":"BUY","size":"7873.02"},{"asset_id":"110216635572655435074987471276357323571387854733835379371586402147734167783946","best_ask":"0.48","best_bid":"0.47","hash":"5af52127edaab09a22c8898056b377418db7695c","price":"0.99","side":"SELL","size":"7873.02"}],"timestamp":"1785130366073"},"payload_hash":"dd3486dca260a72c46c25618b2b36c06fd7e1ab62b901f9e7ca120212bb72f78","raw_frame":"{\"market\":\"0x3b40066b5cf3871a2f6237c5628bd8092a206aa998558ac5ec13c4483e31e160\", \"price_changes\":[{\"asset_id\":\"14766054693214075530629349735273995982307625376442606753688071083149620216746\", \"price\":\"0.01\", \"size\":\"7873.02\", \"side\":\"BUY\", \"hash\":\"b153d86318ed3100f1e1f8b3d1ff3992b119cb1f\", \"best_bid\":\"0.52\", \"best_ask\":\"0.53\"}, {\"asset_id\":\"110216635572655435074987471276357323571387854733835379371586402147734167783946\", \"price\":\"0.99\", \"size\":\"7873.02\", \"side\":\"SELL\", \"hash\":\"5af52127edaab09a22c8898056b377418db7695c\", \"best_bid\":\"0.47\", \"best_ask\":\"0.48\"}], \"timestamp\":\"1785130366073\", \"event_type\":\"price_change\"}","received_at":"2026-07-27T05:32:46.036122Z","schema_version":"clob-market-ws.price_change.v1","sequence":null,"server_hash":null,"server_timestamp":"1785130366073","session_id":"502006c5cfcd437296561ea750c9ec8b","source":"clob_market_ws"},"received_at":"2026-07-27T05:32:46.036122Z","record_id":"ab8decc1caf3a436639c16b075177312763305af30a51d1ab082f23f7f5ce94d","schema_fingerprint":"4aa3821a28b0b7c2400bc59aba4bcc0a76e971dadd19610d3ad38c768e124dc7","schema_version":"edge-lab-recorder.raw.v1","sequence":null,"source":"clob_market_ws"}
{"event_at":"2026-07-27T05:32:46.086000Z","event_fingerprint":"373cccc4deacefee100012fed4f0c812ca5fcaeffc93d2f143bcab6957ff26b3","payload":{"connection_id":"efc69d3132f1467b8e898a382b23ac0d","event_at":"2026-07-27T05:32:46.086000Z","event_type":"price_change","frame_hash":"bffc3da835bd3fd0ef82dac20d4cd60f0a0093604cfea5226f2f77cf5187949c","frame_index":0,"kind":"data","monotonic_ns":232349284000833,"payload":{"event_type":"price_change","market":"0x3b40066b5cf3871a2f6237c5628bd8092a206aa998558ac5ec13c4483e31e160","price_changes":[{"asset_id":"110216635572655435074987471276357323571387854733835379371586402147734167783946","best_ask":"0.48","best_bid":"0.47","hash":"f0ef98def9caec79973b7a37f26bbc2a5b7075c3","price":"0.63","side":"SELL","size":"180.9"},{"asset_id":"14766054693214075530629349735273995982307625376442606753688071083149620216746","best_ask":"0.53","best_bid":"0.52","hash":"e6c1512111470ceace46aab36ee99fab2086dd77","price":"0.37","side":"BUY","size":"180.9"}],"timestamp":"1785130366086"},"payload_hash":"b728482086da6488ac5c6cad4f6d9376032f15c9185e91cfce0f6b1c39d4e0a4","raw_frame":"{\"market\":\"0x3b40066b5cf3871a2f6237c5628bd8092a206aa998558ac5ec13c4483e31e160\", \"price_changes\":[{\"asset_id\":\"110216635572655435074987471276357323571387854733835379371586402147734167783946\", \"price\":\"0.63\", \"size\":\"180.9\", \"side\":\"SELL\", \"hash\":\"f0ef98def9caec79973b7a37f26bbc2a5b7075c3\", \"best_bid\":\"0.47\", \"best_ask\":\"0.48\"}, {\"asset_id\":\"14766054693214075530629349735273995982307625376442606753688071083149620216746\", \"price\":\"0.37\", \"size\":\"180.9\", \"side\":\"BUY\", \"hash\":\"e6c1512111470ceace46aab36ee99fab2086dd77\", \"best_bid\":\"0.52\", \"best_ask\":\"0.53\"}], \"timestamp\":\"1785130366086\", \"event_type\":\"price_change\"}","received_at":"2026-07-27T05:32:46.046945Z","schema_version":"clob-market-ws.price_change.v1","sequence":null,"server_hash":null,"server_timestamp":"1785130366086","session_id":"502006c5cfcd437296561ea750c9ec8b","source":"clob_market_ws"},"received_at":"2026-07-27T05:32:46.046945Z","record_id":"e79dd149756ba9d3074432b9607cd80017b1dfa2a2791d73469cbae7fcd52467","schema_fingerprint":"4aa3821a28b0b7c2400bc59aba4bcc0a76e971dadd19610d3ad38c768e124dc7","schema_version":"edge-lab-recorder.raw.v1","sequence":null,"source":"clob_market_ws"}
{"event_at":"2026-07-27T05:32:46.088000Z","event_fingerprint":"1461a628702e35cbd0726ffd41984c61705cf64709de7d952e3bcc441b6840b0","payload":{"connection_id":"efc69d3132f1467b8e898a382b23ac0d","event_at":"2026-07-27T05:32:46.088000Z","event_type":"price_change","frame_hash":"41bcd68b3b3a2432f8f18ed5e1bb1b4bce20e9e362e8d011f90fbdf6d6683eff","frame_index":0,"kind":"data","monotonic_ns":232349288897916,"payload":{"event_type":"price_change","market":"0x3b40066b5cf3871a2f6237c5628bd8092a206aa998558ac5ec13c4483e31e160","price_changes":[{"asset_id":"110216635572655435074987471276357323571387854733835379371586402147734167783946","best_ask":"0.48","best_bid":"0.47","hash":"4de0a7047b4e4de41a46b2ebe5eafe4ccaa0ed05","price":"0.34","side":"BUY","size":"192.4"},{"asset_id":"14766054693214075530629349735273995982307625376442606753688071083149620216746","best_ask":"0.53","best_bid":"0.52","hash":"3d98a021629862207c33eb1878ef608d575e6e3b","price":"0.66","side":"SELL","size":"192.4"}],"timestamp":"1785130366088"},"payload_hash":"671b30bf900245bad51d0eb1b83d0f29628a67ac9fc012cd414a038768b198ce","raw_frame":"{\"market\":\"0x3b40066b5cf3871a2f6237c5628bd8092a206aa998558ac5ec13c4483e31e160\", \"price_changes\":[{\"asset_id\":\"110216635572655435074987471276357323571387854733835379371586402147734167783946\", \"price\":\"0.34\", \"size\":\"192.4\", \"side\":\"BUY\", \"hash\":\"4de0a7047b4e4de41a46b2ebe5eafe4ccaa0ed05\", \"best_bid\":\"0.47\", \"best_ask\":\"0.48\"}, {\"asset_id\":\"14766054693214075530629349735273995982307625376442606753688071083149620216746\", \"price\":\"0.66\", \"size\":\"192.4\", \"side\":\"SELL\", \"hash\":\"3d98a021629862207c33eb1878ef608d575e6e3b\", \"best_bid\":\"0.52\", \"best_ask\":\"0.53\"}], \"timestamp\":\"1785130366088\", \"event_type\":\"price_change\"}","received_at":"2026-07-27T05:32:46.051841Z","schema_version":"clob-market-ws.price_change.v1","sequence":null,"server_hash":null,"server_timestamp":"1785130366088","session_id":"502006c5cfcd437296561ea750c9ec8b","source":"clob_market_ws"},"received_at":"2026-07-27T05:32:46.051841Z","record_id":"7537c0a4b0f18b3ac46deb4ab2a6558d2e0104d5ef97fbe7c5017d13e4a9fe2c","schema_fingerprint":"4aa3821a28b0b7c2400bc59aba4bcc0a76e971dadd19610d3ad38c768e124dc7","schema_version":"edge-lab-recorder.raw.v1","sequence":null,"source":"clob_market_ws"}
{"event_at":"2026-07-27T05:32:46.102000Z","event_fingerprint":"7751837222acd0b1ba3ea7e1c0683f3f37f20dc57e4c7bdc1762ff58d059ad3e","payload":{"connection_id":"efc69d3132f1467b8e898a382b23ac0d","event_at":"2026-07-27T05:32:46.102000Z","event_type":"price_change","frame_hash":"2f0689897735f68a748112960c4d14e1523f183356204b25f8c1984d6ad6e006","frame_index":0,"kind":"data","monotonic_ns":232349304328541,"payload":{"event_type":"price_change","market":"0x3b40066b5cf3871a2f6237c5628bd8092a206aa998558ac5ec13c4483e31e160","price_changes":[{"asset_id":"14766054693214075530629349735273995982307625376442606753688071083149620216746","best_ask":"0.53","best_bid":"0.52","hash":"e0a60546ea1e516f5d2c0ebe90fdf3ab1d17a641","price":"0.03","side":"BUY","size":"613.1"},{"asset_id":"110216635572655435074987471276357323571387854733835379371586402147734167783946","best_ask":"0.48","best_bid":"0.47","hash":"e8868a75cb0aab552fea5e478d1b24f10f8a80c3","price":"0.97","side":"SELL","size":"613.1"}],"timestamp":"1785130366102"},"payload_hash":"17fef7fb2859f9ed5ac32b03aa9a83e63d91b71726bd5c66a4b5e933543c9fb7","raw_frame":"{\"market\":\"0x3b40066b5cf3871a2f6237c5628bd8092a206aa998558ac5ec13c4483e31e160\", \"price_changes\":[{\"asset_id\":\"14766054693214075530629349735273995982307625376442606753688071083149620216746\", \"price\":\"0.03\", \"size\":\"613.1\", \"side\":\"BUY\", \"hash\":\"e0a60546ea1e516f5d2c0ebe90fdf3ab1d17a641\", \"best_bid\":\"0.52\", \"best_ask\":\"0.53\"}, {\"asset_id\":\"110216635572655435074987471276357323571387854733835379371586402147734167783946\", \"price\":\"0.97\", \"size\":\"613.1\", \"side\":\"SELL\", \"hash\":\"e8868a75cb0aab552fea5e478d1b24f10f8a80c3\", \"best_bid\":\"0.47\", \"best_ask\":\"0.48\"}], \"timestamp\":\"1785130366102\", \"event_type\":\"price_change\"}","received_at":"2026-07-27T05:32:46.067273Z","schema_version":"clob-market-ws.price_change.v1","sequence":null,"server_hash":null,"server_timestamp":"1785130366102","session_id":"502006c5cfcd437296561ea750c9ec8b","source":"clob_market_ws"},"received_at":"2026-07-27T05:32:46.067273Z","record_id":"4a24cc8e0105ee3a080499df368a2b9375722f8090a982da2eb5286141fa14ba","schema_fingerprint":"4aa3821a28b0b7c2400bc59aba4bcc0a76e971dadd19610d3ad38c768e124dc7","schema_version":"edge-lab-recorder.raw.v1","sequence":null,"source":"clob_market_ws"}
{"event_at":"2026-07-27T05:32:46.256000Z","event_fingerprint":"476d38cfc5db38b8751563e511df0513b28b799ce25a082de2494000652b8682","payload":{"connection_id":"efc69d3132f1467b8e898a382b23ac0d","event_at":"2026-07-27T05:32:46.256000Z","event_type":"price_change","frame_hash":"b2a27a146e94479f0d03da5bb68cddeedaf231c008256fdfb63184b1f715d972","frame_index":0,"kind":"data","monotonic_ns":232349454819833,"payload":{"event_type":"price_change","market":"0x3b40066b5cf3871a2f6237c5628bd8092a206aa998558ac5ec13c4483e31e160","price_changes":[{"asset_id":"14766054693214075530629349735273995982307625376442606753688071083149620216746","best_ask":"0.53","best_bid":"0.52","hash":"bf2c3d84ff04f5dabac093a90e47788e6c526a37","price":"0.03","side":"BUY","size":"618.1"},{"asset_id":"110216635572655435074987471276357323571387854733835379371586402147734167783946","best_ask":"0.48","best_bid":"0.47","hash":"725d4d8b5ed9845856a6e3aa6c498e3d105fb117","price":"0.97","side":"SELL","size":"618.1"}],"timestamp":"1785130366256"},"payload_hash":"8114e14e85ef742f07ba5a8cb348d529663cfc48e9b621b3ccef3058a1725fd0","raw_frame":"{\"market\":\"0x3b40066b5cf3871a2f6237c5628bd8092a206aa998558ac5ec13c4483e31e160\", \"price_changes\":[{\"asset_id\":\"14766054693214075530629349735273995982307625376442606753688071083149620216746\", \"price\":\"0.03\", \"size\":\"618.1\", \"side\":\"BUY\", \"hash\":\"bf2c3d84ff04f5dabac093a90e47788e6c526a37\", \"best_bid\":\"0.52\", \"best_ask\":\"0.53\"}, {\"asset_id\":\"110216635572655435074987471276357323571387854733835379371586402147734167783946\", \"price\":\"0.97\", \"size\":\"618.1\", \"side\":\"SELL\", \"hash\":\"725d4d8b5ed9845856a6e3aa6c498e3d105fb117\", \"best_bid\":\"0.47\", \"best_ask\":\"0.48\"}], \"timestamp\":\"1785130366256\", \"event_type\":\"price_change\"}","received_at":"2026-07-27T05:32:46.217762Z","schema_version":"clob-market-ws.price_change.v1","sequence":null,"server_hash":null,"server_timestamp":"1785130366256","session_id":"502006c5cfcd437296561ea750c9ec8b","source":"clob_market_ws"},"received_at":"2026-07-27T05:32:46.217762Z","record_id":"e856f6e34cb0e454dec8bd640974a29bca38b72011ba93b73c1a9e8beb6092f4","schema_fingerprint":"4aa3821a28b0b7c2400bc59aba4bcc0a76e971dadd19610d3ad38c768e124dc7","schema_version":"edge-lab-recorder.raw.v1","sequence":null,"source":"clob_market_ws"}
{"event_at":"2026-07-27T05:32:46.359000Z","event_fingerprint":"9253269b8f8ff20382b02d34dbe27789fa60b2eb8a03860bff3de03279d51a8b","payload":{"connection_id":"efc69d3132f1467b8e898a382b23ac0d","event_at":"2026-07-27T05:32:46.359000Z","event_type":"price_change","frame_hash":"01fa03141374f44d7fcf6dd0a4497541120237ec76730ddfa7ef6f0a896c7559","frame_index":0,"kind":"data","monotonic_ns":232349556705708,"payload":{"event_type":"price_change","market":"0x3b40066b5cf3871a2f6237c5628bd8092a206aa998558ac5ec13c4483e31e160","price_changes":[{"asset_id":"14766054693214075530629349735273995982307625376442606753688071083149620216746","best_ask":"0.53","best_bid":"0.52","hash":"67cdb1281868a2ea20e557a6e0c63d7f29e8f109","price":"0.03","side":"BUY","size":"613.1"},{"asset_id":"110216635572655435074987471276357323571387854733835379371586402147734167783946","best_ask":"0.48","best_bid":"0.47","hash":"1b686d9b681925c59058052c3a75213714ae124a","price":"0.97","side":"SELL","size":"613.1"}],"timestamp":"1785130366359"},"payload_hash":"169f6817485412c30afab7a9447f2f9a474f80cd5584a7a3697169a30c57eb15","raw_frame":"{\"market\":\"0x3b40066b5cf3871a2f6237c5628bd8092a206aa998558ac5ec13c4483e31e160\", \"price_changes\":[{\"asset_id\":\"14766054693214075530629349735273995982307625376442606753688071083149620216746\", \"price\":\"0.03\", \"size\":\"613.1\", \"side\":\"BUY\", \"hash\":\"67cdb1281868a2ea20e557a6e0c63d7f29e8f109\", \"best_bid\":\"0.52\", \"best_ask\":\"0.53\"}, {\"asset_id\":\"110216635572655435074987471276357323571387854733835379371586402147734167783946\", \"price\":\"0.97\", \"size\":\"613.1\", \"side\":\"SELL\", \"hash\":\"1b686d9b681925c59058052c3a75213714ae124a\", \"best_bid\":\"0.47\", \"best_ask\":\"0.48\"}], \"timestamp\":\"1785130366359\", \"event_type\":\"price_change\"}","received_at":"2026-07-27T05:32:46.319650Z","schema_version":"clob-market-ws.price_change.v1","sequence":null,"server_hash":null,"server_timestamp":"1785130366359","session_id":"502006c5cfcd437296561ea750c9ec8b","source":"clob_market_ws"},"received_at":"2026-07-27T05:32:46.319650Z","record_id":"dabc3944bc91dc80540c88eb7db19b9d7f1fbd03fb1af324a88be07e99bbfa32","schema_fingerprint":"4aa3821a28b0b7c2400bc59aba4bcc0a76e971dadd19610d3ad38c768e124dc7","schema_version":"edge-lab-recorder.raw.v1","sequence":null,"source":"clob_market_ws"}
{"event_at":"2026-07-27T05:32:46.371000Z","event_fingerprint":"39e91bc99724afeba2fe1691727b186d35d606729724135574fb003d8f177b72","payload":{"connection_id":"efc69d3132f1467b8e898a382b23ac0d","event_at":"2026-07-27T05:32:46.371000Z","event_type":"price_change","frame_hash":"802e1ffa6f1235503fd57f1416ce60c69585f9a433b063a01f66090d901f5703","frame_index":0,"kind":"data","monotonic_ns":232349567413375,"payload":{"event_type":"price_change","market":"0x3b40066b5cf3871a2f6237c5628bd8092a206aa998558ac5ec13c4483e31e160","price_changes":[{"asset_id":"14766054693214075530629349735273995982307625376442606753688071083149620216746","best_ask":"0.53","best_bid":"0.52","hash":"ee349bd03052ab1637e081b97da8ce6f48037046","price":"0.01","side":"BUY","size":"7878.02"},{"asset_id":"110216635572655435074987471276357323571387854733835379371586402147734167783946","best_ask":"0.48","best_bid":"0.47","hash":"a024cae4611f6e9757cc973ab929c0ef41426cf3","price":"0.99","side":"SELL","size":"7878.02"}],"timestamp":"1785130366371"},"payload_hash":"72aeea18f662abc3aeec352d8c4119b5e58a978e535dfafb47823509d7cf2b64","raw_frame":"{\"market\":\"0x3b40066b5cf3871a2f6237c5628bd8092a206aa998558ac5ec13c4483e31e160\", \"price_changes\":[{\"asset_id\":\"14766054693214075530629349735273995982307625376442606753688071083149620216746\", \"price\":\"0.01\", \"size\":\"7878.02\", \"side\":\"BUY\", \"hash\":\"ee349bd03052ab1637e081b97da8ce6f48037046\", \"best_bid\":\"0.52\", \"best_ask\":\"0.53\"}, {\"asset_id\":\"110216635572655435074987471276357323571387854733835379371586402147734167783946\", \"price\":\"0.99\", \"size\":\"7878.02\", \"side\":\"SELL\", \"hash\":\"a024cae4611f6e9757cc973ab929c0ef41426cf3\", \"best_bid\":\"0.47\", \"best_ask\":\"0.48\"}], \"timestamp\":\"1785130366371\", \"event_type\":\"price_change\"}","received_at":"2026-07-27T05:32:46.330364Z","schema_version":"clob-market-ws.price_change.v1","sequence":null,"server_hash":null,"server_timestamp":"1785130366371","session_id":"502006c5cfcd437296561ea750c9ec8b","source":"clob_market_ws"},"received_at":"2026-07-27T05:32:46.330364Z","record_id":"56e40b758210a82c54adcb5060d5231cb3112ea5748f823ad1b7ca2d064f40d1","schema_fingerprint":"4aa3821a28b0b7c2400bc59aba4bcc0a76e971dadd19610d3ad38c768e124dc7","schema_version":"edge-lab-recorder.raw.v1","sequence":null,"source":"clob_market_ws"}
{"event_at":"2026-07-27T05:32:46.397000Z","event_fingerprint":"e1cdd76ac8a17104d6c66c427fcc0cc43530d2cf55a8b7ea7662a3bececca6fe","payload":{"connection_id":"efc69d3132f1467b8e898a382b23ac0d","event_at":"2026-07-27T05:32:46.397000Z","event_type":"price_change","frame_hash":"0baa273c7eb8ddad760d3625214f2be5f57308cb4b4310c54a1010ac404f81a5","frame_index":0,"kind":"data","monotonic_ns":232349596500041,"payload":{"event_type":"price_change","market":"0x3b40066b5cf3871a2f6237c5628bd8092a206aa998558ac5ec13c4483e31e160","price_changes":[{"asset_id":"14766054693214075530629349735273995982307625376442606753688071083149620216746","best_ask":"0.53","best_bid":"0.52","hash":"11903a980a05380f263247323a3f0c6127df1f5c","price":"0.01","side":"BUY","size":"7873.02"},{"asset_id":"110216635572655435074987471276357323571387854733835379371586402147734167783946","best_ask":"0.48","best_bid":"0.47","hash":"62e5a0a496933d14ce7d32227e67d468ff19a8ca","price":"0.99","side":"SELL","size":"7873.02"}],"timestamp":"1785130366397"},"payload_hash":"0d509e928dcff81cb870f93fdbe59996ddc42d6708d9dce6827b8fa5084765d9","raw_frame":"{\"market\":\"0x3b40066b5cf3871a2f6237c5628bd8092a206aa998558ac5ec13c4483e31e160\", \"price_changes\":[{\"asset_id\":\"14766054693214075530629349735273995982307625376442606753688071083149620216746\", \"price\":\"0.01\", \"size\":\"7873.02\", \"side\":\"BUY\", \"hash\":\"11903a980a05380f263247323a3f0c6127df1f5c\", \"best_bid\":\"0.52\", \"best_ask\":\"0.53\"}, {\"asset_id\":\"110216635572655435074987471276357323571387854733835379371586402147734167783946\", \"price\":\"0.99\", \"size\":\"7873.02\", \"side\":\"SELL\", \"hash\":\"62e5a0a496933d14ce7d32227e67d468ff19a8ca\", \"best_bid\":\"0.47\", \"best_ask\":\"0.48\"}], \"timestamp\":\"1785130366397\", \"event_type\":\"price_change\"}","received_at":"2026-07-27T05:32:46.359446Z","schema_version":"clob-market-ws.price_change.v1","sequence":null,"server_hash":null,"server_timestamp":"1785130366397","session_id":"502006c5cfcd437296561ea750c9ec8b","source":"clob_market_ws"},"received_at":"2026-07-27T05:32:46.359446Z","record_id":"41e48594ab772ad5a09b728bd3a6579a2f65ce399a98c500ef7cf89a78e8be07","schema_fingerprint":"4aa3821a28b0b7c2400bc59aba4bcc0a76e971dadd19610d3ad38c768e124dc7","schema_version":"edge-lab-recorder.raw.v1","sequence":null,"source":"clob_market_ws"}
{"event_at":"2026-07-27T05:32:46.451000Z","event_fingerprint":"76cb204d66db4a3efbc1bab49c090db344b93dfb94ad162170a1e8a3f9b31d8a","payload":{"connection_id":"efc69d3132f1467b8e898a382b23ac0d","event_at":"2026-07-27T05:32:46.451000Z","event_type":"price_change","frame_hash":"2f60f935ebdd43dc7b08e5f5581feb0cd93c9de39d1111076a6af67a643a7d1f","frame_index":0,"kind":"data","monotonic_ns":232349650014500,"payload":{"event_type":"price_change","market":"0x3b40066b5cf3871a2f6237c5628bd8092a206aa998558ac5ec13c4483e31e160","price_changes":[{"asset_id":"14766054693214075530629349735273995982307625376442606753688071083149620216746","best_ask":"0.53","best_bid":"0.52","hash":"3ad91418c13e1966c0cc2dd0355e80714c3374b0","price":"0.01","side":"BUY","size":"7878.02"},{"asset_id":"110216635572655435074987471276357323571387854733835379371586402147734167783946","best_ask":"0.48","best_bid":"0.47","hash":"d4092178075eb7541cf2b41ff6daab5bead031ac","price":"0.99","side":"SELL","size":"7878.02"}],"timestamp":"1785130366451"},"payload_hash":"9501d3c2c9d74a335f51068d409e19424693515e72369933fc9211433ae51775","raw_frame":"{\"market\":\"0x3b40066b5cf3871a2f6237c5628bd8092a206aa998558ac5ec13c4483e31e160\", \"price_changes\":[{\"asset_id\":\"14766054693214075530629349735273995982307625376442606753688071083149620216746\", \"price\":\"0.01\", \"size\":\"7878.02\", \"side\":\"BUY\", \"hash\":\"3ad91418c13e1966c0cc2dd0355e80714c3374b0\", \"best_bid\":\"0.52\", \"best_ask\":\"0.53\"}, {\"asset_id\":\"110216635572655435074987471276357323571387854733835379371586402147734167783946\", \"price\":\"0.99\", \"size\":\"7878.02\", \"side\":\"SELL\", \"hash\":\"d4092178075eb7541cf2b41ff6daab5bead031ac\", \"best_bid\":\"0.47\", \"best_ask\":\"0.48\"}], \"timestamp\":\"1785130366451\", \"event_type\":\"price_change\"}","received_at":"2026-07-27T05:32:46.412961Z","schema_version":"clob-market-ws.price_change.v1","sequence":null,"server_hash":null,"server_timestamp":"1785130366451","session_id":"502006c5cfcd437296561ea750c9ec8b","source":"clob_market_ws"},"received_at":"2026-07-27T05:32:46.412961Z","record_id":"36bdc728f5682f3b34bc3c4213d4d45373108694ca0d0cdb13cbdd172616eda1","schema_fingerprint":"4aa3821a28b0b7c2400bc59aba4bcc0a76e971dadd19610d3ad38c768e124dc7","schema_version":"edge-lab-recorder.raw.v1","sequence":null,"source":"clob_market_ws"}
{"event_at":"2026-07-27T05:32:46.457000Z","event_fingerprint":"07246c09b4475af03909811a6504f3ed8b5a778071bb1e32e32542fd6c4342aa","payload":{"connection_id":"efc69d3132f1467b8e898a382b23ac0d","event_at":"2026-07-27T05:32:46.457000Z","event_type":"price_change","frame_hash":"6f6ef986b6363a684cf1bf6583557543537f067295295dae264a1ed40b842c46","frame_index":0,"kind":"data","monotonic_ns":232349655251791,"payload":{"event_type":"price_change","market":"0x3b40066b5cf3871a2f6237c5628bd8092a206aa998558ac5ec13c4483e31e160","price_changes":[{"asset_id":"14766054693214075530629349735273995982307625376442606753688071083149620216746","best_ask":"0.53","best_bid":"0.52","hash":"f6bc6a253e64236ad693a378ee9274083e70ad4d","price":"0.02","side":"BUY","size":"728.1"},{"asset_id":"110216635572655435074987471276357323571387854733835379371586402147734167783946","best_ask":"0.48","best_bid":"0.47","hash":"c8340d8ba89b2c0692861d13895a333115f68762","price":"0.98","side":"SELL","size":"728.1"}],"timestamp":"1785130366457"},"payload_hash":"9b6158018380d46889246687afcaaf59514d68f44544d56b74dfa49d81ab774c","raw_frame":"{\"market\":\"0x3b40066b5cf3871a2f6237c5628bd8092a206aa998558ac5ec13c4483e31e160\", \"price_changes\":[{\"asset_id\":\"14766054693214075530629349735273995982307625376442606753688071083149620216746\", \"price\":\"0.02\", \"size\":\"728.1\", \"side\":\"BUY\", \"hash\":\"f6bc6a253e64236ad693a378ee9274083e70ad4d\", \"best_bid\":\"0.52\", \"best_ask\":\"0.53\"}, {\"asset_id\":\"110216635572655435074987471276357323571387854733835379371586402147734167783946\", \"price\":\"0.98\", \"size\":\"728.1\", \"side\":\"SELL\", \"hash\":\"c8340d8ba89b2c0692861d13895a333115f68762\", \"best_bid\":\"0.47\", \"best_ask\":\"0.48\"}], \"timestamp\":\"1785130366457\", \"event_type\":\"price_change\"}","received_at":"2026-07-27T05:32:46.418197Z","schema_version":"clob-market-ws.price_change.v1","sequence":null,"server_hash":null,"server_timestamp":"1785130366457","session_id":"502006c5cfcd437296561ea750c9ec8b","source":"clob_market_ws"},"received_at":"2026-07-27T05:32:46.418197Z","record_id":"b2c2ca62b959ce2bd1b9caa7f7b2e949e344cd5aac1509716c7bf84e417f7040","schema_fingerprint":"4aa3821a28b0b7c2400bc59aba4bcc0a76e971dadd19610d3ad38c768e124dc7","schema_version":"edge-lab-recorder.raw.v1","sequence":null,"source":"clob_market_ws"}
{"event_at":"2026-07-27T05:32:46.470000Z","event_fingerprint":"94baadd96aea71eb0683e87f79d8a247e01680d771f8aa2d2b0a1ff9416ed148","payload":{"connection_id":"efc69d3132f1467b8e898a382b23ac0d","event_at":"2026-07-27T05:32:46.470000Z","event_type":"price_change","frame_hash":"59357792e136398595b8da9fb922064aaa84e65335e8700d6d1d55abcc8b4250","frame_index":0,"kind":"data","monotonic_ns":232349667449416,"payload":{"event_type":"price_change","market":"0x3b40066b5cf3871a2f6237c5628bd8092a206aa998558ac5ec13c4483e31e160","price_changes":[{"asset_id":"14766054693214075530629349735273995982307625376442606753688071083149620216746","best_ask":"0.53","best_bid":"0.52","hash":"9865b5074aa0a40383b6f55f0eb0e9e93e7906a1","price":"0.01","side":"BUY","size":"7873.02"},{"asset_id":"110216635572655435074987471276357323571387854733835379371586402147734167783946","best_ask":"0.48","best_bid":"0.47","hash":"c319f59ce607cc0665968c6976773a72fcc16110","price":"0.99","side":"SELL","size":"7873.02"}],"timestamp":"1785130366470"},"payload_hash":"b3df663b35663995d0bf56448061a513c8a6b734c1be0f442364b32664170ec3","raw_frame":"{\"market\":\"0x3b40066b5cf3871a2f6237c5628bd8092a206aa998558ac5ec13c4483e31e160\", \"price_changes\":[{\"asset_id\":\"14766054693214075530629349735273995982307625376442606753688071083149620216746\", \"price\":\"0.01\", \"size\":\"7873.02\", \"side\":\"BUY\", \"hash\":\"9865b5074aa0a40383b6f55f0eb0e9e93e7906a1\", \"best_bid\":\"0.52\", \"best_ask\":\"0.53\"}, {\"asset_id\":\"110216635572655435074987471276357323571387854733835379371586402147734167783946\", \"price\":\"0.99\", \"size\":\"7873.02\", \"side\":\"SELL\", \"hash\":\"c319f59ce607cc0665968c6976773a72fcc16110\", \"best_bid\":\"0.47\", \"best_ask\":\"0.48\"}], \"timestamp\":\"1785130366470\", \"event_type\":\"price_change\"}","received_at":"2026-07-27T05:32:46.430401Z","schema_version":"clob-market-ws.price_change.v1","sequence":null,"server_hash":null,"server_timestamp":"1785130366470","session_id":"502006c5cfcd437296561ea750c9ec8b","source":"clob_market_ws"},"received_at":"2026-07-27T05:32:46.430401Z","record_id":"f0a4306aec1218286d8ff74946b296acd864a6b4607e0155e416bea58b25eba4","schema_fingerprint":"4aa3821a28b0b7c2400bc59aba4bcc0a76e971dadd19610d3ad38c768e124dc7","schema_version":"edge-lab-recorder.raw.v1","sequence":null,"source":"clob_market_ws"}
{"event_at":"2026-07-27T05:32:46.559000Z","event_fingerprint":"6e8cf0a7aa7a0e825ee9d906b7ad3f45948e173b5039086deeef8398bec58400","payload":{"connection_id":"efc69d3132f1467b8e898a382b23ac0d","event_at":"2026-07-27T05:32:46.559000Z","event_type":"price_change","frame_hash":"d0f15ec723c6bbc61b3ab40d68ea9eb3a5a43d4b6e733044c1802d2c3b7af41d","frame_index":0,"kind":"data","monotonic_ns":232349754939083,"payload":{"event_type":"price_change","market":"0x3b40066b5cf3871a2f6237c5628bd8092a206aa998558ac5ec13c4483e31e160","price_changes":[{"asset_id":"14766054693214075530629349735273995982307625376442606753688071083149620216746","best_ask":"0.53","best_bid":"0.52","hash":"9e240f95207d5f3a51334273c5ea0b14e3ba193b","price":"0.02","side":"BUY","size":"723.1"},{"asset_id":"110216635572655435074987471276357323571387854733835379371586402147734167783946","best_ask":"0.48","best_bid":"0.47","hash":"9e8f0ec4c9a939f23d09cf88cb4dabdcca5cd020","price":"0.98","side":"SELL","size":"723.1"}],"timestamp":"1785130366559"},"payload_hash":"92feaf5965033b7a47059d07b02287d3e65c00c3b48b5f233cdb9be6cf8da9f9","raw_frame":"{\"market\":\"0x3b40066b5cf3871a2f6237c5628bd8092a206aa998558ac5ec13c4483e31e160\", \"price_changes\":[{\"asset_id\":\"14766054693214075530629349735273995982307625376442606753688071083149620216746\", \"price\":\"0.02\", \"size\":\"723.1\", \"side\":\"BUY\", \"hash\":\"9e240f95207d5f3a51334273c5ea0b14e3ba193b\", \"best_bid\":\"0.52\", \"best_ask\":\"0.53\"}, {\"asset_id\":\"110216635572655435074987471276357323571387854733835379371586402147734167783946\", \"price\":\"0.98\", \"size\":\"723.1\", \"side\":\"SELL\", \"hash\":\"9e8f0ec4c9a939f23d09cf88cb4dabdcca5cd020\", \"best_bid\":\"0.47\", \"best_ask\":\"0.48\"}], \"timestamp\":\"1785130366559\", \"event_type\":\"price_change\"}","received_at":"2026-07-27T05:32:46.517882Z","schema_version":"clob-market-ws.price_change.v1","sequence":null,"server_hash":null,"server_timestamp":"1785130366559","session_id":"502006c5cfcd437296561ea750c9ec8b","source":"clob_market_ws"},"received_at":"2026-07-27T05:32:46.517882Z","record_id":"8ec147919719e0a191e5343be88c9501159998855c3b3d162c91bb1ec69834da","schema_fingerprint":"4aa3821a28b0b7c2400bc59aba4bcc0a76e971dadd19610d3ad38c768e124dc7","schema_version":"edge-lab-recorder.raw.v1","sequence":null,"source":"clob_market_ws"}
{"event_at":"2026-07-27T05:32:46.655000Z","event_fingerprint":"c2355e1324aba153d46641351172a9830ea31723be8cf824ab97580833b1e28d","payload":{"connection_id":"efc69d3132f1467b8e898a382b23ac0d","event_at":"2026-07-27T05:32:46.655000Z","event_type":"price_change","frame_hash":"0c7ae143729ae90f7d580de5784428301b063c1a2c0a139f57daf24a655e1bd1","frame_index":0,"kind":"data","monotonic_ns":232349855820500,"payload":{"event_type":"price_change","market":"0x3b40066b5cf3871a2f6237c5628bd8092a206aa998558ac5ec13c4483e31e160","price_changes":[{"asset_id":"14766054693214075530629349735273995982307625376442606753688071083149620216746","best_ask":"0.53","best_bid":"0.52","hash":"434d6ea0d41eafa327b09112354104161d26854a","price":"0.01","side":"BUY","size":"7878.02"},{"asset_id":"110216635572655435074987471276357323571387854733835379371586402147734167783946","best_ask":"0.48","best_bid":"0.47","hash":"f07f18ace45303336b2cdb0379516018a4c3e84a","price":"0.99","side":"SELL","size":"7878.02"}],"timestamp":"1785130366655"},"payload_hash":"61a64901f0a25d77717cbd95552d870cf139b4983ed00a7204ba7ed3cdccd516","raw_frame":"{\"market\":\"0x3b40066b5cf3871a2f6237c5628bd8092a206aa998558ac5ec13c4483e31e160\", \"price_changes\":[{\"asset_id\":\"14766054693214075530629349735273995982307625376442606753688071083149620216746\", \"price\":\"0.01\", \"size\":\"7878.02\", \"side\":\"BUY\", \"hash\":\"434d6ea0d41eafa327b09112354104161d26854a\", \"best_bid\":\"0.52\", \"best_ask\":\"0.53\"}, {\"asset_id\":\"110216635572655435074987471276357323571387854733835379371586402147734167783946\", \"price\":\"0.99\", \"size\":\"7878.02\", \"side\":\"SELL\", \"hash\":\"f07f18ace45303336b2cdb0379516018a4c3e84a\", \"best_bid\":\"0.47\", \"best_ask\":\"0.48\"}], \"timestamp\":\"1785130366655\", \"event_type\":\"price_change\"}","received_at":"2026-07-27T05:32:46.618768Z","schema_version":"clob-market-ws.price_change.v1","sequence":null,"server_hash":null,"server_timestamp":"1785130366655","session_id":"502006c5cfcd437296561ea750c9ec8b","source":"clob_market_ws"},"received_at":"2026-07-27T05:32:46.618768Z","record_id":"37b0b4befc60976f4a08a67509e54598f09c8e3afb6cde002f2406469b494ad8","schema_fingerprint":"4aa3821a28b0b7c2400bc59aba4bcc0a76e971dadd19610d3ad38c768e124dc7","schema_version":"edge-lab-recorder.raw.v1","sequence":null,"source":"clob_market_ws"}
{"event_at":"2026-07-27T05:32:46.762000Z","event_fingerprint":"8ad802836bf364630b7ea8aae4a630fd010908bcc7b93e2104dc4756d856347b","payload":{"connection_id":"efc69d3132f1467b8e898a382b23ac0d","event_at":"2026-07-27T05:32:46.762000Z","event_type":"price_change","frame_hash":"862859f0354603dcf4eeba49e74a337c6a28e39a6c82b3b05bd4a82d6eeedb5f","frame_index":0,"kind":"data","monotonic_ns":232349959827833,"payload":{"event_type":"price_change","market":"0x3b40066b5cf3871a2f6237c5628bd8092a206aa998558ac5ec13c4483e31e160","price_changes":[{"asset_id":"14766054693214075530629349735273995982307625376442606753688071083149620216746","best_ask":"0.53","best_bid":"0.52","hash":"4154adedbe5f3e6af910dd056128d560a9dc4c8b","price":"0.01","side":"BUY","size":"7873.02"},{"asset_id":"110216635572655435074987471276357323571387854733835379371586402147734167783946","best_ask":"0.48","best_bid":"0.47","hash":"b3ba833bb6837b6ae2ddd5ea523b5455fb9d0c18","price":"0.99","side":"SELL","size":"7873.02"}],"timestamp":"1785130366762"},"payload_hash":"1f2a5c50af7b1ad840b5e384381df6c7b5c1eeb0e1c8ccd0a06fb5a35a5fb793","raw_frame":"{\"market\":\"0x3b40066b5cf3871a2f6237c5628bd8092a206aa998558ac5ec13c4483e31e160\", \"price_changes\":[{\"asset_id\":\"14766054693214075530629349735273995982307625376442606753688071083149620216746\", \"price\":\"0.01\", \"size\":\"7873.02\", \"side\":\"BUY\", \"hash\":\"4154adedbe5f3e6af910dd056128d560a9dc4c8b\", \"best_bid\":\"0.52\", \"best_ask\":\"0.53\"}, {\"asset_id\":\"110216635572655435074987471276357323571387854733835379371586402147734167783946\", \"price\":\"0.99\", \"size\":\"7873.02\", \"side\":\"SELL\", \"hash\":\"b3ba833bb6837b6ae2ddd5ea523b5455fb9d0c18\", \"best_bid\":\"0.47\", \"best_ask\":\"0.48\"}], \"timestamp\":\"1785130366762\", \"event_type\":\"price_change\"}","received_at":"2026-07-27T05:32:46.722775Z","schema_version":"clob-market-ws.price_change.v1","sequence":null,"server_hash":null,"server_timestamp":"1785130366762","session_id":"502006c5cfcd437296561ea750c9ec8b","source":"clob_market_ws"},"received_at":"2026-07-27T05:32:46.722775Z","record_id":"34f7da8b77ea4c3d219bc95c7ba479cece79feee902649d692d1820e9d690885","schema_fingerprint":"4aa3821a28b0b7c2400bc59aba4bcc0a76e971dadd19610d3ad38c768e124dc7","schema_version":"edge-lab-recorder.raw.v1","sequence":null,"source":"clob_market_ws"}
{"event_at":"2026-07-27T05:32:46.843000Z","event_fingerprint":"3eaeb1202dbd93794b122bdf03826f3426921d4834bc233a0da877db06feb04f","payload":{"connection_id":"efc69d3132f1467b8e898a382b23ac0d","event_at":"2026-07-27T05:32:46.843000Z","event_type":"best_bid_ask","frame_hash":"9b793c908941c41f9ce3697b3903cc7d791269036048ee924c4cfbae1449718e","frame_index":0,"kind":"data","monotonic_ns":232350038953625,"payload":{"asset_id":"14766054693214075530629349735273995982307625376442606753688071083149620216746","best_ask":"0.53","best_bid":"0.45","event_type":"best_bid_ask","market":"0x3b40066b5cf3871a2f6237c5628bd8092a206aa998558ac5ec13c4483e31e160","spread":"0.08","timestamp":"1785130366843"},"payload_hash":"53a54c6499c91450331207f6b8580fcc9462572acb1634f3188fe5539b1e2cd3","raw_frame":"{\"market\":\"0x3b40066b5cf3871a2f6237c5628bd8092a206aa998558ac5ec13c4483e31e160\", \"asset_id\":\"14766054693214075530629349735273995982307625376442606753688071083149620216746\", \"best_bid\":\"0.45\", \"best_ask\":\"0.53\", \"spread\":\"0.08\", \"timestamp\":\"1785130366843\", \"event_type\":\"best_bid_ask\"}","received_at":"2026-07-27T05:32:46.801901Z","schema_version":"clob-market-ws.best_bid_ask.v1","sequence":null,"server_hash":null,"server_timestamp":"1785130366843","session_id":"502006c5cfcd437296561ea750c9ec8b","source":"clob_market_ws"},"received_at":"2026-07-27T05:32:46.801901Z","record_id":"49ed90f03e1d5bfe2e52589cdc0510fb437654f963173f28d17084306db71f9a","schema_fingerprint":"8488399f31b0337811b13b266be932db7062827c2470b78bd8e9e99bab51d17d","schema_version":"edge-lab-recorder.raw.v1","sequence":null,"source":"clob_market_ws"}
{"event_at":"2026-07-27T05:32:46.843000Z","event_fingerprint":"3b86c8c3a1ce951deb134f38d63a864e8b9a3b16289452ea8969e776caab2bbc","payload":{"connection_id":"efc69d3132f1467b8e898a382b23ac0d","event_at":"2026-07-27T05:32:46.843000Z","event_type":"best_bid_ask","frame_hash":"1de68cd87bf7e4fbcf807b1c7f0bb38914fd05afea9d58fa89ba00e9183671fc","frame_index":0,"kind":"data","monotonic_ns":232350040073958,"payload":{"asset_id":"110216635572655435074987471276357323571387854733835379371586402147734167783946","best_ask":"0.55","best_bid":"0.47","event_type":"best_bid_ask","market":"0x3b40066b5cf3871a2f6237c5628bd8092a206aa998558ac5ec13c4483e31e160","spread":"0.08","timestamp":"1785130366843"},"payload_hash":"a2eb350f16ac7a3ef1dc8ecc4b7979df8394beed141bba8e6e753e0df8c7c65d","raw_frame":"{\"market\":\"0x3b40066b5cf3871a2f6237c5628bd8092a206aa998558ac5ec13c4483e31e160\", \"asset_id\":\"110216635572655435074987471276357323571387854733835379371586402147734167783946\", \"best_bid\":\"0.47\", \"best_ask\":\"0.55\", \"spread\":\"0.08\", \"timestamp\":\"1785130366843\", \"event_type\":\"best_bid_ask\"}","received_at":"2026-07-27T05:32:46.803023Z","schema_version":"clob-market-ws.best_bid_ask.v1","sequence":null,"server_hash":null,"server_timestamp":"1785130366843","session_id":"502006c5cfcd437296561ea750c9ec8b","source":"clob_market_ws"},"received_at":"2026-07-27T05:32:46.803023Z","record_id":"6b882e7b158ef1c1d495ce832c049429cbc7895136084b519683ac93c3e9362b","schema_fingerprint":"8488399f31b0337811b13b266be932db7062827c2470b78bd8e9e99bab51d17d","schema_version":"edge-lab-recorder.raw.v1","sequence":null,"source":"clob_market_ws"}
{"event_at":"2026-07-27T05:32:46.842000Z","event_fingerprint":"e005214bae182b22804cfdb3b1f0efffa1ac0e6380821fda451bffc08e22af46","payload":{"connection_id":"efc69d3132f1467b8e898a382b23ac0d","event_at":"2026-07-27T05:32:46.842000Z","event_type":"price_change","frame_hash":"8d90cbe844042b4d1dc252f834eb3b0a5026699129a2f1bf305319e828e4c7df","frame_index":0,"kind":"data","monotonic_ns":232350041445666,"payload":{"event_type":"price_change","market":"0x3b40066b5cf3871a2f6237c5628bd8092a206aa998558ac5ec13c4483e31e160","price_changes":[{"asset_id":"14766054693214075530629349735273995982307625376442606753688071083149620216746","best_ask":"0.53","best_bid":"0.45","hash":"513cb6f79e49c7daa074027ff6bf3aa89d4b487f","price":"0.45","side":"BUY","size":"144.69"},{"asset_id":"110216635572655435074987471276357323571387854733835379371586402147734167783946","best_ask":"0.55","best_bid":"0.47","hash":"6cc5da7e9db27cffdfc49d27f348ca7579859835","price":"0.55","side":"SELL","size":"144.69"}],"timestamp":"1785130366842"},"payload_hash":"17fc515beae7d79154de9116a6ff094dd4d44b46a35126322adf4fa63e80a1b2","raw_frame":"{\"market\":\"0x3b40066b5cf3871a2f6237c5628bd8092a206aa998558ac5ec13c4483e31e160\", \"price_changes\":[{\"asset_id\":\"14766054693214075530629349735273995982307625376442606753688071083149620216746\", \"price\":\"0.45\", \"size\":\"144.69\", \"side\":\"BUY\", \"hash\":\"513cb6f79e49c7daa074027ff6bf3aa89d4b487f\", \"best_bid\":\"0.45\", \"best_ask\":\"0.53\"}, {\"asset_id\":\"110216635572655435074987471276357323571387854733835379371586402147734167783946\", \"price\":\"0.55\", \"size\":\"144.69\", \"side\":\"SELL\", \"hash\":\"6cc5da7e9db27cffdfc49d27f348ca7579859835\", \"best_bid\":\"0.47\", \"best_ask\":\"0.55\"}], \"timestamp\":\"1785130366842\", \"event_type\":\"price_change\"}","received_at":"2026-07-27T05:32:46.804395Z","schema_version":"clob-market-ws.price_change.v1","sequence":null,"server_hash":null,"server_timestamp":"1785130366842","session_id":"502006c5cfcd437296561ea750c9ec8b","source":"clob_market_ws"},"received_at":"2026-07-27T05:32:46.804395Z","record_id":"e2c73751e8aacffe9bccc5515b89d2085afe0a1221914c46ca9dfbd48b74f7a2","schema_fingerprint":"4aa3821a28b0b7c2400bc59aba4bcc0a76e971dadd19610d3ad38c768e124dc7","schema_version":"edge-lab-recorder.raw.v1","sequence":null,"source":"clob_market_ws"}
{"event_at":"2026-07-27T05:32:46.842000Z","event_fingerprint":"aac9304aab4e87f46b4e6de92dd3c67464221f177b70248ee6525ab90ba1685f","payload":{"connection_id":"efc69d3132f1467b8e898a382b23ac0d","event_at":"2026-07-27T05:32:46.842000Z","event_type":"price_change","frame_hash":"00824a5e681405486a1fa12625cc2e87438caa8a12c325ac3a8ad5785dd8c8ac","frame_index":0,"kind":"data","monotonic_ns":232350042979583,"payload":{"event_type":"price_change","market":"0x3b40066b5cf3871a2f6237c5628bd8092a206aa998558ac5ec13c4483e31e160","price_changes":[{"asset_id":"14766054693214075530629349735273995982307625376442606753688071083149620216746","best_ask":"0.53","best_bid":"0.45","hash":"513cb6f79e49c7daa074027ff6bf3aa89d4b487f","price":"0.52","side":"BUY","size":"0"},{"asset_id":"110216635572655435074987471276357323571387854733835379371586402147734167783946","best_ask":"0.55","best_bid":"0.47","hash":"6cc5da7e9db27cffdfc49d27f348ca7579859835","price":"0.48","side":"SELL","size":"0"}],"timestamp":"1785130366842"},"payload_hash":"53d75e2484b30049861d3f337cba4f7210756e9ccb83106962aead711874b9a2","raw_frame":"{\"market\":\"0x3b40066b5cf3871a2f6237c5628bd8092a206aa998558ac5ec13c4483e31e160\", \"price_changes\":[{\"asset_id\":\"14766054693214075530629349735273995982307625376442606753688071083149620216746\", \"price\":\"0.52\", \"size\":\"0\", \"side\":\"BUY\", \"hash\":\"513cb6f79e49c7daa074027ff6bf3aa89d4b487f\", \"best_bid\":\"0.45\", \"best_ask\":\"0.53\"}, {\"asset_id\":\"110216635572655435074987471276357323571387854733835379371586402147734167783946\", \"price\":\"0.48\", \"size\":\"0\", \"side\":\"SELL\", \"hash\":\"6cc5da7e9db27cffdfc49d27f348ca7579859835\", \"best_bid\":\"0.47\", \"best_ask\":\"0.55\"}], \"timestamp\":\"1785130366842\", \"event_type\":\"price_change\"}","received_at":"2026-07-27T05:32:46.805929Z","schema_version":"clob-market-ws.price_change.v1","sequence":null,"server_hash":null,"server_timestamp":"1785130366842","session_id":"502006c5cfcd437296561ea750c9ec8b","source":"clob_market_ws"},"received_at":"2026-07-27T05:32:46.805929Z","record_id":"eda23fb0f00010240983b0719cd31f38d48d0dfd1a0ac10d1f29bd9bb92bd681","schema_fingerprint":"4aa3821a28b0b7c2400bc59aba4bcc0a76e971dadd19610d3ad38c768e124dc7","schema_version":"edge-lab-recorder.raw.v1","sequence":null,"source":"clob_market_ws"}
{"event_at":"2026-07-27T05:32:46.842000Z","event_fingerprint":"eb012e6e2a396edf6274bdd7560ddeb32d854f0400ec5057d8327b2aad5c692a","payload":{"connection_id":"efc69d3132f1467b8e898a382b23ac0d","event_at":"2026-07-27T05:32:46.842000Z","event_type":"price_change","frame_hash":"3f8be3a7a03ea161c1fc97142009941027ec402ada63d697b72b97acdb5b50ab","frame_index":0,"kind":"data","monotonic_ns":232350044692666,"payload":{"event_type":"price_change","market":"0x3b40066b5cf3871a2f6237c5628bd8092a206aa998558ac5ec13c4483e31e160","price_changes":[{"asset_id":"110216635572655435074987471276357323571387854733835379371586402147734167783946","best_ask":"0.55","best_bid":"0.47","hash":"6cc5da7e9db27cffdfc49d27f348ca7579859835","price":"0.48","side":"SELL","size":"0"},{"asset_id":"14766054693214075530629349735273995982307625376442606753688071083149620216746","best_ask":"0.53","best_bid":"0.45","hash":"513cb6f79e49c7daa074027ff6bf3aa89d4b487f","price":"0.52","side":"BUY","size":"0"}],"timestamp":"1785130366842"},"payload_hash":"dc88f7ffd62e3782921a3468cad59f58ee742c9654874413ad4a228c582cc1bf","raw_frame":"{\"market\":\"0x3b40066b5cf3871a2f6237c5628bd8092a206aa998558ac5ec13c4483e31e160\", \"price_changes\":[{\"asset_id\":\"110216635572655435074987471276357323571387854733835379371586402147734167783946\", \"price\":\"0.48\", \"size\":\"0\", \"side\":\"SELL\", \"hash\":\"6cc5da7e9db27cffdfc49d27f348ca7579859835\", \"best_bid\":\"0.47\", \"best_ask\":\"0.55\"}, {\"asset_id\":\"14766054693214075530629349735273995982307625376442606753688071083149620216746\", \"price\":\"0.52\", \"size\":\"0\", \"side\":\"BUY\", \"hash\":\"513cb6f79e49c7daa074027ff6bf3aa89d4b487f\", \"best_bid\":\"0.45\", \"best_ask\":\"0.53\"}], \"timestamp\":\"1785130366842\", \"event_type\":\"price_change\"}","received_at":"2026-07-27T05:32:46.807640Z","schema_version":"clob-market-ws.price_change.v1","sequence":null,"server_hash":null,"server_timestamp":"1785130366842","session_id":"502006c5cfcd437296561ea750c9ec8b","source":"clob_market_ws"},"received_at":"2026-07-27T05:32:46.807640Z","record_id":"db9d5fc7dbed6ef3343e7f05d74a0ca95c0c95fc3c992a1f3b16df4bd1e1455b","schema_fingerprint":"4aa3821a28b0b7c2400bc59aba4bcc0a76e971dadd19610d3ad38c768e124dc7","schema_version":"edge-lab-recorder.raw.v1","sequence":null,"source":"clob_market_ws"}
{"event_at":"2026-07-27T05:32:46.842000Z","event_fingerprint":"39091fe496a7b57ccb67d8ba915be16ee8c3a256cead62820ae5a54ef90b373e","payload":{"connection_id":"efc69d3132f1467b8e898a382b23ac0d","event_at":"2026-07-27T05:32:46.842000Z","event_type":"price_change","frame_hash":"bb4522f5ece242859dfdd5c220a805738b16f5218e763614f9e82ea33187f930","frame_index":0,"kind":"data","monotonic_ns":232350046261416,"payload":{"event_type":"price_change","market":"0x3b40066b5cf3871a2f6237c5628bd8092a206aa998558ac5ec13c4483e31e160","price_changes":[{"asset_id":"14766054693214075530629349735273995982307625376442606753688071083149620216746","best_ask":"0.53","best_bid":"0.45","hash":"513cb6f79e49c7daa074027ff6bf3aa89d4b487f","price":"0.51","side":"BUY","size":"0"},{"asset_id":"110216635572655435074987471276357323571387854733835379371586402147734167783946","best_ask":"0.55","best_bid":"0.47","hash":"6cc5da7e9db27cffdfc49d27f348ca7579859835","price":"0.49","side":"SELL","size":"0"}],"timestamp":"1785130366842"},"payload_hash":"007dcb110688154cde6388a511988be984a2d76f3d1fd58cdccc9c7b8674664f","raw_frame":"{\"market\":\"0x3b40066b5cf3871a2f6237c5628bd8092a206aa998558ac5ec13c4483e31e160\", \"price_changes\":[{\"asset_id\":\"14766054693214075530629349735273995982307625376442606753688071083149620216746\", \"price\":\"0.51\", \"size\":\"0\", \"side\":\"BUY\", \"hash\":\"513cb6f79e49c7daa074027ff6bf3aa89d4b487f\", \"best_bid\":\"0.45\", \"best_ask\":\"0.53\"}, {\"asset_id\":\"110216635572655435074987471276357323571387854733835379371586402147734167783946\", \"price\":\"0.49\", \"size\":\"0\", \"side\":\"SELL\", \"hash\":\"6cc5da7e9db27cffdfc49d27f348ca7579859835\", \"best_bid\":\"0.47\", \"best_ask\":\"0.55\"}], \"timestamp\":\"1785130366842\", \"event_type\":\"price_change\"}","received_at":"2026-07-27T05:32:46.809209Z","schema_version":"clob-market-ws.price_change.v1","sequence":null,"server_hash":null,"server_timestamp":"1785130366842","session_id":"502006c5cfcd437296561ea750c9ec8b","source":"clob_market_ws"},"received_at":"2026-07-27T05:32:46.809209Z","record_id":"5e958627a2a781d27a30906d0981d15e59d99c3e52959561f79fc078f0aa10aa","schema_fingerprint":"4aa3821a28b0b7c2400bc59aba4bcc0a76e971dadd19610d3ad38c768e124dc7","schema_version":"edge-lab-recorder.raw.v1","sequence":null,"source":"clob_market_ws"}
{"event_at":"2026-07-27T05:32:46.842000Z","event_fingerprint":"9b05d83260991193bd9e411f3ec08481acd6c3acfbbf14ed208055edd5b3fd42","payload":{"connection_id":"efc69d3132f1467b8e898a382b23ac0d","event_at":"2026-07-27T05:32:46.842000Z","event_type":"price_change","frame_hash":"d7d51a7d7c0aa9c77ec166cd82ab6b8dac8b847fda7eeede02bad4a59a95bf33","frame_index":0,"kind":"data","monotonic_ns":232350047771666,"payload":{"event_type":"price_change","market":"0x3b40066b5cf3871a2f6237c5628bd8092a206aa998558ac5ec13c4483e31e160","price_changes":[{"asset_id":"14766054693214075530629349735273995982307625376442606753688071083149620216746","best_ask":"0.53","best_bid":"0.45","hash":"513cb6f79e49c7daa074027ff6bf3aa89d4b487f","price":"0.5","side":"BUY","size":"0"},{"asset_id":"110216635572655435074987471276357323571387854733835379371586402147734167783946","best_ask":"0.55","best_bid":"0.47","hash":"6cc5da7e9db27cffdfc49d27f348ca7579859835","price":"0.5","side":"SELL","size":"0"}],"timestamp":"1785130366842"},"payload_hash":"36b93e6c2f5b682b4ee459269d66049db9b310de910ae912bbdef63f5900aadc","raw_frame":"{\"market\":\"0x3b40066b5cf3871a2f6237c5628bd8092a206aa998558ac5ec13c4483e31e160\", \"price_changes\":[{\"asset_id\":\"14766054693214075530629349735273995982307625376442606753688071083149620216746\", \"price\":\"0.5\", \"size\":\"0\", \"side\":\"BUY\", \"hash\":\"513cb6f79e49c7daa074027ff6bf3aa89d4b487f\", \"best_bid\":\"0.45\", \"best_ask\":\"0.53\"}, {\"asset_id\":\"110216635572655435074987471276357323571387854733835379371586402147734167783946\", \"price\":\"0.5\", \"size\":\"0\", \"side\":\"SELL\", \"hash\":\"6cc5da7e9db27cffdfc49d27f348ca7579859835\", \"best_bid\":\"0.47\", \"best_ask\":\"0.55\"}], \"timestamp\":\"1785130366842\", \"event_type\":\"price_change\"}","received_at":"2026-07-27T05:32:46.810721Z","schema_version":"clob-market-ws.price_change.v1","sequence":null,"server_hash":null,"server_timestamp":"1785130366842","session_id":"502006c5cfcd437296561ea750c9ec8b","source":"clob_market_ws"},"received_at":"2026-07-27T05:32:46.810721Z","record_id":"5ffc0c02d3227fff50cdc99b406be88e73ff0a5fb8a8836f920b570414103005","schema_fingerprint":"4aa3821a28b0b7c2400bc59aba4bcc0a76e971dadd19610d3ad38c768e124dc7","schema_version":"edge-lab-recorder.raw.v1","sequence":null,"source":"clob_market_ws"}
{"event_at":"2026-07-27T05:32:46.842000Z","event_fingerprint":"674c7d1825c7981a6a8042c0ff5ed83ff868a35ae459880065b125e53d37533f","payload":{"connection_id":"efc69d3132f1467b8e898a382b23ac0d","event_at":"2026-07-27T05:32:46.842000Z","event_type":"price_change","frame_hash":"8509dc10f3130a19008746b102727dbe75ef692a8e552caf2841ce1a77862459","frame_index":0,"kind":"data","monotonic_ns":232350050799583,"payload":{"event_type":"price_change","market":"0x3b40066b5cf3871a2f6237c5628bd8092a206aa998558ac5ec13c4483e31e160","price_changes":[{"asset_id":"14766054693214075530629349735273995982307625376442606753688071083149620216746","best_ask":"0.53","best_bid":"0.45","hash":"513cb6f79e49c7daa074027ff6bf3aa89d4b487f","price":"0.49","side":"BUY","size":"0"},{"asset_id":"110216635572655435074987471276357323571387854733835379371586402147734167783946","best_ask":"0.55","best_bid":"0.47","hash":"6cc5da7e9db27cffdfc49d27f348ca7579859835","price":"0.51","side":"SELL","size":"0"}],"timestamp":"1785130366842"},"payload_hash":"5c524906c6ff6812554681f91895cd1c21bda46ff87b62016b1ea78a01935e49","raw_frame":"{\"market\":\"0x3b40066b5cf3871a2f6237c5628bd8092a206aa998558ac5ec13c4483e31e160\", \"price_changes\":[{\"asset_id\":\"14766054693214075530629349735273995982307625376442606753688071083149620216746\", \"price\":\"0.49\", \"size\":\"0\", \"side\":\"BUY\", \"hash\":\"513cb6f79e49c7daa074027ff6bf3aa89d4b487f\", \"best_bid\":\"0.45\", \"best_ask\":\"0.53\"}, {\"asset_id\":\"110216635572655435074987471276357323571387854733835379371586402147734167783946\", \"price\":\"0.51\", \"size\":\"0\", \"side\":\"SELL\", \"hash\":\"6cc5da7e9db27cffdfc49d27f348ca7579859835\", \"best_bid\":\"0.47\", \"best_ask\":\"0.55\"}], \"timestamp\":\"1785130366842\", \"event_type\":\"price_change\"}","received_at":"2026-07-27T05:32:46.813754Z","schema_version":"clob-market-ws.price_change.v1","sequence":null,"server_hash":null,"server_timestamp":"1785130366842","session_id":"502006c5cfcd437296561ea750c9ec8b","source":"clob_market_ws"},"received_at":"2026-07-27T05:32:46.813754Z","record_id":"6babcad4db1c0c5bf11da1b6019ffedc75e41b1f48ed2a2128a41a8ce224548c","schema_fingerprint":"4aa3821a28b0b7c2400bc59aba4bcc0a76e971dadd19610d3ad38c768e124dc7","schema_version":"edge-lab-recorder.raw.v1","sequence":null,"source":"clob_market_ws"}
{"event_at":"2026-07-27T05:32:46.842000Z","event_fingerprint":"774734faa8010ab4a4ea9743234a7c1c45a56c85df3fa1e243ac3263abde56e8","payload":{"connection_id":"efc69d3132f1467b8e898a382b23ac0d","event_at":"2026-07-27T05:32:46.842000Z","event_type":"price_change","frame_hash":"4c8a449a3cdcc7f08f8617116279493e9802aab020d422895edbf191154d3d4b","frame_index":0,"kind":"data","monotonic_ns":232350052571875,"payload":{"event_type":"price_change","market":"0x3b40066b5cf3871a2f6237c5628bd8092a206aa998558ac5ec13c4483e31e160","price_changes":[{"asset_id":"14766054693214075530629349735273995982307625376442606753688071083149620216746","best_ask":"0.53","best_bid":"0.45","hash":"513cb6f79e49c7daa074027ff6bf3aa89d4b487f","price":"0.47","side":"BUY","size":"0"},{"asset_id":"110216635572655435074987471276357323571387854733835379371586402147734167783946","best_ask":"0.55","best_bid":"0.47","hash":"6cc5da7e9db27cffdfc49d27f348ca7579859835","price":"0.53","side":"SELL","size":"0"}],"timestamp":"1785130366842"},"payload_hash":"0f5e52aa8373a5d9ff5555de41f27d1f87eea75c4fa14f83c143728fa963bae5","raw_frame":"{\"market\":\"0x3b40066b5cf3871a2f6237c5628bd8092a206aa998558ac5ec13c4483e31e160\", \"price_changes\":[{\"asset_id\":\"14766054693214075530629349735273995982307625376442606753688071083149620216746\", \"price\":\"0.47\", \"size\":\"0\", \"side\":\"BUY\", \"hash\":\"513cb6f79e49c7daa074027ff6bf3aa89d4b487f\", \"best_bid\":\"0.45\", \"best_ask\":\"0.53\"}, {\"asset_id\":\"110216635572655435074987471276357323571387854733835379371586402147734167783946\", \"price\":\"0.53\", \"size\":\"0\", \"side\":\"SELL\", \"hash\":\"6cc5da7e9db27cffdfc49d27f348ca7579859835\", \"best_bid\":\"0.47\", \"best_ask\":\"0.55\"}], \"timestamp\":\"1785130366842\", \"event_type\":\"price_change\"}","received_at":"2026-07-27T05:32:46.815520Z","schema_version":"clob-market-ws.price_change.v1","sequence":null,"server_hash":null,"server_timestamp":"1785130366842","session_id":"502006c5cfcd437296561ea750c9ec8b","source":"clob_market_ws"},"received_at":"2026-07-27T05:32:46.815520Z","record_id":"5d0644f9cc2fc68fe80aa8e64bc2c5f479e1a7c668cf8a9450614a617408d3ee","schema_fingerprint":"4aa3821a28b0b7c2400bc59aba4bcc0a76e971dadd19610d3ad38c768e124dc7","schema_version":"edge-lab-recorder.raw.v1","sequence":null,"source":"clob_market_ws"}
{"event_at":"2026-07-27T05:32:46.842000Z","event_fingerprint":"978f5ceedb186bcb722c590b3c7a99555897af16f53e67e3b460b060fd317470","payload":{"connection_id":"efc69d3132f1467b8e898a382b23ac0d","event_at":"2026-07-27T05:32:46.842000Z","event_type":"price_change","frame_hash":"8abf1dddcd4b2ccced379a95a7df309653fa3770e460a09bbfdca02d2b9e85ce","frame_index":0,"kind":"data","monotonic_ns":232350055767750,"payload":{"event_type":"price_change","market":"0x3b40066b5cf3871a2f6237c5628bd8092a206aa998558ac5ec13c4483e31e160","price_changes":[{"asset_id":"14766054693214075530629349735273995982307625376442606753688071083149620216746","best_ask":"0.53","best_bid":"0.45","hash":"513cb6f79e49c7daa074027ff6bf3aa89d4b487f","price":"0.46","side":"BUY","size":"0"},{"asset_id":"110216635572655435074987471276357323571387854733835379371586402147734167783946","best_ask":"0.55","best_bid":"0.47","hash":"6cc5da7e9db27cffdfc49d27f348ca7579859835","price":"0.54","side":"SELL","size":"0"}],"timestamp":"1785130366842"},"payload_hash":"339955ed6aa2562bf5f3a1f5c6af55e6b1c6af2a219df8c0efaa7704bc022ae3","raw_frame":"{\"market\":\"0x3b40066b5cf3871a2f6237c5628bd8092a206aa998558ac5ec13c4483e31e160\", \"price_changes\":[{\"asset_id\":\"14766054693214075530629349735273995982307625376442606753688071083149620216746\", \"price\":\"0.46\", \"size\":\"0\", \"side\":\"BUY\", \"hash\":\"513cb6f79e49c7daa074027ff6bf3aa89d4b487f\", \"best_bid\":\"0.45\", \"best_ask\":\"0.53\"}, {\"asset_id\":\"110216635572655435074987471276357323571387854733835379371586402147734167783946\", \"price\":\"0.54\", \"size\":\"0\", \"side\":\"SELL\", \"hash\":\"6cc5da7e9db27cffdfc49d27f348ca7579859835\", \"best_bid\":\"0.47\", \"best_ask\":\"0.55\"}], \"timestamp\":\"1785130366842\", \"event_type\":\"price_change\"}","received_at":"2026-07-27T05:32:46.818717Z","schema_version":"clob-market-ws.price_change.v1","sequence":null,"server_hash":null,"server_timestamp":"1785130366842","session_id":"502006c5cfcd437296561ea750c9ec8b","source":"clob_market_ws"},"received_at":"2026-07-27T05:32:46.818717Z","record_id":"e9e36d9e3650ac13b220deacf932966dc4c700021454f8c0e010fbaf3695ffb9","schema_fingerprint":"4aa3821a28b0b7c2400bc59aba4bcc0a76e971dadd19610d3ad38c768e124dc7","schema_version":"edge-lab-recorder.raw.v1","sequence":null,"source":"clob_market_ws"}
{"event_at":null,"event_fingerprint":"3340e0ef2cb94c890ccbbda105cda05caa04bb402823c1dd26c530a8b11cbadd","payload":{"connection_id":"efc69d3132f1467b8e898a382b23ac0d","detail":{"current_server_timestamp":"1785130366842","entity":"clob_market_ws:14766054693214075530629349735273995982307625376442606753688071083149620216746","previous_server_timestamp":"1785130366843"},"event_type":"anomaly.time_regression","kind":"diagnostic","monotonic_ns":232350057750583,"received_at":"2026-07-27T05:32:46.820701Z","schema_version":"edge-lab-recorder.anomaly.v1","session_id":"502006c5cfcd437296561ea750c9ec8b","source":"clob_market_ws","trigger_frame_hash":"87d38ce21bc5d1f959c27082fed1fa98cb85f326b624c92c76a1266ea5e6e6b5","trigger_server_hash":"513cb6f79e49c7daa074027ff6bf3aa89d4b487f"},"received_at":"2026-07-27T05:32:46.820701Z","record_id":"39fc1d2c0f854d98f0eeb1ca341dc131b182465e135d39640f504805595985bb","schema_fingerprint":"cb1780324c96914017c24d4692a681315845f9745a5a4a3a289c5a43388b35c3","schema_version":"edge-lab-recorder.raw.v1","sequence":null,"source":"clob_market_ws"}
{"event_at":"2026-07-27T05:32:46.842000Z","event_fingerprint":"a07e140ec86977039f7b6aa0faf337148d3655436c0fe15fcbe1ccf61d72ced9","payload":{"connection_id":"efc69d3132f1467b8e898a382b23ac0d","event_at":"2026-07-27T05:32:46.842000Z","event_type":"book","frame_hash":"87d38ce21bc5d1f959c27082fed1fa98cb85f326b624c92c76a1266ea5e6e6b5","frame_index":0,"kind":"data","monotonic_ns":232350057401916,"payload":{"asks":[{"price":"0.99","size":"7843.02"},{"price":"0.98","size":"723.1"},{"price":"0.97","size":"776.43"},{"price":"0.96","size":"628.09"},{"price":"0.95","size":"786.68"},{"price":"0.94","size":"583.2"},{"price":"0.93","size":"553.24"},{"price":"0.92","size":"540.79"},{"price":"0.91","size":"566.6"},{"price":"0.9","size":"103.29"},{"price":"0.89","size":"30.6"},{"price":"0.88","size":"58.4"},{"price":"0.87","size":"26.5"},{"price":"0.86","size":"24.9"},{"price":"0.85","size":"100.5"},{"price":"0.84","size":"22.3"},{"price":"0.83","size":"21.3"},{"price":"0.82","size":"58.3"},{"price":"0.81","size":"27.5"},{"price":"0.8","size":"61.8"},{"price":"0.79","size":"65.62"},{"price":"0.78","size":"24.5"},{"price":"0.77","size":"31.23"},{"price":"0.76","size":"53.39"},{"price":"0.75","size":"51"},{"price":"0.74","size":"21.6"},{"price":"0.73","size":"51.2"},{"price":"0.72","size":"20.9"},{"price":"0.71","size":"20.6"},{"price":"0.7","size":"107.3"},{"price":"0.69","size":"53"},{"price":"0.68","size":"465.28"},{"price":"0.67","size":"192.6"},{"price":"0.66","size":"192.4"},{"price":"0.65","size":"248"},{"price":"0.64","size":"268"},{"price":"0.63","size":"178"},{"price":"0.62","size":"138"},{"price":"0.61","size":"296"},{"price":"0.6","size":"38"},{"price":"0.59","size":"58.36"},{"price":"0.58","size":"80.28"},{"price":"0.57","size":"58.21"},{"price":"0.56","size":"44.4"},{"price":"0.55","size":"47"},{"price":"0.54","size":"418.6"},{"price":"0.53","size":"59.4"}],"asset_id":"14766054693214075530629349735273995982307625376442606753688071083149620216746","bids":[{"price":"0.01","size":"7873.02"},{"price":"0.02","size":"723.1"},{"price":"0.03","size":"613.1"},{"price":"0.04","size":"658.09"},{"price":"0.05","size":"884.2"},{"price":"0.06","size":"575.2"},{"price":"0.07","size":"602.24"},{"price":"0.08","size":"557.79"},{"price":"0.09","size":"551.6"},{"price":"0.1","size":"147.29"},{"price":"0.11","size":"43.6"},{"price":"0.12","size":"40.4"},{"price":"0.13","size":"67.5"},{"price":"0.14","size":"34.9"},{"price":"0.15","size":"80.5"},{"price":"0.16","size":"61.3"},{"price":"0.17","size":"30.3"},{"price":"0.18","size":"28.3"},{"price":"0.19","size":"90.5"},{"price":"0.2","size":"94.8"},{"price":"0.21","size":"59.1"},{"price":"0.22","size":"87.5"},{"price":"0.23","size":"56.89"},{"price":"0.24","size":"56.39"},{"price":"0.25","size":"114"},{"price":"0.26","size":"54.6"},{"price":"0.27","size":"54.2"},{"price":"0.28","size":"83.9"},{"price":"0.29","size":"53.6"},{"price":"0.3","size":"59.49"},{"price":"0.31","size":"83"},{"price":"0.32","size":"52.8"},{"price":"0.33","size":"146.6"},{"price":"0.34","size":"187.4"},{"price":"0.35","size":"159.2"},{"price":"0.36","size":"159"},{"price":"0.37","size":"180.9"},{"price":"0.38","size":"158.7"},{"price":"0.39","size":"158.6"},{"price":"0.4","size":"442.49"},{"price":"0.41","size":"158.4"},{"price":"0.42","size":"246"},{"price":"0.43","size":"176"},{"price":"0.44","size":"176"},{"price":"0.45","size":"144.69"}],"event_type":"book","hash":"513cb6f79e49c7daa074027ff6bf3aa89d4b487f","market":"0x3b40066b5cf3871a2f6237c5628bd8092a206aa998558ac5ec13c4483e31e160","timestamp":"1785130366842"},"payload_hash":"a4d6f359450fa3393c7f177f401ffc8f7f37586880bf105ab53e03e849bd818e","raw_frame":"{\"market\":\"0x3b40066b5cf3871a2f6237c5628bd8092a206aa998558ac5ec13c4483e31e160\", \"asset_id\":\"14766054693214075530629349735273995982307625376442606753688071083149620216746\", \"bids\":[{\"price\":\"0.01\", \"size\":\"7873.02\"}, {\"price\":\"0.02\", \"size\":\"723.1\"}, {\"price\":\"0.03\", \"size\":\"613.1\"}, {\"price\":\"0.04\", \"size\":\"658.09\"}, {\"price\":\"0.05\", \"size\":\"884.2\"}, {\"price\":\"0.06\", \"size\":\"575.2\"}, {\"price\":\"0.07\", \"size\":\"602.24\"}, {\"price\":\"0.08\", \"size\":\"557.79\"}, {\"price\":\"0.09\", \"size\":\"551.6\"}, {\"price\":\"0.1\", \"size\":\"147.29\"}, {\"price\":\"0.11\", \"size\":\"43.6\"}, {\"price\":\"0.12\", \"size\":\"40.4\"}, {\"price\":\"0.13\", \"size\":\"67.5\"}, {\"price\":\"0.14\", \"size\":\"34.9\"}, {\"price\":\"0.15\", \"size\":\"80.5\"}, {\"price\":\"0.16\", \"size\":\"61.3\"}, {\"price\":\"0.17\", \"size\":\"30.3\"}, {\"price\":\"0.18\", \"size\":\"28.3\"}, {\"price\":\"0.19\", \"size\":\"90.5\"}, {\"price\":\"0.2\", \"size\":\"94.8\"}, {\"price\":\"0.21\", \"size\":\"59.1\"}, {\"price\":\"0.22\", \"size\":\"87.5\"}, {\"price\":\"0.23\", \"size\":\"56.89\"}, {\"price\":\"0.24\", \"size\":\"56.39\"}, {\"price\":\"0.25\", \"size\":\"114\"}, {\"price\":\"0.26\", \"size\":\"54.6\"}, {\"price\":\"0.27\", \"size\":\"54.2\"}, {\"price\":\"0.28\", \"size\":\"83.9\"}, {\"price\":\"0.29\", \"size\":\"53.6\"}, {\"price\":\"0.3\", \"size\":\"59.49\"}, {\"price\":\"0.31\", \"size\":\"83\"}, {\"price\":\"0.32\", \"size\":\"52.8\"}, {\"price\":\"0.33\", \"size\":\"146.6\"}, {\"price\":\"0.34\", \"size\":\"187.4\"}, {\"price\":\"0.35\", \"size\":\"159.2\"}, {\"price\":\"0.36\", \"size\":\"159\"}, {\"price\":\"0.37\", \"size\":\"180.9\"}, {\"price\":\"0.38\", \"size\":\"158.7\"}, {\"price\":\"0.39\", \"size\":\"158.6\"}, {\"price\":\"0.4\", \"size\":\"442.49\"}, {\"price\":\"0.41\", \"size\":\"158.4\"}, {\"price\":\"0.42\", \"size\":\"246\"}, {\"price\":\"0.43\", \"size\":\"176\"}, {\"price\":\"0.44\", \"size\":\"176\"}, {\"price\":\"0.45\", \"size\":\"144.69\"}], \"asks\":[{\"price\":\"0.99\", \"size\":\"7843.02\"}, {\"price\":\"0.98\", \"size\":\"723.1\"}, {\"price\":\"0.97\", \"size\":\"776.43\"}, {\"price\":\"0.96\", \"size\":\"628.09\"}, {\"price\":\"0.95\", \"size\":\"786.68\"}, {\"price\":\"0.94\", \"size\":\"583.2\"}, {\"price\":\"0.93\", \"size\":\"553.24\"}, {\"price\":\"0.92\", \"size\":\"540.79\"}, {\"price\":\"0.91\", \"size\":\"566.6\"}, {\"price\":\"0.9\", \"size\":\"103.29\"}, {\"price\":\"0.89\", \"size\":\"30.6\"}, {\"price\":\"0.88\", \"size\":\"58.4\"}, {\"price\":\"0.87\", \"size\":\"26.5\"}, {\"price\":\"0.86\", \"size\":\"24.9\"}, {\"price\":\"0.85\", \"size\":\"100.5\"}, {\"price\":\"0.84\", \"size\":\"22.3\"}, {\"price\":\"0.83\", \"size\":\"21.3\"}, {\"price\":\"0.82\", \"size\":\"58.3\"}, {\"price\":\"0.81\", \"size\":\"27.5\"}, {\"price\":\"0.8\", \"size\":\"61.8\"}, {\"price\":\"0.79\", \"size\":\"65.62\"}, {\"price\":\"0.78\", \"size\":\"24.5\"}, {\"price\":\"0.77\", \"size\":\"31.23\"}, {\"price\":\"0.76\", \"size\":\"53.39\"}, {\"price\":\"0.75\", \"size\":\"51\"}, {\"price\":\"0.74\", \"size\":\"21.6\"}, {\"price\":\"0.73\", \"size\":\"51.2\"}, {\"price\":\"0.72\", \"size\":\"20.9\"}, {\"price\":\"0.71\", \"size\":\"20.6\"}, {\"price\":\"0.7\", \"size\":\"107.3\"}, {\"price\":\"0.69\", \"size\":\"53\"}, {\"price\":\"0.68\", \"size\":\"465.28\"}, {\"price\":\"0.67\", \"size\":\"192.6\"}, {\"price\":\"0.66\", \"size\":\"192.4\"}, {\"price\":\"0.65\", \"size\":\"248\"}, {\"price\":\"0.64\", \"size\":\"268\"}, {\"price\":\"0.63\", \"size\":\"178\"}, {\"price\":\"0.62\", \"size\":\"138\"}, {\"price\":\"0.61\", \"size\":\"296\"}, {\"price\":\"0.6\", \"size\":\"38\"}, {\"price\":\"0.59\", \"size\":\"58.36\"}, {\"price\":\"0.58\", \"size\":\"80.28\"}, {\"price\":\"0.57\", \"size\":\"58.21\"}, {\"price\":\"0.56\", \"size\":\"44.4\"}, {\"price\":\"0.55\", \"size\":\"47\"}, {\"price\":\"0.54\", \"size\":\"418.6\"}, {\"price\":\"0.53\", \"size\":\"59.4\"}], \"hash\":\"513cb6f79e49c7daa074027ff6bf3aa89d4b487f\", \"timestamp\":\"1785130366842\", \"event_type\":\"book\"}","received_at":"2026-07-27T05:32:46.820351Z","schema_version":"clob-market-ws.book.v1","sequence":null,"server_hash":"513cb6f79e49c7daa074027ff6bf3aa89d4b487f","server_timestamp":"1785130366842","session_id":"502006c5cfcd437296561ea750c9ec8b","source":"clob_market_ws"},"received_at":"2026-07-27T05:32:46.820351Z","record_id":"86777987e5fd8610784415f8f4d13644e7572c56b6d8b2fccb4ad50b19f1313b","schema_fingerprint":"dc2caa1c89c6a7426e2e07ff925910cd4d0a8a223a515d4092d91d6d127aacb6","schema_version":"edge-lab-recorder.raw.v1","sequence":null,"source":"clob_market_ws"}
{"event_at":null,"event_fingerprint":"f14fc4ad516b0c235c9d9802e494f4196d513622eaae018e4fdf570e43224e7d","payload":{"connection_id":"efc69d3132f1467b8e898a382b23ac0d","detail":{"current_server_timestamp":"1785130366842","entity":"clob_market_ws:110216635572655435074987471276357323571387854733835379371586402147734167783946","previous_server_timestamp":"1785130366843"},"event_type":"anomaly.time_regression","kind":"diagnostic","monotonic_ns":232350067060791,"received_at":"2026-07-27T05:32:46.830011Z","schema_version":"edge-lab-recorder.anomaly.v1","session_id":"502006c5cfcd437296561ea750c9ec8b","source":"clob_market_ws","trigger_frame_hash":"c2f50c9ff9d02421ff183b35cd39579ce008128c4533d5aa2d0b5b65706b931e","trigger_server_hash":"6cc5da7e9db27cffdfc49d27f348ca7579859835"},"received_at":"2026-07-27T05:32:46.830011Z","record_id":"5c17cfe62a3db01c0b02976de46b1c31f8fbdada0945933816610cfdf02572b2","schema_fingerprint":"cb1780324c96914017c24d4692a681315845f9745a5a4a3a289c5a43388b35c3","schema_version":"edge-lab-recorder.raw.v1","sequence":null,"source":"clob_market_ws"}
