{"event_at":"2026-07-27T05:40:51.303000Z","event_fingerprint":"d2c0f85d7a57d1386637fc44015f6eaa7925fef725f635dea69185645028d853","payload":{"connection_id":"efc69d3132f1467b8e898a382b23ac0d","event_at":"2026-07-27T05:40:51.303000Z","event_type":"price_change","frame_hash":"76521c9d09ab6ce4c42556cf452e1b215a11c9fcb73b5829e00f668759b9ee4e","frame_index":0,"kind":"data","monotonic_ns":232840099230375,"payload":{"event_type":"price_change","market":"0x3b40066b5cf3871a2f6237c5628bd8092a206aa998558ac5ec13c4483e31e160","price_changes":[{"asset_id":"110216635572655435074987471276357323571387854733835379371586402147734167783946","best_ask":"0.36","best_bid":"0.34","hash":"413694dc16391cfcaf118f56a64b3b035d82f580","price":"0.31","side":"BUY","size":"44"},{"asset_id":"14766054693214075530629349735273995982307625376442606753688071083149620216746","best_ask":"0.66","best_bid":"0.64","hash":"7fbfc9ff08e9bc79026b33cbb25eee296af4a1f3","price":"0.69","side":"SELL","size":"44"}],"timestamp":"1785130851303"},"payload_hash":"1a927d20c8d5ead060f9eeb1866067a0e0663a4279e861c773223da4efa12f75","raw_frame":"{\"market\":\"0x3b40066b5cf3871a2f6237c5628bd8092a206aa998558ac5ec13c4483e31e160\", \"price_changes\":[{\"asset_id\":\"110216635572655435074987471276357323571387854733835379371586402147734167783946\", \"price\":\"0.31\", \"size\":\"44\", \"side\":\"BUY\", \"hash\":\"413694dc16391cfcaf118f56a64b3b035d82f580\", \"best_bid\":\"0.34\", \"best_ask\":\"0.36\"}, {\"asset_id\":\"14766054693214075530629349735273995982307625376442606753688071083149620216746\", \"price\":\"0.69\", \"size\":\"44\", \"side\":\"SELL\", \"hash\":\"7fbfc9ff08e9bc79026b33cbb25eee296af4a1f3\", \"best_bid\":\"0.64\", \"best_ask\":\"0.66\"}], \"timestamp\":\"1785130851303\", \"event_type\":\"price_change\"}","received_at":"2026-07-27T05:40:56.865584Z","schema_version":"clob-market-ws.price_change.v1","sequence":null,"server_hash":null,"server_timestamp":"1785130851303","session_id":"502006c5cfcd437296561ea750c9ec8b","source":"clob_market_ws"},"received_at":"2026-07-27T05:40:56.865584Z","record_id":"3f37909f8745f9c627ec692c5266bed0615558512b86c4fe44bd427b1cefa664","schema_fingerprint":"4aa3821a28b0b7c2400bc59aba4bcc0a76e971dadd19610d3ad38c768e124dc7","schema_version":"edge-lab-recorder.raw.v1","sequence":null,"source":"clob_market_ws"}
{"event_at":"2026-07-27T05:40:51.304000Z","event_fingerprint":"937fd9c3b9732b192d0d63587447cfca2c7d1fc8ba696b249860f0c8802666fb","payload":{"connection_id":"efc69d3132f1467b8e898a382b23ac0d","event_at":"2026-07-27T05:40:51.304000Z","event_type":"price_change","frame_hash":"6f2abcf1d6c7cedd540aec03c192d897f80c98ecee432b773f24a6dae6e749c5","frame_index":0,"kind":"data","monotonic_ns":232840105581583,"payload":{"event_type":"price_change","market":"0x3b40066b5cf3871a2f6237c5628bd8092a206aa998558ac5ec13c4483e31e160","price_changes":[{"asset_id":"110216635572655435074987471276357323571387854733835379371586402147734167783946","best_ask":"0.36","best_bid":"0.34","hash":"fc4cc2eb445312c38cc79f969f8af68d48ddee0b","price":"0.32","side":"BUY","size":"29.04"},{"asset_id":"14766054693214075530629349735273995982307625376442606753688071083149620216746","best_ask":"0.66","best_bid":"0.64","hash":"599ce4bf5f54fd0af4a24af8663d1ef78a970be5","price":"0.68","side":"SELL","size":"29.04"}],"timestamp":"1785130851304"},"payload_hash":"5fa8f828f8ddac8ae52c3abb723eeefb6a79f90296aef2a663236052682335a8","raw_frame":"{\"market\":\"0x3b40066b5cf3871a2f6237c5628bd8092a206aa998558ac5ec13c4483e31e160\", \"price_changes\":[{\"asset_id\":\"110216635572655435074987471276357323571387854733835379371586402147734167783946\", \"price\":\"0.32\", \"size\":\"29.04\", \"side\":\"BUY\", \"hash\":\"fc4cc2eb445312c38cc79f969f8af68d48ddee0b\", \"best_bid\":\"0.34\", \"best_ask\":\"0.36\"}, {\"asset_id\":\"14766054693214075530629349735273995982307625376442606753688071083149620216746\", \"price\":\"0.68\", \"size\":\"29.04\", \"side\":\"SELL\", \"hash\":\"599ce4bf5f54fd0af4a24af8663d1ef78a970be5\", \"best_bid\":\"0.64\", \"best_ask\":\"0.66\"}], \"timestamp\":\"1785130851304\", \"event_type\":\"price_change\"}","received_at":"2026-07-27T05:40:56.871936Z","schema_version":"clob-market-ws.price_change.v1","sequence":null,"server_hash":null,"server_timestamp":"1785130851304","session_id":"502006c5cfcd437296561ea750c9ec8b","source":"clob_market_ws"},"received_at":"2026-07-27T05:40:56.871936Z","record_id":"1c9dbadf9e9be22c0aebfea1f1f3cada83e8d78dacaf54e294a8ed2bea37cd2e","schema_fingerprint":"4aa3821a28b0b7c2400bc59aba4bcc0a76e971dadd19610d3ad38c768e124dc7","schema_version":"edge-lab-recorder.raw.v1","sequence":null,"source":"clob_market_ws"}
{"event_at":"2026-07-27T05:40:51.305000Z","event_fingerprint":"39227a3545e151e1a62ba54bc26ec5812d15971df18184589e8637c89ef47731","payload":{"connection_id":"efc69d3132f1467b8e898a382b23ac0d","event_at":"2026-07-27T05:40:51.305000Z","event_type":"price_change","frame_hash":"673fa4910cf822515e58c7b41eae740246a0bd07066b2444778f47be71ee0de6","frame_index":0,"kind":"data","monotonic_ns":232840108792083,"payload":{"event_type":"price_change","market":"0x3b40066b5cf3871a2f6237c5628bd8092a206aa998558ac5ec13c4483e31e160","price_changes":[{"asset_id":"110216635572655435074987471276357323571387854733835379371586402147734167783946","best_ask":"0.36","best_bid":"0.34","hash":"093050b3bf72da2709d8348bafadb8d1da695bba","price":"0.37","side":"SELL","size":"31.6"},{"asset_id":"14766054693214075530629349735273995982307625376442606753688071083149620216746","best_ask":"0.66","best_bid":"0.64","hash":"b6f17e4a61c89efb5d840f5d88e3bb0ae405d815","price":"0.63","side":"BUY","size":"31.6"}],"timestamp":"1785130851305"},"payload_hash":"a13ccf71dc20657bb9e8a4626cb7820a8034d2c978d0c3d23dfc7cca481c286c","raw_frame":"{\"market\":\"0x3b40066b5cf3871a2f6237c5628bd8092a206aa998558ac5ec13c4483e31e160\", \"price_changes\":[{\"asset_id\":\"110216635572655435074987471276357323571387854733835379371586402147734167783946\", \"price\":\"0.37\", \"size\":\"31.6\", \"side\":\"SELL\", \"hash\":\"093050b3bf72da2709d8348bafadb8d1da695bba\", \"best_bid\":\"0.34\", \"best_ask\":\"0.36\"}, {\"asset_id\":\"14766054693214075530629349735273995982307625376442606753688071083149620216746\", \"price\":\"0.63\", \"size\":\"31.6\", \"side\":\"BUY\", \"hash\":\"b6f17e4a61c89efb5d840f5d88e3bb0ae405d815\", \"best_bid\":\"0.64\", \"best_ask\":\"0.66\"}], \"timestamp\":\"1785130851305\", \"event_type\":\"price_change\"}","received_at":"2026-07-27T05:40:56.875145Z","schema_version":"clob-market-ws.price_change.v1","sequence":null,"server_hash":null,"server_timestamp":"1785130851305","session_id":"502006c5cfcd437296561ea750c9ec8b","source":"clob_market_ws"},"received_at":"2026-07-27T05:40:56.875145Z","record_id":"c453adf0ef5eaf6d6a9cef64a7341ed51419f68973258d9f7cd26023ac52fdb6","schema_fingerprint":"4aa3821a28b0b7c2400bc59aba4bcc0a76e971dadd19610d3ad38c768e124dc7","schema_version":"edge-lab-recorder.raw.v1","sequence":null,"source":"clob_market_ws"}
{"event_at":"2026-07-27T05:40:51.305000Z","event_fingerprint":"b35f61f85f16218661c42ee68ae3055d6e62f1e6e68ef744c490c3202a8ab827","payload":{"connection_id":"efc69d3132f1467b8e898a382b23ac0d","event_at":"2026-07-27T05:40:51.305000Z","event_type":"price_change","frame_hash":"925741482c284f13797eff09f5ab715d00c1a9acaf04edafbabf8ea2b78accb1","frame_index":0,"kind":"data","monotonic_ns":232840111920916,"payload":{"event_type":"price_change","market":"0x3b40066b5cf3871a2f6237c5628bd8092a206aa998558ac5ec13c4483e31e160","price_changes":[{"asset_id":"110216635572655435074987471276357323571387854733835379371586402147734167783946","best_ask":"0.36","best_bid":"0.34","hash":"4eb3dde1cbd2a92858e978a5e059516b8362cb6a","price":"0.32","side":"BUY","size":"19.04"},{"asset_id":"14766054693214075530629349735273995982307625376442606753688071083149620216746","best_ask":"0.66","best_bid":"0.64","hash":"b305a8c273e79da58367bddd6c0c9e2ce3340f87","price":"0.68","side":"SELL","size":"19.04"}],"timestamp":"1785130851305"},"payload_hash":"f3e0157f495fb00dfe9e493154142dad46c7491171ca3776b4a044ebf917556b","raw_frame":"{\"market\":\"0x3b40066b5cf3871a2f6237c5628bd8092a206aa998558ac5ec13c4483e31e160\", \"price_changes\":[{\"asset_id\":\"110216635572655435074987471276357323571387854733835379371586402147734167783946\", \"price\":\"0.32\", \"size\":\"19.04\", \"side\":\"BUY\", \"hash\":\"4eb3dde1cbd2a92858e978a5e059516b8362cb6a\", \"best_bid\":\"0.34\", \"best_ask\":\"0.36\"}, {\"asset_id\":\"14766054693214075530629349735273995982307625376442606753688071083149620216746\", \"price\":\"0.68\", \"size\":\"19.04\", \"side\":\"SELL\", \"hash\":\"b305a8c273e79da58367bddd6c0c9e2ce3340f87\", \"best_bid\":\"0.64\", \"best_ask\":\"0.66\"}], \"timestamp\":\"1785130851305\", \"event_type\":\"price_change\"}","received_at":"2026-07-27T05:40:56.878223Z","schema_version":"clob-market-ws.price_change.v1","sequence":null,"server_hash":null,"server_timestamp":"1785130851305","session_id":"502006c5cfcd437296561ea750c9ec8b","source":"clob_market_ws"},"received_at":"2026-07-27T05:40:56.878223Z","record_id":"ae5aa929d743a6a06939e45c25f26244421f8214e8f826a0eeba730ea649cc97","schema_fingerprint":"4aa3821a28b0b7c2400bc59aba4bcc0a76e971dadd19610d3ad38c768e124dc7","schema_version":"edge-lab-recorder.raw.v1","sequence":null,"source":"clob_market_ws"}
{"event_at":"2026-07-27T05:40:51.305000Z","event_fingerprint":"abd62f063aedc18bf20e5cfb85db9caff84c5284c710ba3c7fb62ae6206ac326","payload":{"connection_id":"efc69d3132f1467b8e898a382b23ac0d","event_at":"2026-07-27T05:40:51.305000Z","event_type":"price_change","frame_hash":"15b80458aad5a3c679f0cc4fbec9aee615bfa28af690068b096c6372875f254a","frame_index":0,"kind":"data","monotonic_ns":232840114764500,"payload":{"event_type":"price_change","market":"0x3b40066b5cf3871a2f6237c5628bd8092a206aa998558ac5ec13c4483e31e160","price_changes":[{"asset_id":"14766054693214075530629349735273995982307625376442606753688071083149620216746","best_ask":"0.66","best_bid":"0.64","hash":"b70fb8a8a19ded39d7067e7df163c66c213c1fe5","price":"0.48","side":"BUY","size":"80"},{"asset_id":"110216635572655435074987471276357323571387854733835379371586402147734167783946","best_ask":"0.36","best_bid":"0.34","hash":"51779ab75f7d97cf590f09c77929b8517934be40","price":"0.52","side":"SELL","size":"80"}],"timestamp":"1785130851305"},"payload_hash":"c752606dd0fccda259c17c264c8545bfe640ea9fa95592ae73b45e9d0e2371af","raw_frame":"{\"market\":\"0x3b40066b5cf3871a2f6237c5628bd8092a206aa998558ac5ec13c4483e31e160\", \"price_changes\":[{\"asset_id\":\"14766054693214075530629349735273995982307625376442606753688071083149620216746\", \"price\":\"0.48\", \"size\":\"80\", \"side\":\"BUY\", \"hash\":\"b70fb8a8a19ded39d7067e7df163c66c213c1fe5\", \"best_bid\":\"0.64\", \"best_ask\":\"0.66\"}, {\"asset_id\":\"110216635572655435074987471276357323571387854733835379371586402147734167783946\", \"price\":\"0.52\", \"size\":\"80\", \"side\":\"SELL\", \"hash\":\"51779ab75f7d97cf590f09c77929b8517934be40\", \"best_bid\":\"0.34\", \"best_ask\":\"0.36\"}], \"timestamp\":\"1785130851305\", \"event_type\":\"price_change\"}","received_at":"2026-07-27T05:40:56.881125Z","schema_version":"clob-market-ws.price_change.v1","sequence":null,"server_hash":null,"server_timestamp":"1785130851305","session_id":"502006c5cfcd437296561ea750c9ec8b","source":"clob_market_ws"},"received_at":"2026-07-27T05:40:56.881125Z","record_id":"f8828e6401f0157e14849477b2ea03e6af705a7e7fcd72973e8aa692dd83b658","schema_fingerprint":"4aa3821a28b0b7c2400bc59aba4bcc0a76e971dadd19610d3ad38c768e124dc7","schema_version":"edge-lab-recorder.raw.v1","sequence":null,"source":"clob_market_ws"}
{"event_at":"2026-07-27T05:40:51.306000Z","event_fingerprint":"069cccf14186854208abd17c3e3c4b11131c28e6cb3044c5ddf4ba6504f73e10","payload":{"connection_id":"efc69d3132f1467b8e898a382b23ac0d","event_at":"2026-07-27T05:40:51.306000Z","event_type":"price_change","frame_hash":"827a9a36d53f3af7cdbb0638fbd02112e19400f98f7ac6320acc405f44212dbc","frame_index":0,"kind":"data","monotonic_ns":232840116302458,"payload":{"event_type":"price_change","market":"0x3b40066b5cf3871a2f6237c5628bd8092a206aa998558ac5ec13c4483e31e160","price_changes":[{"asset_id":"14766054693214075530629349735273995982307625376442606753688071083149620216746","best_ask":"0.66","best_bid":"0.64","hash":"370f57e45de11471806084f3fbdd6fd3a8767dcf","price":"0.68","side":"SELL","size":"11"},{"asset_id":"110216635572655435074987471276357323571387854733835379371586402147734167783946","best_ask":"0.36","best_bid":"0.34","hash":"d0c9efbd887266823b846c5b7d89a3e4c3d8db3b","price":"0.32","side":"BUY","size":"11"}],"timestamp":"1785130851306"},"payload_hash":"47b22a3513dd63a70d73d51cef77ddc2d03ab5b66edf66303987dd9e25f2f119","raw_frame":"{\"market\":\"0x3b40066b5cf3871a2f6237c5628bd8092a206aa998558ac5ec13c4483e31e160\", \"price_changes\":[{\"asset_id\":\"14766054693214075530629349735273995982307625376442606753688071083149620216746\", \"price\":\"0.68\", \"size\":\"11\", \"side\":\"SELL\", \"hash\":\"370f57e45de11471806084f3fbdd6fd3a8767dcf\", \"best_bid\":\"0.64\", \"best_ask\":\"0.66\"}, {\"asset_id\":\"110216635572655435074987471276357323571387854733835379371586402147734167783946\", \"price\":\"0.32\", \"size\":\"11\", \"side\":\"BUY\", \"hash\":\"d0c9efbd887266823b846c5b7d89a3e4c3d8db3b\", \"best_bid\":\"0.34\", \"best_ask\":\"0.36\"}], \"timestamp\":\"1785130851306\", \"event_type\":\"price_change\"}","received_at":"2026-07-27T05:40:56.882657Z","schema_version":"clob-market-ws.price_change.v1","sequence":null,"server_hash":null,"server_timestamp":"1785130851306","session_id":"502006c5cfcd437296561ea750c9ec8b","source":"clob_market_ws"},"received_at":"2026-07-27T05:40:56.882657Z","record_id":"eacb7a4f07a96c06c074c62ebde20fe662a902bf50aa6aff9f9a36e59282e5c7","schema_fingerprint":"4aa3821a28b0b7c2400bc59aba4bcc0a76e971dadd19610d3ad38c768e124dc7","schema_version":"edge-lab-recorder.raw.v1","sequence":null,"source":"clob_market_ws"}
{"event_at":"2026-07-27T05:40:51.307000Z","event_fingerprint":"dacf89da923fb632e45104de0ad676d0c530ba4076fb660166d3ad36b4405a00","payload":{"connection_id":"efc69d3132f1467b8e898a382b23ac0d","event_at":"2026-07-27T05:40:51.307000Z","event_type":"best_bid_ask","frame_hash":"f415b88720183fb21591ec019c0602b468008e14407c0925a5f93551442e8e03","frame_index":0,"kind":"data","monotonic_ns":232840119290708,"payload":{"asset_id":"14766054693214075530629349735273995982307625376442606753688071083149620216746","best_ask":"0.66","best_bid":"0.65","event_type":"best_bid_ask","market":"0x3b40066b5cf3871a2f6237c5628bd8092a206aa998558ac5ec13c4483e31e160","spread":"0.01","timestamp":"1785130851307"},"payload_hash":"a6cb5969d7555306911e260be9b4b1b08dfb06ba5072ce2610a46f0ea593ee9d","raw_frame":"{\"market\":\"0x3b40066b5cf3871a2f6237c5628bd8092a206aa998558ac5ec13c4483e31e160\", \"asset_id\":\"14766054693214075530629349735273995982307625376442606753688071083149620216746\", \"best_bid\":\"0.65\", \"best_ask\":\"0.66\", \"spread\":\"0.01\", \"timestamp\":\"1785130851307\", \"event_type\":\"best_bid_ask\"}","received_at":"2026-07-27T05:40:56.885645Z","schema_version":"clob-market-ws.best_bid_ask.v1","sequence":null,"server_hash":null,"server_timestamp":"1785130851307","session_id":"502006c5cfcd437296561ea750c9ec8b","source":"clob_market_ws"},"received_at":"2026-07-27T05:40:56.885645Z","record_id":"01764ceeccab2f2970af9b04cb6c0c005671c2709c98cc4f5ac91d6b93ec7f64","schema_fingerprint":"8488399f31b0337811b13b266be932db7062827c2470b78bd8e9e99bab51d17d","schema_version":"edge-lab-recorder.raw.v1","sequence":null,"source":"clob_market_ws"}
{"event_at":"2026-07-27T05:40:51.307000Z","event_fingerprint":"5c16f6cc075ad2720891fbc8ed8806d22cc1681e68940588d81bb33b983e0917","payload":{"connection_id":"efc69d3132f1467b8e898a382b23ac0d","event_at":"2026-07-27T05:40:51.307000Z","event_type":"best_bid_ask","frame_hash":"b52a80065a8b2d101bf0e2c53b1102369b43e9279709ad70f74eb76976a2521d","frame_index":0,"kind":"data","monotonic_ns":232840121811291,"payload":{"asset_id":"110216635572655435074987471276357323571387854733835379371586402147734167783946","best_ask":"0.35","best_bid":"0.34","event_type":"best_bid_ask","market":"0x3b40066b5cf3871a2f6237c5628bd8092a206aa998558ac5ec13c4483e31e160","spread":"0.01","timestamp":"1785130851307"},"payload_hash":"88308b4f3da3f93149ad03d489fcf353ff683197b2d4b1bc29d9a41004c5204d","raw_frame":"{\"market\":\"0x3b40066b5cf3871a2f6237c5628bd8092a206aa998558ac5ec13c4483e31e160\", \"asset_id\":\"110216635572655435074987471276357323571387854733835379371586402147734167783946\", \"best_bid\":\"0.34\", \"best_ask\":\"0.35\", \"spread\":\"0.01\", \"timestamp\":\"1785130851307\", \"event_type\":\"best_bid_ask\"}","received_at":"2026-07-27T05:40:56.888166Z","schema_version":"clob-market-ws.best_bid_ask.v1","sequence":null,"server_hash":null,"server_timestamp":"1785130851307","session_id":"502006c5cfcd437296561ea750c9ec8b","source":"clob_market_ws"},"received_at":"2026-07-27T05:40:56.888166Z","record_id":"ad319ec01d72ba681a60510856c530cfb253f965ff4210c5a202bd8e2ad6aa7e","schema_fingerprint":"8488399f31b0337811b13b266be932db7062827c2470b78bd8e9e99bab51d17d","schema_version":"edge-lab-recorder.raw.v1","sequence":null,"source":"clob_market_ws"}
{"event_at":"2026-07-27T05:40:51.307000Z","event_fingerprint":"42a4c19e9f16377acf2ed6d7e187dc87a2d259f6d85cdbabb6f26b1efeafe13c","payload":{"connection_id":"efc69d3132f1467b8e898a382b23ac0d","event_at":"2026-07-27T05:40:51.307000Z","event_type":"price_change","frame_hash":"9abcc71be91b5709ce675920389114476f3861382335bc338b866afe3ba2d530","frame_index":0,"kind":"data","monotonic_ns":232840124271000,"payload":{"event_type":"price_change","market":"0x3b40066b5cf3871a2f6237c5628bd8092a206aa998558ac5ec13c4483e31e160","price_changes":[{"asset_id":"14766054693214075530629349735273995982307625376442606753688071083149620216746","best_ask":"0.66","best_bid":"0.65","hash":"b09189489ee7a92c64b1c7ba9afde528190c7e3f","price":"0.65","side":"BUY","size":"22"},{"asset_id":"110216635572655435074987471276357323571387854733835379371586402147734167783946","best_ask":"0.35","best_bid":"0.34","hash":"b151e1d25360fbfc34d91075aa0a4c8cadd9220d","price":"0.35","side":"SELL","size":"22"}],"timestamp":"1785130851307"},"payload_hash":"9a0188bc176f58f9bb24402016eba834b1f69c582d56de53fe560368c784ddfa","raw_frame":"{\"market\":\"0x3b40066b5cf3871a2f6237c5628bd8092a206aa998558ac5ec13c4483e31e160\", \"price_changes\":[{\"asset_id\":\"14766054693214075530629349735273995982307625376442606753688071083149620216746\", \"price\":\"0.65\", \"size\":\"22\", \"side\":\"BUY\", \"hash\":\"b09189489ee7a92c64b1c7ba9afde528190c7e3f\", \"best_bid\":\"0.65\", \"best_ask\":\"0.66\"}, {\"asset_id\":\"110216635572655435074987471276357323571387854733835379371586402147734167783946\", \"price\":\"0.35\", \"size\":\"22\", \"side\":\"SELL\", \"hash\":\"b151e1d25360fbfc34d91075aa0a4c8cadd9220d\", \"best_bid\":\"0.34\", \"best_ask\":\"0.35\"}], \"timestamp\":\"1785130851307\", \"event_type\":\"price_change\"}","received_at":"2026-07-27T05:40:56.890626Z","schema_version":"clob-market-ws.price_change.v1","sequence":null,"server_hash":null,"server_timestamp":"1785130851307","session_id":"502006c5cfcd437296561ea750c9ec8b","source":"clob_market_ws"},"received_at":"2026-07-27T05:40:56.890626Z","record_id":"5739c465a26ba9312cc4700d856987839c57515cde3fbae7cafa93d250782883","schema_fingerprint":"4aa3821a28b0b7c2400bc59aba4bcc0a76e971dadd19610d3ad38c768e124dc7","schema_version":"edge-lab-recorder.raw.v1","sequence":null,"source":"clob_market_ws"}
{"event_at":"2026-07-27T05:40:51.307000Z","event_fingerprint":"67b32d1a601d9d04acba3455421795cfb3e65d8177fb04cf6069fd1d7844dde0","payload":{"connection_id":"efc69d3132f1467b8e898a382b23ac0d","event_at":"2026-07-27T05:40:51.307000Z","event_type":"price_change","frame_hash":"2b6e6987381ef691f6f60e28b03cf4e434882de0951ac29a05d81f9ba8814380","frame_index":0,"kind":"data","monotonic_ns":232840127184541,"payload":{"event_type":"price_change","market":"0x3b40066b5cf3871a2f6237c5628bd8092a206aa998558ac5ec13c4483e31e160","price_changes":[{"asset_id":"110216635572655435074987471276357323571387854733835379371586402147734167783946","best_ask":"0.35","best_bid":"0.34","hash":"777cc684e8fe60665e6404c3f5188bc96878de06","price":"0.3","side":"BUY","size":"109.98"},{"asset_id":"14766054693214075530629349735273995982307625376442606753688071083149620216746","best_ask":"0.66","best_bid":"0.65","hash":"b52c38f2b0f609688560a2f771fb687ebe3a7482","price":"0.7","side":"SELL","size":"109.98"}],"timestamp":"1785130851307"},"payload_hash":"657acba5332894534dbe28f6a3a5026e43bbd9ac7aaf87e97759b8a1d82ba2c0","raw_frame":"{\"market\":\"0x3b40066b5cf3871a2f6237c5628bd8092a206aa998558ac5ec13c4483e31e160\", \"price_changes\":[{\"asset_id\":\"110216635572655435074987471276357323571387854733835379371586402147734167783946\", \"price\":\"0.3\", \"size\":\"109.98\", \"side\":\"BUY\", \"hash\":\"777cc684e8fe60665e6404c3f5188bc96878de06\", \"best_bid\":\"0.34\", \"best_ask\":\"0.35\"}, {\"asset_id\":\"14766054693214075530629349735273995982307625376442606753688071083149620216746\", \"price\":\"0.7\", \"size\":\"109.98\", \"side\":\"SELL\", \"hash\":\"b52c38f2b0f609688560a2f771fb687ebe3a7482\", \"best_bid\":\"0.65\", \"best_ask\":\"0.66\"}], \"timestamp\":\"1785130851307\", \"event_type\":\"price_change\"}","received_at":"2026-07-27T05:40:56.893540Z","schema_version":"clob-market-ws.price_change.v1","sequence":null,"server_hash":null,"server_timestamp":"1785130851307","session_id":"502006c5cfcd437296561ea750c9ec8b","source":"clob_market_ws"},"received_at":"2026-07-27T05:40:56.893540Z","record_id":"a2b6658cf324a0e1a0b6d92e22f5bf54954cc82da2c0d0a332f59cf0e60a66f2","schema_fingerprint":"4aa3821a28b0b7c2400bc59aba4bcc0a76e971dadd19610d3ad38c768e124dc7","schema_version":"edge-lab-recorder.raw.v1","sequence":null,"source":"clob_market_ws"}
{"event_at":"2026-07-27T05:40:51.309000Z","event_fingerprint":"49683853a13fd5fe87ac9f010d1a8790f4fa09ec3515cf548874c90c34f88f70","payload":{"connection_id":"efc69d3132f1467b8e898a382b23ac0d","event_at":"2026-07-27T05:40:51.309000Z","event_type":"price_change","frame_hash":"1c8fe985139cfd172ceee678651603aef846f8753f4727ac20bd2e76281e24e1","frame_index":0,"kind":"data","monotonic_ns":232840130140000,"payload":{"event_type":"price_change","market":"0x3b40066b5cf3871a2f6237c5628bd8092a206aa998558ac5ec13c4483e31e160","price_changes":[{"asset_id":"110216635572655435074987471276357323571387854733835379371586402147734167783946","best_ask":"0.35","best_bid":"0.34","hash":"09d2fb5167015c3deed9ca6d2df5c9c178130221","price":"0.3","side":"BUY","size":"114.98"},{"asset_id":"14766054693214075530629349735273995982307625376442606753688071083149620216746","best_ask":"0.66","best_bid":"0.65","hash":"d676a18f5b369e628651f809eb7a0ac97248623c","price":"0.7","side":"SELL","size":"114.98"}],"timestamp":"1785130851309"},"payload_hash":"bda89539a798a0c725ec8eafbd23a15e28026699e3c359de09fbdb5ab06f8a12","raw_frame":"{\"market\":\"0x3b40066b5cf3871a2f6237c5628bd8092a206aa998558ac5ec13c4483e31e160\", \"price_changes\":[{\"asset_id\":\"110216635572655435074987471276357323571387854733835379371586402147734167783946\", \"price\":\"0.3\", \"size\":\"114.98\", \"side\":\"BUY\", \"hash\":\"09d2fb5167015c3deed9ca6d2df5c9c178130221\", \"best_bid\":\"0.34\", \"best_ask\":\"0.35\"}, {\"asset_id\":\"14766054693214075530629349735273995982307625376442606753688071083149620216746\", \"price\":\"0.7\", \"size\":\"114.98\", \"side\":\"SELL\", \"hash\":\"d676a18f5b369e628651f809eb7a0ac97248623c\", \"best_bid\":\"0.65\", \"best_ask\":\"0.66\"}], \"timestamp\":\"1785130851309\", \"event_type\":\"price_change\"}","received_at":"2026-07-27T05:40:56.896495Z","schema_version":"clob-market-ws.price_change.v1","sequence":null,"server_hash":null,"server_timestamp":"1785130851309","session_id":"502006c5cfcd437296561ea750c9ec8b","source":"clob_market_ws"},"received_at":"2026-07-27T05:40:56.896495Z","record_id":"2f4984e92e0f75eb45386a2cddd97abad7907d168ccef97e89d5e7c4384b23d2","schema_fingerprint":"4aa3821a28b0b7c2400bc59aba4bcc0a76e971dadd19610d3ad38c768e124dc7","schema_version":"edge-lab-recorder.raw.v1","sequence":null,"source":"clob_market_ws"}
{"event_at":"2026-07-27T05:40:51.310000Z","event_fingerprint":"dce081d9757aba6c3613680e4a3756879e617f099373c66ec597f630e37cdafc","payload":{"connection_id":"efc69d3132f1467b8e898a382b23ac0d","event_at":"2026-07-27T05:40:51.310000Z","event_type":"price_change","frame_hash":"a08af557d80f12b4aabaace04a5b3bb41cbcb5b725028928cca1f94bcac1de3e","frame_index":0,"kind":"data","monotonic_ns":232840131951541,"payload":{"event_type":"price_change","market":"0x3b40066b5cf3871a2f6237c5628bd8092a206aa998558ac5ec13c4483e31e160","price_changes":[{"asset_id":"14766054693214075530629349735273995982307625376442606753688071083149620216746","best_ask":"0.66","best_bid":"0.65","hash":"36cc7fb1268b70b1cbd5ccaa494a57e97b8ed124","price":"0.51","side":"BUY","size":"75"},{"asset_id":"110216635572655435074987471276357323571387854733835379371586402147734167783946","best_ask":"0.35","best_bid":"0.34","hash":"6b8df390b296ae12069c4866521f8f20362f5f85","price":"0.49","side":"SELL","size":"75"}],"timestamp":"1785130851310"},"payload_hash":"3d75ef005f68641defb9a6bb0c2fe77ad924d96b3657c954e9595e284c1f513e","raw_frame":"{\"market\":\"0x3b40066b5cf3871a2f6237c5628bd8092a206aa998558ac5ec13c4483e31e160\", \"price_changes\":[{\"asset_id\":\"14766054693214075530629349735273995982307625376442606753688071083149620216746\", \"price\":\"0.51\", \"size\":\"75\", \"side\":\"BUY\", \"hash\":\"36cc7fb1268b70b1cbd5ccaa494a57e97b8ed124\", \"best_bid\":\"0.65\", \"best_ask\":\"0.66\"}, {\"asset_id\":\"110216635572655435074987471276357323571387854733835379371586402147734167783946\", \"price\":\"0.49\", \"size\":\"75\", \"side\":\"SELL\", \"hash\":\"6b8df390b296ae12069c4866521f8f20362f5f85\", \"best_bid\":\"0.34\", \"best_ask\":\"0.35\"}], \"timestamp\":\"1785130851310\", \"event_type\":\"price_change\"}","received_at":"2026-07-27T05:40:56.898312Z","schema_version":"clob-market-ws.price_change.v1","sequence":null,"server_hash":null,"server_timestamp":"1785130851310","session_id":"502006c5cfcd437296561ea750c9ec8b","source":"clob_market_ws"},"received_at":"2026-07-27T05:40:56.898312Z","record_id":"12bc056a3d0222d4b3ece208bc7f1f3e088d19dbdc40f173a20d3f38aa6edfde","schema_fingerprint":"4aa3821a28b0b7c2400bc59aba4bcc0a76e971dadd19610d3ad38c768e124dc7","schema_version":"edge-lab-recorder.raw.v1","sequence":null,"source":"clob_market_ws"}
{"event_at":"2026-07-27T05:40:51.311000Z","event_fingerprint":"1698317b9a36829189b4e55509c76a617411eb182ec08e9a340a26ed553e0a42","payload":{"connection_id":"efc69d3132f1467b8e898a382b23ac0d","event_at":"2026-07-27T05:40:51.311000Z","event_type":"price_change","frame_hash":"85d8632cff25902f4495c12c79ad53cc3989bea8106a5ed96b6feaa508f7c886","frame_index":0,"kind":"data","monotonic_ns":232840134442166,"payload":{"event_type":"price_change","market":"0x3b40066b5cf3871a2f6237c5628bd8092a206aa998558ac5ec13c4483e31e160","price_changes":[{"asset_id":"14766054693214075530629349735273995982307625376442606753688071083149620216746","best_ask":"0.66","best_bid":"0.65","hash":"350bc73d70b25434b86758a161886ee1efbea299","price":"0.01","side":"BUY","size":"5638.02"},{"asset_id":"110216635572655435074987471276357323571387854733835379371586402147734167783946","best_ask":"0.35","best_bid":"0.34","hash":"18e13fc429724a0d63e811acc0677164f75751e2","price":"0.99","side":"SELL","size":"5638.02"}],"timestamp":"1785130851311"},"payload_hash":"9185870459cc1ad0f935be9969c74c9c630685d4a3838e8f49694d07438ec345","raw_frame":"{\"market\":\"0x3b40066b5cf3871a2f6237c5628bd8092a206aa998558ac5ec13c4483e31e160\", \"price_changes\":[{\"asset_id\":\"14766054693214075530629349735273995982307625376442606753688071083149620216746\", \"price\":\"0.01\", \"size\":\"5638.02\", \"side\":\"BUY\", \"hash\":\"350bc73d70b25434b86758a161886ee1efbea299\", \"best_bid\":\"0.65\", \"best_ask\":\"0.66\"}, {\"asset_id\":\"110216635572655435074987471276357323571387854733835379371586402147734167783946\", \"price\":\"0.99\", \"size\":\"5638.02\", \"side\":\"SELL\", \"hash\":\"18e13fc429724a0d63e811acc0677164f75751e2\", \"best_bid\":\"0.34\", \"best_ask\":\"0.35\"}], \"timestamp\":\"1785130851311\", \"event_type\":\"price_change\"}","received_at":"2026-07-27T05:40:56.900797Z","schema_version":"clob-market-ws.price_change.v1","sequence":null,"server_hash":null,"server_timestamp":"1785130851311","session_id":"502006c5cfcd437296561ea750c9ec8b","source":"clob_market_ws"},"received_at":"2026-07-27T05:40:56.900797Z","record_id":"eac4f360f4b71933db69c51ec8bfce89ac4f82bcf2cbe0f8836f61d985c9cf2c","schema_fingerprint":"4aa3821a28b0b7c2400bc59aba4bcc0a76e971dadd19610d3ad38c768e124dc7","schema_version":"edge-lab-recorder.raw.v1","sequence":null,"source":"clob_market_ws"}
{"event_at":"2026-07-27T05:40:51.313000Z","event_fingerprint":"2d7caa4aa031abac73c993ad824738e84975c4307e732c5c964c234e006fd816","payload":{"connection_id":"efc69d3132f1467b8e898a382b23ac0d","event_at":"2026-07-27T05:40:51.313000Z","event_type":"price_change","frame_hash":"37a37d462475b03dd4c5668edfe1e5d644e9a0a26e004f0c3d831a707e7f5e6c","frame_index":0,"kind":"data","monotonic_ns":232840137346541,"payload":{"event_type":"price_change","market":"0x3b40066b5cf3871a2f6237c5628bd8092a206aa998558ac5ec13c4483e31e160","price_changes":[{"asset_id":"110216635572655435074987471276357323571387854733835379371586402147734167783946","best_ask":"0.35","best_bid":"0.34","hash":"df79653df2d4433d841c97976272e9d02bfd6bd4","price":"0.19","side":"BUY","size":"82.5"},{"asset_id":"14766054693214075530629349735273995982307625376442606753688071083149620216746","best_ask":"0.66","best_bid":"0.65","hash":"523b9e5a483e9954623de0096021fe2aa7afb0a5","price":"0.81","side":"SELL","size":"82.5"}],"timestamp":"1785130851313"},"payload_hash":"d3ef39d2ef0f42f3200c2251729b0989ed54b9bef3f26de6399d1c4a285d47a2","raw_frame":"{\"market\":\"0x3b40066b5cf3871a2f6237c5628bd8092a206aa998558ac5ec13c4483e31e160\", \"price_changes\":[{\"asset_id\":\"110216635572655435074987471276357323571387854733835379371586402147734167783946\", \"price\":\"0.19\", \"size\":\"82.5\", \"side\":\"BUY\", \"hash\":\"df79653df2d4433d841c97976272e9d02bfd6bd4\", \"best_bid\":\"0.34\", \"best_ask\":\"0.35\"}, {\"asset_id\":\"14766054693214075530629349735273995982307625376442606753688071083149620216746\", \"price\":\"0.81\", \"size\":\"82.5\", \"side\":\"SELL\", \"hash\":\"523b9e5a483e9954623de0096021fe2aa7afb0a5\", \"best_bid\":\"0.65\", \"best_ask\":\"0.66\"}], \"timestamp\":\"1785130851313\", \"event_type\":\"price_change\"}","received_at":"2026-07-27T05:40:56.903702Z","schema_version":"clob-market-ws.price_change.v1","sequence":null,"server_hash":null,"server_timestamp":"1785130851313","session_id":"502006c5cfcd437296561ea750c9ec8b","source":"clob_market_ws"},"received_at":"2026-07-27T05:40:56.903702Z","record_id":"44996d48a9632e80159ddd832bbc4f75871cde4e355d28a56bfe79f5ee939acc","schema_fingerprint":"4aa3821a28b0b7c2400bc59aba4bcc0a76e971dadd19610d3ad38c768e124dc7","schema_version":"edge-lab-recorder.raw.v1","sequence":null,"source":"clob_market_ws"}
{"event_at":"2026-07-27T05:40:51.314000Z","event_fingerprint":"24f667057d9cbe151314dc9e13989cfdeb8d6329bf68c4bc670dad9afc929bd2","payload":{"connection_id":"efc69d3132f1467b8e898a382b23ac0d","event_at":"2026-07-27T05:40:51.314000Z","event_type":"price_change","frame_hash":"4894543dd7e91b1b34ec92e2e69d4a8d780fe93f886cb8e3a9e56a6a375c6fa6","frame_index":0,"kind":"data","monotonic_ns":232840140309208,"payload":{"event_type":"price_change","market":"0x3b40066b5cf3871a2f6237c5628bd8092a206aa998558ac5ec13c4483e31e160","price_changes":[{"asset_id":"14766054693214075530629349735273995982307625376442606753688071083149620216746","best_ask":"0.66","best_bid":"0.65","hash":"cf7c4ef772687fa3b580902303c2339bfefbd396","price":"0.41","side":"BUY","size":"208"},{"asset_id":"110216635572655435074987471276357323571387854733835379371586402147734167783946","best_ask":"0.35","best_bid":"0.34","hash":"35160d03ede3a1fef70dacf44a3eb92d5a873f6f","price":"0.59","side":"SELL","size":"208"}],"timestamp":"1785130851314"},"payload_hash":"6cce43e3fd91718bc4c145442fe68e22e86d300eeaf0602a7bdb5576ab47437b","raw_frame":"{\"market\":\"0x3b40066b5cf3871a2f6237c5628bd8092a206aa998558ac5ec13c4483e31e160\", \"price_changes\":[{\"asset_id\":\"14766054693214075530629349735273995982307625376442606753688071083149620216746\", \"price\":\"0.41\", \"size\":\"208\", \"side\":\"BUY\", \"hash\":\"cf7c4ef772687fa3b580902303c2339bfefbd396\", \"best_bid\":\"0.65\", \"best_ask\":\"0.66\"}, {\"asset_id\":\"110216635572655435074987471276357323571387854733835379371586402147734167783946\", \"price\":\"0.59\", \"size\":\"208\", \"side\":\"SELL\", \"hash\":\"35160d03ede3a1fef70dacf44a3eb92d5a873f6f\", \"best_bid\":\"0.34\", \"best_ask\":\"0.35\"}], \"timestamp\":\"1785130851314\", \"event_type\":\"price_change\"}","received_at":"2026-07-27T05:40:56.906663Z","schema_version":"clob-market-ws.price_change.v1","sequence":null,"server_hash":null,"server_timestamp":"1785130851314","session_id":"502006c5cfcd437296561ea750c9ec8b","source":"clob_market_ws"},"received_at":"2026-07-27T05:40:56.906663Z","record_id":"bd755366404853f7f454a4493c1aba27776af90c87037956c5ebd4115f259542","schema_fingerprint":"4aa3821a28b0b7c2400bc59aba4bcc0a76e971dadd19610d3ad38c768e124dc7","schema_version":"edge-lab-recorder.raw.v1","sequence":null,"source":"clob_market_ws"}
{"event_at":"2026-07-27T05:40:51.315000Z","event_fingerprint":"babee6c41c7aac2b81d09b99f6c69528be312beb28b4ac588eacf29c9a103456","payload":{"connection_id":"efc69d3132f1467b8e898a382b23ac0d","event_at":"2026-07-27T05:40:51.315000Z","event_type":"price_change","frame_hash":"80691e01b97156d018f2fbf348c79c41f54c70b0739d9eea73b2c94995002523","frame_index":0,"kind":"data","monotonic_ns":232840143264750,"payload":{"event_type":"price_change","market":"0x3b40066b5cf3871a2f6237c5628bd8092a206aa998558ac5ec13c4483e31e160","price_changes":[{"asset_id":"110216635572655435074987471276357323571387854733835379371586402147734167783946","best_ask":"0.35","best_bid":"0.34","hash":"2c3899e2884a37a569b4317284f53c63b8bef493","price":"0.29","side":"BUY","size":"39"},{"asset_id":"14766054693214075530629349735273995982307625376442606753688071083149620216746","best_ask":"0.66","best_bid":"0.65","hash":"9b3f736889bfe9765264f744a10333987ee3e858","price":"0.71","side":"SELL","size":"39"}],"timestamp":"1785130851315"},"payload_hash":"97d033e2f734046ebf263aa607447c2312a1feb973a6e4cb2d58f9f2e66e19ef","raw_frame":"{\"market\":\"0x3b40066b5cf3871a2f6237c5628bd8092a206aa998558ac5ec13c4483e31e160\", \"price_changes\":[{\"asset_id\":\"110216635572655435074987471276357323571387854733835379371586402147734167783946\", \"price\":\"0.29\", \"size\":\"39\", \"side\":\"BUY\", \"hash\":\"2c3899e2884a37a569b4317284f53c63b8bef493\", \"best_bid\":\"0.34\", \"best_ask\":\"0.35\"}, {\"asset_id\":\"14766054693214075530629349735273995982307625376442606753688071083149620216746\", \"price\":\"0.71\", \"size\":\"39\", \"side\":\"SELL\", \"hash\":\"9b3f736889bfe9765264f744a10333987ee3e858\", \"best_bid\":\"0.65\", \"best_ask\":\"0.66\"}], \"timestamp\":\"1785130851315\", \"event_type\":\"price_change\"}","received_at":"2026-07-27T05:40:56.909620Z","schema_version":"clob-market-ws.price_change.v1","sequence":null,"server_hash":null,"server_timestamp":"1785130851315","session_id":"502006c5cfcd437296561ea750c9ec8b","source":"clob_market_ws"},"received_at":"2026-07-27T05:40:56.909620Z","record_id":"d58f400b26cd02e667acc61ffda5634d11af2fe5646b33912a00add7622cf3c5","schema_fingerprint":"4aa3821a28b0b7c2400bc59aba4bcc0a76e971dadd19610d3ad38c768e124dc7","schema_version":"edge-lab-recorder.raw.v1","sequence":null,"source":"clob_market_ws"}
{"event_at":"2026-07-27T05:40:51.315000Z","event_fingerprint":"6e013096d63a25c97476645738044f21475031f2516b41a6f4c41020fc7267e2","payload":{"connection_id":"efc69d3132f1467b8e898a382b23ac0d","event_at":"2026-07-27T05:40:51.315000Z","event_type":"price_change","frame_hash":"39436d96dafad67f476e455bd5b178744ce844ab53afb6b7b116b9b40d1f93df","frame_index":0,"kind":"data","monotonic_ns":232840146217416,"payload":{"event_type":"price_change","market":"0x3b40066b5cf3871a2f6237c5628bd8092a206aa998558ac5ec13c4483e31e160","price_changes":[{"asset_id":"110216635572655435074987471276357323571387854733835379371586402147734167783946","best_ask":"0.35","best_bid":"0.34","hash":"d1bf5445ad1834ec970ef0aaeae89898bf0b3fce","price":"0.3","side":"BUY","size":"97.98"},{"asset_id":"14766054693214075530629349735273995982307625376442606753688071083149620216746","best_ask":"0.66","best_bid":"0.65","hash":"99eb6649bfb3d8ce0a703e6861df26aaa8179b4e","price":"0.7","side":"SELL","size":"97.98"}],"timestamp":"1785130851315"},"payload_hash":"c62b77e38a3f715f4b8d97b300acf208c21b53adb758fa42a590b61c9ee875a3","raw_frame":"{\"market\":\"0x3b40066b5cf3871a2f6237c5628bd8092a206aa998558ac5ec13c4483e31e160\", \"price_changes\":[{\"asset_id\":\"110216635572655435074987471276357323571387854733835379371586402147734167783946\", \"price\":\"0.3\", \"size\":\"97.98\", \"side\":\"BUY\", \"hash\":\"d1bf5445ad1834ec970ef0aaeae89898bf0b3fce\", \"best_bid\":\"0.34\", \"best_ask\":\"0.35\"}, {\"asset_id\":\"14766054693214075530629349735273995982307625376442606753688071083149620216746\", \"price\":\"0.7\", \"size\":\"97.98\", \"side\":\"SELL\", \"hash\":\"99eb6649bfb3d8ce0a703e6861df26aaa8179b4e\", \"best_bid\":\"0.65\", \"best_ask\":\"0.66\"}], \"timestamp\":\"1785130851315\", \"event_type\":\"price_change\"}","received_at":"2026-07-27T05:40:56.912567Z","schema_version":"clob-market-ws.price_change.v1","sequence":null,"server_hash":null,"server_timestamp":"1785130851315","session_id":"502006c5cfcd437296561ea750c9ec8b","source":"clob_market_ws"},"received_at":"2026-07-27T05:40:56.912567Z","record_id":"84a991c8b09a76fee134610f21ad9bbc931ae9a5fabf08ff5d4b1d5a8481e269","schema_fingerprint":"4aa3821a28b0b7c2400bc59aba4bcc0a76e971dadd19610d3ad38c768e124dc7","schema_version":"edge-lab-recorder.raw.v1","sequence":null,"source":"clob_market_ws"}
{"event_at":"2026-07-27T05:40:51.315000Z","event_fingerprint":"a57e271ddaa381be004e03420126910c31ab9a8eb28e186a49c7a71aba2ce590","payload":{"connection_id":"efc69d3132f1467b8e898a382b23ac0d","event_at":"2026-07-27T05:40:51.315000Z","event_type":"price_change","frame_hash":"a9d76f3ec148b79dfa1c1c688e7c4d9c70042ac0ed0770adee562e7ba47d468c","frame_index":0,"kind":"data","monotonic_ns":232840148794416,"payload":{"event_type":"price_change","market":"0x3b40066b5cf3871a2f6237c5628bd8092a206aa998558ac5ec13c4483e31e160","price_changes":[{"asset_id":"14766054693214075530629349735273995982307625376442606753688071083149620216746","best_ask":"0.66","best_bid":"0.65","hash":"ea141852d908a5d85e3ff48f8ced910c3f37dcbb","price":"0.41","side":"BUY","size":"126.7"},{"asset_id":"110216635572655435074987471276357323571387854733835379371586402147734167783946","best_ask":"0.35","best_bid":"0.34","hash":"9454b7f1a00933d121b4707db338b0ebf4eec7b9","price":"0.59","side":"SELL","size":"126.7"}],"timestamp":"1785130851315"},"payload_hash":"efe723abd4db9a30759b8cc3fcc6fc5570d895380b59532b3ec973823cc4ad68","raw_frame":"{\"market\":\"0x3b40066b5cf3871a2f6237c5628bd8092a206aa998558ac5ec13c4483e31e160\", \"price_changes\":[{\"asset_id\":\"14766054693214075530629349735273995982307625376442606753688071083149620216746\", \"price\":\"0.41\", \"size\":\"126.7\", \"side\":\"BUY\", \"hash\":\"ea141852d908a5d85e3ff48f8ced910c3f37dcbb\", \"best_bid\":\"0.65\", \"best_ask\":\"0.66\"}, {\"asset_id\":\"110216635572655435074987471276357323571387854733835379371586402147734167783946\", \"price\":\"0.59\", \"size\":\"126.7\", \"side\":\"SELL\", \"hash\":\"9454b7f1a00933d121b4707db338b0ebf4eec7b9\", \"best_bid\":\"0.34\", \"best_ask\":\"0.35\"}], \"timestamp\":\"1785130851315\", \"event_type\":\"price_change\"}","received_at":"2026-07-27T05:40:56.915149Z","schema_version":"clob-market-ws.price_change.v1","sequence":null,"server_hash":null,"server_timestamp":"1785130851315","session_id":"502006c5cfcd437296561ea750c9ec8b","source":"clob_market_ws"},"received_at":"2026-07-27T05:40:56.915149Z","record_id":"85a856d6b9a26222c914ff8795bbfc2a7f7bf0dad86d3849859c1957d3ccfb69","schema_fingerprint":"4aa3821a28b0b7c2400bc59aba4bcc0a76e971dadd19610d3ad38c768e124dc7","schema_version":"edge-lab-recorder.raw.v1","sequence":null,"source":"clob_market_ws"}
{"event_at":"2026-07-27T05:40:51.316000Z","event_fingerprint":"eab3d0c9ba9f3d4a5df90790a4e273f3937b13d59325a58145de7a5bb5a5212f","payload":{"connection_id":"efc69d3132f1467b8e898a382b23ac0d","event_at":"2026-07-27T05:40:51.316000Z","event_type":"price_change","frame_hash":"5d384b56cff9a73eeaf0ab3273952576c74a81fa97986fb862b7862ed2a52e54","frame_index":0,"kind":"data","monotonic_ns":232840151688333,"payload":{"event_type":"price_change","market":"0x3b40066b5cf3871a2f6237c5628bd8092a206aa998558ac5ec13c4483e31e160","price_changes":[{"asset_id":"110216635572655435074987471276357323571387854733835379371586402147734167783946","best_ask":"0.35","best_bid":"0.34","hash":"30d5aa9e5dcb9b9a975ba98bd4273f38b68a3cc0","price":"0.2","side":"BUY","size":"98"},{"asset_id":"14766054693214075530629349735273995982307625376442606753688071083149620216746","best_ask":"0.66","best_bid":"0.65","hash":"b3d8aae138ec2f58e5306c72e791c9b1d9f197e7","price":"0.8","side":"SELL","size":"98"}],"timestamp":"1785130851316"},"payload_hash":"763b1087b3b3568b5f42743beec463142488d318160cd49e1b270e49225015cf","raw_frame":"{\"market\":\"0x3b40066b5cf3871a2f6237c5628bd8092a206aa998558ac5ec13c4483e31e160\", \"price_changes\":[{\"asset_id\":\"110216635572655435074987471276357323571387854733835379371586402147734167783946\", \"price\":\"0.2\", \"size\":\"98\", \"side\":\"BUY\", \"hash\":\"30d5aa9e5dcb9b9a975ba98bd4273f38b68a3cc0\", \"best_bid\":\"0.34\", \"best_ask\":\"0.35\"}, {\"asset_id\":\"14766054693214075530629349735273995982307625376442606753688071083149620216746\", \"price\":\"0.8\", \"size\":\"98\", \"side\":\"SELL\", \"hash\":\"b3d8aae138ec2f58e5306c72e791c9b1d9f197e7\", \"best_bid\":\"0.65\", \"best_ask\":\"0.66\"}], \"timestamp\":\"1785130851316\", \"event_type\":\"price_change\"}","received_at":"2026-07-27T05:40:56.918044Z","schema_version":"clob-market-ws.price_change.v1","sequence":null,"server_hash":null,"server_timestamp":"1785130851316","session_id":"502006c5cfcd437296561ea750c9ec8b","source":"clob_market_ws"},"received_at":"2026-07-27T05:40:56.918044Z","record_id":"71e2f68e7b0fbb79dc64a54be06182fe4caa788accaf2004e49243c1b05229c5","schema_fingerprint":"4aa3821a28b0b7c2400bc59aba4bcc0a76e971dadd19610d3ad38c768e124dc7","schema_version":"edge-lab-recorder.raw.v1","sequence":null,"source":"clob_market_ws"}
{"event_at":"2026-07-27T05:40:51.316000Z","event_fingerprint":"d80b6029e690971f962de516753268bf6c07b64ef43d527baaeaa8b7192c321a","payload":{"connection_id":"efc69d3132f1467b8e898a382b23ac0d","event_at":"2026-07-27T05:40:51.316000Z","event_type":"price_change","frame_hash":"1f03917af2f3612cb679520cf5ee159fc0de80df0c6061f4c40e0ac4712b7ae9","frame_index":0,"kind":"data","monotonic_ns":232840154573791,"payload":{"event_type":"price_change","market":"0x3b40066b5cf3871a2f6237c5628bd8092a206aa998558ac5ec13c4483e31e160","price_changes":[{"asset_id":"14766054693214075530629349735273995982307625376442606753688071083149620216746","best_ask":"0.66","best_bid":"0.65","hash":"5224be2c44de5b6fcbb3b4bea2308ad99e983fc1","price":"0.62","side":"BUY","size":"138.6"},{"asset_id":"110216635572655435074987471276357323571387854733835379371586402147734167783946","best_ask":"0.35","best_bid":"0.34","hash":"a38fe7ec25423ee9e483acdb30e4637e97853345","price":"0.38","side":"SELL","size":"138.6"}],"timestamp":"1785130851316"},"payload_hash":"f83729ab8d39f4fc8e50b8bcc5d9120804e98482882e659c3406e3c63575126b","raw_frame":"{\"market\":\"0x3b40066b5cf3871a2f6237c5628bd8092a206aa998558ac5ec13c4483e31e160\", \"price_changes\":[{\"asset_id\":\"14766054693214075530629349735273995982307625376442606753688071083149620216746\", \"price\":\"0.62\", \"size\":\"138.6\", \"side\":\"BUY\", \"hash\":\"5224be2c44de5b6fcbb3b4bea2308ad99e983fc1\", \"best_bid\":\"0.65\", \"best_ask\":\"0.66\"}, {\"asset_id\":\"110216635572655435074987471276357323571387854733835379371586402147734167783946\", \"price\":\"0.38\", \"size\":\"138.6\", \"side\":\"SELL\", \"hash\":\"a38fe7ec25423ee9e483acdb30e4637e97853345\", \"best_bid\":\"0.34\", \"best_ask\":\"0.35\"}], \"timestamp\":\"1785130851316\", \"event_type\":\"price_change\"}","received_at":"2026-07-27T05:40:56.920929Z","schema_version":"clob-market-ws.price_change.v1","sequence":null,"server_hash":null,"server_timestamp":"1785130851316","session_id":"502006c5cfcd437296561ea750c9ec8b","source":"clob_market_ws"},"received_at":"2026-07-27T05:40:56.920929Z","record_id":"19e9e7519533d7c0875f8b83f71f9ec7a75307e219c5b2b97f10da5db64f0766","schema_fingerprint":"4aa3821a28b0b7c2400bc59aba4bcc0a76e971dadd19610d3ad38c768e124dc7","schema_version":"edge-lab-recorder.raw.v1","sequence":null,"source":"clob_market_ws"}
{"event_at":"2026-07-27T05:40:51.317000Z","event_fingerprint":"5f42d369ec000969d3459f8ac9ebda3e968df2b12733cfc08878fdc92bb7ac70","payload":{"connection_id":"efc69d3132f1467b8e898a382b23ac0d","event_at":"2026-07-27T05:40:51.317000Z","event_type":"price_change","frame_hash":"ea2d79fe84fe4a3e4af02ead63d9008509649a7ceda19189d71866ff17c779b1","frame_index":0,"kind":"data","monotonic_ns":232840157480208,"payload":{"event_type":"price_change","market":"0x3b40066b5cf3871a2f6237c5628bd8092a206aa998558ac5ec13c4483e31e160","price_changes":[{"asset_id":"14766054693214075530629349735273995982307625376442606753688071083149620216746","best_ask":"0.66","best_bid":"0.65","hash":"06a953d05517fcb8533d267aee765d91a5a64cfd","price":"0.64","side":"BUY","size":"31.6"},{"asset_id":"110216635572655435074987471276357323571387854733835379371586402147734167783946","best_ask":"0.35","best_bid":"0.34","hash":"37d8fdf2d96273469a38ce116ca1df9d28f180fa","price":"0.36","side":"SELL","size":"31.6"}],"timestamp":"1785130851317"},"payload_hash":"c8c9c540c4074344a79a7e8687fcef930c911123c6d06d45090b71ba9c9bbb9f","raw_frame":"{\"market\":\"0x3b40066b5cf3871a2f6237c5628bd8092a206aa998558ac5ec13c4483e31e160\", \"price_changes\":[{\"asset_id\":\"14766054693214075530629349735273995982307625376442606753688071083149620216746\", \"price\":\"0.64\", \"size\":\"31.6\", \"side\":\"BUY\", \"hash\":\"06a953d05517fcb8533d267aee765d91a5a64cfd\", \"best_bid\":\"0.65\", \"best_ask\":\"0.66\"}, {\"asset_id\":\"110216635572655435074987471276357323571387854733835379371586402147734167783946\", \"price\":\"0.36\", \"size\":\"31.6\", \"side\":\"SELL\", \"hash\":\"37d8fdf2d96273469a38ce116ca1df9d28f180fa\", \"best_bid\":\"0.34\", \"best_ask\":\"0.35\"}], \"timestamp\":\"1785130851317\", \"event_type\":\"price_change\"}","received_at":"2026-07-27T05:40:56.923836Z","schema_version":"clob-market-ws.price_change.v1","sequence":null,"server_hash":null,"server_timestamp":"1785130851317","session_id":"502006c5cfcd437296561ea750c9ec8b","source":"clob_market_ws"},"received_at":"2026-07-27T05:40:56.923836Z","record_id":"7b1a312833663bc2517a61c2afd8df94e5fa2b7bddbfba34b0b879d6380601e9","schema_fingerprint":"4aa3821a28b0b7c2400bc59aba4bcc0a76e971dadd19610d3ad38c768e124dc7","schema_version":"edge-lab-recorder.raw.v1","sequence":null,"source":"clob_market_ws"}
{"event_at":"2026-07-27T05:40:51.318000Z","event_fingerprint":"f754359d3d2b528e9280cc7d12fbbb412ac8fd19af724ef77395ccffaf9abae8","payload":{"connection_id":"efc69d3132f1467b8e898a382b23ac0d","event_at":"2026-07-27T05:40:51.318000Z","event_type":"price_change","frame_hash":"a9d64701852b5e72add96a348b72f6e61f6f024d92c8dfa03eedca0b228c38dc","frame_index":0,"kind":"data","monotonic_ns":232840160386041,"payload":{"event_type":"price_change","market":"0x3b40066b5cf3871a2f6237c5628bd8092a206aa998558ac5ec13c4483e31e160","price_changes":[{"asset_id":"14766054693214075530629349735273995982307625376442606753688071083149620216746","best_ask":"0.66","best_bid":"0.65","hash":"69588c3b1b32c06a6e274b57ee1b4b8c1bcdc783","price":"0.58","side":"BUY","size":"33"},{"asset_id":"110216635572655435074987471276357323571387854733835379371586402147734167783946","best_ask":"0.35","best_bid":"0.34","hash":"4858c4ffdea5295fc45472f78886613f0f6d1407","price":"0.42","side":"SELL","size":"33"}],"timestamp":"1785130851318"},"payload_hash":"890e12b259b9a04c0a47a992b17d3889448a19bed8b00f4e3a3bfbffdde55f46","raw_frame":"{\"market\":\"0x3b40066b5cf3871a2f6237c5628bd8092a206aa998558ac5ec13c4483e31e160\", \"price_changes\":[{\"asset_id\":\"14766054693214075530629349735273995982307625376442606753688071083149620216746\", \"price\":\"0.58\", \"size\":\"33\", \"side\":\"BUY\", \"hash\":\"69588c3b1b32c06a6e274b57ee1b4b8c1bcdc783\", \"best_bid\":\"0.65\", \"best_ask\":\"0.66\"}, {\"asset_id\":\"110216635572655435074987471276357323571387854733835379371586402147734167783946\", \"price\":\"0.42\", \"size\":\"33\", \"side\":\"SELL\", \"hash\":\"4858c4ffdea5295fc45472f78886613f0f6d1407\", \"best_bid\":\"0.34\", \"best_ask\":\"0.35\"}], \"timestamp\":\"1785130851318\", \"event_type\":\"price_change\"}","received_at":"2026-07-27T05:40:56.926741Z","schema_version":"clob-market-ws.price_change.v1","sequence":null,"server_hash":null,"server_timestamp":"1785130851318","session_id":"502006c5cfcd437296561ea750c9ec8b","source":"clob_market_ws"},"received_at":"2026-07-27T05:40:56.926741Z","record_id":"c8756dbe0b96d04fed7ab4ba0bcdb301db5b9a9fc92a4a17b84378438db6596d","schema_fingerprint":"4aa3821a28b0b7c2400bc59aba4bcc0a76e971dadd19610d3ad38c768e124dc7","schema_version":"edge-lab-recorder.raw.v1","sequence":null,"source":"clob_market_ws"}
{"event_at":"2026-07-27T05:40:51.318000Z","event_fingerprint":"04cb14bd0a2556660e813643fa7ac8a5a74714c61c1882af9abefa178c8ca29a","payload":{"connection_id":"efc69d3132f1467b8e898a382b23ac0d","event_at":"2026-07-27T05:40:51.318000Z","event_type":"price_change","frame_hash":"0a9933a36445eeff954481b98831392cb9b620a570ec358ffc2cfeedf5539f40","frame_index":0,"kind":"data","monotonic_ns":232840163277916,"payload":{"event_type":"price_change","market":"0x3b40066b5cf3871a2f6237c5628bd8092a206aa998558ac5ec13c4483e31e160","price_changes":[{"asset_id":"110216635572655435074987471276357323571387854733835379371586402147734167783946","best_ask":"0.35","best_bid":"0.34","hash":"9d5c861cb5e31044467e883eab1952d40ccabb52","price":"0.19","side":"BUY","size":"108.5"},{"asset_id":"14766054693214075530629349735273995982307625376442606753688071083149620216746","best_ask":"0.66","best_bid":"0.65","hash":"ce4093c070804f008aafe9ed535d8acb0e8f462f","price":"0.81","side":"SELL","size":"108.5"}],"timestamp":"1785130851318"},"payload_hash":"e3121ad0508a0bad64c024df7bb2a251f65e6ba58849b471fd9007065b32aebe","raw_frame":"{\"market\":\"0x3b40066b5cf3871a2f6237c5628bd8092a206aa998558ac5ec13c4483e31e160\", \"price_changes\":[{\"asset_id\":\"110216635572655435074987471276357323571387854733835379371586402147734167783946\", \"price\":\"0.19\", \"size\":\"108.5\", \"side\":\"BUY\", \"hash\":\"9d5c861cb5e31044467e883eab1952d40ccabb52\", \"best_bid\":\"0.34\", \"best_ask\":\"0.35\"}, {\"asset_id\":\"14766054693214075530629349735273995982307625376442606753688071083149620216746\", \"price\":\"0.81\", \"size\":\"108.5\", \"side\":\"SELL\", \"hash\":\"ce4093c070804f008aafe9ed535d8acb0e8f462f\", \"best_bid\":\"0.65\", \"best_ask\":\"0.66\"}], \"timestamp\":\"1785130851318\", \"event_type\":\"price_change\"}","received_at":"2026-07-27T05:40:56.929633Z","schema_version":"clob-market-ws.price_change.v1","sequence":null,"server_hash":null,"server_timestamp":"1785130851318","session_id":"502006c5cfcd437296561ea750c9ec8b","source":"clob_market_ws"},"received_at":"2026-07-27T05:40:56.929633Z","record_id":"b722ccfe1535c2396eec67101cf574d232eea2a27cd3e6aebd2a733437d347bd","schema_fingerprint":"4aa3821a28b0b7c2400bc59aba4bcc0a76e971dadd19610d3ad38c768e124dc7","schema_version":"edge-lab-recorder.raw.v1","sequence":null,"source":"clob_market_ws"}
{"event_at":"2026-07-27T05:40:51.319000Z","event_fingerprint":"59a7017ac214921b0c424bb03259e744bee15c1f24523135067eb71aa847de86","payload":{"connection_id":"efc69d3132f1467b8e898a382b23ac0d","event_at":"2026-07-27T05:40:51.319000Z","event_type":"price_change","frame_hash":"ab866bfdcfed79f277ec89dcb9fa54f9600d554d3de0a49ddf735fdbd969a4e6","frame_index":0,"kind":"data","monotonic_ns":232840165254833,"payload":{"event_type":"price_change","market":"0x3b40066b5cf3871a2f6237c5628bd8092a206aa998558ac5ec13c4483e31e160","price_changes":[{"asset_id":"110216635572655435074987471276357323571387854733835379371586402147734167783946","best_ask":"0.35","best_bid":"0.34","hash":"4f975100f116bbb9c5f96fa257c880144eeedd4a","price":"0.31","side":"BUY","size":"65"},{"asset_id":"14766054693214075530629349735273995982307625376442606753688071083149620216746","best_ask":"0.66","best_bid":"0.65","hash":"dc5b3b0d444ff412215441b81f90c2c43dd2eacb","price":"0.69","side":"SELL","size":"65"}],"timestamp":"1785130851319"},"payload_hash":"1c54eb1b78de340520d0d9d1a8a9d7db52bcb991aeae6fc39d9b6c84d6704698","raw_frame":"{\"market\":\"0x3b40066b5cf3871a2f6237c5628bd8092a206aa998558ac5ec13c4483e31e160\", \"price_changes\":[{\"asset_id\":\"110216635572655435074987471276357323571387854733835379371586402147734167783946\", \"price\":\"0.31\", \"size\":\"65\", \"side\":\"BUY\", \"hash\":\"4f975100f116bbb9c5f96fa257c880144eeedd4a\", \"best_bid\":\"0.34\", \"best_ask\":\"0.35\"}, {\"asset_id\":\"14766054693214075530629349735273995982307625376442606753688071083149620216746\", \"price\":\"0.69\", \"size\":\"65\", \"side\":\"SELL\", \"hash\":\"dc5b3b0d444ff412215441b81f90c2c43dd2eacb\", \"best_bid\":\"0.65\", \"best_ask\":\"0.66\"}], \"timestamp\":\"1785130851319\", \"event_type\":\"price_change\"}","received_at":"2026-07-27T05:40:56.931616Z","schema_version":"clob-market-ws.price_change.v1","sequence":null,"server_hash":null,"server_timestamp":"1785130851319","session_id":"502006c5cfcd437296561ea750c9ec8b","source":"clob_market_ws"},"received_at":"2026-07-27T05:40:56.931616Z","record_id":"b626ccfcb4559e5498e754e05e46edf19f604f39d83a69cea77aa005f2e3a256","schema_fingerprint":"4aa3821a28b0b7c2400bc59aba4bcc0a76e971dadd19610d3ad38c768e124dc7","schema_version":"edge-lab-recorder.raw.v1","sequence":null,"source":"clob_market_ws"}
{"event_at":"2026-07-27T05:40:51.320000Z","event_fingerprint":"128b28117d984bb9810910f804dc048f31474aa0994253daeaba2e5b1879d750","payload":{"connection_id":"efc69d3132f1467b8e898a382b23ac0d","event_at":"2026-07-27T05:40:51.320000Z","event_type":"price_change","frame_hash":"707012eb145d0dc9b84f1f4c2703d26511e335e4cba73e1014d7fdfb2cf6152c","frame_index":0,"kind":"data","monotonic_ns":232840167706791,"payload":{"event_type":"price_change","market":"0x3b40066b5cf3871a2f6237c5628bd8092a206aa998558ac5ec13c4483e31e160","price_changes":[{"asset_id":"14766054693214075530629349735273995982307625376442606753688071083149620216746","best_ask":"0.66","best_bid":"0.65","hash":"b371a374dc680ee89ed18470105323f9b838438c","price":"0.41","side":"BUY","size":"45.4"},{"asset_id":"110216635572655435074987471276357323571387854733835379371586402147734167783946","best_ask":"0.35","best_bid":"0.34","hash":"96297a7029e2cb2ef0d45cf1c17c7dc0f586df3c","price":"0.59","side":"SELL","size":"45.4"}],"timestamp":"1785130851320"},"payload_hash":"67dd8e92ae97d04cfb70da69aa4d2b277e363d15328cc5a6edaf63581f5b6e4a","raw_frame":"{\"market\":\"0x3b40066b5cf3871a2f6237c5628bd8092a206aa998558ac5ec13c4483e31e160\", \"price_changes\":[{\"asset_id\":\"14766054693214075530629349735273995982307625376442606753688071083149620216746\", \"price\":\"0.41\", \"size\":\"45.4\", \"side\":\"BUY\", \"hash\":\"b371a374dc680ee89ed18470105323f9b838438c\", \"best_bid\":\"0.65\", \"best_ask\":\"0.66\"}, {\"asset_id\":\"110216635572655435074987471276357323571387854733835379371586402147734167783946\", \"price\":\"0.59\", \"size\":\"45.4\", \"side\":\"SELL\", \"hash\":\"96297a7029e2cb2ef0d45cf1c17c7dc0f586df3c\", \"best_bid\":\"0.34\", \"best_ask\":\"0.35\"}], \"timestamp\":\"1785130851320\", \"event_type\":\"price_change\"}","received_at":"2026-07-27T05:40:56.934061Z","schema_version":"clob-market-ws.price_change.v1","sequence":null,"server_hash":null,"server_timestamp":"1785130851320","session_id":"502006c5cfcd437296561ea750c9ec8b","source":"clob_market_ws"},"received_at":"2026-07-27T05:40:56.934061Z","record_id":"e6efb683aedbe43c933ebf6c1d4d97c521eb8643706201b790178e7515d319fb","schema_fingerprint":"4aa3821a28b0b7c2400bc59aba4bcc0a76e971dadd19610d3ad38c768e124dc7","schema_version":"edge-lab-recorder.raw.v1","sequence":null,"source":"clob_market_ws"}
{"event_at":"2026-07-27T05:40:51.320000Z","event_fingerprint":"1126e837db98728d1597c98fd17254ca193893e2c79acb55549033b7b98f853b","payload":{"connection_id":"efc69d3132f1467b8e898a382b23ac0d","event_at":"2026-07-27T05:40:51.320000Z","event_type":"price_change","frame_hash":"1870b8bbc73e72a18e0c1f9e44a3d29803ce99a908b02b30e7516c9ea8c2ce90","frame_index":0,"kind":"data","monotonic_ns":232840170666500,"payload":{"event_type":"price_change","market":"0x3b40066b5cf3871a2f6237c5628bd8092a206aa998558ac5ec13c4483e31e160","price_changes":[{"asset_id":"110216635572655435074987471276357323571387854733835379371586402147734167783946","best_ask":"0.35","best_bid":"0.34","hash":"61c3b9a40aa25a8a3e94597bc84e83d105a4c0c4","price":"0.2","side":"BUY","size":"123"},{"asset_id":"14766054693214075530629349735273995982307625376442606753688071083149620216746","best_ask":"0.66","best_bid":"0.65","hash":"1f2a319841b5852e06cde804f272bc162e712b6c","price":"0.8","side":"SELL","size":"123"}],"timestamp":"1785130851320"},"payload_hash":"188ec141574c1af2b946920c6c349b57d6cc1c55b28c85937f49204e373e56c4","raw_frame":"{\"market\":\"0x3b40066b5cf3871a2f6237c5628bd8092a206aa998558ac5ec13c4483e31e160\", \"price_changes\":[{\"asset_id\":\"110216635572655435074987471276357323571387854733835379371586402147734167783946\", \"price\":\"0.2\", \"size\":\"123\", \"side\":\"BUY\", \"hash\":\"61c3b9a40aa25a8a3e94597bc84e83d105a4c0c4\", \"best_bid\":\"0.34\", \"best_ask\":\"0.35\"}, {\"asset_id\":\"14766054693214075530629349735273995982307625376442606753688071083149620216746\", \"price\":\"0.8\", \"size\":\"123\", \"side\":\"SELL\", \"hash\":\"1f2a319841b5852e06cde804f272bc162e712b6c\", \"best_bid\":\"0.65\", \"best_ask\":\"0.66\"}], \"timestamp\":\"1785130851320\", \"event_type\":\"price_change\"}","received_at":"2026-07-27T05:40:56.937021Z","schema_version":"clob-market-ws.price_change.v1","sequence":null,"server_hash":null,"server_timestamp":"1785130851320","session_id":"502006c5cfcd437296561ea750c9ec8b","source":"clob_market_ws"},"received_at":"2026-07-27T05:40:56.937021Z","record_id":"98471262bf475e84434d9b50b193c2dc6f02ed2c348c29fb8e12b9db9a32e21b","schema_fingerprint":"4aa3821a28b0b7c2400bc59aba4bcc0a76e971dadd19610d3ad38c768e124dc7","schema_version":"edge-lab-recorder.raw.v1","sequence":null,"source":"clob_market_ws"}
{"event_at":"2026-07-27T05:40:51.321000Z","event_fingerprint":"aa03a50e352887f0715661400c261ce15cdcf3f01721832c7c963695aaaa33e2","payload":{"connection_id":"efc69d3132f1467b8e898a382b23ac0d","event_at":"2026-07-27T05:40:51.321000Z","event_type":"price_change","frame_hash":"a2c9186a217938d9af9ab3aa3df96a2acbc7ff7ba4b3c01b15aa2b60f256eed3","frame_index":0,"kind":"data","monotonic_ns":232840173698541,"payload":{"event_type":"price_change","market":"0x3b40066b5cf3871a2f6237c5628bd8092a206aa998558ac5ec13c4483e31e160","price_changes":[{"asset_id":"110216635572655435074987471276357323571387854733835379371586402147734167783946","best_ask":"0.35","best_bid":"0.34","hash":"9b96efbd8d5adb0ec06dabab0b44c0c8ad4c6442","price":"0.33","side":"BUY","size":"11"},{"asset_id":"14766054693214075530629349735273995982307625376442606753688071083149620216746","best_ask":"0.66","best_bid":"0.65","hash":"a31b04b2b60f84a275a680f8afb20a0a83d01df3","price":"0.67","side":"SELL","size":"11"}],"timestamp":"1785130851321"},"payload_hash":"12d92ca7d324301d272094bfd71f4c9e7c93dba0b88bcceafdf6fe5d386209d2","raw_frame":"{\"market\":\"0x3b40066b5cf3871a2f6237c5628bd8092a206aa998558ac5ec13c4483e31e160\", \"price_changes\":[{\"asset_id\":\"110216635572655435074987471276357323571387854733835379371586402147734167783946\", \"price\":\"0.33\", \"size\":\"11\", \"side\":\"BUY\", \"hash\":\"9b96efbd8d5adb0ec06dabab0b44c0c8ad4c6442\", \"best_bid\":\"0.34\", \"best_ask\":\"0.35\"}, {\"asset_id\":\"14766054693214075530629349735273995982307625376442606753688071083149620216746\", \"price\":\"0.67\", \"size\":\"11\", \"side\":\"SELL\", \"hash\":\"a31b04b2b60f84a275a680f8afb20a0a83d01df3\", \"best_bid\":\"0.65\", \"best_ask\":\"0.66\"}], \"timestamp\":\"1785130851321\", \"event_type\":\"price_change\"}","received_at":"2026-07-27T05:40:56.940050Z","schema_version":"clob-market-ws.price_change.v1","sequence":null,"server_hash":null,"server_timestamp":"1785130851321","session_id":"502006c5cfcd437296561ea750c9ec8b","source":"clob_market_ws"},"received_at":"2026-07-27T05:40:56.940050Z","record_id":"cca2ff02774073274abda686a688cdcb1103ac835a192641d61aafb71b82c013","schema_fingerprint":"4aa3821a28b0b7c2400bc59aba4bcc0a76e971dadd19610d3ad38c768e124dc7","schema_version":"edge-lab-recorder.raw.v1","sequence":null,"source":"clob_market_ws"}
{"event_at":"2026-07-27T05:40:51.323000Z","event_fingerprint":"003cfc5f2de7e506613b68e5aed38f53137d19e71989213a2f06e12f5751f8a0","payload":{"connection_id":"efc69d3132f1467b8e898a382b23ac0d","event_at":"2026-07-27T05:40:51.323000Z","event_type":"price_change","frame_hash":"1d56293780feb30657b9b3fcdfa9c998bcb65a5941848add2eb6b9eedc1bd8b5","frame_index":0,"kind":"data","monotonic_ns":232840176656708,"payload":{"event_type":"price_change","market":"0x3b40066b5cf3871a2f6237c5628bd8092a206aa998558ac5ec13c4483e31e160","price_changes":[{"asset_id":"110216635572655435074987471276357323571387854733835379371586402147734167783946","best_ask":"0.35","best_bid":"0.34","hash":"a9358d855103238ad1b5df6e8984cad356e2bcb9","price":"0.29","side":"BUY","size":"44"},{"asset_id":"14766054693214075530629349735273995982307625376442606753688071083149620216746","best_ask":"0.66","best_bid":"0.65","hash":"2e0548eaa50947c21996110b1ef799f3c523a883","price":"0.71","side":"SELL","size":"44"}],"timestamp":"1785130851323"},"payload_hash":"676b9d53d9980208f634a51a12c0b6831cc6d405aa80cbca924eebba017c0cdd","raw_frame":"{\"market\":\"0x3b40066b5cf3871a2f6237c5628bd8092a206aa998558ac5ec13c4483e31e160\", \"price_changes\":[{\"asset_id\":\"110216635572655435074987471276357323571387854733835379371586402147734167783946\", \"price\":\"0.29\", \"size\":\"44\", \"side\":\"BUY\", \"hash\":\"a9358d855103238ad1b5df6e8984cad356e2bcb9\", \"best_bid\":\"0.34\", \"best_ask\":\"0.35\"}, {\"asset_id\":\"14766054693214075530629349735273995982307625376442606753688071083149620216746\", \"price\":\"0.71\", \"size\":\"44\", \"side\":\"SELL\", \"hash\":\"2e0548eaa50947c21996110b1ef799f3c523a883\", \"best_bid\":\"0.65\", \"best_ask\":\"0.66\"}], \"timestamp\":\"1785130851323\", \"event_type\":\"price_change\"}","received_at":"2026-07-27T05:40:56.943010Z","schema_version":"clob-market-ws.price_change.v1","sequence":null,"server_hash":null,"server_timestamp":"1785130851323","session_id":"502006c5cfcd437296561ea750c9ec8b","source":"clob_market_ws"},"received_at":"2026-07-27T05:40:56.943010Z","record_id":"2ae80abd712debc8e786071accf79e1a404cc6f813dd7bf24b2b6dc531cf26e8","schema_fingerprint":"4aa3821a28b0b7c2400bc59aba4bcc0a76e971dadd19610d3ad38c768e124dc7","schema_version":"edge-lab-recorder.raw.v1","sequence":null,"source":"clob_market_ws"}
{"event_at":"2026-07-27T05:40:51.324000Z","event_fingerprint":"5126bf690d04db2dfb2afee553ffc77a6f8d9eeea734415d2ccc1125a7568e4b","payload":{"connection_id":"efc69d3132f1467b8e898a382b23ac0d","event_at":"2026-07-27T05:40:51.324000Z","event_type":"price_change","frame_hash":"e1f4c19c2464ed7bce55cf8ac21b0403b203944a7d0d45450ec9c141f7ac27c4","frame_index":0,"kind":"data","monotonic_ns":232840180224083,"payload":{"event_type":"price_change","market":"0x3b40066b5cf3871a2f6237c5628bd8092a206aa998558ac5ec13c4483e31e160","price_changes":[{"asset_id":"110216635572655435074987471276357323571387854733835379371586402147734167783946","best_ask":"0.35","best_bid":"0.34","hash":"52c35efeea06b3c4c81eb6597ecfa9fc971b8260","price":"0.34","side":"BUY","size":"20.6"},{"asset_id":"14766054693214075530629349735273995982307625376442606753688071083149620216746","best_ask":"0.66","best_bid":"0.65","hash":"ff086e511e8de7219b14a7b3406c372214d81a3b","price":"0.66","side":"SELL","size":"20.6"}],"timestamp":"1785130851324"},"payload_hash":"1d50a35b7706f931b530327cadefa8e1c5f816aa0d8eb0b9d2144b0fdd8f7b82","raw_frame":"{\"market\":\"0x3b40066b5cf3871a2f6237c5628bd8092a206aa998558ac5ec13c4483e31e160\", \"price_changes\":[{\"asset_id\":\"110216635572655435074987471276357323571387854733835379371586402147734167783946\", \"price\":\"0.34\", \"size\":\"20.6\", \"side\":\"BUY\", \"hash\":\"52c35efeea06b3c4c81eb6597ecfa9fc971b8260\", \"best_bid\":\"0.34\", \"best_ask\":\"0.35\"}, {\"asset_id\":\"14766054693214075530629349735273995982307625376442606753688071083149620216746\", \"price\":\"0.66\", \"size\":\"20.6\", \"side\":\"SELL\", \"hash\":\"ff086e511e8de7219b14a7b3406c372214d81a3b\", \"best_bid\":\"0.65\", \"best_ask\":\"0.66\"}], \"timestamp\":\"1785130851324\", \"event_type\":\"price_change\"}","received_at":"2026-07-27T05:40:56.946579Z","schema_version":"clob-market-ws.price_change.v1","sequence":null,"server_hash":null,"server_timestamp":"1785130851324","session_id":"502006c5cfcd437296561ea750c9ec8b","source":"clob_market_ws"},"received_at":"2026-07-27T05:40:56.946579Z","record_id":"780b571716087428d4b81f21131e38b9f49263975ef36ccb0d7e919a4226a0de","schema_fingerprint":"4aa3821a28b0b7c2400bc59aba4bcc0a76e971dadd19610d3ad38c768e124dc7","schema_version":"edge-lab-recorder.raw.v1","sequence":null,"source":"clob_market_ws"}
{"event_at":"2026-07-27T05:40:51.325000Z","event_fingerprint":"05b9a42433acdc456734527cf1187a53d01939c0875207ed6fd65687ecc03147","payload":{"connection_id":"efc69d3132f1467b8e898a382b23ac0d","event_at":"2026-07-27T05:40:51.325000Z","event_type":"price_change","frame_hash":"5afc04078fc8e61772c4354050a3571441775b84bc9cb81706ca76390906d703","frame_index":0,"kind":"data","monotonic_ns":232840182364708,"payload":{"event_type":"price_change","market":"0x3b40066b5cf3871a2f6237c5628bd8092a206aa998558ac5ec13c4483e31e160","price_changes":[{"asset_id":"14766054693214075530629349735273995982307625376442606753688071083149620216746","best_ask":"0.66","best_bid":"0.65","hash":"e9b42e1dccc3969d7c913ddc6aa686a967ef1201","price":"0.49","side":"BUY","size":"85"},{"asset_id":"110216635572655435074987471276357323571387854733835379371586402147734167783946","best_ask":"0.35","best_bid":"0.34","hash":"14e918e19816a845501c1a5fa77c5fdd03a652f1","price":"0.51","side":"SELL","size":"85"}],"timestamp":"1785130851325"},"payload_hash":"954966474ce110175068534013d9e6eb7ce3eb16771cb76ca8369a8bebe02c73","raw_frame":"{\"market\":\"0x3b40066b5cf3871a2f6237c5628bd8092a206aa998558ac5ec13c4483e31e160\", \"price_changes\":[{\"asset_id\":\"14766054693214075530629349735273995982307625376442606753688071083149620216746\", \"price\":\"0.49\", \"size\":\"85\", \"side\":\"BUY\", \"hash\":\"e9b42e1dccc3969d7c913ddc6aa686a967ef1201\", \"best_bid\":\"0.65\", \"best_ask\":\"0.66\"}, {\"asset_id\":\"110216635572655435074987471276357323571387854733835379371586402147734167783946\", \"price\":\"0.51\", \"size\":\"85\", \"side\":\"SELL\", \"hash\":\"14e918e19816a845501c1a5fa77c5fdd03a652f1\", \"best_bid\":\"0.34\", \"best_ask\":\"0.35\"}], \"timestamp\":\"1785130851325\", \"event_type\":\"price_change\"}","received_at":"2026-07-27T05:40:56.948720Z","schema_version":"clob-market-ws.price_change.v1","sequence":null,"server_hash":null,"server_timestamp":"1785130851325","session_id":"502006c5cfcd437296561ea750c9ec8b","source":"clob_market_ws"},"received_at":"2026-07-27T05:40:56.948720Z","record_id":"3e10c8ccf5b47af24a4d63c7ef7d8b893e8b9244ad5d3d906873ea33fdf3d46e","schema_fingerprint":"4aa3821a28b0b7c2400bc59aba4bcc0a76e971dadd19610d3ad38c768e124dc7","schema_version":"edge-lab-recorder.raw.v1","sequence":null,"source":"clob_market_ws"}
{"event_at":"2026-07-27T05:40:51.331000Z","event_fingerprint":"fda4a08105337d799cd7996ecf9bc9d60d75fb08425e1cde88b84e177c0ac8c7","payload":{"connection_id":"efc69d3132f1467b8e898a382b23ac0d","event_at":"2026-07-27T05:40:51.331000Z","event_type":"price_change","frame_hash":"1fe09adc63c88d93594c5b53d7d1cd7a959788fbe8869d1f5e9fe161f4094145","frame_index":0,"kind":"data","monotonic_ns":232840185303333,"payload":{"event_type":"price_change","market":"0x3b40066b5cf3871a2f6237c5628bd8092a206aa998558ac5ec13c4483e31e160","price_changes":[{"asset_id":"110216635572655435074987471276357323571387854733835379371586402147734167783946","best_ask":"0.35","best_bid":"0.34","hash":"2f41d32f5a1e826462ff530f32e486dd6d79aa34","price":"0.31","side":"BUY","size":"60"},{"asset_id":"14766054693214075530629349735273995982307625376442606753688071083149620216746","best_ask":"0.66","best_bid":"0.65","hash":"dd1122614012dcbfbdab4b081a138fac618a77b7","price":"0.69","side":"SELL","size":"60"}],"timestamp":"1785130851331"},"payload_hash":"6dc3e3c90a9e9ae6a4b8bf6b65914a56ea94f2c674de1abe133f3a27f13075df","raw_frame":"{\"market\":\"0x3b40066b5cf3871a2f6237c5628bd8092a206aa998558ac5ec13c4483e31e160\", \"price_changes\":[{\"asset_id\":\"110216635572655435074987471276357323571387854733835379371586402147734167783946\", \"price\":\"0.31\", \"size\":\"60\", \"side\":\"BUY\", \"hash\":\"2f41d32f5a1e826462ff530f32e486dd6d79aa34\", \"best_bid\":\"0.34\", \"best_ask\":\"0.35\"}, {\"asset_id\":\"14766054693214075530629349735273995982307625376442606753688071083149620216746\", \"price\":\"0.69\", \"size\":\"60\", \"side\":\"SELL\", \"hash\":\"dd1122614012dcbfbdab4b081a138fac618a77b7\", \"best_bid\":\"0.65\", \"best_ask\":\"0.66\"}], \"timestamp\":\"1785130851331\", \"event_type\":\"price_change\"}","received_at":"2026-07-27T05:40:56.951659Z","schema_version":"clob-market-ws.price_change.v1","sequence":null,"server_hash":null,"server_timestamp":"1785130851331","session_id":"502006c5cfcd437296561ea750c9ec8b","source":"clob_market_ws"},"received_at":"2026-07-27T05:40:56.951659Z","record_id":"36fd9ea8125f0b24a9ec8c929f76e5dfdb5363652718aa645e8abedfc08c4959","schema_fingerprint":"4aa3821a28b0b7c2400bc59aba4bcc0a76e971dadd19610d3ad38c768e124dc7","schema_version":"edge-lab-recorder.raw.v1","sequence":null,"source":"clob_market_ws"}
{"event_at":"2026-07-27T05:40:51.333000Z","event_fingerprint":"06e52899f7a2b93128779dedb2472520f6a50c47c1f9e1ca825ec7ec0682d57b","payload":{"connection_id":"efc69d3132f1467b8e898a382b23ac0d","event_at":"2026-07-27T05:40:51.333000Z","event_type":"price_change","frame_hash":"5a7ab39e572ef00dc9ee7ee0b4f769a82589797c631c6f97fab539b0a1d8f286","frame_index":0,"kind":"data","monotonic_ns":232840188328916,"payload":{"event_type":"price_change","market":"0x3b40066b5cf3871a2f6237c5628bd8092a206aa998558ac5ec13c4483e31e160","price_changes":[{"asset_id":"110216635572655435074987471276357323571387854733835379371586402147734167783946","best_ask":"0.35","best_bid":"0.34","hash":"87ddc9d10065c6576e354a66f434e0bb0a95170c","price":"0.31","side":"BUY","size":"39"},{"asset_id":"14766054693214075530629349735273995982307625376442606753688071083149620216746","best_ask":"0.66","best_bid":"0.65","hash":"23913bb59700ca2a1e0508ab38bee0dd3dcaf96f","price":"0.69","side":"SELL","size":"39"}],"timestamp":"1785130851333"},"payload_hash":"bc5437dc664855742580345ae440f2ecf97fa0fc912bd94a62eaaa57ce52ea60","raw_frame":"{\"market\":\"0x3b40066b5cf3871a2f6237c5628bd8092a206aa998558ac5ec13c4483e31e160\", \"price_changes\":[{\"asset_id\":\"110216635572655435074987471276357323571387854733835379371586402147734167783946\", \"price\":\"0.31\", \"size\":\"39\", \"side\":\"BUY\", \"hash\":\"87ddc9d10065c6576e354a66f434e0bb0a95170c\", \"best_bid\":\"0.34\", \"best_ask\":\"0.35\"}, {\"asset_id\":\"14766054693214075530629349735273995982307625376442606753688071083149620216746\", \"price\":\"0.69\", \"size\":\"39\", \"side\":\"SELL\", \"hash\":\"23913bb59700ca2a1e0508ab38bee0dd3dcaf96f\", \"best_bid\":\"0.65\", \"best_ask\":\"0.66\"}], \"timestamp\":\"1785130851333\", \"event_type\":\"price_change\"}","received_at":"2026-07-27T05:40:56.954683Z","schema_version":"clob-market-ws.price_change.v1","sequence":null,"server_hash":null,"server_timestamp":"1785130851333","session_id":"502006c5cfcd437296561ea750c9ec8b","source":"clob_market_ws"},"received_at":"2026-07-27T05:40:56.954683Z","record_id":"c63578dfb8ea7fed67c1c102790bf66eb5a3943cd004144bc5b5852278df2cc7","schema_fingerprint":"4aa3821a28b0b7c2400bc59aba4bcc0a76e971dadd19610d3ad38c768e124dc7","schema_version":"edge-lab-recorder.raw.v1","sequence":null,"source":"clob_market_ws"}
{"event_at":"2026-07-27T05:40:51.335000Z","event_fingerprint":"69a24930d90c03559b6622651efc8f61ac06dbc5c0677e3d8e808590d43651a6","payload":{"connection_id":"efc69d3132f1467b8e898a382b23ac0d","event_at":"2026-07-27T05:40:51.335000Z","event_type":"price_change","frame_hash":"7390b1133e2045a7b760ff935b629c133ce1953cf695fb77f91a7ec9526c8519","frame_index":0,"kind":"data","monotonic_ns":232840191353708,"payload":{"event_type":"price_change","market":"0x3b40066b5cf3871a2f6237c5628bd8092a206aa998558ac5ec13c4483e31e160","price_changes":[{"asset_id":"14766054693214075530629349735273995982307625376442606753688071083149620216746","best_ask":"0.66","best_bid":"0.65","hash":"5b82b8d4c1f7550bb957cde5d16d425a8be73e22","price":"0.01","side":"BUY","size":"5633.02"},{"asset_id":"110216635572655435074987471276357323571387854733835379371586402147734167783946","best_ask":"0.35","best_bid":"0.34","hash":"7c96c520ac3298b4cda1c571a58ec646514d84e5","price":"0.99","side":"SELL","size":"5633.02"}],"timestamp":"1785130851335"},"payload_hash":"04c6badb52ebea790d2efe4d2338507ab0f95141e0ee85e22ff7f3e6afb9b14e","raw_frame":"{\"market\":\"0x3b40066b5cf3871a2f6237c5628bd8092a206aa998558ac5ec13c4483e31e160\", \"price_changes\":[{\"asset_id\":\"14766054693214075530629349735273995982307625376442606753688071083149620216746\", \"price\":\"0.01\", \"size\":\"5633.02\", \"side\":\"BUY\", \"hash\":\"5b82b8d4c1f7550bb957cde5d16d425a8be73e22\", \"best_bid\":\"0.65\", \"best_ask\":\"0.66\"}, {\"asset_id\":\"110216635572655435074987471276357323571387854733835379371586402147734167783946\", \"price\":\"0.99\", \"size\":\"5633.02\", \"side\":\"SELL\", \"hash\":\"7c96c520ac3298b4cda1c571a58ec646514d84e5\", \"best_bid\":\"0.34\", \"best_ask\":\"0.35\"}], \"timestamp\":\"1785130851335\", \"event_type\":\"price_change\"}","received_at":"2026-07-27T05:40:56.957709Z","schema_version":"clob-market-ws.price_change.v1","sequence":null,"server_hash":null,"server_timestamp":"1785130851335","session_id":"502006c5cfcd437296561ea750c9ec8b","source":"clob_market_ws"},"received_at":"2026-07-27T05:40:56.957709Z","record_id":"a333c64eabf500af32c8b4989555868681583e47e8b60aa810154feb6fc70b30","schema_fingerprint":"4aa3821a28b0b7c2400bc59aba4bcc0a76e971dadd19610d3ad38c768e124dc7","schema_version":"edge-lab-recorder.raw.v1","sequence":null,"source":"clob_market_ws"}
{"event_at":"2026-07-27T05:40:51.336000Z","event_fingerprint":"1e51c6dc3d1a849ae209d33a78792828ab444d194b0ad710b522afa29105b59e","payload":{"connection_id":"efc69d3132f1467b8e898a382b23ac0d","event_at":"2026-07-27T05:40:51.336000Z","event_type":"price_change","frame_hash":"8200ac43307b78db429e3ed83e056d37a8d9a5afbbfafb037c0dbc27bc2a237a","frame_index":0,"kind":"data","monotonic_ns":232840195893875,"payload":{"event_type":"price_change","market":"0x3b40066b5cf3871a2f6237c5628bd8092a206aa998558ac5ec13c4483e31e160","price_changes":[{"asset_id":"110216635572655435074987471276357323571387854733835379371586402147734167783946","best_ask":"0.35","best_bid":"0.34","hash":"2770694d24ff14ef17acdd269a6a38d6cf4fddfc","price":"0.3","side":"BUY","size":"110.93"},{"asset_id":"14766054693214075530629349735273995982307625376442606753688071083149620216746","best_ask":"0.66","best_bid":"0.65","hash":"9382277dab2c92efc82d450b22a22ac9cabf573a","price":"0.7","side":"SELL","size":"110.93"}],"timestamp":"1785130851336"},"payload_hash":"791fff75493a21cad2ff50915561d9cd4613ae6b01a9840946b978d8bebff22e","raw_frame":"{\"market\":\"0x3b40066b5cf3871a2f6237c5628bd8092a206aa998558ac5ec13c4483e31e160\", \"price_changes\":[{\"asset_id\":\"110216635572655435074987471276357323571387854733835379371586402147734167783946\", \"price\":\"0.3\", \"size\":\"110.93\", \"side\":\"BUY\", \"hash\":\"2770694d24ff14ef17acdd269a6a38d6cf4fddfc\", \"best_bid\":\"0.34\", \"best_ask\":\"0.35\"}, {\"asset_id\":\"14766054693214075530629349735273995982307625376442606753688071083149620216746\", \"price\":\"0.7\", \"size\":\"110.93\", \"side\":\"SELL\", \"hash\":\"9382277dab2c92efc82d450b22a22ac9cabf573a\", \"best_bid\":\"0.65\", \"best_ask\":\"0.66\"}], \"timestamp\":\"1785130851336\", \"event_type\":\"price_change\"}","received_at":"2026-07-27T05:40:56.962249Z","schema_version":"clob-market-ws.price_change.v1","sequence":null,"server_hash":null,"server_timestamp":"1785130851336","session_id":"502006c5cfcd437296561ea750c9ec8b","source":"clob_market_ws"},"received_at":"2026-07-27T05:40:56.962249Z","record_id":"708060abb7daef4caa8cbde1ff86b7931d64e4597f9c2ab0812c58eff266889f","schema_fingerprint":"4aa3821a28b0b7c2400bc59aba4bcc0a76e971dadd19610d3ad38c768e124dc7","schema_version":"edge-lab-recorder.raw.v1","sequence":null,"source":"clob_market_ws"}
{"event_at":"2026-07-27T05:40:51.337000Z","event_fingerprint":"1fecb0ab4ab78a88c071daa180ed592bab093b9b46c07124ab4ef1c6ebf28f62","payload":{"connection_id":"efc69d3132f1467b8e898a382b23ac0d","event_at":"2026-07-27T05:40:51.337000Z","event_type":"price_change","frame_hash":"caa31b7cc3186808ac4e7f91d0423681c933e22f7383e6f8652930060af5bece","frame_index":0,"kind":"data","monotonic_ns":232840198893333,"payload":{"event_type":"price_change","market":"0x3b40066b5cf3871a2f6237c5628bd8092a206aa998558ac5ec13c4483e31e160","price_changes":[{"asset_id":"14766054693214075530629349735273995982307625376442606753688071083149620216746","best_ask":"0.66","best_bid":"0.65","hash":"e8045caa31ec1411c8a07bfa9dba7054b0f46a18","price":"0.7","side":"SELL","size":"118.97"},{"asset_id":"110216635572655435074987471276357323571387854733835379371586402147734167783946","best_ask":"0.35","best_bid":"0.34","hash":"d6630a8af38c28c8e13f0fb24c6a76418b3c6f0e","price":"0.3","side":"BUY","size":"118.97"}],"timestamp":"1785130851337"},"payload_hash":"b8b7108424cf155170e3ed1b24fce8f303d1c705d4d500acf3385b14c5676121","raw_frame":"{\"market\":\"0x3b40066b5cf3871a2f6237c5628bd8092a206aa998558ac5ec13c4483e31e160\", \"price_changes\":[{\"asset_id\":\"14766054693214075530629349735273995982307625376442606753688071083149620216746\", \"price\":\"0.7\", \"size\":\"118.97\", \"side\":\"SELL\", \"hash\":\"e8045caa31ec1411c8a07bfa9dba7054b0f46a18\", \"best_bid\":\"0.65\", \"best_ask\":\"0.66\"}, {\"asset_id\":\"110216635572655435074987471276357323571387854733835379371586402147734167783946\", \"price\":\"0.3\", \"size\":\"118.97\", \"side\":\"BUY\", \"hash\":\"d6630a8af38c28c8e13f0fb24c6a76418b3c6f0e\", \"best_bid\":\"0.34\", \"best_ask\":\"0.35\"}], \"timestamp\":\"1785130851337\", \"event_type\":\"price_change\"}","received_at":"2026-07-27T05:40:56.965253Z","schema_version":"clob-market-ws.price_change.v1","sequence":null,"server_hash":null,"server_timestamp":"1785130851337","session_id":"502006c5cfcd437296561ea750c9ec8b","source":"clob_market_ws"},"received_at":"2026-07-27T05:40:56.965253Z","record_id":"424d78fdf07f56b212e3371584cc7ff0d0b2101251f9dc2687c2a9fe365d02ab","schema_fingerprint":"4aa3821a28b0b7c2400bc59aba4bcc0a76e971dadd19610d3ad38c768e124dc7","schema_version":"edge-lab-recorder.raw.v1","sequence":null,"source":"clob_market_ws"}
{"event_at":"2026-07-27T05:40:51.338000Z","event_fingerprint":"ce72ded35f8153a9a26c692cd8b37a1c160561b7961bb039039d7167f5bf13c8","payload":{"connection_id":"efc69d3132f1467b8e898a382b23ac0d","event_at":"2026-07-27T05:40:51.338000Z","event_type":"price_change","frame_hash":"d18179e72406abf08a97f19bf92f0762f9f4b24fa42283b9eb527726f6280b3f","frame_index":0,"kind":"data","monotonic_ns":232840201714916,"payload":{"event_type":"price_change","market":"0x3b40066b5cf3871a2f6237c5628bd8092a206aa998558ac5ec13c4483e31e160","price_changes":[{"asset_id":"110216635572655435074987471276357323571387854733835379371586402147734167783946","best_ask":"0.35","best_bid":"0.34","hash":"03d877bb739eaf7e9aafe57acb64af43ae1703e5","price":"0.28","side":"BUY","size":"60.97"},{"asset_id":"14766054693214075530629349735273995982307625376442606753688071083149620216746","best_ask":"0.66","best_bid":"0.65","hash":"35d1786fca138958b5cb1d5a08bf66ad76bd933b","price":"0.72","side":"SELL","size":"60.97"}],"timestamp":"1785130851338"},"payload_hash":"f771e88b23174ec7546f344c3783bb6ec788ee54b05c3b4dd8165d6a1ce3a117","raw_frame":"{\"market\":\"0x3b40066b5cf3871a2f6237c5628bd8092a206aa998558ac5ec13c4483e31e160\", \"price_changes\":[{\"asset_id\":\"110216635572655435074987471276357323571387854733835379371586402147734167783946\", \"price\":\"0.28\", \"size\":\"60.97\", \"side\":\"BUY\", \"hash\":\"03d877bb739eaf7e9aafe57acb64af43ae1703e5\", \"best_bid\":\"0.34\", \"best_ask\":\"0.35\"}, {\"asset_id\":\"14766054693214075530629349735273995982307625376442606753688071083149620216746\", \"price\":\"0.72\", \"size\":\"60.97\", \"side\":\"SELL\", \"hash\":\"35d1786fca138958b5cb1d5a08bf66ad76bd933b\", \"best_bid\":\"0.65\", \"best_ask\":\"0.66\"}], \"timestamp\":\"1785130851338\", \"event_type\":\"price_change\"}","received_at":"2026-07-27T05:40:56.968071Z","schema_version":"clob-market-ws.price_change.v1","sequence":null,"server_hash":null,"server_timestamp":"1785130851338","session_id":"502006c5cfcd437296561ea750c9ec8b","source":"clob_market_ws"},"received_at":"2026-07-27T05:40:56.968071Z","record_id":"e50c0033cf74981b319cbab48886d9dd82335c2dde638b25c23c031f65f1a4a4","schema_fingerprint":"4aa3821a28b0b7c2400bc59aba4bcc0a76e971dadd19610d3ad38c768e124dc7","schema_version":"edge-lab-recorder.raw.v1","sequence":null,"source":"clob_market_ws"}
{"event_at":"2026-07-27T05:40:51.341000Z","event_fingerprint":"aa648cbd727c785f9a70cf25004b60209e2f4b337dbc07d0dcc927d38a22d60d","payload":{"connection_id":"efc69d3132f1467b8e898a382b23ac0d","event_at":"2026-07-27T05:40:51.341000Z","event_type":"price_change","frame_hash":"fb863c870941508f4758b3ff67c54a08007e609b5ab0fc3897160bf6c68bde01","frame_index":0,"kind":"data","monotonic_ns":232840205389333,"payload":{"event_type":"price_change","market":"0x3b40066b5cf3871a2f6237c5628bd8092a206aa998558ac5ec13c4483e31e160","price_changes":[{"asset_id":"14766054693214075530629349735273995982307625376442606753688071083149620216746","best_ask":"0.66","best_bid":"0.65","hash":"da5b6a723ba1ffb8911d89f1f9aa590a50e19586","price":"0.63","side":"BUY","size":"301.6"},{"asset_id":"110216635572655435074987471276357323571387854733835379371586402147734167783946","best_ask":"0.35","best_bid":"0.34","hash":"4cdcf86ea10cbe2c987d132d668256a6d266e896","price":"0.37","side":"SELL","size":"301.6"}],"timestamp":"1785130851341"},"payload_hash":"10000465ce3cd7d1695fa6198998b17feb73ab33e13c6c290911ade78033e6c1","raw_frame":"{\"market\":\"0x3b40066b5cf3871a2f6237c5628bd8092a206aa998558ac5ec13c4483e31e160\", \"price_changes\":[{\"asset_id\":\"14766054693214075530629349735273995982307625376442606753688071083149620216746\", \"price\":\"0.63\", \"size\":\"301.6\", \"side\":\"BUY\", \"hash\":\"da5b6a723ba1ffb8911d89f1f9aa590a50e19586\", \"best_bid\":\"0.65\", \"best_ask\":\"0.66\"}, {\"asset_id\":\"110216635572655435074987471276357323571387854733835379371586402147734167783946\", \"price\":\"0.37\", \"size\":\"301.6\", \"side\":\"SELL\", \"hash\":\"4cdcf86ea10cbe2c987d132d668256a6d266e896\", \"best_bid\":\"0.34\", \"best_ask\":\"0.35\"}], \"timestamp\":\"1785130851341\", \"event_type\":\"price_change\"}","received_at":"2026-07-27T05:40:56.971744Z","schema_version":"clob-market-ws.price_change.v1","sequence":null,"server_hash":null,"server_timestamp":"1785130851341","session_id":"502006c5cfcd437296561ea750c9ec8b","source":"clob_market_ws"},"received_at":"2026-07-27T05:40:56.971744Z","record_id":"fb32b72fecdff3421a83cb64983623e47aa328d410dea28acb2a126d944716f9","schema_fingerprint":"4aa3821a28b0b7c2400bc59aba4bcc0a76e971dadd19610d3ad38c768e124dc7","schema_version":"edge-lab-recorder.raw.v1","sequence":null,"source":"clob_market_ws"}
{"event_at":"2026-07-27T05:40:51.342000Z","event_fingerprint":"cfa08b65cf381a4f5468fa3c329db384e8733c93baaac648fa75f7bce800971e","payload":{"connection_id":"efc69d3132f1467b8e898a382b23ac0d","event_at":"2026-07-27T05:40:51.342000Z","event_type":"price_change","frame_hash":"025ab767e3b9262c08684bdae73128227afa4917e5605f2464a03c1c0b035af7","frame_index":0,"kind":"data","monotonic_ns":232840208404916,"payload":{"event_type":"price_change","market":"0x3b40066b5cf3871a2f6237c5628bd8092a206aa998558ac5ec13c4483e31e160","price_changes":[{"asset_id":"14766054693214075530629349735273995982307625376442606753688071083149620216746","best_ask":"0.66","best_bid":"0.65","hash":"10f897faaf920721601efd2122f19a82e77471af","price":"0.36","side":"BUY","size":"51"},{"asset_id":"110216635572655435074987471276357323571387854733835379371586402147734167783946","best_ask":"0.35","best_bid":"0.34","hash":"deee8605dddbda19b545e08a75ca9d04077dfc5c","price":"0.64","side":"SELL","size":"51"}],"timestamp":"1785130851342"},"payload_hash":"b823bf18a795360bcb70054d3c0f402fa536929c9e9de8c0d45cfaf7b908d017","raw_frame":"{\"market\":\"0x3b40066b5cf3871a2f6237c5628bd8092a206aa998558ac5ec13c4483e31e160\", \"price_changes\":[{\"asset_id\":\"14766054693214075530629349735273995982307625376442606753688071083149620216746\", \"price\":\"0.36\", \"size\":\"51\", \"side\":\"BUY\", \"hash\":\"10f897faaf920721601efd2122f19a82e77471af\", \"best_bid\":\"0.65\", \"best_ask\":\"0.66\"}, {\"asset_id\":\"110216635572655435074987471276357323571387854733835379371586402147734167783946\", \"price\":\"0.64\", \"size\":\"51\", \"side\":\"SELL\", \"hash\":\"deee8605dddbda19b545e08a75ca9d04077dfc5c\", \"best_bid\":\"0.34\", \"best_ask\":\"0.35\"}], \"timestamp\":\"1785130851342\", \"event_type\":\"price_change\"}","received_at":"2026-07-27T05:40:56.974761Z","schema_version":"clob-market-ws.price_change.v1","sequence":null,"server_hash":null,"server_timestamp":"1785130851342","session_id":"502006c5cfcd437296561ea750c9ec8b","source":"clob_market_ws"},"received_at":"2026-07-27T05:40:56.974761Z","record_id":"bea379a19fc20ef4960500022fd69bbae6347c905a27da1fbb89cf81267bad8c","schema_fingerprint":"4aa3821a28b0b7c2400bc59aba4bcc0a76e971dadd19610d3ad38c768e124dc7","schema_version":"edge-lab-recorder.raw.v1","sequence":null,"source":"clob_market_ws"}
{"event_at":"2026-07-27T05:40:51.342000Z","event_fingerprint":"0b6843f2b32f78b4d9930dacb0ae5bbc2623241f19ed65ae96b0a9bbf0f60fa7","payload":{"connection_id":"efc69d3132f1467b8e898a382b23ac0d","event_at":"2026-07-27T05:40:51.342000Z","event_type":"price_change","frame_hash":"50f9db527b29274659ee0b76be58df7813de1720a2926962b1c747257cc55fba","frame_index":0,"kind":"data","monotonic_ns":232840211332041,"payload":{"event_type":"price_change","market":"0x3b40066b5cf3871a2f6237c5628bd8092a206aa998558ac5ec13c4483e31e160","price_changes":[{"asset_id":"110216635572655435074987471276357323571387854733835379371586402147734167783946","best_ask":"0.35","best_bid":"0.34","hash":"c0bf1f5db70b354fb52557c73f79b204c5b2be7e","price":"0.34","side":"BUY","size":"11"},{"asset_id":"14766054693214075530629349735273995982307625376442606753688071083149620216746","best_ask":"0.66","best_bid":"0.65","hash":"59585f48c1a5ca855ef8459662cde2adc1dc77b4","price":"0.66","side":"SELL","size":"11"}],"timestamp":"1785130851342"},"payload_hash":"a7c40c350fbb363a99bb28b208720b2d71f43297f7aaf56a7476db4d7cb9cc7c","raw_frame":"{\"market\":\"0x3b40066b5cf3871a2f6237c5628bd8092a206aa998558ac5ec13c4483e31e160\", \"price_changes\":[{\"asset_id\":\"110216635572655435074987471276357323571387854733835379371586402147734167783946\", \"price\":\"0.34\", \"size\":\"11\", \"side\":\"BUY\", \"hash\":\"c0bf1f5db70b354fb52557c73f79b204c5b2be7e\", \"best_bid\":\"0.34\", \"best_ask\":\"0.35\"}, {\"asset_id\":\"14766054693214075530629349735273995982307625376442606753688071083149620216746\", \"price\":\"0.66\", \"size\":\"11\", \"side\":\"SELL\", \"hash\":\"59585f48c1a5ca855ef8459662cde2adc1dc77b4\", \"best_bid\":\"0.65\", \"best_ask\":\"0.66\"}], \"timestamp\":\"1785130851342\", \"event_type\":\"price_change\"}","received_at":"2026-07-27T05:40:56.977688Z","schema_version":"clob-market-ws.price_change.v1","sequence":null,"server_hash":null,"server_timestamp":"1785130851342","session_id":"502006c5cfcd437296561ea750c9ec8b","source":"clob_market_ws"},"received_at":"2026-07-27T05:40:56.977688Z","record_id":"9354531b0f880117e41a7bb8408671a2a000330f25edef12a5bf44e031c3dec7","schema_fingerprint":"4aa3821a28b0b7c2400bc59aba4bcc0a76e971dadd19610d3ad38c768e124dc7","schema_version":"edge-lab-recorder.raw.v1","sequence":null,"source":"clob_market_ws"}
{"event_at":"2026-07-27T05:40:51.342000Z","event_fingerprint":"cdb5ecc7621eb699e91da4cb8ae364d63a349477976784026dfc2f0aacf4e3f2","payload":{"connection_id":"efc69d3132f1467b8e898a382b23ac0d","event_at":"2026-07-27T05:40:51.342000Z","event_type":"price_change","frame_hash":"7314763f11c78fef8178c28662d7eae23ad0bd34fd861d557b273f3aab42b483","frame_index":0,"kind":"data","monotonic_ns":232840214296958,"payload":{"event_type":"price_change","market":"0x3b40066b5cf3871a2f6237c5628bd8092a206aa998558ac5ec13c4483e31e160","price_changes":[{"asset_id":"14766054693214075530629349735273995982307625376442606753688071083149620216746","best_ask":"0.66","best_bid":"0.65","hash":"cb6faf5e499b40851fb0d0e175fa6e63357f1ee9","price":"0.65","side":"BUY","size":"33"},{"asset_id":"110216635572655435074987471276357323571387854733835379371586402147734167783946","best_ask":"0.35","best_bid":"0.34","hash":"fdfad5c1b9b247dd1bccd1a8039ff25d743ab9f7","price":"0.35","side":"SELL","size":"33"}],"timestamp":"1785130851342"},"payload_hash":"6bee5b53776155827fb13ee8d4d67d7044f4e668fe6a71237cf2dd227a24389c","raw_frame":"{\"market\":\"0x3b40066b5cf3871a2f6237c5628bd8092a206aa998558ac5ec13c4483e31e160\", \"price_changes\":[{\"asset_id\":\"14766054693214075530629349735273995982307625376442606753688071083149620216746\", \"price\":\"0.65\", \"size\":\"33\", \"side\":\"BUY\", \"hash\":\"cb6faf5e499b40851fb0d0e175fa6e63357f1ee9\", \"best_bid\":\"0.65\", \"best_ask\":\"0.66\"}, {\"asset_id\":\"110216635572655435074987471276357323571387854733835379371586402147734167783946\", \"price\":\"0.35\", \"size\":\"33\", \"side\":\"SELL\", \"hash\":\"fdfad5c1b9b247dd1bccd1a8039ff25d743ab9f7\", \"best_bid\":\"0.34\", \"best_ask\":\"0.35\"}], \"timestamp\":\"1785130851342\", \"event_type\":\"price_change\"}","received_at":"2026-07-27T05:40:56.980653Z","schema_version":"clob-market-ws.price_change.v1","sequence":null,"server_hash":null,"server_timestamp":"1785130851342","session_id":"502006c5cfcd437296561ea750c9ec8b","source":"clob_market_ws"},"received_at":"2026-07-27T05:40:56.980653Z","record_id":"0fd935c57ab77ab71d0e2999c9cb6aff463a16738ef2e665691a4c24f3b03134","schema_fingerprint":"4aa3821a28b0b7c2400bc59aba4bcc0a76e971dadd19610d3ad38c768e124dc7","schema_version":"edge-lab-recorder.raw.v1","sequence":null,"source":"clob_market_ws"}
{"event_at":"2026-07-27T05:40:51.344000Z","event_fingerprint":"593bad58f4524d66bc8626e0f12c0135d19e0506741c9acc17a8e343bc81bdea","payload":{"connection_id":"efc69d3132f1467b8e898a382b23ac0d","event_at":"2026-07-27T05:40:51.344000Z","event_type":"price_change","frame_hash":"840eea02323976480c83fad61234792b147ea963107d2c4411f60ad5b50310a2","frame_index":0,"kind":"data","monotonic_ns":232840216560208,"payload":{"event_type":"price_change","market":"0x3b40066b5cf3871a2f6237c5628bd8092a206aa998558ac5ec13c4483e31e160","price_changes":[{"asset_id":"14766054693214075530629349735273995982307625376442606753688071083149620216746","best_ask":"0.66","best_bid":"0.65","hash":"ac5bb3b858c225628ddec65dae366b1b69266735","price":"0.63","side":"BUY","size":"312.6"},{"asset_id":"110216635572655435074987471276357323571387854733835379371586402147734167783946","best_ask":"0.35","best_bid":"0.34","hash":"8ac56587df5dde87cd53642cddc3951e5729c1d8","price":"0.37","side":"SELL","size":"312.6"}],"timestamp":"1785130851344"},"payload_hash":"c54fe031000043f6510c63e8da536896c4e9e85da0482b31ad2f81d15db5aff5","raw_frame":"{\"market\":\"0x3b40066b5cf3871a2f6237c5628bd8092a206aa998558ac5ec13c4483e31e160\", \"price_changes\":[{\"asset_id\":\"14766054693214075530629349735273995982307625376442606753688071083149620216746\", \"price\":\"0.63\", \"size\":\"312.6\", \"side\":\"BUY\", \"hash\":\"ac5bb3b858c225628ddec65dae366b1b69266735\", \"best_bid\":\"0.65\", \"best_ask\":\"0.66\"}, {\"asset_id\":\"110216635572655435074987471276357323571387854733835379371586402147734167783946\", \"price\":\"0.37\", \"size\":\"312.6\", \"side\":\"SELL\", \"hash\":\"8ac56587df5dde87cd53642cddc3951e5729c1d8\", \"best_bid\":\"0.34\", \"best_ask\":\"0.35\"}], \"timestamp\":\"1785130851344\", \"event_type\":\"price_change\"}","received_at":"2026-07-27T05:40:56.982916Z","schema_version":"clob-market-ws.price_change.v1","sequence":null,"server_hash":null,"server_timestamp":"1785130851344","session_id":"502006c5cfcd437296561ea750c9ec8b","source":"clob_market_ws"},"received_at":"2026-07-27T05:40:56.982916Z","record_id":"5e11063a3bfd0154ae5bec2bca5f82aecdf89df3920d10231457268ce42180cf","schema_fingerprint":"4aa3821a28b0b7c2400bc59aba4bcc0a76e971dadd19610d3ad38c768e124dc7","schema_version":"edge-lab-recorder.raw.v1","sequence":null,"source":"clob_market_ws"}
{"event_at":"2026-07-27T05:40:51.344000Z","event_fingerprint":"856d6f2567ba9f5869088768c18880b80239bef3a3f2943d74b7d0eff4c9e484","payload":{"connection_id":"efc69d3132f1467b8e898a382b23ac0d","event_at":"2026-07-27T05:40:51.344000Z","event_type":"price_change","frame_hash":"4b7c3d2b51a1739e0100093fd3e93498045fc7479de7d10e30ade8d634133efd","frame_index":0,"kind":"data","monotonic_ns":232840219542083,"payload":{"event_type":"price_change","market":"0x3b40066b5cf3871a2f6237c5628bd8092a206aa998558ac5ec13c4483e31e160","price_changes":[{"asset_id":"110216635572655435074987471276357323571387854733835379371586402147734167783946","best_ask":"0.35","best_bid":"0.34","hash":"654826e9b05029848d6b0e35298c851e0f3710cb","price":"0.33","side":"BUY","size":"20.6"},{"asset_id":"14766054693214075530629349735273995982307625376442606753688071083149620216746","best_ask":"0.66","best_bid":"0.65","hash":"73c979e6df33823274da6c306397dd2b2c9e35a3","price":"0.67","side":"SELL","size":"20.6"}],"timestamp":"1785130851344"},"payload_hash":"4eecbaf7a0b67217b465387bdf986725eb22487185dd8d327288ce0cbcc13e20","raw_frame":"{\"market\":\"0x3b40066b5cf3871a2f6237c5628bd8092a206aa998558ac5ec13c4483e31e160\", \"price_changes\":[{\"asset_id\":\"110216635572655435074987471276357323571387854733835379371586402147734167783946\", \"price\":\"0.33\", \"size\":\"20.6\", \"side\":\"BUY\", \"hash\":\"654826e9b05029848d6b0e35298c851e0f3710cb\", \"best_bid\":\"0.34\", \"best_ask\":\"0.35\"}, {\"asset_id\":\"14766054693214075530629349735273995982307625376442606753688071083149620216746\", \"price\":\"0.67\", \"size\":\"20.6\", \"side\":\"SELL\", \"hash\":\"73c979e6df33823274da6c306397dd2b2c9e35a3\", \"best_bid\":\"0.65\", \"best_ask\":\"0.66\"}], \"timestamp\":\"1785130851344\", \"event_type\":\"price_change\"}","received_at":"2026-07-27T05:40:56.985897Z","schema_version":"clob-market-ws.price_change.v1","sequence":null,"server_hash":null,"server_timestamp":"1785130851344","session_id":"502006c5cfcd437296561ea750c9ec8b","source":"clob_market_ws"},"received_at":"2026-07-27T05:40:56.985897Z","record_id":"4819922934a5caf62501e290e50bd01b69b444a2edb7085df24b50d0b7774f60","schema_fingerprint":"4aa3821a28b0b7c2400bc59aba4bcc0a76e971dadd19610d3ad38c768e124dc7","schema_version":"edge-lab-recorder.raw.v1","sequence":null,"source":"clob_market_ws"}
{"event_at":"2026-07-27T05:40:51.345000Z","event_fingerprint":"da3ed3cb4d36aee267c0c7f9ee01c4e2a04f0e61a76b760be74946e99ade701f","payload":{"connection_id":"efc69d3132f1467b8e898a382b23ac0d","event_at":"2026-07-27T05:40:51.345000Z","event_type":"price_change","frame_hash":"1c655762397701f13151c2b7833747ad3596501c69383154c113c67f064121be","frame_index":0,"kind":"data","monotonic_ns":232840222455458,"payload":{"event_type":"price_change","market":"0x3b40066b5cf3871a2f6237c5628bd8092a206aa998558ac5ec13c4483e31e160","price_changes":[{"asset_id":"110216635572655435074987471276357323571387854733835379371586402147734167783946","best_ask":"0.35","best_bid":"0.34","hash":"99ef380467b7d48d6c139e9995c06fc95f8577a2","price":"0.28","side":"BUY","size":"70.97"},{"asset_id":"14766054693214075530629349735273995982307625376442606753688071083149620216746","best_ask":"0.66","best_bid":"0.65","hash":"a6cfbc49df241dd7ec4fcec13ba83288380869d6","price":"0.72","side":"SELL","size":"70.97"}],"timestamp":"1785130851345"},"payload_hash":"6a5be86cce439b6365749968814eb9b49310de64222f04bf7b3b10a75b567f1e","raw_frame":"{\"market\":\"0x3b40066b5cf3871a2f6237c5628bd8092a206aa998558ac5ec13c4483e31e160\", \"price_changes\":[{\"asset_id\":\"110216635572655435074987471276357323571387854733835379371586402147734167783946\", \"price\":\"0.28\", \"size\":\"70.97\", \"side\":\"BUY\", \"hash\":\"99ef380467b7d48d6c139e9995c06fc95f8577a2\", \"best_bid\":\"0.34\", \"best_ask\":\"0.35\"}, {\"asset_id\":\"14766054693214075530629349735273995982307625376442606753688071083149620216746\", \"price\":\"0.72\", \"size\":\"70.97\", \"side\":\"SELL\", \"hash\":\"a6cfbc49df241dd7ec4fcec13ba83288380869d6\", \"best_bid\":\"0.65\", \"best_ask\":\"0.66\"}], \"timestamp\":\"1785130851345\", \"event_type\":\"price_change\"}","received_at":"2026-07-27T05:40:56.988812Z","schema_version":"clob-market-ws.price_change.v1","sequence":null,"server_hash":null,"server_timestamp":"1785130851345","session_id":"502006c5cfcd437296561ea750c9ec8b","source":"clob_market_ws"},"received_at":"2026-07-27T05:40:56.988812Z","record_id":"02674475ea1a3611f65f78299890e963127a854eb743860fafdedcca8dc534aa","schema_fingerprint":"4aa3821a28b0b7c2400bc59aba4bcc0a76e971dadd19610d3ad38c768e124dc7","schema_version":"edge-lab-recorder.raw.v1","sequence":null,"source":"clob_market_ws"}
{"event_at":"2026-07-27T05:40:51.346000Z","event_fingerprint":"8522d4c9f6c6c91df6367dd50a82b6d017b12cd29c632d6635883c9437eec9a8","payload":{"connection_id":"efc69d3132f1467b8e898a382b23ac0d","event_at":"2026-07-27T05:40:51.346000Z","event_type":"price_change","frame_hash":"492f8afbdb50ff2418b64dc5eed4e95828763b6421fdac4993252be348d9f277","frame_index":0,"kind":"data","monotonic_ns":232840225340750,"payload":{"event_type":"price_change","market":"0x3b40066b5cf3871a2f6237c5628bd8092a206aa998558ac5ec13c4483e31e160","price_changes":[{"asset_id":"14766054693214075530629349735273995982307625376442606753688071083149620216746","best_ask":"0.66","best_bid":"0.65","hash":"fea09e307c0d7e661168b94a3a0533349eca19fa","price":"0.61","side":"BUY","size":"52.6"},{"asset_id":"110216635572655435074987471276357323571387854733835379371586402147734167783946","best_ask":"0.35","best_bid":"0.34","hash":"c2dd2512f154906a9587479986256aa8a65dd064","price":"0.39","side":"SELL","size":"52.6"}],"timestamp":"1785130851346"},"payload_hash":"85c55038cc87c369b05bd2788cd8113659bb89c4c5983a4cf370b1b1959178f1","raw_frame":"{\"market\":\"0x3b40066b5cf3871a2f6237c5628bd8092a206aa998558ac5ec13c4483e31e160\", \"price_changes\":[{\"asset_id\":\"14766054693214075530629349735273995982307625376442606753688071083149620216746\", \"price\":\"0.61\", \"size\":\"52.6\", \"side\":\"BUY\", \"hash\":\"fea09e307c0d7e661168b94a3a0533349eca19fa\", \"best_bid\":\"0.65\", \"best_ask\":\"0.66\"}, {\"asset_id\":\"110216635572655435074987471276357323571387854733835379371586402147734167783946\", \"price\":\"0.39\", \"size\":\"52.6\", \"side\":\"SELL\", \"hash\":\"c2dd2512f154906a9587479986256aa8a65dd064\", \"best_bid\":\"0.34\", \"best_ask\":\"0.35\"}], \"timestamp\":\"1785130851346\", \"event_type\":\"price_change\"}","received_at":"2026-07-27T05:40:56.991697Z","schema_version":"clob-market-ws.price_change.v1","sequence":null,"server_hash":null,"server_timestamp":"1785130851346","session_id":"502006c5cfcd437296561ea750c9ec8b","source":"clob_market_ws"},"received_at":"2026-07-27T05:40:56.991697Z","record_id":"bb37526b266dd0b237d3fe9257636ad1d68a1964a67697b0b30cb62eb3ae0346","schema_fingerprint":"4aa3821a28b0b7c2400bc59aba4bcc0a76e971dadd19610d3ad38c768e124dc7","schema_version":"edge-lab-recorder.raw.v1","sequence":null,"source":"clob_market_ws"}
{"event_at":"2026-07-27T05:40:51.347000Z","event_fingerprint":"c4a1636caedc0cc913195ede7603d416bb469d78156863c94ead2dda267d925d","payload":{"connection_id":"efc69d3132f1467b8e898a382b23ac0d","event_at":"2026-07-27T05:40:51.347000Z","event_type":"price_change","frame_hash":"619dd5dcad9165ab33f82dd794083e6f7f608e504046cb6b1c374344a04f82da","frame_index":0,"kind":"data","monotonic_ns":232840228244541,"payload":{"event_type":"price_change","market":"0x3b40066b5cf3871a2f6237c5628bd8092a206aa998558ac5ec13c4483e31e160","price_changes":[{"asset_id":"110216635572655435074987471276357323571387854733835379371586402147734167783946","best_ask":"0.35","best_bid":"0.34","hash":"93e33433b9135edf14f906d9cf4e3937e219c8b2","price":"0.35","side":"SELL","size":"50"},{"asset_id":"14766054693214075530629349735273995982307625376442606753688071083149620216746","best_ask":"0.66","best_bid":"0.65","hash":"5101bc8ac89258f0f43d5b4e37c47c57d31c7e98","price":"0.65","side":"BUY","size":"50"}],"timestamp":"1785130851347"},"payload_hash":"5c512051c08bcedaa51cb11440f951b76a1b19adf34fe1de271865c4e3774183","raw_frame":"{\"market\":\"0x3b40066b5cf3871a2f6237c5628bd8092a206aa998558ac5ec13c4483e31e160\", \"price_changes\":[{\"asset_id\":\"110216635572655435074987471276357323571387854733835379371586402147734167783946\", \"price\":\"0.35\", \"size\":\"50\", \"side\":\"SELL\", \"hash\":\"93e33433b9135edf14f906d9cf4e3937e219c8b2\", \"best_bid\":\"0.34\", \"best_ask\":\"0.35\"}, {\"asset_id\":\"14766054693214075530629349735273995982307625376442606753688071083149620216746\", \"price\":\"0.65\", \"size\":\"50\", \"side\":\"BUY\", \"hash\":\"5101bc8ac89258f0f43d5b4e37c47c57d31c7e98\", \"best_bid\":\"0.65\", \"best_ask\":\"0.66\"}], \"timestamp\":\"1785130851347\", \"event_type\":\"price_change\"}","received_at":"2026-07-27T05:40:56.994600Z","schema_version":"clob-market-ws.price_change.v1","sequence":null,"server_hash":null,"server_timestamp":"1785130851347","session_id":"502006c5cfcd437296561ea750c9ec8b","source":"clob_market_ws"},"received_at":"2026-07-27T05:40:56.994600Z","record_id":"df80bd93bdb83fc990648c9b9eb13aecab5f0c7d3bab98cbc6a715f5ed1aca91","schema_fingerprint":"4aa3821a28b0b7c2400bc59aba4bcc0a76e971dadd19610d3ad38c768e124dc7","schema_version":"edge-lab-recorder.raw.v1","sequence":null,"source":"clob_market_ws"}
{"event_at":"2026-07-27T05:40:51.348000Z","event_fingerprint":"2124f05c3b246083d3e8d75b3bd122448cb432617a30a2796ec7f571d7f4d16c","payload":{"connection_id":"efc69d3132f1467b8e898a382b23ac0d","event_at":"2026-07-27T05:40:51.348000Z","event_type":"price_change","frame_hash":"d54cc66c0fc926bd422eb8310e259b8eba01d47534c069addbd8b83a530026fa","frame_index":0,"kind":"data","monotonic_ns":232840231109375,"payload":{"event_type":"price_change","market":"0x3b40066b5cf3871a2f6237c5628bd8092a206aa998558ac5ec13c4483e31e160","price_changes":[{"asset_id":"14766054693214075530629349735273995982307625376442606753688071083149620216746","best_ask":"0.66","best_bid":"0.65","hash":"4c6dcf70c06cdd974bc862b1ef970d14b71f8cb6","price":"0.65","side":"BUY","size":"59.6"},{"asset_id":"110216635572655435074987471276357323571387854733835379371586402147734167783946","best_ask":"0.35","best_bid":"0.34","hash":"3e2c1d2d674f2c18f91cb7891d8772ee92802efe","price":"0.35","side":"SELL","size":"59.6"}],"timestamp":"1785130851348"},"payload_hash":"df3a4067038100107f42a4a8b3e28d613e6896dfba8886a4a2355873b980631e","raw_frame":"{\"market\":\"0x3b40066b5cf3871a2f6237c5628bd8092a206aa998558ac5ec13c4483e31e160\", \"price_changes\":[{\"asset_id\":\"14766054693214075530629349735273995982307625376442606753688071083149620216746\", \"price\":\"0.65\", \"size\":\"59.6\", \"side\":\"BUY\", \"hash\":\"4c6dcf70c06cdd974bc862b1ef970d14b71f8cb6\", \"best_bid\":\"0.65\", \"best_ask\":\"0.66\"}, {\"asset_id\":\"110216635572655435074987471276357323571387854733835379371586402147734167783946\", \"price\":\"0.35\", \"size\":\"59.6\", \"side\":\"SELL\", \"hash\":\"3e2c1d2d674f2c18f91cb7891d8772ee92802efe\", \"best_bid\":\"0.34\", \"best_ask\":\"0.35\"}], \"timestamp\":\"1785130851348\", \"event_type\":\"price_change\"}","received_at":"2026-07-27T05:40:56.997465Z","schema_version":"clob-market-ws.price_change.v1","sequence":null,"server_hash":null,"server_timestamp":"1785130851348","session_id":"502006c5cfcd437296561ea750c9ec8b","source":"clob_market_ws"},"received_at":"2026-07-27T05:40:56.997465Z","record_id":"bdb8387f1db5abba9223f6d1fc34d29fc5d4245500152cccbec2f39894dec8b8","schema_fingerprint":"4aa3821a28b0b7c2400bc59aba4bcc0a76e971dadd19610d3ad38c768e124dc7","schema_version":"edge-lab-recorder.raw.v1","sequence":null,"source":"clob_market_ws"}
{"event_at":"2026-07-27T05:40:51.349000Z","event_fingerprint":"5b5ca0430a2e3a98b944dc9d3095cbc555eedd40e138088685f815e953853574","payload":{"connection_id":"efc69d3132f1467b8e898a382b23ac0d","event_at":"2026-07-27T05:40:51.349000Z","event_type":"price_change","frame_hash":"ce7a1b5a7d5ba85b18e2450b4625839dbd81e0c168ea66732b111de5f0bf0446","frame_index":0,"kind":"data","monotonic_ns":232840232294041,"payload":{"event_type":"price_change","market":"0x3b40066b5cf3871a2f6237c5628bd8092a206aa998558ac5ec13c4483e31e160","price_changes":[{"asset_id":"110216635572655435074987471276357323571387854733835379371586402147734167783946","best_ask":"0.35","best_bid":"0.34","hash":"9d3c74ec6b63475b722326c6ea82b33c71c8306b","price":"0.35","side":"SELL","size":"66.6"},{"asset_id":"14766054693214075530629349735273995982307625376442606753688071083149620216746","best_ask":"0.66","best_bid":"0.65","hash":"dc8ea80f918b7fde5a7e7edb8315ee26b6cebf43","price":"0.65","side":"BUY","size":"66.6"}],"timestamp":"1785130851349"},"payload_hash":"5601a2d59c972fbb730b1788530d616809cfee0a38280da7f67f0f14acbd1ee0","raw_frame":"{\"market\":\"0x3b40066b5cf3871a2f6237c5628bd8092a206aa998558ac5ec13c4483e31e160\", \"price_changes\":[{\"asset_id\":\"110216635572655435074987471276357323571387854733835379371586402147734167783946\", \"price\":\"0.35\", \"size\":\"66.6\", \"side\":\"SELL\", \"hash\":\"9d3c74ec6b63475b722326c6ea82b33c71c8306b\", \"best_bid\":\"0.34\", \"best_ask\":\"0.35\"}, {\"asset_id\":\"14766054693214075530629349735273995982307625376442606753688071083149620216746\", \"price\":\"0.65\", \"size\":\"66.6\", \"side\":\"BUY\", \"hash\":\"dc8ea80f918b7fde5a7e7edb8315ee26b6cebf43\", \"best_bid\":\"0.65\", \"best_ask\":\"0.66\"}], \"timestamp\":\"1785130851349\", \"event_type\":\"price_change\"}","received_at":"2026-07-27T05:40:56.998656Z","schema_version":"clob-market-ws.price_change.v1","sequence":null,"server_hash":null,"server_timestamp":"1785130851349","session_id":"502006c5cfcd437296561ea750c9ec8b","source":"clob_market_ws"},"received_at":"2026-07-27T05:40:56.998656Z","record_id":"3d9978f3e395d10d23678f9a02fc827c4fcd2dda73a271ada073be33b2ddf5f9","schema_fingerprint":"4aa3821a28b0b7c2400bc59aba4bcc0a76e971dadd19610d3ad38c768e124dc7","schema_version":"edge-lab-recorder.raw.v1","sequence":null,"source":"clob_market_ws"}
{"event_at":"2026-07-27T05:40:51.350000Z","event_fingerprint":"b1a6a352ce8ba7ea6894354cbbf09a157527ef517e875d08f1f8eb73b6163efe","payload":{"connection_id":"efc69d3132f1467b8e898a382b23ac0d","event_at":"2026-07-27T05:40:51.350000Z","event_type":"price_change","frame_hash":"124a6f51d1463aad8513d07d916351a4b3b5c638559bdc4a903f6e604b0ac0e6","frame_index":0,"kind":"data","monotonic_ns":232840234224791,"payload":{"event_type":"price_change","market":"0x3b40066b5cf3871a2f6237c5628bd8092a206aa998558ac5ec13c4483e31e160","price_changes":[{"asset_id":"14766054693214075530629349735273995982307625376442606753688071083149620216746","best_ask":"0.66","best_bid":"0.65","hash":"3f55969c2a4772b8ed5f586028eb5bf89233f801","price":"0.62","side":"BUY","size":"42.6"},{"asset_id":"110216635572655435074987471276357323571387854733835379371586402147734167783946","best_ask":"0.35","best_bid":"0.34","hash":"6da5d1378b16cb9c925a466ec40462e7adf8fad2","price":"0.38","side":"SELL","size":"42.6"}],"timestamp":"1785130851350"},"payload_hash":"347c4df53b2fef3f5538aca5da18f35e1ce83c1e3b4e53a70d3eb59c095be4b1","raw_frame":"{\"market\":\"0x3b40066b5cf3871a2f6237c5628bd8092a206aa998558ac5ec13c4483e31e160\", \"price_changes\":[{\"asset_id\":\"14766054693214075530629349735273995982307625376442606753688071083149620216746\", \"price\":\"0.62\", \"size\":\"42.6\", \"side\":\"BUY\", \"hash\":\"3f55969c2a4772b8ed5f586028eb5bf89233f801\", \"best_bid\":\"0.65\", \"best_ask\":\"0.66\"}, {\"asset_id\":\"110216635572655435074987471276357323571387854733835379371586402147734167783946\", \"price\":\"0.38\", \"size\":\"42.6\", \"side\":\"SELL\", \"hash\":\"6da5d1378b16cb9c925a466ec40462e7adf8fad2\", \"best_bid\":\"0.34\", \"best_ask\":\"0.35\"}], \"timestamp\":\"1785130851350\", \"event_type\":\"price_change\"}","received_at":"2026-07-27T05:40:57.000580Z","schema_version":"clob-market-ws.price_change.v1","sequence":null,"server_hash":null,"server_timestamp":"1785130851350","session_id":"502006c5cfcd437296561ea750c9ec8b","source":"clob_market_ws"},"received_at":"2026-07-27T05:40:57.000580Z","record_id":"97bb48b28dbf57a7d6d0b3fa4e7695fa851678e97319b333962db63c015bf35c","schema_fingerprint":"4aa3821a28b0b7c2400bc59aba4bcc0a76e971dadd19610d3ad38c768e124dc7","schema_version":"edge-lab-recorder.raw.v1","sequence":null,"source":"clob_market_ws"}
{"event_at":"2026-07-27T05:40:51.351000Z","event_fingerprint":"53d55155acfdf8837d86d9e58a509b7a2e2cd5df0cd59422c943ab70ceb84664","payload":{"connection_id":"efc69d3132f1467b8e898a382b23ac0d","event_at":"2026-07-27T05:40:51.351000Z","event_type":"price_change","frame_hash":"b4a559085b044911224218ad45692148f126db3bbd7a49ba8c76d18a01b583fa","frame_index":0,"kind":"data","monotonic_ns":232840236766083,"payload":{"event_type":"price_change","market":"0x3b40066b5cf3871a2f6237c5628bd8092a206aa998558ac5ec13c4483e31e160","price_changes":[{"asset_id":"110216635572655435074987471276357323571387854733835379371586402147734167783946","best_ask":"0.35","best_bid":"0.34","hash":"38b5da2ddd2769d09e1b2fbafa86ffa8cf7a5c78","price":"0.33","side":"BUY","size":"11"},{"asset_id":"14766054693214075530629349735273995982307625376442606753688071083149620216746","best_ask":"0.66","best_bid":"0.65","hash":"af03da84bb04f677a34653cd6e81a2557d1ae4ae","price":"0.67","side":"SELL","size":"11"}],"timestamp":"1785130851351"},"payload_hash":"ecde64509d83b15cd357c9b546a286cdcaddb55a1892e80acd2d07d129b302c6","raw_frame":"{\"market\":\"0x3b40066b5cf3871a2f6237c5628bd8092a206aa998558ac5ec13c4483e31e160\", \"price_changes\":[{\"asset_id\":\"110216635572655435074987471276357323571387854733835379371586402147734167783946\", \"price\":\"0.33\", \"size\":\"11\", \"side\":\"BUY\", \"hash\":\"38b5da2ddd2769d09e1b2fbafa86ffa8cf7a5c78\", \"best_bid\":\"0.34\", \"best_ask\":\"0.35\"}, {\"asset_id\":\"14766054693214075530629349735273995982307625376442606753688071083149620216746\", \"price\":\"0.67\", \"size\":\"11\", \"side\":\"SELL\", \"hash\":\"af03da84bb04f677a34653cd6e81a2557d1ae4ae\", \"best_bid\":\"0.65\", \"best_ask\":\"0.66\"}], \"timestamp\":\"1785130851351\", \"event_type\":\"price_change\"}","received_at":"2026-07-27T05:40:57.003121Z","schema_version":"clob-market-ws.price_change.v1","sequence":null,"server_hash":null,"server_timestamp":"1785130851351","session_id":"502006c5cfcd437296561ea750c9ec8b","source":"clob_market_ws"},"received_at":"2026-07-27T05:40:57.003121Z","record_id":"6c4b45b26869d0c9e8b4d7b89f53e42924269d180c97a74be46255598c42e412","schema_fingerprint":"4aa3821a28b0b7c2400bc59aba4bcc0a76e971dadd19610d3ad38c768e124dc7","schema_version":"edge-lab-recorder.raw.v1","sequence":null,"source":"clob_market_ws"}
{"event_at":"2026-07-27T05:40:51.362000Z","event_fingerprint":"c54b387f74d4956137b45b12d17e2df8341316da74b34c5d46717b0f7971666b","payload":{"connection_id":"efc69d3132f1467b8e898a382b23ac0d","event_at":"2026-07-27T05:40:51.362000Z","event_type":"price_change","frame_hash":"c387230d22d6e1343dbd05c9233e7308c271df6f10a31c206be1290dad9c714d","frame_index":0,"kind":"data","monotonic_ns":232840239697500,"payload":{"event_type":"price_change","market":"0x3b40066b5cf3871a2f6237c5628bd8092a206aa998558ac5ec13c4483e31e160","price_changes":[{"asset_id":"110216635572655435074987471276357323571387854733835379371586402147734167783946","best_ask":"0.35","best_bid":"0.34","hash":"ee8655da01770fdc71848d47822d0bdcb6ea603f","price":"0.28","side":"BUY","size":"60.97"},{"asset_id":"14766054693214075530629349735273995982307625376442606753688071083149620216746","best_ask":"0.66","best_bid":"0.65","hash":"d1b6080a3b5e856a0a50e5f4ab2c338fefdf40f1","price":"0.72","side":"SELL","size":"60.97"}],"timestamp":"1785130851362"},"payload_hash":"d2c637e08d9e79e0c560906d5b2bc7fde1b302a01bb5d3f607ab822fc71b467a","raw_frame":"{\"market\":\"0x3b40066b5cf3871a2f6237c5628bd8092a206aa998558ac5ec13c4483e31e160\", \"price_changes\":[{\"asset_id\":\"110216635572655435074987471276357323571387854733835379371586402147734167783946\", \"price\":\"0.28\", \"size\":\"60.97\", \"side\":\"BUY\", \"hash\":\"ee8655da01770fdc71848d47822d0bdcb6ea603f\", \"best_bid\":\"0.34\", \"best_ask\":\"0.35\"}, {\"asset_id\":\"14766054693214075530629349735273995982307625376442606753688071083149620216746\", \"price\":\"0.72\", \"size\":\"60.97\", \"side\":\"SELL\", \"hash\":\"d1b6080a3b5e856a0a50e5f4ab2c338fefdf40f1\", \"best_bid\":\"0.65\", \"best_ask\":\"0.66\"}], \"timestamp\":\"1785130851362\", \"event_type\":\"price_change\"}","received_at":"2026-07-27T05:40:57.006053Z","schema_version":"clob-market-ws.price_change.v1","sequence":null,"server_hash":null,"server_timestamp":"1785130851362","session_id":"502006c5cfcd437296561ea750c9ec8b","source":"clob_market_ws"},"received_at":"2026-07-27T05:40:57.006053Z","record_id":"dae65e2348a21bd000a06e64d1a7ad798496c3be1d6d5447eb2086e6c795cdc8","schema_fingerprint":"4aa3821a28b0b7c2400bc59aba4bcc0a76e971dadd19610d3ad38c768e124dc7","schema_version":"edge-lab-recorder.raw.v1","sequence":null,"source":"clob_market_ws"}
{"event_at":"2026-07-27T05:40:51.368000Z","event_fingerprint":"40b4d288952bb32833de07e12422cc64068b3e755ce7a4571924445d0c5ab68f","payload":{"connection_id":"efc69d3132f1467b8e898a382b23ac0d","event_at":"2026-07-27T05:40:51.368000Z","event_type":"price_change","frame_hash":"491b2e334370e5f2d8f213b7cd2663606fe59f011c7269ab59a254746250242d","frame_index":0,"kind":"data","monotonic_ns":232840246074708,"payload":{"event_type":"price_change","market":"0x3b40066b5cf3871a2f6237c5628bd8092a206aa998558ac5ec13c4483e31e160","price_changes":[{"asset_id":"110216635572655435074987471276357323571387854733835379371586402147734167783946","best_ask":"0.35","best_bid":"0.34","hash":"827ba1a28bca135d9e9176360f6247ae6e60697b","price":"0.3","side":"BUY","size":"112.97"},{"asset_id":"14766054693214075530629349735273995982307625376442606753688071083149620216746","best_ask":"0.66","best_bid":"0.65","hash":"c43b48b12586e0a73bac702406c3bba90d1dfa3a","price":"0.7","side":"SELL","size":"112.97"}],"timestamp":"1785130851368"},"payload_hash":"0f1f9076f709e2a3c70cc74cf000abd913c059cba6eeededb7c37f4f324d4ac1","raw_frame":"{\"market\":\"0x3b40066b5cf3871a2f6237c5628bd8092a206aa998558ac5ec13c4483e31e160\", \"price_changes\":[{\"asset_id\":\"110216635572655435074987471276357323571387854733835379371586402147734167783946\", \"price\":\"0.3\", \"size\":\"112.97\", \"side\":\"BUY\", \"hash\":\"827ba1a28bca135d9e9176360f6247ae6e60697b\", \"best_bid\":\"0.34\", \"best_ask\":\"0.35\"}, {\"asset_id\":\"14766054693214075530629349735273995982307625376442606753688071083149620216746\", \"price\":\"0.7\", \"size\":\"112.97\", \"side\":\"SELL\", \"hash\":\"c43b48b12586e0a73bac702406c3bba90d1dfa3a\", \"best_bid\":\"0.65\", \"best_ask\":\"0.66\"}], \"timestamp\":\"1785130851368\", \"event_type\":\"price_change\"}","received_at":"2026-07-27T05:40:57.012428Z","schema_version":"clob-market-ws.price_change.v1","sequence":null,"server_hash":null,"server_timestamp":"1785130851368","session_id":"502006c5cfcd437296561ea750c9ec8b","source":"clob_market_ws"},"received_at":"2026-07-27T05:40:57.012428Z","record_id":"d4140552471cb3017e9ce987d85a4f83e9b5479c6b074ed6ea9649c95549289a","schema_fingerprint":"4aa3821a28b0b7c2400bc59aba4bcc0a76e971dadd19610d3ad38c768e124dc7","schema_version":"edge-lab-recorder.raw.v1","sequence":null,"source":"clob_market_ws"}
{"event_at":"2026-07-27T05:40:51.368000Z","event_fingerprint":"3afb50abb584b1da47269329ecc904e0bb98b269937cbdb71e6eebde15b285e1","payload":{"connection_id":"efc69d3132f1467b8e898a382b23ac0d","event_at":"2026-07-27T05:40:51.368000Z","event_type":"price_change","frame_hash":"21ff59af29e621d2a09e2e5e29c9b9f7c04fdc03f6ed081c8abb681e13c5690c","frame_index":0,"kind":"data","monotonic_ns":232840249569000,"payload":{"event_type":"price_change","market":"0x3b40066b5cf3871a2f6237c5628bd8092a206aa998558ac5ec13c4483e31e160","price_changes":[{"asset_id":"14766054693214075530629349735273995982307625376442606753688071083149620216746","best_ask":"0.66","best_bid":"0.65","hash":"b83aab6c0ed76bac855f3888ad25887f86566e63","price":"0.47","side":"BUY","size":"50"},{"asset_id":"110216635572655435074987471276357323571387854733835379371586402147734167783946","best_ask":"0.35","best_bid":"0.34","hash":"807faed0f7239e44b5ea38aefb452ff9d3b08c08","price":"0.53","side":"SELL","size":"50"}],"timestamp":"1785130851368"},"payload_hash":"da23c7867e1957128f15ac8242d5f1392a2e3371fb5a2d642cba02c7a532ca69","raw_frame":"{\"market\":\"0x3b40066b5cf3871a2f6237c5628bd8092a206aa998558ac5ec13c4483e31e160\", \"price_changes\":[{\"asset_id\":\"14766054693214075530629349735273995982307625376442606753688071083149620216746\", \"price\":\"0.47\", \"size\":\"50\", \"side\":\"BUY\", \"hash\":\"b83aab6c0ed76bac855f3888ad25887f86566e63\", \"best_bid\":\"0.65\", \"best_ask\":\"0.66\"}, {\"asset_id\":\"110216635572655435074987471276357323571387854733835379371586402147734167783946\", \"price\":\"0.53\", \"size\":\"50\", \"side\":\"SELL\", \"hash\":\"807faed0f7239e44b5ea38aefb452ff9d3b08c08\", \"best_bid\":\"0.34\", \"best_ask\":\"0.35\"}], \"timestamp\":\"1785130851368\", \"event_type\":\"price_change\"}","received_at":"2026-07-27T05:40:57.015923Z","schema_version":"clob-market-ws.price_change.v1","sequence":null,"server_hash":null,"server_timestamp":"1785130851368","session_id":"502006c5cfcd437296561ea750c9ec8b","source":"clob_market_ws"},"received_at":"2026-07-27T05:40:57.015923Z","record_id":"2143b43c22c20b8c067040d676bb1720c728b512bb3a2582bef467723feca5f3","schema_fingerprint":"4aa3821a28b0b7c2400bc59aba4bcc0a76e971dadd19610d3ad38c768e124dc7","schema_version":"edge-lab-recorder.raw.v1","sequence":null,"source":"clob_market_ws"}
{"event_at":"2026-07-27T05:40:51.373000Z","event_fingerprint":"0b0cf49a3cd39fc5d9ecd95b321b9ad94adde523a4ea1f8aadb9d8b89795988e","payload":{"connection_id":"efc69d3132f1467b8e898a382b23ac0d","event_at":"2026-07-27T05:40:51.373000Z","event_type":"price_change","frame_hash":"31839b02d78977838de88b0bf110d3753b8afb0a01b5e5a5b802ff6257b4308f","frame_index":0,"kind":"data","monotonic_ns":232840255611583,"payload":{"event_type":"price_change","market":"0x3b40066b5cf3871a2f6237c5628bd8092a206aa998558ac5ec13c4483e31e160","price_changes":[{"asset_id":"14766054693214075530629349735273995982307625376442606753688071083149620216746","best_ask":"0.66","best_bid":"0.65","hash":"aaba2bdf568ae37d00a4755838b401edb4030d4b","price":"0.63","side":"BUY","size":"42.6"},{"asset_id":"110216635572655435074987471276357323571387854733835379371586402147734167783946","best_ask":"0.35","best_bid":"0.34","hash":"1783d1807fadb9f43079e07e849feef4e4a4520d","price":"0.37","side":"SELL","size":"42.6"}],"timestamp":"1785130851373"},"payload_hash":"a98861bdfc3d236c95b5d28fc6c37cc23553492acdcbb6a27f645235b7bd553d","raw_frame":"{\"market\":\"0x3b40066b5cf3871a2f6237c5628bd8092a206aa998558ac5ec13c4483e31e160\", \"price_changes\":[{\"asset_id\":\"14766054693214075530629349735273995982307625376442606753688071083149620216746\", \"price\":\"0.63\", \"size\":\"42.6\", \"side\":\"BUY\", \"hash\":\"aaba2bdf568ae37d00a4755838b401edb4030d4b\", \"best_bid\":\"0.65\", \"best_ask\":\"0.66\"}, {\"asset_id\":\"110216635572655435074987471276357323571387854733835379371586402147734167783946\", \"price\":\"0.37\", \"size\":\"42.6\", \"side\":\"SELL\", \"hash\":\"1783d1807fadb9f43079e07e849feef4e4a4520d\", \"best_bid\":\"0.34\", \"best_ask\":\"0.35\"}], \"timestamp\":\"1785130851373\", \"event_type\":\"price_change\"}","received_at":"2026-07-27T05:40:57.021967Z","schema_version":"clob-market-ws.price_change.v1","sequence":null,"server_hash":null,"server_timestamp":"1785130851373","session_id":"502006c5cfcd437296561ea750c9ec8b","source":"clob_market_ws"},"received_at":"2026-07-27T05:40:57.021967Z","record_id":"7207c199462261b7eef3afe09cd97fef7564ffe7a5c71ae8173d3458a6b2b191","schema_fingerprint":"4aa3821a28b0b7c2400bc59aba4bcc0a76e971dadd19610d3ad38c768e124dc7","schema_version":"edge-lab-recorder.raw.v1","sequence":null,"source":"clob_market_ws"}
{"event_at":"2026-07-27T05:40:51.375000Z","event_fingerprint":"b09dd48201a25dacc6193ec4d800ceb16d56c0a197496d1b2754687628c95b87","payload":{"connection_id":"efc69d3132f1467b8e898a382b23ac0d","event_at":"2026-07-27T05:40:51.375000Z","event_type":"price_change","frame_hash":"07b500801e4bc7dc8c98216e046336b2e42c489791a3db8d8e60978e9edba209","frame_index":0,"kind":"data","monotonic_ns":232840260750750,"payload":{"event_type":"price_change","market":"0x3b40066b5cf3871a2f6237c5628bd8092a206aa998558ac5ec13c4483e31e160","price_changes":[{"asset_id":"14766054693214075530629349735273995982307625376442606753688071083149620216746","best_ask":"0.66","best_bid":"0.65","hash":"c1e8a8d6d45112210f768299a425de62d5e89ee5","price":"0.57","side":"BUY","size":"45.2"},{"asset_id":"110216635572655435074987471276357323571387854733835379371586402147734167783946","best_ask":"0.35","best_bid":"0.34","hash":"c6cf6cb9ce8a44eb1ff4269bb538700759b1ef74","price":"0.43","side":"SELL","size":"45.2"}],"timestamp":"1785130851375"},"payload_hash":"fd780b2537c13bb90cad9e81c8b1196c47fbba9f4789624899709cbb5a25e532","raw_frame":"{\"market\":\"0x3b40066b5cf3871a2f6237c5628bd8092a206aa998558ac5ec13c4483e31e160\", \"price_changes\":[{\"asset_id\":\"14766054693214075530629349735273995982307625376442606753688071083149620216746\", \"price\":\"0.57\", \"size\":\"45.2\", \"side\":\"BUY\", \"hash\":\"c1e8a8d6d45112210f768299a425de62d5e89ee5\", \"best_bid\":\"0.65\", \"best_ask\":\"0.66\"}, {\"asset_id\":\"110216635572655435074987471276357323571387854733835379371586402147734167783946\", \"price\":\"0.43\", \"size\":\"45.2\", \"side\":\"SELL\", \"hash\":\"c6cf6cb9ce8a44eb1ff4269bb538700759b1ef74\", \"best_bid\":\"0.34\", \"best_ask\":\"0.35\"}], \"timestamp\":\"1785130851375\", \"event_type\":\"price_change\"}","received_at":"2026-07-27T05:40:57.027105Z","schema_version":"clob-market-ws.price_change.v1","sequence":null,"server_hash":null,"server_timestamp":"1785130851375","session_id":"502006c5cfcd437296561ea750c9ec8b","source":"clob_market_ws"},"received_at":"2026-07-27T05:40:57.027105Z","record_id":"d0efc74f4366b959d20dd036c956c9df91618a4a278ee5ddf2b5244cc0a219cb","schema_fingerprint":"4aa3821a28b0b7c2400bc59aba4bcc0a76e971dadd19610d3ad38c768e124dc7","schema_version":"edge-lab-recorder.raw.v1","sequence":null,"source":"clob_market_ws"}
{"event_at":"2026-07-27T05:40:51.377000Z","event_fingerprint":"0931d9c7dd66f80fcddf52e901b78873bf2ae3e673a1c0f049d8175c6b285f6d","payload":{"connection_id":"efc69d3132f1467b8e898a382b23ac0d","event_at":"2026-07-27T05:40:51.377000Z","event_type":"price_change","frame_hash":"929aaf818902e3ff1ff7e4b2aaf4f719dd1d8b61a99a8bfd3ba3fa6b8042259f","frame_index":0,"kind":"data","monotonic_ns":232840263821250,"payload":{"event_type":"price_change","market":"0x3b40066b5cf3871a2f6237c5628bd8092a206aa998558ac5ec13c4483e31e160","price_changes":[{"asset_id":"14766054693214075530629349735273995982307625376442606753688071083149620216746","best_ask":"0.66","best_bid":"0.65","hash":"581c8386efda81acb1d04b94c6f2ba36ee958de4","price":"0.88","side":"SELL","size":"103.4"},{"asset_id":"110216635572655435074987471276357323571387854733835379371586402147734167783946","best_ask":"0.35","best_bid":"0.34","hash":"c8b0ad53f8e73b6adff3cc17f3282f9ba90c1e69","price":"0.12","side":"BUY","size":"103.4"}],"timestamp":"1785130851377"},"payload_hash":"fb18554df4554d21c5f2b281c9c2f83c549b957e2618d6ce97bf5dd169b26d51","raw_frame":"{\"market\":\"0x3b40066b5cf3871a2f6237c5628bd8092a206aa998558ac5ec13c4483e31e160\", \"price_changes\":[{\"asset_id\":\"14766054693214075530629349735273995982307625376442606753688071083149620216746\", \"price\":\"0.88\", \"size\":\"103.4\", \"side\":\"SELL\", \"hash\":\"581c8386efda81acb1d04b94c6f2ba36ee958de4\", \"best_bid\":\"0.65\", \"best_ask\":\"0.66\"}, {\"asset_id\":\"110216635572655435074987471276357323571387854733835379371586402147734167783946\", \"price\":\"0.12\", \"size\":\"103.4\", \"side\":\"BUY\", \"hash\":\"c8b0ad53f8e73b6adff3cc17f3282f9ba90c1e69\", \"best_bid\":\"0.34\", \"best_ask\":\"0.35\"}], \"timestamp\":\"1785130851377\", \"event_type\":\"price_change\"}","received_at":"2026-07-27T05:40:57.030177Z","schema_version":"clob-market-ws.price_change.v1","sequence":null,"server_hash":null,"server_timestamp":"1785130851377","session_id":"502006c5cfcd437296561ea750c9ec8b","source":"clob_market_ws"},"received_at":"2026-07-27T05:40:57.030177Z","record_id":"b97dfd5ee8146703a19bb4dae1e5ae45e0bfabe7d48d61229643938a603a0cab","schema_fingerprint":"4aa3821a28b0b7c2400bc59aba4bcc0a76e971dadd19610d3ad38c768e124dc7","schema_version":"edge-lab-recorder.raw.v1","sequence":null,"source":"clob_market_ws"}
{"event_at":"2026-07-27T05:40:51.378000Z","event_fingerprint":"b9ae356fbff0eac07ccacbee4ba356c3f083f283ef30596820ca1e16256d9f47","payload":{"connection_id":"efc69d3132f1467b8e898a382b23ac0d","event_at":"2026-07-27T05:40:51.378000Z","event_type":"price_change","frame_hash":"e43761755bdf54a86d209daf63dfc7b2009bdcd6410a86c64ac08ff84e2bd1da","frame_index":0,"kind":"data","monotonic_ns":232840266011166,"payload":{"event_type":"price_change","market":"0x3b40066b5cf3871a2f6237c5628bd8092a206aa998558ac5ec13c4483e31e160","price_changes":[{"asset_id":"110216635572655435074987471276357323571387854733835379371586402147734167783946","best_ask":"0.35","best_bid":"0.34","hash":"781dd1e6422a42c6346f6208350a8e9133e83085","price":"0.33","side":"BUY","size":"20.6"},{"asset_id":"14766054693214075530629349735273995982307625376442606753688071083149620216746","best_ask":"0.66","best_bid":"0.65","hash":"2bde8845638aec5271d9377d2cdfa4d386c17d47","price":"0.67","side":"SELL","size":"20.6"}],"timestamp":"1785130851378"},"payload_hash":"c595691f7d36a9b310086f9cdd85eec5a261389e4d31bda7a206a2f9bedd2e01","raw_frame":"{\"market\":\"0x3b40066b5cf3871a2f6237c5628bd8092a206aa998558ac5ec13c4483e31e160\", \"price_changes\":[{\"asset_id\":\"110216635572655435074987471276357323571387854733835379371586402147734167783946\", \"price\":\"0.33\", \"size\":\"20.6\", \"side\":\"BUY\", \"hash\":\"781dd1e6422a42c6346f6208350a8e9133e83085\", \"best_bid\":\"0.34\", \"best_ask\":\"0.35\"}, {\"asset_id\":\"14766054693214075530629349735273995982307625376442606753688071083149620216746\", \"price\":\"0.67\", \"size\":\"20.6\", \"side\":\"SELL\", \"hash\":\"2bde8845638aec5271d9377d2cdfa4d386c17d47\", \"best_bid\":\"0.65\", \"best_ask\":\"0.66\"}], \"timestamp\":\"1785130851378\", \"event_type\":\"price_change\"}","received_at":"2026-07-27T05:40:57.032367Z","schema_version":"clob-market-ws.price_change.v1","sequence":null,"server_hash":null,"server_timestamp":"1785130851378","session_id":"502006c5cfcd437296561ea750c9ec8b","source":"clob_market_ws"},"received_at":"2026-07-27T05:40:57.032367Z","record_id":"919934d40c65cf8923eecf68514890ea8e446634c7a1562a7a13fb509199cffb","schema_fingerprint":"4aa3821a28b0b7c2400bc59aba4bcc0a76e971dadd19610d3ad38c768e124dc7","schema_version":"edge-lab-recorder.raw.v1","sequence":null,"source":"clob_market_ws"}
{"event_at":"2026-07-27T05:40:51.379000Z","event_fingerprint":"31f20da3a24d7418e8e67cdec8d5741916425cdbd61d0b5d350d196d5053daf5","payload":{"connection_id":"efc69d3132f1467b8e898a382b23ac0d","event_at":"2026-07-27T05:40:51.379000Z","event_type":"price_change","frame_hash":"7c619d705c9bed81ebdc1399a736b00712f609ac6622df0be4add524c33b5143","frame_index":0,"kind":"data","monotonic_ns":232840268446625,"payload":{"event_type":"price_change","market":"0x3b40066b5cf3871a2f6237c5628bd8092a206aa998558ac5ec13c4483e31e160","price_changes":[{"asset_id":"14766054693214075530629349735273995982307625376442606753688071083149620216746","best_ask":"0.66","best_bid":"0.65","hash":"879f12faa0690b74f54c5b5a3275675b3cffeaa1","price":"0.7","side":"SELL","size":"86.98"},{"asset_id":"110216635572655435074987471276357323571387854733835379371586402147734167783946","best_ask":"0.35","best_bid":"0.34","hash":"dabfe52baaf88890b27bbb94f8769da39e48852d","price":"0.3","side":"BUY","size":"86.98"}],"timestamp":"1785130851379"},"payload_hash":"6a12e1de84a34c158559d355e9690458c43be85747263467187236634369065d","raw_frame":"{\"market\":\"0x3b40066b5cf3871a2f6237c5628bd8092a206aa998558ac5ec13c4483e31e160\", \"price_changes\":[{\"asset_id\":\"14766054693214075530629349735273995982307625376442606753688071083149620216746\", \"price\":\"0.7\", \"size\":\"86.98\", \"side\":\"SELL\", \"hash\":\"879f12faa0690b74f54c5b5a3275675b3cffeaa1\", \"best_bid\":\"0.65\", \"best_ask\":\"0.66\"}, {\"asset_id\":\"110216635572655435074987471276357323571387854733835379371586402147734167783946\", \"price\":\"0.3\", \"size\":\"86.98\", \"side\":\"BUY\", \"hash\":\"dabfe52baaf88890b27bbb94f8769da39e48852d\", \"best_bid\":\"0.34\", \"best_ask\":\"0.35\"}], \"timestamp\":\"1785130851379\", \"event_type\":\"price_change\"}","received_at":"2026-07-27T05:40:57.034803Z","schema_version":"clob-market-ws.price_change.v1","sequence":null,"server_hash":null,"server_timestamp":"1785130851379","session_id":"502006c5cfcd437296561ea750c9ec8b","source":"clob_market_ws"},"received_at":"2026-07-27T05:40:57.034803Z","record_id":"2a8ca34472df553d12721f1e6135d6cbae520b952abac3d04abb73fafab46d83","schema_fingerprint":"4aa3821a28b0b7c2400bc59aba4bcc0a76e971dadd19610d3ad38c768e124dc7","schema_version":"edge-lab-recorder.raw.v1","sequence":null,"source":"clob_market_ws"}
{"event_at":"2026-07-27T05:40:51.379000Z","event_fingerprint":"d68fb974937be99167ee02fca4fa9dd7fc86ad5d952d03de33f05c3d688fda44","payload":{"connection_id":"efc69d3132f1467b8e898a382b23ac0d","event_at":"2026-07-27T05:40:51.379000Z","event_type":"price_change","frame_hash":"ba16808c0783ebcc3135d725a8e0bc2b0c95b93ffa3b06b78e57bcafd3d3e57b","frame_index":0,"kind":"data","monotonic_ns":232840271326250,"payload":{"event_type":"price_change","market":"0x3b40066b5cf3871a2f6237c5628bd8092a206aa998558ac5ec13c4483e31e160","price_changes":[{"asset_id":"110216635572655435074987471276357323571387854733835379371586402147734167783946","best_ask":"0.35","best_bid":"0.34","hash":"dabfe52baaf88890b27bbb94f8769da39e48852d","price":"0.3","side":"BUY","size":"86.98"},{"asset_id":"14766054693214075530629349735273995982307625376442606753688071083149620216746","best_ask":"0.66","best_bid":"0.65","hash":"879f12faa0690b74f54c5b5a3275675b3cffeaa1","price":"0.7","side":"SELL","size":"86.98"}],"timestamp":"1785130851379"},"payload_hash":"92063298bd68149bff9036fe313fba8f98eaa528d4b243f77c63fcf77284b3eb","raw_frame":"{\"market\":\"0x3b40066b5cf3871a2f6237c5628bd8092a206aa998558ac5ec13c4483e31e160\", \"price_changes\":[{\"asset_id\":\"110216635572655435074987471276357323571387854733835379371586402147734167783946\", \"price\":\"0.3\", \"size\":\"86.98\", \"side\":\"BUY\", \"hash\":\"dabfe52baaf88890b27bbb94f8769da39e48852d\", \"best_bid\":\"0.34\", \"best_ask\":\"0.35\"}, {\"asset_id\":\"14766054693214075530629349735273995982307625376442606753688071083149620216746\", \"price\":\"0.7\", \"size\":\"86.98\", \"side\":\"SELL\", \"hash\":\"879f12faa0690b74f54c5b5a3275675b3cffeaa1\", \"best_bid\":\"0.65\", \"best_ask\":\"0.66\"}], \"timestamp\":\"1785130851379\", \"event_type\":\"price_change\"}","received_at":"2026-07-27T05:40:57.037682Z","schema_version":"clob-market-ws.price_change.v1","sequence":null,"server_hash":null,"server_timestamp":"1785130851379","session_id":"502006c5cfcd437296561ea750c9ec8b","source":"clob_market_ws"},"received_at":"2026-07-27T05:40:57.037682Z","record_id":"d5eda45c1334ae5a4de6bd766fe1c53a7ce93a32c4206cdf9b429f8a26933627","schema_fingerprint":"4aa3821a28b0b7c2400bc59aba4bcc0a76e971dadd19610d3ad38c768e124dc7","schema_version":"edge-lab-recorder.raw.v1","sequence":null,"source":"clob_market_ws"}
{"event_at":"2026-07-27T05:40:51.380000Z","event_fingerprint":"f5e03d602039d6047f2540b35dbb0da3535888e260d5e1c0a846e5aa73022893","payload":{"connection_id":"efc69d3132f1467b8e898a382b23ac0d","event_at":"2026-07-27T05:40:51.380000Z","event_type":"price_change","frame_hash":"00b094d4417895fe83b101d704097dee6f06f6f37e9930bb3c1e69dbf68ab877","frame_index":0,"kind":"data","monotonic_ns":232840273814541,"payload":{"event_type":"price_change","market":"0x3b40066b5cf3871a2f6237c5628bd8092a206aa998558ac5ec13c4483e31e160","price_changes":[{"asset_id":"14766054693214075530629349735273995982307625376442606753688071083149620216746","best_ask":"0.66","best_bid":"0.65","hash":"c7361f4b698328f800c4643cd31399f87fe9ff90","price":"0.65","side":"BUY","size":"57"},{"asset_id":"110216635572655435074987471276357323571387854733835379371586402147734167783946","best_ask":"0.35","best_bid":"0.34","hash":"b5d08b0cf7e28ec19b3f3b70daa12b0727c6d495","price":"0.35","side":"SELL","size":"57"}],"timestamp":"1785130851380"},"payload_hash":"504759cf6bec6ac4c4d20c6aa05951f3a74ca8de0ef0727f2d3c492553baf289","raw_frame":"{\"market\":\"0x3b40066b5cf3871a2f6237c5628bd8092a206aa998558ac5ec13c4483e31e160\", \"price_changes\":[{\"asset_id\":\"14766054693214075530629349735273995982307625376442606753688071083149620216746\", \"price\":\"0.65\", \"size\":\"57\", \"side\":\"BUY\", \"hash\":\"c7361f4b698328f800c4643cd31399f87fe9ff90\", \"best_bid\":\"0.65\", \"best_ask\":\"0.66\"}, {\"asset_id\":\"110216635572655435074987471276357323571387854733835379371586402147734167783946\", \"price\":\"0.35\", \"size\":\"57\", \"side\":\"SELL\", \"hash\":\"b5d08b0cf7e28ec19b3f3b70daa12b0727c6d495\", \"best_bid\":\"0.34\", \"best_ask\":\"0.35\"}], \"timestamp\":\"1785130851380\", \"event_type\":\"price_change\"}","received_at":"2026-07-27T05:40:57.040171Z","schema_version":"clob-market-ws.price_change.v1","sequence":null,"server_hash":null,"server_timestamp":"1785130851380","session_id":"502006c5cfcd437296561ea750c9ec8b","source":"clob_market_ws"},"received_at":"2026-07-27T05:40:57.040171Z","record_id":"fca7492ebe6e8f9bea888c4c28feb264df527d1b7e133a03fed25a142df37cf5","schema_fingerprint":"4aa3821a28b0b7c2400bc59aba4bcc0a76e971dadd19610d3ad38c768e124dc7","schema_version":"edge-lab-recorder.raw.v1","sequence":null,"source":"clob_market_ws"}
{"event_at":"2026-07-27T05:40:51.383000Z","event_fingerprint":"cb4ca4a04ed0ab13ab95a52bf60f3f68aed40bf24478c3e2fa7cb92013e55c90","payload":{"connection_id":"efc69d3132f1467b8e898a382b23ac0d","event_at":"2026-07-27T05:40:51.383000Z","event_type":"price_change","frame_hash":"4cb4914416aa6faa11661168fae94c998d877a1a28674b96f20f38ed7e1ca4b5","frame_index":0,"kind":"data","monotonic_ns":232840276222250,"payload":{"event_type":"price_change","market":"0x3b40066b5cf3871a2f6237c5628bd8092a206aa998558ac5ec13c4483e31e160","price_changes":[{"asset_id":"110216635572655435074987471276357323571387854733835379371586402147734167783946","best_ask":"0.35","best_bid":"0.34","hash":"ed72647a4cdbe352d591749827e796908cc86688","price":"0.27","side":"BUY","size":"93"},{"asset_id":"14766054693214075530629349735273995982307625376442606753688071083149620216746","best_ask":"0.66","best_bid":"0.65","hash":"beb78fe72a48f897cd4a0b18fb860c929e3c6b58","price":"0.73","side":"SELL","size":"93"}],"timestamp":"1785130851383"},"payload_hash":"3f6d9539e0cf06eea0553c105a25d92c24f9d6015f7e7949884df53aedf335bf","raw_frame":"{\"market\":\"0x3b40066b5cf3871a2f6237c5628bd8092a206aa998558ac5ec13c4483e31e160\", \"price_changes\":[{\"asset_id\":\"110216635572655435074987471276357323571387854733835379371586402147734167783946\", \"price\":\"0.27\", \"size\":\"93\", \"side\":\"BUY\", \"hash\":\"ed72647a4cdbe352d591749827e796908cc86688\", \"best_bid\":\"0.34\", \"best_ask\":\"0.35\"}, {\"asset_id\":\"14766054693214075530629349735273995982307625376442606753688071083149620216746\", \"price\":\"0.73\", \"size\":\"93\", \"side\":\"SELL\", \"hash\":\"beb78fe72a48f897cd4a0b18fb860c929e3c6b58\", \"best_bid\":\"0.65\", \"best_ask\":\"0.66\"}], \"timestamp\":\"1785130851383\", \"event_type\":\"price_change\"}","received_at":"2026-07-27T05:40:57.042578Z","schema_version":"clob-market-ws.price_change.v1","sequence":null,"server_hash":null,"server_timestamp":"1785130851383","session_id":"502006c5cfcd437296561ea750c9ec8b","source":"clob_market_ws"},"received_at":"2026-07-27T05:40:57.042578Z","record_id":"fefba1dea0ba7be199821aaeaf6b0acd291f66b2918b627807ae7880d3530232","schema_fingerprint":"4aa3821a28b0b7c2400bc59aba4bcc0a76e971dadd19610d3ad38c768e124dc7","schema_version":"edge-lab-recorder.raw.v1","sequence":null,"source":"clob_market_ws"}
{"event_at":"2026-07-27T05:40:51.384000Z","event_fingerprint":"2d07206453101fa824b7bb53e40d49989efdd4cab8b6eddea1d8b3f6bcec81cd","payload":{"connection_id":"efc69d3132f1467b8e898a382b23ac0d","event_at":"2026-07-27T05:40:51.384000Z","event_type":"price_change","frame_hash":"15279f9228ccfb806d5539d1ceef1fb550ca3613fbcef3b378443414fa2122ba","frame_index":0,"kind":"data","monotonic_ns":232840279096583,"payload":{"event_type":"price_change","market":"0x3b40066b5cf3871a2f6237c5628bd8092a206aa998558ac5ec13c4483e31e160","price_changes":[{"asset_id":"110216635572655435074987471276357323571387854733835379371586402147734167783946","best_ask":"0.35","best_bid":"0.34","hash":"1d78e6d3e5c720367963dc6fbe7667a00d2b6cf6","price":"0.29","side":"BUY","size":"64"},{"asset_id":"14766054693214075530629349735273995982307625376442606753688071083149620216746","best_ask":"0.66","best_bid":"0.65","hash":"659e742ff1dc68a3402006418825966177d3117d","price":"0.71","side":"SELL","size":"64"}],"timestamp":"1785130851384"},"payload_hash":"6e0847f5ac75d23fb384052f7bb3de5bb59059acaf077e336358b6394201dc34","raw_frame":"{\"market\":\"0x3b40066b5cf3871a2f6237c5628bd8092a206aa998558ac5ec13c4483e31e160\", \"price_changes\":[{\"asset_id\":\"110216635572655435074987471276357323571387854733835379371586402147734167783946\", \"price\":\"0.29\", \"size\":\"64\", \"side\":\"BUY\", \"hash\":\"1d78e6d3e5c720367963dc6fbe7667a00d2b6cf6\", \"best_bid\":\"0.34\", \"best_ask\":\"0.35\"}, {\"asset_id\":\"14766054693214075530629349735273995982307625376442606753688071083149620216746\", \"price\":\"0.71\", \"size\":\"64\", \"side\":\"SELL\", \"hash\":\"659e742ff1dc68a3402006418825966177d3117d\", \"best_bid\":\"0.65\", \"best_ask\":\"0.66\"}], \"timestamp\":\"1785130851384\", \"event_type\":\"price_change\"}","received_at":"2026-07-27T05:40:57.045452Z","schema_version":"clob-market-ws.price_change.v1","sequence":null,"server_hash":null,"server_timestamp":"1785130851384","session_id":"502006c5cfcd437296561ea750c9ec8b","source":"clob_market_ws"},"received_at":"2026-07-27T05:40:57.045452Z","record_id":"07efb8f638568be9d5617d57eeaa163596361c21675a58b03c89f6ed345f7386","schema_fingerprint":"4aa3821a28b0b7c2400bc59aba4bcc0a76e971dadd19610d3ad38c768e124dc7","schema_version":"edge-lab-recorder.raw.v1","sequence":null,"source":"clob_market_ws"}
{"event_at":"2026-07-27T05:40:51.394000Z","event_fingerprint":"d4107a4c5733622de978193add772ebdaa13a855733ff72bef728ceef7f1f8a4","payload":{"connection_id":"efc69d3132f1467b8e898a382b23ac0d","event_at":"2026-07-27T05:40:51.394000Z","event_type":"price_change","frame_hash":"c8ed1e846000224f75ab441c89393707f8eaa5aef397707515e3bd84cbe01a12","frame_index":0,"kind":"data","monotonic_ns":232840281469250,"payload":{"event_type":"price_change","market":"0x3b40066b5cf3871a2f6237c5628bd8092a206aa998558ac5ec13c4483e31e160","price_changes":[{"asset_id":"110216635572655435074987471276357323571387854733835379371586402147734167783946","best_ask":"0.35","best_bid":"0.34","hash":"60c87f3416022235fe76383305e828f1f7510911","price":"0.18","side":"BUY","size":"71"},{"asset_id":"14766054693214075530629349735273995982307625376442606753688071083149620216746","best_ask":"0.66","best_bid":"0.65","hash":"648029f9e6d6b9e56fd32a8790ab7b705c2b52d8","price":"0.82","side":"SELL","size":"71"}],"timestamp":"1785130851394"},"payload_hash":"11fe1842cccbb6f92d23f43bf21fba5effcd43f6228cd3a01442ca10dec31788","raw_frame":"{\"market\":\"0x3b40066b5cf3871a2f6237c5628bd8092a206aa998558ac5ec13c4483e31e160\", \"price_changes\":[{\"asset_id\":\"110216635572655435074987471276357323571387854733835379371586402147734167783946\", \"price\":\"0.18\", \"size\":\"71\", \"side\":\"BUY\", \"hash\":\"60c87f3416022235fe76383305e828f1f7510911\", \"best_bid\":\"0.34\", \"best_ask\":\"0.35\"}, {\"asset_id\":\"14766054693214075530629349735273995982307625376442606753688071083149620216746\", \"price\":\"0.82\", \"size\":\"71\", \"side\":\"SELL\", \"hash\":\"648029f9e6d6b9e56fd32a8790ab7b705c2b52d8\", \"best_bid\":\"0.65\", \"best_ask\":\"0.66\"}], \"timestamp\":\"1785130851394\", \"event_type\":\"price_change\"}","received_at":"2026-07-27T05:40:57.047831Z","schema_version":"clob-market-ws.price_change.v1","sequence":null,"server_hash":null,"server_timestamp":"1785130851394","session_id":"502006c5cfcd437296561ea750c9ec8b","source":"clob_market_ws"},"received_at":"2026-07-27T05:40:57.047831Z","record_id":"9e3ec3199956686ddaeac1612dc8f0236e71c616be10c874c65ea33410bffa25","schema_fingerprint":"4aa3821a28b0b7c2400bc59aba4bcc0a76e971dadd19610d3ad38c768e124dc7","schema_version":"edge-lab-recorder.raw.v1","sequence":null,"source":"clob_market_ws"}
{"event_at":"2026-07-27T05:40:51.394000Z","event_fingerprint":"b7257722a55fcb69d18df59785ec64232bbe0f1d01bbfdca545964bb4bac4a4f","payload":{"connection_id":"efc69d3132f1467b8e898a382b23ac0d","event_at":"2026-07-27T05:40:51.394000Z","event_type":"price_change","frame_hash":"da88ee58a0707a8972324a8b8ec1707e6fb7abe91bd59f0809e18262668d66b9","frame_index":0,"kind":"data","monotonic_ns":232840283313333,"payload":{"event_type":"price_change","market":"0x3b40066b5cf3871a2f6237c5628bd8092a206aa998558ac5ec13c4483e31e160","price_changes":[{"asset_id":"110216635572655435074987471276357323571387854733835379371586402147734167783946","best_ask":"0.35","best_bid":"0.34","hash":"60c87f3416022235fe76383305e828f1f7510911","price":"0.19","side":"BUY","size":"89"},{"asset_id":"14766054693214075530629349735273995982307625376442606753688071083149620216746","best_ask":"0.66","best_bid":"0.65","hash":"648029f9e6d6b9e56fd32a8790ab7b705c2b52d8","price":"0.81","side":"SELL","size":"89"}],"timestamp":"1785130851394"},"payload_hash":"b4b43d0ee02e6d345ab5664696374aef9f23bc0cf4674b62886620eb731b2ab2","raw_frame":"{\"market\":\"0x3b40066b5cf3871a2f6237c5628bd8092a206aa998558ac5ec13c4483e31e160\", \"price_changes\":[{\"asset_id\":\"110216635572655435074987471276357323571387854733835379371586402147734167783946\", \"price\":\"0.19\", \"size\":\"89\", \"side\":\"BUY\", \"hash\":\"60c87f3416022235fe76383305e828f1f7510911\", \"best_bid\":\"0.34\", \"best_ask\":\"0.35\"}, {\"asset_id\":\"14766054693214075530629349735273995982307625376442606753688071083149620216746\", \"price\":\"0.81\", \"size\":\"89\", \"side\":\"SELL\", \"hash\":\"648029f9e6d6b9e56fd32a8790ab7b705c2b52d8\", \"best_bid\":\"0.65\", \"best_ask\":\"0.66\"}], \"timestamp\":\"1785130851394\", \"event_type\":\"price_change\"}","received_at":"2026-07-27T05:40:57.049669Z","schema_version":"clob-market-ws.price_change.v1","sequence":null,"server_hash":null,"server_timestamp":"1785130851394","session_id":"502006c5cfcd437296561ea750c9ec8b","source":"clob_market_ws"},"received_at":"2026-07-27T05:40:57.049669Z","record_id":"f41cdfa0010c4781cc0eb05c6373a81cf809757aeb3cc22fca64021618733d0b","schema_fingerprint":"4aa3821a28b0b7c2400bc59aba4bcc0a76e971dadd19610d3ad38c768e124dc7","schema_version":"edge-lab-recorder.raw.v1","sequence":null,"source":"clob_market_ws"}
{"event_at":"2026-07-27T05:40:51.396000Z","event_fingerprint":"92a94cc505f0fda42836e7b947d88de3f1edae62f5adb0b34054a8dce62e83a4","payload":{"connection_id":"efc69d3132f1467b8e898a382b23ac0d","event_at":"2026-07-27T05:40:51.396000Z","event_type":"price_change","frame_hash":"bf822078c62d92af940f6324411bf5560be4c13fd5984b35ab6ea62e2b553fa0","frame_index":0,"kind":"data","monotonic_ns":232840286280708,"payload":{"event_type":"price_change","market":"0x3b40066b5cf3871a2f6237c5628bd8092a206aa998558ac5ec13c4483e31e160","price_changes":[{"asset_id":"14766054693214075530629349735273995982307625376442606753688071083149620216746","best_ask":"0.66","best_bid":"0.65","hash":"c400713748011fe1a522c940aee76de5497c128a","price":"0.61","side":"BUY","size":"42.6"},{"asset_id":"110216635572655435074987471276357323571387854733835379371586402147734167783946","best_ask":"0.35","best_bid":"0.34","hash":"784721cae8e3abd9aa5ac08a45d4203d6bdc673e","price":"0.39","side":"SELL","size":"42.6"}],"timestamp":"1785130851396"},"payload_hash":"29da2f863806d9613ab9bbf54cf41965a8fae892904eaf76a4cf4c7dc8a75e8b","raw_frame":"{\"market\":\"0x3b40066b5cf3871a2f6237c5628bd8092a206aa998558ac5ec13c4483e31e160\", \"price_changes\":[{\"asset_id\":\"14766054693214075530629349735273995982307625376442606753688071083149620216746\", \"price\":\"0.61\", \"size\":\"42.6\", \"side\":\"BUY\", \"hash\":\"c400713748011fe1a522c940aee76de5497c128a\", \"best_bid\":\"0.65\", \"best_ask\":\"0.66\"}, {\"asset_id\":\"110216635572655435074987471276357323571387854733835379371586402147734167783946\", \"price\":\"0.39\", \"size\":\"42.6\", \"side\":\"SELL\", \"hash\":\"784721cae8e3abd9aa5ac08a45d4203d6bdc673e\", \"best_bid\":\"0.34\", \"best_ask\":\"0.35\"}], \"timestamp\":\"1785130851396\", \"event_type\":\"price_change\"}","received_at":"2026-07-27T05:40:57.052636Z","schema_version":"clob-market-ws.price_change.v1","sequence":null,"server_hash":null,"server_timestamp":"1785130851396","session_id":"502006c5cfcd437296561ea750c9ec8b","source":"clob_market_ws"},"received_at":"2026-07-27T05:40:57.052636Z","record_id":"85767fb522a65704c940dbc39184700f21cf64dd92b5dbc069fd936d45c3d4bb","schema_fingerprint":"4aa3821a28b0b7c2400bc59aba4bcc0a76e971dadd19610d3ad38c768e124dc7","schema_version":"edge-lab-recorder.raw.v1","sequence":null,"source":"clob_market_ws"}
{"event_at":"2026-07-27T05:40:51.398000Z","event_fingerprint":"0dd25c1d3975d2b6529318c153995a4878ede9f6b240bcddb8af59a0050bb17c","payload":{"connection_id":"efc69d3132f1467b8e898a382b23ac0d","event_at":"2026-07-27T05:40:51.398000Z","event_type":"price_change","frame_hash":"b8d4b8b6eec579a1aac1c8c009db5f828bc07e346f851ad24bb08e99e011f76e","frame_index":0,"kind":"data","monotonic_ns":232840289262625,"payload":{"event_type":"price_change","market":"0x3b40066b5cf3871a2f6237c5628bd8092a206aa998558ac5ec13c4483e31e160","price_changes":[{"asset_id":"14766054693214075530629349735273995982307625376442606753688071083149620216746","best_ask":"0.66","best_bid":"0.65","hash":"3d2ae36b92504af21206db732b75329d45411b8d","price":"0.04","side":"BUY","size":"646.09"},{"asset_id":"110216635572655435074987471276357323571387854733835379371586402147734167783946","best_ask":"0.35","best_bid":"0.34","hash":"28ccf38bcc20a22ea9b78c609bd4e0613747f011","price":"0.96","side":"SELL","size":"646.09"}],"timestamp":"1785130851398"},"payload_hash":"7dfda05937a72a6e7c2f333fe8c461f9458f1f385fba58f35c07fda8b3343825","raw_frame":"{\"market\":\"0x3b40066b5cf3871a2f6237c5628bd8092a206aa998558ac5ec13c4483e31e160\", \"price_changes\":[{\"asset_id\":\"14766054693214075530629349735273995982307625376442606753688071083149620216746\", \"price\":\"0.04\", \"size\":\"646.09\", \"side\":\"BUY\", \"hash\":\"3d2ae36b92504af21206db732b75329d45411b8d\", \"best_bid\":\"0.65\", \"best_ask\":\"0.66\"}, {\"asset_id\":\"110216635572655435074987471276357323571387854733835379371586402147734167783946\", \"price\":\"0.96\", \"size\":\"646.09\", \"side\":\"SELL\", \"hash\":\"28ccf38bcc20a22ea9b78c609bd4e0613747f011\", \"best_bid\":\"0.34\", \"best_ask\":\"0.35\"}], \"timestamp\":\"1785130851398\", \"event_type\":\"price_change\"}","received_at":"2026-07-27T05:40:57.055619Z","schema_version":"clob-market-ws.price_change.v1","sequence":null,"server_hash":null,"server_timestamp":"1785130851398","session_id":"502006c5cfcd437296561ea750c9ec8b","source":"clob_market_ws"},"received_at":"2026-07-27T05:40:57.055619Z","record_id":"cdae7a3f345f60f8f1ff700b69da902585f61aa38fa9d7a2e2d83e69654a9405","schema_fingerprint":"4aa3821a28b0b7c2400bc59aba4bcc0a76e971dadd19610d3ad38c768e124dc7","schema_version":"edge-lab-recorder.raw.v1","sequence":null,"source":"clob_market_ws"}
{"event_at":"2026-07-27T05:40:51.403000Z","event_fingerprint":"a24edcca595e9d44af01d14112e5c9b943911b113e69e0bc96c17b3536c650b1","payload":{"connection_id":"efc69d3132f1467b8e898a382b23ac0d","event_at":"2026-07-27T05:40:51.403000Z","event_type":"price_change","frame_hash":"cc0be97d7b43492aff794c6742eb401636b150cf435e9d06ef31bf018b7f6086","frame_index":0,"kind":"data","monotonic_ns":232840292159833,"payload":{"event_type":"price_change","market":"0x3b40066b5cf3871a2f6237c5628bd8092a206aa998558ac5ec13c4483e31e160","price_changes":[{"asset_id":"110216635572655435074987471276357323571387854733835379371586402147734167783946","best_ask":"0.35","best_bid":"0.34","hash":"8dfa633d9a656cfa926495e45941854ab5590086","price":"0.27","side":"BUY","size":"103"},{"asset_id":"14766054693214075530629349735273995982307625376442606753688071083149620216746","best_ask":"0.66","best_bid":"0.65","hash":"9a7aba5a79d3b11f09f974aa7b7f1ad417cf4999","price":"0.73","side":"SELL","size":"103"}],"timestamp":"1785130851403"},"payload_hash":"b5eb84f7df2b497194abbae54ade9a631b08650c5eafe755dec0e3bd936f380e","raw_frame":"{\"market\":\"0x3b40066b5cf3871a2f6237c5628bd8092a206aa998558ac5ec13c4483e31e160\", \"price_changes\":[{\"asset_id\":\"110216635572655435074987471276357323571387854733835379371586402147734167783946\", \"price\":\"0.27\", \"size\":\"103\", \"side\":\"BUY\", \"hash\":\"8dfa633d9a656cfa926495e45941854ab5590086\", \"best_bid\":\"0.34\", \"best_ask\":\"0.35\"}, {\"asset_id\":\"14766054693214075530629349735273995982307625376442606753688071083149620216746\", \"price\":\"0.73\", \"size\":\"103\", \"side\":\"SELL\", \"hash\":\"9a7aba5a79d3b11f09f974aa7b7f1ad417cf4999\", \"best_bid\":\"0.65\", \"best_ask\":\"0.66\"}], \"timestamp\":\"1785130851403\", \"event_type\":\"price_change\"}","received_at":"2026-07-27T05:40:57.058516Z","schema_version":"clob-market-ws.price_change.v1","sequence":null,"server_hash":null,"server_timestamp":"1785130851403","session_id":"502006c5cfcd437296561ea750c9ec8b","source":"clob_market_ws"},"received_at":"2026-07-27T05:40:57.058516Z","record_id":"33d3d4451c48f6d8f9e82d084f250c66b1d83e9f1da347ac6eaec363cd91ce23","schema_fingerprint":"4aa3821a28b0b7c2400bc59aba4bcc0a76e971dadd19610d3ad38c768e124dc7","schema_version":"edge-lab-recorder.raw.v1","sequence":null,"source":"clob_market_ws"}
{"event_at":"2026-07-27T05:40:51.404000Z","event_fingerprint":"61431bd38969dac831a2aa8df3e8d36774ee36a88f357f48c44afdc4995a8044","payload":{"connection_id":"efc69d3132f1467b8e898a382b23ac0d","event_at":"2026-07-27T05:40:51.404000Z","event_type":"price_change","frame_hash":"33e00740fe1c88e49bc3d548a755dd1ff3491a721c3d6434b330db4ba24923eb","frame_index":0,"kind":"data","monotonic_ns":232840294573541,"payload":{"event_type":"price_change","market":"0x3b40066b5cf3871a2f6237c5628bd8092a206aa998558ac5ec13c4483e31e160","price_changes":[{"asset_id":"14766054693214075530629349735273995982307625376442606753688071083149620216746","best_ask":"0.66","best_bid":"0.65","hash":"7cc5cd2ef174a3882550d695b2059997e9eb4765","price":"0.65","side":"BUY","size":"67"},{"asset_id":"110216635572655435074987471276357323571387854733835379371586402147734167783946","best_ask":"0.35","best_bid":"0.34","hash":"b8a42c24ef3ed6040c150d3032e2b807c71b7c3f","price":"0.35","side":"SELL","size":"67"}],"timestamp":"1785130851404"},"payload_hash":"96bd1798f5d3cd11fc9a4210e30ceac207143c5fc6c0c005d34e79531581b1e3","raw_frame":"{\"market\":\"0x3b40066b5cf3871a2f6237c5628bd8092a206aa998558ac5ec13c4483e31e160\", \"price_changes\":[{\"asset_id\":\"14766054693214075530629349735273995982307625376442606753688071083149620216746\", \"price\":\"0.65\", \"size\":\"67\", \"side\":\"BUY\", \"hash\":\"7cc5cd2ef174a3882550d695b2059997e9eb4765\", \"best_bid\":\"0.65\", \"best_ask\":\"0.66\"}, {\"asset_id\":\"110216635572655435074987471276357323571387854733835379371586402147734167783946\", \"price\":\"0.35\", \"size\":\"67\", \"side\":\"SELL\", \"hash\":\"b8a42c24ef3ed6040c150d3032e2b807c71b7c3f\", \"best_bid\":\"0.34\", \"best_ask\":\"0.35\"}], \"timestamp\":\"1785130851404\", \"event_type\":\"price_change\"}","received_at":"2026-07-27T05:40:57.060930Z","schema_version":"clob-market-ws.price_change.v1","sequence":null,"server_hash":null,"server_timestamp":"1785130851404","session_id":"502006c5cfcd437296561ea750c9ec8b","source":"clob_market_ws"},"received_at":"2026-07-27T05:40:57.060930Z","record_id":"dcaa6fa1852c22ee4aca650fe023433afcdca29eef1e91cfbb30a89705a57747","schema_fingerprint":"4aa3821a28b0b7c2400bc59aba4bcc0a76e971dadd19610d3ad38c768e124dc7","schema_version":"edge-lab-recorder.raw.v1","sequence":null,"source":"clob_market_ws"}
{"event_at":"2026-07-27T05:40:51.404000Z","event_fingerprint":"2150200af90e1a806144e80bcc661ed7bfa43dd7e7792c88828a7fc1f999ee85","payload":{"connection_id":"efc69d3132f1467b8e898a382b23ac0d","event_at":"2026-07-27T05:40:51.404000Z","event_type":"price_change","frame_hash":"cfefd54e2d6da8c9e3c5c8a89be5a8caa60ecba9e3599634c9a385dab5c93de0","frame_index":0,"kind":"data","monotonic_ns":232840297059041,"payload":{"event_type":"price_change","market":"0x3b40066b5cf3871a2f6237c5628bd8092a206aa998558ac5ec13c4483e31e160","price_changes":[{"asset_id":"110216635572655435074987471276357323571387854733835379371586402147734167783946","best_ask":"0.35","best_bid":"0.34","hash":"76fce3c3668a19dc0dfd41d7826bc50bd8057dc4","price":"0.29","side":"BUY","size":"44"},{"asset_id":"14766054693214075530629349735273995982307625376442606753688071083149620216746","best_ask":"0.66","best_bid":"0.65","hash":"6287c6cb0ed84aa3021301babe73eff58f93d597","price":"0.71","side":"SELL","size":"44"}],"timestamp":"1785130851404"},"payload_hash":"2886bede1fd3caf3317755199bf05ac4e34837683b8cf362b3c4a3ef29d8cfcb","raw_frame":"{\"market\":\"0x3b40066b5cf3871a2f6237c5628bd8092a206aa998558ac5ec13c4483e31e160\", \"price_changes\":[{\"asset_id\":\"110216635572655435074987471276357323571387854733835379371586402147734167783946\", \"price\":\"0.29\", \"size\":\"44\", \"side\":\"BUY\", \"hash\":\"76fce3c3668a19dc0dfd41d7826bc50bd8057dc4\", \"best_bid\":\"0.34\", \"best_ask\":\"0.35\"}, {\"asset_id\":\"14766054693214075530629349735273995982307625376442606753688071083149620216746\", \"price\":\"0.71\", \"size\":\"44\", \"side\":\"SELL\", \"hash\":\"6287c6cb0ed84aa3021301babe73eff58f93d597\", \"best_bid\":\"0.65\", \"best_ask\":\"0.66\"}], \"timestamp\":\"1785130851404\", \"event_type\":\"price_change\"}","received_at":"2026-07-27T05:40:57.063415Z","schema_version":"clob-market-ws.price_change.v1","sequence":null,"server_hash":null,"server_timestamp":"1785130851404","session_id":"502006c5cfcd437296561ea750c9ec8b","source":"clob_market_ws"},"received_at":"2026-07-27T05:40:57.063415Z","record_id":"9aa475f53e01442326831393af13fe9ec38994bdd9fa79cf94071e66a650373e","schema_fingerprint":"4aa3821a28b0b7c2400bc59aba4bcc0a76e971dadd19610d3ad38c768e124dc7","schema_version":"edge-lab-recorder.raw.v1","sequence":null,"source":"clob_market_ws"}
{"event_at":"2026-07-27T05:40:51.406000Z","event_fingerprint":"c17d87335f1d8235e83f0c5b4b8e0b7b0814ba53d202f2b62c619f97deab84bf","payload":{"connection_id":"efc69d3132f1467b8e898a382b23ac0d","event_at":"2026-07-27T05:40:51.406000Z","event_type":"price_change","frame_hash":"d091880bb90021d54b926417ddf9b5845b07f34cfa3b9723c9265ba5bc80d8a4","frame_index":0,"kind":"data","monotonic_ns":232840298698833,"payload":{"event_type":"price_change","market":"0x3b40066b5cf3871a2f6237c5628bd8092a206aa998558ac5ec13c4483e31e160","price_changes":[{"asset_id":"110216635572655435074987471276357323571387854733835379371586402147734167783946","best_ask":"0.35","best_bid":"0.34","hash":"ec70ad5b42805c4a3548ca26545475505a416fbb","price":"0.03","side":"BUY","size":"676.1"},{"asset_id":"14766054693214075530629349735273995982307625376442606753688071083149620216746","best_ask":"0.66","best_bid":"0.65","hash":"701278a500128ee05de35e8fa94c9170c428b20e","price":"0.97","side":"SELL","size":"676.1"}],"timestamp":"1785130851406"},"payload_hash":"50309e943feeeeffda0d2cf0d90085d18dc36dfcbc54636445ede732e679cba6","raw_frame":"{\"market\":\"0x3b40066b5cf3871a2f6237c5628bd8092a206aa998558ac5ec13c4483e31e160\", \"price_changes\":[{\"asset_id\":\"110216635572655435074987471276357323571387854733835379371586402147734167783946\", \"price\":\"0.03\", \"size\":\"676.1\", \"side\":\"BUY\", \"hash\":\"ec70ad5b42805c4a3548ca26545475505a416fbb\", \"best_bid\":\"0.34\", \"best_ask\":\"0.35\"}, {\"asset_id\":\"14766054693214075530629349735273995982307625376442606753688071083149620216746\", \"price\":\"0.97\", \"size\":\"676.1\", \"side\":\"SELL\", \"hash\":\"701278a500128ee05de35e8fa94c9170c428b20e\", \"best_bid\":\"0.65\", \"best_ask\":\"0.66\"}], \"timestamp\":\"1785130851406\", \"event_type\":\"price_change\"}","received_at":"2026-07-27T05:40:57.065061Z","schema_version":"clob-market-ws.price_change.v1","sequence":null,"server_hash":null,"server_timestamp":"1785130851406","session_id":"502006c5cfcd437296561ea750c9ec8b","source":"clob_market_ws"},"received_at":"2026-07-27T05:40:57.065061Z","record_id":"d30e4e47a55f05a06eac57d3e30909334f43e1c816cae730581f32a6a30a40cb","schema_fingerprint":"4aa3821a28b0b7c2400bc59aba4bcc0a76e971dadd19610d3ad38c768e124dc7","schema_version":"edge-lab-recorder.raw.v1","sequence":null,"source":"clob_market_ws"}
{"event_at":"2026-07-27T05:40:51.406000Z","event_fingerprint":"a0f18e0cc22e83b5ded4c001d24a8c79dc5c92b86ea6bb44cb5e38f3bcf91c46","payload":{"connection_id":"efc69d3132f1467b8e898a382b23ac0d","event_at":"2026-07-27T05:40:51.406000Z","event_type":"price_change","frame_hash":"e0da2b97538f6429c75adb8cb6399349dc815ea6dbe49f568fcf97df43015d0d","frame_index":0,"kind":"data","monotonic_ns":232840301253875,"payload":{"event_type":"price_change","market":"0x3b40066b5cf3871a2f6237c5628bd8092a206aa998558ac5ec13c4483e31e160","price_changes":[{"asset_id":"14766054693214075530629349735273995982307625376442606753688071083149620216746","best_ask":"0.66","best_bid":"0.65","hash":"701278a500128ee05de35e8fa94c9170c428b20e","price":"0.05","side":"BUY","size":"767.2"},{"asset_id":"110216635572655435074987471276357323571387854733835379371586402147734167783946","best_ask":"0.35","best_bid":"0.34","hash":"ec70ad5b42805c4a3548ca26545475505a416fbb","price":"0.95","side":"SELL","size":"767.2"}],"timestamp":"1785130851406"},"payload_hash":"95c765caf09582af28206be811dacebd6dc72abb1d228bec85d43bb9a926524f","raw_frame":"{\"market\":\"0x3b40066b5cf3871a2f6237c5628bd8092a206aa998558ac5ec13c4483e31e160\", \"price_changes\":[{\"asset_id\":\"14766054693214075530629349735273995982307625376442606753688071083149620216746\", \"price\":\"0.05\", \"size\":\"767.2\", \"side\":\"BUY\", \"hash\":\"701278a500128ee05de35e8fa94c9170c428b20e\", \"best_bid\":\"0.65\", \"best_ask\":\"0.66\"}, {\"asset_id\":\"110216635572655435074987471276357323571387854733835379371586402147734167783946\", \"price\":\"0.95\", \"size\":\"767.2\", \"side\":\"SELL\", \"hash\":\"ec70ad5b42805c4a3548ca26545475505a416fbb\", \"best_bid\":\"0.34\", \"best_ask\":\"0.35\"}], \"timestamp\":\"1785130851406\", \"event_type\":\"price_change\"}","received_at":"2026-07-27T05:40:57.067609Z","schema_version":"clob-market-ws.price_change.v1","sequence":null,"server_hash":null,"server_timestamp":"1785130851406","session_id":"502006c5cfcd437296561ea750c9ec8b","source":"clob_market_ws"},"received_at":"2026-07-27T05:40:57.067609Z","record_id":"609b2a9e9525b9b9101b92aa1f37d9373379cd3795e6bc639b1767f345878c0f","schema_fingerprint":"4aa3821a28b0b7c2400bc59aba4bcc0a76e971dadd19610d3ad38c768e124dc7","schema_version":"edge-lab-recorder.raw.v1","sequence":null,"source":"clob_market_ws"}
{"event_at":"2026-07-27T05:40:51.406000Z","event_fingerprint":"98f26dfa52793ec76493ba1654c31c4ef38986bc363f7b6ef4d86deecef5185e","payload":{"connection_id":"efc69d3132f1467b8e898a382b23ac0d","event_at":"2026-07-27T05:40:51.406000Z","event_type":"price_change","frame_hash":"af7b02b6d09a32159404ac0df436e85fc6aa3ef820d4a15b408676c24bb0667f","frame_index":0,"kind":"data","monotonic_ns":232840304207875,"payload":{"event_type":"price_change","market":"0x3b40066b5cf3871a2f6237c5628bd8092a206aa998558ac5ec13c4483e31e160","price_changes":[{"asset_id":"14766054693214075530629349735273995982307625376442606753688071083149620216746","best_ask":"0.66","best_bid":"0.65","hash":"e839fcfd961c2f0dcd6083ed781b3cdbc31eb586","price":"0.65","side":"BUY","size":"79"},{"asset_id":"110216635572655435074987471276357323571387854733835379371586402147734167783946","best_ask":"0.35","best_bid":"0.34","hash":"a39ba6693b67a188c8da2c58385fba6136b7b40f","price":"0.35","side":"SELL","size":"79"}],"timestamp":"1785130851406"},"payload_hash":"f1fab6c3a70926e7f523d7251d6e5654451a7a90cb4ddc0a147b19b89c25261a","raw_frame":"{\"market\":\"0x3b40066b5cf3871a2f6237c5628bd8092a206aa998558ac5ec13c4483e31e160\", \"price_changes\":[{\"asset_id\":\"14766054693214075530629349735273995982307625376442606753688071083149620216746\", \"price\":\"0.65\", \"size\":\"79\", \"side\":\"BUY\", \"hash\":\"e839fcfd961c2f0dcd6083ed781b3cdbc31eb586\", \"best_bid\":\"0.65\", \"best_ask\":\"0.66\"}, {\"asset_id\":\"110216635572655435074987471276357323571387854733835379371586402147734167783946\", \"price\":\"0.35\", \"size\":\"79\", \"side\":\"SELL\", \"hash\":\"a39ba6693b67a188c8da2c58385fba6136b7b40f\", \"best_bid\":\"0.34\", \"best_ask\":\"0.35\"}], \"timestamp\":\"1785130851406\", \"event_type\":\"price_change\"}","received_at":"2026-07-27T05:40:57.070564Z","schema_version":"clob-market-ws.price_change.v1","sequence":null,"server_hash":null,"server_timestamp":"1785130851406","session_id":"502006c5cfcd437296561ea750c9ec8b","source":"clob_market_ws"},"received_at":"2026-07-27T05:40:57.070564Z","record_id":"d7a8d7ee74a46a17d42c77667daceb6201b4f97167765d38addc514020abd8f4","schema_fingerprint":"4aa3821a28b0b7c2400bc59aba4bcc0a76e971dadd19610d3ad38c768e124dc7","schema_version":"edge-lab-recorder.raw.v1","sequence":null,"source":"clob_market_ws"}
{"event_at":"2026-07-27T05:40:51.413000Z","event_fingerprint":"0c11a18ee88e7e23be8dbaa1804151c281a0871d60316449d65cfdf0feeaaf84","payload":{"connection_id":"efc69d3132f1467b8e898a382b23ac0d","event_at":"2026-07-27T05:40:51.413000Z","event_type":"price_change","frame_hash":"21337915f7d5e980d5236c1a56a6de4a0effc21aee1511ae8231216cc4526126","frame_index":0,"kind":"data","monotonic_ns":232840307241833,"payload":{"event_type":"price_change","market":"0x3b40066b5cf3871a2f6237c5628bd8092a206aa998558ac5ec13c4483e31e160","price_changes":[{"asset_id":"14766054693214075530629349735273995982307625376442606753688071083149620216746","best_ask":"0.66","best_bid":"0.65","hash":"596841ed04bb3d7dd7b9431842825bb0eb1239b2","price":"0.41","side":"BUY","size":"50.77"},{"asset_id":"110216635572655435074987471276357323571387854733835379371586402147734167783946","best_ask":"0.35","best_bid":"0.34","hash":"f3e7036029fdd3252a805d7dad1eec7a6d84fadb","price":"0.59","side":"SELL","size":"50.77"}],"timestamp":"1785130851413"},"payload_hash":"37db3fcd39d4edf8756af9175f351d04fb5ac0eab868295319188d8940f655f7","raw_frame":"{\"market\":\"0x3b40066b5cf3871a2f6237c5628bd8092a206aa998558ac5ec13c4483e31e160\", \"price_changes\":[{\"asset_id\":\"14766054693214075530629349735273995982307625376442606753688071083149620216746\", \"price\":\"0.41\", \"size\":\"50.77\", \"side\":\"BUY\", \"hash\":\"596841ed04bb3d7dd7b9431842825bb0eb1239b2\", \"best_bid\":\"0.65\", \"best_ask\":\"0.66\"}, {\"asset_id\":\"110216635572655435074987471276357323571387854733835379371586402147734167783946\", \"price\":\"0.59\", \"size\":\"50.77\", \"side\":\"SELL\", \"hash\":\"f3e7036029fdd3252a805d7dad1eec7a6d84fadb\", \"best_bid\":\"0.34\", \"best_ask\":\"0.35\"}], \"timestamp\":\"1785130851413\", \"event_type\":\"price_change\"}","received_at":"2026-07-27T05:40:57.073594Z","schema_version":"clob-market-ws.price_change.v1","sequence":null,"server_hash":null,"server_timestamp":"1785130851413","session_id":"502006c5cfcd437296561ea750c9ec8b","source":"clob_market_ws"},"received_at":"2026-07-27T05:40:57.073594Z","record_id":"24c1e5145c7ebbecad39c0291f82c9ed31ac92fb7f60f6d2acfaf9e74d5d9a0f","schema_fingerprint":"4aa3821a28b0b7c2400bc59aba4bcc0a76e971dadd19610d3ad38c768e124dc7","schema_version":"edge-lab-recorder.raw.v1","sequence":null,"source":"clob_market_ws"}
{"event_at":"2026-07-27T05:40:51.420000Z","event_fingerprint":"8c35169ddf22019221b5808a1c2abcca20bb306efb0f424d29a6a98269e76a13","payload":{"connection_id":"efc69d3132f1467b8e898a382b23ac0d","event_at":"2026-07-27T05:40:51.420000Z","event_type":"price_change","frame_hash":"93bd853767cf92009ca0a33ca5854d2e728cb0f3e5bc8f430f4eaadd1fd4f901","frame_index":0,"kind":"data","monotonic_ns":232840310275708,"payload":{"event_type":"price_change","market":"0x3b40066b5cf3871a2f6237c5628bd8092a206aa998558ac5ec13c4483e31e160","price_changes":[{"asset_id":"14766054693214075530629349735273995982307625376442606753688071083149620216746","best_ask":"0.66","best_bid":"0.65","hash":"3a6f3443632b9fef5fdb9f779b21523eb61b01db","price":"0.45","side":"BUY","size":"124.17"},{"asset_id":"110216635572655435074987471276357323571387854733835379371586402147734167783946","best_ask":"0.35","best_bid":"0.34","hash":"829c984da32697d2f95a52c98365803dbbc013ce","price":"0.55","side":"SELL","size":"124.17"}],"timestamp":"1785130851420"},"payload_hash":"717f1d1b9446f4b0a91a8456dc067029fd583f4dca92315b7d80e25894f787ed","raw_frame":"{\"market\":\"0x3b40066b5cf3871a2f6237c5628bd8092a206aa998558ac5ec13c4483e31e160\", \"price_changes\":[{\"asset_id\":\"14766054693214075530629349735273995982307625376442606753688071083149620216746\", \"price\":\"0.45\", \"size\":\"124.17\", \"side\":\"BUY\", \"hash\":\"3a6f3443632b9fef5fdb9f779b21523eb61b01db\", \"best_bid\":\"0.65\", \"best_ask\":\"0.66\"}, {\"asset_id\":\"110216635572655435074987471276357323571387854733835379371586402147734167783946\", \"price\":\"0.55\", \"size\":\"124.17\", \"side\":\"SELL\", \"hash\":\"829c984da32697d2f95a52c98365803dbbc013ce\", \"best_bid\":\"0.34\", \"best_ask\":\"0.35\"}], \"timestamp\":\"1785130851420\", \"event_type\":\"price_change\"}","received_at":"2026-07-27T05:40:57.076632Z","schema_version":"clob-market-ws.price_change.v1","sequence":null,"server_hash":null,"server_timestamp":"1785130851420","session_id":"502006c5cfcd437296561ea750c9ec8b","source":"clob_market_ws"},"received_at":"2026-07-27T05:40:57.076632Z","record_id":"7b949601fc0db165964e9b61446206db1c903729d2b6be9dfe0380acb554d9b6","schema_fingerprint":"4aa3821a28b0b7c2400bc59aba4bcc0a76e971dadd19610d3ad38c768e124dc7","schema_version":"edge-lab-recorder.raw.v1","sequence":null,"source":"clob_market_ws"}
{"event_at":"2026-07-27T05:40:51.421000Z","event_fingerprint":"0e218ca7775ae3f5fada0c664636fd27b194224d7f1deeb9696727f09e20d55a","payload":{"connection_id":"efc69d3132f1467b8e898a382b23ac0d","event_at":"2026-07-27T05:40:51.421000Z","event_type":"price_change","frame_hash":"e3693736b8237e1500bf699908ea87f42c837dad18ad90b085f686ee339f5415","frame_index":0,"kind":"data","monotonic_ns":232840313206166,"payload":{"event_type":"price_change","market":"0x3b40066b5cf3871a2f6237c5628bd8092a206aa998558ac5ec13c4483e31e160","price_changes":[{"asset_id":"110216635572655435074987471276357323571387854733835379371586402147734167783946","best_ask":"0.35","best_bid":"0.34","hash":"f311744ed7eca349c6405edace22a68201d4487a","price":"0.12","side":"BUY","size":"298.4"},{"asset_id":"14766054693214075530629349735273995982307625376442606753688071083149620216746","best_ask":"0.66","best_bid":"0.65","hash":"7dea9dba5db64681c20c75587392ea8ba48707c9","price":"0.88","side":"SELL","size":"298.4"}],"timestamp":"1785130851421"},"payload_hash":"9fc6352d3868cbccc50d2533d6c68e6255220dab9796338d31c801fdf34748b3","raw_frame":"{\"market\":\"0x3b40066b5cf3871a2f6237c5628bd8092a206aa998558ac5ec13c4483e31e160\", \"price_changes\":[{\"asset_id\":\"110216635572655435074987471276357323571387854733835379371586402147734167783946\", \"price\":\"0.12\", \"size\":\"298.4\", \"side\":\"BUY\", \"hash\":\"f311744ed7eca349c6405edace22a68201d4487a\", \"best_bid\":\"0.34\", \"best_ask\":\"0.35\"}, {\"asset_id\":\"14766054693214075530629349735273995982307625376442606753688071083149620216746\", \"price\":\"0.88\", \"size\":\"298.4\", \"side\":\"SELL\", \"hash\":\"7dea9dba5db64681c20c75587392ea8ba48707c9\", \"best_bid\":\"0.65\", \"best_ask\":\"0.66\"}], \"timestamp\":\"1785130851421\", \"event_type\":\"price_change\"}","received_at":"2026-07-27T05:40:57.079563Z","schema_version":"clob-market-ws.price_change.v1","sequence":null,"server_hash":null,"server_timestamp":"1785130851421","session_id":"502006c5cfcd437296561ea750c9ec8b","source":"clob_market_ws"},"received_at":"2026-07-27T05:40:57.079563Z","record_id":"aa8dc0d8ee63f63f7ff4eb8ba16a8cee5f6e91b878ede01d4286001badffdaf0","schema_fingerprint":"4aa3821a28b0b7c2400bc59aba4bcc0a76e971dadd19610d3ad38c768e124dc7","schema_version":"edge-lab-recorder.raw.v1","sequence":null,"source":"clob_market_ws"}
{"event_at":"2026-07-27T05:40:51.422000Z","event_fingerprint":"f1daab4d7034e6204da5bff9291d3c75ec18a304e5736464ecb93add420d21db","payload":{"connection_id":"efc69d3132f1467b8e898a382b23ac0d","event_at":"2026-07-27T05:40:51.422000Z","event_type":"price_change","frame_hash":"34b48e82d76546a5d342b5fe23ee2eb213bd049fffb4e2fbb71ef3222f9a25aa","frame_index":0,"kind":"data","monotonic_ns":232840315188250,"payload":{"event_type":"price_change","market":"0x3b40066b5cf3871a2f6237c5628bd8092a206aa998558ac5ec13c4483e31e160","price_changes":[{"asset_id":"14766054693214075530629349735273995982307625376442606753688071083149620216746","best_ask":"0.66","best_bid":"0.65","hash":"b6a2dbc4e4ed94aec1168f4a01288b1794aef1a7","price":"0.62","side":"BUY","size":"52.6"},{"asset_id":"110216635572655435074987471276357323571387854733835379371586402147734167783946","best_ask":"0.35","best_bid":"0.34","hash":"d5cff2544d601927a93349caced10e415230554f","price":"0.38","side":"SELL","size":"52.6"}],"timestamp":"1785130851422"},"payload_hash":"bd40399940d4187bcb0ee21ad7fbc3e1fe71673ee018444d96603b4601e487b9","raw_frame":"{\"market\":\"0x3b40066b5cf3871a2f6237c5628bd8092a206aa998558ac5ec13c4483e31e160\", \"price_changes\":[{\"asset_id\":\"14766054693214075530629349735273995982307625376442606753688071083149620216746\", \"price\":\"0.62\", \"size\":\"52.6\", \"side\":\"BUY\", \"hash\":\"b6a2dbc4e4ed94aec1168f4a01288b1794aef1a7\", \"best_bid\":\"0.65\", \"best_ask\":\"0.66\"}, {\"asset_id\":\"110216635572655435074987471276357323571387854733835379371586402147734167783946\", \"price\":\"0.38\", \"size\":\"52.6\", \"side\":\"SELL\", \"hash\":\"d5cff2544d601927a93349caced10e415230554f\", \"best_bid\":\"0.34\", \"best_ask\":\"0.35\"}], \"timestamp\":\"1785130851422\", \"event_type\":\"price_change\"}","received_at":"2026-07-27T05:40:57.081550Z","schema_version":"clob-market-ws.price_change.v1","sequence":null,"server_hash":null,"server_timestamp":"1785130851422","session_id":"502006c5cfcd437296561ea750c9ec8b","source":"clob_market_ws"},"received_at":"2026-07-27T05:40:57.081550Z","record_id":"3d862e35307acf1e706ea60040a240a14dce8a51be5ee159309693f66966c81a","schema_fingerprint":"4aa3821a28b0b7c2400bc59aba4bcc0a76e971dadd19610d3ad38c768e124dc7","schema_version":"edge-lab-recorder.raw.v1","sequence":null,"source":"clob_market_ws"}
{"event_at":"2026-07-27T05:40:51.426000Z","event_fingerprint":"28a85623b5052cb05dc581c6cc748c47f9511b859855368bd4687b30a0f9c8ed","payload":{"connection_id":"efc69d3132f1467b8e898a382b23ac0d","event_at":"2026-07-27T05:40:51.426000Z","event_type":"price_change","frame_hash":"5542bb6a1cc2340e71aa6261d32e9f98c149110ab96a374a31a9f53f26e453cd","frame_index":0,"kind":"data","monotonic_ns":232840317487166,"payload":{"event_type":"price_change","market":"0x3b40066b5cf3871a2f6237c5628bd8092a206aa998558ac5ec13c4483e31e160","price_changes":[{"asset_id":"110216635572655435074987471276357323571387854733835379371586402147734167783946","best_ask":"0.35","best_bid":"0.34","hash":"a4020a93bced59ae34e54651aeb1e4aa9bef995f","price":"0.28","side":"BUY","size":"70.97"},{"asset_id":"14766054693214075530629349735273995982307625376442606753688071083149620216746","best_ask":"0.66","best_bid":"0.65","hash":"fcf21e2a19bd24a0fc261334a09aa2ba5b5f4aa7","price":"0.72","side":"SELL","size":"70.97"}],"timestamp":"1785130851426"},"payload_hash":"120f924f11668cff74ca18c0dd0d256b86b053480d0f99aa13546aebb17c3670","raw_frame":"{\"market\":\"0x3b40066b5cf3871a2f6237c5628bd8092a206aa998558ac5ec13c4483e31e160\", \"price_changes\":[{\"asset_id\":\"110216635572655435074987471276357323571387854733835379371586402147734167783946\", \"price\":\"0.28\", \"size\":\"70.97\", \"side\":\"BUY\", \"hash\":\"a4020a93bced59ae34e54651aeb1e4aa9bef995f\", \"best_bid\":\"0.34\", \"best_ask\":\"0.35\"}, {\"asset_id\":\"14766054693214075530629349735273995982307625376442606753688071083149620216746\", \"price\":\"0.72\", \"size\":\"70.97\", \"side\":\"SELL\", \"hash\":\"fcf21e2a19bd24a0fc261334a09aa2ba5b5f4aa7\", \"best_bid\":\"0.65\", \"best_ask\":\"0.66\"}], \"timestamp\":\"1785130851426\", \"event_type\":\"price_change\"}","received_at":"2026-07-27T05:40:57.083844Z","schema_version":"clob-market-ws.price_change.v1","sequence":null,"server_hash":null,"server_timestamp":"1785130851426","session_id":"502006c5cfcd437296561ea750c9ec8b","source":"clob_market_ws"},"received_at":"2026-07-27T05:40:57.083844Z","record_id":"830bc80e509a3ccc8fd1d4201be6363219464b2f586adebb5fb3930d598cb025","schema_fingerprint":"4aa3821a28b0b7c2400bc59aba4bcc0a76e971dadd19610d3ad38c768e124dc7","schema_version":"edge-lab-recorder.raw.v1","sequence":null,"source":"clob_market_ws"}
{"event_at":"2026-07-27T05:40:51.429000Z","event_fingerprint":"dcc15afb71bf189805a276f71315dfecc88f952e4f0dd041ae0901561f5b15b8","payload":{"connection_id":"efc69d3132f1467b8e898a382b23ac0d","event_at":"2026-07-27T05:40:51.429000Z","event_type":"price_change","frame_hash":"ddd0e018b69ebe9c68fea5efc31e073a56f5626d069a3db226c23ff8b0073382","frame_index":0,"kind":"data","monotonic_ns":232840319947916,"payload":{"event_type":"price_change","market":"0x3b40066b5cf3871a2f6237c5628bd8092a206aa998558ac5ec13c4483e31e160","price_changes":[{"asset_id":"14766054693214075530629349735273995982307625376442606753688071083149620216746","best_ask":"0.66","best_bid":"0.65","hash":"ea69c04554be91ffc26c30a9eea398382edb17f6","price":"0.9","side":"SELL","size":"146.29"},{"asset_id":"110216635572655435074987471276357323571387854733835379371586402147734167783946","best_ask":"0.35","best_bid":"0.34","hash":"1ad0a8838ae3113e5ebce3ec5210036bcfd76e46","price":"0.1","side":"BUY","size":"146.29"}],"timestamp":"1785130851429"},"payload_hash":"1d450c0a2311a23e1cc325b3596009caabc2118e03b573ae539271e8887fd9f1","raw_frame":"{\"market\":\"0x3b40066b5cf3871a2f6237c5628bd8092a206aa998558ac5ec13c4483e31e160\", \"price_changes\":[{\"asset_id\":\"14766054693214075530629349735273995982307625376442606753688071083149620216746\", \"price\":\"0.9\", \"size\":\"146.29\", \"side\":\"SELL\", \"hash\":\"ea69c04554be91ffc26c30a9eea398382edb17f6\", \"best_bid\":\"0.65\", \"best_ask\":\"0.66\"}, {\"asset_id\":\"110216635572655435074987471276357323571387854733835379371586402147734167783946\", \"price\":\"0.1\", \"size\":\"146.29\", \"side\":\"BUY\", \"hash\":\"1ad0a8838ae3113e5ebce3ec5210036bcfd76e46\", \"best_bid\":\"0.34\", \"best_ask\":\"0.35\"}], \"timestamp\":\"1785130851429\", \"event_type\":\"price_change\"}","received_at":"2026-07-27T05:40:57.086304Z","schema_version":"clob-market-ws.price_change.v1","sequence":null,"server_hash":null,"server_timestamp":"1785130851429","session_id":"502006c5cfcd437296561ea750c9ec8b","source":"clob_market_ws"},"received_at":"2026-07-27T05:40:57.086304Z","record_id":"cda874213ec277f9fc843b5f90584df32cf0ab8b9a1c6aa26b748d8aa728936c","schema_fingerprint":"4aa3821a28b0b7c2400bc59aba4bcc0a76e971dadd19610d3ad38c768e124dc7","schema_version":"edge-lab-recorder.raw.v1","sequence":null,"source":"clob_market_ws"}
{"event_at":"2026-07-27T05:40:51.432000Z","event_fingerprint":"717803ade2173e646ccecfbc347111c460d8a3debacb66631c7fc9afd8822d07","payload":{"connection_id":"efc69d3132f1467b8e898a382b23ac0d","event_at":"2026-07-27T05:40:51.432000Z","event_type":"price_change","frame_hash":"d8507235fa0a396afd9d3bf5365798176ded0bcb5dc9bc1157c68ab6c10d89cc","frame_index":0,"kind":"data","monotonic_ns":232840322425000,"payload":{"event_type":"price_change","market":"0x3b40066b5cf3871a2f6237c5628bd8092a206aa998558ac5ec13c4483e31e160","price_changes":[{"asset_id":"14766054693214075530629349735273995982307625376442606753688071083149620216746","best_ask":"0.66","best_bid":"0.65","hash":"cd80063a25bd6bb314d7510076dffaf8193f0303","price":"0.65","side":"BUY","size":"99"},{"asset_id":"110216635572655435074987471276357323571387854733835379371586402147734167783946","best_ask":"0.35","best_bid":"0.34","hash":"75f5303c199f31eff6d27a4ddaa44d3697f46bcd","price":"0.35","side":"SELL","size":"99"}],"timestamp":"1785130851432"},"payload_hash":"10bbd4f63f1e6a2a3f04badabe21de93ed9cb524435c65966d258a89fa55233a","raw_frame":"{\"market\":\"0x3b40066b5cf3871a2f6237c5628bd8092a206aa998558ac5ec13c4483e31e160\", \"price_changes\":[{\"asset_id\":\"14766054693214075530629349735273995982307625376442606753688071083149620216746\", \"price\":\"0.65\", \"size\":\"99\", \"side\":\"BUY\", \"hash\":\"cd80063a25bd6bb314d7510076dffaf8193f0303\", \"best_bid\":\"0.65\", \"best_ask\":\"0.66\"}, {\"asset_id\":\"110216635572655435074987471276357323571387854733835379371586402147734167783946\", \"price\":\"0.35\", \"size\":\"99\", \"side\":\"SELL\", \"hash\":\"75f5303c199f31eff6d27a4ddaa44d3697f46bcd\", \"best_bid\":\"0.34\", \"best_ask\":\"0.35\"}], \"timestamp\":\"1785130851432\", \"event_type\":\"price_change\"}","received_at":"2026-07-27T05:40:57.088781Z","schema_version":"clob-market-ws.price_change.v1","sequence":null,"server_hash":null,"server_timestamp":"1785130851432","session_id":"502006c5cfcd437296561ea750c9ec8b","source":"clob_market_ws"},"received_at":"2026-07-27T05:40:57.088781Z","record_id":"2f500de55f41a75acd74b922110322950c137eaca1001fced6cbc72732030bc6","schema_fingerprint":"4aa3821a28b0b7c2400bc59aba4bcc0a76e971dadd19610d3ad38c768e124dc7","schema_version":"edge-lab-recorder.raw.v1","sequence":null,"source":"clob_market_ws"}
{"event_at":"2026-07-27T05:40:51.433000Z","event_fingerprint":"908cd2fa7c604abc51eec892af6a45ed5b62f77f91951f8e16e5ffb55ca69e79","payload":{"connection_id":"efc69d3132f1467b8e898a382b23ac0d","event_at":"2026-07-27T05:40:51.433000Z","event_type":"price_change","frame_hash":"e3478a0c1ba17979b6ece06d808edf3f58944eb4032f710018bb2342bbace882","frame_index":0,"kind":"data","monotonic_ns":232840325316208,"payload":{"event_type":"price_change","market":"0x3b40066b5cf3871a2f6237c5628bd8092a206aa998558ac5ec13c4483e31e160","price_changes":[{"asset_id":"110216635572655435074987471276357323571387854733835379371586402147734167783946","best_ask":"0.35","best_bid":"0.34","hash":"d6f22ed6b9b08f6154761463ec91e9c766f0f53c","price":"0.31","side":"BUY","size":"17"},{"asset_id":"14766054693214075530629349735273995982307625376442606753688071083149620216746","best_ask":"0.66","best_bid":"0.65","hash":"9369a926b8c39df37dff80cd4d77aff0e4aa08b2","price":"0.69","side":"SELL","size":"17"}],"timestamp":"1785130851433"},"payload_hash":"8900951bba62878778b69e823215d20f3199b451b2f7b3bb1b5941c964ea8504","raw_frame":"{\"market\":\"0x3b40066b5cf3871a2f6237c5628bd8092a206aa998558ac5ec13c4483e31e160\", \"price_changes\":[{\"asset_id\":\"110216635572655435074987471276357323571387854733835379371586402147734167783946\", \"price\":\"0.31\", \"size\":\"17\", \"side\":\"BUY\", \"hash\":\"d6f22ed6b9b08f6154761463ec91e9c766f0f53c\", \"best_bid\":\"0.34\", \"best_ask\":\"0.35\"}, {\"asset_id\":\"14766054693214075530629349735273995982307625376442606753688071083149620216746\", \"price\":\"0.69\", \"size\":\"17\", \"side\":\"SELL\", \"hash\":\"9369a926b8c39df37dff80cd4d77aff0e4aa08b2\", \"best_bid\":\"0.65\", \"best_ask\":\"0.66\"}], \"timestamp\":\"1785130851433\", \"event_type\":\"price_change\"}","received_at":"2026-07-27T05:40:57.091673Z","schema_version":"clob-market-ws.price_change.v1","sequence":null,"server_hash":null,"server_timestamp":"1785130851433","session_id":"502006c5cfcd437296561ea750c9ec8b","source":"clob_market_ws"},"received_at":"2026-07-27T05:40:57.091673Z","record_id":"4e9606236b99f2fb63174b392b11d21802a1ee6522c8dbe8a4b2faf13bd001cc","schema_fingerprint":"4aa3821a28b0b7c2400bc59aba4bcc0a76e971dadd19610d3ad38c768e124dc7","schema_version":"edge-lab-recorder.raw.v1","sequence":null,"source":"clob_market_ws"}
{"event_at":"2026-07-27T05:40:51.434000Z","event_fingerprint":"99544f624137e6b4b3dc326ebb24cbdfe577cc3acb04a0f260326b2e8473bca2","payload":{"connection_id":"efc69d3132f1467b8e898a382b23ac0d","event_at":"2026-07-27T05:40:51.434000Z","event_type":"price_change","frame_hash":"c7969afb5793489f4a3777588adcfae847089b1d3029c3f7629cee1c3bc18f22","frame_index":0,"kind":"data","monotonic_ns":232840328264291,"payload":{"event_type":"price_change","market":"0x3b40066b5cf3871a2f6237c5628bd8092a206aa998558ac5ec13c4483e31e160","price_changes":[{"asset_id":"110216635572655435074987471276357323571387854733835379371586402147734167783946","best_ask":"0.35","best_bid":"0.34","hash":"65e871263b8ab3c3a63ddc58820ea90281e48b1a","price":"0.29","side":"BUY","size":"22"},{"asset_id":"14766054693214075530629349735273995982307625376442606753688071083149620216746","best_ask":"0.66","best_bid":"0.65","hash":"3611772d2b8698daccdff2ab22e720b0f7569704","price":"0.71","side":"SELL","size":"22"}],"timestamp":"1785130851434"},"payload_hash":"ed60ccfc50fb207b2e966e7dccedd21e6b527d0e847916a6dde66b499a628092","raw_frame":"{\"market\":\"0x3b40066b5cf3871a2f6237c5628bd8092a206aa998558ac5ec13c4483e31e160\", \"price_changes\":[{\"asset_id\":\"110216635572655435074987471276357323571387854733835379371586402147734167783946\", \"price\":\"0.29\", \"size\":\"22\", \"side\":\"BUY\", \"hash\":\"65e871263b8ab3c3a63ddc58820ea90281e48b1a\", \"best_bid\":\"0.34\", \"best_ask\":\"0.35\"}, {\"asset_id\":\"14766054693214075530629349735273995982307625376442606753688071083149620216746\", \"price\":\"0.71\", \"size\":\"22\", \"side\":\"SELL\", \"hash\":\"3611772d2b8698daccdff2ab22e720b0f7569704\", \"best_bid\":\"0.65\", \"best_ask\":\"0.66\"}], \"timestamp\":\"1785130851434\", \"event_type\":\"price_change\"}","received_at":"2026-07-27T05:40:57.094621Z","schema_version":"clob-market-ws.price_change.v1","sequence":null,"server_hash":null,"server_timestamp":"1785130851434","session_id":"502006c5cfcd437296561ea750c9ec8b","source":"clob_market_ws"},"received_at":"2026-07-27T05:40:57.094621Z","record_id":"c1bafd16fcd5bc219bb50f73bd4abae5dcabefd363dd07c78e9037be7060778e","schema_fingerprint":"4aa3821a28b0b7c2400bc59aba4bcc0a76e971dadd19610d3ad38c768e124dc7","schema_version":"edge-lab-recorder.raw.v1","sequence":null,"source":"clob_market_ws"}
{"event_at":"2026-07-27T05:40:51.434000Z","event_fingerprint":"0af5a9d5559c22968033a9a1841134b2e81cf3d9d649c6078f5078540c63e20f","payload":{"connection_id":"efc69d3132f1467b8e898a382b23ac0d","event_at":"2026-07-27T05:40:51.434000Z","event_type":"price_change","frame_hash":"3669fdd3b336a56f235b9917904b1c3cc42839ef22bb98ff87c3a7ba4e23a628","frame_index":0,"kind":"data","monotonic_ns":232840334485333,"payload":{"event_type":"price_change","market":"0x3b40066b5cf3871a2f6237c5628bd8092a206aa998558ac5ec13c4483e31e160","price_changes":[{"asset_id":"110216635572655435074987471276357323571387854733835379371586402147734167783946","best_ask":"0.35","best_bid":"0.34","hash":"a0ae57533852515b5e669c2c6a92367915033a4f","price":"0.3","side":"BUY","size":"64.98"},{"asset_id":"14766054693214075530629349735273995982307625376442606753688071083149620216746","best_ask":"0.66","best_bid":"0.65","hash":"1217ba9de7f1410dfa09c7beb9ce8814ec6a7bc2","price":"0.7","side":"SELL","size":"64.98"}],"timestamp":"1785130851434"},"payload_hash":"6cafc7efe9dde8750eac3fecebd477ac2fdf3fe1909581a125a84882f24bde1b","raw_frame":"{\"market\":\"0x3b40066b5cf3871a2f6237c5628bd8092a206aa998558ac5ec13c4483e31e160\", \"price_changes\":[{\"asset_id\":\"110216635572655435074987471276357323571387854733835379371586402147734167783946\", \"price\":\"0.3\", \"size\":\"64.98\", \"side\":\"BUY\", \"hash\":\"a0ae57533852515b5e669c2c6a92367915033a4f\", \"best_bid\":\"0.34\", \"best_ask\":\"0.35\"}, {\"asset_id\":\"14766054693214075530629349735273995982307625376442606753688071083149620216746\", \"price\":\"0.7\", \"size\":\"64.98\", \"side\":\"SELL\", \"hash\":\"1217ba9de7f1410dfa09c7beb9ce8814ec6a7bc2\", \"best_bid\":\"0.65\", \"best_ask\":\"0.66\"}], \"timestamp\":\"1785130851434\", \"event_type\":\"price_change\"}","received_at":"2026-07-27T05:40:57.100841Z","schema_version":"clob-market-ws.price_change.v1","sequence":null,"server_hash":null,"server_timestamp":"1785130851434","session_id":"502006c5cfcd437296561ea750c9ec8b","source":"clob_market_ws"},"received_at":"2026-07-27T05:40:57.100841Z","record_id":"feda52a8796f1a6f46fe42d383fd52afe2f0e4b20a935df47b0e9fad5caf60cd","schema_fingerprint":"4aa3821a28b0b7c2400bc59aba4bcc0a76e971dadd19610d3ad38c768e124dc7","schema_version":"edge-lab-recorder.raw.v1","sequence":null,"source":"clob_market_ws"}
{"event_at":"2026-07-27T05:40:51.434000Z","event_fingerprint":"d0f0d35a43b41c222d34256ead3b5e8a3d4555a1433d8a6c017f6866c95ac042","payload":{"connection_id":"efc69d3132f1467b8e898a382b23ac0d","event_at":"2026-07-27T05:40:51.434000Z","event_type":"best_bid_ask","frame_hash":"4aec2a0443120c71451bdc002a02bb136c5dc8d5fd88ce27d771703e7069809c","frame_index":0,"kind":"data","monotonic_ns":232840337697875,"payload":{"asset_id":"14766054693214075530629349735273995982307625376442606753688071083149620216746","best_ask":"0.67","best_bid":"0.65","event_type":"best_bid_ask","market":"0x3b40066b5cf3871a2f6237c5628bd8092a206aa998558ac5ec13c4483e31e160","spread":"0.02","timestamp":"1785130851434"},"payload_hash":"e76d674ea036a5c51e9d3f1ddf0455250a9fab094295830963837a05165e30be","raw_frame":"{\"market\":\"0x3b40066b5cf3871a2f6237c5628bd8092a206aa998558ac5ec13c4483e31e160\", \"asset_id\":\"14766054693214075530629349735273995982307625376442606753688071083149620216746\", \"best_bid\":\"0.65\", \"best_ask\":\"0.67\", \"spread\":\"0.02\", \"timestamp\":\"1785130851434\", \"event_type\":\"best_bid_ask\"}","received_at":"2026-07-27T05:40:57.104058Z","schema_version":"clob-market-ws.best_bid_ask.v1","sequence":null,"server_hash":null,"server_timestamp":"1785130851434","session_id":"502006c5cfcd437296561ea750c9ec8b","source":"clob_market_ws"},"received_at":"2026-07-27T05:40:57.104058Z","record_id":"36d749f1a701d4a7dc72664cc8677fe78412fae85eab209402fc7e1eebf9dd07","schema_fingerprint":"8488399f31b0337811b13b266be932db7062827c2470b78bd8e9e99bab51d17d","schema_version":"edge-lab-recorder.raw.v1","sequence":null,"source":"clob_market_ws"}
{"event_at":"2026-07-27T05:40:51.434000Z","event_fingerprint":"62a6327e55feef0858423d010192e34c11ef191b26cbc4b0d248751773df637f","payload":{"connection_id":"efc69d3132f1467b8e898a382b23ac0d","event_at":"2026-07-27T05:40:51.434000Z","event_type":"best_bid_ask","frame_hash":"230f903be7a67a73eabf4723db504be30782f2e9403befdb6b5e04d8f64feb76","frame_index":0,"kind":"data","monotonic_ns":232840342686500,"payload":{"asset_id":"110216635572655435074987471276357323571387854733835379371586402147734167783946","best_ask":"0.35","best_bid":"0.33","event_type":"best_bid_ask","market":"0x3b40066b5cf3871a2f6237c5628bd8092a206aa998558ac5ec13c4483e31e160","spread":"0.02","timestamp":"1785130851434"},"payload_hash":"92a373a4c34039e38022453e847e88ff6500bee84a38b1c3dfc33f928b8e9047","raw_frame":"{\"market\":\"0x3b40066b5cf3871a2f6237c5628bd8092a206aa998558ac5ec13c4483e31e160\", \"asset_id\":\"110216635572655435074987471276357323571387854733835379371586402147734167783946\", \"best_bid\":\"0.33\", \"best_ask\":\"0.35\", \"spread\":\"0.02\", \"timestamp\":\"1785130851434\", \"event_type\":\"best_bid_ask\"}","received_at":"2026-07-27T05:40:57.109045Z","schema_version":"clob-market-ws.best_bid_ask.v1","sequence":null,"server_hash":null,"server_timestamp":"1785130851434","session_id":"502006c5cfcd437296561ea750c9ec8b","source":"clob_market_ws"},"received_at":"2026-07-27T05:40:57.109045Z","record_id":"260ad16899b0c4dfa7badb22123b7cf6453f4047e4713c6c9a4b5ba1ce033fc8","schema_fingerprint":"8488399f31b0337811b13b266be932db7062827c2470b78bd8e9e99bab51d17d","schema_version":"edge-lab-recorder.raw.v1","sequence":null,"source":"clob_market_ws"}
{"event_at":"2026-07-27T05:40:51.434000Z","event_fingerprint":"e36568d7eff5ff0fb75ed45b926f106a959665969eaadeb6ff5e36a32e162f38","payload":{"connection_id":"efc69d3132f1467b8e898a382b23ac0d","event_at":"2026-07-27T05:40:51.434000Z","event_type":"price_change","frame_hash":"3010d5706bf1a5779ce0965cc206b1f69ffedca24a20f9487ab3cd00e87d03f0","frame_index":0,"kind":"data","monotonic_ns":232840343732958,"payload":{"event_type":"price_change","market":"0x3b40066b5cf3871a2f6237c5628bd8092a206aa998558ac5ec13c4483e31e160","price_changes":[{"asset_id":"110216635572655435074987471276357323571387854733835379371586402147734167783946","best_ask":"0.35","best_bid":"0.33","hash":"21f1df1844366b1f1a247700b998ff18eb6a1392","price":"0.34","side":"BUY","size":"0"},{"asset_id":"14766054693214075530629349735273995982307625376442606753688071083149620216746","best_ask":"0.67","best_bid":"0.65","hash":"bd15f4b16ec34371725e97f90e543a9d956058d9","price":"0.66","side":"SELL","size":"0"}],"timestamp":"1785130851434"},"payload_hash":"925f353b7daf3df03f258fcd9e0479e35ec45137aeefe07375d30dcb7aeeb71c","raw_frame":"{\"market\":\"0x3b40066b5cf3871a2f6237c5628bd8092a206aa998558ac5ec13c4483e31e160\", \"price_changes\":[{\"asset_id\":\"110216635572655435074987471276357323571387854733835379371586402147734167783946\", \"price\":\"0.34\", \"size\":\"0\", \"side\":\"BUY\", \"hash\":\"21f1df1844366b1f1a247700b998ff18eb6a1392\", \"best_bid\":\"0.33\", \"best_ask\":\"0.35\"}, {\"asset_id\":\"14766054693214075530629349735273995982307625376442606753688071083149620216746\", \"price\":\"0.66\", \"size\":\"0\", \"side\":\"SELL\", \"hash\":\"bd15f4b16ec34371725e97f90e543a9d956058d9\", \"best_bid\":\"0.65\", \"best_ask\":\"0.67\"}], \"timestamp\":\"1785130851434\", \"event_type\":\"price_change\"}","received_at":"2026-07-27T05:40:57.110086Z","schema_version":"clob-market-ws.price_change.v1","sequence":null,"server_hash":null,"server_timestamp":"1785130851434","session_id":"502006c5cfcd437296561ea750c9ec8b","source":"clob_market_ws"},"received_at":"2026-07-27T05:40:57.110086Z","record_id":"ac24c1c75a7e8785264ec20ad6218b0b3cf26a45578d45951322f09f7d2e4661","schema_fingerprint":"4aa3821a28b0b7c2400bc59aba4bcc0a76e971dadd19610d3ad38c768e124dc7","schema_version":"edge-lab-recorder.raw.v1","sequence":null,"source":"clob_market_ws"}
{"event_at":"2026-07-27T05:40:51.434000Z","event_fingerprint":"22dc706c4ceda1eb489c13775eb76837c99420d28d25b7a5d0c749bdc6e95885","payload":{"connection_id":"efc69d3132f1467b8e898a382b23ac0d","event_at":"2026-07-27T05:40:51.434000Z","event_type":"price_change","frame_hash":"3a38e42e4496ea932cbcc18b1410594a09ba1fd6ee501c73711f4b5160e07300","frame_index":0,"kind":"data","monotonic_ns":232840346122375,"payload":{"event_type":"price_change","market":"0x3b40066b5cf3871a2f6237c5628bd8092a206aa998558ac5ec13c4483e31e160","price_changes":[{"asset_id":"110216635572655435074987471276357323571387854733835379371586402147734167783946","best_ask":"0.35","best_bid":"0.33","hash":"2ba07bad1d83f79efb43a54aa28091da2ec2501c","price":"0.31","side":"BUY","size":"6"},{"asset_id":"14766054693214075530629349735273995982307625376442606753688071083149620216746","best_ask":"0.67","best_bid":"0.65","hash":"01c4e3951c921d4b16193d4bea59e7f82a39cc25","price":"0.69","side":"SELL","size":"6"}],"timestamp":"1785130851434"},"payload_hash":"eb3fba18267bf74cc992fd67f521fde9d9609fed6c1c7bcf6a1863d728baf8c9","raw_frame":"{\"market\":\"0x3b40066b5cf3871a2f6237c5628bd8092a206aa998558ac5ec13c4483e31e160\", \"price_changes\":[{\"asset_id\":\"110216635572655435074987471276357323571387854733835379371586402147734167783946\", \"price\":\"0.31\", \"size\":\"6\", \"side\":\"BUY\", \"hash\":\"2ba07bad1d83f79efb43a54aa28091da2ec2501c\", \"best_bid\":\"0.33\", \"best_ask\":\"0.35\"}, {\"asset_id\":\"14766054693214075530629349735273995982307625376442606753688071083149620216746\", \"price\":\"0.69\", \"size\":\"6\", \"side\":\"SELL\", \"hash\":\"01c4e3951c921d4b16193d4bea59e7f82a39cc25\", \"best_bid\":\"0.65\", \"best_ask\":\"0.67\"}], \"timestamp\":\"1785130851434\", \"event_type\":\"price_change\"}","received_at":"2026-07-27T05:40:57.112483Z","schema_version":"clob-market-ws.price_change.v1","sequence":null,"server_hash":null,"server_timestamp":"1785130851434","session_id":"502006c5cfcd437296561ea750c9ec8b","source":"clob_market_ws"},"received_at":"2026-07-27T05:40:57.112483Z","record_id":"afeb7842688aafa5e73293d13b29ada34a507766cb125e4f712d9568c95f4906","schema_fingerprint":"4aa3821a28b0b7c2400bc59aba4bcc0a76e971dadd19610d3ad38c768e124dc7","schema_version":"edge-lab-recorder.raw.v1","sequence":null,"source":"clob_market_ws"}
{"event_at":"2026-07-27T05:40:51.435000Z","event_fingerprint":"27cefbf3eba4101ae386be17a812b167302d1c7a87275a68299e653795df5de6","payload":{"connection_id":"efc69d3132f1467b8e898a382b23ac0d","event_at":"2026-07-27T05:40:51.435000Z","event_type":"price_change","frame_hash":"82ec0be94ddb28b74ee97757a0bfee1d28195d3fff84e4ee71b71aa3a8a3f8da","frame_index":0,"kind":"data","monotonic_ns":232840348281833,"payload":{"event_type":"price_change","market":"0x3b40066b5cf3871a2f6237c5628bd8092a206aa998558ac5ec13c4483e31e160","price_changes":[{"asset_id":"110216635572655435074987471276357323571387854733835379371586402147734167783946","best_ask":"0.35","best_bid":"0.33","hash":"a11571b7fe955956afa0c001b3e6f1e649f84c61","price":"0.33","side":"BUY","size":"9.6"},{"asset_id":"14766054693214075530629349735273995982307625376442606753688071083149620216746","best_ask":"0.67","best_bid":"0.65","hash":"3ff6fde6eb0da799fe82d69d35cf9d52352615bb","price":"0.67","side":"SELL","size":"9.6"}],"timestamp":"1785130851435"},"payload_hash":"fd3bf7498793b3bf550db942eac3b27eeb5cfa8d6083e048f99c975daedb994e","raw_frame":"{\"market\":\"0x3b40066b5cf3871a2f6237c5628bd8092a206aa998558ac5ec13c4483e31e160\", \"price_changes\":[{\"asset_id\":\"110216635572655435074987471276357323571387854733835379371586402147734167783946\", \"price\":\"0.33\", \"size\":\"9.6\", \"side\":\"BUY\", \"hash\":\"a11571b7fe955956afa0c001b3e6f1e649f84c61\", \"best_bid\":\"0.33\", \"best_ask\":\"0.35\"}, {\"asset_id\":\"14766054693214075530629349735273995982307625376442606753688071083149620216746\", \"price\":\"0.67\", \"size\":\"9.6\", \"side\":\"SELL\", \"hash\":\"3ff6fde6eb0da799fe82d69d35cf9d52352615bb\", \"best_bid\":\"0.65\", \"best_ask\":\"0.67\"}], \"timestamp\":\"1785130851435\", \"event_type\":\"price_change\"}","received_at":"2026-07-27T05:40:57.114644Z","schema_version":"clob-market-ws.price_change.v1","sequence":null,"server_hash":null,"server_timestamp":"1785130851435","session_id":"502006c5cfcd437296561ea750c9ec8b","source":"clob_market_ws"},"received_at":"2026-07-27T05:40:57.114644Z","record_id":"026ab90e86c33f10cafbf047aa497af50b066461feb35271cc3fb55ee00bec24","schema_fingerprint":"4aa3821a28b0b7c2400bc59aba4bcc0a76e971dadd19610d3ad38c768e124dc7","schema_version":"edge-lab-recorder.raw.v1","sequence":null,"source":"clob_market_ws"}
{"event_at":null,"event_fingerprint":"4c888d90788e983c3080469fdc50f9988b878319d04e74c7e3f637c8e6c18fec","payload":{"connection_id":"efc69d3132f1467b8e898a382b23ac0d","detail":{"interval_seconds":10.0,"message":"PING"},"event_type":"heartbeat","kind":"lifecycle","monotonic_ns":232840353469291,"received_at":"2026-07-27T05:40:57.119830Z","schema_version":"edge-lab-recorder.lifecycle.v1","session_id":"502006c5cfcd437296561ea750c9ec8b","source":"clob_market_ws"},"received_at":"2026-07-27T05:40:57.119830Z","record_id":"84ce961eef95febd72718ed996c92db6337e8b2884916a4f6e6f00ef9b83fba2","schema_fingerprint":"cb8aa3aa4cb168a4b724fd9077bee6ecfb9bc586c57cfdf0ab89f00d82045e3c","schema_version":"edge-lab-recorder.raw.v1","sequence":null,"source":"clob_market_ws"}
