{"event_at":"2026-07-27T05:37:31.755000Z","event_fingerprint":"83b34ccf61496b44359dd6b9c14d01ab34775a97a59f929892914315325781c9","payload":{"connection_id":"efc69d3132f1467b8e898a382b23ac0d","event_at":"2026-07-27T05:37:31.755000Z","event_type":"price_change","frame_hash":"b3917ba5fb4d749cd31476ec72748c6fe15b2050de1f45ee642559850ebacffd","frame_index":0,"kind":"data","monotonic_ns":232634949977416,"payload":{"event_type":"price_change","market":"0x3b40066b5cf3871a2f6237c5628bd8092a206aa998558ac5ec13c4483e31e160","price_changes":[{"asset_id":"110216635572655435074987471276357323571387854733835379371586402147734167783946","best_ask":"0.73","best_bid":"0.72","hash":"27d738d909227fa0104625ea1cdcdc609696b6ea","price":"0.04","side":"BUY","size":"583.09"},{"asset_id":"14766054693214075530629349735273995982307625376442606753688071083149620216746","best_ask":"0.28","best_bid":"0.27","hash":"a1476e93f277c7aa3cb94adcc753cdc39bc38bb4","price":"0.96","side":"SELL","size":"583.09"}],"timestamp":"1785130651755"},"payload_hash":"b5af4760ee4f77058e6b764aa5991e58c47bfaba1c18d22b160ec7d4bd15a912","raw_frame":"{\"market\":\"0x3b40066b5cf3871a2f6237c5628bd8092a206aa998558ac5ec13c4483e31e160\", \"price_changes\":[{\"asset_id\":\"110216635572655435074987471276357323571387854733835379371586402147734167783946\", \"price\":\"0.04\", \"size\":\"583.09\", \"side\":\"BUY\", \"hash\":\"27d738d909227fa0104625ea1cdcdc609696b6ea\", \"best_bid\":\"0.72\", \"best_ask\":\"0.73\"}, {\"asset_id\":\"14766054693214075530629349735273995982307625376442606753688071083149620216746\", \"price\":\"0.96\", \"size\":\"583.09\", \"side\":\"SELL\", \"hash\":\"a1476e93f277c7aa3cb94adcc753cdc39bc38bb4\", \"best_bid\":\"0.27\", \"best_ask\":\"0.28\"}], \"timestamp\":\"1785130651755\", \"event_type\":\"price_change\"}","received_at":"2026-07-27T05:37:31.714904Z","schema_version":"clob-market-ws.price_change.v1","sequence":null,"server_hash":null,"server_timestamp":"1785130651755","session_id":"502006c5cfcd437296561ea750c9ec8b","source":"clob_market_ws"},"received_at":"2026-07-27T05:37:31.714904Z","record_id":"f34f8e9382f00c3a834ce17dd3fe9167c1f1349fa38fd4b8af0038a9dfa05cbb","schema_fingerprint":"4aa3821a28b0b7c2400bc59aba4bcc0a76e971dadd19610d3ad38c768e124dc7","schema_version":"edge-lab-recorder.raw.v1","sequence":null,"source":"clob_market_ws"}
{"event_at":"2026-07-27T05:37:31.781000Z","event_fingerprint":"8dcbe13cbe005262f21fe26e95ec8a4e7d7e5e0fc58dc521d5e6c47d65178cea","payload":{"connection_id":"efc69d3132f1467b8e898a382b23ac0d","event_at":"2026-07-27T05:37:31.781000Z","event_type":"price_change","frame_hash":"fd83783badeb48b09308aad346bb580b61058a65b1314adadc6845aa4ffc02fa","frame_index":0,"kind":"data","monotonic_ns":232634975647333,"payload":{"event_type":"price_change","market":"0x3b40066b5cf3871a2f6237c5628bd8092a206aa998558ac5ec13c4483e31e160","price_changes":[{"asset_id":"110216635572655435074987471276357323571387854733835379371586402147734167783946","best_ask":"0.73","best_bid":"0.72","hash":"4ac93434bd3ae4dba1d278c7952026a128782fd9","price":"0.72","side":"BUY","size":"270"},{"asset_id":"14766054693214075530629349735273995982307625376442606753688071083149620216746","best_ask":"0.28","best_bid":"0.27","hash":"7b2346071d59ef984865e3a5c1ccd094951608a2","price":"0.28","side":"SELL","size":"270"}],"timestamp":"1785130651781"},"payload_hash":"471df7f9bc3252839e1197fbd5d1cde735ba034817a736c15d8fdc3e0c6bbf39","raw_frame":"{\"market\":\"0x3b40066b5cf3871a2f6237c5628bd8092a206aa998558ac5ec13c4483e31e160\", \"price_changes\":[{\"asset_id\":\"110216635572655435074987471276357323571387854733835379371586402147734167783946\", \"price\":\"0.72\", \"size\":\"270\", \"side\":\"BUY\", \"hash\":\"4ac93434bd3ae4dba1d278c7952026a128782fd9\", \"best_bid\":\"0.72\", \"best_ask\":\"0.73\"}, {\"asset_id\":\"14766054693214075530629349735273995982307625376442606753688071083149620216746\", \"price\":\"0.28\", \"size\":\"270\", \"side\":\"SELL\", \"hash\":\"7b2346071d59ef984865e3a5c1ccd094951608a2\", \"best_bid\":\"0.27\", \"best_ask\":\"0.28\"}], \"timestamp\":\"1785130651781\", \"event_type\":\"price_change\"}","received_at":"2026-07-27T05:37:31.740575Z","schema_version":"clob-market-ws.price_change.v1","sequence":null,"server_hash":null,"server_timestamp":"1785130651781","session_id":"502006c5cfcd437296561ea750c9ec8b","source":"clob_market_ws"},"received_at":"2026-07-27T05:37:31.740575Z","record_id":"f2dff4809aa4b3076d279265b35f5e5625f4a9959d61604b1809053f1e341e63","schema_fingerprint":"4aa3821a28b0b7c2400bc59aba4bcc0a76e971dadd19610d3ad38c768e124dc7","schema_version":"edge-lab-recorder.raw.v1","sequence":null,"source":"clob_market_ws"}
{"event_at":"2026-07-27T05:37:31.808000Z","event_fingerprint":"ad24b37dc38815f792b82c6b314c12ded19d791cf9844785e37296ae2756b95d","payload":{"connection_id":"efc69d3132f1467b8e898a382b23ac0d","event_at":"2026-07-27T05:37:31.808000Z","event_type":"price_change","frame_hash":"e6eee905f9ff47a772a789afc8bd007f049a6c3e3ed9150ea1c8bb491aded7be","frame_index":0,"kind":"data","monotonic_ns":232635001403125,"payload":{"event_type":"price_change","market":"0x3b40066b5cf3871a2f6237c5628bd8092a206aa998558ac5ec13c4483e31e160","price_changes":[{"asset_id":"110216635572655435074987471276357323571387854733835379371586402147734167783946","best_ask":"0.73","best_bid":"0.72","hash":"2fcc0eb99a10ee6c5239d4ae13eb0a71396b8f83","price":"0.04","side":"BUY","size":"578.09"},{"asset_id":"14766054693214075530629349735273995982307625376442606753688071083149620216746","best_ask":"0.28","best_bid":"0.27","hash":"aacfac6adabe21545cf160e074d4cd942373a4a2","price":"0.96","side":"SELL","size":"578.09"}],"timestamp":"1785130651808"},"payload_hash":"6e6eeab3a89468fbe47f313dab34e5327187d729a97507e0ed02114f56e296ac","raw_frame":"{\"market\":\"0x3b40066b5cf3871a2f6237c5628bd8092a206aa998558ac5ec13c4483e31e160\", \"price_changes\":[{\"asset_id\":\"110216635572655435074987471276357323571387854733835379371586402147734167783946\", \"price\":\"0.04\", \"size\":\"578.09\", \"side\":\"BUY\", \"hash\":\"2fcc0eb99a10ee6c5239d4ae13eb0a71396b8f83\", \"best_bid\":\"0.72\", \"best_ask\":\"0.73\"}, {\"asset_id\":\"14766054693214075530629349735273995982307625376442606753688071083149620216746\", \"price\":\"0.96\", \"size\":\"578.09\", \"side\":\"SELL\", \"hash\":\"aacfac6adabe21545cf160e074d4cd942373a4a2\", \"best_bid\":\"0.27\", \"best_ask\":\"0.28\"}], \"timestamp\":\"1785130651808\", \"event_type\":\"price_change\"}","received_at":"2026-07-27T05:37:31.766331Z","schema_version":"clob-market-ws.price_change.v1","sequence":null,"server_hash":null,"server_timestamp":"1785130651808","session_id":"502006c5cfcd437296561ea750c9ec8b","source":"clob_market_ws"},"received_at":"2026-07-27T05:37:31.766331Z","record_id":"a167f027cd942d71bc41fcfe10f90a27c829c6b19cd9b458299d16e8a8d4f76d","schema_fingerprint":"4aa3821a28b0b7c2400bc59aba4bcc0a76e971dadd19610d3ad38c768e124dc7","schema_version":"edge-lab-recorder.raw.v1","sequence":null,"source":"clob_market_ws"}
{"event_at":"2026-07-27T05:37:31.882000Z","event_fingerprint":"28c33512c8d22e7ecc8960311a32e8af0ac9dab7ac8827fbb536c75e78b7e421","payload":{"connection_id":"efc69d3132f1467b8e898a382b23ac0d","event_at":"2026-07-27T05:37:31.882000Z","event_type":"price_change","frame_hash":"377b55eab0e90a986b0b676373662c945e85deaf43a6987de1155ee371fdbffe","frame_index":0,"kind":"data","monotonic_ns":232635075866833,"payload":{"event_type":"price_change","market":"0x3b40066b5cf3871a2f6237c5628bd8092a206aa998558ac5ec13c4483e31e160","price_changes":[{"asset_id":"110216635572655435074987471276357323571387854733835379371586402147734167783946","best_ask":"0.73","best_bid":"0.72","hash":"03fad3dadbced535192efccd866ae61c14112866","price":"0.7","side":"BUY","size":"45.06"},{"asset_id":"14766054693214075530629349735273995982307625376442606753688071083149620216746","best_ask":"0.28","best_bid":"0.27","hash":"58c6119df12c348254efc69f03cc2866ac7dd0c6","price":"0.3","side":"SELL","size":"45.06"}],"timestamp":"1785130651882"},"payload_hash":"2fb39efef84b7a063e5097821f8fa92f087787d2b94a615130bb3126e0bcbe2a","raw_frame":"{\"market\":\"0x3b40066b5cf3871a2f6237c5628bd8092a206aa998558ac5ec13c4483e31e160\", \"price_changes\":[{\"asset_id\":\"110216635572655435074987471276357323571387854733835379371586402147734167783946\", \"price\":\"0.7\", \"size\":\"45.06\", \"side\":\"BUY\", \"hash\":\"03fad3dadbced535192efccd866ae61c14112866\", \"best_bid\":\"0.72\", \"best_ask\":\"0.73\"}, {\"asset_id\":\"14766054693214075530629349735273995982307625376442606753688071083149620216746\", \"price\":\"0.3\", \"size\":\"45.06\", \"side\":\"SELL\", \"hash\":\"58c6119df12c348254efc69f03cc2866ac7dd0c6\", \"best_bid\":\"0.27\", \"best_ask\":\"0.28\"}], \"timestamp\":\"1785130651882\", \"event_type\":\"price_change\"}","received_at":"2026-07-27T05:37:31.840796Z","schema_version":"clob-market-ws.price_change.v1","sequence":null,"server_hash":null,"server_timestamp":"1785130651882","session_id":"502006c5cfcd437296561ea750c9ec8b","source":"clob_market_ws"},"received_at":"2026-07-27T05:37:31.840796Z","record_id":"3744c990c6dad4f4910a6efd9c96e7fc02598c5c0600a712cd4a565dd0d3eb2f","schema_fingerprint":"4aa3821a28b0b7c2400bc59aba4bcc0a76e971dadd19610d3ad38c768e124dc7","schema_version":"edge-lab-recorder.raw.v1","sequence":null,"source":"clob_market_ws"}
{"event_at":"2026-07-27T05:37:31.884000Z","event_fingerprint":"d58a4a2c4ea7d150d24800859328429d28fd8718676dbad3d47456dd8cbba81a","payload":{"connection_id":"efc69d3132f1467b8e898a382b23ac0d","event_at":"2026-07-27T05:37:31.884000Z","event_type":"price_change","frame_hash":"0d18a37e3ad3200de5de7e7da88b28f32fb7779e9dc2db464565dbea8c83c8ab","frame_index":0,"kind":"data","monotonic_ns":232635078840208,"payload":{"event_type":"price_change","market":"0x3b40066b5cf3871a2f6237c5628bd8092a206aa998558ac5ec13c4483e31e160","price_changes":[{"asset_id":"14766054693214075530629349735273995982307625376442606753688071083149620216746","best_ask":"0.28","best_bid":"0.27","hash":"cca370b7b7a2bc3fa648cf3b9b3d94bc59528380","price":"0.3","side":"SELL","size":"72"},{"asset_id":"110216635572655435074987471276357323571387854733835379371586402147734167783946","best_ask":"0.73","best_bid":"0.72","hash":"778100752a5b037b65c1d89789cc060bd285a6bf","price":"0.7","side":"BUY","size":"72"}],"timestamp":"1785130651884"},"payload_hash":"391bf031ef600c52b72e80d1bf0f267f35e260f4f054b2763cc87f6135b00334","raw_frame":"{\"market\":\"0x3b40066b5cf3871a2f6237c5628bd8092a206aa998558ac5ec13c4483e31e160\", \"price_changes\":[{\"asset_id\":\"14766054693214075530629349735273995982307625376442606753688071083149620216746\", \"price\":\"0.3\", \"size\":\"72\", \"side\":\"SELL\", \"hash\":\"cca370b7b7a2bc3fa648cf3b9b3d94bc59528380\", \"best_bid\":\"0.27\", \"best_ask\":\"0.28\"}, {\"asset_id\":\"110216635572655435074987471276357323571387854733835379371586402147734167783946\", \"price\":\"0.7\", \"size\":\"72\", \"side\":\"BUY\", \"hash\":\"778100752a5b037b65c1d89789cc060bd285a6bf\", \"best_bid\":\"0.72\", \"best_ask\":\"0.73\"}], \"timestamp\":\"1785130651884\", \"event_type\":\"price_change\"}","received_at":"2026-07-27T05:37:31.843769Z","schema_version":"clob-market-ws.price_change.v1","sequence":null,"server_hash":null,"server_timestamp":"1785130651884","session_id":"502006c5cfcd437296561ea750c9ec8b","source":"clob_market_ws"},"received_at":"2026-07-27T05:37:31.843769Z","record_id":"96d03f958f050018c687f2a9b4a00cd57d5ed840620585128260fc9051f4816f","schema_fingerprint":"4aa3821a28b0b7c2400bc59aba4bcc0a76e971dadd19610d3ad38c768e124dc7","schema_version":"edge-lab-recorder.raw.v1","sequence":null,"source":"clob_market_ws"}
{"event_at":"2026-07-27T05:37:31.885000Z","event_fingerprint":"bae4cd95fbfe1aed1e4d8c2c94ebaf9f5b9c63edee30b0349f13cc7dbcfac3e6","payload":{"connection_id":"efc69d3132f1467b8e898a382b23ac0d","event_at":"2026-07-27T05:37:31.885000Z","event_type":"price_change","frame_hash":"2fabf5670167d663e676205c8c58019dd68ae0d452b98e235b81ed7e26941222","frame_index":0,"kind":"data","monotonic_ns":232635080360208,"payload":{"event_type":"price_change","market":"0x3b40066b5cf3871a2f6237c5628bd8092a206aa998558ac5ec13c4483e31e160","price_changes":[{"asset_id":"14766054693214075530629349735273995982307625376442606753688071083149620216746","best_ask":"0.28","best_bid":"0.27","hash":"b0bb21ca97216bbd892cd36a77938d03d459175a","price":"0.31","side":"SELL","size":"128"},{"asset_id":"110216635572655435074987471276357323571387854733835379371586402147734167783946","best_ask":"0.73","best_bid":"0.72","hash":"4f1d5553c5e7619135b6c46125740cd049b14b3d","price":"0.69","side":"BUY","size":"128"}],"timestamp":"1785130651885"},"payload_hash":"0a15c0fd69c4160416139e8e37593c5de702e9bc4bbedc0307c1d4c2d1f9fc4f","raw_frame":"{\"market\":\"0x3b40066b5cf3871a2f6237c5628bd8092a206aa998558ac5ec13c4483e31e160\", \"price_changes\":[{\"asset_id\":\"14766054693214075530629349735273995982307625376442606753688071083149620216746\", \"price\":\"0.31\", \"size\":\"128\", \"side\":\"SELL\", \"hash\":\"b0bb21ca97216bbd892cd36a77938d03d459175a\", \"best_bid\":\"0.27\", \"best_ask\":\"0.28\"}, {\"asset_id\":\"110216635572655435074987471276357323571387854733835379371586402147734167783946\", \"price\":\"0.69\", \"size\":\"128\", \"side\":\"BUY\", \"hash\":\"4f1d5553c5e7619135b6c46125740cd049b14b3d\", \"best_bid\":\"0.72\", \"best_ask\":\"0.73\"}], \"timestamp\":\"1785130651885\", \"event_type\":\"price_change\"}","received_at":"2026-07-27T05:37:31.845288Z","schema_version":"clob-market-ws.price_change.v1","sequence":null,"server_hash":null,"server_timestamp":"1785130651885","session_id":"502006c5cfcd437296561ea750c9ec8b","source":"clob_market_ws"},"received_at":"2026-07-27T05:37:31.845288Z","record_id":"2b9984772397d88c87e341ff006d6ecab6aac2b29558c5b26437bdd9a034a80e","schema_fingerprint":"4aa3821a28b0b7c2400bc59aba4bcc0a76e971dadd19610d3ad38c768e124dc7","schema_version":"edge-lab-recorder.raw.v1","sequence":null,"source":"clob_market_ws"}
{"event_at":"2026-07-27T05:37:31.914000Z","event_fingerprint":"f59fa5150a37568bd8f27581985d91ece14c3ed00a6d1482add75bc0f946ad75","payload":{"connection_id":"efc69d3132f1467b8e898a382b23ac0d","event_at":"2026-07-27T05:37:31.914000Z","event_type":"price_change","frame_hash":"7da555b2bae3ded0780408fbe901ece9814c47d7eb434e91f2e66a826ddbf519","frame_index":0,"kind":"data","monotonic_ns":232635109393166,"payload":{"event_type":"price_change","market":"0x3b40066b5cf3871a2f6237c5628bd8092a206aa998558ac5ec13c4483e31e160","price_changes":[{"asset_id":"110216635572655435074987471276357323571387854733835379371586402147734167783946","best_ask":"0.73","best_bid":"0.72","hash":"4a2cf56275b2c04fe746d3c0bb2a57df3e25128b","price":"0.01","side":"BUY","size":"5617.45"},{"asset_id":"14766054693214075530629349735273995982307625376442606753688071083149620216746","best_ask":"0.28","best_bid":"0.27","hash":"2375b80bf7260ca66d603d43b5b6516e236c71d4","price":"0.99","side":"SELL","size":"5617.45"}],"timestamp":"1785130651914"},"payload_hash":"3c2ac23bbe57f6f8d99beda4c1c09f62d73521399e1df37b5b0dea1c01b7a15f","raw_frame":"{\"market\":\"0x3b40066b5cf3871a2f6237c5628bd8092a206aa998558ac5ec13c4483e31e160\", \"price_changes\":[{\"asset_id\":\"110216635572655435074987471276357323571387854733835379371586402147734167783946\", \"price\":\"0.01\", \"size\":\"5617.45\", \"side\":\"BUY\", \"hash\":\"4a2cf56275b2c04fe746d3c0bb2a57df3e25128b\", \"best_bid\":\"0.72\", \"best_ask\":\"0.73\"}, {\"asset_id\":\"14766054693214075530629349735273995982307625376442606753688071083149620216746\", \"price\":\"0.99\", \"size\":\"5617.45\", \"side\":\"SELL\", \"hash\":\"2375b80bf7260ca66d603d43b5b6516e236c71d4\", \"best_bid\":\"0.27\", \"best_ask\":\"0.28\"}], \"timestamp\":\"1785130651914\", \"event_type\":\"price_change\"}","received_at":"2026-07-27T05:37:31.874321Z","schema_version":"clob-market-ws.price_change.v1","sequence":null,"server_hash":null,"server_timestamp":"1785130651914","session_id":"502006c5cfcd437296561ea750c9ec8b","source":"clob_market_ws"},"received_at":"2026-07-27T05:37:31.874321Z","record_id":"4587feb0624d1bbefafa889e6c5474bc5fb720f21db7e491ac93d3ab2b7a053b","schema_fingerprint":"4aa3821a28b0b7c2400bc59aba4bcc0a76e971dadd19610d3ad38c768e124dc7","schema_version":"edge-lab-recorder.raw.v1","sequence":null,"source":"clob_market_ws"}
{"event_at":"2026-07-27T05:37:31.985000Z","event_fingerprint":"cb7944352597cbc4066cbb921d2de7306acd3d15fde6ed5617d166bad0868a16","payload":{"connection_id":"efc69d3132f1467b8e898a382b23ac0d","event_at":"2026-07-27T05:37:31.985000Z","event_type":"price_change","frame_hash":"fe7b3215554690a13848587b0d22a686f0e22b5303cebc09bf8332c3480dc6f4","frame_index":0,"kind":"data","monotonic_ns":232635180188416,"payload":{"event_type":"price_change","market":"0x3b40066b5cf3871a2f6237c5628bd8092a206aa998558ac5ec13c4483e31e160","price_changes":[{"asset_id":"110216635572655435074987471276357323571387854733835379371586402147734167783946","best_ask":"0.73","best_bid":"0.72","hash":"5c0ca365c2cd1569b8444cd702281dc6e88908c3","price":"0.01","side":"BUY","size":"5622.45"},{"asset_id":"14766054693214075530629349735273995982307625376442606753688071083149620216746","best_ask":"0.28","best_bid":"0.27","hash":"03b4cd5e162ef0c27e1133fd3030647ab8727606","price":"0.99","side":"SELL","size":"5622.45"}],"timestamp":"1785130651985"},"payload_hash":"de059c0fc645fb45cf3d27e67f9db0445ba26c2da91479df70f20b7be5aab89a","raw_frame":"{\"market\":\"0x3b40066b5cf3871a2f6237c5628bd8092a206aa998558ac5ec13c4483e31e160\", \"price_changes\":[{\"asset_id\":\"110216635572655435074987471276357323571387854733835379371586402147734167783946\", \"price\":\"0.01\", \"size\":\"5622.45\", \"side\":\"BUY\", \"hash\":\"5c0ca365c2cd1569b8444cd702281dc6e88908c3\", \"best_bid\":\"0.72\", \"best_ask\":\"0.73\"}, {\"asset_id\":\"14766054693214075530629349735273995982307625376442606753688071083149620216746\", \"price\":\"0.99\", \"size\":\"5622.45\", \"side\":\"SELL\", \"hash\":\"03b4cd5e162ef0c27e1133fd3030647ab8727606\", \"best_bid\":\"0.27\", \"best_ask\":\"0.28\"}], \"timestamp\":\"1785130651985\", \"event_type\":\"price_change\"}","received_at":"2026-07-27T05:37:31.945118Z","schema_version":"clob-market-ws.price_change.v1","sequence":null,"server_hash":null,"server_timestamp":"1785130651985","session_id":"502006c5cfcd437296561ea750c9ec8b","source":"clob_market_ws"},"received_at":"2026-07-27T05:37:31.945118Z","record_id":"9d62aaf1ac660d6c2e4c3b3944a8cc7ed168108dd35f085306def81acca61b93","schema_fingerprint":"4aa3821a28b0b7c2400bc59aba4bcc0a76e971dadd19610d3ad38c768e124dc7","schema_version":"edge-lab-recorder.raw.v1","sequence":null,"source":"clob_market_ws"}
{"event_at":"2026-07-27T05:37:31.997000Z","event_fingerprint":"0312c0e78502d0634ece13a4333de7eb32f2266e4d212720d5361bc5f57a3a89","payload":{"connection_id":"efc69d3132f1467b8e898a382b23ac0d","event_at":"2026-07-27T05:37:31.997000Z","event_type":"price_change","frame_hash":"352921af9d63e71eec7d009c93124f2abc9a8eb1f33863f90999363d69dc6896","frame_index":0,"kind":"data","monotonic_ns":232635190676083,"payload":{"event_type":"price_change","market":"0x3b40066b5cf3871a2f6237c5628bd8092a206aa998558ac5ec13c4483e31e160","price_changes":[{"asset_id":"14766054693214075530629349735273995982307625376442606753688071083149620216746","best_ask":"0.28","best_bid":"0.27","hash":"a3bcd7df4ab7f818b78f1be3f4dfc119b3a57f6f","price":"0.3","side":"SELL","size":"45.06"},{"asset_id":"110216635572655435074987471276357323571387854733835379371586402147734167783946","best_ask":"0.73","best_bid":"0.72","hash":"3d1533e7f919c446549b63c9d803ce371c955f8c","price":"0.7","side":"BUY","size":"45.06"}],"timestamp":"1785130651997"},"payload_hash":"026a1ab115811c096c61b380617ace15954a14df4718def6671d635ff654316d","raw_frame":"{\"market\":\"0x3b40066b5cf3871a2f6237c5628bd8092a206aa998558ac5ec13c4483e31e160\", \"price_changes\":[{\"asset_id\":\"14766054693214075530629349735273995982307625376442606753688071083149620216746\", \"price\":\"0.3\", \"size\":\"45.06\", \"side\":\"SELL\", \"hash\":\"a3bcd7df4ab7f818b78f1be3f4dfc119b3a57f6f\", \"best_bid\":\"0.27\", \"best_ask\":\"0.28\"}, {\"asset_id\":\"110216635572655435074987471276357323571387854733835379371586402147734167783946\", \"price\":\"0.7\", \"size\":\"45.06\", \"side\":\"BUY\", \"hash\":\"3d1533e7f919c446549b63c9d803ce371c955f8c\", \"best_bid\":\"0.72\", \"best_ask\":\"0.73\"}], \"timestamp\":\"1785130651997\", \"event_type\":\"price_change\"}","received_at":"2026-07-27T05:37:31.955604Z","schema_version":"clob-market-ws.price_change.v1","sequence":null,"server_hash":null,"server_timestamp":"1785130651997","session_id":"502006c5cfcd437296561ea750c9ec8b","source":"clob_market_ws"},"received_at":"2026-07-27T05:37:31.955604Z","record_id":"81659d420c80fa0c72b2276cecc73b0fe82dc9f6677159fee0197ab7170ec8a9","schema_fingerprint":"4aa3821a28b0b7c2400bc59aba4bcc0a76e971dadd19610d3ad38c768e124dc7","schema_version":"edge-lab-recorder.raw.v1","sequence":null,"source":"clob_market_ws"}
{"event_at":"2026-07-27T05:37:32.000000Z","event_fingerprint":"fb6c65426c6a4056cf4b2ae1ff12ff84af36a24aaa4b0ab17e5ac30fbc5de625","payload":{"connection_id":"efc69d3132f1467b8e898a382b23ac0d","event_at":"2026-07-27T05:37:32.000000Z","event_type":"price_change","frame_hash":"8df6bbc7f157290307ca1b5e442b27f2cbd32a1b4239c860ac65dfecfd00b266","frame_index":0,"kind":"data","monotonic_ns":232635194742875,"payload":{"event_type":"price_change","market":"0x3b40066b5cf3871a2f6237c5628bd8092a206aa998558ac5ec13c4483e31e160","price_changes":[{"asset_id":"14766054693214075530629349735273995982307625376442606753688071083149620216746","best_ask":"0.28","best_bid":"0.27","hash":"d9f1580d7a9bca20d03c5877fa5aefcb4673df57","price":"0.31","side":"SELL","size":"121"},{"asset_id":"110216635572655435074987471276357323571387854733835379371586402147734167783946","best_ask":"0.73","best_bid":"0.72","hash":"1df6c00413aaea317e0dacc710ab1eb52bc63b89","price":"0.69","side":"BUY","size":"121"}],"timestamp":"1785130652000"},"payload_hash":"65aaa1d7b7175f3be742ddc3e5aca63606576c48ad87a9c2dea097cc1c2ae0a2","raw_frame":"{\"market\":\"0x3b40066b5cf3871a2f6237c5628bd8092a206aa998558ac5ec13c4483e31e160\", \"price_changes\":[{\"asset_id\":\"14766054693214075530629349735273995982307625376442606753688071083149620216746\", \"price\":\"0.31\", \"size\":\"121\", \"side\":\"SELL\", \"hash\":\"d9f1580d7a9bca20d03c5877fa5aefcb4673df57\", \"best_bid\":\"0.27\", \"best_ask\":\"0.28\"}, {\"asset_id\":\"110216635572655435074987471276357323571387854733835379371586402147734167783946\", \"price\":\"0.69\", \"size\":\"121\", \"side\":\"BUY\", \"hash\":\"1df6c00413aaea317e0dacc710ab1eb52bc63b89\", \"best_bid\":\"0.72\", \"best_ask\":\"0.73\"}], \"timestamp\":\"1785130652000\", \"event_type\":\"price_change\"}","received_at":"2026-07-27T05:37:31.959660Z","schema_version":"clob-market-ws.price_change.v1","sequence":null,"server_hash":null,"server_timestamp":"1785130652000","session_id":"502006c5cfcd437296561ea750c9ec8b","source":"clob_market_ws"},"received_at":"2026-07-27T05:37:31.959660Z","record_id":"50fe01a36b446066eddeb88ac4fda36cd6ceacb253cf99ebb8bfc3c56682b5e2","schema_fingerprint":"4aa3821a28b0b7c2400bc59aba4bcc0a76e971dadd19610d3ad38c768e124dc7","schema_version":"edge-lab-recorder.raw.v1","sequence":null,"source":"clob_market_ws"}
