{"event_at":null,"event_fingerprint":"3bc1bc2602e18b5fdfeef7329bca7340fb4b5ca1bf3da5615b0fb409d3f678c1","payload":{"connection_id":"efc69d3132f1467b8e898a382b23ac0d","detail":{"interval_seconds":10.0,"message":"PING"},"event_type":"heartbeat","kind":"lifecycle","monotonic_ns":231936273383666,"received_at":"2026-07-27T05:25:53.033452Z","schema_version":"edge-lab-recorder.lifecycle.v1","session_id":"502006c5cfcd437296561ea750c9ec8b","source":"clob_market_ws"},"received_at":"2026-07-27T05:25:53.033452Z","record_id":"466fdbea398847d5c31427fe7dbdd9f6345c342bb1f7224c491b89b2d2a7ccd8","schema_fingerprint":"cb8aa3aa4cb168a4b724fd9077bee6ecfb9bc586c57cfdf0ab89f00d82045e3c","schema_version":"edge-lab-recorder.raw.v1","sequence":null,"source":"clob_market_ws"}
{"event_at":null,"event_fingerprint":"c813d43baf8e10aaa1fc4162d5459f67d3898e397842f678858470500f451542","payload":{"connection_id":"efc69d3132f1467b8e898a382b23ac0d","event_type":"heartbeat_ack","frame_hash":"95784973cc639977bff93619700168505cb8f7855e44fa643d34622a43706c87","kind":"lifecycle","monotonic_ns":231936478271083,"raw_frame":"PONG","received_at":"2026-07-27T05:25:53.238342Z","schema_version":"edge-lab-recorder.heartbeat-ack.v1","session_id":"502006c5cfcd437296561ea750c9ec8b","source":"clob_market_ws"},"received_at":"2026-07-27T05:25:53.238342Z","record_id":"93008eba8af570f4ee361feb319d2c892326cc37f07fab119fdaf0c970d7a408","schema_fingerprint":"c14ee1aab3ca674ee738e5268877b544d74c41ad3c427cedc09236467dc68ba1","schema_version":"edge-lab-recorder.raw.v1","sequence":null,"source":"clob_market_ws"}
{"event_at":"2026-07-27T05:25:54.316000Z","event_fingerprint":"48e506e527e981f09b29239c13aa5984fe3af009e481ddf5d584074c900dfb8a","payload":{"connection_id":"efc69d3132f1467b8e898a382b23ac0d","event_at":"2026-07-27T05:25:54.316000Z","event_type":"price_change","frame_hash":"08bcc84c217d0a4708074ed532cc2852132f7037c23814c4a7ffea9ac03e9046","frame_index":0,"kind":"data","monotonic_ns":231937518717250,"payload":{"event_type":"price_change","market":"0x3b40066b5cf3871a2f6237c5628bd8092a206aa998558ac5ec13c4483e31e160","price_changes":[{"asset_id":"14766054693214075530629349735273995982307625376442606753688071083149620216746","best_ask":"0.48","best_bid":"0.47","hash":"dcd7f9f8596ef098ff258f1182cfc95049c282be","price":"0.44","side":"BUY","size":"255.68"},{"asset_id":"110216635572655435074987471276357323571387854733835379371586402147734167783946","best_ask":"0.53","best_bid":"0.52","hash":"7c9a9b3ce2c7e8c1eddcb063f6ba19b55a7aa8f6","price":"0.56","side":"SELL","size":"255.68"}],"timestamp":"1785129954316"},"payload_hash":"cdc7ad7d29c8d7d809f048fe5be36a59c89b36c386676db8b3176e11287394cc","raw_frame":"{\"market\":\"0x3b40066b5cf3871a2f6237c5628bd8092a206aa998558ac5ec13c4483e31e160\", \"price_changes\":[{\"asset_id\":\"14766054693214075530629349735273995982307625376442606753688071083149620216746\", \"price\":\"0.44\", \"size\":\"255.68\", \"side\":\"BUY\", \"hash\":\"dcd7f9f8596ef098ff258f1182cfc95049c282be\", \"best_bid\":\"0.47\", \"best_ask\":\"0.48\"}, {\"asset_id\":\"110216635572655435074987471276357323571387854733835379371586402147734167783946\", \"price\":\"0.56\", \"size\":\"255.68\", \"side\":\"SELL\", \"hash\":\"7c9a9b3ce2c7e8c1eddcb063f6ba19b55a7aa8f6\", \"best_bid\":\"0.52\", \"best_ask\":\"0.53\"}], \"timestamp\":\"1785129954316\", \"event_type\":\"price_change\"}","received_at":"2026-07-27T05:25:54.278793Z","schema_version":"clob-market-ws.price_change.v1","sequence":null,"server_hash":null,"server_timestamp":"1785129954316","session_id":"502006c5cfcd437296561ea750c9ec8b","source":"clob_market_ws"},"received_at":"2026-07-27T05:25:54.278793Z","record_id":"fa84375a4320eb03a9fcc6b6683577a2ed21ee257c9db294e1185f8a442f376c","schema_fingerprint":"4aa3821a28b0b7c2400bc59aba4bcc0a76e971dadd19610d3ad38c768e124dc7","schema_version":"edge-lab-recorder.raw.v1","sequence":null,"source":"clob_market_ws"}
{"event_at":"2026-07-27T05:25:54.320000Z","event_fingerprint":"d10467d60bd35603de0a3d575f1c0559bf8c2715a12583fdf1b87d6b0782b27d","payload":{"connection_id":"efc69d3132f1467b8e898a382b23ac0d","event_at":"2026-07-27T05:25:54.320000Z","event_type":"price_change","frame_hash":"ae0fdbac5ab31964e593d0b13bdcdce7c3e9f11319e888ca67554905075c8d5f","frame_index":0,"kind":"data","monotonic_ns":231937526239541,"payload":{"event_type":"price_change","market":"0x3b40066b5cf3871a2f6237c5628bd8092a206aa998558ac5ec13c4483e31e160","price_changes":[{"asset_id":"14766054693214075530629349735273995982307625376442606753688071083149620216746","best_ask":"0.48","best_bid":"0.47","hash":"6465d1bde241754a4ba98c2cadc90f2e8d36df48","price":"0.44","side":"BUY","size":"155.68"},{"asset_id":"110216635572655435074987471276357323571387854733835379371586402147734167783946","best_ask":"0.53","best_bid":"0.52","hash":"c421495c5f664188d5f8c28a4001860aed683924","price":"0.56","side":"SELL","size":"155.68"}],"timestamp":"1785129954320"},"payload_hash":"bd62ff235a2e4398f8f6bd6bab5a565d6ddaff757aece25204b611979f8966c6","raw_frame":"{\"market\":\"0x3b40066b5cf3871a2f6237c5628bd8092a206aa998558ac5ec13c4483e31e160\", \"price_changes\":[{\"asset_id\":\"14766054693214075530629349735273995982307625376442606753688071083149620216746\", \"price\":\"0.44\", \"size\":\"155.68\", \"side\":\"BUY\", \"hash\":\"6465d1bde241754a4ba98c2cadc90f2e8d36df48\", \"best_bid\":\"0.47\", \"best_ask\":\"0.48\"}, {\"asset_id\":\"110216635572655435074987471276357323571387854733835379371586402147734167783946\", \"price\":\"0.56\", \"size\":\"155.68\", \"side\":\"SELL\", \"hash\":\"c421495c5f664188d5f8c28a4001860aed683924\", \"best_bid\":\"0.52\", \"best_ask\":\"0.53\"}], \"timestamp\":\"1785129954320\", \"event_type\":\"price_change\"}","received_at":"2026-07-27T05:25:54.286316Z","schema_version":"clob-market-ws.price_change.v1","sequence":null,"server_hash":null,"server_timestamp":"1785129954320","session_id":"502006c5cfcd437296561ea750c9ec8b","source":"clob_market_ws"},"received_at":"2026-07-27T05:25:54.286316Z","record_id":"bec0b5d8b2ab38ab0ffde2f3f77d489876b8b830533896056d16fd12346d369e","schema_fingerprint":"4aa3821a28b0b7c2400bc59aba4bcc0a76e971dadd19610d3ad38c768e124dc7","schema_version":"edge-lab-recorder.raw.v1","sequence":null,"source":"clob_market_ws"}
{"event_at":"2026-07-27T05:25:54.362000Z","event_fingerprint":"9f37e263b4dd9b4c0abb4f434ae4f9b00fc4f43a4757444c160de8285c058580","payload":{"connection_id":"efc69d3132f1467b8e898a382b23ac0d","event_at":"2026-07-27T05:25:54.362000Z","event_type":"price_change","frame_hash":"173b937d19fe928d638d886f3e2e42d72fb278333d0150fec3dc59d7ad192cf4","frame_index":0,"kind":"data","monotonic_ns":231937563895708,"payload":{"event_type":"price_change","market":"0x3b40066b5cf3871a2f6237c5628bd8092a206aa998558ac5ec13c4483e31e160","price_changes":[{"asset_id":"14766054693214075530629349735273995982307625376442606753688071083149620216746","best_ask":"0.48","best_bid":"0.47","hash":"22279c4b8c64c7b54fc8a71382cf275f48ebb98d","price":"0.41","side":"BUY","size":"209.78"},{"asset_id":"110216635572655435074987471276357323571387854733835379371586402147734167783946","best_ask":"0.53","best_bid":"0.52","hash":"b2f378079cf09d7b46397e4db5bb8505ceb5a60a","price":"0.59","side":"SELL","size":"209.78"}],"timestamp":"1785129954362"},"payload_hash":"2a7240315fde866497831094f1b47b3a3250c71439cd2c9488ed34e48b3de483","raw_frame":"{\"market\":\"0x3b40066b5cf3871a2f6237c5628bd8092a206aa998558ac5ec13c4483e31e160\", \"price_changes\":[{\"asset_id\":\"14766054693214075530629349735273995982307625376442606753688071083149620216746\", \"price\":\"0.41\", \"size\":\"209.78\", \"side\":\"BUY\", \"hash\":\"22279c4b8c64c7b54fc8a71382cf275f48ebb98d\", \"best_bid\":\"0.47\", \"best_ask\":\"0.48\"}, {\"asset_id\":\"110216635572655435074987471276357323571387854733835379371586402147734167783946\", \"price\":\"0.59\", \"size\":\"209.78\", \"side\":\"SELL\", \"hash\":\"b2f378079cf09d7b46397e4db5bb8505ceb5a60a\", \"best_bid\":\"0.52\", \"best_ask\":\"0.53\"}], \"timestamp\":\"1785129954362\", \"event_type\":\"price_change\"}","received_at":"2026-07-27T05:25:54.323973Z","schema_version":"clob-market-ws.price_change.v1","sequence":null,"server_hash":null,"server_timestamp":"1785129954362","session_id":"502006c5cfcd437296561ea750c9ec8b","source":"clob_market_ws"},"received_at":"2026-07-27T05:25:54.323973Z","record_id":"a94828447f99b757fd71f31bd0acec60da89377147511da84b52374884286776","schema_fingerprint":"4aa3821a28b0b7c2400bc59aba4bcc0a76e971dadd19610d3ad38c768e124dc7","schema_version":"edge-lab-recorder.raw.v1","sequence":null,"source":"clob_market_ws"}
{"event_at":"2026-07-27T05:25:54.363000Z","event_fingerprint":"43f6e340c8e00f816755b6877261f6469b912335aa7c7366adeda699c7d97c5c","payload":{"connection_id":"efc69d3132f1467b8e898a382b23ac0d","event_at":"2026-07-27T05:25:54.363000Z","event_type":"price_change","frame_hash":"87f2edf262c5546b7eb44e3ac865253f080b8f629337f5364c3a5cb731bf09ac","frame_index":0,"kind":"data","monotonic_ns":231937567269750,"payload":{"event_type":"price_change","market":"0x3b40066b5cf3871a2f6237c5628bd8092a206aa998558ac5ec13c4483e31e160","price_changes":[{"asset_id":"14766054693214075530629349735273995982307625376442606753688071083149620216746","best_ask":"0.48","best_bid":"0.47","hash":"a5474658f38e660cb3e9c46bb7dbaae91fc89582","price":"0.41","side":"BUY","size":"214.78"},{"asset_id":"110216635572655435074987471276357323571387854733835379371586402147734167783946","best_ask":"0.53","best_bid":"0.52","hash":"8db41a7bf3790be37d9109c13870fd5c9aeb4f30","price":"0.59","side":"SELL","size":"214.78"}],"timestamp":"1785129954363"},"payload_hash":"7499a6b5780aa01f24b1ca231b8dab208dc7a3ffb51ccbbe5733f84bbe7f9b8f","raw_frame":"{\"market\":\"0x3b40066b5cf3871a2f6237c5628bd8092a206aa998558ac5ec13c4483e31e160\", \"price_changes\":[{\"asset_id\":\"14766054693214075530629349735273995982307625376442606753688071083149620216746\", \"price\":\"0.41\", \"size\":\"214.78\", \"side\":\"BUY\", \"hash\":\"a5474658f38e660cb3e9c46bb7dbaae91fc89582\", \"best_bid\":\"0.47\", \"best_ask\":\"0.48\"}, {\"asset_id\":\"110216635572655435074987471276357323571387854733835379371586402147734167783946\", \"price\":\"0.59\", \"size\":\"214.78\", \"side\":\"SELL\", \"hash\":\"8db41a7bf3790be37d9109c13870fd5c9aeb4f30\", \"best_bid\":\"0.52\", \"best_ask\":\"0.53\"}], \"timestamp\":\"1785129954363\", \"event_type\":\"price_change\"}","received_at":"2026-07-27T05:25:54.327348Z","schema_version":"clob-market-ws.price_change.v1","sequence":null,"server_hash":null,"server_timestamp":"1785129954363","session_id":"502006c5cfcd437296561ea750c9ec8b","source":"clob_market_ws"},"received_at":"2026-07-27T05:25:54.327348Z","record_id":"78c0891e71cbbf2c051034595f762df1bed04a10377b6e8b532a564d33152726","schema_fingerprint":"4aa3821a28b0b7c2400bc59aba4bcc0a76e971dadd19610d3ad38c768e124dc7","schema_version":"edge-lab-recorder.raw.v1","sequence":null,"source":"clob_market_ws"}
{"event_at":"2026-07-27T05:25:54.366000Z","event_fingerprint":"8c2c32285f97cf39fdcd910f182e36b8c18cf214b8fc1ab78dc1bec4f7215f4f","payload":{"connection_id":"efc69d3132f1467b8e898a382b23ac0d","event_at":"2026-07-27T05:25:54.366000Z","event_type":"price_change","frame_hash":"3affe3bc4e3e7907d591f05a8c0fe419701d785224b728fa6df3eda1b5d6392b","frame_index":0,"kind":"data","monotonic_ns":231937571240208,"payload":{"event_type":"price_change","market":"0x3b40066b5cf3871a2f6237c5628bd8092a206aa998558ac5ec13c4483e31e160","price_changes":[{"asset_id":"14766054693214075530629349735273995982307625376442606753688071083149620216746","best_ask":"0.48","best_bid":"0.47","hash":"7816ab30a320cd0f03483dc64d714b54747e197b","price":"0.41","side":"BUY","size":"219.78"},{"asset_id":"110216635572655435074987471276357323571387854733835379371586402147734167783946","best_ask":"0.53","best_bid":"0.52","hash":"8f19d752e257dd7951cfe55b3a6640a9866ba955","price":"0.59","side":"SELL","size":"219.78"}],"timestamp":"1785129954366"},"payload_hash":"7f67a4ca1b86e68154fb4842f51168d7c7e49a13b7da2bfcc6940f83ebbfef88","raw_frame":"{\"market\":\"0x3b40066b5cf3871a2f6237c5628bd8092a206aa998558ac5ec13c4483e31e160\", \"price_changes\":[{\"asset_id\":\"14766054693214075530629349735273995982307625376442606753688071083149620216746\", \"price\":\"0.41\", \"size\":\"219.78\", \"side\":\"BUY\", \"hash\":\"7816ab30a320cd0f03483dc64d714b54747e197b\", \"best_bid\":\"0.47\", \"best_ask\":\"0.48\"}, {\"asset_id\":\"110216635572655435074987471276357323571387854733835379371586402147734167783946\", \"price\":\"0.59\", \"size\":\"219.78\", \"side\":\"SELL\", \"hash\":\"8f19d752e257dd7951cfe55b3a6640a9866ba955\", \"best_bid\":\"0.52\", \"best_ask\":\"0.53\"}], \"timestamp\":\"1785129954366\", \"event_type\":\"price_change\"}","received_at":"2026-07-27T05:25:54.331316Z","schema_version":"clob-market-ws.price_change.v1","sequence":null,"server_hash":null,"server_timestamp":"1785129954366","session_id":"502006c5cfcd437296561ea750c9ec8b","source":"clob_market_ws"},"received_at":"2026-07-27T05:25:54.331316Z","record_id":"a7ec963cb097f0892765231d294bfc0bd8cd010fa361508b968ea88b6e7c4d8c","schema_fingerprint":"4aa3821a28b0b7c2400bc59aba4bcc0a76e971dadd19610d3ad38c768e124dc7","schema_version":"edge-lab-recorder.raw.v1","sequence":null,"source":"clob_market_ws"}
{"event_at":"2026-07-27T05:25:54.368000Z","event_fingerprint":"bc4a905eba25b3705dd7fc1f3fc6e7f1d041b68ee6f756586c8be169fbebd307","payload":{"connection_id":"efc69d3132f1467b8e898a382b23ac0d","event_at":"2026-07-27T05:25:54.368000Z","event_type":"price_change","frame_hash":"53f1e72fe4e2fcf6dc2797361d95b388c1564db63dbd158320bc9e6f71c4dbbe","frame_index":0,"kind":"data","monotonic_ns":231937573594333,"payload":{"event_type":"price_change","market":"0x3b40066b5cf3871a2f6237c5628bd8092a206aa998558ac5ec13c4483e31e160","price_changes":[{"asset_id":"14766054693214075530629349735273995982307625376442606753688071083149620216746","best_ask":"0.48","best_bid":"0.47","hash":"a4352abbc3c20b4706ab553e553b3625f215a90e","price":"0.41","side":"BUY","size":"224.78"},{"asset_id":"110216635572655435074987471276357323571387854733835379371586402147734167783946","best_ask":"0.53","best_bid":"0.52","hash":"929cf6341014669cc6afc921213d1d3fe3bcdfa1","price":"0.59","side":"SELL","size":"224.78"}],"timestamp":"1785129954368"},"payload_hash":"67bbde9cf5e849aadd8ecc08a0496b3ace610b2af7287a3d5f8ba28479f5cb16","raw_frame":"{\"market\":\"0x3b40066b5cf3871a2f6237c5628bd8092a206aa998558ac5ec13c4483e31e160\", \"price_changes\":[{\"asset_id\":\"14766054693214075530629349735273995982307625376442606753688071083149620216746\", \"price\":\"0.41\", \"size\":\"224.78\", \"side\":\"BUY\", \"hash\":\"a4352abbc3c20b4706ab553e553b3625f215a90e\", \"best_bid\":\"0.47\", \"best_ask\":\"0.48\"}, {\"asset_id\":\"110216635572655435074987471276357323571387854733835379371586402147734167783946\", \"price\":\"0.59\", \"size\":\"224.78\", \"side\":\"SELL\", \"hash\":\"929cf6341014669cc6afc921213d1d3fe3bcdfa1\", \"best_bid\":\"0.52\", \"best_ask\":\"0.53\"}], \"timestamp\":\"1785129954368\", \"event_type\":\"price_change\"}","received_at":"2026-07-27T05:25:54.333672Z","schema_version":"clob-market-ws.price_change.v1","sequence":null,"server_hash":null,"server_timestamp":"1785129954368","session_id":"502006c5cfcd437296561ea750c9ec8b","source":"clob_market_ws"},"received_at":"2026-07-27T05:25:54.333672Z","record_id":"ba1eacd937ef12a4f563eccd2b55e2afca397e9709de3469c1357f524c1a3cc0","schema_fingerprint":"4aa3821a28b0b7c2400bc59aba4bcc0a76e971dadd19610d3ad38c768e124dc7","schema_version":"edge-lab-recorder.raw.v1","sequence":null,"source":"clob_market_ws"}
{"event_at":"2026-07-27T05:25:54.371000Z","event_fingerprint":"a439d2ff4bd496913ec431b1046cdccca9589da1820e176bced76cc174926310","payload":{"connection_id":"efc69d3132f1467b8e898a382b23ac0d","event_at":"2026-07-27T05:25:54.371000Z","event_type":"price_change","frame_hash":"c683c83d2e14da82f4b218458c2c319fdc7c73120aba0fed3b59529633a2a8b5","frame_index":0,"kind":"data","monotonic_ns":231937575831458,"payload":{"event_type":"price_change","market":"0x3b40066b5cf3871a2f6237c5628bd8092a206aa998558ac5ec13c4483e31e160","price_changes":[{"asset_id":"14766054693214075530629349735273995982307625376442606753688071083149620216746","best_ask":"0.48","best_bid":"0.47","hash":"f786bb102a7433989860c72b244a55d043c65208","price":"0.41","side":"BUY","size":"229.78"},{"asset_id":"110216635572655435074987471276357323571387854733835379371586402147734167783946","best_ask":"0.53","best_bid":"0.52","hash":"c87c2407c9e51a646c91d6584604ed6ee3283cf7","price":"0.59","side":"SELL","size":"229.78"}],"timestamp":"1785129954371"},"payload_hash":"a42a7c89c86777e69477d63b5475b14c0484d44f503400ce367dd9f66a70ea3f","raw_frame":"{\"market\":\"0x3b40066b5cf3871a2f6237c5628bd8092a206aa998558ac5ec13c4483e31e160\", \"price_changes\":[{\"asset_id\":\"14766054693214075530629349735273995982307625376442606753688071083149620216746\", \"price\":\"0.41\", \"size\":\"229.78\", \"side\":\"BUY\", \"hash\":\"f786bb102a7433989860c72b244a55d043c65208\", \"best_bid\":\"0.47\", \"best_ask\":\"0.48\"}, {\"asset_id\":\"110216635572655435074987471276357323571387854733835379371586402147734167783946\", \"price\":\"0.59\", \"size\":\"229.78\", \"side\":\"SELL\", \"hash\":\"c87c2407c9e51a646c91d6584604ed6ee3283cf7\", \"best_bid\":\"0.52\", \"best_ask\":\"0.53\"}], \"timestamp\":\"1785129954371\", \"event_type\":\"price_change\"}","received_at":"2026-07-27T05:25:54.335909Z","schema_version":"clob-market-ws.price_change.v1","sequence":null,"server_hash":null,"server_timestamp":"1785129954371","session_id":"502006c5cfcd437296561ea750c9ec8b","source":"clob_market_ws"},"received_at":"2026-07-27T05:25:54.335909Z","record_id":"bcffdf45788109ddd081a2704da11614b4dfdbba1b90b2a02891a4ab04dd0559","schema_fingerprint":"4aa3821a28b0b7c2400bc59aba4bcc0a76e971dadd19610d3ad38c768e124dc7","schema_version":"edge-lab-recorder.raw.v1","sequence":null,"source":"clob_market_ws"}
{"event_at":"2026-07-27T05:25:54.374000Z","event_fingerprint":"49cba50e9b7a22423aaba82a2eec2e2a8de332a2c9b2cf7451b1de12896cbdc2","payload":{"connection_id":"efc69d3132f1467b8e898a382b23ac0d","event_at":"2026-07-27T05:25:54.374000Z","event_type":"price_change","frame_hash":"9bfb26ce8d24775d158734cf99d5d2d7f50899d60eb1742dd4a230767ee8b4a7","frame_index":0,"kind":"data","monotonic_ns":231937578692708,"payload":{"event_type":"price_change","market":"0x3b40066b5cf3871a2f6237c5628bd8092a206aa998558ac5ec13c4483e31e160","price_changes":[{"asset_id":"14766054693214075530629349735273995982307625376442606753688071083149620216746","best_ask":"0.48","best_bid":"0.47","hash":"5477d1a675cd4430aca286c0121cd035c8e8c5fc","price":"0.41","side":"BUY","size":"234.78"},{"asset_id":"110216635572655435074987471276357323571387854733835379371586402147734167783946","best_ask":"0.53","best_bid":"0.52","hash":"4661f5405cff03bc9a6c64478fc1a89164203cc1","price":"0.59","side":"SELL","size":"234.78"}],"timestamp":"1785129954374"},"payload_hash":"ae722157aa963f8baf0c82889742aaa5242ac8a49ae76e1356e06b250c3ab3e5","raw_frame":"{\"market\":\"0x3b40066b5cf3871a2f6237c5628bd8092a206aa998558ac5ec13c4483e31e160\", \"price_changes\":[{\"asset_id\":\"14766054693214075530629349735273995982307625376442606753688071083149620216746\", \"price\":\"0.41\", \"size\":\"234.78\", \"side\":\"BUY\", \"hash\":\"5477d1a675cd4430aca286c0121cd035c8e8c5fc\", \"best_bid\":\"0.47\", \"best_ask\":\"0.48\"}, {\"asset_id\":\"110216635572655435074987471276357323571387854733835379371586402147734167783946\", \"price\":\"0.59\", \"size\":\"234.78\", \"side\":\"SELL\", \"hash\":\"4661f5405cff03bc9a6c64478fc1a89164203cc1\", \"best_bid\":\"0.52\", \"best_ask\":\"0.53\"}], \"timestamp\":\"1785129954374\", \"event_type\":\"price_change\"}","received_at":"2026-07-27T05:25:54.338770Z","schema_version":"clob-market-ws.price_change.v1","sequence":null,"server_hash":null,"server_timestamp":"1785129954374","session_id":"502006c5cfcd437296561ea750c9ec8b","source":"clob_market_ws"},"received_at":"2026-07-27T05:25:54.338770Z","record_id":"6b9526a5d9635b7a27b14e80083f3838d46bcf542e1dc27d5fe74452e407b89e","schema_fingerprint":"4aa3821a28b0b7c2400bc59aba4bcc0a76e971dadd19610d3ad38c768e124dc7","schema_version":"edge-lab-recorder.raw.v1","sequence":null,"source":"clob_market_ws"}
{"event_at":"2026-07-27T05:25:54.375000Z","event_fingerprint":"d32d3b70b0082e080fdd273367c1f7066f9863002db1bc5bcb54683e12120ff8","payload":{"connection_id":"efc69d3132f1467b8e898a382b23ac0d","event_at":"2026-07-27T05:25:54.375000Z","event_type":"price_change","frame_hash":"16b9760ca44947074dff873831dea142a4e8fe7a0925846ce521e49309fe9d0e","frame_index":0,"kind":"data","monotonic_ns":231937581507166,"payload":{"event_type":"price_change","market":"0x3b40066b5cf3871a2f6237c5628bd8092a206aa998558ac5ec13c4483e31e160","price_changes":[{"asset_id":"14766054693214075530629349735273995982307625376442606753688071083149620216746","best_ask":"0.48","best_bid":"0.47","hash":"96cb17bf0de6438d6c225c3a5e41644b8941e7eb","price":"0.41","side":"BUY","size":"239.78"},{"asset_id":"110216635572655435074987471276357323571387854733835379371586402147734167783946","best_ask":"0.53","best_bid":"0.52","hash":"e14ef243a13152a4eb8468867b442e602b56715c","price":"0.59","side":"SELL","size":"239.78"}],"timestamp":"1785129954375"},"payload_hash":"3004deb8eccca53fb0e0a5cae0048e0c271c06129d81255a154fd9e7c4cddf45","raw_frame":"{\"market\":\"0x3b40066b5cf3871a2f6237c5628bd8092a206aa998558ac5ec13c4483e31e160\", \"price_changes\":[{\"asset_id\":\"14766054693214075530629349735273995982307625376442606753688071083149620216746\", \"price\":\"0.41\", \"size\":\"239.78\", \"side\":\"BUY\", \"hash\":\"96cb17bf0de6438d6c225c3a5e41644b8941e7eb\", \"best_bid\":\"0.47\", \"best_ask\":\"0.48\"}, {\"asset_id\":\"110216635572655435074987471276357323571387854733835379371586402147734167783946\", \"price\":\"0.59\", \"size\":\"239.78\", \"side\":\"SELL\", \"hash\":\"e14ef243a13152a4eb8468867b442e602b56715c\", \"best_bid\":\"0.52\", \"best_ask\":\"0.53\"}], \"timestamp\":\"1785129954375\", \"event_type\":\"price_change\"}","received_at":"2026-07-27T05:25:54.341585Z","schema_version":"clob-market-ws.price_change.v1","sequence":null,"server_hash":null,"server_timestamp":"1785129954375","session_id":"502006c5cfcd437296561ea750c9ec8b","source":"clob_market_ws"},"received_at":"2026-07-27T05:25:54.341585Z","record_id":"36cfff6ee3159ea5e7d4c7a7504a535e6ff9f1eb7286fa435e52e4b42871b6b2","schema_fingerprint":"4aa3821a28b0b7c2400bc59aba4bcc0a76e971dadd19610d3ad38c768e124dc7","schema_version":"edge-lab-recorder.raw.v1","sequence":null,"source":"clob_market_ws"}
{"event_at":"2026-07-27T05:25:54.376000Z","event_fingerprint":"83c84ca9dd79a5123ee5b6d9c852ea1cb9a1aaaf906a8f0cf0b262fbd9c2a653","payload":{"connection_id":"efc69d3132f1467b8e898a382b23ac0d","event_at":"2026-07-27T05:25:54.376000Z","event_type":"price_change","frame_hash":"cd7b08af96e19cb98b2072866c403b004a62a4249e9bfad9c589735de535c883","frame_index":0,"kind":"data","monotonic_ns":231937584317333,"payload":{"event_type":"price_change","market":"0x3b40066b5cf3871a2f6237c5628bd8092a206aa998558ac5ec13c4483e31e160","price_changes":[{"asset_id":"14766054693214075530629349735273995982307625376442606753688071083149620216746","best_ask":"0.48","best_bid":"0.47","hash":"8305f130b13cc820ecf294cef104c4e63f593b3c","price":"0.41","side":"BUY","size":"244.78"},{"asset_id":"110216635572655435074987471276357323571387854733835379371586402147734167783946","best_ask":"0.53","best_bid":"0.52","hash":"77bcb37322c023ecaa459140792e7c17ad0b9d2c","price":"0.59","side":"SELL","size":"244.78"}],"timestamp":"1785129954376"},"payload_hash":"5769862fc522c06249e9e6d2d015548e18443e2f1906b2d5b31ab2da7c981ae4","raw_frame":"{\"market\":\"0x3b40066b5cf3871a2f6237c5628bd8092a206aa998558ac5ec13c4483e31e160\", \"price_changes\":[{\"asset_id\":\"14766054693214075530629349735273995982307625376442606753688071083149620216746\", \"price\":\"0.41\", \"size\":\"244.78\", \"side\":\"BUY\", \"hash\":\"8305f130b13cc820ecf294cef104c4e63f593b3c\", \"best_bid\":\"0.47\", \"best_ask\":\"0.48\"}, {\"asset_id\":\"110216635572655435074987471276357323571387854733835379371586402147734167783946\", \"price\":\"0.59\", \"size\":\"244.78\", \"side\":\"SELL\", \"hash\":\"77bcb37322c023ecaa459140792e7c17ad0b9d2c\", \"best_bid\":\"0.52\", \"best_ask\":\"0.53\"}], \"timestamp\":\"1785129954376\", \"event_type\":\"price_change\"}","received_at":"2026-07-27T05:25:54.344396Z","schema_version":"clob-market-ws.price_change.v1","sequence":null,"server_hash":null,"server_timestamp":"1785129954376","session_id":"502006c5cfcd437296561ea750c9ec8b","source":"clob_market_ws"},"received_at":"2026-07-27T05:25:54.344396Z","record_id":"9f22fa380916d2168f8058f5385b8d26e911a7920f2a5527d4f4fc36534a1372","schema_fingerprint":"4aa3821a28b0b7c2400bc59aba4bcc0a76e971dadd19610d3ad38c768e124dc7","schema_version":"edge-lab-recorder.raw.v1","sequence":null,"source":"clob_market_ws"}
{"event_at":"2026-07-27T05:25:54.378000Z","event_fingerprint":"daa7e091be59a123d04b88b821d86c89b9032d565a8ca28201717e8d0708d806","payload":{"connection_id":"efc69d3132f1467b8e898a382b23ac0d","event_at":"2026-07-27T05:25:54.378000Z","event_type":"price_change","frame_hash":"3f2625c0a50959ed069c18a8a64cff2b49e31f6b42a97d35cc4a6f38bf78c179","frame_index":0,"kind":"data","monotonic_ns":231937710758500,"payload":{"event_type":"price_change","market":"0x3b40066b5cf3871a2f6237c5628bd8092a206aa998558ac5ec13c4483e31e160","price_changes":[{"asset_id":"14766054693214075530629349735273995982307625376442606753688071083149620216746","best_ask":"0.48","best_bid":"0.47","hash":"e4af50cf44aa0a06ca60d422bc449bacbaebe9d0","price":"0.41","side":"BUY","size":"249.78"},{"asset_id":"110216635572655435074987471276357323571387854733835379371586402147734167783946","best_ask":"0.53","best_bid":"0.52","hash":"16b6f9c707221828faa85ee7e76498705b9b2375","price":"0.59","side":"SELL","size":"249.78"}],"timestamp":"1785129954378"},"payload_hash":"6597c96a5158e65a643249bbfd958b8b83fa8978e1e39f173ed2b2a5d57074af","raw_frame":"{\"market\":\"0x3b40066b5cf3871a2f6237c5628bd8092a206aa998558ac5ec13c4483e31e160\", \"price_changes\":[{\"asset_id\":\"14766054693214075530629349735273995982307625376442606753688071083149620216746\", \"price\":\"0.41\", \"size\":\"249.78\", \"side\":\"BUY\", \"hash\":\"e4af50cf44aa0a06ca60d422bc449bacbaebe9d0\", \"best_bid\":\"0.47\", \"best_ask\":\"0.48\"}, {\"asset_id\":\"110216635572655435074987471276357323571387854733835379371586402147734167783946\", \"price\":\"0.59\", \"size\":\"249.78\", \"side\":\"SELL\", \"hash\":\"16b6f9c707221828faa85ee7e76498705b9b2375\", \"best_bid\":\"0.52\", \"best_ask\":\"0.53\"}], \"timestamp\":\"1785129954378\", \"event_type\":\"price_change\"}","received_at":"2026-07-27T05:25:54.470836Z","schema_version":"clob-market-ws.price_change.v1","sequence":null,"server_hash":null,"server_timestamp":"1785129954378","session_id":"502006c5cfcd437296561ea750c9ec8b","source":"clob_market_ws"},"received_at":"2026-07-27T05:25:54.470836Z","record_id":"a25585d59661f45867e08a0984d65f0c40797b4c5d5cba0cea0e25ce9f9af853","schema_fingerprint":"4aa3821a28b0b7c2400bc59aba4bcc0a76e971dadd19610d3ad38c768e124dc7","schema_version":"edge-lab-recorder.raw.v1","sequence":null,"source":"clob_market_ws"}
{"event_at":"2026-07-27T05:25:54.379000Z","event_fingerprint":"86c54daf174d5bc8d488c4f167dc1ae8d94a128181fcfdf33d943ca320ac04f1","payload":{"connection_id":"efc69d3132f1467b8e898a382b23ac0d","event_at":"2026-07-27T05:25:54.379000Z","event_type":"price_change","frame_hash":"753ec8f739762696478f00a1ffe3f6e6a388c63e15e031a2d0b0d5a7cffbae77","frame_index":0,"kind":"data","monotonic_ns":231937717549375,"payload":{"event_type":"price_change","market":"0x3b40066b5cf3871a2f6237c5628bd8092a206aa998558ac5ec13c4483e31e160","price_changes":[{"asset_id":"14766054693214075530629349735273995982307625376442606753688071083149620216746","best_ask":"0.48","best_bid":"0.47","hash":"f1f984aaf476b312cf83fe0fd5d962415cbc0cc3","price":"0.41","side":"BUY","size":"254.78"},{"asset_id":"110216635572655435074987471276357323571387854733835379371586402147734167783946","best_ask":"0.53","best_bid":"0.52","hash":"46e09f6c577822a070cf6f4da200a71521e71553","price":"0.59","side":"SELL","size":"254.78"}],"timestamp":"1785129954379"},"payload_hash":"0afedd2fef028758a7581e15456b0730bec6b0e77d1f146f1527637c6c9eb4d6","raw_frame":"{\"market\":\"0x3b40066b5cf3871a2f6237c5628bd8092a206aa998558ac5ec13c4483e31e160\", \"price_changes\":[{\"asset_id\":\"14766054693214075530629349735273995982307625376442606753688071083149620216746\", \"price\":\"0.41\", \"size\":\"254.78\", \"side\":\"BUY\", \"hash\":\"f1f984aaf476b312cf83fe0fd5d962415cbc0cc3\", \"best_bid\":\"0.47\", \"best_ask\":\"0.48\"}, {\"asset_id\":\"110216635572655435074987471276357323571387854733835379371586402147734167783946\", \"price\":\"0.59\", \"size\":\"254.78\", \"side\":\"SELL\", \"hash\":\"46e09f6c577822a070cf6f4da200a71521e71553\", \"best_bid\":\"0.52\", \"best_ask\":\"0.53\"}], \"timestamp\":\"1785129954379\", \"event_type\":\"price_change\"}","received_at":"2026-07-27T05:25:54.477628Z","schema_version":"clob-market-ws.price_change.v1","sequence":null,"server_hash":null,"server_timestamp":"1785129954379","session_id":"502006c5cfcd437296561ea750c9ec8b","source":"clob_market_ws"},"received_at":"2026-07-27T05:25:54.477628Z","record_id":"d350b3c5c09bcc4c7a002d97b8333ad0940f4b3076c052132f22a2eb76687947","schema_fingerprint":"4aa3821a28b0b7c2400bc59aba4bcc0a76e971dadd19610d3ad38c768e124dc7","schema_version":"edge-lab-recorder.raw.v1","sequence":null,"source":"clob_market_ws"}
{"event_at":"2026-07-27T05:25:54.380000Z","event_fingerprint":"585d685397ae5048c232d70a3a24ba20ec3d5c1a1b8ae22f46169ea9f5dd8ddf","payload":{"connection_id":"efc69d3132f1467b8e898a382b23ac0d","event_at":"2026-07-27T05:25:54.380000Z","event_type":"price_change","frame_hash":"1249e1592b36704373b34e1ad9a2f2daf00cf2c5bac838e2538d844938a63634","frame_index":0,"kind":"data","monotonic_ns":231937722210958,"payload":{"event_type":"price_change","market":"0x3b40066b5cf3871a2f6237c5628bd8092a206aa998558ac5ec13c4483e31e160","price_changes":[{"asset_id":"14766054693214075530629349735273995982307625376442606753688071083149620216746","best_ask":"0.48","best_bid":"0.47","hash":"751b951bfe92dd8d87c07d9eb79d9578b79f0f92","price":"0.41","side":"BUY","size":"259.78"},{"asset_id":"110216635572655435074987471276357323571387854733835379371586402147734167783946","best_ask":"0.53","best_bid":"0.52","hash":"cd060cf5194a45ecec979c0cc84b24c3cefb4f13","price":"0.59","side":"SELL","size":"259.78"}],"timestamp":"1785129954380"},"payload_hash":"2307ad3acaba59b2e3332e30a66dc9ef65f48a2ee7e4e2136b7cd1fa259323a0","raw_frame":"{\"market\":\"0x3b40066b5cf3871a2f6237c5628bd8092a206aa998558ac5ec13c4483e31e160\", \"price_changes\":[{\"asset_id\":\"14766054693214075530629349735273995982307625376442606753688071083149620216746\", \"price\":\"0.41\", \"size\":\"259.78\", \"side\":\"BUY\", \"hash\":\"751b951bfe92dd8d87c07d9eb79d9578b79f0f92\", \"best_bid\":\"0.47\", \"best_ask\":\"0.48\"}, {\"asset_id\":\"110216635572655435074987471276357323571387854733835379371586402147734167783946\", \"price\":\"0.59\", \"size\":\"259.78\", \"side\":\"SELL\", \"hash\":\"cd060cf5194a45ecec979c0cc84b24c3cefb4f13\", \"best_bid\":\"0.52\", \"best_ask\":\"0.53\"}], \"timestamp\":\"1785129954380\", \"event_type\":\"price_change\"}","received_at":"2026-07-27T05:25:54.482290Z","schema_version":"clob-market-ws.price_change.v1","sequence":null,"server_hash":null,"server_timestamp":"1785129954380","session_id":"502006c5cfcd437296561ea750c9ec8b","source":"clob_market_ws"},"received_at":"2026-07-27T05:25:54.482290Z","record_id":"b1297b9ee8a5eb8e5924bb527ad70d10821232e0304f35c7dd165f2b9af71335","schema_fingerprint":"4aa3821a28b0b7c2400bc59aba4bcc0a76e971dadd19610d3ad38c768e124dc7","schema_version":"edge-lab-recorder.raw.v1","sequence":null,"source":"clob_market_ws"}
{"event_at":"2026-07-27T05:25:54.382000Z","event_fingerprint":"6fff899ee012ec97fc9e67a7bff684d5b1cf06ad003bf6054ca473936d5730ed","payload":{"connection_id":"efc69d3132f1467b8e898a382b23ac0d","event_at":"2026-07-27T05:25:54.382000Z","event_type":"price_change","frame_hash":"f89c42e0c0145b9d67e3f956e9e76cdbd4d6ecad9228c2cf75cb4eb9265a3bf3","frame_index":0,"kind":"data","monotonic_ns":231937730190750,"payload":{"event_type":"price_change","market":"0x3b40066b5cf3871a2f6237c5628bd8092a206aa998558ac5ec13c4483e31e160","price_changes":[{"asset_id":"14766054693214075530629349735273995982307625376442606753688071083149620216746","best_ask":"0.48","best_bid":"0.47","hash":"14c5b9751794e84309317be26d5ec50f0b6f5347","price":"0.41","side":"BUY","size":"264.78"},{"asset_id":"110216635572655435074987471276357323571387854733835379371586402147734167783946","best_ask":"0.53","best_bid":"0.52","hash":"6e06324052d241682f319ce43ae84e71dd3819a1","price":"0.59","side":"SELL","size":"264.78"}],"timestamp":"1785129954382"},"payload_hash":"63d13854f896c4a78eac871269e6a1193b0549f8c54ec9e86d00174f7a4aa798","raw_frame":"{\"market\":\"0x3b40066b5cf3871a2f6237c5628bd8092a206aa998558ac5ec13c4483e31e160\", \"price_changes\":[{\"asset_id\":\"14766054693214075530629349735273995982307625376442606753688071083149620216746\", \"price\":\"0.41\", \"size\":\"264.78\", \"side\":\"BUY\", \"hash\":\"14c5b9751794e84309317be26d5ec50f0b6f5347\", \"best_bid\":\"0.47\", \"best_ask\":\"0.48\"}, {\"asset_id\":\"110216635572655435074987471276357323571387854733835379371586402147734167783946\", \"price\":\"0.59\", \"size\":\"264.78\", \"side\":\"SELL\", \"hash\":\"6e06324052d241682f319ce43ae84e71dd3819a1\", \"best_bid\":\"0.52\", \"best_ask\":\"0.53\"}], \"timestamp\":\"1785129954382\", \"event_type\":\"price_change\"}","received_at":"2026-07-27T05:25:54.490270Z","schema_version":"clob-market-ws.price_change.v1","sequence":null,"server_hash":null,"server_timestamp":"1785129954382","session_id":"502006c5cfcd437296561ea750c9ec8b","source":"clob_market_ws"},"received_at":"2026-07-27T05:25:54.490270Z","record_id":"6ef4349e965412903d09a8b5898f991062c27c4a530eed5c04159f461b01dfc3","schema_fingerprint":"4aa3821a28b0b7c2400bc59aba4bcc0a76e971dadd19610d3ad38c768e124dc7","schema_version":"edge-lab-recorder.raw.v1","sequence":null,"source":"clob_market_ws"}
{"event_at":"2026-07-27T05:25:54.383000Z","event_fingerprint":"edf34dd335612514f96b7ed1c33b85bd8c16b556feafde5a1bb0ea328998f5c4","payload":{"connection_id":"efc69d3132f1467b8e898a382b23ac0d","event_at":"2026-07-27T05:25:54.383000Z","event_type":"price_change","frame_hash":"d60a3de5ec9c39c4ad6cfca8310ce3fcd55ba2d646594060c0a049fe89c69ffc","frame_index":0,"kind":"data","monotonic_ns":231937735267750,"payload":{"event_type":"price_change","market":"0x3b40066b5cf3871a2f6237c5628bd8092a206aa998558ac5ec13c4483e31e160","price_changes":[{"asset_id":"14766054693214075530629349735273995982307625376442606753688071083149620216746","best_ask":"0.48","best_bid":"0.47","hash":"c0a6df97da773c658f8c68eb8a4bee73be79621a","price":"0.41","side":"BUY","size":"269.78"},{"asset_id":"110216635572655435074987471276357323571387854733835379371586402147734167783946","best_ask":"0.53","best_bid":"0.52","hash":"7226ef5e6c57ec96f7a2a095f65fe879477cf7da","price":"0.59","side":"SELL","size":"269.78"}],"timestamp":"1785129954383"},"payload_hash":"c929624b27f25fd6cdd78a026d12bf2d4da7c0c956eb6bba1a2ddcd5aa62e5c6","raw_frame":"{\"market\":\"0x3b40066b5cf3871a2f6237c5628bd8092a206aa998558ac5ec13c4483e31e160\", \"price_changes\":[{\"asset_id\":\"14766054693214075530629349735273995982307625376442606753688071083149620216746\", \"price\":\"0.41\", \"size\":\"269.78\", \"side\":\"BUY\", \"hash\":\"c0a6df97da773c658f8c68eb8a4bee73be79621a\", \"best_bid\":\"0.47\", \"best_ask\":\"0.48\"}, {\"asset_id\":\"110216635572655435074987471276357323571387854733835379371586402147734167783946\", \"price\":\"0.59\", \"size\":\"269.78\", \"side\":\"SELL\", \"hash\":\"7226ef5e6c57ec96f7a2a095f65fe879477cf7da\", \"best_bid\":\"0.52\", \"best_ask\":\"0.53\"}], \"timestamp\":\"1785129954383\", \"event_type\":\"price_change\"}","received_at":"2026-07-27T05:25:54.495346Z","schema_version":"clob-market-ws.price_change.v1","sequence":null,"server_hash":null,"server_timestamp":"1785129954383","session_id":"502006c5cfcd437296561ea750c9ec8b","source":"clob_market_ws"},"received_at":"2026-07-27T05:25:54.495346Z","record_id":"ca75466f370fe40149870562e5780aafea93bbb2028def1e9c0cecddd4f836fc","schema_fingerprint":"4aa3821a28b0b7c2400bc59aba4bcc0a76e971dadd19610d3ad38c768e124dc7","schema_version":"edge-lab-recorder.raw.v1","sequence":null,"source":"clob_market_ws"}
{"event_at":"2026-07-27T05:25:54.384000Z","event_fingerprint":"a5576379bd8083b515aa989f53e717019e789292c9a0660e2cd1914a1bc5de44","payload":{"connection_id":"efc69d3132f1467b8e898a382b23ac0d","event_at":"2026-07-27T05:25:54.384000Z","event_type":"price_change","frame_hash":"0482dce7c8e3cf354a5d7cf784f07c7110cf3f18761e17fd352505d5ce05b851","frame_index":0,"kind":"data","monotonic_ns":231937738082125,"payload":{"event_type":"price_change","market":"0x3b40066b5cf3871a2f6237c5628bd8092a206aa998558ac5ec13c4483e31e160","price_changes":[{"asset_id":"14766054693214075530629349735273995982307625376442606753688071083149620216746","best_ask":"0.48","best_bid":"0.47","hash":"6f12191c9914bc3572a5daa4c94c1e5aece388d9","price":"0.41","side":"BUY","size":"274.78"},{"asset_id":"110216635572655435074987471276357323571387854733835379371586402147734167783946","best_ask":"0.53","best_bid":"0.52","hash":"839c1dc2f18c95a30589b39b59733111c2661102","price":"0.59","side":"SELL","size":"274.78"}],"timestamp":"1785129954384"},"payload_hash":"4bc2fe1a32a3e5aeaa9aef4ad1d22be5d4331f801d109641807e9132ce63cec2","raw_frame":"{\"market\":\"0x3b40066b5cf3871a2f6237c5628bd8092a206aa998558ac5ec13c4483e31e160\", \"price_changes\":[{\"asset_id\":\"14766054693214075530629349735273995982307625376442606753688071083149620216746\", \"price\":\"0.41\", \"size\":\"274.78\", \"side\":\"BUY\", \"hash\":\"6f12191c9914bc3572a5daa4c94c1e5aece388d9\", \"best_bid\":\"0.47\", \"best_ask\":\"0.48\"}, {\"asset_id\":\"110216635572655435074987471276357323571387854733835379371586402147734167783946\", \"price\":\"0.59\", \"size\":\"274.78\", \"side\":\"SELL\", \"hash\":\"839c1dc2f18c95a30589b39b59733111c2661102\", \"best_bid\":\"0.52\", \"best_ask\":\"0.53\"}], \"timestamp\":\"1785129954384\", \"event_type\":\"price_change\"}","received_at":"2026-07-27T05:25:54.498161Z","schema_version":"clob-market-ws.price_change.v1","sequence":null,"server_hash":null,"server_timestamp":"1785129954384","session_id":"502006c5cfcd437296561ea750c9ec8b","source":"clob_market_ws"},"received_at":"2026-07-27T05:25:54.498161Z","record_id":"3dd54c507face10c23362370d168e34fb4033542c49ce076de69c4e5e2e9de2a","schema_fingerprint":"4aa3821a28b0b7c2400bc59aba4bcc0a76e971dadd19610d3ad38c768e124dc7","schema_version":"edge-lab-recorder.raw.v1","sequence":null,"source":"clob_market_ws"}
{"event_at":"2026-07-27T05:25:54.385000Z","event_fingerprint":"e65990bc2d5edc993f35e16c1cac95b739f9fb7ad51443516a46d01f1061df0b","payload":{"connection_id":"efc69d3132f1467b8e898a382b23ac0d","event_at":"2026-07-27T05:25:54.385000Z","event_type":"price_change","frame_hash":"58b28d25f4017467ace0e03d86992d3b75254a810ff560c7c8cca4455d773260","frame_index":0,"kind":"data","monotonic_ns":231937740658375,"payload":{"event_type":"price_change","market":"0x3b40066b5cf3871a2f6237c5628bd8092a206aa998558ac5ec13c4483e31e160","price_changes":[{"asset_id":"14766054693214075530629349735273995982307625376442606753688071083149620216746","best_ask":"0.48","best_bid":"0.47","hash":"873352385a5385fb9124bfa9722dc2208c3d30a7","price":"0.41","side":"BUY","size":"279.78"},{"asset_id":"110216635572655435074987471276357323571387854733835379371586402147734167783946","best_ask":"0.53","best_bid":"0.52","hash":"c074b1302ef640588c124f17bc121df622e6873a","price":"0.59","side":"SELL","size":"279.78"}],"timestamp":"1785129954385"},"payload_hash":"56a01ad36e31bb32ba56f482ae34c2765b5f67429fa7f016e62eb691e83151a2","raw_frame":"{\"market\":\"0x3b40066b5cf3871a2f6237c5628bd8092a206aa998558ac5ec13c4483e31e160\", \"price_changes\":[{\"asset_id\":\"14766054693214075530629349735273995982307625376442606753688071083149620216746\", \"price\":\"0.41\", \"size\":\"279.78\", \"side\":\"BUY\", \"hash\":\"873352385a5385fb9124bfa9722dc2208c3d30a7\", \"best_bid\":\"0.47\", \"best_ask\":\"0.48\"}, {\"asset_id\":\"110216635572655435074987471276357323571387854733835379371586402147734167783946\", \"price\":\"0.59\", \"size\":\"279.78\", \"side\":\"SELL\", \"hash\":\"c074b1302ef640588c124f17bc121df622e6873a\", \"best_bid\":\"0.52\", \"best_ask\":\"0.53\"}], \"timestamp\":\"1785129954385\", \"event_type\":\"price_change\"}","received_at":"2026-07-27T05:25:54.500738Z","schema_version":"clob-market-ws.price_change.v1","sequence":null,"server_hash":null,"server_timestamp":"1785129954385","session_id":"502006c5cfcd437296561ea750c9ec8b","source":"clob_market_ws"},"received_at":"2026-07-27T05:25:54.500738Z","record_id":"f43b5e2a54d4214ffdab62b17134466580c825e04efbafe893326a74dbdda609","schema_fingerprint":"4aa3821a28b0b7c2400bc59aba4bcc0a76e971dadd19610d3ad38c768e124dc7","schema_version":"edge-lab-recorder.raw.v1","sequence":null,"source":"clob_market_ws"}
{"event_at":"2026-07-27T05:25:54.387000Z","event_fingerprint":"d75a0f278aa1574d45bcd4e03ac8209199f2a47845a324e9582c5fde9cc5eb28","payload":{"connection_id":"efc69d3132f1467b8e898a382b23ac0d","event_at":"2026-07-27T05:25:54.387000Z","event_type":"price_change","frame_hash":"376acca202d7d98cfaab95bfb4f6238a963807e4a99107e6264782f64e911f41","frame_index":0,"kind":"data","monotonic_ns":231937744539083,"payload":{"event_type":"price_change","market":"0x3b40066b5cf3871a2f6237c5628bd8092a206aa998558ac5ec13c4483e31e160","price_changes":[{"asset_id":"14766054693214075530629349735273995982307625376442606753688071083149620216746","best_ask":"0.48","best_bid":"0.47","hash":"2153ebd909782bb75b9ea37329a726e2f3284610","price":"0.41","side":"BUY","size":"284.78"},{"asset_id":"110216635572655435074987471276357323571387854733835379371586402147734167783946","best_ask":"0.53","best_bid":"0.52","hash":"716439e04db30adfd94ef614498c7eeb7661a924","price":"0.59","side":"SELL","size":"284.78"}],"timestamp":"1785129954387"},"payload_hash":"16484257066bb8f63927c494202dd8da7371e60c99583de19978fabae75a62f2","raw_frame":"{\"market\":\"0x3b40066b5cf3871a2f6237c5628bd8092a206aa998558ac5ec13c4483e31e160\", \"price_changes\":[{\"asset_id\":\"14766054693214075530629349735273995982307625376442606753688071083149620216746\", \"price\":\"0.41\", \"size\":\"284.78\", \"side\":\"BUY\", \"hash\":\"2153ebd909782bb75b9ea37329a726e2f3284610\", \"best_bid\":\"0.47\", \"best_ask\":\"0.48\"}, {\"asset_id\":\"110216635572655435074987471276357323571387854733835379371586402147734167783946\", \"price\":\"0.59\", \"size\":\"284.78\", \"side\":\"SELL\", \"hash\":\"716439e04db30adfd94ef614498c7eeb7661a924\", \"best_bid\":\"0.52\", \"best_ask\":\"0.53\"}], \"timestamp\":\"1785129954387\", \"event_type\":\"price_change\"}","received_at":"2026-07-27T05:25:54.504617Z","schema_version":"clob-market-ws.price_change.v1","sequence":null,"server_hash":null,"server_timestamp":"1785129954387","session_id":"502006c5cfcd437296561ea750c9ec8b","source":"clob_market_ws"},"received_at":"2026-07-27T05:25:54.504617Z","record_id":"b41cc848c9d90cc7407bbe1978280d8ee616c78cd2b9d6773f82e42864356218","schema_fingerprint":"4aa3821a28b0b7c2400bc59aba4bcc0a76e971dadd19610d3ad38c768e124dc7","schema_version":"edge-lab-recorder.raw.v1","sequence":null,"source":"clob_market_ws"}
{"event_at":"2026-07-27T05:25:54.388000Z","event_fingerprint":"5f1b6b1d4179cd7021a274c30e3dc4245c623f6b27854f9bca873d0be40eb2e7","payload":{"connection_id":"efc69d3132f1467b8e898a382b23ac0d","event_at":"2026-07-27T05:25:54.388000Z","event_type":"price_change","frame_hash":"5da7d1887fa52cf88ceffb096a40dafe95dfb5e790a6f5c12d7d30af54b962cb","frame_index":0,"kind":"data","monotonic_ns":231937749016708,"payload":{"event_type":"price_change","market":"0x3b40066b5cf3871a2f6237c5628bd8092a206aa998558ac5ec13c4483e31e160","price_changes":[{"asset_id":"14766054693214075530629349735273995982307625376442606753688071083149620216746","best_ask":"0.48","best_bid":"0.47","hash":"f1624762c5785c3a05e4ebbc3d3e24bc680ec8ea","price":"0.41","side":"BUY","size":"289.78"},{"asset_id":"110216635572655435074987471276357323571387854733835379371586402147734167783946","best_ask":"0.53","best_bid":"0.52","hash":"ce8a4a02a0a95ddcb61a16d101dda93a8aabe868","price":"0.59","side":"SELL","size":"289.78"}],"timestamp":"1785129954388"},"payload_hash":"85a920ff580e70d27e9eeab53de7e6ad126878411bc72a2b88e70341365a5ebc","raw_frame":"{\"market\":\"0x3b40066b5cf3871a2f6237c5628bd8092a206aa998558ac5ec13c4483e31e160\", \"price_changes\":[{\"asset_id\":\"14766054693214075530629349735273995982307625376442606753688071083149620216746\", \"price\":\"0.41\", \"size\":\"289.78\", \"side\":\"BUY\", \"hash\":\"f1624762c5785c3a05e4ebbc3d3e24bc680ec8ea\", \"best_bid\":\"0.47\", \"best_ask\":\"0.48\"}, {\"asset_id\":\"110216635572655435074987471276357323571387854733835379371586402147734167783946\", \"price\":\"0.59\", \"size\":\"289.78\", \"side\":\"SELL\", \"hash\":\"ce8a4a02a0a95ddcb61a16d101dda93a8aabe868\", \"best_bid\":\"0.52\", \"best_ask\":\"0.53\"}], \"timestamp\":\"1785129954388\", \"event_type\":\"price_change\"}","received_at":"2026-07-27T05:25:54.509096Z","schema_version":"clob-market-ws.price_change.v1","sequence":null,"server_hash":null,"server_timestamp":"1785129954388","session_id":"502006c5cfcd437296561ea750c9ec8b","source":"clob_market_ws"},"received_at":"2026-07-27T05:25:54.509096Z","record_id":"a3554674229ee9e50b2053048ac36112ce0f6201101d0cbee9e5c9b96880337e","schema_fingerprint":"4aa3821a28b0b7c2400bc59aba4bcc0a76e971dadd19610d3ad38c768e124dc7","schema_version":"edge-lab-recorder.raw.v1","sequence":null,"source":"clob_market_ws"}
{"event_at":"2026-07-27T05:25:54.391000Z","event_fingerprint":"bce8cf54d2629f59bb70a00cff45e36e259d5aa8b63c49fdb3f7d1b0749e5151","payload":{"connection_id":"efc69d3132f1467b8e898a382b23ac0d","event_at":"2026-07-27T05:25:54.391000Z","event_type":"price_change","frame_hash":"a1a6e526531146525195e134ff91948187bde2e7abdf9110db6eb13577248a4a","frame_index":0,"kind":"data","monotonic_ns":231937753696583,"payload":{"event_type":"price_change","market":"0x3b40066b5cf3871a2f6237c5628bd8092a206aa998558ac5ec13c4483e31e160","price_changes":[{"asset_id":"14766054693214075530629349735273995982307625376442606753688071083149620216746","best_ask":"0.48","best_bid":"0.47","hash":"397b958bbd4a58a6ed9ed307e0a968149efe5a4d","price":"0.41","side":"BUY","size":"294.78"},{"asset_id":"110216635572655435074987471276357323571387854733835379371586402147734167783946","best_ask":"0.53","best_bid":"0.52","hash":"1ce87895b0be60e509457f706ad4a91bf07bf9b1","price":"0.59","side":"SELL","size":"294.78"}],"timestamp":"1785129954391"},"payload_hash":"bbfd8b10f497d3ebeca7a06044db57b2b45021eb3fa6bc4f2f88926b2df817a8","raw_frame":"{\"market\":\"0x3b40066b5cf3871a2f6237c5628bd8092a206aa998558ac5ec13c4483e31e160\", \"price_changes\":[{\"asset_id\":\"14766054693214075530629349735273995982307625376442606753688071083149620216746\", \"price\":\"0.41\", \"size\":\"294.78\", \"side\":\"BUY\", \"hash\":\"397b958bbd4a58a6ed9ed307e0a968149efe5a4d\", \"best_bid\":\"0.47\", \"best_ask\":\"0.48\"}, {\"asset_id\":\"110216635572655435074987471276357323571387854733835379371586402147734167783946\", \"price\":\"0.59\", \"size\":\"294.78\", \"side\":\"SELL\", \"hash\":\"1ce87895b0be60e509457f706ad4a91bf07bf9b1\", \"best_bid\":\"0.52\", \"best_ask\":\"0.53\"}], \"timestamp\":\"1785129954391\", \"event_type\":\"price_change\"}","received_at":"2026-07-27T05:25:54.513782Z","schema_version":"clob-market-ws.price_change.v1","sequence":null,"server_hash":null,"server_timestamp":"1785129954391","session_id":"502006c5cfcd437296561ea750c9ec8b","source":"clob_market_ws"},"received_at":"2026-07-27T05:25:54.513782Z","record_id":"a5d70b34b4c4140cd8fb1c47122d028ec6f3722c21294a86b4f25f15b81d8604","schema_fingerprint":"4aa3821a28b0b7c2400bc59aba4bcc0a76e971dadd19610d3ad38c768e124dc7","schema_version":"edge-lab-recorder.raw.v1","sequence":null,"source":"clob_market_ws"}
{"event_at":"2026-07-27T05:25:54.394000Z","event_fingerprint":"6468ad0de828e664c66845f84da2d2407a1f3e7ee434818eec3d141c14c5afcd","payload":{"connection_id":"efc69d3132f1467b8e898a382b23ac0d","event_at":"2026-07-27T05:25:54.394000Z","event_type":"price_change","frame_hash":"a0db98c201d119b17e91ac73e3d2c79bbc53b6c80c4f04ffc59f91a0d222cd64","frame_index":0,"kind":"data","monotonic_ns":231937757552875,"payload":{"event_type":"price_change","market":"0x3b40066b5cf3871a2f6237c5628bd8092a206aa998558ac5ec13c4483e31e160","price_changes":[{"asset_id":"14766054693214075530629349735273995982307625376442606753688071083149620216746","best_ask":"0.48","best_bid":"0.47","hash":"2894ff66fab5f5c0167d01656b40e53be5f4b1ef","price":"0.41","side":"BUY","size":"299.78"},{"asset_id":"110216635572655435074987471276357323571387854733835379371586402147734167783946","best_ask":"0.53","best_bid":"0.52","hash":"4d8d43d6e6b2b5fd69dd1b56b46be7e5b790cbbd","price":"0.59","side":"SELL","size":"299.78"}],"timestamp":"1785129954394"},"payload_hash":"e0c49e897a6b61b9d1b53e3dc761d853bf4cc3e09ff7f80f464b2ffeaf14972f","raw_frame":"{\"market\":\"0x3b40066b5cf3871a2f6237c5628bd8092a206aa998558ac5ec13c4483e31e160\", \"price_changes\":[{\"asset_id\":\"14766054693214075530629349735273995982307625376442606753688071083149620216746\", \"price\":\"0.41\", \"size\":\"299.78\", \"side\":\"BUY\", \"hash\":\"2894ff66fab5f5c0167d01656b40e53be5f4b1ef\", \"best_bid\":\"0.47\", \"best_ask\":\"0.48\"}, {\"asset_id\":\"110216635572655435074987471276357323571387854733835379371586402147734167783946\", \"price\":\"0.59\", \"size\":\"299.78\", \"side\":\"SELL\", \"hash\":\"4d8d43d6e6b2b5fd69dd1b56b46be7e5b790cbbd\", \"best_bid\":\"0.52\", \"best_ask\":\"0.53\"}], \"timestamp\":\"1785129954394\", \"event_type\":\"price_change\"}","received_at":"2026-07-27T05:25:54.517633Z","schema_version":"clob-market-ws.price_change.v1","sequence":null,"server_hash":null,"server_timestamp":"1785129954394","session_id":"502006c5cfcd437296561ea750c9ec8b","source":"clob_market_ws"},"received_at":"2026-07-27T05:25:54.517633Z","record_id":"fab73d83c4d58ce855cfe74b47fa1557367eb8f32d10a5cea7d3e8f5beea93a7","schema_fingerprint":"4aa3821a28b0b7c2400bc59aba4bcc0a76e971dadd19610d3ad38c768e124dc7","schema_version":"edge-lab-recorder.raw.v1","sequence":null,"source":"clob_market_ws"}
{"event_at":"2026-07-27T05:25:54.395000Z","event_fingerprint":"bc19ab15bcf71cb1ce0fee74b462cb4693ed2310fc12fe53979e97e9bc04b625","payload":{"connection_id":"efc69d3132f1467b8e898a382b23ac0d","event_at":"2026-07-27T05:25:54.395000Z","event_type":"price_change","frame_hash":"44535d3a22a7a328c3741003fd39a999134a33d0120e00eff31b0a44b1824386","frame_index":0,"kind":"data","monotonic_ns":231937759511500,"payload":{"event_type":"price_change","market":"0x3b40066b5cf3871a2f6237c5628bd8092a206aa998558ac5ec13c4483e31e160","price_changes":[{"asset_id":"14766054693214075530629349735273995982307625376442606753688071083149620216746","best_ask":"0.48","best_bid":"0.47","hash":"474d55b2a0e931fb844104807b182f466ef73f4d","price":"0.41","side":"BUY","size":"304.78"},{"asset_id":"110216635572655435074987471276357323571387854733835379371586402147734167783946","best_ask":"0.53","best_bid":"0.52","hash":"1f5e5af59814bf610201258e56533568e3d32da8","price":"0.59","side":"SELL","size":"304.78"}],"timestamp":"1785129954395"},"payload_hash":"b52de8407c31b7d40189f1b1a5fe9a3a38553b956850898ec5db6fc341affad5","raw_frame":"{\"market\":\"0x3b40066b5cf3871a2f6237c5628bd8092a206aa998558ac5ec13c4483e31e160\", \"price_changes\":[{\"asset_id\":\"14766054693214075530629349735273995982307625376442606753688071083149620216746\", \"price\":\"0.41\", \"size\":\"304.78\", \"side\":\"BUY\", \"hash\":\"474d55b2a0e931fb844104807b182f466ef73f4d\", \"best_bid\":\"0.47\", \"best_ask\":\"0.48\"}, {\"asset_id\":\"110216635572655435074987471276357323571387854733835379371586402147734167783946\", \"price\":\"0.59\", \"size\":\"304.78\", \"side\":\"SELL\", \"hash\":\"1f5e5af59814bf610201258e56533568e3d32da8\", \"best_bid\":\"0.52\", \"best_ask\":\"0.53\"}], \"timestamp\":\"1785129954395\", \"event_type\":\"price_change\"}","received_at":"2026-07-27T05:25:54.519591Z","schema_version":"clob-market-ws.price_change.v1","sequence":null,"server_hash":null,"server_timestamp":"1785129954395","session_id":"502006c5cfcd437296561ea750c9ec8b","source":"clob_market_ws"},"received_at":"2026-07-27T05:25:54.519591Z","record_id":"ac7fc2e3a891c002f8a211ded87cfa98600247b8353c4692582c37030b75698c","schema_fingerprint":"4aa3821a28b0b7c2400bc59aba4bcc0a76e971dadd19610d3ad38c768e124dc7","schema_version":"edge-lab-recorder.raw.v1","sequence":null,"source":"clob_market_ws"}
{"event_at":"2026-07-27T05:25:54.396000Z","event_fingerprint":"8af0c5791f023105201c3d80731f7da28713e098d99583a96163623675b44f01","payload":{"connection_id":"efc69d3132f1467b8e898a382b23ac0d","event_at":"2026-07-27T05:25:54.396000Z","event_type":"price_change","frame_hash":"709be67d8083a112dafa8c4f143e98c91052ca4e139587723df92114163d4fdb","frame_index":0,"kind":"data","monotonic_ns":231937761900500,"payload":{"event_type":"price_change","market":"0x3b40066b5cf3871a2f6237c5628bd8092a206aa998558ac5ec13c4483e31e160","price_changes":[{"asset_id":"14766054693214075530629349735273995982307625376442606753688071083149620216746","best_ask":"0.48","best_bid":"0.47","hash":"60534ff10bb43f1cf3857e7ac78fd6cc52ddd5d2","price":"0.41","side":"BUY","size":"309.78"},{"asset_id":"110216635572655435074987471276357323571387854733835379371586402147734167783946","best_ask":"0.53","best_bid":"0.52","hash":"d319eb4036bcd68786c94892b28fc2027537ac3b","price":"0.59","side":"SELL","size":"309.78"}],"timestamp":"1785129954396"},"payload_hash":"70bffc0963aa2e95bb41637eef8145712bf7e18bb1e1f8259951485e3234aaee","raw_frame":"{\"market\":\"0x3b40066b5cf3871a2f6237c5628bd8092a206aa998558ac5ec13c4483e31e160\", \"price_changes\":[{\"asset_id\":\"14766054693214075530629349735273995982307625376442606753688071083149620216746\", \"price\":\"0.41\", \"size\":\"309.78\", \"side\":\"BUY\", \"hash\":\"60534ff10bb43f1cf3857e7ac78fd6cc52ddd5d2\", \"best_bid\":\"0.47\", \"best_ask\":\"0.48\"}, {\"asset_id\":\"110216635572655435074987471276357323571387854733835379371586402147734167783946\", \"price\":\"0.59\", \"size\":\"309.78\", \"side\":\"SELL\", \"hash\":\"d319eb4036bcd68786c94892b28fc2027537ac3b\", \"best_bid\":\"0.52\", \"best_ask\":\"0.53\"}], \"timestamp\":\"1785129954396\", \"event_type\":\"price_change\"}","received_at":"2026-07-27T05:25:54.521981Z","schema_version":"clob-market-ws.price_change.v1","sequence":null,"server_hash":null,"server_timestamp":"1785129954396","session_id":"502006c5cfcd437296561ea750c9ec8b","source":"clob_market_ws"},"received_at":"2026-07-27T05:25:54.521981Z","record_id":"66af7946b314db65c46f00e225a665538027eddacfca60786706ed8bb2cbca16","schema_fingerprint":"4aa3821a28b0b7c2400bc59aba4bcc0a76e971dadd19610d3ad38c768e124dc7","schema_version":"edge-lab-recorder.raw.v1","sequence":null,"source":"clob_market_ws"}
{"event_at":"2026-07-27T05:25:54.398000Z","event_fingerprint":"7a9baec7ddeb2c7dea935150f06b6e7896550b5d8389da71f180eedef66c0182","payload":{"connection_id":"efc69d3132f1467b8e898a382b23ac0d","event_at":"2026-07-27T05:25:54.398000Z","event_type":"price_change","frame_hash":"9057e4aff935e036652d3191d133f9c9d20531a29d6ba5c4018e4cb69a4572dc","frame_index":0,"kind":"data","monotonic_ns":231937764337958,"payload":{"event_type":"price_change","market":"0x3b40066b5cf3871a2f6237c5628bd8092a206aa998558ac5ec13c4483e31e160","price_changes":[{"asset_id":"14766054693214075530629349735273995982307625376442606753688071083149620216746","best_ask":"0.48","best_bid":"0.47","hash":"6557fccc35b064806eae6e1ebaeccf458d1e232f","price":"0.41","side":"BUY","size":"314.78"},{"asset_id":"110216635572655435074987471276357323571387854733835379371586402147734167783946","best_ask":"0.53","best_bid":"0.52","hash":"a1dcc1c7013166b5dac5bfef913a5b24436c9685","price":"0.59","side":"SELL","size":"314.78"}],"timestamp":"1785129954398"},"payload_hash":"ab4e05c0361d6ad8f44c290bcc0a628bba84e011f9e50f185aaae71bcdfdfcc9","raw_frame":"{\"market\":\"0x3b40066b5cf3871a2f6237c5628bd8092a206aa998558ac5ec13c4483e31e160\", \"price_changes\":[{\"asset_id\":\"14766054693214075530629349735273995982307625376442606753688071083149620216746\", \"price\":\"0.41\", \"size\":\"314.78\", \"side\":\"BUY\", \"hash\":\"6557fccc35b064806eae6e1ebaeccf458d1e232f\", \"best_bid\":\"0.47\", \"best_ask\":\"0.48\"}, {\"asset_id\":\"110216635572655435074987471276357323571387854733835379371586402147734167783946\", \"price\":\"0.59\", \"size\":\"314.78\", \"side\":\"SELL\", \"hash\":\"a1dcc1c7013166b5dac5bfef913a5b24436c9685\", \"best_bid\":\"0.52\", \"best_ask\":\"0.53\"}], \"timestamp\":\"1785129954398\", \"event_type\":\"price_change\"}","received_at":"2026-07-27T05:25:54.524417Z","schema_version":"clob-market-ws.price_change.v1","sequence":null,"server_hash":null,"server_timestamp":"1785129954398","session_id":"502006c5cfcd437296561ea750c9ec8b","source":"clob_market_ws"},"received_at":"2026-07-27T05:25:54.524417Z","record_id":"f35d746d1b560ef3291d6a07167cd828d1717a8d2dff1fa615a28c1cbca03575","schema_fingerprint":"4aa3821a28b0b7c2400bc59aba4bcc0a76e971dadd19610d3ad38c768e124dc7","schema_version":"edge-lab-recorder.raw.v1","sequence":null,"source":"clob_market_ws"}
{"event_at":"2026-07-27T05:25:54.400000Z","event_fingerprint":"b414037bf5506deef29d891659a6f1a0e61d1b3d4eefd9f329d5e9b42b80a018","payload":{"connection_id":"efc69d3132f1467b8e898a382b23ac0d","event_at":"2026-07-27T05:25:54.400000Z","event_type":"price_change","frame_hash":"1a6f55d31130d0e5f8a41bd4d52e324c8b1b963e8d4a3a6c4a687c64d2aedd43","frame_index":0,"kind":"data","monotonic_ns":231937767171375,"payload":{"event_type":"price_change","market":"0x3b40066b5cf3871a2f6237c5628bd8092a206aa998558ac5ec13c4483e31e160","price_changes":[{"asset_id":"14766054693214075530629349735273995982307625376442606753688071083149620216746","best_ask":"0.48","best_bid":"0.47","hash":"ffc3e207a302582a750da01d0b811e2480254c05","price":"0.41","side":"BUY","size":"319.78"},{"asset_id":"110216635572655435074987471276357323571387854733835379371586402147734167783946","best_ask":"0.53","best_bid":"0.52","hash":"cd342cfc856857cc1b6ab2eebfe3ae9cf2a2a238","price":"0.59","side":"SELL","size":"319.78"}],"timestamp":"1785129954400"},"payload_hash":"a7cde803b26b6a4d51ed74764e150ebce8abf591c6c7090d2ee09cc20c404f3e","raw_frame":"{\"market\":\"0x3b40066b5cf3871a2f6237c5628bd8092a206aa998558ac5ec13c4483e31e160\", \"price_changes\":[{\"asset_id\":\"14766054693214075530629349735273995982307625376442606753688071083149620216746\", \"price\":\"0.41\", \"size\":\"319.78\", \"side\":\"BUY\", \"hash\":\"ffc3e207a302582a750da01d0b811e2480254c05\", \"best_bid\":\"0.47\", \"best_ask\":\"0.48\"}, {\"asset_id\":\"110216635572655435074987471276357323571387854733835379371586402147734167783946\", \"price\":\"0.59\", \"size\":\"319.78\", \"side\":\"SELL\", \"hash\":\"cd342cfc856857cc1b6ab2eebfe3ae9cf2a2a238\", \"best_bid\":\"0.52\", \"best_ask\":\"0.53\"}], \"timestamp\":\"1785129954400\", \"event_type\":\"price_change\"}","received_at":"2026-07-27T05:25:54.527251Z","schema_version":"clob-market-ws.price_change.v1","sequence":null,"server_hash":null,"server_timestamp":"1785129954400","session_id":"502006c5cfcd437296561ea750c9ec8b","source":"clob_market_ws"},"received_at":"2026-07-27T05:25:54.527251Z","record_id":"cce1ad004f1416788320a5b322d103475f29430f4496b569be115195c21599b2","schema_fingerprint":"4aa3821a28b0b7c2400bc59aba4bcc0a76e971dadd19610d3ad38c768e124dc7","schema_version":"edge-lab-recorder.raw.v1","sequence":null,"source":"clob_market_ws"}
{"event_at":"2026-07-27T05:25:54.402000Z","event_fingerprint":"18635ec76696b833ed601176a9ce440f9e049d6f9ebc9c519ba87c5c58d1c40c","payload":{"connection_id":"efc69d3132f1467b8e898a382b23ac0d","event_at":"2026-07-27T05:25:54.402000Z","event_type":"price_change","frame_hash":"2eda9bc9b4a96de7a2268792d83068be44bc2a096b811fb4b65cffc6a671d18a","frame_index":0,"kind":"data","monotonic_ns":231937770346791,"payload":{"event_type":"price_change","market":"0x3b40066b5cf3871a2f6237c5628bd8092a206aa998558ac5ec13c4483e31e160","price_changes":[{"asset_id":"14766054693214075530629349735273995982307625376442606753688071083149620216746","best_ask":"0.48","best_bid":"0.47","hash":"bedb655fa341e64be3d634cba5f181319678bd48","price":"0.41","side":"BUY","size":"324.78"},{"asset_id":"110216635572655435074987471276357323571387854733835379371586402147734167783946","best_ask":"0.53","best_bid":"0.52","hash":"99b598df8a699cf8e2dc9933483231c7912a156c","price":"0.59","side":"SELL","size":"324.78"}],"timestamp":"1785129954402"},"payload_hash":"bc0142ceeddbaa2eb15b4c0f0fd7b64103630d059235cec5378bd1e638b05591","raw_frame":"{\"market\":\"0x3b40066b5cf3871a2f6237c5628bd8092a206aa998558ac5ec13c4483e31e160\", \"price_changes\":[{\"asset_id\":\"14766054693214075530629349735273995982307625376442606753688071083149620216746\", \"price\":\"0.41\", \"size\":\"324.78\", \"side\":\"BUY\", \"hash\":\"bedb655fa341e64be3d634cba5f181319678bd48\", \"best_bid\":\"0.47\", \"best_ask\":\"0.48\"}, {\"asset_id\":\"110216635572655435074987471276357323571387854733835379371586402147734167783946\", \"price\":\"0.59\", \"size\":\"324.78\", \"side\":\"SELL\", \"hash\":\"99b598df8a699cf8e2dc9933483231c7912a156c\", \"best_bid\":\"0.52\", \"best_ask\":\"0.53\"}], \"timestamp\":\"1785129954402\", \"event_type\":\"price_change\"}","received_at":"2026-07-27T05:25:54.530432Z","schema_version":"clob-market-ws.price_change.v1","sequence":null,"server_hash":null,"server_timestamp":"1785129954402","session_id":"502006c5cfcd437296561ea750c9ec8b","source":"clob_market_ws"},"received_at":"2026-07-27T05:25:54.530432Z","record_id":"674a7c395232c32dab353d3e1afb337de1958c4f5ddc8a4f349854cfcb905292","schema_fingerprint":"4aa3821a28b0b7c2400bc59aba4bcc0a76e971dadd19610d3ad38c768e124dc7","schema_version":"edge-lab-recorder.raw.v1","sequence":null,"source":"clob_market_ws"}
{"event_at":"2026-07-27T05:25:54.404000Z","event_fingerprint":"1a3203b914f8087bdcb9d7efe14c4e90f59a6582064ae69138ba9dd8bd81c69b","payload":{"connection_id":"efc69d3132f1467b8e898a382b23ac0d","event_at":"2026-07-27T05:25:54.404000Z","event_type":"price_change","frame_hash":"f94402f786c21652faf18c86a2d3dd2f36ba0d3a15b6eb927412cc8c597589f8","frame_index":0,"kind":"data","monotonic_ns":231937773337541,"payload":{"event_type":"price_change","market":"0x3b40066b5cf3871a2f6237c5628bd8092a206aa998558ac5ec13c4483e31e160","price_changes":[{"asset_id":"14766054693214075530629349735273995982307625376442606753688071083149620216746","best_ask":"0.48","best_bid":"0.47","hash":"5c752b196bc84ff47c992d871e8f082dc33275ca","price":"0.41","side":"BUY","size":"329.78"},{"asset_id":"110216635572655435074987471276357323571387854733835379371586402147734167783946","best_ask":"0.53","best_bid":"0.52","hash":"89ce5c0088e160518775e66fba9d825eeae9cf4d","price":"0.59","side":"SELL","size":"329.78"}],"timestamp":"1785129954404"},"payload_hash":"435687612eeef69c8f39ebfcc04574f9ecc9055791cc849819c72a675ff44677","raw_frame":"{\"market\":\"0x3b40066b5cf3871a2f6237c5628bd8092a206aa998558ac5ec13c4483e31e160\", \"price_changes\":[{\"asset_id\":\"14766054693214075530629349735273995982307625376442606753688071083149620216746\", \"price\":\"0.41\", \"size\":\"329.78\", \"side\":\"BUY\", \"hash\":\"5c752b196bc84ff47c992d871e8f082dc33275ca\", \"best_bid\":\"0.47\", \"best_ask\":\"0.48\"}, {\"asset_id\":\"110216635572655435074987471276357323571387854733835379371586402147734167783946\", \"price\":\"0.59\", \"size\":\"329.78\", \"side\":\"SELL\", \"hash\":\"89ce5c0088e160518775e66fba9d825eeae9cf4d\", \"best_bid\":\"0.52\", \"best_ask\":\"0.53\"}], \"timestamp\":\"1785129954404\", \"event_type\":\"price_change\"}","received_at":"2026-07-27T05:25:54.533418Z","schema_version":"clob-market-ws.price_change.v1","sequence":null,"server_hash":null,"server_timestamp":"1785129954404","session_id":"502006c5cfcd437296561ea750c9ec8b","source":"clob_market_ws"},"received_at":"2026-07-27T05:25:54.533418Z","record_id":"8b62f930fc2b3d6088fef18050d2b9c1215e430affc6ea25f56dec382878db7b","schema_fingerprint":"4aa3821a28b0b7c2400bc59aba4bcc0a76e971dadd19610d3ad38c768e124dc7","schema_version":"edge-lab-recorder.raw.v1","sequence":null,"source":"clob_market_ws"}
{"event_at":"2026-07-27T05:25:54.407000Z","event_fingerprint":"4d252af0abbcb8db3d68f3f0d8462ff6a94b5f502b6862762e6fb1efb42295bd","payload":{"connection_id":"efc69d3132f1467b8e898a382b23ac0d","event_at":"2026-07-27T05:25:54.407000Z","event_type":"price_change","frame_hash":"06990909af9945303b27b20f1f68b84611a9b58dea4ecee3c075920fb1a1a7a3","frame_index":0,"kind":"data","monotonic_ns":231937777270541,"payload":{"event_type":"price_change","market":"0x3b40066b5cf3871a2f6237c5628bd8092a206aa998558ac5ec13c4483e31e160","price_changes":[{"asset_id":"14766054693214075530629349735273995982307625376442606753688071083149620216746","best_ask":"0.48","best_bid":"0.47","hash":"a37e1115d18b202e43c1a3d9e12d70fd7a79e941","price":"0.41","side":"BUY","size":"334.78"},{"asset_id":"110216635572655435074987471276357323571387854733835379371586402147734167783946","best_ask":"0.53","best_bid":"0.52","hash":"dfa1736bd40fc4c800b3a8ef6930fdb00d0a34ec","price":"0.59","side":"SELL","size":"334.78"}],"timestamp":"1785129954407"},"payload_hash":"4b9a08e3053100586048d8d86b5d35a83c86a450cfabc6c073ac509c4c74bc49","raw_frame":"{\"market\":\"0x3b40066b5cf3871a2f6237c5628bd8092a206aa998558ac5ec13c4483e31e160\", \"price_changes\":[{\"asset_id\":\"14766054693214075530629349735273995982307625376442606753688071083149620216746\", \"price\":\"0.41\", \"size\":\"334.78\", \"side\":\"BUY\", \"hash\":\"a37e1115d18b202e43c1a3d9e12d70fd7a79e941\", \"best_bid\":\"0.47\", \"best_ask\":\"0.48\"}, {\"asset_id\":\"110216635572655435074987471276357323571387854733835379371586402147734167783946\", \"price\":\"0.59\", \"size\":\"334.78\", \"side\":\"SELL\", \"hash\":\"dfa1736bd40fc4c800b3a8ef6930fdb00d0a34ec\", \"best_bid\":\"0.52\", \"best_ask\":\"0.53\"}], \"timestamp\":\"1785129954407\", \"event_type\":\"price_change\"}","received_at":"2026-07-27T05:25:54.537351Z","schema_version":"clob-market-ws.price_change.v1","sequence":null,"server_hash":null,"server_timestamp":"1785129954407","session_id":"502006c5cfcd437296561ea750c9ec8b","source":"clob_market_ws"},"received_at":"2026-07-27T05:25:54.537351Z","record_id":"2c03c8b189aef49f4aa09fe81d5210514d2b7db2bcdc2c9165a3dcef1eaf43db","schema_fingerprint":"4aa3821a28b0b7c2400bc59aba4bcc0a76e971dadd19610d3ad38c768e124dc7","schema_version":"edge-lab-recorder.raw.v1","sequence":null,"source":"clob_market_ws"}
{"event_at":"2026-07-27T05:25:54.408000Z","event_fingerprint":"c8712c7f61ab3118e7d1b60c44187d5eaeb7765fddbd43fbf338a9cfa111271d","payload":{"connection_id":"efc69d3132f1467b8e898a382b23ac0d","event_at":"2026-07-27T05:25:54.408000Z","event_type":"price_change","frame_hash":"bea82ec19e26ac2817d8ecbf854c6376fa9f9b32e65df4154df8b3f76558f6e3","frame_index":0,"kind":"data","monotonic_ns":231937780107416,"payload":{"event_type":"price_change","market":"0x3b40066b5cf3871a2f6237c5628bd8092a206aa998558ac5ec13c4483e31e160","price_changes":[{"asset_id":"14766054693214075530629349735273995982307625376442606753688071083149620216746","best_ask":"0.48","best_bid":"0.47","hash":"e92406e3505df7eb11232d1a0ea5698c132e8c5a","price":"0.41","side":"BUY","size":"339.78"},{"asset_id":"110216635572655435074987471276357323571387854733835379371586402147734167783946","best_ask":"0.53","best_bid":"0.52","hash":"ed44c8a43ed0f23e5135e544dea684ee53f03cc4","price":"0.59","side":"SELL","size":"339.78"}],"timestamp":"1785129954408"},"payload_hash":"08362c3205b2ac36799947ff5ed10e30e1595aca1de293b62ad7678e640055a3","raw_frame":"{\"market\":\"0x3b40066b5cf3871a2f6237c5628bd8092a206aa998558ac5ec13c4483e31e160\", \"price_changes\":[{\"asset_id\":\"14766054693214075530629349735273995982307625376442606753688071083149620216746\", \"price\":\"0.41\", \"size\":\"339.78\", \"side\":\"BUY\", \"hash\":\"e92406e3505df7eb11232d1a0ea5698c132e8c5a\", \"best_bid\":\"0.47\", \"best_ask\":\"0.48\"}, {\"asset_id\":\"110216635572655435074987471276357323571387854733835379371586402147734167783946\", \"price\":\"0.59\", \"size\":\"339.78\", \"side\":\"SELL\", \"hash\":\"ed44c8a43ed0f23e5135e544dea684ee53f03cc4\", \"best_bid\":\"0.52\", \"best_ask\":\"0.53\"}], \"timestamp\":\"1785129954408\", \"event_type\":\"price_change\"}","received_at":"2026-07-27T05:25:54.540187Z","schema_version":"clob-market-ws.price_change.v1","sequence":null,"server_hash":null,"server_timestamp":"1785129954408","session_id":"502006c5cfcd437296561ea750c9ec8b","source":"clob_market_ws"},"received_at":"2026-07-27T05:25:54.540187Z","record_id":"4655eda1978931b0c89abe9f6866dfee13e9f9952ef3a56703163c7c6883ad3b","schema_fingerprint":"4aa3821a28b0b7c2400bc59aba4bcc0a76e971dadd19610d3ad38c768e124dc7","schema_version":"edge-lab-recorder.raw.v1","sequence":null,"source":"clob_market_ws"}
{"event_at":"2026-07-27T05:25:54.411000Z","event_fingerprint":"da92a18142260ba368b19d308b7e775ebe274387785dd6229b8b84d469bb80aa","payload":{"connection_id":"efc69d3132f1467b8e898a382b23ac0d","event_at":"2026-07-27T05:25:54.411000Z","event_type":"price_change","frame_hash":"bac4c73bc2ec9aff7d9eba0146cff51630e5b84de5868ca740a2e506619f6b6b","frame_index":0,"kind":"data","monotonic_ns":231937782901333,"payload":{"event_type":"price_change","market":"0x3b40066b5cf3871a2f6237c5628bd8092a206aa998558ac5ec13c4483e31e160","price_changes":[{"asset_id":"14766054693214075530629349735273995982307625376442606753688071083149620216746","best_ask":"0.48","best_bid":"0.47","hash":"b68032b48595d99f23fb499b9724e501255915ea","price":"0.41","side":"BUY","size":"344.78"},{"asset_id":"110216635572655435074987471276357323571387854733835379371586402147734167783946","best_ask":"0.53","best_bid":"0.52","hash":"63bd17c029dd8573be688fa5ea1e35a846331050","price":"0.59","side":"SELL","size":"344.78"}],"timestamp":"1785129954411"},"payload_hash":"34d46b1a341293a3a165f7cdfcf6d1c16a6d556a461089e79b89101fe4f092e7","raw_frame":"{\"market\":\"0x3b40066b5cf3871a2f6237c5628bd8092a206aa998558ac5ec13c4483e31e160\", \"price_changes\":[{\"asset_id\":\"14766054693214075530629349735273995982307625376442606753688071083149620216746\", \"price\":\"0.41\", \"size\":\"344.78\", \"side\":\"BUY\", \"hash\":\"b68032b48595d99f23fb499b9724e501255915ea\", \"best_bid\":\"0.47\", \"best_ask\":\"0.48\"}, {\"asset_id\":\"110216635572655435074987471276357323571387854733835379371586402147734167783946\", \"price\":\"0.59\", \"size\":\"344.78\", \"side\":\"SELL\", \"hash\":\"63bd17c029dd8573be688fa5ea1e35a846331050\", \"best_bid\":\"0.52\", \"best_ask\":\"0.53\"}], \"timestamp\":\"1785129954411\", \"event_type\":\"price_change\"}","received_at":"2026-07-27T05:25:54.542979Z","schema_version":"clob-market-ws.price_change.v1","sequence":null,"server_hash":null,"server_timestamp":"1785129954411","session_id":"502006c5cfcd437296561ea750c9ec8b","source":"clob_market_ws"},"received_at":"2026-07-27T05:25:54.542979Z","record_id":"9b1ad3f76cb787af897250a725c6532bbb2e61eed1ad86d74b8f4ed20dd453b4","schema_fingerprint":"4aa3821a28b0b7c2400bc59aba4bcc0a76e971dadd19610d3ad38c768e124dc7","schema_version":"edge-lab-recorder.raw.v1","sequence":null,"source":"clob_market_ws"}
{"event_at":"2026-07-27T05:25:54.413000Z","event_fingerprint":"284b44897cb6d377410f04c2860b57ee32f12808c0ab4942af024b65a9be2357","payload":{"connection_id":"efc69d3132f1467b8e898a382b23ac0d","event_at":"2026-07-27T05:25:54.413000Z","event_type":"price_change","frame_hash":"cfe47a9e2de8f4a5a3574be0b696f9a4bee0796ae22d5b9afecd47c4ee73f84c","frame_index":0,"kind":"data","monotonic_ns":231937785717375,"payload":{"event_type":"price_change","market":"0x3b40066b5cf3871a2f6237c5628bd8092a206aa998558ac5ec13c4483e31e160","price_changes":[{"asset_id":"14766054693214075530629349735273995982307625376442606753688071083149620216746","best_ask":"0.48","best_bid":"0.47","hash":"a05c999f38e25ff09837b62011e62e9c4a46e1de","price":"0.41","side":"BUY","size":"349.78"},{"asset_id":"110216635572655435074987471276357323571387854733835379371586402147734167783946","best_ask":"0.53","best_bid":"0.52","hash":"65ed9eecdccaf5cd52e234c4b4de241482c8cdae","price":"0.59","side":"SELL","size":"349.78"}],"timestamp":"1785129954413"},"payload_hash":"0c24872f08ed976c533ff9a8c0f71c0bfa760b591b76ef54c1d52b377c405a19","raw_frame":"{\"market\":\"0x3b40066b5cf3871a2f6237c5628bd8092a206aa998558ac5ec13c4483e31e160\", \"price_changes\":[{\"asset_id\":\"14766054693214075530629349735273995982307625376442606753688071083149620216746\", \"price\":\"0.41\", \"size\":\"349.78\", \"side\":\"BUY\", \"hash\":\"a05c999f38e25ff09837b62011e62e9c4a46e1de\", \"best_bid\":\"0.47\", \"best_ask\":\"0.48\"}, {\"asset_id\":\"110216635572655435074987471276357323571387854733835379371586402147734167783946\", \"price\":\"0.59\", \"size\":\"349.78\", \"side\":\"SELL\", \"hash\":\"65ed9eecdccaf5cd52e234c4b4de241482c8cdae\", \"best_bid\":\"0.52\", \"best_ask\":\"0.53\"}], \"timestamp\":\"1785129954413\", \"event_type\":\"price_change\"}","received_at":"2026-07-27T05:25:54.545797Z","schema_version":"clob-market-ws.price_change.v1","sequence":null,"server_hash":null,"server_timestamp":"1785129954413","session_id":"502006c5cfcd437296561ea750c9ec8b","source":"clob_market_ws"},"received_at":"2026-07-27T05:25:54.545797Z","record_id":"703402b00f5d3e9393a5614164b23af18a644555f13cff992c65d18fe9602bbd","schema_fingerprint":"4aa3821a28b0b7c2400bc59aba4bcc0a76e971dadd19610d3ad38c768e124dc7","schema_version":"edge-lab-recorder.raw.v1","sequence":null,"source":"clob_market_ws"}
{"event_at":"2026-07-27T05:25:54.415000Z","event_fingerprint":"177c7c687742f86e16641750b2d618640c68480559c6a8abc1212ab96b0ec8b2","payload":{"connection_id":"efc69d3132f1467b8e898a382b23ac0d","event_at":"2026-07-27T05:25:54.415000Z","event_type":"price_change","frame_hash":"363397c5c41d1d1368e2db40d3d002fa94293d9d36170325e05c7bc25fb9f58f","frame_index":0,"kind":"data","monotonic_ns":231937787067833,"payload":{"event_type":"price_change","market":"0x3b40066b5cf3871a2f6237c5628bd8092a206aa998558ac5ec13c4483e31e160","price_changes":[{"asset_id":"14766054693214075530629349735273995982307625376442606753688071083149620216746","best_ask":"0.48","best_bid":"0.47","hash":"4f119cc8b0337a6e71945dbe4e3402d2b5c9faea","price":"0.41","side":"BUY","size":"354.78"},{"asset_id":"110216635572655435074987471276357323571387854733835379371586402147734167783946","best_ask":"0.53","best_bid":"0.52","hash":"1f89d9c6097ddcea76671c20b940fc0eae140527","price":"0.59","side":"SELL","size":"354.78"}],"timestamp":"1785129954415"},"payload_hash":"439521127db0306cbb2c7f9c8efd127c3f0478cc948f41292036ac8473adb53f","raw_frame":"{\"market\":\"0x3b40066b5cf3871a2f6237c5628bd8092a206aa998558ac5ec13c4483e31e160\", \"price_changes\":[{\"asset_id\":\"14766054693214075530629349735273995982307625376442606753688071083149620216746\", \"price\":\"0.41\", \"size\":\"354.78\", \"side\":\"BUY\", \"hash\":\"4f119cc8b0337a6e71945dbe4e3402d2b5c9faea\", \"best_bid\":\"0.47\", \"best_ask\":\"0.48\"}, {\"asset_id\":\"110216635572655435074987471276357323571387854733835379371586402147734167783946\", \"price\":\"0.59\", \"size\":\"354.78\", \"side\":\"SELL\", \"hash\":\"1f89d9c6097ddcea76671c20b940fc0eae140527\", \"best_bid\":\"0.52\", \"best_ask\":\"0.53\"}], \"timestamp\":\"1785129954415\", \"event_type\":\"price_change\"}","received_at":"2026-07-27T05:25:54.547154Z","schema_version":"clob-market-ws.price_change.v1","sequence":null,"server_hash":null,"server_timestamp":"1785129954415","session_id":"502006c5cfcd437296561ea750c9ec8b","source":"clob_market_ws"},"received_at":"2026-07-27T05:25:54.547154Z","record_id":"a62daa57f7ecc68590498e35f9240e11d5229eb8a30cbf3051a7f1c532c288f4","schema_fingerprint":"4aa3821a28b0b7c2400bc59aba4bcc0a76e971dadd19610d3ad38c768e124dc7","schema_version":"edge-lab-recorder.raw.v1","sequence":null,"source":"clob_market_ws"}
{"event_at":"2026-07-27T05:25:54.417000Z","event_fingerprint":"609b9f87e569e44664e33cfac1519743472389694d95eeac8ac68a78c4ac6cf6","payload":{"connection_id":"efc69d3132f1467b8e898a382b23ac0d","event_at":"2026-07-27T05:25:54.417000Z","event_type":"price_change","frame_hash":"0a7531f55947a5303fcd54b8720e22e62e6fc2956becefba2cf8c511a944e87d","frame_index":0,"kind":"data","monotonic_ns":231937789149041,"payload":{"event_type":"price_change","market":"0x3b40066b5cf3871a2f6237c5628bd8092a206aa998558ac5ec13c4483e31e160","price_changes":[{"asset_id":"14766054693214075530629349735273995982307625376442606753688071083149620216746","best_ask":"0.48","best_bid":"0.47","hash":"2964c9a5f10b94848ce218028fcfdb4f12927e0e","price":"0.41","side":"BUY","size":"359.78"},{"asset_id":"110216635572655435074987471276357323571387854733835379371586402147734167783946","best_ask":"0.53","best_bid":"0.52","hash":"5f4e3669c107aac5bbd3383293793dae43400e68","price":"0.59","side":"SELL","size":"359.78"}],"timestamp":"1785129954417"},"payload_hash":"f5519d23805b2ca46b9eef0e6c7866e5c2cd3fc5219eb8b33e3bc6192531f3f9","raw_frame":"{\"market\":\"0x3b40066b5cf3871a2f6237c5628bd8092a206aa998558ac5ec13c4483e31e160\", \"price_changes\":[{\"asset_id\":\"14766054693214075530629349735273995982307625376442606753688071083149620216746\", \"price\":\"0.41\", \"size\":\"359.78\", \"side\":\"BUY\", \"hash\":\"2964c9a5f10b94848ce218028fcfdb4f12927e0e\", \"best_bid\":\"0.47\", \"best_ask\":\"0.48\"}, {\"asset_id\":\"110216635572655435074987471276357323571387854733835379371586402147734167783946\", \"price\":\"0.59\", \"size\":\"359.78\", \"side\":\"SELL\", \"hash\":\"5f4e3669c107aac5bbd3383293793dae43400e68\", \"best_bid\":\"0.52\", \"best_ask\":\"0.53\"}], \"timestamp\":\"1785129954417\", \"event_type\":\"price_change\"}","received_at":"2026-07-27T05:25:54.549229Z","schema_version":"clob-market-ws.price_change.v1","sequence":null,"server_hash":null,"server_timestamp":"1785129954417","session_id":"502006c5cfcd437296561ea750c9ec8b","source":"clob_market_ws"},"received_at":"2026-07-27T05:25:54.549229Z","record_id":"b6284e251569cff78f23fd23b2b362c8c9ffe0ffbbbd038e69555d611f8d18be","schema_fingerprint":"4aa3821a28b0b7c2400bc59aba4bcc0a76e971dadd19610d3ad38c768e124dc7","schema_version":"edge-lab-recorder.raw.v1","sequence":null,"source":"clob_market_ws"}
{"event_at":"2026-07-27T05:25:54.418000Z","event_fingerprint":"669d9f26c32f6c6033c4621040c9d457a36ba59f812a10c367d9099c58e7c6c8","payload":{"connection_id":"efc69d3132f1467b8e898a382b23ac0d","event_at":"2026-07-27T05:25:54.418000Z","event_type":"price_change","frame_hash":"c8c92733d7676334a3d5487f46456fbd4d78293b9f883e99c189fbf44ad083e3","frame_index":0,"kind":"data","monotonic_ns":231937791899250,"payload":{"event_type":"price_change","market":"0x3b40066b5cf3871a2f6237c5628bd8092a206aa998558ac5ec13c4483e31e160","price_changes":[{"asset_id":"14766054693214075530629349735273995982307625376442606753688071083149620216746","best_ask":"0.48","best_bid":"0.47","hash":"549c3ae0d48d8c7ebc50fa43b8511e5bce0e9e4e","price":"0.41","side":"BUY","size":"364.78"},{"asset_id":"110216635572655435074987471276357323571387854733835379371586402147734167783946","best_ask":"0.53","best_bid":"0.52","hash":"e32ed83c9643845a7467d238b3d69e55fa77e611","price":"0.59","side":"SELL","size":"364.78"}],"timestamp":"1785129954418"},"payload_hash":"485ab1769d387a63598f059295010c032b1afa1d8ede187d618b21933cff8b73","raw_frame":"{\"market\":\"0x3b40066b5cf3871a2f6237c5628bd8092a206aa998558ac5ec13c4483e31e160\", \"price_changes\":[{\"asset_id\":\"14766054693214075530629349735273995982307625376442606753688071083149620216746\", \"price\":\"0.41\", \"size\":\"364.78\", \"side\":\"BUY\", \"hash\":\"549c3ae0d48d8c7ebc50fa43b8511e5bce0e9e4e\", \"best_bid\":\"0.47\", \"best_ask\":\"0.48\"}, {\"asset_id\":\"110216635572655435074987471276357323571387854733835379371586402147734167783946\", \"price\":\"0.59\", \"size\":\"364.78\", \"side\":\"SELL\", \"hash\":\"e32ed83c9643845a7467d238b3d69e55fa77e611\", \"best_bid\":\"0.52\", \"best_ask\":\"0.53\"}], \"timestamp\":\"1785129954418\", \"event_type\":\"price_change\"}","received_at":"2026-07-27T05:25:54.551980Z","schema_version":"clob-market-ws.price_change.v1","sequence":null,"server_hash":null,"server_timestamp":"1785129954418","session_id":"502006c5cfcd437296561ea750c9ec8b","source":"clob_market_ws"},"received_at":"2026-07-27T05:25:54.551980Z","record_id":"0f8ac25c6d39ea3aa7ba0e7e9cd4a5b76899b0100d2c7cc2a344ab13b6afbf20","schema_fingerprint":"4aa3821a28b0b7c2400bc59aba4bcc0a76e971dadd19610d3ad38c768e124dc7","schema_version":"edge-lab-recorder.raw.v1","sequence":null,"source":"clob_market_ws"}
{"event_at":"2026-07-27T05:25:54.422000Z","event_fingerprint":"0f2fcc2627d989012a5d0ac7d85433fdc4f9512c7fc4cdc15f883df9bd511e9c","payload":{"connection_id":"efc69d3132f1467b8e898a382b23ac0d","event_at":"2026-07-27T05:25:54.422000Z","event_type":"price_change","frame_hash":"36a65c29a7d6dda0ad1427cc69250d187892af00cbb34449a887e7c7632dc43b","frame_index":0,"kind":"data","monotonic_ns":231937794005958,"payload":{"event_type":"price_change","market":"0x3b40066b5cf3871a2f6237c5628bd8092a206aa998558ac5ec13c4483e31e160","price_changes":[{"asset_id":"14766054693214075530629349735273995982307625376442606753688071083149620216746","best_ask":"0.48","best_bid":"0.47","hash":"3762c8eb2cf75b0657db9f57e099c2fcc86c986c","price":"0.41","side":"BUY","size":"369.78"},{"asset_id":"110216635572655435074987471276357323571387854733835379371586402147734167783946","best_ask":"0.53","best_bid":"0.52","hash":"ea80110e296df804bc24f4970771af2885083750","price":"0.59","side":"SELL","size":"369.78"}],"timestamp":"1785129954422"},"payload_hash":"81372923c1769e5274955b2d652fd5f3e026bd1f0434ed8d635afea7c5f7df81","raw_frame":"{\"market\":\"0x3b40066b5cf3871a2f6237c5628bd8092a206aa998558ac5ec13c4483e31e160\", \"price_changes\":[{\"asset_id\":\"14766054693214075530629349735273995982307625376442606753688071083149620216746\", \"price\":\"0.41\", \"size\":\"369.78\", \"side\":\"BUY\", \"hash\":\"3762c8eb2cf75b0657db9f57e099c2fcc86c986c\", \"best_bid\":\"0.47\", \"best_ask\":\"0.48\"}, {\"asset_id\":\"110216635572655435074987471276357323571387854733835379371586402147734167783946\", \"price\":\"0.59\", \"size\":\"369.78\", \"side\":\"SELL\", \"hash\":\"ea80110e296df804bc24f4970771af2885083750\", \"best_bid\":\"0.52\", \"best_ask\":\"0.53\"}], \"timestamp\":\"1785129954422\", \"event_type\":\"price_change\"}","received_at":"2026-07-27T05:25:54.554086Z","schema_version":"clob-market-ws.price_change.v1","sequence":null,"server_hash":null,"server_timestamp":"1785129954422","session_id":"502006c5cfcd437296561ea750c9ec8b","source":"clob_market_ws"},"received_at":"2026-07-27T05:25:54.554086Z","record_id":"ece8113b5476a074bfb6a684139d8e0c58d157ab52184dca59cd883f5b9bc8bd","schema_fingerprint":"4aa3821a28b0b7c2400bc59aba4bcc0a76e971dadd19610d3ad38c768e124dc7","schema_version":"edge-lab-recorder.raw.v1","sequence":null,"source":"clob_market_ws"}
{"event_at":"2026-07-27T05:25:54.424000Z","event_fingerprint":"0a4a8ba149d6c2f9dc9719c7930f6fbb8c5fa637ff15b7378712e2cb06288d23","payload":{"connection_id":"efc69d3132f1467b8e898a382b23ac0d","event_at":"2026-07-27T05:25:54.424000Z","event_type":"price_change","frame_hash":"6d6d077966966677d96967062363dafcc3111f9049d144c6b875d74f3e087736","frame_index":0,"kind":"data","monotonic_ns":231937796513083,"payload":{"event_type":"price_change","market":"0x3b40066b5cf3871a2f6237c5628bd8092a206aa998558ac5ec13c4483e31e160","price_changes":[{"asset_id":"14766054693214075530629349735273995982307625376442606753688071083149620216746","best_ask":"0.48","best_bid":"0.47","hash":"ec1e9c5a213fe463d3ee231581c3e95e053a0e7f","price":"0.41","side":"BUY","size":"374.78"},{"asset_id":"110216635572655435074987471276357323571387854733835379371586402147734167783946","best_ask":"0.53","best_bid":"0.52","hash":"b21cde2d6f0adb81bcfaddf8245526759a71a817","price":"0.59","side":"SELL","size":"374.78"}],"timestamp":"1785129954424"},"payload_hash":"6d67068d7f56b8fce151f1defb011341ec93d3fa7517377e1b80150096370456","raw_frame":"{\"market\":\"0x3b40066b5cf3871a2f6237c5628bd8092a206aa998558ac5ec13c4483e31e160\", \"price_changes\":[{\"asset_id\":\"14766054693214075530629349735273995982307625376442606753688071083149620216746\", \"price\":\"0.41\", \"size\":\"374.78\", \"side\":\"BUY\", \"hash\":\"ec1e9c5a213fe463d3ee231581c3e95e053a0e7f\", \"best_bid\":\"0.47\", \"best_ask\":\"0.48\"}, {\"asset_id\":\"110216635572655435074987471276357323571387854733835379371586402147734167783946\", \"price\":\"0.59\", \"size\":\"374.78\", \"side\":\"SELL\", \"hash\":\"b21cde2d6f0adb81bcfaddf8245526759a71a817\", \"best_bid\":\"0.52\", \"best_ask\":\"0.53\"}], \"timestamp\":\"1785129954424\", \"event_type\":\"price_change\"}","received_at":"2026-07-27T05:25:54.556594Z","schema_version":"clob-market-ws.price_change.v1","sequence":null,"server_hash":null,"server_timestamp":"1785129954424","session_id":"502006c5cfcd437296561ea750c9ec8b","source":"clob_market_ws"},"received_at":"2026-07-27T05:25:54.556594Z","record_id":"f3503b8cbfb7af965118fa7305ad51395970b4f04c013ace98fb7faa2f01206e","schema_fingerprint":"4aa3821a28b0b7c2400bc59aba4bcc0a76e971dadd19610d3ad38c768e124dc7","schema_version":"edge-lab-recorder.raw.v1","sequence":null,"source":"clob_market_ws"}
{"event_at":"2026-07-27T05:25:54.425000Z","event_fingerprint":"0e31b98c2816adaeb5af59a73d316a91afa9db86c32846d7a0ebfea2f4756269","payload":{"connection_id":"efc69d3132f1467b8e898a382b23ac0d","event_at":"2026-07-27T05:25:54.425000Z","event_type":"price_change","frame_hash":"e3cdf16e503d90b1e551921cbf60ed74af62c230d49aa04bd71a4d1d56d93ed2","frame_index":0,"kind":"data","monotonic_ns":231937801734875,"payload":{"event_type":"price_change","market":"0x3b40066b5cf3871a2f6237c5628bd8092a206aa998558ac5ec13c4483e31e160","price_changes":[{"asset_id":"14766054693214075530629349735273995982307625376442606753688071083149620216746","best_ask":"0.48","best_bid":"0.47","hash":"7c8feb1a20cc8d254c000608dfda9c0066e2d851","price":"0.41","side":"BUY","size":"379.78"},{"asset_id":"110216635572655435074987471276357323571387854733835379371586402147734167783946","best_ask":"0.53","best_bid":"0.52","hash":"0fc35b3ba1ba517c4bdd2bd3ee4169c5f42cc51c","price":"0.59","side":"SELL","size":"379.78"}],"timestamp":"1785129954425"},"payload_hash":"2c688c7e15fc2785cc89ebdfc9883e23b5888170995104c1f0ed5e7d9b09c608","raw_frame":"{\"market\":\"0x3b40066b5cf3871a2f6237c5628bd8092a206aa998558ac5ec13c4483e31e160\", \"price_changes\":[{\"asset_id\":\"14766054693214075530629349735273995982307625376442606753688071083149620216746\", \"price\":\"0.41\", \"size\":\"379.78\", \"side\":\"BUY\", \"hash\":\"7c8feb1a20cc8d254c000608dfda9c0066e2d851\", \"best_bid\":\"0.47\", \"best_ask\":\"0.48\"}, {\"asset_id\":\"110216635572655435074987471276357323571387854733835379371586402147734167783946\", \"price\":\"0.59\", \"size\":\"379.78\", \"side\":\"SELL\", \"hash\":\"0fc35b3ba1ba517c4bdd2bd3ee4169c5f42cc51c\", \"best_bid\":\"0.52\", \"best_ask\":\"0.53\"}], \"timestamp\":\"1785129954425\", \"event_type\":\"price_change\"}","received_at":"2026-07-27T05:25:54.561815Z","schema_version":"clob-market-ws.price_change.v1","sequence":null,"server_hash":null,"server_timestamp":"1785129954425","session_id":"502006c5cfcd437296561ea750c9ec8b","source":"clob_market_ws"},"received_at":"2026-07-27T05:25:54.561815Z","record_id":"448b6966ea0c301f65eb17c7ebc87396d48171ca5eacb86b3dfd510f17d940a1","schema_fingerprint":"4aa3821a28b0b7c2400bc59aba4bcc0a76e971dadd19610d3ad38c768e124dc7","schema_version":"edge-lab-recorder.raw.v1","sequence":null,"source":"clob_market_ws"}
{"event_at":"2026-07-27T05:25:54.426000Z","event_fingerprint":"574d6a777ec4cbd773343b514db3948a1fc6fc8dd5d292bbf33696533793519a","payload":{"connection_id":"efc69d3132f1467b8e898a382b23ac0d","event_at":"2026-07-27T05:25:54.426000Z","event_type":"price_change","frame_hash":"a2e88238484e11ee22d15d5be5060ffd45324e8a1eae2662d062be0fce159331","frame_index":0,"kind":"data","monotonic_ns":231937805697708,"payload":{"event_type":"price_change","market":"0x3b40066b5cf3871a2f6237c5628bd8092a206aa998558ac5ec13c4483e31e160","price_changes":[{"asset_id":"14766054693214075530629349735273995982307625376442606753688071083149620216746","best_ask":"0.48","best_bid":"0.47","hash":"bcb5890c89ec5ecd32b76c328c5a4a50501c4929","price":"0.41","side":"BUY","size":"384.78"},{"asset_id":"110216635572655435074987471276357323571387854733835379371586402147734167783946","best_ask":"0.53","best_bid":"0.52","hash":"5fdb2d4172204fa6861ec1fc4356d24942d91325","price":"0.59","side":"SELL","size":"384.78"}],"timestamp":"1785129954426"},"payload_hash":"787f64aec86161314f6f2c244bdd13409fd8c9110c58bdf75ddf25265c0c8ee1","raw_frame":"{\"market\":\"0x3b40066b5cf3871a2f6237c5628bd8092a206aa998558ac5ec13c4483e31e160\", \"price_changes\":[{\"asset_id\":\"14766054693214075530629349735273995982307625376442606753688071083149620216746\", \"price\":\"0.41\", \"size\":\"384.78\", \"side\":\"BUY\", \"hash\":\"bcb5890c89ec5ecd32b76c328c5a4a50501c4929\", \"best_bid\":\"0.47\", \"best_ask\":\"0.48\"}, {\"asset_id\":\"110216635572655435074987471276357323571387854733835379371586402147734167783946\", \"price\":\"0.59\", \"size\":\"384.78\", \"side\":\"SELL\", \"hash\":\"5fdb2d4172204fa6861ec1fc4356d24942d91325\", \"best_bid\":\"0.52\", \"best_ask\":\"0.53\"}], \"timestamp\":\"1785129954426\", \"event_type\":\"price_change\"}","received_at":"2026-07-27T05:25:54.565779Z","schema_version":"clob-market-ws.price_change.v1","sequence":null,"server_hash":null,"server_timestamp":"1785129954426","session_id":"502006c5cfcd437296561ea750c9ec8b","source":"clob_market_ws"},"received_at":"2026-07-27T05:25:54.565779Z","record_id":"4745b95beb40442355c4da3ec28cbbd45e46de3a3b1d0d13262d5ab650f5e43a","schema_fingerprint":"4aa3821a28b0b7c2400bc59aba4bcc0a76e971dadd19610d3ad38c768e124dc7","schema_version":"edge-lab-recorder.raw.v1","sequence":null,"source":"clob_market_ws"}
{"event_at":"2026-07-27T05:25:54.427000Z","event_fingerprint":"ae5d26b784b6d1d945222f5ee7b098943aae29d719b1872a7f596c16a3c10507","payload":{"connection_id":"efc69d3132f1467b8e898a382b23ac0d","event_at":"2026-07-27T05:25:54.427000Z","event_type":"price_change","frame_hash":"e6f11d91e16531399a2316f01a55c4d665e2933473c51f18ecb852726cfc1cb4","frame_index":0,"kind":"data","monotonic_ns":231937809199333,"payload":{"event_type":"price_change","market":"0x3b40066b5cf3871a2f6237c5628bd8092a206aa998558ac5ec13c4483e31e160","price_changes":[{"asset_id":"14766054693214075530629349735273995982307625376442606753688071083149620216746","best_ask":"0.48","best_bid":"0.47","hash":"b6f16ecd9ca83ebd2eef9e99b0f733e642aaae50","price":"0.41","side":"BUY","size":"389.78"},{"asset_id":"110216635572655435074987471276357323571387854733835379371586402147734167783946","best_ask":"0.53","best_bid":"0.52","hash":"37cdaf8caa0d41c2bbab857384ad78434f6c37c2","price":"0.59","side":"SELL","size":"389.78"}],"timestamp":"1785129954427"},"payload_hash":"915ead5dc840eeadc6a7119bcf13e707fece973f46777bedc1c8a29d72456a20","raw_frame":"{\"market\":\"0x3b40066b5cf3871a2f6237c5628bd8092a206aa998558ac5ec13c4483e31e160\", \"price_changes\":[{\"asset_id\":\"14766054693214075530629349735273995982307625376442606753688071083149620216746\", \"price\":\"0.41\", \"size\":\"389.78\", \"side\":\"BUY\", \"hash\":\"b6f16ecd9ca83ebd2eef9e99b0f733e642aaae50\", \"best_bid\":\"0.47\", \"best_ask\":\"0.48\"}, {\"asset_id\":\"110216635572655435074987471276357323571387854733835379371586402147734167783946\", \"price\":\"0.59\", \"size\":\"389.78\", \"side\":\"SELL\", \"hash\":\"37cdaf8caa0d41c2bbab857384ad78434f6c37c2\", \"best_bid\":\"0.52\", \"best_ask\":\"0.53\"}], \"timestamp\":\"1785129954427\", \"event_type\":\"price_change\"}","received_at":"2026-07-27T05:25:54.569274Z","schema_version":"clob-market-ws.price_change.v1","sequence":null,"server_hash":null,"server_timestamp":"1785129954427","session_id":"502006c5cfcd437296561ea750c9ec8b","source":"clob_market_ws"},"received_at":"2026-07-27T05:25:54.569274Z","record_id":"a5df708407fb77edec117e64cf65c0fc194fc4d0083074cba0f3b8d9265b8fe5","schema_fingerprint":"4aa3821a28b0b7c2400bc59aba4bcc0a76e971dadd19610d3ad38c768e124dc7","schema_version":"edge-lab-recorder.raw.v1","sequence":null,"source":"clob_market_ws"}
{"event_at":"2026-07-27T05:25:54.429000Z","event_fingerprint":"2c5cb31a90bb4111ede8d7ec811d4d07b9cf9e3813a406d0f03e77ad0954c4a8","payload":{"connection_id":"efc69d3132f1467b8e898a382b23ac0d","event_at":"2026-07-27T05:25:54.429000Z","event_type":"price_change","frame_hash":"fd86c468d6b41256c8dc131f99e5932dfa06b3a27ea3bdaa071c0e4829fe30c5","frame_index":0,"kind":"data","monotonic_ns":231937813462333,"payload":{"event_type":"price_change","market":"0x3b40066b5cf3871a2f6237c5628bd8092a206aa998558ac5ec13c4483e31e160","price_changes":[{"asset_id":"14766054693214075530629349735273995982307625376442606753688071083149620216746","best_ask":"0.48","best_bid":"0.47","hash":"ce4b9a91173293470fe27cdcca1de233dc9eb7a9","price":"0.41","side":"BUY","size":"394.78"},{"asset_id":"110216635572655435074987471276357323571387854733835379371586402147734167783946","best_ask":"0.53","best_bid":"0.52","hash":"e1962cbcf456a68db1521aba712b105cb25110d2","price":"0.59","side":"SELL","size":"394.78"}],"timestamp":"1785129954429"},"payload_hash":"14a72ecdda54f0376ccfbb868ee0a5f1ca52a4fb0b0f69b356e6c3f8c5e5a64c","raw_frame":"{\"market\":\"0x3b40066b5cf3871a2f6237c5628bd8092a206aa998558ac5ec13c4483e31e160\", \"price_changes\":[{\"asset_id\":\"14766054693214075530629349735273995982307625376442606753688071083149620216746\", \"price\":\"0.41\", \"size\":\"394.78\", \"side\":\"BUY\", \"hash\":\"ce4b9a91173293470fe27cdcca1de233dc9eb7a9\", \"best_bid\":\"0.47\", \"best_ask\":\"0.48\"}, {\"asset_id\":\"110216635572655435074987471276357323571387854733835379371586402147734167783946\", \"price\":\"0.59\", \"size\":\"394.78\", \"side\":\"SELL\", \"hash\":\"e1962cbcf456a68db1521aba712b105cb25110d2\", \"best_bid\":\"0.52\", \"best_ask\":\"0.53\"}], \"timestamp\":\"1785129954429\", \"event_type\":\"price_change\"}","received_at":"2026-07-27T05:25:54.573541Z","schema_version":"clob-market-ws.price_change.v1","sequence":null,"server_hash":null,"server_timestamp":"1785129954429","session_id":"502006c5cfcd437296561ea750c9ec8b","source":"clob_market_ws"},"received_at":"2026-07-27T05:25:54.573541Z","record_id":"244e3ea7ea9fb05ccc9c954420ecbe082bcaed7e9f7a2a4348f36385ae657559","schema_fingerprint":"4aa3821a28b0b7c2400bc59aba4bcc0a76e971dadd19610d3ad38c768e124dc7","schema_version":"edge-lab-recorder.raw.v1","sequence":null,"source":"clob_market_ws"}
{"event_at":"2026-07-27T05:25:54.430000Z","event_fingerprint":"ca37d907f925605eacbdfb115fa086e2f327495799c11c606a2225c93a1c88b1","payload":{"connection_id":"efc69d3132f1467b8e898a382b23ac0d","event_at":"2026-07-27T05:25:54.430000Z","event_type":"price_change","frame_hash":"b780af48af7ce7d3543c432cec2f406796a4b5eb1a8f5f0b6cdd495a11ebe1e4","frame_index":0,"kind":"data","monotonic_ns":231937816202875,"payload":{"event_type":"price_change","market":"0x3b40066b5cf3871a2f6237c5628bd8092a206aa998558ac5ec13c4483e31e160","price_changes":[{"asset_id":"14766054693214075530629349735273995982307625376442606753688071083149620216746","best_ask":"0.48","best_bid":"0.47","hash":"3e6e5597bb545ce6d7e9417665c44e825a38c9e5","price":"0.41","side":"BUY","size":"399.78"},{"asset_id":"110216635572655435074987471276357323571387854733835379371586402147734167783946","best_ask":"0.53","best_bid":"0.52","hash":"c5d5a6e7d4024dfffd3679cc1de1e5498bcf2fa5","price":"0.59","side":"SELL","size":"399.78"}],"timestamp":"1785129954430"},"payload_hash":"45a7f564957801d3bda78d7c948856009867f5c9a0039e85d7fc7483cef7b732","raw_frame":"{\"market\":\"0x3b40066b5cf3871a2f6237c5628bd8092a206aa998558ac5ec13c4483e31e160\", \"price_changes\":[{\"asset_id\":\"14766054693214075530629349735273995982307625376442606753688071083149620216746\", \"price\":\"0.41\", \"size\":\"399.78\", \"side\":\"BUY\", \"hash\":\"3e6e5597bb545ce6d7e9417665c44e825a38c9e5\", \"best_bid\":\"0.47\", \"best_ask\":\"0.48\"}, {\"asset_id\":\"110216635572655435074987471276357323571387854733835379371586402147734167783946\", \"price\":\"0.59\", \"size\":\"399.78\", \"side\":\"SELL\", \"hash\":\"c5d5a6e7d4024dfffd3679cc1de1e5498bcf2fa5\", \"best_bid\":\"0.52\", \"best_ask\":\"0.53\"}], \"timestamp\":\"1785129954430\", \"event_type\":\"price_change\"}","received_at":"2026-07-27T05:25:54.576283Z","schema_version":"clob-market-ws.price_change.v1","sequence":null,"server_hash":null,"server_timestamp":"1785129954430","session_id":"502006c5cfcd437296561ea750c9ec8b","source":"clob_market_ws"},"received_at":"2026-07-27T05:25:54.576283Z","record_id":"a9e5c38ea15591d1909f87b55d5a3e1f51507d8605e06e5b5231ac34e3272644","schema_fingerprint":"4aa3821a28b0b7c2400bc59aba4bcc0a76e971dadd19610d3ad38c768e124dc7","schema_version":"edge-lab-recorder.raw.v1","sequence":null,"source":"clob_market_ws"}
{"event_at":"2026-07-27T05:25:54.436000Z","event_fingerprint":"22c19e849f3a4e96d410def1d9990d568302654eb68dec68f25c793b86fc30a7","payload":{"connection_id":"efc69d3132f1467b8e898a382b23ac0d","event_at":"2026-07-27T05:25:54.436000Z","event_type":"price_change","frame_hash":"f690959f3649b229c93fef41dd76a6b17e871ef1a746376d5cdff88d84cb0143","frame_index":0,"kind":"data","monotonic_ns":231937819027125,"payload":{"event_type":"price_change","market":"0x3b40066b5cf3871a2f6237c5628bd8092a206aa998558ac5ec13c4483e31e160","price_changes":[{"asset_id":"14766054693214075530629349735273995982307625376442606753688071083149620216746","best_ask":"0.48","best_bid":"0.47","hash":"1a17ac2f56d5f153ed233e764d3b1e2531300a66","price":"0.41","side":"BUY","size":"404.78"},{"asset_id":"110216635572655435074987471276357323571387854733835379371586402147734167783946","best_ask":"0.53","best_bid":"0.52","hash":"005fbb16dcd229c4c692c13d3f2988c279069189","price":"0.59","side":"SELL","size":"404.78"}],"timestamp":"1785129954436"},"payload_hash":"2d43c9864a51911ae5144dbeea350949b8c17a3f2bace2aaaab380c780fced1c","raw_frame":"{\"market\":\"0x3b40066b5cf3871a2f6237c5628bd8092a206aa998558ac5ec13c4483e31e160\", \"price_changes\":[{\"asset_id\":\"14766054693214075530629349735273995982307625376442606753688071083149620216746\", \"price\":\"0.41\", \"size\":\"404.78\", \"side\":\"BUY\", \"hash\":\"1a17ac2f56d5f153ed233e764d3b1e2531300a66\", \"best_bid\":\"0.47\", \"best_ask\":\"0.48\"}, {\"asset_id\":\"110216635572655435074987471276357323571387854733835379371586402147734167783946\", \"price\":\"0.59\", \"size\":\"404.78\", \"side\":\"SELL\", \"hash\":\"005fbb16dcd229c4c692c13d3f2988c279069189\", \"best_bid\":\"0.52\", \"best_ask\":\"0.53\"}], \"timestamp\":\"1785129954436\", \"event_type\":\"price_change\"}","received_at":"2026-07-27T05:25:54.579108Z","schema_version":"clob-market-ws.price_change.v1","sequence":null,"server_hash":null,"server_timestamp":"1785129954436","session_id":"502006c5cfcd437296561ea750c9ec8b","source":"clob_market_ws"},"received_at":"2026-07-27T05:25:54.579108Z","record_id":"1f1437c4d0d10af8c717e95071126b9e817303867e1c5b8bff92a90183f81672","schema_fingerprint":"4aa3821a28b0b7c2400bc59aba4bcc0a76e971dadd19610d3ad38c768e124dc7","schema_version":"edge-lab-recorder.raw.v1","sequence":null,"source":"clob_market_ws"}
{"event_at":"2026-07-27T05:26:00.626000Z","event_fingerprint":"8d0770256c43566f73d4ff1a94053edbd84a164be2525f94755422aa88145c51","payload":{"connection_id":"efc69d3132f1467b8e898a382b23ac0d","event_at":"2026-07-27T05:26:00.626000Z","event_type":"price_change","frame_hash":"e1dd0637171bb4bc6f954663440176df2075373bf4a551dab23be733c3cc68c9","frame_index":0,"kind":"data","monotonic_ns":231943834469541,"payload":{"event_type":"price_change","market":"0x3b40066b5cf3871a2f6237c5628bd8092a206aa998558ac5ec13c4483e31e160","price_changes":[{"asset_id":"110216635572655435074987471276357323571387854733835379371586402147734167783946","best_ask":"0.53","best_bid":"0.52","hash":"d6e1981a904e9139f744069ba50cb10eea1d8282","price":"0.26","side":"BUY","size":"379.24"},{"asset_id":"14766054693214075530629349735273995982307625376442606753688071083149620216746","best_ask":"0.48","best_bid":"0.47","hash":"2c5dcbab34ff520e7656321f8ee44f08c60db1fa","price":"0.74","side":"SELL","size":"379.24"}],"timestamp":"1785129960626"},"payload_hash":"1dd9a3a0158b3360f0fe373a463b648602bcea1b09f8d17f0d2aa200cf5e74de","raw_frame":"{\"market\":\"0x3b40066b5cf3871a2f6237c5628bd8092a206aa998558ac5ec13c4483e31e160\", \"price_changes\":[{\"asset_id\":\"110216635572655435074987471276357323571387854733835379371586402147734167783946\", \"price\":\"0.26\", \"size\":\"379.24\", \"side\":\"BUY\", \"hash\":\"d6e1981a904e9139f744069ba50cb10eea1d8282\", \"best_bid\":\"0.52\", \"best_ask\":\"0.53\"}, {\"asset_id\":\"14766054693214075530629349735273995982307625376442606753688071083149620216746\", \"price\":\"0.74\", \"size\":\"379.24\", \"side\":\"SELL\", \"hash\":\"2c5dcbab34ff520e7656321f8ee44f08c60db1fa\", \"best_bid\":\"0.47\", \"best_ask\":\"0.48\"}], \"timestamp\":\"1785129960626\", \"event_type\":\"price_change\"}","received_at":"2026-07-27T05:26:00.594590Z","schema_version":"clob-market-ws.price_change.v1","sequence":null,"server_hash":null,"server_timestamp":"1785129960626","session_id":"502006c5cfcd437296561ea750c9ec8b","source":"clob_market_ws"},"received_at":"2026-07-27T05:26:00.594590Z","record_id":"130e368a62aab89729cc2f4e625e200f0c32546b9ffcf2ed801b5a5184b47e8c","schema_fingerprint":"4aa3821a28b0b7c2400bc59aba4bcc0a76e971dadd19610d3ad38c768e124dc7","schema_version":"edge-lab-recorder.raw.v1","sequence":null,"source":"clob_market_ws"}
{"event_at":"2026-07-27T05:26:00.626000Z","event_fingerprint":"3dd6586f6dca7ac8aecf645335e9c9dbb1ef1777e7fe6ec5ba08504de37118fd","payload":{"connection_id":"efc69d3132f1467b8e898a382b23ac0d","event_at":"2026-07-27T05:26:00.626000Z","event_type":"price_change","frame_hash":"455738a2bdc6356d386fa895aa61ab4b2cc760cec344a0fd7ca808cde11d5906","frame_index":0,"kind":"data","monotonic_ns":231943842042208,"payload":{"event_type":"price_change","market":"0x3b40066b5cf3871a2f6237c5628bd8092a206aa998558ac5ec13c4483e31e160","price_changes":[{"asset_id":"110216635572655435074987471276357323571387854733835379371586402147734167783946","best_ask":"0.53","best_bid":"0.52","hash":"b361fb3d1584ebea73799fd269e9c8e994a016b8","price":"0.33","side":"BUY","size":"586.16"},{"asset_id":"14766054693214075530629349735273995982307625376442606753688071083149620216746","best_ask":"0.48","best_bid":"0.47","hash":"db4b26095b78b775bccc59b6700b278afdf0a5d6","price":"0.67","side":"SELL","size":"586.16"}],"timestamp":"1785129960626"},"payload_hash":"5d7f57ecbeaa12454ff89555407ed6b05d00eba6a942abffa53e8add849c6197","raw_frame":"{\"market\":\"0x3b40066b5cf3871a2f6237c5628bd8092a206aa998558ac5ec13c4483e31e160\", \"price_changes\":[{\"asset_id\":\"110216635572655435074987471276357323571387854733835379371586402147734167783946\", \"price\":\"0.33\", \"size\":\"586.16\", \"side\":\"BUY\", \"hash\":\"b361fb3d1584ebea73799fd269e9c8e994a016b8\", \"best_bid\":\"0.52\", \"best_ask\":\"0.53\"}, {\"asset_id\":\"14766054693214075530629349735273995982307625376442606753688071083149620216746\", \"price\":\"0.67\", \"size\":\"586.16\", \"side\":\"SELL\", \"hash\":\"db4b26095b78b775bccc59b6700b278afdf0a5d6\", \"best_bid\":\"0.47\", \"best_ask\":\"0.48\"}], \"timestamp\":\"1785129960626\", \"event_type\":\"price_change\"}","received_at":"2026-07-27T05:26:00.602164Z","schema_version":"clob-market-ws.price_change.v1","sequence":null,"server_hash":null,"server_timestamp":"1785129960626","session_id":"502006c5cfcd437296561ea750c9ec8b","source":"clob_market_ws"},"received_at":"2026-07-27T05:26:00.602164Z","record_id":"8c2620cd20b478766335c28a11afaa4e8c22c1152c094b99f6b9a2b918fad16b","schema_fingerprint":"4aa3821a28b0b7c2400bc59aba4bcc0a76e971dadd19610d3ad38c768e124dc7","schema_version":"edge-lab-recorder.raw.v1","sequence":null,"source":"clob_market_ws"}
{"event_at":"2026-07-27T05:26:00.705000Z","event_fingerprint":"5e2566aa2cafd0c50736826f63a2fa913e3f48f0a2f36acc8e71afc6ac529728","payload":{"connection_id":"efc69d3132f1467b8e898a382b23ac0d","event_at":"2026-07-27T05:26:00.705000Z","event_type":"price_change","frame_hash":"7c98cc766a2e880b7cf906312ad28aeb719f92d3b19197072bcc16b944689c48","frame_index":0,"kind":"data","monotonic_ns":231943908370375,"payload":{"event_type":"price_change","market":"0x3b40066b5cf3871a2f6237c5628bd8092a206aa998558ac5ec13c4483e31e160","price_changes":[{"asset_id":"14766054693214075530629349735273995982307625376442606753688071083149620216746","best_ask":"0.48","best_bid":"0.47","hash":"6b03dd90166e5775efe76685a78fd78599adc64c","price":"0.26","side":"BUY","size":"379.24"},{"asset_id":"110216635572655435074987471276357323571387854733835379371586402147734167783946","best_ask":"0.53","best_bid":"0.52","hash":"451b4554f9344849c4f59bb7baff9f1c1c42cc88","price":"0.74","side":"SELL","size":"379.24"}],"timestamp":"1785129960705"},"payload_hash":"7d43a5369f1b16578632a27d70743aea9e0cb6ec1bbd19344576b3db7e1ef0bf","raw_frame":"{\"market\":\"0x3b40066b5cf3871a2f6237c5628bd8092a206aa998558ac5ec13c4483e31e160\", \"price_changes\":[{\"asset_id\":\"14766054693214075530629349735273995982307625376442606753688071083149620216746\", \"price\":\"0.26\", \"size\":\"379.24\", \"side\":\"BUY\", \"hash\":\"6b03dd90166e5775efe76685a78fd78599adc64c\", \"best_bid\":\"0.47\", \"best_ask\":\"0.48\"}, {\"asset_id\":\"110216635572655435074987471276357323571387854733835379371586402147734167783946\", \"price\":\"0.74\", \"size\":\"379.24\", \"side\":\"SELL\", \"hash\":\"451b4554f9344849c4f59bb7baff9f1c1c42cc88\", \"best_bid\":\"0.52\", \"best_ask\":\"0.53\"}], \"timestamp\":\"1785129960705\", \"event_type\":\"price_change\"}","received_at":"2026-07-27T05:26:00.668489Z","schema_version":"clob-market-ws.price_change.v1","sequence":null,"server_hash":null,"server_timestamp":"1785129960705","session_id":"502006c5cfcd437296561ea750c9ec8b","source":"clob_market_ws"},"received_at":"2026-07-27T05:26:00.668489Z","record_id":"025182b251d502135b9b9aac8bab686a54ce5e1bc13e71aed26a9571bc882041","schema_fingerprint":"4aa3821a28b0b7c2400bc59aba4bcc0a76e971dadd19610d3ad38c768e124dc7","schema_version":"edge-lab-recorder.raw.v1","sequence":null,"source":"clob_market_ws"}
{"event_at":"2026-07-27T05:26:00.706000Z","event_fingerprint":"ad81299757360e0f7799a2110f8086a9f57d2cfbf74ded49670f904bd4ea2f57","payload":{"connection_id":"efc69d3132f1467b8e898a382b23ac0d","event_at":"2026-07-27T05:26:00.706000Z","event_type":"price_change","frame_hash":"8a51e140e0fe873e4b0aa2a93c5cbc855ab6ca6355755b8256e3de5d1a894a5b","frame_index":0,"kind":"data","monotonic_ns":231943911665083,"payload":{"event_type":"price_change","market":"0x3b40066b5cf3871a2f6237c5628bd8092a206aa998558ac5ec13c4483e31e160","price_changes":[{"asset_id":"14766054693214075530629349735273995982307625376442606753688071083149620216746","best_ask":"0.48","best_bid":"0.47","hash":"2540ba1ba340c08678275b55ebdc9df18683f4ed","price":"0.2","side":"BUY","size":"1245"},{"asset_id":"110216635572655435074987471276357323571387854733835379371586402147734167783946","best_ask":"0.53","best_bid":"0.52","hash":"a18107de3e623b38bf1fe569da67a73d86894016","price":"0.8","side":"SELL","size":"1245"}],"timestamp":"1785129960706"},"payload_hash":"68cebb8e011f818664432e6e31e6d2184ffcd045e7542d1e580b6cef0bf0eebf","raw_frame":"{\"market\":\"0x3b40066b5cf3871a2f6237c5628bd8092a206aa998558ac5ec13c4483e31e160\", \"price_changes\":[{\"asset_id\":\"14766054693214075530629349735273995982307625376442606753688071083149620216746\", \"price\":\"0.2\", \"size\":\"1245\", \"side\":\"BUY\", \"hash\":\"2540ba1ba340c08678275b55ebdc9df18683f4ed\", \"best_bid\":\"0.47\", \"best_ask\":\"0.48\"}, {\"asset_id\":\"110216635572655435074987471276357323571387854733835379371586402147734167783946\", \"price\":\"0.8\", \"size\":\"1245\", \"side\":\"SELL\", \"hash\":\"a18107de3e623b38bf1fe569da67a73d86894016\", \"best_bid\":\"0.52\", \"best_ask\":\"0.53\"}], \"timestamp\":\"1785129960706\", \"event_type\":\"price_change\"}","received_at":"2026-07-27T05:26:00.671788Z","schema_version":"clob-market-ws.price_change.v1","sequence":null,"server_hash":null,"server_timestamp":"1785129960706","session_id":"502006c5cfcd437296561ea750c9ec8b","source":"clob_market_ws"},"received_at":"2026-07-27T05:26:00.671788Z","record_id":"1035cdaa895ed8d2dd5ea850665a9f1a9d6c3d6cb948a7b7a85a6e92d09e46f9","schema_fingerprint":"4aa3821a28b0b7c2400bc59aba4bcc0a76e971dadd19610d3ad38c768e124dc7","schema_version":"edge-lab-recorder.raw.v1","sequence":null,"source":"clob_market_ws"}
{"event_at":"2026-07-27T05:26:00.747000Z","event_fingerprint":"7d57c53f1ab1b499617730457048bdbfedecd1a56271bac7a7f3a95f3dc42d32","payload":{"connection_id":"efc69d3132f1467b8e898a382b23ac0d","event_at":"2026-07-27T05:26:00.747000Z","event_type":"price_change","frame_hash":"7eb523cd2aa7675e4b24e73d5912ca39d3d70c830762293dbf551e8888e6350d","frame_index":0,"kind":"data","monotonic_ns":231943950045833,"payload":{"event_type":"price_change","market":"0x3b40066b5cf3871a2f6237c5628bd8092a206aa998558ac5ec13c4483e31e160","price_changes":[{"asset_id":"110216635572655435074987471276357323571387854733835379371586402147734167783946","best_ask":"0.53","best_bid":"0.52","hash":"d9774c7dc97f3bb6d994340a61aa8dec355b9d0a","price":"0.13","side":"BUY","size":"58.47"},{"asset_id":"14766054693214075530629349735273995982307625376442606753688071083149620216746","best_ask":"0.48","best_bid":"0.47","hash":"468cafee8dbabdbb2fded22460aa7fdb906d1409","price":"0.87","side":"SELL","size":"58.47"}],"timestamp":"1785129960747"},"payload_hash":"15f96563184e011551aa8295ad4fdf394dee1f9269530634ff2c5b9051adaf67","raw_frame":"{\"market\":\"0x3b40066b5cf3871a2f6237c5628bd8092a206aa998558ac5ec13c4483e31e160\", \"price_changes\":[{\"asset_id\":\"110216635572655435074987471276357323571387854733835379371586402147734167783946\", \"price\":\"0.13\", \"size\":\"58.47\", \"side\":\"BUY\", \"hash\":\"d9774c7dc97f3bb6d994340a61aa8dec355b9d0a\", \"best_bid\":\"0.52\", \"best_ask\":\"0.53\"}, {\"asset_id\":\"14766054693214075530629349735273995982307625376442606753688071083149620216746\", \"price\":\"0.87\", \"size\":\"58.47\", \"side\":\"SELL\", \"hash\":\"468cafee8dbabdbb2fded22460aa7fdb906d1409\", \"best_bid\":\"0.47\", \"best_ask\":\"0.48\"}], \"timestamp\":\"1785129960747\", \"event_type\":\"price_change\"}","received_at":"2026-07-27T05:26:00.710168Z","schema_version":"clob-market-ws.price_change.v1","sequence":null,"server_hash":null,"server_timestamp":"1785129960747","session_id":"502006c5cfcd437296561ea750c9ec8b","source":"clob_market_ws"},"received_at":"2026-07-27T05:26:00.710168Z","record_id":"2c6e8367f25ee0812da26a2cafd5de6eeac74903af2ed27fd21e5346aaaa5b56","schema_fingerprint":"4aa3821a28b0b7c2400bc59aba4bcc0a76e971dadd19610d3ad38c768e124dc7","schema_version":"edge-lab-recorder.raw.v1","sequence":null,"source":"clob_market_ws"}
{"event_at":"2026-07-27T05:26:00.748000Z","event_fingerprint":"b9f1c8fb3c7472fe84525b018eb80e448a9a933ed93deef7d9fae58f0f8a43ad","payload":{"connection_id":"efc69d3132f1467b8e898a382b23ac0d","event_at":"2026-07-27T05:26:00.748000Z","event_type":"price_change","frame_hash":"38c4246ff53c3809589b2d5cae34d5f095f1df68d300e0fd67322ad0973d8323","frame_index":0,"kind":"data","monotonic_ns":231943956402958,"payload":{"event_type":"price_change","market":"0x3b40066b5cf3871a2f6237c5628bd8092a206aa998558ac5ec13c4483e31e160","price_changes":[{"asset_id":"110216635572655435074987471276357323571387854733835379371586402147734167783946","best_ask":"0.53","best_bid":"0.52","hash":"083677e154566079b6e06186b9336972984c7a0d","price":"0.44","side":"BUY","size":"242.05"},{"asset_id":"14766054693214075530629349735273995982307625376442606753688071083149620216746","best_ask":"0.48","best_bid":"0.47","hash":"9cdf8a3972c5dd82afa7a8a6f2033771669526dc","price":"0.56","side":"SELL","size":"242.05"}],"timestamp":"1785129960748"},"payload_hash":"f073c5fda3694aba35ef815661c6d9fca2007e8ca471a1751fe17e1483c23d1c","raw_frame":"{\"market\":\"0x3b40066b5cf3871a2f6237c5628bd8092a206aa998558ac5ec13c4483e31e160\", \"price_changes\":[{\"asset_id\":\"110216635572655435074987471276357323571387854733835379371586402147734167783946\", \"price\":\"0.44\", \"size\":\"242.05\", \"side\":\"BUY\", \"hash\":\"083677e154566079b6e06186b9336972984c7a0d\", \"best_bid\":\"0.52\", \"best_ask\":\"0.53\"}, {\"asset_id\":\"14766054693214075530629349735273995982307625376442606753688071083149620216746\", \"price\":\"0.56\", \"size\":\"242.05\", \"side\":\"SELL\", \"hash\":\"9cdf8a3972c5dd82afa7a8a6f2033771669526dc\", \"best_bid\":\"0.47\", \"best_ask\":\"0.48\"}], \"timestamp\":\"1785129960748\", \"event_type\":\"price_change\"}","received_at":"2026-07-27T05:26:00.716525Z","schema_version":"clob-market-ws.price_change.v1","sequence":null,"server_hash":null,"server_timestamp":"1785129960748","session_id":"502006c5cfcd437296561ea750c9ec8b","source":"clob_market_ws"},"received_at":"2026-07-27T05:26:00.716525Z","record_id":"118dc4813b6f108962a99d89d9ff895cc22471b7965e95dc5df28a56cebc2dc5","schema_fingerprint":"4aa3821a28b0b7c2400bc59aba4bcc0a76e971dadd19610d3ad38c768e124dc7","schema_version":"edge-lab-recorder.raw.v1","sequence":null,"source":"clob_market_ws"}
{"event_at":"2026-07-27T05:26:00.803000Z","event_fingerprint":"f3fa4cb224af9735c27df6c677bfee138e0c12bc31e1bb46e870716d220d6393","payload":{"connection_id":"efc69d3132f1467b8e898a382b23ac0d","event_at":"2026-07-27T05:26:00.803000Z","event_type":"price_change","frame_hash":"a1764b32daf00591cd0f2c5858a801ea7514bf055c21ae4e1aa3e3eb04224d4e","frame_index":0,"kind":"data","monotonic_ns":231944005537500,"payload":{"event_type":"price_change","market":"0x3b40066b5cf3871a2f6237c5628bd8092a206aa998558ac5ec13c4483e31e160","price_changes":[{"asset_id":"14766054693214075530629349735273995982307625376442606753688071083149620216746","best_ask":"0.48","best_bid":"0.47","hash":"267aa69b2e25ad3c59427c30496f2270f55b00e0","price":"0.07","side":"BUY","size":"591.44"},{"asset_id":"110216635572655435074987471276357323571387854733835379371586402147734167783946","best_ask":"0.53","best_bid":"0.52","hash":"3907e8c87cd08a046c6d7c9a4fc8859647b5ba9a","price":"0.93","side":"SELL","size":"591.44"}],"timestamp":"1785129960803"},"payload_hash":"de79644046af6f8a4c4b6d53e28763428e78a78ce8add6b965094b8322b10172","raw_frame":"{\"market\":\"0x3b40066b5cf3871a2f6237c5628bd8092a206aa998558ac5ec13c4483e31e160\", \"price_changes\":[{\"asset_id\":\"14766054693214075530629349735273995982307625376442606753688071083149620216746\", \"price\":\"0.07\", \"size\":\"591.44\", \"side\":\"BUY\", \"hash\":\"267aa69b2e25ad3c59427c30496f2270f55b00e0\", \"best_bid\":\"0.47\", \"best_ask\":\"0.48\"}, {\"asset_id\":\"110216635572655435074987471276357323571387854733835379371586402147734167783946\", \"price\":\"0.93\", \"size\":\"591.44\", \"side\":\"SELL\", \"hash\":\"3907e8c87cd08a046c6d7c9a4fc8859647b5ba9a\", \"best_bid\":\"0.52\", \"best_ask\":\"0.53\"}], \"timestamp\":\"1785129960803\", \"event_type\":\"price_change\"}","received_at":"2026-07-27T05:26:00.765660Z","schema_version":"clob-market-ws.price_change.v1","sequence":null,"server_hash":null,"server_timestamp":"1785129960803","session_id":"502006c5cfcd437296561ea750c9ec8b","source":"clob_market_ws"},"received_at":"2026-07-27T05:26:00.765660Z","record_id":"f6bf701ef8b5c8ca4d008006f3f27fdd7ef4cebe900ba5a90ccacd29a5e9507c","schema_fingerprint":"4aa3821a28b0b7c2400bc59aba4bcc0a76e971dadd19610d3ad38c768e124dc7","schema_version":"edge-lab-recorder.raw.v1","sequence":null,"source":"clob_market_ws"}
{"event_at":"2026-07-27T05:26:00.842000Z","event_fingerprint":"0af1169830bb5c4fc0d629fdad6c28478f0d9f6cb55d24d26a2f425ca32af9a1","payload":{"connection_id":"efc69d3132f1467b8e898a382b23ac0d","event_at":"2026-07-27T05:26:00.842000Z","event_type":"price_change","frame_hash":"248dc7380d736d56ffd46f8fa9f86ee4bccb2863cfe8f61fc88341789bee4bbc","frame_index":0,"kind":"data","monotonic_ns":231944042292791,"payload":{"event_type":"price_change","market":"0x3b40066b5cf3871a2f6237c5628bd8092a206aa998558ac5ec13c4483e31e160","price_changes":[{"asset_id":"110216635572655435074987471276357323571387854733835379371586402147734167783946","best_ask":"0.53","best_bid":"0.52","hash":"e9ad7f1ba797029247f5e23baa7d45232265c470","price":"0.24","side":"BUY","size":"833.34"},{"asset_id":"14766054693214075530629349735273995982307625376442606753688071083149620216746","best_ask":"0.48","best_bid":"0.47","hash":"aa210942ba103f0ca19958b24731988e4b8e5f73","price":"0.76","side":"SELL","size":"833.34"}],"timestamp":"1785129960842"},"payload_hash":"2d4f859d3b1beac5949d68b5389ffe84d7030f1122c9b5f8fd2e110e9593d813","raw_frame":"{\"market\":\"0x3b40066b5cf3871a2f6237c5628bd8092a206aa998558ac5ec13c4483e31e160\", \"price_changes\":[{\"asset_id\":\"110216635572655435074987471276357323571387854733835379371586402147734167783946\", \"price\":\"0.24\", \"size\":\"833.34\", \"side\":\"BUY\", \"hash\":\"e9ad7f1ba797029247f5e23baa7d45232265c470\", \"best_bid\":\"0.52\", \"best_ask\":\"0.53\"}, {\"asset_id\":\"14766054693214075530629349735273995982307625376442606753688071083149620216746\", \"price\":\"0.76\", \"size\":\"833.34\", \"side\":\"SELL\", \"hash\":\"aa210942ba103f0ca19958b24731988e4b8e5f73\", \"best_bid\":\"0.47\", \"best_ask\":\"0.48\"}], \"timestamp\":\"1785129960842\", \"event_type\":\"price_change\"}","received_at":"2026-07-27T05:26:00.802415Z","schema_version":"clob-market-ws.price_change.v1","sequence":null,"server_hash":null,"server_timestamp":"1785129960842","session_id":"502006c5cfcd437296561ea750c9ec8b","source":"clob_market_ws"},"received_at":"2026-07-27T05:26:00.802415Z","record_id":"3b78b5fc5f7d82d989db9d66880ad5c355fa5127b5b8e509ba048aaee79bcefc","schema_fingerprint":"4aa3821a28b0b7c2400bc59aba4bcc0a76e971dadd19610d3ad38c768e124dc7","schema_version":"edge-lab-recorder.raw.v1","sequence":null,"source":"clob_market_ws"}
{"event_at":"2026-07-27T05:26:00.843000Z","event_fingerprint":"0486a8e33611fc2f12eb639dbac3468b7d48f5f0eaefb4688189bce9a3fa0a4b","payload":{"connection_id":"efc69d3132f1467b8e898a382b23ac0d","event_at":"2026-07-27T05:26:00.843000Z","event_type":"price_change","frame_hash":"6c165b35cdb053281d51f03d5ae940c27d61e19c2b8d0e4c03b30502c4ff75bc","frame_index":0,"kind":"data","monotonic_ns":231944045540166,"payload":{"event_type":"price_change","market":"0x3b40066b5cf3871a2f6237c5628bd8092a206aa998558ac5ec13c4483e31e160","price_changes":[{"asset_id":"110216635572655435074987471276357323571387854733835379371586402147734167783946","best_ask":"0.53","best_bid":"0.52","hash":"9a502b62556f191590a3535297fdc643a153fbf7","price":"0.1","side":"BUY","size":"3188"},{"asset_id":"14766054693214075530629349735273995982307625376442606753688071083149620216746","best_ask":"0.48","best_bid":"0.47","hash":"70cba29edbe1c88178fc7312dfdacc10ff6fe036","price":"0.9","side":"SELL","size":"3188"}],"timestamp":"1785129960843"},"payload_hash":"7292e78ba77284775df06ca8ae231ff5d531f1b0205b2b9cdd8dd7df7ef1cedf","raw_frame":"{\"market\":\"0x3b40066b5cf3871a2f6237c5628bd8092a206aa998558ac5ec13c4483e31e160\", \"price_changes\":[{\"asset_id\":\"110216635572655435074987471276357323571387854733835379371586402147734167783946\", \"price\":\"0.1\", \"size\":\"3188\", \"side\":\"BUY\", \"hash\":\"9a502b62556f191590a3535297fdc643a153fbf7\", \"best_bid\":\"0.52\", \"best_ask\":\"0.53\"}, {\"asset_id\":\"14766054693214075530629349735273995982307625376442606753688071083149620216746\", \"price\":\"0.9\", \"size\":\"3188\", \"side\":\"SELL\", \"hash\":\"70cba29edbe1c88178fc7312dfdacc10ff6fe036\", \"best_bid\":\"0.47\", \"best_ask\":\"0.48\"}], \"timestamp\":\"1785129960843\", \"event_type\":\"price_change\"}","received_at":"2026-07-27T05:26:00.805662Z","schema_version":"clob-market-ws.price_change.v1","sequence":null,"server_hash":null,"server_timestamp":"1785129960843","session_id":"502006c5cfcd437296561ea750c9ec8b","source":"clob_market_ws"},"received_at":"2026-07-27T05:26:00.805662Z","record_id":"3ea82f60f13ea9357f155becfe926de8b608c85099526a2c70224ea60dc8849a","schema_fingerprint":"4aa3821a28b0b7c2400bc59aba4bcc0a76e971dadd19610d3ad38c768e124dc7","schema_version":"edge-lab-recorder.raw.v1","sequence":null,"source":"clob_market_ws"}
{"event_at":"2026-07-27T05:26:00.844000Z","event_fingerprint":"d1fe22a7a477407dab8c8f6429274f0ff0baf0b9dd07d0b7ce84ac9a40b8fb44","payload":{"connection_id":"efc69d3132f1467b8e898a382b23ac0d","event_at":"2026-07-27T05:26:00.844000Z","event_type":"price_change","frame_hash":"4414dbe9ad9525b971a903d80d2e56de96450e0bb76bfc049e33a721b537a3bd","frame_index":0,"kind":"data","monotonic_ns":231944048639375,"payload":{"event_type":"price_change","market":"0x3b40066b5cf3871a2f6237c5628bd8092a206aa998558ac5ec13c4483e31e160","price_changes":[{"asset_id":"110216635572655435074987471276357323571387854733835379371586402147734167783946","best_ask":"0.53","best_bid":"0.52","hash":"a022f71840ce6e371be5a89ba0e726fdc85ea056","price":"0.2","side":"BUY","size":"1245"},{"asset_id":"14766054693214075530629349735273995982307625376442606753688071083149620216746","best_ask":"0.48","best_bid":"0.47","hash":"5c8a7eba550e4bbdd40ee8455a1c1faf7eb4645c","price":"0.8","side":"SELL","size":"1245"}],"timestamp":"1785129960844"},"payload_hash":"61abcdab8a00225cdf14eac329c7337971b00129465d7d661afc3e1e01d5711f","raw_frame":"{\"market\":\"0x3b40066b5cf3871a2f6237c5628bd8092a206aa998558ac5ec13c4483e31e160\", \"price_changes\":[{\"asset_id\":\"110216635572655435074987471276357323571387854733835379371586402147734167783946\", \"price\":\"0.2\", \"size\":\"1245\", \"side\":\"BUY\", \"hash\":\"a022f71840ce6e371be5a89ba0e726fdc85ea056\", \"best_bid\":\"0.52\", \"best_ask\":\"0.53\"}, {\"asset_id\":\"14766054693214075530629349735273995982307625376442606753688071083149620216746\", \"price\":\"0.8\", \"size\":\"1245\", \"side\":\"SELL\", \"hash\":\"5c8a7eba550e4bbdd40ee8455a1c1faf7eb4645c\", \"best_bid\":\"0.47\", \"best_ask\":\"0.48\"}], \"timestamp\":\"1785129960844\", \"event_type\":\"price_change\"}","received_at":"2026-07-27T05:26:00.808762Z","schema_version":"clob-market-ws.price_change.v1","sequence":null,"server_hash":null,"server_timestamp":"1785129960844","session_id":"502006c5cfcd437296561ea750c9ec8b","source":"clob_market_ws"},"received_at":"2026-07-27T05:26:00.808762Z","record_id":"a0352341b99bdb1f765b72ae472f2e50cad3f923eb3d46dca4561177e08710d9","schema_fingerprint":"4aa3821a28b0b7c2400bc59aba4bcc0a76e971dadd19610d3ad38c768e124dc7","schema_version":"edge-lab-recorder.raw.v1","sequence":null,"source":"clob_market_ws"}
{"event_at":"2026-07-27T05:26:00.845000Z","event_fingerprint":"e238c64ac7d94306eb7b950cdb609dd4f20007d94b0bab492bf672eb459c7d18","payload":{"connection_id":"efc69d3132f1467b8e898a382b23ac0d","event_at":"2026-07-27T05:26:00.845000Z","event_type":"price_change","frame_hash":"2fa9205924cadd59a488469588bc57bc0334c8eed48132011a5f656f4e6028ef","frame_index":0,"kind":"data","monotonic_ns":231944053299333,"payload":{"event_type":"price_change","market":"0x3b40066b5cf3871a2f6237c5628bd8092a206aa998558ac5ec13c4483e31e160","price_changes":[{"asset_id":"14766054693214075530629349735273995982307625376442606753688071083149620216746","best_ask":"0.48","best_bid":"0.47","hash":"18d6e3445c78820bc05940cf91f9550dda27abda","price":"0.33","side":"BUY","size":"441.16"},{"asset_id":"110216635572655435074987471276357323571387854733835379371586402147734167783946","best_ask":"0.53","best_bid":"0.52","hash":"fdce81274cb4bc927fff7c7109796e25fcf34d20","price":"0.67","side":"SELL","size":"441.16"}],"timestamp":"1785129960845"},"payload_hash":"598a807dcacb5b7510443d6945ce61cb3439b8b2d5c6d343e0589c78ba497e62","raw_frame":"{\"market\":\"0x3b40066b5cf3871a2f6237c5628bd8092a206aa998558ac5ec13c4483e31e160\", \"price_changes\":[{\"asset_id\":\"14766054693214075530629349735273995982307625376442606753688071083149620216746\", \"price\":\"0.33\", \"size\":\"441.16\", \"side\":\"BUY\", \"hash\":\"18d6e3445c78820bc05940cf91f9550dda27abda\", \"best_bid\":\"0.47\", \"best_ask\":\"0.48\"}, {\"asset_id\":\"110216635572655435074987471276357323571387854733835379371586402147734167783946\", \"price\":\"0.67\", \"size\":\"441.16\", \"side\":\"SELL\", \"hash\":\"fdce81274cb4bc927fff7c7109796e25fcf34d20\", \"best_bid\":\"0.52\", \"best_ask\":\"0.53\"}], \"timestamp\":\"1785129960845\", \"event_type\":\"price_change\"}","received_at":"2026-07-27T05:26:00.813429Z","schema_version":"clob-market-ws.price_change.v1","sequence":null,"server_hash":null,"server_timestamp":"1785129960845","session_id":"502006c5cfcd437296561ea750c9ec8b","source":"clob_market_ws"},"received_at":"2026-07-27T05:26:00.813429Z","record_id":"7e858cd357a20db893ac25e86aee7fd82a1e0a7ac92379ce657bb41ccd4e4f9e","schema_fingerprint":"4aa3821a28b0b7c2400bc59aba4bcc0a76e971dadd19610d3ad38c768e124dc7","schema_version":"edge-lab-recorder.raw.v1","sequence":null,"source":"clob_market_ws"}
{"event_at":"2026-07-27T05:26:00.846000Z","event_fingerprint":"4cb9cd2e058b154676147e422019f00aa917c40a1ee162b4d5b472eda86cb6b6","payload":{"connection_id":"efc69d3132f1467b8e898a382b23ac0d","event_at":"2026-07-27T05:26:00.846000Z","event_type":"price_change","frame_hash":"b1282b74af10cf449ebec839507bf217e05a93e835916688fe5de8190b9fbcf7","frame_index":0,"kind":"data","monotonic_ns":231944056787083,"payload":{"event_type":"price_change","market":"0x3b40066b5cf3871a2f6237c5628bd8092a206aa998558ac5ec13c4483e31e160","price_changes":[{"asset_id":"14766054693214075530629349735273995982307625376442606753688071083149620216746","best_ask":"0.48","best_bid":"0.47","hash":"311a9d953928a798913828c2195634d442ed07de","price":"0.2","side":"BUY","size":"1789"},{"asset_id":"110216635572655435074987471276357323571387854733835379371586402147734167783946","best_ask":"0.53","best_bid":"0.52","hash":"49d3c3e78d3ab0bf97c2c58264a7dc0f8833bffd","price":"0.8","side":"SELL","size":"1789"}],"timestamp":"1785129960846"},"payload_hash":"3f3b2529862e0fb2bacb4016b222409f5ca909db56589c6cf4c7a276d5b9dc3f","raw_frame":"{\"market\":\"0x3b40066b5cf3871a2f6237c5628bd8092a206aa998558ac5ec13c4483e31e160\", \"price_changes\":[{\"asset_id\":\"14766054693214075530629349735273995982307625376442606753688071083149620216746\", \"price\":\"0.2\", \"size\":\"1789\", \"side\":\"BUY\", \"hash\":\"311a9d953928a798913828c2195634d442ed07de\", \"best_bid\":\"0.47\", \"best_ask\":\"0.48\"}, {\"asset_id\":\"110216635572655435074987471276357323571387854733835379371586402147734167783946\", \"price\":\"0.8\", \"size\":\"1789\", \"side\":\"SELL\", \"hash\":\"49d3c3e78d3ab0bf97c2c58264a7dc0f8833bffd\", \"best_bid\":\"0.52\", \"best_ask\":\"0.53\"}], \"timestamp\":\"1785129960846\", \"event_type\":\"price_change\"}","received_at":"2026-07-27T05:26:00.816910Z","schema_version":"clob-market-ws.price_change.v1","sequence":null,"server_hash":null,"server_timestamp":"1785129960846","session_id":"502006c5cfcd437296561ea750c9ec8b","source":"clob_market_ws"},"received_at":"2026-07-27T05:26:00.816910Z","record_id":"357d58bf70bda70d54ec4a971fa720dc74d6a53c99f0dd73d7d20a642c5aae6b","schema_fingerprint":"4aa3821a28b0b7c2400bc59aba4bcc0a76e971dadd19610d3ad38c768e124dc7","schema_version":"edge-lab-recorder.raw.v1","sequence":null,"source":"clob_market_ws"}
{"event_at":"2026-07-27T05:26:00.847000Z","event_fingerprint":"0d5ec9cb063a6a0bd62851a84b7de3c2bd2bb1132fbd7505d38540d742903f9c","payload":{"connection_id":"efc69d3132f1467b8e898a382b23ac0d","event_at":"2026-07-27T05:26:00.847000Z","event_type":"price_change","frame_hash":"08a6f3a6bb6040cac24ac13b70b59cfde0f7f679a91bb0ead5eaa7041263fc43","frame_index":0,"kind":"data","monotonic_ns":231944060420750,"payload":{"event_type":"price_change","market":"0x3b40066b5cf3871a2f6237c5628bd8092a206aa998558ac5ec13c4483e31e160","price_changes":[{"asset_id":"14766054693214075530629349735273995982307625376442606753688071083149620216746","best_ask":"0.48","best_bid":"0.47","hash":"18214119e96c8cada9694a4cebbac7068a7bf1be","price":"0.44","side":"BUY","size":"167.05"},{"asset_id":"110216635572655435074987471276357323571387854733835379371586402147734167783946","best_ask":"0.53","best_bid":"0.52","hash":"c9b4f4ffb3bc15fba22b50b86c0ce948795a00b3","price":"0.56","side":"SELL","size":"167.05"}],"timestamp":"1785129960847"},"payload_hash":"a755e3ab9172ca2b6b205dc204c3dff5e5ab2a40654cffae77e7c0e0c4718e7b","raw_frame":"{\"market\":\"0x3b40066b5cf3871a2f6237c5628bd8092a206aa998558ac5ec13c4483e31e160\", \"price_changes\":[{\"asset_id\":\"14766054693214075530629349735273995982307625376442606753688071083149620216746\", \"price\":\"0.44\", \"size\":\"167.05\", \"side\":\"BUY\", \"hash\":\"18214119e96c8cada9694a4cebbac7068a7bf1be\", \"best_bid\":\"0.47\", \"best_ask\":\"0.48\"}, {\"asset_id\":\"110216635572655435074987471276357323571387854733835379371586402147734167783946\", \"price\":\"0.56\", \"size\":\"167.05\", \"side\":\"SELL\", \"hash\":\"c9b4f4ffb3bc15fba22b50b86c0ce948795a00b3\", \"best_bid\":\"0.52\", \"best_ask\":\"0.53\"}], \"timestamp\":\"1785129960847\", \"event_type\":\"price_change\"}","received_at":"2026-07-27T05:26:00.820545Z","schema_version":"clob-market-ws.price_change.v1","sequence":null,"server_hash":null,"server_timestamp":"1785129960847","session_id":"502006c5cfcd437296561ea750c9ec8b","source":"clob_market_ws"},"received_at":"2026-07-27T05:26:00.820545Z","record_id":"e0ee019de89f75c1c0af5defaf2eb8695c31466e0ca91d55ad3edf114e5da481","schema_fingerprint":"4aa3821a28b0b7c2400bc59aba4bcc0a76e971dadd19610d3ad38c768e124dc7","schema_version":"edge-lab-recorder.raw.v1","sequence":null,"source":"clob_market_ws"}
{"event_at":"2026-07-27T05:26:00.852000Z","event_fingerprint":"99c63dc4da0462e7f93ce1427d8945e6c0c847a4bad5d0cc653282e4866034a1","payload":{"connection_id":"efc69d3132f1467b8e898a382b23ac0d","event_at":"2026-07-27T05:26:00.852000Z","event_type":"price_change","frame_hash":"4fac5b0d7e0b77c61fc4d6d31b625b1e218768d56b63edb238dc3c2a72326775","frame_index":0,"kind":"data","monotonic_ns":231944062689958,"payload":{"event_type":"price_change","market":"0x3b40066b5cf3871a2f6237c5628bd8092a206aa998558ac5ec13c4483e31e160","price_changes":[{"asset_id":"110216635572655435074987471276357323571387854733835379371586402147734167783946","best_ask":"0.53","best_bid":"0.52","hash":"caa7351dc3e5bb00a6fec3a8526dc1478753833d","price":"0.2","side":"BUY","size":"1789"},{"asset_id":"14766054693214075530629349735273995982307625376442606753688071083149620216746","best_ask":"0.48","best_bid":"0.47","hash":"a201231ef5188b2e117aacfc83e0d40780cbfc7a","price":"0.8","side":"SELL","size":"1789"}],"timestamp":"1785129960852"},"payload_hash":"47d56483b59d6681d86ce328bb765e48c473c9d8db85a9c96abb1ecccbf1875b","raw_frame":"{\"market\":\"0x3b40066b5cf3871a2f6237c5628bd8092a206aa998558ac5ec13c4483e31e160\", \"price_changes\":[{\"asset_id\":\"110216635572655435074987471276357323571387854733835379371586402147734167783946\", \"price\":\"0.2\", \"size\":\"1789\", \"side\":\"BUY\", \"hash\":\"caa7351dc3e5bb00a6fec3a8526dc1478753833d\", \"best_bid\":\"0.52\", \"best_ask\":\"0.53\"}, {\"asset_id\":\"14766054693214075530629349735273995982307625376442606753688071083149620216746\", \"price\":\"0.8\", \"size\":\"1789\", \"side\":\"SELL\", \"hash\":\"a201231ef5188b2e117aacfc83e0d40780cbfc7a\", \"best_bid\":\"0.47\", \"best_ask\":\"0.48\"}], \"timestamp\":\"1785129960852\", \"event_type\":\"price_change\"}","received_at":"2026-07-27T05:26:00.822813Z","schema_version":"clob-market-ws.price_change.v1","sequence":null,"server_hash":null,"server_timestamp":"1785129960852","session_id":"502006c5cfcd437296561ea750c9ec8b","source":"clob_market_ws"},"received_at":"2026-07-27T05:26:00.822813Z","record_id":"20a34ee5294c518dc85f597ee7f5f666f24c18c494c3492f8b1e62dc39709451","schema_fingerprint":"4aa3821a28b0b7c2400bc59aba4bcc0a76e971dadd19610d3ad38c768e124dc7","schema_version":"edge-lab-recorder.raw.v1","sequence":null,"source":"clob_market_ws"}
{"event_at":"2026-07-27T05:26:00.886000Z","event_fingerprint":"2624d678fccc2603ccd239234361fd34a81ba1cc62cc41b16078110f3088fe99","payload":{"connection_id":"efc69d3132f1467b8e898a382b23ac0d","event_at":"2026-07-27T05:26:00.886000Z","event_type":"price_change","frame_hash":"90e0d21733b3905c4c84359acf2bb01cc87520f662b796eaa8948390bddcff4b","frame_index":0,"kind":"data","monotonic_ns":231944096556458,"payload":{"event_type":"price_change","market":"0x3b40066b5cf3871a2f6237c5628bd8092a206aa998558ac5ec13c4483e31e160","price_changes":[{"asset_id":"14766054693214075530629349735273995982307625376442606753688071083149620216746","best_ask":"0.48","best_bid":"0.47","hash":"ce5b301ccc35ff76b295dcfe43a93d61db0d67e6","price":"0.13","side":"BUY","size":"58.47"},{"asset_id":"110216635572655435074987471276357323571387854733835379371586402147734167783946","best_ask":"0.53","best_bid":"0.52","hash":"d33f9d62ddb74904008b35f48e44ae4913c1c625","price":"0.87","side":"SELL","size":"58.47"}],"timestamp":"1785129960886"},"payload_hash":"c01bcdded664280bf88496298684809d05fdcebb54e285b184e80eab36affb2b","raw_frame":"{\"market\":\"0x3b40066b5cf3871a2f6237c5628bd8092a206aa998558ac5ec13c4483e31e160\", \"price_changes\":[{\"asset_id\":\"14766054693214075530629349735273995982307625376442606753688071083149620216746\", \"price\":\"0.13\", \"size\":\"58.47\", \"side\":\"BUY\", \"hash\":\"ce5b301ccc35ff76b295dcfe43a93d61db0d67e6\", \"best_bid\":\"0.47\", \"best_ask\":\"0.48\"}, {\"asset_id\":\"110216635572655435074987471276357323571387854733835379371586402147734167783946\", \"price\":\"0.87\", \"size\":\"58.47\", \"side\":\"SELL\", \"hash\":\"d33f9d62ddb74904008b35f48e44ae4913c1c625\", \"best_bid\":\"0.52\", \"best_ask\":\"0.53\"}], \"timestamp\":\"1785129960886\", \"event_type\":\"price_change\"}","received_at":"2026-07-27T05:26:00.856679Z","schema_version":"clob-market-ws.price_change.v1","sequence":null,"server_hash":null,"server_timestamp":"1785129960886","session_id":"502006c5cfcd437296561ea750c9ec8b","source":"clob_market_ws"},"received_at":"2026-07-27T05:26:00.856679Z","record_id":"7847995d6dc3ce69b027f99c18ebba76178dd5baee1860951bc7b130e066fdd9","schema_fingerprint":"4aa3821a28b0b7c2400bc59aba4bcc0a76e971dadd19610d3ad38c768e124dc7","schema_version":"edge-lab-recorder.raw.v1","sequence":null,"source":"clob_market_ws"}
{"event_at":"2026-07-27T05:26:00.923000Z","event_fingerprint":"fd4cb8e562ab48c0ad0d395eb0b9db66bbecb0e50a7e5cb559683b238cde1faf","payload":{"connection_id":"efc69d3132f1467b8e898a382b23ac0d","event_at":"2026-07-27T05:26:00.923000Z","event_type":"price_change","frame_hash":"6241494d0e5dfec7a1b877e3ec8da9a2cdde3668d3d1f4f9d7dfeb65b05d72fa","frame_index":0,"kind":"data","monotonic_ns":231944124015041,"payload":{"event_type":"price_change","market":"0x3b40066b5cf3871a2f6237c5628bd8092a206aa998558ac5ec13c4483e31e160","price_changes":[{"asset_id":"110216635572655435074987471276357323571387854733835379371586402147734167783946","best_ask":"0.53","best_bid":"0.52","hash":"696e289d01bad9e6fb647f59956a305ec06235c7","price":"0.07","side":"BUY","size":"591.44"},{"asset_id":"14766054693214075530629349735273995982307625376442606753688071083149620216746","best_ask":"0.48","best_bid":"0.47","hash":"6fd28343c7455d32ac11ea3790e1bf25a1f75083","price":"0.93","side":"SELL","size":"591.44"}],"timestamp":"1785129960923"},"payload_hash":"c7b757c9c838b31e53c1a38d2213fae56a29106148a53d706d731b7d64f1721e","raw_frame":"{\"market\":\"0x3b40066b5cf3871a2f6237c5628bd8092a206aa998558ac5ec13c4483e31e160\", \"price_changes\":[{\"asset_id\":\"110216635572655435074987471276357323571387854733835379371586402147734167783946\", \"price\":\"0.07\", \"size\":\"591.44\", \"side\":\"BUY\", \"hash\":\"696e289d01bad9e6fb647f59956a305ec06235c7\", \"best_bid\":\"0.52\", \"best_ask\":\"0.53\"}, {\"asset_id\":\"14766054693214075530629349735273995982307625376442606753688071083149620216746\", \"price\":\"0.93\", \"size\":\"591.44\", \"side\":\"SELL\", \"hash\":\"6fd28343c7455d32ac11ea3790e1bf25a1f75083\", \"best_bid\":\"0.47\", \"best_ask\":\"0.48\"}], \"timestamp\":\"1785129960923\", \"event_type\":\"price_change\"}","received_at":"2026-07-27T05:26:00.884139Z","schema_version":"clob-market-ws.price_change.v1","sequence":null,"server_hash":null,"server_timestamp":"1785129960923","session_id":"502006c5cfcd437296561ea750c9ec8b","source":"clob_market_ws"},"received_at":"2026-07-27T05:26:00.884139Z","record_id":"ab0b925279269a0398d61fde830d5a50e7e3f60efaf72e7f4f01311599a1d1ca","schema_fingerprint":"4aa3821a28b0b7c2400bc59aba4bcc0a76e971dadd19610d3ad38c768e124dc7","schema_version":"edge-lab-recorder.raw.v1","sequence":null,"source":"clob_market_ws"}
{"event_at":"2026-07-27T05:26:00.945000Z","event_fingerprint":"b5387e3baad2ff1b19c13ebadaeaf8a859768c019e136d6c4d01a4d9bd6bf49c","payload":{"connection_id":"efc69d3132f1467b8e898a382b23ac0d","event_at":"2026-07-27T05:26:00.945000Z","event_type":"price_change","frame_hash":"1b7966a73c8d907a3077419848dd6564c16e72b03d58dd2a5e0a0873865b6890","frame_index":0,"kind":"data","monotonic_ns":231944144996375,"payload":{"event_type":"price_change","market":"0x3b40066b5cf3871a2f6237c5628bd8092a206aa998558ac5ec13c4483e31e160","price_changes":[{"asset_id":"14766054693214075530629349735273995982307625376442606753688071083149620216746","best_ask":"0.48","best_bid":"0.47","hash":"a455b01d965b2670e5c5d91ecd4a527f9d5af548","price":"0.32","side":"BUY","size":"745"},{"asset_id":"110216635572655435074987471276357323571387854733835379371586402147734167783946","best_ask":"0.53","best_bid":"0.52","hash":"fe8c18c72ceb533fbbafe8d4045fec7fe1ad1453","price":"0.68","side":"SELL","size":"745"}],"timestamp":"1785129960945"},"payload_hash":"66160410bdf684e8b9f04e71793f156b5244c6520e4281e2c27b8d031ea293da","raw_frame":"{\"market\":\"0x3b40066b5cf3871a2f6237c5628bd8092a206aa998558ac5ec13c4483e31e160\", \"price_changes\":[{\"asset_id\":\"14766054693214075530629349735273995982307625376442606753688071083149620216746\", \"price\":\"0.32\", \"size\":\"745\", \"side\":\"BUY\", \"hash\":\"a455b01d965b2670e5c5d91ecd4a527f9d5af548\", \"best_bid\":\"0.47\", \"best_ask\":\"0.48\"}, {\"asset_id\":\"110216635572655435074987471276357323571387854733835379371586402147734167783946\", \"price\":\"0.68\", \"size\":\"745\", \"side\":\"SELL\", \"hash\":\"fe8c18c72ceb533fbbafe8d4045fec7fe1ad1453\", \"best_bid\":\"0.52\", \"best_ask\":\"0.53\"}], \"timestamp\":\"1785129960945\", \"event_type\":\"price_change\"}","received_at":"2026-07-27T05:26:00.905118Z","schema_version":"clob-market-ws.price_change.v1","sequence":null,"server_hash":null,"server_timestamp":"1785129960945","session_id":"502006c5cfcd437296561ea750c9ec8b","source":"clob_market_ws"},"received_at":"2026-07-27T05:26:00.905118Z","record_id":"71eb34bbb3d82dff35af59e3ccca9e3c3f8fb54c08754fec6d05e6a3dac4865d","schema_fingerprint":"4aa3821a28b0b7c2400bc59aba4bcc0a76e971dadd19610d3ad38c768e124dc7","schema_version":"edge-lab-recorder.raw.v1","sequence":null,"source":"clob_market_ws"}
{"event_at":"2026-07-27T05:26:00.971000Z","event_fingerprint":"c743c949bb7ea59fc7400172abbba3f313e35a6cc4cfe49b9a76c16983d9b685","payload":{"connection_id":"efc69d3132f1467b8e898a382b23ac0d","event_at":"2026-07-27T05:26:00.971000Z","event_type":"price_change","frame_hash":"0c1d107611ce4772b4cc04688e139be77db341deacdb713a84707d476bc6bc07","frame_index":0,"kind":"data","monotonic_ns":231944171409833,"payload":{"event_type":"price_change","market":"0x3b40066b5cf3871a2f6237c5628bd8092a206aa998558ac5ec13c4483e31e160","price_changes":[{"asset_id":"14766054693214075530629349735273995982307625376442606753688071083149620216746","best_ask":"0.48","best_bid":"0.47","hash":"62d9d42b5953f38dbc246834a96eec4201888a6f","price":"0.24","side":"BUY","size":"833.34"},{"asset_id":"110216635572655435074987471276357323571387854733835379371586402147734167783946","best_ask":"0.53","best_bid":"0.52","hash":"63b28e9614fdc6b5c9d92cfb699925488e95f436","price":"0.76","side":"SELL","size":"833.34"}],"timestamp":"1785129960971"},"payload_hash":"65076a2c8560053c02fa0a35eef6fe8130f6b9cf6e9fb68bedd1a540c42a9b05","raw_frame":"{\"market\":\"0x3b40066b5cf3871a2f6237c5628bd8092a206aa998558ac5ec13c4483e31e160\", \"price_changes\":[{\"asset_id\":\"14766054693214075530629349735273995982307625376442606753688071083149620216746\", \"price\":\"0.24\", \"size\":\"833.34\", \"side\":\"BUY\", \"hash\":\"62d9d42b5953f38dbc246834a96eec4201888a6f\", \"best_bid\":\"0.47\", \"best_ask\":\"0.48\"}, {\"asset_id\":\"110216635572655435074987471276357323571387854733835379371586402147734167783946\", \"price\":\"0.76\", \"size\":\"833.34\", \"side\":\"SELL\", \"hash\":\"63b28e9614fdc6b5c9d92cfb699925488e95f436\", \"best_bid\":\"0.52\", \"best_ask\":\"0.53\"}], \"timestamp\":\"1785129960971\", \"event_type\":\"price_change\"}","received_at":"2026-07-27T05:26:00.931534Z","schema_version":"clob-market-ws.price_change.v1","sequence":null,"server_hash":null,"server_timestamp":"1785129960971","session_id":"502006c5cfcd437296561ea750c9ec8b","source":"clob_market_ws"},"received_at":"2026-07-27T05:26:00.931534Z","record_id":"f7685528abbe9dca0177ad8cf685d214228e08666d03bf3354a186c198b4349c","schema_fingerprint":"4aa3821a28b0b7c2400bc59aba4bcc0a76e971dadd19610d3ad38c768e124dc7","schema_version":"edge-lab-recorder.raw.v1","sequence":null,"source":"clob_market_ws"}
{"event_at":"2026-07-27T05:26:00.973000Z","event_fingerprint":"f24986f4cb4ce2d4be2a3354606727743319d0c3e8e291ecec7f38381fd8f495","payload":{"connection_id":"efc69d3132f1467b8e898a382b23ac0d","event_at":"2026-07-27T05:26:00.973000Z","event_type":"price_change","frame_hash":"011dd64dce9527d70ca4d8ae562301acf2a7facfdcbd78ea9b11e9865bd6649d","frame_index":0,"kind":"data","monotonic_ns":231944178416916,"payload":{"event_type":"price_change","market":"0x3b40066b5cf3871a2f6237c5628bd8092a206aa998558ac5ec13c4483e31e160","price_changes":[{"asset_id":"14766054693214075530629349735273995982307625376442606753688071083149620216746","best_ask":"0.48","best_bid":"0.47","hash":"da23da06f22b655820d2ea10cabeb65418a71379","price":"0.15","side":"BUY","size":"2217.34"},{"asset_id":"110216635572655435074987471276357323571387854733835379371586402147734167783946","best_ask":"0.53","best_bid":"0.52","hash":"7ddb5d173f5fd8d0c258837575b5bba4784e4fe1","price":"0.85","side":"SELL","size":"2217.34"}],"timestamp":"1785129960973"},"payload_hash":"7c27d63c6e5b43ec2ee8cc7c73d5a5f88ffea645d9d05969392e55b96ebf068a","raw_frame":"{\"market\":\"0x3b40066b5cf3871a2f6237c5628bd8092a206aa998558ac5ec13c4483e31e160\", \"price_changes\":[{\"asset_id\":\"14766054693214075530629349735273995982307625376442606753688071083149620216746\", \"price\":\"0.15\", \"size\":\"2217.34\", \"side\":\"BUY\", \"hash\":\"da23da06f22b655820d2ea10cabeb65418a71379\", \"best_bid\":\"0.47\", \"best_ask\":\"0.48\"}, {\"asset_id\":\"110216635572655435074987471276357323571387854733835379371586402147734167783946\", \"price\":\"0.85\", \"size\":\"2217.34\", \"side\":\"SELL\", \"hash\":\"7ddb5d173f5fd8d0c258837575b5bba4784e4fe1\", \"best_bid\":\"0.52\", \"best_ask\":\"0.53\"}], \"timestamp\":\"1785129960973\", \"event_type\":\"price_change\"}","received_at":"2026-07-27T05:26:00.938537Z","schema_version":"clob-market-ws.price_change.v1","sequence":null,"server_hash":null,"server_timestamp":"1785129960973","session_id":"502006c5cfcd437296561ea750c9ec8b","source":"clob_market_ws"},"received_at":"2026-07-27T05:26:00.938537Z","record_id":"7d25c748f997292b1334ec4d773cfa01e718f25a99c1915ec04622bbe99eb1f6","schema_fingerprint":"4aa3821a28b0b7c2400bc59aba4bcc0a76e971dadd19610d3ad38c768e124dc7","schema_version":"edge-lab-recorder.raw.v1","sequence":null,"source":"clob_market_ws"}
{"event_at":"2026-07-27T05:26:00.980000Z","event_fingerprint":"33bb29b79391b15362a02c95088e6910112cd4ad0eeef742d4bc32a4a29f7eb9","payload":{"connection_id":"efc69d3132f1467b8e898a382b23ac0d","event_at":"2026-07-27T05:26:00.980000Z","event_type":"price_change","frame_hash":"b22f69bf73e078179157d202ebb1b098959dcb0449e445f911c0fb64f6d0ea06","frame_index":0,"kind":"data","monotonic_ns":231944184577958,"payload":{"event_type":"price_change","market":"0x3b40066b5cf3871a2f6237c5628bd8092a206aa998558ac5ec13c4483e31e160","price_changes":[{"asset_id":"110216635572655435074987471276357323571387854733835379371586402147734167783946","best_ask":"0.53","best_bid":"0.52","hash":"44d70e4383afb2dff366762f6cf5fa5d7a60f5b6","price":"0.05","side":"BUY","size":"6733"},{"asset_id":"14766054693214075530629349735273995982307625376442606753688071083149620216746","best_ask":"0.48","best_bid":"0.47","hash":"148febdcd27dd81db46b25a37c612eebb6620b75","price":"0.95","side":"SELL","size":"6733"}],"timestamp":"1785129960980"},"payload_hash":"709ad723cd35aa2f257a539dcf063c2ffe3eecbf3b3981ca2c734ce50753f5c3","raw_frame":"{\"market\":\"0x3b40066b5cf3871a2f6237c5628bd8092a206aa998558ac5ec13c4483e31e160\", \"price_changes\":[{\"asset_id\":\"110216635572655435074987471276357323571387854733835379371586402147734167783946\", \"price\":\"0.05\", \"size\":\"6733\", \"side\":\"BUY\", \"hash\":\"44d70e4383afb2dff366762f6cf5fa5d7a60f5b6\", \"best_bid\":\"0.52\", \"best_ask\":\"0.53\"}, {\"asset_id\":\"14766054693214075530629349735273995982307625376442606753688071083149620216746\", \"price\":\"0.95\", \"size\":\"6733\", \"side\":\"SELL\", \"hash\":\"148febdcd27dd81db46b25a37c612eebb6620b75\", \"best_bid\":\"0.47\", \"best_ask\":\"0.48\"}], \"timestamp\":\"1785129960980\", \"event_type\":\"price_change\"}","received_at":"2026-07-27T05:26:00.944702Z","schema_version":"clob-market-ws.price_change.v1","sequence":null,"server_hash":null,"server_timestamp":"1785129960980","session_id":"502006c5cfcd437296561ea750c9ec8b","source":"clob_market_ws"},"received_at":"2026-07-27T05:26:00.944702Z","record_id":"d6f557524e10a574b1ece2207b09ea1b6352311223757eedc64dc6958981f1e3","schema_fingerprint":"4aa3821a28b0b7c2400bc59aba4bcc0a76e971dadd19610d3ad38c768e124dc7","schema_version":"edge-lab-recorder.raw.v1","sequence":null,"source":"clob_market_ws"}
{"event_at":"2026-07-27T05:26:01.025000Z","event_fingerprint":"2e4085c8faf81de4e0d4046a53f3acdd983d1ba415365e10026ea82bcb350a03","payload":{"connection_id":"efc69d3132f1467b8e898a382b23ac0d","event_at":"2026-07-27T05:26:01.025000Z","event_type":"price_change","frame_hash":"219f27b930253d83d5cb869a0801f69bbe79806d8ef71143ab620cdd7d2de50e","frame_index":0,"kind":"data","monotonic_ns":231944233147708,"payload":{"event_type":"price_change","market":"0x3b40066b5cf3871a2f6237c5628bd8092a206aa998558ac5ec13c4483e31e160","price_changes":[{"asset_id":"110216635572655435074987471276357323571387854733835379371586402147734167783946","best_ask":"0.53","best_bid":"0.52","hash":"f92bbdc2cd39138c813539e9d85b991cc97b6e8c","price":"0.32","side":"BUY","size":"600"},{"asset_id":"14766054693214075530629349735273995982307625376442606753688071083149620216746","best_ask":"0.48","best_bid":"0.47","hash":"c027f0c8b94cc375368ef9e47c7f9cede8c0f7ed","price":"0.68","side":"SELL","size":"600"}],"timestamp":"1785129961025"},"payload_hash":"b82b4d1dffb212702b727b9064757bdd47e60712fc0ad54147bb90d8e9a4dae3","raw_frame":"{\"market\":\"0x3b40066b5cf3871a2f6237c5628bd8092a206aa998558ac5ec13c4483e31e160\", \"price_changes\":[{\"asset_id\":\"110216635572655435074987471276357323571387854733835379371586402147734167783946\", \"price\":\"0.32\", \"size\":\"600\", \"side\":\"BUY\", \"hash\":\"f92bbdc2cd39138c813539e9d85b991cc97b6e8c\", \"best_bid\":\"0.52\", \"best_ask\":\"0.53\"}, {\"asset_id\":\"14766054693214075530629349735273995982307625376442606753688071083149620216746\", \"price\":\"0.68\", \"size\":\"600\", \"side\":\"SELL\", \"hash\":\"c027f0c8b94cc375368ef9e47c7f9cede8c0f7ed\", \"best_bid\":\"0.47\", \"best_ask\":\"0.48\"}], \"timestamp\":\"1785129961025\", \"event_type\":\"price_change\"}","received_at":"2026-07-27T05:26:00.993272Z","schema_version":"clob-market-ws.price_change.v1","sequence":null,"server_hash":null,"server_timestamp":"1785129961025","session_id":"502006c5cfcd437296561ea750c9ec8b","source":"clob_market_ws"},"received_at":"2026-07-27T05:26:00.993272Z","record_id":"c3a6cb39447ae74b0395083626a283b25f785a2faaeff78d894813b09b2181d8","schema_fingerprint":"4aa3821a28b0b7c2400bc59aba4bcc0a76e971dadd19610d3ad38c768e124dc7","schema_version":"edge-lab-recorder.raw.v1","sequence":null,"source":"clob_market_ws"}
{"event_at":"2026-07-27T05:26:01.030000Z","event_fingerprint":"d0b0e96d3e01576aee69c26be80140c65727169a06ce9a7428b34ae1fdea04d4","payload":{"connection_id":"efc69d3132f1467b8e898a382b23ac0d","event_at":"2026-07-27T05:26:01.030000Z","event_type":"price_change","frame_hash":"e41dfb33d361ed8da3497f480d25a5758e7be565fc91d178d34ade34c8b6705b","frame_index":0,"kind":"data","monotonic_ns":231944236603291,"payload":{"event_type":"price_change","market":"0x3b40066b5cf3871a2f6237c5628bd8092a206aa998558ac5ec13c4483e31e160","price_changes":[{"asset_id":"14766054693214075530629349735273995982307625376442606753688071083149620216746","best_ask":"0.48","best_bid":"0.47","hash":"dae85460c69f89419e83b1397938f47ab137ba76","price":"0.05","side":"BUY","size":"6733"},{"asset_id":"110216635572655435074987471276357323571387854733835379371586402147734167783946","best_ask":"0.53","best_bid":"0.52","hash":"e762eee580f778db2860b3cf20a518c593313734","price":"0.95","side":"SELL","size":"6733"}],"timestamp":"1785129961030"},"payload_hash":"f446492245dfc405db30eb5bc196e35b34c20e301e0857ae75a2c1a18d615337","raw_frame":"{\"market\":\"0x3b40066b5cf3871a2f6237c5628bd8092a206aa998558ac5ec13c4483e31e160\", \"price_changes\":[{\"asset_id\":\"14766054693214075530629349735273995982307625376442606753688071083149620216746\", \"price\":\"0.05\", \"size\":\"6733\", \"side\":\"BUY\", \"hash\":\"dae85460c69f89419e83b1397938f47ab137ba76\", \"best_bid\":\"0.47\", \"best_ask\":\"0.48\"}, {\"asset_id\":\"110216635572655435074987471276357323571387854733835379371586402147734167783946\", \"price\":\"0.95\", \"size\":\"6733\", \"side\":\"SELL\", \"hash\":\"e762eee580f778db2860b3cf20a518c593313734\", \"best_bid\":\"0.52\", \"best_ask\":\"0.53\"}], \"timestamp\":\"1785129961030\", \"event_type\":\"price_change\"}","received_at":"2026-07-27T05:26:00.996734Z","schema_version":"clob-market-ws.price_change.v1","sequence":null,"server_hash":null,"server_timestamp":"1785129961030","session_id":"502006c5cfcd437296561ea750c9ec8b","source":"clob_market_ws"},"received_at":"2026-07-27T05:26:00.996734Z","record_id":"b93914af05d1fb3b60d7de0ccec5ac285e3093cb4ca1a322afd6155d494fec1d","schema_fingerprint":"4aa3821a28b0b7c2400bc59aba4bcc0a76e971dadd19610d3ad38c768e124dc7","schema_version":"edge-lab-recorder.raw.v1","sequence":null,"source":"clob_market_ws"}
{"event_at":"2026-07-27T05:26:01.032000Z","event_fingerprint":"04b11e6f7e838e897e0e853255cc4a265683614ca806c8721b684d48ca824da4","payload":{"connection_id":"efc69d3132f1467b8e898a382b23ac0d","event_at":"2026-07-27T05:26:01.032000Z","event_type":"price_change","frame_hash":"fa0738413fb1d0b736fc7e06db29fb21171d271fd853eac4e55ac9aebbc30ec7","frame_index":0,"kind":"data","monotonic_ns":231944245292791,"payload":{"event_type":"price_change","market":"0x3b40066b5cf3871a2f6237c5628bd8092a206aa998558ac5ec13c4483e31e160","price_changes":[{"asset_id":"110216635572655435074987471276357323571387854733835379371586402147734167783946","best_ask":"0.53","best_bid":"0.52","hash":"a13c2394cc7f8074d44113f1673d03916d875444","price":"0.15","side":"BUY","size":"2217.34"},{"asset_id":"14766054693214075530629349735273995982307625376442606753688071083149620216746","best_ask":"0.48","best_bid":"0.47","hash":"360540ade99a3ba641a8365b41243ce24634382c","price":"0.85","side":"SELL","size":"2217.34"}],"timestamp":"1785129961032"},"payload_hash":"f58f796a0f930271015170b7df8721f0bdfd750c7a1c4ac95517ef7cca1dc964","raw_frame":"{\"market\":\"0x3b40066b5cf3871a2f6237c5628bd8092a206aa998558ac5ec13c4483e31e160\", \"price_changes\":[{\"asset_id\":\"110216635572655435074987471276357323571387854733835379371586402147734167783946\", \"price\":\"0.15\", \"size\":\"2217.34\", \"side\":\"BUY\", \"hash\":\"a13c2394cc7f8074d44113f1673d03916d875444\", \"best_bid\":\"0.52\", \"best_ask\":\"0.53\"}, {\"asset_id\":\"14766054693214075530629349735273995982307625376442606753688071083149620216746\", \"price\":\"0.85\", \"size\":\"2217.34\", \"side\":\"SELL\", \"hash\":\"360540ade99a3ba641a8365b41243ce24634382c\", \"best_bid\":\"0.47\", \"best_ask\":\"0.48\"}], \"timestamp\":\"1785129961032\", \"event_type\":\"price_change\"}","received_at":"2026-07-27T05:26:01.005417Z","schema_version":"clob-market-ws.price_change.v1","sequence":null,"server_hash":null,"server_timestamp":"1785129961032","session_id":"502006c5cfcd437296561ea750c9ec8b","source":"clob_market_ws"},"received_at":"2026-07-27T05:26:01.005417Z","record_id":"1437ee5425f5b90cb4c4d4cf94d357098e7944652d098bf07e8b86d9752ee89d","schema_fingerprint":"4aa3821a28b0b7c2400bc59aba4bcc0a76e971dadd19610d3ad38c768e124dc7","schema_version":"edge-lab-recorder.raw.v1","sequence":null,"source":"clob_market_ws"}
{"event_at":"2026-07-27T05:26:01.045000Z","event_fingerprint":"4e9981a38372f2424ddb3dc91cdf3108ee83b95de97f4f3e1510d53960deb3ee","payload":{"connection_id":"efc69d3132f1467b8e898a382b23ac0d","event_at":"2026-07-27T05:26:01.045000Z","event_type":"price_change","frame_hash":"b6aa1db7a5a165992ef433ef8494379329e7ef1ca3fd758a2fa8d83b4c8c6163","frame_index":0,"kind":"data","monotonic_ns":231944253657833,"payload":{"event_type":"price_change","market":"0x3b40066b5cf3871a2f6237c5628bd8092a206aa998558ac5ec13c4483e31e160","price_changes":[{"asset_id":"14766054693214075530629349735273995982307625376442606753688071083149620216746","best_ask":"0.48","best_bid":"0.47","hash":"76c55f9180814e49044f1e7000c08030afe4e11e","price":"0.1","side":"BUY","size":"3188"},{"asset_id":"110216635572655435074987471276357323571387854733835379371586402147734167783946","best_ask":"0.53","best_bid":"0.52","hash":"e5bbfbad18c3c33419e43982f47390387ceefe2f","price":"0.9","side":"SELL","size":"3188"}],"timestamp":"1785129961045"},"payload_hash":"91dd664ee08b563de9637b9e215ed52272126b1c0f1fe5604e6c1bbe4cb5312e","raw_frame":"{\"market\":\"0x3b40066b5cf3871a2f6237c5628bd8092a206aa998558ac5ec13c4483e31e160\", \"price_changes\":[{\"asset_id\":\"14766054693214075530629349735273995982307625376442606753688071083149620216746\", \"price\":\"0.1\", \"size\":\"3188\", \"side\":\"BUY\", \"hash\":\"76c55f9180814e49044f1e7000c08030afe4e11e\", \"best_bid\":\"0.47\", \"best_ask\":\"0.48\"}, {\"asset_id\":\"110216635572655435074987471276357323571387854733835379371586402147734167783946\", \"price\":\"0.9\", \"size\":\"3188\", \"side\":\"SELL\", \"hash\":\"e5bbfbad18c3c33419e43982f47390387ceefe2f\", \"best_bid\":\"0.52\", \"best_ask\":\"0.53\"}], \"timestamp\":\"1785129961045\", \"event_type\":\"price_change\"}","received_at":"2026-07-27T05:26:01.013788Z","schema_version":"clob-market-ws.price_change.v1","sequence":null,"server_hash":null,"server_timestamp":"1785129961045","session_id":"502006c5cfcd437296561ea750c9ec8b","source":"clob_market_ws"},"received_at":"2026-07-27T05:26:01.013788Z","record_id":"357b70f9f13eda07c5c634051027cefe8592ec66d017e20dbdebdd9ae7cdd49f","schema_fingerprint":"4aa3821a28b0b7c2400bc59aba4bcc0a76e971dadd19610d3ad38c768e124dc7","schema_version":"edge-lab-recorder.raw.v1","sequence":null,"source":"clob_market_ws"}
{"event_at":"2026-07-27T05:26:01.155000Z","event_fingerprint":"65b7e2a62c6332551db6701e0d401eeb4c4c6b76a22133e7dbe070069ac811d3","payload":{"connection_id":"efc69d3132f1467b8e898a382b23ac0d","event_at":"2026-07-27T05:26:01.155000Z","event_type":"price_change","frame_hash":"71bec0a63d3ede9831c3c0d9db33bae2eac326035bb58f01a5834ea9b41590ca","frame_index":0,"kind":"data","monotonic_ns":231944355815166,"payload":{"event_type":"price_change","market":"0x3b40066b5cf3871a2f6237c5628bd8092a206aa998558ac5ec13c4483e31e160","price_changes":[{"asset_id":"110216635572655435074987471276357323571387854733835379371586402147734167783946","best_ask":"0.53","best_bid":"0.52","hash":"8d853d5b97929f2d6e4f6029b68e7f8887bbb9dd","price":"0.23","side":"BUY","size":"41.74"},{"asset_id":"14766054693214075530629349735273995982307625376442606753688071083149620216746","best_ask":"0.48","best_bid":"0.47","hash":"c71380ae07f14ba713ad8920b581fc2cf936d0c3","price":"0.77","side":"SELL","size":"41.74"}],"timestamp":"1785129961155"},"payload_hash":"5c4e9f56505edf013545adeca784232e9ce88855bcd8063d1b74300afdf5b5a9","raw_frame":"{\"market\":\"0x3b40066b5cf3871a2f6237c5628bd8092a206aa998558ac5ec13c4483e31e160\", \"price_changes\":[{\"asset_id\":\"110216635572655435074987471276357323571387854733835379371586402147734167783946\", \"price\":\"0.23\", \"size\":\"41.74\", \"side\":\"BUY\", \"hash\":\"8d853d5b97929f2d6e4f6029b68e7f8887bbb9dd\", \"best_bid\":\"0.52\", \"best_ask\":\"0.53\"}, {\"asset_id\":\"14766054693214075530629349735273995982307625376442606753688071083149620216746\", \"price\":\"0.77\", \"size\":\"41.74\", \"side\":\"SELL\", \"hash\":\"c71380ae07f14ba713ad8920b581fc2cf936d0c3\", \"best_bid\":\"0.47\", \"best_ask\":\"0.48\"}], \"timestamp\":\"1785129961155\", \"event_type\":\"price_change\"}","received_at":"2026-07-27T05:26:01.115936Z","schema_version":"clob-market-ws.price_change.v1","sequence":null,"server_hash":null,"server_timestamp":"1785129961155","session_id":"502006c5cfcd437296561ea750c9ec8b","source":"clob_market_ws"},"received_at":"2026-07-27T05:26:01.115936Z","record_id":"01468a3691090596002412b7f85b888903ac5695601ea29023f391b34731455b","schema_fingerprint":"4aa3821a28b0b7c2400bc59aba4bcc0a76e971dadd19610d3ad38c768e124dc7","schema_version":"edge-lab-recorder.raw.v1","sequence":null,"source":"clob_market_ws"}
{"event_at":"2026-07-27T05:26:01.226000Z","event_fingerprint":"fbc387acfab3298ac4c408173717033f55f9b4d38e35d6bd79d24133c3249c1b","payload":{"connection_id":"efc69d3132f1467b8e898a382b23ac0d","event_at":"2026-07-27T05:26:01.226000Z","event_type":"price_change","frame_hash":"419ba4fd996ec6424d1799b7d326eeca3a0751c68c1418043a314e685f838c65","frame_index":0,"kind":"data","monotonic_ns":231944427239500,"payload":{"event_type":"price_change","market":"0x3b40066b5cf3871a2f6237c5628bd8092a206aa998558ac5ec13c4483e31e160","price_changes":[{"asset_id":"110216635572655435074987471276357323571387854733835379371586402147734167783946","best_ask":"0.53","best_bid":"0.52","hash":"dfb17ce96b13f9fe7a1ca964e9ec94eef5cd9282","price":"0.29","side":"BUY","size":"87.25"},{"asset_id":"14766054693214075530629349735273995982307625376442606753688071083149620216746","best_ask":"0.48","best_bid":"0.47","hash":"317b5e1f1fb0128804bcdff05e39e71f103dc16e","price":"0.71","side":"SELL","size":"87.25"}],"timestamp":"1785129961226"},"payload_hash":"41fdcb4b0eb7fc60be06d7193d9368ea1fa3c12ae4e7bf3b405cf4045349bdc1","raw_frame":"{\"market\":\"0x3b40066b5cf3871a2f6237c5628bd8092a206aa998558ac5ec13c4483e31e160\", \"price_changes\":[{\"asset_id\":\"110216635572655435074987471276357323571387854733835379371586402147734167783946\", \"price\":\"0.29\", \"size\":\"87.25\", \"side\":\"BUY\", \"hash\":\"dfb17ce96b13f9fe7a1ca964e9ec94eef5cd9282\", \"best_bid\":\"0.52\", \"best_ask\":\"0.53\"}, {\"asset_id\":\"14766054693214075530629349735273995982307625376442606753688071083149620216746\", \"price\":\"0.71\", \"size\":\"87.25\", \"side\":\"SELL\", \"hash\":\"317b5e1f1fb0128804bcdff05e39e71f103dc16e\", \"best_bid\":\"0.47\", \"best_ask\":\"0.48\"}], \"timestamp\":\"1785129961226\", \"event_type\":\"price_change\"}","received_at":"2026-07-27T05:26:01.187363Z","schema_version":"clob-market-ws.price_change.v1","sequence":null,"server_hash":null,"server_timestamp":"1785129961226","session_id":"502006c5cfcd437296561ea750c9ec8b","source":"clob_market_ws"},"received_at":"2026-07-27T05:26:01.187363Z","record_id":"85c5317cfd54f871b75d3c3cb9c8f9a131fc8d7e7a49bd4777a9d26e5eebe5f4","schema_fingerprint":"4aa3821a28b0b7c2400bc59aba4bcc0a76e971dadd19610d3ad38c768e124dc7","schema_version":"edge-lab-recorder.raw.v1","sequence":null,"source":"clob_market_ws"}
{"event_at":"2026-07-27T05:26:01.227000Z","event_fingerprint":"da02d2a783443a79b5401dcac3b73e2774348ae7121e08b7f1377471f159e7b5","payload":{"connection_id":"efc69d3132f1467b8e898a382b23ac0d","event_at":"2026-07-27T05:26:01.227000Z","event_type":"price_change","frame_hash":"decf998e179b4ea1321a067127f2f8be793f07226ec7946fd05fb62220050df1","frame_index":0,"kind":"data","monotonic_ns":231944430275166,"payload":{"event_type":"price_change","market":"0x3b40066b5cf3871a2f6237c5628bd8092a206aa998558ac5ec13c4483e31e160","price_changes":[{"asset_id":"110216635572655435074987471276357323571387854733835379371586402147734167783946","best_ask":"0.53","best_bid":"0.52","hash":"1b601f60d66ce82b092370a59042e468f589e417","price":"0.38","side":"BUY","size":"267.16"},{"asset_id":"14766054693214075530629349735273995982307625376442606753688071083149620216746","best_ask":"0.48","best_bid":"0.47","hash":"cce42e8a7f7683a5c79bfffac713c3fe5ed9f04a","price":"0.62","side":"SELL","size":"267.16"}],"timestamp":"1785129961227"},"payload_hash":"ebd1df467ca98f12c014fe61d97107d0a8bbe01166ee2331f7c6174041443e5a","raw_frame":"{\"market\":\"0x3b40066b5cf3871a2f6237c5628bd8092a206aa998558ac5ec13c4483e31e160\", \"price_changes\":[{\"asset_id\":\"110216635572655435074987471276357323571387854733835379371586402147734167783946\", \"price\":\"0.38\", \"size\":\"267.16\", \"side\":\"BUY\", \"hash\":\"1b601f60d66ce82b092370a59042e468f589e417\", \"best_bid\":\"0.52\", \"best_ask\":\"0.53\"}, {\"asset_id\":\"14766054693214075530629349735273995982307625376442606753688071083149620216746\", \"price\":\"0.62\", \"size\":\"267.16\", \"side\":\"SELL\", \"hash\":\"cce42e8a7f7683a5c79bfffac713c3fe5ed9f04a\", \"best_bid\":\"0.47\", \"best_ask\":\"0.48\"}], \"timestamp\":\"1785129961227\", \"event_type\":\"price_change\"}","received_at":"2026-07-27T05:26:01.190401Z","schema_version":"clob-market-ws.price_change.v1","sequence":null,"server_hash":null,"server_timestamp":"1785129961227","session_id":"502006c5cfcd437296561ea750c9ec8b","source":"clob_market_ws"},"received_at":"2026-07-27T05:26:01.190401Z","record_id":"8e42b459620ac3ade0b306c8c6e982e9198e1afb9e473d85e67aa699dae2cb59","schema_fingerprint":"4aa3821a28b0b7c2400bc59aba4bcc0a76e971dadd19610d3ad38c768e124dc7","schema_version":"edge-lab-recorder.raw.v1","sequence":null,"source":"clob_market_ws"}
{"event_at":"2026-07-27T05:26:01.228000Z","event_fingerprint":"a2841030b6f498818bec0e3432600087dc15f781dd91fd6779028d1622aecf59","payload":{"connection_id":"efc69d3132f1467b8e898a382b23ac0d","event_at":"2026-07-27T05:26:01.228000Z","event_type":"price_change","frame_hash":"07df7c27878a9434900696c8f2f4a8d6255d3359d4dd6e1b95f9cd3c029744d8","frame_index":0,"kind":"data","monotonic_ns":231944434726916,"payload":{"event_type":"price_change","market":"0x3b40066b5cf3871a2f6237c5628bd8092a206aa998558ac5ec13c4483e31e160","price_changes":[{"asset_id":"14766054693214075530629349735273995982307625376442606753688071083149620216746","best_ask":"0.48","best_bid":"0.47","hash":"f0ef1947a813b510eb9d8f28708631cf1b4bbbe3","price":"0.23","side":"BUY","size":"41.74"},{"asset_id":"110216635572655435074987471276357323571387854733835379371586402147734167783946","best_ask":"0.53","best_bid":"0.52","hash":"151f91ad4d9ddb85c3923fe5f000b8c00d409739","price":"0.77","side":"SELL","size":"41.74"}],"timestamp":"1785129961228"},"payload_hash":"9db514a9f0a8217c0acb267bd211e3b785af8c1d28a6b800ce5722d9f47e0fa3","raw_frame":"{\"market\":\"0x3b40066b5cf3871a2f6237c5628bd8092a206aa998558ac5ec13c4483e31e160\", \"price_changes\":[{\"asset_id\":\"14766054693214075530629349735273995982307625376442606753688071083149620216746\", \"price\":\"0.23\", \"size\":\"41.74\", \"side\":\"BUY\", \"hash\":\"f0ef1947a813b510eb9d8f28708631cf1b4bbbe3\", \"best_bid\":\"0.47\", \"best_ask\":\"0.48\"}, {\"asset_id\":\"110216635572655435074987471276357323571387854733835379371586402147734167783946\", \"price\":\"0.77\", \"size\":\"41.74\", \"side\":\"SELL\", \"hash\":\"151f91ad4d9ddb85c3923fe5f000b8c00d409739\", \"best_bid\":\"0.52\", \"best_ask\":\"0.53\"}], \"timestamp\":\"1785129961228\", \"event_type\":\"price_change\"}","received_at":"2026-07-27T05:26:01.194852Z","schema_version":"clob-market-ws.price_change.v1","sequence":null,"server_hash":null,"server_timestamp":"1785129961228","session_id":"502006c5cfcd437296561ea750c9ec8b","source":"clob_market_ws"},"received_at":"2026-07-27T05:26:01.194852Z","record_id":"ce4391acf810977923fea552ceb386df42b2f7ead473e936d76f91120539dc98","schema_fingerprint":"4aa3821a28b0b7c2400bc59aba4bcc0a76e971dadd19610d3ad38c768e124dc7","schema_version":"edge-lab-recorder.raw.v1","sequence":null,"source":"clob_market_ws"}
{"event_at":"2026-07-27T05:26:01.310000Z","event_fingerprint":"956a5a51a1e5bfaabc1b47977e8a5e1075baf06137b66e2f1d0c5d7fbb586e99","payload":{"connection_id":"efc69d3132f1467b8e898a382b23ac0d","event_at":"2026-07-27T05:26:01.310000Z","event_type":"price_change","frame_hash":"b5a7f727f90938c20a165c94c2593a7a36530f8793788b3a42bd9f99c2463e5a","frame_index":0,"kind":"data","monotonic_ns":231944515349416,"payload":{"event_type":"price_change","market":"0x3b40066b5cf3871a2f6237c5628bd8092a206aa998558ac5ec13c4483e31e160","price_changes":[{"asset_id":"110216635572655435074987471276357323571387854733835379371586402147734167783946","best_ask":"0.53","best_bid":"0.52","hash":"cd6e11a8343a9faed4448428ac206090be4bc6d2","price":"0.11","side":"BUY","size":"45.46"},{"asset_id":"14766054693214075530629349735273995982307625376442606753688071083149620216746","best_ask":"0.48","best_bid":"0.47","hash":"8ce7220bb44b6c72e72040c0561eabca3da46e18","price":"0.89","side":"SELL","size":"45.46"}],"timestamp":"1785129961310"},"payload_hash":"d5ee98045607a766a33a75785bb9c1062ed1a5adf673edeba0349364227b222f","raw_frame":"{\"market\":\"0x3b40066b5cf3871a2f6237c5628bd8092a206aa998558ac5ec13c4483e31e160\", \"price_changes\":[{\"asset_id\":\"110216635572655435074987471276357323571387854733835379371586402147734167783946\", \"price\":\"0.11\", \"size\":\"45.46\", \"side\":\"BUY\", \"hash\":\"cd6e11a8343a9faed4448428ac206090be4bc6d2\", \"best_bid\":\"0.52\", \"best_ask\":\"0.53\"}, {\"asset_id\":\"14766054693214075530629349735273995982307625376442606753688071083149620216746\", \"price\":\"0.89\", \"size\":\"45.46\", \"side\":\"SELL\", \"hash\":\"8ce7220bb44b6c72e72040c0561eabca3da46e18\", \"best_bid\":\"0.47\", \"best_ask\":\"0.48\"}], \"timestamp\":\"1785129961310\", \"event_type\":\"price_change\"}","received_at":"2026-07-27T05:26:01.275474Z","schema_version":"clob-market-ws.price_change.v1","sequence":null,"server_hash":null,"server_timestamp":"1785129961310","session_id":"502006c5cfcd437296561ea750c9ec8b","source":"clob_market_ws"},"received_at":"2026-07-27T05:26:01.275474Z","record_id":"f05ab6a70b2f5eb3215668cae14eeac1737d853435eb44b595b8dba42f500894","schema_fingerprint":"4aa3821a28b0b7c2400bc59aba4bcc0a76e971dadd19610d3ad38c768e124dc7","schema_version":"edge-lab-recorder.raw.v1","sequence":null,"source":"clob_market_ws"}
{"event_at":"2026-07-27T05:26:01.378000Z","event_fingerprint":"ae5bb8a4af0826eaa0c09a4b2bdce3326b16d11f8be8b57a0d713e84e08f276d","payload":{"connection_id":"efc69d3132f1467b8e898a382b23ac0d","event_at":"2026-07-27T05:26:01.378000Z","event_type":"price_change","frame_hash":"a0a65eec20dbbef596a0b8e183e3cd406a3ba6569976ecabd2417f24ae690d5f","frame_index":0,"kind":"data","monotonic_ns":231944579339541,"payload":{"event_type":"price_change","market":"0x3b40066b5cf3871a2f6237c5628bd8092a206aa998558ac5ec13c4483e31e160","price_changes":[{"asset_id":"14766054693214075530629349735273995982307625376442606753688071083149620216746","best_ask":"0.48","best_bid":"0.47","hash":"64d3c1739f7947385cc1d32a352d7426d2ddbd7b","price":"0.38","side":"BUY","size":"228.16"},{"asset_id":"110216635572655435074987471276357323571387854733835379371586402147734167783946","best_ask":"0.53","best_bid":"0.52","hash":"150daefde6cff373ede03287e9c637ca19a7c56c","price":"0.62","side":"SELL","size":"228.16"}],"timestamp":"1785129961378"},"payload_hash":"a9b7eab2abe1df9076a6647015cc74e5bfd96323c9098e5c302d866cf813d2c5","raw_frame":"{\"market\":\"0x3b40066b5cf3871a2f6237c5628bd8092a206aa998558ac5ec13c4483e31e160\", \"price_changes\":[{\"asset_id\":\"14766054693214075530629349735273995982307625376442606753688071083149620216746\", \"price\":\"0.38\", \"size\":\"228.16\", \"side\":\"BUY\", \"hash\":\"64d3c1739f7947385cc1d32a352d7426d2ddbd7b\", \"best_bid\":\"0.47\", \"best_ask\":\"0.48\"}, {\"asset_id\":\"110216635572655435074987471276357323571387854733835379371586402147734167783946\", \"price\":\"0.62\", \"size\":\"228.16\", \"side\":\"SELL\", \"hash\":\"150daefde6cff373ede03287e9c637ca19a7c56c\", \"best_bid\":\"0.52\", \"best_ask\":\"0.53\"}], \"timestamp\":\"1785129961378\", \"event_type\":\"price_change\"}","received_at":"2026-07-27T05:26:01.339464Z","schema_version":"clob-market-ws.price_change.v1","sequence":null,"server_hash":null,"server_timestamp":"1785129961378","session_id":"502006c5cfcd437296561ea750c9ec8b","source":"clob_market_ws"},"received_at":"2026-07-27T05:26:01.339464Z","record_id":"fdb264faf354a532a2b4bcdeaf8f9dd5090c7c31a373712fe0d5deb64200d5ca","schema_fingerprint":"4aa3821a28b0b7c2400bc59aba4bcc0a76e971dadd19610d3ad38c768e124dc7","schema_version":"edge-lab-recorder.raw.v1","sequence":null,"source":"clob_market_ws"}
{"event_at":"2026-07-27T05:26:01.379000Z","event_fingerprint":"395c2a1954c880165fe1d3f00ed76ac88fc64e4193f5cfb6ae0cc906e6b48b85","payload":{"connection_id":"efc69d3132f1467b8e898a382b23ac0d","event_at":"2026-07-27T05:26:01.379000Z","event_type":"price_change","frame_hash":"c92539343e685c65d41c6daeda0489ecd334de085435fb00ad0b28806846546a","frame_index":0,"kind":"data","monotonic_ns":231944580885083,"payload":{"event_type":"price_change","market":"0x3b40066b5cf3871a2f6237c5628bd8092a206aa998558ac5ec13c4483e31e160","price_changes":[{"asset_id":"14766054693214075530629349735273995982307625376442606753688071083149620216746","best_ask":"0.48","best_bid":"0.47","hash":"82e32a569b21fcaa42e9564daf4dc9d9b4604dc1","price":"0.06","side":"BUY","size":"722.34"},{"asset_id":"110216635572655435074987471276357323571387854733835379371586402147734167783946","best_ask":"0.53","best_bid":"0.52","hash":"71900d5dee408314009b586bfee53506ff12c5e3","price":"0.94","side":"SELL","size":"722.34"}],"timestamp":"1785129961379"},"payload_hash":"a0ea5e5cbcd64d160ee12735880753a5e5b60ccf4daf984c0c8d3de337b16fdf","raw_frame":"{\"market\":\"0x3b40066b5cf3871a2f6237c5628bd8092a206aa998558ac5ec13c4483e31e160\", \"price_changes\":[{\"asset_id\":\"14766054693214075530629349735273995982307625376442606753688071083149620216746\", \"price\":\"0.06\", \"size\":\"722.34\", \"side\":\"BUY\", \"hash\":\"82e32a569b21fcaa42e9564daf4dc9d9b4604dc1\", \"best_bid\":\"0.47\", \"best_ask\":\"0.48\"}, {\"asset_id\":\"110216635572655435074987471276357323571387854733835379371586402147734167783946\", \"price\":\"0.94\", \"size\":\"722.34\", \"side\":\"SELL\", \"hash\":\"71900d5dee408314009b586bfee53506ff12c5e3\", \"best_bid\":\"0.52\", \"best_ask\":\"0.53\"}], \"timestamp\":\"1785129961379\", \"event_type\":\"price_change\"}","received_at":"2026-07-27T05:26:01.341010Z","schema_version":"clob-market-ws.price_change.v1","sequence":null,"server_hash":null,"server_timestamp":"1785129961379","session_id":"502006c5cfcd437296561ea750c9ec8b","source":"clob_market_ws"},"received_at":"2026-07-27T05:26:01.341010Z","record_id":"e48905f349ffd7074f7f3d477f68c077d245ef7b4918cc25701eca95dda651c9","schema_fingerprint":"4aa3821a28b0b7c2400bc59aba4bcc0a76e971dadd19610d3ad38c768e124dc7","schema_version":"edge-lab-recorder.raw.v1","sequence":null,"source":"clob_market_ws"}
{"event_at":"2026-07-27T05:26:01.448000Z","event_fingerprint":"afb7415d81629e33a6c5fb5a63a0ed11f5b932c81405f254de2342dd1d568e2d","payload":{"connection_id":"efc69d3132f1467b8e898a382b23ac0d","event_at":"2026-07-27T05:26:01.448000Z","event_type":"price_change","frame_hash":"ada9b8bc6a4d68a7ba6b3331292d8967e0d9b8233f2906da74d80506bc47ade5","frame_index":0,"kind":"data","monotonic_ns":231944651556708,"payload":{"event_type":"price_change","market":"0x3b40066b5cf3871a2f6237c5628bd8092a206aa998558ac5ec13c4483e31e160","price_changes":[{"asset_id":"14766054693214075530629349735273995982307625376442606753688071083149620216746","best_ask":"0.48","best_bid":"0.47","hash":"834190e9ad5e08c3d2ef6034b47c72fedd3bb06a","price":"0.29","side":"BUY","size":"87.25"},{"asset_id":"110216635572655435074987471276357323571387854733835379371586402147734167783946","best_ask":"0.53","best_bid":"0.52","hash":"c9ea2c11196409950d60bde723e7c17c37c1834a","price":"0.71","side":"SELL","size":"87.25"}],"timestamp":"1785129961448"},"payload_hash":"a36e3487329135232817346a7ffcf5e8cdc2b2a005e82518d31e338bc19024ee","raw_frame":"{\"market\":\"0x3b40066b5cf3871a2f6237c5628bd8092a206aa998558ac5ec13c4483e31e160\", \"price_changes\":[{\"asset_id\":\"14766054693214075530629349735273995982307625376442606753688071083149620216746\", \"price\":\"0.29\", \"size\":\"87.25\", \"side\":\"BUY\", \"hash\":\"834190e9ad5e08c3d2ef6034b47c72fedd3bb06a\", \"best_bid\":\"0.47\", \"best_ask\":\"0.48\"}, {\"asset_id\":\"110216635572655435074987471276357323571387854733835379371586402147734167783946\", \"price\":\"0.71\", \"size\":\"87.25\", \"side\":\"SELL\", \"hash\":\"c9ea2c11196409950d60bde723e7c17c37c1834a\", \"best_bid\":\"0.52\", \"best_ask\":\"0.53\"}], \"timestamp\":\"1785129961448\", \"event_type\":\"price_change\"}","received_at":"2026-07-27T05:26:01.411680Z","schema_version":"clob-market-ws.price_change.v1","sequence":null,"server_hash":null,"server_timestamp":"1785129961448","session_id":"502006c5cfcd437296561ea750c9ec8b","source":"clob_market_ws"},"received_at":"2026-07-27T05:26:01.411680Z","record_id":"d4f3baf910db5f848e6296ec04277a3b7c949ebe29500e1bfd9d7c2f0f08d400","schema_fingerprint":"4aa3821a28b0b7c2400bc59aba4bcc0a76e971dadd19610d3ad38c768e124dc7","schema_version":"edge-lab-recorder.raw.v1","sequence":null,"source":"clob_market_ws"}
{"event_at":"2026-07-27T05:26:01.449000Z","event_fingerprint":"ff5980d59625fddf29578eebc42dd5d47983136f887f4430b6eca76b6a354765","payload":{"connection_id":"efc69d3132f1467b8e898a382b23ac0d","event_at":"2026-07-27T05:26:01.449000Z","event_type":"price_change","frame_hash":"72ba4424b4f50d7c6bb9b61c4577b4bcc5b7e0bd749d35ba330793006825d700","frame_index":0,"kind":"data","monotonic_ns":231944653041958,"payload":{"event_type":"price_change","market":"0x3b40066b5cf3871a2f6237c5628bd8092a206aa998558ac5ec13c4483e31e160","price_changes":[{"asset_id":"110216635572655435074987471276357323571387854733835379371586402147734167783946","best_ask":"0.53","best_bid":"0.52","hash":"3178b567c022e3f260563edfef53b1bddfb9958a","price":"0.17","side":"BUY","size":"49.42"},{"asset_id":"14766054693214075530629349735273995982307625376442606753688071083149620216746","best_ask":"0.48","best_bid":"0.47","hash":"25a5aeaf3fc812240a42884b11d3b28f1d2efe1b","price":"0.83","side":"SELL","size":"49.42"}],"timestamp":"1785129961449"},"payload_hash":"c61e3861fb8c48cd3c332f0f6d106206a8bad6f76be088c8b504d93d1b091263","raw_frame":"{\"market\":\"0x3b40066b5cf3871a2f6237c5628bd8092a206aa998558ac5ec13c4483e31e160\", \"price_changes\":[{\"asset_id\":\"110216635572655435074987471276357323571387854733835379371586402147734167783946\", \"price\":\"0.17\", \"size\":\"49.42\", \"side\":\"BUY\", \"hash\":\"3178b567c022e3f260563edfef53b1bddfb9958a\", \"best_bid\":\"0.52\", \"best_ask\":\"0.53\"}, {\"asset_id\":\"14766054693214075530629349735273995982307625376442606753688071083149620216746\", \"price\":\"0.83\", \"size\":\"49.42\", \"side\":\"SELL\", \"hash\":\"25a5aeaf3fc812240a42884b11d3b28f1d2efe1b\", \"best_bid\":\"0.47\", \"best_ask\":\"0.48\"}], \"timestamp\":\"1785129961449\", \"event_type\":\"price_change\"}","received_at":"2026-07-27T05:26:01.413175Z","schema_version":"clob-market-ws.price_change.v1","sequence":null,"server_hash":null,"server_timestamp":"1785129961449","session_id":"502006c5cfcd437296561ea750c9ec8b","source":"clob_market_ws"},"received_at":"2026-07-27T05:26:01.413175Z","record_id":"7f911be236557f6f3b365e36155ffe7126dc742b0351a18cfcbc94ef823e3f48","schema_fingerprint":"4aa3821a28b0b7c2400bc59aba4bcc0a76e971dadd19610d3ad38c768e124dc7","schema_version":"edge-lab-recorder.raw.v1","sequence":null,"source":"clob_market_ws"}
{"event_at":"2026-07-27T05:26:01.521000Z","event_fingerprint":"fb478427c2e162ff90477c2083cf56e081cddbd04565b1a82721dec5cc6cae35","payload":{"connection_id":"efc69d3132f1467b8e898a382b23ac0d","event_at":"2026-07-27T05:26:01.521000Z","event_type":"price_change","frame_hash":"0a74a0c37dac3b60b0a8cbf9bba75b904c76ae37be74a14dae80dfdfeece6923","frame_index":0,"kind":"data","monotonic_ns":231944721601208,"payload":{"event_type":"price_change","market":"0x3b40066b5cf3871a2f6237c5628bd8092a206aa998558ac5ec13c4483e31e160","price_changes":[{"asset_id":"110216635572655435074987471276357323571387854733835379371586402147734167783946","best_ask":"0.53","best_bid":"0.52","hash":"2d1f60e9d01c5cfcde2982ae0e18781e9b340019","price":"0.06","side":"BUY","size":"722.34"},{"asset_id":"14766054693214075530629349735273995982307625376442606753688071083149620216746","best_ask":"0.48","best_bid":"0.47","hash":"5a2afbc79454613974c47c6d11cb6aaba9349b69","price":"0.94","side":"SELL","size":"722.34"}],"timestamp":"1785129961521"},"payload_hash":"6b8a0b1eb400fc7c6a295bb7837d7cb24e50524225bf72800177da78e4e822d8","raw_frame":"{\"market\":\"0x3b40066b5cf3871a2f6237c5628bd8092a206aa998558ac5ec13c4483e31e160\", \"price_changes\":[{\"asset_id\":\"110216635572655435074987471276357323571387854733835379371586402147734167783946\", \"price\":\"0.06\", \"size\":\"722.34\", \"side\":\"BUY\", \"hash\":\"2d1f60e9d01c5cfcde2982ae0e18781e9b340019\", \"best_bid\":\"0.52\", \"best_ask\":\"0.53\"}, {\"asset_id\":\"14766054693214075530629349735273995982307625376442606753688071083149620216746\", \"price\":\"0.94\", \"size\":\"722.34\", \"side\":\"SELL\", \"hash\":\"5a2afbc79454613974c47c6d11cb6aaba9349b69\", \"best_bid\":\"0.47\", \"best_ask\":\"0.48\"}], \"timestamp\":\"1785129961521\", \"event_type\":\"price_change\"}","received_at":"2026-07-27T05:26:01.481731Z","schema_version":"clob-market-ws.price_change.v1","sequence":null,"server_hash":null,"server_timestamp":"1785129961521","session_id":"502006c5cfcd437296561ea750c9ec8b","source":"clob_market_ws"},"received_at":"2026-07-27T05:26:01.481731Z","record_id":"e02b14105752f889e6ee1175234cf63b223ae9c08c7e11977815d1958206b442","schema_fingerprint":"4aa3821a28b0b7c2400bc59aba4bcc0a76e971dadd19610d3ad38c768e124dc7","schema_version":"edge-lab-recorder.raw.v1","sequence":null,"source":"clob_market_ws"}
{"event_at":"2026-07-27T05:26:01.522000Z","event_fingerprint":"4437785d383c2f09a3d1be0383397790efd6d825fa81d7ea500babdfc620cd39","payload":{"connection_id":"efc69d3132f1467b8e898a382b23ac0d","event_at":"2026-07-27T05:26:01.522000Z","event_type":"price_change","frame_hash":"63d8ae1efcc732cb658286de73dc742ccb27cee5867d1ee0a85d854828427b29","frame_index":0,"kind":"data","monotonic_ns":231944724102958,"payload":{"event_type":"price_change","market":"0x3b40066b5cf3871a2f6237c5628bd8092a206aa998558ac5ec13c4483e31e160","price_changes":[{"asset_id":"14766054693214075530629349735273995982307625376442606753688071083149620216746","best_ask":"0.48","best_bid":"0.47","hash":"daed708adc291f3b7ba2744c16f82f8af0126603","price":"0.11","side":"BUY","size":"45.46"},{"asset_id":"110216635572655435074987471276357323571387854733835379371586402147734167783946","best_ask":"0.53","best_bid":"0.52","hash":"8f35463d707f9f732bb40065f393ca1df0a5ae54","price":"0.89","side":"SELL","size":"45.46"}],"timestamp":"1785129961522"},"payload_hash":"29e3931dbebbd0aa6a1bd5d0991a8f85ddb28ae23df3949fe650538d4f1ffe33","raw_frame":"{\"market\":\"0x3b40066b5cf3871a2f6237c5628bd8092a206aa998558ac5ec13c4483e31e160\", \"price_changes\":[{\"asset_id\":\"14766054693214075530629349735273995982307625376442606753688071083149620216746\", \"price\":\"0.11\", \"size\":\"45.46\", \"side\":\"BUY\", \"hash\":\"daed708adc291f3b7ba2744c16f82f8af0126603\", \"best_bid\":\"0.47\", \"best_ask\":\"0.48\"}, {\"asset_id\":\"110216635572655435074987471276357323571387854733835379371586402147734167783946\", \"price\":\"0.89\", \"size\":\"45.46\", \"side\":\"SELL\", \"hash\":\"8f35463d707f9f732bb40065f393ca1df0a5ae54\", \"best_bid\":\"0.52\", \"best_ask\":\"0.53\"}], \"timestamp\":\"1785129961522\", \"event_type\":\"price_change\"}","received_at":"2026-07-27T05:26:01.484227Z","schema_version":"clob-market-ws.price_change.v1","sequence":null,"server_hash":null,"server_timestamp":"1785129961522","session_id":"502006c5cfcd437296561ea750c9ec8b","source":"clob_market_ws"},"received_at":"2026-07-27T05:26:01.484227Z","record_id":"a6497bc99fefb1100c2d247870f327d472c3c3496088702ed12a7dda421dcd61","schema_fingerprint":"4aa3821a28b0b7c2400bc59aba4bcc0a76e971dadd19610d3ad38c768e124dc7","schema_version":"edge-lab-recorder.raw.v1","sequence":null,"source":"clob_market_ws"}
{"event_at":"2026-07-27T05:26:01.592000Z","event_fingerprint":"f3a7495583c074ccfbc0bb8abb2d269e8a0cbcaf34b33ede518832e5b7d1f417","payload":{"connection_id":"efc69d3132f1467b8e898a382b23ac0d","event_at":"2026-07-27T05:26:01.592000Z","event_type":"price_change","frame_hash":"e62789b402fe893d704da5fd391f1d81be01fcbcdb79ab9aeaea113485d09d99","frame_index":0,"kind":"data","monotonic_ns":231944795272833,"payload":{"event_type":"price_change","market":"0x3b40066b5cf3871a2f6237c5628bd8092a206aa998558ac5ec13c4483e31e160","price_changes":[{"asset_id":"14766054693214075530629349735273995982307625376442606753688071083149620216746","best_ask":"0.48","best_bid":"0.47","hash":"4107642d7f34a91da4c7184135b4fbc1a5bba19c","price":"0.17","side":"BUY","size":"49.42"},{"asset_id":"110216635572655435074987471276357323571387854733835379371586402147734167783946","best_ask":"0.53","best_bid":"0.52","hash":"e280b2f546fe947efa351da9b39f6d7f2891427c","price":"0.83","side":"SELL","size":"49.42"}],"timestamp":"1785129961592"},"payload_hash":"d878a4a99ff853122ce4afd590968a8dc11c994a8dbc95e4a0065e9d703bf887","raw_frame":"{\"market\":\"0x3b40066b5cf3871a2f6237c5628bd8092a206aa998558ac5ec13c4483e31e160\", \"price_changes\":[{\"asset_id\":\"14766054693214075530629349735273995982307625376442606753688071083149620216746\", \"price\":\"0.17\", \"size\":\"49.42\", \"side\":\"BUY\", \"hash\":\"4107642d7f34a91da4c7184135b4fbc1a5bba19c\", \"best_bid\":\"0.47\", \"best_ask\":\"0.48\"}, {\"asset_id\":\"110216635572655435074987471276357323571387854733835379371586402147734167783946\", \"price\":\"0.83\", \"size\":\"49.42\", \"side\":\"SELL\", \"hash\":\"e280b2f546fe947efa351da9b39f6d7f2891427c\", \"best_bid\":\"0.52\", \"best_ask\":\"0.53\"}], \"timestamp\":\"1785129961592\", \"event_type\":\"price_change\"}","received_at":"2026-07-27T05:26:01.555402Z","schema_version":"clob-market-ws.price_change.v1","sequence":null,"server_hash":null,"server_timestamp":"1785129961592","session_id":"502006c5cfcd437296561ea750c9ec8b","source":"clob_market_ws"},"received_at":"2026-07-27T05:26:01.555402Z","record_id":"827238bfb4466d2f8fb4f74dcdfd88323fbbfc7d96996be71a38c392ce53850b","schema_fingerprint":"4aa3821a28b0b7c2400bc59aba4bcc0a76e971dadd19610d3ad38c768e124dc7","schema_version":"edge-lab-recorder.raw.v1","sequence":null,"source":"clob_market_ws"}
{"event_at":null,"event_fingerprint":"285155a28fac68f685d90b4d8dfdfc392caa7ddc8ad341f3483a0ba9635e164d","payload":{"connection_id":"efc69d3132f1467b8e898a382b23ac0d","detail":{"interval_seconds":10.0,"message":"PING"},"event_type":"heartbeat","kind":"lifecycle","monotonic_ns":231946282352375,"received_at":"2026-07-27T05:26:03.042488Z","schema_version":"edge-lab-recorder.lifecycle.v1","session_id":"502006c5cfcd437296561ea750c9ec8b","source":"clob_market_ws"},"received_at":"2026-07-27T05:26:03.042488Z","record_id":"89fde046f63a05bcff21e21885e4b6f06265b13b92174144d9bd0798803ce532","schema_fingerprint":"cb8aa3aa4cb168a4b724fd9077bee6ecfb9bc586c57cfdf0ab89f00d82045e3c","schema_version":"edge-lab-recorder.raw.v1","sequence":null,"source":"clob_market_ws"}
{"event_at":null,"event_fingerprint":"264f44e38cd604e3bcdee832383ce8143ce7fdd7313f3d60d03052e945396249","payload":{"connection_id":"efc69d3132f1467b8e898a382b23ac0d","event_type":"heartbeat_ack","frame_hash":"95784973cc639977bff93619700168505cb8f7855e44fa643d34622a43706c87","kind":"lifecycle","monotonic_ns":231946489602708,"raw_frame":"PONG","received_at":"2026-07-27T05:26:03.249743Z","schema_version":"edge-lab-recorder.heartbeat-ack.v1","session_id":"502006c5cfcd437296561ea750c9ec8b","source":"clob_market_ws"},"received_at":"2026-07-27T05:26:03.249743Z","record_id":"613215d80f0adccad355cf1278d444825a9c91e823ce198fe162b6928fe3c6f4","schema_fingerprint":"c14ee1aab3ca674ee738e5268877b544d74c41ad3c427cedc09236467dc68ba1","schema_version":"edge-lab-recorder.raw.v1","sequence":null,"source":"clob_market_ws"}
{"event_at":"2026-07-27T05:26:05.416000Z","event_fingerprint":"3b803f03f023d7cc83ffb5f06278de70c43953d5593f57f6bfecb408002cfed9","payload":{"connection_id":"efc69d3132f1467b8e898a382b23ac0d","event_at":"2026-07-27T05:26:05.416000Z","event_type":"price_change","frame_hash":"fde622add15bd6ab8605eb44e42c02e6b8fc6a4dc51c99eff27ec8592b9df22b","frame_index":0,"kind":"data","monotonic_ns":231948618750958,"payload":{"event_type":"price_change","market":"0x3b40066b5cf3871a2f6237c5628bd8092a206aa998558ac5ec13c4483e31e160","price_changes":[{"asset_id":"14766054693214075530629349735273995982307625376442606753688071083149620216746","best_ask":"0.48","best_bid":"0.47","hash":"039845a8d7f58a52c314d7c4eafc1f5fadd3c4c5","price":"0.43","side":"BUY","size":"310"},{"asset_id":"110216635572655435074987471276357323571387854733835379371586402147734167783946","best_ask":"0.53","best_bid":"0.52","hash":"9b0a4442e90fcf31b6f67aad5d24ea8609136575","price":"0.57","side":"SELL","size":"310"}],"timestamp":"1785129965416"},"payload_hash":"4516107c6e04d80901ef70facde002dad317d9075ea42d702bc0d322f9b9aad0","raw_frame":"{\"market\":\"0x3b40066b5cf3871a2f6237c5628bd8092a206aa998558ac5ec13c4483e31e160\", \"price_changes\":[{\"asset_id\":\"14766054693214075530629349735273995982307625376442606753688071083149620216746\", \"price\":\"0.43\", \"size\":\"310\", \"side\":\"BUY\", \"hash\":\"039845a8d7f58a52c314d7c4eafc1f5fadd3c4c5\", \"best_bid\":\"0.47\", \"best_ask\":\"0.48\"}, {\"asset_id\":\"110216635572655435074987471276357323571387854733835379371586402147734167783946\", \"price\":\"0.57\", \"size\":\"310\", \"side\":\"SELL\", \"hash\":\"9b0a4442e90fcf31b6f67aad5d24ea8609136575\", \"best_bid\":\"0.52\", \"best_ask\":\"0.53\"}], \"timestamp\":\"1785129965416\", \"event_type\":\"price_change\"}","received_at":"2026-07-27T05:26:05.378906Z","schema_version":"clob-market-ws.price_change.v1","sequence":null,"server_hash":null,"server_timestamp":"1785129965416","session_id":"502006c5cfcd437296561ea750c9ec8b","source":"clob_market_ws"},"received_at":"2026-07-27T05:26:05.378906Z","record_id":"10b0c891b3f567de2be486f30eb7f13251ebe65f1ee72bd911a40c8d56899d2f","schema_fingerprint":"4aa3821a28b0b7c2400bc59aba4bcc0a76e971dadd19610d3ad38c768e124dc7","schema_version":"edge-lab-recorder.raw.v1","sequence":null,"source":"clob_market_ws"}
{"event_at":"2026-07-27T05:26:05.416000Z","event_fingerprint":"0c3cfb89bdce37b3fda3f268fea34977bd249e5391a9dd926839b3ef27b3145b","payload":{"connection_id":"efc69d3132f1467b8e898a382b23ac0d","event_at":"2026-07-27T05:26:05.416000Z","event_type":"price_change","frame_hash":"1701005365a86c09ed06ecd345aa5455954a64a2f65efbbbf814c2c1193ecfff","frame_index":0,"kind":"data","monotonic_ns":231948623676250,"payload":{"event_type":"price_change","market":"0x3b40066b5cf3871a2f6237c5628bd8092a206aa998558ac5ec13c4483e31e160","price_changes":[{"asset_id":"14766054693214075530629349735273995982307625376442606753688071083149620216746","best_ask":"0.48","best_bid":"0.47","hash":"039845a8d7f58a52c314d7c4eafc1f5fadd3c4c5","price":"0.41","side":"BUY","size":"304.78"},{"asset_id":"110216635572655435074987471276357323571387854733835379371586402147734167783946","best_ask":"0.53","best_bid":"0.52","hash":"9b0a4442e90fcf31b6f67aad5d24ea8609136575","price":"0.59","side":"SELL","size":"304.78"}],"timestamp":"1785129965416"},"payload_hash":"fd87e8438eb6bea7137baae58a38b69acfe11fa27f38a054d967a332fb8066cc","raw_frame":"{\"market\":\"0x3b40066b5cf3871a2f6237c5628bd8092a206aa998558ac5ec13c4483e31e160\", \"price_changes\":[{\"asset_id\":\"14766054693214075530629349735273995982307625376442606753688071083149620216746\", \"price\":\"0.41\", \"size\":\"304.78\", \"side\":\"BUY\", \"hash\":\"039845a8d7f58a52c314d7c4eafc1f5fadd3c4c5\", \"best_bid\":\"0.47\", \"best_ask\":\"0.48\"}, {\"asset_id\":\"110216635572655435074987471276357323571387854733835379371586402147734167783946\", \"price\":\"0.59\", \"size\":\"304.78\", \"side\":\"SELL\", \"hash\":\"9b0a4442e90fcf31b6f67aad5d24ea8609136575\", \"best_bid\":\"0.52\", \"best_ask\":\"0.53\"}], \"timestamp\":\"1785129965416\", \"event_type\":\"price_change\"}","received_at":"2026-07-27T05:26:05.383827Z","schema_version":"clob-market-ws.price_change.v1","sequence":null,"server_hash":null,"server_timestamp":"1785129965416","session_id":"502006c5cfcd437296561ea750c9ec8b","source":"clob_market_ws"},"received_at":"2026-07-27T05:26:05.383827Z","record_id":"bfd9f37084019fda3c5efba843d6aafdf61cad15a54e8feca91dee0ec507c599","schema_fingerprint":"4aa3821a28b0b7c2400bc59aba4bcc0a76e971dadd19610d3ad38c768e124dc7","schema_version":"edge-lab-recorder.raw.v1","sequence":null,"source":"clob_market_ws"}
{"event_at":"2026-07-27T05:26:05.416000Z","event_fingerprint":"c2127cdc9f398929494eec7273c7a72ff1587f53c7dc4b06b77c217660948177","payload":{"connection_id":"efc69d3132f1467b8e898a382b23ac0d","event_at":"2026-07-27T05:26:05.416000Z","event_type":"price_change","frame_hash":"4ebb622e2890ab3d986bbe94ee5a50c60f039f0971b94e9773ba19186b7e7f9e","frame_index":0,"kind":"data","monotonic_ns":231948631703291,"payload":{"event_type":"price_change","market":"0x3b40066b5cf3871a2f6237c5628bd8092a206aa998558ac5ec13c4483e31e160","price_changes":[{"asset_id":"110216635572655435074987471276357323571387854733835379371586402147734167783946","best_ask":"0.53","best_bid":"0.52","hash":"9b0a4442e90fcf31b6f67aad5d24ea8609136575","price":"0.45","side":"BUY","size":"15.33"},{"asset_id":"14766054693214075530629349735273995982307625376442606753688071083149620216746","best_ask":"0.48","best_bid":"0.47","hash":"039845a8d7f58a52c314d7c4eafc1f5fadd3c4c5","price":"0.55","side":"SELL","size":"15.33"}],"timestamp":"1785129965416"},"payload_hash":"fba11adc25fd610cda65f7cb526a65357776340a6a2c80ab4bb4ff2f3423579e","raw_frame":"{\"market\":\"0x3b40066b5cf3871a2f6237c5628bd8092a206aa998558ac5ec13c4483e31e160\", \"price_changes\":[{\"asset_id\":\"110216635572655435074987471276357323571387854733835379371586402147734167783946\", \"price\":\"0.45\", \"size\":\"15.33\", \"side\":\"BUY\", \"hash\":\"9b0a4442e90fcf31b6f67aad5d24ea8609136575\", \"best_bid\":\"0.52\", \"best_ask\":\"0.53\"}, {\"asset_id\":\"14766054693214075530629349735273995982307625376442606753688071083149620216746\", \"price\":\"0.55\", \"size\":\"15.33\", \"side\":\"SELL\", \"hash\":\"039845a8d7f58a52c314d7c4eafc1f5fadd3c4c5\", \"best_bid\":\"0.47\", \"best_ask\":\"0.48\"}], \"timestamp\":\"1785129965416\", \"event_type\":\"price_change\"}","received_at":"2026-07-27T05:26:05.391859Z","schema_version":"clob-market-ws.price_change.v1","sequence":null,"server_hash":null,"server_timestamp":"1785129965416","session_id":"502006c5cfcd437296561ea750c9ec8b","source":"clob_market_ws"},"received_at":"2026-07-27T05:26:05.391859Z","record_id":"39f5b86a0344315a504ee809ec4d79f33fcf4c5c561c82407a0a357a0c347f27","schema_fingerprint":"4aa3821a28b0b7c2400bc59aba4bcc0a76e971dadd19610d3ad38c768e124dc7","schema_version":"edge-lab-recorder.raw.v1","sequence":null,"source":"clob_market_ws"}
{"event_at":"2026-07-27T05:26:07.177000Z","event_fingerprint":"0752955445d114dfa4509ff98909328e327f0c6e2310d9f79392a68447b89836","payload":{"connection_id":"efc69d3132f1467b8e898a382b23ac0d","event_at":"2026-07-27T05:26:07.177000Z","event_type":"best_bid_ask","frame_hash":"5ef1c187a2761e85a0b899cd3ded413e3f55104a5da8169e538a46f05206a01e","frame_index":0,"kind":"data","monotonic_ns":231950392292250,"payload":{"asset_id":"14766054693214075530629349735273995982307625376442606753688071083149620216746","best_ask":"0.48","best_bid":"0.46","event_type":"best_bid_ask","market":"0x3b40066b5cf3871a2f6237c5628bd8092a206aa998558ac5ec13c4483e31e160","spread":"0.02","timestamp":"1785129967177"},"payload_hash":"cbe243a4bd8e60551e40d43e8c3663f80b702484d64e245a5b22d186c925efc3","raw_frame":"{\"market\":\"0x3b40066b5cf3871a2f6237c5628bd8092a206aa998558ac5ec13c4483e31e160\", \"asset_id\":\"14766054693214075530629349735273995982307625376442606753688071083149620216746\", \"best_bid\":\"0.46\", \"best_ask\":\"0.48\", \"spread\":\"0.02\", \"timestamp\":\"1785129967177\", \"event_type\":\"best_bid_ask\"}","received_at":"2026-07-27T05:26:07.152460Z","schema_version":"clob-market-ws.best_bid_ask.v1","sequence":null,"server_hash":null,"server_timestamp":"1785129967177","session_id":"502006c5cfcd437296561ea750c9ec8b","source":"clob_market_ws"},"received_at":"2026-07-27T05:26:07.152460Z","record_id":"9a395f6e498c1f76a295696ba4e3f43b9c9e7e0ec75d72e9c2f54da188407ec6","schema_fingerprint":"8488399f31b0337811b13b266be932db7062827c2470b78bd8e9e99bab51d17d","schema_version":"edge-lab-recorder.raw.v1","sequence":null,"source":"clob_market_ws"}
{"event_at":"2026-07-27T05:26:07.178000Z","event_fingerprint":"b53389773ace82106fd7bf724b09211015dd5e29cc944b1ca6e096b5fb32fc46","payload":{"connection_id":"efc69d3132f1467b8e898a382b23ac0d","event_at":"2026-07-27T05:26:07.178000Z","event_type":"best_bid_ask","frame_hash":"0b3b64221f61521f22c0568eba85707cd79a1f69e41677c49f9550fc7e89a203","frame_index":0,"kind":"data","monotonic_ns":231950398219666,"payload":{"asset_id":"110216635572655435074987471276357323571387854733835379371586402147734167783946","best_ask":"0.54","best_bid":"0.52","event_type":"best_bid_ask","market":"0x3b40066b5cf3871a2f6237c5628bd8092a206aa998558ac5ec13c4483e31e160","spread":"0.02","timestamp":"1785129967178"},"payload_hash":"0101318aadf3d67e2881ac9b1eb013b9c4478f7c8edb28badc3ce14e1b885a5c","raw_frame":"{\"market\":\"0x3b40066b5cf3871a2f6237c5628bd8092a206aa998558ac5ec13c4483e31e160\", \"asset_id\":\"110216635572655435074987471276357323571387854733835379371586402147734167783946\", \"best_bid\":\"0.52\", \"best_ask\":\"0.54\", \"spread\":\"0.02\", \"timestamp\":\"1785129967178\", \"event_type\":\"best_bid_ask\"}","received_at":"2026-07-27T05:26:07.158387Z","schema_version":"clob-market-ws.best_bid_ask.v1","sequence":null,"server_hash":null,"server_timestamp":"1785129967178","session_id":"502006c5cfcd437296561ea750c9ec8b","source":"clob_market_ws"},"received_at":"2026-07-27T05:26:07.158387Z","record_id":"6c4b5a3ef930149decf4d1e4e9966068fe37f70918f103813eed799bf89ae522","schema_fingerprint":"8488399f31b0337811b13b266be932db7062827c2470b78bd8e9e99bab51d17d","schema_version":"edge-lab-recorder.raw.v1","sequence":null,"source":"clob_market_ws"}
{"event_at":"2026-07-27T05:26:07.177000Z","event_fingerprint":"d082ec1651aeaa45a4fa367165d084b266b43439449b8494a1fa877133c96fa6","payload":{"connection_id":"efc69d3132f1467b8e898a382b23ac0d","event_at":"2026-07-27T05:26:07.177000Z","event_type":"price_change","frame_hash":"29a68a6ac2b692107fce055b5df3a8a6a09f6444a9d7326b493d413c840ce805","frame_index":0,"kind":"data","monotonic_ns":231950403450541,"payload":{"event_type":"price_change","market":"0x3b40066b5cf3871a2f6237c5628bd8092a206aa998558ac5ec13c4483e31e160","price_changes":[{"asset_id":"14766054693214075530629349735273995982307625376442606753688071083149620216746","best_ask":"0.48","best_bid":"0.46","hash":"0c2598014a852bf63d5f3fd9a73cc23b9cb9ea8c","price":"0.46","side":"BUY","size":"24.9"},{"asset_id":"110216635572655435074987471276357323571387854733835379371586402147734167783946","best_ask":"0.54","best_bid":"0.52","hash":"f61fd0d008b882d64f8d3e9e1045f69486335a2c","price":"0.54","side":"SELL","size":"24.9"}],"timestamp":"1785129967177"},"payload_hash":"f7311a99771886f06e300f48ba2d427ffd82076997567e1b77fdc9bcc06535cf","raw_frame":"{\"market\":\"0x3b40066b5cf3871a2f6237c5628bd8092a206aa998558ac5ec13c4483e31e160\", \"price_changes\":[{\"asset_id\":\"14766054693214075530629349735273995982307625376442606753688071083149620216746\", \"price\":\"0.46\", \"size\":\"24.9\", \"side\":\"BUY\", \"hash\":\"0c2598014a852bf63d5f3fd9a73cc23b9cb9ea8c\", \"best_bid\":\"0.46\", \"best_ask\":\"0.48\"}, {\"asset_id\":\"110216635572655435074987471276357323571387854733835379371586402147734167783946\", \"price\":\"0.54\", \"size\":\"24.9\", \"side\":\"SELL\", \"hash\":\"f61fd0d008b882d64f8d3e9e1045f69486335a2c\", \"best_bid\":\"0.52\", \"best_ask\":\"0.54\"}], \"timestamp\":\"1785129967177\", \"event_type\":\"price_change\"}","received_at":"2026-07-27T05:26:07.163624Z","schema_version":"clob-market-ws.price_change.v1","sequence":null,"server_hash":null,"server_timestamp":"1785129967177","session_id":"502006c5cfcd437296561ea750c9ec8b","source":"clob_market_ws"},"received_at":"2026-07-27T05:26:07.163624Z","record_id":"c0e018be553df068c555aeacb27bd1d5b1ef951904528b8fa1aa70c9fd38fecf","schema_fingerprint":"4aa3821a28b0b7c2400bc59aba4bcc0a76e971dadd19610d3ad38c768e124dc7","schema_version":"edge-lab-recorder.raw.v1","sequence":null,"source":"clob_market_ws"}
{"event_at":"2026-07-27T05:26:07.177000Z","event_fingerprint":"63a15030983ff97b7ee9ba680adaec18f2af75efce35edcb64c8379e6656b0d4","payload":{"connection_id":"efc69d3132f1467b8e898a382b23ac0d","event_at":"2026-07-27T05:26:07.177000Z","event_type":"price_change","frame_hash":"e8404d59a3fc52b396a63d94113e3cc0211a19fc63dd988755be064b3a65b518","frame_index":0,"kind":"data","monotonic_ns":231950406748125,"payload":{"event_type":"price_change","market":"0x3b40066b5cf3871a2f6237c5628bd8092a206aa998558ac5ec13c4483e31e160","price_changes":[{"asset_id":"14766054693214075530629349735273995982307625376442606753688071083149620216746","best_ask":"0.48","best_bid":"0.46","hash":"0c2598014a852bf63d5f3fd9a73cc23b9cb9ea8c","price":"0.47","side":"BUY","size":"0"},{"asset_id":"110216635572655435074987471276357323571387854733835379371586402147734167783946","best_ask":"0.54","best_bid":"0.52","hash":"f61fd0d008b882d64f8d3e9e1045f69486335a2c","price":"0.53","side":"SELL","size":"0"}],"timestamp":"1785129967177"},"payload_hash":"e16d987d5703d5538b80d1a0dfc09f4e6e224b67e3655b9192b20d41bda62f49","raw_frame":"{\"market\":\"0x3b40066b5cf3871a2f6237c5628bd8092a206aa998558ac5ec13c4483e31e160\", \"price_changes\":[{\"asset_id\":\"14766054693214075530629349735273995982307625376442606753688071083149620216746\", \"price\":\"0.47\", \"size\":\"0\", \"side\":\"BUY\", \"hash\":\"0c2598014a852bf63d5f3fd9a73cc23b9cb9ea8c\", \"best_bid\":\"0.46\", \"best_ask\":\"0.48\"}, {\"asset_id\":\"110216635572655435074987471276357323571387854733835379371586402147734167783946\", \"price\":\"0.53\", \"size\":\"0\", \"side\":\"SELL\", \"hash\":\"f61fd0d008b882d64f8d3e9e1045f69486335a2c\", \"best_bid\":\"0.52\", \"best_ask\":\"0.54\"}], \"timestamp\":\"1785129967177\", \"event_type\":\"price_change\"}","received_at":"2026-07-27T05:26:07.166916Z","schema_version":"clob-market-ws.price_change.v1","sequence":null,"server_hash":null,"server_timestamp":"1785129967177","session_id":"502006c5cfcd437296561ea750c9ec8b","source":"clob_market_ws"},"received_at":"2026-07-27T05:26:07.166916Z","record_id":"1dbb38cac702e1c74de11abb5530bf6ee45b3a222c85fb5a8f02cdfeed2c17e5","schema_fingerprint":"4aa3821a28b0b7c2400bc59aba4bcc0a76e971dadd19610d3ad38c768e124dc7","schema_version":"edge-lab-recorder.raw.v1","sequence":null,"source":"clob_market_ws"}
