{"event_at":"2026-07-27T05:42:11.670000Z","event_fingerprint":"acaab8062c2015e84489ec7af0ea8f82085b57f1150095e8b217c6650bb48490","payload":{"connection_id":"efc69d3132f1467b8e898a382b23ac0d","event_at":"2026-07-27T05:42:11.670000Z","event_type":"price_change","frame_hash":"e2a74b3f61734df12f2ae26e5fbef0e0b6db77ec85cc71957c5d2bfec4097caa","frame_index":0,"kind":"data","monotonic_ns":232915125493708,"payload":{"event_type":"price_change","market":"0x3b40066b5cf3871a2f6237c5628bd8092a206aa998558ac5ec13c4483e31e160","price_changes":[{"asset_id":"110216635572655435074987471276357323571387854733835379371586402147734167783946","best_ask":"0.27","best_bid":"0.26","hash":"97bfea1b31baf230c3ecdf485d67e19f625461d3","price":"0.26","side":"BUY","size":"11"},{"asset_id":"14766054693214075530629349735273995982307625376442606753688071083149620216746","best_ask":"0.74","best_bid":"0.73","hash":"87c2a656ee7d34f75dc258adf4364ddf6e0a9a8f","price":"0.74","side":"SELL","size":"11"}],"timestamp":"1785130931670"},"payload_hash":"00813d133ff7db2b8825d82f3be129c02f08dfc08fccd8637840582ef00e2121","raw_frame":"{\"market\":\"0x3b40066b5cf3871a2f6237c5628bd8092a206aa998558ac5ec13c4483e31e160\", \"price_changes\":[{\"asset_id\":\"110216635572655435074987471276357323571387854733835379371586402147734167783946\", \"price\":\"0.26\", \"size\":\"11\", \"side\":\"BUY\", \"hash\":\"97bfea1b31baf230c3ecdf485d67e19f625461d3\", \"best_bid\":\"0.26\", \"best_ask\":\"0.27\"}, {\"asset_id\":\"14766054693214075530629349735273995982307625376442606753688071083149620216746\", \"price\":\"0.74\", \"size\":\"11\", \"side\":\"SELL\", \"hash\":\"87c2a656ee7d34f75dc258adf4364ddf6e0a9a8f\", \"best_bid\":\"0.73\", \"best_ask\":\"0.74\"}], \"timestamp\":\"1785130931670\", \"event_type\":\"price_change\"}","received_at":"2026-07-27T05:42:11.892366Z","schema_version":"clob-market-ws.price_change.v1","sequence":null,"server_hash":null,"server_timestamp":"1785130931670","session_id":"502006c5cfcd437296561ea750c9ec8b","source":"clob_market_ws"},"received_at":"2026-07-27T05:42:11.892366Z","record_id":"4445c7d1da54da79793e19da197b40c0fae0bb9f89a185d0e963020021bb4b5a","schema_fingerprint":"4aa3821a28b0b7c2400bc59aba4bcc0a76e971dadd19610d3ad38c768e124dc7","schema_version":"edge-lab-recorder.raw.v1","sequence":null,"source":"clob_market_ws"}
{"event_at":"2026-07-27T05:42:11.670000Z","event_fingerprint":"0aba3a92abf77d52801d69a7836d527fb93abe1f94bb89bb30de13aab2f9b94f","payload":{"connection_id":"efc69d3132f1467b8e898a382b23ac0d","event_at":"2026-07-27T05:42:11.670000Z","event_type":"price_change","frame_hash":"09a038b9a5e04ac679adc4be96aa1a1123236c0b99e8f91f52ddc74f10becaf7","frame_index":0,"kind":"data","monotonic_ns":232915135207583,"payload":{"event_type":"price_change","market":"0x3b40066b5cf3871a2f6237c5628bd8092a206aa998558ac5ec13c4483e31e160","price_changes":[{"asset_id":"14766054693214075530629349735273995982307625376442606753688071083149620216746","best_ask":"0.74","best_bid":"0.73","hash":"e66d5e31edfdfe9c6d7ee4ad2450cdbc503c9d7b","price":"0.65","side":"BUY","size":"48"},{"asset_id":"110216635572655435074987471276357323571387854733835379371586402147734167783946","best_ask":"0.27","best_bid":"0.26","hash":"ac5c7f4d30f8866af4b5b9e2bf953c143c6c4684","price":"0.35","side":"SELL","size":"48"}],"timestamp":"1785130931670"},"payload_hash":"8ba9f3fb5ceb9e203148785d7ba37bf99f927caf514dfe455e0be793986a85f6","raw_frame":"{\"market\":\"0x3b40066b5cf3871a2f6237c5628bd8092a206aa998558ac5ec13c4483e31e160\", \"price_changes\":[{\"asset_id\":\"14766054693214075530629349735273995982307625376442606753688071083149620216746\", \"price\":\"0.65\", \"size\":\"48\", \"side\":\"BUY\", \"hash\":\"e66d5e31edfdfe9c6d7ee4ad2450cdbc503c9d7b\", \"best_bid\":\"0.73\", \"best_ask\":\"0.74\"}, {\"asset_id\":\"110216635572655435074987471276357323571387854733835379371586402147734167783946\", \"price\":\"0.35\", \"size\":\"48\", \"side\":\"SELL\", \"hash\":\"ac5c7f4d30f8866af4b5b9e2bf953c143c6c4684\", \"best_bid\":\"0.26\", \"best_ask\":\"0.27\"}], \"timestamp\":\"1785130931670\", \"event_type\":\"price_change\"}","received_at":"2026-07-27T05:42:11.902083Z","schema_version":"clob-market-ws.price_change.v1","sequence":null,"server_hash":null,"server_timestamp":"1785130931670","session_id":"502006c5cfcd437296561ea750c9ec8b","source":"clob_market_ws"},"received_at":"2026-07-27T05:42:11.902083Z","record_id":"c187288624951855ee91b93eb553c3cb6ed7cfcd67b2a58e11e75078be3fb166","schema_fingerprint":"4aa3821a28b0b7c2400bc59aba4bcc0a76e971dadd19610d3ad38c768e124dc7","schema_version":"edge-lab-recorder.raw.v1","sequence":null,"source":"clob_market_ws"}
{"event_at":"2026-07-27T05:42:11.671000Z","event_fingerprint":"f2251ee79c471bb30666f608c5a91f34949261741f1adb410c3dba9091e252a6","payload":{"connection_id":"efc69d3132f1467b8e898a382b23ac0d","event_at":"2026-07-27T05:42:11.671000Z","event_type":"price_change","frame_hash":"a2d3432083f9e3be8ec772ba8949943637f1bc1cdeb18bec1ab70cd8859e7b9f","frame_index":0,"kind":"data","monotonic_ns":232915138904416,"payload":{"event_type":"price_change","market":"0x3b40066b5cf3871a2f6237c5628bd8092a206aa998558ac5ec13c4483e31e160","price_changes":[{"asset_id":"110216635572655435074987471276357323571387854733835379371586402147734167783946","best_ask":"0.27","best_bid":"0.26","hash":"773cecc02f06088a9192cf1505d44f8f150880ea","price":"0.23","side":"BUY","size":"16.8"},{"asset_id":"14766054693214075530629349735273995982307625376442606753688071083149620216746","best_ask":"0.74","best_bid":"0.73","hash":"13ad087cfa79c7931263d0408c11822eed33e0bc","price":"0.77","side":"SELL","size":"16.8"}],"timestamp":"1785130931671"},"payload_hash":"14bd7b5f69e7c02d4da0654cde5f3517bbc6f9ef51bba342157d955d1255f939","raw_frame":"{\"market\":\"0x3b40066b5cf3871a2f6237c5628bd8092a206aa998558ac5ec13c4483e31e160\", \"price_changes\":[{\"asset_id\":\"110216635572655435074987471276357323571387854733835379371586402147734167783946\", \"price\":\"0.23\", \"size\":\"16.8\", \"side\":\"BUY\", \"hash\":\"773cecc02f06088a9192cf1505d44f8f150880ea\", \"best_bid\":\"0.26\", \"best_ask\":\"0.27\"}, {\"asset_id\":\"14766054693214075530629349735273995982307625376442606753688071083149620216746\", \"price\":\"0.77\", \"size\":\"16.8\", \"side\":\"SELL\", \"hash\":\"13ad087cfa79c7931263d0408c11822eed33e0bc\", \"best_bid\":\"0.73\", \"best_ask\":\"0.74\"}], \"timestamp\":\"1785130931671\", \"event_type\":\"price_change\"}","received_at":"2026-07-27T05:42:11.905780Z","schema_version":"clob-market-ws.price_change.v1","sequence":null,"server_hash":null,"server_timestamp":"1785130931671","session_id":"502006c5cfcd437296561ea750c9ec8b","source":"clob_market_ws"},"received_at":"2026-07-27T05:42:11.905780Z","record_id":"719acfb655dd145cf96130df8157c170cb56afb378127581b9302fb312f6e98f","schema_fingerprint":"4aa3821a28b0b7c2400bc59aba4bcc0a76e971dadd19610d3ad38c768e124dc7","schema_version":"edge-lab-recorder.raw.v1","sequence":null,"source":"clob_market_ws"}
{"event_at":"2026-07-27T05:42:11.672000Z","event_fingerprint":"ddac89fbde3444abc004d73259fd331f225246c2254f4b14653127963380499e","payload":{"connection_id":"efc69d3132f1467b8e898a382b23ac0d","event_at":"2026-07-27T05:42:11.672000Z","event_type":"price_change","frame_hash":"d06d906217b7c352ad26b093aad2ba46337fc4c96d2f86f43232295f773b2baf","frame_index":0,"kind":"data","monotonic_ns":232915141904291,"payload":{"event_type":"price_change","market":"0x3b40066b5cf3871a2f6237c5628bd8092a206aa998558ac5ec13c4483e31e160","price_changes":[{"asset_id":"14766054693214075530629349735273995982307625376442606753688071083149620216746","best_ask":"0.74","best_bid":"0.73","hash":"44146c1fe248880b00a95483f11c9d5267218c73","price":"0.01","side":"BUY","size":"5330.02"},{"asset_id":"110216635572655435074987471276357323571387854733835379371586402147734167783946","best_ask":"0.27","best_bid":"0.26","hash":"de49cbb7ea44fcc3b9138de26a4a648372b4a29b","price":"0.99","side":"SELL","size":"5330.02"}],"timestamp":"1785130931672"},"payload_hash":"b9e81446f1de59b7282ebbcca2fcad220478348de76bc55a5096b78007903805","raw_frame":"{\"market\":\"0x3b40066b5cf3871a2f6237c5628bd8092a206aa998558ac5ec13c4483e31e160\", \"price_changes\":[{\"asset_id\":\"14766054693214075530629349735273995982307625376442606753688071083149620216746\", \"price\":\"0.01\", \"size\":\"5330.02\", \"side\":\"BUY\", \"hash\":\"44146c1fe248880b00a95483f11c9d5267218c73\", \"best_bid\":\"0.73\", \"best_ask\":\"0.74\"}, {\"asset_id\":\"110216635572655435074987471276357323571387854733835379371586402147734167783946\", \"price\":\"0.99\", \"size\":\"5330.02\", \"side\":\"SELL\", \"hash\":\"de49cbb7ea44fcc3b9138de26a4a648372b4a29b\", \"best_bid\":\"0.26\", \"best_ask\":\"0.27\"}], \"timestamp\":\"1785130931672\", \"event_type\":\"price_change\"}","received_at":"2026-07-27T05:42:11.908780Z","schema_version":"clob-market-ws.price_change.v1","sequence":null,"server_hash":null,"server_timestamp":"1785130931672","session_id":"502006c5cfcd437296561ea750c9ec8b","source":"clob_market_ws"},"received_at":"2026-07-27T05:42:11.908780Z","record_id":"742d4a3eb966a532ccedc7b9bd162530dfa7a8aa5804f6f9c7088f6f2a27907c","schema_fingerprint":"4aa3821a28b0b7c2400bc59aba4bcc0a76e971dadd19610d3ad38c768e124dc7","schema_version":"edge-lab-recorder.raw.v1","sequence":null,"source":"clob_market_ws"}
{"event_at":"2026-07-27T05:42:11.672000Z","event_fingerprint":"123cd71fa899cfc0bd176f1c96c4cde7b72eb817a88c3aca47d1fcc283c06c13","payload":{"connection_id":"efc69d3132f1467b8e898a382b23ac0d","event_at":"2026-07-27T05:42:11.672000Z","event_type":"price_change","frame_hash":"4d4da77af552298db61356e5a62c45e1f1e3ecacf17131bdda34216e232333ad","frame_index":0,"kind":"data","monotonic_ns":232915144839333,"payload":{"event_type":"price_change","market":"0x3b40066b5cf3871a2f6237c5628bd8092a206aa998558ac5ec13c4483e31e160","price_changes":[{"asset_id":"110216635572655435074987471276357323571387854733835379371586402147734167783946","best_ask":"0.27","best_bid":"0.26","hash":"363d78cf5eeeb09486aa85bad241a3488c914773","price":"0.25","side":"BUY","size":"11"},{"asset_id":"14766054693214075530629349735273995982307625376442606753688071083149620216746","best_ask":"0.74","best_bid":"0.73","hash":"f40af92804028879654a6ff76274fad6205db69a","price":"0.75","side":"SELL","size":"11"}],"timestamp":"1785130931672"},"payload_hash":"5b0553661ca55ebe11f46c1717d73e2d6729b4bd62bba253fce237093c97faab","raw_frame":"{\"market\":\"0x3b40066b5cf3871a2f6237c5628bd8092a206aa998558ac5ec13c4483e31e160\", \"price_changes\":[{\"asset_id\":\"110216635572655435074987471276357323571387854733835379371586402147734167783946\", \"price\":\"0.25\", \"size\":\"11\", \"side\":\"BUY\", \"hash\":\"363d78cf5eeeb09486aa85bad241a3488c914773\", \"best_bid\":\"0.26\", \"best_ask\":\"0.27\"}, {\"asset_id\":\"14766054693214075530629349735273995982307625376442606753688071083149620216746\", \"price\":\"0.75\", \"size\":\"11\", \"side\":\"SELL\", \"hash\":\"f40af92804028879654a6ff76274fad6205db69a\", \"best_bid\":\"0.73\", \"best_ask\":\"0.74\"}], \"timestamp\":\"1785130931672\", \"event_type\":\"price_change\"}","received_at":"2026-07-27T05:42:11.911713Z","schema_version":"clob-market-ws.price_change.v1","sequence":null,"server_hash":null,"server_timestamp":"1785130931672","session_id":"502006c5cfcd437296561ea750c9ec8b","source":"clob_market_ws"},"received_at":"2026-07-27T05:42:11.911713Z","record_id":"e0f5a0c84d65f20157f8003a7d250cf6707a5ae4d430f5ac44bab5f2e27cb7bb","schema_fingerprint":"4aa3821a28b0b7c2400bc59aba4bcc0a76e971dadd19610d3ad38c768e124dc7","schema_version":"edge-lab-recorder.raw.v1","sequence":null,"source":"clob_market_ws"}
{"event_at":"2026-07-27T05:42:11.674000Z","event_fingerprint":"2a147b2a15491de2cd0d05040e3033d95f9b7ff0710d1255bca1b9b55ca67342","payload":{"connection_id":"efc69d3132f1467b8e898a382b23ac0d","event_at":"2026-07-27T05:42:11.674000Z","event_type":"price_change","frame_hash":"f93e25b28d6c283b04125b1bf117ce53e62dadb9ef06604c580e7da68f126e30","frame_index":0,"kind":"data","monotonic_ns":232915147070041,"payload":{"event_type":"price_change","market":"0x3b40066b5cf3871a2f6237c5628bd8092a206aa998558ac5ec13c4483e31e160","price_changes":[{"asset_id":"14766054693214075530629349735273995982307625376442606753688071083149620216746","best_ask":"0.74","best_bid":"0.73","hash":"1441dc2b0492c258110f3a77cf551d0d85ae6c47","price":"0.01","side":"BUY","size":"5335.02"},{"asset_id":"110216635572655435074987471276357323571387854733835379371586402147734167783946","best_ask":"0.27","best_bid":"0.26","hash":"1f218e3c4cc33718d1a6c3c84cab95365567ba18","price":"0.99","side":"SELL","size":"5335.02"}],"timestamp":"1785130931674"},"payload_hash":"65ecc9f1d37e31f3683ad40c642d96abbecf2ff537359e14822fb9b9216f35af","raw_frame":"{\"market\":\"0x3b40066b5cf3871a2f6237c5628bd8092a206aa998558ac5ec13c4483e31e160\", \"price_changes\":[{\"asset_id\":\"14766054693214075530629349735273995982307625376442606753688071083149620216746\", \"price\":\"0.01\", \"size\":\"5335.02\", \"side\":\"BUY\", \"hash\":\"1441dc2b0492c258110f3a77cf551d0d85ae6c47\", \"best_bid\":\"0.73\", \"best_ask\":\"0.74\"}, {\"asset_id\":\"110216635572655435074987471276357323571387854733835379371586402147734167783946\", \"price\":\"0.99\", \"size\":\"5335.02\", \"side\":\"SELL\", \"hash\":\"1f218e3c4cc33718d1a6c3c84cab95365567ba18\", \"best_bid\":\"0.26\", \"best_ask\":\"0.27\"}], \"timestamp\":\"1785130931674\", \"event_type\":\"price_change\"}","received_at":"2026-07-27T05:42:11.913947Z","schema_version":"clob-market-ws.price_change.v1","sequence":null,"server_hash":null,"server_timestamp":"1785130931674","session_id":"502006c5cfcd437296561ea750c9ec8b","source":"clob_market_ws"},"received_at":"2026-07-27T05:42:11.913947Z","record_id":"183decd6d98aeb38963bb759e1f2c204aa4403da0c59efe2bdd1685595f4285e","schema_fingerprint":"4aa3821a28b0b7c2400bc59aba4bcc0a76e971dadd19610d3ad38c768e124dc7","schema_version":"edge-lab-recorder.raw.v1","sequence":null,"source":"clob_market_ws"}
{"event_at":"2026-07-27T05:42:11.678000Z","event_fingerprint":"aec686f616053ee1935a090fdb0f4d2405dac9077c4230832e7098e9297ce5bd","payload":{"connection_id":"efc69d3132f1467b8e898a382b23ac0d","event_at":"2026-07-27T05:42:11.678000Z","event_type":"price_change","frame_hash":"95707ba0d47b5dc83e8fc1cf2a2b015bba217a6eb68e7f6f66621e655f9b60c9","frame_index":0,"kind":"data","monotonic_ns":232915148915458,"payload":{"event_type":"price_change","market":"0x3b40066b5cf3871a2f6237c5628bd8092a206aa998558ac5ec13c4483e31e160","price_changes":[{"asset_id":"110216635572655435074987471276357323571387854733835379371586402147734167783946","best_ask":"0.27","best_bid":"0.26","hash":"3f0fedfaaf9c0abc6ea2bc25a99f3f146b23fe0f","price":"0.23","side":"BUY","size":"38.8"},{"asset_id":"14766054693214075530629349735273995982307625376442606753688071083149620216746","best_ask":"0.74","best_bid":"0.73","hash":"f0b4af9bddf8033571d59ee7bfc2fda5f5d2a3ee","price":"0.77","side":"SELL","size":"38.8"}],"timestamp":"1785130931678"},"payload_hash":"b447b4e44172533d25b78dee37557343f67348d8e0ac14c3dd23197fdd3c505e","raw_frame":"{\"market\":\"0x3b40066b5cf3871a2f6237c5628bd8092a206aa998558ac5ec13c4483e31e160\", \"price_changes\":[{\"asset_id\":\"110216635572655435074987471276357323571387854733835379371586402147734167783946\", \"price\":\"0.23\", \"size\":\"38.8\", \"side\":\"BUY\", \"hash\":\"3f0fedfaaf9c0abc6ea2bc25a99f3f146b23fe0f\", \"best_bid\":\"0.26\", \"best_ask\":\"0.27\"}, {\"asset_id\":\"14766054693214075530629349735273995982307625376442606753688071083149620216746\", \"price\":\"0.77\", \"size\":\"38.8\", \"side\":\"SELL\", \"hash\":\"f0b4af9bddf8033571d59ee7bfc2fda5f5d2a3ee\", \"best_bid\":\"0.73\", \"best_ask\":\"0.74\"}], \"timestamp\":\"1785130931678\", \"event_type\":\"price_change\"}","received_at":"2026-07-27T05:42:11.915791Z","schema_version":"clob-market-ws.price_change.v1","sequence":null,"server_hash":null,"server_timestamp":"1785130931678","session_id":"502006c5cfcd437296561ea750c9ec8b","source":"clob_market_ws"},"received_at":"2026-07-27T05:42:11.915791Z","record_id":"69b0c9a1fa4de08fd939ab3175fede9ca100b649448b4ad43c091c5235a08045","schema_fingerprint":"4aa3821a28b0b7c2400bc59aba4bcc0a76e971dadd19610d3ad38c768e124dc7","schema_version":"edge-lab-recorder.raw.v1","sequence":null,"source":"clob_market_ws"}
{"event_at":"2026-07-27T05:42:11.679000Z","event_fingerprint":"d0c093d425326017a0ddfc659fe553052fdeaa53b0125435ab7f5353e815b80b","payload":{"connection_id":"efc69d3132f1467b8e898a382b23ac0d","event_at":"2026-07-27T05:42:11.679000Z","event_type":"price_change","frame_hash":"1d6dfe45c7c3ebee44b0e7ba4101058e69e8d2497b2b6d5575a8d4e2e4bb194f","frame_index":0,"kind":"data","monotonic_ns":232915151808000,"payload":{"event_type":"price_change","market":"0x3b40066b5cf3871a2f6237c5628bd8092a206aa998558ac5ec13c4483e31e160","price_changes":[{"asset_id":"110216635572655435074987471276357323571387854733835379371586402147734167783946","best_ask":"0.27","best_bid":"0.26","hash":"8e0e13a83daa3b19d31a398f48be9377161b068c","price":"0.25","side":"BUY","size":"33"},{"asset_id":"14766054693214075530629349735273995982307625376442606753688071083149620216746","best_ask":"0.74","best_bid":"0.73","hash":"b6f50d2ae50003ea8b420664769b89392bdc0d89","price":"0.75","side":"SELL","size":"33"}],"timestamp":"1785130931679"},"payload_hash":"f14d7f2f6677c5498059c0d3c65428b9c875e10984176967bf51ec986ca77887","raw_frame":"{\"market\":\"0x3b40066b5cf3871a2f6237c5628bd8092a206aa998558ac5ec13c4483e31e160\", \"price_changes\":[{\"asset_id\":\"110216635572655435074987471276357323571387854733835379371586402147734167783946\", \"price\":\"0.25\", \"size\":\"33\", \"side\":\"BUY\", \"hash\":\"8e0e13a83daa3b19d31a398f48be9377161b068c\", \"best_bid\":\"0.26\", \"best_ask\":\"0.27\"}, {\"asset_id\":\"14766054693214075530629349735273995982307625376442606753688071083149620216746\", \"price\":\"0.75\", \"size\":\"33\", \"side\":\"SELL\", \"hash\":\"b6f50d2ae50003ea8b420664769b89392bdc0d89\", \"best_bid\":\"0.73\", \"best_ask\":\"0.74\"}], \"timestamp\":\"1785130931679\", \"event_type\":\"price_change\"}","received_at":"2026-07-27T05:42:11.918684Z","schema_version":"clob-market-ws.price_change.v1","sequence":null,"server_hash":null,"server_timestamp":"1785130931679","session_id":"502006c5cfcd437296561ea750c9ec8b","source":"clob_market_ws"},"received_at":"2026-07-27T05:42:11.918684Z","record_id":"cede760e65864253081f6182bbce392020701bd49fc05b156ddaa44080a36b8a","schema_fingerprint":"4aa3821a28b0b7c2400bc59aba4bcc0a76e971dadd19610d3ad38c768e124dc7","schema_version":"edge-lab-recorder.raw.v1","sequence":null,"source":"clob_market_ws"}
{"event_at":"2026-07-27T05:42:11.680000Z","event_fingerprint":"0823c6ced80cb322ada26fc872d0e0773170bd06a36b4682babbf16e9cb66a42","payload":{"connection_id":"efc69d3132f1467b8e898a382b23ac0d","event_at":"2026-07-27T05:42:11.680000Z","event_type":"price_change","frame_hash":"d79a41fa7b3f92830eb22bd4332ca51052c802c1e3f62bcd9e1a9a8f8aee8844","frame_index":0,"kind":"data","monotonic_ns":232915154871708,"payload":{"event_type":"price_change","market":"0x3b40066b5cf3871a2f6237c5628bd8092a206aa998558ac5ec13c4483e31e160","price_changes":[{"asset_id":"14766054693214075530629349735273995982307625376442606753688071083149620216746","best_ask":"0.74","best_bid":"0.73","hash":"0dbdeb80ffd538b49cd1b7549c1b0c22e8308870","price":"0.78","side":"SELL","size":"147.4"},{"asset_id":"110216635572655435074987471276357323571387854733835379371586402147734167783946","best_ask":"0.27","best_bid":"0.26","hash":"b54ec8be5013d2888c95df6e1bf73fc63cb65916","price":"0.22","side":"BUY","size":"147.4"}],"timestamp":"1785130931680"},"payload_hash":"a395fce5678683708c322e7f3e6fee152b98e9709bce59ead9b7a9df3bea5ffb","raw_frame":"{\"market\":\"0x3b40066b5cf3871a2f6237c5628bd8092a206aa998558ac5ec13c4483e31e160\", \"price_changes\":[{\"asset_id\":\"14766054693214075530629349735273995982307625376442606753688071083149620216746\", \"price\":\"0.78\", \"size\":\"147.4\", \"side\":\"SELL\", \"hash\":\"0dbdeb80ffd538b49cd1b7549c1b0c22e8308870\", \"best_bid\":\"0.73\", \"best_ask\":\"0.74\"}, {\"asset_id\":\"110216635572655435074987471276357323571387854733835379371586402147734167783946\", \"price\":\"0.22\", \"size\":\"147.4\", \"side\":\"BUY\", \"hash\":\"b54ec8be5013d2888c95df6e1bf73fc63cb65916\", \"best_bid\":\"0.26\", \"best_ask\":\"0.27\"}], \"timestamp\":\"1785130931680\", \"event_type\":\"price_change\"}","received_at":"2026-07-27T05:42:11.921748Z","schema_version":"clob-market-ws.price_change.v1","sequence":null,"server_hash":null,"server_timestamp":"1785130931680","session_id":"502006c5cfcd437296561ea750c9ec8b","source":"clob_market_ws"},"received_at":"2026-07-27T05:42:11.921748Z","record_id":"5f789766d0921f43200353ee69bc1ae926274fd3f23f00a6d45c856e918f661f","schema_fingerprint":"4aa3821a28b0b7c2400bc59aba4bcc0a76e971dadd19610d3ad38c768e124dc7","schema_version":"edge-lab-recorder.raw.v1","sequence":null,"source":"clob_market_ws"}
{"event_at":"2026-07-27T05:42:11.681000Z","event_fingerprint":"a9e6d7b8214b0e732601d01dd4f12d02bab90320c052c1d2c4696519d27d8812","payload":{"connection_id":"efc69d3132f1467b8e898a382b23ac0d","event_at":"2026-07-27T05:42:11.681000Z","event_type":"price_change","frame_hash":"1c2758e29ceea88035df7882cafe15d7c734a9ab57f9e5c21421a19752a8449a","frame_index":0,"kind":"data","monotonic_ns":232915158990041,"payload":{"event_type":"price_change","market":"0x3b40066b5cf3871a2f6237c5628bd8092a206aa998558ac5ec13c4483e31e160","price_changes":[{"asset_id":"110216635572655435074987471276357323571387854733835379371586402147734167783946","best_ask":"0.27","best_bid":"0.26","hash":"7fcfe91766047965fa3a5d11345b45bb253e698e","price":"0.24","side":"BUY","size":"22"},{"asset_id":"14766054693214075530629349735273995982307625376442606753688071083149620216746","best_ask":"0.74","best_bid":"0.73","hash":"734f008a8324060a0a6c922e0cd4559c4da77350","price":"0.76","side":"SELL","size":"22"}],"timestamp":"1785130931681"},"payload_hash":"98cf6a047ad477a5be282661605812b7aedda5c27ac36c3820b66f7e8642a163","raw_frame":"{\"market\":\"0x3b40066b5cf3871a2f6237c5628bd8092a206aa998558ac5ec13c4483e31e160\", \"price_changes\":[{\"asset_id\":\"110216635572655435074987471276357323571387854733835379371586402147734167783946\", \"price\":\"0.24\", \"size\":\"22\", \"side\":\"BUY\", \"hash\":\"7fcfe91766047965fa3a5d11345b45bb253e698e\", \"best_bid\":\"0.26\", \"best_ask\":\"0.27\"}, {\"asset_id\":\"14766054693214075530629349735273995982307625376442606753688071083149620216746\", \"price\":\"0.76\", \"size\":\"22\", \"side\":\"SELL\", \"hash\":\"734f008a8324060a0a6c922e0cd4559c4da77350\", \"best_bid\":\"0.73\", \"best_ask\":\"0.74\"}], \"timestamp\":\"1785130931681\", \"event_type\":\"price_change\"}","received_at":"2026-07-27T05:42:11.925866Z","schema_version":"clob-market-ws.price_change.v1","sequence":null,"server_hash":null,"server_timestamp":"1785130931681","session_id":"502006c5cfcd437296561ea750c9ec8b","source":"clob_market_ws"},"received_at":"2026-07-27T05:42:11.925866Z","record_id":"a15e97935195d5dfe5e2774972a1676be780af09922842052cd58f6f65924692","schema_fingerprint":"4aa3821a28b0b7c2400bc59aba4bcc0a76e971dadd19610d3ad38c768e124dc7","schema_version":"edge-lab-recorder.raw.v1","sequence":null,"source":"clob_market_ws"}
{"event_at":"2026-07-27T05:42:11.681000Z","event_fingerprint":"201ba64b83d38e0feccb856a4b67e6e0b99a7712e917c06afe4ddc3302936aab","payload":{"connection_id":"efc69d3132f1467b8e898a382b23ac0d","event_at":"2026-07-27T05:42:11.681000Z","event_type":"price_change","frame_hash":"158fa51dda154fca302a9995f57de7496ff3e14233118e31516f6d3e728a4144","frame_index":0,"kind":"data","monotonic_ns":232915163838291,"payload":{"event_type":"price_change","market":"0x3b40066b5cf3871a2f6237c5628bd8092a206aa998558ac5ec13c4483e31e160","price_changes":[{"asset_id":"110216635572655435074987471276357323571387854733835379371586402147734167783946","best_ask":"0.27","best_bid":"0.26","hash":"6a8b10ceb1256f0b193bc7a0883c7fd3b514ab49","price":"0.23","side":"BUY","size":"49.8"},{"asset_id":"14766054693214075530629349735273995982307625376442606753688071083149620216746","best_ask":"0.74","best_bid":"0.73","hash":"c8029f19978712f7f225bdd6ff0211b06b2ccd57","price":"0.77","side":"SELL","size":"49.8"}],"timestamp":"1785130931681"},"payload_hash":"05e59737c8bc2cee6c1fd16000f64b994814c7fea00f378fb263ba56abed4ebe","raw_frame":"{\"market\":\"0x3b40066b5cf3871a2f6237c5628bd8092a206aa998558ac5ec13c4483e31e160\", \"price_changes\":[{\"asset_id\":\"110216635572655435074987471276357323571387854733835379371586402147734167783946\", \"price\":\"0.23\", \"size\":\"49.8\", \"side\":\"BUY\", \"hash\":\"6a8b10ceb1256f0b193bc7a0883c7fd3b514ab49\", \"best_bid\":\"0.26\", \"best_ask\":\"0.27\"}, {\"asset_id\":\"14766054693214075530629349735273995982307625376442606753688071083149620216746\", \"price\":\"0.77\", \"size\":\"49.8\", \"side\":\"SELL\", \"hash\":\"c8029f19978712f7f225bdd6ff0211b06b2ccd57\", \"best_bid\":\"0.73\", \"best_ask\":\"0.74\"}], \"timestamp\":\"1785130931681\", \"event_type\":\"price_change\"}","received_at":"2026-07-27T05:42:11.930715Z","schema_version":"clob-market-ws.price_change.v1","sequence":null,"server_hash":null,"server_timestamp":"1785130931681","session_id":"502006c5cfcd437296561ea750c9ec8b","source":"clob_market_ws"},"received_at":"2026-07-27T05:42:11.930715Z","record_id":"31dae852c0cca1d516f5d14387ffdbce3c87b0346a4b8697d165f35f558e23e7","schema_fingerprint":"4aa3821a28b0b7c2400bc59aba4bcc0a76e971dadd19610d3ad38c768e124dc7","schema_version":"edge-lab-recorder.raw.v1","sequence":null,"source":"clob_market_ws"}
{"event_at":"2026-07-27T05:42:11.682000Z","event_fingerprint":"fdff83d5df17a8ab4c09c13603dfbbe41ffd37b38d9c447d55fc7924866eec80","payload":{"connection_id":"efc69d3132f1467b8e898a382b23ac0d","event_at":"2026-07-27T05:42:11.682000Z","event_type":"price_change","frame_hash":"52ace34912454e9b6713127eaef074aa86976e570fc8120f6108bb24cc5502b4","frame_index":0,"kind":"data","monotonic_ns":232915166801541,"payload":{"event_type":"price_change","market":"0x3b40066b5cf3871a2f6237c5628bd8092a206aa998558ac5ec13c4483e31e160","price_changes":[{"asset_id":"110216635572655435074987471276357323571387854733835379371586402147734167783946","best_ask":"0.27","best_bid":"0.26","hash":"51152b60b64f19616bd192df4470faedabb14f91","price":"0.22","side":"BUY","size":"141.4"},{"asset_id":"14766054693214075530629349735273995982307625376442606753688071083149620216746","best_ask":"0.74","best_bid":"0.73","hash":"47eeb476da297941794aaf3ef16cc6be155bda03","price":"0.78","side":"SELL","size":"141.4"}],"timestamp":"1785130931682"},"payload_hash":"02d508bd5e372396ce15e0cbaab91c0241cbc9ca07e5d1e5fd013bae22d53183","raw_frame":"{\"market\":\"0x3b40066b5cf3871a2f6237c5628bd8092a206aa998558ac5ec13c4483e31e160\", \"price_changes\":[{\"asset_id\":\"110216635572655435074987471276357323571387854733835379371586402147734167783946\", \"price\":\"0.22\", \"size\":\"141.4\", \"side\":\"BUY\", \"hash\":\"51152b60b64f19616bd192df4470faedabb14f91\", \"best_bid\":\"0.26\", \"best_ask\":\"0.27\"}, {\"asset_id\":\"14766054693214075530629349735273995982307625376442606753688071083149620216746\", \"price\":\"0.78\", \"size\":\"141.4\", \"side\":\"SELL\", \"hash\":\"47eeb476da297941794aaf3ef16cc6be155bda03\", \"best_bid\":\"0.73\", \"best_ask\":\"0.74\"}], \"timestamp\":\"1785130931682\", \"event_type\":\"price_change\"}","received_at":"2026-07-27T05:42:11.933678Z","schema_version":"clob-market-ws.price_change.v1","sequence":null,"server_hash":null,"server_timestamp":"1785130931682","session_id":"502006c5cfcd437296561ea750c9ec8b","source":"clob_market_ws"},"received_at":"2026-07-27T05:42:11.933678Z","record_id":"39783f78ddd8125f0fe119deb3362f30e07fdb2b9d911a05af569788a88a6107","schema_fingerprint":"4aa3821a28b0b7c2400bc59aba4bcc0a76e971dadd19610d3ad38c768e124dc7","schema_version":"edge-lab-recorder.raw.v1","sequence":null,"source":"clob_market_ws"}
{"event_at":"2026-07-27T05:42:11.683000Z","event_fingerprint":"f05b952c3d909c453c0136d8dfc5fe23986eefd0aaced257521af6df85719fa7","payload":{"connection_id":"efc69d3132f1467b8e898a382b23ac0d","event_at":"2026-07-27T05:42:11.683000Z","event_type":"price_change","frame_hash":"e2793018696ec26cd42819c103594560955eedf5f68885b23fdb5ce90c161b26","frame_index":0,"kind":"data","monotonic_ns":232915169753791,"payload":{"event_type":"price_change","market":"0x3b40066b5cf3871a2f6237c5628bd8092a206aa998558ac5ec13c4483e31e160","price_changes":[{"asset_id":"14766054693214075530629349735273995982307625376442606753688071083149620216746","best_ask":"0.74","best_bid":"0.73","hash":"aace88e6de9ce64c2c5774db14a9a855afdd88b9","price":"0.63","side":"BUY","size":"80.65"},{"asset_id":"110216635572655435074987471276357323571387854733835379371586402147734167783946","best_ask":"0.27","best_bid":"0.26","hash":"0094b2d3bdc8dbc7d400a6a212c3afa75474f9cd","price":"0.37","side":"SELL","size":"80.65"}],"timestamp":"1785130931683"},"payload_hash":"f8d7dd236af2fd91103285f24ea01f8f277fc60d49cd3525ac12cca4e0aa7b90","raw_frame":"{\"market\":\"0x3b40066b5cf3871a2f6237c5628bd8092a206aa998558ac5ec13c4483e31e160\", \"price_changes\":[{\"asset_id\":\"14766054693214075530629349735273995982307625376442606753688071083149620216746\", \"price\":\"0.63\", \"size\":\"80.65\", \"side\":\"BUY\", \"hash\":\"aace88e6de9ce64c2c5774db14a9a855afdd88b9\", \"best_bid\":\"0.73\", \"best_ask\":\"0.74\"}, {\"asset_id\":\"110216635572655435074987471276357323571387854733835379371586402147734167783946\", \"price\":\"0.37\", \"size\":\"80.65\", \"side\":\"SELL\", \"hash\":\"0094b2d3bdc8dbc7d400a6a212c3afa75474f9cd\", \"best_bid\":\"0.26\", \"best_ask\":\"0.27\"}], \"timestamp\":\"1785130931683\", \"event_type\":\"price_change\"}","received_at":"2026-07-27T05:42:11.936630Z","schema_version":"clob-market-ws.price_change.v1","sequence":null,"server_hash":null,"server_timestamp":"1785130931683","session_id":"502006c5cfcd437296561ea750c9ec8b","source":"clob_market_ws"},"received_at":"2026-07-27T05:42:11.936630Z","record_id":"756df799db041a635c6f6e744b3312a23dd9ce16b5898979ab052a80cc76b607","schema_fingerprint":"4aa3821a28b0b7c2400bc59aba4bcc0a76e971dadd19610d3ad38c768e124dc7","schema_version":"edge-lab-recorder.raw.v1","sequence":null,"source":"clob_market_ws"}
{"event_at":"2026-07-27T05:42:11.684000Z","event_fingerprint":"5d165c1291ec3c664831361e9173c474598e2893d671474849f07d5c950c7d00","payload":{"connection_id":"efc69d3132f1467b8e898a382b23ac0d","event_at":"2026-07-27T05:42:11.684000Z","event_type":"price_change","frame_hash":"24429741835b084b29e790979af9373541fee2afbcff00babd48c3956994fd38","frame_index":0,"kind":"data","monotonic_ns":232915172662708,"payload":{"event_type":"price_change","market":"0x3b40066b5cf3871a2f6237c5628bd8092a206aa998558ac5ec13c4483e31e160","price_changes":[{"asset_id":"110216635572655435074987471276357323571387854733835379371586402147734167783946","best_ask":"0.27","best_bid":"0.26","hash":"23145905738335b5c7f3c1ad491b2300c77f4248","price":"0.22","side":"BUY","size":"128.4"},{"asset_id":"14766054693214075530629349735273995982307625376442606753688071083149620216746","best_ask":"0.74","best_bid":"0.73","hash":"7535f0e7dd8ae6ee62c9bbb77eff203bd17228ae","price":"0.78","side":"SELL","size":"128.4"}],"timestamp":"1785130931684"},"payload_hash":"420ded6685639674e3963d4f8359f93982eb921d23273c75c3884e7a3e82b44e","raw_frame":"{\"market\":\"0x3b40066b5cf3871a2f6237c5628bd8092a206aa998558ac5ec13c4483e31e160\", \"price_changes\":[{\"asset_id\":\"110216635572655435074987471276357323571387854733835379371586402147734167783946\", \"price\":\"0.22\", \"size\":\"128.4\", \"side\":\"BUY\", \"hash\":\"23145905738335b5c7f3c1ad491b2300c77f4248\", \"best_bid\":\"0.26\", \"best_ask\":\"0.27\"}, {\"asset_id\":\"14766054693214075530629349735273995982307625376442606753688071083149620216746\", \"price\":\"0.78\", \"size\":\"128.4\", \"side\":\"SELL\", \"hash\":\"7535f0e7dd8ae6ee62c9bbb77eff203bd17228ae\", \"best_bid\":\"0.73\", \"best_ask\":\"0.74\"}], \"timestamp\":\"1785130931684\", \"event_type\":\"price_change\"}","received_at":"2026-07-27T05:42:11.939540Z","schema_version":"clob-market-ws.price_change.v1","sequence":null,"server_hash":null,"server_timestamp":"1785130931684","session_id":"502006c5cfcd437296561ea750c9ec8b","source":"clob_market_ws"},"received_at":"2026-07-27T05:42:11.939540Z","record_id":"b7bf2cecc88ec8fccf3d02f7001761fe4fdb9cb2c98ba599d9ce328e20c54cad","schema_fingerprint":"4aa3821a28b0b7c2400bc59aba4bcc0a76e971dadd19610d3ad38c768e124dc7","schema_version":"edge-lab-recorder.raw.v1","sequence":null,"source":"clob_market_ws"}
{"event_at":"2026-07-27T05:42:11.685000Z","event_fingerprint":"62bebdb0a327b336678152533c55042922c59d05430793d788ce92e7ba34f5b3","payload":{"connection_id":"efc69d3132f1467b8e898a382b23ac0d","event_at":"2026-07-27T05:42:11.685000Z","event_type":"price_change","frame_hash":"71dd4f343927edc46de2c93f8401898ce9dd9847553c06f6f174c72eba740c1e","frame_index":0,"kind":"data","monotonic_ns":232915175502291,"payload":{"event_type":"price_change","market":"0x3b40066b5cf3871a2f6237c5628bd8092a206aa998558ac5ec13c4483e31e160","price_changes":[{"asset_id":"14766054693214075530629349735273995982307625376442606753688071083149620216746","best_ask":"0.74","best_bid":"0.73","hash":"f45422d25a3f2b72c95c924c80227e80b2dfa7ed","price":"0.59","side":"BUY","size":"68"},{"asset_id":"110216635572655435074987471276357323571387854733835379371586402147734167783946","best_ask":"0.27","best_bid":"0.26","hash":"a34a19e9331eadb408956d10246d0016e6079f53","price":"0.41","side":"SELL","size":"68"}],"timestamp":"1785130931685"},"payload_hash":"22d9aa6bbbacd38daae98cffbba06978af4d5d23963fab4ab22294c60dfe65bc","raw_frame":"{\"market\":\"0x3b40066b5cf3871a2f6237c5628bd8092a206aa998558ac5ec13c4483e31e160\", \"price_changes\":[{\"asset_id\":\"14766054693214075530629349735273995982307625376442606753688071083149620216746\", \"price\":\"0.59\", \"size\":\"68\", \"side\":\"BUY\", \"hash\":\"f45422d25a3f2b72c95c924c80227e80b2dfa7ed\", \"best_bid\":\"0.73\", \"best_ask\":\"0.74\"}, {\"asset_id\":\"110216635572655435074987471276357323571387854733835379371586402147734167783946\", \"price\":\"0.41\", \"size\":\"68\", \"side\":\"SELL\", \"hash\":\"a34a19e9331eadb408956d10246d0016e6079f53\", \"best_bid\":\"0.26\", \"best_ask\":\"0.27\"}], \"timestamp\":\"1785130931685\", \"event_type\":\"price_change\"}","received_at":"2026-07-27T05:42:11.942379Z","schema_version":"clob-market-ws.price_change.v1","sequence":null,"server_hash":null,"server_timestamp":"1785130931685","session_id":"502006c5cfcd437296561ea750c9ec8b","source":"clob_market_ws"},"received_at":"2026-07-27T05:42:11.942379Z","record_id":"deeba7c4c435051a28bc7607c58f8cd501a6b1adcf8ba89cca282beb53c8bf51","schema_fingerprint":"4aa3821a28b0b7c2400bc59aba4bcc0a76e971dadd19610d3ad38c768e124dc7","schema_version":"edge-lab-recorder.raw.v1","sequence":null,"source":"clob_market_ws"}
{"event_at":"2026-07-27T05:42:11.685000Z","event_fingerprint":"0d05dbbc902ffd244ef9b70a6d940185cc441772605fb9ca29e66a41eff37132","payload":{"connection_id":"efc69d3132f1467b8e898a382b23ac0d","event_at":"2026-07-27T05:42:11.685000Z","event_type":"price_change","frame_hash":"6455cb703277cd4fb9d040d8e973403272f900c35be4d6467ebb563cdd6b6336","frame_index":0,"kind":"data","monotonic_ns":232915178349958,"payload":{"event_type":"price_change","market":"0x3b40066b5cf3871a2f6237c5628bd8092a206aa998558ac5ec13c4483e31e160","price_changes":[{"asset_id":"14766054693214075530629349735273995982307625376442606753688071083149620216746","best_ask":"0.74","best_bid":"0.73","hash":"2c84695418214e095f5d333222201ff2d4027111","price":"0.78","side":"SELL","size":"119.4"},{"asset_id":"110216635572655435074987471276357323571387854733835379371586402147734167783946","best_ask":"0.27","best_bid":"0.26","hash":"b07c38476df505c66b9dfabd7f171ec6f6856b99","price":"0.22","side":"BUY","size":"119.4"}],"timestamp":"1785130931685"},"payload_hash":"ca962d9a65bbb3b9a493c9614ba27e9827f93394772aa6322c047301ce7e5e1a","raw_frame":"{\"market\":\"0x3b40066b5cf3871a2f6237c5628bd8092a206aa998558ac5ec13c4483e31e160\", \"price_changes\":[{\"asset_id\":\"14766054693214075530629349735273995982307625376442606753688071083149620216746\", \"price\":\"0.78\", \"size\":\"119.4\", \"side\":\"SELL\", \"hash\":\"2c84695418214e095f5d333222201ff2d4027111\", \"best_bid\":\"0.73\", \"best_ask\":\"0.74\"}, {\"asset_id\":\"110216635572655435074987471276357323571387854733835379371586402147734167783946\", \"price\":\"0.22\", \"size\":\"119.4\", \"side\":\"BUY\", \"hash\":\"b07c38476df505c66b9dfabd7f171ec6f6856b99\", \"best_bid\":\"0.26\", \"best_ask\":\"0.27\"}], \"timestamp\":\"1785130931685\", \"event_type\":\"price_change\"}","received_at":"2026-07-27T05:42:11.945226Z","schema_version":"clob-market-ws.price_change.v1","sequence":null,"server_hash":null,"server_timestamp":"1785130931685","session_id":"502006c5cfcd437296561ea750c9ec8b","source":"clob_market_ws"},"received_at":"2026-07-27T05:42:11.945226Z","record_id":"81b14bef858da8186088102902948e273422cb8726df264d37faa8555f1e2683","schema_fingerprint":"4aa3821a28b0b7c2400bc59aba4bcc0a76e971dadd19610d3ad38c768e124dc7","schema_version":"edge-lab-recorder.raw.v1","sequence":null,"source":"clob_market_ws"}
{"event_at":"2026-07-27T05:42:11.686000Z","event_fingerprint":"e9e3e4a9440ffa67734013cf8537f4fb574052b53b1c63e40bd4374aedd490a4","payload":{"connection_id":"efc69d3132f1467b8e898a382b23ac0d","event_at":"2026-07-27T05:42:11.686000Z","event_type":"price_change","frame_hash":"ef28d483c2bfad59fdc7989534dab774f2c27349bb3b52f9f019933312676f17","frame_index":0,"kind":"data","monotonic_ns":232915181086791,"payload":{"event_type":"price_change","market":"0x3b40066b5cf3871a2f6237c5628bd8092a206aa998558ac5ec13c4483e31e160","price_changes":[{"asset_id":"110216635572655435074987471276357323571387854733835379371586402147734167783946","best_ask":"0.27","best_bid":"0.26","hash":"731e1f61f83374a676c165fe68df0e7c96e1b500","price":"0.26","side":"BUY","size":"33"},{"asset_id":"14766054693214075530629349735273995982307625376442606753688071083149620216746","best_ask":"0.74","best_bid":"0.73","hash":"ce062903243130fa05afad16da8b8cd3d9e902e6","price":"0.74","side":"SELL","size":"33"}],"timestamp":"1785130931686"},"payload_hash":"34e7f4428f415112298a70590d571335277bed39330335e9aef43e8235f00902","raw_frame":"{\"market\":\"0x3b40066b5cf3871a2f6237c5628bd8092a206aa998558ac5ec13c4483e31e160\", \"price_changes\":[{\"asset_id\":\"110216635572655435074987471276357323571387854733835379371586402147734167783946\", \"price\":\"0.26\", \"size\":\"33\", \"side\":\"BUY\", \"hash\":\"731e1f61f83374a676c165fe68df0e7c96e1b500\", \"best_bid\":\"0.26\", \"best_ask\":\"0.27\"}, {\"asset_id\":\"14766054693214075530629349735273995982307625376442606753688071083149620216746\", \"price\":\"0.74\", \"size\":\"33\", \"side\":\"SELL\", \"hash\":\"ce062903243130fa05afad16da8b8cd3d9e902e6\", \"best_bid\":\"0.73\", \"best_ask\":\"0.74\"}], \"timestamp\":\"1785130931686\", \"event_type\":\"price_change\"}","received_at":"2026-07-27T05:42:11.947968Z","schema_version":"clob-market-ws.price_change.v1","sequence":null,"server_hash":null,"server_timestamp":"1785130931686","session_id":"502006c5cfcd437296561ea750c9ec8b","source":"clob_market_ws"},"received_at":"2026-07-27T05:42:11.947968Z","record_id":"73a26b59e9318d5fda55d1c9c815e0c2b387c0da709fd2de653bbcc024f664fb","schema_fingerprint":"4aa3821a28b0b7c2400bc59aba4bcc0a76e971dadd19610d3ad38c768e124dc7","schema_version":"edge-lab-recorder.raw.v1","sequence":null,"source":"clob_market_ws"}
