{"event_at":"2026-07-27T05:40:26.817000Z","event_fingerprint":"539490f1b1f932678806efc413b3a365edbcc7bed39ddcf76fdba64fb33cd33e","payload":{"connection_id":"efc69d3132f1467b8e898a382b23ac0d","event_at":"2026-07-27T05:40:26.817000Z","event_type":"price_change","frame_hash":"e39a9bc416b8efa99bf5832ff882854018697640bb31b33098050adf3d19d65e","frame_index":0,"kind":"data","monotonic_ns":232811848458125,"payload":{"event_type":"price_change","market":"0x3b40066b5cf3871a2f6237c5628bd8092a206aa998558ac5ec13c4483e31e160","price_changes":[{"asset_id":"14766054693214075530629349735273995982307625376442606753688071083149620216746","best_ask":"0.58","best_bid":"0.57","hash":"0136a1b884256b5239572c4aa2b72492d80a5cb3","price":"0.49","side":"BUY","size":"23"},{"asset_id":"110216635572655435074987471276357323571387854733835379371586402147734167783946","best_ask":"0.43","best_bid":"0.42","hash":"8d191411905f63c648ace425c70a3d34bcc4012a","price":"0.51","side":"SELL","size":"23"}],"timestamp":"1785130826817"},"payload_hash":"3a730e3464b13ffb771e2abdf23be90cbe667587479d27ef0ffe1b2fe0e12913","raw_frame":"{\"market\":\"0x3b40066b5cf3871a2f6237c5628bd8092a206aa998558ac5ec13c4483e31e160\", \"price_changes\":[{\"asset_id\":\"14766054693214075530629349735273995982307625376442606753688071083149620216746\", \"price\":\"0.49\", \"size\":\"23\", \"side\":\"BUY\", \"hash\":\"0136a1b884256b5239572c4aa2b72492d80a5cb3\", \"best_bid\":\"0.57\", \"best_ask\":\"0.58\"}, {\"asset_id\":\"110216635572655435074987471276357323571387854733835379371586402147734167783946\", \"price\":\"0.51\", \"size\":\"23\", \"side\":\"SELL\", \"hash\":\"8d191411905f63c648ace425c70a3d34bcc4012a\", \"best_bid\":\"0.42\", \"best_ask\":\"0.43\"}], \"timestamp\":\"1785130826817\", \"event_type\":\"price_change\"}","received_at":"2026-07-27T05:40:28.614617Z","schema_version":"clob-market-ws.price_change.v1","sequence":null,"server_hash":null,"server_timestamp":"1785130826817","session_id":"502006c5cfcd437296561ea750c9ec8b","source":"clob_market_ws"},"received_at":"2026-07-27T05:40:28.614617Z","record_id":"67ad9f47c5abdc9eff2fe4fd450ad4a6b5cab89346d299eb3c999935ba98666e","schema_fingerprint":"4aa3821a28b0b7c2400bc59aba4bcc0a76e971dadd19610d3ad38c768e124dc7","schema_version":"edge-lab-recorder.raw.v1","sequence":null,"source":"clob_market_ws"}
{"event_at":"2026-07-27T05:40:26.817000Z","event_fingerprint":"abc233c4a593a38b3ae1916ecef907e84ec810b74660ca5d1fe63ab5a726fad1","payload":{"connection_id":"efc69d3132f1467b8e898a382b23ac0d","event_at":"2026-07-27T05:40:26.817000Z","event_type":"price_change","frame_hash":"f23c7b9d72a5b121c5e87c6dbd1adc97fad2458fef7c1ede6b2072a61cdc1c1b","frame_index":0,"kind":"data","monotonic_ns":232811861404333,"payload":{"event_type":"price_change","market":"0x3b40066b5cf3871a2f6237c5628bd8092a206aa998558ac5ec13c4483e31e160","price_changes":[{"asset_id":"14766054693214075530629349735273995982307625376442606753688071083149620216746","best_ask":"0.58","best_bid":"0.57","hash":"daafb995ff30eb6787b4e81c34b7aba48b345acf","price":"0.48","side":"BUY","size":"15"},{"asset_id":"110216635572655435074987471276357323571387854733835379371586402147734167783946","best_ask":"0.43","best_bid":"0.42","hash":"05eb169469a2881fda4856bf921041c1b00c2bdf","price":"0.52","side":"SELL","size":"15"}],"timestamp":"1785130826817"},"payload_hash":"9c018aa3fcb5c71b7e5e3d7806f85aa15a18150376c61dcccca920e6b5895e8c","raw_frame":"{\"market\":\"0x3b40066b5cf3871a2f6237c5628bd8092a206aa998558ac5ec13c4483e31e160\", \"price_changes\":[{\"asset_id\":\"14766054693214075530629349735273995982307625376442606753688071083149620216746\", \"price\":\"0.48\", \"size\":\"15\", \"side\":\"BUY\", \"hash\":\"daafb995ff30eb6787b4e81c34b7aba48b345acf\", \"best_bid\":\"0.57\", \"best_ask\":\"0.58\"}, {\"asset_id\":\"110216635572655435074987471276357323571387854733835379371586402147734167783946\", \"price\":\"0.52\", \"size\":\"15\", \"side\":\"SELL\", \"hash\":\"05eb169469a2881fda4856bf921041c1b00c2bdf\", \"best_bid\":\"0.42\", \"best_ask\":\"0.43\"}], \"timestamp\":\"1785130826817\", \"event_type\":\"price_change\"}","received_at":"2026-07-27T05:40:28.627563Z","schema_version":"clob-market-ws.price_change.v1","sequence":null,"server_hash":null,"server_timestamp":"1785130826817","session_id":"502006c5cfcd437296561ea750c9ec8b","source":"clob_market_ws"},"received_at":"2026-07-27T05:40:28.627563Z","record_id":"74d7aae4b053eabc336fa1be0a3f80814f83c2241681ea8057e26d1e2201ab3f","schema_fingerprint":"4aa3821a28b0b7c2400bc59aba4bcc0a76e971dadd19610d3ad38c768e124dc7","schema_version":"edge-lab-recorder.raw.v1","sequence":null,"source":"clob_market_ws"}
{"event_at":"2026-07-27T05:40:26.817000Z","event_fingerprint":"7ff2dc3983111f629b6486d920e1d928fc658501f0eb1a1d11f053eef4676b42","payload":{"connection_id":"efc69d3132f1467b8e898a382b23ac0d","event_at":"2026-07-27T05:40:26.817000Z","event_type":"price_change","frame_hash":"f81e24757a0d28f3fd2dc4c89ab76539ebf81fc93c7de4a2beba9015e187c363","frame_index":0,"kind":"data","monotonic_ns":232811867456875,"payload":{"event_type":"price_change","market":"0x3b40066b5cf3871a2f6237c5628bd8092a206aa998558ac5ec13c4483e31e160","price_changes":[{"asset_id":"110216635572655435074987471276357323571387854733835379371586402147734167783946","best_ask":"0.43","best_bid":"0.42","hash":"71e525e727f841c4d6f998ff252fee832508f7b2","price":"0.31","side":"BUY","size":"123.95"},{"asset_id":"14766054693214075530629349735273995982307625376442606753688071083149620216746","best_ask":"0.58","best_bid":"0.57","hash":"e9a048a4982a942e6c27417d7568539ad856184e","price":"0.69","side":"SELL","size":"123.95"}],"timestamp":"1785130826817"},"payload_hash":"efcb965b66e4d2b0fc8ddd3c05d5b0c891b1412395f95328d4265532fb2fc81a","raw_frame":"{\"market\":\"0x3b40066b5cf3871a2f6237c5628bd8092a206aa998558ac5ec13c4483e31e160\", \"price_changes\":[{\"asset_id\":\"110216635572655435074987471276357323571387854733835379371586402147734167783946\", \"price\":\"0.31\", \"size\":\"123.95\", \"side\":\"BUY\", \"hash\":\"71e525e727f841c4d6f998ff252fee832508f7b2\", \"best_bid\":\"0.42\", \"best_ask\":\"0.43\"}, {\"asset_id\":\"14766054693214075530629349735273995982307625376442606753688071083149620216746\", \"price\":\"0.69\", \"size\":\"123.95\", \"side\":\"SELL\", \"hash\":\"e9a048a4982a942e6c27417d7568539ad856184e\", \"best_bid\":\"0.57\", \"best_ask\":\"0.58\"}], \"timestamp\":\"1785130826817\", \"event_type\":\"price_change\"}","received_at":"2026-07-27T05:40:28.633616Z","schema_version":"clob-market-ws.price_change.v1","sequence":null,"server_hash":null,"server_timestamp":"1785130826817","session_id":"502006c5cfcd437296561ea750c9ec8b","source":"clob_market_ws"},"received_at":"2026-07-27T05:40:28.633616Z","record_id":"3539f3c679b59c58ba92c270ea26bd3bc71dc9e49d60e04e9fed3ace0b3cbbb5","schema_fingerprint":"4aa3821a28b0b7c2400bc59aba4bcc0a76e971dadd19610d3ad38c768e124dc7","schema_version":"edge-lab-recorder.raw.v1","sequence":null,"source":"clob_market_ws"}
{"event_at":"2026-07-27T05:40:26.819000Z","event_fingerprint":"8a6767ea040c05c008d92222aa5d349df5f2b37d4b8fe6f2633d401478670a65","payload":{"connection_id":"efc69d3132f1467b8e898a382b23ac0d","event_at":"2026-07-27T05:40:26.819000Z","event_type":"price_change","frame_hash":"6962362b491c5f29da2663b07c8667b248f8ba58280450a35ad45eb5a862265c","frame_index":0,"kind":"data","monotonic_ns":232811874082208,"payload":{"event_type":"price_change","market":"0x3b40066b5cf3871a2f6237c5628bd8092a206aa998558ac5ec13c4483e31e160","price_changes":[{"asset_id":"110216635572655435074987471276357323571387854733835379371586402147734167783946","best_ask":"0.43","best_bid":"0.42","hash":"afa1bdf8b6af7c79af947190f31a7f18d667e63e","price":"0.31","side":"BUY","size":"153.95"},{"asset_id":"14766054693214075530629349735273995982307625376442606753688071083149620216746","best_ask":"0.58","best_bid":"0.57","hash":"d5dc09a66517ff848bf1fe7e230e1b689dce9f30","price":"0.69","side":"SELL","size":"153.95"}],"timestamp":"1785130826819"},"payload_hash":"90cecd10b48c523255c0327fde737e86237764060f28d1b0f4a37c64518487c7","raw_frame":"{\"market\":\"0x3b40066b5cf3871a2f6237c5628bd8092a206aa998558ac5ec13c4483e31e160\", \"price_changes\":[{\"asset_id\":\"110216635572655435074987471276357323571387854733835379371586402147734167783946\", \"price\":\"0.31\", \"size\":\"153.95\", \"side\":\"BUY\", \"hash\":\"afa1bdf8b6af7c79af947190f31a7f18d667e63e\", \"best_bid\":\"0.42\", \"best_ask\":\"0.43\"}, {\"asset_id\":\"14766054693214075530629349735273995982307625376442606753688071083149620216746\", \"price\":\"0.69\", \"size\":\"153.95\", \"side\":\"SELL\", \"hash\":\"d5dc09a66517ff848bf1fe7e230e1b689dce9f30\", \"best_bid\":\"0.57\", \"best_ask\":\"0.58\"}], \"timestamp\":\"1785130826819\", \"event_type\":\"price_change\"}","received_at":"2026-07-27T05:40:28.640242Z","schema_version":"clob-market-ws.price_change.v1","sequence":null,"server_hash":null,"server_timestamp":"1785130826819","session_id":"502006c5cfcd437296561ea750c9ec8b","source":"clob_market_ws"},"received_at":"2026-07-27T05:40:28.640242Z","record_id":"107c0e659e782e3e891b7a0c5099def1d11e8c88a6ce0d3c18a1740506d81f05","schema_fingerprint":"4aa3821a28b0b7c2400bc59aba4bcc0a76e971dadd19610d3ad38c768e124dc7","schema_version":"edge-lab-recorder.raw.v1","sequence":null,"source":"clob_market_ws"}
{"event_at":"2026-07-27T05:40:26.845000Z","event_fingerprint":"e37378a6a6799df1ab314d426a251952981fa61d6fe2348d355749c5c71891c9","payload":{"connection_id":"efc69d3132f1467b8e898a382b23ac0d","event_at":"2026-07-27T05:40:26.845000Z","event_type":"price_change","frame_hash":"1c84edc027f8fd1e931aad38721782d24b885ec90eea569fb055d3a12498af56","frame_index":0,"kind":"data","monotonic_ns":232811881178041,"payload":{"event_type":"price_change","market":"0x3b40066b5cf3871a2f6237c5628bd8092a206aa998558ac5ec13c4483e31e160","price_changes":[{"asset_id":"110216635572655435074987471276357323571387854733835379371586402147734167783946","best_ask":"0.43","best_bid":"0.42","hash":"d29f198e4b7e616919639f9279b89b2bf8a345c2","price":"0.33","side":"BUY","size":"90"},{"asset_id":"14766054693214075530629349735273995982307625376442606753688071083149620216746","best_ask":"0.58","best_bid":"0.57","hash":"14df5d052060b36d6cacec85299e432fa13e5707","price":"0.67","side":"SELL","size":"90"}],"timestamp":"1785130826845"},"payload_hash":"904c1942eed6a460ec43842c9630c924fced57a3589694b3b5847a383f95841b","raw_frame":"{\"market\":\"0x3b40066b5cf3871a2f6237c5628bd8092a206aa998558ac5ec13c4483e31e160\", \"price_changes\":[{\"asset_id\":\"110216635572655435074987471276357323571387854733835379371586402147734167783946\", \"price\":\"0.33\", \"size\":\"90\", \"side\":\"BUY\", \"hash\":\"d29f198e4b7e616919639f9279b89b2bf8a345c2\", \"best_bid\":\"0.42\", \"best_ask\":\"0.43\"}, {\"asset_id\":\"14766054693214075530629349735273995982307625376442606753688071083149620216746\", \"price\":\"0.67\", \"size\":\"90\", \"side\":\"SELL\", \"hash\":\"14df5d052060b36d6cacec85299e432fa13e5707\", \"best_bid\":\"0.57\", \"best_ask\":\"0.58\"}], \"timestamp\":\"1785130826845\", \"event_type\":\"price_change\"}","received_at":"2026-07-27T05:40:28.647337Z","schema_version":"clob-market-ws.price_change.v1","sequence":null,"server_hash":null,"server_timestamp":"1785130826845","session_id":"502006c5cfcd437296561ea750c9ec8b","source":"clob_market_ws"},"received_at":"2026-07-27T05:40:28.647337Z","record_id":"5e4a9c9e401a3f7c688edcc8c94b5b631d65adbca91fbae4111f401591640b3b","schema_fingerprint":"4aa3821a28b0b7c2400bc59aba4bcc0a76e971dadd19610d3ad38c768e124dc7","schema_version":"edge-lab-recorder.raw.v1","sequence":null,"source":"clob_market_ws"}
{"event_at":"2026-07-27T05:40:26.845000Z","event_fingerprint":"412dcb6d47712b6ea7bb16a2294dce23b218dd4924f1523fccbb3ab575665d87","payload":{"connection_id":"efc69d3132f1467b8e898a382b23ac0d","event_at":"2026-07-27T05:40:26.845000Z","event_type":"price_change","frame_hash":"df60599b540d2954aa2b22bdaad5bc0c863822695ce96cd8a4653b6d9504a205","frame_index":0,"kind":"data","monotonic_ns":232811886049458,"payload":{"event_type":"price_change","market":"0x3b40066b5cf3871a2f6237c5628bd8092a206aa998558ac5ec13c4483e31e160","price_changes":[{"asset_id":"110216635572655435074987471276357323571387854733835379371586402147734167783946","best_ask":"0.43","best_bid":"0.42","hash":"bea99ca1a6aeea1aca5397fef1df302790b4e124","price":"0.3","side":"BUY","size":"91.98"},{"asset_id":"14766054693214075530629349735273995982307625376442606753688071083149620216746","best_ask":"0.58","best_bid":"0.57","hash":"3ad9fbc0f66095a84579ae81cc36bc88b0abc5bb","price":"0.7","side":"SELL","size":"91.98"}],"timestamp":"1785130826845"},"payload_hash":"cdde8f931c02aa3ed558532f5561e3d77f360a5b96d4ce6e80220eec8eee926c","raw_frame":"{\"market\":\"0x3b40066b5cf3871a2f6237c5628bd8092a206aa998558ac5ec13c4483e31e160\", \"price_changes\":[{\"asset_id\":\"110216635572655435074987471276357323571387854733835379371586402147734167783946\", \"price\":\"0.3\", \"size\":\"91.98\", \"side\":\"BUY\", \"hash\":\"bea99ca1a6aeea1aca5397fef1df302790b4e124\", \"best_bid\":\"0.42\", \"best_ask\":\"0.43\"}, {\"asset_id\":\"14766054693214075530629349735273995982307625376442606753688071083149620216746\", \"price\":\"0.7\", \"size\":\"91.98\", \"side\":\"SELL\", \"hash\":\"3ad9fbc0f66095a84579ae81cc36bc88b0abc5bb\", \"best_bid\":\"0.57\", \"best_ask\":\"0.58\"}], \"timestamp\":\"1785130826845\", \"event_type\":\"price_change\"}","received_at":"2026-07-27T05:40:28.652209Z","schema_version":"clob-market-ws.price_change.v1","sequence":null,"server_hash":null,"server_timestamp":"1785130826845","session_id":"502006c5cfcd437296561ea750c9ec8b","source":"clob_market_ws"},"received_at":"2026-07-27T05:40:28.652209Z","record_id":"a6c8f4ed387894e983e87b55785007a6fde2e0357df4d078b9edd4ff77d49fb1","schema_fingerprint":"4aa3821a28b0b7c2400bc59aba4bcc0a76e971dadd19610d3ad38c768e124dc7","schema_version":"edge-lab-recorder.raw.v1","sequence":null,"source":"clob_market_ws"}
{"event_at":"2026-07-27T05:40:26.846000Z","event_fingerprint":"de9353beca7f73aae57ce5b080a3a7def1cf937351112b75469cfbc1ca9b943b","payload":{"connection_id":"efc69d3132f1467b8e898a382b23ac0d","event_at":"2026-07-27T05:40:26.846000Z","event_type":"price_change","frame_hash":"3662d3a4918c8b5a2335f9a010c357a1adeede5c23a7e1a04cc7e16f5719120a","frame_index":0,"kind":"data","monotonic_ns":232811892061375,"payload":{"event_type":"price_change","market":"0x3b40066b5cf3871a2f6237c5628bd8092a206aa998558ac5ec13c4483e31e160","price_changes":[{"asset_id":"110216635572655435074987471276357323571387854733835379371586402147734167783946","best_ask":"0.43","best_bid":"0.42","hash":"4fd73e690f652b0ea52fb2fe12e1aa4b17a2fed0","price":"0.32","side":"BUY","size":"79"},{"asset_id":"14766054693214075530629349735273995982307625376442606753688071083149620216746","best_ask":"0.58","best_bid":"0.57","hash":"fc9a7bdf2f68a12f3dfc81841156a4a156788092","price":"0.68","side":"SELL","size":"79"}],"timestamp":"1785130826846"},"payload_hash":"b806b990bd4497d87ff9493b69c5077861dd1c926105f8cb4aa1e66044752550","raw_frame":"{\"market\":\"0x3b40066b5cf3871a2f6237c5628bd8092a206aa998558ac5ec13c4483e31e160\", \"price_changes\":[{\"asset_id\":\"110216635572655435074987471276357323571387854733835379371586402147734167783946\", \"price\":\"0.32\", \"size\":\"79\", \"side\":\"BUY\", \"hash\":\"4fd73e690f652b0ea52fb2fe12e1aa4b17a2fed0\", \"best_bid\":\"0.42\", \"best_ask\":\"0.43\"}, {\"asset_id\":\"14766054693214075530629349735273995982307625376442606753688071083149620216746\", \"price\":\"0.68\", \"size\":\"79\", \"side\":\"SELL\", \"hash\":\"fc9a7bdf2f68a12f3dfc81841156a4a156788092\", \"best_bid\":\"0.57\", \"best_ask\":\"0.58\"}], \"timestamp\":\"1785130826846\", \"event_type\":\"price_change\"}","received_at":"2026-07-27T05:40:28.658221Z","schema_version":"clob-market-ws.price_change.v1","sequence":null,"server_hash":null,"server_timestamp":"1785130826846","session_id":"502006c5cfcd437296561ea750c9ec8b","source":"clob_market_ws"},"received_at":"2026-07-27T05:40:28.658221Z","record_id":"8ee701ac4a08e752b104dcb050093c2929ae208456f6969e1034f2d929b0c331","schema_fingerprint":"4aa3821a28b0b7c2400bc59aba4bcc0a76e971dadd19610d3ad38c768e124dc7","schema_version":"edge-lab-recorder.raw.v1","sequence":null,"source":"clob_market_ws"}
{"event_at":"2026-07-27T05:40:26.848000Z","event_fingerprint":"cf78de3196638b33dfa6823acbd34c50a8d94a2c199801b538cad4bdc2e4ca12","payload":{"connection_id":"efc69d3132f1467b8e898a382b23ac0d","event_at":"2026-07-27T05:40:26.848000Z","event_type":"price_change","frame_hash":"9818a9375fa974c22e402c32fc124aed33aebbcdcd208a597536a309dad389c3","frame_index":0,"kind":"data","monotonic_ns":232811898544958,"payload":{"event_type":"price_change","market":"0x3b40066b5cf3871a2f6237c5628bd8092a206aa998558ac5ec13c4483e31e160","price_changes":[{"asset_id":"14766054693214075530629349735273995982307625376442606753688071083149620216746","best_ask":"0.58","best_bid":"0.57","hash":"9ca3796cbe02455b68e02c70615cc7a3fd3943ea","price":"0.8","side":"SELL","size":"81.8"},{"asset_id":"110216635572655435074987471276357323571387854733835379371586402147734167783946","best_ask":"0.43","best_bid":"0.42","hash":"ca2e81aa0bc83b254bab5f433506704e5f34534b","price":"0.2","side":"BUY","size":"81.8"}],"timestamp":"1785130826848"},"payload_hash":"c30b7bd99d3897d7e5f0a516b480781c61c2fa5a3d554b4f806161175c18738e","raw_frame":"{\"market\":\"0x3b40066b5cf3871a2f6237c5628bd8092a206aa998558ac5ec13c4483e31e160\", \"price_changes\":[{\"asset_id\":\"14766054693214075530629349735273995982307625376442606753688071083149620216746\", \"price\":\"0.8\", \"size\":\"81.8\", \"side\":\"SELL\", \"hash\":\"9ca3796cbe02455b68e02c70615cc7a3fd3943ea\", \"best_bid\":\"0.57\", \"best_ask\":\"0.58\"}, {\"asset_id\":\"110216635572655435074987471276357323571387854733835379371586402147734167783946\", \"price\":\"0.2\", \"size\":\"81.8\", \"side\":\"BUY\", \"hash\":\"ca2e81aa0bc83b254bab5f433506704e5f34534b\", \"best_bid\":\"0.42\", \"best_ask\":\"0.43\"}], \"timestamp\":\"1785130826848\", \"event_type\":\"price_change\"}","received_at":"2026-07-27T05:40:28.664709Z","schema_version":"clob-market-ws.price_change.v1","sequence":null,"server_hash":null,"server_timestamp":"1785130826848","session_id":"502006c5cfcd437296561ea750c9ec8b","source":"clob_market_ws"},"received_at":"2026-07-27T05:40:28.664709Z","record_id":"3d21eb91c84b9e8b46857d682cd5fecdeab60c2c3d86b91bb0e058733db78945","schema_fingerprint":"4aa3821a28b0b7c2400bc59aba4bcc0a76e971dadd19610d3ad38c768e124dc7","schema_version":"edge-lab-recorder.raw.v1","sequence":null,"source":"clob_market_ws"}
{"event_at":"2026-07-27T05:40:26.852000Z","event_fingerprint":"6d4aefad860ef89b4bbc6c392b7cac667945e0441128be163cd816e235c057e2","payload":{"connection_id":"efc69d3132f1467b8e898a382b23ac0d","event_at":"2026-07-27T05:40:26.852000Z","event_type":"price_change","frame_hash":"ef5cd5450f3395e151f49d6879a563cd7645ee9bfe88b54e44b91a9ccf91f8d7","frame_index":0,"kind":"data","monotonic_ns":232811903981250,"payload":{"event_type":"price_change","market":"0x3b40066b5cf3871a2f6237c5628bd8092a206aa998558ac5ec13c4483e31e160","price_changes":[{"asset_id":"110216635572655435074987471276357323571387854733835379371586402147734167783946","best_ask":"0.43","best_bid":"0.42","hash":"a82638d8cd42d5393c286e4a3d58ba0c0abb931e","price":"0.23","side":"BUY","size":"368.71"},{"asset_id":"14766054693214075530629349735273995982307625376442606753688071083149620216746","best_ask":"0.58","best_bid":"0.57","hash":"4923b113975c99314229bb44e0e5a5a1d26a392d","price":"0.77","side":"SELL","size":"368.71"}],"timestamp":"1785130826852"},"payload_hash":"aca0b49c2d1e3ae60e6eca5703b331c137addb1a9e3f5229ddc1c0666844fccb","raw_frame":"{\"market\":\"0x3b40066b5cf3871a2f6237c5628bd8092a206aa998558ac5ec13c4483e31e160\", \"price_changes\":[{\"asset_id\":\"110216635572655435074987471276357323571387854733835379371586402147734167783946\", \"price\":\"0.23\", \"size\":\"368.71\", \"side\":\"BUY\", \"hash\":\"a82638d8cd42d5393c286e4a3d58ba0c0abb931e\", \"best_bid\":\"0.42\", \"best_ask\":\"0.43\"}, {\"asset_id\":\"14766054693214075530629349735273995982307625376442606753688071083149620216746\", \"price\":\"0.77\", \"size\":\"368.71\", \"side\":\"SELL\", \"hash\":\"4923b113975c99314229bb44e0e5a5a1d26a392d\", \"best_bid\":\"0.57\", \"best_ask\":\"0.58\"}], \"timestamp\":\"1785130826852\", \"event_type\":\"price_change\"}","received_at":"2026-07-27T05:40:28.670141Z","schema_version":"clob-market-ws.price_change.v1","sequence":null,"server_hash":null,"server_timestamp":"1785130826852","session_id":"502006c5cfcd437296561ea750c9ec8b","source":"clob_market_ws"},"received_at":"2026-07-27T05:40:28.670141Z","record_id":"8da13d2ba76ad2b88d6065b65dc64278b739e824e63fbc5ff2003ef7042deaf1","schema_fingerprint":"4aa3821a28b0b7c2400bc59aba4bcc0a76e971dadd19610d3ad38c768e124dc7","schema_version":"edge-lab-recorder.raw.v1","sequence":null,"source":"clob_market_ws"}
{"event_at":"2026-07-27T05:40:26.855000Z","event_fingerprint":"d832e1b48c9252feeaf958a6b2a13ef64467c55e63dcdbed50e03a2005c7c09d","payload":{"connection_id":"efc69d3132f1467b8e898a382b23ac0d","event_at":"2026-07-27T05:40:26.855000Z","event_type":"best_bid_ask","frame_hash":"179cdedc1099ba8b41360e2aae32ed8d7279b56e4fea31706ef4171abf62bfe7","frame_index":0,"kind":"data","monotonic_ns":232811909725833,"payload":{"asset_id":"14766054693214075530629349735273995982307625376442606753688071083149620216746","best_ask":"0.58","best_bid":"0.57","event_type":"best_bid_ask","market":"0x3b40066b5cf3871a2f6237c5628bd8092a206aa998558ac5ec13c4483e31e160","spread":"0.01","timestamp":"1785130826855"},"payload_hash":"69cd1ef2b735995d5a4cb3795ca96f4901721858a11894fd1ecffa92ce750173","raw_frame":"{\"market\":\"0x3b40066b5cf3871a2f6237c5628bd8092a206aa998558ac5ec13c4483e31e160\", \"asset_id\":\"14766054693214075530629349735273995982307625376442606753688071083149620216746\", \"best_bid\":\"0.57\", \"best_ask\":\"0.58\", \"spread\":\"0.01\", \"timestamp\":\"1785130826855\", \"event_type\":\"best_bid_ask\"}","received_at":"2026-07-27T05:40:28.675884Z","schema_version":"clob-market-ws.best_bid_ask.v1","sequence":null,"server_hash":null,"server_timestamp":"1785130826855","session_id":"502006c5cfcd437296561ea750c9ec8b","source":"clob_market_ws"},"received_at":"2026-07-27T05:40:28.675884Z","record_id":"3986df9277d7e2ffd54b0ce037a41354556da6d037973039b96cc4fd482558b4","schema_fingerprint":"8488399f31b0337811b13b266be932db7062827c2470b78bd8e9e99bab51d17d","schema_version":"edge-lab-recorder.raw.v1","sequence":null,"source":"clob_market_ws"}
{"event_at":"2026-07-27T05:40:26.855000Z","event_fingerprint":"1998778c0a53169fd32e11d59cbf9e0d0e86ad77cd4288bbd23cb428f58f5ba7","payload":{"connection_id":"efc69d3132f1467b8e898a382b23ac0d","event_at":"2026-07-27T05:40:26.855000Z","event_type":"best_bid_ask","frame_hash":"4442909c92deddd015254f19a6c3a6ea6e7c8f98a72a738b1a4d43395142c85e","frame_index":0,"kind":"data","monotonic_ns":232811914989083,"payload":{"asset_id":"110216635572655435074987471276357323571387854733835379371586402147734167783946","best_ask":"0.43","best_bid":"0.42","event_type":"best_bid_ask","market":"0x3b40066b5cf3871a2f6237c5628bd8092a206aa998558ac5ec13c4483e31e160","spread":"0.01","timestamp":"1785130826855"},"payload_hash":"4d61260e9488fe8a1c44c57e8ef5a511f4292cc4997c731cf4ae28f021550152","raw_frame":"{\"market\":\"0x3b40066b5cf3871a2f6237c5628bd8092a206aa998558ac5ec13c4483e31e160\", \"asset_id\":\"110216635572655435074987471276357323571387854733835379371586402147734167783946\", \"best_bid\":\"0.42\", \"best_ask\":\"0.43\", \"spread\":\"0.01\", \"timestamp\":\"1785130826855\", \"event_type\":\"best_bid_ask\"}","received_at":"2026-07-27T05:40:28.681153Z","schema_version":"clob-market-ws.best_bid_ask.v1","sequence":null,"server_hash":null,"server_timestamp":"1785130826855","session_id":"502006c5cfcd437296561ea750c9ec8b","source":"clob_market_ws"},"received_at":"2026-07-27T05:40:28.681153Z","record_id":"2456626f87bf340eaf68cb03ac1ae33dad15129ee24a7870ea774342c24bc567","schema_fingerprint":"8488399f31b0337811b13b266be932db7062827c2470b78bd8e9e99bab51d17d","schema_version":"edge-lab-recorder.raw.v1","sequence":null,"source":"clob_market_ws"}
{"event_at":"2026-07-27T05:40:26.855000Z","event_fingerprint":"baa879e1bdfe63c2c26398ed4d3fc70a943a3ffd37315ae3ddce8c4d7b0a5c76","payload":{"connection_id":"efc69d3132f1467b8e898a382b23ac0d","event_at":"2026-07-27T05:40:26.855000Z","event_type":"price_change","frame_hash":"ba8b1657aea35bacb6cea1ae693300edc7f2558a3417b3d55f87ad2477eb23a5","frame_index":0,"kind":"data","monotonic_ns":232811920110208,"payload":{"event_type":"price_change","market":"0x3b40066b5cf3871a2f6237c5628bd8092a206aa998558ac5ec13c4483e31e160","price_changes":[{"asset_id":"110216635572655435074987471276357323571387854733835379371586402147734167783946","best_ask":"0.43","best_bid":"0.42","hash":"75908271c944087751da9ca934ac10f6f8bc60aa","price":"0.42","side":"BUY","size":"134.6"},{"asset_id":"14766054693214075530629349735273995982307625376442606753688071083149620216746","best_ask":"0.58","best_bid":"0.57","hash":"6e38758a72246d58b947a03e8664417926c9bd90","price":"0.58","side":"SELL","size":"134.6"}],"timestamp":"1785130826855"},"payload_hash":"1d18f6c7ae2e329cf8aa7b3bd53514095ac207a47a3b8cf73b839554f6d9983d","raw_frame":"{\"market\":\"0x3b40066b5cf3871a2f6237c5628bd8092a206aa998558ac5ec13c4483e31e160\", \"price_changes\":[{\"asset_id\":\"110216635572655435074987471276357323571387854733835379371586402147734167783946\", \"price\":\"0.42\", \"size\":\"134.6\", \"side\":\"BUY\", \"hash\":\"75908271c944087751da9ca934ac10f6f8bc60aa\", \"best_bid\":\"0.42\", \"best_ask\":\"0.43\"}, {\"asset_id\":\"14766054693214075530629349735273995982307625376442606753688071083149620216746\", \"price\":\"0.58\", \"size\":\"134.6\", \"side\":\"SELL\", \"hash\":\"6e38758a72246d58b947a03e8664417926c9bd90\", \"best_bid\":\"0.57\", \"best_ask\":\"0.58\"}], \"timestamp\":\"1785130826855\", \"event_type\":\"price_change\"}","received_at":"2026-07-27T05:40:28.686270Z","schema_version":"clob-market-ws.price_change.v1","sequence":null,"server_hash":null,"server_timestamp":"1785130826855","session_id":"502006c5cfcd437296561ea750c9ec8b","source":"clob_market_ws"},"received_at":"2026-07-27T05:40:28.686270Z","record_id":"ee13a0acf9e681e16a3e170a31c46fd98ea383dab1a8a710e22b703148c9f3e1","schema_fingerprint":"4aa3821a28b0b7c2400bc59aba4bcc0a76e971dadd19610d3ad38c768e124dc7","schema_version":"edge-lab-recorder.raw.v1","sequence":null,"source":"clob_market_ws"}
{"event_at":"2026-07-27T05:40:26.855000Z","event_fingerprint":"a27d0838873d979ef7f0ed4d766f9273f2a1e5b59c9380bf69a32e3e2631dca9","payload":{"connection_id":"efc69d3132f1467b8e898a382b23ac0d","event_at":"2026-07-27T05:40:26.855000Z","event_type":"book","frame_hash":"203d7c1956dfed9f0fc939cd69f6a7a13a472e20236ff8f19f4719289d0e511f","frame_index":0,"kind":"data","monotonic_ns":232811925310583,"payload":{"asks":[{"price":"0.99","size":"5645.45"},{"price":"0.98","size":"806.1"},{"price":"0.97","size":"676.1"},{"price":"0.96","size":"611.09"},{"price":"0.95","size":"655.68"},{"price":"0.94","size":"638.2"},{"price":"0.93","size":"105.24"},{"price":"0.92","size":"90.79"},{"price":"0.91","size":"114.6"},{"price":"0.9","size":"85.29"},{"price":"0.89","size":"76.6"},{"price":"0.88","size":"103.4"},{"price":"0.87","size":"81.5"},{"price":"0.86","size":"365.9"},{"price":"0.85","size":"96.5"},{"price":"0.84","size":"64.3"},{"price":"0.83","size":"63.3"},{"price":"0.82","size":"91.3"},{"price":"0.81","size":"82.5"},{"price":"0.8","size":"81.8"},{"price":"0.79","size":"89.1"},{"price":"0.78","size":"80.5"},{"price":"0.77","size":"368.71"},{"price":"0.76","size":"107.39"},{"price":"0.75","size":"94"},{"price":"0.74","size":"65"},{"price":"0.73","size":"94"},{"price":"0.72","size":"59.97"},{"price":"0.71","size":"67.04"},{"price":"0.7","size":"91.98"},{"price":"0.69","size":"153.95"},{"price":"0.68","size":"79"},{"price":"0.67","size":"90"},{"price":"0.66","size":"126.79"},{"price":"0.65","size":"54"},{"price":"0.64","size":"101.94"},{"price":"0.63","size":"65.85"},{"price":"0.62","size":"65.68"},{"price":"0.61","size":"104.21"},{"price":"0.6","size":"64.3"},{"price":"0.59","size":"64.4"},{"price":"0.58","size":"134.6"}],"asset_id":"14766054693214075530629349735273995982307625376442606753688071083149620216746","bids":[{"price":"0.01","size":"5633.02"},{"price":"0.02","size":"705.1"},{"price":"0.03","size":"635.1"},{"price":"0.04","size":"641.09"},{"price":"0.05","size":"741.2"},{"price":"0.06","size":"586.2"},{"price":"0.07","size":"616.24"},{"price":"0.08","size":"573.79"},{"price":"0.09","size":"569.6"},{"price":"0.1","size":"266.29"},{"price":"0.11","size":"63.6"},{"price":"0.12","size":"61.4"},{"price":"0.13","size":"89.5"},{"price":"0.14","size":"57.9"},{"price":"0.15","size":"103.5"},{"price":"0.16","size":"85.3"},{"price":"0.17","size":"54.3"},{"price":"0.18","size":"53.3"},{"price":"0.19","size":"95.76"},{"price":"0.2","size":"94.8"},{"price":"0.21","size":"130.52"},{"price":"0.22","size":"87.5"},{"price":"0.23","size":"56.89"},{"price":"0.24","size":"56.39"},{"price":"0.25","size":"114"},{"price":"0.26","size":"54.6"},{"price":"0.27","size":"54.2"},{"price":"0.28","size":"83.9"},{"price":"0.29","size":"53.6"},{"price":"0.3","size":"77.3"},{"price":"0.31","size":"83"},{"price":"0.32","size":"156.96"},{"price":"0.33","size":"46.6"},{"price":"0.34","size":"82.4"},{"price":"0.35","size":"67.5"},{"price":"0.36","size":"51"},{"price":"0.37","size":"80.9"},{"price":"0.38","size":"50.7"},{"price":"0.39","size":"50.6"},{"price":"0.4","size":"103.5"},{"price":"0.41","size":"50.4"},{"price":"0.42","size":"50.3"},{"price":"0.43","size":"80.2"},{"price":"0.44","size":"38"},{"price":"0.45","size":"54"},{"price":"0.46","size":"68"},{"price":"0.47","size":"308"},{"price":"0.48","size":"15"},{"price":"0.49","size":"23"},{"price":"0.5","size":"14"},{"price":"0.51","size":"13"},{"price":"0.52","size":"5"},{"price":"0.53","size":"31"},{"price":"0.57","size":"0.4"}],"event_type":"book","hash":"6e38758a72246d58b947a03e8664417926c9bd90","market":"0x3b40066b5cf3871a2f6237c5628bd8092a206aa998558ac5ec13c4483e31e160","timestamp":"1785130826855"},"payload_hash":"580fd28e9f44fba6e328734b3d3b48a6a419af7caf9566452795c5365d2f5bd5","raw_frame":"{\"market\":\"0x3b40066b5cf3871a2f6237c5628bd8092a206aa998558ac5ec13c4483e31e160\", \"asset_id\":\"14766054693214075530629349735273995982307625376442606753688071083149620216746\", \"bids\":[{\"price\":\"0.01\", \"size\":\"5633.02\"}, {\"price\":\"0.02\", \"size\":\"705.1\"}, {\"price\":\"0.03\", \"size\":\"635.1\"}, {\"price\":\"0.04\", \"size\":\"641.09\"}, {\"price\":\"0.05\", \"size\":\"741.2\"}, {\"price\":\"0.06\", \"size\":\"586.2\"}, {\"price\":\"0.07\", \"size\":\"616.24\"}, {\"price\":\"0.08\", \"size\":\"573.79\"}, {\"price\":\"0.09\", \"size\":\"569.6\"}, {\"price\":\"0.1\", \"size\":\"266.29\"}, {\"price\":\"0.11\", \"size\":\"63.6\"}, {\"price\":\"0.12\", \"size\":\"61.4\"}, {\"price\":\"0.13\", \"size\":\"89.5\"}, {\"price\":\"0.14\", \"size\":\"57.9\"}, {\"price\":\"0.15\", \"size\":\"103.5\"}, {\"price\":\"0.16\", \"size\":\"85.3\"}, {\"price\":\"0.17\", \"size\":\"54.3\"}, {\"price\":\"0.18\", \"size\":\"53.3\"}, {\"price\":\"0.19\", \"size\":\"95.76\"}, {\"price\":\"0.2\", \"size\":\"94.8\"}, {\"price\":\"0.21\", \"size\":\"130.52\"}, {\"price\":\"0.22\", \"size\":\"87.5\"}, {\"price\":\"0.23\", \"size\":\"56.89\"}, {\"price\":\"0.24\", \"size\":\"56.39\"}, {\"price\":\"0.25\", \"size\":\"114\"}, {\"price\":\"0.26\", \"size\":\"54.6\"}, {\"price\":\"0.27\", \"size\":\"54.2\"}, {\"price\":\"0.28\", \"size\":\"83.9\"}, {\"price\":\"0.29\", \"size\":\"53.6\"}, {\"price\":\"0.3\", \"size\":\"77.3\"}, {\"price\":\"0.31\", \"size\":\"83\"}, {\"price\":\"0.32\", \"size\":\"156.96\"}, {\"price\":\"0.33\", \"size\":\"46.6\"}, {\"price\":\"0.34\", \"size\":\"82.4\"}, {\"price\":\"0.35\", \"size\":\"67.5\"}, {\"price\":\"0.36\", \"size\":\"51\"}, {\"price\":\"0.37\", \"size\":\"80.9\"}, {\"price\":\"0.38\", \"size\":\"50.7\"}, {\"price\":\"0.39\", \"size\":\"50.6\"}, {\"price\":\"0.4\", \"size\":\"103.5\"}, {\"price\":\"0.41\", \"size\":\"50.4\"}, {\"price\":\"0.42\", \"size\":\"50.3\"}, {\"price\":\"0.43\", \"size\":\"80.2\"}, {\"price\":\"0.44\", \"size\":\"38\"}, {\"price\":\"0.45\", \"size\":\"54\"}, {\"price\":\"0.46\", \"size\":\"68\"}, {\"price\":\"0.47\", \"size\":\"308\"}, {\"price\":\"0.48\", \"size\":\"15\"}, {\"price\":\"0.49\", \"size\":\"23\"}, {\"price\":\"0.5\", \"size\":\"14\"}, {\"price\":\"0.51\", \"size\":\"13\"}, {\"price\":\"0.52\", \"size\":\"5\"}, {\"price\":\"0.53\", \"size\":\"31\"}, {\"price\":\"0.57\", \"size\":\"0.4\"}], \"asks\":[{\"price\":\"0.99\", \"size\":\"5645.45\"}, {\"price\":\"0.98\", \"size\":\"806.1\"}, {\"price\":\"0.97\", \"size\":\"676.1\"}, {\"price\":\"0.96\", \"size\":\"611.09\"}, {\"price\":\"0.95\", \"size\":\"655.68\"}, {\"price\":\"0.94\", \"size\":\"638.2\"}, {\"price\":\"0.93\", \"size\":\"105.24\"}, {\"price\":\"0.92\", \"size\":\"90.79\"}, {\"price\":\"0.91\", \"size\":\"114.6\"}, {\"price\":\"0.9\", \"size\":\"85.29\"}, {\"price\":\"0.89\", \"size\":\"76.6\"}, {\"price\":\"0.88\", \"size\":\"103.4\"}, {\"price\":\"0.87\", \"size\":\"81.5\"}, {\"price\":\"0.86\", \"size\":\"365.9\"}, {\"price\":\"0.85\", \"size\":\"96.5\"}, {\"price\":\"0.84\", \"size\":\"64.3\"}, {\"price\":\"0.83\", \"size\":\"63.3\"}, {\"price\":\"0.82\", \"size\":\"91.3\"}, {\"price\":\"0.81\", \"size\":\"82.5\"}, {\"price\":\"0.8\", \"size\":\"81.8\"}, {\"price\":\"0.79\", \"size\":\"89.1\"}, {\"price\":\"0.78\", \"size\":\"80.5\"}, {\"price\":\"0.77\", \"size\":\"368.71\"}, {\"price\":\"0.76\", \"size\":\"107.39\"}, {\"price\":\"0.75\", \"size\":\"94\"}, {\"price\":\"0.74\", \"size\":\"65\"}, {\"price\":\"0.73\", \"size\":\"94\"}, {\"price\":\"0.72\", \"size\":\"59.97\"}, {\"price\":\"0.71\", \"size\":\"67.04\"}, {\"price\":\"0.7\", \"size\":\"91.98\"}, {\"price\":\"0.69\", \"size\":\"153.95\"}, {\"price\":\"0.68\", \"size\":\"79\"}, {\"price\":\"0.67\", \"size\":\"90\"}, {\"price\":\"0.66\", \"size\":\"126.79\"}, {\"price\":\"0.65\", \"size\":\"54\"}, {\"price\":\"0.64\", \"size\":\"101.94\"}, {\"price\":\"0.63\", \"size\":\"65.85\"}, {\"price\":\"0.62\", \"size\":\"65.68\"}, {\"price\":\"0.61\", \"size\":\"104.21\"}, {\"price\":\"0.6\", \"size\":\"64.3\"}, {\"price\":\"0.59\", \"size\":\"64.4\"}, {\"price\":\"0.58\", \"size\":\"134.6\"}], \"hash\":\"6e38758a72246d58b947a03e8664417926c9bd90\", \"timestamp\":\"1785130826855\", \"event_type\":\"book\"}","received_at":"2026-07-27T05:40:28.691471Z","schema_version":"clob-market-ws.book.v1","sequence":null,"server_hash":"6e38758a72246d58b947a03e8664417926c9bd90","server_timestamp":"1785130826855","session_id":"502006c5cfcd437296561ea750c9ec8b","source":"clob_market_ws"},"received_at":"2026-07-27T05:40:28.691471Z","record_id":"8b35817cf1fd5b431a0316de7282ce33356e2808f3fb0ce0f062b405267a408c","schema_fingerprint":"dc2caa1c89c6a7426e2e07ff925910cd4d0a8a223a515d4092d91d6d127aacb6","schema_version":"edge-lab-recorder.raw.v1","sequence":null,"source":"clob_market_ws"}
{"event_at":"2026-07-27T05:40:26.855000Z","event_fingerprint":"e367bed2c6f9e6e2b93df0d05c5fd3d0179d94fbf4edeae9b5f7955d73e363c5","payload":{"connection_id":"efc69d3132f1467b8e898a382b23ac0d","event_at":"2026-07-27T05:40:26.855000Z","event_type":"book","frame_hash":"4e6a5fad7e88c5a41729f527fa594805bb86530d4d2b01250f72c70e214f3391","frame_index":0,"kind":"data","monotonic_ns":232811936133541,"payload":{"asks":[{"price":"0.99","size":"5633.02"},{"price":"0.98","size":"705.1"},{"price":"0.97","size":"635.1"},{"price":"0.96","size":"641.09"},{"price":"0.95","size":"741.2"},{"price":"0.94","size":"586.2"},{"price":"0.93","size":"616.24"},{"price":"0.92","size":"573.79"},{"price":"0.91","size":"569.6"},{"price":"0.9","size":"266.29"},{"price":"0.89","size":"63.6"},{"price":"0.88","size":"61.4"},{"price":"0.87","size":"89.5"},{"price":"0.86","size":"57.9"},{"price":"0.85","size":"103.5"},{"price":"0.84","size":"85.3"},{"price":"0.83","size":"54.3"},{"price":"0.82","size":"53.3"},{"price":"0.81","size":"95.76"},{"price":"0.8","size":"94.8"},{"price":"0.79","size":"130.52"},{"price":"0.78","size":"87.5"},{"price":"0.77","size":"56.89"},{"price":"0.76","size":"56.39"},{"price":"0.75","size":"114"},{"price":"0.74","size":"54.6"},{"price":"0.73","size":"54.2"},{"price":"0.72","size":"83.9"},{"price":"0.71","size":"53.6"},{"price":"0.7","size":"77.3"},{"price":"0.69","size":"83"},{"price":"0.68","size":"156.96"},{"price":"0.67","size":"46.6"},{"price":"0.66","size":"82.4"},{"price":"0.65","size":"67.5"},{"price":"0.64","size":"51"},{"price":"0.63","size":"80.9"},{"price":"0.62","size":"50.7"},{"price":"0.61","size":"50.6"},{"price":"0.6","size":"103.5"},{"price":"0.59","size":"50.4"},{"price":"0.58","size":"50.3"},{"price":"0.57","size":"80.2"},{"price":"0.56","size":"38"},{"price":"0.55","size":"54"},{"price":"0.54","size":"68"},{"price":"0.53","size":"308"},{"price":"0.52","size":"15"},{"price":"0.51","size":"23"},{"price":"0.5","size":"14"},{"price":"0.49","size":"13"},{"price":"0.48","size":"5"},{"price":"0.47","size":"31"},{"price":"0.43","size":"0.4"}],"asset_id":"110216635572655435074987471276357323571387854733835379371586402147734167783946","bids":[{"price":"0.01","size":"5645.45"},{"price":"0.02","size":"806.1"},{"price":"0.03","size":"676.1"},{"price":"0.04","size":"611.09"},{"price":"0.05","size":"655.68"},{"price":"0.06","size":"638.2"},{"price":"0.07","size":"105.24"},{"price":"0.08","size":"90.79"},{"price":"0.09","size":"114.6"},{"price":"0.1","size":"85.29"},{"price":"0.11","size":"76.6"},{"price":"0.12","size":"103.4"},{"price":"0.13","size":"81.5"},{"price":"0.14","size":"365.9"},{"price":"0.15","size":"96.5"},{"price":"0.16","size":"64.3"},{"price":"0.17","size":"63.3"},{"price":"0.18","size":"91.3"},{"price":"0.19","size":"82.5"},{"price":"0.2","size":"81.8"},{"price":"0.21","size":"89.1"},{"price":"0.22","size":"80.5"},{"price":"0.23","size":"368.71"},{"price":"0.24","size":"107.39"},{"price":"0.25","size":"94"},{"price":"0.26","size":"65"},{"price":"0.27","size":"94"},{"price":"0.28","size":"59.97"},{"price":"0.29","size":"67.04"},{"price":"0.3","size":"91.98"},{"price":"0.31","size":"153.95"},{"price":"0.32","size":"79"},{"price":"0.33","size":"90"},{"price":"0.34","size":"126.79"},{"price":"0.35","size":"54"},{"price":"0.36","size":"101.94"},{"price":"0.37","size":"65.85"},{"price":"0.38","size":"65.68"},{"price":"0.39","size":"104.21"},{"price":"0.4","size":"64.3"},{"price":"0.41","size":"64.4"},{"price":"0.42","size":"134.6"}],"event_type":"book","hash":"75908271c944087751da9ca934ac10f6f8bc60aa","market":"0x3b40066b5cf3871a2f6237c5628bd8092a206aa998558ac5ec13c4483e31e160","timestamp":"1785130826855"},"payload_hash":"e64eba5502e9c8af7692e9e69eff578cb62950f0b3cb51f286b1112ed1f3b0dc","raw_frame":"{\"market\":\"0x3b40066b5cf3871a2f6237c5628bd8092a206aa998558ac5ec13c4483e31e160\", \"asset_id\":\"110216635572655435074987471276357323571387854733835379371586402147734167783946\", \"bids\":[{\"price\":\"0.01\", \"size\":\"5645.45\"}, {\"price\":\"0.02\", \"size\":\"806.1\"}, {\"price\":\"0.03\", \"size\":\"676.1\"}, {\"price\":\"0.04\", \"size\":\"611.09\"}, {\"price\":\"0.05\", \"size\":\"655.68\"}, {\"price\":\"0.06\", \"size\":\"638.2\"}, {\"price\":\"0.07\", \"size\":\"105.24\"}, {\"price\":\"0.08\", \"size\":\"90.79\"}, {\"price\":\"0.09\", \"size\":\"114.6\"}, {\"price\":\"0.1\", \"size\":\"85.29\"}, {\"price\":\"0.11\", \"size\":\"76.6\"}, {\"price\":\"0.12\", \"size\":\"103.4\"}, {\"price\":\"0.13\", \"size\":\"81.5\"}, {\"price\":\"0.14\", \"size\":\"365.9\"}, {\"price\":\"0.15\", \"size\":\"96.5\"}, {\"price\":\"0.16\", \"size\":\"64.3\"}, {\"price\":\"0.17\", \"size\":\"63.3\"}, {\"price\":\"0.18\", \"size\":\"91.3\"}, {\"price\":\"0.19\", \"size\":\"82.5\"}, {\"price\":\"0.2\", \"size\":\"81.8\"}, {\"price\":\"0.21\", \"size\":\"89.1\"}, {\"price\":\"0.22\", \"size\":\"80.5\"}, {\"price\":\"0.23\", \"size\":\"368.71\"}, {\"price\":\"0.24\", \"size\":\"107.39\"}, {\"price\":\"0.25\", \"size\":\"94\"}, {\"price\":\"0.26\", \"size\":\"65\"}, {\"price\":\"0.27\", \"size\":\"94\"}, {\"price\":\"0.28\", \"size\":\"59.97\"}, {\"price\":\"0.29\", \"size\":\"67.04\"}, {\"price\":\"0.3\", \"size\":\"91.98\"}, {\"price\":\"0.31\", \"size\":\"153.95\"}, {\"price\":\"0.32\", \"size\":\"79\"}, {\"price\":\"0.33\", \"size\":\"90\"}, {\"price\":\"0.34\", \"size\":\"126.79\"}, {\"price\":\"0.35\", \"size\":\"54\"}, {\"price\":\"0.36\", \"size\":\"101.94\"}, {\"price\":\"0.37\", \"size\":\"65.85\"}, {\"price\":\"0.38\", \"size\":\"65.68\"}, {\"price\":\"0.39\", \"size\":\"104.21\"}, {\"price\":\"0.4\", \"size\":\"64.3\"}, {\"price\":\"0.41\", \"size\":\"64.4\"}, {\"price\":\"0.42\", \"size\":\"134.6\"}], \"asks\":[{\"price\":\"0.99\", \"size\":\"5633.02\"}, {\"price\":\"0.98\", \"size\":\"705.1\"}, {\"price\":\"0.97\", \"size\":\"635.1\"}, {\"price\":\"0.96\", \"size\":\"641.09\"}, {\"price\":\"0.95\", \"size\":\"741.2\"}, {\"price\":\"0.94\", \"size\":\"586.2\"}, {\"price\":\"0.93\", \"size\":\"616.24\"}, {\"price\":\"0.92\", \"size\":\"573.79\"}, {\"price\":\"0.91\", \"size\":\"569.6\"}, {\"price\":\"0.9\", \"size\":\"266.29\"}, {\"price\":\"0.89\", \"size\":\"63.6\"}, {\"price\":\"0.88\", \"size\":\"61.4\"}, {\"price\":\"0.87\", \"size\":\"89.5\"}, {\"price\":\"0.86\", \"size\":\"57.9\"}, {\"price\":\"0.85\", \"size\":\"103.5\"}, {\"price\":\"0.84\", \"size\":\"85.3\"}, {\"price\":\"0.83\", \"size\":\"54.3\"}, {\"price\":\"0.82\", \"size\":\"53.3\"}, {\"price\":\"0.81\", \"size\":\"95.76\"}, {\"price\":\"0.8\", \"size\":\"94.8\"}, {\"price\":\"0.79\", \"size\":\"130.52\"}, {\"price\":\"0.78\", \"size\":\"87.5\"}, {\"price\":\"0.77\", \"size\":\"56.89\"}, {\"price\":\"0.76\", \"size\":\"56.39\"}, {\"price\":\"0.75\", \"size\":\"114\"}, {\"price\":\"0.74\", \"size\":\"54.6\"}, {\"price\":\"0.73\", \"size\":\"54.2\"}, {\"price\":\"0.72\", \"size\":\"83.9\"}, {\"price\":\"0.71\", \"size\":\"53.6\"}, {\"price\":\"0.7\", \"size\":\"77.3\"}, {\"price\":\"0.69\", \"size\":\"83\"}, {\"price\":\"0.68\", \"size\":\"156.96\"}, {\"price\":\"0.67\", \"size\":\"46.6\"}, {\"price\":\"0.66\", \"size\":\"82.4\"}, {\"price\":\"0.65\", \"size\":\"67.5\"}, {\"price\":\"0.64\", \"size\":\"51\"}, {\"price\":\"0.63\", \"size\":\"80.9\"}, {\"price\":\"0.62\", \"size\":\"50.7\"}, {\"price\":\"0.61\", \"size\":\"50.6\"}, {\"price\":\"0.6\", \"size\":\"103.5\"}, {\"price\":\"0.59\", \"size\":\"50.4\"}, {\"price\":\"0.58\", \"size\":\"50.3\"}, {\"price\":\"0.57\", \"size\":\"80.2\"}, {\"price\":\"0.56\", \"size\":\"38\"}, {\"price\":\"0.55\", \"size\":\"54\"}, {\"price\":\"0.54\", \"size\":\"68\"}, {\"price\":\"0.53\", \"size\":\"308\"}, {\"price\":\"0.52\", \"size\":\"15\"}, {\"price\":\"0.51\", \"size\":\"23\"}, {\"price\":\"0.5\", \"size\":\"14\"}, {\"price\":\"0.49\", \"size\":\"13\"}, {\"price\":\"0.48\", \"size\":\"5\"}, {\"price\":\"0.47\", \"size\":\"31\"}, {\"price\":\"0.43\", \"size\":\"0.4\"}], \"hash\":\"75908271c944087751da9ca934ac10f6f8bc60aa\", \"timestamp\":\"1785130826855\", \"event_type\":\"book\"}","received_at":"2026-07-27T05:40:28.702293Z","schema_version":"clob-market-ws.book.v1","sequence":null,"server_hash":"75908271c944087751da9ca934ac10f6f8bc60aa","server_timestamp":"1785130826855","session_id":"502006c5cfcd437296561ea750c9ec8b","source":"clob_market_ws"},"received_at":"2026-07-27T05:40:28.702293Z","record_id":"8506197630d82b90e2ffa5848ecec31d401f2cccb5b9dc0332f06bba81d81ce3","schema_fingerprint":"dc2caa1c89c6a7426e2e07ff925910cd4d0a8a223a515d4092d91d6d127aacb6","schema_version":"edge-lab-recorder.raw.v1","sequence":null,"source":"clob_market_ws"}
{"event_at":"2026-07-27T05:40:26.860000Z","event_fingerprint":"6c8ff4631f68607380d9b48fe310d5415f20197e694922277188e68ea24bb6d7","payload":{"connection_id":"efc69d3132f1467b8e898a382b23ac0d","event_at":"2026-07-27T05:40:26.860000Z","event_type":"price_change","frame_hash":"f8c27e7672e1d17391b936258f94cdf64ca726f546e9319df98dce4174ef3e4b","frame_index":0,"kind":"data","monotonic_ns":232811950720333,"payload":{"event_type":"price_change","market":"0x3b40066b5cf3871a2f6237c5628bd8092a206aa998558ac5ec13c4483e31e160","price_changes":[{"asset_id":"14766054693214075530629349735273995982307625376442606753688071083149620216746","best_ask":"0.58","best_bid":"0.57","hash":"7007e2d5733727ae486299f13e13ccb02099b1ed","price":"0.03","side":"BUY","size":"640.1"},{"asset_id":"110216635572655435074987471276357323571387854733835379371586402147734167783946","best_ask":"0.43","best_bid":"0.42","hash":"68850ecfb370fed49a42c052320ceee5fb2d74d9","price":"0.97","side":"SELL","size":"640.1"}],"timestamp":"1785130826860"},"payload_hash":"b8d9b823d4f70f308fa6ffc7863ccf9796b95efa8227e3e138eac6967d55f8c7","raw_frame":"{\"market\":\"0x3b40066b5cf3871a2f6237c5628bd8092a206aa998558ac5ec13c4483e31e160\", \"price_changes\":[{\"asset_id\":\"14766054693214075530629349735273995982307625376442606753688071083149620216746\", \"price\":\"0.03\", \"size\":\"640.1\", \"side\":\"BUY\", \"hash\":\"7007e2d5733727ae486299f13e13ccb02099b1ed\", \"best_bid\":\"0.57\", \"best_ask\":\"0.58\"}, {\"asset_id\":\"110216635572655435074987471276357323571387854733835379371586402147734167783946\", \"price\":\"0.97\", \"size\":\"640.1\", \"side\":\"SELL\", \"hash\":\"68850ecfb370fed49a42c052320ceee5fb2d74d9\", \"best_bid\":\"0.42\", \"best_ask\":\"0.43\"}], \"timestamp\":\"1785130826860\", \"event_type\":\"price_change\"}","received_at":"2026-07-27T05:40:28.716877Z","schema_version":"clob-market-ws.price_change.v1","sequence":null,"server_hash":null,"server_timestamp":"1785130826860","session_id":"502006c5cfcd437296561ea750c9ec8b","source":"clob_market_ws"},"received_at":"2026-07-27T05:40:28.716877Z","record_id":"cc0b7709b31219c928abd102d22346051515aacb7e99651174a2279f3c99235c","schema_fingerprint":"4aa3821a28b0b7c2400bc59aba4bcc0a76e971dadd19610d3ad38c768e124dc7","schema_version":"edge-lab-recorder.raw.v1","sequence":null,"source":"clob_market_ws"}
{"event_at":"2026-07-27T05:40:26.861000Z","event_fingerprint":"1cfecf979e0e6c34565296f7197e4182c5ff223774565d3609731552ce7431ca","payload":{"connection_id":"efc69d3132f1467b8e898a382b23ac0d","event_at":"2026-07-27T05:40:26.861000Z","event_type":"price_change","frame_hash":"c4aeaff2676e48c4010c568a5d9d47d11dff35178cbfffb5bae1176a2b291bdd","frame_index":0,"kind":"data","monotonic_ns":232811956234958,"payload":{"event_type":"price_change","market":"0x3b40066b5cf3871a2f6237c5628bd8092a206aa998558ac5ec13c4483e31e160","price_changes":[{"asset_id":"14766054693214075530629349735273995982307625376442606753688071083149620216746","best_ask":"0.58","best_bid":"0.57","hash":"d9bbafd416e0d892b06bf1ed5d44ece44f5c1b4e","price":"0.32","side":"BUY","size":"261.12"},{"asset_id":"110216635572655435074987471276357323571387854733835379371586402147734167783946","best_ask":"0.43","best_bid":"0.42","hash":"1814c0dbb3fb31a756c6c82afeadc01c3b0cc992","price":"0.68","side":"SELL","size":"261.12"}],"timestamp":"1785130826861"},"payload_hash":"3152b1673999f9df5ec31b85c33ac0095b4183711c7e8de90ab83fbd6134f508","raw_frame":"{\"market\":\"0x3b40066b5cf3871a2f6237c5628bd8092a206aa998558ac5ec13c4483e31e160\", \"price_changes\":[{\"asset_id\":\"14766054693214075530629349735273995982307625376442606753688071083149620216746\", \"price\":\"0.32\", \"size\":\"261.12\", \"side\":\"BUY\", \"hash\":\"d9bbafd416e0d892b06bf1ed5d44ece44f5c1b4e\", \"best_bid\":\"0.57\", \"best_ask\":\"0.58\"}, {\"asset_id\":\"110216635572655435074987471276357323571387854733835379371586402147734167783946\", \"price\":\"0.68\", \"size\":\"261.12\", \"side\":\"SELL\", \"hash\":\"1814c0dbb3fb31a756c6c82afeadc01c3b0cc992\", \"best_bid\":\"0.42\", \"best_ask\":\"0.43\"}], \"timestamp\":\"1785130826861\", \"event_type\":\"price_change\"}","received_at":"2026-07-27T05:40:28.722386Z","schema_version":"clob-market-ws.price_change.v1","sequence":null,"server_hash":null,"server_timestamp":"1785130826861","session_id":"502006c5cfcd437296561ea750c9ec8b","source":"clob_market_ws"},"received_at":"2026-07-27T05:40:28.722386Z","record_id":"e2d9c638c61a4d5f2f37d14928ce600d024b536320f6e09bbdae8dd78d954e33","schema_fingerprint":"4aa3821a28b0b7c2400bc59aba4bcc0a76e971dadd19610d3ad38c768e124dc7","schema_version":"edge-lab-recorder.raw.v1","sequence":null,"source":"clob_market_ws"}
{"event_at":"2026-07-27T05:40:26.872000Z","event_fingerprint":"9952783ad390ff677b726062037916b6891f9f558b9b2148dd7aa33963d34f17","payload":{"connection_id":"efc69d3132f1467b8e898a382b23ac0d","event_at":"2026-07-27T05:40:26.872000Z","event_type":"price_change","frame_hash":"433773560193582b505ff6938f8a001bc76e95ca2c5d514e6aed3674b1c2c6eb","frame_index":0,"kind":"data","monotonic_ns":232811962679333,"payload":{"event_type":"price_change","market":"0x3b40066b5cf3871a2f6237c5628bd8092a206aa998558ac5ec13c4483e31e160","price_changes":[{"asset_id":"14766054693214075530629349735273995982307625376442606753688071083149620216746","best_ask":"0.58","best_bid":"0.57","hash":"82caf1bbb0f69949e718c6e38d876ceef9a83971","price":"0.74","side":"SELL","size":"105"},{"asset_id":"110216635572655435074987471276357323571387854733835379371586402147734167783946","best_ask":"0.43","best_bid":"0.42","hash":"7aec2a6993b4ea27f12312b82a6a72de385fcdc0","price":"0.26","side":"BUY","size":"105"}],"timestamp":"1785130826872"},"payload_hash":"3292a38218bf51b28d645e0e1a6ae8fbfa485599069886c856da8aa2c861779d","raw_frame":"{\"market\":\"0x3b40066b5cf3871a2f6237c5628bd8092a206aa998558ac5ec13c4483e31e160\", \"price_changes\":[{\"asset_id\":\"14766054693214075530629349735273995982307625376442606753688071083149620216746\", \"price\":\"0.74\", \"size\":\"105\", \"side\":\"SELL\", \"hash\":\"82caf1bbb0f69949e718c6e38d876ceef9a83971\", \"best_bid\":\"0.57\", \"best_ask\":\"0.58\"}, {\"asset_id\":\"110216635572655435074987471276357323571387854733835379371586402147734167783946\", \"price\":\"0.26\", \"size\":\"105\", \"side\":\"BUY\", \"hash\":\"7aec2a6993b4ea27f12312b82a6a72de385fcdc0\", \"best_bid\":\"0.42\", \"best_ask\":\"0.43\"}], \"timestamp\":\"1785130826872\", \"event_type\":\"price_change\"}","received_at":"2026-07-27T05:40:28.728819Z","schema_version":"clob-market-ws.price_change.v1","sequence":null,"server_hash":null,"server_timestamp":"1785130826872","session_id":"502006c5cfcd437296561ea750c9ec8b","source":"clob_market_ws"},"received_at":"2026-07-27T05:40:28.728819Z","record_id":"90b008eaa29ece8bc3bd34983908e9c3e0bcdc1ee46ea5d40942358d86dfc2d7","schema_fingerprint":"4aa3821a28b0b7c2400bc59aba4bcc0a76e971dadd19610d3ad38c768e124dc7","schema_version":"edge-lab-recorder.raw.v1","sequence":null,"source":"clob_market_ws"}
{"event_at":"2026-07-27T05:40:26.874000Z","event_fingerprint":"072ca394b31228d68cb0c8eee4db3eb681d7e6d5a92f1ee68da81d2835dc261f","payload":{"connection_id":"efc69d3132f1467b8e898a382b23ac0d","event_at":"2026-07-27T05:40:26.874000Z","event_type":"price_change","frame_hash":"a5c2af0db90993cab6c8c133f266e15930d3ad57375eee0ad2fa54e0915eafa3","frame_index":0,"kind":"data","monotonic_ns":232811967558833,"payload":{"event_type":"price_change","market":"0x3b40066b5cf3871a2f6237c5628bd8092a206aa998558ac5ec13c4483e31e160","price_changes":[{"asset_id":"14766054693214075530629349735273995982307625376442606753688071083149620216746","best_ask":"0.58","best_bid":"0.57","hash":"407939a58c59776907c93f50253c3dbba5e958fb","price":"0.58","side":"SELL","size":"159.6"},{"asset_id":"110216635572655435074987471276357323571387854733835379371586402147734167783946","best_ask":"0.43","best_bid":"0.42","hash":"3fcdd9edad3ebab0f8733d68f3818ba1b0694982","price":"0.42","side":"BUY","size":"159.6"}],"timestamp":"1785130826874"},"payload_hash":"1a2fa5610e3647b895d0bf4af1c9ec42b2bb088dd3576f5b2f9fd3183a6945ce","raw_frame":"{\"market\":\"0x3b40066b5cf3871a2f6237c5628bd8092a206aa998558ac5ec13c4483e31e160\", \"price_changes\":[{\"asset_id\":\"14766054693214075530629349735273995982307625376442606753688071083149620216746\", \"price\":\"0.58\", \"size\":\"159.6\", \"side\":\"SELL\", \"hash\":\"407939a58c59776907c93f50253c3dbba5e958fb\", \"best_bid\":\"0.57\", \"best_ask\":\"0.58\"}, {\"asset_id\":\"110216635572655435074987471276357323571387854733835379371586402147734167783946\", \"price\":\"0.42\", \"size\":\"159.6\", \"side\":\"BUY\", \"hash\":\"3fcdd9edad3ebab0f8733d68f3818ba1b0694982\", \"best_bid\":\"0.42\", \"best_ask\":\"0.43\"}], \"timestamp\":\"1785130826874\", \"event_type\":\"price_change\"}","received_at":"2026-07-27T05:40:28.733720Z","schema_version":"clob-market-ws.price_change.v1","sequence":null,"server_hash":null,"server_timestamp":"1785130826874","session_id":"502006c5cfcd437296561ea750c9ec8b","source":"clob_market_ws"},"received_at":"2026-07-27T05:40:28.733720Z","record_id":"227c8d4b2fded96abae6feb65d0527f5ce4d551c35671ba6f2138bdf40faf3a8","schema_fingerprint":"4aa3821a28b0b7c2400bc59aba4bcc0a76e971dadd19610d3ad38c768e124dc7","schema_version":"edge-lab-recorder.raw.v1","sequence":null,"source":"clob_market_ws"}
{"event_at":"2026-07-27T05:40:26.876000Z","event_fingerprint":"9cf8c24ef473c3f3c9332520d825ec6188239cc8394450c1fd1bdecf2fb2ae22","payload":{"connection_id":"efc69d3132f1467b8e898a382b23ac0d","event_at":"2026-07-27T05:40:26.876000Z","event_type":"price_change","frame_hash":"3b37a1f9d659e9f68e7d31ca63397ef8ef19bb45c8a3797f404f753dfc430c17","frame_index":0,"kind":"data","monotonic_ns":232811974106458,"payload":{"event_type":"price_change","market":"0x3b40066b5cf3871a2f6237c5628bd8092a206aa998558ac5ec13c4483e31e160","price_changes":[{"asset_id":"110216635572655435074987471276357323571387854733835379371586402147734167783946","best_ask":"0.43","best_bid":"0.42","hash":"4427001aaf2f6c83151b6fd14203a51b140d423e","price":"0.42","side":"BUY","size":"184.6"},{"asset_id":"14766054693214075530629349735273995982307625376442606753688071083149620216746","best_ask":"0.58","best_bid":"0.57","hash":"6f55728ef600ea52df7b79902e67a11089f0768e","price":"0.58","side":"SELL","size":"184.6"}],"timestamp":"1785130826876"},"payload_hash":"da327c9ba7aae1253f4a08a3122f3321b2d3c2a1ca904a26edb34d6a36ced077","raw_frame":"{\"market\":\"0x3b40066b5cf3871a2f6237c5628bd8092a206aa998558ac5ec13c4483e31e160\", \"price_changes\":[{\"asset_id\":\"110216635572655435074987471276357323571387854733835379371586402147734167783946\", \"price\":\"0.42\", \"size\":\"184.6\", \"side\":\"BUY\", \"hash\":\"4427001aaf2f6c83151b6fd14203a51b140d423e\", \"best_bid\":\"0.42\", \"best_ask\":\"0.43\"}, {\"asset_id\":\"14766054693214075530629349735273995982307625376442606753688071083149620216746\", \"price\":\"0.58\", \"size\":\"184.6\", \"side\":\"SELL\", \"hash\":\"6f55728ef600ea52df7b79902e67a11089f0768e\", \"best_bid\":\"0.57\", \"best_ask\":\"0.58\"}], \"timestamp\":\"1785130826876\", \"event_type\":\"price_change\"}","received_at":"2026-07-27T05:40:28.740266Z","schema_version":"clob-market-ws.price_change.v1","sequence":null,"server_hash":null,"server_timestamp":"1785130826876","session_id":"502006c5cfcd437296561ea750c9ec8b","source":"clob_market_ws"},"received_at":"2026-07-27T05:40:28.740266Z","record_id":"01b2d3e2107439fc29bf24fa1c2a62a6c9b6cbe6310f2d1c1ad23ad65caa143c","schema_fingerprint":"4aa3821a28b0b7c2400bc59aba4bcc0a76e971dadd19610d3ad38c768e124dc7","schema_version":"edge-lab-recorder.raw.v1","sequence":null,"source":"clob_market_ws"}
{"event_at":"2026-07-27T05:40:26.878000Z","event_fingerprint":"9e09a92f045faf3ab79e5e3b74a7da687377caebbb7dd2459c3f10a2bb86b9e7","payload":{"connection_id":"efc69d3132f1467b8e898a382b23ac0d","event_at":"2026-07-27T05:40:26.878000Z","event_type":"price_change","frame_hash":"15b8ba84fefd79f13a780f0c4fc2242de9cdd85812bb52468307f6ab5b0eb775","frame_index":0,"kind":"data","monotonic_ns":232811981549583,"payload":{"event_type":"price_change","market":"0x3b40066b5cf3871a2f6237c5628bd8092a206aa998558ac5ec13c4483e31e160","price_changes":[{"asset_id":"110216635572655435074987471276357323571387854733835379371586402147734167783946","best_ask":"0.43","best_bid":"0.42","hash":"250e95ec5d8b036c1fbc49525b24af832dce0384","price":"0.26","side":"BUY","size":"145"},{"asset_id":"14766054693214075530629349735273995982307625376442606753688071083149620216746","best_ask":"0.58","best_bid":"0.57","hash":"d52434fa06fcca89ab26bdd7465ba7144a1e9777","price":"0.74","side":"SELL","size":"145"}],"timestamp":"1785130826878"},"payload_hash":"a9ff3d6860f1b5386d0110d06cf396e9050e01ed7df2929a3bc543b6095cb086","raw_frame":"{\"market\":\"0x3b40066b5cf3871a2f6237c5628bd8092a206aa998558ac5ec13c4483e31e160\", \"price_changes\":[{\"asset_id\":\"110216635572655435074987471276357323571387854733835379371586402147734167783946\", \"price\":\"0.26\", \"size\":\"145\", \"side\":\"BUY\", \"hash\":\"250e95ec5d8b036c1fbc49525b24af832dce0384\", \"best_bid\":\"0.42\", \"best_ask\":\"0.43\"}, {\"asset_id\":\"14766054693214075530629349735273995982307625376442606753688071083149620216746\", \"price\":\"0.74\", \"size\":\"145\", \"side\":\"SELL\", \"hash\":\"d52434fa06fcca89ab26bdd7465ba7144a1e9777\", \"best_bid\":\"0.57\", \"best_ask\":\"0.58\"}], \"timestamp\":\"1785130826878\", \"event_type\":\"price_change\"}","received_at":"2026-07-27T05:40:28.747715Z","schema_version":"clob-market-ws.price_change.v1","sequence":null,"server_hash":null,"server_timestamp":"1785130826878","session_id":"502006c5cfcd437296561ea750c9ec8b","source":"clob_market_ws"},"received_at":"2026-07-27T05:40:28.747715Z","record_id":"a306459ecc94eeb014af350b9225b76777010f249c1692a4fd2f393a426e94b3","schema_fingerprint":"4aa3821a28b0b7c2400bc59aba4bcc0a76e971dadd19610d3ad38c768e124dc7","schema_version":"edge-lab-recorder.raw.v1","sequence":null,"source":"clob_market_ws"}
{"event_at":"2026-07-27T05:40:26.881000Z","event_fingerprint":"bafafd6305530730a91be9fd3b4c12f33c53bc483b436ea66d48ae8b935e9511","payload":{"connection_id":"efc69d3132f1467b8e898a382b23ac0d","event_at":"2026-07-27T05:40:26.881000Z","event_type":"price_change","frame_hash":"d8518ef1b08e73715316412642f8af40f3018406ce620a4348063f646edcabd9","frame_index":0,"kind":"data","monotonic_ns":232811986631375,"payload":{"event_type":"price_change","market":"0x3b40066b5cf3871a2f6237c5628bd8092a206aa998558ac5ec13c4483e31e160","price_changes":[{"asset_id":"14766054693214075530629349735273995982307625376442606753688071083149620216746","best_ask":"0.58","best_bid":"0.57","hash":"e0cc1a795849d7889465b9cc916ee265600af173","price":"0.79","side":"SELL","size":"94.1"},{"asset_id":"110216635572655435074987471276357323571387854733835379371586402147734167783946","best_ask":"0.43","best_bid":"0.42","hash":"7318fd95308c808c28cc75efebeb45dee2d40b81","price":"0.21","side":"BUY","size":"94.1"}],"timestamp":"1785130826881"},"payload_hash":"3a67360fac7c2c7669fd7c1a1e877209a09b5b2ef42c5f23ce07a549fb7c4ee0","raw_frame":"{\"market\":\"0x3b40066b5cf3871a2f6237c5628bd8092a206aa998558ac5ec13c4483e31e160\", \"price_changes\":[{\"asset_id\":\"14766054693214075530629349735273995982307625376442606753688071083149620216746\", \"price\":\"0.79\", \"size\":\"94.1\", \"side\":\"SELL\", \"hash\":\"e0cc1a795849d7889465b9cc916ee265600af173\", \"best_bid\":\"0.57\", \"best_ask\":\"0.58\"}, {\"asset_id\":\"110216635572655435074987471276357323571387854733835379371586402147734167783946\", \"price\":\"0.21\", \"size\":\"94.1\", \"side\":\"BUY\", \"hash\":\"7318fd95308c808c28cc75efebeb45dee2d40b81\", \"best_bid\":\"0.42\", \"best_ask\":\"0.43\"}], \"timestamp\":\"1785130826881\", \"event_type\":\"price_change\"}","received_at":"2026-07-27T05:40:28.752791Z","schema_version":"clob-market-ws.price_change.v1","sequence":null,"server_hash":null,"server_timestamp":"1785130826881","session_id":"502006c5cfcd437296561ea750c9ec8b","source":"clob_market_ws"},"received_at":"2026-07-27T05:40:28.752791Z","record_id":"f752e0e86d3a4591703fdefb6f128d178a32642fe35a188f8bbda491427902f0","schema_fingerprint":"4aa3821a28b0b7c2400bc59aba4bcc0a76e971dadd19610d3ad38c768e124dc7","schema_version":"edge-lab-recorder.raw.v1","sequence":null,"source":"clob_market_ws"}
{"event_at":"2026-07-27T05:40:26.880000Z","event_fingerprint":"f0e8873e8351977c4ab5bbfaef8000c95ba34834cc54c4f273bd547f4803dc2a","payload":{"connection_id":"efc69d3132f1467b8e898a382b23ac0d","event_at":"2026-07-27T05:40:26.880000Z","event_type":"last_trade_price","frame_hash":"dee8fb1fcfa1b4748f96cf0d50102c8491b8579e99625428c6751716d2859203","frame_index":0,"kind":"data","monotonic_ns":232811994851375,"payload":{"asset_id":"14766054693214075530629349735273995982307625376442606753688071083149620216746","event_type":"last_trade_price","fee_rate_bps":"0","market":"0x3b40066b5cf3871a2f6237c5628bd8092a206aa998558ac5ec13c4483e31e160","price":"0.58","side":"BUY","size":"5","timestamp":"1785130826880","transaction_hash":"0x93cd2bbea93f4d76742c863c7637500d5f8c957417a8ce48c22ae14f9563004c"},"payload_hash":"9ba9592f6b2987bc73f43a34a4b30200f482a651f36d4a58df4473c44400d19f","raw_frame":"{\"market\":\"0x3b40066b5cf3871a2f6237c5628bd8092a206aa998558ac5ec13c4483e31e160\", \"asset_id\":\"14766054693214075530629349735273995982307625376442606753688071083149620216746\", \"price\":\"0.58\", \"size\":\"5\", \"fee_rate_bps\":\"0\", \"side\":\"BUY\", \"timestamp\":\"1785130826880\", \"event_type\":\"last_trade_price\", \"transaction_hash\":\"0x93cd2bbea93f4d76742c863c7637500d5f8c957417a8ce48c22ae14f9563004c\"}","received_at":"2026-07-27T05:40:28.761012Z","schema_version":"clob-market-ws.last_trade_price.v1","sequence":null,"server_hash":null,"server_timestamp":"1785130826880","session_id":"502006c5cfcd437296561ea750c9ec8b","source":"clob_market_ws"},"received_at":"2026-07-27T05:40:28.761012Z","record_id":"e168a4c4d3beaa13e369cf814a4473320b6ae3028177937a9c472d219a38fa72","schema_fingerprint":"95ad9be75a4b695cd99991e12b2592bc7346f3f5388a82d0000ba65bc0d9fd0a","schema_version":"edge-lab-recorder.raw.v1","sequence":null,"source":"clob_market_ws"}
{"event_at":"2026-07-27T05:40:26.891000Z","event_fingerprint":"ebad69093f265e74d77f9ed34064ad98d13d3a50db17943749e8f5668cc56ab7","payload":{"connection_id":"efc69d3132f1467b8e898a382b23ac0d","event_at":"2026-07-27T05:40:26.891000Z","event_type":"price_change","frame_hash":"fda9825d28f924a6efbedfa1aea272de2f071b7ef6297702bbfcb87e57216fa9","frame_index":0,"kind":"data","monotonic_ns":232811999243875,"payload":{"event_type":"price_change","market":"0x3b40066b5cf3871a2f6237c5628bd8092a206aa998558ac5ec13c4483e31e160","price_changes":[{"asset_id":"110216635572655435074987471276357323571387854733835379371586402147734167783946","best_ask":"0.43","best_bid":"0.42","hash":"1d7242577da404b5a3ae2f5ad1e1b586dc2cc8ad","price":"0.47","side":"SELL","size":"39.42"},{"asset_id":"14766054693214075530629349735273995982307625376442606753688071083149620216746","best_ask":"0.58","best_bid":"0.57","hash":"f4eb3254455f9a4f4de7b04a33ce549a45f59fdd","price":"0.53","side":"BUY","size":"39.42"}],"timestamp":"1785130826891"},"payload_hash":"33965f8ec15a26258a44294844dfad0b439d8a242832288f419d18d48d221c36","raw_frame":"{\"market\":\"0x3b40066b5cf3871a2f6237c5628bd8092a206aa998558ac5ec13c4483e31e160\", \"price_changes\":[{\"asset_id\":\"110216635572655435074987471276357323571387854733835379371586402147734167783946\", \"price\":\"0.47\", \"size\":\"39.42\", \"side\":\"SELL\", \"hash\":\"1d7242577da404b5a3ae2f5ad1e1b586dc2cc8ad\", \"best_bid\":\"0.42\", \"best_ask\":\"0.43\"}, {\"asset_id\":\"14766054693214075530629349735273995982307625376442606753688071083149620216746\", \"price\":\"0.53\", \"size\":\"39.42\", \"side\":\"BUY\", \"hash\":\"f4eb3254455f9a4f4de7b04a33ce549a45f59fdd\", \"best_bid\":\"0.57\", \"best_ask\":\"0.58\"}], \"timestamp\":\"1785130826891\", \"event_type\":\"price_change\"}","received_at":"2026-07-27T05:40:28.765403Z","schema_version":"clob-market-ws.price_change.v1","sequence":null,"server_hash":null,"server_timestamp":"1785130826891","session_id":"502006c5cfcd437296561ea750c9ec8b","source":"clob_market_ws"},"received_at":"2026-07-27T05:40:28.765403Z","record_id":"fcdb08e9c08d654c4bdfbc2c13be73fc01fc412b45a3e00bb5282ae476c5c082","schema_fingerprint":"4aa3821a28b0b7c2400bc59aba4bcc0a76e971dadd19610d3ad38c768e124dc7","schema_version":"edge-lab-recorder.raw.v1","sequence":null,"source":"clob_market_ws"}
{"event_at":"2026-07-27T05:40:26.904000Z","event_fingerprint":"701b0d8f7bfe97ba5e3b187d32a8e52dd1c2a09ac577d0a8a26958f83dbd33ae","payload":{"connection_id":"efc69d3132f1467b8e898a382b23ac0d","event_at":"2026-07-27T05:40:26.904000Z","event_type":"price_change","frame_hash":"1fe3327f2c5da531cfd6b801d2bd07377e530935982c0a59f962aa156673d0bb","frame_index":0,"kind":"data","monotonic_ns":232812004618833,"payload":{"event_type":"price_change","market":"0x3b40066b5cf3871a2f6237c5628bd8092a206aa998558ac5ec13c4483e31e160","price_changes":[{"asset_id":"110216635572655435074987471276357323571387854733835379371586402147734167783946","best_ask":"0.43","best_bid":"0.42","hash":"3bded0fbcf2c9548167b2ca892838c9a87ec9fa1","price":"0.24","side":"BUY","size":"114.51"},{"asset_id":"14766054693214075530629349735273995982307625376442606753688071083149620216746","best_ask":"0.58","best_bid":"0.57","hash":"193925b3f4165bd7ed31dbcd88d17f09ae0c0a7c","price":"0.76","side":"SELL","size":"114.51"}],"timestamp":"1785130826904"},"payload_hash":"2a4621bf5cbce02ca1d94bf49a691c6c224f0a387700986cd14744e734c6cac5","raw_frame":"{\"market\":\"0x3b40066b5cf3871a2f6237c5628bd8092a206aa998558ac5ec13c4483e31e160\", \"price_changes\":[{\"asset_id\":\"110216635572655435074987471276357323571387854733835379371586402147734167783946\", \"price\":\"0.24\", \"size\":\"114.51\", \"side\":\"BUY\", \"hash\":\"3bded0fbcf2c9548167b2ca892838c9a87ec9fa1\", \"best_bid\":\"0.42\", \"best_ask\":\"0.43\"}, {\"asset_id\":\"14766054693214075530629349735273995982307625376442606753688071083149620216746\", \"price\":\"0.76\", \"size\":\"114.51\", \"side\":\"SELL\", \"hash\":\"193925b3f4165bd7ed31dbcd88d17f09ae0c0a7c\", \"best_bid\":\"0.57\", \"best_ask\":\"0.58\"}], \"timestamp\":\"1785130826904\", \"event_type\":\"price_change\"}","received_at":"2026-07-27T05:40:28.770776Z","schema_version":"clob-market-ws.price_change.v1","sequence":null,"server_hash":null,"server_timestamp":"1785130826904","session_id":"502006c5cfcd437296561ea750c9ec8b","source":"clob_market_ws"},"received_at":"2026-07-27T05:40:28.770776Z","record_id":"ff32f7f2ef18429b504b261d959765ab6e6f6fa3fba1299a99771af467ba419c","schema_fingerprint":"4aa3821a28b0b7c2400bc59aba4bcc0a76e971dadd19610d3ad38c768e124dc7","schema_version":"edge-lab-recorder.raw.v1","sequence":null,"source":"clob_market_ws"}
{"event_at":"2026-07-27T05:40:26.910000Z","event_fingerprint":"c0ca32278504b7828409c9a308ad259aac3e71df90528099a52878657d3639bf","payload":{"connection_id":"efc69d3132f1467b8e898a382b23ac0d","event_at":"2026-07-27T05:40:26.910000Z","event_type":"price_change","frame_hash":"52210b80d7140e505f7688c3357f5756ddf30c6b71de2374abdc3b430541e8e2","frame_index":0,"kind":"data","monotonic_ns":232812013850583,"payload":{"event_type":"price_change","market":"0x3b40066b5cf3871a2f6237c5628bd8092a206aa998558ac5ec13c4483e31e160","price_changes":[{"asset_id":"14766054693214075530629349735273995982307625376442606753688071083149620216746","best_ask":"0.58","best_bid":"0.57","hash":"0c582918c8e707d335e65856419c0383d0dce502","price":"0.03","side":"BUY","size":"635.1"},{"asset_id":"110216635572655435074987471276357323571387854733835379371586402147734167783946","best_ask":"0.43","best_bid":"0.42","hash":"b10c2048cad0fdd2c38c74af224e6841bf3c53b7","price":"0.97","side":"SELL","size":"635.1"}],"timestamp":"1785130826910"},"payload_hash":"cafe0646417615bc7bba835058e6daa23188ac8773088fde1414fa174af0454a","raw_frame":"{\"market\":\"0x3b40066b5cf3871a2f6237c5628bd8092a206aa998558ac5ec13c4483e31e160\", \"price_changes\":[{\"asset_id\":\"14766054693214075530629349735273995982307625376442606753688071083149620216746\", \"price\":\"0.03\", \"size\":\"635.1\", \"side\":\"BUY\", \"hash\":\"0c582918c8e707d335e65856419c0383d0dce502\", \"best_bid\":\"0.57\", \"best_ask\":\"0.58\"}, {\"asset_id\":\"110216635572655435074987471276357323571387854733835379371586402147734167783946\", \"price\":\"0.97\", \"size\":\"635.1\", \"side\":\"SELL\", \"hash\":\"b10c2048cad0fdd2c38c74af224e6841bf3c53b7\", \"best_bid\":\"0.42\", \"best_ask\":\"0.43\"}], \"timestamp\":\"1785130826910\", \"event_type\":\"price_change\"}","received_at":"2026-07-27T05:40:28.780009Z","schema_version":"clob-market-ws.price_change.v1","sequence":null,"server_hash":null,"server_timestamp":"1785130826910","session_id":"502006c5cfcd437296561ea750c9ec8b","source":"clob_market_ws"},"received_at":"2026-07-27T05:40:28.780009Z","record_id":"034bb6bd0a760a6235770efd9b93416a7f9f491ffff57dbee61e4ddf5b9bd760","schema_fingerprint":"4aa3821a28b0b7c2400bc59aba4bcc0a76e971dadd19610d3ad38c768e124dc7","schema_version":"edge-lab-recorder.raw.v1","sequence":null,"source":"clob_market_ws"}
{"event_at":"2026-07-27T05:40:26.935000Z","event_fingerprint":"45604caa97cac0c994f6b2b01f6a27a3110734da4837f7c18045ec2b7f74b0b3","payload":{"connection_id":"efc69d3132f1467b8e898a382b23ac0d","event_at":"2026-07-27T05:40:26.935000Z","event_type":"best_bid_ask","frame_hash":"faff9414463b0bd24ea7e9ab577dd23ac7367b116b355fe35325292d22b9151d","frame_index":0,"kind":"data","monotonic_ns":232812018485625,"payload":{"asset_id":"14766054693214075530629349735273995982307625376442606753688071083149620216746","best_ask":"0.58","best_bid":"0.57","event_type":"best_bid_ask","market":"0x3b40066b5cf3871a2f6237c5628bd8092a206aa998558ac5ec13c4483e31e160","spread":"0.01","timestamp":"1785130826935"},"payload_hash":"e6b0e0ab9c652531bb8a1bf9676ae0e5e0d453b8a789b9008a80aad33e6a9d46","raw_frame":"{\"market\":\"0x3b40066b5cf3871a2f6237c5628bd8092a206aa998558ac5ec13c4483e31e160\", \"asset_id\":\"14766054693214075530629349735273995982307625376442606753688071083149620216746\", \"best_bid\":\"0.57\", \"best_ask\":\"0.58\", \"spread\":\"0.01\", \"timestamp\":\"1785130826935\", \"event_type\":\"best_bid_ask\"}","received_at":"2026-07-27T05:40:28.784645Z","schema_version":"clob-market-ws.best_bid_ask.v1","sequence":null,"server_hash":null,"server_timestamp":"1785130826935","session_id":"502006c5cfcd437296561ea750c9ec8b","source":"clob_market_ws"},"received_at":"2026-07-27T05:40:28.784645Z","record_id":"49dac5634680ef7c7b7e57eac19703aebcc42c8adbe8d81ec3417aff18ce704d","schema_fingerprint":"8488399f31b0337811b13b266be932db7062827c2470b78bd8e9e99bab51d17d","schema_version":"edge-lab-recorder.raw.v1","sequence":null,"source":"clob_market_ws"}
{"event_at":"2026-07-27T05:40:26.935000Z","event_fingerprint":"b0c3676b57c4c7c241d5d74597bbe80b6485b54652a87b34fc158168e45e9dbc","payload":{"connection_id":"efc69d3132f1467b8e898a382b23ac0d","event_at":"2026-07-27T05:40:26.935000Z","event_type":"best_bid_ask","frame_hash":"7bd62e8603466acefac378973bb4adae54e257e535cd191e62a3c31c77dbaeaf","frame_index":0,"kind":"data","monotonic_ns":232812026262041,"payload":{"asset_id":"110216635572655435074987471276357323571387854733835379371586402147734167783946","best_ask":"0.43","best_bid":"0.42","event_type":"best_bid_ask","market":"0x3b40066b5cf3871a2f6237c5628bd8092a206aa998558ac5ec13c4483e31e160","spread":"0.01","timestamp":"1785130826935"},"payload_hash":"db11bc52a6bbfcbc1d89b1477b0287ad189c9a26c3056c17c1d9d305b17cf58f","raw_frame":"{\"market\":\"0x3b40066b5cf3871a2f6237c5628bd8092a206aa998558ac5ec13c4483e31e160\", \"asset_id\":\"110216635572655435074987471276357323571387854733835379371586402147734167783946\", \"best_bid\":\"0.42\", \"best_ask\":\"0.43\", \"spread\":\"0.01\", \"timestamp\":\"1785130826935\", \"event_type\":\"best_bid_ask\"}","received_at":"2026-07-27T05:40:28.792423Z","schema_version":"clob-market-ws.best_bid_ask.v1","sequence":null,"server_hash":null,"server_timestamp":"1785130826935","session_id":"502006c5cfcd437296561ea750c9ec8b","source":"clob_market_ws"},"received_at":"2026-07-27T05:40:28.792423Z","record_id":"877788e6484af82f39e7f3ef1f3f567f247dd105e23fca9e7d5f91326ba20a82","schema_fingerprint":"8488399f31b0337811b13b266be932db7062827c2470b78bd8e9e99bab51d17d","schema_version":"edge-lab-recorder.raw.v1","sequence":null,"source":"clob_market_ws"}
{"event_at":"2026-07-27T05:40:26.935000Z","event_fingerprint":"136540a0d23e78bab437c1bfffd46333b1635c28650aa6c0e951f7198656066e","payload":{"connection_id":"efc69d3132f1467b8e898a382b23ac0d","event_at":"2026-07-27T05:40:26.935000Z","event_type":"price_change","frame_hash":"9f7132535a5c1315eff8b7cbf0ea59686a9c05b5ee6e9b5fc63854a79cc7a60e","frame_index":0,"kind":"data","monotonic_ns":232812034594833,"payload":{"event_type":"price_change","market":"0x3b40066b5cf3871a2f6237c5628bd8092a206aa998558ac5ec13c4483e31e160","price_changes":[{"asset_id":"14766054693214075530629349735273995982307625376442606753688071083149620216746","best_ask":"0.58","best_bid":"0.57","hash":"110034f7fb97e81cbad42df0663c59aae5e89b49","price":"0.57","side":"BUY","size":"0.38"},{"asset_id":"110216635572655435074987471276357323571387854733835379371586402147734167783946","best_ask":"0.43","best_bid":"0.42","hash":"d610b6592c8f97ebca162995e1be8640fd5118c7","price":"0.43","side":"SELL","size":"0.38"}],"timestamp":"1785130826935"},"payload_hash":"846ca56066bb714260c11302a1458039b0e454df836c5d5a94d1a329e9f6be0c","raw_frame":"{\"market\":\"0x3b40066b5cf3871a2f6237c5628bd8092a206aa998558ac5ec13c4483e31e160\", \"price_changes\":[{\"asset_id\":\"14766054693214075530629349735273995982307625376442606753688071083149620216746\", \"price\":\"0.57\", \"size\":\"0.38\", \"side\":\"BUY\", \"hash\":\"110034f7fb97e81cbad42df0663c59aae5e89b49\", \"best_bid\":\"0.57\", \"best_ask\":\"0.58\"}, {\"asset_id\":\"110216635572655435074987471276357323571387854733835379371586402147734167783946\", \"price\":\"0.43\", \"size\":\"0.38\", \"side\":\"SELL\", \"hash\":\"d610b6592c8f97ebca162995e1be8640fd5118c7\", \"best_bid\":\"0.42\", \"best_ask\":\"0.43\"}], \"timestamp\":\"1785130826935\", \"event_type\":\"price_change\"}","received_at":"2026-07-27T05:40:28.800755Z","schema_version":"clob-market-ws.price_change.v1","sequence":null,"server_hash":null,"server_timestamp":"1785130826935","session_id":"502006c5cfcd437296561ea750c9ec8b","source":"clob_market_ws"},"received_at":"2026-07-27T05:40:28.800755Z","record_id":"e61f4707e23440d98a11892e66950322383bb87ffb7bf2858955a5020cff35d6","schema_fingerprint":"4aa3821a28b0b7c2400bc59aba4bcc0a76e971dadd19610d3ad38c768e124dc7","schema_version":"edge-lab-recorder.raw.v1","sequence":null,"source":"clob_market_ws"}
{"event_at":"2026-07-27T05:40:26.935000Z","event_fingerprint":"813f5d8cac6c4f6d3447e25fa200eb1f71222aa2df66086bb095eff19e0adc21","payload":{"connection_id":"efc69d3132f1467b8e898a382b23ac0d","event_at":"2026-07-27T05:40:26.935000Z","event_type":"book","frame_hash":"6aa3e8ddc93ad2fb6738a146994cf77706fa8894be709a009f7fcf4dfef1cd1f","frame_index":0,"kind":"data","monotonic_ns":232812040047750,"payload":{"asks":[{"price":"0.99","size":"5645.45"},{"price":"0.98","size":"806.1"},{"price":"0.97","size":"676.1"},{"price":"0.96","size":"611.09"},{"price":"0.95","size":"655.68"},{"price":"0.94","size":"638.2"},{"price":"0.93","size":"105.24"},{"price":"0.92","size":"90.79"},{"price":"0.91","size":"114.6"},{"price":"0.9","size":"85.29"},{"price":"0.89","size":"76.6"},{"price":"0.88","size":"103.4"},{"price":"0.87","size":"81.5"},{"price":"0.86","size":"365.9"},{"price":"0.85","size":"96.5"},{"price":"0.84","size":"64.3"},{"price":"0.83","size":"63.3"},{"price":"0.82","size":"91.3"},{"price":"0.81","size":"82.5"},{"price":"0.8","size":"81.8"},{"price":"0.79","size":"94.1"},{"price":"0.78","size":"80.5"},{"price":"0.77","size":"368.71"},{"price":"0.76","size":"114.51"},{"price":"0.75","size":"94"},{"price":"0.74","size":"145"},{"price":"0.73","size":"94"},{"price":"0.72","size":"59.97"},{"price":"0.71","size":"67.04"},{"price":"0.7","size":"91.98"},{"price":"0.69","size":"153.95"},{"price":"0.68","size":"79"},{"price":"0.67","size":"90"},{"price":"0.66","size":"126.79"},{"price":"0.65","size":"54"},{"price":"0.64","size":"101.94"},{"price":"0.63","size":"65.85"},{"price":"0.62","size":"65.68"},{"price":"0.61","size":"104.21"},{"price":"0.6","size":"64.3"},{"price":"0.59","size":"64.4"},{"price":"0.58","size":"184.6"}],"asset_id":"14766054693214075530629349735273995982307625376442606753688071083149620216746","bids":[{"price":"0.01","size":"5633.02"},{"price":"0.02","size":"705.1"},{"price":"0.03","size":"635.1"},{"price":"0.04","size":"641.09"},{"price":"0.05","size":"741.2"},{"price":"0.06","size":"586.2"},{"price":"0.07","size":"616.24"},{"price":"0.08","size":"573.79"},{"price":"0.09","size":"569.6"},{"price":"0.1","size":"266.29"},{"price":"0.11","size":"63.6"},{"price":"0.12","size":"61.4"},{"price":"0.13","size":"89.5"},{"price":"0.14","size":"57.9"},{"price":"0.15","size":"103.5"},{"price":"0.16","size":"85.3"},{"price":"0.17","size":"54.3"},{"price":"0.18","size":"53.3"},{"price":"0.19","size":"95.76"},{"price":"0.2","size":"94.8"},{"price":"0.21","size":"130.52"},{"price":"0.22","size":"87.5"},{"price":"0.23","size":"56.89"},{"price":"0.24","size":"56.39"},{"price":"0.25","size":"114"},{"price":"0.26","size":"54.6"},{"price":"0.27","size":"54.2"},{"price":"0.28","size":"83.9"},{"price":"0.29","size":"53.6"},{"price":"0.3","size":"77.3"},{"price":"0.31","size":"83"},{"price":"0.32","size":"261.12"},{"price":"0.33","size":"46.6"},{"price":"0.34","size":"82.4"},{"price":"0.35","size":"67.5"},{"price":"0.36","size":"51"},{"price":"0.37","size":"80.9"},{"price":"0.38","size":"50.7"},{"price":"0.39","size":"50.6"},{"price":"0.4","size":"103.5"},{"price":"0.41","size":"50.4"},{"price":"0.42","size":"50.3"},{"price":"0.43","size":"80.2"},{"price":"0.44","size":"38"},{"price":"0.45","size":"54"},{"price":"0.46","size":"68"},{"price":"0.47","size":"308"},{"price":"0.48","size":"15"},{"price":"0.49","size":"23"},{"price":"0.5","size":"14"},{"price":"0.51","size":"13"},{"price":"0.52","size":"5"},{"price":"0.53","size":"39.42"},{"price":"0.57","size":"0.38"}],"event_type":"book","hash":"110034f7fb97e81cbad42df0663c59aae5e89b49","market":"0x3b40066b5cf3871a2f6237c5628bd8092a206aa998558ac5ec13c4483e31e160","timestamp":"1785130826935"},"payload_hash":"a79693eab3f80d462a8a56b27a9641ab369acc95d4af64bd0ff79b59b64e984a","raw_frame":"{\"market\":\"0x3b40066b5cf3871a2f6237c5628bd8092a206aa998558ac5ec13c4483e31e160\", \"asset_id\":\"14766054693214075530629349735273995982307625376442606753688071083149620216746\", \"bids\":[{\"price\":\"0.01\", \"size\":\"5633.02\"}, {\"price\":\"0.02\", \"size\":\"705.1\"}, {\"price\":\"0.03\", \"size\":\"635.1\"}, {\"price\":\"0.04\", \"size\":\"641.09\"}, {\"price\":\"0.05\", \"size\":\"741.2\"}, {\"price\":\"0.06\", \"size\":\"586.2\"}, {\"price\":\"0.07\", \"size\":\"616.24\"}, {\"price\":\"0.08\", \"size\":\"573.79\"}, {\"price\":\"0.09\", \"size\":\"569.6\"}, {\"price\":\"0.1\", \"size\":\"266.29\"}, {\"price\":\"0.11\", \"size\":\"63.6\"}, {\"price\":\"0.12\", \"size\":\"61.4\"}, {\"price\":\"0.13\", \"size\":\"89.5\"}, {\"price\":\"0.14\", \"size\":\"57.9\"}, {\"price\":\"0.15\", \"size\":\"103.5\"}, {\"price\":\"0.16\", \"size\":\"85.3\"}, {\"price\":\"0.17\", \"size\":\"54.3\"}, {\"price\":\"0.18\", \"size\":\"53.3\"}, {\"price\":\"0.19\", \"size\":\"95.76\"}, {\"price\":\"0.2\", \"size\":\"94.8\"}, {\"price\":\"0.21\", \"size\":\"130.52\"}, {\"price\":\"0.22\", \"size\":\"87.5\"}, {\"price\":\"0.23\", \"size\":\"56.89\"}, {\"price\":\"0.24\", \"size\":\"56.39\"}, {\"price\":\"0.25\", \"size\":\"114\"}, {\"price\":\"0.26\", \"size\":\"54.6\"}, {\"price\":\"0.27\", \"size\":\"54.2\"}, {\"price\":\"0.28\", \"size\":\"83.9\"}, {\"price\":\"0.29\", \"size\":\"53.6\"}, {\"price\":\"0.3\", \"size\":\"77.3\"}, {\"price\":\"0.31\", \"size\":\"83\"}, {\"price\":\"0.32\", \"size\":\"261.12\"}, {\"price\":\"0.33\", \"size\":\"46.6\"}, {\"price\":\"0.34\", \"size\":\"82.4\"}, {\"price\":\"0.35\", \"size\":\"67.5\"}, {\"price\":\"0.36\", \"size\":\"51\"}, {\"price\":\"0.37\", \"size\":\"80.9\"}, {\"price\":\"0.38\", \"size\":\"50.7\"}, {\"price\":\"0.39\", \"size\":\"50.6\"}, {\"price\":\"0.4\", \"size\":\"103.5\"}, {\"price\":\"0.41\", \"size\":\"50.4\"}, {\"price\":\"0.42\", \"size\":\"50.3\"}, {\"price\":\"0.43\", \"size\":\"80.2\"}, {\"price\":\"0.44\", \"size\":\"38\"}, {\"price\":\"0.45\", \"size\":\"54\"}, {\"price\":\"0.46\", \"size\":\"68\"}, {\"price\":\"0.47\", \"size\":\"308\"}, {\"price\":\"0.48\", \"size\":\"15\"}, {\"price\":\"0.49\", \"size\":\"23\"}, {\"price\":\"0.5\", \"size\":\"14\"}, {\"price\":\"0.51\", \"size\":\"13\"}, {\"price\":\"0.52\", \"size\":\"5\"}, {\"price\":\"0.53\", \"size\":\"39.42\"}, {\"price\":\"0.57\", \"size\":\"0.38\"}], \"asks\":[{\"price\":\"0.99\", \"size\":\"5645.45\"}, {\"price\":\"0.98\", \"size\":\"806.1\"}, {\"price\":\"0.97\", \"size\":\"676.1\"}, {\"price\":\"0.96\", \"size\":\"611.09\"}, {\"price\":\"0.95\", \"size\":\"655.68\"}, {\"price\":\"0.94\", \"size\":\"638.2\"}, {\"price\":\"0.93\", \"size\":\"105.24\"}, {\"price\":\"0.92\", \"size\":\"90.79\"}, {\"price\":\"0.91\", \"size\":\"114.6\"}, {\"price\":\"0.9\", \"size\":\"85.29\"}, {\"price\":\"0.89\", \"size\":\"76.6\"}, {\"price\":\"0.88\", \"size\":\"103.4\"}, {\"price\":\"0.87\", \"size\":\"81.5\"}, {\"price\":\"0.86\", \"size\":\"365.9\"}, {\"price\":\"0.85\", \"size\":\"96.5\"}, {\"price\":\"0.84\", \"size\":\"64.3\"}, {\"price\":\"0.83\", \"size\":\"63.3\"}, {\"price\":\"0.82\", \"size\":\"91.3\"}, {\"price\":\"0.81\", \"size\":\"82.5\"}, {\"price\":\"0.8\", \"size\":\"81.8\"}, {\"price\":\"0.79\", \"size\":\"94.1\"}, {\"price\":\"0.78\", \"size\":\"80.5\"}, {\"price\":\"0.77\", \"size\":\"368.71\"}, {\"price\":\"0.76\", \"size\":\"114.51\"}, {\"price\":\"0.75\", \"size\":\"94\"}, {\"price\":\"0.74\", \"size\":\"145\"}, {\"price\":\"0.73\", \"size\":\"94\"}, {\"price\":\"0.72\", \"size\":\"59.97\"}, {\"price\":\"0.71\", \"size\":\"67.04\"}, {\"price\":\"0.7\", \"size\":\"91.98\"}, {\"price\":\"0.69\", \"size\":\"153.95\"}, {\"price\":\"0.68\", \"size\":\"79\"}, {\"price\":\"0.67\", \"size\":\"90\"}, {\"price\":\"0.66\", \"size\":\"126.79\"}, {\"price\":\"0.65\", \"size\":\"54\"}, {\"price\":\"0.64\", \"size\":\"101.94\"}, {\"price\":\"0.63\", \"size\":\"65.85\"}, {\"price\":\"0.62\", \"size\":\"65.68\"}, {\"price\":\"0.61\", \"size\":\"104.21\"}, {\"price\":\"0.6\", \"size\":\"64.3\"}, {\"price\":\"0.59\", \"size\":\"64.4\"}, {\"price\":\"0.58\", \"size\":\"184.6\"}], \"hash\":\"110034f7fb97e81cbad42df0663c59aae5e89b49\", \"timestamp\":\"1785130826935\", \"event_type\":\"book\"}","received_at":"2026-07-27T05:40:28.806208Z","schema_version":"clob-market-ws.book.v1","sequence":null,"server_hash":"110034f7fb97e81cbad42df0663c59aae5e89b49","server_timestamp":"1785130826935","session_id":"502006c5cfcd437296561ea750c9ec8b","source":"clob_market_ws"},"received_at":"2026-07-27T05:40:28.806208Z","record_id":"882fb631f86846f58753ee4dcb8b19b088c5f03ddc17399f95872f20cab42b64","schema_fingerprint":"dc2caa1c89c6a7426e2e07ff925910cd4d0a8a223a515d4092d91d6d127aacb6","schema_version":"edge-lab-recorder.raw.v1","sequence":null,"source":"clob_market_ws"}
{"event_at":"2026-07-27T05:40:26.935000Z","event_fingerprint":"0edee7bf68d7c8f650f73371ff99982446933d977d8683af7592cd8c6cdcf920","payload":{"connection_id":"efc69d3132f1467b8e898a382b23ac0d","event_at":"2026-07-27T05:40:26.935000Z","event_type":"book","frame_hash":"d5b64be01f578873363ca572cc1342ce51d8eb0d93f6385a8dac66a9a74233b1","frame_index":0,"kind":"data","monotonic_ns":232812052750833,"payload":{"asks":[{"price":"0.99","size":"5633.02"},{"price":"0.98","size":"705.1"},{"price":"0.97","size":"635.1"},{"price":"0.96","size":"641.09"},{"price":"0.95","size":"741.2"},{"price":"0.94","size":"586.2"},{"price":"0.93","size":"616.24"},{"price":"0.92","size":"573.79"},{"price":"0.91","size":"569.6"},{"price":"0.9","size":"266.29"},{"price":"0.89","size":"63.6"},{"price":"0.88","size":"61.4"},{"price":"0.87","size":"89.5"},{"price":"0.86","size":"57.9"},{"price":"0.85","size":"103.5"},{"price":"0.84","size":"85.3"},{"price":"0.83","size":"54.3"},{"price":"0.82","size":"53.3"},{"price":"0.81","size":"95.76"},{"price":"0.8","size":"94.8"},{"price":"0.79","size":"130.52"},{"price":"0.78","size":"87.5"},{"price":"0.77","size":"56.89"},{"price":"0.76","size":"56.39"},{"price":"0.75","size":"114"},{"price":"0.74","size":"54.6"},{"price":"0.73","size":"54.2"},{"price":"0.72","size":"83.9"},{"price":"0.71","size":"53.6"},{"price":"0.7","size":"77.3"},{"price":"0.69","size":"83"},{"price":"0.68","size":"261.12"},{"price":"0.67","size":"46.6"},{"price":"0.66","size":"82.4"},{"price":"0.65","size":"67.5"},{"price":"0.64","size":"51"},{"price":"0.63","size":"80.9"},{"price":"0.62","size":"50.7"},{"price":"0.61","size":"50.6"},{"price":"0.6","size":"103.5"},{"price":"0.59","size":"50.4"},{"price":"0.58","size":"50.3"},{"price":"0.57","size":"80.2"},{"price":"0.56","size":"38"},{"price":"0.55","size":"54"},{"price":"0.54","size":"68"},{"price":"0.53","size":"308"},{"price":"0.52","size":"15"},{"price":"0.51","size":"23"},{"price":"0.5","size":"14"},{"price":"0.49","size":"13"},{"price":"0.48","size":"5"},{"price":"0.47","size":"39.42"},{"price":"0.43","size":"0.38"}],"asset_id":"110216635572655435074987471276357323571387854733835379371586402147734167783946","bids":[{"price":"0.01","size":"5645.45"},{"price":"0.02","size":"806.1"},{"price":"0.03","size":"676.1"},{"price":"0.04","size":"611.09"},{"price":"0.05","size":"655.68"},{"price":"0.06","size":"638.2"},{"price":"0.07","size":"105.24"},{"price":"0.08","size":"90.79"},{"price":"0.09","size":"114.6"},{"price":"0.1","size":"85.29"},{"price":"0.11","size":"76.6"},{"price":"0.12","size":"103.4"},{"price":"0.13","size":"81.5"},{"price":"0.14","size":"365.9"},{"price":"0.15","size":"96.5"},{"price":"0.16","size":"64.3"},{"price":"0.17","size":"63.3"},{"price":"0.18","size":"91.3"},{"price":"0.19","size":"82.5"},{"price":"0.2","size":"81.8"},{"price":"0.21","size":"94.1"},{"price":"0.22","size":"80.5"},{"price":"0.23","size":"368.71"},{"price":"0.24","size":"114.51"},{"price":"0.25","size":"94"},{"price":"0.26","size":"145"},{"price":"0.27","size":"94"},{"price":"0.28","size":"59.97"},{"price":"0.29","size":"67.04"},{"price":"0.3","size":"91.98"},{"price":"0.31","size":"153.95"},{"price":"0.32","size":"79"},{"price":"0.33","size":"90"},{"price":"0.34","size":"126.79"},{"price":"0.35","size":"54"},{"price":"0.36","size":"101.94"},{"price":"0.37","size":"65.85"},{"price":"0.38","size":"65.68"},{"price":"0.39","size":"104.21"},{"price":"0.4","size":"64.3"},{"price":"0.41","size":"64.4"},{"price":"0.42","size":"184.6"}],"event_type":"book","hash":"d610b6592c8f97ebca162995e1be8640fd5118c7","market":"0x3b40066b5cf3871a2f6237c5628bd8092a206aa998558ac5ec13c4483e31e160","timestamp":"1785130826935"},"payload_hash":"3430deecbd60e268894537f4a89e8539a9e2375279fe7d85ab2fbc6d4f4304e4","raw_frame":"{\"market\":\"0x3b40066b5cf3871a2f6237c5628bd8092a206aa998558ac5ec13c4483e31e160\", \"asset_id\":\"110216635572655435074987471276357323571387854733835379371586402147734167783946\", \"bids\":[{\"price\":\"0.01\", \"size\":\"5645.45\"}, {\"price\":\"0.02\", \"size\":\"806.1\"}, {\"price\":\"0.03\", \"size\":\"676.1\"}, {\"price\":\"0.04\", \"size\":\"611.09\"}, {\"price\":\"0.05\", \"size\":\"655.68\"}, {\"price\":\"0.06\", \"size\":\"638.2\"}, {\"price\":\"0.07\", \"size\":\"105.24\"}, {\"price\":\"0.08\", \"size\":\"90.79\"}, {\"price\":\"0.09\", \"size\":\"114.6\"}, {\"price\":\"0.1\", \"size\":\"85.29\"}, {\"price\":\"0.11\", \"size\":\"76.6\"}, {\"price\":\"0.12\", \"size\":\"103.4\"}, {\"price\":\"0.13\", \"size\":\"81.5\"}, {\"price\":\"0.14\", \"size\":\"365.9\"}, {\"price\":\"0.15\", \"size\":\"96.5\"}, {\"price\":\"0.16\", \"size\":\"64.3\"}, {\"price\":\"0.17\", \"size\":\"63.3\"}, {\"price\":\"0.18\", \"size\":\"91.3\"}, {\"price\":\"0.19\", \"size\":\"82.5\"}, {\"price\":\"0.2\", \"size\":\"81.8\"}, {\"price\":\"0.21\", \"size\":\"94.1\"}, {\"price\":\"0.22\", \"size\":\"80.5\"}, {\"price\":\"0.23\", \"size\":\"368.71\"}, {\"price\":\"0.24\", \"size\":\"114.51\"}, {\"price\":\"0.25\", \"size\":\"94\"}, {\"price\":\"0.26\", \"size\":\"145\"}, {\"price\":\"0.27\", \"size\":\"94\"}, {\"price\":\"0.28\", \"size\":\"59.97\"}, {\"price\":\"0.29\", \"size\":\"67.04\"}, {\"price\":\"0.3\", \"size\":\"91.98\"}, {\"price\":\"0.31\", \"size\":\"153.95\"}, {\"price\":\"0.32\", \"size\":\"79\"}, {\"price\":\"0.33\", \"size\":\"90\"}, {\"price\":\"0.34\", \"size\":\"126.79\"}, {\"price\":\"0.35\", \"size\":\"54\"}, {\"price\":\"0.36\", \"size\":\"101.94\"}, {\"price\":\"0.37\", \"size\":\"65.85\"}, {\"price\":\"0.38\", \"size\":\"65.68\"}, {\"price\":\"0.39\", \"size\":\"104.21\"}, {\"price\":\"0.4\", \"size\":\"64.3\"}, {\"price\":\"0.41\", \"size\":\"64.4\"}, {\"price\":\"0.42\", \"size\":\"184.6\"}], \"asks\":[{\"price\":\"0.99\", \"size\":\"5633.02\"}, {\"price\":\"0.98\", \"size\":\"705.1\"}, {\"price\":\"0.97\", \"size\":\"635.1\"}, {\"price\":\"0.96\", \"size\":\"641.09\"}, {\"price\":\"0.95\", \"size\":\"741.2\"}, {\"price\":\"0.94\", \"size\":\"586.2\"}, {\"price\":\"0.93\", \"size\":\"616.24\"}, {\"price\":\"0.92\", \"size\":\"573.79\"}, {\"price\":\"0.91\", \"size\":\"569.6\"}, {\"price\":\"0.9\", \"size\":\"266.29\"}, {\"price\":\"0.89\", \"size\":\"63.6\"}, {\"price\":\"0.88\", \"size\":\"61.4\"}, {\"price\":\"0.87\", \"size\":\"89.5\"}, {\"price\":\"0.86\", \"size\":\"57.9\"}, {\"price\":\"0.85\", \"size\":\"103.5\"}, {\"price\":\"0.84\", \"size\":\"85.3\"}, {\"price\":\"0.83\", \"size\":\"54.3\"}, {\"price\":\"0.82\", \"size\":\"53.3\"}, {\"price\":\"0.81\", \"size\":\"95.76\"}, {\"price\":\"0.8\", \"size\":\"94.8\"}, {\"price\":\"0.79\", \"size\":\"130.52\"}, {\"price\":\"0.78\", \"size\":\"87.5\"}, {\"price\":\"0.77\", \"size\":\"56.89\"}, {\"price\":\"0.76\", \"size\":\"56.39\"}, {\"price\":\"0.75\", \"size\":\"114\"}, {\"price\":\"0.74\", \"size\":\"54.6\"}, {\"price\":\"0.73\", \"size\":\"54.2\"}, {\"price\":\"0.72\", \"size\":\"83.9\"}, {\"price\":\"0.71\", \"size\":\"53.6\"}, {\"price\":\"0.7\", \"size\":\"77.3\"}, {\"price\":\"0.69\", \"size\":\"83\"}, {\"price\":\"0.68\", \"size\":\"261.12\"}, {\"price\":\"0.67\", \"size\":\"46.6\"}, {\"price\":\"0.66\", \"size\":\"82.4\"}, {\"price\":\"0.65\", \"size\":\"67.5\"}, {\"price\":\"0.64\", \"size\":\"51\"}, {\"price\":\"0.63\", \"size\":\"80.9\"}, {\"price\":\"0.62\", \"size\":\"50.7\"}, {\"price\":\"0.61\", \"size\":\"50.6\"}, {\"price\":\"0.6\", \"size\":\"103.5\"}, {\"price\":\"0.59\", \"size\":\"50.4\"}, {\"price\":\"0.58\", \"size\":\"50.3\"}, {\"price\":\"0.57\", \"size\":\"80.2\"}, {\"price\":\"0.56\", \"size\":\"38\"}, {\"price\":\"0.55\", \"size\":\"54\"}, {\"price\":\"0.54\", \"size\":\"68\"}, {\"price\":\"0.53\", \"size\":\"308\"}, {\"price\":\"0.52\", \"size\":\"15\"}, {\"price\":\"0.51\", \"size\":\"23\"}, {\"price\":\"0.5\", \"size\":\"14\"}, {\"price\":\"0.49\", \"size\":\"13\"}, {\"price\":\"0.48\", \"size\":\"5\"}, {\"price\":\"0.47\", \"size\":\"39.42\"}, {\"price\":\"0.43\", \"size\":\"0.38\"}], \"hash\":\"d610b6592c8f97ebca162995e1be8640fd5118c7\", \"timestamp\":\"1785130826935\", \"event_type\":\"book\"}","received_at":"2026-07-27T05:40:28.818911Z","schema_version":"clob-market-ws.book.v1","sequence":null,"server_hash":"d610b6592c8f97ebca162995e1be8640fd5118c7","server_timestamp":"1785130826935","session_id":"502006c5cfcd437296561ea750c9ec8b","source":"clob_market_ws"},"received_at":"2026-07-27T05:40:28.818911Z","record_id":"cbdf3134c3e7923be15091004ba0b0a8fb9444f596a45b07b22884849cefa9c2","schema_fingerprint":"dc2caa1c89c6a7426e2e07ff925910cd4d0a8a223a515d4092d91d6d127aacb6","schema_version":"edge-lab-recorder.raw.v1","sequence":null,"source":"clob_market_ws"}
{"event_at":"2026-07-27T05:40:26.952000Z","event_fingerprint":"8ae9b52c3dae0bbf4b95f3c9a8a4289b41e5b36bdae8066484d3e1b2ba1c1079","payload":{"connection_id":"efc69d3132f1467b8e898a382b23ac0d","event_at":"2026-07-27T05:40:26.952000Z","event_type":"best_bid_ask","frame_hash":"1d750bfcf6a1088bbaed134d01f47ff6e3577f150e5783f2cc7e6acd9774487a","frame_index":0,"kind":"data","monotonic_ns":232812072687291,"payload":{"asset_id":"14766054693214075530629349735273995982307625376442606753688071083149620216746","best_ask":"0.58","best_bid":"0.53","event_type":"best_bid_ask","market":"0x3b40066b5cf3871a2f6237c5628bd8092a206aa998558ac5ec13c4483e31e160","spread":"0.05","timestamp":"1785130826952"},"payload_hash":"8d9d382defbaeb421ed89d9fe7e6f86a41df950ed9599b1503a9b2aa5565cc8a","raw_frame":"{\"market\":\"0x3b40066b5cf3871a2f6237c5628bd8092a206aa998558ac5ec13c4483e31e160\", \"asset_id\":\"14766054693214075530629349735273995982307625376442606753688071083149620216746\", \"best_bid\":\"0.53\", \"best_ask\":\"0.58\", \"spread\":\"0.05\", \"timestamp\":\"1785130826952\", \"event_type\":\"best_bid_ask\"}","received_at":"2026-07-27T05:40:28.838848Z","schema_version":"clob-market-ws.best_bid_ask.v1","sequence":null,"server_hash":null,"server_timestamp":"1785130826952","session_id":"502006c5cfcd437296561ea750c9ec8b","source":"clob_market_ws"},"received_at":"2026-07-27T05:40:28.838848Z","record_id":"03df1998e3c816140bb1cbd40c31e9852f075463f4ce4fe140cf30cbb4b55e87","schema_fingerprint":"8488399f31b0337811b13b266be932db7062827c2470b78bd8e9e99bab51d17d","schema_version":"edge-lab-recorder.raw.v1","sequence":null,"source":"clob_market_ws"}
{"event_at":"2026-07-27T05:40:26.952000Z","event_fingerprint":"b3a529d1a3fc05c72c87158b016c85203d704a6678fa05b9babc3016356af4ac","payload":{"connection_id":"efc69d3132f1467b8e898a382b23ac0d","event_at":"2026-07-27T05:40:26.952000Z","event_type":"best_bid_ask","frame_hash":"07ec0eb78e08e01ba879f7195b5ffde2c01c56a34e017202d9cae5cdb9055ce1","frame_index":0,"kind":"data","monotonic_ns":232812078435916,"payload":{"asset_id":"110216635572655435074987471276357323571387854733835379371586402147734167783946","best_ask":"0.47","best_bid":"0.42","event_type":"best_bid_ask","market":"0x3b40066b5cf3871a2f6237c5628bd8092a206aa998558ac5ec13c4483e31e160","spread":"0.05","timestamp":"1785130826952"},"payload_hash":"169f760a6f16436d9d926bab3c3f125d6f6680d4e4736d77c969e97c8bea81a0","raw_frame":"{\"market\":\"0x3b40066b5cf3871a2f6237c5628bd8092a206aa998558ac5ec13c4483e31e160\", \"asset_id\":\"110216635572655435074987471276357323571387854733835379371586402147734167783946\", \"best_bid\":\"0.42\", \"best_ask\":\"0.47\", \"spread\":\"0.05\", \"timestamp\":\"1785130826952\", \"event_type\":\"best_bid_ask\"}","received_at":"2026-07-27T05:40:28.844596Z","schema_version":"clob-market-ws.best_bid_ask.v1","sequence":null,"server_hash":null,"server_timestamp":"1785130826952","session_id":"502006c5cfcd437296561ea750c9ec8b","source":"clob_market_ws"},"received_at":"2026-07-27T05:40:28.844596Z","record_id":"a5af4db65270d93d30f601d28deeed2d0374f6fa7f30a6fa1a575d671ac05ae0","schema_fingerprint":"8488399f31b0337811b13b266be932db7062827c2470b78bd8e9e99bab51d17d","schema_version":"edge-lab-recorder.raw.v1","sequence":null,"source":"clob_market_ws"}
{"event_at":"2026-07-27T05:40:26.952000Z","event_fingerprint":"d7266c31aacb55f0ba4668044a4bfad4bea4bc559292eb3c13e1568bc368f313","payload":{"connection_id":"efc69d3132f1467b8e898a382b23ac0d","event_at":"2026-07-27T05:40:26.952000Z","event_type":"price_change","frame_hash":"1e470995195b96a584e491c9c515c7c5c4400851521bd24afe796140fb1b91e7","frame_index":0,"kind":"data","monotonic_ns":232812081880500,"payload":{"event_type":"price_change","market":"0x3b40066b5cf3871a2f6237c5628bd8092a206aa998558ac5ec13c4483e31e160","price_changes":[{"asset_id":"14766054693214075530629349735273995982307625376442606753688071083149620216746","best_ask":"0.58","best_bid":"0.53","hash":"df06977b22a12b991d3ef82acf846082dabff5eb","price":"0.57","side":"BUY","size":"0"},{"asset_id":"110216635572655435074987471276357323571387854733835379371586402147734167783946","best_ask":"0.47","best_bid":"0.42","hash":"3cb7290f247689f901852ed63a9333c3c56984e6","price":"0.43","side":"SELL","size":"0"}],"timestamp":"1785130826952"},"payload_hash":"eb6dacb04eb1e8c1cb0729cdd74320e2fe4fec58cf1a280812043cef650ac0e3","raw_frame":"{\"market\":\"0x3b40066b5cf3871a2f6237c5628bd8092a206aa998558ac5ec13c4483e31e160\", \"price_changes\":[{\"asset_id\":\"14766054693214075530629349735273995982307625376442606753688071083149620216746\", \"price\":\"0.57\", \"size\":\"0\", \"side\":\"BUY\", \"hash\":\"df06977b22a12b991d3ef82acf846082dabff5eb\", \"best_bid\":\"0.53\", \"best_ask\":\"0.58\"}, {\"asset_id\":\"110216635572655435074987471276357323571387854733835379371586402147734167783946\", \"price\":\"0.43\", \"size\":\"0\", \"side\":\"SELL\", \"hash\":\"3cb7290f247689f901852ed63a9333c3c56984e6\", \"best_bid\":\"0.42\", \"best_ask\":\"0.47\"}], \"timestamp\":\"1785130826952\", \"event_type\":\"price_change\"}","received_at":"2026-07-27T05:40:28.848046Z","schema_version":"clob-market-ws.price_change.v1","sequence":null,"server_hash":null,"server_timestamp":"1785130826952","session_id":"502006c5cfcd437296561ea750c9ec8b","source":"clob_market_ws"},"received_at":"2026-07-27T05:40:28.848046Z","record_id":"da2e586ac70d379d7982bfffcdc747eb5b5088d5a5722246d6cb948d92e38871","schema_fingerprint":"4aa3821a28b0b7c2400bc59aba4bcc0a76e971dadd19610d3ad38c768e124dc7","schema_version":"edge-lab-recorder.raw.v1","sequence":null,"source":"clob_market_ws"}
{"event_at":"2026-07-27T05:40:26.952000Z","event_fingerprint":"0aa6be208954cff7b21de5c900b5148f482899e733578df69cdbccc8a3779259","payload":{"connection_id":"efc69d3132f1467b8e898a382b23ac0d","event_at":"2026-07-27T05:40:26.952000Z","event_type":"book","frame_hash":"2a2697839e5021e2ccc66433c099b824c54b86564c40ccdb4b1a1198d0938bb4","frame_index":0,"kind":"data","monotonic_ns":232812086188958,"payload":{"asks":[{"price":"0.99","size":"5645.45"},{"price":"0.98","size":"806.1"},{"price":"0.97","size":"676.1"},{"price":"0.96","size":"611.09"},{"price":"0.95","size":"655.68"},{"price":"0.94","size":"638.2"},{"price":"0.93","size":"105.24"},{"price":"0.92","size":"90.79"},{"price":"0.91","size":"114.6"},{"price":"0.9","size":"85.29"},{"price":"0.89","size":"76.6"},{"price":"0.88","size":"103.4"},{"price":"0.87","size":"81.5"},{"price":"0.86","size":"365.9"},{"price":"0.85","size":"96.5"},{"price":"0.84","size":"64.3"},{"price":"0.83","size":"63.3"},{"price":"0.82","size":"91.3"},{"price":"0.81","size":"82.5"},{"price":"0.8","size":"81.8"},{"price":"0.79","size":"94.1"},{"price":"0.78","size":"80.5"},{"price":"0.77","size":"368.71"},{"price":"0.76","size":"114.51"},{"price":"0.75","size":"94"},{"price":"0.74","size":"145"},{"price":"0.73","size":"94"},{"price":"0.72","size":"59.97"},{"price":"0.71","size":"67.04"},{"price":"0.7","size":"91.98"},{"price":"0.69","size":"153.95"},{"price":"0.68","size":"79"},{"price":"0.67","size":"90"},{"price":"0.66","size":"126.79"},{"price":"0.65","size":"54"},{"price":"0.64","size":"101.94"},{"price":"0.63","size":"65.85"},{"price":"0.62","size":"65.68"},{"price":"0.61","size":"104.21"},{"price":"0.6","size":"64.3"},{"price":"0.59","size":"64.4"},{"price":"0.58","size":"184.6"}],"asset_id":"14766054693214075530629349735273995982307625376442606753688071083149620216746","bids":[{"price":"0.01","size":"5633.02"},{"price":"0.02","size":"705.1"},{"price":"0.03","size":"635.1"},{"price":"0.04","size":"641.09"},{"price":"0.05","size":"741.2"},{"price":"0.06","size":"586.2"},{"price":"0.07","size":"616.24"},{"price":"0.08","size":"573.79"},{"price":"0.09","size":"569.6"},{"price":"0.1","size":"266.29"},{"price":"0.11","size":"63.6"},{"price":"0.12","size":"61.4"},{"price":"0.13","size":"89.5"},{"price":"0.14","size":"57.9"},{"price":"0.15","size":"103.5"},{"price":"0.16","size":"85.3"},{"price":"0.17","size":"54.3"},{"price":"0.18","size":"53.3"},{"price":"0.19","size":"95.76"},{"price":"0.2","size":"94.8"},{"price":"0.21","size":"130.52"},{"price":"0.22","size":"87.5"},{"price":"0.23","size":"56.89"},{"price":"0.24","size":"56.39"},{"price":"0.25","size":"114"},{"price":"0.26","size":"54.6"},{"price":"0.27","size":"54.2"},{"price":"0.28","size":"83.9"},{"price":"0.29","size":"53.6"},{"price":"0.3","size":"77.3"},{"price":"0.31","size":"83"},{"price":"0.32","size":"261.12"},{"price":"0.33","size":"46.6"},{"price":"0.34","size":"82.4"},{"price":"0.35","size":"67.5"},{"price":"0.36","size":"51"},{"price":"0.37","size":"80.9"},{"price":"0.38","size":"50.7"},{"price":"0.39","size":"50.6"},{"price":"0.4","size":"103.5"},{"price":"0.41","size":"50.4"},{"price":"0.42","size":"50.3"},{"price":"0.43","size":"80.2"},{"price":"0.44","size":"38"},{"price":"0.45","size":"54"},{"price":"0.46","size":"68"},{"price":"0.47","size":"308"},{"price":"0.48","size":"15"},{"price":"0.49","size":"23"},{"price":"0.5","size":"14"},{"price":"0.51","size":"13"},{"price":"0.52","size":"5"},{"price":"0.53","size":"39.42"}],"event_type":"book","hash":"df06977b22a12b991d3ef82acf846082dabff5eb","market":"0x3b40066b5cf3871a2f6237c5628bd8092a206aa998558ac5ec13c4483e31e160","timestamp":"1785130826952"},"payload_hash":"fcd5716a99a99c7504dd756bfbd26c5ffea28bee96485c4512af7053956ac5e9","raw_frame":"{\"market\":\"0x3b40066b5cf3871a2f6237c5628bd8092a206aa998558ac5ec13c4483e31e160\", \"asset_id\":\"14766054693214075530629349735273995982307625376442606753688071083149620216746\", \"bids\":[{\"price\":\"0.01\", \"size\":\"5633.02\"}, {\"price\":\"0.02\", \"size\":\"705.1\"}, {\"price\":\"0.03\", \"size\":\"635.1\"}, {\"price\":\"0.04\", \"size\":\"641.09\"}, {\"price\":\"0.05\", \"size\":\"741.2\"}, {\"price\":\"0.06\", \"size\":\"586.2\"}, {\"price\":\"0.07\", \"size\":\"616.24\"}, {\"price\":\"0.08\", \"size\":\"573.79\"}, {\"price\":\"0.09\", \"size\":\"569.6\"}, {\"price\":\"0.1\", \"size\":\"266.29\"}, {\"price\":\"0.11\", \"size\":\"63.6\"}, {\"price\":\"0.12\", \"size\":\"61.4\"}, {\"price\":\"0.13\", \"size\":\"89.5\"}, {\"price\":\"0.14\", \"size\":\"57.9\"}, {\"price\":\"0.15\", \"size\":\"103.5\"}, {\"price\":\"0.16\", \"size\":\"85.3\"}, {\"price\":\"0.17\", \"size\":\"54.3\"}, {\"price\":\"0.18\", \"size\":\"53.3\"}, {\"price\":\"0.19\", \"size\":\"95.76\"}, {\"price\":\"0.2\", \"size\":\"94.8\"}, {\"price\":\"0.21\", \"size\":\"130.52\"}, {\"price\":\"0.22\", \"size\":\"87.5\"}, {\"price\":\"0.23\", \"size\":\"56.89\"}, {\"price\":\"0.24\", \"size\":\"56.39\"}, {\"price\":\"0.25\", \"size\":\"114\"}, {\"price\":\"0.26\", \"size\":\"54.6\"}, {\"price\":\"0.27\", \"size\":\"54.2\"}, {\"price\":\"0.28\", \"size\":\"83.9\"}, {\"price\":\"0.29\", \"size\":\"53.6\"}, {\"price\":\"0.3\", \"size\":\"77.3\"}, {\"price\":\"0.31\", \"size\":\"83\"}, {\"price\":\"0.32\", \"size\":\"261.12\"}, {\"price\":\"0.33\", \"size\":\"46.6\"}, {\"price\":\"0.34\", \"size\":\"82.4\"}, {\"price\":\"0.35\", \"size\":\"67.5\"}, {\"price\":\"0.36\", \"size\":\"51\"}, {\"price\":\"0.37\", \"size\":\"80.9\"}, {\"price\":\"0.38\", \"size\":\"50.7\"}, {\"price\":\"0.39\", \"size\":\"50.6\"}, {\"price\":\"0.4\", \"size\":\"103.5\"}, {\"price\":\"0.41\", \"size\":\"50.4\"}, {\"price\":\"0.42\", \"size\":\"50.3\"}, {\"price\":\"0.43\", \"size\":\"80.2\"}, {\"price\":\"0.44\", \"size\":\"38\"}, {\"price\":\"0.45\", \"size\":\"54\"}, {\"price\":\"0.46\", \"size\":\"68\"}, {\"price\":\"0.47\", \"size\":\"308\"}, {\"price\":\"0.48\", \"size\":\"15\"}, {\"price\":\"0.49\", \"size\":\"23\"}, {\"price\":\"0.5\", \"size\":\"14\"}, {\"price\":\"0.51\", \"size\":\"13\"}, {\"price\":\"0.52\", \"size\":\"5\"}, {\"price\":\"0.53\", \"size\":\"39.42\"}], \"asks\":[{\"price\":\"0.99\", \"size\":\"5645.45\"}, {\"price\":\"0.98\", \"size\":\"806.1\"}, {\"price\":\"0.97\", \"size\":\"676.1\"}, {\"price\":\"0.96\", \"size\":\"611.09\"}, {\"price\":\"0.95\", \"size\":\"655.68\"}, {\"price\":\"0.94\", \"size\":\"638.2\"}, {\"price\":\"0.93\", \"size\":\"105.24\"}, {\"price\":\"0.92\", \"size\":\"90.79\"}, {\"price\":\"0.91\", \"size\":\"114.6\"}, {\"price\":\"0.9\", \"size\":\"85.29\"}, {\"price\":\"0.89\", \"size\":\"76.6\"}, {\"price\":\"0.88\", \"size\":\"103.4\"}, {\"price\":\"0.87\", \"size\":\"81.5\"}, {\"price\":\"0.86\", \"size\":\"365.9\"}, {\"price\":\"0.85\", \"size\":\"96.5\"}, {\"price\":\"0.84\", \"size\":\"64.3\"}, {\"price\":\"0.83\", \"size\":\"63.3\"}, {\"price\":\"0.82\", \"size\":\"91.3\"}, {\"price\":\"0.81\", \"size\":\"82.5\"}, {\"price\":\"0.8\", \"size\":\"81.8\"}, {\"price\":\"0.79\", \"size\":\"94.1\"}, {\"price\":\"0.78\", \"size\":\"80.5\"}, {\"price\":\"0.77\", \"size\":\"368.71\"}, {\"price\":\"0.76\", \"size\":\"114.51\"}, {\"price\":\"0.75\", \"size\":\"94\"}, {\"price\":\"0.74\", \"size\":\"145\"}, {\"price\":\"0.73\", \"size\":\"94\"}, {\"price\":\"0.72\", \"size\":\"59.97\"}, {\"price\":\"0.71\", \"size\":\"67.04\"}, {\"price\":\"0.7\", \"size\":\"91.98\"}, {\"price\":\"0.69\", \"size\":\"153.95\"}, {\"price\":\"0.68\", \"size\":\"79\"}, {\"price\":\"0.67\", \"size\":\"90\"}, {\"price\":\"0.66\", \"size\":\"126.79\"}, {\"price\":\"0.65\", \"size\":\"54\"}, {\"price\":\"0.64\", \"size\":\"101.94\"}, {\"price\":\"0.63\", \"size\":\"65.85\"}, {\"price\":\"0.62\", \"size\":\"65.68\"}, {\"price\":\"0.61\", \"size\":\"104.21\"}, {\"price\":\"0.6\", \"size\":\"64.3\"}, {\"price\":\"0.59\", \"size\":\"64.4\"}, {\"price\":\"0.58\", \"size\":\"184.6\"}], \"hash\":\"df06977b22a12b991d3ef82acf846082dabff5eb\", \"timestamp\":\"1785130826952\", \"event_type\":\"book\"}","received_at":"2026-07-27T05:40:28.852349Z","schema_version":"clob-market-ws.book.v1","sequence":null,"server_hash":"df06977b22a12b991d3ef82acf846082dabff5eb","server_timestamp":"1785130826952","session_id":"502006c5cfcd437296561ea750c9ec8b","source":"clob_market_ws"},"received_at":"2026-07-27T05:40:28.852349Z","record_id":"f82be9c26b98dcc1e7c89346b36f2ab25e275fa80ab1c1dfdd455ae753e8f049","schema_fingerprint":"dc2caa1c89c6a7426e2e07ff925910cd4d0a8a223a515d4092d91d6d127aacb6","schema_version":"edge-lab-recorder.raw.v1","sequence":null,"source":"clob_market_ws"}
{"event_at":"2026-07-27T05:40:26.952000Z","event_fingerprint":"b1512b1e50da6ab4d893bbf575e9eef7f954f3172f25c92db7afc38be59b6cfa","payload":{"connection_id":"efc69d3132f1467b8e898a382b23ac0d","event_at":"2026-07-27T05:40:26.952000Z","event_type":"book","frame_hash":"574e0c77e774bcbd274cbea78fbd06bbe177b719eb70514351eee01b7be4cea6","frame_index":0,"kind":"data","monotonic_ns":232812102112416,"payload":{"asks":[{"price":"0.99","size":"5633.02"},{"price":"0.98","size":"705.1"},{"price":"0.97","size":"635.1"},{"price":"0.96","size":"641.09"},{"price":"0.95","size":"741.2"},{"price":"0.94","size":"586.2"},{"price":"0.93","size":"616.24"},{"price":"0.92","size":"573.79"},{"price":"0.91","size":"569.6"},{"price":"0.9","size":"266.29"},{"price":"0.89","size":"63.6"},{"price":"0.88","size":"61.4"},{"price":"0.87","size":"89.5"},{"price":"0.86","size":"57.9"},{"price":"0.85","size":"103.5"},{"price":"0.84","size":"85.3"},{"price":"0.83","size":"54.3"},{"price":"0.82","size":"53.3"},{"price":"0.81","size":"95.76"},{"price":"0.8","size":"94.8"},{"price":"0.79","size":"130.52"},{"price":"0.78","size":"87.5"},{"price":"0.77","size":"56.89"},{"price":"0.76","size":"56.39"},{"price":"0.75","size":"114"},{"price":"0.74","size":"54.6"},{"price":"0.73","size":"54.2"},{"price":"0.72","size":"83.9"},{"price":"0.71","size":"53.6"},{"price":"0.7","size":"77.3"},{"price":"0.69","size":"83"},{"price":"0.68","size":"261.12"},{"price":"0.67","size":"46.6"},{"price":"0.66","size":"82.4"},{"price":"0.65","size":"67.5"},{"price":"0.64","size":"51"},{"price":"0.63","size":"80.9"},{"price":"0.62","size":"50.7"},{"price":"0.61","size":"50.6"},{"price":"0.6","size":"103.5"},{"price":"0.59","size":"50.4"},{"price":"0.58","size":"50.3"},{"price":"0.57","size":"80.2"},{"price":"0.56","size":"38"},{"price":"0.55","size":"54"},{"price":"0.54","size":"68"},{"price":"0.53","size":"308"},{"price":"0.52","size":"15"},{"price":"0.51","size":"23"},{"price":"0.5","size":"14"},{"price":"0.49","size":"13"},{"price":"0.48","size":"5"},{"price":"0.47","size":"39.42"}],"asset_id":"110216635572655435074987471276357323571387854733835379371586402147734167783946","bids":[{"price":"0.01","size":"5645.45"},{"price":"0.02","size":"806.1"},{"price":"0.03","size":"676.1"},{"price":"0.04","size":"611.09"},{"price":"0.05","size":"655.68"},{"price":"0.06","size":"638.2"},{"price":"0.07","size":"105.24"},{"price":"0.08","size":"90.79"},{"price":"0.09","size":"114.6"},{"price":"0.1","size":"85.29"},{"price":"0.11","size":"76.6"},{"price":"0.12","size":"103.4"},{"price":"0.13","size":"81.5"},{"price":"0.14","size":"365.9"},{"price":"0.15","size":"96.5"},{"price":"0.16","size":"64.3"},{"price":"0.17","size":"63.3"},{"price":"0.18","size":"91.3"},{"price":"0.19","size":"82.5"},{"price":"0.2","size":"81.8"},{"price":"0.21","size":"94.1"},{"price":"0.22","size":"80.5"},{"price":"0.23","size":"368.71"},{"price":"0.24","size":"114.51"},{"price":"0.25","size":"94"},{"price":"0.26","size":"145"},{"price":"0.27","size":"94"},{"price":"0.28","size":"59.97"},{"price":"0.29","size":"67.04"},{"price":"0.3","size":"91.98"},{"price":"0.31","size":"153.95"},{"price":"0.32","size":"79"},{"price":"0.33","size":"90"},{"price":"0.34","size":"126.79"},{"price":"0.35","size":"54"},{"price":"0.36","size":"101.94"},{"price":"0.37","size":"65.85"},{"price":"0.38","size":"65.68"},{"price":"0.39","size":"104.21"},{"price":"0.4","size":"64.3"},{"price":"0.41","size":"64.4"},{"price":"0.42","size":"184.6"}],"event_type":"book","hash":"3cb7290f247689f901852ed63a9333c3c56984e6","market":"0x3b40066b5cf3871a2f6237c5628bd8092a206aa998558ac5ec13c4483e31e160","timestamp":"1785130826952"},"payload_hash":"9feafb30e7fb0ed90a856427fe2ef200bbd63d872a698968805f840021acfd0e","raw_frame":"{\"market\":\"0x3b40066b5cf3871a2f6237c5628bd8092a206aa998558ac5ec13c4483e31e160\", \"asset_id\":\"110216635572655435074987471276357323571387854733835379371586402147734167783946\", \"bids\":[{\"price\":\"0.01\", \"size\":\"5645.45\"}, {\"price\":\"0.02\", \"size\":\"806.1\"}, {\"price\":\"0.03\", \"size\":\"676.1\"}, {\"price\":\"0.04\", \"size\":\"611.09\"}, {\"price\":\"0.05\", \"size\":\"655.68\"}, {\"price\":\"0.06\", \"size\":\"638.2\"}, {\"price\":\"0.07\", \"size\":\"105.24\"}, {\"price\":\"0.08\", \"size\":\"90.79\"}, {\"price\":\"0.09\", \"size\":\"114.6\"}, {\"price\":\"0.1\", \"size\":\"85.29\"}, {\"price\":\"0.11\", \"size\":\"76.6\"}, {\"price\":\"0.12\", \"size\":\"103.4\"}, {\"price\":\"0.13\", \"size\":\"81.5\"}, {\"price\":\"0.14\", \"size\":\"365.9\"}, {\"price\":\"0.15\", \"size\":\"96.5\"}, {\"price\":\"0.16\", \"size\":\"64.3\"}, {\"price\":\"0.17\", \"size\":\"63.3\"}, {\"price\":\"0.18\", \"size\":\"91.3\"}, {\"price\":\"0.19\", \"size\":\"82.5\"}, {\"price\":\"0.2\", \"size\":\"81.8\"}, {\"price\":\"0.21\", \"size\":\"94.1\"}, {\"price\":\"0.22\", \"size\":\"80.5\"}, {\"price\":\"0.23\", \"size\":\"368.71\"}, {\"price\":\"0.24\", \"size\":\"114.51\"}, {\"price\":\"0.25\", \"size\":\"94\"}, {\"price\":\"0.26\", \"size\":\"145\"}, {\"price\":\"0.27\", \"size\":\"94\"}, {\"price\":\"0.28\", \"size\":\"59.97\"}, {\"price\":\"0.29\", \"size\":\"67.04\"}, {\"price\":\"0.3\", \"size\":\"91.98\"}, {\"price\":\"0.31\", \"size\":\"153.95\"}, {\"price\":\"0.32\", \"size\":\"79\"}, {\"price\":\"0.33\", \"size\":\"90\"}, {\"price\":\"0.34\", \"size\":\"126.79\"}, {\"price\":\"0.35\", \"size\":\"54\"}, {\"price\":\"0.36\", \"size\":\"101.94\"}, {\"price\":\"0.37\", \"size\":\"65.85\"}, {\"price\":\"0.38\", \"size\":\"65.68\"}, {\"price\":\"0.39\", \"size\":\"104.21\"}, {\"price\":\"0.4\", \"size\":\"64.3\"}, {\"price\":\"0.41\", \"size\":\"64.4\"}, {\"price\":\"0.42\", \"size\":\"184.6\"}], \"asks\":[{\"price\":\"0.99\", \"size\":\"5633.02\"}, {\"price\":\"0.98\", \"size\":\"705.1\"}, {\"price\":\"0.97\", \"size\":\"635.1\"}, {\"price\":\"0.96\", \"size\":\"641.09\"}, {\"price\":\"0.95\", \"size\":\"741.2\"}, {\"price\":\"0.94\", \"size\":\"586.2\"}, {\"price\":\"0.93\", \"size\":\"616.24\"}, {\"price\":\"0.92\", \"size\":\"573.79\"}, {\"price\":\"0.91\", \"size\":\"569.6\"}, {\"price\":\"0.9\", \"size\":\"266.29\"}, {\"price\":\"0.89\", \"size\":\"63.6\"}, {\"price\":\"0.88\", \"size\":\"61.4\"}, {\"price\":\"0.87\", \"size\":\"89.5\"}, {\"price\":\"0.86\", \"size\":\"57.9\"}, {\"price\":\"0.85\", \"size\":\"103.5\"}, {\"price\":\"0.84\", \"size\":\"85.3\"}, {\"price\":\"0.83\", \"size\":\"54.3\"}, {\"price\":\"0.82\", \"size\":\"53.3\"}, {\"price\":\"0.81\", \"size\":\"95.76\"}, {\"price\":\"0.8\", \"size\":\"94.8\"}, {\"price\":\"0.79\", \"size\":\"130.52\"}, {\"price\":\"0.78\", \"size\":\"87.5\"}, {\"price\":\"0.77\", \"size\":\"56.89\"}, {\"price\":\"0.76\", \"size\":\"56.39\"}, {\"price\":\"0.75\", \"size\":\"114\"}, {\"price\":\"0.74\", \"size\":\"54.6\"}, {\"price\":\"0.73\", \"size\":\"54.2\"}, {\"price\":\"0.72\", \"size\":\"83.9\"}, {\"price\":\"0.71\", \"size\":\"53.6\"}, {\"price\":\"0.7\", \"size\":\"77.3\"}, {\"price\":\"0.69\", \"size\":\"83\"}, {\"price\":\"0.68\", \"size\":\"261.12\"}, {\"price\":\"0.67\", \"size\":\"46.6\"}, {\"price\":\"0.66\", \"size\":\"82.4\"}, {\"price\":\"0.65\", \"size\":\"67.5\"}, {\"price\":\"0.64\", \"size\":\"51\"}, {\"price\":\"0.63\", \"size\":\"80.9\"}, {\"price\":\"0.62\", \"size\":\"50.7\"}, {\"price\":\"0.61\", \"size\":\"50.6\"}, {\"price\":\"0.6\", \"size\":\"103.5\"}, {\"price\":\"0.59\", \"size\":\"50.4\"}, {\"price\":\"0.58\", \"size\":\"50.3\"}, {\"price\":\"0.57\", \"size\":\"80.2\"}, {\"price\":\"0.56\", \"size\":\"38\"}, {\"price\":\"0.55\", \"size\":\"54\"}, {\"price\":\"0.54\", \"size\":\"68\"}, {\"price\":\"0.53\", \"size\":\"308\"}, {\"price\":\"0.52\", \"size\":\"15\"}, {\"price\":\"0.51\", \"size\":\"23\"}, {\"price\":\"0.5\", \"size\":\"14\"}, {\"price\":\"0.49\", \"size\":\"13\"}, {\"price\":\"0.48\", \"size\":\"5\"}, {\"price\":\"0.47\", \"size\":\"39.42\"}], \"hash\":\"3cb7290f247689f901852ed63a9333c3c56984e6\", \"timestamp\":\"1785130826952\", \"event_type\":\"book\"}","received_at":"2026-07-27T05:40:28.868276Z","schema_version":"clob-market-ws.book.v1","sequence":null,"server_hash":"3cb7290f247689f901852ed63a9333c3c56984e6","server_timestamp":"1785130826952","session_id":"502006c5cfcd437296561ea750c9ec8b","source":"clob_market_ws"},"received_at":"2026-07-27T05:40:28.868276Z","record_id":"6157c7e53784d675e77e76240529c900bc8f93b25f7720e9eb4604d8e3927275","schema_fingerprint":"dc2caa1c89c6a7426e2e07ff925910cd4d0a8a223a515d4092d91d6d127aacb6","schema_version":"edge-lab-recorder.raw.v1","sequence":null,"source":"clob_market_ws"}
{"event_at":"2026-07-27T05:40:26.956000Z","event_fingerprint":"77ebba86bc300c8edfc8dffb50b07271870aebbb8d99f583ed74b896ee4f421f","payload":{"connection_id":"efc69d3132f1467b8e898a382b23ac0d","event_at":"2026-07-27T05:40:26.956000Z","event_type":"best_bid_ask","frame_hash":"2d046d1502958d1777f289417e3c66ff06098bceed5a1f90779e9e7108e5d692","frame_index":0,"kind":"data","monotonic_ns":232812112519791,"payload":{"asset_id":"14766054693214075530629349735273995982307625376442606753688071083149620216746","best_ask":"0.54","best_bid":"0.53","event_type":"best_bid_ask","market":"0x3b40066b5cf3871a2f6237c5628bd8092a206aa998558ac5ec13c4483e31e160","spread":"0.01","timestamp":"1785130826956"},"payload_hash":"05c09ffb15b61d147bd7ee7c3374760e4d58594157eeefd10cd6be2ce8117cec","raw_frame":"{\"market\":\"0x3b40066b5cf3871a2f6237c5628bd8092a206aa998558ac5ec13c4483e31e160\", \"asset_id\":\"14766054693214075530629349735273995982307625376442606753688071083149620216746\", \"best_bid\":\"0.53\", \"best_ask\":\"0.54\", \"spread\":\"0.01\", \"timestamp\":\"1785130826956\", \"event_type\":\"best_bid_ask\"}","received_at":"2026-07-27T05:40:28.878679Z","schema_version":"clob-market-ws.best_bid_ask.v1","sequence":null,"server_hash":null,"server_timestamp":"1785130826956","session_id":"502006c5cfcd437296561ea750c9ec8b","source":"clob_market_ws"},"received_at":"2026-07-27T05:40:28.878679Z","record_id":"23b830f35296762bd8b60f09fe5eee1d5d73491d6d8ca9c727f8d4258942c234","schema_fingerprint":"8488399f31b0337811b13b266be932db7062827c2470b78bd8e9e99bab51d17d","schema_version":"edge-lab-recorder.raw.v1","sequence":null,"source":"clob_market_ws"}
{"event_at":"2026-07-27T05:40:26.956000Z","event_fingerprint":"66b4df7dfcc356dfca15253817d3e36c405a175690aa4413e21d2f64378b4bd7","payload":{"connection_id":"efc69d3132f1467b8e898a382b23ac0d","event_at":"2026-07-27T05:40:26.956000Z","event_type":"best_bid_ask","frame_hash":"d48c32ac8c27ca6bfa83b4fc56a5f6cf0e7f61c3a07e51d0699d6d33cbcfbbc0","frame_index":0,"kind":"data","monotonic_ns":232812116060250,"payload":{"asset_id":"110216635572655435074987471276357323571387854733835379371586402147734167783946","best_ask":"0.47","best_bid":"0.46","event_type":"best_bid_ask","market":"0x3b40066b5cf3871a2f6237c5628bd8092a206aa998558ac5ec13c4483e31e160","spread":"0.01","timestamp":"1785130826956"},"payload_hash":"fa05463de971bdc2edd7d82fb0cc4d06d2dd809dc3ffe717cee8232d2618c1cc","raw_frame":"{\"market\":\"0x3b40066b5cf3871a2f6237c5628bd8092a206aa998558ac5ec13c4483e31e160\", \"asset_id\":\"110216635572655435074987471276357323571387854733835379371586402147734167783946\", \"best_bid\":\"0.46\", \"best_ask\":\"0.47\", \"spread\":\"0.01\", \"timestamp\":\"1785130826956\", \"event_type\":\"best_bid_ask\"}","received_at":"2026-07-27T05:40:28.882222Z","schema_version":"clob-market-ws.best_bid_ask.v1","sequence":null,"server_hash":null,"server_timestamp":"1785130826956","session_id":"502006c5cfcd437296561ea750c9ec8b","source":"clob_market_ws"},"received_at":"2026-07-27T05:40:28.882222Z","record_id":"c1238ab8f14a4d92b5e322f82aed6079c09359a319004b7c79725b951a871ad6","schema_fingerprint":"8488399f31b0337811b13b266be932db7062827c2470b78bd8e9e99bab51d17d","schema_version":"edge-lab-recorder.raw.v1","sequence":null,"source":"clob_market_ws"}
{"event_at":"2026-07-27T05:40:26.956000Z","event_fingerprint":"df4c47c9725285275dce190f22a59a26b1696fbe6004dc54569d04b74fc92afb","payload":{"connection_id":"efc69d3132f1467b8e898a382b23ac0d","event_at":"2026-07-27T05:40:26.956000Z","event_type":"price_change","frame_hash":"05125e075f0d8d0809c954822438643607d9fcc7ce8920a85ebd3e0eb7b63968","frame_index":0,"kind":"data","monotonic_ns":232812119267083,"payload":{"event_type":"price_change","market":"0x3b40066b5cf3871a2f6237c5628bd8092a206aa998558ac5ec13c4483e31e160","price_changes":[{"asset_id":"110216635572655435074987471276357323571387854733835379371586402147734167783946","best_ask":"0.47","best_bid":"0.46","hash":"37ebb2b88a754f1d8568a7b5cbdccaf34a7425c9","price":"0.46","side":"BUY","size":"22"},{"asset_id":"14766054693214075530629349735273995982307625376442606753688071083149620216746","best_ask":"0.54","best_bid":"0.53","hash":"a51ff7369f321bde687a4535edc2b73d1649da73","price":"0.54","side":"SELL","size":"22"}],"timestamp":"1785130826956"},"payload_hash":"5f85a3b1acd30f8e94679962361d9dafc3b9a5deaa3afad3ed3bd188fec5fdf4","raw_frame":"{\"market\":\"0x3b40066b5cf3871a2f6237c5628bd8092a206aa998558ac5ec13c4483e31e160\", \"price_changes\":[{\"asset_id\":\"110216635572655435074987471276357323571387854733835379371586402147734167783946\", \"price\":\"0.46\", \"size\":\"22\", \"side\":\"BUY\", \"hash\":\"37ebb2b88a754f1d8568a7b5cbdccaf34a7425c9\", \"best_bid\":\"0.46\", \"best_ask\":\"0.47\"}, {\"asset_id\":\"14766054693214075530629349735273995982307625376442606753688071083149620216746\", \"price\":\"0.54\", \"size\":\"22\", \"side\":\"SELL\", \"hash\":\"a51ff7369f321bde687a4535edc2b73d1649da73\", \"best_bid\":\"0.53\", \"best_ask\":\"0.54\"}], \"timestamp\":\"1785130826956\", \"event_type\":\"price_change\"}","received_at":"2026-07-27T05:40:28.885428Z","schema_version":"clob-market-ws.price_change.v1","sequence":null,"server_hash":null,"server_timestamp":"1785130826956","session_id":"502006c5cfcd437296561ea750c9ec8b","source":"clob_market_ws"},"received_at":"2026-07-27T05:40:28.885428Z","record_id":"cdbc2078277007b16f5b2ad9aa476ee3614e2b6187f70a69a9f5c6ca30cecd87","schema_fingerprint":"4aa3821a28b0b7c2400bc59aba4bcc0a76e971dadd19610d3ad38c768e124dc7","schema_version":"edge-lab-recorder.raw.v1","sequence":null,"source":"clob_market_ws"}
{"event_at":"2026-07-27T05:40:26.957000Z","event_fingerprint":"c9f6d43321a53acb4148e1097c2030a83991fecd09c8b94009a8d73f4c4c4a9e","payload":{"connection_id":"efc69d3132f1467b8e898a382b23ac0d","event_at":"2026-07-27T05:40:26.957000Z","event_type":"price_change","frame_hash":"e96445a5d0fca9f7231911e22df48bde38ef6ff2432543a4636c6c4dbc78f586","frame_index":0,"kind":"data","monotonic_ns":232812125874500,"payload":{"event_type":"price_change","market":"0x3b40066b5cf3871a2f6237c5628bd8092a206aa998558ac5ec13c4483e31e160","price_changes":[{"asset_id":"110216635572655435074987471276357323571387854733835379371586402147734167783946","best_ask":"0.47","best_bid":"0.46","hash":"92b97a382c5a468b5958202cdb5710e270a51354","price":"0.46","side":"BUY","size":"33"},{"asset_id":"14766054693214075530629349735273995982307625376442606753688071083149620216746","best_ask":"0.54","best_bid":"0.53","hash":"94632318c3f8a5cd20ab8dda46b1bc893e000b4e","price":"0.54","side":"SELL","size":"33"}],"timestamp":"1785130826957"},"payload_hash":"072a8bfc7b1c3471beede2b265113bd37ce498035deb3d78f5bdb734a252931a","raw_frame":"{\"market\":\"0x3b40066b5cf3871a2f6237c5628bd8092a206aa998558ac5ec13c4483e31e160\", \"price_changes\":[{\"asset_id\":\"110216635572655435074987471276357323571387854733835379371586402147734167783946\", \"price\":\"0.46\", \"size\":\"33\", \"side\":\"BUY\", \"hash\":\"92b97a382c5a468b5958202cdb5710e270a51354\", \"best_bid\":\"0.46\", \"best_ask\":\"0.47\"}, {\"asset_id\":\"14766054693214075530629349735273995982307625376442606753688071083149620216746\", \"price\":\"0.54\", \"size\":\"33\", \"side\":\"SELL\", \"hash\":\"94632318c3f8a5cd20ab8dda46b1bc893e000b4e\", \"best_bid\":\"0.53\", \"best_ask\":\"0.54\"}], \"timestamp\":\"1785130826957\", \"event_type\":\"price_change\"}","received_at":"2026-07-27T05:40:28.892035Z","schema_version":"clob-market-ws.price_change.v1","sequence":null,"server_hash":null,"server_timestamp":"1785130826957","session_id":"502006c5cfcd437296561ea750c9ec8b","source":"clob_market_ws"},"received_at":"2026-07-27T05:40:28.892035Z","record_id":"041c462ed06731803aa21b498a2265b4beb2bfa3d89dac8565a865926184edbd","schema_fingerprint":"4aa3821a28b0b7c2400bc59aba4bcc0a76e971dadd19610d3ad38c768e124dc7","schema_version":"edge-lab-recorder.raw.v1","sequence":null,"source":"clob_market_ws"}
{"event_at":"2026-07-27T05:40:26.958000Z","event_fingerprint":"7b57d4ddca13b0d1a44ad61fce05ae064a007056d57289655727684575cc601a","payload":{"connection_id":"efc69d3132f1467b8e898a382b23ac0d","event_at":"2026-07-27T05:40:26.958000Z","event_type":"price_change","frame_hash":"b94a36e360446fcc94ca70cc75543dedb3c6e76fd9592ac843ec4c66ad25e139","frame_index":0,"kind":"data","monotonic_ns":232812131600458,"payload":{"event_type":"price_change","market":"0x3b40066b5cf3871a2f6237c5628bd8092a206aa998558ac5ec13c4483e31e160","price_changes":[{"asset_id":"110216635572655435074987471276357323571387854733835379371586402147734167783946","best_ask":"0.47","best_bid":"0.46","hash":"edcf0e445f3c8cd4b851ea7bd4b346bf88177a60","price":"0.44","side":"BUY","size":"22"},{"asset_id":"14766054693214075530629349735273995982307625376442606753688071083149620216746","best_ask":"0.54","best_bid":"0.53","hash":"e42e5f9ac44c00c2b5e07be0ed4a6dc1f9965a06","price":"0.56","side":"SELL","size":"22"}],"timestamp":"1785130826958"},"payload_hash":"ae93a85abadde1a7a4ef2195f8153a956044d76ea72972dea7601d44dc9eafbb","raw_frame":"{\"market\":\"0x3b40066b5cf3871a2f6237c5628bd8092a206aa998558ac5ec13c4483e31e160\", \"price_changes\":[{\"asset_id\":\"110216635572655435074987471276357323571387854733835379371586402147734167783946\", \"price\":\"0.44\", \"size\":\"22\", \"side\":\"BUY\", \"hash\":\"edcf0e445f3c8cd4b851ea7bd4b346bf88177a60\", \"best_bid\":\"0.46\", \"best_ask\":\"0.47\"}, {\"asset_id\":\"14766054693214075530629349735273995982307625376442606753688071083149620216746\", \"price\":\"0.56\", \"size\":\"22\", \"side\":\"SELL\", \"hash\":\"e42e5f9ac44c00c2b5e07be0ed4a6dc1f9965a06\", \"best_bid\":\"0.53\", \"best_ask\":\"0.54\"}], \"timestamp\":\"1785130826958\", \"event_type\":\"price_change\"}","received_at":"2026-07-27T05:40:28.897766Z","schema_version":"clob-market-ws.price_change.v1","sequence":null,"server_hash":null,"server_timestamp":"1785130826958","session_id":"502006c5cfcd437296561ea750c9ec8b","source":"clob_market_ws"},"received_at":"2026-07-27T05:40:28.897766Z","record_id":"f0df74858857c6f40814e9d993be1abac04af461e9a6aaa3bfb34a012cd4274b","schema_fingerprint":"4aa3821a28b0b7c2400bc59aba4bcc0a76e971dadd19610d3ad38c768e124dc7","schema_version":"edge-lab-recorder.raw.v1","sequence":null,"source":"clob_market_ws"}
{"event_at":"2026-07-27T05:40:26.959000Z","event_fingerprint":"80bf663502a87ca6a018df94ef144e59a0acff1d8deb68db37104ed8b5e14eb6","payload":{"connection_id":"efc69d3132f1467b8e898a382b23ac0d","event_at":"2026-07-27T05:40:26.959000Z","event_type":"price_change","frame_hash":"20bed9d867774fed2ccdb4601f0a60e50407131ac4b71847f4db714ce5e8e7dd","frame_index":0,"kind":"data","monotonic_ns":232812136967333,"payload":{"event_type":"price_change","market":"0x3b40066b5cf3871a2f6237c5628bd8092a206aa998558ac5ec13c4483e31e160","price_changes":[{"asset_id":"110216635572655435074987471276357323571387854733835379371586402147734167783946","best_ask":"0.47","best_bid":"0.46","hash":"d9d2fdcbb840b3245ee5206cbd3d9b00adb40aac","price":"0.45","side":"BUY","size":"11"},{"asset_id":"14766054693214075530629349735273995982307625376442606753688071083149620216746","best_ask":"0.54","best_bid":"0.53","hash":"dfb96b67421e426e78bf7f84f5c4123c54930f21","price":"0.55","side":"SELL","size":"11"}],"timestamp":"1785130826959"},"payload_hash":"381c9c8fd5087319991036b80934235117c99d7790b49295a84f328c85a3df4c","raw_frame":"{\"market\":\"0x3b40066b5cf3871a2f6237c5628bd8092a206aa998558ac5ec13c4483e31e160\", \"price_changes\":[{\"asset_id\":\"110216635572655435074987471276357323571387854733835379371586402147734167783946\", \"price\":\"0.45\", \"size\":\"11\", \"side\":\"BUY\", \"hash\":\"d9d2fdcbb840b3245ee5206cbd3d9b00adb40aac\", \"best_bid\":\"0.46\", \"best_ask\":\"0.47\"}, {\"asset_id\":\"14766054693214075530629349735273995982307625376442606753688071083149620216746\", \"price\":\"0.55\", \"size\":\"11\", \"side\":\"SELL\", \"hash\":\"dfb96b67421e426e78bf7f84f5c4123c54930f21\", \"best_bid\":\"0.53\", \"best_ask\":\"0.54\"}], \"timestamp\":\"1785130826959\", \"event_type\":\"price_change\"}","received_at":"2026-07-27T05:40:28.903127Z","schema_version":"clob-market-ws.price_change.v1","sequence":null,"server_hash":null,"server_timestamp":"1785130826959","session_id":"502006c5cfcd437296561ea750c9ec8b","source":"clob_market_ws"},"received_at":"2026-07-27T05:40:28.903127Z","record_id":"a4e348fb4664b5ce72c9ead24e506a1723e88ce2e41c0dc7b3722a988f2867ef","schema_fingerprint":"4aa3821a28b0b7c2400bc59aba4bcc0a76e971dadd19610d3ad38c768e124dc7","schema_version":"edge-lab-recorder.raw.v1","sequence":null,"source":"clob_market_ws"}
{"event_at":"2026-07-27T05:40:26.960000Z","event_fingerprint":"2f41c6298d950319e818cf6f7fe9d37a32d660b3d1ade0f01672606a8e40922e","payload":{"connection_id":"efc69d3132f1467b8e898a382b23ac0d","event_at":"2026-07-27T05:40:26.960000Z","event_type":"price_change","frame_hash":"00fb62d37913fc6ffdccfe8c8a3e4d4694d4c20bd24a2c58f7af1233a687e123","frame_index":0,"kind":"data","monotonic_ns":232812142820750,"payload":{"event_type":"price_change","market":"0x3b40066b5cf3871a2f6237c5628bd8092a206aa998558ac5ec13c4483e31e160","price_changes":[{"asset_id":"110216635572655435074987471276357323571387854733835379371586402147734167783946","best_ask":"0.47","best_bid":"0.46","hash":"a9e894498916a664b8ec72566dd1413c6519742a","price":"0.43","side":"BUY","size":"22"},{"asset_id":"14766054693214075530629349735273995982307625376442606753688071083149620216746","best_ask":"0.54","best_bid":"0.53","hash":"bc4e8c67a33098136d6f8280dd509bf28d4bf2fc","price":"0.57","side":"SELL","size":"22"}],"timestamp":"1785130826960"},"payload_hash":"3ac994a8bf7e5dcc73e80181fe0ff4d5543689e752610fef126dacc55003bd94","raw_frame":"{\"market\":\"0x3b40066b5cf3871a2f6237c5628bd8092a206aa998558ac5ec13c4483e31e160\", \"price_changes\":[{\"asset_id\":\"110216635572655435074987471276357323571387854733835379371586402147734167783946\", \"price\":\"0.43\", \"size\":\"22\", \"side\":\"BUY\", \"hash\":\"a9e894498916a664b8ec72566dd1413c6519742a\", \"best_bid\":\"0.46\", \"best_ask\":\"0.47\"}, {\"asset_id\":\"14766054693214075530629349735273995982307625376442606753688071083149620216746\", \"price\":\"0.57\", \"size\":\"22\", \"side\":\"SELL\", \"hash\":\"bc4e8c67a33098136d6f8280dd509bf28d4bf2fc\", \"best_bid\":\"0.53\", \"best_ask\":\"0.54\"}], \"timestamp\":\"1785130826960\", \"event_type\":\"price_change\"}","received_at":"2026-07-27T05:40:28.908981Z","schema_version":"clob-market-ws.price_change.v1","sequence":null,"server_hash":null,"server_timestamp":"1785130826960","session_id":"502006c5cfcd437296561ea750c9ec8b","source":"clob_market_ws"},"received_at":"2026-07-27T05:40:28.908981Z","record_id":"d0e880172fde92e7aadf76176c672a343a1f086452556b8992cfc5e151aee766","schema_fingerprint":"4aa3821a28b0b7c2400bc59aba4bcc0a76e971dadd19610d3ad38c768e124dc7","schema_version":"edge-lab-recorder.raw.v1","sequence":null,"source":"clob_market_ws"}
{"event_at":"2026-07-27T05:40:26.960000Z","event_fingerprint":"6d7c6fcbe0b56243ad60efd41e889fac062f8db0c99c749b448b46d6b980e21c","payload":{"connection_id":"efc69d3132f1467b8e898a382b23ac0d","event_at":"2026-07-27T05:40:26.960000Z","event_type":"price_change","frame_hash":"8572080e53622c55fddc8eee2149e55b9b0dabc12257ea08c78f6bd59beb4b07","frame_index":0,"kind":"data","monotonic_ns":232812148334750,"payload":{"event_type":"price_change","market":"0x3b40066b5cf3871a2f6237c5628bd8092a206aa998558ac5ec13c4483e31e160","price_changes":[{"asset_id":"110216635572655435074987471276357323571387854733835379371586402147734167783946","best_ask":"0.47","best_bid":"0.46","hash":"bf4d232e73f5ba5fa4f41610acebb97f4d6d827d","price":"0.45","side":"BUY","size":"33"},{"asset_id":"14766054693214075530629349735273995982307625376442606753688071083149620216746","best_ask":"0.54","best_bid":"0.53","hash":"b3c44047f771cabb169a41e34341be72517690f8","price":"0.55","side":"SELL","size":"33"}],"timestamp":"1785130826960"},"payload_hash":"d71f6367fff5ddaccb2606f5b75942edbb9aef95e874b04e568e2aeaabd7fec7","raw_frame":"{\"market\":\"0x3b40066b5cf3871a2f6237c5628bd8092a206aa998558ac5ec13c4483e31e160\", \"price_changes\":[{\"asset_id\":\"110216635572655435074987471276357323571387854733835379371586402147734167783946\", \"price\":\"0.45\", \"size\":\"33\", \"side\":\"BUY\", \"hash\":\"bf4d232e73f5ba5fa4f41610acebb97f4d6d827d\", \"best_bid\":\"0.46\", \"best_ask\":\"0.47\"}, {\"asset_id\":\"14766054693214075530629349735273995982307625376442606753688071083149620216746\", \"price\":\"0.55\", \"size\":\"33\", \"side\":\"SELL\", \"hash\":\"b3c44047f771cabb169a41e34341be72517690f8\", \"best_bid\":\"0.53\", \"best_ask\":\"0.54\"}], \"timestamp\":\"1785130826960\", \"event_type\":\"price_change\"}","received_at":"2026-07-27T05:40:28.914501Z","schema_version":"clob-market-ws.price_change.v1","sequence":null,"server_hash":null,"server_timestamp":"1785130826960","session_id":"502006c5cfcd437296561ea750c9ec8b","source":"clob_market_ws"},"received_at":"2026-07-27T05:40:28.914501Z","record_id":"e9f4044c73a6fc68ba94b5a71266709c037c061ba66618715090244ec925f997","schema_fingerprint":"4aa3821a28b0b7c2400bc59aba4bcc0a76e971dadd19610d3ad38c768e124dc7","schema_version":"edge-lab-recorder.raw.v1","sequence":null,"source":"clob_market_ws"}
{"event_at":"2026-07-27T05:40:26.966000Z","event_fingerprint":"7896cb52144bb4f928e41b4a7b4381e001a0aaf542f923f39ea31cabfd0227a4","payload":{"connection_id":"efc69d3132f1467b8e898a382b23ac0d","event_at":"2026-07-27T05:40:26.966000Z","event_type":"price_change","frame_hash":"95ba5614ce5dc3fe136a92c9cc4788e43cd47d07e1d9d6535343ddd4c3e82088","frame_index":0,"kind":"data","monotonic_ns":232812154883916,"payload":{"event_type":"price_change","market":"0x3b40066b5cf3871a2f6237c5628bd8092a206aa998558ac5ec13c4483e31e160","price_changes":[{"asset_id":"110216635572655435074987471276357323571387854733835379371586402147734167783946","best_ask":"0.47","best_bid":"0.46","hash":"7e98805e593e4ab75b84d9874b3d2d9c0c898935","price":"0.45","side":"BUY","size":"49.8"},{"asset_id":"14766054693214075530629349735273995982307625376442606753688071083149620216746","best_ask":"0.54","best_bid":"0.53","hash":"891d2cd0155fae015a430201ea38fb621c2de234","price":"0.55","side":"SELL","size":"49.8"}],"timestamp":"1785130826966"},"payload_hash":"0442e964e4f34b1e547ec242bcfb537024119b88f3a85e41e648351053f7c19a","raw_frame":"{\"market\":\"0x3b40066b5cf3871a2f6237c5628bd8092a206aa998558ac5ec13c4483e31e160\", \"price_changes\":[{\"asset_id\":\"110216635572655435074987471276357323571387854733835379371586402147734167783946\", \"price\":\"0.45\", \"size\":\"49.8\", \"side\":\"BUY\", \"hash\":\"7e98805e593e4ab75b84d9874b3d2d9c0c898935\", \"best_bid\":\"0.46\", \"best_ask\":\"0.47\"}, {\"asset_id\":\"14766054693214075530629349735273995982307625376442606753688071083149620216746\", \"price\":\"0.55\", \"size\":\"49.8\", \"side\":\"SELL\", \"hash\":\"891d2cd0155fae015a430201ea38fb621c2de234\", \"best_bid\":\"0.53\", \"best_ask\":\"0.54\"}], \"timestamp\":\"1785130826966\", \"event_type\":\"price_change\"}","received_at":"2026-07-27T05:40:28.921045Z","schema_version":"clob-market-ws.price_change.v1","sequence":null,"server_hash":null,"server_timestamp":"1785130826966","session_id":"502006c5cfcd437296561ea750c9ec8b","source":"clob_market_ws"},"received_at":"2026-07-27T05:40:28.921045Z","record_id":"e8ab0195ce55c7fa91090cf3a71ef51c9982d665f30f5dbbe09cbdb689bd0d0d","schema_fingerprint":"4aa3821a28b0b7c2400bc59aba4bcc0a76e971dadd19610d3ad38c768e124dc7","schema_version":"edge-lab-recorder.raw.v1","sequence":null,"source":"clob_market_ws"}
{"event_at":"2026-07-27T05:40:26.968000Z","event_fingerprint":"06b2c27f730723de63dd6ebd74c37910f167a2f6e072207f3b9c5205a9b0ba96","payload":{"connection_id":"efc69d3132f1467b8e898a382b23ac0d","event_at":"2026-07-27T05:40:26.968000Z","event_type":"price_change","frame_hash":"f8a7951769f7eac9078592717e31ab41a267fa3c936c2104ab7dd7e8450abd8c","frame_index":0,"kind":"data","monotonic_ns":232812158609875,"payload":{"event_type":"price_change","market":"0x3b40066b5cf3871a2f6237c5628bd8092a206aa998558ac5ec13c4483e31e160","price_changes":[{"asset_id":"110216635572655435074987471276357323571387854733835379371586402147734167783946","best_ask":"0.47","best_bid":"0.46","hash":"7f5c9c0eb3dd30b1c7edc72c2a585d8226dfe6cb","price":"0.42","side":"BUY","size":"164.6"},{"asset_id":"14766054693214075530629349735273995982307625376442606753688071083149620216746","best_ask":"0.54","best_bid":"0.53","hash":"7aa5e6026b9ca3177cf2c0569c717939dd6aa4cb","price":"0.58","side":"SELL","size":"164.6"}],"timestamp":"1785130826968"},"payload_hash":"f89b41a5db2ec140423360ddc330784efee4eab456168f46372cf1482a344856","raw_frame":"{\"market\":\"0x3b40066b5cf3871a2f6237c5628bd8092a206aa998558ac5ec13c4483e31e160\", \"price_changes\":[{\"asset_id\":\"110216635572655435074987471276357323571387854733835379371586402147734167783946\", \"price\":\"0.42\", \"size\":\"164.6\", \"side\":\"BUY\", \"hash\":\"7f5c9c0eb3dd30b1c7edc72c2a585d8226dfe6cb\", \"best_bid\":\"0.46\", \"best_ask\":\"0.47\"}, {\"asset_id\":\"14766054693214075530629349735273995982307625376442606753688071083149620216746\", \"price\":\"0.58\", \"size\":\"164.6\", \"side\":\"SELL\", \"hash\":\"7aa5e6026b9ca3177cf2c0569c717939dd6aa4cb\", \"best_bid\":\"0.53\", \"best_ask\":\"0.54\"}], \"timestamp\":\"1785130826968\", \"event_type\":\"price_change\"}","received_at":"2026-07-27T05:40:28.924771Z","schema_version":"clob-market-ws.price_change.v1","sequence":null,"server_hash":null,"server_timestamp":"1785130826968","session_id":"502006c5cfcd437296561ea750c9ec8b","source":"clob_market_ws"},"received_at":"2026-07-27T05:40:28.924771Z","record_id":"f52682c73ebd194e965c504ae8f5b26ca145f16aea7cd871bece8669ffa047b9","schema_fingerprint":"4aa3821a28b0b7c2400bc59aba4bcc0a76e971dadd19610d3ad38c768e124dc7","schema_version":"edge-lab-recorder.raw.v1","sequence":null,"source":"clob_market_ws"}
{"event_at":"2026-07-27T05:40:26.969000Z","event_fingerprint":"e4e0ee0d59b48c4ebb4a5dc2a7f92c47c0b08893bdaa90b8f7a11a06c950f4e1","payload":{"connection_id":"efc69d3132f1467b8e898a382b23ac0d","event_at":"2026-07-27T05:40:26.969000Z","event_type":"price_change","frame_hash":"ca40bc99925c18e66bef27de5d33d16a4c8d5f2bc776b993d72d6b55996ce5dd","frame_index":0,"kind":"data","monotonic_ns":232812165269916,"payload":{"event_type":"price_change","market":"0x3b40066b5cf3871a2f6237c5628bd8092a206aa998558ac5ec13c4483e31e160","price_changes":[{"asset_id":"110216635572655435074987471276357323571387854733835379371586402147734167783946","best_ask":"0.47","best_bid":"0.46","hash":"51599872f058c3b940b490bd334a06fc8027a4bc","price":"0.42","side":"BUY","size":"147.6"},{"asset_id":"14766054693214075530629349735273995982307625376442606753688071083149620216746","best_ask":"0.54","best_bid":"0.53","hash":"6dacac0b95fef3039cac4c7d67f44a89d6c96fb6","price":"0.58","side":"SELL","size":"147.6"}],"timestamp":"1785130826969"},"payload_hash":"ff1a502a49f81d05727b8cff83a1e08cda617843da93082357fd7e837a02cddf","raw_frame":"{\"market\":\"0x3b40066b5cf3871a2f6237c5628bd8092a206aa998558ac5ec13c4483e31e160\", \"price_changes\":[{\"asset_id\":\"110216635572655435074987471276357323571387854733835379371586402147734167783946\", \"price\":\"0.42\", \"size\":\"147.6\", \"side\":\"BUY\", \"hash\":\"51599872f058c3b940b490bd334a06fc8027a4bc\", \"best_bid\":\"0.46\", \"best_ask\":\"0.47\"}, {\"asset_id\":\"14766054693214075530629349735273995982307625376442606753688071083149620216746\", \"price\":\"0.58\", \"size\":\"147.6\", \"side\":\"SELL\", \"hash\":\"6dacac0b95fef3039cac4c7d67f44a89d6c96fb6\", \"best_bid\":\"0.53\", \"best_ask\":\"0.54\"}], \"timestamp\":\"1785130826969\", \"event_type\":\"price_change\"}","received_at":"2026-07-27T05:40:28.931436Z","schema_version":"clob-market-ws.price_change.v1","sequence":null,"server_hash":null,"server_timestamp":"1785130826969","session_id":"502006c5cfcd437296561ea750c9ec8b","source":"clob_market_ws"},"received_at":"2026-07-27T05:40:28.931436Z","record_id":"61f8e669dcc166b026c8ff9854398495f9fc9e30f68c04790ce95c8a7799255c","schema_fingerprint":"4aa3821a28b0b7c2400bc59aba4bcc0a76e971dadd19610d3ad38c768e124dc7","schema_version":"edge-lab-recorder.raw.v1","sequence":null,"source":"clob_market_ws"}
{"event_at":"2026-07-27T05:40:26.969000Z","event_fingerprint":"41068ff57ad3151939520732cc2ba199e8e4ca3f7ced802c53b8c2a130537fd2","payload":{"connection_id":"efc69d3132f1467b8e898a382b23ac0d","event_at":"2026-07-27T05:40:26.969000Z","event_type":"price_change","frame_hash":"730f8d3d35967f2664e75944a1813364e1f7dea7c0475fa8e16081a5d7e2c42c","frame_index":0,"kind":"data","monotonic_ns":232812170226375,"payload":{"event_type":"price_change","market":"0x3b40066b5cf3871a2f6237c5628bd8092a206aa998558ac5ec13c4483e31e160","price_changes":[{"asset_id":"14766054693214075530629349735273995982307625376442606753688071083149620216746","best_ask":"0.54","best_bid":"0.53","hash":"1913cac11b5fd8f6ea154a709e3976b378bc6c4c","price":"0.47","side":"BUY","size":"38"},{"asset_id":"110216635572655435074987471276357323571387854733835379371586402147734167783946","best_ask":"0.47","best_bid":"0.46","hash":"2342a54b64a10509f56e80e8afd674cd8e8b6ade","price":"0.53","side":"SELL","size":"38"}],"timestamp":"1785130826969"},"payload_hash":"ceec6f83226c52dc3f70644930802bead00a24e3d790e42eb7439ebe69c442dc","raw_frame":"{\"market\":\"0x3b40066b5cf3871a2f6237c5628bd8092a206aa998558ac5ec13c4483e31e160\", \"price_changes\":[{\"asset_id\":\"14766054693214075530629349735273995982307625376442606753688071083149620216746\", \"price\":\"0.47\", \"size\":\"38\", \"side\":\"BUY\", \"hash\":\"1913cac11b5fd8f6ea154a709e3976b378bc6c4c\", \"best_bid\":\"0.53\", \"best_ask\":\"0.54\"}, {\"asset_id\":\"110216635572655435074987471276357323571387854733835379371586402147734167783946\", \"price\":\"0.53\", \"size\":\"38\", \"side\":\"SELL\", \"hash\":\"2342a54b64a10509f56e80e8afd674cd8e8b6ade\", \"best_bid\":\"0.46\", \"best_ask\":\"0.47\"}], \"timestamp\":\"1785130826969\", \"event_type\":\"price_change\"}","received_at":"2026-07-27T05:40:28.936388Z","schema_version":"clob-market-ws.price_change.v1","sequence":null,"server_hash":null,"server_timestamp":"1785130826969","session_id":"502006c5cfcd437296561ea750c9ec8b","source":"clob_market_ws"},"received_at":"2026-07-27T05:40:28.936388Z","record_id":"258a46f675b518f293b1ed4db6d18c8b6b01f0684c7508f10eb93b80a04fd143","schema_fingerprint":"4aa3821a28b0b7c2400bc59aba4bcc0a76e971dadd19610d3ad38c768e124dc7","schema_version":"edge-lab-recorder.raw.v1","sequence":null,"source":"clob_market_ws"}
{"event_at":"2026-07-27T05:40:26.969000Z","event_fingerprint":"65d93a9fc0235ebb9af25c36bb554dd4402a9706f2905862d3ceac282057251c","payload":{"connection_id":"efc69d3132f1467b8e898a382b23ac0d","event_at":"2026-07-27T05:40:26.969000Z","event_type":"price_change","frame_hash":"42ad7b065bb70125e68ef3ed198d97ef4a96a6d07cf744f7109ff3882c0c386f","frame_index":0,"kind":"data","monotonic_ns":232812176235791,"payload":{"event_type":"price_change","market":"0x3b40066b5cf3871a2f6237c5628bd8092a206aa998558ac5ec13c4483e31e160","price_changes":[{"asset_id":"14766054693214075530629349735273995982307625376442606753688071083149620216746","best_ask":"0.54","best_bid":"0.53","hash":"cb7beedc103b5f7b18ab976a563975818172b021","price":"0.49","side":"BUY","size":"13"},{"asset_id":"110216635572655435074987471276357323571387854733835379371586402147734167783946","best_ask":"0.47","best_bid":"0.46","hash":"a2f59251e7ef34a45b444f39558ab76234a198e1","price":"0.51","side":"SELL","size":"13"}],"timestamp":"1785130826969"},"payload_hash":"0de6d22a4ce17f2f024cf12c6ec18838e0eac34fe59d3c074c4320c2dfbc61e4","raw_frame":"{\"market\":\"0x3b40066b5cf3871a2f6237c5628bd8092a206aa998558ac5ec13c4483e31e160\", \"price_changes\":[{\"asset_id\":\"14766054693214075530629349735273995982307625376442606753688071083149620216746\", \"price\":\"0.49\", \"size\":\"13\", \"side\":\"BUY\", \"hash\":\"cb7beedc103b5f7b18ab976a563975818172b021\", \"best_bid\":\"0.53\", \"best_ask\":\"0.54\"}, {\"asset_id\":\"110216635572655435074987471276357323571387854733835379371586402147734167783946\", \"price\":\"0.51\", \"size\":\"13\", \"side\":\"SELL\", \"hash\":\"a2f59251e7ef34a45b444f39558ab76234a198e1\", \"best_bid\":\"0.46\", \"best_ask\":\"0.47\"}], \"timestamp\":\"1785130826969\", \"event_type\":\"price_change\"}","received_at":"2026-07-27T05:40:28.942396Z","schema_version":"clob-market-ws.price_change.v1","sequence":null,"server_hash":null,"server_timestamp":"1785130826969","session_id":"502006c5cfcd437296561ea750c9ec8b","source":"clob_market_ws"},"received_at":"2026-07-27T05:40:28.942396Z","record_id":"4b9cc9ed6fb701eb421c740f57b63e316904b0a014565558bc15f5591d730e7c","schema_fingerprint":"4aa3821a28b0b7c2400bc59aba4bcc0a76e971dadd19610d3ad38c768e124dc7","schema_version":"edge-lab-recorder.raw.v1","sequence":null,"source":"clob_market_ws"}
{"event_at":"2026-07-27T05:40:26.970000Z","event_fingerprint":"16d20991f580e1fed5c4442b66813e0a330a609d6a0aebf61b3a206f86692d64","payload":{"connection_id":"efc69d3132f1467b8e898a382b23ac0d","event_at":"2026-07-27T05:40:26.970000Z","event_type":"price_change","frame_hash":"9b62f203d5490f4711b1dbe9c8deb9c67acff235def1d1914e8ed05e776efd1c","frame_index":0,"kind":"data","monotonic_ns":232812186733541,"payload":{"event_type":"price_change","market":"0x3b40066b5cf3871a2f6237c5628bd8092a206aa998558ac5ec13c4483e31e160","price_changes":[{"asset_id":"14766054693214075530629349735273995982307625376442606753688071083149620216746","best_ask":"0.54","best_bid":"0.53","hash":"9aa3098ea62894c5f4c1139082435bcbf76ccdcf","price":"0.58","side":"SELL","size":"127.6"},{"asset_id":"110216635572655435074987471276357323571387854733835379371586402147734167783946","best_ask":"0.47","best_bid":"0.46","hash":"2c0292d92c79dc63b679b7062cd41792972ae0c1","price":"0.42","side":"BUY","size":"127.6"}],"timestamp":"1785130826970"},"payload_hash":"921074881fdb559b9ccba90c4650a29649f7f7df7690463b5dd9dfd0604a4c7e","raw_frame":"{\"market\":\"0x3b40066b5cf3871a2f6237c5628bd8092a206aa998558ac5ec13c4483e31e160\", \"price_changes\":[{\"asset_id\":\"14766054693214075530629349735273995982307625376442606753688071083149620216746\", \"price\":\"0.58\", \"size\":\"127.6\", \"side\":\"SELL\", \"hash\":\"9aa3098ea62894c5f4c1139082435bcbf76ccdcf\", \"best_bid\":\"0.53\", \"best_ask\":\"0.54\"}, {\"asset_id\":\"110216635572655435074987471276357323571387854733835379371586402147734167783946\", \"price\":\"0.42\", \"size\":\"127.6\", \"side\":\"BUY\", \"hash\":\"2c0292d92c79dc63b679b7062cd41792972ae0c1\", \"best_bid\":\"0.46\", \"best_ask\":\"0.47\"}], \"timestamp\":\"1785130826970\", \"event_type\":\"price_change\"}","received_at":"2026-07-27T05:40:28.952896Z","schema_version":"clob-market-ws.price_change.v1","sequence":null,"server_hash":null,"server_timestamp":"1785130826970","session_id":"502006c5cfcd437296561ea750c9ec8b","source":"clob_market_ws"},"received_at":"2026-07-27T05:40:28.952896Z","record_id":"1b3f8e4bba7f28cc5f7e0b6dda131f906ff7fc0f6fd52be222ad9d433b3188fe","schema_fingerprint":"4aa3821a28b0b7c2400bc59aba4bcc0a76e971dadd19610d3ad38c768e124dc7","schema_version":"edge-lab-recorder.raw.v1","sequence":null,"source":"clob_market_ws"}
{"event_at":"2026-07-27T05:40:26.971000Z","event_fingerprint":"a9616333f8df50a657c39e6fc5f4fb69af62ffdbda50c2f589cc47ab4140e80b","payload":{"connection_id":"efc69d3132f1467b8e898a382b23ac0d","event_at":"2026-07-27T05:40:26.971000Z","event_type":"price_change","frame_hash":"85c848ec1079ecb0de94f5846a181508f720ff8d11607510a06c09af710c5f66","frame_index":0,"kind":"data","monotonic_ns":232812193137250,"payload":{"event_type":"price_change","market":"0x3b40066b5cf3871a2f6237c5628bd8092a206aa998558ac5ec13c4483e31e160","price_changes":[{"asset_id":"14766054693214075530629349735273995982307625376442606753688071083149620216746","best_ask":"0.54","best_bid":"0.53","hash":"7ad57f8c478556e7ef067b24f44873f0b98f28f9","price":"0.58","side":"SELL","size":"107.6"},{"asset_id":"110216635572655435074987471276357323571387854733835379371586402147734167783946","best_ask":"0.47","best_bid":"0.46","hash":"6c9f61904faeeb6eb0a6943d25528df18ac1944f","price":"0.42","side":"BUY","size":"107.6"}],"timestamp":"1785130826971"},"payload_hash":"fc9984d9e7ec65245a3690103777798dbef6ace413e12fc665561c9dbcc94010","raw_frame":"{\"market\":\"0x3b40066b5cf3871a2f6237c5628bd8092a206aa998558ac5ec13c4483e31e160\", \"price_changes\":[{\"asset_id\":\"14766054693214075530629349735273995982307625376442606753688071083149620216746\", \"price\":\"0.58\", \"size\":\"107.6\", \"side\":\"SELL\", \"hash\":\"7ad57f8c478556e7ef067b24f44873f0b98f28f9\", \"best_bid\":\"0.53\", \"best_ask\":\"0.54\"}, {\"asset_id\":\"110216635572655435074987471276357323571387854733835379371586402147734167783946\", \"price\":\"0.42\", \"size\":\"107.6\", \"side\":\"BUY\", \"hash\":\"6c9f61904faeeb6eb0a6943d25528df18ac1944f\", \"best_bid\":\"0.46\", \"best_ask\":\"0.47\"}], \"timestamp\":\"1785130826971\", \"event_type\":\"price_change\"}","received_at":"2026-07-27T05:40:28.959298Z","schema_version":"clob-market-ws.price_change.v1","sequence":null,"server_hash":null,"server_timestamp":"1785130826971","session_id":"502006c5cfcd437296561ea750c9ec8b","source":"clob_market_ws"},"received_at":"2026-07-27T05:40:28.959298Z","record_id":"4aa5c2028b2056eafe53edb7a461db22a6c703db9e3d41377a7a60bcd77b5b72","schema_fingerprint":"4aa3821a28b0b7c2400bc59aba4bcc0a76e971dadd19610d3ad38c768e124dc7","schema_version":"edge-lab-recorder.raw.v1","sequence":null,"source":"clob_market_ws"}
{"event_at":"2026-07-27T05:40:26.976000Z","event_fingerprint":"8585623e5325371fa7d7d4ce4d9bee43f15c0337ee406facf9f811154d72e5ac","payload":{"connection_id":"efc69d3132f1467b8e898a382b23ac0d","event_at":"2026-07-27T05:40:26.976000Z","event_type":"price_change","frame_hash":"935ddb0b81803442804a471aab897a9b08b81d75cc50016670f6dd513b01db09","frame_index":0,"kind":"data","monotonic_ns":232812200130750,"payload":{"event_type":"price_change","market":"0x3b40066b5cf3871a2f6237c5628bd8092a206aa998558ac5ec13c4483e31e160","price_changes":[{"asset_id":"110216635572655435074987471276357323571387854733835379371586402147734167783946","best_ask":"0.47","best_bid":"0.46","hash":"1aa1deeb21662fa8f21f758bb21caf0f473da664","price":"0.42","side":"BUY","size":"114.38"},{"asset_id":"14766054693214075530629349735273995982307625376442606753688071083149620216746","best_ask":"0.54","best_bid":"0.53","hash":"c1aba65fda68b6be099d58980cd85c19d3325622","price":"0.58","side":"SELL","size":"114.38"}],"timestamp":"1785130826976"},"payload_hash":"152e7eaaa8ffa4e927a8c2b4bf93d78f0b313512f68d04864c038f46444cdab0","raw_frame":"{\"market\":\"0x3b40066b5cf3871a2f6237c5628bd8092a206aa998558ac5ec13c4483e31e160\", \"price_changes\":[{\"asset_id\":\"110216635572655435074987471276357323571387854733835379371586402147734167783946\", \"price\":\"0.42\", \"size\":\"114.38\", \"side\":\"BUY\", \"hash\":\"1aa1deeb21662fa8f21f758bb21caf0f473da664\", \"best_bid\":\"0.46\", \"best_ask\":\"0.47\"}, {\"asset_id\":\"14766054693214075530629349735273995982307625376442606753688071083149620216746\", \"price\":\"0.58\", \"size\":\"114.38\", \"side\":\"SELL\", \"hash\":\"c1aba65fda68b6be099d58980cd85c19d3325622\", \"best_bid\":\"0.53\", \"best_ask\":\"0.54\"}], \"timestamp\":\"1785130826976\", \"event_type\":\"price_change\"}","received_at":"2026-07-27T05:40:28.966291Z","schema_version":"clob-market-ws.price_change.v1","sequence":null,"server_hash":null,"server_timestamp":"1785130826976","session_id":"502006c5cfcd437296561ea750c9ec8b","source":"clob_market_ws"},"received_at":"2026-07-27T05:40:28.966291Z","record_id":"c98022649bbc5e4453103b5ee2c57e6d528797cb2f1270f5ff7ada4e2f17c471","schema_fingerprint":"4aa3821a28b0b7c2400bc59aba4bcc0a76e971dadd19610d3ad38c768e124dc7","schema_version":"edge-lab-recorder.raw.v1","sequence":null,"source":"clob_market_ws"}
{"event_at":"2026-07-27T05:40:26.977000Z","event_fingerprint":"35dc394d07fb5988398a62f11613e27879f20cc6cb7edbd4d5cc4eb59be46448","payload":{"connection_id":"efc69d3132f1467b8e898a382b23ac0d","event_at":"2026-07-27T05:40:26.977000Z","event_type":"price_change","frame_hash":"34fe454f21b7b36d3908191a3b7bb49010f9242a8b33479ba8672a7cac7b764c","frame_index":0,"kind":"data","monotonic_ns":232812205454166,"payload":{"event_type":"price_change","market":"0x3b40066b5cf3871a2f6237c5628bd8092a206aa998558ac5ec13c4483e31e160","price_changes":[{"asset_id":"110216635572655435074987471276357323571387854733835379371586402147734167783946","best_ask":"0.47","best_bid":"0.46","hash":"cd8c9d3dcaaa98c830e6a5a714afe27fb7916556","price":"0.23","side":"BUY","size":"513.62"},{"asset_id":"14766054693214075530629349735273995982307625376442606753688071083149620216746","best_ask":"0.54","best_bid":"0.53","hash":"8688cc29c14b2e2d9cbffcd168ad74a4861c71ec","price":"0.77","side":"SELL","size":"513.62"}],"timestamp":"1785130826977"},"payload_hash":"4de5604d7f4627eba7154943456c34bbb1c1d5b8d3375733b530ecbe490be130","raw_frame":"{\"market\":\"0x3b40066b5cf3871a2f6237c5628bd8092a206aa998558ac5ec13c4483e31e160\", \"price_changes\":[{\"asset_id\":\"110216635572655435074987471276357323571387854733835379371586402147734167783946\", \"price\":\"0.23\", \"size\":\"513.62\", \"side\":\"BUY\", \"hash\":\"cd8c9d3dcaaa98c830e6a5a714afe27fb7916556\", \"best_bid\":\"0.46\", \"best_ask\":\"0.47\"}, {\"asset_id\":\"14766054693214075530629349735273995982307625376442606753688071083149620216746\", \"price\":\"0.77\", \"size\":\"513.62\", \"side\":\"SELL\", \"hash\":\"8688cc29c14b2e2d9cbffcd168ad74a4861c71ec\", \"best_bid\":\"0.53\", \"best_ask\":\"0.54\"}], \"timestamp\":\"1785130826977\", \"event_type\":\"price_change\"}","received_at":"2026-07-27T05:40:28.971615Z","schema_version":"clob-market-ws.price_change.v1","sequence":null,"server_hash":null,"server_timestamp":"1785130826977","session_id":"502006c5cfcd437296561ea750c9ec8b","source":"clob_market_ws"},"received_at":"2026-07-27T05:40:28.971615Z","record_id":"28ad8fb1edb336938d3a73814de5a17d1b25d73f47a761c5a97ed262e544c545","schema_fingerprint":"4aa3821a28b0b7c2400bc59aba4bcc0a76e971dadd19610d3ad38c768e124dc7","schema_version":"edge-lab-recorder.raw.v1","sequence":null,"source":"clob_market_ws"}
{"event_at":"2026-07-27T05:40:26.978000Z","event_fingerprint":"efc14dae8610af2abed72329e294f9458563447da136264f47d88f7cb24a610e","payload":{"connection_id":"efc69d3132f1467b8e898a382b23ac0d","event_at":"2026-07-27T05:40:26.978000Z","event_type":"price_change","frame_hash":"539c94217285fcebeb9ed535574b79b1864a3ffd6b7c9f4302b13f624373d8c8","frame_index":0,"kind":"data","monotonic_ns":232812210227083,"payload":{"event_type":"price_change","market":"0x3b40066b5cf3871a2f6237c5628bd8092a206aa998558ac5ec13c4483e31e160","price_changes":[{"asset_id":"110216635572655435074987471276357323571387854733835379371586402147734167783946","best_ask":"0.47","best_bid":"0.46","hash":"b65c1ffadd55651764803417409f977f7ff96e7b","price":"0.39","side":"BUY","size":"94.61"},{"asset_id":"14766054693214075530629349735273995982307625376442606753688071083149620216746","best_ask":"0.54","best_bid":"0.53","hash":"2ec2b638c01dbc8a0d5a7d5467887dba8eee0c08","price":"0.61","side":"SELL","size":"94.61"}],"timestamp":"1785130826978"},"payload_hash":"f0a7d5cc54b35434a37b38be5a2595740ea56c2ff48d6534630469344502bc06","raw_frame":"{\"market\":\"0x3b40066b5cf3871a2f6237c5628bd8092a206aa998558ac5ec13c4483e31e160\", \"price_changes\":[{\"asset_id\":\"110216635572655435074987471276357323571387854733835379371586402147734167783946\", \"price\":\"0.39\", \"size\":\"94.61\", \"side\":\"BUY\", \"hash\":\"b65c1ffadd55651764803417409f977f7ff96e7b\", \"best_bid\":\"0.46\", \"best_ask\":\"0.47\"}, {\"asset_id\":\"14766054693214075530629349735273995982307625376442606753688071083149620216746\", \"price\":\"0.61\", \"size\":\"94.61\", \"side\":\"SELL\", \"hash\":\"2ec2b638c01dbc8a0d5a7d5467887dba8eee0c08\", \"best_bid\":\"0.53\", \"best_ask\":\"0.54\"}], \"timestamp\":\"1785130826978\", \"event_type\":\"price_change\"}","received_at":"2026-07-27T05:40:28.976389Z","schema_version":"clob-market-ws.price_change.v1","sequence":null,"server_hash":null,"server_timestamp":"1785130826978","session_id":"502006c5cfcd437296561ea750c9ec8b","source":"clob_market_ws"},"received_at":"2026-07-27T05:40:28.976389Z","record_id":"0f6d1479d6246ac7991e2686d322ad8bf5663226800b02c4dcbc08757014062f","schema_fingerprint":"4aa3821a28b0b7c2400bc59aba4bcc0a76e971dadd19610d3ad38c768e124dc7","schema_version":"edge-lab-recorder.raw.v1","sequence":null,"source":"clob_market_ws"}
{"event_at":"2026-07-27T05:40:26.979000Z","event_fingerprint":"d61e77a5b7058244405f8f5192ae8368be3a17240470d685315790c85bbddf9c","payload":{"connection_id":"efc69d3132f1467b8e898a382b23ac0d","event_at":"2026-07-27T05:40:26.979000Z","event_type":"price_change","frame_hash":"a22628c73d918b474ef8738897776b4431aeacc4758687faafd22e5454586433","frame_index":0,"kind":"data","monotonic_ns":232812215696041,"payload":{"event_type":"price_change","market":"0x3b40066b5cf3871a2f6237c5628bd8092a206aa998558ac5ec13c4483e31e160","price_changes":[{"asset_id":"110216635572655435074987471276357323571387854733835379371586402147734167783946","best_ask":"0.47","best_bid":"0.46","hash":"d7807cc47707844a81a559042819433bd26e0481","price":"0.43","side":"BUY","size":"31.6"},{"asset_id":"14766054693214075530629349735273995982307625376442606753688071083149620216746","best_ask":"0.54","best_bid":"0.53","hash":"0e060ba7c20237b7c55ae6c219b593f51d94eefd","price":"0.57","side":"SELL","size":"31.6"}],"timestamp":"1785130826979"},"payload_hash":"ef0890d48a61947359eba376d3b304c2e54eb80a7a6562f0912438a85bcbd672","raw_frame":"{\"market\":\"0x3b40066b5cf3871a2f6237c5628bd8092a206aa998558ac5ec13c4483e31e160\", \"price_changes\":[{\"asset_id\":\"110216635572655435074987471276357323571387854733835379371586402147734167783946\", \"price\":\"0.43\", \"size\":\"31.6\", \"side\":\"BUY\", \"hash\":\"d7807cc47707844a81a559042819433bd26e0481\", \"best_bid\":\"0.46\", \"best_ask\":\"0.47\"}, {\"asset_id\":\"14766054693214075530629349735273995982307625376442606753688071083149620216746\", \"price\":\"0.57\", \"size\":\"31.6\", \"side\":\"SELL\", \"hash\":\"0e060ba7c20237b7c55ae6c219b593f51d94eefd\", \"best_bid\":\"0.53\", \"best_ask\":\"0.54\"}], \"timestamp\":\"1785130826979\", \"event_type\":\"price_change\"}","received_at":"2026-07-27T05:40:28.981862Z","schema_version":"clob-market-ws.price_change.v1","sequence":null,"server_hash":null,"server_timestamp":"1785130826979","session_id":"502006c5cfcd437296561ea750c9ec8b","source":"clob_market_ws"},"received_at":"2026-07-27T05:40:28.981862Z","record_id":"f50c4bebcc51ed1d3c300a52677c9dade10a881327a94368259d418516472c8d","schema_fingerprint":"4aa3821a28b0b7c2400bc59aba4bcc0a76e971dadd19610d3ad38c768e124dc7","schema_version":"edge-lab-recorder.raw.v1","sequence":null,"source":"clob_market_ws"}
{"event_at":"2026-07-27T05:40:26.980000Z","event_fingerprint":"b86dd25fd7336caa3fcd2e0c2434215e3e89fe2264a05a0c3cb086998260aed5","payload":{"connection_id":"efc69d3132f1467b8e898a382b23ac0d","event_at":"2026-07-27T05:40:26.980000Z","event_type":"price_change","frame_hash":"9e1a758caac0a1a8a998db54c4d223d1a3b1e0155df19b28cb9bcaf0dba0e2e8","frame_index":0,"kind":"data","monotonic_ns":232812221480166,"payload":{"event_type":"price_change","market":"0x3b40066b5cf3871a2f6237c5628bd8092a206aa998558ac5ec13c4483e31e160","price_changes":[{"asset_id":"14766054693214075530629349735273995982307625376442606753688071083149620216746","best_ask":"0.54","best_bid":"0.53","hash":"d7bf3f26d717653b6e1e28e6db7ec70029182366","price":"0.53","side":"BUY","size":"33.42"},{"asset_id":"110216635572655435074987471276357323571387854733835379371586402147734167783946","best_ask":"0.47","best_bid":"0.46","hash":"2541d43201cde453e08694552e8ef7d4d160be42","price":"0.47","side":"SELL","size":"33.42"}],"timestamp":"1785130826980"},"payload_hash":"934f45778ad6d29325b522d4e087e1f163bda04f179263250e959fbb809d1aca","raw_frame":"{\"market\":\"0x3b40066b5cf3871a2f6237c5628bd8092a206aa998558ac5ec13c4483e31e160\", \"price_changes\":[{\"asset_id\":\"14766054693214075530629349735273995982307625376442606753688071083149620216746\", \"price\":\"0.53\", \"size\":\"33.42\", \"side\":\"BUY\", \"hash\":\"d7bf3f26d717653b6e1e28e6db7ec70029182366\", \"best_bid\":\"0.53\", \"best_ask\":\"0.54\"}, {\"asset_id\":\"110216635572655435074987471276357323571387854733835379371586402147734167783946\", \"price\":\"0.47\", \"size\":\"33.42\", \"side\":\"SELL\", \"hash\":\"2541d43201cde453e08694552e8ef7d4d160be42\", \"best_bid\":\"0.46\", \"best_ask\":\"0.47\"}], \"timestamp\":\"1785130826980\", \"event_type\":\"price_change\"}","received_at":"2026-07-27T05:40:28.987642Z","schema_version":"clob-market-ws.price_change.v1","sequence":null,"server_hash":null,"server_timestamp":"1785130826980","session_id":"502006c5cfcd437296561ea750c9ec8b","source":"clob_market_ws"},"received_at":"2026-07-27T05:40:28.987642Z","record_id":"4c72d55f7c36a0e2c6e1c2a897b518befbb97bfbe57cf4961a4e8eaa8a24739a","schema_fingerprint":"4aa3821a28b0b7c2400bc59aba4bcc0a76e971dadd19610d3ad38c768e124dc7","schema_version":"edge-lab-recorder.raw.v1","sequence":null,"source":"clob_market_ws"}
{"event_at":"2026-07-27T05:40:26.980000Z","event_fingerprint":"8c9431662fe2f364065b1d373d77facb6df7d89e8ff2093fcc9b8b71ee5b28e3","payload":{"connection_id":"efc69d3132f1467b8e898a382b23ac0d","event_at":"2026-07-27T05:40:26.980000Z","event_type":"price_change","frame_hash":"fd28c13c427c37304784cb3fd58e930e056282dc027f9bdd0f574485bc9ee67e","frame_index":0,"kind":"data","monotonic_ns":232812229753541,"payload":{"event_type":"price_change","market":"0x3b40066b5cf3871a2f6237c5628bd8092a206aa998558ac5ec13c4483e31e160","price_changes":[{"asset_id":"14766054693214075530629349735273995982307625376442606753688071083149620216746","best_ask":"0.54","best_bid":"0.53","hash":"0db5b868d139c6fe2a4e7636a7be97fb2d41ed4e","price":"0.53","side":"BUY","size":"43.02"},{"asset_id":"110216635572655435074987471276357323571387854733835379371586402147734167783946","best_ask":"0.47","best_bid":"0.46","hash":"b62688ef1a4bda0a9a280bb69216e8328c3abd13","price":"0.47","side":"SELL","size":"43.02"}],"timestamp":"1785130826980"},"payload_hash":"46b9db50aed662ea33ce23d17b6733aa6e5fb19fb3f154e1d37bec8db88779d7","raw_frame":"{\"market\":\"0x3b40066b5cf3871a2f6237c5628bd8092a206aa998558ac5ec13c4483e31e160\", \"price_changes\":[{\"asset_id\":\"14766054693214075530629349735273995982307625376442606753688071083149620216746\", \"price\":\"0.53\", \"size\":\"43.02\", \"side\":\"BUY\", \"hash\":\"0db5b868d139c6fe2a4e7636a7be97fb2d41ed4e\", \"best_bid\":\"0.53\", \"best_ask\":\"0.54\"}, {\"asset_id\":\"110216635572655435074987471276357323571387854733835379371586402147734167783946\", \"price\":\"0.47\", \"size\":\"43.02\", \"side\":\"SELL\", \"hash\":\"b62688ef1a4bda0a9a280bb69216e8328c3abd13\", \"best_bid\":\"0.46\", \"best_ask\":\"0.47\"}], \"timestamp\":\"1785130826980\", \"event_type\":\"price_change\"}","received_at":"2026-07-27T05:40:28.995914Z","schema_version":"clob-market-ws.price_change.v1","sequence":null,"server_hash":null,"server_timestamp":"1785130826980","session_id":"502006c5cfcd437296561ea750c9ec8b","source":"clob_market_ws"},"received_at":"2026-07-27T05:40:28.995914Z","record_id":"60890322322fd219b68b2b0955aee7915274dafb08bdf67ce47f02d725655d19","schema_fingerprint":"4aa3821a28b0b7c2400bc59aba4bcc0a76e971dadd19610d3ad38c768e124dc7","schema_version":"edge-lab-recorder.raw.v1","sequence":null,"source":"clob_market_ws"}
{"event_at":"2026-07-27T05:40:26.981000Z","event_fingerprint":"810ed7becd4821db6d687dcdd419eeb5bba60f5e4300899bd9a964a629127ddd","payload":{"connection_id":"efc69d3132f1467b8e898a382b23ac0d","event_at":"2026-07-27T05:40:26.981000Z","event_type":"price_change","frame_hash":"07ebeac16259b2ce30bad281376a5a57465527222d315de262ecb4947c3f056f","frame_index":0,"kind":"data","monotonic_ns":232812234401833,"payload":{"event_type":"price_change","market":"0x3b40066b5cf3871a2f6237c5628bd8092a206aa998558ac5ec13c4483e31e160","price_changes":[{"asset_id":"14766054693214075530629349735273995982307625376442606753688071083149620216746","best_ask":"0.54","best_bid":"0.53","hash":"998077c8721b2c24fdb81639fc3f3559b71ce1df","price":"0.53","side":"BUY","size":"23.02"},{"asset_id":"110216635572655435074987471276357323571387854733835379371586402147734167783946","best_ask":"0.47","best_bid":"0.46","hash":"6b732d913c2ebdf10b80fd2debf5b3e140373490","price":"0.47","side":"SELL","size":"23.02"}],"timestamp":"1785130826981"},"payload_hash":"cb488a420854198e17a851000f5a4ca36df5e6f37b18c0318add560ffcc2f0e1","raw_frame":"{\"market\":\"0x3b40066b5cf3871a2f6237c5628bd8092a206aa998558ac5ec13c4483e31e160\", \"price_changes\":[{\"asset_id\":\"14766054693214075530629349735273995982307625376442606753688071083149620216746\", \"price\":\"0.53\", \"size\":\"23.02\", \"side\":\"BUY\", \"hash\":\"998077c8721b2c24fdb81639fc3f3559b71ce1df\", \"best_bid\":\"0.53\", \"best_ask\":\"0.54\"}, {\"asset_id\":\"110216635572655435074987471276357323571387854733835379371586402147734167783946\", \"price\":\"0.47\", \"size\":\"23.02\", \"side\":\"SELL\", \"hash\":\"6b732d913c2ebdf10b80fd2debf5b3e140373490\", \"best_bid\":\"0.46\", \"best_ask\":\"0.47\"}], \"timestamp\":\"1785130826981\", \"event_type\":\"price_change\"}","received_at":"2026-07-27T05:40:29.000563Z","schema_version":"clob-market-ws.price_change.v1","sequence":null,"server_hash":null,"server_timestamp":"1785130826981","session_id":"502006c5cfcd437296561ea750c9ec8b","source":"clob_market_ws"},"received_at":"2026-07-27T05:40:29.000563Z","record_id":"d0581b58c0a9ce80b9ffb512bc7d73cd5e158e8820936af4a3ce514944146af3","schema_fingerprint":"4aa3821a28b0b7c2400bc59aba4bcc0a76e971dadd19610d3ad38c768e124dc7","schema_version":"edge-lab-recorder.raw.v1","sequence":null,"source":"clob_market_ws"}
{"event_at":"2026-07-27T05:40:26.981000Z","event_fingerprint":"f9ec580f893887148dbf4de09e0b26a05d9656f85ea1c24325038f1b848e667a","payload":{"connection_id":"efc69d3132f1467b8e898a382b23ac0d","event_at":"2026-07-27T05:40:26.981000Z","event_type":"price_change","frame_hash":"5ea220e060cbe1a9728106f7763dbcedd464a023ac1d910affa044ef44e9c51a","frame_index":0,"kind":"data","monotonic_ns":232812238263625,"payload":{"event_type":"price_change","market":"0x3b40066b5cf3871a2f6237c5628bd8092a206aa998558ac5ec13c4483e31e160","price_changes":[{"asset_id":"14766054693214075530629349735273995982307625376442606753688071083149620216746","best_ask":"0.54","best_bid":"0.53","hash":"3d9598af3714e8a79493c87aad903a31dba2565a","price":"0.44","side":"BUY","size":"68"},{"asset_id":"110216635572655435074987471276357323571387854733835379371586402147734167783946","best_ask":"0.47","best_bid":"0.46","hash":"2195b379516d750cd4cbcdd8d83697ea8162e61b","price":"0.56","side":"SELL","size":"68"}],"timestamp":"1785130826981"},"payload_hash":"02fef20f35d66e393ab9b18cbade3ad87712ecb853a6b9e96f6161934afb79ea","raw_frame":"{\"market\":\"0x3b40066b5cf3871a2f6237c5628bd8092a206aa998558ac5ec13c4483e31e160\", \"price_changes\":[{\"asset_id\":\"14766054693214075530629349735273995982307625376442606753688071083149620216746\", \"price\":\"0.44\", \"size\":\"68\", \"side\":\"BUY\", \"hash\":\"3d9598af3714e8a79493c87aad903a31dba2565a\", \"best_bid\":\"0.53\", \"best_ask\":\"0.54\"}, {\"asset_id\":\"110216635572655435074987471276357323571387854733835379371586402147734167783946\", \"price\":\"0.56\", \"size\":\"68\", \"side\":\"SELL\", \"hash\":\"2195b379516d750cd4cbcdd8d83697ea8162e61b\", \"best_bid\":\"0.46\", \"best_ask\":\"0.47\"}], \"timestamp\":\"1785130826981\", \"event_type\":\"price_change\"}","received_at":"2026-07-27T05:40:29.004425Z","schema_version":"clob-market-ws.price_change.v1","sequence":null,"server_hash":null,"server_timestamp":"1785130826981","session_id":"502006c5cfcd437296561ea750c9ec8b","source":"clob_market_ws"},"received_at":"2026-07-27T05:40:29.004425Z","record_id":"d398a6d148eff3ec2f4c368dc9460525ca6791823c9bc4f2e75dce85f0e69dc1","schema_fingerprint":"4aa3821a28b0b7c2400bc59aba4bcc0a76e971dadd19610d3ad38c768e124dc7","schema_version":"edge-lab-recorder.raw.v1","sequence":null,"source":"clob_market_ws"}
{"event_at":"2026-07-27T05:40:26.982000Z","event_fingerprint":"8bc7ae5af757fd5a4d5152978948271f46a89e4fa9a9b4d7159e9c9c4f04e8ea","payload":{"connection_id":"efc69d3132f1467b8e898a382b23ac0d","event_at":"2026-07-27T05:40:26.982000Z","event_type":"price_change","frame_hash":"f4940c0a1f8973b5671afd495be4d08943d0a71e6bf708fde12ef8344b937256","frame_index":0,"kind":"data","monotonic_ns":232812245201750,"payload":{"event_type":"price_change","market":"0x3b40066b5cf3871a2f6237c5628bd8092a206aa998558ac5ec13c4483e31e160","price_changes":[{"asset_id":"110216635572655435074987471276357323571387854733835379371586402147734167783946","best_ask":"0.47","best_bid":"0.46","hash":"850314d9a33ddf5f9b02825a577d6ec44db2631d","price":"0.47","side":"SELL","size":"14.6"},{"asset_id":"14766054693214075530629349735273995982307625376442606753688071083149620216746","best_ask":"0.54","best_bid":"0.53","hash":"9f3bd1e81b35265665f7221470479d7e8c606ed8","price":"0.53","side":"BUY","size":"14.6"}],"timestamp":"1785130826982"},"payload_hash":"948bf39c999b8e6a74f494eff1c01eea127c1c0c6efef2e4a588bab66594d2fd","raw_frame":"{\"market\":\"0x3b40066b5cf3871a2f6237c5628bd8092a206aa998558ac5ec13c4483e31e160\", \"price_changes\":[{\"asset_id\":\"110216635572655435074987471276357323571387854733835379371586402147734167783946\", \"price\":\"0.47\", \"size\":\"14.6\", \"side\":\"SELL\", \"hash\":\"850314d9a33ddf5f9b02825a577d6ec44db2631d\", \"best_bid\":\"0.46\", \"best_ask\":\"0.47\"}, {\"asset_id\":\"14766054693214075530629349735273995982307625376442606753688071083149620216746\", \"price\":\"0.53\", \"size\":\"14.6\", \"side\":\"BUY\", \"hash\":\"9f3bd1e81b35265665f7221470479d7e8c606ed8\", \"best_bid\":\"0.53\", \"best_ask\":\"0.54\"}], \"timestamp\":\"1785130826982\", \"event_type\":\"price_change\"}","received_at":"2026-07-27T05:40:29.011363Z","schema_version":"clob-market-ws.price_change.v1","sequence":null,"server_hash":null,"server_timestamp":"1785130826982","session_id":"502006c5cfcd437296561ea750c9ec8b","source":"clob_market_ws"},"received_at":"2026-07-27T05:40:29.011363Z","record_id":"3727beead01fd6d5d4bb23f7c9e9efaece0b8976f08352025e485f297f1c9c42","schema_fingerprint":"4aa3821a28b0b7c2400bc59aba4bcc0a76e971dadd19610d3ad38c768e124dc7","schema_version":"edge-lab-recorder.raw.v1","sequence":null,"source":"clob_market_ws"}
{"event_at":"2026-07-27T05:40:26.982000Z","event_fingerprint":"9cc2485c3679fc95e86eaabb6e6eadc3050e57c9a996c3f6a4dcd35d58a618db","payload":{"connection_id":"efc69d3132f1467b8e898a382b23ac0d","event_at":"2026-07-27T05:40:26.982000Z","event_type":"price_change","frame_hash":"09434f0a84241acfb4a915c5ba9d33fcfe9f0dee9db379ba07e3721a3a08864d","frame_index":0,"kind":"data","monotonic_ns":232812249498333,"payload":{"event_type":"price_change","market":"0x3b40066b5cf3871a2f6237c5628bd8092a206aa998558ac5ec13c4483e31e160","price_changes":[{"asset_id":"14766054693214075530629349735273995982307625376442606753688071083149620216746","best_ask":"0.54","best_bid":"0.53","hash":"0d7d861bfc8b3477fba281c154317b97407018de","price":"0.49","side":"BUY","size":"35"},{"asset_id":"110216635572655435074987471276357323571387854733835379371586402147734167783946","best_ask":"0.47","best_bid":"0.46","hash":"79924b45d4c1951b5091eefed9f62f79b50d478d","price":"0.51","side":"SELL","size":"35"}],"timestamp":"1785130826982"},"payload_hash":"40eb4c83794078b4079931529db152bfc39eee2b5794d9b0a59db21566b07482","raw_frame":"{\"market\":\"0x3b40066b5cf3871a2f6237c5628bd8092a206aa998558ac5ec13c4483e31e160\", \"price_changes\":[{\"asset_id\":\"14766054693214075530629349735273995982307625376442606753688071083149620216746\", \"price\":\"0.49\", \"size\":\"35\", \"side\":\"BUY\", \"hash\":\"0d7d861bfc8b3477fba281c154317b97407018de\", \"best_bid\":\"0.53\", \"best_ask\":\"0.54\"}, {\"asset_id\":\"110216635572655435074987471276357323571387854733835379371586402147734167783946\", \"price\":\"0.51\", \"size\":\"35\", \"side\":\"SELL\", \"hash\":\"79924b45d4c1951b5091eefed9f62f79b50d478d\", \"best_bid\":\"0.46\", \"best_ask\":\"0.47\"}], \"timestamp\":\"1785130826982\", \"event_type\":\"price_change\"}","received_at":"2026-07-27T05:40:29.015659Z","schema_version":"clob-market-ws.price_change.v1","sequence":null,"server_hash":null,"server_timestamp":"1785130826982","session_id":"502006c5cfcd437296561ea750c9ec8b","source":"clob_market_ws"},"received_at":"2026-07-27T05:40:29.015659Z","record_id":"11642b07796ac6a65a2d4e29f078b4fa1f5443e18f973f974dd2c35037edac08","schema_fingerprint":"4aa3821a28b0b7c2400bc59aba4bcc0a76e971dadd19610d3ad38c768e124dc7","schema_version":"edge-lab-recorder.raw.v1","sequence":null,"source":"clob_market_ws"}
{"event_at":"2026-07-27T05:40:26.982000Z","event_fingerprint":"734bb816714c592b6b7473e7c4291250d52b3f7d4c982a2a32b32324b1e47ee0","payload":{"connection_id":"efc69d3132f1467b8e898a382b23ac0d","event_at":"2026-07-27T05:40:26.982000Z","event_type":"price_change","frame_hash":"f6f77d19958341b6867c31255ef28526653810928ff832e866b447b5f2341205","frame_index":0,"kind":"data","monotonic_ns":232812256496541,"payload":{"event_type":"price_change","market":"0x3b40066b5cf3871a2f6237c5628bd8092a206aa998558ac5ec13c4483e31e160","price_changes":[{"asset_id":"14766054693214075530629349735273995982307625376442606753688071083149620216746","best_ask":"0.54","best_bid":"0.53","hash":"5b118fecaa2dc76e5a00a9ef1af49788cd66bb87","price":"0.48","side":"BUY","size":"26"},{"asset_id":"110216635572655435074987471276357323571387854733835379371586402147734167783946","best_ask":"0.47","best_bid":"0.46","hash":"7ee5be4fefa4e9a014c1f0283ab16aceb03c5cf7","price":"0.52","side":"SELL","size":"26"}],"timestamp":"1785130826982"},"payload_hash":"aa9eac6febeaae3416a2acf5ed710cfc7ee3d1c7a160d229a3fd848917bf57c8","raw_frame":"{\"market\":\"0x3b40066b5cf3871a2f6237c5628bd8092a206aa998558ac5ec13c4483e31e160\", \"price_changes\":[{\"asset_id\":\"14766054693214075530629349735273995982307625376442606753688071083149620216746\", \"price\":\"0.48\", \"size\":\"26\", \"side\":\"BUY\", \"hash\":\"5b118fecaa2dc76e5a00a9ef1af49788cd66bb87\", \"best_bid\":\"0.53\", \"best_ask\":\"0.54\"}, {\"asset_id\":\"110216635572655435074987471276357323571387854733835379371586402147734167783946\", \"price\":\"0.52\", \"size\":\"26\", \"side\":\"SELL\", \"hash\":\"7ee5be4fefa4e9a014c1f0283ab16aceb03c5cf7\", \"best_bid\":\"0.46\", \"best_ask\":\"0.47\"}], \"timestamp\":\"1785130826982\", \"event_type\":\"price_change\"}","received_at":"2026-07-27T05:40:29.022659Z","schema_version":"clob-market-ws.price_change.v1","sequence":null,"server_hash":null,"server_timestamp":"1785130826982","session_id":"502006c5cfcd437296561ea750c9ec8b","source":"clob_market_ws"},"received_at":"2026-07-27T05:40:29.022659Z","record_id":"48f2b83c1f8af9ccd573e49925b3db7d75e3e8963ed1cd96edf78ac614118619","schema_fingerprint":"4aa3821a28b0b7c2400bc59aba4bcc0a76e971dadd19610d3ad38c768e124dc7","schema_version":"edge-lab-recorder.raw.v1","sequence":null,"source":"clob_market_ws"}
{"event_at":"2026-07-27T05:40:26.984000Z","event_fingerprint":"229af15dbfe6f11fbd6a2d61047e7b55cda89b7219a0654bb56fb5df96f4ad94","payload":{"connection_id":"efc69d3132f1467b8e898a382b23ac0d","event_at":"2026-07-27T05:40:26.984000Z","event_type":"price_change","frame_hash":"b100ccd8a76f2798776ba100f49d4771e77becc8085bd9486f63572c09e99216","frame_index":0,"kind":"data","monotonic_ns":232812261859541,"payload":{"event_type":"price_change","market":"0x3b40066b5cf3871a2f6237c5628bd8092a206aa998558ac5ec13c4483e31e160","price_changes":[{"asset_id":"110216635572655435074987471276357323571387854733835379371586402147734167783946","best_ask":"0.47","best_bid":"0.46","hash":"749cbb3b3a793284fae9a4f854b0ecb747c5a1e6","price":"0.4","side":"BUY","size":"47.5"},{"asset_id":"14766054693214075530629349735273995982307625376442606753688071083149620216746","best_ask":"0.54","best_bid":"0.53","hash":"122f30b080bd050df7bab2f280fdeb6b30ad8490","price":"0.6","side":"SELL","size":"47.5"}],"timestamp":"1785130826984"},"payload_hash":"638b7037a72b1605ec5d92342b4e78f4258cdcb99f2901bf06bbaa4d08559586","raw_frame":"{\"market\":\"0x3b40066b5cf3871a2f6237c5628bd8092a206aa998558ac5ec13c4483e31e160\", \"price_changes\":[{\"asset_id\":\"110216635572655435074987471276357323571387854733835379371586402147734167783946\", \"price\":\"0.4\", \"size\":\"47.5\", \"side\":\"BUY\", \"hash\":\"749cbb3b3a793284fae9a4f854b0ecb747c5a1e6\", \"best_bid\":\"0.46\", \"best_ask\":\"0.47\"}, {\"asset_id\":\"14766054693214075530629349735273995982307625376442606753688071083149620216746\", \"price\":\"0.6\", \"size\":\"47.5\", \"side\":\"SELL\", \"hash\":\"122f30b080bd050df7bab2f280fdeb6b30ad8490\", \"best_bid\":\"0.53\", \"best_ask\":\"0.54\"}], \"timestamp\":\"1785130826984\", \"event_type\":\"price_change\"}","received_at":"2026-07-27T05:40:29.028020Z","schema_version":"clob-market-ws.price_change.v1","sequence":null,"server_hash":null,"server_timestamp":"1785130826984","session_id":"502006c5cfcd437296561ea750c9ec8b","source":"clob_market_ws"},"received_at":"2026-07-27T05:40:29.028020Z","record_id":"628a5949b45c501059d7d68387f916427cf7a9e1e5df9bcf017d6b5efbdd6cee","schema_fingerprint":"4aa3821a28b0b7c2400bc59aba4bcc0a76e971dadd19610d3ad38c768e124dc7","schema_version":"edge-lab-recorder.raw.v1","sequence":null,"source":"clob_market_ws"}
{"event_at":"2026-07-27T05:40:26.984000Z","event_fingerprint":"07dd65fc263a8e4c67b8d357096a8d1aa020d62c618b7ec87cd9b98f591a633c","payload":{"connection_id":"efc69d3132f1467b8e898a382b23ac0d","event_at":"2026-07-27T05:40:26.984000Z","event_type":"price_change","frame_hash":"2bfe0e22e081df874c5c15876feeeda190517ee27ff0c391b918880b870b7c7d","frame_index":0,"kind":"data","monotonic_ns":232812265503666,"payload":{"event_type":"price_change","market":"0x3b40066b5cf3871a2f6237c5628bd8092a206aa998558ac5ec13c4483e31e160","price_changes":[{"asset_id":"14766054693214075530629349735273995982307625376442606753688071083149620216746","best_ask":"0.54","best_bid":"0.53","hash":"75cf69c0d98af82f7b7cefd2c9ca2ecf6cb4c677","price":"0.4","side":"BUY","size":"133.5"},{"asset_id":"110216635572655435074987471276357323571387854733835379371586402147734167783946","best_ask":"0.47","best_bid":"0.46","hash":"f8f8113bdd47f33f472a222b9e24140ef58b37be","price":"0.6","side":"SELL","size":"133.5"}],"timestamp":"1785130826984"},"payload_hash":"26063528075ff88f5c202120ddc79abe55fe06d949b9fb86f35b4e1b46d8fc83","raw_frame":"{\"market\":\"0x3b40066b5cf3871a2f6237c5628bd8092a206aa998558ac5ec13c4483e31e160\", \"price_changes\":[{\"asset_id\":\"14766054693214075530629349735273995982307625376442606753688071083149620216746\", \"price\":\"0.4\", \"size\":\"133.5\", \"side\":\"BUY\", \"hash\":\"75cf69c0d98af82f7b7cefd2c9ca2ecf6cb4c677\", \"best_bid\":\"0.53\", \"best_ask\":\"0.54\"}, {\"asset_id\":\"110216635572655435074987471276357323571387854733835379371586402147734167783946\", \"price\":\"0.6\", \"size\":\"133.5\", \"side\":\"SELL\", \"hash\":\"f8f8113bdd47f33f472a222b9e24140ef58b37be\", \"best_bid\":\"0.46\", \"best_ask\":\"0.47\"}], \"timestamp\":\"1785130826984\", \"event_type\":\"price_change\"}","received_at":"2026-07-27T05:40:29.031671Z","schema_version":"clob-market-ws.price_change.v1","sequence":null,"server_hash":null,"server_timestamp":"1785130826984","session_id":"502006c5cfcd437296561ea750c9ec8b","source":"clob_market_ws"},"received_at":"2026-07-27T05:40:29.031671Z","record_id":"0216b194130be3ba5d2f9a93b927a82cb17727e6939220eb03ba4df68404c90b","schema_fingerprint":"4aa3821a28b0b7c2400bc59aba4bcc0a76e971dadd19610d3ad38c768e124dc7","schema_version":"edge-lab-recorder.raw.v1","sequence":null,"source":"clob_market_ws"}
{"event_at":"2026-07-27T05:40:26.985000Z","event_fingerprint":"cd19c8a9c4735489a7519dc6c845473b22b4966ec647173291e33c555000cadd","payload":{"connection_id":"efc69d3132f1467b8e898a382b23ac0d","event_at":"2026-07-27T05:40:26.985000Z","event_type":"price_change","frame_hash":"73ceaa709540b0c5a8d26559a3a945fa1cac874c79242411a9b30c1bdd01ffc0","frame_index":0,"kind":"data","monotonic_ns":232812271106416,"payload":{"event_type":"price_change","market":"0x3b40066b5cf3871a2f6237c5628bd8092a206aa998558ac5ec13c4483e31e160","price_changes":[{"asset_id":"14766054693214075530629349735273995982307625376442606753688071083149620216746","best_ask":"0.54","best_bid":"0.53","hash":"60a83aa31234cd274fe8d59679575aa5c4c10fbb","price":"0.32","side":"BUY","size":"365.28"},{"asset_id":"110216635572655435074987471276357323571387854733835379371586402147734167783946","best_ask":"0.47","best_bid":"0.46","hash":"4547e777745fdbde95dedfc6ba733f1260cdf4f0","price":"0.68","side":"SELL","size":"365.28"}],"timestamp":"1785130826985"},"payload_hash":"f9835c917b9d268531642df694eaa52be8267a9e421801ddb8111948c0039e4c","raw_frame":"{\"market\":\"0x3b40066b5cf3871a2f6237c5628bd8092a206aa998558ac5ec13c4483e31e160\", \"price_changes\":[{\"asset_id\":\"14766054693214075530629349735273995982307625376442606753688071083149620216746\", \"price\":\"0.32\", \"size\":\"365.28\", \"side\":\"BUY\", \"hash\":\"60a83aa31234cd274fe8d59679575aa5c4c10fbb\", \"best_bid\":\"0.53\", \"best_ask\":\"0.54\"}, {\"asset_id\":\"110216635572655435074987471276357323571387854733835379371586402147734167783946\", \"price\":\"0.68\", \"size\":\"365.28\", \"side\":\"SELL\", \"hash\":\"4547e777745fdbde95dedfc6ba733f1260cdf4f0\", \"best_bid\":\"0.46\", \"best_ask\":\"0.47\"}], \"timestamp\":\"1785130826985\", \"event_type\":\"price_change\"}","received_at":"2026-07-27T05:40:29.037260Z","schema_version":"clob-market-ws.price_change.v1","sequence":null,"server_hash":null,"server_timestamp":"1785130826985","session_id":"502006c5cfcd437296561ea750c9ec8b","source":"clob_market_ws"},"received_at":"2026-07-27T05:40:29.037260Z","record_id":"931eb48f0fc2cf3a7f01802d9a20dcb4ebf1dfe74934a28f31b97c434c77339e","schema_fingerprint":"4aa3821a28b0b7c2400bc59aba4bcc0a76e971dadd19610d3ad38c768e124dc7","schema_version":"edge-lab-recorder.raw.v1","sequence":null,"source":"clob_market_ws"}
{"event_at":"2026-07-27T05:40:26.985000Z","event_fingerprint":"45db9ded4a488b1ae79d9814be99550dc1e0479ed5ce1fc414ba028b36941663","payload":{"connection_id":"efc69d3132f1467b8e898a382b23ac0d","event_at":"2026-07-27T05:40:26.985000Z","event_type":"price_change","frame_hash":"0012cae56b9f3fc650b7dd74a877bd76ce7c51eb29e6617f7ed7f754bbf4a77f","frame_index":0,"kind":"data","monotonic_ns":232812277682458,"payload":{"event_type":"price_change","market":"0x3b40066b5cf3871a2f6237c5628bd8092a206aa998558ac5ec13c4483e31e160","price_changes":[{"asset_id":"14766054693214075530629349735273995982307625376442606753688071083149620216746","best_ask":"0.54","best_bid":"0.53","hash":"e9d6ba4485817f509becf809abf52edec2d8853b","price":"0.5","side":"BUY","size":"36"},{"asset_id":"110216635572655435074987471276357323571387854733835379371586402147734167783946","best_ask":"0.47","best_bid":"0.46","hash":"250faa880c8868881c023f0312bf3d4cf774e615","price":"0.5","side":"SELL","size":"36"}],"timestamp":"1785130826985"},"payload_hash":"61771937b1b3c6eb50494518b5148face3012db859d1b0d632d370f884531a8c","raw_frame":"{\"market\":\"0x3b40066b5cf3871a2f6237c5628bd8092a206aa998558ac5ec13c4483e31e160\", \"price_changes\":[{\"asset_id\":\"14766054693214075530629349735273995982307625376442606753688071083149620216746\", \"price\":\"0.5\", \"size\":\"36\", \"side\":\"BUY\", \"hash\":\"e9d6ba4485817f509becf809abf52edec2d8853b\", \"best_bid\":\"0.53\", \"best_ask\":\"0.54\"}, {\"asset_id\":\"110216635572655435074987471276357323571387854733835379371586402147734167783946\", \"price\":\"0.5\", \"size\":\"36\", \"side\":\"SELL\", \"hash\":\"250faa880c8868881c023f0312bf3d4cf774e615\", \"best_bid\":\"0.46\", \"best_ask\":\"0.47\"}], \"timestamp\":\"1785130826985\", \"event_type\":\"price_change\"}","received_at":"2026-07-27T05:40:29.043833Z","schema_version":"clob-market-ws.price_change.v1","sequence":null,"server_hash":null,"server_timestamp":"1785130826985","session_id":"502006c5cfcd437296561ea750c9ec8b","source":"clob_market_ws"},"received_at":"2026-07-27T05:40:29.043833Z","record_id":"cda3d1ece10319458646eab17c909db9bbd12b64e51128dd07d3b59abd0daf12","schema_fingerprint":"4aa3821a28b0b7c2400bc59aba4bcc0a76e971dadd19610d3ad38c768e124dc7","schema_version":"edge-lab-recorder.raw.v1","sequence":null,"source":"clob_market_ws"}
{"event_at":"2026-07-27T05:40:26.986000Z","event_fingerprint":"b4f672d2a14871587eb95f9c676dc75c70c7d5ab18f6bd7447a997cf991e90f6","payload":{"connection_id":"efc69d3132f1467b8e898a382b23ac0d","event_at":"2026-07-27T05:40:26.986000Z","event_type":"price_change","frame_hash":"cb0aae33e15007f0418c98015f64919b51e954f8f460dcbe97e76f477ae70454","frame_index":0,"kind":"data","monotonic_ns":232812283547416,"payload":{"event_type":"price_change","market":"0x3b40066b5cf3871a2f6237c5628bd8092a206aa998558ac5ec13c4483e31e160","price_changes":[{"asset_id":"14766054693214075530629349735273995982307625376442606753688071083149620216746","best_ask":"0.54","best_bid":"0.53","hash":"ec9d8205ebe56a9be4c12b526dcaea2612edf127","price":"0.52","side":"BUY","size":"31"},{"asset_id":"110216635572655435074987471276357323571387854733835379371586402147734167783946","best_ask":"0.47","best_bid":"0.46","hash":"55e265cab68da0b617e5beeb51436b156e444456","price":"0.48","side":"SELL","size":"31"}],"timestamp":"1785130826986"},"payload_hash":"d38e2999b4c7b925fa0c457baec06c376b0707e008bd88c443d96dfe993936c2","raw_frame":"{\"market\":\"0x3b40066b5cf3871a2f6237c5628bd8092a206aa998558ac5ec13c4483e31e160\", \"price_changes\":[{\"asset_id\":\"14766054693214075530629349735273995982307625376442606753688071083149620216746\", \"price\":\"0.52\", \"size\":\"31\", \"side\":\"BUY\", \"hash\":\"ec9d8205ebe56a9be4c12b526dcaea2612edf127\", \"best_bid\":\"0.53\", \"best_ask\":\"0.54\"}, {\"asset_id\":\"110216635572655435074987471276357323571387854733835379371586402147734167783946\", \"price\":\"0.48\", \"size\":\"31\", \"side\":\"SELL\", \"hash\":\"55e265cab68da0b617e5beeb51436b156e444456\", \"best_bid\":\"0.46\", \"best_ask\":\"0.47\"}], \"timestamp\":\"1785130826986\", \"event_type\":\"price_change\"}","received_at":"2026-07-27T05:40:29.049709Z","schema_version":"clob-market-ws.price_change.v1","sequence":null,"server_hash":null,"server_timestamp":"1785130826986","session_id":"502006c5cfcd437296561ea750c9ec8b","source":"clob_market_ws"},"received_at":"2026-07-27T05:40:29.049709Z","record_id":"2dce6a0855b30df69deefe8c7118fdc8c5231093b3be8e322646e5a08dad5d1b","schema_fingerprint":"4aa3821a28b0b7c2400bc59aba4bcc0a76e971dadd19610d3ad38c768e124dc7","schema_version":"edge-lab-recorder.raw.v1","sequence":null,"source":"clob_market_ws"}
{"event_at":"2026-07-27T05:40:26.987000Z","event_fingerprint":"fc7925ab095970a4722b3c27b0d7ba0fb600aa4b5f9f6d51190627ecdabcc0ac","payload":{"connection_id":"efc69d3132f1467b8e898a382b23ac0d","event_at":"2026-07-27T05:40:26.987000Z","event_type":"price_change","frame_hash":"f5248f8bbb2ade62886cc2c3e66b8003efcb0645f2e60281f09701c9d24bedbf","frame_index":0,"kind":"data","monotonic_ns":232812291241833,"payload":{"event_type":"price_change","market":"0x3b40066b5cf3871a2f6237c5628bd8092a206aa998558ac5ec13c4483e31e160","price_changes":[{"asset_id":"110216635572655435074987471276357323571387854733835379371586402147734167783946","best_ask":"0.47","best_bid":"0.46","hash":"58b434a50379bcae4004e82658dbe113b58e00ec","price":"0.43","side":"BUY","size":"42.6"},{"asset_id":"14766054693214075530629349735273995982307625376442606753688071083149620216746","best_ask":"0.54","best_bid":"0.53","hash":"cc586f98418e127e29f4fe11e378a0d1770f56ca","price":"0.57","side":"SELL","size":"42.6"}],"timestamp":"1785130826987"},"payload_hash":"4fae11e01e7fc2c4db03d4a48efb26f91955c02ec2e0b430c16ed97d83355905","raw_frame":"{\"market\":\"0x3b40066b5cf3871a2f6237c5628bd8092a206aa998558ac5ec13c4483e31e160\", \"price_changes\":[{\"asset_id\":\"110216635572655435074987471276357323571387854733835379371586402147734167783946\", \"price\":\"0.43\", \"size\":\"42.6\", \"side\":\"BUY\", \"hash\":\"58b434a50379bcae4004e82658dbe113b58e00ec\", \"best_bid\":\"0.46\", \"best_ask\":\"0.47\"}, {\"asset_id\":\"14766054693214075530629349735273995982307625376442606753688071083149620216746\", \"price\":\"0.57\", \"size\":\"42.6\", \"side\":\"SELL\", \"hash\":\"cc586f98418e127e29f4fe11e378a0d1770f56ca\", \"best_bid\":\"0.53\", \"best_ask\":\"0.54\"}], \"timestamp\":\"1785130826987\", \"event_type\":\"price_change\"}","received_at":"2026-07-27T05:40:29.057403Z","schema_version":"clob-market-ws.price_change.v1","sequence":null,"server_hash":null,"server_timestamp":"1785130826987","session_id":"502006c5cfcd437296561ea750c9ec8b","source":"clob_market_ws"},"received_at":"2026-07-27T05:40:29.057403Z","record_id":"a526dc0c36406d48a4b0a077be758cd684e6d39a62b00c4bc3e9f23d0a576e66","schema_fingerprint":"4aa3821a28b0b7c2400bc59aba4bcc0a76e971dadd19610d3ad38c768e124dc7","schema_version":"edge-lab-recorder.raw.v1","sequence":null,"source":"clob_market_ws"}
{"event_at":"2026-07-27T05:40:26.988000Z","event_fingerprint":"37dc93d4b1fe947ecb12e99b6c0b83a0b9c500912cefe4b9036992b56f5dfaad","payload":{"connection_id":"efc69d3132f1467b8e898a382b23ac0d","event_at":"2026-07-27T05:40:26.988000Z","event_type":"price_change","frame_hash":"93c616279cffaa385686d052276e0f77b35c27cf1840aa9277cd0233fbee7e53","frame_index":0,"kind":"data","monotonic_ns":232812297569958,"payload":{"event_type":"price_change","market":"0x3b40066b5cf3871a2f6237c5628bd8092a206aa998558ac5ec13c4483e31e160","price_changes":[{"asset_id":"110216635572655435074987471276357323571387854733835379371586402147734167783946","best_ask":"0.47","best_bid":"0.46","hash":"bce252b3696670eb06f4504bb1644c6ec8408f47","price":"0.4","side":"BUY","size":"37.9"},{"asset_id":"14766054693214075530629349735273995982307625376442606753688071083149620216746","best_ask":"0.54","best_bid":"0.53","hash":"2a1fdc6fdd74e72ecf38dffa7f3d76d4f57bf55e","price":"0.6","side":"SELL","size":"37.9"}],"timestamp":"1785130826988"},"payload_hash":"62c968a25fdac87d71b208d090b0ea0025481fcd595b1245e9455c45b652bcaf","raw_frame":"{\"market\":\"0x3b40066b5cf3871a2f6237c5628bd8092a206aa998558ac5ec13c4483e31e160\", \"price_changes\":[{\"asset_id\":\"110216635572655435074987471276357323571387854733835379371586402147734167783946\", \"price\":\"0.4\", \"size\":\"37.9\", \"side\":\"BUY\", \"hash\":\"bce252b3696670eb06f4504bb1644c6ec8408f47\", \"best_bid\":\"0.46\", \"best_ask\":\"0.47\"}, {\"asset_id\":\"14766054693214075530629349735273995982307625376442606753688071083149620216746\", \"price\":\"0.6\", \"size\":\"37.9\", \"side\":\"SELL\", \"hash\":\"2a1fdc6fdd74e72ecf38dffa7f3d76d4f57bf55e\", \"best_bid\":\"0.53\", \"best_ask\":\"0.54\"}], \"timestamp\":\"1785130826988\", \"event_type\":\"price_change\"}","received_at":"2026-07-27T05:40:29.063731Z","schema_version":"clob-market-ws.price_change.v1","sequence":null,"server_hash":null,"server_timestamp":"1785130826988","session_id":"502006c5cfcd437296561ea750c9ec8b","source":"clob_market_ws"},"received_at":"2026-07-27T05:40:29.063731Z","record_id":"89b3efac2a79ad4edb648675791bfb9aca2e6802cb50f9737d52c7ae481bc9f1","schema_fingerprint":"4aa3821a28b0b7c2400bc59aba4bcc0a76e971dadd19610d3ad38c768e124dc7","schema_version":"edge-lab-recorder.raw.v1","sequence":null,"source":"clob_market_ws"}
{"event_at":"2026-07-27T05:40:26.988000Z","event_fingerprint":"72237d115f251d2e97f3d084403a608c2a6bff89546f09df4eedfad9eb83f5f0","payload":{"connection_id":"efc69d3132f1467b8e898a382b23ac0d","event_at":"2026-07-27T05:40:26.988000Z","event_type":"price_change","frame_hash":"605aa6d18c28a50d0fc7f1d460ff934d3edb9804575b636261270fba93a81c13","frame_index":0,"kind":"data","monotonic_ns":232812304073750,"payload":{"event_type":"price_change","market":"0x3b40066b5cf3871a2f6237c5628bd8092a206aa998558ac5ec13c4483e31e160","price_changes":[{"asset_id":"14766054693214075530629349735273995982307625376442606753688071083149620216746","best_ask":"0.54","best_bid":"0.53","hash":"00d1380abea330b4665c6ca4490576836221ff21","price":"0.48","side":"BUY","size":"48"},{"asset_id":"110216635572655435074987471276357323571387854733835379371586402147734167783946","best_ask":"0.47","best_bid":"0.46","hash":"723fb2f314efb6eecf1dbc2c12be61fb9f405fd3","price":"0.52","side":"SELL","size":"48"}],"timestamp":"1785130826988"},"payload_hash":"9a1b60b86a617e51c21622413157ec1ec80243c50e007779e9c3908dc2212b9a","raw_frame":"{\"market\":\"0x3b40066b5cf3871a2f6237c5628bd8092a206aa998558ac5ec13c4483e31e160\", \"price_changes\":[{\"asset_id\":\"14766054693214075530629349735273995982307625376442606753688071083149620216746\", \"price\":\"0.48\", \"size\":\"48\", \"side\":\"BUY\", \"hash\":\"00d1380abea330b4665c6ca4490576836221ff21\", \"best_bid\":\"0.53\", \"best_ask\":\"0.54\"}, {\"asset_id\":\"110216635572655435074987471276357323571387854733835379371586402147734167783946\", \"price\":\"0.52\", \"size\":\"48\", \"side\":\"SELL\", \"hash\":\"723fb2f314efb6eecf1dbc2c12be61fb9f405fd3\", \"best_bid\":\"0.46\", \"best_ask\":\"0.47\"}], \"timestamp\":\"1785130826988\", \"event_type\":\"price_change\"}","received_at":"2026-07-27T05:40:29.070223Z","schema_version":"clob-market-ws.price_change.v1","sequence":null,"server_hash":null,"server_timestamp":"1785130826988","session_id":"502006c5cfcd437296561ea750c9ec8b","source":"clob_market_ws"},"received_at":"2026-07-27T05:40:29.070223Z","record_id":"90ef83fe5abeb60819629c081f812e68869690045570ada1a4fe10a5eaea2a63","schema_fingerprint":"4aa3821a28b0b7c2400bc59aba4bcc0a76e971dadd19610d3ad38c768e124dc7","schema_version":"edge-lab-recorder.raw.v1","sequence":null,"source":"clob_market_ws"}
{"event_at":"2026-07-27T05:40:26.991000Z","event_fingerprint":"574fe92fba2fc9cce910461dac4fe729dff5ba4c8a02b43083ac9f916f95174d","payload":{"connection_id":"efc69d3132f1467b8e898a382b23ac0d","event_at":"2026-07-27T05:40:26.991000Z","event_type":"price_change","frame_hash":"1fa0c318239cc2a5c464e6b6152e737501991151e6d2e19b4771520936bff312","frame_index":0,"kind":"data","monotonic_ns":232812309540083,"payload":{"event_type":"price_change","market":"0x3b40066b5cf3871a2f6237c5628bd8092a206aa998558ac5ec13c4483e31e160","price_changes":[{"asset_id":"14766054693214075530629349735273995982307625376442606753688071083149620216746","best_ask":"0.54","best_bid":"0.53","hash":"3fb8b0d8ee53b3cd883175763099cdec1e2dafc4","price":"0.43","side":"BUY","size":"110.2"},{"asset_id":"110216635572655435074987471276357323571387854733835379371586402147734167783946","best_ask":"0.47","best_bid":"0.46","hash":"ced94f00e61f523a762bc6f7f7b01838d7257d0b","price":"0.57","side":"SELL","size":"110.2"}],"timestamp":"1785130826991"},"payload_hash":"a9cffe8a71fa92127607d73e0e613c64c2d0919c81e0438956ec7f11e197ea99","raw_frame":"{\"market\":\"0x3b40066b5cf3871a2f6237c5628bd8092a206aa998558ac5ec13c4483e31e160\", \"price_changes\":[{\"asset_id\":\"14766054693214075530629349735273995982307625376442606753688071083149620216746\", \"price\":\"0.43\", \"size\":\"110.2\", \"side\":\"BUY\", \"hash\":\"3fb8b0d8ee53b3cd883175763099cdec1e2dafc4\", \"best_bid\":\"0.53\", \"best_ask\":\"0.54\"}, {\"asset_id\":\"110216635572655435074987471276357323571387854733835379371586402147734167783946\", \"price\":\"0.57\", \"size\":\"110.2\", \"side\":\"SELL\", \"hash\":\"ced94f00e61f523a762bc6f7f7b01838d7257d0b\", \"best_bid\":\"0.46\", \"best_ask\":\"0.47\"}], \"timestamp\":\"1785130826991\", \"event_type\":\"price_change\"}","received_at":"2026-07-27T05:40:29.075702Z","schema_version":"clob-market-ws.price_change.v1","sequence":null,"server_hash":null,"server_timestamp":"1785130826991","session_id":"502006c5cfcd437296561ea750c9ec8b","source":"clob_market_ws"},"received_at":"2026-07-27T05:40:29.075702Z","record_id":"cd59a02ba008eaa44fd8ebe051c962f5b0eabe88a002df2e21a309f457149a59","schema_fingerprint":"4aa3821a28b0b7c2400bc59aba4bcc0a76e971dadd19610d3ad38c768e124dc7","schema_version":"edge-lab-recorder.raw.v1","sequence":null,"source":"clob_market_ws"}
{"event_at":"2026-07-27T05:40:26.992000Z","event_fingerprint":"47c51e2468d8117b3a82ca5a1ba6c4b759ecaf64f11cf04b33b04b1e925883c2","payload":{"connection_id":"efc69d3132f1467b8e898a382b23ac0d","event_at":"2026-07-27T05:40:26.992000Z","event_type":"price_change","frame_hash":"51bae04e9c8f1a1e3bbaa86a1a9441294fc202d78e98166b633eb3bd1c2421b2","frame_index":0,"kind":"data","monotonic_ns":232812315250333,"payload":{"event_type":"price_change","market":"0x3b40066b5cf3871a2f6237c5628bd8092a206aa998558ac5ec13c4483e31e160","price_changes":[{"asset_id":"110216635572655435074987471276357323571387854733835379371586402147734167783946","best_ask":"0.47","best_bid":"0.46","hash":"9a24551dbd7f57faccd10abe3025406f08227540","price":"0.46","side":"BUY","size":"49"},{"asset_id":"14766054693214075530629349735273995982307625376442606753688071083149620216746","best_ask":"0.54","best_bid":"0.53","hash":"867219ff576e97256f31cea33461ad7b63713fa0","price":"0.54","side":"SELL","size":"49"}],"timestamp":"1785130826992"},"payload_hash":"642adbbb408b9d7f3be1278a286ebc4bc0b2cb564c89054dea4c1ce6ba6aa0fe","raw_frame":"{\"market\":\"0x3b40066b5cf3871a2f6237c5628bd8092a206aa998558ac5ec13c4483e31e160\", \"price_changes\":[{\"asset_id\":\"110216635572655435074987471276357323571387854733835379371586402147734167783946\", \"price\":\"0.46\", \"size\":\"49\", \"side\":\"BUY\", \"hash\":\"9a24551dbd7f57faccd10abe3025406f08227540\", \"best_bid\":\"0.46\", \"best_ask\":\"0.47\"}, {\"asset_id\":\"14766054693214075530629349735273995982307625376442606753688071083149620216746\", \"price\":\"0.54\", \"size\":\"49\", \"side\":\"SELL\", \"hash\":\"867219ff576e97256f31cea33461ad7b63713fa0\", \"best_bid\":\"0.53\", \"best_ask\":\"0.54\"}], \"timestamp\":\"1785130826992\", \"event_type\":\"price_change\"}","received_at":"2026-07-27T05:40:29.081418Z","schema_version":"clob-market-ws.price_change.v1","sequence":null,"server_hash":null,"server_timestamp":"1785130826992","session_id":"502006c5cfcd437296561ea750c9ec8b","source":"clob_market_ws"},"received_at":"2026-07-27T05:40:29.081418Z","record_id":"33bec73c97dada86e971b63b8801560dd7f162b5ebefd6bfdd3ccdf3df80f1df","schema_fingerprint":"4aa3821a28b0b7c2400bc59aba4bcc0a76e971dadd19610d3ad38c768e124dc7","schema_version":"edge-lab-recorder.raw.v1","sequence":null,"source":"clob_market_ws"}
{"event_at":"2026-07-27T05:40:26.993000Z","event_fingerprint":"5e8149831ade53fa00f4990093d55db18ac38dd9d3b3772a9820fe429c20f390","payload":{"connection_id":"efc69d3132f1467b8e898a382b23ac0d","event_at":"2026-07-27T05:40:26.993000Z","event_type":"price_change","frame_hash":"fda0026ec5bfb0537252e9903ca1513dadbd911411955c51e6f0cf3d666ed108","frame_index":0,"kind":"data","monotonic_ns":232812318932875,"payload":{"event_type":"price_change","market":"0x3b40066b5cf3871a2f6237c5628bd8092a206aa998558ac5ec13c4483e31e160","price_changes":[{"asset_id":"14766054693214075530629349735273995982307625376442606753688071083149620216746","best_ask":"0.54","best_bid":"0.53","hash":"f730bdc245995e74aa3a5dfafb5809bd1848e9e4","price":"0.04","side":"BUY","size":"646.09"},{"asset_id":"110216635572655435074987471276357323571387854733835379371586402147734167783946","best_ask":"0.47","best_bid":"0.46","hash":"b858ac5433ea1b6b12d3f9bd2549d5548829de0c","price":"0.96","side":"SELL","size":"646.09"}],"timestamp":"1785130826993"},"payload_hash":"8e6802588c41283fd45252da999afa72e0bd66147c1dc7a11a3a81ab41d3bab7","raw_frame":"{\"market\":\"0x3b40066b5cf3871a2f6237c5628bd8092a206aa998558ac5ec13c4483e31e160\", \"price_changes\":[{\"asset_id\":\"14766054693214075530629349735273995982307625376442606753688071083149620216746\", \"price\":\"0.04\", \"size\":\"646.09\", \"side\":\"BUY\", \"hash\":\"f730bdc245995e74aa3a5dfafb5809bd1848e9e4\", \"best_bid\":\"0.53\", \"best_ask\":\"0.54\"}, {\"asset_id\":\"110216635572655435074987471276357323571387854733835379371586402147734167783946\", \"price\":\"0.96\", \"size\":\"646.09\", \"side\":\"SELL\", \"hash\":\"b858ac5433ea1b6b12d3f9bd2549d5548829de0c\", \"best_bid\":\"0.46\", \"best_ask\":\"0.47\"}], \"timestamp\":\"1785130826993\", \"event_type\":\"price_change\"}","received_at":"2026-07-27T05:40:29.085095Z","schema_version":"clob-market-ws.price_change.v1","sequence":null,"server_hash":null,"server_timestamp":"1785130826993","session_id":"502006c5cfcd437296561ea750c9ec8b","source":"clob_market_ws"},"received_at":"2026-07-27T05:40:29.085095Z","record_id":"3b1563cd979fefb46de1ff299940d3553cb2e8f3097fa40249072fd560b3af42","schema_fingerprint":"4aa3821a28b0b7c2400bc59aba4bcc0a76e971dadd19610d3ad38c768e124dc7","schema_version":"edge-lab-recorder.raw.v1","sequence":null,"source":"clob_market_ws"}
