{"event_at":null,"event_fingerprint":"48378d23570134738f1cc6bb920122d92ed0ca22c99f230f6daf35f4dcfa2a57","payload":{"connection_id":"efc69d3132f1467b8e898a382b23ac0d","detail":{"connection_number":1,"url":"wss://ws-subscriptions-clob.polymarket.com/ws/market"},"event_type":"connected","kind":"lifecycle","monotonic_ns":231916251086750,"received_at":"2026-07-27T05:25:33.011014Z","schema_version":"edge-lab-recorder.lifecycle.v1","session_id":"502006c5cfcd437296561ea750c9ec8b","source":"clob_market_ws"},"received_at":"2026-07-27T05:25:33.011014Z","record_id":"8c98a665c29187c277cb57c69146f425217dcc34fd293cf1f8c0ae25ec3dc489","schema_fingerprint":"55796180566b13b76a84121638a57ef403d9319ab253f490d610e05227425126","schema_version":"edge-lab-recorder.raw.v1","sequence":null,"source":"clob_market_ws"}
{"event_at":null,"event_fingerprint":"e8e76322b65db5b6b59fe9067fe45e86763712fb9292affebf4f35463b3556bf","payload":{"connection_id":"efc69d3132f1467b8e898a382b23ac0d","detail":{"subscription":{"assets_ids":["14766054693214075530629349735273995982307625376442606753688071083149620216746","110216635572655435074987471276357323571387854733835379371586402147734167783946"],"custom_feature_enabled":true,"type":"market"}},"event_type":"subscribed","kind":"lifecycle","monotonic_ns":231916252653083,"received_at":"2026-07-27T05:25:33.012580Z","schema_version":"edge-lab-recorder.lifecycle.v1","session_id":"502006c5cfcd437296561ea750c9ec8b","source":"clob_market_ws"},"received_at":"2026-07-27T05:25:33.012580Z","record_id":"89b07d9b54cc39b919c5d10cd7e2750bdb4266940749968adacd02e39615b041","schema_fingerprint":"b75a00837e5ec1c947d19ddcc8d68c4b066cd91e376ddfb07f3243c8653c02ea","schema_version":"edge-lab-recorder.raw.v1","sequence":null,"source":"clob_market_ws"}
{"event_at":null,"event_fingerprint":"2c20c88fa149b7ede8f2f5331ad1950b7333f6fb35c18d0ceb58e9c2fb9efdb9","payload":{"connection_id":"efc69d3132f1467b8e898a382b23ac0d","detail":{"connection_number":1},"event_type":"resync_begin","kind":"lifecycle","monotonic_ns":231916253242666,"received_at":"2026-07-27T05:25:33.013179Z","schema_version":"edge-lab-recorder.lifecycle.v1","session_id":"502006c5cfcd437296561ea750c9ec8b","source":"clob_market_ws"},"received_at":"2026-07-27T05:25:33.013179Z","record_id":"f7bae16c4b117ab8be0444940194668fd4240bb1627e88ebd090b7dd89879062","schema_fingerprint":"16efb6e904eff9642268f91e8fb4718646b6f037026603a8520e9d118f1aea24","schema_version":"edge-lab-recorder.raw.v1","sequence":null,"source":"clob_market_ws"}
{"event_at":null,"event_fingerprint":"515b7dd1385c7efb83ea384949914d0485cefe8a022359ab2ab467756e015228","payload":{"connection_id":"efc69d3132f1467b8e898a382b23ac0d","detail":{"interval_seconds":10.0,"message":"PING"},"event_type":"heartbeat","kind":"lifecycle","monotonic_ns":231926260163625,"received_at":"2026-07-27T05:25:43.020167Z","schema_version":"edge-lab-recorder.lifecycle.v1","session_id":"502006c5cfcd437296561ea750c9ec8b","source":"clob_market_ws"},"received_at":"2026-07-27T05:25:43.020167Z","record_id":"81d160ca8ca32b442d097eb86a018bd237a2409a59ec154166962ddbae4d1157","schema_fingerprint":"cb8aa3aa4cb168a4b724fd9077bee6ecfb9bc586c57cfdf0ab89f00d82045e3c","schema_version":"edge-lab-recorder.raw.v1","sequence":null,"source":"clob_market_ws"}
{"event_at":"2026-07-27T05:25:33.234000Z","event_fingerprint":"4716477f1360bcdcf1ad26dd843edb5b44813f58d411555984c9b2e2048cc0e6","payload":{"connection_id":"efc69d3132f1467b8e898a382b23ac0d","event_at":"2026-07-27T05:25:33.234000Z","event_type":"book","frame_hash":"fe0695d7e6d4859db8a6fff8a8021f1181745bf1ee412cc8b4b1ae6206f0ec3a","frame_index":0,"kind":"quarantine","monotonic_ns":231916457799333,"payload":{"asks":[{"price":"0.99","size":"97392.55"},{"price":"0.98","size":"16597.9"},{"price":"0.97","size":"10950"},{"price":"0.96","size":"730"},{"price":"0.95","size":"5330.75"},{"price":"0.94","size":"639"},{"price":"0.93","size":"520"},{"price":"0.92","size":"611"},{"price":"0.91","size":"520"},{"price":"0.9","size":"2420"},{"price":"0.88","size":"20"},{"price":"0.87","size":"25.22"},{"price":"0.86","size":"20"},{"price":"0.85","size":"1620"},{"price":"0.84","size":"20"},{"price":"0.83","size":"20"},{"price":"0.82","size":"20"},{"price":"0.81","size":"20"},{"price":"0.8","size":"1220"},{"price":"0.79","size":"260"},{"price":"0.78","size":"20"},{"price":"0.77","size":"20"},{"price":"0.76","size":"220"},{"price":"0.75","size":"980"},{"price":"0.74","size":"360"},{"price":"0.73","size":"20"},{"price":"0.72","size":"305"},{"price":"0.71","size":"70"},{"price":"0.7","size":"1060"},{"price":"0.69","size":"20"},{"price":"0.68","size":"140"},{"price":"0.67","size":"571"},{"price":"0.66","size":"175"},{"price":"0.65","size":"10"},{"price":"0.64","size":"634"},{"price":"0.63","size":"121.62"},{"price":"0.62","size":"254"},{"price":"0.61","size":"48"},{"price":"0.6","size":"82"},{"price":"0.59","size":"95.78"},{"price":"0.58","size":"118"},{"price":"0.57","size":"250"},{"price":"0.56","size":"230.68"},{"price":"0.55","size":"15.33"},{"price":"0.54","size":"25"},{"price":"0.53","size":"14.67"},{"price":"0.52","size":"100"},{"price":"0.51","size":"311"},{"price":"0.5","size":"620"},{"price":"0.49","size":"325"},{"price":"0.48","size":"214.69"}],"asset_id":"14766054693214075530629349735273995982307625376442606753688071083149620216746","bids":[{"price":"0.01","size":"97397.3"},{"price":"0.02","size":"16598.17"},{"price":"0.03","size":"10950"},{"price":"0.04","size":"730"},{"price":"0.05","size":"5331.11"},{"price":"0.06","size":"639"},{"price":"0.07","size":"520"},{"price":"0.08","size":"611"},{"price":"0.09","size":"520"},{"price":"0.1","size":"2420"},{"price":"0.12","size":"20"},{"price":"0.13","size":"25.05"},{"price":"0.14","size":"20"},{"price":"0.15","size":"1620"},{"price":"0.16","size":"20"},{"price":"0.17","size":"20"},{"price":"0.18","size":"20"},{"price":"0.19","size":"20"},{"price":"0.2","size":"1220"},{"price":"0.21","size":"260"},{"price":"0.22","size":"165"},{"price":"0.23","size":"20"},{"price":"0.24","size":"220"},{"price":"0.25","size":"980"},{"price":"0.26","size":"360"},{"price":"0.27","size":"165"},{"price":"0.28","size":"160"},{"price":"0.29","size":"70"},{"price":"0.3","size":"1060"},{"price":"0.31","size":"20"},{"price":"0.32","size":"285"},{"price":"0.33","size":"426"},{"price":"0.34","size":"275"},{"price":"0.35","size":"110"},{"price":"0.36","size":"740"},{"price":"0.37","size":"366.62"},{"price":"0.38","size":"215"},{"price":"0.39","size":"98"},{"price":"0.4","size":"135"},{"price":"0.41","size":"104.78"},{"price":"0.42","size":"222"},{"price":"0.43","size":"310"},{"price":"0.44","size":"355.68"},{"price":"0.45","size":"225.33"},{"price":"0.46","size":"30"},{"price":"0.47","size":"15.79"}],"event_type":"book","hash":"d8c22b6c7c391a7c170c6c1640e72590d03cc26c","last_trade_price":"0.470","market":"0x3b40066b5cf3871a2f6237c5628bd8092a206aa998558ac5ec13c4483e31e160","tick_size":"0.01","timestamp":"1785129933234"},"payload_hash":"032f7f9e8414d74bb42b8b412e718b0995f0d30105f2bf49891d5fcb8463ae28","raw_frame":"[{\"market\":\"0x3b40066b5cf3871a2f6237c5628bd8092a206aa998558ac5ec13c4483e31e160\",\"asset_id\":\"14766054693214075530629349735273995982307625376442606753688071083149620216746\",\"timestamp\":\"1785129933234\",\"hash\":\"d8c22b6c7c391a7c170c6c1640e72590d03cc26c\",\"bids\":[{\"price\":\"0.01\",\"size\":\"97397.3\"},{\"price\":\"0.02\",\"size\":\"16598.17\"},{\"price\":\"0.03\",\"size\":\"10950\"},{\"price\":\"0.04\",\"size\":\"730\"},{\"price\":\"0.05\",\"size\":\"5331.11\"},{\"price\":\"0.06\",\"size\":\"639\"},{\"price\":\"0.07\",\"size\":\"520\"},{\"price\":\"0.08\",\"size\":\"611\"},{\"price\":\"0.09\",\"size\":\"520\"},{\"price\":\"0.1\",\"size\":\"2420\"},{\"price\":\"0.12\",\"size\":\"20\"},{\"price\":\"0.13\",\"size\":\"25.05\"},{\"price\":\"0.14\",\"size\":\"20\"},{\"price\":\"0.15\",\"size\":\"1620\"},{\"price\":\"0.16\",\"size\":\"20\"},{\"price\":\"0.17\",\"size\":\"20\"},{\"price\":\"0.18\",\"size\":\"20\"},{\"price\":\"0.19\",\"size\":\"20\"},{\"price\":\"0.2\",\"size\":\"1220\"},{\"price\":\"0.21\",\"size\":\"260\"},{\"price\":\"0.22\",\"size\":\"165\"},{\"price\":\"0.23\",\"size\":\"20\"},{\"price\":\"0.24\",\"size\":\"220\"},{\"price\":\"0.25\",\"size\":\"980\"},{\"price\":\"0.26\",\"size\":\"360\"},{\"price\":\"0.27\",\"size\":\"165\"},{\"price\":\"0.28\",\"size\":\"160\"},{\"price\":\"0.29\",\"size\":\"70\"},{\"price\":\"0.3\",\"size\":\"1060\"},{\"price\":\"0.31\",\"size\":\"20\"},{\"price\":\"0.32\",\"size\":\"285\"},{\"price\":\"0.33\",\"size\":\"426\"},{\"price\":\"0.34\",\"size\":\"275\"},{\"price\":\"0.35\",\"size\":\"110\"},{\"price\":\"0.36\",\"size\":\"740\"},{\"price\":\"0.37\",\"size\":\"366.62\"},{\"price\":\"0.38\",\"size\":\"215\"},{\"price\":\"0.39\",\"size\":\"98\"},{\"price\":\"0.4\",\"size\":\"135\"},{\"price\":\"0.41\",\"size\":\"104.78\"},{\"price\":\"0.42\",\"size\":\"222\"},{\"price\":\"0.43\",\"size\":\"310\"},{\"price\":\"0.44\",\"size\":\"355.68\"},{\"price\":\"0.45\",\"size\":\"225.33\"},{\"price\":\"0.46\",\"size\":\"30\"},{\"price\":\"0.47\",\"size\":\"15.79\"}],\"asks\":[{\"price\":\"0.99\",\"size\":\"97392.55\"},{\"price\":\"0.98\",\"size\":\"16597.9\"},{\"price\":\"0.97\",\"size\":\"10950\"},{\"price\":\"0.96\",\"size\":\"730\"},{\"price\":\"0.95\",\"size\":\"5330.75\"},{\"price\":\"0.94\",\"size\":\"639\"},{\"price\":\"0.93\",\"size\":\"520\"},{\"price\":\"0.92\",\"size\":\"611\"},{\"price\":\"0.91\",\"size\":\"520\"},{\"price\":\"0.9\",\"size\":\"2420\"},{\"price\":\"0.88\",\"size\":\"20\"},{\"price\":\"0.87\",\"size\":\"25.22\"},{\"price\":\"0.86\",\"size\":\"20\"},{\"price\":\"0.85\",\"size\":\"1620\"},{\"price\":\"0.84\",\"size\":\"20\"},{\"price\":\"0.83\",\"size\":\"20\"},{\"price\":\"0.82\",\"size\":\"20\"},{\"price\":\"0.81\",\"size\":\"20\"},{\"price\":\"0.8\",\"size\":\"1220\"},{\"price\":\"0.79\",\"size\":\"260\"},{\"price\":\"0.78\",\"size\":\"20\"},{\"price\":\"0.77\",\"size\":\"20\"},{\"price\":\"0.76\",\"size\":\"220\"},{\"price\":\"0.75\",\"size\":\"980\"},{\"price\":\"0.74\",\"size\":\"360\"},{\"price\":\"0.73\",\"size\":\"20\"},{\"price\":\"0.72\",\"size\":\"305\"},{\"price\":\"0.71\",\"size\":\"70\"},{\"price\":\"0.7\",\"size\":\"1060\"},{\"price\":\"0.69\",\"size\":\"20\"},{\"price\":\"0.68\",\"size\":\"140\"},{\"price\":\"0.67\",\"size\":\"571\"},{\"price\":\"0.66\",\"size\":\"175\"},{\"price\":\"0.65\",\"size\":\"10\"},{\"price\":\"0.64\",\"size\":\"634\"},{\"price\":\"0.63\",\"size\":\"121.62\"},{\"price\":\"0.62\",\"size\":\"254\"},{\"price\":\"0.61\",\"size\":\"48\"},{\"price\":\"0.6\",\"size\":\"82\"},{\"price\":\"0.59\",\"size\":\"95.78\"},{\"price\":\"0.58\",\"size\":\"118\"},{\"price\":\"0.57\",\"size\":\"250\"},{\"price\":\"0.56\",\"size\":\"230.68\"},{\"price\":\"0.55\",\"size\":\"15.33\"},{\"price\":\"0.54\",\"size\":\"25\"},{\"price\":\"0.53\",\"size\":\"14.67\"},{\"price\":\"0.52\",\"size\":\"100\"},{\"price\":\"0.51\",\"size\":\"311\"},{\"price\":\"0.5\",\"size\":\"620\"},{\"price\":\"0.49\",\"size\":\"325\"},{\"price\":\"0.48\",\"size\":\"214.69\"}],\"tick_size\":\"0.01\",\"event_type\":\"book\",\"last_trade_price\":\"0.470\"},{\"market\":\"0x3b40066b5cf3871a2f6237c5628bd8092a206aa998558ac5ec13c4483e31e160\",\"asset_id\":\"110216635572655435074987471276357323571387854733835379371586402147734167783946\",\"timestamp\":\"1785129933234\",\"hash\":\"a0fc07aa73d9ad2cfaa22d806ecd2f9d0bafeb5b\",\"bids\":[{\"price\":\"0.01\",\"size\":\"97392.55\"},{\"price\":\"0.02\",\"size\":\"16597.9\"},{\"price\":\"0.03\",\"size\":\"10950\"},{\"price\":\"0.04\",\"size\":\"730\"},{\"price\":\"0.05\",\"size\":\"5330.75\"},{\"price\":\"0.06\",\"size\":\"639\"},{\"price\":\"0.07\",\"size\":\"520\"},{\"price\":\"0.08\",\"size\":\"611\"},{\"price\":\"0.09\",\"size\":\"520\"},{\"price\":\"0.1\",\"size\":\"2420\"},{\"price\":\"0.12\",\"size\":\"20\"},{\"price\":\"0.13\",\"size\":\"25.22\"},{\"price\":\"0.14\",\"size\":\"20\"},{\"price\":\"0.15\",\"size\":\"1620\"},{\"price\":\"0.16\",\"size\":\"20\"},{\"price\":\"0.17\",\"size\":\"20\"},{\"price\":\"0.18\",\"size\":\"20\"},{\"price\":\"0.19\",\"size\":\"20\"},{\"price\":\"0.2\",\"size\":\"1220\"},{\"price\":\"0.21\",\"size\":\"260\"},{\"price\":\"0.22\",\"size\":\"20\"},{\"price\":\"0.23\",\"size\":\"20\"},{\"price\":\"0.24\",\"size\":\"220\"},{\"price\":\"0.25\",\"size\":\"980\"},{\"price\":\"0.26\",\"size\":\"360\"},{\"price\":\"0.27\",\"size\":\"20\"},{\"price\":\"0.28\",\"size\":\"305\"},{\"price\":\"0.29\",\"size\":\"70\"},{\"price\":\"0.3\",\"size\":\"1060\"},{\"price\":\"0.31\",\"size\":\"20\"},{\"price\":\"0.32\",\"size\":\"140\"},{\"price\":\"0.33\",\"size\":\"571\"},{\"price\":\"0.34\",\"size\":\"175\"},{\"price\":\"0.35\",\"size\":\"10\"},{\"price\":\"0.36\",\"size\":\"634\"},{\"price\":\"0.37\",\"size\":\"121.62\"},{\"price\":\"0.38\",\"size\":\"254\"},{\"price\":\"0.39\",\"size\":\"48\"},{\"price\":\"0.4\",\"size\":\"82\"},{\"price\":\"0.41\",\"size\":\"95.78\"},{\"price\":\"0.42\",\"size\":\"118\"},{\"price\":\"0.43\",\"size\":\"250\"},{\"price\":\"0.44\",\"size\":\"230.68\"},{\"price\":\"0.45\",\"size\":\"15.33\"},{\"price\":\"0.46\",\"size\":\"25\"},{\"price\":\"0.47\",\"size\":\"14.67\"},{\"price\":\"0.48\",\"size\":\"100\"},{\"price\":\"0.49\",\"size\":\"311\"},{\"price\":\"0.5\",\"size\":\"620\"},{\"price\":\"0.51\",\"size\":\"325\"},{\"price\":\"0.52\",\"size\":\"214.69\"}],\"asks\":[{\"price\":\"0.99\",\"size\":\"97397.3\"},{\"price\":\"0.98\",\"size\":\"16598.17\"},{\"price\":\"0.97\",\"size\":\"10950\"},{\"price\":\"0.96\",\"size\":\"730\"},{\"price\":\"0.95\",\"size\":\"5331.11\"},{\"price\":\"0.94\",\"size\":\"639\"},{\"price\":\"0.93\",\"size\":\"520\"},{\"price\":\"0.92\",\"size\":\"611\"},{\"price\":\"0.91\",\"size\":\"520\"},{\"price\":\"0.9\",\"size\":\"2420\"},{\"price\":\"0.88\",\"size\":\"20\"},{\"price\":\"0.87\",\"size\":\"25.05\"},{\"price\":\"0.86\",\"size\":\"20\"},{\"price\":\"0.85\",\"size\":\"1620\"},{\"price\":\"0.84\",\"size\":\"20\"},{\"price\":\"0.83\",\"size\":\"20\"},{\"price\":\"0.82\",\"size\":\"20\"},{\"price\":\"0.81\",\"size\":\"20\"},{\"price\":\"0.8\",\"size\":\"1220\"},{\"price\":\"0.79\",\"size\":\"260\"},{\"price\":\"0.78\",\"size\":\"165\"},{\"price\":\"0.77\",\"size\":\"20\"},{\"price\":\"0.76\",\"size\":\"220\"},{\"price\":\"0.75\",\"size\":\"980\"},{\"price\":\"0.74\",\"size\":\"360\"},{\"price\":\"0.73\",\"size\":\"165\"},{\"price\":\"0.72\",\"size\":\"160\"},{\"price\":\"0.71\",\"size\":\"70\"},{\"price\":\"0.7\",\"size\":\"1060\"},{\"price\":\"0.69\",\"size\":\"20\"},{\"price\":\"0.68\",\"size\":\"285\"},{\"price\":\"0.67\",\"size\":\"426\"},{\"price\":\"0.66\",\"size\":\"275\"},{\"price\":\"0.65\",\"size\":\"110\"},{\"price\":\"0.64\",\"size\":\"740\"},{\"price\":\"0.63\",\"size\":\"366.62\"},{\"price\":\"0.62\",\"size\":\"215\"},{\"price\":\"0.61\",\"size\":\"98\"},{\"price\":\"0.6\",\"size\":\"135\"},{\"price\":\"0.59\",\"size\":\"104.78\"},{\"price\":\"0.58\",\"size\":\"222\"},{\"price\":\"0.57\",\"size\":\"310\"},{\"price\":\"0.56\",\"size\":\"355.68\"},{\"price\":\"0.55\",\"size\":\"225.33\"},{\"price\":\"0.54\",\"size\":\"30\"},{\"price\":\"0.53\",\"size\":\"15.79\"}],\"tick_size\":\"0.01\",\"event_type\":\"book\",\"last_trade_price\":\"0.470\"}]\n","received_at":"2026-07-27T05:25:33.217726Z","replay_eligible":false,"resync_asset_ids":["14766054693214075530629349735273995982307625376442606753688071083149620216746"],"resync_asset_watermarks_ns":{"14766054693214075530629349735273995982307625376442606753688071083149620216746":1785129938639000000},"resync_buffered":true,"resync_status":"success","resync_watermark_ns":1785129938639000000,"schema_version":"clob-market-ws.book.v1","sequence":null,"server_hash":"d8c22b6c7c391a7c170c6c1640e72590d03cc26c","server_timestamp":"1785129933234","session_id":"502006c5cfcd437296561ea750c9ec8b","source":"clob_market_ws"},"received_at":"2026-07-27T05:25:33.217726Z","record_id":"7851bae1a83830a3df92a5d69e0022285caece59c080cfe9ad2357605dfed2c1","schema_fingerprint":"de2a90517d76eedae6198def7f64cce23f9cd8c3faaeea8475d2f26f17c6c28d","schema_version":"edge-lab-recorder.raw.v1","sequence":null,"source":"clob_market_ws"}
{"event_at":"2026-07-27T05:25:33.234000Z","event_fingerprint":"c2c216d9eced17a4196914304605ec3ca549af27f02ed8564c57e09b480d7712","payload":{"connection_id":"efc69d3132f1467b8e898a382b23ac0d","event_at":"2026-07-27T05:25:33.234000Z","event_type":"book","frame_hash":"fe0695d7e6d4859db8a6fff8a8021f1181745bf1ee412cc8b4b1ae6206f0ec3a","frame_index":1,"kind":"quarantine","monotonic_ns":231916457799333,"payload":{"asks":[{"price":"0.99","size":"97397.3"},{"price":"0.98","size":"16598.17"},{"price":"0.97","size":"10950"},{"price":"0.96","size":"730"},{"price":"0.95","size":"5331.11"},{"price":"0.94","size":"639"},{"price":"0.93","size":"520"},{"price":"0.92","size":"611"},{"price":"0.91","size":"520"},{"price":"0.9","size":"2420"},{"price":"0.88","size":"20"},{"price":"0.87","size":"25.05"},{"price":"0.86","size":"20"},{"price":"0.85","size":"1620"},{"price":"0.84","size":"20"},{"price":"0.83","size":"20"},{"price":"0.82","size":"20"},{"price":"0.81","size":"20"},{"price":"0.8","size":"1220"},{"price":"0.79","size":"260"},{"price":"0.78","size":"165"},{"price":"0.77","size":"20"},{"price":"0.76","size":"220"},{"price":"0.75","size":"980"},{"price":"0.74","size":"360"},{"price":"0.73","size":"165"},{"price":"0.72","size":"160"},{"price":"0.71","size":"70"},{"price":"0.7","size":"1060"},{"price":"0.69","size":"20"},{"price":"0.68","size":"285"},{"price":"0.67","size":"426"},{"price":"0.66","size":"275"},{"price":"0.65","size":"110"},{"price":"0.64","size":"740"},{"price":"0.63","size":"366.62"},{"price":"0.62","size":"215"},{"price":"0.61","size":"98"},{"price":"0.6","size":"135"},{"price":"0.59","size":"104.78"},{"price":"0.58","size":"222"},{"price":"0.57","size":"310"},{"price":"0.56","size":"355.68"},{"price":"0.55","size":"225.33"},{"price":"0.54","size":"30"},{"price":"0.53","size":"15.79"}],"asset_id":"110216635572655435074987471276357323571387854733835379371586402147734167783946","bids":[{"price":"0.01","size":"97392.55"},{"price":"0.02","size":"16597.9"},{"price":"0.03","size":"10950"},{"price":"0.04","size":"730"},{"price":"0.05","size":"5330.75"},{"price":"0.06","size":"639"},{"price":"0.07","size":"520"},{"price":"0.08","size":"611"},{"price":"0.09","size":"520"},{"price":"0.1","size":"2420"},{"price":"0.12","size":"20"},{"price":"0.13","size":"25.22"},{"price":"0.14","size":"20"},{"price":"0.15","size":"1620"},{"price":"0.16","size":"20"},{"price":"0.17","size":"20"},{"price":"0.18","size":"20"},{"price":"0.19","size":"20"},{"price":"0.2","size":"1220"},{"price":"0.21","size":"260"},{"price":"0.22","size":"20"},{"price":"0.23","size":"20"},{"price":"0.24","size":"220"},{"price":"0.25","size":"980"},{"price":"0.26","size":"360"},{"price":"0.27","size":"20"},{"price":"0.28","size":"305"},{"price":"0.29","size":"70"},{"price":"0.3","size":"1060"},{"price":"0.31","size":"20"},{"price":"0.32","size":"140"},{"price":"0.33","size":"571"},{"price":"0.34","size":"175"},{"price":"0.35","size":"10"},{"price":"0.36","size":"634"},{"price":"0.37","size":"121.62"},{"price":"0.38","size":"254"},{"price":"0.39","size":"48"},{"price":"0.4","size":"82"},{"price":"0.41","size":"95.78"},{"price":"0.42","size":"118"},{"price":"0.43","size":"250"},{"price":"0.44","size":"230.68"},{"price":"0.45","size":"15.33"},{"price":"0.46","size":"25"},{"price":"0.47","size":"14.67"},{"price":"0.48","size":"100"},{"price":"0.49","size":"311"},{"price":"0.5","size":"620"},{"price":"0.51","size":"325"},{"price":"0.52","size":"214.69"}],"event_type":"book","hash":"a0fc07aa73d9ad2cfaa22d806ecd2f9d0bafeb5b","last_trade_price":"0.470","market":"0x3b40066b5cf3871a2f6237c5628bd8092a206aa998558ac5ec13c4483e31e160","tick_size":"0.01","timestamp":"1785129933234"},"payload_hash":"a338db90a4ded3184d1b96c031a138a48fde6450e65d5aa26c06719206e2da5a","raw_frame":"[{\"market\":\"0x3b40066b5cf3871a2f6237c5628bd8092a206aa998558ac5ec13c4483e31e160\",\"asset_id\":\"14766054693214075530629349735273995982307625376442606753688071083149620216746\",\"timestamp\":\"1785129933234\",\"hash\":\"d8c22b6c7c391a7c170c6c1640e72590d03cc26c\",\"bids\":[{\"price\":\"0.01\",\"size\":\"97397.3\"},{\"price\":\"0.02\",\"size\":\"16598.17\"},{\"price\":\"0.03\",\"size\":\"10950\"},{\"price\":\"0.04\",\"size\":\"730\"},{\"price\":\"0.05\",\"size\":\"5331.11\"},{\"price\":\"0.06\",\"size\":\"639\"},{\"price\":\"0.07\",\"size\":\"520\"},{\"price\":\"0.08\",\"size\":\"611\"},{\"price\":\"0.09\",\"size\":\"520\"},{\"price\":\"0.1\",\"size\":\"2420\"},{\"price\":\"0.12\",\"size\":\"20\"},{\"price\":\"0.13\",\"size\":\"25.05\"},{\"price\":\"0.14\",\"size\":\"20\"},{\"price\":\"0.15\",\"size\":\"1620\"},{\"price\":\"0.16\",\"size\":\"20\"},{\"price\":\"0.17\",\"size\":\"20\"},{\"price\":\"0.18\",\"size\":\"20\"},{\"price\":\"0.19\",\"size\":\"20\"},{\"price\":\"0.2\",\"size\":\"1220\"},{\"price\":\"0.21\",\"size\":\"260\"},{\"price\":\"0.22\",\"size\":\"165\"},{\"price\":\"0.23\",\"size\":\"20\"},{\"price\":\"0.24\",\"size\":\"220\"},{\"price\":\"0.25\",\"size\":\"980\"},{\"price\":\"0.26\",\"size\":\"360\"},{\"price\":\"0.27\",\"size\":\"165\"},{\"price\":\"0.28\",\"size\":\"160\"},{\"price\":\"0.29\",\"size\":\"70\"},{\"price\":\"0.3\",\"size\":\"1060\"},{\"price\":\"0.31\",\"size\":\"20\"},{\"price\":\"0.32\",\"size\":\"285\"},{\"price\":\"0.33\",\"size\":\"426\"},{\"price\":\"0.34\",\"size\":\"275\"},{\"price\":\"0.35\",\"size\":\"110\"},{\"price\":\"0.36\",\"size\":\"740\"},{\"price\":\"0.37\",\"size\":\"366.62\"},{\"price\":\"0.38\",\"size\":\"215\"},{\"price\":\"0.39\",\"size\":\"98\"},{\"price\":\"0.4\",\"size\":\"135\"},{\"price\":\"0.41\",\"size\":\"104.78\"},{\"price\":\"0.42\",\"size\":\"222\"},{\"price\":\"0.43\",\"size\":\"310\"},{\"price\":\"0.44\",\"size\":\"355.68\"},{\"price\":\"0.45\",\"size\":\"225.33\"},{\"price\":\"0.46\",\"size\":\"30\"},{\"price\":\"0.47\",\"size\":\"15.79\"}],\"asks\":[{\"price\":\"0.99\",\"size\":\"97392.55\"},{\"price\":\"0.98\",\"size\":\"16597.9\"},{\"price\":\"0.97\",\"size\":\"10950\"},{\"price\":\"0.96\",\"size\":\"730\"},{\"price\":\"0.95\",\"size\":\"5330.75\"},{\"price\":\"0.94\",\"size\":\"639\"},{\"price\":\"0.93\",\"size\":\"520\"},{\"price\":\"0.92\",\"size\":\"611\"},{\"price\":\"0.91\",\"size\":\"520\"},{\"price\":\"0.9\",\"size\":\"2420\"},{\"price\":\"0.88\",\"size\":\"20\"},{\"price\":\"0.87\",\"size\":\"25.22\"},{\"price\":\"0.86\",\"size\":\"20\"},{\"price\":\"0.85\",\"size\":\"1620\"},{\"price\":\"0.84\",\"size\":\"20\"},{\"price\":\"0.83\",\"size\":\"20\"},{\"price\":\"0.82\",\"size\":\"20\"},{\"price\":\"0.81\",\"size\":\"20\"},{\"price\":\"0.8\",\"size\":\"1220\"},{\"price\":\"0.79\",\"size\":\"260\"},{\"price\":\"0.78\",\"size\":\"20\"},{\"price\":\"0.77\",\"size\":\"20\"},{\"price\":\"0.76\",\"size\":\"220\"},{\"price\":\"0.75\",\"size\":\"980\"},{\"price\":\"0.74\",\"size\":\"360\"},{\"price\":\"0.73\",\"size\":\"20\"},{\"price\":\"0.72\",\"size\":\"305\"},{\"price\":\"0.71\",\"size\":\"70\"},{\"price\":\"0.7\",\"size\":\"1060\"},{\"price\":\"0.69\",\"size\":\"20\"},{\"price\":\"0.68\",\"size\":\"140\"},{\"price\":\"0.67\",\"size\":\"571\"},{\"price\":\"0.66\",\"size\":\"175\"},{\"price\":\"0.65\",\"size\":\"10\"},{\"price\":\"0.64\",\"size\":\"634\"},{\"price\":\"0.63\",\"size\":\"121.62\"},{\"price\":\"0.62\",\"size\":\"254\"},{\"price\":\"0.61\",\"size\":\"48\"},{\"price\":\"0.6\",\"size\":\"82\"},{\"price\":\"0.59\",\"size\":\"95.78\"},{\"price\":\"0.58\",\"size\":\"118\"},{\"price\":\"0.57\",\"size\":\"250\"},{\"price\":\"0.56\",\"size\":\"230.68\"},{\"price\":\"0.55\",\"size\":\"15.33\"},{\"price\":\"0.54\",\"size\":\"25\"},{\"price\":\"0.53\",\"size\":\"14.67\"},{\"price\":\"0.52\",\"size\":\"100\"},{\"price\":\"0.51\",\"size\":\"311\"},{\"price\":\"0.5\",\"size\":\"620\"},{\"price\":\"0.49\",\"size\":\"325\"},{\"price\":\"0.48\",\"size\":\"214.69\"}],\"tick_size\":\"0.01\",\"event_type\":\"book\",\"last_trade_price\":\"0.470\"},{\"market\":\"0x3b40066b5cf3871a2f6237c5628bd8092a206aa998558ac5ec13c4483e31e160\",\"asset_id\":\"110216635572655435074987471276357323571387854733835379371586402147734167783946\",\"timestamp\":\"1785129933234\",\"hash\":\"a0fc07aa73d9ad2cfaa22d806ecd2f9d0bafeb5b\",\"bids\":[{\"price\":\"0.01\",\"size\":\"97392.55\"},{\"price\":\"0.02\",\"size\":\"16597.9\"},{\"price\":\"0.03\",\"size\":\"10950\"},{\"price\":\"0.04\",\"size\":\"730\"},{\"price\":\"0.05\",\"size\":\"5330.75\"},{\"price\":\"0.06\",\"size\":\"639\"},{\"price\":\"0.07\",\"size\":\"520\"},{\"price\":\"0.08\",\"size\":\"611\"},{\"price\":\"0.09\",\"size\":\"520\"},{\"price\":\"0.1\",\"size\":\"2420\"},{\"price\":\"0.12\",\"size\":\"20\"},{\"price\":\"0.13\",\"size\":\"25.22\"},{\"price\":\"0.14\",\"size\":\"20\"},{\"price\":\"0.15\",\"size\":\"1620\"},{\"price\":\"0.16\",\"size\":\"20\"},{\"price\":\"0.17\",\"size\":\"20\"},{\"price\":\"0.18\",\"size\":\"20\"},{\"price\":\"0.19\",\"size\":\"20\"},{\"price\":\"0.2\",\"size\":\"1220\"},{\"price\":\"0.21\",\"size\":\"260\"},{\"price\":\"0.22\",\"size\":\"20\"},{\"price\":\"0.23\",\"size\":\"20\"},{\"price\":\"0.24\",\"size\":\"220\"},{\"price\":\"0.25\",\"size\":\"980\"},{\"price\":\"0.26\",\"size\":\"360\"},{\"price\":\"0.27\",\"size\":\"20\"},{\"price\":\"0.28\",\"size\":\"305\"},{\"price\":\"0.29\",\"size\":\"70\"},{\"price\":\"0.3\",\"size\":\"1060\"},{\"price\":\"0.31\",\"size\":\"20\"},{\"price\":\"0.32\",\"size\":\"140\"},{\"price\":\"0.33\",\"size\":\"571\"},{\"price\":\"0.34\",\"size\":\"175\"},{\"price\":\"0.35\",\"size\":\"10\"},{\"price\":\"0.36\",\"size\":\"634\"},{\"price\":\"0.37\",\"size\":\"121.62\"},{\"price\":\"0.38\",\"size\":\"254\"},{\"price\":\"0.39\",\"size\":\"48\"},{\"price\":\"0.4\",\"size\":\"82\"},{\"price\":\"0.41\",\"size\":\"95.78\"},{\"price\":\"0.42\",\"size\":\"118\"},{\"price\":\"0.43\",\"size\":\"250\"},{\"price\":\"0.44\",\"size\":\"230.68\"},{\"price\":\"0.45\",\"size\":\"15.33\"},{\"price\":\"0.46\",\"size\":\"25\"},{\"price\":\"0.47\",\"size\":\"14.67\"},{\"price\":\"0.48\",\"size\":\"100\"},{\"price\":\"0.49\",\"size\":\"311\"},{\"price\":\"0.5\",\"size\":\"620\"},{\"price\":\"0.51\",\"size\":\"325\"},{\"price\":\"0.52\",\"size\":\"214.69\"}],\"asks\":[{\"price\":\"0.99\",\"size\":\"97397.3\"},{\"price\":\"0.98\",\"size\":\"16598.17\"},{\"price\":\"0.97\",\"size\":\"10950\"},{\"price\":\"0.96\",\"size\":\"730\"},{\"price\":\"0.95\",\"size\":\"5331.11\"},{\"price\":\"0.94\",\"size\":\"639\"},{\"price\":\"0.93\",\"size\":\"520\"},{\"price\":\"0.92\",\"size\":\"611\"},{\"price\":\"0.91\",\"size\":\"520\"},{\"price\":\"0.9\",\"size\":\"2420\"},{\"price\":\"0.88\",\"size\":\"20\"},{\"price\":\"0.87\",\"size\":\"25.05\"},{\"price\":\"0.86\",\"size\":\"20\"},{\"price\":\"0.85\",\"size\":\"1620\"},{\"price\":\"0.84\",\"size\":\"20\"},{\"price\":\"0.83\",\"size\":\"20\"},{\"price\":\"0.82\",\"size\":\"20\"},{\"price\":\"0.81\",\"size\":\"20\"},{\"price\":\"0.8\",\"size\":\"1220\"},{\"price\":\"0.79\",\"size\":\"260\"},{\"price\":\"0.78\",\"size\":\"165\"},{\"price\":\"0.77\",\"size\":\"20\"},{\"price\":\"0.76\",\"size\":\"220\"},{\"price\":\"0.75\",\"size\":\"980\"},{\"price\":\"0.74\",\"size\":\"360\"},{\"price\":\"0.73\",\"size\":\"165\"},{\"price\":\"0.72\",\"size\":\"160\"},{\"price\":\"0.71\",\"size\":\"70\"},{\"price\":\"0.7\",\"size\":\"1060\"},{\"price\":\"0.69\",\"size\":\"20\"},{\"price\":\"0.68\",\"size\":\"285\"},{\"price\":\"0.67\",\"size\":\"426\"},{\"price\":\"0.66\",\"size\":\"275\"},{\"price\":\"0.65\",\"size\":\"110\"},{\"price\":\"0.64\",\"size\":\"740\"},{\"price\":\"0.63\",\"size\":\"366.62\"},{\"price\":\"0.62\",\"size\":\"215\"},{\"price\":\"0.61\",\"size\":\"98\"},{\"price\":\"0.6\",\"size\":\"135\"},{\"price\":\"0.59\",\"size\":\"104.78\"},{\"price\":\"0.58\",\"size\":\"222\"},{\"price\":\"0.57\",\"size\":\"310\"},{\"price\":\"0.56\",\"size\":\"355.68\"},{\"price\":\"0.55\",\"size\":\"225.33\"},{\"price\":\"0.54\",\"size\":\"30\"},{\"price\":\"0.53\",\"size\":\"15.79\"}],\"tick_size\":\"0.01\",\"event_type\":\"book\",\"last_trade_price\":\"0.470\"}]\n","received_at":"2026-07-27T05:25:33.217726Z","replay_eligible":false,"resync_asset_ids":["110216635572655435074987471276357323571387854733835379371586402147734167783946"],"resync_asset_watermarks_ns":{"110216635572655435074987471276357323571387854733835379371586402147734167783946":1785129938639000000},"resync_buffered":true,"resync_status":"success","resync_watermark_ns":1785129938639000000,"schema_version":"clob-market-ws.book.v1","sequence":null,"server_hash":"a0fc07aa73d9ad2cfaa22d806ecd2f9d0bafeb5b","server_timestamp":"1785129933234","session_id":"502006c5cfcd437296561ea750c9ec8b","source":"clob_market_ws"},"received_at":"2026-07-27T05:25:33.217726Z","record_id":"2d37217f11fcc04836c88add84d8f3a0462d929aca4bae1883e07c0518d0c743","schema_fingerprint":"bd8e68d06b0dc86ad1ab9ebc389aea1e698782198baca22572d48aaf3334b0bb","schema_version":"edge-lab-recorder.raw.v1","sequence":null,"source":"clob_market_ws"}
{"event_at":"2026-07-27T05:25:34.001000Z","event_fingerprint":"fbf7079db3e423ae5548039393b45682690ebbba17714f4c726f6251f2a8309f","payload":{"connection_id":"efc69d3132f1467b8e898a382b23ac0d","event_at":"2026-07-27T05:25:34.001000Z","event_type":"price_change","frame_hash":"9a08e02780c142d5d359e3861d918ca35b2b4f226244b3dc5ecff9e44fa6207e","frame_index":0,"kind":"quarantine","monotonic_ns":231917207481541,"payload":{"event_type":"price_change","market":"0x3b40066b5cf3871a2f6237c5628bd8092a206aa998558ac5ec13c4483e31e160","price_changes":[{"asset_id":"110216635572655435074987471276357323571387854733835379371586402147734167783946","best_ask":"0.53","best_bid":"0.52","hash":"d2ce36eb2e10f08ee1893a6da807c80437fe72b3","price":"0.05","side":"BUY","size":"5325"},{"asset_id":"14766054693214075530629349735273995982307625376442606753688071083149620216746","best_ask":"0.48","best_bid":"0.47","hash":"9ba8fcb8914b6dd1ae68c86c07bab7c81d21e677","price":"0.95","side":"SELL","size":"5325"}],"timestamp":"1785129934001"},"payload_hash":"73cb0aad3b2913b5534fc70442bdc3f6ce2e91c09c3044672e3a5dfcf0e18313","raw_frame":"{\"market\":\"0x3b40066b5cf3871a2f6237c5628bd8092a206aa998558ac5ec13c4483e31e160\", \"price_changes\":[{\"asset_id\":\"110216635572655435074987471276357323571387854733835379371586402147734167783946\", \"price\":\"0.05\", \"size\":\"5325\", \"side\":\"BUY\", \"hash\":\"d2ce36eb2e10f08ee1893a6da807c80437fe72b3\", \"best_bid\":\"0.52\", \"best_ask\":\"0.53\"}, {\"asset_id\":\"14766054693214075530629349735273995982307625376442606753688071083149620216746\", \"price\":\"0.95\", \"size\":\"5325\", \"side\":\"SELL\", \"hash\":\"9ba8fcb8914b6dd1ae68c86c07bab7c81d21e677\", \"best_bid\":\"0.47\", \"best_ask\":\"0.48\"}], \"timestamp\":\"1785129934001\", \"event_type\":\"price_change\"}","received_at":"2026-07-27T05:25:33.967417Z","replay_eligible":false,"resync_asset_ids":["110216635572655435074987471276357323571387854733835379371586402147734167783946","14766054693214075530629349735273995982307625376442606753688071083149620216746"],"resync_asset_watermarks_ns":{"110216635572655435074987471276357323571387854733835379371586402147734167783946":1785129938639000000,"14766054693214075530629349735273995982307625376442606753688071083149620216746":1785129938639000000},"resync_buffered":true,"resync_status":"success","resync_watermark_ns":1785129938639000000,"schema_version":"clob-market-ws.price_change.v1","sequence":null,"server_hash":null,"server_timestamp":"1785129934001","session_id":"502006c5cfcd437296561ea750c9ec8b","source":"clob_market_ws"},"received_at":"2026-07-27T05:25:33.967417Z","record_id":"1ae87b5a9148a152104dbda5b0afa448b1c60a849e1cede1fedb768efb325a8b","schema_fingerprint":"c990bfb60716dbc222c50044da5e7a1f30d07e145848f9bd19c7d4fa0162d2eb","schema_version":"edge-lab-recorder.raw.v1","sequence":null,"source":"clob_market_ws"}
{"event_at":"2026-07-27T05:25:34.001000Z","event_fingerprint":"a4b267ba9baf0b0f4e6ee62c5d59fa7e4ab765a473f877db7b40a049de35f1bc","payload":{"connection_id":"efc69d3132f1467b8e898a382b23ac0d","event_at":"2026-07-27T05:25:34.001000Z","event_type":"price_change","frame_hash":"b69e78bc935f1838d2973dab57b238c865850dcbc08f092ae9922831ad184298","frame_index":0,"kind":"quarantine","monotonic_ns":231917207505583,"payload":{"event_type":"price_change","market":"0x3b40066b5cf3871a2f6237c5628bd8092a206aa998558ac5ec13c4483e31e160","price_changes":[{"asset_id":"110216635572655435074987471276357323571387854733835379371586402147734167783946","best_ask":"0.53","best_bid":"0.52","hash":"d2ce36eb2e10f08ee1893a6da807c80437fe72b3","price":"0.13","side":"BUY","size":"20"},{"asset_id":"14766054693214075530629349735273995982307625376442606753688071083149620216746","best_ask":"0.48","best_bid":"0.47","hash":"9ba8fcb8914b6dd1ae68c86c07bab7c81d21e677","price":"0.87","side":"SELL","size":"20"}],"timestamp":"1785129934001"},"payload_hash":"a1f0fce02223ea30fa82ea0460c3ba5b608c73c5df175755a192d16c06ed09ee","raw_frame":"{\"market\":\"0x3b40066b5cf3871a2f6237c5628bd8092a206aa998558ac5ec13c4483e31e160\", \"price_changes\":[{\"asset_id\":\"110216635572655435074987471276357323571387854733835379371586402147734167783946\", \"price\":\"0.13\", \"size\":\"20\", \"side\":\"BUY\", \"hash\":\"d2ce36eb2e10f08ee1893a6da807c80437fe72b3\", \"best_bid\":\"0.52\", \"best_ask\":\"0.53\"}, {\"asset_id\":\"14766054693214075530629349735273995982307625376442606753688071083149620216746\", \"price\":\"0.87\", \"size\":\"20\", \"side\":\"SELL\", \"hash\":\"9ba8fcb8914b6dd1ae68c86c07bab7c81d21e677\", \"best_bid\":\"0.47\", \"best_ask\":\"0.48\"}], \"timestamp\":\"1785129934001\", \"event_type\":\"price_change\"}","received_at":"2026-07-27T05:25:33.967444Z","replay_eligible":false,"resync_asset_ids":["110216635572655435074987471276357323571387854733835379371586402147734167783946","14766054693214075530629349735273995982307625376442606753688071083149620216746"],"resync_asset_watermarks_ns":{"110216635572655435074987471276357323571387854733835379371586402147734167783946":1785129938639000000,"14766054693214075530629349735273995982307625376442606753688071083149620216746":1785129938639000000},"resync_buffered":true,"resync_status":"success","resync_watermark_ns":1785129938639000000,"schema_version":"clob-market-ws.price_change.v1","sequence":null,"server_hash":null,"server_timestamp":"1785129934001","session_id":"502006c5cfcd437296561ea750c9ec8b","source":"clob_market_ws"},"received_at":"2026-07-27T05:25:33.967444Z","record_id":"6ae7781e8aa151b63bd9bcc389348bc7e435499d0c88dc4c5787af740e7c4aab","schema_fingerprint":"c990bfb60716dbc222c50044da5e7a1f30d07e145848f9bd19c7d4fa0162d2eb","schema_version":"edge-lab-recorder.raw.v1","sequence":null,"source":"clob_market_ws"}
{"event_at":"2026-07-27T05:25:34.001000Z","event_fingerprint":"2813ff346134230d502cc9154a3281b8142906f817845d565cf3bee01e5a1866","payload":{"connection_id":"efc69d3132f1467b8e898a382b23ac0d","event_at":"2026-07-27T05:25:34.001000Z","event_type":"price_change","frame_hash":"dd2b6cf6d6cf538fa027923eeaf76aab1fd285ce153a5196a4bfa41ef6d969e2","frame_index":0,"kind":"quarantine","monotonic_ns":231917207525875,"payload":{"event_type":"price_change","market":"0x3b40066b5cf3871a2f6237c5628bd8092a206aa998558ac5ec13c4483e31e160","price_changes":[{"asset_id":"110216635572655435074987471276357323571387854733835379371586402147734167783946","best_ask":"0.53","best_bid":"0.52","hash":"d2ce36eb2e10f08ee1893a6da807c80437fe72b3","price":"0.01","side":"BUY","size":"97385.02"},{"asset_id":"14766054693214075530629349735273995982307625376442606753688071083149620216746","best_ask":"0.48","best_bid":"0.47","hash":"9ba8fcb8914b6dd1ae68c86c07bab7c81d21e677","price":"0.99","side":"SELL","size":"97385.02"}],"timestamp":"1785129934001"},"payload_hash":"1a43826a1b2509cb02f2e258d3470c9acebf957cd8c42198c8825d317ea82d19","raw_frame":"{\"market\":\"0x3b40066b5cf3871a2f6237c5628bd8092a206aa998558ac5ec13c4483e31e160\", \"price_changes\":[{\"asset_id\":\"110216635572655435074987471276357323571387854733835379371586402147734167783946\", \"price\":\"0.01\", \"size\":\"97385.02\", \"side\":\"BUY\", \"hash\":\"d2ce36eb2e10f08ee1893a6da807c80437fe72b3\", \"best_bid\":\"0.52\", \"best_ask\":\"0.53\"}, {\"asset_id\":\"14766054693214075530629349735273995982307625376442606753688071083149620216746\", \"price\":\"0.99\", \"size\":\"97385.02\", \"side\":\"SELL\", \"hash\":\"9ba8fcb8914b6dd1ae68c86c07bab7c81d21e677\", \"best_bid\":\"0.47\", \"best_ask\":\"0.48\"}], \"timestamp\":\"1785129934001\", \"event_type\":\"price_change\"}","received_at":"2026-07-27T05:25:33.967465Z","replay_eligible":false,"resync_asset_ids":["110216635572655435074987471276357323571387854733835379371586402147734167783946","14766054693214075530629349735273995982307625376442606753688071083149620216746"],"resync_asset_watermarks_ns":{"110216635572655435074987471276357323571387854733835379371586402147734167783946":1785129938639000000,"14766054693214075530629349735273995982307625376442606753688071083149620216746":1785129938639000000},"resync_buffered":true,"resync_status":"success","resync_watermark_ns":1785129938639000000,"schema_version":"clob-market-ws.price_change.v1","sequence":null,"server_hash":null,"server_timestamp":"1785129934001","session_id":"502006c5cfcd437296561ea750c9ec8b","source":"clob_market_ws"},"received_at":"2026-07-27T05:25:33.967465Z","record_id":"fd64d375a9eeae8c4b744ab6e7a2a8086dc3db2be9aa1095110dbbb1e8370f10","schema_fingerprint":"c990bfb60716dbc222c50044da5e7a1f30d07e145848f9bd19c7d4fa0162d2eb","schema_version":"edge-lab-recorder.raw.v1","sequence":null,"source":"clob_market_ws"}
{"event_at":"2026-07-27T05:25:34.002000Z","event_fingerprint":"1759ae064dac46a72554174a04b64b69a36edec42f3721a84c98fa8c6fc2e28c","payload":{"connection_id":"efc69d3132f1467b8e898a382b23ac0d","event_at":"2026-07-27T05:25:34.002000Z","event_type":"price_change","frame_hash":"9ee6e4890ec284beceda861e0ffd7b27263b90238f73d412152da9a6045b2c75","frame_index":0,"kind":"quarantine","monotonic_ns":231917211264083,"payload":{"event_type":"price_change","market":"0x3b40066b5cf3871a2f6237c5628bd8092a206aa998558ac5ec13c4483e31e160","price_changes":[{"asset_id":"14766054693214075530629349735273995982307625376442606753688071083149620216746","best_ask":"0.48","best_bid":"0.47","hash":"402ec0135ae0a854aa7d994ca2efafd1831b03b2","price":"0.05","side":"BUY","size":"5325"},{"asset_id":"110216635572655435074987471276357323571387854733835379371586402147734167783946","best_ask":"0.53","best_bid":"0.52","hash":"6bed8992f56c696d89ce3fbb3d89fd85238b2a20","price":"0.95","side":"SELL","size":"5325"}],"timestamp":"1785129934002"},"payload_hash":"c098cf8134b83de35561291b421cd664d64dca6072b81285bc8820580a167d26","raw_frame":"{\"market\":\"0x3b40066b5cf3871a2f6237c5628bd8092a206aa998558ac5ec13c4483e31e160\", \"price_changes\":[{\"asset_id\":\"14766054693214075530629349735273995982307625376442606753688071083149620216746\", \"price\":\"0.05\", \"size\":\"5325\", \"side\":\"BUY\", \"hash\":\"402ec0135ae0a854aa7d994ca2efafd1831b03b2\", \"best_bid\":\"0.47\", \"best_ask\":\"0.48\"}, {\"asset_id\":\"110216635572655435074987471276357323571387854733835379371586402147734167783946\", \"price\":\"0.95\", \"size\":\"5325\", \"side\":\"SELL\", \"hash\":\"6bed8992f56c696d89ce3fbb3d89fd85238b2a20\", \"best_bid\":\"0.52\", \"best_ask\":\"0.53\"}], \"timestamp\":\"1785129934002\", \"event_type\":\"price_change\"}","received_at":"2026-07-27T05:25:33.971201Z","replay_eligible":false,"resync_asset_ids":["110216635572655435074987471276357323571387854733835379371586402147734167783946","14766054693214075530629349735273995982307625376442606753688071083149620216746"],"resync_asset_watermarks_ns":{"110216635572655435074987471276357323571387854733835379371586402147734167783946":1785129938639000000,"14766054693214075530629349735273995982307625376442606753688071083149620216746":1785129938639000000},"resync_buffered":true,"resync_status":"success","resync_watermark_ns":1785129938639000000,"schema_version":"clob-market-ws.price_change.v1","sequence":null,"server_hash":null,"server_timestamp":"1785129934002","session_id":"502006c5cfcd437296561ea750c9ec8b","source":"clob_market_ws"},"received_at":"2026-07-27T05:25:33.971201Z","record_id":"e4d5c7f54372c6905a131d813b1dc390c7a8b400260e7749bfc8097e8fdb41d2","schema_fingerprint":"c990bfb60716dbc222c50044da5e7a1f30d07e145848f9bd19c7d4fa0162d2eb","schema_version":"edge-lab-recorder.raw.v1","sequence":null,"source":"clob_market_ws"}
{"event_at":"2026-07-27T05:25:34.010000Z","event_fingerprint":"7155909b61bf19181057e615e5fbe65924592c55671d8432b02ebee99120a945","payload":{"connection_id":"efc69d3132f1467b8e898a382b23ac0d","event_at":"2026-07-27T05:25:34.010000Z","event_type":"price_change","frame_hash":"83a47569c4c88553b89f403a7e202708f5b918675dbbd296d78ef144d7382ba2","frame_index":0,"kind":"quarantine","monotonic_ns":231917211287791,"payload":{"event_type":"price_change","market":"0x3b40066b5cf3871a2f6237c5628bd8092a206aa998558ac5ec13c4483e31e160","price_changes":[{"asset_id":"14766054693214075530629349735273995982307625376442606753688071083149620216746","best_ask":"0.48","best_bid":"0.47","hash":"6597540c569d7f5e33564361312b116008e3b876","price":"0.01","side":"BUY","size":"97390.02"},{"asset_id":"110216635572655435074987471276357323571387854733835379371586402147734167783946","best_ask":"0.53","best_bid":"0.52","hash":"017962661440c0d092770a29a96c8971543a7b5c","price":"0.99","side":"SELL","size":"97390.02"}],"timestamp":"1785129934010"},"payload_hash":"32107a0d2fa04ec3aea254db4a605a23826d51622bdf26bc51a2351c73c9ace1","raw_frame":"{\"market\":\"0x3b40066b5cf3871a2f6237c5628bd8092a206aa998558ac5ec13c4483e31e160\", \"price_changes\":[{\"asset_id\":\"14766054693214075530629349735273995982307625376442606753688071083149620216746\", \"price\":\"0.01\", \"size\":\"97390.02\", \"side\":\"BUY\", \"hash\":\"6597540c569d7f5e33564361312b116008e3b876\", \"best_bid\":\"0.47\", \"best_ask\":\"0.48\"}, {\"asset_id\":\"110216635572655435074987471276357323571387854733835379371586402147734167783946\", \"price\":\"0.99\", \"size\":\"97390.02\", \"side\":\"SELL\", \"hash\":\"017962661440c0d092770a29a96c8971543a7b5c\", \"best_bid\":\"0.52\", \"best_ask\":\"0.53\"}], \"timestamp\":\"1785129934010\", \"event_type\":\"price_change\"}","received_at":"2026-07-27T05:25:33.971227Z","replay_eligible":false,"resync_asset_ids":["110216635572655435074987471276357323571387854733835379371586402147734167783946","14766054693214075530629349735273995982307625376442606753688071083149620216746"],"resync_asset_watermarks_ns":{"110216635572655435074987471276357323571387854733835379371586402147734167783946":1785129938639000000,"14766054693214075530629349735273995982307625376442606753688071083149620216746":1785129938639000000},"resync_buffered":true,"resync_status":"success","resync_watermark_ns":1785129938639000000,"schema_version":"clob-market-ws.price_change.v1","sequence":null,"server_hash":null,"server_timestamp":"1785129934010","session_id":"502006c5cfcd437296561ea750c9ec8b","source":"clob_market_ws"},"received_at":"2026-07-27T05:25:33.971227Z","record_id":"0daace9e6f4e6b2c88bbed8528ffa5d046efec97f30e131bd7254492ca2580db","schema_fingerprint":"c990bfb60716dbc222c50044da5e7a1f30d07e145848f9bd19c7d4fa0162d2eb","schema_version":"edge-lab-recorder.raw.v1","sequence":null,"source":"clob_market_ws"}
{"event_at":"2026-07-27T05:25:34.010000Z","event_fingerprint":"a7de1d93e0749df7cba74a7661ba0612cd0a61217d188bfd04ef94d4c7c43585","payload":{"connection_id":"efc69d3132f1467b8e898a382b23ac0d","event_at":"2026-07-27T05:25:34.010000Z","event_type":"price_change","frame_hash":"0e3cea375e358d2cbcfb08503d3c5150c945417743fab943254f5a3115adaad2","frame_index":0,"kind":"quarantine","monotonic_ns":231917211315333,"payload":{"event_type":"price_change","market":"0x3b40066b5cf3871a2f6237c5628bd8092a206aa998558ac5ec13c4483e31e160","price_changes":[{"asset_id":"14766054693214075530629349735273995982307625376442606753688071083149620216746","best_ask":"0.48","best_bid":"0.47","hash":"6597540c569d7f5e33564361312b116008e3b876","price":"0.13","side":"BUY","size":"20"},{"asset_id":"110216635572655435074987471276357323571387854733835379371586402147734167783946","best_ask":"0.53","best_bid":"0.52","hash":"017962661440c0d092770a29a96c8971543a7b5c","price":"0.87","side":"SELL","size":"20"}],"timestamp":"1785129934010"},"payload_hash":"8ea5fa4f331c2897e78aa9a5d149928a921f5ed54ebbadb3dfa52685880df89d","raw_frame":"{\"market\":\"0x3b40066b5cf3871a2f6237c5628bd8092a206aa998558ac5ec13c4483e31e160\", \"price_changes\":[{\"asset_id\":\"14766054693214075530629349735273995982307625376442606753688071083149620216746\", \"price\":\"0.13\", \"size\":\"20\", \"side\":\"BUY\", \"hash\":\"6597540c569d7f5e33564361312b116008e3b876\", \"best_bid\":\"0.47\", \"best_ask\":\"0.48\"}, {\"asset_id\":\"110216635572655435074987471276357323571387854733835379371586402147734167783946\", \"price\":\"0.87\", \"size\":\"20\", \"side\":\"SELL\", \"hash\":\"017962661440c0d092770a29a96c8971543a7b5c\", \"best_bid\":\"0.52\", \"best_ask\":\"0.53\"}], \"timestamp\":\"1785129934010\", \"event_type\":\"price_change\"}","received_at":"2026-07-27T05:25:33.971254Z","replay_eligible":false,"resync_asset_ids":["110216635572655435074987471276357323571387854733835379371586402147734167783946","14766054693214075530629349735273995982307625376442606753688071083149620216746"],"resync_asset_watermarks_ns":{"110216635572655435074987471276357323571387854733835379371586402147734167783946":1785129938639000000,"14766054693214075530629349735273995982307625376442606753688071083149620216746":1785129938639000000},"resync_buffered":true,"resync_status":"success","resync_watermark_ns":1785129938639000000,"schema_version":"clob-market-ws.price_change.v1","sequence":null,"server_hash":null,"server_timestamp":"1785129934010","session_id":"502006c5cfcd437296561ea750c9ec8b","source":"clob_market_ws"},"received_at":"2026-07-27T05:25:33.971254Z","record_id":"e6373460f96ad7426ca030972638c89f4a528a706383a2aae187f81e58edc806","schema_fingerprint":"c990bfb60716dbc222c50044da5e7a1f30d07e145848f9bd19c7d4fa0162d2eb","schema_version":"edge-lab-recorder.raw.v1","sequence":null,"source":"clob_market_ws"}
{"event_at":"2026-07-27T05:25:34.010000Z","event_fingerprint":"cbeda13589b46ef299574082c59c0c534c690c3d4bfb0efdff9d200f97322839","payload":{"connection_id":"efc69d3132f1467b8e898a382b23ac0d","event_at":"2026-07-27T05:25:34.010000Z","event_type":"price_change","frame_hash":"33e205abf955760e2a4c92b465c76c6517cebc49983165801aa013b615286b21","frame_index":0,"kind":"quarantine","monotonic_ns":231917211334166,"payload":{"event_type":"price_change","market":"0x3b40066b5cf3871a2f6237c5628bd8092a206aa998558ac5ec13c4483e31e160","price_changes":[{"asset_id":"110216635572655435074987471276357323571387854733835379371586402147734167783946","best_ask":"0.53","best_bid":"0.52","hash":"017962661440c0d092770a29a96c8971543a7b5c","price":"0.02","side":"BUY","size":"16590"},{"asset_id":"14766054693214075530629349735273995982307625376442606753688071083149620216746","best_ask":"0.48","best_bid":"0.47","hash":"6597540c569d7f5e33564361312b116008e3b876","price":"0.98","side":"SELL","size":"16590"}],"timestamp":"1785129934010"},"payload_hash":"cc02c4790d547590c7fffd9dd14cee28fd881a44cd4024fd6afb72c93c06c906","raw_frame":"{\"market\":\"0x3b40066b5cf3871a2f6237c5628bd8092a206aa998558ac5ec13c4483e31e160\", \"price_changes\":[{\"asset_id\":\"110216635572655435074987471276357323571387854733835379371586402147734167783946\", \"price\":\"0.02\", \"size\":\"16590\", \"side\":\"BUY\", \"hash\":\"017962661440c0d092770a29a96c8971543a7b5c\", \"best_bid\":\"0.52\", \"best_ask\":\"0.53\"}, {\"asset_id\":\"14766054693214075530629349735273995982307625376442606753688071083149620216746\", \"price\":\"0.98\", \"size\":\"16590\", \"side\":\"SELL\", \"hash\":\"6597540c569d7f5e33564361312b116008e3b876\", \"best_bid\":\"0.47\", \"best_ask\":\"0.48\"}], \"timestamp\":\"1785129934010\", \"event_type\":\"price_change\"}","received_at":"2026-07-27T05:25:33.971274Z","replay_eligible":false,"resync_asset_ids":["110216635572655435074987471276357323571387854733835379371586402147734167783946","14766054693214075530629349735273995982307625376442606753688071083149620216746"],"resync_asset_watermarks_ns":{"110216635572655435074987471276357323571387854733835379371586402147734167783946":1785129938639000000,"14766054693214075530629349735273995982307625376442606753688071083149620216746":1785129938639000000},"resync_buffered":true,"resync_status":"success","resync_watermark_ns":1785129938639000000,"schema_version":"clob-market-ws.price_change.v1","sequence":null,"server_hash":null,"server_timestamp":"1785129934010","session_id":"502006c5cfcd437296561ea750c9ec8b","source":"clob_market_ws"},"received_at":"2026-07-27T05:25:33.971274Z","record_id":"3957515a34708b4772d25c25425b13026415406994c3c3b46e53d231b3c23294","schema_fingerprint":"c990bfb60716dbc222c50044da5e7a1f30d07e145848f9bd19c7d4fa0162d2eb","schema_version":"edge-lab-recorder.raw.v1","sequence":null,"source":"clob_market_ws"}
{"event_at":"2026-07-27T05:25:34.011000Z","event_fingerprint":"32570f0daa6277401a139cc901720e54bbbc073f78acdd9a3acf1dd0abd2c9a5","payload":{"connection_id":"efc69d3132f1467b8e898a382b23ac0d","event_at":"2026-07-27T05:25:34.011000Z","event_type":"price_change","frame_hash":"1371d8279ec7c89eeeff5d8c5dae2c458e9c19678380d2ad6760cfcb24cf65ac","frame_index":0,"kind":"quarantine","monotonic_ns":231917211352750,"payload":{"event_type":"price_change","market":"0x3b40066b5cf3871a2f6237c5628bd8092a206aa998558ac5ec13c4483e31e160","price_changes":[{"asset_id":"14766054693214075530629349735273995982307625376442606753688071083149620216746","best_ask":"0.48","best_bid":"0.47","hash":"f1e07068931ce2a3bb5c98f5da48e4503cc87e3f","price":"0.02","side":"BUY","size":"16590"},{"asset_id":"110216635572655435074987471276357323571387854733835379371586402147734167783946","best_ask":"0.53","best_bid":"0.52","hash":"5f748441f318f12e774e39cc4c4679ded11d3a7b","price":"0.98","side":"SELL","size":"16590"}],"timestamp":"1785129934011"},"payload_hash":"2a6d5f70dc8e5c3c900b78cdb3b73cc4d7ef34a4ff88d12e4c36da2cba59fc26","raw_frame":"{\"market\":\"0x3b40066b5cf3871a2f6237c5628bd8092a206aa998558ac5ec13c4483e31e160\", \"price_changes\":[{\"asset_id\":\"14766054693214075530629349735273995982307625376442606753688071083149620216746\", \"price\":\"0.02\", \"size\":\"16590\", \"side\":\"BUY\", \"hash\":\"f1e07068931ce2a3bb5c98f5da48e4503cc87e3f\", \"best_bid\":\"0.47\", \"best_ask\":\"0.48\"}, {\"asset_id\":\"110216635572655435074987471276357323571387854733835379371586402147734167783946\", \"price\":\"0.98\", \"size\":\"16590\", \"side\":\"SELL\", \"hash\":\"5f748441f318f12e774e39cc4c4679ded11d3a7b\", \"best_bid\":\"0.52\", \"best_ask\":\"0.53\"}], \"timestamp\":\"1785129934011\", \"event_type\":\"price_change\"}","received_at":"2026-07-27T05:25:33.971293Z","replay_eligible":false,"resync_asset_ids":["110216635572655435074987471276357323571387854733835379371586402147734167783946","14766054693214075530629349735273995982307625376442606753688071083149620216746"],"resync_asset_watermarks_ns":{"110216635572655435074987471276357323571387854733835379371586402147734167783946":1785129938639000000,"14766054693214075530629349735273995982307625376442606753688071083149620216746":1785129938639000000},"resync_buffered":true,"resync_status":"success","resync_watermark_ns":1785129938639000000,"schema_version":"clob-market-ws.price_change.v1","sequence":null,"server_hash":null,"server_timestamp":"1785129934011","session_id":"502006c5cfcd437296561ea750c9ec8b","source":"clob_market_ws"},"received_at":"2026-07-27T05:25:33.971293Z","record_id":"560bc2ffd9572c7b8aeb8793a2f1993514215450b66d6211f579b1cc43333b58","schema_fingerprint":"c990bfb60716dbc222c50044da5e7a1f30d07e145848f9bd19c7d4fa0162d2eb","schema_version":"edge-lab-recorder.raw.v1","sequence":null,"source":"clob_market_ws"}
{"event_at":"2026-07-27T05:25:34.070000Z","event_fingerprint":"27b3763e370f9e7ee5c289a35eb48d31308e855b7d9a146025cfee5453e37440","payload":{"connection_id":"efc69d3132f1467b8e898a382b23ac0d","event_at":"2026-07-27T05:25:34.070000Z","event_type":"price_change","frame_hash":"c6e6d1fa328265155fe0f4a0c19bb7d5acca12dd24200b31eddf293421377ed7","frame_index":0,"kind":"quarantine","monotonic_ns":231917270599166,"payload":{"event_type":"price_change","market":"0x3b40066b5cf3871a2f6237c5628bd8092a206aa998558ac5ec13c4483e31e160","price_changes":[{"asset_id":"14766054693214075530629349735273995982307625376442606753688071083149620216746","best_ask":"0.48","best_bid":"0.47","hash":"fde639b76fa80f609818b1fdf03c5f3dcd585cff","price":"0.01","side":"BUY","size":"97385.02"},{"asset_id":"110216635572655435074987471276357323571387854733835379371586402147734167783946","best_ask":"0.53","best_bid":"0.52","hash":"0f36c4925b1bc34aad164408a9726e8d03aa3c4e","price":"0.99","side":"SELL","size":"97385.02"}],"timestamp":"1785129934070"},"payload_hash":"86bd168c0b01ed731b190a59c6fac49ed2f69d1a17a51504baa69ee2dc63bc22","raw_frame":"{\"market\":\"0x3b40066b5cf3871a2f6237c5628bd8092a206aa998558ac5ec13c4483e31e160\", \"price_changes\":[{\"asset_id\":\"14766054693214075530629349735273995982307625376442606753688071083149620216746\", \"price\":\"0.01\", \"size\":\"97385.02\", \"side\":\"BUY\", \"hash\":\"fde639b76fa80f609818b1fdf03c5f3dcd585cff\", \"best_bid\":\"0.47\", \"best_ask\":\"0.48\"}, {\"asset_id\":\"110216635572655435074987471276357323571387854733835379371586402147734167783946\", \"price\":\"0.99\", \"size\":\"97385.02\", \"side\":\"SELL\", \"hash\":\"0f36c4925b1bc34aad164408a9726e8d03aa3c4e\", \"best_bid\":\"0.52\", \"best_ask\":\"0.53\"}], \"timestamp\":\"1785129934070\", \"event_type\":\"price_change\"}","received_at":"2026-07-27T05:25:34.030534Z","replay_eligible":false,"resync_asset_ids":["110216635572655435074987471276357323571387854733835379371586402147734167783946","14766054693214075530629349735273995982307625376442606753688071083149620216746"],"resync_asset_watermarks_ns":{"110216635572655435074987471276357323571387854733835379371586402147734167783946":1785129938639000000,"14766054693214075530629349735273995982307625376442606753688071083149620216746":1785129938639000000},"resync_buffered":true,"resync_status":"success","resync_watermark_ns":1785129938639000000,"schema_version":"clob-market-ws.price_change.v1","sequence":null,"server_hash":null,"server_timestamp":"1785129934070","session_id":"502006c5cfcd437296561ea750c9ec8b","source":"clob_market_ws"},"received_at":"2026-07-27T05:25:34.030534Z","record_id":"1210a172496b44dd66441f067fbbc51caf34a75f8ce92099e814da29721147fa","schema_fingerprint":"c990bfb60716dbc222c50044da5e7a1f30d07e145848f9bd19c7d4fa0162d2eb","schema_version":"edge-lab-recorder.raw.v1","sequence":null,"source":"clob_market_ws"}
{"event_at":"2026-07-27T05:25:37.491000Z","event_fingerprint":"70ead5efc98bf7c1a3178798ab4388676ab11b878063eb85a4134a7ba0bddc44","payload":{"connection_id":"efc69d3132f1467b8e898a382b23ac0d","event_at":"2026-07-27T05:25:37.491000Z","event_type":"price_change","frame_hash":"05c16d5284ae7f7f0ee0db56d643efa2486e64f446c7bed0cbc03ec2dde559bb","frame_index":0,"kind":"quarantine","monotonic_ns":231920692291416,"payload":{"event_type":"price_change","market":"0x3b40066b5cf3871a2f6237c5628bd8092a206aa998558ac5ec13c4483e31e160","price_changes":[{"asset_id":"14766054693214075530629349735273995982307625376442606753688071083149620216746","best_ask":"0.48","best_bid":"0.47","hash":"1c50edee568817593d4a07caec84b77d81cf0839","price":"0.34","side":"BUY","size":"175"},{"asset_id":"110216635572655435074987471276357323571387854733835379371586402147734167783946","best_ask":"0.53","best_bid":"0.52","hash":"5260b68f383534427b8d72e9f7d42658ea08a650","price":"0.66","side":"SELL","size":"175"}],"timestamp":"1785129937491"},"payload_hash":"804d07a4c688cb08bf9252a14b6574574c268878a386849c81ea73c79cb03524","raw_frame":"{\"market\":\"0x3b40066b5cf3871a2f6237c5628bd8092a206aa998558ac5ec13c4483e31e160\", \"price_changes\":[{\"asset_id\":\"14766054693214075530629349735273995982307625376442606753688071083149620216746\", \"price\":\"0.34\", \"size\":\"175\", \"side\":\"BUY\", \"hash\":\"1c50edee568817593d4a07caec84b77d81cf0839\", \"best_bid\":\"0.47\", \"best_ask\":\"0.48\"}, {\"asset_id\":\"110216635572655435074987471276357323571387854733835379371586402147734167783946\", \"price\":\"0.66\", \"size\":\"175\", \"side\":\"SELL\", \"hash\":\"5260b68f383534427b8d72e9f7d42658ea08a650\", \"best_bid\":\"0.52\", \"best_ask\":\"0.53\"}], \"timestamp\":\"1785129937491\", \"event_type\":\"price_change\"}","received_at":"2026-07-27T05:25:37.452253Z","replay_eligible":false,"resync_asset_ids":["110216635572655435074987471276357323571387854733835379371586402147734167783946","14766054693214075530629349735273995982307625376442606753688071083149620216746"],"resync_asset_watermarks_ns":{"110216635572655435074987471276357323571387854733835379371586402147734167783946":1785129938639000000,"14766054693214075530629349735273995982307625376442606753688071083149620216746":1785129938639000000},"resync_buffered":true,"resync_status":"success","resync_watermark_ns":1785129938639000000,"schema_version":"clob-market-ws.price_change.v1","sequence":null,"server_hash":null,"server_timestamp":"1785129937491","session_id":"502006c5cfcd437296561ea750c9ec8b","source":"clob_market_ws"},"received_at":"2026-07-27T05:25:37.452253Z","record_id":"2a2a2bdc68edce6f90eb3e197d51bfef785988cf99c4eaff3d45db0eae1b6574","schema_fingerprint":"c990bfb60716dbc222c50044da5e7a1f30d07e145848f9bd19c7d4fa0162d2eb","schema_version":"edge-lab-recorder.raw.v1","sequence":null,"source":"clob_market_ws"}
{"event_at":"2026-07-27T05:25:37.491000Z","event_fingerprint":"1266f81e140433585b4c285b098ad79fcec8a2d275ebb00c01d65f0b3ca92ca6","payload":{"connection_id":"efc69d3132f1467b8e898a382b23ac0d","event_at":"2026-07-27T05:25:37.491000Z","event_type":"price_change","frame_hash":"b3416ec856d80f62f4f9415aa82c933dbcbc7521fb3fe903f467cb6554f4e407","frame_index":0,"kind":"quarantine","monotonic_ns":231920692315083,"payload":{"event_type":"price_change","market":"0x3b40066b5cf3871a2f6237c5628bd8092a206aa998558ac5ec13c4483e31e160","price_changes":[{"asset_id":"14766054693214075530629349735273995982307625376442606753688071083149620216746","best_ask":"0.48","best_bid":"0.47","hash":"1c50edee568817593d4a07caec84b77d81cf0839","price":"0.35","side":"BUY","size":"10"},{"asset_id":"110216635572655435074987471276357323571387854733835379371586402147734167783946","best_ask":"0.53","best_bid":"0.52","hash":"5260b68f383534427b8d72e9f7d42658ea08a650","price":"0.65","side":"SELL","size":"10"}],"timestamp":"1785129937491"},"payload_hash":"a1141b8568669d0b29cd1ee0fe2c39225e796d29172521da8e3aa43c5ba2e08a","raw_frame":"{\"market\":\"0x3b40066b5cf3871a2f6237c5628bd8092a206aa998558ac5ec13c4483e31e160\", \"price_changes\":[{\"asset_id\":\"14766054693214075530629349735273995982307625376442606753688071083149620216746\", \"price\":\"0.35\", \"size\":\"10\", \"side\":\"BUY\", \"hash\":\"1c50edee568817593d4a07caec84b77d81cf0839\", \"best_bid\":\"0.47\", \"best_ask\":\"0.48\"}, {\"asset_id\":\"110216635572655435074987471276357323571387854733835379371586402147734167783946\", \"price\":\"0.65\", \"size\":\"10\", \"side\":\"SELL\", \"hash\":\"5260b68f383534427b8d72e9f7d42658ea08a650\", \"best_bid\":\"0.52\", \"best_ask\":\"0.53\"}], \"timestamp\":\"1785129937491\", \"event_type\":\"price_change\"}","received_at":"2026-07-27T05:25:37.452278Z","replay_eligible":false,"resync_asset_ids":["110216635572655435074987471276357323571387854733835379371586402147734167783946","14766054693214075530629349735273995982307625376442606753688071083149620216746"],"resync_asset_watermarks_ns":{"110216635572655435074987471276357323571387854733835379371586402147734167783946":1785129938639000000,"14766054693214075530629349735273995982307625376442606753688071083149620216746":1785129938639000000},"resync_buffered":true,"resync_status":"success","resync_watermark_ns":1785129938639000000,"schema_version":"clob-market-ws.price_change.v1","sequence":null,"server_hash":null,"server_timestamp":"1785129937491","session_id":"502006c5cfcd437296561ea750c9ec8b","source":"clob_market_ws"},"received_at":"2026-07-27T05:25:37.452278Z","record_id":"ab989d1cad832de6895cc7999352bc43ec8aa0fd8459b7b1e1fa4f92dfd32804","schema_fingerprint":"c990bfb60716dbc222c50044da5e7a1f30d07e145848f9bd19c7d4fa0162d2eb","schema_version":"edge-lab-recorder.raw.v1","sequence":null,"source":"clob_market_ws"}
{"event_at":"2026-07-27T05:25:37.491000Z","event_fingerprint":"bd68b7a687502fcea2e57c3bedbca40e7a69171632a5b8a5e146367d98dc4b31","payload":{"connection_id":"efc69d3132f1467b8e898a382b23ac0d","event_at":"2026-07-27T05:25:37.491000Z","event_type":"price_change","frame_hash":"3803eae89d29edd4f4a4fb334d986f095940568747f3e27087168c266cbb4563","frame_index":0,"kind":"quarantine","monotonic_ns":231920692335875,"payload":{"event_type":"price_change","market":"0x3b40066b5cf3871a2f6237c5628bd8092a206aa998558ac5ec13c4483e31e160","price_changes":[{"asset_id":"14766054693214075530629349735273995982307625376442606753688071083149620216746","best_ask":"0.48","best_bid":"0.47","hash":"1c50edee568817593d4a07caec84b77d81cf0839","price":"0.36","side":"BUY","size":"640"},{"asset_id":"110216635572655435074987471276357323571387854733835379371586402147734167783946","best_ask":"0.53","best_bid":"0.52","hash":"5260b68f383534427b8d72e9f7d42658ea08a650","price":"0.64","side":"SELL","size":"640"}],"timestamp":"1785129937491"},"payload_hash":"0f2be2c8a58d2226074d23f44014b4993cd10b1e79b71939af950b717ec90e6e","raw_frame":"{\"market\":\"0x3b40066b5cf3871a2f6237c5628bd8092a206aa998558ac5ec13c4483e31e160\", \"price_changes\":[{\"asset_id\":\"14766054693214075530629349735273995982307625376442606753688071083149620216746\", \"price\":\"0.36\", \"size\":\"640\", \"side\":\"BUY\", \"hash\":\"1c50edee568817593d4a07caec84b77d81cf0839\", \"best_bid\":\"0.47\", \"best_ask\":\"0.48\"}, {\"asset_id\":\"110216635572655435074987471276357323571387854733835379371586402147734167783946\", \"price\":\"0.64\", \"size\":\"640\", \"side\":\"SELL\", \"hash\":\"5260b68f383534427b8d72e9f7d42658ea08a650\", \"best_bid\":\"0.52\", \"best_ask\":\"0.53\"}], \"timestamp\":\"1785129937491\", \"event_type\":\"price_change\"}","received_at":"2026-07-27T05:25:37.452299Z","replay_eligible":false,"resync_asset_ids":["110216635572655435074987471276357323571387854733835379371586402147734167783946","14766054693214075530629349735273995982307625376442606753688071083149620216746"],"resync_asset_watermarks_ns":{"110216635572655435074987471276357323571387854733835379371586402147734167783946":1785129938639000000,"14766054693214075530629349735273995982307625376442606753688071083149620216746":1785129938639000000},"resync_buffered":true,"resync_status":"success","resync_watermark_ns":1785129938639000000,"schema_version":"clob-market-ws.price_change.v1","sequence":null,"server_hash":null,"server_timestamp":"1785129937491","session_id":"502006c5cfcd437296561ea750c9ec8b","source":"clob_market_ws"},"received_at":"2026-07-27T05:25:37.452299Z","record_id":"0b3b3023e9934c0d6c0f1efbbac9318045f25841a6a8fd3aa46563902be9f62a","schema_fingerprint":"c990bfb60716dbc222c50044da5e7a1f30d07e145848f9bd19c7d4fa0162d2eb","schema_version":"edge-lab-recorder.raw.v1","sequence":null,"source":"clob_market_ws"}
{"event_at":"2026-07-27T05:25:37.491000Z","event_fingerprint":"c4c8757121fcbbb8645d782279f542791a33af10231a4198c1859fbb0959ac8a","payload":{"connection_id":"efc69d3132f1467b8e898a382b23ac0d","event_at":"2026-07-27T05:25:37.491000Z","event_type":"price_change","frame_hash":"d0943274f34835b667eeb3e0ad12bbe6881158791b9879fc5fbc9f670ee2debf","frame_index":0,"kind":"quarantine","monotonic_ns":231920692355916,"payload":{"event_type":"price_change","market":"0x3b40066b5cf3871a2f6237c5628bd8092a206aa998558ac5ec13c4483e31e160","price_changes":[{"asset_id":"110216635572655435074987471276357323571387854733835379371586402147734167783946","best_ask":"0.53","best_bid":"0.52","hash":"5260b68f383534427b8d72e9f7d42658ea08a650","price":"0.52","side":"BUY","size":"16.78"},{"asset_id":"14766054693214075530629349735273995982307625376442606753688071083149620216746","best_ask":"0.48","best_bid":"0.47","hash":"1c50edee568817593d4a07caec84b77d81cf0839","price":"0.48","side":"SELL","size":"16.78"}],"timestamp":"1785129937491"},"payload_hash":"4e7fb507af71b6996c453d2f1e66f947db37ee7a2a90574e14adcabd98df827c","raw_frame":"{\"market\":\"0x3b40066b5cf3871a2f6237c5628bd8092a206aa998558ac5ec13c4483e31e160\", \"price_changes\":[{\"asset_id\":\"110216635572655435074987471276357323571387854733835379371586402147734167783946\", \"price\":\"0.52\", \"size\":\"16.78\", \"side\":\"BUY\", \"hash\":\"5260b68f383534427b8d72e9f7d42658ea08a650\", \"best_bid\":\"0.52\", \"best_ask\":\"0.53\"}, {\"asset_id\":\"14766054693214075530629349735273995982307625376442606753688071083149620216746\", \"price\":\"0.48\", \"size\":\"16.78\", \"side\":\"SELL\", \"hash\":\"1c50edee568817593d4a07caec84b77d81cf0839\", \"best_bid\":\"0.47\", \"best_ask\":\"0.48\"}], \"timestamp\":\"1785129937491\", \"event_type\":\"price_change\"}","received_at":"2026-07-27T05:25:37.452319Z","replay_eligible":false,"resync_asset_ids":["110216635572655435074987471276357323571387854733835379371586402147734167783946","14766054693214075530629349735273995982307625376442606753688071083149620216746"],"resync_asset_watermarks_ns":{"110216635572655435074987471276357323571387854733835379371586402147734167783946":1785129938639000000,"14766054693214075530629349735273995982307625376442606753688071083149620216746":1785129938639000000},"resync_buffered":true,"resync_status":"success","resync_watermark_ns":1785129938639000000,"schema_version":"clob-market-ws.price_change.v1","sequence":null,"server_hash":null,"server_timestamp":"1785129937491","session_id":"502006c5cfcd437296561ea750c9ec8b","source":"clob_market_ws"},"received_at":"2026-07-27T05:25:37.452319Z","record_id":"e9d9f2179396db154368f33af5defd99b9c0994af42fc6eecb17ec285e9078bf","schema_fingerprint":"c990bfb60716dbc222c50044da5e7a1f30d07e145848f9bd19c7d4fa0162d2eb","schema_version":"edge-lab-recorder.raw.v1","sequence":null,"source":"clob_market_ws"}
{"event_at":"2026-07-27T05:25:37.491000Z","event_fingerprint":"ac5609f8a000c9636e24657bcdb88591ba61917b10cc534b7c99862ae8a27478","payload":{"connection_id":"efc69d3132f1467b8e898a382b23ac0d","event_at":"2026-07-27T05:25:37.491000Z","event_type":"price_change","frame_hash":"dd2452037f2d9c9537d7d34336e3c7aab0522be2144fd4d2f942c0da4a76c680","frame_index":0,"kind":"quarantine","monotonic_ns":231920692376000,"payload":{"event_type":"price_change","market":"0x3b40066b5cf3871a2f6237c5628bd8092a206aa998558ac5ec13c4483e31e160","price_changes":[{"asset_id":"110216635572655435074987471276357323571387854733835379371586402147734167783946","best_ask":"0.53","best_bid":"0.52","hash":"5260b68f383534427b8d72e9f7d42658ea08a650","price":"0.51","side":"BUY","size":"275"},{"asset_id":"14766054693214075530629349735273995982307625376442606753688071083149620216746","best_ask":"0.48","best_bid":"0.47","hash":"1c50edee568817593d4a07caec84b77d81cf0839","price":"0.49","side":"SELL","size":"275"}],"timestamp":"1785129937491"},"payload_hash":"1a42e80a5e99e34daee13be088de7c0dd6fae1670348360fc771e7de2f70ca11","raw_frame":"{\"market\":\"0x3b40066b5cf3871a2f6237c5628bd8092a206aa998558ac5ec13c4483e31e160\", \"price_changes\":[{\"asset_id\":\"110216635572655435074987471276357323571387854733835379371586402147734167783946\", \"price\":\"0.51\", \"size\":\"275\", \"side\":\"BUY\", \"hash\":\"5260b68f383534427b8d72e9f7d42658ea08a650\", \"best_bid\":\"0.52\", \"best_ask\":\"0.53\"}, {\"asset_id\":\"14766054693214075530629349735273995982307625376442606753688071083149620216746\", \"price\":\"0.49\", \"size\":\"275\", \"side\":\"SELL\", \"hash\":\"1c50edee568817593d4a07caec84b77d81cf0839\", \"best_bid\":\"0.47\", \"best_ask\":\"0.48\"}], \"timestamp\":\"1785129937491\", \"event_type\":\"price_change\"}","received_at":"2026-07-27T05:25:37.452340Z","replay_eligible":false,"resync_asset_ids":["110216635572655435074987471276357323571387854733835379371586402147734167783946","14766054693214075530629349735273995982307625376442606753688071083149620216746"],"resync_asset_watermarks_ns":{"110216635572655435074987471276357323571387854733835379371586402147734167783946":1785129938639000000,"14766054693214075530629349735273995982307625376442606753688071083149620216746":1785129938639000000},"resync_buffered":true,"resync_status":"success","resync_watermark_ns":1785129938639000000,"schema_version":"clob-market-ws.price_change.v1","sequence":null,"server_hash":null,"server_timestamp":"1785129937491","session_id":"502006c5cfcd437296561ea750c9ec8b","source":"clob_market_ws"},"received_at":"2026-07-27T05:25:37.452340Z","record_id":"82655f5a511c42532cd52df7171f9aebce925dcadd1cf4d31e9ab9ba9b61faec","schema_fingerprint":"c990bfb60716dbc222c50044da5e7a1f30d07e145848f9bd19c7d4fa0162d2eb","schema_version":"edge-lab-recorder.raw.v1","sequence":null,"source":"clob_market_ws"}
{"event_at":"2026-07-27T05:25:37.491000Z","event_fingerprint":"f717363b15effb22f3503cae3ee42452e89a11b082a41bc485da887414820d6a","payload":{"connection_id":"efc69d3132f1467b8e898a382b23ac0d","event_at":"2026-07-27T05:25:37.491000Z","event_type":"price_change","frame_hash":"db54ceda1e53c8f3528ecef64b9e3fffa3cbb00a3a531f7f2a30cd25ab27b1a8","frame_index":0,"kind":"quarantine","monotonic_ns":231920692395583,"payload":{"event_type":"price_change","market":"0x3b40066b5cf3871a2f6237c5628bd8092a206aa998558ac5ec13c4483e31e160","price_changes":[{"asset_id":"110216635572655435074987471276357323571387854733835379371586402147734167783946","best_ask":"0.53","best_bid":"0.52","hash":"5260b68f383534427b8d72e9f7d42658ea08a650","price":"0.5","side":"BUY","size":"570"},{"asset_id":"14766054693214075530629349735273995982307625376442606753688071083149620216746","best_ask":"0.48","best_bid":"0.47","hash":"1c50edee568817593d4a07caec84b77d81cf0839","price":"0.5","side":"SELL","size":"570"}],"timestamp":"1785129937491"},"payload_hash":"19464a58338b42ca1ee83a590f55499f43e1fec600ff7d874c8a363112ab42f1","raw_frame":"{\"market\":\"0x3b40066b5cf3871a2f6237c5628bd8092a206aa998558ac5ec13c4483e31e160\", \"price_changes\":[{\"asset_id\":\"110216635572655435074987471276357323571387854733835379371586402147734167783946\", \"price\":\"0.5\", \"size\":\"570\", \"side\":\"BUY\", \"hash\":\"5260b68f383534427b8d72e9f7d42658ea08a650\", \"best_bid\":\"0.52\", \"best_ask\":\"0.53\"}, {\"asset_id\":\"14766054693214075530629349735273995982307625376442606753688071083149620216746\", \"price\":\"0.5\", \"size\":\"570\", \"side\":\"SELL\", \"hash\":\"1c50edee568817593d4a07caec84b77d81cf0839\", \"best_bid\":\"0.47\", \"best_ask\":\"0.48\"}], \"timestamp\":\"1785129937491\", \"event_type\":\"price_change\"}","received_at":"2026-07-27T05:25:37.452359Z","replay_eligible":false,"resync_asset_ids":["110216635572655435074987471276357323571387854733835379371586402147734167783946","14766054693214075530629349735273995982307625376442606753688071083149620216746"],"resync_asset_watermarks_ns":{"110216635572655435074987471276357323571387854733835379371586402147734167783946":1785129938639000000,"14766054693214075530629349735273995982307625376442606753688071083149620216746":1785129938639000000},"resync_buffered":true,"resync_status":"success","resync_watermark_ns":1785129938639000000,"schema_version":"clob-market-ws.price_change.v1","sequence":null,"server_hash":null,"server_timestamp":"1785129937491","session_id":"502006c5cfcd437296561ea750c9ec8b","source":"clob_market_ws"},"received_at":"2026-07-27T05:25:37.452359Z","record_id":"9e3106e9fb7ab1951dc6becf53954dbc4c7d059df73c3d5ad5c2a0f8f361c692","schema_fingerprint":"c990bfb60716dbc222c50044da5e7a1f30d07e145848f9bd19c7d4fa0162d2eb","schema_version":"edge-lab-recorder.raw.v1","sequence":null,"source":"clob_market_ws"}
{"event_at":"2026-07-27T05:25:38.634000Z","event_fingerprint":"c3c76f7dbc65b443ca842c039522920939f7a21f9f588566a998a457ffba5d44","payload":{"connection_id":"efc69d3132f1467b8e898a382b23ac0d","event_at":"2026-07-27T05:25:38.634000Z","event_type":"price_change","frame_hash":"f7198772fa3c434698b6544e664d22b72a656ca0bec9c6e9a23802f513017ad3","frame_index":0,"kind":"quarantine","monotonic_ns":231921835170083,"payload":{"event_type":"price_change","market":"0x3b40066b5cf3871a2f6237c5628bd8092a206aa998558ac5ec13c4483e31e160","price_changes":[{"asset_id":"14766054693214075530629349735273995982307625376442606753688071083149620216746","best_ask":"0.48","best_bid":"0.47","hash":"45f23620aa14e935ce91e5e53aebba31771c3e2d","price":"0.41","side":"BUY","size":"204.78"},{"asset_id":"110216635572655435074987471276357323571387854733835379371586402147734167783946","best_ask":"0.53","best_bid":"0.52","hash":"ad27ffde5242db3364b51b209b0d0764ce4c3437","price":"0.59","side":"SELL","size":"204.78"}],"timestamp":"1785129938634"},"payload_hash":"87df70c88e407138157b23499ba60dda635c2ceaa5385e7341bda8a12ac211fc","raw_frame":"{\"market\":\"0x3b40066b5cf3871a2f6237c5628bd8092a206aa998558ac5ec13c4483e31e160\", \"price_changes\":[{\"asset_id\":\"14766054693214075530629349735273995982307625376442606753688071083149620216746\", \"price\":\"0.41\", \"size\":\"204.78\", \"side\":\"BUY\", \"hash\":\"45f23620aa14e935ce91e5e53aebba31771c3e2d\", \"best_bid\":\"0.47\", \"best_ask\":\"0.48\"}, {\"asset_id\":\"110216635572655435074987471276357323571387854733835379371586402147734167783946\", \"price\":\"0.59\", \"size\":\"204.78\", \"side\":\"SELL\", \"hash\":\"ad27ffde5242db3364b51b209b0d0764ce4c3437\", \"best_bid\":\"0.52\", \"best_ask\":\"0.53\"}], \"timestamp\":\"1785129938634\", \"event_type\":\"price_change\"}","received_at":"2026-07-27T05:25:38.595137Z","replay_eligible":false,"resync_asset_ids":["110216635572655435074987471276357323571387854733835379371586402147734167783946","14766054693214075530629349735273995982307625376442606753688071083149620216746"],"resync_asset_watermarks_ns":{"110216635572655435074987471276357323571387854733835379371586402147734167783946":1785129938639000000,"14766054693214075530629349735273995982307625376442606753688071083149620216746":1785129938639000000},"resync_buffered":true,"resync_status":"success","resync_watermark_ns":1785129938639000000,"schema_version":"clob-market-ws.price_change.v1","sequence":null,"server_hash":null,"server_timestamp":"1785129938634","session_id":"502006c5cfcd437296561ea750c9ec8b","source":"clob_market_ws"},"received_at":"2026-07-27T05:25:38.595137Z","record_id":"fc404f36fcb1a0361edec90767ac14c44951733dae41a3e96197b6bba17bfcc3","schema_fingerprint":"c990bfb60716dbc222c50044da5e7a1f30d07e145848f9bd19c7d4fa0162d2eb","schema_version":"edge-lab-recorder.raw.v1","sequence":null,"source":"clob_market_ws"}
{"event_at":"2026-07-27T05:25:38.635000Z","event_fingerprint":"45d293b99b5f9bfa769298cac89df3af30a9908f2f52441cbabc9a697d67516c","payload":{"connection_id":"efc69d3132f1467b8e898a382b23ac0d","event_at":"2026-07-27T05:25:38.635000Z","event_type":"price_change","frame_hash":"321428f7547ca2247c728a24390b85fd21fd691180b02945cff5f173ea504f59","frame_index":0,"kind":"quarantine","monotonic_ns":231921836268500,"payload":{"event_type":"price_change","market":"0x3b40066b5cf3871a2f6237c5628bd8092a206aa998558ac5ec13c4483e31e160","price_changes":[{"asset_id":"110216635572655435074987471276357323571387854733835379371586402147734167783946","best_ask":"0.53","best_bid":"0.52","hash":"7b450171188c4127559600827cf438e62df87f2c","price":"0.46","side":"BUY","size":"125"},{"asset_id":"14766054693214075530629349735273995982307625376442606753688071083149620216746","best_ask":"0.48","best_bid":"0.47","hash":"e204754d3f2e455a3e0befed2eb3811a153dac69","price":"0.54","side":"SELL","size":"125"}],"timestamp":"1785129938635"},"payload_hash":"a736d45e29323c8475f62041871df04b9e1adbf9e8518d1e7359af257448cabc","raw_frame":"{\"market\":\"0x3b40066b5cf3871a2f6237c5628bd8092a206aa998558ac5ec13c4483e31e160\", \"price_changes\":[{\"asset_id\":\"110216635572655435074987471276357323571387854733835379371586402147734167783946\", \"price\":\"0.46\", \"size\":\"125\", \"side\":\"BUY\", \"hash\":\"7b450171188c4127559600827cf438e62df87f2c\", \"best_bid\":\"0.52\", \"best_ask\":\"0.53\"}, {\"asset_id\":\"14766054693214075530629349735273995982307625376442606753688071083149620216746\", \"price\":\"0.54\", \"size\":\"125\", \"side\":\"SELL\", \"hash\":\"e204754d3f2e455a3e0befed2eb3811a153dac69\", \"best_bid\":\"0.47\", \"best_ask\":\"0.48\"}], \"timestamp\":\"1785129938635\", \"event_type\":\"price_change\"}","received_at":"2026-07-27T05:25:38.596237Z","replay_eligible":false,"resync_asset_ids":["110216635572655435074987471276357323571387854733835379371586402147734167783946","14766054693214075530629349735273995982307625376442606753688071083149620216746"],"resync_asset_watermarks_ns":{"110216635572655435074987471276357323571387854733835379371586402147734167783946":1785129938639000000,"14766054693214075530629349735273995982307625376442606753688071083149620216746":1785129938639000000},"resync_buffered":true,"resync_status":"success","resync_watermark_ns":1785129938639000000,"schema_version":"clob-market-ws.price_change.v1","sequence":null,"server_hash":null,"server_timestamp":"1785129938635","session_id":"502006c5cfcd437296561ea750c9ec8b","source":"clob_market_ws"},"received_at":"2026-07-27T05:25:38.596237Z","record_id":"d3dfc40f0a62a798a2ef8526fb0843ddc58cc2a79a1bcbb2eb10ec19f1214bc1","schema_fingerprint":"c990bfb60716dbc222c50044da5e7a1f30d07e145848f9bd19c7d4fa0162d2eb","schema_version":"edge-lab-recorder.raw.v1","sequence":null,"source":"clob_market_ws"}
{"event_at":"2026-07-27T05:25:38.636000Z","event_fingerprint":"409f73b20e13914d4b75eff150c5964c330c8de45cb6d26adf446c00009bb0b3","payload":{"connection_id":"efc69d3132f1467b8e898a382b23ac0d","event_at":"2026-07-27T05:25:38.636000Z","event_type":"price_change","frame_hash":"24d46dcd471234866ba02bdf015c2106be78580e1cc0b3470548f53d5b5d694f","frame_index":0,"kind":"quarantine","monotonic_ns":231921836291041,"payload":{"event_type":"price_change","market":"0x3b40066b5cf3871a2f6237c5628bd8092a206aa998558ac5ec13c4483e31e160","price_changes":[{"asset_id":"14766054693214075530629349735273995982307625376442606753688071083149620216746","best_ask":"0.48","best_bid":"0.47","hash":"dff64fe1cb2f7ed34653906d91429835d5603ece","price":"0.39","side":"BUY","size":"148"},{"asset_id":"110216635572655435074987471276357323571387854733835379371586402147734167783946","best_ask":"0.53","best_bid":"0.52","hash":"c5f2789ca22926980c87795696d6ccf258401e09","price":"0.61","side":"SELL","size":"148"}],"timestamp":"1785129938636"},"payload_hash":"0905c342bd48a070d088d96620f8ac9838a0c1240466901f82e76b327ceb9932","raw_frame":"{\"market\":\"0x3b40066b5cf3871a2f6237c5628bd8092a206aa998558ac5ec13c4483e31e160\", \"price_changes\":[{\"asset_id\":\"14766054693214075530629349735273995982307625376442606753688071083149620216746\", \"price\":\"0.39\", \"size\":\"148\", \"side\":\"BUY\", \"hash\":\"dff64fe1cb2f7ed34653906d91429835d5603ece\", \"best_bid\":\"0.47\", \"best_ask\":\"0.48\"}, {\"asset_id\":\"110216635572655435074987471276357323571387854733835379371586402147734167783946\", \"price\":\"0.61\", \"size\":\"148\", \"side\":\"SELL\", \"hash\":\"c5f2789ca22926980c87795696d6ccf258401e09\", \"best_bid\":\"0.52\", \"best_ask\":\"0.53\"}], \"timestamp\":\"1785129938636\", \"event_type\":\"price_change\"}","received_at":"2026-07-27T05:25:38.596262Z","replay_eligible":false,"resync_asset_ids":["110216635572655435074987471276357323571387854733835379371586402147734167783946","14766054693214075530629349735273995982307625376442606753688071083149620216746"],"resync_asset_watermarks_ns":{"110216635572655435074987471276357323571387854733835379371586402147734167783946":1785129938639000000,"14766054693214075530629349735273995982307625376442606753688071083149620216746":1785129938639000000},"resync_buffered":true,"resync_status":"success","resync_watermark_ns":1785129938639000000,"schema_version":"clob-market-ws.price_change.v1","sequence":null,"server_hash":null,"server_timestamp":"1785129938636","session_id":"502006c5cfcd437296561ea750c9ec8b","source":"clob_market_ws"},"received_at":"2026-07-27T05:25:38.596262Z","record_id":"14d9ee8524ccb849544d2317b0ce20b875d317cbd962e4ac07bbb1cc91f66dd2","schema_fingerprint":"c990bfb60716dbc222c50044da5e7a1f30d07e145848f9bd19c7d4fa0162d2eb","schema_version":"edge-lab-recorder.raw.v1","sequence":null,"source":"clob_market_ws"}
{"event_at":"2026-07-27T05:25:38.637000Z","event_fingerprint":"158da8506f1a7ea9427a019b36f3d78152f52d0e57ca847d6e85dee0cefc6a03","payload":{"connection_id":"efc69d3132f1467b8e898a382b23ac0d","event_at":"2026-07-27T05:25:38.637000Z","event_type":"price_change","frame_hash":"b28f0c558b373fecefc647240f7abc1d17b03af4011e662508dd0ad492619ed7","frame_index":0,"kind":"quarantine","monotonic_ns":231921839434458,"payload":{"event_type":"price_change","market":"0x3b40066b5cf3871a2f6237c5628bd8092a206aa998558ac5ec13c4483e31e160","price_changes":[{"asset_id":"14766054693214075530629349735273995982307625376442606753688071083149620216746","best_ask":"0.48","best_bid":"0.47","hash":"633389a020e98d2f976e2a061af0cf99bfe583d1","price":"0.42","side":"BUY","size":"272"},{"asset_id":"110216635572655435074987471276357323571387854733835379371586402147734167783946","best_ask":"0.53","best_bid":"0.52","hash":"c8076f5f95804f1b18fa21009b991ab9ed03a7d1","price":"0.58","side":"SELL","size":"272"}],"timestamp":"1785129938637"},"payload_hash":"2a615859cb1a1d37a3ecda235cbe048b554c80775b77b4be998935fbab126cc5","raw_frame":"{\"market\":\"0x3b40066b5cf3871a2f6237c5628bd8092a206aa998558ac5ec13c4483e31e160\", \"price_changes\":[{\"asset_id\":\"14766054693214075530629349735273995982307625376442606753688071083149620216746\", \"price\":\"0.42\", \"size\":\"272\", \"side\":\"BUY\", \"hash\":\"633389a020e98d2f976e2a061af0cf99bfe583d1\", \"best_bid\":\"0.47\", \"best_ask\":\"0.48\"}, {\"asset_id\":\"110216635572655435074987471276357323571387854733835379371586402147734167783946\", \"price\":\"0.58\", \"size\":\"272\", \"side\":\"SELL\", \"hash\":\"c8076f5f95804f1b18fa21009b991ab9ed03a7d1\", \"best_bid\":\"0.52\", \"best_ask\":\"0.53\"}], \"timestamp\":\"1785129938637\", \"event_type\":\"price_change\"}","received_at":"2026-07-27T05:25:38.599403Z","replay_eligible":false,"resync_asset_ids":["110216635572655435074987471276357323571387854733835379371586402147734167783946","14766054693214075530629349735273995982307625376442606753688071083149620216746"],"resync_asset_watermarks_ns":{"110216635572655435074987471276357323571387854733835379371586402147734167783946":1785129938639000000,"14766054693214075530629349735273995982307625376442606753688071083149620216746":1785129938639000000},"resync_buffered":true,"resync_status":"success","resync_watermark_ns":1785129938639000000,"schema_version":"clob-market-ws.price_change.v1","sequence":null,"server_hash":null,"server_timestamp":"1785129938637","session_id":"502006c5cfcd437296561ea750c9ec8b","source":"clob_market_ws"},"received_at":"2026-07-27T05:25:38.599403Z","record_id":"72a71afc70ea9eaaac2cae215459b30157ea6370859a11b3942de77eceab9bb4","schema_fingerprint":"c990bfb60716dbc222c50044da5e7a1f30d07e145848f9bd19c7d4fa0162d2eb","schema_version":"edge-lab-recorder.raw.v1","sequence":null,"source":"clob_market_ws"}
{"event_at":"2026-07-27T05:25:38.638000Z","event_fingerprint":"4aa626eb25e797329d7f728d6dca8ed4773d59d021a37e44f2ceb57940c8f861","payload":{"connection_id":"efc69d3132f1467b8e898a382b23ac0d","event_at":"2026-07-27T05:25:38.638000Z","event_type":"price_change","frame_hash":"aec8e571664bb9b6bfae22cd776a50ad3f78c172e9328a5f7b718d2620a57468","frame_index":0,"kind":"quarantine","monotonic_ns":231921839458291,"payload":{"event_type":"price_change","market":"0x3b40066b5cf3871a2f6237c5628bd8092a206aa998558ac5ec13c4483e31e160","price_changes":[{"asset_id":"14766054693214075530629349735273995982307625376442606753688071083149620216746","best_ask":"0.48","best_bid":"0.47","hash":"f20ef766569efcdf5002faf311765c107fd64c26","price":"0.43","side":"BUY","size":"360"},{"asset_id":"110216635572655435074987471276357323571387854733835379371586402147734167783946","best_ask":"0.53","best_bid":"0.52","hash":"75c9f217c26fbb7614a04b3e920f963dbc56a0ec","price":"0.57","side":"SELL","size":"360"}],"timestamp":"1785129938638"},"payload_hash":"bdff02e7694b95a8968627cf8fff8e8e0ae5c821c9647582dd21e1e6489a250f","raw_frame":"{\"market\":\"0x3b40066b5cf3871a2f6237c5628bd8092a206aa998558ac5ec13c4483e31e160\", \"price_changes\":[{\"asset_id\":\"14766054693214075530629349735273995982307625376442606753688071083149620216746\", \"price\":\"0.43\", \"size\":\"360\", \"side\":\"BUY\", \"hash\":\"f20ef766569efcdf5002faf311765c107fd64c26\", \"best_bid\":\"0.47\", \"best_ask\":\"0.48\"}, {\"asset_id\":\"110216635572655435074987471276357323571387854733835379371586402147734167783946\", \"price\":\"0.57\", \"size\":\"360\", \"side\":\"SELL\", \"hash\":\"75c9f217c26fbb7614a04b3e920f963dbc56a0ec\", \"best_bid\":\"0.52\", \"best_ask\":\"0.53\"}], \"timestamp\":\"1785129938638\", \"event_type\":\"price_change\"}","received_at":"2026-07-27T05:25:38.599429Z","replay_eligible":false,"resync_asset_ids":["110216635572655435074987471276357323571387854733835379371586402147734167783946","14766054693214075530629349735273995982307625376442606753688071083149620216746"],"resync_asset_watermarks_ns":{"110216635572655435074987471276357323571387854733835379371586402147734167783946":1785129938639000000,"14766054693214075530629349735273995982307625376442606753688071083149620216746":1785129938639000000},"resync_buffered":true,"resync_status":"success","resync_watermark_ns":1785129938639000000,"schema_version":"clob-market-ws.price_change.v1","sequence":null,"server_hash":null,"server_timestamp":"1785129938638","session_id":"502006c5cfcd437296561ea750c9ec8b","source":"clob_market_ws"},"received_at":"2026-07-27T05:25:38.599429Z","record_id":"8a0f35ff62c7ae6dd107f28b8e2fa6dd49dbce2ec32fc56c816fcd28d58788b0","schema_fingerprint":"c990bfb60716dbc222c50044da5e7a1f30d07e145848f9bd19c7d4fa0162d2eb","schema_version":"edge-lab-recorder.raw.v1","sequence":null,"source":"clob_market_ws"}
{"event_at":"2026-07-27T05:25:38.639000Z","event_fingerprint":"048922101c6cb1c1a1b9af783cfdab9f38d19b5dfb0463d56f9fc5fe36800114","payload":{"connection_id":"efc69d3132f1467b8e898a382b23ac0d","event_at":"2026-07-27T05:25:38.639000Z","event_type":"price_change","frame_hash":"34129ed8ae6706dda2fde3e2993d601244b5e516cfb72013f21729c437a305e7","frame_index":0,"kind":"quarantine","monotonic_ns":231921839477333,"payload":{"event_type":"price_change","market":"0x3b40066b5cf3871a2f6237c5628bd8092a206aa998558ac5ec13c4483e31e160","price_changes":[{"asset_id":"14766054693214075530629349735273995982307625376442606753688071083149620216746","best_ask":"0.48","best_bid":"0.47","hash":"891242c7d0feb723a764ad10723ad2b8d72b7fc2","price":"0.4","side":"BUY","size":"185"},{"asset_id":"110216635572655435074987471276357323571387854733835379371586402147734167783946","best_ask":"0.53","best_bid":"0.52","hash":"1adea42d03db0cc52da761de130db06a5f8d5688","price":"0.6","side":"SELL","size":"185"}],"timestamp":"1785129938639"},"payload_hash":"696b723d77f96735bcd11cb5ee5ca8b8fc8f57e093e969cacb9fb0df0d56765e","raw_frame":"{\"market\":\"0x3b40066b5cf3871a2f6237c5628bd8092a206aa998558ac5ec13c4483e31e160\", \"price_changes\":[{\"asset_id\":\"14766054693214075530629349735273995982307625376442606753688071083149620216746\", \"price\":\"0.4\", \"size\":\"185\", \"side\":\"BUY\", \"hash\":\"891242c7d0feb723a764ad10723ad2b8d72b7fc2\", \"best_bid\":\"0.47\", \"best_ask\":\"0.48\"}, {\"asset_id\":\"110216635572655435074987471276357323571387854733835379371586402147734167783946\", \"price\":\"0.6\", \"size\":\"185\", \"side\":\"SELL\", \"hash\":\"1adea42d03db0cc52da761de130db06a5f8d5688\", \"best_bid\":\"0.52\", \"best_ask\":\"0.53\"}], \"timestamp\":\"1785129938639\", \"event_type\":\"price_change\"}","received_at":"2026-07-27T05:25:38.599449Z","replay_eligible":false,"resync_asset_ids":["110216635572655435074987471276357323571387854733835379371586402147734167783946","14766054693214075530629349735273995982307625376442606753688071083149620216746"],"resync_asset_watermarks_ns":{"110216635572655435074987471276357323571387854733835379371586402147734167783946":1785129938639000000,"14766054693214075530629349735273995982307625376442606753688071083149620216746":1785129938639000000},"resync_buffered":true,"resync_status":"success","resync_watermark_ns":1785129938639000000,"schema_version":"clob-market-ws.price_change.v1","sequence":null,"server_hash":null,"server_timestamp":"1785129938639","session_id":"502006c5cfcd437296561ea750c9ec8b","source":"clob_market_ws"},"received_at":"2026-07-27T05:25:38.599449Z","record_id":"7b287d1a3f77c4648662799587283f074999fc08a5fb5f45fc4596e7d9390bc5","schema_fingerprint":"c990bfb60716dbc222c50044da5e7a1f30d07e145848f9bd19c7d4fa0162d2eb","schema_version":"edge-lab-recorder.raw.v1","sequence":null,"source":"clob_market_ws"}
{"event_at":"2026-07-27T05:25:38.640000Z","event_fingerprint":"1eba3a581254921db973a940bed22090b9eff9e333a804d062eb0ccbbbc722c8","payload":{"connection_id":"efc69d3132f1467b8e898a382b23ac0d","event_at":"2026-07-27T05:25:38.640000Z","event_type":"price_change","frame_hash":"9beb8004cc501ee1b62ee2aa1b867744893a3c5b230cadf7d8f5ae1987372de2","frame_index":0,"kind":"data","monotonic_ns":231921841954916,"payload":{"event_type":"price_change","market":"0x3b40066b5cf3871a2f6237c5628bd8092a206aa998558ac5ec13c4483e31e160","price_changes":[{"asset_id":"110216635572655435074987471276357323571387854733835379371586402147734167783946","best_ask":"0.53","best_bid":"0.52","hash":"81445e4737811d18accf493058dbb0f5264338f0","price":"0.47","side":"BUY","size":"114.67"},{"asset_id":"14766054693214075530629349735273995982307625376442606753688071083149620216746","best_ask":"0.48","best_bid":"0.47","hash":"8d69610ebd31b9d0bad54897c85350cde4d0f152","price":"0.53","side":"SELL","size":"114.67"}],"timestamp":"1785129938640"},"payload_hash":"6c524adeaa28f38732ceb3653de139051c06d68b0f152dcd7e02700a198a896c","raw_frame":"{\"market\":\"0x3b40066b5cf3871a2f6237c5628bd8092a206aa998558ac5ec13c4483e31e160\", \"price_changes\":[{\"asset_id\":\"110216635572655435074987471276357323571387854733835379371586402147734167783946\", \"price\":\"0.47\", \"size\":\"114.67\", \"side\":\"BUY\", \"hash\":\"81445e4737811d18accf493058dbb0f5264338f0\", \"best_bid\":\"0.52\", \"best_ask\":\"0.53\"}, {\"asset_id\":\"14766054693214075530629349735273995982307625376442606753688071083149620216746\", \"price\":\"0.53\", \"size\":\"114.67\", \"side\":\"SELL\", \"hash\":\"8d69610ebd31b9d0bad54897c85350cde4d0f152\", \"best_bid\":\"0.47\", \"best_ask\":\"0.48\"}], \"timestamp\":\"1785129938640\", \"event_type\":\"price_change\"}","received_at":"2026-07-27T05:25:38.601923Z","replay_eligible":true,"resync_asset_ids":["110216635572655435074987471276357323571387854733835379371586402147734167783946","14766054693214075530629349735273995982307625376442606753688071083149620216746"],"resync_asset_watermarks_ns":{"110216635572655435074987471276357323571387854733835379371586402147734167783946":1785129938639000000,"14766054693214075530629349735273995982307625376442606753688071083149620216746":1785129938639000000},"resync_buffered":true,"resync_status":"success","resync_watermark_ns":1785129938639000000,"schema_version":"clob-market-ws.price_change.v1","sequence":null,"server_hash":null,"server_timestamp":"1785129938640","session_id":"502006c5cfcd437296561ea750c9ec8b","source":"clob_market_ws"},"received_at":"2026-07-27T05:25:38.601923Z","record_id":"64fed55f40a6115dab0b8c2748797414c9a171e878629e8a712410cf111bc212","schema_fingerprint":"c990bfb60716dbc222c50044da5e7a1f30d07e145848f9bd19c7d4fa0162d2eb","schema_version":"edge-lab-recorder.raw.v1","sequence":null,"source":"clob_market_ws"}
{"event_at":"2026-07-27T05:25:38.641000Z","event_fingerprint":"50fbbdc5c61ac92b15baaa3b4393c3774e967f6fdded820b01b8f15931915c94","payload":{"connection_id":"efc69d3132f1467b8e898a382b23ac0d","event_at":"2026-07-27T05:25:38.641000Z","event_type":"price_change","frame_hash":"5937d1c4843eb018fa72c3399af53a92a75b86684eecc0efbd860c679a180d3a","frame_index":0,"kind":"data","monotonic_ns":231921841978250,"payload":{"event_type":"price_change","market":"0x3b40066b5cf3871a2f6237c5628bd8092a206aa998558ac5ec13c4483e31e160","price_changes":[{"asset_id":"110216635572655435074987471276357323571387854733835379371586402147734167783946","best_ask":"0.53","best_bid":"0.52","hash":"da73d0e635abdbf1de405aa8219c5a8dc016862c","price":"0.45","side":"BUY","size":"115.33"},{"asset_id":"14766054693214075530629349735273995982307625376442606753688071083149620216746","best_ask":"0.48","best_bid":"0.47","hash":"522a38d4c5f0b3cd4c6dc167e4b7b1bc979725af","price":"0.55","side":"SELL","size":"115.33"}],"timestamp":"1785129938641"},"payload_hash":"b118afe6567fdadc73cbbe2b34d2d724e2856ae5c8bb56774b50e207f93218fb","raw_frame":"{\"market\":\"0x3b40066b5cf3871a2f6237c5628bd8092a206aa998558ac5ec13c4483e31e160\", \"price_changes\":[{\"asset_id\":\"110216635572655435074987471276357323571387854733835379371586402147734167783946\", \"price\":\"0.45\", \"size\":\"115.33\", \"side\":\"BUY\", \"hash\":\"da73d0e635abdbf1de405aa8219c5a8dc016862c\", \"best_bid\":\"0.52\", \"best_ask\":\"0.53\"}, {\"asset_id\":\"14766054693214075530629349735273995982307625376442606753688071083149620216746\", \"price\":\"0.55\", \"size\":\"115.33\", \"side\":\"SELL\", \"hash\":\"522a38d4c5f0b3cd4c6dc167e4b7b1bc979725af\", \"best_bid\":\"0.47\", \"best_ask\":\"0.48\"}], \"timestamp\":\"1785129938641\", \"event_type\":\"price_change\"}","received_at":"2026-07-27T05:25:38.601949Z","replay_eligible":true,"resync_asset_ids":["110216635572655435074987471276357323571387854733835379371586402147734167783946","14766054693214075530629349735273995982307625376442606753688071083149620216746"],"resync_asset_watermarks_ns":{"110216635572655435074987471276357323571387854733835379371586402147734167783946":1785129938639000000,"14766054693214075530629349735273995982307625376442606753688071083149620216746":1785129938639000000},"resync_buffered":true,"resync_status":"success","resync_watermark_ns":1785129938639000000,"schema_version":"clob-market-ws.price_change.v1","sequence":null,"server_hash":null,"server_timestamp":"1785129938641","session_id":"502006c5cfcd437296561ea750c9ec8b","source":"clob_market_ws"},"received_at":"2026-07-27T05:25:38.601949Z","record_id":"8a4d4e37a503082f9699407f62e5d21410c68886529e88a2b2097e1af10a60ae","schema_fingerprint":"c990bfb60716dbc222c50044da5e7a1f30d07e145848f9bd19c7d4fa0162d2eb","schema_version":"edge-lab-recorder.raw.v1","sequence":null,"source":"clob_market_ws"}
{"event_at":null,"event_fingerprint":"d728262c383e4efa1a0032f86634d33a2315755fa9eb03b1746115f2db265d2a","payload":{"connection_id":"efc69d3132f1467b8e898a382b23ac0d","event_type":"heartbeat_ack","frame_hash":"95784973cc639977bff93619700168505cb8f7855e44fa643d34622a43706c87","kind":"lifecycle","monotonic_ns":231926464849875,"raw_frame":"PONG","received_at":"2026-07-27T05:25:43.224850Z","schema_version":"edge-lab-recorder.heartbeat-ack.v1","session_id":"502006c5cfcd437296561ea750c9ec8b","source":"clob_market_ws"},"received_at":"2026-07-27T05:25:43.224850Z","record_id":"17760fd9cb6db665ce77861b3eb9241ecf89dcee1f3e6dc7a7e8bc92a232a7f9","schema_fingerprint":"c14ee1aab3ca674ee738e5268877b544d74c41ad3c427cedc09236467dc68ba1","schema_version":"edge-lab-recorder.raw.v1","sequence":null,"source":"clob_market_ws"}
{"event_at":null,"event_fingerprint":"6c28350bbc74d1f8f801e0d2b414a83fa74287525a626c71366acd7900135b9d","payload":{"connection_id":"efc69d3132f1467b8e898a382b23ac0d","detail":{"asset_watermarks_ns":{"110216635572655435074987471276357323571387854733835379371586402147734167783946":1785129938639000000,"14766054693214075530629349735273995982307625376442606753688071083149620216746":1785129938639000000},"buffered_count":25,"connection_number":1,"watermark_ns":1785129938639000000},"event_type":"resync_complete","kind":"lifecycle","monotonic_ns":231927226210541,"received_at":"2026-07-27T05:25:43.986216Z","schema_version":"edge-lab-recorder.lifecycle.v1","session_id":"502006c5cfcd437296561ea750c9ec8b","source":"clob_market_ws"},"received_at":"2026-07-27T05:25:43.986216Z","record_id":"04128630928fb93ad1d477f4061d96230fa90ba867063d07e86f81d02475054b","schema_fingerprint":"f42d20aa1499cc1dcd55053be1577ddc40b68ae9faea1a5f2c81f3adc7b2aeb3","schema_version":"edge-lab-recorder.raw.v1","sequence":null,"source":"clob_market_ws"}
