{"event_at":"2026-07-27T05:38:42.280000Z","event_fingerprint":"4ea84bc040d899b869daff3a3d60517fde1ad683492c9ae349adb5c865b367cd","payload":{"connection_id":"efc69d3132f1467b8e898a382b23ac0d","event_at":"2026-07-27T05:38:42.280000Z","event_type":"price_change","frame_hash":"66910f64dd42ba9be1d1e4e9dbabbdae314b90009887b1ede73b174478ed61f4","frame_index":0,"kind":"data","monotonic_ns":232708685569166,"payload":{"event_type":"price_change","market":"0x3b40066b5cf3871a2f6237c5628bd8092a206aa998558ac5ec13c4483e31e160","price_changes":[{"asset_id":"110216635572655435074987471276357323571387854733835379371586402147734167783946","best_ask":"0.42","best_bid":"0.41","hash":"986508c0a5b62d4c3f8bb06d29124f8cfb782ec0","price":"0.31","side":"BUY","size":"225"},{"asset_id":"14766054693214075530629349735273995982307625376442606753688071083149620216746","best_ask":"0.59","best_bid":"0.58","hash":"d49655d42f5d8989b32dace94ba565461c1a3953","price":"0.69","side":"SELL","size":"225"}],"timestamp":"1785130722280"},"payload_hash":"dee1915986429c456b427b67499db2f89c1d9f2c0d36fd66faa09e6e40aa8b15","raw_frame":"{\"market\":\"0x3b40066b5cf3871a2f6237c5628bd8092a206aa998558ac5ec13c4483e31e160\", \"price_changes\":[{\"asset_id\":\"110216635572655435074987471276357323571387854733835379371586402147734167783946\", \"price\":\"0.31\", \"size\":\"225\", \"side\":\"BUY\", \"hash\":\"986508c0a5b62d4c3f8bb06d29124f8cfb782ec0\", \"best_bid\":\"0.41\", \"best_ask\":\"0.42\"}, {\"asset_id\":\"14766054693214075530629349735273995982307625376442606753688071083149620216746\", \"price\":\"0.69\", \"size\":\"225\", \"side\":\"SELL\", \"hash\":\"d49655d42f5d8989b32dace94ba565461c1a3953\", \"best_bid\":\"0.58\", \"best_ask\":\"0.59\"}], \"timestamp\":\"1785130722280\", \"event_type\":\"price_change\"}","received_at":"2026-07-27T05:38:45.451010Z","schema_version":"clob-market-ws.price_change.v1","sequence":null,"server_hash":null,"server_timestamp":"1785130722280","session_id":"502006c5cfcd437296561ea750c9ec8b","source":"clob_market_ws"},"received_at":"2026-07-27T05:38:45.451010Z","record_id":"b6d231a4f5d0cd9d92f7008a6a6e1be4246fae0bcc7e21fbf4c96bf53249f6d7","schema_fingerprint":"4aa3821a28b0b7c2400bc59aba4bcc0a76e971dadd19610d3ad38c768e124dc7","schema_version":"edge-lab-recorder.raw.v1","sequence":null,"source":"clob_market_ws"}
{"event_at":"2026-07-27T05:38:42.281000Z","event_fingerprint":"213f432dce7319f339218034d1ae80d5dd2700510f1c8a02ef11255c8f109e05","payload":{"connection_id":"efc69d3132f1467b8e898a382b23ac0d","event_at":"2026-07-27T05:38:42.281000Z","event_type":"price_change","frame_hash":"742ecc2fffaada539760f497805a4f8d9bf578010761d871d77eca31a0a5a4c3","frame_index":0,"kind":"data","monotonic_ns":232708697059958,"payload":{"event_type":"price_change","market":"0x3b40066b5cf3871a2f6237c5628bd8092a206aa998558ac5ec13c4483e31e160","price_changes":[{"asset_id":"110216635572655435074987471276357323571387854733835379371586402147734167783946","best_ask":"0.42","best_bid":"0.41","hash":"4a7846849b1af89d34acb64d19127f19404325b5","price":"0.28","side":"BUY","size":"117"},{"asset_id":"14766054693214075530629349735273995982307625376442606753688071083149620216746","best_ask":"0.59","best_bid":"0.58","hash":"b6e77d794cdb6dddd440f18f5cc245317e1600ea","price":"0.72","side":"SELL","size":"117"}],"timestamp":"1785130722281"},"payload_hash":"d1e44b2e6239b16cc1d5ccafb0d23818cca165dab04490b389dfbbc4fdcdc186","raw_frame":"{\"market\":\"0x3b40066b5cf3871a2f6237c5628bd8092a206aa998558ac5ec13c4483e31e160\", \"price_changes\":[{\"asset_id\":\"110216635572655435074987471276357323571387854733835379371586402147734167783946\", \"price\":\"0.28\", \"size\":\"117\", \"side\":\"BUY\", \"hash\":\"4a7846849b1af89d34acb64d19127f19404325b5\", \"best_bid\":\"0.41\", \"best_ask\":\"0.42\"}, {\"asset_id\":\"14766054693214075530629349735273995982307625376442606753688071083149620216746\", \"price\":\"0.72\", \"size\":\"117\", \"side\":\"SELL\", \"hash\":\"b6e77d794cdb6dddd440f18f5cc245317e1600ea\", \"best_bid\":\"0.58\", \"best_ask\":\"0.59\"}], \"timestamp\":\"1785130722281\", \"event_type\":\"price_change\"}","received_at":"2026-07-27T05:38:45.462494Z","schema_version":"clob-market-ws.price_change.v1","sequence":null,"server_hash":null,"server_timestamp":"1785130722281","session_id":"502006c5cfcd437296561ea750c9ec8b","source":"clob_market_ws"},"received_at":"2026-07-27T05:38:45.462494Z","record_id":"f8ce852f7158b3ce659019a32f8e0765cc47f20d56bdd027e6b717d95b392cf1","schema_fingerprint":"4aa3821a28b0b7c2400bc59aba4bcc0a76e971dadd19610d3ad38c768e124dc7","schema_version":"edge-lab-recorder.raw.v1","sequence":null,"source":"clob_market_ws"}
{"event_at":"2026-07-27T05:38:42.283000Z","event_fingerprint":"f4ce0e83e8a2135c3d5fb8bb9e456641025c2546fd5ad2f856549573681bf341","payload":{"connection_id":"efc69d3132f1467b8e898a382b23ac0d","event_at":"2026-07-27T05:38:42.283000Z","event_type":"price_change","frame_hash":"093645fe5189ad3455c776269216df2699ca90372305b4c6aa8d3d6fb419fd10","frame_index":0,"kind":"data","monotonic_ns":232708701169000,"payload":{"event_type":"price_change","market":"0x3b40066b5cf3871a2f6237c5628bd8092a206aa998558ac5ec13c4483e31e160","price_changes":[{"asset_id":"110216635572655435074987471276357323571387854733835379371586402147734167783946","best_ask":"0.42","best_bid":"0.41","hash":"0bbb4fd43c1cc3594f818f1c5379b8790ddd110e","price":"0.31","side":"BUY","size":"255"},{"asset_id":"14766054693214075530629349735273995982307625376442606753688071083149620216746","best_ask":"0.59","best_bid":"0.58","hash":"00d906b0397c169b127ba7761ecf337fd45f267d","price":"0.69","side":"SELL","size":"255"}],"timestamp":"1785130722283"},"payload_hash":"4ffd81c45ac135328f299913b8c632905c487e51adfbc3d8c4f29e26325cc48e","raw_frame":"{\"market\":\"0x3b40066b5cf3871a2f6237c5628bd8092a206aa998558ac5ec13c4483e31e160\", \"price_changes\":[{\"asset_id\":\"110216635572655435074987471276357323571387854733835379371586402147734167783946\", \"price\":\"0.31\", \"size\":\"255\", \"side\":\"BUY\", \"hash\":\"0bbb4fd43c1cc3594f818f1c5379b8790ddd110e\", \"best_bid\":\"0.41\", \"best_ask\":\"0.42\"}, {\"asset_id\":\"14766054693214075530629349735273995982307625376442606753688071083149620216746\", \"price\":\"0.69\", \"size\":\"255\", \"side\":\"SELL\", \"hash\":\"00d906b0397c169b127ba7761ecf337fd45f267d\", \"best_bid\":\"0.58\", \"best_ask\":\"0.59\"}], \"timestamp\":\"1785130722283\", \"event_type\":\"price_change\"}","received_at":"2026-07-27T05:38:45.466610Z","schema_version":"clob-market-ws.price_change.v1","sequence":null,"server_hash":null,"server_timestamp":"1785130722283","session_id":"502006c5cfcd437296561ea750c9ec8b","source":"clob_market_ws"},"received_at":"2026-07-27T05:38:45.466610Z","record_id":"734b24e05e7d9567a0d17fb6031939c6aafec6ff0444e696dea023ab2855014b","schema_fingerprint":"4aa3821a28b0b7c2400bc59aba4bcc0a76e971dadd19610d3ad38c768e124dc7","schema_version":"edge-lab-recorder.raw.v1","sequence":null,"source":"clob_market_ws"}
{"event_at":"2026-07-27T05:38:42.285000Z","event_fingerprint":"65fc3d0204cb10025d678a04592d672a200463cf0a68d64e2b225292d25824ae","payload":{"connection_id":"efc69d3132f1467b8e898a382b23ac0d","event_at":"2026-07-27T05:38:42.285000Z","event_type":"price_change","frame_hash":"22c7146476224efa69a5c58b91bba00896382139fe33ba104b7a73252ea71997","frame_index":0,"kind":"data","monotonic_ns":232708712854625,"payload":{"event_type":"price_change","market":"0x3b40066b5cf3871a2f6237c5628bd8092a206aa998558ac5ec13c4483e31e160","price_changes":[{"asset_id":"14766054693214075530629349735273995982307625376442606753688071083149620216746","best_ask":"0.59","best_bid":"0.58","hash":"dbb9dc8f7d3137da5d9888131a60e375339376f6","price":"0.01","side":"BUY","size":"5633.02"},{"asset_id":"110216635572655435074987471276357323571387854733835379371586402147734167783946","best_ask":"0.42","best_bid":"0.41","hash":"928c07414fa7431436482a129f6fe696d28fd0f6","price":"0.99","side":"SELL","size":"5633.02"}],"timestamp":"1785130722285"},"payload_hash":"082de2c17c51d9f4d0a3321c40758afa838fa58219b474bd61faf0d9128f76de","raw_frame":"{\"market\":\"0x3b40066b5cf3871a2f6237c5628bd8092a206aa998558ac5ec13c4483e31e160\", \"price_changes\":[{\"asset_id\":\"14766054693214075530629349735273995982307625376442606753688071083149620216746\", \"price\":\"0.01\", \"size\":\"5633.02\", \"side\":\"BUY\", \"hash\":\"dbb9dc8f7d3137da5d9888131a60e375339376f6\", \"best_bid\":\"0.58\", \"best_ask\":\"0.59\"}, {\"asset_id\":\"110216635572655435074987471276357323571387854733835379371586402147734167783946\", \"price\":\"0.99\", \"size\":\"5633.02\", \"side\":\"SELL\", \"hash\":\"928c07414fa7431436482a129f6fe696d28fd0f6\", \"best_bid\":\"0.41\", \"best_ask\":\"0.42\"}], \"timestamp\":\"1785130722285\", \"event_type\":\"price_change\"}","received_at":"2026-07-27T05:38:45.478294Z","schema_version":"clob-market-ws.price_change.v1","sequence":null,"server_hash":null,"server_timestamp":"1785130722285","session_id":"502006c5cfcd437296561ea750c9ec8b","source":"clob_market_ws"},"received_at":"2026-07-27T05:38:45.478294Z","record_id":"34ea48663ec1b55587128984249970dca5a813c1c2fe4c7a50163b788dc5e526","schema_fingerprint":"4aa3821a28b0b7c2400bc59aba4bcc0a76e971dadd19610d3ad38c768e124dc7","schema_version":"edge-lab-recorder.raw.v1","sequence":null,"source":"clob_market_ws"}
{"event_at":"2026-07-27T05:38:42.288000Z","event_fingerprint":"aa7256b8217bea811b00237fa2c82a80d43afc055c6edd8334b998395c7c7f6a","payload":{"connection_id":"efc69d3132f1467b8e898a382b23ac0d","event_at":"2026-07-27T05:38:42.288000Z","event_type":"price_change","frame_hash":"c85ca4cb830169e7af12c47b9eb9f4c9d75a3da7aff8dd61f05468d6aab82650","frame_index":0,"kind":"data","monotonic_ns":232708719992041,"payload":{"event_type":"price_change","market":"0x3b40066b5cf3871a2f6237c5628bd8092a206aa998558ac5ec13c4483e31e160","price_changes":[{"asset_id":"110216635572655435074987471276357323571387854733835379371586402147734167783946","best_ask":"0.42","best_bid":"0.41","hash":"e5fc2de2cbc59539e04c7ed5d8e96cc34ca10331","price":"0.37","side":"BUY","size":"352.27"},{"asset_id":"14766054693214075530629349735273995982307625376442606753688071083149620216746","best_ask":"0.59","best_bid":"0.58","hash":"b84ea2a55c26525f5b5dbb196866dc3d5c8b557a","price":"0.63","side":"SELL","size":"352.27"}],"timestamp":"1785130722288"},"payload_hash":"0a7c53a354d61ae3e9eea83929a3e728eeadbe343713a0bbb2f7e001012b48c9","raw_frame":"{\"market\":\"0x3b40066b5cf3871a2f6237c5628bd8092a206aa998558ac5ec13c4483e31e160\", \"price_changes\":[{\"asset_id\":\"110216635572655435074987471276357323571387854733835379371586402147734167783946\", \"price\":\"0.37\", \"size\":\"352.27\", \"side\":\"BUY\", \"hash\":\"e5fc2de2cbc59539e04c7ed5d8e96cc34ca10331\", \"best_bid\":\"0.41\", \"best_ask\":\"0.42\"}, {\"asset_id\":\"14766054693214075530629349735273995982307625376442606753688071083149620216746\", \"price\":\"0.63\", \"size\":\"352.27\", \"side\":\"SELL\", \"hash\":\"b84ea2a55c26525f5b5dbb196866dc3d5c8b557a\", \"best_bid\":\"0.58\", \"best_ask\":\"0.59\"}], \"timestamp\":\"1785130722288\", \"event_type\":\"price_change\"}","received_at":"2026-07-27T05:38:45.485433Z","schema_version":"clob-market-ws.price_change.v1","sequence":null,"server_hash":null,"server_timestamp":"1785130722288","session_id":"502006c5cfcd437296561ea750c9ec8b","source":"clob_market_ws"},"received_at":"2026-07-27T05:38:45.485433Z","record_id":"d114383bb6ef3bf3dd90ea22fed0ef37821adf7d75af984d76ce805494dec3a8","schema_fingerprint":"4aa3821a28b0b7c2400bc59aba4bcc0a76e971dadd19610d3ad38c768e124dc7","schema_version":"edge-lab-recorder.raw.v1","sequence":null,"source":"clob_market_ws"}
{"event_at":"2026-07-27T05:38:42.306000Z","event_fingerprint":"82d31a6aaa9fceaa65498c8c1553ca8ae4898c31441757bf4e5864326bb8a47e","payload":{"connection_id":"efc69d3132f1467b8e898a382b23ac0d","event_at":"2026-07-27T05:38:42.306000Z","event_type":"price_change","frame_hash":"98b84a45e505873bf4b345ddf423ec6d828145e8c7cc8a9683eb2d3dbadd5987","frame_index":0,"kind":"data","monotonic_ns":232708725236791,"payload":{"event_type":"price_change","market":"0x3b40066b5cf3871a2f6237c5628bd8092a206aa998558ac5ec13c4483e31e160","price_changes":[{"asset_id":"110216635572655435074987471276357323571387854733835379371586402147734167783946","best_ask":"0.42","best_bid":"0.41","hash":"d947a0cd1d57cc9e8996e0aeca21ab40604c2c73","price":"0.37","side":"BUY","size":"342.27"},{"asset_id":"14766054693214075530629349735273995982307625376442606753688071083149620216746","best_ask":"0.59","best_bid":"0.58","hash":"05dc83cf07f3824be454ca75cf4c43e9c2ad2229","price":"0.63","side":"SELL","size":"342.27"}],"timestamp":"1785130722306"},"payload_hash":"ea92eb7c8ca298fc058650ef60b7e6b0aeb42e45a9e1136eda37da0cac63a55d","raw_frame":"{\"market\":\"0x3b40066b5cf3871a2f6237c5628bd8092a206aa998558ac5ec13c4483e31e160\", \"price_changes\":[{\"asset_id\":\"110216635572655435074987471276357323571387854733835379371586402147734167783946\", \"price\":\"0.37\", \"size\":\"342.27\", \"side\":\"BUY\", \"hash\":\"d947a0cd1d57cc9e8996e0aeca21ab40604c2c73\", \"best_bid\":\"0.41\", \"best_ask\":\"0.42\"}, {\"asset_id\":\"14766054693214075530629349735273995982307625376442606753688071083149620216746\", \"price\":\"0.63\", \"size\":\"342.27\", \"side\":\"SELL\", \"hash\":\"05dc83cf07f3824be454ca75cf4c43e9c2ad2229\", \"best_bid\":\"0.58\", \"best_ask\":\"0.59\"}], \"timestamp\":\"1785130722306\", \"event_type\":\"price_change\"}","received_at":"2026-07-27T05:38:45.490677Z","schema_version":"clob-market-ws.price_change.v1","sequence":null,"server_hash":null,"server_timestamp":"1785130722306","session_id":"502006c5cfcd437296561ea750c9ec8b","source":"clob_market_ws"},"received_at":"2026-07-27T05:38:45.490677Z","record_id":"70733350b495ae6b6bd51d535bf777327c25db25855425642b173b809a2ee592","schema_fingerprint":"4aa3821a28b0b7c2400bc59aba4bcc0a76e971dadd19610d3ad38c768e124dc7","schema_version":"edge-lab-recorder.raw.v1","sequence":null,"source":"clob_market_ws"}
{"event_at":"2026-07-27T05:38:42.336000Z","event_fingerprint":"b4588e3f478f83c5eeab2b6854263da9accc017cf628fa635efe0c1b66664120","payload":{"connection_id":"efc69d3132f1467b8e898a382b23ac0d","event_at":"2026-07-27T05:38:42.336000Z","event_type":"price_change","frame_hash":"dbc7a2885d05f057b97fa468dcde85af9473233f371318eaa29d05646d7b6e12","frame_index":0,"kind":"data","monotonic_ns":232708729252541,"payload":{"event_type":"price_change","market":"0x3b40066b5cf3871a2f6237c5628bd8092a206aa998558ac5ec13c4483e31e160","price_changes":[{"asset_id":"14766054693214075530629349735273995982307625376442606753688071083149620216746","best_ask":"0.59","best_bid":"0.58","hash":"7878e1ac203ce1585a9b602aa164e697c72c71d2","price":"0.33","side":"BUY","size":"52.47"},{"asset_id":"110216635572655435074987471276357323571387854733835379371586402147734167783946","best_ask":"0.42","best_bid":"0.41","hash":"43946c31a5e541e5e487bef5a1eae44bbe6301f8","price":"0.67","side":"SELL","size":"52.47"}],"timestamp":"1785130722336"},"payload_hash":"8db8f656e08cfaa5edf4855778aed9dbc2fd0753b2dd1e9390d8cb06f0dba2cc","raw_frame":"{\"market\":\"0x3b40066b5cf3871a2f6237c5628bd8092a206aa998558ac5ec13c4483e31e160\", \"price_changes\":[{\"asset_id\":\"14766054693214075530629349735273995982307625376442606753688071083149620216746\", \"price\":\"0.33\", \"size\":\"52.47\", \"side\":\"BUY\", \"hash\":\"7878e1ac203ce1585a9b602aa164e697c72c71d2\", \"best_bid\":\"0.58\", \"best_ask\":\"0.59\"}, {\"asset_id\":\"110216635572655435074987471276357323571387854733835379371586402147734167783946\", \"price\":\"0.67\", \"size\":\"52.47\", \"side\":\"SELL\", \"hash\":\"43946c31a5e541e5e487bef5a1eae44bbe6301f8\", \"best_bid\":\"0.41\", \"best_ask\":\"0.42\"}], \"timestamp\":\"1785130722336\", \"event_type\":\"price_change\"}","received_at":"2026-07-27T05:38:45.494695Z","schema_version":"clob-market-ws.price_change.v1","sequence":null,"server_hash":null,"server_timestamp":"1785130722336","session_id":"502006c5cfcd437296561ea750c9ec8b","source":"clob_market_ws"},"received_at":"2026-07-27T05:38:45.494695Z","record_id":"65c167956c28fa1a00e763d54c67c59f2ba2ee61e1dd282c0a6007f438745cbe","schema_fingerprint":"4aa3821a28b0b7c2400bc59aba4bcc0a76e971dadd19610d3ad38c768e124dc7","schema_version":"edge-lab-recorder.raw.v1","sequence":null,"source":"clob_market_ws"}
{"event_at":"2026-07-27T05:38:42.338000Z","event_fingerprint":"754a032397cca0c40da23f8bac5f25cf7fcb9ef2bd49307c8512896998548854","payload":{"connection_id":"efc69d3132f1467b8e898a382b23ac0d","event_at":"2026-07-27T05:38:42.338000Z","event_type":"last_trade_price","frame_hash":"09de3a32a7a667b89a5aaa2be9fcace9ab88aec618be25711d4f289df6b24052","frame_index":0,"kind":"data","monotonic_ns":232708732708416,"payload":{"asset_id":"14766054693214075530629349735273995982307625376442606753688071083149620216746","event_type":"last_trade_price","fee_rate_bps":"0","market":"0x3b40066b5cf3871a2f6237c5628bd8092a206aa998558ac5ec13c4483e31e160","price":"0.59","side":"BUY","size":"5","timestamp":"1785130722338","transaction_hash":"0x3e11a329a91fed975449cba490fdc62d23d7b758e5594bc8c0f521d9bf3cf44b"},"payload_hash":"ba4f300aa87fae65390760aa5d637c180d0bd888784d00d7bbbf64d2eb2f901d","raw_frame":"{\"market\":\"0x3b40066b5cf3871a2f6237c5628bd8092a206aa998558ac5ec13c4483e31e160\", \"asset_id\":\"14766054693214075530629349735273995982307625376442606753688071083149620216746\", \"price\":\"0.59\", \"size\":\"5\", \"fee_rate_bps\":\"0\", \"side\":\"BUY\", \"timestamp\":\"1785130722338\", \"event_type\":\"last_trade_price\", \"transaction_hash\":\"0x3e11a329a91fed975449cba490fdc62d23d7b758e5594bc8c0f521d9bf3cf44b\"}","received_at":"2026-07-27T05:38:45.498156Z","schema_version":"clob-market-ws.last_trade_price.v1","sequence":null,"server_hash":null,"server_timestamp":"1785130722338","session_id":"502006c5cfcd437296561ea750c9ec8b","source":"clob_market_ws"},"received_at":"2026-07-27T05:38:45.498156Z","record_id":"f32292787aa07b41c2a0a3f1b0016116b8ae7b3c9fae09d4719b108170e4625a","schema_fingerprint":"95ad9be75a4b695cd99991e12b2592bc7346f3f5388a82d0000ba65bc0d9fd0a","schema_version":"edge-lab-recorder.raw.v1","sequence":null,"source":"clob_market_ws"}
{"event_at":"2026-07-27T05:38:42.345000Z","event_fingerprint":"036c240f0d9dbd8ad7c22a9e4ae286986241517ae6a105e1b2a8a3a853fe5102","payload":{"connection_id":"efc69d3132f1467b8e898a382b23ac0d","event_at":"2026-07-27T05:38:42.345000Z","event_type":"price_change","frame_hash":"33e455e320922fa07203ffb38d13fc4f5ce617f6573a2232bf8f42e3011c4889","frame_index":0,"kind":"data","monotonic_ns":232708735779916,"payload":{"event_type":"price_change","market":"0x3b40066b5cf3871a2f6237c5628bd8092a206aa998558ac5ec13c4483e31e160","price_changes":[{"asset_id":"110216635572655435074987471276357323571387854733835379371586402147734167783946","best_ask":"0.42","best_bid":"0.41","hash":"7c19d8d030ca169726d7199ec83a7e5fecf5d87b","price":"0.38","side":"BUY","size":"169.62"},{"asset_id":"14766054693214075530629349735273995982307625376442606753688071083149620216746","best_ask":"0.59","best_bid":"0.58","hash":"6ecf486c461b2b65b34caaf6b0435c7ec190e155","price":"0.62","side":"SELL","size":"169.62"}],"timestamp":"1785130722345"},"payload_hash":"230e98475802f094865b3f2614368ac2970f9ff02519ff31b6f75ae512ac1f30","raw_frame":"{\"market\":\"0x3b40066b5cf3871a2f6237c5628bd8092a206aa998558ac5ec13c4483e31e160\", \"price_changes\":[{\"asset_id\":\"110216635572655435074987471276357323571387854733835379371586402147734167783946\", \"price\":\"0.38\", \"size\":\"169.62\", \"side\":\"BUY\", \"hash\":\"7c19d8d030ca169726d7199ec83a7e5fecf5d87b\", \"best_bid\":\"0.41\", \"best_ask\":\"0.42\"}, {\"asset_id\":\"14766054693214075530629349735273995982307625376442606753688071083149620216746\", \"price\":\"0.62\", \"size\":\"169.62\", \"side\":\"SELL\", \"hash\":\"6ecf486c461b2b65b34caaf6b0435c7ec190e155\", \"best_bid\":\"0.58\", \"best_ask\":\"0.59\"}], \"timestamp\":\"1785130722345\", \"event_type\":\"price_change\"}","received_at":"2026-07-27T05:38:45.501222Z","schema_version":"clob-market-ws.price_change.v1","sequence":null,"server_hash":null,"server_timestamp":"1785130722345","session_id":"502006c5cfcd437296561ea750c9ec8b","source":"clob_market_ws"},"received_at":"2026-07-27T05:38:45.501222Z","record_id":"4fa5cdd123599f4421ab0072fbcff5613e2f9b709d8ea35d097d342748759cf5","schema_fingerprint":"4aa3821a28b0b7c2400bc59aba4bcc0a76e971dadd19610d3ad38c768e124dc7","schema_version":"edge-lab-recorder.raw.v1","sequence":null,"source":"clob_market_ws"}
{"event_at":"2026-07-27T05:38:42.360000Z","event_fingerprint":"e3aaa394965024558d1feb6f7b3f2a9bbcb697ee286d6680e835e55422aae6c1","payload":{"connection_id":"efc69d3132f1467b8e898a382b23ac0d","event_at":"2026-07-27T05:38:42.360000Z","event_type":"price_change","frame_hash":"e114087220d59b84206bda589e0be9ffa051dc4e6be873f2e4b466c140ec7715","frame_index":0,"kind":"data","monotonic_ns":232708739790833,"payload":{"event_type":"price_change","market":"0x3b40066b5cf3871a2f6237c5628bd8092a206aa998558ac5ec13c4483e31e160","price_changes":[{"asset_id":"14766054693214075530629349735273995982307625376442606753688071083149620216746","best_ask":"0.59","best_bid":"0.58","hash":"c49d4e831b95e8a31bf0cde210cf20411da7ac0e","price":"0.04","side":"BUY","size":"646.09"},{"asset_id":"110216635572655435074987471276357323571387854733835379371586402147734167783946","best_ask":"0.42","best_bid":"0.41","hash":"e8a3ade6a3085df4ab8fcf65ae09bec011ccfc1f","price":"0.96","side":"SELL","size":"646.09"}],"timestamp":"1785130722360"},"payload_hash":"4a8c7176ab1e90dcdebc27fa16542952215c311e1d702fddd41e6a09724e44fd","raw_frame":"{\"market\":\"0x3b40066b5cf3871a2f6237c5628bd8092a206aa998558ac5ec13c4483e31e160\", \"price_changes\":[{\"asset_id\":\"14766054693214075530629349735273995982307625376442606753688071083149620216746\", \"price\":\"0.04\", \"size\":\"646.09\", \"side\":\"BUY\", \"hash\":\"c49d4e831b95e8a31bf0cde210cf20411da7ac0e\", \"best_bid\":\"0.58\", \"best_ask\":\"0.59\"}, {\"asset_id\":\"110216635572655435074987471276357323571387854733835379371586402147734167783946\", \"price\":\"0.96\", \"size\":\"646.09\", \"side\":\"SELL\", \"hash\":\"e8a3ade6a3085df4ab8fcf65ae09bec011ccfc1f\", \"best_bid\":\"0.41\", \"best_ask\":\"0.42\"}], \"timestamp\":\"1785130722360\", \"event_type\":\"price_change\"}","received_at":"2026-07-27T05:38:45.505233Z","schema_version":"clob-market-ws.price_change.v1","sequence":null,"server_hash":null,"server_timestamp":"1785130722360","session_id":"502006c5cfcd437296561ea750c9ec8b","source":"clob_market_ws"},"received_at":"2026-07-27T05:38:45.505233Z","record_id":"900e451ecf9d3d4fc66af417da9d79811e9b80ac30fde645b36839ffbfd4b67a","schema_fingerprint":"4aa3821a28b0b7c2400bc59aba4bcc0a76e971dadd19610d3ad38c768e124dc7","schema_version":"edge-lab-recorder.raw.v1","sequence":null,"source":"clob_market_ws"}
{"event_at":"2026-07-27T05:38:42.360000Z","event_fingerprint":"a34a671235459782cb01f11552bcb5f4f5088099ebfa112892f2c8ee5f9c2edc","payload":{"connection_id":"efc69d3132f1467b8e898a382b23ac0d","event_at":"2026-07-27T05:38:42.360000Z","event_type":"price_change","frame_hash":"731707b63ce307db4d59cf4dba4d5f5b334106aa729c682652474348a960ce25","frame_index":0,"kind":"data","monotonic_ns":232708744143875,"payload":{"event_type":"price_change","market":"0x3b40066b5cf3871a2f6237c5628bd8092a206aa998558ac5ec13c4483e31e160","price_changes":[{"asset_id":"14766054693214075530629349735273995982307625376442606753688071083149620216746","best_ask":"0.59","best_bid":"0.58","hash":"c2f85069f206141e329876ea2215a99f45d649ff","price":"0.64","side":"SELL","size":"132.9"},{"asset_id":"110216635572655435074987471276357323571387854733835379371586402147734167783946","best_ask":"0.42","best_bid":"0.41","hash":"c12f8981e445579db9ce3e8e7fa551f5d6638a6e","price":"0.36","side":"BUY","size":"132.9"}],"timestamp":"1785130722360"},"payload_hash":"6142927fe38a09e765f8b402f4f6a2c5beada51d2ba3b49b0a3b283b862d3278","raw_frame":"{\"market\":\"0x3b40066b5cf3871a2f6237c5628bd8092a206aa998558ac5ec13c4483e31e160\", \"price_changes\":[{\"asset_id\":\"14766054693214075530629349735273995982307625376442606753688071083149620216746\", \"price\":\"0.64\", \"size\":\"132.9\", \"side\":\"SELL\", \"hash\":\"c2f85069f206141e329876ea2215a99f45d649ff\", \"best_bid\":\"0.58\", \"best_ask\":\"0.59\"}, {\"asset_id\":\"110216635572655435074987471276357323571387854733835379371586402147734167783946\", \"price\":\"0.36\", \"size\":\"132.9\", \"side\":\"BUY\", \"hash\":\"c12f8981e445579db9ce3e8e7fa551f5d6638a6e\", \"best_bid\":\"0.41\", \"best_ask\":\"0.42\"}], \"timestamp\":\"1785130722360\", \"event_type\":\"price_change\"}","received_at":"2026-07-27T05:38:45.509586Z","schema_version":"clob-market-ws.price_change.v1","sequence":null,"server_hash":null,"server_timestamp":"1785130722360","session_id":"502006c5cfcd437296561ea750c9ec8b","source":"clob_market_ws"},"received_at":"2026-07-27T05:38:45.509586Z","record_id":"47afea687097f30a5bce9c78cd5e6731e1381ce2ec8f299e2927e7be2ff9ae8b","schema_fingerprint":"4aa3821a28b0b7c2400bc59aba4bcc0a76e971dadd19610d3ad38c768e124dc7","schema_version":"edge-lab-recorder.raw.v1","sequence":null,"source":"clob_market_ws"}
{"event_at":"2026-07-27T05:38:42.361000Z","event_fingerprint":"48f1d8c78cd0b831cfdbb84f03287c9799b25c3c587a510c54027293a240d626","payload":{"connection_id":"efc69d3132f1467b8e898a382b23ac0d","event_at":"2026-07-27T05:38:42.361000Z","event_type":"price_change","frame_hash":"5978d3637449919467af499182ac9fcf75ddd159634436120eb74683cde16776","frame_index":0,"kind":"data","monotonic_ns":232708754365958,"payload":{"event_type":"price_change","market":"0x3b40066b5cf3871a2f6237c5628bd8092a206aa998558ac5ec13c4483e31e160","price_changes":[{"asset_id":"110216635572655435074987471276357323571387854733835379371586402147734167783946","best_ask":"0.42","best_bid":"0.41","hash":"95b4d45b83c87f8c7c1fb97dfdf16e929286ec60","price":"0.36","side":"BUY","size":"107.9"},{"asset_id":"14766054693214075530629349735273995982307625376442606753688071083149620216746","best_ask":"0.59","best_bid":"0.58","hash":"6036267f830138fb0d3fa77163ab6aea93595cdd","price":"0.64","side":"SELL","size":"107.9"}],"timestamp":"1785130722361"},"payload_hash":"5f1b4f515a8b7fb044b3d06050aa8a4f0847279c1151cd6c3ed8f979d2dbef6e","raw_frame":"{\"market\":\"0x3b40066b5cf3871a2f6237c5628bd8092a206aa998558ac5ec13c4483e31e160\", \"price_changes\":[{\"asset_id\":\"110216635572655435074987471276357323571387854733835379371586402147734167783946\", \"price\":\"0.36\", \"size\":\"107.9\", \"side\":\"BUY\", \"hash\":\"95b4d45b83c87f8c7c1fb97dfdf16e929286ec60\", \"best_bid\":\"0.41\", \"best_ask\":\"0.42\"}, {\"asset_id\":\"14766054693214075530629349735273995982307625376442606753688071083149620216746\", \"price\":\"0.64\", \"size\":\"107.9\", \"side\":\"SELL\", \"hash\":\"6036267f830138fb0d3fa77163ab6aea93595cdd\", \"best_bid\":\"0.58\", \"best_ask\":\"0.59\"}], \"timestamp\":\"1785130722361\", \"event_type\":\"price_change\"}","received_at":"2026-07-27T05:38:45.519806Z","schema_version":"clob-market-ws.price_change.v1","sequence":null,"server_hash":null,"server_timestamp":"1785130722361","session_id":"502006c5cfcd437296561ea750c9ec8b","source":"clob_market_ws"},"received_at":"2026-07-27T05:38:45.519806Z","record_id":"9e55780c3d6d3fdb494b7a2336bda9b4a6e9213b5dcb7a3f12eb634b0df20b72","schema_fingerprint":"4aa3821a28b0b7c2400bc59aba4bcc0a76e971dadd19610d3ad38c768e124dc7","schema_version":"edge-lab-recorder.raw.v1","sequence":null,"source":"clob_market_ws"}
{"event_at":"2026-07-27T05:38:42.376000Z","event_fingerprint":"ad73e2561ea8cbbae18c329a8230abc4f96a7c0b548197438332cc659161aaa3","payload":{"connection_id":"efc69d3132f1467b8e898a382b23ac0d","event_at":"2026-07-27T05:38:42.376000Z","event_type":"price_change","frame_hash":"c9d7e5e4eba994f96280c1a1455a106157bac7218916900b75fe8a5d080d3e09","frame_index":0,"kind":"data","monotonic_ns":232708761256041,"payload":{"event_type":"price_change","market":"0x3b40066b5cf3871a2f6237c5628bd8092a206aa998558ac5ec13c4483e31e160","price_changes":[{"asset_id":"110216635572655435074987471276357323571387854733835379371586402147734167783946","best_ask":"0.42","best_bid":"0.41","hash":"1ef695b3bb9a8d576d6d5439f89f944dbe05c2bc","price":"0.01","side":"BUY","size":"5612.45"},{"asset_id":"14766054693214075530629349735273995982307625376442606753688071083149620216746","best_ask":"0.59","best_bid":"0.58","hash":"bc4307a63078c31cc796a06b4091bb48348486bf","price":"0.99","side":"SELL","size":"5612.45"}],"timestamp":"1785130722376"},"payload_hash":"517df68e399416867b56225c5cb634cce3f4c07b0864c6c94c2bdedaf4f4f0f0","raw_frame":"{\"market\":\"0x3b40066b5cf3871a2f6237c5628bd8092a206aa998558ac5ec13c4483e31e160\", \"price_changes\":[{\"asset_id\":\"110216635572655435074987471276357323571387854733835379371586402147734167783946\", \"price\":\"0.01\", \"size\":\"5612.45\", \"side\":\"BUY\", \"hash\":\"1ef695b3bb9a8d576d6d5439f89f944dbe05c2bc\", \"best_bid\":\"0.41\", \"best_ask\":\"0.42\"}, {\"asset_id\":\"14766054693214075530629349735273995982307625376442606753688071083149620216746\", \"price\":\"0.99\", \"size\":\"5612.45\", \"side\":\"SELL\", \"hash\":\"bc4307a63078c31cc796a06b4091bb48348486bf\", \"best_bid\":\"0.58\", \"best_ask\":\"0.59\"}], \"timestamp\":\"1785130722376\", \"event_type\":\"price_change\"}","received_at":"2026-07-27T05:38:45.526698Z","schema_version":"clob-market-ws.price_change.v1","sequence":null,"server_hash":null,"server_timestamp":"1785130722376","session_id":"502006c5cfcd437296561ea750c9ec8b","source":"clob_market_ws"},"received_at":"2026-07-27T05:38:45.526698Z","record_id":"c260ef9241da93b3208f28b9d09169808dfb77fc0eccbb9cb1036bda19bd59bf","schema_fingerprint":"4aa3821a28b0b7c2400bc59aba4bcc0a76e971dadd19610d3ad38c768e124dc7","schema_version":"edge-lab-recorder.raw.v1","sequence":null,"source":"clob_market_ws"}
{"event_at":"2026-07-27T05:38:42.377000Z","event_fingerprint":"fb32fe38115ad57f5f7071ef733bf6c88b2a6d413503595980e2dc5c77ee4164","payload":{"connection_id":"efc69d3132f1467b8e898a382b23ac0d","event_at":"2026-07-27T05:38:42.377000Z","event_type":"price_change","frame_hash":"ac5d0c9e52bb05d02b686d60488200e23a95c023e7816da0be9cb3f552d6c54f","frame_index":0,"kind":"data","monotonic_ns":232708766876500,"payload":{"event_type":"price_change","market":"0x3b40066b5cf3871a2f6237c5628bd8092a206aa998558ac5ec13c4483e31e160","price_changes":[{"asset_id":"14766054693214075530629349735273995982307625376442606753688071083149620216746","best_ask":"0.59","best_bid":"0.58","hash":"37443dbf1aa90076fe4b4d1130650bf3c730fac7","price":"0.58","side":"BUY","size":"387"},{"asset_id":"110216635572655435074987471276357323571387854733835379371586402147734167783946","best_ask":"0.42","best_bid":"0.41","hash":"2671703da77fdb2faaf10cdc634602ccfae5cc04","price":"0.42","side":"SELL","size":"387"}],"timestamp":"1785130722377"},"payload_hash":"4dadc220a2effe006b2c0ec914900a3c1ac2ad1c386584a6159f445c8d13463c","raw_frame":"{\"market\":\"0x3b40066b5cf3871a2f6237c5628bd8092a206aa998558ac5ec13c4483e31e160\", \"price_changes\":[{\"asset_id\":\"14766054693214075530629349735273995982307625376442606753688071083149620216746\", \"price\":\"0.58\", \"size\":\"387\", \"side\":\"BUY\", \"hash\":\"37443dbf1aa90076fe4b4d1130650bf3c730fac7\", \"best_bid\":\"0.58\", \"best_ask\":\"0.59\"}, {\"asset_id\":\"110216635572655435074987471276357323571387854733835379371586402147734167783946\", \"price\":\"0.42\", \"size\":\"387\", \"side\":\"SELL\", \"hash\":\"2671703da77fdb2faaf10cdc634602ccfae5cc04\", \"best_bid\":\"0.41\", \"best_ask\":\"0.42\"}], \"timestamp\":\"1785130722377\", \"event_type\":\"price_change\"}","received_at":"2026-07-27T05:38:45.532319Z","schema_version":"clob-market-ws.price_change.v1","sequence":null,"server_hash":null,"server_timestamp":"1785130722377","session_id":"502006c5cfcd437296561ea750c9ec8b","source":"clob_market_ws"},"received_at":"2026-07-27T05:38:45.532319Z","record_id":"e1df46e91884793794110e09c29670f2655ac4b830fce2eefe1e773b6ec3cc43","schema_fingerprint":"4aa3821a28b0b7c2400bc59aba4bcc0a76e971dadd19610d3ad38c768e124dc7","schema_version":"edge-lab-recorder.raw.v1","sequence":null,"source":"clob_market_ws"}
{"event_at":"2026-07-27T05:38:42.379000Z","event_fingerprint":"f2339c1fcd382d9897cc62e03dd6e9a60a4e3edf242948ea853bcc750e4437f4","payload":{"connection_id":"efc69d3132f1467b8e898a382b23ac0d","event_at":"2026-07-27T05:38:42.379000Z","event_type":"price_change","frame_hash":"d1577c62f5449cb66ed36a75de1e57f3538598f2bc9dd40f21a08727882134e3","frame_index":0,"kind":"data","monotonic_ns":232708776628666,"payload":{"event_type":"price_change","market":"0x3b40066b5cf3871a2f6237c5628bd8092a206aa998558ac5ec13c4483e31e160","price_changes":[{"asset_id":"110216635572655435074987471276357323571387854733835379371586402147734167783946","best_ask":"0.42","best_bid":"0.41","hash":"d8835117a4be85542d7e43007db58c9e18031e3b","price":"0.42","side":"SELL","size":"382"},{"asset_id":"14766054693214075530629349735273995982307625376442606753688071083149620216746","best_ask":"0.59","best_bid":"0.58","hash":"b71bdb548324fda698ce21e1b87cb08b8a82be1d","price":"0.58","side":"BUY","size":"382"}],"timestamp":"1785130722379"},"payload_hash":"18e183bcd9f590e4d63de08ab0ebd65583d93c2d05cabbfa795c03cfa410d646","raw_frame":"{\"market\":\"0x3b40066b5cf3871a2f6237c5628bd8092a206aa998558ac5ec13c4483e31e160\", \"price_changes\":[{\"asset_id\":\"110216635572655435074987471276357323571387854733835379371586402147734167783946\", \"price\":\"0.42\", \"size\":\"382\", \"side\":\"SELL\", \"hash\":\"d8835117a4be85542d7e43007db58c9e18031e3b\", \"best_bid\":\"0.41\", \"best_ask\":\"0.42\"}, {\"asset_id\":\"14766054693214075530629349735273995982307625376442606753688071083149620216746\", \"price\":\"0.58\", \"size\":\"382\", \"side\":\"BUY\", \"hash\":\"b71bdb548324fda698ce21e1b87cb08b8a82be1d\", \"best_bid\":\"0.58\", \"best_ask\":\"0.59\"}], \"timestamp\":\"1785130722379\", \"event_type\":\"price_change\"}","received_at":"2026-07-27T05:38:45.542069Z","schema_version":"clob-market-ws.price_change.v1","sequence":null,"server_hash":null,"server_timestamp":"1785130722379","session_id":"502006c5cfcd437296561ea750c9ec8b","source":"clob_market_ws"},"received_at":"2026-07-27T05:38:45.542069Z","record_id":"aeb8950464b2bb33cc82e25fa8908427dc1d269591c9a84d4253ddb7a3af323e","schema_fingerprint":"4aa3821a28b0b7c2400bc59aba4bcc0a76e971dadd19610d3ad38c768e124dc7","schema_version":"edge-lab-recorder.raw.v1","sequence":null,"source":"clob_market_ws"}
{"event_at":"2026-07-27T05:38:42.380000Z","event_fingerprint":"a7b38deef8daa03465e7cc705f7549e85144fd485602cb7ba3ae7b7fa1e51376","payload":{"connection_id":"efc69d3132f1467b8e898a382b23ac0d","event_at":"2026-07-27T05:38:42.380000Z","event_type":"price_change","frame_hash":"7d1b680aea81b1fe215c81ebd1b0e0ed7223b46e1147615d5d7ecf877a75d726","frame_index":0,"kind":"data","monotonic_ns":232708781243666,"payload":{"event_type":"price_change","market":"0x3b40066b5cf3871a2f6237c5628bd8092a206aa998558ac5ec13c4483e31e160","price_changes":[{"asset_id":"14766054693214075530629349735273995982307625376442606753688071083149620216746","best_ask":"0.59","best_bid":"0.58","hash":"4a4e4743c27c2ee64820cb83d65a71536d9ebb8c","price":"0.58","side":"BUY","size":"373"},{"asset_id":"110216635572655435074987471276357323571387854733835379371586402147734167783946","best_ask":"0.42","best_bid":"0.41","hash":"d6cb2011caedabca0b1a204f1089e3f510566c37","price":"0.42","side":"SELL","size":"373"}],"timestamp":"1785130722380"},"payload_hash":"7222c5edb66b07e3c84fc8243fe046022d2183c26c127fbd63796332c3e942c9","raw_frame":"{\"market\":\"0x3b40066b5cf3871a2f6237c5628bd8092a206aa998558ac5ec13c4483e31e160\", \"price_changes\":[{\"asset_id\":\"14766054693214075530629349735273995982307625376442606753688071083149620216746\", \"price\":\"0.58\", \"size\":\"373\", \"side\":\"BUY\", \"hash\":\"4a4e4743c27c2ee64820cb83d65a71536d9ebb8c\", \"best_bid\":\"0.58\", \"best_ask\":\"0.59\"}, {\"asset_id\":\"110216635572655435074987471276357323571387854733835379371586402147734167783946\", \"price\":\"0.42\", \"size\":\"373\", \"side\":\"SELL\", \"hash\":\"d6cb2011caedabca0b1a204f1089e3f510566c37\", \"best_bid\":\"0.41\", \"best_ask\":\"0.42\"}], \"timestamp\":\"1785130722380\", \"event_type\":\"price_change\"}","received_at":"2026-07-27T05:38:45.546684Z","schema_version":"clob-market-ws.price_change.v1","sequence":null,"server_hash":null,"server_timestamp":"1785130722380","session_id":"502006c5cfcd437296561ea750c9ec8b","source":"clob_market_ws"},"received_at":"2026-07-27T05:38:45.546684Z","record_id":"47d575d9b7a65a938ff871ea20b75a6e2bc1d78f4e4a0795446262180dd49486","schema_fingerprint":"4aa3821a28b0b7c2400bc59aba4bcc0a76e971dadd19610d3ad38c768e124dc7","schema_version":"edge-lab-recorder.raw.v1","sequence":null,"source":"clob_market_ws"}
{"event_at":"2026-07-27T05:38:42.381000Z","event_fingerprint":"db1b3437baff8d100067ffa40a95f15aeb78cdd4e4a9b978a16c4b7383416439","payload":{"connection_id":"efc69d3132f1467b8e898a382b23ac0d","event_at":"2026-07-27T05:38:42.381000Z","event_type":"price_change","frame_hash":"198a5bee4b1d7c8b6c90b1f48d33c4330c1fe8b2f94cb0534dad0d72961d01ad","frame_index":0,"kind":"data","monotonic_ns":232708783503750,"payload":{"event_type":"price_change","market":"0x3b40066b5cf3871a2f6237c5628bd8092a206aa998558ac5ec13c4483e31e160","price_changes":[{"asset_id":"110216635572655435074987471276357323571387854733835379371586402147734167783946","best_ask":"0.42","best_bid":"0.41","hash":"0af56af11a565a0b160ea377047ddeb7b2580229","price":"0.42","side":"SELL","size":"366"},{"asset_id":"14766054693214075530629349735273995982307625376442606753688071083149620216746","best_ask":"0.59","best_bid":"0.58","hash":"d2daf6272ef4b6143aa73a4d9fb9236a3dc5cd26","price":"0.58","side":"BUY","size":"366"}],"timestamp":"1785130722381"},"payload_hash":"47d7d915ce8142d06e338c628aad167fd78a998eb0cb077c3bd416bf92f84119","raw_frame":"{\"market\":\"0x3b40066b5cf3871a2f6237c5628bd8092a206aa998558ac5ec13c4483e31e160\", \"price_changes\":[{\"asset_id\":\"110216635572655435074987471276357323571387854733835379371586402147734167783946\", \"price\":\"0.42\", \"size\":\"366\", \"side\":\"SELL\", \"hash\":\"0af56af11a565a0b160ea377047ddeb7b2580229\", \"best_bid\":\"0.41\", \"best_ask\":\"0.42\"}, {\"asset_id\":\"14766054693214075530629349735273995982307625376442606753688071083149620216746\", \"price\":\"0.58\", \"size\":\"366\", \"side\":\"BUY\", \"hash\":\"d2daf6272ef4b6143aa73a4d9fb9236a3dc5cd26\", \"best_bid\":\"0.58\", \"best_ask\":\"0.59\"}], \"timestamp\":\"1785130722381\", \"event_type\":\"price_change\"}","received_at":"2026-07-27T05:38:45.548946Z","schema_version":"clob-market-ws.price_change.v1","sequence":null,"server_hash":null,"server_timestamp":"1785130722381","session_id":"502006c5cfcd437296561ea750c9ec8b","source":"clob_market_ws"},"received_at":"2026-07-27T05:38:45.548946Z","record_id":"8288945046051e3ee01c629d554e05ce04320a6c7fee4e6aa93896a8e69c9dce","schema_fingerprint":"4aa3821a28b0b7c2400bc59aba4bcc0a76e971dadd19610d3ad38c768e124dc7","schema_version":"edge-lab-recorder.raw.v1","sequence":null,"source":"clob_market_ws"}
{"event_at":"2026-07-27T05:38:42.381000Z","event_fingerprint":"180adeab10ff10d1bcbc647f7bbf38bf45b04e1e2e953e20f7dfc6779896d3b3","payload":{"connection_id":"efc69d3132f1467b8e898a382b23ac0d","event_at":"2026-07-27T05:38:42.381000Z","event_type":"price_change","frame_hash":"d47f485518d7c3df7d8380b7e2d8ac9fc4020834935072b34355f28d18829eb0","frame_index":0,"kind":"data","monotonic_ns":232708787515791,"payload":{"event_type":"price_change","market":"0x3b40066b5cf3871a2f6237c5628bd8092a206aa998558ac5ec13c4483e31e160","price_changes":[{"asset_id":"14766054693214075530629349735273995982307625376442606753688071083149620216746","best_ask":"0.59","best_bid":"0.58","hash":"4b74f33499fd0dd67a627f17b1cf3751ce4452be","price":"0.57","side":"BUY","size":"96"},{"asset_id":"110216635572655435074987471276357323571387854733835379371586402147734167783946","best_ask":"0.42","best_bid":"0.41","hash":"644f366a8027eab309c4a1a0285db20f3e1d81ff","price":"0.43","side":"SELL","size":"96"}],"timestamp":"1785130722381"},"payload_hash":"5031b93dc044789b7c6ed82645e4f14232d5d1012c42e2c6e59fd521431812cd","raw_frame":"{\"market\":\"0x3b40066b5cf3871a2f6237c5628bd8092a206aa998558ac5ec13c4483e31e160\", \"price_changes\":[{\"asset_id\":\"14766054693214075530629349735273995982307625376442606753688071083149620216746\", \"price\":\"0.57\", \"size\":\"96\", \"side\":\"BUY\", \"hash\":\"4b74f33499fd0dd67a627f17b1cf3751ce4452be\", \"best_bid\":\"0.58\", \"best_ask\":\"0.59\"}, {\"asset_id\":\"110216635572655435074987471276357323571387854733835379371586402147734167783946\", \"price\":\"0.43\", \"size\":\"96\", \"side\":\"SELL\", \"hash\":\"644f366a8027eab309c4a1a0285db20f3e1d81ff\", \"best_bid\":\"0.41\", \"best_ask\":\"0.42\"}], \"timestamp\":\"1785130722381\", \"event_type\":\"price_change\"}","received_at":"2026-07-27T05:38:45.552958Z","schema_version":"clob-market-ws.price_change.v1","sequence":null,"server_hash":null,"server_timestamp":"1785130722381","session_id":"502006c5cfcd437296561ea750c9ec8b","source":"clob_market_ws"},"received_at":"2026-07-27T05:38:45.552958Z","record_id":"8cc4635a8fefb40906bdee9f8b417b0021b6dcb58b36d7321ccb0375e28a015c","schema_fingerprint":"4aa3821a28b0b7c2400bc59aba4bcc0a76e971dadd19610d3ad38c768e124dc7","schema_version":"edge-lab-recorder.raw.v1","sequence":null,"source":"clob_market_ws"}
{"event_at":"2026-07-27T05:38:42.382000Z","event_fingerprint":"bbd7c435377034a5376811102136c328be2c3b9d5923bfa3fec6e8b778c2cce4","payload":{"connection_id":"efc69d3132f1467b8e898a382b23ac0d","event_at":"2026-07-27T05:38:42.382000Z","event_type":"price_change","frame_hash":"e74a7592788f1c4fcc7a51aad0345402606d722d90f07bc78c96a59be0dbd51b","frame_index":0,"kind":"data","monotonic_ns":232708791843958,"payload":{"event_type":"price_change","market":"0x3b40066b5cf3871a2f6237c5628bd8092a206aa998558ac5ec13c4483e31e160","price_changes":[{"asset_id":"110216635572655435074987471276357323571387854733835379371586402147734167783946","best_ask":"0.42","best_bid":"0.41","hash":"1b3dd948392127307505cafa7e76d6941c0158a4","price":"0.37","side":"BUY","size":"72.27"},{"asset_id":"14766054693214075530629349735273995982307625376442606753688071083149620216746","best_ask":"0.59","best_bid":"0.58","hash":"ff4ce1482e638cf241d5810a09786936e975377f","price":"0.63","side":"SELL","size":"72.27"}],"timestamp":"1785130722382"},"payload_hash":"a11ddb3e111a765a60af10172ce4fb839c8104521aaec180780615f8be525a6c","raw_frame":"{\"market\":\"0x3b40066b5cf3871a2f6237c5628bd8092a206aa998558ac5ec13c4483e31e160\", \"price_changes\":[{\"asset_id\":\"110216635572655435074987471276357323571387854733835379371586402147734167783946\", \"price\":\"0.37\", \"size\":\"72.27\", \"side\":\"BUY\", \"hash\":\"1b3dd948392127307505cafa7e76d6941c0158a4\", \"best_bid\":\"0.41\", \"best_ask\":\"0.42\"}, {\"asset_id\":\"14766054693214075530629349735273995982307625376442606753688071083149620216746\", \"price\":\"0.63\", \"size\":\"72.27\", \"side\":\"SELL\", \"hash\":\"ff4ce1482e638cf241d5810a09786936e975377f\", \"best_bid\":\"0.58\", \"best_ask\":\"0.59\"}], \"timestamp\":\"1785130722382\", \"event_type\":\"price_change\"}","received_at":"2026-07-27T05:38:45.557287Z","schema_version":"clob-market-ws.price_change.v1","sequence":null,"server_hash":null,"server_timestamp":"1785130722382","session_id":"502006c5cfcd437296561ea750c9ec8b","source":"clob_market_ws"},"received_at":"2026-07-27T05:38:45.557287Z","record_id":"2ad7e24550d7704a65c5a75f2631785b24ef3d9bb73ee054dbf8f51a02da5c6f","schema_fingerprint":"4aa3821a28b0b7c2400bc59aba4bcc0a76e971dadd19610d3ad38c768e124dc7","schema_version":"edge-lab-recorder.raw.v1","sequence":null,"source":"clob_market_ws"}
{"event_at":"2026-07-27T05:38:42.383000Z","event_fingerprint":"b93c3a043f24d4b83e079a9dddf431a967d363c40cfd05f120f33d61dfcec9b1","payload":{"connection_id":"efc69d3132f1467b8e898a382b23ac0d","event_at":"2026-07-27T05:38:42.383000Z","event_type":"price_change","frame_hash":"ade981f5d4027d6a5e70966e7b7449b9f0d8f42cd3d591f366052e41a43da0bd","frame_index":0,"kind":"data","monotonic_ns":232708798835458,"payload":{"event_type":"price_change","market":"0x3b40066b5cf3871a2f6237c5628bd8092a206aa998558ac5ec13c4483e31e160","price_changes":[{"asset_id":"110216635572655435074987471276357323571387854733835379371586402147734167783946","best_ask":"0.42","best_bid":"0.41","hash":"ec716e1f26702a897f0b59033f2ef54c920d5df6","price":"0.38","side":"BUY","size":"439.62"},{"asset_id":"14766054693214075530629349735273995982307625376442606753688071083149620216746","best_ask":"0.59","best_bid":"0.58","hash":"9a805858c39dbd89285ab41d7f99da72a896a42a","price":"0.62","side":"SELL","size":"439.62"}],"timestamp":"1785130722383"},"payload_hash":"e47cca9bdd4b102bf22464cd710d5038ccd433b20e5dca7c7ffec2a148028439","raw_frame":"{\"market\":\"0x3b40066b5cf3871a2f6237c5628bd8092a206aa998558ac5ec13c4483e31e160\", \"price_changes\":[{\"asset_id\":\"110216635572655435074987471276357323571387854733835379371586402147734167783946\", \"price\":\"0.38\", \"size\":\"439.62\", \"side\":\"BUY\", \"hash\":\"ec716e1f26702a897f0b59033f2ef54c920d5df6\", \"best_bid\":\"0.41\", \"best_ask\":\"0.42\"}, {\"asset_id\":\"14766054693214075530629349735273995982307625376442606753688071083149620216746\", \"price\":\"0.62\", \"size\":\"439.62\", \"side\":\"SELL\", \"hash\":\"9a805858c39dbd89285ab41d7f99da72a896a42a\", \"best_bid\":\"0.58\", \"best_ask\":\"0.59\"}], \"timestamp\":\"1785130722383\", \"event_type\":\"price_change\"}","received_at":"2026-07-27T05:38:45.564283Z","schema_version":"clob-market-ws.price_change.v1","sequence":null,"server_hash":null,"server_timestamp":"1785130722383","session_id":"502006c5cfcd437296561ea750c9ec8b","source":"clob_market_ws"},"received_at":"2026-07-27T05:38:45.564283Z","record_id":"36b58b4a3876b7201d1fb95eca39e42810aaa3b8dfb741cb3537aa1afc6c8d14","schema_fingerprint":"4aa3821a28b0b7c2400bc59aba4bcc0a76e971dadd19610d3ad38c768e124dc7","schema_version":"edge-lab-recorder.raw.v1","sequence":null,"source":"clob_market_ws"}
{"event_at":"2026-07-27T05:38:42.385000Z","event_fingerprint":"a0d1413c31a30aa0f373fa5725ee060af82be514cb50c7e0fb2ee265168e4caa","payload":{"connection_id":"efc69d3132f1467b8e898a382b23ac0d","event_at":"2026-07-27T05:38:42.385000Z","event_type":"price_change","frame_hash":"bb80773db878ca0a4244f048f114c9e0a336db064412b263094ff8bb0c965aa7","frame_index":0,"kind":"data","monotonic_ns":232708806271083,"payload":{"event_type":"price_change","market":"0x3b40066b5cf3871a2f6237c5628bd8092a206aa998558ac5ec13c4483e31e160","price_changes":[{"asset_id":"14766054693214075530629349735273995982307625376442606753688071083149620216746","best_ask":"0.59","best_bid":"0.58","hash":"856d0a393d35f07043d736af50e6499f34ea11d4","price":"0.58","side":"BUY","size":"96"},{"asset_id":"110216635572655435074987471276357323571387854733835379371586402147734167783946","best_ask":"0.42","best_bid":"0.41","hash":"cc4a1fb03f06d9ad882b95aec43464cbeffbcefb","price":"0.42","side":"SELL","size":"96"}],"timestamp":"1785130722385"},"payload_hash":"7ed189fb8f8fcec8a0dabab2751a915dde4826dcbcedc70cca46933eca0d0b75","raw_frame":"{\"market\":\"0x3b40066b5cf3871a2f6237c5628bd8092a206aa998558ac5ec13c4483e31e160\", \"price_changes\":[{\"asset_id\":\"14766054693214075530629349735273995982307625376442606753688071083149620216746\", \"price\":\"0.58\", \"size\":\"96\", \"side\":\"BUY\", \"hash\":\"856d0a393d35f07043d736af50e6499f34ea11d4\", \"best_bid\":\"0.58\", \"best_ask\":\"0.59\"}, {\"asset_id\":\"110216635572655435074987471276357323571387854733835379371586402147734167783946\", \"price\":\"0.42\", \"size\":\"96\", \"side\":\"SELL\", \"hash\":\"cc4a1fb03f06d9ad882b95aec43464cbeffbcefb\", \"best_bid\":\"0.41\", \"best_ask\":\"0.42\"}], \"timestamp\":\"1785130722385\", \"event_type\":\"price_change\"}","received_at":"2026-07-27T05:38:45.571713Z","schema_version":"clob-market-ws.price_change.v1","sequence":null,"server_hash":null,"server_timestamp":"1785130722385","session_id":"502006c5cfcd437296561ea750c9ec8b","source":"clob_market_ws"},"received_at":"2026-07-27T05:38:45.571713Z","record_id":"e8517cfd1129d7c941e8127555e8e81f0073b0ee9340ddf97df8d2b680a96957","schema_fingerprint":"4aa3821a28b0b7c2400bc59aba4bcc0a76e971dadd19610d3ad38c768e124dc7","schema_version":"edge-lab-recorder.raw.v1","sequence":null,"source":"clob_market_ws"}
{"event_at":null,"event_fingerprint":"70b6aca902f7f048a234c3d52d462652568b517001a8a017f9caa4b97d207915","payload":{"connection_id":"efc69d3132f1467b8e898a382b23ac0d","detail":{"interval_seconds":10.0,"message":"PING"},"event_type":"heartbeat","kind":"lifecycle","monotonic_ns":232708816471125,"received_at":"2026-07-27T05:38:45.581911Z","schema_version":"edge-lab-recorder.lifecycle.v1","session_id":"502006c5cfcd437296561ea750c9ec8b","source":"clob_market_ws"},"received_at":"2026-07-27T05:38:45.581911Z","record_id":"6b32a3ffbc26f36944e5682217fb8b307f194df0d24d344d72ec21a80720f9f1","schema_fingerprint":"cb8aa3aa4cb168a4b724fd9077bee6ecfb9bc586c57cfdf0ab89f00d82045e3c","schema_version":"edge-lab-recorder.raw.v1","sequence":null,"source":"clob_market_ws"}
{"event_at":"2026-07-27T05:38:42.385000Z","event_fingerprint":"6532e50e57e468f4bce79fc1d8d792c77d1b4c611097bba5ce61a77b27bf262b","payload":{"connection_id":"efc69d3132f1467b8e898a382b23ac0d","event_at":"2026-07-27T05:38:42.385000Z","event_type":"best_bid_ask","frame_hash":"85b680e15aced6a212180c8ec56a2638ae0ac158be62823a04298d24edef132c","frame_index":0,"kind":"data","monotonic_ns":232708816599833,"payload":{"asset_id":"14766054693214075530629349735273995982307625376442606753688071083149620216746","best_ask":"0.59","best_bid":"0.57","event_type":"best_bid_ask","market":"0x3b40066b5cf3871a2f6237c5628bd8092a206aa998558ac5ec13c4483e31e160","spread":"0.02","timestamp":"1785130722385"},"payload_hash":"63892d576e9028640cff0632afd666766e5ba1743f49a19fcd0244307670759c","raw_frame":"{\"market\":\"0x3b40066b5cf3871a2f6237c5628bd8092a206aa998558ac5ec13c4483e31e160\", \"asset_id\":\"14766054693214075530629349735273995982307625376442606753688071083149620216746\", \"best_bid\":\"0.57\", \"best_ask\":\"0.59\", \"spread\":\"0.02\", \"timestamp\":\"1785130722385\", \"event_type\":\"best_bid_ask\"}","received_at":"2026-07-27T05:38:45.582041Z","schema_version":"clob-market-ws.best_bid_ask.v1","sequence":null,"server_hash":null,"server_timestamp":"1785130722385","session_id":"502006c5cfcd437296561ea750c9ec8b","source":"clob_market_ws"},"received_at":"2026-07-27T05:38:45.582041Z","record_id":"4b4ce791714020a2552c776fe0a2b71cf7d18cfd1c2f7a29b0709dbdc0a17ef5","schema_fingerprint":"8488399f31b0337811b13b266be932db7062827c2470b78bd8e9e99bab51d17d","schema_version":"edge-lab-recorder.raw.v1","sequence":null,"source":"clob_market_ws"}
{"event_at":"2026-07-27T05:38:42.385000Z","event_fingerprint":"3599090fd78e8867eaf73cfe471a6d3291e0897e7e898a68c5d40321e2003e6d","payload":{"connection_id":"efc69d3132f1467b8e898a382b23ac0d","event_at":"2026-07-27T05:38:42.385000Z","event_type":"best_bid_ask","frame_hash":"20f39679c6197dd5d7cc0f395ad87960eba61c812bd7d054da80211c6566be04","frame_index":0,"kind":"data","monotonic_ns":232708823119833,"payload":{"asset_id":"110216635572655435074987471276357323571387854733835379371586402147734167783946","best_ask":"0.43","best_bid":"0.41","event_type":"best_bid_ask","market":"0x3b40066b5cf3871a2f6237c5628bd8092a206aa998558ac5ec13c4483e31e160","spread":"0.02","timestamp":"1785130722385"},"payload_hash":"6db0e86f79edde8ad0b97dd52a99e6a514a8a92787c0ad8cc3aee8f7e2bdbee0","raw_frame":"{\"market\":\"0x3b40066b5cf3871a2f6237c5628bd8092a206aa998558ac5ec13c4483e31e160\", \"asset_id\":\"110216635572655435074987471276357323571387854733835379371586402147734167783946\", \"best_bid\":\"0.41\", \"best_ask\":\"0.43\", \"spread\":\"0.02\", \"timestamp\":\"1785130722385\", \"event_type\":\"best_bid_ask\"}","received_at":"2026-07-27T05:38:45.588562Z","schema_version":"clob-market-ws.best_bid_ask.v1","sequence":null,"server_hash":null,"server_timestamp":"1785130722385","session_id":"502006c5cfcd437296561ea750c9ec8b","source":"clob_market_ws"},"received_at":"2026-07-27T05:38:45.588562Z","record_id":"d6fb37fc4fc09c0d31938cb5c126c09ee284a6eee168151146ec1a16cdd540a8","schema_fingerprint":"8488399f31b0337811b13b266be932db7062827c2470b78bd8e9e99bab51d17d","schema_version":"edge-lab-recorder.raw.v1","sequence":null,"source":"clob_market_ws"}
{"event_at":"2026-07-27T05:38:42.385000Z","event_fingerprint":"a2a550ff11c39a2f8884e6dd0ef614035df1bb5b8c6ab9d248a055467a739480","payload":{"connection_id":"efc69d3132f1467b8e898a382b23ac0d","event_at":"2026-07-27T05:38:42.385000Z","event_type":"price_change","frame_hash":"5399095ce1e98b58de2a2a781d880ccd759a3d4b392a528a17164e1e201a88c6","frame_index":0,"kind":"data","monotonic_ns":232708826593750,"payload":{"event_type":"price_change","market":"0x3b40066b5cf3871a2f6237c5628bd8092a206aa998558ac5ec13c4483e31e160","price_changes":[{"asset_id":"14766054693214075530629349735273995982307625376442606753688071083149620216746","best_ask":"0.59","best_bid":"0.57","hash":"ad5b4b8f29f933b5840fdd273022d696f13ca86b","price":"0.58","side":"BUY","size":"0"},{"asset_id":"110216635572655435074987471276357323571387854733835379371586402147734167783946","best_ask":"0.43","best_bid":"0.41","hash":"a34668b7e287f66a156c74fcec7a4333f41db259","price":"0.42","side":"SELL","size":"0"}],"timestamp":"1785130722385"},"payload_hash":"aef7d6bae661d588b37c0d42c40257190aacc12116251ef811228234363aaff2","raw_frame":"{\"market\":\"0x3b40066b5cf3871a2f6237c5628bd8092a206aa998558ac5ec13c4483e31e160\", \"price_changes\":[{\"asset_id\":\"14766054693214075530629349735273995982307625376442606753688071083149620216746\", \"price\":\"0.58\", \"size\":\"0\", \"side\":\"BUY\", \"hash\":\"ad5b4b8f29f933b5840fdd273022d696f13ca86b\", \"best_bid\":\"0.57\", \"best_ask\":\"0.59\"}, {\"asset_id\":\"110216635572655435074987471276357323571387854733835379371586402147734167783946\", \"price\":\"0.42\", \"size\":\"0\", \"side\":\"SELL\", \"hash\":\"a34668b7e287f66a156c74fcec7a4333f41db259\", \"best_bid\":\"0.41\", \"best_ask\":\"0.43\"}], \"timestamp\":\"1785130722385\", \"event_type\":\"price_change\"}","received_at":"2026-07-27T05:38:45.592037Z","schema_version":"clob-market-ws.price_change.v1","sequence":null,"server_hash":null,"server_timestamp":"1785130722385","session_id":"502006c5cfcd437296561ea750c9ec8b","source":"clob_market_ws"},"received_at":"2026-07-27T05:38:45.592037Z","record_id":"f7a3c12d77e7f9ffddf8e9f5f88bb679ed8ab9bd35c46a99191a3ab638db7341","schema_fingerprint":"4aa3821a28b0b7c2400bc59aba4bcc0a76e971dadd19610d3ad38c768e124dc7","schema_version":"edge-lab-recorder.raw.v1","sequence":null,"source":"clob_market_ws"}
{"event_at":"2026-07-27T05:38:42.385000Z","event_fingerprint":"88bf7847975790673141e841bc4ced2264c2d785516c3acf952764768d760d9c","payload":{"connection_id":"efc69d3132f1467b8e898a382b23ac0d","event_at":"2026-07-27T05:38:42.385000Z","event_type":"price_change","frame_hash":"aa92e515d8f327e098536bcb492ab75701578664be93d9e715c19a6d49393b2e","frame_index":0,"kind":"data","monotonic_ns":232708831233375,"payload":{"event_type":"price_change","market":"0x3b40066b5cf3871a2f6237c5628bd8092a206aa998558ac5ec13c4483e31e160","price_changes":[{"asset_id":"110216635572655435074987471276357323571387854733835379371586402147734167783946","best_ask":"0.43","best_bid":"0.41","hash":"a34668b7e287f66a156c74fcec7a4333f41db259","price":"0.38","side":"BUY","size":"343.62"},{"asset_id":"14766054693214075530629349735273995982307625376442606753688071083149620216746","best_ask":"0.59","best_bid":"0.57","hash":"ad5b4b8f29f933b5840fdd273022d696f13ca86b","price":"0.62","side":"SELL","size":"343.62"}],"timestamp":"1785130722385"},"payload_hash":"6c1fce44e753dbc882fcc9537ebad9e18cf57fc4d5478983d0c0913425bf1337","raw_frame":"{\"market\":\"0x3b40066b5cf3871a2f6237c5628bd8092a206aa998558ac5ec13c4483e31e160\", \"price_changes\":[{\"asset_id\":\"110216635572655435074987471276357323571387854733835379371586402147734167783946\", \"price\":\"0.38\", \"size\":\"343.62\", \"side\":\"BUY\", \"hash\":\"a34668b7e287f66a156c74fcec7a4333f41db259\", \"best_bid\":\"0.41\", \"best_ask\":\"0.43\"}, {\"asset_id\":\"14766054693214075530629349735273995982307625376442606753688071083149620216746\", \"price\":\"0.62\", \"size\":\"343.62\", \"side\":\"SELL\", \"hash\":\"ad5b4b8f29f933b5840fdd273022d696f13ca86b\", \"best_bid\":\"0.57\", \"best_ask\":\"0.59\"}], \"timestamp\":\"1785130722385\", \"event_type\":\"price_change\"}","received_at":"2026-07-27T05:38:45.596677Z","schema_version":"clob-market-ws.price_change.v1","sequence":null,"server_hash":null,"server_timestamp":"1785130722385","session_id":"502006c5cfcd437296561ea750c9ec8b","source":"clob_market_ws"},"received_at":"2026-07-27T05:38:45.596677Z","record_id":"b103c9afbc15457985b427e69c39a21200d62e8c0ed90683c03e70582cf543d4","schema_fingerprint":"4aa3821a28b0b7c2400bc59aba4bcc0a76e971dadd19610d3ad38c768e124dc7","schema_version":"edge-lab-recorder.raw.v1","sequence":null,"source":"clob_market_ws"}
{"event_at":"2026-07-27T05:38:42.385000Z","event_fingerprint":"3d9ac2b89dcc24e6ab97081fe427e44d3be39d8e7d453bd5c3ddc08c4f884d90","payload":{"connection_id":"efc69d3132f1467b8e898a382b23ac0d","event_at":"2026-07-27T05:38:42.385000Z","event_type":"best_bid_ask","frame_hash":"3ba8c36bdbebb861f7b91570c2a2688387aea68dc8bb6983a77ddd09e86da520","frame_index":0,"kind":"data","monotonic_ns":232708839928125,"payload":{"asset_id":"14766054693214075530629349735273995982307625376442606753688071083149620216746","best_ask":"0.58","best_bid":"0.57","event_type":"best_bid_ask","market":"0x3b40066b5cf3871a2f6237c5628bd8092a206aa998558ac5ec13c4483e31e160","spread":"0.01","timestamp":"1785130722385"},"payload_hash":"009ae49fcbcac161a7f6fd98265fe997fbbedf73d989c909135b27ba2b2b238c","raw_frame":"{\"market\":\"0x3b40066b5cf3871a2f6237c5628bd8092a206aa998558ac5ec13c4483e31e160\", \"asset_id\":\"14766054693214075530629349735273995982307625376442606753688071083149620216746\", \"best_bid\":\"0.57\", \"best_ask\":\"0.58\", \"spread\":\"0.01\", \"timestamp\":\"1785130722385\", \"event_type\":\"best_bid_ask\"}","received_at":"2026-07-27T05:38:45.605371Z","schema_version":"clob-market-ws.best_bid_ask.v1","sequence":null,"server_hash":null,"server_timestamp":"1785130722385","session_id":"502006c5cfcd437296561ea750c9ec8b","source":"clob_market_ws"},"received_at":"2026-07-27T05:38:45.605371Z","record_id":"ba2b7a3be357df19adb9aa2bcdc8dd5fc7013637793515d98457ec3a5ee401c7","schema_fingerprint":"8488399f31b0337811b13b266be932db7062827c2470b78bd8e9e99bab51d17d","schema_version":"edge-lab-recorder.raw.v1","sequence":null,"source":"clob_market_ws"}
{"event_at":"2026-07-27T05:38:42.385000Z","event_fingerprint":"56545c5bf33a11fee1595239d40abf61c76977db0779976125d63ac73670e651","payload":{"connection_id":"efc69d3132f1467b8e898a382b23ac0d","event_at":"2026-07-27T05:38:42.385000Z","event_type":"best_bid_ask","frame_hash":"e322eee18c97e4e0be00557134b34c25b348a39e173bf94058dfc4f815b08e7c","frame_index":0,"kind":"data","monotonic_ns":232708846655625,"payload":{"asset_id":"110216635572655435074987471276357323571387854733835379371586402147734167783946","best_ask":"0.43","best_bid":"0.42","event_type":"best_bid_ask","market":"0x3b40066b5cf3871a2f6237c5628bd8092a206aa998558ac5ec13c4483e31e160","spread":"0.01","timestamp":"1785130722385"},"payload_hash":"bdf7b04f750100ddb78e603a37cbd3945effc9f1ddbb757b2af7d99fcc017609","raw_frame":"{\"market\":\"0x3b40066b5cf3871a2f6237c5628bd8092a206aa998558ac5ec13c4483e31e160\", \"asset_id\":\"110216635572655435074987471276357323571387854733835379371586402147734167783946\", \"best_bid\":\"0.42\", \"best_ask\":\"0.43\", \"spread\":\"0.01\", \"timestamp\":\"1785130722385\", \"event_type\":\"best_bid_ask\"}","received_at":"2026-07-27T05:38:45.612095Z","schema_version":"clob-market-ws.best_bid_ask.v1","sequence":null,"server_hash":null,"server_timestamp":"1785130722385","session_id":"502006c5cfcd437296561ea750c9ec8b","source":"clob_market_ws"},"received_at":"2026-07-27T05:38:45.612095Z","record_id":"a922712367ddb49cadd4f49a02ab39fd49ba05ce07db68f8bb7d014a53f4f3db","schema_fingerprint":"8488399f31b0337811b13b266be932db7062827c2470b78bd8e9e99bab51d17d","schema_version":"edge-lab-recorder.raw.v1","sequence":null,"source":"clob_market_ws"}
{"event_at":"2026-07-27T05:38:42.385000Z","event_fingerprint":"1cee691eb824facfbcb21479eddd35595f780023e48efaa28cf55c7229bc1dd9","payload":{"connection_id":"efc69d3132f1467b8e898a382b23ac0d","event_at":"2026-07-27T05:38:42.385000Z","event_type":"price_change","frame_hash":"0c97338cdfd403631dcf03dcdba2f87043d94a72603700b41731316c4f88be16","frame_index":0,"kind":"data","monotonic_ns":232708853810916,"payload":{"event_type":"price_change","market":"0x3b40066b5cf3871a2f6237c5628bd8092a206aa998558ac5ec13c4483e31e160","price_changes":[{"asset_id":"110216635572655435074987471276357323571387854733835379371586402147734167783946","best_ask":"0.43","best_bid":"0.42","hash":"9ce287af155872fe3b117df0fd851fa2cbf306a0","price":"0.42","side":"BUY","size":"11"},{"asset_id":"14766054693214075530629349735273995982307625376442606753688071083149620216746","best_ask":"0.58","best_bid":"0.57","hash":"824301c2998f06f677d1101b412dcb730bcb3ef4","price":"0.58","side":"SELL","size":"11"}],"timestamp":"1785130722385"},"payload_hash":"6f1f905f0e375f6c9a56f5807cfad80eef6a32b5851ea879a90b2299dd869646","raw_frame":"{\"market\":\"0x3b40066b5cf3871a2f6237c5628bd8092a206aa998558ac5ec13c4483e31e160\", \"price_changes\":[{\"asset_id\":\"110216635572655435074987471276357323571387854733835379371586402147734167783946\", \"price\":\"0.42\", \"size\":\"11\", \"side\":\"BUY\", \"hash\":\"9ce287af155872fe3b117df0fd851fa2cbf306a0\", \"best_bid\":\"0.42\", \"best_ask\":\"0.43\"}, {\"asset_id\":\"14766054693214075530629349735273995982307625376442606753688071083149620216746\", \"price\":\"0.58\", \"size\":\"11\", \"side\":\"SELL\", \"hash\":\"824301c2998f06f677d1101b412dcb730bcb3ef4\", \"best_bid\":\"0.57\", \"best_ask\":\"0.58\"}], \"timestamp\":\"1785130722385\", \"event_type\":\"price_change\"}","received_at":"2026-07-27T05:38:45.619253Z","schema_version":"clob-market-ws.price_change.v1","sequence":null,"server_hash":null,"server_timestamp":"1785130722385","session_id":"502006c5cfcd437296561ea750c9ec8b","source":"clob_market_ws"},"received_at":"2026-07-27T05:38:45.619253Z","record_id":"8c6c11dbf2fe80bed957c053b03f0cf9e9fa23b20a6ce219479dc47b5844e296","schema_fingerprint":"4aa3821a28b0b7c2400bc59aba4bcc0a76e971dadd19610d3ad38c768e124dc7","schema_version":"edge-lab-recorder.raw.v1","sequence":null,"source":"clob_market_ws"}
{"event_at":"2026-07-27T05:38:42.389000Z","event_fingerprint":"a485a6623c17b9d0e32c7ea3e185ac7517704ada06f540f846ca357ff53e8daf","payload":{"connection_id":"efc69d3132f1467b8e898a382b23ac0d","event_at":"2026-07-27T05:38:42.389000Z","event_type":"price_change","frame_hash":"7326d2e14e020134a1ab3b3766e4b14972bc72fc7148a29b118b7d889a51227a","frame_index":0,"kind":"data","monotonic_ns":232708858995291,"payload":{"event_type":"price_change","market":"0x3b40066b5cf3871a2f6237c5628bd8092a206aa998558ac5ec13c4483e31e160","price_changes":[{"asset_id":"110216635572655435074987471276357323571387854733835379371586402147734167783946","best_ask":"0.43","best_bid":"0.42","hash":"ee4e9b22f73dfc748591b8c6449fd0e4e85710d1","price":"0.38","side":"BUY","size":"333.62"},{"asset_id":"14766054693214075530629349735273995982307625376442606753688071083149620216746","best_ask":"0.58","best_bid":"0.57","hash":"f3d89ae8a1309b39818c2e567e3debe8fca94f70","price":"0.62","side":"SELL","size":"333.62"}],"timestamp":"1785130722389"},"payload_hash":"66edf26c4a04a2c1e22e5524b2d283958c285aa83f3b584780d50cceddf6215e","raw_frame":"{\"market\":\"0x3b40066b5cf3871a2f6237c5628bd8092a206aa998558ac5ec13c4483e31e160\", \"price_changes\":[{\"asset_id\":\"110216635572655435074987471276357323571387854733835379371586402147734167783946\", \"price\":\"0.38\", \"size\":\"333.62\", \"side\":\"BUY\", \"hash\":\"ee4e9b22f73dfc748591b8c6449fd0e4e85710d1\", \"best_bid\":\"0.42\", \"best_ask\":\"0.43\"}, {\"asset_id\":\"14766054693214075530629349735273995982307625376442606753688071083149620216746\", \"price\":\"0.62\", \"size\":\"333.62\", \"side\":\"SELL\", \"hash\":\"f3d89ae8a1309b39818c2e567e3debe8fca94f70\", \"best_bid\":\"0.57\", \"best_ask\":\"0.58\"}], \"timestamp\":\"1785130722389\", \"event_type\":\"price_change\"}","received_at":"2026-07-27T05:38:45.624437Z","schema_version":"clob-market-ws.price_change.v1","sequence":null,"server_hash":null,"server_timestamp":"1785130722389","session_id":"502006c5cfcd437296561ea750c9ec8b","source":"clob_market_ws"},"received_at":"2026-07-27T05:38:45.624437Z","record_id":"04e9dd094a9c85e969f99acac791e4b5f5e8d0371e06cd074b72135570914b27","schema_fingerprint":"4aa3821a28b0b7c2400bc59aba4bcc0a76e971dadd19610d3ad38c768e124dc7","schema_version":"edge-lab-recorder.raw.v1","sequence":null,"source":"clob_market_ws"}
{"event_at":"2026-07-27T05:38:42.389000Z","event_fingerprint":"9a2b0d177c0be0941530ec4f7eef563dd53fbf483b6cb8a920d8e6ee7c0599ab","payload":{"connection_id":"efc69d3132f1467b8e898a382b23ac0d","event_at":"2026-07-27T05:38:42.389000Z","event_type":"price_change","frame_hash":"8dc7a3493c142ad243987dc4ebb05216042dd7971c7d2cee2a7d955e4dda699f","frame_index":0,"kind":"data","monotonic_ns":232708863199958,"payload":{"event_type":"price_change","market":"0x3b40066b5cf3871a2f6237c5628bd8092a206aa998558ac5ec13c4483e31e160","price_changes":[{"asset_id":"14766054693214075530629349735273995982307625376442606753688071083149620216746","best_ask":"0.58","best_bid":"0.57","hash":"f3d89ae8a1309b39818c2e567e3debe8fca94f70","price":"0.53","side":"BUY","size":"64.4"},{"asset_id":"110216635572655435074987471276357323571387854733835379371586402147734167783946","best_ask":"0.43","best_bid":"0.42","hash":"ee4e9b22f73dfc748591b8c6449fd0e4e85710d1","price":"0.47","side":"SELL","size":"64.4"}],"timestamp":"1785130722389"},"payload_hash":"7b2e93e340e80307b6328df1a6b8771710f0a11cf93c24492573893ae0e7c7ad","raw_frame":"{\"market\":\"0x3b40066b5cf3871a2f6237c5628bd8092a206aa998558ac5ec13c4483e31e160\", \"price_changes\":[{\"asset_id\":\"14766054693214075530629349735273995982307625376442606753688071083149620216746\", \"price\":\"0.53\", \"size\":\"64.4\", \"side\":\"BUY\", \"hash\":\"f3d89ae8a1309b39818c2e567e3debe8fca94f70\", \"best_bid\":\"0.57\", \"best_ask\":\"0.58\"}, {\"asset_id\":\"110216635572655435074987471276357323571387854733835379371586402147734167783946\", \"price\":\"0.47\", \"size\":\"64.4\", \"side\":\"SELL\", \"hash\":\"ee4e9b22f73dfc748591b8c6449fd0e4e85710d1\", \"best_bid\":\"0.42\", \"best_ask\":\"0.43\"}], \"timestamp\":\"1785130722389\", \"event_type\":\"price_change\"}","received_at":"2026-07-27T05:38:45.628649Z","schema_version":"clob-market-ws.price_change.v1","sequence":null,"server_hash":null,"server_timestamp":"1785130722389","session_id":"502006c5cfcd437296561ea750c9ec8b","source":"clob_market_ws"},"received_at":"2026-07-27T05:38:45.628649Z","record_id":"1da85d2674cbfdbb40fb3818f42abdbcb4b4151904f104bba96057dfbe54c563","schema_fingerprint":"4aa3821a28b0b7c2400bc59aba4bcc0a76e971dadd19610d3ad38c768e124dc7","schema_version":"edge-lab-recorder.raw.v1","sequence":null,"source":"clob_market_ws"}
