{"event_at":"2026-07-27T05:32:04.841000Z","event_fingerprint":"b4b13ceb3431f5147cf2551fe4fa3a1cb7153989c1cc75f7efafdaedafdf3339","payload":{"connection_id":"efc69d3132f1467b8e898a382b23ac0d","event_at":"2026-07-27T05:32:04.841000Z","event_type":"price_change","frame_hash":"9dc877fa27cd886d3db49f9bb12b2649e0ae937a4cd2d27690ad4ae1cdd38d85","frame_index":0,"kind":"data","monotonic_ns":232308085355333,"payload":{"event_type":"price_change","market":"0x3b40066b5cf3871a2f6237c5628bd8092a206aa998558ac5ec13c4483e31e160","price_changes":[{"asset_id":"110216635572655435074987471276357323571387854733835379371586402147734167783946","best_ask":"0.55","best_bid":"0.54","hash":"5569c4049092853b8e19258eb5476860ef5816df","price":"0.01","side":"BUY","size":"7848.02"},{"asset_id":"14766054693214075530629349735273995982307625376442606753688071083149620216746","best_ask":"0.46","best_bid":"0.45","hash":"81b495492d15e21c163383c157ce927c7238a5f5","price":"0.99","side":"SELL","size":"7848.02"}],"timestamp":"1785130324841"},"payload_hash":"c5ad7c6d6a632161b6f246f65adaa5c22b0d1210fbe1dc34ed9d702f67f04e0e","raw_frame":"{\"market\":\"0x3b40066b5cf3871a2f6237c5628bd8092a206aa998558ac5ec13c4483e31e160\", \"price_changes\":[{\"asset_id\":\"110216635572655435074987471276357323571387854733835379371586402147734167783946\", \"price\":\"0.01\", \"size\":\"7848.02\", \"side\":\"BUY\", \"hash\":\"5569c4049092853b8e19258eb5476860ef5816df\", \"best_bid\":\"0.54\", \"best_ask\":\"0.55\"}, {\"asset_id\":\"14766054693214075530629349735273995982307625376442606753688071083149620216746\", \"price\":\"0.99\", \"size\":\"7848.02\", \"side\":\"SELL\", \"hash\":\"81b495492d15e21c163383c157ce927c7238a5f5\", \"best_bid\":\"0.45\", \"best_ask\":\"0.46\"}], \"timestamp\":\"1785130324841\", \"event_type\":\"price_change\"}","received_at":"2026-07-27T05:32:04.848013Z","schema_version":"clob-market-ws.price_change.v1","sequence":null,"server_hash":null,"server_timestamp":"1785130324841","session_id":"502006c5cfcd437296561ea750c9ec8b","source":"clob_market_ws"},"received_at":"2026-07-27T05:32:04.848013Z","record_id":"c5be59cb44b5de84f83f6178fe699cbbc76017ff9df96815405e5451907cc06d","schema_fingerprint":"4aa3821a28b0b7c2400bc59aba4bcc0a76e971dadd19610d3ad38c768e124dc7","schema_version":"edge-lab-recorder.raw.v1","sequence":null,"source":"clob_market_ws"}
{"event_at":"2026-07-27T05:32:04.849000Z","event_fingerprint":"b3b7709879679b991f7252205ca323cd31110b652a79cc40be335e36fa4a0833","payload":{"connection_id":"efc69d3132f1467b8e898a382b23ac0d","event_at":"2026-07-27T05:32:04.849000Z","event_type":"price_change","frame_hash":"9e5c4100abd223b65d2f45f57a17c8e45ffcf17a6f93d93f355d6cac8e208936","frame_index":0,"kind":"data","monotonic_ns":232308096144166,"payload":{"event_type":"price_change","market":"0x3b40066b5cf3871a2f6237c5628bd8092a206aa998558ac5ec13c4483e31e160","price_changes":[{"asset_id":"110216635572655435074987471276357323571387854733835379371586402147734167783946","best_ask":"0.55","best_bid":"0.54","hash":"66121321836b83af19b19b8fa785b0aa8c1c9da0","price":"0.54","side":"BUY","size":"404"},{"asset_id":"14766054693214075530629349735273995982307625376442606753688071083149620216746","best_ask":"0.46","best_bid":"0.45","hash":"65f5de51d623b8cb77f32d001ac984b3dc4b2fa4","price":"0.46","side":"SELL","size":"404"}],"timestamp":"1785130324849"},"payload_hash":"bf0973ab716561d9c952e674a9afe442974226c415a378a336d189bf5faf85b7","raw_frame":"{\"market\":\"0x3b40066b5cf3871a2f6237c5628bd8092a206aa998558ac5ec13c4483e31e160\", \"price_changes\":[{\"asset_id\":\"110216635572655435074987471276357323571387854733835379371586402147734167783946\", \"price\":\"0.54\", \"size\":\"404\", \"side\":\"BUY\", \"hash\":\"66121321836b83af19b19b8fa785b0aa8c1c9da0\", \"best_bid\":\"0.54\", \"best_ask\":\"0.55\"}, {\"asset_id\":\"14766054693214075530629349735273995982307625376442606753688071083149620216746\", \"price\":\"0.46\", \"size\":\"404\", \"side\":\"SELL\", \"hash\":\"65f5de51d623b8cb77f32d001ac984b3dc4b2fa4\", \"best_bid\":\"0.45\", \"best_ask\":\"0.46\"}], \"timestamp\":\"1785130324849\", \"event_type\":\"price_change\"}","received_at":"2026-07-27T05:32:04.858801Z","schema_version":"clob-market-ws.price_change.v1","sequence":null,"server_hash":null,"server_timestamp":"1785130324849","session_id":"502006c5cfcd437296561ea750c9ec8b","source":"clob_market_ws"},"received_at":"2026-07-27T05:32:04.858801Z","record_id":"08fed6a60d9036f8b1b72813c91653bc3fb31d4f199a34a6f62844cb1850ee89","schema_fingerprint":"4aa3821a28b0b7c2400bc59aba4bcc0a76e971dadd19610d3ad38c768e124dc7","schema_version":"edge-lab-recorder.raw.v1","sequence":null,"source":"clob_market_ws"}
{"event_at":"2026-07-27T05:32:04.858000Z","event_fingerprint":"fe6d09dbe4e3cab7b177c53aaef5fb9ee31d2526ea39e13c4d87d3eb6a3c9739","payload":{"connection_id":"efc69d3132f1467b8e898a382b23ac0d","event_at":"2026-07-27T05:32:04.858000Z","event_type":"price_change","frame_hash":"60c464e0ba6aa3583be4290ee3d11d516a1645f4a747225181fe60b5e5dce84e","frame_index":0,"kind":"data","monotonic_ns":232308100990875,"payload":{"event_type":"price_change","market":"0x3b40066b5cf3871a2f6237c5628bd8092a206aa998558ac5ec13c4483e31e160","price_changes":[{"asset_id":"110216635572655435074987471276357323571387854733835379371586402147734167783946","best_ask":"0.55","best_bid":"0.54","hash":"31d76c93df743df1d14b786b3c05586c91464dc2","price":"0.02","side":"BUY","size":"723.1"},{"asset_id":"14766054693214075530629349735273995982307625376442606753688071083149620216746","best_ask":"0.46","best_bid":"0.45","hash":"622ad2d84f57001bd00445fcc685ec2713995ddb","price":"0.98","side":"SELL","size":"723.1"}],"timestamp":"1785130324858"},"payload_hash":"8e18ca2a0b150910ebaec9309738acb01da3e8131234f84982300c40020cb89b","raw_frame":"{\"market\":\"0x3b40066b5cf3871a2f6237c5628bd8092a206aa998558ac5ec13c4483e31e160\", \"price_changes\":[{\"asset_id\":\"110216635572655435074987471276357323571387854733835379371586402147734167783946\", \"price\":\"0.02\", \"size\":\"723.1\", \"side\":\"BUY\", \"hash\":\"31d76c93df743df1d14b786b3c05586c91464dc2\", \"best_bid\":\"0.54\", \"best_ask\":\"0.55\"}, {\"asset_id\":\"14766054693214075530629349735273995982307625376442606753688071083149620216746\", \"price\":\"0.98\", \"size\":\"723.1\", \"side\":\"SELL\", \"hash\":\"622ad2d84f57001bd00445fcc685ec2713995ddb\", \"best_bid\":\"0.45\", \"best_ask\":\"0.46\"}], \"timestamp\":\"1785130324858\", \"event_type\":\"price_change\"}","received_at":"2026-07-27T05:32:04.863654Z","schema_version":"clob-market-ws.price_change.v1","sequence":null,"server_hash":null,"server_timestamp":"1785130324858","session_id":"502006c5cfcd437296561ea750c9ec8b","source":"clob_market_ws"},"received_at":"2026-07-27T05:32:04.863654Z","record_id":"f71678eb12b76a382351ca3a8f3e5709aa11b60b413e3cc1bc95e7d117409d1d","schema_fingerprint":"4aa3821a28b0b7c2400bc59aba4bcc0a76e971dadd19610d3ad38c768e124dc7","schema_version":"edge-lab-recorder.raw.v1","sequence":null,"source":"clob_market_ws"}
{"event_at":"2026-07-27T05:32:04.869000Z","event_fingerprint":"df1b21ca84539078e89ac698d13d0d1059dd363fa4c3230958f40d1d9b7feea8","payload":{"connection_id":"efc69d3132f1467b8e898a382b23ac0d","event_at":"2026-07-27T05:32:04.869000Z","event_type":"price_change","frame_hash":"9b98d3cb046002bfd57be1341d844d8ad26761001b251441078f7163220240fc","frame_index":0,"kind":"data","monotonic_ns":232308103928666,"payload":{"event_type":"price_change","market":"0x3b40066b5cf3871a2f6237c5628bd8092a206aa998558ac5ec13c4483e31e160","price_changes":[{"asset_id":"110216635572655435074987471276357323571387854733835379371586402147734167783946","best_ask":"0.55","best_bid":"0.54","hash":"f85c38565aee421f4567ae69800ca460b9ec6c60","price":"0.01","side":"BUY","size":"7843.02"},{"asset_id":"14766054693214075530629349735273995982307625376442606753688071083149620216746","best_ask":"0.46","best_bid":"0.45","hash":"6ae436e37f4fec082881f44d684dc88d631272ba","price":"0.99","side":"SELL","size":"7843.02"}],"timestamp":"1785130324869"},"payload_hash":"8072ff83ede676f5e3004667cd20e391554df8cab5408e16fce3a41be422ba54","raw_frame":"{\"market\":\"0x3b40066b5cf3871a2f6237c5628bd8092a206aa998558ac5ec13c4483e31e160\", \"price_changes\":[{\"asset_id\":\"110216635572655435074987471276357323571387854733835379371586402147734167783946\", \"price\":\"0.01\", \"size\":\"7843.02\", \"side\":\"BUY\", \"hash\":\"f85c38565aee421f4567ae69800ca460b9ec6c60\", \"best_bid\":\"0.54\", \"best_ask\":\"0.55\"}, {\"asset_id\":\"14766054693214075530629349735273995982307625376442606753688071083149620216746\", \"price\":\"0.99\", \"size\":\"7843.02\", \"side\":\"SELL\", \"hash\":\"6ae436e37f4fec082881f44d684dc88d631272ba\", \"best_bid\":\"0.45\", \"best_ask\":\"0.46\"}], \"timestamp\":\"1785130324869\", \"event_type\":\"price_change\"}","received_at":"2026-07-27T05:32:04.866583Z","schema_version":"clob-market-ws.price_change.v1","sequence":null,"server_hash":null,"server_timestamp":"1785130324869","session_id":"502006c5cfcd437296561ea750c9ec8b","source":"clob_market_ws"},"received_at":"2026-07-27T05:32:04.866583Z","record_id":"721cd40ff929fe58acade4efa53df263111fa6524af689d16973ef7c82292780","schema_fingerprint":"4aa3821a28b0b7c2400bc59aba4bcc0a76e971dadd19610d3ad38c768e124dc7","schema_version":"edge-lab-recorder.raw.v1","sequence":null,"source":"clob_market_ws"}
{"event_at":"2026-07-27T05:32:04.893000Z","event_fingerprint":"d94b6070818f9f4b2dcc9072bcc1c161e65efd43becfde7f892120188dff7b50","payload":{"connection_id":"efc69d3132f1467b8e898a382b23ac0d","event_at":"2026-07-27T05:32:04.893000Z","event_type":"price_change","frame_hash":"486d6d0b71e73dde1dfdcd01a75088358652efb4e3243d86982ce650cab5b98e","frame_index":0,"kind":"data","monotonic_ns":232308110629416,"payload":{"event_type":"price_change","market":"0x3b40066b5cf3871a2f6237c5628bd8092a206aa998558ac5ec13c4483e31e160","price_changes":[{"asset_id":"14766054693214075530629349735273995982307625376442606753688071083149620216746","best_ask":"0.46","best_bid":"0.45","hash":"94e49e0e9c099b8e8f160f4a0534a554d753309b","price":"0.42","side":"BUY","size":"118.29"},{"asset_id":"110216635572655435074987471276357323571387854733835379371586402147734167783946","best_ask":"0.55","best_bid":"0.54","hash":"69d832d66eb72de2ec63d49d6b3023305786425a","price":"0.58","side":"SELL","size":"118.29"}],"timestamp":"1785130324893"},"payload_hash":"d7f3143dc42a257177bf312b293d9aafdeba461f721c8befea69193c63636275","raw_frame":"{\"market\":\"0x3b40066b5cf3871a2f6237c5628bd8092a206aa998558ac5ec13c4483e31e160\", \"price_changes\":[{\"asset_id\":\"14766054693214075530629349735273995982307625376442606753688071083149620216746\", \"price\":\"0.42\", \"size\":\"118.29\", \"side\":\"BUY\", \"hash\":\"94e49e0e9c099b8e8f160f4a0534a554d753309b\", \"best_bid\":\"0.45\", \"best_ask\":\"0.46\"}, {\"asset_id\":\"110216635572655435074987471276357323571387854733835379371586402147734167783946\", \"price\":\"0.58\", \"size\":\"118.29\", \"side\":\"SELL\", \"hash\":\"69d832d66eb72de2ec63d49d6b3023305786425a\", \"best_bid\":\"0.54\", \"best_ask\":\"0.55\"}], \"timestamp\":\"1785130324893\", \"event_type\":\"price_change\"}","received_at":"2026-07-27T05:32:04.873287Z","schema_version":"clob-market-ws.price_change.v1","sequence":null,"server_hash":null,"server_timestamp":"1785130324893","session_id":"502006c5cfcd437296561ea750c9ec8b","source":"clob_market_ws"},"received_at":"2026-07-27T05:32:04.873287Z","record_id":"74ed5db266e0703afb480e702f15fa955bf1f32b6f7cc4605f0edd4a0c43dee0","schema_fingerprint":"4aa3821a28b0b7c2400bc59aba4bcc0a76e971dadd19610d3ad38c768e124dc7","schema_version":"edge-lab-recorder.raw.v1","sequence":null,"source":"clob_market_ws"}
{"event_at":"2026-07-27T05:32:04.894000Z","event_fingerprint":"3e422bb51547ca2dcb2af69c4b5f116d00486eb4cf1c3aef6ca003eac45f1cb0","payload":{"connection_id":"efc69d3132f1467b8e898a382b23ac0d","event_at":"2026-07-27T05:32:04.894000Z","event_type":"price_change","frame_hash":"9a388ab17527cbe6bcd33528e4a4b502d8a100a9c93cca81522098abb1f6e734","frame_index":0,"kind":"data","monotonic_ns":232308114054000,"payload":{"event_type":"price_change","market":"0x3b40066b5cf3871a2f6237c5628bd8092a206aa998558ac5ec13c4483e31e160","price_changes":[{"asset_id":"110216635572655435074987471276357323571387854733835379371586402147734167783946","best_ask":"0.55","best_bid":"0.54","hash":"8873c1eff4acde8c6d7827b385470a396e777a78","price":"0.54","side":"BUY","size":"134"},{"asset_id":"14766054693214075530629349735273995982307625376442606753688071083149620216746","best_ask":"0.46","best_bid":"0.45","hash":"491ba5f813ba3c28baa8c5c21dad467868963fb1","price":"0.46","side":"SELL","size":"134"}],"timestamp":"1785130324894"},"payload_hash":"80344bf185b54e570c4c4075e55d9b7fb66e20c5c1bb880daf07e3f185d799c4","raw_frame":"{\"market\":\"0x3b40066b5cf3871a2f6237c5628bd8092a206aa998558ac5ec13c4483e31e160\", \"price_changes\":[{\"asset_id\":\"110216635572655435074987471276357323571387854733835379371586402147734167783946\", \"price\":\"0.54\", \"size\":\"134\", \"side\":\"BUY\", \"hash\":\"8873c1eff4acde8c6d7827b385470a396e777a78\", \"best_bid\":\"0.54\", \"best_ask\":\"0.55\"}, {\"asset_id\":\"14766054693214075530629349735273995982307625376442606753688071083149620216746\", \"price\":\"0.46\", \"size\":\"134\", \"side\":\"SELL\", \"hash\":\"491ba5f813ba3c28baa8c5c21dad467868963fb1\", \"best_bid\":\"0.45\", \"best_ask\":\"0.46\"}], \"timestamp\":\"1785130324894\", \"event_type\":\"price_change\"}","received_at":"2026-07-27T05:32:04.876711Z","schema_version":"clob-market-ws.price_change.v1","sequence":null,"server_hash":null,"server_timestamp":"1785130324894","session_id":"502006c5cfcd437296561ea750c9ec8b","source":"clob_market_ws"},"received_at":"2026-07-27T05:32:04.876711Z","record_id":"8121c50dafbe9c3babf7c6b880aa044fbec5c0288e89829daf3b9280e305b78d","schema_fingerprint":"4aa3821a28b0b7c2400bc59aba4bcc0a76e971dadd19610d3ad38c768e124dc7","schema_version":"edge-lab-recorder.raw.v1","sequence":null,"source":"clob_market_ws"}
{"event_at":"2026-07-27T05:32:04.895000Z","event_fingerprint":"46e2ded5df66b487475f153fad323a0dafe664e664e303440d4c861cc87b9373","payload":{"connection_id":"efc69d3132f1467b8e898a382b23ac0d","event_at":"2026-07-27T05:32:04.895000Z","event_type":"price_change","frame_hash":"ef9be6551bb026d22086fcb25f261a59ded1a3d93c7faaf780ba22f6c128f1cb","frame_index":0,"kind":"data","monotonic_ns":232308119095791,"payload":{"event_type":"price_change","market":"0x3b40066b5cf3871a2f6237c5628bd8092a206aa998558ac5ec13c4483e31e160","price_changes":[{"asset_id":"110216635572655435074987471276357323571387854733835379371586402147734167783946","best_ask":"0.55","best_bid":"0.54","hash":"8b6f22024abf436bb421838431661ced52ec713d","price":"0.53","side":"BUY","size":"33"},{"asset_id":"14766054693214075530629349735273995982307625376442606753688071083149620216746","best_ask":"0.46","best_bid":"0.45","hash":"9a4e376cc2cda255b16eb78d516fee526893a9d3","price":"0.47","side":"SELL","size":"33"}],"timestamp":"1785130324895"},"payload_hash":"1835eef54dbaf37c4a0a4e5726250416df4c04fa47126238ca1a06c6627eb090","raw_frame":"{\"market\":\"0x3b40066b5cf3871a2f6237c5628bd8092a206aa998558ac5ec13c4483e31e160\", \"price_changes\":[{\"asset_id\":\"110216635572655435074987471276357323571387854733835379371586402147734167783946\", \"price\":\"0.53\", \"size\":\"33\", \"side\":\"BUY\", \"hash\":\"8b6f22024abf436bb421838431661ced52ec713d\", \"best_bid\":\"0.54\", \"best_ask\":\"0.55\"}, {\"asset_id\":\"14766054693214075530629349735273995982307625376442606753688071083149620216746\", \"price\":\"0.47\", \"size\":\"33\", \"side\":\"SELL\", \"hash\":\"9a4e376cc2cda255b16eb78d516fee526893a9d3\", \"best_bid\":\"0.45\", \"best_ask\":\"0.46\"}], \"timestamp\":\"1785130324895\", \"event_type\":\"price_change\"}","received_at":"2026-07-27T05:32:04.881753Z","schema_version":"clob-market-ws.price_change.v1","sequence":null,"server_hash":null,"server_timestamp":"1785130324895","session_id":"502006c5cfcd437296561ea750c9ec8b","source":"clob_market_ws"},"received_at":"2026-07-27T05:32:04.881753Z","record_id":"a3fccfaea5961c92f94c136fec4a71ba6dda8eba21e1478fefa2413745b2dd07","schema_fingerprint":"4aa3821a28b0b7c2400bc59aba4bcc0a76e971dadd19610d3ad38c768e124dc7","schema_version":"edge-lab-recorder.raw.v1","sequence":null,"source":"clob_market_ws"}
{"event_at":"2026-07-27T05:32:04.901000Z","event_fingerprint":"ce950e1784161cb0ef02fb654b71d86c6c0ab97dd835cdfe4672e664d2561721","payload":{"connection_id":"efc69d3132f1467b8e898a382b23ac0d","event_at":"2026-07-27T05:32:04.901000Z","event_type":"price_change","frame_hash":"b3655a12a9b9e16124983876d5bf848f8b59662ad0d5225594f9d048d96bf277","frame_index":0,"kind":"data","monotonic_ns":232308124165333,"payload":{"event_type":"price_change","market":"0x3b40066b5cf3871a2f6237c5628bd8092a206aa998558ac5ec13c4483e31e160","price_changes":[{"asset_id":"14766054693214075530629349735273995982307625376442606753688071083149620216746","best_ask":"0.46","best_bid":"0.45","hash":"5be2d9fe38ee2be0afbf49ef0e3a30959c2837ba","price":"0.42","side":"BUY","size":"22.29"},{"asset_id":"110216635572655435074987471276357323571387854733835379371586402147734167783946","best_ask":"0.55","best_bid":"0.54","hash":"771f89764c10ab51b9039557c7908191e569ea19","price":"0.58","side":"SELL","size":"22.29"}],"timestamp":"1785130324901"},"payload_hash":"19f341006c1821e9107732c62048128f8f5ee1dfe0bbd2c510b32e95259b329c","raw_frame":"{\"market\":\"0x3b40066b5cf3871a2f6237c5628bd8092a206aa998558ac5ec13c4483e31e160\", \"price_changes\":[{\"asset_id\":\"14766054693214075530629349735273995982307625376442606753688071083149620216746\", \"price\":\"0.42\", \"size\":\"22.29\", \"side\":\"BUY\", \"hash\":\"5be2d9fe38ee2be0afbf49ef0e3a30959c2837ba\", \"best_bid\":\"0.45\", \"best_ask\":\"0.46\"}, {\"asset_id\":\"110216635572655435074987471276357323571387854733835379371586402147734167783946\", \"price\":\"0.58\", \"size\":\"22.29\", \"side\":\"SELL\", \"hash\":\"771f89764c10ab51b9039557c7908191e569ea19\", \"best_bid\":\"0.54\", \"best_ask\":\"0.55\"}], \"timestamp\":\"1785130324901\", \"event_type\":\"price_change\"}","received_at":"2026-07-27T05:32:04.886824Z","schema_version":"clob-market-ws.price_change.v1","sequence":null,"server_hash":null,"server_timestamp":"1785130324901","session_id":"502006c5cfcd437296561ea750c9ec8b","source":"clob_market_ws"},"received_at":"2026-07-27T05:32:04.886824Z","record_id":"ee5381c384949a515d931417f5c41efe358e125e20ac50627f472eb7c734d18b","schema_fingerprint":"4aa3821a28b0b7c2400bc59aba4bcc0a76e971dadd19610d3ad38c768e124dc7","schema_version":"edge-lab-recorder.raw.v1","sequence":null,"source":"clob_market_ws"}
{"event_at":"2026-07-27T05:32:04.952000Z","event_fingerprint":"1ebb7978d2f39e4ea59d4e7e8fffba4b38e46ffc0abc173b7f0f32fa39c4d1ea","payload":{"connection_id":"efc69d3132f1467b8e898a382b23ac0d","event_at":"2026-07-27T05:32:04.952000Z","event_type":"price_change","frame_hash":"0f781e7f1369aa42859efd80164e732582338cfe33a6997bdc2cf65de8083d5a","frame_index":0,"kind":"data","monotonic_ns":232308151769833,"payload":{"event_type":"price_change","market":"0x3b40066b5cf3871a2f6237c5628bd8092a206aa998558ac5ec13c4483e31e160","price_changes":[{"asset_id":"110216635572655435074987471276357323571387854733835379371586402147734167783946","best_ask":"0.55","best_bid":"0.54","hash":"088f23a48098466e79b980930bada08ffd7e21bf","price":"0.49","side":"BUY","size":"104.6"},{"asset_id":"14766054693214075530629349735273995982307625376442606753688071083149620216746","best_ask":"0.46","best_bid":"0.45","hash":"7717759cc01d0b1410c6a88563da90cf670b35d1","price":"0.51","side":"SELL","size":"104.6"}],"timestamp":"1785130324952"},"payload_hash":"3302ec876a0e6af7e0275b7f7a8f1166acd46c7f13320e98854152c415aed963","raw_frame":"{\"market\":\"0x3b40066b5cf3871a2f6237c5628bd8092a206aa998558ac5ec13c4483e31e160\", \"price_changes\":[{\"asset_id\":\"110216635572655435074987471276357323571387854733835379371586402147734167783946\", \"price\":\"0.49\", \"size\":\"104.6\", \"side\":\"BUY\", \"hash\":\"088f23a48098466e79b980930bada08ffd7e21bf\", \"best_bid\":\"0.54\", \"best_ask\":\"0.55\"}, {\"asset_id\":\"14766054693214075530629349735273995982307625376442606753688071083149620216746\", \"price\":\"0.51\", \"size\":\"104.6\", \"side\":\"SELL\", \"hash\":\"7717759cc01d0b1410c6a88563da90cf670b35d1\", \"best_bid\":\"0.45\", \"best_ask\":\"0.46\"}], \"timestamp\":\"1785130324952\", \"event_type\":\"price_change\"}","received_at":"2026-07-27T05:32:04.914427Z","schema_version":"clob-market-ws.price_change.v1","sequence":null,"server_hash":null,"server_timestamp":"1785130324952","session_id":"502006c5cfcd437296561ea750c9ec8b","source":"clob_market_ws"},"received_at":"2026-07-27T05:32:04.914427Z","record_id":"75ff2532f919215961cc29d217f23c6002f6e2d697156d269a7706ed8d69d9f9","schema_fingerprint":"4aa3821a28b0b7c2400bc59aba4bcc0a76e971dadd19610d3ad38c768e124dc7","schema_version":"edge-lab-recorder.raw.v1","sequence":null,"source":"clob_market_ws"}
{"event_at":"2026-07-27T05:32:04.952000Z","event_fingerprint":"e5a2eb9885b52edd72ef7d96b4f4166b7190fd8b4912825377743b92f04b3ff8","payload":{"connection_id":"efc69d3132f1467b8e898a382b23ac0d","event_at":"2026-07-27T05:32:04.952000Z","event_type":"price_change","frame_hash":"03dd1035078c711c111643980e8bcdbaac17ac7559bc6a55e7342d8220e9e921","frame_index":0,"kind":"data","monotonic_ns":232308156994708,"payload":{"event_type":"price_change","market":"0x3b40066b5cf3871a2f6237c5628bd8092a206aa998558ac5ec13c4483e31e160","price_changes":[{"asset_id":"110216635572655435074987471276357323571387854733835379371586402147734167783946","best_ask":"0.55","best_bid":"0.54","hash":"088f23a48098466e79b980930bada08ffd7e21bf","price":"0.51","side":"BUY","size":"74.4"},{"asset_id":"14766054693214075530629349735273995982307625376442606753688071083149620216746","best_ask":"0.46","best_bid":"0.45","hash":"7717759cc01d0b1410c6a88563da90cf670b35d1","price":"0.49","side":"SELL","size":"74.4"}],"timestamp":"1785130324952"},"payload_hash":"9b39167ecf4143ffdb7d4446bbde9968f7742e2b8fce42bed579bd6a1893671b","raw_frame":"{\"market\":\"0x3b40066b5cf3871a2f6237c5628bd8092a206aa998558ac5ec13c4483e31e160\", \"price_changes\":[{\"asset_id\":\"110216635572655435074987471276357323571387854733835379371586402147734167783946\", \"price\":\"0.51\", \"size\":\"74.4\", \"side\":\"BUY\", \"hash\":\"088f23a48098466e79b980930bada08ffd7e21bf\", \"best_bid\":\"0.54\", \"best_ask\":\"0.55\"}, {\"asset_id\":\"14766054693214075530629349735273995982307625376442606753688071083149620216746\", \"price\":\"0.49\", \"size\":\"74.4\", \"side\":\"SELL\", \"hash\":\"7717759cc01d0b1410c6a88563da90cf670b35d1\", \"best_bid\":\"0.45\", \"best_ask\":\"0.46\"}], \"timestamp\":\"1785130324952\", \"event_type\":\"price_change\"}","received_at":"2026-07-27T05:32:04.919653Z","schema_version":"clob-market-ws.price_change.v1","sequence":null,"server_hash":null,"server_timestamp":"1785130324952","session_id":"502006c5cfcd437296561ea750c9ec8b","source":"clob_market_ws"},"received_at":"2026-07-27T05:32:04.919653Z","record_id":"a416cbac12a93328c426be1c0c921d98b19385d2767ddc858be6d44d65a71760","schema_fingerprint":"4aa3821a28b0b7c2400bc59aba4bcc0a76e971dadd19610d3ad38c768e124dc7","schema_version":"edge-lab-recorder.raw.v1","sequence":null,"source":"clob_market_ws"}
