{"event_at":"2026-07-27T05:31:12.477000Z","event_fingerprint":"42fca25c6886f2395dc3956ce32dbea0d87989c0ed4bb90889b84dc6f4e2ec6d","payload":{"connection_id":"efc69d3132f1467b8e898a382b23ac0d","event_at":"2026-07-27T05:31:12.477000Z","event_type":"price_change","frame_hash":"23234f2a26a2f879b287bdbfeb60daf46caf8b2d58604a825c7b26609c25b250","frame_index":0,"kind":"data","monotonic_ns":232255716363958,"payload":{"event_type":"price_change","market":"0x3b40066b5cf3871a2f6237c5628bd8092a206aa998558ac5ec13c4483e31e160","price_changes":[{"asset_id":"14766054693214075530629349735273995982307625376442606753688071083149620216746","best_ask":"0.51","best_bid":"0.5","hash":"31d8373fc83d2f615e15dd0c97dcb4232f5e8cac","price":"0.52","side":"SELL","size":"156.6"},{"asset_id":"110216635572655435074987471276357323571387854733835379371586402147734167783946","best_ask":"0.5","best_bid":"0.49","hash":"be43b2a0abf4591c8df6284f89a9f4872a914721","price":"0.48","side":"BUY","size":"156.6"}],"timestamp":"1785130272477"},"payload_hash":"482ba9b420cb6d8f74e0999ad7e71bb33cadcd5d2aab9daaf808718f7a6e664e","raw_frame":"{\"market\":\"0x3b40066b5cf3871a2f6237c5628bd8092a206aa998558ac5ec13c4483e31e160\", \"price_changes\":[{\"asset_id\":\"14766054693214075530629349735273995982307625376442606753688071083149620216746\", \"price\":\"0.52\", \"size\":\"156.6\", \"side\":\"SELL\", \"hash\":\"31d8373fc83d2f615e15dd0c97dcb4232f5e8cac\", \"best_bid\":\"0.5\", \"best_ask\":\"0.51\"}, {\"asset_id\":\"110216635572655435074987471276357323571387854733835379371586402147734167783946\", \"price\":\"0.48\", \"size\":\"156.6\", \"side\":\"BUY\", \"hash\":\"be43b2a0abf4591c8df6284f89a9f4872a914721\", \"best_bid\":\"0.49\", \"best_ask\":\"0.5\"}], \"timestamp\":\"1785130272477\", \"event_type\":\"price_change\"}","received_at":"2026-07-27T05:31:12.478664Z","schema_version":"clob-market-ws.price_change.v1","sequence":null,"server_hash":null,"server_timestamp":"1785130272477","session_id":"502006c5cfcd437296561ea750c9ec8b","source":"clob_market_ws"},"received_at":"2026-07-27T05:31:12.478664Z","record_id":"20ba4663c0e1560a539ecdb48535d40db9ea4c7c578017c4748e4a3de6aaecb7","schema_fingerprint":"4aa3821a28b0b7c2400bc59aba4bcc0a76e971dadd19610d3ad38c768e124dc7","schema_version":"edge-lab-recorder.raw.v1","sequence":null,"source":"clob_market_ws"}
{"event_at":"2026-07-27T05:31:12.506000Z","event_fingerprint":"e677ed71016c95d0816404de54c370b9186a62c566b4d9aa6d795ee0f4d4d421","payload":{"connection_id":"efc69d3132f1467b8e898a382b23ac0d","event_at":"2026-07-27T05:31:12.506000Z","event_type":"price_change","frame_hash":"3b484d06c6fa5feac93d575111d3dc8fbb3c4ff9712796c98c090c4cc2e6f0d2","frame_index":0,"kind":"data","monotonic_ns":232255728285666,"payload":{"event_type":"price_change","market":"0x3b40066b5cf3871a2f6237c5628bd8092a206aa998558ac5ec13c4483e31e160","price_changes":[{"asset_id":"14766054693214075530629349735273995982307625376442606753688071083149620216746","best_ask":"0.51","best_bid":"0.5","hash":"7af938f816928c282f0f880a1e2b2f59c6921bb2","price":"0.5","side":"BUY","size":"400.4"},{"asset_id":"110216635572655435074987471276357323571387854733835379371586402147734167783946","best_ask":"0.5","best_bid":"0.49","hash":"2e3e4b7d78350f181efe1b3195a9e9e7c3ec6560","price":"0.5","side":"SELL","size":"400.4"}],"timestamp":"1785130272506"},"payload_hash":"2cc1a6bac97942b2cb43fc099aa286aea536f533393b8b9d9f4191620f4d74b0","raw_frame":"{\"market\":\"0x3b40066b5cf3871a2f6237c5628bd8092a206aa998558ac5ec13c4483e31e160\", \"price_changes\":[{\"asset_id\":\"14766054693214075530629349735273995982307625376442606753688071083149620216746\", \"price\":\"0.5\", \"size\":\"400.4\", \"side\":\"BUY\", \"hash\":\"7af938f816928c282f0f880a1e2b2f59c6921bb2\", \"best_bid\":\"0.5\", \"best_ask\":\"0.51\"}, {\"asset_id\":\"110216635572655435074987471276357323571387854733835379371586402147734167783946\", \"price\":\"0.5\", \"size\":\"400.4\", \"side\":\"SELL\", \"hash\":\"2e3e4b7d78350f181efe1b3195a9e9e7c3ec6560\", \"best_bid\":\"0.49\", \"best_ask\":\"0.5\"}], \"timestamp\":\"1785130272506\", \"event_type\":\"price_change\"}","received_at":"2026-07-27T05:31:12.490580Z","schema_version":"clob-market-ws.price_change.v1","sequence":null,"server_hash":null,"server_timestamp":"1785130272506","session_id":"502006c5cfcd437296561ea750c9ec8b","source":"clob_market_ws"},"received_at":"2026-07-27T05:31:12.490580Z","record_id":"dde0078eb9c480c227e89df1f5abd0dbd6de22ade322f7492437f46182b21eee","schema_fingerprint":"4aa3821a28b0b7c2400bc59aba4bcc0a76e971dadd19610d3ad38c768e124dc7","schema_version":"edge-lab-recorder.raw.v1","sequence":null,"source":"clob_market_ws"}
{"event_at":"2026-07-27T05:31:12.563000Z","event_fingerprint":"9251852637775aad9d0404f94f25a86da81faab192d8116011b6b0f20a65aee6","payload":{"connection_id":"efc69d3132f1467b8e898a382b23ac0d","event_at":"2026-07-27T05:31:12.563000Z","event_type":"price_change","frame_hash":"47ab733425fca643c1ce5c209be761f24cccec4f3bfb9cbe9b8bbbd9379dfc14","frame_index":0,"kind":"data","monotonic_ns":232255762536666,"payload":{"event_type":"price_change","market":"0x3b40066b5cf3871a2f6237c5628bd8092a206aa998558ac5ec13c4483e31e160","price_changes":[{"asset_id":"14766054693214075530629349735273995982307625376442606753688071083149620216746","best_ask":"0.51","best_bid":"0.5","hash":"f025ceee2c08bacee6f8a9b3401329639b2c1e94","price":"0.52","side":"SELL","size":"148.6"},{"asset_id":"110216635572655435074987471276357323571387854733835379371586402147734167783946","best_ask":"0.5","best_bid":"0.49","hash":"887b83ba3a6d1ad6d3571738ceb862f8814d3846","price":"0.48","side":"BUY","size":"148.6"}],"timestamp":"1785130272563"},"payload_hash":"d1da9a7a92dd47f031778aa2c23d4d1fca1986d5d0c419b4068960336d016a70","raw_frame":"{\"market\":\"0x3b40066b5cf3871a2f6237c5628bd8092a206aa998558ac5ec13c4483e31e160\", \"price_changes\":[{\"asset_id\":\"14766054693214075530629349735273995982307625376442606753688071083149620216746\", \"price\":\"0.52\", \"size\":\"148.6\", \"side\":\"SELL\", \"hash\":\"f025ceee2c08bacee6f8a9b3401329639b2c1e94\", \"best_bid\":\"0.5\", \"best_ask\":\"0.51\"}, {\"asset_id\":\"110216635572655435074987471276357323571387854733835379371586402147734167783946\", \"price\":\"0.48\", \"size\":\"148.6\", \"side\":\"BUY\", \"hash\":\"887b83ba3a6d1ad6d3571738ceb862f8814d3846\", \"best_bid\":\"0.49\", \"best_ask\":\"0.5\"}], \"timestamp\":\"1785130272563\", \"event_type\":\"price_change\"}","received_at":"2026-07-27T05:31:12.524837Z","schema_version":"clob-market-ws.price_change.v1","sequence":null,"server_hash":null,"server_timestamp":"1785130272563","session_id":"502006c5cfcd437296561ea750c9ec8b","source":"clob_market_ws"},"received_at":"2026-07-27T05:31:12.524837Z","record_id":"7d93e8fb54c8eb2585aa934e5337dad3bdb71644c11bc738a39e85471ba16f9a","schema_fingerprint":"4aa3821a28b0b7c2400bc59aba4bcc0a76e971dadd19610d3ad38c768e124dc7","schema_version":"edge-lab-recorder.raw.v1","sequence":null,"source":"clob_market_ws"}
{"event_at":"2026-07-27T05:31:12.563000Z","event_fingerprint":"8d3be3684e31c3709668c486e6a27b452eaa648c799587eb1612f912a8d223c8","payload":{"connection_id":"efc69d3132f1467b8e898a382b23ac0d","event_at":"2026-07-27T05:31:12.563000Z","event_type":"price_change","frame_hash":"6152607e80810533d572741fcc1d596f3efed060562945093694f4b636b6c3ac","frame_index":0,"kind":"data","monotonic_ns":232255765523458,"payload":{"event_type":"price_change","market":"0x3b40066b5cf3871a2f6237c5628bd8092a206aa998558ac5ec13c4483e31e160","price_changes":[{"asset_id":"14766054693214075530629349735273995982307625376442606753688071083149620216746","best_ask":"0.51","best_bid":"0.5","hash":"c2fb368c63a47a0cb9bc521d938708533feece9c","price":"0.01","side":"BUY","size":"7878.02"},{"asset_id":"110216635572655435074987471276357323571387854733835379371586402147734167783946","best_ask":"0.5","best_bid":"0.49","hash":"42b6e02e2fda3e7ef661d11c332294fce869d686","price":"0.99","side":"SELL","size":"7878.02"}],"timestamp":"1785130272563"},"payload_hash":"a7f51a3998d63ae62bce7a4254eba25d58349e668dd653955c2db85ece25b85f","raw_frame":"{\"market\":\"0x3b40066b5cf3871a2f6237c5628bd8092a206aa998558ac5ec13c4483e31e160\", \"price_changes\":[{\"asset_id\":\"14766054693214075530629349735273995982307625376442606753688071083149620216746\", \"price\":\"0.01\", \"size\":\"7878.02\", \"side\":\"BUY\", \"hash\":\"c2fb368c63a47a0cb9bc521d938708533feece9c\", \"best_bid\":\"0.5\", \"best_ask\":\"0.51\"}, {\"asset_id\":\"110216635572655435074987471276357323571387854733835379371586402147734167783946\", \"price\":\"0.99\", \"size\":\"7878.02\", \"side\":\"SELL\", \"hash\":\"42b6e02e2fda3e7ef661d11c332294fce869d686\", \"best_bid\":\"0.49\", \"best_ask\":\"0.5\"}], \"timestamp\":\"1785130272563\", \"event_type\":\"price_change\"}","received_at":"2026-07-27T05:31:12.527823Z","schema_version":"clob-market-ws.price_change.v1","sequence":null,"server_hash":null,"server_timestamp":"1785130272563","session_id":"502006c5cfcd437296561ea750c9ec8b","source":"clob_market_ws"},"received_at":"2026-07-27T05:31:12.527823Z","record_id":"03248e2f6245fe9510d3e0b6ea7c3bd9b4fbe954d6333c0ecbc6bec79d968be5","schema_fingerprint":"4aa3821a28b0b7c2400bc59aba4bcc0a76e971dadd19610d3ad38c768e124dc7","schema_version":"edge-lab-recorder.raw.v1","sequence":null,"source":"clob_market_ws"}
{"event_at":"2026-07-27T05:31:12.577000Z","event_fingerprint":"bf7941dd6b5fc86d2653a7465f501d3415bfe71eeb841c8149cc60857f9f41e4","payload":{"connection_id":"efc69d3132f1467b8e898a382b23ac0d","event_at":"2026-07-27T05:31:12.577000Z","event_type":"price_change","frame_hash":"c02f3c6fb720deb771edc271ab72d636be1972bad346efabcdb0976f2acd4158","frame_index":0,"kind":"data","monotonic_ns":232255775742083,"payload":{"event_type":"price_change","market":"0x3b40066b5cf3871a2f6237c5628bd8092a206aa998558ac5ec13c4483e31e160","price_changes":[{"asset_id":"110216635572655435074987471276357323571387854733835379371586402147734167783946","best_ask":"0.5","best_bid":"0.49","hash":"33ce61f93f316ea47af15e968ea9afe0c0a299be","price":"0.48","side":"BUY","size":"156.6"},{"asset_id":"14766054693214075530629349735273995982307625376442606753688071083149620216746","best_ask":"0.51","best_bid":"0.5","hash":"b0ee79a3dea9de6dac8682ba71877347b4b2acba","price":"0.52","side":"SELL","size":"156.6"}],"timestamp":"1785130272577"},"payload_hash":"f96e7eba61560d4a4c2fa4345d68d4f98ce1da39bec2f518cdb576b1df8bc0b8","raw_frame":"{\"market\":\"0x3b40066b5cf3871a2f6237c5628bd8092a206aa998558ac5ec13c4483e31e160\", \"price_changes\":[{\"asset_id\":\"110216635572655435074987471276357323571387854733835379371586402147734167783946\", \"price\":\"0.48\", \"size\":\"156.6\", \"side\":\"BUY\", \"hash\":\"33ce61f93f316ea47af15e968ea9afe0c0a299be\", \"best_bid\":\"0.49\", \"best_ask\":\"0.5\"}, {\"asset_id\":\"14766054693214075530629349735273995982307625376442606753688071083149620216746\", \"price\":\"0.52\", \"size\":\"156.6\", \"side\":\"SELL\", \"hash\":\"b0ee79a3dea9de6dac8682ba71877347b4b2acba\", \"best_bid\":\"0.5\", \"best_ask\":\"0.51\"}], \"timestamp\":\"1785130272577\", \"event_type\":\"price_change\"}","received_at":"2026-07-27T05:31:12.538037Z","schema_version":"clob-market-ws.price_change.v1","sequence":null,"server_hash":null,"server_timestamp":"1785130272577","session_id":"502006c5cfcd437296561ea750c9ec8b","source":"clob_market_ws"},"received_at":"2026-07-27T05:31:12.538037Z","record_id":"ca40a2111081565a185f1c007bb85139d803b470835c3e586cc4e7c424669289","schema_fingerprint":"4aa3821a28b0b7c2400bc59aba4bcc0a76e971dadd19610d3ad38c768e124dc7","schema_version":"edge-lab-recorder.raw.v1","sequence":null,"source":"clob_market_ws"}
{"event_at":"2026-07-27T05:31:12.651000Z","event_fingerprint":"3b94d6b88c007921740f0686271e5184ad3aba9a29a8e188829e096b98d27db6","payload":{"connection_id":"efc69d3132f1467b8e898a382b23ac0d","event_at":"2026-07-27T05:31:12.651000Z","event_type":"price_change","frame_hash":"4d214c394866ad177be467701ac29a78a8b5f42d280a3595f4a13bade45dc611","frame_index":0,"kind":"data","monotonic_ns":232255856972333,"payload":{"event_type":"price_change","market":"0x3b40066b5cf3871a2f6237c5628bd8092a206aa998558ac5ec13c4483e31e160","price_changes":[{"asset_id":"14766054693214075530629349735273995982307625376442606753688071083149620216746","best_ask":"0.51","best_bid":"0.5","hash":"6c13c70f2efb534b619fb4b0be0127591c7bc6c8","price":"0.01","side":"BUY","size":"7883.02"},{"asset_id":"110216635572655435074987471276357323571387854733835379371586402147734167783946","best_ask":"0.5","best_bid":"0.49","hash":"04ec4f23d9a1d9dcb771628d388db68456e9aa07","price":"0.99","side":"SELL","size":"7883.02"}],"timestamp":"1785130272651"},"payload_hash":"ee36073b35badd1c2bb980ab85401cc8b93ac08f7f3a257611d399722f4444d4","raw_frame":"{\"market\":\"0x3b40066b5cf3871a2f6237c5628bd8092a206aa998558ac5ec13c4483e31e160\", \"price_changes\":[{\"asset_id\":\"14766054693214075530629349735273995982307625376442606753688071083149620216746\", \"price\":\"0.01\", \"size\":\"7883.02\", \"side\":\"BUY\", \"hash\":\"6c13c70f2efb534b619fb4b0be0127591c7bc6c8\", \"best_bid\":\"0.5\", \"best_ask\":\"0.51\"}, {\"asset_id\":\"110216635572655435074987471276357323571387854733835379371586402147734167783946\", \"price\":\"0.99\", \"size\":\"7883.02\", \"side\":\"SELL\", \"hash\":\"04ec4f23d9a1d9dcb771628d388db68456e9aa07\", \"best_bid\":\"0.49\", \"best_ask\":\"0.5\"}], \"timestamp\":\"1785130272651\", \"event_type\":\"price_change\"}","received_at":"2026-07-27T05:31:12.619266Z","schema_version":"clob-market-ws.price_change.v1","sequence":null,"server_hash":null,"server_timestamp":"1785130272651","session_id":"502006c5cfcd437296561ea750c9ec8b","source":"clob_market_ws"},"received_at":"2026-07-27T05:31:12.619266Z","record_id":"8d7c3251d75f75d18650829013cb0267ad4f9407491b8876ba3e83cae7b942c3","schema_fingerprint":"4aa3821a28b0b7c2400bc59aba4bcc0a76e971dadd19610d3ad38c768e124dc7","schema_version":"edge-lab-recorder.raw.v1","sequence":null,"source":"clob_market_ws"}
{"event_at":"2026-07-27T05:31:12.661000Z","event_fingerprint":"2e7656dc6cd45e57e0c3103d63ef791049f125edce8467b8788513981681d1a3","payload":{"connection_id":"efc69d3132f1467b8e898a382b23ac0d","event_at":"2026-07-27T05:31:12.661000Z","event_type":"price_change","frame_hash":"cae98a9852981e42e88dd46791e3390006f394f89ee331d33545d0d8eba1d28b","frame_index":0,"kind":"data","monotonic_ns":232255866700000,"payload":{"event_type":"price_change","market":"0x3b40066b5cf3871a2f6237c5628bd8092a206aa998558ac5ec13c4483e31e160","price_changes":[{"asset_id":"14766054693214075530629349735273995982307625376442606753688071083149620216746","best_ask":"0.51","best_bid":"0.5","hash":"cc3319dceba76e3f39f50c2fcbcad01f556e50af","price":"0.01","side":"BUY","size":"7878.02"},{"asset_id":"110216635572655435074987471276357323571387854733835379371586402147734167783946","best_ask":"0.5","best_bid":"0.49","hash":"7c3dc6683238c7f4adc0beb654f3dff6ef3e1a89","price":"0.99","side":"SELL","size":"7878.02"}],"timestamp":"1785130272661"},"payload_hash":"f737307b9295c338dd7727078bd8b1c1b7c516e40171164ef2c97339db040b00","raw_frame":"{\"market\":\"0x3b40066b5cf3871a2f6237c5628bd8092a206aa998558ac5ec13c4483e31e160\", \"price_changes\":[{\"asset_id\":\"14766054693214075530629349735273995982307625376442606753688071083149620216746\", \"price\":\"0.01\", \"size\":\"7878.02\", \"side\":\"BUY\", \"hash\":\"cc3319dceba76e3f39f50c2fcbcad01f556e50af\", \"best_bid\":\"0.5\", \"best_ask\":\"0.51\"}, {\"asset_id\":\"110216635572655435074987471276357323571387854733835379371586402147734167783946\", \"price\":\"0.99\", \"size\":\"7878.02\", \"side\":\"SELL\", \"hash\":\"7c3dc6683238c7f4adc0beb654f3dff6ef3e1a89\", \"best_bid\":\"0.49\", \"best_ask\":\"0.5\"}], \"timestamp\":\"1785130272661\", \"event_type\":\"price_change\"}","received_at":"2026-07-27T05:31:12.628992Z","schema_version":"clob-market-ws.price_change.v1","sequence":null,"server_hash":null,"server_timestamp":"1785130272661","session_id":"502006c5cfcd437296561ea750c9ec8b","source":"clob_market_ws"},"received_at":"2026-07-27T05:31:12.628992Z","record_id":"6b840a085ee1ab641995eb1ddcb43bca9235a6393d0a7bc1694bcec16650734f","schema_fingerprint":"4aa3821a28b0b7c2400bc59aba4bcc0a76e971dadd19610d3ad38c768e124dc7","schema_version":"edge-lab-recorder.raw.v1","sequence":null,"source":"clob_market_ws"}
{"event_at":"2026-07-27T05:31:12.672000Z","event_fingerprint":"995b6b3a6af4cecdb96267c7a495923fb5fb13a128a4f16e705c07816fe29ef2","payload":{"connection_id":"efc69d3132f1467b8e898a382b23ac0d","event_at":"2026-07-27T05:31:12.672000Z","event_type":"price_change","frame_hash":"e34da418f0a3da13aae49e41aba1ad4f4f79246a2262b59560f7370e262abbbf","frame_index":0,"kind":"data","monotonic_ns":232255872542625,"payload":{"event_type":"price_change","market":"0x3b40066b5cf3871a2f6237c5628bd8092a206aa998558ac5ec13c4483e31e160","price_changes":[{"asset_id":"14766054693214075530629349735273995982307625376442606753688071083149620216746","best_ask":"0.51","best_bid":"0.5","hash":"1a870a7d8833bbcc11d68f1a7edf75ebd0fe021a","price":"0.01","side":"BUY","size":"7873.02"},{"asset_id":"110216635572655435074987471276357323571387854733835379371586402147734167783946","best_ask":"0.5","best_bid":"0.49","hash":"6ce51cca188747335c416c89fc99c4029c296398","price":"0.99","side":"SELL","size":"7873.02"}],"timestamp":"1785130272672"},"payload_hash":"f72873d9de8a7ac85b85e1ce22f8da8e0484c21c2c2ea1370c0deedd3e8c30c5","raw_frame":"{\"market\":\"0x3b40066b5cf3871a2f6237c5628bd8092a206aa998558ac5ec13c4483e31e160\", \"price_changes\":[{\"asset_id\":\"14766054693214075530629349735273995982307625376442606753688071083149620216746\", \"price\":\"0.01\", \"size\":\"7873.02\", \"side\":\"BUY\", \"hash\":\"1a870a7d8833bbcc11d68f1a7edf75ebd0fe021a\", \"best_bid\":\"0.5\", \"best_ask\":\"0.51\"}, {\"asset_id\":\"110216635572655435074987471276357323571387854733835379371586402147734167783946\", \"price\":\"0.99\", \"size\":\"7873.02\", \"side\":\"SELL\", \"hash\":\"6ce51cca188747335c416c89fc99c4029c296398\", \"best_bid\":\"0.49\", \"best_ask\":\"0.5\"}], \"timestamp\":\"1785130272672\", \"event_type\":\"price_change\"}","received_at":"2026-07-27T05:31:12.634838Z","schema_version":"clob-market-ws.price_change.v1","sequence":null,"server_hash":null,"server_timestamp":"1785130272672","session_id":"502006c5cfcd437296561ea750c9ec8b","source":"clob_market_ws"},"received_at":"2026-07-27T05:31:12.634838Z","record_id":"ef887b53be98175f8cc50c1328dd25a578300cebedd67d74bdbb3fcb48bd5a7e","schema_fingerprint":"4aa3821a28b0b7c2400bc59aba4bcc0a76e971dadd19610d3ad38c768e124dc7","schema_version":"edge-lab-recorder.raw.v1","sequence":null,"source":"clob_market_ws"}
{"event_at":"2026-07-27T05:31:12.676000Z","event_fingerprint":"07aaf989b7c2e2eecf972f44df3400aac075dbbfde63cb7396a557bb393cce83","payload":{"connection_id":"efc69d3132f1467b8e898a382b23ac0d","event_at":"2026-07-27T05:31:12.676000Z","event_type":"price_change","frame_hash":"a9769d5c9b607ca318d32e8334ab5ab742fe3dc7b72c7b4562c7f445e2dbc605","frame_index":0,"kind":"data","monotonic_ns":232255877019833,"payload":{"event_type":"price_change","market":"0x3b40066b5cf3871a2f6237c5628bd8092a206aa998558ac5ec13c4483e31e160","price_changes":[{"asset_id":"110216635572655435074987471276357323571387854733835379371586402147734167783946","best_ask":"0.5","best_bid":"0.49","hash":"46e18e117832555e2755273b0e045408e56b53c1","price":"0.48","side":"BUY","size":"148.6"},{"asset_id":"14766054693214075530629349735273995982307625376442606753688071083149620216746","best_ask":"0.51","best_bid":"0.5","hash":"7902c71d15953fa5ca1b48086db11245a2112869","price":"0.52","side":"SELL","size":"148.6"}],"timestamp":"1785130272676"},"payload_hash":"02c9d2f18daeb9714f6abbba3d92b39c34420861931841ae359c9cd9b8888f47","raw_frame":"{\"market\":\"0x3b40066b5cf3871a2f6237c5628bd8092a206aa998558ac5ec13c4483e31e160\", \"price_changes\":[{\"asset_id\":\"110216635572655435074987471276357323571387854733835379371586402147734167783946\", \"price\":\"0.48\", \"size\":\"148.6\", \"side\":\"BUY\", \"hash\":\"46e18e117832555e2755273b0e045408e56b53c1\", \"best_bid\":\"0.49\", \"best_ask\":\"0.5\"}, {\"asset_id\":\"14766054693214075530629349735273995982307625376442606753688071083149620216746\", \"price\":\"0.52\", \"size\":\"148.6\", \"side\":\"SELL\", \"hash\":\"7902c71d15953fa5ca1b48086db11245a2112869\", \"best_bid\":\"0.5\", \"best_ask\":\"0.51\"}], \"timestamp\":\"1785130272676\", \"event_type\":\"price_change\"}","received_at":"2026-07-27T05:31:12.639314Z","schema_version":"clob-market-ws.price_change.v1","sequence":null,"server_hash":null,"server_timestamp":"1785130272676","session_id":"502006c5cfcd437296561ea750c9ec8b","source":"clob_market_ws"},"received_at":"2026-07-27T05:31:12.639314Z","record_id":"a9b5bfa74ff359b3d0038c46d4a1756731b520b2f91a26805f65a465abcb2761","schema_fingerprint":"4aa3821a28b0b7c2400bc59aba4bcc0a76e971dadd19610d3ad38c768e124dc7","schema_version":"edge-lab-recorder.raw.v1","sequence":null,"source":"clob_market_ws"}
{"event_at":"2026-07-27T05:31:12.687000Z","event_fingerprint":"9da3718b7ab55f18027ce3632dbef2ea08770e459e5acea7c7e8cd06754ae0cb","payload":{"connection_id":"efc69d3132f1467b8e898a382b23ac0d","event_at":"2026-07-27T05:31:12.687000Z","event_type":"price_change","frame_hash":"9d43befb8e67ef2f9d906d1f0f11d102414991a0f5b30f9fd7cc8dc1df270d91","frame_index":0,"kind":"data","monotonic_ns":232255888919166,"payload":{"event_type":"price_change","market":"0x3b40066b5cf3871a2f6237c5628bd8092a206aa998558ac5ec13c4483e31e160","price_changes":[{"asset_id":"110216635572655435074987471276357323571387854733835379371586402147734167783946","best_ask":"0.5","best_bid":"0.49","hash":"05807b471492298da7f3a2d9985850384a742a70","price":"0.43","side":"BUY","size":"62.25"},{"asset_id":"14766054693214075530629349735273995982307625376442606753688071083149620216746","best_ask":"0.51","best_bid":"0.5","hash":"fb0d8d07898a28e4b602c2c1bf97671e72c7bd2e","price":"0.57","side":"SELL","size":"62.25"}],"timestamp":"1785130272687"},"payload_hash":"fb950618891077da93b8ca493ab03e64c71b1da321827b67759d9ef96655c08b","raw_frame":"{\"market\":\"0x3b40066b5cf3871a2f6237c5628bd8092a206aa998558ac5ec13c4483e31e160\", \"price_changes\":[{\"asset_id\":\"110216635572655435074987471276357323571387854733835379371586402147734167783946\", \"price\":\"0.43\", \"size\":\"62.25\", \"side\":\"BUY\", \"hash\":\"05807b471492298da7f3a2d9985850384a742a70\", \"best_bid\":\"0.49\", \"best_ask\":\"0.5\"}, {\"asset_id\":\"14766054693214075530629349735273995982307625376442606753688071083149620216746\", \"price\":\"0.57\", \"size\":\"62.25\", \"side\":\"SELL\", \"hash\":\"fb0d8d07898a28e4b602c2c1bf97671e72c7bd2e\", \"best_bid\":\"0.5\", \"best_ask\":\"0.51\"}], \"timestamp\":\"1785130272687\", \"event_type\":\"price_change\"}","received_at":"2026-07-27T05:31:12.651214Z","schema_version":"clob-market-ws.price_change.v1","sequence":null,"server_hash":null,"server_timestamp":"1785130272687","session_id":"502006c5cfcd437296561ea750c9ec8b","source":"clob_market_ws"},"received_at":"2026-07-27T05:31:12.651214Z","record_id":"6ef664ea5686f409496558bbf0f8c910543a13c795c02c75656be4285d09f2dc","schema_fingerprint":"4aa3821a28b0b7c2400bc59aba4bcc0a76e971dadd19610d3ad38c768e124dc7","schema_version":"edge-lab-recorder.raw.v1","sequence":null,"source":"clob_market_ws"}
{"event_at":"2026-07-27T05:31:12.701000Z","event_fingerprint":"0eee55753a9c7992100a3fadd34a37e77d14cea861823eee2154deab5062b06f","payload":{"connection_id":"efc69d3132f1467b8e898a382b23ac0d","event_at":"2026-07-27T05:31:12.701000Z","event_type":"price_change","frame_hash":"b918c8da2c76ae524055fb635b41dfd938c46bd2cf3d75ffaa9d9447c1b362b5","frame_index":0,"kind":"data","monotonic_ns":232255901914541,"payload":{"event_type":"price_change","market":"0x3b40066b5cf3871a2f6237c5628bd8092a206aa998558ac5ec13c4483e31e160","price_changes":[{"asset_id":"14766054693214075530629349735273995982307625376442606753688071083149620216746","best_ask":"0.51","best_bid":"0.5","hash":"2398d5d99cd3dd172624e1e13b0bda96d703291c","price":"0.52","side":"SELL","size":"156.6"},{"asset_id":"110216635572655435074987471276357323571387854733835379371586402147734167783946","best_ask":"0.5","best_bid":"0.49","hash":"e8423b96f90b640e02b4079b9f19bca824db7e46","price":"0.48","side":"BUY","size":"156.6"}],"timestamp":"1785130272701"},"payload_hash":"9b08b4bc66651883c7dc0880cd7a3abeabd56e84777697cc2cedda121df2e192","raw_frame":"{\"market\":\"0x3b40066b5cf3871a2f6237c5628bd8092a206aa998558ac5ec13c4483e31e160\", \"price_changes\":[{\"asset_id\":\"14766054693214075530629349735273995982307625376442606753688071083149620216746\", \"price\":\"0.52\", \"size\":\"156.6\", \"side\":\"SELL\", \"hash\":\"2398d5d99cd3dd172624e1e13b0bda96d703291c\", \"best_bid\":\"0.5\", \"best_ask\":\"0.51\"}, {\"asset_id\":\"110216635572655435074987471276357323571387854733835379371586402147734167783946\", \"price\":\"0.48\", \"size\":\"156.6\", \"side\":\"BUY\", \"hash\":\"e8423b96f90b640e02b4079b9f19bca824db7e46\", \"best_bid\":\"0.49\", \"best_ask\":\"0.5\"}], \"timestamp\":\"1785130272701\", \"event_type\":\"price_change\"}","received_at":"2026-07-27T05:31:12.664216Z","schema_version":"clob-market-ws.price_change.v1","sequence":null,"server_hash":null,"server_timestamp":"1785130272701","session_id":"502006c5cfcd437296561ea750c9ec8b","source":"clob_market_ws"},"received_at":"2026-07-27T05:31:12.664216Z","record_id":"4ecc61c676a2b1648ebeb1d2368fe80ba31716cf4e5e51563f701e3e6deffff8","schema_fingerprint":"4aa3821a28b0b7c2400bc59aba4bcc0a76e971dadd19610d3ad38c768e124dc7","schema_version":"edge-lab-recorder.raw.v1","sequence":null,"source":"clob_market_ws"}
{"event_at":"2026-07-27T05:31:12.755000Z","event_fingerprint":"1272a049a70b3f543bdadbe3e3d9d739666ae54736a662f34464ebde93280509","payload":{"connection_id":"efc69d3132f1467b8e898a382b23ac0d","event_at":"2026-07-27T05:31:12.755000Z","event_type":"price_change","frame_hash":"7c4b0ac7be83a2f4b82b92e36e595e74adc8ab1569c4d96707376424aa083808","frame_index":0,"kind":"data","monotonic_ns":232255958035083,"payload":{"event_type":"price_change","market":"0x3b40066b5cf3871a2f6237c5628bd8092a206aa998558ac5ec13c4483e31e160","price_changes":[{"asset_id":"14766054693214075530629349735273995982307625376442606753688071083149620216746","best_ask":"0.51","best_bid":"0.5","hash":"102c4d70534d6f076315ff16ab0f1a9efe545544","price":"0.49","side":"BUY","size":"144.4"},{"asset_id":"110216635572655435074987471276357323571387854733835379371586402147734167783946","best_ask":"0.5","best_bid":"0.49","hash":"b7ebd61ff448177651f4971c33fb9b3ed984187b","price":"0.51","side":"SELL","size":"144.4"}],"timestamp":"1785130272755"},"payload_hash":"9dd5f8a3b3e1df4324c4097bde3c9f7bd0e15319c0fce7c4f6c5db3631e60fc6","raw_frame":"{\"market\":\"0x3b40066b5cf3871a2f6237c5628bd8092a206aa998558ac5ec13c4483e31e160\", \"price_changes\":[{\"asset_id\":\"14766054693214075530629349735273995982307625376442606753688071083149620216746\", \"price\":\"0.49\", \"size\":\"144.4\", \"side\":\"BUY\", \"hash\":\"102c4d70534d6f076315ff16ab0f1a9efe545544\", \"best_bid\":\"0.5\", \"best_ask\":\"0.51\"}, {\"asset_id\":\"110216635572655435074987471276357323571387854733835379371586402147734167783946\", \"price\":\"0.51\", \"size\":\"144.4\", \"side\":\"SELL\", \"hash\":\"b7ebd61ff448177651f4971c33fb9b3ed984187b\", \"best_bid\":\"0.49\", \"best_ask\":\"0.5\"}], \"timestamp\":\"1785130272755\", \"event_type\":\"price_change\"}","received_at":"2026-07-27T05:31:12.720329Z","schema_version":"clob-market-ws.price_change.v1","sequence":null,"server_hash":null,"server_timestamp":"1785130272755","session_id":"502006c5cfcd437296561ea750c9ec8b","source":"clob_market_ws"},"received_at":"2026-07-27T05:31:12.720329Z","record_id":"695a52fafec64863bc51218229b2872cb612615f16076d940b08f4535b64f5a7","schema_fingerprint":"4aa3821a28b0b7c2400bc59aba4bcc0a76e971dadd19610d3ad38c768e124dc7","schema_version":"edge-lab-recorder.raw.v1","sequence":null,"source":"clob_market_ws"}
{"event_at":"2026-07-27T05:31:12.757000Z","event_fingerprint":"22d4329678f8b07dfe953974649724cc0b19f7c83807a19e24551c691a911914","payload":{"connection_id":"efc69d3132f1467b8e898a382b23ac0d","event_at":"2026-07-27T05:31:12.757000Z","event_type":"price_change","frame_hash":"81c11736fa08351da4505f69b8cdac8fd2727c897ca50390526c2965fefdcd67","frame_index":0,"kind":"data","monotonic_ns":232255963653791,"payload":{"event_type":"price_change","market":"0x3b40066b5cf3871a2f6237c5628bd8092a206aa998558ac5ec13c4483e31e160","price_changes":[{"asset_id":"110216635572655435074987471276357323571387854733835379371586402147734167783946","best_ask":"0.5","best_bid":"0.49","hash":"65f8716678a632e0e4150bd7b0ed095e44d57e97","price":"0.46","side":"BUY","size":"311"},{"asset_id":"14766054693214075530629349735273995982307625376442606753688071083149620216746","best_ask":"0.51","best_bid":"0.5","hash":"5bcca79f9c00c94a35dbbb31c52388e15597b6ae","price":"0.54","side":"SELL","size":"311"}],"timestamp":"1785130272757"},"payload_hash":"834c596acb73442f1a91e9277f1049e8f931b270f4bb20606187c3d441004cf4","raw_frame":"{\"market\":\"0x3b40066b5cf3871a2f6237c5628bd8092a206aa998558ac5ec13c4483e31e160\", \"price_changes\":[{\"asset_id\":\"110216635572655435074987471276357323571387854733835379371586402147734167783946\", \"price\":\"0.46\", \"size\":\"311\", \"side\":\"BUY\", \"hash\":\"65f8716678a632e0e4150bd7b0ed095e44d57e97\", \"best_bid\":\"0.49\", \"best_ask\":\"0.5\"}, {\"asset_id\":\"14766054693214075530629349735273995982307625376442606753688071083149620216746\", \"price\":\"0.54\", \"size\":\"311\", \"side\":\"SELL\", \"hash\":\"5bcca79f9c00c94a35dbbb31c52388e15597b6ae\", \"best_bid\":\"0.5\", \"best_ask\":\"0.51\"}], \"timestamp\":\"1785130272757\", \"event_type\":\"price_change\"}","received_at":"2026-07-27T05:31:12.725955Z","schema_version":"clob-market-ws.price_change.v1","sequence":null,"server_hash":null,"server_timestamp":"1785130272757","session_id":"502006c5cfcd437296561ea750c9ec8b","source":"clob_market_ws"},"received_at":"2026-07-27T05:31:12.725955Z","record_id":"74deaa7dd713963c4760b4e2208144daf9591e4b889a99bf5e1b79abae3ea40c","schema_fingerprint":"4aa3821a28b0b7c2400bc59aba4bcc0a76e971dadd19610d3ad38c768e124dc7","schema_version":"edge-lab-recorder.raw.v1","sequence":null,"source":"clob_market_ws"}
{"event_at":"2026-07-27T05:31:12.758000Z","event_fingerprint":"26b04be2b912bdbcc39070d0069ff6330223791b6d8cbf3a080ebbae6a58c4f0","payload":{"connection_id":"efc69d3132f1467b8e898a382b23ac0d","event_at":"2026-07-27T05:31:12.758000Z","event_type":"price_change","frame_hash":"0d98e7e641b8ed65e27e900d4f4afc3931f585237f68fa3a2a05d473a12c1107","frame_index":0,"kind":"data","monotonic_ns":232255966821083,"payload":{"event_type":"price_change","market":"0x3b40066b5cf3871a2f6237c5628bd8092a206aa998558ac5ec13c4483e31e160","price_changes":[{"asset_id":"14766054693214075530629349735273995982307625376442606753688071083149620216746","best_ask":"0.51","best_bid":"0.5","hash":"c20250a1775493d0051da26fe7e477d7365e0afc","price":"0.04","side":"BUY","size":"663.09"},{"asset_id":"110216635572655435074987471276357323571387854733835379371586402147734167783946","best_ask":"0.5","best_bid":"0.49","hash":"1609f02211c45d13cc64f98526bb5c2516969f15","price":"0.96","side":"SELL","size":"663.09"}],"timestamp":"1785130272758"},"payload_hash":"f4b0ceea92e2d56513126f4ae225f109c9aca24c299e764a07d446b7fa9f5e15","raw_frame":"{\"market\":\"0x3b40066b5cf3871a2f6237c5628bd8092a206aa998558ac5ec13c4483e31e160\", \"price_changes\":[{\"asset_id\":\"14766054693214075530629349735273995982307625376442606753688071083149620216746\", \"price\":\"0.04\", \"size\":\"663.09\", \"side\":\"BUY\", \"hash\":\"c20250a1775493d0051da26fe7e477d7365e0afc\", \"best_bid\":\"0.5\", \"best_ask\":\"0.51\"}, {\"asset_id\":\"110216635572655435074987471276357323571387854733835379371586402147734167783946\", \"price\":\"0.96\", \"size\":\"663.09\", \"side\":\"SELL\", \"hash\":\"1609f02211c45d13cc64f98526bb5c2516969f15\", \"best_bid\":\"0.49\", \"best_ask\":\"0.5\"}], \"timestamp\":\"1785130272758\", \"event_type\":\"price_change\"}","received_at":"2026-07-27T05:31:12.729118Z","schema_version":"clob-market-ws.price_change.v1","sequence":null,"server_hash":null,"server_timestamp":"1785130272758","session_id":"502006c5cfcd437296561ea750c9ec8b","source":"clob_market_ws"},"received_at":"2026-07-27T05:31:12.729118Z","record_id":"c575a6c06477e559e415a8a0c52a977e4d10c50a54ab7f93ae93e0c8bf6ce51a","schema_fingerprint":"4aa3821a28b0b7c2400bc59aba4bcc0a76e971dadd19610d3ad38c768e124dc7","schema_version":"edge-lab-recorder.raw.v1","sequence":null,"source":"clob_market_ws"}
{"event_at":"2026-07-27T05:31:12.765000Z","event_fingerprint":"d6c67ee58d359d27b2378f3523fe6e7b1fadda8d578252aeb20030d1c1175846","payload":{"connection_id":"efc69d3132f1467b8e898a382b23ac0d","event_at":"2026-07-27T05:31:12.765000Z","event_type":"price_change","frame_hash":"5df927a5c4cc2cf60e5b75ceced8caa31a49b7cd50ada04828997344a40c6b5c","frame_index":0,"kind":"data","monotonic_ns":232255969899458,"payload":{"event_type":"price_change","market":"0x3b40066b5cf3871a2f6237c5628bd8092a206aa998558ac5ec13c4483e31e160","price_changes":[{"asset_id":"110216635572655435074987471276357323571387854733835379371586402147734167783946","best_ask":"0.5","best_bid":"0.49","hash":"a9c3d172eeb7280352472b92ff07cb15f8591f1a","price":"0.31","side":"BUY","size":"42"},{"asset_id":"14766054693214075530629349735273995982307625376442606753688071083149620216746","best_ask":"0.51","best_bid":"0.5","hash":"ab6e25a9c78e304777f07cdecbcf7ea55263f4c4","price":"0.69","side":"SELL","size":"42"}],"timestamp":"1785130272765"},"payload_hash":"17c528152abf6f4ca21f7e356917e1bb2437120c5a9bf5351b64dac1cfd00095","raw_frame":"{\"market\":\"0x3b40066b5cf3871a2f6237c5628bd8092a206aa998558ac5ec13c4483e31e160\", \"price_changes\":[{\"asset_id\":\"110216635572655435074987471276357323571387854733835379371586402147734167783946\", \"price\":\"0.31\", \"size\":\"42\", \"side\":\"BUY\", \"hash\":\"a9c3d172eeb7280352472b92ff07cb15f8591f1a\", \"best_bid\":\"0.49\", \"best_ask\":\"0.5\"}, {\"asset_id\":\"14766054693214075530629349735273995982307625376442606753688071083149620216746\", \"price\":\"0.69\", \"size\":\"42\", \"side\":\"SELL\", \"hash\":\"ab6e25a9c78e304777f07cdecbcf7ea55263f4c4\", \"best_bid\":\"0.5\", \"best_ask\":\"0.51\"}], \"timestamp\":\"1785130272765\", \"event_type\":\"price_change\"}","received_at":"2026-07-27T05:31:12.732195Z","schema_version":"clob-market-ws.price_change.v1","sequence":null,"server_hash":null,"server_timestamp":"1785130272765","session_id":"502006c5cfcd437296561ea750c9ec8b","source":"clob_market_ws"},"received_at":"2026-07-27T05:31:12.732195Z","record_id":"c003ed04ec65fb71ea43bab634f636e148e5e5bc457dd1dab383d413ec475e65","schema_fingerprint":"4aa3821a28b0b7c2400bc59aba4bcc0a76e971dadd19610d3ad38c768e124dc7","schema_version":"edge-lab-recorder.raw.v1","sequence":null,"source":"clob_market_ws"}
{"event_at":"2026-07-27T05:31:12.778000Z","event_fingerprint":"a5004e71010a1685f354e23d1b81f70e257809035e1d6110ea5575255ffad8b8","payload":{"connection_id":"efc69d3132f1467b8e898a382b23ac0d","event_at":"2026-07-27T05:31:12.778000Z","event_type":"price_change","frame_hash":"32d92cccbe5fe089be829c5e69a900f74e64aa6a3cbabf8f225deca24167fa5b","frame_index":0,"kind":"data","monotonic_ns":232255979215416,"payload":{"event_type":"price_change","market":"0x3b40066b5cf3871a2f6237c5628bd8092a206aa998558ac5ec13c4483e31e160","price_changes":[{"asset_id":"110216635572655435074987471276357323571387854733835379371586402147734167783946","best_ask":"0.5","best_bid":"0.49","hash":"baf276a6c50d128816632fa8de6a00b09041d466","price":"0.4","side":"BUY","size":"199"},{"asset_id":"14766054693214075530629349735273995982307625376442606753688071083149620216746","best_ask":"0.51","best_bid":"0.5","hash":"deaffe11dacc708aab5a79cdf72789f3e91c2799","price":"0.6","side":"SELL","size":"199"}],"timestamp":"1785130272778"},"payload_hash":"24ff661883ac195132b5e862f1cb82cbb5746484fef816306712e7e52d19bbbf","raw_frame":"{\"market\":\"0x3b40066b5cf3871a2f6237c5628bd8092a206aa998558ac5ec13c4483e31e160\", \"price_changes\":[{\"asset_id\":\"110216635572655435074987471276357323571387854733835379371586402147734167783946\", \"price\":\"0.4\", \"size\":\"199\", \"side\":\"BUY\", \"hash\":\"baf276a6c50d128816632fa8de6a00b09041d466\", \"best_bid\":\"0.49\", \"best_ask\":\"0.5\"}, {\"asset_id\":\"14766054693214075530629349735273995982307625376442606753688071083149620216746\", \"price\":\"0.6\", \"size\":\"199\", \"side\":\"SELL\", \"hash\":\"deaffe11dacc708aab5a79cdf72789f3e91c2799\", \"best_bid\":\"0.5\", \"best_ask\":\"0.51\"}], \"timestamp\":\"1785130272778\", \"event_type\":\"price_change\"}","received_at":"2026-07-27T05:31:12.741511Z","schema_version":"clob-market-ws.price_change.v1","sequence":null,"server_hash":null,"server_timestamp":"1785130272778","session_id":"502006c5cfcd437296561ea750c9ec8b","source":"clob_market_ws"},"received_at":"2026-07-27T05:31:12.741511Z","record_id":"68d20df66f56d48e8e9c03e538140b09529564849c622db498d18a9f51757e24","schema_fingerprint":"4aa3821a28b0b7c2400bc59aba4bcc0a76e971dadd19610d3ad38c768e124dc7","schema_version":"edge-lab-recorder.raw.v1","sequence":null,"source":"clob_market_ws"}
{"event_at":"2026-07-27T05:31:12.779000Z","event_fingerprint":"0abf5811f9f834baca47233a29d7010d32760ec62277d17f200a84892b1f6f52","payload":{"connection_id":"efc69d3132f1467b8e898a382b23ac0d","event_at":"2026-07-27T05:31:12.779000Z","event_type":"price_change","frame_hash":"f3504ebcdc9d357f909a636dafee137bbd2205288832a76b8dcd6757c9689681","frame_index":0,"kind":"data","monotonic_ns":232255984156208,"payload":{"event_type":"price_change","market":"0x3b40066b5cf3871a2f6237c5628bd8092a206aa998558ac5ec13c4483e31e160","price_changes":[{"asset_id":"110216635572655435074987471276357323571387854733835379371586402147734167783946","best_ask":"0.5","best_bid":"0.49","hash":"24dbf428b686d71644d1b4b369b9512c7545abf4","price":"0.4","side":"BUY","size":"181"},{"asset_id":"14766054693214075530629349735273995982307625376442606753688071083149620216746","best_ask":"0.51","best_bid":"0.5","hash":"7d3799c160be92b5715cb39a844e925211f0a3be","price":"0.6","side":"SELL","size":"181"}],"timestamp":"1785130272779"},"payload_hash":"dbd62a05053d2d7db88788b800611995bc0e2bdfd1165a206752dff57c0c63fc","raw_frame":"{\"market\":\"0x3b40066b5cf3871a2f6237c5628bd8092a206aa998558ac5ec13c4483e31e160\", \"price_changes\":[{\"asset_id\":\"110216635572655435074987471276357323571387854733835379371586402147734167783946\", \"price\":\"0.4\", \"size\":\"181\", \"side\":\"BUY\", \"hash\":\"24dbf428b686d71644d1b4b369b9512c7545abf4\", \"best_bid\":\"0.49\", \"best_ask\":\"0.5\"}, {\"asset_id\":\"14766054693214075530629349735273995982307625376442606753688071083149620216746\", \"price\":\"0.6\", \"size\":\"181\", \"side\":\"SELL\", \"hash\":\"7d3799c160be92b5715cb39a844e925211f0a3be\", \"best_bid\":\"0.5\", \"best_ask\":\"0.51\"}], \"timestamp\":\"1785130272779\", \"event_type\":\"price_change\"}","received_at":"2026-07-27T05:31:12.746455Z","schema_version":"clob-market-ws.price_change.v1","sequence":null,"server_hash":null,"server_timestamp":"1785130272779","session_id":"502006c5cfcd437296561ea750c9ec8b","source":"clob_market_ws"},"received_at":"2026-07-27T05:31:12.746455Z","record_id":"eae27fa3b7dbdbd58981eea10e13f5fc5c136b1011d3d8f21ef3440dd947591e","schema_fingerprint":"4aa3821a28b0b7c2400bc59aba4bcc0a76e971dadd19610d3ad38c768e124dc7","schema_version":"edge-lab-recorder.raw.v1","sequence":null,"source":"clob_market_ws"}
{"event_at":"2026-07-27T05:31:12.781000Z","event_fingerprint":"12b0d2e2a71125e0ae041be5935d29ba3b22b8ff1612d1b7ec5c2339fb3616eb","payload":{"connection_id":"efc69d3132f1467b8e898a382b23ac0d","event_at":"2026-07-27T05:31:12.781000Z","event_type":"price_change","frame_hash":"929059bac75bd97aefd06ef356066591dc992173a6835322b1bf9294abc281a5","frame_index":0,"kind":"data","monotonic_ns":232255986191125,"payload":{"event_type":"price_change","market":"0x3b40066b5cf3871a2f6237c5628bd8092a206aa998558ac5ec13c4483e31e160","price_changes":[{"asset_id":"110216635572655435074987471276357323571387854733835379371586402147734167783946","best_ask":"0.5","best_bid":"0.49","hash":"0c907fdb0dffefa816ff27d0b08cbe20b169cd0c","price":"0.4","side":"BUY","size":"151"},{"asset_id":"14766054693214075530629349735273995982307625376442606753688071083149620216746","best_ask":"0.51","best_bid":"0.5","hash":"50b3a32e8150231a08ad10c581eb7b4b8fddadc0","price":"0.6","side":"SELL","size":"151"}],"timestamp":"1785130272781"},"payload_hash":"871b58d0e4512b5f0d0875d2b758c5fc3eadb96bf39d8cddb1ca367a90994590","raw_frame":"{\"market\":\"0x3b40066b5cf3871a2f6237c5628bd8092a206aa998558ac5ec13c4483e31e160\", \"price_changes\":[{\"asset_id\":\"110216635572655435074987471276357323571387854733835379371586402147734167783946\", \"price\":\"0.4\", \"size\":\"151\", \"side\":\"BUY\", \"hash\":\"0c907fdb0dffefa816ff27d0b08cbe20b169cd0c\", \"best_bid\":\"0.49\", \"best_ask\":\"0.5\"}, {\"asset_id\":\"14766054693214075530629349735273995982307625376442606753688071083149620216746\", \"price\":\"0.6\", \"size\":\"151\", \"side\":\"SELL\", \"hash\":\"50b3a32e8150231a08ad10c581eb7b4b8fddadc0\", \"best_bid\":\"0.5\", \"best_ask\":\"0.51\"}], \"timestamp\":\"1785130272781\", \"event_type\":\"price_change\"}","received_at":"2026-07-27T05:31:12.748487Z","schema_version":"clob-market-ws.price_change.v1","sequence":null,"server_hash":null,"server_timestamp":"1785130272781","session_id":"502006c5cfcd437296561ea750c9ec8b","source":"clob_market_ws"},"received_at":"2026-07-27T05:31:12.748487Z","record_id":"f7dd51e0395097055afd476843dcc331e58a24453ad1d9316c64234d021fd45a","schema_fingerprint":"4aa3821a28b0b7c2400bc59aba4bcc0a76e971dadd19610d3ad38c768e124dc7","schema_version":"edge-lab-recorder.raw.v1","sequence":null,"source":"clob_market_ws"}
{"event_at":"2026-07-27T05:31:12.782000Z","event_fingerprint":"4b106df86820317b133161f46f1fb0e9ad7f6f510a9e830ad7ad173ac8a3a2da","payload":{"connection_id":"efc69d3132f1467b8e898a382b23ac0d","event_at":"2026-07-27T05:31:12.782000Z","event_type":"price_change","frame_hash":"539ed378125f03d88ad3e75dc0486cb23d893ba335bd687188ce246dcd3e9204","frame_index":0,"kind":"data","monotonic_ns":232255993674583,"payload":{"event_type":"price_change","market":"0x3b40066b5cf3871a2f6237c5628bd8092a206aa998558ac5ec13c4483e31e160","price_changes":[{"asset_id":"14766054693214075530629349735273995982307625376442606753688071083149620216746","best_ask":"0.51","best_bid":"0.5","hash":"4e29d65580fe7b14d04e1ef1a27924b50ecd41fd","price":"0.52","side":"SELL","size":"148.6"},{"asset_id":"110216635572655435074987471276357323571387854733835379371586402147734167783946","best_ask":"0.5","best_bid":"0.49","hash":"98ce75b41262e9cbefd727f4cd50da8508d08b0b","price":"0.48","side":"BUY","size":"148.6"}],"timestamp":"1785130272782"},"payload_hash":"6156af90eb2e6a16b59b3fdf789d8bda19dcc7569f21d1b617ec292624fa9969","raw_frame":"{\"market\":\"0x3b40066b5cf3871a2f6237c5628bd8092a206aa998558ac5ec13c4483e31e160\", \"price_changes\":[{\"asset_id\":\"14766054693214075530629349735273995982307625376442606753688071083149620216746\", \"price\":\"0.52\", \"size\":\"148.6\", \"side\":\"SELL\", \"hash\":\"4e29d65580fe7b14d04e1ef1a27924b50ecd41fd\", \"best_bid\":\"0.5\", \"best_ask\":\"0.51\"}, {\"asset_id\":\"110216635572655435074987471276357323571387854733835379371586402147734167783946\", \"price\":\"0.48\", \"size\":\"148.6\", \"side\":\"BUY\", \"hash\":\"98ce75b41262e9cbefd727f4cd50da8508d08b0b\", \"best_bid\":\"0.49\", \"best_ask\":\"0.5\"}], \"timestamp\":\"1785130272782\", \"event_type\":\"price_change\"}","received_at":"2026-07-27T05:31:12.755969Z","schema_version":"clob-market-ws.price_change.v1","sequence":null,"server_hash":null,"server_timestamp":"1785130272782","session_id":"502006c5cfcd437296561ea750c9ec8b","source":"clob_market_ws"},"received_at":"2026-07-27T05:31:12.755969Z","record_id":"43e0b975cd52756dbbd5da30bea6954c844931da10cfe0fb46012c3536b4e589","schema_fingerprint":"4aa3821a28b0b7c2400bc59aba4bcc0a76e971dadd19610d3ad38c768e124dc7","schema_version":"edge-lab-recorder.raw.v1","sequence":null,"source":"clob_market_ws"}
{"event_at":"2026-07-27T05:31:12.786000Z","event_fingerprint":"a7a9f8102c12ee43d47daaaa60376352d187433f18eb5607317e9fa1882c5f67","payload":{"connection_id":"efc69d3132f1467b8e898a382b23ac0d","event_at":"2026-07-27T05:31:12.786000Z","event_type":"price_change","frame_hash":"6416c90ebc57ff0f7f9c95a66a746a75900a2e72b4d8a723db23b3a632dd93c3","frame_index":0,"kind":"data","monotonic_ns":232255997530958,"payload":{"event_type":"price_change","market":"0x3b40066b5cf3871a2f6237c5628bd8092a206aa998558ac5ec13c4483e31e160","price_changes":[{"asset_id":"110216635572655435074987471276357323571387854733835379371586402147734167783946","best_ask":"0.5","best_bid":"0.49","hash":"cdb75b5313d27338d17f9a81ee2c3796175ce7a9","price":"0.48","side":"BUY","size":"52.6"},{"asset_id":"14766054693214075530629349735273995982307625376442606753688071083149620216746","best_ask":"0.51","best_bid":"0.5","hash":"ad112a7460d4c63d89699416253dde95c8170cdc","price":"0.52","side":"SELL","size":"52.6"}],"timestamp":"1785130272786"},"payload_hash":"ecc8092709edd7fe4f6bf1363b07524c20b5416a6d16e27a1a6b44d985518352","raw_frame":"{\"market\":\"0x3b40066b5cf3871a2f6237c5628bd8092a206aa998558ac5ec13c4483e31e160\", \"price_changes\":[{\"asset_id\":\"110216635572655435074987471276357323571387854733835379371586402147734167783946\", \"price\":\"0.48\", \"size\":\"52.6\", \"side\":\"BUY\", \"hash\":\"cdb75b5313d27338d17f9a81ee2c3796175ce7a9\", \"best_bid\":\"0.49\", \"best_ask\":\"0.5\"}, {\"asset_id\":\"14766054693214075530629349735273995982307625376442606753688071083149620216746\", \"price\":\"0.52\", \"size\":\"52.6\", \"side\":\"SELL\", \"hash\":\"ad112a7460d4c63d89699416253dde95c8170cdc\", \"best_bid\":\"0.5\", \"best_ask\":\"0.51\"}], \"timestamp\":\"1785130272786\", \"event_type\":\"price_change\"}","received_at":"2026-07-27T05:31:12.759828Z","schema_version":"clob-market-ws.price_change.v1","sequence":null,"server_hash":null,"server_timestamp":"1785130272786","session_id":"502006c5cfcd437296561ea750c9ec8b","source":"clob_market_ws"},"received_at":"2026-07-27T05:31:12.759828Z","record_id":"c4d2ee93b442efe298b4485555192bad27372b71556c1479c5747faefd1a0565","schema_fingerprint":"4aa3821a28b0b7c2400bc59aba4bcc0a76e971dadd19610d3ad38c768e124dc7","schema_version":"edge-lab-recorder.raw.v1","sequence":null,"source":"clob_market_ws"}
{"event_at":"2026-07-27T05:31:12.789000Z","event_fingerprint":"0f668be78f466723c3d01eb56ececa0fb1eaf8f7b225955aa2bc546b339e77ae","payload":{"connection_id":"efc69d3132f1467b8e898a382b23ac0d","event_at":"2026-07-27T05:31:12.789000Z","event_type":"price_change","frame_hash":"2f4fc8a4e7284cee3d7a7d69eea5492b0279fc1c6dd4171b41ce00e5c66a7039","frame_index":0,"kind":"data","monotonic_ns":232256001390583,"payload":{"event_type":"price_change","market":"0x3b40066b5cf3871a2f6237c5628bd8092a206aa998558ac5ec13c4483e31e160","price_changes":[{"asset_id":"110216635572655435074987471276357323571387854733835379371586402147734167783946","best_ask":"0.5","best_bid":"0.49","hash":"4c0b1a8908a05a681bb7db5ad86e017f1cd55ffb","price":"0.48","side":"BUY","size":"60.6"},{"asset_id":"14766054693214075530629349735273995982307625376442606753688071083149620216746","best_ask":"0.51","best_bid":"0.5","hash":"23e60508eb34bf27f4c5c030e9fe8afbbff97ac9","price":"0.52","side":"SELL","size":"60.6"}],"timestamp":"1785130272789"},"payload_hash":"1fb2d14f11e1cbb6a87fa08ed88bd48a9094c5de44b519f0e3f0dd4121ba6408","raw_frame":"{\"market\":\"0x3b40066b5cf3871a2f6237c5628bd8092a206aa998558ac5ec13c4483e31e160\", \"price_changes\":[{\"asset_id\":\"110216635572655435074987471276357323571387854733835379371586402147734167783946\", \"price\":\"0.48\", \"size\":\"60.6\", \"side\":\"BUY\", \"hash\":\"4c0b1a8908a05a681bb7db5ad86e017f1cd55ffb\", \"best_bid\":\"0.49\", \"best_ask\":\"0.5\"}, {\"asset_id\":\"14766054693214075530629349735273995982307625376442606753688071083149620216746\", \"price\":\"0.52\", \"size\":\"60.6\", \"side\":\"SELL\", \"hash\":\"23e60508eb34bf27f4c5c030e9fe8afbbff97ac9\", \"best_bid\":\"0.5\", \"best_ask\":\"0.51\"}], \"timestamp\":\"1785130272789\", \"event_type\":\"price_change\"}","received_at":"2026-07-27T05:31:12.763692Z","schema_version":"clob-market-ws.price_change.v1","sequence":null,"server_hash":null,"server_timestamp":"1785130272789","session_id":"502006c5cfcd437296561ea750c9ec8b","source":"clob_market_ws"},"received_at":"2026-07-27T05:31:12.763692Z","record_id":"964aa9ffd551f4a45ff3ef6f8b9456cc3756ef06b9c21b87eb68ee3f99e91964","schema_fingerprint":"4aa3821a28b0b7c2400bc59aba4bcc0a76e971dadd19610d3ad38c768e124dc7","schema_version":"edge-lab-recorder.raw.v1","sequence":null,"source":"clob_market_ws"}
{"event_at":"2026-07-27T05:31:12.790000Z","event_fingerprint":"afc7f326c141e4d24b84166d306443d42ce9c85e0e1201ea601e44bc80828c56","payload":{"connection_id":"efc69d3132f1467b8e898a382b23ac0d","event_at":"2026-07-27T05:31:12.790000Z","event_type":"price_change","frame_hash":"3f511f2853c6abbb980a97f3e5b3dac3cc63d677a9177a90e409ab8389d9cdb3","frame_index":0,"kind":"data","monotonic_ns":232256003337458,"payload":{"event_type":"price_change","market":"0x3b40066b5cf3871a2f6237c5628bd8092a206aa998558ac5ec13c4483e31e160","price_changes":[{"asset_id":"110216635572655435074987471276357323571387854733835379371586402147734167783946","best_ask":"0.5","best_bid":"0.49","hash":"8e1f8b6efeff6f2dd5100fc771a435a0e7a86a83","price":"0.33","side":"BUY","size":"415.63"},{"asset_id":"14766054693214075530629349735273995982307625376442606753688071083149620216746","best_ask":"0.51","best_bid":"0.5","hash":"20b2a03c97cdd5b28a3f4a828b92a773b7a6cd1f","price":"0.67","side":"SELL","size":"415.63"}],"timestamp":"1785130272790"},"payload_hash":"d834f9cad96acce5d49a548da3233b2de982f90675f4099fba9ea2057f5e4116","raw_frame":"{\"market\":\"0x3b40066b5cf3871a2f6237c5628bd8092a206aa998558ac5ec13c4483e31e160\", \"price_changes\":[{\"asset_id\":\"110216635572655435074987471276357323571387854733835379371586402147734167783946\", \"price\":\"0.33\", \"size\":\"415.63\", \"side\":\"BUY\", \"hash\":\"8e1f8b6efeff6f2dd5100fc771a435a0e7a86a83\", \"best_bid\":\"0.49\", \"best_ask\":\"0.5\"}, {\"asset_id\":\"14766054693214075530629349735273995982307625376442606753688071083149620216746\", \"price\":\"0.67\", \"size\":\"415.63\", \"side\":\"SELL\", \"hash\":\"20b2a03c97cdd5b28a3f4a828b92a773b7a6cd1f\", \"best_bid\":\"0.5\", \"best_ask\":\"0.51\"}], \"timestamp\":\"1785130272790\", \"event_type\":\"price_change\"}","received_at":"2026-07-27T05:31:12.765633Z","schema_version":"clob-market-ws.price_change.v1","sequence":null,"server_hash":null,"server_timestamp":"1785130272790","session_id":"502006c5cfcd437296561ea750c9ec8b","source":"clob_market_ws"},"received_at":"2026-07-27T05:31:12.765633Z","record_id":"f3a2f42decced42ef320fc468c098afb3f21e9dee7834dd53bdf54495561c4ed","schema_fingerprint":"4aa3821a28b0b7c2400bc59aba4bcc0a76e971dadd19610d3ad38c768e124dc7","schema_version":"edge-lab-recorder.raw.v1","sequence":null,"source":"clob_market_ws"}
{"event_at":"2026-07-27T05:31:12.793000Z","event_fingerprint":"3a203bba0b5b24ef74745dd4cd0add86903499fa441b2a3271039bf3090d0506","payload":{"connection_id":"efc69d3132f1467b8e898a382b23ac0d","event_at":"2026-07-27T05:31:12.793000Z","event_type":"price_change","frame_hash":"17a1d65f237446521b9d632db5a7483c17256fef83c265d2130b36334926d9e0","frame_index":0,"kind":"data","monotonic_ns":232256007828083,"payload":{"event_type":"price_change","market":"0x3b40066b5cf3871a2f6237c5628bd8092a206aa998558ac5ec13c4483e31e160","price_changes":[{"asset_id":"110216635572655435074987471276357323571387854733835379371586402147734167783946","best_ask":"0.5","best_bid":"0.49","hash":"95869f40a501cc6a9ceaeb2e950e08040a68d69c","price":"0.47","side":"BUY","size":"129"},{"asset_id":"14766054693214075530629349735273995982307625376442606753688071083149620216746","best_ask":"0.51","best_bid":"0.5","hash":"8982363505d814eb30b29a3c939d2158d01fecd1","price":"0.53","side":"SELL","size":"129"}],"timestamp":"1785130272793"},"payload_hash":"223db22d646b48a588288e6b7f0b384e30a96fc3e957b75a550a815390d55b30","raw_frame":"{\"market\":\"0x3b40066b5cf3871a2f6237c5628bd8092a206aa998558ac5ec13c4483e31e160\", \"price_changes\":[{\"asset_id\":\"110216635572655435074987471276357323571387854733835379371586402147734167783946\", \"price\":\"0.47\", \"size\":\"129\", \"side\":\"BUY\", \"hash\":\"95869f40a501cc6a9ceaeb2e950e08040a68d69c\", \"best_bid\":\"0.49\", \"best_ask\":\"0.5\"}, {\"asset_id\":\"14766054693214075530629349735273995982307625376442606753688071083149620216746\", \"price\":\"0.53\", \"size\":\"129\", \"side\":\"SELL\", \"hash\":\"8982363505d814eb30b29a3c939d2158d01fecd1\", \"best_bid\":\"0.5\", \"best_ask\":\"0.51\"}], \"timestamp\":\"1785130272793\", \"event_type\":\"price_change\"}","received_at":"2026-07-27T05:31:12.770124Z","schema_version":"clob-market-ws.price_change.v1","sequence":null,"server_hash":null,"server_timestamp":"1785130272793","session_id":"502006c5cfcd437296561ea750c9ec8b","source":"clob_market_ws"},"received_at":"2026-07-27T05:31:12.770124Z","record_id":"9475c9e9e00cf0cf0794202d65eeed3c9bddfcb4578ed9e4ae48bf998d357acc","schema_fingerprint":"4aa3821a28b0b7c2400bc59aba4bcc0a76e971dadd19610d3ad38c768e124dc7","schema_version":"edge-lab-recorder.raw.v1","sequence":null,"source":"clob_market_ws"}
{"event_at":"2026-07-27T05:31:12.802000Z","event_fingerprint":"52ea4b8ed0f69909e09158301a9cef70d6151f0122cb5e979125a6632349fa33","payload":{"connection_id":"efc69d3132f1467b8e898a382b23ac0d","event_at":"2026-07-27T05:31:12.802000Z","event_type":"price_change","frame_hash":"db618749bf00190e5f66e127c3eb36a829ebca8bb336fe9207d6df44c52a02fa","frame_index":0,"kind":"data","monotonic_ns":232256012185666,"payload":{"event_type":"price_change","market":"0x3b40066b5cf3871a2f6237c5628bd8092a206aa998558ac5ec13c4483e31e160","price_changes":[{"asset_id":"110216635572655435074987471276357323571387854733835379371586402147734167783946","best_ask":"0.5","best_bid":"0.49","hash":"e84105f3b3fb6d12677d3eef0cdc7bab7c8b05ba","price":"0.39","side":"BUY","size":"116"},{"asset_id":"14766054693214075530629349735273995982307625376442606753688071083149620216746","best_ask":"0.51","best_bid":"0.5","hash":"2655b69e06360fb7e9214d5320405b09029fff4d","price":"0.61","side":"SELL","size":"116"}],"timestamp":"1785130272802"},"payload_hash":"0ad677a213fb218fb3f4ceda2faa1ec473517a886121c6405f8c2e83a77653b1","raw_frame":"{\"market\":\"0x3b40066b5cf3871a2f6237c5628bd8092a206aa998558ac5ec13c4483e31e160\", \"price_changes\":[{\"asset_id\":\"110216635572655435074987471276357323571387854733835379371586402147734167783946\", \"price\":\"0.39\", \"size\":\"116\", \"side\":\"BUY\", \"hash\":\"e84105f3b3fb6d12677d3eef0cdc7bab7c8b05ba\", \"best_bid\":\"0.49\", \"best_ask\":\"0.5\"}, {\"asset_id\":\"14766054693214075530629349735273995982307625376442606753688071083149620216746\", \"price\":\"0.61\", \"size\":\"116\", \"side\":\"SELL\", \"hash\":\"2655b69e06360fb7e9214d5320405b09029fff4d\", \"best_bid\":\"0.5\", \"best_ask\":\"0.51\"}], \"timestamp\":\"1785130272802\", \"event_type\":\"price_change\"}","received_at":"2026-07-27T05:31:12.774481Z","schema_version":"clob-market-ws.price_change.v1","sequence":null,"server_hash":null,"server_timestamp":"1785130272802","session_id":"502006c5cfcd437296561ea750c9ec8b","source":"clob_market_ws"},"received_at":"2026-07-27T05:31:12.774481Z","record_id":"5502f56d1af8f13563264b045801ab27baf21046b50e03263a6b96fcec534159","schema_fingerprint":"4aa3821a28b0b7c2400bc59aba4bcc0a76e971dadd19610d3ad38c768e124dc7","schema_version":"edge-lab-recorder.raw.v1","sequence":null,"source":"clob_market_ws"}
{"event_at":"2026-07-27T05:31:12.810000Z","event_fingerprint":"a8905e4ff3de68aca279baca179579e3430025c206a8661bfe4244e9154f7291","payload":{"connection_id":"efc69d3132f1467b8e898a382b23ac0d","event_at":"2026-07-27T05:31:12.810000Z","event_type":"price_change","frame_hash":"b11296885faf4754fefa2bd98991e16edc628ed949db1424a10a0ce0dd144876","frame_index":0,"kind":"data","monotonic_ns":232256015934458,"payload":{"event_type":"price_change","market":"0x3b40066b5cf3871a2f6237c5628bd8092a206aa998558ac5ec13c4483e31e160","price_changes":[{"asset_id":"110216635572655435074987471276357323571387854733835379371586402147734167783946","best_ask":"0.5","best_bid":"0.49","hash":"3bc418eaf9c9a53575191f08c9f6d87cf9f93562","price":"0.39","side":"BUY","size":"134"},{"asset_id":"14766054693214075530629349735273995982307625376442606753688071083149620216746","best_ask":"0.51","best_bid":"0.5","hash":"8b1d7782fc67fc6f36b4b17c8f97148ccbab0a0a","price":"0.61","side":"SELL","size":"134"}],"timestamp":"1785130272810"},"payload_hash":"4a13453f6abd087c613eb5241ff353e932db4fbddeba0fca3815cd929714ef72","raw_frame":"{\"market\":\"0x3b40066b5cf3871a2f6237c5628bd8092a206aa998558ac5ec13c4483e31e160\", \"price_changes\":[{\"asset_id\":\"110216635572655435074987471276357323571387854733835379371586402147734167783946\", \"price\":\"0.39\", \"size\":\"134\", \"side\":\"BUY\", \"hash\":\"3bc418eaf9c9a53575191f08c9f6d87cf9f93562\", \"best_bid\":\"0.49\", \"best_ask\":\"0.5\"}, {\"asset_id\":\"14766054693214075530629349735273995982307625376442606753688071083149620216746\", \"price\":\"0.61\", \"size\":\"134\", \"side\":\"SELL\", \"hash\":\"8b1d7782fc67fc6f36b4b17c8f97148ccbab0a0a\", \"best_bid\":\"0.5\", \"best_ask\":\"0.51\"}], \"timestamp\":\"1785130272810\", \"event_type\":\"price_change\"}","received_at":"2026-07-27T05:31:12.778231Z","schema_version":"clob-market-ws.price_change.v1","sequence":null,"server_hash":null,"server_timestamp":"1785130272810","session_id":"502006c5cfcd437296561ea750c9ec8b","source":"clob_market_ws"},"received_at":"2026-07-27T05:31:12.778231Z","record_id":"f53f59c8b55d0b851d271dcd89ee5142b4cd1191a6e4c1e67c8fa96a550e6429","schema_fingerprint":"4aa3821a28b0b7c2400bc59aba4bcc0a76e971dadd19610d3ad38c768e124dc7","schema_version":"edge-lab-recorder.raw.v1","sequence":null,"source":"clob_market_ws"}
{"event_at":"2026-07-27T05:31:12.811000Z","event_fingerprint":"bef2129e6065000c47a39641badb2d8c754d5e2fde221a2a097b899706712e37","payload":{"connection_id":"efc69d3132f1467b8e898a382b23ac0d","event_at":"2026-07-27T05:31:12.811000Z","event_type":"price_change","frame_hash":"24f15ff618abd126372ad834966a954a696287074b080b6c424f793078f871e2","frame_index":0,"kind":"data","monotonic_ns":232256018529666,"payload":{"event_type":"price_change","market":"0x3b40066b5cf3871a2f6237c5628bd8092a206aa998558ac5ec13c4483e31e160","price_changes":[{"asset_id":"14766054693214075530629349735273995982307625376442606753688071083149620216746","best_ask":"0.51","best_bid":"0.5","hash":"d8baef156ae7e2565eae44a3e4914eacfcdc9111","price":"0.04","side":"BUY","size":"658.09"},{"asset_id":"110216635572655435074987471276357323571387854733835379371586402147734167783946","best_ask":"0.5","best_bid":"0.49","hash":"f1f7f44512f0f9d0a00a4462d4dfa3f57029b2a0","price":"0.96","side":"SELL","size":"658.09"}],"timestamp":"1785130272811"},"payload_hash":"b3b6de29ac4adc59837c818009cf59c0a500f5ec5f4f8045a46777c83a196f1f","raw_frame":"{\"market\":\"0x3b40066b5cf3871a2f6237c5628bd8092a206aa998558ac5ec13c4483e31e160\", \"price_changes\":[{\"asset_id\":\"14766054693214075530629349735273995982307625376442606753688071083149620216746\", \"price\":\"0.04\", \"size\":\"658.09\", \"side\":\"BUY\", \"hash\":\"d8baef156ae7e2565eae44a3e4914eacfcdc9111\", \"best_bid\":\"0.5\", \"best_ask\":\"0.51\"}, {\"asset_id\":\"110216635572655435074987471276357323571387854733835379371586402147734167783946\", \"price\":\"0.96\", \"size\":\"658.09\", \"side\":\"SELL\", \"hash\":\"f1f7f44512f0f9d0a00a4462d4dfa3f57029b2a0\", \"best_bid\":\"0.49\", \"best_ask\":\"0.5\"}], \"timestamp\":\"1785130272811\", \"event_type\":\"price_change\"}","received_at":"2026-07-27T05:31:12.780832Z","schema_version":"clob-market-ws.price_change.v1","sequence":null,"server_hash":null,"server_timestamp":"1785130272811","session_id":"502006c5cfcd437296561ea750c9ec8b","source":"clob_market_ws"},"received_at":"2026-07-27T05:31:12.780832Z","record_id":"cb12d074b211cfb9825c09aedf48190f3eb3538ec054b1eb787ab2d8055c5709","schema_fingerprint":"4aa3821a28b0b7c2400bc59aba4bcc0a76e971dadd19610d3ad38c768e124dc7","schema_version":"edge-lab-recorder.raw.v1","sequence":null,"source":"clob_market_ws"}
{"event_at":"2026-07-27T05:31:12.816000Z","event_fingerprint":"3d0113db70a3e9745e1c25bc3c7610ca808461ab6166838ab23d03527f38d743","payload":{"connection_id":"efc69d3132f1467b8e898a382b23ac0d","event_at":"2026-07-27T05:31:12.816000Z","event_type":"price_change","frame_hash":"2444a551169377d9ea997d0a4452345484d5a142b59ffde025e409a2bf3b3fe7","frame_index":0,"kind":"data","monotonic_ns":232256022082250,"payload":{"event_type":"price_change","market":"0x3b40066b5cf3871a2f6237c5628bd8092a206aa998558ac5ec13c4483e31e160","price_changes":[{"asset_id":"110216635572655435074987471276357323571387854733835379371586402147734167783946","best_ask":"0.5","best_bid":"0.49","hash":"e6d4a876a7ff42563842f3e4632b203e1ed0693b","price":"0.39","side":"BUY","size":"164"},{"asset_id":"14766054693214075530629349735273995982307625376442606753688071083149620216746","best_ask":"0.51","best_bid":"0.5","hash":"25d80caa0f7edda0459f082032a6ee4d53fcacba","price":"0.61","side":"SELL","size":"164"}],"timestamp":"1785130272816"},"payload_hash":"81f7eb7544017f1c3921eeca73c3e963368c68c3a26988d7e2c7277f8d35fab5","raw_frame":"{\"market\":\"0x3b40066b5cf3871a2f6237c5628bd8092a206aa998558ac5ec13c4483e31e160\", \"price_changes\":[{\"asset_id\":\"110216635572655435074987471276357323571387854733835379371586402147734167783946\", \"price\":\"0.39\", \"size\":\"164\", \"side\":\"BUY\", \"hash\":\"e6d4a876a7ff42563842f3e4632b203e1ed0693b\", \"best_bid\":\"0.49\", \"best_ask\":\"0.5\"}, {\"asset_id\":\"14766054693214075530629349735273995982307625376442606753688071083149620216746\", \"price\":\"0.61\", \"size\":\"164\", \"side\":\"SELL\", \"hash\":\"25d80caa0f7edda0459f082032a6ee4d53fcacba\", \"best_bid\":\"0.5\", \"best_ask\":\"0.51\"}], \"timestamp\":\"1785130272816\", \"event_type\":\"price_change\"}","received_at":"2026-07-27T05:31:12.784378Z","schema_version":"clob-market-ws.price_change.v1","sequence":null,"server_hash":null,"server_timestamp":"1785130272816","session_id":"502006c5cfcd437296561ea750c9ec8b","source":"clob_market_ws"},"received_at":"2026-07-27T05:31:12.784378Z","record_id":"682bfb6a4ffb53aa92832026ac0a9638b62943b795b672cea2f92de46a8257c7","schema_fingerprint":"4aa3821a28b0b7c2400bc59aba4bcc0a76e971dadd19610d3ad38c768e124dc7","schema_version":"edge-lab-recorder.raw.v1","sequence":null,"source":"clob_market_ws"}
{"event_at":"2026-07-27T05:31:12.822000Z","event_fingerprint":"9956e775492dff1e476d86aa174566e2e762a500d1896fab777ef3b7fd23d947","payload":{"connection_id":"efc69d3132f1467b8e898a382b23ac0d","event_at":"2026-07-27T05:31:12.822000Z","event_type":"price_change","frame_hash":"ed3d245257157acaef05aad4fc1b8db1d4c38c1ff86acf7dcc9024031961bfb3","frame_index":0,"kind":"data","monotonic_ns":232256025089166,"payload":{"event_type":"price_change","market":"0x3b40066b5cf3871a2f6237c5628bd8092a206aa998558ac5ec13c4483e31e160","price_changes":[{"asset_id":"110216635572655435074987471276357323571387854733835379371586402147734167783946","best_ask":"0.5","best_bid":"0.49","hash":"38b969b203dbbe3afe44ca67cc63132a3b3a1d2d","price":"0.44","side":"BUY","size":"57.19"},{"asset_id":"14766054693214075530629349735273995982307625376442606753688071083149620216746","best_ask":"0.51","best_bid":"0.5","hash":"2f748451d7ee2934cdc5567b35262b8a8a867074","price":"0.56","side":"SELL","size":"57.19"}],"timestamp":"1785130272822"},"payload_hash":"962cb1d6610e018a1e411957ac0d86a0956506bc73d45e137634741001e2b00c","raw_frame":"{\"market\":\"0x3b40066b5cf3871a2f6237c5628bd8092a206aa998558ac5ec13c4483e31e160\", \"price_changes\":[{\"asset_id\":\"110216635572655435074987471276357323571387854733835379371586402147734167783946\", \"price\":\"0.44\", \"size\":\"57.19\", \"side\":\"BUY\", \"hash\":\"38b969b203dbbe3afe44ca67cc63132a3b3a1d2d\", \"best_bid\":\"0.49\", \"best_ask\":\"0.5\"}, {\"asset_id\":\"14766054693214075530629349735273995982307625376442606753688071083149620216746\", \"price\":\"0.56\", \"size\":\"57.19\", \"side\":\"SELL\", \"hash\":\"2f748451d7ee2934cdc5567b35262b8a8a867074\", \"best_bid\":\"0.5\", \"best_ask\":\"0.51\"}], \"timestamp\":\"1785130272822\", \"event_type\":\"price_change\"}","received_at":"2026-07-27T05:31:12.787385Z","schema_version":"clob-market-ws.price_change.v1","sequence":null,"server_hash":null,"server_timestamp":"1785130272822","session_id":"502006c5cfcd437296561ea750c9ec8b","source":"clob_market_ws"},"received_at":"2026-07-27T05:31:12.787385Z","record_id":"2fbfa6c7d942169e7369086c437289b9a219db20df724e7a2768e0237c614101","schema_fingerprint":"4aa3821a28b0b7c2400bc59aba4bcc0a76e971dadd19610d3ad38c768e124dc7","schema_version":"edge-lab-recorder.raw.v1","sequence":null,"source":"clob_market_ws"}
{"event_at":"2026-07-27T05:31:12.824000Z","event_fingerprint":"64c24940ed1c76b78b9c94643f822a323a6ae8d31be6762f687e766b7e2d2b86","payload":{"connection_id":"efc69d3132f1467b8e898a382b23ac0d","event_at":"2026-07-27T05:31:12.824000Z","event_type":"price_change","frame_hash":"8958d2c1f488000801ddeb6e8dceed864db4a554e438ccbf4d81fe4935ed0210","frame_index":0,"kind":"data","monotonic_ns":232256029481208,"payload":{"event_type":"price_change","market":"0x3b40066b5cf3871a2f6237c5628bd8092a206aa998558ac5ec13c4483e31e160","price_changes":[{"asset_id":"14766054693214075530629349735273995982307625376442606753688071083149620216746","best_ask":"0.51","best_bid":"0.5","hash":"f547672798c4916f7135acdfb23448e96cd0ed40","price":"0.01","side":"BUY","size":"7878.02"},{"asset_id":"110216635572655435074987471276357323571387854733835379371586402147734167783946","best_ask":"0.5","best_bid":"0.49","hash":"78fcd5a953c4285f0fa4292ad0f419673019874e","price":"0.99","side":"SELL","size":"7878.02"}],"timestamp":"1785130272824"},"payload_hash":"edc02d2dbc9448a0e96055c216923ee3ef536b957a16a16711a2b42c22f12ba8","raw_frame":"{\"market\":\"0x3b40066b5cf3871a2f6237c5628bd8092a206aa998558ac5ec13c4483e31e160\", \"price_changes\":[{\"asset_id\":\"14766054693214075530629349735273995982307625376442606753688071083149620216746\", \"price\":\"0.01\", \"size\":\"7878.02\", \"side\":\"BUY\", \"hash\":\"f547672798c4916f7135acdfb23448e96cd0ed40\", \"best_bid\":\"0.5\", \"best_ask\":\"0.51\"}, {\"asset_id\":\"110216635572655435074987471276357323571387854733835379371586402147734167783946\", \"price\":\"0.99\", \"size\":\"7878.02\", \"side\":\"SELL\", \"hash\":\"78fcd5a953c4285f0fa4292ad0f419673019874e\", \"best_bid\":\"0.49\", \"best_ask\":\"0.5\"}], \"timestamp\":\"1785130272824\", \"event_type\":\"price_change\"}","received_at":"2026-07-27T05:31:12.791778Z","schema_version":"clob-market-ws.price_change.v1","sequence":null,"server_hash":null,"server_timestamp":"1785130272824","session_id":"502006c5cfcd437296561ea750c9ec8b","source":"clob_market_ws"},"received_at":"2026-07-27T05:31:12.791778Z","record_id":"7b29bca6e046cf291dcd3a701dcd10f7b98f1ba51e247b656ff481c963bd9e94","schema_fingerprint":"4aa3821a28b0b7c2400bc59aba4bcc0a76e971dadd19610d3ad38c768e124dc7","schema_version":"edge-lab-recorder.raw.v1","sequence":null,"source":"clob_market_ws"}
{"event_at":"2026-07-27T05:31:12.842000Z","event_fingerprint":"86c3b335c408651c716fec079e7eca3d4a7524ce7f0cc905cc36cd4aae6cd3a8","payload":{"connection_id":"efc69d3132f1467b8e898a382b23ac0d","event_at":"2026-07-27T05:31:12.842000Z","event_type":"price_change","frame_hash":"60fd2a45abb60e86346a3f73a6709852cde4b93dde95f3e104593b2387cc949f","frame_index":0,"kind":"data","monotonic_ns":232256040700666,"payload":{"event_type":"price_change","market":"0x3b40066b5cf3871a2f6237c5628bd8092a206aa998558ac5ec13c4483e31e160","price_changes":[{"asset_id":"14766054693214075530629349735273995982307625376442606753688071083149620216746","best_ask":"0.51","best_bid":"0.5","hash":"2260604028c0526402616c0b6d3ff9049f88e4a1","price":"0.48","side":"BUY","size":"47.62"},{"asset_id":"110216635572655435074987471276357323571387854733835379371586402147734167783946","best_ask":"0.5","best_bid":"0.49","hash":"f8fbe68e99da05eba39c2c271dff2746b70aa7b8","price":"0.52","side":"SELL","size":"47.62"}],"timestamp":"1785130272842"},"payload_hash":"85b88c77c6e9bda752616ef8137140af48b7c055286fb48af6ebed98de4f104a","raw_frame":"{\"market\":\"0x3b40066b5cf3871a2f6237c5628bd8092a206aa998558ac5ec13c4483e31e160\", \"price_changes\":[{\"asset_id\":\"14766054693214075530629349735273995982307625376442606753688071083149620216746\", \"price\":\"0.48\", \"size\":\"47.62\", \"side\":\"BUY\", \"hash\":\"2260604028c0526402616c0b6d3ff9049f88e4a1\", \"best_bid\":\"0.5\", \"best_ask\":\"0.51\"}, {\"asset_id\":\"110216635572655435074987471276357323571387854733835379371586402147734167783946\", \"price\":\"0.52\", \"size\":\"47.62\", \"side\":\"SELL\", \"hash\":\"f8fbe68e99da05eba39c2c271dff2746b70aa7b8\", \"best_bid\":\"0.49\", \"best_ask\":\"0.5\"}], \"timestamp\":\"1785130272842\", \"event_type\":\"price_change\"}","received_at":"2026-07-27T05:31:12.802997Z","schema_version":"clob-market-ws.price_change.v1","sequence":null,"server_hash":null,"server_timestamp":"1785130272842","session_id":"502006c5cfcd437296561ea750c9ec8b","source":"clob_market_ws"},"received_at":"2026-07-27T05:31:12.802997Z","record_id":"e822514cadb9fbac3efc4df8676fbff34c0ce8e109df31430d0f0bca5f3e321a","schema_fingerprint":"4aa3821a28b0b7c2400bc59aba4bcc0a76e971dadd19610d3ad38c768e124dc7","schema_version":"edge-lab-recorder.raw.v1","sequence":null,"source":"clob_market_ws"}
{"event_at":"2026-07-27T05:31:12.845000Z","event_fingerprint":"488849ca1905bed755ba0b171cebbab9dcdd5c231bacaec10f69159c30c9ff3e","payload":{"connection_id":"efc69d3132f1467b8e898a382b23ac0d","event_at":"2026-07-27T05:31:12.845000Z","event_type":"price_change","frame_hash":"af8441d251f5e61a7e131f7a3a51e81a8427854c65a33b043fd8e559d0c00f30","frame_index":0,"kind":"data","monotonic_ns":232256045333208,"payload":{"event_type":"price_change","market":"0x3b40066b5cf3871a2f6237c5628bd8092a206aa998558ac5ec13c4483e31e160","price_changes":[{"asset_id":"14766054693214075530629349735273995982307625376442606753688071083149620216746","best_ask":"0.51","best_bid":"0.5","hash":"e3027e722d457db1c4346760136f7a98164398df","price":"0.48","side":"BUY","size":"36.62"},{"asset_id":"110216635572655435074987471276357323571387854733835379371586402147734167783946","best_ask":"0.5","best_bid":"0.49","hash":"bfc9fdbb6a531af619638a608b712750c64c1aba","price":"0.52","side":"SELL","size":"36.62"}],"timestamp":"1785130272845"},"payload_hash":"eb25714a2cc9342aa6b3399b7a7a9a60a42961cb14597d504581e46116a3305d","raw_frame":"{\"market\":\"0x3b40066b5cf3871a2f6237c5628bd8092a206aa998558ac5ec13c4483e31e160\", \"price_changes\":[{\"asset_id\":\"14766054693214075530629349735273995982307625376442606753688071083149620216746\", \"price\":\"0.48\", \"size\":\"36.62\", \"side\":\"BUY\", \"hash\":\"e3027e722d457db1c4346760136f7a98164398df\", \"best_bid\":\"0.5\", \"best_ask\":\"0.51\"}, {\"asset_id\":\"110216635572655435074987471276357323571387854733835379371586402147734167783946\", \"price\":\"0.52\", \"size\":\"36.62\", \"side\":\"SELL\", \"hash\":\"bfc9fdbb6a531af619638a608b712750c64c1aba\", \"best_bid\":\"0.49\", \"best_ask\":\"0.5\"}], \"timestamp\":\"1785130272845\", \"event_type\":\"price_change\"}","received_at":"2026-07-27T05:31:12.807627Z","schema_version":"clob-market-ws.price_change.v1","sequence":null,"server_hash":null,"server_timestamp":"1785130272845","session_id":"502006c5cfcd437296561ea750c9ec8b","source":"clob_market_ws"},"received_at":"2026-07-27T05:31:12.807627Z","record_id":"cfca1a765e2210a3166e727646d58e3cffd33b548e1be5a277e244043e3af481","schema_fingerprint":"4aa3821a28b0b7c2400bc59aba4bcc0a76e971dadd19610d3ad38c768e124dc7","schema_version":"edge-lab-recorder.raw.v1","sequence":null,"source":"clob_market_ws"}
{"event_at":"2026-07-27T05:31:12.851000Z","event_fingerprint":"b4fbbbf0ea57d882628c7f10e5e24048298e074793edb57783ae480c1a502de2","payload":{"connection_id":"efc69d3132f1467b8e898a382b23ac0d","event_at":"2026-07-27T05:31:12.851000Z","event_type":"price_change","frame_hash":"824e067cad48dd1cec20177f5c749c5fc005e5f13bdca707b9f2c802b7eb822c","frame_index":0,"kind":"data","monotonic_ns":232256057237416,"payload":{"event_type":"price_change","market":"0x3b40066b5cf3871a2f6237c5628bd8092a206aa998558ac5ec13c4483e31e160","price_changes":[{"asset_id":"14766054693214075530629349735273995982307625376442606753688071083149620216746","best_ask":"0.51","best_bid":"0.5","hash":"af7d85708325cbe1afd8b5e3277875603c3484dd","price":"0.01","side":"BUY","size":"7873.02"},{"asset_id":"110216635572655435074987471276357323571387854733835379371586402147734167783946","best_ask":"0.5","best_bid":"0.49","hash":"17d6c7a774cc5eaf374642f94ba2f97b610b1d40","price":"0.99","side":"SELL","size":"7873.02"}],"timestamp":"1785130272851"},"payload_hash":"fb18ec7aad479cf09248c3f3eb1ee04a0f98e99b9e37e4b72225d45f5fdd0f72","raw_frame":"{\"market\":\"0x3b40066b5cf3871a2f6237c5628bd8092a206aa998558ac5ec13c4483e31e160\", \"price_changes\":[{\"asset_id\":\"14766054693214075530629349735273995982307625376442606753688071083149620216746\", \"price\":\"0.01\", \"size\":\"7873.02\", \"side\":\"BUY\", \"hash\":\"af7d85708325cbe1afd8b5e3277875603c3484dd\", \"best_bid\":\"0.5\", \"best_ask\":\"0.51\"}, {\"asset_id\":\"110216635572655435074987471276357323571387854733835379371586402147734167783946\", \"price\":\"0.99\", \"size\":\"7873.02\", \"side\":\"SELL\", \"hash\":\"17d6c7a774cc5eaf374642f94ba2f97b610b1d40\", \"best_bid\":\"0.49\", \"best_ask\":\"0.5\"}], \"timestamp\":\"1785130272851\", \"event_type\":\"price_change\"}","received_at":"2026-07-27T05:31:12.819531Z","schema_version":"clob-market-ws.price_change.v1","sequence":null,"server_hash":null,"server_timestamp":"1785130272851","session_id":"502006c5cfcd437296561ea750c9ec8b","source":"clob_market_ws"},"received_at":"2026-07-27T05:31:12.819531Z","record_id":"c6f57576d72a38d414f7e41ec06836a2bb59aceecd28843346285e04ffd7f99b","schema_fingerprint":"4aa3821a28b0b7c2400bc59aba4bcc0a76e971dadd19610d3ad38c768e124dc7","schema_version":"edge-lab-recorder.raw.v1","sequence":null,"source":"clob_market_ws"}
{"event_at":"2026-07-27T05:31:12.860000Z","event_fingerprint":"16e131bbb2799c5e4dad20239de1abe7315e3e806759cbf88adf6f879d4c24e2","payload":{"connection_id":"efc69d3132f1467b8e898a382b23ac0d","event_at":"2026-07-27T05:31:12.860000Z","event_type":"price_change","frame_hash":"54783bb956397a2feabec749379f2cacc20c063255dc475d1370476c1c502742","frame_index":0,"kind":"data","monotonic_ns":232256061598291,"payload":{"event_type":"price_change","market":"0x3b40066b5cf3871a2f6237c5628bd8092a206aa998558ac5ec13c4483e31e160","price_changes":[{"asset_id":"110216635572655435074987471276357323571387854733835379371586402147734167783946","best_ask":"0.5","best_bid":"0.49","hash":"95a75ac3962ddba85f787dfdfa9712cacad9ec39","price":"0.44","side":"BUY","size":"68.19"},{"asset_id":"14766054693214075530629349735273995982307625376442606753688071083149620216746","best_ask":"0.51","best_bid":"0.5","hash":"c8add05f456700241f94fc2a5366cb132bf5b804","price":"0.56","side":"SELL","size":"68.19"}],"timestamp":"1785130272860"},"payload_hash":"f21b9b7460919311450eba520985f7a206144804968b995b687495aafcb67107","raw_frame":"{\"market\":\"0x3b40066b5cf3871a2f6237c5628bd8092a206aa998558ac5ec13c4483e31e160\", \"price_changes\":[{\"asset_id\":\"110216635572655435074987471276357323571387854733835379371586402147734167783946\", \"price\":\"0.44\", \"size\":\"68.19\", \"side\":\"BUY\", \"hash\":\"95a75ac3962ddba85f787dfdfa9712cacad9ec39\", \"best_bid\":\"0.49\", \"best_ask\":\"0.5\"}, {\"asset_id\":\"14766054693214075530629349735273995982307625376442606753688071083149620216746\", \"price\":\"0.56\", \"size\":\"68.19\", \"side\":\"SELL\", \"hash\":\"c8add05f456700241f94fc2a5366cb132bf5b804\", \"best_bid\":\"0.5\", \"best_ask\":\"0.51\"}], \"timestamp\":\"1785130272860\", \"event_type\":\"price_change\"}","received_at":"2026-07-27T05:31:12.823895Z","schema_version":"clob-market-ws.price_change.v1","sequence":null,"server_hash":null,"server_timestamp":"1785130272860","session_id":"502006c5cfcd437296561ea750c9ec8b","source":"clob_market_ws"},"received_at":"2026-07-27T05:31:12.823895Z","record_id":"97299fc753c57600ddd46c3baa9b4cf7c615abe4c20b34bf2bf71989bae349e6","schema_fingerprint":"4aa3821a28b0b7c2400bc59aba4bcc0a76e971dadd19610d3ad38c768e124dc7","schema_version":"edge-lab-recorder.raw.v1","sequence":null,"source":"clob_market_ws"}
{"event_at":"2026-07-27T05:31:12.863000Z","event_fingerprint":"aa6960fec0840f24c6bf375c4addcd7d40e6aa0bd3137b5b5a6238cafa003cdc","payload":{"connection_id":"efc69d3132f1467b8e898a382b23ac0d","event_at":"2026-07-27T05:31:12.863000Z","event_type":"price_change","frame_hash":"bed37b4add5bc3661072321fb96cddee684c908a43bf434ac375959f34f9907e","frame_index":0,"kind":"data","monotonic_ns":232256067551666,"payload":{"event_type":"price_change","market":"0x3b40066b5cf3871a2f6237c5628bd8092a206aa998558ac5ec13c4483e31e160","price_changes":[{"asset_id":"110216635572655435074987471276357323571387854733835379371586402147734167783946","best_ask":"0.5","best_bid":"0.49","hash":"437b600ff83acd270ea9ff61b3456edbaafa0ff9","price":"0.33","side":"BUY","size":"390.63"},{"asset_id":"14766054693214075530629349735273995982307625376442606753688071083149620216746","best_ask":"0.51","best_bid":"0.5","hash":"9df3557c11bbda8ce598a576e0b90056845835c7","price":"0.67","side":"SELL","size":"390.63"}],"timestamp":"1785130272863"},"payload_hash":"d7b82616f92e975ddca355e9cffab979d1b7de47a2190713620eaabfbec465fb","raw_frame":"{\"market\":\"0x3b40066b5cf3871a2f6237c5628bd8092a206aa998558ac5ec13c4483e31e160\", \"price_changes\":[{\"asset_id\":\"110216635572655435074987471276357323571387854733835379371586402147734167783946\", \"price\":\"0.33\", \"size\":\"390.63\", \"side\":\"BUY\", \"hash\":\"437b600ff83acd270ea9ff61b3456edbaafa0ff9\", \"best_bid\":\"0.49\", \"best_ask\":\"0.5\"}, {\"asset_id\":\"14766054693214075530629349735273995982307625376442606753688071083149620216746\", \"price\":\"0.67\", \"size\":\"390.63\", \"side\":\"SELL\", \"hash\":\"9df3557c11bbda8ce598a576e0b90056845835c7\", \"best_bid\":\"0.5\", \"best_ask\":\"0.51\"}], \"timestamp\":\"1785130272863\", \"event_type\":\"price_change\"}","received_at":"2026-07-27T05:31:12.829848Z","schema_version":"clob-market-ws.price_change.v1","sequence":null,"server_hash":null,"server_timestamp":"1785130272863","session_id":"502006c5cfcd437296561ea750c9ec8b","source":"clob_market_ws"},"received_at":"2026-07-27T05:31:12.829848Z","record_id":"dfff1e1a85db99dd90f8db40860217dc5b741016e2db9486a57ab0c85305e579","schema_fingerprint":"4aa3821a28b0b7c2400bc59aba4bcc0a76e971dadd19610d3ad38c768e124dc7","schema_version":"edge-lab-recorder.raw.v1","sequence":null,"source":"clob_market_ws"}
{"event_at":"2026-07-27T05:31:12.882000Z","event_fingerprint":"eb558e290c754cb32a1291eda8967296df2c9ff2789dc2a309b2cba20b8d5cb5","payload":{"connection_id":"efc69d3132f1467b8e898a382b23ac0d","event_at":"2026-07-27T05:31:12.882000Z","event_type":"price_change","frame_hash":"52806b66648173be936464fcb5d291ec2c5e9674e70f4b88c8555216d62dc495","frame_index":0,"kind":"data","monotonic_ns":232256082321750,"payload":{"event_type":"price_change","market":"0x3b40066b5cf3871a2f6237c5628bd8092a206aa998558ac5ec13c4483e31e160","price_changes":[{"asset_id":"110216635572655435074987471276357323571387854733835379371586402147734167783946","best_ask":"0.5","best_bid":"0.49","hash":"60eb9c1962ad4f499e68fc0bc810509a8a89b3e6","price":"0.44","side":"BUY","size":"57.19"},{"asset_id":"14766054693214075530629349735273995982307625376442606753688071083149620216746","best_ask":"0.51","best_bid":"0.5","hash":"08e27c65494a95ac32095210a8ba1a93c5ad4966","price":"0.56","side":"SELL","size":"57.19"}],"timestamp":"1785130272882"},"payload_hash":"8d0ea661af1ab6676bb2978c9b2a47d24d8cd15d0e5cdcd424e829f2a4dcef85","raw_frame":"{\"market\":\"0x3b40066b5cf3871a2f6237c5628bd8092a206aa998558ac5ec13c4483e31e160\", \"price_changes\":[{\"asset_id\":\"110216635572655435074987471276357323571387854733835379371586402147734167783946\", \"price\":\"0.44\", \"size\":\"57.19\", \"side\":\"BUY\", \"hash\":\"60eb9c1962ad4f499e68fc0bc810509a8a89b3e6\", \"best_bid\":\"0.49\", \"best_ask\":\"0.5\"}, {\"asset_id\":\"14766054693214075530629349735273995982307625376442606753688071083149620216746\", \"price\":\"0.56\", \"size\":\"57.19\", \"side\":\"SELL\", \"hash\":\"08e27c65494a95ac32095210a8ba1a93c5ad4966\", \"best_bid\":\"0.5\", \"best_ask\":\"0.51\"}], \"timestamp\":\"1785130272882\", \"event_type\":\"price_change\"}","received_at":"2026-07-27T05:31:12.844617Z","schema_version":"clob-market-ws.price_change.v1","sequence":null,"server_hash":null,"server_timestamp":"1785130272882","session_id":"502006c5cfcd437296561ea750c9ec8b","source":"clob_market_ws"},"received_at":"2026-07-27T05:31:12.844617Z","record_id":"fa1b325263ee516d13071cf7ba792dad50bf4aabe3fab933a881ac2bb899c659","schema_fingerprint":"4aa3821a28b0b7c2400bc59aba4bcc0a76e971dadd19610d3ad38c768e124dc7","schema_version":"edge-lab-recorder.raw.v1","sequence":null,"source":"clob_market_ws"}
{"event_at":"2026-07-27T05:31:12.885000Z","event_fingerprint":"72898fd7dc3741918e18dbf9e283593cfc71a62244370030907b738a45537473","payload":{"connection_id":"efc69d3132f1467b8e898a382b23ac0d","event_at":"2026-07-27T05:31:12.885000Z","event_type":"price_change","frame_hash":"d14478dd0c95b34dff59dcf877f71698cbd399917d61502d8428065b8ba112f7","frame_index":0,"kind":"data","monotonic_ns":232256085768708,"payload":{"event_type":"price_change","market":"0x3b40066b5cf3871a2f6237c5628bd8092a206aa998558ac5ec13c4483e31e160","price_changes":[{"asset_id":"110216635572655435074987471276357323571387854733835379371586402147734167783946","best_ask":"0.5","best_bid":"0.49","hash":"952f204de2fd68493ea482ef151ad151e87c7acb","price":"0.48","side":"BUY","size":"52.6"},{"asset_id":"14766054693214075530629349735273995982307625376442606753688071083149620216746","best_ask":"0.51","best_bid":"0.5","hash":"5dc7ea6f0c1f64a8ec85bec1bf32813e225710c5","price":"0.52","side":"SELL","size":"52.6"}],"timestamp":"1785130272885"},"payload_hash":"40ce556f82956b3e7299031c3071bdb1c4a99dbf71cf1cbdd4a54c93cbbb46d3","raw_frame":"{\"market\":\"0x3b40066b5cf3871a2f6237c5628bd8092a206aa998558ac5ec13c4483e31e160\", \"price_changes\":[{\"asset_id\":\"110216635572655435074987471276357323571387854733835379371586402147734167783946\", \"price\":\"0.48\", \"size\":\"52.6\", \"side\":\"BUY\", \"hash\":\"952f204de2fd68493ea482ef151ad151e87c7acb\", \"best_bid\":\"0.49\", \"best_ask\":\"0.5\"}, {\"asset_id\":\"14766054693214075530629349735273995982307625376442606753688071083149620216746\", \"price\":\"0.52\", \"size\":\"52.6\", \"side\":\"SELL\", \"hash\":\"5dc7ea6f0c1f64a8ec85bec1bf32813e225710c5\", \"best_bid\":\"0.5\", \"best_ask\":\"0.51\"}], \"timestamp\":\"1785130272885\", \"event_type\":\"price_change\"}","received_at":"2026-07-27T05:31:12.848071Z","schema_version":"clob-market-ws.price_change.v1","sequence":null,"server_hash":null,"server_timestamp":"1785130272885","session_id":"502006c5cfcd437296561ea750c9ec8b","source":"clob_market_ws"},"received_at":"2026-07-27T05:31:12.848071Z","record_id":"cf78a006f2214323deecb9c18da05b085679a7cd5ef887611ee4d89d5d03da98","schema_fingerprint":"4aa3821a28b0b7c2400bc59aba4bcc0a76e971dadd19610d3ad38c768e124dc7","schema_version":"edge-lab-recorder.raw.v1","sequence":null,"source":"clob_market_ws"}
{"event_at":"2026-07-27T05:31:12.889000Z","event_fingerprint":"0981b54b86711b68ae11376a995f169636da03eb4cbda25935906af3b2267b72","payload":{"connection_id":"efc69d3132f1467b8e898a382b23ac0d","event_at":"2026-07-27T05:31:12.889000Z","event_type":"price_change","frame_hash":"386d0da5080159736d2125aef44fddd8b2f6bffa64c99d81a4e106756b81bb14","frame_index":0,"kind":"data","monotonic_ns":232256094726375,"payload":{"event_type":"price_change","market":"0x3b40066b5cf3871a2f6237c5628bd8092a206aa998558ac5ec13c4483e31e160","price_changes":[{"asset_id":"14766054693214075530629349735273995982307625376442606753688071083149620216746","best_ask":"0.51","best_bid":"0.5","hash":"d11d61e8df600268f3522e8dec2d2a9e615c26d5","price":"0.52","side":"SELL","size":"59.6"},{"asset_id":"110216635572655435074987471276357323571387854733835379371586402147734167783946","best_ask":"0.5","best_bid":"0.49","hash":"9730e09cbcd8edc7d98752a4460f44b63892382a","price":"0.48","side":"BUY","size":"59.6"}],"timestamp":"1785130272889"},"payload_hash":"f3b1d570dda474d60f69f1db10eb8b49cc9a50ce936998d5e5646114ff3ac3d7","raw_frame":"{\"market\":\"0x3b40066b5cf3871a2f6237c5628bd8092a206aa998558ac5ec13c4483e31e160\", \"price_changes\":[{\"asset_id\":\"14766054693214075530629349735273995982307625376442606753688071083149620216746\", \"price\":\"0.52\", \"size\":\"59.6\", \"side\":\"SELL\", \"hash\":\"d11d61e8df600268f3522e8dec2d2a9e615c26d5\", \"best_bid\":\"0.5\", \"best_ask\":\"0.51\"}, {\"asset_id\":\"110216635572655435074987471276357323571387854733835379371586402147734167783946\", \"price\":\"0.48\", \"size\":\"59.6\", \"side\":\"BUY\", \"hash\":\"9730e09cbcd8edc7d98752a4460f44b63892382a\", \"best_bid\":\"0.49\", \"best_ask\":\"0.5\"}], \"timestamp\":\"1785130272889\", \"event_type\":\"price_change\"}","received_at":"2026-07-27T05:31:12.857020Z","schema_version":"clob-market-ws.price_change.v1","sequence":null,"server_hash":null,"server_timestamp":"1785130272889","session_id":"502006c5cfcd437296561ea750c9ec8b","source":"clob_market_ws"},"received_at":"2026-07-27T05:31:12.857020Z","record_id":"4624959986ed3e325a6a95e8e43dc435485d23060586cb54fcbe2972ee8ea421","schema_fingerprint":"4aa3821a28b0b7c2400bc59aba4bcc0a76e971dadd19610d3ad38c768e124dc7","schema_version":"edge-lab-recorder.raw.v1","sequence":null,"source":"clob_market_ws"}
{"event_at":"2026-07-27T05:31:12.893000Z","event_fingerprint":"8c939b9398fc81acf60f2dd283b4c98db87a5a274c8e75f585decc5df964a281","payload":{"connection_id":"efc69d3132f1467b8e898a382b23ac0d","event_at":"2026-07-27T05:31:12.893000Z","event_type":"price_change","frame_hash":"cb9e272f2d7067d055487b7ac635d971098e4f57f83bc0b066fc4830018c53fb","frame_index":0,"kind":"data","monotonic_ns":232256099329041,"payload":{"event_type":"price_change","market":"0x3b40066b5cf3871a2f6237c5628bd8092a206aa998558ac5ec13c4483e31e160","price_changes":[{"asset_id":"110216635572655435074987471276357323571387854733835379371586402147734167783946","best_ask":"0.5","best_bid":"0.49","hash":"462539dd5119e52c04f691fd65f40f28366a83aa","price":"0.44","side":"BUY","size":"45"},{"asset_id":"14766054693214075530629349735273995982307625376442606753688071083149620216746","best_ask":"0.51","best_bid":"0.5","hash":"9e7c2c87b09e7b1574c112d7863ae7c5bf57bf9a","price":"0.56","side":"SELL","size":"45"}],"timestamp":"1785130272893"},"payload_hash":"1455a0239e6b8897a65a2c9bfd15299bc1c4dd89c350d76700652f8d1b075fbc","raw_frame":"{\"market\":\"0x3b40066b5cf3871a2f6237c5628bd8092a206aa998558ac5ec13c4483e31e160\", \"price_changes\":[{\"asset_id\":\"110216635572655435074987471276357323571387854733835379371586402147734167783946\", \"price\":\"0.44\", \"size\":\"45\", \"side\":\"BUY\", \"hash\":\"462539dd5119e52c04f691fd65f40f28366a83aa\", \"best_bid\":\"0.49\", \"best_ask\":\"0.5\"}, {\"asset_id\":\"14766054693214075530629349735273995982307625376442606753688071083149620216746\", \"price\":\"0.56\", \"size\":\"45\", \"side\":\"SELL\", \"hash\":\"9e7c2c87b09e7b1574c112d7863ae7c5bf57bf9a\", \"best_bid\":\"0.5\", \"best_ask\":\"0.51\"}], \"timestamp\":\"1785130272893\", \"event_type\":\"price_change\"}","received_at":"2026-07-27T05:31:12.861625Z","schema_version":"clob-market-ws.price_change.v1","sequence":null,"server_hash":null,"server_timestamp":"1785130272893","session_id":"502006c5cfcd437296561ea750c9ec8b","source":"clob_market_ws"},"received_at":"2026-07-27T05:31:12.861625Z","record_id":"84765d6924717fe6359d4f1b962ad1cb68087ad6a7d67ca539d3f55003a7efe3","schema_fingerprint":"4aa3821a28b0b7c2400bc59aba4bcc0a76e971dadd19610d3ad38c768e124dc7","schema_version":"edge-lab-recorder.raw.v1","sequence":null,"source":"clob_market_ws"}
{"event_at":"2026-07-27T05:31:12.897000Z","event_fingerprint":"e0eb7a8f49661bc7c9e6be3a9240fa30c976d9b3d5668f5d389f5864c33d24fb","payload":{"connection_id":"efc69d3132f1467b8e898a382b23ac0d","event_at":"2026-07-27T05:31:12.897000Z","event_type":"price_change","frame_hash":"44ee3b545e0fdff73570e55e9bd477a69d812422736120e69f5cf766003c860c","frame_index":0,"kind":"data","monotonic_ns":232256102048333,"payload":{"event_type":"price_change","market":"0x3b40066b5cf3871a2f6237c5628bd8092a206aa998558ac5ec13c4483e31e160","price_changes":[{"asset_id":"110216635572655435074987471276357323571387854733835379371586402147734167783946","best_ask":"0.5","best_bid":"0.49","hash":"cdca0bc3759a2d145bd218e6722297e1ecb29a2f","price":"0.42","side":"BUY","size":"92.32"},{"asset_id":"14766054693214075530629349735273995982307625376442606753688071083149620216746","best_ask":"0.51","best_bid":"0.5","hash":"afd4076b2d9cf1fff71b7799bffb7c96114daea9","price":"0.58","side":"SELL","size":"92.32"}],"timestamp":"1785130272897"},"payload_hash":"5ba4f5a4f892642da3195aaa238523ee7bff59b205cf332bc7a1cf7266b5c5cd","raw_frame":"{\"market\":\"0x3b40066b5cf3871a2f6237c5628bd8092a206aa998558ac5ec13c4483e31e160\", \"price_changes\":[{\"asset_id\":\"110216635572655435074987471276357323571387854733835379371586402147734167783946\", \"price\":\"0.42\", \"size\":\"92.32\", \"side\":\"BUY\", \"hash\":\"cdca0bc3759a2d145bd218e6722297e1ecb29a2f\", \"best_bid\":\"0.49\", \"best_ask\":\"0.5\"}, {\"asset_id\":\"14766054693214075530629349735273995982307625376442606753688071083149620216746\", \"price\":\"0.58\", \"size\":\"92.32\", \"side\":\"SELL\", \"hash\":\"afd4076b2d9cf1fff71b7799bffb7c96114daea9\", \"best_bid\":\"0.5\", \"best_ask\":\"0.51\"}], \"timestamp\":\"1785130272897\", \"event_type\":\"price_change\"}","received_at":"2026-07-27T05:31:12.864350Z","schema_version":"clob-market-ws.price_change.v1","sequence":null,"server_hash":null,"server_timestamp":"1785130272897","session_id":"502006c5cfcd437296561ea750c9ec8b","source":"clob_market_ws"},"received_at":"2026-07-27T05:31:12.864350Z","record_id":"d7bd2b8d5ba9c1ac1ff4c9867982bbc5e5ef28beb4648b839a233fcf29a56253","schema_fingerprint":"4aa3821a28b0b7c2400bc59aba4bcc0a76e971dadd19610d3ad38c768e124dc7","schema_version":"edge-lab-recorder.raw.v1","sequence":null,"source":"clob_market_ws"}
{"event_at":"2026-07-27T05:31:12.909000Z","event_fingerprint":"c9d8fc120a3a1df102f7fa4a8fafc156062c57378ba371068e740c57e88b0d52","payload":{"connection_id":"efc69d3132f1467b8e898a382b23ac0d","event_at":"2026-07-27T05:31:12.909000Z","event_type":"price_change","frame_hash":"d84279c39dc0b15c9d8ab1ee469a3229acbc22f9d5bd08aec69c1b35f65b2959","frame_index":0,"kind":"data","monotonic_ns":232256109175291,"payload":{"event_type":"price_change","market":"0x3b40066b5cf3871a2f6237c5628bd8092a206aa998558ac5ec13c4483e31e160","price_changes":[{"asset_id":"110216635572655435074987471276357323571387854733835379371586402147734167783946","best_ask":"0.5","best_bid":"0.49","hash":"592e41dd6ea4355da26431c0d10aaadc87c47f5c","price":"0.48","side":"BUY","size":"49.6"},{"asset_id":"14766054693214075530629349735273995982307625376442606753688071083149620216746","best_ask":"0.51","best_bid":"0.5","hash":"372a9806f4a02ce0a51d20a42e7b9a7ec6a5b16a","price":"0.52","side":"SELL","size":"49.6"}],"timestamp":"1785130272909"},"payload_hash":"c771c2baedba0fea3efdfe01920775fcd7f30989e270a9cacfffc5b8c7bf3d17","raw_frame":"{\"market\":\"0x3b40066b5cf3871a2f6237c5628bd8092a206aa998558ac5ec13c4483e31e160\", \"price_changes\":[{\"asset_id\":\"110216635572655435074987471276357323571387854733835379371586402147734167783946\", \"price\":\"0.48\", \"size\":\"49.6\", \"side\":\"BUY\", \"hash\":\"592e41dd6ea4355da26431c0d10aaadc87c47f5c\", \"best_bid\":\"0.49\", \"best_ask\":\"0.5\"}, {\"asset_id\":\"14766054693214075530629349735273995982307625376442606753688071083149620216746\", \"price\":\"0.52\", \"size\":\"49.6\", \"side\":\"SELL\", \"hash\":\"372a9806f4a02ce0a51d20a42e7b9a7ec6a5b16a\", \"best_bid\":\"0.5\", \"best_ask\":\"0.51\"}], \"timestamp\":\"1785130272909\", \"event_type\":\"price_change\"}","received_at":"2026-07-27T05:31:12.871472Z","schema_version":"clob-market-ws.price_change.v1","sequence":null,"server_hash":null,"server_timestamp":"1785130272909","session_id":"502006c5cfcd437296561ea750c9ec8b","source":"clob_market_ws"},"received_at":"2026-07-27T05:31:12.871472Z","record_id":"453a8c937032e2258fc15ed4606fa0b24cab9a02458d1d81b15e5a805149192b","schema_fingerprint":"4aa3821a28b0b7c2400bc59aba4bcc0a76e971dadd19610d3ad38c768e124dc7","schema_version":"edge-lab-recorder.raw.v1","sequence":null,"source":"clob_market_ws"}
{"event_at":"2026-07-27T05:31:12.916000Z","event_fingerprint":"6e3e2677dd9844a9f93e216ee07fe0ef0e89823623424e03483fcdd5fe5307ab","payload":{"connection_id":"efc69d3132f1467b8e898a382b23ac0d","event_at":"2026-07-27T05:31:12.916000Z","event_type":"price_change","frame_hash":"97145b7dea1a6457cbb45535c2ac3adc4bf5141ab6eaefc5d8101563ca65c55f","frame_index":0,"kind":"data","monotonic_ns":232256132341000,"payload":{"event_type":"price_change","market":"0x3b40066b5cf3871a2f6237c5628bd8092a206aa998558ac5ec13c4483e31e160","price_changes":[{"asset_id":"14766054693214075530629349735273995982307625376442606753688071083149620216746","best_ask":"0.51","best_bid":"0.5","hash":"62b8eb65700d2136dace4f07944b9a4b383cafee","price":"0.03","side":"BUY","size":"618.1"},{"asset_id":"110216635572655435074987471276357323571387854733835379371586402147734167783946","best_ask":"0.5","best_bid":"0.49","hash":"3e64dc92af3c9253cc285f9c69ee87ddc8d11cae","price":"0.97","side":"SELL","size":"618.1"}],"timestamp":"1785130272916"},"payload_hash":"6ad6dd315309f05fba627585fda3d40ca898662b05f50439da8ef0ad99e98d61","raw_frame":"{\"market\":\"0x3b40066b5cf3871a2f6237c5628bd8092a206aa998558ac5ec13c4483e31e160\", \"price_changes\":[{\"asset_id\":\"14766054693214075530629349735273995982307625376442606753688071083149620216746\", \"price\":\"0.03\", \"size\":\"618.1\", \"side\":\"BUY\", \"hash\":\"62b8eb65700d2136dace4f07944b9a4b383cafee\", \"best_bid\":\"0.5\", \"best_ask\":\"0.51\"}, {\"asset_id\":\"110216635572655435074987471276357323571387854733835379371586402147734167783946\", \"price\":\"0.97\", \"size\":\"618.1\", \"side\":\"SELL\", \"hash\":\"3e64dc92af3c9253cc285f9c69ee87ddc8d11cae\", \"best_bid\":\"0.49\", \"best_ask\":\"0.5\"}], \"timestamp\":\"1785130272916\", \"event_type\":\"price_change\"}","received_at":"2026-07-27T05:31:12.894639Z","schema_version":"clob-market-ws.price_change.v1","sequence":null,"server_hash":null,"server_timestamp":"1785130272916","session_id":"502006c5cfcd437296561ea750c9ec8b","source":"clob_market_ws"},"received_at":"2026-07-27T05:31:12.894639Z","record_id":"3dc42449e45a718323d10c2de2a338dfd12389e555605d704015d1abd4e3bc94","schema_fingerprint":"4aa3821a28b0b7c2400bc59aba4bcc0a76e971dadd19610d3ad38c768e124dc7","schema_version":"edge-lab-recorder.raw.v1","sequence":null,"source":"clob_market_ws"}
{"event_at":"2026-07-27T05:31:12.940000Z","event_fingerprint":"3e7d9519cfb7e67e7e6b9baf5868459069cd3557b3944b9bddd4066c42bd9acc","payload":{"connection_id":"efc69d3132f1467b8e898a382b23ac0d","event_at":"2026-07-27T05:31:12.940000Z","event_type":"price_change","frame_hash":"35526d7e07748d404d0b8b51d322131307586c83b305ec6c61f6053d7cecae7b","frame_index":0,"kind":"data","monotonic_ns":232256150551250,"payload":{"event_type":"price_change","market":"0x3b40066b5cf3871a2f6237c5628bd8092a206aa998558ac5ec13c4483e31e160","price_changes":[{"asset_id":"110216635572655435074987471276357323571387854733835379371586402147734167783946","best_ask":"0.5","best_bid":"0.49","hash":"d710586ea8c3050bed387d6078e9a5ad7ebd5669","price":"0.49","side":"BUY","size":"43"},{"asset_id":"14766054693214075530629349735273995982307625376442606753688071083149620216746","best_ask":"0.51","best_bid":"0.5","hash":"a0d72f9be2c42181aa74017696ea3d763986f474","price":"0.51","side":"SELL","size":"43"}],"timestamp":"1785130272940"},"payload_hash":"ee738e0e5830c9d1b32d0135d19a165d9e7d9dc66864fdc81e67002b94aff04e","raw_frame":"{\"market\":\"0x3b40066b5cf3871a2f6237c5628bd8092a206aa998558ac5ec13c4483e31e160\", \"price_changes\":[{\"asset_id\":\"110216635572655435074987471276357323571387854733835379371586402147734167783946\", \"price\":\"0.49\", \"size\":\"43\", \"side\":\"BUY\", \"hash\":\"d710586ea8c3050bed387d6078e9a5ad7ebd5669\", \"best_bid\":\"0.49\", \"best_ask\":\"0.5\"}, {\"asset_id\":\"14766054693214075530629349735273995982307625376442606753688071083149620216746\", \"price\":\"0.51\", \"size\":\"43\", \"side\":\"SELL\", \"hash\":\"a0d72f9be2c42181aa74017696ea3d763986f474\", \"best_bid\":\"0.5\", \"best_ask\":\"0.51\"}], \"timestamp\":\"1785130272940\", \"event_type\":\"price_change\"}","received_at":"2026-07-27T05:31:12.912847Z","schema_version":"clob-market-ws.price_change.v1","sequence":null,"server_hash":null,"server_timestamp":"1785130272940","session_id":"502006c5cfcd437296561ea750c9ec8b","source":"clob_market_ws"},"received_at":"2026-07-27T05:31:12.912847Z","record_id":"317ff9e24b72bd4f4594bfe3cfded7fc5e3f52b312852a7a0e38620791556e3a","schema_fingerprint":"4aa3821a28b0b7c2400bc59aba4bcc0a76e971dadd19610d3ad38c768e124dc7","schema_version":"edge-lab-recorder.raw.v1","sequence":null,"source":"clob_market_ws"}
{"event_at":"2026-07-27T05:31:12.966000Z","event_fingerprint":"832997584f76055d409f69b86f5f0628a4e8cb3f7ad963237309ebd4ca81b580","payload":{"connection_id":"efc69d3132f1467b8e898a382b23ac0d","event_at":"2026-07-27T05:31:12.966000Z","event_type":"price_change","frame_hash":"af65980ac6b850a5051bbd1d88b509d6f4b12eee8703f50ba56ca0aab77a0f0f","frame_index":0,"kind":"data","monotonic_ns":232256166464000,"payload":{"event_type":"price_change","market":"0x3b40066b5cf3871a2f6237c5628bd8092a206aa998558ac5ec13c4483e31e160","price_changes":[{"asset_id":"110216635572655435074987471276357323571387854733835379371586402147734167783946","best_ask":"0.5","best_bid":"0.49","hash":"5dcad9081c9413e759c970a6f93f52d1691dab66","price":"0.31","side":"BUY","size":"67"},{"asset_id":"14766054693214075530629349735273995982307625376442606753688071083149620216746","best_ask":"0.51","best_bid":"0.5","hash":"87d53ad33db18829ee4e37c3864235ff619d9abf","price":"0.69","side":"SELL","size":"67"}],"timestamp":"1785130272966"},"payload_hash":"9904ceb80f9a17510464b09f5b717d7c8da82a22a4815b3223121c6d9def5a59","raw_frame":"{\"market\":\"0x3b40066b5cf3871a2f6237c5628bd8092a206aa998558ac5ec13c4483e31e160\", \"price_changes\":[{\"asset_id\":\"110216635572655435074987471276357323571387854733835379371586402147734167783946\", \"price\":\"0.31\", \"size\":\"67\", \"side\":\"BUY\", \"hash\":\"5dcad9081c9413e759c970a6f93f52d1691dab66\", \"best_bid\":\"0.49\", \"best_ask\":\"0.5\"}, {\"asset_id\":\"14766054693214075530629349735273995982307625376442606753688071083149620216746\", \"price\":\"0.69\", \"size\":\"67\", \"side\":\"SELL\", \"hash\":\"87d53ad33db18829ee4e37c3864235ff619d9abf\", \"best_bid\":\"0.5\", \"best_ask\":\"0.51\"}], \"timestamp\":\"1785130272966\", \"event_type\":\"price_change\"}","received_at":"2026-07-27T05:31:12.928761Z","schema_version":"clob-market-ws.price_change.v1","sequence":null,"server_hash":null,"server_timestamp":"1785130272966","session_id":"502006c5cfcd437296561ea750c9ec8b","source":"clob_market_ws"},"received_at":"2026-07-27T05:31:12.928761Z","record_id":"85360b21673f69928cb222c617e449c3f7a1f1cfdd729306bb385e6fecbe7455","schema_fingerprint":"4aa3821a28b0b7c2400bc59aba4bcc0a76e971dadd19610d3ad38c768e124dc7","schema_version":"edge-lab-recorder.raw.v1","sequence":null,"source":"clob_market_ws"}
{"event_at":"2026-07-27T05:31:12.971000Z","event_fingerprint":"9528a659a20b1f832c7f607a97320bd09d29fbfd5512ecc995d9547308adfba4","payload":{"connection_id":"efc69d3132f1467b8e898a382b23ac0d","event_at":"2026-07-27T05:31:12.971000Z","event_type":"price_change","frame_hash":"b5e1ce0c7402e946e6cda1fe4627a5de44a5772a57103a065662bfea04be58be","frame_index":0,"kind":"data","monotonic_ns":232256172459083,"payload":{"event_type":"price_change","market":"0x3b40066b5cf3871a2f6237c5628bd8092a206aa998558ac5ec13c4483e31e160","price_changes":[{"asset_id":"14766054693214075530629349735273995982307625376442606753688071083149620216746","best_ask":"0.51","best_bid":"0.5","hash":"39532a4312195a35f865121403c8c9dc8885243b","price":"0.03","side":"BUY","size":"613.1"},{"asset_id":"110216635572655435074987471276357323571387854733835379371586402147734167783946","best_ask":"0.5","best_bid":"0.49","hash":"b9184d8cdbbdf2ae1992851fbf345d70b1e7e9eb","price":"0.97","side":"SELL","size":"613.1"}],"timestamp":"1785130272971"},"payload_hash":"deb74730d80f8c83b25d465f0a83b196cdca97f9ddc106bcd97269d016885203","raw_frame":"{\"market\":\"0x3b40066b5cf3871a2f6237c5628bd8092a206aa998558ac5ec13c4483e31e160\", \"price_changes\":[{\"asset_id\":\"14766054693214075530629349735273995982307625376442606753688071083149620216746\", \"price\":\"0.03\", \"size\":\"613.1\", \"side\":\"BUY\", \"hash\":\"39532a4312195a35f865121403c8c9dc8885243b\", \"best_bid\":\"0.5\", \"best_ask\":\"0.51\"}, {\"asset_id\":\"110216635572655435074987471276357323571387854733835379371586402147734167783946\", \"price\":\"0.97\", \"size\":\"613.1\", \"side\":\"SELL\", \"hash\":\"b9184d8cdbbdf2ae1992851fbf345d70b1e7e9eb\", \"best_bid\":\"0.49\", \"best_ask\":\"0.5\"}], \"timestamp\":\"1785130272971\", \"event_type\":\"price_change\"}","received_at":"2026-07-27T05:31:12.934756Z","schema_version":"clob-market-ws.price_change.v1","sequence":null,"server_hash":null,"server_timestamp":"1785130272971","session_id":"502006c5cfcd437296561ea750c9ec8b","source":"clob_market_ws"},"received_at":"2026-07-27T05:31:12.934756Z","record_id":"5511bd768cb134ed506cc00a4db69d7b5098c47db098e76c4ad3c48f8a236531","schema_fingerprint":"4aa3821a28b0b7c2400bc59aba4bcc0a76e971dadd19610d3ad38c768e124dc7","schema_version":"edge-lab-recorder.raw.v1","sequence":null,"source":"clob_market_ws"}
{"event_at":"2026-07-27T05:31:12.993000Z","event_fingerprint":"14e1c6935753f9492bbd3598dd52be13d05857bd93662882ea409504f908f995","payload":{"connection_id":"efc69d3132f1467b8e898a382b23ac0d","event_at":"2026-07-27T05:31:12.993000Z","event_type":"price_change","frame_hash":"742a9cf2ee91e324e8dff7222ef370c988f13deb12c22a8c187101c26d4b5cec","frame_index":0,"kind":"data","monotonic_ns":232256195251583,"payload":{"event_type":"price_change","market":"0x3b40066b5cf3871a2f6237c5628bd8092a206aa998558ac5ec13c4483e31e160","price_changes":[{"asset_id":"110216635572655435074987471276357323571387854733835379371586402147734167783946","best_ask":"0.5","best_bid":"0.49","hash":"21b6c02151d65972f0a8aeca7824447f040be883","price":"0.48","side":"BUY","size":"55.6"},{"asset_id":"14766054693214075530629349735273995982307625376442606753688071083149620216746","best_ask":"0.51","best_bid":"0.5","hash":"e5caaee3f91f5cd0489bfba9c362cb9a79bbd495","price":"0.52","side":"SELL","size":"55.6"}],"timestamp":"1785130272993"},"payload_hash":"fb53f11b2dac329dee7146229f2f99cdbe47b3494c9f5247aeed25832543bb21","raw_frame":"{\"market\":\"0x3b40066b5cf3871a2f6237c5628bd8092a206aa998558ac5ec13c4483e31e160\", \"price_changes\":[{\"asset_id\":\"110216635572655435074987471276357323571387854733835379371586402147734167783946\", \"price\":\"0.48\", \"size\":\"55.6\", \"side\":\"BUY\", \"hash\":\"21b6c02151d65972f0a8aeca7824447f040be883\", \"best_bid\":\"0.49\", \"best_ask\":\"0.5\"}, {\"asset_id\":\"14766054693214075530629349735273995982307625376442606753688071083149620216746\", \"price\":\"0.52\", \"size\":\"55.6\", \"side\":\"SELL\", \"hash\":\"e5caaee3f91f5cd0489bfba9c362cb9a79bbd495\", \"best_bid\":\"0.5\", \"best_ask\":\"0.51\"}], \"timestamp\":\"1785130272993\", \"event_type\":\"price_change\"}","received_at":"2026-07-27T05:31:12.957548Z","schema_version":"clob-market-ws.price_change.v1","sequence":null,"server_hash":null,"server_timestamp":"1785130272993","session_id":"502006c5cfcd437296561ea750c9ec8b","source":"clob_market_ws"},"received_at":"2026-07-27T05:31:12.957548Z","record_id":"738a7640483bb3a00e68e3b358e6db50d9b37666bf8c21efd6bdc2b75b7caf7a","schema_fingerprint":"4aa3821a28b0b7c2400bc59aba4bcc0a76e971dadd19610d3ad38c768e124dc7","schema_version":"edge-lab-recorder.raw.v1","sequence":null,"source":"clob_market_ws"}
{"event_at":"2026-07-27T05:31:13.013000Z","event_fingerprint":"aa5b233555284bcd56ba653f688884004e12e86a4b88ad73ea87df52ac691221","payload":{"connection_id":"efc69d3132f1467b8e898a382b23ac0d","event_at":"2026-07-27T05:31:13.013000Z","event_type":"price_change","frame_hash":"9e0d81fb6084ba865d170382e60922e3f3c1375577613fe4ed74ab5a64f378a2","frame_index":0,"kind":"data","monotonic_ns":232256213009166,"payload":{"event_type":"price_change","market":"0x3b40066b5cf3871a2f6237c5628bd8092a206aa998558ac5ec13c4483e31e160","price_changes":[{"asset_id":"110216635572655435074987471276357323571387854733835379371586402147734167783946","best_ask":"0.5","best_bid":"0.49","hash":"2a03ef36d98536ae5b089421dc2ec56200143765","price":"0.49","side":"BUY","size":"33"},{"asset_id":"14766054693214075530629349735273995982307625376442606753688071083149620216746","best_ask":"0.51","best_bid":"0.5","hash":"391525e0afe31380be9b2b22cdf2938b989ded36","price":"0.51","side":"SELL","size":"33"}],"timestamp":"1785130273013"},"payload_hash":"f779abe11e9b1e20199c3877f4d65044d897c8db5ffa36ae818d74104c9e548a","raw_frame":"{\"market\":\"0x3b40066b5cf3871a2f6237c5628bd8092a206aa998558ac5ec13c4483e31e160\", \"price_changes\":[{\"asset_id\":\"110216635572655435074987471276357323571387854733835379371586402147734167783946\", \"price\":\"0.49\", \"size\":\"33\", \"side\":\"BUY\", \"hash\":\"2a03ef36d98536ae5b089421dc2ec56200143765\", \"best_bid\":\"0.49\", \"best_ask\":\"0.5\"}, {\"asset_id\":\"14766054693214075530629349735273995982307625376442606753688071083149620216746\", \"price\":\"0.51\", \"size\":\"33\", \"side\":\"SELL\", \"hash\":\"391525e0afe31380be9b2b22cdf2938b989ded36\", \"best_bid\":\"0.5\", \"best_ask\":\"0.51\"}], \"timestamp\":\"1785130273013\", \"event_type\":\"price_change\"}","received_at":"2026-07-27T05:31:12.975306Z","schema_version":"clob-market-ws.price_change.v1","sequence":null,"server_hash":null,"server_timestamp":"1785130273013","session_id":"502006c5cfcd437296561ea750c9ec8b","source":"clob_market_ws"},"received_at":"2026-07-27T05:31:12.975306Z","record_id":"2aea4f6da45f2fc60368455112cf6d5c8313080c9bf78b47d1b2d46107776b6f","schema_fingerprint":"4aa3821a28b0b7c2400bc59aba4bcc0a76e971dadd19610d3ad38c768e124dc7","schema_version":"edge-lab-recorder.raw.v1","sequence":null,"source":"clob_market_ws"}
{"event_at":"2026-07-27T05:31:13.022000Z","event_fingerprint":"9f3f2acc90c93582bdc376ee1d3aec177e54d19e84ad4959640a0af3357305a1","payload":{"connection_id":"efc69d3132f1467b8e898a382b23ac0d","event_at":"2026-07-27T05:31:13.022000Z","event_type":"price_change","frame_hash":"1cd6dcf793dc1d31459e03c2548a12cb4d45d3bbcba793540f850623820103e7","frame_index":0,"kind":"data","monotonic_ns":232256222201583,"payload":{"event_type":"price_change","market":"0x3b40066b5cf3871a2f6237c5628bd8092a206aa998558ac5ec13c4483e31e160","price_changes":[{"asset_id":"110216635572655435074987471276357323571387854733835379371586402147734167783946","best_ask":"0.5","best_bid":"0.49","hash":"c2f4b256a9c2ceafe6ec77dfde131b2f2b4a2059","price":"0.01","side":"BUY","size":"7848.02"},{"asset_id":"14766054693214075530629349735273995982307625376442606753688071083149620216746","best_ask":"0.51","best_bid":"0.5","hash":"ff53169739ba2fb459f6a1446e0f0fc487841833","price":"0.99","side":"SELL","size":"7848.02"}],"timestamp":"1785130273022"},"payload_hash":"b3519facbd56ff79e459a49274c1847ee03ea996d2c9ebbdea84dd84f81f503f","raw_frame":"{\"market\":\"0x3b40066b5cf3871a2f6237c5628bd8092a206aa998558ac5ec13c4483e31e160\", \"price_changes\":[{\"asset_id\":\"110216635572655435074987471276357323571387854733835379371586402147734167783946\", \"price\":\"0.01\", \"size\":\"7848.02\", \"side\":\"BUY\", \"hash\":\"c2f4b256a9c2ceafe6ec77dfde131b2f2b4a2059\", \"best_bid\":\"0.49\", \"best_ask\":\"0.5\"}, {\"asset_id\":\"14766054693214075530629349735273995982307625376442606753688071083149620216746\", \"price\":\"0.99\", \"size\":\"7848.02\", \"side\":\"SELL\", \"hash\":\"ff53169739ba2fb459f6a1446e0f0fc487841833\", \"best_bid\":\"0.5\", \"best_ask\":\"0.51\"}], \"timestamp\":\"1785130273022\", \"event_type\":\"price_change\"}","received_at":"2026-07-27T05:31:12.984496Z","schema_version":"clob-market-ws.price_change.v1","sequence":null,"server_hash":null,"server_timestamp":"1785130273022","session_id":"502006c5cfcd437296561ea750c9ec8b","source":"clob_market_ws"},"received_at":"2026-07-27T05:31:12.984496Z","record_id":"2d977bb385901af97db52ea2dcb5abef5062b3e15b96c589af2e43770d3787f5","schema_fingerprint":"4aa3821a28b0b7c2400bc59aba4bcc0a76e971dadd19610d3ad38c768e124dc7","schema_version":"edge-lab-recorder.raw.v1","sequence":null,"source":"clob_market_ws"}
{"event_at":"2026-07-27T05:31:13.026000Z","event_fingerprint":"98fdf52e9b9cdae5dc11e385e43d837af87ef927b700e77bb7e148317de89b82","payload":{"connection_id":"efc69d3132f1467b8e898a382b23ac0d","event_at":"2026-07-27T05:31:13.026000Z","event_type":"price_change","frame_hash":"7db056e34843d88de689dcb7faf08b02c61cb4d5ec9c91c49d75f61e63ea308a","frame_index":0,"kind":"data","monotonic_ns":232256227669666,"payload":{"event_type":"price_change","market":"0x3b40066b5cf3871a2f6237c5628bd8092a206aa998558ac5ec13c4483e31e160","price_changes":[{"asset_id":"110216635572655435074987471276357323571387854733835379371586402147734167783946","best_ask":"0.5","best_bid":"0.49","hash":"6d9cfca948ecf35959751671fb210f021b9eeaf3","price":"0.01","side":"BUY","size":"7853.02"},{"asset_id":"14766054693214075530629349735273995982307625376442606753688071083149620216746","best_ask":"0.51","best_bid":"0.5","hash":"dc90614f1d096d1a5563a326eaf4a27cc414f6c5","price":"0.99","side":"SELL","size":"7853.02"}],"timestamp":"1785130273026"},"payload_hash":"706a1b6250cca3cea36d3a5428178b8e3528ef783a1cc99fdba7fb7cf41ed937","raw_frame":"{\"market\":\"0x3b40066b5cf3871a2f6237c5628bd8092a206aa998558ac5ec13c4483e31e160\", \"price_changes\":[{\"asset_id\":\"110216635572655435074987471276357323571387854733835379371586402147734167783946\", \"price\":\"0.01\", \"size\":\"7853.02\", \"side\":\"BUY\", \"hash\":\"6d9cfca948ecf35959751671fb210f021b9eeaf3\", \"best_bid\":\"0.49\", \"best_ask\":\"0.5\"}, {\"asset_id\":\"14766054693214075530629349735273995982307625376442606753688071083149620216746\", \"price\":\"0.99\", \"size\":\"7853.02\", \"side\":\"SELL\", \"hash\":\"dc90614f1d096d1a5563a326eaf4a27cc414f6c5\", \"best_bid\":\"0.5\", \"best_ask\":\"0.51\"}], \"timestamp\":\"1785130273026\", \"event_type\":\"price_change\"}","received_at":"2026-07-27T05:31:12.989965Z","schema_version":"clob-market-ws.price_change.v1","sequence":null,"server_hash":null,"server_timestamp":"1785130273026","session_id":"502006c5cfcd437296561ea750c9ec8b","source":"clob_market_ws"},"received_at":"2026-07-27T05:31:12.989965Z","record_id":"464b533211d88f5a3f7f961efe0598d282ac009eb2dcbde4faca468fb9a6cb8d","schema_fingerprint":"4aa3821a28b0b7c2400bc59aba4bcc0a76e971dadd19610d3ad38c768e124dc7","schema_version":"edge-lab-recorder.raw.v1","sequence":null,"source":"clob_market_ws"}
{"event_at":"2026-07-27T05:31:13.044000Z","event_fingerprint":"7610dfd7561749feaa5ae751208298f40d0c16d7d1c0e54b2a41d1b1f5a455d6","payload":{"connection_id":"efc69d3132f1467b8e898a382b23ac0d","event_at":"2026-07-27T05:31:13.044000Z","event_type":"price_change","frame_hash":"944f3add57e301caf32d200d0d3c62bb44758863798d7ece7e65b3ed20fbb905","frame_index":0,"kind":"data","monotonic_ns":232256244665958,"payload":{"event_type":"price_change","market":"0x3b40066b5cf3871a2f6237c5628bd8092a206aa998558ac5ec13c4483e31e160","price_changes":[{"asset_id":"110216635572655435074987471276357323571387854733835379371586402147734167783946","best_ask":"0.5","best_bid":"0.49","hash":"6d41a66f2af08782a3a1b667068bc00d554ff5f8","price":"0.48","side":"BUY","size":"65.6"},{"asset_id":"14766054693214075530629349735273995982307625376442606753688071083149620216746","best_ask":"0.51","best_bid":"0.5","hash":"ae35832b9e321fec247229ff563bf3b2e10a42c3","price":"0.52","side":"SELL","size":"65.6"}],"timestamp":"1785130273044"},"payload_hash":"0974251100256930aff6ab3287b40f2e65e282f9a885742a41ba248e73c7f5bc","raw_frame":"{\"market\":\"0x3b40066b5cf3871a2f6237c5628bd8092a206aa998558ac5ec13c4483e31e160\", \"price_changes\":[{\"asset_id\":\"110216635572655435074987471276357323571387854733835379371586402147734167783946\", \"price\":\"0.48\", \"size\":\"65.6\", \"side\":\"BUY\", \"hash\":\"6d41a66f2af08782a3a1b667068bc00d554ff5f8\", \"best_bid\":\"0.49\", \"best_ask\":\"0.5\"}, {\"asset_id\":\"14766054693214075530629349735273995982307625376442606753688071083149620216746\", \"price\":\"0.52\", \"size\":\"65.6\", \"side\":\"SELL\", \"hash\":\"ae35832b9e321fec247229ff563bf3b2e10a42c3\", \"best_bid\":\"0.5\", \"best_ask\":\"0.51\"}], \"timestamp\":\"1785130273044\", \"event_type\":\"price_change\"}","received_at":"2026-07-27T05:31:13.006962Z","schema_version":"clob-market-ws.price_change.v1","sequence":null,"server_hash":null,"server_timestamp":"1785130273044","session_id":"502006c5cfcd437296561ea750c9ec8b","source":"clob_market_ws"},"received_at":"2026-07-27T05:31:13.006962Z","record_id":"279efdfb66711b395171f5b8d555014b630c979a20091c9bb066674c77ddd9d9","schema_fingerprint":"4aa3821a28b0b7c2400bc59aba4bcc0a76e971dadd19610d3ad38c768e124dc7","schema_version":"edge-lab-recorder.raw.v1","sequence":null,"source":"clob_market_ws"}
{"event_at":"2026-07-27T05:31:13.052000Z","event_fingerprint":"b0fe1b98952b6e8fdde8c628fab4199de1e480801e3e696fcc0ffd8c5208c973","payload":{"connection_id":"efc69d3132f1467b8e898a382b23ac0d","event_at":"2026-07-27T05:31:13.052000Z","event_type":"price_change","frame_hash":"54be498d057f842a0f59f77fcd28343ed73c98ab9a82dc3cd577827eb0959ca2","frame_index":0,"kind":"data","monotonic_ns":232256251401833,"payload":{"event_type":"price_change","market":"0x3b40066b5cf3871a2f6237c5628bd8092a206aa998558ac5ec13c4483e31e160","price_changes":[{"asset_id":"14766054693214075530629349735273995982307625376442606753688071083149620216746","best_ask":"0.51","best_bid":"0.5","hash":"1ccd81fdef023dbd7d7360f74dd1d2bb6bc53adf","price":"0.01","side":"BUY","size":"7878.02"},{"asset_id":"110216635572655435074987471276357323571387854733835379371586402147734167783946","best_ask":"0.5","best_bid":"0.49","hash":"740685d64c15e66c5ac9a68dd1eba35e26d2e16d","price":"0.99","side":"SELL","size":"7878.02"}],"timestamp":"1785130273052"},"payload_hash":"7913f20c01e0657c532e44fe49c7a893ccdbbd3c1f170aaaaaa2fc8ccd341f91","raw_frame":"{\"market\":\"0x3b40066b5cf3871a2f6237c5628bd8092a206aa998558ac5ec13c4483e31e160\", \"price_changes\":[{\"asset_id\":\"14766054693214075530629349735273995982307625376442606753688071083149620216746\", \"price\":\"0.01\", \"size\":\"7878.02\", \"side\":\"BUY\", \"hash\":\"1ccd81fdef023dbd7d7360f74dd1d2bb6bc53adf\", \"best_bid\":\"0.5\", \"best_ask\":\"0.51\"}, {\"asset_id\":\"110216635572655435074987471276357323571387854733835379371586402147734167783946\", \"price\":\"0.99\", \"size\":\"7878.02\", \"side\":\"SELL\", \"hash\":\"740685d64c15e66c5ac9a68dd1eba35e26d2e16d\", \"best_bid\":\"0.49\", \"best_ask\":\"0.5\"}], \"timestamp\":\"1785130273052\", \"event_type\":\"price_change\"}","received_at":"2026-07-27T05:31:13.013706Z","schema_version":"clob-market-ws.price_change.v1","sequence":null,"server_hash":null,"server_timestamp":"1785130273052","session_id":"502006c5cfcd437296561ea750c9ec8b","source":"clob_market_ws"},"received_at":"2026-07-27T05:31:13.013706Z","record_id":"495cdbbbc7e953cb5aa28df96ee6d5efc18a6f0942ea0320cde34217dbc0ef74","schema_fingerprint":"4aa3821a28b0b7c2400bc59aba4bcc0a76e971dadd19610d3ad38c768e124dc7","schema_version":"edge-lab-recorder.raw.v1","sequence":null,"source":"clob_market_ws"}
{"event_at":"2026-07-27T05:31:13.056000Z","event_fingerprint":"c3860bbb051e768f14d10f2941711007b63895230fccf92d9d66bc191fbf1334","payload":{"connection_id":"efc69d3132f1467b8e898a382b23ac0d","event_at":"2026-07-27T05:31:13.056000Z","event_type":"price_change","frame_hash":"3e56e4e1495fa5ed5b2d8a1a1c0e0e945fbe8cf581bec47776b9564bdaf25000","frame_index":0,"kind":"data","monotonic_ns":232256254689625,"payload":{"event_type":"price_change","market":"0x3b40066b5cf3871a2f6237c5628bd8092a206aa998558ac5ec13c4483e31e160","price_changes":[{"asset_id":"110216635572655435074987471276357323571387854733835379371586402147734167783946","best_ask":"0.5","best_bid":"0.49","hash":"91eebafd2a65b87cfd2a0f460af6b770b9336bfe","price":"0.01","side":"BUY","size":"7848.02"},{"asset_id":"14766054693214075530629349735273995982307625376442606753688071083149620216746","best_ask":"0.51","best_bid":"0.5","hash":"f75ef840f69e94c1ad28eee93601fd20d40a408c","price":"0.99","side":"SELL","size":"7848.02"}],"timestamp":"1785130273056"},"payload_hash":"c45ec0e13b218c8d93a884c922a419f30fdc7c8ab970adbc241a4af4e4897864","raw_frame":"{\"market\":\"0x3b40066b5cf3871a2f6237c5628bd8092a206aa998558ac5ec13c4483e31e160\", \"price_changes\":[{\"asset_id\":\"110216635572655435074987471276357323571387854733835379371586402147734167783946\", \"price\":\"0.01\", \"size\":\"7848.02\", \"side\":\"BUY\", \"hash\":\"91eebafd2a65b87cfd2a0f460af6b770b9336bfe\", \"best_bid\":\"0.49\", \"best_ask\":\"0.5\"}, {\"asset_id\":\"14766054693214075530629349735273995982307625376442606753688071083149620216746\", \"price\":\"0.99\", \"size\":\"7848.02\", \"side\":\"SELL\", \"hash\":\"f75ef840f69e94c1ad28eee93601fd20d40a408c\", \"best_bid\":\"0.5\", \"best_ask\":\"0.51\"}], \"timestamp\":\"1785130273056\", \"event_type\":\"price_change\"}","received_at":"2026-07-27T05:31:13.016986Z","schema_version":"clob-market-ws.price_change.v1","sequence":null,"server_hash":null,"server_timestamp":"1785130273056","session_id":"502006c5cfcd437296561ea750c9ec8b","source":"clob_market_ws"},"received_at":"2026-07-27T05:31:13.016986Z","record_id":"195305cb8cc8b722d7082c4a3b308eb1c328f07413ffe426db421e8e9fb6b138","schema_fingerprint":"4aa3821a28b0b7c2400bc59aba4bcc0a76e971dadd19610d3ad38c768e124dc7","schema_version":"edge-lab-recorder.raw.v1","sequence":null,"source":"clob_market_ws"}
{"event_at":"2026-07-27T05:31:13.058000Z","event_fingerprint":"73a88fbb30a9a44a8b3642add09330e7eb9211148581cbf958d5ab436d1c350f","payload":{"connection_id":"efc69d3132f1467b8e898a382b23ac0d","event_at":"2026-07-27T05:31:13.058000Z","event_type":"price_change","frame_hash":"0228c49bf1baf2e5d5baa453b6618f0dab66c926464c3be581e9ff4c4d52afea","frame_index":0,"kind":"data","monotonic_ns":232256259895583,"payload":{"event_type":"price_change","market":"0x3b40066b5cf3871a2f6237c5628bd8092a206aa998558ac5ec13c4483e31e160","price_changes":[{"asset_id":"14766054693214075530629349735273995982307625376442606753688071083149620216746","best_ask":"0.51","best_bid":"0.5","hash":"eacc1177f2707232236706ccc162adb9a401170f","price":"0.02","side":"BUY","size":"728.1"},{"asset_id":"110216635572655435074987471276357323571387854733835379371586402147734167783946","best_ask":"0.5","best_bid":"0.49","hash":"c64131a191483b919c018a46b41d676776c6801a","price":"0.98","side":"SELL","size":"728.1"}],"timestamp":"1785130273058"},"payload_hash":"30f9339eb142c59447ea1427a3400902e3646183293566af05c1bc9539b9d233","raw_frame":"{\"market\":\"0x3b40066b5cf3871a2f6237c5628bd8092a206aa998558ac5ec13c4483e31e160\", \"price_changes\":[{\"asset_id\":\"14766054693214075530629349735273995982307625376442606753688071083149620216746\", \"price\":\"0.02\", \"size\":\"728.1\", \"side\":\"BUY\", \"hash\":\"eacc1177f2707232236706ccc162adb9a401170f\", \"best_bid\":\"0.5\", \"best_ask\":\"0.51\"}, {\"asset_id\":\"110216635572655435074987471276357323571387854733835379371586402147734167783946\", \"price\":\"0.98\", \"size\":\"728.1\", \"side\":\"SELL\", \"hash\":\"c64131a191483b919c018a46b41d676776c6801a\", \"best_bid\":\"0.49\", \"best_ask\":\"0.5\"}], \"timestamp\":\"1785130273058\", \"event_type\":\"price_change\"}","received_at":"2026-07-27T05:31:13.022193Z","schema_version":"clob-market-ws.price_change.v1","sequence":null,"server_hash":null,"server_timestamp":"1785130273058","session_id":"502006c5cfcd437296561ea750c9ec8b","source":"clob_market_ws"},"received_at":"2026-07-27T05:31:13.022193Z","record_id":"8837b739a2598326264fe419b5a38da8f18f704132f5a53807427170c8cc6d04","schema_fingerprint":"4aa3821a28b0b7c2400bc59aba4bcc0a76e971dadd19610d3ad38c768e124dc7","schema_version":"edge-lab-recorder.raw.v1","sequence":null,"source":"clob_market_ws"}
{"event_at":"2026-07-27T05:31:13.071000Z","event_fingerprint":"28a489e82667879e1076b52649bcdaaf53dffb91aed4cb74674790abee974a5d","payload":{"connection_id":"efc69d3132f1467b8e898a382b23ac0d","event_at":"2026-07-27T05:31:13.071000Z","event_type":"price_change","frame_hash":"a7260f4dd12e19d6a6acc428692f2463054752bd1f1b70089ae1403bc829a822","frame_index":0,"kind":"data","monotonic_ns":232256270689791,"payload":{"event_type":"price_change","market":"0x3b40066b5cf3871a2f6237c5628bd8092a206aa998558ac5ec13c4483e31e160","price_changes":[{"asset_id":"14766054693214075530629349735273995982307625376442606753688071083149620216746","best_ask":"0.51","best_bid":"0.5","hash":"22c936043c96caac0f4b1890dbbed2479c578987","price":"0.01","side":"BUY","size":"7873.02"},{"asset_id":"110216635572655435074987471276357323571387854733835379371586402147734167783946","best_ask":"0.5","best_bid":"0.49","hash":"7a85208f4deada4edffab4b060a9affaab60606c","price":"0.99","side":"SELL","size":"7873.02"}],"timestamp":"1785130273071"},"payload_hash":"e6993e43494fb43c4b2c741f903a3eb751d5fe7dff395918174ca88f64bf65c7","raw_frame":"{\"market\":\"0x3b40066b5cf3871a2f6237c5628bd8092a206aa998558ac5ec13c4483e31e160\", \"price_changes\":[{\"asset_id\":\"14766054693214075530629349735273995982307625376442606753688071083149620216746\", \"price\":\"0.01\", \"size\":\"7873.02\", \"side\":\"BUY\", \"hash\":\"22c936043c96caac0f4b1890dbbed2479c578987\", \"best_bid\":\"0.5\", \"best_ask\":\"0.51\"}, {\"asset_id\":\"110216635572655435074987471276357323571387854733835379371586402147734167783946\", \"price\":\"0.99\", \"size\":\"7873.02\", \"side\":\"SELL\", \"hash\":\"7a85208f4deada4edffab4b060a9affaab60606c\", \"best_bid\":\"0.49\", \"best_ask\":\"0.5\"}], \"timestamp\":\"1785130273071\", \"event_type\":\"price_change\"}","received_at":"2026-07-27T05:31:13.032981Z","schema_version":"clob-market-ws.price_change.v1","sequence":null,"server_hash":null,"server_timestamp":"1785130273071","session_id":"502006c5cfcd437296561ea750c9ec8b","source":"clob_market_ws"},"received_at":"2026-07-27T05:31:13.032981Z","record_id":"ee23c0eb21e1d8e375d6f9e36ef83430dcba7f6281d5c007eedd317e1bb2e90f","schema_fingerprint":"4aa3821a28b0b7c2400bc59aba4bcc0a76e971dadd19610d3ad38c768e124dc7","schema_version":"edge-lab-recorder.raw.v1","sequence":null,"source":"clob_market_ws"}
{"event_at":"2026-07-27T05:31:13.080000Z","event_fingerprint":"31a768c6ed93a077c865af9270447daf2efcc8e094fd39fb9201a1c0c6fc69c3","payload":{"connection_id":"efc69d3132f1467b8e898a382b23ac0d","event_at":"2026-07-27T05:31:13.080000Z","event_type":"price_change","frame_hash":"69a028004ac58150be7b8eea51eb6fd31be25f963456373d6464914ed0fcb465","frame_index":0,"kind":"data","monotonic_ns":232256284359333,"payload":{"event_type":"price_change","market":"0x3b40066b5cf3871a2f6237c5628bd8092a206aa998558ac5ec13c4483e31e160","price_changes":[{"asset_id":"110216635572655435074987471276357323571387854733835379371586402147734167783946","best_ask":"0.5","best_bid":"0.49","hash":"8298f1a7082ee2060d7b39b27b03e191119edf6d","price":"0.47","side":"BUY","size":"33"},{"asset_id":"14766054693214075530629349735273995982307625376442606753688071083149620216746","best_ask":"0.51","best_bid":"0.5","hash":"58a84ff67b33c9eb4b82c1d64f0c1909b933e896","price":"0.53","side":"SELL","size":"33"}],"timestamp":"1785130273080"},"payload_hash":"1b06305a700195a60e51fa1b3360e0f01eea0e361034f82f6ad6625b969f3521","raw_frame":"{\"market\":\"0x3b40066b5cf3871a2f6237c5628bd8092a206aa998558ac5ec13c4483e31e160\", \"price_changes\":[{\"asset_id\":\"110216635572655435074987471276357323571387854733835379371586402147734167783946\", \"price\":\"0.47\", \"size\":\"33\", \"side\":\"BUY\", \"hash\":\"8298f1a7082ee2060d7b39b27b03e191119edf6d\", \"best_bid\":\"0.49\", \"best_ask\":\"0.5\"}, {\"asset_id\":\"14766054693214075530629349735273995982307625376442606753688071083149620216746\", \"price\":\"0.53\", \"size\":\"33\", \"side\":\"SELL\", \"hash\":\"58a84ff67b33c9eb4b82c1d64f0c1909b933e896\", \"best_bid\":\"0.5\", \"best_ask\":\"0.51\"}], \"timestamp\":\"1785130273080\", \"event_type\":\"price_change\"}","received_at":"2026-07-27T05:31:13.046658Z","schema_version":"clob-market-ws.price_change.v1","sequence":null,"server_hash":null,"server_timestamp":"1785130273080","session_id":"502006c5cfcd437296561ea750c9ec8b","source":"clob_market_ws"},"received_at":"2026-07-27T05:31:13.046658Z","record_id":"337c815ab90b3f601d35a96f6c1f0414d493bd56f2b91974a4a40bef1f8fc690","schema_fingerprint":"4aa3821a28b0b7c2400bc59aba4bcc0a76e971dadd19610d3ad38c768e124dc7","schema_version":"edge-lab-recorder.raw.v1","sequence":null,"source":"clob_market_ws"}
{"event_at":"2026-07-27T05:31:13.108000Z","event_fingerprint":"edf8c49e93468e81b17de86bb70bbfa01697baed45039ef741040969425512c4","payload":{"connection_id":"efc69d3132f1467b8e898a382b23ac0d","event_at":"2026-07-27T05:31:13.108000Z","event_type":"price_change","frame_hash":"c6e645c24aaca890523e70d1e3c19a408e58d10a5df730657996fdc69f995877","frame_index":0,"kind":"data","monotonic_ns":232256306270375,"payload":{"event_type":"price_change","market":"0x3b40066b5cf3871a2f6237c5628bd8092a206aa998558ac5ec13c4483e31e160","price_changes":[{"asset_id":"110216635572655435074987471276357323571387854733835379371586402147734167783946","best_ask":"0.5","best_bid":"0.49","hash":"9f4727ae399d1707e5999597abd87bdf8e1e4a8e","price":"0.01","side":"BUY","size":"7843.02"},{"asset_id":"14766054693214075530629349735273995982307625376442606753688071083149620216746","best_ask":"0.51","best_bid":"0.5","hash":"726b7a05753b3f312362e9aeb2f34450b6328f67","price":"0.99","side":"SELL","size":"7843.02"}],"timestamp":"1785130273108"},"payload_hash":"87f0bdcffe6a7af45dc9d8ac2b8dc5c45d27aec83ffb443fb3f9961357b97fcc","raw_frame":"{\"market\":\"0x3b40066b5cf3871a2f6237c5628bd8092a206aa998558ac5ec13c4483e31e160\", \"price_changes\":[{\"asset_id\":\"110216635572655435074987471276357323571387854733835379371586402147734167783946\", \"price\":\"0.01\", \"size\":\"7843.02\", \"side\":\"BUY\", \"hash\":\"9f4727ae399d1707e5999597abd87bdf8e1e4a8e\", \"best_bid\":\"0.49\", \"best_ask\":\"0.5\"}, {\"asset_id\":\"14766054693214075530629349735273995982307625376442606753688071083149620216746\", \"price\":\"0.99\", \"size\":\"7843.02\", \"side\":\"SELL\", \"hash\":\"726b7a05753b3f312362e9aeb2f34450b6328f67\", \"best_bid\":\"0.5\", \"best_ask\":\"0.51\"}], \"timestamp\":\"1785130273108\", \"event_type\":\"price_change\"}","received_at":"2026-07-27T05:31:13.068569Z","schema_version":"clob-market-ws.price_change.v1","sequence":null,"server_hash":null,"server_timestamp":"1785130273108","session_id":"502006c5cfcd437296561ea750c9ec8b","source":"clob_market_ws"},"received_at":"2026-07-27T05:31:13.068569Z","record_id":"533ad9a32de377b31b21d054123b5bded5cb0bfecbbe5ed07a25e4640157f78b","schema_fingerprint":"4aa3821a28b0b7c2400bc59aba4bcc0a76e971dadd19610d3ad38c768e124dc7","schema_version":"edge-lab-recorder.raw.v1","sequence":null,"source":"clob_market_ws"}
{"event_at":"2026-07-27T05:31:13.112000Z","event_fingerprint":"35b2d63e6ddaa0c90815c0dcf397f74f0f96077c718308665c610ebac7fa36ff","payload":{"connection_id":"efc69d3132f1467b8e898a382b23ac0d","event_at":"2026-07-27T05:31:13.112000Z","event_type":"price_change","frame_hash":"bb6e62f7d4d46e35178f35de57f9a8c5ff1eb0091c12aa294d9935c61980b6ac","frame_index":0,"kind":"data","monotonic_ns":232256314629583,"payload":{"event_type":"price_change","market":"0x3b40066b5cf3871a2f6237c5628bd8092a206aa998558ac5ec13c4483e31e160","price_changes":[{"asset_id":"14766054693214075530629349735273995982307625376442606753688071083149620216746","best_ask":"0.51","best_bid":"0.5","hash":"4b444f2d08f3c6804d4dd532448bb48c21337276","price":"0.02","side":"BUY","size":"723.1"},{"asset_id":"110216635572655435074987471276357323571387854733835379371586402147734167783946","best_ask":"0.5","best_bid":"0.49","hash":"32caaf354709d5e25a30befc1205322fd6e02087","price":"0.98","side":"SELL","size":"723.1"}],"timestamp":"1785130273112"},"payload_hash":"e55922c12344d2eb2a9d98b10b5b46899145ffbd2cfb1514aa238858f8bcf1aa","raw_frame":"{\"market\":\"0x3b40066b5cf3871a2f6237c5628bd8092a206aa998558ac5ec13c4483e31e160\", \"price_changes\":[{\"asset_id\":\"14766054693214075530629349735273995982307625376442606753688071083149620216746\", \"price\":\"0.02\", \"size\":\"723.1\", \"side\":\"BUY\", \"hash\":\"4b444f2d08f3c6804d4dd532448bb48c21337276\", \"best_bid\":\"0.5\", \"best_ask\":\"0.51\"}, {\"asset_id\":\"110216635572655435074987471276357323571387854733835379371586402147734167783946\", \"price\":\"0.98\", \"size\":\"723.1\", \"side\":\"SELL\", \"hash\":\"32caaf354709d5e25a30befc1205322fd6e02087\", \"best_bid\":\"0.49\", \"best_ask\":\"0.5\"}], \"timestamp\":\"1785130273112\", \"event_type\":\"price_change\"}","received_at":"2026-07-27T05:31:13.076925Z","schema_version":"clob-market-ws.price_change.v1","sequence":null,"server_hash":null,"server_timestamp":"1785130273112","session_id":"502006c5cfcd437296561ea750c9ec8b","source":"clob_market_ws"},"received_at":"2026-07-27T05:31:13.076925Z","record_id":"4d830e77df3fbdaa46a72ff1681a3c7edfd538cf2b67ac95505e4f6207498ef8","schema_fingerprint":"4aa3821a28b0b7c2400bc59aba4bcc0a76e971dadd19610d3ad38c768e124dc7","schema_version":"edge-lab-recorder.raw.v1","sequence":null,"source":"clob_market_ws"}
{"event_at":"2026-07-27T05:31:13.116000Z","event_fingerprint":"e029ccdb935cbd5b280a8166dc0db964b2cd055d1110d7c5278842225cfe4936","payload":{"connection_id":"efc69d3132f1467b8e898a382b23ac0d","event_at":"2026-07-27T05:31:13.116000Z","event_type":"price_change","frame_hash":"a237bd7347c2e92cbb4f22610822cd243516f565235de13bb7a86928ed14c513","frame_index":0,"kind":"data","monotonic_ns":232256318859500,"payload":{"event_type":"price_change","market":"0x3b40066b5cf3871a2f6237c5628bd8092a206aa998558ac5ec13c4483e31e160","price_changes":[{"asset_id":"110216635572655435074987471276357323571387854733835379371586402147734167783946","best_ask":"0.5","best_bid":"0.49","hash":"fe8faa1805ea9d87b0f8e5bfa27fd9a4bb3c6d81","price":"0.48","side":"BUY","size":"55.6"},{"asset_id":"14766054693214075530629349735273995982307625376442606753688071083149620216746","best_ask":"0.51","best_bid":"0.5","hash":"18caa7c129b4225b3acde9868f097e9d7d28f884","price":"0.52","side":"SELL","size":"55.6"}],"timestamp":"1785130273116"},"payload_hash":"6d305616c3b5d0335b134a14b90304b2edaa8424936cf2dae4cd268bee7314a2","raw_frame":"{\"market\":\"0x3b40066b5cf3871a2f6237c5628bd8092a206aa998558ac5ec13c4483e31e160\", \"price_changes\":[{\"asset_id\":\"110216635572655435074987471276357323571387854733835379371586402147734167783946\", \"price\":\"0.48\", \"size\":\"55.6\", \"side\":\"BUY\", \"hash\":\"fe8faa1805ea9d87b0f8e5bfa27fd9a4bb3c6d81\", \"best_bid\":\"0.49\", \"best_ask\":\"0.5\"}, {\"asset_id\":\"14766054693214075530629349735273995982307625376442606753688071083149620216746\", \"price\":\"0.52\", \"size\":\"55.6\", \"side\":\"SELL\", \"hash\":\"18caa7c129b4225b3acde9868f097e9d7d28f884\", \"best_bid\":\"0.5\", \"best_ask\":\"0.51\"}], \"timestamp\":\"1785130273116\", \"event_type\":\"price_change\"}","received_at":"2026-07-27T05:31:13.081164Z","schema_version":"clob-market-ws.price_change.v1","sequence":null,"server_hash":null,"server_timestamp":"1785130273116","session_id":"502006c5cfcd437296561ea750c9ec8b","source":"clob_market_ws"},"received_at":"2026-07-27T05:31:13.081164Z","record_id":"14486e26a9dd9d9553ae47cc4fc0f30e1c01e0bfaa0dcf1d3c0daee4216107d9","schema_fingerprint":"4aa3821a28b0b7c2400bc59aba4bcc0a76e971dadd19610d3ad38c768e124dc7","schema_version":"edge-lab-recorder.raw.v1","sequence":null,"source":"clob_market_ws"}
{"event_at":"2026-07-27T05:31:13.121000Z","event_fingerprint":"9fd9e2a79a9de7c29b1f73733bce33d8f820399bbc998936218d6c291971d956","payload":{"connection_id":"efc69d3132f1467b8e898a382b23ac0d","event_at":"2026-07-27T05:31:13.121000Z","event_type":"price_change","frame_hash":"20814071ed88b16675ba9350697a429d8e8d5703122b15d9623bc8efaa1be918","frame_index":0,"kind":"data","monotonic_ns":232256324063041,"payload":{"event_type":"price_change","market":"0x3b40066b5cf3871a2f6237c5628bd8092a206aa998558ac5ec13c4483e31e160","price_changes":[{"asset_id":"110216635572655435074987471276357323571387854733835379371586402147734167783946","best_ask":"0.5","best_bid":"0.49","hash":"584b3268578ccef4c156529edebbfb27b6238169","price":"0.47","side":"BUY","size":"129"},{"asset_id":"14766054693214075530629349735273995982307625376442606753688071083149620216746","best_ask":"0.51","best_bid":"0.5","hash":"c7cb28342a4a2d7ec56c7ed299c76127eed59157","price":"0.53","side":"SELL","size":"129"}],"timestamp":"1785130273121"},"payload_hash":"59e1fa7fc6fbed4723e053e5a8704124ebec6e3b841cdbedb544f5e41061da66","raw_frame":"{\"market\":\"0x3b40066b5cf3871a2f6237c5628bd8092a206aa998558ac5ec13c4483e31e160\", \"price_changes\":[{\"asset_id\":\"110216635572655435074987471276357323571387854733835379371586402147734167783946\", \"price\":\"0.47\", \"size\":\"129\", \"side\":\"BUY\", \"hash\":\"584b3268578ccef4c156529edebbfb27b6238169\", \"best_bid\":\"0.49\", \"best_ask\":\"0.5\"}, {\"asset_id\":\"14766054693214075530629349735273995982307625376442606753688071083149620216746\", \"price\":\"0.53\", \"size\":\"129\", \"side\":\"SELL\", \"hash\":\"c7cb28342a4a2d7ec56c7ed299c76127eed59157\", \"best_bid\":\"0.5\", \"best_ask\":\"0.51\"}], \"timestamp\":\"1785130273121\", \"event_type\":\"price_change\"}","received_at":"2026-07-27T05:31:13.086362Z","schema_version":"clob-market-ws.price_change.v1","sequence":null,"server_hash":null,"server_timestamp":"1785130273121","session_id":"502006c5cfcd437296561ea750c9ec8b","source":"clob_market_ws"},"received_at":"2026-07-27T05:31:13.086362Z","record_id":"64381b66d104ebde35a6cf90a11762e13e7a4759e808eafc492b35b6ac88d409","schema_fingerprint":"4aa3821a28b0b7c2400bc59aba4bcc0a76e971dadd19610d3ad38c768e124dc7","schema_version":"edge-lab-recorder.raw.v1","sequence":null,"source":"clob_market_ws"}
{"event_at":"2026-07-27T05:31:13.122000Z","event_fingerprint":"193c467cfc82230ab159cddbcb3d21a1dd975fdf2d8529167f780ec65c41944a","payload":{"connection_id":"efc69d3132f1467b8e898a382b23ac0d","event_at":"2026-07-27T05:31:13.122000Z","event_type":"price_change","frame_hash":"eec3d94a4416bb064bd3f4afb68ad13dd4bfa59ae9c678af81893ca9a6c59f32","frame_index":0,"kind":"data","monotonic_ns":232256330916041,"payload":{"event_type":"price_change","market":"0x3b40066b5cf3871a2f6237c5628bd8092a206aa998558ac5ec13c4483e31e160","price_changes":[{"asset_id":"14766054693214075530629349735273995982307625376442606753688071083149620216746","best_ask":"0.51","best_bid":"0.5","hash":"9a1b07b549c8f4d510fa42bf33e90fcc18ce480b","price":"0.48","side":"BUY","size":"58.62"},{"asset_id":"110216635572655435074987471276357323571387854733835379371586402147734167783946","best_ask":"0.5","best_bid":"0.49","hash":"f25274674d83ecf2bf5c2d43aade90a29edd82e0","price":"0.52","side":"SELL","size":"58.62"}],"timestamp":"1785130273122"},"payload_hash":"f6c38de2eca4b5120ae61142c50d616457da8a960d84d2ecfc9578d11bb9f35e","raw_frame":"{\"market\":\"0x3b40066b5cf3871a2f6237c5628bd8092a206aa998558ac5ec13c4483e31e160\", \"price_changes\":[{\"asset_id\":\"14766054693214075530629349735273995982307625376442606753688071083149620216746\", \"price\":\"0.48\", \"size\":\"58.62\", \"side\":\"BUY\", \"hash\":\"9a1b07b549c8f4d510fa42bf33e90fcc18ce480b\", \"best_bid\":\"0.5\", \"best_ask\":\"0.51\"}, {\"asset_id\":\"110216635572655435074987471276357323571387854733835379371586402147734167783946\", \"price\":\"0.52\", \"size\":\"58.62\", \"side\":\"SELL\", \"hash\":\"f25274674d83ecf2bf5c2d43aade90a29edd82e0\", \"best_bid\":\"0.49\", \"best_ask\":\"0.5\"}], \"timestamp\":\"1785130273122\", \"event_type\":\"price_change\"}","received_at":"2026-07-27T05:31:13.093212Z","schema_version":"clob-market-ws.price_change.v1","sequence":null,"server_hash":null,"server_timestamp":"1785130273122","session_id":"502006c5cfcd437296561ea750c9ec8b","source":"clob_market_ws"},"received_at":"2026-07-27T05:31:13.093212Z","record_id":"c70a2c181cf853ef6cee955374249e849cb24506dc1f70c61ded27233297bb73","schema_fingerprint":"4aa3821a28b0b7c2400bc59aba4bcc0a76e971dadd19610d3ad38c768e124dc7","schema_version":"edge-lab-recorder.raw.v1","sequence":null,"source":"clob_market_ws"}
{"event_at":"2026-07-27T05:31:13.126000Z","event_fingerprint":"30c4904cda9cfa8770a9bd894729ba169fc6a9ffe84ccc9a2257ea83ab411967","payload":{"connection_id":"efc69d3132f1467b8e898a382b23ac0d","event_at":"2026-07-27T05:31:13.126000Z","event_type":"price_change","frame_hash":"3a9097a8f4d281c600eefc270a12ea54ae1d89b7399840e78c40980755e08474","frame_index":0,"kind":"data","monotonic_ns":232256337020875,"payload":{"event_type":"price_change","market":"0x3b40066b5cf3871a2f6237c5628bd8092a206aa998558ac5ec13c4483e31e160","price_changes":[{"asset_id":"14766054693214075530629349735273995982307625376442606753688071083149620216746","best_ask":"0.51","best_bid":"0.5","hash":"169b11664182d1948cc12399b95006c9f64bac9d","price":"0.48","side":"BUY","size":"69.62"},{"asset_id":"110216635572655435074987471276357323571387854733835379371586402147734167783946","best_ask":"0.5","best_bid":"0.49","hash":"f4c98a1fb19e3373eee4cd44abdf9354986cac8e","price":"0.52","side":"SELL","size":"69.62"}],"timestamp":"1785130273126"},"payload_hash":"a76dcf39da5f170eac5b603756ba1b7c1631edbc05a60397bd7664c586fb363a","raw_frame":"{\"market\":\"0x3b40066b5cf3871a2f6237c5628bd8092a206aa998558ac5ec13c4483e31e160\", \"price_changes\":[{\"asset_id\":\"14766054693214075530629349735273995982307625376442606753688071083149620216746\", \"price\":\"0.48\", \"size\":\"69.62\", \"side\":\"BUY\", \"hash\":\"169b11664182d1948cc12399b95006c9f64bac9d\", \"best_bid\":\"0.5\", \"best_ask\":\"0.51\"}, {\"asset_id\":\"110216635572655435074987471276357323571387854733835379371586402147734167783946\", \"price\":\"0.52\", \"size\":\"69.62\", \"side\":\"SELL\", \"hash\":\"f4c98a1fb19e3373eee4cd44abdf9354986cac8e\", \"best_bid\":\"0.49\", \"best_ask\":\"0.5\"}], \"timestamp\":\"1785130273126\", \"event_type\":\"price_change\"}","received_at":"2026-07-27T05:31:13.099320Z","schema_version":"clob-market-ws.price_change.v1","sequence":null,"server_hash":null,"server_timestamp":"1785130273126","session_id":"502006c5cfcd437296561ea750c9ec8b","source":"clob_market_ws"},"received_at":"2026-07-27T05:31:13.099320Z","record_id":"b8ee45872ccc9f18c884ed5c40299cf826d3f85be72dea79c6ad752795b45f97","schema_fingerprint":"4aa3821a28b0b7c2400bc59aba4bcc0a76e971dadd19610d3ad38c768e124dc7","schema_version":"edge-lab-recorder.raw.v1","sequence":null,"source":"clob_market_ws"}
{"event_at":"2026-07-27T05:31:13.145000Z","event_fingerprint":"6f23d8cf6fa169d6e0f8626a5222e83d5205e93a6621f6e2265bb0661f84d52e","payload":{"connection_id":"efc69d3132f1467b8e898a382b23ac0d","event_at":"2026-07-27T05:31:13.145000Z","event_type":"price_change","frame_hash":"37c529c9a7701a06bc8854b5ac3db8574015ac3613cc863cbdf61ec420aedccf","frame_index":0,"kind":"data","monotonic_ns":232256351835583,"payload":{"event_type":"price_change","market":"0x3b40066b5cf3871a2f6237c5628bd8092a206aa998558ac5ec13c4483e31e160","price_changes":[{"asset_id":"110216635572655435074987471276357323571387854733835379371586402147734167783946","best_ask":"0.5","best_bid":"0.49","hash":"d432cb74755e6ca2041af268ef38987b0b348031","price":"0.49","side":"BUY","size":"43"},{"asset_id":"14766054693214075530629349735273995982307625376442606753688071083149620216746","best_ask":"0.51","best_bid":"0.5","hash":"06edc9ad4d1056f8074cb6e72589b550c967818b","price":"0.51","side":"SELL","size":"43"}],"timestamp":"1785130273145"},"payload_hash":"478247bf7a523ceeadf5ffc2561445cd4d64cffce2519e17dd49d13f7605e092","raw_frame":"{\"market\":\"0x3b40066b5cf3871a2f6237c5628bd8092a206aa998558ac5ec13c4483e31e160\", \"price_changes\":[{\"asset_id\":\"110216635572655435074987471276357323571387854733835379371586402147734167783946\", \"price\":\"0.49\", \"size\":\"43\", \"side\":\"BUY\", \"hash\":\"d432cb74755e6ca2041af268ef38987b0b348031\", \"best_bid\":\"0.49\", \"best_ask\":\"0.5\"}, {\"asset_id\":\"14766054693214075530629349735273995982307625376442606753688071083149620216746\", \"price\":\"0.51\", \"size\":\"43\", \"side\":\"SELL\", \"hash\":\"06edc9ad4d1056f8074cb6e72589b550c967818b\", \"best_bid\":\"0.5\", \"best_ask\":\"0.51\"}], \"timestamp\":\"1785130273145\", \"event_type\":\"price_change\"}","received_at":"2026-07-27T05:31:13.114136Z","schema_version":"clob-market-ws.price_change.v1","sequence":null,"server_hash":null,"server_timestamp":"1785130273145","session_id":"502006c5cfcd437296561ea750c9ec8b","source":"clob_market_ws"},"received_at":"2026-07-27T05:31:13.114136Z","record_id":"ad7ad43e0b207b11b0015246bb66b4e123f16f617cf533ba65909bdcf19c3089","schema_fingerprint":"4aa3821a28b0b7c2400bc59aba4bcc0a76e971dadd19610d3ad38c768e124dc7","schema_version":"edge-lab-recorder.raw.v1","sequence":null,"source":"clob_market_ws"}
{"event_at":"2026-07-27T05:31:13.147000Z","event_fingerprint":"3e3f8349ff67edf80ce6345ba7393656ca97eb0157b7e75183ebf8cb0c41bbb7","payload":{"connection_id":"efc69d3132f1467b8e898a382b23ac0d","event_at":"2026-07-27T05:31:13.147000Z","event_type":"price_change","frame_hash":"7d267678e9e2bf16932a0170462c35641931f97e9aeccd98a196bf976b99ffa2","frame_index":0,"kind":"data","monotonic_ns":232256358059750,"payload":{"event_type":"price_change","market":"0x3b40066b5cf3871a2f6237c5628bd8092a206aa998558ac5ec13c4483e31e160","price_changes":[{"asset_id":"14766054693214075530629349735273995982307625376442606753688071083149620216746","best_ask":"0.51","best_bid":"0.5","hash":"f18014bae5903b9d68a95ac06008900828cc3e53","price":"0.44","side":"BUY","size":"149"},{"asset_id":"110216635572655435074987471276357323571387854733835379371586402147734167783946","best_ask":"0.5","best_bid":"0.49","hash":"d9922b018c6c5bd815ca2bfbc64635c35ef07406","price":"0.56","side":"SELL","size":"149"}],"timestamp":"1785130273147"},"payload_hash":"ab33c8957cf90c408042e1da236a30f400904e9ff93219f07a65e283060f8fed","raw_frame":"{\"market\":\"0x3b40066b5cf3871a2f6237c5628bd8092a206aa998558ac5ec13c4483e31e160\", \"price_changes\":[{\"asset_id\":\"14766054693214075530629349735273995982307625376442606753688071083149620216746\", \"price\":\"0.44\", \"size\":\"149\", \"side\":\"BUY\", \"hash\":\"f18014bae5903b9d68a95ac06008900828cc3e53\", \"best_bid\":\"0.5\", \"best_ask\":\"0.51\"}, {\"asset_id\":\"110216635572655435074987471276357323571387854733835379371586402147734167783946\", \"price\":\"0.56\", \"size\":\"149\", \"side\":\"SELL\", \"hash\":\"d9922b018c6c5bd815ca2bfbc64635c35ef07406\", \"best_bid\":\"0.49\", \"best_ask\":\"0.5\"}], \"timestamp\":\"1785130273147\", \"event_type\":\"price_change\"}","received_at":"2026-07-27T05:31:13.120356Z","schema_version":"clob-market-ws.price_change.v1","sequence":null,"server_hash":null,"server_timestamp":"1785130273147","session_id":"502006c5cfcd437296561ea750c9ec8b","source":"clob_market_ws"},"received_at":"2026-07-27T05:31:13.120356Z","record_id":"d8c1b7df69aebdb4ca6b01794e8b8bdb79f5f45ab8f5917aeb4c226650944d8c","schema_fingerprint":"4aa3821a28b0b7c2400bc59aba4bcc0a76e971dadd19610d3ad38c768e124dc7","schema_version":"edge-lab-recorder.raw.v1","sequence":null,"source":"clob_market_ws"}
{"event_at":"2026-07-27T05:31:13.214000Z","event_fingerprint":"a44f0bda166c6c5dfd75620363b029cd0c4bc27a61cf0a69b7623636a3e4899f","payload":{"connection_id":"efc69d3132f1467b8e898a382b23ac0d","event_at":"2026-07-27T05:31:13.214000Z","event_type":"price_change","frame_hash":"f95f5e219477f2a8c108b7afbd2033f67c4919fdaa7eae4ab6292c854560da25","frame_index":0,"kind":"data","monotonic_ns":232256417333000,"payload":{"event_type":"price_change","market":"0x3b40066b5cf3871a2f6237c5628bd8092a206aa998558ac5ec13c4483e31e160","price_changes":[{"asset_id":"110216635572655435074987471276357323571387854733835379371586402147734167783946","best_ask":"0.5","best_bid":"0.49","hash":"6b646d77a941783e6bca8a61a044c93557f8e28d","price":"0.49","side":"BUY","size":"21"},{"asset_id":"14766054693214075530629349735273995982307625376442606753688071083149620216746","best_ask":"0.51","best_bid":"0.5","hash":"881aece67a621ef8a678d4ec71abaf0c4614f977","price":"0.51","side":"SELL","size":"21"}],"timestamp":"1785130273214"},"payload_hash":"d68bb166cfbfb9bd969936ecabe275982664b7bb8972fdad83a670c95b34521f","raw_frame":"{\"market\":\"0x3b40066b5cf3871a2f6237c5628bd8092a206aa998558ac5ec13c4483e31e160\", \"price_changes\":[{\"asset_id\":\"110216635572655435074987471276357323571387854733835379371586402147734167783946\", \"price\":\"0.49\", \"size\":\"21\", \"side\":\"BUY\", \"hash\":\"6b646d77a941783e6bca8a61a044c93557f8e28d\", \"best_bid\":\"0.49\", \"best_ask\":\"0.5\"}, {\"asset_id\":\"14766054693214075530629349735273995982307625376442606753688071083149620216746\", \"price\":\"0.51\", \"size\":\"21\", \"side\":\"SELL\", \"hash\":\"881aece67a621ef8a678d4ec71abaf0c4614f977\", \"best_bid\":\"0.5\", \"best_ask\":\"0.51\"}], \"timestamp\":\"1785130273214\", \"event_type\":\"price_change\"}","received_at":"2026-07-27T05:31:13.179632Z","schema_version":"clob-market-ws.price_change.v1","sequence":null,"server_hash":null,"server_timestamp":"1785130273214","session_id":"502006c5cfcd437296561ea750c9ec8b","source":"clob_market_ws"},"received_at":"2026-07-27T05:31:13.179632Z","record_id":"ad66f2d012c7c180498b521513e13a861f3ab715cfaa6db7b935a052417bb083","schema_fingerprint":"4aa3821a28b0b7c2400bc59aba4bcc0a76e971dadd19610d3ad38c768e124dc7","schema_version":"edge-lab-recorder.raw.v1","sequence":null,"source":"clob_market_ws"}
{"event_at":"2026-07-27T05:31:13.215000Z","event_fingerprint":"fb671b8be9d1be995d45314f093fbdfeb7b9968b787d4f65d33b325e2a23e79e","payload":{"connection_id":"efc69d3132f1467b8e898a382b23ac0d","event_at":"2026-07-27T05:31:13.215000Z","event_type":"price_change","frame_hash":"d83be5df367c211b8e04523d6559bb3c47a44f9ed561adb6c829cd55f89a059b","frame_index":0,"kind":"data","monotonic_ns":232256421634750,"payload":{"event_type":"price_change","market":"0x3b40066b5cf3871a2f6237c5628bd8092a206aa998558ac5ec13c4483e31e160","price_changes":[{"asset_id":"110216635572655435074987471276357323571387854733835379371586402147734167783946","best_ask":"0.5","best_bid":"0.49","hash":"db6e703b9182a129f1e42d61da240213690f9320","price":"0.49","side":"BUY","size":"10"},{"asset_id":"14766054693214075530629349735273995982307625376442606753688071083149620216746","best_ask":"0.51","best_bid":"0.5","hash":"7bddb399f1ce044f755fa6e7a85340fb8569444f","price":"0.51","side":"SELL","size":"10"}],"timestamp":"1785130273215"},"payload_hash":"4cd961e7cde05bed10ccf725e771a17ed3bdc1636c10367b9cfc88be33b6dfcc","raw_frame":"{\"market\":\"0x3b40066b5cf3871a2f6237c5628bd8092a206aa998558ac5ec13c4483e31e160\", \"price_changes\":[{\"asset_id\":\"110216635572655435074987471276357323571387854733835379371586402147734167783946\", \"price\":\"0.49\", \"size\":\"10\", \"side\":\"BUY\", \"hash\":\"db6e703b9182a129f1e42d61da240213690f9320\", \"best_bid\":\"0.49\", \"best_ask\":\"0.5\"}, {\"asset_id\":\"14766054693214075530629349735273995982307625376442606753688071083149620216746\", \"price\":\"0.51\", \"size\":\"10\", \"side\":\"SELL\", \"hash\":\"7bddb399f1ce044f755fa6e7a85340fb8569444f\", \"best_bid\":\"0.5\", \"best_ask\":\"0.51\"}], \"timestamp\":\"1785130273215\", \"event_type\":\"price_change\"}","received_at":"2026-07-27T05:31:13.183933Z","schema_version":"clob-market-ws.price_change.v1","sequence":null,"server_hash":null,"server_timestamp":"1785130273215","session_id":"502006c5cfcd437296561ea750c9ec8b","source":"clob_market_ws"},"received_at":"2026-07-27T05:31:13.183933Z","record_id":"2ab13b248f941e0d1d71f655184aec5285b5c4526ca200b6ba6dd8a13792df1f","schema_fingerprint":"4aa3821a28b0b7c2400bc59aba4bcc0a76e971dadd19610d3ad38c768e124dc7","schema_version":"edge-lab-recorder.raw.v1","sequence":null,"source":"clob_market_ws"}
{"event_at":"2026-07-27T05:31:13.216000Z","event_fingerprint":"20c5ad4a24260ac4efe2343311332152beeb31f7e7080da90f5481976c2389aa","payload":{"connection_id":"efc69d3132f1467b8e898a382b23ac0d","event_at":"2026-07-27T05:31:13.216000Z","event_type":"best_bid_ask","frame_hash":"cd255b5818a3fea00da7d5a4af905f125c4a8ee0596d6862c92ae43795d7c322","frame_index":0,"kind":"data","monotonic_ns":232256426547291,"payload":{"asset_id":"14766054693214075530629349735273995982307625376442606753688071083149620216746","best_ask":"0.52","best_bid":"0.5","event_type":"best_bid_ask","market":"0x3b40066b5cf3871a2f6237c5628bd8092a206aa998558ac5ec13c4483e31e160","spread":"0.02","timestamp":"1785130273216"},"payload_hash":"0647bec7efd2517b7b27f01825faafbacf9b21bc14a13c25dcd67d36efc41b7f","raw_frame":"{\"market\":\"0x3b40066b5cf3871a2f6237c5628bd8092a206aa998558ac5ec13c4483e31e160\", \"asset_id\":\"14766054693214075530629349735273995982307625376442606753688071083149620216746\", \"best_bid\":\"0.5\", \"best_ask\":\"0.52\", \"spread\":\"0.02\", \"timestamp\":\"1785130273216\", \"event_type\":\"best_bid_ask\"}","received_at":"2026-07-27T05:31:13.188847Z","schema_version":"clob-market-ws.best_bid_ask.v1","sequence":null,"server_hash":null,"server_timestamp":"1785130273216","session_id":"502006c5cfcd437296561ea750c9ec8b","source":"clob_market_ws"},"received_at":"2026-07-27T05:31:13.188847Z","record_id":"5299a1bcc93ab8ff8fa14637c1395efe5d6d6792c25b1b4ef3a2288ac24f51d0","schema_fingerprint":"8488399f31b0337811b13b266be932db7062827c2470b78bd8e9e99bab51d17d","schema_version":"edge-lab-recorder.raw.v1","sequence":null,"source":"clob_market_ws"}
{"event_at":"2026-07-27T05:31:13.216000Z","event_fingerprint":"656aae810680ea1b956a917a119a895058c9a4d6590113c8b0cfed40fb1fc8bc","payload":{"connection_id":"efc69d3132f1467b8e898a382b23ac0d","event_at":"2026-07-27T05:31:13.216000Z","event_type":"best_bid_ask","frame_hash":"efa2e6a07cd8a91c9bab34087e3f690900da154ac7169977cbc6dce6ee8aa704","frame_index":0,"kind":"data","monotonic_ns":232256432886791,"payload":{"asset_id":"110216635572655435074987471276357323571387854733835379371586402147734167783946","best_ask":"0.5","best_bid":"0.48","event_type":"best_bid_ask","market":"0x3b40066b5cf3871a2f6237c5628bd8092a206aa998558ac5ec13c4483e31e160","spread":"0.02","timestamp":"1785130273216"},"payload_hash":"326ad2adfa7c4793a39245274d864e70e4e16aba97efd11e978058d1c829118d","raw_frame":"{\"market\":\"0x3b40066b5cf3871a2f6237c5628bd8092a206aa998558ac5ec13c4483e31e160\", \"asset_id\":\"110216635572655435074987471276357323571387854733835379371586402147734167783946\", \"best_bid\":\"0.48\", \"best_ask\":\"0.5\", \"spread\":\"0.02\", \"timestamp\":\"1785130273216\", \"event_type\":\"best_bid_ask\"}","received_at":"2026-07-27T05:31:13.195185Z","schema_version":"clob-market-ws.best_bid_ask.v1","sequence":null,"server_hash":null,"server_timestamp":"1785130273216","session_id":"502006c5cfcd437296561ea750c9ec8b","source":"clob_market_ws"},"received_at":"2026-07-27T05:31:13.195185Z","record_id":"f57cde9bc88ce19b394f16b0bbc14fc785f5c433b4b513b1f4b03ba56b3fcc51","schema_fingerprint":"8488399f31b0337811b13b266be932db7062827c2470b78bd8e9e99bab51d17d","schema_version":"edge-lab-recorder.raw.v1","sequence":null,"source":"clob_market_ws"}
{"event_at":"2026-07-27T05:31:13.216000Z","event_fingerprint":"d684e42f76dc2dca31444d618fe1082935845144e35424f70939631b368b2b7b","payload":{"connection_id":"efc69d3132f1467b8e898a382b23ac0d","event_at":"2026-07-27T05:31:13.216000Z","event_type":"price_change","frame_hash":"c82396e8f8f78dadcaedb0eb2d5ea9a2363a9b130e6e494af1d21338798dce17","frame_index":0,"kind":"data","monotonic_ns":232256438920541,"payload":{"event_type":"price_change","market":"0x3b40066b5cf3871a2f6237c5628bd8092a206aa998558ac5ec13c4483e31e160","price_changes":[{"asset_id":"110216635572655435074987471276357323571387854733835379371586402147734167783946","best_ask":"0.5","best_bid":"0.48","hash":"807c75f2e4f57222dbbfc93d7533b5899cf1c24c","price":"0.49","side":"BUY","size":"0"},{"asset_id":"14766054693214075530629349735273995982307625376442606753688071083149620216746","best_ask":"0.52","best_bid":"0.5","hash":"4b6833f95a26a70923cc47466d439655bca05da1","price":"0.51","side":"SELL","size":"0"}],"timestamp":"1785130273216"},"payload_hash":"394961ddd79dcd01d47ffe9c1bb001e63589f79fc13d38c0d1fcb49db6a57b12","raw_frame":"{\"market\":\"0x3b40066b5cf3871a2f6237c5628bd8092a206aa998558ac5ec13c4483e31e160\", \"price_changes\":[{\"asset_id\":\"110216635572655435074987471276357323571387854733835379371586402147734167783946\", \"price\":\"0.49\", \"size\":\"0\", \"side\":\"BUY\", \"hash\":\"807c75f2e4f57222dbbfc93d7533b5899cf1c24c\", \"best_bid\":\"0.48\", \"best_ask\":\"0.5\"}, {\"asset_id\":\"14766054693214075530629349735273995982307625376442606753688071083149620216746\", \"price\":\"0.51\", \"size\":\"0\", \"side\":\"SELL\", \"hash\":\"4b6833f95a26a70923cc47466d439655bca05da1\", \"best_bid\":\"0.5\", \"best_ask\":\"0.52\"}], \"timestamp\":\"1785130273216\", \"event_type\":\"price_change\"}","received_at":"2026-07-27T05:31:13.201220Z","schema_version":"clob-market-ws.price_change.v1","sequence":null,"server_hash":null,"server_timestamp":"1785130273216","session_id":"502006c5cfcd437296561ea750c9ec8b","source":"clob_market_ws"},"received_at":"2026-07-27T05:31:13.201220Z","record_id":"e5d75b02f301cb7f73fc157721e9f2d32e95a83d4172ecd99b0710e214a2eaca","schema_fingerprint":"4aa3821a28b0b7c2400bc59aba4bcc0a76e971dadd19610d3ad38c768e124dc7","schema_version":"edge-lab-recorder.raw.v1","sequence":null,"source":"clob_market_ws"}
{"event_at":"2026-07-27T05:31:13.233000Z","event_fingerprint":"0794eb433b1c34376e419127e33289bd0447fd1e6ba8dbf9bd43fdd2ba01637b","payload":{"connection_id":"efc69d3132f1467b8e898a382b23ac0d","event_at":"2026-07-27T05:31:13.233000Z","event_type":"price_change","frame_hash":"67a0066afbba2277782da56adcbb18c8ce0befd29f0e2849cf6c3f5cd057fe22","frame_index":0,"kind":"data","monotonic_ns":232256445260583,"payload":{"event_type":"price_change","market":"0x3b40066b5cf3871a2f6237c5628bd8092a206aa998558ac5ec13c4483e31e160","price_changes":[{"asset_id":"14766054693214075530629349735273995982307625376442606753688071083149620216746","best_ask":"0.52","best_bid":"0.5","hash":"ca5c34665f2bcec2933a2a76fda0c6dd77c8fcee","price":"0.5","side":"BUY","size":"393.4"},{"asset_id":"110216635572655435074987471276357323571387854733835379371586402147734167783946","best_ask":"0.5","best_bid":"0.48","hash":"d2f03e71743c7f57e64fc1814109fcfbd5143902","price":"0.5","side":"SELL","size":"393.4"}],"timestamp":"1785130273233"},"payload_hash":"c5a147398ab91efe7c3f6e93812c70a463a3110c9fa4b2af4f140c54becf68fc","raw_frame":"{\"market\":\"0x3b40066b5cf3871a2f6237c5628bd8092a206aa998558ac5ec13c4483e31e160\", \"price_changes\":[{\"asset_id\":\"14766054693214075530629349735273995982307625376442606753688071083149620216746\", \"price\":\"0.5\", \"size\":\"393.4\", \"side\":\"BUY\", \"hash\":\"ca5c34665f2bcec2933a2a76fda0c6dd77c8fcee\", \"best_bid\":\"0.5\", \"best_ask\":\"0.52\"}, {\"asset_id\":\"110216635572655435074987471276357323571387854733835379371586402147734167783946\", \"price\":\"0.5\", \"size\":\"393.4\", \"side\":\"SELL\", \"hash\":\"d2f03e71743c7f57e64fc1814109fcfbd5143902\", \"best_bid\":\"0.48\", \"best_ask\":\"0.5\"}], \"timestamp\":\"1785130273233\", \"event_type\":\"price_change\"}","received_at":"2026-07-27T05:31:13.207559Z","schema_version":"clob-market-ws.price_change.v1","sequence":null,"server_hash":null,"server_timestamp":"1785130273233","session_id":"502006c5cfcd437296561ea750c9ec8b","source":"clob_market_ws"},"received_at":"2026-07-27T05:31:13.207559Z","record_id":"76c2f089992443a13b7266b657bee96b98b125d23f06031b51ba7fef0177d34a","schema_fingerprint":"4aa3821a28b0b7c2400bc59aba4bcc0a76e971dadd19610d3ad38c768e124dc7","schema_version":"edge-lab-recorder.raw.v1","sequence":null,"source":"clob_market_ws"}
{"event_at":"2026-07-27T05:31:13.234000Z","event_fingerprint":"f9be81887b9c6b06e893912b2ab3f65568ccfe05e53a104daa8974f5a921890e","payload":{"connection_id":"efc69d3132f1467b8e898a382b23ac0d","event_at":"2026-07-27T05:31:13.234000Z","event_type":"price_change","frame_hash":"b743cda353d821561e5bf9b69f3c3b215344479748a45639309ed08a3a09c86c","frame_index":0,"kind":"data","monotonic_ns":232256450999666,"payload":{"event_type":"price_change","market":"0x3b40066b5cf3871a2f6237c5628bd8092a206aa998558ac5ec13c4483e31e160","price_changes":[{"asset_id":"110216635572655435074987471276357323571387854733835379371586402147734167783946","best_ask":"0.5","best_bid":"0.48","hash":"bae84961353ec0c8e95243abcbfec7764e9722af","price":"0.5","side":"SELL","size":"388.4"},{"asset_id":"14766054693214075530629349735273995982307625376442606753688071083149620216746","best_ask":"0.52","best_bid":"0.5","hash":"a09a1abcc2a6c6a8ac7857791b8b80f5569b3cbe","price":"0.5","side":"BUY","size":"388.4"}],"timestamp":"1785130273234"},"payload_hash":"abdfb01e2c8ae8eb4f95b982c3502ad752a2da05467ffe4dce40af4a20cf5099","raw_frame":"{\"market\":\"0x3b40066b5cf3871a2f6237c5628bd8092a206aa998558ac5ec13c4483e31e160\", \"price_changes\":[{\"asset_id\":\"110216635572655435074987471276357323571387854733835379371586402147734167783946\", \"price\":\"0.5\", \"size\":\"388.4\", \"side\":\"SELL\", \"hash\":\"bae84961353ec0c8e95243abcbfec7764e9722af\", \"best_bid\":\"0.48\", \"best_ask\":\"0.5\"}, {\"asset_id\":\"14766054693214075530629349735273995982307625376442606753688071083149620216746\", \"price\":\"0.5\", \"size\":\"388.4\", \"side\":\"BUY\", \"hash\":\"a09a1abcc2a6c6a8ac7857791b8b80f5569b3cbe\", \"best_bid\":\"0.5\", \"best_ask\":\"0.52\"}], \"timestamp\":\"1785130273234\", \"event_type\":\"price_change\"}","received_at":"2026-07-27T05:31:13.213298Z","schema_version":"clob-market-ws.price_change.v1","sequence":null,"server_hash":null,"server_timestamp":"1785130273234","session_id":"502006c5cfcd437296561ea750c9ec8b","source":"clob_market_ws"},"received_at":"2026-07-27T05:31:13.213298Z","record_id":"678443c0596df40d85d2bbc662ab7e6f9f134f6e0c17d2a37583d126063f9a94","schema_fingerprint":"4aa3821a28b0b7c2400bc59aba4bcc0a76e971dadd19610d3ad38c768e124dc7","schema_version":"edge-lab-recorder.raw.v1","sequence":null,"source":"clob_market_ws"}
{"event_at":"2026-07-27T05:31:13.238000Z","event_fingerprint":"e8b703b080905aaa29574edb7a6d43b0d22685ff1ac0a816255a7cfc5a3c03fc","payload":{"connection_id":"efc69d3132f1467b8e898a382b23ac0d","event_at":"2026-07-27T05:31:13.238000Z","event_type":"price_change","frame_hash":"3e4a7c3a53c6d224f2a6d3955ef2c1647d4efec7099cf9775c65d025011f6883","frame_index":0,"kind":"data","monotonic_ns":232256457401708,"payload":{"event_type":"price_change","market":"0x3b40066b5cf3871a2f6237c5628bd8092a206aa998558ac5ec13c4483e31e160","price_changes":[{"asset_id":"14766054693214075530629349735273995982307625376442606753688071083149620216746","best_ask":"0.52","best_bid":"0.5","hash":"ebe6d342e804c8b7a6e79b52d5d6e84ea13f193c","price":"0.5","side":"BUY","size":"383.4"},{"asset_id":"110216635572655435074987471276357323571387854733835379371586402147734167783946","best_ask":"0.5","best_bid":"0.48","hash":"d942b363024592c66f8e0adc83763d0fbbfee097","price":"0.5","side":"SELL","size":"383.4"}],"timestamp":"1785130273238"},"payload_hash":"d10656bca2df6577531e152df0a11f851e74b3e7b5818f139061bb16e21b3e9d","raw_frame":"{\"market\":\"0x3b40066b5cf3871a2f6237c5628bd8092a206aa998558ac5ec13c4483e31e160\", \"price_changes\":[{\"asset_id\":\"14766054693214075530629349735273995982307625376442606753688071083149620216746\", \"price\":\"0.5\", \"size\":\"383.4\", \"side\":\"BUY\", \"hash\":\"ebe6d342e804c8b7a6e79b52d5d6e84ea13f193c\", \"best_bid\":\"0.5\", \"best_ask\":\"0.52\"}, {\"asset_id\":\"110216635572655435074987471276357323571387854733835379371586402147734167783946\", \"price\":\"0.5\", \"size\":\"383.4\", \"side\":\"SELL\", \"hash\":\"d942b363024592c66f8e0adc83763d0fbbfee097\", \"best_bid\":\"0.48\", \"best_ask\":\"0.5\"}], \"timestamp\":\"1785130273238\", \"event_type\":\"price_change\"}","received_at":"2026-07-27T05:31:13.219702Z","schema_version":"clob-market-ws.price_change.v1","sequence":null,"server_hash":null,"server_timestamp":"1785130273238","session_id":"502006c5cfcd437296561ea750c9ec8b","source":"clob_market_ws"},"received_at":"2026-07-27T05:31:13.219702Z","record_id":"90fb90bebd34550bc86fb54243219781fb4467ccc9acb6109e1ff152124740de","schema_fingerprint":"4aa3821a28b0b7c2400bc59aba4bcc0a76e971dadd19610d3ad38c768e124dc7","schema_version":"edge-lab-recorder.raw.v1","sequence":null,"source":"clob_market_ws"}
{"event_at":"2026-07-27T05:31:13.239000Z","event_fingerprint":"04fef93ff2bc531be3e7b04d90664cb2ed13290bff6863b02f292e81abab35b2","payload":{"connection_id":"efc69d3132f1467b8e898a382b23ac0d","event_at":"2026-07-27T05:31:13.239000Z","event_type":"best_bid_ask","frame_hash":"599d4228645f3175b7d4cc914a00d94e2ec74fadb037ddbbfc814da6d48b37b7","frame_index":0,"kind":"data","monotonic_ns":232256460580541,"payload":{"asset_id":"14766054693214075530629349735273995982307625376442606753688071083149620216746","best_ask":"0.52","best_bid":"0.51","event_type":"best_bid_ask","market":"0x3b40066b5cf3871a2f6237c5628bd8092a206aa998558ac5ec13c4483e31e160","spread":"0.01","timestamp":"1785130273239"},"payload_hash":"c1b2274d11c7115546bdd133233f552c87ca70e8a9df8783f3e05161f2fd78cc","raw_frame":"{\"market\":\"0x3b40066b5cf3871a2f6237c5628bd8092a206aa998558ac5ec13c4483e31e160\", \"asset_id\":\"14766054693214075530629349735273995982307625376442606753688071083149620216746\", \"best_bid\":\"0.51\", \"best_ask\":\"0.52\", \"spread\":\"0.01\", \"timestamp\":\"1785130273239\", \"event_type\":\"best_bid_ask\"}","received_at":"2026-07-27T05:31:13.222880Z","schema_version":"clob-market-ws.best_bid_ask.v1","sequence":null,"server_hash":null,"server_timestamp":"1785130273239","session_id":"502006c5cfcd437296561ea750c9ec8b","source":"clob_market_ws"},"received_at":"2026-07-27T05:31:13.222880Z","record_id":"126d346ea9fced6409bf92e13929481fb72c53dd981443738362a77e93fbb613","schema_fingerprint":"8488399f31b0337811b13b266be932db7062827c2470b78bd8e9e99bab51d17d","schema_version":"edge-lab-recorder.raw.v1","sequence":null,"source":"clob_market_ws"}
{"event_at":"2026-07-27T05:31:13.239000Z","event_fingerprint":"1764297cb45f171206aa8f0d5e125499c476dca3cc5f55f30c79e9d6534602c8","payload":{"connection_id":"efc69d3132f1467b8e898a382b23ac0d","event_at":"2026-07-27T05:31:13.239000Z","event_type":"best_bid_ask","frame_hash":"6423b5e504fb865e68879642b2f61956af291777ae738c5ad804c8de7a73d372","frame_index":0,"kind":"data","monotonic_ns":232256465164750,"payload":{"asset_id":"110216635572655435074987471276357323571387854733835379371586402147734167783946","best_ask":"0.49","best_bid":"0.48","event_type":"best_bid_ask","market":"0x3b40066b5cf3871a2f6237c5628bd8092a206aa998558ac5ec13c4483e31e160","spread":"0.01","timestamp":"1785130273239"},"payload_hash":"f21cc8e735ac97c88afe850b543584c47e806d321ed18e2170f9b0809888b147","raw_frame":"{\"market\":\"0x3b40066b5cf3871a2f6237c5628bd8092a206aa998558ac5ec13c4483e31e160\", \"asset_id\":\"110216635572655435074987471276357323571387854733835379371586402147734167783946\", \"best_bid\":\"0.48\", \"best_ask\":\"0.49\", \"spread\":\"0.01\", \"timestamp\":\"1785130273239\", \"event_type\":\"best_bid_ask\"}","received_at":"2026-07-27T05:31:13.227464Z","schema_version":"clob-market-ws.best_bid_ask.v1","sequence":null,"server_hash":null,"server_timestamp":"1785130273239","session_id":"502006c5cfcd437296561ea750c9ec8b","source":"clob_market_ws"},"received_at":"2026-07-27T05:31:13.227464Z","record_id":"23eeeeb2f01f39b0adfc7e987e1ef3df6322b8ddc3a15986a1e3a516ca184835","schema_fingerprint":"8488399f31b0337811b13b266be932db7062827c2470b78bd8e9e99bab51d17d","schema_version":"edge-lab-recorder.raw.v1","sequence":null,"source":"clob_market_ws"}
{"event_at":"2026-07-27T05:31:13.239000Z","event_fingerprint":"f8b24e92ad0eed33805e69d21ddc0f4a3f428fdd61d8e65f4a986186a90a8969","payload":{"connection_id":"efc69d3132f1467b8e898a382b23ac0d","event_at":"2026-07-27T05:31:13.239000Z","event_type":"price_change","frame_hash":"689141f394ea934c9bb25171fd5b8200472f6b33378fc174127e6a6b6e945775","frame_index":0,"kind":"data","monotonic_ns":232256468773583,"payload":{"event_type":"price_change","market":"0x3b40066b5cf3871a2f6237c5628bd8092a206aa998558ac5ec13c4483e31e160","price_changes":[{"asset_id":"14766054693214075530629349735273995982307625376442606753688071083149620216746","best_ask":"0.52","best_bid":"0.51","hash":"a1eac793e08a379e932856799314bf8a0555b90c","price":"0.51","side":"BUY","size":"5"},{"asset_id":"110216635572655435074987471276357323571387854733835379371586402147734167783946","best_ask":"0.49","best_bid":"0.48","hash":"feb75d97b437f459a2f1f7bc5e2685a673c5537c","price":"0.49","side":"SELL","size":"5"}],"timestamp":"1785130273239"},"payload_hash":"9bddb5049e49d81a37ab51c6685a4071fa33cd3e7929276aceb217b622e4cc5a","raw_frame":"{\"market\":\"0x3b40066b5cf3871a2f6237c5628bd8092a206aa998558ac5ec13c4483e31e160\", \"price_changes\":[{\"asset_id\":\"14766054693214075530629349735273995982307625376442606753688071083149620216746\", \"price\":\"0.51\", \"size\":\"5\", \"side\":\"BUY\", \"hash\":\"a1eac793e08a379e932856799314bf8a0555b90c\", \"best_bid\":\"0.51\", \"best_ask\":\"0.52\"}, {\"asset_id\":\"110216635572655435074987471276357323571387854733835379371586402147734167783946\", \"price\":\"0.49\", \"size\":\"5\", \"side\":\"SELL\", \"hash\":\"feb75d97b437f459a2f1f7bc5e2685a673c5537c\", \"best_bid\":\"0.48\", \"best_ask\":\"0.49\"}], \"timestamp\":\"1785130273239\", \"event_type\":\"price_change\"}","received_at":"2026-07-27T05:31:13.231077Z","schema_version":"clob-market-ws.price_change.v1","sequence":null,"server_hash":null,"server_timestamp":"1785130273239","session_id":"502006c5cfcd437296561ea750c9ec8b","source":"clob_market_ws"},"received_at":"2026-07-27T05:31:13.231077Z","record_id":"92c919c11f12be764132d08469802ac7fcc23a51cad08d8721b7ec91ab588a82","schema_fingerprint":"4aa3821a28b0b7c2400bc59aba4bcc0a76e971dadd19610d3ad38c768e124dc7","schema_version":"edge-lab-recorder.raw.v1","sequence":null,"source":"clob_market_ws"}
{"event_at":"2026-07-27T05:31:13.240000Z","event_fingerprint":"55045671cfc53e191f92ad49d734543f8e64acdbd19abb75dfe516607f8a8a43","payload":{"connection_id":"efc69d3132f1467b8e898a382b23ac0d","event_at":"2026-07-27T05:31:13.240000Z","event_type":"price_change","frame_hash":"d76cfe2cc439c3ebb2f39e6c72c2f3e0b5ee15d893fb09bf4e1105a4ce32f546","frame_index":0,"kind":"data","monotonic_ns":232256474070333,"payload":{"event_type":"price_change","market":"0x3b40066b5cf3871a2f6237c5628bd8092a206aa998558ac5ec13c4483e31e160","price_changes":[{"asset_id":"14766054693214075530629349735273995982307625376442606753688071083149620216746","best_ask":"0.52","best_bid":"0.51","hash":"4fbb7cc0997e29e6f885a7af44a835ef4f0433d2","price":"0.51","side":"BUY","size":"10"},{"asset_id":"110216635572655435074987471276357323571387854733835379371586402147734167783946","best_ask":"0.49","best_bid":"0.48","hash":"3a87569d2253e9e1976729b07cb43ff59a0b369e","price":"0.49","side":"SELL","size":"10"}],"timestamp":"1785130273240"},"payload_hash":"a6fd6409791fd244e8d5732be74d94b09d72e4d0f88652e0ec87ca67073b00f7","raw_frame":"{\"market\":\"0x3b40066b5cf3871a2f6237c5628bd8092a206aa998558ac5ec13c4483e31e160\", \"price_changes\":[{\"asset_id\":\"14766054693214075530629349735273995982307625376442606753688071083149620216746\", \"price\":\"0.51\", \"size\":\"10\", \"side\":\"BUY\", \"hash\":\"4fbb7cc0997e29e6f885a7af44a835ef4f0433d2\", \"best_bid\":\"0.51\", \"best_ask\":\"0.52\"}, {\"asset_id\":\"110216635572655435074987471276357323571387854733835379371586402147734167783946\", \"price\":\"0.49\", \"size\":\"10\", \"side\":\"SELL\", \"hash\":\"3a87569d2253e9e1976729b07cb43ff59a0b369e\", \"best_bid\":\"0.48\", \"best_ask\":\"0.49\"}], \"timestamp\":\"1785130273240\", \"event_type\":\"price_change\"}","received_at":"2026-07-27T05:31:13.236371Z","schema_version":"clob-market-ws.price_change.v1","sequence":null,"server_hash":null,"server_timestamp":"1785130273240","session_id":"502006c5cfcd437296561ea750c9ec8b","source":"clob_market_ws"},"received_at":"2026-07-27T05:31:13.236371Z","record_id":"cc42a90ddf3ea30f48206006332e7e7db5c705d182ef5471b5ae9a2b8baca24d","schema_fingerprint":"4aa3821a28b0b7c2400bc59aba4bcc0a76e971dadd19610d3ad38c768e124dc7","schema_version":"edge-lab-recorder.raw.v1","sequence":null,"source":"clob_market_ws"}
{"event_at":"2026-07-27T05:31:13.241000Z","event_fingerprint":"b477a7d9f4e236ef6e94d46b09517346fa76180776f15cacb26b93d079aaa57d","payload":{"connection_id":"efc69d3132f1467b8e898a382b23ac0d","event_at":"2026-07-27T05:31:13.241000Z","event_type":"price_change","frame_hash":"cd325488af3c3c6b535a973e8080fda0b5ab934c089e00c983e6fd1acdbe1a10","frame_index":0,"kind":"data","monotonic_ns":232256481322625,"payload":{"event_type":"price_change","market":"0x3b40066b5cf3871a2f6237c5628bd8092a206aa998558ac5ec13c4483e31e160","price_changes":[{"asset_id":"14766054693214075530629349735273995982307625376442606753688071083149620216746","best_ask":"0.52","best_bid":"0.51","hash":"04bcaec4263bcfe98ae4c18c07c17e6766d5230a","price":"0.51","side":"BUY","size":"15"},{"asset_id":"110216635572655435074987471276357323571387854733835379371586402147734167783946","best_ask":"0.49","best_bid":"0.48","hash":"253de8119e01d298a0234323b41a9d5570ebb42c","price":"0.49","side":"SELL","size":"15"}],"timestamp":"1785130273241"},"payload_hash":"37ae396b9755b4dfaa776f3b5c4c7c2f8d00d21e1086ef4929c5292c4cbffa09","raw_frame":"{\"market\":\"0x3b40066b5cf3871a2f6237c5628bd8092a206aa998558ac5ec13c4483e31e160\", \"price_changes\":[{\"asset_id\":\"14766054693214075530629349735273995982307625376442606753688071083149620216746\", \"price\":\"0.51\", \"size\":\"15\", \"side\":\"BUY\", \"hash\":\"04bcaec4263bcfe98ae4c18c07c17e6766d5230a\", \"best_bid\":\"0.51\", \"best_ask\":\"0.52\"}, {\"asset_id\":\"110216635572655435074987471276357323571387854733835379371586402147734167783946\", \"price\":\"0.49\", \"size\":\"15\", \"side\":\"SELL\", \"hash\":\"253de8119e01d298a0234323b41a9d5570ebb42c\", \"best_bid\":\"0.48\", \"best_ask\":\"0.49\"}], \"timestamp\":\"1785130273241\", \"event_type\":\"price_change\"}","received_at":"2026-07-27T05:31:13.243621Z","schema_version":"clob-market-ws.price_change.v1","sequence":null,"server_hash":null,"server_timestamp":"1785130273241","session_id":"502006c5cfcd437296561ea750c9ec8b","source":"clob_market_ws"},"received_at":"2026-07-27T05:31:13.243621Z","record_id":"74a37417424e72ae20c277a0a44dc1e19f243882d1ab7512ba71bba45db612b2","schema_fingerprint":"4aa3821a28b0b7c2400bc59aba4bcc0a76e971dadd19610d3ad38c768e124dc7","schema_version":"edge-lab-recorder.raw.v1","sequence":null,"source":"clob_market_ws"}
{"event_at":"2026-07-27T05:31:13.243000Z","event_fingerprint":"9fae1c9b12b788ca276f6338892bc4e0db15cf6b14f15321418c3ca208ff6ef8","payload":{"connection_id":"efc69d3132f1467b8e898a382b23ac0d","event_at":"2026-07-27T05:31:13.243000Z","event_type":"price_change","frame_hash":"30135141fe531e506a85b941a5729fe6bd87994a13373654e8fa9081a710561c","frame_index":0,"kind":"data","monotonic_ns":232256485679708,"payload":{"event_type":"price_change","market":"0x3b40066b5cf3871a2f6237c5628bd8092a206aa998558ac5ec13c4483e31e160","price_changes":[{"asset_id":"110216635572655435074987471276357323571387854733835379371586402147734167783946","best_ask":"0.49","best_bid":"0.48","hash":"1ee8f81f275270023d2267364d599f595a61c744","price":"0.48","side":"BUY","size":"65.6"},{"asset_id":"14766054693214075530629349735273995982307625376442606753688071083149620216746","best_ask":"0.52","best_bid":"0.51","hash":"f58cfc92ce095ba2b0d610dc7251392600a25552","price":"0.52","side":"SELL","size":"65.6"}],"timestamp":"1785130273243"},"payload_hash":"53ccab74fc821e98663529153c646b122355a6afdac29fca590c6769047a017e","raw_frame":"{\"market\":\"0x3b40066b5cf3871a2f6237c5628bd8092a206aa998558ac5ec13c4483e31e160\", \"price_changes\":[{\"asset_id\":\"110216635572655435074987471276357323571387854733835379371586402147734167783946\", \"price\":\"0.48\", \"size\":\"65.6\", \"side\":\"BUY\", \"hash\":\"1ee8f81f275270023d2267364d599f595a61c744\", \"best_bid\":\"0.48\", \"best_ask\":\"0.49\"}, {\"asset_id\":\"14766054693214075530629349735273995982307625376442606753688071083149620216746\", \"price\":\"0.52\", \"size\":\"65.6\", \"side\":\"SELL\", \"hash\":\"f58cfc92ce095ba2b0d610dc7251392600a25552\", \"best_bid\":\"0.51\", \"best_ask\":\"0.52\"}], \"timestamp\":\"1785130273243\", \"event_type\":\"price_change\"}","received_at":"2026-07-27T05:31:13.247979Z","schema_version":"clob-market-ws.price_change.v1","sequence":null,"server_hash":null,"server_timestamp":"1785130273243","session_id":"502006c5cfcd437296561ea750c9ec8b","source":"clob_market_ws"},"received_at":"2026-07-27T05:31:13.247979Z","record_id":"f591813cdaff04c0c801560683f236c2bbba9b8999d5cefe5d65c0cf1a62998c","schema_fingerprint":"4aa3821a28b0b7c2400bc59aba4bcc0a76e971dadd19610d3ad38c768e124dc7","schema_version":"edge-lab-recorder.raw.v1","sequence":null,"source":"clob_market_ws"}
{"event_at":"2026-07-27T05:31:13.244000Z","event_fingerprint":"01a087f483c8ce03875a1c322d1086df22afda2881d569372c1abfe75e2e1f1e","payload":{"connection_id":"efc69d3132f1467b8e898a382b23ac0d","event_at":"2026-07-27T05:31:13.244000Z","event_type":"price_change","frame_hash":"75484ab0be1a5a5dc1968f10fdfac3d4abb9d7888913e3748ebed964e0d73501","frame_index":0,"kind":"data","monotonic_ns":232256491510291,"payload":{"event_type":"price_change","market":"0x3b40066b5cf3871a2f6237c5628bd8092a206aa998558ac5ec13c4483e31e160","price_changes":[{"asset_id":"14766054693214075530629349735273995982307625376442606753688071083149620216746","best_ask":"0.52","best_bid":"0.51","hash":"7eea82ee02e9abafae166aee71c9963d65e12d39","price":"0.01","side":"BUY","size":"7878.02"},{"asset_id":"110216635572655435074987471276357323571387854733835379371586402147734167783946","best_ask":"0.49","best_bid":"0.48","hash":"0b92584cc1f9d9729762dcfe42160d3adddf4c77","price":"0.99","side":"SELL","size":"7878.02"}],"timestamp":"1785130273244"},"payload_hash":"f82febef109e121e730f2d2c02b9350e8641e1855e61ea3bbd44bbd63aa3d038","raw_frame":"{\"market\":\"0x3b40066b5cf3871a2f6237c5628bd8092a206aa998558ac5ec13c4483e31e160\", \"price_changes\":[{\"asset_id\":\"14766054693214075530629349735273995982307625376442606753688071083149620216746\", \"price\":\"0.01\", \"size\":\"7878.02\", \"side\":\"BUY\", \"hash\":\"7eea82ee02e9abafae166aee71c9963d65e12d39\", \"best_bid\":\"0.51\", \"best_ask\":\"0.52\"}, {\"asset_id\":\"110216635572655435074987471276357323571387854733835379371586402147734167783946\", \"price\":\"0.99\", \"size\":\"7878.02\", \"side\":\"SELL\", \"hash\":\"0b92584cc1f9d9729762dcfe42160d3adddf4c77\", \"best_bid\":\"0.48\", \"best_ask\":\"0.49\"}], \"timestamp\":\"1785130273244\", \"event_type\":\"price_change\"}","received_at":"2026-07-27T05:31:13.253810Z","schema_version":"clob-market-ws.price_change.v1","sequence":null,"server_hash":null,"server_timestamp":"1785130273244","session_id":"502006c5cfcd437296561ea750c9ec8b","source":"clob_market_ws"},"received_at":"2026-07-27T05:31:13.253810Z","record_id":"783c488c486761c87e6b283014a6950767f7e47bad13f3f5a09740654c819fbf","schema_fingerprint":"4aa3821a28b0b7c2400bc59aba4bcc0a76e971dadd19610d3ad38c768e124dc7","schema_version":"edge-lab-recorder.raw.v1","sequence":null,"source":"clob_market_ws"}
{"event_at":"2026-07-27T05:31:13.249000Z","event_fingerprint":"516c9cbf96fd9eb7dbe8f10d257ac9b82af53f63991fe3e9bdb7e1124c62c06c","payload":{"connection_id":"efc69d3132f1467b8e898a382b23ac0d","event_at":"2026-07-27T05:31:13.249000Z","event_type":"price_change","frame_hash":"e06cb08401b3aca105ea462cf54e290f1fbd48598c4ef980c1fd12edda3d7dfb","frame_index":0,"kind":"data","monotonic_ns":232256497451291,"payload":{"event_type":"price_change","market":"0x3b40066b5cf3871a2f6237c5628bd8092a206aa998558ac5ec13c4483e31e160","price_changes":[{"asset_id":"14766054693214075530629349735273995982307625376442606753688071083149620216746","best_ask":"0.52","best_bid":"0.51","hash":"5258f9a31f94a199ddad1670071949f6fd8b882c","price":"0.51","side":"BUY","size":"20"},{"asset_id":"110216635572655435074987471276357323571387854733835379371586402147734167783946","best_ask":"0.49","best_bid":"0.48","hash":"63d17e4c881e41efbcba7ba6280b477a3f58034e","price":"0.49","side":"SELL","size":"20"}],"timestamp":"1785130273249"},"payload_hash":"fb2eecfbebdde8a0b9817f4f96cdbec71501afcc285a8ba123f1cc48475819e5","raw_frame":"{\"market\":\"0x3b40066b5cf3871a2f6237c5628bd8092a206aa998558ac5ec13c4483e31e160\", \"price_changes\":[{\"asset_id\":\"14766054693214075530629349735273995982307625376442606753688071083149620216746\", \"price\":\"0.51\", \"size\":\"20\", \"side\":\"BUY\", \"hash\":\"5258f9a31f94a199ddad1670071949f6fd8b882c\", \"best_bid\":\"0.51\", \"best_ask\":\"0.52\"}, {\"asset_id\":\"110216635572655435074987471276357323571387854733835379371586402147734167783946\", \"price\":\"0.49\", \"size\":\"20\", \"side\":\"SELL\", \"hash\":\"63d17e4c881e41efbcba7ba6280b477a3f58034e\", \"best_bid\":\"0.48\", \"best_ask\":\"0.49\"}], \"timestamp\":\"1785130273249\", \"event_type\":\"price_change\"}","received_at":"2026-07-27T05:31:13.259745Z","schema_version":"clob-market-ws.price_change.v1","sequence":null,"server_hash":null,"server_timestamp":"1785130273249","session_id":"502006c5cfcd437296561ea750c9ec8b","source":"clob_market_ws"},"received_at":"2026-07-27T05:31:13.259745Z","record_id":"b52c256faa9a5cf973e25e6dc5e47218c66098594ee3ce5641b328a331d7dfa1","schema_fingerprint":"4aa3821a28b0b7c2400bc59aba4bcc0a76e971dadd19610d3ad38c768e124dc7","schema_version":"edge-lab-recorder.raw.v1","sequence":null,"source":"clob_market_ws"}
{"event_at":"2026-07-27T05:31:13.262000Z","event_fingerprint":"ab4626ecf3af2f1a75bafca89e7078811747ed7f7ab83b39b419759dcfdb0bd0","payload":{"connection_id":"efc69d3132f1467b8e898a382b23ac0d","event_at":"2026-07-27T05:31:13.262000Z","event_type":"price_change","frame_hash":"6439530dd0bc648740870b82db9b0fb7f0cc577639a631a80a26318840779e05","frame_index":0,"kind":"data","monotonic_ns":232256502204416,"payload":{"event_type":"price_change","market":"0x3b40066b5cf3871a2f6237c5628bd8092a206aa998558ac5ec13c4483e31e160","price_changes":[{"asset_id":"14766054693214075530629349735273995982307625376442606753688071083149620216746","best_ask":"0.52","best_bid":"0.51","hash":"34b8ff39339a72c1a7d16349f01e8f2cf1d78e35","price":"0.5","side":"BUY","size":"358.4"},{"asset_id":"110216635572655435074987471276357323571387854733835379371586402147734167783946","best_ask":"0.49","best_bid":"0.48","hash":"99e929430dd027aa62886a2fe4ddeda1d6f85098","price":"0.5","side":"SELL","size":"358.4"}],"timestamp":"1785130273262"},"payload_hash":"c2d589bbac86af179f90c41a3e386aeb662f519eaf0006d27eb1136d485650ba","raw_frame":"{\"market\":\"0x3b40066b5cf3871a2f6237c5628bd8092a206aa998558ac5ec13c4483e31e160\", \"price_changes\":[{\"asset_id\":\"14766054693214075530629349735273995982307625376442606753688071083149620216746\", \"price\":\"0.5\", \"size\":\"358.4\", \"side\":\"BUY\", \"hash\":\"34b8ff39339a72c1a7d16349f01e8f2cf1d78e35\", \"best_bid\":\"0.51\", \"best_ask\":\"0.52\"}, {\"asset_id\":\"110216635572655435074987471276357323571387854733835379371586402147734167783946\", \"price\":\"0.5\", \"size\":\"358.4\", \"side\":\"SELL\", \"hash\":\"99e929430dd027aa62886a2fe4ddeda1d6f85098\", \"best_bid\":\"0.48\", \"best_ask\":\"0.49\"}], \"timestamp\":\"1785130273262\", \"event_type\":\"price_change\"}","received_at":"2026-07-27T05:31:13.264505Z","schema_version":"clob-market-ws.price_change.v1","sequence":null,"server_hash":null,"server_timestamp":"1785130273262","session_id":"502006c5cfcd437296561ea750c9ec8b","source":"clob_market_ws"},"received_at":"2026-07-27T05:31:13.264505Z","record_id":"99846a15a0f51e415c9435becb6ed6e68383dce1513ac9ed9d91a8b851e0d789","schema_fingerprint":"4aa3821a28b0b7c2400bc59aba4bcc0a76e971dadd19610d3ad38c768e124dc7","schema_version":"edge-lab-recorder.raw.v1","sequence":null,"source":"clob_market_ws"}
{"event_at":"2026-07-27T05:31:13.272000Z","event_fingerprint":"5c2c268a0db05439749c063cb747ddb51708ddaadf81fcce65b002fde6703607","payload":{"connection_id":"efc69d3132f1467b8e898a382b23ac0d","event_at":"2026-07-27T05:31:13.272000Z","event_type":"price_change","frame_hash":"307432ac0c1a64e071d482d9271b32be0b269e2ab6e2114025b99e3bbb33ee6f","frame_index":0,"kind":"data","monotonic_ns":232256507207166,"payload":{"event_type":"price_change","market":"0x3b40066b5cf3871a2f6237c5628bd8092a206aa998558ac5ec13c4483e31e160","price_changes":[{"asset_id":"14766054693214075530629349735273995982307625376442606753688071083149620216746","best_ask":"0.52","best_bid":"0.51","hash":"3d2fd57b15f1a96c225b109462a96497c4c537fc","price":"0.45","side":"BUY","size":"81"},{"asset_id":"110216635572655435074987471276357323571387854733835379371586402147734167783946","best_ask":"0.49","best_bid":"0.48","hash":"1797a53b2291becac4d6ed12d0d9caed09fbfcde","price":"0.55","side":"SELL","size":"81"}],"timestamp":"1785130273272"},"payload_hash":"8fe9c7491fd64c0d6ef75d96edc6b02f8bfba657aa9104889548fba593eceb20","raw_frame":"{\"market\":\"0x3b40066b5cf3871a2f6237c5628bd8092a206aa998558ac5ec13c4483e31e160\", \"price_changes\":[{\"asset_id\":\"14766054693214075530629349735273995982307625376442606753688071083149620216746\", \"price\":\"0.45\", \"size\":\"81\", \"side\":\"BUY\", \"hash\":\"3d2fd57b15f1a96c225b109462a96497c4c537fc\", \"best_bid\":\"0.51\", \"best_ask\":\"0.52\"}, {\"asset_id\":\"110216635572655435074987471276357323571387854733835379371586402147734167783946\", \"price\":\"0.55\", \"size\":\"81\", \"side\":\"SELL\", \"hash\":\"1797a53b2291becac4d6ed12d0d9caed09fbfcde\", \"best_bid\":\"0.48\", \"best_ask\":\"0.49\"}], \"timestamp\":\"1785130273272\", \"event_type\":\"price_change\"}","received_at":"2026-07-27T05:31:13.269508Z","schema_version":"clob-market-ws.price_change.v1","sequence":null,"server_hash":null,"server_timestamp":"1785130273272","session_id":"502006c5cfcd437296561ea750c9ec8b","source":"clob_market_ws"},"received_at":"2026-07-27T05:31:13.269508Z","record_id":"f63c74bc11b00bb6770f75ee8adce5f7c8487bb9a8af201aad27d2779bb5b989","schema_fingerprint":"4aa3821a28b0b7c2400bc59aba4bcc0a76e971dadd19610d3ad38c768e124dc7","schema_version":"edge-lab-recorder.raw.v1","sequence":null,"source":"clob_market_ws"}
{"event_at":"2026-07-27T05:31:13.286000Z","event_fingerprint":"30e4d5cbdc4a593eb90a1efe1883e3bf6730d6d347c8ecd805ba4e9f653f4a11","payload":{"connection_id":"efc69d3132f1467b8e898a382b23ac0d","event_at":"2026-07-27T05:31:13.286000Z","event_type":"price_change","frame_hash":"4643cec40033153b11348465c3676defc6942bb78d157660482a3db8d9ce0b33","frame_index":0,"kind":"data","monotonic_ns":232256514292500,"payload":{"event_type":"price_change","market":"0x3b40066b5cf3871a2f6237c5628bd8092a206aa998558ac5ec13c4483e31e160","price_changes":[{"asset_id":"14766054693214075530629349735273995982307625376442606753688071083149620216746","best_ask":"0.52","best_bid":"0.51","hash":"8f2c7a87037830a60c5bc6e9e3b9d2a552ff5a42","price":"0.49","side":"BUY","size":"166.4"},{"asset_id":"110216635572655435074987471276357323571387854733835379371586402147734167783946","best_ask":"0.49","best_bid":"0.48","hash":"4210c3509a72b5399e576c2ff6f9cfa258f5c1ed","price":"0.51","side":"SELL","size":"166.4"}],"timestamp":"1785130273286"},"payload_hash":"9f60c539e3dcf07a2cbc10e34da19c8cfc80a67d3cd3a48c3c18c68f068967d3","raw_frame":"{\"market\":\"0x3b40066b5cf3871a2f6237c5628bd8092a206aa998558ac5ec13c4483e31e160\", \"price_changes\":[{\"asset_id\":\"14766054693214075530629349735273995982307625376442606753688071083149620216746\", \"price\":\"0.49\", \"size\":\"166.4\", \"side\":\"BUY\", \"hash\":\"8f2c7a87037830a60c5bc6e9e3b9d2a552ff5a42\", \"best_bid\":\"0.51\", \"best_ask\":\"0.52\"}, {\"asset_id\":\"110216635572655435074987471276357323571387854733835379371586402147734167783946\", \"price\":\"0.51\", \"size\":\"166.4\", \"side\":\"SELL\", \"hash\":\"4210c3509a72b5399e576c2ff6f9cfa258f5c1ed\", \"best_bid\":\"0.48\", \"best_ask\":\"0.49\"}], \"timestamp\":\"1785130273286\", \"event_type\":\"price_change\"}","received_at":"2026-07-27T05:31:13.276591Z","schema_version":"clob-market-ws.price_change.v1","sequence":null,"server_hash":null,"server_timestamp":"1785130273286","session_id":"502006c5cfcd437296561ea750c9ec8b","source":"clob_market_ws"},"received_at":"2026-07-27T05:31:13.276591Z","record_id":"acb6efc219ef1ad26179620c4614650ca99baeb1706d9cf53fcc3db2bd2104fc","schema_fingerprint":"4aa3821a28b0b7c2400bc59aba4bcc0a76e971dadd19610d3ad38c768e124dc7","schema_version":"edge-lab-recorder.raw.v1","sequence":null,"source":"clob_market_ws"}
{"event_at":"2026-07-27T05:31:13.287000Z","event_fingerprint":"9f82aacce79ae7639048cef2d26f55bdbd234f9c9d205c7619245ba2a12f4c24","payload":{"connection_id":"efc69d3132f1467b8e898a382b23ac0d","event_at":"2026-07-27T05:31:13.287000Z","event_type":"price_change","frame_hash":"f1a10732c627ac21ae7e3e39730066b311ef654cc845fc5faed459c1b93eebf5","frame_index":0,"kind":"data","monotonic_ns":232256518850333,"payload":{"event_type":"price_change","market":"0x3b40066b5cf3871a2f6237c5628bd8092a206aa998558ac5ec13c4483e31e160","price_changes":[{"asset_id":"14766054693214075530629349735273995982307625376442606753688071083149620216746","best_ask":"0.52","best_bid":"0.51","hash":"c4479fc7ea523307bd6b9e4736f3851d8b804072","price":"0.49","side":"BUY","size":"177.4"},{"asset_id":"110216635572655435074987471276357323571387854733835379371586402147734167783946","best_ask":"0.49","best_bid":"0.48","hash":"469b9048335a229f3491135ecdb59f18a3ce002a","price":"0.51","side":"SELL","size":"177.4"}],"timestamp":"1785130273287"},"payload_hash":"b9a400d3b3db18388dbfb01f9f9ea89a91eb0f5f1b1901fd722f28c941d8aea3","raw_frame":"{\"market\":\"0x3b40066b5cf3871a2f6237c5628bd8092a206aa998558ac5ec13c4483e31e160\", \"price_changes\":[{\"asset_id\":\"14766054693214075530629349735273995982307625376442606753688071083149620216746\", \"price\":\"0.49\", \"size\":\"177.4\", \"side\":\"BUY\", \"hash\":\"c4479fc7ea523307bd6b9e4736f3851d8b804072\", \"best_bid\":\"0.51\", \"best_ask\":\"0.52\"}, {\"asset_id\":\"110216635572655435074987471276357323571387854733835379371586402147734167783946\", \"price\":\"0.51\", \"size\":\"177.4\", \"side\":\"SELL\", \"hash\":\"469b9048335a229f3491135ecdb59f18a3ce002a\", \"best_bid\":\"0.48\", \"best_ask\":\"0.49\"}], \"timestamp\":\"1785130273287\", \"event_type\":\"price_change\"}","received_at":"2026-07-27T05:31:13.281151Z","schema_version":"clob-market-ws.price_change.v1","sequence":null,"server_hash":null,"server_timestamp":"1785130273287","session_id":"502006c5cfcd437296561ea750c9ec8b","source":"clob_market_ws"},"received_at":"2026-07-27T05:31:13.281151Z","record_id":"5992a85a8cf4a9643d13b43dceb490f7990b26c803b6097d99f463d5c9c724c5","schema_fingerprint":"4aa3821a28b0b7c2400bc59aba4bcc0a76e971dadd19610d3ad38c768e124dc7","schema_version":"edge-lab-recorder.raw.v1","sequence":null,"source":"clob_market_ws"}
{"event_at":"2026-07-27T05:31:13.288000Z","event_fingerprint":"dd5f74129940713c7c7a99ff90e077f792f1c0d7b8af8d7cc60c38541011c027","payload":{"connection_id":"efc69d3132f1467b8e898a382b23ac0d","event_at":"2026-07-27T05:31:13.288000Z","event_type":"price_change","frame_hash":"b7d8d1e76834f1fdf4329b03fc36cecb9d94f630f04d8b3901bc26ac4384440d","frame_index":0,"kind":"data","monotonic_ns":232256523996958,"payload":{"event_type":"price_change","market":"0x3b40066b5cf3871a2f6237c5628bd8092a206aa998558ac5ec13c4483e31e160","price_changes":[{"asset_id":"14766054693214075530629349735273995982307625376442606753688071083149620216746","best_ask":"0.52","best_bid":"0.51","hash":"5878e8791ca3d4dc2103e0ce6851f988ac756082","price":"0.51","side":"BUY","size":"45"},{"asset_id":"110216635572655435074987471276357323571387854733835379371586402147734167783946","best_ask":"0.49","best_bid":"0.48","hash":"80f7c3c4b120caa9f2561cb125126303a8b0cb03","price":"0.49","side":"SELL","size":"45"}],"timestamp":"1785130273288"},"payload_hash":"0ef4f6c18fa1c39ccda9f06ef13c5c87402c7cdcb234aa97806ea6e8d30ef0e0","raw_frame":"{\"market\":\"0x3b40066b5cf3871a2f6237c5628bd8092a206aa998558ac5ec13c4483e31e160\", \"price_changes\":[{\"asset_id\":\"14766054693214075530629349735273995982307625376442606753688071083149620216746\", \"price\":\"0.51\", \"size\":\"45\", \"side\":\"BUY\", \"hash\":\"5878e8791ca3d4dc2103e0ce6851f988ac756082\", \"best_bid\":\"0.51\", \"best_ask\":\"0.52\"}, {\"asset_id\":\"110216635572655435074987471276357323571387854733835379371586402147734167783946\", \"price\":\"0.49\", \"size\":\"45\", \"side\":\"SELL\", \"hash\":\"80f7c3c4b120caa9f2561cb125126303a8b0cb03\", \"best_bid\":\"0.48\", \"best_ask\":\"0.49\"}], \"timestamp\":\"1785130273288\", \"event_type\":\"price_change\"}","received_at":"2026-07-27T05:31:13.286296Z","schema_version":"clob-market-ws.price_change.v1","sequence":null,"server_hash":null,"server_timestamp":"1785130273288","session_id":"502006c5cfcd437296561ea750c9ec8b","source":"clob_market_ws"},"received_at":"2026-07-27T05:31:13.286296Z","record_id":"64961b794ba9608d9dee498c7d9b254f04aad3aa6c7410d71bc0b5b9df7174a8","schema_fingerprint":"4aa3821a28b0b7c2400bc59aba4bcc0a76e971dadd19610d3ad38c768e124dc7","schema_version":"edge-lab-recorder.raw.v1","sequence":null,"source":"clob_market_ws"}
{"event_at":"2026-07-27T05:31:13.296000Z","event_fingerprint":"1f4456375fd00d5a765da5d738dec5ac3517dec7e01f01f8278c7306fac65505","payload":{"connection_id":"efc69d3132f1467b8e898a382b23ac0d","event_at":"2026-07-27T05:31:13.296000Z","event_type":"price_change","frame_hash":"b74221f4f6eb53d3cf5a4fd0d8f3895cda55417e287b45d0f5fc346546bc6f1a","frame_index":0,"kind":"data","monotonic_ns":232256529058041,"payload":{"event_type":"price_change","market":"0x3b40066b5cf3871a2f6237c5628bd8092a206aa998558ac5ec13c4483e31e160","price_changes":[{"asset_id":"14766054693214075530629349735273995982307625376442606753688071083149620216746","best_ask":"0.52","best_bid":"0.51","hash":"510f8521f7d76e6b3aaa0cddce45c2af8c6a4373","price":"0.51","side":"BUY","size":"52"},{"asset_id":"110216635572655435074987471276357323571387854733835379371586402147734167783946","best_ask":"0.49","best_bid":"0.48","hash":"4f517722b82ac96ef84c5a97b1b1471a7a7ffde8","price":"0.49","side":"SELL","size":"52"}],"timestamp":"1785130273296"},"payload_hash":"f9411f2b584bc0bc77214b5dbbf112c6cf3cd5ca28286db562c05eb259f66d12","raw_frame":"{\"market\":\"0x3b40066b5cf3871a2f6237c5628bd8092a206aa998558ac5ec13c4483e31e160\", \"price_changes\":[{\"asset_id\":\"14766054693214075530629349735273995982307625376442606753688071083149620216746\", \"price\":\"0.51\", \"size\":\"52\", \"side\":\"BUY\", \"hash\":\"510f8521f7d76e6b3aaa0cddce45c2af8c6a4373\", \"best_bid\":\"0.51\", \"best_ask\":\"0.52\"}, {\"asset_id\":\"110216635572655435074987471276357323571387854733835379371586402147734167783946\", \"price\":\"0.49\", \"size\":\"52\", \"side\":\"SELL\", \"hash\":\"4f517722b82ac96ef84c5a97b1b1471a7a7ffde8\", \"best_bid\":\"0.48\", \"best_ask\":\"0.49\"}], \"timestamp\":\"1785130273296\", \"event_type\":\"price_change\"}","received_at":"2026-07-27T05:31:13.291357Z","schema_version":"clob-market-ws.price_change.v1","sequence":null,"server_hash":null,"server_timestamp":"1785130273296","session_id":"502006c5cfcd437296561ea750c9ec8b","source":"clob_market_ws"},"received_at":"2026-07-27T05:31:13.291357Z","record_id":"ab134f56d934b7ae167ee73cbf3231e92f6c42ba7bb01de362778a17b43b474e","schema_fingerprint":"4aa3821a28b0b7c2400bc59aba4bcc0a76e971dadd19610d3ad38c768e124dc7","schema_version":"edge-lab-recorder.raw.v1","sequence":null,"source":"clob_market_ws"}
{"event_at":"2026-07-27T05:31:13.297000Z","event_fingerprint":"41c58d7cd7531b23e60039549b5a55bad570b6bfbb6d90e5acaa2f9c9b1ceecc","payload":{"connection_id":"efc69d3132f1467b8e898a382b23ac0d","event_at":"2026-07-27T05:31:13.297000Z","event_type":"price_change","frame_hash":"c1d3c963486cecbee89d564dde382ba8cdec5e985a9e9af83fbf11837c783ce0","frame_index":0,"kind":"data","monotonic_ns":232256534951750,"payload":{"event_type":"price_change","market":"0x3b40066b5cf3871a2f6237c5628bd8092a206aa998558ac5ec13c4483e31e160","price_changes":[{"asset_id":"110216635572655435074987471276357323571387854733835379371586402147734167783946","best_ask":"0.49","best_bid":"0.48","hash":"130c9965bdbdf9e52d1195a663b214903524e00c","price":"0.35","side":"BUY","size":"177"},{"asset_id":"14766054693214075530629349735273995982307625376442606753688071083149620216746","best_ask":"0.52","best_bid":"0.51","hash":"4ad751178847c21bf49f8a7f43cd41741a8b7a39","price":"0.65","side":"SELL","size":"177"}],"timestamp":"1785130273297"},"payload_hash":"31ef0c403054b8b9814c10eb62fb37b1f81b2638abbf53e43e6385114dfb31de","raw_frame":"{\"market\":\"0x3b40066b5cf3871a2f6237c5628bd8092a206aa998558ac5ec13c4483e31e160\", \"price_changes\":[{\"asset_id\":\"110216635572655435074987471276357323571387854733835379371586402147734167783946\", \"price\":\"0.35\", \"size\":\"177\", \"side\":\"BUY\", \"hash\":\"130c9965bdbdf9e52d1195a663b214903524e00c\", \"best_bid\":\"0.48\", \"best_ask\":\"0.49\"}, {\"asset_id\":\"14766054693214075530629349735273995982307625376442606753688071083149620216746\", \"price\":\"0.65\", \"size\":\"177\", \"side\":\"SELL\", \"hash\":\"4ad751178847c21bf49f8a7f43cd41741a8b7a39\", \"best_bid\":\"0.51\", \"best_ask\":\"0.52\"}], \"timestamp\":\"1785130273297\", \"event_type\":\"price_change\"}","received_at":"2026-07-27T05:31:13.297257Z","schema_version":"clob-market-ws.price_change.v1","sequence":null,"server_hash":null,"server_timestamp":"1785130273297","session_id":"502006c5cfcd437296561ea750c9ec8b","source":"clob_market_ws"},"received_at":"2026-07-27T05:31:13.297257Z","record_id":"e3afb26854e1c6876de05f8625151d7a678c225efa59fce220346da83dbf4b64","schema_fingerprint":"4aa3821a28b0b7c2400bc59aba4bcc0a76e971dadd19610d3ad38c768e124dc7","schema_version":"edge-lab-recorder.raw.v1","sequence":null,"source":"clob_market_ws"}
{"event_at":"2026-07-27T05:31:13.299000Z","event_fingerprint":"41b9e4f56f744cf768ac04b4db2174c58f87dcb823cc711cf3673827ed056292","payload":{"connection_id":"efc69d3132f1467b8e898a382b23ac0d","event_at":"2026-07-27T05:31:13.299000Z","event_type":"price_change","frame_hash":"9d110fa7acd1ec09fb6bc28420d4eea11ab4cc6ed937478c4833c9b435fc5031","frame_index":0,"kind":"data","monotonic_ns":232256538305333,"payload":{"event_type":"price_change","market":"0x3b40066b5cf3871a2f6237c5628bd8092a206aa998558ac5ec13c4483e31e160","price_changes":[{"asset_id":"110216635572655435074987471276357323571387854733835379371586402147734167783946","best_ask":"0.49","best_bid":"0.48","hash":"7ad152adba4550ed531d388fbd670c826ac01139","price":"0.49","side":"SELL","size":"57"},{"asset_id":"14766054693214075530629349735273995982307625376442606753688071083149620216746","best_ask":"0.52","best_bid":"0.51","hash":"405f8ecc5c89ef0794d911a5750574a1a5b8f342","price":"0.51","side":"BUY","size":"57"}],"timestamp":"1785130273299"},"payload_hash":"3144f2dcfae22baa8b06aa22312d70508d9012df082f4b9fdc4484082dc3a811","raw_frame":"{\"market\":\"0x3b40066b5cf3871a2f6237c5628bd8092a206aa998558ac5ec13c4483e31e160\", \"price_changes\":[{\"asset_id\":\"110216635572655435074987471276357323571387854733835379371586402147734167783946\", \"price\":\"0.49\", \"size\":\"57\", \"side\":\"SELL\", \"hash\":\"7ad152adba4550ed531d388fbd670c826ac01139\", \"best_bid\":\"0.48\", \"best_ask\":\"0.49\"}, {\"asset_id\":\"14766054693214075530629349735273995982307625376442606753688071083149620216746\", \"price\":\"0.51\", \"size\":\"57\", \"side\":\"BUY\", \"hash\":\"405f8ecc5c89ef0794d911a5750574a1a5b8f342\", \"best_bid\":\"0.51\", \"best_ask\":\"0.52\"}], \"timestamp\":\"1785130273299\", \"event_type\":\"price_change\"}","received_at":"2026-07-27T05:31:13.300605Z","schema_version":"clob-market-ws.price_change.v1","sequence":null,"server_hash":null,"server_timestamp":"1785130273299","session_id":"502006c5cfcd437296561ea750c9ec8b","source":"clob_market_ws"},"received_at":"2026-07-27T05:31:13.300605Z","record_id":"df5bd2b913694e2cb625084f090e0c77bbe086ce0850338c93a7d469a408e7db","schema_fingerprint":"4aa3821a28b0b7c2400bc59aba4bcc0a76e971dadd19610d3ad38c768e124dc7","schema_version":"edge-lab-recorder.raw.v1","sequence":null,"source":"clob_market_ws"}
{"event_at":"2026-07-27T05:31:13.300000Z","event_fingerprint":"0be35322a219f6d732aa87d3b84a36989c29f7c49db0ab2003123e10a4bee36d","payload":{"connection_id":"efc69d3132f1467b8e898a382b23ac0d","event_at":"2026-07-27T05:31:13.300000Z","event_type":"price_change","frame_hash":"032152700e7d9a3d9ec8a0d4e156ff317b7e19e7bbf3d12966a16c5b0c3a78b7","frame_index":0,"kind":"data","monotonic_ns":232256549012791,"payload":{"event_type":"price_change","market":"0x3b40066b5cf3871a2f6237c5628bd8092a206aa998558ac5ec13c4483e31e160","price_changes":[{"asset_id":"110216635572655435074987471276357323571387854733835379371586402147734167783946","best_ask":"0.49","best_bid":"0.48","hash":"574227294412dc096087a972d76aa7211c9592b9","price":"0.38","side":"BUY","size":"51"},{"asset_id":"14766054693214075530629349735273995982307625376442606753688071083149620216746","best_ask":"0.52","best_bid":"0.51","hash":"3b51de293e0b078d83c5ba9264bf8e548216c6aa","price":"0.62","side":"SELL","size":"51"}],"timestamp":"1785130273300"},"payload_hash":"812b080249e05e1d726d90acae7d5a21b7e385930bd94653c8ce7c7c498001a4","raw_frame":"{\"market\":\"0x3b40066b5cf3871a2f6237c5628bd8092a206aa998558ac5ec13c4483e31e160\", \"price_changes\":[{\"asset_id\":\"110216635572655435074987471276357323571387854733835379371586402147734167783946\", \"price\":\"0.38\", \"size\":\"51\", \"side\":\"BUY\", \"hash\":\"574227294412dc096087a972d76aa7211c9592b9\", \"best_bid\":\"0.48\", \"best_ask\":\"0.49\"}, {\"asset_id\":\"14766054693214075530629349735273995982307625376442606753688071083149620216746\", \"price\":\"0.62\", \"size\":\"51\", \"side\":\"SELL\", \"hash\":\"3b51de293e0b078d83c5ba9264bf8e548216c6aa\", \"best_bid\":\"0.51\", \"best_ask\":\"0.52\"}], \"timestamp\":\"1785130273300\", \"event_type\":\"price_change\"}","received_at":"2026-07-27T05:31:13.311311Z","schema_version":"clob-market-ws.price_change.v1","sequence":null,"server_hash":null,"server_timestamp":"1785130273300","session_id":"502006c5cfcd437296561ea750c9ec8b","source":"clob_market_ws"},"received_at":"2026-07-27T05:31:13.311311Z","record_id":"95d791f7575ad04486aff9328ab545ad2be9103068105530124744f7d4c583e5","schema_fingerprint":"4aa3821a28b0b7c2400bc59aba4bcc0a76e971dadd19610d3ad38c768e124dc7","schema_version":"edge-lab-recorder.raw.v1","sequence":null,"source":"clob_market_ws"}
