{"event_at":"2026-07-27T05:37:32.001000Z","event_fingerprint":"17cbca88efb6078d268a680446fbf2c711d2aa40bfdab49a16c89e0bab0fd612","payload":{"connection_id":"efc69d3132f1467b8e898a382b23ac0d","event_at":"2026-07-27T05:37:32.001000Z","event_type":"price_change","frame_hash":"7ac522af85d06273a8f4a81af7f30c63d1559ef1ddb80b128c4c88316a93912f","frame_index":0,"kind":"data","monotonic_ns":232635205345625,"payload":{"event_type":"price_change","market":"0x3b40066b5cf3871a2f6237c5628bd8092a206aa998558ac5ec13c4483e31e160","price_changes":[{"asset_id":"110216635572655435074987471276357323571387854733835379371586402147734167783946","best_ask":"0.73","best_bid":"0.72","hash":"9c45be013064957e71b6056fee31169778d054cf","price":"0.7","side":"BUY","size":"72"},{"asset_id":"14766054693214075530629349735273995982307625376442606753688071083149620216746","best_ask":"0.28","best_bid":"0.27","hash":"e15619e1bdf6e61d2d1c2605336c5f816acef100","price":"0.3","side":"SELL","size":"72"}],"timestamp":"1785130652001"},"payload_hash":"f1891a7f2220a85d600ee411de2947bfbc5d24d9fc1bc535f00c23286592a02b","raw_frame":"{\"market\":\"0x3b40066b5cf3871a2f6237c5628bd8092a206aa998558ac5ec13c4483e31e160\", \"price_changes\":[{\"asset_id\":\"110216635572655435074987471276357323571387854733835379371586402147734167783946\", \"price\":\"0.7\", \"size\":\"72\", \"side\":\"BUY\", \"hash\":\"9c45be013064957e71b6056fee31169778d054cf\", \"best_bid\":\"0.72\", \"best_ask\":\"0.73\"}, {\"asset_id\":\"14766054693214075530629349735273995982307625376442606753688071083149620216746\", \"price\":\"0.3\", \"size\":\"72\", \"side\":\"SELL\", \"hash\":\"e15619e1bdf6e61d2d1c2605336c5f816acef100\", \"best_bid\":\"0.27\", \"best_ask\":\"0.28\"}], \"timestamp\":\"1785130652001\", \"event_type\":\"price_change\"}","received_at":"2026-07-27T05:37:31.970276Z","schema_version":"clob-market-ws.price_change.v1","sequence":null,"server_hash":null,"server_timestamp":"1785130652001","session_id":"502006c5cfcd437296561ea750c9ec8b","source":"clob_market_ws"},"received_at":"2026-07-27T05:37:31.970276Z","record_id":"94104fd2c4c8f6dd5e6d021c3f8849e0ed6c5678181cadbe383859b6646589fc","schema_fingerprint":"4aa3821a28b0b7c2400bc59aba4bcc0a76e971dadd19610d3ad38c768e124dc7","schema_version":"edge-lab-recorder.raw.v1","sequence":null,"source":"clob_market_ws"}
{"event_at":"2026-07-27T05:37:32.009000Z","event_fingerprint":"acb204f2d5064cd6f50309a4c2f48319463899881860098d507958b32d1eef8e","payload":{"connection_id":"efc69d3132f1467b8e898a382b23ac0d","event_at":"2026-07-27T05:37:32.009000Z","event_type":"price_change","frame_hash":"b6ea497a656faaf1585adb7967f35113fa7d7a60cfab7cb9d204a45e657cc3e7","frame_index":0,"kind":"data","monotonic_ns":232635207584416,"payload":{"event_type":"price_change","market":"0x3b40066b5cf3871a2f6237c5628bd8092a206aa998558ac5ec13c4483e31e160","price_changes":[{"asset_id":"110216635572655435074987471276357323571387854733835379371586402147734167783946","best_ask":"0.73","best_bid":"0.72","hash":"36859a41b717f966e561918712ef734d5f1a9d23","price":"0.01","side":"BUY","size":"5617.45"},{"asset_id":"14766054693214075530629349735273995982307625376442606753688071083149620216746","best_ask":"0.28","best_bid":"0.27","hash":"6ffbade83af4569b17848439842007cded374776","price":"0.99","side":"SELL","size":"5617.45"}],"timestamp":"1785130652009"},"payload_hash":"020897714b6f64cbc070b870726a30d686f75280fc264c367afbe5bd5083b966","raw_frame":"{\"market\":\"0x3b40066b5cf3871a2f6237c5628bd8092a206aa998558ac5ec13c4483e31e160\", \"price_changes\":[{\"asset_id\":\"110216635572655435074987471276357323571387854733835379371586402147734167783946\", \"price\":\"0.01\", \"size\":\"5617.45\", \"side\":\"BUY\", \"hash\":\"36859a41b717f966e561918712ef734d5f1a9d23\", \"best_bid\":\"0.72\", \"best_ask\":\"0.73\"}, {\"asset_id\":\"14766054693214075530629349735273995982307625376442606753688071083149620216746\", \"price\":\"0.99\", \"size\":\"5617.45\", \"side\":\"SELL\", \"hash\":\"6ffbade83af4569b17848439842007cded374776\", \"best_bid\":\"0.27\", \"best_ask\":\"0.28\"}], \"timestamp\":\"1785130652009\", \"event_type\":\"price_change\"}","received_at":"2026-07-27T05:37:31.972514Z","schema_version":"clob-market-ws.price_change.v1","sequence":null,"server_hash":null,"server_timestamp":"1785130652009","session_id":"502006c5cfcd437296561ea750c9ec8b","source":"clob_market_ws"},"received_at":"2026-07-27T05:37:31.972514Z","record_id":"9e7caf33917ca68be7a1fa97245ad9185dce6281beab95322276288bf7eba64e","schema_fingerprint":"4aa3821a28b0b7c2400bc59aba4bcc0a76e971dadd19610d3ad38c768e124dc7","schema_version":"edge-lab-recorder.raw.v1","sequence":null,"source":"clob_market_ws"}
{"event_at":"2026-07-27T05:37:32.018000Z","event_fingerprint":"9826b56c898f2009de4db8bd6f8bc291cdb0733899a1201bad166986bdd5d744","payload":{"connection_id":"efc69d3132f1467b8e898a382b23ac0d","event_at":"2026-07-27T05:37:32.018000Z","event_type":"price_change","frame_hash":"dc79c48ea0f05de72cfd5e764721a4bb2d7186007536bd4b8766f949902707d5","frame_index":0,"kind":"data","monotonic_ns":232635212344041,"payload":{"event_type":"price_change","market":"0x3b40066b5cf3871a2f6237c5628bd8092a206aa998558ac5ec13c4483e31e160","price_changes":[{"asset_id":"110216635572655435074987471276357323571387854733835379371586402147734167783946","best_ask":"0.73","best_bid":"0.72","hash":"3c971c2fe76bf7741f5c22248a990e372f09b87a","price":"0.65","side":"BUY","size":"150.91"},{"asset_id":"14766054693214075530629349735273995982307625376442606753688071083149620216746","best_ask":"0.28","best_bid":"0.27","hash":"58cb95b107a12f7c7024fe7975a77a957591c43c","price":"0.35","side":"SELL","size":"150.91"}],"timestamp":"1785130652018"},"payload_hash":"c4455dbca6db10bb7283a6d0a1773c5785f005988c4e4983eee218cc807b5571","raw_frame":"{\"market\":\"0x3b40066b5cf3871a2f6237c5628bd8092a206aa998558ac5ec13c4483e31e160\", \"price_changes\":[{\"asset_id\":\"110216635572655435074987471276357323571387854733835379371586402147734167783946\", \"price\":\"0.65\", \"size\":\"150.91\", \"side\":\"BUY\", \"hash\":\"3c971c2fe76bf7741f5c22248a990e372f09b87a\", \"best_bid\":\"0.72\", \"best_ask\":\"0.73\"}, {\"asset_id\":\"14766054693214075530629349735273995982307625376442606753688071083149620216746\", \"price\":\"0.35\", \"size\":\"150.91\", \"side\":\"SELL\", \"hash\":\"58cb95b107a12f7c7024fe7975a77a957591c43c\", \"best_bid\":\"0.27\", \"best_ask\":\"0.28\"}], \"timestamp\":\"1785130652018\", \"event_type\":\"price_change\"}","received_at":"2026-07-27T05:37:31.977274Z","schema_version":"clob-market-ws.price_change.v1","sequence":null,"server_hash":null,"server_timestamp":"1785130652018","session_id":"502006c5cfcd437296561ea750c9ec8b","source":"clob_market_ws"},"received_at":"2026-07-27T05:37:31.977274Z","record_id":"273df0e55595db80f0af39ddc58d71dffcb94c1dd183202b47dc334f36334b48","schema_fingerprint":"4aa3821a28b0b7c2400bc59aba4bcc0a76e971dadd19610d3ad38c768e124dc7","schema_version":"edge-lab-recorder.raw.v1","sequence":null,"source":"clob_market_ws"}
{"event_at":"2026-07-27T05:37:32.024000Z","event_fingerprint":"fb3ab96fdda1f7966d56bc51cff128030c48fb7ff1dbbb69b5eca77a157aecf0","payload":{"connection_id":"efc69d3132f1467b8e898a382b23ac0d","event_at":"2026-07-27T05:37:32.024000Z","event_type":"price_change","frame_hash":"8e48c366536e81e7b013ee7ffe03fd74a3a1575b8325397ca7c54166deaa4cf3","frame_index":0,"kind":"data","monotonic_ns":232635217518625,"payload":{"event_type":"price_change","market":"0x3b40066b5cf3871a2f6237c5628bd8092a206aa998558ac5ec13c4483e31e160","price_changes":[{"asset_id":"14766054693214075530629349735273995982307625376442606753688071083149620216746","best_ask":"0.28","best_bid":"0.27","hash":"7fab2e3db61570f140494a7a235366c78f45d4a2","price":"0.01","side":"BUY","size":"5628.02"},{"asset_id":"110216635572655435074987471276357323571387854733835379371586402147734167783946","best_ask":"0.73","best_bid":"0.72","hash":"d15e84ca6737079a5012a7c95923b2dc8050cd4a","price":"0.99","side":"SELL","size":"5628.02"}],"timestamp":"1785130652024"},"payload_hash":"11275c3e1f13dd877a8932904db719768c8327f675e33be7b66e439c2dab8f4e","raw_frame":"{\"market\":\"0x3b40066b5cf3871a2f6237c5628bd8092a206aa998558ac5ec13c4483e31e160\", \"price_changes\":[{\"asset_id\":\"14766054693214075530629349735273995982307625376442606753688071083149620216746\", \"price\":\"0.01\", \"size\":\"5628.02\", \"side\":\"BUY\", \"hash\":\"7fab2e3db61570f140494a7a235366c78f45d4a2\", \"best_bid\":\"0.27\", \"best_ask\":\"0.28\"}, {\"asset_id\":\"110216635572655435074987471276357323571387854733835379371586402147734167783946\", \"price\":\"0.99\", \"size\":\"5628.02\", \"side\":\"SELL\", \"hash\":\"d15e84ca6737079a5012a7c95923b2dc8050cd4a\", \"best_bid\":\"0.72\", \"best_ask\":\"0.73\"}], \"timestamp\":\"1785130652024\", \"event_type\":\"price_change\"}","received_at":"2026-07-27T05:37:31.982447Z","schema_version":"clob-market-ws.price_change.v1","sequence":null,"server_hash":null,"server_timestamp":"1785130652024","session_id":"502006c5cfcd437296561ea750c9ec8b","source":"clob_market_ws"},"received_at":"2026-07-27T05:37:31.982447Z","record_id":"eba0446c42b0d4ec4a921dc261f5a26bbe5cf64d0273d7cf2feded66ee9ffbeb","schema_fingerprint":"4aa3821a28b0b7c2400bc59aba4bcc0a76e971dadd19610d3ad38c768e124dc7","schema_version":"edge-lab-recorder.raw.v1","sequence":null,"source":"clob_market_ws"}
{"event_at":"2026-07-27T05:37:32.024000Z","event_fingerprint":"404b1cafa5fc25534436e9f0b72b57241f6c90416a77310a13b1c5893f64c408","payload":{"connection_id":"efc69d3132f1467b8e898a382b23ac0d","event_at":"2026-07-27T05:37:32.024000Z","event_type":"price_change","frame_hash":"fbeda995102548ccb73f41c14148114c935250301a92906d5df9bd7cace6e038","frame_index":0,"kind":"data","monotonic_ns":232635219701750,"payload":{"event_type":"price_change","market":"0x3b40066b5cf3871a2f6237c5628bd8092a206aa998558ac5ec13c4483e31e160","price_changes":[{"asset_id":"110216635572655435074987471276357323571387854733835379371586402147734167783946","best_ask":"0.73","best_bid":"0.72","hash":"d93f327f099f834231bc68a92e56ae18695c15c1","price":"0.01","side":"BUY","size":"5612.45"},{"asset_id":"14766054693214075530629349735273995982307625376442606753688071083149620216746","best_ask":"0.28","best_bid":"0.27","hash":"f75ecb67f26882254be5b2b011abaeada239c78e","price":"0.99","side":"SELL","size":"5612.45"}],"timestamp":"1785130652024"},"payload_hash":"51cfd6b5ac6032434e160a8b02fd521d24dec0191652958ab3bd4813d5617ad2","raw_frame":"{\"market\":\"0x3b40066b5cf3871a2f6237c5628bd8092a206aa998558ac5ec13c4483e31e160\", \"price_changes\":[{\"asset_id\":\"110216635572655435074987471276357323571387854733835379371586402147734167783946\", \"price\":\"0.01\", \"size\":\"5612.45\", \"side\":\"BUY\", \"hash\":\"d93f327f099f834231bc68a92e56ae18695c15c1\", \"best_bid\":\"0.72\", \"best_ask\":\"0.73\"}, {\"asset_id\":\"14766054693214075530629349735273995982307625376442606753688071083149620216746\", \"price\":\"0.99\", \"size\":\"5612.45\", \"side\":\"SELL\", \"hash\":\"f75ecb67f26882254be5b2b011abaeada239c78e\", \"best_bid\":\"0.27\", \"best_ask\":\"0.28\"}], \"timestamp\":\"1785130652024\", \"event_type\":\"price_change\"}","received_at":"2026-07-27T05:37:31.984631Z","schema_version":"clob-market-ws.price_change.v1","sequence":null,"server_hash":null,"server_timestamp":"1785130652024","session_id":"502006c5cfcd437296561ea750c9ec8b","source":"clob_market_ws"},"received_at":"2026-07-27T05:37:31.984631Z","record_id":"d03e59f23b4ce88ec8fe723bf271444d8a163372508adcff020d04621629cae8","schema_fingerprint":"4aa3821a28b0b7c2400bc59aba4bcc0a76e971dadd19610d3ad38c768e124dc7","schema_version":"edge-lab-recorder.raw.v1","sequence":null,"source":"clob_market_ws"}
{"event_at":"2026-07-27T05:37:32.044000Z","event_fingerprint":"46fc81ef56cc0897dfb62db1e1537c70e30dcb731a4797d8f8fe898717ad5963","payload":{"connection_id":"efc69d3132f1467b8e898a382b23ac0d","event_at":"2026-07-27T05:37:32.044000Z","event_type":"price_change","frame_hash":"84817259d08d9655de63074daa52e456a0b1759c4b632648e9cd86d76711844e","frame_index":0,"kind":"data","monotonic_ns":232635236717000,"payload":{"event_type":"price_change","market":"0x3b40066b5cf3871a2f6237c5628bd8092a206aa998558ac5ec13c4483e31e160","price_changes":[{"asset_id":"14766054693214075530629349735273995982307625376442606753688071083149620216746","best_ask":"0.28","best_bid":"0.27","hash":"092f64a448f9f3f5b94461cc0b80a3ac0c93ad59","price":"0.01","side":"BUY","size":"5623.02"},{"asset_id":"110216635572655435074987471276357323571387854733835379371586402147734167783946","best_ask":"0.73","best_bid":"0.72","hash":"3c251d08ae10133a5ff292c04949e046397c54ae","price":"0.99","side":"SELL","size":"5623.02"}],"timestamp":"1785130652044"},"payload_hash":"2b793ac556d33590b25cd5a6d80e8bf9217f76f8c8b8a3a70bf15566bbce0577","raw_frame":"{\"market\":\"0x3b40066b5cf3871a2f6237c5628bd8092a206aa998558ac5ec13c4483e31e160\", \"price_changes\":[{\"asset_id\":\"14766054693214075530629349735273995982307625376442606753688071083149620216746\", \"price\":\"0.01\", \"size\":\"5623.02\", \"side\":\"BUY\", \"hash\":\"092f64a448f9f3f5b94461cc0b80a3ac0c93ad59\", \"best_bid\":\"0.27\", \"best_ask\":\"0.28\"}, {\"asset_id\":\"110216635572655435074987471276357323571387854733835379371586402147734167783946\", \"price\":\"0.99\", \"size\":\"5623.02\", \"side\":\"SELL\", \"hash\":\"3c251d08ae10133a5ff292c04949e046397c54ae\", \"best_bid\":\"0.72\", \"best_ask\":\"0.73\"}], \"timestamp\":\"1785130652044\", \"event_type\":\"price_change\"}","received_at":"2026-07-27T05:37:32.001647Z","schema_version":"clob-market-ws.price_change.v1","sequence":null,"server_hash":null,"server_timestamp":"1785130652044","session_id":"502006c5cfcd437296561ea750c9ec8b","source":"clob_market_ws"},"received_at":"2026-07-27T05:37:32.001647Z","record_id":"9bf64b8bfa66559756ea57989a6305022d308bab0737e8ef9ecb06e95e91b77d","schema_fingerprint":"4aa3821a28b0b7c2400bc59aba4bcc0a76e971dadd19610d3ad38c768e124dc7","schema_version":"edge-lab-recorder.raw.v1","sequence":null,"source":"clob_market_ws"}
{"event_at":"2026-07-27T05:37:32.052000Z","event_fingerprint":"368d0d4b68401ee6982ab74e7614677c734c41c82c3bfe79f4269251edde4e72","payload":{"connection_id":"efc69d3132f1467b8e898a382b23ac0d","event_at":"2026-07-27T05:37:32.052000Z","event_type":"price_change","frame_hash":"d0b5710b0a46fa5f570653f12e9a417bb0e0263155376214c5730a3ceb78d202","frame_index":0,"kind":"data","monotonic_ns":232635246771416,"payload":{"event_type":"price_change","market":"0x3b40066b5cf3871a2f6237c5628bd8092a206aa998558ac5ec13c4483e31e160","price_changes":[{"asset_id":"110216635572655435074987471276357323571387854733835379371586402147734167783946","best_ask":"0.73","best_bid":"0.72","hash":"aee06f55032739e3e739301b9e191160edea0194","price":"0.01","side":"BUY","size":"5617.45"},{"asset_id":"14766054693214075530629349735273995982307625376442606753688071083149620216746","best_ask":"0.28","best_bid":"0.27","hash":"a9065fa0fb3813bb12abfca9e52fe53eef007fd5","price":"0.99","side":"SELL","size":"5617.45"}],"timestamp":"1785130652052"},"payload_hash":"277e5a51b8bfc1fbb77a0fab4cd13ae3deb9acdc1e117be0cd8957b6a71730e7","raw_frame":"{\"market\":\"0x3b40066b5cf3871a2f6237c5628bd8092a206aa998558ac5ec13c4483e31e160\", \"price_changes\":[{\"asset_id\":\"110216635572655435074987471276357323571387854733835379371586402147734167783946\", \"price\":\"0.01\", \"size\":\"5617.45\", \"side\":\"BUY\", \"hash\":\"aee06f55032739e3e739301b9e191160edea0194\", \"best_bid\":\"0.72\", \"best_ask\":\"0.73\"}, {\"asset_id\":\"14766054693214075530629349735273995982307625376442606753688071083149620216746\", \"price\":\"0.99\", \"size\":\"5617.45\", \"side\":\"SELL\", \"hash\":\"a9065fa0fb3813bb12abfca9e52fe53eef007fd5\", \"best_bid\":\"0.27\", \"best_ask\":\"0.28\"}], \"timestamp\":\"1785130652052\", \"event_type\":\"price_change\"}","received_at":"2026-07-27T05:37:32.011701Z","schema_version":"clob-market-ws.price_change.v1","sequence":null,"server_hash":null,"server_timestamp":"1785130652052","session_id":"502006c5cfcd437296561ea750c9ec8b","source":"clob_market_ws"},"received_at":"2026-07-27T05:37:32.011701Z","record_id":"bc1473ef614873287caa87a62d928681bcaf06c61e0adccb0d1ce143ab820a4e","schema_fingerprint":"4aa3821a28b0b7c2400bc59aba4bcc0a76e971dadd19610d3ad38c768e124dc7","schema_version":"edge-lab-recorder.raw.v1","sequence":null,"source":"clob_market_ws"}
{"event_at":"2026-07-27T05:37:32.070000Z","event_fingerprint":"867262905ccf52ac5961509a6a0117253e708059156425e8ff2b14beb5050e77","payload":{"connection_id":"efc69d3132f1467b8e898a382b23ac0d","event_at":"2026-07-27T05:37:32.070000Z","event_type":"price_change","frame_hash":"b0f745d6e692bbf33f4bcfc5f9c43d06da131c92e8a8aa5b41767b2568746f38","frame_index":0,"kind":"data","monotonic_ns":232635263879375,"payload":{"event_type":"price_change","market":"0x3b40066b5cf3871a2f6237c5628bd8092a206aa998558ac5ec13c4483e31e160","price_changes":[{"asset_id":"110216635572655435074987471276357323571387854733835379371586402147734167783946","best_ask":"0.73","best_bid":"0.72","hash":"ba41022a4bfef2804341d2184b9470d3ccf1828a","price":"0.01","side":"BUY","size":"5612.45"},{"asset_id":"14766054693214075530629349735273995982307625376442606753688071083149620216746","best_ask":"0.28","best_bid":"0.27","hash":"970bc8b6c698e18bf88f892ce92504e28b62cebb","price":"0.99","side":"SELL","size":"5612.45"}],"timestamp":"1785130652070"},"payload_hash":"a2788a0ead9a740ff319bad5dd0ddc1d1254d11e7c0623e36d07cf126e691788","raw_frame":"{\"market\":\"0x3b40066b5cf3871a2f6237c5628bd8092a206aa998558ac5ec13c4483e31e160\", \"price_changes\":[{\"asset_id\":\"110216635572655435074987471276357323571387854733835379371586402147734167783946\", \"price\":\"0.01\", \"size\":\"5612.45\", \"side\":\"BUY\", \"hash\":\"ba41022a4bfef2804341d2184b9470d3ccf1828a\", \"best_bid\":\"0.72\", \"best_ask\":\"0.73\"}, {\"asset_id\":\"14766054693214075530629349735273995982307625376442606753688071083149620216746\", \"price\":\"0.99\", \"size\":\"5612.45\", \"side\":\"SELL\", \"hash\":\"970bc8b6c698e18bf88f892ce92504e28b62cebb\", \"best_bid\":\"0.27\", \"best_ask\":\"0.28\"}], \"timestamp\":\"1785130652070\", \"event_type\":\"price_change\"}","received_at":"2026-07-27T05:37:32.028809Z","schema_version":"clob-market-ws.price_change.v1","sequence":null,"server_hash":null,"server_timestamp":"1785130652070","session_id":"502006c5cfcd437296561ea750c9ec8b","source":"clob_market_ws"},"received_at":"2026-07-27T05:37:32.028809Z","record_id":"2813051d018d44ab50a19a06b98ec47441f1b93cbeef5a1b4e7192c10f4a240f","schema_fingerprint":"4aa3821a28b0b7c2400bc59aba4bcc0a76e971dadd19610d3ad38c768e124dc7","schema_version":"edge-lab-recorder.raw.v1","sequence":null,"source":"clob_market_ws"}
{"event_at":"2026-07-27T05:37:32.071000Z","event_fingerprint":"985c38e07f50972626b4ed29c40318a5eeb5f50137298f4754eb924a0a0937a6","payload":{"connection_id":"efc69d3132f1467b8e898a382b23ac0d","event_at":"2026-07-27T05:37:32.071000Z","event_type":"price_change","frame_hash":"52ef078199f803de81792df2f5d74cff23a871be7cf98a42d05ee0413f35918e","frame_index":0,"kind":"data","monotonic_ns":232635266570291,"payload":{"event_type":"price_change","market":"0x3b40066b5cf3871a2f6237c5628bd8092a206aa998558ac5ec13c4483e31e160","price_changes":[{"asset_id":"110216635572655435074987471276357323571387854733835379371586402147734167783946","best_ask":"0.73","best_bid":"0.72","hash":"82fe9733fc0710b0f3ab1f88613d9d276bfe98bc","price":"0.66","side":"BUY","size":"207.06"},{"asset_id":"14766054693214075530629349735273995982307625376442606753688071083149620216746","best_ask":"0.28","best_bid":"0.27","hash":"99a106971705c1a901c394f433acbd1d4d6be5b8","price":"0.34","side":"SELL","size":"207.06"}],"timestamp":"1785130652071"},"payload_hash":"ebbf904aef5159b5744e71c6750ccc934af899e62086bc73b6df93e93ab984b3","raw_frame":"{\"market\":\"0x3b40066b5cf3871a2f6237c5628bd8092a206aa998558ac5ec13c4483e31e160\", \"price_changes\":[{\"asset_id\":\"110216635572655435074987471276357323571387854733835379371586402147734167783946\", \"price\":\"0.66\", \"size\":\"207.06\", \"side\":\"BUY\", \"hash\":\"82fe9733fc0710b0f3ab1f88613d9d276bfe98bc\", \"best_bid\":\"0.72\", \"best_ask\":\"0.73\"}, {\"asset_id\":\"14766054693214075530629349735273995982307625376442606753688071083149620216746\", \"price\":\"0.34\", \"size\":\"207.06\", \"side\":\"SELL\", \"hash\":\"99a106971705c1a901c394f433acbd1d4d6be5b8\", \"best_bid\":\"0.27\", \"best_ask\":\"0.28\"}], \"timestamp\":\"1785130652071\", \"event_type\":\"price_change\"}","received_at":"2026-07-27T05:37:32.031501Z","schema_version":"clob-market-ws.price_change.v1","sequence":null,"server_hash":null,"server_timestamp":"1785130652071","session_id":"502006c5cfcd437296561ea750c9ec8b","source":"clob_market_ws"},"received_at":"2026-07-27T05:37:32.031501Z","record_id":"43d6c3e5e09b6e74d731410c98a891c9224a1558a275b48b7f365c9b263b6179","schema_fingerprint":"4aa3821a28b0b7c2400bc59aba4bcc0a76e971dadd19610d3ad38c768e124dc7","schema_version":"edge-lab-recorder.raw.v1","sequence":null,"source":"clob_market_ws"}
{"event_at":"2026-07-27T05:37:32.083000Z","event_fingerprint":"8aab46ad2b4d76b8f43c7dfcc8de2979e852a11c5997fce04b508a667854ffe4","payload":{"connection_id":"efc69d3132f1467b8e898a382b23ac0d","event_at":"2026-07-27T05:37:32.083000Z","event_type":"price_change","frame_hash":"2708317de635962a94738906aa5834dd83b24f1d63ce6cbee23ed5f8abb8bf50","frame_index":0,"kind":"data","monotonic_ns":232635276188625,"payload":{"event_type":"price_change","market":"0x3b40066b5cf3871a2f6237c5628bd8092a206aa998558ac5ec13c4483e31e160","price_changes":[{"asset_id":"14766054693214075530629349735273995982307625376442606753688071083149620216746","best_ask":"0.28","best_bid":"0.27","hash":"bdb8545521e283a53e7eb48a95106787eab0b568","price":"0.21","side":"BUY","size":"56"},{"asset_id":"110216635572655435074987471276357323571387854733835379371586402147734167783946","best_ask":"0.73","best_bid":"0.72","hash":"cd188a8d9c823351363ea2d86ac3d1dde5d476bc","price":"0.79","side":"SELL","size":"56"}],"timestamp":"1785130652083"},"payload_hash":"d5235729570d1e5649538df5b4e4b1413f3c57d76bf47dfa53efcc41a52737e5","raw_frame":"{\"market\":\"0x3b40066b5cf3871a2f6237c5628bd8092a206aa998558ac5ec13c4483e31e160\", \"price_changes\":[{\"asset_id\":\"14766054693214075530629349735273995982307625376442606753688071083149620216746\", \"price\":\"0.21\", \"size\":\"56\", \"side\":\"BUY\", \"hash\":\"bdb8545521e283a53e7eb48a95106787eab0b568\", \"best_bid\":\"0.27\", \"best_ask\":\"0.28\"}, {\"asset_id\":\"110216635572655435074987471276357323571387854733835379371586402147734167783946\", \"price\":\"0.79\", \"size\":\"56\", \"side\":\"SELL\", \"hash\":\"cd188a8d9c823351363ea2d86ac3d1dde5d476bc\", \"best_bid\":\"0.72\", \"best_ask\":\"0.73\"}], \"timestamp\":\"1785130652083\", \"event_type\":\"price_change\"}","received_at":"2026-07-27T05:37:32.041120Z","schema_version":"clob-market-ws.price_change.v1","sequence":null,"server_hash":null,"server_timestamp":"1785130652083","session_id":"502006c5cfcd437296561ea750c9ec8b","source":"clob_market_ws"},"received_at":"2026-07-27T05:37:32.041120Z","record_id":"6e59fba90455c91625781bc254e0ef42a00a296be8aeead166842e6515174dca","schema_fingerprint":"4aa3821a28b0b7c2400bc59aba4bcc0a76e971dadd19610d3ad38c768e124dc7","schema_version":"edge-lab-recorder.raw.v1","sequence":null,"source":"clob_market_ws"}
{"event_at":"2026-07-27T05:37:32.094000Z","event_fingerprint":"bc5d89889f5270c472aac8f11c3cfe226aeb9f998d4bf0daff246a76fa8f7799","payload":{"connection_id":"efc69d3132f1467b8e898a382b23ac0d","event_at":"2026-07-27T05:37:32.094000Z","event_type":"price_change","frame_hash":"f94a73bf63d31385e39224ee02c64c0af97ed9f6d8edb3f2f23896a930ee98b2","frame_index":0,"kind":"data","monotonic_ns":232635287720833,"payload":{"event_type":"price_change","market":"0x3b40066b5cf3871a2f6237c5628bd8092a206aa998558ac5ec13c4483e31e160","price_changes":[{"asset_id":"14766054693214075530629349735273995982307625376442606753688071083149620216746","best_ask":"0.28","best_bid":"0.27","hash":"9d04f85bba35cce0ca734b5a8e2bd782dd7fd581","price":"0.48","side":"SELL","size":"50"},{"asset_id":"110216635572655435074987471276357323571387854733835379371586402147734167783946","best_ask":"0.73","best_bid":"0.72","hash":"6c9eb739237e10a6fb9283b43c2adfd120be74ac","price":"0.52","side":"BUY","size":"50"}],"timestamp":"1785130652094"},"payload_hash":"0a3713b2f4df42ceef9624a5efc2f8380764f130b1b7d3166de0926ffa964afa","raw_frame":"{\"market\":\"0x3b40066b5cf3871a2f6237c5628bd8092a206aa998558ac5ec13c4483e31e160\", \"price_changes\":[{\"asset_id\":\"14766054693214075530629349735273995982307625376442606753688071083149620216746\", \"price\":\"0.48\", \"size\":\"50\", \"side\":\"SELL\", \"hash\":\"9d04f85bba35cce0ca734b5a8e2bd782dd7fd581\", \"best_bid\":\"0.27\", \"best_ask\":\"0.28\"}, {\"asset_id\":\"110216635572655435074987471276357323571387854733835379371586402147734167783946\", \"price\":\"0.52\", \"size\":\"50\", \"side\":\"BUY\", \"hash\":\"6c9eb739237e10a6fb9283b43c2adfd120be74ac\", \"best_bid\":\"0.72\", \"best_ask\":\"0.73\"}], \"timestamp\":\"1785130652094\", \"event_type\":\"price_change\"}","received_at":"2026-07-27T05:37:32.052652Z","schema_version":"clob-market-ws.price_change.v1","sequence":null,"server_hash":null,"server_timestamp":"1785130652094","session_id":"502006c5cfcd437296561ea750c9ec8b","source":"clob_market_ws"},"received_at":"2026-07-27T05:37:32.052652Z","record_id":"3427c7b07ad7376b29496b7a76bea95bc1a5d0216753fc50efb2b8d412f81664","schema_fingerprint":"4aa3821a28b0b7c2400bc59aba4bcc0a76e971dadd19610d3ad38c768e124dc7","schema_version":"edge-lab-recorder.raw.v1","sequence":null,"source":"clob_market_ws"}
{"event_at":"2026-07-27T05:37:32.119000Z","event_fingerprint":"fec00d0e7625985f4fc09a8c0bbf97314fd9e3b298e4c894f55436d6b897de24","payload":{"connection_id":"efc69d3132f1467b8e898a382b23ac0d","event_at":"2026-07-27T05:37:32.119000Z","event_type":"price_change","frame_hash":"29fdd5c1fff42894355df89e9c980ad9c8c4ec2d0f0e565ac89e8a9e8262c873","frame_index":0,"kind":"data","monotonic_ns":232635313529083,"payload":{"event_type":"price_change","market":"0x3b40066b5cf3871a2f6237c5628bd8092a206aa998558ac5ec13c4483e31e160","price_changes":[{"asset_id":"110216635572655435074987471276357323571387854733835379371586402147734167783946","best_ask":"0.73","best_bid":"0.72","hash":"10059c86c8945686eea4394c63dc3fbc43879a0a","price":"0.01","side":"BUY","size":"5617.45"},{"asset_id":"14766054693214075530629349735273995982307625376442606753688071083149620216746","best_ask":"0.28","best_bid":"0.27","hash":"55d35cc04820e06aea7d0ae6074aa7e418ad225b","price":"0.99","side":"SELL","size":"5617.45"}],"timestamp":"1785130652119"},"payload_hash":"ddae3b63b549c7c67cf050364d8366f685016c8f6e37c6dd47dd927023bbe087","raw_frame":"{\"market\":\"0x3b40066b5cf3871a2f6237c5628bd8092a206aa998558ac5ec13c4483e31e160\", \"price_changes\":[{\"asset_id\":\"110216635572655435074987471276357323571387854733835379371586402147734167783946\", \"price\":\"0.01\", \"size\":\"5617.45\", \"side\":\"BUY\", \"hash\":\"10059c86c8945686eea4394c63dc3fbc43879a0a\", \"best_bid\":\"0.72\", \"best_ask\":\"0.73\"}, {\"asset_id\":\"14766054693214075530629349735273995982307625376442606753688071083149620216746\", \"price\":\"0.99\", \"size\":\"5617.45\", \"side\":\"SELL\", \"hash\":\"55d35cc04820e06aea7d0ae6074aa7e418ad225b\", \"best_bid\":\"0.27\", \"best_ask\":\"0.28\"}], \"timestamp\":\"1785130652119\", \"event_type\":\"price_change\"}","received_at":"2026-07-27T05:37:32.078461Z","schema_version":"clob-market-ws.price_change.v1","sequence":null,"server_hash":null,"server_timestamp":"1785130652119","session_id":"502006c5cfcd437296561ea750c9ec8b","source":"clob_market_ws"},"received_at":"2026-07-27T05:37:32.078461Z","record_id":"395f12adffb595ab37a769dea1f8e6a4b112b95032dab9f1f6824b9442a61904","schema_fingerprint":"4aa3821a28b0b7c2400bc59aba4bcc0a76e971dadd19610d3ad38c768e124dc7","schema_version":"edge-lab-recorder.raw.v1","sequence":null,"source":"clob_market_ws"}
{"event_at":"2026-07-27T05:37:32.119000Z","event_fingerprint":"339e59b26a9cff2d43338eea8356c62df3773dba337d744ca79fa037960e47b8","payload":{"connection_id":"efc69d3132f1467b8e898a382b23ac0d","event_at":"2026-07-27T05:37:32.119000Z","event_type":"price_change","frame_hash":"17ce4503691a7290fcc45eee8dc4a2f115fad06813588eb264c6302e96fe7345","frame_index":0,"kind":"data","monotonic_ns":232635315882541,"payload":{"event_type":"price_change","market":"0x3b40066b5cf3871a2f6237c5628bd8092a206aa998558ac5ec13c4483e31e160","price_changes":[{"asset_id":"110216635572655435074987471276357323571387854733835379371586402147734167783946","best_ask":"0.73","best_bid":"0.72","hash":"1a85f07ee3d4d6aa2d386fd0f08cd2d32e35c416","price":"0.7","side":"BUY","size":"45.06"},{"asset_id":"14766054693214075530629349735273995982307625376442606753688071083149620216746","best_ask":"0.28","best_bid":"0.27","hash":"92f949d52de2e903b9fe611d205db0598624cf65","price":"0.3","side":"SELL","size":"45.06"}],"timestamp":"1785130652119"},"payload_hash":"7846deadecadc3acac49ad8e373099a531b9884d12383b7ce8c342a5cad08888","raw_frame":"{\"market\":\"0x3b40066b5cf3871a2f6237c5628bd8092a206aa998558ac5ec13c4483e31e160\", \"price_changes\":[{\"asset_id\":\"110216635572655435074987471276357323571387854733835379371586402147734167783946\", \"price\":\"0.7\", \"size\":\"45.06\", \"side\":\"BUY\", \"hash\":\"1a85f07ee3d4d6aa2d386fd0f08cd2d32e35c416\", \"best_bid\":\"0.72\", \"best_ask\":\"0.73\"}, {\"asset_id\":\"14766054693214075530629349735273995982307625376442606753688071083149620216746\", \"price\":\"0.3\", \"size\":\"45.06\", \"side\":\"SELL\", \"hash\":\"92f949d52de2e903b9fe611d205db0598624cf65\", \"best_bid\":\"0.27\", \"best_ask\":\"0.28\"}], \"timestamp\":\"1785130652119\", \"event_type\":\"price_change\"}","received_at":"2026-07-27T05:37:32.080820Z","schema_version":"clob-market-ws.price_change.v1","sequence":null,"server_hash":null,"server_timestamp":"1785130652119","session_id":"502006c5cfcd437296561ea750c9ec8b","source":"clob_market_ws"},"received_at":"2026-07-27T05:37:32.080820Z","record_id":"210721622eecf72a593ac4bd6b30bf8bf0700c2642f37b5ecf101d4e492d64d3","schema_fingerprint":"4aa3821a28b0b7c2400bc59aba4bcc0a76e971dadd19610d3ad38c768e124dc7","schema_version":"edge-lab-recorder.raw.v1","sequence":null,"source":"clob_market_ws"}
{"event_at":"2026-07-27T05:37:32.121000Z","event_fingerprint":"2dd65fc0c4ca45c5497decb6c320a567a3d13d2a1cb67491e214fe35bc5bb304","payload":{"connection_id":"efc69d3132f1467b8e898a382b23ac0d","event_at":"2026-07-27T05:37:32.121000Z","event_type":"price_change","frame_hash":"2a6e0104ff044c8a8e023de21dd1eff9e14861899d152cc87bd6c6aa6ce82ae8","frame_index":0,"kind":"data","monotonic_ns":232635316576208,"payload":{"event_type":"price_change","market":"0x3b40066b5cf3871a2f6237c5628bd8092a206aa998558ac5ec13c4483e31e160","price_changes":[{"asset_id":"14766054693214075530629349735273995982307625376442606753688071083149620216746","best_ask":"0.28","best_bid":"0.27","hash":"f5d79c61a14a77332308377cf08d12e3ec13c5d1","price":"0.47","side":"SELL","size":"55"},{"asset_id":"110216635572655435074987471276357323571387854733835379371586402147734167783946","best_ask":"0.73","best_bid":"0.72","hash":"04723a15995993338dd967f5e9d2a2342250ff32","price":"0.53","side":"BUY","size":"55"}],"timestamp":"1785130652121"},"payload_hash":"6cbffd64a5b18d119fc47e1daaa7704ffff6389336516650a3b47a2dfbe232dc","raw_frame":"{\"market\":\"0x3b40066b5cf3871a2f6237c5628bd8092a206aa998558ac5ec13c4483e31e160\", \"price_changes\":[{\"asset_id\":\"14766054693214075530629349735273995982307625376442606753688071083149620216746\", \"price\":\"0.47\", \"size\":\"55\", \"side\":\"SELL\", \"hash\":\"f5d79c61a14a77332308377cf08d12e3ec13c5d1\", \"best_bid\":\"0.27\", \"best_ask\":\"0.28\"}, {\"asset_id\":\"110216635572655435074987471276357323571387854733835379371586402147734167783946\", \"price\":\"0.53\", \"size\":\"55\", \"side\":\"BUY\", \"hash\":\"04723a15995993338dd967f5e9d2a2342250ff32\", \"best_bid\":\"0.72\", \"best_ask\":\"0.73\"}], \"timestamp\":\"1785130652121\", \"event_type\":\"price_change\"}","received_at":"2026-07-27T05:37:32.081514Z","schema_version":"clob-market-ws.price_change.v1","sequence":null,"server_hash":null,"server_timestamp":"1785130652121","session_id":"502006c5cfcd437296561ea750c9ec8b","source":"clob_market_ws"},"received_at":"2026-07-27T05:37:32.081514Z","record_id":"eba7cbcd04d25344ac9cc1bd34700cb10733d9ec528da61143c188d0fea6d3ba","schema_fingerprint":"4aa3821a28b0b7c2400bc59aba4bcc0a76e971dadd19610d3ad38c768e124dc7","schema_version":"edge-lab-recorder.raw.v1","sequence":null,"source":"clob_market_ws"}
{"event_at":"2026-07-27T05:37:32.122000Z","event_fingerprint":"3eb33c90ba684ba202a3c387c6556a706ba650b0a7de1001c85235c47b943673","payload":{"connection_id":"efc69d3132f1467b8e898a382b23ac0d","event_at":"2026-07-27T05:37:32.122000Z","event_type":"price_change","frame_hash":"b1e59e943866e183686d475c7eae3af02b89f6c8ebd58bccd71d5182d2aa7cf7","frame_index":0,"kind":"data","monotonic_ns":232635317700916,"payload":{"event_type":"price_change","market":"0x3b40066b5cf3871a2f6237c5628bd8092a206aa998558ac5ec13c4483e31e160","price_changes":[{"asset_id":"14766054693214075530629349735273995982307625376442606753688071083149620216746","best_ask":"0.28","best_bid":"0.27","hash":"f1cebad5d9f3c08bf9332399152667f1aece61d7","price":"0.3","side":"SELL","size":"72"},{"asset_id":"110216635572655435074987471276357323571387854733835379371586402147734167783946","best_ask":"0.73","best_bid":"0.72","hash":"ac35592044ad1b2790af656fd571a8e2818926c2","price":"0.7","side":"BUY","size":"72"}],"timestamp":"1785130652122"},"payload_hash":"2a9e35eb2a585e8c6d68865df2a7ea40ba1ca9c179ef6dd42010b21ba3499075","raw_frame":"{\"market\":\"0x3b40066b5cf3871a2f6237c5628bd8092a206aa998558ac5ec13c4483e31e160\", \"price_changes\":[{\"asset_id\":\"14766054693214075530629349735273995982307625376442606753688071083149620216746\", \"price\":\"0.3\", \"size\":\"72\", \"side\":\"SELL\", \"hash\":\"f1cebad5d9f3c08bf9332399152667f1aece61d7\", \"best_bid\":\"0.27\", \"best_ask\":\"0.28\"}, {\"asset_id\":\"110216635572655435074987471276357323571387854733835379371586402147734167783946\", \"price\":\"0.7\", \"size\":\"72\", \"side\":\"BUY\", \"hash\":\"ac35592044ad1b2790af656fd571a8e2818926c2\", \"best_bid\":\"0.72\", \"best_ask\":\"0.73\"}], \"timestamp\":\"1785130652122\", \"event_type\":\"price_change\"}","received_at":"2026-07-27T05:37:32.082632Z","schema_version":"clob-market-ws.price_change.v1","sequence":null,"server_hash":null,"server_timestamp":"1785130652122","session_id":"502006c5cfcd437296561ea750c9ec8b","source":"clob_market_ws"},"received_at":"2026-07-27T05:37:32.082632Z","record_id":"6dcac27cd54dcf4d9adb4f1db8e74c170a4d3b50f0c7e0c6fbb55a227e88e706","schema_fingerprint":"4aa3821a28b0b7c2400bc59aba4bcc0a76e971dadd19610d3ad38c768e124dc7","schema_version":"edge-lab-recorder.raw.v1","sequence":null,"source":"clob_market_ws"}
{"event_at":"2026-07-27T05:37:32.124000Z","event_fingerprint":"903db161d87b877f17e7d2444df542109c73e51f7a4900e65767549781424cf2","payload":{"connection_id":"efc69d3132f1467b8e898a382b23ac0d","event_at":"2026-07-27T05:37:32.124000Z","event_type":"price_change","frame_hash":"f1716e08a6d0e3dfefe6fa0f5f260299b606cd4872c1032881c7c3d615c760e8","frame_index":0,"kind":"data","monotonic_ns":232635319341208,"payload":{"event_type":"price_change","market":"0x3b40066b5cf3871a2f6237c5628bd8092a206aa998558ac5ec13c4483e31e160","price_changes":[{"asset_id":"14766054693214075530629349735273995982307625376442606753688071083149620216746","best_ask":"0.28","best_bid":"0.27","hash":"e88d8cc696a9a3b0d750968193987ff2cac56723","price":"0.31","side":"SELL","size":"128"},{"asset_id":"110216635572655435074987471276357323571387854733835379371586402147734167783946","best_ask":"0.73","best_bid":"0.72","hash":"6e67083f64ce421119ba0e4115e27adb1addd104","price":"0.69","side":"BUY","size":"128"}],"timestamp":"1785130652124"},"payload_hash":"07f069a3fecfb75f2f93e9c036e2c6b2b35260e413e909a6b8d0fa170aeec1cd","raw_frame":"{\"market\":\"0x3b40066b5cf3871a2f6237c5628bd8092a206aa998558ac5ec13c4483e31e160\", \"price_changes\":[{\"asset_id\":\"14766054693214075530629349735273995982307625376442606753688071083149620216746\", \"price\":\"0.31\", \"size\":\"128\", \"side\":\"SELL\", \"hash\":\"e88d8cc696a9a3b0d750968193987ff2cac56723\", \"best_bid\":\"0.27\", \"best_ask\":\"0.28\"}, {\"asset_id\":\"110216635572655435074987471276357323571387854733835379371586402147734167783946\", \"price\":\"0.69\", \"size\":\"128\", \"side\":\"BUY\", \"hash\":\"6e67083f64ce421119ba0e4115e27adb1addd104\", \"best_bid\":\"0.72\", \"best_ask\":\"0.73\"}], \"timestamp\":\"1785130652124\", \"event_type\":\"price_change\"}","received_at":"2026-07-27T05:37:32.084271Z","schema_version":"clob-market-ws.price_change.v1","sequence":null,"server_hash":null,"server_timestamp":"1785130652124","session_id":"502006c5cfcd437296561ea750c9ec8b","source":"clob_market_ws"},"received_at":"2026-07-27T05:37:32.084271Z","record_id":"d76426f8e1c4271188071a7a95663d1e4fd581d7c6c1d9ae9f7e1a0440cef7fa","schema_fingerprint":"4aa3821a28b0b7c2400bc59aba4bcc0a76e971dadd19610d3ad38c768e124dc7","schema_version":"edge-lab-recorder.raw.v1","sequence":null,"source":"clob_market_ws"}
{"event_at":"2026-07-27T05:37:32.143000Z","event_fingerprint":"f5442a3fd9a060e45c2d3610a9fb8f9362b8d88a77c2d05abf3233d3ed4cfb6b","payload":{"connection_id":"efc69d3132f1467b8e898a382b23ac0d","event_at":"2026-07-27T05:37:32.143000Z","event_type":"price_change","frame_hash":"79d685195b6afb55761b0a285df99cc864e2b3dcd8a6a3537a5e1687f37634b9","frame_index":0,"kind":"data","monotonic_ns":232635337972708,"payload":{"event_type":"price_change","market":"0x3b40066b5cf3871a2f6237c5628bd8092a206aa998558ac5ec13c4483e31e160","price_changes":[{"asset_id":"14766054693214075530629349735273995982307625376442606753688071083149620216746","best_ask":"0.28","best_bid":"0.27","hash":"e8dc4eaa57331d054de65279ea2ea5f1232d7ec3","price":"0.01","side":"BUY","size":"5628.02"},{"asset_id":"110216635572655435074987471276357323571387854733835379371586402147734167783946","best_ask":"0.73","best_bid":"0.72","hash":"cd821624b1ae9e068a551c838c4e24a614cd36f8","price":"0.99","side":"SELL","size":"5628.02"}],"timestamp":"1785130652143"},"payload_hash":"00392f0ce67af9b7dc0aa0f2fe3650d617598d12f3fb95feeb1636fb15976b7a","raw_frame":"{\"market\":\"0x3b40066b5cf3871a2f6237c5628bd8092a206aa998558ac5ec13c4483e31e160\", \"price_changes\":[{\"asset_id\":\"14766054693214075530629349735273995982307625376442606753688071083149620216746\", \"price\":\"0.01\", \"size\":\"5628.02\", \"side\":\"BUY\", \"hash\":\"e8dc4eaa57331d054de65279ea2ea5f1232d7ec3\", \"best_bid\":\"0.27\", \"best_ask\":\"0.28\"}, {\"asset_id\":\"110216635572655435074987471276357323571387854733835379371586402147734167783946\", \"price\":\"0.99\", \"size\":\"5628.02\", \"side\":\"SELL\", \"hash\":\"cd821624b1ae9e068a551c838c4e24a614cd36f8\", \"best_bid\":\"0.72\", \"best_ask\":\"0.73\"}], \"timestamp\":\"1785130652143\", \"event_type\":\"price_change\"}","received_at":"2026-07-27T05:37:32.102902Z","schema_version":"clob-market-ws.price_change.v1","sequence":null,"server_hash":null,"server_timestamp":"1785130652143","session_id":"502006c5cfcd437296561ea750c9ec8b","source":"clob_market_ws"},"received_at":"2026-07-27T05:37:32.102902Z","record_id":"72bb5c4cd9522ab246641377cd1dbd61ce544b67b94d02b956d52c0f88f05464","schema_fingerprint":"4aa3821a28b0b7c2400bc59aba4bcc0a76e971dadd19610d3ad38c768e124dc7","schema_version":"edge-lab-recorder.raw.v1","sequence":null,"source":"clob_market_ws"}
{"event_at":"2026-07-27T05:37:32.164000Z","event_fingerprint":"0b61cca6db8f9ae3ef5ea0e26ff37e420f53e8694b6153083dc689c0857730d2","payload":{"connection_id":"efc69d3132f1467b8e898a382b23ac0d","event_at":"2026-07-27T05:37:32.164000Z","event_type":"price_change","frame_hash":"8c00d7afbb1efdc6658eabdcb785778a6dbc3cacd11f8017c4f7762f16d9b134","frame_index":0,"kind":"data","monotonic_ns":232635358003666,"payload":{"event_type":"price_change","market":"0x3b40066b5cf3871a2f6237c5628bd8092a206aa998558ac5ec13c4483e31e160","price_changes":[{"asset_id":"14766054693214075530629349735273995982307625376442606753688071083149620216746","best_ask":"0.28","best_bid":"0.27","hash":"0dfbd168fa01e8e9baf4a6190f575829c645b352","price":"0.01","side":"BUY","size":"5623.02"},{"asset_id":"110216635572655435074987471276357323571387854733835379371586402147734167783946","best_ask":"0.73","best_bid":"0.72","hash":"837955038a3ed554bae3171db192dd5002b9de3e","price":"0.99","side":"SELL","size":"5623.02"}],"timestamp":"1785130652164"},"payload_hash":"f950580b1c9cb9273d28f58ba9749b9e80c4174a37f5cb0fa5d2ee9b61fbdf68","raw_frame":"{\"market\":\"0x3b40066b5cf3871a2f6237c5628bd8092a206aa998558ac5ec13c4483e31e160\", \"price_changes\":[{\"asset_id\":\"14766054693214075530629349735273995982307625376442606753688071083149620216746\", \"price\":\"0.01\", \"size\":\"5623.02\", \"side\":\"BUY\", \"hash\":\"0dfbd168fa01e8e9baf4a6190f575829c645b352\", \"best_bid\":\"0.27\", \"best_ask\":\"0.28\"}, {\"asset_id\":\"110216635572655435074987471276357323571387854733835379371586402147734167783946\", \"price\":\"0.99\", \"size\":\"5623.02\", \"side\":\"SELL\", \"hash\":\"837955038a3ed554bae3171db192dd5002b9de3e\", \"best_bid\":\"0.72\", \"best_ask\":\"0.73\"}], \"timestamp\":\"1785130652164\", \"event_type\":\"price_change\"}","received_at":"2026-07-27T05:37:32.122933Z","schema_version":"clob-market-ws.price_change.v1","sequence":null,"server_hash":null,"server_timestamp":"1785130652164","session_id":"502006c5cfcd437296561ea750c9ec8b","source":"clob_market_ws"},"received_at":"2026-07-27T05:37:32.122933Z","record_id":"567e4accacca33f30c7d9d28445e154f1088141e98f1e117cc0abcd10107ac03","schema_fingerprint":"4aa3821a28b0b7c2400bc59aba4bcc0a76e971dadd19610d3ad38c768e124dc7","schema_version":"edge-lab-recorder.raw.v1","sequence":null,"source":"clob_market_ws"}
{"event_at":"2026-07-27T05:37:32.176000Z","event_fingerprint":"7e8276d010c8bfca2736007dee4a0f08617af9fbb8e7dfcc163e5b1764ca0f35","payload":{"connection_id":"efc69d3132f1467b8e898a382b23ac0d","event_at":"2026-07-27T05:37:32.176000Z","event_type":"price_change","frame_hash":"485ef1fba200d62b90ffcd3c45dfe213a1e47186f2ca3f19103269be68f8b57f","frame_index":0,"kind":"data","monotonic_ns":232635370096500,"payload":{"event_type":"price_change","market":"0x3b40066b5cf3871a2f6237c5628bd8092a206aa998558ac5ec13c4483e31e160","price_changes":[{"asset_id":"110216635572655435074987471276357323571387854733835379371586402147734167783946","best_ask":"0.73","best_bid":"0.72","hash":"e01de7e52ab12e35fb3ea8834e43450b604ef68d","price":"0.01","side":"BUY","size":"5612.45"},{"asset_id":"14766054693214075530629349735273995982307625376442606753688071083149620216746","best_ask":"0.28","best_bid":"0.27","hash":"3bd92c0dc5d48ed52931233ca26fcbab5b7fd66d","price":"0.99","side":"SELL","size":"5612.45"}],"timestamp":"1785130652176"},"payload_hash":"54d1f946ece53260765b411ab4e6aa03049956960315649b98fa54854d3fdd19","raw_frame":"{\"market\":\"0x3b40066b5cf3871a2f6237c5628bd8092a206aa998558ac5ec13c4483e31e160\", \"price_changes\":[{\"asset_id\":\"110216635572655435074987471276357323571387854733835379371586402147734167783946\", \"price\":\"0.01\", \"size\":\"5612.45\", \"side\":\"BUY\", \"hash\":\"e01de7e52ab12e35fb3ea8834e43450b604ef68d\", \"best_bid\":\"0.72\", \"best_ask\":\"0.73\"}, {\"asset_id\":\"14766054693214075530629349735273995982307625376442606753688071083149620216746\", \"price\":\"0.99\", \"size\":\"5612.45\", \"side\":\"SELL\", \"hash\":\"3bd92c0dc5d48ed52931233ca26fcbab5b7fd66d\", \"best_bid\":\"0.27\", \"best_ask\":\"0.28\"}], \"timestamp\":\"1785130652176\", \"event_type\":\"price_change\"}","received_at":"2026-07-27T05:37:32.135027Z","schema_version":"clob-market-ws.price_change.v1","sequence":null,"server_hash":null,"server_timestamp":"1785130652176","session_id":"502006c5cfcd437296561ea750c9ec8b","source":"clob_market_ws"},"received_at":"2026-07-27T05:37:32.135027Z","record_id":"2ad288342accc23882910e077036cdec6afdeb4d0d0ac621af32d4da0fe40676","schema_fingerprint":"4aa3821a28b0b7c2400bc59aba4bcc0a76e971dadd19610d3ad38c768e124dc7","schema_version":"edge-lab-recorder.raw.v1","sequence":null,"source":"clob_market_ws"}
{"event_at":"2026-07-27T05:37:32.199000Z","event_fingerprint":"d8c995ee6e138f8eb68db1844bdf895b55c86b499fd4ca46455bd4992dede0c8","payload":{"connection_id":"efc69d3132f1467b8e898a382b23ac0d","event_at":"2026-07-27T05:37:32.199000Z","event_type":"price_change","frame_hash":"215252c7ee81528d5f6c1ed2f13029838609261f7c078bb9daac0f3ae6d2976c","frame_index":0,"kind":"data","monotonic_ns":232635396336083,"payload":{"event_type":"price_change","market":"0x3b40066b5cf3871a2f6237c5628bd8092a206aa998558ac5ec13c4483e31e160","price_changes":[{"asset_id":"110216635572655435074987471276357323571387854733835379371586402147734167783946","best_ask":"0.73","best_bid":"0.72","hash":"b30d290cb8748a75d23d1fb33b78a313bb9e2248","price":"0.71","side":"BUY","size":"59.4"},{"asset_id":"14766054693214075530629349735273995982307625376442606753688071083149620216746","best_ask":"0.28","best_bid":"0.27","hash":"a54a0e4e1ef59471f5142705f7affadb479d2d4b","price":"0.29","side":"SELL","size":"59.4"}],"timestamp":"1785130652199"},"payload_hash":"c04f5626559341c977a285f3b3de7f5f9e633def1fcc67b3a60080cb9925fb0f","raw_frame":"{\"market\":\"0x3b40066b5cf3871a2f6237c5628bd8092a206aa998558ac5ec13c4483e31e160\", \"price_changes\":[{\"asset_id\":\"110216635572655435074987471276357323571387854733835379371586402147734167783946\", \"price\":\"0.71\", \"size\":\"59.4\", \"side\":\"BUY\", \"hash\":\"b30d290cb8748a75d23d1fb33b78a313bb9e2248\", \"best_bid\":\"0.72\", \"best_ask\":\"0.73\"}, {\"asset_id\":\"14766054693214075530629349735273995982307625376442606753688071083149620216746\", \"price\":\"0.29\", \"size\":\"59.4\", \"side\":\"SELL\", \"hash\":\"a54a0e4e1ef59471f5142705f7affadb479d2d4b\", \"best_bid\":\"0.27\", \"best_ask\":\"0.28\"}], \"timestamp\":\"1785130652199\", \"event_type\":\"price_change\"}","received_at":"2026-07-27T05:37:32.161268Z","schema_version":"clob-market-ws.price_change.v1","sequence":null,"server_hash":null,"server_timestamp":"1785130652199","session_id":"502006c5cfcd437296561ea750c9ec8b","source":"clob_market_ws"},"received_at":"2026-07-27T05:37:32.161268Z","record_id":"8d14d2ca933dc73509cbd362766fd67388ae9069d0b38c64dbdcd5a222c2c213","schema_fingerprint":"4aa3821a28b0b7c2400bc59aba4bcc0a76e971dadd19610d3ad38c768e124dc7","schema_version":"edge-lab-recorder.raw.v1","sequence":null,"source":"clob_market_ws"}
{"event_at":"2026-07-27T05:37:32.200000Z","event_fingerprint":"b0eaa9717f7ff70a6aff59b41cd1233dc8b6add954a1feecef18e9858140da70","payload":{"connection_id":"efc69d3132f1467b8e898a382b23ac0d","event_at":"2026-07-27T05:37:32.200000Z","event_type":"price_change","frame_hash":"1875ef44407e03dcf955ea4c6c9a1522d3f60694e29b4b0b8f37917eaae31491","frame_index":0,"kind":"data","monotonic_ns":232635399295708,"payload":{"event_type":"price_change","market":"0x3b40066b5cf3871a2f6237c5628bd8092a206aa998558ac5ec13c4483e31e160","price_changes":[{"asset_id":"110216635572655435074987471276357323571387854733835379371586402147734167783946","best_ask":"0.73","best_bid":"0.72","hash":"8b9bd837254474bbe2f083d165a50f5c5a6f08f2","price":"0.72","side":"BUY","size":"366"},{"asset_id":"14766054693214075530629349735273995982307625376442606753688071083149620216746","best_ask":"0.28","best_bid":"0.27","hash":"3ee908a8149ee6df69d7e9a0e4f269133a87886c","price":"0.28","side":"SELL","size":"366"}],"timestamp":"1785130652200"},"payload_hash":"da7d5e94d88ec708ea79592f6d666c82ea30336695ee75e6408949a6e8024952","raw_frame":"{\"market\":\"0x3b40066b5cf3871a2f6237c5628bd8092a206aa998558ac5ec13c4483e31e160\", \"price_changes\":[{\"asset_id\":\"110216635572655435074987471276357323571387854733835379371586402147734167783946\", \"price\":\"0.72\", \"size\":\"366\", \"side\":\"BUY\", \"hash\":\"8b9bd837254474bbe2f083d165a50f5c5a6f08f2\", \"best_bid\":\"0.72\", \"best_ask\":\"0.73\"}, {\"asset_id\":\"14766054693214075530629349735273995982307625376442606753688071083149620216746\", \"price\":\"0.28\", \"size\":\"366\", \"side\":\"SELL\", \"hash\":\"3ee908a8149ee6df69d7e9a0e4f269133a87886c\", \"best_bid\":\"0.27\", \"best_ask\":\"0.28\"}], \"timestamp\":\"1785130652200\", \"event_type\":\"price_change\"}","received_at":"2026-07-27T05:37:32.164233Z","schema_version":"clob-market-ws.price_change.v1","sequence":null,"server_hash":null,"server_timestamp":"1785130652200","session_id":"502006c5cfcd437296561ea750c9ec8b","source":"clob_market_ws"},"received_at":"2026-07-27T05:37:32.164233Z","record_id":"eca12fae9e8fb8631503c23697b4df15521f62549d4095a06e335fd33f0995c6","schema_fingerprint":"4aa3821a28b0b7c2400bc59aba4bcc0a76e971dadd19610d3ad38c768e124dc7","schema_version":"edge-lab-recorder.raw.v1","sequence":null,"source":"clob_market_ws"}
{"event_at":"2026-07-27T05:37:32.220000Z","event_fingerprint":"8d24b0283507f47deb378503ab89b03401775deca985ecc1bce96b969be450ab","payload":{"connection_id":"efc69d3132f1467b8e898a382b23ac0d","event_at":"2026-07-27T05:37:32.220000Z","event_type":"price_change","frame_hash":"d3ebeb220fe8fff0d6058b2d775bff1da6d9806073d7ff0d8256c0fe70733add","frame_index":0,"kind":"data","monotonic_ns":232635418677291,"payload":{"event_type":"price_change","market":"0x3b40066b5cf3871a2f6237c5628bd8092a206aa998558ac5ec13c4483e31e160","price_changes":[{"asset_id":"14766054693214075530629349735273995982307625376442606753688071083149620216746","best_ask":"0.28","best_bid":"0.27","hash":"6d388d8b85b5bee997ea54d11bead95c8513bdaf","price":"0.31","side":"SELL","size":"121"},{"asset_id":"110216635572655435074987471276357323571387854733835379371586402147734167783946","best_ask":"0.73","best_bid":"0.72","hash":"696c286d8ea4ee63594a035673475996abdaaeb9","price":"0.69","side":"BUY","size":"121"}],"timestamp":"1785130652220"},"payload_hash":"683dfb81cce2990855d2bac3977fff22820e744e8b0f1c6cc5911f7b55110cb1","raw_frame":"{\"market\":\"0x3b40066b5cf3871a2f6237c5628bd8092a206aa998558ac5ec13c4483e31e160\", \"price_changes\":[{\"asset_id\":\"14766054693214075530629349735273995982307625376442606753688071083149620216746\", \"price\":\"0.31\", \"size\":\"121\", \"side\":\"SELL\", \"hash\":\"6d388d8b85b5bee997ea54d11bead95c8513bdaf\", \"best_bid\":\"0.27\", \"best_ask\":\"0.28\"}, {\"asset_id\":\"110216635572655435074987471276357323571387854733835379371586402147734167783946\", \"price\":\"0.69\", \"size\":\"121\", \"side\":\"BUY\", \"hash\":\"696c286d8ea4ee63594a035673475996abdaaeb9\", \"best_bid\":\"0.72\", \"best_ask\":\"0.73\"}], \"timestamp\":\"1785130652220\", \"event_type\":\"price_change\"}","received_at":"2026-07-27T05:37:32.183608Z","schema_version":"clob-market-ws.price_change.v1","sequence":null,"server_hash":null,"server_timestamp":"1785130652220","session_id":"502006c5cfcd437296561ea750c9ec8b","source":"clob_market_ws"},"received_at":"2026-07-27T05:37:32.183608Z","record_id":"6aad39edf600c315115e837be8e22ed909a401c8d0afb4d07d0173ac4c7c9e56","schema_fingerprint":"4aa3821a28b0b7c2400bc59aba4bcc0a76e971dadd19610d3ad38c768e124dc7","schema_version":"edge-lab-recorder.raw.v1","sequence":null,"source":"clob_market_ws"}
{"event_at":"2026-07-27T05:37:32.221000Z","event_fingerprint":"8472c47935c1d7fe0772e51e5be5244e009dff670c5eadd300b6c6f3917ef748","payload":{"connection_id":"efc69d3132f1467b8e898a382b23ac0d","event_at":"2026-07-27T05:37:32.221000Z","event_type":"price_change","frame_hash":"2ff91c4c55095634f55ac0dcc9a72e22c47ae70fdccf2082e49d2cf63ef84ee6","frame_index":0,"kind":"data","monotonic_ns":232635420262500,"payload":{"event_type":"price_change","market":"0x3b40066b5cf3871a2f6237c5628bd8092a206aa998558ac5ec13c4483e31e160","price_changes":[{"asset_id":"14766054693214075530629349735273995982307625376442606753688071083149620216746","best_ask":"0.28","best_bid":"0.27","hash":"a21ace00b821a09d09fcf88fb26b62a07bcb9ccf","price":"0.3","side":"SELL","size":"45.06"},{"asset_id":"110216635572655435074987471276357323571387854733835379371586402147734167783946","best_ask":"0.73","best_bid":"0.72","hash":"993a35e609a65aae332f9c7441204abed262e756","price":"0.7","side":"BUY","size":"45.06"}],"timestamp":"1785130652221"},"payload_hash":"e73af6bca75d7222072295597cd7201ae1201a096691a5f9cbc1e96aa2535e38","raw_frame":"{\"market\":\"0x3b40066b5cf3871a2f6237c5628bd8092a206aa998558ac5ec13c4483e31e160\", \"price_changes\":[{\"asset_id\":\"14766054693214075530629349735273995982307625376442606753688071083149620216746\", \"price\":\"0.3\", \"size\":\"45.06\", \"side\":\"SELL\", \"hash\":\"a21ace00b821a09d09fcf88fb26b62a07bcb9ccf\", \"best_bid\":\"0.27\", \"best_ask\":\"0.28\"}, {\"asset_id\":\"110216635572655435074987471276357323571387854733835379371586402147734167783946\", \"price\":\"0.7\", \"size\":\"45.06\", \"side\":\"BUY\", \"hash\":\"993a35e609a65aae332f9c7441204abed262e756\", \"best_bid\":\"0.72\", \"best_ask\":\"0.73\"}], \"timestamp\":\"1785130652221\", \"event_type\":\"price_change\"}","received_at":"2026-07-27T05:37:32.185195Z","schema_version":"clob-market-ws.price_change.v1","sequence":null,"server_hash":null,"server_timestamp":"1785130652221","session_id":"502006c5cfcd437296561ea750c9ec8b","source":"clob_market_ws"},"received_at":"2026-07-27T05:37:32.185195Z","record_id":"37e5f5bfd0f740bd494f709b5370cf0041b975ce25d2fb0dfb1509b4be44b851","schema_fingerprint":"4aa3821a28b0b7c2400bc59aba4bcc0a76e971dadd19610d3ad38c768e124dc7","schema_version":"edge-lab-recorder.raw.v1","sequence":null,"source":"clob_market_ws"}
{"event_at":"2026-07-27T05:37:32.224000Z","event_fingerprint":"d501ae7b184dc2655e2c6b797d4a33c76ff80de3e7727a7e4ce0d2f12bcc5b70","payload":{"connection_id":"efc69d3132f1467b8e898a382b23ac0d","event_at":"2026-07-27T05:37:32.224000Z","event_type":"price_change","frame_hash":"e7ddcdfd7e0e15d0eca97a188c267fa3bd86cf753d8eeafd93b88ea648318dd4","frame_index":0,"kind":"data","monotonic_ns":232635421778666,"payload":{"event_type":"price_change","market":"0x3b40066b5cf3871a2f6237c5628bd8092a206aa998558ac5ec13c4483e31e160","price_changes":[{"asset_id":"110216635572655435074987471276357323571387854733835379371586402147734167783946","best_ask":"0.73","best_bid":"0.72","hash":"b5d92cdee09e17c203e72b117dd74c7294a8d8c6","price":"0.7","side":"BUY","size":"72"},{"asset_id":"14766054693214075530629349735273995982307625376442606753688071083149620216746","best_ask":"0.28","best_bid":"0.27","hash":"2c416ca780509d7d630b19029887b758077684a9","price":"0.3","side":"SELL","size":"72"}],"timestamp":"1785130652224"},"payload_hash":"f61f4727544482dcddffb6ebc331692ed2fd3d36f5ac3d6c027d1a9c976ac330","raw_frame":"{\"market\":\"0x3b40066b5cf3871a2f6237c5628bd8092a206aa998558ac5ec13c4483e31e160\", \"price_changes\":[{\"asset_id\":\"110216635572655435074987471276357323571387854733835379371586402147734167783946\", \"price\":\"0.7\", \"size\":\"72\", \"side\":\"BUY\", \"hash\":\"b5d92cdee09e17c203e72b117dd74c7294a8d8c6\", \"best_bid\":\"0.72\", \"best_ask\":\"0.73\"}, {\"asset_id\":\"14766054693214075530629349735273995982307625376442606753688071083149620216746\", \"price\":\"0.3\", \"size\":\"72\", \"side\":\"SELL\", \"hash\":\"2c416ca780509d7d630b19029887b758077684a9\", \"best_bid\":\"0.27\", \"best_ask\":\"0.28\"}], \"timestamp\":\"1785130652224\", \"event_type\":\"price_change\"}","received_at":"2026-07-27T05:37:32.186710Z","schema_version":"clob-market-ws.price_change.v1","sequence":null,"server_hash":null,"server_timestamp":"1785130652224","session_id":"502006c5cfcd437296561ea750c9ec8b","source":"clob_market_ws"},"received_at":"2026-07-27T05:37:32.186710Z","record_id":"83a29329b556f99b41f68017b1de962cc06314ca8b47f8cfbdaf52aae84da853","schema_fingerprint":"4aa3821a28b0b7c2400bc59aba4bcc0a76e971dadd19610d3ad38c768e124dc7","schema_version":"edge-lab-recorder.raw.v1","sequence":null,"source":"clob_market_ws"}
{"event_at":"2026-07-27T05:37:32.257000Z","event_fingerprint":"24db8c1b918a25d36457dae43567fd3f5d2eef08f4bad685d64693b13f41ed20","payload":{"connection_id":"efc69d3132f1467b8e898a382b23ac0d","event_at":"2026-07-27T05:37:32.257000Z","event_type":"price_change","frame_hash":"fc47c3e375d7b92281dfd9e829b801bcd1ba5a3d5da2185cd4a5a24b0727c2e5","frame_index":0,"kind":"data","monotonic_ns":232635452219416,"payload":{"event_type":"price_change","market":"0x3b40066b5cf3871a2f6237c5628bd8092a206aa998558ac5ec13c4483e31e160","price_changes":[{"asset_id":"110216635572655435074987471276357323571387854733835379371586402147734167783946","best_ask":"0.73","best_bid":"0.72","hash":"8d49dbd105da7e4fdad80677e5f97e628a7206cf","price":"0.02","side":"BUY","size":"688.1"},{"asset_id":"14766054693214075530629349735273995982307625376442606753688071083149620216746","best_ask":"0.28","best_bid":"0.27","hash":"de20f3da810ed8e46fa395e76a075b3871e3c70b","price":"0.98","side":"SELL","size":"688.1"}],"timestamp":"1785130652257"},"payload_hash":"1036b77dae2befe1a23f849debac6e708fd8b7d3cd3286892546d71d5a1abe40","raw_frame":"{\"market\":\"0x3b40066b5cf3871a2f6237c5628bd8092a206aa998558ac5ec13c4483e31e160\", \"price_changes\":[{\"asset_id\":\"110216635572655435074987471276357323571387854733835379371586402147734167783946\", \"price\":\"0.02\", \"size\":\"688.1\", \"side\":\"BUY\", \"hash\":\"8d49dbd105da7e4fdad80677e5f97e628a7206cf\", \"best_bid\":\"0.72\", \"best_ask\":\"0.73\"}, {\"asset_id\":\"14766054693214075530629349735273995982307625376442606753688071083149620216746\", \"price\":\"0.98\", \"size\":\"688.1\", \"side\":\"SELL\", \"hash\":\"de20f3da810ed8e46fa395e76a075b3871e3c70b\", \"best_bid\":\"0.27\", \"best_ask\":\"0.28\"}], \"timestamp\":\"1785130652257\", \"event_type\":\"price_change\"}","received_at":"2026-07-27T05:37:32.217151Z","schema_version":"clob-market-ws.price_change.v1","sequence":null,"server_hash":null,"server_timestamp":"1785130652257","session_id":"502006c5cfcd437296561ea750c9ec8b","source":"clob_market_ws"},"received_at":"2026-07-27T05:37:32.217151Z","record_id":"06ad82025cf8120efb36241f9f8653340cc9488510d6c3b2dbbaaabea4fe8147","schema_fingerprint":"4aa3821a28b0b7c2400bc59aba4bcc0a76e971dadd19610d3ad38c768e124dc7","schema_version":"edge-lab-recorder.raw.v1","sequence":null,"source":"clob_market_ws"}
{"event_at":"2026-07-27T05:37:32.331000Z","event_fingerprint":"3df60ba5f80bf8ed216fd9a9deffda31bbe8a0d7f844fbc2c359a80cead2b08f","payload":{"connection_id":"efc69d3132f1467b8e898a382b23ac0d","event_at":"2026-07-27T05:37:32.331000Z","event_type":"price_change","frame_hash":"f68aa7c85980021715c01c631fb110e4d8f549c5e6bb402eefa1d3fc58cba78f","frame_index":0,"kind":"data","monotonic_ns":232635524239750,"payload":{"event_type":"price_change","market":"0x3b40066b5cf3871a2f6237c5628bd8092a206aa998558ac5ec13c4483e31e160","price_changes":[{"asset_id":"110216635572655435074987471276357323571387854733835379371586402147734167783946","best_ask":"0.73","best_bid":"0.72","hash":"f51661f57e16213614ac2780339c980e2d88e243","price":"0.7","side":"BUY","size":"45.06"},{"asset_id":"14766054693214075530629349735273995982307625376442606753688071083149620216746","best_ask":"0.28","best_bid":"0.27","hash":"d42c623f9dc5723bac6aea7998a002badbdcc35c","price":"0.3","side":"SELL","size":"45.06"}],"timestamp":"1785130652331"},"payload_hash":"2cb73ec84a96c0dfe5bcdb990f00b383dabeb3488e69da32c98b8299264f03bc","raw_frame":"{\"market\":\"0x3b40066b5cf3871a2f6237c5628bd8092a206aa998558ac5ec13c4483e31e160\", \"price_changes\":[{\"asset_id\":\"110216635572655435074987471276357323571387854733835379371586402147734167783946\", \"price\":\"0.7\", \"size\":\"45.06\", \"side\":\"BUY\", \"hash\":\"f51661f57e16213614ac2780339c980e2d88e243\", \"best_bid\":\"0.72\", \"best_ask\":\"0.73\"}, {\"asset_id\":\"14766054693214075530629349735273995982307625376442606753688071083149620216746\", \"price\":\"0.3\", \"size\":\"45.06\", \"side\":\"SELL\", \"hash\":\"d42c623f9dc5723bac6aea7998a002badbdcc35c\", \"best_bid\":\"0.27\", \"best_ask\":\"0.28\"}], \"timestamp\":\"1785130652331\", \"event_type\":\"price_change\"}","received_at":"2026-07-27T05:37:32.289171Z","schema_version":"clob-market-ws.price_change.v1","sequence":null,"server_hash":null,"server_timestamp":"1785130652331","session_id":"502006c5cfcd437296561ea750c9ec8b","source":"clob_market_ws"},"received_at":"2026-07-27T05:37:32.289171Z","record_id":"8f72c0fc2e11c343e67ee3bf50abbd830cb3105b76c430b8cd0d74fc3c79f8fa","schema_fingerprint":"4aa3821a28b0b7c2400bc59aba4bcc0a76e971dadd19610d3ad38c768e124dc7","schema_version":"edge-lab-recorder.raw.v1","sequence":null,"source":"clob_market_ws"}
{"event_at":"2026-07-27T05:37:32.336000Z","event_fingerprint":"510c2f8cacabb545511ed0f0d20a7eb7185c030f28e81dde9412624917f394c0","payload":{"connection_id":"efc69d3132f1467b8e898a382b23ac0d","event_at":"2026-07-27T05:37:32.336000Z","event_type":"price_change","frame_hash":"4162e548e98e3bd7cfa7eaa60ec0fc00ad09a737dc8f28da06ed307ce2ac5c0a","frame_index":0,"kind":"data","monotonic_ns":232635529832375,"payload":{"event_type":"price_change","market":"0x3b40066b5cf3871a2f6237c5628bd8092a206aa998558ac5ec13c4483e31e160","price_changes":[{"asset_id":"14766054693214075530629349735273995982307625376442606753688071083149620216746","best_ask":"0.28","best_bid":"0.27","hash":"0d184e32d4ba7e6f637a06d08d948cd8dce5b8ce","price":"0.31","side":"SELL","size":"128"},{"asset_id":"110216635572655435074987471276357323571387854733835379371586402147734167783946","best_ask":"0.73","best_bid":"0.72","hash":"e4f1fcfe7d4178c5752f0db7ec490e6c0cf011b2","price":"0.69","side":"BUY","size":"128"}],"timestamp":"1785130652336"},"payload_hash":"6f5addb1ec6256892f5e00d8f543573900b1fbc2464f16cb000e28ef766220f5","raw_frame":"{\"market\":\"0x3b40066b5cf3871a2f6237c5628bd8092a206aa998558ac5ec13c4483e31e160\", \"price_changes\":[{\"asset_id\":\"14766054693214075530629349735273995982307625376442606753688071083149620216746\", \"price\":\"0.31\", \"size\":\"128\", \"side\":\"SELL\", \"hash\":\"0d184e32d4ba7e6f637a06d08d948cd8dce5b8ce\", \"best_bid\":\"0.27\", \"best_ask\":\"0.28\"}, {\"asset_id\":\"110216635572655435074987471276357323571387854733835379371586402147734167783946\", \"price\":\"0.69\", \"size\":\"128\", \"side\":\"BUY\", \"hash\":\"e4f1fcfe7d4178c5752f0db7ec490e6c0cf011b2\", \"best_bid\":\"0.72\", \"best_ask\":\"0.73\"}], \"timestamp\":\"1785130652336\", \"event_type\":\"price_change\"}","received_at":"2026-07-27T05:37:32.294763Z","schema_version":"clob-market-ws.price_change.v1","sequence":null,"server_hash":null,"server_timestamp":"1785130652336","session_id":"502006c5cfcd437296561ea750c9ec8b","source":"clob_market_ws"},"received_at":"2026-07-27T05:37:32.294763Z","record_id":"b283c4877ae673249fc450c269c004ce769e5fa0a252d0eba56fa664e68cc7c4","schema_fingerprint":"4aa3821a28b0b7c2400bc59aba4bcc0a76e971dadd19610d3ad38c768e124dc7","schema_version":"edge-lab-recorder.raw.v1","sequence":null,"source":"clob_market_ws"}
{"event_at":"2026-07-27T05:37:32.336000Z","event_fingerprint":"032fe05933794b6759690a2888a532f8f8fef4ad8261e644a011bcaa719647cb","payload":{"connection_id":"efc69d3132f1467b8e898a382b23ac0d","event_at":"2026-07-27T05:37:32.336000Z","event_type":"price_change","frame_hash":"655eb3eb89e92229947a7272847b4d6b48fcb0c7d2742ad9fd4e0866a70c88e2","frame_index":0,"kind":"data","monotonic_ns":232635532839083,"payload":{"event_type":"price_change","market":"0x3b40066b5cf3871a2f6237c5628bd8092a206aa998558ac5ec13c4483e31e160","price_changes":[{"asset_id":"14766054693214075530629349735273995982307625376442606753688071083149620216746","best_ask":"0.28","best_bid":"0.27","hash":"aed797cda49de0e7236dd322bfec52fcac0aabe3","price":"0.3","side":"SELL","size":"72"},{"asset_id":"110216635572655435074987471276357323571387854733835379371586402147734167783946","best_ask":"0.73","best_bid":"0.72","hash":"5fb19dfa4d0c398e2a194a69203e6304a529a32f","price":"0.7","side":"BUY","size":"72"}],"timestamp":"1785130652336"},"payload_hash":"e586044c987c031e64309a6db95179e5f5e12d52207c83f29bc0fadc33660c37","raw_frame":"{\"market\":\"0x3b40066b5cf3871a2f6237c5628bd8092a206aa998558ac5ec13c4483e31e160\", \"price_changes\":[{\"asset_id\":\"14766054693214075530629349735273995982307625376442606753688071083149620216746\", \"price\":\"0.3\", \"size\":\"72\", \"side\":\"SELL\", \"hash\":\"aed797cda49de0e7236dd322bfec52fcac0aabe3\", \"best_bid\":\"0.27\", \"best_ask\":\"0.28\"}, {\"asset_id\":\"110216635572655435074987471276357323571387854733835379371586402147734167783946\", \"price\":\"0.7\", \"size\":\"72\", \"side\":\"BUY\", \"hash\":\"5fb19dfa4d0c398e2a194a69203e6304a529a32f\", \"best_bid\":\"0.72\", \"best_ask\":\"0.73\"}], \"timestamp\":\"1785130652336\", \"event_type\":\"price_change\"}","received_at":"2026-07-27T05:37:32.297778Z","schema_version":"clob-market-ws.price_change.v1","sequence":null,"server_hash":null,"server_timestamp":"1785130652336","session_id":"502006c5cfcd437296561ea750c9ec8b","source":"clob_market_ws"},"received_at":"2026-07-27T05:37:32.297778Z","record_id":"c79878e6c9187d895cc5d9b5149548812d280cdda0d93cc0982ee6e3585dbaca","schema_fingerprint":"4aa3821a28b0b7c2400bc59aba4bcc0a76e971dadd19610d3ad38c768e124dc7","schema_version":"edge-lab-recorder.raw.v1","sequence":null,"source":"clob_market_ws"}
{"event_at":"2026-07-27T05:37:32.358000Z","event_fingerprint":"9b5cf34b9cec32d0a4b2d9015a6a679f0d31157ca2ff8195e464794ade234e04","payload":{"connection_id":"efc69d3132f1467b8e898a382b23ac0d","event_at":"2026-07-27T05:37:32.358000Z","event_type":"price_change","frame_hash":"282407ece979e144d95a41a2c2bc692574c667a4f2b37621be9fc2ea32791da2","frame_index":0,"kind":"data","monotonic_ns":232635556236083,"payload":{"event_type":"price_change","market":"0x3b40066b5cf3871a2f6237c5628bd8092a206aa998558ac5ec13c4483e31e160","price_changes":[{"asset_id":"110216635572655435074987471276357323571387854733835379371586402147734167783946","best_ask":"0.73","best_bid":"0.72","hash":"6280b46cdff6e6f2e7653d0335c41f5e1782e129","price":"0.02","side":"BUY","size":"683.1"},{"asset_id":"14766054693214075530629349735273995982307625376442606753688071083149620216746","best_ask":"0.28","best_bid":"0.27","hash":"71233f04f0f2d537e0f040476f79bee39767ec38","price":"0.98","side":"SELL","size":"683.1"}],"timestamp":"1785130652358"},"payload_hash":"de690a005e8dc24f58823cd1f304ce83d67a01110d46baaa1de482dabba29948","raw_frame":"{\"market\":\"0x3b40066b5cf3871a2f6237c5628bd8092a206aa998558ac5ec13c4483e31e160\", \"price_changes\":[{\"asset_id\":\"110216635572655435074987471276357323571387854733835379371586402147734167783946\", \"price\":\"0.02\", \"size\":\"683.1\", \"side\":\"BUY\", \"hash\":\"6280b46cdff6e6f2e7653d0335c41f5e1782e129\", \"best_bid\":\"0.72\", \"best_ask\":\"0.73\"}, {\"asset_id\":\"14766054693214075530629349735273995982307625376442606753688071083149620216746\", \"price\":\"0.98\", \"size\":\"683.1\", \"side\":\"SELL\", \"hash\":\"71233f04f0f2d537e0f040476f79bee39767ec38\", \"best_bid\":\"0.27\", \"best_ask\":\"0.28\"}], \"timestamp\":\"1785130652358\", \"event_type\":\"price_change\"}","received_at":"2026-07-27T05:37:32.321168Z","schema_version":"clob-market-ws.price_change.v1","sequence":null,"server_hash":null,"server_timestamp":"1785130652358","session_id":"502006c5cfcd437296561ea750c9ec8b","source":"clob_market_ws"},"received_at":"2026-07-27T05:37:32.321168Z","record_id":"575f720439ec591f52129f7e8847a8f8e501c4c7996beb42afc3e6eb1641913d","schema_fingerprint":"4aa3821a28b0b7c2400bc59aba4bcc0a76e971dadd19610d3ad38c768e124dc7","schema_version":"edge-lab-recorder.raw.v1","sequence":null,"source":"clob_market_ws"}
{"event_at":"2026-07-27T05:37:32.370000Z","event_fingerprint":"4059ce90ceea9c438adf1d5b0f451ccd22f55d052f73ebdce2cd7fd3b1d450e1","payload":{"connection_id":"efc69d3132f1467b8e898a382b23ac0d","event_at":"2026-07-27T05:37:32.370000Z","event_type":"price_change","frame_hash":"7017c1148acf5bf496204bb3a30c53debbf07b260b95bade03066a48e5c1f214","frame_index":0,"kind":"data","monotonic_ns":232635564039625,"payload":{"event_type":"price_change","market":"0x3b40066b5cf3871a2f6237c5628bd8092a206aa998558ac5ec13c4483e31e160","price_changes":[{"asset_id":"14766054693214075530629349735273995982307625376442606753688071083149620216746","best_ask":"0.28","best_bid":"0.27","hash":"f936afc7652eb9f98c1777ed45bd17571b3a282f","price":"0.15","side":"BUY","size":"265.2"},{"asset_id":"110216635572655435074987471276357323571387854733835379371586402147734167783946","best_ask":"0.73","best_bid":"0.72","hash":"8ccdebd05ad461e60ff6550cb5992076d4d412ea","price":"0.85","side":"SELL","size":"265.2"}],"timestamp":"1785130652370"},"payload_hash":"838a71770495d95e190ce3679bd2c3956eb6be988b928717f66fc012efadfcdb","raw_frame":"{\"market\":\"0x3b40066b5cf3871a2f6237c5628bd8092a206aa998558ac5ec13c4483e31e160\", \"price_changes\":[{\"asset_id\":\"14766054693214075530629349735273995982307625376442606753688071083149620216746\", \"price\":\"0.15\", \"size\":\"265.2\", \"side\":\"BUY\", \"hash\":\"f936afc7652eb9f98c1777ed45bd17571b3a282f\", \"best_bid\":\"0.27\", \"best_ask\":\"0.28\"}, {\"asset_id\":\"110216635572655435074987471276357323571387854733835379371586402147734167783946\", \"price\":\"0.85\", \"size\":\"265.2\", \"side\":\"SELL\", \"hash\":\"8ccdebd05ad461e60ff6550cb5992076d4d412ea\", \"best_bid\":\"0.72\", \"best_ask\":\"0.73\"}], \"timestamp\":\"1785130652370\", \"event_type\":\"price_change\"}","received_at":"2026-07-27T05:37:32.328973Z","schema_version":"clob-market-ws.price_change.v1","sequence":null,"server_hash":null,"server_timestamp":"1785130652370","session_id":"502006c5cfcd437296561ea750c9ec8b","source":"clob_market_ws"},"received_at":"2026-07-27T05:37:32.328973Z","record_id":"e964f5562ca6521de42cacd1d5a14ea673b9ac1932bfd917de5084cafca1aebf","schema_fingerprint":"4aa3821a28b0b7c2400bc59aba4bcc0a76e971dadd19610d3ad38c768e124dc7","schema_version":"edge-lab-recorder.raw.v1","sequence":null,"source":"clob_market_ws"}
{"event_at":"2026-07-27T05:37:32.374000Z","event_fingerprint":"b433ea7cf2f9c05f2bc6fd66004336150df9af1416ae3a4b6dc5ca4b1ad87b31","payload":{"connection_id":"efc69d3132f1467b8e898a382b23ac0d","event_at":"2026-07-27T05:37:32.374000Z","event_type":"price_change","frame_hash":"9e25a997e85ed19698f49b244ba0b96f4fdbff2b0fb2f004b8e6238e7281c369","frame_index":0,"kind":"data","monotonic_ns":232635569461416,"payload":{"event_type":"price_change","market":"0x3b40066b5cf3871a2f6237c5628bd8092a206aa998558ac5ec13c4483e31e160","price_changes":[{"asset_id":"110216635572655435074987471276357323571387854733835379371586402147734167783946","best_ask":"0.73","best_bid":"0.72","hash":"209ac886f306d649df70e5542773ce8f22bc3162","price":"0.43","side":"BUY","size":"55.2"},{"asset_id":"14766054693214075530629349735273995982307625376442606753688071083149620216746","best_ask":"0.28","best_bid":"0.27","hash":"dfec929f9260d13534814a82b56e18f0390ffd0e","price":"0.57","side":"SELL","size":"55.2"}],"timestamp":"1785130652374"},"payload_hash":"83ab4f744c0668c8e8d9bcb274e63e47e4dc3ec3745e52270e014e5d52b1b2e1","raw_frame":"{\"market\":\"0x3b40066b5cf3871a2f6237c5628bd8092a206aa998558ac5ec13c4483e31e160\", \"price_changes\":[{\"asset_id\":\"110216635572655435074987471276357323571387854733835379371586402147734167783946\", \"price\":\"0.43\", \"size\":\"55.2\", \"side\":\"BUY\", \"hash\":\"209ac886f306d649df70e5542773ce8f22bc3162\", \"best_bid\":\"0.72\", \"best_ask\":\"0.73\"}, {\"asset_id\":\"14766054693214075530629349735273995982307625376442606753688071083149620216746\", \"price\":\"0.57\", \"size\":\"55.2\", \"side\":\"SELL\", \"hash\":\"dfec929f9260d13534814a82b56e18f0390ffd0e\", \"best_bid\":\"0.27\", \"best_ask\":\"0.28\"}], \"timestamp\":\"1785130652374\", \"event_type\":\"price_change\"}","received_at":"2026-07-27T05:37:32.334394Z","schema_version":"clob-market-ws.price_change.v1","sequence":null,"server_hash":null,"server_timestamp":"1785130652374","session_id":"502006c5cfcd437296561ea750c9ec8b","source":"clob_market_ws"},"received_at":"2026-07-27T05:37:32.334394Z","record_id":"a4157399e5398b9f1bcc86b78c38c2a48c60e9acee2fa6830ee855aeb29e1ddd","schema_fingerprint":"4aa3821a28b0b7c2400bc59aba4bcc0a76e971dadd19610d3ad38c768e124dc7","schema_version":"edge-lab-recorder.raw.v1","sequence":null,"source":"clob_market_ws"}
{"event_at":"2026-07-27T05:37:32.413000Z","event_fingerprint":"66dc64a5e03a6baba161ddc02811f62b16c5778388cb290c11fca9d4df4393ea","payload":{"connection_id":"efc69d3132f1467b8e898a382b23ac0d","event_at":"2026-07-27T05:37:32.413000Z","event_type":"price_change","frame_hash":"d297b6e9feb00247bde3c66520181f7d66bcae2659bbc1137534c0d438d658da","frame_index":0,"kind":"data","monotonic_ns":232635611737583,"payload":{"event_type":"price_change","market":"0x3b40066b5cf3871a2f6237c5628bd8092a206aa998558ac5ec13c4483e31e160","price_changes":[{"asset_id":"14766054693214075530629349735273995982307625376442606753688071083149620216746","best_ask":"0.28","best_bid":"0.27","hash":"496a0691355610dbf54edd27b58ed35bac762356","price":"0.14","side":"BUY","size":"178.69"},{"asset_id":"110216635572655435074987471276357323571387854733835379371586402147734167783946","best_ask":"0.73","best_bid":"0.72","hash":"855a6945e2127c4df6193e6560802d40d99d2af7","price":"0.86","side":"SELL","size":"178.69"}],"timestamp":"1785130652413"},"payload_hash":"1538cd2dd4e927d3eee085f6759f46fa2fc01846a49eeb9747ef958d705e6110","raw_frame":"{\"market\":\"0x3b40066b5cf3871a2f6237c5628bd8092a206aa998558ac5ec13c4483e31e160\", \"price_changes\":[{\"asset_id\":\"14766054693214075530629349735273995982307625376442606753688071083149620216746\", \"price\":\"0.14\", \"size\":\"178.69\", \"side\":\"BUY\", \"hash\":\"496a0691355610dbf54edd27b58ed35bac762356\", \"best_bid\":\"0.27\", \"best_ask\":\"0.28\"}, {\"asset_id\":\"110216635572655435074987471276357323571387854733835379371586402147734167783946\", \"price\":\"0.86\", \"size\":\"178.69\", \"side\":\"SELL\", \"hash\":\"855a6945e2127c4df6193e6560802d40d99d2af7\", \"best_bid\":\"0.72\", \"best_ask\":\"0.73\"}], \"timestamp\":\"1785130652413\", \"event_type\":\"price_change\"}","received_at":"2026-07-27T05:37:32.376668Z","schema_version":"clob-market-ws.price_change.v1","sequence":null,"server_hash":null,"server_timestamp":"1785130652413","session_id":"502006c5cfcd437296561ea750c9ec8b","source":"clob_market_ws"},"received_at":"2026-07-27T05:37:32.376668Z","record_id":"5a6cee8c02f2e41b5f407efb545c502a2d25a3715a73c7e8fc14fbd824263843","schema_fingerprint":"4aa3821a28b0b7c2400bc59aba4bcc0a76e971dadd19610d3ad38c768e124dc7","schema_version":"edge-lab-recorder.raw.v1","sequence":null,"source":"clob_market_ws"}
{"event_at":"2026-07-27T05:37:32.416000Z","event_fingerprint":"00d5b76577633b33537d384a8600df74345919ee20021f48777b844373efbbed","payload":{"connection_id":"efc69d3132f1467b8e898a382b23ac0d","event_at":"2026-07-27T05:37:32.416000Z","event_type":"price_change","frame_hash":"9735744bc47637cc16ef888f90b58d2d895c2f4e2cf64ab57cedd7767db211c9","frame_index":0,"kind":"data","monotonic_ns":232635613403625,"payload":{"event_type":"price_change","market":"0x3b40066b5cf3871a2f6237c5628bd8092a206aa998558ac5ec13c4483e31e160","price_changes":[{"asset_id":"110216635572655435074987471276357323571387854733835379371586402147734167783946","best_ask":"0.73","best_bid":"0.72","hash":"1172edf875c1c389bcc6c0c92d0402d65ff93dd1","price":"0.44","side":"BUY","size":"55.47"},{"asset_id":"14766054693214075530629349735273995982307625376442606753688071083149620216746","best_ask":"0.28","best_bid":"0.27","hash":"6ae538ff7066a4ad940e7b01ff9b12ed56ddbfbe","price":"0.56","side":"SELL","size":"55.47"}],"timestamp":"1785130652416"},"payload_hash":"25d0bf621f589c66f59192b3128d8d1edb587dd41050fe6fa65c3a118cb8f51d","raw_frame":"{\"market\":\"0x3b40066b5cf3871a2f6237c5628bd8092a206aa998558ac5ec13c4483e31e160\", \"price_changes\":[{\"asset_id\":\"110216635572655435074987471276357323571387854733835379371586402147734167783946\", \"price\":\"0.44\", \"size\":\"55.47\", \"side\":\"BUY\", \"hash\":\"1172edf875c1c389bcc6c0c92d0402d65ff93dd1\", \"best_bid\":\"0.72\", \"best_ask\":\"0.73\"}, {\"asset_id\":\"14766054693214075530629349735273995982307625376442606753688071083149620216746\", \"price\":\"0.56\", \"size\":\"55.47\", \"side\":\"SELL\", \"hash\":\"6ae538ff7066a4ad940e7b01ff9b12ed56ddbfbe\", \"best_bid\":\"0.27\", \"best_ask\":\"0.28\"}], \"timestamp\":\"1785130652416\", \"event_type\":\"price_change\"}","received_at":"2026-07-27T05:37:32.378334Z","schema_version":"clob-market-ws.price_change.v1","sequence":null,"server_hash":null,"server_timestamp":"1785130652416","session_id":"502006c5cfcd437296561ea750c9ec8b","source":"clob_market_ws"},"received_at":"2026-07-27T05:37:32.378334Z","record_id":"64183815abfedefb9fd246e2ee3b78289d0a6609d84bdba6462c4aeb77c9218c","schema_fingerprint":"4aa3821a28b0b7c2400bc59aba4bcc0a76e971dadd19610d3ad38c768e124dc7","schema_version":"edge-lab-recorder.raw.v1","sequence":null,"source":"clob_market_ws"}
{"event_at":"2026-07-27T05:37:32.442000Z","event_fingerprint":"d2e13176e4c7688648c1222dfffe983fc1f032e619e4384d8429954f79bd2eb6","payload":{"connection_id":"efc69d3132f1467b8e898a382b23ac0d","event_at":"2026-07-27T05:37:32.442000Z","event_type":"price_change","frame_hash":"ea5f4a071328d5f5873638332fdb55b6bf2fad41758de28a4217150d5cc9a09a","frame_index":0,"kind":"data","monotonic_ns":232635637395958,"payload":{"event_type":"price_change","market":"0x3b40066b5cf3871a2f6237c5628bd8092a206aa998558ac5ec13c4483e31e160","price_changes":[{"asset_id":"110216635572655435074987471276357323571387854733835379371586402147734167783946","best_ask":"0.73","best_bid":"0.72","hash":"e33bc67034e5abb0142369c7d36b3bcd63633a71","price":"0.02","side":"BUY","size":"688.1"},{"asset_id":"14766054693214075530629349735273995982307625376442606753688071083149620216746","best_ask":"0.28","best_bid":"0.27","hash":"cbace31b55579a0a860bb6a6b6358a708d7c6fd5","price":"0.98","side":"SELL","size":"688.1"}],"timestamp":"1785130652442"},"payload_hash":"dc37a4cba1e7c5477b1e5c2bdeda1a135f64f9cb400f9fdd97efea9829f8a44c","raw_frame":"{\"market\":\"0x3b40066b5cf3871a2f6237c5628bd8092a206aa998558ac5ec13c4483e31e160\", \"price_changes\":[{\"asset_id\":\"110216635572655435074987471276357323571387854733835379371586402147734167783946\", \"price\":\"0.02\", \"size\":\"688.1\", \"side\":\"BUY\", \"hash\":\"e33bc67034e5abb0142369c7d36b3bcd63633a71\", \"best_bid\":\"0.72\", \"best_ask\":\"0.73\"}, {\"asset_id\":\"14766054693214075530629349735273995982307625376442606753688071083149620216746\", \"price\":\"0.98\", \"size\":\"688.1\", \"side\":\"SELL\", \"hash\":\"cbace31b55579a0a860bb6a6b6358a708d7c6fd5\", \"best_bid\":\"0.27\", \"best_ask\":\"0.28\"}], \"timestamp\":\"1785130652442\", \"event_type\":\"price_change\"}","received_at":"2026-07-27T05:37:32.402325Z","schema_version":"clob-market-ws.price_change.v1","sequence":null,"server_hash":null,"server_timestamp":"1785130652442","session_id":"502006c5cfcd437296561ea750c9ec8b","source":"clob_market_ws"},"received_at":"2026-07-27T05:37:32.402325Z","record_id":"a3d1f42027f7159dad8bbfe516d3ba4498c780a6deb97fb29a6ed3ce159beb64","schema_fingerprint":"4aa3821a28b0b7c2400bc59aba4bcc0a76e971dadd19610d3ad38c768e124dc7","schema_version":"edge-lab-recorder.raw.v1","sequence":null,"source":"clob_market_ws"}
{"event_at":"2026-07-27T05:37:32.452000Z","event_fingerprint":"9f4b837fd7f57689a070cb24a48506d69d02d1177fbf08d88ca8b4a61f3586c7","payload":{"connection_id":"efc69d3132f1467b8e898a382b23ac0d","event_at":"2026-07-27T05:37:32.452000Z","event_type":"price_change","frame_hash":"4aa6eefbc746c1762012454761b9a2879badd71d511041fe980181e317e6763b","frame_index":0,"kind":"data","monotonic_ns":232635646914916,"payload":{"event_type":"price_change","market":"0x3b40066b5cf3871a2f6237c5628bd8092a206aa998558ac5ec13c4483e31e160","price_changes":[{"asset_id":"110216635572655435074987471276357323571387854733835379371586402147734167783946","best_ask":"0.73","best_bid":"0.72","hash":"f3f288c044b098959eff4077e5d8207e6a37d5a3","price":"0.01","side":"BUY","size":"5617.45"},{"asset_id":"14766054693214075530629349735273995982307625376442606753688071083149620216746","best_ask":"0.28","best_bid":"0.27","hash":"0b9332e10e1ea67845e937e78686b24d3fff1cc7","price":"0.99","side":"SELL","size":"5617.45"}],"timestamp":"1785130652452"},"payload_hash":"795099dbda0fbe32b0fd95dd277c96b51bd2d74363aca38f34d25baa70780c75","raw_frame":"{\"market\":\"0x3b40066b5cf3871a2f6237c5628bd8092a206aa998558ac5ec13c4483e31e160\", \"price_changes\":[{\"asset_id\":\"110216635572655435074987471276357323571387854733835379371586402147734167783946\", \"price\":\"0.01\", \"size\":\"5617.45\", \"side\":\"BUY\", \"hash\":\"f3f288c044b098959eff4077e5d8207e6a37d5a3\", \"best_bid\":\"0.72\", \"best_ask\":\"0.73\"}, {\"asset_id\":\"14766054693214075530629349735273995982307625376442606753688071083149620216746\", \"price\":\"0.99\", \"size\":\"5617.45\", \"side\":\"SELL\", \"hash\":\"0b9332e10e1ea67845e937e78686b24d3fff1cc7\", \"best_bid\":\"0.27\", \"best_ask\":\"0.28\"}], \"timestamp\":\"1785130652452\", \"event_type\":\"price_change\"}","received_at":"2026-07-27T05:37:32.411847Z","schema_version":"clob-market-ws.price_change.v1","sequence":null,"server_hash":null,"server_timestamp":"1785130652452","session_id":"502006c5cfcd437296561ea750c9ec8b","source":"clob_market_ws"},"received_at":"2026-07-27T05:37:32.411847Z","record_id":"4388bd95270dd6ed8f68b605550ef6900384c78e6b3385975278ac224c57f121","schema_fingerprint":"4aa3821a28b0b7c2400bc59aba4bcc0a76e971dadd19610d3ad38c768e124dc7","schema_version":"edge-lab-recorder.raw.v1","sequence":null,"source":"clob_market_ws"}
{"event_at":"2026-07-27T05:37:32.459000Z","event_fingerprint":"32d5036392b92a40eec0df1f5b288feb3e284fa14e205e3d6de1c9017ca614b8","payload":{"connection_id":"efc69d3132f1467b8e898a382b23ac0d","event_at":"2026-07-27T05:37:32.459000Z","event_type":"price_change","frame_hash":"9121519ed13b0a304213624065d94d114f618320ba37c317b020225292faef5a","frame_index":0,"kind":"data","monotonic_ns":232635653025791,"payload":{"event_type":"price_change","market":"0x3b40066b5cf3871a2f6237c5628bd8092a206aa998558ac5ec13c4483e31e160","price_changes":[{"asset_id":"110216635572655435074987471276357323571387854733835379371586402147734167783946","best_ask":"0.73","best_bid":"0.72","hash":"8d1005c1dd1f4e557a77069950fe7eaa060f875e","price":"0.91","side":"SELL","size":"584.6"},{"asset_id":"14766054693214075530629349735273995982307625376442606753688071083149620216746","best_ask":"0.28","best_bid":"0.27","hash":"87d74aad27a87d3f68e4606d06559ffbbf709eaf","price":"0.09","side":"BUY","size":"584.6"}],"timestamp":"1785130652459"},"payload_hash":"963609e552b36798b94dfd8870a5014ba85a1ba2bc389eeb3bed40b421083657","raw_frame":"{\"market\":\"0x3b40066b5cf3871a2f6237c5628bd8092a206aa998558ac5ec13c4483e31e160\", \"price_changes\":[{\"asset_id\":\"110216635572655435074987471276357323571387854733835379371586402147734167783946\", \"price\":\"0.91\", \"size\":\"584.6\", \"side\":\"SELL\", \"hash\":\"8d1005c1dd1f4e557a77069950fe7eaa060f875e\", \"best_bid\":\"0.72\", \"best_ask\":\"0.73\"}, {\"asset_id\":\"14766054693214075530629349735273995982307625376442606753688071083149620216746\", \"price\":\"0.09\", \"size\":\"584.6\", \"side\":\"BUY\", \"hash\":\"87d74aad27a87d3f68e4606d06559ffbbf709eaf\", \"best_bid\":\"0.27\", \"best_ask\":\"0.28\"}], \"timestamp\":\"1785130652459\", \"event_type\":\"price_change\"}","received_at":"2026-07-27T05:37:32.417958Z","schema_version":"clob-market-ws.price_change.v1","sequence":null,"server_hash":null,"server_timestamp":"1785130652459","session_id":"502006c5cfcd437296561ea750c9ec8b","source":"clob_market_ws"},"received_at":"2026-07-27T05:37:32.417958Z","record_id":"8de9a34826fee547afc53db1290a712b7e276173f26b11f4f9ee8f3f4aebd897","schema_fingerprint":"4aa3821a28b0b7c2400bc59aba4bcc0a76e971dadd19610d3ad38c768e124dc7","schema_version":"edge-lab-recorder.raw.v1","sequence":null,"source":"clob_market_ws"}
{"event_at":"2026-07-27T05:37:32.473000Z","event_fingerprint":"f13a50ef9eec9e21f3cab22ef7435e101aa0f055171bb0179baf2f12cba4e066","payload":{"connection_id":"efc69d3132f1467b8e898a382b23ac0d","event_at":"2026-07-27T05:37:32.473000Z","event_type":"price_change","frame_hash":"5b3ecac5bb20da1bd8f90d1410492d63f7e03778f8a43c8b154e4ab630bd1e27","frame_index":0,"kind":"data","monotonic_ns":232635668247500,"payload":{"event_type":"price_change","market":"0x3b40066b5cf3871a2f6237c5628bd8092a206aa998558ac5ec13c4483e31e160","price_changes":[{"asset_id":"110216635572655435074987471276357323571387854733835379371586402147734167783946","best_ask":"0.73","best_bid":"0.72","hash":"4303c9bbfd31a50958a1fe388a048e24422c2cb6","price":"0.01","side":"BUY","size":"5612.45"},{"asset_id":"14766054693214075530629349735273995982307625376442606753688071083149620216746","best_ask":"0.28","best_bid":"0.27","hash":"30428e1384a9509cf174c5c888429c34048f2209","price":"0.99","side":"SELL","size":"5612.45"}],"timestamp":"1785130652473"},"payload_hash":"af6dff94b50afadeecec3dcf649f80afbe69bcee8a3ff1e708fab41f9ba2f65f","raw_frame":"{\"market\":\"0x3b40066b5cf3871a2f6237c5628bd8092a206aa998558ac5ec13c4483e31e160\", \"price_changes\":[{\"asset_id\":\"110216635572655435074987471276357323571387854733835379371586402147734167783946\", \"price\":\"0.01\", \"size\":\"5612.45\", \"side\":\"BUY\", \"hash\":\"4303c9bbfd31a50958a1fe388a048e24422c2cb6\", \"best_bid\":\"0.72\", \"best_ask\":\"0.73\"}, {\"asset_id\":\"14766054693214075530629349735273995982307625376442606753688071083149620216746\", \"price\":\"0.99\", \"size\":\"5612.45\", \"side\":\"SELL\", \"hash\":\"30428e1384a9509cf174c5c888429c34048f2209\", \"best_bid\":\"0.27\", \"best_ask\":\"0.28\"}], \"timestamp\":\"1785130652473\", \"event_type\":\"price_change\"}","received_at":"2026-07-27T05:37:32.433179Z","schema_version":"clob-market-ws.price_change.v1","sequence":null,"server_hash":null,"server_timestamp":"1785130652473","session_id":"502006c5cfcd437296561ea750c9ec8b","source":"clob_market_ws"},"received_at":"2026-07-27T05:37:32.433179Z","record_id":"6bb7c9c7f2c1a593f9e6714724f3dbddf73a8515cb1b182b84ded3843e3174ed","schema_fingerprint":"4aa3821a28b0b7c2400bc59aba4bcc0a76e971dadd19610d3ad38c768e124dc7","schema_version":"edge-lab-recorder.raw.v1","sequence":null,"source":"clob_market_ws"}
{"event_at":"2026-07-27T05:37:32.477000Z","event_fingerprint":"b33852a46ad78f535d4cd513f4a53cb502bf7edb8c78d83141a8f0d2f6ff3488","payload":{"connection_id":"efc69d3132f1467b8e898a382b23ac0d","event_at":"2026-07-27T05:37:32.477000Z","event_type":"price_change","frame_hash":"15b4003f3140b5bb1bb8f2aac64991d0001cc345725a9c3dd7cc063017138453","frame_index":0,"kind":"data","monotonic_ns":232635672036791,"payload":{"event_type":"price_change","market":"0x3b40066b5cf3871a2f6237c5628bd8092a206aa998558ac5ec13c4483e31e160","price_changes":[{"asset_id":"14766054693214075530629349735273995982307625376442606753688071083149620216746","best_ask":"0.28","best_bid":"0.27","hash":"15d27c33c2afca48c2c983fa729d70c6eb5cf42c","price":"0.3","side":"SELL","size":"45.06"},{"asset_id":"110216635572655435074987471276357323571387854733835379371586402147734167783946","best_ask":"0.73","best_bid":"0.72","hash":"377671a09d5547e815082fbb128d92ee739cc188","price":"0.7","side":"BUY","size":"45.06"}],"timestamp":"1785130652477"},"payload_hash":"33046ac618938a08aa2f8e6a0367d808b14c17aee2ecf39ec45175d41def6243","raw_frame":"{\"market\":\"0x3b40066b5cf3871a2f6237c5628bd8092a206aa998558ac5ec13c4483e31e160\", \"price_changes\":[{\"asset_id\":\"14766054693214075530629349735273995982307625376442606753688071083149620216746\", \"price\":\"0.3\", \"size\":\"45.06\", \"side\":\"SELL\", \"hash\":\"15d27c33c2afca48c2c983fa729d70c6eb5cf42c\", \"best_bid\":\"0.27\", \"best_ask\":\"0.28\"}, {\"asset_id\":\"110216635572655435074987471276357323571387854733835379371586402147734167783946\", \"price\":\"0.7\", \"size\":\"45.06\", \"side\":\"BUY\", \"hash\":\"377671a09d5547e815082fbb128d92ee739cc188\", \"best_bid\":\"0.72\", \"best_ask\":\"0.73\"}], \"timestamp\":\"1785130652477\", \"event_type\":\"price_change\"}","received_at":"2026-07-27T05:37:32.436970Z","schema_version":"clob-market-ws.price_change.v1","sequence":null,"server_hash":null,"server_timestamp":"1785130652477","session_id":"502006c5cfcd437296561ea750c9ec8b","source":"clob_market_ws"},"received_at":"2026-07-27T05:37:32.436970Z","record_id":"e8e80f32a5678c84d24c0e4286259e1772c87dcd78f52cf8d15812e93d181fec","schema_fingerprint":"4aa3821a28b0b7c2400bc59aba4bcc0a76e971dadd19610d3ad38c768e124dc7","schema_version":"edge-lab-recorder.raw.v1","sequence":null,"source":"clob_market_ws"}
{"event_at":"2026-07-27T05:37:32.482000Z","event_fingerprint":"81916ed27405dcff4ae5f760585ab1e308952ce172c54fa6529b54893c285de7","payload":{"connection_id":"efc69d3132f1467b8e898a382b23ac0d","event_at":"2026-07-27T05:37:32.482000Z","event_type":"price_change","frame_hash":"eec53c235b9cf6fad18a5c095cd49afd3b5323498e43268b231a6fb2f25fbfad","frame_index":0,"kind":"data","monotonic_ns":232635675915500,"payload":{"event_type":"price_change","market":"0x3b40066b5cf3871a2f6237c5628bd8092a206aa998558ac5ec13c4483e31e160","price_changes":[{"asset_id":"14766054693214075530629349735273995982307625376442606753688071083149620216746","best_ask":"0.28","best_bid":"0.27","hash":"761071956175e472c29ce33d192cc27313d31cfb","price":"0.31","side":"SELL","size":"121"},{"asset_id":"110216635572655435074987471276357323571387854733835379371586402147734167783946","best_ask":"0.73","best_bid":"0.72","hash":"43f2c54756ef1235b0f4a48233d6ca192b66c80d","price":"0.69","side":"BUY","size":"121"}],"timestamp":"1785130652482"},"payload_hash":"4e9716162e769a0b6595d5566eb93ed891d9dc32f8c48f3c4dd0b3b560050f19","raw_frame":"{\"market\":\"0x3b40066b5cf3871a2f6237c5628bd8092a206aa998558ac5ec13c4483e31e160\", \"price_changes\":[{\"asset_id\":\"14766054693214075530629349735273995982307625376442606753688071083149620216746\", \"price\":\"0.31\", \"size\":\"121\", \"side\":\"SELL\", \"hash\":\"761071956175e472c29ce33d192cc27313d31cfb\", \"best_bid\":\"0.27\", \"best_ask\":\"0.28\"}, {\"asset_id\":\"110216635572655435074987471276357323571387854733835379371586402147734167783946\", \"price\":\"0.69\", \"size\":\"121\", \"side\":\"BUY\", \"hash\":\"43f2c54756ef1235b0f4a48233d6ca192b66c80d\", \"best_bid\":\"0.72\", \"best_ask\":\"0.73\"}], \"timestamp\":\"1785130652482\", \"event_type\":\"price_change\"}","received_at":"2026-07-27T05:37:32.440848Z","schema_version":"clob-market-ws.price_change.v1","sequence":null,"server_hash":null,"server_timestamp":"1785130652482","session_id":"502006c5cfcd437296561ea750c9ec8b","source":"clob_market_ws"},"received_at":"2026-07-27T05:37:32.440848Z","record_id":"a3d9caad05068abdf17a72e8b1567b477c1c74687901f6a7c6bbbba06865e650","schema_fingerprint":"4aa3821a28b0b7c2400bc59aba4bcc0a76e971dadd19610d3ad38c768e124dc7","schema_version":"edge-lab-recorder.raw.v1","sequence":null,"source":"clob_market_ws"}
{"event_at":"2026-07-27T05:37:32.482000Z","event_fingerprint":"47a21ddb4d6d3d0cc4375e6baccbfe75e5036cf6a843033c3fb8ef81e2282cc9","payload":{"connection_id":"efc69d3132f1467b8e898a382b23ac0d","event_at":"2026-07-27T05:37:32.482000Z","event_type":"price_change","frame_hash":"66347dbc77c0b8c9710e7179ddd44391b5c100e9a89f7756987d7446efce556b","frame_index":0,"kind":"data","monotonic_ns":232635678132208,"payload":{"event_type":"price_change","market":"0x3b40066b5cf3871a2f6237c5628bd8092a206aa998558ac5ec13c4483e31e160","price_changes":[{"asset_id":"110216635572655435074987471276357323571387854733835379371586402147734167783946","best_ask":"0.73","best_bid":"0.72","hash":"94c24c14ef3b3b15e160b84426d6963e6463b161","price":"0.7","side":"BUY","size":"72"},{"asset_id":"14766054693214075530629349735273995982307625376442606753688071083149620216746","best_ask":"0.28","best_bid":"0.27","hash":"33f0bdcb6c30b6012510182a548c215934a90daa","price":"0.3","side":"SELL","size":"72"}],"timestamp":"1785130652482"},"payload_hash":"6844818315a1e3b4c821b566bb31135d23b8e87e23e1ecd45c96386e153401a4","raw_frame":"{\"market\":\"0x3b40066b5cf3871a2f6237c5628bd8092a206aa998558ac5ec13c4483e31e160\", \"price_changes\":[{\"asset_id\":\"110216635572655435074987471276357323571387854733835379371586402147734167783946\", \"price\":\"0.7\", \"size\":\"72\", \"side\":\"BUY\", \"hash\":\"94c24c14ef3b3b15e160b84426d6963e6463b161\", \"best_bid\":\"0.72\", \"best_ask\":\"0.73\"}, {\"asset_id\":\"14766054693214075530629349735273995982307625376442606753688071083149620216746\", \"price\":\"0.3\", \"size\":\"72\", \"side\":\"SELL\", \"hash\":\"33f0bdcb6c30b6012510182a548c215934a90daa\", \"best_bid\":\"0.27\", \"best_ask\":\"0.28\"}], \"timestamp\":\"1785130652482\", \"event_type\":\"price_change\"}","received_at":"2026-07-27T05:37:32.443066Z","schema_version":"clob-market-ws.price_change.v1","sequence":null,"server_hash":null,"server_timestamp":"1785130652482","session_id":"502006c5cfcd437296561ea750c9ec8b","source":"clob_market_ws"},"received_at":"2026-07-27T05:37:32.443066Z","record_id":"daf11902fdd115153d77ebb8b7102621f2f92ef0a81ae2e311e11ac2e76f925f","schema_fingerprint":"4aa3821a28b0b7c2400bc59aba4bcc0a76e971dadd19610d3ad38c768e124dc7","schema_version":"edge-lab-recorder.raw.v1","sequence":null,"source":"clob_market_ws"}
{"event_at":"2026-07-27T05:37:32.499000Z","event_fingerprint":"94e05843e618290128555fb2174bafffcb91ca71782830d14079aa843e3916e2","payload":{"connection_id":"efc69d3132f1467b8e898a382b23ac0d","event_at":"2026-07-27T05:37:32.499000Z","event_type":"price_change","frame_hash":"4b24e3741b6cdc6abb67b9f64322c47e9f2dfdbbff118f405b07fb7e14e850c3","frame_index":0,"kind":"data","monotonic_ns":232635695054583,"payload":{"event_type":"price_change","market":"0x3b40066b5cf3871a2f6237c5628bd8092a206aa998558ac5ec13c4483e31e160","price_changes":[{"asset_id":"110216635572655435074987471276357323571387854733835379371586402147734167783946","best_ask":"0.73","best_bid":"0.72","hash":"1f90b06fe16d000e769ea25ff95ded4430819b88","price":"0.01","side":"BUY","size":"5617.45"},{"asset_id":"14766054693214075530629349735273995982307625376442606753688071083149620216746","best_ask":"0.28","best_bid":"0.27","hash":"bb782f32a37fbb69b55b368636a12ce751c94a3b","price":"0.99","side":"SELL","size":"5617.45"}],"timestamp":"1785130652499"},"payload_hash":"3c7c1cc3b1accfa583ae85c3034e1f30648245621760df50f82761af70d3c28d","raw_frame":"{\"market\":\"0x3b40066b5cf3871a2f6237c5628bd8092a206aa998558ac5ec13c4483e31e160\", \"price_changes\":[{\"asset_id\":\"110216635572655435074987471276357323571387854733835379371586402147734167783946\", \"price\":\"0.01\", \"size\":\"5617.45\", \"side\":\"BUY\", \"hash\":\"1f90b06fe16d000e769ea25ff95ded4430819b88\", \"best_bid\":\"0.72\", \"best_ask\":\"0.73\"}, {\"asset_id\":\"14766054693214075530629349735273995982307625376442606753688071083149620216746\", \"price\":\"0.99\", \"size\":\"5617.45\", \"side\":\"SELL\", \"hash\":\"bb782f32a37fbb69b55b368636a12ce751c94a3b\", \"best_bid\":\"0.27\", \"best_ask\":\"0.28\"}], \"timestamp\":\"1785130652499\", \"event_type\":\"price_change\"}","received_at":"2026-07-27T05:37:32.459988Z","schema_version":"clob-market-ws.price_change.v1","sequence":null,"server_hash":null,"server_timestamp":"1785130652499","session_id":"502006c5cfcd437296561ea750c9ec8b","source":"clob_market_ws"},"received_at":"2026-07-27T05:37:32.459988Z","record_id":"70ecd1daf4741f519fc1529d9843ab699114d14a460d7a7938a4553539e1b342","schema_fingerprint":"4aa3821a28b0b7c2400bc59aba4bcc0a76e971dadd19610d3ad38c768e124dc7","schema_version":"edge-lab-recorder.raw.v1","sequence":null,"source":"clob_market_ws"}
{"event_at":"2026-07-27T05:37:32.503000Z","event_fingerprint":"a95fc501d03995ba7d0c87babbdbe3922bc79f7d2701eb0a8d820a4d8ee191cd","payload":{"connection_id":"efc69d3132f1467b8e898a382b23ac0d","event_at":"2026-07-27T05:37:32.503000Z","event_type":"price_change","frame_hash":"0a5957ac101ba70d66237b44105fd07e513e928ea44d751045656158235f92fa","frame_index":0,"kind":"data","monotonic_ns":232635698029708,"payload":{"event_type":"price_change","market":"0x3b40066b5cf3871a2f6237c5628bd8092a206aa998558ac5ec13c4483e31e160","price_changes":[{"asset_id":"110216635572655435074987471276357323571387854733835379371586402147734167783946","best_ask":"0.73","best_bid":"0.72","hash":"c90a5e081370b28942dcf7c2d3022baf6952a5bf","price":"0.02","side":"BUY","size":"683.1"},{"asset_id":"14766054693214075530629349735273995982307625376442606753688071083149620216746","best_ask":"0.28","best_bid":"0.27","hash":"cdbf2990e057a3db07d43af2519045b7c1434d58","price":"0.98","side":"SELL","size":"683.1"}],"timestamp":"1785130652503"},"payload_hash":"a09333de1590d5ef0115e810970f81ad24fe7ba7d6f3ccd66656c452bd259e52","raw_frame":"{\"market\":\"0x3b40066b5cf3871a2f6237c5628bd8092a206aa998558ac5ec13c4483e31e160\", \"price_changes\":[{\"asset_id\":\"110216635572655435074987471276357323571387854733835379371586402147734167783946\", \"price\":\"0.02\", \"size\":\"683.1\", \"side\":\"BUY\", \"hash\":\"c90a5e081370b28942dcf7c2d3022baf6952a5bf\", \"best_bid\":\"0.72\", \"best_ask\":\"0.73\"}, {\"asset_id\":\"14766054693214075530629349735273995982307625376442606753688071083149620216746\", \"price\":\"0.98\", \"size\":\"683.1\", \"side\":\"SELL\", \"hash\":\"cdbf2990e057a3db07d43af2519045b7c1434d58\", \"best_bid\":\"0.27\", \"best_ask\":\"0.28\"}], \"timestamp\":\"1785130652503\", \"event_type\":\"price_change\"}","received_at":"2026-07-27T05:37:32.462962Z","schema_version":"clob-market-ws.price_change.v1","sequence":null,"server_hash":null,"server_timestamp":"1785130652503","session_id":"502006c5cfcd437296561ea750c9ec8b","source":"clob_market_ws"},"received_at":"2026-07-27T05:37:32.462962Z","record_id":"768aa2e517cb49a721f01e17287c662b2ea6ff44a9c0056e6a1309168cc0533c","schema_fingerprint":"4aa3821a28b0b7c2400bc59aba4bcc0a76e971dadd19610d3ad38c768e124dc7","schema_version":"edge-lab-recorder.raw.v1","sequence":null,"source":"clob_market_ws"}
{"event_at":"2026-07-27T05:37:32.530000Z","event_fingerprint":"22b892b5f972ee1e2e5f88ac308092dd1faca03a0d5db60b4e94409caed33489","payload":{"connection_id":"efc69d3132f1467b8e898a382b23ac0d","event_at":"2026-07-27T05:37:32.530000Z","event_type":"price_change","frame_hash":"96261a42a012a2f62f18c5e2d0c5c860362785d6b27891243314a5b4b62a4b0a","frame_index":0,"kind":"data","monotonic_ns":232635726244291,"payload":{"event_type":"price_change","market":"0x3b40066b5cf3871a2f6237c5628bd8092a206aa998558ac5ec13c4483e31e160","price_changes":[{"asset_id":"110216635572655435074987471276357323571387854733835379371586402147734167783946","best_ask":"0.73","best_bid":"0.72","hash":"dbd83f8dd677ac2990da06a259db5aa999f2a1f6","price":"0.01","side":"BUY","size":"5612.45"},{"asset_id":"14766054693214075530629349735273995982307625376442606753688071083149620216746","best_ask":"0.28","best_bid":"0.27","hash":"38b41c4182065c5d4fbd333670f9a375c5214ffa","price":"0.99","side":"SELL","size":"5612.45"}],"timestamp":"1785130652530"},"payload_hash":"c425a9b9f15d3ec54da9e221bfd2f0be3706ee6ddd2de1d30ff0ca2fcab13a7a","raw_frame":"{\"market\":\"0x3b40066b5cf3871a2f6237c5628bd8092a206aa998558ac5ec13c4483e31e160\", \"price_changes\":[{\"asset_id\":\"110216635572655435074987471276357323571387854733835379371586402147734167783946\", \"price\":\"0.01\", \"size\":\"5612.45\", \"side\":\"BUY\", \"hash\":\"dbd83f8dd677ac2990da06a259db5aa999f2a1f6\", \"best_bid\":\"0.72\", \"best_ask\":\"0.73\"}, {\"asset_id\":\"14766054693214075530629349735273995982307625376442606753688071083149620216746\", \"price\":\"0.99\", \"size\":\"5612.45\", \"side\":\"SELL\", \"hash\":\"38b41c4182065c5d4fbd333670f9a375c5214ffa\", \"best_bid\":\"0.27\", \"best_ask\":\"0.28\"}], \"timestamp\":\"1785130652530\", \"event_type\":\"price_change\"}","received_at":"2026-07-27T05:37:32.491178Z","schema_version":"clob-market-ws.price_change.v1","sequence":null,"server_hash":null,"server_timestamp":"1785130652530","session_id":"502006c5cfcd437296561ea750c9ec8b","source":"clob_market_ws"},"received_at":"2026-07-27T05:37:32.491178Z","record_id":"7d56d998b1008522122591e49e54406433c13b5a0da5b2e777f0b77656bf0e25","schema_fingerprint":"4aa3821a28b0b7c2400bc59aba4bcc0a76e971dadd19610d3ad38c768e124dc7","schema_version":"edge-lab-recorder.raw.v1","sequence":null,"source":"clob_market_ws"}
{"event_at":"2026-07-27T05:37:32.579000Z","event_fingerprint":"da6b0da13021b514c2af7c3f17f40eced7f39cf47c34510813c88e8c4796c067","payload":{"connection_id":"efc69d3132f1467b8e898a382b23ac0d","event_at":"2026-07-27T05:37:32.579000Z","event_type":"price_change","frame_hash":"56208ef8c14d66d72765955fe0127d2d20e3abff6241c93896d7868218457c14","frame_index":0,"kind":"data","monotonic_ns":232635776032166,"payload":{"event_type":"price_change","market":"0x3b40066b5cf3871a2f6237c5628bd8092a206aa998558ac5ec13c4483e31e160","price_changes":[{"asset_id":"110216635572655435074987471276357323571387854733835379371586402147734167783946","best_ask":"0.73","best_bid":"0.72","hash":"ca825d32fc04fbe1ee5e68b4b759e9a8c2633b37","price":"0.7","side":"BUY","size":"45.06"},{"asset_id":"14766054693214075530629349735273995982307625376442606753688071083149620216746","best_ask":"0.28","best_bid":"0.27","hash":"e14e832c4b08d6ab0922905194718c29487f3487","price":"0.3","side":"SELL","size":"45.06"}],"timestamp":"1785130652579"},"payload_hash":"f096457f69444ae2c45a6050d7808c4d4bc57f5a1c0d2d99fe079489170ae741","raw_frame":"{\"market\":\"0x3b40066b5cf3871a2f6237c5628bd8092a206aa998558ac5ec13c4483e31e160\", \"price_changes\":[{\"asset_id\":\"110216635572655435074987471276357323571387854733835379371586402147734167783946\", \"price\":\"0.7\", \"size\":\"45.06\", \"side\":\"BUY\", \"hash\":\"ca825d32fc04fbe1ee5e68b4b759e9a8c2633b37\", \"best_bid\":\"0.72\", \"best_ask\":\"0.73\"}, {\"asset_id\":\"14766054693214075530629349735273995982307625376442606753688071083149620216746\", \"price\":\"0.3\", \"size\":\"45.06\", \"side\":\"SELL\", \"hash\":\"e14e832c4b08d6ab0922905194718c29487f3487\", \"best_bid\":\"0.27\", \"best_ask\":\"0.28\"}], \"timestamp\":\"1785130652579\", \"event_type\":\"price_change\"}","received_at":"2026-07-27T05:37:32.540964Z","schema_version":"clob-market-ws.price_change.v1","sequence":null,"server_hash":null,"server_timestamp":"1785130652579","session_id":"502006c5cfcd437296561ea750c9ec8b","source":"clob_market_ws"},"received_at":"2026-07-27T05:37:32.540964Z","record_id":"71ff1622952219466b5df411ae7db34b3b6212dcb2fe71b3a453a73e54a029c1","schema_fingerprint":"4aa3821a28b0b7c2400bc59aba4bcc0a76e971dadd19610d3ad38c768e124dc7","schema_version":"edge-lab-recorder.raw.v1","sequence":null,"source":"clob_market_ws"}
{"event_at":"2026-07-27T05:37:32.583000Z","event_fingerprint":"89b8044a0172b618fb782444825e45ef329cc68306cc251559e4437ce62f9762","payload":{"connection_id":"efc69d3132f1467b8e898a382b23ac0d","event_at":"2026-07-27T05:37:32.583000Z","event_type":"price_change","frame_hash":"88cefd7265383224099952d6a036bb767625fb81fc522e899aaaa4dfc4d6bf6f","frame_index":0,"kind":"data","monotonic_ns":232635780719375,"payload":{"event_type":"price_change","market":"0x3b40066b5cf3871a2f6237c5628bd8092a206aa998558ac5ec13c4483e31e160","price_changes":[{"asset_id":"14766054693214075530629349735273995982307625376442606753688071083149620216746","best_ask":"0.28","best_bid":"0.27","hash":"f1f16b333c1fbd5f57a8edafe6feb50c5962a139","price":"0.31","side":"SELL","size":"128"},{"asset_id":"110216635572655435074987471276357323571387854733835379371586402147734167783946","best_ask":"0.73","best_bid":"0.72","hash":"da460897d3ac43d1e92e1dc98ea1f409f6857b34","price":"0.69","side":"BUY","size":"128"}],"timestamp":"1785130652583"},"payload_hash":"7d90dcad187198db2d63c00af6c723fdb314ac14a98ca549d8a8d0b6bf96f1d8","raw_frame":"{\"market\":\"0x3b40066b5cf3871a2f6237c5628bd8092a206aa998558ac5ec13c4483e31e160\", \"price_changes\":[{\"asset_id\":\"14766054693214075530629349735273995982307625376442606753688071083149620216746\", \"price\":\"0.31\", \"size\":\"128\", \"side\":\"SELL\", \"hash\":\"f1f16b333c1fbd5f57a8edafe6feb50c5962a139\", \"best_bid\":\"0.27\", \"best_ask\":\"0.28\"}, {\"asset_id\":\"110216635572655435074987471276357323571387854733835379371586402147734167783946\", \"price\":\"0.69\", \"size\":\"128\", \"side\":\"BUY\", \"hash\":\"da460897d3ac43d1e92e1dc98ea1f409f6857b34\", \"best_bid\":\"0.72\", \"best_ask\":\"0.73\"}], \"timestamp\":\"1785130652583\", \"event_type\":\"price_change\"}","received_at":"2026-07-27T05:37:32.545648Z","schema_version":"clob-market-ws.price_change.v1","sequence":null,"server_hash":null,"server_timestamp":"1785130652583","session_id":"502006c5cfcd437296561ea750c9ec8b","source":"clob_market_ws"},"received_at":"2026-07-27T05:37:32.545648Z","record_id":"aef9699b458cfa8d6dc03b626fa3513936211014e3d964adc40d166443441349","schema_fingerprint":"4aa3821a28b0b7c2400bc59aba4bcc0a76e971dadd19610d3ad38c768e124dc7","schema_version":"edge-lab-recorder.raw.v1","sequence":null,"source":"clob_market_ws"}
{"event_at":"2026-07-27T05:37:32.585000Z","event_fingerprint":"63b628dd5b0b976c1f9b5b6190f68535eb0932f41fedbb9c819d89626c23a500","payload":{"connection_id":"efc69d3132f1467b8e898a382b23ac0d","event_at":"2026-07-27T05:37:32.585000Z","event_type":"price_change","frame_hash":"acf529d1ed05c9871e5d2076a85c3c43674dad493ca7b583696e4725a78fbece","frame_index":0,"kind":"data","monotonic_ns":232635783204208,"payload":{"event_type":"price_change","market":"0x3b40066b5cf3871a2f6237c5628bd8092a206aa998558ac5ec13c4483e31e160","price_changes":[{"asset_id":"14766054693214075530629349735273995982307625376442606753688071083149620216746","best_ask":"0.28","best_bid":"0.27","hash":"0271896edc81581c6c5f947ce71f0d0f18eb8460","price":"0.3","side":"SELL","size":"72"},{"asset_id":"110216635572655435074987471276357323571387854733835379371586402147734167783946","best_ask":"0.73","best_bid":"0.72","hash":"8651e8cacda695053430c00acc5ec194e1ecfa73","price":"0.7","side":"BUY","size":"72"}],"timestamp":"1785130652585"},"payload_hash":"d868acf414b9efd7ba40763d6706e06928870017a31cdef35cbd78f91aedba94","raw_frame":"{\"market\":\"0x3b40066b5cf3871a2f6237c5628bd8092a206aa998558ac5ec13c4483e31e160\", \"price_changes\":[{\"asset_id\":\"14766054693214075530629349735273995982307625376442606753688071083149620216746\", \"price\":\"0.3\", \"size\":\"72\", \"side\":\"SELL\", \"hash\":\"0271896edc81581c6c5f947ce71f0d0f18eb8460\", \"best_bid\":\"0.27\", \"best_ask\":\"0.28\"}, {\"asset_id\":\"110216635572655435074987471276357323571387854733835379371586402147734167783946\", \"price\":\"0.7\", \"size\":\"72\", \"side\":\"BUY\", \"hash\":\"8651e8cacda695053430c00acc5ec194e1ecfa73\", \"best_bid\":\"0.72\", \"best_ask\":\"0.73\"}], \"timestamp\":\"1785130652585\", \"event_type\":\"price_change\"}","received_at":"2026-07-27T05:37:32.548145Z","schema_version":"clob-market-ws.price_change.v1","sequence":null,"server_hash":null,"server_timestamp":"1785130652585","session_id":"502006c5cfcd437296561ea750c9ec8b","source":"clob_market_ws"},"received_at":"2026-07-27T05:37:32.548145Z","record_id":"a923c2231010b3befb707f42d77c0bd213c7ce3648ca41441cf824f6eea73253","schema_fingerprint":"4aa3821a28b0b7c2400bc59aba4bcc0a76e971dadd19610d3ad38c768e124dc7","schema_version":"edge-lab-recorder.raw.v1","sequence":null,"source":"clob_market_ws"}
{"event_at":"2026-07-27T05:37:32.608000Z","event_fingerprint":"64d44255c5ff31a6f1349b00fce433f25c2a136b39da7ad71bcb5a17dbf8b30c","payload":{"connection_id":"efc69d3132f1467b8e898a382b23ac0d","event_at":"2026-07-27T05:37:32.608000Z","event_type":"price_change","frame_hash":"90bd06290567f67442ea2fc9110c1a6b171276854e4b4dda2ecf70f4b268ff41","frame_index":0,"kind":"data","monotonic_ns":232635802822541,"payload":{"event_type":"price_change","market":"0x3b40066b5cf3871a2f6237c5628bd8092a206aa998558ac5ec13c4483e31e160","price_changes":[{"asset_id":"110216635572655435074987471276357323571387854733835379371586402147734167783946","best_ask":"0.73","best_bid":"0.72","hash":"9a47add90c74f39a6fc20ac79d3abe7826523c40","price":"0.04","side":"BUY","size":"583.09"},{"asset_id":"14766054693214075530629349735273995982307625376442606753688071083149620216746","best_ask":"0.28","best_bid":"0.27","hash":"c781e7faab8944882dbc24bf575585f6918ce3ba","price":"0.96","side":"SELL","size":"583.09"}],"timestamp":"1785130652608"},"payload_hash":"71c94a011fddca00fbcfdf4261b981cf0acee37a3417eef01949951980958f35","raw_frame":"{\"market\":\"0x3b40066b5cf3871a2f6237c5628bd8092a206aa998558ac5ec13c4483e31e160\", \"price_changes\":[{\"asset_id\":\"110216635572655435074987471276357323571387854733835379371586402147734167783946\", \"price\":\"0.04\", \"size\":\"583.09\", \"side\":\"BUY\", \"hash\":\"9a47add90c74f39a6fc20ac79d3abe7826523c40\", \"best_bid\":\"0.72\", \"best_ask\":\"0.73\"}, {\"asset_id\":\"14766054693214075530629349735273995982307625376442606753688071083149620216746\", \"price\":\"0.96\", \"size\":\"583.09\", \"side\":\"SELL\", \"hash\":\"c781e7faab8944882dbc24bf575585f6918ce3ba\", \"best_bid\":\"0.27\", \"best_ask\":\"0.28\"}], \"timestamp\":\"1785130652608\", \"event_type\":\"price_change\"}","received_at":"2026-07-27T05:37:32.567755Z","schema_version":"clob-market-ws.price_change.v1","sequence":null,"server_hash":null,"server_timestamp":"1785130652608","session_id":"502006c5cfcd437296561ea750c9ec8b","source":"clob_market_ws"},"received_at":"2026-07-27T05:37:32.567755Z","record_id":"d310959ecb652e51a2ed4a5109fe9a2b320c4718ccb1d50345669b23383c10ca","schema_fingerprint":"4aa3821a28b0b7c2400bc59aba4bcc0a76e971dadd19610d3ad38c768e124dc7","schema_version":"edge-lab-recorder.raw.v1","sequence":null,"source":"clob_market_ws"}
{"event_at":"2026-07-27T05:37:32.732000Z","event_fingerprint":"55cf3a842ecff1a6585ebdfec750c3716bef0755ed388933ac4c2b56aa00950d","payload":{"connection_id":"efc69d3132f1467b8e898a382b23ac0d","event_at":"2026-07-27T05:37:32.732000Z","event_type":"price_change","frame_hash":"ac12c7cc29ebd3e31cd1852682d4562dfc1bb51e5a3b8e65a7049b254faa3898","frame_index":0,"kind":"data","monotonic_ns":232635931026875,"payload":{"event_type":"price_change","market":"0x3b40066b5cf3871a2f6237c5628bd8092a206aa998558ac5ec13c4483e31e160","price_changes":[{"asset_id":"110216635572655435074987471276357323571387854733835379371586402147734167783946","best_ask":"0.73","best_bid":"0.72","hash":"a4ebc1a35f4b0a3b6e0c9d8a76df0bf4ba64a39d","price":"0.65","side":"BUY","size":"138"},{"asset_id":"14766054693214075530629349735273995982307625376442606753688071083149620216746","best_ask":"0.28","best_bid":"0.27","hash":"3303a83eaa82b43480737c9a010471aa06bea0f5","price":"0.35","side":"SELL","size":"138"}],"timestamp":"1785130652732"},"payload_hash":"0288b6c2fa4812cc75e23ae627b27a52c72ade60b86aa8e894d0d5cd62f8e42d","raw_frame":"{\"market\":\"0x3b40066b5cf3871a2f6237c5628bd8092a206aa998558ac5ec13c4483e31e160\", \"price_changes\":[{\"asset_id\":\"110216635572655435074987471276357323571387854733835379371586402147734167783946\", \"price\":\"0.65\", \"size\":\"138\", \"side\":\"BUY\", \"hash\":\"a4ebc1a35f4b0a3b6e0c9d8a76df0bf4ba64a39d\", \"best_bid\":\"0.72\", \"best_ask\":\"0.73\"}, {\"asset_id\":\"14766054693214075530629349735273995982307625376442606753688071083149620216746\", \"price\":\"0.35\", \"size\":\"138\", \"side\":\"SELL\", \"hash\":\"3303a83eaa82b43480737c9a010471aa06bea0f5\", \"best_bid\":\"0.27\", \"best_ask\":\"0.28\"}], \"timestamp\":\"1785130652732\", \"event_type\":\"price_change\"}","received_at":"2026-07-27T05:37:32.695969Z","schema_version":"clob-market-ws.price_change.v1","sequence":null,"server_hash":null,"server_timestamp":"1785130652732","session_id":"502006c5cfcd437296561ea750c9ec8b","source":"clob_market_ws"},"received_at":"2026-07-27T05:37:32.695969Z","record_id":"2d4d7d2a775e22bce03bb653f4a697fedb5bc746d8fca2d9a8f4e84aac32e92a","schema_fingerprint":"4aa3821a28b0b7c2400bc59aba4bcc0a76e971dadd19610d3ad38c768e124dc7","schema_version":"edge-lab-recorder.raw.v1","sequence":null,"source":"clob_market_ws"}
{"event_at":"2026-07-27T05:37:32.738000Z","event_fingerprint":"4d0451a9ececa51dfc673518681aac7b4f736fd6ef3fb20b598cbf77a3e2ed2d","payload":{"connection_id":"efc69d3132f1467b8e898a382b23ac0d","event_at":"2026-07-27T05:37:32.738000Z","event_type":"price_change","frame_hash":"39fc538b265103d9c5cc72778a0dc4b5957c786a13d67f9834ac759443406bd3","frame_index":0,"kind":"data","monotonic_ns":232635933274291,"payload":{"event_type":"price_change","market":"0x3b40066b5cf3871a2f6237c5628bd8092a206aa998558ac5ec13c4483e31e160","price_changes":[{"asset_id":"110216635572655435074987471276357323571387854733835379371586402147734167783946","best_ask":"0.73","best_bid":"0.72","hash":"8c0dad49d9fa7f3e4b261222bdc0a8306c09262d","price":"0.69","side":"BUY","size":"141.53"},{"asset_id":"14766054693214075530629349735273995982307625376442606753688071083149620216746","best_ask":"0.28","best_bid":"0.27","hash":"be0a4a81d58189a8aa8029e2d7b2cfcf7a571f1a","price":"0.31","side":"SELL","size":"141.53"}],"timestamp":"1785130652738"},"payload_hash":"5ab3f9014a487c24c60f746b8a535e72f35354c5707cc0def249f7a925deae88","raw_frame":"{\"market\":\"0x3b40066b5cf3871a2f6237c5628bd8092a206aa998558ac5ec13c4483e31e160\", \"price_changes\":[{\"asset_id\":\"110216635572655435074987471276357323571387854733835379371586402147734167783946\", \"price\":\"0.69\", \"size\":\"141.53\", \"side\":\"BUY\", \"hash\":\"8c0dad49d9fa7f3e4b261222bdc0a8306c09262d\", \"best_bid\":\"0.72\", \"best_ask\":\"0.73\"}, {\"asset_id\":\"14766054693214075530629349735273995982307625376442606753688071083149620216746\", \"price\":\"0.31\", \"size\":\"141.53\", \"side\":\"SELL\", \"hash\":\"be0a4a81d58189a8aa8029e2d7b2cfcf7a571f1a\", \"best_bid\":\"0.27\", \"best_ask\":\"0.28\"}], \"timestamp\":\"1785130652738\", \"event_type\":\"price_change\"}","received_at":"2026-07-27T05:37:32.698207Z","schema_version":"clob-market-ws.price_change.v1","sequence":null,"server_hash":null,"server_timestamp":"1785130652738","session_id":"502006c5cfcd437296561ea750c9ec8b","source":"clob_market_ws"},"received_at":"2026-07-27T05:37:32.698207Z","record_id":"f5a6966ba7c0b29e1bb26af0eabbac525f965a3151f1738128ba89582d9ad2f3","schema_fingerprint":"4aa3821a28b0b7c2400bc59aba4bcc0a76e971dadd19610d3ad38c768e124dc7","schema_version":"edge-lab-recorder.raw.v1","sequence":null,"source":"clob_market_ws"}
{"event_at":"2026-07-27T05:37:32.756000Z","event_fingerprint":"b915868abc97fdd0f2b679ef12ecdd775579924e4d7aebc5d04ab03d14af5ab7","payload":{"connection_id":"efc69d3132f1467b8e898a382b23ac0d","event_at":"2026-07-27T05:37:32.756000Z","event_type":"price_change","frame_hash":"3383b04bfbec34d77f50ce29aac196f196d8b1dab6829e4a531be812b25bf4e4","frame_index":0,"kind":"data","monotonic_ns":232635949849958,"payload":{"event_type":"price_change","market":"0x3b40066b5cf3871a2f6237c5628bd8092a206aa998558ac5ec13c4483e31e160","price_changes":[{"asset_id":"110216635572655435074987471276357323571387854733835379371586402147734167783946","best_ask":"0.73","best_bid":"0.72","hash":"dc3c4942465c75d79bb81985691e15d6912bcbec","price":"0.04","side":"BUY","size":"578.09"},{"asset_id":"14766054693214075530629349735273995982307625376442606753688071083149620216746","best_ask":"0.28","best_bid":"0.27","hash":"3d24c8180298451844fdfcb42a7daf4e769686b8","price":"0.96","side":"SELL","size":"578.09"}],"timestamp":"1785130652756"},"payload_hash":"b25de51b89edbdd205d28916c37f0ddd67aade7f8ea69a3bca8594c112c02050","raw_frame":"{\"market\":\"0x3b40066b5cf3871a2f6237c5628bd8092a206aa998558ac5ec13c4483e31e160\", \"price_changes\":[{\"asset_id\":\"110216635572655435074987471276357323571387854733835379371586402147734167783946\", \"price\":\"0.04\", \"size\":\"578.09\", \"side\":\"BUY\", \"hash\":\"dc3c4942465c75d79bb81985691e15d6912bcbec\", \"best_bid\":\"0.72\", \"best_ask\":\"0.73\"}, {\"asset_id\":\"14766054693214075530629349735273995982307625376442606753688071083149620216746\", \"price\":\"0.96\", \"size\":\"578.09\", \"side\":\"SELL\", \"hash\":\"3d24c8180298451844fdfcb42a7daf4e769686b8\", \"best_bid\":\"0.27\", \"best_ask\":\"0.28\"}], \"timestamp\":\"1785130652756\", \"event_type\":\"price_change\"}","received_at":"2026-07-27T05:37:32.714784Z","schema_version":"clob-market-ws.price_change.v1","sequence":null,"server_hash":null,"server_timestamp":"1785130652756","session_id":"502006c5cfcd437296561ea750c9ec8b","source":"clob_market_ws"},"received_at":"2026-07-27T05:37:32.714784Z","record_id":"5684d13b8dc2bf742f998eae498cbb4d28613f9207e2a5ca31a03693712827cd","schema_fingerprint":"4aa3821a28b0b7c2400bc59aba4bcc0a76e971dadd19610d3ad38c768e124dc7","schema_version":"edge-lab-recorder.raw.v1","sequence":null,"source":"clob_market_ws"}
{"event_at":"2026-07-27T05:37:32.757000Z","event_fingerprint":"d3e69ea4f68b08f6e34aa998dd348784bc953a22e1086ab84809822334e516c0","payload":{"connection_id":"efc69d3132f1467b8e898a382b23ac0d","event_at":"2026-07-27T05:37:32.757000Z","event_type":"price_change","frame_hash":"0910e4440f8090ca528905d48bb76ed224e01a384953ca2c8f7d7378cc90537f","frame_index":0,"kind":"data","monotonic_ns":232635952055208,"payload":{"event_type":"price_change","market":"0x3b40066b5cf3871a2f6237c5628bd8092a206aa998558ac5ec13c4483e31e160","price_changes":[{"asset_id":"14766054693214075530629349735273995982307625376442606753688071083149620216746","best_ask":"0.28","best_bid":"0.27","hash":"7410d8bbbdd41ae2501f60fb69db28b5423c05c4","price":"0.3","side":"SELL","size":"45.06"},{"asset_id":"110216635572655435074987471276357323571387854733835379371586402147734167783946","best_ask":"0.73","best_bid":"0.72","hash":"db21835f78ad7681962a56372dff6233df6e13e9","price":"0.7","side":"BUY","size":"45.06"}],"timestamp":"1785130652757"},"payload_hash":"df184552bc48f19ba6d46cd386783b3aace4bfb63b5b9aefe75855829f1871ee","raw_frame":"{\"market\":\"0x3b40066b5cf3871a2f6237c5628bd8092a206aa998558ac5ec13c4483e31e160\", \"price_changes\":[{\"asset_id\":\"14766054693214075530629349735273995982307625376442606753688071083149620216746\", \"price\":\"0.3\", \"size\":\"45.06\", \"side\":\"SELL\", \"hash\":\"7410d8bbbdd41ae2501f60fb69db28b5423c05c4\", \"best_bid\":\"0.27\", \"best_ask\":\"0.28\"}, {\"asset_id\":\"110216635572655435074987471276357323571387854733835379371586402147734167783946\", \"price\":\"0.7\", \"size\":\"45.06\", \"side\":\"BUY\", \"hash\":\"db21835f78ad7681962a56372dff6233df6e13e9\", \"best_bid\":\"0.72\", \"best_ask\":\"0.73\"}], \"timestamp\":\"1785130652757\", \"event_type\":\"price_change\"}","received_at":"2026-07-27T05:37:32.716989Z","schema_version":"clob-market-ws.price_change.v1","sequence":null,"server_hash":null,"server_timestamp":"1785130652757","session_id":"502006c5cfcd437296561ea750c9ec8b","source":"clob_market_ws"},"received_at":"2026-07-27T05:37:32.716989Z","record_id":"30c708d3f700c7079f5d582a89cb179e3e7994f95019c9983ec6bedc0da64383","schema_fingerprint":"4aa3821a28b0b7c2400bc59aba4bcc0a76e971dadd19610d3ad38c768e124dc7","schema_version":"edge-lab-recorder.raw.v1","sequence":null,"source":"clob_market_ws"}
{"event_at":"2026-07-27T05:37:32.760000Z","event_fingerprint":"557e6ac79c4797b27628406adaa1b273a618ed8d23ab88694299c3774013eb35","payload":{"connection_id":"efc69d3132f1467b8e898a382b23ac0d","event_at":"2026-07-27T05:37:32.760000Z","event_type":"price_change","frame_hash":"f9699e9b412b7c9ecfce82545c94e9c15e6a4c130cbad9cdebe9f8b2028dca09","frame_index":0,"kind":"data","monotonic_ns":232635955080791,"payload":{"event_type":"price_change","market":"0x3b40066b5cf3871a2f6237c5628bd8092a206aa998558ac5ec13c4483e31e160","price_changes":[{"asset_id":"14766054693214075530629349735273995982307625376442606753688071083149620216746","best_ask":"0.28","best_bid":"0.27","hash":"8d48fd500454d9628fad6dd8dca0f7c6a181d8e8","price":"0.31","side":"SELL","size":"134.53"},{"asset_id":"110216635572655435074987471276357323571387854733835379371586402147734167783946","best_ask":"0.73","best_bid":"0.72","hash":"10a48137cc93e782ea0470772e4ddde314ad9b0b","price":"0.69","side":"BUY","size":"134.53"}],"timestamp":"1785130652760"},"payload_hash":"8d54b227e14c3168076bc8a5ab1a794c4206043cabf5d96ee921899997111b60","raw_frame":"{\"market\":\"0x3b40066b5cf3871a2f6237c5628bd8092a206aa998558ac5ec13c4483e31e160\", \"price_changes\":[{\"asset_id\":\"14766054693214075530629349735273995982307625376442606753688071083149620216746\", \"price\":\"0.31\", \"size\":\"134.53\", \"side\":\"SELL\", \"hash\":\"8d48fd500454d9628fad6dd8dca0f7c6a181d8e8\", \"best_bid\":\"0.27\", \"best_ask\":\"0.28\"}, {\"asset_id\":\"110216635572655435074987471276357323571387854733835379371586402147734167783946\", \"price\":\"0.69\", \"size\":\"134.53\", \"side\":\"BUY\", \"hash\":\"10a48137cc93e782ea0470772e4ddde314ad9b0b\", \"best_bid\":\"0.72\", \"best_ask\":\"0.73\"}], \"timestamp\":\"1785130652760\", \"event_type\":\"price_change\"}","received_at":"2026-07-27T05:37:32.720003Z","schema_version":"clob-market-ws.price_change.v1","sequence":null,"server_hash":null,"server_timestamp":"1785130652760","session_id":"502006c5cfcd437296561ea750c9ec8b","source":"clob_market_ws"},"received_at":"2026-07-27T05:37:32.720003Z","record_id":"6215e36f1cb000ceff924159f871f9047aceaad2bc40b6f7fbd0fe8ffa28aded","schema_fingerprint":"4aa3821a28b0b7c2400bc59aba4bcc0a76e971dadd19610d3ad38c768e124dc7","schema_version":"edge-lab-recorder.raw.v1","sequence":null,"source":"clob_market_ws"}
{"event_at":"2026-07-27T05:37:32.762000Z","event_fingerprint":"ad33ac326dfdcd604af526d763c14fa2bd9b620ac92c8324eff24d3cc1cbc3ba","payload":{"connection_id":"efc69d3132f1467b8e898a382b23ac0d","event_at":"2026-07-27T05:37:32.762000Z","event_type":"price_change","frame_hash":"8cf9f85c40f35d6174341b5305d34a556838981c1cf8c62c51cd9224d690a3ca","frame_index":0,"kind":"data","monotonic_ns":232635958158541,"payload":{"event_type":"price_change","market":"0x3b40066b5cf3871a2f6237c5628bd8092a206aa998558ac5ec13c4483e31e160","price_changes":[{"asset_id":"110216635572655435074987471276357323571387854733835379371586402147734167783946","best_ask":"0.73","best_bid":"0.72","hash":"a83173ba689a336195864cf361f4906af87f7832","price":"0.7","side":"BUY","size":"72"},{"asset_id":"14766054693214075530629349735273995982307625376442606753688071083149620216746","best_ask":"0.28","best_bid":"0.27","hash":"01af4147fb20f9d24aeebbb7d4a7851b6ac18a13","price":"0.3","side":"SELL","size":"72"}],"timestamp":"1785130652762"},"payload_hash":"51825b1c647387c18734554888eeec9854bfbdf4671ca5424bf6c54f72fd816d","raw_frame":"{\"market\":\"0x3b40066b5cf3871a2f6237c5628bd8092a206aa998558ac5ec13c4483e31e160\", \"price_changes\":[{\"asset_id\":\"110216635572655435074987471276357323571387854733835379371586402147734167783946\", \"price\":\"0.7\", \"size\":\"72\", \"side\":\"BUY\", \"hash\":\"a83173ba689a336195864cf361f4906af87f7832\", \"best_bid\":\"0.72\", \"best_ask\":\"0.73\"}, {\"asset_id\":\"14766054693214075530629349735273995982307625376442606753688071083149620216746\", \"price\":\"0.3\", \"size\":\"72\", \"side\":\"SELL\", \"hash\":\"01af4147fb20f9d24aeebbb7d4a7851b6ac18a13\", \"best_bid\":\"0.27\", \"best_ask\":\"0.28\"}], \"timestamp\":\"1785130652762\", \"event_type\":\"price_change\"}","received_at":"2026-07-27T05:37:32.723095Z","schema_version":"clob-market-ws.price_change.v1","sequence":null,"server_hash":null,"server_timestamp":"1785130652762","session_id":"502006c5cfcd437296561ea750c9ec8b","source":"clob_market_ws"},"received_at":"2026-07-27T05:37:32.723095Z","record_id":"f0a6d01e6c0b18efa27eec0ee55abcc1952cbc2abbad6d069eff5fd01a075e12","schema_fingerprint":"4aa3821a28b0b7c2400bc59aba4bcc0a76e971dadd19610d3ad38c768e124dc7","schema_version":"edge-lab-recorder.raw.v1","sequence":null,"source":"clob_market_ws"}
{"event_at":"2026-07-27T05:37:32.853000Z","event_fingerprint":"4f22efa41951ef92b4b41616c0013ea37955c09bb427682b74e5ad83a6627aa0","payload":{"connection_id":"efc69d3132f1467b8e898a382b23ac0d","event_at":"2026-07-27T05:37:32.853000Z","event_type":"price_change","frame_hash":"66b79a53ef9100d331e2c95179477bbd695811822bdd251eaa0ac44c1269104d","frame_index":0,"kind":"data","monotonic_ns":232636049915416,"payload":{"event_type":"price_change","market":"0x3b40066b5cf3871a2f6237c5628bd8092a206aa998558ac5ec13c4483e31e160","price_changes":[{"asset_id":"110216635572655435074987471276357323571387854733835379371586402147734167783946","best_ask":"0.73","best_bid":"0.72","hash":"cd800fec15c4e44631aab3cb99ba1794c33d796c","price":"0.01","side":"BUY","size":"5617.45"},{"asset_id":"14766054693214075530629349735273995982307625376442606753688071083149620216746","best_ask":"0.28","best_bid":"0.27","hash":"5cf0849941a6d87615830edc7f62384da741177f","price":"0.99","side":"SELL","size":"5617.45"}],"timestamp":"1785130652853"},"payload_hash":"2f6ddadc368bdb733f930714d39e1c77b6707d801aabcf37afda50819570c1f2","raw_frame":"{\"market\":\"0x3b40066b5cf3871a2f6237c5628bd8092a206aa998558ac5ec13c4483e31e160\", \"price_changes\":[{\"asset_id\":\"110216635572655435074987471276357323571387854733835379371586402147734167783946\", \"price\":\"0.01\", \"size\":\"5617.45\", \"side\":\"BUY\", \"hash\":\"cd800fec15c4e44631aab3cb99ba1794c33d796c\", \"best_bid\":\"0.72\", \"best_ask\":\"0.73\"}, {\"asset_id\":\"14766054693214075530629349735273995982307625376442606753688071083149620216746\", \"price\":\"0.99\", \"size\":\"5617.45\", \"side\":\"SELL\", \"hash\":\"5cf0849941a6d87615830edc7f62384da741177f\", \"best_bid\":\"0.27\", \"best_ask\":\"0.28\"}], \"timestamp\":\"1785130652853\", \"event_type\":\"price_change\"}","received_at":"2026-07-27T05:37:32.814842Z","schema_version":"clob-market-ws.price_change.v1","sequence":null,"server_hash":null,"server_timestamp":"1785130652853","session_id":"502006c5cfcd437296561ea750c9ec8b","source":"clob_market_ws"},"received_at":"2026-07-27T05:37:32.814842Z","record_id":"b2e205b53146d35cceb0a6d9e5ed92c0eb5ab45b6572eaa022dc70e72eae1ee6","schema_fingerprint":"4aa3821a28b0b7c2400bc59aba4bcc0a76e971dadd19610d3ad38c768e124dc7","schema_version":"edge-lab-recorder.raw.v1","sequence":null,"source":"clob_market_ws"}
{"event_at":"2026-07-27T05:37:32.854000Z","event_fingerprint":"f8c09d18cdefb9dfc8b8a1af4f89c88fe85e95a19b45c06e064d660eefb42e7f","payload":{"connection_id":"efc69d3132f1467b8e898a382b23ac0d","event_at":"2026-07-27T05:37:32.854000Z","event_type":"price_change","frame_hash":"c5a1bf18e847ae7fb9f7574c9f7cbda2bb29d92605d401b617d3baf63d36aad6","frame_index":0,"kind":"data","monotonic_ns":232636051726916,"payload":{"event_type":"price_change","market":"0x3b40066b5cf3871a2f6237c5628bd8092a206aa998558ac5ec13c4483e31e160","price_changes":[{"asset_id":"110216635572655435074987471276357323571387854733835379371586402147734167783946","best_ask":"0.73","best_bid":"0.72","hash":"7f80875533d8205755aeba548df54ecedbd71c2f","price":"0.02","side":"BUY","size":"688.1"},{"asset_id":"14766054693214075530629349735273995982307625376442606753688071083149620216746","best_ask":"0.28","best_bid":"0.27","hash":"344c00e5133da641653af13b4d9e8969f887f2f5","price":"0.98","side":"SELL","size":"688.1"}],"timestamp":"1785130652854"},"payload_hash":"52c8733ce5e729e143a3219adb3e76721957aa847c8479ebc90d2d7c70a87a06","raw_frame":"{\"market\":\"0x3b40066b5cf3871a2f6237c5628bd8092a206aa998558ac5ec13c4483e31e160\", \"price_changes\":[{\"asset_id\":\"110216635572655435074987471276357323571387854733835379371586402147734167783946\", \"price\":\"0.02\", \"size\":\"688.1\", \"side\":\"BUY\", \"hash\":\"7f80875533d8205755aeba548df54ecedbd71c2f\", \"best_bid\":\"0.72\", \"best_ask\":\"0.73\"}, {\"asset_id\":\"14766054693214075530629349735273995982307625376442606753688071083149620216746\", \"price\":\"0.98\", \"size\":\"688.1\", \"side\":\"SELL\", \"hash\":\"344c00e5133da641653af13b4d9e8969f887f2f5\", \"best_bid\":\"0.27\", \"best_ask\":\"0.28\"}], \"timestamp\":\"1785130652854\", \"event_type\":\"price_change\"}","received_at":"2026-07-27T05:37:32.816661Z","schema_version":"clob-market-ws.price_change.v1","sequence":null,"server_hash":null,"server_timestamp":"1785130652854","session_id":"502006c5cfcd437296561ea750c9ec8b","source":"clob_market_ws"},"received_at":"2026-07-27T05:37:32.816661Z","record_id":"fca76d349be8d60f74aa1bc53de4ec371a71ec14c8b80dd05cd201db069039ca","schema_fingerprint":"4aa3821a28b0b7c2400bc59aba4bcc0a76e971dadd19610d3ad38c768e124dc7","schema_version":"edge-lab-recorder.raw.v1","sequence":null,"source":"clob_market_ws"}
{"event_at":"2026-07-27T05:37:32.870000Z","event_fingerprint":"c939f72cc89322b4882d5fba15e32e2dfc5ad62bfcc3e0695cf1c9afe3a2ed20","payload":{"connection_id":"efc69d3132f1467b8e898a382b23ac0d","event_at":"2026-07-27T05:37:32.870000Z","event_type":"price_change","frame_hash":"4df3253c5d99813958e25ecb70deb9b5ae40a1a8e2c627698e16fab98e892b21","frame_index":0,"kind":"data","monotonic_ns":232636064656125,"payload":{"event_type":"price_change","market":"0x3b40066b5cf3871a2f6237c5628bd8092a206aa998558ac5ec13c4483e31e160","price_changes":[{"asset_id":"110216635572655435074987471276357323571387854733835379371586402147734167783946","best_ask":"0.73","best_bid":"0.72","hash":"4460e289c460d1a34d87a85b3810abe6c17b0c10","price":"0.67","side":"BUY","size":"119.22"},{"asset_id":"14766054693214075530629349735273995982307625376442606753688071083149620216746","best_ask":"0.28","best_bid":"0.27","hash":"86bf8cb5904d00c7a37cc1a9d6ce3f62d60497e4","price":"0.33","side":"SELL","size":"119.22"}],"timestamp":"1785130652870"},"payload_hash":"99dbdbca209fbe78ba11dbd218cc50838412b772f926564e3f49e79f0af8cebb","raw_frame":"{\"market\":\"0x3b40066b5cf3871a2f6237c5628bd8092a206aa998558ac5ec13c4483e31e160\", \"price_changes\":[{\"asset_id\":\"110216635572655435074987471276357323571387854733835379371586402147734167783946\", \"price\":\"0.67\", \"size\":\"119.22\", \"side\":\"BUY\", \"hash\":\"4460e289c460d1a34d87a85b3810abe6c17b0c10\", \"best_bid\":\"0.72\", \"best_ask\":\"0.73\"}, {\"asset_id\":\"14766054693214075530629349735273995982307625376442606753688071083149620216746\", \"price\":\"0.33\", \"size\":\"119.22\", \"side\":\"SELL\", \"hash\":\"86bf8cb5904d00c7a37cc1a9d6ce3f62d60497e4\", \"best_bid\":\"0.27\", \"best_ask\":\"0.28\"}], \"timestamp\":\"1785130652870\", \"event_type\":\"price_change\"}","received_at":"2026-07-27T05:37:32.829591Z","schema_version":"clob-market-ws.price_change.v1","sequence":null,"server_hash":null,"server_timestamp":"1785130652870","session_id":"502006c5cfcd437296561ea750c9ec8b","source":"clob_market_ws"},"received_at":"2026-07-27T05:37:32.829591Z","record_id":"73c3e540643c7c64e2af048aa3b2d9de2b5ab23bc0fe4032b41b8c15e7a66c21","schema_fingerprint":"4aa3821a28b0b7c2400bc59aba4bcc0a76e971dadd19610d3ad38c768e124dc7","schema_version":"edge-lab-recorder.raw.v1","sequence":null,"source":"clob_market_ws"}
{"event_at":"2026-07-27T05:37:32.872000Z","event_fingerprint":"97e1bf27004547b745968754c8d1fa86bea31a717824a79274037d427fa0972b","payload":{"connection_id":"efc69d3132f1467b8e898a382b23ac0d","event_at":"2026-07-27T05:37:32.872000Z","event_type":"price_change","frame_hash":"392e326ce5ca827145a145799dc11b8d83efdd5fcacbdeec5059d5da67597d9d","frame_index":0,"kind":"data","monotonic_ns":232636066571291,"payload":{"event_type":"price_change","market":"0x3b40066b5cf3871a2f6237c5628bd8092a206aa998558ac5ec13c4483e31e160","price_changes":[{"asset_id":"110216635572655435074987471276357323571387854733835379371586402147734167783946","best_ask":"0.73","best_bid":"0.72","hash":"8122ca06c14ef139936944e9a9d960019bdf894a","price":"0.01","side":"BUY","size":"5612.45"},{"asset_id":"14766054693214075530629349735273995982307625376442606753688071083149620216746","best_ask":"0.28","best_bid":"0.27","hash":"c2bc5373ddc1469e10e3ede8a71e070d290c642b","price":"0.99","side":"SELL","size":"5612.45"}],"timestamp":"1785130652872"},"payload_hash":"1204492a1294fa8cbad9b0422f047a846af3d13a4a089f842feec4a8bb9bc527","raw_frame":"{\"market\":\"0x3b40066b5cf3871a2f6237c5628bd8092a206aa998558ac5ec13c4483e31e160\", \"price_changes\":[{\"asset_id\":\"110216635572655435074987471276357323571387854733835379371586402147734167783946\", \"price\":\"0.01\", \"size\":\"5612.45\", \"side\":\"BUY\", \"hash\":\"8122ca06c14ef139936944e9a9d960019bdf894a\", \"best_bid\":\"0.72\", \"best_ask\":\"0.73\"}, {\"asset_id\":\"14766054693214075530629349735273995982307625376442606753688071083149620216746\", \"price\":\"0.99\", \"size\":\"5612.45\", \"side\":\"SELL\", \"hash\":\"c2bc5373ddc1469e10e3ede8a71e070d290c642b\", \"best_bid\":\"0.27\", \"best_ask\":\"0.28\"}], \"timestamp\":\"1785130652872\", \"event_type\":\"price_change\"}","received_at":"2026-07-27T05:37:32.831514Z","schema_version":"clob-market-ws.price_change.v1","sequence":null,"server_hash":null,"server_timestamp":"1785130652872","session_id":"502006c5cfcd437296561ea750c9ec8b","source":"clob_market_ws"},"received_at":"2026-07-27T05:37:32.831514Z","record_id":"d4b6e4434840336b503fe6243d9f4c8717b13cbd3425159a3efe440b2a2f85ee","schema_fingerprint":"4aa3821a28b0b7c2400bc59aba4bcc0a76e971dadd19610d3ad38c768e124dc7","schema_version":"edge-lab-recorder.raw.v1","sequence":null,"source":"clob_market_ws"}
{"event_at":"2026-07-27T05:37:32.887000Z","event_fingerprint":"a7d22b24c7d2ac6fe65aa4a5114d4ea1528de5935f60e668396a16c6de69f47e","payload":{"connection_id":"efc69d3132f1467b8e898a382b23ac0d","event_at":"2026-07-27T05:37:32.887000Z","event_type":"price_change","frame_hash":"95778816630444fb66075c420a95b4392477a1a3256f1848dea682a82f915fe7","frame_index":0,"kind":"data","monotonic_ns":232636082588583,"payload":{"event_type":"price_change","market":"0x3b40066b5cf3871a2f6237c5628bd8092a206aa998558ac5ec13c4483e31e160","price_changes":[{"asset_id":"14766054693214075530629349735273995982307625376442606753688071083149620216746","best_ask":"0.28","best_bid":"0.27","hash":"d0b5c2a9ed9e103f3849a8eeeeb4681a51b97842","price":"0.17","side":"BUY","size":"827.94"},{"asset_id":"110216635572655435074987471276357323571387854733835379371586402147734167783946","best_ask":"0.73","best_bid":"0.72","hash":"6f5fb2d5d9d6e0e9347a3acf1d3e03b113e97db1","price":"0.83","side":"SELL","size":"827.94"}],"timestamp":"1785130652887"},"payload_hash":"5cda32f647d0dc9d6fc91d2a4352c8cbaf882643a7860000c3598515602a73c5","raw_frame":"{\"market\":\"0x3b40066b5cf3871a2f6237c5628bd8092a206aa998558ac5ec13c4483e31e160\", \"price_changes\":[{\"asset_id\":\"14766054693214075530629349735273995982307625376442606753688071083149620216746\", \"price\":\"0.17\", \"size\":\"827.94\", \"side\":\"BUY\", \"hash\":\"d0b5c2a9ed9e103f3849a8eeeeb4681a51b97842\", \"best_bid\":\"0.27\", \"best_ask\":\"0.28\"}, {\"asset_id\":\"110216635572655435074987471276357323571387854733835379371586402147734167783946\", \"price\":\"0.83\", \"size\":\"827.94\", \"side\":\"SELL\", \"hash\":\"6f5fb2d5d9d6e0e9347a3acf1d3e03b113e97db1\", \"best_bid\":\"0.72\", \"best_ask\":\"0.73\"}], \"timestamp\":\"1785130652887\", \"event_type\":\"price_change\"}","received_at":"2026-07-27T05:37:32.847530Z","schema_version":"clob-market-ws.price_change.v1","sequence":null,"server_hash":null,"server_timestamp":"1785130652887","session_id":"502006c5cfcd437296561ea750c9ec8b","source":"clob_market_ws"},"received_at":"2026-07-27T05:37:32.847530Z","record_id":"0b9b621dea79cb0c38adfecd4eb611e984b3f0ccbf9e5c929753cd10a51dfa08","schema_fingerprint":"4aa3821a28b0b7c2400bc59aba4bcc0a76e971dadd19610d3ad38c768e124dc7","schema_version":"edge-lab-recorder.raw.v1","sequence":null,"source":"clob_market_ws"}
{"event_at":"2026-07-27T05:37:32.897000Z","event_fingerprint":"89d00a8b720e2eadf3f4e32e354088dbaafb4e3deef7f047822bb28b8f5fa740","payload":{"connection_id":"efc69d3132f1467b8e898a382b23ac0d","event_at":"2026-07-27T05:37:32.897000Z","event_type":"price_change","frame_hash":"de2fd1a2c4e127c0fbbe765535586725b5892a8393d1fdd546dfc639a94c33b3","frame_index":0,"kind":"data","monotonic_ns":232636090956416,"payload":{"event_type":"price_change","market":"0x3b40066b5cf3871a2f6237c5628bd8092a206aa998558ac5ec13c4483e31e160","price_changes":[{"asset_id":"110216635572655435074987471276357323571387854733835379371586402147734167783946","best_ask":"0.73","best_bid":"0.72","hash":"edde2ddeee749e1ed2a61693ae4b046e8a918f54","price":"0.68","side":"BUY","size":"106.37"},{"asset_id":"14766054693214075530629349735273995982307625376442606753688071083149620216746","best_ask":"0.28","best_bid":"0.27","hash":"c02fd36287e28b2ac020e07a1169b767941a1b9b","price":"0.32","side":"SELL","size":"106.37"}],"timestamp":"1785130652897"},"payload_hash":"e7b91b982bdbfbc8d32e3d19e2a9b92de373fd7fb5c2ef8f7615ea57c48f46ce","raw_frame":"{\"market\":\"0x3b40066b5cf3871a2f6237c5628bd8092a206aa998558ac5ec13c4483e31e160\", \"price_changes\":[{\"asset_id\":\"110216635572655435074987471276357323571387854733835379371586402147734167783946\", \"price\":\"0.68\", \"size\":\"106.37\", \"side\":\"BUY\", \"hash\":\"edde2ddeee749e1ed2a61693ae4b046e8a918f54\", \"best_bid\":\"0.72\", \"best_ask\":\"0.73\"}, {\"asset_id\":\"14766054693214075530629349735273995982307625376442606753688071083149620216746\", \"price\":\"0.32\", \"size\":\"106.37\", \"side\":\"SELL\", \"hash\":\"c02fd36287e28b2ac020e07a1169b767941a1b9b\", \"best_bid\":\"0.27\", \"best_ask\":\"0.28\"}], \"timestamp\":\"1785130652897\", \"event_type\":\"price_change\"}","received_at":"2026-07-27T05:37:32.855890Z","schema_version":"clob-market-ws.price_change.v1","sequence":null,"server_hash":null,"server_timestamp":"1785130652897","session_id":"502006c5cfcd437296561ea750c9ec8b","source":"clob_market_ws"},"received_at":"2026-07-27T05:37:32.855890Z","record_id":"12e7ae85abf48c74d56618ca27c02e3c2e6deb1d0d71813c99e1f6ce02854322","schema_fingerprint":"4aa3821a28b0b7c2400bc59aba4bcc0a76e971dadd19610d3ad38c768e124dc7","schema_version":"edge-lab-recorder.raw.v1","sequence":null,"source":"clob_market_ws"}
{"event_at":"2026-07-27T05:37:32.907000Z","event_fingerprint":"092ac4567c2b0a45c5a6aa11021ad54466b9ad425b7e75762c4607d79ec2ab66","payload":{"connection_id":"efc69d3132f1467b8e898a382b23ac0d","event_at":"2026-07-27T05:37:32.907000Z","event_type":"price_change","frame_hash":"fde90b060334794f65f36c6a698128fb51d461369c5d6fa7a415a2f80f275808","frame_index":0,"kind":"data","monotonic_ns":232636101155333,"payload":{"event_type":"price_change","market":"0x3b40066b5cf3871a2f6237c5628bd8092a206aa998558ac5ec13c4483e31e160","price_changes":[{"asset_id":"110216635572655435074987471276357323571387854733835379371586402147734167783946","best_ask":"0.73","best_bid":"0.72","hash":"d27fa47ab94d530e7342e5c49360114171f00461","price":"0.7","side":"BUY","size":"45.06"},{"asset_id":"14766054693214075530629349735273995982307625376442606753688071083149620216746","best_ask":"0.28","best_bid":"0.27","hash":"68186db5fb3bf3894d8f83d940e6cde5883e2f9d","price":"0.3","side":"SELL","size":"45.06"}],"timestamp":"1785130652907"},"payload_hash":"5fe9a0ba83946fb69f23ae7caa935d32ba2618192a3dc25a8e924c23c3ce0849","raw_frame":"{\"market\":\"0x3b40066b5cf3871a2f6237c5628bd8092a206aa998558ac5ec13c4483e31e160\", \"price_changes\":[{\"asset_id\":\"110216635572655435074987471276357323571387854733835379371586402147734167783946\", \"price\":\"0.7\", \"size\":\"45.06\", \"side\":\"BUY\", \"hash\":\"d27fa47ab94d530e7342e5c49360114171f00461\", \"best_bid\":\"0.72\", \"best_ask\":\"0.73\"}, {\"asset_id\":\"14766054693214075530629349735273995982307625376442606753688071083149620216746\", \"price\":\"0.3\", \"size\":\"45.06\", \"side\":\"SELL\", \"hash\":\"68186db5fb3bf3894d8f83d940e6cde5883e2f9d\", \"best_bid\":\"0.27\", \"best_ask\":\"0.28\"}], \"timestamp\":\"1785130652907\", \"event_type\":\"price_change\"}","received_at":"2026-07-27T05:37:32.866090Z","schema_version":"clob-market-ws.price_change.v1","sequence":null,"server_hash":null,"server_timestamp":"1785130652907","session_id":"502006c5cfcd437296561ea750c9ec8b","source":"clob_market_ws"},"received_at":"2026-07-27T05:37:32.866090Z","record_id":"2e66730200929921b8d561fce9f3eaf9e354a6c0a45ddb9e3e0b9169716a2f26","schema_fingerprint":"4aa3821a28b0b7c2400bc59aba4bcc0a76e971dadd19610d3ad38c768e124dc7","schema_version":"edge-lab-recorder.raw.v1","sequence":null,"source":"clob_market_ws"}
{"event_at":"2026-07-27T05:37:32.910000Z","event_fingerprint":"f434bde98a0f02bc6debf0c5175eaa19c47b0f7d5c83a48e1c3049beafc7943a","payload":{"connection_id":"efc69d3132f1467b8e898a382b23ac0d","event_at":"2026-07-27T05:37:32.910000Z","event_type":"price_change","frame_hash":"04ed1b0be4227286bef38018901612c17b66d6f9b43e484eb893eb4e19535023","frame_index":0,"kind":"data","monotonic_ns":232636104266791,"payload":{"event_type":"price_change","market":"0x3b40066b5cf3871a2f6237c5628bd8092a206aa998558ac5ec13c4483e31e160","price_changes":[{"asset_id":"14766054693214075530629349735273995982307625376442606753688071083149620216746","best_ask":"0.28","best_bid":"0.27","hash":"9d777752d27cb3f0e673a20278e87882ca17253d","price":"0.31","side":"SELL","size":"141.53"},{"asset_id":"110216635572655435074987471276357323571387854733835379371586402147734167783946","best_ask":"0.73","best_bid":"0.72","hash":"5d1c56c6bf448920c639885f025261c4f9c19638","price":"0.69","side":"BUY","size":"141.53"}],"timestamp":"1785130652910"},"payload_hash":"fb4ae731860c787fab4a7f1091a1da9ec0b1af27063306d2edfcf7a3ba1fc028","raw_frame":"{\"market\":\"0x3b40066b5cf3871a2f6237c5628bd8092a206aa998558ac5ec13c4483e31e160\", \"price_changes\":[{\"asset_id\":\"14766054693214075530629349735273995982307625376442606753688071083149620216746\", \"price\":\"0.31\", \"size\":\"141.53\", \"side\":\"SELL\", \"hash\":\"9d777752d27cb3f0e673a20278e87882ca17253d\", \"best_bid\":\"0.27\", \"best_ask\":\"0.28\"}, {\"asset_id\":\"110216635572655435074987471276357323571387854733835379371586402147734167783946\", \"price\":\"0.69\", \"size\":\"141.53\", \"side\":\"BUY\", \"hash\":\"5d1c56c6bf448920c639885f025261c4f9c19638\", \"best_bid\":\"0.72\", \"best_ask\":\"0.73\"}], \"timestamp\":\"1785130652910\", \"event_type\":\"price_change\"}","received_at":"2026-07-27T05:37:32.869203Z","schema_version":"clob-market-ws.price_change.v1","sequence":null,"server_hash":null,"server_timestamp":"1785130652910","session_id":"502006c5cfcd437296561ea750c9ec8b","source":"clob_market_ws"},"received_at":"2026-07-27T05:37:32.869203Z","record_id":"ed8e3555f1a826f7fbb0e9335f665bd913038d5b16ea62abd7ab69f7564eb2f8","schema_fingerprint":"4aa3821a28b0b7c2400bc59aba4bcc0a76e971dadd19610d3ad38c768e124dc7","schema_version":"edge-lab-recorder.raw.v1","sequence":null,"source":"clob_market_ws"}
{"event_at":"2026-07-27T05:37:32.910000Z","event_fingerprint":"68c7a5f0621a43889ad9ecc08fea1b08f4a9456c790422398b601189349dc418","payload":{"connection_id":"efc69d3132f1467b8e898a382b23ac0d","event_at":"2026-07-27T05:37:32.910000Z","event_type":"price_change","frame_hash":"0598735fe74d0e79a97869595f81c23ea5fc8f9251fdc8b8dd2bcfc9195fabae","frame_index":0,"kind":"data","monotonic_ns":232636106914791,"payload":{"event_type":"price_change","market":"0x3b40066b5cf3871a2f6237c5628bd8092a206aa998558ac5ec13c4483e31e160","price_changes":[{"asset_id":"14766054693214075530629349735273995982307625376442606753688071083149620216746","best_ask":"0.28","best_bid":"0.27","hash":"9ad37ec06734d08c457e3a5bff6414257776d7bf","price":"0.3","side":"SELL","size":"72"},{"asset_id":"110216635572655435074987471276357323571387854733835379371586402147734167783946","best_ask":"0.73","best_bid":"0.72","hash":"06d3445718b6cad6e30f92b09fc9e6b162f64224","price":"0.7","side":"BUY","size":"72"}],"timestamp":"1785130652910"},"payload_hash":"5c544e85f485e6114dec0300b03a8f784de96ebfcd9fcf0c07f19375cd6b2d1a","raw_frame":"{\"market\":\"0x3b40066b5cf3871a2f6237c5628bd8092a206aa998558ac5ec13c4483e31e160\", \"price_changes\":[{\"asset_id\":\"14766054693214075530629349735273995982307625376442606753688071083149620216746\", \"price\":\"0.3\", \"size\":\"72\", \"side\":\"SELL\", \"hash\":\"9ad37ec06734d08c457e3a5bff6414257776d7bf\", \"best_bid\":\"0.27\", \"best_ask\":\"0.28\"}, {\"asset_id\":\"110216635572655435074987471276357323571387854733835379371586402147734167783946\", \"price\":\"0.7\", \"size\":\"72\", \"side\":\"BUY\", \"hash\":\"06d3445718b6cad6e30f92b09fc9e6b162f64224\", \"best_bid\":\"0.72\", \"best_ask\":\"0.73\"}], \"timestamp\":\"1785130652910\", \"event_type\":\"price_change\"}","received_at":"2026-07-27T05:37:32.871843Z","schema_version":"clob-market-ws.price_change.v1","sequence":null,"server_hash":null,"server_timestamp":"1785130652910","session_id":"502006c5cfcd437296561ea750c9ec8b","source":"clob_market_ws"},"received_at":"2026-07-27T05:37:32.871843Z","record_id":"1dcf4039a0db60b8e55f7061fa520e7403c2942386d6ce5f83850692a482cc45","schema_fingerprint":"4aa3821a28b0b7c2400bc59aba4bcc0a76e971dadd19610d3ad38c768e124dc7","schema_version":"edge-lab-recorder.raw.v1","sequence":null,"source":"clob_market_ws"}
{"event_at":"2026-07-27T05:37:32.921000Z","event_fingerprint":"81a276e23fdd7f221ba41bc9d3c8afcbe3afc3d4f538a8581a1ab6bd34ce311a","payload":{"connection_id":"efc69d3132f1467b8e898a382b23ac0d","event_at":"2026-07-27T05:37:32.921000Z","event_type":"price_change","frame_hash":"8ae3b73fe53b500218f4c5e4a4e182e2b76842d25c9f65d0cf03c0125c3c108a","frame_index":0,"kind":"data","monotonic_ns":232636119805500,"payload":{"event_type":"price_change","market":"0x3b40066b5cf3871a2f6237c5628bd8092a206aa998558ac5ec13c4483e31e160","price_changes":[{"asset_id":"110216635572655435074987471276357323571387854733835379371586402147734167783946","best_ask":"0.73","best_bid":"0.72","hash":"7fe005fd5b83ebc9e50dbb9d56bac45f1b6ec588","price":"0.02","side":"BUY","size":"683.1"},{"asset_id":"14766054693214075530629349735273995982307625376442606753688071083149620216746","best_ask":"0.28","best_bid":"0.27","hash":"821256f1501641b7974d60aa982b6d0a23612ebd","price":"0.98","side":"SELL","size":"683.1"}],"timestamp":"1785130652921"},"payload_hash":"8388baade174fbc7d41279365b65e09241877f5dc967f0879b7dbeea436ba6c2","raw_frame":"{\"market\":\"0x3b40066b5cf3871a2f6237c5628bd8092a206aa998558ac5ec13c4483e31e160\", \"price_changes\":[{\"asset_id\":\"110216635572655435074987471276357323571387854733835379371586402147734167783946\", \"price\":\"0.02\", \"size\":\"683.1\", \"side\":\"BUY\", \"hash\":\"7fe005fd5b83ebc9e50dbb9d56bac45f1b6ec588\", \"best_bid\":\"0.72\", \"best_ask\":\"0.73\"}, {\"asset_id\":\"14766054693214075530629349735273995982307625376442606753688071083149620216746\", \"price\":\"0.98\", \"size\":\"683.1\", \"side\":\"SELL\", \"hash\":\"821256f1501641b7974d60aa982b6d0a23612ebd\", \"best_bid\":\"0.27\", \"best_ask\":\"0.28\"}], \"timestamp\":\"1785130652921\", \"event_type\":\"price_change\"}","received_at":"2026-07-27T05:37:32.884741Z","schema_version":"clob-market-ws.price_change.v1","sequence":null,"server_hash":null,"server_timestamp":"1785130652921","session_id":"502006c5cfcd437296561ea750c9ec8b","source":"clob_market_ws"},"received_at":"2026-07-27T05:37:32.884741Z","record_id":"fb296f4e731837e97cb068b7bb94e1fa913e250329d9f18ef4d4ab3dae3593ff","schema_fingerprint":"4aa3821a28b0b7c2400bc59aba4bcc0a76e971dadd19610d3ad38c768e124dc7","schema_version":"edge-lab-recorder.raw.v1","sequence":null,"source":"clob_market_ws"}
{"event_at":"2026-07-27T05:37:32.978000Z","event_fingerprint":"f6d688f96319f760291310d72c0213e323476eafd0b87999c8d7fab90f280f3c","payload":{"connection_id":"efc69d3132f1467b8e898a382b23ac0d","event_at":"2026-07-27T05:37:32.978000Z","event_type":"price_change","frame_hash":"4ddbb78d36c82d4dff1360f3e89b8cf7471722689758596f25ff6e0e959b1d9e","frame_index":0,"kind":"data","monotonic_ns":232636172155625,"payload":{"event_type":"price_change","market":"0x3b40066b5cf3871a2f6237c5628bd8092a206aa998558ac5ec13c4483e31e160","price_changes":[{"asset_id":"110216635572655435074987471276357323571387854733835379371586402147734167783946","best_ask":"0.73","best_bid":"0.72","hash":"25424883c6dc5263c43972b6f9e5f4b96a655347","price":"0.01","side":"BUY","size":"5617.45"},{"asset_id":"14766054693214075530629349735273995982307625376442606753688071083149620216746","best_ask":"0.28","best_bid":"0.27","hash":"c0e67ea759a6f8dba01d150d1203f966ebe0d472","price":"0.99","side":"SELL","size":"5617.45"}],"timestamp":"1785130652978"},"payload_hash":"702cb34a7682202c1deb42d06c857f5c77d87b60ba8624400a5475e9cae9659d","raw_frame":"{\"market\":\"0x3b40066b5cf3871a2f6237c5628bd8092a206aa998558ac5ec13c4483e31e160\", \"price_changes\":[{\"asset_id\":\"110216635572655435074987471276357323571387854733835379371586402147734167783946\", \"price\":\"0.01\", \"size\":\"5617.45\", \"side\":\"BUY\", \"hash\":\"25424883c6dc5263c43972b6f9e5f4b96a655347\", \"best_bid\":\"0.72\", \"best_ask\":\"0.73\"}, {\"asset_id\":\"14766054693214075530629349735273995982307625376442606753688071083149620216746\", \"price\":\"0.99\", \"size\":\"5617.45\", \"side\":\"SELL\", \"hash\":\"c0e67ea759a6f8dba01d150d1203f966ebe0d472\", \"best_bid\":\"0.27\", \"best_ask\":\"0.28\"}], \"timestamp\":\"1785130652978\", \"event_type\":\"price_change\"}","received_at":"2026-07-27T05:37:32.937092Z","schema_version":"clob-market-ws.price_change.v1","sequence":null,"server_hash":null,"server_timestamp":"1785130652978","session_id":"502006c5cfcd437296561ea750c9ec8b","source":"clob_market_ws"},"received_at":"2026-07-27T05:37:32.937092Z","record_id":"c866579a91a6a9bb589f2d802e44a88e648fc38d1f12343ff8ee57c8da79d8e9","schema_fingerprint":"4aa3821a28b0b7c2400bc59aba4bcc0a76e971dadd19610d3ad38c768e124dc7","schema_version":"edge-lab-recorder.raw.v1","sequence":null,"source":"clob_market_ws"}
{"event_at":"2026-07-27T05:37:33.001000Z","event_fingerprint":"5f41678136e2bd175cbf2adb9f5c54fef2085929edbcb35aaa5003d3a5229070","payload":{"connection_id":"efc69d3132f1467b8e898a382b23ac0d","event_at":"2026-07-27T05:37:33.001000Z","event_type":"price_change","frame_hash":"83b3756866e049cfadf30111bb1d2116df3a9f78c1b37326741697457ec3c7b3","frame_index":0,"kind":"data","monotonic_ns":232636210507583,"payload":{"event_type":"price_change","market":"0x3b40066b5cf3871a2f6237c5628bd8092a206aa998558ac5ec13c4483e31e160","price_changes":[{"asset_id":"110216635572655435074987471276357323571387854733835379371586402147734167783946","best_ask":"0.73","best_bid":"0.72","hash":"065ad1a625a99ce345f93bbc9fb6cf64c81366e0","price":"0.01","side":"BUY","size":"5612.45"},{"asset_id":"14766054693214075530629349735273995982307625376442606753688071083149620216746","best_ask":"0.28","best_bid":"0.27","hash":"54eb4e256088ac08dda69bc6a39be17194390ab4","price":"0.99","side":"SELL","size":"5612.45"}],"timestamp":"1785130653001"},"payload_hash":"7589944d64d2cfe9318f6a5339cac5f941d1b3a30ac02757614a4defd6c71973","raw_frame":"{\"market\":\"0x3b40066b5cf3871a2f6237c5628bd8092a206aa998558ac5ec13c4483e31e160\", \"price_changes\":[{\"asset_id\":\"110216635572655435074987471276357323571387854733835379371586402147734167783946\", \"price\":\"0.01\", \"size\":\"5612.45\", \"side\":\"BUY\", \"hash\":\"065ad1a625a99ce345f93bbc9fb6cf64c81366e0\", \"best_bid\":\"0.72\", \"best_ask\":\"0.73\"}, {\"asset_id\":\"14766054693214075530629349735273995982307625376442606753688071083149620216746\", \"price\":\"0.99\", \"size\":\"5612.45\", \"side\":\"SELL\", \"hash\":\"54eb4e256088ac08dda69bc6a39be17194390ab4\", \"best_bid\":\"0.27\", \"best_ask\":\"0.28\"}], \"timestamp\":\"1785130653001\", \"event_type\":\"price_change\"}","received_at":"2026-07-27T05:37:32.975445Z","schema_version":"clob-market-ws.price_change.v1","sequence":null,"server_hash":null,"server_timestamp":"1785130653001","session_id":"502006c5cfcd437296561ea750c9ec8b","source":"clob_market_ws"},"received_at":"2026-07-27T05:37:32.975445Z","record_id":"71b73a1296379142af0f431d0be471e75498c30f68b5b858be984aaf59439504","schema_fingerprint":"4aa3821a28b0b7c2400bc59aba4bcc0a76e971dadd19610d3ad38c768e124dc7","schema_version":"edge-lab-recorder.raw.v1","sequence":null,"source":"clob_market_ws"}
{"event_at":"2026-07-27T05:37:33.019000Z","event_fingerprint":"38042e6c00d816de3c5bb831bf86f6246290e4a95e6a090e3c347207de25bb74","payload":{"connection_id":"efc69d3132f1467b8e898a382b23ac0d","event_at":"2026-07-27T05:37:33.019000Z","event_type":"price_change","frame_hash":"cede7df6b0eb23d536cffbaa26dee9dcb8fc0080833bdca4af8c742a389d13fb","frame_index":0,"kind":"data","monotonic_ns":232636226479958,"payload":{"event_type":"price_change","market":"0x3b40066b5cf3871a2f6237c5628bd8092a206aa998558ac5ec13c4483e31e160","price_changes":[{"asset_id":"110216635572655435074987471276357323571387854733835379371586402147734167783946","best_ask":"0.73","best_bid":"0.72","hash":"90434ea746a062bcc3537ed995058101b72f469d","price":"0.01","side":"BUY","size":"5617.45"},{"asset_id":"14766054693214075530629349735273995982307625376442606753688071083149620216746","best_ask":"0.28","best_bid":"0.27","hash":"940c95b6f2a3ecb0915b6cec6edb2d14a0ff1654","price":"0.99","side":"SELL","size":"5617.45"}],"timestamp":"1785130653019"},"payload_hash":"2de38e7a9446a853be2ccb20aa224c91a8da59fe430853550162d8c2cc864259","raw_frame":"{\"market\":\"0x3b40066b5cf3871a2f6237c5628bd8092a206aa998558ac5ec13c4483e31e160\", \"price_changes\":[{\"asset_id\":\"110216635572655435074987471276357323571387854733835379371586402147734167783946\", \"price\":\"0.01\", \"size\":\"5617.45\", \"side\":\"BUY\", \"hash\":\"90434ea746a062bcc3537ed995058101b72f469d\", \"best_bid\":\"0.72\", \"best_ask\":\"0.73\"}, {\"asset_id\":\"14766054693214075530629349735273995982307625376442606753688071083149620216746\", \"price\":\"0.99\", \"size\":\"5617.45\", \"side\":\"SELL\", \"hash\":\"940c95b6f2a3ecb0915b6cec6edb2d14a0ff1654\", \"best_bid\":\"0.27\", \"best_ask\":\"0.28\"}], \"timestamp\":\"1785130653019\", \"event_type\":\"price_change\"}","received_at":"2026-07-27T05:37:32.991416Z","schema_version":"clob-market-ws.price_change.v1","sequence":null,"server_hash":null,"server_timestamp":"1785130653019","session_id":"502006c5cfcd437296561ea750c9ec8b","source":"clob_market_ws"},"received_at":"2026-07-27T05:37:32.991416Z","record_id":"18b47381c2d670a5d648aa91b864eed9a9076ca4eb12e2b3712d818465b2e019","schema_fingerprint":"4aa3821a28b0b7c2400bc59aba4bcc0a76e971dadd19610d3ad38c768e124dc7","schema_version":"edge-lab-recorder.raw.v1","sequence":null,"source":"clob_market_ws"}
{"event_at":"2026-07-27T05:37:33.022000Z","event_fingerprint":"f4d61c3d1eba84272ef5b8c80283daa4d8681c2edc96287aa812a4426205f024","payload":{"connection_id":"efc69d3132f1467b8e898a382b23ac0d","event_at":"2026-07-27T05:37:33.022000Z","event_type":"price_change","frame_hash":"2ea471082bafef9c441c90fdfb836314a5e1df0cbb85281d599c1ea34de804e9","frame_index":0,"kind":"data","monotonic_ns":232636231300500,"payload":{"event_type":"price_change","market":"0x3b40066b5cf3871a2f6237c5628bd8092a206aa998558ac5ec13c4483e31e160","price_changes":[{"asset_id":"14766054693214075530629349735273995982307625376442606753688071083149620216746","best_ask":"0.28","best_bid":"0.27","hash":"51e69e11cb14245fb7039dbabd38d502f179e61c","price":"0.01","side":"BUY","size":"5628.02"},{"asset_id":"110216635572655435074987471276357323571387854733835379371586402147734167783946","best_ask":"0.73","best_bid":"0.72","hash":"7d358313318e334455e407f2db5192776a8fa8f7","price":"0.99","side":"SELL","size":"5628.02"}],"timestamp":"1785130653022"},"payload_hash":"67b20b7634cdcb30bad569555ef2090997b16c7fe281896e337d5517d0908118","raw_frame":"{\"market\":\"0x3b40066b5cf3871a2f6237c5628bd8092a206aa998558ac5ec13c4483e31e160\", \"price_changes\":[{\"asset_id\":\"14766054693214075530629349735273995982307625376442606753688071083149620216746\", \"price\":\"0.01\", \"size\":\"5628.02\", \"side\":\"BUY\", \"hash\":\"51e69e11cb14245fb7039dbabd38d502f179e61c\", \"best_bid\":\"0.27\", \"best_ask\":\"0.28\"}, {\"asset_id\":\"110216635572655435074987471276357323571387854733835379371586402147734167783946\", \"price\":\"0.99\", \"size\":\"5628.02\", \"side\":\"SELL\", \"hash\":\"7d358313318e334455e407f2db5192776a8fa8f7\", \"best_bid\":\"0.72\", \"best_ask\":\"0.73\"}], \"timestamp\":\"1785130653022\", \"event_type\":\"price_change\"}","received_at":"2026-07-27T05:37:32.996245Z","schema_version":"clob-market-ws.price_change.v1","sequence":null,"server_hash":null,"server_timestamp":"1785130653022","session_id":"502006c5cfcd437296561ea750c9ec8b","source":"clob_market_ws"},"received_at":"2026-07-27T05:37:32.996245Z","record_id":"5ce504c249c398196ca422b578fd8e30dbc95ccff94d855da068c319d677a837","schema_fingerprint":"4aa3821a28b0b7c2400bc59aba4bcc0a76e971dadd19610d3ad38c768e124dc7","schema_version":"edge-lab-recorder.raw.v1","sequence":null,"source":"clob_market_ws"}
{"event_at":"2026-07-27T05:37:33.023000Z","event_fingerprint":"f0e8327bfc83f8a56e1a95fafb2935cedeac1cf7c37e7128b2c76010898ccb39","payload":{"connection_id":"efc69d3132f1467b8e898a382b23ac0d","event_at":"2026-07-27T05:37:33.023000Z","event_type":"price_change","frame_hash":"3e45fbcdb44682ce5cea83ac0a38c8a531e1386551376ee4e06478446f69afa4","frame_index":0,"kind":"data","monotonic_ns":232636233755625,"payload":{"event_type":"price_change","market":"0x3b40066b5cf3871a2f6237c5628bd8092a206aa998558ac5ec13c4483e31e160","price_changes":[{"asset_id":"110216635572655435074987471276357323571387854733835379371586402147734167783946","best_ask":"0.73","best_bid":"0.72","hash":"f1abf2e05c062dfbed8d9240afe6d291e36e9692","price":"0.67","side":"BUY","size":"89.22"},{"asset_id":"14766054693214075530629349735273995982307625376442606753688071083149620216746","best_ask":"0.28","best_bid":"0.27","hash":"4edab4866ef0f542187d8d68409c0d4389558358","price":"0.33","side":"SELL","size":"89.22"}],"timestamp":"1785130653023"},"payload_hash":"8c8f6415c3373fe5307e6d68cc88adb8de44a31c16f001158a5408cbab513994","raw_frame":"{\"market\":\"0x3b40066b5cf3871a2f6237c5628bd8092a206aa998558ac5ec13c4483e31e160\", \"price_changes\":[{\"asset_id\":\"110216635572655435074987471276357323571387854733835379371586402147734167783946\", \"price\":\"0.67\", \"size\":\"89.22\", \"side\":\"BUY\", \"hash\":\"f1abf2e05c062dfbed8d9240afe6d291e36e9692\", \"best_bid\":\"0.72\", \"best_ask\":\"0.73\"}, {\"asset_id\":\"14766054693214075530629349735273995982307625376442606753688071083149620216746\", \"price\":\"0.33\", \"size\":\"89.22\", \"side\":\"SELL\", \"hash\":\"4edab4866ef0f542187d8d68409c0d4389558358\", \"best_bid\":\"0.27\", \"best_ask\":\"0.28\"}], \"timestamp\":\"1785130653023\", \"event_type\":\"price_change\"}","received_at":"2026-07-27T05:37:32.998693Z","schema_version":"clob-market-ws.price_change.v1","sequence":null,"server_hash":null,"server_timestamp":"1785130653023","session_id":"502006c5cfcd437296561ea750c9ec8b","source":"clob_market_ws"},"received_at":"2026-07-27T05:37:32.998693Z","record_id":"a57c410a197d3ec552f0d6151f9c9dcb169c5bc01753820335771a6d6be0bfa0","schema_fingerprint":"4aa3821a28b0b7c2400bc59aba4bcc0a76e971dadd19610d3ad38c768e124dc7","schema_version":"edge-lab-recorder.raw.v1","sequence":null,"source":"clob_market_ws"}
{"event_at":"2026-07-27T05:37:33.024000Z","event_fingerprint":"3a993c6a5ffb8443720ef3a3b55140236c80d868574b0d7fad284142b66c8662","payload":{"connection_id":"efc69d3132f1467b8e898a382b23ac0d","event_at":"2026-07-27T05:37:33.024000Z","event_type":"price_change","frame_hash":"ff1577bc862b462d4af754763cb1f75e06ff9a421c159c67c30440a91616a6de","frame_index":0,"kind":"data","monotonic_ns":232636238553625,"payload":{"event_type":"price_change","market":"0x3b40066b5cf3871a2f6237c5628bd8092a206aa998558ac5ec13c4483e31e160","price_changes":[{"asset_id":"110216635572655435074987471276357323571387854733835379371586402147734167783946","best_ask":"0.73","best_bid":"0.72","hash":"f84b2008bf1ff36cc9f74aa569c705d03a90ddbc","price":"0.67","side":"BUY","size":"59.22"},{"asset_id":"14766054693214075530629349735273995982307625376442606753688071083149620216746","best_ask":"0.28","best_bid":"0.27","hash":"70ed24483b1167b3500574e9e410971bf9956c94","price":"0.33","side":"SELL","size":"59.22"}],"timestamp":"1785130653024"},"payload_hash":"a871c6397739f13009934f5021d0e1b162c7d71048ff9732fa41195f2a0a4da2","raw_frame":"{\"market\":\"0x3b40066b5cf3871a2f6237c5628bd8092a206aa998558ac5ec13c4483e31e160\", \"price_changes\":[{\"asset_id\":\"110216635572655435074987471276357323571387854733835379371586402147734167783946\", \"price\":\"0.67\", \"size\":\"59.22\", \"side\":\"BUY\", \"hash\":\"f84b2008bf1ff36cc9f74aa569c705d03a90ddbc\", \"best_bid\":\"0.72\", \"best_ask\":\"0.73\"}, {\"asset_id\":\"14766054693214075530629349735273995982307625376442606753688071083149620216746\", \"price\":\"0.33\", \"size\":\"59.22\", \"side\":\"SELL\", \"hash\":\"70ed24483b1167b3500574e9e410971bf9956c94\", \"best_bid\":\"0.27\", \"best_ask\":\"0.28\"}], \"timestamp\":\"1785130653024\", \"event_type\":\"price_change\"}","received_at":"2026-07-27T05:37:33.003491Z","schema_version":"clob-market-ws.price_change.v1","sequence":null,"server_hash":null,"server_timestamp":"1785130653024","session_id":"502006c5cfcd437296561ea750c9ec8b","source":"clob_market_ws"},"received_at":"2026-07-27T05:37:33.003491Z","record_id":"54c4a8c048c8292dd389a9571ba3bfea1cb7603684b006e180108d37ab22114d","schema_fingerprint":"4aa3821a28b0b7c2400bc59aba4bcc0a76e971dadd19610d3ad38c768e124dc7","schema_version":"edge-lab-recorder.raw.v1","sequence":null,"source":"clob_market_ws"}
{"event_at":"2026-07-27T05:37:33.024000Z","event_fingerprint":"8aca8d63917eb44b09c3e95b86d5f6556818f4d70a864002e9c05246855ea30b","payload":{"connection_id":"efc69d3132f1467b8e898a382b23ac0d","event_at":"2026-07-27T05:37:33.024000Z","event_type":"price_change","frame_hash":"bb930cd4a63c47b5e6b216ed20af70a5711f38032af06f980907eb51ad3330b4","frame_index":0,"kind":"data","monotonic_ns":232636241750791,"payload":{"event_type":"price_change","market":"0x3b40066b5cf3871a2f6237c5628bd8092a206aa998558ac5ec13c4483e31e160","price_changes":[{"asset_id":"14766054693214075530629349735273995982307625376442606753688071083149620216746","best_ask":"0.28","best_bid":"0.27","hash":"dfddb08abe69ac94c7e9c0359b51839a83fe1890","price":"0.31","side":"SELL","size":"134.53"},{"asset_id":"110216635572655435074987471276357323571387854733835379371586402147734167783946","best_ask":"0.73","best_bid":"0.72","hash":"6d13fb19726bdc1225bf29b802e624d12a4cbb17","price":"0.69","side":"BUY","size":"134.53"}],"timestamp":"1785130653024"},"payload_hash":"c959641de21cc887a9f59f70d81d57a8fb90e07e1c21bb63a94ab55f013260c7","raw_frame":"{\"market\":\"0x3b40066b5cf3871a2f6237c5628bd8092a206aa998558ac5ec13c4483e31e160\", \"price_changes\":[{\"asset_id\":\"14766054693214075530629349735273995982307625376442606753688071083149620216746\", \"price\":\"0.31\", \"size\":\"134.53\", \"side\":\"SELL\", \"hash\":\"dfddb08abe69ac94c7e9c0359b51839a83fe1890\", \"best_bid\":\"0.27\", \"best_ask\":\"0.28\"}, {\"asset_id\":\"110216635572655435074987471276357323571387854733835379371586402147734167783946\", \"price\":\"0.69\", \"size\":\"134.53\", \"side\":\"BUY\", \"hash\":\"6d13fb19726bdc1225bf29b802e624d12a4cbb17\", \"best_bid\":\"0.72\", \"best_ask\":\"0.73\"}], \"timestamp\":\"1785130653024\", \"event_type\":\"price_change\"}","received_at":"2026-07-27T05:37:33.006689Z","schema_version":"clob-market-ws.price_change.v1","sequence":null,"server_hash":null,"server_timestamp":"1785130653024","session_id":"502006c5cfcd437296561ea750c9ec8b","source":"clob_market_ws"},"received_at":"2026-07-27T05:37:33.006689Z","record_id":"0864128b2a6c9aaf83cdd5c793ba52c75a492aa9a2fb76bdae0f87bd534b52d9","schema_fingerprint":"4aa3821a28b0b7c2400bc59aba4bcc0a76e971dadd19610d3ad38c768e124dc7","schema_version":"edge-lab-recorder.raw.v1","sequence":null,"source":"clob_market_ws"}
{"event_at":"2026-07-27T05:37:33.028000Z","event_fingerprint":"f7f923c4a9433d1c2dbf7bd3eb169cde686dabfff24653f399df2d504d7850f6","payload":{"connection_id":"efc69d3132f1467b8e898a382b23ac0d","event_at":"2026-07-27T05:37:33.028000Z","event_type":"price_change","frame_hash":"b4517117e876b7189c8a2b65074ff4e9519be6936280c91d15f767720cdb88fd","frame_index":0,"kind":"data","monotonic_ns":232636243519500,"payload":{"event_type":"price_change","market":"0x3b40066b5cf3871a2f6237c5628bd8092a206aa998558ac5ec13c4483e31e160","price_changes":[{"asset_id":"14766054693214075530629349735273995982307625376442606753688071083149620216746","best_ask":"0.28","best_bid":"0.27","hash":"3adb53ac9c311a67e8462e864a7ce621f07562a3","price":"0.3","side":"SELL","size":"45.06"},{"asset_id":"110216635572655435074987471276357323571387854733835379371586402147734167783946","best_ask":"0.73","best_bid":"0.72","hash":"4747205dac7781c0a64286ce449627d14be86146","price":"0.7","side":"BUY","size":"45.06"}],"timestamp":"1785130653028"},"payload_hash":"d837916eb7bfddd983a2f47bbd9b61eaaa1a1b4f91cbd1f5194c6cac5c2ca226","raw_frame":"{\"market\":\"0x3b40066b5cf3871a2f6237c5628bd8092a206aa998558ac5ec13c4483e31e160\", \"price_changes\":[{\"asset_id\":\"14766054693214075530629349735273995982307625376442606753688071083149620216746\", \"price\":\"0.3\", \"size\":\"45.06\", \"side\":\"SELL\", \"hash\":\"3adb53ac9c311a67e8462e864a7ce621f07562a3\", \"best_bid\":\"0.27\", \"best_ask\":\"0.28\"}, {\"asset_id\":\"110216635572655435074987471276357323571387854733835379371586402147734167783946\", \"price\":\"0.7\", \"size\":\"45.06\", \"side\":\"BUY\", \"hash\":\"4747205dac7781c0a64286ce449627d14be86146\", \"best_bid\":\"0.72\", \"best_ask\":\"0.73\"}], \"timestamp\":\"1785130653028\", \"event_type\":\"price_change\"}","received_at":"2026-07-27T05:37:33.008456Z","schema_version":"clob-market-ws.price_change.v1","sequence":null,"server_hash":null,"server_timestamp":"1785130653028","session_id":"502006c5cfcd437296561ea750c9ec8b","source":"clob_market_ws"},"received_at":"2026-07-27T05:37:33.008456Z","record_id":"bd444656cfe8cca59619503417af749d9b4c14c5b0188bd5e0c58bc9bf7d4f01","schema_fingerprint":"4aa3821a28b0b7c2400bc59aba4bcc0a76e971dadd19610d3ad38c768e124dc7","schema_version":"edge-lab-recorder.raw.v1","sequence":null,"source":"clob_market_ws"}
{"event_at":"2026-07-27T05:37:33.030000Z","event_fingerprint":"2f8893053240cca49a77ed13feae7cd82aa4863c9d132860d5f6253bc8a329a6","payload":{"connection_id":"efc69d3132f1467b8e898a382b23ac0d","event_at":"2026-07-27T05:37:33.030000Z","event_type":"price_change","frame_hash":"d3df0b419ae5e2813a25b501853b24e42de03d45d03c5a15279f6f0e0ad3f3c8","frame_index":0,"kind":"data","monotonic_ns":232636245171916,"payload":{"event_type":"price_change","market":"0x3b40066b5cf3871a2f6237c5628bd8092a206aa998558ac5ec13c4483e31e160","price_changes":[{"asset_id":"110216635572655435074987471276357323571387854733835379371586402147734167783946","best_ask":"0.73","best_bid":"0.72","hash":"10314f9a056f6721ef3e9addcc2efa07f411443d","price":"0.7","side":"BUY","size":"72"},{"asset_id":"14766054693214075530629349735273995982307625376442606753688071083149620216746","best_ask":"0.28","best_bid":"0.27","hash":"7354419b1bc3a1c59c0942058775792119a3e692","price":"0.3","side":"SELL","size":"72"}],"timestamp":"1785130653030"},"payload_hash":"3c468f08b8d12f8b811085fd40850507c2a58c67d6c58f874754dedf69adefc3","raw_frame":"{\"market\":\"0x3b40066b5cf3871a2f6237c5628bd8092a206aa998558ac5ec13c4483e31e160\", \"price_changes\":[{\"asset_id\":\"110216635572655435074987471276357323571387854733835379371586402147734167783946\", \"price\":\"0.7\", \"size\":\"72\", \"side\":\"BUY\", \"hash\":\"10314f9a056f6721ef3e9addcc2efa07f411443d\", \"best_bid\":\"0.72\", \"best_ask\":\"0.73\"}, {\"asset_id\":\"14766054693214075530629349735273995982307625376442606753688071083149620216746\", \"price\":\"0.3\", \"size\":\"72\", \"side\":\"SELL\", \"hash\":\"7354419b1bc3a1c59c0942058775792119a3e692\", \"best_bid\":\"0.27\", \"best_ask\":\"0.28\"}], \"timestamp\":\"1785130653030\", \"event_type\":\"price_change\"}","received_at":"2026-07-27T05:37:33.010110Z","schema_version":"clob-market-ws.price_change.v1","sequence":null,"server_hash":null,"server_timestamp":"1785130653030","session_id":"502006c5cfcd437296561ea750c9ec8b","source":"clob_market_ws"},"received_at":"2026-07-27T05:37:33.010110Z","record_id":"2ee92f2397da9ef30ff443518665d33b92b284cf26ccd3154e65550ddcb44790","schema_fingerprint":"4aa3821a28b0b7c2400bc59aba4bcc0a76e971dadd19610d3ad38c768e124dc7","schema_version":"edge-lab-recorder.raw.v1","sequence":null,"source":"clob_market_ws"}
{"event_at":"2026-07-27T05:37:33.034000Z","event_fingerprint":"2f26a4810242a654e9d94f3f746819240ca3a17f18b0f07f8fe44b3d5bb11f46","payload":{"connection_id":"efc69d3132f1467b8e898a382b23ac0d","event_at":"2026-07-27T05:37:33.034000Z","event_type":"price_change","frame_hash":"12a8e0d9bfd37c6609d657afa2000adf55be2c36cce5d73b6a38594fc232adeb","frame_index":0,"kind":"data","monotonic_ns":232636246770541,"payload":{"event_type":"price_change","market":"0x3b40066b5cf3871a2f6237c5628bd8092a206aa998558ac5ec13c4483e31e160","price_changes":[{"asset_id":"14766054693214075530629349735273995982307625376442606753688071083149620216746","best_ask":"0.28","best_bid":"0.27","hash":"192bf963731acc7abe549be67ae057040076ef6a","price":"0.01","side":"BUY","size":"5633.02"},{"asset_id":"110216635572655435074987471276357323571387854733835379371586402147734167783946","best_ask":"0.73","best_bid":"0.72","hash":"10687abf59fe5729d1ea43350c2fb05c0b905cd6","price":"0.99","side":"SELL","size":"5633.02"}],"timestamp":"1785130653034"},"payload_hash":"aa2d42aefb18c19ac8cc7749911a8798eb6148ee9ebdfe5803805993b55b76d6","raw_frame":"{\"market\":\"0x3b40066b5cf3871a2f6237c5628bd8092a206aa998558ac5ec13c4483e31e160\", \"price_changes\":[{\"asset_id\":\"14766054693214075530629349735273995982307625376442606753688071083149620216746\", \"price\":\"0.01\", \"size\":\"5633.02\", \"side\":\"BUY\", \"hash\":\"192bf963731acc7abe549be67ae057040076ef6a\", \"best_bid\":\"0.27\", \"best_ask\":\"0.28\"}, {\"asset_id\":\"110216635572655435074987471276357323571387854733835379371586402147734167783946\", \"price\":\"0.99\", \"size\":\"5633.02\", \"side\":\"SELL\", \"hash\":\"10687abf59fe5729d1ea43350c2fb05c0b905cd6\", \"best_bid\":\"0.72\", \"best_ask\":\"0.73\"}], \"timestamp\":\"1785130653034\", \"event_type\":\"price_change\"}","received_at":"2026-07-27T05:37:33.011709Z","schema_version":"clob-market-ws.price_change.v1","sequence":null,"server_hash":null,"server_timestamp":"1785130653034","session_id":"502006c5cfcd437296561ea750c9ec8b","source":"clob_market_ws"},"received_at":"2026-07-27T05:37:33.011709Z","record_id":"91071080ff95e8b721a7e7e16d52762c64e41e978e514b60c04700b27c1ba6a9","schema_fingerprint":"4aa3821a28b0b7c2400bc59aba4bcc0a76e971dadd19610d3ad38c768e124dc7","schema_version":"edge-lab-recorder.raw.v1","sequence":null,"source":"clob_market_ws"}
{"event_at":"2026-07-27T05:37:33.061000Z","event_fingerprint":"b9e2082853896359570375a4ab2624f0b220f50ec72a04317e31f98e4c98ca64","payload":{"connection_id":"efc69d3132f1467b8e898a382b23ac0d","event_at":"2026-07-27T05:37:33.061000Z","event_type":"price_change","frame_hash":"08c884249755f592309118d46cfed04e5d341a6a01aec5f7946a5e7cba6e51ec","frame_index":0,"kind":"data","monotonic_ns":232636254869166,"payload":{"event_type":"price_change","market":"0x3b40066b5cf3871a2f6237c5628bd8092a206aa998558ac5ec13c4483e31e160","price_changes":[{"asset_id":"110216635572655435074987471276357323571387854733835379371586402147734167783946","best_ask":"0.73","best_bid":"0.72","hash":"8e605eb1303d7e5f88f0efa5755ddea16e4f381a","price":"0.01","side":"BUY","size":"5612.45"},{"asset_id":"14766054693214075530629349735273995982307625376442606753688071083149620216746","best_ask":"0.28","best_bid":"0.27","hash":"c6b889d4bdbc07375d63212e7ea33ee895dac010","price":"0.99","side":"SELL","size":"5612.45"}],"timestamp":"1785130653061"},"payload_hash":"ccc4b5b212d74450eba9226598e91fdf95809d5a07beaab42e78d47dbc268a93","raw_frame":"{\"market\":\"0x3b40066b5cf3871a2f6237c5628bd8092a206aa998558ac5ec13c4483e31e160\", \"price_changes\":[{\"asset_id\":\"110216635572655435074987471276357323571387854733835379371586402147734167783946\", \"price\":\"0.01\", \"size\":\"5612.45\", \"side\":\"BUY\", \"hash\":\"8e605eb1303d7e5f88f0efa5755ddea16e4f381a\", \"best_bid\":\"0.72\", \"best_ask\":\"0.73\"}, {\"asset_id\":\"14766054693214075530629349735273995982307625376442606753688071083149620216746\", \"price\":\"0.99\", \"size\":\"5612.45\", \"side\":\"SELL\", \"hash\":\"c6b889d4bdbc07375d63212e7ea33ee895dac010\", \"best_bid\":\"0.27\", \"best_ask\":\"0.28\"}], \"timestamp\":\"1785130653061\", \"event_type\":\"price_change\"}","received_at":"2026-07-27T05:37:33.019801Z","schema_version":"clob-market-ws.price_change.v1","sequence":null,"server_hash":null,"server_timestamp":"1785130653061","session_id":"502006c5cfcd437296561ea750c9ec8b","source":"clob_market_ws"},"received_at":"2026-07-27T05:37:33.019801Z","record_id":"cd0ce96bc4c59c753856dd7214dd63853e63b2a823e7907453d9054b236db346","schema_fingerprint":"4aa3821a28b0b7c2400bc59aba4bcc0a76e971dadd19610d3ad38c768e124dc7","schema_version":"edge-lab-recorder.raw.v1","sequence":null,"source":"clob_market_ws"}
{"event_at":"2026-07-27T05:37:33.063000Z","event_fingerprint":"5cb96c7e6796b6865b951e5b35911a36841a9df88a308fa55214a3efc415290c","payload":{"connection_id":"efc69d3132f1467b8e898a382b23ac0d","event_at":"2026-07-27T05:37:33.063000Z","event_type":"price_change","frame_hash":"0d356dfd73714fcc5c91bebebdda214ea96808e7bc63f19110220b747a5f033b","frame_index":0,"kind":"data","monotonic_ns":232636259698500,"payload":{"event_type":"price_change","market":"0x3b40066b5cf3871a2f6237c5628bd8092a206aa998558ac5ec13c4483e31e160","price_changes":[{"asset_id":"14766054693214075530629349735273995982307625376442606753688071083149620216746","best_ask":"0.28","best_bid":"0.27","hash":"24e73005b62376c8f9434f53184e3aee7ee57c91","price":"0.01","side":"BUY","size":"5628.02"},{"asset_id":"110216635572655435074987471276357323571387854733835379371586402147734167783946","best_ask":"0.73","best_bid":"0.72","hash":"e950483400980dddd6ad08e2afb4e200e8f8ea65","price":"0.99","side":"SELL","size":"5628.02"}],"timestamp":"1785130653063"},"payload_hash":"6c306cdf9ddc6d209af649769af0c06be4bb1633b0a5427e7314b3b70f58dc96","raw_frame":"{\"market\":\"0x3b40066b5cf3871a2f6237c5628bd8092a206aa998558ac5ec13c4483e31e160\", \"price_changes\":[{\"asset_id\":\"14766054693214075530629349735273995982307625376442606753688071083149620216746\", \"price\":\"0.01\", \"size\":\"5628.02\", \"side\":\"BUY\", \"hash\":\"24e73005b62376c8f9434f53184e3aee7ee57c91\", \"best_bid\":\"0.27\", \"best_ask\":\"0.28\"}, {\"asset_id\":\"110216635572655435074987471276357323571387854733835379371586402147734167783946\", \"price\":\"0.99\", \"size\":\"5628.02\", \"side\":\"SELL\", \"hash\":\"e950483400980dddd6ad08e2afb4e200e8f8ea65\", \"best_bid\":\"0.72\", \"best_ask\":\"0.73\"}], \"timestamp\":\"1785130653063\", \"event_type\":\"price_change\"}","received_at":"2026-07-27T05:37:33.024636Z","schema_version":"clob-market-ws.price_change.v1","sequence":null,"server_hash":null,"server_timestamp":"1785130653063","session_id":"502006c5cfcd437296561ea750c9ec8b","source":"clob_market_ws"},"received_at":"2026-07-27T05:37:33.024636Z","record_id":"557b5a638ac48de51c5bdf648596bd508469a9cc8255f864cd6d72deff6688f9","schema_fingerprint":"4aa3821a28b0b7c2400bc59aba4bcc0a76e971dadd19610d3ad38c768e124dc7","schema_version":"edge-lab-recorder.raw.v1","sequence":null,"source":"clob_market_ws"}
{"event_at":"2026-07-27T05:37:33.079000Z","event_fingerprint":"5fb3ec53d31194948c815457e4dae440d50b03779fefac4adda4f6ef259c2432","payload":{"connection_id":"efc69d3132f1467b8e898a382b23ac0d","event_at":"2026-07-27T05:37:33.079000Z","event_type":"price_change","frame_hash":"c0e3928d8e81a3c4c4d7255fd2aea4ee172b08c61aa36c464123d2b83ebe49ae","frame_index":0,"kind":"data","monotonic_ns":232636273968500,"payload":{"event_type":"price_change","market":"0x3b40066b5cf3871a2f6237c5628bd8092a206aa998558ac5ec13c4483e31e160","price_changes":[{"asset_id":"110216635572655435074987471276357323571387854733835379371586402147734167783946","best_ask":"0.73","best_bid":"0.72","hash":"33e8f7ce883fec61c58ea558114cc3df84d24ea7","price":"0.68","side":"BUY","size":"136.37"},{"asset_id":"14766054693214075530629349735273995982307625376442606753688071083149620216746","best_ask":"0.28","best_bid":"0.27","hash":"280881853daf8d4d559131794cc3923ed3e7ad94","price":"0.32","side":"SELL","size":"136.37"}],"timestamp":"1785130653079"},"payload_hash":"619ce2d4826fee0d1f95604992ad41b96d2f12758077bb2dd140bd52ede7d70c","raw_frame":"{\"market\":\"0x3b40066b5cf3871a2f6237c5628bd8092a206aa998558ac5ec13c4483e31e160\", \"price_changes\":[{\"asset_id\":\"110216635572655435074987471276357323571387854733835379371586402147734167783946\", \"price\":\"0.68\", \"size\":\"136.37\", \"side\":\"BUY\", \"hash\":\"33e8f7ce883fec61c58ea558114cc3df84d24ea7\", \"best_bid\":\"0.72\", \"best_ask\":\"0.73\"}, {\"asset_id\":\"14766054693214075530629349735273995982307625376442606753688071083149620216746\", \"price\":\"0.32\", \"size\":\"136.37\", \"side\":\"SELL\", \"hash\":\"280881853daf8d4d559131794cc3923ed3e7ad94\", \"best_bid\":\"0.27\", \"best_ask\":\"0.28\"}], \"timestamp\":\"1785130653079\", \"event_type\":\"price_change\"}","received_at":"2026-07-27T05:37:33.038903Z","schema_version":"clob-market-ws.price_change.v1","sequence":null,"server_hash":null,"server_timestamp":"1785130653079","session_id":"502006c5cfcd437296561ea750c9ec8b","source":"clob_market_ws"},"received_at":"2026-07-27T05:37:33.038903Z","record_id":"2ed257e869155f4e0dfa39bd1f2169fe30253866936d90b37bb7eb52fafc8d85","schema_fingerprint":"4aa3821a28b0b7c2400bc59aba4bcc0a76e971dadd19610d3ad38c768e124dc7","schema_version":"edge-lab-recorder.raw.v1","sequence":null,"source":"clob_market_ws"}
{"event_at":"2026-07-27T05:37:33.087000Z","event_fingerprint":"44f04db8f8715ed1b7d775b648bdc9c355d616ed25a209c2bb9e4a89817e6bed","payload":{"connection_id":"efc69d3132f1467b8e898a382b23ac0d","event_at":"2026-07-27T05:37:33.087000Z","event_type":"price_change","frame_hash":"c97bfdf846c431bbc97db3caf65ae82f61f7c51e363d823b69ebc2c965fc21e4","frame_index":0,"kind":"data","monotonic_ns":232636281495500,"payload":{"event_type":"price_change","market":"0x3b40066b5cf3871a2f6237c5628bd8092a206aa998558ac5ec13c4483e31e160","price_changes":[{"asset_id":"110216635572655435074987471276357323571387854733835379371586402147734167783946","best_ask":"0.73","best_bid":"0.72","hash":"78df028a80e04963cf7660d7b8a17b595ffdba53","price":"0.68","side":"BUY","size":"166.37"},{"asset_id":"14766054693214075530629349735273995982307625376442606753688071083149620216746","best_ask":"0.28","best_bid":"0.27","hash":"0544428131f7164ac0451f2d7b8cdba15198eef6","price":"0.32","side":"SELL","size":"166.37"}],"timestamp":"1785130653087"},"payload_hash":"dec557a17bf588be9c33186dddfcc3b922de1512096599921b0c58edd508e6e4","raw_frame":"{\"market\":\"0x3b40066b5cf3871a2f6237c5628bd8092a206aa998558ac5ec13c4483e31e160\", \"price_changes\":[{\"asset_id\":\"110216635572655435074987471276357323571387854733835379371586402147734167783946\", \"price\":\"0.68\", \"size\":\"166.37\", \"side\":\"BUY\", \"hash\":\"78df028a80e04963cf7660d7b8a17b595ffdba53\", \"best_bid\":\"0.72\", \"best_ask\":\"0.73\"}, {\"asset_id\":\"14766054693214075530629349735273995982307625376442606753688071083149620216746\", \"price\":\"0.32\", \"size\":\"166.37\", \"side\":\"SELL\", \"hash\":\"0544428131f7164ac0451f2d7b8cdba15198eef6\", \"best_bid\":\"0.27\", \"best_ask\":\"0.28\"}], \"timestamp\":\"1785130653087\", \"event_type\":\"price_change\"}","received_at":"2026-07-27T05:37:33.046432Z","schema_version":"clob-market-ws.price_change.v1","sequence":null,"server_hash":null,"server_timestamp":"1785130653087","session_id":"502006c5cfcd437296561ea750c9ec8b","source":"clob_market_ws"},"received_at":"2026-07-27T05:37:33.046432Z","record_id":"4a204f76eea9e8e26ebff4862448b87bcb87dc84a8b047010d2de83624b4ad88","schema_fingerprint":"4aa3821a28b0b7c2400bc59aba4bcc0a76e971dadd19610d3ad38c768e124dc7","schema_version":"edge-lab-recorder.raw.v1","sequence":null,"source":"clob_market_ws"}
{"event_at":"2026-07-27T05:37:33.159000Z","event_fingerprint":"4d01157f724f0b833041ad2c4ca229b8b05dc6af1d13ef7becf99c1f75f7b396","payload":{"connection_id":"efc69d3132f1467b8e898a382b23ac0d","event_at":"2026-07-27T05:37:33.159000Z","event_type":"price_change","frame_hash":"8aec46c0039599c5faff525fa106c5da539bd817af1ecbc9bd5e3b88a03e9c67","frame_index":0,"kind":"data","monotonic_ns":232636353786458,"payload":{"event_type":"price_change","market":"0x3b40066b5cf3871a2f6237c5628bd8092a206aa998558ac5ec13c4483e31e160","price_changes":[{"asset_id":"110216635572655435074987471276357323571387854733835379371586402147734167783946","best_ask":"0.73","best_bid":"0.72","hash":"75d1e0c0ce138196abd329be69215a883edec7ee","price":"0.01","side":"BUY","size":"5617.45"},{"asset_id":"14766054693214075530629349735273995982307625376442606753688071083149620216746","best_ask":"0.28","best_bid":"0.27","hash":"6aebb7c6d81e7c7ff867ed28f86bc672473ebba8","price":"0.99","side":"SELL","size":"5617.45"}],"timestamp":"1785130653159"},"payload_hash":"f9c206e7c26371894d2c7669814eb011b56342cc0e9affd9dde5128d13cafac2","raw_frame":"{\"market\":\"0x3b40066b5cf3871a2f6237c5628bd8092a206aa998558ac5ec13c4483e31e160\", \"price_changes\":[{\"asset_id\":\"110216635572655435074987471276357323571387854733835379371586402147734167783946\", \"price\":\"0.01\", \"size\":\"5617.45\", \"side\":\"BUY\", \"hash\":\"75d1e0c0ce138196abd329be69215a883edec7ee\", \"best_bid\":\"0.72\", \"best_ask\":\"0.73\"}, {\"asset_id\":\"14766054693214075530629349735273995982307625376442606753688071083149620216746\", \"price\":\"0.99\", \"size\":\"5617.45\", \"side\":\"SELL\", \"hash\":\"6aebb7c6d81e7c7ff867ed28f86bc672473ebba8\", \"best_bid\":\"0.27\", \"best_ask\":\"0.28\"}], \"timestamp\":\"1785130653159\", \"event_type\":\"price_change\"}","received_at":"2026-07-27T05:37:33.118722Z","schema_version":"clob-market-ws.price_change.v1","sequence":null,"server_hash":null,"server_timestamp":"1785130653159","session_id":"502006c5cfcd437296561ea750c9ec8b","source":"clob_market_ws"},"received_at":"2026-07-27T05:37:33.118722Z","record_id":"74ee0ffe58fe3f4957635524d7146e016b9a7e3f62c6c46e9dfc70237ae492ca","schema_fingerprint":"4aa3821a28b0b7c2400bc59aba4bcc0a76e971dadd19610d3ad38c768e124dc7","schema_version":"edge-lab-recorder.raw.v1","sequence":null,"source":"clob_market_ws"}
{"event_at":"2026-07-27T05:37:33.167000Z","event_fingerprint":"dfd8b2eb4a00e32388a6a70b3201a7f7bcf9cbf645bde725bdb4b7c9a8b6092a","payload":{"connection_id":"efc69d3132f1467b8e898a382b23ac0d","event_at":"2026-07-27T05:37:33.167000Z","event_type":"price_change","frame_hash":"596974c3c13ddadcd2c02108e3bcd247702d30c6043b17313e02db2032d6be3d","frame_index":0,"kind":"data","monotonic_ns":232636362105583,"payload":{"event_type":"price_change","market":"0x3b40066b5cf3871a2f6237c5628bd8092a206aa998558ac5ec13c4483e31e160","price_changes":[{"asset_id":"110216635572655435074987471276357323571387854733835379371586402147734167783946","best_ask":"0.73","best_bid":"0.72","hash":"ecf439c42b54af2b7de18d85116a533824ceb241","price":"0.7","side":"BUY","size":"45.06"},{"asset_id":"14766054693214075530629349735273995982307625376442606753688071083149620216746","best_ask":"0.28","best_bid":"0.27","hash":"e90b4195b18ae09125d1a57e8b38783918bf739c","price":"0.3","side":"SELL","size":"45.06"}],"timestamp":"1785130653167"},"payload_hash":"20790b6f21e71ebf83cbee326bfaf4d8dc1f58f09a77a417e03ff08476e31f1c","raw_frame":"{\"market\":\"0x3b40066b5cf3871a2f6237c5628bd8092a206aa998558ac5ec13c4483e31e160\", \"price_changes\":[{\"asset_id\":\"110216635572655435074987471276357323571387854733835379371586402147734167783946\", \"price\":\"0.7\", \"size\":\"45.06\", \"side\":\"BUY\", \"hash\":\"ecf439c42b54af2b7de18d85116a533824ceb241\", \"best_bid\":\"0.72\", \"best_ask\":\"0.73\"}, {\"asset_id\":\"14766054693214075530629349735273995982307625376442606753688071083149620216746\", \"price\":\"0.3\", \"size\":\"45.06\", \"side\":\"SELL\", \"hash\":\"e90b4195b18ae09125d1a57e8b38783918bf739c\", \"best_bid\":\"0.27\", \"best_ask\":\"0.28\"}], \"timestamp\":\"1785130653167\", \"event_type\":\"price_change\"}","received_at":"2026-07-27T05:37:33.127035Z","schema_version":"clob-market-ws.price_change.v1","sequence":null,"server_hash":null,"server_timestamp":"1785130653167","session_id":"502006c5cfcd437296561ea750c9ec8b","source":"clob_market_ws"},"received_at":"2026-07-27T05:37:33.127035Z","record_id":"72b2d3b987aaf30528f73e0333e3fdb1fea8199844d45ec2903f8e652def02d1","schema_fingerprint":"4aa3821a28b0b7c2400bc59aba4bcc0a76e971dadd19610d3ad38c768e124dc7","schema_version":"edge-lab-recorder.raw.v1","sequence":null,"source":"clob_market_ws"}
{"event_at":"2026-07-27T05:37:33.173000Z","event_fingerprint":"d4255e5cb45abc87fd68157b9f27dc79c8ab3f654768c9994ee6845dc6b99312","payload":{"connection_id":"efc69d3132f1467b8e898a382b23ac0d","event_at":"2026-07-27T05:37:33.173000Z","event_type":"price_change","frame_hash":"af3e20b637b745bdf82d3b8680e49d1051b2df2c2dbefa2d5ceb4bbdc5248e07","frame_index":0,"kind":"data","monotonic_ns":232636366838083,"payload":{"event_type":"price_change","market":"0x3b40066b5cf3871a2f6237c5628bd8092a206aa998558ac5ec13c4483e31e160","price_changes":[{"asset_id":"14766054693214075530629349735273995982307625376442606753688071083149620216746","best_ask":"0.28","best_bid":"0.27","hash":"1149acb3a93a274cc3fe8be742b3569816cc9175","price":"0.3","side":"SELL","size":"72"},{"asset_id":"110216635572655435074987471276357323571387854733835379371586402147734167783946","best_ask":"0.73","best_bid":"0.72","hash":"820f474cce03024bea592621f62152e195fd5adc","price":"0.7","side":"BUY","size":"72"}],"timestamp":"1785130653173"},"payload_hash":"1fe1c992faa68d5bc7d9071f05f9707d1081edfd2dde6312e793cd513e37d7ab","raw_frame":"{\"market\":\"0x3b40066b5cf3871a2f6237c5628bd8092a206aa998558ac5ec13c4483e31e160\", \"price_changes\":[{\"asset_id\":\"14766054693214075530629349735273995982307625376442606753688071083149620216746\", \"price\":\"0.3\", \"size\":\"72\", \"side\":\"SELL\", \"hash\":\"1149acb3a93a274cc3fe8be742b3569816cc9175\", \"best_bid\":\"0.27\", \"best_ask\":\"0.28\"}, {\"asset_id\":\"110216635572655435074987471276357323571387854733835379371586402147734167783946\", \"price\":\"0.7\", \"size\":\"72\", \"side\":\"BUY\", \"hash\":\"820f474cce03024bea592621f62152e195fd5adc\", \"best_bid\":\"0.72\", \"best_ask\":\"0.73\"}], \"timestamp\":\"1785130653173\", \"event_type\":\"price_change\"}","received_at":"2026-07-27T05:37:33.131772Z","schema_version":"clob-market-ws.price_change.v1","sequence":null,"server_hash":null,"server_timestamp":"1785130653173","session_id":"502006c5cfcd437296561ea750c9ec8b","source":"clob_market_ws"},"received_at":"2026-07-27T05:37:33.131772Z","record_id":"7900f8ef38852dcc6ca482282242046d7f84fae83eacfc7efa23946995826cd3","schema_fingerprint":"4aa3821a28b0b7c2400bc59aba4bcc0a76e971dadd19610d3ad38c768e124dc7","schema_version":"edge-lab-recorder.raw.v1","sequence":null,"source":"clob_market_ws"}
{"event_at":"2026-07-27T05:37:33.174000Z","event_fingerprint":"fb676a496b11e949937fc3fe15cec13f9fe637da174495af1755b56da637bac2","payload":{"connection_id":"efc69d3132f1467b8e898a382b23ac0d","event_at":"2026-07-27T05:37:33.174000Z","event_type":"price_change","frame_hash":"f3258760b74072db4580e0f86646be11f8a332f91d6cef96b19d16407ab508eb","frame_index":0,"kind":"data","monotonic_ns":232636368708250,"payload":{"event_type":"price_change","market":"0x3b40066b5cf3871a2f6237c5628bd8092a206aa998558ac5ec13c4483e31e160","price_changes":[{"asset_id":"14766054693214075530629349735273995982307625376442606753688071083149620216746","best_ask":"0.28","best_bid":"0.27","hash":"059815677585e3a21294f413279658fde0c8c869","price":"0.31","side":"SELL","size":"141.53"},{"asset_id":"110216635572655435074987471276357323571387854733835379371586402147734167783946","best_ask":"0.73","best_bid":"0.72","hash":"d5b9c1c1328cea941550998a60bf8a5edcdcf9b7","price":"0.69","side":"BUY","size":"141.53"}],"timestamp":"1785130653174"},"payload_hash":"35819605bf75104402d58871f327f552d8810b38576812b4aa233b4f38eabdd1","raw_frame":"{\"market\":\"0x3b40066b5cf3871a2f6237c5628bd8092a206aa998558ac5ec13c4483e31e160\", \"price_changes\":[{\"asset_id\":\"14766054693214075530629349735273995982307625376442606753688071083149620216746\", \"price\":\"0.31\", \"size\":\"141.53\", \"side\":\"SELL\", \"hash\":\"059815677585e3a21294f413279658fde0c8c869\", \"best_bid\":\"0.27\", \"best_ask\":\"0.28\"}, {\"asset_id\":\"110216635572655435074987471276357323571387854733835379371586402147734167783946\", \"price\":\"0.69\", \"size\":\"141.53\", \"side\":\"BUY\", \"hash\":\"d5b9c1c1328cea941550998a60bf8a5edcdcf9b7\", \"best_bid\":\"0.72\", \"best_ask\":\"0.73\"}], \"timestamp\":\"1785130653174\", \"event_type\":\"price_change\"}","received_at":"2026-07-27T05:37:33.133645Z","schema_version":"clob-market-ws.price_change.v1","sequence":null,"server_hash":null,"server_timestamp":"1785130653174","session_id":"502006c5cfcd437296561ea750c9ec8b","source":"clob_market_ws"},"received_at":"2026-07-27T05:37:33.133645Z","record_id":"eeff10730cd8a7bb51fd068d4bc5a3a473b1306d669fddb311a42c85de5185d2","schema_fingerprint":"4aa3821a28b0b7c2400bc59aba4bcc0a76e971dadd19610d3ad38c768e124dc7","schema_version":"edge-lab-recorder.raw.v1","sequence":null,"source":"clob_market_ws"}
{"event_at":"2026-07-27T05:37:33.186000Z","event_fingerprint":"2ab93f536b4fd4443e4035538d4b61646b1046a645a8195f08b63633cd81bfeb","payload":{"connection_id":"efc69d3132f1467b8e898a382b23ac0d","event_at":"2026-07-27T05:37:33.186000Z","event_type":"price_change","frame_hash":"929f01201c1a05d6cc6b72d4b0f696069bc444c0c0a3ed84f7dca27862efe8b5","frame_index":0,"kind":"data","monotonic_ns":232636380617041,"payload":{"event_type":"price_change","market":"0x3b40066b5cf3871a2f6237c5628bd8092a206aa998558ac5ec13c4483e31e160","price_changes":[{"asset_id":"14766054693214075530629349735273995982307625376442606753688071083149620216746","best_ask":"0.28","best_bid":"0.27","hash":"8c963b0c95d1940ce6c4d06a3589022982335cc9","price":"0.01","side":"BUY","size":"5623.02"},{"asset_id":"110216635572655435074987471276357323571387854733835379371586402147734167783946","best_ask":"0.73","best_bid":"0.72","hash":"e77021ea1cd5cf0c8c071a91769e79cd3a6b4d5f","price":"0.99","side":"SELL","size":"5623.02"}],"timestamp":"1785130653186"},"payload_hash":"88faf9a2f05183f67d8d065617d29319ca2334b174c7f644a2504651d4a22c2e","raw_frame":"{\"market\":\"0x3b40066b5cf3871a2f6237c5628bd8092a206aa998558ac5ec13c4483e31e160\", \"price_changes\":[{\"asset_id\":\"14766054693214075530629349735273995982307625376442606753688071083149620216746\", \"price\":\"0.01\", \"size\":\"5623.02\", \"side\":\"BUY\", \"hash\":\"8c963b0c95d1940ce6c4d06a3589022982335cc9\", \"best_bid\":\"0.27\", \"best_ask\":\"0.28\"}, {\"asset_id\":\"110216635572655435074987471276357323571387854733835379371586402147734167783946\", \"price\":\"0.99\", \"size\":\"5623.02\", \"side\":\"SELL\", \"hash\":\"e77021ea1cd5cf0c8c071a91769e79cd3a6b4d5f\", \"best_bid\":\"0.72\", \"best_ask\":\"0.73\"}], \"timestamp\":\"1785130653186\", \"event_type\":\"price_change\"}","received_at":"2026-07-27T05:37:33.145554Z","schema_version":"clob-market-ws.price_change.v1","sequence":null,"server_hash":null,"server_timestamp":"1785130653186","session_id":"502006c5cfcd437296561ea750c9ec8b","source":"clob_market_ws"},"received_at":"2026-07-27T05:37:33.145554Z","record_id":"4762ab607db83752f036e6faace1a1a2cd39b4caf5cb62b72147a0952b53b87d","schema_fingerprint":"4aa3821a28b0b7c2400bc59aba4bcc0a76e971dadd19610d3ad38c768e124dc7","schema_version":"edge-lab-recorder.raw.v1","sequence":null,"source":"clob_market_ws"}
{"event_at":"2026-07-27T05:37:33.218000Z","event_fingerprint":"63fd911c15ae324ed46f572538a6b9fa2c90c880207725c801659afdf93267f4","payload":{"connection_id":"efc69d3132f1467b8e898a382b23ac0d","event_at":"2026-07-27T05:37:33.218000Z","event_type":"price_change","frame_hash":"2658aec2f11c1ee39e411e0a774758037313fbff8f543b970b2662874e281151","frame_index":0,"kind":"data","monotonic_ns":232636412480166,"payload":{"event_type":"price_change","market":"0x3b40066b5cf3871a2f6237c5628bd8092a206aa998558ac5ec13c4483e31e160","price_changes":[{"asset_id":"110216635572655435074987471276357323571387854733835379371586402147734167783946","best_ask":"0.73","best_bid":"0.72","hash":"419034eb17786b0099cf9daa77710b453296a57c","price":"0.01","side":"BUY","size":"5612.45"},{"asset_id":"14766054693214075530629349735273995982307625376442606753688071083149620216746","best_ask":"0.28","best_bid":"0.27","hash":"ca95e9124e5af9b8822828f3c740d15837a51e67","price":"0.99","side":"SELL","size":"5612.45"}],"timestamp":"1785130653218"},"payload_hash":"73db72bc6cf69a9cc5f64069d184ded37aecce342ea98fe7da4f15198ca91746","raw_frame":"{\"market\":\"0x3b40066b5cf3871a2f6237c5628bd8092a206aa998558ac5ec13c4483e31e160\", \"price_changes\":[{\"asset_id\":\"110216635572655435074987471276357323571387854733835379371586402147734167783946\", \"price\":\"0.01\", \"size\":\"5612.45\", \"side\":\"BUY\", \"hash\":\"419034eb17786b0099cf9daa77710b453296a57c\", \"best_bid\":\"0.72\", \"best_ask\":\"0.73\"}, {\"asset_id\":\"14766054693214075530629349735273995982307625376442606753688071083149620216746\", \"price\":\"0.99\", \"size\":\"5612.45\", \"side\":\"SELL\", \"hash\":\"ca95e9124e5af9b8822828f3c740d15837a51e67\", \"best_bid\":\"0.27\", \"best_ask\":\"0.28\"}], \"timestamp\":\"1785130653218\", \"event_type\":\"price_change\"}","received_at":"2026-07-27T05:37:33.177418Z","schema_version":"clob-market-ws.price_change.v1","sequence":null,"server_hash":null,"server_timestamp":"1785130653218","session_id":"502006c5cfcd437296561ea750c9ec8b","source":"clob_market_ws"},"received_at":"2026-07-27T05:37:33.177418Z","record_id":"2e0e3843467d4ed2684036978cf7ae2287894fab94e0875595404a318dd1b76a","schema_fingerprint":"4aa3821a28b0b7c2400bc59aba4bcc0a76e971dadd19610d3ad38c768e124dc7","schema_version":"edge-lab-recorder.raw.v1","sequence":null,"source":"clob_market_ws"}
{"event_at":"2026-07-27T05:37:33.253000Z","event_fingerprint":"abf8ce66979fa2516989b81586e8c23e487a161666080f4e7e868b33448c22e3","payload":{"connection_id":"efc69d3132f1467b8e898a382b23ac0d","event_at":"2026-07-27T05:37:33.253000Z","event_type":"price_change","frame_hash":"ab0b0fab846a2c3db58ae3404819a79199f979d67b51dac5a984104c64f6c734","frame_index":0,"kind":"data","monotonic_ns":232636446771333,"payload":{"event_type":"price_change","market":"0x3b40066b5cf3871a2f6237c5628bd8092a206aa998558ac5ec13c4483e31e160","price_changes":[{"asset_id":"110216635572655435074987471276357323571387854733835379371586402147734167783946","best_ask":"0.73","best_bid":"0.72","hash":"260854ea110de4a8fec8d29c4fa6b91a95701b19","price":"0.01","side":"BUY","size":"5617.45"},{"asset_id":"14766054693214075530629349735273995982307625376442606753688071083149620216746","best_ask":"0.28","best_bid":"0.27","hash":"13a2ca7c88d1e4ae65c45476c8c77d1edbdc9faa","price":"0.99","side":"SELL","size":"5617.45"}],"timestamp":"1785130653253"},"payload_hash":"c5fd758080bc2801ded65e438c3de8c903f6ac964f9490063150b8093d375256","raw_frame":"{\"market\":\"0x3b40066b5cf3871a2f6237c5628bd8092a206aa998558ac5ec13c4483e31e160\", \"price_changes\":[{\"asset_id\":\"110216635572655435074987471276357323571387854733835379371586402147734167783946\", \"price\":\"0.01\", \"size\":\"5617.45\", \"side\":\"BUY\", \"hash\":\"260854ea110de4a8fec8d29c4fa6b91a95701b19\", \"best_bid\":\"0.72\", \"best_ask\":\"0.73\"}, {\"asset_id\":\"14766054693214075530629349735273995982307625376442606753688071083149620216746\", \"price\":\"0.99\", \"size\":\"5617.45\", \"side\":\"SELL\", \"hash\":\"13a2ca7c88d1e4ae65c45476c8c77d1edbdc9faa\", \"best_bid\":\"0.27\", \"best_ask\":\"0.28\"}], \"timestamp\":\"1785130653253\", \"event_type\":\"price_change\"}","received_at":"2026-07-27T05:37:33.211709Z","schema_version":"clob-market-ws.price_change.v1","sequence":null,"server_hash":null,"server_timestamp":"1785130653253","session_id":"502006c5cfcd437296561ea750c9ec8b","source":"clob_market_ws"},"received_at":"2026-07-27T05:37:33.211709Z","record_id":"88640fefefe28ab7a561d755cce8f394bb6fadcc98ba821630ca7e2c46f80728","schema_fingerprint":"4aa3821a28b0b7c2400bc59aba4bcc0a76e971dadd19610d3ad38c768e124dc7","schema_version":"edge-lab-recorder.raw.v1","sequence":null,"source":"clob_market_ws"}
{"event_at":"2026-07-27T05:37:33.273000Z","event_fingerprint":"8d7bfabc3942ebb2a89c6123e8a7dad0a07472f825e27790eb19976ec276f974","payload":{"connection_id":"efc69d3132f1467b8e898a382b23ac0d","event_at":"2026-07-27T05:37:33.273000Z","event_type":"price_change","frame_hash":"4ece092ccd928efabefeb7232e5070af0266a07de20564b1fc00d53c59146a3e","frame_index":0,"kind":"data","monotonic_ns":232636466829875,"payload":{"event_type":"price_change","market":"0x3b40066b5cf3871a2f6237c5628bd8092a206aa998558ac5ec13c4483e31e160","price_changes":[{"asset_id":"110216635572655435074987471276357323571387854733835379371586402147734167783946","best_ask":"0.73","best_bid":"0.72","hash":"9225d145f942ac51bd945baf1673e7cc78ea1340","price":"0.01","side":"BUY","size":"5612.45"},{"asset_id":"14766054693214075530629349735273995982307625376442606753688071083149620216746","best_ask":"0.28","best_bid":"0.27","hash":"7289242b2702bf24399c12d0c17e6f0226416864","price":"0.99","side":"SELL","size":"5612.45"}],"timestamp":"1785130653273"},"payload_hash":"14a62549c8ec83b772bb958d25a6b752283e323a9cd366d9ad087d4c9f974a68","raw_frame":"{\"market\":\"0x3b40066b5cf3871a2f6237c5628bd8092a206aa998558ac5ec13c4483e31e160\", \"price_changes\":[{\"asset_id\":\"110216635572655435074987471276357323571387854733835379371586402147734167783946\", \"price\":\"0.01\", \"size\":\"5612.45\", \"side\":\"BUY\", \"hash\":\"9225d145f942ac51bd945baf1673e7cc78ea1340\", \"best_bid\":\"0.72\", \"best_ask\":\"0.73\"}, {\"asset_id\":\"14766054693214075530629349735273995982307625376442606753688071083149620216746\", \"price\":\"0.99\", \"size\":\"5612.45\", \"side\":\"SELL\", \"hash\":\"7289242b2702bf24399c12d0c17e6f0226416864\", \"best_bid\":\"0.27\", \"best_ask\":\"0.28\"}], \"timestamp\":\"1785130653273\", \"event_type\":\"price_change\"}","received_at":"2026-07-27T05:37:33.231768Z","schema_version":"clob-market-ws.price_change.v1","sequence":null,"server_hash":null,"server_timestamp":"1785130653273","session_id":"502006c5cfcd437296561ea750c9ec8b","source":"clob_market_ws"},"received_at":"2026-07-27T05:37:33.231768Z","record_id":"859cdecb98cfe2204c143590a6578b92d95b5cb2c0d1f0b036ee387b2181d6b6","schema_fingerprint":"4aa3821a28b0b7c2400bc59aba4bcc0a76e971dadd19610d3ad38c768e124dc7","schema_version":"edge-lab-recorder.raw.v1","sequence":null,"source":"clob_market_ws"}
