{"event_at":"2026-07-27T05:36:03.234000Z","event_fingerprint":"82d91b0707c6cf0586367807385f47647eccfc9375ed65098c041a73ecf3b3ed","payload":{"connection_id":"efc69d3132f1467b8e898a382b23ac0d","event_at":"2026-07-27T05:36:03.234000Z","event_type":"price_change","frame_hash":"3bb1be16671a2d8eeef898c8ef5e5ecfd8b422f3b03aa97282ba8e261ad45d2d","frame_index":0,"kind":"data","monotonic_ns":232546526138625,"payload":{"event_type":"price_change","market":"0x3b40066b5cf3871a2f6237c5628bd8092a206aa998558ac5ec13c4483e31e160","price_changes":[{"asset_id":"110216635572655435074987471276357323571387854733835379371586402147734167783946","best_ask":"0.68","best_bid":"0.67","hash":"c98be7b084f21c82e07cdbe8cbd281a41873fb5d","price":"0.5","side":"BUY","size":"155"},{"asset_id":"14766054693214075530629349735273995982307625376442606753688071083149620216746","best_ask":"0.33","best_bid":"0.32","hash":"adbc845a4f59eb16b17664c05d7e99d7640da8af","price":"0.5","side":"SELL","size":"155"}],"timestamp":"1785130563234"},"payload_hash":"c215687d6633871ea7f97d2e259fd1f04da96c93329e58260b368405f96d2d4a","raw_frame":"{\"market\":\"0x3b40066b5cf3871a2f6237c5628bd8092a206aa998558ac5ec13c4483e31e160\", \"price_changes\":[{\"asset_id\":\"110216635572655435074987471276357323571387854733835379371586402147734167783946\", \"price\":\"0.5\", \"size\":\"155\", \"side\":\"BUY\", \"hash\":\"c98be7b084f21c82e07cdbe8cbd281a41873fb5d\", \"best_bid\":\"0.67\", \"best_ask\":\"0.68\"}, {\"asset_id\":\"14766054693214075530629349735273995982307625376442606753688071083149620216746\", \"price\":\"0.5\", \"size\":\"155\", \"side\":\"SELL\", \"hash\":\"adbc845a4f59eb16b17664c05d7e99d7640da8af\", \"best_bid\":\"0.32\", \"best_ask\":\"0.33\"}], \"timestamp\":\"1785130563234\", \"event_type\":\"price_change\"}","received_at":"2026-07-27T05:36:03.290453Z","schema_version":"clob-market-ws.price_change.v1","sequence":null,"server_hash":null,"server_timestamp":"1785130563234","session_id":"502006c5cfcd437296561ea750c9ec8b","source":"clob_market_ws"},"received_at":"2026-07-27T05:36:03.290453Z","record_id":"3176d72355299926dcf6f7027be7a9ffa8b90649984dbe8ecc7c8b5ce12619ca","schema_fingerprint":"4aa3821a28b0b7c2400bc59aba4bcc0a76e971dadd19610d3ad38c768e124dc7","schema_version":"edge-lab-recorder.raw.v1","sequence":null,"source":"clob_market_ws"}
{"event_at":"2026-07-27T05:36:03.261000Z","event_fingerprint":"963b2507856d59a108dbf894e85079621242c5783c09fd85137df0df78e945c2","payload":{"connection_id":"efc69d3132f1467b8e898a382b23ac0d","event_at":"2026-07-27T05:36:03.261000Z","event_type":"price_change","frame_hash":"7a56c251054fbd01e0f780ea559558de2b3f23fc0c1b05c4139c42d5acd48a85","frame_index":0,"kind":"data","monotonic_ns":232546535749458,"payload":{"event_type":"price_change","market":"0x3b40066b5cf3871a2f6237c5628bd8092a206aa998558ac5ec13c4483e31e160","price_changes":[{"asset_id":"110216635572655435074987471276357323571387854733835379371586402147734167783946","best_ask":"0.68","best_bid":"0.67","hash":"9608201e269fbd3afe011afb5de569ab3ff76da5","price":"0.66","side":"BUY","size":"61.66"},{"asset_id":"14766054693214075530629349735273995982307625376442606753688071083149620216746","best_ask":"0.33","best_bid":"0.32","hash":"fa36536edf9d4a7fce0fa1e0bac2acf0d58f35d0","price":"0.34","side":"SELL","size":"61.66"}],"timestamp":"1785130563261"},"payload_hash":"b4d8c1dba08071da116420db3f98dd2dfdba4e4b338305d2a667a1ebb374bda4","raw_frame":"{\"market\":\"0x3b40066b5cf3871a2f6237c5628bd8092a206aa998558ac5ec13c4483e31e160\", \"price_changes\":[{\"asset_id\":\"110216635572655435074987471276357323571387854733835379371586402147734167783946\", \"price\":\"0.66\", \"size\":\"61.66\", \"side\":\"BUY\", \"hash\":\"9608201e269fbd3afe011afb5de569ab3ff76da5\", \"best_bid\":\"0.67\", \"best_ask\":\"0.68\"}, {\"asset_id\":\"14766054693214075530629349735273995982307625376442606753688071083149620216746\", \"price\":\"0.34\", \"size\":\"61.66\", \"side\":\"SELL\", \"hash\":\"fa36536edf9d4a7fce0fa1e0bac2acf0d58f35d0\", \"best_bid\":\"0.32\", \"best_ask\":\"0.33\"}], \"timestamp\":\"1785130563261\", \"event_type\":\"price_change\"}","received_at":"2026-07-27T05:36:03.300059Z","schema_version":"clob-market-ws.price_change.v1","sequence":null,"server_hash":null,"server_timestamp":"1785130563261","session_id":"502006c5cfcd437296561ea750c9ec8b","source":"clob_market_ws"},"received_at":"2026-07-27T05:36:03.300059Z","record_id":"79870f5388b0336d220d7d60a7a5d9fb712b7e0502ecdec921c48fd58194bba8","schema_fingerprint":"4aa3821a28b0b7c2400bc59aba4bcc0a76e971dadd19610d3ad38c768e124dc7","schema_version":"edge-lab-recorder.raw.v1","sequence":null,"source":"clob_market_ws"}
{"event_at":"2026-07-27T05:36:03.268000Z","event_fingerprint":"ab8cf41ac221138548cdac828eaa91595be06722c4dd1aaf33d6a230b358865a","payload":{"connection_id":"efc69d3132f1467b8e898a382b23ac0d","event_at":"2026-07-27T05:36:03.268000Z","event_type":"price_change","frame_hash":"485dcc6cb059556d7b74b4fbd61672c062ff086e182ff6546f240c5030ea1e63","frame_index":0,"kind":"data","monotonic_ns":232546541485625,"payload":{"event_type":"price_change","market":"0x3b40066b5cf3871a2f6237c5628bd8092a206aa998558ac5ec13c4483e31e160","price_changes":[{"asset_id":"14766054693214075530629349735273995982307625376442606753688071083149620216746","best_ask":"0.33","best_bid":"0.32","hash":"05d1da03cb204b397e333c384d6e42de0a7688aa","price":"0.25","side":"BUY","size":"300"},{"asset_id":"110216635572655435074987471276357323571387854733835379371586402147734167783946","best_ask":"0.68","best_bid":"0.67","hash":"859650319c17a8792d233e3255718bf3c4f777d4","price":"0.75","side":"SELL","size":"300"}],"timestamp":"1785130563268"},"payload_hash":"b647b95200d2e5bc0a8839a077447746f44a49069808d03bf5a74c7bcaee54ee","raw_frame":"{\"market\":\"0x3b40066b5cf3871a2f6237c5628bd8092a206aa998558ac5ec13c4483e31e160\", \"price_changes\":[{\"asset_id\":\"14766054693214075530629349735273995982307625376442606753688071083149620216746\", \"price\":\"0.25\", \"size\":\"300\", \"side\":\"BUY\", \"hash\":\"05d1da03cb204b397e333c384d6e42de0a7688aa\", \"best_bid\":\"0.32\", \"best_ask\":\"0.33\"}, {\"asset_id\":\"110216635572655435074987471276357323571387854733835379371586402147734167783946\", \"price\":\"0.75\", \"size\":\"300\", \"side\":\"SELL\", \"hash\":\"859650319c17a8792d233e3255718bf3c4f777d4\", \"best_bid\":\"0.67\", \"best_ask\":\"0.68\"}], \"timestamp\":\"1785130563268\", \"event_type\":\"price_change\"}","received_at":"2026-07-27T05:36:03.305792Z","schema_version":"clob-market-ws.price_change.v1","sequence":null,"server_hash":null,"server_timestamp":"1785130563268","session_id":"502006c5cfcd437296561ea750c9ec8b","source":"clob_market_ws"},"received_at":"2026-07-27T05:36:03.305792Z","record_id":"cf3975668ba4871f42bd0c992fc81e0c08a87f9db100e4994a61a763d6e6a792","schema_fingerprint":"4aa3821a28b0b7c2400bc59aba4bcc0a76e971dadd19610d3ad38c768e124dc7","schema_version":"edge-lab-recorder.raw.v1","sequence":null,"source":"clob_market_ws"}
{"event_at":"2026-07-27T05:36:03.271000Z","event_fingerprint":"7975450bd131bdddd3a9c674c283448d7a87e44f0eb89307f7d2a6603668272e","payload":{"connection_id":"efc69d3132f1467b8e898a382b23ac0d","event_at":"2026-07-27T05:36:03.271000Z","event_type":"price_change","frame_hash":"2aa40808e29fccc6029b700ef3c965a3a7e121992b6802e55c3c3ec760c00df0","frame_index":0,"kind":"data","monotonic_ns":232546546962708,"payload":{"event_type":"price_change","market":"0x3b40066b5cf3871a2f6237c5628bd8092a206aa998558ac5ec13c4483e31e160","price_changes":[{"asset_id":"14766054693214075530629349735273995982307625376442606753688071083149620216746","best_ask":"0.33","best_bid":"0.32","hash":"36c4f394522973d0c4d178ce28bed44cdde17867","price":"0.21","side":"BUY","size":"493.93"},{"asset_id":"110216635572655435074987471276357323571387854733835379371586402147734167783946","best_ask":"0.68","best_bid":"0.67","hash":"32344f1dc0395709a8e450ee39f7e92cf59f5a84","price":"0.79","side":"SELL","size":"493.93"}],"timestamp":"1785130563271"},"payload_hash":"a380a4e5b9c6aa0392e940bd7d8809981080b5a0cf788a90801718b1ec7824a7","raw_frame":"{\"market\":\"0x3b40066b5cf3871a2f6237c5628bd8092a206aa998558ac5ec13c4483e31e160\", \"price_changes\":[{\"asset_id\":\"14766054693214075530629349735273995982307625376442606753688071083149620216746\", \"price\":\"0.21\", \"size\":\"493.93\", \"side\":\"BUY\", \"hash\":\"36c4f394522973d0c4d178ce28bed44cdde17867\", \"best_bid\":\"0.32\", \"best_ask\":\"0.33\"}, {\"asset_id\":\"110216635572655435074987471276357323571387854733835379371586402147734167783946\", \"price\":\"0.79\", \"size\":\"493.93\", \"side\":\"SELL\", \"hash\":\"32344f1dc0395709a8e450ee39f7e92cf59f5a84\", \"best_bid\":\"0.67\", \"best_ask\":\"0.68\"}], \"timestamp\":\"1785130563271\", \"event_type\":\"price_change\"}","received_at":"2026-07-27T05:36:03.311278Z","schema_version":"clob-market-ws.price_change.v1","sequence":null,"server_hash":null,"server_timestamp":"1785130563271","session_id":"502006c5cfcd437296561ea750c9ec8b","source":"clob_market_ws"},"received_at":"2026-07-27T05:36:03.311278Z","record_id":"39d9a613c5bdf18937a9dcfe173e5881a7b4ed55c1ad43957e04c56b5be2545c","schema_fingerprint":"4aa3821a28b0b7c2400bc59aba4bcc0a76e971dadd19610d3ad38c768e124dc7","schema_version":"edge-lab-recorder.raw.v1","sequence":null,"source":"clob_market_ws"}
{"event_at":"2026-07-27T05:36:03.283000Z","event_fingerprint":"6bfca571b681c540f34cfefb811ae2fe272a21ffb61ed43408089a8f80359b81","payload":{"connection_id":"efc69d3132f1467b8e898a382b23ac0d","event_at":"2026-07-27T05:36:03.283000Z","event_type":"price_change","frame_hash":"324c11ac101cd6b0bf4f0ec1accfe99ed0bc2adb92298152843a453488694906","frame_index":0,"kind":"data","monotonic_ns":232546550119458,"payload":{"event_type":"price_change","market":"0x3b40066b5cf3871a2f6237c5628bd8092a206aa998558ac5ec13c4483e31e160","price_changes":[{"asset_id":"14766054693214075530629349735273995982307625376442606753688071083149620216746","best_ask":"0.33","best_bid":"0.32","hash":"2424f9c74c100bacc8b338792adf39003da0c87c","price":"0.34","side":"SELL","size":"83.6"},{"asset_id":"110216635572655435074987471276357323571387854733835379371586402147734167783946","best_ask":"0.68","best_bid":"0.67","hash":"1aa97844ad33fb834eb6e25ca54703e505971ec3","price":"0.66","side":"BUY","size":"83.6"}],"timestamp":"1785130563283"},"payload_hash":"2a361fab41adc70c71b715cf5fb714ac862135ec0d6f3155f51c7812ac9e4986","raw_frame":"{\"market\":\"0x3b40066b5cf3871a2f6237c5628bd8092a206aa998558ac5ec13c4483e31e160\", \"price_changes\":[{\"asset_id\":\"14766054693214075530629349735273995982307625376442606753688071083149620216746\", \"price\":\"0.34\", \"size\":\"83.6\", \"side\":\"SELL\", \"hash\":\"2424f9c74c100bacc8b338792adf39003da0c87c\", \"best_bid\":\"0.32\", \"best_ask\":\"0.33\"}, {\"asset_id\":\"110216635572655435074987471276357323571387854733835379371586402147734167783946\", \"price\":\"0.66\", \"size\":\"83.6\", \"side\":\"BUY\", \"hash\":\"1aa97844ad33fb834eb6e25ca54703e505971ec3\", \"best_bid\":\"0.67\", \"best_ask\":\"0.68\"}], \"timestamp\":\"1785130563283\", \"event_type\":\"price_change\"}","received_at":"2026-07-27T05:36:03.314440Z","schema_version":"clob-market-ws.price_change.v1","sequence":null,"server_hash":null,"server_timestamp":"1785130563283","session_id":"502006c5cfcd437296561ea750c9ec8b","source":"clob_market_ws"},"received_at":"2026-07-27T05:36:03.314440Z","record_id":"8f1f7e893d50573a92b18925e53e604767543724d53221df85bb81582f65830b","schema_fingerprint":"4aa3821a28b0b7c2400bc59aba4bcc0a76e971dadd19610d3ad38c768e124dc7","schema_version":"edge-lab-recorder.raw.v1","sequence":null,"source":"clob_market_ws"}
{"event_at":"2026-07-27T05:36:03.311000Z","event_fingerprint":"9338ae57c0424349b990e87fd40acbdc597eaff7aa6cf5c42744a15eb33e1aac","payload":{"connection_id":"efc69d3132f1467b8e898a382b23ac0d","event_at":"2026-07-27T05:36:03.311000Z","event_type":"price_change","frame_hash":"1b46c706f27589cc29dbd829b7419e6902e965cb23e46c6b9af09ed91a5c853f","frame_index":0,"kind":"data","monotonic_ns":232546553964250,"payload":{"event_type":"price_change","market":"0x3b40066b5cf3871a2f6237c5628bd8092a206aa998558ac5ec13c4483e31e160","price_changes":[{"asset_id":"14766054693214075530629349735273995982307625376442606753688071083149620216746","best_ask":"0.33","best_bid":"0.32","hash":"132b2d1847793c25ba8db731f6872c37ffd58b0b","price":"0.2","side":"BUY","size":"242.38"},{"asset_id":"110216635572655435074987471276357323571387854733835379371586402147734167783946","best_ask":"0.68","best_bid":"0.67","hash":"5244553574ddea06dc9dfd94da0a9edb9d1b2d5d","price":"0.8","side":"SELL","size":"242.38"}],"timestamp":"1785130563311"},"payload_hash":"460bad34a8eda805a7a98322568717371666d60e7080519eca652b2ce494829a","raw_frame":"{\"market\":\"0x3b40066b5cf3871a2f6237c5628bd8092a206aa998558ac5ec13c4483e31e160\", \"price_changes\":[{\"asset_id\":\"14766054693214075530629349735273995982307625376442606753688071083149620216746\", \"price\":\"0.2\", \"size\":\"242.38\", \"side\":\"BUY\", \"hash\":\"132b2d1847793c25ba8db731f6872c37ffd58b0b\", \"best_bid\":\"0.32\", \"best_ask\":\"0.33\"}, {\"asset_id\":\"110216635572655435074987471276357323571387854733835379371586402147734167783946\", \"price\":\"0.8\", \"size\":\"242.38\", \"side\":\"SELL\", \"hash\":\"5244553574ddea06dc9dfd94da0a9edb9d1b2d5d\", \"best_bid\":\"0.67\", \"best_ask\":\"0.68\"}], \"timestamp\":\"1785130563311\", \"event_type\":\"price_change\"}","received_at":"2026-07-27T05:36:03.318278Z","schema_version":"clob-market-ws.price_change.v1","sequence":null,"server_hash":null,"server_timestamp":"1785130563311","session_id":"502006c5cfcd437296561ea750c9ec8b","source":"clob_market_ws"},"received_at":"2026-07-27T05:36:03.318278Z","record_id":"e27a0e2479646c36bbc6122cb121e35df22c1f71588674c5e2d6d8be4f817025","schema_fingerprint":"4aa3821a28b0b7c2400bc59aba4bcc0a76e971dadd19610d3ad38c768e124dc7","schema_version":"edge-lab-recorder.raw.v1","sequence":null,"source":"clob_market_ws"}
{"event_at":"2026-07-27T05:36:03.334000Z","event_fingerprint":"9fcf282debbac0819ee6ef1e7a06ab1de055cf7d3fb976e8a34f3bc8d2e0d135","payload":{"connection_id":"efc69d3132f1467b8e898a382b23ac0d","event_at":"2026-07-27T05:36:03.334000Z","event_type":"price_change","frame_hash":"7d2bb6e2b2f45a8cd59f35b217707806cba1fea76ed52a5cd6dd6c959447bf05","frame_index":0,"kind":"data","monotonic_ns":232546558621083,"payload":{"event_type":"price_change","market":"0x3b40066b5cf3871a2f6237c5628bd8092a206aa998558ac5ec13c4483e31e160","price_changes":[{"asset_id":"110216635572655435074987471276357323571387854733835379371586402147734167783946","best_ask":"0.68","best_bid":"0.67","hash":"b1b050f56be49d39a2072311f4ced0a412a7f62d","price":"0.48","side":"BUY","size":"218.88"},{"asset_id":"14766054693214075530629349735273995982307625376442606753688071083149620216746","best_ask":"0.33","best_bid":"0.32","hash":"89fd4c7fa3446fe10c1240832c61861875adb9d4","price":"0.52","side":"SELL","size":"218.88"}],"timestamp":"1785130563334"},"payload_hash":"c8927534889306ed8cf2f1c1abf9b6bc4c8dc35c65a85744aa55ebdc7c6c8382","raw_frame":"{\"market\":\"0x3b40066b5cf3871a2f6237c5628bd8092a206aa998558ac5ec13c4483e31e160\", \"price_changes\":[{\"asset_id\":\"110216635572655435074987471276357323571387854733835379371586402147734167783946\", \"price\":\"0.48\", \"size\":\"218.88\", \"side\":\"BUY\", \"hash\":\"b1b050f56be49d39a2072311f4ced0a412a7f62d\", \"best_bid\":\"0.67\", \"best_ask\":\"0.68\"}, {\"asset_id\":\"14766054693214075530629349735273995982307625376442606753688071083149620216746\", \"price\":\"0.52\", \"size\":\"218.88\", \"side\":\"SELL\", \"hash\":\"89fd4c7fa3446fe10c1240832c61861875adb9d4\", \"best_bid\":\"0.32\", \"best_ask\":\"0.33\"}], \"timestamp\":\"1785130563334\", \"event_type\":\"price_change\"}","received_at":"2026-07-27T05:36:03.322936Z","schema_version":"clob-market-ws.price_change.v1","sequence":null,"server_hash":null,"server_timestamp":"1785130563334","session_id":"502006c5cfcd437296561ea750c9ec8b","source":"clob_market_ws"},"received_at":"2026-07-27T05:36:03.322936Z","record_id":"dbb1f9fd40d2ef1d4a19857cac7dd5a9aed554492539a0aa549e2bdd9fee0aac","schema_fingerprint":"4aa3821a28b0b7c2400bc59aba4bcc0a76e971dadd19610d3ad38c768e124dc7","schema_version":"edge-lab-recorder.raw.v1","sequence":null,"source":"clob_market_ws"}
{"event_at":"2026-07-27T05:36:03.339000Z","event_fingerprint":"1a32cb29fb4765d8cc40a3dec0d1fb9bda3ed9d569a7f39efe7a3e0578e6826a","payload":{"connection_id":"efc69d3132f1467b8e898a382b23ac0d","event_at":"2026-07-27T05:36:03.339000Z","event_type":"price_change","frame_hash":"8d5b2e7083c651e040b2ba580adc37d9624b84bdb0cde06410f5924dbbe67120","frame_index":0,"kind":"data","monotonic_ns":232546562431125,"payload":{"event_type":"price_change","market":"0x3b40066b5cf3871a2f6237c5628bd8092a206aa998558ac5ec13c4483e31e160","price_changes":[{"asset_id":"14766054693214075530629349735273995982307625376442606753688071083149620216746","best_ask":"0.33","best_bid":"0.32","hash":"18081c5841b7bb5ba0f8cfa7881de0a06052309e","price":"0.21","side":"BUY","size":"533.93"},{"asset_id":"110216635572655435074987471276357323571387854733835379371586402147734167783946","best_ask":"0.68","best_bid":"0.67","hash":"126ceff978a073829a671f15eb7e8ae2407811a9","price":"0.79","side":"SELL","size":"533.93"}],"timestamp":"1785130563339"},"payload_hash":"81fd5d50280fa03d40737a247c04e44a415cae78425f7995ba1c9cd99c74caeb","raw_frame":"{\"market\":\"0x3b40066b5cf3871a2f6237c5628bd8092a206aa998558ac5ec13c4483e31e160\", \"price_changes\":[{\"asset_id\":\"14766054693214075530629349735273995982307625376442606753688071083149620216746\", \"price\":\"0.21\", \"size\":\"533.93\", \"side\":\"BUY\", \"hash\":\"18081c5841b7bb5ba0f8cfa7881de0a06052309e\", \"best_bid\":\"0.32\", \"best_ask\":\"0.33\"}, {\"asset_id\":\"110216635572655435074987471276357323571387854733835379371586402147734167783946\", \"price\":\"0.79\", \"size\":\"533.93\", \"side\":\"SELL\", \"hash\":\"126ceff978a073829a671f15eb7e8ae2407811a9\", \"best_bid\":\"0.67\", \"best_ask\":\"0.68\"}], \"timestamp\":\"1785130563339\", \"event_type\":\"price_change\"}","received_at":"2026-07-27T05:36:03.326742Z","schema_version":"clob-market-ws.price_change.v1","sequence":null,"server_hash":null,"server_timestamp":"1785130563339","session_id":"502006c5cfcd437296561ea750c9ec8b","source":"clob_market_ws"},"received_at":"2026-07-27T05:36:03.326742Z","record_id":"8e757c5df7263198b2134c7bb8374f94aae0c821ecc0de9b4258ace494fda765","schema_fingerprint":"4aa3821a28b0b7c2400bc59aba4bcc0a76e971dadd19610d3ad38c768e124dc7","schema_version":"edge-lab-recorder.raw.v1","sequence":null,"source":"clob_market_ws"}
{"event_at":"2026-07-27T05:36:03.340000Z","event_fingerprint":"7c8ebad9d07409f81fbf600d152d205b781069b6e1fe44312a77f79503079e70","payload":{"connection_id":"efc69d3132f1467b8e898a382b23ac0d","event_at":"2026-07-27T05:36:03.340000Z","event_type":"price_change","frame_hash":"13555b7f8d0b81565e005899bd29eea183b1eed5e661949fddea238076aa4bd0","frame_index":0,"kind":"data","monotonic_ns":232546566663208,"payload":{"event_type":"price_change","market":"0x3b40066b5cf3871a2f6237c5628bd8092a206aa998558ac5ec13c4483e31e160","price_changes":[{"asset_id":"110216635572655435074987471276357323571387854733835379371586402147734167783946","best_ask":"0.68","best_bid":"0.67","hash":"b86c6948e2979ab02676c28072aa673b697ce45c","price":"0.02","side":"BUY","size":"678.1"},{"asset_id":"14766054693214075530629349735273995982307625376442606753688071083149620216746","best_ask":"0.33","best_bid":"0.32","hash":"d0181bd2cda831d3b03920e9852fd1ecd1a31582","price":"0.98","side":"SELL","size":"678.1"}],"timestamp":"1785130563340"},"payload_hash":"fca6ef0765e8c1ef706b1c850b75b48f3831a942898689500c77f7ddf9981188","raw_frame":"{\"market\":\"0x3b40066b5cf3871a2f6237c5628bd8092a206aa998558ac5ec13c4483e31e160\", \"price_changes\":[{\"asset_id\":\"110216635572655435074987471276357323571387854733835379371586402147734167783946\", \"price\":\"0.02\", \"size\":\"678.1\", \"side\":\"BUY\", \"hash\":\"b86c6948e2979ab02676c28072aa673b697ce45c\", \"best_bid\":\"0.67\", \"best_ask\":\"0.68\"}, {\"asset_id\":\"14766054693214075530629349735273995982307625376442606753688071083149620216746\", \"price\":\"0.98\", \"size\":\"678.1\", \"side\":\"SELL\", \"hash\":\"d0181bd2cda831d3b03920e9852fd1ecd1a31582\", \"best_bid\":\"0.32\", \"best_ask\":\"0.33\"}], \"timestamp\":\"1785130563340\", \"event_type\":\"price_change\"}","received_at":"2026-07-27T05:36:03.330984Z","schema_version":"clob-market-ws.price_change.v1","sequence":null,"server_hash":null,"server_timestamp":"1785130563340","session_id":"502006c5cfcd437296561ea750c9ec8b","source":"clob_market_ws"},"received_at":"2026-07-27T05:36:03.330984Z","record_id":"a29e6b78614048dfd8fcd402dba18bdc47aefd4d2e8f1de54b11fed01401daf7","schema_fingerprint":"4aa3821a28b0b7c2400bc59aba4bcc0a76e971dadd19610d3ad38c768e124dc7","schema_version":"edge-lab-recorder.raw.v1","sequence":null,"source":"clob_market_ws"}
{"event_at":"2026-07-27T05:36:03.367000Z","event_fingerprint":"c58e1264068e67f2e916151c00802fd5c9f21d8612042ed997dd13ca8cc58761","payload":{"connection_id":"efc69d3132f1467b8e898a382b23ac0d","event_at":"2026-07-27T05:36:03.367000Z","event_type":"price_change","frame_hash":"cacc80322f509f72210e865fa956527c2f2ba079c8ae9f88c0db38488804126f","frame_index":0,"kind":"data","monotonic_ns":232546572026791,"payload":{"event_type":"price_change","market":"0x3b40066b5cf3871a2f6237c5628bd8092a206aa998558ac5ec13c4483e31e160","price_changes":[{"asset_id":"14766054693214075530629349735273995982307625376442606753688071083149620216746","best_ask":"0.33","best_bid":"0.32","hash":"2be643a5c165f6f94a95bf5b3a4c051580b6e0d0","price":"0.34","side":"SELL","size":"61.66"},{"asset_id":"110216635572655435074987471276357323571387854733835379371586402147734167783946","best_ask":"0.68","best_bid":"0.67","hash":"40c4773a5fd275052833e87fe44aaa835f15e116","price":"0.66","side":"BUY","size":"61.66"}],"timestamp":"1785130563367"},"payload_hash":"7c7eb5a1eabc7e7b86560974062f473922e4f84e0572fe7ed0bbe5fc11808f2f","raw_frame":"{\"market\":\"0x3b40066b5cf3871a2f6237c5628bd8092a206aa998558ac5ec13c4483e31e160\", \"price_changes\":[{\"asset_id\":\"14766054693214075530629349735273995982307625376442606753688071083149620216746\", \"price\":\"0.34\", \"size\":\"61.66\", \"side\":\"SELL\", \"hash\":\"2be643a5c165f6f94a95bf5b3a4c051580b6e0d0\", \"best_bid\":\"0.32\", \"best_ask\":\"0.33\"}, {\"asset_id\":\"110216635572655435074987471276357323571387854733835379371586402147734167783946\", \"price\":\"0.66\", \"size\":\"61.66\", \"side\":\"BUY\", \"hash\":\"40c4773a5fd275052833e87fe44aaa835f15e116\", \"best_bid\":\"0.67\", \"best_ask\":\"0.68\"}], \"timestamp\":\"1785130563367\", \"event_type\":\"price_change\"}","received_at":"2026-07-27T05:36:03.336341Z","schema_version":"clob-market-ws.price_change.v1","sequence":null,"server_hash":null,"server_timestamp":"1785130563367","session_id":"502006c5cfcd437296561ea750c9ec8b","source":"clob_market_ws"},"received_at":"2026-07-27T05:36:03.336341Z","record_id":"0241cf2bc809a36dca4011b6869419ae8c333e0876d903e11f512781690dd7a9","schema_fingerprint":"4aa3821a28b0b7c2400bc59aba4bcc0a76e971dadd19610d3ad38c768e124dc7","schema_version":"edge-lab-recorder.raw.v1","sequence":null,"source":"clob_market_ws"}
{"event_at":"2026-07-27T05:36:03.368000Z","event_fingerprint":"ae77c796dc7358be805fe826c3d26cfe17493194aede58cf8e405f3af200809b","payload":{"connection_id":"efc69d3132f1467b8e898a382b23ac0d","event_at":"2026-07-27T05:36:03.368000Z","event_type":"price_change","frame_hash":"68bbf86e357257fe1f86b06199617e3214e357e5d4dd65e76fe32356803fae3a","frame_index":0,"kind":"data","monotonic_ns":232546575300375,"payload":{"event_type":"price_change","market":"0x3b40066b5cf3871a2f6237c5628bd8092a206aa998558ac5ec13c4483e31e160","price_changes":[{"asset_id":"14766054693214075530629349735273995982307625376442606753688071083149620216746","best_ask":"0.33","best_bid":"0.32","hash":"cd9ebc3fbff2c08a41d3a146055a8748d10cc8c4","price":"0.25","side":"BUY","size":"294"},{"asset_id":"110216635572655435074987471276357323571387854733835379371586402147734167783946","best_ask":"0.68","best_bid":"0.67","hash":"dfd0d9d117195fc28e372c12a534de37dabe9ffc","price":"0.75","side":"SELL","size":"294"}],"timestamp":"1785130563368"},"payload_hash":"a2f748a76e1ba08ed703010b5f66096c4edb4fe3a5c2a1c276d43c94a416c841","raw_frame":"{\"market\":\"0x3b40066b5cf3871a2f6237c5628bd8092a206aa998558ac5ec13c4483e31e160\", \"price_changes\":[{\"asset_id\":\"14766054693214075530629349735273995982307625376442606753688071083149620216746\", \"price\":\"0.25\", \"size\":\"294\", \"side\":\"BUY\", \"hash\":\"cd9ebc3fbff2c08a41d3a146055a8748d10cc8c4\", \"best_bid\":\"0.32\", \"best_ask\":\"0.33\"}, {\"asset_id\":\"110216635572655435074987471276357323571387854733835379371586402147734167783946\", \"price\":\"0.75\", \"size\":\"294\", \"side\":\"SELL\", \"hash\":\"dfd0d9d117195fc28e372c12a534de37dabe9ffc\", \"best_bid\":\"0.67\", \"best_ask\":\"0.68\"}], \"timestamp\":\"1785130563368\", \"event_type\":\"price_change\"}","received_at":"2026-07-27T05:36:03.339615Z","schema_version":"clob-market-ws.price_change.v1","sequence":null,"server_hash":null,"server_timestamp":"1785130563368","session_id":"502006c5cfcd437296561ea750c9ec8b","source":"clob_market_ws"},"received_at":"2026-07-27T05:36:03.339615Z","record_id":"d4fc6176380e69729982f9e6acc7f8f2c93ae07438b0944a0ab98fafe994e528","schema_fingerprint":"4aa3821a28b0b7c2400bc59aba4bcc0a76e971dadd19610d3ad38c768e124dc7","schema_version":"edge-lab-recorder.raw.v1","sequence":null,"source":"clob_market_ws"}
{"event_at":"2026-07-27T05:36:03.375000Z","event_fingerprint":"9f5b5d3631d6a22398b8b408d72559bf8cdf4d6220ae101127a9a941cefa36c4","payload":{"connection_id":"efc69d3132f1467b8e898a382b23ac0d","event_at":"2026-07-27T05:36:03.375000Z","event_type":"price_change","frame_hash":"29d25d01d37f5df0bdfb43ffd5daa0e0a0013ffb58386cd1113e022c9ed8e0b1","frame_index":0,"kind":"data","monotonic_ns":232546579912250,"payload":{"event_type":"price_change","market":"0x3b40066b5cf3871a2f6237c5628bd8092a206aa998558ac5ec13c4483e31e160","price_changes":[{"asset_id":"110216635572655435074987471276357323571387854733835379371586402147734167783946","best_ask":"0.68","best_bid":"0.67","hash":"31a88c88c3cd25a765fb7f3ffc165e59d06fe29c","price":"0.66","side":"BUY","size":"81.59"},{"asset_id":"14766054693214075530629349735273995982307625376442606753688071083149620216746","best_ask":"0.33","best_bid":"0.32","hash":"791e4a432610578cad8757badfa68b85c38bf8c3","price":"0.34","side":"SELL","size":"81.59"}],"timestamp":"1785130563375"},"payload_hash":"004ba339e0d70d66883153aa7cc0e513a1ff427ab575ef2ee832af7a39149868","raw_frame":"{\"market\":\"0x3b40066b5cf3871a2f6237c5628bd8092a206aa998558ac5ec13c4483e31e160\", \"price_changes\":[{\"asset_id\":\"110216635572655435074987471276357323571387854733835379371586402147734167783946\", \"price\":\"0.66\", \"size\":\"81.59\", \"side\":\"BUY\", \"hash\":\"31a88c88c3cd25a765fb7f3ffc165e59d06fe29c\", \"best_bid\":\"0.67\", \"best_ask\":\"0.68\"}, {\"asset_id\":\"14766054693214075530629349735273995982307625376442606753688071083149620216746\", \"price\":\"0.34\", \"size\":\"81.59\", \"side\":\"SELL\", \"hash\":\"791e4a432610578cad8757badfa68b85c38bf8c3\", \"best_bid\":\"0.32\", \"best_ask\":\"0.33\"}], \"timestamp\":\"1785130563375\", \"event_type\":\"price_change\"}","received_at":"2026-07-27T05:36:03.344226Z","schema_version":"clob-market-ws.price_change.v1","sequence":null,"server_hash":null,"server_timestamp":"1785130563375","session_id":"502006c5cfcd437296561ea750c9ec8b","source":"clob_market_ws"},"received_at":"2026-07-27T05:36:03.344226Z","record_id":"dd754676e2546ecac897533540421e6e3142d591444b9c7645f6d30e1f75c66b","schema_fingerprint":"4aa3821a28b0b7c2400bc59aba4bcc0a76e971dadd19610d3ad38c768e124dc7","schema_version":"edge-lab-recorder.raw.v1","sequence":null,"source":"clob_market_ws"}
{"event_at":"2026-07-27T05:36:03.394000Z","event_fingerprint":"f90b4aebb0dfe1af844ef90c23fbf206a36656e9b75f6271977f6d1dc970fed5","payload":{"connection_id":"efc69d3132f1467b8e898a382b23ac0d","event_at":"2026-07-27T05:36:03.394000Z","event_type":"price_change","frame_hash":"c8933ba9f0a711fae17b3d272ec31f9918e6eb1fdf448dcdd33dfab4f24e4f29","frame_index":0,"kind":"data","monotonic_ns":232546588917500,"payload":{"event_type":"price_change","market":"0x3b40066b5cf3871a2f6237c5628bd8092a206aa998558ac5ec13c4483e31e160","price_changes":[{"asset_id":"110216635572655435074987471276357323571387854733835379371586402147734167783946","best_ask":"0.68","best_bid":"0.67","hash":"18d05fe26601c1afe257936de1bb414887fd8492","price":"0.02","side":"BUY","size":"673.1"},{"asset_id":"14766054693214075530629349735273995982307625376442606753688071083149620216746","best_ask":"0.33","best_bid":"0.32","hash":"94422739e72cbffbec265f6cdf5c9d6d5e2a58b6","price":"0.98","side":"SELL","size":"673.1"}],"timestamp":"1785130563394"},"payload_hash":"fd53ad68f09d2f8e7225010f8e69b7fe158f08e43f1c9642b6b6e4cad7185e10","raw_frame":"{\"market\":\"0x3b40066b5cf3871a2f6237c5628bd8092a206aa998558ac5ec13c4483e31e160\", \"price_changes\":[{\"asset_id\":\"110216635572655435074987471276357323571387854733835379371586402147734167783946\", \"price\":\"0.02\", \"size\":\"673.1\", \"side\":\"BUY\", \"hash\":\"18d05fe26601c1afe257936de1bb414887fd8492\", \"best_bid\":\"0.67\", \"best_ask\":\"0.68\"}, {\"asset_id\":\"14766054693214075530629349735273995982307625376442606753688071083149620216746\", \"price\":\"0.98\", \"size\":\"673.1\", \"side\":\"SELL\", \"hash\":\"94422739e72cbffbec265f6cdf5c9d6d5e2a58b6\", \"best_bid\":\"0.32\", \"best_ask\":\"0.33\"}], \"timestamp\":\"1785130563394\", \"event_type\":\"price_change\"}","received_at":"2026-07-27T05:36:03.353233Z","schema_version":"clob-market-ws.price_change.v1","sequence":null,"server_hash":null,"server_timestamp":"1785130563394","session_id":"502006c5cfcd437296561ea750c9ec8b","source":"clob_market_ws"},"received_at":"2026-07-27T05:36:03.353233Z","record_id":"7a7578fac3c585e8195a1aaa638d03d5e91a9d98cbb717b80845ce28eca23a2b","schema_fingerprint":"4aa3821a28b0b7c2400bc59aba4bcc0a76e971dadd19610d3ad38c768e124dc7","schema_version":"edge-lab-recorder.raw.v1","sequence":null,"source":"clob_market_ws"}
{"event_at":"2026-07-27T05:36:03.403000Z","event_fingerprint":"b8be16d402cc8a75336dc571b7827251f930fbb8191abebd99b38c36f19ad601","payload":{"connection_id":"efc69d3132f1467b8e898a382b23ac0d","event_at":"2026-07-27T05:36:03.403000Z","event_type":"price_change","frame_hash":"5b3203c9cf8a518a3cfbb9e6e7de9c9fc9bade16a049dd5a8cd756c7fdb24d82","frame_index":0,"kind":"data","monotonic_ns":232546599752250,"payload":{"event_type":"price_change","market":"0x3b40066b5cf3871a2f6237c5628bd8092a206aa998558ac5ec13c4483e31e160","price_changes":[{"asset_id":"14766054693214075530629349735273995982307625376442606753688071083149620216746","best_ask":"0.33","best_bid":"0.32","hash":"ebea5b26f1f1c9b4a035e467317c877502399ae4","price":"0.21","side":"BUY","size":"692.66"},{"asset_id":"110216635572655435074987471276357323571387854733835379371586402147734167783946","best_ask":"0.68","best_bid":"0.67","hash":"663cb75125ed2b2502b9319651ffcc2d0895e729","price":"0.79","side":"SELL","size":"692.66"}],"timestamp":"1785130563403"},"payload_hash":"45e2b7e359c04789d1c56db0d8992014eaba02558bda1f7346aea6bab621e5e2","raw_frame":"{\"market\":\"0x3b40066b5cf3871a2f6237c5628bd8092a206aa998558ac5ec13c4483e31e160\", \"price_changes\":[{\"asset_id\":\"14766054693214075530629349735273995982307625376442606753688071083149620216746\", \"price\":\"0.21\", \"size\":\"692.66\", \"side\":\"BUY\", \"hash\":\"ebea5b26f1f1c9b4a035e467317c877502399ae4\", \"best_bid\":\"0.32\", \"best_ask\":\"0.33\"}, {\"asset_id\":\"110216635572655435074987471276357323571387854733835379371586402147734167783946\", \"price\":\"0.79\", \"size\":\"692.66\", \"side\":\"SELL\", \"hash\":\"663cb75125ed2b2502b9319651ffcc2d0895e729\", \"best_bid\":\"0.67\", \"best_ask\":\"0.68\"}], \"timestamp\":\"1785130563403\", \"event_type\":\"price_change\"}","received_at":"2026-07-27T05:36:03.364074Z","schema_version":"clob-market-ws.price_change.v1","sequence":null,"server_hash":null,"server_timestamp":"1785130563403","session_id":"502006c5cfcd437296561ea750c9ec8b","source":"clob_market_ws"},"received_at":"2026-07-27T05:36:03.364074Z","record_id":"de8bc9e9bbff96c8b81e62204327232153d071fa4a626461aa9c70750bf69136","schema_fingerprint":"4aa3821a28b0b7c2400bc59aba4bcc0a76e971dadd19610d3ad38c768e124dc7","schema_version":"edge-lab-recorder.raw.v1","sequence":null,"source":"clob_market_ws"}
{"event_at":"2026-07-27T05:36:03.450000Z","event_fingerprint":"37eef437c3f5f7ac44d20d49bce00a535a612a2e846a2d850335e69e1817779c","payload":{"connection_id":"efc69d3132f1467b8e898a382b23ac0d","event_at":"2026-07-27T05:36:03.450000Z","event_type":"price_change","frame_hash":"7dd6db5033005dac7c35c5a2904552e64036092609cb2850e033bfc60dd87c7f","frame_index":0,"kind":"data","monotonic_ns":232546645727416,"payload":{"event_type":"price_change","market":"0x3b40066b5cf3871a2f6237c5628bd8092a206aa998558ac5ec13c4483e31e160","price_changes":[{"asset_id":"110216635572655435074987471276357323571387854733835379371586402147734167783946","best_ask":"0.68","best_bid":"0.67","hash":"15ae304fb884cbd8bb92b18000d5185da28aaad0","price":"0.01","side":"BUY","size":"5607.45"},{"asset_id":"14766054693214075530629349735273995982307625376442606753688071083149620216746","best_ask":"0.33","best_bid":"0.32","hash":"df7d123fecc0dc6bfddb4daa0df4c3e4082b7187","price":"0.99","side":"SELL","size":"5607.45"}],"timestamp":"1785130563450"},"payload_hash":"f18b464f0ec20b7fc149b59a5018ad4ea0531263344a4aa1029be1a20482248e","raw_frame":"{\"market\":\"0x3b40066b5cf3871a2f6237c5628bd8092a206aa998558ac5ec13c4483e31e160\", \"price_changes\":[{\"asset_id\":\"110216635572655435074987471276357323571387854733835379371586402147734167783946\", \"price\":\"0.01\", \"size\":\"5607.45\", \"side\":\"BUY\", \"hash\":\"15ae304fb884cbd8bb92b18000d5185da28aaad0\", \"best_bid\":\"0.67\", \"best_ask\":\"0.68\"}, {\"asset_id\":\"14766054693214075530629349735273995982307625376442606753688071083149620216746\", \"price\":\"0.99\", \"size\":\"5607.45\", \"side\":\"SELL\", \"hash\":\"df7d123fecc0dc6bfddb4daa0df4c3e4082b7187\", \"best_bid\":\"0.32\", \"best_ask\":\"0.33\"}], \"timestamp\":\"1785130563450\", \"event_type\":\"price_change\"}","received_at":"2026-07-27T05:36:03.410037Z","schema_version":"clob-market-ws.price_change.v1","sequence":null,"server_hash":null,"server_timestamp":"1785130563450","session_id":"502006c5cfcd437296561ea750c9ec8b","source":"clob_market_ws"},"received_at":"2026-07-27T05:36:03.410037Z","record_id":"bbe80a507df6f8a99ab7c0f5996523feb6dad3b70661871def5492bb1375e1d2","schema_fingerprint":"4aa3821a28b0b7c2400bc59aba4bcc0a76e971dadd19610d3ad38c768e124dc7","schema_version":"edge-lab-recorder.raw.v1","sequence":null,"source":"clob_market_ws"}
{"event_at":"2026-07-27T05:36:03.462000Z","event_fingerprint":"536d51c8828cb3a93495fbf1f8b7beaac684bdee0e843cef6d866740f2c7b8f9","payload":{"connection_id":"efc69d3132f1467b8e898a382b23ac0d","event_at":"2026-07-27T05:36:03.462000Z","event_type":"price_change","frame_hash":"43430b81a363dfb0d3bddad0a80a33ade4ce32ce55a93d0583a0699001a88844","frame_index":0,"kind":"data","monotonic_ns":232546659242791,"payload":{"event_type":"price_change","market":"0x3b40066b5cf3871a2f6237c5628bd8092a206aa998558ac5ec13c4483e31e160","price_changes":[{"asset_id":"110216635572655435074987471276357323571387854733835379371586402147734167783946","best_ask":"0.68","best_bid":"0.67","hash":"0fea1a424798bd3272e7e91d6edd4d80bd18f05c","price":"0.48","side":"BUY","size":"288.32"},{"asset_id":"14766054693214075530629349735273995982307625376442606753688071083149620216746","best_ask":"0.33","best_bid":"0.32","hash":"6f03db6c01dbf72670bddb9b07cffb7af740daaf","price":"0.52","side":"SELL","size":"288.32"}],"timestamp":"1785130563462"},"payload_hash":"e3e97c882fb0eb9d80439cc9fe30bbcae37f04095b3752d1118250c5ba65e607","raw_frame":"{\"market\":\"0x3b40066b5cf3871a2f6237c5628bd8092a206aa998558ac5ec13c4483e31e160\", \"price_changes\":[{\"asset_id\":\"110216635572655435074987471276357323571387854733835379371586402147734167783946\", \"price\":\"0.48\", \"size\":\"288.32\", \"side\":\"BUY\", \"hash\":\"0fea1a424798bd3272e7e91d6edd4d80bd18f05c\", \"best_bid\":\"0.67\", \"best_ask\":\"0.68\"}, {\"asset_id\":\"14766054693214075530629349735273995982307625376442606753688071083149620216746\", \"price\":\"0.52\", \"size\":\"288.32\", \"side\":\"SELL\", \"hash\":\"6f03db6c01dbf72670bddb9b07cffb7af740daaf\", \"best_bid\":\"0.32\", \"best_ask\":\"0.33\"}], \"timestamp\":\"1785130563462\", \"event_type\":\"price_change\"}","received_at":"2026-07-27T05:36:03.423558Z","schema_version":"clob-market-ws.price_change.v1","sequence":null,"server_hash":null,"server_timestamp":"1785130563462","session_id":"502006c5cfcd437296561ea750c9ec8b","source":"clob_market_ws"},"received_at":"2026-07-27T05:36:03.423558Z","record_id":"d5078ae69da4c55e5e9933425e8c6d882d4dbbeea0acc3789661ef4171189e0e","schema_fingerprint":"4aa3821a28b0b7c2400bc59aba4bcc0a76e971dadd19610d3ad38c768e124dc7","schema_version":"edge-lab-recorder.raw.v1","sequence":null,"source":"clob_market_ws"}
{"event_at":"2026-07-27T05:36:03.464000Z","event_fingerprint":"9300447508ca02912182bb773d565db042a14beffcd6c16adc7d38c700d7890b","payload":{"connection_id":"efc69d3132f1467b8e898a382b23ac0d","event_at":"2026-07-27T05:36:03.464000Z","event_type":"price_change","frame_hash":"8dbafc960e2d11b4a1089782afd019b77119659387777a988359fbef32dfbae4","frame_index":0,"kind":"data","monotonic_ns":232546663309833,"payload":{"event_type":"price_change","market":"0x3b40066b5cf3871a2f6237c5628bd8092a206aa998558ac5ec13c4483e31e160","price_changes":[{"asset_id":"110216635572655435074987471276357323571387854733835379371586402147734167783946","best_ask":"0.68","best_bid":"0.67","hash":"73fd485df9ebabafa96f80c7777ae6896fde64c7","price":"0.01","side":"BUY","size":"5612.45"},{"asset_id":"14766054693214075530629349735273995982307625376442606753688071083149620216746","best_ask":"0.33","best_bid":"0.32","hash":"ddbe540facba5c663f3a9c632de22f787f36e32a","price":"0.99","side":"SELL","size":"5612.45"}],"timestamp":"1785130563464"},"payload_hash":"4749f1888442f7d347277b9d3784f724562971b5f7fb796ad9ec4044a80e4149","raw_frame":"{\"market\":\"0x3b40066b5cf3871a2f6237c5628bd8092a206aa998558ac5ec13c4483e31e160\", \"price_changes\":[{\"asset_id\":\"110216635572655435074987471276357323571387854733835379371586402147734167783946\", \"price\":\"0.01\", \"size\":\"5612.45\", \"side\":\"BUY\", \"hash\":\"73fd485df9ebabafa96f80c7777ae6896fde64c7\", \"best_bid\":\"0.67\", \"best_ask\":\"0.68\"}, {\"asset_id\":\"14766054693214075530629349735273995982307625376442606753688071083149620216746\", \"price\":\"0.99\", \"size\":\"5612.45\", \"side\":\"SELL\", \"hash\":\"ddbe540facba5c663f3a9c632de22f787f36e32a\", \"best_bid\":\"0.32\", \"best_ask\":\"0.33\"}], \"timestamp\":\"1785130563464\", \"event_type\":\"price_change\"}","received_at":"2026-07-27T05:36:03.427626Z","schema_version":"clob-market-ws.price_change.v1","sequence":null,"server_hash":null,"server_timestamp":"1785130563464","session_id":"502006c5cfcd437296561ea750c9ec8b","source":"clob_market_ws"},"received_at":"2026-07-27T05:36:03.427626Z","record_id":"348a71b7db4b0a979d59f3d8b6db884b4dffaa43fa6107aaa30c3943e1139805","schema_fingerprint":"4aa3821a28b0b7c2400bc59aba4bcc0a76e971dadd19610d3ad38c768e124dc7","schema_version":"edge-lab-recorder.raw.v1","sequence":null,"source":"clob_market_ws"}
{"event_at":"2026-07-27T05:36:03.472000Z","event_fingerprint":"9a36c8dcb68f7f4aa1ebefdbadf2e23e399b4f06904ef224184f31ea7f29d0ed","payload":{"connection_id":"efc69d3132f1467b8e898a382b23ac0d","event_at":"2026-07-27T05:36:03.472000Z","event_type":"price_change","frame_hash":"00e53977641295be43fa51c45096dcdda37d40b62a1b66c82bdd9c572db8c684","frame_index":0,"kind":"data","monotonic_ns":232546666934791,"payload":{"event_type":"price_change","market":"0x3b40066b5cf3871a2f6237c5628bd8092a206aa998558ac5ec13c4483e31e160","price_changes":[{"asset_id":"110216635572655435074987471276357323571387854733835379371586402147734167783946","best_ask":"0.68","best_bid":"0.67","hash":"28681ee8dfc05ee7c8f3d8fe123f258ba5416671","price":"0.01","side":"BUY","size":"5607.45"},{"asset_id":"14766054693214075530629349735273995982307625376442606753688071083149620216746","best_ask":"0.33","best_bid":"0.32","hash":"6c91f05de4e94af1541527c144fbcebad1a5fe7a","price":"0.99","side":"SELL","size":"5607.45"}],"timestamp":"1785130563472"},"payload_hash":"121e40fd7ac0747bb899baef178ee91315d4c140bce186ed18d8142e6d7b983e","raw_frame":"{\"market\":\"0x3b40066b5cf3871a2f6237c5628bd8092a206aa998558ac5ec13c4483e31e160\", \"price_changes\":[{\"asset_id\":\"110216635572655435074987471276357323571387854733835379371586402147734167783946\", \"price\":\"0.01\", \"size\":\"5607.45\", \"side\":\"BUY\", \"hash\":\"28681ee8dfc05ee7c8f3d8fe123f258ba5416671\", \"best_bid\":\"0.67\", \"best_ask\":\"0.68\"}, {\"asset_id\":\"14766054693214075530629349735273995982307625376442606753688071083149620216746\", \"price\":\"0.99\", \"size\":\"5607.45\", \"side\":\"SELL\", \"hash\":\"6c91f05de4e94af1541527c144fbcebad1a5fe7a\", \"best_bid\":\"0.32\", \"best_ask\":\"0.33\"}], \"timestamp\":\"1785130563472\", \"event_type\":\"price_change\"}","received_at":"2026-07-27T05:36:03.431256Z","schema_version":"clob-market-ws.price_change.v1","sequence":null,"server_hash":null,"server_timestamp":"1785130563472","session_id":"502006c5cfcd437296561ea750c9ec8b","source":"clob_market_ws"},"received_at":"2026-07-27T05:36:03.431256Z","record_id":"d02fcdb23d042cb9e437b4bd39c778dbc300fc29e9a97182fdd2519c1f39d7ad","schema_fingerprint":"4aa3821a28b0b7c2400bc59aba4bcc0a76e971dadd19610d3ad38c768e124dc7","schema_version":"edge-lab-recorder.raw.v1","sequence":null,"source":"clob_market_ws"}
{"event_at":"2026-07-27T05:36:03.477000Z","event_fingerprint":"8f2fff43a1a980326cfc931ebea42c5364411c7a5d03e6c209c0dba42f6d9ac0","payload":{"connection_id":"efc69d3132f1467b8e898a382b23ac0d","event_at":"2026-07-27T05:36:03.477000Z","event_type":"price_change","frame_hash":"c1ad3e40eae4a81d07f7b3d5bae9ceac31f791bfee961f759134000ce924f37f","frame_index":0,"kind":"data","monotonic_ns":232546672066583,"payload":{"event_type":"price_change","market":"0x3b40066b5cf3871a2f6237c5628bd8092a206aa998558ac5ec13c4483e31e160","price_changes":[{"asset_id":"110216635572655435074987471276357323571387854733835379371586402147734167783946","best_ask":"0.68","best_bid":"0.67","hash":"5e918c2fe6ecbed62cb14704e5ee19de0071fb6f","price":"0.66","side":"BUY","size":"61.66"},{"asset_id":"14766054693214075530629349735273995982307625376442606753688071083149620216746","best_ask":"0.33","best_bid":"0.32","hash":"946da64770c12e5cca3939781d82f51dc2c92e41","price":"0.34","side":"SELL","size":"61.66"}],"timestamp":"1785130563477"},"payload_hash":"8023321f8a0504a7eac7f36b07aa4eb7d7d233f2afb9c9b8c9ed6f3f0b7adb7e","raw_frame":"{\"market\":\"0x3b40066b5cf3871a2f6237c5628bd8092a206aa998558ac5ec13c4483e31e160\", \"price_changes\":[{\"asset_id\":\"110216635572655435074987471276357323571387854733835379371586402147734167783946\", \"price\":\"0.66\", \"size\":\"61.66\", \"side\":\"BUY\", \"hash\":\"5e918c2fe6ecbed62cb14704e5ee19de0071fb6f\", \"best_bid\":\"0.67\", \"best_ask\":\"0.68\"}, {\"asset_id\":\"14766054693214075530629349735273995982307625376442606753688071083149620216746\", \"price\":\"0.34\", \"size\":\"61.66\", \"side\":\"SELL\", \"hash\":\"946da64770c12e5cca3939781d82f51dc2c92e41\", \"best_bid\":\"0.32\", \"best_ask\":\"0.33\"}], \"timestamp\":\"1785130563477\", \"event_type\":\"price_change\"}","received_at":"2026-07-27T05:36:03.436383Z","schema_version":"clob-market-ws.price_change.v1","sequence":null,"server_hash":null,"server_timestamp":"1785130563477","session_id":"502006c5cfcd437296561ea750c9ec8b","source":"clob_market_ws"},"received_at":"2026-07-27T05:36:03.436383Z","record_id":"e0d6b29c4b8a1db723877b3c4af3bac6fd58420869b5c4ea0794d70e39d50ef1","schema_fingerprint":"4aa3821a28b0b7c2400bc59aba4bcc0a76e971dadd19610d3ad38c768e124dc7","schema_version":"edge-lab-recorder.raw.v1","sequence":null,"source":"clob_market_ws"}
{"event_at":"2026-07-27T05:36:03.480000Z","event_fingerprint":"b1edd8ac997d63a87de87f79d2ff044660942ce4bf3f4e79cb8a9e10d848aff3","payload":{"connection_id":"efc69d3132f1467b8e898a382b23ac0d","event_at":"2026-07-27T05:36:03.480000Z","event_type":"price_change","frame_hash":"3764474128ed142889e50787b2a56d57d54fbd5d8c79d289e172b82bda78ea42","frame_index":0,"kind":"data","monotonic_ns":232546678219166,"payload":{"event_type":"price_change","market":"0x3b40066b5cf3871a2f6237c5628bd8092a206aa998558ac5ec13c4483e31e160","price_changes":[{"asset_id":"110216635572655435074987471276357323571387854733835379371586402147734167783946","best_ask":"0.68","best_bid":"0.67","hash":"077d47738a5414cee405d9a7dbb86afc8c548731","price":"0.02","side":"BUY","size":"678.1"},{"asset_id":"14766054693214075530629349735273995982307625376442606753688071083149620216746","best_ask":"0.33","best_bid":"0.32","hash":"6012c0ca53b2e97a4ee8656893e742de4b06fdde","price":"0.98","side":"SELL","size":"678.1"}],"timestamp":"1785130563480"},"payload_hash":"14134080cc889634e500b5aca4a71dd82580253ede3830c048a15b0f369aa460","raw_frame":"{\"market\":\"0x3b40066b5cf3871a2f6237c5628bd8092a206aa998558ac5ec13c4483e31e160\", \"price_changes\":[{\"asset_id\":\"110216635572655435074987471276357323571387854733835379371586402147734167783946\", \"price\":\"0.02\", \"size\":\"678.1\", \"side\":\"BUY\", \"hash\":\"077d47738a5414cee405d9a7dbb86afc8c548731\", \"best_bid\":\"0.67\", \"best_ask\":\"0.68\"}, {\"asset_id\":\"14766054693214075530629349735273995982307625376442606753688071083149620216746\", \"price\":\"0.98\", \"size\":\"678.1\", \"side\":\"SELL\", \"hash\":\"6012c0ca53b2e97a4ee8656893e742de4b06fdde\", \"best_bid\":\"0.32\", \"best_ask\":\"0.33\"}], \"timestamp\":\"1785130563480\", \"event_type\":\"price_change\"}","received_at":"2026-07-27T05:36:03.442536Z","schema_version":"clob-market-ws.price_change.v1","sequence":null,"server_hash":null,"server_timestamp":"1785130563480","session_id":"502006c5cfcd437296561ea750c9ec8b","source":"clob_market_ws"},"received_at":"2026-07-27T05:36:03.442536Z","record_id":"6aed2e914f8ecc5d96b885b1ca9b2823e025205216ad4ca5eb7dfaf57ad3095b","schema_fingerprint":"4aa3821a28b0b7c2400bc59aba4bcc0a76e971dadd19610d3ad38c768e124dc7","schema_version":"edge-lab-recorder.raw.v1","sequence":null,"source":"clob_market_ws"}
{"event_at":"2026-07-27T05:36:03.482000Z","event_fingerprint":"1504cafa85935fe5c06fae5d8a0e794344d1f14778c75d9bfd6f7d096b250bb0","payload":{"connection_id":"efc69d3132f1467b8e898a382b23ac0d","event_at":"2026-07-27T05:36:03.482000Z","event_type":"price_change","frame_hash":"353f0ea12710fae0b2e60b26e2757512f3b7de637b5a97aa721808c29b7fb47d","frame_index":0,"kind":"data","monotonic_ns":232546683577000,"payload":{"event_type":"price_change","market":"0x3b40066b5cf3871a2f6237c5628bd8092a206aa998558ac5ec13c4483e31e160","price_changes":[{"asset_id":"14766054693214075530629349735273995982307625376442606753688071083149620216746","best_ask":"0.33","best_bid":"0.32","hash":"6a1362cf8258d42a6e5bac66eefc4ad23a3dedf5","price":"0.34","side":"SELL","size":"86.6"},{"asset_id":"110216635572655435074987471276357323571387854733835379371586402147734167783946","best_ask":"0.68","best_bid":"0.67","hash":"31f823e6b11622c28dc49d2168efdd447ab11e3f","price":"0.66","side":"BUY","size":"86.6"}],"timestamp":"1785130563482"},"payload_hash":"e8da2dfbb55c3900c9e244e9a0f75261731dd60861333d510eb135cead8304e0","raw_frame":"{\"market\":\"0x3b40066b5cf3871a2f6237c5628bd8092a206aa998558ac5ec13c4483e31e160\", \"price_changes\":[{\"asset_id\":\"14766054693214075530629349735273995982307625376442606753688071083149620216746\", \"price\":\"0.34\", \"size\":\"86.6\", \"side\":\"SELL\", \"hash\":\"6a1362cf8258d42a6e5bac66eefc4ad23a3dedf5\", \"best_bid\":\"0.32\", \"best_ask\":\"0.33\"}, {\"asset_id\":\"110216635572655435074987471276357323571387854733835379371586402147734167783946\", \"price\":\"0.66\", \"size\":\"86.6\", \"side\":\"BUY\", \"hash\":\"31f823e6b11622c28dc49d2168efdd447ab11e3f\", \"best_bid\":\"0.67\", \"best_ask\":\"0.68\"}], \"timestamp\":\"1785130563482\", \"event_type\":\"price_change\"}","received_at":"2026-07-27T05:36:03.447898Z","schema_version":"clob-market-ws.price_change.v1","sequence":null,"server_hash":null,"server_timestamp":"1785130563482","session_id":"502006c5cfcd437296561ea750c9ec8b","source":"clob_market_ws"},"received_at":"2026-07-27T05:36:03.447898Z","record_id":"3b8b869c043fab1e0ded408dcaf3cdd480e1fca9618799a45b9478625311c0b9","schema_fingerprint":"4aa3821a28b0b7c2400bc59aba4bcc0a76e971dadd19610d3ad38c768e124dc7","schema_version":"edge-lab-recorder.raw.v1","sequence":null,"source":"clob_market_ws"}
{"event_at":"2026-07-27T05:36:03.488000Z","event_fingerprint":"02d33122f9cfc53e6636199a258ef0ce3b442726a799d117a29da79e0daf7e1c","payload":{"connection_id":"efc69d3132f1467b8e898a382b23ac0d","event_at":"2026-07-27T05:36:03.488000Z","event_type":"price_change","frame_hash":"75b6b1545cf3ad90c51855e86fb0b7c098fb6086872da6b1244fd18245c90973","frame_index":0,"kind":"data","monotonic_ns":232546691169791,"payload":{"event_type":"price_change","market":"0x3b40066b5cf3871a2f6237c5628bd8092a206aa998558ac5ec13c4483e31e160","price_changes":[{"asset_id":"110216635572655435074987471276357323571387854733835379371586402147734167783946","best_ask":"0.68","best_bid":"0.67","hash":"571aa690e6803afe880e5ab6676bdd0ae1340fd8","price":"0.01","side":"BUY","size":"5602.45"},{"asset_id":"14766054693214075530629349735273995982307625376442606753688071083149620216746","best_ask":"0.33","best_bid":"0.32","hash":"a330f5a099074391e3bd12dbd88df4bff3710c3c","price":"0.99","side":"SELL","size":"5602.45"}],"timestamp":"1785130563488"},"payload_hash":"b732ca97a0760f473df22bf191750306286dc93aa857b10bdf93c1acd4fcc5d6","raw_frame":"{\"market\":\"0x3b40066b5cf3871a2f6237c5628bd8092a206aa998558ac5ec13c4483e31e160\", \"price_changes\":[{\"asset_id\":\"110216635572655435074987471276357323571387854733835379371586402147734167783946\", \"price\":\"0.01\", \"size\":\"5602.45\", \"side\":\"BUY\", \"hash\":\"571aa690e6803afe880e5ab6676bdd0ae1340fd8\", \"best_bid\":\"0.67\", \"best_ask\":\"0.68\"}, {\"asset_id\":\"14766054693214075530629349735273995982307625376442606753688071083149620216746\", \"price\":\"0.99\", \"size\":\"5602.45\", \"side\":\"SELL\", \"hash\":\"a330f5a099074391e3bd12dbd88df4bff3710c3c\", \"best_bid\":\"0.32\", \"best_ask\":\"0.33\"}], \"timestamp\":\"1785130563488\", \"event_type\":\"price_change\"}","received_at":"2026-07-27T05:36:03.455485Z","schema_version":"clob-market-ws.price_change.v1","sequence":null,"server_hash":null,"server_timestamp":"1785130563488","session_id":"502006c5cfcd437296561ea750c9ec8b","source":"clob_market_ws"},"received_at":"2026-07-27T05:36:03.455485Z","record_id":"ba4a8ce0560478683b38d1807f38e2e6dc8053065eda5088e440b9cea224a226","schema_fingerprint":"4aa3821a28b0b7c2400bc59aba4bcc0a76e971dadd19610d3ad38c768e124dc7","schema_version":"edge-lab-recorder.raw.v1","sequence":null,"source":"clob_market_ws"}
{"event_at":"2026-07-27T05:36:03.557000Z","event_fingerprint":"f791be99478ed87febe13b89042f3a961c6d0d86276939b2fbeb43e762a8f378","payload":{"connection_id":"efc69d3132f1467b8e898a382b23ac0d","event_at":"2026-07-27T05:36:03.557000Z","event_type":"price_change","frame_hash":"6beb41e00881a829840448507b737813ddb34f475e7fe839f7dff1b98264bbfd","frame_index":0,"kind":"data","monotonic_ns":232546759338166,"payload":{"event_type":"price_change","market":"0x3b40066b5cf3871a2f6237c5628bd8092a206aa998558ac5ec13c4483e31e160","price_changes":[{"asset_id":"110216635572655435074987471276357323571387854733835379371586402147734167783946","best_ask":"0.68","best_bid":"0.67","hash":"a38973a14489b00226a594f6b5c4e674ddee83c1","price":"0.02","side":"BUY","size":"673.1"},{"asset_id":"14766054693214075530629349735273995982307625376442606753688071083149620216746","best_ask":"0.33","best_bid":"0.32","hash":"f4aae8fd24c50449a551f660ca8811ad6f746c0c","price":"0.98","side":"SELL","size":"673.1"}],"timestamp":"1785130563557"},"payload_hash":"91dc254b0a0beea35b500d54a97ed0cff57c9a18a3a74e344246de0aa9f0caa3","raw_frame":"{\"market\":\"0x3b40066b5cf3871a2f6237c5628bd8092a206aa998558ac5ec13c4483e31e160\", \"price_changes\":[{\"asset_id\":\"110216635572655435074987471276357323571387854733835379371586402147734167783946\", \"price\":\"0.02\", \"size\":\"673.1\", \"side\":\"BUY\", \"hash\":\"a38973a14489b00226a594f6b5c4e674ddee83c1\", \"best_bid\":\"0.67\", \"best_ask\":\"0.68\"}, {\"asset_id\":\"14766054693214075530629349735273995982307625376442606753688071083149620216746\", \"price\":\"0.98\", \"size\":\"673.1\", \"side\":\"SELL\", \"hash\":\"f4aae8fd24c50449a551f660ca8811ad6f746c0c\", \"best_bid\":\"0.32\", \"best_ask\":\"0.33\"}], \"timestamp\":\"1785130563557\", \"event_type\":\"price_change\"}","received_at":"2026-07-27T05:36:03.523644Z","schema_version":"clob-market-ws.price_change.v1","sequence":null,"server_hash":null,"server_timestamp":"1785130563557","session_id":"502006c5cfcd437296561ea750c9ec8b","source":"clob_market_ws"},"received_at":"2026-07-27T05:36:03.523644Z","record_id":"e4753bde4e652c4727d7a47c7b172c2df6dcb75ffa98761e9498fdba76897826","schema_fingerprint":"4aa3821a28b0b7c2400bc59aba4bcc0a76e971dadd19610d3ad38c768e124dc7","schema_version":"edge-lab-recorder.raw.v1","sequence":null,"source":"clob_market_ws"}
{"event_at":"2026-07-27T05:36:03.588000Z","event_fingerprint":"67fe290a2cf15261822a64511513c005bb4c55250cb1a1228d301de24ddad43e","payload":{"connection_id":"efc69d3132f1467b8e898a382b23ac0d","event_at":"2026-07-27T05:36:03.588000Z","event_type":"price_change","frame_hash":"9d0d3f631cc9f864712a2fe2963ac8d9c902b8bc458afea5632ee6c1e6dc0ca6","frame_index":0,"kind":"data","monotonic_ns":232546783981791,"payload":{"event_type":"price_change","market":"0x3b40066b5cf3871a2f6237c5628bd8092a206aa998558ac5ec13c4483e31e160","price_changes":[{"asset_id":"14766054693214075530629349735273995982307625376442606753688071083149620216746","best_ask":"0.33","best_bid":"0.32","hash":"e478a96b7d1121b74a79fa861a89a3ea22fce87a","price":"0.34","side":"SELL","size":"61.66"},{"asset_id":"110216635572655435074987471276357323571387854733835379371586402147734167783946","best_ask":"0.68","best_bid":"0.67","hash":"1f303f37a7de9c2d2151709581bd8724c8aaee4f","price":"0.66","side":"BUY","size":"61.66"}],"timestamp":"1785130563588"},"payload_hash":"ce1164d3dd859a278378e9cdae6581ff88c0dfed19014adae0b2c527be13958b","raw_frame":"{\"market\":\"0x3b40066b5cf3871a2f6237c5628bd8092a206aa998558ac5ec13c4483e31e160\", \"price_changes\":[{\"asset_id\":\"14766054693214075530629349735273995982307625376442606753688071083149620216746\", \"price\":\"0.34\", \"size\":\"61.66\", \"side\":\"SELL\", \"hash\":\"e478a96b7d1121b74a79fa861a89a3ea22fce87a\", \"best_bid\":\"0.32\", \"best_ask\":\"0.33\"}, {\"asset_id\":\"110216635572655435074987471276357323571387854733835379371586402147734167783946\", \"price\":\"0.66\", \"size\":\"61.66\", \"side\":\"BUY\", \"hash\":\"1f303f37a7de9c2d2151709581bd8724c8aaee4f\", \"best_bid\":\"0.67\", \"best_ask\":\"0.68\"}], \"timestamp\":\"1785130563588\", \"event_type\":\"price_change\"}","received_at":"2026-07-27T05:36:03.548301Z","schema_version":"clob-market-ws.price_change.v1","sequence":null,"server_hash":null,"server_timestamp":"1785130563588","session_id":"502006c5cfcd437296561ea750c9ec8b","source":"clob_market_ws"},"received_at":"2026-07-27T05:36:03.548301Z","record_id":"87dbe3471ec50e90704c00db8e4a7215bcf22951171dbd24929ad334481c7656","schema_fingerprint":"4aa3821a28b0b7c2400bc59aba4bcc0a76e971dadd19610d3ad38c768e124dc7","schema_version":"edge-lab-recorder.raw.v1","sequence":null,"source":"clob_market_ws"}
{"event_at":"2026-07-27T05:36:03.595000Z","event_fingerprint":"79c7452bfdd661708c208ed2f3b748ec16471d2d497738c6cce493a6d88a8665","payload":{"connection_id":"efc69d3132f1467b8e898a382b23ac0d","event_at":"2026-07-27T05:36:03.595000Z","event_type":"price_change","frame_hash":"41b5b61c4cd63133f96dcc8c425e98d72b8ae8cfdeae53e917ce0f739546aaa0","frame_index":0,"kind":"data","monotonic_ns":232546790566708,"payload":{"event_type":"price_change","market":"0x3b40066b5cf3871a2f6237c5628bd8092a206aa998558ac5ec13c4483e31e160","price_changes":[{"asset_id":"110216635572655435074987471276357323571387854733835379371586402147734167783946","best_ask":"0.68","best_bid":"0.67","hash":"99f91d8332e5e4195dc54520691b8f85efc78238","price":"0.66","side":"BUY","size":"85.6"},{"asset_id":"14766054693214075530629349735273995982307625376442606753688071083149620216746","best_ask":"0.33","best_bid":"0.32","hash":"36f81157e2eddfe0a91ea1c08c2d1b5ef059b1db","price":"0.34","side":"SELL","size":"85.6"}],"timestamp":"1785130563595"},"payload_hash":"d41696936132b88a18817920296ebd8a1b25657146a673b43780fa0ea2cf7256","raw_frame":"{\"market\":\"0x3b40066b5cf3871a2f6237c5628bd8092a206aa998558ac5ec13c4483e31e160\", \"price_changes\":[{\"asset_id\":\"110216635572655435074987471276357323571387854733835379371586402147734167783946\", \"price\":\"0.66\", \"size\":\"85.6\", \"side\":\"BUY\", \"hash\":\"99f91d8332e5e4195dc54520691b8f85efc78238\", \"best_bid\":\"0.67\", \"best_ask\":\"0.68\"}, {\"asset_id\":\"14766054693214075530629349735273995982307625376442606753688071083149620216746\", \"price\":\"0.34\", \"size\":\"85.6\", \"side\":\"SELL\", \"hash\":\"36f81157e2eddfe0a91ea1c08c2d1b5ef059b1db\", \"best_bid\":\"0.32\", \"best_ask\":\"0.33\"}], \"timestamp\":\"1785130563595\", \"event_type\":\"price_change\"}","received_at":"2026-07-27T05:36:03.554881Z","schema_version":"clob-market-ws.price_change.v1","sequence":null,"server_hash":null,"server_timestamp":"1785130563595","session_id":"502006c5cfcd437296561ea750c9ec8b","source":"clob_market_ws"},"received_at":"2026-07-27T05:36:03.554881Z","record_id":"35f89968099447e1b498a10fec3c9597bb44ce50c1a63073dcdb08981c4773f4","schema_fingerprint":"4aa3821a28b0b7c2400bc59aba4bcc0a76e971dadd19610d3ad38c768e124dc7","schema_version":"edge-lab-recorder.raw.v1","sequence":null,"source":"clob_market_ws"}
{"event_at":"2026-07-27T05:36:03.657000Z","event_fingerprint":"33d2e972e20c813d9e3305a2ebae5716ac10909854c8a52252aa2b1149a85272","payload":{"connection_id":"efc69d3132f1467b8e898a382b23ac0d","event_at":"2026-07-27T05:36:03.657000Z","event_type":"price_change","frame_hash":"726e0760fd905b498171e2ed9df332c7b48359e1c5b7340181be591c9b5323d9","frame_index":0,"kind":"data","monotonic_ns":232546856959708,"payload":{"event_type":"price_change","market":"0x3b40066b5cf3871a2f6237c5628bd8092a206aa998558ac5ec13c4483e31e160","price_changes":[{"asset_id":"110216635572655435074987471276357323571387854733835379371586402147734167783946","best_ask":"0.68","best_bid":"0.67","hash":"ad78e7441b1fcde96a837061d62326a390486cd0","price":"0.02","side":"BUY","size":"678.1"},{"asset_id":"14766054693214075530629349735273995982307625376442606753688071083149620216746","best_ask":"0.33","best_bid":"0.32","hash":"f59205e08b2fc79895c77f0d76c841fa93fa4a00","price":"0.98","side":"SELL","size":"678.1"}],"timestamp":"1785130563657"},"payload_hash":"5ceeb5b3620df7d72d6c22b3987b09bfd32dc216e37cd84573b45dc4798ac507","raw_frame":"{\"market\":\"0x3b40066b5cf3871a2f6237c5628bd8092a206aa998558ac5ec13c4483e31e160\", \"price_changes\":[{\"asset_id\":\"110216635572655435074987471276357323571387854733835379371586402147734167783946\", \"price\":\"0.02\", \"size\":\"678.1\", \"side\":\"BUY\", \"hash\":\"ad78e7441b1fcde96a837061d62326a390486cd0\", \"best_bid\":\"0.67\", \"best_ask\":\"0.68\"}, {\"asset_id\":\"14766054693214075530629349735273995982307625376442606753688071083149620216746\", \"price\":\"0.98\", \"size\":\"678.1\", \"side\":\"SELL\", \"hash\":\"f59205e08b2fc79895c77f0d76c841fa93fa4a00\", \"best_bid\":\"0.32\", \"best_ask\":\"0.33\"}], \"timestamp\":\"1785130563657\", \"event_type\":\"price_change\"}","received_at":"2026-07-27T05:36:03.621272Z","schema_version":"clob-market-ws.price_change.v1","sequence":null,"server_hash":null,"server_timestamp":"1785130563657","session_id":"502006c5cfcd437296561ea750c9ec8b","source":"clob_market_ws"},"received_at":"2026-07-27T05:36:03.621272Z","record_id":"7fafbad7c7d31e983f9a5ba0a14fa12918421e690d3d7baac566997a4e2089af","schema_fingerprint":"4aa3821a28b0b7c2400bc59aba4bcc0a76e971dadd19610d3ad38c768e124dc7","schema_version":"edge-lab-recorder.raw.v1","sequence":null,"source":"clob_market_ws"}
{"event_at":"2026-07-27T05:36:03.686000Z","event_fingerprint":"7b78dc3de1fdbcc8561c5dcb072f99335224ec105cd59584c80211e8e30283a4","payload":{"connection_id":"efc69d3132f1467b8e898a382b23ac0d","event_at":"2026-07-27T05:36:03.686000Z","event_type":"price_change","frame_hash":"f651bd7291720c0ef5d68ceb88b2fa690f5f946bf1fc5cfc4126e7013a806979","frame_index":0,"kind":"data","monotonic_ns":232546882505625,"payload":{"event_type":"price_change","market":"0x3b40066b5cf3871a2f6237c5628bd8092a206aa998558ac5ec13c4483e31e160","price_changes":[{"asset_id":"110216635572655435074987471276357323571387854733835379371586402147734167783946","best_ask":"0.68","best_bid":"0.67","hash":"8e9b0e8061fa64880636b317ca7543aa665b2ac4","price":"0.83","side":"SELL","size":"168.3"},{"asset_id":"14766054693214075530629349735273995982307625376442606753688071083149620216746","best_ask":"0.33","best_bid":"0.32","hash":"6fb2b60f5fcec2d1966b7cc14841b1d624bf4390","price":"0.17","side":"BUY","size":"168.3"}],"timestamp":"1785130563686"},"payload_hash":"9835994ab76462218538f758444c199984ccefad730bcbc5bf0481ced67f862c","raw_frame":"{\"market\":\"0x3b40066b5cf3871a2f6237c5628bd8092a206aa998558ac5ec13c4483e31e160\", \"price_changes\":[{\"asset_id\":\"110216635572655435074987471276357323571387854733835379371586402147734167783946\", \"price\":\"0.83\", \"size\":\"168.3\", \"side\":\"SELL\", \"hash\":\"8e9b0e8061fa64880636b317ca7543aa665b2ac4\", \"best_bid\":\"0.67\", \"best_ask\":\"0.68\"}, {\"asset_id\":\"14766054693214075530629349735273995982307625376442606753688071083149620216746\", \"price\":\"0.17\", \"size\":\"168.3\", \"side\":\"BUY\", \"hash\":\"6fb2b60f5fcec2d1966b7cc14841b1d624bf4390\", \"best_bid\":\"0.32\", \"best_ask\":\"0.33\"}], \"timestamp\":\"1785130563686\", \"event_type\":\"price_change\"}","received_at":"2026-07-27T05:36:03.646824Z","schema_version":"clob-market-ws.price_change.v1","sequence":null,"server_hash":null,"server_timestamp":"1785130563686","session_id":"502006c5cfcd437296561ea750c9ec8b","source":"clob_market_ws"},"received_at":"2026-07-27T05:36:03.646824Z","record_id":"ee95b17d05b9d8121ae40b8785f582e609dc61a910f1444b15bdfc68b8025bee","schema_fingerprint":"4aa3821a28b0b7c2400bc59aba4bcc0a76e971dadd19610d3ad38c768e124dc7","schema_version":"edge-lab-recorder.raw.v1","sequence":null,"source":"clob_market_ws"}
{"event_at":"2026-07-27T05:36:03.695000Z","event_fingerprint":"2c507f0c6b591cc32ee6949fbb4f72e14846931a17b3b48e5583805001544f89","payload":{"connection_id":"efc69d3132f1467b8e898a382b23ac0d","event_at":"2026-07-27T05:36:03.695000Z","event_type":"price_change","frame_hash":"530b16523d79afc58545d1e719308b356824f9e519be3527903c2720926bab98","frame_index":0,"kind":"data","monotonic_ns":232546891970583,"payload":{"event_type":"price_change","market":"0x3b40066b5cf3871a2f6237c5628bd8092a206aa998558ac5ec13c4483e31e160","price_changes":[{"asset_id":"110216635572655435074987471276357323571387854733835379371586402147734167783946","best_ask":"0.68","best_bid":"0.67","hash":"3c2fdde484406ceafdd49988ee093d3e0f3c12a1","price":"0.66","side":"BUY","size":"61.66"},{"asset_id":"14766054693214075530629349735273995982307625376442606753688071083149620216746","best_ask":"0.33","best_bid":"0.32","hash":"190154f33622f6f433c44ba4cc9fb98aa3a8d2e7","price":"0.34","side":"SELL","size":"61.66"}],"timestamp":"1785130563695"},"payload_hash":"fa0620e4e24f3ea494574c5d5b4978479566772bf93a18f3de753eca4b61c6b0","raw_frame":"{\"market\":\"0x3b40066b5cf3871a2f6237c5628bd8092a206aa998558ac5ec13c4483e31e160\", \"price_changes\":[{\"asset_id\":\"110216635572655435074987471276357323571387854733835379371586402147734167783946\", \"price\":\"0.66\", \"size\":\"61.66\", \"side\":\"BUY\", \"hash\":\"3c2fdde484406ceafdd49988ee093d3e0f3c12a1\", \"best_bid\":\"0.67\", \"best_ask\":\"0.68\"}, {\"asset_id\":\"14766054693214075530629349735273995982307625376442606753688071083149620216746\", \"price\":\"0.34\", \"size\":\"61.66\", \"side\":\"SELL\", \"hash\":\"190154f33622f6f433c44ba4cc9fb98aa3a8d2e7\", \"best_bid\":\"0.32\", \"best_ask\":\"0.33\"}], \"timestamp\":\"1785130563695\", \"event_type\":\"price_change\"}","received_at":"2026-07-27T05:36:03.656283Z","schema_version":"clob-market-ws.price_change.v1","sequence":null,"server_hash":null,"server_timestamp":"1785130563695","session_id":"502006c5cfcd437296561ea750c9ec8b","source":"clob_market_ws"},"received_at":"2026-07-27T05:36:03.656283Z","record_id":"4456524aaa45680c113993cf92caab5bbffa1e31e0c6f5c2606403ff1f9307a5","schema_fingerprint":"4aa3821a28b0b7c2400bc59aba4bcc0a76e971dadd19610d3ad38c768e124dc7","schema_version":"edge-lab-recorder.raw.v1","sequence":null,"source":"clob_market_ws"}
{"event_at":"2026-07-27T05:36:03.699000Z","event_fingerprint":"4e29df54e8c85617d8dad722e6b2e421fedbada6b4bf3545996656e0f13b258d","payload":{"connection_id":"efc69d3132f1467b8e898a382b23ac0d","event_at":"2026-07-27T05:36:03.699000Z","event_type":"price_change","frame_hash":"cdb7e38b420de14232bdcdf48f702580f068a633fa3930c32f9abd362687ff58","frame_index":0,"kind":"data","monotonic_ns":232546896610333,"payload":{"event_type":"price_change","market":"0x3b40066b5cf3871a2f6237c5628bd8092a206aa998558ac5ec13c4483e31e160","price_changes":[{"asset_id":"110216635572655435074987471276357323571387854733835379371586402147734167783946","best_ask":"0.68","best_bid":"0.67","hash":"d21eeee757e336fbaf33cb0cbb142a53f01ea42e","price":"0.63","side":"BUY","size":"200.65"},{"asset_id":"14766054693214075530629349735273995982307625376442606753688071083149620216746","best_ask":"0.33","best_bid":"0.32","hash":"6ad851f6a142c6d831161567cbb0bea08546e493","price":"0.37","side":"SELL","size":"200.65"}],"timestamp":"1785130563699"},"payload_hash":"2299db47c3d0ae7614003eafe198dd831637b614bdbb64a3b323efdad14535f9","raw_frame":"{\"market\":\"0x3b40066b5cf3871a2f6237c5628bd8092a206aa998558ac5ec13c4483e31e160\", \"price_changes\":[{\"asset_id\":\"110216635572655435074987471276357323571387854733835379371586402147734167783946\", \"price\":\"0.63\", \"size\":\"200.65\", \"side\":\"BUY\", \"hash\":\"d21eeee757e336fbaf33cb0cbb142a53f01ea42e\", \"best_bid\":\"0.67\", \"best_ask\":\"0.68\"}, {\"asset_id\":\"14766054693214075530629349735273995982307625376442606753688071083149620216746\", \"price\":\"0.37\", \"size\":\"200.65\", \"side\":\"SELL\", \"hash\":\"6ad851f6a142c6d831161567cbb0bea08546e493\", \"best_bid\":\"0.32\", \"best_ask\":\"0.33\"}], \"timestamp\":\"1785130563699\", \"event_type\":\"price_change\"}","received_at":"2026-07-27T05:36:03.660934Z","schema_version":"clob-market-ws.price_change.v1","sequence":null,"server_hash":null,"server_timestamp":"1785130563699","session_id":"502006c5cfcd437296561ea750c9ec8b","source":"clob_market_ws"},"received_at":"2026-07-27T05:36:03.660934Z","record_id":"abf4f1c3fdb8167f6f68a77d0cc7f9d19b4ad9cab23a9f1926f4c195e0984f2c","schema_fingerprint":"4aa3821a28b0b7c2400bc59aba4bcc0a76e971dadd19610d3ad38c768e124dc7","schema_version":"edge-lab-recorder.raw.v1","sequence":null,"source":"clob_market_ws"}
{"event_at":"2026-07-27T05:36:03.700000Z","event_fingerprint":"67c88c17803806f9e094ec73b54ff79c647291ac3bd6b3c037a04508e6c24252","payload":{"connection_id":"efc69d3132f1467b8e898a382b23ac0d","event_at":"2026-07-27T05:36:03.700000Z","event_type":"price_change","frame_hash":"8c7851a6c98a5295c83ec238b3cfc8afd38d47a8ffa8300d8e8058b745170f6a","frame_index":0,"kind":"data","monotonic_ns":232546900203875,"payload":{"event_type":"price_change","market":"0x3b40066b5cf3871a2f6237c5628bd8092a206aa998558ac5ec13c4483e31e160","price_changes":[{"asset_id":"14766054693214075530629349735273995982307625376442606753688071083149620216746","best_ask":"0.33","best_bid":"0.32","hash":"153f1cadc9cfa5295122c3d0a7b5e6e5e9ca364a","price":"0.5","side":"SELL","size":"150"},{"asset_id":"110216635572655435074987471276357323571387854733835379371586402147734167783946","best_ask":"0.68","best_bid":"0.67","hash":"91e0c788860eb08bdbf3647643840808556714b7","price":"0.5","side":"BUY","size":"150"}],"timestamp":"1785130563700"},"payload_hash":"250784dfaa1063d662768854d4c2cfacbb74912d9ae32e9f40e61afafc575a7b","raw_frame":"{\"market\":\"0x3b40066b5cf3871a2f6237c5628bd8092a206aa998558ac5ec13c4483e31e160\", \"price_changes\":[{\"asset_id\":\"14766054693214075530629349735273995982307625376442606753688071083149620216746\", \"price\":\"0.5\", \"size\":\"150\", \"side\":\"SELL\", \"hash\":\"153f1cadc9cfa5295122c3d0a7b5e6e5e9ca364a\", \"best_bid\":\"0.32\", \"best_ask\":\"0.33\"}, {\"asset_id\":\"110216635572655435074987471276357323571387854733835379371586402147734167783946\", \"price\":\"0.5\", \"size\":\"150\", \"side\":\"BUY\", \"hash\":\"91e0c788860eb08bdbf3647643840808556714b7\", \"best_bid\":\"0.67\", \"best_ask\":\"0.68\"}], \"timestamp\":\"1785130563700\", \"event_type\":\"price_change\"}","received_at":"2026-07-27T05:36:03.664527Z","schema_version":"clob-market-ws.price_change.v1","sequence":null,"server_hash":null,"server_timestamp":"1785130563700","session_id":"502006c5cfcd437296561ea750c9ec8b","source":"clob_market_ws"},"received_at":"2026-07-27T05:36:03.664527Z","record_id":"9b127164238ffcff2a3eb0960d2f42833bbb3818f7b51d7fb0283140710b050d","schema_fingerprint":"4aa3821a28b0b7c2400bc59aba4bcc0a76e971dadd19610d3ad38c768e124dc7","schema_version":"edge-lab-recorder.raw.v1","sequence":null,"source":"clob_market_ws"}
{"event_at":"2026-07-27T05:36:03.701000Z","event_fingerprint":"224466a365a9373224347a2229ea140178adc91df6b8d7495e2ce636d0c59092","payload":{"connection_id":"efc69d3132f1467b8e898a382b23ac0d","event_at":"2026-07-27T05:36:03.701000Z","event_type":"price_change","frame_hash":"eb97195f5380fb88a33bf1ede0c3bc7842e43b86df79a8fd617048d5797d4acb","frame_index":0,"kind":"data","monotonic_ns":232546909442625,"payload":{"event_type":"price_change","market":"0x3b40066b5cf3871a2f6237c5628bd8092a206aa998558ac5ec13c4483e31e160","price_changes":[{"asset_id":"14766054693214075530629349735273995982307625376442606753688071083149620216746","best_ask":"0.33","best_bid":"0.32","hash":"2ad890a7194a5c7cf39a15336545edbe189bab96","price":"0.34","side":"SELL","size":"86.6"},{"asset_id":"110216635572655435074987471276357323571387854733835379371586402147734167783946","best_ask":"0.68","best_bid":"0.67","hash":"c47f92de80866333a0b71f1e5b01d7908e3a75f2","price":"0.66","side":"BUY","size":"86.6"}],"timestamp":"1785130563701"},"payload_hash":"206be4b87be2b9d31318268bba1c13e12bbab7ffa35ffbe67a5df6b0c6770d7c","raw_frame":"{\"market\":\"0x3b40066b5cf3871a2f6237c5628bd8092a206aa998558ac5ec13c4483e31e160\", \"price_changes\":[{\"asset_id\":\"14766054693214075530629349735273995982307625376442606753688071083149620216746\", \"price\":\"0.34\", \"size\":\"86.6\", \"side\":\"SELL\", \"hash\":\"2ad890a7194a5c7cf39a15336545edbe189bab96\", \"best_bid\":\"0.32\", \"best_ask\":\"0.33\"}, {\"asset_id\":\"110216635572655435074987471276357323571387854733835379371586402147734167783946\", \"price\":\"0.66\", \"size\":\"86.6\", \"side\":\"BUY\", \"hash\":\"c47f92de80866333a0b71f1e5b01d7908e3a75f2\", \"best_bid\":\"0.67\", \"best_ask\":\"0.68\"}], \"timestamp\":\"1785130563701\", \"event_type\":\"price_change\"}","received_at":"2026-07-27T05:36:03.673760Z","schema_version":"clob-market-ws.price_change.v1","sequence":null,"server_hash":null,"server_timestamp":"1785130563701","session_id":"502006c5cfcd437296561ea750c9ec8b","source":"clob_market_ws"},"received_at":"2026-07-27T05:36:03.673760Z","record_id":"9c9fbc8a946df72331748bf872154f294542c9c8243427225724309f34530752","schema_fingerprint":"4aa3821a28b0b7c2400bc59aba4bcc0a76e971dadd19610d3ad38c768e124dc7","schema_version":"edge-lab-recorder.raw.v1","sequence":null,"source":"clob_market_ws"}
{"event_at":"2026-07-27T05:36:03.715000Z","event_fingerprint":"efc1295ac6ae290cf9695afdf00982f53f42b8def5ce01e57d54a8d49bf860db","payload":{"connection_id":"efc69d3132f1467b8e898a382b23ac0d","event_at":"2026-07-27T05:36:03.715000Z","event_type":"price_change","frame_hash":"56f4d2619a8d0c410f0eed47a68523e2e1bbfef9a5f0ce6f8ab563c7c7bb96a6","frame_index":0,"kind":"data","monotonic_ns":232546914763250,"payload":{"event_type":"price_change","market":"0x3b40066b5cf3871a2f6237c5628bd8092a206aa998558ac5ec13c4483e31e160","price_changes":[{"asset_id":"110216635572655435074987471276357323571387854733835379371586402147734167783946","best_ask":"0.68","best_bid":"0.67","hash":"239bb97697a7b8ae919ca6d97974710bbddd3dd7","price":"0.02","side":"BUY","size":"673.1"},{"asset_id":"14766054693214075530629349735273995982307625376442606753688071083149620216746","best_ask":"0.33","best_bid":"0.32","hash":"3150ca1f9835f446b91985ad10b4aa592026971f","price":"0.98","side":"SELL","size":"673.1"}],"timestamp":"1785130563715"},"payload_hash":"d1d52e485562ed15759ac189457e559fa92be656ec5ace8fb33014f6e1df3a01","raw_frame":"{\"market\":\"0x3b40066b5cf3871a2f6237c5628bd8092a206aa998558ac5ec13c4483e31e160\", \"price_changes\":[{\"asset_id\":\"110216635572655435074987471276357323571387854733835379371586402147734167783946\", \"price\":\"0.02\", \"size\":\"673.1\", \"side\":\"BUY\", \"hash\":\"239bb97697a7b8ae919ca6d97974710bbddd3dd7\", \"best_bid\":\"0.67\", \"best_ask\":\"0.68\"}, {\"asset_id\":\"14766054693214075530629349735273995982307625376442606753688071083149620216746\", \"price\":\"0.98\", \"size\":\"673.1\", \"side\":\"SELL\", \"hash\":\"3150ca1f9835f446b91985ad10b4aa592026971f\", \"best_bid\":\"0.32\", \"best_ask\":\"0.33\"}], \"timestamp\":\"1785130563715\", \"event_type\":\"price_change\"}","received_at":"2026-07-27T05:36:03.679081Z","schema_version":"clob-market-ws.price_change.v1","sequence":null,"server_hash":null,"server_timestamp":"1785130563715","session_id":"502006c5cfcd437296561ea750c9ec8b","source":"clob_market_ws"},"received_at":"2026-07-27T05:36:03.679081Z","record_id":"5b0d549119be350d4199005b10b1711e263bb4b7ea6c33de4f611b76ec835f26","schema_fingerprint":"4aa3821a28b0b7c2400bc59aba4bcc0a76e971dadd19610d3ad38c768e124dc7","schema_version":"edge-lab-recorder.raw.v1","sequence":null,"source":"clob_market_ws"}
{"event_at":"2026-07-27T05:36:03.721000Z","event_fingerprint":"01bb5e4f63a113e6a31ca316e6ca8eb3d5948b3e840e5364fc2a456498213778","payload":{"connection_id":"efc69d3132f1467b8e898a382b23ac0d","event_at":"2026-07-27T05:36:03.721000Z","event_type":"price_change","frame_hash":"674938fb8fe3a2db7eb99dade6ef28fc17701fbe817f3cd2521021ba478e6f56","frame_index":0,"kind":"data","monotonic_ns":232546918833250,"payload":{"event_type":"price_change","market":"0x3b40066b5cf3871a2f6237c5628bd8092a206aa998558ac5ec13c4483e31e160","price_changes":[{"asset_id":"14766054693214075530629349735273995982307625376442606753688071083149620216746","best_ask":"0.33","best_bid":"0.32","hash":"7461abfe1b37c62bc8ace5143e784f3893c3675f","price":"0.35","side":"SELL","size":"77.96"},{"asset_id":"110216635572655435074987471276357323571387854733835379371586402147734167783946","best_ask":"0.68","best_bid":"0.67","hash":"33459fc371f6b5119a61d85c8e10803e6444c450","price":"0.65","side":"BUY","size":"77.96"}],"timestamp":"1785130563721"},"payload_hash":"9dae0c602257fdad27631536f9c097b1b29a9bebb26c11caa8ccf871aaf6fb33","raw_frame":"{\"market\":\"0x3b40066b5cf3871a2f6237c5628bd8092a206aa998558ac5ec13c4483e31e160\", \"price_changes\":[{\"asset_id\":\"14766054693214075530629349735273995982307625376442606753688071083149620216746\", \"price\":\"0.35\", \"size\":\"77.96\", \"side\":\"SELL\", \"hash\":\"7461abfe1b37c62bc8ace5143e784f3893c3675f\", \"best_bid\":\"0.32\", \"best_ask\":\"0.33\"}, {\"asset_id\":\"110216635572655435074987471276357323571387854733835379371586402147734167783946\", \"price\":\"0.65\", \"size\":\"77.96\", \"side\":\"BUY\", \"hash\":\"33459fc371f6b5119a61d85c8e10803e6444c450\", \"best_bid\":\"0.67\", \"best_ask\":\"0.68\"}], \"timestamp\":\"1785130563721\", \"event_type\":\"price_change\"}","received_at":"2026-07-27T05:36:03.683151Z","schema_version":"clob-market-ws.price_change.v1","sequence":null,"server_hash":null,"server_timestamp":"1785130563721","session_id":"502006c5cfcd437296561ea750c9ec8b","source":"clob_market_ws"},"received_at":"2026-07-27T05:36:03.683151Z","record_id":"aae703ff7839d8ea6af5e6d38515454acb148f9967fa04beb45cdfdae3adb9a3","schema_fingerprint":"4aa3821a28b0b7c2400bc59aba4bcc0a76e971dadd19610d3ad38c768e124dc7","schema_version":"edge-lab-recorder.raw.v1","sequence":null,"source":"clob_market_ws"}
{"event_at":"2026-07-27T05:36:03.721000Z","event_fingerprint":"e481c658985c8528ecdeb87674264d7cdecf17f4ed3e270b581837cfeba6dd3c","payload":{"connection_id":"efc69d3132f1467b8e898a382b23ac0d","event_at":"2026-07-27T05:36:03.721000Z","event_type":"price_change","frame_hash":"6fe1ee2617192f48a3627320ccecf2e7a0ee0fd4d7198d044bc418f7cdbe1a2c","frame_index":0,"kind":"data","monotonic_ns":232546922764666,"payload":{"event_type":"price_change","market":"0x3b40066b5cf3871a2f6237c5628bd8092a206aa998558ac5ec13c4483e31e160","price_changes":[{"asset_id":"110216635572655435074987471276357323571387854733835379371586402147734167783946","best_ask":"0.68","best_bid":"0.67","hash":"bf8cacc37dd5bab075b4547f360eeb567c4d329b","price":"0.65","side":"BUY","size":"52.96"},{"asset_id":"14766054693214075530629349735273995982307625376442606753688071083149620216746","best_ask":"0.33","best_bid":"0.32","hash":"b0a2f46dff775a17aec2b68b9b4a1b770a299d52","price":"0.35","side":"SELL","size":"52.96"}],"timestamp":"1785130563721"},"payload_hash":"f1bec180510270e726db0e12c2be40b8c3009d13436a8b1c928500e4174fe6d5","raw_frame":"{\"market\":\"0x3b40066b5cf3871a2f6237c5628bd8092a206aa998558ac5ec13c4483e31e160\", \"price_changes\":[{\"asset_id\":\"110216635572655435074987471276357323571387854733835379371586402147734167783946\", \"price\":\"0.65\", \"size\":\"52.96\", \"side\":\"BUY\", \"hash\":\"bf8cacc37dd5bab075b4547f360eeb567c4d329b\", \"best_bid\":\"0.67\", \"best_ask\":\"0.68\"}, {\"asset_id\":\"14766054693214075530629349735273995982307625376442606753688071083149620216746\", \"price\":\"0.35\", \"size\":\"52.96\", \"side\":\"SELL\", \"hash\":\"b0a2f46dff775a17aec2b68b9b4a1b770a299d52\", \"best_bid\":\"0.32\", \"best_ask\":\"0.33\"}], \"timestamp\":\"1785130563721\", \"event_type\":\"price_change\"}","received_at":"2026-07-27T05:36:03.687081Z","schema_version":"clob-market-ws.price_change.v1","sequence":null,"server_hash":null,"server_timestamp":"1785130563721","session_id":"502006c5cfcd437296561ea750c9ec8b","source":"clob_market_ws"},"received_at":"2026-07-27T05:36:03.687081Z","record_id":"8fd18d386f6da31813e42a38f08b740b2455cfbceb6b146817a2728be3444d1e","schema_fingerprint":"4aa3821a28b0b7c2400bc59aba4bcc0a76e971dadd19610d3ad38c768e124dc7","schema_version":"edge-lab-recorder.raw.v1","sequence":null,"source":"clob_market_ws"}
{"event_at":"2026-07-27T05:36:03.729000Z","event_fingerprint":"da7756b84711dd30e61a9ab595228c94ae0c236dd8bd1681ccae03df21d642b3","payload":{"connection_id":"efc69d3132f1467b8e898a382b23ac0d","event_at":"2026-07-27T05:36:03.729000Z","event_type":"price_change","frame_hash":"32ed00211d0898edaf4305cd8c550952f96d737629801f93048095300548c7af","frame_index":0,"kind":"data","monotonic_ns":232546928026791,"payload":{"event_type":"price_change","market":"0x3b40066b5cf3871a2f6237c5628bd8092a206aa998558ac5ec13c4483e31e160","price_changes":[{"asset_id":"14766054693214075530629349735273995982307625376442606753688071083149620216746","best_ask":"0.33","best_bid":"0.32","hash":"bcbc9c4b5363d1883117e901d637f5106a9253b1","price":"0.49","side":"SELL","size":"190"},{"asset_id":"110216635572655435074987471276357323571387854733835379371586402147734167783946","best_ask":"0.68","best_bid":"0.67","hash":"35ce61ffa192f17c3d003b50029365f84f9af91f","price":"0.51","side":"BUY","size":"190"}],"timestamp":"1785130563729"},"payload_hash":"94f3139245ff07333f0fbe416a45fe9bcd7992ec05bb8b35235767fe4c522abb","raw_frame":"{\"market\":\"0x3b40066b5cf3871a2f6237c5628bd8092a206aa998558ac5ec13c4483e31e160\", \"price_changes\":[{\"asset_id\":\"14766054693214075530629349735273995982307625376442606753688071083149620216746\", \"price\":\"0.49\", \"size\":\"190\", \"side\":\"SELL\", \"hash\":\"bcbc9c4b5363d1883117e901d637f5106a9253b1\", \"best_bid\":\"0.32\", \"best_ask\":\"0.33\"}, {\"asset_id\":\"110216635572655435074987471276357323571387854733835379371586402147734167783946\", \"price\":\"0.51\", \"size\":\"190\", \"side\":\"BUY\", \"hash\":\"35ce61ffa192f17c3d003b50029365f84f9af91f\", \"best_bid\":\"0.67\", \"best_ask\":\"0.68\"}], \"timestamp\":\"1785130563729\", \"event_type\":\"price_change\"}","received_at":"2026-07-27T05:36:03.692345Z","schema_version":"clob-market-ws.price_change.v1","sequence":null,"server_hash":null,"server_timestamp":"1785130563729","session_id":"502006c5cfcd437296561ea750c9ec8b","source":"clob_market_ws"},"received_at":"2026-07-27T05:36:03.692345Z","record_id":"80ffa5f0a8a7518def05ac5c6b76bac6d18e6bef8bbaca525960bb3c0fa92119","schema_fingerprint":"4aa3821a28b0b7c2400bc59aba4bcc0a76e971dadd19610d3ad38c768e124dc7","schema_version":"edge-lab-recorder.raw.v1","sequence":null,"source":"clob_market_ws"}
{"event_at":"2026-07-27T05:36:03.745000Z","event_fingerprint":"dadc692c9667680fddacf5207d519966903b93cc87b2d25f138edb661cd5a84a","payload":{"connection_id":"efc69d3132f1467b8e898a382b23ac0d","event_at":"2026-07-27T05:36:03.745000Z","event_type":"price_change","frame_hash":"e94770ed6239763ee713f76f525e5aa6edf36129cd4a784bdd92ba5db5723aa7","frame_index":0,"kind":"data","monotonic_ns":232546940147666,"payload":{"event_type":"price_change","market":"0x3b40066b5cf3871a2f6237c5628bd8092a206aa998558ac5ec13c4483e31e160","price_changes":[{"asset_id":"14766054693214075530629349735273995982307625376442606753688071083149620216746","best_ask":"0.33","best_bid":"0.32","hash":"ae909af04cc272d5c74d9c759d3a5e2d8d3dc0d1","price":"0.34","side":"SELL","size":"111.6"},{"asset_id":"110216635572655435074987471276357323571387854733835379371586402147734167783946","best_ask":"0.68","best_bid":"0.67","hash":"dfc4d5d2d485040852cb667d7f57e61464c8311a","price":"0.66","side":"BUY","size":"111.6"}],"timestamp":"1785130563745"},"payload_hash":"8b2cbd8f88361bd50417139ca84c0df0918a77d8a1d5f3c4fa8aee41a5234854","raw_frame":"{\"market\":\"0x3b40066b5cf3871a2f6237c5628bd8092a206aa998558ac5ec13c4483e31e160\", \"price_changes\":[{\"asset_id\":\"14766054693214075530629349735273995982307625376442606753688071083149620216746\", \"price\":\"0.34\", \"size\":\"111.6\", \"side\":\"SELL\", \"hash\":\"ae909af04cc272d5c74d9c759d3a5e2d8d3dc0d1\", \"best_bid\":\"0.32\", \"best_ask\":\"0.33\"}, {\"asset_id\":\"110216635572655435074987471276357323571387854733835379371586402147734167783946\", \"price\":\"0.66\", \"size\":\"111.6\", \"side\":\"BUY\", \"hash\":\"dfc4d5d2d485040852cb667d7f57e61464c8311a\", \"best_bid\":\"0.67\", \"best_ask\":\"0.68\"}], \"timestamp\":\"1785130563745\", \"event_type\":\"price_change\"}","received_at":"2026-07-27T05:36:03.704465Z","schema_version":"clob-market-ws.price_change.v1","sequence":null,"server_hash":null,"server_timestamp":"1785130563745","session_id":"502006c5cfcd437296561ea750c9ec8b","source":"clob_market_ws"},"received_at":"2026-07-27T05:36:03.704465Z","record_id":"09e48af6187d6d54244e6858adb710f834f39aae706a92864feac1aa1efba2f6","schema_fingerprint":"4aa3821a28b0b7c2400bc59aba4bcc0a76e971dadd19610d3ad38c768e124dc7","schema_version":"edge-lab-recorder.raw.v1","sequence":null,"source":"clob_market_ws"}
{"event_at":"2026-07-27T05:36:03.746000Z","event_fingerprint":"17b8781b809c8ff1b2870b4d19f5cbbc35456a392ad8aac7beb5ba4699848536","payload":{"connection_id":"efc69d3132f1467b8e898a382b23ac0d","event_at":"2026-07-27T05:36:03.746000Z","event_type":"price_change","frame_hash":"f031492811ed9b041abddbe3f92a9f8319fa68c649817ed9ad4b1a9b6a310c88","frame_index":0,"kind":"data","monotonic_ns":232546944909375,"payload":{"event_type":"price_change","market":"0x3b40066b5cf3871a2f6237c5628bd8092a206aa998558ac5ec13c4483e31e160","price_changes":[{"asset_id":"110216635572655435074987471276357323571387854733835379371586402147734167783946","best_ask":"0.68","best_bid":"0.67","hash":"a818ce9c82a4ec736e397c63da26f6a2e0502514","price":"0.66","side":"BUY","size":"136.6"},{"asset_id":"14766054693214075530629349735273995982307625376442606753688071083149620216746","best_ask":"0.33","best_bid":"0.32","hash":"715e53dfaf2e9062de399136d4432085f7175828","price":"0.34","side":"SELL","size":"136.6"}],"timestamp":"1785130563746"},"payload_hash":"2fda39d23597974cbf68fe3a89b9cd00fe321399b183d75cace6d82bf28ce7d4","raw_frame":"{\"market\":\"0x3b40066b5cf3871a2f6237c5628bd8092a206aa998558ac5ec13c4483e31e160\", \"price_changes\":[{\"asset_id\":\"110216635572655435074987471276357323571387854733835379371586402147734167783946\", \"price\":\"0.66\", \"size\":\"136.6\", \"side\":\"BUY\", \"hash\":\"a818ce9c82a4ec736e397c63da26f6a2e0502514\", \"best_bid\":\"0.67\", \"best_ask\":\"0.68\"}, {\"asset_id\":\"14766054693214075530629349735273995982307625376442606753688071083149620216746\", \"price\":\"0.34\", \"size\":\"136.6\", \"side\":\"SELL\", \"hash\":\"715e53dfaf2e9062de399136d4432085f7175828\", \"best_bid\":\"0.32\", \"best_ask\":\"0.33\"}], \"timestamp\":\"1785130563746\", \"event_type\":\"price_change\"}","received_at":"2026-07-27T05:36:03.709227Z","schema_version":"clob-market-ws.price_change.v1","sequence":null,"server_hash":null,"server_timestamp":"1785130563746","session_id":"502006c5cfcd437296561ea750c9ec8b","source":"clob_market_ws"},"received_at":"2026-07-27T05:36:03.709227Z","record_id":"6b866a84a4f282d1a06b2b1e228b643390814b5d3fe23fd3f5a831f6471ed574","schema_fingerprint":"4aa3821a28b0b7c2400bc59aba4bcc0a76e971dadd19610d3ad38c768e124dc7","schema_version":"edge-lab-recorder.raw.v1","sequence":null,"source":"clob_market_ws"}
{"event_at":"2026-07-27T05:36:03.755000Z","event_fingerprint":"06d1ffb89c7f5f13a39314c96413ed58dd7a21fd1c6727f34ca212ab076d3edd","payload":{"connection_id":"efc69d3132f1467b8e898a382b23ac0d","event_at":"2026-07-27T05:36:03.755000Z","event_type":"price_change","frame_hash":"c3eab3eb94350bf5d480f21d092f81d1ffb83ada501b5b486f142976dee6e549","frame_index":0,"kind":"data","monotonic_ns":232546948973708,"payload":{"event_type":"price_change","market":"0x3b40066b5cf3871a2f6237c5628bd8092a206aa998558ac5ec13c4483e31e160","price_changes":[{"asset_id":"14766054693214075530629349735273995982307625376442606753688071083149620216746","best_ask":"0.33","best_bid":"0.32","hash":"36fbc061b0bcae12c4ccf39ab6385956070d4054","price":"0.28","side":"BUY","size":"322.43"},{"asset_id":"110216635572655435074987471276357323571387854733835379371586402147734167783946","best_ask":"0.68","best_bid":"0.67","hash":"cfac3b9555e6bef07e8a96a347b6c74efba4cecc","price":"0.72","side":"SELL","size":"322.43"}],"timestamp":"1785130563755"},"payload_hash":"77a22751f6543335d0aa110ee859c3598379b49e0b757e0c620f78c441bf1143","raw_frame":"{\"market\":\"0x3b40066b5cf3871a2f6237c5628bd8092a206aa998558ac5ec13c4483e31e160\", \"price_changes\":[{\"asset_id\":\"14766054693214075530629349735273995982307625376442606753688071083149620216746\", \"price\":\"0.28\", \"size\":\"322.43\", \"side\":\"BUY\", \"hash\":\"36fbc061b0bcae12c4ccf39ab6385956070d4054\", \"best_bid\":\"0.32\", \"best_ask\":\"0.33\"}, {\"asset_id\":\"110216635572655435074987471276357323571387854733835379371586402147734167783946\", \"price\":\"0.72\", \"size\":\"322.43\", \"side\":\"SELL\", \"hash\":\"cfac3b9555e6bef07e8a96a347b6c74efba4cecc\", \"best_bid\":\"0.67\", \"best_ask\":\"0.68\"}], \"timestamp\":\"1785130563755\", \"event_type\":\"price_change\"}","received_at":"2026-07-27T05:36:03.713289Z","schema_version":"clob-market-ws.price_change.v1","sequence":null,"server_hash":null,"server_timestamp":"1785130563755","session_id":"502006c5cfcd437296561ea750c9ec8b","source":"clob_market_ws"},"received_at":"2026-07-27T05:36:03.713289Z","record_id":"8957695c6eec18d19addc293b0361116dc187281e0be7d24ee2227ce1b0a7958","schema_fingerprint":"4aa3821a28b0b7c2400bc59aba4bcc0a76e971dadd19610d3ad38c768e124dc7","schema_version":"edge-lab-recorder.raw.v1","sequence":null,"source":"clob_market_ws"}
{"event_at":"2026-07-27T05:36:03.756000Z","event_fingerprint":"68b666eaadcdf8ee98b9631ea1f50d4da00ac0a1a1ed09a61b7cfbc859884b28","payload":{"connection_id":"efc69d3132f1467b8e898a382b23ac0d","event_at":"2026-07-27T05:36:03.756000Z","event_type":"price_change","frame_hash":"42e51c0bacff2c4a25a1d404818d53a9cf53b9ed87f907cc709d496a020b6ae0","frame_index":0,"kind":"data","monotonic_ns":232546953923208,"payload":{"event_type":"price_change","market":"0x3b40066b5cf3871a2f6237c5628bd8092a206aa998558ac5ec13c4483e31e160","price_changes":[{"asset_id":"14766054693214075530629349735273995982307625376442606753688071083149620216746","best_ask":"0.33","best_bid":"0.32","hash":"6ef966d4828bb3cea9452d5a316c62d8d174f1e6","price":"0.29","side":"BUY","size":"69.4"},{"asset_id":"110216635572655435074987471276357323571387854733835379371586402147734167783946","best_ask":"0.68","best_bid":"0.67","hash":"2fca06a1e6b5510961713220efcc59eebc0e96dd","price":"0.71","side":"SELL","size":"69.4"}],"timestamp":"1785130563756"},"payload_hash":"e175751bbb2efc905823dacc7f827c38cef69ab10e7e59a0264d7f7c10740792","raw_frame":"{\"market\":\"0x3b40066b5cf3871a2f6237c5628bd8092a206aa998558ac5ec13c4483e31e160\", \"price_changes\":[{\"asset_id\":\"14766054693214075530629349735273995982307625376442606753688071083149620216746\", \"price\":\"0.29\", \"size\":\"69.4\", \"side\":\"BUY\", \"hash\":\"6ef966d4828bb3cea9452d5a316c62d8d174f1e6\", \"best_bid\":\"0.32\", \"best_ask\":\"0.33\"}, {\"asset_id\":\"110216635572655435074987471276357323571387854733835379371586402147734167783946\", \"price\":\"0.71\", \"size\":\"69.4\", \"side\":\"SELL\", \"hash\":\"2fca06a1e6b5510961713220efcc59eebc0e96dd\", \"best_bid\":\"0.67\", \"best_ask\":\"0.68\"}], \"timestamp\":\"1785130563756\", \"event_type\":\"price_change\"}","received_at":"2026-07-27T05:36:03.718235Z","schema_version":"clob-market-ws.price_change.v1","sequence":null,"server_hash":null,"server_timestamp":"1785130563756","session_id":"502006c5cfcd437296561ea750c9ec8b","source":"clob_market_ws"},"received_at":"2026-07-27T05:36:03.718235Z","record_id":"347f513419352ec7a2f584a9cd84570fd44ed7f2db86bb1d5dae01d122fc882e","schema_fingerprint":"4aa3821a28b0b7c2400bc59aba4bcc0a76e971dadd19610d3ad38c768e124dc7","schema_version":"edge-lab-recorder.raw.v1","sequence":null,"source":"clob_market_ws"}
{"event_at":"2026-07-27T05:36:03.773000Z","event_fingerprint":"097f3821228a8a2fb6c0294fba283ee7fc05a6fdda0c21d0ea18835e538c85a3","payload":{"connection_id":"efc69d3132f1467b8e898a382b23ac0d","event_at":"2026-07-27T05:36:03.773000Z","event_type":"best_bid_ask","frame_hash":"f69d0e18bc369f044c89e2ade9190727d42e80cce3ded0d2713284b56ec6b126","frame_index":0,"kind":"data","monotonic_ns":232546970751625,"payload":{"asset_id":"14766054693214075530629349735273995982307625376442606753688071083149620216746","best_ask":"0.33","best_bid":"0.31","event_type":"best_bid_ask","market":"0x3b40066b5cf3871a2f6237c5628bd8092a206aa998558ac5ec13c4483e31e160","spread":"0.02","timestamp":"1785130563773"},"payload_hash":"513b9960fff0a4d086c92aa807a6c8161f089d04e49f28801842b1d2cc162605","raw_frame":"{\"market\":\"0x3b40066b5cf3871a2f6237c5628bd8092a206aa998558ac5ec13c4483e31e160\", \"asset_id\":\"14766054693214075530629349735273995982307625376442606753688071083149620216746\", \"best_bid\":\"0.31\", \"best_ask\":\"0.33\", \"spread\":\"0.02\", \"timestamp\":\"1785130563773\", \"event_type\":\"best_bid_ask\"}","received_at":"2026-07-27T05:36:03.735063Z","schema_version":"clob-market-ws.best_bid_ask.v1","sequence":null,"server_hash":null,"server_timestamp":"1785130563773","session_id":"502006c5cfcd437296561ea750c9ec8b","source":"clob_market_ws"},"received_at":"2026-07-27T05:36:03.735063Z","record_id":"2e242e1d96d4348ec8f07e7358abd902996ed2f3faf6fde290e308fc42964c8a","schema_fingerprint":"8488399f31b0337811b13b266be932db7062827c2470b78bd8e9e99bab51d17d","schema_version":"edge-lab-recorder.raw.v1","sequence":null,"source":"clob_market_ws"}
{"event_at":"2026-07-27T05:36:03.773000Z","event_fingerprint":"9524971e90023e50f90623c3bda17fd6a11a2983858d532f144900425f3a824c","payload":{"connection_id":"efc69d3132f1467b8e898a382b23ac0d","event_at":"2026-07-27T05:36:03.773000Z","event_type":"best_bid_ask","frame_hash":"518ac5b72feacb690a3b44c3f6eb02e0a175adb6b020a3e8622bf69eca89d850","frame_index":0,"kind":"data","monotonic_ns":232546975031083,"payload":{"asset_id":"110216635572655435074987471276357323571387854733835379371586402147734167783946","best_ask":"0.69","best_bid":"0.67","event_type":"best_bid_ask","market":"0x3b40066b5cf3871a2f6237c5628bd8092a206aa998558ac5ec13c4483e31e160","spread":"0.02","timestamp":"1785130563773"},"payload_hash":"ed53514b93fa73d0c5647bbcdb9bc3467cab22a79faf8acb646437dfecf5b3d9","raw_frame":"{\"market\":\"0x3b40066b5cf3871a2f6237c5628bd8092a206aa998558ac5ec13c4483e31e160\", \"asset_id\":\"110216635572655435074987471276357323571387854733835379371586402147734167783946\", \"best_bid\":\"0.67\", \"best_ask\":\"0.69\", \"spread\":\"0.02\", \"timestamp\":\"1785130563773\", \"event_type\":\"best_bid_ask\"}","received_at":"2026-07-27T05:36:03.739347Z","schema_version":"clob-market-ws.best_bid_ask.v1","sequence":null,"server_hash":null,"server_timestamp":"1785130563773","session_id":"502006c5cfcd437296561ea750c9ec8b","source":"clob_market_ws"},"received_at":"2026-07-27T05:36:03.739347Z","record_id":"285a26c1c017a3ff2cbfb955acb16f7ad6841e3244ba125b27d46eaf0c3dc72d","schema_fingerprint":"8488399f31b0337811b13b266be932db7062827c2470b78bd8e9e99bab51d17d","schema_version":"edge-lab-recorder.raw.v1","sequence":null,"source":"clob_market_ws"}
{"event_at":"2026-07-27T05:36:03.773000Z","event_fingerprint":"7001319ac13ebe16c5cd1d8798092694d4fead047b0ec17e2cd17c7b91aab236","payload":{"connection_id":"efc69d3132f1467b8e898a382b23ac0d","event_at":"2026-07-27T05:36:03.773000Z","event_type":"price_change","frame_hash":"a0a795413fedd879d31ca5626dda45e5b0ddd47d5d8c70c601e99d23e81af338","frame_index":0,"kind":"data","monotonic_ns":232546979593666,"payload":{"event_type":"price_change","market":"0x3b40066b5cf3871a2f6237c5628bd8092a206aa998558ac5ec13c4483e31e160","price_changes":[{"asset_id":"14766054693214075530629349735273995982307625376442606753688071083149620216746","best_ask":"0.33","best_bid":"0.31","hash":"c950387f8e7017493652702ab870094af5956855","price":"0.31","side":"BUY","size":"11"},{"asset_id":"110216635572655435074987471276357323571387854733835379371586402147734167783946","best_ask":"0.69","best_bid":"0.67","hash":"4c3a0b71859ddb7ca330a2c89939036c5cdd1b78","price":"0.69","side":"SELL","size":"11"}],"timestamp":"1785130563773"},"payload_hash":"d22ee835d54a9c62adde789fbe0a9868c2744d79f6a9ec254a22146f82777099","raw_frame":"{\"market\":\"0x3b40066b5cf3871a2f6237c5628bd8092a206aa998558ac5ec13c4483e31e160\", \"price_changes\":[{\"asset_id\":\"14766054693214075530629349735273995982307625376442606753688071083149620216746\", \"price\":\"0.31\", \"size\":\"11\", \"side\":\"BUY\", \"hash\":\"c950387f8e7017493652702ab870094af5956855\", \"best_bid\":\"0.31\", \"best_ask\":\"0.33\"}, {\"asset_id\":\"110216635572655435074987471276357323571387854733835379371586402147734167783946\", \"price\":\"0.69\", \"size\":\"11\", \"side\":\"SELL\", \"hash\":\"4c3a0b71859ddb7ca330a2c89939036c5cdd1b78\", \"best_bid\":\"0.67\", \"best_ask\":\"0.69\"}], \"timestamp\":\"1785130563773\", \"event_type\":\"price_change\"}","received_at":"2026-07-27T05:36:03.743911Z","schema_version":"clob-market-ws.price_change.v1","sequence":null,"server_hash":null,"server_timestamp":"1785130563773","session_id":"502006c5cfcd437296561ea750c9ec8b","source":"clob_market_ws"},"received_at":"2026-07-27T05:36:03.743911Z","record_id":"401bcd487981533d617a6a7aaee0cdb092282d4f0edb2b17c53f8dbeeb56ae5e","schema_fingerprint":"4aa3821a28b0b7c2400bc59aba4bcc0a76e971dadd19610d3ad38c768e124dc7","schema_version":"edge-lab-recorder.raw.v1","sequence":null,"source":"clob_market_ws"}
{"event_at":"2026-07-27T05:36:03.773000Z","event_fingerprint":"22b14674a572c2c77f6c4109d5317c6bb96e160a81645df1bc7cf53b42b0ccb3","payload":{"connection_id":"efc69d3132f1467b8e898a382b23ac0d","event_at":"2026-07-27T05:36:03.773000Z","event_type":"price_change","frame_hash":"ad03a484fe5c99a292a9f4bbe0d6fed15b1206791671e9c5a193794b885002e4","frame_index":0,"kind":"data","monotonic_ns":232546982081000,"payload":{"event_type":"price_change","market":"0x3b40066b5cf3871a2f6237c5628bd8092a206aa998558ac5ec13c4483e31e160","price_changes":[{"asset_id":"14766054693214075530629349735273995982307625376442606753688071083149620216746","best_ask":"0.33","best_bid":"0.31","hash":"c950387f8e7017493652702ab870094af5956855","price":"0.32","side":"BUY","size":"0"},{"asset_id":"110216635572655435074987471276357323571387854733835379371586402147734167783946","best_ask":"0.69","best_bid":"0.67","hash":"4c3a0b71859ddb7ca330a2c89939036c5cdd1b78","price":"0.68","side":"SELL","size":"0"}],"timestamp":"1785130563773"},"payload_hash":"8270e9720fed227b291b05f26a39b281f27a6381127ecc54be510022c246cba7","raw_frame":"{\"market\":\"0x3b40066b5cf3871a2f6237c5628bd8092a206aa998558ac5ec13c4483e31e160\", \"price_changes\":[{\"asset_id\":\"14766054693214075530629349735273995982307625376442606753688071083149620216746\", \"price\":\"0.32\", \"size\":\"0\", \"side\":\"BUY\", \"hash\":\"c950387f8e7017493652702ab870094af5956855\", \"best_bid\":\"0.31\", \"best_ask\":\"0.33\"}, {\"asset_id\":\"110216635572655435074987471276357323571387854733835379371586402147734167783946\", \"price\":\"0.68\", \"size\":\"0\", \"side\":\"SELL\", \"hash\":\"4c3a0b71859ddb7ca330a2c89939036c5cdd1b78\", \"best_bid\":\"0.67\", \"best_ask\":\"0.69\"}], \"timestamp\":\"1785130563773\", \"event_type\":\"price_change\"}","received_at":"2026-07-27T05:36:03.746400Z","schema_version":"clob-market-ws.price_change.v1","sequence":null,"server_hash":null,"server_timestamp":"1785130563773","session_id":"502006c5cfcd437296561ea750c9ec8b","source":"clob_market_ws"},"received_at":"2026-07-27T05:36:03.746400Z","record_id":"933e7cce555ed811a434addfddc0ce16c0dcf6b6375ff9b6d59c96cea4128d15","schema_fingerprint":"4aa3821a28b0b7c2400bc59aba4bcc0a76e971dadd19610d3ad38c768e124dc7","schema_version":"edge-lab-recorder.raw.v1","sequence":null,"source":"clob_market_ws"}
{"event_at":"2026-07-27T05:36:03.774000Z","event_fingerprint":"b22b7e03c46b71a910abdd1e267cf5c171b329b4d4cfa35fadb87aacd2f75fe8","payload":{"connection_id":"efc69d3132f1467b8e898a382b23ac0d","event_at":"2026-07-27T05:36:03.774000Z","event_type":"price_change","frame_hash":"6ed217277fbf74db3c5bfbfa9f3229e182e2a8e6b4888492ec41b474e4411b80","frame_index":0,"kind":"data","monotonic_ns":232546986159916,"payload":{"event_type":"price_change","market":"0x3b40066b5cf3871a2f6237c5628bd8092a206aa998558ac5ec13c4483e31e160","price_changes":[{"asset_id":"14766054693214075530629349735273995982307625376442606753688071083149620216746","best_ask":"0.33","best_bid":"0.31","hash":"1efb5b9a5fe285316b3c9e00a24c909f9001d307","price":"0.23","side":"BUY","size":"181.09"},{"asset_id":"110216635572655435074987471276357323571387854733835379371586402147734167783946","best_ask":"0.69","best_bid":"0.67","hash":"0aca5c7ae80353534dbbbd32aa1c772b4bf0ec39","price":"0.77","side":"SELL","size":"181.09"}],"timestamp":"1785130563774"},"payload_hash":"0ff36fc6ec0682eadd3a99076363e27b93f17b3503e43e97dda28556a003d3a0","raw_frame":"{\"market\":\"0x3b40066b5cf3871a2f6237c5628bd8092a206aa998558ac5ec13c4483e31e160\", \"price_changes\":[{\"asset_id\":\"14766054693214075530629349735273995982307625376442606753688071083149620216746\", \"price\":\"0.23\", \"size\":\"181.09\", \"side\":\"BUY\", \"hash\":\"1efb5b9a5fe285316b3c9e00a24c909f9001d307\", \"best_bid\":\"0.31\", \"best_ask\":\"0.33\"}, {\"asset_id\":\"110216635572655435074987471276357323571387854733835379371586402147734167783946\", \"price\":\"0.77\", \"size\":\"181.09\", \"side\":\"SELL\", \"hash\":\"0aca5c7ae80353534dbbbd32aa1c772b4bf0ec39\", \"best_bid\":\"0.67\", \"best_ask\":\"0.69\"}], \"timestamp\":\"1785130563774\", \"event_type\":\"price_change\"}","received_at":"2026-07-27T05:36:03.750478Z","schema_version":"clob-market-ws.price_change.v1","sequence":null,"server_hash":null,"server_timestamp":"1785130563774","session_id":"502006c5cfcd437296561ea750c9ec8b","source":"clob_market_ws"},"received_at":"2026-07-27T05:36:03.750478Z","record_id":"3d3c9b971da79370dbafaedb85c47d534a876c847184752a2edd36d2e0736986","schema_fingerprint":"4aa3821a28b0b7c2400bc59aba4bcc0a76e971dadd19610d3ad38c768e124dc7","schema_version":"edge-lab-recorder.raw.v1","sequence":null,"source":"clob_market_ws"}
{"event_at":"2026-07-27T05:36:03.793000Z","event_fingerprint":"70f1a574e193b186a52e7d1f4a75c9d9fc48f7fcd87c62dbb0558634412a4043","payload":{"connection_id":"efc69d3132f1467b8e898a382b23ac0d","event_at":"2026-07-27T05:36:03.793000Z","event_type":"price_change","frame_hash":"43fc8d8a6978330e11a1e5adf0c0149c7090e9a81616e948a78a4fc2c8f339df","frame_index":0,"kind":"data","monotonic_ns":232546992386916,"payload":{"event_type":"price_change","market":"0x3b40066b5cf3871a2f6237c5628bd8092a206aa998558ac5ec13c4483e31e160","price_changes":[{"asset_id":"14766054693214075530629349735273995982307625376442606753688071083149620216746","best_ask":"0.33","best_bid":"0.31","hash":"461b00c3d971d7d18e40f26f8257214d6e085905","price":"0.26","side":"BUY","size":"46"},{"asset_id":"110216635572655435074987471276357323571387854733835379371586402147734167783946","best_ask":"0.69","best_bid":"0.67","hash":"1d703c7e6e3d21c8477839a10c37df0e53587c30","price":"0.74","side":"SELL","size":"46"}],"timestamp":"1785130563793"},"payload_hash":"1cf6ddc78a2ba90faf96355b07c62bdadd31c79bb4cc46aab6df1eb8f1855bed","raw_frame":"{\"market\":\"0x3b40066b5cf3871a2f6237c5628bd8092a206aa998558ac5ec13c4483e31e160\", \"price_changes\":[{\"asset_id\":\"14766054693214075530629349735273995982307625376442606753688071083149620216746\", \"price\":\"0.26\", \"size\":\"46\", \"side\":\"BUY\", \"hash\":\"461b00c3d971d7d18e40f26f8257214d6e085905\", \"best_bid\":\"0.31\", \"best_ask\":\"0.33\"}, {\"asset_id\":\"110216635572655435074987471276357323571387854733835379371586402147734167783946\", \"price\":\"0.74\", \"size\":\"46\", \"side\":\"SELL\", \"hash\":\"1d703c7e6e3d21c8477839a10c37df0e53587c30\", \"best_bid\":\"0.67\", \"best_ask\":\"0.69\"}], \"timestamp\":\"1785130563793\", \"event_type\":\"price_change\"}","received_at":"2026-07-27T05:36:03.756700Z","schema_version":"clob-market-ws.price_change.v1","sequence":null,"server_hash":null,"server_timestamp":"1785130563793","session_id":"502006c5cfcd437296561ea750c9ec8b","source":"clob_market_ws"},"received_at":"2026-07-27T05:36:03.756700Z","record_id":"98a663206c62d46df86ebc4e3337b806e602ecb4f90acc06ffa24acd9830f42d","schema_fingerprint":"4aa3821a28b0b7c2400bc59aba4bcc0a76e971dadd19610d3ad38c768e124dc7","schema_version":"edge-lab-recorder.raw.v1","sequence":null,"source":"clob_market_ws"}
{"event_at":"2026-07-27T05:36:03.799000Z","event_fingerprint":"5c6b30f58811bf81bf90228ed2b7b76e6f7898136ff58f2bb8ac223beb3dd5af","payload":{"connection_id":"efc69d3132f1467b8e898a382b23ac0d","event_at":"2026-07-27T05:36:03.799000Z","event_type":"price_change","frame_hash":"e21134eb024ad9586aa1e3ea608d9a0ece28b6f80e863579093aaf077cef08ce","frame_index":0,"kind":"data","monotonic_ns":232547000144916,"payload":{"event_type":"price_change","market":"0x3b40066b5cf3871a2f6237c5628bd8092a206aa998558ac5ec13c4483e31e160","price_changes":[{"asset_id":"14766054693214075530629349735273995982307625376442606753688071083149620216746","best_ask":"0.33","best_bid":"0.31","hash":"4c17c3814c70cb42b3e3712397bab59e08489bd6","price":"0.3","side":"BUY","size":"138.6"},{"asset_id":"110216635572655435074987471276357323571387854733835379371586402147734167783946","best_ask":"0.69","best_bid":"0.67","hash":"c2631e19bd5aa41599d53d6bcb958db95d9b329b","price":"0.7","side":"SELL","size":"138.6"}],"timestamp":"1785130563799"},"payload_hash":"8cbc36816f199256a1d927e17be815e7ac53626c909f108469addd1659254ae4","raw_frame":"{\"market\":\"0x3b40066b5cf3871a2f6237c5628bd8092a206aa998558ac5ec13c4483e31e160\", \"price_changes\":[{\"asset_id\":\"14766054693214075530629349735273995982307625376442606753688071083149620216746\", \"price\":\"0.3\", \"size\":\"138.6\", \"side\":\"BUY\", \"hash\":\"4c17c3814c70cb42b3e3712397bab59e08489bd6\", \"best_bid\":\"0.31\", \"best_ask\":\"0.33\"}, {\"asset_id\":\"110216635572655435074987471276357323571387854733835379371586402147734167783946\", \"price\":\"0.7\", \"size\":\"138.6\", \"side\":\"SELL\", \"hash\":\"c2631e19bd5aa41599d53d6bcb958db95d9b329b\", \"best_bid\":\"0.67\", \"best_ask\":\"0.69\"}], \"timestamp\":\"1785130563799\", \"event_type\":\"price_change\"}","received_at":"2026-07-27T05:36:03.764469Z","schema_version":"clob-market-ws.price_change.v1","sequence":null,"server_hash":null,"server_timestamp":"1785130563799","session_id":"502006c5cfcd437296561ea750c9ec8b","source":"clob_market_ws"},"received_at":"2026-07-27T05:36:03.764469Z","record_id":"7495f010fca37dea37f2662b50759cfc5def8018a327a74708fb029dda6cdb8c","schema_fingerprint":"4aa3821a28b0b7c2400bc59aba4bcc0a76e971dadd19610d3ad38c768e124dc7","schema_version":"edge-lab-recorder.raw.v1","sequence":null,"source":"clob_market_ws"}
{"event_at":"2026-07-27T05:36:03.800000Z","event_fingerprint":"44dafeaf5921c8384c9a2578108d3ebf2c88e8aabd2fa882251335359d9b2048","payload":{"connection_id":"efc69d3132f1467b8e898a382b23ac0d","event_at":"2026-07-27T05:36:03.800000Z","event_type":"price_change","frame_hash":"71191b8245427d81fc4e0103410bc5eb3fd2ca1020841b509803f979ee335f29","frame_index":0,"kind":"data","monotonic_ns":232547004468791,"payload":{"event_type":"price_change","market":"0x3b40066b5cf3871a2f6237c5628bd8092a206aa998558ac5ec13c4483e31e160","price_changes":[{"asset_id":"14766054693214075530629349735273995982307625376442606753688071083149620216746","best_ask":"0.33","best_bid":"0.31","hash":"75171b80d83159d487fa3c6dc70d0545d7779a31","price":"0.34","side":"SELL","size":"111.66"},{"asset_id":"110216635572655435074987471276357323571387854733835379371586402147734167783946","best_ask":"0.69","best_bid":"0.67","hash":"a9ea1d0ee7f066cc6ca65b19228aebe32bfb7667","price":"0.66","side":"BUY","size":"111.66"}],"timestamp":"1785130563800"},"payload_hash":"8553128c9a18433077520befa83f29a092301c89e6fd08262a4b27d9b737098d","raw_frame":"{\"market\":\"0x3b40066b5cf3871a2f6237c5628bd8092a206aa998558ac5ec13c4483e31e160\", \"price_changes\":[{\"asset_id\":\"14766054693214075530629349735273995982307625376442606753688071083149620216746\", \"price\":\"0.34\", \"size\":\"111.66\", \"side\":\"SELL\", \"hash\":\"75171b80d83159d487fa3c6dc70d0545d7779a31\", \"best_bid\":\"0.31\", \"best_ask\":\"0.33\"}, {\"asset_id\":\"110216635572655435074987471276357323571387854733835379371586402147734167783946\", \"price\":\"0.66\", \"size\":\"111.66\", \"side\":\"BUY\", \"hash\":\"a9ea1d0ee7f066cc6ca65b19228aebe32bfb7667\", \"best_bid\":\"0.67\", \"best_ask\":\"0.69\"}], \"timestamp\":\"1785130563800\", \"event_type\":\"price_change\"}","received_at":"2026-07-27T05:36:03.768785Z","schema_version":"clob-market-ws.price_change.v1","sequence":null,"server_hash":null,"server_timestamp":"1785130563800","session_id":"502006c5cfcd437296561ea750c9ec8b","source":"clob_market_ws"},"received_at":"2026-07-27T05:36:03.768785Z","record_id":"490311d0f2ff2b572a941f01216017deb482c38a387451d6361a559eab1e1d76","schema_fingerprint":"4aa3821a28b0b7c2400bc59aba4bcc0a76e971dadd19610d3ad38c768e124dc7","schema_version":"edge-lab-recorder.raw.v1","sequence":null,"source":"clob_market_ws"}
{"event_at":"2026-07-27T05:36:03.801000Z","event_fingerprint":"81cab1cf6fcc91e73e9bfaae30346cb5a54a593c30316a18f4f2b5ae7495342b","payload":{"connection_id":"efc69d3132f1467b8e898a382b23ac0d","event_at":"2026-07-27T05:36:03.801000Z","event_type":"price_change","frame_hash":"6b3a2dc188eacad7e867a9b26f6e37bf6e5dcd66430c3cbe738668fdb1407628","frame_index":0,"kind":"data","monotonic_ns":232547008574166,"payload":{"event_type":"price_change","market":"0x3b40066b5cf3871a2f6237c5628bd8092a206aa998558ac5ec13c4483e31e160","price_changes":[{"asset_id":"110216635572655435074987471276357323571387854733835379371586402147734167783946","best_ask":"0.69","best_bid":"0.67","hash":"8ce17165cc3a88cba9681e7c701070228a2439f5","price":"0.03","side":"BUY","size":"648.1"},{"asset_id":"14766054693214075530629349735273995982307625376442606753688071083149620216746","best_ask":"0.33","best_bid":"0.31","hash":"4a4d382a44ce03428dc88b9ec929737f21f2bdd4","price":"0.97","side":"SELL","size":"648.1"}],"timestamp":"1785130563801"},"payload_hash":"d6b040a894e34b092207dfbfe45abbcc245def7b76ad6aeea52d597267b3bbb7","raw_frame":"{\"market\":\"0x3b40066b5cf3871a2f6237c5628bd8092a206aa998558ac5ec13c4483e31e160\", \"price_changes\":[{\"asset_id\":\"110216635572655435074987471276357323571387854733835379371586402147734167783946\", \"price\":\"0.03\", \"size\":\"648.1\", \"side\":\"BUY\", \"hash\":\"8ce17165cc3a88cba9681e7c701070228a2439f5\", \"best_bid\":\"0.67\", \"best_ask\":\"0.69\"}, {\"asset_id\":\"14766054693214075530629349735273995982307625376442606753688071083149620216746\", \"price\":\"0.97\", \"size\":\"648.1\", \"side\":\"SELL\", \"hash\":\"4a4d382a44ce03428dc88b9ec929737f21f2bdd4\", \"best_bid\":\"0.31\", \"best_ask\":\"0.33\"}], \"timestamp\":\"1785130563801\", \"event_type\":\"price_change\"}","received_at":"2026-07-27T05:36:03.772892Z","schema_version":"clob-market-ws.price_change.v1","sequence":null,"server_hash":null,"server_timestamp":"1785130563801","session_id":"502006c5cfcd437296561ea750c9ec8b","source":"clob_market_ws"},"received_at":"2026-07-27T05:36:03.772892Z","record_id":"5e0bc3440d14e02a73d6688cc3d8f99d90f2949b7fe7d1c2c9e37445246bb736","schema_fingerprint":"4aa3821a28b0b7c2400bc59aba4bcc0a76e971dadd19610d3ad38c768e124dc7","schema_version":"edge-lab-recorder.raw.v1","sequence":null,"source":"clob_market_ws"}
{"event_at":"2026-07-27T05:36:03.804000Z","event_fingerprint":"170c9b7b3972cd8e242ef5d570e556fedf7c1c789597ccb70aa6f0dd18772bae","payload":{"connection_id":"efc69d3132f1467b8e898a382b23ac0d","event_at":"2026-07-27T05:36:03.804000Z","event_type":"price_change","frame_hash":"48f140369e8e2ada8b1c86469a441ddb6b23e5c2a297c4a3fa7a3ffdc14fd4d0","frame_index":0,"kind":"data","monotonic_ns":232547013166708,"payload":{"event_type":"price_change","market":"0x3b40066b5cf3871a2f6237c5628bd8092a206aa998558ac5ec13c4483e31e160","price_changes":[{"asset_id":"110216635572655435074987471276357323571387854733835379371586402147734167783946","best_ask":"0.69","best_bid":"0.67","hash":"c6897946c5956a958b87789cf22709a93d6b3252","price":"0.66","side":"BUY","size":"135.6"},{"asset_id":"14766054693214075530629349735273995982307625376442606753688071083149620216746","best_ask":"0.33","best_bid":"0.31","hash":"e82ccbfa9a7978105832171ca6ba2eca59c108c6","price":"0.34","side":"SELL","size":"135.6"}],"timestamp":"1785130563804"},"payload_hash":"a236d1190bb5184c24104006c188737442f539e82826a2f3662e42713082487a","raw_frame":"{\"market\":\"0x3b40066b5cf3871a2f6237c5628bd8092a206aa998558ac5ec13c4483e31e160\", \"price_changes\":[{\"asset_id\":\"110216635572655435074987471276357323571387854733835379371586402147734167783946\", \"price\":\"0.66\", \"size\":\"135.6\", \"side\":\"BUY\", \"hash\":\"c6897946c5956a958b87789cf22709a93d6b3252\", \"best_bid\":\"0.67\", \"best_ask\":\"0.69\"}, {\"asset_id\":\"14766054693214075530629349735273995982307625376442606753688071083149620216746\", \"price\":\"0.34\", \"size\":\"135.6\", \"side\":\"SELL\", \"hash\":\"e82ccbfa9a7978105832171ca6ba2eca59c108c6\", \"best_bid\":\"0.31\", \"best_ask\":\"0.33\"}], \"timestamp\":\"1785130563804\", \"event_type\":\"price_change\"}","received_at":"2026-07-27T05:36:03.777484Z","schema_version":"clob-market-ws.price_change.v1","sequence":null,"server_hash":null,"server_timestamp":"1785130563804","session_id":"502006c5cfcd437296561ea750c9ec8b","source":"clob_market_ws"},"received_at":"2026-07-27T05:36:03.777484Z","record_id":"ffafeaea7f02e08463fef124ae804bd276be624ba24428701d8f91e57bcc59c5","schema_fingerprint":"4aa3821a28b0b7c2400bc59aba4bcc0a76e971dadd19610d3ad38c768e124dc7","schema_version":"edge-lab-recorder.raw.v1","sequence":null,"source":"clob_market_ws"}
{"event_at":"2026-07-27T05:36:03.815000Z","event_fingerprint":"c75f9770eca89aaf9ebe5da78a6f4953e62610192025ef68316444dfd8d3cc84","payload":{"connection_id":"efc69d3132f1467b8e898a382b23ac0d","event_at":"2026-07-27T05:36:03.815000Z","event_type":"price_change","frame_hash":"debd873e90b67ba5cdc9d7c9517b2d0cbd41cd7ca9b282d755a4e26317acb5bd","frame_index":0,"kind":"data","monotonic_ns":232547016846791,"payload":{"event_type":"price_change","market":"0x3b40066b5cf3871a2f6237c5628bd8092a206aa998558ac5ec13c4483e31e160","price_changes":[{"asset_id":"14766054693214075530629349735273995982307625376442606753688071083149620216746","best_ask":"0.33","best_bid":"0.31","hash":"14c5d20f805c4bb6b2cb320ffd49a8c7d7c59839","price":"0.25","side":"BUY","size":"304"},{"asset_id":"110216635572655435074987471276357323571387854733835379371586402147734167783946","best_ask":"0.69","best_bid":"0.67","hash":"4f456b3e41a53cc9c062c7cfcb0475a7c0f45f22","price":"0.75","side":"SELL","size":"304"}],"timestamp":"1785130563815"},"payload_hash":"f26b0c89ee03855fa0194e2efdbc76e04aa68af221189ba4ffde74df275f7563","raw_frame":"{\"market\":\"0x3b40066b5cf3871a2f6237c5628bd8092a206aa998558ac5ec13c4483e31e160\", \"price_changes\":[{\"asset_id\":\"14766054693214075530629349735273995982307625376442606753688071083149620216746\", \"price\":\"0.25\", \"size\":\"304\", \"side\":\"BUY\", \"hash\":\"14c5d20f805c4bb6b2cb320ffd49a8c7d7c59839\", \"best_bid\":\"0.31\", \"best_ask\":\"0.33\"}, {\"asset_id\":\"110216635572655435074987471276357323571387854733835379371586402147734167783946\", \"price\":\"0.75\", \"size\":\"304\", \"side\":\"SELL\", \"hash\":\"4f456b3e41a53cc9c062c7cfcb0475a7c0f45f22\", \"best_bid\":\"0.67\", \"best_ask\":\"0.69\"}], \"timestamp\":\"1785130563815\", \"event_type\":\"price_change\"}","received_at":"2026-07-27T05:36:03.781170Z","schema_version":"clob-market-ws.price_change.v1","sequence":null,"server_hash":null,"server_timestamp":"1785130563815","session_id":"502006c5cfcd437296561ea750c9ec8b","source":"clob_market_ws"},"received_at":"2026-07-27T05:36:03.781170Z","record_id":"c2a17305aa22dea96bc38256ed7f29f1c2c1233c1407a2bf308535e843da7421","schema_fingerprint":"4aa3821a28b0b7c2400bc59aba4bcc0a76e971dadd19610d3ad38c768e124dc7","schema_version":"edge-lab-recorder.raw.v1","sequence":null,"source":"clob_market_ws"}
{"event_at":"2026-07-27T05:36:03.821000Z","event_fingerprint":"29fa64cfae31f3bf629f4b056ed873e6ace578902c5eb48819d86991a2e82933","payload":{"connection_id":"efc69d3132f1467b8e898a382b23ac0d","event_at":"2026-07-27T05:36:03.821000Z","event_type":"price_change","frame_hash":"0938244059f994683735aa2d3393b9f649ab51ca7740c26bed1c130cec20aa00","frame_index":0,"kind":"data","monotonic_ns":232547029721291,"payload":{"event_type":"price_change","market":"0x3b40066b5cf3871a2f6237c5628bd8092a206aa998558ac5ec13c4483e31e160","price_changes":[{"asset_id":"14766054693214075530629349735273995982307625376442606753688071083149620216746","best_ask":"0.33","best_bid":"0.31","hash":"9e8711800e4deeba940b79bf7a52c63a3a6ae90f","price":"0.22","side":"BUY","size":"271.49"},{"asset_id":"110216635572655435074987471276357323571387854733835379371586402147734167783946","best_ask":"0.69","best_bid":"0.67","hash":"3bf1943b298b2fd090b41853b3012f66c96f8a85","price":"0.78","side":"SELL","size":"271.49"}],"timestamp":"1785130563821"},"payload_hash":"b734a674de971ddc58062e927b0eb8eae4d969deccb1f2f4b36d752d614ab604","raw_frame":"{\"market\":\"0x3b40066b5cf3871a2f6237c5628bd8092a206aa998558ac5ec13c4483e31e160\", \"price_changes\":[{\"asset_id\":\"14766054693214075530629349735273995982307625376442606753688071083149620216746\", \"price\":\"0.22\", \"size\":\"271.49\", \"side\":\"BUY\", \"hash\":\"9e8711800e4deeba940b79bf7a52c63a3a6ae90f\", \"best_bid\":\"0.31\", \"best_ask\":\"0.33\"}, {\"asset_id\":\"110216635572655435074987471276357323571387854733835379371586402147734167783946\", \"price\":\"0.78\", \"size\":\"271.49\", \"side\":\"SELL\", \"hash\":\"3bf1943b298b2fd090b41853b3012f66c96f8a85\", \"best_bid\":\"0.67\", \"best_ask\":\"0.69\"}], \"timestamp\":\"1785130563821\", \"event_type\":\"price_change\"}","received_at":"2026-07-27T05:36:03.794040Z","schema_version":"clob-market-ws.price_change.v1","sequence":null,"server_hash":null,"server_timestamp":"1785130563821","session_id":"502006c5cfcd437296561ea750c9ec8b","source":"clob_market_ws"},"received_at":"2026-07-27T05:36:03.794040Z","record_id":"95e6e9e86b25fc26c551ce7fffe07cb0dee45ba0d215d9b8aff67feee3a2f8ff","schema_fingerprint":"4aa3821a28b0b7c2400bc59aba4bcc0a76e971dadd19610d3ad38c768e124dc7","schema_version":"edge-lab-recorder.raw.v1","sequence":null,"source":"clob_market_ws"}
{"event_at":"2026-07-27T05:36:03.833000Z","event_fingerprint":"736526f6a85f1ac76954ffcc571ff282cacaf97bb240520edf1819ea02ef7e65","payload":{"connection_id":"efc69d3132f1467b8e898a382b23ac0d","event_at":"2026-07-27T05:36:03.833000Z","event_type":"price_change","frame_hash":"94873d8dd3e63c4a22474f986f0edaa33ec6ed626c6db28668a6ad027ea82374","frame_index":0,"kind":"data","monotonic_ns":232547033168166,"payload":{"event_type":"price_change","market":"0x3b40066b5cf3871a2f6237c5628bd8092a206aa998558ac5ec13c4483e31e160","price_changes":[{"asset_id":"14766054693214075530629349735273995982307625376442606753688071083149620216746","best_ask":"0.33","best_bid":"0.31","hash":"e2854e9afb7d296648a725cdbe4dad1ca7e64004","price":"0.29","side":"BUY","size":"165.4"},{"asset_id":"110216635572655435074987471276357323571387854733835379371586402147734167783946","best_ask":"0.69","best_bid":"0.67","hash":"4ff81cde435100208f6f81f9bb74fe667d3ffcb5","price":"0.71","side":"SELL","size":"165.4"}],"timestamp":"1785130563833"},"payload_hash":"b8373f774da738fe3be6a1bf8f6dfbb1ccf59301b652d9eade4d1ac702b63bed","raw_frame":"{\"market\":\"0x3b40066b5cf3871a2f6237c5628bd8092a206aa998558ac5ec13c4483e31e160\", \"price_changes\":[{\"asset_id\":\"14766054693214075530629349735273995982307625376442606753688071083149620216746\", \"price\":\"0.29\", \"size\":\"165.4\", \"side\":\"BUY\", \"hash\":\"e2854e9afb7d296648a725cdbe4dad1ca7e64004\", \"best_bid\":\"0.31\", \"best_ask\":\"0.33\"}, {\"asset_id\":\"110216635572655435074987471276357323571387854733835379371586402147734167783946\", \"price\":\"0.71\", \"size\":\"165.4\", \"side\":\"SELL\", \"hash\":\"4ff81cde435100208f6f81f9bb74fe667d3ffcb5\", \"best_bid\":\"0.67\", \"best_ask\":\"0.69\"}], \"timestamp\":\"1785130563833\", \"event_type\":\"price_change\"}","received_at":"2026-07-27T05:36:03.797492Z","schema_version":"clob-market-ws.price_change.v1","sequence":null,"server_hash":null,"server_timestamp":"1785130563833","session_id":"502006c5cfcd437296561ea750c9ec8b","source":"clob_market_ws"},"received_at":"2026-07-27T05:36:03.797492Z","record_id":"4e3770f7eb9e2dc8670b01da41cbf20ed34b9723d27d51f85ccf5bbb9d489c85","schema_fingerprint":"4aa3821a28b0b7c2400bc59aba4bcc0a76e971dadd19610d3ad38c768e124dc7","schema_version":"edge-lab-recorder.raw.v1","sequence":null,"source":"clob_market_ws"}
{"event_at":"2026-07-27T05:36:03.837000Z","event_fingerprint":"6bed6c9409ae66e212aafe0eadc6d9abdeb5972252a8b22bfcfa67fa2db0a406","payload":{"connection_id":"efc69d3132f1467b8e898a382b23ac0d","event_at":"2026-07-27T05:36:03.837000Z","event_type":"price_change","frame_hash":"b7146b9700a1b4f5dd71c4a2d3b8a44fa131527b8fef5c51503c280886b05488","frame_index":0,"kind":"data","monotonic_ns":232547043862458,"payload":{"event_type":"price_change","market":"0x3b40066b5cf3871a2f6237c5628bd8092a206aa998558ac5ec13c4483e31e160","price_changes":[{"asset_id":"14766054693214075530629349735273995982307625376442606753688071083149620216746","best_ask":"0.33","best_bid":"0.31","hash":"fb6646610ce1dba2768738b5aaf55772e3838159","price":"0.3","side":"BUY","size":"42.6"},{"asset_id":"110216635572655435074987471276357323571387854733835379371586402147734167783946","best_ask":"0.69","best_bid":"0.67","hash":"6672d713c6ee414cf850a4e3c49002b2f412f7b6","price":"0.7","side":"SELL","size":"42.6"}],"timestamp":"1785130563837"},"payload_hash":"086ba5b30d8c6fb3163f003106953fd0017462244285f3c777d5f8bfb1fb51b4","raw_frame":"{\"market\":\"0x3b40066b5cf3871a2f6237c5628bd8092a206aa998558ac5ec13c4483e31e160\", \"price_changes\":[{\"asset_id\":\"14766054693214075530629349735273995982307625376442606753688071083149620216746\", \"price\":\"0.3\", \"size\":\"42.6\", \"side\":\"BUY\", \"hash\":\"fb6646610ce1dba2768738b5aaf55772e3838159\", \"best_bid\":\"0.31\", \"best_ask\":\"0.33\"}, {\"asset_id\":\"110216635572655435074987471276357323571387854733835379371586402147734167783946\", \"price\":\"0.7\", \"size\":\"42.6\", \"side\":\"SELL\", \"hash\":\"6672d713c6ee414cf850a4e3c49002b2f412f7b6\", \"best_bid\":\"0.67\", \"best_ask\":\"0.69\"}], \"timestamp\":\"1785130563837\", \"event_type\":\"price_change\"}","received_at":"2026-07-27T05:36:03.808174Z","schema_version":"clob-market-ws.price_change.v1","sequence":null,"server_hash":null,"server_timestamp":"1785130563837","session_id":"502006c5cfcd437296561ea750c9ec8b","source":"clob_market_ws"},"received_at":"2026-07-27T05:36:03.808174Z","record_id":"c52571fd14e191bbcdeff10a126a6fcd31ab1a86857d829b510ead543aff4026","schema_fingerprint":"4aa3821a28b0b7c2400bc59aba4bcc0a76e971dadd19610d3ad38c768e124dc7","schema_version":"edge-lab-recorder.raw.v1","sequence":null,"source":"clob_market_ws"}
{"event_at":"2026-07-27T05:36:03.840000Z","event_fingerprint":"b7148ea7258d39c94a68301c404ca7339a2e5d209b962e7e8b36d43c8fe9527c","payload":{"connection_id":"efc69d3132f1467b8e898a382b23ac0d","event_at":"2026-07-27T05:36:03.840000Z","event_type":"price_change","frame_hash":"8b77185a021e4d82d4a8dbcf9dd55e67ef625f1edfb446a1ec554fb633c283fd","frame_index":0,"kind":"data","monotonic_ns":232547047262041,"payload":{"event_type":"price_change","market":"0x3b40066b5cf3871a2f6237c5628bd8092a206aa998558ac5ec13c4483e31e160","price_changes":[{"asset_id":"14766054693214075530629349735273995982307625376442606753688071083149620216746","best_ask":"0.33","best_bid":"0.31","hash":"887d43ef2fb3a09f4aaf27ecf6fad7288b9c2f49","price":"0.3","side":"BUY","size":"33"},{"asset_id":"110216635572655435074987471276357323571387854733835379371586402147734167783946","best_ask":"0.69","best_bid":"0.67","hash":"cc90e8de062d9b5a37a0bf8dbf1b264d2e9e06fd","price":"0.7","side":"SELL","size":"33"}],"timestamp":"1785130563840"},"payload_hash":"df0d76d3af42690d355936494e9201b880e74850963706a8d5a3cf9f29d5606b","raw_frame":"{\"market\":\"0x3b40066b5cf3871a2f6237c5628bd8092a206aa998558ac5ec13c4483e31e160\", \"price_changes\":[{\"asset_id\":\"14766054693214075530629349735273995982307625376442606753688071083149620216746\", \"price\":\"0.3\", \"size\":\"33\", \"side\":\"BUY\", \"hash\":\"887d43ef2fb3a09f4aaf27ecf6fad7288b9c2f49\", \"best_bid\":\"0.31\", \"best_ask\":\"0.33\"}, {\"asset_id\":\"110216635572655435074987471276357323571387854733835379371586402147734167783946\", \"price\":\"0.7\", \"size\":\"33\", \"side\":\"SELL\", \"hash\":\"cc90e8de062d9b5a37a0bf8dbf1b264d2e9e06fd\", \"best_bid\":\"0.67\", \"best_ask\":\"0.69\"}], \"timestamp\":\"1785130563840\", \"event_type\":\"price_change\"}","received_at":"2026-07-27T05:36:03.811581Z","schema_version":"clob-market-ws.price_change.v1","sequence":null,"server_hash":null,"server_timestamp":"1785130563840","session_id":"502006c5cfcd437296561ea750c9ec8b","source":"clob_market_ws"},"received_at":"2026-07-27T05:36:03.811581Z","record_id":"ed9047d37c8ce316eb8aca65a02fa8a4933f853fedc79b51d46400c44724fa69","schema_fingerprint":"4aa3821a28b0b7c2400bc59aba4bcc0a76e971dadd19610d3ad38c768e124dc7","schema_version":"edge-lab-recorder.raw.v1","sequence":null,"source":"clob_market_ws"}
{"event_at":"2026-07-27T05:36:03.844000Z","event_fingerprint":"f45b0337f0e51b00af2a78221d3c5fd1b97b658192d37d822367344fd9754de9","payload":{"connection_id":"efc69d3132f1467b8e898a382b23ac0d","event_at":"2026-07-27T05:36:03.844000Z","event_type":"best_bid_ask","frame_hash":"613ba2ce2f12121dfd87aa3615b310ce404d11c9db912cbafaeda8fc397314fe","frame_index":0,"kind":"data","monotonic_ns":232547050386041,"payload":{"asset_id":"14766054693214075530629349735273995982307625376442606753688071083149620216746","best_ask":"0.32","best_bid":"0.31","event_type":"best_bid_ask","market":"0x3b40066b5cf3871a2f6237c5628bd8092a206aa998558ac5ec13c4483e31e160","spread":"0.01","timestamp":"1785130563844"},"payload_hash":"d5886f941aa4a108c42909ed6adffb37b48d7b4d108a6bc218909c73b8a403a5","raw_frame":"{\"market\":\"0x3b40066b5cf3871a2f6237c5628bd8092a206aa998558ac5ec13c4483e31e160\", \"asset_id\":\"14766054693214075530629349735273995982307625376442606753688071083149620216746\", \"best_bid\":\"0.31\", \"best_ask\":\"0.32\", \"spread\":\"0.01\", \"timestamp\":\"1785130563844\", \"event_type\":\"best_bid_ask\"}","received_at":"2026-07-27T05:36:03.814710Z","schema_version":"clob-market-ws.best_bid_ask.v1","sequence":null,"server_hash":null,"server_timestamp":"1785130563844","session_id":"502006c5cfcd437296561ea750c9ec8b","source":"clob_market_ws"},"received_at":"2026-07-27T05:36:03.814710Z","record_id":"ab043df6b5122b67bc0083c1ab5eb6e60a3c9f273280c46e30ca8273bb05a960","schema_fingerprint":"8488399f31b0337811b13b266be932db7062827c2470b78bd8e9e99bab51d17d","schema_version":"edge-lab-recorder.raw.v1","sequence":null,"source":"clob_market_ws"}
{"event_at":"2026-07-27T05:36:03.844000Z","event_fingerprint":"abd51d06f6afb233c98803ef0d4d465eff3013ff04cae72f8c2358711c9cc12d","payload":{"connection_id":"efc69d3132f1467b8e898a382b23ac0d","event_at":"2026-07-27T05:36:03.844000Z","event_type":"best_bid_ask","frame_hash":"dc33084afb9876802ac54984017b0bee292dce8a94d8e1db637c9d16e571e7b9","frame_index":0,"kind":"data","monotonic_ns":232547054461458,"payload":{"asset_id":"110216635572655435074987471276357323571387854733835379371586402147734167783946","best_ask":"0.69","best_bid":"0.68","event_type":"best_bid_ask","market":"0x3b40066b5cf3871a2f6237c5628bd8092a206aa998558ac5ec13c4483e31e160","spread":"0.01","timestamp":"1785130563844"},"payload_hash":"ff9f7f54c9194456ec460fe90c7b28c26f289c664eac0b7054b183673fc6ba2a","raw_frame":"{\"market\":\"0x3b40066b5cf3871a2f6237c5628bd8092a206aa998558ac5ec13c4483e31e160\", \"asset_id\":\"110216635572655435074987471276357323571387854733835379371586402147734167783946\", \"best_bid\":\"0.68\", \"best_ask\":\"0.69\", \"spread\":\"0.01\", \"timestamp\":\"1785130563844\", \"event_type\":\"best_bid_ask\"}","received_at":"2026-07-27T05:36:03.818780Z","schema_version":"clob-market-ws.best_bid_ask.v1","sequence":null,"server_hash":null,"server_timestamp":"1785130563844","session_id":"502006c5cfcd437296561ea750c9ec8b","source":"clob_market_ws"},"received_at":"2026-07-27T05:36:03.818780Z","record_id":"7d35df2c44aca2c4c488829af8adf328869af00f0da921be3871be1c2fc170d2","schema_fingerprint":"8488399f31b0337811b13b266be932db7062827c2470b78bd8e9e99bab51d17d","schema_version":"edge-lab-recorder.raw.v1","sequence":null,"source":"clob_market_ws"}
{"event_at":"2026-07-27T05:36:03.843000Z","event_fingerprint":"01d1d9f1cfd69f24e491a3e36e2bf5f9bb596675335cfe48ebd8a7684c4619f2","payload":{"connection_id":"efc69d3132f1467b8e898a382b23ac0d","event_at":"2026-07-27T05:36:03.843000Z","event_type":"price_change","frame_hash":"d6fbfdbf5b2aeb23bd232d51a13a85e4c25bc526176ddb706ad15920369176d9","frame_index":0,"kind":"data","monotonic_ns":232547058521041,"payload":{"event_type":"price_change","market":"0x3b40066b5cf3871a2f6237c5628bd8092a206aa998558ac5ec13c4483e31e160","price_changes":[{"asset_id":"110216635572655435074987471276357323571387854733835379371586402147734167783946","best_ask":"0.69","best_bid":"0.68","hash":"eb87fa864869c61720662866af7917ab9b2e44dc","price":"0.68","side":"BUY","size":"9.6"},{"asset_id":"14766054693214075530629349735273995982307625376442606753688071083149620216746","best_ask":"0.32","best_bid":"0.31","hash":"a3fefd6171c690a1048b4ccf4e17a6faab0862d9","price":"0.32","side":"SELL","size":"9.6"}],"timestamp":"1785130563843"},"payload_hash":"f03c1e7db3520be709ae904a1ee3b8cd8414a7b0810bbf9e35e9061e5377261f","raw_frame":"{\"market\":\"0x3b40066b5cf3871a2f6237c5628bd8092a206aa998558ac5ec13c4483e31e160\", \"price_changes\":[{\"asset_id\":\"110216635572655435074987471276357323571387854733835379371586402147734167783946\", \"price\":\"0.68\", \"size\":\"9.6\", \"side\":\"BUY\", \"hash\":\"eb87fa864869c61720662866af7917ab9b2e44dc\", \"best_bid\":\"0.68\", \"best_ask\":\"0.69\"}, {\"asset_id\":\"14766054693214075530629349735273995982307625376442606753688071083149620216746\", \"price\":\"0.32\", \"size\":\"9.6\", \"side\":\"SELL\", \"hash\":\"a3fefd6171c690a1048b4ccf4e17a6faab0862d9\", \"best_bid\":\"0.31\", \"best_ask\":\"0.32\"}], \"timestamp\":\"1785130563843\", \"event_type\":\"price_change\"}","received_at":"2026-07-27T05:36:03.822840Z","schema_version":"clob-market-ws.price_change.v1","sequence":null,"server_hash":null,"server_timestamp":"1785130563843","session_id":"502006c5cfcd437296561ea750c9ec8b","source":"clob_market_ws"},"received_at":"2026-07-27T05:36:03.822840Z","record_id":"4a443158349458b013366610d03c48516b89511e16ccf8e798ba40ac1bef65af","schema_fingerprint":"4aa3821a28b0b7c2400bc59aba4bcc0a76e971dadd19610d3ad38c768e124dc7","schema_version":"edge-lab-recorder.raw.v1","sequence":null,"source":"clob_market_ws"}
{"event_at":"2026-07-27T05:36:03.844000Z","event_fingerprint":"fdb123fad64149caca9ee96ec123ea0799e58684e6d83eb8dd0fba7043160247","payload":{"connection_id":"efc69d3132f1467b8e898a382b23ac0d","event_at":"2026-07-27T05:36:03.844000Z","event_type":"price_change","frame_hash":"ba22ded8ce1ca27b32f4c109c30fbe0d461c32131f12c7f43614259cb6d78a6c","frame_index":0,"kind":"data","monotonic_ns":232547062465333,"payload":{"event_type":"price_change","market":"0x3b40066b5cf3871a2f6237c5628bd8092a206aa998558ac5ec13c4483e31e160","price_changes":[{"asset_id":"110216635572655435074987471276357323571387854733835379371586402147734167783946","best_ask":"0.69","best_bid":"0.68","hash":"ca6c298c19a38fd6ea169274dba86848c24dcd26","price":"0.68","side":"BUY","size":"26.4"},{"asset_id":"14766054693214075530629349735273995982307625376442606753688071083149620216746","best_ask":"0.32","best_bid":"0.31","hash":"85ccb8861e64af953ff62ebbc4bca1fad3e6e525","price":"0.32","side":"SELL","size":"26.4"}],"timestamp":"1785130563844"},"payload_hash":"f19dc1b6ad9a7c541a2d90b571961f73a0acddad442c54958a4c11b3d589d7a6","raw_frame":"{\"market\":\"0x3b40066b5cf3871a2f6237c5628bd8092a206aa998558ac5ec13c4483e31e160\", \"price_changes\":[{\"asset_id\":\"110216635572655435074987471276357323571387854733835379371586402147734167783946\", \"price\":\"0.68\", \"size\":\"26.4\", \"side\":\"BUY\", \"hash\":\"ca6c298c19a38fd6ea169274dba86848c24dcd26\", \"best_bid\":\"0.68\", \"best_ask\":\"0.69\"}, {\"asset_id\":\"14766054693214075530629349735273995982307625376442606753688071083149620216746\", \"price\":\"0.32\", \"size\":\"26.4\", \"side\":\"SELL\", \"hash\":\"85ccb8861e64af953ff62ebbc4bca1fad3e6e525\", \"best_bid\":\"0.31\", \"best_ask\":\"0.32\"}], \"timestamp\":\"1785130563844\", \"event_type\":\"price_change\"}","received_at":"2026-07-27T05:36:03.826784Z","schema_version":"clob-market-ws.price_change.v1","sequence":null,"server_hash":null,"server_timestamp":"1785130563844","session_id":"502006c5cfcd437296561ea750c9ec8b","source":"clob_market_ws"},"received_at":"2026-07-27T05:36:03.826784Z","record_id":"9bf23240bf959f8b070b3d3c3966389974b5d0f9331b70dcfbe6defa6ca9574b","schema_fingerprint":"4aa3821a28b0b7c2400bc59aba4bcc0a76e971dadd19610d3ad38c768e124dc7","schema_version":"edge-lab-recorder.raw.v1","sequence":null,"source":"clob_market_ws"}
{"event_at":"2026-07-27T05:36:03.845000Z","event_fingerprint":"d8e1e0544c215f6ab75c0b8cf535623d21da8cbfcc718d3f20535a3ba95bad1a","payload":{"connection_id":"efc69d3132f1467b8e898a382b23ac0d","event_at":"2026-07-27T05:36:03.845000Z","event_type":"price_change","frame_hash":"c0d0d0ca45df7e44e1bf917eaf42f1b98bbd5181952bce76a5bad6448d186340","frame_index":0,"kind":"data","monotonic_ns":232547069598458,"payload":{"event_type":"price_change","market":"0x3b40066b5cf3871a2f6237c5628bd8092a206aa998558ac5ec13c4483e31e160","price_changes":[{"asset_id":"110216635572655435074987471276357323571387854733835379371586402147734167783946","best_ask":"0.69","best_bid":"0.68","hash":"b5f031cdecd444cc1957ea4e65f22d4b31b21dcb","price":"0.67","side":"BUY","size":"328.4"},{"asset_id":"14766054693214075530629349735273995982307625376442606753688071083149620216746","best_ask":"0.32","best_bid":"0.31","hash":"78dfa16751364863306a2fd8703ff8ade91c3d1d","price":"0.33","side":"SELL","size":"328.4"}],"timestamp":"1785130563845"},"payload_hash":"cde4a4c44bbec0dc37b158d7a377ff6a05d84892c71e96fca3c32833ab4425e8","raw_frame":"{\"market\":\"0x3b40066b5cf3871a2f6237c5628bd8092a206aa998558ac5ec13c4483e31e160\", \"price_changes\":[{\"asset_id\":\"110216635572655435074987471276357323571387854733835379371586402147734167783946\", \"price\":\"0.67\", \"size\":\"328.4\", \"side\":\"BUY\", \"hash\":\"b5f031cdecd444cc1957ea4e65f22d4b31b21dcb\", \"best_bid\":\"0.68\", \"best_ask\":\"0.69\"}, {\"asset_id\":\"14766054693214075530629349735273995982307625376442606753688071083149620216746\", \"price\":\"0.33\", \"size\":\"328.4\", \"side\":\"SELL\", \"hash\":\"78dfa16751364863306a2fd8703ff8ade91c3d1d\", \"best_bid\":\"0.31\", \"best_ask\":\"0.32\"}], \"timestamp\":\"1785130563845\", \"event_type\":\"price_change\"}","received_at":"2026-07-27T05:36:03.833915Z","schema_version":"clob-market-ws.price_change.v1","sequence":null,"server_hash":null,"server_timestamp":"1785130563845","session_id":"502006c5cfcd437296561ea750c9ec8b","source":"clob_market_ws"},"received_at":"2026-07-27T05:36:03.833915Z","record_id":"74def6a4a186e43ca5b79a019ec65c12b93105cf76cced846b363ebdeae1142f","schema_fingerprint":"4aa3821a28b0b7c2400bc59aba4bcc0a76e971dadd19610d3ad38c768e124dc7","schema_version":"edge-lab-recorder.raw.v1","sequence":null,"source":"clob_market_ws"}
{"event_at":"2026-07-27T05:36:03.852000Z","event_fingerprint":"6e2d705aae7241db04edc6c1dcc23e035423e09f271f52a0568058932095e7e6","payload":{"connection_id":"efc69d3132f1467b8e898a382b23ac0d","event_at":"2026-07-27T05:36:03.852000Z","event_type":"price_change","frame_hash":"834a2471fa9a30a15ae96fd09babd8b58fae14824a3823cc79859e5a419dba83","frame_index":0,"kind":"data","monotonic_ns":232547085249791,"payload":{"event_type":"price_change","market":"0x3b40066b5cf3871a2f6237c5628bd8092a206aa998558ac5ec13c4483e31e160","price_changes":[{"asset_id":"110216635572655435074987471276357323571387854733835379371586402147734167783946","best_ask":"0.69","best_bid":"0.68","hash":"e1da070873f9f4401151d964fdbbcb2c11423d19","price":"0.01","side":"BUY","size":"5607.45"},{"asset_id":"14766054693214075530629349735273995982307625376442606753688071083149620216746","best_ask":"0.32","best_bid":"0.31","hash":"686e40790b8e29c937add266f6e8035cbe0c672a","price":"0.99","side":"SELL","size":"5607.45"}],"timestamp":"1785130563852"},"payload_hash":"8908b9bb27975f44c42b47b95ae76160f28f9dfba39298d48362bb42a28ec1d0","raw_frame":"{\"market\":\"0x3b40066b5cf3871a2f6237c5628bd8092a206aa998558ac5ec13c4483e31e160\", \"price_changes\":[{\"asset_id\":\"110216635572655435074987471276357323571387854733835379371586402147734167783946\", \"price\":\"0.01\", \"size\":\"5607.45\", \"side\":\"BUY\", \"hash\":\"e1da070873f9f4401151d964fdbbcb2c11423d19\", \"best_bid\":\"0.68\", \"best_ask\":\"0.69\"}, {\"asset_id\":\"14766054693214075530629349735273995982307625376442606753688071083149620216746\", \"price\":\"0.99\", \"size\":\"5607.45\", \"side\":\"SELL\", \"hash\":\"686e40790b8e29c937add266f6e8035cbe0c672a\", \"best_bid\":\"0.31\", \"best_ask\":\"0.32\"}], \"timestamp\":\"1785130563852\", \"event_type\":\"price_change\"}","received_at":"2026-07-27T05:36:03.849568Z","schema_version":"clob-market-ws.price_change.v1","sequence":null,"server_hash":null,"server_timestamp":"1785130563852","session_id":"502006c5cfcd437296561ea750c9ec8b","source":"clob_market_ws"},"received_at":"2026-07-27T05:36:03.849568Z","record_id":"6e56ef529bee4c1555818d0d97a45b314ab28ed39ba2abe5d60dec9b74338ee4","schema_fingerprint":"4aa3821a28b0b7c2400bc59aba4bcc0a76e971dadd19610d3ad38c768e124dc7","schema_version":"edge-lab-recorder.raw.v1","sequence":null,"source":"clob_market_ws"}
{"event_at":"2026-07-27T05:36:03.858000Z","event_fingerprint":"936df0d68343ccf95614ef979f2f518456018a5ec63aaa3e7275e4e387e25c22","payload":{"connection_id":"efc69d3132f1467b8e898a382b23ac0d","event_at":"2026-07-27T05:36:03.858000Z","event_type":"price_change","frame_hash":"5e9d3a96db401d24986c43be7b43dff4332c7c5f317590b2bcee6e09b1d353a8","frame_index":0,"kind":"data","monotonic_ns":232547091443083,"payload":{"event_type":"price_change","market":"0x3b40066b5cf3871a2f6237c5628bd8092a206aa998558ac5ec13c4483e31e160","price_changes":[{"asset_id":"110216635572655435074987471276357323571387854733835379371586402147734167783946","best_ask":"0.69","best_bid":"0.68","hash":"dd5446b25cae678dd05e77348c871b49d5dc6550","price":"0.03","side":"BUY","size":"643.1"},{"asset_id":"14766054693214075530629349735273995982307625376442606753688071083149620216746","best_ask":"0.32","best_bid":"0.31","hash":"44f588edb11c8991899e5e1ada53d4b69f91b4cb","price":"0.97","side":"SELL","size":"643.1"}],"timestamp":"1785130563858"},"payload_hash":"aeaec59cf5200ba04360322b683fdd55f09b0e8fbcb85f1f1344c6ec8e72ba29","raw_frame":"{\"market\":\"0x3b40066b5cf3871a2f6237c5628bd8092a206aa998558ac5ec13c4483e31e160\", \"price_changes\":[{\"asset_id\":\"110216635572655435074987471276357323571387854733835379371586402147734167783946\", \"price\":\"0.03\", \"size\":\"643.1\", \"side\":\"BUY\", \"hash\":\"dd5446b25cae678dd05e77348c871b49d5dc6550\", \"best_bid\":\"0.68\", \"best_ask\":\"0.69\"}, {\"asset_id\":\"14766054693214075530629349735273995982307625376442606753688071083149620216746\", \"price\":\"0.97\", \"size\":\"643.1\", \"side\":\"SELL\", \"hash\":\"44f588edb11c8991899e5e1ada53d4b69f91b4cb\", \"best_bid\":\"0.31\", \"best_ask\":\"0.32\"}], \"timestamp\":\"1785130563858\", \"event_type\":\"price_change\"}","received_at":"2026-07-27T05:36:03.855764Z","schema_version":"clob-market-ws.price_change.v1","sequence":null,"server_hash":null,"server_timestamp":"1785130563858","session_id":"502006c5cfcd437296561ea750c9ec8b","source":"clob_market_ws"},"received_at":"2026-07-27T05:36:03.855764Z","record_id":"cf5c8361e87de49afbdabfe70ef71fac2ae1267199e3ce0d88b86eda048bc43a","schema_fingerprint":"4aa3821a28b0b7c2400bc59aba4bcc0a76e971dadd19610d3ad38c768e124dc7","schema_version":"edge-lab-recorder.raw.v1","sequence":null,"source":"clob_market_ws"}
{"event_at":"2026-07-27T05:36:03.862000Z","event_fingerprint":"66b663f7150c38b815976a644a98d422963624f8bcde8e10609770d8a26cb1a8","payload":{"connection_id":"efc69d3132f1467b8e898a382b23ac0d","event_at":"2026-07-27T05:36:03.862000Z","event_type":"price_change","frame_hash":"28dc01d8d02cf82be2393259e7584b8b68a71c90787a0c3d69d69b8c44c33f5c","frame_index":0,"kind":"data","monotonic_ns":232547094218125,"payload":{"event_type":"price_change","market":"0x3b40066b5cf3871a2f6237c5628bd8092a206aa998558ac5ec13c4483e31e160","price_changes":[{"asset_id":"110216635572655435074987471276357323571387854733835379371586402147734167783946","best_ask":"0.69","best_bid":"0.68","hash":"f727f566c81834e15f590982511d4f2b81f3ed9f","price":"0.67","side":"BUY","size":"318.4"},{"asset_id":"14766054693214075530629349735273995982307625376442606753688071083149620216746","best_ask":"0.32","best_bid":"0.31","hash":"96d6db22ec27f48854fc7a8b228b597bbfd74b8e","price":"0.33","side":"SELL","size":"318.4"}],"timestamp":"1785130563862"},"payload_hash":"59a7048a58c02ef3db5c5013cfaf75dad0adefdb64debc0e831da973de85bda3","raw_frame":"{\"market\":\"0x3b40066b5cf3871a2f6237c5628bd8092a206aa998558ac5ec13c4483e31e160\", \"price_changes\":[{\"asset_id\":\"110216635572655435074987471276357323571387854733835379371586402147734167783946\", \"price\":\"0.67\", \"size\":\"318.4\", \"side\":\"BUY\", \"hash\":\"f727f566c81834e15f590982511d4f2b81f3ed9f\", \"best_bid\":\"0.68\", \"best_ask\":\"0.69\"}, {\"asset_id\":\"14766054693214075530629349735273995982307625376442606753688071083149620216746\", \"price\":\"0.33\", \"size\":\"318.4\", \"side\":\"SELL\", \"hash\":\"96d6db22ec27f48854fc7a8b228b597bbfd74b8e\", \"best_bid\":\"0.31\", \"best_ask\":\"0.32\"}], \"timestamp\":\"1785130563862\", \"event_type\":\"price_change\"}","received_at":"2026-07-27T05:36:03.858540Z","schema_version":"clob-market-ws.price_change.v1","sequence":null,"server_hash":null,"server_timestamp":"1785130563862","session_id":"502006c5cfcd437296561ea750c9ec8b","source":"clob_market_ws"},"received_at":"2026-07-27T05:36:03.858540Z","record_id":"b5d3fb5c748b9e3f3cc57b19bad84c2d748fa7ca2b946fcdf23bf2cbcdcb509c","schema_fingerprint":"4aa3821a28b0b7c2400bc59aba4bcc0a76e971dadd19610d3ad38c768e124dc7","schema_version":"edge-lab-recorder.raw.v1","sequence":null,"source":"clob_market_ws"}
{"event_at":"2026-07-27T05:36:03.864000Z","event_fingerprint":"e5365e522388ac6390c8506e2c70b93aa3c6481a7d9c68212337e44f774242a3","payload":{"connection_id":"efc69d3132f1467b8e898a382b23ac0d","event_at":"2026-07-27T05:36:03.864000Z","event_type":"price_change","frame_hash":"eacfa3228c0cfd7e6b424b976ca07c5f29248dd1ec51855228eac610ac70e985","frame_index":0,"kind":"data","monotonic_ns":232547097288708,"payload":{"event_type":"price_change","market":"0x3b40066b5cf3871a2f6237c5628bd8092a206aa998558ac5ec13c4483e31e160","price_changes":[{"asset_id":"14766054693214075530629349735273995982307625376442606753688071083149620216746","best_ask":"0.32","best_bid":"0.31","hash":"c5ed8066dfc0e00c4b5ee16ed6c9c29deef75341","price":"0.28","side":"BUY","size":"52.43"},{"asset_id":"110216635572655435074987471276357323571387854733835379371586402147734167783946","best_ask":"0.69","best_bid":"0.68","hash":"e01a0a24ed7f897a9fea166d425f6392ca5fbb3d","price":"0.72","side":"SELL","size":"52.43"}],"timestamp":"1785130563864"},"payload_hash":"7873172472ee62e17fc300f88f320a95993cb2083f6d78d72b26022c89b58aca","raw_frame":"{\"market\":\"0x3b40066b5cf3871a2f6237c5628bd8092a206aa998558ac5ec13c4483e31e160\", \"price_changes\":[{\"asset_id\":\"14766054693214075530629349735273995982307625376442606753688071083149620216746\", \"price\":\"0.28\", \"size\":\"52.43\", \"side\":\"BUY\", \"hash\":\"c5ed8066dfc0e00c4b5ee16ed6c9c29deef75341\", \"best_bid\":\"0.31\", \"best_ask\":\"0.32\"}, {\"asset_id\":\"110216635572655435074987471276357323571387854733835379371586402147734167783946\", \"price\":\"0.72\", \"size\":\"52.43\", \"side\":\"SELL\", \"hash\":\"e01a0a24ed7f897a9fea166d425f6392ca5fbb3d\", \"best_bid\":\"0.68\", \"best_ask\":\"0.69\"}], \"timestamp\":\"1785130563864\", \"event_type\":\"price_change\"}","received_at":"2026-07-27T05:36:03.861611Z","schema_version":"clob-market-ws.price_change.v1","sequence":null,"server_hash":null,"server_timestamp":"1785130563864","session_id":"502006c5cfcd437296561ea750c9ec8b","source":"clob_market_ws"},"received_at":"2026-07-27T05:36:03.861611Z","record_id":"966005cd352d8b586c89e52321049b83bb0884a73f9e25da823cb285c1cd2f0b","schema_fingerprint":"4aa3821a28b0b7c2400bc59aba4bcc0a76e971dadd19610d3ad38c768e124dc7","schema_version":"edge-lab-recorder.raw.v1","sequence":null,"source":"clob_market_ws"}
{"event_at":"2026-07-27T05:36:03.865000Z","event_fingerprint":"a46e311d8a4504ad05a822feb82981b4f328807df7b5aff9923cf18a11755625","payload":{"connection_id":"efc69d3132f1467b8e898a382b23ac0d","event_at":"2026-07-27T05:36:03.865000Z","event_type":"price_change","frame_hash":"f0d613dc986c56df029e16db31192d8528370b4fa997acf60669c19ef7d63a2b","frame_index":0,"kind":"data","monotonic_ns":232547100073458,"payload":{"event_type":"price_change","market":"0x3b40066b5cf3871a2f6237c5628bd8092a206aa998558ac5ec13c4483e31e160","price_changes":[{"asset_id":"14766054693214075530629349735273995982307625376442606753688071083149620216746","best_ask":"0.32","best_bid":"0.31","hash":"ad77e7cd9fc59f714f180258727cfa1bab4dcb1b","price":"0.29","side":"BUY","size":"69.4"},{"asset_id":"110216635572655435074987471276357323571387854733835379371586402147734167783946","best_ask":"0.69","best_bid":"0.68","hash":"7b6f094e810536ff979c758e7690b03e5088bf84","price":"0.71","side":"SELL","size":"69.4"}],"timestamp":"1785130563865"},"payload_hash":"6fceeb843e376f68f5d899a87a49df92fd7b0c915b1adf05e79742b6d7f234f3","raw_frame":"{\"market\":\"0x3b40066b5cf3871a2f6237c5628bd8092a206aa998558ac5ec13c4483e31e160\", \"price_changes\":[{\"asset_id\":\"14766054693214075530629349735273995982307625376442606753688071083149620216746\", \"price\":\"0.29\", \"size\":\"69.4\", \"side\":\"BUY\", \"hash\":\"ad77e7cd9fc59f714f180258727cfa1bab4dcb1b\", \"best_bid\":\"0.31\", \"best_ask\":\"0.32\"}, {\"asset_id\":\"110216635572655435074987471276357323571387854733835379371586402147734167783946\", \"price\":\"0.71\", \"size\":\"69.4\", \"side\":\"SELL\", \"hash\":\"7b6f094e810536ff979c758e7690b03e5088bf84\", \"best_bid\":\"0.68\", \"best_ask\":\"0.69\"}], \"timestamp\":\"1785130563865\", \"event_type\":\"price_change\"}","received_at":"2026-07-27T05:36:03.864398Z","schema_version":"clob-market-ws.price_change.v1","sequence":null,"server_hash":null,"server_timestamp":"1785130563865","session_id":"502006c5cfcd437296561ea750c9ec8b","source":"clob_market_ws"},"received_at":"2026-07-27T05:36:03.864398Z","record_id":"972bcc239b1f8d622f594890c5b10b97e22ed1c620cbb72c5914fe0dec0f1d1f","schema_fingerprint":"4aa3821a28b0b7c2400bc59aba4bcc0a76e971dadd19610d3ad38c768e124dc7","schema_version":"edge-lab-recorder.raw.v1","sequence":null,"source":"clob_market_ws"}
{"event_at":"2026-07-27T05:36:03.867000Z","event_fingerprint":"eb70fff09aba6059189939dbf57a6ba1ff69f6e83168d792ae157e728818004e","payload":{"connection_id":"efc69d3132f1467b8e898a382b23ac0d","event_at":"2026-07-27T05:36:03.867000Z","event_type":"price_change","frame_hash":"6857ea6bda9fdd06d868489402bd9b8bcf42b67f27af3787f9ad9137c72705be","frame_index":0,"kind":"data","monotonic_ns":232547103337583,"payload":{"event_type":"price_change","market":"0x3b40066b5cf3871a2f6237c5628bd8092a206aa998558ac5ec13c4483e31e160","price_changes":[{"asset_id":"110216635572655435074987471276357323571387854733835379371586402147734167783946","best_ask":"0.69","best_bid":"0.68","hash":"7132f70ff584449c14896bd16d60b947d7cac0ca","price":"0.68","side":"BUY","size":"33.18"},{"asset_id":"14766054693214075530629349735273995982307625376442606753688071083149620216746","best_ask":"0.32","best_bid":"0.31","hash":"6de846d1adffb947d2241a273e89d81fec2632b1","price":"0.32","side":"SELL","size":"33.18"}],"timestamp":"1785130563867"},"payload_hash":"7f6088e8f917fc12f3f7a87a1869d9eec24546440a4a1d1436e339bd217919c2","raw_frame":"{\"market\":\"0x3b40066b5cf3871a2f6237c5628bd8092a206aa998558ac5ec13c4483e31e160\", \"price_changes\":[{\"asset_id\":\"110216635572655435074987471276357323571387854733835379371586402147734167783946\", \"price\":\"0.68\", \"size\":\"33.18\", \"side\":\"BUY\", \"hash\":\"7132f70ff584449c14896bd16d60b947d7cac0ca\", \"best_bid\":\"0.68\", \"best_ask\":\"0.69\"}, {\"asset_id\":\"14766054693214075530629349735273995982307625376442606753688071083149620216746\", \"price\":\"0.32\", \"size\":\"33.18\", \"side\":\"SELL\", \"hash\":\"6de846d1adffb947d2241a273e89d81fec2632b1\", \"best_bid\":\"0.31\", \"best_ask\":\"0.32\"}], \"timestamp\":\"1785130563867\", \"event_type\":\"price_change\"}","received_at":"2026-07-27T05:36:03.867656Z","schema_version":"clob-market-ws.price_change.v1","sequence":null,"server_hash":null,"server_timestamp":"1785130563867","session_id":"502006c5cfcd437296561ea750c9ec8b","source":"clob_market_ws"},"received_at":"2026-07-27T05:36:03.867656Z","record_id":"7e3c69555610723d6039830de19bce6b5f17f7852a08f219d16c280848225d44","schema_fingerprint":"4aa3821a28b0b7c2400bc59aba4bcc0a76e971dadd19610d3ad38c768e124dc7","schema_version":"edge-lab-recorder.raw.v1","sequence":null,"source":"clob_market_ws"}
{"event_at":"2026-07-27T05:36:03.872000Z","event_fingerprint":"4e9508fcf766df1ddcda34f1b38512f111c8ac8e6b1f732a7285b21f1407c1c4","payload":{"connection_id":"efc69d3132f1467b8e898a382b23ac0d","event_at":"2026-07-27T05:36:03.872000Z","event_type":"price_change","frame_hash":"293007f696ba3a741ed3d58bd559a40076ce236bbf76457c0bb1a86796d32811","frame_index":0,"kind":"data","monotonic_ns":232547108701875,"payload":{"event_type":"price_change","market":"0x3b40066b5cf3871a2f6237c5628bd8092a206aa998558ac5ec13c4483e31e160","price_changes":[{"asset_id":"110216635572655435074987471276357323571387854733835379371586402147734167783946","best_ask":"0.69","best_bid":"0.68","hash":"61128ac20a4a5433e080c00461de469dc5f91f81","price":"0.68","side":"BUY","size":"39.96"},{"asset_id":"14766054693214075530629349735273995982307625376442606753688071083149620216746","best_ask":"0.32","best_bid":"0.31","hash":"e01eef0ed1f9806e646d5f8df3f9e081cb2d7476","price":"0.32","side":"SELL","size":"39.96"}],"timestamp":"1785130563872"},"payload_hash":"e94a2b9cb95ff84ab5ad4e488f7c1384cf9ef0a34d51e8b2934e0877ec4322f2","raw_frame":"{\"market\":\"0x3b40066b5cf3871a2f6237c5628bd8092a206aa998558ac5ec13c4483e31e160\", \"price_changes\":[{\"asset_id\":\"110216635572655435074987471276357323571387854733835379371586402147734167783946\", \"price\":\"0.68\", \"size\":\"39.96\", \"side\":\"BUY\", \"hash\":\"61128ac20a4a5433e080c00461de469dc5f91f81\", \"best_bid\":\"0.68\", \"best_ask\":\"0.69\"}, {\"asset_id\":\"14766054693214075530629349735273995982307625376442606753688071083149620216746\", \"price\":\"0.32\", \"size\":\"39.96\", \"side\":\"SELL\", \"hash\":\"e01eef0ed1f9806e646d5f8df3f9e081cb2d7476\", \"best_bid\":\"0.31\", \"best_ask\":\"0.32\"}], \"timestamp\":\"1785130563872\", \"event_type\":\"price_change\"}","received_at":"2026-07-27T05:36:03.873021Z","schema_version":"clob-market-ws.price_change.v1","sequence":null,"server_hash":null,"server_timestamp":"1785130563872","session_id":"502006c5cfcd437296561ea750c9ec8b","source":"clob_market_ws"},"received_at":"2026-07-27T05:36:03.873021Z","record_id":"712ce0b0be0747724bd155f642dccba06685c2c23e1d0c9a61b3dc4aed1ffca3","schema_fingerprint":"4aa3821a28b0b7c2400bc59aba4bcc0a76e971dadd19610d3ad38c768e124dc7","schema_version":"edge-lab-recorder.raw.v1","sequence":null,"source":"clob_market_ws"}
{"event_at":"2026-07-27T05:36:03.873000Z","event_fingerprint":"e0f9bf25128277c9936a6b8edd1351cb28176b9a66523feca4986b66474b15ac","payload":{"connection_id":"efc69d3132f1467b8e898a382b23ac0d","event_at":"2026-07-27T05:36:03.873000Z","event_type":"price_change","frame_hash":"d6f7f0f537eeee8df53ecb123145f9dfa6cc3bf1fd4dd3df317797ac8f0cae96","frame_index":0,"kind":"data","monotonic_ns":232547112854666,"payload":{"event_type":"price_change","market":"0x3b40066b5cf3871a2f6237c5628bd8092a206aa998558ac5ec13c4483e31e160","price_changes":[{"asset_id":"110216635572655435074987471276357323571387854733835379371586402147734167783946","best_ask":"0.69","best_bid":"0.68","hash":"2c99e0677664ccc321e49618246720dd90af3510","price":"0.01","side":"BUY","size":"5602.45"},{"asset_id":"14766054693214075530629349735273995982307625376442606753688071083149620216746","best_ask":"0.32","best_bid":"0.31","hash":"318e5208edf9c8885fe3177263dfa51997f5eb74","price":"0.99","side":"SELL","size":"5602.45"}],"timestamp":"1785130563873"},"payload_hash":"84d6908e497727ad9be91dcf10d2a10a77e3d768e2f57587573583c5cea48b62","raw_frame":"{\"market\":\"0x3b40066b5cf3871a2f6237c5628bd8092a206aa998558ac5ec13c4483e31e160\", \"price_changes\":[{\"asset_id\":\"110216635572655435074987471276357323571387854733835379371586402147734167783946\", \"price\":\"0.01\", \"size\":\"5602.45\", \"side\":\"BUY\", \"hash\":\"2c99e0677664ccc321e49618246720dd90af3510\", \"best_bid\":\"0.68\", \"best_ask\":\"0.69\"}, {\"asset_id\":\"14766054693214075530629349735273995982307625376442606753688071083149620216746\", \"price\":\"0.99\", \"size\":\"5602.45\", \"side\":\"SELL\", \"hash\":\"318e5208edf9c8885fe3177263dfa51997f5eb74\", \"best_bid\":\"0.31\", \"best_ask\":\"0.32\"}], \"timestamp\":\"1785130563873\", \"event_type\":\"price_change\"}","received_at":"2026-07-27T05:36:03.877175Z","schema_version":"clob-market-ws.price_change.v1","sequence":null,"server_hash":null,"server_timestamp":"1785130563873","session_id":"502006c5cfcd437296561ea750c9ec8b","source":"clob_market_ws"},"received_at":"2026-07-27T05:36:03.877175Z","record_id":"a8947f6067a488d343f97eb919432ae01e9d6f3fbfa7c54ef8811b83b31a4bd3","schema_fingerprint":"4aa3821a28b0b7c2400bc59aba4bcc0a76e971dadd19610d3ad38c768e124dc7","schema_version":"edge-lab-recorder.raw.v1","sequence":null,"source":"clob_market_ws"}
{"event_at":"2026-07-27T05:36:03.878000Z","event_fingerprint":"839792ba30e0771eee5ba0dc628ce8eee5f4452bb8c769dfb737ff002162aa30","payload":{"connection_id":"efc69d3132f1467b8e898a382b23ac0d","event_at":"2026-07-27T05:36:03.878000Z","event_type":"price_change","frame_hash":"10e88c002abba6cf503def2c634a0c21f913bbd6b261879c920498090153557f","frame_index":0,"kind":"data","monotonic_ns":232547116031458,"payload":{"event_type":"price_change","market":"0x3b40066b5cf3871a2f6237c5628bd8092a206aa998558ac5ec13c4483e31e160","price_changes":[{"asset_id":"110216635572655435074987471276357323571387854733835379371586402147734167783946","best_ask":"0.69","best_bid":"0.68","hash":"cd791f807cb52c806d1be5884b38e5a5630b0d99","price":"0.63","side":"BUY","size":"190.65"},{"asset_id":"14766054693214075530629349735273995982307625376442606753688071083149620216746","best_ask":"0.32","best_bid":"0.31","hash":"8cec19a68e13d7721113a73d945b0cbc28d2b62d","price":"0.37","side":"SELL","size":"190.65"}],"timestamp":"1785130563878"},"payload_hash":"61daf31853ce69996d6e34857cabfadf721f01427978a2ed53d0f03a67841c4a","raw_frame":"{\"market\":\"0x3b40066b5cf3871a2f6237c5628bd8092a206aa998558ac5ec13c4483e31e160\", \"price_changes\":[{\"asset_id\":\"110216635572655435074987471276357323571387854733835379371586402147734167783946\", \"price\":\"0.63\", \"size\":\"190.65\", \"side\":\"BUY\", \"hash\":\"cd791f807cb52c806d1be5884b38e5a5630b0d99\", \"best_bid\":\"0.68\", \"best_ask\":\"0.69\"}, {\"asset_id\":\"14766054693214075530629349735273995982307625376442606753688071083149620216746\", \"price\":\"0.37\", \"size\":\"190.65\", \"side\":\"SELL\", \"hash\":\"8cec19a68e13d7721113a73d945b0cbc28d2b62d\", \"best_bid\":\"0.31\", \"best_ask\":\"0.32\"}], \"timestamp\":\"1785130563878\", \"event_type\":\"price_change\"}","received_at":"2026-07-27T05:36:03.880350Z","schema_version":"clob-market-ws.price_change.v1","sequence":null,"server_hash":null,"server_timestamp":"1785130563878","session_id":"502006c5cfcd437296561ea750c9ec8b","source":"clob_market_ws"},"received_at":"2026-07-27T05:36:03.880350Z","record_id":"2a5fabbe584e85ccedf7f89bc0d7fd12ad89d580aab5f8e979774f6a92cc7ee4","schema_fingerprint":"4aa3821a28b0b7c2400bc59aba4bcc0a76e971dadd19610d3ad38c768e124dc7","schema_version":"edge-lab-recorder.raw.v1","sequence":null,"source":"clob_market_ws"}
{"event_at":"2026-07-27T05:36:03.878000Z","event_fingerprint":"3fdc129c5199776f9b75cb041bf60723999468fd13a8ee78db354467aeabd82d","payload":{"connection_id":"efc69d3132f1467b8e898a382b23ac0d","event_at":"2026-07-27T05:36:03.878000Z","event_type":"price_change","frame_hash":"d20643650a92237eaa5efa934918865458870d150b5ef83efc3154f44127aab4","frame_index":0,"kind":"data","monotonic_ns":232547118919916,"payload":{"event_type":"price_change","market":"0x3b40066b5cf3871a2f6237c5628bd8092a206aa998558ac5ec13c4483e31e160","price_changes":[{"asset_id":"14766054693214075530629349735273995982307625376442606753688071083149620216746","best_ask":"0.32","best_bid":"0.31","hash":"8cec19a68e13d7721113a73d945b0cbc28d2b62d","price":"0.29","side":"BUY","size":"59.4"},{"asset_id":"110216635572655435074987471276357323571387854733835379371586402147734167783946","best_ask":"0.69","best_bid":"0.68","hash":"cd791f807cb52c806d1be5884b38e5a5630b0d99","price":"0.71","side":"SELL","size":"59.4"}],"timestamp":"1785130563878"},"payload_hash":"a4b171aba2db24ff6732a17e26c93c324129a569e349e55368b3bcd2cddd0c3b","raw_frame":"{\"market\":\"0x3b40066b5cf3871a2f6237c5628bd8092a206aa998558ac5ec13c4483e31e160\", \"price_changes\":[{\"asset_id\":\"14766054693214075530629349735273995982307625376442606753688071083149620216746\", \"price\":\"0.29\", \"size\":\"59.4\", \"side\":\"BUY\", \"hash\":\"8cec19a68e13d7721113a73d945b0cbc28d2b62d\", \"best_bid\":\"0.31\", \"best_ask\":\"0.32\"}, {\"asset_id\":\"110216635572655435074987471276357323571387854733835379371586402147734167783946\", \"price\":\"0.71\", \"size\":\"59.4\", \"side\":\"SELL\", \"hash\":\"cd791f807cb52c806d1be5884b38e5a5630b0d99\", \"best_bid\":\"0.68\", \"best_ask\":\"0.69\"}], \"timestamp\":\"1785130563878\", \"event_type\":\"price_change\"}","received_at":"2026-07-27T05:36:03.883238Z","schema_version":"clob-market-ws.price_change.v1","sequence":null,"server_hash":null,"server_timestamp":"1785130563878","session_id":"502006c5cfcd437296561ea750c9ec8b","source":"clob_market_ws"},"received_at":"2026-07-27T05:36:03.883238Z","record_id":"dd8d844e338780ca8682e4b8a520594f25a731bcac0214a1213bb25b6fed4204","schema_fingerprint":"4aa3821a28b0b7c2400bc59aba4bcc0a76e971dadd19610d3ad38c768e124dc7","schema_version":"edge-lab-recorder.raw.v1","sequence":null,"source":"clob_market_ws"}
{"event_at":"2026-07-27T05:36:03.884000Z","event_fingerprint":"ececdcdbd64ae3c62b2095130642e4f84017ec4ea476feb8314f5c0f98d7b1a4","payload":{"connection_id":"efc69d3132f1467b8e898a382b23ac0d","event_at":"2026-07-27T05:36:03.884000Z","event_type":"price_change","frame_hash":"f80a8eb0d5b1c5e17333e2b10ef096ad42f55d863e5925c59bee282ae9f910b3","frame_index":0,"kind":"data","monotonic_ns":232547122749166,"payload":{"event_type":"price_change","market":"0x3b40066b5cf3871a2f6237c5628bd8092a206aa998558ac5ec13c4483e31e160","price_changes":[{"asset_id":"14766054693214075530629349735273995982307625376442606753688071083149620216746","best_ask":"0.32","best_bid":"0.31","hash":"7000bd25ca160e20e70573e0bb1fbf33b7f2ee2f","price":"0.27","side":"BUY","size":"151.6"},{"asset_id":"110216635572655435074987471276357323571387854733835379371586402147734167783946","best_ask":"0.69","best_bid":"0.68","hash":"962d7512540e41c9dead0e381da7fac6e535f72d","price":"0.73","side":"SELL","size":"151.6"}],"timestamp":"1785130563884"},"payload_hash":"82834adc15684ad56897ff68ca7621cdae38a6364efb481283b495874c2b1864","raw_frame":"{\"market\":\"0x3b40066b5cf3871a2f6237c5628bd8092a206aa998558ac5ec13c4483e31e160\", \"price_changes\":[{\"asset_id\":\"14766054693214075530629349735273995982307625376442606753688071083149620216746\", \"price\":\"0.27\", \"size\":\"151.6\", \"side\":\"BUY\", \"hash\":\"7000bd25ca160e20e70573e0bb1fbf33b7f2ee2f\", \"best_bid\":\"0.31\", \"best_ask\":\"0.32\"}, {\"asset_id\":\"110216635572655435074987471276357323571387854733835379371586402147734167783946\", \"price\":\"0.73\", \"size\":\"151.6\", \"side\":\"SELL\", \"hash\":\"962d7512540e41c9dead0e381da7fac6e535f72d\", \"best_bid\":\"0.68\", \"best_ask\":\"0.69\"}], \"timestamp\":\"1785130563884\", \"event_type\":\"price_change\"}","received_at":"2026-07-27T05:36:03.887069Z","schema_version":"clob-market-ws.price_change.v1","sequence":null,"server_hash":null,"server_timestamp":"1785130563884","session_id":"502006c5cfcd437296561ea750c9ec8b","source":"clob_market_ws"},"received_at":"2026-07-27T05:36:03.887069Z","record_id":"e03733cf01ccf6fdcb9e248ef3d09e17296dafb2d3eefdfc2034bf5fdc7242ca","schema_fingerprint":"4aa3821a28b0b7c2400bc59aba4bcc0a76e971dadd19610d3ad38c768e124dc7","schema_version":"edge-lab-recorder.raw.v1","sequence":null,"source":"clob_market_ws"}
{"event_at":"2026-07-27T05:36:03.888000Z","event_fingerprint":"b20362881d3e7fa09eb297e6877493eee5af30ed8ec84fb2c173010d9b0589af","payload":{"connection_id":"efc69d3132f1467b8e898a382b23ac0d","event_at":"2026-07-27T05:36:03.888000Z","event_type":"price_change","frame_hash":"14e3973f37601453693f902023c8e90abb5aacd7a9542701eb953291671bcae2","frame_index":0,"kind":"data","monotonic_ns":232547126632333,"payload":{"event_type":"price_change","market":"0x3b40066b5cf3871a2f6237c5628bd8092a206aa998558ac5ec13c4483e31e160","price_changes":[{"asset_id":"14766054693214075530629349735273995982307625376442606753688071083149620216746","best_ask":"0.32","best_bid":"0.31","hash":"b69057a0acaf5087fa0388dad14f3d2817a5d050","price":"0.26","side":"BUY","size":"316"},{"asset_id":"110216635572655435074987471276357323571387854733835379371586402147734167783946","best_ask":"0.69","best_bid":"0.68","hash":"d2f012cdea2c004282576f789b06a0d89a85a366","price":"0.74","side":"SELL","size":"316"}],"timestamp":"1785130563888"},"payload_hash":"a831cfd3ff6f6dc2c8c71b1cd82a8ea462eda81d90defae60b74b5eb35ed0dca","raw_frame":"{\"market\":\"0x3b40066b5cf3871a2f6237c5628bd8092a206aa998558ac5ec13c4483e31e160\", \"price_changes\":[{\"asset_id\":\"14766054693214075530629349735273995982307625376442606753688071083149620216746\", \"price\":\"0.26\", \"size\":\"316\", \"side\":\"BUY\", \"hash\":\"b69057a0acaf5087fa0388dad14f3d2817a5d050\", \"best_bid\":\"0.31\", \"best_ask\":\"0.32\"}, {\"asset_id\":\"110216635572655435074987471276357323571387854733835379371586402147734167783946\", \"price\":\"0.74\", \"size\":\"316\", \"side\":\"SELL\", \"hash\":\"d2f012cdea2c004282576f789b06a0d89a85a366\", \"best_bid\":\"0.68\", \"best_ask\":\"0.69\"}], \"timestamp\":\"1785130563888\", \"event_type\":\"price_change\"}","received_at":"2026-07-27T05:36:03.890951Z","schema_version":"clob-market-ws.price_change.v1","sequence":null,"server_hash":null,"server_timestamp":"1785130563888","session_id":"502006c5cfcd437296561ea750c9ec8b","source":"clob_market_ws"},"received_at":"2026-07-27T05:36:03.890951Z","record_id":"bf08086548a427dcf0ed5b1d30f9c39b8a81d5bd3dd2231cee7877e880dcaa63","schema_fingerprint":"4aa3821a28b0b7c2400bc59aba4bcc0a76e971dadd19610d3ad38c768e124dc7","schema_version":"edge-lab-recorder.raw.v1","sequence":null,"source":"clob_market_ws"}
{"event_at":"2026-07-27T05:36:03.888000Z","event_fingerprint":"c208dd5fab1fb5581600f372d415ff946df8daaf05fbe621921b1b7b0860c010","payload":{"connection_id":"efc69d3132f1467b8e898a382b23ac0d","event_at":"2026-07-27T05:36:03.888000Z","event_type":"price_change","frame_hash":"187016cb2a9a2773279077641712008c9abd0260ac481ca4334cbdd21ed5185e","frame_index":0,"kind":"data","monotonic_ns":232547130401666,"payload":{"event_type":"price_change","market":"0x3b40066b5cf3871a2f6237c5628bd8092a206aa998558ac5ec13c4483e31e160","price_changes":[{"asset_id":"110216635572655435074987471276357323571387854733835379371586402147734167783946","best_ask":"0.69","best_bid":"0.68","hash":"a9e69888b79a7a938b762300730f626a2597977e","price":"0.68","side":"BUY","size":"49.96"},{"asset_id":"14766054693214075530629349735273995982307625376442606753688071083149620216746","best_ask":"0.32","best_bid":"0.31","hash":"67905feb345e617696ce5db5ca9ce4ae556a4fa2","price":"0.32","side":"SELL","size":"49.96"}],"timestamp":"1785130563888"},"payload_hash":"426bbfe2598fa018931b46cd53c295e5b472c4a60057eda168c8c17d65a4cdbf","raw_frame":"{\"market\":\"0x3b40066b5cf3871a2f6237c5628bd8092a206aa998558ac5ec13c4483e31e160\", \"price_changes\":[{\"asset_id\":\"110216635572655435074987471276357323571387854733835379371586402147734167783946\", \"price\":\"0.68\", \"size\":\"49.96\", \"side\":\"BUY\", \"hash\":\"a9e69888b79a7a938b762300730f626a2597977e\", \"best_bid\":\"0.68\", \"best_ask\":\"0.69\"}, {\"asset_id\":\"14766054693214075530629349735273995982307625376442606753688071083149620216746\", \"price\":\"0.32\", \"size\":\"49.96\", \"side\":\"SELL\", \"hash\":\"67905feb345e617696ce5db5ca9ce4ae556a4fa2\", \"best_bid\":\"0.31\", \"best_ask\":\"0.32\"}], \"timestamp\":\"1785130563888\", \"event_type\":\"price_change\"}","received_at":"2026-07-27T05:36:03.894721Z","schema_version":"clob-market-ws.price_change.v1","sequence":null,"server_hash":null,"server_timestamp":"1785130563888","session_id":"502006c5cfcd437296561ea750c9ec8b","source":"clob_market_ws"},"received_at":"2026-07-27T05:36:03.894721Z","record_id":"ac65623a83f7e89e6c0ac058d7cbc54e28a95b40017441cbb374b963e30c20e8","schema_fingerprint":"4aa3821a28b0b7c2400bc59aba4bcc0a76e971dadd19610d3ad38c768e124dc7","schema_version":"edge-lab-recorder.raw.v1","sequence":null,"source":"clob_market_ws"}
{"event_at":"2026-07-27T05:36:03.906000Z","event_fingerprint":"368eb33ca8417b47bcd4bb22e63cfe83feb244153f053e68f8c11833012f99e0","payload":{"connection_id":"efc69d3132f1467b8e898a382b23ac0d","event_at":"2026-07-27T05:36:03.906000Z","event_type":"price_change","frame_hash":"5991ae916200a2b67e4fbb4098b83b0d734f1bd4cb22f90d4ea1544e1d5c1c6e","frame_index":0,"kind":"data","monotonic_ns":232547133278416,"payload":{"event_type":"price_change","market":"0x3b40066b5cf3871a2f6237c5628bd8092a206aa998558ac5ec13c4483e31e160","price_changes":[{"asset_id":"14766054693214075530629349735273995982307625376442606753688071083149620216746","best_ask":"0.32","best_bid":"0.31","hash":"cb819dea2d5377811287e54341947498c72cb266","price":"0.34","side":"SELL","size":"160.54"},{"asset_id":"110216635572655435074987471276357323571387854733835379371586402147734167783946","best_ask":"0.69","best_bid":"0.68","hash":"d765b0fb99442d9a0065718b03fda8277b355d39","price":"0.66","side":"BUY","size":"160.54"}],"timestamp":"1785130563906"},"payload_hash":"31c95406a2fd8d10969b6d4a5f74960c583cf8589605ed3d61e02b27d72131ef","raw_frame":"{\"market\":\"0x3b40066b5cf3871a2f6237c5628bd8092a206aa998558ac5ec13c4483e31e160\", \"price_changes\":[{\"asset_id\":\"14766054693214075530629349735273995982307625376442606753688071083149620216746\", \"price\":\"0.34\", \"size\":\"160.54\", \"side\":\"SELL\", \"hash\":\"cb819dea2d5377811287e54341947498c72cb266\", \"best_bid\":\"0.31\", \"best_ask\":\"0.32\"}, {\"asset_id\":\"110216635572655435074987471276357323571387854733835379371586402147734167783946\", \"price\":\"0.66\", \"size\":\"160.54\", \"side\":\"BUY\", \"hash\":\"d765b0fb99442d9a0065718b03fda8277b355d39\", \"best_bid\":\"0.68\", \"best_ask\":\"0.69\"}], \"timestamp\":\"1785130563906\", \"event_type\":\"price_change\"}","received_at":"2026-07-27T05:36:03.897603Z","schema_version":"clob-market-ws.price_change.v1","sequence":null,"server_hash":null,"server_timestamp":"1785130563906","session_id":"502006c5cfcd437296561ea750c9ec8b","source":"clob_market_ws"},"received_at":"2026-07-27T05:36:03.897603Z","record_id":"6839bbca70ffa6257962ccb830ee32fed524d08efbae65b88116b057727bc730","schema_fingerprint":"4aa3821a28b0b7c2400bc59aba4bcc0a76e971dadd19610d3ad38c768e124dc7","schema_version":"edge-lab-recorder.raw.v1","sequence":null,"source":"clob_market_ws"}
{"event_at":"2026-07-27T05:36:03.909000Z","event_fingerprint":"91acb69c7c9b87150b228d7f29efe24624ccebc1a8b632d263e81d380a67bb7b","payload":{"connection_id":"efc69d3132f1467b8e898a382b23ac0d","event_at":"2026-07-27T05:36:03.909000Z","event_type":"price_change","frame_hash":"6758677500c7b4974e89d662291fa8f4f0d4d8220e0c33b618a5b806d9ec9448","frame_index":0,"kind":"data","monotonic_ns":232547136386708,"payload":{"event_type":"price_change","market":"0x3b40066b5cf3871a2f6237c5628bd8092a206aa998558ac5ec13c4483e31e160","price_changes":[{"asset_id":"110216635572655435074987471276357323571387854733835379371586402147734167783946","best_ask":"0.69","best_bid":"0.68","hash":"49f332b8700e48f1148ef69458b3fe88f091e528","price":"0.64","side":"BUY","size":"62.83"},{"asset_id":"14766054693214075530629349735273995982307625376442606753688071083149620216746","best_ask":"0.32","best_bid":"0.31","hash":"c98bc8f7a01b885bf5c06f78219d5f507495fd0d","price":"0.36","side":"SELL","size":"62.83"}],"timestamp":"1785130563909"},"payload_hash":"868f271306b41837eed06a4cdd3f386c24f959b8fcf39b0137cc1ebb296e8747","raw_frame":"{\"market\":\"0x3b40066b5cf3871a2f6237c5628bd8092a206aa998558ac5ec13c4483e31e160\", \"price_changes\":[{\"asset_id\":\"110216635572655435074987471276357323571387854733835379371586402147734167783946\", \"price\":\"0.64\", \"size\":\"62.83\", \"side\":\"BUY\", \"hash\":\"49f332b8700e48f1148ef69458b3fe88f091e528\", \"best_bid\":\"0.68\", \"best_ask\":\"0.69\"}, {\"asset_id\":\"14766054693214075530629349735273995982307625376442606753688071083149620216746\", \"price\":\"0.36\", \"size\":\"62.83\", \"side\":\"SELL\", \"hash\":\"c98bc8f7a01b885bf5c06f78219d5f507495fd0d\", \"best_bid\":\"0.31\", \"best_ask\":\"0.32\"}], \"timestamp\":\"1785130563909\", \"event_type\":\"price_change\"}","received_at":"2026-07-27T05:36:03.900705Z","schema_version":"clob-market-ws.price_change.v1","sequence":null,"server_hash":null,"server_timestamp":"1785130563909","session_id":"502006c5cfcd437296561ea750c9ec8b","source":"clob_market_ws"},"received_at":"2026-07-27T05:36:03.900705Z","record_id":"b2d53d7439d6ab5f05098128e2f053d2dc7c245fea9b98f055d680c6c7181a71","schema_fingerprint":"4aa3821a28b0b7c2400bc59aba4bcc0a76e971dadd19610d3ad38c768e124dc7","schema_version":"edge-lab-recorder.raw.v1","sequence":null,"source":"clob_market_ws"}
{"event_at":"2026-07-27T05:36:03.910000Z","event_fingerprint":"5ce52588ec7b19bcc6a57e4974f35aaab313916157533c191a57af216c1afd34","payload":{"connection_id":"efc69d3132f1467b8e898a382b23ac0d","event_at":"2026-07-27T05:36:03.910000Z","event_type":"price_change","frame_hash":"a3f5a4f2527562e70bbdd4913327f4d3475a85f8714852c35348e89d54fe7e9d","frame_index":0,"kind":"data","monotonic_ns":232547139689791,"payload":{"event_type":"price_change","market":"0x3b40066b5cf3871a2f6237c5628bd8092a206aa998558ac5ec13c4483e31e160","price_changes":[{"asset_id":"14766054693214075530629349735273995982307625376442606753688071083149620216746","best_ask":"0.32","best_bid":"0.31","hash":"45391595ab93558f1b999d255986a31d8b4e0a6b","price":"0.28","side":"BUY","size":"62.43"},{"asset_id":"110216635572655435074987471276357323571387854733835379371586402147734167783946","best_ask":"0.69","best_bid":"0.68","hash":"d36053b061dcfa57dca5b7540f373a7a5e7e3191","price":"0.72","side":"SELL","size":"62.43"}],"timestamp":"1785130563910"},"payload_hash":"12504edb866081206b6b803a9a52639c357ebe18e35675d628ce7f12ea88cfc9","raw_frame":"{\"market\":\"0x3b40066b5cf3871a2f6237c5628bd8092a206aa998558ac5ec13c4483e31e160\", \"price_changes\":[{\"asset_id\":\"14766054693214075530629349735273995982307625376442606753688071083149620216746\", \"price\":\"0.28\", \"size\":\"62.43\", \"side\":\"BUY\", \"hash\":\"45391595ab93558f1b999d255986a31d8b4e0a6b\", \"best_bid\":\"0.31\", \"best_ask\":\"0.32\"}, {\"asset_id\":\"110216635572655435074987471276357323571387854733835379371586402147734167783946\", \"price\":\"0.72\", \"size\":\"62.43\", \"side\":\"SELL\", \"hash\":\"d36053b061dcfa57dca5b7540f373a7a5e7e3191\", \"best_bid\":\"0.68\", \"best_ask\":\"0.69\"}], \"timestamp\":\"1785130563910\", \"event_type\":\"price_change\"}","received_at":"2026-07-27T05:36:03.904009Z","schema_version":"clob-market-ws.price_change.v1","sequence":null,"server_hash":null,"server_timestamp":"1785130563910","session_id":"502006c5cfcd437296561ea750c9ec8b","source":"clob_market_ws"},"received_at":"2026-07-27T05:36:03.904009Z","record_id":"4d0dda2059018189d35f1c197e8670f15dd7fdd69759876caaa33c6ccabfe6be","schema_fingerprint":"4aa3821a28b0b7c2400bc59aba4bcc0a76e971dadd19610d3ad38c768e124dc7","schema_version":"edge-lab-recorder.raw.v1","sequence":null,"source":"clob_market_ws"}
{"event_at":"2026-07-27T05:36:03.921000Z","event_fingerprint":"ea920ff679183a9c77efaefd82176fa9ef63af6addc701735f7f8cd6860bda1a","payload":{"connection_id":"efc69d3132f1467b8e898a382b23ac0d","event_at":"2026-07-27T05:36:03.921000Z","event_type":"price_change","frame_hash":"2402743e4c7285ca5990830f4d7c2e50de7d9331c1cdc42b3a7977f6b2077eeb","frame_index":0,"kind":"data","monotonic_ns":232547146714666,"payload":{"event_type":"price_change","market":"0x3b40066b5cf3871a2f6237c5628bd8092a206aa998558ac5ec13c4483e31e160","price_changes":[{"asset_id":"110216635572655435074987471276357323571387854733835379371586402147734167783946","best_ask":"0.69","best_bid":"0.68","hash":"d3fa568e0971406f50b2e6313a5ef8eb489888c5","price":"0.66","side":"BUY","size":"135.54"},{"asset_id":"14766054693214075530629349735273995982307625376442606753688071083149620216746","best_ask":"0.32","best_bid":"0.31","hash":"0a6fb46b4589792e84ae5ff5ac33e9e193b3c8e3","price":"0.34","side":"SELL","size":"135.54"}],"timestamp":"1785130563921"},"payload_hash":"306f2714ad6700a9aa702b63c475e0d5a53a2bcc65ffdcddd85cda6a41d53505","raw_frame":"{\"market\":\"0x3b40066b5cf3871a2f6237c5628bd8092a206aa998558ac5ec13c4483e31e160\", \"price_changes\":[{\"asset_id\":\"110216635572655435074987471276357323571387854733835379371586402147734167783946\", \"price\":\"0.66\", \"size\":\"135.54\", \"side\":\"BUY\", \"hash\":\"d3fa568e0971406f50b2e6313a5ef8eb489888c5\", \"best_bid\":\"0.68\", \"best_ask\":\"0.69\"}, {\"asset_id\":\"14766054693214075530629349735273995982307625376442606753688071083149620216746\", \"price\":\"0.34\", \"size\":\"135.54\", \"side\":\"SELL\", \"hash\":\"0a6fb46b4589792e84ae5ff5ac33e9e193b3c8e3\", \"best_bid\":\"0.31\", \"best_ask\":\"0.32\"}], \"timestamp\":\"1785130563921\", \"event_type\":\"price_change\"}","received_at":"2026-07-27T05:36:03.911034Z","schema_version":"clob-market-ws.price_change.v1","sequence":null,"server_hash":null,"server_timestamp":"1785130563921","session_id":"502006c5cfcd437296561ea750c9ec8b","source":"clob_market_ws"},"received_at":"2026-07-27T05:36:03.911034Z","record_id":"304fa5abe3189d13444d604063ca4fb215127f808dd0a876f0c703052bf7de50","schema_fingerprint":"4aa3821a28b0b7c2400bc59aba4bcc0a76e971dadd19610d3ad38c768e124dc7","schema_version":"edge-lab-recorder.raw.v1","sequence":null,"source":"clob_market_ws"}
{"event_at":"2026-07-27T05:36:03.923000Z","event_fingerprint":"55fef1e800b2dc1b5404f1b6cc317344750686e2f160da977bef6a68b5802038","payload":{"connection_id":"efc69d3132f1467b8e898a382b23ac0d","event_at":"2026-07-27T05:36:03.923000Z","event_type":"price_change","frame_hash":"c0e8fa2b8f75ee52cd003c87aa794eeceff4ebb78ddcfdba8e01aa80e80a266f","frame_index":0,"kind":"data","monotonic_ns":232547150261583,"payload":{"event_type":"price_change","market":"0x3b40066b5cf3871a2f6237c5628bd8092a206aa998558ac5ec13c4483e31e160","price_changes":[{"asset_id":"14766054693214075530629349735273995982307625376442606753688071083149620216746","best_ask":"0.32","best_bid":"0.31","hash":"fdf8a50a70ff17195a4d0994836f6350d63c382c","price":"0.34","side":"SELL","size":"110.54"},{"asset_id":"110216635572655435074987471276357323571387854733835379371586402147734167783946","best_ask":"0.69","best_bid":"0.68","hash":"869d5d525c82a25f91658ca8df25cc8e1dc38047","price":"0.66","side":"BUY","size":"110.54"}],"timestamp":"1785130563923"},"payload_hash":"f9cc0b76a05bddff46d553d065cd3ecb71a1c8da87b7333296abb54ba3987908","raw_frame":"{\"market\":\"0x3b40066b5cf3871a2f6237c5628bd8092a206aa998558ac5ec13c4483e31e160\", \"price_changes\":[{\"asset_id\":\"14766054693214075530629349735273995982307625376442606753688071083149620216746\", \"price\":\"0.34\", \"size\":\"110.54\", \"side\":\"SELL\", \"hash\":\"fdf8a50a70ff17195a4d0994836f6350d63c382c\", \"best_bid\":\"0.31\", \"best_ask\":\"0.32\"}, {\"asset_id\":\"110216635572655435074987471276357323571387854733835379371586402147734167783946\", \"price\":\"0.66\", \"size\":\"110.54\", \"side\":\"BUY\", \"hash\":\"869d5d525c82a25f91658ca8df25cc8e1dc38047\", \"best_bid\":\"0.68\", \"best_ask\":\"0.69\"}], \"timestamp\":\"1785130563923\", \"event_type\":\"price_change\"}","received_at":"2026-07-27T05:36:03.914587Z","schema_version":"clob-market-ws.price_change.v1","sequence":null,"server_hash":null,"server_timestamp":"1785130563923","session_id":"502006c5cfcd437296561ea750c9ec8b","source":"clob_market_ws"},"received_at":"2026-07-27T05:36:03.914587Z","record_id":"00d864e062d28995e44f8ae0896b4f268945e832ee50d7a80e2846d04bb2d6b2","schema_fingerprint":"4aa3821a28b0b7c2400bc59aba4bcc0a76e971dadd19610d3ad38c768e124dc7","schema_version":"edge-lab-recorder.raw.v1","sequence":null,"source":"clob_market_ws"}
{"event_at":"2026-07-27T05:36:03.929000Z","event_fingerprint":"a2714f5857774d86657afe72bca1aad6aa9b9313a276298d7419654162bf0d90","payload":{"connection_id":"efc69d3132f1467b8e898a382b23ac0d","event_at":"2026-07-27T05:36:03.929000Z","event_type":"price_change","frame_hash":"20143e2716d8b47d3ee50f2f1c74c7302a982e8014dd9bc733eadb0aca8654b1","frame_index":0,"kind":"data","monotonic_ns":232547153592666,"payload":{"event_type":"price_change","market":"0x3b40066b5cf3871a2f6237c5628bd8092a206aa998558ac5ec13c4483e31e160","price_changes":[{"asset_id":"14766054693214075530629349735273995982307625376442606753688071083149620216746","best_ask":"0.32","best_bid":"0.31","hash":"8ecd8c9d91c6e9622783f930c130185af7ae13c8","price":"0.49","side":"SELL","size":"185"},{"asset_id":"110216635572655435074987471276357323571387854733835379371586402147734167783946","best_ask":"0.69","best_bid":"0.68","hash":"f5f1edca015d4b6d8270b91c5615dcd9913f8689","price":"0.51","side":"BUY","size":"185"}],"timestamp":"1785130563929"},"payload_hash":"29bcf3f492c7f62974149a49fffbed53a6c72af711fae578da261c5de54d48a7","raw_frame":"{\"market\":\"0x3b40066b5cf3871a2f6237c5628bd8092a206aa998558ac5ec13c4483e31e160\", \"price_changes\":[{\"asset_id\":\"14766054693214075530629349735273995982307625376442606753688071083149620216746\", \"price\":\"0.49\", \"size\":\"185\", \"side\":\"SELL\", \"hash\":\"8ecd8c9d91c6e9622783f930c130185af7ae13c8\", \"best_bid\":\"0.31\", \"best_ask\":\"0.32\"}, {\"asset_id\":\"110216635572655435074987471276357323571387854733835379371586402147734167783946\", \"price\":\"0.51\", \"size\":\"185\", \"side\":\"BUY\", \"hash\":\"f5f1edca015d4b6d8270b91c5615dcd9913f8689\", \"best_bid\":\"0.68\", \"best_ask\":\"0.69\"}], \"timestamp\":\"1785130563929\", \"event_type\":\"price_change\"}","received_at":"2026-07-27T05:36:03.917912Z","schema_version":"clob-market-ws.price_change.v1","sequence":null,"server_hash":null,"server_timestamp":"1785130563929","session_id":"502006c5cfcd437296561ea750c9ec8b","source":"clob_market_ws"},"received_at":"2026-07-27T05:36:03.917912Z","record_id":"1d663f5ad4decd3c59eddc911578d5f8b6b0f73566303c45ea6cbf8cd1b1a0bc","schema_fingerprint":"4aa3821a28b0b7c2400bc59aba4bcc0a76e971dadd19610d3ad38c768e124dc7","schema_version":"edge-lab-recorder.raw.v1","sequence":null,"source":"clob_market_ws"}
{"event_at":"2026-07-27T05:36:03.939000Z","event_fingerprint":"a8c3e333e35bc350b753167c34b1ca1b3022185ebd349d3406edfa4f4fc0da6d","payload":{"connection_id":"efc69d3132f1467b8e898a382b23ac0d","event_at":"2026-07-27T05:36:03.939000Z","event_type":"price_change","frame_hash":"f397d51a22423f93602c1ec47c98e3cb4f63b58d7f832bf3dcf671f42946bfde","frame_index":0,"kind":"data","monotonic_ns":232547156691666,"payload":{"event_type":"price_change","market":"0x3b40066b5cf3871a2f6237c5628bd8092a206aa998558ac5ec13c4483e31e160","price_changes":[{"asset_id":"110216635572655435074987471276357323571387854733835379371586402147734167783946","best_ask":"0.69","best_bid":"0.68","hash":"d30fffc99068a99bbe547ebe6c74db26016e0797","price":"0.02","side":"BUY","size":"678.1"},{"asset_id":"14766054693214075530629349735273995982307625376442606753688071083149620216746","best_ask":"0.32","best_bid":"0.31","hash":"d2412493e1e5fde302a26f51314e1b26d80de805","price":"0.98","side":"SELL","size":"678.1"}],"timestamp":"1785130563939"},"payload_hash":"62e7f83958ee4b4f4fcc22b5ce511817d50e5081dc37b8354c3462fe4563c5d1","raw_frame":"{\"market\":\"0x3b40066b5cf3871a2f6237c5628bd8092a206aa998558ac5ec13c4483e31e160\", \"price_changes\":[{\"asset_id\":\"110216635572655435074987471276357323571387854733835379371586402147734167783946\", \"price\":\"0.02\", \"size\":\"678.1\", \"side\":\"BUY\", \"hash\":\"d30fffc99068a99bbe547ebe6c74db26016e0797\", \"best_bid\":\"0.68\", \"best_ask\":\"0.69\"}, {\"asset_id\":\"14766054693214075530629349735273995982307625376442606753688071083149620216746\", \"price\":\"0.98\", \"size\":\"678.1\", \"side\":\"SELL\", \"hash\":\"d2412493e1e5fde302a26f51314e1b26d80de805\", \"best_bid\":\"0.31\", \"best_ask\":\"0.32\"}], \"timestamp\":\"1785130563939\", \"event_type\":\"price_change\"}","received_at":"2026-07-27T05:36:03.921011Z","schema_version":"clob-market-ws.price_change.v1","sequence":null,"server_hash":null,"server_timestamp":"1785130563939","session_id":"502006c5cfcd437296561ea750c9ec8b","source":"clob_market_ws"},"received_at":"2026-07-27T05:36:03.921011Z","record_id":"0a69064b0320e883f2d6c6e4d0d2099b675f81992d8ae490dedec097a3e4330e","schema_fingerprint":"4aa3821a28b0b7c2400bc59aba4bcc0a76e971dadd19610d3ad38c768e124dc7","schema_version":"edge-lab-recorder.raw.v1","sequence":null,"source":"clob_market_ws"}
{"event_at":"2026-07-27T05:36:03.946000Z","event_fingerprint":"98451ab404faf73ca927dcb2cb90c9f59f07d86ed9da986630c6a662645fc789","payload":{"connection_id":"efc69d3132f1467b8e898a382b23ac0d","event_at":"2026-07-27T05:36:03.946000Z","event_type":"price_change","frame_hash":"c537cfd6f61ec73bfb13aa6011e6d7a81dd38c43864692f73f728324ea2dae1b","frame_index":0,"kind":"data","monotonic_ns":232547161257750,"payload":{"event_type":"price_change","market":"0x3b40066b5cf3871a2f6237c5628bd8092a206aa998558ac5ec13c4483e31e160","price_changes":[{"asset_id":"110216635572655435074987471276357323571387854733835379371586402147734167783946","best_ask":"0.69","best_bid":"0.68","hash":"d592f2b3c96668f6eddd40e094efb5229738ab4c","price":"0.68","side":"BUY","size":"74.96"},{"asset_id":"14766054693214075530629349735273995982307625376442606753688071083149620216746","best_ask":"0.32","best_bid":"0.31","hash":"bd758e386d8a0b9b3a55dc4c8a125ed60f12b627","price":"0.32","side":"SELL","size":"74.96"}],"timestamp":"1785130563946"},"payload_hash":"d661ef5a0eb27b78a109b8cbad0458c04ab65087e2bd482b91283384e7803737","raw_frame":"{\"market\":\"0x3b40066b5cf3871a2f6237c5628bd8092a206aa998558ac5ec13c4483e31e160\", \"price_changes\":[{\"asset_id\":\"110216635572655435074987471276357323571387854733835379371586402147734167783946\", \"price\":\"0.68\", \"size\":\"74.96\", \"side\":\"BUY\", \"hash\":\"d592f2b3c96668f6eddd40e094efb5229738ab4c\", \"best_bid\":\"0.68\", \"best_ask\":\"0.69\"}, {\"asset_id\":\"14766054693214075530629349735273995982307625376442606753688071083149620216746\", \"price\":\"0.32\", \"size\":\"74.96\", \"side\":\"SELL\", \"hash\":\"bd758e386d8a0b9b3a55dc4c8a125ed60f12b627\", \"best_bid\":\"0.31\", \"best_ask\":\"0.32\"}], \"timestamp\":\"1785130563946\", \"event_type\":\"price_change\"}","received_at":"2026-07-27T05:36:03.925574Z","schema_version":"clob-market-ws.price_change.v1","sequence":null,"server_hash":null,"server_timestamp":"1785130563946","session_id":"502006c5cfcd437296561ea750c9ec8b","source":"clob_market_ws"},"received_at":"2026-07-27T05:36:03.925574Z","record_id":"cde92d4c9b2b3dead75c5dc385e533b1b0cbe3c79691bcb90ef4d52e0f2dfe45","schema_fingerprint":"4aa3821a28b0b7c2400bc59aba4bcc0a76e971dadd19610d3ad38c768e124dc7","schema_version":"edge-lab-recorder.raw.v1","sequence":null,"source":"clob_market_ws"}
{"event_at":"2026-07-27T05:36:03.947000Z","event_fingerprint":"401a2616b4fba81118de384b263ad7c00e7f51337f66a927961e992a46976ea5","payload":{"connection_id":"efc69d3132f1467b8e898a382b23ac0d","event_at":"2026-07-27T05:36:03.947000Z","event_type":"price_change","frame_hash":"ea2138603add547bfbcc954ebdcce366eb2ea35478b5661050f29fd92378f451","frame_index":0,"kind":"data","monotonic_ns":232547167616583,"payload":{"event_type":"price_change","market":"0x3b40066b5cf3871a2f6237c5628bd8092a206aa998558ac5ec13c4483e31e160","price_changes":[{"asset_id":"110216635572655435074987471276357323571387854733835379371586402147734167783946","best_ask":"0.69","best_bid":"0.68","hash":"95ae98ce1c51c02a730b5d2e26ae09acf210a379","price":"0.66","side":"BUY","size":"86.6"},{"asset_id":"14766054693214075530629349735273995982307625376442606753688071083149620216746","best_ask":"0.32","best_bid":"0.31","hash":"bf91d561ab3c730709704513098d4c71e28d7e3c","price":"0.34","side":"SELL","size":"86.6"}],"timestamp":"1785130563947"},"payload_hash":"b0f5f341c98b04d6bf957ee87dea9a1f231f414ed2dc2669ad495f5e16372a8d","raw_frame":"{\"market\":\"0x3b40066b5cf3871a2f6237c5628bd8092a206aa998558ac5ec13c4483e31e160\", \"price_changes\":[{\"asset_id\":\"110216635572655435074987471276357323571387854733835379371586402147734167783946\", \"price\":\"0.66\", \"size\":\"86.6\", \"side\":\"BUY\", \"hash\":\"95ae98ce1c51c02a730b5d2e26ae09acf210a379\", \"best_bid\":\"0.68\", \"best_ask\":\"0.69\"}, {\"asset_id\":\"14766054693214075530629349735273995982307625376442606753688071083149620216746\", \"price\":\"0.34\", \"size\":\"86.6\", \"side\":\"SELL\", \"hash\":\"bf91d561ab3c730709704513098d4c71e28d7e3c\", \"best_bid\":\"0.31\", \"best_ask\":\"0.32\"}], \"timestamp\":\"1785130563947\", \"event_type\":\"price_change\"}","received_at":"2026-07-27T05:36:03.931936Z","schema_version":"clob-market-ws.price_change.v1","sequence":null,"server_hash":null,"server_timestamp":"1785130563947","session_id":"502006c5cfcd437296561ea750c9ec8b","source":"clob_market_ws"},"received_at":"2026-07-27T05:36:03.931936Z","record_id":"90239777981344711fb22b4b2fee35b90240f6c64563c5cbed1fded0002cb7b3","schema_fingerprint":"4aa3821a28b0b7c2400bc59aba4bcc0a76e971dadd19610d3ad38c768e124dc7","schema_version":"edge-lab-recorder.raw.v1","sequence":null,"source":"clob_market_ws"}
{"event_at":"2026-07-27T05:36:03.948000Z","event_fingerprint":"d4e4d9653097bf6a3fbeaab133c73b104f18f92ece69388c2b32430f6fa2ba2f","payload":{"connection_id":"efc69d3132f1467b8e898a382b23ac0d","event_at":"2026-07-27T05:36:03.948000Z","event_type":"price_change","frame_hash":"9a66e648b19d37f0f3d09edb9d15f7a0936bad12fdff923624115fdd5a6c76c8","frame_index":0,"kind":"data","monotonic_ns":232547172202041,"payload":{"event_type":"price_change","market":"0x3b40066b5cf3871a2f6237c5628bd8092a206aa998558ac5ec13c4483e31e160","price_changes":[{"asset_id":"14766054693214075530629349735273995982307625376442606753688071083149620216746","best_ask":"0.32","best_bid":"0.31","hash":"4a1e772517fd7d0bb9399da0ecf2a71e9c8cadaf","price":"0.32","side":"SELL","size":"99.96"},{"asset_id":"110216635572655435074987471276357323571387854733835379371586402147734167783946","best_ask":"0.69","best_bid":"0.68","hash":"55e874dcca90bb0107bb1215999b6bc6100a475e","price":"0.68","side":"BUY","size":"99.96"}],"timestamp":"1785130563948"},"payload_hash":"4c541e6c5520f57e9f0ac5c9576bdfdddb5a3e27a1932490b4c9016afca822cf","raw_frame":"{\"market\":\"0x3b40066b5cf3871a2f6237c5628bd8092a206aa998558ac5ec13c4483e31e160\", \"price_changes\":[{\"asset_id\":\"14766054693214075530629349735273995982307625376442606753688071083149620216746\", \"price\":\"0.32\", \"size\":\"99.96\", \"side\":\"SELL\", \"hash\":\"4a1e772517fd7d0bb9399da0ecf2a71e9c8cadaf\", \"best_bid\":\"0.31\", \"best_ask\":\"0.32\"}, {\"asset_id\":\"110216635572655435074987471276357323571387854733835379371586402147734167783946\", \"price\":\"0.68\", \"size\":\"99.96\", \"side\":\"BUY\", \"hash\":\"55e874dcca90bb0107bb1215999b6bc6100a475e\", \"best_bid\":\"0.68\", \"best_ask\":\"0.69\"}], \"timestamp\":\"1785130563948\", \"event_type\":\"price_change\"}","received_at":"2026-07-27T05:36:03.936516Z","schema_version":"clob-market-ws.price_change.v1","sequence":null,"server_hash":null,"server_timestamp":"1785130563948","session_id":"502006c5cfcd437296561ea750c9ec8b","source":"clob_market_ws"},"received_at":"2026-07-27T05:36:03.936516Z","record_id":"bf1dbad1c6e6f707cf09542dc1ce1e8ed6ee3e39a36b299afdc5a6fd14cff855","schema_fingerprint":"4aa3821a28b0b7c2400bc59aba4bcc0a76e971dadd19610d3ad38c768e124dc7","schema_version":"edge-lab-recorder.raw.v1","sequence":null,"source":"clob_market_ws"}
{"event_at":"2026-07-27T05:36:03.957000Z","event_fingerprint":"1b2419fb10289fa7a98e899ac4271a1240475a0481df63a0aa966fbf53021e61","payload":{"connection_id":"efc69d3132f1467b8e898a382b23ac0d","event_at":"2026-07-27T05:36:03.957000Z","event_type":"price_change","frame_hash":"a8ad4003d4d6f9d37a7919b71c98763ac2d06b7bd9ff6258fe75ee5b2dc57317","frame_index":0,"kind":"data","monotonic_ns":232547176689625,"payload":{"event_type":"price_change","market":"0x3b40066b5cf3871a2f6237c5628bd8092a206aa998558ac5ec13c4483e31e160","price_changes":[{"asset_id":"14766054693214075530629349735273995982307625376442606753688071083149620216746","best_ask":"0.32","best_bid":"0.31","hash":"a75046d50577ec1d75f742b1fbd6e300478188c0","price":"0.32","side":"SELL","size":"104.96"},{"asset_id":"110216635572655435074987471276357323571387854733835379371586402147734167783946","best_ask":"0.69","best_bid":"0.68","hash":"484aaf7aac5aa87490e8853123ae21807709e6c1","price":"0.68","side":"BUY","size":"104.96"}],"timestamp":"1785130563957"},"payload_hash":"339175db03fdcfbc48c55723fc355b6b4229b7f83c12f7fd8a6da86702c996d7","raw_frame":"{\"market\":\"0x3b40066b5cf3871a2f6237c5628bd8092a206aa998558ac5ec13c4483e31e160\", \"price_changes\":[{\"asset_id\":\"14766054693214075530629349735273995982307625376442606753688071083149620216746\", \"price\":\"0.32\", \"size\":\"104.96\", \"side\":\"SELL\", \"hash\":\"a75046d50577ec1d75f742b1fbd6e300478188c0\", \"best_bid\":\"0.31\", \"best_ask\":\"0.32\"}, {\"asset_id\":\"110216635572655435074987471276357323571387854733835379371586402147734167783946\", \"price\":\"0.68\", \"size\":\"104.96\", \"side\":\"BUY\", \"hash\":\"484aaf7aac5aa87490e8853123ae21807709e6c1\", \"best_bid\":\"0.68\", \"best_ask\":\"0.69\"}], \"timestamp\":\"1785130563957\", \"event_type\":\"price_change\"}","received_at":"2026-07-27T05:36:03.941010Z","schema_version":"clob-market-ws.price_change.v1","sequence":null,"server_hash":null,"server_timestamp":"1785130563957","session_id":"502006c5cfcd437296561ea750c9ec8b","source":"clob_market_ws"},"received_at":"2026-07-27T05:36:03.941010Z","record_id":"568cea12df006935471bbf9e0b56e1af038cc75928d0bfdb079f24b76f9d5d05","schema_fingerprint":"4aa3821a28b0b7c2400bc59aba4bcc0a76e971dadd19610d3ad38c768e124dc7","schema_version":"edge-lab-recorder.raw.v1","sequence":null,"source":"clob_market_ws"}
{"event_at":"2026-07-27T05:36:03.959000Z","event_fingerprint":"6d7d43a59cf4550d079dac1c6e2d702ecc1b9b059688bf48d2f3ff0d5c4089e2","payload":{"connection_id":"efc69d3132f1467b8e898a382b23ac0d","event_at":"2026-07-27T05:36:03.959000Z","event_type":"price_change","frame_hash":"8719cd5ccb195d80f836c83263238e2f70e5d8d3d31474d464e1aeab7ead23ea","frame_index":0,"kind":"data","monotonic_ns":232547183478875,"payload":{"event_type":"price_change","market":"0x3b40066b5cf3871a2f6237c5628bd8092a206aa998558ac5ec13c4483e31e160","price_changes":[{"asset_id":"110216635572655435074987471276357323571387854733835379371586402147734167783946","best_ask":"0.69","best_bid":"0.68","hash":"b1f03cce40d2dce0d11ce8a4de3ce725953d7ab6","price":"0.68","side":"BUY","size":"109.96"},{"asset_id":"14766054693214075530629349735273995982307625376442606753688071083149620216746","best_ask":"0.32","best_bid":"0.31","hash":"4445565d0d245607cbd8747c977376fe93b0b90d","price":"0.32","side":"SELL","size":"109.96"}],"timestamp":"1785130563959"},"payload_hash":"7a26792f2516e02baab70da716a5e1ff9b9b2eb6574b8fff50fb0f002aaf7c1c","raw_frame":"{\"market\":\"0x3b40066b5cf3871a2f6237c5628bd8092a206aa998558ac5ec13c4483e31e160\", \"price_changes\":[{\"asset_id\":\"110216635572655435074987471276357323571387854733835379371586402147734167783946\", \"price\":\"0.68\", \"size\":\"109.96\", \"side\":\"BUY\", \"hash\":\"b1f03cce40d2dce0d11ce8a4de3ce725953d7ab6\", \"best_bid\":\"0.68\", \"best_ask\":\"0.69\"}, {\"asset_id\":\"14766054693214075530629349735273995982307625376442606753688071083149620216746\", \"price\":\"0.32\", \"size\":\"109.96\", \"side\":\"SELL\", \"hash\":\"4445565d0d245607cbd8747c977376fe93b0b90d\", \"best_bid\":\"0.31\", \"best_ask\":\"0.32\"}], \"timestamp\":\"1785130563959\", \"event_type\":\"price_change\"}","received_at":"2026-07-27T05:36:03.947804Z","schema_version":"clob-market-ws.price_change.v1","sequence":null,"server_hash":null,"server_timestamp":"1785130563959","session_id":"502006c5cfcd437296561ea750c9ec8b","source":"clob_market_ws"},"received_at":"2026-07-27T05:36:03.947804Z","record_id":"9300a4105091f32b3bae6bf5ac134cadd5ee2c9f92f48c9ab979bd184a7dd1aa","schema_fingerprint":"4aa3821a28b0b7c2400bc59aba4bcc0a76e971dadd19610d3ad38c768e124dc7","schema_version":"edge-lab-recorder.raw.v1","sequence":null,"source":"clob_market_ws"}
{"event_at":"2026-07-27T05:36:03.965000Z","event_fingerprint":"a363d6202703ede948df7fe465d0ff2cb77c50d6d1ffd486dc85c6c25da73e3b","payload":{"connection_id":"efc69d3132f1467b8e898a382b23ac0d","event_at":"2026-07-27T05:36:03.965000Z","event_type":"price_change","frame_hash":"d4f0c1213cfaf05ee9d760d3cd031fae762cf3d5822a832a0710932e241bf024","frame_index":0,"kind":"data","monotonic_ns":232547189805750,"payload":{"event_type":"price_change","market":"0x3b40066b5cf3871a2f6237c5628bd8092a206aa998558ac5ec13c4483e31e160","price_changes":[{"asset_id":"14766054693214075530629349735273995982307625376442606753688071083149620216746","best_ask":"0.32","best_bid":"0.31","hash":"8a822a4415cb5a478d5590e08790d37f98636ac0","price":"0.48","side":"SELL","size":"155"},{"asset_id":"110216635572655435074987471276357323571387854733835379371586402147734167783946","best_ask":"0.69","best_bid":"0.68","hash":"da0e8e1236cc23a1708ea741ff66f87e3b7d1190","price":"0.52","side":"BUY","size":"155"}],"timestamp":"1785130563965"},"payload_hash":"5422458ac94dfe7e22232574d64a626303e145ffbbc60d9b88944b7bcdacf6e6","raw_frame":"{\"market\":\"0x3b40066b5cf3871a2f6237c5628bd8092a206aa998558ac5ec13c4483e31e160\", \"price_changes\":[{\"asset_id\":\"14766054693214075530629349735273995982307625376442606753688071083149620216746\", \"price\":\"0.48\", \"size\":\"155\", \"side\":\"SELL\", \"hash\":\"8a822a4415cb5a478d5590e08790d37f98636ac0\", \"best_bid\":\"0.31\", \"best_ask\":\"0.32\"}, {\"asset_id\":\"110216635572655435074987471276357323571387854733835379371586402147734167783946\", \"price\":\"0.52\", \"size\":\"155\", \"side\":\"BUY\", \"hash\":\"da0e8e1236cc23a1708ea741ff66f87e3b7d1190\", \"best_bid\":\"0.68\", \"best_ask\":\"0.69\"}], \"timestamp\":\"1785130563965\", \"event_type\":\"price_change\"}","received_at":"2026-07-27T05:36:03.954126Z","schema_version":"clob-market-ws.price_change.v1","sequence":null,"server_hash":null,"server_timestamp":"1785130563965","session_id":"502006c5cfcd437296561ea750c9ec8b","source":"clob_market_ws"},"received_at":"2026-07-27T05:36:03.954126Z","record_id":"4f04a7f98018a658ed53cccfaab4527e09dbbdf282e2eedc546291a5fcbcf295","schema_fingerprint":"4aa3821a28b0b7c2400bc59aba4bcc0a76e971dadd19610d3ad38c768e124dc7","schema_version":"edge-lab-recorder.raw.v1","sequence":null,"source":"clob_market_ws"}
{"event_at":"2026-07-27T05:36:03.972000Z","event_fingerprint":"d436524d65d62ea812d43a0bdd635cab61ad5d01869f5c4ec73c4408ce74a99a","payload":{"connection_id":"efc69d3132f1467b8e898a382b23ac0d","event_at":"2026-07-27T05:36:03.972000Z","event_type":"price_change","frame_hash":"195133946bfa6071a1ff84a27644e70946cea1b6da3ef73d740226841e8501b9","frame_index":0,"kind":"data","monotonic_ns":232547194491750,"payload":{"event_type":"price_change","market":"0x3b40066b5cf3871a2f6237c5628bd8092a206aa998558ac5ec13c4483e31e160","price_changes":[{"asset_id":"110216635572655435074987471276357323571387854733835379371586402147734167783946","best_ask":"0.69","best_bid":"0.68","hash":"c4c79e1f92c0856d27eb55af1c1031237b658d93","price":"0.01","side":"BUY","size":"5607.45"},{"asset_id":"14766054693214075530629349735273995982307625376442606753688071083149620216746","best_ask":"0.32","best_bid":"0.31","hash":"3b6a3575baedce72d85154adcb40f1161b1aad00","price":"0.99","side":"SELL","size":"5607.45"}],"timestamp":"1785130563972"},"payload_hash":"cf701d782781c1417fa8d8b926d554a764a44642ae284be0b6206d78eb1a8b5d","raw_frame":"{\"market\":\"0x3b40066b5cf3871a2f6237c5628bd8092a206aa998558ac5ec13c4483e31e160\", \"price_changes\":[{\"asset_id\":\"110216635572655435074987471276357323571387854733835379371586402147734167783946\", \"price\":\"0.01\", \"size\":\"5607.45\", \"side\":\"BUY\", \"hash\":\"c4c79e1f92c0856d27eb55af1c1031237b658d93\", \"best_bid\":\"0.68\", \"best_ask\":\"0.69\"}, {\"asset_id\":\"14766054693214075530629349735273995982307625376442606753688071083149620216746\", \"price\":\"0.99\", \"size\":\"5607.45\", \"side\":\"SELL\", \"hash\":\"3b6a3575baedce72d85154adcb40f1161b1aad00\", \"best_bid\":\"0.31\", \"best_ask\":\"0.32\"}], \"timestamp\":\"1785130563972\", \"event_type\":\"price_change\"}","received_at":"2026-07-27T05:36:03.958811Z","schema_version":"clob-market-ws.price_change.v1","sequence":null,"server_hash":null,"server_timestamp":"1785130563972","session_id":"502006c5cfcd437296561ea750c9ec8b","source":"clob_market_ws"},"received_at":"2026-07-27T05:36:03.958811Z","record_id":"b822090180aca7e963f5b2f70c9bf20c50fbf7bc965510638c46910be766f79c","schema_fingerprint":"4aa3821a28b0b7c2400bc59aba4bcc0a76e971dadd19610d3ad38c768e124dc7","schema_version":"edge-lab-recorder.raw.v1","sequence":null,"source":"clob_market_ws"}
{"event_at":"2026-07-27T05:36:03.990000Z","event_fingerprint":"7183c6cd1d7ad1ec189e7fa47433c7e2e4dbd520d85f8555e968d69fe280b9bd","payload":{"connection_id":"efc69d3132f1467b8e898a382b23ac0d","event_at":"2026-07-27T05:36:03.990000Z","event_type":"price_change","frame_hash":"d0cd810428c323fc66b1c3fc7623b02c49cdedb3038cbcdb837f00400ea4e674","frame_index":0,"kind":"data","monotonic_ns":232547199721666,"payload":{"event_type":"price_change","market":"0x3b40066b5cf3871a2f6237c5628bd8092a206aa998558ac5ec13c4483e31e160","price_changes":[{"asset_id":"110216635572655435074987471276357323571387854733835379371586402147734167783946","best_ask":"0.69","best_bid":"0.68","hash":"f52463783d1760428ae5ab056ee9eaac8356c23d","price":"0.02","side":"BUY","size":"673.1"},{"asset_id":"14766054693214075530629349735273995982307625376442606753688071083149620216746","best_ask":"0.32","best_bid":"0.31","hash":"0afa416c94ea17087c9b94137c43c3276aa7c964","price":"0.98","side":"SELL","size":"673.1"}],"timestamp":"1785130563990"},"payload_hash":"c65cdb48db618c9f695c9dfd59fa5a394d803666e167de8ff3e1fb19c85ad3d5","raw_frame":"{\"market\":\"0x3b40066b5cf3871a2f6237c5628bd8092a206aa998558ac5ec13c4483e31e160\", \"price_changes\":[{\"asset_id\":\"110216635572655435074987471276357323571387854733835379371586402147734167783946\", \"price\":\"0.02\", \"size\":\"673.1\", \"side\":\"BUY\", \"hash\":\"f52463783d1760428ae5ab056ee9eaac8356c23d\", \"best_bid\":\"0.68\", \"best_ask\":\"0.69\"}, {\"asset_id\":\"14766054693214075530629349735273995982307625376442606753688071083149620216746\", \"price\":\"0.98\", \"size\":\"673.1\", \"side\":\"SELL\", \"hash\":\"0afa416c94ea17087c9b94137c43c3276aa7c964\", \"best_bid\":\"0.31\", \"best_ask\":\"0.32\"}], \"timestamp\":\"1785130563990\", \"event_type\":\"price_change\"}","received_at":"2026-07-27T05:36:03.964047Z","schema_version":"clob-market-ws.price_change.v1","sequence":null,"server_hash":null,"server_timestamp":"1785130563990","session_id":"502006c5cfcd437296561ea750c9ec8b","source":"clob_market_ws"},"received_at":"2026-07-27T05:36:03.964047Z","record_id":"2b392af027bb9e7440eb871901a635669ec8527eb7f54ed06b8f735e788da961","schema_fingerprint":"4aa3821a28b0b7c2400bc59aba4bcc0a76e971dadd19610d3ad38c768e124dc7","schema_version":"edge-lab-recorder.raw.v1","sequence":null,"source":"clob_market_ws"}
