{"event_at":"2026-07-27T04:41:11.258000Z","event_fingerprint":"9fbb01924a3b434c5e9ae929817a4a75fe2c427a4f0c1b919c6c0ba502aa3e09","payload":{"connection_id":"0f4979d6978d463e9660b042fdcf555f","event_at":"2026-07-27T04:41:11.258000Z","event_type":"price_change","frame_hash":"364cc2fe3679190d151e7f12f7dd64da8496450a4b99814bb5cf6667db80ffea","frame_index":0,"kind":"data","monotonic_ns":229254575794458,"payload":{"event_type":"price_change","market":"0xeb66215f2e9faa6449e30a02bab5b8ed7b79a38bf961f6b24d0073c9c2419250","price_changes":[{"asset_id":"60386828328910021732068595344565885737045900010034836345809386672230885527307","best_ask":"0.16","best_bid":"0.15","hash":"87697a0deac8d6c0771d9f0a26a474d329e00cea","price":"0.07","side":"BUY","size":"190"},{"asset_id":"69697746896130839564035629862476347944307040470122503199396727085502753297492","best_ask":"0.85","best_bid":"0.84","hash":"2edc1ae7fc7e3c998f5fd9f3a8f4b9875ac587c5","price":"0.93","side":"SELL","size":"190"}],"timestamp":"1785127271258"},"payload_hash":"71cd7d53d8b55a4b1d24347c05d29be8d5742f116634989b92108ca84188a9ff","raw_frame":"{\"market\":\"0xeb66215f2e9faa6449e30a02bab5b8ed7b79a38bf961f6b24d0073c9c2419250\", \"price_changes\":[{\"asset_id\":\"60386828328910021732068595344565885737045900010034836345809386672230885527307\", \"price\":\"0.07\", \"size\":\"190\", \"side\":\"BUY\", \"hash\":\"87697a0deac8d6c0771d9f0a26a474d329e00cea\", \"best_bid\":\"0.15\", \"best_ask\":\"0.16\"}, {\"asset_id\":\"69697746896130839564035629862476347944307040470122503199396727085502753297492\", \"price\":\"0.93\", \"size\":\"190\", \"side\":\"SELL\", \"hash\":\"2edc1ae7fc7e3c998f5fd9f3a8f4b9875ac587c5\", \"best_bid\":\"0.84\", \"best_ask\":\"0.85\"}], \"timestamp\":\"1785127271258\", \"event_type\":\"price_change\"}","received_at":"2026-07-27T04:41:11.311774Z","schema_version":"clob-market-ws.price_change.v1","sequence":null,"server_hash":null,"server_timestamp":"1785127271258","session_id":"e9443c7415a0419799bee9cfbb1a9e4d","source":"clob_market_ws"},"received_at":"2026-07-27T04:41:11.311774Z","record_id":"4df369cbc6a0af56777f9fe7ee4cacb724f97abd217c6ccf3a03bbc6c28b62a5","schema_fingerprint":"4aa3821a28b0b7c2400bc59aba4bcc0a76e971dadd19610d3ad38c768e124dc7","schema_version":"edge-lab-recorder.raw.v1","sequence":null,"source":"clob_market_ws"}
{"event_at":"2026-07-27T04:41:11.259000Z","event_fingerprint":"a367641bb9ce2fe1ed9dc0e0468f58c7a24e6675ee96ee3416501cb00fefad50","payload":{"connection_id":"0f4979d6978d463e9660b042fdcf555f","event_at":"2026-07-27T04:41:11.259000Z","event_type":"price_change","frame_hash":"9f877912fd204dc5344b1c124ae9182b5c78ca51d9342af7371a42fb2e892911","frame_index":0,"kind":"data","monotonic_ns":229254585060583,"payload":{"event_type":"price_change","market":"0xeb66215f2e9faa6449e30a02bab5b8ed7b79a38bf961f6b24d0073c9c2419250","price_changes":[{"asset_id":"69697746896130839564035629862476347944307040470122503199396727085502753297492","best_ask":"0.85","best_bid":"0.84","hash":"372374a0329bc242ec44904476568003ee3ab9b4","price":"0.85","side":"SELL","size":"155.6"},{"asset_id":"60386828328910021732068595344565885737045900010034836345809386672230885527307","best_ask":"0.16","best_bid":"0.15","hash":"1f5c3e5ad8f3f136c2507f20dd78b03717398eaa","price":"0.15","side":"BUY","size":"155.6"}],"timestamp":"1785127271259"},"payload_hash":"1d1e3940129c6ef7415682a5dd390767b917ffc12135a973553eb8e4fb6693ea","raw_frame":"{\"market\":\"0xeb66215f2e9faa6449e30a02bab5b8ed7b79a38bf961f6b24d0073c9c2419250\", \"price_changes\":[{\"asset_id\":\"69697746896130839564035629862476347944307040470122503199396727085502753297492\", \"price\":\"0.85\", \"size\":\"155.6\", \"side\":\"SELL\", \"hash\":\"372374a0329bc242ec44904476568003ee3ab9b4\", \"best_bid\":\"0.84\", \"best_ask\":\"0.85\"}, {\"asset_id\":\"60386828328910021732068595344565885737045900010034836345809386672230885527307\", \"price\":\"0.15\", \"size\":\"155.6\", \"side\":\"BUY\", \"hash\":\"1f5c3e5ad8f3f136c2507f20dd78b03717398eaa\", \"best_bid\":\"0.15\", \"best_ask\":\"0.16\"}], \"timestamp\":\"1785127271259\", \"event_type\":\"price_change\"}","received_at":"2026-07-27T04:41:11.321033Z","schema_version":"clob-market-ws.price_change.v1","sequence":null,"server_hash":null,"server_timestamp":"1785127271259","session_id":"e9443c7415a0419799bee9cfbb1a9e4d","source":"clob_market_ws"},"received_at":"2026-07-27T04:41:11.321033Z","record_id":"9d1df70a6838bb7a9160b1d27797ca5791209745b19c19fb1c059bf5d80798b0","schema_fingerprint":"4aa3821a28b0b7c2400bc59aba4bcc0a76e971dadd19610d3ad38c768e124dc7","schema_version":"edge-lab-recorder.raw.v1","sequence":null,"source":"clob_market_ws"}
{"event_at":"2026-07-27T04:41:11.261000Z","event_fingerprint":"2098d19e085cfa2338ec91226b4d0f62cb5f45a0fa1415fa71777f1e60dfbc0f","payload":{"connection_id":"0f4979d6978d463e9660b042fdcf555f","event_at":"2026-07-27T04:41:11.261000Z","event_type":"price_change","frame_hash":"6132cc4f7552764ce0330bab8a1a5d173453faa56309bd7aef524bd3d0198051","frame_index":0,"kind":"data","monotonic_ns":229254588785416,"payload":{"event_type":"price_change","market":"0xeb66215f2e9faa6449e30a02bab5b8ed7b79a38bf961f6b24d0073c9c2419250","price_changes":[{"asset_id":"69697746896130839564035629862476347944307040470122503199396727085502753297492","best_ask":"0.85","best_bid":"0.84","hash":"71529c204f44bb06c89c887e846af3f82e7c1f61","price":"0.84","side":"BUY","size":"15"},{"asset_id":"60386828328910021732068595344565885737045900010034836345809386672230885527307","best_ask":"0.16","best_bid":"0.15","hash":"8a7d0cdba4484f4bf366f5e70c5dbc6a32aae534","price":"0.16","side":"SELL","size":"15"}],"timestamp":"1785127271261"},"payload_hash":"999ddc74e90af29f2be868d24cd572fb32180f616a81a393ea515efe1f98eff4","raw_frame":"{\"market\":\"0xeb66215f2e9faa6449e30a02bab5b8ed7b79a38bf961f6b24d0073c9c2419250\", \"price_changes\":[{\"asset_id\":\"69697746896130839564035629862476347944307040470122503199396727085502753297492\", \"price\":\"0.84\", \"size\":\"15\", \"side\":\"BUY\", \"hash\":\"71529c204f44bb06c89c887e846af3f82e7c1f61\", \"best_bid\":\"0.84\", \"best_ask\":\"0.85\"}, {\"asset_id\":\"60386828328910021732068595344565885737045900010034836345809386672230885527307\", \"price\":\"0.16\", \"size\":\"15\", \"side\":\"SELL\", \"hash\":\"8a7d0cdba4484f4bf366f5e70c5dbc6a32aae534\", \"best_bid\":\"0.15\", \"best_ask\":\"0.16\"}], \"timestamp\":\"1785127271261\", \"event_type\":\"price_change\"}","received_at":"2026-07-27T04:41:11.324767Z","schema_version":"clob-market-ws.price_change.v1","sequence":null,"server_hash":null,"server_timestamp":"1785127271261","session_id":"e9443c7415a0419799bee9cfbb1a9e4d","source":"clob_market_ws"},"received_at":"2026-07-27T04:41:11.324767Z","record_id":"3afaaecd78094583df3da8ff0e8011d5383c21aac0f745352204feab49b3aee6","schema_fingerprint":"4aa3821a28b0b7c2400bc59aba4bcc0a76e971dadd19610d3ad38c768e124dc7","schema_version":"edge-lab-recorder.raw.v1","sequence":null,"source":"clob_market_ws"}
{"event_at":"2026-07-27T04:41:11.262000Z","event_fingerprint":"21093362842365752fc6bad68cc7e4a4880c36aacd19c6ff99c18e0c8a8edd7f","payload":{"connection_id":"0f4979d6978d463e9660b042fdcf555f","event_at":"2026-07-27T04:41:11.262000Z","event_type":"price_change","frame_hash":"8a45d2ca24d7efcc28f8a0bd63a715e99e65dec66d05b7e2af75a99bb1a75954","frame_index":0,"kind":"data","monotonic_ns":229254592948750,"payload":{"event_type":"price_change","market":"0xeb66215f2e9faa6449e30a02bab5b8ed7b79a38bf961f6b24d0073c9c2419250","price_changes":[{"asset_id":"69697746896130839564035629862476347944307040470122503199396727085502753297492","best_ask":"0.85","best_bid":"0.84","hash":"cc98cd40f79674c1a2a5e0fbfc7a1e816c5a7349","price":"0.83","side":"BUY","size":"65.21"},{"asset_id":"60386828328910021732068595344565885737045900010034836345809386672230885527307","best_ask":"0.16","best_bid":"0.15","hash":"5822aa697c14536d6bd8919de9b17e27bdeeadc4","price":"0.17","side":"SELL","size":"65.21"}],"timestamp":"1785127271262"},"payload_hash":"0abf45396cfca7ad2769752a56fecd4eb0dcc3c89960e02cb00e171f491bb8eb","raw_frame":"{\"market\":\"0xeb66215f2e9faa6449e30a02bab5b8ed7b79a38bf961f6b24d0073c9c2419250\", \"price_changes\":[{\"asset_id\":\"69697746896130839564035629862476347944307040470122503199396727085502753297492\", \"price\":\"0.83\", \"size\":\"65.21\", \"side\":\"BUY\", \"hash\":\"cc98cd40f79674c1a2a5e0fbfc7a1e816c5a7349\", \"best_bid\":\"0.84\", \"best_ask\":\"0.85\"}, {\"asset_id\":\"60386828328910021732068595344565885737045900010034836345809386672230885527307\", \"price\":\"0.17\", \"size\":\"65.21\", \"side\":\"SELL\", \"hash\":\"5822aa697c14536d6bd8919de9b17e27bdeeadc4\", \"best_bid\":\"0.15\", \"best_ask\":\"0.16\"}], \"timestamp\":\"1785127271262\", \"event_type\":\"price_change\"}","received_at":"2026-07-27T04:41:11.328929Z","schema_version":"clob-market-ws.price_change.v1","sequence":null,"server_hash":null,"server_timestamp":"1785127271262","session_id":"e9443c7415a0419799bee9cfbb1a9e4d","source":"clob_market_ws"},"received_at":"2026-07-27T04:41:11.328929Z","record_id":"175caf3ec856367a64ca5cad680d77e74e4af6c9d86bba3e527fd2f7326bc209","schema_fingerprint":"4aa3821a28b0b7c2400bc59aba4bcc0a76e971dadd19610d3ad38c768e124dc7","schema_version":"edge-lab-recorder.raw.v1","sequence":null,"source":"clob_market_ws"}
{"event_at":"2026-07-27T04:41:11.263000Z","event_fingerprint":"4ccfeacc5dc89a57b09c69e42095490af3ff1ab82ff1608beffa951609f0136a","payload":{"connection_id":"0f4979d6978d463e9660b042fdcf555f","event_at":"2026-07-27T04:41:11.263000Z","event_type":"price_change","frame_hash":"b79d3b0da627b50843b02b7eac1ad0470be37ec61a2c5c23f89ea58a3c42ed18","frame_index":0,"kind":"data","monotonic_ns":229254596589083,"payload":{"event_type":"price_change","market":"0xeb66215f2e9faa6449e30a02bab5b8ed7b79a38bf961f6b24d0073c9c2419250","price_changes":[{"asset_id":"69697746896130839564035629862476347944307040470122503199396727085502753297492","best_ask":"0.85","best_bid":"0.84","hash":"63bcad2f927d23814e9584719154638b75c72cff","price":"0.84","side":"BUY","size":"10"},{"asset_id":"60386828328910021732068595344565885737045900010034836345809386672230885527307","best_ask":"0.16","best_bid":"0.15","hash":"4b4f50cf7b9e80b49f0684e21275dbe05b8310b2","price":"0.16","side":"SELL","size":"10"}],"timestamp":"1785127271263"},"payload_hash":"3d1a98d758c2a26f1c34be3f20013a584e05b11ab228fee0a9aafb0428afaa42","raw_frame":"{\"market\":\"0xeb66215f2e9faa6449e30a02bab5b8ed7b79a38bf961f6b24d0073c9c2419250\", \"price_changes\":[{\"asset_id\":\"69697746896130839564035629862476347944307040470122503199396727085502753297492\", \"price\":\"0.84\", \"size\":\"10\", \"side\":\"BUY\", \"hash\":\"63bcad2f927d23814e9584719154638b75c72cff\", \"best_bid\":\"0.84\", \"best_ask\":\"0.85\"}, {\"asset_id\":\"60386828328910021732068595344565885737045900010034836345809386672230885527307\", \"price\":\"0.16\", \"size\":\"10\", \"side\":\"SELL\", \"hash\":\"4b4f50cf7b9e80b49f0684e21275dbe05b8310b2\", \"best_bid\":\"0.15\", \"best_ask\":\"0.16\"}], \"timestamp\":\"1785127271263\", \"event_type\":\"price_change\"}","received_at":"2026-07-27T04:41:11.332570Z","schema_version":"clob-market-ws.price_change.v1","sequence":null,"server_hash":null,"server_timestamp":"1785127271263","session_id":"e9443c7415a0419799bee9cfbb1a9e4d","source":"clob_market_ws"},"received_at":"2026-07-27T04:41:11.332570Z","record_id":"f08783ccb549f3e55c6ad13455a3915414fc7c322974bfbe821276d82a21d40c","schema_fingerprint":"4aa3821a28b0b7c2400bc59aba4bcc0a76e971dadd19610d3ad38c768e124dc7","schema_version":"edge-lab-recorder.raw.v1","sequence":null,"source":"clob_market_ws"}
{"event_at":"2026-07-27T04:41:11.264000Z","event_fingerprint":"39374cb19528d51ba778c3deeef7230cc13a52dc4689fdbfec6204f7fc834673","payload":{"connection_id":"0f4979d6978d463e9660b042fdcf555f","event_at":"2026-07-27T04:41:11.264000Z","event_type":"price_change","frame_hash":"b2f30d234f275c4703f3c483361aaba8b1729970a0d4f812baabb5adc37de8f7","frame_index":0,"kind":"data","monotonic_ns":229254601611125,"payload":{"event_type":"price_change","market":"0xeb66215f2e9faa6449e30a02bab5b8ed7b79a38bf961f6b24d0073c9c2419250","price_changes":[{"asset_id":"69697746896130839564035629862476347944307040470122503199396727085502753297492","best_ask":"0.85","best_bid":"0.84","hash":"5609fd9c0eb963052d46d4f4cfeecbb60ff6a54e","price":"0.78","side":"BUY","size":"17.5"},{"asset_id":"60386828328910021732068595344565885737045900010034836345809386672230885527307","best_ask":"0.16","best_bid":"0.15","hash":"d0a0dcff08b69745a890c1a3232ef8b5b7a88a85","price":"0.22","side":"SELL","size":"17.5"}],"timestamp":"1785127271264"},"payload_hash":"dfdc91aa1758628da2917ca8d60c576e9eba3a7106fedff6cad9360fddf8e6c8","raw_frame":"{\"market\":\"0xeb66215f2e9faa6449e30a02bab5b8ed7b79a38bf961f6b24d0073c9c2419250\", \"price_changes\":[{\"asset_id\":\"69697746896130839564035629862476347944307040470122503199396727085502753297492\", \"price\":\"0.78\", \"size\":\"17.5\", \"side\":\"BUY\", \"hash\":\"5609fd9c0eb963052d46d4f4cfeecbb60ff6a54e\", \"best_bid\":\"0.84\", \"best_ask\":\"0.85\"}, {\"asset_id\":\"60386828328910021732068595344565885737045900010034836345809386672230885527307\", \"price\":\"0.22\", \"size\":\"17.5\", \"side\":\"SELL\", \"hash\":\"d0a0dcff08b69745a890c1a3232ef8b5b7a88a85\", \"best_bid\":\"0.15\", \"best_ask\":\"0.16\"}], \"timestamp\":\"1785127271264\", \"event_type\":\"price_change\"}","received_at":"2026-07-27T04:41:11.337586Z","schema_version":"clob-market-ws.price_change.v1","sequence":null,"server_hash":null,"server_timestamp":"1785127271264","session_id":"e9443c7415a0419799bee9cfbb1a9e4d","source":"clob_market_ws"},"received_at":"2026-07-27T04:41:11.337586Z","record_id":"4cef7ffa9731642ab7e26210889c343eb1be6628447b1f2ee6a2879a2cedd63f","schema_fingerprint":"4aa3821a28b0b7c2400bc59aba4bcc0a76e971dadd19610d3ad38c768e124dc7","schema_version":"edge-lab-recorder.raw.v1","sequence":null,"source":"clob_market_ws"}
{"event_at":"2026-07-27T04:41:11.264000Z","event_fingerprint":"ee16abd357d647d1d709dc6c2c2487903be2708cd27a81d1f9e53091d531ba92","payload":{"connection_id":"0f4979d6978d463e9660b042fdcf555f","event_at":"2026-07-27T04:41:11.264000Z","event_type":"price_change","frame_hash":"1cf533872c3860573fb4b68a21fb99063e99930819f9b3add4250c79e6980ece","frame_index":0,"kind":"data","monotonic_ns":229254606397958,"payload":{"event_type":"price_change","market":"0xeb66215f2e9faa6449e30a02bab5b8ed7b79a38bf961f6b24d0073c9c2419250","price_changes":[{"asset_id":"69697746896130839564035629862476347944307040470122503199396727085502753297492","best_ask":"0.85","best_bid":"0.84","hash":"8d4e8757c2aed3d2c29b6d8384ecef93ec6b865f","price":"0.79","side":"BUY","size":"71.9"},{"asset_id":"60386828328910021732068595344565885737045900010034836345809386672230885527307","best_ask":"0.16","best_bid":"0.15","hash":"f1ccb445c374ff46e02d4745a96322828aa70c7b","price":"0.21","side":"SELL","size":"71.9"}],"timestamp":"1785127271264"},"payload_hash":"e702c5d1be7aa05ee510be26854988198e26012528bfc63e89f84a5ff3263341","raw_frame":"{\"market\":\"0xeb66215f2e9faa6449e30a02bab5b8ed7b79a38bf961f6b24d0073c9c2419250\", \"price_changes\":[{\"asset_id\":\"69697746896130839564035629862476347944307040470122503199396727085502753297492\", \"price\":\"0.79\", \"size\":\"71.9\", \"side\":\"BUY\", \"hash\":\"8d4e8757c2aed3d2c29b6d8384ecef93ec6b865f\", \"best_bid\":\"0.84\", \"best_ask\":\"0.85\"}, {\"asset_id\":\"60386828328910021732068595344565885737045900010034836345809386672230885527307\", \"price\":\"0.21\", \"size\":\"71.9\", \"side\":\"SELL\", \"hash\":\"f1ccb445c374ff46e02d4745a96322828aa70c7b\", \"best_bid\":\"0.15\", \"best_ask\":\"0.16\"}], \"timestamp\":\"1785127271264\", \"event_type\":\"price_change\"}","received_at":"2026-07-27T04:41:11.342378Z","schema_version":"clob-market-ws.price_change.v1","sequence":null,"server_hash":null,"server_timestamp":"1785127271264","session_id":"e9443c7415a0419799bee9cfbb1a9e4d","source":"clob_market_ws"},"received_at":"2026-07-27T04:41:11.342378Z","record_id":"eef207a4ef8a10f79097a7379eb84c8252cab2a70801d9ab606f0a390df699a9","schema_fingerprint":"4aa3821a28b0b7c2400bc59aba4bcc0a76e971dadd19610d3ad38c768e124dc7","schema_version":"edge-lab-recorder.raw.v1","sequence":null,"source":"clob_market_ws"}
{"event_at":"2026-07-27T04:41:11.264000Z","event_fingerprint":"df32e3184ddf36f175ae85cbf1aaebf560eb2c6de3b606b2339f0c04a15a5aa1","payload":{"connection_id":"0f4979d6978d463e9660b042fdcf555f","event_at":"2026-07-27T04:41:11.264000Z","event_type":"price_change","frame_hash":"043eb1cd6d7b7ae886d4a13c1264b51c413897c0ea348e11bdeea7075f2f8047","frame_index":0,"kind":"data","monotonic_ns":229254611417833,"payload":{"event_type":"price_change","market":"0xeb66215f2e9faa6449e30a02bab5b8ed7b79a38bf961f6b24d0073c9c2419250","price_changes":[{"asset_id":"60386828328910021732068595344565885737045900010034836345809386672230885527307","best_ask":"0.16","best_bid":"0.15","hash":"f1ccb445c374ff46e02d4745a96322828aa70c7b","price":"0.12","side":"BUY","size":"126.43"},{"asset_id":"69697746896130839564035629862476347944307040470122503199396727085502753297492","best_ask":"0.85","best_bid":"0.84","hash":"8d4e8757c2aed3d2c29b6d8384ecef93ec6b865f","price":"0.88","side":"SELL","size":"126.43"}],"timestamp":"1785127271264"},"payload_hash":"f3d47522d0dd8c86c36cb3fbd282cee6a405d5bbe123e39e7029352b72c05a52","raw_frame":"{\"market\":\"0xeb66215f2e9faa6449e30a02bab5b8ed7b79a38bf961f6b24d0073c9c2419250\", \"price_changes\":[{\"asset_id\":\"60386828328910021732068595344565885737045900010034836345809386672230885527307\", \"price\":\"0.12\", \"size\":\"126.43\", \"side\":\"BUY\", \"hash\":\"f1ccb445c374ff46e02d4745a96322828aa70c7b\", \"best_bid\":\"0.15\", \"best_ask\":\"0.16\"}, {\"asset_id\":\"69697746896130839564035629862476347944307040470122503199396727085502753297492\", \"price\":\"0.88\", \"size\":\"126.43\", \"side\":\"SELL\", \"hash\":\"8d4e8757c2aed3d2c29b6d8384ecef93ec6b865f\", \"best_bid\":\"0.84\", \"best_ask\":\"0.85\"}], \"timestamp\":\"1785127271264\", \"event_type\":\"price_change\"}","received_at":"2026-07-27T04:41:11.347399Z","schema_version":"clob-market-ws.price_change.v1","sequence":null,"server_hash":null,"server_timestamp":"1785127271264","session_id":"e9443c7415a0419799bee9cfbb1a9e4d","source":"clob_market_ws"},"received_at":"2026-07-27T04:41:11.347399Z","record_id":"f13a3c3dbe239adf47936b89a9234d64a4bdcbd2fbba615f30bb9dc00397377d","schema_fingerprint":"4aa3821a28b0b7c2400bc59aba4bcc0a76e971dadd19610d3ad38c768e124dc7","schema_version":"edge-lab-recorder.raw.v1","sequence":null,"source":"clob_market_ws"}
{"event_at":"2026-07-27T04:41:11.270000Z","event_fingerprint":"6efc6bdf6c486082541d4dc542cc7d878dae10fa16626dd00443e79ddd80c9ca","payload":{"connection_id":"0f4979d6978d463e9660b042fdcf555f","event_at":"2026-07-27T04:41:11.270000Z","event_type":"price_change","frame_hash":"1e85d764d6a8bf4f409f5c87a9a07a62bcb91900a496ba78dee2276e47a92fff","frame_index":0,"kind":"data","monotonic_ns":229254613805208,"payload":{"event_type":"price_change","market":"0xeb66215f2e9faa6449e30a02bab5b8ed7b79a38bf961f6b24d0073c9c2419250","price_changes":[{"asset_id":"69697746896130839564035629862476347944307040470122503199396727085502753297492","best_ask":"0.85","best_bid":"0.84","hash":"09681f490c38070f1f82112f25fdbcde3b5fb478","price":"0.02","side":"BUY","size":"688.1"},{"asset_id":"60386828328910021732068595344565885737045900010034836345809386672230885527307","best_ask":"0.16","best_bid":"0.15","hash":"cfac600201039ca3c0a957694a2306b699399975","price":"0.98","side":"SELL","size":"688.1"}],"timestamp":"1785127271270"},"payload_hash":"d3131661a44b118d777d39bb23e844c09ec51383093940e88536adbafa1ea977","raw_frame":"{\"market\":\"0xeb66215f2e9faa6449e30a02bab5b8ed7b79a38bf961f6b24d0073c9c2419250\", \"price_changes\":[{\"asset_id\":\"69697746896130839564035629862476347944307040470122503199396727085502753297492\", \"price\":\"0.02\", \"size\":\"688.1\", \"side\":\"BUY\", \"hash\":\"09681f490c38070f1f82112f25fdbcde3b5fb478\", \"best_bid\":\"0.84\", \"best_ask\":\"0.85\"}, {\"asset_id\":\"60386828328910021732068595344565885737045900010034836345809386672230885527307\", \"price\":\"0.98\", \"size\":\"688.1\", \"side\":\"SELL\", \"hash\":\"cfac600201039ca3c0a957694a2306b699399975\", \"best_bid\":\"0.15\", \"best_ask\":\"0.16\"}], \"timestamp\":\"1785127271270\", \"event_type\":\"price_change\"}","received_at":"2026-07-27T04:41:11.349786Z","schema_version":"clob-market-ws.price_change.v1","sequence":null,"server_hash":null,"server_timestamp":"1785127271270","session_id":"e9443c7415a0419799bee9cfbb1a9e4d","source":"clob_market_ws"},"received_at":"2026-07-27T04:41:11.349786Z","record_id":"e57a45d3d4472cb0e53bcffb657046e3340604c64bd1e91b9ce1363f7e94e261","schema_fingerprint":"4aa3821a28b0b7c2400bc59aba4bcc0a76e971dadd19610d3ad38c768e124dc7","schema_version":"edge-lab-recorder.raw.v1","sequence":null,"source":"clob_market_ws"}
{"event_at":"2026-07-27T04:41:11.270000Z","event_fingerprint":"9c38ae7728ffd4aed2d1108c194dc4a85f249b073f80ba701b183e2a5a133aa2","payload":{"connection_id":"0f4979d6978d463e9660b042fdcf555f","event_at":"2026-07-27T04:41:11.270000Z","event_type":"price_change","frame_hash":"40c316def9f06293fae986bf9dbbb6737a9bd9f4701663d242d8e0893b055a31","frame_index":0,"kind":"data","monotonic_ns":229254620960291,"payload":{"event_type":"price_change","market":"0xeb66215f2e9faa6449e30a02bab5b8ed7b79a38bf961f6b24d0073c9c2419250","price_changes":[{"asset_id":"69697746896130839564035629862476347944307040470122503199396727085502753297492","best_ask":"0.85","best_bid":"0.84","hash":"d611d3a77738e1e5ac56d251e754e97d12914d49","price":"0.84","side":"BUY","size":"16"},{"asset_id":"60386828328910021732068595344565885737045900010034836345809386672230885527307","best_ask":"0.16","best_bid":"0.15","hash":"4f3c764e72efbb394fc4e0cbfa44682a31789c6e","price":"0.16","side":"SELL","size":"16"}],"timestamp":"1785127271270"},"payload_hash":"f55906dafc78444b90669f045fccc4a72f43b90be386d9e4af8cece62f35b047","raw_frame":"{\"market\":\"0xeb66215f2e9faa6449e30a02bab5b8ed7b79a38bf961f6b24d0073c9c2419250\", \"price_changes\":[{\"asset_id\":\"69697746896130839564035629862476347944307040470122503199396727085502753297492\", \"price\":\"0.84\", \"size\":\"16\", \"side\":\"BUY\", \"hash\":\"d611d3a77738e1e5ac56d251e754e97d12914d49\", \"best_bid\":\"0.84\", \"best_ask\":\"0.85\"}, {\"asset_id\":\"60386828328910021732068595344565885737045900010034836345809386672230885527307\", \"price\":\"0.16\", \"size\":\"16\", \"side\":\"SELL\", \"hash\":\"4f3c764e72efbb394fc4e0cbfa44682a31789c6e\", \"best_bid\":\"0.15\", \"best_ask\":\"0.16\"}], \"timestamp\":\"1785127271270\", \"event_type\":\"price_change\"}","received_at":"2026-07-27T04:41:11.356941Z","schema_version":"clob-market-ws.price_change.v1","sequence":null,"server_hash":null,"server_timestamp":"1785127271270","session_id":"e9443c7415a0419799bee9cfbb1a9e4d","source":"clob_market_ws"},"received_at":"2026-07-27T04:41:11.356941Z","record_id":"437cb48cffaa1b0a42dbc766b01be340e51ad88bd7e887989dfdba3e39f7ea0b","schema_fingerprint":"4aa3821a28b0b7c2400bc59aba4bcc0a76e971dadd19610d3ad38c768e124dc7","schema_version":"edge-lab-recorder.raw.v1","sequence":null,"source":"clob_market_ws"}
