{"event_at":"2026-07-27T04:31:52.073000Z","event_fingerprint":"e1a82b23794772d5b5318cdf0fd5087491612849321b4670434b3541f128c5d5","payload":{"connection_id":"0f4979d6978d463e9660b042fdcf555f","event_at":"2026-07-27T04:31:52.073000Z","event_type":"price_change","frame_hash":"4f5e3cab93dc50b6e4835050a9d25e1b93620d7020216fd1178f31c73c8540f9","frame_index":0,"kind":"data","monotonic_ns":228695302154250,"payload":{"event_type":"price_change","market":"0xeb66215f2e9faa6449e30a02bab5b8ed7b79a38bf961f6b24d0073c9c2419250","price_changes":[{"asset_id":"60386828328910021732068595344565885737045900010034836345809386672230885527307","best_ask":"0.71","best_bid":"0.7","hash":"a387fd2403759538f4a08aeba6909bc31b4d344f","price":"0.01","side":"BUY","size":"7703.02"},{"asset_id":"69697746896130839564035629862476347944307040470122503199396727085502753297492","best_ask":"0.3","best_bid":"0.29","hash":"ab17a1988540c03f7bda0f141468f85d28e615bd","price":"0.99","side":"SELL","size":"7703.02"}],"timestamp":"1785126712073"},"payload_hash":"23885c1cbf3a0f46f83766ac45e65af759374635a480a7475c2b4f3fab48c99e","raw_frame":"{\"market\":\"0xeb66215f2e9faa6449e30a02bab5b8ed7b79a38bf961f6b24d0073c9c2419250\", \"price_changes\":[{\"asset_id\":\"60386828328910021732068595344565885737045900010034836345809386672230885527307\", \"price\":\"0.01\", \"size\":\"7703.02\", \"side\":\"BUY\", \"hash\":\"a387fd2403759538f4a08aeba6909bc31b4d344f\", \"best_bid\":\"0.7\", \"best_ask\":\"0.71\"}, {\"asset_id\":\"69697746896130839564035629862476347944307040470122503199396727085502753297492\", \"price\":\"0.99\", \"size\":\"7703.02\", \"side\":\"SELL\", \"hash\":\"ab17a1988540c03f7bda0f141468f85d28e615bd\", \"best_bid\":\"0.29\", \"best_ask\":\"0.3\"}], \"timestamp\":\"1785126712073\", \"event_type\":\"price_change\"}","received_at":"2026-07-27T04:31:52.033292Z","schema_version":"clob-market-ws.price_change.v1","sequence":null,"server_hash":null,"server_timestamp":"1785126712073","session_id":"e9443c7415a0419799bee9cfbb1a9e4d","source":"clob_market_ws"},"received_at":"2026-07-27T04:31:52.033292Z","record_id":"9e2b58e6211cb1e79c11e960d41d21c743f5215e80c4389cdf1fc20181f210d0","schema_fingerprint":"4aa3821a28b0b7c2400bc59aba4bcc0a76e971dadd19610d3ad38c768e124dc7","schema_version":"edge-lab-recorder.raw.v1","sequence":null,"source":"clob_market_ws"}
{"event_at":"2026-07-27T04:31:52.090000Z","event_fingerprint":"37b16c711edc57065be671ffadb95cddd31bea8b3a93663d62a89e65d1809a81","payload":{"connection_id":"0f4979d6978d463e9660b042fdcf555f","event_at":"2026-07-27T04:31:52.090000Z","event_type":"price_change","frame_hash":"552b8031491cbc64265d3e6f5cd4de83862f8f4eae3762037291e5574739c006","frame_index":0,"kind":"data","monotonic_ns":228695303692166,"payload":{"event_type":"price_change","market":"0xeb66215f2e9faa6449e30a02bab5b8ed7b79a38bf961f6b24d0073c9c2419250","price_changes":[{"asset_id":"60386828328910021732068595344565885737045900010034836345809386672230885527307","best_ask":"0.71","best_bid":"0.7","hash":"2f42dd113d6de2879eeb297c5609827c0d77a68f","price":"0.55","side":"BUY","size":"316.8"},{"asset_id":"69697746896130839564035629862476347944307040470122503199396727085502753297492","best_ask":"0.3","best_bid":"0.29","hash":"56097c74e45585feabab447f429c250286b162a9","price":"0.45","side":"SELL","size":"316.8"}],"timestamp":"1785126712090"},"payload_hash":"26561cf1f089bab1a51f616206a2d7d8085b12ef729cf5523bece4a868429819","raw_frame":"{\"market\":\"0xeb66215f2e9faa6449e30a02bab5b8ed7b79a38bf961f6b24d0073c9c2419250\", \"price_changes\":[{\"asset_id\":\"60386828328910021732068595344565885737045900010034836345809386672230885527307\", \"price\":\"0.55\", \"size\":\"316.8\", \"side\":\"BUY\", \"hash\":\"2f42dd113d6de2879eeb297c5609827c0d77a68f\", \"best_bid\":\"0.7\", \"best_ask\":\"0.71\"}, {\"asset_id\":\"69697746896130839564035629862476347944307040470122503199396727085502753297492\", \"price\":\"0.45\", \"size\":\"316.8\", \"side\":\"SELL\", \"hash\":\"56097c74e45585feabab447f429c250286b162a9\", \"best_bid\":\"0.29\", \"best_ask\":\"0.3\"}], \"timestamp\":\"1785126712090\", \"event_type\":\"price_change\"}","received_at":"2026-07-27T04:31:52.034832Z","schema_version":"clob-market-ws.price_change.v1","sequence":null,"server_hash":null,"server_timestamp":"1785126712090","session_id":"e9443c7415a0419799bee9cfbb1a9e4d","source":"clob_market_ws"},"received_at":"2026-07-27T04:31:52.034832Z","record_id":"208821e805756391fc10cc6467b50bf2bf34ba818e80e9c4d18fb27c75a6ca2f","schema_fingerprint":"4aa3821a28b0b7c2400bc59aba4bcc0a76e971dadd19610d3ad38c768e124dc7","schema_version":"edge-lab-recorder.raw.v1","sequence":null,"source":"clob_market_ws"}
{"event_at":"2026-07-27T04:31:52.091000Z","event_fingerprint":"268506d35e4a60d7c5791e9a362aa5c987086a6ea81bd881649f887c6ad613e5","payload":{"connection_id":"0f4979d6978d463e9660b042fdcf555f","event_at":"2026-07-27T04:31:52.091000Z","event_type":"price_change","frame_hash":"10e4a3b409f60e21dcf1f299c135f1dc1ad519a2ea4f25b31597ae798f504b18","frame_index":0,"kind":"data","monotonic_ns":228695304809666,"payload":{"event_type":"price_change","market":"0xeb66215f2e9faa6449e30a02bab5b8ed7b79a38bf961f6b24d0073c9c2419250","price_changes":[{"asset_id":"69697746896130839564035629862476347944307040470122503199396727085502753297492","best_ask":"0.3","best_bid":"0.29","hash":"ed324083ef0979dd1db01cc8c64ad99f4b891019","price":"0.14","side":"BUY","size":"245.69"},{"asset_id":"60386828328910021732068595344565885737045900010034836345809386672230885527307","best_ask":"0.71","best_bid":"0.7","hash":"e0c9105d792b63890eb93de2a6c1aae1d2f7119c","price":"0.86","side":"SELL","size":"245.69"}],"timestamp":"1785126712091"},"payload_hash":"14ad8bd0ee42b4bfb020c39f15824a8865acb8d3b7a9b913b2ff76b2ad807757","raw_frame":"{\"market\":\"0xeb66215f2e9faa6449e30a02bab5b8ed7b79a38bf961f6b24d0073c9c2419250\", \"price_changes\":[{\"asset_id\":\"69697746896130839564035629862476347944307040470122503199396727085502753297492\", \"price\":\"0.14\", \"size\":\"245.69\", \"side\":\"BUY\", \"hash\":\"ed324083ef0979dd1db01cc8c64ad99f4b891019\", \"best_bid\":\"0.29\", \"best_ask\":\"0.3\"}, {\"asset_id\":\"60386828328910021732068595344565885737045900010034836345809386672230885527307\", \"price\":\"0.86\", \"size\":\"245.69\", \"side\":\"SELL\", \"hash\":\"e0c9105d792b63890eb93de2a6c1aae1d2f7119c\", \"best_bid\":\"0.7\", \"best_ask\":\"0.71\"}], \"timestamp\":\"1785126712091\", \"event_type\":\"price_change\"}","received_at":"2026-07-27T04:31:52.035947Z","schema_version":"clob-market-ws.price_change.v1","sequence":null,"server_hash":null,"server_timestamp":"1785126712091","session_id":"e9443c7415a0419799bee9cfbb1a9e4d","source":"clob_market_ws"},"received_at":"2026-07-27T04:31:52.035947Z","record_id":"de625d20c518d022ffe6be3430ae56187b2c659873f0085842799ff793c7de59","schema_fingerprint":"4aa3821a28b0b7c2400bc59aba4bcc0a76e971dadd19610d3ad38c768e124dc7","schema_version":"edge-lab-recorder.raw.v1","sequence":null,"source":"clob_market_ws"}
{"event_at":"2026-07-27T04:31:52.101000Z","event_fingerprint":"6f7ad702d3a9fc8f56c957db59860cdde87d3d80e3204a3843ca7a5f8a7a6c20","payload":{"connection_id":"0f4979d6978d463e9660b042fdcf555f","event_at":"2026-07-27T04:31:52.101000Z","event_type":"price_change","frame_hash":"2ca0211dc36ff401db3ff7afad53150b0d53d9f080d17ff159133f84dd309d95","frame_index":0,"kind":"data","monotonic_ns":228695314372791,"payload":{"event_type":"price_change","market":"0xeb66215f2e9faa6449e30a02bab5b8ed7b79a38bf961f6b24d0073c9c2419250","price_changes":[{"asset_id":"69697746896130839564035629862476347944307040470122503199396727085502753297492","best_ask":"0.3","best_bid":"0.29","hash":"07deb44644b9a88513f02263bc9948f724dd380e","price":"0.31","side":"SELL","size":"426.56"},{"asset_id":"60386828328910021732068595344565885737045900010034836345809386672230885527307","best_ask":"0.71","best_bid":"0.7","hash":"fd6743dd53f9014b361dc00033d541dab8fa8617","price":"0.69","side":"BUY","size":"426.56"}],"timestamp":"1785126712101"},"payload_hash":"0c7dc2f7979fdba582a30052a436ccef3c433b03671101d11f12ad008d5e8e6b","raw_frame":"{\"market\":\"0xeb66215f2e9faa6449e30a02bab5b8ed7b79a38bf961f6b24d0073c9c2419250\", \"price_changes\":[{\"asset_id\":\"69697746896130839564035629862476347944307040470122503199396727085502753297492\", \"price\":\"0.31\", \"size\":\"426.56\", \"side\":\"SELL\", \"hash\":\"07deb44644b9a88513f02263bc9948f724dd380e\", \"best_bid\":\"0.29\", \"best_ask\":\"0.3\"}, {\"asset_id\":\"60386828328910021732068595344565885737045900010034836345809386672230885527307\", \"price\":\"0.69\", \"size\":\"426.56\", \"side\":\"BUY\", \"hash\":\"fd6743dd53f9014b361dc00033d541dab8fa8617\", \"best_bid\":\"0.7\", \"best_ask\":\"0.71\"}], \"timestamp\":\"1785126712101\", \"event_type\":\"price_change\"}","received_at":"2026-07-27T04:31:52.045512Z","schema_version":"clob-market-ws.price_change.v1","sequence":null,"server_hash":null,"server_timestamp":"1785126712101","session_id":"e9443c7415a0419799bee9cfbb1a9e4d","source":"clob_market_ws"},"received_at":"2026-07-27T04:31:52.045512Z","record_id":"fd3a06c332b5ec638a43dbdd5b0f96eeea71784c94b0b7cd852c9f9dfbd1cd2a","schema_fingerprint":"4aa3821a28b0b7c2400bc59aba4bcc0a76e971dadd19610d3ad38c768e124dc7","schema_version":"edge-lab-recorder.raw.v1","sequence":null,"source":"clob_market_ws"}
{"event_at":"2026-07-27T04:31:52.112000Z","event_fingerprint":"96601673e46de9562cfae478cd17dab45779adf02c8b3930c72374d9c3d1c2b5","payload":{"connection_id":"0f4979d6978d463e9660b042fdcf555f","event_at":"2026-07-27T04:31:52.112000Z","event_type":"price_change","frame_hash":"2f2f195ef92af58f12069fde7590777765b945e9c6c65ee69b722297df2238be","frame_index":0,"kind":"data","monotonic_ns":228695325916166,"payload":{"event_type":"price_change","market":"0xeb66215f2e9faa6449e30a02bab5b8ed7b79a38bf961f6b24d0073c9c2419250","price_changes":[{"asset_id":"69697746896130839564035629862476347944307040470122503199396727085502753297492","best_ask":"0.3","best_bid":"0.29","hash":"09f91b5437a11dc4fb4fa0f5bf9c9885b5cb3b91","price":"0.26","side":"BUY","size":"72.09"},{"asset_id":"60386828328910021732068595344565885737045900010034836345809386672230885527307","best_ask":"0.71","best_bid":"0.7","hash":"5b604c4e316eed4d3abdc32f947838ffe9832355","price":"0.74","side":"SELL","size":"72.09"}],"timestamp":"1785126712112"},"payload_hash":"cf35ebae7c2ed0f76956b8cbd6847c6579a0b3ee043c8e6a119ec7981a9cc92f","raw_frame":"{\"market\":\"0xeb66215f2e9faa6449e30a02bab5b8ed7b79a38bf961f6b24d0073c9c2419250\", \"price_changes\":[{\"asset_id\":\"69697746896130839564035629862476347944307040470122503199396727085502753297492\", \"price\":\"0.26\", \"size\":\"72.09\", \"side\":\"BUY\", \"hash\":\"09f91b5437a11dc4fb4fa0f5bf9c9885b5cb3b91\", \"best_bid\":\"0.29\", \"best_ask\":\"0.3\"}, {\"asset_id\":\"60386828328910021732068595344565885737045900010034836345809386672230885527307\", \"price\":\"0.74\", \"size\":\"72.09\", \"side\":\"SELL\", \"hash\":\"5b604c4e316eed4d3abdc32f947838ffe9832355\", \"best_bid\":\"0.7\", \"best_ask\":\"0.71\"}], \"timestamp\":\"1785126712112\", \"event_type\":\"price_change\"}","received_at":"2026-07-27T04:31:52.057051Z","schema_version":"clob-market-ws.price_change.v1","sequence":null,"server_hash":null,"server_timestamp":"1785126712112","session_id":"e9443c7415a0419799bee9cfbb1a9e4d","source":"clob_market_ws"},"received_at":"2026-07-27T04:31:52.057051Z","record_id":"01ebef45e3475fa3efc6257c423e7915420858f74dc756f25a8e2d8bf04aa30a","schema_fingerprint":"4aa3821a28b0b7c2400bc59aba4bcc0a76e971dadd19610d3ad38c768e124dc7","schema_version":"edge-lab-recorder.raw.v1","sequence":null,"source":"clob_market_ws"}
{"event_at":"2026-07-27T04:31:52.114000Z","event_fingerprint":"ebfa679f1999e342ec7320f54a6b4468fdabeaaaa0ec59ce080acb78f0d11311","payload":{"connection_id":"0f4979d6978d463e9660b042fdcf555f","event_at":"2026-07-27T04:31:52.114000Z","event_type":"price_change","frame_hash":"3f432d2cdf67146a929979c652c19a2736883a5c4f279e65584d94406f9a5a1a","frame_index":0,"kind":"data","monotonic_ns":228695328497125,"payload":{"event_type":"price_change","market":"0xeb66215f2e9faa6449e30a02bab5b8ed7b79a38bf961f6b24d0073c9c2419250","price_changes":[{"asset_id":"60386828328910021732068595344565885737045900010034836345809386672230885527307","best_ask":"0.71","best_bid":"0.7","hash":"4bbb768133d365025e2c8cfb99120f05d0e1955d","price":"0.65","side":"BUY","size":"60.47"},{"asset_id":"69697746896130839564035629862476347944307040470122503199396727085502753297492","best_ask":"0.3","best_bid":"0.29","hash":"af8a06c3be3df15c2d258243cbe48d0e09c2d589","price":"0.35","side":"SELL","size":"60.47"}],"timestamp":"1785126712114"},"payload_hash":"d2f4689ca46911607653bc283b03a57e2474fe81da74bb9b0ee46787bf14ceb9","raw_frame":"{\"market\":\"0xeb66215f2e9faa6449e30a02bab5b8ed7b79a38bf961f6b24d0073c9c2419250\", \"price_changes\":[{\"asset_id\":\"60386828328910021732068595344565885737045900010034836345809386672230885527307\", \"price\":\"0.65\", \"size\":\"60.47\", \"side\":\"BUY\", \"hash\":\"4bbb768133d365025e2c8cfb99120f05d0e1955d\", \"best_bid\":\"0.7\", \"best_ask\":\"0.71\"}, {\"asset_id\":\"69697746896130839564035629862476347944307040470122503199396727085502753297492\", \"price\":\"0.35\", \"size\":\"60.47\", \"side\":\"SELL\", \"hash\":\"af8a06c3be3df15c2d258243cbe48d0e09c2d589\", \"best_bid\":\"0.29\", \"best_ask\":\"0.3\"}], \"timestamp\":\"1785126712114\", \"event_type\":\"price_change\"}","received_at":"2026-07-27T04:31:52.059631Z","schema_version":"clob-market-ws.price_change.v1","sequence":null,"server_hash":null,"server_timestamp":"1785126712114","session_id":"e9443c7415a0419799bee9cfbb1a9e4d","source":"clob_market_ws"},"received_at":"2026-07-27T04:31:52.059631Z","record_id":"a3bd6d50e5e821a6f3011cfce61d1b4e4d54501ec4bb5815ce973e6e269a2c56","schema_fingerprint":"4aa3821a28b0b7c2400bc59aba4bcc0a76e971dadd19610d3ad38c768e124dc7","schema_version":"edge-lab-recorder.raw.v1","sequence":null,"source":"clob_market_ws"}
{"event_at":"2026-07-27T04:31:52.119000Z","event_fingerprint":"ba9a3ee94e4a16d7d7ff4fd0991a1f9efa696e5e6fd1dbfbf60398bb14e8a944","payload":{"connection_id":"0f4979d6978d463e9660b042fdcf555f","event_at":"2026-07-27T04:31:52.119000Z","event_type":"price_change","frame_hash":"67ab76a6b1286159dea02b3c22ed7ad4f094f0a2f755e53177abb32315f80629","frame_index":0,"kind":"data","monotonic_ns":228695332992375,"payload":{"event_type":"price_change","market":"0xeb66215f2e9faa6449e30a02bab5b8ed7b79a38bf961f6b24d0073c9c2419250","price_changes":[{"asset_id":"60386828328910021732068595344565885737045900010034836345809386672230885527307","best_ask":"0.71","best_bid":"0.7","hash":"48077ed96bc84e5fb432f59a0c44ab7e16bbda32","price":"0.63","side":"BUY","size":"242"},{"asset_id":"69697746896130839564035629862476347944307040470122503199396727085502753297492","best_ask":"0.3","best_bid":"0.29","hash":"526a5d7dc24b7aaa3e301ac27a58f37e40c2ee19","price":"0.37","side":"SELL","size":"242"}],"timestamp":"1785126712119"},"payload_hash":"5590852db8d5788f544dfe3b7fa39a8671d2ddcac1dc38c686768a5ff4716e2e","raw_frame":"{\"market\":\"0xeb66215f2e9faa6449e30a02bab5b8ed7b79a38bf961f6b24d0073c9c2419250\", \"price_changes\":[{\"asset_id\":\"60386828328910021732068595344565885737045900010034836345809386672230885527307\", \"price\":\"0.63\", \"size\":\"242\", \"side\":\"BUY\", \"hash\":\"48077ed96bc84e5fb432f59a0c44ab7e16bbda32\", \"best_bid\":\"0.7\", \"best_ask\":\"0.71\"}, {\"asset_id\":\"69697746896130839564035629862476347944307040470122503199396727085502753297492\", \"price\":\"0.37\", \"size\":\"242\", \"side\":\"SELL\", \"hash\":\"526a5d7dc24b7aaa3e301ac27a58f37e40c2ee19\", \"best_bid\":\"0.29\", \"best_ask\":\"0.3\"}], \"timestamp\":\"1785126712119\", \"event_type\":\"price_change\"}","received_at":"2026-07-27T04:31:52.064124Z","schema_version":"clob-market-ws.price_change.v1","sequence":null,"server_hash":null,"server_timestamp":"1785126712119","session_id":"e9443c7415a0419799bee9cfbb1a9e4d","source":"clob_market_ws"},"received_at":"2026-07-27T04:31:52.064124Z","record_id":"40d2ab8fba4b2efc54368252f9b486d3807e24222bd9d89d7907438003b8fdb2","schema_fingerprint":"4aa3821a28b0b7c2400bc59aba4bcc0a76e971dadd19610d3ad38c768e124dc7","schema_version":"edge-lab-recorder.raw.v1","sequence":null,"source":"clob_market_ws"}
{"event_at":"2026-07-27T04:31:52.140000Z","event_fingerprint":"ab0b877d24181926df10f5d4c890a8719e31ec2b6ccecc08069e83618f075855","payload":{"connection_id":"0f4979d6978d463e9660b042fdcf555f","event_at":"2026-07-27T04:31:52.140000Z","event_type":"price_change","frame_hash":"1f298e05ef54d7b39ac2ad878767591c46d034e29c3a21cb142b6c29ad1f562d","frame_index":0,"kind":"data","monotonic_ns":228695353632458,"payload":{"event_type":"price_change","market":"0xeb66215f2e9faa6449e30a02bab5b8ed7b79a38bf961f6b24d0073c9c2419250","price_changes":[{"asset_id":"60386828328910021732068595344565885737045900010034836345809386672230885527307","best_ask":"0.71","best_bid":"0.7","hash":"b5d0de678c21d731272be4b696f02b58ef4a5faa","price":"0.01","side":"BUY","size":"7708.02"},{"asset_id":"69697746896130839564035629862476347944307040470122503199396727085502753297492","best_ask":"0.3","best_bid":"0.29","hash":"1cd3f215ff2d9645c2f23a27ece5934020faa5fe","price":"0.99","side":"SELL","size":"7708.02"}],"timestamp":"1785126712140"},"payload_hash":"af877115f23e566cb6bb9c50deac014340de43228552b870bff69b93773d856e","raw_frame":"{\"market\":\"0xeb66215f2e9faa6449e30a02bab5b8ed7b79a38bf961f6b24d0073c9c2419250\", \"price_changes\":[{\"asset_id\":\"60386828328910021732068595344565885737045900010034836345809386672230885527307\", \"price\":\"0.01\", \"size\":\"7708.02\", \"side\":\"BUY\", \"hash\":\"b5d0de678c21d731272be4b696f02b58ef4a5faa\", \"best_bid\":\"0.7\", \"best_ask\":\"0.71\"}, {\"asset_id\":\"69697746896130839564035629862476347944307040470122503199396727085502753297492\", \"price\":\"0.99\", \"size\":\"7708.02\", \"side\":\"SELL\", \"hash\":\"1cd3f215ff2d9645c2f23a27ece5934020faa5fe\", \"best_bid\":\"0.29\", \"best_ask\":\"0.3\"}], \"timestamp\":\"1785126712140\", \"event_type\":\"price_change\"}","received_at":"2026-07-27T04:31:52.084770Z","schema_version":"clob-market-ws.price_change.v1","sequence":null,"server_hash":null,"server_timestamp":"1785126712140","session_id":"e9443c7415a0419799bee9cfbb1a9e4d","source":"clob_market_ws"},"received_at":"2026-07-27T04:31:52.084770Z","record_id":"33bd3302dde5200600dc2141a19a9dda48c4b3cd30da35994216c447728e7213","schema_fingerprint":"4aa3821a28b0b7c2400bc59aba4bcc0a76e971dadd19610d3ad38c768e124dc7","schema_version":"edge-lab-recorder.raw.v1","sequence":null,"source":"clob_market_ws"}
{"event_at":"2026-07-27T04:31:52.163000Z","event_fingerprint":"b141342d0ad97d1d5dd1f1bd59e6ac3732d6d7bf66d90680c5b55459ed963dd8","payload":{"connection_id":"0f4979d6978d463e9660b042fdcf555f","event_at":"2026-07-27T04:31:52.163000Z","event_type":"price_change","frame_hash":"f540521a8b5dd19cae99f6d7f6c2d6cd3271773c970b54ba3a6ae2e3dd41a1b1","frame_index":0,"kind":"data","monotonic_ns":228695376232416,"payload":{"event_type":"price_change","market":"0xeb66215f2e9faa6449e30a02bab5b8ed7b79a38bf961f6b24d0073c9c2419250","price_changes":[{"asset_id":"69697746896130839564035629862476347944307040470122503199396727085502753297492","best_ask":"0.3","best_bid":"0.29","hash":"bd2fba09f734a1f6ab27ae2feda185cf7f033995","price":"0.01","side":"BUY","size":"7919.91"},{"asset_id":"60386828328910021732068595344565885737045900010034836345809386672230885527307","best_ask":"0.71","best_bid":"0.7","hash":"67c14dea1583ade518efd6272e9f3c85969d17e8","price":"0.99","side":"SELL","size":"7919.91"}],"timestamp":"1785126712163"},"payload_hash":"c99e16f1af361438710f9afa44c2cc676fe11421d5d6fb0131aa6e873a3f8c54","raw_frame":"{\"market\":\"0xeb66215f2e9faa6449e30a02bab5b8ed7b79a38bf961f6b24d0073c9c2419250\", \"price_changes\":[{\"asset_id\":\"69697746896130839564035629862476347944307040470122503199396727085502753297492\", \"price\":\"0.01\", \"size\":\"7919.91\", \"side\":\"BUY\", \"hash\":\"bd2fba09f734a1f6ab27ae2feda185cf7f033995\", \"best_bid\":\"0.29\", \"best_ask\":\"0.3\"}, {\"asset_id\":\"60386828328910021732068595344565885737045900010034836345809386672230885527307\", \"price\":\"0.99\", \"size\":\"7919.91\", \"side\":\"SELL\", \"hash\":\"67c14dea1583ade518efd6272e9f3c85969d17e8\", \"best_bid\":\"0.7\", \"best_ask\":\"0.71\"}], \"timestamp\":\"1785126712163\", \"event_type\":\"price_change\"}","received_at":"2026-07-27T04:31:52.107364Z","schema_version":"clob-market-ws.price_change.v1","sequence":null,"server_hash":null,"server_timestamp":"1785126712163","session_id":"e9443c7415a0419799bee9cfbb1a9e4d","source":"clob_market_ws"},"received_at":"2026-07-27T04:31:52.107364Z","record_id":"53c10d1fcda32cd77c930b32f4a18fb82296da2581bbc1532777c0748f51f76e","schema_fingerprint":"4aa3821a28b0b7c2400bc59aba4bcc0a76e971dadd19610d3ad38c768e124dc7","schema_version":"edge-lab-recorder.raw.v1","sequence":null,"source":"clob_market_ws"}
{"event_at":"2026-07-27T04:31:52.202000Z","event_fingerprint":"7afc42c92e442c2b61df2c85e76b60787a021c1924b43117858de279a928d4ba","payload":{"connection_id":"0f4979d6978d463e9660b042fdcf555f","event_at":"2026-07-27T04:31:52.202000Z","event_type":"price_change","frame_hash":"326126ae517faa9451064ebdc5bef1639417c60c2b199d3d2b8afe97c88c2698","frame_index":0,"kind":"data","monotonic_ns":228695415521750,"payload":{"event_type":"price_change","market":"0xeb66215f2e9faa6449e30a02bab5b8ed7b79a38bf961f6b24d0073c9c2419250","price_changes":[{"asset_id":"60386828328910021732068595344565885737045900010034836345809386672230885527307","best_ask":"0.71","best_bid":"0.7","hash":"f2a4c9ef40d25f38fcc4c23a63c24ce87379fc3b","price":"0.01","side":"BUY","size":"7703.02"},{"asset_id":"69697746896130839564035629862476347944307040470122503199396727085502753297492","best_ask":"0.3","best_bid":"0.29","hash":"24edd8b98c83d9c512355df28138ff0c073c902e","price":"0.99","side":"SELL","size":"7703.02"}],"timestamp":"1785126712202"},"payload_hash":"6dd34429e77a9467be095b58a4d97ac694667cb0ffac30fd29b6f1013789752f","raw_frame":"{\"market\":\"0xeb66215f2e9faa6449e30a02bab5b8ed7b79a38bf961f6b24d0073c9c2419250\", \"price_changes\":[{\"asset_id\":\"60386828328910021732068595344565885737045900010034836345809386672230885527307\", \"price\":\"0.01\", \"size\":\"7703.02\", \"side\":\"BUY\", \"hash\":\"f2a4c9ef40d25f38fcc4c23a63c24ce87379fc3b\", \"best_bid\":\"0.7\", \"best_ask\":\"0.71\"}, {\"asset_id\":\"69697746896130839564035629862476347944307040470122503199396727085502753297492\", \"price\":\"0.99\", \"size\":\"7703.02\", \"side\":\"SELL\", \"hash\":\"24edd8b98c83d9c512355df28138ff0c073c902e\", \"best_bid\":\"0.29\", \"best_ask\":\"0.3\"}], \"timestamp\":\"1785126712202\", \"event_type\":\"price_change\"}","received_at":"2026-07-27T04:31:52.146656Z","schema_version":"clob-market-ws.price_change.v1","sequence":null,"server_hash":null,"server_timestamp":"1785126712202","session_id":"e9443c7415a0419799bee9cfbb1a9e4d","source":"clob_market_ws"},"received_at":"2026-07-27T04:31:52.146656Z","record_id":"d0b6b727639bdb56729728d913195ea562940477c56b9061be538accb1b6ca0d","schema_fingerprint":"4aa3821a28b0b7c2400bc59aba4bcc0a76e971dadd19610d3ad38c768e124dc7","schema_version":"edge-lab-recorder.raw.v1","sequence":null,"source":"clob_market_ws"}
{"event_at":"2026-07-27T04:31:52.209000Z","event_fingerprint":"ea5ad33b9bdd2ce25981b6a7a2c5c5ec8bb250ce0be8679745500ece7c49f1b5","payload":{"connection_id":"0f4979d6978d463e9660b042fdcf555f","event_at":"2026-07-27T04:31:52.209000Z","event_type":"price_change","frame_hash":"be6000a62350d9f0030af30cb4b5c0ee5158e8fb531e83ec77e727922707ddcf","frame_index":0,"kind":"data","monotonic_ns":228695430577458,"payload":{"event_type":"price_change","market":"0xeb66215f2e9faa6449e30a02bab5b8ed7b79a38bf961f6b24d0073c9c2419250","price_changes":[{"asset_id":"69697746896130839564035629862476347944307040470122503199396727085502753297492","best_ask":"0.3","best_bid":"0.29","hash":"7983ef92e983d35bbdb0b5a416667d5e7b47b1da","price":"0.31","side":"SELL","size":"431.6"},{"asset_id":"60386828328910021732068595344565885737045900010034836345809386672230885527307","best_ask":"0.71","best_bid":"0.7","hash":"0d8255b9a1f7267c3816b190ff6026df8011cfe6","price":"0.69","side":"BUY","size":"431.6"}],"timestamp":"1785126712209"},"payload_hash":"fc1739553663f5f85a4ff025f333a800d06baf06e6db94f572e65c8f8a758b59","raw_frame":"{\"market\":\"0xeb66215f2e9faa6449e30a02bab5b8ed7b79a38bf961f6b24d0073c9c2419250\", \"price_changes\":[{\"asset_id\":\"69697746896130839564035629862476347944307040470122503199396727085502753297492\", \"price\":\"0.31\", \"size\":\"431.6\", \"side\":\"SELL\", \"hash\":\"7983ef92e983d35bbdb0b5a416667d5e7b47b1da\", \"best_bid\":\"0.29\", \"best_ask\":\"0.3\"}, {\"asset_id\":\"60386828328910021732068595344565885737045900010034836345809386672230885527307\", \"price\":\"0.69\", \"size\":\"431.6\", \"side\":\"BUY\", \"hash\":\"0d8255b9a1f7267c3816b190ff6026df8011cfe6\", \"best_bid\":\"0.7\", \"best_ask\":\"0.71\"}], \"timestamp\":\"1785126712209\", \"event_type\":\"price_change\"}","received_at":"2026-07-27T04:31:52.161711Z","schema_version":"clob-market-ws.price_change.v1","sequence":null,"server_hash":null,"server_timestamp":"1785126712209","session_id":"e9443c7415a0419799bee9cfbb1a9e4d","source":"clob_market_ws"},"received_at":"2026-07-27T04:31:52.161711Z","record_id":"f993d8f5212733c15eb5a414a1a20aaeddee65eb77808ee916f93a0ba9613d8e","schema_fingerprint":"4aa3821a28b0b7c2400bc59aba4bcc0a76e971dadd19610d3ad38c768e124dc7","schema_version":"edge-lab-recorder.raw.v1","sequence":null,"source":"clob_market_ws"}
{"event_at":"2026-07-27T04:31:52.273000Z","event_fingerprint":"77f4a0aa03f9727b6416b5f9052221ebaa5e2d656b28a775f92c97055ad34b8b","payload":{"connection_id":"0f4979d6978d463e9660b042fdcf555f","event_at":"2026-07-27T04:31:52.273000Z","event_type":"price_change","frame_hash":"ce3a5c3ec7a984534900be4da8ef7836958cf059938586af9601096c6289c89f","frame_index":0,"kind":"data","monotonic_ns":228695485555208,"payload":{"event_type":"price_change","market":"0xeb66215f2e9faa6449e30a02bab5b8ed7b79a38bf961f6b24d0073c9c2419250","price_changes":[{"asset_id":"60386828328910021732068595344565885737045900010034836345809386672230885527307","best_ask":"0.71","best_bid":"0.7","hash":"e85a4cfa64170b6b5fc1e72f91f2ed818e43e3e6","price":"0.01","side":"BUY","size":"7708.02"},{"asset_id":"69697746896130839564035629862476347944307040470122503199396727085502753297492","best_ask":"0.3","best_bid":"0.29","hash":"29e470a95049e554c742c089950f06aa83a70dd9","price":"0.99","side":"SELL","size":"7708.02"}],"timestamp":"1785126712273"},"payload_hash":"f2dd94092d2c7ef1afcfc21732ef1e2635475dff0f544ed8a83378cc28b5e9cb","raw_frame":"{\"market\":\"0xeb66215f2e9faa6449e30a02bab5b8ed7b79a38bf961f6b24d0073c9c2419250\", \"price_changes\":[{\"asset_id\":\"60386828328910021732068595344565885737045900010034836345809386672230885527307\", \"price\":\"0.01\", \"size\":\"7708.02\", \"side\":\"BUY\", \"hash\":\"e85a4cfa64170b6b5fc1e72f91f2ed818e43e3e6\", \"best_bid\":\"0.7\", \"best_ask\":\"0.71\"}, {\"asset_id\":\"69697746896130839564035629862476347944307040470122503199396727085502753297492\", \"price\":\"0.99\", \"size\":\"7708.02\", \"side\":\"SELL\", \"hash\":\"29e470a95049e554c742c089950f06aa83a70dd9\", \"best_bid\":\"0.29\", \"best_ask\":\"0.3\"}], \"timestamp\":\"1785126712273\", \"event_type\":\"price_change\"}","received_at":"2026-07-27T04:31:52.216691Z","schema_version":"clob-market-ws.price_change.v1","sequence":null,"server_hash":null,"server_timestamp":"1785126712273","session_id":"e9443c7415a0419799bee9cfbb1a9e4d","source":"clob_market_ws"},"received_at":"2026-07-27T04:31:52.216691Z","record_id":"20b7fe1fabedbdf8811f75d3897a303f97c57624cbace70fc549496c927b67ca","schema_fingerprint":"4aa3821a28b0b7c2400bc59aba4bcc0a76e971dadd19610d3ad38c768e124dc7","schema_version":"edge-lab-recorder.raw.v1","sequence":null,"source":"clob_market_ws"}
{"event_at":"2026-07-27T04:31:52.296000Z","event_fingerprint":"5c223d50b28cbce7507ce613ac0f2dc93252f3d68a7a83cacf6a07f3d71ccaaf","payload":{"connection_id":"0f4979d6978d463e9660b042fdcf555f","event_at":"2026-07-27T04:31:52.296000Z","event_type":"price_change","frame_hash":"4744938c50d9dbede924601a8dd392f328eb7574b82509076f40c26cfd51b0b3","frame_index":0,"kind":"data","monotonic_ns":228695509048583,"payload":{"event_type":"price_change","market":"0xeb66215f2e9faa6449e30a02bab5b8ed7b79a38bf961f6b24d0073c9c2419250","price_changes":[{"asset_id":"60386828328910021732068595344565885737045900010034836345809386672230885527307","best_ask":"0.71","best_bid":"0.7","hash":"3e1fa41a2f3db44141df816626fe6470e3ce3589","price":"0.01","side":"BUY","size":"7713.02"},{"asset_id":"69697746896130839564035629862476347944307040470122503199396727085502753297492","best_ask":"0.3","best_bid":"0.29","hash":"d7637376fd45901962d76a8142ea442ffe8ce3e8","price":"0.99","side":"SELL","size":"7713.02"}],"timestamp":"1785126712296"},"payload_hash":"bd6993f4f7c193fded9b5a06aa26d2e28dc289d63be6467b9fb489c998d63817","raw_frame":"{\"market\":\"0xeb66215f2e9faa6449e30a02bab5b8ed7b79a38bf961f6b24d0073c9c2419250\", \"price_changes\":[{\"asset_id\":\"60386828328910021732068595344565885737045900010034836345809386672230885527307\", \"price\":\"0.01\", \"size\":\"7713.02\", \"side\":\"BUY\", \"hash\":\"3e1fa41a2f3db44141df816626fe6470e3ce3589\", \"best_bid\":\"0.7\", \"best_ask\":\"0.71\"}, {\"asset_id\":\"69697746896130839564035629862476347944307040470122503199396727085502753297492\", \"price\":\"0.99\", \"size\":\"7713.02\", \"side\":\"SELL\", \"hash\":\"d7637376fd45901962d76a8142ea442ffe8ce3e8\", \"best_bid\":\"0.29\", \"best_ask\":\"0.3\"}], \"timestamp\":\"1785126712296\", \"event_type\":\"price_change\"}","received_at":"2026-07-27T04:31:52.240182Z","schema_version":"clob-market-ws.price_change.v1","sequence":null,"server_hash":null,"server_timestamp":"1785126712296","session_id":"e9443c7415a0419799bee9cfbb1a9e4d","source":"clob_market_ws"},"received_at":"2026-07-27T04:31:52.240182Z","record_id":"ed6ec39b963548a16a7013a1c2f2640f425f5c06267fd59dcd67108c4af08498","schema_fingerprint":"4aa3821a28b0b7c2400bc59aba4bcc0a76e971dadd19610d3ad38c768e124dc7","schema_version":"edge-lab-recorder.raw.v1","sequence":null,"source":"clob_market_ws"}
{"event_at":"2026-07-27T04:31:52.298000Z","event_fingerprint":"50ba0ea6d7c0f744f62475b8bb17e2a18807b2a07a71cf18d2acf1a866568845","payload":{"connection_id":"0f4979d6978d463e9660b042fdcf555f","event_at":"2026-07-27T04:31:52.298000Z","event_type":"price_change","frame_hash":"24b70f8a8cca2e35c3008751b34284b05943c6b065e8bb8f61b1e52363872e20","frame_index":0,"kind":"data","monotonic_ns":228695511854916,"payload":{"event_type":"price_change","market":"0xeb66215f2e9faa6449e30a02bab5b8ed7b79a38bf961f6b24d0073c9c2419250","price_changes":[{"asset_id":"60386828328910021732068595344565885737045900010034836345809386672230885527307","best_ask":"0.71","best_bid":"0.7","hash":"49b0617318b368b109c868c618dcf84917cc3c0f","price":"0.01","side":"BUY","size":"7708.02"},{"asset_id":"69697746896130839564035629862476347944307040470122503199396727085502753297492","best_ask":"0.3","best_bid":"0.29","hash":"ce38481b78f322c83fb7048ed2f0af3ee5b5334c","price":"0.99","side":"SELL","size":"7708.02"}],"timestamp":"1785126712298"},"payload_hash":"4d9eff3be6033940a853ee143b36d09afdf5774a00e2b27dc99e041bdc82a4a9","raw_frame":"{\"market\":\"0xeb66215f2e9faa6449e30a02bab5b8ed7b79a38bf961f6b24d0073c9c2419250\", \"price_changes\":[{\"asset_id\":\"60386828328910021732068595344565885737045900010034836345809386672230885527307\", \"price\":\"0.01\", \"size\":\"7708.02\", \"side\":\"BUY\", \"hash\":\"49b0617318b368b109c868c618dcf84917cc3c0f\", \"best_bid\":\"0.7\", \"best_ask\":\"0.71\"}, {\"asset_id\":\"69697746896130839564035629862476347944307040470122503199396727085502753297492\", \"price\":\"0.99\", \"size\":\"7708.02\", \"side\":\"SELL\", \"hash\":\"ce38481b78f322c83fb7048ed2f0af3ee5b5334c\", \"best_bid\":\"0.29\", \"best_ask\":\"0.3\"}], \"timestamp\":\"1785126712298\", \"event_type\":\"price_change\"}","received_at":"2026-07-27T04:31:52.242989Z","schema_version":"clob-market-ws.price_change.v1","sequence":null,"server_hash":null,"server_timestamp":"1785126712298","session_id":"e9443c7415a0419799bee9cfbb1a9e4d","source":"clob_market_ws"},"received_at":"2026-07-27T04:31:52.242989Z","record_id":"869431b6115268165e5f3bcb47a249dd762cdd37c278af083e961492f2023735","schema_fingerprint":"4aa3821a28b0b7c2400bc59aba4bcc0a76e971dadd19610d3ad38c768e124dc7","schema_version":"edge-lab-recorder.raw.v1","sequence":null,"source":"clob_market_ws"}
{"event_at":"2026-07-27T04:31:52.310000Z","event_fingerprint":"e0002d94c73bcbbf0026996624e9be2c0d848c8cd256e303556c518a120d4f14","payload":{"connection_id":"0f4979d6978d463e9660b042fdcf555f","event_at":"2026-07-27T04:31:52.310000Z","event_type":"price_change","frame_hash":"78c33f4550d3a3968fbb396f156b737fe6d8a2a4c85922d79e7ab12edf59a8d7","frame_index":0,"kind":"data","monotonic_ns":228695524272083,"payload":{"event_type":"price_change","market":"0xeb66215f2e9faa6449e30a02bab5b8ed7b79a38bf961f6b24d0073c9c2419250","price_changes":[{"asset_id":"69697746896130839564035629862476347944307040470122503199396727085502753297492","best_ask":"0.3","best_bid":"0.29","hash":"049c2546d41137d5d904a038c6f2b230f918e0da","price":"0.31","side":"SELL","size":"426.56"},{"asset_id":"60386828328910021732068595344565885737045900010034836345809386672230885527307","best_ask":"0.71","best_bid":"0.7","hash":"04bd01bb0b28d5fdb47ce96485023f3be151e8af","price":"0.69","side":"BUY","size":"426.56"}],"timestamp":"1785126712310"},"payload_hash":"e87d6618a29656f4f35f305ab718bc3859cf62ef46626778ea1a9f5914b91d06","raw_frame":"{\"market\":\"0xeb66215f2e9faa6449e30a02bab5b8ed7b79a38bf961f6b24d0073c9c2419250\", \"price_changes\":[{\"asset_id\":\"69697746896130839564035629862476347944307040470122503199396727085502753297492\", \"price\":\"0.31\", \"size\":\"426.56\", \"side\":\"SELL\", \"hash\":\"049c2546d41137d5d904a038c6f2b230f918e0da\", \"best_bid\":\"0.29\", \"best_ask\":\"0.3\"}, {\"asset_id\":\"60386828328910021732068595344565885737045900010034836345809386672230885527307\", \"price\":\"0.69\", \"size\":\"426.56\", \"side\":\"BUY\", \"hash\":\"04bd01bb0b28d5fdb47ce96485023f3be151e8af\", \"best_bid\":\"0.7\", \"best_ask\":\"0.71\"}], \"timestamp\":\"1785126712310\", \"event_type\":\"price_change\"}","received_at":"2026-07-27T04:31:52.255407Z","schema_version":"clob-market-ws.price_change.v1","sequence":null,"server_hash":null,"server_timestamp":"1785126712310","session_id":"e9443c7415a0419799bee9cfbb1a9e4d","source":"clob_market_ws"},"received_at":"2026-07-27T04:31:52.255407Z","record_id":"0f61a4e89b08aa1504b48559be493679e5726b3e3ec7431c4ce767c77a972ea0","schema_fingerprint":"4aa3821a28b0b7c2400bc59aba4bcc0a76e971dadd19610d3ad38c768e124dc7","schema_version":"edge-lab-recorder.raw.v1","sequence":null,"source":"clob_market_ws"}
{"event_at":"2026-07-27T04:31:52.343000Z","event_fingerprint":"88e143462b6537ab87dcce8bc1c434ced322026657795dac8a57142afc647078","payload":{"connection_id":"0f4979d6978d463e9660b042fdcf555f","event_at":"2026-07-27T04:31:52.343000Z","event_type":"price_change","frame_hash":"5158d8f11198ac88751a91be8c3867c6a8457e44460de553fb460a2d5b7b4880","frame_index":0,"kind":"data","monotonic_ns":228695556522250,"payload":{"event_type":"price_change","market":"0xeb66215f2e9faa6449e30a02bab5b8ed7b79a38bf961f6b24d0073c9c2419250","price_changes":[{"asset_id":"60386828328910021732068595344565885737045900010034836345809386672230885527307","best_ask":"0.71","best_bid":"0.7","hash":"c20899bfaf79234b3398df1266468187042ab563","price":"0.67","side":"BUY","size":"72.65"},{"asset_id":"69697746896130839564035629862476347944307040470122503199396727085502753297492","best_ask":"0.3","best_bid":"0.29","hash":"80a689515d745aadf04570cab9d32b758b56c129","price":"0.33","side":"SELL","size":"72.65"}],"timestamp":"1785126712343"},"payload_hash":"1ae9cda6e9797d083ed54ee32de4064e4cb5fa7d36307f02c6593cc17e8a543e","raw_frame":"{\"market\":\"0xeb66215f2e9faa6449e30a02bab5b8ed7b79a38bf961f6b24d0073c9c2419250\", \"price_changes\":[{\"asset_id\":\"60386828328910021732068595344565885737045900010034836345809386672230885527307\", \"price\":\"0.67\", \"size\":\"72.65\", \"side\":\"BUY\", \"hash\":\"c20899bfaf79234b3398df1266468187042ab563\", \"best_bid\":\"0.7\", \"best_ask\":\"0.71\"}, {\"asset_id\":\"69697746896130839564035629862476347944307040470122503199396727085502753297492\", \"price\":\"0.33\", \"size\":\"72.65\", \"side\":\"SELL\", \"hash\":\"80a689515d745aadf04570cab9d32b758b56c129\", \"best_bid\":\"0.29\", \"best_ask\":\"0.3\"}], \"timestamp\":\"1785126712343\", \"event_type\":\"price_change\"}","received_at":"2026-07-27T04:31:52.287655Z","schema_version":"clob-market-ws.price_change.v1","sequence":null,"server_hash":null,"server_timestamp":"1785126712343","session_id":"e9443c7415a0419799bee9cfbb1a9e4d","source":"clob_market_ws"},"received_at":"2026-07-27T04:31:52.287655Z","record_id":"63b719da59b2a58260c1cc24967ace0a05d40185357949fec525cbf654bc6478","schema_fingerprint":"4aa3821a28b0b7c2400bc59aba4bcc0a76e971dadd19610d3ad38c768e124dc7","schema_version":"edge-lab-recorder.raw.v1","sequence":null,"source":"clob_market_ws"}
{"event_at":"2026-07-27T04:31:52.369000Z","event_fingerprint":"a318ffe29f850aac65a5fcdc4d0a7ecfb616821ee2ceb1f377c50c133a26904e","payload":{"connection_id":"0f4979d6978d463e9660b042fdcf555f","event_at":"2026-07-27T04:31:52.369000Z","event_type":"price_change","frame_hash":"7914398210708727d47f57f6a1115ce229266d80e3748683afc5448bacdbbad2","frame_index":0,"kind":"data","monotonic_ns":228695585777250,"payload":{"event_type":"price_change","market":"0xeb66215f2e9faa6449e30a02bab5b8ed7b79a38bf961f6b24d0073c9c2419250","price_changes":[{"asset_id":"60386828328910021732068595344565885737045900010034836345809386672230885527307","best_ask":"0.71","best_bid":"0.7","hash":"2e221c25f6aef322e604f5db4b7215a2f2011996","price":"0.01","side":"BUY","size":"7703.02"},{"asset_id":"69697746896130839564035629862476347944307040470122503199396727085502753297492","best_ask":"0.3","best_bid":"0.29","hash":"58d7c37ddf651ed7aa7afb22bad02ecc8dcf4597","price":"0.99","side":"SELL","size":"7703.02"}],"timestamp":"1785126712369"},"payload_hash":"84c6eaee926ac96f5403d6f8c62cbb77d4c7cd003fc53dcbfffdb29487ef1f9f","raw_frame":"{\"market\":\"0xeb66215f2e9faa6449e30a02bab5b8ed7b79a38bf961f6b24d0073c9c2419250\", \"price_changes\":[{\"asset_id\":\"60386828328910021732068595344565885737045900010034836345809386672230885527307\", \"price\":\"0.01\", \"size\":\"7703.02\", \"side\":\"BUY\", \"hash\":\"2e221c25f6aef322e604f5db4b7215a2f2011996\", \"best_bid\":\"0.7\", \"best_ask\":\"0.71\"}, {\"asset_id\":\"69697746896130839564035629862476347944307040470122503199396727085502753297492\", \"price\":\"0.99\", \"size\":\"7703.02\", \"side\":\"SELL\", \"hash\":\"58d7c37ddf651ed7aa7afb22bad02ecc8dcf4597\", \"best_bid\":\"0.29\", \"best_ask\":\"0.3\"}], \"timestamp\":\"1785126712369\", \"event_type\":\"price_change\"}","received_at":"2026-07-27T04:31:52.316911Z","schema_version":"clob-market-ws.price_change.v1","sequence":null,"server_hash":null,"server_timestamp":"1785126712369","session_id":"e9443c7415a0419799bee9cfbb1a9e4d","source":"clob_market_ws"},"received_at":"2026-07-27T04:31:52.316911Z","record_id":"6c8da7589c2fc711024dcae8baa0d9d45b51db5b63b1a12a5794548f6b43fc41","schema_fingerprint":"4aa3821a28b0b7c2400bc59aba4bcc0a76e971dadd19610d3ad38c768e124dc7","schema_version":"edge-lab-recorder.raw.v1","sequence":null,"source":"clob_market_ws"}
{"event_at":"2026-07-27T04:31:52.417000Z","event_fingerprint":"f01555b410e6233f7c742113984b2a5c98c5ed9420366f73d428b3ee2eea9b54","payload":{"connection_id":"0f4979d6978d463e9660b042fdcf555f","event_at":"2026-07-27T04:31:52.417000Z","event_type":"price_change","frame_hash":"155a513a4c539d922b04d7893c0affcb7db9cd946820736af6eab260c2e3e234","frame_index":0,"kind":"data","monotonic_ns":228695631016333,"payload":{"event_type":"price_change","market":"0xeb66215f2e9faa6449e30a02bab5b8ed7b79a38bf961f6b24d0073c9c2419250","price_changes":[{"asset_id":"60386828328910021732068595344565885737045900010034836345809386672230885527307","best_ask":"0.71","best_bid":"0.7","hash":"0e00e62e89042ae041dff6a80cfc27a8f4137780","price":"0.67","side":"BUY","size":"92.65"},{"asset_id":"69697746896130839564035629862476347944307040470122503199396727085502753297492","best_ask":"0.3","best_bid":"0.29","hash":"009b3835942c853c22bdc3ca5d6d7f80742f801b","price":"0.33","side":"SELL","size":"92.65"}],"timestamp":"1785126712417"},"payload_hash":"6bdcb925dfee7fa7de8dac5d069bab1a7d02f89f56914b1a9262566552c8060f","raw_frame":"{\"market\":\"0xeb66215f2e9faa6449e30a02bab5b8ed7b79a38bf961f6b24d0073c9c2419250\", \"price_changes\":[{\"asset_id\":\"60386828328910021732068595344565885737045900010034836345809386672230885527307\", \"price\":\"0.67\", \"size\":\"92.65\", \"side\":\"BUY\", \"hash\":\"0e00e62e89042ae041dff6a80cfc27a8f4137780\", \"best_bid\":\"0.7\", \"best_ask\":\"0.71\"}, {\"asset_id\":\"69697746896130839564035629862476347944307040470122503199396727085502753297492\", \"price\":\"0.33\", \"size\":\"92.65\", \"side\":\"SELL\", \"hash\":\"009b3835942c853c22bdc3ca5d6d7f80742f801b\", \"best_bid\":\"0.29\", \"best_ask\":\"0.3\"}], \"timestamp\":\"1785126712417\", \"event_type\":\"price_change\"}","received_at":"2026-07-27T04:31:52.362148Z","schema_version":"clob-market-ws.price_change.v1","sequence":null,"server_hash":null,"server_timestamp":"1785126712417","session_id":"e9443c7415a0419799bee9cfbb1a9e4d","source":"clob_market_ws"},"received_at":"2026-07-27T04:31:52.362148Z","record_id":"833bca7925844102594aed5ff1d494d5f6e4249eb490ffa2edf35ed84d1f0549","schema_fingerprint":"4aa3821a28b0b7c2400bc59aba4bcc0a76e971dadd19610d3ad38c768e124dc7","schema_version":"edge-lab-recorder.raw.v1","sequence":null,"source":"clob_market_ws"}
{"event_at":"2026-07-27T04:31:52.425000Z","event_fingerprint":"a3b891c4ff73b899c1b77fbfccc1908426f451b14bc3f2163690587145764863","payload":{"connection_id":"0f4979d6978d463e9660b042fdcf555f","event_at":"2026-07-27T04:31:52.425000Z","event_type":"price_change","frame_hash":"68dbb5f4eb4b4aa4d3138715f70b93f546608c135c87accf5d068786b3958f2c","frame_index":0,"kind":"data","monotonic_ns":228695637459125,"payload":{"event_type":"price_change","market":"0xeb66215f2e9faa6449e30a02bab5b8ed7b79a38bf961f6b24d0073c9c2419250","price_changes":[{"asset_id":"69697746896130839564035629862476347944307040470122503199396727085502753297492","best_ask":"0.3","best_bid":"0.29","hash":"7642d296722fe0e93ae1543228b21b2f0ac8f835","price":"0.31","side":"SELL","size":"431.6"},{"asset_id":"60386828328910021732068595344565885737045900010034836345809386672230885527307","best_ask":"0.71","best_bid":"0.7","hash":"7cf3cccab96fa5c2c1b4f7eb4ce97bd30d274532","price":"0.69","side":"BUY","size":"431.6"}],"timestamp":"1785126712425"},"payload_hash":"9d91db0593f23e3c1cbc0379fa798c6d90a09978da74c848dfb1dca7bc3dc9cc","raw_frame":"{\"market\":\"0xeb66215f2e9faa6449e30a02bab5b8ed7b79a38bf961f6b24d0073c9c2419250\", \"price_changes\":[{\"asset_id\":\"69697746896130839564035629862476347944307040470122503199396727085502753297492\", \"price\":\"0.31\", \"size\":\"431.6\", \"side\":\"SELL\", \"hash\":\"7642d296722fe0e93ae1543228b21b2f0ac8f835\", \"best_bid\":\"0.29\", \"best_ask\":\"0.3\"}, {\"asset_id\":\"60386828328910021732068595344565885737045900010034836345809386672230885527307\", \"price\":\"0.69\", \"size\":\"431.6\", \"side\":\"BUY\", \"hash\":\"7cf3cccab96fa5c2c1b4f7eb4ce97bd30d274532\", \"best_bid\":\"0.7\", \"best_ask\":\"0.71\"}], \"timestamp\":\"1785126712425\", \"event_type\":\"price_change\"}","received_at":"2026-07-27T04:31:52.368592Z","schema_version":"clob-market-ws.price_change.v1","sequence":null,"server_hash":null,"server_timestamp":"1785126712425","session_id":"e9443c7415a0419799bee9cfbb1a9e4d","source":"clob_market_ws"},"received_at":"2026-07-27T04:31:52.368592Z","record_id":"bd09ca712cda8122484e643169c26695be00169d91d004ce3703ad944b9d223d","schema_fingerprint":"4aa3821a28b0b7c2400bc59aba4bcc0a76e971dadd19610d3ad38c768e124dc7","schema_version":"edge-lab-recorder.raw.v1","sequence":null,"source":"clob_market_ws"}
{"event_at":"2026-07-27T04:31:52.449000Z","event_fingerprint":"201f5f68a65227890bae8c771454db69eb6b738897885245d4e9883e2248d6e8","payload":{"connection_id":"0f4979d6978d463e9660b042fdcf555f","event_at":"2026-07-27T04:31:52.449000Z","event_type":"price_change","frame_hash":"5c5ce262be401da06d4171bab0106da48bef59870b7c1efee50e57cf6d3a5a9f","frame_index":0,"kind":"data","monotonic_ns":228695664889208,"payload":{"event_type":"price_change","market":"0xeb66215f2e9faa6449e30a02bab5b8ed7b79a38bf961f6b24d0073c9c2419250","price_changes":[{"asset_id":"60386828328910021732068595344565885737045900010034836345809386672230885527307","best_ask":"0.71","best_bid":"0.7","hash":"c50ead716d6047fceb421e692d394c3d4b882ef7","price":"0.67","side":"BUY","size":"72.65"},{"asset_id":"69697746896130839564035629862476347944307040470122503199396727085502753297492","best_ask":"0.3","best_bid":"0.29","hash":"94802768ae0379df1be17ddd701e37232c679582","price":"0.33","side":"SELL","size":"72.65"}],"timestamp":"1785126712449"},"payload_hash":"cb44f1677ad4f60400905b29c260d735ede7665fa8304b571b8de26ec456357f","raw_frame":"{\"market\":\"0xeb66215f2e9faa6449e30a02bab5b8ed7b79a38bf961f6b24d0073c9c2419250\", \"price_changes\":[{\"asset_id\":\"60386828328910021732068595344565885737045900010034836345809386672230885527307\", \"price\":\"0.67\", \"size\":\"72.65\", \"side\":\"BUY\", \"hash\":\"c50ead716d6047fceb421e692d394c3d4b882ef7\", \"best_bid\":\"0.7\", \"best_ask\":\"0.71\"}, {\"asset_id\":\"69697746896130839564035629862476347944307040470122503199396727085502753297492\", \"price\":\"0.33\", \"size\":\"72.65\", \"side\":\"SELL\", \"hash\":\"94802768ae0379df1be17ddd701e37232c679582\", \"best_bid\":\"0.29\", \"best_ask\":\"0.3\"}], \"timestamp\":\"1785126712449\", \"event_type\":\"price_change\"}","received_at":"2026-07-27T04:31:52.396027Z","schema_version":"clob-market-ws.price_change.v1","sequence":null,"server_hash":null,"server_timestamp":"1785126712449","session_id":"e9443c7415a0419799bee9cfbb1a9e4d","source":"clob_market_ws"},"received_at":"2026-07-27T04:31:52.396027Z","record_id":"aab3ed1b3ecd01580b99d390878a5bc20810d727a48c32f13d8c2f9bfca9d864","schema_fingerprint":"4aa3821a28b0b7c2400bc59aba4bcc0a76e971dadd19610d3ad38c768e124dc7","schema_version":"edge-lab-recorder.raw.v1","sequence":null,"source":"clob_market_ws"}
{"event_at":"2026-07-27T04:31:52.449000Z","event_fingerprint":"f3a19a52bbeb24a600aab34b194c4ded1227d5fd536b57ded4f3ed6c33c37194","payload":{"connection_id":"0f4979d6978d463e9660b042fdcf555f","event_at":"2026-07-27T04:31:52.449000Z","event_type":"price_change","frame_hash":"bfd03510c782e34b388fd61c8a1fd41cb967595025b7a17a107d5ddf0f5b1846","frame_index":0,"kind":"data","monotonic_ns":228695669060000,"payload":{"event_type":"price_change","market":"0xeb66215f2e9faa6449e30a02bab5b8ed7b79a38bf961f6b24d0073c9c2419250","price_changes":[{"asset_id":"60386828328910021732068595344565885737045900010034836345809386672230885527307","best_ask":"0.71","best_bid":"0.7","hash":"c93c48ae9d49e81c9dd30cdf2f5c618a878d7805","price":"0.04","side":"BUY","size":"633.09"},{"asset_id":"69697746896130839564035629862476347944307040470122503199396727085502753297492","best_ask":"0.3","best_bid":"0.29","hash":"28bf4352fc1522c7fc89eb777f126984bff4f14f","price":"0.96","side":"SELL","size":"633.09"}],"timestamp":"1785126712449"},"payload_hash":"14a389f8a66a15839da79c97e4ff06a878068c1f14693aafc341095e061b7270","raw_frame":"{\"market\":\"0xeb66215f2e9faa6449e30a02bab5b8ed7b79a38bf961f6b24d0073c9c2419250\", \"price_changes\":[{\"asset_id\":\"60386828328910021732068595344565885737045900010034836345809386672230885527307\", \"price\":\"0.04\", \"size\":\"633.09\", \"side\":\"BUY\", \"hash\":\"c93c48ae9d49e81c9dd30cdf2f5c618a878d7805\", \"best_bid\":\"0.7\", \"best_ask\":\"0.71\"}, {\"asset_id\":\"69697746896130839564035629862476347944307040470122503199396727085502753297492\", \"price\":\"0.96\", \"size\":\"633.09\", \"side\":\"SELL\", \"hash\":\"28bf4352fc1522c7fc89eb777f126984bff4f14f\", \"best_bid\":\"0.29\", \"best_ask\":\"0.3\"}], \"timestamp\":\"1785126712449\", \"event_type\":\"price_change\"}","received_at":"2026-07-27T04:31:52.400196Z","schema_version":"clob-market-ws.price_change.v1","sequence":null,"server_hash":null,"server_timestamp":"1785126712449","session_id":"e9443c7415a0419799bee9cfbb1a9e4d","source":"clob_market_ws"},"received_at":"2026-07-27T04:31:52.400196Z","record_id":"166df46b05f32f24eba348fc8f131b35d216eac96bcf2756d5615789d8304bee","schema_fingerprint":"4aa3821a28b0b7c2400bc59aba4bcc0a76e971dadd19610d3ad38c768e124dc7","schema_version":"edge-lab-recorder.raw.v1","sequence":null,"source":"clob_market_ws"}
{"event_at":"2026-07-27T04:31:52.453000Z","event_fingerprint":"93cf36643994507b0b4ee4d0f0021bf32591decf675202a22a9b13f12e7e9c3c","payload":{"connection_id":"0f4979d6978d463e9660b042fdcf555f","event_at":"2026-07-27T04:31:52.453000Z","event_type":"price_change","frame_hash":"036b8e6fb9cb498834d611756cec32672c6457c77557da4452a74b219a699860","frame_index":0,"kind":"data","monotonic_ns":228695672419708,"payload":{"event_type":"price_change","market":"0xeb66215f2e9faa6449e30a02bab5b8ed7b79a38bf961f6b24d0073c9c2419250","price_changes":[{"asset_id":"60386828328910021732068595344565885737045900010034836345809386672230885527307","best_ask":"0.71","best_bid":"0.7","hash":"e40315f0386e76b955ebf8d1e4a4fe2fc6d9efc6","price":"0.01","side":"BUY","size":"7708.02"},{"asset_id":"69697746896130839564035629862476347944307040470122503199396727085502753297492","best_ask":"0.3","best_bid":"0.29","hash":"af43dedb2d0c2fe12208324c108d5efb555f6217","price":"0.99","side":"SELL","size":"7708.02"}],"timestamp":"1785126712453"},"payload_hash":"44e0ed41de715939b87292fed73ce948c7d1d6810f46276f33eeb61b8d0d3b5c","raw_frame":"{\"market\":\"0xeb66215f2e9faa6449e30a02bab5b8ed7b79a38bf961f6b24d0073c9c2419250\", \"price_changes\":[{\"asset_id\":\"60386828328910021732068595344565885737045900010034836345809386672230885527307\", \"price\":\"0.01\", \"size\":\"7708.02\", \"side\":\"BUY\", \"hash\":\"e40315f0386e76b955ebf8d1e4a4fe2fc6d9efc6\", \"best_bid\":\"0.7\", \"best_ask\":\"0.71\"}, {\"asset_id\":\"69697746896130839564035629862476347944307040470122503199396727085502753297492\", \"price\":\"0.99\", \"size\":\"7708.02\", \"side\":\"SELL\", \"hash\":\"af43dedb2d0c2fe12208324c108d5efb555f6217\", \"best_bid\":\"0.29\", \"best_ask\":\"0.3\"}], \"timestamp\":\"1785126712453\", \"event_type\":\"price_change\"}","received_at":"2026-07-27T04:31:52.403556Z","schema_version":"clob-market-ws.price_change.v1","sequence":null,"server_hash":null,"server_timestamp":"1785126712453","session_id":"e9443c7415a0419799bee9cfbb1a9e4d","source":"clob_market_ws"},"received_at":"2026-07-27T04:31:52.403556Z","record_id":"70685834e2a7adcd93bae424cae02d4fa7db32def5e97a825c0f7cca27503dcd","schema_fingerprint":"4aa3821a28b0b7c2400bc59aba4bcc0a76e971dadd19610d3ad38c768e124dc7","schema_version":"edge-lab-recorder.raw.v1","sequence":null,"source":"clob_market_ws"}
{"event_at":"2026-07-27T04:31:52.474000Z","event_fingerprint":"bbb6fa76f3d7dc84fab97c53fccb15e6b85c9c2587d483b641a9db4ed4121685","payload":{"connection_id":"0f4979d6978d463e9660b042fdcf555f","event_at":"2026-07-27T04:31:52.474000Z","event_type":"price_change","frame_hash":"194beb8ed18646ea9c8eb58a009f2ac1a0d02482f1b2de79a1d7cf70a8282514","frame_index":0,"kind":"data","monotonic_ns":228695689270375,"payload":{"event_type":"price_change","market":"0xeb66215f2e9faa6449e30a02bab5b8ed7b79a38bf961f6b24d0073c9c2419250","price_changes":[{"asset_id":"60386828328910021732068595344565885737045900010034836345809386672230885527307","best_ask":"0.71","best_bid":"0.7","hash":"97a1c572bcb8ebf020f096e87cb2b654305f4360","price":"0.01","side":"BUY","size":"7703.02"},{"asset_id":"69697746896130839564035629862476347944307040470122503199396727085502753297492","best_ask":"0.3","best_bid":"0.29","hash":"ba70df67326196b96bad66e1f67c3e0842802e51","price":"0.99","side":"SELL","size":"7703.02"}],"timestamp":"1785126712474"},"payload_hash":"45bddb536c5e9e23be7261b1c1032a07b82267156945e324bfb6a9bad348aeea","raw_frame":"{\"market\":\"0xeb66215f2e9faa6449e30a02bab5b8ed7b79a38bf961f6b24d0073c9c2419250\", \"price_changes\":[{\"asset_id\":\"60386828328910021732068595344565885737045900010034836345809386672230885527307\", \"price\":\"0.01\", \"size\":\"7703.02\", \"side\":\"BUY\", \"hash\":\"97a1c572bcb8ebf020f096e87cb2b654305f4360\", \"best_bid\":\"0.7\", \"best_ask\":\"0.71\"}, {\"asset_id\":\"69697746896130839564035629862476347944307040470122503199396727085502753297492\", \"price\":\"0.99\", \"size\":\"7703.02\", \"side\":\"SELL\", \"hash\":\"ba70df67326196b96bad66e1f67c3e0842802e51\", \"best_bid\":\"0.29\", \"best_ask\":\"0.3\"}], \"timestamp\":\"1785126712474\", \"event_type\":\"price_change\"}","received_at":"2026-07-27T04:31:52.420408Z","schema_version":"clob-market-ws.price_change.v1","sequence":null,"server_hash":null,"server_timestamp":"1785126712474","session_id":"e9443c7415a0419799bee9cfbb1a9e4d","source":"clob_market_ws"},"received_at":"2026-07-27T04:31:52.420408Z","record_id":"af0a4f7d6d2cf051b9038cc0dfcd4e85d17a16f9c38c6e9ba679a65473dd7d28","schema_fingerprint":"4aa3821a28b0b7c2400bc59aba4bcc0a76e971dadd19610d3ad38c768e124dc7","schema_version":"edge-lab-recorder.raw.v1","sequence":null,"source":"clob_market_ws"}
{"event_at":"2026-07-27T04:31:52.488000Z","event_fingerprint":"93274f255a460981252bedc5cc7713cd231173bfc63f9a6848e09ea4a1674121","payload":{"connection_id":"0f4979d6978d463e9660b042fdcf555f","event_at":"2026-07-27T04:31:52.488000Z","event_type":"price_change","frame_hash":"2e6955eeb36004d4e31ea4ac4352427ce692c60607b623f4580bee35190b2903","frame_index":0,"kind":"data","monotonic_ns":228695704586291,"payload":{"event_type":"price_change","market":"0xeb66215f2e9faa6449e30a02bab5b8ed7b79a38bf961f6b24d0073c9c2419250","price_changes":[{"asset_id":"69697746896130839564035629862476347944307040470122503199396727085502753297492","best_ask":"0.3","best_bid":"0.29","hash":"13d8e09bbf1aec2317b73bf47c8ef8298ace29db","price":"0.27","side":"BUY","size":"406.95"},{"asset_id":"60386828328910021732068595344565885737045900010034836345809386672230885527307","best_ask":"0.71","best_bid":"0.7","hash":"84ae646c0ab4ed1beb32508592b7986aaea85e29","price":"0.73","side":"SELL","size":"406.95"}],"timestamp":"1785126712488"},"payload_hash":"c84a0f6d7961cbcf2024855a5716078e2ba60b03f109974aab441abf26b2050d","raw_frame":"{\"market\":\"0xeb66215f2e9faa6449e30a02bab5b8ed7b79a38bf961f6b24d0073c9c2419250\", \"price_changes\":[{\"asset_id\":\"69697746896130839564035629862476347944307040470122503199396727085502753297492\", \"price\":\"0.27\", \"size\":\"406.95\", \"side\":\"BUY\", \"hash\":\"13d8e09bbf1aec2317b73bf47c8ef8298ace29db\", \"best_bid\":\"0.29\", \"best_ask\":\"0.3\"}, {\"asset_id\":\"60386828328910021732068595344565885737045900010034836345809386672230885527307\", \"price\":\"0.73\", \"size\":\"406.95\", \"side\":\"SELL\", \"hash\":\"84ae646c0ab4ed1beb32508592b7986aaea85e29\", \"best_bid\":\"0.7\", \"best_ask\":\"0.71\"}], \"timestamp\":\"1785126712488\", \"event_type\":\"price_change\"}","received_at":"2026-07-27T04:31:52.435722Z","schema_version":"clob-market-ws.price_change.v1","sequence":null,"server_hash":null,"server_timestamp":"1785126712488","session_id":"e9443c7415a0419799bee9cfbb1a9e4d","source":"clob_market_ws"},"received_at":"2026-07-27T04:31:52.435722Z","record_id":"a648f4f54020ae75c05ba4cb71e0ddbb5dd96b480ad01665973621b10d6b6d8a","schema_fingerprint":"4aa3821a28b0b7c2400bc59aba4bcc0a76e971dadd19610d3ad38c768e124dc7","schema_version":"edge-lab-recorder.raw.v1","sequence":null,"source":"clob_market_ws"}
{"event_at":"2026-07-27T04:31:52.492000Z","event_fingerprint":"d7291336d3e54cce3db3e555b0c6f45373555c8ec528ddd9c8e3754113925c9a","payload":{"connection_id":"0f4979d6978d463e9660b042fdcf555f","event_at":"2026-07-27T04:31:52.492000Z","event_type":"price_change","frame_hash":"70ebdb12e3e30e1ea5aae177aecb7f6e9710ca259ba4188396bfee06e7ee7b96","frame_index":0,"kind":"data","monotonic_ns":228695708781916,"payload":{"event_type":"price_change","market":"0xeb66215f2e9faa6449e30a02bab5b8ed7b79a38bf961f6b24d0073c9c2419250","price_changes":[{"asset_id":"69697746896130839564035629862476347944307040470122503199396727085502753297492","best_ask":"0.3","best_bid":"0.29","hash":"79797593123bbda11bfdeec9009adc27a49ac9f5","price":"0.28","side":"BUY","size":"53"},{"asset_id":"60386828328910021732068595344565885737045900010034836345809386672230885527307","best_ask":"0.71","best_bid":"0.7","hash":"2a8b2f00809defe1cf68593aa5b577c45a7be9fb","price":"0.72","side":"SELL","size":"53"}],"timestamp":"1785126712492"},"payload_hash":"be9d4b2a2fa5dd4d5e1e6c523fef20735b86ffa5f6383a08b5beba5e474ee35a","raw_frame":"{\"market\":\"0xeb66215f2e9faa6449e30a02bab5b8ed7b79a38bf961f6b24d0073c9c2419250\", \"price_changes\":[{\"asset_id\":\"69697746896130839564035629862476347944307040470122503199396727085502753297492\", \"price\":\"0.28\", \"size\":\"53\", \"side\":\"BUY\", \"hash\":\"79797593123bbda11bfdeec9009adc27a49ac9f5\", \"best_bid\":\"0.29\", \"best_ask\":\"0.3\"}, {\"asset_id\":\"60386828328910021732068595344565885737045900010034836345809386672230885527307\", \"price\":\"0.72\", \"size\":\"53\", \"side\":\"SELL\", \"hash\":\"2a8b2f00809defe1cf68593aa5b577c45a7be9fb\", \"best_bid\":\"0.7\", \"best_ask\":\"0.71\"}], \"timestamp\":\"1785126712492\", \"event_type\":\"price_change\"}","received_at":"2026-07-27T04:31:52.439918Z","schema_version":"clob-market-ws.price_change.v1","sequence":null,"server_hash":null,"server_timestamp":"1785126712492","session_id":"e9443c7415a0419799bee9cfbb1a9e4d","source":"clob_market_ws"},"received_at":"2026-07-27T04:31:52.439918Z","record_id":"4a0ea73f137ef25e08e7c9ae971397afa7a4d59ddf931952a65e13da3e7d8cfd","schema_fingerprint":"4aa3821a28b0b7c2400bc59aba4bcc0a76e971dadd19610d3ad38c768e124dc7","schema_version":"edge-lab-recorder.raw.v1","sequence":null,"source":"clob_market_ws"}
{"event_at":"2026-07-27T04:31:52.494000Z","event_fingerprint":"a0d7b3ca618fb9834c1a396f2d29b9775f21ef2cdfb77b7f511c56986f0386d1","payload":{"connection_id":"0f4979d6978d463e9660b042fdcf555f","event_at":"2026-07-27T04:31:52.494000Z","event_type":"price_change","frame_hash":"39b673f4aabae6be94167b294eb189a0aa4d44ea755f659d6b30168473018e85","frame_index":0,"kind":"data","monotonic_ns":228695719272000,"payload":{"event_type":"price_change","market":"0xeb66215f2e9faa6449e30a02bab5b8ed7b79a38bf961f6b24d0073c9c2419250","price_changes":[{"asset_id":"60386828328910021732068595344565885737045900010034836345809386672230885527307","best_ask":"0.71","best_bid":"0.7","hash":"39c901ee466c944468d7fa69d3bf5e0af59573c0","price":"0.7","side":"BUY","size":"52.68"},{"asset_id":"69697746896130839564035629862476347944307040470122503199396727085502753297492","best_ask":"0.3","best_bid":"0.29","hash":"c881798726c0c49aa2cc3b703a0770e6e5d0e0d4","price":"0.3","side":"SELL","size":"52.68"}],"timestamp":"1785126712494"},"payload_hash":"ade3a86c6c602973b4e710f328550aca9d4e4d2cb5fd9462f8d93fafcf5afb99","raw_frame":"{\"market\":\"0xeb66215f2e9faa6449e30a02bab5b8ed7b79a38bf961f6b24d0073c9c2419250\", \"price_changes\":[{\"asset_id\":\"60386828328910021732068595344565885737045900010034836345809386672230885527307\", \"price\":\"0.7\", \"size\":\"52.68\", \"side\":\"BUY\", \"hash\":\"39c901ee466c944468d7fa69d3bf5e0af59573c0\", \"best_bid\":\"0.7\", \"best_ask\":\"0.71\"}, {\"asset_id\":\"69697746896130839564035629862476347944307040470122503199396727085502753297492\", \"price\":\"0.3\", \"size\":\"52.68\", \"side\":\"SELL\", \"hash\":\"c881798726c0c49aa2cc3b703a0770e6e5d0e0d4\", \"best_bid\":\"0.29\", \"best_ask\":\"0.3\"}], \"timestamp\":\"1785126712494\", \"event_type\":\"price_change\"}","received_at":"2026-07-27T04:31:52.450408Z","schema_version":"clob-market-ws.price_change.v1","sequence":null,"server_hash":null,"server_timestamp":"1785126712494","session_id":"e9443c7415a0419799bee9cfbb1a9e4d","source":"clob_market_ws"},"received_at":"2026-07-27T04:31:52.450408Z","record_id":"b55f62b5bfff8d79977aca2b3e137429a9fec2d629ae5eb1720379e1861c307e","schema_fingerprint":"4aa3821a28b0b7c2400bc59aba4bcc0a76e971dadd19610d3ad38c768e124dc7","schema_version":"edge-lab-recorder.raw.v1","sequence":null,"source":"clob_market_ws"}
{"event_at":"2026-07-27T04:31:52.504000Z","event_fingerprint":"9d5e28b3efab0e9acd9e3390d408b789a717a36c159890ce3bdbcbc05939ebdf","payload":{"connection_id":"0f4979d6978d463e9660b042fdcf555f","event_at":"2026-07-27T04:31:52.504000Z","event_type":"price_change","frame_hash":"7314284ff8eeedc7ae92ecd08197c2d3ede21fd1390f20159e93e65e07504780","frame_index":0,"kind":"data","monotonic_ns":228695723555541,"payload":{"event_type":"price_change","market":"0xeb66215f2e9faa6449e30a02bab5b8ed7b79a38bf961f6b24d0073c9c2419250","price_changes":[{"asset_id":"60386828328910021732068595344565885737045900010034836345809386672230885527307","best_ask":"0.71","best_bid":"0.7","hash":"5a3cb8cdcafe2a3ebb8a568b25507b8a0f37771b","price":"0.04","side":"BUY","size":"628.09"},{"asset_id":"69697746896130839564035629862476347944307040470122503199396727085502753297492","best_ask":"0.3","best_bid":"0.29","hash":"c43e065d6662236239a3b46402d39ce20b7523b0","price":"0.96","side":"SELL","size":"628.09"}],"timestamp":"1785126712504"},"payload_hash":"95033b1aafc0735b628e86fec89228ebc04913339e5ec91b98c40c912f895a99","raw_frame":"{\"market\":\"0xeb66215f2e9faa6449e30a02bab5b8ed7b79a38bf961f6b24d0073c9c2419250\", \"price_changes\":[{\"asset_id\":\"60386828328910021732068595344565885737045900010034836345809386672230885527307\", \"price\":\"0.04\", \"size\":\"628.09\", \"side\":\"BUY\", \"hash\":\"5a3cb8cdcafe2a3ebb8a568b25507b8a0f37771b\", \"best_bid\":\"0.7\", \"best_ask\":\"0.71\"}, {\"asset_id\":\"69697746896130839564035629862476347944307040470122503199396727085502753297492\", \"price\":\"0.96\", \"size\":\"628.09\", \"side\":\"SELL\", \"hash\":\"c43e065d6662236239a3b46402d39ce20b7523b0\", \"best_bid\":\"0.29\", \"best_ask\":\"0.3\"}], \"timestamp\":\"1785126712504\", \"event_type\":\"price_change\"}","received_at":"2026-07-27T04:31:52.454692Z","schema_version":"clob-market-ws.price_change.v1","sequence":null,"server_hash":null,"server_timestamp":"1785126712504","session_id":"e9443c7415a0419799bee9cfbb1a9e4d","source":"clob_market_ws"},"received_at":"2026-07-27T04:31:52.454692Z","record_id":"3dcbb304d0863c14a3c965a4242e86eb024f9760c6e84ac6cceec2e6642b08fe","schema_fingerprint":"4aa3821a28b0b7c2400bc59aba4bcc0a76e971dadd19610d3ad38c768e124dc7","schema_version":"edge-lab-recorder.raw.v1","sequence":null,"source":"clob_market_ws"}
{"event_at":"2026-07-27T04:31:52.511000Z","event_fingerprint":"eb7600045235486e9118cea7f2cf0fd08d3fc34d2685be259f7d0c01f1a6f717","payload":{"connection_id":"0f4979d6978d463e9660b042fdcf555f","event_at":"2026-07-27T04:31:52.511000Z","event_type":"price_change","frame_hash":"a22c7d97a0ce3c4315acfeb0e99d9399f5c7e37b57254ee75bf6bb885ec8080b","frame_index":0,"kind":"data","monotonic_ns":228695729095666,"payload":{"event_type":"price_change","market":"0xeb66215f2e9faa6449e30a02bab5b8ed7b79a38bf961f6b24d0073c9c2419250","price_changes":[{"asset_id":"60386828328910021732068595344565885737045900010034836345809386672230885527307","best_ask":"0.71","best_bid":"0.7","hash":"5f46f46c0becd6c172e248349e6c5a03660228bb","price":"0.65","side":"BUY","size":"50.47"},{"asset_id":"69697746896130839564035629862476347944307040470122503199396727085502753297492","best_ask":"0.3","best_bid":"0.29","hash":"ab034f7ad3fa6d6817fe0da7c0db0c5b57021b2e","price":"0.35","side":"SELL","size":"50.47"}],"timestamp":"1785126712511"},"payload_hash":"7f1c6911b48ad43fbe392a094bf4930963375162e4df4a3da8f764a03feefd95","raw_frame":"{\"market\":\"0xeb66215f2e9faa6449e30a02bab5b8ed7b79a38bf961f6b24d0073c9c2419250\", \"price_changes\":[{\"asset_id\":\"60386828328910021732068595344565885737045900010034836345809386672230885527307\", \"price\":\"0.65\", \"size\":\"50.47\", \"side\":\"BUY\", \"hash\":\"5f46f46c0becd6c172e248349e6c5a03660228bb\", \"best_bid\":\"0.7\", \"best_ask\":\"0.71\"}, {\"asset_id\":\"69697746896130839564035629862476347944307040470122503199396727085502753297492\", \"price\":\"0.35\", \"size\":\"50.47\", \"side\":\"SELL\", \"hash\":\"ab034f7ad3fa6d6817fe0da7c0db0c5b57021b2e\", \"best_bid\":\"0.29\", \"best_ask\":\"0.3\"}], \"timestamp\":\"1785126712511\", \"event_type\":\"price_change\"}","received_at":"2026-07-27T04:31:52.460233Z","schema_version":"clob-market-ws.price_change.v1","sequence":null,"server_hash":null,"server_timestamp":"1785126712511","session_id":"e9443c7415a0419799bee9cfbb1a9e4d","source":"clob_market_ws"},"received_at":"2026-07-27T04:31:52.460233Z","record_id":"020e0a490ac4b48dd81498d62aa51909370f7d75c9025eda01db741162172336","schema_fingerprint":"4aa3821a28b0b7c2400bc59aba4bcc0a76e971dadd19610d3ad38c768e124dc7","schema_version":"edge-lab-recorder.raw.v1","sequence":null,"source":"clob_market_ws"}
{"event_at":"2026-07-27T04:31:52.516000Z","event_fingerprint":"45ac7b0e4b6abdfd1f1d98964a82cc04cd1e845b423ef8076c00e7c08a6d64b3","payload":{"connection_id":"0f4979d6978d463e9660b042fdcf555f","event_at":"2026-07-27T04:31:52.516000Z","event_type":"price_change","frame_hash":"a0e701deeca57428e9eda388c4d8924fd95ad032e34cfe3e998743884a1b27e3","frame_index":0,"kind":"data","monotonic_ns":228695732966583,"payload":{"event_type":"price_change","market":"0xeb66215f2e9faa6449e30a02bab5b8ed7b79a38bf961f6b24d0073c9c2419250","price_changes":[{"asset_id":"69697746896130839564035629862476347944307040470122503199396727085502753297492","best_ask":"0.3","best_bid":"0.29","hash":"5c8546dc46a6a216e2a1ae0cbbe9e1b309ed7923","price":"0.31","side":"SELL","size":"426.56"},{"asset_id":"60386828328910021732068595344565885737045900010034836345809386672230885527307","best_ask":"0.71","best_bid":"0.7","hash":"69828fa0ecb55004d7b3d85938aa83f92c480886","price":"0.69","side":"BUY","size":"426.56"}],"timestamp":"1785126712516"},"payload_hash":"5ee3d8760229b0cc714a17ddd2b0daa2175ddb9adec1e450ac18aaffd516b657","raw_frame":"{\"market\":\"0xeb66215f2e9faa6449e30a02bab5b8ed7b79a38bf961f6b24d0073c9c2419250\", \"price_changes\":[{\"asset_id\":\"69697746896130839564035629862476347944307040470122503199396727085502753297492\", \"price\":\"0.31\", \"size\":\"426.56\", \"side\":\"SELL\", \"hash\":\"5c8546dc46a6a216e2a1ae0cbbe9e1b309ed7923\", \"best_bid\":\"0.29\", \"best_ask\":\"0.3\"}, {\"asset_id\":\"60386828328910021732068595344565885737045900010034836345809386672230885527307\", \"price\":\"0.69\", \"size\":\"426.56\", \"side\":\"BUY\", \"hash\":\"69828fa0ecb55004d7b3d85938aa83f92c480886\", \"best_bid\":\"0.7\", \"best_ask\":\"0.71\"}], \"timestamp\":\"1785126712516\", \"event_type\":\"price_change\"}","received_at":"2026-07-27T04:31:52.464105Z","schema_version":"clob-market-ws.price_change.v1","sequence":null,"server_hash":null,"server_timestamp":"1785126712516","session_id":"e9443c7415a0419799bee9cfbb1a9e4d","source":"clob_market_ws"},"received_at":"2026-07-27T04:31:52.464105Z","record_id":"0b9f969a43bb4cc859d1671746bb1b46355a738945991f2b5729b67cddd3767e","schema_fingerprint":"4aa3821a28b0b7c2400bc59aba4bcc0a76e971dadd19610d3ad38c768e124dc7","schema_version":"edge-lab-recorder.raw.v1","sequence":null,"source":"clob_market_ws"}
{"event_at":"2026-07-27T04:31:52.536000Z","event_fingerprint":"6f062d3c76dfcad75d83c5d039be00685d539170f59af69c2465496bf9901ef5","payload":{"connection_id":"0f4979d6978d463e9660b042fdcf555f","event_at":"2026-07-27T04:31:52.536000Z","event_type":"price_change","frame_hash":"f8e483080d6fe5a85264ec9689604de23f16de5b004e50d1a384ac4662b96c83","frame_index":0,"kind":"data","monotonic_ns":228695750272333,"payload":{"event_type":"price_change","market":"0xeb66215f2e9faa6449e30a02bab5b8ed7b79a38bf961f6b24d0073c9c2419250","price_changes":[{"asset_id":"60386828328910021732068595344565885737045900010034836345809386672230885527307","best_ask":"0.71","best_bid":"0.7","hash":"22e0d829074a89b3205db563bb9fdcfaf993e390","price":"0.66","side":"BUY","size":"155.47"},{"asset_id":"69697746896130839564035629862476347944307040470122503199396727085502753297492","best_ask":"0.3","best_bid":"0.29","hash":"a34f7983a522ddf144d41fbbf49ce18d5f9398c1","price":"0.34","side":"SELL","size":"155.47"}],"timestamp":"1785126712536"},"payload_hash":"7d621292376a522ae7478ecef4a63d3d31239417511d6c98693ece9a4101fbc1","raw_frame":"{\"market\":\"0xeb66215f2e9faa6449e30a02bab5b8ed7b79a38bf961f6b24d0073c9c2419250\", \"price_changes\":[{\"asset_id\":\"60386828328910021732068595344565885737045900010034836345809386672230885527307\", \"price\":\"0.66\", \"size\":\"155.47\", \"side\":\"BUY\", \"hash\":\"22e0d829074a89b3205db563bb9fdcfaf993e390\", \"best_bid\":\"0.7\", \"best_ask\":\"0.71\"}, {\"asset_id\":\"69697746896130839564035629862476347944307040470122503199396727085502753297492\", \"price\":\"0.34\", \"size\":\"155.47\", \"side\":\"SELL\", \"hash\":\"a34f7983a522ddf144d41fbbf49ce18d5f9398c1\", \"best_bid\":\"0.29\", \"best_ask\":\"0.3\"}], \"timestamp\":\"1785126712536\", \"event_type\":\"price_change\"}","received_at":"2026-07-27T04:31:52.481408Z","schema_version":"clob-market-ws.price_change.v1","sequence":null,"server_hash":null,"server_timestamp":"1785126712536","session_id":"e9443c7415a0419799bee9cfbb1a9e4d","source":"clob_market_ws"},"received_at":"2026-07-27T04:31:52.481408Z","record_id":"42a9518dd6391ed8704e2f48819919bd271a3065f0e00fbcc42ba250364482f1","schema_fingerprint":"4aa3821a28b0b7c2400bc59aba4bcc0a76e971dadd19610d3ad38c768e124dc7","schema_version":"edge-lab-recorder.raw.v1","sequence":null,"source":"clob_market_ws"}
{"event_at":"2026-07-27T04:31:52.574000Z","event_fingerprint":"74adb810a7306b38598e035cc2e8f6f58dcdd29ebc7b9563d5e359d67eb289cd","payload":{"connection_id":"0f4979d6978d463e9660b042fdcf555f","event_at":"2026-07-27T04:31:52.574000Z","event_type":"price_change","frame_hash":"5462666f29a23a4e62554049ea15e5bccfe9fcd5991f1477cc7ca3799a6a562a","frame_index":0,"kind":"data","monotonic_ns":228695786691333,"payload":{"event_type":"price_change","market":"0xeb66215f2e9faa6449e30a02bab5b8ed7b79a38bf961f6b24d0073c9c2419250","price_changes":[{"asset_id":"60386828328910021732068595344565885737045900010034836345809386672230885527307","best_ask":"0.71","best_bid":"0.7","hash":"5c214eb0e352be3e0abdd134c0236d312ce4202d","price":"0.59","side":"BUY","size":"13"},{"asset_id":"69697746896130839564035629862476347944307040470122503199396727085502753297492","best_ask":"0.3","best_bid":"0.29","hash":"d5ac9de273f72486566a09db6549dde5c1ca3050","price":"0.41","side":"SELL","size":"13"}],"timestamp":"1785126712574"},"payload_hash":"849f989598ffe5a7e9d850fb4f68ec8fdbdd6765850dbc24dc8424ade6bd78dc","raw_frame":"{\"market\":\"0xeb66215f2e9faa6449e30a02bab5b8ed7b79a38bf961f6b24d0073c9c2419250\", \"price_changes\":[{\"asset_id\":\"60386828328910021732068595344565885737045900010034836345809386672230885527307\", \"price\":\"0.59\", \"size\":\"13\", \"side\":\"BUY\", \"hash\":\"5c214eb0e352be3e0abdd134c0236d312ce4202d\", \"best_bid\":\"0.7\", \"best_ask\":\"0.71\"}, {\"asset_id\":\"69697746896130839564035629862476347944307040470122503199396727085502753297492\", \"price\":\"0.41\", \"size\":\"13\", \"side\":\"SELL\", \"hash\":\"d5ac9de273f72486566a09db6549dde5c1ca3050\", \"best_bid\":\"0.29\", \"best_ask\":\"0.3\"}], \"timestamp\":\"1785126712574\", \"event_type\":\"price_change\"}","received_at":"2026-07-27T04:31:52.517822Z","schema_version":"clob-market-ws.price_change.v1","sequence":null,"server_hash":null,"server_timestamp":"1785126712574","session_id":"e9443c7415a0419799bee9cfbb1a9e4d","source":"clob_market_ws"},"received_at":"2026-07-27T04:31:52.517822Z","record_id":"40205f45aabb9e2aabfc90ddc7f43ba7d0b8bf8878b3538bd93e82c3f9aede71","schema_fingerprint":"4aa3821a28b0b7c2400bc59aba4bcc0a76e971dadd19610d3ad38c768e124dc7","schema_version":"edge-lab-recorder.raw.v1","sequence":null,"source":"clob_market_ws"}
{"event_at":"2026-07-27T04:31:52.600000Z","event_fingerprint":"7aa6da5771b976848a4ad2d1479410abede62079cba57762af2ef168172dee71","payload":{"connection_id":"0f4979d6978d463e9660b042fdcf555f","event_at":"2026-07-27T04:31:52.600000Z","event_type":"price_change","frame_hash":"6f7b9bd8b39d62f6283a0de8e581c99726c8e8fd2780da7e93a3ed527fbebebc","frame_index":0,"kind":"data","monotonic_ns":228695814027583,"payload":{"event_type":"price_change","market":"0xeb66215f2e9faa6449e30a02bab5b8ed7b79a38bf961f6b24d0073c9c2419250","price_changes":[{"asset_id":"60386828328910021732068595344565885737045900010034836345809386672230885527307","best_ask":"0.71","best_bid":"0.7","hash":"94eae2d9806e34f3738cdb68688e52cfc28c9942","price":"0.02","side":"BUY","size":"738.1"},{"asset_id":"69697746896130839564035629862476347944307040470122503199396727085502753297492","best_ask":"0.3","best_bid":"0.29","hash":"2a7ebae483de82afca345b862b2e4caeae5990da","price":"0.98","side":"SELL","size":"738.1"}],"timestamp":"1785126712600"},"payload_hash":"774d1727a62af0f15e70d73af2c86beb658e8fd5d42b6af095c3aa64b45a14be","raw_frame":"{\"market\":\"0xeb66215f2e9faa6449e30a02bab5b8ed7b79a38bf961f6b24d0073c9c2419250\", \"price_changes\":[{\"asset_id\":\"60386828328910021732068595344565885737045900010034836345809386672230885527307\", \"price\":\"0.02\", \"size\":\"738.1\", \"side\":\"BUY\", \"hash\":\"94eae2d9806e34f3738cdb68688e52cfc28c9942\", \"best_bid\":\"0.7\", \"best_ask\":\"0.71\"}, {\"asset_id\":\"69697746896130839564035629862476347944307040470122503199396727085502753297492\", \"price\":\"0.98\", \"size\":\"738.1\", \"side\":\"SELL\", \"hash\":\"2a7ebae483de82afca345b862b2e4caeae5990da\", \"best_bid\":\"0.29\", \"best_ask\":\"0.3\"}], \"timestamp\":\"1785126712600\", \"event_type\":\"price_change\"}","received_at":"2026-07-27T04:31:52.545165Z","schema_version":"clob-market-ws.price_change.v1","sequence":null,"server_hash":null,"server_timestamp":"1785126712600","session_id":"e9443c7415a0419799bee9cfbb1a9e4d","source":"clob_market_ws"},"received_at":"2026-07-27T04:31:52.545165Z","record_id":"85f348fea5e1fe395abdd987cd0e9545eed1f890138187cc1ff1485a8da08ca7","schema_fingerprint":"4aa3821a28b0b7c2400bc59aba4bcc0a76e971dadd19610d3ad38c768e124dc7","schema_version":"edge-lab-recorder.raw.v1","sequence":null,"source":"clob_market_ws"}
{"event_at":"2026-07-27T04:31:52.614000Z","event_fingerprint":"7f5277b1eef577c6c4580cdf27c9bc85afccf0807ce22a5622afcad48f615f3e","payload":{"connection_id":"0f4979d6978d463e9660b042fdcf555f","event_at":"2026-07-27T04:31:52.614000Z","event_type":"price_change","frame_hash":"fdf4ca26d9face2990c46188708c2278dc48bc30e34a8b0594f668e2b89fd52c","frame_index":0,"kind":"data","monotonic_ns":228695828699708,"payload":{"event_type":"price_change","market":"0xeb66215f2e9faa6449e30a02bab5b8ed7b79a38bf961f6b24d0073c9c2419250","price_changes":[{"asset_id":"60386828328910021732068595344565885737045900010034836345809386672230885527307","best_ask":"0.71","best_bid":"0.7","hash":"cccd911bb520445636844861c25ddae8bdf0d8e7","price":"0.66","side":"BUY","size":"145.47"},{"asset_id":"69697746896130839564035629862476347944307040470122503199396727085502753297492","best_ask":"0.3","best_bid":"0.29","hash":"e5b5dcf08dd006ea3a459909dfc4a71845811ac0","price":"0.34","side":"SELL","size":"145.47"}],"timestamp":"1785126712614"},"payload_hash":"638d7922ef3aaefd2ca2fedb8c91d23be45a40422c88a4b24cfe73c2e0b8026e","raw_frame":"{\"market\":\"0xeb66215f2e9faa6449e30a02bab5b8ed7b79a38bf961f6b24d0073c9c2419250\", \"price_changes\":[{\"asset_id\":\"60386828328910021732068595344565885737045900010034836345809386672230885527307\", \"price\":\"0.66\", \"size\":\"145.47\", \"side\":\"BUY\", \"hash\":\"cccd911bb520445636844861c25ddae8bdf0d8e7\", \"best_bid\":\"0.7\", \"best_ask\":\"0.71\"}, {\"asset_id\":\"69697746896130839564035629862476347944307040470122503199396727085502753297492\", \"price\":\"0.34\", \"size\":\"145.47\", \"side\":\"SELL\", \"hash\":\"e5b5dcf08dd006ea3a459909dfc4a71845811ac0\", \"best_bid\":\"0.29\", \"best_ask\":\"0.3\"}], \"timestamp\":\"1785126712614\", \"event_type\":\"price_change\"}","received_at":"2026-07-27T04:31:52.559837Z","schema_version":"clob-market-ws.price_change.v1","sequence":null,"server_hash":null,"server_timestamp":"1785126712614","session_id":"e9443c7415a0419799bee9cfbb1a9e4d","source":"clob_market_ws"},"received_at":"2026-07-27T04:31:52.559837Z","record_id":"ccb9b2550e313f182601efebaa72f176beb532381072c0b711983ba3b7bbd91e","schema_fingerprint":"4aa3821a28b0b7c2400bc59aba4bcc0a76e971dadd19610d3ad38c768e124dc7","schema_version":"edge-lab-recorder.raw.v1","sequence":null,"source":"clob_market_ws"}
{"event_at":"2026-07-27T04:31:52.622000Z","event_fingerprint":"89e7bf4fff016870d2ee140a43c5b92606048677cde91bbc761633cfe5e560fd","payload":{"connection_id":"0f4979d6978d463e9660b042fdcf555f","event_at":"2026-07-27T04:31:52.622000Z","event_type":"price_change","frame_hash":"3b285f00e520029d158074cd65be45ffcad7664aff80c995362dc4a413904876","frame_index":0,"kind":"data","monotonic_ns":228695835565083,"payload":{"event_type":"price_change","market":"0xeb66215f2e9faa6449e30a02bab5b8ed7b79a38bf961f6b24d0073c9c2419250","price_changes":[{"asset_id":"69697746896130839564035629862476347944307040470122503199396727085502753297492","best_ask":"0.3","best_bid":"0.29","hash":"559e9e12f651d63827a4ee7006fa590b4d2616ee","price":"0.31","side":"SELL","size":"431.6"},{"asset_id":"60386828328910021732068595344565885737045900010034836345809386672230885527307","best_ask":"0.71","best_bid":"0.7","hash":"fcffd27a0c6e3299a14e27fe3e1060e804caa6a4","price":"0.69","side":"BUY","size":"431.6"}],"timestamp":"1785126712622"},"payload_hash":"d341bcd9fc48ff1bbbed5b87b6364b07a7070999571f2e695bf97614a8002e4e","raw_frame":"{\"market\":\"0xeb66215f2e9faa6449e30a02bab5b8ed7b79a38bf961f6b24d0073c9c2419250\", \"price_changes\":[{\"asset_id\":\"69697746896130839564035629862476347944307040470122503199396727085502753297492\", \"price\":\"0.31\", \"size\":\"431.6\", \"side\":\"SELL\", \"hash\":\"559e9e12f651d63827a4ee7006fa590b4d2616ee\", \"best_bid\":\"0.29\", \"best_ask\":\"0.3\"}, {\"asset_id\":\"60386828328910021732068595344565885737045900010034836345809386672230885527307\", \"price\":\"0.69\", \"size\":\"431.6\", \"side\":\"BUY\", \"hash\":\"fcffd27a0c6e3299a14e27fe3e1060e804caa6a4\", \"best_bid\":\"0.7\", \"best_ask\":\"0.71\"}], \"timestamp\":\"1785126712622\", \"event_type\":\"price_change\"}","received_at":"2026-07-27T04:31:52.566702Z","schema_version":"clob-market-ws.price_change.v1","sequence":null,"server_hash":null,"server_timestamp":"1785126712622","session_id":"e9443c7415a0419799bee9cfbb1a9e4d","source":"clob_market_ws"},"received_at":"2026-07-27T04:31:52.566702Z","record_id":"819379940485ff8419fb8044c51f01c37d63b48d375847c51e5f44aea766442f","schema_fingerprint":"4aa3821a28b0b7c2400bc59aba4bcc0a76e971dadd19610d3ad38c768e124dc7","schema_version":"edge-lab-recorder.raw.v1","sequence":null,"source":"clob_market_ws"}
{"event_at":"2026-07-27T04:31:52.640000Z","event_fingerprint":"ebfbed5e2df593ab4c327ef912aeb78a2782370c915575b3d9b0f6010a88040e","payload":{"connection_id":"0f4979d6978d463e9660b042fdcf555f","event_at":"2026-07-27T04:31:52.640000Z","event_type":"price_change","frame_hash":"83bb94f41ee4adb1871f908f348be500f19404e61ee9cfc2909d3867176bccdb","frame_index":0,"kind":"data","monotonic_ns":228695852025666,"payload":{"event_type":"price_change","market":"0xeb66215f2e9faa6449e30a02bab5b8ed7b79a38bf961f6b24d0073c9c2419250","price_changes":[{"asset_id":"60386828328910021732068595344565885737045900010034836345809386672230885527307","best_ask":"0.71","best_bid":"0.7","hash":"50040bdf8ef6cea26ea5fda03f47203d07cdd2ce","price":"0.65","side":"BUY","size":"60.47"},{"asset_id":"69697746896130839564035629862476347944307040470122503199396727085502753297492","best_ask":"0.3","best_bid":"0.29","hash":"e2d9c580d8057f0757e56e8f18053f690f8cb534","price":"0.35","side":"SELL","size":"60.47"}],"timestamp":"1785126712640"},"payload_hash":"b28fac369d5d79f03b97fbf106530a317eb510589ae97578709a464fd4cf425c","raw_frame":"{\"market\":\"0xeb66215f2e9faa6449e30a02bab5b8ed7b79a38bf961f6b24d0073c9c2419250\", \"price_changes\":[{\"asset_id\":\"60386828328910021732068595344565885737045900010034836345809386672230885527307\", \"price\":\"0.65\", \"size\":\"60.47\", \"side\":\"BUY\", \"hash\":\"50040bdf8ef6cea26ea5fda03f47203d07cdd2ce\", \"best_bid\":\"0.7\", \"best_ask\":\"0.71\"}, {\"asset_id\":\"69697746896130839564035629862476347944307040470122503199396727085502753297492\", \"price\":\"0.35\", \"size\":\"60.47\", \"side\":\"SELL\", \"hash\":\"e2d9c580d8057f0757e56e8f18053f690f8cb534\", \"best_bid\":\"0.29\", \"best_ask\":\"0.3\"}], \"timestamp\":\"1785126712640\", \"event_type\":\"price_change\"}","received_at":"2026-07-27T04:31:52.583163Z","schema_version":"clob-market-ws.price_change.v1","sequence":null,"server_hash":null,"server_timestamp":"1785126712640","session_id":"e9443c7415a0419799bee9cfbb1a9e4d","source":"clob_market_ws"},"received_at":"2026-07-27T04:31:52.583163Z","record_id":"da4c665e067a8f644556ace4ca2f0f017b6d535cead9e0ca594718fa79024d8a","schema_fingerprint":"4aa3821a28b0b7c2400bc59aba4bcc0a76e971dadd19610d3ad38c768e124dc7","schema_version":"edge-lab-recorder.raw.v1","sequence":null,"source":"clob_market_ws"}
{"event_at":"2026-07-27T04:31:52.666000Z","event_fingerprint":"870a4e1c23cdcdfd2680e1e33bbf1d890cf90cc3d9c9c5148a630c07c56279f3","payload":{"connection_id":"0f4979d6978d463e9660b042fdcf555f","event_at":"2026-07-27T04:31:52.666000Z","event_type":"price_change","frame_hash":"7e7b70f00e6c14bc576d4aab20edd6518829f0f22b84abf7dcebc06d136422e7","frame_index":0,"kind":"data","monotonic_ns":228695879288750,"payload":{"event_type":"price_change","market":"0xeb66215f2e9faa6449e30a02bab5b8ed7b79a38bf961f6b24d0073c9c2419250","price_changes":[{"asset_id":"60386828328910021732068595344565885737045900010034836345809386672230885527307","best_ask":"0.71","best_bid":"0.7","hash":"4707ef35594bf65d781fab75eedfe5e52e4c4ac8","price":"0.02","side":"BUY","size":"733.1"},{"asset_id":"69697746896130839564035629862476347944307040470122503199396727085502753297492","best_ask":"0.3","best_bid":"0.29","hash":"1009cfb1bfd76d7dab97b48798e569b926c10636","price":"0.98","side":"SELL","size":"733.1"}],"timestamp":"1785126712666"},"payload_hash":"1b9f3f5dfaa8a4c9459faac1de53800c587eda9e7eacccd2454f25c312055065","raw_frame":"{\"market\":\"0xeb66215f2e9faa6449e30a02bab5b8ed7b79a38bf961f6b24d0073c9c2419250\", \"price_changes\":[{\"asset_id\":\"60386828328910021732068595344565885737045900010034836345809386672230885527307\", \"price\":\"0.02\", \"size\":\"733.1\", \"side\":\"BUY\", \"hash\":\"4707ef35594bf65d781fab75eedfe5e52e4c4ac8\", \"best_bid\":\"0.7\", \"best_ask\":\"0.71\"}, {\"asset_id\":\"69697746896130839564035629862476347944307040470122503199396727085502753297492\", \"price\":\"0.98\", \"size\":\"733.1\", \"side\":\"SELL\", \"hash\":\"1009cfb1bfd76d7dab97b48798e569b926c10636\", \"best_bid\":\"0.29\", \"best_ask\":\"0.3\"}], \"timestamp\":\"1785126712666\", \"event_type\":\"price_change\"}","received_at":"2026-07-27T04:31:52.610421Z","schema_version":"clob-market-ws.price_change.v1","sequence":null,"server_hash":null,"server_timestamp":"1785126712666","session_id":"e9443c7415a0419799bee9cfbb1a9e4d","source":"clob_market_ws"},"received_at":"2026-07-27T04:31:52.610421Z","record_id":"f921457aa40a68009eee2a0bc2ebf89c86f3e61b37b5b84558ff82be84b67680","schema_fingerprint":"4aa3821a28b0b7c2400bc59aba4bcc0a76e971dadd19610d3ad38c768e124dc7","schema_version":"edge-lab-recorder.raw.v1","sequence":null,"source":"clob_market_ws"}
{"event_at":"2026-07-27T04:31:52.685000Z","event_fingerprint":"6ace6adbbeb0071795a9f967c2b1b7f16574468eac9a6c67da2927736ca247d6","payload":{"connection_id":"0f4979d6978d463e9660b042fdcf555f","event_at":"2026-07-27T04:31:52.685000Z","event_type":"price_change","frame_hash":"c2354573918deaace832b7faa4f75c939a7db98deea44ca87ce0d37ed6f8646e","frame_index":0,"kind":"data","monotonic_ns":228695899015708,"payload":{"event_type":"price_change","market":"0xeb66215f2e9faa6449e30a02bab5b8ed7b79a38bf961f6b24d0073c9c2419250","price_changes":[{"asset_id":"69697746896130839564035629862476347944307040470122503199396727085502753297492","best_ask":"0.3","best_bid":"0.29","hash":"279da10d1ab698e23cedb8b16300ac59e0be84ae","price":"0.28","side":"BUY","size":"149"},{"asset_id":"60386828328910021732068595344565885737045900010034836345809386672230885527307","best_ask":"0.71","best_bid":"0.7","hash":"dd107578bdbf3633f22a66c597a10a991d7b2ba1","price":"0.72","side":"SELL","size":"149"}],"timestamp":"1785126712685"},"payload_hash":"b4c6ec88230e47faae451558c7d5b6b09c30c1aa0ba093ce6609f5ceba45919a","raw_frame":"{\"market\":\"0xeb66215f2e9faa6449e30a02bab5b8ed7b79a38bf961f6b24d0073c9c2419250\", \"price_changes\":[{\"asset_id\":\"69697746896130839564035629862476347944307040470122503199396727085502753297492\", \"price\":\"0.28\", \"size\":\"149\", \"side\":\"BUY\", \"hash\":\"279da10d1ab698e23cedb8b16300ac59e0be84ae\", \"best_bid\":\"0.29\", \"best_ask\":\"0.3\"}, {\"asset_id\":\"60386828328910021732068595344565885737045900010034836345809386672230885527307\", \"price\":\"0.72\", \"size\":\"149\", \"side\":\"SELL\", \"hash\":\"dd107578bdbf3633f22a66c597a10a991d7b2ba1\", \"best_bid\":\"0.7\", \"best_ask\":\"0.71\"}], \"timestamp\":\"1785126712685\", \"event_type\":\"price_change\"}","received_at":"2026-07-27T04:31:52.630153Z","schema_version":"clob-market-ws.price_change.v1","sequence":null,"server_hash":null,"server_timestamp":"1785126712685","session_id":"e9443c7415a0419799bee9cfbb1a9e4d","source":"clob_market_ws"},"received_at":"2026-07-27T04:31:52.630153Z","record_id":"fb2c1607450e85f15a96dab67635b2567e2571bcb2eb499a38380969d491cd27","schema_fingerprint":"4aa3821a28b0b7c2400bc59aba4bcc0a76e971dadd19610d3ad38c768e124dc7","schema_version":"edge-lab-recorder.raw.v1","sequence":null,"source":"clob_market_ws"}
{"event_at":"2026-07-27T04:31:52.686000Z","event_fingerprint":"02dfe40c51add4d1e27b9b311b612fbc88a8ffa87de908c04d304904881c6d94","payload":{"connection_id":"0f4979d6978d463e9660b042fdcf555f","event_at":"2026-07-27T04:31:52.686000Z","event_type":"price_change","frame_hash":"cb4f232f16fc84d5930bf9bafaae15852f9a73a5912e361f69264b0a0c4acc73","frame_index":0,"kind":"data","monotonic_ns":228695902214291,"payload":{"event_type":"price_change","market":"0xeb66215f2e9faa6449e30a02bab5b8ed7b79a38bf961f6b24d0073c9c2419250","price_changes":[{"asset_id":"69697746896130839564035629862476347944307040470122503199396727085502753297492","best_ask":"0.3","best_bid":"0.29","hash":"17b29cc04be9ccde3498cbc51bf80b92cd1bda76","price":"0.28","side":"BUY","size":"419"},{"asset_id":"60386828328910021732068595344565885737045900010034836345809386672230885527307","best_ask":"0.71","best_bid":"0.7","hash":"477f4231bfa60d85ba7a513b3f4d01a39d0847b6","price":"0.72","side":"SELL","size":"419"}],"timestamp":"1785126712686"},"payload_hash":"aff0f98d41f044c81da83fc87c2bd1ad4bc176e0f01f67e20fed6c859655f172","raw_frame":"{\"market\":\"0xeb66215f2e9faa6449e30a02bab5b8ed7b79a38bf961f6b24d0073c9c2419250\", \"price_changes\":[{\"asset_id\":\"69697746896130839564035629862476347944307040470122503199396727085502753297492\", \"price\":\"0.28\", \"size\":\"419\", \"side\":\"BUY\", \"hash\":\"17b29cc04be9ccde3498cbc51bf80b92cd1bda76\", \"best_bid\":\"0.29\", \"best_ask\":\"0.3\"}, {\"asset_id\":\"60386828328910021732068595344565885737045900010034836345809386672230885527307\", \"price\":\"0.72\", \"size\":\"419\", \"side\":\"SELL\", \"hash\":\"477f4231bfa60d85ba7a513b3f4d01a39d0847b6\", \"best_bid\":\"0.7\", \"best_ask\":\"0.71\"}], \"timestamp\":\"1785126712686\", \"event_type\":\"price_change\"}","received_at":"2026-07-27T04:31:52.633359Z","schema_version":"clob-market-ws.price_change.v1","sequence":null,"server_hash":null,"server_timestamp":"1785126712686","session_id":"e9443c7415a0419799bee9cfbb1a9e4d","source":"clob_market_ws"},"received_at":"2026-07-27T04:31:52.633359Z","record_id":"6ab505221ecbc50a7a5927ac37a925248749199a29dc6795d214484ddde27df9","schema_fingerprint":"4aa3821a28b0b7c2400bc59aba4bcc0a76e971dadd19610d3ad38c768e124dc7","schema_version":"edge-lab-recorder.raw.v1","sequence":null,"source":"clob_market_ws"}
{"event_at":"2026-07-27T04:31:52.687000Z","event_fingerprint":"fdbbf9175600e9f6dde010617a0bf760d34740982dc9f5c6d9d3e9d4ec0aad48","payload":{"connection_id":"0f4979d6978d463e9660b042fdcf555f","event_at":"2026-07-27T04:31:52.687000Z","event_type":"price_change","frame_hash":"ced268bd902d89f01c1ed20662cadb04e71b5b930ed9c8386f0ec4cd6b705e73","frame_index":0,"kind":"data","monotonic_ns":228695902899875,"payload":{"event_type":"price_change","market":"0xeb66215f2e9faa6449e30a02bab5b8ed7b79a38bf961f6b24d0073c9c2419250","price_changes":[{"asset_id":"69697746896130839564035629862476347944307040470122503199396727085502753297492","best_ask":"0.3","best_bid":"0.29","hash":"7b634a849226cc4fba9231c60e615dc7c5d16e56","price":"0.27","side":"BUY","size":"136.95"},{"asset_id":"60386828328910021732068595344565885737045900010034836345809386672230885527307","best_ask":"0.71","best_bid":"0.7","hash":"585cff122643bce44133b224e46c2911b96c61d8","price":"0.73","side":"SELL","size":"136.95"}],"timestamp":"1785126712687"},"payload_hash":"ff4ee594bac9f5fbdfa778ccda1a7b9e56209538f3808aaf2525cd00a8417830","raw_frame":"{\"market\":\"0xeb66215f2e9faa6449e30a02bab5b8ed7b79a38bf961f6b24d0073c9c2419250\", \"price_changes\":[{\"asset_id\":\"69697746896130839564035629862476347944307040470122503199396727085502753297492\", \"price\":\"0.27\", \"size\":\"136.95\", \"side\":\"BUY\", \"hash\":\"7b634a849226cc4fba9231c60e615dc7c5d16e56\", \"best_bid\":\"0.29\", \"best_ask\":\"0.3\"}, {\"asset_id\":\"60386828328910021732068595344565885737045900010034836345809386672230885527307\", \"price\":\"0.73\", \"size\":\"136.95\", \"side\":\"SELL\", \"hash\":\"585cff122643bce44133b224e46c2911b96c61d8\", \"best_bid\":\"0.7\", \"best_ask\":\"0.71\"}], \"timestamp\":\"1785126712687\", \"event_type\":\"price_change\"}","received_at":"2026-07-27T04:31:52.634044Z","schema_version":"clob-market-ws.price_change.v1","sequence":null,"server_hash":null,"server_timestamp":"1785126712687","session_id":"e9443c7415a0419799bee9cfbb1a9e4d","source":"clob_market_ws"},"received_at":"2026-07-27T04:31:52.634044Z","record_id":"366786ea3814cfefd23b5da9924d229ac4e2ed9910b8b16a7f864f530dd9ec39","schema_fingerprint":"4aa3821a28b0b7c2400bc59aba4bcc0a76e971dadd19610d3ad38c768e124dc7","schema_version":"edge-lab-recorder.raw.v1","sequence":null,"source":"clob_market_ws"}
{"event_at":"2026-07-27T04:31:52.692000Z","event_fingerprint":"957ba1e5f135644eb0ca01b8830960cc02b8895792a1ce5b945c8f7f45fc0aff","payload":{"connection_id":"0f4979d6978d463e9660b042fdcf555f","event_at":"2026-07-27T04:31:52.692000Z","event_type":"price_change","frame_hash":"1a901d190b2f0f208aaa54638fb795a657e8b4b2dde118a82b7e83e93502a00c","frame_index":0,"kind":"data","monotonic_ns":228695905618875,"payload":{"event_type":"price_change","market":"0xeb66215f2e9faa6449e30a02bab5b8ed7b79a38bf961f6b24d0073c9c2419250","price_changes":[{"asset_id":"60386828328910021732068595344565885737045900010034836345809386672230885527307","best_ask":"0.71","best_bid":"0.7","hash":"108e23744cf01e4aa85f5ba0e202b02dfe0e3c1a","price":"0.69","side":"BUY","size":"161.6"},{"asset_id":"69697746896130839564035629862476347944307040470122503199396727085502753297492","best_ask":"0.3","best_bid":"0.29","hash":"2e0e5f6ba50011b3df99824b9f2f38929f5d4484","price":"0.31","side":"SELL","size":"161.6"}],"timestamp":"1785126712692"},"payload_hash":"950cc31d2c435dcc258fa360e30186363b5b8f394ba20461368174b04e2e13a3","raw_frame":"{\"market\":\"0xeb66215f2e9faa6449e30a02bab5b8ed7b79a38bf961f6b24d0073c9c2419250\", \"price_changes\":[{\"asset_id\":\"60386828328910021732068595344565885737045900010034836345809386672230885527307\", \"price\":\"0.69\", \"size\":\"161.6\", \"side\":\"BUY\", \"hash\":\"108e23744cf01e4aa85f5ba0e202b02dfe0e3c1a\", \"best_bid\":\"0.7\", \"best_ask\":\"0.71\"}, {\"asset_id\":\"69697746896130839564035629862476347944307040470122503199396727085502753297492\", \"price\":\"0.31\", \"size\":\"161.6\", \"side\":\"SELL\", \"hash\":\"2e0e5f6ba50011b3df99824b9f2f38929f5d4484\", \"best_bid\":\"0.29\", \"best_ask\":\"0.3\"}], \"timestamp\":\"1785126712692\", \"event_type\":\"price_change\"}","received_at":"2026-07-27T04:31:52.636763Z","schema_version":"clob-market-ws.price_change.v1","sequence":null,"server_hash":null,"server_timestamp":"1785126712692","session_id":"e9443c7415a0419799bee9cfbb1a9e4d","source":"clob_market_ws"},"received_at":"2026-07-27T04:31:52.636763Z","record_id":"63889519dd3cc53a921a3046d13b444174cb511200ff2d208f3af7467944e123","schema_fingerprint":"4aa3821a28b0b7c2400bc59aba4bcc0a76e971dadd19610d3ad38c768e124dc7","schema_version":"edge-lab-recorder.raw.v1","sequence":null,"source":"clob_market_ws"}
{"event_at":"2026-07-27T04:31:52.695000Z","event_fingerprint":"267d62d9b2da9a9c3477096c1edb9344d9817205291f489f6873c0f8b11b2e4a","payload":{"connection_id":"0f4979d6978d463e9660b042fdcf555f","event_at":"2026-07-27T04:31:52.695000Z","event_type":"price_change","frame_hash":"340d0e25a6609be4d6391cd00fda3a1d08e7b9d1bdaf79c719246a2e8598d645","frame_index":0,"kind":"data","monotonic_ns":228695908026791,"payload":{"event_type":"price_change","market":"0xeb66215f2e9faa6449e30a02bab5b8ed7b79a38bf961f6b24d0073c9c2419250","price_changes":[{"asset_id":"69697746896130839564035629862476347944307040470122503199396727085502753297492","best_ask":"0.3","best_bid":"0.29","hash":"b60e84324a57a6d9c2344b303278f613ab8fea6e","price":"0.27","side":"BUY","size":"40.95"},{"asset_id":"60386828328910021732068595344565885737045900010034836345809386672230885527307","best_ask":"0.71","best_bid":"0.7","hash":"9367a7d9b7d33f30fef25f102be6a561008473e8","price":"0.73","side":"SELL","size":"40.95"}],"timestamp":"1785126712695"},"payload_hash":"2ffef2ebd70ab6a4e6af3a79f3a11368ce9e4aabc9cbaa0081bc66da064a26ff","raw_frame":"{\"market\":\"0xeb66215f2e9faa6449e30a02bab5b8ed7b79a38bf961f6b24d0073c9c2419250\", \"price_changes\":[{\"asset_id\":\"69697746896130839564035629862476347944307040470122503199396727085502753297492\", \"price\":\"0.27\", \"size\":\"40.95\", \"side\":\"BUY\", \"hash\":\"b60e84324a57a6d9c2344b303278f613ab8fea6e\", \"best_bid\":\"0.29\", \"best_ask\":\"0.3\"}, {\"asset_id\":\"60386828328910021732068595344565885737045900010034836345809386672230885527307\", \"price\":\"0.73\", \"size\":\"40.95\", \"side\":\"SELL\", \"hash\":\"9367a7d9b7d33f30fef25f102be6a561008473e8\", \"best_bid\":\"0.7\", \"best_ask\":\"0.71\"}], \"timestamp\":\"1785126712695\", \"event_type\":\"price_change\"}","received_at":"2026-07-27T04:31:52.639165Z","schema_version":"clob-market-ws.price_change.v1","sequence":null,"server_hash":null,"server_timestamp":"1785126712695","session_id":"e9443c7415a0419799bee9cfbb1a9e4d","source":"clob_market_ws"},"received_at":"2026-07-27T04:31:52.639165Z","record_id":"fd4ceca05be0083018ddca45ed94ca4567c0bcab153c468a2a139da46caae580","schema_fingerprint":"4aa3821a28b0b7c2400bc59aba4bcc0a76e971dadd19610d3ad38c768e124dc7","schema_version":"edge-lab-recorder.raw.v1","sequence":null,"source":"clob_market_ws"}
{"event_at":"2026-07-27T04:31:52.721000Z","event_fingerprint":"7b5a3e648d0aae4963507aab6ad49a874f062bd587fcf94d9acdb8315fad8ced","payload":{"connection_id":"0f4979d6978d463e9660b042fdcf555f","event_at":"2026-07-27T04:31:52.721000Z","event_type":"price_change","frame_hash":"1b8761d6ac8bfaaaf9d4f6c8d44a71c199992d785ba9f0defa0ac52ed9174253","frame_index":0,"kind":"data","monotonic_ns":228695935205500,"payload":{"event_type":"price_change","market":"0xeb66215f2e9faa6449e30a02bab5b8ed7b79a38bf961f6b24d0073c9c2419250","price_changes":[{"asset_id":"69697746896130839564035629862476347944307040470122503199396727085502753297492","best_ask":"0.3","best_bid":"0.29","hash":"33f64c251c230d6469ca9c70a78ec4be67d3a4af","price":"0.31","side":"SELL","size":"156.56"},{"asset_id":"60386828328910021732068595344565885737045900010034836345809386672230885527307","best_ask":"0.71","best_bid":"0.7","hash":"971c8c2da959792ad4a640b36c92a3c621ca4826","price":"0.69","side":"BUY","size":"156.56"}],"timestamp":"1785126712721"},"payload_hash":"edc4af00fe4c22d0cb8af199f79bebaa3f59bf931493ff04e9234b844120b01e","raw_frame":"{\"market\":\"0xeb66215f2e9faa6449e30a02bab5b8ed7b79a38bf961f6b24d0073c9c2419250\", \"price_changes\":[{\"asset_id\":\"69697746896130839564035629862476347944307040470122503199396727085502753297492\", \"price\":\"0.31\", \"size\":\"156.56\", \"side\":\"SELL\", \"hash\":\"33f64c251c230d6469ca9c70a78ec4be67d3a4af\", \"best_bid\":\"0.29\", \"best_ask\":\"0.3\"}, {\"asset_id\":\"60386828328910021732068595344565885737045900010034836345809386672230885527307\", \"price\":\"0.69\", \"size\":\"156.56\", \"side\":\"BUY\", \"hash\":\"971c8c2da959792ad4a640b36c92a3c621ca4826\", \"best_bid\":\"0.7\", \"best_ask\":\"0.71\"}], \"timestamp\":\"1785126712721\", \"event_type\":\"price_change\"}","received_at":"2026-07-27T04:31:52.666344Z","schema_version":"clob-market-ws.price_change.v1","sequence":null,"server_hash":null,"server_timestamp":"1785126712721","session_id":"e9443c7415a0419799bee9cfbb1a9e4d","source":"clob_market_ws"},"received_at":"2026-07-27T04:31:52.666344Z","record_id":"229a1363b41af52879cb545ff790fac7cb8e69fc95cba776602712433fc303b3","schema_fingerprint":"4aa3821a28b0b7c2400bc59aba4bcc0a76e971dadd19610d3ad38c768e124dc7","schema_version":"edge-lab-recorder.raw.v1","sequence":null,"source":"clob_market_ws"}
{"event_at":"2026-07-27T04:31:52.722000Z","event_fingerprint":"b4fb253ef7f3eb1559d09db110dfd77ab931dcaa13d162d2b523fcbd12c50266","payload":{"connection_id":"0f4979d6978d463e9660b042fdcf555f","event_at":"2026-07-27T04:31:52.722000Z","event_type":"price_change","frame_hash":"59a0346a324aa62807504fc421b9c3658c823ed18a1ed36616a3ffa92e05f81c","frame_index":0,"kind":"data","monotonic_ns":228695936743708,"payload":{"event_type":"price_change","market":"0xeb66215f2e9faa6449e30a02bab5b8ed7b79a38bf961f6b24d0073c9c2419250","price_changes":[{"asset_id":"60386828328910021732068595344565885737045900010034836345809386672230885527307","best_ask":"0.71","best_bid":"0.7","hash":"106caf323571cce20ca37896a114274db1c4fc62","price":"0.68","side":"BUY","size":"285.6"},{"asset_id":"69697746896130839564035629862476347944307040470122503199396727085502753297492","best_ask":"0.3","best_bid":"0.29","hash":"fbd1d39b7b97b16c103f97c3b3ea082df30a592d","price":"0.32","side":"SELL","size":"285.6"}],"timestamp":"1785126712722"},"payload_hash":"e76555982bcdf830efd8717f890429eaf0f4a123f3b9ef7bc36e6297f9838e08","raw_frame":"{\"market\":\"0xeb66215f2e9faa6449e30a02bab5b8ed7b79a38bf961f6b24d0073c9c2419250\", \"price_changes\":[{\"asset_id\":\"60386828328910021732068595344565885737045900010034836345809386672230885527307\", \"price\":\"0.68\", \"size\":\"285.6\", \"side\":\"BUY\", \"hash\":\"106caf323571cce20ca37896a114274db1c4fc62\", \"best_bid\":\"0.7\", \"best_ask\":\"0.71\"}, {\"asset_id\":\"69697746896130839564035629862476347944307040470122503199396727085502753297492\", \"price\":\"0.32\", \"size\":\"285.6\", \"side\":\"SELL\", \"hash\":\"fbd1d39b7b97b16c103f97c3b3ea082df30a592d\", \"best_bid\":\"0.29\", \"best_ask\":\"0.3\"}], \"timestamp\":\"1785126712722\", \"event_type\":\"price_change\"}","received_at":"2026-07-27T04:31:52.667884Z","schema_version":"clob-market-ws.price_change.v1","sequence":null,"server_hash":null,"server_timestamp":"1785126712722","session_id":"e9443c7415a0419799bee9cfbb1a9e4d","source":"clob_market_ws"},"received_at":"2026-07-27T04:31:52.667884Z","record_id":"b1b4d6c184735151eb58db22ce4ade13bf2a109c7056f8bc2196fa1aab082dc2","schema_fingerprint":"4aa3821a28b0b7c2400bc59aba4bcc0a76e971dadd19610d3ad38c768e124dc7","schema_version":"edge-lab-recorder.raw.v1","sequence":null,"source":"clob_market_ws"}
{"event_at":"2026-07-27T04:31:52.745000Z","event_fingerprint":"0f6684827d7fca0a03a9c81e2c589d4b5b5f0f4e19f9ba17a8c3f2fc6309e98d","payload":{"connection_id":"0f4979d6978d463e9660b042fdcf555f","event_at":"2026-07-27T04:31:52.745000Z","event_type":"price_change","frame_hash":"fae5f3800c6e27d5eefbc55867ac7211cd8430ed3a5b10c337ecb3544baa61b3","frame_index":0,"kind":"data","monotonic_ns":228695958771458,"payload":{"event_type":"price_change","market":"0xeb66215f2e9faa6449e30a02bab5b8ed7b79a38bf961f6b24d0073c9c2419250","price_changes":[{"asset_id":"60386828328910021732068595344565885737045900010034836345809386672230885527307","best_ask":"0.71","best_bid":"0.7","hash":"1619687c8b91099dac571d4d03ce7e2789818b13","price":"0.03","side":"BUY","size":"648.1"},{"asset_id":"69697746896130839564035629862476347944307040470122503199396727085502753297492","best_ask":"0.3","best_bid":"0.29","hash":"50a168f7cb69fe9f2d307efe1627d6aecfec208e","price":"0.97","side":"SELL","size":"648.1"}],"timestamp":"1785126712745"},"payload_hash":"322a3e033607b5a4d5390569dc69ab2514ac5122ca3f6a015b621aca03335d45","raw_frame":"{\"market\":\"0xeb66215f2e9faa6449e30a02bab5b8ed7b79a38bf961f6b24d0073c9c2419250\", \"price_changes\":[{\"asset_id\":\"60386828328910021732068595344565885737045900010034836345809386672230885527307\", \"price\":\"0.03\", \"size\":\"648.1\", \"side\":\"BUY\", \"hash\":\"1619687c8b91099dac571d4d03ce7e2789818b13\", \"best_bid\":\"0.7\", \"best_ask\":\"0.71\"}, {\"asset_id\":\"69697746896130839564035629862476347944307040470122503199396727085502753297492\", \"price\":\"0.97\", \"size\":\"648.1\", \"side\":\"SELL\", \"hash\":\"50a168f7cb69fe9f2d307efe1627d6aecfec208e\", \"best_bid\":\"0.29\", \"best_ask\":\"0.3\"}], \"timestamp\":\"1785126712745\", \"event_type\":\"price_change\"}","received_at":"2026-07-27T04:31:52.689907Z","schema_version":"clob-market-ws.price_change.v1","sequence":null,"server_hash":null,"server_timestamp":"1785126712745","session_id":"e9443c7415a0419799bee9cfbb1a9e4d","source":"clob_market_ws"},"received_at":"2026-07-27T04:31:52.689907Z","record_id":"99d801ba6122115351f39becc1f227cfcaa73e912e674d37b442f77b53aac25e","schema_fingerprint":"4aa3821a28b0b7c2400bc59aba4bcc0a76e971dadd19610d3ad38c768e124dc7","schema_version":"edge-lab-recorder.raw.v1","sequence":null,"source":"clob_market_ws"}
{"event_at":"2026-07-27T04:31:52.752000Z","event_fingerprint":"afa4caa96c10b7be1c9011f64a4138fa697349f953c2411d2caa7ac5d921894c","payload":{"connection_id":"0f4979d6978d463e9660b042fdcf555f","event_at":"2026-07-27T04:31:52.752000Z","event_type":"price_change","frame_hash":"5d58c8663c2d57787a4686ceaa345a3024f4e2a0d6b609c8f541034a304acbed","frame_index":0,"kind":"data","monotonic_ns":228695968136500,"payload":{"event_type":"price_change","market":"0xeb66215f2e9faa6449e30a02bab5b8ed7b79a38bf961f6b24d0073c9c2419250","price_changes":[{"asset_id":"60386828328910021732068595344565885737045900010034836345809386672230885527307","best_ask":"0.71","best_bid":"0.7","hash":"23759c2771e4f4c62dec39e2a216f64629d3cba5","price":"0.7","side":"BUY","size":"47.68"},{"asset_id":"69697746896130839564035629862476347944307040470122503199396727085502753297492","best_ask":"0.3","best_bid":"0.29","hash":"af237d8db6f85244ef309592c503c1b97115114e","price":"0.3","side":"SELL","size":"47.68"}],"timestamp":"1785126712752"},"payload_hash":"021719d98e66a0b15ee853661cbfef2e0ee1d12fc237454d013eeb8a9c15a078","raw_frame":"{\"market\":\"0xeb66215f2e9faa6449e30a02bab5b8ed7b79a38bf961f6b24d0073c9c2419250\", \"price_changes\":[{\"asset_id\":\"60386828328910021732068595344565885737045900010034836345809386672230885527307\", \"price\":\"0.7\", \"size\":\"47.68\", \"side\":\"BUY\", \"hash\":\"23759c2771e4f4c62dec39e2a216f64629d3cba5\", \"best_bid\":\"0.7\", \"best_ask\":\"0.71\"}, {\"asset_id\":\"69697746896130839564035629862476347944307040470122503199396727085502753297492\", \"price\":\"0.3\", \"size\":\"47.68\", \"side\":\"SELL\", \"hash\":\"af237d8db6f85244ef309592c503c1b97115114e\", \"best_bid\":\"0.29\", \"best_ask\":\"0.3\"}], \"timestamp\":\"1785126712752\", \"event_type\":\"price_change\"}","received_at":"2026-07-27T04:31:52.699276Z","schema_version":"clob-market-ws.price_change.v1","sequence":null,"server_hash":null,"server_timestamp":"1785126712752","session_id":"e9443c7415a0419799bee9cfbb1a9e4d","source":"clob_market_ws"},"received_at":"2026-07-27T04:31:52.699276Z","record_id":"81314ba1fce7b4e87fb7381beaae32925facc5be835f79cba1f4deb088614ee7","schema_fingerprint":"4aa3821a28b0b7c2400bc59aba4bcc0a76e971dadd19610d3ad38c768e124dc7","schema_version":"edge-lab-recorder.raw.v1","sequence":null,"source":"clob_market_ws"}
{"event_at":"2026-07-27T04:31:52.752000Z","event_fingerprint":"fa02c8e8415818fea7b6adcb171389575553d2f7316b1f9df5c059c8a8eae463","payload":{"connection_id":"0f4979d6978d463e9660b042fdcf555f","event_at":"2026-07-27T04:31:52.752000Z","event_type":"price_change","frame_hash":"bda689ad41e9e47c7ee02e6161403ddbe5b6660ea6f6030fc77ac95b0164091b","frame_index":0,"kind":"data","monotonic_ns":228695970700208,"payload":{"event_type":"price_change","market":"0xeb66215f2e9faa6449e30a02bab5b8ed7b79a38bf961f6b24d0073c9c2419250","price_changes":[{"asset_id":"60386828328910021732068595344565885737045900010034836345809386672230885527307","best_ask":"0.71","best_bid":"0.7","hash":"7f9b43e18b7fa670d24f814b64b66f7044071bbb","price":"0.7","side":"BUY","size":"42.51"},{"asset_id":"69697746896130839564035629862476347944307040470122503199396727085502753297492","best_ask":"0.3","best_bid":"0.29","hash":"fa2fd7d15c33c746d47318edc64d26360adb360d","price":"0.3","side":"SELL","size":"42.51"}],"timestamp":"1785126712752"},"payload_hash":"89488d5acfc226742e14e200ffcd2e8da620513179c4a1a23d86dbf43e7547a4","raw_frame":"{\"market\":\"0xeb66215f2e9faa6449e30a02bab5b8ed7b79a38bf961f6b24d0073c9c2419250\", \"price_changes\":[{\"asset_id\":\"60386828328910021732068595344565885737045900010034836345809386672230885527307\", \"price\":\"0.7\", \"size\":\"42.51\", \"side\":\"BUY\", \"hash\":\"7f9b43e18b7fa670d24f814b64b66f7044071bbb\", \"best_bid\":\"0.7\", \"best_ask\":\"0.71\"}, {\"asset_id\":\"69697746896130839564035629862476347944307040470122503199396727085502753297492\", \"price\":\"0.3\", \"size\":\"42.51\", \"side\":\"SELL\", \"hash\":\"fa2fd7d15c33c746d47318edc64d26360adb360d\", \"best_bid\":\"0.29\", \"best_ask\":\"0.3\"}], \"timestamp\":\"1785126712752\", \"event_type\":\"price_change\"}","received_at":"2026-07-27T04:31:52.701833Z","schema_version":"clob-market-ws.price_change.v1","sequence":null,"server_hash":null,"server_timestamp":"1785126712752","session_id":"e9443c7415a0419799bee9cfbb1a9e4d","source":"clob_market_ws"},"received_at":"2026-07-27T04:31:52.701833Z","record_id":"106056e2f4816bdffa74736e00588edcb6e4c701e17b2d9c5ce975cac9f4d4bd","schema_fingerprint":"4aa3821a28b0b7c2400bc59aba4bcc0a76e971dadd19610d3ad38c768e124dc7","schema_version":"edge-lab-recorder.raw.v1","sequence":null,"source":"clob_market_ws"}
{"event_at":"2026-07-27T04:31:52.753000Z","event_fingerprint":"0b7d713f40df271620ffcbd5b04818279e026ae3a623005e4a075807645acaed","payload":{"connection_id":"0f4979d6978d463e9660b042fdcf555f","event_at":"2026-07-27T04:31:52.753000Z","event_type":"price_change","frame_hash":"eed482e889d0a6f11469a8accc477150ed454d6d79b00b7d5c9184081322cafb","frame_index":0,"kind":"data","monotonic_ns":228695972648666,"payload":{"event_type":"price_change","market":"0xeb66215f2e9faa6449e30a02bab5b8ed7b79a38bf961f6b24d0073c9c2419250","price_changes":[{"asset_id":"60386828328910021732068595344565885737045900010034836345809386672230885527307","best_ask":"0.71","best_bid":"0.7","hash":"019e68bc8179c6a2a34002ada9fdef075ba66373","price":"0.7","side":"BUY","size":"37.34"},{"asset_id":"69697746896130839564035629862476347944307040470122503199396727085502753297492","best_ask":"0.3","best_bid":"0.29","hash":"cef5fba33bb8fc972e1b578345a585784437efc7","price":"0.3","side":"SELL","size":"37.34"}],"timestamp":"1785126712753"},"payload_hash":"ce3f9276c070bc7000a1f407c5ac750f2f783e4e71fc0327a6ace858f1f6c392","raw_frame":"{\"market\":\"0xeb66215f2e9faa6449e30a02bab5b8ed7b79a38bf961f6b24d0073c9c2419250\", \"price_changes\":[{\"asset_id\":\"60386828328910021732068595344565885737045900010034836345809386672230885527307\", \"price\":\"0.7\", \"size\":\"37.34\", \"side\":\"BUY\", \"hash\":\"019e68bc8179c6a2a34002ada9fdef075ba66373\", \"best_bid\":\"0.7\", \"best_ask\":\"0.71\"}, {\"asset_id\":\"69697746896130839564035629862476347944307040470122503199396727085502753297492\", \"price\":\"0.3\", \"size\":\"37.34\", \"side\":\"SELL\", \"hash\":\"cef5fba33bb8fc972e1b578345a585784437efc7\", \"best_bid\":\"0.29\", \"best_ask\":\"0.3\"}], \"timestamp\":\"1785126712753\", \"event_type\":\"price_change\"}","received_at":"2026-07-27T04:31:52.703786Z","schema_version":"clob-market-ws.price_change.v1","sequence":null,"server_hash":null,"server_timestamp":"1785126712753","session_id":"e9443c7415a0419799bee9cfbb1a9e4d","source":"clob_market_ws"},"received_at":"2026-07-27T04:31:52.703786Z","record_id":"df9483667533438de470b50c7b9483cd36bc7ad6474239e68e69b65ece300e5b","schema_fingerprint":"4aa3821a28b0b7c2400bc59aba4bcc0a76e971dadd19610d3ad38c768e124dc7","schema_version":"edge-lab-recorder.raw.v1","sequence":null,"source":"clob_market_ws"}
{"event_at":"2026-07-27T04:31:52.778000Z","event_fingerprint":"c42287371c99e6beb0140fa35baa55a8785dcb2cf5ea7fda71b0aca8e156ac85","payload":{"connection_id":"0f4979d6978d463e9660b042fdcf555f","event_at":"2026-07-27T04:31:52.778000Z","event_type":"price_change","frame_hash":"d2de015e259bf6dbbb4e73b4d904c7056a31d97e9dabaa94a15ad0c898d1590a","frame_index":0,"kind":"data","monotonic_ns":228695990910333,"payload":{"event_type":"price_change","market":"0xeb66215f2e9faa6449e30a02bab5b8ed7b79a38bf961f6b24d0073c9c2419250","price_changes":[{"asset_id":"60386828328910021732068595344565885737045900010034836345809386672230885527307","best_ask":"0.71","best_bid":"0.7","hash":"79854244b5c926c724fdca060efed870bfafe050","price":"0.56","side":"BUY","size":"160"},{"asset_id":"69697746896130839564035629862476347944307040470122503199396727085502753297492","best_ask":"0.3","best_bid":"0.29","hash":"f6bc663af6af7e2113dea977027d2dfeec83b25a","price":"0.44","side":"SELL","size":"160"}],"timestamp":"1785126712778"},"payload_hash":"768c407b01f10a0069ca2c13430f83d3e4a64a5e91a2c04ecc4a5d5d808585ea","raw_frame":"{\"market\":\"0xeb66215f2e9faa6449e30a02bab5b8ed7b79a38bf961f6b24d0073c9c2419250\", \"price_changes\":[{\"asset_id\":\"60386828328910021732068595344565885737045900010034836345809386672230885527307\", \"price\":\"0.56\", \"size\":\"160\", \"side\":\"BUY\", \"hash\":\"79854244b5c926c724fdca060efed870bfafe050\", \"best_bid\":\"0.7\", \"best_ask\":\"0.71\"}, {\"asset_id\":\"69697746896130839564035629862476347944307040470122503199396727085502753297492\", \"price\":\"0.44\", \"size\":\"160\", \"side\":\"SELL\", \"hash\":\"f6bc663af6af7e2113dea977027d2dfeec83b25a\", \"best_bid\":\"0.29\", \"best_ask\":\"0.3\"}], \"timestamp\":\"1785126712778\", \"event_type\":\"price_change\"}","received_at":"2026-07-27T04:31:52.722046Z","schema_version":"clob-market-ws.price_change.v1","sequence":null,"server_hash":null,"server_timestamp":"1785126712778","session_id":"e9443c7415a0419799bee9cfbb1a9e4d","source":"clob_market_ws"},"received_at":"2026-07-27T04:31:52.722046Z","record_id":"dd1a2be1b356a30f34a667ffee8a9cd148bf6d42f4b1a90fe44ad9c8ab6125e1","schema_fingerprint":"4aa3821a28b0b7c2400bc59aba4bcc0a76e971dadd19610d3ad38c768e124dc7","schema_version":"edge-lab-recorder.raw.v1","sequence":null,"source":"clob_market_ws"}
{"event_at":"2026-07-27T04:31:52.779000Z","event_fingerprint":"8808eed9dcdb46faf0cd85339f5e2c3183e3e4092d368184a3916e8c317e83a1","payload":{"connection_id":"0f4979d6978d463e9660b042fdcf555f","event_at":"2026-07-27T04:31:52.779000Z","event_type":"price_change","frame_hash":"9fd78942e97c717fd567dac056774a42412322a8b1e07b5dcd819e736d20577d","frame_index":0,"kind":"data","monotonic_ns":228695992528250,"payload":{"event_type":"price_change","market":"0xeb66215f2e9faa6449e30a02bab5b8ed7b79a38bf961f6b24d0073c9c2419250","price_changes":[{"asset_id":"60386828328910021732068595344565885737045900010034836345809386672230885527307","best_ask":"0.71","best_bid":"0.7","hash":"405aa1cc497ddd042cdba1f574be250b97bac7dc","price":"0.01","side":"BUY","size":"7708.02"},{"asset_id":"69697746896130839564035629862476347944307040470122503199396727085502753297492","best_ask":"0.3","best_bid":"0.29","hash":"c2df332feb7928a0760a12258bd35f11ac77d0a9","price":"0.99","side":"SELL","size":"7708.02"}],"timestamp":"1785126712779"},"payload_hash":"c20f285d83467a6787efba7958eb2d5f629f5b9dde4c38cab3f1f158dbe0d37f","raw_frame":"{\"market\":\"0xeb66215f2e9faa6449e30a02bab5b8ed7b79a38bf961f6b24d0073c9c2419250\", \"price_changes\":[{\"asset_id\":\"60386828328910021732068595344565885737045900010034836345809386672230885527307\", \"price\":\"0.01\", \"size\":\"7708.02\", \"side\":\"BUY\", \"hash\":\"405aa1cc497ddd042cdba1f574be250b97bac7dc\", \"best_bid\":\"0.7\", \"best_ask\":\"0.71\"}, {\"asset_id\":\"69697746896130839564035629862476347944307040470122503199396727085502753297492\", \"price\":\"0.99\", \"size\":\"7708.02\", \"side\":\"SELL\", \"hash\":\"c2df332feb7928a0760a12258bd35f11ac77d0a9\", \"best_bid\":\"0.29\", \"best_ask\":\"0.3\"}], \"timestamp\":\"1785126712779\", \"event_type\":\"price_change\"}","received_at":"2026-07-27T04:31:52.723668Z","schema_version":"clob-market-ws.price_change.v1","sequence":null,"server_hash":null,"server_timestamp":"1785126712779","session_id":"e9443c7415a0419799bee9cfbb1a9e4d","source":"clob_market_ws"},"received_at":"2026-07-27T04:31:52.723668Z","record_id":"2f83dbad3681efd145b4366470456e7c2b0cc4a678d72d2a0e1adcb78a0c9144","schema_fingerprint":"4aa3821a28b0b7c2400bc59aba4bcc0a76e971dadd19610d3ad38c768e124dc7","schema_version":"edge-lab-recorder.raw.v1","sequence":null,"source":"clob_market_ws"}
{"event_at":"2026-07-27T04:31:52.802000Z","event_fingerprint":"43265b422cbed29424e85f44ca4da1356138036528d80230bcb89f1edddec09c","payload":{"connection_id":"0f4979d6978d463e9660b042fdcf555f","event_at":"2026-07-27T04:31:52.802000Z","event_type":"price_change","frame_hash":"32ce54cb3a4f39c888edbbd9d9db6a7aa83bf261881366ee6423b32ad94c4dc8","frame_index":0,"kind":"data","monotonic_ns":228696015306208,"payload":{"event_type":"price_change","market":"0xeb66215f2e9faa6449e30a02bab5b8ed7b79a38bf961f6b24d0073c9c2419250","price_changes":[{"asset_id":"60386828328910021732068595344565885737045900010034836345809386672230885527307","best_ask":"0.71","best_bid":"0.7","hash":"78595209e04a28d23f54bccce04399e080ce24a1","price":"0.03","side":"BUY","size":"643.1"},{"asset_id":"69697746896130839564035629862476347944307040470122503199396727085502753297492","best_ask":"0.3","best_bid":"0.29","hash":"a6d9e464ec264ae4c92225d50a806e135781a975","price":"0.97","side":"SELL","size":"643.1"}],"timestamp":"1785126712802"},"payload_hash":"6631da9e63405ee4cc33bceba1c57af9df1bd12dae7061ace4725f890f1fc88b","raw_frame":"{\"market\":\"0xeb66215f2e9faa6449e30a02bab5b8ed7b79a38bf961f6b24d0073c9c2419250\", \"price_changes\":[{\"asset_id\":\"60386828328910021732068595344565885737045900010034836345809386672230885527307\", \"price\":\"0.03\", \"size\":\"643.1\", \"side\":\"BUY\", \"hash\":\"78595209e04a28d23f54bccce04399e080ce24a1\", \"best_bid\":\"0.7\", \"best_ask\":\"0.71\"}, {\"asset_id\":\"69697746896130839564035629862476347944307040470122503199396727085502753297492\", \"price\":\"0.97\", \"size\":\"643.1\", \"side\":\"SELL\", \"hash\":\"a6d9e464ec264ae4c92225d50a806e135781a975\", \"best_bid\":\"0.29\", \"best_ask\":\"0.3\"}], \"timestamp\":\"1785126712802\", \"event_type\":\"price_change\"}","received_at":"2026-07-27T04:31:52.746444Z","schema_version":"clob-market-ws.price_change.v1","sequence":null,"server_hash":null,"server_timestamp":"1785126712802","session_id":"e9443c7415a0419799bee9cfbb1a9e4d","source":"clob_market_ws"},"received_at":"2026-07-27T04:31:52.746444Z","record_id":"ba3a08b984451801e413f10951180d8289c59a40e702b14186aa18edc3259588","schema_fingerprint":"4aa3821a28b0b7c2400bc59aba4bcc0a76e971dadd19610d3ad38c768e124dc7","schema_version":"edge-lab-recorder.raw.v1","sequence":null,"source":"clob_market_ws"}
{"event_at":"2026-07-27T04:31:52.805000Z","event_fingerprint":"63481293ca90534170e7a95abc6b27c12db585b4a2bb18ba820c5f3f1e42a5ca","payload":{"connection_id":"0f4979d6978d463e9660b042fdcf555f","event_at":"2026-07-27T04:31:52.805000Z","event_type":"price_change","frame_hash":"4fc92f6fea777974e5ec6f079c5b6559d0a740c38f98a01d32f269295213c6cf","frame_index":0,"kind":"data","monotonic_ns":228696018224250,"payload":{"event_type":"price_change","market":"0xeb66215f2e9faa6449e30a02bab5b8ed7b79a38bf961f6b24d0073c9c2419250","price_changes":[{"asset_id":"60386828328910021732068595344565885737045900010034836345809386672230885527307","best_ask":"0.71","best_bid":"0.7","hash":"61d9bb166ed6e394f886d539bdbe5c5b52ac6ec8","price":"0.01","side":"BUY","size":"7703.02"},{"asset_id":"69697746896130839564035629862476347944307040470122503199396727085502753297492","best_ask":"0.3","best_bid":"0.29","hash":"1545a1f80032c909fb90cac1e39d5966448240d0","price":"0.99","side":"SELL","size":"7703.02"}],"timestamp":"1785126712805"},"payload_hash":"a95cb805c6a6055d7b03b3aee450ddedc49275152a71927defe5f9b545278396","raw_frame":"{\"market\":\"0xeb66215f2e9faa6449e30a02bab5b8ed7b79a38bf961f6b24d0073c9c2419250\", \"price_changes\":[{\"asset_id\":\"60386828328910021732068595344565885737045900010034836345809386672230885527307\", \"price\":\"0.01\", \"size\":\"7703.02\", \"side\":\"BUY\", \"hash\":\"61d9bb166ed6e394f886d539bdbe5c5b52ac6ec8\", \"best_bid\":\"0.7\", \"best_ask\":\"0.71\"}, {\"asset_id\":\"69697746896130839564035629862476347944307040470122503199396727085502753297492\", \"price\":\"0.99\", \"size\":\"7703.02\", \"side\":\"SELL\", \"hash\":\"1545a1f80032c909fb90cac1e39d5966448240d0\", \"best_bid\":\"0.29\", \"best_ask\":\"0.3\"}], \"timestamp\":\"1785126712805\", \"event_type\":\"price_change\"}","received_at":"2026-07-27T04:31:52.749363Z","schema_version":"clob-market-ws.price_change.v1","sequence":null,"server_hash":null,"server_timestamp":"1785126712805","session_id":"e9443c7415a0419799bee9cfbb1a9e4d","source":"clob_market_ws"},"received_at":"2026-07-27T04:31:52.749363Z","record_id":"3698c27ad9540c08ab950f389e93b09cd1c634a3536b1a9c74c48910b19978c8","schema_fingerprint":"4aa3821a28b0b7c2400bc59aba4bcc0a76e971dadd19610d3ad38c768e124dc7","schema_version":"edge-lab-recorder.raw.v1","sequence":null,"source":"clob_market_ws"}
{"event_at":"2026-07-27T04:31:52.826000Z","event_fingerprint":"1ab69aa08409bf044333f34e9d63f262d68c0afd8ff56f67d0e734947a0739d7","payload":{"connection_id":"0f4979d6978d463e9660b042fdcf555f","event_at":"2026-07-27T04:31:52.826000Z","event_type":"price_change","frame_hash":"8297193379a03cf88e75837d213a37984dbfb7fef39d0c9d30bf541c1fa852eb","frame_index":0,"kind":"data","monotonic_ns":228696039151458,"payload":{"event_type":"price_change","market":"0xeb66215f2e9faa6449e30a02bab5b8ed7b79a38bf961f6b24d0073c9c2419250","price_changes":[{"asset_id":"69697746896130839564035629862476347944307040470122503199396727085502753297492","best_ask":"0.3","best_bid":"0.29","hash":"417528160f4a4a27b0b387cc0a5c1ada8ea6b0e7","price":"0.31","side":"SELL","size":"161.6"},{"asset_id":"60386828328910021732068595344565885737045900010034836345809386672230885527307","best_ask":"0.71","best_bid":"0.7","hash":"8e20de2cbca1bd10944063f62bc41211cfca65fc","price":"0.69","side":"BUY","size":"161.6"}],"timestamp":"1785126712826"},"payload_hash":"b2391a50b5b6e39e6af5e0d7db09c29a1ee0f80d4f27c6412d20d72bfcb4e204","raw_frame":"{\"market\":\"0xeb66215f2e9faa6449e30a02bab5b8ed7b79a38bf961f6b24d0073c9c2419250\", \"price_changes\":[{\"asset_id\":\"69697746896130839564035629862476347944307040470122503199396727085502753297492\", \"price\":\"0.31\", \"size\":\"161.6\", \"side\":\"SELL\", \"hash\":\"417528160f4a4a27b0b387cc0a5c1ada8ea6b0e7\", \"best_bid\":\"0.29\", \"best_ask\":\"0.3\"}, {\"asset_id\":\"60386828328910021732068595344565885737045900010034836345809386672230885527307\", \"price\":\"0.69\", \"size\":\"161.6\", \"side\":\"BUY\", \"hash\":\"8e20de2cbca1bd10944063f62bc41211cfca65fc\", \"best_bid\":\"0.7\", \"best_ask\":\"0.71\"}], \"timestamp\":\"1785126712826\", \"event_type\":\"price_change\"}","received_at":"2026-07-27T04:31:52.770287Z","schema_version":"clob-market-ws.price_change.v1","sequence":null,"server_hash":null,"server_timestamp":"1785126712826","session_id":"e9443c7415a0419799bee9cfbb1a9e4d","source":"clob_market_ws"},"received_at":"2026-07-27T04:31:52.770287Z","record_id":"2cf19a2f57b33e1bca98caf460806a5ee751ea7ae32982e0972e68fa42010334","schema_fingerprint":"4aa3821a28b0b7c2400bc59aba4bcc0a76e971dadd19610d3ad38c768e124dc7","schema_version":"edge-lab-recorder.raw.v1","sequence":null,"source":"clob_market_ws"}
{"event_at":"2026-07-27T04:31:52.854000Z","event_fingerprint":"12248d8ec64461bd3f6778f420b22947d99aaa54d4ceb3590339f19aad6406f3","payload":{"connection_id":"0f4979d6978d463e9660b042fdcf555f","event_at":"2026-07-27T04:31:52.854000Z","event_type":"price_change","frame_hash":"7ccc954c8097ad24442bc7d7cc1e6ff941b6708b029fa14175a9c99a74e34473","frame_index":0,"kind":"data","monotonic_ns":228696066425750,"payload":{"event_type":"price_change","market":"0xeb66215f2e9faa6449e30a02bab5b8ed7b79a38bf961f6b24d0073c9c2419250","price_changes":[{"asset_id":"60386828328910021732068595344565885737045900010034836345809386672230885527307","best_ask":"0.71","best_bid":"0.7","hash":"29e67334a0f973e298834ac008b07714cd3e600b","price":"0.01","side":"BUY","size":"7708.02"},{"asset_id":"69697746896130839564035629862476347944307040470122503199396727085502753297492","best_ask":"0.3","best_bid":"0.29","hash":"b28dc44e5b4ddb268f3a71354931ebdaf3acfa87","price":"0.99","side":"SELL","size":"7708.02"}],"timestamp":"1785126712854"},"payload_hash":"c9004effa19f17fe32c08bcde808a7c3560dc1429b8fd97f77f44ca3783680c0","raw_frame":"{\"market\":\"0xeb66215f2e9faa6449e30a02bab5b8ed7b79a38bf961f6b24d0073c9c2419250\", \"price_changes\":[{\"asset_id\":\"60386828328910021732068595344565885737045900010034836345809386672230885527307\", \"price\":\"0.01\", \"size\":\"7708.02\", \"side\":\"BUY\", \"hash\":\"29e67334a0f973e298834ac008b07714cd3e600b\", \"best_bid\":\"0.7\", \"best_ask\":\"0.71\"}, {\"asset_id\":\"69697746896130839564035629862476347944307040470122503199396727085502753297492\", \"price\":\"0.99\", \"size\":\"7708.02\", \"side\":\"SELL\", \"hash\":\"b28dc44e5b4ddb268f3a71354931ebdaf3acfa87\", \"best_bid\":\"0.29\", \"best_ask\":\"0.3\"}], \"timestamp\":\"1785126712854\", \"event_type\":\"price_change\"}","received_at":"2026-07-27T04:31:52.797565Z","schema_version":"clob-market-ws.price_change.v1","sequence":null,"server_hash":null,"server_timestamp":"1785126712854","session_id":"e9443c7415a0419799bee9cfbb1a9e4d","source":"clob_market_ws"},"received_at":"2026-07-27T04:31:52.797565Z","record_id":"ee25f24977299d1faede300f8b6cce6a791277133f034602d22fd66d7f83d8e8","schema_fingerprint":"4aa3821a28b0b7c2400bc59aba4bcc0a76e971dadd19610d3ad38c768e124dc7","schema_version":"edge-lab-recorder.raw.v1","sequence":null,"source":"clob_market_ws"}
{"event_at":"2026-07-27T04:31:52.862000Z","event_fingerprint":"bdde9656a33254a4cfa1f7dd53e3ee18f8a1828a1e6f177fc2f67eff95815a00","payload":{"connection_id":"0f4979d6978d463e9660b042fdcf555f","event_at":"2026-07-27T04:31:52.862000Z","event_type":"price_change","frame_hash":"620b9e9315d2218884617e3672f40ebbde158c7729c31cf26fc35eb8cf589086","frame_index":0,"kind":"data","monotonic_ns":228696075596000,"payload":{"event_type":"price_change","market":"0xeb66215f2e9faa6449e30a02bab5b8ed7b79a38bf961f6b24d0073c9c2419250","price_changes":[{"asset_id":"60386828328910021732068595344565885737045900010034836345809386672230885527307","best_ask":"0.71","best_bid":"0.7","hash":"c8018ace45c31152f0fbcd53bec48aaca5e7e6b6","price":"0.56","side":"BUY","size":"217"},{"asset_id":"69697746896130839564035629862476347944307040470122503199396727085502753297492","best_ask":"0.3","best_bid":"0.29","hash":"2d8613ab32319a5ce6459c89e65c42312997fa33","price":"0.44","side":"SELL","size":"217"}],"timestamp":"1785126712862"},"payload_hash":"e9316ab84807e6fceec13157fcee389fce3bd3721481378275c9629fb2bbcb51","raw_frame":"{\"market\":\"0xeb66215f2e9faa6449e30a02bab5b8ed7b79a38bf961f6b24d0073c9c2419250\", \"price_changes\":[{\"asset_id\":\"60386828328910021732068595344565885737045900010034836345809386672230885527307\", \"price\":\"0.56\", \"size\":\"217\", \"side\":\"BUY\", \"hash\":\"c8018ace45c31152f0fbcd53bec48aaca5e7e6b6\", \"best_bid\":\"0.7\", \"best_ask\":\"0.71\"}, {\"asset_id\":\"69697746896130839564035629862476347944307040470122503199396727085502753297492\", \"price\":\"0.44\", \"size\":\"217\", \"side\":\"SELL\", \"hash\":\"2d8613ab32319a5ce6459c89e65c42312997fa33\", \"best_bid\":\"0.29\", \"best_ask\":\"0.3\"}], \"timestamp\":\"1785126712862\", \"event_type\":\"price_change\"}","received_at":"2026-07-27T04:31:52.806734Z","schema_version":"clob-market-ws.price_change.v1","sequence":null,"server_hash":null,"server_timestamp":"1785126712862","session_id":"e9443c7415a0419799bee9cfbb1a9e4d","source":"clob_market_ws"},"received_at":"2026-07-27T04:31:52.806734Z","record_id":"58893bcf70c67aa788ea26ccbf57e3ea57aeb14ce51a8c51de4823e48f53a4fb","schema_fingerprint":"4aa3821a28b0b7c2400bc59aba4bcc0a76e971dadd19610d3ad38c768e124dc7","schema_version":"edge-lab-recorder.raw.v1","sequence":null,"source":"clob_market_ws"}
{"event_at":"2026-07-27T04:31:52.877000Z","event_fingerprint":"5c6de3e4713c5c314eea939c56d2eb5a022d7196944e4658756b190dd43bf160","payload":{"connection_id":"0f4979d6978d463e9660b042fdcf555f","event_at":"2026-07-27T04:31:52.877000Z","event_type":"price_change","frame_hash":"62ce349dddb53eb1fbbf047d75d2bd95c0affe2db49e7851a759750004a2cf4f","frame_index":0,"kind":"data","monotonic_ns":228696091057416,"payload":{"event_type":"price_change","market":"0xeb66215f2e9faa6449e30a02bab5b8ed7b79a38bf961f6b24d0073c9c2419250","price_changes":[{"asset_id":"60386828328910021732068595344565885737045900010034836345809386672230885527307","best_ask":"0.71","best_bid":"0.7","hash":"42e49c8b8fb8ef50eeed1547ec802d725b02d972","price":"0.01","side":"BUY","size":"7703.02"},{"asset_id":"69697746896130839564035629862476347944307040470122503199396727085502753297492","best_ask":"0.3","best_bid":"0.29","hash":"72ed37de62fb801b4b20bcd2a1b54fb42cf3ebe9","price":"0.99","side":"SELL","size":"7703.02"}],"timestamp":"1785126712877"},"payload_hash":"6b74742511645a2fab74f307b298416ac1249a9c6b19411d9b25d56dce3cc1b5","raw_frame":"{\"market\":\"0xeb66215f2e9faa6449e30a02bab5b8ed7b79a38bf961f6b24d0073c9c2419250\", \"price_changes\":[{\"asset_id\":\"60386828328910021732068595344565885737045900010034836345809386672230885527307\", \"price\":\"0.01\", \"size\":\"7703.02\", \"side\":\"BUY\", \"hash\":\"42e49c8b8fb8ef50eeed1547ec802d725b02d972\", \"best_bid\":\"0.7\", \"best_ask\":\"0.71\"}, {\"asset_id\":\"69697746896130839564035629862476347944307040470122503199396727085502753297492\", \"price\":\"0.99\", \"size\":\"7703.02\", \"side\":\"SELL\", \"hash\":\"72ed37de62fb801b4b20bcd2a1b54fb42cf3ebe9\", \"best_bid\":\"0.29\", \"best_ask\":\"0.3\"}], \"timestamp\":\"1785126712877\", \"event_type\":\"price_change\"}","received_at":"2026-07-27T04:31:52.822194Z","schema_version":"clob-market-ws.price_change.v1","sequence":null,"server_hash":null,"server_timestamp":"1785126712877","session_id":"e9443c7415a0419799bee9cfbb1a9e4d","source":"clob_market_ws"},"received_at":"2026-07-27T04:31:52.822194Z","record_id":"e62916a29fe72200458fbe4eebcbef740974588d8ee797be9aa38d01fb653af9","schema_fingerprint":"4aa3821a28b0b7c2400bc59aba4bcc0a76e971dadd19610d3ad38c768e124dc7","schema_version":"edge-lab-recorder.raw.v1","sequence":null,"source":"clob_market_ws"}
{"event_at":"2026-07-27T04:31:52.888000Z","event_fingerprint":"fa76b58f1e5f00ff8f598f201012e70c3b610dd14cbf855beaa5f7c4888cf99a","payload":{"connection_id":"0f4979d6978d463e9660b042fdcf555f","event_at":"2026-07-27T04:31:52.888000Z","event_type":"price_change","frame_hash":"13c973fe56a2597a3e124aedd590bfeb40ca11741eef9f2af743e106fe43e242","frame_index":0,"kind":"data","monotonic_ns":228696101678625,"payload":{"event_type":"price_change","market":"0xeb66215f2e9faa6449e30a02bab5b8ed7b79a38bf961f6b24d0073c9c2419250","price_changes":[{"asset_id":"60386828328910021732068595344565885737045900010034836345809386672230885527307","best_ask":"0.71","best_bid":"0.7","hash":"feb02f635540a2ef412593f997d3f930c741f536","price":"0.03","side":"BUY","size":"648.1"},{"asset_id":"69697746896130839564035629862476347944307040470122503199396727085502753297492","best_ask":"0.3","best_bid":"0.29","hash":"657b3ff371a36dca2aed1622b440d4197c410177","price":"0.97","side":"SELL","size":"648.1"}],"timestamp":"1785126712888"},"payload_hash":"2725dbd5b3b65ea2e0f8d93cee9007f715c00d5e641904997a5237ce6963565b","raw_frame":"{\"market\":\"0xeb66215f2e9faa6449e30a02bab5b8ed7b79a38bf961f6b24d0073c9c2419250\", \"price_changes\":[{\"asset_id\":\"60386828328910021732068595344565885737045900010034836345809386672230885527307\", \"price\":\"0.03\", \"size\":\"648.1\", \"side\":\"BUY\", \"hash\":\"feb02f635540a2ef412593f997d3f930c741f536\", \"best_bid\":\"0.7\", \"best_ask\":\"0.71\"}, {\"asset_id\":\"69697746896130839564035629862476347944307040470122503199396727085502753297492\", \"price\":\"0.97\", \"size\":\"648.1\", \"side\":\"SELL\", \"hash\":\"657b3ff371a36dca2aed1622b440d4197c410177\", \"best_bid\":\"0.29\", \"best_ask\":\"0.3\"}], \"timestamp\":\"1785126712888\", \"event_type\":\"price_change\"}","received_at":"2026-07-27T04:31:52.832819Z","schema_version":"clob-market-ws.price_change.v1","sequence":null,"server_hash":null,"server_timestamp":"1785126712888","session_id":"e9443c7415a0419799bee9cfbb1a9e4d","source":"clob_market_ws"},"received_at":"2026-07-27T04:31:52.832819Z","record_id":"743fac872149ba9fad2650893634a0e925c1d18e38b8dbfc3704f855a046fbc5","schema_fingerprint":"4aa3821a28b0b7c2400bc59aba4bcc0a76e971dadd19610d3ad38c768e124dc7","schema_version":"edge-lab-recorder.raw.v1","sequence":null,"source":"clob_market_ws"}
{"event_at":"2026-07-27T04:31:52.930000Z","event_fingerprint":"6c37c8d30f46e82cd328085648c530c8231b1bb4b53d9a4a9d2380ca68d145a4","payload":{"connection_id":"0f4979d6978d463e9660b042fdcf555f","event_at":"2026-07-27T04:31:52.930000Z","event_type":"price_change","frame_hash":"222db80aa81987761285fca1ca80a28e1997db7fad930767282ebd51741b1cc5","frame_index":0,"kind":"data","monotonic_ns":228696143391875,"payload":{"event_type":"price_change","market":"0xeb66215f2e9faa6449e30a02bab5b8ed7b79a38bf961f6b24d0073c9c2419250","price_changes":[{"asset_id":"69697746896130839564035629862476347944307040470122503199396727085502753297492","best_ask":"0.3","best_bid":"0.29","hash":"f2027bbe06999d7fe851fd0055fd2f0edaa39825","price":"0.31","side":"SELL","size":"156.56"},{"asset_id":"60386828328910021732068595344565885737045900010034836345809386672230885527307","best_ask":"0.71","best_bid":"0.7","hash":"b3d6746b78c23b9dab0e666ef132917b0e04fafb","price":"0.69","side":"BUY","size":"156.56"}],"timestamp":"1785126712930"},"payload_hash":"3c29076c2da874dae084264ff0915b334b5ef27c960af6aed50965993e5a6868","raw_frame":"{\"market\":\"0xeb66215f2e9faa6449e30a02bab5b8ed7b79a38bf961f6b24d0073c9c2419250\", \"price_changes\":[{\"asset_id\":\"69697746896130839564035629862476347944307040470122503199396727085502753297492\", \"price\":\"0.31\", \"size\":\"156.56\", \"side\":\"SELL\", \"hash\":\"f2027bbe06999d7fe851fd0055fd2f0edaa39825\", \"best_bid\":\"0.29\", \"best_ask\":\"0.3\"}, {\"asset_id\":\"60386828328910021732068595344565885737045900010034836345809386672230885527307\", \"price\":\"0.69\", \"size\":\"156.56\", \"side\":\"BUY\", \"hash\":\"b3d6746b78c23b9dab0e666ef132917b0e04fafb\", \"best_bid\":\"0.7\", \"best_ask\":\"0.71\"}], \"timestamp\":\"1785126712930\", \"event_type\":\"price_change\"}","received_at":"2026-07-27T04:31:52.874530Z","schema_version":"clob-market-ws.price_change.v1","sequence":null,"server_hash":null,"server_timestamp":"1785126712930","session_id":"e9443c7415a0419799bee9cfbb1a9e4d","source":"clob_market_ws"},"received_at":"2026-07-27T04:31:52.874530Z","record_id":"618390637a5e8c224db4d36f2fe0a1effc43560158017f6998da0f34fdc1c802","schema_fingerprint":"4aa3821a28b0b7c2400bc59aba4bcc0a76e971dadd19610d3ad38c768e124dc7","schema_version":"edge-lab-recorder.raw.v1","sequence":null,"source":"clob_market_ws"}
{"event_at":"2026-07-27T04:31:52.959000Z","event_fingerprint":"ebdd7441b1054a148e788bf60255e8b6b1f60abca0c9b02feae9878b2e96fbba","payload":{"connection_id":"0f4979d6978d463e9660b042fdcf555f","event_at":"2026-07-27T04:31:52.959000Z","event_type":"price_change","frame_hash":"bd8c34e5412989c4f27e8e00eac872c8ea168e6be67bb7d5063b0442743e0840","frame_index":0,"kind":"data","monotonic_ns":228696172455500,"payload":{"event_type":"price_change","market":"0xeb66215f2e9faa6449e30a02bab5b8ed7b79a38bf961f6b24d0073c9c2419250","price_changes":[{"asset_id":"60386828328910021732068595344565885737045900010034836345809386672230885527307","best_ask":"0.71","best_bid":"0.7","hash":"bf096e28796e870bb57714709b7a714b447d41fa","price":"0.03","side":"BUY","size":"643.1"},{"asset_id":"69697746896130839564035629862476347944307040470122503199396727085502753297492","best_ask":"0.3","best_bid":"0.29","hash":"4c1267a834a63750d505a2dbe5f2c46a2da653c4","price":"0.97","side":"SELL","size":"643.1"}],"timestamp":"1785126712959"},"payload_hash":"cfb66b20eb1e4f6059ed67fa4a78991c03cf47467f8345a8d07758e77ec55be0","raw_frame":"{\"market\":\"0xeb66215f2e9faa6449e30a02bab5b8ed7b79a38bf961f6b24d0073c9c2419250\", \"price_changes\":[{\"asset_id\":\"60386828328910021732068595344565885737045900010034836345809386672230885527307\", \"price\":\"0.03\", \"size\":\"643.1\", \"side\":\"BUY\", \"hash\":\"bf096e28796e870bb57714709b7a714b447d41fa\", \"best_bid\":\"0.7\", \"best_ask\":\"0.71\"}, {\"asset_id\":\"69697746896130839564035629862476347944307040470122503199396727085502753297492\", \"price\":\"0.97\", \"size\":\"643.1\", \"side\":\"SELL\", \"hash\":\"4c1267a834a63750d505a2dbe5f2c46a2da653c4\", \"best_bid\":\"0.29\", \"best_ask\":\"0.3\"}], \"timestamp\":\"1785126712959\", \"event_type\":\"price_change\"}","received_at":"2026-07-27T04:31:52.903592Z","schema_version":"clob-market-ws.price_change.v1","sequence":null,"server_hash":null,"server_timestamp":"1785126712959","session_id":"e9443c7415a0419799bee9cfbb1a9e4d","source":"clob_market_ws"},"received_at":"2026-07-27T04:31:52.903592Z","record_id":"9f95827149c4a5bb63a135984a343fd5bacba4ada0a278fa72a6e3d6221816c8","schema_fingerprint":"4aa3821a28b0b7c2400bc59aba4bcc0a76e971dadd19610d3ad38c768e124dc7","schema_version":"edge-lab-recorder.raw.v1","sequence":null,"source":"clob_market_ws"}
{"event_at":"2026-07-27T04:31:52.986000Z","event_fingerprint":"8468e05899240df79bfd2bddec0d60f6819fb26f7029e85f950f8e36f0b6875e","payload":{"connection_id":"0f4979d6978d463e9660b042fdcf555f","event_at":"2026-07-27T04:31:52.986000Z","event_type":"price_change","frame_hash":"0b941d325b02d847b09c72efedffa2a6e60982bc7f41586a15a983de3262fe9d","frame_index":0,"kind":"data","monotonic_ns":228696199895541,"payload":{"event_type":"price_change","market":"0xeb66215f2e9faa6449e30a02bab5b8ed7b79a38bf961f6b24d0073c9c2419250","price_changes":[{"asset_id":"60386828328910021732068595344565885737045900010034836345809386672230885527307","best_ask":"0.71","best_bid":"0.7","hash":"a471cd5dec4ba77982b94c640d3065add6bb665d","price":"0.68","side":"BUY","size":"15.6"},{"asset_id":"69697746896130839564035629862476347944307040470122503199396727085502753297492","best_ask":"0.3","best_bid":"0.29","hash":"aee11e0f3c6c67c0282651fe53b20f6ffcd55268","price":"0.32","side":"SELL","size":"15.6"}],"timestamp":"1785126712986"},"payload_hash":"5e2143aac97d6c50ab84b781fbeece91212866fd99d666a594a5699c117e90ed","raw_frame":"{\"market\":\"0xeb66215f2e9faa6449e30a02bab5b8ed7b79a38bf961f6b24d0073c9c2419250\", \"price_changes\":[{\"asset_id\":\"60386828328910021732068595344565885737045900010034836345809386672230885527307\", \"price\":\"0.68\", \"size\":\"15.6\", \"side\":\"BUY\", \"hash\":\"a471cd5dec4ba77982b94c640d3065add6bb665d\", \"best_bid\":\"0.7\", \"best_ask\":\"0.71\"}, {\"asset_id\":\"69697746896130839564035629862476347944307040470122503199396727085502753297492\", \"price\":\"0.32\", \"size\":\"15.6\", \"side\":\"SELL\", \"hash\":\"aee11e0f3c6c67c0282651fe53b20f6ffcd55268\", \"best_bid\":\"0.29\", \"best_ask\":\"0.3\"}], \"timestamp\":\"1785126712986\", \"event_type\":\"price_change\"}","received_at":"2026-07-27T04:31:52.931036Z","schema_version":"clob-market-ws.price_change.v1","sequence":null,"server_hash":null,"server_timestamp":"1785126712986","session_id":"e9443c7415a0419799bee9cfbb1a9e4d","source":"clob_market_ws"},"received_at":"2026-07-27T04:31:52.931036Z","record_id":"0ea9396cf964377776176a549930fcfc1a636200929c9d494e6a7f1335339d62","schema_fingerprint":"4aa3821a28b0b7c2400bc59aba4bcc0a76e971dadd19610d3ad38c768e124dc7","schema_version":"edge-lab-recorder.raw.v1","sequence":null,"source":"clob_market_ws"}
{"event_at":"2026-07-27T04:31:52.988000Z","event_fingerprint":"04e787e8cd71aa95ffd99f79deca0cb0710b7e50dfbb21055fb391b6263b14e1","payload":{"connection_id":"0f4979d6978d463e9660b042fdcf555f","event_at":"2026-07-27T04:31:52.988000Z","event_type":"price_change","frame_hash":"dd7d18a312b0142defa9d70a2fe716511f599710530d43f8c4818bb70a8a790b","frame_index":0,"kind":"data","monotonic_ns":228696203850583,"payload":{"event_type":"price_change","market":"0xeb66215f2e9faa6449e30a02bab5b8ed7b79a38bf961f6b24d0073c9c2419250","price_changes":[{"asset_id":"60386828328910021732068595344565885737045900010034836345809386672230885527307","best_ask":"0.71","best_bid":"0.7","hash":"3be22a2f2e368422a2b3282872c8aa7b80772c1a","price":"0.69","side":"BUY","size":"426.56"},{"asset_id":"69697746896130839564035629862476347944307040470122503199396727085502753297492","best_ask":"0.3","best_bid":"0.29","hash":"7665eb3a143161073cbd6048344e23d821478eb2","price":"0.31","side":"SELL","size":"426.56"}],"timestamp":"1785126712988"},"payload_hash":"2391db456161c5dcd64c0f3423e09fa143259bbde487b108b3250e3874e797e8","raw_frame":"{\"market\":\"0xeb66215f2e9faa6449e30a02bab5b8ed7b79a38bf961f6b24d0073c9c2419250\", \"price_changes\":[{\"asset_id\":\"60386828328910021732068595344565885737045900010034836345809386672230885527307\", \"price\":\"0.69\", \"size\":\"426.56\", \"side\":\"BUY\", \"hash\":\"3be22a2f2e368422a2b3282872c8aa7b80772c1a\", \"best_bid\":\"0.7\", \"best_ask\":\"0.71\"}, {\"asset_id\":\"69697746896130839564035629862476347944307040470122503199396727085502753297492\", \"price\":\"0.31\", \"size\":\"426.56\", \"side\":\"SELL\", \"hash\":\"7665eb3a143161073cbd6048344e23d821478eb2\", \"best_bid\":\"0.29\", \"best_ask\":\"0.3\"}], \"timestamp\":\"1785126712988\", \"event_type\":\"price_change\"}","received_at":"2026-07-27T04:31:52.934992Z","schema_version":"clob-market-ws.price_change.v1","sequence":null,"server_hash":null,"server_timestamp":"1785126712988","session_id":"e9443c7415a0419799bee9cfbb1a9e4d","source":"clob_market_ws"},"received_at":"2026-07-27T04:31:52.934992Z","record_id":"265e528cafe805d61493bc5c8c56b9972e56229ac72a6fa4684c1d55f1681ed6","schema_fingerprint":"4aa3821a28b0b7c2400bc59aba4bcc0a76e971dadd19610d3ad38c768e124dc7","schema_version":"edge-lab-recorder.raw.v1","sequence":null,"source":"clob_market_ws"}
{"event_at":"2026-07-27T04:31:53.028000Z","event_fingerprint":"14e28c86ae859a622d0c06b72b0417a061e7290602a7f729d7986edec715d457","payload":{"connection_id":"0f4979d6978d463e9660b042fdcf555f","event_at":"2026-07-27T04:31:53.028000Z","event_type":"price_change","frame_hash":"b395968c52594071beebf719054b2f296a7c46c4790bf46c8dfbe4298d811d3d","frame_index":0,"kind":"data","monotonic_ns":228696241198333,"payload":{"event_type":"price_change","market":"0xeb66215f2e9faa6449e30a02bab5b8ed7b79a38bf961f6b24d0073c9c2419250","price_changes":[{"asset_id":"69697746896130839564035629862476347944307040470122503199396727085502753297492","best_ask":"0.3","best_bid":"0.29","hash":"439eb6fd7f746c9b3f75a05d40a661a1a06659a3","price":"0.01","side":"BUY","size":"7924.91"},{"asset_id":"60386828328910021732068595344565885737045900010034836345809386672230885527307","best_ask":"0.71","best_bid":"0.7","hash":"a39562f26b32f250ddf3a368d283ad621c5e0814","price":"0.99","side":"SELL","size":"7924.91"}],"timestamp":"1785126713028"},"payload_hash":"cfd926f50fe21a4d3c8391b29ce59718d2a7570305974171ea39ee97bb1540c1","raw_frame":"{\"market\":\"0xeb66215f2e9faa6449e30a02bab5b8ed7b79a38bf961f6b24d0073c9c2419250\", \"price_changes\":[{\"asset_id\":\"69697746896130839564035629862476347944307040470122503199396727085502753297492\", \"price\":\"0.01\", \"size\":\"7924.91\", \"side\":\"BUY\", \"hash\":\"439eb6fd7f746c9b3f75a05d40a661a1a06659a3\", \"best_bid\":\"0.29\", \"best_ask\":\"0.3\"}, {\"asset_id\":\"60386828328910021732068595344565885737045900010034836345809386672230885527307\", \"price\":\"0.99\", \"size\":\"7924.91\", \"side\":\"SELL\", \"hash\":\"a39562f26b32f250ddf3a368d283ad621c5e0814\", \"best_bid\":\"0.7\", \"best_ask\":\"0.71\"}], \"timestamp\":\"1785126713028\", \"event_type\":\"price_change\"}","received_at":"2026-07-27T04:31:52.972337Z","schema_version":"clob-market-ws.price_change.v1","sequence":null,"server_hash":null,"server_timestamp":"1785126713028","session_id":"e9443c7415a0419799bee9cfbb1a9e4d","source":"clob_market_ws"},"received_at":"2026-07-27T04:31:52.972337Z","record_id":"be6d1762d5ac10935b1c2f1da94571c1c3558f1cff574d1913d5582c865ff204","schema_fingerprint":"4aa3821a28b0b7c2400bc59aba4bcc0a76e971dadd19610d3ad38c768e124dc7","schema_version":"edge-lab-recorder.raw.v1","sequence":null,"source":"clob_market_ws"}
{"event_at":"2026-07-27T04:31:53.030000Z","event_fingerprint":"0ad478d3228caf8806a6c5f59d48c0dcbf8c51ce7649ec01bb54d965e0185f2d","payload":{"connection_id":"0f4979d6978d463e9660b042fdcf555f","event_at":"2026-07-27T04:31:53.030000Z","event_type":"price_change","frame_hash":"e35cfd3331bbb26e2a6288f4503c52782b86a02aab37b88483728a28dabf3c3d","frame_index":0,"kind":"data","monotonic_ns":228696243354416,"payload":{"event_type":"price_change","market":"0xeb66215f2e9faa6449e30a02bab5b8ed7b79a38bf961f6b24d0073c9c2419250","price_changes":[{"asset_id":"69697746896130839564035629862476347944307040470122503199396727085502753297492","best_ask":"0.3","best_bid":"0.29","hash":"ce590018eeb02a2599c0537909025f8713c16c95","price":"0.31","side":"SELL","size":"431.6"},{"asset_id":"60386828328910021732068595344565885737045900010034836345809386672230885527307","best_ask":"0.71","best_bid":"0.7","hash":"1bac5268e278976573907c057d3da883a9e749f5","price":"0.69","side":"BUY","size":"431.6"}],"timestamp":"1785126713030"},"payload_hash":"d74ba7648a05e5cdde05bae445783201e818aa4f02173674e9b44daf8fd2feb5","raw_frame":"{\"market\":\"0xeb66215f2e9faa6449e30a02bab5b8ed7b79a38bf961f6b24d0073c9c2419250\", \"price_changes\":[{\"asset_id\":\"69697746896130839564035629862476347944307040470122503199396727085502753297492\", \"price\":\"0.31\", \"size\":\"431.6\", \"side\":\"SELL\", \"hash\":\"ce590018eeb02a2599c0537909025f8713c16c95\", \"best_bid\":\"0.29\", \"best_ask\":\"0.3\"}, {\"asset_id\":\"60386828328910021732068595344565885737045900010034836345809386672230885527307\", \"price\":\"0.69\", \"size\":\"431.6\", \"side\":\"BUY\", \"hash\":\"1bac5268e278976573907c057d3da883a9e749f5\", \"best_bid\":\"0.7\", \"best_ask\":\"0.71\"}], \"timestamp\":\"1785126713030\", \"event_type\":\"price_change\"}","received_at":"2026-07-27T04:31:52.974494Z","schema_version":"clob-market-ws.price_change.v1","sequence":null,"server_hash":null,"server_timestamp":"1785126713030","session_id":"e9443c7415a0419799bee9cfbb1a9e4d","source":"clob_market_ws"},"received_at":"2026-07-27T04:31:52.974494Z","record_id":"7c3ec80e8d6c82227c7c4d78c9b86fe511532d703c91bbcd21f627f294268686","schema_fingerprint":"4aa3821a28b0b7c2400bc59aba4bcc0a76e971dadd19610d3ad38c768e124dc7","schema_version":"edge-lab-recorder.raw.v1","sequence":null,"source":"clob_market_ws"}
{"event_at":"2026-07-27T04:31:53.032000Z","event_fingerprint":"01e4e323f9c8c70bfc8cabec2de26e9c1ea8fe573615c65916484c8caf917797","payload":{"connection_id":"0f4979d6978d463e9660b042fdcf555f","event_at":"2026-07-27T04:31:53.032000Z","event_type":"price_change","frame_hash":"a2d80d00dd6f2a51385853327556aed2462a725611563c5eb5378f2a0cee7578","frame_index":0,"kind":"data","monotonic_ns":228696246565791,"payload":{"event_type":"price_change","market":"0xeb66215f2e9faa6449e30a02bab5b8ed7b79a38bf961f6b24d0073c9c2419250","price_changes":[{"asset_id":"69697746896130839564035629862476347944307040470122503199396727085502753297492","best_ask":"0.3","best_bid":"0.29","hash":"400a00175ac1e737a4367eecee855764277691cc","price":"0.01","side":"BUY","size":"7929.91"},{"asset_id":"60386828328910021732068595344565885737045900010034836345809386672230885527307","best_ask":"0.71","best_bid":"0.7","hash":"787bbc55c989619920529f5f81863805c6eb0969","price":"0.99","side":"SELL","size":"7929.91"}],"timestamp":"1785126713032"},"payload_hash":"05f53758b05ac673fa148b3e029b3eb925b461960d1cf6de8da233fd248c9c32","raw_frame":"{\"market\":\"0xeb66215f2e9faa6449e30a02bab5b8ed7b79a38bf961f6b24d0073c9c2419250\", \"price_changes\":[{\"asset_id\":\"69697746896130839564035629862476347944307040470122503199396727085502753297492\", \"price\":\"0.01\", \"size\":\"7929.91\", \"side\":\"BUY\", \"hash\":\"400a00175ac1e737a4367eecee855764277691cc\", \"best_bid\":\"0.29\", \"best_ask\":\"0.3\"}, {\"asset_id\":\"60386828328910021732068595344565885737045900010034836345809386672230885527307\", \"price\":\"0.99\", \"size\":\"7929.91\", \"side\":\"SELL\", \"hash\":\"787bbc55c989619920529f5f81863805c6eb0969\", \"best_bid\":\"0.7\", \"best_ask\":\"0.71\"}], \"timestamp\":\"1785126713032\", \"event_type\":\"price_change\"}","received_at":"2026-07-27T04:31:52.977708Z","schema_version":"clob-market-ws.price_change.v1","sequence":null,"server_hash":null,"server_timestamp":"1785126713032","session_id":"e9443c7415a0419799bee9cfbb1a9e4d","source":"clob_market_ws"},"received_at":"2026-07-27T04:31:52.977708Z","record_id":"76d9214da3791ee9eec28c780bd49070f11bf1436cc2de5ba22f2b24cd413c2e","schema_fingerprint":"4aa3821a28b0b7c2400bc59aba4bcc0a76e971dadd19610d3ad38c768e124dc7","schema_version":"edge-lab-recorder.raw.v1","sequence":null,"source":"clob_market_ws"}
{"event_at":"2026-07-27T04:31:53.053000Z","event_fingerprint":"77b0a3b8386d54d6de47f5f68970cd55bc642504558803dd5438f468aa601bcb","payload":{"connection_id":"0f4979d6978d463e9660b042fdcf555f","event_at":"2026-07-27T04:31:53.053000Z","event_type":"price_change","frame_hash":"bcafff75beff6f1e4cf591c1142175aacd609b7aa6624744f91b50f9379e1a2a","frame_index":0,"kind":"data","monotonic_ns":228696266018750,"payload":{"event_type":"price_change","market":"0xeb66215f2e9faa6449e30a02bab5b8ed7b79a38bf961f6b24d0073c9c2419250","price_changes":[{"asset_id":"69697746896130839564035629862476347944307040470122503199396727085502753297492","best_ask":"0.3","best_bid":"0.29","hash":"261ad14f86a56e7a24005b53e3bb006547e56fe6","price":"0.01","side":"BUY","size":"7924.91"},{"asset_id":"60386828328910021732068595344565885737045900010034836345809386672230885527307","best_ask":"0.71","best_bid":"0.7","hash":"e9e1acc66e18b74f00115ad8ba71bb459631b793","price":"0.99","side":"SELL","size":"7924.91"}],"timestamp":"1785126713053"},"payload_hash":"45f942b66c46e09098ce4c7a9bb99de9293a1f673d5ae5c30de749ea09beee15","raw_frame":"{\"market\":\"0xeb66215f2e9faa6449e30a02bab5b8ed7b79a38bf961f6b24d0073c9c2419250\", \"price_changes\":[{\"asset_id\":\"69697746896130839564035629862476347944307040470122503199396727085502753297492\", \"price\":\"0.01\", \"size\":\"7924.91\", \"side\":\"BUY\", \"hash\":\"261ad14f86a56e7a24005b53e3bb006547e56fe6\", \"best_bid\":\"0.29\", \"best_ask\":\"0.3\"}, {\"asset_id\":\"60386828328910021732068595344565885737045900010034836345809386672230885527307\", \"price\":\"0.99\", \"size\":\"7924.91\", \"side\":\"SELL\", \"hash\":\"e9e1acc66e18b74f00115ad8ba71bb459631b793\", \"best_bid\":\"0.7\", \"best_ask\":\"0.71\"}], \"timestamp\":\"1785126713053\", \"event_type\":\"price_change\"}","received_at":"2026-07-27T04:31:52.997158Z","schema_version":"clob-market-ws.price_change.v1","sequence":null,"server_hash":null,"server_timestamp":"1785126713053","session_id":"e9443c7415a0419799bee9cfbb1a9e4d","source":"clob_market_ws"},"received_at":"2026-07-27T04:31:52.997158Z","record_id":"7ed09d6c11fc03d137872a6737ef4c759e0d9089a3e2f4554a0b26cc02ae684a","schema_fingerprint":"4aa3821a28b0b7c2400bc59aba4bcc0a76e971dadd19610d3ad38c768e124dc7","schema_version":"edge-lab-recorder.raw.v1","sequence":null,"source":"clob_market_ws"}
{"event_at":"2026-07-27T04:31:53.054000Z","event_fingerprint":"4eef56e75faa45a96f28a9c95bfac0a3ffebc1113204bf2009b4a17593c45dcf","payload":{"connection_id":"0f4979d6978d463e9660b042fdcf555f","event_at":"2026-07-27T04:31:53.054000Z","event_type":"price_change","frame_hash":"a5798a58913668ccf98d39e9c09d91f61681db0df79e17a7580cd86fb1640a39","frame_index":0,"kind":"data","monotonic_ns":228696269067875,"payload":{"event_type":"price_change","market":"0xeb66215f2e9faa6449e30a02bab5b8ed7b79a38bf961f6b24d0073c9c2419250","price_changes":[{"asset_id":"60386828328910021732068595344565885737045900010034836345809386672230885527307","best_ask":"0.71","best_bid":"0.7","hash":"4a977ddeaea131f63e2c3efa9447d3c7e06cfccd","price":"0.03","side":"BUY","size":"648.1"},{"asset_id":"69697746896130839564035629862476347944307040470122503199396727085502753297492","best_ask":"0.3","best_bid":"0.29","hash":"f0d88c636f904fc41748b24e5b91eae72f38a6a5","price":"0.97","side":"SELL","size":"648.1"}],"timestamp":"1785126713054"},"payload_hash":"7696ea9fdf3c5dfd169f7806057dcb761250d2606e848e378db8e5b91eba39cf","raw_frame":"{\"market\":\"0xeb66215f2e9faa6449e30a02bab5b8ed7b79a38bf961f6b24d0073c9c2419250\", \"price_changes\":[{\"asset_id\":\"60386828328910021732068595344565885737045900010034836345809386672230885527307\", \"price\":\"0.03\", \"size\":\"648.1\", \"side\":\"BUY\", \"hash\":\"4a977ddeaea131f63e2c3efa9447d3c7e06cfccd\", \"best_bid\":\"0.7\", \"best_ask\":\"0.71\"}, {\"asset_id\":\"69697746896130839564035629862476347944307040470122503199396727085502753297492\", \"price\":\"0.97\", \"size\":\"648.1\", \"side\":\"SELL\", \"hash\":\"f0d88c636f904fc41748b24e5b91eae72f38a6a5\", \"best_bid\":\"0.29\", \"best_ask\":\"0.3\"}], \"timestamp\":\"1785126713054\", \"event_type\":\"price_change\"}","received_at":"2026-07-27T04:31:53.000208Z","schema_version":"clob-market-ws.price_change.v1","sequence":null,"server_hash":null,"server_timestamp":"1785126713054","session_id":"e9443c7415a0419799bee9cfbb1a9e4d","source":"clob_market_ws"},"received_at":"2026-07-27T04:31:53.000208Z","record_id":"86b15d633567c2c94a3a819cf5e1c9ccc0c18865adcd4cdbfe613b389aa1d181","schema_fingerprint":"4aa3821a28b0b7c2400bc59aba4bcc0a76e971dadd19610d3ad38c768e124dc7","schema_version":"edge-lab-recorder.raw.v1","sequence":null,"source":"clob_market_ws"}
{"event_at":"2026-07-27T04:31:53.097000Z","event_fingerprint":"b8f876ec2711ad1bbbb5f841bc05ef295ead32c65ee1a93ff7d7b36cf9f15458","payload":{"connection_id":"0f4979d6978d463e9660b042fdcf555f","event_at":"2026-07-27T04:31:53.097000Z","event_type":"price_change","frame_hash":"400d994be36c1e2510dd20b47e0f054063d58805e344efeb29bd10b90eb7c6ae","frame_index":0,"kind":"data","monotonic_ns":228696309821875,"payload":{"event_type":"price_change","market":"0xeb66215f2e9faa6449e30a02bab5b8ed7b79a38bf961f6b24d0073c9c2419250","price_changes":[{"asset_id":"60386828328910021732068595344565885737045900010034836345809386672230885527307","best_ask":"0.71","best_bid":"0.7","hash":"68c6d4f339ae254b20a687ea386de2efac9972cc","price":"0.55","side":"BUY","size":"311.8"},{"asset_id":"69697746896130839564035629862476347944307040470122503199396727085502753297492","best_ask":"0.3","best_bid":"0.29","hash":"3b52ec26f015981b76b200d1c763391bfb27b3e7","price":"0.45","side":"SELL","size":"311.8"}],"timestamp":"1785126713097"},"payload_hash":"ab1bc15aae8434c571cb3f7a47e91d703391ec71ee6b0e4c6cc4103ff5a25b8a","raw_frame":"{\"market\":\"0xeb66215f2e9faa6449e30a02bab5b8ed7b79a38bf961f6b24d0073c9c2419250\", \"price_changes\":[{\"asset_id\":\"60386828328910021732068595344565885737045900010034836345809386672230885527307\", \"price\":\"0.55\", \"size\":\"311.8\", \"side\":\"BUY\", \"hash\":\"68c6d4f339ae254b20a687ea386de2efac9972cc\", \"best_bid\":\"0.7\", \"best_ask\":\"0.71\"}, {\"asset_id\":\"69697746896130839564035629862476347944307040470122503199396727085502753297492\", \"price\":\"0.45\", \"size\":\"311.8\", \"side\":\"SELL\", \"hash\":\"3b52ec26f015981b76b200d1c763391bfb27b3e7\", \"best_bid\":\"0.29\", \"best_ask\":\"0.3\"}], \"timestamp\":\"1785126713097\", \"event_type\":\"price_change\"}","received_at":"2026-07-27T04:31:53.040970Z","schema_version":"clob-market-ws.price_change.v1","sequence":null,"server_hash":null,"server_timestamp":"1785126713097","session_id":"e9443c7415a0419799bee9cfbb1a9e4d","source":"clob_market_ws"},"received_at":"2026-07-27T04:31:53.040970Z","record_id":"94780129532572bde87ebd588392e873fec060aef411ef64b736c5afab54b0e4","schema_fingerprint":"4aa3821a28b0b7c2400bc59aba4bcc0a76e971dadd19610d3ad38c768e124dc7","schema_version":"edge-lab-recorder.raw.v1","sequence":null,"source":"clob_market_ws"}
{"event_at":"2026-07-27T04:31:53.105000Z","event_fingerprint":"e240a61245da4e643730d7ff7a1146a6977deb757e8faffaa8ac07dd8112acfc","payload":{"connection_id":"0f4979d6978d463e9660b042fdcf555f","event_at":"2026-07-27T04:31:53.105000Z","event_type":"price_change","frame_hash":"a4471c264cb685c6c097f71c1056b1036dea61fe854fa099d78b1082a07eca19","frame_index":0,"kind":"data","monotonic_ns":228696319066625,"payload":{"event_type":"price_change","market":"0xeb66215f2e9faa6449e30a02bab5b8ed7b79a38bf961f6b24d0073c9c2419250","price_changes":[{"asset_id":"60386828328910021732068595344565885737045900010034836345809386672230885527307","best_ask":"0.71","best_bid":"0.7","hash":"374ffd34f7328a297d6bb4a839cbc051e9be172a","price":"0.65","side":"BUY","size":"160.47"},{"asset_id":"69697746896130839564035629862476347944307040470122503199396727085502753297492","best_ask":"0.3","best_bid":"0.29","hash":"17e73cecc21a30b1021696c2eac3f7f29c40d158","price":"0.35","side":"SELL","size":"160.47"}],"timestamp":"1785126713105"},"payload_hash":"ca0cfa95ca2e61debf57dfd20f249544316f9e09451b3a909fc8586d8672686b","raw_frame":"{\"market\":\"0xeb66215f2e9faa6449e30a02bab5b8ed7b79a38bf961f6b24d0073c9c2419250\", \"price_changes\":[{\"asset_id\":\"60386828328910021732068595344565885737045900010034836345809386672230885527307\", \"price\":\"0.65\", \"size\":\"160.47\", \"side\":\"BUY\", \"hash\":\"374ffd34f7328a297d6bb4a839cbc051e9be172a\", \"best_bid\":\"0.7\", \"best_ask\":\"0.71\"}, {\"asset_id\":\"69697746896130839564035629862476347944307040470122503199396727085502753297492\", \"price\":\"0.35\", \"size\":\"160.47\", \"side\":\"SELL\", \"hash\":\"17e73cecc21a30b1021696c2eac3f7f29c40d158\", \"best_bid\":\"0.29\", \"best_ask\":\"0.3\"}], \"timestamp\":\"1785126713105\", \"event_type\":\"price_change\"}","received_at":"2026-07-27T04:31:53.050211Z","schema_version":"clob-market-ws.price_change.v1","sequence":null,"server_hash":null,"server_timestamp":"1785126713105","session_id":"e9443c7415a0419799bee9cfbb1a9e4d","source":"clob_market_ws"},"received_at":"2026-07-27T04:31:53.050211Z","record_id":"59f568e59620ed3e1b1bf8d8834454eae6d2f0b3bf7ae478332eb0eaf9c3422a","schema_fingerprint":"4aa3821a28b0b7c2400bc59aba4bcc0a76e971dadd19610d3ad38c768e124dc7","schema_version":"edge-lab-recorder.raw.v1","sequence":null,"source":"clob_market_ws"}
{"event_at":"2026-07-27T04:31:53.122000Z","event_fingerprint":"f81e6793a17b746c82fa5762fca66e6e71eb88fccbbc2be382594a2e2425e6a3","payload":{"connection_id":"0f4979d6978d463e9660b042fdcf555f","event_at":"2026-07-27T04:31:53.122000Z","event_type":"price_change","frame_hash":"c6e24a4fba86a47224d58cb252f76e1bdb9b06a84f8cf953f93d13da0fdd5169","frame_index":0,"kind":"data","monotonic_ns":228696335717291,"payload":{"event_type":"price_change","market":"0xeb66215f2e9faa6449e30a02bab5b8ed7b79a38bf961f6b24d0073c9c2419250","price_changes":[{"asset_id":"60386828328910021732068595344565885737045900010034836345809386672230885527307","best_ask":"0.71","best_bid":"0.7","hash":"8aecd3cafb88f3afe074758b6df52e7afdce0b94","price":"0.03","side":"BUY","size":"643.1"},{"asset_id":"69697746896130839564035629862476347944307040470122503199396727085502753297492","best_ask":"0.3","best_bid":"0.29","hash":"87e23a0e21aabf607c9759ccb0bb6377ee7ee5bc","price":"0.97","side":"SELL","size":"643.1"}],"timestamp":"1785126713122"},"payload_hash":"a1cc2c77b538f2d3808ac2bc44ae3d40d9ab481422afb22075e652cf2999792f","raw_frame":"{\"market\":\"0xeb66215f2e9faa6449e30a02bab5b8ed7b79a38bf961f6b24d0073c9c2419250\", \"price_changes\":[{\"asset_id\":\"60386828328910021732068595344565885737045900010034836345809386672230885527307\", \"price\":\"0.03\", \"size\":\"643.1\", \"side\":\"BUY\", \"hash\":\"8aecd3cafb88f3afe074758b6df52e7afdce0b94\", \"best_bid\":\"0.7\", \"best_ask\":\"0.71\"}, {\"asset_id\":\"69697746896130839564035629862476347944307040470122503199396727085502753297492\", \"price\":\"0.97\", \"size\":\"643.1\", \"side\":\"SELL\", \"hash\":\"87e23a0e21aabf607c9759ccb0bb6377ee7ee5bc\", \"best_bid\":\"0.29\", \"best_ask\":\"0.3\"}], \"timestamp\":\"1785126713122\", \"event_type\":\"price_change\"}","received_at":"2026-07-27T04:31:53.066852Z","schema_version":"clob-market-ws.price_change.v1","sequence":null,"server_hash":null,"server_timestamp":"1785126713122","session_id":"e9443c7415a0419799bee9cfbb1a9e4d","source":"clob_market_ws"},"received_at":"2026-07-27T04:31:53.066852Z","record_id":"bf933495ce79b73bb2a7f009477360f21a55fb3e49a74a8064b36f905ed2c815","schema_fingerprint":"4aa3821a28b0b7c2400bc59aba4bcc0a76e971dadd19610d3ad38c768e124dc7","schema_version":"edge-lab-recorder.raw.v1","sequence":null,"source":"clob_market_ws"}
{"event_at":"2026-07-27T04:31:53.133000Z","event_fingerprint":"6c4f5d29c61f7fbd8edeae4b659649f42ed629bf6066eae90acd3f00594cc546","payload":{"connection_id":"0f4979d6978d463e9660b042fdcf555f","event_at":"2026-07-27T04:31:53.133000Z","event_type":"price_change","frame_hash":"515880c3f833e5d84a02de8b863b181523d83ab722fa1abdca587ad4192d861f","frame_index":0,"kind":"data","monotonic_ns":228696345793416,"payload":{"event_type":"price_change","market":"0xeb66215f2e9faa6449e30a02bab5b8ed7b79a38bf961f6b24d0073c9c2419250","price_changes":[{"asset_id":"60386828328910021732068595344565885737045900010034836345809386672230885527307","best_ask":"0.71","best_bid":"0.7","hash":"211d2b981f64f4d54cbd586ec04e4404c485a65c","price":"0.56","side":"BUY","size":"222"},{"asset_id":"69697746896130839564035629862476347944307040470122503199396727085502753297492","best_ask":"0.3","best_bid":"0.29","hash":"32247db6c32e0b06ee143bbc3e714a91471f3b19","price":"0.44","side":"SELL","size":"222"}],"timestamp":"1785126713133"},"payload_hash":"1973fe094150687ec1dd531f2f5aad572a6a065f433ef39cbe2e84f524382b3f","raw_frame":"{\"market\":\"0xeb66215f2e9faa6449e30a02bab5b8ed7b79a38bf961f6b24d0073c9c2419250\", \"price_changes\":[{\"asset_id\":\"60386828328910021732068595344565885737045900010034836345809386672230885527307\", \"price\":\"0.56\", \"size\":\"222\", \"side\":\"BUY\", \"hash\":\"211d2b981f64f4d54cbd586ec04e4404c485a65c\", \"best_bid\":\"0.7\", \"best_ask\":\"0.71\"}, {\"asset_id\":\"69697746896130839564035629862476347944307040470122503199396727085502753297492\", \"price\":\"0.44\", \"size\":\"222\", \"side\":\"SELL\", \"hash\":\"32247db6c32e0b06ee143bbc3e714a91471f3b19\", \"best_bid\":\"0.29\", \"best_ask\":\"0.3\"}], \"timestamp\":\"1785126713133\", \"event_type\":\"price_change\"}","received_at":"2026-07-27T04:31:53.076937Z","schema_version":"clob-market-ws.price_change.v1","sequence":null,"server_hash":null,"server_timestamp":"1785126713133","session_id":"e9443c7415a0419799bee9cfbb1a9e4d","source":"clob_market_ws"},"received_at":"2026-07-27T04:31:53.076937Z","record_id":"c8812133e231e538d447ad3ceb07c37a98493049cc59cbe883f86eb0eefc377c","schema_fingerprint":"4aa3821a28b0b7c2400bc59aba4bcc0a76e971dadd19610d3ad38c768e124dc7","schema_version":"edge-lab-recorder.raw.v1","sequence":null,"source":"clob_market_ws"}
{"event_at":"2026-07-27T04:31:53.141000Z","event_fingerprint":"2e3766fedb1483284621db29b38a14a9c647780e08928b57cc8b10f6ba80af61","payload":{"connection_id":"0f4979d6978d463e9660b042fdcf555f","event_at":"2026-07-27T04:31:53.141000Z","event_type":"price_change","frame_hash":"a9d7c7efd3d561669c31d74b14b61bd8446932cc50c91b552ae1a0b5938ba0e3","frame_index":0,"kind":"data","monotonic_ns":228696354076750,"payload":{"event_type":"price_change","market":"0xeb66215f2e9faa6449e30a02bab5b8ed7b79a38bf961f6b24d0073c9c2419250","price_changes":[{"asset_id":"69697746896130839564035629862476347944307040470122503199396727085502753297492","best_ask":"0.3","best_bid":"0.29","hash":"91daefb6165bde298cfa965552ed4706f2896b13","price":"0.31","side":"SELL","size":"426.56"},{"asset_id":"60386828328910021732068595344565885737045900010034836345809386672230885527307","best_ask":"0.71","best_bid":"0.7","hash":"54494886176b9bb7799572c9e352209f00895628","price":"0.69","side":"BUY","size":"426.56"}],"timestamp":"1785126713141"},"payload_hash":"e60ebc06c276cbd1b1cc71979e16a72974623ba6f4395599b7e47d8fa143503a","raw_frame":"{\"market\":\"0xeb66215f2e9faa6449e30a02bab5b8ed7b79a38bf961f6b24d0073c9c2419250\", \"price_changes\":[{\"asset_id\":\"69697746896130839564035629862476347944307040470122503199396727085502753297492\", \"price\":\"0.31\", \"size\":\"426.56\", \"side\":\"SELL\", \"hash\":\"91daefb6165bde298cfa965552ed4706f2896b13\", \"best_bid\":\"0.29\", \"best_ask\":\"0.3\"}, {\"asset_id\":\"60386828328910021732068595344565885737045900010034836345809386672230885527307\", \"price\":\"0.69\", \"size\":\"426.56\", \"side\":\"BUY\", \"hash\":\"54494886176b9bb7799572c9e352209f00895628\", \"best_bid\":\"0.7\", \"best_ask\":\"0.71\"}], \"timestamp\":\"1785126713141\", \"event_type\":\"price_change\"}","received_at":"2026-07-27T04:31:53.085225Z","schema_version":"clob-market-ws.price_change.v1","sequence":null,"server_hash":null,"server_timestamp":"1785126713141","session_id":"e9443c7415a0419799bee9cfbb1a9e4d","source":"clob_market_ws"},"received_at":"2026-07-27T04:31:53.085225Z","record_id":"7f63a3574c93a6f1a20101861d24dfddb4cedf008e7379a285ccf929d339992e","schema_fingerprint":"4aa3821a28b0b7c2400bc59aba4bcc0a76e971dadd19610d3ad38c768e124dc7","schema_version":"edge-lab-recorder.raw.v1","sequence":null,"source":"clob_market_ws"}
{"event_at":"2026-07-27T04:31:53.162000Z","event_fingerprint":"ed47f801c6eaa8b4724e28d53c35e9c8d911aecb08551ac43ab2d3e5c6e00a16","payload":{"connection_id":"0f4979d6978d463e9660b042fdcf555f","event_at":"2026-07-27T04:31:53.162000Z","event_type":"price_change","frame_hash":"2f7f4b088bd100c303c535383745576fe22cba8850c90df5b266c13ee07ae03b","frame_index":0,"kind":"data","monotonic_ns":228696376193125,"payload":{"event_type":"price_change","market":"0xeb66215f2e9faa6449e30a02bab5b8ed7b79a38bf961f6b24d0073c9c2419250","price_changes":[{"asset_id":"69697746896130839564035629862476347944307040470122503199396727085502753297492","best_ask":"0.3","best_bid":"0.29","hash":"2c873b50d7c74fa97a93f2827f53c9ff11a40f63","price":"0.01","side":"BUY","size":"7919.91"},{"asset_id":"60386828328910021732068595344565885737045900010034836345809386672230885527307","best_ask":"0.71","best_bid":"0.7","hash":"eda9adc05f37890eee97758ec8516fd6c2962ed6","price":"0.99","side":"SELL","size":"7919.91"}],"timestamp":"1785126713162"},"payload_hash":"d66484a6d76aeb4f54b320fdc833abdf47f59feaa05a1ec8298d8fb1597baf06","raw_frame":"{\"market\":\"0xeb66215f2e9faa6449e30a02bab5b8ed7b79a38bf961f6b24d0073c9c2419250\", \"price_changes\":[{\"asset_id\":\"69697746896130839564035629862476347944307040470122503199396727085502753297492\", \"price\":\"0.01\", \"size\":\"7919.91\", \"side\":\"BUY\", \"hash\":\"2c873b50d7c74fa97a93f2827f53c9ff11a40f63\", \"best_bid\":\"0.29\", \"best_ask\":\"0.3\"}, {\"asset_id\":\"60386828328910021732068595344565885737045900010034836345809386672230885527307\", \"price\":\"0.99\", \"size\":\"7919.91\", \"side\":\"SELL\", \"hash\":\"eda9adc05f37890eee97758ec8516fd6c2962ed6\", \"best_bid\":\"0.7\", \"best_ask\":\"0.71\"}], \"timestamp\":\"1785126713162\", \"event_type\":\"price_change\"}","received_at":"2026-07-27T04:31:53.107341Z","schema_version":"clob-market-ws.price_change.v1","sequence":null,"server_hash":null,"server_timestamp":"1785126713162","session_id":"e9443c7415a0419799bee9cfbb1a9e4d","source":"clob_market_ws"},"received_at":"2026-07-27T04:31:53.107341Z","record_id":"aba9ebf0f063b214c1ba61e57b9995e5fa88aeb9bf054969eb2ed4511ba21dcc","schema_fingerprint":"4aa3821a28b0b7c2400bc59aba4bcc0a76e971dadd19610d3ad38c768e124dc7","schema_version":"edge-lab-recorder.raw.v1","sequence":null,"source":"clob_market_ws"}
{"event_at":"2026-07-27T04:31:53.180000Z","event_fingerprint":"341d7ab0ce5ff6aedbc1ff4bc09f314cdd19d6b82b0bf68e56be7dc23d3e4fad","payload":{"connection_id":"0f4979d6978d463e9660b042fdcf555f","event_at":"2026-07-27T04:31:53.180000Z","event_type":"price_change","frame_hash":"5be9e0af10b02e84ecee6b7984dceb9649b8c236d7f8a4feace7ee15576449f1","frame_index":0,"kind":"data","monotonic_ns":228696393734541,"payload":{"event_type":"price_change","market":"0xeb66215f2e9faa6449e30a02bab5b8ed7b79a38bf961f6b24d0073c9c2419250","price_changes":[{"asset_id":"60386828328910021732068595344565885737045900010034836345809386672230885527307","best_ask":"0.71","best_bid":"0.7","hash":"df68a24874b49c444e9239880e39e389c0b01b84","price":"0.65","side":"BUY","size":"260.47"},{"asset_id":"69697746896130839564035629862476347944307040470122503199396727085502753297492","best_ask":"0.3","best_bid":"0.29","hash":"76188f69ec952a91d180760d2bbbdef083da251a","price":"0.35","side":"SELL","size":"260.47"}],"timestamp":"1785126713180"},"payload_hash":"7ac1aff563b947789aef58ce4e0f6038341e0e10ab19d6e7374a8d43be10a0c7","raw_frame":"{\"market\":\"0xeb66215f2e9faa6449e30a02bab5b8ed7b79a38bf961f6b24d0073c9c2419250\", \"price_changes\":[{\"asset_id\":\"60386828328910021732068595344565885737045900010034836345809386672230885527307\", \"price\":\"0.65\", \"size\":\"260.47\", \"side\":\"BUY\", \"hash\":\"df68a24874b49c444e9239880e39e389c0b01b84\", \"best_bid\":\"0.7\", \"best_ask\":\"0.71\"}, {\"asset_id\":\"69697746896130839564035629862476347944307040470122503199396727085502753297492\", \"price\":\"0.35\", \"size\":\"260.47\", \"side\":\"SELL\", \"hash\":\"76188f69ec952a91d180760d2bbbdef083da251a\", \"best_bid\":\"0.29\", \"best_ask\":\"0.3\"}], \"timestamp\":\"1785126713180\", \"event_type\":\"price_change\"}","received_at":"2026-07-27T04:31:53.124871Z","schema_version":"clob-market-ws.price_change.v1","sequence":null,"server_hash":null,"server_timestamp":"1785126713180","session_id":"e9443c7415a0419799bee9cfbb1a9e4d","source":"clob_market_ws"},"received_at":"2026-07-27T04:31:53.124871Z","record_id":"5a1559d83f06ff4728ca623378b50c64cf54f2836dbb8e620ea86dd4a14355a1","schema_fingerprint":"4aa3821a28b0b7c2400bc59aba4bcc0a76e971dadd19610d3ad38c768e124dc7","schema_version":"edge-lab-recorder.raw.v1","sequence":null,"source":"clob_market_ws"}
{"event_at":"2026-07-27T04:31:53.205000Z","event_fingerprint":"411bfcce9213d22cad2b5b79c21733929b06c4c2a4070e430c588a11fd9968c0","payload":{"connection_id":"0f4979d6978d463e9660b042fdcf555f","event_at":"2026-07-27T04:31:53.205000Z","event_type":"price_change","frame_hash":"ec49be153e9243760aa7a740c892eb156606eda730ca8cf9a1680168591c6af2","frame_index":0,"kind":"data","monotonic_ns":228696420799250,"payload":{"event_type":"price_change","market":"0xeb66215f2e9faa6449e30a02bab5b8ed7b79a38bf961f6b24d0073c9c2419250","price_changes":[{"asset_id":"60386828328910021732068595344565885737045900010034836345809386672230885527307","best_ask":"0.71","best_bid":"0.7","hash":"10cc40a968bbc7ac67d17c66a33c0b8ba12b9d33","price":"0.02","side":"BUY","size":"738.1"},{"asset_id":"69697746896130839564035629862476347944307040470122503199396727085502753297492","best_ask":"0.3","best_bid":"0.29","hash":"6a99139e428a5674b284711acad6f7bb276af1d7","price":"0.98","side":"SELL","size":"738.1"}],"timestamp":"1785126713205"},"payload_hash":"dc5634113f2f98b37c8377a8bdcd9a3e3a6055ca3be42840ab20e05e7dab3990","raw_frame":"{\"market\":\"0xeb66215f2e9faa6449e30a02bab5b8ed7b79a38bf961f6b24d0073c9c2419250\", \"price_changes\":[{\"asset_id\":\"60386828328910021732068595344565885737045900010034836345809386672230885527307\", \"price\":\"0.02\", \"size\":\"738.1\", \"side\":\"BUY\", \"hash\":\"10cc40a968bbc7ac67d17c66a33c0b8ba12b9d33\", \"best_bid\":\"0.7\", \"best_ask\":\"0.71\"}, {\"asset_id\":\"69697746896130839564035629862476347944307040470122503199396727085502753297492\", \"price\":\"0.98\", \"size\":\"738.1\", \"side\":\"SELL\", \"hash\":\"6a99139e428a5674b284711acad6f7bb276af1d7\", \"best_bid\":\"0.29\", \"best_ask\":\"0.3\"}], \"timestamp\":\"1785126713205\", \"event_type\":\"price_change\"}","received_at":"2026-07-27T04:31:53.151942Z","schema_version":"clob-market-ws.price_change.v1","sequence":null,"server_hash":null,"server_timestamp":"1785126713205","session_id":"e9443c7415a0419799bee9cfbb1a9e4d","source":"clob_market_ws"},"received_at":"2026-07-27T04:31:53.151942Z","record_id":"64c54989cd6619e57b55b9c20a37ca2ff74e9a40db06a3899d2e8e6d67a6a7e0","schema_fingerprint":"4aa3821a28b0b7c2400bc59aba4bcc0a76e971dadd19610d3ad38c768e124dc7","schema_version":"edge-lab-recorder.raw.v1","sequence":null,"source":"clob_market_ws"}
{"event_at":"2026-07-27T04:31:53.245000Z","event_fingerprint":"65904d2a29703eb9e85bd0d69f5369246f99627ef19937a61953efe512f90877","payload":{"connection_id":"0f4979d6978d463e9660b042fdcf555f","event_at":"2026-07-27T04:31:53.245000Z","event_type":"price_change","frame_hash":"e38120ea881520aad5e5b8d68de7f3f3e9ba8bbcb95c15d7930a9a04152a9327","frame_index":0,"kind":"data","monotonic_ns":228696458366083,"payload":{"event_type":"price_change","market":"0xeb66215f2e9faa6449e30a02bab5b8ed7b79a38bf961f6b24d0073c9c2419250","price_changes":[{"asset_id":"69697746896130839564035629862476347944307040470122503199396727085502753297492","best_ask":"0.3","best_bid":"0.29","hash":"88ecbaf3c23931e62dc976c8a32f5c570b894bba","price":"0.31","side":"SELL","size":"431.6"},{"asset_id":"60386828328910021732068595344565885737045900010034836345809386672230885527307","best_ask":"0.71","best_bid":"0.7","hash":"5b89d36f45b755cbdc6f0b4ad882ecdf17d4cb74","price":"0.69","side":"BUY","size":"431.6"}],"timestamp":"1785126713245"},"payload_hash":"43e3b44e103839c125c48cc800658e802bf7b453ce6112f463408822210ef07e","raw_frame":"{\"market\":\"0xeb66215f2e9faa6449e30a02bab5b8ed7b79a38bf961f6b24d0073c9c2419250\", \"price_changes\":[{\"asset_id\":\"69697746896130839564035629862476347944307040470122503199396727085502753297492\", \"price\":\"0.31\", \"size\":\"431.6\", \"side\":\"SELL\", \"hash\":\"88ecbaf3c23931e62dc976c8a32f5c570b894bba\", \"best_bid\":\"0.29\", \"best_ask\":\"0.3\"}, {\"asset_id\":\"60386828328910021732068595344565885737045900010034836345809386672230885527307\", \"price\":\"0.69\", \"size\":\"431.6\", \"side\":\"BUY\", \"hash\":\"5b89d36f45b755cbdc6f0b4ad882ecdf17d4cb74\", \"best_bid\":\"0.7\", \"best_ask\":\"0.71\"}], \"timestamp\":\"1785126713245\", \"event_type\":\"price_change\"}","received_at":"2026-07-27T04:31:53.189506Z","schema_version":"clob-market-ws.price_change.v1","sequence":null,"server_hash":null,"server_timestamp":"1785126713245","session_id":"e9443c7415a0419799bee9cfbb1a9e4d","source":"clob_market_ws"},"received_at":"2026-07-27T04:31:53.189506Z","record_id":"fcb66c09d800f9e81f327a8d12848acdc740e8e018841b11888fa0d1b031abca","schema_fingerprint":"4aa3821a28b0b7c2400bc59aba4bcc0a76e971dadd19610d3ad38c768e124dc7","schema_version":"edge-lab-recorder.raw.v1","sequence":null,"source":"clob_market_ws"}
{"event_at":"2026-07-27T04:31:53.252000Z","event_fingerprint":"e21622a19c838435dbb62df9c87d6dedf097b35f310714cc5d4eb3be3a6a6bd5","payload":{"connection_id":"0f4979d6978d463e9660b042fdcf555f","event_at":"2026-07-27T04:31:53.252000Z","event_type":"price_change","frame_hash":"fdcfc177b1a7049f11985a4b5dcfc76c03f5ab7718b5b4a75c44f07c81154328","frame_index":0,"kind":"data","monotonic_ns":228696465755208,"payload":{"event_type":"price_change","market":"0xeb66215f2e9faa6449e30a02bab5b8ed7b79a38bf961f6b24d0073c9c2419250","price_changes":[{"asset_id":"60386828328910021732068595344565885737045900010034836345809386672230885527307","best_ask":"0.71","best_bid":"0.7","hash":"dff83d4238e0eec5f39655084fef057f1dd958ee","price":"0.01","side":"BUY","size":"7708.02"},{"asset_id":"69697746896130839564035629862476347944307040470122503199396727085502753297492","best_ask":"0.3","best_bid":"0.29","hash":"073c823232702ec018d66d10b2e344cf8ef98695","price":"0.99","side":"SELL","size":"7708.02"}],"timestamp":"1785126713252"},"payload_hash":"2a3cc58851eefc29b9cfe7626476af6df56231d9356bd42cbe46528d91a2fc68","raw_frame":"{\"market\":\"0xeb66215f2e9faa6449e30a02bab5b8ed7b79a38bf961f6b24d0073c9c2419250\", \"price_changes\":[{\"asset_id\":\"60386828328910021732068595344565885737045900010034836345809386672230885527307\", \"price\":\"0.01\", \"size\":\"7708.02\", \"side\":\"BUY\", \"hash\":\"dff83d4238e0eec5f39655084fef057f1dd958ee\", \"best_bid\":\"0.7\", \"best_ask\":\"0.71\"}, {\"asset_id\":\"69697746896130839564035629862476347944307040470122503199396727085502753297492\", \"price\":\"0.99\", \"size\":\"7708.02\", \"side\":\"SELL\", \"hash\":\"073c823232702ec018d66d10b2e344cf8ef98695\", \"best_bid\":\"0.29\", \"best_ask\":\"0.3\"}], \"timestamp\":\"1785126713252\", \"event_type\":\"price_change\"}","received_at":"2026-07-27T04:31:53.196895Z","schema_version":"clob-market-ws.price_change.v1","sequence":null,"server_hash":null,"server_timestamp":"1785126713252","session_id":"e9443c7415a0419799bee9cfbb1a9e4d","source":"clob_market_ws"},"received_at":"2026-07-27T04:31:53.196895Z","record_id":"38b9ef199cd755f17a066180ad029932905ff316b64685e8c0e4dce46bcd8156","schema_fingerprint":"4aa3821a28b0b7c2400bc59aba4bcc0a76e971dadd19610d3ad38c768e124dc7","schema_version":"edge-lab-recorder.raw.v1","sequence":null,"source":"clob_market_ws"}
{"event_at":"2026-07-27T04:31:53.266000Z","event_fingerprint":"b70e32299b914984556e0e9f7776cc1edee5de3da5f695058302d671840365f9","payload":{"connection_id":"0f4979d6978d463e9660b042fdcf555f","event_at":"2026-07-27T04:31:53.266000Z","event_type":"price_change","frame_hash":"cf5cd831bec70cd3ff14d6a4cf009a06b79868373356fedddd941b56ba7e71d6","frame_index":0,"kind":"data","monotonic_ns":228696482190041,"payload":{"event_type":"price_change","market":"0xeb66215f2e9faa6449e30a02bab5b8ed7b79a38bf961f6b24d0073c9c2419250","price_changes":[{"asset_id":"60386828328910021732068595344565885737045900010034836345809386672230885527307","best_ask":"0.71","best_bid":"0.7","hash":"9ecbf2edb55d43a8c7cc52dd2ba89f76ceb094ad","price":"0.01","side":"BUY","size":"7713.02"},{"asset_id":"69697746896130839564035629862476347944307040470122503199396727085502753297492","best_ask":"0.3","best_bid":"0.29","hash":"d6940353d27010ed2dfae1116c2d70e0512ef31d","price":"0.99","side":"SELL","size":"7713.02"}],"timestamp":"1785126713266"},"payload_hash":"6c8cf1779e71345758c6ad49bcaab293b51a6308784c43a47012363c646b407e","raw_frame":"{\"market\":\"0xeb66215f2e9faa6449e30a02bab5b8ed7b79a38bf961f6b24d0073c9c2419250\", \"price_changes\":[{\"asset_id\":\"60386828328910021732068595344565885737045900010034836345809386672230885527307\", \"price\":\"0.01\", \"size\":\"7713.02\", \"side\":\"BUY\", \"hash\":\"9ecbf2edb55d43a8c7cc52dd2ba89f76ceb094ad\", \"best_bid\":\"0.7\", \"best_ask\":\"0.71\"}, {\"asset_id\":\"69697746896130839564035629862476347944307040470122503199396727085502753297492\", \"price\":\"0.99\", \"size\":\"7713.02\", \"side\":\"SELL\", \"hash\":\"d6940353d27010ed2dfae1116c2d70e0512ef31d\", \"best_bid\":\"0.29\", \"best_ask\":\"0.3\"}], \"timestamp\":\"1785126713266\", \"event_type\":\"price_change\"}","received_at":"2026-07-27T04:31:53.213332Z","schema_version":"clob-market-ws.price_change.v1","sequence":null,"server_hash":null,"server_timestamp":"1785126713266","session_id":"e9443c7415a0419799bee9cfbb1a9e4d","source":"clob_market_ws"},"received_at":"2026-07-27T04:31:53.213332Z","record_id":"f83a352fe3afed788c5f92511d54cbe6e27a90ac45a8468a6db8b1b07b062341","schema_fingerprint":"4aa3821a28b0b7c2400bc59aba4bcc0a76e971dadd19610d3ad38c768e124dc7","schema_version":"edge-lab-recorder.raw.v1","sequence":null,"source":"clob_market_ws"}
{"event_at":"2026-07-27T04:31:53.270000Z","event_fingerprint":"3080b8f70a98aa9ba078de3ed280d00c4aa176214f291f28fdcac88cf612d1e5","payload":{"connection_id":"0f4979d6978d463e9660b042fdcf555f","event_at":"2026-07-27T04:31:53.270000Z","event_type":"price_change","frame_hash":"f4bec0b2c7c735d8709618fa1cb521b9ef6d7637c0abd9c86899ed1eaa413981","frame_index":0,"kind":"data","monotonic_ns":228696483729916,"payload":{"event_type":"price_change","market":"0xeb66215f2e9faa6449e30a02bab5b8ed7b79a38bf961f6b24d0073c9c2419250","price_changes":[{"asset_id":"60386828328910021732068595344565885737045900010034836345809386672230885527307","best_ask":"0.71","best_bid":"0.7","hash":"a23888125620560e9c3d902d7a2c83b7bda925ad","price":"0.02","side":"BUY","size":"733.1"},{"asset_id":"69697746896130839564035629862476347944307040470122503199396727085502753297492","best_ask":"0.3","best_bid":"0.29","hash":"816c74e82bb7bacf5eee0aa4b2ab21b09fe279dd","price":"0.98","side":"SELL","size":"733.1"}],"timestamp":"1785126713270"},"payload_hash":"5656a9a857446465786f0b566ee9adf5e62b550e80c631807d99045a71a67562","raw_frame":"{\"market\":\"0xeb66215f2e9faa6449e30a02bab5b8ed7b79a38bf961f6b24d0073c9c2419250\", \"price_changes\":[{\"asset_id\":\"60386828328910021732068595344565885737045900010034836345809386672230885527307\", \"price\":\"0.02\", \"size\":\"733.1\", \"side\":\"BUY\", \"hash\":\"a23888125620560e9c3d902d7a2c83b7bda925ad\", \"best_bid\":\"0.7\", \"best_ask\":\"0.71\"}, {\"asset_id\":\"69697746896130839564035629862476347944307040470122503199396727085502753297492\", \"price\":\"0.98\", \"size\":\"733.1\", \"side\":\"SELL\", \"hash\":\"816c74e82bb7bacf5eee0aa4b2ab21b09fe279dd\", \"best_bid\":\"0.29\", \"best_ask\":\"0.3\"}], \"timestamp\":\"1785126713270\", \"event_type\":\"price_change\"}","received_at":"2026-07-27T04:31:53.214874Z","schema_version":"clob-market-ws.price_change.v1","sequence":null,"server_hash":null,"server_timestamp":"1785126713270","session_id":"e9443c7415a0419799bee9cfbb1a9e4d","source":"clob_market_ws"},"received_at":"2026-07-27T04:31:53.214874Z","record_id":"eae795bc43e83ecc0b50bcdd51fdbc54544cc1f72d4fd66cc317626537117b7d","schema_fingerprint":"4aa3821a28b0b7c2400bc59aba4bcc0a76e971dadd19610d3ad38c768e124dc7","schema_version":"edge-lab-recorder.raw.v1","sequence":null,"source":"clob_market_ws"}
{"event_at":"2026-07-27T04:31:53.273000Z","event_fingerprint":"31de7e73b38cfe1b5045098bc3a38a7f7975e4d5a0fdcc133170176566bbe1c8","payload":{"connection_id":"0f4979d6978d463e9660b042fdcf555f","event_at":"2026-07-27T04:31:53.273000Z","event_type":"price_change","frame_hash":"e2f26b03785139a06930403be86c6af605abf7114bd1ba71aa899dc359587c49","frame_index":0,"kind":"data","monotonic_ns":228696486259000,"payload":{"event_type":"price_change","market":"0xeb66215f2e9faa6449e30a02bab5b8ed7b79a38bf961f6b24d0073c9c2419250","price_changes":[{"asset_id":"60386828328910021732068595344565885737045900010034836345809386672230885527307","best_ask":"0.71","best_bid":"0.7","hash":"585587f0b62d8296bcbecc010a3f914e18a769ac","price":"0.01","side":"BUY","size":"7708.02"},{"asset_id":"69697746896130839564035629862476347944307040470122503199396727085502753297492","best_ask":"0.3","best_bid":"0.29","hash":"cd39132ab618222b395ba6eb7bd079b0e480a59f","price":"0.99","side":"SELL","size":"7708.02"}],"timestamp":"1785126713273"},"payload_hash":"b7277837da246c7276242b3ba4e11ff28fabab061c4c362fa9ead6a0c87a0165","raw_frame":"{\"market\":\"0xeb66215f2e9faa6449e30a02bab5b8ed7b79a38bf961f6b24d0073c9c2419250\", \"price_changes\":[{\"asset_id\":\"60386828328910021732068595344565885737045900010034836345809386672230885527307\", \"price\":\"0.01\", \"size\":\"7708.02\", \"side\":\"BUY\", \"hash\":\"585587f0b62d8296bcbecc010a3f914e18a769ac\", \"best_bid\":\"0.7\", \"best_ask\":\"0.71\"}, {\"asset_id\":\"69697746896130839564035629862476347944307040470122503199396727085502753297492\", \"price\":\"0.99\", \"size\":\"7708.02\", \"side\":\"SELL\", \"hash\":\"cd39132ab618222b395ba6eb7bd079b0e480a59f\", \"best_bid\":\"0.29\", \"best_ask\":\"0.3\"}], \"timestamp\":\"1785126713273\", \"event_type\":\"price_change\"}","received_at":"2026-07-27T04:31:53.217403Z","schema_version":"clob-market-ws.price_change.v1","sequence":null,"server_hash":null,"server_timestamp":"1785126713273","session_id":"e9443c7415a0419799bee9cfbb1a9e4d","source":"clob_market_ws"},"received_at":"2026-07-27T04:31:53.217403Z","record_id":"e364dfcb062a7f27b94406bed3e5dc471e7ecd7be70f850e296b15a2357e2872","schema_fingerprint":"4aa3821a28b0b7c2400bc59aba4bcc0a76e971dadd19610d3ad38c768e124dc7","schema_version":"edge-lab-recorder.raw.v1","sequence":null,"source":"clob_market_ws"}
{"event_at":"2026-07-27T04:31:53.297000Z","event_fingerprint":"aaea349c4b48981109c3df26687cc8bc7b8478ab0e0b25d8aa159f3b312361c9","payload":{"connection_id":"0f4979d6978d463e9660b042fdcf555f","event_at":"2026-07-27T04:31:53.297000Z","event_type":"price_change","frame_hash":"620cacfce7a4cb3d55e073b3a2b154cefa82855c86fcc97a5b0e673e9cd591e8","frame_index":0,"kind":"data","monotonic_ns":228696509858791,"payload":{"event_type":"price_change","market":"0xeb66215f2e9faa6449e30a02bab5b8ed7b79a38bf961f6b24d0073c9c2419250","price_changes":[{"asset_id":"60386828328910021732068595344565885737045900010034836345809386672230885527307","best_ask":"0.71","best_bid":"0.7","hash":"9ec67c0a7e1811a0f4fd73a7c2fcb11c0ccf2c7f","price":"0.01","side":"BUY","size":"7703.02"},{"asset_id":"69697746896130839564035629862476347944307040470122503199396727085502753297492","best_ask":"0.3","best_bid":"0.29","hash":"5be82921d72e2989ad7527d9f9c4f14fcee9028f","price":"0.99","side":"SELL","size":"7703.02"}],"timestamp":"1785126713297"},"payload_hash":"24a592e16c11371373207c0a00f91fcedd9e9e438bc0df4e6d1a9962d6f307cf","raw_frame":"{\"market\":\"0xeb66215f2e9faa6449e30a02bab5b8ed7b79a38bf961f6b24d0073c9c2419250\", \"price_changes\":[{\"asset_id\":\"60386828328910021732068595344565885737045900010034836345809386672230885527307\", \"price\":\"0.01\", \"size\":\"7703.02\", \"side\":\"BUY\", \"hash\":\"9ec67c0a7e1811a0f4fd73a7c2fcb11c0ccf2c7f\", \"best_bid\":\"0.7\", \"best_ask\":\"0.71\"}, {\"asset_id\":\"69697746896130839564035629862476347944307040470122503199396727085502753297492\", \"price\":\"0.99\", \"size\":\"7703.02\", \"side\":\"SELL\", \"hash\":\"5be82921d72e2989ad7527d9f9c4f14fcee9028f\", \"best_bid\":\"0.29\", \"best_ask\":\"0.3\"}], \"timestamp\":\"1785126713297\", \"event_type\":\"price_change\"}","received_at":"2026-07-27T04:31:53.240999Z","schema_version":"clob-market-ws.price_change.v1","sequence":null,"server_hash":null,"server_timestamp":"1785126713297","session_id":"e9443c7415a0419799bee9cfbb1a9e4d","source":"clob_market_ws"},"received_at":"2026-07-27T04:31:53.240999Z","record_id":"6346fe2e2ef502959dca008ca7a3a784340d93b49247a7696b337b546cb279ce","schema_fingerprint":"4aa3821a28b0b7c2400bc59aba4bcc0a76e971dadd19610d3ad38c768e124dc7","schema_version":"edge-lab-recorder.raw.v1","sequence":null,"source":"clob_market_ws"}
{"event_at":"2026-07-27T04:31:53.343000Z","event_fingerprint":"e731978da822d7b76a189deeb1bfb4efeece64e9e5892b498d8e12a1f5f0eb8e","payload":{"connection_id":"0f4979d6978d463e9660b042fdcf555f","event_at":"2026-07-27T04:31:53.343000Z","event_type":"price_change","frame_hash":"d159130ac98747793c5da2b331a38804ea50daefac2940cf571c83c3dd2e9527","frame_index":0,"kind":"data","monotonic_ns":228696558590625,"payload":{"event_type":"price_change","market":"0xeb66215f2e9faa6449e30a02bab5b8ed7b79a38bf961f6b24d0073c9c2419250","price_changes":[{"asset_id":"60386828328910021732068595344565885737045900010034836345809386672230885527307","best_ask":"0.71","best_bid":"0.7","hash":"473f7a038a89565732c737cd5c106176a38ca970","price":"0.56","side":"BUY","size":"165"},{"asset_id":"69697746896130839564035629862476347944307040470122503199396727085502753297492","best_ask":"0.3","best_bid":"0.29","hash":"9255f20529b7cec268cbb288745b34892db7a947","price":"0.44","side":"SELL","size":"165"}],"timestamp":"1785126713343"},"payload_hash":"871dd89f5ac61ed5ada43a5a9e10223777fb0fd9af0b9c1364b9ca613d33f684","raw_frame":"{\"market\":\"0xeb66215f2e9faa6449e30a02bab5b8ed7b79a38bf961f6b24d0073c9c2419250\", \"price_changes\":[{\"asset_id\":\"60386828328910021732068595344565885737045900010034836345809386672230885527307\", \"price\":\"0.56\", \"size\":\"165\", \"side\":\"BUY\", \"hash\":\"473f7a038a89565732c737cd5c106176a38ca970\", \"best_bid\":\"0.7\", \"best_ask\":\"0.71\"}, {\"asset_id\":\"69697746896130839564035629862476347944307040470122503199396727085502753297492\", \"price\":\"0.44\", \"size\":\"165\", \"side\":\"SELL\", \"hash\":\"9255f20529b7cec268cbb288745b34892db7a947\", \"best_bid\":\"0.29\", \"best_ask\":\"0.3\"}], \"timestamp\":\"1785126713343\", \"event_type\":\"price_change\"}","received_at":"2026-07-27T04:31:53.289735Z","schema_version":"clob-market-ws.price_change.v1","sequence":null,"server_hash":null,"server_timestamp":"1785126713343","session_id":"e9443c7415a0419799bee9cfbb1a9e4d","source":"clob_market_ws"},"received_at":"2026-07-27T04:31:53.289735Z","record_id":"d9cce3f225637dafb6dc8e529340aa3d9b96cf92cbd529485d725b65ec658feb","schema_fingerprint":"4aa3821a28b0b7c2400bc59aba4bcc0a76e971dadd19610d3ad38c768e124dc7","schema_version":"edge-lab-recorder.raw.v1","sequence":null,"source":"clob_market_ws"}
{"event_at":"2026-07-27T04:31:53.344000Z","event_fingerprint":"64edaf483d7c61c5212fec5eb30fc128a68ba8a5a7a317bca5dc3c897932ce1b","payload":{"connection_id":"0f4979d6978d463e9660b042fdcf555f","event_at":"2026-07-27T04:31:53.344000Z","event_type":"price_change","frame_hash":"1bc5bce458b992f43ca58dd73a8b13688478ed5771d6242cb951c2e2c81a6754","frame_index":0,"kind":"data","monotonic_ns":228696561159000,"payload":{"event_type":"price_change","market":"0xeb66215f2e9faa6449e30a02bab5b8ed7b79a38bf961f6b24d0073c9c2419250","price_changes":[{"asset_id":"69697746896130839564035629862476347944307040470122503199396727085502753297492","best_ask":"0.3","best_bid":"0.29","hash":"67db33bc377fab633f46c52f015f780b93615a95","price":"0.31","side":"SELL","size":"426.56"},{"asset_id":"60386828328910021732068595344565885737045900010034836345809386672230885527307","best_ask":"0.71","best_bid":"0.7","hash":"0f8ff42a206591eeaeaf06ea59dbb1e6692ef7e1","price":"0.69","side":"BUY","size":"426.56"}],"timestamp":"1785126713344"},"payload_hash":"a2e5d9f54c4024ace478b89610ad4bc50e96dd5279549a443b152ac68fe40ba1","raw_frame":"{\"market\":\"0xeb66215f2e9faa6449e30a02bab5b8ed7b79a38bf961f6b24d0073c9c2419250\", \"price_changes\":[{\"asset_id\":\"69697746896130839564035629862476347944307040470122503199396727085502753297492\", \"price\":\"0.31\", \"size\":\"426.56\", \"side\":\"SELL\", \"hash\":\"67db33bc377fab633f46c52f015f780b93615a95\", \"best_bid\":\"0.29\", \"best_ask\":\"0.3\"}, {\"asset_id\":\"60386828328910021732068595344565885737045900010034836345809386672230885527307\", \"price\":\"0.69\", \"size\":\"426.56\", \"side\":\"BUY\", \"hash\":\"0f8ff42a206591eeaeaf06ea59dbb1e6692ef7e1\", \"best_bid\":\"0.7\", \"best_ask\":\"0.71\"}], \"timestamp\":\"1785126713344\", \"event_type\":\"price_change\"}","received_at":"2026-07-27T04:31:53.292303Z","schema_version":"clob-market-ws.price_change.v1","sequence":null,"server_hash":null,"server_timestamp":"1785126713344","session_id":"e9443c7415a0419799bee9cfbb1a9e4d","source":"clob_market_ws"},"received_at":"2026-07-27T04:31:53.292303Z","record_id":"7a9829a5ecc912d243bb8d0653ad0427142bfb7fc1480fa33072992e08e0fd0a","schema_fingerprint":"4aa3821a28b0b7c2400bc59aba4bcc0a76e971dadd19610d3ad38c768e124dc7","schema_version":"edge-lab-recorder.raw.v1","sequence":null,"source":"clob_market_ws"}
{"event_at":"2026-07-27T04:31:53.369000Z","event_fingerprint":"cf0ff085399c5d7f00ebc529f32ac35a0236a0cef2e9988b90aef74ea411f583","payload":{"connection_id":"0f4979d6978d463e9660b042fdcf555f","event_at":"2026-07-27T04:31:53.369000Z","event_type":"price_change","frame_hash":"c19404bc4151f5dd67be1f2a28469e80c042f1d7ebab64297979f6a8e38faecf","frame_index":0,"kind":"data","monotonic_ns":228696583806083,"payload":{"event_type":"price_change","market":"0xeb66215f2e9faa6449e30a02bab5b8ed7b79a38bf961f6b24d0073c9c2419250","price_changes":[{"asset_id":"60386828328910021732068595344565885737045900010034836345809386672230885527307","best_ask":"0.71","best_bid":"0.7","hash":"1b39331423ae5ab7e73be4d38f6e2fbcb58209b0","price":"0.01","side":"BUY","size":"7708.02"},{"asset_id":"69697746896130839564035629862476347944307040470122503199396727085502753297492","best_ask":"0.3","best_bid":"0.29","hash":"8c42b1748e1ef180b6dfb3222a71a031fcfe64a1","price":"0.99","side":"SELL","size":"7708.02"}],"timestamp":"1785126713369"},"payload_hash":"8885a0231b8a9c68338d5e08237f9c63053d4b44b6ef1ae837001da4e57ec47a","raw_frame":"{\"market\":\"0xeb66215f2e9faa6449e30a02bab5b8ed7b79a38bf961f6b24d0073c9c2419250\", \"price_changes\":[{\"asset_id\":\"60386828328910021732068595344565885737045900010034836345809386672230885527307\", \"price\":\"0.01\", \"size\":\"7708.02\", \"side\":\"BUY\", \"hash\":\"1b39331423ae5ab7e73be4d38f6e2fbcb58209b0\", \"best_bid\":\"0.7\", \"best_ask\":\"0.71\"}, {\"asset_id\":\"69697746896130839564035629862476347944307040470122503199396727085502753297492\", \"price\":\"0.99\", \"size\":\"7708.02\", \"side\":\"SELL\", \"hash\":\"8c42b1748e1ef180b6dfb3222a71a031fcfe64a1\", \"best_bid\":\"0.29\", \"best_ask\":\"0.3\"}], \"timestamp\":\"1785126713369\", \"event_type\":\"price_change\"}","received_at":"2026-07-27T04:31:53.314950Z","schema_version":"clob-market-ws.price_change.v1","sequence":null,"server_hash":null,"server_timestamp":"1785126713369","session_id":"e9443c7415a0419799bee9cfbb1a9e4d","source":"clob_market_ws"},"received_at":"2026-07-27T04:31:53.314950Z","record_id":"60a94e2561116aba084dfe39974e01ec83c82f6fb763feca5b1cccb37fc6ae9c","schema_fingerprint":"4aa3821a28b0b7c2400bc59aba4bcc0a76e971dadd19610d3ad38c768e124dc7","schema_version":"edge-lab-recorder.raw.v1","sequence":null,"source":"clob_market_ws"}
{"event_at":"2026-07-27T04:31:53.448000Z","event_fingerprint":"aa5c0d39a8a1ddb0efb0a8cb4e60a106f75753968538564d84b467353c7a2814","payload":{"connection_id":"0f4979d6978d463e9660b042fdcf555f","event_at":"2026-07-27T04:31:53.448000Z","event_type":"price_change","frame_hash":"1ecf0b585576ddd70e54a1ac05a9a6b7c892e715d51be7a18d8de9674495838c","frame_index":0,"kind":"data","monotonic_ns":228696661863583,"payload":{"event_type":"price_change","market":"0xeb66215f2e9faa6449e30a02bab5b8ed7b79a38bf961f6b24d0073c9c2419250","price_changes":[{"asset_id":"69697746896130839564035629862476347944307040470122503199396727085502753297492","best_ask":"0.3","best_bid":"0.29","hash":"2de18f1de09e54c7dae6d3e9d66398e917de6761","price":"0.31","side":"SELL","size":"431.6"},{"asset_id":"60386828328910021732068595344565885737045900010034836345809386672230885527307","best_ask":"0.71","best_bid":"0.7","hash":"02ad78581e60c6e5d5aa0a8aa4ba3b37a976d2cb","price":"0.69","side":"BUY","size":"431.6"}],"timestamp":"1785126713448"},"payload_hash":"f0978386e0e8b1e9b8b2c8c706d85d8faa732a35145a39a0ed1cc201d478f84c","raw_frame":"{\"market\":\"0xeb66215f2e9faa6449e30a02bab5b8ed7b79a38bf961f6b24d0073c9c2419250\", \"price_changes\":[{\"asset_id\":\"69697746896130839564035629862476347944307040470122503199396727085502753297492\", \"price\":\"0.31\", \"size\":\"431.6\", \"side\":\"SELL\", \"hash\":\"2de18f1de09e54c7dae6d3e9d66398e917de6761\", \"best_bid\":\"0.29\", \"best_ask\":\"0.3\"}, {\"asset_id\":\"60386828328910021732068595344565885737045900010034836345809386672230885527307\", \"price\":\"0.69\", \"size\":\"431.6\", \"side\":\"BUY\", \"hash\":\"02ad78581e60c6e5d5aa0a8aa4ba3b37a976d2cb\", \"best_bid\":\"0.7\", \"best_ask\":\"0.71\"}], \"timestamp\":\"1785126713448\", \"event_type\":\"price_change\"}","received_at":"2026-07-27T04:31:53.393006Z","schema_version":"clob-market-ws.price_change.v1","sequence":null,"server_hash":null,"server_timestamp":"1785126713448","session_id":"e9443c7415a0419799bee9cfbb1a9e4d","source":"clob_market_ws"},"received_at":"2026-07-27T04:31:53.393006Z","record_id":"0028876308b7269a4b13d1bc4445c8600c66a8023166486af480c9ec9177bd5b","schema_fingerprint":"4aa3821a28b0b7c2400bc59aba4bcc0a76e971dadd19610d3ad38c768e124dc7","schema_version":"edge-lab-recorder.raw.v1","sequence":null,"source":"clob_market_ws"}
{"event_at":"2026-07-27T04:31:53.474000Z","event_fingerprint":"bfa1c7444c0684ec8e63624a8dc0433e3992f3aa3682feb8bfd3c40e4ea6f7c9","payload":{"connection_id":"0f4979d6978d463e9660b042fdcf555f","event_at":"2026-07-27T04:31:53.474000Z","event_type":"price_change","frame_hash":"5bd92892e5f8dcb912a27d0429fbaaf77ec63e0059447d5ba77b920d341e4eed","frame_index":0,"kind":"data","monotonic_ns":228696685959500,"payload":{"event_type":"price_change","market":"0xeb66215f2e9faa6449e30a02bab5b8ed7b79a38bf961f6b24d0073c9c2419250","price_changes":[{"asset_id":"60386828328910021732068595344565885737045900010034836345809386672230885527307","best_ask":"0.71","best_bid":"0.7","hash":"3a401db80ee1d6ffe3e1538694f588a030c1e0ba","price":"0.01","side":"BUY","size":"7703.02"},{"asset_id":"69697746896130839564035629862476347944307040470122503199396727085502753297492","best_ask":"0.3","best_bid":"0.29","hash":"5b5d2453a95d577d6a0c42d32f64876d5c7d498f","price":"0.99","side":"SELL","size":"7703.02"}],"timestamp":"1785126713474"},"payload_hash":"f3ba44c3b816f121700223c5449cc9c1688036980a584adfdc2374bedd1b274f","raw_frame":"{\"market\":\"0xeb66215f2e9faa6449e30a02bab5b8ed7b79a38bf961f6b24d0073c9c2419250\", \"price_changes\":[{\"asset_id\":\"60386828328910021732068595344565885737045900010034836345809386672230885527307\", \"price\":\"0.01\", \"size\":\"7703.02\", \"side\":\"BUY\", \"hash\":\"3a401db80ee1d6ffe3e1538694f588a030c1e0ba\", \"best_bid\":\"0.7\", \"best_ask\":\"0.71\"}, {\"asset_id\":\"69697746896130839564035629862476347944307040470122503199396727085502753297492\", \"price\":\"0.99\", \"size\":\"7703.02\", \"side\":\"SELL\", \"hash\":\"5b5d2453a95d577d6a0c42d32f64876d5c7d498f\", \"best_bid\":\"0.29\", \"best_ask\":\"0.3\"}], \"timestamp\":\"1785126713474\", \"event_type\":\"price_change\"}","received_at":"2026-07-27T04:31:53.417101Z","schema_version":"clob-market-ws.price_change.v1","sequence":null,"server_hash":null,"server_timestamp":"1785126713474","session_id":"e9443c7415a0419799bee9cfbb1a9e4d","source":"clob_market_ws"},"received_at":"2026-07-27T04:31:53.417101Z","record_id":"f5e60e04533f552d210cc37a5e3acbb4f1aa2739be20c3315ae369e8112b5bfe","schema_fingerprint":"4aa3821a28b0b7c2400bc59aba4bcc0a76e971dadd19610d3ad38c768e124dc7","schema_version":"edge-lab-recorder.raw.v1","sequence":null,"source":"clob_market_ws"}
{"event_at":"2026-07-27T04:31:53.567000Z","event_fingerprint":"c5579c9fee5f8c5cdb361f2871ad275cb09e50d8fb2743376a4646ac458c1bef","payload":{"connection_id":"0f4979d6978d463e9660b042fdcf555f","event_at":"2026-07-27T04:31:53.567000Z","event_type":"price_change","frame_hash":"9627d94e4da9b5998c1a2478eb3761281ae25f8da5b2990c30e40c8ff6d3e1df","frame_index":0,"kind":"data","monotonic_ns":228696781494041,"payload":{"event_type":"price_change","market":"0xeb66215f2e9faa6449e30a02bab5b8ed7b79a38bf961f6b24d0073c9c2419250","price_changes":[{"asset_id":"69697746896130839564035629862476347944307040470122503199396727085502753297492","best_ask":"0.3","best_bid":"0.29","hash":"36a3539d25272b7ba011dd58b1baa834bffebc2e","price":"0.31","side":"SELL","size":"426.56"},{"asset_id":"60386828328910021732068595344565885737045900010034836345809386672230885527307","best_ask":"0.71","best_bid":"0.7","hash":"1b9a03386576f6aa921f9c6c9e48a21e066fb1a8","price":"0.69","side":"BUY","size":"426.56"}],"timestamp":"1785126713567"},"payload_hash":"7f25aca07cf37c7ac5ef7b8135bf2d6e18f1a60a80473746c52858dd0e6109be","raw_frame":"{\"market\":\"0xeb66215f2e9faa6449e30a02bab5b8ed7b79a38bf961f6b24d0073c9c2419250\", \"price_changes\":[{\"asset_id\":\"69697746896130839564035629862476347944307040470122503199396727085502753297492\", \"price\":\"0.31\", \"size\":\"426.56\", \"side\":\"SELL\", \"hash\":\"36a3539d25272b7ba011dd58b1baa834bffebc2e\", \"best_bid\":\"0.29\", \"best_ask\":\"0.3\"}, {\"asset_id\":\"60386828328910021732068595344565885737045900010034836345809386672230885527307\", \"price\":\"0.69\", \"size\":\"426.56\", \"side\":\"BUY\", \"hash\":\"1b9a03386576f6aa921f9c6c9e48a21e066fb1a8\", \"best_bid\":\"0.7\", \"best_ask\":\"0.71\"}], \"timestamp\":\"1785126713567\", \"event_type\":\"price_change\"}","received_at":"2026-07-27T04:31:53.512637Z","schema_version":"clob-market-ws.price_change.v1","sequence":null,"server_hash":null,"server_timestamp":"1785126713567","session_id":"e9443c7415a0419799bee9cfbb1a9e4d","source":"clob_market_ws"},"received_at":"2026-07-27T04:31:53.512637Z","record_id":"0fa099e9439eda533038e1fa386df592443f71fc602f4122780dfe9f5fdbdcec","schema_fingerprint":"4aa3821a28b0b7c2400bc59aba4bcc0a76e971dadd19610d3ad38c768e124dc7","schema_version":"edge-lab-recorder.raw.v1","sequence":null,"source":"clob_market_ws"}
