{"event_at":"2026-07-27T04:40:26.776000Z","event_fingerprint":"636c3d4d69518d9d046bdb1839e3d2d08e03957b135e14f31fa82f3c486da809","payload":{"connection_id":"0f4979d6978d463e9660b042fdcf555f","event_at":"2026-07-27T04:40:26.776000Z","event_type":"price_change","frame_hash":"b3b07cca4ab99b9659474b90552b7936f907ba3e90bc7eab783cc1383194de9a","frame_index":0,"kind":"data","monotonic_ns":229210044705958,"payload":{"event_type":"price_change","market":"0xeb66215f2e9faa6449e30a02bab5b8ed7b79a38bf961f6b24d0073c9c2419250","price_changes":[{"asset_id":"69697746896130839564035629862476347944307040470122503199396727085502753297492","best_ask":"0.73","best_bid":"0.72","hash":"15b069827fc7e316cb98caeab3b5fbf803223ef1","price":"0.7","side":"BUY","size":"41.94"},{"asset_id":"60386828328910021732068595344565885737045900010034836345809386672230885527307","best_ask":"0.28","best_bid":"0.27","hash":"5a26a55054a380be262b00a134ace1ed5ff141c4","price":"0.3","side":"SELL","size":"41.94"}],"timestamp":"1785127226776"},"payload_hash":"c0594e5dd504260bbcaef4d24e9920ce8b98ae2642cdd3aac9e1bd1c46b0fd67","raw_frame":"{\"market\":\"0xeb66215f2e9faa6449e30a02bab5b8ed7b79a38bf961f6b24d0073c9c2419250\", \"price_changes\":[{\"asset_id\":\"69697746896130839564035629862476347944307040470122503199396727085502753297492\", \"price\":\"0.7\", \"size\":\"41.94\", \"side\":\"BUY\", \"hash\":\"15b069827fc7e316cb98caeab3b5fbf803223ef1\", \"best_bid\":\"0.72\", \"best_ask\":\"0.73\"}, {\"asset_id\":\"60386828328910021732068595344565885737045900010034836345809386672230885527307\", \"price\":\"0.3\", \"size\":\"41.94\", \"side\":\"SELL\", \"hash\":\"5a26a55054a380be262b00a134ace1ed5ff141c4\", \"best_bid\":\"0.27\", \"best_ask\":\"0.28\"}], \"timestamp\":\"1785127226776\", \"event_type\":\"price_change\"}","received_at":"2026-07-27T04:40:26.780306Z","schema_version":"clob-market-ws.price_change.v1","sequence":null,"server_hash":null,"server_timestamp":"1785127226776","session_id":"e9443c7415a0419799bee9cfbb1a9e4d","source":"clob_market_ws"},"received_at":"2026-07-27T04:40:26.780306Z","record_id":"60806ad4f4b128ea9806db584ac6a9ee284e720f063d8dd1e58a1fa55b07afa3","schema_fingerprint":"4aa3821a28b0b7c2400bc59aba4bcc0a76e971dadd19610d3ad38c768e124dc7","schema_version":"edge-lab-recorder.raw.v1","sequence":null,"source":"clob_market_ws"}
{"event_at":"2026-07-27T04:40:26.779000Z","event_fingerprint":"7354308a8a5f0c5daa483d2551945c0f9f84a6f19a70fc2e65779fd14fc4c3d6","payload":{"connection_id":"0f4979d6978d463e9660b042fdcf555f","event_at":"2026-07-27T04:40:26.779000Z","event_type":"price_change","frame_hash":"c4a326b473779a52ede5ac09be803840ee776c415fcc3c6684a50583ddf309d9","frame_index":0,"kind":"data","monotonic_ns":229210049560375,"payload":{"event_type":"price_change","market":"0xeb66215f2e9faa6449e30a02bab5b8ed7b79a38bf961f6b24d0073c9c2419250","price_changes":[{"asset_id":"60386828328910021732068595344565885737045900010034836345809386672230885527307","best_ask":"0.28","best_bid":"0.27","hash":"31b99469871a54b95f98c2fbee09fe543a5e609d","price":"0.3","side":"SELL","size":"84.94"},{"asset_id":"69697746896130839564035629862476347944307040470122503199396727085502753297492","best_ask":"0.73","best_bid":"0.72","hash":"5d3e2faf5b38e751a40697a09f0e8f2adfe68656","price":"0.7","side":"BUY","size":"84.94"}],"timestamp":"1785127226779"},"payload_hash":"b82cfd4066df9b525c26555b85228374d3e4f5570cfe4f9c8d77c84de27dd412","raw_frame":"{\"market\":\"0xeb66215f2e9faa6449e30a02bab5b8ed7b79a38bf961f6b24d0073c9c2419250\", \"price_changes\":[{\"asset_id\":\"60386828328910021732068595344565885737045900010034836345809386672230885527307\", \"price\":\"0.3\", \"size\":\"84.94\", \"side\":\"SELL\", \"hash\":\"31b99469871a54b95f98c2fbee09fe543a5e609d\", \"best_bid\":\"0.27\", \"best_ask\":\"0.28\"}, {\"asset_id\":\"69697746896130839564035629862476347944307040470122503199396727085502753297492\", \"price\":\"0.7\", \"size\":\"84.94\", \"side\":\"BUY\", \"hash\":\"5d3e2faf5b38e751a40697a09f0e8f2adfe68656\", \"best_bid\":\"0.72\", \"best_ask\":\"0.73\"}], \"timestamp\":\"1785127226779\", \"event_type\":\"price_change\"}","received_at":"2026-07-27T04:40:26.785159Z","schema_version":"clob-market-ws.price_change.v1","sequence":null,"server_hash":null,"server_timestamp":"1785127226779","session_id":"e9443c7415a0419799bee9cfbb1a9e4d","source":"clob_market_ws"},"received_at":"2026-07-27T04:40:26.785159Z","record_id":"b9a3879e4fba88a39b15d5ccce4dc0c7858049e90602524d4f9d4e737101b5d5","schema_fingerprint":"4aa3821a28b0b7c2400bc59aba4bcc0a76e971dadd19610d3ad38c768e124dc7","schema_version":"edge-lab-recorder.raw.v1","sequence":null,"source":"clob_market_ws"}
{"event_at":"2026-07-27T04:40:26.780000Z","event_fingerprint":"94762b8bbcd20a2727cc1c3262e089ec790dbaa3ce301214e4de5ad4ed4128ab","payload":{"connection_id":"0f4979d6978d463e9660b042fdcf555f","event_at":"2026-07-27T04:40:26.780000Z","event_type":"price_change","frame_hash":"fb4dcb9505cad7240db0b2d8627e8ffe8448e73a70c0856f58b841032a3f840d","frame_index":0,"kind":"data","monotonic_ns":229210052427041,"payload":{"event_type":"price_change","market":"0xeb66215f2e9faa6449e30a02bab5b8ed7b79a38bf961f6b24d0073c9c2419250","price_changes":[{"asset_id":"69697746896130839564035629862476347944307040470122503199396727085502753297492","best_ask":"0.73","best_bid":"0.72","hash":"add2b3d872688e879cf612f2faabd03673a0e234","price":"0.68","side":"BUY","size":"305.4"},{"asset_id":"60386828328910021732068595344565885737045900010034836345809386672230885527307","best_ask":"0.28","best_bid":"0.27","hash":"c689aae4f67522fb7597328a9081233de60b59e1","price":"0.32","side":"SELL","size":"305.4"}],"timestamp":"1785127226780"},"payload_hash":"cd25caeb85b06ea40cee68c63c58e985da89d4d9dc390803a7d2c5c59121dc66","raw_frame":"{\"market\":\"0xeb66215f2e9faa6449e30a02bab5b8ed7b79a38bf961f6b24d0073c9c2419250\", \"price_changes\":[{\"asset_id\":\"69697746896130839564035629862476347944307040470122503199396727085502753297492\", \"price\":\"0.68\", \"size\":\"305.4\", \"side\":\"BUY\", \"hash\":\"add2b3d872688e879cf612f2faabd03673a0e234\", \"best_bid\":\"0.72\", \"best_ask\":\"0.73\"}, {\"asset_id\":\"60386828328910021732068595344565885737045900010034836345809386672230885527307\", \"price\":\"0.32\", \"size\":\"305.4\", \"side\":\"SELL\", \"hash\":\"c689aae4f67522fb7597328a9081233de60b59e1\", \"best_bid\":\"0.27\", \"best_ask\":\"0.28\"}], \"timestamp\":\"1785127226780\", \"event_type\":\"price_change\"}","received_at":"2026-07-27T04:40:26.788025Z","schema_version":"clob-market-ws.price_change.v1","sequence":null,"server_hash":null,"server_timestamp":"1785127226780","session_id":"e9443c7415a0419799bee9cfbb1a9e4d","source":"clob_market_ws"},"received_at":"2026-07-27T04:40:26.788025Z","record_id":"5157018793b88d9aacb5c3f4195e7647ba0afe04e203d85e7c6b10a0d39cb51e","schema_fingerprint":"4aa3821a28b0b7c2400bc59aba4bcc0a76e971dadd19610d3ad38c768e124dc7","schema_version":"edge-lab-recorder.raw.v1","sequence":null,"source":"clob_market_ws"}
{"event_at":"2026-07-27T04:40:26.781000Z","event_fingerprint":"d3591b6707f089078c064aae22667a7d8763d9267b761e6af3b18966a0390324","payload":{"connection_id":"0f4979d6978d463e9660b042fdcf555f","event_at":"2026-07-27T04:40:26.781000Z","event_type":"price_change","frame_hash":"3933691a22f63dbd05e85d33908b81be0582bf548711f1950444bf62f0228927","frame_index":0,"kind":"data","monotonic_ns":229210054159916,"payload":{"event_type":"price_change","market":"0xeb66215f2e9faa6449e30a02bab5b8ed7b79a38bf961f6b24d0073c9c2419250","price_changes":[{"asset_id":"60386828328910021732068595344565885737045900010034836345809386672230885527307","best_ask":"0.28","best_bid":"0.27","hash":"5a094999450d291390ce51df4f87821fbca0fe57","price":"0.31","side":"SELL","size":"166.23"},{"asset_id":"69697746896130839564035629862476347944307040470122503199396727085502753297492","best_ask":"0.73","best_bid":"0.72","hash":"19770a55cf7f07268e46382f70e66b60b91ae63b","price":"0.69","side":"BUY","size":"166.23"}],"timestamp":"1785127226781"},"payload_hash":"2856db44b5d0b59c12d84881f7c87c5d21ab60665858fba4087b0c23d694cb4d","raw_frame":"{\"market\":\"0xeb66215f2e9faa6449e30a02bab5b8ed7b79a38bf961f6b24d0073c9c2419250\", \"price_changes\":[{\"asset_id\":\"60386828328910021732068595344565885737045900010034836345809386672230885527307\", \"price\":\"0.31\", \"size\":\"166.23\", \"side\":\"SELL\", \"hash\":\"5a094999450d291390ce51df4f87821fbca0fe57\", \"best_bid\":\"0.27\", \"best_ask\":\"0.28\"}, {\"asset_id\":\"69697746896130839564035629862476347944307040470122503199396727085502753297492\", \"price\":\"0.69\", \"size\":\"166.23\", \"side\":\"BUY\", \"hash\":\"19770a55cf7f07268e46382f70e66b60b91ae63b\", \"best_bid\":\"0.72\", \"best_ask\":\"0.73\"}], \"timestamp\":\"1785127226781\", \"event_type\":\"price_change\"}","received_at":"2026-07-27T04:40:26.789762Z","schema_version":"clob-market-ws.price_change.v1","sequence":null,"server_hash":null,"server_timestamp":"1785127226781","session_id":"e9443c7415a0419799bee9cfbb1a9e4d","source":"clob_market_ws"},"received_at":"2026-07-27T04:40:26.789762Z","record_id":"6950bc570facd1cac65114c12a17173654b0125e90a07f84e2e4714b388d989d","schema_fingerprint":"4aa3821a28b0b7c2400bc59aba4bcc0a76e971dadd19610d3ad38c768e124dc7","schema_version":"edge-lab-recorder.raw.v1","sequence":null,"source":"clob_market_ws"}
{"event_at":"2026-07-27T04:40:26.808000Z","event_fingerprint":"7e8e853cdeaff5e2db32ac574d2f84abeec25fff657abb31088a1acb37f96b50","payload":{"connection_id":"0f4979d6978d463e9660b042fdcf555f","event_at":"2026-07-27T04:40:26.808000Z","event_type":"price_change","frame_hash":"aa8db00461e167e6449d5b532e5bdedeb7a1d2580149a0d91bd39e8f0d4549c7","frame_index":0,"kind":"data","monotonic_ns":229210055446583,"payload":{"event_type":"price_change","market":"0xeb66215f2e9faa6449e30a02bab5b8ed7b79a38bf961f6b24d0073c9c2419250","price_changes":[{"asset_id":"60386828328910021732068595344565885737045900010034836345809386672230885527307","best_ask":"0.28","best_bid":"0.27","hash":"4d375792506515db3880252c30fa21d1a5d869e6","price":"0.19","side":"BUY","size":"174"},{"asset_id":"69697746896130839564035629862476347944307040470122503199396727085502753297492","best_ask":"0.73","best_bid":"0.72","hash":"738f4f02d5005cc52ff73f5b687d585752b55597","price":"0.81","side":"SELL","size":"174"}],"timestamp":"1785127226808"},"payload_hash":"2a4545bed4342f7083d8d0cf5cd95f25cbe17f18be74dc4867e5dca2b9eb38cc","raw_frame":"{\"market\":\"0xeb66215f2e9faa6449e30a02bab5b8ed7b79a38bf961f6b24d0073c9c2419250\", \"price_changes\":[{\"asset_id\":\"60386828328910021732068595344565885737045900010034836345809386672230885527307\", \"price\":\"0.19\", \"size\":\"174\", \"side\":\"BUY\", \"hash\":\"4d375792506515db3880252c30fa21d1a5d869e6\", \"best_bid\":\"0.27\", \"best_ask\":\"0.28\"}, {\"asset_id\":\"69697746896130839564035629862476347944307040470122503199396727085502753297492\", \"price\":\"0.81\", \"size\":\"174\", \"side\":\"SELL\", \"hash\":\"738f4f02d5005cc52ff73f5b687d585752b55597\", \"best_bid\":\"0.72\", \"best_ask\":\"0.73\"}], \"timestamp\":\"1785127226808\", \"event_type\":\"price_change\"}","received_at":"2026-07-27T04:40:26.791048Z","schema_version":"clob-market-ws.price_change.v1","sequence":null,"server_hash":null,"server_timestamp":"1785127226808","session_id":"e9443c7415a0419799bee9cfbb1a9e4d","source":"clob_market_ws"},"received_at":"2026-07-27T04:40:26.791048Z","record_id":"f9fef7c17728635ff90003fae53b2e0c57d1c4810a45b8940e03cdfde8c51ec4","schema_fingerprint":"4aa3821a28b0b7c2400bc59aba4bcc0a76e971dadd19610d3ad38c768e124dc7","schema_version":"edge-lab-recorder.raw.v1","sequence":null,"source":"clob_market_ws"}
{"event_at":"2026-07-27T04:40:26.825000Z","event_fingerprint":"fef070746fe4746bbfadb1b49aa615540ac4a89b9d91236a15f66a30f0389736","payload":{"connection_id":"0f4979d6978d463e9660b042fdcf555f","event_at":"2026-07-27T04:40:26.825000Z","event_type":"price_change","frame_hash":"0c190b530877699916cea7b58b04b38bb015ae8e575f6e8143e545eae7be09dc","frame_index":0,"kind":"data","monotonic_ns":229210059017708,"payload":{"event_type":"price_change","market":"0xeb66215f2e9faa6449e30a02bab5b8ed7b79a38bf961f6b24d0073c9c2419250","price_changes":[{"asset_id":"60386828328910021732068595344565885737045900010034836345809386672230885527307","best_ask":"0.28","best_bid":"0.27","hash":"2f28c251a6898c44a459b797c771c538242f4fa3","price":"0.19","side":"BUY","size":"144"},{"asset_id":"69697746896130839564035629862476347944307040470122503199396727085502753297492","best_ask":"0.73","best_bid":"0.72","hash":"363a8f0a394e98e57ed9de06ed1ae885f490be5b","price":"0.81","side":"SELL","size":"144"}],"timestamp":"1785127226825"},"payload_hash":"1dcef119a211b2f917312d772771da7b5ad3dd058620c3b018a64d876b1c0104","raw_frame":"{\"market\":\"0xeb66215f2e9faa6449e30a02bab5b8ed7b79a38bf961f6b24d0073c9c2419250\", \"price_changes\":[{\"asset_id\":\"60386828328910021732068595344565885737045900010034836345809386672230885527307\", \"price\":\"0.19\", \"size\":\"144\", \"side\":\"BUY\", \"hash\":\"2f28c251a6898c44a459b797c771c538242f4fa3\", \"best_bid\":\"0.27\", \"best_ask\":\"0.28\"}, {\"asset_id\":\"69697746896130839564035629862476347944307040470122503199396727085502753297492\", \"price\":\"0.81\", \"size\":\"144\", \"side\":\"SELL\", \"hash\":\"363a8f0a394e98e57ed9de06ed1ae885f490be5b\", \"best_bid\":\"0.72\", \"best_ask\":\"0.73\"}], \"timestamp\":\"1785127226825\", \"event_type\":\"price_change\"}","received_at":"2026-07-27T04:40:26.794613Z","schema_version":"clob-market-ws.price_change.v1","sequence":null,"server_hash":null,"server_timestamp":"1785127226825","session_id":"e9443c7415a0419799bee9cfbb1a9e4d","source":"clob_market_ws"},"received_at":"2026-07-27T04:40:26.794613Z","record_id":"e21652a7eeddc856089c6352fe0cf4b0c531c9259a78b34c44ecbe6641137b98","schema_fingerprint":"4aa3821a28b0b7c2400bc59aba4bcc0a76e971dadd19610d3ad38c768e124dc7","schema_version":"edge-lab-recorder.raw.v1","sequence":null,"source":"clob_market_ws"}
{"event_at":"2026-07-27T04:40:26.834000Z","event_fingerprint":"fed15b2667dd34dead8d2cb41bb03969804ed7cf5b57ce3b03a36829858f2c33","payload":{"connection_id":"0f4979d6978d463e9660b042fdcf555f","event_at":"2026-07-27T04:40:26.834000Z","event_type":"price_change","frame_hash":"07ada3436b10fced63832ecb3eb114a34df30ba1e91bfd8cf46e56bf5ed3ff8c","frame_index":0,"kind":"data","monotonic_ns":229210063593875,"payload":{"event_type":"price_change","market":"0xeb66215f2e9faa6449e30a02bab5b8ed7b79a38bf961f6b24d0073c9c2419250","price_changes":[{"asset_id":"69697746896130839564035629862476347944307040470122503199396727085502753297492","best_ask":"0.73","best_bid":"0.72","hash":"f1d51291121aaf9367e146ab77c22ead6d4342dd","price":"0.01","side":"BUY","size":"5633.02"},{"asset_id":"60386828328910021732068595344565885737045900010034836345809386672230885527307","best_ask":"0.28","best_bid":"0.27","hash":"12a638a396b9b82f31d850e8338d210a281aa1b2","price":"0.99","side":"SELL","size":"5633.02"}],"timestamp":"1785127226834"},"payload_hash":"df7a04efb6b4948e9c954e1c62ff94e1f333f358d9d9cf2c81f14c69252330c8","raw_frame":"{\"market\":\"0xeb66215f2e9faa6449e30a02bab5b8ed7b79a38bf961f6b24d0073c9c2419250\", \"price_changes\":[{\"asset_id\":\"69697746896130839564035629862476347944307040470122503199396727085502753297492\", \"price\":\"0.01\", \"size\":\"5633.02\", \"side\":\"BUY\", \"hash\":\"f1d51291121aaf9367e146ab77c22ead6d4342dd\", \"best_bid\":\"0.72\", \"best_ask\":\"0.73\"}, {\"asset_id\":\"60386828328910021732068595344565885737045900010034836345809386672230885527307\", \"price\":\"0.99\", \"size\":\"5633.02\", \"side\":\"SELL\", \"hash\":\"12a638a396b9b82f31d850e8338d210a281aa1b2\", \"best_bid\":\"0.27\", \"best_ask\":\"0.28\"}], \"timestamp\":\"1785127226834\", \"event_type\":\"price_change\"}","received_at":"2026-07-27T04:40:26.799188Z","schema_version":"clob-market-ws.price_change.v1","sequence":null,"server_hash":null,"server_timestamp":"1785127226834","session_id":"e9443c7415a0419799bee9cfbb1a9e4d","source":"clob_market_ws"},"received_at":"2026-07-27T04:40:26.799188Z","record_id":"c723502df758763e7869323c911b1cf7362dc0eccd1adde5e66748e979bdff85","schema_fingerprint":"4aa3821a28b0b7c2400bc59aba4bcc0a76e971dadd19610d3ad38c768e124dc7","schema_version":"edge-lab-recorder.raw.v1","sequence":null,"source":"clob_market_ws"}
{"event_at":"2026-07-27T04:40:26.851000Z","event_fingerprint":"b577d8fe8945467cc921e3ff6c2f468c521049f6890c911c31d6a5f1daf5bd09","payload":{"connection_id":"0f4979d6978d463e9660b042fdcf555f","event_at":"2026-07-27T04:40:26.851000Z","event_type":"price_change","frame_hash":"51e2db6c351b0d18e4908682fbf6aa7e030ec012ec8baad8c07c781f2c88ff8b","frame_index":0,"kind":"data","monotonic_ns":229210067952791,"payload":{"event_type":"price_change","market":"0xeb66215f2e9faa6449e30a02bab5b8ed7b79a38bf961f6b24d0073c9c2419250","price_changes":[{"asset_id":"69697746896130839564035629862476347944307040470122503199396727085502753297492","best_ask":"0.73","best_bid":"0.72","hash":"f1ea2a30d8f4f1b92bf996138e03037ddfe65021","price":"0.01","side":"BUY","size":"5638.02"},{"asset_id":"60386828328910021732068595344565885737045900010034836345809386672230885527307","best_ask":"0.28","best_bid":"0.27","hash":"c7ae40e723b80e821c630952aa86e8160a1fff4f","price":"0.99","side":"SELL","size":"5638.02"}],"timestamp":"1785127226851"},"payload_hash":"431b05245b069409808eb23655c5f69753ca3d775339a8d755b373c87c88ed41","raw_frame":"{\"market\":\"0xeb66215f2e9faa6449e30a02bab5b8ed7b79a38bf961f6b24d0073c9c2419250\", \"price_changes\":[{\"asset_id\":\"69697746896130839564035629862476347944307040470122503199396727085502753297492\", \"price\":\"0.01\", \"size\":\"5638.02\", \"side\":\"BUY\", \"hash\":\"f1ea2a30d8f4f1b92bf996138e03037ddfe65021\", \"best_bid\":\"0.72\", \"best_ask\":\"0.73\"}, {\"asset_id\":\"60386828328910021732068595344565885737045900010034836345809386672230885527307\", \"price\":\"0.99\", \"size\":\"5638.02\", \"side\":\"SELL\", \"hash\":\"c7ae40e723b80e821c630952aa86e8160a1fff4f\", \"best_bid\":\"0.27\", \"best_ask\":\"0.28\"}], \"timestamp\":\"1785127226851\", \"event_type\":\"price_change\"}","received_at":"2026-07-27T04:40:26.803547Z","schema_version":"clob-market-ws.price_change.v1","sequence":null,"server_hash":null,"server_timestamp":"1785127226851","session_id":"e9443c7415a0419799bee9cfbb1a9e4d","source":"clob_market_ws"},"received_at":"2026-07-27T04:40:26.803547Z","record_id":"67b8ee7583dc45358ca745d1c750d547c33bbff5a721de0eba56b9ed5c131e21","schema_fingerprint":"4aa3821a28b0b7c2400bc59aba4bcc0a76e971dadd19610d3ad38c768e124dc7","schema_version":"edge-lab-recorder.raw.v1","sequence":null,"source":"clob_market_ws"}
{"event_at":"2026-07-27T04:40:26.859000Z","event_fingerprint":"d4e3556dfae4c652f3c1ff14759b7aaf1e7721fefe1d0e6930fabe21b9d8f72a","payload":{"connection_id":"0f4979d6978d463e9660b042fdcf555f","event_at":"2026-07-27T04:40:26.859000Z","event_type":"price_change","frame_hash":"947d9cc96241de4c3c055216a9b6386ef46a4d2904c3f0f78ecb67142fc87f92","frame_index":0,"kind":"data","monotonic_ns":229210071827875,"payload":{"event_type":"price_change","market":"0xeb66215f2e9faa6449e30a02bab5b8ed7b79a38bf961f6b24d0073c9c2419250","price_changes":[{"asset_id":"60386828328910021732068595344565885737045900010034836345809386672230885527307","best_ask":"0.28","best_bid":"0.27","hash":"b1a50b64b89cfa741689c76eb1f17aa29aae51b4","price":"0.18","side":"BUY","size":"131.01"},{"asset_id":"69697746896130839564035629862476347944307040470122503199396727085502753297492","best_ask":"0.73","best_bid":"0.72","hash":"fc7e71c3eddea8ca0b2653bfef99d65507f4df98","price":"0.82","side":"SELL","size":"131.01"}],"timestamp":"1785127226859"},"payload_hash":"dc698aa592b44c00b9a91d74094fa61eecc27206a6015aaa46918760c93bf0f3","raw_frame":"{\"market\":\"0xeb66215f2e9faa6449e30a02bab5b8ed7b79a38bf961f6b24d0073c9c2419250\", \"price_changes\":[{\"asset_id\":\"60386828328910021732068595344565885737045900010034836345809386672230885527307\", \"price\":\"0.18\", \"size\":\"131.01\", \"side\":\"BUY\", \"hash\":\"b1a50b64b89cfa741689c76eb1f17aa29aae51b4\", \"best_bid\":\"0.27\", \"best_ask\":\"0.28\"}, {\"asset_id\":\"69697746896130839564035629862476347944307040470122503199396727085502753297492\", \"price\":\"0.82\", \"size\":\"131.01\", \"side\":\"SELL\", \"hash\":\"fc7e71c3eddea8ca0b2653bfef99d65507f4df98\", \"best_bid\":\"0.72\", \"best_ask\":\"0.73\"}], \"timestamp\":\"1785127226859\", \"event_type\":\"price_change\"}","received_at":"2026-07-27T04:40:26.807429Z","schema_version":"clob-market-ws.price_change.v1","sequence":null,"server_hash":null,"server_timestamp":"1785127226859","session_id":"e9443c7415a0419799bee9cfbb1a9e4d","source":"clob_market_ws"},"received_at":"2026-07-27T04:40:26.807429Z","record_id":"206657f55579d0ec6347bdfc97a9c6ebe74cbd4f19adaa4832bb5872cfd64659","schema_fingerprint":"4aa3821a28b0b7c2400bc59aba4bcc0a76e971dadd19610d3ad38c768e124dc7","schema_version":"edge-lab-recorder.raw.v1","sequence":null,"source":"clob_market_ws"}
{"event_at":"2026-07-27T04:40:26.863000Z","event_fingerprint":"c59432833e21ae27ade6038ff7dc73c08402720910480b1fd321f3cbc81b7a10","payload":{"connection_id":"0f4979d6978d463e9660b042fdcf555f","event_at":"2026-07-27T04:40:26.863000Z","event_type":"price_change","frame_hash":"c32cea4475bac35e3e250130d36cdabb46306731370a3271223fbbd5d4e677fa","frame_index":0,"kind":"data","monotonic_ns":229210080183250,"payload":{"event_type":"price_change","market":"0xeb66215f2e9faa6449e30a02bab5b8ed7b79a38bf961f6b24d0073c9c2419250","price_changes":[{"asset_id":"60386828328910021732068595344565885737045900010034836345809386672230885527307","best_ask":"0.28","best_bid":"0.27","hash":"1a9329ed4d15cf99dba09fd278a341375bf95eae","price":"0.18","side":"BUY","size":"161.01"},{"asset_id":"69697746896130839564035629862476347944307040470122503199396727085502753297492","best_ask":"0.73","best_bid":"0.72","hash":"e42839ea258258dbf28e30bebd113603fdb9a585","price":"0.82","side":"SELL","size":"161.01"}],"timestamp":"1785127226863"},"payload_hash":"2c28f231f7b252ef78e24355ed38713cac7f0e3faaf51351c0daa81c0fc6f5f3","raw_frame":"{\"market\":\"0xeb66215f2e9faa6449e30a02bab5b8ed7b79a38bf961f6b24d0073c9c2419250\", \"price_changes\":[{\"asset_id\":\"60386828328910021732068595344565885737045900010034836345809386672230885527307\", \"price\":\"0.18\", \"size\":\"161.01\", \"side\":\"BUY\", \"hash\":\"1a9329ed4d15cf99dba09fd278a341375bf95eae\", \"best_bid\":\"0.27\", \"best_ask\":\"0.28\"}, {\"asset_id\":\"69697746896130839564035629862476347944307040470122503199396727085502753297492\", \"price\":\"0.82\", \"size\":\"161.01\", \"side\":\"SELL\", \"hash\":\"e42839ea258258dbf28e30bebd113603fdb9a585\", \"best_bid\":\"0.72\", \"best_ask\":\"0.73\"}], \"timestamp\":\"1785127226863\", \"event_type\":\"price_change\"}","received_at":"2026-07-27T04:40:26.815779Z","schema_version":"clob-market-ws.price_change.v1","sequence":null,"server_hash":null,"server_timestamp":"1785127226863","session_id":"e9443c7415a0419799bee9cfbb1a9e4d","source":"clob_market_ws"},"received_at":"2026-07-27T04:40:26.815779Z","record_id":"26472eec8dbb37dcd7339253a4b0a2f1f1d4dcead57dd83368b1beed2c232e27","schema_fingerprint":"4aa3821a28b0b7c2400bc59aba4bcc0a76e971dadd19610d3ad38c768e124dc7","schema_version":"edge-lab-recorder.raw.v1","sequence":null,"source":"clob_market_ws"}
{"event_at":"2026-07-27T04:40:26.868000Z","event_fingerprint":"b87407129624378cb19bd334e544b0dd5c6e2df7a018a192d6ad10abdbe27678","payload":{"connection_id":"0f4979d6978d463e9660b042fdcf555f","event_at":"2026-07-27T04:40:26.868000Z","event_type":"price_change","frame_hash":"a8fcd3017af67a168f948dc4af26f0c781fbf6218c4d75f6d9a6bc655ab41c83","frame_index":0,"kind":"data","monotonic_ns":229210085165583,"payload":{"event_type":"price_change","market":"0xeb66215f2e9faa6449e30a02bab5b8ed7b79a38bf961f6b24d0073c9c2419250","price_changes":[{"asset_id":"69697746896130839564035629862476347944307040470122503199396727085502753297492","best_ask":"0.73","best_bid":"0.72","hash":"745d343fb0847a0b4624dc63739fc9216806fa64","price":"0.01","side":"BUY","size":"5633.02"},{"asset_id":"60386828328910021732068595344565885737045900010034836345809386672230885527307","best_ask":"0.28","best_bid":"0.27","hash":"e6903c7d2a639558530fb737afcc89caba45e1ff","price":"0.99","side":"SELL","size":"5633.02"}],"timestamp":"1785127226868"},"payload_hash":"7c31bfd161a954304aa98c90c4087fb746ab8fc9966ed879d7188e0b24b7d139","raw_frame":"{\"market\":\"0xeb66215f2e9faa6449e30a02bab5b8ed7b79a38bf961f6b24d0073c9c2419250\", \"price_changes\":[{\"asset_id\":\"69697746896130839564035629862476347944307040470122503199396727085502753297492\", \"price\":\"0.01\", \"size\":\"5633.02\", \"side\":\"BUY\", \"hash\":\"745d343fb0847a0b4624dc63739fc9216806fa64\", \"best_bid\":\"0.72\", \"best_ask\":\"0.73\"}, {\"asset_id\":\"60386828328910021732068595344565885737045900010034836345809386672230885527307\", \"price\":\"0.99\", \"size\":\"5633.02\", \"side\":\"SELL\", \"hash\":\"e6903c7d2a639558530fb737afcc89caba45e1ff\", \"best_bid\":\"0.27\", \"best_ask\":\"0.28\"}], \"timestamp\":\"1785127226868\", \"event_type\":\"price_change\"}","received_at":"2026-07-27T04:40:26.820767Z","schema_version":"clob-market-ws.price_change.v1","sequence":null,"server_hash":null,"server_timestamp":"1785127226868","session_id":"e9443c7415a0419799bee9cfbb1a9e4d","source":"clob_market_ws"},"received_at":"2026-07-27T04:40:26.820767Z","record_id":"93b9841a81e71cd2c01ea446536a9223d93c82bb18dd8462c4ffac305b5fb329","schema_fingerprint":"4aa3821a28b0b7c2400bc59aba4bcc0a76e971dadd19610d3ad38c768e124dc7","schema_version":"edge-lab-recorder.raw.v1","sequence":null,"source":"clob_market_ws"}
{"event_at":"2026-07-27T04:40:26.982000Z","event_fingerprint":"d0f74e5a2d712b84c1f6af460a9660ca89ab26978c65fd3867f4f3b639f7a3e2","payload":{"connection_id":"0f4979d6978d463e9660b042fdcf555f","event_at":"2026-07-27T04:40:26.982000Z","event_type":"price_change","frame_hash":"d46710809737d8cce46cd9aac1f3b9adf3c33f7d02c7668ba99e8b84d5908aa5","frame_index":0,"kind":"data","monotonic_ns":229210194831583,"payload":{"event_type":"price_change","market":"0xeb66215f2e9faa6449e30a02bab5b8ed7b79a38bf961f6b24d0073c9c2419250","price_changes":[{"asset_id":"69697746896130839564035629862476347944307040470122503199396727085502753297492","best_ask":"0.73","best_bid":"0.72","hash":"f81db5d1afe2059a0687069442981b44717e420c","price":"0.69","side":"BUY","size":"161.23"},{"asset_id":"60386828328910021732068595344565885737045900010034836345809386672230885527307","best_ask":"0.28","best_bid":"0.27","hash":"d8bc561a6e1f8aecb7add9cf821e32b828b804a6","price":"0.31","side":"SELL","size":"161.23"}],"timestamp":"1785127226982"},"payload_hash":"f4d872a5176dd6d6fe898871e6bf10b8045718ac4817faea8fe6e242a5aee98e","raw_frame":"{\"market\":\"0xeb66215f2e9faa6449e30a02bab5b8ed7b79a38bf961f6b24d0073c9c2419250\", \"price_changes\":[{\"asset_id\":\"69697746896130839564035629862476347944307040470122503199396727085502753297492\", \"price\":\"0.69\", \"size\":\"161.23\", \"side\":\"BUY\", \"hash\":\"f81db5d1afe2059a0687069442981b44717e420c\", \"best_bid\":\"0.72\", \"best_ask\":\"0.73\"}, {\"asset_id\":\"60386828328910021732068595344565885737045900010034836345809386672230885527307\", \"price\":\"0.31\", \"size\":\"161.23\", \"side\":\"SELL\", \"hash\":\"d8bc561a6e1f8aecb7add9cf821e32b828b804a6\", \"best_bid\":\"0.27\", \"best_ask\":\"0.28\"}], \"timestamp\":\"1785127226982\", \"event_type\":\"price_change\"}","received_at":"2026-07-27T04:40:26.930428Z","schema_version":"clob-market-ws.price_change.v1","sequence":null,"server_hash":null,"server_timestamp":"1785127226982","session_id":"e9443c7415a0419799bee9cfbb1a9e4d","source":"clob_market_ws"},"received_at":"2026-07-27T04:40:26.930428Z","record_id":"f7c314ec52e20b1de37f9a41e1ec3b08f114f9a31f48d6981a10e5f59be184da","schema_fingerprint":"4aa3821a28b0b7c2400bc59aba4bcc0a76e971dadd19610d3ad38c768e124dc7","schema_version":"edge-lab-recorder.raw.v1","sequence":null,"source":"clob_market_ws"}
{"event_at":"2026-07-27T04:40:26.986000Z","event_fingerprint":"945c4584e4979c2253fa956134898ddfa6a00b6267accfb8d756c5a14e4101d3","payload":{"connection_id":"0f4979d6978d463e9660b042fdcf555f","event_at":"2026-07-27T04:40:26.986000Z","event_type":"price_change","frame_hash":"b2e6a81b4001e84219a26473d129895070a802975e9ab2aeab1358e9e502da6f","frame_index":0,"kind":"data","monotonic_ns":229210201797083,"payload":{"event_type":"price_change","market":"0xeb66215f2e9faa6449e30a02bab5b8ed7b79a38bf961f6b24d0073c9c2419250","price_changes":[{"asset_id":"60386828328910021732068595344565885737045900010034836345809386672230885527307","best_ask":"0.28","best_bid":"0.27","hash":"51256c4bb3d5e1024a206ce349ed8f70872fa075","price":"0.31","side":"SELL","size":"154.16"},{"asset_id":"69697746896130839564035629862476347944307040470122503199396727085502753297492","best_ask":"0.73","best_bid":"0.72","hash":"22bafcbddd4aa2b97f90c3431095f3b26c0c77a5","price":"0.69","side":"BUY","size":"154.16"}],"timestamp":"1785127226986"},"payload_hash":"ec38b531dca8fc02e5cb6548923e9ce4bb468b93b9cfc1a8df99e5d9c1836cc4","raw_frame":"{\"market\":\"0xeb66215f2e9faa6449e30a02bab5b8ed7b79a38bf961f6b24d0073c9c2419250\", \"price_changes\":[{\"asset_id\":\"60386828328910021732068595344565885737045900010034836345809386672230885527307\", \"price\":\"0.31\", \"size\":\"154.16\", \"side\":\"SELL\", \"hash\":\"51256c4bb3d5e1024a206ce349ed8f70872fa075\", \"best_bid\":\"0.27\", \"best_ask\":\"0.28\"}, {\"asset_id\":\"69697746896130839564035629862476347944307040470122503199396727085502753297492\", \"price\":\"0.69\", \"size\":\"154.16\", \"side\":\"BUY\", \"hash\":\"22bafcbddd4aa2b97f90c3431095f3b26c0c77a5\", \"best_bid\":\"0.72\", \"best_ask\":\"0.73\"}], \"timestamp\":\"1785127226986\", \"event_type\":\"price_change\"}","received_at":"2026-07-27T04:40:26.937400Z","schema_version":"clob-market-ws.price_change.v1","sequence":null,"server_hash":null,"server_timestamp":"1785127226986","session_id":"e9443c7415a0419799bee9cfbb1a9e4d","source":"clob_market_ws"},"received_at":"2026-07-27T04:40:26.937400Z","record_id":"037859008ee3165e60ac8abe17bbb87f7f21e84d4f3d44e78ef543e95641856d","schema_fingerprint":"4aa3821a28b0b7c2400bc59aba4bcc0a76e971dadd19610d3ad38c768e124dc7","schema_version":"edge-lab-recorder.raw.v1","sequence":null,"source":"clob_market_ws"}
{"event_at":"2026-07-27T04:40:26.986000Z","event_fingerprint":"0dbac6d85de11e7833f825ef585bc833f6ee4cfd015ae3d10d14828e895ae817","payload":{"connection_id":"0f4979d6978d463e9660b042fdcf555f","event_at":"2026-07-27T04:40:26.986000Z","event_type":"price_change","frame_hash":"1eac1404b9b3acb1f11f7b4aaa64e38030a4b487e5b3fbe9d302ddb3bd53d400","frame_index":0,"kind":"data","monotonic_ns":229210205629000,"payload":{"event_type":"price_change","market":"0xeb66215f2e9faa6449e30a02bab5b8ed7b79a38bf961f6b24d0073c9c2419250","price_changes":[{"asset_id":"69697746896130839564035629862476347944307040470122503199396727085502753297492","best_ask":"0.73","best_bid":"0.72","hash":"22bafcbddd4aa2b97f90c3431095f3b26c0c77a5","price":"0.68","side":"BUY","size":"298.4"},{"asset_id":"60386828328910021732068595344565885737045900010034836345809386672230885527307","best_ask":"0.28","best_bid":"0.27","hash":"51256c4bb3d5e1024a206ce349ed8f70872fa075","price":"0.32","side":"SELL","size":"298.4"}],"timestamp":"1785127226986"},"payload_hash":"b7c8820b26bf37a1c7898b5851729e6b69f1aa408b33ea1c3d725683b27042ae","raw_frame":"{\"market\":\"0xeb66215f2e9faa6449e30a02bab5b8ed7b79a38bf961f6b24d0073c9c2419250\", \"price_changes\":[{\"asset_id\":\"69697746896130839564035629862476347944307040470122503199396727085502753297492\", \"price\":\"0.68\", \"size\":\"298.4\", \"side\":\"BUY\", \"hash\":\"22bafcbddd4aa2b97f90c3431095f3b26c0c77a5\", \"best_bid\":\"0.72\", \"best_ask\":\"0.73\"}, {\"asset_id\":\"60386828328910021732068595344565885737045900010034836345809386672230885527307\", \"price\":\"0.32\", \"size\":\"298.4\", \"side\":\"SELL\", \"hash\":\"51256c4bb3d5e1024a206ce349ed8f70872fa075\", \"best_bid\":\"0.27\", \"best_ask\":\"0.28\"}], \"timestamp\":\"1785127226986\", \"event_type\":\"price_change\"}","received_at":"2026-07-27T04:40:26.941226Z","schema_version":"clob-market-ws.price_change.v1","sequence":null,"server_hash":null,"server_timestamp":"1785127226986","session_id":"e9443c7415a0419799bee9cfbb1a9e4d","source":"clob_market_ws"},"received_at":"2026-07-27T04:40:26.941226Z","record_id":"773b4b63682b8ff1ed6bac26e908975c5cb05287fbc8e5b4d7f17fb38f8624a0","schema_fingerprint":"4aa3821a28b0b7c2400bc59aba4bcc0a76e971dadd19610d3ad38c768e124dc7","schema_version":"edge-lab-recorder.raw.v1","sequence":null,"source":"clob_market_ws"}
