{"event_at":"2026-07-27T04:40:26.986000Z","event_fingerprint":"570f4306ce7740adc9012f52804ba6a29a05c7ae59c330d54be7187a48f90562","payload":{"connection_id":"0f4979d6978d463e9660b042fdcf555f","event_at":"2026-07-27T04:40:26.986000Z","event_type":"price_change","frame_hash":"6c6b2c927aa1ff73fc96b87e6e9ca7d7d98367f4cc8e79216678c6b5e90c12b2","frame_index":0,"kind":"data","monotonic_ns":229210246571791,"payload":{"event_type":"price_change","market":"0xeb66215f2e9faa6449e30a02bab5b8ed7b79a38bf961f6b24d0073c9c2419250","price_changes":[{"asset_id":"60386828328910021732068595344565885737045900010034836345809386672230885527307","best_ask":"0.28","best_bid":"0.27","hash":"51256c4bb3d5e1024a206ce349ed8f70872fa075","price":"0.3","side":"SELL","size":"41.94"},{"asset_id":"69697746896130839564035629862476347944307040470122503199396727085502753297492","best_ask":"0.73","best_bid":"0.72","hash":"22bafcbddd4aa2b97f90c3431095f3b26c0c77a5","price":"0.7","side":"BUY","size":"41.94"}],"timestamp":"1785127226986"},"payload_hash":"06e8bbbcba35be8d6eb5d905a7b27b4fe992df4fbc027a4107279196c6c35c0f","raw_frame":"{\"market\":\"0xeb66215f2e9faa6449e30a02bab5b8ed7b79a38bf961f6b24d0073c9c2419250\", \"price_changes\":[{\"asset_id\":\"60386828328910021732068595344565885737045900010034836345809386672230885527307\", \"price\":\"0.3\", \"size\":\"41.94\", \"side\":\"SELL\", \"hash\":\"51256c4bb3d5e1024a206ce349ed8f70872fa075\", \"best_bid\":\"0.27\", \"best_ask\":\"0.28\"}, {\"asset_id\":\"69697746896130839564035629862476347944307040470122503199396727085502753297492\", \"price\":\"0.7\", \"size\":\"41.94\", \"side\":\"BUY\", \"hash\":\"22bafcbddd4aa2b97f90c3431095f3b26c0c77a5\", \"best_bid\":\"0.72\", \"best_ask\":\"0.73\"}], \"timestamp\":\"1785127226986\", \"event_type\":\"price_change\"}","received_at":"2026-07-27T04:40:26.982169Z","schema_version":"clob-market-ws.price_change.v1","sequence":null,"server_hash":null,"server_timestamp":"1785127226986","session_id":"e9443c7415a0419799bee9cfbb1a9e4d","source":"clob_market_ws"},"received_at":"2026-07-27T04:40:26.982169Z","record_id":"ea54bce05dcb152a14de4394cd7b0e9442fe440eee877da02efb03bd8824b2a8","schema_fingerprint":"4aa3821a28b0b7c2400bc59aba4bcc0a76e971dadd19610d3ad38c768e124dc7","schema_version":"edge-lab-recorder.raw.v1","sequence":null,"source":"clob_market_ws"}
{"event_at":"2026-07-27T04:40:26.996000Z","event_fingerprint":"79ced27bc968be42bd45df2459a5c9f611520a9694c32e9fdf4000f4c6b82e32","payload":{"connection_id":"0f4979d6978d463e9660b042fdcf555f","event_at":"2026-07-27T04:40:26.996000Z","event_type":"price_change","frame_hash":"87e8b12042e431313c9f0c2dd9ee68cbc7630a6ae869308ebcbec48a00bee74b","frame_index":0,"kind":"data","monotonic_ns":229210273940666,"payload":{"event_type":"price_change","market":"0xeb66215f2e9faa6449e30a02bab5b8ed7b79a38bf961f6b24d0073c9c2419250","price_changes":[{"asset_id":"69697746896130839564035629862476347944307040470122503199396727085502753297492","best_ask":"0.73","best_bid":"0.72","hash":"b3fbba3789aa646b95922b2502c1a09ae08bd6ca","price":"0.7","side":"BUY","size":"84.94"},{"asset_id":"60386828328910021732068595344565885737045900010034836345809386672230885527307","best_ask":"0.28","best_bid":"0.27","hash":"4993d15232a488f2157f2df4ab62733953befed8","price":"0.3","side":"SELL","size":"84.94"}],"timestamp":"1785127226996"},"payload_hash":"7f0c5f32bbdfcd06c4ff0460e322eca5764df318445897d8445764f1b3976d42","raw_frame":"{\"market\":\"0xeb66215f2e9faa6449e30a02bab5b8ed7b79a38bf961f6b24d0073c9c2419250\", \"price_changes\":[{\"asset_id\":\"69697746896130839564035629862476347944307040470122503199396727085502753297492\", \"price\":\"0.7\", \"size\":\"84.94\", \"side\":\"BUY\", \"hash\":\"b3fbba3789aa646b95922b2502c1a09ae08bd6ca\", \"best_bid\":\"0.72\", \"best_ask\":\"0.73\"}, {\"asset_id\":\"60386828328910021732068595344565885737045900010034836345809386672230885527307\", \"price\":\"0.3\", \"size\":\"84.94\", \"side\":\"SELL\", \"hash\":\"4993d15232a488f2157f2df4ab62733953befed8\", \"best_bid\":\"0.27\", \"best_ask\":\"0.28\"}], \"timestamp\":\"1785127226996\", \"event_type\":\"price_change\"}","received_at":"2026-07-27T04:40:27.009536Z","schema_version":"clob-market-ws.price_change.v1","sequence":null,"server_hash":null,"server_timestamp":"1785127226996","session_id":"e9443c7415a0419799bee9cfbb1a9e4d","source":"clob_market_ws"},"received_at":"2026-07-27T04:40:27.009536Z","record_id":"f7b64c6242fa5a0e8669b9c204fc55a4ca4f75075a757cdaf6dd9412e181c172","schema_fingerprint":"4aa3821a28b0b7c2400bc59aba4bcc0a76e971dadd19610d3ad38c768e124dc7","schema_version":"edge-lab-recorder.raw.v1","sequence":null,"source":"clob_market_ws"}
{"event_at":"2026-07-27T04:40:27.005000Z","event_fingerprint":"6b2dbc1a3a5f93a6b411c598da5948031e33b276296bec8687dbd4b2b7f12ddc","payload":{"connection_id":"0f4979d6978d463e9660b042fdcf555f","event_at":"2026-07-27T04:40:27.005000Z","event_type":"price_change","frame_hash":"c1042bf068daa7b7d037bf977bc7bd413f67fcd685b3a63e43af46a3f8c3b6bc","frame_index":0,"kind":"data","monotonic_ns":229210278509291,"payload":{"event_type":"price_change","market":"0xeb66215f2e9faa6449e30a02bab5b8ed7b79a38bf961f6b24d0073c9c2419250","price_changes":[{"asset_id":"69697746896130839564035629862476347944307040470122503199396727085502753297492","best_ask":"0.73","best_bid":"0.72","hash":"dbd71ff3057a961e6721b4153a3468e910a113c3","price":"0.03","side":"BUY","size":"618.1"},{"asset_id":"60386828328910021732068595344565885737045900010034836345809386672230885527307","best_ask":"0.28","best_bid":"0.27","hash":"5b12188ee2fae91550a83b4cca93355393c79a15","price":"0.97","side":"SELL","size":"618.1"}],"timestamp":"1785127227005"},"payload_hash":"c363e21ca0e8f4a6601f44489369cab9776e763d278e9af7f07da557c361cffa","raw_frame":"{\"market\":\"0xeb66215f2e9faa6449e30a02bab5b8ed7b79a38bf961f6b24d0073c9c2419250\", \"price_changes\":[{\"asset_id\":\"69697746896130839564035629862476347944307040470122503199396727085502753297492\", \"price\":\"0.03\", \"size\":\"618.1\", \"side\":\"BUY\", \"hash\":\"dbd71ff3057a961e6721b4153a3468e910a113c3\", \"best_bid\":\"0.72\", \"best_ask\":\"0.73\"}, {\"asset_id\":\"60386828328910021732068595344565885737045900010034836345809386672230885527307\", \"price\":\"0.97\", \"size\":\"618.1\", \"side\":\"SELL\", \"hash\":\"5b12188ee2fae91550a83b4cca93355393c79a15\", \"best_bid\":\"0.27\", \"best_ask\":\"0.28\"}], \"timestamp\":\"1785127227005\", \"event_type\":\"price_change\"}","received_at":"2026-07-27T04:40:27.014106Z","schema_version":"clob-market-ws.price_change.v1","sequence":null,"server_hash":null,"server_timestamp":"1785127227005","session_id":"e9443c7415a0419799bee9cfbb1a9e4d","source":"clob_market_ws"},"received_at":"2026-07-27T04:40:27.014106Z","record_id":"b1a23c3f649a2e5bf4c2a22822c5f0bd822ec824df6b506cd219ed624b18a589","schema_fingerprint":"4aa3821a28b0b7c2400bc59aba4bcc0a76e971dadd19610d3ad38c768e124dc7","schema_version":"edge-lab-recorder.raw.v1","sequence":null,"source":"clob_market_ws"}
{"event_at":"2026-07-27T04:40:27.015000Z","event_fingerprint":"4e23da1220d94ca4340e96bc7b2c9780fc1255982b5ef37596e30a5d182eebc7","payload":{"connection_id":"0f4979d6978d463e9660b042fdcf555f","event_at":"2026-07-27T04:40:27.015000Z","event_type":"price_change","frame_hash":"9722413b214091613ac9f9f8555f51793875a5d6f852014d22564c9d402f3616","frame_index":0,"kind":"data","monotonic_ns":229210282394666,"payload":{"event_type":"price_change","market":"0xeb66215f2e9faa6449e30a02bab5b8ed7b79a38bf961f6b24d0073c9c2419250","price_changes":[{"asset_id":"69697746896130839564035629862476347944307040470122503199396727085502753297492","best_ask":"0.73","best_bid":"0.72","hash":"a5d66e4d8e697540d41b4056ee93cc0a5c62530b","price":"0.01","side":"BUY","size":"5638.02"},{"asset_id":"60386828328910021732068595344565885737045900010034836345809386672230885527307","best_ask":"0.28","best_bid":"0.27","hash":"d0f2cc962d67fc900be6a390b79d9a7bb7c3bd9d","price":"0.99","side":"SELL","size":"5638.02"}],"timestamp":"1785127227015"},"payload_hash":"c8edcde492a7b3f670e6f84f59c13661151aba4f550512b99ea2d455566a4b1d","raw_frame":"{\"market\":\"0xeb66215f2e9faa6449e30a02bab5b8ed7b79a38bf961f6b24d0073c9c2419250\", \"price_changes\":[{\"asset_id\":\"69697746896130839564035629862476347944307040470122503199396727085502753297492\", \"price\":\"0.01\", \"size\":\"5638.02\", \"side\":\"BUY\", \"hash\":\"a5d66e4d8e697540d41b4056ee93cc0a5c62530b\", \"best_bid\":\"0.72\", \"best_ask\":\"0.73\"}, {\"asset_id\":\"60386828328910021732068595344565885737045900010034836345809386672230885527307\", \"price\":\"0.99\", \"size\":\"5638.02\", \"side\":\"SELL\", \"hash\":\"d0f2cc962d67fc900be6a390b79d9a7bb7c3bd9d\", \"best_bid\":\"0.27\", \"best_ask\":\"0.28\"}], \"timestamp\":\"1785127227015\", \"event_type\":\"price_change\"}","received_at":"2026-07-27T04:40:27.017993Z","schema_version":"clob-market-ws.price_change.v1","sequence":null,"server_hash":null,"server_timestamp":"1785127227015","session_id":"e9443c7415a0419799bee9cfbb1a9e4d","source":"clob_market_ws"},"received_at":"2026-07-27T04:40:27.017993Z","record_id":"06d709b31bc3d5a6d894ceb362ba0695c3f77af46a6dfe692e6afd2c1741a289","schema_fingerprint":"4aa3821a28b0b7c2400bc59aba4bcc0a76e971dadd19610d3ad38c768e124dc7","schema_version":"edge-lab-recorder.raw.v1","sequence":null,"source":"clob_market_ws"}
{"event_at":"2026-07-27T04:40:27.016000Z","event_fingerprint":"42a8a8f0e38c4d0d54dbc20d65068f9c0456929f778c1b79bce289d49fb25aa6","payload":{"connection_id":"0f4979d6978d463e9660b042fdcf555f","event_at":"2026-07-27T04:40:27.016000Z","event_type":"price_change","frame_hash":"e643cbabe644974cb96dce0e8c7c3c548cbab9f2d2d230bd706f271fc0affa61","frame_index":0,"kind":"data","monotonic_ns":229210285754416,"payload":{"event_type":"price_change","market":"0xeb66215f2e9faa6449e30a02bab5b8ed7b79a38bf961f6b24d0073c9c2419250","price_changes":[{"asset_id":"69697746896130839564035629862476347944307040470122503199396727085502753297492","best_ask":"0.73","best_bid":"0.72","hash":"13c4e817df718b33926a23dfaa756064e2199c1f","price":"0.71","side":"BUY","size":"28.59"},{"asset_id":"60386828328910021732068595344565885737045900010034836345809386672230885527307","best_ask":"0.28","best_bid":"0.27","hash":"ce6b4b0755ed07b636e302c9412173486f8f3c5d","price":"0.29","side":"SELL","size":"28.59"}],"timestamp":"1785127227016"},"payload_hash":"daa02c68f3a935ed9f107172ea9758a48683a01a7d66c538384cddc66871ffbd","raw_frame":"{\"market\":\"0xeb66215f2e9faa6449e30a02bab5b8ed7b79a38bf961f6b24d0073c9c2419250\", \"price_changes\":[{\"asset_id\":\"69697746896130839564035629862476347944307040470122503199396727085502753297492\", \"price\":\"0.71\", \"size\":\"28.59\", \"side\":\"BUY\", \"hash\":\"13c4e817df718b33926a23dfaa756064e2199c1f\", \"best_bid\":\"0.72\", \"best_ask\":\"0.73\"}, {\"asset_id\":\"60386828328910021732068595344565885737045900010034836345809386672230885527307\", \"price\":\"0.29\", \"size\":\"28.59\", \"side\":\"SELL\", \"hash\":\"ce6b4b0755ed07b636e302c9412173486f8f3c5d\", \"best_bid\":\"0.27\", \"best_ask\":\"0.28\"}], \"timestamp\":\"1785127227016\", \"event_type\":\"price_change\"}","received_at":"2026-07-27T04:40:27.021350Z","schema_version":"clob-market-ws.price_change.v1","sequence":null,"server_hash":null,"server_timestamp":"1785127227016","session_id":"e9443c7415a0419799bee9cfbb1a9e4d","source":"clob_market_ws"},"received_at":"2026-07-27T04:40:27.021350Z","record_id":"ed5487cd3f10cf3d095e57048b9818ce923d22f31f59615016382ff912255a5f","schema_fingerprint":"4aa3821a28b0b7c2400bc59aba4bcc0a76e971dadd19610d3ad38c768e124dc7","schema_version":"edge-lab-recorder.raw.v1","sequence":null,"source":"clob_market_ws"}
{"event_at":"2026-07-27T04:40:27.024000Z","event_fingerprint":"7bbba3fa5fdf2dbe19da8575863f335eef9a33ef3aa3c26091117e946e61dbee","payload":{"connection_id":"0f4979d6978d463e9660b042fdcf555f","event_at":"2026-07-27T04:40:27.024000Z","event_type":"price_change","frame_hash":"7354c34b6d5b33017ce3675f346335b7ce1260d860b353e67a718333736e126b","frame_index":0,"kind":"data","monotonic_ns":229210290200666,"payload":{"event_type":"price_change","market":"0xeb66215f2e9faa6449e30a02bab5b8ed7b79a38bf961f6b24d0073c9c2419250","price_changes":[{"asset_id":"60386828328910021732068595344565885737045900010034836345809386672230885527307","best_ask":"0.28","best_bid":"0.27","hash":"8cd2ce2a79557d56ad69732a2d6885eab0ab201e","price":"0.22","side":"BUY","size":"54.86"},{"asset_id":"69697746896130839564035629862476347944307040470122503199396727085502753297492","best_ask":"0.73","best_bid":"0.72","hash":"488b2b3f9f968c68c7f2f3a8482e542d0f9a9324","price":"0.78","side":"SELL","size":"54.86"}],"timestamp":"1785127227024"},"payload_hash":"f3dd6bb5a42621eda364322c52bc437c690f453523d050059b555bf6da22af9f","raw_frame":"{\"market\":\"0xeb66215f2e9faa6449e30a02bab5b8ed7b79a38bf961f6b24d0073c9c2419250\", \"price_changes\":[{\"asset_id\":\"60386828328910021732068595344565885737045900010034836345809386672230885527307\", \"price\":\"0.22\", \"size\":\"54.86\", \"side\":\"BUY\", \"hash\":\"8cd2ce2a79557d56ad69732a2d6885eab0ab201e\", \"best_bid\":\"0.27\", \"best_ask\":\"0.28\"}, {\"asset_id\":\"69697746896130839564035629862476347944307040470122503199396727085502753297492\", \"price\":\"0.78\", \"size\":\"54.86\", \"side\":\"SELL\", \"hash\":\"488b2b3f9f968c68c7f2f3a8482e542d0f9a9324\", \"best_bid\":\"0.72\", \"best_ask\":\"0.73\"}], \"timestamp\":\"1785127227024\", \"event_type\":\"price_change\"}","received_at":"2026-07-27T04:40:27.025799Z","schema_version":"clob-market-ws.price_change.v1","sequence":null,"server_hash":null,"server_timestamp":"1785127227024","session_id":"e9443c7415a0419799bee9cfbb1a9e4d","source":"clob_market_ws"},"received_at":"2026-07-27T04:40:27.025799Z","record_id":"fd3e42762b9303733fabdfc6281c4c530b6f401b7592b69c0c2784531844ecff","schema_fingerprint":"4aa3821a28b0b7c2400bc59aba4bcc0a76e971dadd19610d3ad38c768e124dc7","schema_version":"edge-lab-recorder.raw.v1","sequence":null,"source":"clob_market_ws"}
{"event_at":"2026-07-27T04:40:27.025000Z","event_fingerprint":"0fb3778cd36ff614de62fab66ae30b9c6cbcbee46f5787d1420250e58eb9611e","payload":{"connection_id":"0f4979d6978d463e9660b042fdcf555f","event_at":"2026-07-27T04:40:27.025000Z","event_type":"price_change","frame_hash":"282497fc4eca40f1be1b407e7d3c57a96c1144768b5303bf60ff180aa325193a","frame_index":0,"kind":"data","monotonic_ns":229210296774458,"payload":{"event_type":"price_change","market":"0xeb66215f2e9faa6449e30a02bab5b8ed7b79a38bf961f6b24d0073c9c2419250","price_changes":[{"asset_id":"60386828328910021732068595344565885737045900010034836345809386672230885527307","best_ask":"0.28","best_bid":"0.27","hash":"e6291e6b1db98247d2c05073ac4e1c23ebfc4e7f","price":"0.01","side":"BUY","size":"5698.02"},{"asset_id":"69697746896130839564035629862476347944307040470122503199396727085502753297492","best_ask":"0.73","best_bid":"0.72","hash":"4d809c77e54a67ed85fa3bcbcd0083e4e9043d7f","price":"0.99","side":"SELL","size":"5698.02"}],"timestamp":"1785127227025"},"payload_hash":"866c22afcd11b46f8b978172a727bd6a10ccb5ab5c5c9ae3910ffe22305cf17e","raw_frame":"{\"market\":\"0xeb66215f2e9faa6449e30a02bab5b8ed7b79a38bf961f6b24d0073c9c2419250\", \"price_changes\":[{\"asset_id\":\"60386828328910021732068595344565885737045900010034836345809386672230885527307\", \"price\":\"0.01\", \"size\":\"5698.02\", \"side\":\"BUY\", \"hash\":\"e6291e6b1db98247d2c05073ac4e1c23ebfc4e7f\", \"best_bid\":\"0.27\", \"best_ask\":\"0.28\"}, {\"asset_id\":\"69697746896130839564035629862476347944307040470122503199396727085502753297492\", \"price\":\"0.99\", \"size\":\"5698.02\", \"side\":\"SELL\", \"hash\":\"4d809c77e54a67ed85fa3bcbcd0083e4e9043d7f\", \"best_bid\":\"0.72\", \"best_ask\":\"0.73\"}], \"timestamp\":\"1785127227025\", \"event_type\":\"price_change\"}","received_at":"2026-07-27T04:40:27.032372Z","schema_version":"clob-market-ws.price_change.v1","sequence":null,"server_hash":null,"server_timestamp":"1785127227025","session_id":"e9443c7415a0419799bee9cfbb1a9e4d","source":"clob_market_ws"},"received_at":"2026-07-27T04:40:27.032372Z","record_id":"55d164b5174f59bb70f99ab2b9dd4617dbf17f0caffc6b9efed0d08ade701302","schema_fingerprint":"4aa3821a28b0b7c2400bc59aba4bcc0a76e971dadd19610d3ad38c768e124dc7","schema_version":"edge-lab-recorder.raw.v1","sequence":null,"source":"clob_market_ws"}
{"event_at":"2026-07-27T04:40:27.026000Z","event_fingerprint":"24a96732de8ff76bf94914f6052d95ba8df7ca772930dd508d68b06496af2c03","payload":{"connection_id":"0f4979d6978d463e9660b042fdcf555f","event_at":"2026-07-27T04:40:27.026000Z","event_type":"price_change","frame_hash":"2bcd36f7919abf81c0db5946a50d50042b3dc3b1d3aa5ab535484ec78275c904","frame_index":0,"kind":"data","monotonic_ns":229210302829208,"payload":{"event_type":"price_change","market":"0xeb66215f2e9faa6449e30a02bab5b8ed7b79a38bf961f6b24d0073c9c2419250","price_changes":[{"asset_id":"60386828328910021732068595344565885737045900010034836345809386672230885527307","best_ask":"0.28","best_bid":"0.27","hash":"d8f3932c630f6775d0ab15bb1a4d7a1acdeffdcc","price":"0.22","side":"BUY","size":"49.86"},{"asset_id":"69697746896130839564035629862476347944307040470122503199396727085502753297492","best_ask":"0.73","best_bid":"0.72","hash":"221020e782fd390ae5ed59a15148d4177dc2f5ac","price":"0.78","side":"SELL","size":"49.86"}],"timestamp":"1785127227026"},"payload_hash":"cfab2dfef107821311216478dfd2cd08bbd9ca3c34600792d3d2d66cc1b1ca1a","raw_frame":"{\"market\":\"0xeb66215f2e9faa6449e30a02bab5b8ed7b79a38bf961f6b24d0073c9c2419250\", \"price_changes\":[{\"asset_id\":\"60386828328910021732068595344565885737045900010034836345809386672230885527307\", \"price\":\"0.22\", \"size\":\"49.86\", \"side\":\"BUY\", \"hash\":\"d8f3932c630f6775d0ab15bb1a4d7a1acdeffdcc\", \"best_bid\":\"0.27\", \"best_ask\":\"0.28\"}, {\"asset_id\":\"69697746896130839564035629862476347944307040470122503199396727085502753297492\", \"price\":\"0.78\", \"size\":\"49.86\", \"side\":\"SELL\", \"hash\":\"221020e782fd390ae5ed59a15148d4177dc2f5ac\", \"best_bid\":\"0.72\", \"best_ask\":\"0.73\"}], \"timestamp\":\"1785127227026\", \"event_type\":\"price_change\"}","received_at":"2026-07-27T04:40:27.038423Z","schema_version":"clob-market-ws.price_change.v1","sequence":null,"server_hash":null,"server_timestamp":"1785127227026","session_id":"e9443c7415a0419799bee9cfbb1a9e4d","source":"clob_market_ws"},"received_at":"2026-07-27T04:40:27.038423Z","record_id":"9faf25e494666d02b9a170c17d3aed454ea940b3f855c6a24dacb602aae37030","schema_fingerprint":"4aa3821a28b0b7c2400bc59aba4bcc0a76e971dadd19610d3ad38c768e124dc7","schema_version":"edge-lab-recorder.raw.v1","sequence":null,"source":"clob_market_ws"}
{"event_at":"2026-07-27T04:40:27.029000Z","event_fingerprint":"dac013cbb163463c259e51f76e87b9a36ff8718f28a5c2038c9fc6abc15965ba","payload":{"connection_id":"0f4979d6978d463e9660b042fdcf555f","event_at":"2026-07-27T04:40:27.029000Z","event_type":"price_change","frame_hash":"7073cff73c5fbffcf39027df72d1094793f4cbf239e5e8eb5b2b7f3aa5c60a83","frame_index":0,"kind":"data","monotonic_ns":229210306571833,"payload":{"event_type":"price_change","market":"0xeb66215f2e9faa6449e30a02bab5b8ed7b79a38bf961f6b24d0073c9c2419250","price_changes":[{"asset_id":"60386828328910021732068595344565885737045900010034836345809386672230885527307","best_ask":"0.28","best_bid":"0.27","hash":"3442d8d7ce9ba8825e0a807d80421ae2bcbb50b3","price":"0.01","side":"BUY","size":"5703.02"},{"asset_id":"69697746896130839564035629862476347944307040470122503199396727085502753297492","best_ask":"0.73","best_bid":"0.72","hash":"469891921f09107108752a5c474c8ffb397a3612","price":"0.99","side":"SELL","size":"5703.02"}],"timestamp":"1785127227029"},"payload_hash":"60a4e58fbd3fad09ea99c377a38fd5e54ad48a5d28b3afb33a5eeb1059d3a233","raw_frame":"{\"market\":\"0xeb66215f2e9faa6449e30a02bab5b8ed7b79a38bf961f6b24d0073c9c2419250\", \"price_changes\":[{\"asset_id\":\"60386828328910021732068595344565885737045900010034836345809386672230885527307\", \"price\":\"0.01\", \"size\":\"5703.02\", \"side\":\"BUY\", \"hash\":\"3442d8d7ce9ba8825e0a807d80421ae2bcbb50b3\", \"best_bid\":\"0.27\", \"best_ask\":\"0.28\"}, {\"asset_id\":\"69697746896130839564035629862476347944307040470122503199396727085502753297492\", \"price\":\"0.99\", \"size\":\"5703.02\", \"side\":\"SELL\", \"hash\":\"469891921f09107108752a5c474c8ffb397a3612\", \"best_bid\":\"0.72\", \"best_ask\":\"0.73\"}], \"timestamp\":\"1785127227029\", \"event_type\":\"price_change\"}","received_at":"2026-07-27T04:40:27.042171Z","schema_version":"clob-market-ws.price_change.v1","sequence":null,"server_hash":null,"server_timestamp":"1785127227029","session_id":"e9443c7415a0419799bee9cfbb1a9e4d","source":"clob_market_ws"},"received_at":"2026-07-27T04:40:27.042171Z","record_id":"57ee092a1d169209400a7a0f79650bbec4a3fdd442c3e5b5877783b8c624d773","schema_fingerprint":"4aa3821a28b0b7c2400bc59aba4bcc0a76e971dadd19610d3ad38c768e124dc7","schema_version":"edge-lab-recorder.raw.v1","sequence":null,"source":"clob_market_ws"}
{"event_at":"2026-07-27T04:40:27.041000Z","event_fingerprint":"f229782650ca397e4c96c4ab5a2b56b4ec66e14219e2805b2f2a1b603f331231","payload":{"connection_id":"0f4979d6978d463e9660b042fdcf555f","event_at":"2026-07-27T04:40:27.041000Z","event_type":"price_change","frame_hash":"0d2237aa448dab57f49e3183f95ae385bf6b1fd56635f40e4eaabf6e2b362291","frame_index":0,"kind":"data","monotonic_ns":229210314048750,"payload":{"event_type":"price_change","market":"0xeb66215f2e9faa6449e30a02bab5b8ed7b79a38bf961f6b24d0073c9c2419250","price_changes":[{"asset_id":"60386828328910021732068595344565885737045900010034836345809386672230885527307","best_ask":"0.28","best_bid":"0.27","hash":"98e96437ef62e974fef9d9de1eb14ba5e19478f5","price":"0.16","side":"BUY","size":"177"},{"asset_id":"69697746896130839564035629862476347944307040470122503199396727085502753297492","best_ask":"0.73","best_bid":"0.72","hash":"c6b29f55673edf3c235affa8faf52fe4c2befc46","price":"0.84","side":"SELL","size":"177"}],"timestamp":"1785127227041"},"payload_hash":"9fb35f419762183ece46ea8fd6c0234e4de533dc45ad5c0dbc6e22322761dd73","raw_frame":"{\"market\":\"0xeb66215f2e9faa6449e30a02bab5b8ed7b79a38bf961f6b24d0073c9c2419250\", \"price_changes\":[{\"asset_id\":\"60386828328910021732068595344565885737045900010034836345809386672230885527307\", \"price\":\"0.16\", \"size\":\"177\", \"side\":\"BUY\", \"hash\":\"98e96437ef62e974fef9d9de1eb14ba5e19478f5\", \"best_bid\":\"0.27\", \"best_ask\":\"0.28\"}, {\"asset_id\":\"69697746896130839564035629862476347944307040470122503199396727085502753297492\", \"price\":\"0.84\", \"size\":\"177\", \"side\":\"SELL\", \"hash\":\"c6b29f55673edf3c235affa8faf52fe4c2befc46\", \"best_bid\":\"0.72\", \"best_ask\":\"0.73\"}], \"timestamp\":\"1785127227041\", \"event_type\":\"price_change\"}","received_at":"2026-07-27T04:40:27.049647Z","schema_version":"clob-market-ws.price_change.v1","sequence":null,"server_hash":null,"server_timestamp":"1785127227041","session_id":"e9443c7415a0419799bee9cfbb1a9e4d","source":"clob_market_ws"},"received_at":"2026-07-27T04:40:27.049647Z","record_id":"9e779d629301008a6bfefc609a78c2da1c5a076ef0bf0773841d2a5b025c369b","schema_fingerprint":"4aa3821a28b0b7c2400bc59aba4bcc0a76e971dadd19610d3ad38c768e124dc7","schema_version":"edge-lab-recorder.raw.v1","sequence":null,"source":"clob_market_ws"}
{"event_at":"2026-07-27T04:40:27.044000Z","event_fingerprint":"19921211888922af608417a2f168b195b5df729ee928136908ed62e5d20b12cf","payload":{"connection_id":"0f4979d6978d463e9660b042fdcf555f","event_at":"2026-07-27T04:40:27.044000Z","event_type":"price_change","frame_hash":"0379600fe1994a46ac4ba38fa81611d2448df81ca15df852ca7b11d9fcc0707b","frame_index":0,"kind":"data","monotonic_ns":229210319769916,"payload":{"event_type":"price_change","market":"0xeb66215f2e9faa6449e30a02bab5b8ed7b79a38bf961f6b24d0073c9c2419250","price_changes":[{"asset_id":"69697746896130839564035629862476347944307040470122503199396727085502753297492","best_ask":"0.73","best_bid":"0.72","hash":"fe09d96d879adb439ce9e007475edeca92cd5332","price":"0.01","side":"BUY","size":"5633.02"},{"asset_id":"60386828328910021732068595344565885737045900010034836345809386672230885527307","best_ask":"0.28","best_bid":"0.27","hash":"26d15e8ca7acaca8702019572ff41e0e1301ac51","price":"0.99","side":"SELL","size":"5633.02"}],"timestamp":"1785127227044"},"payload_hash":"2fa9cb8ad8b97467e4c72a8632f8f7a3963a6d151a4713a3d141d93d3972b9b3","raw_frame":"{\"market\":\"0xeb66215f2e9faa6449e30a02bab5b8ed7b79a38bf961f6b24d0073c9c2419250\", \"price_changes\":[{\"asset_id\":\"69697746896130839564035629862476347944307040470122503199396727085502753297492\", \"price\":\"0.01\", \"size\":\"5633.02\", \"side\":\"BUY\", \"hash\":\"fe09d96d879adb439ce9e007475edeca92cd5332\", \"best_bid\":\"0.72\", \"best_ask\":\"0.73\"}, {\"asset_id\":\"60386828328910021732068595344565885737045900010034836345809386672230885527307\", \"price\":\"0.99\", \"size\":\"5633.02\", \"side\":\"SELL\", \"hash\":\"26d15e8ca7acaca8702019572ff41e0e1301ac51\", \"best_bid\":\"0.27\", \"best_ask\":\"0.28\"}], \"timestamp\":\"1785127227044\", \"event_type\":\"price_change\"}","received_at":"2026-07-27T04:40:27.055366Z","schema_version":"clob-market-ws.price_change.v1","sequence":null,"server_hash":null,"server_timestamp":"1785127227044","session_id":"e9443c7415a0419799bee9cfbb1a9e4d","source":"clob_market_ws"},"received_at":"2026-07-27T04:40:27.055366Z","record_id":"9df8d838845795f8efec0ee3194b0a482304948fa5a2fdfa8c8f20386fe35fe4","schema_fingerprint":"4aa3821a28b0b7c2400bc59aba4bcc0a76e971dadd19610d3ad38c768e124dc7","schema_version":"edge-lab-recorder.raw.v1","sequence":null,"source":"clob_market_ws"}
{"event_at":"2026-07-27T04:40:27.052000Z","event_fingerprint":"130b922a94d79675966bfab73e7987d73a063cab7d836588edf192892e306f6f","payload":{"connection_id":"0f4979d6978d463e9660b042fdcf555f","event_at":"2026-07-27T04:40:27.052000Z","event_type":"price_change","frame_hash":"7388ce5e4c7828b536f1b65e566ea64a69eefbedd2e00c8162dfc20e5d7a07bc","frame_index":0,"kind":"data","monotonic_ns":229210328480250,"payload":{"event_type":"price_change","market":"0xeb66215f2e9faa6449e30a02bab5b8ed7b79a38bf961f6b24d0073c9c2419250","price_changes":[{"asset_id":"60386828328910021732068595344565885737045900010034836345809386672230885527307","best_ask":"0.28","best_bid":"0.27","hash":"13a628b008c88983d64472fb8a9d6be04fbe8364","price":"0.01","side":"BUY","size":"5698.02"},{"asset_id":"69697746896130839564035629862476347944307040470122503199396727085502753297492","best_ask":"0.73","best_bid":"0.72","hash":"a060e983a79bcf5f7c65218fd4422849a948ccce","price":"0.99","side":"SELL","size":"5698.02"}],"timestamp":"1785127227052"},"payload_hash":"d45f9dabb978c9ff3e57814c71125ac42d41668eda5bcc79eec29926f2bdf325","raw_frame":"{\"market\":\"0xeb66215f2e9faa6449e30a02bab5b8ed7b79a38bf961f6b24d0073c9c2419250\", \"price_changes\":[{\"asset_id\":\"60386828328910021732068595344565885737045900010034836345809386672230885527307\", \"price\":\"0.01\", \"size\":\"5698.02\", \"side\":\"BUY\", \"hash\":\"13a628b008c88983d64472fb8a9d6be04fbe8364\", \"best_bid\":\"0.27\", \"best_ask\":\"0.28\"}, {\"asset_id\":\"69697746896130839564035629862476347944307040470122503199396727085502753297492\", \"price\":\"0.99\", \"size\":\"5698.02\", \"side\":\"SELL\", \"hash\":\"a060e983a79bcf5f7c65218fd4422849a948ccce\", \"best_bid\":\"0.72\", \"best_ask\":\"0.73\"}], \"timestamp\":\"1785127227052\", \"event_type\":\"price_change\"}","received_at":"2026-07-27T04:40:27.064073Z","schema_version":"clob-market-ws.price_change.v1","sequence":null,"server_hash":null,"server_timestamp":"1785127227052","session_id":"e9443c7415a0419799bee9cfbb1a9e4d","source":"clob_market_ws"},"received_at":"2026-07-27T04:40:27.064073Z","record_id":"d281b2f2987f1904f35845cc70ba5aed342158f419b17d673b9abadec44fddfe","schema_fingerprint":"4aa3821a28b0b7c2400bc59aba4bcc0a76e971dadd19610d3ad38c768e124dc7","schema_version":"edge-lab-recorder.raw.v1","sequence":null,"source":"clob_market_ws"}
{"event_at":"2026-07-27T04:40:27.055000Z","event_fingerprint":"0708059579c7658934aea34600f06e6027efa4eb74c4d1a352b68254c8aa4625","payload":{"connection_id":"0f4979d6978d463e9660b042fdcf555f","event_at":"2026-07-27T04:40:27.055000Z","event_type":"price_change","frame_hash":"c44bd88d410f0fe10ab87fa63ca76210c6049d638baa425ba59a6ae09e481257","frame_index":0,"kind":"data","monotonic_ns":229210333185125,"payload":{"event_type":"price_change","market":"0xeb66215f2e9faa6449e30a02bab5b8ed7b79a38bf961f6b24d0073c9c2419250","price_changes":[{"asset_id":"69697746896130839564035629862476347944307040470122503199396727085502753297492","best_ask":"0.73","best_bid":"0.72","hash":"d4dced32c0f959cab191ea0423ff761c210feb7c","price":"0.03","side":"BUY","size":"613.1"},{"asset_id":"60386828328910021732068595344565885737045900010034836345809386672230885527307","best_ask":"0.28","best_bid":"0.27","hash":"eb9cf7442b7d79fc208aa6e873fcd1147c663001","price":"0.97","side":"SELL","size":"613.1"}],"timestamp":"1785127227055"},"payload_hash":"ddea71721e5804ea0fc3eaa1cbdcbeec316136954c311578531545ba57dbc292","raw_frame":"{\"market\":\"0xeb66215f2e9faa6449e30a02bab5b8ed7b79a38bf961f6b24d0073c9c2419250\", \"price_changes\":[{\"asset_id\":\"69697746896130839564035629862476347944307040470122503199396727085502753297492\", \"price\":\"0.03\", \"size\":\"613.1\", \"side\":\"BUY\", \"hash\":\"d4dced32c0f959cab191ea0423ff761c210feb7c\", \"best_bid\":\"0.72\", \"best_ask\":\"0.73\"}, {\"asset_id\":\"60386828328910021732068595344565885737045900010034836345809386672230885527307\", \"price\":\"0.97\", \"size\":\"613.1\", \"side\":\"SELL\", \"hash\":\"eb9cf7442b7d79fc208aa6e873fcd1147c663001\", \"best_bid\":\"0.27\", \"best_ask\":\"0.28\"}], \"timestamp\":\"1785127227055\", \"event_type\":\"price_change\"}","received_at":"2026-07-27T04:40:27.068782Z","schema_version":"clob-market-ws.price_change.v1","sequence":null,"server_hash":null,"server_timestamp":"1785127227055","session_id":"e9443c7415a0419799bee9cfbb1a9e4d","source":"clob_market_ws"},"received_at":"2026-07-27T04:40:27.068782Z","record_id":"45a117460a10f9f3918d19c7b41ed23acf31063799404e158cbd5b23145e7895","schema_fingerprint":"4aa3821a28b0b7c2400bc59aba4bcc0a76e971dadd19610d3ad38c768e124dc7","schema_version":"edge-lab-recorder.raw.v1","sequence":null,"source":"clob_market_ws"}
{"event_at":"2026-07-27T04:40:27.057000Z","event_fingerprint":"882b51ad7f1c47f11d3d7c31e70483ac4d84c45d2ddbf7dfbc1623011cb1b91e","payload":{"connection_id":"0f4979d6978d463e9660b042fdcf555f","event_at":"2026-07-27T04:40:27.057000Z","event_type":"price_change","frame_hash":"5e9782b2f70ac860342845e76cebed6d3cb095fcdea924ea5beed03deb4e4744","frame_index":0,"kind":"data","monotonic_ns":229210335866333,"payload":{"event_type":"price_change","market":"0xeb66215f2e9faa6449e30a02bab5b8ed7b79a38bf961f6b24d0073c9c2419250","price_changes":[{"asset_id":"60386828328910021732068595344565885737045900010034836345809386672230885527307","best_ask":"0.28","best_bid":"0.27","hash":"51faf201a19de4cd6e6af4685741b4efc88366df","price":"0.21","side":"BUY","size":"103.05"},{"asset_id":"69697746896130839564035629862476347944307040470122503199396727085502753297492","best_ask":"0.73","best_bid":"0.72","hash":"3627975d82f274e9910b73c448a37751618684bd","price":"0.79","side":"SELL","size":"103.05"}],"timestamp":"1785127227057"},"payload_hash":"b7db48b21d678793747ea39fad174b2499a5964467be8df92c52520dcaddecfd","raw_frame":"{\"market\":\"0xeb66215f2e9faa6449e30a02bab5b8ed7b79a38bf961f6b24d0073c9c2419250\", \"price_changes\":[{\"asset_id\":\"60386828328910021732068595344565885737045900010034836345809386672230885527307\", \"price\":\"0.21\", \"size\":\"103.05\", \"side\":\"BUY\", \"hash\":\"51faf201a19de4cd6e6af4685741b4efc88366df\", \"best_bid\":\"0.27\", \"best_ask\":\"0.28\"}, {\"asset_id\":\"69697746896130839564035629862476347944307040470122503199396727085502753297492\", \"price\":\"0.79\", \"size\":\"103.05\", \"side\":\"SELL\", \"hash\":\"3627975d82f274e9910b73c448a37751618684bd\", \"best_bid\":\"0.72\", \"best_ask\":\"0.73\"}], \"timestamp\":\"1785127227057\", \"event_type\":\"price_change\"}","received_at":"2026-07-27T04:40:27.071463Z","schema_version":"clob-market-ws.price_change.v1","sequence":null,"server_hash":null,"server_timestamp":"1785127227057","session_id":"e9443c7415a0419799bee9cfbb1a9e4d","source":"clob_market_ws"},"received_at":"2026-07-27T04:40:27.071463Z","record_id":"ebf2a234e8ffda07c4fad5c719fbf115df2b47b8cd5d9cb661f71d6840124609","schema_fingerprint":"4aa3821a28b0b7c2400bc59aba4bcc0a76e971dadd19610d3ad38c768e124dc7","schema_version":"edge-lab-recorder.raw.v1","sequence":null,"source":"clob_market_ws"}
{"event_at":"2026-07-27T04:40:27.058000Z","event_fingerprint":"808107206f3c7393274dfe184fbe5b02e005ecd1a420c68351c13da8ea551ac2","payload":{"connection_id":"0f4979d6978d463e9660b042fdcf555f","event_at":"2026-07-27T04:40:27.058000Z","event_type":"price_change","frame_hash":"ea7406b5a1236d685e8fe32e18d6803854243cc978e9d88f7698abd2e83005a4","frame_index":0,"kind":"data","monotonic_ns":229210340360208,"payload":{"event_type":"price_change","market":"0xeb66215f2e9faa6449e30a02bab5b8ed7b79a38bf961f6b24d0073c9c2419250","price_changes":[{"asset_id":"60386828328910021732068595344565885737045900010034836345809386672230885527307","best_ask":"0.28","best_bid":"0.27","hash":"96003304eb026ce78dc5d5df4b3bd56dda3caa06","price":"0.21","side":"BUY","size":"130.65"},{"asset_id":"69697746896130839564035629862476347944307040470122503199396727085502753297492","best_ask":"0.73","best_bid":"0.72","hash":"666ddba07d62b9116ab3cb67d24f52ca30755c9a","price":"0.79","side":"SELL","size":"130.65"}],"timestamp":"1785127227058"},"payload_hash":"86999cf520f2bb010a6c7f6a51f6782af861ed11bc9d92b22fd694e28b7cb996","raw_frame":"{\"market\":\"0xeb66215f2e9faa6449e30a02bab5b8ed7b79a38bf961f6b24d0073c9c2419250\", \"price_changes\":[{\"asset_id\":\"60386828328910021732068595344565885737045900010034836345809386672230885527307\", \"price\":\"0.21\", \"size\":\"130.65\", \"side\":\"BUY\", \"hash\":\"96003304eb026ce78dc5d5df4b3bd56dda3caa06\", \"best_bid\":\"0.27\", \"best_ask\":\"0.28\"}, {\"asset_id\":\"69697746896130839564035629862476347944307040470122503199396727085502753297492\", \"price\":\"0.79\", \"size\":\"130.65\", \"side\":\"SELL\", \"hash\":\"666ddba07d62b9116ab3cb67d24f52ca30755c9a\", \"best_bid\":\"0.72\", \"best_ask\":\"0.73\"}], \"timestamp\":\"1785127227058\", \"event_type\":\"price_change\"}","received_at":"2026-07-27T04:40:27.075958Z","schema_version":"clob-market-ws.price_change.v1","sequence":null,"server_hash":null,"server_timestamp":"1785127227058","session_id":"e9443c7415a0419799bee9cfbb1a9e4d","source":"clob_market_ws"},"received_at":"2026-07-27T04:40:27.075958Z","record_id":"8e4bcf3c7a0d194b6aface63f20497c304253b67dbb355b24fe9827d1431be1e","schema_fingerprint":"4aa3821a28b0b7c2400bc59aba4bcc0a76e971dadd19610d3ad38c768e124dc7","schema_version":"edge-lab-recorder.raw.v1","sequence":null,"source":"clob_market_ws"}
{"event_at":"2026-07-27T04:40:27.101000Z","event_fingerprint":"88cff8c8e517a3bf85c259178a32ed231b337705271e81b14713f99d5ffa406d","payload":{"connection_id":"0f4979d6978d463e9660b042fdcf555f","event_at":"2026-07-27T04:40:27.101000Z","event_type":"price_change","frame_hash":"d85936c53237b5845b4e68b6eecf5e25243fd448aa13aad5130380d8b4ce010a","frame_index":0,"kind":"data","monotonic_ns":229210344945416,"payload":{"event_type":"price_change","market":"0xeb66215f2e9faa6449e30a02bab5b8ed7b79a38bf961f6b24d0073c9c2419250","price_changes":[{"asset_id":"69697746896130839564035629862476347944307040470122503199396727085502753297492","best_ask":"0.73","best_bid":"0.72","hash":"513caa2ffe194130cfd06fb24f4ec64a50d25915","price":"0.71","side":"BUY","size":"23.59"},{"asset_id":"60386828328910021732068595344565885737045900010034836345809386672230885527307","best_ask":"0.28","best_bid":"0.27","hash":"4f5f3cf706bf8ab6a6233c0907cfdb5d1e4e8e8c","price":"0.29","side":"SELL","size":"23.59"}],"timestamp":"1785127227101"},"payload_hash":"d10cc0ef5bc0438acd3e065e74b777c6cd1b267a1dc86c337b332ab935af8d78","raw_frame":"{\"market\":\"0xeb66215f2e9faa6449e30a02bab5b8ed7b79a38bf961f6b24d0073c9c2419250\", \"price_changes\":[{\"asset_id\":\"69697746896130839564035629862476347944307040470122503199396727085502753297492\", \"price\":\"0.71\", \"size\":\"23.59\", \"side\":\"BUY\", \"hash\":\"513caa2ffe194130cfd06fb24f4ec64a50d25915\", \"best_bid\":\"0.72\", \"best_ask\":\"0.73\"}, {\"asset_id\":\"60386828328910021732068595344565885737045900010034836345809386672230885527307\", \"price\":\"0.29\", \"size\":\"23.59\", \"side\":\"SELL\", \"hash\":\"4f5f3cf706bf8ab6a6233c0907cfdb5d1e4e8e8c\", \"best_bid\":\"0.27\", \"best_ask\":\"0.28\"}], \"timestamp\":\"1785127227101\", \"event_type\":\"price_change\"}","received_at":"2026-07-27T04:40:27.080541Z","schema_version":"clob-market-ws.price_change.v1","sequence":null,"server_hash":null,"server_timestamp":"1785127227101","session_id":"e9443c7415a0419799bee9cfbb1a9e4d","source":"clob_market_ws"},"received_at":"2026-07-27T04:40:27.080541Z","record_id":"b4c1f1cde67eebb0eede633444d878f4dea61f201f3cd40d7f107c2d11e55ce8","schema_fingerprint":"4aa3821a28b0b7c2400bc59aba4bcc0a76e971dadd19610d3ad38c768e124dc7","schema_version":"edge-lab-recorder.raw.v1","sequence":null,"source":"clob_market_ws"}
{"event_at":"2026-07-27T04:40:27.125000Z","event_fingerprint":"2a59526f348b9bcd7268494205952fb8b3793edcd45d5f4bfb25c2a56e3c2657","payload":{"connection_id":"0f4979d6978d463e9660b042fdcf555f","event_at":"2026-07-27T04:40:27.125000Z","event_type":"price_change","frame_hash":"a9bf34512db45bcd9a727c9b0a74cbe7956c8251fcc5d2cd8213080e77f9f933","frame_index":0,"kind":"data","monotonic_ns":229210349160541,"payload":{"event_type":"price_change","market":"0xeb66215f2e9faa6449e30a02bab5b8ed7b79a38bf961f6b24d0073c9c2419250","price_changes":[{"asset_id":"69697746896130839564035629862476347944307040470122503199396727085502753297492","best_ask":"0.73","best_bid":"0.72","hash":"f4ae6916baecc2024c99c2371e03927b0a634287","price":"0.7","side":"BUY","size":"41.94"},{"asset_id":"60386828328910021732068595344565885737045900010034836345809386672230885527307","best_ask":"0.28","best_bid":"0.27","hash":"f619d5bdf9852996836a4cc84351cec19358aea2","price":"0.3","side":"SELL","size":"41.94"}],"timestamp":"1785127227125"},"payload_hash":"a28211fd339deeb3ceaae5c725b4350a76da84025b7ca6a96dfa563042fa6391","raw_frame":"{\"market\":\"0xeb66215f2e9faa6449e30a02bab5b8ed7b79a38bf961f6b24d0073c9c2419250\", \"price_changes\":[{\"asset_id\":\"69697746896130839564035629862476347944307040470122503199396727085502753297492\", \"price\":\"0.7\", \"size\":\"41.94\", \"side\":\"BUY\", \"hash\":\"f4ae6916baecc2024c99c2371e03927b0a634287\", \"best_bid\":\"0.72\", \"best_ask\":\"0.73\"}, {\"asset_id\":\"60386828328910021732068595344565885737045900010034836345809386672230885527307\", \"price\":\"0.3\", \"size\":\"41.94\", \"side\":\"SELL\", \"hash\":\"f619d5bdf9852996836a4cc84351cec19358aea2\", \"best_bid\":\"0.27\", \"best_ask\":\"0.28\"}], \"timestamp\":\"1785127227125\", \"event_type\":\"price_change\"}","received_at":"2026-07-27T04:40:27.084757Z","schema_version":"clob-market-ws.price_change.v1","sequence":null,"server_hash":null,"server_timestamp":"1785127227125","session_id":"e9443c7415a0419799bee9cfbb1a9e4d","source":"clob_market_ws"},"received_at":"2026-07-27T04:40:27.084757Z","record_id":"28b8c85eea85c8fce494304ddf4a237a2040970b533591913bf87fcff74cdf62","schema_fingerprint":"4aa3821a28b0b7c2400bc59aba4bcc0a76e971dadd19610d3ad38c768e124dc7","schema_version":"edge-lab-recorder.raw.v1","sequence":null,"source":"clob_market_ws"}
{"event_at":"2026-07-27T04:40:27.132000Z","event_fingerprint":"8821aba8be2788282a29801c3bef20f82dc6bde32d8d9de09c86eb4c8f72e737","payload":{"connection_id":"0f4979d6978d463e9660b042fdcf555f","event_at":"2026-07-27T04:40:27.132000Z","event_type":"price_change","frame_hash":"d2991b5587d9d3afe808ac112650e3ba393157e3885db6faa2bc0a9858ac7d0a","frame_index":0,"kind":"data","monotonic_ns":229210359558416,"payload":{"event_type":"price_change","market":"0xeb66215f2e9faa6449e30a02bab5b8ed7b79a38bf961f6b24d0073c9c2419250","price_changes":[{"asset_id":"69697746896130839564035629862476347944307040470122503199396727085502753297492","best_ask":"0.73","best_bid":"0.72","hash":"83b06939fcfbbeee26b3aeb54a3323dc1f5a2308","price":"0.68","side":"BUY","size":"306.4"},{"asset_id":"60386828328910021732068595344565885737045900010034836345809386672230885527307","best_ask":"0.28","best_bid":"0.27","hash":"ee379e2da41c59b4d31251afee6dad32858d9c6d","price":"0.32","side":"SELL","size":"306.4"}],"timestamp":"1785127227132"},"payload_hash":"ceb169ac67826a496ac1a39e6a65a964a6ce1b06920d84cbe71cef16e9748ee7","raw_frame":"{\"market\":\"0xeb66215f2e9faa6449e30a02bab5b8ed7b79a38bf961f6b24d0073c9c2419250\", \"price_changes\":[{\"asset_id\":\"69697746896130839564035629862476347944307040470122503199396727085502753297492\", \"price\":\"0.68\", \"size\":\"306.4\", \"side\":\"BUY\", \"hash\":\"83b06939fcfbbeee26b3aeb54a3323dc1f5a2308\", \"best_bid\":\"0.72\", \"best_ask\":\"0.73\"}, {\"asset_id\":\"60386828328910021732068595344565885737045900010034836345809386672230885527307\", \"price\":\"0.32\", \"size\":\"306.4\", \"side\":\"SELL\", \"hash\":\"ee379e2da41c59b4d31251afee6dad32858d9c6d\", \"best_bid\":\"0.27\", \"best_ask\":\"0.28\"}], \"timestamp\":\"1785127227132\", \"event_type\":\"price_change\"}","received_at":"2026-07-27T04:40:27.095155Z","schema_version":"clob-market-ws.price_change.v1","sequence":null,"server_hash":null,"server_timestamp":"1785127227132","session_id":"e9443c7415a0419799bee9cfbb1a9e4d","source":"clob_market_ws"},"received_at":"2026-07-27T04:40:27.095155Z","record_id":"9c5d3a65b14a61d512befeddf64dde805f94f13e9ee2addac1f1165fdd1eb002","schema_fingerprint":"4aa3821a28b0b7c2400bc59aba4bcc0a76e971dadd19610d3ad38c768e124dc7","schema_version":"edge-lab-recorder.raw.v1","sequence":null,"source":"clob_market_ws"}
{"event_at":"2026-07-27T04:40:27.133000Z","event_fingerprint":"4d692e30a54c27b3a6a59e72895f2d2ef792c56ba8e33034603e4bc6c2dfc897","payload":{"connection_id":"0f4979d6978d463e9660b042fdcf555f","event_at":"2026-07-27T04:40:27.133000Z","event_type":"price_change","frame_hash":"7e24664997a05e0116d612033f06ebbfae04c726de4718dbc3549d2927052548","frame_index":0,"kind":"data","monotonic_ns":229210362712916,"payload":{"event_type":"price_change","market":"0xeb66215f2e9faa6449e30a02bab5b8ed7b79a38bf961f6b24d0073c9c2419250","price_changes":[{"asset_id":"60386828328910021732068595344565885737045900010034836345809386672230885527307","best_ask":"0.28","best_bid":"0.27","hash":"d4db501611483cca3f141fffb309c174d9f1530e","price":"0.3","side":"SELL","size":"84.94"},{"asset_id":"69697746896130839564035629862476347944307040470122503199396727085502753297492","best_ask":"0.73","best_bid":"0.72","hash":"348186f16832652bea8e2bfcad44a9d726859289","price":"0.7","side":"BUY","size":"84.94"}],"timestamp":"1785127227133"},"payload_hash":"e3a301c3b5593a4a794e7934ea6600f0539df6734b2c2ab57bd1e451ff2cc4f8","raw_frame":"{\"market\":\"0xeb66215f2e9faa6449e30a02bab5b8ed7b79a38bf961f6b24d0073c9c2419250\", \"price_changes\":[{\"asset_id\":\"60386828328910021732068595344565885737045900010034836345809386672230885527307\", \"price\":\"0.3\", \"size\":\"84.94\", \"side\":\"SELL\", \"hash\":\"d4db501611483cca3f141fffb309c174d9f1530e\", \"best_bid\":\"0.27\", \"best_ask\":\"0.28\"}, {\"asset_id\":\"69697746896130839564035629862476347944307040470122503199396727085502753297492\", \"price\":\"0.7\", \"size\":\"84.94\", \"side\":\"BUY\", \"hash\":\"348186f16832652bea8e2bfcad44a9d726859289\", \"best_bid\":\"0.72\", \"best_ask\":\"0.73\"}], \"timestamp\":\"1785127227133\", \"event_type\":\"price_change\"}","received_at":"2026-07-27T04:40:27.098311Z","schema_version":"clob-market-ws.price_change.v1","sequence":null,"server_hash":null,"server_timestamp":"1785127227133","session_id":"e9443c7415a0419799bee9cfbb1a9e4d","source":"clob_market_ws"},"received_at":"2026-07-27T04:40:27.098311Z","record_id":"e3d3adf2304d6f525dc7341e62455c4e551fa381ecad48199527b3fa6cc364c1","schema_fingerprint":"4aa3821a28b0b7c2400bc59aba4bcc0a76e971dadd19610d3ad38c768e124dc7","schema_version":"edge-lab-recorder.raw.v1","sequence":null,"source":"clob_market_ws"}
{"event_at":"2026-07-27T04:40:27.134000Z","event_fingerprint":"9c908817219f3acff8c6815b23b3370cef6f313f6d5b2c027f85dbb73a023da2","payload":{"connection_id":"0f4979d6978d463e9660b042fdcf555f","event_at":"2026-07-27T04:40:27.134000Z","event_type":"price_change","frame_hash":"a6f1c57367a81cb21ae0372d7570ba0bf0319ec307bf40d6961e4c44183a1c9e","frame_index":0,"kind":"data","monotonic_ns":229210374632625,"payload":{"event_type":"price_change","market":"0xeb66215f2e9faa6449e30a02bab5b8ed7b79a38bf961f6b24d0073c9c2419250","price_changes":[{"asset_id":"60386828328910021732068595344565885737045900010034836345809386672230885527307","best_ask":"0.28","best_bid":"0.27","hash":"02a57e16f4210aee2d3006186b3803a12c4665e8","price":"0.31","side":"SELL","size":"161.23"},{"asset_id":"69697746896130839564035629862476347944307040470122503199396727085502753297492","best_ask":"0.73","best_bid":"0.72","hash":"a9caed403df5fa4afb2e9496cfca67294415aa7c","price":"0.69","side":"BUY","size":"161.23"}],"timestamp":"1785127227134"},"payload_hash":"9bfc36d69e63445f67e4ad01773226cab0e00f29af140f90fcea43f22a84f2af","raw_frame":"{\"market\":\"0xeb66215f2e9faa6449e30a02bab5b8ed7b79a38bf961f6b24d0073c9c2419250\", \"price_changes\":[{\"asset_id\":\"60386828328910021732068595344565885737045900010034836345809386672230885527307\", \"price\":\"0.31\", \"size\":\"161.23\", \"side\":\"SELL\", \"hash\":\"02a57e16f4210aee2d3006186b3803a12c4665e8\", \"best_bid\":\"0.27\", \"best_ask\":\"0.28\"}, {\"asset_id\":\"69697746896130839564035629862476347944307040470122503199396727085502753297492\", \"price\":\"0.69\", \"size\":\"161.23\", \"side\":\"BUY\", \"hash\":\"a9caed403df5fa4afb2e9496cfca67294415aa7c\", \"best_bid\":\"0.72\", \"best_ask\":\"0.73\"}], \"timestamp\":\"1785127227134\", \"event_type\":\"price_change\"}","received_at":"2026-07-27T04:40:27.110232Z","schema_version":"clob-market-ws.price_change.v1","sequence":null,"server_hash":null,"server_timestamp":"1785127227134","session_id":"e9443c7415a0419799bee9cfbb1a9e4d","source":"clob_market_ws"},"received_at":"2026-07-27T04:40:27.110232Z","record_id":"c8b7fb5a309440f31d8aac62950859cf7990920a78390b1a83815301f69e9fb1","schema_fingerprint":"4aa3821a28b0b7c2400bc59aba4bcc0a76e971dadd19610d3ad38c768e124dc7","schema_version":"edge-lab-recorder.raw.v1","sequence":null,"source":"clob_market_ws"}
{"event_at":"2026-07-27T04:40:27.135000Z","event_fingerprint":"9da1bc488c2a4effc870a6fb300675b345b21088a6dde5a8ac8ca32a54be7d2e","payload":{"connection_id":"0f4979d6978d463e9660b042fdcf555f","event_at":"2026-07-27T04:40:27.135000Z","event_type":"price_change","frame_hash":"98e2029aa52d56c9afa699a2157dcf3ace58e7570c7592077c27313d03c76c85","frame_index":0,"kind":"data","monotonic_ns":229210378952416,"payload":{"event_type":"price_change","market":"0xeb66215f2e9faa6449e30a02bab5b8ed7b79a38bf961f6b24d0073c9c2419250","price_changes":[{"asset_id":"69697746896130839564035629862476347944307040470122503199396727085502753297492","best_ask":"0.73","best_bid":"0.72","hash":"ba26717165918f26f9f634f3269b5109003eef73","price":"0.69","side":"BUY","size":"166.23"},{"asset_id":"60386828328910021732068595344565885737045900010034836345809386672230885527307","best_ask":"0.28","best_bid":"0.27","hash":"cdf07033068fa2c7859d8cbd834385137ef35866","price":"0.31","side":"SELL","size":"166.23"}],"timestamp":"1785127227135"},"payload_hash":"9b99b552d8fb1cd49d985bd7a0da493fe7db667a89b9de9a7076a990fdc27e7a","raw_frame":"{\"market\":\"0xeb66215f2e9faa6449e30a02bab5b8ed7b79a38bf961f6b24d0073c9c2419250\", \"price_changes\":[{\"asset_id\":\"69697746896130839564035629862476347944307040470122503199396727085502753297492\", \"price\":\"0.69\", \"size\":\"166.23\", \"side\":\"BUY\", \"hash\":\"ba26717165918f26f9f634f3269b5109003eef73\", \"best_bid\":\"0.72\", \"best_ask\":\"0.73\"}, {\"asset_id\":\"60386828328910021732068595344565885737045900010034836345809386672230885527307\", \"price\":\"0.31\", \"size\":\"166.23\", \"side\":\"SELL\", \"hash\":\"cdf07033068fa2c7859d8cbd834385137ef35866\", \"best_bid\":\"0.27\", \"best_ask\":\"0.28\"}], \"timestamp\":\"1785127227135\", \"event_type\":\"price_change\"}","received_at":"2026-07-27T04:40:27.114552Z","schema_version":"clob-market-ws.price_change.v1","sequence":null,"server_hash":null,"server_timestamp":"1785127227135","session_id":"e9443c7415a0419799bee9cfbb1a9e4d","source":"clob_market_ws"},"received_at":"2026-07-27T04:40:27.114552Z","record_id":"c8a360bbe8f4674234ff7e4f638c58d9fd8c91fb452cc1918ed4ef3d3e77a01f","schema_fingerprint":"4aa3821a28b0b7c2400bc59aba4bcc0a76e971dadd19610d3ad38c768e124dc7","schema_version":"edge-lab-recorder.raw.v1","sequence":null,"source":"clob_market_ws"}
{"event_at":"2026-07-27T04:40:27.146000Z","event_fingerprint":"feb91a2fb3e4677f91a5391a2899ccf722c7f7b475cd0ccecf5189022705aad9","payload":{"connection_id":"0f4979d6978d463e9660b042fdcf555f","event_at":"2026-07-27T04:40:27.146000Z","event_type":"price_change","frame_hash":"b7fdda6f99b1ccbd9c5639422a2bad7eeb44132a60abf4a0849af2679183f291","frame_index":0,"kind":"data","monotonic_ns":229210383273625,"payload":{"event_type":"price_change","market":"0xeb66215f2e9faa6449e30a02bab5b8ed7b79a38bf961f6b24d0073c9c2419250","price_changes":[{"asset_id":"60386828328910021732068595344565885737045900010034836345809386672230885527307","best_ask":"0.28","best_bid":"0.27","hash":"f21c2b4251ec4b43d0fdd276eedef854f49abfb9","price":"0.01","side":"BUY","size":"5693.02"},{"asset_id":"69697746896130839564035629862476347944307040470122503199396727085502753297492","best_ask":"0.73","best_bid":"0.72","hash":"7732c57dab28ce65a805ec9a8b30d5fcd2e8064f","price":"0.99","side":"SELL","size":"5693.02"}],"timestamp":"1785127227146"},"payload_hash":"5bc207648a678d7fa70b26a804c4773c18e3ed965224246e1968c45af450598d","raw_frame":"{\"market\":\"0xeb66215f2e9faa6449e30a02bab5b8ed7b79a38bf961f6b24d0073c9c2419250\", \"price_changes\":[{\"asset_id\":\"60386828328910021732068595344565885737045900010034836345809386672230885527307\", \"price\":\"0.01\", \"size\":\"5693.02\", \"side\":\"BUY\", \"hash\":\"f21c2b4251ec4b43d0fdd276eedef854f49abfb9\", \"best_bid\":\"0.27\", \"best_ask\":\"0.28\"}, {\"asset_id\":\"69697746896130839564035629862476347944307040470122503199396727085502753297492\", \"price\":\"0.99\", \"size\":\"5693.02\", \"side\":\"SELL\", \"hash\":\"7732c57dab28ce65a805ec9a8b30d5fcd2e8064f\", \"best_bid\":\"0.72\", \"best_ask\":\"0.73\"}], \"timestamp\":\"1785127227146\", \"event_type\":\"price_change\"}","received_at":"2026-07-27T04:40:27.118872Z","schema_version":"clob-market-ws.price_change.v1","sequence":null,"server_hash":null,"server_timestamp":"1785127227146","session_id":"e9443c7415a0419799bee9cfbb1a9e4d","source":"clob_market_ws"},"received_at":"2026-07-27T04:40:27.118872Z","record_id":"6bed84f4823227e59a9d1fc45e1c61bbf2e8e0047585bb1a84f04c92860c3daa","schema_fingerprint":"4aa3821a28b0b7c2400bc59aba4bcc0a76e971dadd19610d3ad38c768e124dc7","schema_version":"edge-lab-recorder.raw.v1","sequence":null,"source":"clob_market_ws"}
{"event_at":"2026-07-27T04:40:27.155000Z","event_fingerprint":"e9cd8be6763f37554b60890a81ce54bbd033203ba9eb55818329d4b786edab16","payload":{"connection_id":"0f4979d6978d463e9660b042fdcf555f","event_at":"2026-07-27T04:40:27.155000Z","event_type":"price_change","frame_hash":"00e9ea0c2555c28e04870cfecf1bb1b6002c82c1e8d7eff00498f26a0b2d2921","frame_index":0,"kind":"data","monotonic_ns":229210385680875,"payload":{"event_type":"price_change","market":"0xeb66215f2e9faa6449e30a02bab5b8ed7b79a38bf961f6b24d0073c9c2419250","price_changes":[{"asset_id":"69697746896130839564035629862476347944307040470122503199396727085502753297492","best_ask":"0.73","best_bid":"0.72","hash":"ea59cd9fb3284697f16289ee1c9d54f4d849bffb","price":"0.01","side":"BUY","size":"5638.02"},{"asset_id":"60386828328910021732068595344565885737045900010034836345809386672230885527307","best_ask":"0.28","best_bid":"0.27","hash":"cd419f9421a0fda86f8ff297e59cdd0773a36641","price":"0.99","side":"SELL","size":"5638.02"}],"timestamp":"1785127227155"},"payload_hash":"c8b9f082adf2c97a315f5093afdaea5c26c4d121cb0f8651203a5ce5b6bbdfe4","raw_frame":"{\"market\":\"0xeb66215f2e9faa6449e30a02bab5b8ed7b79a38bf961f6b24d0073c9c2419250\", \"price_changes\":[{\"asset_id\":\"69697746896130839564035629862476347944307040470122503199396727085502753297492\", \"price\":\"0.01\", \"size\":\"5638.02\", \"side\":\"BUY\", \"hash\":\"ea59cd9fb3284697f16289ee1c9d54f4d849bffb\", \"best_bid\":\"0.72\", \"best_ask\":\"0.73\"}, {\"asset_id\":\"60386828328910021732068595344565885737045900010034836345809386672230885527307\", \"price\":\"0.99\", \"size\":\"5638.02\", \"side\":\"SELL\", \"hash\":\"cd419f9421a0fda86f8ff297e59cdd0773a36641\", \"best_bid\":\"0.27\", \"best_ask\":\"0.28\"}], \"timestamp\":\"1785127227155\", \"event_type\":\"price_change\"}","received_at":"2026-07-27T04:40:27.121280Z","schema_version":"clob-market-ws.price_change.v1","sequence":null,"server_hash":null,"server_timestamp":"1785127227155","session_id":"e9443c7415a0419799bee9cfbb1a9e4d","source":"clob_market_ws"},"received_at":"2026-07-27T04:40:27.121280Z","record_id":"5e76ba01dc519fb64ac4627b9cff5074c1853e26cbf6f133e9d271263f0ec58c","schema_fingerprint":"4aa3821a28b0b7c2400bc59aba4bcc0a76e971dadd19610d3ad38c768e124dc7","schema_version":"edge-lab-recorder.raw.v1","sequence":null,"source":"clob_market_ws"}
{"event_at":"2026-07-27T04:40:27.157000Z","event_fingerprint":"56478176f40d6b2cfeff3c33f8c9469319e8b5c69753e3b12c3c3c8db7dca570","payload":{"connection_id":"0f4979d6978d463e9660b042fdcf555f","event_at":"2026-07-27T04:40:27.157000Z","event_type":"price_change","frame_hash":"7b1b7a4e773a6780bcd5d248b19095420cb07b103e3edf19bd7bc8cb166445e3","frame_index":0,"kind":"data","monotonic_ns":229210389443208,"payload":{"event_type":"price_change","market":"0xeb66215f2e9faa6449e30a02bab5b8ed7b79a38bf961f6b24d0073c9c2419250","price_changes":[{"asset_id":"60386828328910021732068595344565885737045900010034836345809386672230885527307","best_ask":"0.28","best_bid":"0.27","hash":"8e2a201400dd1442f245a07a0e9c83b4a853878d","price":"0.17","side":"BUY","size":"197.02"},{"asset_id":"69697746896130839564035629862476347944307040470122503199396727085502753297492","best_ask":"0.73","best_bid":"0.72","hash":"868275b66865f23dc6ea48cf48c9dac193cbc796","price":"0.83","side":"SELL","size":"197.02"}],"timestamp":"1785127227157"},"payload_hash":"05d5b1c7599dd19012c33718881d9d6fca0c9e080caf1d8d78976bc027e80919","raw_frame":"{\"market\":\"0xeb66215f2e9faa6449e30a02bab5b8ed7b79a38bf961f6b24d0073c9c2419250\", \"price_changes\":[{\"asset_id\":\"60386828328910021732068595344565885737045900010034836345809386672230885527307\", \"price\":\"0.17\", \"size\":\"197.02\", \"side\":\"BUY\", \"hash\":\"8e2a201400dd1442f245a07a0e9c83b4a853878d\", \"best_bid\":\"0.27\", \"best_ask\":\"0.28\"}, {\"asset_id\":\"69697746896130839564035629862476347944307040470122503199396727085502753297492\", \"price\":\"0.83\", \"size\":\"197.02\", \"side\":\"SELL\", \"hash\":\"868275b66865f23dc6ea48cf48c9dac193cbc796\", \"best_bid\":\"0.72\", \"best_ask\":\"0.73\"}], \"timestamp\":\"1785127227157\", \"event_type\":\"price_change\"}","received_at":"2026-07-27T04:40:27.125042Z","schema_version":"clob-market-ws.price_change.v1","sequence":null,"server_hash":null,"server_timestamp":"1785127227157","session_id":"e9443c7415a0419799bee9cfbb1a9e4d","source":"clob_market_ws"},"received_at":"2026-07-27T04:40:27.125042Z","record_id":"ecb028c91302dffe4068fb7267a0a611615712b425e355eae2d7e69f9649667b","schema_fingerprint":"4aa3821a28b0b7c2400bc59aba4bcc0a76e971dadd19610d3ad38c768e124dc7","schema_version":"edge-lab-recorder.raw.v1","sequence":null,"source":"clob_market_ws"}
{"event_at":"2026-07-27T04:40:27.158000Z","event_fingerprint":"28ae016ae137804f4d9ec4134254f8334326f4f66fe46cea6ea916e85fc92d82","payload":{"connection_id":"0f4979d6978d463e9660b042fdcf555f","event_at":"2026-07-27T04:40:27.158000Z","event_type":"price_change","frame_hash":"8215c526ce12a9796ac9874f52950f6706af09f60361011a9eee9cf145c45143","frame_index":0,"kind":"data","monotonic_ns":229210394670333,"payload":{"event_type":"price_change","market":"0xeb66215f2e9faa6449e30a02bab5b8ed7b79a38bf961f6b24d0073c9c2419250","price_changes":[{"asset_id":"69697746896130839564035629862476347944307040470122503199396727085502753297492","best_ask":"0.73","best_bid":"0.72","hash":"ad8aaa5dc62e3e1c84734c6c2fc8854156b2c86f","price":"0.67","side":"BUY","size":"55.6"},{"asset_id":"60386828328910021732068595344565885737045900010034836345809386672230885527307","best_ask":"0.28","best_bid":"0.27","hash":"710476a85b51681c1b291e8eeb0bec2fe8754c82","price":"0.33","side":"SELL","size":"55.6"}],"timestamp":"1785127227158"},"payload_hash":"4243d8fd9ea5e9aa67811b8732e62fd44b3d019a977f57ef29c4c736adc2ee23","raw_frame":"{\"market\":\"0xeb66215f2e9faa6449e30a02bab5b8ed7b79a38bf961f6b24d0073c9c2419250\", \"price_changes\":[{\"asset_id\":\"69697746896130839564035629862476347944307040470122503199396727085502753297492\", \"price\":\"0.67\", \"size\":\"55.6\", \"side\":\"BUY\", \"hash\":\"ad8aaa5dc62e3e1c84734c6c2fc8854156b2c86f\", \"best_bid\":\"0.72\", \"best_ask\":\"0.73\"}, {\"asset_id\":\"60386828328910021732068595344565885737045900010034836345809386672230885527307\", \"price\":\"0.33\", \"size\":\"55.6\", \"side\":\"SELL\", \"hash\":\"710476a85b51681c1b291e8eeb0bec2fe8754c82\", \"best_bid\":\"0.27\", \"best_ask\":\"0.28\"}], \"timestamp\":\"1785127227158\", \"event_type\":\"price_change\"}","received_at":"2026-07-27T04:40:27.130270Z","schema_version":"clob-market-ws.price_change.v1","sequence":null,"server_hash":null,"server_timestamp":"1785127227158","session_id":"e9443c7415a0419799bee9cfbb1a9e4d","source":"clob_market_ws"},"received_at":"2026-07-27T04:40:27.130270Z","record_id":"7acb0936df154148e4bfbe76dfb758d8ccf503a82b408e6ee8ec1b0db402b39a","schema_fingerprint":"4aa3821a28b0b7c2400bc59aba4bcc0a76e971dadd19610d3ad38c768e124dc7","schema_version":"edge-lab-recorder.raw.v1","sequence":null,"source":"clob_market_ws"}
{"event_at":"2026-07-27T04:40:27.209000Z","event_fingerprint":"cf48155d9d241a63488d58113d691aca7f2b0dcd7a56ff11c6838089f2c1f78e","payload":{"connection_id":"0f4979d6978d463e9660b042fdcf555f","event_at":"2026-07-27T04:40:27.209000Z","event_type":"price_change","frame_hash":"8ce5d2fc86321fc4eba00094dcb9b283594498dd62730e71ba04e0bc1e93b6ea","frame_index":0,"kind":"data","monotonic_ns":229210420842958,"payload":{"event_type":"price_change","market":"0xeb66215f2e9faa6449e30a02bab5b8ed7b79a38bf961f6b24d0073c9c2419250","price_changes":[{"asset_id":"69697746896130839564035629862476347944307040470122503199396727085502753297492","best_ask":"0.73","best_bid":"0.72","hash":"efa264d421e94b24e731d9b1075127edec7a693e","price":"0.01","side":"BUY","size":"5633.02"},{"asset_id":"60386828328910021732068595344565885737045900010034836345809386672230885527307","best_ask":"0.28","best_bid":"0.27","hash":"27fa0f5ba2602282af3e730feb355ddfb504e578","price":"0.99","side":"SELL","size":"5633.02"}],"timestamp":"1785127227209"},"payload_hash":"aae7987fac6f6fdf3a9e856cb7651e2c2e7f7f4881d0cd693dddff7fa3d58804","raw_frame":"{\"market\":\"0xeb66215f2e9faa6449e30a02bab5b8ed7b79a38bf961f6b24d0073c9c2419250\", \"price_changes\":[{\"asset_id\":\"69697746896130839564035629862476347944307040470122503199396727085502753297492\", \"price\":\"0.01\", \"size\":\"5633.02\", \"side\":\"BUY\", \"hash\":\"efa264d421e94b24e731d9b1075127edec7a693e\", \"best_bid\":\"0.72\", \"best_ask\":\"0.73\"}, {\"asset_id\":\"60386828328910021732068595344565885737045900010034836345809386672230885527307\", \"price\":\"0.99\", \"size\":\"5633.02\", \"side\":\"SELL\", \"hash\":\"27fa0f5ba2602282af3e730feb355ddfb504e578\", \"best_bid\":\"0.27\", \"best_ask\":\"0.28\"}], \"timestamp\":\"1785127227209\", \"event_type\":\"price_change\"}","received_at":"2026-07-27T04:40:27.156441Z","schema_version":"clob-market-ws.price_change.v1","sequence":null,"server_hash":null,"server_timestamp":"1785127227209","session_id":"e9443c7415a0419799bee9cfbb1a9e4d","source":"clob_market_ws"},"received_at":"2026-07-27T04:40:27.156441Z","record_id":"9d02c43fc7dbe61204ae472c785ba9d935419686ce0c0eba40b2bc91edcb897f","schema_fingerprint":"4aa3821a28b0b7c2400bc59aba4bcc0a76e971dadd19610d3ad38c768e124dc7","schema_version":"edge-lab-recorder.raw.v1","sequence":null,"source":"clob_market_ws"}
{"event_at":"2026-07-27T04:40:27.230000Z","event_fingerprint":"5d70cc876b94fe48a7e7c9c291adce4d95eaeddfe1d2cfe2471877babf94b0cc","payload":{"connection_id":"0f4979d6978d463e9660b042fdcf555f","event_at":"2026-07-27T04:40:27.230000Z","event_type":"price_change","frame_hash":"37559d5cfd2dff975c5675d369c2b4e24b22e1894ac52aaf22a96d4d8126790b","frame_index":0,"kind":"data","monotonic_ns":229210447712625,"payload":{"event_type":"price_change","market":"0xeb66215f2e9faa6449e30a02bab5b8ed7b79a38bf961f6b24d0073c9c2419250","price_changes":[{"asset_id":"69697746896130839564035629862476347944307040470122503199396727085502753297492","best_ask":"0.73","best_bid":"0.72","hash":"baaf40ebbb8d944855eae2020fd599f3449f299f","price":"0.68","side":"BUY","size":"298.4"},{"asset_id":"60386828328910021732068595344565885737045900010034836345809386672230885527307","best_ask":"0.28","best_bid":"0.27","hash":"f06020b6283cb304c2865073d57c1c1317fee998","price":"0.32","side":"SELL","size":"298.4"}],"timestamp":"1785127227230"},"payload_hash":"157824541004f7e5613941de418bc8941a9c3f92ad5142285caab422c5c05192","raw_frame":"{\"market\":\"0xeb66215f2e9faa6449e30a02bab5b8ed7b79a38bf961f6b24d0073c9c2419250\", \"price_changes\":[{\"asset_id\":\"69697746896130839564035629862476347944307040470122503199396727085502753297492\", \"price\":\"0.68\", \"size\":\"298.4\", \"side\":\"BUY\", \"hash\":\"baaf40ebbb8d944855eae2020fd599f3449f299f\", \"best_bid\":\"0.72\", \"best_ask\":\"0.73\"}, {\"asset_id\":\"60386828328910021732068595344565885737045900010034836345809386672230885527307\", \"price\":\"0.32\", \"size\":\"298.4\", \"side\":\"SELL\", \"hash\":\"f06020b6283cb304c2865073d57c1c1317fee998\", \"best_bid\":\"0.27\", \"best_ask\":\"0.28\"}], \"timestamp\":\"1785127227230\", \"event_type\":\"price_change\"}","received_at":"2026-07-27T04:40:27.183312Z","schema_version":"clob-market-ws.price_change.v1","sequence":null,"server_hash":null,"server_timestamp":"1785127227230","session_id":"e9443c7415a0419799bee9cfbb1a9e4d","source":"clob_market_ws"},"received_at":"2026-07-27T04:40:27.183312Z","record_id":"4d0111e165ab04d9c460d2a0d29f43d7943a16e92d212dc045618ce42b0e1a0a","schema_fingerprint":"4aa3821a28b0b7c2400bc59aba4bcc0a76e971dadd19610d3ad38c768e124dc7","schema_version":"edge-lab-recorder.raw.v1","sequence":null,"source":"clob_market_ws"}
{"event_at":"2026-07-27T04:40:27.230000Z","event_fingerprint":"b272b8ab1dc5b0ca0ccd8d6354aa4b6a52f732aefb72a2e9098b4353f4f98b98","payload":{"connection_id":"0f4979d6978d463e9660b042fdcf555f","event_at":"2026-07-27T04:40:27.230000Z","event_type":"price_change","frame_hash":"0915816780a5f4140746f8f2a3fbacab27beddffa6230135ad1259428f45935a","frame_index":0,"kind":"data","monotonic_ns":229210453035375,"payload":{"event_type":"price_change","market":"0xeb66215f2e9faa6449e30a02bab5b8ed7b79a38bf961f6b24d0073c9c2419250","price_changes":[{"asset_id":"60386828328910021732068595344565885737045900010034836345809386672230885527307","best_ask":"0.28","best_bid":"0.27","hash":"f06020b6283cb304c2865073d57c1c1317fee998","price":"0.3","side":"SELL","size":"41.94"},{"asset_id":"69697746896130839564035629862476347944307040470122503199396727085502753297492","best_ask":"0.73","best_bid":"0.72","hash":"baaf40ebbb8d944855eae2020fd599f3449f299f","price":"0.7","side":"BUY","size":"41.94"}],"timestamp":"1785127227230"},"payload_hash":"54d749b8db5abafe6a3907e59df1a322231b9390f23efa204419c859e99ed055","raw_frame":"{\"market\":\"0xeb66215f2e9faa6449e30a02bab5b8ed7b79a38bf961f6b24d0073c9c2419250\", \"price_changes\":[{\"asset_id\":\"60386828328910021732068595344565885737045900010034836345809386672230885527307\", \"price\":\"0.3\", \"size\":\"41.94\", \"side\":\"SELL\", \"hash\":\"f06020b6283cb304c2865073d57c1c1317fee998\", \"best_bid\":\"0.27\", \"best_ask\":\"0.28\"}, {\"asset_id\":\"69697746896130839564035629862476347944307040470122503199396727085502753297492\", \"price\":\"0.7\", \"size\":\"41.94\", \"side\":\"BUY\", \"hash\":\"baaf40ebbb8d944855eae2020fd599f3449f299f\", \"best_bid\":\"0.72\", \"best_ask\":\"0.73\"}], \"timestamp\":\"1785127227230\", \"event_type\":\"price_change\"}","received_at":"2026-07-27T04:40:27.188633Z","schema_version":"clob-market-ws.price_change.v1","sequence":null,"server_hash":null,"server_timestamp":"1785127227230","session_id":"e9443c7415a0419799bee9cfbb1a9e4d","source":"clob_market_ws"},"received_at":"2026-07-27T04:40:27.188633Z","record_id":"69852e23510cfd5b37784d54984ceeb74e2eb793dbbedbbed793ec0a113ac99a","schema_fingerprint":"4aa3821a28b0b7c2400bc59aba4bcc0a76e971dadd19610d3ad38c768e124dc7","schema_version":"edge-lab-recorder.raw.v1","sequence":null,"source":"clob_market_ws"}
{"event_at":"2026-07-27T04:40:27.230000Z","event_fingerprint":"abd4b5e6b6e8c0f39e5e815dc8ca0d2acc1e9d2e5cbe414e9cc43d8fe99bdf9d","payload":{"connection_id":"0f4979d6978d463e9660b042fdcf555f","event_at":"2026-07-27T04:40:27.230000Z","event_type":"price_change","frame_hash":"4223a9a1ec759c078e7289c7bd54b3f8ab2d2526c576d20abae12a60531fd398","frame_index":0,"kind":"data","monotonic_ns":229210460763875,"payload":{"event_type":"price_change","market":"0xeb66215f2e9faa6449e30a02bab5b8ed7b79a38bf961f6b24d0073c9c2419250","price_changes":[{"asset_id":"60386828328910021732068595344565885737045900010034836345809386672230885527307","best_ask":"0.28","best_bid":"0.27","hash":"f06020b6283cb304c2865073d57c1c1317fee998","price":"0.31","side":"SELL","size":"159.16"},{"asset_id":"69697746896130839564035629862476347944307040470122503199396727085502753297492","best_ask":"0.73","best_bid":"0.72","hash":"baaf40ebbb8d944855eae2020fd599f3449f299f","price":"0.69","side":"BUY","size":"159.16"}],"timestamp":"1785127227230"},"payload_hash":"35c3036bb19fdf8ca12371196666cd5daa4a994d9ff01a61c641c2f9205e191d","raw_frame":"{\"market\":\"0xeb66215f2e9faa6449e30a02bab5b8ed7b79a38bf961f6b24d0073c9c2419250\", \"price_changes\":[{\"asset_id\":\"60386828328910021732068595344565885737045900010034836345809386672230885527307\", \"price\":\"0.31\", \"size\":\"159.16\", \"side\":\"SELL\", \"hash\":\"f06020b6283cb304c2865073d57c1c1317fee998\", \"best_bid\":\"0.27\", \"best_ask\":\"0.28\"}, {\"asset_id\":\"69697746896130839564035629862476347944307040470122503199396727085502753297492\", \"price\":\"0.69\", \"size\":\"159.16\", \"side\":\"BUY\", \"hash\":\"baaf40ebbb8d944855eae2020fd599f3449f299f\", \"best_bid\":\"0.72\", \"best_ask\":\"0.73\"}], \"timestamp\":\"1785127227230\", \"event_type\":\"price_change\"}","received_at":"2026-07-27T04:40:27.196363Z","schema_version":"clob-market-ws.price_change.v1","sequence":null,"server_hash":null,"server_timestamp":"1785127227230","session_id":"e9443c7415a0419799bee9cfbb1a9e4d","source":"clob_market_ws"},"received_at":"2026-07-27T04:40:27.196363Z","record_id":"dc8614be15ec70725572b7182322a8a86ad51ddca90ae9a9549bef0f083d0d3b","schema_fingerprint":"4aa3821a28b0b7c2400bc59aba4bcc0a76e971dadd19610d3ad38c768e124dc7","schema_version":"edge-lab-recorder.raw.v1","sequence":null,"source":"clob_market_ws"}
{"event_at":"2026-07-27T04:40:27.252000Z","event_fingerprint":"49a5608d05729025457c9f8e7a1d22e6ebd7ea497112992d659efa6722bee350","payload":{"connection_id":"0f4979d6978d463e9660b042fdcf555f","event_at":"2026-07-27T04:40:27.252000Z","event_type":"price_change","frame_hash":"f1ea2f430a91a2ca3f612b757f7b6c290f173a5f0921249f82cd47e58dc467c9","frame_index":0,"kind":"data","monotonic_ns":229210464926125,"payload":{"event_type":"price_change","market":"0xeb66215f2e9faa6449e30a02bab5b8ed7b79a38bf961f6b24d0073c9c2419250","price_changes":[{"asset_id":"69697746896130839564035629862476347944307040470122503199396727085502753297492","best_ask":"0.73","best_bid":"0.72","hash":"ee5c75278c33e03d2bcf69dd84d711085e7ddb32","price":"0.7","side":"BUY","size":"84.94"},{"asset_id":"60386828328910021732068595344565885737045900010034836345809386672230885527307","best_ask":"0.28","best_bid":"0.27","hash":"1a4947acff7a054057eace2c5f3dfcc4eada78b4","price":"0.3","side":"SELL","size":"84.94"}],"timestamp":"1785127227252"},"payload_hash":"f0f575f4bb2098c42f050aacc5b3cbdd820a0b4a9373cd743c353da476dc9f67","raw_frame":"{\"market\":\"0xeb66215f2e9faa6449e30a02bab5b8ed7b79a38bf961f6b24d0073c9c2419250\", \"price_changes\":[{\"asset_id\":\"69697746896130839564035629862476347944307040470122503199396727085502753297492\", \"price\":\"0.7\", \"size\":\"84.94\", \"side\":\"BUY\", \"hash\":\"ee5c75278c33e03d2bcf69dd84d711085e7ddb32\", \"best_bid\":\"0.72\", \"best_ask\":\"0.73\"}, {\"asset_id\":\"60386828328910021732068595344565885737045900010034836345809386672230885527307\", \"price\":\"0.3\", \"size\":\"84.94\", \"side\":\"SELL\", \"hash\":\"1a4947acff7a054057eace2c5f3dfcc4eada78b4\", \"best_bid\":\"0.27\", \"best_ask\":\"0.28\"}], \"timestamp\":\"1785127227252\", \"event_type\":\"price_change\"}","received_at":"2026-07-27T04:40:27.200522Z","schema_version":"clob-market-ws.price_change.v1","sequence":null,"server_hash":null,"server_timestamp":"1785127227252","session_id":"e9443c7415a0419799bee9cfbb1a9e4d","source":"clob_market_ws"},"received_at":"2026-07-27T04:40:27.200522Z","record_id":"a21b2c4c6580a525fe643133950e3c9e06b22e64c2becc00f590da0118b1ade6","schema_fingerprint":"4aa3821a28b0b7c2400bc59aba4bcc0a76e971dadd19610d3ad38c768e124dc7","schema_version":"edge-lab-recorder.raw.v1","sequence":null,"source":"clob_market_ws"}
{"event_at":"2026-07-27T04:40:27.252000Z","event_fingerprint":"c3554bc41e300371d931c2f13e3fa4555f2642a5d255a7545d1919bbc38cecf4","payload":{"connection_id":"0f4979d6978d463e9660b042fdcf555f","event_at":"2026-07-27T04:40:27.252000Z","event_type":"price_change","frame_hash":"e082dcf62a286f9060e4f02acbde45d1cbc652113f26a9cad249f91186fd96f0","frame_index":0,"kind":"data","monotonic_ns":229210469016708,"payload":{"event_type":"price_change","market":"0xeb66215f2e9faa6449e30a02bab5b8ed7b79a38bf961f6b24d0073c9c2419250","price_changes":[{"asset_id":"69697746896130839564035629862476347944307040470122503199396727085502753297492","best_ask":"0.73","best_bid":"0.72","hash":"d21072f58264776f089e7bfb1e85b9696e8f125d","price":"0.01","side":"BUY","size":"5638.02"},{"asset_id":"60386828328910021732068595344565885737045900010034836345809386672230885527307","best_ask":"0.28","best_bid":"0.27","hash":"249e209ab88fd01df57b03423fa86273592375cb","price":"0.99","side":"SELL","size":"5638.02"}],"timestamp":"1785127227252"},"payload_hash":"8e40d725b249fd7b756ec8f9af51d66a00310f5fa3ee99874ff62dd05f7c09ed","raw_frame":"{\"market\":\"0xeb66215f2e9faa6449e30a02bab5b8ed7b79a38bf961f6b24d0073c9c2419250\", \"price_changes\":[{\"asset_id\":\"69697746896130839564035629862476347944307040470122503199396727085502753297492\", \"price\":\"0.01\", \"size\":\"5638.02\", \"side\":\"BUY\", \"hash\":\"d21072f58264776f089e7bfb1e85b9696e8f125d\", \"best_bid\":\"0.72\", \"best_ask\":\"0.73\"}, {\"asset_id\":\"60386828328910021732068595344565885737045900010034836345809386672230885527307\", \"price\":\"0.99\", \"size\":\"5638.02\", \"side\":\"SELL\", \"hash\":\"249e209ab88fd01df57b03423fa86273592375cb\", \"best_bid\":\"0.27\", \"best_ask\":\"0.28\"}], \"timestamp\":\"1785127227252\", \"event_type\":\"price_change\"}","received_at":"2026-07-27T04:40:27.204612Z","schema_version":"clob-market-ws.price_change.v1","sequence":null,"server_hash":null,"server_timestamp":"1785127227252","session_id":"e9443c7415a0419799bee9cfbb1a9e4d","source":"clob_market_ws"},"received_at":"2026-07-27T04:40:27.204612Z","record_id":"ce98e0a4c85ecb2c47d584716e392c1fa889a80a9b93d37186c3db71ed31adbb","schema_fingerprint":"4aa3821a28b0b7c2400bc59aba4bcc0a76e971dadd19610d3ad38c768e124dc7","schema_version":"edge-lab-recorder.raw.v1","sequence":null,"source":"clob_market_ws"}
{"event_at":"2026-07-27T04:40:27.274000Z","event_fingerprint":"cbddaadeca42f784184410be0fc6d15c5f0d15085af6dece9f8b4740359771c8","payload":{"connection_id":"0f4979d6978d463e9660b042fdcf555f","event_at":"2026-07-27T04:40:27.274000Z","event_type":"price_change","frame_hash":"865bae0419fd0ddfb8f0682bc95961747bcefc0bb0fe7413ecaf7be138a5df27","frame_index":0,"kind":"data","monotonic_ns":229210494158333,"payload":{"event_type":"price_change","market":"0xeb66215f2e9faa6449e30a02bab5b8ed7b79a38bf961f6b24d0073c9c2419250","price_changes":[{"asset_id":"69697746896130839564035629862476347944307040470122503199396727085502753297492","best_ask":"0.73","best_bid":"0.72","hash":"ed2bea47343e0e823d5fc91b49730dd85aab58b9","price":"0.01","side":"BUY","size":"5633.02"},{"asset_id":"60386828328910021732068595344565885737045900010034836345809386672230885527307","best_ask":"0.28","best_bid":"0.27","hash":"408b93eeff79c753a58db9a87c1447632e1fbdc8","price":"0.99","side":"SELL","size":"5633.02"}],"timestamp":"1785127227274"},"payload_hash":"848253a70d62f0d4fed9cae683c55bb9052eff751d649297349141073a6f8d6d","raw_frame":"{\"market\":\"0xeb66215f2e9faa6449e30a02bab5b8ed7b79a38bf961f6b24d0073c9c2419250\", \"price_changes\":[{\"asset_id\":\"69697746896130839564035629862476347944307040470122503199396727085502753297492\", \"price\":\"0.01\", \"size\":\"5633.02\", \"side\":\"BUY\", \"hash\":\"ed2bea47343e0e823d5fc91b49730dd85aab58b9\", \"best_bid\":\"0.72\", \"best_ask\":\"0.73\"}, {\"asset_id\":\"60386828328910021732068595344565885737045900010034836345809386672230885527307\", \"price\":\"0.99\", \"size\":\"5633.02\", \"side\":\"SELL\", \"hash\":\"408b93eeff79c753a58db9a87c1447632e1fbdc8\", \"best_bid\":\"0.27\", \"best_ask\":\"0.28\"}], \"timestamp\":\"1785127227274\", \"event_type\":\"price_change\"}","received_at":"2026-07-27T04:40:27.229758Z","schema_version":"clob-market-ws.price_change.v1","sequence":null,"server_hash":null,"server_timestamp":"1785127227274","session_id":"e9443c7415a0419799bee9cfbb1a9e4d","source":"clob_market_ws"},"received_at":"2026-07-27T04:40:27.229758Z","record_id":"bb52e1ccdfb35da11a33825c1287047da3297e516cdf9d8ebc0b638385bd437c","schema_fingerprint":"4aa3821a28b0b7c2400bc59aba4bcc0a76e971dadd19610d3ad38c768e124dc7","schema_version":"edge-lab-recorder.raw.v1","sequence":null,"source":"clob_market_ws"}
{"event_at":"2026-07-27T04:40:27.302000Z","event_fingerprint":"8de2a1f520d5b462ffac42fccde5d8fb5b3d1195108f60cc10853632ef312ae4","payload":{"connection_id":"0f4979d6978d463e9660b042fdcf555f","event_at":"2026-07-27T04:40:27.302000Z","event_type":"price_change","frame_hash":"233d0a00cafaf1f717aea6ef6624674ff6eb1b011f1222fb47999d3e80be48e0","frame_index":0,"kind":"data","monotonic_ns":229210514958458,"payload":{"event_type":"price_change","market":"0xeb66215f2e9faa6449e30a02bab5b8ed7b79a38bf961f6b24d0073c9c2419250","price_changes":[{"asset_id":"69697746896130839564035629862476347944307040470122503199396727085502753297492","best_ask":"0.73","best_bid":"0.72","hash":"94a086b57e74ede09c439185bc8243cd06cd003a","price":"0.01","side":"BUY","size":"5638.02"},{"asset_id":"60386828328910021732068595344565885737045900010034836345809386672230885527307","best_ask":"0.28","best_bid":"0.27","hash":"0ba578b7e06c10183d38ec43ca10ac05fb55f88c","price":"0.99","side":"SELL","size":"5638.02"}],"timestamp":"1785127227302"},"payload_hash":"ac1993aefc02ed98ff9bfb9050493ad21e4ea8ea9969fb07a3bdecf0fab9f8a4","raw_frame":"{\"market\":\"0xeb66215f2e9faa6449e30a02bab5b8ed7b79a38bf961f6b24d0073c9c2419250\", \"price_changes\":[{\"asset_id\":\"69697746896130839564035629862476347944307040470122503199396727085502753297492\", \"price\":\"0.01\", \"size\":\"5638.02\", \"side\":\"BUY\", \"hash\":\"94a086b57e74ede09c439185bc8243cd06cd003a\", \"best_bid\":\"0.72\", \"best_ask\":\"0.73\"}, {\"asset_id\":\"60386828328910021732068595344565885737045900010034836345809386672230885527307\", \"price\":\"0.99\", \"size\":\"5638.02\", \"side\":\"SELL\", \"hash\":\"0ba578b7e06c10183d38ec43ca10ac05fb55f88c\", \"best_bid\":\"0.27\", \"best_ask\":\"0.28\"}], \"timestamp\":\"1785127227302\", \"event_type\":\"price_change\"}","received_at":"2026-07-27T04:40:27.250558Z","schema_version":"clob-market-ws.price_change.v1","sequence":null,"server_hash":null,"server_timestamp":"1785127227302","session_id":"e9443c7415a0419799bee9cfbb1a9e4d","source":"clob_market_ws"},"received_at":"2026-07-27T04:40:27.250558Z","record_id":"2d8cf3026e2fefe3709a430a41d36cf359317277873a6c62c464d9ced750cd78","schema_fingerprint":"4aa3821a28b0b7c2400bc59aba4bcc0a76e971dadd19610d3ad38c768e124dc7","schema_version":"edge-lab-recorder.raw.v1","sequence":null,"source":"clob_market_ws"}
{"event_at":"2026-07-27T04:40:27.312000Z","event_fingerprint":"d34e4113029de63eef4a257985d0f16930768a6e02dfdb39e537f0624787aa5a","payload":{"connection_id":"0f4979d6978d463e9660b042fdcf555f","event_at":"2026-07-27T04:40:27.312000Z","event_type":"price_change","frame_hash":"8798b8d85ed5aec5deadb3be8e1c9d5596d94d1f89427ae6b33f3be5c6939013","frame_index":0,"kind":"data","monotonic_ns":229210525888500,"payload":{"event_type":"price_change","market":"0xeb66215f2e9faa6449e30a02bab5b8ed7b79a38bf961f6b24d0073c9c2419250","price_changes":[{"asset_id":"60386828328910021732068595344565885737045900010034836345809386672230885527307","best_ask":"0.28","best_bid":"0.27","hash":"3930987161b06b8bdf0be531d97ebd262c11eb58","price":"0.16","side":"BUY","size":"197"},{"asset_id":"69697746896130839564035629862476347944307040470122503199396727085502753297492","best_ask":"0.73","best_bid":"0.72","hash":"50c87e26fb73742d5996719c8af6314c4d688a3f","price":"0.84","side":"SELL","size":"197"}],"timestamp":"1785127227312"},"payload_hash":"634ce26b910d886a96ba9c63726f34b90879657241491da55f9c046822eaac48","raw_frame":"{\"market\":\"0xeb66215f2e9faa6449e30a02bab5b8ed7b79a38bf961f6b24d0073c9c2419250\", \"price_changes\":[{\"asset_id\":\"60386828328910021732068595344565885737045900010034836345809386672230885527307\", \"price\":\"0.16\", \"size\":\"197\", \"side\":\"BUY\", \"hash\":\"3930987161b06b8bdf0be531d97ebd262c11eb58\", \"best_bid\":\"0.27\", \"best_ask\":\"0.28\"}, {\"asset_id\":\"69697746896130839564035629862476347944307040470122503199396727085502753297492\", \"price\":\"0.84\", \"size\":\"197\", \"side\":\"SELL\", \"hash\":\"50c87e26fb73742d5996719c8af6314c4d688a3f\", \"best_bid\":\"0.72\", \"best_ask\":\"0.73\"}], \"timestamp\":\"1785127227312\", \"event_type\":\"price_change\"}","received_at":"2026-07-27T04:40:27.261488Z","schema_version":"clob-market-ws.price_change.v1","sequence":null,"server_hash":null,"server_timestamp":"1785127227312","session_id":"e9443c7415a0419799bee9cfbb1a9e4d","source":"clob_market_ws"},"received_at":"2026-07-27T04:40:27.261488Z","record_id":"cb154fdadfd7e69dc5759dc5ba41578a65c97edfa5547a80e3d49be77c646c08","schema_fingerprint":"4aa3821a28b0b7c2400bc59aba4bcc0a76e971dadd19610d3ad38c768e124dc7","schema_version":"edge-lab-recorder.raw.v1","sequence":null,"source":"clob_market_ws"}
{"event_at":"2026-07-27T04:40:27.344000Z","event_fingerprint":"6c9c304e0475f7b5880524709c5ade0634d47db0964ab6d83f18651df40fbe70","payload":{"connection_id":"0f4979d6978d463e9660b042fdcf555f","event_at":"2026-07-27T04:40:27.344000Z","event_type":"price_change","frame_hash":"788b142d20e64e6ec3eda6272194a1b565d33f28ebe042ca08a572860ea93211","frame_index":0,"kind":"data","monotonic_ns":229210561697708,"payload":{"event_type":"price_change","market":"0xeb66215f2e9faa6449e30a02bab5b8ed7b79a38bf961f6b24d0073c9c2419250","price_changes":[{"asset_id":"60386828328910021732068595344565885737045900010034836345809386672230885527307","best_ask":"0.28","best_bid":"0.27","hash":"6338811d11589298dbe02d0c418bf44701af569b","price":"0.16","side":"BUY","size":"177"},{"asset_id":"69697746896130839564035629862476347944307040470122503199396727085502753297492","best_ask":"0.73","best_bid":"0.72","hash":"9547d46962324abb0d02a40a282e2e8dfe327eda","price":"0.84","side":"SELL","size":"177"}],"timestamp":"1785127227344"},"payload_hash":"a8c716e104cbd545979b77f161f5efd407a1a25e368fd3550f828e0d3394f744","raw_frame":"{\"market\":\"0xeb66215f2e9faa6449e30a02bab5b8ed7b79a38bf961f6b24d0073c9c2419250\", \"price_changes\":[{\"asset_id\":\"60386828328910021732068595344565885737045900010034836345809386672230885527307\", \"price\":\"0.16\", \"size\":\"177\", \"side\":\"BUY\", \"hash\":\"6338811d11589298dbe02d0c418bf44701af569b\", \"best_bid\":\"0.27\", \"best_ask\":\"0.28\"}, {\"asset_id\":\"69697746896130839564035629862476347944307040470122503199396727085502753297492\", \"price\":\"0.84\", \"size\":\"177\", \"side\":\"SELL\", \"hash\":\"9547d46962324abb0d02a40a282e2e8dfe327eda\", \"best_bid\":\"0.72\", \"best_ask\":\"0.73\"}], \"timestamp\":\"1785127227344\", \"event_type\":\"price_change\"}","received_at":"2026-07-27T04:40:27.297302Z","schema_version":"clob-market-ws.price_change.v1","sequence":null,"server_hash":null,"server_timestamp":"1785127227344","session_id":"e9443c7415a0419799bee9cfbb1a9e4d","source":"clob_market_ws"},"received_at":"2026-07-27T04:40:27.297302Z","record_id":"c32e2910d6708899653b6d8cc74efe04c1dda41648ffc5d6b119312ab5964aed","schema_fingerprint":"4aa3821a28b0b7c2400bc59aba4bcc0a76e971dadd19610d3ad38c768e124dc7","schema_version":"edge-lab-recorder.raw.v1","sequence":null,"source":"clob_market_ws"}
{"event_at":"2026-07-27T04:40:27.373000Z","event_fingerprint":"ef12877d35adb45642efdf1e65587d8992c33dfe91cea227bfecd397a573eacd","payload":{"connection_id":"0f4979d6978d463e9660b042fdcf555f","event_at":"2026-07-27T04:40:27.373000Z","event_type":"price_change","frame_hash":"f011684ec44c67bec6eadad9e31391141b6d25e6a5a12018b41a7347df0868b2","frame_index":0,"kind":"data","monotonic_ns":229210587864083,"payload":{"event_type":"price_change","market":"0xeb66215f2e9faa6449e30a02bab5b8ed7b79a38bf961f6b24d0073c9c2419250","price_changes":[{"asset_id":"69697746896130839564035629862476347944307040470122503199396727085502753297492","best_ask":"0.73","best_bid":"0.72","hash":"f5c6223a8e52c2a35d7e99929e1850cee52e1705","price":"0.01","side":"BUY","size":"5633.02"},{"asset_id":"60386828328910021732068595344565885737045900010034836345809386672230885527307","best_ask":"0.28","best_bid":"0.27","hash":"f3418532fe3bbd33ba1fc0326ad869eb9503920a","price":"0.99","side":"SELL","size":"5633.02"}],"timestamp":"1785127227373"},"payload_hash":"814167410d4f1857751cc5dfca256fccf753e9d34fb3eb5cd24ae32a2ce10073","raw_frame":"{\"market\":\"0xeb66215f2e9faa6449e30a02bab5b8ed7b79a38bf961f6b24d0073c9c2419250\", \"price_changes\":[{\"asset_id\":\"69697746896130839564035629862476347944307040470122503199396727085502753297492\", \"price\":\"0.01\", \"size\":\"5633.02\", \"side\":\"BUY\", \"hash\":\"f5c6223a8e52c2a35d7e99929e1850cee52e1705\", \"best_bid\":\"0.72\", \"best_ask\":\"0.73\"}, {\"asset_id\":\"60386828328910021732068595344565885737045900010034836345809386672230885527307\", \"price\":\"0.99\", \"size\":\"5633.02\", \"side\":\"SELL\", \"hash\":\"f3418532fe3bbd33ba1fc0326ad869eb9503920a\", \"best_bid\":\"0.27\", \"best_ask\":\"0.28\"}], \"timestamp\":\"1785127227373\", \"event_type\":\"price_change\"}","received_at":"2026-07-27T04:40:27.323455Z","schema_version":"clob-market-ws.price_change.v1","sequence":null,"server_hash":null,"server_timestamp":"1785127227373","session_id":"e9443c7415a0419799bee9cfbb1a9e4d","source":"clob_market_ws"},"received_at":"2026-07-27T04:40:27.323455Z","record_id":"ce0a6e7d0fec29e4ddb649c77372b381a82b56bc3f7085e85306b6703cb82734","schema_fingerprint":"4aa3821a28b0b7c2400bc59aba4bcc0a76e971dadd19610d3ad38c768e124dc7","schema_version":"edge-lab-recorder.raw.v1","sequence":null,"source":"clob_market_ws"}
{"event_at":"2026-07-27T04:40:27.374000Z","event_fingerprint":"f0d3fd827f0b379ef893c6138337c4db37a31b9b63b9408d24a68f09c10fa679","payload":{"connection_id":"0f4979d6978d463e9660b042fdcf555f","event_at":"2026-07-27T04:40:27.374000Z","event_type":"price_change","frame_hash":"fd3c8ab69c58b1730312f02bf43e6058fcdcea3ec85ffdc8fb3b9f2bc4584ff3","frame_index":0,"kind":"data","monotonic_ns":229210593009583,"payload":{"event_type":"price_change","market":"0xeb66215f2e9faa6449e30a02bab5b8ed7b79a38bf961f6b24d0073c9c2419250","price_changes":[{"asset_id":"69697746896130839564035629862476347944307040470122503199396727085502753297492","best_ask":"0.73","best_bid":"0.72","hash":"f748b77da8b8f093fc5cbee0f62c9a1cde0d6e03","price":"0.7","side":"BUY","size":"41.94"},{"asset_id":"60386828328910021732068595344565885737045900010034836345809386672230885527307","best_ask":"0.28","best_bid":"0.27","hash":"bf55f6159ef48207f7f28e8697adbda1e696ee11","price":"0.3","side":"SELL","size":"41.94"}],"timestamp":"1785127227374"},"payload_hash":"b86dc3b5a71069b11d4d263e0309d1e5edccc70c916089071f10abcfb89e8034","raw_frame":"{\"market\":\"0xeb66215f2e9faa6449e30a02bab5b8ed7b79a38bf961f6b24d0073c9c2419250\", \"price_changes\":[{\"asset_id\":\"69697746896130839564035629862476347944307040470122503199396727085502753297492\", \"price\":\"0.7\", \"size\":\"41.94\", \"side\":\"BUY\", \"hash\":\"f748b77da8b8f093fc5cbee0f62c9a1cde0d6e03\", \"best_bid\":\"0.72\", \"best_ask\":\"0.73\"}, {\"asset_id\":\"60386828328910021732068595344565885737045900010034836345809386672230885527307\", \"price\":\"0.3\", \"size\":\"41.94\", \"side\":\"SELL\", \"hash\":\"bf55f6159ef48207f7f28e8697adbda1e696ee11\", \"best_bid\":\"0.27\", \"best_ask\":\"0.28\"}], \"timestamp\":\"1785127227374\", \"event_type\":\"price_change\"}","received_at":"2026-07-27T04:40:27.328609Z","schema_version":"clob-market-ws.price_change.v1","sequence":null,"server_hash":null,"server_timestamp":"1785127227374","session_id":"e9443c7415a0419799bee9cfbb1a9e4d","source":"clob_market_ws"},"received_at":"2026-07-27T04:40:27.328609Z","record_id":"565cc592431475a1665f92abc8a43aa428bb883ddf937a90a87c9c4b3bea59d6","schema_fingerprint":"4aa3821a28b0b7c2400bc59aba4bcc0a76e971dadd19610d3ad38c768e124dc7","schema_version":"edge-lab-recorder.raw.v1","sequence":null,"source":"clob_market_ws"}
{"event_at":"2026-07-27T04:40:27.379000Z","event_fingerprint":"92ad66e693ccec63a53d9ca4207e63d24313e038aaf27a4245bff587579517da","payload":{"connection_id":"0f4979d6978d463e9660b042fdcf555f","event_at":"2026-07-27T04:40:27.379000Z","event_type":"price_change","frame_hash":"1cf04a60b2303de82154448d5a6cbe8ac2c1c95c887d92c4947c3377d9c77562","frame_index":0,"kind":"data","monotonic_ns":229210597615833,"payload":{"event_type":"price_change","market":"0xeb66215f2e9faa6449e30a02bab5b8ed7b79a38bf961f6b24d0073c9c2419250","price_changes":[{"asset_id":"69697746896130839564035629862476347944307040470122503199396727085502753297492","best_ask":"0.73","best_bid":"0.72","hash":"0922f480f5bf670756ff89b45a72c313aaca9b52","price":"0.68","side":"BUY","size":"306.4"},{"asset_id":"60386828328910021732068595344565885737045900010034836345809386672230885527307","best_ask":"0.28","best_bid":"0.27","hash":"c3b3d26d7fb8eca5fa54aec7137698f5429fa078","price":"0.32","side":"SELL","size":"306.4"}],"timestamp":"1785127227379"},"payload_hash":"eddd4f55e03db1b6423f38d1dcfed07bc57347b95a13ae29d4681ca5023db1e5","raw_frame":"{\"market\":\"0xeb66215f2e9faa6449e30a02bab5b8ed7b79a38bf961f6b24d0073c9c2419250\", \"price_changes\":[{\"asset_id\":\"69697746896130839564035629862476347944307040470122503199396727085502753297492\", \"price\":\"0.68\", \"size\":\"306.4\", \"side\":\"BUY\", \"hash\":\"0922f480f5bf670756ff89b45a72c313aaca9b52\", \"best_bid\":\"0.72\", \"best_ask\":\"0.73\"}, {\"asset_id\":\"60386828328910021732068595344565885737045900010034836345809386672230885527307\", \"price\":\"0.32\", \"size\":\"306.4\", \"side\":\"SELL\", \"hash\":\"c3b3d26d7fb8eca5fa54aec7137698f5429fa078\", \"best_bid\":\"0.27\", \"best_ask\":\"0.28\"}], \"timestamp\":\"1785127227379\", \"event_type\":\"price_change\"}","received_at":"2026-07-27T04:40:27.333214Z","schema_version":"clob-market-ws.price_change.v1","sequence":null,"server_hash":null,"server_timestamp":"1785127227379","session_id":"e9443c7415a0419799bee9cfbb1a9e4d","source":"clob_market_ws"},"received_at":"2026-07-27T04:40:27.333214Z","record_id":"8f1dd115e31b9e84dfb15472108407d4ffbbb623f1958606a662265e0db9a28f","schema_fingerprint":"4aa3821a28b0b7c2400bc59aba4bcc0a76e971dadd19610d3ad38c768e124dc7","schema_version":"edge-lab-recorder.raw.v1","sequence":null,"source":"clob_market_ws"}
{"event_at":"2026-07-27T04:40:27.380000Z","event_fingerprint":"0f067c4da79c120ca18f4612af42dabb474e04e30671aa832465d8e34d0422f1","payload":{"connection_id":"0f4979d6978d463e9660b042fdcf555f","event_at":"2026-07-27T04:40:27.380000Z","event_type":"price_change","frame_hash":"9b28734705a0fcef940b8dc243a37b70dc533ec010922c87fc36da9f35b2bbe9","frame_index":0,"kind":"data","monotonic_ns":229210601871666,"payload":{"event_type":"price_change","market":"0xeb66215f2e9faa6449e30a02bab5b8ed7b79a38bf961f6b24d0073c9c2419250","price_changes":[{"asset_id":"60386828328910021732068595344565885737045900010034836345809386672230885527307","best_ask":"0.28","best_bid":"0.27","hash":"37a660b7b0a2ad42e75979d57664127c25f97d94","price":"0.3","side":"SELL","size":"84.94"},{"asset_id":"69697746896130839564035629862476347944307040470122503199396727085502753297492","best_ask":"0.73","best_bid":"0.72","hash":"76f86513b2097877136c50b829e5fda2bc1a82ef","price":"0.7","side":"BUY","size":"84.94"}],"timestamp":"1785127227380"},"payload_hash":"e46f84c7889bf944d82bd6c9de960f590f134563e26ac30157e8b4e45bc0dc12","raw_frame":"{\"market\":\"0xeb66215f2e9faa6449e30a02bab5b8ed7b79a38bf961f6b24d0073c9c2419250\", \"price_changes\":[{\"asset_id\":\"60386828328910021732068595344565885737045900010034836345809386672230885527307\", \"price\":\"0.3\", \"size\":\"84.94\", \"side\":\"SELL\", \"hash\":\"37a660b7b0a2ad42e75979d57664127c25f97d94\", \"best_bid\":\"0.27\", \"best_ask\":\"0.28\"}, {\"asset_id\":\"69697746896130839564035629862476347944307040470122503199396727085502753297492\", \"price\":\"0.7\", \"size\":\"84.94\", \"side\":\"BUY\", \"hash\":\"76f86513b2097877136c50b829e5fda2bc1a82ef\", \"best_bid\":\"0.72\", \"best_ask\":\"0.73\"}], \"timestamp\":\"1785127227380\", \"event_type\":\"price_change\"}","received_at":"2026-07-27T04:40:27.337466Z","schema_version":"clob-market-ws.price_change.v1","sequence":null,"server_hash":null,"server_timestamp":"1785127227380","session_id":"e9443c7415a0419799bee9cfbb1a9e4d","source":"clob_market_ws"},"received_at":"2026-07-27T04:40:27.337466Z","record_id":"e970c14479a17e05f3b4ef77d388307af0d01f4335ba8da3db9762e0b3423516","schema_fingerprint":"4aa3821a28b0b7c2400bc59aba4bcc0a76e971dadd19610d3ad38c768e124dc7","schema_version":"edge-lab-recorder.raw.v1","sequence":null,"source":"clob_market_ws"}
{"event_at":"2026-07-27T04:40:27.381000Z","event_fingerprint":"7bb8fbe8a39cc0bfde1a258edceecac17d5c26aabbadd6b2747f541a20ba3999","payload":{"connection_id":"0f4979d6978d463e9660b042fdcf555f","event_at":"2026-07-27T04:40:27.381000Z","event_type":"price_change","frame_hash":"61c3da047e8e84705cc94595a3b36a6172f0218cab1ed2200354097b0ca2302a","frame_index":0,"kind":"data","monotonic_ns":229210606322458,"payload":{"event_type":"price_change","market":"0xeb66215f2e9faa6449e30a02bab5b8ed7b79a38bf961f6b24d0073c9c2419250","price_changes":[{"asset_id":"60386828328910021732068595344565885737045900010034836345809386672230885527307","best_ask":"0.28","best_bid":"0.27","hash":"99da825a7a3ae2954c4fcd8b5d8ad85945f14de8","price":"0.31","side":"SELL","size":"166.23"},{"asset_id":"69697746896130839564035629862476347944307040470122503199396727085502753297492","best_ask":"0.73","best_bid":"0.72","hash":"4abbfef78431767d833c0409ac76785760335d36","price":"0.69","side":"BUY","size":"166.23"}],"timestamp":"1785127227381"},"payload_hash":"ac0ade59ce197435c401db8efb76981b63772143c68498488d67396b70fa8e32","raw_frame":"{\"market\":\"0xeb66215f2e9faa6449e30a02bab5b8ed7b79a38bf961f6b24d0073c9c2419250\", \"price_changes\":[{\"asset_id\":\"60386828328910021732068595344565885737045900010034836345809386672230885527307\", \"price\":\"0.31\", \"size\":\"166.23\", \"side\":\"SELL\", \"hash\":\"99da825a7a3ae2954c4fcd8b5d8ad85945f14de8\", \"best_bid\":\"0.27\", \"best_ask\":\"0.28\"}, {\"asset_id\":\"69697746896130839564035629862476347944307040470122503199396727085502753297492\", \"price\":\"0.69\", \"size\":\"166.23\", \"side\":\"BUY\", \"hash\":\"4abbfef78431767d833c0409ac76785760335d36\", \"best_bid\":\"0.72\", \"best_ask\":\"0.73\"}], \"timestamp\":\"1785127227381\", \"event_type\":\"price_change\"}","received_at":"2026-07-27T04:40:27.341922Z","schema_version":"clob-market-ws.price_change.v1","sequence":null,"server_hash":null,"server_timestamp":"1785127227381","session_id":"e9443c7415a0419799bee9cfbb1a9e4d","source":"clob_market_ws"},"received_at":"2026-07-27T04:40:27.341922Z","record_id":"2c6be83fd0ba8bc4d3b55f11017341e195fe4f8b12077cfeea260f0617bbd9e8","schema_fingerprint":"4aa3821a28b0b7c2400bc59aba4bcc0a76e971dadd19610d3ad38c768e124dc7","schema_version":"edge-lab-recorder.raw.v1","sequence":null,"source":"clob_market_ws"}
{"event_at":"2026-07-27T04:40:27.413000Z","event_fingerprint":"427b697e88f552e513be2d1c1c6283ebade11093ae399352eabd520647ab4276","payload":{"connection_id":"0f4979d6978d463e9660b042fdcf555f","event_at":"2026-07-27T04:40:27.413000Z","event_type":"price_change","frame_hash":"19619cd6ec4152c6b958646fcf91b1294bcd4e0afcc22ae228da333425ad21c0","frame_index":0,"kind":"data","monotonic_ns":229210628744541,"payload":{"event_type":"price_change","market":"0xeb66215f2e9faa6449e30a02bab5b8ed7b79a38bf961f6b24d0073c9c2419250","price_changes":[{"asset_id":"60386828328910021732068595344565885737045900010034836345809386672230885527307","best_ask":"0.28","best_bid":"0.27","hash":"d2874728fd7ee5fb52bf72ffcfcfbc536216cf32","price":"0.15","side":"BUY","size":"211"},{"asset_id":"69697746896130839564035629862476347944307040470122503199396727085502753297492","best_ask":"0.73","best_bid":"0.72","hash":"51520145cb8181e9e26f83aa84284812cc21a11c","price":"0.85","side":"SELL","size":"211"}],"timestamp":"1785127227413"},"payload_hash":"7cc1a1c03203a34b742f4f3278039061d79f7a30cc9238f9d1907e76188198e3","raw_frame":"{\"market\":\"0xeb66215f2e9faa6449e30a02bab5b8ed7b79a38bf961f6b24d0073c9c2419250\", \"price_changes\":[{\"asset_id\":\"60386828328910021732068595344565885737045900010034836345809386672230885527307\", \"price\":\"0.15\", \"size\":\"211\", \"side\":\"BUY\", \"hash\":\"d2874728fd7ee5fb52bf72ffcfcfbc536216cf32\", \"best_bid\":\"0.27\", \"best_ask\":\"0.28\"}, {\"asset_id\":\"69697746896130839564035629862476347944307040470122503199396727085502753297492\", \"price\":\"0.85\", \"size\":\"211\", \"side\":\"SELL\", \"hash\":\"51520145cb8181e9e26f83aa84284812cc21a11c\", \"best_bid\":\"0.72\", \"best_ask\":\"0.73\"}], \"timestamp\":\"1785127227413\", \"event_type\":\"price_change\"}","received_at":"2026-07-27T04:40:27.364344Z","schema_version":"clob-market-ws.price_change.v1","sequence":null,"server_hash":null,"server_timestamp":"1785127227413","session_id":"e9443c7415a0419799bee9cfbb1a9e4d","source":"clob_market_ws"},"received_at":"2026-07-27T04:40:27.364344Z","record_id":"2b3a91b99d0a892e9b6392729e7d61f5c5078294eef0b810c39c99294e43ad73","schema_fingerprint":"4aa3821a28b0b7c2400bc59aba4bcc0a76e971dadd19610d3ad38c768e124dc7","schema_version":"edge-lab-recorder.raw.v1","sequence":null,"source":"clob_market_ws"}
{"event_at":"2026-07-27T04:40:27.494000Z","event_fingerprint":"6b8b4392341432c052ddfbed89aefaf1d9334d8bcd1b79986720ed612e1cf2a8","payload":{"connection_id":"0f4979d6978d463e9660b042fdcf555f","event_at":"2026-07-27T04:40:27.494000Z","event_type":"price_change","frame_hash":"5cf40284847329eb7acb32455ef3843580af3228b79eec59cbc1ad55cfdba23d","frame_index":0,"kind":"data","monotonic_ns":229210707712333,"payload":{"event_type":"price_change","market":"0xeb66215f2e9faa6449e30a02bab5b8ed7b79a38bf961f6b24d0073c9c2419250","price_changes":[{"asset_id":"69697746896130839564035629862476347944307040470122503199396727085502753297492","best_ask":"0.73","best_bid":"0.72","hash":"85f451ea729d54924bc2bcc46849cf5753a19831","price":"0.68","side":"BUY","size":"298.4"},{"asset_id":"60386828328910021732068595344565885737045900010034836345809386672230885527307","best_ask":"0.28","best_bid":"0.27","hash":"79e6ed066c0036b5c226942d8f56e9cd1bdf5106","price":"0.32","side":"SELL","size":"298.4"}],"timestamp":"1785127227494"},"payload_hash":"a5a7c26b914b0b7f3ec37c78ce45f8cede63c85a80b283a40ec4424f4da30c3d","raw_frame":"{\"market\":\"0xeb66215f2e9faa6449e30a02bab5b8ed7b79a38bf961f6b24d0073c9c2419250\", \"price_changes\":[{\"asset_id\":\"69697746896130839564035629862476347944307040470122503199396727085502753297492\", \"price\":\"0.68\", \"size\":\"298.4\", \"side\":\"BUY\", \"hash\":\"85f451ea729d54924bc2bcc46849cf5753a19831\", \"best_bid\":\"0.72\", \"best_ask\":\"0.73\"}, {\"asset_id\":\"60386828328910021732068595344565885737045900010034836345809386672230885527307\", \"price\":\"0.32\", \"size\":\"298.4\", \"side\":\"SELL\", \"hash\":\"79e6ed066c0036b5c226942d8f56e9cd1bdf5106\", \"best_bid\":\"0.27\", \"best_ask\":\"0.28\"}], \"timestamp\":\"1785127227494\", \"event_type\":\"price_change\"}","received_at":"2026-07-27T04:40:27.443312Z","schema_version":"clob-market-ws.price_change.v1","sequence":null,"server_hash":null,"server_timestamp":"1785127227494","session_id":"e9443c7415a0419799bee9cfbb1a9e4d","source":"clob_market_ws"},"received_at":"2026-07-27T04:40:27.443312Z","record_id":"9a37649e2f138329f5bdae026a66d88361933fca717edacb568fd7217dc4059e","schema_fingerprint":"4aa3821a28b0b7c2400bc59aba4bcc0a76e971dadd19610d3ad38c768e124dc7","schema_version":"edge-lab-recorder.raw.v1","sequence":null,"source":"clob_market_ws"}
{"event_at":"2026-07-27T04:40:27.495000Z","event_fingerprint":"67d78c80efd22bc053d84f0edc19f5ebc0705bb468535c50079bfc2561919dd2","payload":{"connection_id":"0f4979d6978d463e9660b042fdcf555f","event_at":"2026-07-27T04:40:27.495000Z","event_type":"price_change","frame_hash":"be0f85a5473906fec4853bd519501ddad2122f8f363ea0a32a29ccabf87b2222","frame_index":0,"kind":"data","monotonic_ns":229210712305250,"payload":{"event_type":"price_change","market":"0xeb66215f2e9faa6449e30a02bab5b8ed7b79a38bf961f6b24d0073c9c2419250","price_changes":[{"asset_id":"60386828328910021732068595344565885737045900010034836345809386672230885527307","best_ask":"0.28","best_bid":"0.27","hash":"ba5b8c841fcca5050aedd611f6d73337d51c2371","price":"0.3","side":"SELL","size":"41.94"},{"asset_id":"69697746896130839564035629862476347944307040470122503199396727085502753297492","best_ask":"0.73","best_bid":"0.72","hash":"24ccab05d7655f4b6a912ba67d0b5abf395009b0","price":"0.7","side":"BUY","size":"41.94"}],"timestamp":"1785127227495"},"payload_hash":"ab940f1dc5f2385d04e2297d700713da4ebc900219ba6da5e123ce798e186f2e","raw_frame":"{\"market\":\"0xeb66215f2e9faa6449e30a02bab5b8ed7b79a38bf961f6b24d0073c9c2419250\", \"price_changes\":[{\"asset_id\":\"60386828328910021732068595344565885737045900010034836345809386672230885527307\", \"price\":\"0.3\", \"size\":\"41.94\", \"side\":\"SELL\", \"hash\":\"ba5b8c841fcca5050aedd611f6d73337d51c2371\", \"best_bid\":\"0.27\", \"best_ask\":\"0.28\"}, {\"asset_id\":\"69697746896130839564035629862476347944307040470122503199396727085502753297492\", \"price\":\"0.7\", \"size\":\"41.94\", \"side\":\"BUY\", \"hash\":\"24ccab05d7655f4b6a912ba67d0b5abf395009b0\", \"best_bid\":\"0.72\", \"best_ask\":\"0.73\"}], \"timestamp\":\"1785127227495\", \"event_type\":\"price_change\"}","received_at":"2026-07-27T04:40:27.447907Z","schema_version":"clob-market-ws.price_change.v1","sequence":null,"server_hash":null,"server_timestamp":"1785127227495","session_id":"e9443c7415a0419799bee9cfbb1a9e4d","source":"clob_market_ws"},"received_at":"2026-07-27T04:40:27.447907Z","record_id":"361eb43faf160c9a874d35348898a1fd3429b6b0323878e301baf845df87ff80","schema_fingerprint":"4aa3821a28b0b7c2400bc59aba4bcc0a76e971dadd19610d3ad38c768e124dc7","schema_version":"edge-lab-recorder.raw.v1","sequence":null,"source":"clob_market_ws"}
{"event_at":"2026-07-27T04:40:27.496000Z","event_fingerprint":"1e385ef233da2cf527996fff864034661f24af08e7c16d40ea9f48ad829ae576","payload":{"connection_id":"0f4979d6978d463e9660b042fdcf555f","event_at":"2026-07-27T04:40:27.496000Z","event_type":"price_change","frame_hash":"235211e9afbd57c185b0b810c3338397872cab9902cdb274e42340a2a9b33997","frame_index":0,"kind":"data","monotonic_ns":229210715730041,"payload":{"event_type":"price_change","market":"0xeb66215f2e9faa6449e30a02bab5b8ed7b79a38bf961f6b24d0073c9c2419250","price_changes":[{"asset_id":"60386828328910021732068595344565885737045900010034836345809386672230885527307","best_ask":"0.28","best_bid":"0.27","hash":"e07364f0daa16fb23339bd37dd6dfb8a962b5872","price":"0.31","side":"SELL","size":"159.16"},{"asset_id":"69697746896130839564035629862476347944307040470122503199396727085502753297492","best_ask":"0.73","best_bid":"0.72","hash":"68f00bcae9f4a6147e0ca1d379c5a569d33eecde","price":"0.69","side":"BUY","size":"159.16"}],"timestamp":"1785127227496"},"payload_hash":"7e05dfbd50537d381e801cb4686e27980e83f2894cc882da253109309fe4587f","raw_frame":"{\"market\":\"0xeb66215f2e9faa6449e30a02bab5b8ed7b79a38bf961f6b24d0073c9c2419250\", \"price_changes\":[{\"asset_id\":\"60386828328910021732068595344565885737045900010034836345809386672230885527307\", \"price\":\"0.31\", \"size\":\"159.16\", \"side\":\"SELL\", \"hash\":\"e07364f0daa16fb23339bd37dd6dfb8a962b5872\", \"best_bid\":\"0.27\", \"best_ask\":\"0.28\"}, {\"asset_id\":\"69697746896130839564035629862476347944307040470122503199396727085502753297492\", \"price\":\"0.69\", \"size\":\"159.16\", \"side\":\"BUY\", \"hash\":\"68f00bcae9f4a6147e0ca1d379c5a569d33eecde\", \"best_bid\":\"0.72\", \"best_ask\":\"0.73\"}], \"timestamp\":\"1785127227496\", \"event_type\":\"price_change\"}","received_at":"2026-07-27T04:40:27.451333Z","schema_version":"clob-market-ws.price_change.v1","sequence":null,"server_hash":null,"server_timestamp":"1785127227496","session_id":"e9443c7415a0419799bee9cfbb1a9e4d","source":"clob_market_ws"},"received_at":"2026-07-27T04:40:27.451333Z","record_id":"8f5a4c740e8d71137a8a869193d7fd02d93a7a728672eea2705bd45fba909bf8","schema_fingerprint":"4aa3821a28b0b7c2400bc59aba4bcc0a76e971dadd19610d3ad38c768e124dc7","schema_version":"edge-lab-recorder.raw.v1","sequence":null,"source":"clob_market_ws"}
{"event_at":"2026-07-27T04:40:27.503000Z","event_fingerprint":"820c115e667cfed104c1a088293d0b8589990e10168eaccc43bc634422326adf","payload":{"connection_id":"0f4979d6978d463e9660b042fdcf555f","event_at":"2026-07-27T04:40:27.503000Z","event_type":"price_change","frame_hash":"de07e69bf9089e4c052fbbcfc8a2148c9602e9ba7761e2001e5c3ec3754f18a6","frame_index":0,"kind":"data","monotonic_ns":229210719007250,"payload":{"event_type":"price_change","market":"0xeb66215f2e9faa6449e30a02bab5b8ed7b79a38bf961f6b24d0073c9c2419250","price_changes":[{"asset_id":"69697746896130839564035629862476347944307040470122503199396727085502753297492","best_ask":"0.73","best_bid":"0.72","hash":"e8e82d72578c7dc3dc68fcbc59c6b15613c0f7ed","price":"0.03","side":"BUY","size":"618.1"},{"asset_id":"60386828328910021732068595344565885737045900010034836345809386672230885527307","best_ask":"0.28","best_bid":"0.27","hash":"27655b3b7b4bdbb3d140f9b95459d493367fa45a","price":"0.97","side":"SELL","size":"618.1"}],"timestamp":"1785127227503"},"payload_hash":"dd20233a03d265960a795ef9b6707f6f1bc8c29107ba6ee848b0a0b9040d32ae","raw_frame":"{\"market\":\"0xeb66215f2e9faa6449e30a02bab5b8ed7b79a38bf961f6b24d0073c9c2419250\", \"price_changes\":[{\"asset_id\":\"69697746896130839564035629862476347944307040470122503199396727085502753297492\", \"price\":\"0.03\", \"size\":\"618.1\", \"side\":\"BUY\", \"hash\":\"e8e82d72578c7dc3dc68fcbc59c6b15613c0f7ed\", \"best_bid\":\"0.72\", \"best_ask\":\"0.73\"}, {\"asset_id\":\"60386828328910021732068595344565885737045900010034836345809386672230885527307\", \"price\":\"0.97\", \"size\":\"618.1\", \"side\":\"SELL\", \"hash\":\"27655b3b7b4bdbb3d140f9b95459d493367fa45a\", \"best_bid\":\"0.27\", \"best_ask\":\"0.28\"}], \"timestamp\":\"1785127227503\", \"event_type\":\"price_change\"}","received_at":"2026-07-27T04:40:27.454558Z","schema_version":"clob-market-ws.price_change.v1","sequence":null,"server_hash":null,"server_timestamp":"1785127227503","session_id":"e9443c7415a0419799bee9cfbb1a9e4d","source":"clob_market_ws"},"received_at":"2026-07-27T04:40:27.454558Z","record_id":"3f0ed4de70ff1d45190811a3efbeacda32eeb94be22f6325edaf71bd941ecd12","schema_fingerprint":"4aa3821a28b0b7c2400bc59aba4bcc0a76e971dadd19610d3ad38c768e124dc7","schema_version":"edge-lab-recorder.raw.v1","sequence":null,"source":"clob_market_ws"}
{"event_at":"2026-07-27T04:40:27.504000Z","event_fingerprint":"d9357e6f2738830f1b310ac2b9b693d3992731bd7234599224e66bcaa59c7466","payload":{"connection_id":"0f4979d6978d463e9660b042fdcf555f","event_at":"2026-07-27T04:40:27.504000Z","event_type":"price_change","frame_hash":"9cbf434aaa4e83ce444ad6b17c51f3efbf72e042cefa8ec465e5e11ec570325d","frame_index":0,"kind":"data","monotonic_ns":229210723851041,"payload":{"event_type":"price_change","market":"0xeb66215f2e9faa6449e30a02bab5b8ed7b79a38bf961f6b24d0073c9c2419250","price_changes":[{"asset_id":"69697746896130839564035629862476347944307040470122503199396727085502753297492","best_ask":"0.73","best_bid":"0.72","hash":"704ed78db60419da3196dc26a3ab2eaa92e5e106","price":"0.7","side":"BUY","size":"83.94"},{"asset_id":"60386828328910021732068595344565885737045900010034836345809386672230885527307","best_ask":"0.28","best_bid":"0.27","hash":"0b029a25044c4eceb3245e71b2516d89a249a6a4","price":"0.3","side":"SELL","size":"83.94"}],"timestamp":"1785127227504"},"payload_hash":"70aead717b6e07637f78669a1dfa331f81affdea9f298fc122f1d0b4106fa460","raw_frame":"{\"market\":\"0xeb66215f2e9faa6449e30a02bab5b8ed7b79a38bf961f6b24d0073c9c2419250\", \"price_changes\":[{\"asset_id\":\"69697746896130839564035629862476347944307040470122503199396727085502753297492\", \"price\":\"0.7\", \"size\":\"83.94\", \"side\":\"BUY\", \"hash\":\"704ed78db60419da3196dc26a3ab2eaa92e5e106\", \"best_bid\":\"0.72\", \"best_ask\":\"0.73\"}, {\"asset_id\":\"60386828328910021732068595344565885737045900010034836345809386672230885527307\", \"price\":\"0.3\", \"size\":\"83.94\", \"side\":\"SELL\", \"hash\":\"0b029a25044c4eceb3245e71b2516d89a249a6a4\", \"best_bid\":\"0.27\", \"best_ask\":\"0.28\"}], \"timestamp\":\"1785127227504\", \"event_type\":\"price_change\"}","received_at":"2026-07-27T04:40:27.459456Z","schema_version":"clob-market-ws.price_change.v1","sequence":null,"server_hash":null,"server_timestamp":"1785127227504","session_id":"e9443c7415a0419799bee9cfbb1a9e4d","source":"clob_market_ws"},"received_at":"2026-07-27T04:40:27.459456Z","record_id":"3e5037f9bdc7487797b28fdbba5e7550dc076564e9dfc348ffa1055e4038b244","schema_fingerprint":"4aa3821a28b0b7c2400bc59aba4bcc0a76e971dadd19610d3ad38c768e124dc7","schema_version":"edge-lab-recorder.raw.v1","sequence":null,"source":"clob_market_ws"}
{"event_at":"2026-07-27T04:40:27.522000Z","event_fingerprint":"f997df38d69ad0b102b20afc39a493ad98a1f8cb7fc261d1b296ad13262f21d5","payload":{"connection_id":"0f4979d6978d463e9660b042fdcf555f","event_at":"2026-07-27T04:40:27.522000Z","event_type":"price_change","frame_hash":"8de25feec3d417c4b6eafdd1f438444fe8d9916d055857a87edb849ef32b2e06","frame_index":0,"kind":"data","monotonic_ns":229210734408791,"payload":{"event_type":"price_change","market":"0xeb66215f2e9faa6449e30a02bab5b8ed7b79a38bf961f6b24d0073c9c2419250","price_changes":[{"asset_id":"69697746896130839564035629862476347944307040470122503199396727085502753297492","best_ask":"0.73","best_bid":"0.72","hash":"3e80a91eb1f6a0dd30003688d09afabe177100c6","price":"0.65","side":"BUY","size":"56.2"},{"asset_id":"60386828328910021732068595344565885737045900010034836345809386672230885527307","best_ask":"0.28","best_bid":"0.27","hash":"05e22171c980c71251ded3d5e2116e278d02bfb9","price":"0.35","side":"SELL","size":"56.2"}],"timestamp":"1785127227522"},"payload_hash":"2a24221875a74130d958f51ec7a4a77a79a93e61b01ec89a57b7f2845ada0930","raw_frame":"{\"market\":\"0xeb66215f2e9faa6449e30a02bab5b8ed7b79a38bf961f6b24d0073c9c2419250\", \"price_changes\":[{\"asset_id\":\"69697746896130839564035629862476347944307040470122503199396727085502753297492\", \"price\":\"0.65\", \"size\":\"56.2\", \"side\":\"BUY\", \"hash\":\"3e80a91eb1f6a0dd30003688d09afabe177100c6\", \"best_bid\":\"0.72\", \"best_ask\":\"0.73\"}, {\"asset_id\":\"60386828328910021732068595344565885737045900010034836345809386672230885527307\", \"price\":\"0.35\", \"size\":\"56.2\", \"side\":\"SELL\", \"hash\":\"05e22171c980c71251ded3d5e2116e278d02bfb9\", \"best_bid\":\"0.27\", \"best_ask\":\"0.28\"}], \"timestamp\":\"1785127227522\", \"event_type\":\"price_change\"}","received_at":"2026-07-27T04:40:27.470016Z","schema_version":"clob-market-ws.price_change.v1","sequence":null,"server_hash":null,"server_timestamp":"1785127227522","session_id":"e9443c7415a0419799bee9cfbb1a9e4d","source":"clob_market_ws"},"received_at":"2026-07-27T04:40:27.470016Z","record_id":"2345c65684b6c8af56af389b237a868e1386f73ecf7ad4f22ca3a6a09424d20e","schema_fingerprint":"4aa3821a28b0b7c2400bc59aba4bcc0a76e971dadd19610d3ad38c768e124dc7","schema_version":"edge-lab-recorder.raw.v1","sequence":null,"source":"clob_market_ws"}
{"event_at":"2026-07-27T04:40:27.531000Z","event_fingerprint":"f6bdfac9ad5bdf83b7a5d8b4f3e7cc6eca3c7293b83e0dc6177c10d58a0739a7","payload":{"connection_id":"0f4979d6978d463e9660b042fdcf555f","event_at":"2026-07-27T04:40:27.531000Z","event_type":"price_change","frame_hash":"e81091528d19a004d8fc6b82fef4e68a9b3ba64e70f5651d02679d2cc0266fe8","frame_index":0,"kind":"data","monotonic_ns":229210754329333,"payload":{"event_type":"price_change","market":"0xeb66215f2e9faa6449e30a02bab5b8ed7b79a38bf961f6b24d0073c9c2419250","price_changes":[{"asset_id":"69697746896130839564035629862476347944307040470122503199396727085502753297492","best_ask":"0.73","best_bid":"0.72","hash":"805b6e70e0acf893d5cf82f0b90a8a7de5d49f46","price":"0.61","side":"BUY","size":"147.6"},{"asset_id":"60386828328910021732068595344565885737045900010034836345809386672230885527307","best_ask":"0.28","best_bid":"0.27","hash":"f00fe667c9cac3447d06f8fbd48cda78dd86f2d7","price":"0.39","side":"SELL","size":"147.6"}],"timestamp":"1785127227531"},"payload_hash":"3e587e675cf9386d9bc747145aa9416c3a1abf4097e457d15897b8cdd2b2fde3","raw_frame":"{\"market\":\"0xeb66215f2e9faa6449e30a02bab5b8ed7b79a38bf961f6b24d0073c9c2419250\", \"price_changes\":[{\"asset_id\":\"69697746896130839564035629862476347944307040470122503199396727085502753297492\", \"price\":\"0.61\", \"size\":\"147.6\", \"side\":\"BUY\", \"hash\":\"805b6e70e0acf893d5cf82f0b90a8a7de5d49f46\", \"best_bid\":\"0.72\", \"best_ask\":\"0.73\"}, {\"asset_id\":\"60386828328910021732068595344565885737045900010034836345809386672230885527307\", \"price\":\"0.39\", \"size\":\"147.6\", \"side\":\"SELL\", \"hash\":\"f00fe667c9cac3447d06f8fbd48cda78dd86f2d7\", \"best_bid\":\"0.27\", \"best_ask\":\"0.28\"}], \"timestamp\":\"1785127227531\", \"event_type\":\"price_change\"}","received_at":"2026-07-27T04:40:27.489934Z","schema_version":"clob-market-ws.price_change.v1","sequence":null,"server_hash":null,"server_timestamp":"1785127227531","session_id":"e9443c7415a0419799bee9cfbb1a9e4d","source":"clob_market_ws"},"received_at":"2026-07-27T04:40:27.489934Z","record_id":"3311df7143e5c8f4d3e66753a6f89f5f3268ddf50b2d584b108b3a00a86feab3","schema_fingerprint":"4aa3821a28b0b7c2400bc59aba4bcc0a76e971dadd19610d3ad38c768e124dc7","schema_version":"edge-lab-recorder.raw.v1","sequence":null,"source":"clob_market_ws"}
{"event_at":"2026-07-27T04:40:27.536000Z","event_fingerprint":"b150aac2c174a33124bedaf12d91604904a19f6e62a4935624a65259aea0dbfd","payload":{"connection_id":"0f4979d6978d463e9660b042fdcf555f","event_at":"2026-07-27T04:40:27.536000Z","event_type":"price_change","frame_hash":"e70b7a894d913d8ddc0c756808599424013443f7e2bf5267c719ef3a5ebcf1d6","frame_index":0,"kind":"data","monotonic_ns":229210756816041,"payload":{"event_type":"price_change","market":"0xeb66215f2e9faa6449e30a02bab5b8ed7b79a38bf961f6b24d0073c9c2419250","price_changes":[{"asset_id":"69697746896130839564035629862476347944307040470122503199396727085502753297492","best_ask":"0.73","best_bid":"0.72","hash":"4350ff19fa39f5e1594c7a81c453c2a39ee4ddf5","price":"0.01","side":"BUY","size":"5638.02"},{"asset_id":"60386828328910021732068595344565885737045900010034836345809386672230885527307","best_ask":"0.28","best_bid":"0.27","hash":"74c5907a91cba2cbd4d64ac3d25d2a6ec3c96600","price":"0.99","side":"SELL","size":"5638.02"}],"timestamp":"1785127227536"},"payload_hash":"d095e191f17051a55a1457ead60354bc1b94a5ae5522f81e9f5adeabb80bf57c","raw_frame":"{\"market\":\"0xeb66215f2e9faa6449e30a02bab5b8ed7b79a38bf961f6b24d0073c9c2419250\", \"price_changes\":[{\"asset_id\":\"69697746896130839564035629862476347944307040470122503199396727085502753297492\", \"price\":\"0.01\", \"size\":\"5638.02\", \"side\":\"BUY\", \"hash\":\"4350ff19fa39f5e1594c7a81c453c2a39ee4ddf5\", \"best_bid\":\"0.72\", \"best_ask\":\"0.73\"}, {\"asset_id\":\"60386828328910021732068595344565885737045900010034836345809386672230885527307\", \"price\":\"0.99\", \"size\":\"5638.02\", \"side\":\"SELL\", \"hash\":\"74c5907a91cba2cbd4d64ac3d25d2a6ec3c96600\", \"best_bid\":\"0.27\", \"best_ask\":\"0.28\"}], \"timestamp\":\"1785127227536\", \"event_type\":\"price_change\"}","received_at":"2026-07-27T04:40:27.492422Z","schema_version":"clob-market-ws.price_change.v1","sequence":null,"server_hash":null,"server_timestamp":"1785127227536","session_id":"e9443c7415a0419799bee9cfbb1a9e4d","source":"clob_market_ws"},"received_at":"2026-07-27T04:40:27.492422Z","record_id":"4481f9ebf077a051c66d8f8f6e96ac7bcb307ddc45078a79835bbb3391bdb4af","schema_fingerprint":"4aa3821a28b0b7c2400bc59aba4bcc0a76e971dadd19610d3ad38c768e124dc7","schema_version":"edge-lab-recorder.raw.v1","sequence":null,"source":"clob_market_ws"}
{"event_at":"2026-07-27T04:40:27.557000Z","event_fingerprint":"b460aea5e36d93296e36afa99c45dc040d05f04ae7e5b2d5a1c85070e338d899","payload":{"connection_id":"0f4979d6978d463e9660b042fdcf555f","event_at":"2026-07-27T04:40:27.557000Z","event_type":"price_change","frame_hash":"fa757bb41a5d27f52c55285dbb205a290d64df7c11db01ee3b28f2d8567ff63e","frame_index":0,"kind":"data","monotonic_ns":229210769931291,"payload":{"event_type":"price_change","market":"0xeb66215f2e9faa6449e30a02bab5b8ed7b79a38bf961f6b24d0073c9c2419250","price_changes":[{"asset_id":"69697746896130839564035629862476347944307040470122503199396727085502753297492","best_ask":"0.73","best_bid":"0.72","hash":"200e3ed3fba4bfe5b0ca4ef00e5d300204c23aab","price":"0.6","side":"BUY","size":"241.5"},{"asset_id":"60386828328910021732068595344565885737045900010034836345809386672230885527307","best_ask":"0.28","best_bid":"0.27","hash":"f875e740383df81e9ed284527f17066765c6ad6a","price":"0.4","side":"SELL","size":"241.5"}],"timestamp":"1785127227557"},"payload_hash":"35bd13f56d2fcf93066f9bcbb77819721209f06678590eb92fd4e4066bb1dbc3","raw_frame":"{\"market\":\"0xeb66215f2e9faa6449e30a02bab5b8ed7b79a38bf961f6b24d0073c9c2419250\", \"price_changes\":[{\"asset_id\":\"69697746896130839564035629862476347944307040470122503199396727085502753297492\", \"price\":\"0.6\", \"size\":\"241.5\", \"side\":\"BUY\", \"hash\":\"200e3ed3fba4bfe5b0ca4ef00e5d300204c23aab\", \"best_bid\":\"0.72\", \"best_ask\":\"0.73\"}, {\"asset_id\":\"60386828328910021732068595344565885737045900010034836345809386672230885527307\", \"price\":\"0.4\", \"size\":\"241.5\", \"side\":\"SELL\", \"hash\":\"f875e740383df81e9ed284527f17066765c6ad6a\", \"best_bid\":\"0.27\", \"best_ask\":\"0.28\"}], \"timestamp\":\"1785127227557\", \"event_type\":\"price_change\"}","received_at":"2026-07-27T04:40:27.505539Z","schema_version":"clob-market-ws.price_change.v1","sequence":null,"server_hash":null,"server_timestamp":"1785127227557","session_id":"e9443c7415a0419799bee9cfbb1a9e4d","source":"clob_market_ws"},"received_at":"2026-07-27T04:40:27.505539Z","record_id":"55784c80d433d71bb5f0aa7d8e93c0c210c2c3ce5747019a7c9f26711fa314c7","schema_fingerprint":"4aa3821a28b0b7c2400bc59aba4bcc0a76e971dadd19610d3ad38c768e124dc7","schema_version":"edge-lab-recorder.raw.v1","sequence":null,"source":"clob_market_ws"}
{"event_at":"2026-07-27T04:40:27.561000Z","event_fingerprint":"b4e9c53924490e57ecad2163a8a6804c67b84ef84a204d9834706f0818b6a61b","payload":{"connection_id":"0f4979d6978d463e9660b042fdcf555f","event_at":"2026-07-27T04:40:27.561000Z","event_type":"price_change","frame_hash":"ac43cc105d23fd06fedf52f4325802c9017a4b8c63b53a778890b231c514e958","frame_index":0,"kind":"data","monotonic_ns":229210773529625,"payload":{"event_type":"price_change","market":"0xeb66215f2e9faa6449e30a02bab5b8ed7b79a38bf961f6b24d0073c9c2419250","price_changes":[{"asset_id":"69697746896130839564035629862476347944307040470122503199396727085502753297492","best_ask":"0.73","best_bid":"0.72","hash":"054323d122bf7d9652cb40c701461e3b6c6db1d0","price":"0.03","side":"BUY","size":"613.1"},{"asset_id":"60386828328910021732068595344565885737045900010034836345809386672230885527307","best_ask":"0.28","best_bid":"0.27","hash":"be353737f1c62687e251ad680b342bf89b8f656b","price":"0.97","side":"SELL","size":"613.1"}],"timestamp":"1785127227561"},"payload_hash":"f3c6d2b746187c036776a06a967f3a04c315175cbd225407c7af28c2b02d5b4b","raw_frame":"{\"market\":\"0xeb66215f2e9faa6449e30a02bab5b8ed7b79a38bf961f6b24d0073c9c2419250\", \"price_changes\":[{\"asset_id\":\"69697746896130839564035629862476347944307040470122503199396727085502753297492\", \"price\":\"0.03\", \"size\":\"613.1\", \"side\":\"BUY\", \"hash\":\"054323d122bf7d9652cb40c701461e3b6c6db1d0\", \"best_bid\":\"0.72\", \"best_ask\":\"0.73\"}, {\"asset_id\":\"60386828328910021732068595344565885737045900010034836345809386672230885527307\", \"price\":\"0.97\", \"size\":\"613.1\", \"side\":\"SELL\", \"hash\":\"be353737f1c62687e251ad680b342bf89b8f656b\", \"best_bid\":\"0.27\", \"best_ask\":\"0.28\"}], \"timestamp\":\"1785127227561\", \"event_type\":\"price_change\"}","received_at":"2026-07-27T04:40:27.509131Z","schema_version":"clob-market-ws.price_change.v1","sequence":null,"server_hash":null,"server_timestamp":"1785127227561","session_id":"e9443c7415a0419799bee9cfbb1a9e4d","source":"clob_market_ws"},"received_at":"2026-07-27T04:40:27.509131Z","record_id":"d5a5e6f0b7c4b1fc931a7cdb6c7f75ce11fda1ad0e8ed96b5203ea857ba67694","schema_fingerprint":"4aa3821a28b0b7c2400bc59aba4bcc0a76e971dadd19610d3ad38c768e124dc7","schema_version":"edge-lab-recorder.raw.v1","sequence":null,"source":"clob_market_ws"}
{"event_at":"2026-07-27T04:40:27.564000Z","event_fingerprint":"52273e915b7e84ae0a00cfd1aae007b01ac1ae5d78afe6a17308e44ffc1fe55d","payload":{"connection_id":"0f4979d6978d463e9660b042fdcf555f","event_at":"2026-07-27T04:40:27.564000Z","event_type":"price_change","frame_hash":"dcefa1b1ed5263025f3a3852a114775a9b1658c35b2b1efa7027f417b7725f9d","frame_index":0,"kind":"data","monotonic_ns":229210777998083,"payload":{"event_type":"price_change","market":"0xeb66215f2e9faa6449e30a02bab5b8ed7b79a38bf961f6b24d0073c9c2419250","price_changes":[{"asset_id":"69697746896130839564035629862476347944307040470122503199396727085502753297492","best_ask":"0.73","best_bid":"0.72","hash":"fcb8e7c53e7efda55d61248223965dbd8b9e37b2","price":"0.64","side":"BUY","size":"84.26"},{"asset_id":"60386828328910021732068595344565885737045900010034836345809386672230885527307","best_ask":"0.28","best_bid":"0.27","hash":"eca1a568dc6badf534480c150748c4cd473e0281","price":"0.36","side":"SELL","size":"84.26"}],"timestamp":"1785127227564"},"payload_hash":"7f318cd11ee8cd8011812a076284b9bcaf77ed9fa9eaaf95210b92fd0cef6d4d","raw_frame":"{\"market\":\"0xeb66215f2e9faa6449e30a02bab5b8ed7b79a38bf961f6b24d0073c9c2419250\", \"price_changes\":[{\"asset_id\":\"69697746896130839564035629862476347944307040470122503199396727085502753297492\", \"price\":\"0.64\", \"size\":\"84.26\", \"side\":\"BUY\", \"hash\":\"fcb8e7c53e7efda55d61248223965dbd8b9e37b2\", \"best_bid\":\"0.72\", \"best_ask\":\"0.73\"}, {\"asset_id\":\"60386828328910021732068595344565885737045900010034836345809386672230885527307\", \"price\":\"0.36\", \"size\":\"84.26\", \"side\":\"SELL\", \"hash\":\"eca1a568dc6badf534480c150748c4cd473e0281\", \"best_bid\":\"0.27\", \"best_ask\":\"0.28\"}], \"timestamp\":\"1785127227564\", \"event_type\":\"price_change\"}","received_at":"2026-07-27T04:40:27.513599Z","schema_version":"clob-market-ws.price_change.v1","sequence":null,"server_hash":null,"server_timestamp":"1785127227564","session_id":"e9443c7415a0419799bee9cfbb1a9e4d","source":"clob_market_ws"},"received_at":"2026-07-27T04:40:27.513599Z","record_id":"b7c9994d8d8042ae46f23feaf015d99e34291b73ce500f0f08d74e8ee6496ddd","schema_fingerprint":"4aa3821a28b0b7c2400bc59aba4bcc0a76e971dadd19610d3ad38c768e124dc7","schema_version":"edge-lab-recorder.raw.v1","sequence":null,"source":"clob_market_ws"}
{"event_at":"2026-07-27T04:40:27.567000Z","event_fingerprint":"b15cff8c847cfc68bfbe52eba9a186e957ec1de899fd15e866370587d6149288","payload":{"connection_id":"0f4979d6978d463e9660b042fdcf555f","event_at":"2026-07-27T04:40:27.567000Z","event_type":"price_change","frame_hash":"76bb024a8a9717ca7748e39102669d9a01548d39e42f6e970e0f664416b1d65f","frame_index":0,"kind":"data","monotonic_ns":229210783017375,"payload":{"event_type":"price_change","market":"0xeb66215f2e9faa6449e30a02bab5b8ed7b79a38bf961f6b24d0073c9c2419250","price_changes":[{"asset_id":"69697746896130839564035629862476347944307040470122503199396727085502753297492","best_ask":"0.73","best_bid":"0.72","hash":"e0ca228dc098cad07ceaf0336380ce1ee92f3575","price":"0.01","side":"BUY","size":"5633.02"},{"asset_id":"60386828328910021732068595344565885737045900010034836345809386672230885527307","best_ask":"0.28","best_bid":"0.27","hash":"1e1aa0e825eaa8fd7410c05a08c48da958241645","price":"0.99","side":"SELL","size":"5633.02"}],"timestamp":"1785127227567"},"payload_hash":"9530073db75728438dbbfb09594a5920da3c196e9af11fc1fbfd9a8a73c66234","raw_frame":"{\"market\":\"0xeb66215f2e9faa6449e30a02bab5b8ed7b79a38bf961f6b24d0073c9c2419250\", \"price_changes\":[{\"asset_id\":\"69697746896130839564035629862476347944307040470122503199396727085502753297492\", \"price\":\"0.01\", \"size\":\"5633.02\", \"side\":\"BUY\", \"hash\":\"e0ca228dc098cad07ceaf0336380ce1ee92f3575\", \"best_bid\":\"0.72\", \"best_ask\":\"0.73\"}, {\"asset_id\":\"60386828328910021732068595344565885737045900010034836345809386672230885527307\", \"price\":\"0.99\", \"size\":\"5633.02\", \"side\":\"SELL\", \"hash\":\"1e1aa0e825eaa8fd7410c05a08c48da958241645\", \"best_bid\":\"0.27\", \"best_ask\":\"0.28\"}], \"timestamp\":\"1785127227567\", \"event_type\":\"price_change\"}","received_at":"2026-07-27T04:40:27.518625Z","schema_version":"clob-market-ws.price_change.v1","sequence":null,"server_hash":null,"server_timestamp":"1785127227567","session_id":"e9443c7415a0419799bee9cfbb1a9e4d","source":"clob_market_ws"},"received_at":"2026-07-27T04:40:27.518625Z","record_id":"7a6e3f1accb283fec7d0f6a3fccdd21433dd13ac388e9841c26b2d1e890a1cb2","schema_fingerprint":"4aa3821a28b0b7c2400bc59aba4bcc0a76e971dadd19610d3ad38c768e124dc7","schema_version":"edge-lab-recorder.raw.v1","sequence":null,"source":"clob_market_ws"}
{"event_at":"2026-07-27T04:40:27.613000Z","event_fingerprint":"74f76972484b92d6b4559f975a16fdf76b70b63cc7a82485fd1bf37479d57f49","payload":{"connection_id":"0f4979d6978d463e9660b042fdcf555f","event_at":"2026-07-27T04:40:27.613000Z","event_type":"price_change","frame_hash":"e8983a888bb01912a1f3883060e759a17935af9d612faeda2eb9da7fb6f95384","frame_index":0,"kind":"data","monotonic_ns":229210827747000,"payload":{"event_type":"price_change","market":"0xeb66215f2e9faa6449e30a02bab5b8ed7b79a38bf961f6b24d0073c9c2419250","price_changes":[{"asset_id":"69697746896130839564035629862476347944307040470122503199396727085502753297492","best_ask":"0.73","best_bid":"0.72","hash":"86f8cde1ff3f8b11993fd2612fb470e7feb9f2fe","price":"0.69","side":"BUY","size":"153.14"},{"asset_id":"60386828328910021732068595344565885737045900010034836345809386672230885527307","best_ask":"0.28","best_bid":"0.27","hash":"c11a99c66bb925872db8d0fe9fa56f83ea50a563","price":"0.31","side":"SELL","size":"153.14"}],"timestamp":"1785127227613"},"payload_hash":"62167f4faef40d6bd4f8da8c3b612fd00a6b34ea01743982c05a7542d40073f8","raw_frame":"{\"market\":\"0xeb66215f2e9faa6449e30a02bab5b8ed7b79a38bf961f6b24d0073c9c2419250\", \"price_changes\":[{\"asset_id\":\"69697746896130839564035629862476347944307040470122503199396727085502753297492\", \"price\":\"0.69\", \"size\":\"153.14\", \"side\":\"BUY\", \"hash\":\"86f8cde1ff3f8b11993fd2612fb470e7feb9f2fe\", \"best_bid\":\"0.72\", \"best_ask\":\"0.73\"}, {\"asset_id\":\"60386828328910021732068595344565885737045900010034836345809386672230885527307\", \"price\":\"0.31\", \"size\":\"153.14\", \"side\":\"SELL\", \"hash\":\"c11a99c66bb925872db8d0fe9fa56f83ea50a563\", \"best_bid\":\"0.27\", \"best_ask\":\"0.28\"}], \"timestamp\":\"1785127227613\", \"event_type\":\"price_change\"}","received_at":"2026-07-27T04:40:27.563349Z","schema_version":"clob-market-ws.price_change.v1","sequence":null,"server_hash":null,"server_timestamp":"1785127227613","session_id":"e9443c7415a0419799bee9cfbb1a9e4d","source":"clob_market_ws"},"received_at":"2026-07-27T04:40:27.563349Z","record_id":"d6211ebf5f5c57b83f948ae65a7b8f8251fab3af1fa3cd78c7bfc30d233a2076","schema_fingerprint":"4aa3821a28b0b7c2400bc59aba4bcc0a76e971dadd19610d3ad38c768e124dc7","schema_version":"edge-lab-recorder.raw.v1","sequence":null,"source":"clob_market_ws"}
{"event_at":"2026-07-27T04:40:27.614000Z","event_fingerprint":"24ff52ac2d948c1813bd1cc70a25d3218c1493783456df4b508b7e704dd73e17","payload":{"connection_id":"0f4979d6978d463e9660b042fdcf555f","event_at":"2026-07-27T04:40:27.614000Z","event_type":"price_change","frame_hash":"a77a772bc25fea2ec8dd96910446ce133d1c13277b4dcf0592228ca6e2a4eead","frame_index":0,"kind":"data","monotonic_ns":229210837089250,"payload":{"event_type":"price_change","market":"0xeb66215f2e9faa6449e30a02bab5b8ed7b79a38bf961f6b24d0073c9c2419250","price_changes":[{"asset_id":"69697746896130839564035629862476347944307040470122503199396727085502753297492","best_ask":"0.73","best_bid":"0.72","hash":"56fca6b75e643bb964586dbb4b1a729767901db6","price":"0.7","side":"BUY","size":"41.94"},{"asset_id":"60386828328910021732068595344565885737045900010034836345809386672230885527307","best_ask":"0.28","best_bid":"0.27","hash":"606620ea23b6e07dfbf0e4b15ec388e7e21af2b6","price":"0.3","side":"SELL","size":"41.94"}],"timestamp":"1785127227614"},"payload_hash":"b27ab9860285e2fba8849727677bea9a85645d765e8474af918b5f056e7950f6","raw_frame":"{\"market\":\"0xeb66215f2e9faa6449e30a02bab5b8ed7b79a38bf961f6b24d0073c9c2419250\", \"price_changes\":[{\"asset_id\":\"69697746896130839564035629862476347944307040470122503199396727085502753297492\", \"price\":\"0.7\", \"size\":\"41.94\", \"side\":\"BUY\", \"hash\":\"56fca6b75e643bb964586dbb4b1a729767901db6\", \"best_bid\":\"0.72\", \"best_ask\":\"0.73\"}, {\"asset_id\":\"60386828328910021732068595344565885737045900010034836345809386672230885527307\", \"price\":\"0.3\", \"size\":\"41.94\", \"side\":\"SELL\", \"hash\":\"606620ea23b6e07dfbf0e4b15ec388e7e21af2b6\", \"best_bid\":\"0.27\", \"best_ask\":\"0.28\"}], \"timestamp\":\"1785127227614\", \"event_type\":\"price_change\"}","received_at":"2026-07-27T04:40:27.572690Z","schema_version":"clob-market-ws.price_change.v1","sequence":null,"server_hash":null,"server_timestamp":"1785127227614","session_id":"e9443c7415a0419799bee9cfbb1a9e4d","source":"clob_market_ws"},"received_at":"2026-07-27T04:40:27.572690Z","record_id":"8985ee2f33cb9f48ef068ac0dd52aa8518d31b8501b9faf4d2a7fa844f6a5ffe","schema_fingerprint":"4aa3821a28b0b7c2400bc59aba4bcc0a76e971dadd19610d3ad38c768e124dc7","schema_version":"edge-lab-recorder.raw.v1","sequence":null,"source":"clob_market_ws"}
{"event_at":"2026-07-27T04:40:27.623000Z","event_fingerprint":"703ad7ae6869dcf5c794f745d14a681bf185c6cb93f1e5d33cfc432e67050fce","payload":{"connection_id":"0f4979d6978d463e9660b042fdcf555f","event_at":"2026-07-27T04:40:27.623000Z","event_type":"price_change","frame_hash":"4e81306c4e0d8afabd1dabedc2852d1e9ffd855ce6b2f2097940f5566152d94e","frame_index":0,"kind":"data","monotonic_ns":229210842494750,"payload":{"event_type":"price_change","market":"0xeb66215f2e9faa6449e30a02bab5b8ed7b79a38bf961f6b24d0073c9c2419250","price_changes":[{"asset_id":"60386828328910021732068595344565885737045900010034836345809386672230885527307","best_ask":"0.28","best_bid":"0.27","hash":"4a7430de472abc3cd825821ee51d39ebea981a7c","price":"0.31","side":"SELL","size":"161.14"},{"asset_id":"69697746896130839564035629862476347944307040470122503199396727085502753297492","best_ask":"0.73","best_bid":"0.72","hash":"4f11494b7e8498558c23fc162db0d678a3e6f1d3","price":"0.69","side":"BUY","size":"161.14"}],"timestamp":"1785127227623"},"payload_hash":"37eb919ee6ee34943ae4cae3e1bf907d2aa8863dfd0409f007d53c818fc81859","raw_frame":"{\"market\":\"0xeb66215f2e9faa6449e30a02bab5b8ed7b79a38bf961f6b24d0073c9c2419250\", \"price_changes\":[{\"asset_id\":\"60386828328910021732068595344565885737045900010034836345809386672230885527307\", \"price\":\"0.31\", \"size\":\"161.14\", \"side\":\"SELL\", \"hash\":\"4a7430de472abc3cd825821ee51d39ebea981a7c\", \"best_bid\":\"0.27\", \"best_ask\":\"0.28\"}, {\"asset_id\":\"69697746896130839564035629862476347944307040470122503199396727085502753297492\", \"price\":\"0.69\", \"size\":\"161.14\", \"side\":\"BUY\", \"hash\":\"4f11494b7e8498558c23fc162db0d678a3e6f1d3\", \"best_bid\":\"0.72\", \"best_ask\":\"0.73\"}], \"timestamp\":\"1785127227623\", \"event_type\":\"price_change\"}","received_at":"2026-07-27T04:40:27.578098Z","schema_version":"clob-market-ws.price_change.v1","sequence":null,"server_hash":null,"server_timestamp":"1785127227623","session_id":"e9443c7415a0419799bee9cfbb1a9e4d","source":"clob_market_ws"},"received_at":"2026-07-27T04:40:27.578098Z","record_id":"a2d026e9cbfa9bca857eec48009f2c2347cde41c3f39022c00ab7395466966af","schema_fingerprint":"4aa3821a28b0b7c2400bc59aba4bcc0a76e971dadd19610d3ad38c768e124dc7","schema_version":"edge-lab-recorder.raw.v1","sequence":null,"source":"clob_market_ws"}
{"event_at":"2026-07-27T04:40:27.624000Z","event_fingerprint":"20bfb456f093da7cdde82abf8add8be44225441f55aa015fca4ae31203b3de0a","payload":{"connection_id":"0f4979d6978d463e9660b042fdcf555f","event_at":"2026-07-27T04:40:27.624000Z","event_type":"price_change","frame_hash":"0df0e7666ea9a66b8b0544a1d9accac8b67db9154ea1aa71c63fb021e7cc4587","frame_index":0,"kind":"data","monotonic_ns":229210846869375,"payload":{"event_type":"price_change","market":"0xeb66215f2e9faa6449e30a02bab5b8ed7b79a38bf961f6b24d0073c9c2419250","price_changes":[{"asset_id":"69697746896130839564035629862476347944307040470122503199396727085502753297492","best_ask":"0.73","best_bid":"0.72","hash":"055fa9e605fba88d6ef1e7b01529cd5a6619b745","price":"0.68","side":"BUY","size":"305.32"},{"asset_id":"60386828328910021732068595344565885737045900010034836345809386672230885527307","best_ask":"0.28","best_bid":"0.27","hash":"f72cb675ea3374a1d9d63adf4782a8a70d41922c","price":"0.32","side":"SELL","size":"305.32"}],"timestamp":"1785127227624"},"payload_hash":"0f0a4a0660217921e8f5142bd3a5c83960f16579ce8182650980d1fb08778003","raw_frame":"{\"market\":\"0xeb66215f2e9faa6449e30a02bab5b8ed7b79a38bf961f6b24d0073c9c2419250\", \"price_changes\":[{\"asset_id\":\"69697746896130839564035629862476347944307040470122503199396727085502753297492\", \"price\":\"0.68\", \"size\":\"305.32\", \"side\":\"BUY\", \"hash\":\"055fa9e605fba88d6ef1e7b01529cd5a6619b745\", \"best_bid\":\"0.72\", \"best_ask\":\"0.73\"}, {\"asset_id\":\"60386828328910021732068595344565885737045900010034836345809386672230885527307\", \"price\":\"0.32\", \"size\":\"305.32\", \"side\":\"SELL\", \"hash\":\"f72cb675ea3374a1d9d63adf4782a8a70d41922c\", \"best_bid\":\"0.27\", \"best_ask\":\"0.28\"}], \"timestamp\":\"1785127227624\", \"event_type\":\"price_change\"}","received_at":"2026-07-27T04:40:27.582472Z","schema_version":"clob-market-ws.price_change.v1","sequence":null,"server_hash":null,"server_timestamp":"1785127227624","session_id":"e9443c7415a0419799bee9cfbb1a9e4d","source":"clob_market_ws"},"received_at":"2026-07-27T04:40:27.582472Z","record_id":"069b25562aebeba669904be1709740332ae35b78627dc176cdd7e2035c39b63d","schema_fingerprint":"4aa3821a28b0b7c2400bc59aba4bcc0a76e971dadd19610d3ad38c768e124dc7","schema_version":"edge-lab-recorder.raw.v1","sequence":null,"source":"clob_market_ws"}
{"event_at":"2026-07-27T04:40:27.637000Z","event_fingerprint":"03c1bc264c0f6f806141d208fb656f919f34a952865301345dca6fd14259f33e","payload":{"connection_id":"0f4979d6978d463e9660b042fdcf555f","event_at":"2026-07-27T04:40:27.637000Z","event_type":"price_change","frame_hash":"1cd29baaafad56c4e4e20b429f1a267f5e06446b229600d036382ed919d1b94c","frame_index":0,"kind":"data","monotonic_ns":229210851379875,"payload":{"event_type":"price_change","market":"0xeb66215f2e9faa6449e30a02bab5b8ed7b79a38bf961f6b24d0073c9c2419250","price_changes":[{"asset_id":"60386828328910021732068595344565885737045900010034836345809386672230885527307","best_ask":"0.28","best_bid":"0.27","hash":"6411413697832bc24c02ad0c9e53053931423eb5","price":"0.3","side":"SELL","size":"83.94"},{"asset_id":"69697746896130839564035629862476347944307040470122503199396727085502753297492","best_ask":"0.73","best_bid":"0.72","hash":"8a22d23a6ddc620e3d2188dfff249189707fd971","price":"0.7","side":"BUY","size":"83.94"}],"timestamp":"1785127227637"},"payload_hash":"148eaaeec492f6b1f3a76e69f9fc66b0a56cdbc1c97323f47886b53be7d40d65","raw_frame":"{\"market\":\"0xeb66215f2e9faa6449e30a02bab5b8ed7b79a38bf961f6b24d0073c9c2419250\", \"price_changes\":[{\"asset_id\":\"60386828328910021732068595344565885737045900010034836345809386672230885527307\", \"price\":\"0.3\", \"size\":\"83.94\", \"side\":\"SELL\", \"hash\":\"6411413697832bc24c02ad0c9e53053931423eb5\", \"best_bid\":\"0.27\", \"best_ask\":\"0.28\"}, {\"asset_id\":\"69697746896130839564035629862476347944307040470122503199396727085502753297492\", \"price\":\"0.7\", \"size\":\"83.94\", \"side\":\"BUY\", \"hash\":\"8a22d23a6ddc620e3d2188dfff249189707fd971\", \"best_bid\":\"0.72\", \"best_ask\":\"0.73\"}], \"timestamp\":\"1785127227637\", \"event_type\":\"price_change\"}","received_at":"2026-07-27T04:40:27.586984Z","schema_version":"clob-market-ws.price_change.v1","sequence":null,"server_hash":null,"server_timestamp":"1785127227637","session_id":"e9443c7415a0419799bee9cfbb1a9e4d","source":"clob_market_ws"},"received_at":"2026-07-27T04:40:27.586984Z","record_id":"815748e8291cd46c81a8f8adc857e0a675390280e2848bc7e60a6e4e013a4b3c","schema_fingerprint":"4aa3821a28b0b7c2400bc59aba4bcc0a76e971dadd19610d3ad38c768e124dc7","schema_version":"edge-lab-recorder.raw.v1","sequence":null,"source":"clob_market_ws"}
{"event_at":"2026-07-27T04:40:27.642000Z","event_fingerprint":"6929c8679d8f1acc6c9ca9cfa7790c6d73d5f9d8b76cdf44b7538427c66319cf","payload":{"connection_id":"0f4979d6978d463e9660b042fdcf555f","event_at":"2026-07-27T04:40:27.642000Z","event_type":"price_change","frame_hash":"927e1a91e2fef91b02f645a89fc6786fc4a22be51b92b7059f3b3631da189586","frame_index":0,"kind":"data","monotonic_ns":229210855927833,"payload":{"event_type":"price_change","market":"0xeb66215f2e9faa6449e30a02bab5b8ed7b79a38bf961f6b24d0073c9c2419250","price_changes":[{"asset_id":"69697746896130839564035629862476347944307040470122503199396727085502753297492","best_ask":"0.73","best_bid":"0.72","hash":"154eef993fcd2de3da4210ad8dbcb4743a71c520","price":"0.02","side":"BUY","size":"688.1"},{"asset_id":"60386828328910021732068595344565885737045900010034836345809386672230885527307","best_ask":"0.28","best_bid":"0.27","hash":"f0dcc07dfc6dec4259477ba26ae62949e6f88f7d","price":"0.98","side":"SELL","size":"688.1"}],"timestamp":"1785127227642"},"payload_hash":"7535d6cb780eefbec8f04a96954feee1db219bdd4091b86b00ecf7364b8ab58a","raw_frame":"{\"market\":\"0xeb66215f2e9faa6449e30a02bab5b8ed7b79a38bf961f6b24d0073c9c2419250\", \"price_changes\":[{\"asset_id\":\"69697746896130839564035629862476347944307040470122503199396727085502753297492\", \"price\":\"0.02\", \"size\":\"688.1\", \"side\":\"BUY\", \"hash\":\"154eef993fcd2de3da4210ad8dbcb4743a71c520\", \"best_bid\":\"0.72\", \"best_ask\":\"0.73\"}, {\"asset_id\":\"60386828328910021732068595344565885737045900010034836345809386672230885527307\", \"price\":\"0.98\", \"size\":\"688.1\", \"side\":\"SELL\", \"hash\":\"f0dcc07dfc6dec4259477ba26ae62949e6f88f7d\", \"best_bid\":\"0.27\", \"best_ask\":\"0.28\"}], \"timestamp\":\"1785127227642\", \"event_type\":\"price_change\"}","received_at":"2026-07-27T04:40:27.591531Z","schema_version":"clob-market-ws.price_change.v1","sequence":null,"server_hash":null,"server_timestamp":"1785127227642","session_id":"e9443c7415a0419799bee9cfbb1a9e4d","source":"clob_market_ws"},"received_at":"2026-07-27T04:40:27.591531Z","record_id":"bd6ab8f280c2a65249cdbb3e60929d8e1e076c9b4fdc4134080aea332ce5b103","schema_fingerprint":"4aa3821a28b0b7c2400bc59aba4bcc0a76e971dadd19610d3ad38c768e124dc7","schema_version":"edge-lab-recorder.raw.v1","sequence":null,"source":"clob_market_ws"}
{"event_at":"2026-07-27T04:40:27.652000Z","event_fingerprint":"ba17804d22c88150fb9d5c1055e50267bc69231cfcae9b9eabe544518ce2ae7a","payload":{"connection_id":"0f4979d6978d463e9660b042fdcf555f","event_at":"2026-07-27T04:40:27.652000Z","event_type":"price_change","frame_hash":"c3931043315f776d1547f97570302ca54b2524b45990a23974cd892d45896191","frame_index":0,"kind":"data","monotonic_ns":229210864110250,"payload":{"event_type":"price_change","market":"0xeb66215f2e9faa6449e30a02bab5b8ed7b79a38bf961f6b24d0073c9c2419250","price_changes":[{"asset_id":"69697746896130839564035629862476347944307040470122503199396727085502753297492","best_ask":"0.73","best_bid":"0.72","hash":"407e47725a14e69932ff7d884cd8e5f6810ffa36","price":"0.01","side":"BUY","size":"5638.02"},{"asset_id":"60386828328910021732068595344565885737045900010034836345809386672230885527307","best_ask":"0.28","best_bid":"0.27","hash":"422e674825942f4289cb9f2349d2739ad7874865","price":"0.99","side":"SELL","size":"5638.02"}],"timestamp":"1785127227652"},"payload_hash":"395c00c04c39057e0f370447c05a9572f4a44a7b74bfdb72ac668b5c5c315068","raw_frame":"{\"market\":\"0xeb66215f2e9faa6449e30a02bab5b8ed7b79a38bf961f6b24d0073c9c2419250\", \"price_changes\":[{\"asset_id\":\"69697746896130839564035629862476347944307040470122503199396727085502753297492\", \"price\":\"0.01\", \"size\":\"5638.02\", \"side\":\"BUY\", \"hash\":\"407e47725a14e69932ff7d884cd8e5f6810ffa36\", \"best_bid\":\"0.72\", \"best_ask\":\"0.73\"}, {\"asset_id\":\"60386828328910021732068595344565885737045900010034836345809386672230885527307\", \"price\":\"0.99\", \"size\":\"5638.02\", \"side\":\"SELL\", \"hash\":\"422e674825942f4289cb9f2349d2739ad7874865\", \"best_bid\":\"0.27\", \"best_ask\":\"0.28\"}], \"timestamp\":\"1785127227652\", \"event_type\":\"price_change\"}","received_at":"2026-07-27T04:40:27.599713Z","schema_version":"clob-market-ws.price_change.v1","sequence":null,"server_hash":null,"server_timestamp":"1785127227652","session_id":"e9443c7415a0419799bee9cfbb1a9e4d","source":"clob_market_ws"},"received_at":"2026-07-27T04:40:27.599713Z","record_id":"e81ec0cbe463935091b6839a9b9adee2506f9ac29ebb23f28aa8251601910800","schema_fingerprint":"4aa3821a28b0b7c2400bc59aba4bcc0a76e971dadd19610d3ad38c768e124dc7","schema_version":"edge-lab-recorder.raw.v1","sequence":null,"source":"clob_market_ws"}
{"event_at":"2026-07-27T04:40:27.669000Z","event_fingerprint":"901ad865caf68a5bfa1fa573718931f1fa26011891c78abaf6a6ed03b51cf7c5","payload":{"connection_id":"0f4979d6978d463e9660b042fdcf555f","event_at":"2026-07-27T04:40:27.669000Z","event_type":"price_change","frame_hash":"7e9ec591d4013f9cf7bb7249687345804e4d19b0a081f5cfec12e89d18eacd99","frame_index":0,"kind":"data","monotonic_ns":229210883496500,"payload":{"event_type":"price_change","market":"0xeb66215f2e9faa6449e30a02bab5b8ed7b79a38bf961f6b24d0073c9c2419250","price_changes":[{"asset_id":"69697746896130839564035629862476347944307040470122503199396727085502753297492","best_ask":"0.73","best_bid":"0.72","hash":"1fc74846a9178e3667649df8553d1ab1f4e5197a","price":"0.01","side":"BUY","size":"5633.02"},{"asset_id":"60386828328910021732068595344565885737045900010034836345809386672230885527307","best_ask":"0.28","best_bid":"0.27","hash":"c466d75d8c0e2b0df8e3378701dd858902baa2a1","price":"0.99","side":"SELL","size":"5633.02"}],"timestamp":"1785127227669"},"payload_hash":"2166f458e0f067ee7e5df50c485f70413d10327ca87e37d9d8e1e7585c8c8d7b","raw_frame":"{\"market\":\"0xeb66215f2e9faa6449e30a02bab5b8ed7b79a38bf961f6b24d0073c9c2419250\", \"price_changes\":[{\"asset_id\":\"69697746896130839564035629862476347944307040470122503199396727085502753297492\", \"price\":\"0.01\", \"size\":\"5633.02\", \"side\":\"BUY\", \"hash\":\"1fc74846a9178e3667649df8553d1ab1f4e5197a\", \"best_bid\":\"0.72\", \"best_ask\":\"0.73\"}, {\"asset_id\":\"60386828328910021732068595344565885737045900010034836345809386672230885527307\", \"price\":\"0.99\", \"size\":\"5633.02\", \"side\":\"SELL\", \"hash\":\"c466d75d8c0e2b0df8e3378701dd858902baa2a1\", \"best_bid\":\"0.27\", \"best_ask\":\"0.28\"}], \"timestamp\":\"1785127227669\", \"event_type\":\"price_change\"}","received_at":"2026-07-27T04:40:27.619099Z","schema_version":"clob-market-ws.price_change.v1","sequence":null,"server_hash":null,"server_timestamp":"1785127227669","session_id":"e9443c7415a0419799bee9cfbb1a9e4d","source":"clob_market_ws"},"received_at":"2026-07-27T04:40:27.619099Z","record_id":"c3486548a94f4e998af4caeafc3274167124aaa8a0b01e3b9f19978f8f895007","schema_fingerprint":"4aa3821a28b0b7c2400bc59aba4bcc0a76e971dadd19610d3ad38c768e124dc7","schema_version":"edge-lab-recorder.raw.v1","sequence":null,"source":"clob_market_ws"}
{"event_at":"2026-07-27T04:40:27.695000Z","event_fingerprint":"914994e1254d43063398ddad471d534b74b69d9c56f0062aec58a92fbf738fe5","payload":{"connection_id":"0f4979d6978d463e9660b042fdcf555f","event_at":"2026-07-27T04:40:27.695000Z","event_type":"price_change","frame_hash":"6d8789e397cf3c8a9f38fe585cabd24cf22446e766926e9daca50f1fa9389e3b","frame_index":0,"kind":"data","monotonic_ns":229210908173625,"payload":{"event_type":"price_change","market":"0xeb66215f2e9faa6449e30a02bab5b8ed7b79a38bf961f6b24d0073c9c2419250","price_changes":[{"asset_id":"69697746896130839564035629862476347944307040470122503199396727085502753297492","best_ask":"0.73","best_bid":"0.72","hash":"35e9ab6811e2054e3352cd95ff720dcc3967b428","price":"0.02","side":"BUY","size":"683.1"},{"asset_id":"60386828328910021732068595344565885737045900010034836345809386672230885527307","best_ask":"0.28","best_bid":"0.27","hash":"23c2146942b8d41b812f1965924929896741865d","price":"0.98","side":"SELL","size":"683.1"}],"timestamp":"1785127227695"},"payload_hash":"4af5e2a62d17a942b40402b4c0037ac33649a2ac568665e808df6b34fd810701","raw_frame":"{\"market\":\"0xeb66215f2e9faa6449e30a02bab5b8ed7b79a38bf961f6b24d0073c9c2419250\", \"price_changes\":[{\"asset_id\":\"69697746896130839564035629862476347944307040470122503199396727085502753297492\", \"price\":\"0.02\", \"size\":\"683.1\", \"side\":\"BUY\", \"hash\":\"35e9ab6811e2054e3352cd95ff720dcc3967b428\", \"best_bid\":\"0.72\", \"best_ask\":\"0.73\"}, {\"asset_id\":\"60386828328910021732068595344565885737045900010034836345809386672230885527307\", \"price\":\"0.98\", \"size\":\"683.1\", \"side\":\"SELL\", \"hash\":\"23c2146942b8d41b812f1965924929896741865d\", \"best_bid\":\"0.27\", \"best_ask\":\"0.28\"}], \"timestamp\":\"1785127227695\", \"event_type\":\"price_change\"}","received_at":"2026-07-27T04:40:27.643777Z","schema_version":"clob-market-ws.price_change.v1","sequence":null,"server_hash":null,"server_timestamp":"1785127227695","session_id":"e9443c7415a0419799bee9cfbb1a9e4d","source":"clob_market_ws"},"received_at":"2026-07-27T04:40:27.643777Z","record_id":"17cc17a140431a55ee7baa7bbee73d58c1141ecf974613d0899d4e4301c48e3b","schema_fingerprint":"4aa3821a28b0b7c2400bc59aba4bcc0a76e971dadd19610d3ad38c768e124dc7","schema_version":"edge-lab-recorder.raw.v1","sequence":null,"source":"clob_market_ws"}
{"event_at":"2026-07-27T04:40:27.726000Z","event_fingerprint":"d0c3d59e75664b51d29788c35fefa4693d5123312f0b5de7134eaaec841927e4","payload":{"connection_id":"0f4979d6978d463e9660b042fdcf555f","event_at":"2026-07-27T04:40:27.726000Z","event_type":"price_change","frame_hash":"ff7d8f06348b309c9bd795887200e6267f2badd6ddbf0842cf5fc1b584f7be2b","frame_index":0,"kind":"data","monotonic_ns":229210942590375,"payload":{"event_type":"price_change","market":"0xeb66215f2e9faa6449e30a02bab5b8ed7b79a38bf961f6b24d0073c9c2419250","price_changes":[{"asset_id":"60386828328910021732068595344565885737045900010034836345809386672230885527307","best_ask":"0.28","best_bid":"0.27","hash":"96d98288b9c384b1f9ce98afef4bb05be14d7604","price":"0.31","side":"SELL","size":"153.14"},{"asset_id":"69697746896130839564035629862476347944307040470122503199396727085502753297492","best_ask":"0.73","best_bid":"0.72","hash":"9f95dd3ccb5f89d020ce4e52d00534d6b393dff0","price":"0.69","side":"BUY","size":"153.14"}],"timestamp":"1785127227726"},"payload_hash":"341b0db110f89d19d4366c5d5c631884248090b17923a89e477383114335ec77","raw_frame":"{\"market\":\"0xeb66215f2e9faa6449e30a02bab5b8ed7b79a38bf961f6b24d0073c9c2419250\", \"price_changes\":[{\"asset_id\":\"60386828328910021732068595344565885737045900010034836345809386672230885527307\", \"price\":\"0.31\", \"size\":\"153.14\", \"side\":\"SELL\", \"hash\":\"96d98288b9c384b1f9ce98afef4bb05be14d7604\", \"best_bid\":\"0.27\", \"best_ask\":\"0.28\"}, {\"asset_id\":\"69697746896130839564035629862476347944307040470122503199396727085502753297492\", \"price\":\"0.69\", \"size\":\"153.14\", \"side\":\"BUY\", \"hash\":\"9f95dd3ccb5f89d020ce4e52d00534d6b393dff0\", \"best_bid\":\"0.72\", \"best_ask\":\"0.73\"}], \"timestamp\":\"1785127227726\", \"event_type\":\"price_change\"}","received_at":"2026-07-27T04:40:27.678194Z","schema_version":"clob-market-ws.price_change.v1","sequence":null,"server_hash":null,"server_timestamp":"1785127227726","session_id":"e9443c7415a0419799bee9cfbb1a9e4d","source":"clob_market_ws"},"received_at":"2026-07-27T04:40:27.678194Z","record_id":"56f63245adf50ba3c24429065bf717e5dea8c70dad7819fe40346fd0210fb3f7","schema_fingerprint":"4aa3821a28b0b7c2400bc59aba4bcc0a76e971dadd19610d3ad38c768e124dc7","schema_version":"edge-lab-recorder.raw.v1","sequence":null,"source":"clob_market_ws"}
{"event_at":"2026-07-27T04:40:27.729000Z","event_fingerprint":"8a9c9acb25a20f0ea329e613983e81d611ecd98cb3a62ca1dd70c822fb76618d","payload":{"connection_id":"0f4979d6978d463e9660b042fdcf555f","event_at":"2026-07-27T04:40:27.729000Z","event_type":"price_change","frame_hash":"8d901c8d2ad7d660f1e418929ef2231a8a2a72e2e4795343d39d33d4ce4db376","frame_index":0,"kind":"data","monotonic_ns":229210950186625,"payload":{"event_type":"price_change","market":"0xeb66215f2e9faa6449e30a02bab5b8ed7b79a38bf961f6b24d0073c9c2419250","price_changes":[{"asset_id":"60386828328910021732068595344565885737045900010034836345809386672230885527307","best_ask":"0.28","best_bid":"0.27","hash":"7930cf4de77589aa8e5de7ed3c9182db7683e0e0","price":"0.3","side":"SELL","size":"41.94"},{"asset_id":"69697746896130839564035629862476347944307040470122503199396727085502753297492","best_ask":"0.73","best_bid":"0.72","hash":"65baabe4d6d8eb8384310006de2c881f51ce9a88","price":"0.7","side":"BUY","size":"41.94"}],"timestamp":"1785127227729"},"payload_hash":"ac2f7ef1c365932693feefdb6b8ac41d3558f924d2e30cfa4c7f2293a4de1469","raw_frame":"{\"market\":\"0xeb66215f2e9faa6449e30a02bab5b8ed7b79a38bf961f6b24d0073c9c2419250\", \"price_changes\":[{\"asset_id\":\"60386828328910021732068595344565885737045900010034836345809386672230885527307\", \"price\":\"0.3\", \"size\":\"41.94\", \"side\":\"SELL\", \"hash\":\"7930cf4de77589aa8e5de7ed3c9182db7683e0e0\", \"best_bid\":\"0.27\", \"best_ask\":\"0.28\"}, {\"asset_id\":\"69697746896130839564035629862476347944307040470122503199396727085502753297492\", \"price\":\"0.7\", \"size\":\"41.94\", \"side\":\"BUY\", \"hash\":\"65baabe4d6d8eb8384310006de2c881f51ce9a88\", \"best_bid\":\"0.72\", \"best_ask\":\"0.73\"}], \"timestamp\":\"1785127227729\", \"event_type\":\"price_change\"}","received_at":"2026-07-27T04:40:27.685795Z","schema_version":"clob-market-ws.price_change.v1","sequence":null,"server_hash":null,"server_timestamp":"1785127227729","session_id":"e9443c7415a0419799bee9cfbb1a9e4d","source":"clob_market_ws"},"received_at":"2026-07-27T04:40:27.685795Z","record_id":"f73bf8bce02c52e0e98fdcfc41b3bf8000d7997a10f36aa717a6747efc4163e5","schema_fingerprint":"4aa3821a28b0b7c2400bc59aba4bcc0a76e971dadd19610d3ad38c768e124dc7","schema_version":"edge-lab-recorder.raw.v1","sequence":null,"source":"clob_market_ws"}
{"event_at":"2026-07-27T04:40:27.737000Z","event_fingerprint":"1d0aaeca1efe6b3e536fa66f7e4cbbcdd0e012aea28eeabe0a7a641bf0f922a0","payload":{"connection_id":"0f4979d6978d463e9660b042fdcf555f","event_at":"2026-07-27T04:40:27.737000Z","event_type":"price_change","frame_hash":"8a10a1115030a4e94df7ef5fa47ac93dc8bd9585a6da6916cce4208aaad0bd2d","frame_index":0,"kind":"data","monotonic_ns":229210952223416,"payload":{"event_type":"price_change","market":"0xeb66215f2e9faa6449e30a02bab5b8ed7b79a38bf961f6b24d0073c9c2419250","price_changes":[{"asset_id":"69697746896130839564035629862476347944307040470122503199396727085502753297492","best_ask":"0.73","best_bid":"0.72","hash":"49355730424dcb242e913dc9a0f1affd0c791834","price":"0.7","side":"BUY","size":"83.86"},{"asset_id":"60386828328910021732068595344565885737045900010034836345809386672230885527307","best_ask":"0.28","best_bid":"0.27","hash":"784f89dbdd0dfc0d54e7381400ccf8cef885df11","price":"0.3","side":"SELL","size":"83.86"}],"timestamp":"1785127227737"},"payload_hash":"29be13a46f87407f3bca57509315bb4052d8e982df263653cdf72990e3b4111e","raw_frame":"{\"market\":\"0xeb66215f2e9faa6449e30a02bab5b8ed7b79a38bf961f6b24d0073c9c2419250\", \"price_changes\":[{\"asset_id\":\"69697746896130839564035629862476347944307040470122503199396727085502753297492\", \"price\":\"0.7\", \"size\":\"83.86\", \"side\":\"BUY\", \"hash\":\"49355730424dcb242e913dc9a0f1affd0c791834\", \"best_bid\":\"0.72\", \"best_ask\":\"0.73\"}, {\"asset_id\":\"60386828328910021732068595344565885737045900010034836345809386672230885527307\", \"price\":\"0.3\", \"size\":\"83.86\", \"side\":\"SELL\", \"hash\":\"784f89dbdd0dfc0d54e7381400ccf8cef885df11\", \"best_bid\":\"0.27\", \"best_ask\":\"0.28\"}], \"timestamp\":\"1785127227737\", \"event_type\":\"price_change\"}","received_at":"2026-07-27T04:40:27.687833Z","schema_version":"clob-market-ws.price_change.v1","sequence":null,"server_hash":null,"server_timestamp":"1785127227737","session_id":"e9443c7415a0419799bee9cfbb1a9e4d","source":"clob_market_ws"},"received_at":"2026-07-27T04:40:27.687833Z","record_id":"6a943020e33b17968cfb9fc692e6f022a008a9e9d0a313f21c7dedb2183f565e","schema_fingerprint":"4aa3821a28b0b7c2400bc59aba4bcc0a76e971dadd19610d3ad38c768e124dc7","schema_version":"edge-lab-recorder.raw.v1","sequence":null,"source":"clob_market_ws"}
{"event_at":"2026-07-27T04:40:27.738000Z","event_fingerprint":"4cce7a26ab5a24a9f4ae809939d066eafade2efe184fe7c81c19b2758eb919b6","payload":{"connection_id":"0f4979d6978d463e9660b042fdcf555f","event_at":"2026-07-27T04:40:27.738000Z","event_type":"price_change","frame_hash":"3efeb7ab2e5225db3f81833e70207b8fc690f3d11ca1a10a1b56e0a98c24a57d","frame_index":0,"kind":"data","monotonic_ns":229210953971833,"payload":{"event_type":"price_change","market":"0xeb66215f2e9faa6449e30a02bab5b8ed7b79a38bf961f6b24d0073c9c2419250","price_changes":[{"asset_id":"69697746896130839564035629862476347944307040470122503199396727085502753297492","best_ask":"0.73","best_bid":"0.72","hash":"e43e8c403b1011748279ea10a36fa0d0b69c38fe","price":"0.69","side":"BUY","size":"161.14"},{"asset_id":"60386828328910021732068595344565885737045900010034836345809386672230885527307","best_ask":"0.28","best_bid":"0.27","hash":"5b26f441629b1e187d46c7143c2b58855a5e8e58","price":"0.31","side":"SELL","size":"161.14"}],"timestamp":"1785127227738"},"payload_hash":"e5f385ed6b52911d7323ffc96a00a4a3f92677b251334e6d983e9b6a16bea946","raw_frame":"{\"market\":\"0xeb66215f2e9faa6449e30a02bab5b8ed7b79a38bf961f6b24d0073c9c2419250\", \"price_changes\":[{\"asset_id\":\"69697746896130839564035629862476347944307040470122503199396727085502753297492\", \"price\":\"0.69\", \"size\":\"161.14\", \"side\":\"BUY\", \"hash\":\"e43e8c403b1011748279ea10a36fa0d0b69c38fe\", \"best_bid\":\"0.72\", \"best_ask\":\"0.73\"}, {\"asset_id\":\"60386828328910021732068595344565885737045900010034836345809386672230885527307\", \"price\":\"0.31\", \"size\":\"161.14\", \"side\":\"SELL\", \"hash\":\"5b26f441629b1e187d46c7143c2b58855a5e8e58\", \"best_bid\":\"0.27\", \"best_ask\":\"0.28\"}], \"timestamp\":\"1785127227738\", \"event_type\":\"price_change\"}","received_at":"2026-07-27T04:40:27.689580Z","schema_version":"clob-market-ws.price_change.v1","sequence":null,"server_hash":null,"server_timestamp":"1785127227738","session_id":"e9443c7415a0419799bee9cfbb1a9e4d","source":"clob_market_ws"},"received_at":"2026-07-27T04:40:27.689580Z","record_id":"2f84840310297c7d642fa090a196a3dd4650f23ac6ee27508bfd6eadf8282e15","schema_fingerprint":"4aa3821a28b0b7c2400bc59aba4bcc0a76e971dadd19610d3ad38c768e124dc7","schema_version":"edge-lab-recorder.raw.v1","sequence":null,"source":"clob_market_ws"}
{"event_at":"2026-07-27T04:40:27.802000Z","event_fingerprint":"d70c4b868de5fbcde6164cc0c0bb5abe0ea0586215866e76d62dd5e980ae935a","payload":{"connection_id":"0f4979d6978d463e9660b042fdcf555f","event_at":"2026-07-27T04:40:27.802000Z","event_type":"price_change","frame_hash":"bcf191a1c9c9973fc54c104e1c3f908d7e8325ca0d71ccccdbaad05386d6ad15","frame_index":0,"kind":"data","monotonic_ns":229211015736000,"payload":{"event_type":"price_change","market":"0xeb66215f2e9faa6449e30a02bab5b8ed7b79a38bf961f6b24d0073c9c2419250","price_changes":[{"asset_id":"69697746896130839564035629862476347944307040470122503199396727085502753297492","best_ask":"0.73","best_bid":"0.72","hash":"6af68e879efa7ad3b6f2054315f6974c2a40f40e","price":"0.03","side":"BUY","size":"618.1"},{"asset_id":"60386828328910021732068595344565885737045900010034836345809386672230885527307","best_ask":"0.28","best_bid":"0.27","hash":"89cbc2916720117fe32e34426fd6d747ad8ea308","price":"0.97","side":"SELL","size":"618.1"}],"timestamp":"1785127227802"},"payload_hash":"d125c5e3bc3946a061d9d165b7864841cbb72167267cfc5e42a3b1d1079311b3","raw_frame":"{\"market\":\"0xeb66215f2e9faa6449e30a02bab5b8ed7b79a38bf961f6b24d0073c9c2419250\", \"price_changes\":[{\"asset_id\":\"69697746896130839564035629862476347944307040470122503199396727085502753297492\", \"price\":\"0.03\", \"size\":\"618.1\", \"side\":\"BUY\", \"hash\":\"6af68e879efa7ad3b6f2054315f6974c2a40f40e\", \"best_bid\":\"0.72\", \"best_ask\":\"0.73\"}, {\"asset_id\":\"60386828328910021732068595344565885737045900010034836345809386672230885527307\", \"price\":\"0.97\", \"size\":\"618.1\", \"side\":\"SELL\", \"hash\":\"89cbc2916720117fe32e34426fd6d747ad8ea308\", \"best_bid\":\"0.27\", \"best_ask\":\"0.28\"}], \"timestamp\":\"1785127227802\", \"event_type\":\"price_change\"}","received_at":"2026-07-27T04:40:27.751339Z","schema_version":"clob-market-ws.price_change.v1","sequence":null,"server_hash":null,"server_timestamp":"1785127227802","session_id":"e9443c7415a0419799bee9cfbb1a9e4d","source":"clob_market_ws"},"received_at":"2026-07-27T04:40:27.751339Z","record_id":"f2723c8799ded889a44c984d4e3eda13e90ff242c122dedd679a1eea49576f93","schema_fingerprint":"4aa3821a28b0b7c2400bc59aba4bcc0a76e971dadd19610d3ad38c768e124dc7","schema_version":"edge-lab-recorder.raw.v1","sequence":null,"source":"clob_market_ws"}
{"event_at":"2026-07-27T04:40:27.864000Z","event_fingerprint":"dee65f86cab598ef9167c182d166bea6fc3a002b0d74040d248428ebea390d12","payload":{"connection_id":"0f4979d6978d463e9660b042fdcf555f","event_at":"2026-07-27T04:40:27.864000Z","event_type":"price_change","frame_hash":"f1337d88b56a8ed392a01a4c3b3e29bd14bc73178870441c4cd7878e618a008f","frame_index":0,"kind":"data","monotonic_ns":229211076571583,"payload":{"event_type":"price_change","market":"0xeb66215f2e9faa6449e30a02bab5b8ed7b79a38bf961f6b24d0073c9c2419250","price_changes":[{"asset_id":"69697746896130839564035629862476347944307040470122503199396727085502753297492","best_ask":"0.73","best_bid":"0.72","hash":"f0661193ebd32a994fa2f2673eae92622bdd8c12","price":"0.7","side":"BUY","size":"41.94"},{"asset_id":"60386828328910021732068595344565885737045900010034836345809386672230885527307","best_ask":"0.28","best_bid":"0.27","hash":"202a7923933d0cda71ee6b36fe4d242a6a49f08b","price":"0.3","side":"SELL","size":"41.94"}],"timestamp":"1785127227864"},"payload_hash":"4958b3de0029f4b5e739cdffdb22c94cc1e77671941c67226bf7548e5ab8f1d6","raw_frame":"{\"market\":\"0xeb66215f2e9faa6449e30a02bab5b8ed7b79a38bf961f6b24d0073c9c2419250\", \"price_changes\":[{\"asset_id\":\"69697746896130839564035629862476347944307040470122503199396727085502753297492\", \"price\":\"0.7\", \"size\":\"41.94\", \"side\":\"BUY\", \"hash\":\"f0661193ebd32a994fa2f2673eae92622bdd8c12\", \"best_bid\":\"0.72\", \"best_ask\":\"0.73\"}, {\"asset_id\":\"60386828328910021732068595344565885737045900010034836345809386672230885527307\", \"price\":\"0.3\", \"size\":\"41.94\", \"side\":\"SELL\", \"hash\":\"202a7923933d0cda71ee6b36fe4d242a6a49f08b\", \"best_bid\":\"0.27\", \"best_ask\":\"0.28\"}], \"timestamp\":\"1785127227864\", \"event_type\":\"price_change\"}","received_at":"2026-07-27T04:40:27.812173Z","schema_version":"clob-market-ws.price_change.v1","sequence":null,"server_hash":null,"server_timestamp":"1785127227864","session_id":"e9443c7415a0419799bee9cfbb1a9e4d","source":"clob_market_ws"},"received_at":"2026-07-27T04:40:27.812173Z","record_id":"2dbaed20c845958de5023fe9c315e514d416a0f78ece2a279198aa32ca7a7591","schema_fingerprint":"4aa3821a28b0b7c2400bc59aba4bcc0a76e971dadd19610d3ad38c768e124dc7","schema_version":"edge-lab-recorder.raw.v1","sequence":null,"source":"clob_market_ws"}
{"event_at":"2026-07-27T04:40:27.864000Z","event_fingerprint":"0c491489b857ca923b974981f9ea9bf25c2e88635a71fd356f8a30de1f297531","payload":{"connection_id":"0f4979d6978d463e9660b042fdcf555f","event_at":"2026-07-27T04:40:27.864000Z","event_type":"price_change","frame_hash":"e0411df0d97d190704759590140eff4fef3ab716e856fa84eb0d3e99c63de247","frame_index":0,"kind":"data","monotonic_ns":229211080213583,"payload":{"event_type":"price_change","market":"0xeb66215f2e9faa6449e30a02bab5b8ed7b79a38bf961f6b24d0073c9c2419250","price_changes":[{"asset_id":"69697746896130839564035629862476347944307040470122503199396727085502753297492","best_ask":"0.73","best_bid":"0.72","hash":"1daaa4b2e82c853b06c325923c29424452e7d04b","price":"0.69","side":"BUY","size":"153.14"},{"asset_id":"60386828328910021732068595344565885737045900010034836345809386672230885527307","best_ask":"0.28","best_bid":"0.27","hash":"f703c7efd4241feda7ad35fc7deaf21666a6dc58","price":"0.31","side":"SELL","size":"153.14"}],"timestamp":"1785127227864"},"payload_hash":"eca4147176c7dae7cd7fe15af74be36dd8240746690e40dd05ec2cc665e5066b","raw_frame":"{\"market\":\"0xeb66215f2e9faa6449e30a02bab5b8ed7b79a38bf961f6b24d0073c9c2419250\", \"price_changes\":[{\"asset_id\":\"69697746896130839564035629862476347944307040470122503199396727085502753297492\", \"price\":\"0.69\", \"size\":\"153.14\", \"side\":\"BUY\", \"hash\":\"1daaa4b2e82c853b06c325923c29424452e7d04b\", \"best_bid\":\"0.72\", \"best_ask\":\"0.73\"}, {\"asset_id\":\"60386828328910021732068595344565885737045900010034836345809386672230885527307\", \"price\":\"0.31\", \"size\":\"153.14\", \"side\":\"SELL\", \"hash\":\"f703c7efd4241feda7ad35fc7deaf21666a6dc58\", \"best_bid\":\"0.27\", \"best_ask\":\"0.28\"}], \"timestamp\":\"1785127227864\", \"event_type\":\"price_change\"}","received_at":"2026-07-27T04:40:27.815818Z","schema_version":"clob-market-ws.price_change.v1","sequence":null,"server_hash":null,"server_timestamp":"1785127227864","session_id":"e9443c7415a0419799bee9cfbb1a9e4d","source":"clob_market_ws"},"received_at":"2026-07-27T04:40:27.815818Z","record_id":"6730fee65021bc94b0a7e0610ebb1343536f078de4b0e9ca3a7b1f5207163e19","schema_fingerprint":"4aa3821a28b0b7c2400bc59aba4bcc0a76e971dadd19610d3ad38c768e124dc7","schema_version":"edge-lab-recorder.raw.v1","sequence":null,"source":"clob_market_ws"}
{"event_at":"2026-07-27T04:40:27.868000Z","event_fingerprint":"4422ff417e8046845ad29b7dadd2e9af5ac0d5111e3dceb7f153b4b325e57555","payload":{"connection_id":"0f4979d6978d463e9660b042fdcf555f","event_at":"2026-07-27T04:40:27.868000Z","event_type":"price_change","frame_hash":"d47ba5cd45dac19d99384b500979bf3f8fefd22ecd0dbb1659d2b1b6ac34e298","frame_index":0,"kind":"data","monotonic_ns":229211085492708,"payload":{"event_type":"price_change","market":"0xeb66215f2e9faa6449e30a02bab5b8ed7b79a38bf961f6b24d0073c9c2419250","price_changes":[{"asset_id":"60386828328910021732068595344565885737045900010034836345809386672230885527307","best_ask":"0.28","best_bid":"0.27","hash":"137a3dc5aa27e0476cd3688245444dc6bb5b42cf","price":"0.31","side":"SELL","size":"161.14"},{"asset_id":"69697746896130839564035629862476347944307040470122503199396727085502753297492","best_ask":"0.73","best_bid":"0.72","hash":"368bcb07bd941a0684da063cd6a67f7815218c79","price":"0.69","side":"BUY","size":"161.14"}],"timestamp":"1785127227868"},"payload_hash":"1efd6c78d95dc4e99a2ecfaa57949c0053bc5dd2b869c4d146078e1a4644e519","raw_frame":"{\"market\":\"0xeb66215f2e9faa6449e30a02bab5b8ed7b79a38bf961f6b24d0073c9c2419250\", \"price_changes\":[{\"asset_id\":\"60386828328910021732068595344565885737045900010034836345809386672230885527307\", \"price\":\"0.31\", \"size\":\"161.14\", \"side\":\"SELL\", \"hash\":\"137a3dc5aa27e0476cd3688245444dc6bb5b42cf\", \"best_bid\":\"0.27\", \"best_ask\":\"0.28\"}, {\"asset_id\":\"69697746896130839564035629862476347944307040470122503199396727085502753297492\", \"price\":\"0.69\", \"size\":\"161.14\", \"side\":\"BUY\", \"hash\":\"368bcb07bd941a0684da063cd6a67f7815218c79\", \"best_bid\":\"0.72\", \"best_ask\":\"0.73\"}], \"timestamp\":\"1785127227868\", \"event_type\":\"price_change\"}","received_at":"2026-07-27T04:40:27.821099Z","schema_version":"clob-market-ws.price_change.v1","sequence":null,"server_hash":null,"server_timestamp":"1785127227868","session_id":"e9443c7415a0419799bee9cfbb1a9e4d","source":"clob_market_ws"},"received_at":"2026-07-27T04:40:27.821099Z","record_id":"493d514443272229a968b8b83a7bd35a0defcdf2e52b8b3c29ed5755bfc5e2b3","schema_fingerprint":"4aa3821a28b0b7c2400bc59aba4bcc0a76e971dadd19610d3ad38c768e124dc7","schema_version":"edge-lab-recorder.raw.v1","sequence":null,"source":"clob_market_ws"}
{"event_at":"2026-07-27T04:40:27.869000Z","event_fingerprint":"0a107c6b6c5ed7e5c6b59d5da3642be547c712eeb118e5ebb4c358e0f67d45f0","payload":{"connection_id":"0f4979d6978d463e9660b042fdcf555f","event_at":"2026-07-27T04:40:27.869000Z","event_type":"price_change","frame_hash":"ddf2b3575ebbaac947971afd0fac1cf2fd427598669700711716ae7c6bf29460","frame_index":0,"kind":"data","monotonic_ns":229211089348583,"payload":{"event_type":"price_change","market":"0xeb66215f2e9faa6449e30a02bab5b8ed7b79a38bf961f6b24d0073c9c2419250","price_changes":[{"asset_id":"60386828328910021732068595344565885737045900010034836345809386672230885527307","best_ask":"0.28","best_bid":"0.27","hash":"501c90b6c65b78c0fd7777cec509fd85bc0726c5","price":"0.3","side":"SELL","size":"83.94"},{"asset_id":"69697746896130839564035629862476347944307040470122503199396727085502753297492","best_ask":"0.73","best_bid":"0.72","hash":"409026f5cae7595bf2ce58b9c0e530c05c2b1adf","price":"0.7","side":"BUY","size":"83.94"}],"timestamp":"1785127227869"},"payload_hash":"3a677100babc1b312780ceafde464954607210b5de9eb145ecb91a0cdd39438a","raw_frame":"{\"market\":\"0xeb66215f2e9faa6449e30a02bab5b8ed7b79a38bf961f6b24d0073c9c2419250\", \"price_changes\":[{\"asset_id\":\"60386828328910021732068595344565885737045900010034836345809386672230885527307\", \"price\":\"0.3\", \"size\":\"83.94\", \"side\":\"SELL\", \"hash\":\"501c90b6c65b78c0fd7777cec509fd85bc0726c5\", \"best_bid\":\"0.27\", \"best_ask\":\"0.28\"}, {\"asset_id\":\"69697746896130839564035629862476347944307040470122503199396727085502753297492\", \"price\":\"0.7\", \"size\":\"83.94\", \"side\":\"BUY\", \"hash\":\"409026f5cae7595bf2ce58b9c0e530c05c2b1adf\", \"best_bid\":\"0.72\", \"best_ask\":\"0.73\"}], \"timestamp\":\"1785127227869\", \"event_type\":\"price_change\"}","received_at":"2026-07-27T04:40:27.824953Z","schema_version":"clob-market-ws.price_change.v1","sequence":null,"server_hash":null,"server_timestamp":"1785127227869","session_id":"e9443c7415a0419799bee9cfbb1a9e4d","source":"clob_market_ws"},"received_at":"2026-07-27T04:40:27.824953Z","record_id":"8af1ccdcbd057576696f72fc9998763d6215493a2d943bba9b79c9a0da14d133","schema_fingerprint":"4aa3821a28b0b7c2400bc59aba4bcc0a76e971dadd19610d3ad38c768e124dc7","schema_version":"edge-lab-recorder.raw.v1","sequence":null,"source":"clob_market_ws"}
{"event_at":"2026-07-27T04:40:27.880000Z","event_fingerprint":"b59837f72145b72bc8fafd89e728db3a11470368023931ffe9949df920229832","payload":{"connection_id":"0f4979d6978d463e9660b042fdcf555f","event_at":"2026-07-27T04:40:27.880000Z","event_type":"price_change","frame_hash":"6c6c88f6f742e07a6dbe8af1f1b08aaa34b38511766413caed56aba5b91a98ac","frame_index":0,"kind":"data","monotonic_ns":229211093750208,"payload":{"event_type":"price_change","market":"0xeb66215f2e9faa6449e30a02bab5b8ed7b79a38bf961f6b24d0073c9c2419250","price_changes":[{"asset_id":"60386828328910021732068595344565885737045900010034836345809386672230885527307","best_ask":"0.28","best_bid":"0.27","hash":"9e60a815f9fe008fd1e13b1060296d504af88bee","price":"0.14","side":"BUY","size":"70.9"},{"asset_id":"69697746896130839564035629862476347944307040470122503199396727085502753297492","best_ask":"0.73","best_bid":"0.72","hash":"9bdefeb9084a18074a72f789d6b3aa26b6f2244d","price":"0.86","side":"SELL","size":"70.9"}],"timestamp":"1785127227880"},"payload_hash":"4a7de5475b57af36d2c3aba34d6fe190f844296d3ff2cade4d148a5305c8bd89","raw_frame":"{\"market\":\"0xeb66215f2e9faa6449e30a02bab5b8ed7b79a38bf961f6b24d0073c9c2419250\", \"price_changes\":[{\"asset_id\":\"60386828328910021732068595344565885737045900010034836345809386672230885527307\", \"price\":\"0.14\", \"size\":\"70.9\", \"side\":\"BUY\", \"hash\":\"9e60a815f9fe008fd1e13b1060296d504af88bee\", \"best_bid\":\"0.27\", \"best_ask\":\"0.28\"}, {\"asset_id\":\"69697746896130839564035629862476347944307040470122503199396727085502753297492\", \"price\":\"0.86\", \"size\":\"70.9\", \"side\":\"SELL\", \"hash\":\"9bdefeb9084a18074a72f789d6b3aa26b6f2244d\", \"best_bid\":\"0.72\", \"best_ask\":\"0.73\"}], \"timestamp\":\"1785127227880\", \"event_type\":\"price_change\"}","received_at":"2026-07-27T04:40:27.829355Z","schema_version":"clob-market-ws.price_change.v1","sequence":null,"server_hash":null,"server_timestamp":"1785127227880","session_id":"e9443c7415a0419799bee9cfbb1a9e4d","source":"clob_market_ws"},"received_at":"2026-07-27T04:40:27.829355Z","record_id":"44c7f469a5bc17b2e8ea4b17da37188d167bb7a4fb473858ba1d0173fddd7e8b","schema_fingerprint":"4aa3821a28b0b7c2400bc59aba4bcc0a76e971dadd19610d3ad38c768e124dc7","schema_version":"edge-lab-recorder.raw.v1","sequence":null,"source":"clob_market_ws"}
{"event_at":"2026-07-27T04:40:27.896000Z","event_fingerprint":"b5758d51133c9a083779daf42b7900c24ceaf0acedaef6e28b759da3bad32c06","payload":{"connection_id":"0f4979d6978d463e9660b042fdcf555f","event_at":"2026-07-27T04:40:27.896000Z","event_type":"price_change","frame_hash":"0c726fd6454dad773cde0f95510789ee08e6f27297c91420a585919094172401","frame_index":0,"kind":"data","monotonic_ns":229211110761875,"payload":{"event_type":"price_change","market":"0xeb66215f2e9faa6449e30a02bab5b8ed7b79a38bf961f6b24d0073c9c2419250","price_changes":[{"asset_id":"69697746896130839564035629862476347944307040470122503199396727085502753297492","best_ask":"0.73","best_bid":"0.72","hash":"608b36402cd694964825d42027af5353241f9c14","price":"0.03","side":"BUY","size":"613.1"},{"asset_id":"60386828328910021732068595344565885737045900010034836345809386672230885527307","best_ask":"0.28","best_bid":"0.27","hash":"3395f1315b4d02f898c36968281e3f858098a606","price":"0.97","side":"SELL","size":"613.1"}],"timestamp":"1785127227896"},"payload_hash":"c434a5960f28cf8f638897e0b34f00c0f8bf8178a313a894baa97fedd9a69b85","raw_frame":"{\"market\":\"0xeb66215f2e9faa6449e30a02bab5b8ed7b79a38bf961f6b24d0073c9c2419250\", \"price_changes\":[{\"asset_id\":\"69697746896130839564035629862476347944307040470122503199396727085502753297492\", \"price\":\"0.03\", \"size\":\"613.1\", \"side\":\"BUY\", \"hash\":\"608b36402cd694964825d42027af5353241f9c14\", \"best_bid\":\"0.72\", \"best_ask\":\"0.73\"}, {\"asset_id\":\"60386828328910021732068595344565885737045900010034836345809386672230885527307\", \"price\":\"0.97\", \"size\":\"613.1\", \"side\":\"SELL\", \"hash\":\"3395f1315b4d02f898c36968281e3f858098a606\", \"best_bid\":\"0.27\", \"best_ask\":\"0.28\"}], \"timestamp\":\"1785127227896\", \"event_type\":\"price_change\"}","received_at":"2026-07-27T04:40:27.846367Z","schema_version":"clob-market-ws.price_change.v1","sequence":null,"server_hash":null,"server_timestamp":"1785127227896","session_id":"e9443c7415a0419799bee9cfbb1a9e4d","source":"clob_market_ws"},"received_at":"2026-07-27T04:40:27.846367Z","record_id":"aa96645e055df2557224e5a4c5280d0d98f6b06a86e9ac85f805abdc23dcfe79","schema_fingerprint":"4aa3821a28b0b7c2400bc59aba4bcc0a76e971dadd19610d3ad38c768e124dc7","schema_version":"edge-lab-recorder.raw.v1","sequence":null,"source":"clob_market_ws"}
{"event_at":"2026-07-27T04:40:27.945000Z","event_fingerprint":"2829b24d348639d6823daa2f0af4ce2f27c97703d1614d4f8f7ceb60e9b7189b","payload":{"connection_id":"0f4979d6978d463e9660b042fdcf555f","event_at":"2026-07-27T04:40:27.945000Z","event_type":"price_change","frame_hash":"5ba85dd512abf658c3b6e746d928f0896e4574a12effae27c905dcc8ce72ed83","frame_index":0,"kind":"data","monotonic_ns":229211158622666,"payload":{"event_type":"price_change","market":"0xeb66215f2e9faa6449e30a02bab5b8ed7b79a38bf961f6b24d0073c9c2419250","price_changes":[{"asset_id":"60386828328910021732068595344565885737045900010034836345809386672230885527307","best_ask":"0.28","best_bid":"0.27","hash":"760215fd33ee95defaafd76111f1ea71dee0eb99","price":"0.28","side":"SELL","size":"24.24"},{"asset_id":"69697746896130839564035629862476347944307040470122503199396727085502753297492","best_ask":"0.73","best_bid":"0.72","hash":"732b8b6162e2ce94b6b81966e1986fb9f17a637a","price":"0.72","side":"BUY","size":"24.24"}],"timestamp":"1785127227945"},"payload_hash":"970a82878395f9b0fb97f6c3c5ab8fe6a04755485645c699670e2178d3f7f0d1","raw_frame":"{\"market\":\"0xeb66215f2e9faa6449e30a02bab5b8ed7b79a38bf961f6b24d0073c9c2419250\", \"price_changes\":[{\"asset_id\":\"60386828328910021732068595344565885737045900010034836345809386672230885527307\", \"price\":\"0.28\", \"size\":\"24.24\", \"side\":\"SELL\", \"hash\":\"760215fd33ee95defaafd76111f1ea71dee0eb99\", \"best_bid\":\"0.27\", \"best_ask\":\"0.28\"}, {\"asset_id\":\"69697746896130839564035629862476347944307040470122503199396727085502753297492\", \"price\":\"0.72\", \"size\":\"24.24\", \"side\":\"BUY\", \"hash\":\"732b8b6162e2ce94b6b81966e1986fb9f17a637a\", \"best_bid\":\"0.72\", \"best_ask\":\"0.73\"}], \"timestamp\":\"1785127227945\", \"event_type\":\"price_change\"}","received_at":"2026-07-27T04:40:27.894228Z","schema_version":"clob-market-ws.price_change.v1","sequence":null,"server_hash":null,"server_timestamp":"1785127227945","session_id":"e9443c7415a0419799bee9cfbb1a9e4d","source":"clob_market_ws"},"received_at":"2026-07-27T04:40:27.894228Z","record_id":"b06b8cde84bb3d80f5cc6f9f5baa5da3637cd99a95d3f10e5b1c369ca47adac4","schema_fingerprint":"4aa3821a28b0b7c2400bc59aba4bcc0a76e971dadd19610d3ad38c768e124dc7","schema_version":"edge-lab-recorder.raw.v1","sequence":null,"source":"clob_market_ws"}
{"event_at":"2026-07-27T04:40:27.962000Z","event_fingerprint":"bc09f338c39273db8318a465fa646db5ce273c1ca5899bc30bfaeacca9cd4554","payload":{"connection_id":"0f4979d6978d463e9660b042fdcf555f","event_at":"2026-07-27T04:40:27.962000Z","event_type":"price_change","frame_hash":"ba6ec310eef996ed52a70575192af762e99bfe069d59cbcff225ff4d065fa02a","frame_index":0,"kind":"data","monotonic_ns":229211175802416,"payload":{"event_type":"price_change","market":"0xeb66215f2e9faa6449e30a02bab5b8ed7b79a38bf961f6b24d0073c9c2419250","price_changes":[{"asset_id":"60386828328910021732068595344565885737045900010034836345809386672230885527307","best_ask":"0.28","best_bid":"0.27","hash":"85b46da131394472c3e1c4a481c8a55d772d4f8f","price":"0.31","side":"SELL","size":"153.14"},{"asset_id":"69697746896130839564035629862476347944307040470122503199396727085502753297492","best_ask":"0.73","best_bid":"0.72","hash":"52aebe09328d150158fdcf9e447e5512fee6ad4e","price":"0.69","side":"BUY","size":"153.14"}],"timestamp":"1785127227962"},"payload_hash":"09e7974e05a08de1aa334fb1b81a42eee83d5fe92d50447dd7a11621225643ba","raw_frame":"{\"market\":\"0xeb66215f2e9faa6449e30a02bab5b8ed7b79a38bf961f6b24d0073c9c2419250\", \"price_changes\":[{\"asset_id\":\"60386828328910021732068595344565885737045900010034836345809386672230885527307\", \"price\":\"0.31\", \"size\":\"153.14\", \"side\":\"SELL\", \"hash\":\"85b46da131394472c3e1c4a481c8a55d772d4f8f\", \"best_bid\":\"0.27\", \"best_ask\":\"0.28\"}, {\"asset_id\":\"69697746896130839564035629862476347944307040470122503199396727085502753297492\", \"price\":\"0.69\", \"size\":\"153.14\", \"side\":\"BUY\", \"hash\":\"52aebe09328d150158fdcf9e447e5512fee6ad4e\", \"best_bid\":\"0.72\", \"best_ask\":\"0.73\"}], \"timestamp\":\"1785127227962\", \"event_type\":\"price_change\"}","received_at":"2026-07-27T04:40:27.911408Z","schema_version":"clob-market-ws.price_change.v1","sequence":null,"server_hash":null,"server_timestamp":"1785127227962","session_id":"e9443c7415a0419799bee9cfbb1a9e4d","source":"clob_market_ws"},"received_at":"2026-07-27T04:40:27.911408Z","record_id":"eaabb287900a20c4f68c28125394c8a70c7b97113d8e01a889ce85950b49d721","schema_fingerprint":"4aa3821a28b0b7c2400bc59aba4bcc0a76e971dadd19610d3ad38c768e124dc7","schema_version":"edge-lab-recorder.raw.v1","sequence":null,"source":"clob_market_ws"}
{"event_at":"2026-07-27T04:40:27.962000Z","event_fingerprint":"9dcc01626d5b146eb1d90deca22ee482795b7e58196aaaef3c0c909826abd2e8","payload":{"connection_id":"0f4979d6978d463e9660b042fdcf555f","event_at":"2026-07-27T04:40:27.962000Z","event_type":"price_change","frame_hash":"f33b97ce963641bf917b6a5135828c89da70c5053646bdca55263358481408e1","frame_index":0,"kind":"data","monotonic_ns":229211180027875,"payload":{"event_type":"price_change","market":"0xeb66215f2e9faa6449e30a02bab5b8ed7b79a38bf961f6b24d0073c9c2419250","price_changes":[{"asset_id":"60386828328910021732068595344565885737045900010034836345809386672230885527307","best_ask":"0.28","best_bid":"0.27","hash":"6db16bd8445f16de126bc0ab40b85da15b193bf7","price":"0.3","side":"SELL","size":"41.94"},{"asset_id":"69697746896130839564035629862476347944307040470122503199396727085502753297492","best_ask":"0.73","best_bid":"0.72","hash":"07d94a9688c401cbf317c55044573cdf2cbc5ab0","price":"0.7","side":"BUY","size":"41.94"}],"timestamp":"1785127227962"},"payload_hash":"f4ef5f4e36b66a50d4cfddd5fb7222e54a148920fa43e717cebeafe5fff573c9","raw_frame":"{\"market\":\"0xeb66215f2e9faa6449e30a02bab5b8ed7b79a38bf961f6b24d0073c9c2419250\", \"price_changes\":[{\"asset_id\":\"60386828328910021732068595344565885737045900010034836345809386672230885527307\", \"price\":\"0.3\", \"size\":\"41.94\", \"side\":\"SELL\", \"hash\":\"6db16bd8445f16de126bc0ab40b85da15b193bf7\", \"best_bid\":\"0.27\", \"best_ask\":\"0.28\"}, {\"asset_id\":\"69697746896130839564035629862476347944307040470122503199396727085502753297492\", \"price\":\"0.7\", \"size\":\"41.94\", \"side\":\"BUY\", \"hash\":\"07d94a9688c401cbf317c55044573cdf2cbc5ab0\", \"best_bid\":\"0.72\", \"best_ask\":\"0.73\"}], \"timestamp\":\"1785127227962\", \"event_type\":\"price_change\"}","received_at":"2026-07-27T04:40:27.915634Z","schema_version":"clob-market-ws.price_change.v1","sequence":null,"server_hash":null,"server_timestamp":"1785127227962","session_id":"e9443c7415a0419799bee9cfbb1a9e4d","source":"clob_market_ws"},"received_at":"2026-07-27T04:40:27.915634Z","record_id":"8913433c969673f584f7277f31e2c9c687c8a3616d9f7219b88b032ece001fa8","schema_fingerprint":"4aa3821a28b0b7c2400bc59aba4bcc0a76e971dadd19610d3ad38c768e124dc7","schema_version":"edge-lab-recorder.raw.v1","sequence":null,"source":"clob_market_ws"}
{"event_at":"2026-07-27T04:40:27.967000Z","event_fingerprint":"459b7e055fa6d0977d8ac9e4c4e43bd32926727d8c2aed5265d058c7198fab6e","payload":{"connection_id":"0f4979d6978d463e9660b042fdcf555f","event_at":"2026-07-27T04:40:27.967000Z","event_type":"price_change","frame_hash":"fa90980a8ea9e4e92192d05e169ae1f6fa9e99ad0f58f2891db11e27fa040907","frame_index":0,"kind":"data","monotonic_ns":229211185385875,"payload":{"event_type":"price_change","market":"0xeb66215f2e9faa6449e30a02bab5b8ed7b79a38bf961f6b24d0073c9c2419250","price_changes":[{"asset_id":"69697746896130839564035629862476347944307040470122503199396727085502753297492","best_ask":"0.73","best_bid":"0.72","hash":"ffc23bed57a1237f373cbd735e9f9e8ce93d71ee","price":"0.7","side":"BUY","size":"83.86"},{"asset_id":"60386828328910021732068595344565885737045900010034836345809386672230885527307","best_ask":"0.28","best_bid":"0.27","hash":"dd8addd67fe6f97e7a3af80324675fc70880dda6","price":"0.3","side":"SELL","size":"83.86"}],"timestamp":"1785127227967"},"payload_hash":"cf3e60641c73d122b7d68b0d70773b00b1d66b01bfa7c57707c4c15d593b67bd","raw_frame":"{\"market\":\"0xeb66215f2e9faa6449e30a02bab5b8ed7b79a38bf961f6b24d0073c9c2419250\", \"price_changes\":[{\"asset_id\":\"69697746896130839564035629862476347944307040470122503199396727085502753297492\", \"price\":\"0.7\", \"size\":\"83.86\", \"side\":\"BUY\", \"hash\":\"ffc23bed57a1237f373cbd735e9f9e8ce93d71ee\", \"best_bid\":\"0.72\", \"best_ask\":\"0.73\"}, {\"asset_id\":\"60386828328910021732068595344565885737045900010034836345809386672230885527307\", \"price\":\"0.3\", \"size\":\"83.86\", \"side\":\"SELL\", \"hash\":\"dd8addd67fe6f97e7a3af80324675fc70880dda6\", \"best_bid\":\"0.27\", \"best_ask\":\"0.28\"}], \"timestamp\":\"1785127227967\", \"event_type\":\"price_change\"}","received_at":"2026-07-27T04:40:27.920991Z","schema_version":"clob-market-ws.price_change.v1","sequence":null,"server_hash":null,"server_timestamp":"1785127227967","session_id":"e9443c7415a0419799bee9cfbb1a9e4d","source":"clob_market_ws"},"received_at":"2026-07-27T04:40:27.920991Z","record_id":"11401b0e2347bfc3c0fda1aad65e0edf2c4cf6ba7221f515ea1f32dc7439e4a2","schema_fingerprint":"4aa3821a28b0b7c2400bc59aba4bcc0a76e971dadd19610d3ad38c768e124dc7","schema_version":"edge-lab-recorder.raw.v1","sequence":null,"source":"clob_market_ws"}
{"event_at":"2026-07-27T04:40:27.969000Z","event_fingerprint":"3d6ba4851c78e42fab54a8180abcc1067af0f28ad29df964c89b65486dd3b492","payload":{"connection_id":"0f4979d6978d463e9660b042fdcf555f","event_at":"2026-07-27T04:40:27.969000Z","event_type":"price_change","frame_hash":"6b8e284111e5c9808ca5378f2bf0998fb56e44dcc8376bdd29e265c31c4d54a3","frame_index":0,"kind":"data","monotonic_ns":229211191595250,"payload":{"event_type":"price_change","market":"0xeb66215f2e9faa6449e30a02bab5b8ed7b79a38bf961f6b24d0073c9c2419250","price_changes":[{"asset_id":"69697746896130839564035629862476347944307040470122503199396727085502753297492","best_ask":"0.73","best_bid":"0.72","hash":"9169515293a82fcf4d9ec65f91e662c6a0ec630a","price":"0.69","side":"BUY","size":"161.14"},{"asset_id":"60386828328910021732068595344565885737045900010034836345809386672230885527307","best_ask":"0.28","best_bid":"0.27","hash":"9c4b116519012a02fb0b3013057cd396fe61bc2c","price":"0.31","side":"SELL","size":"161.14"}],"timestamp":"1785127227969"},"payload_hash":"d1092ffd3db2e08fecdead62ffc22a3ee7bada7ae9fb9c0dfec848792f282ebe","raw_frame":"{\"market\":\"0xeb66215f2e9faa6449e30a02bab5b8ed7b79a38bf961f6b24d0073c9c2419250\", \"price_changes\":[{\"asset_id\":\"69697746896130839564035629862476347944307040470122503199396727085502753297492\", \"price\":\"0.69\", \"size\":\"161.14\", \"side\":\"BUY\", \"hash\":\"9169515293a82fcf4d9ec65f91e662c6a0ec630a\", \"best_bid\":\"0.72\", \"best_ask\":\"0.73\"}, {\"asset_id\":\"60386828328910021732068595344565885737045900010034836345809386672230885527307\", \"price\":\"0.31\", \"size\":\"161.14\", \"side\":\"SELL\", \"hash\":\"9c4b116519012a02fb0b3013057cd396fe61bc2c\", \"best_bid\":\"0.27\", \"best_ask\":\"0.28\"}], \"timestamp\":\"1785127227969\", \"event_type\":\"price_change\"}","received_at":"2026-07-27T04:40:27.927201Z","schema_version":"clob-market-ws.price_change.v1","sequence":null,"server_hash":null,"server_timestamp":"1785127227969","session_id":"e9443c7415a0419799bee9cfbb1a9e4d","source":"clob_market_ws"},"received_at":"2026-07-27T04:40:27.927201Z","record_id":"8d8fa8e4b1d4d8d93e6c7ed588360bf3c60031b7dbb52422e3028a27c9a3c891","schema_fingerprint":"4aa3821a28b0b7c2400bc59aba4bcc0a76e971dadd19610d3ad38c768e124dc7","schema_version":"edge-lab-recorder.raw.v1","sequence":null,"source":"clob_market_ws"}
{"event_at":"2026-07-27T04:40:27.989000Z","event_fingerprint":"a1f2c133d70e545d3f86a17fd9bfebc24223f62695fd45281743f65284f8ef9c","payload":{"connection_id":"0f4979d6978d463e9660b042fdcf555f","event_at":"2026-07-27T04:40:27.989000Z","event_type":"price_change","frame_hash":"b1686831e1c2c360f619efd7b00b0dbbebfbcd67c85ee46b30980681f45fffec","frame_index":0,"kind":"data","monotonic_ns":229211203288625,"payload":{"event_type":"price_change","market":"0xeb66215f2e9faa6449e30a02bab5b8ed7b79a38bf961f6b24d0073c9c2419250","price_changes":[{"asset_id":"69697746896130839564035629862476347944307040470122503199396727085502753297492","best_ask":"0.73","best_bid":"0.72","hash":"6128fac95a7a2f9f668b6cc78ceff3ae0fea5ab4","price":"0.02","side":"BUY","size":"688.1"},{"asset_id":"60386828328910021732068595344565885737045900010034836345809386672230885527307","best_ask":"0.28","best_bid":"0.27","hash":"7a04f9dd6c247de8debd38f718f98b5f526e5cc8","price":"0.98","side":"SELL","size":"688.1"}],"timestamp":"1785127227989"},"payload_hash":"172685bf201cdf429d049f6415b02cff09754ed78c7c5246a593aeff7f62fb7b","raw_frame":"{\"market\":\"0xeb66215f2e9faa6449e30a02bab5b8ed7b79a38bf961f6b24d0073c9c2419250\", \"price_changes\":[{\"asset_id\":\"69697746896130839564035629862476347944307040470122503199396727085502753297492\", \"price\":\"0.02\", \"size\":\"688.1\", \"side\":\"BUY\", \"hash\":\"6128fac95a7a2f9f668b6cc78ceff3ae0fea5ab4\", \"best_bid\":\"0.72\", \"best_ask\":\"0.73\"}, {\"asset_id\":\"60386828328910021732068595344565885737045900010034836345809386672230885527307\", \"price\":\"0.98\", \"size\":\"688.1\", \"side\":\"SELL\", \"hash\":\"7a04f9dd6c247de8debd38f718f98b5f526e5cc8\", \"best_bid\":\"0.27\", \"best_ask\":\"0.28\"}], \"timestamp\":\"1785127227989\", \"event_type\":\"price_change\"}","received_at":"2026-07-27T04:40:27.938894Z","schema_version":"clob-market-ws.price_change.v1","sequence":null,"server_hash":null,"server_timestamp":"1785127227989","session_id":"e9443c7415a0419799bee9cfbb1a9e4d","source":"clob_market_ws"},"received_at":"2026-07-27T04:40:27.938894Z","record_id":"46491d9c96e5e7b2120770735eebe4c522bd5480641de0a3f14aebad74075eba","schema_fingerprint":"4aa3821a28b0b7c2400bc59aba4bcc0a76e971dadd19610d3ad38c768e124dc7","schema_version":"edge-lab-recorder.raw.v1","sequence":null,"source":"clob_market_ws"}
{"event_at":"2026-07-27T04:40:28.015000Z","event_fingerprint":"82271ae4427d977a568aeb2821fbce96bbbcd74d97b40dbac73fda2e8d93f230","payload":{"connection_id":"0f4979d6978d463e9660b042fdcf555f","event_at":"2026-07-27T04:40:28.015000Z","event_type":"price_change","frame_hash":"07310d8594f1c96be675bbb6c52c8009b9e1e1f8b699aa04df75f6701c9eb822","frame_index":0,"kind":"data","monotonic_ns":229211230399583,"payload":{"event_type":"price_change","market":"0xeb66215f2e9faa6449e30a02bab5b8ed7b79a38bf961f6b24d0073c9c2419250","price_changes":[{"asset_id":"69697746896130839564035629862476347944307040470122503199396727085502753297492","best_ask":"0.73","best_bid":"0.72","hash":"2ba3b51442b4f49e171d6da11067e49640775ef7","price":"0.01","side":"BUY","size":"5638.02"},{"asset_id":"60386828328910021732068595344565885737045900010034836345809386672230885527307","best_ask":"0.28","best_bid":"0.27","hash":"16ec0fe6e625b6a861c0511f38bc843536b1c42f","price":"0.99","side":"SELL","size":"5638.02"}],"timestamp":"1785127228015"},"payload_hash":"2943e98c8215932ae013edd6dd5d919bc84ae4c07100bec20df11037ef778773","raw_frame":"{\"market\":\"0xeb66215f2e9faa6449e30a02bab5b8ed7b79a38bf961f6b24d0073c9c2419250\", \"price_changes\":[{\"asset_id\":\"69697746896130839564035629862476347944307040470122503199396727085502753297492\", \"price\":\"0.01\", \"size\":\"5638.02\", \"side\":\"BUY\", \"hash\":\"2ba3b51442b4f49e171d6da11067e49640775ef7\", \"best_bid\":\"0.72\", \"best_ask\":\"0.73\"}, {\"asset_id\":\"60386828328910021732068595344565885737045900010034836345809386672230885527307\", \"price\":\"0.99\", \"size\":\"5638.02\", \"side\":\"SELL\", \"hash\":\"16ec0fe6e625b6a861c0511f38bc843536b1c42f\", \"best_bid\":\"0.27\", \"best_ask\":\"0.28\"}], \"timestamp\":\"1785127228015\", \"event_type\":\"price_change\"}","received_at":"2026-07-27T04:40:27.966007Z","schema_version":"clob-market-ws.price_change.v1","sequence":null,"server_hash":null,"server_timestamp":"1785127228015","session_id":"e9443c7415a0419799bee9cfbb1a9e4d","source":"clob_market_ws"},"received_at":"2026-07-27T04:40:27.966007Z","record_id":"1343c2682bdc97b886a404e4e63a876919f7d02d563cb1f7bddf61c38d038d5e","schema_fingerprint":"4aa3821a28b0b7c2400bc59aba4bcc0a76e971dadd19610d3ad38c768e124dc7","schema_version":"edge-lab-recorder.raw.v1","sequence":null,"source":"clob_market_ws"}
{"event_at":"2026-07-27T04:40:28.022000Z","event_fingerprint":"442588a4d382790b17487357979b2d77fed918d4a6f59183f17e9de1c59dc496","payload":{"connection_id":"0f4979d6978d463e9660b042fdcf555f","event_at":"2026-07-27T04:40:28.022000Z","event_type":"price_change","frame_hash":"7d3ca6b13f46d5b1a8f05c491c40ad207c7060d25fa420c22c56a898ac15a672","frame_index":0,"kind":"data","monotonic_ns":229211236042375,"payload":{"event_type":"price_change","market":"0xeb66215f2e9faa6449e30a02bab5b8ed7b79a38bf961f6b24d0073c9c2419250","price_changes":[{"asset_id":"60386828328910021732068595344565885737045900010034836345809386672230885527307","best_ask":"0.28","best_bid":"0.27","hash":"80a6b5443728acc3494507b7c1a3b3fcaaaad37f","price":"0.01","side":"BUY","size":"5698.02"},{"asset_id":"69697746896130839564035629862476347944307040470122503199396727085502753297492","best_ask":"0.73","best_bid":"0.72","hash":"6c509c9af18fb1381dd477895d396efda26279cb","price":"0.99","side":"SELL","size":"5698.02"}],"timestamp":"1785127228022"},"payload_hash":"0387ba4b190a10d170d1208d2212f890fe6e6eb2c42167e8ac97bafceb7dcfb9","raw_frame":"{\"market\":\"0xeb66215f2e9faa6449e30a02bab5b8ed7b79a38bf961f6b24d0073c9c2419250\", \"price_changes\":[{\"asset_id\":\"60386828328910021732068595344565885737045900010034836345809386672230885527307\", \"price\":\"0.01\", \"size\":\"5698.02\", \"side\":\"BUY\", \"hash\":\"80a6b5443728acc3494507b7c1a3b3fcaaaad37f\", \"best_bid\":\"0.27\", \"best_ask\":\"0.28\"}, {\"asset_id\":\"69697746896130839564035629862476347944307040470122503199396727085502753297492\", \"price\":\"0.99\", \"size\":\"5698.02\", \"side\":\"SELL\", \"hash\":\"6c509c9af18fb1381dd477895d396efda26279cb\", \"best_bid\":\"0.72\", \"best_ask\":\"0.73\"}], \"timestamp\":\"1785127228022\", \"event_type\":\"price_change\"}","received_at":"2026-07-27T04:40:27.971645Z","schema_version":"clob-market-ws.price_change.v1","sequence":null,"server_hash":null,"server_timestamp":"1785127228022","session_id":"e9443c7415a0419799bee9cfbb1a9e4d","source":"clob_market_ws"},"received_at":"2026-07-27T04:40:27.971645Z","record_id":"7087376fe1fa1b9548d9355b066e2ff8a5d83aa5603360550366c7b66f145058","schema_fingerprint":"4aa3821a28b0b7c2400bc59aba4bcc0a76e971dadd19610d3ad38c768e124dc7","schema_version":"edge-lab-recorder.raw.v1","sequence":null,"source":"clob_market_ws"}
{"event_at":"2026-07-27T04:40:28.026000Z","event_fingerprint":"d0d71c576426222a2af5063292fa0184df723dc62ccb9b5af0cf170caebe4e92","payload":{"connection_id":"0f4979d6978d463e9660b042fdcf555f","event_at":"2026-07-27T04:40:28.026000Z","event_type":"price_change","frame_hash":"89eb1ceb4bd8eaadf8ea084788b492a7dc8b60c912a97c36354016bab8e378de","frame_index":0,"kind":"data","monotonic_ns":229211239301958,"payload":{"event_type":"price_change","market":"0xeb66215f2e9faa6449e30a02bab5b8ed7b79a38bf961f6b24d0073c9c2419250","price_changes":[{"asset_id":"60386828328910021732068595344565885737045900010034836345809386672230885527307","best_ask":"0.28","best_bid":"0.27","hash":"cbee5c7b66326f8f7ae098fb7c9e095f3f55b4a5","price":"0.01","side":"BUY","size":"5703.02"},{"asset_id":"69697746896130839564035629862476347944307040470122503199396727085502753297492","best_ask":"0.73","best_bid":"0.72","hash":"e96354c40681da8f58377420eac56c2099191991","price":"0.99","side":"SELL","size":"5703.02"}],"timestamp":"1785127228026"},"payload_hash":"f47cad409ea803d397e3e80d04c0e9a5a4e84281567f3fdd0ec36361d7ae8fca","raw_frame":"{\"market\":\"0xeb66215f2e9faa6449e30a02bab5b8ed7b79a38bf961f6b24d0073c9c2419250\", \"price_changes\":[{\"asset_id\":\"60386828328910021732068595344565885737045900010034836345809386672230885527307\", \"price\":\"0.01\", \"size\":\"5703.02\", \"side\":\"BUY\", \"hash\":\"cbee5c7b66326f8f7ae098fb7c9e095f3f55b4a5\", \"best_bid\":\"0.27\", \"best_ask\":\"0.28\"}, {\"asset_id\":\"69697746896130839564035629862476347944307040470122503199396727085502753297492\", \"price\":\"0.99\", \"size\":\"5703.02\", \"side\":\"SELL\", \"hash\":\"e96354c40681da8f58377420eac56c2099191991\", \"best_bid\":\"0.72\", \"best_ask\":\"0.73\"}], \"timestamp\":\"1785127228026\", \"event_type\":\"price_change\"}","received_at":"2026-07-27T04:40:27.974908Z","schema_version":"clob-market-ws.price_change.v1","sequence":null,"server_hash":null,"server_timestamp":"1785127228026","session_id":"e9443c7415a0419799bee9cfbb1a9e4d","source":"clob_market_ws"},"received_at":"2026-07-27T04:40:27.974908Z","record_id":"3ce2d9a0ca43309fd9f821db0852f049517aec850e98629ad8d85a071b2d79e9","schema_fingerprint":"4aa3821a28b0b7c2400bc59aba4bcc0a76e971dadd19610d3ad38c768e124dc7","schema_version":"edge-lab-recorder.raw.v1","sequence":null,"source":"clob_market_ws"}
{"event_at":"2026-07-27T04:40:28.044000Z","event_fingerprint":"591b38faed642e5a5659bd7e90a6c776c00f878d370bdbfacb28573a0dfc6fb4","payload":{"connection_id":"0f4979d6978d463e9660b042fdcf555f","event_at":"2026-07-27T04:40:28.044000Z","event_type":"price_change","frame_hash":"60f38e8a771e67d36f057dba93f1358ea5c15daaf55e428c5991e8d54789c47a","frame_index":0,"kind":"data","monotonic_ns":229211259064583,"payload":{"event_type":"price_change","market":"0xeb66215f2e9faa6449e30a02bab5b8ed7b79a38bf961f6b24d0073c9c2419250","price_changes":[{"asset_id":"69697746896130839564035629862476347944307040470122503199396727085502753297492","best_ask":"0.73","best_bid":"0.72","hash":"44c005e428eb36fa5e6600a7cf0e0a5879302c05","price":"0.02","side":"BUY","size":"683.1"},{"asset_id":"60386828328910021732068595344565885737045900010034836345809386672230885527307","best_ask":"0.28","best_bid":"0.27","hash":"c39beeaeb1d4a4836f2442a0672f6c1197b960b3","price":"0.98","side":"SELL","size":"683.1"}],"timestamp":"1785127228044"},"payload_hash":"a3dda882db77589092e9ee2bd3f3695edefb46c8ec4f250997d99604a6406773","raw_frame":"{\"market\":\"0xeb66215f2e9faa6449e30a02bab5b8ed7b79a38bf961f6b24d0073c9c2419250\", \"price_changes\":[{\"asset_id\":\"69697746896130839564035629862476347944307040470122503199396727085502753297492\", \"price\":\"0.02\", \"size\":\"683.1\", \"side\":\"BUY\", \"hash\":\"44c005e428eb36fa5e6600a7cf0e0a5879302c05\", \"best_bid\":\"0.72\", \"best_ask\":\"0.73\"}, {\"asset_id\":\"60386828328910021732068595344565885737045900010034836345809386672230885527307\", \"price\":\"0.98\", \"size\":\"683.1\", \"side\":\"SELL\", \"hash\":\"c39beeaeb1d4a4836f2442a0672f6c1197b960b3\", \"best_bid\":\"0.27\", \"best_ask\":\"0.28\"}], \"timestamp\":\"1785127228044\", \"event_type\":\"price_change\"}","received_at":"2026-07-27T04:40:27.994671Z","schema_version":"clob-market-ws.price_change.v1","sequence":null,"server_hash":null,"server_timestamp":"1785127228044","session_id":"e9443c7415a0419799bee9cfbb1a9e4d","source":"clob_market_ws"},"received_at":"2026-07-27T04:40:27.994671Z","record_id":"ab1a756293369756368b099c00218897b3c387ce436d6f3396509025460ad025","schema_fingerprint":"4aa3821a28b0b7c2400bc59aba4bcc0a76e971dadd19610d3ad38c768e124dc7","schema_version":"edge-lab-recorder.raw.v1","sequence":null,"source":"clob_market_ws"}
{"event_at":"2026-07-27T04:40:28.048000Z","event_fingerprint":"517f8759a99208fa41284570782847bd569367763b7f12a8e2ca1028ada1b446","payload":{"connection_id":"0f4979d6978d463e9660b042fdcf555f","event_at":"2026-07-27T04:40:28.048000Z","event_type":"price_change","frame_hash":"935677a922fae90c160d714aedf3c96735d0cf9ef9bd6a8568f5da64677a5ac4","frame_index":0,"kind":"data","monotonic_ns":229211265570708,"payload":{"event_type":"price_change","market":"0xeb66215f2e9faa6449e30a02bab5b8ed7b79a38bf961f6b24d0073c9c2419250","price_changes":[{"asset_id":"69697746896130839564035629862476347944307040470122503199396727085502753297492","best_ask":"0.73","best_bid":"0.72","hash":"0d2f52f456c9187dec0607a496540fd626d73a20","price":"0.01","side":"BUY","size":"5633.02"},{"asset_id":"60386828328910021732068595344565885737045900010034836345809386672230885527307","best_ask":"0.28","best_bid":"0.27","hash":"9d4d94a4879ec6f97544b970a9cd06d55373dcd6","price":"0.99","side":"SELL","size":"5633.02"}],"timestamp":"1785127228048"},"payload_hash":"cbc42900d40b6043f815f974a32bb71385d1b52c6ff560a0f9b2369620d057e7","raw_frame":"{\"market\":\"0xeb66215f2e9faa6449e30a02bab5b8ed7b79a38bf961f6b24d0073c9c2419250\", \"price_changes\":[{\"asset_id\":\"69697746896130839564035629862476347944307040470122503199396727085502753297492\", \"price\":\"0.01\", \"size\":\"5633.02\", \"side\":\"BUY\", \"hash\":\"0d2f52f456c9187dec0607a496540fd626d73a20\", \"best_bid\":\"0.72\", \"best_ask\":\"0.73\"}, {\"asset_id\":\"60386828328910021732068595344565885737045900010034836345809386672230885527307\", \"price\":\"0.99\", \"size\":\"5633.02\", \"side\":\"SELL\", \"hash\":\"9d4d94a4879ec6f97544b970a9cd06d55373dcd6\", \"best_bid\":\"0.27\", \"best_ask\":\"0.28\"}], \"timestamp\":\"1785127228048\", \"event_type\":\"price_change\"}","received_at":"2026-07-27T04:40:28.001177Z","schema_version":"clob-market-ws.price_change.v1","sequence":null,"server_hash":null,"server_timestamp":"1785127228048","session_id":"e9443c7415a0419799bee9cfbb1a9e4d","source":"clob_market_ws"},"received_at":"2026-07-27T04:40:28.001177Z","record_id":"ccad6ce48dcb834489371c319bab1905931976c1e87d0ee8541c1782d06c4692","schema_fingerprint":"4aa3821a28b0b7c2400bc59aba4bcc0a76e971dadd19610d3ad38c768e124dc7","schema_version":"edge-lab-recorder.raw.v1","sequence":null,"source":"clob_market_ws"}
{"event_at":"2026-07-27T04:40:28.050000Z","event_fingerprint":"38e04f0aac7feaa93e892fa70f67f6094baa87ba0017fd485dd75983643921e7","payload":{"connection_id":"0f4979d6978d463e9660b042fdcf555f","event_at":"2026-07-27T04:40:28.050000Z","event_type":"price_change","frame_hash":"a636f006e08f911fa2d1858e8972edefe10bc41d47a55fdf9fd48a5ed6ae64f1","frame_index":0,"kind":"data","monotonic_ns":229211281590833,"payload":{"event_type":"price_change","market":"0xeb66215f2e9faa6449e30a02bab5b8ed7b79a38bf961f6b24d0073c9c2419250","price_changes":[{"asset_id":"60386828328910021732068595344565885737045900010034836345809386672230885527307","best_ask":"0.28","best_bid":"0.27","hash":"c5949122a6df84a6e2b17d8aeb8fa88ecc07e646","price":"0.01","side":"BUY","size":"5698.02"},{"asset_id":"69697746896130839564035629862476347944307040470122503199396727085502753297492","best_ask":"0.73","best_bid":"0.72","hash":"a8adb56c898315d3280eb94ddeccee35f329f3a0","price":"0.99","side":"SELL","size":"5698.02"}],"timestamp":"1785127228050"},"payload_hash":"a90d1300284e3eb780a2c0acb13c69d65f46ffad4eb1258c5d1c783a9fc73e17","raw_frame":"{\"market\":\"0xeb66215f2e9faa6449e30a02bab5b8ed7b79a38bf961f6b24d0073c9c2419250\", \"price_changes\":[{\"asset_id\":\"60386828328910021732068595344565885737045900010034836345809386672230885527307\", \"price\":\"0.01\", \"size\":\"5698.02\", \"side\":\"BUY\", \"hash\":\"c5949122a6df84a6e2b17d8aeb8fa88ecc07e646\", \"best_bid\":\"0.27\", \"best_ask\":\"0.28\"}, {\"asset_id\":\"69697746896130839564035629862476347944307040470122503199396727085502753297492\", \"price\":\"0.99\", \"size\":\"5698.02\", \"side\":\"SELL\", \"hash\":\"a8adb56c898315d3280eb94ddeccee35f329f3a0\", \"best_bid\":\"0.72\", \"best_ask\":\"0.73\"}], \"timestamp\":\"1785127228050\", \"event_type\":\"price_change\"}","received_at":"2026-07-27T04:40:28.017198Z","schema_version":"clob-market-ws.price_change.v1","sequence":null,"server_hash":null,"server_timestamp":"1785127228050","session_id":"e9443c7415a0419799bee9cfbb1a9e4d","source":"clob_market_ws"},"received_at":"2026-07-27T04:40:28.017198Z","record_id":"95ba90d6bfe586bfe626df44b62338e38ee83f05081aeb0148663962acf153a7","schema_fingerprint":"4aa3821a28b0b7c2400bc59aba4bcc0a76e971dadd19610d3ad38c768e124dc7","schema_version":"edge-lab-recorder.raw.v1","sequence":null,"source":"clob_market_ws"}
