{"event_at":"2026-07-27T04:30:26.519000Z","event_fingerprint":"8fa15cb89af0fb93f6cb7272ea3cc457d99cbd720cb4f134551dc3619400bbb1","payload":{"connection_id":"0f4979d6978d463e9660b042fdcf555f","event_at":"2026-07-27T04:30:26.519000Z","event_type":"price_change","frame_hash":"1403dac83d584e3b3c93cd2c2030417f1642401cf3baa1d5b0996b687032b4af","frame_index":0,"kind":"data","monotonic_ns":228611188643916,"payload":{"event_type":"price_change","market":"0xeb66215f2e9faa6449e30a02bab5b8ed7b79a38bf961f6b24d0073c9c2419250","price_changes":[{"asset_id":"60386828328910021732068595344565885737045900010034836345809386672230885527307","best_ask":"0.6","best_bid":"0.59","hash":"7f3d3518dffc9e46a60ebb7b4953184344b0ed2d","price":"0.45","side":"BUY","size":"68"},{"asset_id":"69697746896130839564035629862476347944307040470122503199396727085502753297492","best_ask":"0.41","best_bid":"0.4","hash":"50faac55089991fbe4eb64ee319e5206478d47fe","price":"0.55","side":"SELL","size":"68"}],"timestamp":"1785126626519"},"payload_hash":"87deeb5216270fb087b845cea8d9c648ee3e01678038c7adf05d1e473e4a8399","raw_frame":"{\"market\":\"0xeb66215f2e9faa6449e30a02bab5b8ed7b79a38bf961f6b24d0073c9c2419250\", \"price_changes\":[{\"asset_id\":\"60386828328910021732068595344565885737045900010034836345809386672230885527307\", \"price\":\"0.45\", \"size\":\"68\", \"side\":\"BUY\", \"hash\":\"7f3d3518dffc9e46a60ebb7b4953184344b0ed2d\", \"best_bid\":\"0.59\", \"best_ask\":\"0.6\"}, {\"asset_id\":\"69697746896130839564035629862476347944307040470122503199396727085502753297492\", \"price\":\"0.55\", \"size\":\"68\", \"side\":\"SELL\", \"hash\":\"50faac55089991fbe4eb64ee319e5206478d47fe\", \"best_bid\":\"0.4\", \"best_ask\":\"0.41\"}], \"timestamp\":\"1785126626519\", \"event_type\":\"price_change\"}","received_at":"2026-07-27T04:30:27.919049Z","schema_version":"clob-market-ws.price_change.v1","sequence":null,"server_hash":null,"server_timestamp":"1785126626519","session_id":"e9443c7415a0419799bee9cfbb1a9e4d","source":"clob_market_ws"},"received_at":"2026-07-27T04:30:27.919049Z","record_id":"a85ffe08c67f814d1138f0c9be638d594956058e30a03352a0c3ac5c632a4acb","schema_fingerprint":"4aa3821a28b0b7c2400bc59aba4bcc0a76e971dadd19610d3ad38c768e124dc7","schema_version":"edge-lab-recorder.raw.v1","sequence":null,"source":"clob_market_ws"}
{"event_at":"2026-07-27T04:30:26.519000Z","event_fingerprint":"303a7626886dc41324013e5c47777456849df275c4c143a51181203f3e48565d","payload":{"connection_id":"0f4979d6978d463e9660b042fdcf555f","event_at":"2026-07-27T04:30:26.519000Z","event_type":"price_change","frame_hash":"f5e8e2c21d826d952edfb9dfd82b55fae67dae7e8937dc7f3c2e65ebc7b65e87","frame_index":0,"kind":"data","monotonic_ns":228611220716791,"payload":{"event_type":"price_change","market":"0xeb66215f2e9faa6449e30a02bab5b8ed7b79a38bf961f6b24d0073c9c2419250","price_changes":[{"asset_id":"69697746896130839564035629862476347944307040470122503199396727085502753297492","best_ask":"0.41","best_bid":"0.4","hash":"64134fad71f2536a4306b5198c5ce10a171b87d8","price":"0.38","side":"BUY","size":"21"},{"asset_id":"60386828328910021732068595344565885737045900010034836345809386672230885527307","best_ask":"0.6","best_bid":"0.59","hash":"acf30f982d88b43e2a4a559b1c6d43c1b304b9c4","price":"0.62","side":"SELL","size":"21"}],"timestamp":"1785126626519"},"payload_hash":"f15628ebf2ca6e91304583c382c81a45edc0ebc75c0fa2ba12533db35a5097c1","raw_frame":"{\"market\":\"0xeb66215f2e9faa6449e30a02bab5b8ed7b79a38bf961f6b24d0073c9c2419250\", \"price_changes\":[{\"asset_id\":\"69697746896130839564035629862476347944307040470122503199396727085502753297492\", \"price\":\"0.38\", \"size\":\"21\", \"side\":\"BUY\", \"hash\":\"64134fad71f2536a4306b5198c5ce10a171b87d8\", \"best_bid\":\"0.4\", \"best_ask\":\"0.41\"}, {\"asset_id\":\"60386828328910021732068595344565885737045900010034836345809386672230885527307\", \"price\":\"0.62\", \"size\":\"21\", \"side\":\"SELL\", \"hash\":\"acf30f982d88b43e2a4a559b1c6d43c1b304b9c4\", \"best_bid\":\"0.59\", \"best_ask\":\"0.6\"}], \"timestamp\":\"1785126626519\", \"event_type\":\"price_change\"}","received_at":"2026-07-27T04:30:27.951121Z","schema_version":"clob-market-ws.price_change.v1","sequence":null,"server_hash":null,"server_timestamp":"1785126626519","session_id":"e9443c7415a0419799bee9cfbb1a9e4d","source":"clob_market_ws"},"received_at":"2026-07-27T04:30:27.951121Z","record_id":"c42fab987fbf06ab8d6cdbf0ab81d6649661efb0db46f13a5dc62cd664413dd4","schema_fingerprint":"4aa3821a28b0b7c2400bc59aba4bcc0a76e971dadd19610d3ad38c768e124dc7","schema_version":"edge-lab-recorder.raw.v1","sequence":null,"source":"clob_market_ws"}
{"event_at":"2026-07-27T04:30:26.524000Z","event_fingerprint":"6d0479131aca3896f0b7df104a353ba227769b77170b2fd7290d22230fafa43a","payload":{"connection_id":"0f4979d6978d463e9660b042fdcf555f","event_at":"2026-07-27T04:30:26.524000Z","event_type":"price_change","frame_hash":"b686b3f2ec62b04b16192e5ea51bdfbfe5c9716975278b3caa1f6b90797b65a5","frame_index":0,"kind":"data","monotonic_ns":228611234291583,"payload":{"event_type":"price_change","market":"0xeb66215f2e9faa6449e30a02bab5b8ed7b79a38bf961f6b24d0073c9c2419250","price_changes":[{"asset_id":"69697746896130839564035629862476347944307040470122503199396727085502753297492","best_ask":"0.41","best_bid":"0.4","hash":"b8cebc8b84155cf92fb8e72270ef71492879d0ac","price":"0.22","side":"BUY","size":"37"},{"asset_id":"60386828328910021732068595344565885737045900010034836345809386672230885527307","best_ask":"0.6","best_bid":"0.59","hash":"ee9bfcea624045f743c19d67d07675a0d1687de7","price":"0.78","side":"SELL","size":"37"}],"timestamp":"1785126626524"},"payload_hash":"2df1f167ff3f8081d1f3006f934cdaf7c8b50cb5ec1914cceb6de84cfc881d94","raw_frame":"{\"market\":\"0xeb66215f2e9faa6449e30a02bab5b8ed7b79a38bf961f6b24d0073c9c2419250\", \"price_changes\":[{\"asset_id\":\"69697746896130839564035629862476347944307040470122503199396727085502753297492\", \"price\":\"0.22\", \"size\":\"37\", \"side\":\"BUY\", \"hash\":\"b8cebc8b84155cf92fb8e72270ef71492879d0ac\", \"best_bid\":\"0.4\", \"best_ask\":\"0.41\"}, {\"asset_id\":\"60386828328910021732068595344565885737045900010034836345809386672230885527307\", \"price\":\"0.78\", \"size\":\"37\", \"side\":\"SELL\", \"hash\":\"ee9bfcea624045f743c19d67d07675a0d1687de7\", \"best_bid\":\"0.59\", \"best_ask\":\"0.6\"}], \"timestamp\":\"1785126626524\", \"event_type\":\"price_change\"}","received_at":"2026-07-27T04:30:27.964697Z","schema_version":"clob-market-ws.price_change.v1","sequence":null,"server_hash":null,"server_timestamp":"1785126626524","session_id":"e9443c7415a0419799bee9cfbb1a9e4d","source":"clob_market_ws"},"received_at":"2026-07-27T04:30:27.964697Z","record_id":"fa4b561e63bbec1728ca28929e379fb0ba1ceeb50579c81adfce49c812e044af","schema_fingerprint":"4aa3821a28b0b7c2400bc59aba4bcc0a76e971dadd19610d3ad38c768e124dc7","schema_version":"edge-lab-recorder.raw.v1","sequence":null,"source":"clob_market_ws"}
{"event_at":"2026-07-27T04:30:26.525000Z","event_fingerprint":"f66b479b9070bdbdf257c56967ecc21f15e4846ca6b79ed0f8515a6429bfdf85","payload":{"connection_id":"0f4979d6978d463e9660b042fdcf555f","event_at":"2026-07-27T04:30:26.525000Z","event_type":"price_change","frame_hash":"910c5a9591b95f8dcb38477d714600fb821f8f441ff395fee2e665850fe17ff8","frame_index":0,"kind":"data","monotonic_ns":228611245598416,"payload":{"event_type":"price_change","market":"0xeb66215f2e9faa6449e30a02bab5b8ed7b79a38bf961f6b24d0073c9c2419250","price_changes":[{"asset_id":"60386828328910021732068595344565885737045900010034836345809386672230885527307","best_ask":"0.6","best_bid":"0.59","hash":"295cdadc21abbc4bda226f2301489e12c9e1bc14","price":"0.54","side":"BUY","size":"256.64"},{"asset_id":"69697746896130839564035629862476347944307040470122503199396727085502753297492","best_ask":"0.41","best_bid":"0.4","hash":"dbebe669d1ea1bc3b3e9bcda2de273b3413d631a","price":"0.46","side":"SELL","size":"256.64"}],"timestamp":"1785126626525"},"payload_hash":"869a0d692d51bde89f32c2a18dde16012362ae3cc0dfa06a3ce9e9991f90fa62","raw_frame":"{\"market\":\"0xeb66215f2e9faa6449e30a02bab5b8ed7b79a38bf961f6b24d0073c9c2419250\", \"price_changes\":[{\"asset_id\":\"60386828328910021732068595344565885737045900010034836345809386672230885527307\", \"price\":\"0.54\", \"size\":\"256.64\", \"side\":\"BUY\", \"hash\":\"295cdadc21abbc4bda226f2301489e12c9e1bc14\", \"best_bid\":\"0.59\", \"best_ask\":\"0.6\"}, {\"asset_id\":\"69697746896130839564035629862476347944307040470122503199396727085502753297492\", \"price\":\"0.46\", \"size\":\"256.64\", \"side\":\"SELL\", \"hash\":\"dbebe669d1ea1bc3b3e9bcda2de273b3413d631a\", \"best_bid\":\"0.4\", \"best_ask\":\"0.41\"}], \"timestamp\":\"1785126626525\", \"event_type\":\"price_change\"}","received_at":"2026-07-27T04:30:27.976004Z","schema_version":"clob-market-ws.price_change.v1","sequence":null,"server_hash":null,"server_timestamp":"1785126626525","session_id":"e9443c7415a0419799bee9cfbb1a9e4d","source":"clob_market_ws"},"received_at":"2026-07-27T04:30:27.976004Z","record_id":"d908cadb3d7bdf5462b6f7ae862f30be12c3ae559abf6e313981f770ea35909d","schema_fingerprint":"4aa3821a28b0b7c2400bc59aba4bcc0a76e971dadd19610d3ad38c768e124dc7","schema_version":"edge-lab-recorder.raw.v1","sequence":null,"source":"clob_market_ws"}
{"event_at":"2026-07-27T04:30:26.533000Z","event_fingerprint":"e14d8ae874057491667cb01289d6c9ad3f0686ead1d88860716c093cd9512c96","payload":{"connection_id":"0f4979d6978d463e9660b042fdcf555f","event_at":"2026-07-27T04:30:26.533000Z","event_type":"last_trade_price","frame_hash":"a4cbb56e37eeab5eadc5d0cde73cbd29dc8d4530f18b00a26c9d799f11fb1d27","frame_index":0,"kind":"data","monotonic_ns":228611256073500,"payload":{"asset_id":"60386828328910021732068595344565885737045900010034836345809386672230885527307","event_type":"last_trade_price","fee_rate_bps":"0","market":"0xeb66215f2e9faa6449e30a02bab5b8ed7b79a38bf961f6b24d0073c9c2419250","price":"0.6","side":"BUY","size":"3.5","timestamp":"1785126626533","transaction_hash":"0xc8e6f4106774fccc346d93adafa2a62532289af9fb8ef6142f9ad1e6a2c70ee8"},"payload_hash":"d73c5318976232e50a4fc8189f9d5dfaa92985be55f2269cfe53b183a95ef36c","raw_frame":"{\"market\":\"0xeb66215f2e9faa6449e30a02bab5b8ed7b79a38bf961f6b24d0073c9c2419250\", \"asset_id\":\"60386828328910021732068595344565885737045900010034836345809386672230885527307\", \"price\":\"0.6\", \"size\":\"3.5\", \"fee_rate_bps\":\"0\", \"side\":\"BUY\", \"timestamp\":\"1785126626533\", \"event_type\":\"last_trade_price\", \"transaction_hash\":\"0xc8e6f4106774fccc346d93adafa2a62532289af9fb8ef6142f9ad1e6a2c70ee8\"}","received_at":"2026-07-27T04:30:27.986475Z","schema_version":"clob-market-ws.last_trade_price.v1","sequence":null,"server_hash":null,"server_timestamp":"1785126626533","session_id":"e9443c7415a0419799bee9cfbb1a9e4d","source":"clob_market_ws"},"received_at":"2026-07-27T04:30:27.986475Z","record_id":"84f72a840b6b6ae788073c2253ec5910a1874772527f4e53c4e6aeed631f439b","schema_fingerprint":"95ad9be75a4b695cd99991e12b2592bc7346f3f5388a82d0000ba65bc0d9fd0a","schema_version":"edge-lab-recorder.raw.v1","sequence":null,"source":"clob_market_ws"}
{"event_at":"2026-07-27T04:30:26.546000Z","event_fingerprint":"e3434abb5474890b9d64813b229a6d43a0cf499eed77713e418ac8c5170d91d5","payload":{"connection_id":"0f4979d6978d463e9660b042fdcf555f","event_at":"2026-07-27T04:30:26.546000Z","event_type":"price_change","frame_hash":"884e5f32b021948ee1f77787055e84fe156e4199fbad19bb55d7657cab2acf45","frame_index":0,"kind":"data","monotonic_ns":228611264668083,"payload":{"event_type":"price_change","market":"0xeb66215f2e9faa6449e30a02bab5b8ed7b79a38bf961f6b24d0073c9c2419250","price_changes":[{"asset_id":"60386828328910021732068595344565885737045900010034836345809386672230885527307","best_ask":"0.6","best_bid":"0.59","hash":"ea869ecef423b2fe8c7c14180e25eef0737057fb","price":"0.47","side":"BUY","size":"81.92"},{"asset_id":"69697746896130839564035629862476347944307040470122503199396727085502753297492","best_ask":"0.41","best_bid":"0.4","hash":"9d557c5d7577155bb940d44db60c85b7cd54ab3c","price":"0.53","side":"SELL","size":"81.92"}],"timestamp":"1785126626546"},"payload_hash":"2b56b2d49f190de5f265eb514af8c1755f1b253d01910f63ba4514d612ec9760","raw_frame":"{\"market\":\"0xeb66215f2e9faa6449e30a02bab5b8ed7b79a38bf961f6b24d0073c9c2419250\", \"price_changes\":[{\"asset_id\":\"60386828328910021732068595344565885737045900010034836345809386672230885527307\", \"price\":\"0.47\", \"size\":\"81.92\", \"side\":\"BUY\", \"hash\":\"ea869ecef423b2fe8c7c14180e25eef0737057fb\", \"best_bid\":\"0.59\", \"best_ask\":\"0.6\"}, {\"asset_id\":\"69697746896130839564035629862476347944307040470122503199396727085502753297492\", \"price\":\"0.53\", \"size\":\"81.92\", \"side\":\"SELL\", \"hash\":\"9d557c5d7577155bb940d44db60c85b7cd54ab3c\", \"best_bid\":\"0.4\", \"best_ask\":\"0.41\"}], \"timestamp\":\"1785126626546\", \"event_type\":\"price_change\"}","received_at":"2026-07-27T04:30:27.995069Z","schema_version":"clob-market-ws.price_change.v1","sequence":null,"server_hash":null,"server_timestamp":"1785126626546","session_id":"e9443c7415a0419799bee9cfbb1a9e4d","source":"clob_market_ws"},"received_at":"2026-07-27T04:30:27.995069Z","record_id":"8bdeab884dcb8c0ef89c26442cc44881b496fbb1d2dac5cc6849aa89e0ed93ef","schema_fingerprint":"4aa3821a28b0b7c2400bc59aba4bcc0a76e971dadd19610d3ad38c768e124dc7","schema_version":"edge-lab-recorder.raw.v1","sequence":null,"source":"clob_market_ws"}
{"event_at":"2026-07-27T04:30:26.553000Z","event_fingerprint":"16785091b724840087ff6d13d52affe2e851eb87bb1036b5885bd4f3a0164823","payload":{"connection_id":"0f4979d6978d463e9660b042fdcf555f","event_at":"2026-07-27T04:30:26.553000Z","event_type":"price_change","frame_hash":"b46c44fd9b5ef681ef723cbb9c4f7a8b17cab9fd504700906263a00ac77b21dc","frame_index":0,"kind":"data","monotonic_ns":228611277354375,"payload":{"event_type":"price_change","market":"0xeb66215f2e9faa6449e30a02bab5b8ed7b79a38bf961f6b24d0073c9c2419250","price_changes":[{"asset_id":"60386828328910021732068595344565885737045900010034836345809386672230885527307","best_ask":"0.6","best_bid":"0.59","hash":"bdf57d6ef4927a734e799a3901da3abda5eb34fc","price":"0.05","side":"BUY","size":"858.2"},{"asset_id":"69697746896130839564035629862476347944307040470122503199396727085502753297492","best_ask":"0.41","best_bid":"0.4","hash":"a00f71253c019f8d85dab88ccda89ec20473ef43","price":"0.95","side":"SELL","size":"858.2"}],"timestamp":"1785126626553"},"payload_hash":"58aacf5898ef892809582ef21e231749b41ca95f43a06c9d3e70d6b36e3f2225","raw_frame":"{\"market\":\"0xeb66215f2e9faa6449e30a02bab5b8ed7b79a38bf961f6b24d0073c9c2419250\", \"price_changes\":[{\"asset_id\":\"60386828328910021732068595344565885737045900010034836345809386672230885527307\", \"price\":\"0.05\", \"size\":\"858.2\", \"side\":\"BUY\", \"hash\":\"bdf57d6ef4927a734e799a3901da3abda5eb34fc\", \"best_bid\":\"0.59\", \"best_ask\":\"0.6\"}, {\"asset_id\":\"69697746896130839564035629862476347944307040470122503199396727085502753297492\", \"price\":\"0.95\", \"size\":\"858.2\", \"side\":\"SELL\", \"hash\":\"a00f71253c019f8d85dab88ccda89ec20473ef43\", \"best_bid\":\"0.4\", \"best_ask\":\"0.41\"}], \"timestamp\":\"1785126626553\", \"event_type\":\"price_change\"}","received_at":"2026-07-27T04:30:28.007760Z","schema_version":"clob-market-ws.price_change.v1","sequence":null,"server_hash":null,"server_timestamp":"1785126626553","session_id":"e9443c7415a0419799bee9cfbb1a9e4d","source":"clob_market_ws"},"received_at":"2026-07-27T04:30:28.007760Z","record_id":"f16f5ec43a6fc2ad37a050fe99e941722524561497bcdaa75a84e13ca03e9967","schema_fingerprint":"4aa3821a28b0b7c2400bc59aba4bcc0a76e971dadd19610d3ad38c768e124dc7","schema_version":"edge-lab-recorder.raw.v1","sequence":null,"source":"clob_market_ws"}
{"event_at":"2026-07-27T04:30:26.564000Z","event_fingerprint":"1ce0d6bab2ff3d3f19996b4c92af06f7ee84fff95a5b54b770af7fffc7752ca1","payload":{"connection_id":"0f4979d6978d463e9660b042fdcf555f","event_at":"2026-07-27T04:30:26.564000Z","event_type":"price_change","frame_hash":"3ce49d69734b9f235e25544faafac7d81de1819699ec1c7f56f20a6b1872d83b","frame_index":0,"kind":"data","monotonic_ns":228611289939791,"payload":{"event_type":"price_change","market":"0xeb66215f2e9faa6449e30a02bab5b8ed7b79a38bf961f6b24d0073c9c2419250","price_changes":[{"asset_id":"69697746896130839564035629862476347944307040470122503199396727085502753297492","best_ask":"0.41","best_bid":"0.4","hash":"da73761ec64d8cd4f2b7d326b0e6cd860db97da9","price":"0.42","side":"SELL","size":"136.01"},{"asset_id":"60386828328910021732068595344565885737045900010034836345809386672230885527307","best_ask":"0.6","best_bid":"0.59","hash":"6434afb7c11a4c3f2c05f5a8667ee1ef815ab904","price":"0.58","side":"BUY","size":"136.01"}],"timestamp":"1785126626564"},"payload_hash":"d00ca5bdacc28a5123e1ca7ab3de88702a5dc40ae9f7be8d04ee58e49f3971e3","raw_frame":"{\"market\":\"0xeb66215f2e9faa6449e30a02bab5b8ed7b79a38bf961f6b24d0073c9c2419250\", \"price_changes\":[{\"asset_id\":\"69697746896130839564035629862476347944307040470122503199396727085502753297492\", \"price\":\"0.42\", \"size\":\"136.01\", \"side\":\"SELL\", \"hash\":\"da73761ec64d8cd4f2b7d326b0e6cd860db97da9\", \"best_bid\":\"0.4\", \"best_ask\":\"0.41\"}, {\"asset_id\":\"60386828328910021732068595344565885737045900010034836345809386672230885527307\", \"price\":\"0.58\", \"size\":\"136.01\", \"side\":\"BUY\", \"hash\":\"6434afb7c11a4c3f2c05f5a8667ee1ef815ab904\", \"best_bid\":\"0.59\", \"best_ask\":\"0.6\"}], \"timestamp\":\"1785126626564\", \"event_type\":\"price_change\"}","received_at":"2026-07-27T04:30:28.020347Z","schema_version":"clob-market-ws.price_change.v1","sequence":null,"server_hash":null,"server_timestamp":"1785126626564","session_id":"e9443c7415a0419799bee9cfbb1a9e4d","source":"clob_market_ws"},"received_at":"2026-07-27T04:30:28.020347Z","record_id":"baf6bdf044c2d5542356420f3dc4c912974e38362a2d6ca6d9ac56d7a0f7a2fb","schema_fingerprint":"4aa3821a28b0b7c2400bc59aba4bcc0a76e971dadd19610d3ad38c768e124dc7","schema_version":"edge-lab-recorder.raw.v1","sequence":null,"source":"clob_market_ws"}
{"event_at":"2026-07-27T04:30:26.564000Z","event_fingerprint":"d7b1dad172af3a716124d9aeed6e640c96084d1941dd3f3d17e0a89460011189","payload":{"connection_id":"0f4979d6978d463e9660b042fdcf555f","event_at":"2026-07-27T04:30:26.564000Z","event_type":"price_change","frame_hash":"3654ce71f91c834c8c2ce775b4a6915471e24200d65416a06d904d8b58c8be30","frame_index":0,"kind":"data","monotonic_ns":228611298438000,"payload":{"event_type":"price_change","market":"0xeb66215f2e9faa6449e30a02bab5b8ed7b79a38bf961f6b24d0073c9c2419250","price_changes":[{"asset_id":"60386828328910021732068595344565885737045900010034836345809386672230885527307","best_ask":"0.6","best_bid":"0.59","hash":"37120d6913c619578907c6bf9fb9757a38925b74","price":"0.03","side":"BUY","size":"1063.1"},{"asset_id":"69697746896130839564035629862476347944307040470122503199396727085502753297492","best_ask":"0.41","best_bid":"0.4","hash":"1ce756e2ae87459e4737f038adf0cea8a5716c5d","price":"0.97","side":"SELL","size":"1063.1"}],"timestamp":"1785126626564"},"payload_hash":"5a500c7a50f100e0297117083ba2f002b34aae8e17c4fc09d8616843dfe7da3f","raw_frame":"{\"market\":\"0xeb66215f2e9faa6449e30a02bab5b8ed7b79a38bf961f6b24d0073c9c2419250\", \"price_changes\":[{\"asset_id\":\"60386828328910021732068595344565885737045900010034836345809386672230885527307\", \"price\":\"0.03\", \"size\":\"1063.1\", \"side\":\"BUY\", \"hash\":\"37120d6913c619578907c6bf9fb9757a38925b74\", \"best_bid\":\"0.59\", \"best_ask\":\"0.6\"}, {\"asset_id\":\"69697746896130839564035629862476347944307040470122503199396727085502753297492\", \"price\":\"0.97\", \"size\":\"1063.1\", \"side\":\"SELL\", \"hash\":\"1ce756e2ae87459e4737f038adf0cea8a5716c5d\", \"best_bid\":\"0.4\", \"best_ask\":\"0.41\"}], \"timestamp\":\"1785126626564\", \"event_type\":\"price_change\"}","received_at":"2026-07-27T04:30:28.028849Z","schema_version":"clob-market-ws.price_change.v1","sequence":null,"server_hash":null,"server_timestamp":"1785126626564","session_id":"e9443c7415a0419799bee9cfbb1a9e4d","source":"clob_market_ws"},"received_at":"2026-07-27T04:30:28.028849Z","record_id":"c8c00481417a41246e6ffbfc3636a0c52bc9a7a56e9cf6069efc6db2676d8e73","schema_fingerprint":"4aa3821a28b0b7c2400bc59aba4bcc0a76e971dadd19610d3ad38c768e124dc7","schema_version":"edge-lab-recorder.raw.v1","sequence":null,"source":"clob_market_ws"}
{"event_at":"2026-07-27T04:30:26.565000Z","event_fingerprint":"6723f1a59e1274a3b3169a8d39e21049723ec828c3cee3dc677ac9688df065b0","payload":{"connection_id":"0f4979d6978d463e9660b042fdcf555f","event_at":"2026-07-27T04:30:26.565000Z","event_type":"price_change","frame_hash":"333626d2d8d8e3be77e44a6134fecfc858bc3704db5ef0e430cab167e8bba20c","frame_index":0,"kind":"data","monotonic_ns":228611310329208,"payload":{"event_type":"price_change","market":"0xeb66215f2e9faa6449e30a02bab5b8ed7b79a38bf961f6b24d0073c9c2419250","price_changes":[{"asset_id":"60386828328910021732068595344565885737045900010034836345809386672230885527307","best_ask":"0.6","best_bid":"0.59","hash":"034db21144a7f0faf246a0775d5992d50e634098","price":"0.59","side":"BUY","size":"143.42"},{"asset_id":"69697746896130839564035629862476347944307040470122503199396727085502753297492","best_ask":"0.41","best_bid":"0.4","hash":"04f4fcc3ea5b5f05a35856f0022e9beda4d78a99","price":"0.41","side":"SELL","size":"143.42"}],"timestamp":"1785126626565"},"payload_hash":"82c322aa5d72383e2b1e4b4ae1c858b1f32d1cd2051f3369bf513ee290bdcb33","raw_frame":"{\"market\":\"0xeb66215f2e9faa6449e30a02bab5b8ed7b79a38bf961f6b24d0073c9c2419250\", \"price_changes\":[{\"asset_id\":\"60386828328910021732068595344565885737045900010034836345809386672230885527307\", \"price\":\"0.59\", \"size\":\"143.42\", \"side\":\"BUY\", \"hash\":\"034db21144a7f0faf246a0775d5992d50e634098\", \"best_bid\":\"0.59\", \"best_ask\":\"0.6\"}, {\"asset_id\":\"69697746896130839564035629862476347944307040470122503199396727085502753297492\", \"price\":\"0.41\", \"size\":\"143.42\", \"side\":\"SELL\", \"hash\":\"04f4fcc3ea5b5f05a35856f0022e9beda4d78a99\", \"best_bid\":\"0.4\", \"best_ask\":\"0.41\"}], \"timestamp\":\"1785126626565\", \"event_type\":\"price_change\"}","received_at":"2026-07-27T04:30:28.040734Z","schema_version":"clob-market-ws.price_change.v1","sequence":null,"server_hash":null,"server_timestamp":"1785126626565","session_id":"e9443c7415a0419799bee9cfbb1a9e4d","source":"clob_market_ws"},"received_at":"2026-07-27T04:30:28.040734Z","record_id":"1faa5ab8b13bf737a9cfd0377553c99dfdd6ebe71784b441099c33b9028b893f","schema_fingerprint":"4aa3821a28b0b7c2400bc59aba4bcc0a76e971dadd19610d3ad38c768e124dc7","schema_version":"edge-lab-recorder.raw.v1","sequence":null,"source":"clob_market_ws"}
{"event_at":"2026-07-27T04:30:26.566000Z","event_fingerprint":"fc6a83c878bd995583d6e8658c07b60ed7fd2f089dfc9a0f2c1faa0418d48685","payload":{"connection_id":"0f4979d6978d463e9660b042fdcf555f","event_at":"2026-07-27T04:30:26.566000Z","event_type":"price_change","frame_hash":"01a60af209e0d5703912e8f66bde04cda9b76cec82d10db99c2ff03ca28d94a1","frame_index":0,"kind":"data","monotonic_ns":228611315822333,"payload":{"event_type":"price_change","market":"0xeb66215f2e9faa6449e30a02bab5b8ed7b79a38bf961f6b24d0073c9c2419250","price_changes":[{"asset_id":"60386828328910021732068595344565885737045900010034836345809386672230885527307","best_ask":"0.6","best_bid":"0.59","hash":"e88432d6db509a60cdb45aebbaa4ace9387d11dc","price":"0.58","side":"BUY","size":"40.01"},{"asset_id":"69697746896130839564035629862476347944307040470122503199396727085502753297492","best_ask":"0.41","best_bid":"0.4","hash":"06a59014985f418a5864ca45f8164dd9d09d1b4a","price":"0.42","side":"SELL","size":"40.01"}],"timestamp":"1785126626566"},"payload_hash":"eed7037e8fc2c3fe4021df5c8c396cad9f3d6a2ffbcf8652bf1ceda3a6fdefc6","raw_frame":"{\"market\":\"0xeb66215f2e9faa6449e30a02bab5b8ed7b79a38bf961f6b24d0073c9c2419250\", \"price_changes\":[{\"asset_id\":\"60386828328910021732068595344565885737045900010034836345809386672230885527307\", \"price\":\"0.58\", \"size\":\"40.01\", \"side\":\"BUY\", \"hash\":\"e88432d6db509a60cdb45aebbaa4ace9387d11dc\", \"best_bid\":\"0.59\", \"best_ask\":\"0.6\"}, {\"asset_id\":\"69697746896130839564035629862476347944307040470122503199396727085502753297492\", \"price\":\"0.42\", \"size\":\"40.01\", \"side\":\"SELL\", \"hash\":\"06a59014985f418a5864ca45f8164dd9d09d1b4a\", \"best_bid\":\"0.4\", \"best_ask\":\"0.41\"}], \"timestamp\":\"1785126626566\", \"event_type\":\"price_change\"}","received_at":"2026-07-27T04:30:28.046229Z","schema_version":"clob-market-ws.price_change.v1","sequence":null,"server_hash":null,"server_timestamp":"1785126626566","session_id":"e9443c7415a0419799bee9cfbb1a9e4d","source":"clob_market_ws"},"received_at":"2026-07-27T04:30:28.046229Z","record_id":"f9c2e13b58c33bd39040f0392db284688fdc61ab3a5104f923c2c4d08eadfdb9","schema_fingerprint":"4aa3821a28b0b7c2400bc59aba4bcc0a76e971dadd19610d3ad38c768e124dc7","schema_version":"edge-lab-recorder.raw.v1","sequence":null,"source":"clob_market_ws"}
{"event_at":"2026-07-27T04:30:26.567000Z","event_fingerprint":"e147143b59a6d141606397d9d2195b8d1458b474c85bdc1b03578f61f52b2da6","payload":{"connection_id":"0f4979d6978d463e9660b042fdcf555f","event_at":"2026-07-27T04:30:26.567000Z","event_type":"price_change","frame_hash":"69f01244412bf0b5363dd388191040aceeb6dee05f4e35a58008435119dadec2","frame_index":0,"kind":"data","monotonic_ns":228611319868041,"payload":{"event_type":"price_change","market":"0xeb66215f2e9faa6449e30a02bab5b8ed7b79a38bf961f6b24d0073c9c2419250","price_changes":[{"asset_id":"60386828328910021732068595344565885737045900010034836345809386672230885527307","best_ask":"0.6","best_bid":"0.59","hash":"ecbdfec7756f7f3b9a5b5fa9d7c9281b701d1719","price":"0.58","side":"BUY","size":"45.01"},{"asset_id":"69697746896130839564035629862476347944307040470122503199396727085502753297492","best_ask":"0.41","best_bid":"0.4","hash":"bfae08406583445278466ad6842450b54fb3181a","price":"0.42","side":"SELL","size":"45.01"}],"timestamp":"1785126626567"},"payload_hash":"4b80b2bfcbf3285e5cce52537b48586027616bb611798615d48158b82e9b98a4","raw_frame":"{\"market\":\"0xeb66215f2e9faa6449e30a02bab5b8ed7b79a38bf961f6b24d0073c9c2419250\", \"price_changes\":[{\"asset_id\":\"60386828328910021732068595344565885737045900010034836345809386672230885527307\", \"price\":\"0.58\", \"size\":\"45.01\", \"side\":\"BUY\", \"hash\":\"ecbdfec7756f7f3b9a5b5fa9d7c9281b701d1719\", \"best_bid\":\"0.59\", \"best_ask\":\"0.6\"}, {\"asset_id\":\"69697746896130839564035629862476347944307040470122503199396727085502753297492\", \"price\":\"0.42\", \"size\":\"45.01\", \"side\":\"SELL\", \"hash\":\"bfae08406583445278466ad6842450b54fb3181a\", \"best_bid\":\"0.4\", \"best_ask\":\"0.41\"}], \"timestamp\":\"1785126626567\", \"event_type\":\"price_change\"}","received_at":"2026-07-27T04:30:28.050277Z","schema_version":"clob-market-ws.price_change.v1","sequence":null,"server_hash":null,"server_timestamp":"1785126626567","session_id":"e9443c7415a0419799bee9cfbb1a9e4d","source":"clob_market_ws"},"received_at":"2026-07-27T04:30:28.050277Z","record_id":"857f4282629484ad9931b5d25e6802021ef6447f3ae8dd96d94ebc20407a2767","schema_fingerprint":"4aa3821a28b0b7c2400bc59aba4bcc0a76e971dadd19610d3ad38c768e124dc7","schema_version":"edge-lab-recorder.raw.v1","sequence":null,"source":"clob_market_ws"}
{"event_at":"2026-07-27T04:30:26.579000Z","event_fingerprint":"6fbc61b722bafe1dd174fe4b1d809c6daf4f8c79fe0c6a3cd8cc9c2ca70fe1b3","payload":{"connection_id":"0f4979d6978d463e9660b042fdcf555f","event_at":"2026-07-27T04:30:26.579000Z","event_type":"price_change","frame_hash":"af1f44caa82d7c52f23b7701845bff27075f675fa0d5937380468dc6d8e4f82b","frame_index":0,"kind":"data","monotonic_ns":228611325643333,"payload":{"event_type":"price_change","market":"0xeb66215f2e9faa6449e30a02bab5b8ed7b79a38bf961f6b24d0073c9c2419250","price_changes":[{"asset_id":"60386828328910021732068595344565885737045900010034836345809386672230885527307","best_ask":"0.6","best_bid":"0.59","hash":"cdb8ff38266e6dc1327676aac2d1892ed06cd3e0","price":"0.46","side":"BUY","size":"21"},{"asset_id":"69697746896130839564035629862476347944307040470122503199396727085502753297492","best_ask":"0.41","best_bid":"0.4","hash":"09b2b8ab3507b5135d1209a5564ac67b12e03f8a","price":"0.54","side":"SELL","size":"21"}],"timestamp":"1785126626579"},"payload_hash":"f1ee3fe516faea85b332413db3bb76fc3a73d6eee78503239c59f04dd2bd2b86","raw_frame":"{\"market\":\"0xeb66215f2e9faa6449e30a02bab5b8ed7b79a38bf961f6b24d0073c9c2419250\", \"price_changes\":[{\"asset_id\":\"60386828328910021732068595344565885737045900010034836345809386672230885527307\", \"price\":\"0.46\", \"size\":\"21\", \"side\":\"BUY\", \"hash\":\"cdb8ff38266e6dc1327676aac2d1892ed06cd3e0\", \"best_bid\":\"0.59\", \"best_ask\":\"0.6\"}, {\"asset_id\":\"69697746896130839564035629862476347944307040470122503199396727085502753297492\", \"price\":\"0.54\", \"size\":\"21\", \"side\":\"SELL\", \"hash\":\"09b2b8ab3507b5135d1209a5564ac67b12e03f8a\", \"best_bid\":\"0.4\", \"best_ask\":\"0.41\"}], \"timestamp\":\"1785126626579\", \"event_type\":\"price_change\"}","received_at":"2026-07-27T04:30:28.056053Z","schema_version":"clob-market-ws.price_change.v1","sequence":null,"server_hash":null,"server_timestamp":"1785126626579","session_id":"e9443c7415a0419799bee9cfbb1a9e4d","source":"clob_market_ws"},"received_at":"2026-07-27T04:30:28.056053Z","record_id":"3075ec981f88cae02b14d9b3247b522d83e6d433431a0f300f64fd4051f4c600","schema_fingerprint":"4aa3821a28b0b7c2400bc59aba4bcc0a76e971dadd19610d3ad38c768e124dc7","schema_version":"edge-lab-recorder.raw.v1","sequence":null,"source":"clob_market_ws"}
{"event_at":"2026-07-27T04:30:26.585000Z","event_fingerprint":"91a5996089335252054cffaa99d63b4751a6a3367234da6540c5e52c16d56cf0","payload":{"connection_id":"0f4979d6978d463e9660b042fdcf555f","event_at":"2026-07-27T04:30:26.585000Z","event_type":"price_change","frame_hash":"ca8e9fdc869eef58c5465eaf13b8751e924ea39f7b0e0acd20d14ae982e40cd4","frame_index":0,"kind":"data","monotonic_ns":228611328889958,"payload":{"event_type":"price_change","market":"0xeb66215f2e9faa6449e30a02bab5b8ed7b79a38bf961f6b24d0073c9c2419250","price_changes":[{"asset_id":"69697746896130839564035629862476347944307040470122503199396727085502753297492","best_ask":"0.41","best_bid":"0.4","hash":"5156b909c838184fbc14f8e426694ac9ae255354","price":"0.21","side":"BUY","size":"15.83"},{"asset_id":"60386828328910021732068595344565885737045900010034836345809386672230885527307","best_ask":"0.6","best_bid":"0.59","hash":"e29bd8ce38828fd707d696bf8c75c816e1a8f98c","price":"0.79","side":"SELL","size":"15.83"}],"timestamp":"1785126626585"},"payload_hash":"b44c9faf8e003c391e1ac69c0e6a8b49c750bb7cdfe05404b7ce7d184950f678","raw_frame":"{\"market\":\"0xeb66215f2e9faa6449e30a02bab5b8ed7b79a38bf961f6b24d0073c9c2419250\", \"price_changes\":[{\"asset_id\":\"69697746896130839564035629862476347944307040470122503199396727085502753297492\", \"price\":\"0.21\", \"size\":\"15.83\", \"side\":\"BUY\", \"hash\":\"5156b909c838184fbc14f8e426694ac9ae255354\", \"best_bid\":\"0.4\", \"best_ask\":\"0.41\"}, {\"asset_id\":\"60386828328910021732068595344565885737045900010034836345809386672230885527307\", \"price\":\"0.79\", \"size\":\"15.83\", \"side\":\"SELL\", \"hash\":\"e29bd8ce38828fd707d696bf8c75c816e1a8f98c\", \"best_bid\":\"0.59\", \"best_ask\":\"0.6\"}], \"timestamp\":\"1785126626585\", \"event_type\":\"price_change\"}","received_at":"2026-07-27T04:30:28.059301Z","schema_version":"clob-market-ws.price_change.v1","sequence":null,"server_hash":null,"server_timestamp":"1785126626585","session_id":"e9443c7415a0419799bee9cfbb1a9e4d","source":"clob_market_ws"},"received_at":"2026-07-27T04:30:28.059301Z","record_id":"06a05752e3abaac7d5aa032c7918b967a3e40e8e1f0c7ccc8409387591a66990","schema_fingerprint":"4aa3821a28b0b7c2400bc59aba4bcc0a76e971dadd19610d3ad38c768e124dc7","schema_version":"edge-lab-recorder.raw.v1","sequence":null,"source":"clob_market_ws"}
{"event_at":"2026-07-27T04:30:26.609000Z","event_fingerprint":"e9e6ad8ec006765d31277fb1bf6765f6d651f926eeabf45866b6cfe2e3692ef7","payload":{"connection_id":"0f4979d6978d463e9660b042fdcf555f","event_at":"2026-07-27T04:30:26.609000Z","event_type":"price_change","frame_hash":"e012beba3defa63b1869a4b0d8daf526ae9ebbb8c21c2de3516646d469470bca","frame_index":0,"kind":"data","monotonic_ns":228611334637375,"payload":{"event_type":"price_change","market":"0xeb66215f2e9faa6449e30a02bab5b8ed7b79a38bf961f6b24d0073c9c2419250","price_changes":[{"asset_id":"69697746896130839564035629862476347944307040470122503199396727085502753297492","best_ask":"0.41","best_bid":"0.4","hash":"a177ae0536be26d45bc0d4fd5d6fa2f57cc5e7aa","price":"0.38","side":"BUY","size":"33.62"},{"asset_id":"60386828328910021732068595344565885737045900010034836345809386672230885527307","best_ask":"0.6","best_bid":"0.59","hash":"98c6cec8b0a8dd7af9804a9cf77e3e1ce90e58f8","price":"0.62","side":"SELL","size":"33.62"}],"timestamp":"1785126626609"},"payload_hash":"75f901be8022ab92060754e3113e1d83141e52bbb427c80d58bc50877760e7cc","raw_frame":"{\"market\":\"0xeb66215f2e9faa6449e30a02bab5b8ed7b79a38bf961f6b24d0073c9c2419250\", \"price_changes\":[{\"asset_id\":\"69697746896130839564035629862476347944307040470122503199396727085502753297492\", \"price\":\"0.38\", \"size\":\"33.62\", \"side\":\"BUY\", \"hash\":\"a177ae0536be26d45bc0d4fd5d6fa2f57cc5e7aa\", \"best_bid\":\"0.4\", \"best_ask\":\"0.41\"}, {\"asset_id\":\"60386828328910021732068595344565885737045900010034836345809386672230885527307\", \"price\":\"0.62\", \"size\":\"33.62\", \"side\":\"SELL\", \"hash\":\"98c6cec8b0a8dd7af9804a9cf77e3e1ce90e58f8\", \"best_bid\":\"0.59\", \"best_ask\":\"0.6\"}], \"timestamp\":\"1785126626609\", \"event_type\":\"price_change\"}","received_at":"2026-07-27T04:30:28.065047Z","schema_version":"clob-market-ws.price_change.v1","sequence":null,"server_hash":null,"server_timestamp":"1785126626609","session_id":"e9443c7415a0419799bee9cfbb1a9e4d","source":"clob_market_ws"},"received_at":"2026-07-27T04:30:28.065047Z","record_id":"e6ea6921958a24d82472444d9b2634bf40d522548ed3e795c08bbac4a6fb228f","schema_fingerprint":"4aa3821a28b0b7c2400bc59aba4bcc0a76e971dadd19610d3ad38c768e124dc7","schema_version":"edge-lab-recorder.raw.v1","sequence":null,"source":"clob_market_ws"}
{"event_at":"2026-07-27T04:30:26.609000Z","event_fingerprint":"d0319bdc40a94e1b6c1e89d1921de05c18f7f80592be47bd597797e1edece0fa","payload":{"connection_id":"0f4979d6978d463e9660b042fdcf555f","event_at":"2026-07-27T04:30:26.609000Z","event_type":"price_change","frame_hash":"6ee9f028cf98da21d7d7f7bd734d21891461997532835ae156ac118a238e763e","frame_index":0,"kind":"data","monotonic_ns":228611336694916,"payload":{"event_type":"price_change","market":"0xeb66215f2e9faa6449e30a02bab5b8ed7b79a38bf961f6b24d0073c9c2419250","price_changes":[{"asset_id":"69697746896130839564035629862476347944307040470122503199396727085502753297492","best_ask":"0.41","best_bid":"0.4","hash":"a518a0eaf3f89e737fb5b882dd8b822cdd36c32e","price":"0.35","side":"BUY","size":"32"},{"asset_id":"60386828328910021732068595344565885737045900010034836345809386672230885527307","best_ask":"0.6","best_bid":"0.59","hash":"958e89ecbf93babe98668a85ed743408dd9cce89","price":"0.65","side":"SELL","size":"32"}],"timestamp":"1785126626609"},"payload_hash":"7e63817c86c600d6270268e0a087bbcea9fda19688a24aba2427b8c222984dba","raw_frame":"{\"market\":\"0xeb66215f2e9faa6449e30a02bab5b8ed7b79a38bf961f6b24d0073c9c2419250\", \"price_changes\":[{\"asset_id\":\"69697746896130839564035629862476347944307040470122503199396727085502753297492\", \"price\":\"0.35\", \"size\":\"32\", \"side\":\"BUY\", \"hash\":\"a518a0eaf3f89e737fb5b882dd8b822cdd36c32e\", \"best_bid\":\"0.4\", \"best_ask\":\"0.41\"}, {\"asset_id\":\"60386828328910021732068595344565885737045900010034836345809386672230885527307\", \"price\":\"0.65\", \"size\":\"32\", \"side\":\"SELL\", \"hash\":\"958e89ecbf93babe98668a85ed743408dd9cce89\", \"best_bid\":\"0.59\", \"best_ask\":\"0.6\"}], \"timestamp\":\"1785126626609\", \"event_type\":\"price_change\"}","received_at":"2026-07-27T04:30:28.067107Z","schema_version":"clob-market-ws.price_change.v1","sequence":null,"server_hash":null,"server_timestamp":"1785126626609","session_id":"e9443c7415a0419799bee9cfbb1a9e4d","source":"clob_market_ws"},"received_at":"2026-07-27T04:30:28.067107Z","record_id":"d712ac73bbebb30c381d219c10c7fede3210368f33ed8fe6e62bbc3f47c75fc7","schema_fingerprint":"4aa3821a28b0b7c2400bc59aba4bcc0a76e971dadd19610d3ad38c768e124dc7","schema_version":"edge-lab-recorder.raw.v1","sequence":null,"source":"clob_market_ws"}
{"event_at":"2026-07-27T04:30:26.613000Z","event_fingerprint":"a588dd2936345f1501689f8b59574bae8b290d4f1c23530ec4d323f9acb7255b","payload":{"connection_id":"0f4979d6978d463e9660b042fdcf555f","event_at":"2026-07-27T04:30:26.613000Z","event_type":"price_change","frame_hash":"8fd449c33895a347f6f72959637122369f7fd483bed1ebd93c0f247c31c37c61","frame_index":0,"kind":"data","monotonic_ns":228611344043875,"payload":{"event_type":"price_change","market":"0xeb66215f2e9faa6449e30a02bab5b8ed7b79a38bf961f6b24d0073c9c2419250","price_changes":[{"asset_id":"60386828328910021732068595344565885737045900010034836345809386672230885527307","best_ask":"0.6","best_bid":"0.59","hash":"ef7e6bd3760a9afc6e6a1a5877250fb540f40eba","price":"0.45","side":"BUY","size":"73"},{"asset_id":"69697746896130839564035629862476347944307040470122503199396727085502753297492","best_ask":"0.41","best_bid":"0.4","hash":"04a07859f3dd1b4af7ddff39e6771765dda2a9e5","price":"0.55","side":"SELL","size":"73"}],"timestamp":"1785126626613"},"payload_hash":"9f3f0d906c7bc56800295a872ff50128dc15703faa90a9be1b3deed7db8c668d","raw_frame":"{\"market\":\"0xeb66215f2e9faa6449e30a02bab5b8ed7b79a38bf961f6b24d0073c9c2419250\", \"price_changes\":[{\"asset_id\":\"60386828328910021732068595344565885737045900010034836345809386672230885527307\", \"price\":\"0.45\", \"size\":\"73\", \"side\":\"BUY\", \"hash\":\"ef7e6bd3760a9afc6e6a1a5877250fb540f40eba\", \"best_bid\":\"0.59\", \"best_ask\":\"0.6\"}, {\"asset_id\":\"69697746896130839564035629862476347944307040470122503199396727085502753297492\", \"price\":\"0.55\", \"size\":\"73\", \"side\":\"SELL\", \"hash\":\"04a07859f3dd1b4af7ddff39e6771765dda2a9e5\", \"best_bid\":\"0.4\", \"best_ask\":\"0.41\"}], \"timestamp\":\"1785126626613\", \"event_type\":\"price_change\"}","received_at":"2026-07-27T04:30:28.074450Z","schema_version":"clob-market-ws.price_change.v1","sequence":null,"server_hash":null,"server_timestamp":"1785126626613","session_id":"e9443c7415a0419799bee9cfbb1a9e4d","source":"clob_market_ws"},"received_at":"2026-07-27T04:30:28.074450Z","record_id":"fa5cb7dc42b91e417c37213299979879fe9e1b0f1c61c5f5e4d2c5468bb0979a","schema_fingerprint":"4aa3821a28b0b7c2400bc59aba4bcc0a76e971dadd19610d3ad38c768e124dc7","schema_version":"edge-lab-recorder.raw.v1","sequence":null,"source":"clob_market_ws"}
{"event_at":"2026-07-27T04:30:26.666000Z","event_fingerprint":"1bdc8350fffe9f4f51aebcea716175947a64fca78a6fb4f840350cd3f7402aa1","payload":{"connection_id":"0f4979d6978d463e9660b042fdcf555f","event_at":"2026-07-27T04:30:26.666000Z","event_type":"price_change","frame_hash":"a5408949ff31cbf8cde80f1e54a57a2d8115a61f557870b3c2f4aff262cddbd1","frame_index":0,"kind":"data","monotonic_ns":228611352643000,"payload":{"event_type":"price_change","market":"0xeb66215f2e9faa6449e30a02bab5b8ed7b79a38bf961f6b24d0073c9c2419250","price_changes":[{"asset_id":"69697746896130839564035629862476347944307040470122503199396727085502753297492","best_ask":"0.41","best_bid":"0.4","hash":"92556038b01ab202fcb2b354f040a6ba6c9f98f3","price":"0.34","side":"BUY","size":"51"},{"asset_id":"60386828328910021732068595344565885737045900010034836345809386672230885527307","best_ask":"0.6","best_bid":"0.59","hash":"1c41405891245efd1d01a934eecf4016db3d1c73","price":"0.66","side":"SELL","size":"51"}],"timestamp":"1785126626666"},"payload_hash":"252c7addd557e361789dd3549d52c62046e34bf04a9e88068080abd2e86a7ea0","raw_frame":"{\"market\":\"0xeb66215f2e9faa6449e30a02bab5b8ed7b79a38bf961f6b24d0073c9c2419250\", \"price_changes\":[{\"asset_id\":\"69697746896130839564035629862476347944307040470122503199396727085502753297492\", \"price\":\"0.34\", \"size\":\"51\", \"side\":\"BUY\", \"hash\":\"92556038b01ab202fcb2b354f040a6ba6c9f98f3\", \"best_bid\":\"0.4\", \"best_ask\":\"0.41\"}, {\"asset_id\":\"60386828328910021732068595344565885737045900010034836345809386672230885527307\", \"price\":\"0.66\", \"size\":\"51\", \"side\":\"SELL\", \"hash\":\"1c41405891245efd1d01a934eecf4016db3d1c73\", \"best_bid\":\"0.59\", \"best_ask\":\"0.6\"}], \"timestamp\":\"1785126626666\", \"event_type\":\"price_change\"}","received_at":"2026-07-27T04:30:28.083055Z","schema_version":"clob-market-ws.price_change.v1","sequence":null,"server_hash":null,"server_timestamp":"1785126626666","session_id":"e9443c7415a0419799bee9cfbb1a9e4d","source":"clob_market_ws"},"received_at":"2026-07-27T04:30:28.083055Z","record_id":"64551fe1d2529c8b4374f9396a33294ddf3a58f83f855592a9adb961f1bf872d","schema_fingerprint":"4aa3821a28b0b7c2400bc59aba4bcc0a76e971dadd19610d3ad38c768e124dc7","schema_version":"edge-lab-recorder.raw.v1","sequence":null,"source":"clob_market_ws"}
{"event_at":"2026-07-27T04:30:26.666000Z","event_fingerprint":"47b79e941e239def2c34251f0415240114c65d7b63750776ee68d31145461ffc","payload":{"connection_id":"0f4979d6978d463e9660b042fdcf555f","event_at":"2026-07-27T04:30:26.666000Z","event_type":"price_change","frame_hash":"aa85f8b18fd254af693280a4ca1ef5d51549a8a4be2a827aeb52426b41c9a628","frame_index":0,"kind":"data","monotonic_ns":228611364164000,"payload":{"event_type":"price_change","market":"0xeb66215f2e9faa6449e30a02bab5b8ed7b79a38bf961f6b24d0073c9c2419250","price_changes":[{"asset_id":"69697746896130839564035629862476347944307040470122503199396727085502753297492","best_ask":"0.41","best_bid":"0.4","hash":"92556038b01ab202fcb2b354f040a6ba6c9f98f3","price":"0.36","side":"BUY","size":"31.87"},{"asset_id":"60386828328910021732068595344565885737045900010034836345809386672230885527307","best_ask":"0.6","best_bid":"0.59","hash":"1c41405891245efd1d01a934eecf4016db3d1c73","price":"0.64","side":"SELL","size":"31.87"}],"timestamp":"1785126626666"},"payload_hash":"fc3949e919137e1a821bc2f6d838465fa27714a64833eb829b36f55dcfe92212","raw_frame":"{\"market\":\"0xeb66215f2e9faa6449e30a02bab5b8ed7b79a38bf961f6b24d0073c9c2419250\", \"price_changes\":[{\"asset_id\":\"69697746896130839564035629862476347944307040470122503199396727085502753297492\", \"price\":\"0.36\", \"size\":\"31.87\", \"side\":\"BUY\", \"hash\":\"92556038b01ab202fcb2b354f040a6ba6c9f98f3\", \"best_bid\":\"0.4\", \"best_ask\":\"0.41\"}, {\"asset_id\":\"60386828328910021732068595344565885737045900010034836345809386672230885527307\", \"price\":\"0.64\", \"size\":\"31.87\", \"side\":\"SELL\", \"hash\":\"1c41405891245efd1d01a934eecf4016db3d1c73\", \"best_bid\":\"0.59\", \"best_ask\":\"0.6\"}], \"timestamp\":\"1785126626666\", \"event_type\":\"price_change\"}","received_at":"2026-07-27T04:30:28.094569Z","schema_version":"clob-market-ws.price_change.v1","sequence":null,"server_hash":null,"server_timestamp":"1785126626666","session_id":"e9443c7415a0419799bee9cfbb1a9e4d","source":"clob_market_ws"},"received_at":"2026-07-27T04:30:28.094569Z","record_id":"dedeb2f45db312126eae154728a8798cafa61aa82c3ca5cc2b8bea63f8ac776e","schema_fingerprint":"4aa3821a28b0b7c2400bc59aba4bcc0a76e971dadd19610d3ad38c768e124dc7","schema_version":"edge-lab-recorder.raw.v1","sequence":null,"source":"clob_market_ws"}
{"event_at":"2026-07-27T04:30:26.666000Z","event_fingerprint":"f4ca69067290782ee7844eaf4680ff32d3428eeb58a577b0aafeb6e1189c28f4","payload":{"connection_id":"0f4979d6978d463e9660b042fdcf555f","event_at":"2026-07-27T04:30:26.666000Z","event_type":"price_change","frame_hash":"7c874fc51cb29883bbcee576086958e9ce94cb28ad19def0bd2bb31a245a4af2","frame_index":0,"kind":"data","monotonic_ns":228611373417166,"payload":{"event_type":"price_change","market":"0xeb66215f2e9faa6449e30a02bab5b8ed7b79a38bf961f6b24d0073c9c2419250","price_changes":[{"asset_id":"69697746896130839564035629862476347944307040470122503199396727085502753297492","best_ask":"0.41","best_bid":"0.4","hash":"92556038b01ab202fcb2b354f040a6ba6c9f98f3","price":"0.38","side":"BUY","size":"25.62"},{"asset_id":"60386828328910021732068595344565885737045900010034836345809386672230885527307","best_ask":"0.6","best_bid":"0.59","hash":"1c41405891245efd1d01a934eecf4016db3d1c73","price":"0.62","side":"SELL","size":"25.62"}],"timestamp":"1785126626666"},"payload_hash":"46ebd0326e48f2dac7699d6d7458f07be82dbed9b3acef1f14686b9196732a84","raw_frame":"{\"market\":\"0xeb66215f2e9faa6449e30a02bab5b8ed7b79a38bf961f6b24d0073c9c2419250\", \"price_changes\":[{\"asset_id\":\"69697746896130839564035629862476347944307040470122503199396727085502753297492\", \"price\":\"0.38\", \"size\":\"25.62\", \"side\":\"BUY\", \"hash\":\"92556038b01ab202fcb2b354f040a6ba6c9f98f3\", \"best_bid\":\"0.4\", \"best_ask\":\"0.41\"}, {\"asset_id\":\"60386828328910021732068595344565885737045900010034836345809386672230885527307\", \"price\":\"0.62\", \"size\":\"25.62\", \"side\":\"SELL\", \"hash\":\"1c41405891245efd1d01a934eecf4016db3d1c73\", \"best_bid\":\"0.59\", \"best_ask\":\"0.6\"}], \"timestamp\":\"1785126626666\", \"event_type\":\"price_change\"}","received_at":"2026-07-27T04:30:28.103822Z","schema_version":"clob-market-ws.price_change.v1","sequence":null,"server_hash":null,"server_timestamp":"1785126626666","session_id":"e9443c7415a0419799bee9cfbb1a9e4d","source":"clob_market_ws"},"received_at":"2026-07-27T04:30:28.103822Z","record_id":"986fe6b73cfbd4f2689236c408b1a84023ef3e5c06105d8f1f1350bcf7992534","schema_fingerprint":"4aa3821a28b0b7c2400bc59aba4bcc0a76e971dadd19610d3ad38c768e124dc7","schema_version":"edge-lab-recorder.raw.v1","sequence":null,"source":"clob_market_ws"}
{"event_at":"2026-07-27T04:30:26.670000Z","event_fingerprint":"44142cb009deafb023bb0a694ebb6e95b9daf81472a6156af4aa2f4ec1655243","payload":{"connection_id":"0f4979d6978d463e9660b042fdcf555f","event_at":"2026-07-27T04:30:26.670000Z","event_type":"price_change","frame_hash":"7b85c451acf35c0168f70ad6af4994836575bf9a6136be7e0fec4d5eefd0507e","frame_index":0,"kind":"data","monotonic_ns":228611381860125,"payload":{"event_type":"price_change","market":"0xeb66215f2e9faa6449e30a02bab5b8ed7b79a38bf961f6b24d0073c9c2419250","price_changes":[{"asset_id":"69697746896130839564035629862476347944307040470122503199396727085502753297492","best_ask":"0.41","best_bid":"0.4","hash":"e8475bd8dc60c246ce9c06e0023b72c20b1ff2e4","price":"0.42","side":"SELL","size":"50.01"},{"asset_id":"60386828328910021732068595344565885737045900010034836345809386672230885527307","best_ask":"0.6","best_bid":"0.59","hash":"11e3187fa0e50d2b2eed0e0f6dd9fccc24bca482","price":"0.58","side":"BUY","size":"50.01"}],"timestamp":"1785126626670"},"payload_hash":"861db687457d033307f4df4f8c41be5342e7607ab2154085cf2d402492d68538","raw_frame":"{\"market\":\"0xeb66215f2e9faa6449e30a02bab5b8ed7b79a38bf961f6b24d0073c9c2419250\", \"price_changes\":[{\"asset_id\":\"69697746896130839564035629862476347944307040470122503199396727085502753297492\", \"price\":\"0.42\", \"size\":\"50.01\", \"side\":\"SELL\", \"hash\":\"e8475bd8dc60c246ce9c06e0023b72c20b1ff2e4\", \"best_bid\":\"0.4\", \"best_ask\":\"0.41\"}, {\"asset_id\":\"60386828328910021732068595344565885737045900010034836345809386672230885527307\", \"price\":\"0.58\", \"size\":\"50.01\", \"side\":\"BUY\", \"hash\":\"11e3187fa0e50d2b2eed0e0f6dd9fccc24bca482\", \"best_bid\":\"0.59\", \"best_ask\":\"0.6\"}], \"timestamp\":\"1785126626670\", \"event_type\":\"price_change\"}","received_at":"2026-07-27T04:30:28.112268Z","schema_version":"clob-market-ws.price_change.v1","sequence":null,"server_hash":null,"server_timestamp":"1785126626670","session_id":"e9443c7415a0419799bee9cfbb1a9e4d","source":"clob_market_ws"},"received_at":"2026-07-27T04:30:28.112268Z","record_id":"3718275e76c88610ec03e21d84fdb756018f1646f4ea81240f44d9bb3524b77a","schema_fingerprint":"4aa3821a28b0b7c2400bc59aba4bcc0a76e971dadd19610d3ad38c768e124dc7","schema_version":"edge-lab-recorder.raw.v1","sequence":null,"source":"clob_market_ws"}
{"event_at":"2026-07-27T04:30:26.671000Z","event_fingerprint":"adca14321088e587867f73d1f080bb265de1c2eaadc836021372ee628db5eb82","payload":{"connection_id":"0f4979d6978d463e9660b042fdcf555f","event_at":"2026-07-27T04:30:26.671000Z","event_type":"price_change","frame_hash":"c0c574e8e5d080a5b3e867abea69942db3e4366a275db0f5c0593e0cf033e488","frame_index":0,"kind":"data","monotonic_ns":228611392222250,"payload":{"event_type":"price_change","market":"0xeb66215f2e9faa6449e30a02bab5b8ed7b79a38bf961f6b24d0073c9c2419250","price_changes":[{"asset_id":"69697746896130839564035629862476347944307040470122503199396727085502753297492","best_ask":"0.41","best_bid":"0.4","hash":"d92076b4c1a33fd6e9d3111a696f071b2ee934e6","price":"0.35","side":"BUY","size":"40"},{"asset_id":"60386828328910021732068595344565885737045900010034836345809386672230885527307","best_ask":"0.6","best_bid":"0.59","hash":"1c0d6d6ed72b36671754ec08d82dd21852c9a629","price":"0.65","side":"SELL","size":"40"}],"timestamp":"1785126626671"},"payload_hash":"bb8119c5e0e8686b04bde277e083a264b359ba6cce34c87af66817c1dfaf8657","raw_frame":"{\"market\":\"0xeb66215f2e9faa6449e30a02bab5b8ed7b79a38bf961f6b24d0073c9c2419250\", \"price_changes\":[{\"asset_id\":\"69697746896130839564035629862476347944307040470122503199396727085502753297492\", \"price\":\"0.35\", \"size\":\"40\", \"side\":\"BUY\", \"hash\":\"d92076b4c1a33fd6e9d3111a696f071b2ee934e6\", \"best_bid\":\"0.4\", \"best_ask\":\"0.41\"}, {\"asset_id\":\"60386828328910021732068595344565885737045900010034836345809386672230885527307\", \"price\":\"0.65\", \"size\":\"40\", \"side\":\"SELL\", \"hash\":\"1c0d6d6ed72b36671754ec08d82dd21852c9a629\", \"best_bid\":\"0.59\", \"best_ask\":\"0.6\"}], \"timestamp\":\"1785126626671\", \"event_type\":\"price_change\"}","received_at":"2026-07-27T04:30:28.122628Z","schema_version":"clob-market-ws.price_change.v1","sequence":null,"server_hash":null,"server_timestamp":"1785126626671","session_id":"e9443c7415a0419799bee9cfbb1a9e4d","source":"clob_market_ws"},"received_at":"2026-07-27T04:30:28.122628Z","record_id":"15fd56b47da2125999eeea1850a9c67e54a17aec81f1f6bc7e483c6e1d7bc435","schema_fingerprint":"4aa3821a28b0b7c2400bc59aba4bcc0a76e971dadd19610d3ad38c768e124dc7","schema_version":"edge-lab-recorder.raw.v1","sequence":null,"source":"clob_market_ws"}
{"event_at":"2026-07-27T04:30:26.671000Z","event_fingerprint":"992f0e1aa38d2aba5c51c60a8ec1d9ee27c07e4322021f67af5db5f31d266e30","payload":{"connection_id":"0f4979d6978d463e9660b042fdcf555f","event_at":"2026-07-27T04:30:26.671000Z","event_type":"price_change","frame_hash":"315f040a8e701fa36e447483c83057840ef5ba6152037fdf91971eaa616adb63","frame_index":0,"kind":"data","monotonic_ns":228611400360333,"payload":{"event_type":"price_change","market":"0xeb66215f2e9faa6449e30a02bab5b8ed7b79a38bf961f6b24d0073c9c2419250","price_changes":[{"asset_id":"69697746896130839564035629862476347944307040470122503199396727085502753297492","best_ask":"0.41","best_bid":"0.4","hash":"3f67a321cb40a94320da4e1c5cb87222404cd41c","price":"0.33","side":"BUY","size":"22"},{"asset_id":"60386828328910021732068595344565885737045900010034836345809386672230885527307","best_ask":"0.6","best_bid":"0.59","hash":"54a53e3a6dbca7526a361b72cdb092b8a6d77633","price":"0.67","side":"SELL","size":"22"}],"timestamp":"1785126626671"},"payload_hash":"7fa7208ae36623fa811fcbd6f5fcc8400e353f7f946edd1790dd230fcade077c","raw_frame":"{\"market\":\"0xeb66215f2e9faa6449e30a02bab5b8ed7b79a38bf961f6b24d0073c9c2419250\", \"price_changes\":[{\"asset_id\":\"69697746896130839564035629862476347944307040470122503199396727085502753297492\", \"price\":\"0.33\", \"size\":\"22\", \"side\":\"BUY\", \"hash\":\"3f67a321cb40a94320da4e1c5cb87222404cd41c\", \"best_bid\":\"0.4\", \"best_ask\":\"0.41\"}, {\"asset_id\":\"60386828328910021732068595344565885737045900010034836345809386672230885527307\", \"price\":\"0.67\", \"size\":\"22\", \"side\":\"SELL\", \"hash\":\"54a53e3a6dbca7526a361b72cdb092b8a6d77633\", \"best_bid\":\"0.59\", \"best_ask\":\"0.6\"}], \"timestamp\":\"1785126626671\", \"event_type\":\"price_change\"}","received_at":"2026-07-27T04:30:28.130767Z","schema_version":"clob-market-ws.price_change.v1","sequence":null,"server_hash":null,"server_timestamp":"1785126626671","session_id":"e9443c7415a0419799bee9cfbb1a9e4d","source":"clob_market_ws"},"received_at":"2026-07-27T04:30:28.130767Z","record_id":"d46fd331cd632a7c3c842cf7cdff7c40a37607369916e3cc39c5308bc1d980cb","schema_fingerprint":"4aa3821a28b0b7c2400bc59aba4bcc0a76e971dadd19610d3ad38c768e124dc7","schema_version":"edge-lab-recorder.raw.v1","sequence":null,"source":"clob_market_ws"}
{"event_at":"2026-07-27T04:30:26.673000Z","event_fingerprint":"cb7b53a21998aa53080821873ff0f8c8a87bc919a6985cfd4fbd94739ea26edf","payload":{"connection_id":"0f4979d6978d463e9660b042fdcf555f","event_at":"2026-07-27T04:30:26.673000Z","event_type":"price_change","frame_hash":"eb67726dc02f038ce3e26a6cfe26053deb464e876d1312c3b4af527a2d56e60b","frame_index":0,"kind":"data","monotonic_ns":228611408981291,"payload":{"event_type":"price_change","market":"0xeb66215f2e9faa6449e30a02bab5b8ed7b79a38bf961f6b24d0073c9c2419250","price_changes":[{"asset_id":"69697746896130839564035629862476347944307040470122503199396727085502753297492","best_ask":"0.41","best_bid":"0.4","hash":"1998e1798792882cea8b9b7db2157572cc8c04a8","price":"0.37","side":"BUY","size":"139.74"},{"asset_id":"60386828328910021732068595344565885737045900010034836345809386672230885527307","best_ask":"0.6","best_bid":"0.59","hash":"d2c122892495e65999e2a0edb1a933e49ae769ae","price":"0.63","side":"SELL","size":"139.74"}],"timestamp":"1785126626673"},"payload_hash":"0e591ed79788a5f991d4bd9c35615ef316f3df7ecb5ec64bd9bfd6b1a639f97e","raw_frame":"{\"market\":\"0xeb66215f2e9faa6449e30a02bab5b8ed7b79a38bf961f6b24d0073c9c2419250\", \"price_changes\":[{\"asset_id\":\"69697746896130839564035629862476347944307040470122503199396727085502753297492\", \"price\":\"0.37\", \"size\":\"139.74\", \"side\":\"BUY\", \"hash\":\"1998e1798792882cea8b9b7db2157572cc8c04a8\", \"best_bid\":\"0.4\", \"best_ask\":\"0.41\"}, {\"asset_id\":\"60386828328910021732068595344565885737045900010034836345809386672230885527307\", \"price\":\"0.63\", \"size\":\"139.74\", \"side\":\"SELL\", \"hash\":\"d2c122892495e65999e2a0edb1a933e49ae769ae\", \"best_bid\":\"0.59\", \"best_ask\":\"0.6\"}], \"timestamp\":\"1785126626673\", \"event_type\":\"price_change\"}","received_at":"2026-07-27T04:30:28.139386Z","schema_version":"clob-market-ws.price_change.v1","sequence":null,"server_hash":null,"server_timestamp":"1785126626673","session_id":"e9443c7415a0419799bee9cfbb1a9e4d","source":"clob_market_ws"},"received_at":"2026-07-27T04:30:28.139386Z","record_id":"31b70f4e62f31135861af1a2ce2eb6685fb0492e7338045db508e5276e5fee78","schema_fingerprint":"4aa3821a28b0b7c2400bc59aba4bcc0a76e971dadd19610d3ad38c768e124dc7","schema_version":"edge-lab-recorder.raw.v1","sequence":null,"source":"clob_market_ws"}
{"event_at":"2026-07-27T04:30:26.674000Z","event_fingerprint":"30370b338ee3ca04674b0a1be38914e9290bd76f939f0df649dafd734009d1ea","payload":{"connection_id":"0f4979d6978d463e9660b042fdcf555f","event_at":"2026-07-27T04:30:26.674000Z","event_type":"price_change","frame_hash":"6b3bd1cec7900924dd0bd25bc551788ba7e654f0dce31626ae3c307a4f4e543f","frame_index":0,"kind":"data","monotonic_ns":228611416455791,"payload":{"event_type":"price_change","market":"0xeb66215f2e9faa6449e30a02bab5b8ed7b79a38bf961f6b24d0073c9c2419250","price_changes":[{"asset_id":"60386828328910021732068595344565885737045900010034836345809386672230885527307","best_ask":"0.6","best_bid":"0.59","hash":"19e59a8cfe5d9cb2e1662711b5b26259f278dd51","price":"0.47","side":"BUY","size":"152.84"},{"asset_id":"69697746896130839564035629862476347944307040470122503199396727085502753297492","best_ask":"0.41","best_bid":"0.4","hash":"7fc35c6a3071190d80ba47990011e31c984464c0","price":"0.53","side":"SELL","size":"152.84"}],"timestamp":"1785126626674"},"payload_hash":"b4cc1585b3e33ce601d43049c262d7c59c0011a79b666ca349bfecaf01f51537","raw_frame":"{\"market\":\"0xeb66215f2e9faa6449e30a02bab5b8ed7b79a38bf961f6b24d0073c9c2419250\", \"price_changes\":[{\"asset_id\":\"60386828328910021732068595344565885737045900010034836345809386672230885527307\", \"price\":\"0.47\", \"size\":\"152.84\", \"side\":\"BUY\", \"hash\":\"19e59a8cfe5d9cb2e1662711b5b26259f278dd51\", \"best_bid\":\"0.59\", \"best_ask\":\"0.6\"}, {\"asset_id\":\"69697746896130839564035629862476347944307040470122503199396727085502753297492\", \"price\":\"0.53\", \"size\":\"152.84\", \"side\":\"SELL\", \"hash\":\"7fc35c6a3071190d80ba47990011e31c984464c0\", \"best_bid\":\"0.4\", \"best_ask\":\"0.41\"}], \"timestamp\":\"1785126626674\", \"event_type\":\"price_change\"}","received_at":"2026-07-27T04:30:28.146863Z","schema_version":"clob-market-ws.price_change.v1","sequence":null,"server_hash":null,"server_timestamp":"1785126626674","session_id":"e9443c7415a0419799bee9cfbb1a9e4d","source":"clob_market_ws"},"received_at":"2026-07-27T04:30:28.146863Z","record_id":"b0357874857c4fa00c3128fce9d62581c4c5cd4e20f2e2e2ad773ef58ac792ae","schema_fingerprint":"4aa3821a28b0b7c2400bc59aba4bcc0a76e971dadd19610d3ad38c768e124dc7","schema_version":"edge-lab-recorder.raw.v1","sequence":null,"source":"clob_market_ws"}
{"event_at":"2026-07-27T04:30:26.669000Z","event_fingerprint":"264866cea1881f386ebd04640305a2f67d0103424ce72f79a07e419c7b2085d0","payload":{"connection_id":"0f4979d6978d463e9660b042fdcf555f","event_at":"2026-07-27T04:30:26.669000Z","event_type":"last_trade_price","frame_hash":"baa34c5d9d31999bd4ecfb15f921868d664148b1c1693a888fc512b03551864e","frame_index":0,"kind":"data","monotonic_ns":228611430936458,"payload":{"asset_id":"69697746896130839564035629862476347944307040470122503199396727085502753297492","event_type":"last_trade_price","fee_rate_bps":"0","market":"0xeb66215f2e9faa6449e30a02bab5b8ed7b79a38bf961f6b24d0073c9c2419250","price":"0.4","side":"SELL","size":"0.02","timestamp":"1785126626669","transaction_hash":"0x304e1320ae8bca0ba20937fd3b6784215d1776763517851f80f90b8171802a1c"},"payload_hash":"1cc6754e1b5c1dbe3fcfddc1d8402afef034ec5642deec6939ff1a94af80dfc3","raw_frame":"{\"market\":\"0xeb66215f2e9faa6449e30a02bab5b8ed7b79a38bf961f6b24d0073c9c2419250\", \"asset_id\":\"69697746896130839564035629862476347944307040470122503199396727085502753297492\", \"price\":\"0.4\", \"size\":\"0.02\", \"fee_rate_bps\":\"0\", \"side\":\"SELL\", \"timestamp\":\"1785126626669\", \"event_type\":\"last_trade_price\", \"transaction_hash\":\"0x304e1320ae8bca0ba20937fd3b6784215d1776763517851f80f90b8171802a1c\"}","received_at":"2026-07-27T04:30:28.161344Z","schema_version":"clob-market-ws.last_trade_price.v1","sequence":null,"server_hash":null,"server_timestamp":"1785126626669","session_id":"e9443c7415a0419799bee9cfbb1a9e4d","source":"clob_market_ws"},"received_at":"2026-07-27T04:30:28.161344Z","record_id":"ae2b46ef7dcf649159518d700f9694ac6e2c80127ab3696e4e4171104a509a2d","schema_fingerprint":"95ad9be75a4b695cd99991e12b2592bc7346f3f5388a82d0000ba65bc0d9fd0a","schema_version":"edge-lab-recorder.raw.v1","sequence":null,"source":"clob_market_ws"}
{"event_at":"2026-07-27T04:30:26.678000Z","event_fingerprint":"8ae2e8a0549d2058385cfc20341b219444678dbb73895d5e53c3b4e7b4ada20a","payload":{"connection_id":"0f4979d6978d463e9660b042fdcf555f","event_at":"2026-07-27T04:30:26.678000Z","event_type":"price_change","frame_hash":"908d3eccbafa2053d908bcb18f28e1c2687a21ccdc4ce0c8fadc47fc97b6ed48","frame_index":0,"kind":"data","monotonic_ns":228611442195125,"payload":{"event_type":"price_change","market":"0xeb66215f2e9faa6449e30a02bab5b8ed7b79a38bf961f6b24d0073c9c2419250","price_changes":[{"asset_id":"60386828328910021732068595344565885737045900010034836345809386672230885527307","best_ask":"0.6","best_bid":"0.59","hash":"c1240ebb118770af37f1127045236a8c0a1c24dd","price":"0.54","side":"BUY","size":"356.64"},{"asset_id":"69697746896130839564035629862476347944307040470122503199396727085502753297492","best_ask":"0.41","best_bid":"0.4","hash":"109e05f8c5f221a5454d1c2ea6029f32ea679677","price":"0.46","side":"SELL","size":"356.64"}],"timestamp":"1785126626678"},"payload_hash":"1cc673789c2bd1bbaa0a05c988bb91b0f9e572b244a3e3510c81ae144c2bdd90","raw_frame":"{\"market\":\"0xeb66215f2e9faa6449e30a02bab5b8ed7b79a38bf961f6b24d0073c9c2419250\", \"price_changes\":[{\"asset_id\":\"60386828328910021732068595344565885737045900010034836345809386672230885527307\", \"price\":\"0.54\", \"size\":\"356.64\", \"side\":\"BUY\", \"hash\":\"c1240ebb118770af37f1127045236a8c0a1c24dd\", \"best_bid\":\"0.59\", \"best_ask\":\"0.6\"}, {\"asset_id\":\"69697746896130839564035629862476347944307040470122503199396727085502753297492\", \"price\":\"0.46\", \"size\":\"356.64\", \"side\":\"SELL\", \"hash\":\"109e05f8c5f221a5454d1c2ea6029f32ea679677\", \"best_bid\":\"0.4\", \"best_ask\":\"0.41\"}], \"timestamp\":\"1785126626678\", \"event_type\":\"price_change\"}","received_at":"2026-07-27T04:30:28.172602Z","schema_version":"clob-market-ws.price_change.v1","sequence":null,"server_hash":null,"server_timestamp":"1785126626678","session_id":"e9443c7415a0419799bee9cfbb1a9e4d","source":"clob_market_ws"},"received_at":"2026-07-27T04:30:28.172602Z","record_id":"1f4d1ccda72e3a6079292fd8f7628bff06e69fe4976caffe0917dedb8166863c","schema_fingerprint":"4aa3821a28b0b7c2400bc59aba4bcc0a76e971dadd19610d3ad38c768e124dc7","schema_version":"edge-lab-recorder.raw.v1","sequence":null,"source":"clob_market_ws"}
{"event_at":"2026-07-27T04:30:26.691000Z","event_fingerprint":"b966c617e5e6f50326ac3c7cc5cb47e7f2dffa6e29fd3d161eb86e4e07ebd134","payload":{"connection_id":"0f4979d6978d463e9660b042fdcf555f","event_at":"2026-07-27T04:30:26.691000Z","event_type":"price_change","frame_hash":"7cd2e55ae46a16e633e5e654ab9c812d451e8714e984abe5f83359cf4db249de","frame_index":0,"kind":"data","monotonic_ns":228611455170916,"payload":{"event_type":"price_change","market":"0xeb66215f2e9faa6449e30a02bab5b8ed7b79a38bf961f6b24d0073c9c2419250","price_changes":[{"asset_id":"60386828328910021732068595344565885737045900010034836345809386672230885527307","best_ask":"0.6","best_bid":"0.59","hash":"f750d1e72d4453b8f91247488816351881ac6739","price":"0.01","side":"BUY","size":"7708.02"},{"asset_id":"69697746896130839564035629862476347944307040470122503199396727085502753297492","best_ask":"0.41","best_bid":"0.4","hash":"9c06fec04f14f1d388965c605063a26dcd3d2ba0","price":"0.99","side":"SELL","size":"7708.02"}],"timestamp":"1785126626691"},"payload_hash":"8c11ec0c3560bd253aa3d64f86fc7a39880d61d7845f3ed619a2a25efe2a18ab","raw_frame":"{\"market\":\"0xeb66215f2e9faa6449e30a02bab5b8ed7b79a38bf961f6b24d0073c9c2419250\", \"price_changes\":[{\"asset_id\":\"60386828328910021732068595344565885737045900010034836345809386672230885527307\", \"price\":\"0.01\", \"size\":\"7708.02\", \"side\":\"BUY\", \"hash\":\"f750d1e72d4453b8f91247488816351881ac6739\", \"best_bid\":\"0.59\", \"best_ask\":\"0.6\"}, {\"asset_id\":\"69697746896130839564035629862476347944307040470122503199396727085502753297492\", \"price\":\"0.99\", \"size\":\"7708.02\", \"side\":\"SELL\", \"hash\":\"9c06fec04f14f1d388965c605063a26dcd3d2ba0\", \"best_bid\":\"0.4\", \"best_ask\":\"0.41\"}], \"timestamp\":\"1785126626691\", \"event_type\":\"price_change\"}","received_at":"2026-07-27T04:30:28.185573Z","schema_version":"clob-market-ws.price_change.v1","sequence":null,"server_hash":null,"server_timestamp":"1785126626691","session_id":"e9443c7415a0419799bee9cfbb1a9e4d","source":"clob_market_ws"},"received_at":"2026-07-27T04:30:28.185573Z","record_id":"efadcdf16afd57911fe31c039085a864f13137f5798b0c8f353275597d093f0c","schema_fingerprint":"4aa3821a28b0b7c2400bc59aba4bcc0a76e971dadd19610d3ad38c768e124dc7","schema_version":"edge-lab-recorder.raw.v1","sequence":null,"source":"clob_market_ws"}
{"event_at":"2026-07-27T04:30:26.703000Z","event_fingerprint":"266eebe838b68495014d30215c44bf1740fa3cc9d9df212734860aaac4ad3798","payload":{"connection_id":"0f4979d6978d463e9660b042fdcf555f","event_at":"2026-07-27T04:30:26.703000Z","event_type":"price_change","frame_hash":"926704fce919a9d663919fc6e5fefd05315b7e8a61119442c26701c7bd80a67a","frame_index":0,"kind":"data","monotonic_ns":228611467347791,"payload":{"event_type":"price_change","market":"0xeb66215f2e9faa6449e30a02bab5b8ed7b79a38bf961f6b24d0073c9c2419250","price_changes":[{"asset_id":"60386828328910021732068595344565885737045900010034836345809386672230885527307","best_ask":"0.6","best_bid":"0.59","hash":"7be1c42333061f4dd02d79bf8ea73d615c01e1dd","price":"0.01","side":"BUY","size":"7713.02"},{"asset_id":"69697746896130839564035629862476347944307040470122503199396727085502753297492","best_ask":"0.41","best_bid":"0.4","hash":"2ec5905c07da6ae5501d45d54b29e53cbcf43bb0","price":"0.99","side":"SELL","size":"7713.02"}],"timestamp":"1785126626703"},"payload_hash":"1145acbd2cc3995eba84ac42206874f6e14ae6b499e53691d40d7102a855d9b0","raw_frame":"{\"market\":\"0xeb66215f2e9faa6449e30a02bab5b8ed7b79a38bf961f6b24d0073c9c2419250\", \"price_changes\":[{\"asset_id\":\"60386828328910021732068595344565885737045900010034836345809386672230885527307\", \"price\":\"0.01\", \"size\":\"7713.02\", \"side\":\"BUY\", \"hash\":\"7be1c42333061f4dd02d79bf8ea73d615c01e1dd\", \"best_bid\":\"0.59\", \"best_ask\":\"0.6\"}, {\"asset_id\":\"69697746896130839564035629862476347944307040470122503199396727085502753297492\", \"price\":\"0.99\", \"size\":\"7713.02\", \"side\":\"SELL\", \"hash\":\"2ec5905c07da6ae5501d45d54b29e53cbcf43bb0\", \"best_bid\":\"0.4\", \"best_ask\":\"0.41\"}], \"timestamp\":\"1785126626703\", \"event_type\":\"price_change\"}","received_at":"2026-07-27T04:30:28.197754Z","schema_version":"clob-market-ws.price_change.v1","sequence":null,"server_hash":null,"server_timestamp":"1785126626703","session_id":"e9443c7415a0419799bee9cfbb1a9e4d","source":"clob_market_ws"},"received_at":"2026-07-27T04:30:28.197754Z","record_id":"0b5e3cd13110c2a9b32f3be6b6b3be5e125eaeb3aa4e949eade81cb94d8a2072","schema_fingerprint":"4aa3821a28b0b7c2400bc59aba4bcc0a76e971dadd19610d3ad38c768e124dc7","schema_version":"edge-lab-recorder.raw.v1","sequence":null,"source":"clob_market_ws"}
{"event_at":"2026-07-27T04:30:26.728000Z","event_fingerprint":"8aa4b9d7338d5e572b77d6379198184fa82cf2cd5d5ce9e838a4a282cebc5874","payload":{"connection_id":"0f4979d6978d463e9660b042fdcf555f","event_at":"2026-07-27T04:30:26.728000Z","event_type":"price_change","frame_hash":"e4b06a8c3bf38102fbbb319350e6be9ca5ff1f0cefb35e596d7a4738e43d5ca7","frame_index":0,"kind":"data","monotonic_ns":228611473934166,"payload":{"event_type":"price_change","market":"0xeb66215f2e9faa6449e30a02bab5b8ed7b79a38bf961f6b24d0073c9c2419250","price_changes":[{"asset_id":"60386828328910021732068595344565885737045900010034836345809386672230885527307","best_ask":"0.6","best_bid":"0.59","hash":"a3cc63c29635eddcb057040b8baf224c6208978a","price":"0.01","side":"BUY","size":"7708.02"},{"asset_id":"69697746896130839564035629862476347944307040470122503199396727085502753297492","best_ask":"0.41","best_bid":"0.4","hash":"b5a476469d3280decdd664f50a4c11e43e1222d7","price":"0.99","side":"SELL","size":"7708.02"}],"timestamp":"1785126626728"},"payload_hash":"a58fb37b0df58ec10bcb256976c9b001131c33370e34c000fd092590cf9316cf","raw_frame":"{\"market\":\"0xeb66215f2e9faa6449e30a02bab5b8ed7b79a38bf961f6b24d0073c9c2419250\", \"price_changes\":[{\"asset_id\":\"60386828328910021732068595344565885737045900010034836345809386672230885527307\", \"price\":\"0.01\", \"size\":\"7708.02\", \"side\":\"BUY\", \"hash\":\"a3cc63c29635eddcb057040b8baf224c6208978a\", \"best_bid\":\"0.59\", \"best_ask\":\"0.6\"}, {\"asset_id\":\"69697746896130839564035629862476347944307040470122503199396727085502753297492\", \"price\":\"0.99\", \"size\":\"7708.02\", \"side\":\"SELL\", \"hash\":\"b5a476469d3280decdd664f50a4c11e43e1222d7\", \"best_bid\":\"0.4\", \"best_ask\":\"0.41\"}], \"timestamp\":\"1785126626728\", \"event_type\":\"price_change\"}","received_at":"2026-07-27T04:30:28.204339Z","schema_version":"clob-market-ws.price_change.v1","sequence":null,"server_hash":null,"server_timestamp":"1785126626728","session_id":"e9443c7415a0419799bee9cfbb1a9e4d","source":"clob_market_ws"},"received_at":"2026-07-27T04:30:28.204339Z","record_id":"a517dd70ad3471851011f98a1e8ba7816fa766f05a12f9243414c486e9b99940","schema_fingerprint":"4aa3821a28b0b7c2400bc59aba4bcc0a76e971dadd19610d3ad38c768e124dc7","schema_version":"edge-lab-recorder.raw.v1","sequence":null,"source":"clob_market_ws"}
{"event_at":"2026-07-27T04:30:26.755000Z","event_fingerprint":"d02adff513b220911230282c90488626ac4d45ad778ec0554f101211be6a74a3","payload":{"connection_id":"0f4979d6978d463e9660b042fdcf555f","event_at":"2026-07-27T04:30:26.755000Z","event_type":"price_change","frame_hash":"8a1150d78d4a746fa9899b29ce381ea9fcd0a1302d67ddbcdfc469d7932debd5","frame_index":0,"kind":"data","monotonic_ns":228611480096833,"payload":{"event_type":"price_change","market":"0xeb66215f2e9faa6449e30a02bab5b8ed7b79a38bf961f6b24d0073c9c2419250","price_changes":[{"asset_id":"60386828328910021732068595344565885737045900010034836345809386672230885527307","best_ask":"0.6","best_bid":"0.59","hash":"270947ce30320f9241000a1b29f880211771cd8f","price":"0.01","side":"BUY","size":"7703.02"},{"asset_id":"69697746896130839564035629862476347944307040470122503199396727085502753297492","best_ask":"0.41","best_bid":"0.4","hash":"e8771f9cb434d87e09db8d1be3d7fca9b319e15b","price":"0.99","side":"SELL","size":"7703.02"}],"timestamp":"1785126626755"},"payload_hash":"e1f12352e711176be2a3348035f94d2fd9db06df64dfce2491bb8c75d704c58b","raw_frame":"{\"market\":\"0xeb66215f2e9faa6449e30a02bab5b8ed7b79a38bf961f6b24d0073c9c2419250\", \"price_changes\":[{\"asset_id\":\"60386828328910021732068595344565885737045900010034836345809386672230885527307\", \"price\":\"0.01\", \"size\":\"7703.02\", \"side\":\"BUY\", \"hash\":\"270947ce30320f9241000a1b29f880211771cd8f\", \"best_bid\":\"0.59\", \"best_ask\":\"0.6\"}, {\"asset_id\":\"69697746896130839564035629862476347944307040470122503199396727085502753297492\", \"price\":\"0.99\", \"size\":\"7703.02\", \"side\":\"SELL\", \"hash\":\"e8771f9cb434d87e09db8d1be3d7fca9b319e15b\", \"best_bid\":\"0.4\", \"best_ask\":\"0.41\"}], \"timestamp\":\"1785126626755\", \"event_type\":\"price_change\"}","received_at":"2026-07-27T04:30:28.210506Z","schema_version":"clob-market-ws.price_change.v1","sequence":null,"server_hash":null,"server_timestamp":"1785126626755","session_id":"e9443c7415a0419799bee9cfbb1a9e4d","source":"clob_market_ws"},"received_at":"2026-07-27T04:30:28.210506Z","record_id":"4f0cf9c2f2bbd678a37947afda3c5d6d047024cd02be2f295f1cf9aa288a065e","schema_fingerprint":"4aa3821a28b0b7c2400bc59aba4bcc0a76e971dadd19610d3ad38c768e124dc7","schema_version":"edge-lab-recorder.raw.v1","sequence":null,"source":"clob_market_ws"}
{"event_at":"2026-07-27T04:30:26.763000Z","event_fingerprint":"489e01ac41022120672e8eede74f1deedadd5216147916bd1817c32dc637fcd2","payload":{"connection_id":"0f4979d6978d463e9660b042fdcf555f","event_at":"2026-07-27T04:30:26.763000Z","event_type":"price_change","frame_hash":"0e560e9e04df6f42f6c0ae3429b33ce747d825015e876df5aa1ce7ea5ae64569","frame_index":0,"kind":"data","monotonic_ns":228611487652458,"payload":{"event_type":"price_change","market":"0xeb66215f2e9faa6449e30a02bab5b8ed7b79a38bf961f6b24d0073c9c2419250","price_changes":[{"asset_id":"69697746896130839564035629862476347944307040470122503199396727085502753297492","best_ask":"0.41","best_bid":"0.4","hash":"6911175a5b660363b96199fd58e8aac135b3c733","price":"0.42","side":"SELL","size":"45.01"},{"asset_id":"60386828328910021732068595344565885737045900010034836345809386672230885527307","best_ask":"0.6","best_bid":"0.59","hash":"c316da40a11b3bf7f6a701e2ca96e23eb743c76b","price":"0.58","side":"BUY","size":"45.01"}],"timestamp":"1785126626763"},"payload_hash":"f2a20471567716ed33e2c2dab9b2cea08a8fa237ab5eb4ad6d066653b3565bc7","raw_frame":"{\"market\":\"0xeb66215f2e9faa6449e30a02bab5b8ed7b79a38bf961f6b24d0073c9c2419250\", \"price_changes\":[{\"asset_id\":\"69697746896130839564035629862476347944307040470122503199396727085502753297492\", \"price\":\"0.42\", \"size\":\"45.01\", \"side\":\"SELL\", \"hash\":\"6911175a5b660363b96199fd58e8aac135b3c733\", \"best_bid\":\"0.4\", \"best_ask\":\"0.41\"}, {\"asset_id\":\"60386828328910021732068595344565885737045900010034836345809386672230885527307\", \"price\":\"0.58\", \"size\":\"45.01\", \"side\":\"BUY\", \"hash\":\"c316da40a11b3bf7f6a701e2ca96e23eb743c76b\", \"best_bid\":\"0.59\", \"best_ask\":\"0.6\"}], \"timestamp\":\"1785126626763\", \"event_type\":\"price_change\"}","received_at":"2026-07-27T04:30:28.218060Z","schema_version":"clob-market-ws.price_change.v1","sequence":null,"server_hash":null,"server_timestamp":"1785126626763","session_id":"e9443c7415a0419799bee9cfbb1a9e4d","source":"clob_market_ws"},"received_at":"2026-07-27T04:30:28.218060Z","record_id":"6aacf6ab17624af4adb3b22e5d271576abe251974d8b998c2a042689e2f28612","schema_fingerprint":"4aa3821a28b0b7c2400bc59aba4bcc0a76e971dadd19610d3ad38c768e124dc7","schema_version":"edge-lab-recorder.raw.v1","sequence":null,"source":"clob_market_ws"}
{"event_at":"2026-07-27T04:30:26.787000Z","event_fingerprint":"6c908209534fb3c2ad0f6dfe80f1ed342c84c3b04230d5e4204a692750087cf6","payload":{"connection_id":"0f4979d6978d463e9660b042fdcf555f","event_at":"2026-07-27T04:30:26.787000Z","event_type":"price_change","frame_hash":"02072af6dccd41d891ba5f47e492c8eea8a8df0f60c39dd60d70416346a293d9","frame_index":0,"kind":"data","monotonic_ns":228611495385000,"payload":{"event_type":"price_change","market":"0xeb66215f2e9faa6449e30a02bab5b8ed7b79a38bf961f6b24d0073c9c2419250","price_changes":[{"asset_id":"60386828328910021732068595344565885737045900010034836345809386672230885527307","best_ask":"0.6","best_bid":"0.59","hash":"862f04cd25ddf8675bcaf12327d0b3f2e47f6ebb","price":"0.51","side":"BUY","size":"72.64"},{"asset_id":"69697746896130839564035629862476347944307040470122503199396727085502753297492","best_ask":"0.41","best_bid":"0.4","hash":"cddb58346df9c77ed897a492f015af5c5fe6cf74","price":"0.49","side":"SELL","size":"72.64"}],"timestamp":"1785126626787"},"payload_hash":"22fdda5162c812957e976375aac19348744e0bf9630b297ef3912c6f6891a0d2","raw_frame":"{\"market\":\"0xeb66215f2e9faa6449e30a02bab5b8ed7b79a38bf961f6b24d0073c9c2419250\", \"price_changes\":[{\"asset_id\":\"60386828328910021732068595344565885737045900010034836345809386672230885527307\", \"price\":\"0.51\", \"size\":\"72.64\", \"side\":\"BUY\", \"hash\":\"862f04cd25ddf8675bcaf12327d0b3f2e47f6ebb\", \"best_bid\":\"0.59\", \"best_ask\":\"0.6\"}, {\"asset_id\":\"69697746896130839564035629862476347944307040470122503199396727085502753297492\", \"price\":\"0.49\", \"size\":\"72.64\", \"side\":\"SELL\", \"hash\":\"cddb58346df9c77ed897a492f015af5c5fe6cf74\", \"best_bid\":\"0.4\", \"best_ask\":\"0.41\"}], \"timestamp\":\"1785126626787\", \"event_type\":\"price_change\"}","received_at":"2026-07-27T04:30:28.225793Z","schema_version":"clob-market-ws.price_change.v1","sequence":null,"server_hash":null,"server_timestamp":"1785126626787","session_id":"e9443c7415a0419799bee9cfbb1a9e4d","source":"clob_market_ws"},"received_at":"2026-07-27T04:30:28.225793Z","record_id":"8d8a54f838741bf40796062ae900819033e978e501fddfdf1be195513264fa98","schema_fingerprint":"4aa3821a28b0b7c2400bc59aba4bcc0a76e971dadd19610d3ad38c768e124dc7","schema_version":"edge-lab-recorder.raw.v1","sequence":null,"source":"clob_market_ws"}
{"event_at":"2026-07-27T04:30:26.797000Z","event_fingerprint":"5b97604240e85bfb38d8f8053403ae475fcc54563fad995ce42f56ef66320cdb","payload":{"connection_id":"0f4979d6978d463e9660b042fdcf555f","event_at":"2026-07-27T04:30:26.797000Z","event_type":"price_change","frame_hash":"1b6a702def1a94c88d14f0c3234c53372a1b334020832d1fc8e32a23324d30de","frame_index":0,"kind":"data","monotonic_ns":228611507610041,"payload":{"event_type":"price_change","market":"0xeb66215f2e9faa6449e30a02bab5b8ed7b79a38bf961f6b24d0073c9c2419250","price_changes":[{"asset_id":"69697746896130839564035629862476347944307040470122503199396727085502753297492","best_ask":"0.41","best_bid":"0.4","hash":"d6a1a708bfd9aa6796e08e41638ebaa2998bf9b0","price":"0.04","side":"BUY","size":"868.09"},{"asset_id":"60386828328910021732068595344565885737045900010034836345809386672230885527307","best_ask":"0.6","best_bid":"0.59","hash":"9fb9522ad8bb279722f7a6453557e6847fc5e15d","price":"0.96","side":"SELL","size":"868.09"}],"timestamp":"1785126626797"},"payload_hash":"989e1a5e964bad4cc3ef31d36f761c0992b9ac52a517126e9be98125443347e5","raw_frame":"{\"market\":\"0xeb66215f2e9faa6449e30a02bab5b8ed7b79a38bf961f6b24d0073c9c2419250\", \"price_changes\":[{\"asset_id\":\"69697746896130839564035629862476347944307040470122503199396727085502753297492\", \"price\":\"0.04\", \"size\":\"868.09\", \"side\":\"BUY\", \"hash\":\"d6a1a708bfd9aa6796e08e41638ebaa2998bf9b0\", \"best_bid\":\"0.4\", \"best_ask\":\"0.41\"}, {\"asset_id\":\"60386828328910021732068595344565885737045900010034836345809386672230885527307\", \"price\":\"0.96\", \"size\":\"868.09\", \"side\":\"SELL\", \"hash\":\"9fb9522ad8bb279722f7a6453557e6847fc5e15d\", \"best_bid\":\"0.59\", \"best_ask\":\"0.6\"}], \"timestamp\":\"1785126626797\", \"event_type\":\"price_change\"}","received_at":"2026-07-27T04:30:28.238019Z","schema_version":"clob-market-ws.price_change.v1","sequence":null,"server_hash":null,"server_timestamp":"1785126626797","session_id":"e9443c7415a0419799bee9cfbb1a9e4d","source":"clob_market_ws"},"received_at":"2026-07-27T04:30:28.238019Z","record_id":"57a7e32a97aa88b084c3d676a761bc12e500834b110f252090662088a8e2e77f","schema_fingerprint":"4aa3821a28b0b7c2400bc59aba4bcc0a76e971dadd19610d3ad38c768e124dc7","schema_version":"edge-lab-recorder.raw.v1","sequence":null,"source":"clob_market_ws"}
{"event_at":"2026-07-27T04:30:26.807000Z","event_fingerprint":"089edd524479df18b21f365957be4761b86035c6c3c7806308ca5cd195f6ccc2","payload":{"connection_id":"0f4979d6978d463e9660b042fdcf555f","event_at":"2026-07-27T04:30:26.807000Z","event_type":"price_change","frame_hash":"8f5df266e778e3518de165ff680911b4c1865fefb959d7e727f1a728aca475e0","frame_index":0,"kind":"data","monotonic_ns":228611514797625,"payload":{"event_type":"price_change","market":"0xeb66215f2e9faa6449e30a02bab5b8ed7b79a38bf961f6b24d0073c9c2419250","price_changes":[{"asset_id":"60386828328910021732068595344565885737045900010034836345809386672230885527307","best_ask":"0.6","best_bid":"0.59","hash":"55f06ddf382af19d8e9149c4a629b966c06410a9","price":"0.47","side":"BUY","size":"223.76"},{"asset_id":"69697746896130839564035629862476347944307040470122503199396727085502753297492","best_ask":"0.41","best_bid":"0.4","hash":"15198850e5f993c6154095eb54e5b091f97353d4","price":"0.53","side":"SELL","size":"223.76"}],"timestamp":"1785126626807"},"payload_hash":"854f1bf6260cb1ffc7bec5bf183d27e7666e01fdb55625ae3d64e763b5498e9e","raw_frame":"{\"market\":\"0xeb66215f2e9faa6449e30a02bab5b8ed7b79a38bf961f6b24d0073c9c2419250\", \"price_changes\":[{\"asset_id\":\"60386828328910021732068595344565885737045900010034836345809386672230885527307\", \"price\":\"0.47\", \"size\":\"223.76\", \"side\":\"BUY\", \"hash\":\"55f06ddf382af19d8e9149c4a629b966c06410a9\", \"best_bid\":\"0.59\", \"best_ask\":\"0.6\"}, {\"asset_id\":\"69697746896130839564035629862476347944307040470122503199396727085502753297492\", \"price\":\"0.53\", \"size\":\"223.76\", \"side\":\"SELL\", \"hash\":\"15198850e5f993c6154095eb54e5b091f97353d4\", \"best_bid\":\"0.4\", \"best_ask\":\"0.41\"}], \"timestamp\":\"1785126626807\", \"event_type\":\"price_change\"}","received_at":"2026-07-27T04:30:28.245205Z","schema_version":"clob-market-ws.price_change.v1","sequence":null,"server_hash":null,"server_timestamp":"1785126626807","session_id":"e9443c7415a0419799bee9cfbb1a9e4d","source":"clob_market_ws"},"received_at":"2026-07-27T04:30:28.245205Z","record_id":"4f62fa72d5b551044248f02f115bb295f86a59b6819250576da34a3520b3dd93","schema_fingerprint":"4aa3821a28b0b7c2400bc59aba4bcc0a76e971dadd19610d3ad38c768e124dc7","schema_version":"edge-lab-recorder.raw.v1","sequence":null,"source":"clob_market_ws"}
{"event_at":"2026-07-27T04:30:26.850000Z","event_fingerprint":"86e36f8f432fb4c7d33fc8b04e41955b198d211f05c9043c57aacf3573cd0f16","payload":{"connection_id":"0f4979d6978d463e9660b042fdcf555f","event_at":"2026-07-27T04:30:26.850000Z","event_type":"price_change","frame_hash":"80f7a9de6a652f91bb7b15d7aad8070028a944c1d90cba27ddeee130a130583f","frame_index":0,"kind":"data","monotonic_ns":228611522757291,"payload":{"event_type":"price_change","market":"0xeb66215f2e9faa6449e30a02bab5b8ed7b79a38bf961f6b24d0073c9c2419250","price_changes":[{"asset_id":"60386828328910021732068595344565885737045900010034836345809386672230885527307","best_ask":"0.6","best_bid":"0.59","hash":"c989fa9229d8ddad0d1afd1d5dcaf74d9f1e9a21","price":"0.01","side":"BUY","size":"7708.02"},{"asset_id":"69697746896130839564035629862476347944307040470122503199396727085502753297492","best_ask":"0.41","best_bid":"0.4","hash":"88f0c4a0ef26503f7db10f17a2d8d79bea9f97c2","price":"0.99","side":"SELL","size":"7708.02"}],"timestamp":"1785126626850"},"payload_hash":"9ac6ee201bee686f6c0a0203fe72a731430b5a85628895c7f6234a3f8c79a94f","raw_frame":"{\"market\":\"0xeb66215f2e9faa6449e30a02bab5b8ed7b79a38bf961f6b24d0073c9c2419250\", \"price_changes\":[{\"asset_id\":\"60386828328910021732068595344565885737045900010034836345809386672230885527307\", \"price\":\"0.01\", \"size\":\"7708.02\", \"side\":\"BUY\", \"hash\":\"c989fa9229d8ddad0d1afd1d5dcaf74d9f1e9a21\", \"best_bid\":\"0.59\", \"best_ask\":\"0.6\"}, {\"asset_id\":\"69697746896130839564035629862476347944307040470122503199396727085502753297492\", \"price\":\"0.99\", \"size\":\"7708.02\", \"side\":\"SELL\", \"hash\":\"88f0c4a0ef26503f7db10f17a2d8d79bea9f97c2\", \"best_bid\":\"0.4\", \"best_ask\":\"0.41\"}], \"timestamp\":\"1785126626850\", \"event_type\":\"price_change\"}","received_at":"2026-07-27T04:30:28.253163Z","schema_version":"clob-market-ws.price_change.v1","sequence":null,"server_hash":null,"server_timestamp":"1785126626850","session_id":"e9443c7415a0419799bee9cfbb1a9e4d","source":"clob_market_ws"},"received_at":"2026-07-27T04:30:28.253163Z","record_id":"5c79a461b901090a4c46b5e4d20c98e9c8f552a06b08d6b388341dbe16bffed4","schema_fingerprint":"4aa3821a28b0b7c2400bc59aba4bcc0a76e971dadd19610d3ad38c768e124dc7","schema_version":"edge-lab-recorder.raw.v1","sequence":null,"source":"clob_market_ws"}
{"event_at":"2026-07-27T04:30:26.870000Z","event_fingerprint":"6948d30f8e942b33e8c03e684b4a3bd4e8ff04d0e1ed271a8747f2ad913d72fe","payload":{"connection_id":"0f4979d6978d463e9660b042fdcf555f","event_at":"2026-07-27T04:30:26.870000Z","event_type":"price_change","frame_hash":"e6f1cce4a58ad720e979db5b9106ab5cdeeaf06ecfdddc358f55a3220bbdeef2","frame_index":0,"kind":"data","monotonic_ns":228611542496500,"payload":{"event_type":"price_change","market":"0xeb66215f2e9faa6449e30a02bab5b8ed7b79a38bf961f6b24d0073c9c2419250","price_changes":[{"asset_id":"69697746896130839564035629862476347944307040470122503199396727085502753297492","best_ask":"0.41","best_bid":"0.4","hash":"2562be3b0b2aa04388c70a08ca05db0c2f764a41","price":"0.42","side":"SELL","size":"50.01"},{"asset_id":"60386828328910021732068595344565885737045900010034836345809386672230885527307","best_ask":"0.6","best_bid":"0.59","hash":"74a81f625af03604ab007e2c0e22ce83202b52b6","price":"0.58","side":"BUY","size":"50.01"}],"timestamp":"1785126626870"},"payload_hash":"efa9b14a1e3936cf412b302787e5d2a6a58366e6334c3e3c636b4a9092925057","raw_frame":"{\"market\":\"0xeb66215f2e9faa6449e30a02bab5b8ed7b79a38bf961f6b24d0073c9c2419250\", \"price_changes\":[{\"asset_id\":\"69697746896130839564035629862476347944307040470122503199396727085502753297492\", \"price\":\"0.42\", \"size\":\"50.01\", \"side\":\"SELL\", \"hash\":\"2562be3b0b2aa04388c70a08ca05db0c2f764a41\", \"best_bid\":\"0.4\", \"best_ask\":\"0.41\"}, {\"asset_id\":\"60386828328910021732068595344565885737045900010034836345809386672230885527307\", \"price\":\"0.58\", \"size\":\"50.01\", \"side\":\"BUY\", \"hash\":\"74a81f625af03604ab007e2c0e22ce83202b52b6\", \"best_bid\":\"0.59\", \"best_ask\":\"0.6\"}], \"timestamp\":\"1785126626870\", \"event_type\":\"price_change\"}","received_at":"2026-07-27T04:30:28.272902Z","schema_version":"clob-market-ws.price_change.v1","sequence":null,"server_hash":null,"server_timestamp":"1785126626870","session_id":"e9443c7415a0419799bee9cfbb1a9e4d","source":"clob_market_ws"},"received_at":"2026-07-27T04:30:28.272902Z","record_id":"8ec7d74f3260073abbd46f5e5f3e68f79dad7c82fc3a61b9200b4b0c9e5cffc5","schema_fingerprint":"4aa3821a28b0b7c2400bc59aba4bcc0a76e971dadd19610d3ad38c768e124dc7","schema_version":"edge-lab-recorder.raw.v1","sequence":null,"source":"clob_market_ws"}
{"event_at":"2026-07-27T04:30:26.872000Z","event_fingerprint":"54ebe48c647e37cb81877f687d3cff08fd2ea9c5efa45a432871de9c075bb269","payload":{"connection_id":"0f4979d6978d463e9660b042fdcf555f","event_at":"2026-07-27T04:30:26.872000Z","event_type":"price_change","frame_hash":"a72206dbb621b0b2793e5a9b8a184d2ca7f4b9f39950aed7a180d61724f8255a","frame_index":0,"kind":"data","monotonic_ns":228611561368458,"payload":{"event_type":"price_change","market":"0xeb66215f2e9faa6449e30a02bab5b8ed7b79a38bf961f6b24d0073c9c2419250","price_changes":[{"asset_id":"60386828328910021732068595344565885737045900010034836345809386672230885527307","best_ask":"0.6","best_bid":"0.59","hash":"3f648ec95c170f835d4a9c72cd0b55f1fbbf5a48","price":"0.01","side":"BUY","size":"7703.02"},{"asset_id":"69697746896130839564035629862476347944307040470122503199396727085502753297492","best_ask":"0.41","best_bid":"0.4","hash":"210ceffdbfc80805e32ba696242ca16764122f7d","price":"0.99","side":"SELL","size":"7703.02"}],"timestamp":"1785126626872"},"payload_hash":"e1e3eea68ff7ddaba6ecca0991ec3517985a0a3376a76fff19e71b7dbcaca24e","raw_frame":"{\"market\":\"0xeb66215f2e9faa6449e30a02bab5b8ed7b79a38bf961f6b24d0073c9c2419250\", \"price_changes\":[{\"asset_id\":\"60386828328910021732068595344565885737045900010034836345809386672230885527307\", \"price\":\"0.01\", \"size\":\"7703.02\", \"side\":\"BUY\", \"hash\":\"3f648ec95c170f835d4a9c72cd0b55f1fbbf5a48\", \"best_bid\":\"0.59\", \"best_ask\":\"0.6\"}, {\"asset_id\":\"69697746896130839564035629862476347944307040470122503199396727085502753297492\", \"price\":\"0.99\", \"size\":\"7703.02\", \"side\":\"SELL\", \"hash\":\"210ceffdbfc80805e32ba696242ca16764122f7d\", \"best_bid\":\"0.4\", \"best_ask\":\"0.41\"}], \"timestamp\":\"1785126626872\", \"event_type\":\"price_change\"}","received_at":"2026-07-27T04:30:28.291776Z","schema_version":"clob-market-ws.price_change.v1","sequence":null,"server_hash":null,"server_timestamp":"1785126626872","session_id":"e9443c7415a0419799bee9cfbb1a9e4d","source":"clob_market_ws"},"received_at":"2026-07-27T04:30:28.291776Z","record_id":"4cfb0d72ebdb6bc5eb203bca13f5ad3a95dc83ec4acef91c210ce435400da67b","schema_fingerprint":"4aa3821a28b0b7c2400bc59aba4bcc0a76e971dadd19610d3ad38c768e124dc7","schema_version":"edge-lab-recorder.raw.v1","sequence":null,"source":"clob_market_ws"}
{"event_at":"2026-07-27T04:30:26.875000Z","event_fingerprint":"3de24df6a74a1e4ed7854f1be64ac16baac1c6f28c317995dfd0c6cd1885ec73","payload":{"connection_id":"0f4979d6978d463e9660b042fdcf555f","event_at":"2026-07-27T04:30:26.875000Z","event_type":"price_change","frame_hash":"d29b582592c2765f3c83643c1196d14ad4c8d15434e8a5e2cc53d0891639f3fb","frame_index":0,"kind":"data","monotonic_ns":228611570902208,"payload":{"event_type":"price_change","market":"0xeb66215f2e9faa6449e30a02bab5b8ed7b79a38bf961f6b24d0073c9c2419250","price_changes":[{"asset_id":"60386828328910021732068595344565885737045900010034836345809386672230885527307","best_ask":"0.6","best_bid":"0.59","hash":"849bf64cb16158d2ac432c74e6dede876763416b","price":"0.03","side":"BUY","size":"1068.1"},{"asset_id":"69697746896130839564035629862476347944307040470122503199396727085502753297492","best_ask":"0.41","best_bid":"0.4","hash":"8e23f3c2390e666aba4a3e7fee537e6e32d963f5","price":"0.97","side":"SELL","size":"1068.1"}],"timestamp":"1785126626875"},"payload_hash":"811c7967e6170d0ccbd7cd3aac9e2421ef62062562a036544cba7c384730f1db","raw_frame":"{\"market\":\"0xeb66215f2e9faa6449e30a02bab5b8ed7b79a38bf961f6b24d0073c9c2419250\", \"price_changes\":[{\"asset_id\":\"60386828328910021732068595344565885737045900010034836345809386672230885527307\", \"price\":\"0.03\", \"size\":\"1068.1\", \"side\":\"BUY\", \"hash\":\"849bf64cb16158d2ac432c74e6dede876763416b\", \"best_bid\":\"0.59\", \"best_ask\":\"0.6\"}, {\"asset_id\":\"69697746896130839564035629862476347944307040470122503199396727085502753297492\", \"price\":\"0.97\", \"size\":\"1068.1\", \"side\":\"SELL\", \"hash\":\"8e23f3c2390e666aba4a3e7fee537e6e32d963f5\", \"best_bid\":\"0.4\", \"best_ask\":\"0.41\"}], \"timestamp\":\"1785126626875\", \"event_type\":\"price_change\"}","received_at":"2026-07-27T04:30:28.301310Z","schema_version":"clob-market-ws.price_change.v1","sequence":null,"server_hash":null,"server_timestamp":"1785126626875","session_id":"e9443c7415a0419799bee9cfbb1a9e4d","source":"clob_market_ws"},"received_at":"2026-07-27T04:30:28.301310Z","record_id":"3695f5b255f60c696ab12e413d485f12f3a79bdb017db27aa789fef489f45a6d","schema_fingerprint":"4aa3821a28b0b7c2400bc59aba4bcc0a76e971dadd19610d3ad38c768e124dc7","schema_version":"edge-lab-recorder.raw.v1","sequence":null,"source":"clob_market_ws"}
{"event_at":"2026-07-27T04:30:26.931000Z","event_fingerprint":"f073780e051324531c87882e3677f58758dec16a4d9b73d290ee7dfb1ccb3ef0","payload":{"connection_id":"0f4979d6978d463e9660b042fdcf555f","event_at":"2026-07-27T04:30:26.931000Z","event_type":"price_change","frame_hash":"302142f3460893d6cb00e6b38fd90ae954d81931d7d321b183472afc2f76f50d","frame_index":0,"kind":"data","monotonic_ns":228611582204791,"payload":{"event_type":"price_change","market":"0xeb66215f2e9faa6449e30a02bab5b8ed7b79a38bf961f6b24d0073c9c2419250","price_changes":[{"asset_id":"69697746896130839564035629862476347944307040470122503199396727085502753297492","best_ask":"0.41","best_bid":"0.4","hash":"ad5b666a106068c676b08d44b8faebf5cefc356b","price":"0.39","side":"BUY","size":"22.6"},{"asset_id":"60386828328910021732068595344565885737045900010034836345809386672230885527307","best_ask":"0.6","best_bid":"0.59","hash":"f34b29c477fffbbcd4f8908fed706c1b0dc8c29f","price":"0.61","side":"SELL","size":"22.6"}],"timestamp":"1785126626931"},"payload_hash":"6ce54d2837af17d5982929cb811bc6caca0a5d27e7980b18bfbdc7624fff3cf6","raw_frame":"{\"market\":\"0xeb66215f2e9faa6449e30a02bab5b8ed7b79a38bf961f6b24d0073c9c2419250\", \"price_changes\":[{\"asset_id\":\"69697746896130839564035629862476347944307040470122503199396727085502753297492\", \"price\":\"0.39\", \"size\":\"22.6\", \"side\":\"BUY\", \"hash\":\"ad5b666a106068c676b08d44b8faebf5cefc356b\", \"best_bid\":\"0.4\", \"best_ask\":\"0.41\"}, {\"asset_id\":\"60386828328910021732068595344565885737045900010034836345809386672230885527307\", \"price\":\"0.61\", \"size\":\"22.6\", \"side\":\"SELL\", \"hash\":\"f34b29c477fffbbcd4f8908fed706c1b0dc8c29f\", \"best_bid\":\"0.59\", \"best_ask\":\"0.6\"}], \"timestamp\":\"1785126626931\", \"event_type\":\"price_change\"}","received_at":"2026-07-27T04:30:28.312613Z","schema_version":"clob-market-ws.price_change.v1","sequence":null,"server_hash":null,"server_timestamp":"1785126626931","session_id":"e9443c7415a0419799bee9cfbb1a9e4d","source":"clob_market_ws"},"received_at":"2026-07-27T04:30:28.312613Z","record_id":"3f43ea400946033ff08d04e0eb4b1beddbb05a7d57652ac81bf26705b55a6346","schema_fingerprint":"4aa3821a28b0b7c2400bc59aba4bcc0a76e971dadd19610d3ad38c768e124dc7","schema_version":"edge-lab-recorder.raw.v1","sequence":null,"source":"clob_market_ws"}
{"event_at":"2026-07-27T04:30:26.957000Z","event_fingerprint":"2e049aec91d59ea86f5a4385173566e142a3d0d00a6698133d20234ef03d79d6","payload":{"connection_id":"0f4979d6978d463e9660b042fdcf555f","event_at":"2026-07-27T04:30:26.957000Z","event_type":"price_change","frame_hash":"2ffd8bd81bcaa99620480f23d482dabc539bc0ab3587170d5723dc13786f9304","frame_index":0,"kind":"data","monotonic_ns":228611592568166,"payload":{"event_type":"price_change","market":"0xeb66215f2e9faa6449e30a02bab5b8ed7b79a38bf961f6b24d0073c9c2419250","price_changes":[{"asset_id":"60386828328910021732068595344565885737045900010034836345809386672230885527307","best_ask":"0.6","best_bid":"0.59","hash":"7807164a1c7119d46e3814bb7aa69c3aba088c6a","price":"0.03","side":"BUY","size":"1063.1"},{"asset_id":"69697746896130839564035629862476347944307040470122503199396727085502753297492","best_ask":"0.41","best_bid":"0.4","hash":"08d8d80abde89dcd5e6dfcaf7f5f8fa7095a31f6","price":"0.97","side":"SELL","size":"1063.1"}],"timestamp":"1785126626957"},"payload_hash":"213d26a9d31f9576ed1f7e76bd75485527a348abe1f82e2c2b1eb7e7b94d608f","raw_frame":"{\"market\":\"0xeb66215f2e9faa6449e30a02bab5b8ed7b79a38bf961f6b24d0073c9c2419250\", \"price_changes\":[{\"asset_id\":\"60386828328910021732068595344565885737045900010034836345809386672230885527307\", \"price\":\"0.03\", \"size\":\"1063.1\", \"side\":\"BUY\", \"hash\":\"7807164a1c7119d46e3814bb7aa69c3aba088c6a\", \"best_bid\":\"0.59\", \"best_ask\":\"0.6\"}, {\"asset_id\":\"69697746896130839564035629862476347944307040470122503199396727085502753297492\", \"price\":\"0.97\", \"size\":\"1063.1\", \"side\":\"SELL\", \"hash\":\"08d8d80abde89dcd5e6dfcaf7f5f8fa7095a31f6\", \"best_bid\":\"0.4\", \"best_ask\":\"0.41\"}], \"timestamp\":\"1785126626957\", \"event_type\":\"price_change\"}","received_at":"2026-07-27T04:30:28.322975Z","schema_version":"clob-market-ws.price_change.v1","sequence":null,"server_hash":null,"server_timestamp":"1785126626957","session_id":"e9443c7415a0419799bee9cfbb1a9e4d","source":"clob_market_ws"},"received_at":"2026-07-27T04:30:28.322975Z","record_id":"098384e6cc198d2e9cde11c3d5b59c045129bdf68244e54059ad2b7b3d55df21","schema_fingerprint":"4aa3821a28b0b7c2400bc59aba4bcc0a76e971dadd19610d3ad38c768e124dc7","schema_version":"edge-lab-recorder.raw.v1","sequence":null,"source":"clob_market_ws"}
{"event_at":"2026-07-27T04:30:26.969000Z","event_fingerprint":"73c33acc7886b4155716883477fae5775620383f1e559e5df7cc6f1855b1e369","payload":{"connection_id":"0f4979d6978d463e9660b042fdcf555f","event_at":"2026-07-27T04:30:26.969000Z","event_type":"price_change","frame_hash":"04a8be2875c7e885b74671437bef33478b568f78d8c051192f15126104902087","frame_index":0,"kind":"data","monotonic_ns":228611604976000,"payload":{"event_type":"price_change","market":"0xeb66215f2e9faa6449e30a02bab5b8ed7b79a38bf961f6b24d0073c9c2419250","price_changes":[{"asset_id":"69697746896130839564035629862476347944307040470122503199396727085502753297492","best_ask":"0.41","best_bid":"0.4","hash":"1dbdb15b2bb497fb4f10dc613c140a28904c14a1","price":"0.42","side":"SELL","size":"45.01"},{"asset_id":"60386828328910021732068595344565885737045900010034836345809386672230885527307","best_ask":"0.6","best_bid":"0.59","hash":"3de468195e700140dc1eaacbdced2c60c13b2f0c","price":"0.58","side":"BUY","size":"45.01"}],"timestamp":"1785126626969"},"payload_hash":"901701bf2c444def9e0704bda50a8321ecd13b8f7287c5371f8ac131f1d8f1c1","raw_frame":"{\"market\":\"0xeb66215f2e9faa6449e30a02bab5b8ed7b79a38bf961f6b24d0073c9c2419250\", \"price_changes\":[{\"asset_id\":\"69697746896130839564035629862476347944307040470122503199396727085502753297492\", \"price\":\"0.42\", \"size\":\"45.01\", \"side\":\"SELL\", \"hash\":\"1dbdb15b2bb497fb4f10dc613c140a28904c14a1\", \"best_bid\":\"0.4\", \"best_ask\":\"0.41\"}, {\"asset_id\":\"60386828328910021732068595344565885737045900010034836345809386672230885527307\", \"price\":\"0.58\", \"size\":\"45.01\", \"side\":\"BUY\", \"hash\":\"3de468195e700140dc1eaacbdced2c60c13b2f0c\", \"best_bid\":\"0.59\", \"best_ask\":\"0.6\"}], \"timestamp\":\"1785126626969\", \"event_type\":\"price_change\"}","received_at":"2026-07-27T04:30:28.335383Z","schema_version":"clob-market-ws.price_change.v1","sequence":null,"server_hash":null,"server_timestamp":"1785126626969","session_id":"e9443c7415a0419799bee9cfbb1a9e4d","source":"clob_market_ws"},"received_at":"2026-07-27T04:30:28.335383Z","record_id":"2ce565e2aff5aa58b68c3342d003a29541aa777aaa53478da403b92e32c735e3","schema_fingerprint":"4aa3821a28b0b7c2400bc59aba4bcc0a76e971dadd19610d3ad38c768e124dc7","schema_version":"edge-lab-recorder.raw.v1","sequence":null,"source":"clob_market_ws"}
{"event_at":"2026-07-27T04:30:26.989000Z","event_fingerprint":"e2aba37931d696009f26775e00e0c95a04e474d6c8fc5797b4a02810ebe953e9","payload":{"connection_id":"0f4979d6978d463e9660b042fdcf555f","event_at":"2026-07-27T04:30:26.989000Z","event_type":"price_change","frame_hash":"e0801491f9d4975152a8268c8277daf35ef129bf0a61afa5263c9b3e577193ce","frame_index":0,"kind":"data","monotonic_ns":228611614830791,"payload":{"event_type":"price_change","market":"0xeb66215f2e9faa6449e30a02bab5b8ed7b79a38bf961f6b24d0073c9c2419250","price_changes":[{"asset_id":"69697746896130839564035629862476347944307040470122503199396727085502753297492","best_ask":"0.41","best_bid":"0.4","hash":"6ccdc08124dc946cca3ce26e2f467390f84bed2c","price":"0.36","side":"BUY","size":"26.87"},{"asset_id":"60386828328910021732068595344565885737045900010034836345809386672230885527307","best_ask":"0.6","best_bid":"0.59","hash":"84e4e13b7503d2c231c70e8e8ef417b5c560a66d","price":"0.64","side":"SELL","size":"26.87"}],"timestamp":"1785126626989"},"payload_hash":"1816329da430dac1288c022b2a37b68ecb2c2d9ad6b0a929c5b8e3e89d169b72","raw_frame":"{\"market\":\"0xeb66215f2e9faa6449e30a02bab5b8ed7b79a38bf961f6b24d0073c9c2419250\", \"price_changes\":[{\"asset_id\":\"69697746896130839564035629862476347944307040470122503199396727085502753297492\", \"price\":\"0.36\", \"size\":\"26.87\", \"side\":\"BUY\", \"hash\":\"6ccdc08124dc946cca3ce26e2f467390f84bed2c\", \"best_bid\":\"0.4\", \"best_ask\":\"0.41\"}, {\"asset_id\":\"60386828328910021732068595344565885737045900010034836345809386672230885527307\", \"price\":\"0.64\", \"size\":\"26.87\", \"side\":\"SELL\", \"hash\":\"84e4e13b7503d2c231c70e8e8ef417b5c560a66d\", \"best_bid\":\"0.59\", \"best_ask\":\"0.6\"}], \"timestamp\":\"1785126626989\", \"event_type\":\"price_change\"}","received_at":"2026-07-27T04:30:28.345239Z","schema_version":"clob-market-ws.price_change.v1","sequence":null,"server_hash":null,"server_timestamp":"1785126626989","session_id":"e9443c7415a0419799bee9cfbb1a9e4d","source":"clob_market_ws"},"received_at":"2026-07-27T04:30:28.345239Z","record_id":"b4deedc417242dabdd5cd361a47a7c3ef74c3576bde038e91f0770e47ca1255a","schema_fingerprint":"4aa3821a28b0b7c2400bc59aba4bcc0a76e971dadd19610d3ad38c768e124dc7","schema_version":"edge-lab-recorder.raw.v1","sequence":null,"source":"clob_market_ws"}
{"event_at":"2026-07-27T04:30:26.994000Z","event_fingerprint":"c0f3ee2106dbdf122b8e4656749d233cf0d6d5ca5a5902f1cd891e7e43b05039","payload":{"connection_id":"0f4979d6978d463e9660b042fdcf555f","event_at":"2026-07-27T04:30:26.994000Z","event_type":"price_change","frame_hash":"d959eaf7825848ce70e6bc4caa32c5f9a9a9c3f9994acd73acbfb9d81811b857","frame_index":0,"kind":"data","monotonic_ns":228611622891041,"payload":{"event_type":"price_change","market":"0xeb66215f2e9faa6449e30a02bab5b8ed7b79a38bf961f6b24d0073c9c2419250","price_changes":[{"asset_id":"69697746896130839564035629862476347944307040470122503199396727085502753297492","best_ask":"0.41","best_bid":"0.4","hash":"2b3f13036a6bc5070f77fe28f14888cd7174342b","price":"0.39","side":"BUY","size":"13"},{"asset_id":"60386828328910021732068595344565885737045900010034836345809386672230885527307","best_ask":"0.6","best_bid":"0.59","hash":"617bd6f141d518b4c7a631a006413fa76bec37b1","price":"0.61","side":"SELL","size":"13"}],"timestamp":"1785126626994"},"payload_hash":"1b007fd62cad4a45b4b7694acf7d53c83fe39d89559af8087f0d7dbd4fc51931","raw_frame":"{\"market\":\"0xeb66215f2e9faa6449e30a02bab5b8ed7b79a38bf961f6b24d0073c9c2419250\", \"price_changes\":[{\"asset_id\":\"69697746896130839564035629862476347944307040470122503199396727085502753297492\", \"price\":\"0.39\", \"size\":\"13\", \"side\":\"BUY\", \"hash\":\"2b3f13036a6bc5070f77fe28f14888cd7174342b\", \"best_bid\":\"0.4\", \"best_ask\":\"0.41\"}, {\"asset_id\":\"60386828328910021732068595344565885737045900010034836345809386672230885527307\", \"price\":\"0.61\", \"size\":\"13\", \"side\":\"SELL\", \"hash\":\"617bd6f141d518b4c7a631a006413fa76bec37b1\", \"best_bid\":\"0.59\", \"best_ask\":\"0.6\"}], \"timestamp\":\"1785126626994\", \"event_type\":\"price_change\"}","received_at":"2026-07-27T04:30:28.353298Z","schema_version":"clob-market-ws.price_change.v1","sequence":null,"server_hash":null,"server_timestamp":"1785126626994","session_id":"e9443c7415a0419799bee9cfbb1a9e4d","source":"clob_market_ws"},"received_at":"2026-07-27T04:30:28.353298Z","record_id":"5f6396cdd6a796bab0c288baf9bb60615f8ac6326c1e83579a733260faac8f2f","schema_fingerprint":"4aa3821a28b0b7c2400bc59aba4bcc0a76e971dadd19610d3ad38c768e124dc7","schema_version":"edge-lab-recorder.raw.v1","sequence":null,"source":"clob_market_ws"}
{"event_at":"2026-07-27T04:30:26.999000Z","event_fingerprint":"9e30f93253340cbb837b90a1cd784704efe9f3d225e2e95ceecd3adb74b9749e","payload":{"connection_id":"0f4979d6978d463e9660b042fdcf555f","event_at":"2026-07-27T04:30:26.999000Z","event_type":"price_change","frame_hash":"3b0c4fbbaf81f26e55b0c3b7dd3540de01d97bc8ad104e9d6152d3d53fd2f8fe","frame_index":0,"kind":"data","monotonic_ns":228611631025541,"payload":{"event_type":"price_change","market":"0xeb66215f2e9faa6449e30a02bab5b8ed7b79a38bf961f6b24d0073c9c2419250","price_changes":[{"asset_id":"69697746896130839564035629862476347944307040470122503199396727085502753297492","best_ask":"0.41","best_bid":"0.4","hash":"e391dea0bf51a6a82a2624c189edf569efd2bb5c","price":"0.1","side":"BUY","size":"190"},{"asset_id":"60386828328910021732068595344565885737045900010034836345809386672230885527307","best_ask":"0.6","best_bid":"0.59","hash":"4bb96a888824eaa842aebbb972d3882df00a1ded","price":"0.9","side":"SELL","size":"190"}],"timestamp":"1785126626999"},"payload_hash":"ecfb1c3d113997c606fb017a7c624083c8a620ca5d74f143dc9c22dfbfdaead5","raw_frame":"{\"market\":\"0xeb66215f2e9faa6449e30a02bab5b8ed7b79a38bf961f6b24d0073c9c2419250\", \"price_changes\":[{\"asset_id\":\"69697746896130839564035629862476347944307040470122503199396727085502753297492\", \"price\":\"0.1\", \"size\":\"190\", \"side\":\"BUY\", \"hash\":\"e391dea0bf51a6a82a2624c189edf569efd2bb5c\", \"best_bid\":\"0.4\", \"best_ask\":\"0.41\"}, {\"asset_id\":\"60386828328910021732068595344565885737045900010034836345809386672230885527307\", \"price\":\"0.9\", \"size\":\"190\", \"side\":\"SELL\", \"hash\":\"4bb96a888824eaa842aebbb972d3882df00a1ded\", \"best_bid\":\"0.59\", \"best_ask\":\"0.6\"}], \"timestamp\":\"1785126626999\", \"event_type\":\"price_change\"}","received_at":"2026-07-27T04:30:28.361433Z","schema_version":"clob-market-ws.price_change.v1","sequence":null,"server_hash":null,"server_timestamp":"1785126626999","session_id":"e9443c7415a0419799bee9cfbb1a9e4d","source":"clob_market_ws"},"received_at":"2026-07-27T04:30:28.361433Z","record_id":"6aaf3b15b9204f91cf5e65e6d057d3ee18554963e578aa062b2a56fb57df56b4","schema_fingerprint":"4aa3821a28b0b7c2400bc59aba4bcc0a76e971dadd19610d3ad38c768e124dc7","schema_version":"edge-lab-recorder.raw.v1","sequence":null,"source":"clob_market_ws"}
{"event_at":"2026-07-27T04:30:27.002000Z","event_fingerprint":"55673401eb9c2c92327addf65a48fc7836149aad5b34e3923bb6cf0c3a22d53d","payload":{"connection_id":"0f4979d6978d463e9660b042fdcf555f","event_at":"2026-07-27T04:30:27.002000Z","event_type":"price_change","frame_hash":"76f422ab4ae144adf16a363d9355ef6763302d5e046add4f5619ee91bbc0c4cc","frame_index":0,"kind":"data","monotonic_ns":228611638696291,"payload":{"event_type":"price_change","market":"0xeb66215f2e9faa6449e30a02bab5b8ed7b79a38bf961f6b24d0073c9c2419250","price_changes":[{"asset_id":"69697746896130839564035629862476347944307040470122503199396727085502753297492","best_ask":"0.41","best_bid":"0.4","hash":"53045e50cbfdbdbbbb72ed4ebd68023a5ef758b9","price":"0.37","side":"BUY","size":"43.74"},{"asset_id":"60386828328910021732068595344565885737045900010034836345809386672230885527307","best_ask":"0.6","best_bid":"0.59","hash":"d792b66b5b279aed07e177322eb03a87edb032d6","price":"0.63","side":"SELL","size":"43.74"}],"timestamp":"1785126627002"},"payload_hash":"deb5133fb55742072f846d563ddb4e61d26b8c3423685fdd4f5d6ff2aea08151","raw_frame":"{\"market\":\"0xeb66215f2e9faa6449e30a02bab5b8ed7b79a38bf961f6b24d0073c9c2419250\", \"price_changes\":[{\"asset_id\":\"69697746896130839564035629862476347944307040470122503199396727085502753297492\", \"price\":\"0.37\", \"size\":\"43.74\", \"side\":\"BUY\", \"hash\":\"53045e50cbfdbdbbbb72ed4ebd68023a5ef758b9\", \"best_bid\":\"0.4\", \"best_ask\":\"0.41\"}, {\"asset_id\":\"60386828328910021732068595344565885737045900010034836345809386672230885527307\", \"price\":\"0.63\", \"size\":\"43.74\", \"side\":\"SELL\", \"hash\":\"d792b66b5b279aed07e177322eb03a87edb032d6\", \"best_bid\":\"0.59\", \"best_ask\":\"0.6\"}], \"timestamp\":\"1785126627002\", \"event_type\":\"price_change\"}","received_at":"2026-07-27T04:30:28.369105Z","schema_version":"clob-market-ws.price_change.v1","sequence":null,"server_hash":null,"server_timestamp":"1785126627002","session_id":"e9443c7415a0419799bee9cfbb1a9e4d","source":"clob_market_ws"},"received_at":"2026-07-27T04:30:28.369105Z","record_id":"76d6195cd754f1c6d3877c946b3d13b5d233f764aaa3310b59fa18f4281a4e0c","schema_fingerprint":"4aa3821a28b0b7c2400bc59aba4bcc0a76e971dadd19610d3ad38c768e124dc7","schema_version":"edge-lab-recorder.raw.v1","sequence":null,"source":"clob_market_ws"}
{"event_at":"2026-07-27T04:30:27.003000Z","event_fingerprint":"2abe3554ab436aec4019a757ddb14beb26ea01ebed4f8bf7795cffed6d37cb86","payload":{"connection_id":"0f4979d6978d463e9660b042fdcf555f","event_at":"2026-07-27T04:30:27.003000Z","event_type":"price_change","frame_hash":"b9c25d644d2cdd0fcefaa7ac8a2415e487586fbe2068447deb914f7025ccba1e","frame_index":0,"kind":"data","monotonic_ns":228611645569916,"payload":{"event_type":"price_change","market":"0xeb66215f2e9faa6449e30a02bab5b8ed7b79a38bf961f6b24d0073c9c2419250","price_changes":[{"asset_id":"69697746896130839564035629862476347944307040470122503199396727085502753297492","best_ask":"0.41","best_bid":"0.4","hash":"a7439010eda130584e0e84e3e5290b83ec75ffe1","price":"0.07","side":"BUY","size":"556.14"},{"asset_id":"60386828328910021732068595344565885737045900010034836345809386672230885527307","best_ask":"0.6","best_bid":"0.59","hash":"d3ae4671441107f4fc69e79eb7db14d1a897869a","price":"0.93","side":"SELL","size":"556.14"}],"timestamp":"1785126627003"},"payload_hash":"3f5a4ded598af3a5235fa196b4cd9f4d55898f49db706547e7436acf66efb1ec","raw_frame":"{\"market\":\"0xeb66215f2e9faa6449e30a02bab5b8ed7b79a38bf961f6b24d0073c9c2419250\", \"price_changes\":[{\"asset_id\":\"69697746896130839564035629862476347944307040470122503199396727085502753297492\", \"price\":\"0.07\", \"size\":\"556.14\", \"side\":\"BUY\", \"hash\":\"a7439010eda130584e0e84e3e5290b83ec75ffe1\", \"best_bid\":\"0.4\", \"best_ask\":\"0.41\"}, {\"asset_id\":\"60386828328910021732068595344565885737045900010034836345809386672230885527307\", \"price\":\"0.93\", \"size\":\"556.14\", \"side\":\"SELL\", \"hash\":\"d3ae4671441107f4fc69e79eb7db14d1a897869a\", \"best_bid\":\"0.59\", \"best_ask\":\"0.6\"}], \"timestamp\":\"1785126627003\", \"event_type\":\"price_change\"}","received_at":"2026-07-27T04:30:28.375979Z","schema_version":"clob-market-ws.price_change.v1","sequence":null,"server_hash":null,"server_timestamp":"1785126627003","session_id":"e9443c7415a0419799bee9cfbb1a9e4d","source":"clob_market_ws"},"received_at":"2026-07-27T04:30:28.375979Z","record_id":"2207c079cb06458ca876a92ad65578b6a44c1a959c7e04e818b22b8c101cc49e","schema_fingerprint":"4aa3821a28b0b7c2400bc59aba4bcc0a76e971dadd19610d3ad38c768e124dc7","schema_version":"edge-lab-recorder.raw.v1","sequence":null,"source":"clob_market_ws"}
{"event_at":"2026-07-27T04:30:27.004000Z","event_fingerprint":"bdd0cb9e51f6f2ce78c22afef032187a8000830c0e7d66ad8f5e46e36bfa81b3","payload":{"connection_id":"0f4979d6978d463e9660b042fdcf555f","event_at":"2026-07-27T04:30:27.004000Z","event_type":"price_change","frame_hash":"c657af692f939e126a4d970c1c09a53a61f8a7ae3266f5bf3e3eb11841d1e25e","frame_index":0,"kind":"data","monotonic_ns":228611655234500,"payload":{"event_type":"price_change","market":"0xeb66215f2e9faa6449e30a02bab5b8ed7b79a38bf961f6b24d0073c9c2419250","price_changes":[{"asset_id":"69697746896130839564035629862476347944307040470122503199396727085502753297492","best_ask":"0.41","best_bid":"0.4","hash":"913340d4d0797809c282fdd07ac0a5799dfe73b0","price":"0.09","side":"BUY","size":"515"},{"asset_id":"60386828328910021732068595344565885737045900010034836345809386672230885527307","best_ask":"0.6","best_bid":"0.59","hash":"39bf354566d9d66d1445cd5b2fb91f92d869c161","price":"0.91","side":"SELL","size":"515"}],"timestamp":"1785126627004"},"payload_hash":"9da9786ba51853cf7fba409a2ce98c31fc132c53186faf12f3ccd6a2a79f47d6","raw_frame":"{\"market\":\"0xeb66215f2e9faa6449e30a02bab5b8ed7b79a38bf961f6b24d0073c9c2419250\", \"price_changes\":[{\"asset_id\":\"69697746896130839564035629862476347944307040470122503199396727085502753297492\", \"price\":\"0.09\", \"size\":\"515\", \"side\":\"BUY\", \"hash\":\"913340d4d0797809c282fdd07ac0a5799dfe73b0\", \"best_bid\":\"0.4\", \"best_ask\":\"0.41\"}, {\"asset_id\":\"60386828328910021732068595344565885737045900010034836345809386672230885527307\", \"price\":\"0.91\", \"size\":\"515\", \"side\":\"SELL\", \"hash\":\"39bf354566d9d66d1445cd5b2fb91f92d869c161\", \"best_bid\":\"0.59\", \"best_ask\":\"0.6\"}], \"timestamp\":\"1785126627004\", \"event_type\":\"price_change\"}","received_at":"2026-07-27T04:30:28.385634Z","schema_version":"clob-market-ws.price_change.v1","sequence":null,"server_hash":null,"server_timestamp":"1785126627004","session_id":"e9443c7415a0419799bee9cfbb1a9e4d","source":"clob_market_ws"},"received_at":"2026-07-27T04:30:28.385634Z","record_id":"5f2e0982becfe3355c14048ad53a30a3b0f6863dc5438cf1a4e253daf967232b","schema_fingerprint":"4aa3821a28b0b7c2400bc59aba4bcc0a76e971dadd19610d3ad38c768e124dc7","schema_version":"edge-lab-recorder.raw.v1","sequence":null,"source":"clob_market_ws"}
{"event_at":"2026-07-27T04:30:27.005000Z","event_fingerprint":"53bdd5a7b3d55aba4608458fbe5c1d7227dbde134379263bc75da26960e96d17","payload":{"connection_id":"0f4979d6978d463e9660b042fdcf555f","event_at":"2026-07-27T04:30:27.005000Z","event_type":"price_change","frame_hash":"27408f84a5719a63a00e31e7675576756c8d2e9e5020deb4254c811b88889530","frame_index":0,"kind":"data","monotonic_ns":228611665544708,"payload":{"event_type":"price_change","market":"0xeb66215f2e9faa6449e30a02bab5b8ed7b79a38bf961f6b24d0073c9c2419250","price_changes":[{"asset_id":"69697746896130839564035629862476347944307040470122503199396727085502753297492","best_ask":"0.41","best_bid":"0.4","hash":"b33e5c93f1238fd879797503e2a0a29f7793e758","price":"0.11","side":"BUY","size":"13"},{"asset_id":"60386828328910021732068595344565885737045900010034836345809386672230885527307","best_ask":"0.6","best_bid":"0.59","hash":"5acb1ded91983e9417ed7d8fd82f0564dfa0ae81","price":"0.89","side":"SELL","size":"13"}],"timestamp":"1785126627005"},"payload_hash":"30023fa71b3e024ab2d7a6cf310e2ab2efd95928217e66586d0851c60b8be39f","raw_frame":"{\"market\":\"0xeb66215f2e9faa6449e30a02bab5b8ed7b79a38bf961f6b24d0073c9c2419250\", \"price_changes\":[{\"asset_id\":\"69697746896130839564035629862476347944307040470122503199396727085502753297492\", \"price\":\"0.11\", \"size\":\"13\", \"side\":\"BUY\", \"hash\":\"b33e5c93f1238fd879797503e2a0a29f7793e758\", \"best_bid\":\"0.4\", \"best_ask\":\"0.41\"}, {\"asset_id\":\"60386828328910021732068595344565885737045900010034836345809386672230885527307\", \"price\":\"0.89\", \"size\":\"13\", \"side\":\"SELL\", \"hash\":\"5acb1ded91983e9417ed7d8fd82f0564dfa0ae81\", \"best_bid\":\"0.59\", \"best_ask\":\"0.6\"}], \"timestamp\":\"1785126627005\", \"event_type\":\"price_change\"}","received_at":"2026-07-27T04:30:28.395952Z","schema_version":"clob-market-ws.price_change.v1","sequence":null,"server_hash":null,"server_timestamp":"1785126627005","session_id":"e9443c7415a0419799bee9cfbb1a9e4d","source":"clob_market_ws"},"received_at":"2026-07-27T04:30:28.395952Z","record_id":"f767978c71fe2b1584eea1541ec45a04a070d7b316c5d09d721443ad049014db","schema_fingerprint":"4aa3821a28b0b7c2400bc59aba4bcc0a76e971dadd19610d3ad38c768e124dc7","schema_version":"edge-lab-recorder.raw.v1","sequence":null,"source":"clob_market_ws"}
{"event_at":"2026-07-27T04:30:27.006000Z","event_fingerprint":"286581a91955bb08998b4b9c15cd17f4ec3e34b85ff799d642cf7e251f610bc0","payload":{"connection_id":"0f4979d6978d463e9660b042fdcf555f","event_at":"2026-07-27T04:30:27.006000Z","event_type":"price_change","frame_hash":"3023c85488d60f87e2819c96326585a56e1be6624f5b1e39863931f692032fd5","frame_index":0,"kind":"data","monotonic_ns":228611675718250,"payload":{"event_type":"price_change","market":"0xeb66215f2e9faa6449e30a02bab5b8ed7b79a38bf961f6b24d0073c9c2419250","price_changes":[{"asset_id":"69697746896130839564035629862476347944307040470122503199396727085502753297492","best_ask":"0.41","best_bid":"0.4","hash":"0b25c042a0dff39f3a01390a37e34c4c9e8f7fa5","price":"0.08","side":"BUY","size":"608"},{"asset_id":"60386828328910021732068595344565885737045900010034836345809386672230885527307","best_ask":"0.6","best_bid":"0.59","hash":"d0286f2531dc00c512e6c47bbb8157112d0737cf","price":"0.92","side":"SELL","size":"608"}],"timestamp":"1785126627006"},"payload_hash":"82a18dad4bfbe174c9fee7d1855fee5d5ac11a13d9a5bfee1f0d82f2c323e619","raw_frame":"{\"market\":\"0xeb66215f2e9faa6449e30a02bab5b8ed7b79a38bf961f6b24d0073c9c2419250\", \"price_changes\":[{\"asset_id\":\"69697746896130839564035629862476347944307040470122503199396727085502753297492\", \"price\":\"0.08\", \"size\":\"608\", \"side\":\"BUY\", \"hash\":\"0b25c042a0dff39f3a01390a37e34c4c9e8f7fa5\", \"best_bid\":\"0.4\", \"best_ask\":\"0.41\"}, {\"asset_id\":\"60386828328910021732068595344565885737045900010034836345809386672230885527307\", \"price\":\"0.92\", \"size\":\"608\", \"side\":\"SELL\", \"hash\":\"d0286f2531dc00c512e6c47bbb8157112d0737cf\", \"best_bid\":\"0.59\", \"best_ask\":\"0.6\"}], \"timestamp\":\"1785126627006\", \"event_type\":\"price_change\"}","received_at":"2026-07-27T04:30:28.406125Z","schema_version":"clob-market-ws.price_change.v1","sequence":null,"server_hash":null,"server_timestamp":"1785126627006","session_id":"e9443c7415a0419799bee9cfbb1a9e4d","source":"clob_market_ws"},"received_at":"2026-07-27T04:30:28.406125Z","record_id":"e10e7519cafb6c7078ff468698f9929d3a31ae0ef05f118b0fea3dc6490a9cb8","schema_fingerprint":"4aa3821a28b0b7c2400bc59aba4bcc0a76e971dadd19610d3ad38c768e124dc7","schema_version":"edge-lab-recorder.raw.v1","sequence":null,"source":"clob_market_ws"}
{"event_at":"2026-07-27T04:30:27.016000Z","event_fingerprint":"18dfad4cc615917961dec42b82a213aaadb21959b15770bbf306a18a3f5c9547","payload":{"connection_id":"0f4979d6978d463e9660b042fdcf555f","event_at":"2026-07-27T04:30:27.016000Z","event_type":"price_change","frame_hash":"21aff693cad952ea913b0fe839c4df30e4eed64f0c3187c97156bf6406661924","frame_index":0,"kind":"data","monotonic_ns":228611699784750,"payload":{"event_type":"price_change","market":"0xeb66215f2e9faa6449e30a02bab5b8ed7b79a38bf961f6b24d0073c9c2419250","price_changes":[{"asset_id":"60386828328910021732068595344565885737045900010034836345809386672230885527307","best_ask":"0.6","best_bid":"0.59","hash":"6f4ca21568eec22fbedac02e15e7ee505f1756be","price":"0.45","side":"BUY","size":"68"},{"asset_id":"69697746896130839564035629862476347944307040470122503199396727085502753297492","best_ask":"0.41","best_bid":"0.4","hash":"5ba5d3f00735dd775098f71c89e0e1c9730a9044","price":"0.55","side":"SELL","size":"68"}],"timestamp":"1785126627016"},"payload_hash":"679a562ef3a7c4c722c5c78984cc78011d65e22fd31a5deeda4b1ec9c3d40c49","raw_frame":"{\"market\":\"0xeb66215f2e9faa6449e30a02bab5b8ed7b79a38bf961f6b24d0073c9c2419250\", \"price_changes\":[{\"asset_id\":\"60386828328910021732068595344565885737045900010034836345809386672230885527307\", \"price\":\"0.45\", \"size\":\"68\", \"side\":\"BUY\", \"hash\":\"6f4ca21568eec22fbedac02e15e7ee505f1756be\", \"best_bid\":\"0.59\", \"best_ask\":\"0.6\"}, {\"asset_id\":\"69697746896130839564035629862476347944307040470122503199396727085502753297492\", \"price\":\"0.55\", \"size\":\"68\", \"side\":\"SELL\", \"hash\":\"5ba5d3f00735dd775098f71c89e0e1c9730a9044\", \"best_bid\":\"0.4\", \"best_ask\":\"0.41\"}], \"timestamp\":\"1785126627016\", \"event_type\":\"price_change\"}","received_at":"2026-07-27T04:30:28.430194Z","schema_version":"clob-market-ws.price_change.v1","sequence":null,"server_hash":null,"server_timestamp":"1785126627016","session_id":"e9443c7415a0419799bee9cfbb1a9e4d","source":"clob_market_ws"},"received_at":"2026-07-27T04:30:28.430194Z","record_id":"7e4881895cb7be09577b564d0d290a4e6d94680162154fd66b422807954bf375","schema_fingerprint":"4aa3821a28b0b7c2400bc59aba4bcc0a76e971dadd19610d3ad38c768e124dc7","schema_version":"edge-lab-recorder.raw.v1","sequence":null,"source":"clob_market_ws"}
{"event_at":"2026-07-27T04:30:27.021000Z","event_fingerprint":"19da19a2bac2d76ad4799a0c8cb70e19ed1f660411fa9fd7ed0c6b1434815834","payload":{"connection_id":"0f4979d6978d463e9660b042fdcf555f","event_at":"2026-07-27T04:30:27.021000Z","event_type":"price_change","frame_hash":"201ce52c32a847c0c4ef7e393d8a7408cdcbbbdf802e51f2f5b6274e32991aea","frame_index":0,"kind":"data","monotonic_ns":228611714456166,"payload":{"event_type":"price_change","market":"0xeb66215f2e9faa6449e30a02bab5b8ed7b79a38bf961f6b24d0073c9c2419250","price_changes":[{"asset_id":"69697746896130839564035629862476347944307040470122503199396727085502753297492","best_ask":"0.41","best_bid":"0.4","hash":"50fc7331c620efb0c2eb087bf33490fd11c16dce","price":"0.01","side":"BUY","size":"7738.02"},{"asset_id":"60386828328910021732068595344565885737045900010034836345809386672230885527307","best_ask":"0.6","best_bid":"0.59","hash":"2bcbd1cd593c835200904cbec11b415a75299a54","price":"0.99","side":"SELL","size":"7738.02"}],"timestamp":"1785126627021"},"payload_hash":"4438fa252af3f45b89b87b402c2df5e9dfcf4e4964bcdc46bc6dc400e16841db","raw_frame":"{\"market\":\"0xeb66215f2e9faa6449e30a02bab5b8ed7b79a38bf961f6b24d0073c9c2419250\", \"price_changes\":[{\"asset_id\":\"69697746896130839564035629862476347944307040470122503199396727085502753297492\", \"price\":\"0.01\", \"size\":\"7738.02\", \"side\":\"BUY\", \"hash\":\"50fc7331c620efb0c2eb087bf33490fd11c16dce\", \"best_bid\":\"0.4\", \"best_ask\":\"0.41\"}, {\"asset_id\":\"60386828328910021732068595344565885737045900010034836345809386672230885527307\", \"price\":\"0.99\", \"size\":\"7738.02\", \"side\":\"SELL\", \"hash\":\"2bcbd1cd593c835200904cbec11b415a75299a54\", \"best_bid\":\"0.59\", \"best_ask\":\"0.6\"}], \"timestamp\":\"1785126627021\", \"event_type\":\"price_change\"}","received_at":"2026-07-27T04:30:28.444866Z","schema_version":"clob-market-ws.price_change.v1","sequence":null,"server_hash":null,"server_timestamp":"1785126627021","session_id":"e9443c7415a0419799bee9cfbb1a9e4d","source":"clob_market_ws"},"received_at":"2026-07-27T04:30:28.444866Z","record_id":"90bdf02e14a5a1c205d9b574556ea4d956c3ac1e7d13a51f9596cd72631076d6","schema_fingerprint":"4aa3821a28b0b7c2400bc59aba4bcc0a76e971dadd19610d3ad38c768e124dc7","schema_version":"edge-lab-recorder.raw.v1","sequence":null,"source":"clob_market_ws"}
{"event_at":"2026-07-27T04:30:27.036000Z","event_fingerprint":"54aa74b528b3afe99338b70fc9034b9eda2c05cb52cd671649ae08a02c1c5c96","payload":{"connection_id":"0f4979d6978d463e9660b042fdcf555f","event_at":"2026-07-27T04:30:27.036000Z","event_type":"price_change","frame_hash":"e3208de7a9b3a1e5c4c2942e88fc75ae8468a2d7d0f302ab4587d6cabd3b6453","frame_index":0,"kind":"data","monotonic_ns":228611722930833,"payload":{"event_type":"price_change","market":"0xeb66215f2e9faa6449e30a02bab5b8ed7b79a38bf961f6b24d0073c9c2419250","price_changes":[{"asset_id":"60386828328910021732068595344565885737045900010034836345809386672230885527307","best_ask":"0.6","best_bid":"0.59","hash":"78b883065c0b490d8ed80f4abfca3e33fd5f012f","price":"0.58","side":"BUY","size":"35.01"},{"asset_id":"69697746896130839564035629862476347944307040470122503199396727085502753297492","best_ask":"0.41","best_bid":"0.4","hash":"390935e4b0db2ffd34e38418ada1eaa1d7b2f107","price":"0.42","side":"SELL","size":"35.01"}],"timestamp":"1785126627036"},"payload_hash":"6d611d502cd9064eefd2d35e38d1283f8166f3b06dd4d4e714fe5828126c6b3c","raw_frame":"{\"market\":\"0xeb66215f2e9faa6449e30a02bab5b8ed7b79a38bf961f6b24d0073c9c2419250\", \"price_changes\":[{\"asset_id\":\"60386828328910021732068595344565885737045900010034836345809386672230885527307\", \"price\":\"0.58\", \"size\":\"35.01\", \"side\":\"BUY\", \"hash\":\"78b883065c0b490d8ed80f4abfca3e33fd5f012f\", \"best_bid\":\"0.59\", \"best_ask\":\"0.6\"}, {\"asset_id\":\"69697746896130839564035629862476347944307040470122503199396727085502753297492\", \"price\":\"0.42\", \"size\":\"35.01\", \"side\":\"SELL\", \"hash\":\"390935e4b0db2ffd34e38418ada1eaa1d7b2f107\", \"best_bid\":\"0.4\", \"best_ask\":\"0.41\"}], \"timestamp\":\"1785126627036\", \"event_type\":\"price_change\"}","received_at":"2026-07-27T04:30:28.453339Z","schema_version":"clob-market-ws.price_change.v1","sequence":null,"server_hash":null,"server_timestamp":"1785126627036","session_id":"e9443c7415a0419799bee9cfbb1a9e4d","source":"clob_market_ws"},"received_at":"2026-07-27T04:30:28.453339Z","record_id":"bb03fa186ace139ae8e4cc32136c079e7b2a53c80565abaf611d6689650b3fda","schema_fingerprint":"4aa3821a28b0b7c2400bc59aba4bcc0a76e971dadd19610d3ad38c768e124dc7","schema_version":"edge-lab-recorder.raw.v1","sequence":null,"source":"clob_market_ws"}
{"event_at":"2026-07-27T04:30:27.036000Z","event_fingerprint":"efe0b0c40f6562d901899afa58a9ff2798caaea69d1cc1ddca4d252352d4be9c","payload":{"connection_id":"0f4979d6978d463e9660b042fdcf555f","event_at":"2026-07-27T04:30:27.036000Z","event_type":"price_change","frame_hash":"500d7d28631dfa88a3ad842ce17d3d26a7e3924fc9fef55cad8bcbbe8607c84c","frame_index":0,"kind":"data","monotonic_ns":228611731584583,"payload":{"event_type":"price_change","market":"0xeb66215f2e9faa6449e30a02bab5b8ed7b79a38bf961f6b24d0073c9c2419250","price_changes":[{"asset_id":"69697746896130839564035629862476347944307040470122503199396727085502753297492","best_ask":"0.41","best_bid":"0.4","hash":"390935e4b0db2ffd34e38418ada1eaa1d7b2f107","price":"0.37","side":"BUY","size":"33.74"},{"asset_id":"60386828328910021732068595344565885737045900010034836345809386672230885527307","best_ask":"0.6","best_bid":"0.59","hash":"78b883065c0b490d8ed80f4abfca3e33fd5f012f","price":"0.63","side":"SELL","size":"33.74"}],"timestamp":"1785126627036"},"payload_hash":"c340996bbb6eb9a76e86d77a6d585c3a86b455f4246da2f61fa33a40eb19568c","raw_frame":"{\"market\":\"0xeb66215f2e9faa6449e30a02bab5b8ed7b79a38bf961f6b24d0073c9c2419250\", \"price_changes\":[{\"asset_id\":\"69697746896130839564035629862476347944307040470122503199396727085502753297492\", \"price\":\"0.37\", \"size\":\"33.74\", \"side\":\"BUY\", \"hash\":\"390935e4b0db2ffd34e38418ada1eaa1d7b2f107\", \"best_bid\":\"0.4\", \"best_ask\":\"0.41\"}, {\"asset_id\":\"60386828328910021732068595344565885737045900010034836345809386672230885527307\", \"price\":\"0.63\", \"size\":\"33.74\", \"side\":\"SELL\", \"hash\":\"78b883065c0b490d8ed80f4abfca3e33fd5f012f\", \"best_bid\":\"0.59\", \"best_ask\":\"0.6\"}], \"timestamp\":\"1785126627036\", \"event_type\":\"price_change\"}","received_at":"2026-07-27T04:30:28.461992Z","schema_version":"clob-market-ws.price_change.v1","sequence":null,"server_hash":null,"server_timestamp":"1785126627036","session_id":"e9443c7415a0419799bee9cfbb1a9e4d","source":"clob_market_ws"},"received_at":"2026-07-27T04:30:28.461992Z","record_id":"cde49f0690b4b0ad52bd8719f220920d1a6653ee269e37e5233b0147bbb62c6e","schema_fingerprint":"4aa3821a28b0b7c2400bc59aba4bcc0a76e971dadd19610d3ad38c768e124dc7","schema_version":"edge-lab-recorder.raw.v1","sequence":null,"source":"clob_market_ws"}
{"event_at":"2026-07-27T04:30:27.042000Z","event_fingerprint":"54da4f1e8128588538579948e046f5a140a3c1f85444a8bc1251841dccafd428","payload":{"connection_id":"0f4979d6978d463e9660b042fdcf555f","event_at":"2026-07-27T04:30:27.042000Z","event_type":"price_change","frame_hash":"8121f68a37f2eb940b6dda300eac5618ccc105e0e61b971dca36470b0f0b8766","frame_index":0,"kind":"data","monotonic_ns":228611742805000,"payload":{"event_type":"price_change","market":"0xeb66215f2e9faa6449e30a02bab5b8ed7b79a38bf961f6b24d0073c9c2419250","price_changes":[{"asset_id":"69697746896130839564035629862476347944307040470122503199396727085502753297492","best_ask":"0.41","best_bid":"0.4","hash":"b6a676b01921b36ac1888b69a12c68184fa1c4d2","price":"0.31","side":"BUY","size":"57"},{"asset_id":"60386828328910021732068595344565885737045900010034836345809386672230885527307","best_ask":"0.6","best_bid":"0.59","hash":"d6d6c7f35bf1aab094c592bb0160ef0b3a32af14","price":"0.69","side":"SELL","size":"57"}],"timestamp":"1785126627042"},"payload_hash":"6ad765c1dcdb6dac378373ea6a3b93557dbe8c64bd53b75684225f53e2e11c30","raw_frame":"{\"market\":\"0xeb66215f2e9faa6449e30a02bab5b8ed7b79a38bf961f6b24d0073c9c2419250\", \"price_changes\":[{\"asset_id\":\"69697746896130839564035629862476347944307040470122503199396727085502753297492\", \"price\":\"0.31\", \"size\":\"57\", \"side\":\"BUY\", \"hash\":\"b6a676b01921b36ac1888b69a12c68184fa1c4d2\", \"best_bid\":\"0.4\", \"best_ask\":\"0.41\"}, {\"asset_id\":\"60386828328910021732068595344565885737045900010034836345809386672230885527307\", \"price\":\"0.69\", \"size\":\"57\", \"side\":\"SELL\", \"hash\":\"d6d6c7f35bf1aab094c592bb0160ef0b3a32af14\", \"best_bid\":\"0.59\", \"best_ask\":\"0.6\"}], \"timestamp\":\"1785126627042\", \"event_type\":\"price_change\"}","received_at":"2026-07-27T04:30:28.473212Z","schema_version":"clob-market-ws.price_change.v1","sequence":null,"server_hash":null,"server_timestamp":"1785126627042","session_id":"e9443c7415a0419799bee9cfbb1a9e4d","source":"clob_market_ws"},"received_at":"2026-07-27T04:30:28.473212Z","record_id":"a78dcd90d547841d52c7c6ca7e1fb61c008ab6fa6223e48ee2ba8265ce08a5e6","schema_fingerprint":"4aa3821a28b0b7c2400bc59aba4bcc0a76e971dadd19610d3ad38c768e124dc7","schema_version":"edge-lab-recorder.raw.v1","sequence":null,"source":"clob_market_ws"}
{"event_at":"2026-07-27T04:30:27.043000Z","event_fingerprint":"53b0d4a314d90ff4c8e7b9aaac1164c4fc99c1fcb00c01c3e8357fb7523d18a8","payload":{"connection_id":"0f4979d6978d463e9660b042fdcf555f","event_at":"2026-07-27T04:30:27.043000Z","event_type":"price_change","frame_hash":"1e51d0844d34de7c3b7236acd5cfff729b28f244703c2a0e1337783fadbc238f","frame_index":0,"kind":"data","monotonic_ns":228611751514458,"payload":{"event_type":"price_change","market":"0xeb66215f2e9faa6449e30a02bab5b8ed7b79a38bf961f6b24d0073c9c2419250","price_changes":[{"asset_id":"60386828328910021732068595344565885737045900010034836345809386672230885527307","best_ask":"0.6","best_bid":"0.59","hash":"92e6d806f140f44e28716c35b7aecc27e70b8b95","price":"0.03","side":"BUY","size":"1068.1"},{"asset_id":"69697746896130839564035629862476347944307040470122503199396727085502753297492","best_ask":"0.41","best_bid":"0.4","hash":"3c4229fa5d17618284d4c4c0e4854114db37f4e9","price":"0.97","side":"SELL","size":"1068.1"}],"timestamp":"1785126627043"},"payload_hash":"02954d9b358c25dc38efb8a333bd948fee7c5bf9babc9fd4e80240f776663e5e","raw_frame":"{\"market\":\"0xeb66215f2e9faa6449e30a02bab5b8ed7b79a38bf961f6b24d0073c9c2419250\", \"price_changes\":[{\"asset_id\":\"60386828328910021732068595344565885737045900010034836345809386672230885527307\", \"price\":\"0.03\", \"size\":\"1068.1\", \"side\":\"BUY\", \"hash\":\"92e6d806f140f44e28716c35b7aecc27e70b8b95\", \"best_bid\":\"0.59\", \"best_ask\":\"0.6\"}, {\"asset_id\":\"69697746896130839564035629862476347944307040470122503199396727085502753297492\", \"price\":\"0.97\", \"size\":\"1068.1\", \"side\":\"SELL\", \"hash\":\"3c4229fa5d17618284d4c4c0e4854114db37f4e9\", \"best_bid\":\"0.4\", \"best_ask\":\"0.41\"}], \"timestamp\":\"1785126627043\", \"event_type\":\"price_change\"}","received_at":"2026-07-27T04:30:28.481922Z","schema_version":"clob-market-ws.price_change.v1","sequence":null,"server_hash":null,"server_timestamp":"1785126627043","session_id":"e9443c7415a0419799bee9cfbb1a9e4d","source":"clob_market_ws"},"received_at":"2026-07-27T04:30:28.481922Z","record_id":"ba692866973de1dbadd336da318729a2596b9a19d92c2fbff2f693bf4e71ee87","schema_fingerprint":"4aa3821a28b0b7c2400bc59aba4bcc0a76e971dadd19610d3ad38c768e124dc7","schema_version":"edge-lab-recorder.raw.v1","sequence":null,"source":"clob_market_ws"}
{"event_at":"2026-07-27T04:30:27.045000Z","event_fingerprint":"9d2a7f41d1c355270858db1874ffc57581c2940263c9a81d78533554379094c8","payload":{"connection_id":"0f4979d6978d463e9660b042fdcf555f","event_at":"2026-07-27T04:30:27.045000Z","event_type":"price_change","frame_hash":"4cc2bc9a4df845444519a186a42f8ef2353258bfce0a549a9c7811b6f6d655a7","frame_index":0,"kind":"data","monotonic_ns":228611765810708,"payload":{"event_type":"price_change","market":"0xeb66215f2e9faa6449e30a02bab5b8ed7b79a38bf961f6b24d0073c9c2419250","price_changes":[{"asset_id":"69697746896130839564035629862476347944307040470122503199396727085502753297492","best_ask":"0.41","best_bid":"0.4","hash":"b2d3045a9a1fd7d1b7fcd7656921ed5982065264","price":"0.01","side":"BUY","size":"7733.02"},{"asset_id":"60386828328910021732068595344565885737045900010034836345809386672230885527307","best_ask":"0.6","best_bid":"0.59","hash":"5bc35af4d7c48c3f60016b4910484b3a915a613f","price":"0.99","side":"SELL","size":"7733.02"}],"timestamp":"1785126627045"},"payload_hash":"42ca9ab499eb1b6bd0f7b635d7e9fe08cc360b6cc1a215fda7e9e892281a3b87","raw_frame":"{\"market\":\"0xeb66215f2e9faa6449e30a02bab5b8ed7b79a38bf961f6b24d0073c9c2419250\", \"price_changes\":[{\"asset_id\":\"69697746896130839564035629862476347944307040470122503199396727085502753297492\", \"price\":\"0.01\", \"size\":\"7733.02\", \"side\":\"BUY\", \"hash\":\"b2d3045a9a1fd7d1b7fcd7656921ed5982065264\", \"best_bid\":\"0.4\", \"best_ask\":\"0.41\"}, {\"asset_id\":\"60386828328910021732068595344565885737045900010034836345809386672230885527307\", \"price\":\"0.99\", \"size\":\"7733.02\", \"side\":\"SELL\", \"hash\":\"5bc35af4d7c48c3f60016b4910484b3a915a613f\", \"best_bid\":\"0.59\", \"best_ask\":\"0.6\"}], \"timestamp\":\"1785126627045\", \"event_type\":\"price_change\"}","received_at":"2026-07-27T04:30:28.496216Z","schema_version":"clob-market-ws.price_change.v1","sequence":null,"server_hash":null,"server_timestamp":"1785126627045","session_id":"e9443c7415a0419799bee9cfbb1a9e4d","source":"clob_market_ws"},"received_at":"2026-07-27T04:30:28.496216Z","record_id":"2fc5b68a14203e4b366ccf108cd3a5f5234714fd504b6a4b5a9f3d9d2a1e9b6c","schema_fingerprint":"4aa3821a28b0b7c2400bc59aba4bcc0a76e971dadd19610d3ad38c768e124dc7","schema_version":"edge-lab-recorder.raw.v1","sequence":null,"source":"clob_market_ws"}
{"event_at":"2026-07-27T04:30:27.050000Z","event_fingerprint":"997e2b57487df4cf63bcf20ce4bf65bbeed6914742c33f2fe1e8a966f961a1fa","payload":{"connection_id":"0f4979d6978d463e9660b042fdcf555f","event_at":"2026-07-27T04:30:27.050000Z","event_type":"price_change","frame_hash":"55860260da17a23f2ee262581a53a555d4cd129b02bd8a10a7ccc259d027a607","frame_index":0,"kind":"data","monotonic_ns":228611786232458,"payload":{"event_type":"price_change","market":"0xeb66215f2e9faa6449e30a02bab5b8ed7b79a38bf961f6b24d0073c9c2419250","price_changes":[{"asset_id":"69697746896130839564035629862476347944307040470122503199396727085502753297492","best_ask":"0.41","best_bid":"0.4","hash":"1c8fc3b3254e58561426464ccad60a16eb686796","price":"0.05","side":"BUY","size":"618.2"},{"asset_id":"60386828328910021732068595344565885737045900010034836345809386672230885527307","best_ask":"0.6","best_bid":"0.59","hash":"577387947a2b1a88a1f6b76f1de486e6984b2b69","price":"0.95","side":"SELL","size":"618.2"}],"timestamp":"1785126627050"},"payload_hash":"12af6946603e6482b714574ae9888a68eb6ef38f528435dd830db8ef2e95c79e","raw_frame":"{\"market\":\"0xeb66215f2e9faa6449e30a02bab5b8ed7b79a38bf961f6b24d0073c9c2419250\", \"price_changes\":[{\"asset_id\":\"69697746896130839564035629862476347944307040470122503199396727085502753297492\", \"price\":\"0.05\", \"size\":\"618.2\", \"side\":\"BUY\", \"hash\":\"1c8fc3b3254e58561426464ccad60a16eb686796\", \"best_bid\":\"0.4\", \"best_ask\":\"0.41\"}, {\"asset_id\":\"60386828328910021732068595344565885737045900010034836345809386672230885527307\", \"price\":\"0.95\", \"size\":\"618.2\", \"side\":\"SELL\", \"hash\":\"577387947a2b1a88a1f6b76f1de486e6984b2b69\", \"best_bid\":\"0.59\", \"best_ask\":\"0.6\"}], \"timestamp\":\"1785126627050\", \"event_type\":\"price_change\"}","received_at":"2026-07-27T04:30:28.516643Z","schema_version":"clob-market-ws.price_change.v1","sequence":null,"server_hash":null,"server_timestamp":"1785126627050","session_id":"e9443c7415a0419799bee9cfbb1a9e4d","source":"clob_market_ws"},"received_at":"2026-07-27T04:30:28.516643Z","record_id":"710593f91ebc787bb056e3abb6ea0d596a7dfeecd8907a6084e645326547283b","schema_fingerprint":"4aa3821a28b0b7c2400bc59aba4bcc0a76e971dadd19610d3ad38c768e124dc7","schema_version":"edge-lab-recorder.raw.v1","sequence":null,"source":"clob_market_ws"}
{"event_at":"2026-07-27T04:30:27.061000Z","event_fingerprint":"356d69ad20de6c3648f8626c115b433366a4329024bf9314835ae23cdf31e311","payload":{"connection_id":"0f4979d6978d463e9660b042fdcf555f","event_at":"2026-07-27T04:30:27.061000Z","event_type":"price_change","frame_hash":"04e268c519f8265a6d29396e69094214d444dee540a17fab8f1374c7d7fc5003","frame_index":0,"kind":"data","monotonic_ns":228611801173833,"payload":{"event_type":"price_change","market":"0xeb66215f2e9faa6449e30a02bab5b8ed7b79a38bf961f6b24d0073c9c2419250","price_changes":[{"asset_id":"60386828328910021732068595344565885737045900010034836345809386672230885527307","best_ask":"0.6","best_bid":"0.59","hash":"0bcedc519ef585dee5f98ca48e6c11a3888ff851","price":"0.46","side":"BUY","size":"26"},{"asset_id":"69697746896130839564035629862476347944307040470122503199396727085502753297492","best_ask":"0.41","best_bid":"0.4","hash":"bc756b07628c970440f2f4c6ced95b2135a210f6","price":"0.54","side":"SELL","size":"26"}],"timestamp":"1785126627061"},"payload_hash":"37e06ce88c2e79f5f14fcf7cc36298a6bc80dcd1fa9bde3d7668e3c268decdf3","raw_frame":"{\"market\":\"0xeb66215f2e9faa6449e30a02bab5b8ed7b79a38bf961f6b24d0073c9c2419250\", \"price_changes\":[{\"asset_id\":\"60386828328910021732068595344565885737045900010034836345809386672230885527307\", \"price\":\"0.46\", \"size\":\"26\", \"side\":\"BUY\", \"hash\":\"0bcedc519ef585dee5f98ca48e6c11a3888ff851\", \"best_bid\":\"0.59\", \"best_ask\":\"0.6\"}, {\"asset_id\":\"69697746896130839564035629862476347944307040470122503199396727085502753297492\", \"price\":\"0.54\", \"size\":\"26\", \"side\":\"SELL\", \"hash\":\"bc756b07628c970440f2f4c6ced95b2135a210f6\", \"best_bid\":\"0.4\", \"best_ask\":\"0.41\"}], \"timestamp\":\"1785126627061\", \"event_type\":\"price_change\"}","received_at":"2026-07-27T04:30:28.531585Z","schema_version":"clob-market-ws.price_change.v1","sequence":null,"server_hash":null,"server_timestamp":"1785126627061","session_id":"e9443c7415a0419799bee9cfbb1a9e4d","source":"clob_market_ws"},"received_at":"2026-07-27T04:30:28.531585Z","record_id":"f11a6babe6dca14972f1d286c8c26419da1343064f3d25b4190a37646b5a3fec","schema_fingerprint":"4aa3821a28b0b7c2400bc59aba4bcc0a76e971dadd19610d3ad38c768e124dc7","schema_version":"edge-lab-recorder.raw.v1","sequence":null,"source":"clob_market_ws"}
{"event_at":"2026-07-27T04:30:27.063000Z","event_fingerprint":"2f3200d95602d182b18dd54c9dafd17e6495159f42c64b92d4d8435d6e8e4bde","payload":{"connection_id":"0f4979d6978d463e9660b042fdcf555f","event_at":"2026-07-27T04:30:27.063000Z","event_type":"price_change","frame_hash":"c1282aafb830715a4a75b56a0da13b48755977ef5d3022df86b762f00fd65b46","frame_index":0,"kind":"data","monotonic_ns":228611819103333,"payload":{"event_type":"price_change","market":"0xeb66215f2e9faa6449e30a02bab5b8ed7b79a38bf961f6b24d0073c9c2419250","price_changes":[{"asset_id":"60386828328910021732068595344565885737045900010034836345809386672230885527307","best_ask":"0.6","best_bid":"0.59","hash":"59407a0c91b2b1b685f75f24de053a45bcd43522","price":"0.59","side":"BUY","size":"153.42"},{"asset_id":"69697746896130839564035629862476347944307040470122503199396727085502753297492","best_ask":"0.41","best_bid":"0.4","hash":"4808eb779b6f03f33ec905dfb0cc8a9952a3ec2b","price":"0.41","side":"SELL","size":"153.42"}],"timestamp":"1785126627063"},"payload_hash":"06ded6b030b48be1ae05d066cde0436fc9e426aa1059d69c121e702e1d780bda","raw_frame":"{\"market\":\"0xeb66215f2e9faa6449e30a02bab5b8ed7b79a38bf961f6b24d0073c9c2419250\", \"price_changes\":[{\"asset_id\":\"60386828328910021732068595344565885737045900010034836345809386672230885527307\", \"price\":\"0.59\", \"size\":\"153.42\", \"side\":\"BUY\", \"hash\":\"59407a0c91b2b1b685f75f24de053a45bcd43522\", \"best_bid\":\"0.59\", \"best_ask\":\"0.6\"}, {\"asset_id\":\"69697746896130839564035629862476347944307040470122503199396727085502753297492\", \"price\":\"0.41\", \"size\":\"153.42\", \"side\":\"SELL\", \"hash\":\"4808eb779b6f03f33ec905dfb0cc8a9952a3ec2b\", \"best_bid\":\"0.4\", \"best_ask\":\"0.41\"}], \"timestamp\":\"1785126627063\", \"event_type\":\"price_change\"}","received_at":"2026-07-27T04:30:28.549513Z","schema_version":"clob-market-ws.price_change.v1","sequence":null,"server_hash":null,"server_timestamp":"1785126627063","session_id":"e9443c7415a0419799bee9cfbb1a9e4d","source":"clob_market_ws"},"received_at":"2026-07-27T04:30:28.549513Z","record_id":"8bfaa09ff8656eb48731745da31765c178782e84dec15158fa3197c3f8f30527","schema_fingerprint":"4aa3821a28b0b7c2400bc59aba4bcc0a76e971dadd19610d3ad38c768e124dc7","schema_version":"edge-lab-recorder.raw.v1","sequence":null,"source":"clob_market_ws"}
{"event_at":"2026-07-27T04:30:27.071000Z","event_fingerprint":"69743a75bb186f4d0b0c75897842760a284df56040ed3469b95b6b7ea26054b8","payload":{"connection_id":"0f4979d6978d463e9660b042fdcf555f","event_at":"2026-07-27T04:30:27.071000Z","event_type":"price_change","frame_hash":"63e178b75c65dbb8ac70fcb4822bf3f8c56ab6abca734b09b7691eb82def412a","frame_index":0,"kind":"data","monotonic_ns":228611829218416,"payload":{"event_type":"price_change","market":"0xeb66215f2e9faa6449e30a02bab5b8ed7b79a38bf961f6b24d0073c9c2419250","price_changes":[{"asset_id":"69697746896130839564035629862476347944307040470122503199396727085502753297492","best_ask":"0.41","best_bid":"0.4","hash":"d3ba362a3675498d278a308f46fbf7cef1e6752d","price":"0.36","side":"BUY","size":"36.87"},{"asset_id":"60386828328910021732068595344565885737045900010034836345809386672230885527307","best_ask":"0.6","best_bid":"0.59","hash":"4e3271bad03d99b6f428ba0aaa08492f67b5cc65","price":"0.64","side":"SELL","size":"36.87"}],"timestamp":"1785126627071"},"payload_hash":"0b6def8a3061dbfb1972e0957bb749097c023d3796ecc73b4ccfbacf6aff0422","raw_frame":"{\"market\":\"0xeb66215f2e9faa6449e30a02bab5b8ed7b79a38bf961f6b24d0073c9c2419250\", \"price_changes\":[{\"asset_id\":\"69697746896130839564035629862476347944307040470122503199396727085502753297492\", \"price\":\"0.36\", \"size\":\"36.87\", \"side\":\"BUY\", \"hash\":\"d3ba362a3675498d278a308f46fbf7cef1e6752d\", \"best_bid\":\"0.4\", \"best_ask\":\"0.41\"}, {\"asset_id\":\"60386828328910021732068595344565885737045900010034836345809386672230885527307\", \"price\":\"0.64\", \"size\":\"36.87\", \"side\":\"SELL\", \"hash\":\"4e3271bad03d99b6f428ba0aaa08492f67b5cc65\", \"best_bid\":\"0.59\", \"best_ask\":\"0.6\"}], \"timestamp\":\"1785126627071\", \"event_type\":\"price_change\"}","received_at":"2026-07-27T04:30:28.559629Z","schema_version":"clob-market-ws.price_change.v1","sequence":null,"server_hash":null,"server_timestamp":"1785126627071","session_id":"e9443c7415a0419799bee9cfbb1a9e4d","source":"clob_market_ws"},"received_at":"2026-07-27T04:30:28.559629Z","record_id":"5d8480334b9a46a969c85080545e5d55c43c095fa6a19812589afdfc22d023b1","schema_fingerprint":"4aa3821a28b0b7c2400bc59aba4bcc0a76e971dadd19610d3ad38c768e124dc7","schema_version":"edge-lab-recorder.raw.v1","sequence":null,"source":"clob_market_ws"}
{"event_at":"2026-07-27T04:30:27.076000Z","event_fingerprint":"a725045d374c0ec01c09ce139d78561ec5d6ca1a8ec37c4b40e7e39685cae133","payload":{"connection_id":"0f4979d6978d463e9660b042fdcf555f","event_at":"2026-07-27T04:30:27.076000Z","event_type":"price_change","frame_hash":"b6222a925ce0b02eeb45fc4cbea2cf7c36c162d4ddb4f69130ac8c981dbab1d7","frame_index":0,"kind":"data","monotonic_ns":228611843282708,"payload":{"event_type":"price_change","market":"0xeb66215f2e9faa6449e30a02bab5b8ed7b79a38bf961f6b24d0073c9c2419250","price_changes":[{"asset_id":"69697746896130839564035629862476347944307040470122503199396727085502753297492","best_ask":"0.41","best_bid":"0.4","hash":"22fdb60e8ad189a7325c7f293b8310bd4c05f71c","price":"0.28","side":"BUY","size":"238.6"},{"asset_id":"60386828328910021732068595344565885737045900010034836345809386672230885527307","best_ask":"0.6","best_bid":"0.59","hash":"eeb064c0518326ecf8566fc84a8e489754cfb204","price":"0.72","side":"SELL","size":"238.6"}],"timestamp":"1785126627076"},"payload_hash":"05bcc8be17e5c63dc52071a521fdcdf7a597f90006f0c548c5eaba74fe7daa7a","raw_frame":"{\"market\":\"0xeb66215f2e9faa6449e30a02bab5b8ed7b79a38bf961f6b24d0073c9c2419250\", \"price_changes\":[{\"asset_id\":\"69697746896130839564035629862476347944307040470122503199396727085502753297492\", \"price\":\"0.28\", \"size\":\"238.6\", \"side\":\"BUY\", \"hash\":\"22fdb60e8ad189a7325c7f293b8310bd4c05f71c\", \"best_bid\":\"0.4\", \"best_ask\":\"0.41\"}, {\"asset_id\":\"60386828328910021732068595344565885737045900010034836345809386672230885527307\", \"price\":\"0.72\", \"size\":\"238.6\", \"side\":\"SELL\", \"hash\":\"eeb064c0518326ecf8566fc84a8e489754cfb204\", \"best_bid\":\"0.59\", \"best_ask\":\"0.6\"}], \"timestamp\":\"1785126627076\", \"event_type\":\"price_change\"}","received_at":"2026-07-27T04:30:28.573690Z","schema_version":"clob-market-ws.price_change.v1","sequence":null,"server_hash":null,"server_timestamp":"1785126627076","session_id":"e9443c7415a0419799bee9cfbb1a9e4d","source":"clob_market_ws"},"received_at":"2026-07-27T04:30:28.573690Z","record_id":"899669a351053dc94381f2563332dfdcb6d630e37319c656b357a610c8a87a0f","schema_fingerprint":"4aa3821a28b0b7c2400bc59aba4bcc0a76e971dadd19610d3ad38c768e124dc7","schema_version":"edge-lab-recorder.raw.v1","sequence":null,"source":"clob_market_ws"}
{"event_at":"2026-07-27T04:30:27.081000Z","event_fingerprint":"0c80b229769c288528ef13f708c2d0ecaac618ef61f2f04605073de078a4367b","payload":{"connection_id":"0f4979d6978d463e9660b042fdcf555f","event_at":"2026-07-27T04:30:27.081000Z","event_type":"price_change","frame_hash":"7daccdb97c969abf6b2ba449aa993214ffc8b2146544f604e1c3b948c596d9e7","frame_index":0,"kind":"data","monotonic_ns":228611849599458,"payload":{"event_type":"price_change","market":"0xeb66215f2e9faa6449e30a02bab5b8ed7b79a38bf961f6b24d0073c9c2419250","price_changes":[{"asset_id":"69697746896130839564035629862476347944307040470122503199396727085502753297492","best_ask":"0.41","best_bid":"0.4","hash":"e19a0c559b314ef1a1a2de0f2ed1e347838e6b53","price":"0.42","side":"SELL","size":"40.01"},{"asset_id":"60386828328910021732068595344565885737045900010034836345809386672230885527307","best_ask":"0.6","best_bid":"0.59","hash":"60f1517367791f1b60165b03be9335757f77e618","price":"0.58","side":"BUY","size":"40.01"}],"timestamp":"1785126627081"},"payload_hash":"c99681551c02ed520358599263eabd96078b6a61173ef82d12f59aae6a44e7cd","raw_frame":"{\"market\":\"0xeb66215f2e9faa6449e30a02bab5b8ed7b79a38bf961f6b24d0073c9c2419250\", \"price_changes\":[{\"asset_id\":\"69697746896130839564035629862476347944307040470122503199396727085502753297492\", \"price\":\"0.42\", \"size\":\"40.01\", \"side\":\"SELL\", \"hash\":\"e19a0c559b314ef1a1a2de0f2ed1e347838e6b53\", \"best_bid\":\"0.4\", \"best_ask\":\"0.41\"}, {\"asset_id\":\"60386828328910021732068595344565885737045900010034836345809386672230885527307\", \"price\":\"0.58\", \"size\":\"40.01\", \"side\":\"BUY\", \"hash\":\"60f1517367791f1b60165b03be9335757f77e618\", \"best_bid\":\"0.59\", \"best_ask\":\"0.6\"}], \"timestamp\":\"1785126627081\", \"event_type\":\"price_change\"}","received_at":"2026-07-27T04:30:28.580010Z","schema_version":"clob-market-ws.price_change.v1","sequence":null,"server_hash":null,"server_timestamp":"1785126627081","session_id":"e9443c7415a0419799bee9cfbb1a9e4d","source":"clob_market_ws"},"received_at":"2026-07-27T04:30:28.580010Z","record_id":"9f2148b3a3cf77abd2aa5a2eccf652ba52791ce92ce2cb0ef1f2acfed2a32162","schema_fingerprint":"4aa3821a28b0b7c2400bc59aba4bcc0a76e971dadd19610d3ad38c768e124dc7","schema_version":"edge-lab-recorder.raw.v1","sequence":null,"source":"clob_market_ws"}
{"event_at":"2026-07-27T04:30:27.092000Z","event_fingerprint":"0c7ab148308ce112d5346ad82ec8c0273b34034104964c1cb44c599cc4bd6f39","payload":{"connection_id":"0f4979d6978d463e9660b042fdcf555f","event_at":"2026-07-27T04:30:27.092000Z","event_type":"price_change","frame_hash":"d646c1806c7bdbf328fa4cdf03cfa4f9264ed7041d8175488a09e6b2490fe1e7","frame_index":0,"kind":"data","monotonic_ns":228611860987041,"payload":{"event_type":"price_change","market":"0xeb66215f2e9faa6449e30a02bab5b8ed7b79a38bf961f6b24d0073c9c2419250","price_changes":[{"asset_id":"60386828328910021732068595344565885737045900010034836345809386672230885527307","best_ask":"0.6","best_bid":"0.59","hash":"1fb67b112fa2b5db43afb753aa7a14cf875ddb7d","price":"0.53","side":"BUY","size":"145.86"},{"asset_id":"69697746896130839564035629862476347944307040470122503199396727085502753297492","best_ask":"0.41","best_bid":"0.4","hash":"a87c7311e9619e1a7118f2e41f28fda9554e6e7e","price":"0.47","side":"SELL","size":"145.86"}],"timestamp":"1785126627092"},"payload_hash":"8b0e058291e5e805e1812c931f1f372b2800249892f9d89467950deadb56472c","raw_frame":"{\"market\":\"0xeb66215f2e9faa6449e30a02bab5b8ed7b79a38bf961f6b24d0073c9c2419250\", \"price_changes\":[{\"asset_id\":\"60386828328910021732068595344565885737045900010034836345809386672230885527307\", \"price\":\"0.53\", \"size\":\"145.86\", \"side\":\"BUY\", \"hash\":\"1fb67b112fa2b5db43afb753aa7a14cf875ddb7d\", \"best_bid\":\"0.59\", \"best_ask\":\"0.6\"}, {\"asset_id\":\"69697746896130839564035629862476347944307040470122503199396727085502753297492\", \"price\":\"0.47\", \"size\":\"145.86\", \"side\":\"SELL\", \"hash\":\"a87c7311e9619e1a7118f2e41f28fda9554e6e7e\", \"best_bid\":\"0.4\", \"best_ask\":\"0.41\"}], \"timestamp\":\"1785126627092\", \"event_type\":\"price_change\"}","received_at":"2026-07-27T04:30:28.591396Z","schema_version":"clob-market-ws.price_change.v1","sequence":null,"server_hash":null,"server_timestamp":"1785126627092","session_id":"e9443c7415a0419799bee9cfbb1a9e4d","source":"clob_market_ws"},"received_at":"2026-07-27T04:30:28.591396Z","record_id":"662b6760f2430807a72920e137dbbcef3d500ab97613fbb9a7df3d6062d6eedc","schema_fingerprint":"4aa3821a28b0b7c2400bc59aba4bcc0a76e971dadd19610d3ad38c768e124dc7","schema_version":"edge-lab-recorder.raw.v1","sequence":null,"source":"clob_market_ws"}
{"event_at":"2026-07-27T04:30:27.103000Z","event_fingerprint":"a84386115466d4a6f62ee245c25bc06bdb560aea099f3a93981cd5984c98f3d0","payload":{"connection_id":"0f4979d6978d463e9660b042fdcf555f","event_at":"2026-07-27T04:30:27.103000Z","event_type":"price_change","frame_hash":"35a944a071f0ecd93e57e8106ecf7bff726c67547a73e83d509b23a102573bdb","frame_index":0,"kind":"data","monotonic_ns":228611868600833,"payload":{"event_type":"price_change","market":"0xeb66215f2e9faa6449e30a02bab5b8ed7b79a38bf961f6b24d0073c9c2419250","price_changes":[{"asset_id":"60386828328910021732068595344565885737045900010034836345809386672230885527307","best_ask":"0.6","best_bid":"0.59","hash":"676d8aa6faef808f523bb04a16b10eaa2d8a3558","price":"0.03","side":"BUY","size":"1063.1"},{"asset_id":"69697746896130839564035629862476347944307040470122503199396727085502753297492","best_ask":"0.41","best_bid":"0.4","hash":"07ec28a2a9a2103c0bd4ab7b91cb031369b822d6","price":"0.97","side":"SELL","size":"1063.1"}],"timestamp":"1785126627103"},"payload_hash":"53fd7c6970a4ea6acfded32cdb139ede6cb311433c2df04eb887b3ce16f4c827","raw_frame":"{\"market\":\"0xeb66215f2e9faa6449e30a02bab5b8ed7b79a38bf961f6b24d0073c9c2419250\", \"price_changes\":[{\"asset_id\":\"60386828328910021732068595344565885737045900010034836345809386672230885527307\", \"price\":\"0.03\", \"size\":\"1063.1\", \"side\":\"BUY\", \"hash\":\"676d8aa6faef808f523bb04a16b10eaa2d8a3558\", \"best_bid\":\"0.59\", \"best_ask\":\"0.6\"}, {\"asset_id\":\"69697746896130839564035629862476347944307040470122503199396727085502753297492\", \"price\":\"0.97\", \"size\":\"1063.1\", \"side\":\"SELL\", \"hash\":\"07ec28a2a9a2103c0bd4ab7b91cb031369b822d6\", \"best_bid\":\"0.4\", \"best_ask\":\"0.41\"}], \"timestamp\":\"1785126627103\", \"event_type\":\"price_change\"}","received_at":"2026-07-27T04:30:28.599012Z","schema_version":"clob-market-ws.price_change.v1","sequence":null,"server_hash":null,"server_timestamp":"1785126627103","session_id":"e9443c7415a0419799bee9cfbb1a9e4d","source":"clob_market_ws"},"received_at":"2026-07-27T04:30:28.599012Z","record_id":"a4a1aeda22459c9a53b14d36d622f5c65b607e77da40508926461fbd482fe487","schema_fingerprint":"4aa3821a28b0b7c2400bc59aba4bcc0a76e971dadd19610d3ad38c768e124dc7","schema_version":"edge-lab-recorder.raw.v1","sequence":null,"source":"clob_market_ws"}
{"event_at":"2026-07-27T04:30:27.150000Z","event_fingerprint":"87c0bea640f6ca1e68716f3ef89c0232bfbae690ad8a5fb07d20465243c2c17a","payload":{"connection_id":"0f4979d6978d463e9660b042fdcf555f","event_at":"2026-07-27T04:30:27.150000Z","event_type":"price_change","frame_hash":"c0eedc3ffac0f3351d6966797fa7c89a2a33cb2a70995810f250ff75f1dda9bb","frame_index":0,"kind":"data","monotonic_ns":228611876349083,"payload":{"event_type":"price_change","market":"0xeb66215f2e9faa6449e30a02bab5b8ed7b79a38bf961f6b24d0073c9c2419250","price_changes":[{"asset_id":"69697746896130839564035629862476347944307040470122503199396727085502753297492","best_ask":"0.41","best_bid":"0.4","hash":"558bea6db726a4e9ae5a54063d70485b3fb6a320","price":"0.3","side":"BUY","size":"329.22"},{"asset_id":"60386828328910021732068595344565885737045900010034836345809386672230885527307","best_ask":"0.6","best_bid":"0.59","hash":"e24ee7da2c93778d1b2013611f9d9acbe2d43c49","price":"0.7","side":"SELL","size":"329.22"}],"timestamp":"1785126627150"},"payload_hash":"2d7b5a9ed808d545a03f761006083b798a58074aeae215a45a6efb3ed199fcae","raw_frame":"{\"market\":\"0xeb66215f2e9faa6449e30a02bab5b8ed7b79a38bf961f6b24d0073c9c2419250\", \"price_changes\":[{\"asset_id\":\"69697746896130839564035629862476347944307040470122503199396727085502753297492\", \"price\":\"0.3\", \"size\":\"329.22\", \"side\":\"BUY\", \"hash\":\"558bea6db726a4e9ae5a54063d70485b3fb6a320\", \"best_bid\":\"0.4\", \"best_ask\":\"0.41\"}, {\"asset_id\":\"60386828328910021732068595344565885737045900010034836345809386672230885527307\", \"price\":\"0.7\", \"size\":\"329.22\", \"side\":\"SELL\", \"hash\":\"e24ee7da2c93778d1b2013611f9d9acbe2d43c49\", \"best_bid\":\"0.59\", \"best_ask\":\"0.6\"}], \"timestamp\":\"1785126627150\", \"event_type\":\"price_change\"}","received_at":"2026-07-27T04:30:28.606761Z","schema_version":"clob-market-ws.price_change.v1","sequence":null,"server_hash":null,"server_timestamp":"1785126627150","session_id":"e9443c7415a0419799bee9cfbb1a9e4d","source":"clob_market_ws"},"received_at":"2026-07-27T04:30:28.606761Z","record_id":"3aa9edf11cc2bd5cea48bf5af81fee25eb834fc1d1a97ed8996b728553dc6f55","schema_fingerprint":"4aa3821a28b0b7c2400bc59aba4bcc0a76e971dadd19610d3ad38c768e124dc7","schema_version":"edge-lab-recorder.raw.v1","sequence":null,"source":"clob_market_ws"}
