{"event_at":"2026-07-27T04:36:02.851000Z","event_fingerprint":"b317e5493c9b452674c57fed316e770f9b744c1e6dbcdb1132c6018c5ed448d2","payload":{"connection_id":"0f4979d6978d463e9660b042fdcf555f","event_at":"2026-07-27T04:36:02.851000Z","event_type":"price_change","frame_hash":"ce0da174a128e6aa4314920c2505703281991764700601af8c7f809714913b18","frame_index":0,"kind":"data","monotonic_ns":228946841873791,"payload":{"event_type":"price_change","market":"0xeb66215f2e9faa6449e30a02bab5b8ed7b79a38bf961f6b24d0073c9c2419250","price_changes":[{"asset_id":"60386828328910021732068595344565885737045900010034836345809386672230885527307","best_ask":"0.7","best_bid":"0.69","hash":"6b07e6b5f8af0a80caa24307b3b5c6eedfefb3f4","price":"0.01","side":"BUY","size":"5458.02"},{"asset_id":"69697746896130839564035629862476347944307040470122503199396727085502753297492","best_ask":"0.31","best_bid":"0.3","hash":"19e1532f45d08ee32a4402bdef19d17847df1a97","price":"0.99","side":"SELL","size":"5458.02"}],"timestamp":"1785126962851"},"payload_hash":"65e12fa785c39180a7f02797a9d1e10b829b69685bd0e3c08e24c65930af496d","raw_frame":"{\"market\":\"0xeb66215f2e9faa6449e30a02bab5b8ed7b79a38bf961f6b24d0073c9c2419250\", \"price_changes\":[{\"asset_id\":\"60386828328910021732068595344565885737045900010034836345809386672230885527307\", \"price\":\"0.01\", \"size\":\"5458.02\", \"side\":\"BUY\", \"hash\":\"6b07e6b5f8af0a80caa24307b3b5c6eedfefb3f4\", \"best_bid\":\"0.69\", \"best_ask\":\"0.7\"}, {\"asset_id\":\"69697746896130839564035629862476347944307040470122503199396727085502753297492\", \"price\":\"0.99\", \"size\":\"5458.02\", \"side\":\"SELL\", \"hash\":\"19e1532f45d08ee32a4402bdef19d17847df1a97\", \"best_bid\":\"0.3\", \"best_ask\":\"0.31\"}], \"timestamp\":\"1785126962851\", \"event_type\":\"price_change\"}","received_at":"2026-07-27T04:36:03.575187Z","schema_version":"clob-market-ws.price_change.v1","sequence":null,"server_hash":null,"server_timestamp":"1785126962851","session_id":"e9443c7415a0419799bee9cfbb1a9e4d","source":"clob_market_ws"},"received_at":"2026-07-27T04:36:03.575187Z","record_id":"89179eb3ba30b7c15dae3812716cf371606b016210d8455221dc05e2b47e0958","schema_fingerprint":"4aa3821a28b0b7c2400bc59aba4bcc0a76e971dadd19610d3ad38c768e124dc7","schema_version":"edge-lab-recorder.raw.v1","sequence":null,"source":"clob_market_ws"}
{"event_at":"2026-07-27T04:36:02.860000Z","event_fingerprint":"5d8150a9df7c5c602bb12e5e4e9072d4351138861fdcca404fe15f9cda31a014","payload":{"connection_id":"0f4979d6978d463e9660b042fdcf555f","event_at":"2026-07-27T04:36:02.860000Z","event_type":"price_change","frame_hash":"1abfb953034cf1a135d447ea19399458582d0db8f62d3b333ce7618da1d69471","frame_index":0,"kind":"data","monotonic_ns":228946856283666,"payload":{"event_type":"price_change","market":"0xeb66215f2e9faa6449e30a02bab5b8ed7b79a38bf961f6b24d0073c9c2419250","price_changes":[{"asset_id":"69697746896130839564035629862476347944307040470122503199396727085502753297492","best_ask":"0.31","best_bid":"0.3","hash":"ef9c39b8bcaa28fa2ba0d21ad6364934d8c78704","price":"0.33","side":"SELL","size":"174.6"},{"asset_id":"60386828328910021732068595344565885737045900010034836345809386672230885527307","best_ask":"0.7","best_bid":"0.69","hash":"5ceb0310733e6a342af3533a196c0b6f961a62fb","price":"0.67","side":"BUY","size":"174.6"}],"timestamp":"1785126962860"},"payload_hash":"6f1284d3c2c1232f09530be9c00d3414c35fc73629f5efbbacade1067f478a0b","raw_frame":"{\"market\":\"0xeb66215f2e9faa6449e30a02bab5b8ed7b79a38bf961f6b24d0073c9c2419250\", \"price_changes\":[{\"asset_id\":\"69697746896130839564035629862476347944307040470122503199396727085502753297492\", \"price\":\"0.33\", \"size\":\"174.6\", \"side\":\"SELL\", \"hash\":\"ef9c39b8bcaa28fa2ba0d21ad6364934d8c78704\", \"best_bid\":\"0.3\", \"best_ask\":\"0.31\"}, {\"asset_id\":\"60386828328910021732068595344565885737045900010034836345809386672230885527307\", \"price\":\"0.67\", \"size\":\"174.6\", \"side\":\"BUY\", \"hash\":\"5ceb0310733e6a342af3533a196c0b6f961a62fb\", \"best_bid\":\"0.69\", \"best_ask\":\"0.7\"}], \"timestamp\":\"1785126962860\", \"event_type\":\"price_change\"}","received_at":"2026-07-27T04:36:03.589599Z","schema_version":"clob-market-ws.price_change.v1","sequence":null,"server_hash":null,"server_timestamp":"1785126962860","session_id":"e9443c7415a0419799bee9cfbb1a9e4d","source":"clob_market_ws"},"received_at":"2026-07-27T04:36:03.589599Z","record_id":"5d097c4a80c08819170ff60db70d02e795fcc2acd7ac10c6b6ee4a19f7b6481c","schema_fingerprint":"4aa3821a28b0b7c2400bc59aba4bcc0a76e971dadd19610d3ad38c768e124dc7","schema_version":"edge-lab-recorder.raw.v1","sequence":null,"source":"clob_market_ws"}
{"event_at":"2026-07-27T04:36:02.864000Z","event_fingerprint":"061e75d7a443e3905abe123e9b016ac66da9a5f60e26182a9171ed0bd261f1c2","payload":{"connection_id":"0f4979d6978d463e9660b042fdcf555f","event_at":"2026-07-27T04:36:02.864000Z","event_type":"price_change","frame_hash":"d5f3e0b4a413bd8d63d71150046124bf480d49bd214e3cf211b4df4f081be8a2","frame_index":0,"kind":"data","monotonic_ns":228946862832500,"payload":{"event_type":"price_change","market":"0xeb66215f2e9faa6449e30a02bab5b8ed7b79a38bf961f6b24d0073c9c2419250","price_changes":[{"asset_id":"60386828328910021732068595344565885737045900010034836345809386672230885527307","best_ask":"0.7","best_bid":"0.69","hash":"436e6057f0b584367dfed23b7f68d9e25a848276","price":"0.03","side":"BUY","size":"648.1"},{"asset_id":"69697746896130839564035629862476347944307040470122503199396727085502753297492","best_ask":"0.31","best_bid":"0.3","hash":"ae454b6fcd18928f1f951e6b95a87af372017207","price":"0.97","side":"SELL","size":"648.1"}],"timestamp":"1785126962864"},"payload_hash":"ec4011f4a43805b9e81b704a9b346e2e4939725735aed9c4be69719728c691bb","raw_frame":"{\"market\":\"0xeb66215f2e9faa6449e30a02bab5b8ed7b79a38bf961f6b24d0073c9c2419250\", \"price_changes\":[{\"asset_id\":\"60386828328910021732068595344565885737045900010034836345809386672230885527307\", \"price\":\"0.03\", \"size\":\"648.1\", \"side\":\"BUY\", \"hash\":\"436e6057f0b584367dfed23b7f68d9e25a848276\", \"best_bid\":\"0.69\", \"best_ask\":\"0.7\"}, {\"asset_id\":\"69697746896130839564035629862476347944307040470122503199396727085502753297492\", \"price\":\"0.97\", \"size\":\"648.1\", \"side\":\"SELL\", \"hash\":\"ae454b6fcd18928f1f951e6b95a87af372017207\", \"best_bid\":\"0.3\", \"best_ask\":\"0.31\"}], \"timestamp\":\"1785126962864\", \"event_type\":\"price_change\"}","received_at":"2026-07-27T04:36:03.596147Z","schema_version":"clob-market-ws.price_change.v1","sequence":null,"server_hash":null,"server_timestamp":"1785126962864","session_id":"e9443c7415a0419799bee9cfbb1a9e4d","source":"clob_market_ws"},"received_at":"2026-07-27T04:36:03.596147Z","record_id":"3a1f7e2d3a20d9222230d1934e2a1a5188cfd8fc2fa3aa589c34796d5ca2ab86","schema_fingerprint":"4aa3821a28b0b7c2400bc59aba4bcc0a76e971dadd19610d3ad38c768e124dc7","schema_version":"edge-lab-recorder.raw.v1","sequence":null,"source":"clob_market_ws"}
{"event_at":"2026-07-27T04:36:02.869000Z","event_fingerprint":"e229cc84a0edeeffcffe2eefde4525e641f97398d034a6197069ec2b93fb9288","payload":{"connection_id":"0f4979d6978d463e9660b042fdcf555f","event_at":"2026-07-27T04:36:02.869000Z","event_type":"price_change","frame_hash":"858e998ad27f64d48a7a9dde71a459eb22218569f0422a033f4a21cde7ad9d6c","frame_index":0,"kind":"data","monotonic_ns":228946866743416,"payload":{"event_type":"price_change","market":"0xeb66215f2e9faa6449e30a02bab5b8ed7b79a38bf961f6b24d0073c9c2419250","price_changes":[{"asset_id":"60386828328910021732068595344565885737045900010034836345809386672230885527307","best_ask":"0.7","best_bid":"0.69","hash":"c6c381927e2fbe58ee84763ead2f2c731ab59cd1","price":"0.01","side":"BUY","size":"5453.02"},{"asset_id":"69697746896130839564035629862476347944307040470122503199396727085502753297492","best_ask":"0.31","best_bid":"0.3","hash":"82cc114f0fa4044f8521b119060107af34882323","price":"0.99","side":"SELL","size":"5453.02"}],"timestamp":"1785126962869"},"payload_hash":"4ee8387aee165115c62b7fbd7c7764bb8f520a862efd74d3487697c74ccd3c58","raw_frame":"{\"market\":\"0xeb66215f2e9faa6449e30a02bab5b8ed7b79a38bf961f6b24d0073c9c2419250\", \"price_changes\":[{\"asset_id\":\"60386828328910021732068595344565885737045900010034836345809386672230885527307\", \"price\":\"0.01\", \"size\":\"5453.02\", \"side\":\"BUY\", \"hash\":\"c6c381927e2fbe58ee84763ead2f2c731ab59cd1\", \"best_bid\":\"0.69\", \"best_ask\":\"0.7\"}, {\"asset_id\":\"69697746896130839564035629862476347944307040470122503199396727085502753297492\", \"price\":\"0.99\", \"size\":\"5453.02\", \"side\":\"SELL\", \"hash\":\"82cc114f0fa4044f8521b119060107af34882323\", \"best_bid\":\"0.3\", \"best_ask\":\"0.31\"}], \"timestamp\":\"1785126962869\", \"event_type\":\"price_change\"}","received_at":"2026-07-27T04:36:03.600054Z","schema_version":"clob-market-ws.price_change.v1","sequence":null,"server_hash":null,"server_timestamp":"1785126962869","session_id":"e9443c7415a0419799bee9cfbb1a9e4d","source":"clob_market_ws"},"received_at":"2026-07-27T04:36:03.600054Z","record_id":"f2f7e15ee55c60a214b8af04c91375f0b888851140a9678724e8deb9b9ad954a","schema_fingerprint":"4aa3821a28b0b7c2400bc59aba4bcc0a76e971dadd19610d3ad38c768e124dc7","schema_version":"edge-lab-recorder.raw.v1","sequence":null,"source":"clob_market_ws"}
{"event_at":"2026-07-27T04:36:02.934000Z","event_fingerprint":"be9a67dcd6943807f49c3379775b58a21b25bd6573c5f73c778edb0bd9a9bd18","payload":{"connection_id":"0f4979d6978d463e9660b042fdcf555f","event_at":"2026-07-27T04:36:02.934000Z","event_type":"price_change","frame_hash":"4bef2d9e9125743aba79299dab0753a73dcfffc4f69fa7bde02bfeafd22d5104","frame_index":0,"kind":"data","monotonic_ns":228946872317500,"payload":{"event_type":"price_change","market":"0xeb66215f2e9faa6449e30a02bab5b8ed7b79a38bf961f6b24d0073c9c2419250","price_changes":[{"asset_id":"60386828328910021732068595344565885737045900010034836345809386672230885527307","best_ask":"0.7","best_bid":"0.69","hash":"e7f2d2e27f87a63e24254a309031a201820b9ec9","price":"0.01","side":"BUY","size":"5458.02"},{"asset_id":"69697746896130839564035629862476347944307040470122503199396727085502753297492","best_ask":"0.31","best_bid":"0.3","hash":"0642fccfb315fb27ef289fac3f3fbadecc182e53","price":"0.99","side":"SELL","size":"5458.02"}],"timestamp":"1785126962934"},"payload_hash":"8c8f11b39504be64e95a5e99194ce723b1e182c124c6586e0712ad13af667630","raw_frame":"{\"market\":\"0xeb66215f2e9faa6449e30a02bab5b8ed7b79a38bf961f6b24d0073c9c2419250\", \"price_changes\":[{\"asset_id\":\"60386828328910021732068595344565885737045900010034836345809386672230885527307\", \"price\":\"0.01\", \"size\":\"5458.02\", \"side\":\"BUY\", \"hash\":\"e7f2d2e27f87a63e24254a309031a201820b9ec9\", \"best_bid\":\"0.69\", \"best_ask\":\"0.7\"}, {\"asset_id\":\"69697746896130839564035629862476347944307040470122503199396727085502753297492\", \"price\":\"0.99\", \"size\":\"5458.02\", \"side\":\"SELL\", \"hash\":\"0642fccfb315fb27ef289fac3f3fbadecc182e53\", \"best_bid\":\"0.3\", \"best_ask\":\"0.31\"}], \"timestamp\":\"1785126962934\", \"event_type\":\"price_change\"}","received_at":"2026-07-27T04:36:03.605624Z","schema_version":"clob-market-ws.price_change.v1","sequence":null,"server_hash":null,"server_timestamp":"1785126962934","session_id":"e9443c7415a0419799bee9cfbb1a9e4d","source":"clob_market_ws"},"received_at":"2026-07-27T04:36:03.605624Z","record_id":"f495a3abd82166537ff67fd9f111c58de1d5697d377d6791394ff1be5ede8943","schema_fingerprint":"4aa3821a28b0b7c2400bc59aba4bcc0a76e971dadd19610d3ad38c768e124dc7","schema_version":"edge-lab-recorder.raw.v1","sequence":null,"source":"clob_market_ws"}
{"event_at":"2026-07-27T04:36:02.946000Z","event_fingerprint":"0b32fdc21a9da325b23e268519aaa9b5770f0295d313786f8933c619d49ca183","payload":{"connection_id":"0f4979d6978d463e9660b042fdcf555f","event_at":"2026-07-27T04:36:02.946000Z","event_type":"price_change","frame_hash":"ad16293f93051005685b0c0eef9d67f513079240973b301ed67e5997345167b1","frame_index":0,"kind":"data","monotonic_ns":228946878480666,"payload":{"event_type":"price_change","market":"0xeb66215f2e9faa6449e30a02bab5b8ed7b79a38bf961f6b24d0073c9c2419250","price_changes":[{"asset_id":"60386828328910021732068595344565885737045900010034836345809386672230885527307","best_ask":"0.7","best_bid":"0.69","hash":"607d179803e62f53093fc9185931cbcf4182f7c0","price":"0.43","side":"BUY","size":"17.2"},{"asset_id":"69697746896130839564035629862476347944307040470122503199396727085502753297492","best_ask":"0.31","best_bid":"0.3","hash":"3627d9fc4d27764d3dd7d754b3e662a05a716b7f","price":"0.57","side":"SELL","size":"17.2"}],"timestamp":"1785126962946"},"payload_hash":"0475bcaac73fe9ad563c29138765f838201f28606b1a506977d3ad58a43584eb","raw_frame":"{\"market\":\"0xeb66215f2e9faa6449e30a02bab5b8ed7b79a38bf961f6b24d0073c9c2419250\", \"price_changes\":[{\"asset_id\":\"60386828328910021732068595344565885737045900010034836345809386672230885527307\", \"price\":\"0.43\", \"size\":\"17.2\", \"side\":\"BUY\", \"hash\":\"607d179803e62f53093fc9185931cbcf4182f7c0\", \"best_bid\":\"0.69\", \"best_ask\":\"0.7\"}, {\"asset_id\":\"69697746896130839564035629862476347944307040470122503199396727085502753297492\", \"price\":\"0.57\", \"size\":\"17.2\", \"side\":\"SELL\", \"hash\":\"3627d9fc4d27764d3dd7d754b3e662a05a716b7f\", \"best_bid\":\"0.3\", \"best_ask\":\"0.31\"}], \"timestamp\":\"1785126962946\", \"event_type\":\"price_change\"}","received_at":"2026-07-27T04:36:03.611803Z","schema_version":"clob-market-ws.price_change.v1","sequence":null,"server_hash":null,"server_timestamp":"1785126962946","session_id":"e9443c7415a0419799bee9cfbb1a9e4d","source":"clob_market_ws"},"received_at":"2026-07-27T04:36:03.611803Z","record_id":"ae2efe80ac0e59ae9197aa6b23b8de0ebd895a08f250a726e187704eb772709a","schema_fingerprint":"4aa3821a28b0b7c2400bc59aba4bcc0a76e971dadd19610d3ad38c768e124dc7","schema_version":"edge-lab-recorder.raw.v1","sequence":null,"source":"clob_market_ws"}
{"event_at":"2026-07-27T04:36:02.954000Z","event_fingerprint":"edcf4fff73d3c4fad3a0c8159228d70976da92ec693d29808f6e19dfc9525da5","payload":{"connection_id":"0f4979d6978d463e9660b042fdcf555f","event_at":"2026-07-27T04:36:02.954000Z","event_type":"price_change","frame_hash":"3bf86f018e686e7c859b46b0a75e184faee2a1b2001d1d251aae2fab44104f6c","frame_index":0,"kind":"data","monotonic_ns":228946884239875,"payload":{"event_type":"price_change","market":"0xeb66215f2e9faa6449e30a02bab5b8ed7b79a38bf961f6b24d0073c9c2419250","price_changes":[{"asset_id":"60386828328910021732068595344565885737045900010034836345809386672230885527307","best_ask":"0.7","best_bid":"0.69","hash":"f8b5f6ca679ee4f245fcb2548c009079f6446dab","price":"0.01","side":"BUY","size":"5453.02"},{"asset_id":"69697746896130839564035629862476347944307040470122503199396727085502753297492","best_ask":"0.31","best_bid":"0.3","hash":"e6436377fb262d5e4415cc6aa5ae31daa159215c","price":"0.99","side":"SELL","size":"5453.02"}],"timestamp":"1785126962954"},"payload_hash":"5f4250981b93e7e16692aa3019c343ec31f77f8f47edd0b93b69412f8964eaac","raw_frame":"{\"market\":\"0xeb66215f2e9faa6449e30a02bab5b8ed7b79a38bf961f6b24d0073c9c2419250\", \"price_changes\":[{\"asset_id\":\"60386828328910021732068595344565885737045900010034836345809386672230885527307\", \"price\":\"0.01\", \"size\":\"5453.02\", \"side\":\"BUY\", \"hash\":\"f8b5f6ca679ee4f245fcb2548c009079f6446dab\", \"best_bid\":\"0.69\", \"best_ask\":\"0.7\"}, {\"asset_id\":\"69697746896130839564035629862476347944307040470122503199396727085502753297492\", \"price\":\"0.99\", \"size\":\"5453.02\", \"side\":\"SELL\", \"hash\":\"e6436377fb262d5e4415cc6aa5ae31daa159215c\", \"best_bid\":\"0.3\", \"best_ask\":\"0.31\"}], \"timestamp\":\"1785126962954\", \"event_type\":\"price_change\"}","received_at":"2026-07-27T04:36:03.617556Z","schema_version":"clob-market-ws.price_change.v1","sequence":null,"server_hash":null,"server_timestamp":"1785126962954","session_id":"e9443c7415a0419799bee9cfbb1a9e4d","source":"clob_market_ws"},"received_at":"2026-07-27T04:36:03.617556Z","record_id":"76bbf04cddc2fad650abe740907e3b10a634f622c24acfb454ef7d26aa780df7","schema_fingerprint":"4aa3821a28b0b7c2400bc59aba4bcc0a76e971dadd19610d3ad38c768e124dc7","schema_version":"edge-lab-recorder.raw.v1","sequence":null,"source":"clob_market_ws"}
{"event_at":"2026-07-27T04:36:02.957000Z","event_fingerprint":"08ff5f66ef5d86822a8b943564f30e76b642a1d4317c06ff6d8fed602069e267","payload":{"connection_id":"0f4979d6978d463e9660b042fdcf555f","event_at":"2026-07-27T04:36:02.957000Z","event_type":"price_change","frame_hash":"92fff828014af6beb993df9210be15907bc596e8a94c2b4761502930de7c719a","frame_index":0,"kind":"data","monotonic_ns":228946886933625,"payload":{"event_type":"price_change","market":"0xeb66215f2e9faa6449e30a02bab5b8ed7b79a38bf961f6b24d0073c9c2419250","price_changes":[{"asset_id":"60386828328910021732068595344565885737045900010034836345809386672230885527307","best_ask":"0.7","best_bid":"0.69","hash":"8525c677f19deb4110667a525ab05db4cb6a4543","price":"0.67","side":"BUY","size":"78.6"},{"asset_id":"69697746896130839564035629862476347944307040470122503199396727085502753297492","best_ask":"0.31","best_bid":"0.3","hash":"0811545f0b2b44b15c98a703dafd76f269f600c4","price":"0.33","side":"SELL","size":"78.6"}],"timestamp":"1785126962957"},"payload_hash":"fd1e8bf40c162819506c970d3dc091cc396582ee8c5e6e2f99ee70265b52709a","raw_frame":"{\"market\":\"0xeb66215f2e9faa6449e30a02bab5b8ed7b79a38bf961f6b24d0073c9c2419250\", \"price_changes\":[{\"asset_id\":\"60386828328910021732068595344565885737045900010034836345809386672230885527307\", \"price\":\"0.67\", \"size\":\"78.6\", \"side\":\"BUY\", \"hash\":\"8525c677f19deb4110667a525ab05db4cb6a4543\", \"best_bid\":\"0.69\", \"best_ask\":\"0.7\"}, {\"asset_id\":\"69697746896130839564035629862476347944307040470122503199396727085502753297492\", \"price\":\"0.33\", \"size\":\"78.6\", \"side\":\"SELL\", \"hash\":\"0811545f0b2b44b15c98a703dafd76f269f600c4\", \"best_bid\":\"0.3\", \"best_ask\":\"0.31\"}], \"timestamp\":\"1785126962957\", \"event_type\":\"price_change\"}","received_at":"2026-07-27T04:36:03.620253Z","schema_version":"clob-market-ws.price_change.v1","sequence":null,"server_hash":null,"server_timestamp":"1785126962957","session_id":"e9443c7415a0419799bee9cfbb1a9e4d","source":"clob_market_ws"},"received_at":"2026-07-27T04:36:03.620253Z","record_id":"147479dcfb2ec9fdd5cc8c1d6f76648e9255736e1fe18c74a35ca36fce36a13b","schema_fingerprint":"4aa3821a28b0b7c2400bc59aba4bcc0a76e971dadd19610d3ad38c768e124dc7","schema_version":"edge-lab-recorder.raw.v1","sequence":null,"source":"clob_market_ws"}
{"event_at":"2026-07-27T04:36:02.957000Z","event_fingerprint":"9e615f6d47d5a9a0091ad28f9af0d67f7e95659a51cd1c03f6bd7835ed5863f0","payload":{"connection_id":"0f4979d6978d463e9660b042fdcf555f","event_at":"2026-07-27T04:36:02.957000Z","event_type":"price_change","frame_hash":"2148aa83fc07a2a03c961ef5f9634e7165f12eee30281f6d492feb3748fdd003","frame_index":0,"kind":"data","monotonic_ns":228946891780750,"payload":{"event_type":"price_change","market":"0xeb66215f2e9faa6449e30a02bab5b8ed7b79a38bf961f6b24d0073c9c2419250","price_changes":[{"asset_id":"69697746896130839564035629862476347944307040470122503199396727085502753297492","best_ask":"0.31","best_bid":"0.3","hash":"917c9557db150c4b5d5206c71356b3dc3946d5d5","price":"0.29","side":"BUY","size":"32.6"},{"asset_id":"60386828328910021732068595344565885737045900010034836345809386672230885527307","best_ask":"0.7","best_bid":"0.69","hash":"30da74fbfae44263f9ac1433abbab3b95b4177c6","price":"0.71","side":"SELL","size":"32.6"}],"timestamp":"1785126962957"},"payload_hash":"a9b952acb52b577de32aaf42a14120006f6d151ce0ef1e3fe078d3306316a42b","raw_frame":"{\"market\":\"0xeb66215f2e9faa6449e30a02bab5b8ed7b79a38bf961f6b24d0073c9c2419250\", \"price_changes\":[{\"asset_id\":\"69697746896130839564035629862476347944307040470122503199396727085502753297492\", \"price\":\"0.29\", \"size\":\"32.6\", \"side\":\"BUY\", \"hash\":\"917c9557db150c4b5d5206c71356b3dc3946d5d5\", \"best_bid\":\"0.3\", \"best_ask\":\"0.31\"}, {\"asset_id\":\"60386828328910021732068595344565885737045900010034836345809386672230885527307\", \"price\":\"0.71\", \"size\":\"32.6\", \"side\":\"SELL\", \"hash\":\"30da74fbfae44263f9ac1433abbab3b95b4177c6\", \"best_bid\":\"0.69\", \"best_ask\":\"0.7\"}], \"timestamp\":\"1785126962957\", \"event_type\":\"price_change\"}","received_at":"2026-07-27T04:36:03.625097Z","schema_version":"clob-market-ws.price_change.v1","sequence":null,"server_hash":null,"server_timestamp":"1785126962957","session_id":"e9443c7415a0419799bee9cfbb1a9e4d","source":"clob_market_ws"},"received_at":"2026-07-27T04:36:03.625097Z","record_id":"48491c04d4bb28cb3d105fbfe89da7a7398d30df8802cfc204b19462ffbc1548","schema_fingerprint":"4aa3821a28b0b7c2400bc59aba4bcc0a76e971dadd19610d3ad38c768e124dc7","schema_version":"edge-lab-recorder.raw.v1","sequence":null,"source":"clob_market_ws"}
{"event_at":"2026-07-27T04:36:02.961000Z","event_fingerprint":"95a7a018971b594378dbff4b2651eb0934260eeb62c58eeb385d82c79f8a0c90","payload":{"connection_id":"0f4979d6978d463e9660b042fdcf555f","event_at":"2026-07-27T04:36:02.961000Z","event_type":"price_change","frame_hash":"01a44742711f2f4c74a326f62ce8de0f96d6458d72fc0b44785a65c7f7d21bed","frame_index":0,"kind":"data","monotonic_ns":228946897959125,"payload":{"event_type":"price_change","market":"0xeb66215f2e9faa6449e30a02bab5b8ed7b79a38bf961f6b24d0073c9c2419250","price_changes":[{"asset_id":"60386828328910021732068595344565885737045900010034836345809386672230885527307","best_ask":"0.7","best_bid":"0.69","hash":"51de19a68ead876d362fae2986d6273e882adb31","price":"0.03","side":"BUY","size":"643.1"},{"asset_id":"69697746896130839564035629862476347944307040470122503199396727085502753297492","best_ask":"0.31","best_bid":"0.3","hash":"0cbbe5d2350ab1c1a9a3a73b2cf2d5e2878be421","price":"0.97","side":"SELL","size":"643.1"}],"timestamp":"1785126962961"},"payload_hash":"f46dd7d10b2cf285828feb1c21ddf2e4e5ce1b09d7426158d8671e2a14ba26aa","raw_frame":"{\"market\":\"0xeb66215f2e9faa6449e30a02bab5b8ed7b79a38bf961f6b24d0073c9c2419250\", \"price_changes\":[{\"asset_id\":\"60386828328910021732068595344565885737045900010034836345809386672230885527307\", \"price\":\"0.03\", \"size\":\"643.1\", \"side\":\"BUY\", \"hash\":\"51de19a68ead876d362fae2986d6273e882adb31\", \"best_bid\":\"0.69\", \"best_ask\":\"0.7\"}, {\"asset_id\":\"69697746896130839564035629862476347944307040470122503199396727085502753297492\", \"price\":\"0.97\", \"size\":\"643.1\", \"side\":\"SELL\", \"hash\":\"0cbbe5d2350ab1c1a9a3a73b2cf2d5e2878be421\", \"best_bid\":\"0.3\", \"best_ask\":\"0.31\"}], \"timestamp\":\"1785126962961\", \"event_type\":\"price_change\"}","received_at":"2026-07-27T04:36:03.631274Z","schema_version":"clob-market-ws.price_change.v1","sequence":null,"server_hash":null,"server_timestamp":"1785126962961","session_id":"e9443c7415a0419799bee9cfbb1a9e4d","source":"clob_market_ws"},"received_at":"2026-07-27T04:36:03.631274Z","record_id":"ad1d552aa0987325881cfe9ebf2a7ab879286a5e232974dd26faab5d7281eb63","schema_fingerprint":"4aa3821a28b0b7c2400bc59aba4bcc0a76e971dadd19610d3ad38c768e124dc7","schema_version":"edge-lab-recorder.raw.v1","sequence":null,"source":"clob_market_ws"}
{"event_at":"2026-07-27T04:36:02.964000Z","event_fingerprint":"fdce608ad1710c57f216ca80a57c1807d1b60b6d6aa4954517ccc854d4b019ca","payload":{"connection_id":"0f4979d6978d463e9660b042fdcf555f","event_at":"2026-07-27T04:36:02.964000Z","event_type":"price_change","frame_hash":"c67b81cc699e4bcb7afc9f8368c6808eedb210a6f1206f15e483853c7826fe75","frame_index":0,"kind":"data","monotonic_ns":228946902859791,"payload":{"event_type":"price_change","market":"0xeb66215f2e9faa6449e30a02bab5b8ed7b79a38bf961f6b24d0073c9c2419250","price_changes":[{"asset_id":"69697746896130839564035629862476347944307040470122503199396727085502753297492","best_ask":"0.31","best_bid":"0.3","hash":"00f570b34ade125998e45497c9a9a673cf0b2367","price":"0.28","side":"BUY","size":"42.02"},{"asset_id":"60386828328910021732068595344565885737045900010034836345809386672230885527307","best_ask":"0.7","best_bid":"0.69","hash":"fba5c1f877721e1ed04112b4104be0e4a75d4ef7","price":"0.72","side":"SELL","size":"42.02"}],"timestamp":"1785126962964"},"payload_hash":"42eea253c8eb3bdead8c711b8efb1f856ef06cb96732ae99e812dfffbb81c9c0","raw_frame":"{\"market\":\"0xeb66215f2e9faa6449e30a02bab5b8ed7b79a38bf961f6b24d0073c9c2419250\", \"price_changes\":[{\"asset_id\":\"69697746896130839564035629862476347944307040470122503199396727085502753297492\", \"price\":\"0.28\", \"size\":\"42.02\", \"side\":\"BUY\", \"hash\":\"00f570b34ade125998e45497c9a9a673cf0b2367\", \"best_bid\":\"0.3\", \"best_ask\":\"0.31\"}, {\"asset_id\":\"60386828328910021732068595344565885737045900010034836345809386672230885527307\", \"price\":\"0.72\", \"size\":\"42.02\", \"side\":\"SELL\", \"hash\":\"fba5c1f877721e1ed04112b4104be0e4a75d4ef7\", \"best_bid\":\"0.69\", \"best_ask\":\"0.7\"}], \"timestamp\":\"1785126962964\", \"event_type\":\"price_change\"}","received_at":"2026-07-27T04:36:03.636180Z","schema_version":"clob-market-ws.price_change.v1","sequence":null,"server_hash":null,"server_timestamp":"1785126962964","session_id":"e9443c7415a0419799bee9cfbb1a9e4d","source":"clob_market_ws"},"received_at":"2026-07-27T04:36:03.636180Z","record_id":"775b124b67eb85796512ef82a71d265a0b5a249d8f3132ad23b2bedfc9589b70","schema_fingerprint":"4aa3821a28b0b7c2400bc59aba4bcc0a76e971dadd19610d3ad38c768e124dc7","schema_version":"edge-lab-recorder.raw.v1","sequence":null,"source":"clob_market_ws"}
{"event_at":"2026-07-27T04:36:02.964000Z","event_fingerprint":"ec1d09295ed6898dcb157fecc0df81d16a21a5255eb9e6b74e352015b7d37e42","payload":{"connection_id":"0f4979d6978d463e9660b042fdcf555f","event_at":"2026-07-27T04:36:02.964000Z","event_type":"price_change","frame_hash":"5ec90a065bf314df3d9c4aadf222749bf7161ccf81e3d022b8d7425fe076c3f7","frame_index":0,"kind":"data","monotonic_ns":228946910993125,"payload":{"event_type":"price_change","market":"0xeb66215f2e9faa6449e30a02bab5b8ed7b79a38bf961f6b24d0073c9c2419250","price_changes":[{"asset_id":"60386828328910021732068595344565885737045900010034836345809386672230885527307","best_ask":"0.7","best_bid":"0.69","hash":"fba5c1f877721e1ed04112b4104be0e4a75d4ef7","price":"0.65","side":"BUY","size":"41.77"},{"asset_id":"69697746896130839564035629862476347944307040470122503199396727085502753297492","best_ask":"0.31","best_bid":"0.3","hash":"00f570b34ade125998e45497c9a9a673cf0b2367","price":"0.35","side":"SELL","size":"41.77"}],"timestamp":"1785126962964"},"payload_hash":"0f397c0fd2b349019a239a947ae9e42df7f1e4695415514b2a151752456a34b3","raw_frame":"{\"market\":\"0xeb66215f2e9faa6449e30a02bab5b8ed7b79a38bf961f6b24d0073c9c2419250\", \"price_changes\":[{\"asset_id\":\"60386828328910021732068595344565885737045900010034836345809386672230885527307\", \"price\":\"0.65\", \"size\":\"41.77\", \"side\":\"BUY\", \"hash\":\"fba5c1f877721e1ed04112b4104be0e4a75d4ef7\", \"best_bid\":\"0.69\", \"best_ask\":\"0.7\"}, {\"asset_id\":\"69697746896130839564035629862476347944307040470122503199396727085502753297492\", \"price\":\"0.35\", \"size\":\"41.77\", \"side\":\"SELL\", \"hash\":\"00f570b34ade125998e45497c9a9a673cf0b2367\", \"best_bid\":\"0.3\", \"best_ask\":\"0.31\"}], \"timestamp\":\"1785126962964\", \"event_type\":\"price_change\"}","received_at":"2026-07-27T04:36:03.644310Z","schema_version":"clob-market-ws.price_change.v1","sequence":null,"server_hash":null,"server_timestamp":"1785126962964","session_id":"e9443c7415a0419799bee9cfbb1a9e4d","source":"clob_market_ws"},"received_at":"2026-07-27T04:36:03.644310Z","record_id":"1ddef94a07095cbca58606f7bbd44e020d8e85d210dce329e4a875f4257940ea","schema_fingerprint":"4aa3821a28b0b7c2400bc59aba4bcc0a76e971dadd19610d3ad38c768e124dc7","schema_version":"edge-lab-recorder.raw.v1","sequence":null,"source":"clob_market_ws"}
{"event_at":"2026-07-27T04:36:02.966000Z","event_fingerprint":"3c4b206ddaf7029a3b71a6ae76fc6289cc75aeb7fff6c9ff54670fdb77347b58","payload":{"connection_id":"0f4979d6978d463e9660b042fdcf555f","event_at":"2026-07-27T04:36:02.966000Z","event_type":"price_change","frame_hash":"5903a5aa7f09b0c40c06bfc0bb856298510c7517fca749a4ba1f0386f699db00","frame_index":0,"kind":"data","monotonic_ns":228946917107208,"payload":{"event_type":"price_change","market":"0xeb66215f2e9faa6449e30a02bab5b8ed7b79a38bf961f6b24d0073c9c2419250","price_changes":[{"asset_id":"69697746896130839564035629862476347944307040470122503199396727085502753297492","best_ask":"0.31","best_bid":"0.3","hash":"5b5cf0daede03459582ad6e52b8f91a24f6a0129","price":"0.28","side":"BUY","size":"312.02"},{"asset_id":"60386828328910021732068595344565885737045900010034836345809386672230885527307","best_ask":"0.7","best_bid":"0.69","hash":"5ede074c8097ad8ecec1a77b70de6a4e837bdb40","price":"0.72","side":"SELL","size":"312.02"}],"timestamp":"1785126962966"},"payload_hash":"7e71fa2b0530748392b4bfe91aa85aeae8f297b67621aaa816dfe75c2f9679d6","raw_frame":"{\"market\":\"0xeb66215f2e9faa6449e30a02bab5b8ed7b79a38bf961f6b24d0073c9c2419250\", \"price_changes\":[{\"asset_id\":\"69697746896130839564035629862476347944307040470122503199396727085502753297492\", \"price\":\"0.28\", \"size\":\"312.02\", \"side\":\"BUY\", \"hash\":\"5b5cf0daede03459582ad6e52b8f91a24f6a0129\", \"best_bid\":\"0.3\", \"best_ask\":\"0.31\"}, {\"asset_id\":\"60386828328910021732068595344565885737045900010034836345809386672230885527307\", \"price\":\"0.72\", \"size\":\"312.02\", \"side\":\"SELL\", \"hash\":\"5ede074c8097ad8ecec1a77b70de6a4e837bdb40\", \"best_bid\":\"0.69\", \"best_ask\":\"0.7\"}], \"timestamp\":\"1785126962966\", \"event_type\":\"price_change\"}","received_at":"2026-07-27T04:36:03.650425Z","schema_version":"clob-market-ws.price_change.v1","sequence":null,"server_hash":null,"server_timestamp":"1785126962966","session_id":"e9443c7415a0419799bee9cfbb1a9e4d","source":"clob_market_ws"},"received_at":"2026-07-27T04:36:03.650425Z","record_id":"a80861c5a735c989720fa10a9090487d6ecd1557c347f6d31d80045eeb072dcd","schema_fingerprint":"4aa3821a28b0b7c2400bc59aba4bcc0a76e971dadd19610d3ad38c768e124dc7","schema_version":"edge-lab-recorder.raw.v1","sequence":null,"source":"clob_market_ws"}
{"event_at":"2026-07-27T04:36:02.970000Z","event_fingerprint":"e1f1de02a7d588e11e918c8513ddd26b883c35d527b13778d1e0009e17760147","payload":{"connection_id":"0f4979d6978d463e9660b042fdcf555f","event_at":"2026-07-27T04:36:02.970000Z","event_type":"price_change","frame_hash":"50c347bbdee8122770520b2ec7ec80ccc86165270496a506f5082b206875be44","frame_index":0,"kind":"data","monotonic_ns":228946924957708,"payload":{"event_type":"price_change","market":"0xeb66215f2e9faa6449e30a02bab5b8ed7b79a38bf961f6b24d0073c9c2419250","price_changes":[{"asset_id":"69697746896130839564035629862476347944307040470122503199396727085502753297492","best_ask":"0.31","best_bid":"0.3","hash":"b33e41578e8af8e3f5fa5285c6cb3afe5b208e34","price":"0.27","side":"BUY","size":"203.12"},{"asset_id":"60386828328910021732068595344565885737045900010034836345809386672230885527307","best_ask":"0.7","best_bid":"0.69","hash":"46352487613625c98bd5e76fc6be43f0a8630220","price":"0.73","side":"SELL","size":"203.12"}],"timestamp":"1785126962970"},"payload_hash":"3c9ce9f50cc8b7be3c40ad51d4ef4eb2b286cfc530f6f95d53798000cf0f3c87","raw_frame":"{\"market\":\"0xeb66215f2e9faa6449e30a02bab5b8ed7b79a38bf961f6b24d0073c9c2419250\", \"price_changes\":[{\"asset_id\":\"69697746896130839564035629862476347944307040470122503199396727085502753297492\", \"price\":\"0.27\", \"size\":\"203.12\", \"side\":\"BUY\", \"hash\":\"b33e41578e8af8e3f5fa5285c6cb3afe5b208e34\", \"best_bid\":\"0.3\", \"best_ask\":\"0.31\"}, {\"asset_id\":\"60386828328910021732068595344565885737045900010034836345809386672230885527307\", \"price\":\"0.73\", \"size\":\"203.12\", \"side\":\"SELL\", \"hash\":\"46352487613625c98bd5e76fc6be43f0a8630220\", \"best_bid\":\"0.69\", \"best_ask\":\"0.7\"}], \"timestamp\":\"1785126962970\", \"event_type\":\"price_change\"}","received_at":"2026-07-27T04:36:03.658275Z","schema_version":"clob-market-ws.price_change.v1","sequence":null,"server_hash":null,"server_timestamp":"1785126962970","session_id":"e9443c7415a0419799bee9cfbb1a9e4d","source":"clob_market_ws"},"received_at":"2026-07-27T04:36:03.658275Z","record_id":"1ef36b941e2872bedd646921035f01524f41b3fa12dfd89fb00babbc6ee94045","schema_fingerprint":"4aa3821a28b0b7c2400bc59aba4bcc0a76e971dadd19610d3ad38c768e124dc7","schema_version":"edge-lab-recorder.raw.v1","sequence":null,"source":"clob_market_ws"}
{"event_at":"2026-07-27T04:36:02.971000Z","event_fingerprint":"5aba0c119c48853df39b5c3223094a01eb9efc86a0f0a5f1d9a9af41a9b67fae","payload":{"connection_id":"0f4979d6978d463e9660b042fdcf555f","event_at":"2026-07-27T04:36:02.971000Z","event_type":"price_change","frame_hash":"271a38c1063eb9a335820f97faeeee3241608b128dcdfd706b2810e5f1c1a578","frame_index":0,"kind":"data","monotonic_ns":228946931020208,"payload":{"event_type":"price_change","market":"0xeb66215f2e9faa6449e30a02bab5b8ed7b79a38bf961f6b24d0073c9c2419250","price_changes":[{"asset_id":"69697746896130839564035629862476347944307040470122503199396727085502753297492","best_ask":"0.31","best_bid":"0.3","hash":"8102c06dd337ef7265a5a44fcfa936e9964bcb7c","price":"0.33","side":"SELL","size":"48.56"},{"asset_id":"60386828328910021732068595344565885737045900010034836345809386672230885527307","best_ask":"0.7","best_bid":"0.69","hash":"be5161cf62aa1103c7cf33c97b57a7178f253c2c","price":"0.67","side":"BUY","size":"48.56"}],"timestamp":"1785126962971"},"payload_hash":"e1d718962c8158312b22f351344a281e415facd3a86d52ce4f5f622eaddd74ec","raw_frame":"{\"market\":\"0xeb66215f2e9faa6449e30a02bab5b8ed7b79a38bf961f6b24d0073c9c2419250\", \"price_changes\":[{\"asset_id\":\"69697746896130839564035629862476347944307040470122503199396727085502753297492\", \"price\":\"0.33\", \"size\":\"48.56\", \"side\":\"SELL\", \"hash\":\"8102c06dd337ef7265a5a44fcfa936e9964bcb7c\", \"best_bid\":\"0.3\", \"best_ask\":\"0.31\"}, {\"asset_id\":\"60386828328910021732068595344565885737045900010034836345809386672230885527307\", \"price\":\"0.67\", \"size\":\"48.56\", \"side\":\"BUY\", \"hash\":\"be5161cf62aa1103c7cf33c97b57a7178f253c2c\", \"best_bid\":\"0.69\", \"best_ask\":\"0.7\"}], \"timestamp\":\"1785126962971\", \"event_type\":\"price_change\"}","received_at":"2026-07-27T04:36:03.664337Z","schema_version":"clob-market-ws.price_change.v1","sequence":null,"server_hash":null,"server_timestamp":"1785126962971","session_id":"e9443c7415a0419799bee9cfbb1a9e4d","source":"clob_market_ws"},"received_at":"2026-07-27T04:36:03.664337Z","record_id":"e9d3cb24c3ff8f801fdcd385eadb36eddf9e639941896e3c47dab580097a14c7","schema_fingerprint":"4aa3821a28b0b7c2400bc59aba4bcc0a76e971dadd19610d3ad38c768e124dc7","schema_version":"edge-lab-recorder.raw.v1","sequence":null,"source":"clob_market_ws"}
{"event_at":"2026-07-27T04:36:02.990000Z","event_fingerprint":"0cacb452844d5bb8364ab21776efde55397a31f6988bd6ea487aaa38a7410323","payload":{"connection_id":"0f4979d6978d463e9660b042fdcf555f","event_at":"2026-07-27T04:36:02.990000Z","event_type":"price_change","frame_hash":"72924281eccfc2f0d1545a38c2e7ef21e8b077d68971538de0e746967f836d31","frame_index":0,"kind":"data","monotonic_ns":228946936777208,"payload":{"event_type":"price_change","market":"0xeb66215f2e9faa6449e30a02bab5b8ed7b79a38bf961f6b24d0073c9c2419250","price_changes":[{"asset_id":"60386828328910021732068595344565885737045900010034836345809386672230885527307","best_ask":"0.7","best_bid":"0.69","hash":"23c43e5172f2da4beca37c85bc5082997fbbc5e4","price":"0.66","side":"BUY","size":"37.96"},{"asset_id":"69697746896130839564035629862476347944307040470122503199396727085502753297492","best_ask":"0.31","best_bid":"0.3","hash":"ca83478f73bba56cccbda4467368e57a523642b7","price":"0.34","side":"SELL","size":"37.96"}],"timestamp":"1785126962990"},"payload_hash":"651c47c641fa6b574fb2c643d04921074416d6857e536db2e6b4624abb604537","raw_frame":"{\"market\":\"0xeb66215f2e9faa6449e30a02bab5b8ed7b79a38bf961f6b24d0073c9c2419250\", \"price_changes\":[{\"asset_id\":\"60386828328910021732068595344565885737045900010034836345809386672230885527307\", \"price\":\"0.66\", \"size\":\"37.96\", \"side\":\"BUY\", \"hash\":\"23c43e5172f2da4beca37c85bc5082997fbbc5e4\", \"best_bid\":\"0.69\", \"best_ask\":\"0.7\"}, {\"asset_id\":\"69697746896130839564035629862476347944307040470122503199396727085502753297492\", \"price\":\"0.34\", \"size\":\"37.96\", \"side\":\"SELL\", \"hash\":\"ca83478f73bba56cccbda4467368e57a523642b7\", \"best_bid\":\"0.3\", \"best_ask\":\"0.31\"}], \"timestamp\":\"1785126962990\", \"event_type\":\"price_change\"}","received_at":"2026-07-27T04:36:03.670092Z","schema_version":"clob-market-ws.price_change.v1","sequence":null,"server_hash":null,"server_timestamp":"1785126962990","session_id":"e9443c7415a0419799bee9cfbb1a9e4d","source":"clob_market_ws"},"received_at":"2026-07-27T04:36:03.670092Z","record_id":"e3bdcc1822ca17f88fc4b445e4e288e621b2fe47e598c13664870788b614a127","schema_fingerprint":"4aa3821a28b0b7c2400bc59aba4bcc0a76e971dadd19610d3ad38c768e124dc7","schema_version":"edge-lab-recorder.raw.v1","sequence":null,"source":"clob_market_ws"}
{"event_at":"2026-07-27T04:36:02.995000Z","event_fingerprint":"5821984a93dc9b31864bd73ec1808d3536ea477c3203219cd18f81547335b9fc","payload":{"connection_id":"0f4979d6978d463e9660b042fdcf555f","event_at":"2026-07-27T04:36:02.995000Z","event_type":"price_change","frame_hash":"e0ca46852363acd4d1a78811d613fc2a7c6d7a979f97b1df2e270e860708e8fb","frame_index":0,"kind":"data","monotonic_ns":228946943960166,"payload":{"event_type":"price_change","market":"0xeb66215f2e9faa6449e30a02bab5b8ed7b79a38bf961f6b24d0073c9c2419250","price_changes":[{"asset_id":"69697746896130839564035629862476347944307040470122503199396727085502753297492","best_ask":"0.31","best_bid":"0.3","hash":"c067bd06b1eb7951bc662cb9971e98645d438fa7","price":"0.27","side":"BUY","size":"213.12"},{"asset_id":"60386828328910021732068595344565885737045900010034836345809386672230885527307","best_ask":"0.7","best_bid":"0.69","hash":"0c7b785aaee74d2b01fefd972fa62e9197eedc1b","price":"0.73","side":"SELL","size":"213.12"}],"timestamp":"1785126962995"},"payload_hash":"0dd2ddf64656df86c5e0ecd1c4d38ff0ef8896b915db6d7c45aae831565ad43e","raw_frame":"{\"market\":\"0xeb66215f2e9faa6449e30a02bab5b8ed7b79a38bf961f6b24d0073c9c2419250\", \"price_changes\":[{\"asset_id\":\"69697746896130839564035629862476347944307040470122503199396727085502753297492\", \"price\":\"0.27\", \"size\":\"213.12\", \"side\":\"BUY\", \"hash\":\"c067bd06b1eb7951bc662cb9971e98645d438fa7\", \"best_bid\":\"0.3\", \"best_ask\":\"0.31\"}, {\"asset_id\":\"60386828328910021732068595344565885737045900010034836345809386672230885527307\", \"price\":\"0.73\", \"size\":\"213.12\", \"side\":\"SELL\", \"hash\":\"0c7b785aaee74d2b01fefd972fa62e9197eedc1b\", \"best_bid\":\"0.69\", \"best_ask\":\"0.7\"}], \"timestamp\":\"1785126962995\", \"event_type\":\"price_change\"}","received_at":"2026-07-27T04:36:03.677280Z","schema_version":"clob-market-ws.price_change.v1","sequence":null,"server_hash":null,"server_timestamp":"1785126962995","session_id":"e9443c7415a0419799bee9cfbb1a9e4d","source":"clob_market_ws"},"received_at":"2026-07-27T04:36:03.677280Z","record_id":"0b8777a9af68b35eee9f6c70ceb863c942cf2ff005d81143ed09860ec292d3a3","schema_fingerprint":"4aa3821a28b0b7c2400bc59aba4bcc0a76e971dadd19610d3ad38c768e124dc7","schema_version":"edge-lab-recorder.raw.v1","sequence":null,"source":"clob_market_ws"}
{"event_at":"2026-07-27T04:36:03.005000Z","event_fingerprint":"4be15b91186ef4d8b0166305effc1589702f544c4de29c158913abf65ae44ddb","payload":{"connection_id":"0f4979d6978d463e9660b042fdcf555f","event_at":"2026-07-27T04:36:03.005000Z","event_type":"price_change","frame_hash":"00ab923b48219c3c750d70983f3d5323356bed5df5060f4359216ffb3916b70e","frame_index":0,"kind":"data","monotonic_ns":228946949428416,"payload":{"event_type":"price_change","market":"0xeb66215f2e9faa6449e30a02bab5b8ed7b79a38bf961f6b24d0073c9c2419250","price_changes":[{"asset_id":"60386828328910021732068595344565885737045900010034836345809386672230885527307","best_ask":"0.7","best_bid":"0.69","hash":"9dc8f7d204b118ff800bb9d9ec40ebaf0ed0e8f4","price":"0.67","side":"BUY","size":"79.6"},{"asset_id":"69697746896130839564035629862476347944307040470122503199396727085502753297492","best_ask":"0.31","best_bid":"0.3","hash":"3d47bb9be4bd9720c989697d4809d50effa04f3d","price":"0.33","side":"SELL","size":"79.6"}],"timestamp":"1785126963005"},"payload_hash":"846f30c1526d490189fb173c203741c87baa43e8602fd60821ec826b083b1ac2","raw_frame":"{\"market\":\"0xeb66215f2e9faa6449e30a02bab5b8ed7b79a38bf961f6b24d0073c9c2419250\", \"price_changes\":[{\"asset_id\":\"60386828328910021732068595344565885737045900010034836345809386672230885527307\", \"price\":\"0.67\", \"size\":\"79.6\", \"side\":\"BUY\", \"hash\":\"9dc8f7d204b118ff800bb9d9ec40ebaf0ed0e8f4\", \"best_bid\":\"0.69\", \"best_ask\":\"0.7\"}, {\"asset_id\":\"69697746896130839564035629862476347944307040470122503199396727085502753297492\", \"price\":\"0.33\", \"size\":\"79.6\", \"side\":\"SELL\", \"hash\":\"3d47bb9be4bd9720c989697d4809d50effa04f3d\", \"best_bid\":\"0.3\", \"best_ask\":\"0.31\"}], \"timestamp\":\"1785126963005\", \"event_type\":\"price_change\"}","received_at":"2026-07-27T04:36:03.682746Z","schema_version":"clob-market-ws.price_change.v1","sequence":null,"server_hash":null,"server_timestamp":"1785126963005","session_id":"e9443c7415a0419799bee9cfbb1a9e4d","source":"clob_market_ws"},"received_at":"2026-07-27T04:36:03.682746Z","record_id":"7bdedf95c012b9c9f3c4662e534768d3d1141317efff06b222d37310d0361f94","schema_fingerprint":"4aa3821a28b0b7c2400bc59aba4bcc0a76e971dadd19610d3ad38c768e124dc7","schema_version":"edge-lab-recorder.raw.v1","sequence":null,"source":"clob_market_ws"}
{"event_at":"2026-07-27T04:36:03.011000Z","event_fingerprint":"5caf43a33d5565af865b2af28eb72604fad28e8f88cbd05137dc24bd4de23365","payload":{"connection_id":"0f4979d6978d463e9660b042fdcf555f","event_at":"2026-07-27T04:36:03.011000Z","event_type":"price_change","frame_hash":"cf8c6a1ee3e1580dfd5be2d7f5c40ba315e9dfe9a30049b2834f376bd0a11be5","frame_index":0,"kind":"data","monotonic_ns":228946958064750,"payload":{"event_type":"price_change","market":"0xeb66215f2e9faa6449e30a02bab5b8ed7b79a38bf961f6b24d0073c9c2419250","price_changes":[{"asset_id":"60386828328910021732068595344565885737045900010034836345809386672230885527307","best_ask":"0.7","best_bid":"0.69","hash":"e05344f545017a6bda9de04ebe652dc39cbbb74f","price":"0.43","side":"BUY","size":"22.5"},{"asset_id":"69697746896130839564035629862476347944307040470122503199396727085502753297492","best_ask":"0.31","best_bid":"0.3","hash":"d0631e1589b3e041aeeb1de5b4dee5334c701de8","price":"0.57","side":"SELL","size":"22.5"}],"timestamp":"1785126963011"},"payload_hash":"9eda84d6b0301f09602880d465ee89e078ac4e99890638d24946a602d5e52504","raw_frame":"{\"market\":\"0xeb66215f2e9faa6449e30a02bab5b8ed7b79a38bf961f6b24d0073c9c2419250\", \"price_changes\":[{\"asset_id\":\"60386828328910021732068595344565885737045900010034836345809386672230885527307\", \"price\":\"0.43\", \"size\":\"22.5\", \"side\":\"BUY\", \"hash\":\"e05344f545017a6bda9de04ebe652dc39cbbb74f\", \"best_bid\":\"0.69\", \"best_ask\":\"0.7\"}, {\"asset_id\":\"69697746896130839564035629862476347944307040470122503199396727085502753297492\", \"price\":\"0.57\", \"size\":\"22.5\", \"side\":\"SELL\", \"hash\":\"d0631e1589b3e041aeeb1de5b4dee5334c701de8\", \"best_bid\":\"0.3\", \"best_ask\":\"0.31\"}], \"timestamp\":\"1785126963011\", \"event_type\":\"price_change\"}","received_at":"2026-07-27T04:36:03.691381Z","schema_version":"clob-market-ws.price_change.v1","sequence":null,"server_hash":null,"server_timestamp":"1785126963011","session_id":"e9443c7415a0419799bee9cfbb1a9e4d","source":"clob_market_ws"},"received_at":"2026-07-27T04:36:03.691381Z","record_id":"3bbac3dc1d74452cb898ebdc1cffe8db199c05d19cfc27cd71242bfcde1a9579","schema_fingerprint":"4aa3821a28b0b7c2400bc59aba4bcc0a76e971dadd19610d3ad38c768e124dc7","schema_version":"edge-lab-recorder.raw.v1","sequence":null,"source":"clob_market_ws"}
{"event_at":"2026-07-27T04:36:03.023000Z","event_fingerprint":"d0a72e3c289998ddf7aa42cbef57e282b808eea045d66c38dfd50618313dab7c","payload":{"connection_id":"0f4979d6978d463e9660b042fdcf555f","event_at":"2026-07-27T04:36:03.023000Z","event_type":"price_change","frame_hash":"195a25d85ea8cfe1430d2596ec33690b81b95f26dd5a9bc17887c19cbbf57518","frame_index":0,"kind":"data","monotonic_ns":228946965641875,"payload":{"event_type":"price_change","market":"0xeb66215f2e9faa6449e30a02bab5b8ed7b79a38bf961f6b24d0073c9c2419250","price_changes":[{"asset_id":"69697746896130839564035629862476347944307040470122503199396727085502753297492","best_ask":"0.31","best_bid":"0.3","hash":"85c92a831fbe3fbed544d6b85198407b8f342e43","price":"0.01","side":"BUY","size":"5674.91"},{"asset_id":"60386828328910021732068595344565885737045900010034836345809386672230885527307","best_ask":"0.7","best_bid":"0.69","hash":"a2f32bed01301a690a90b59af0c0c79c7b85a88d","price":"0.99","side":"SELL","size":"5674.91"}],"timestamp":"1785126963023"},"payload_hash":"fa3dcd2edf090316821bc862f754733665e631f6fd18d6bd708e3a5f7d9d97c1","raw_frame":"{\"market\":\"0xeb66215f2e9faa6449e30a02bab5b8ed7b79a38bf961f6b24d0073c9c2419250\", \"price_changes\":[{\"asset_id\":\"69697746896130839564035629862476347944307040470122503199396727085502753297492\", \"price\":\"0.01\", \"size\":\"5674.91\", \"side\":\"BUY\", \"hash\":\"85c92a831fbe3fbed544d6b85198407b8f342e43\", \"best_bid\":\"0.3\", \"best_ask\":\"0.31\"}, {\"asset_id\":\"60386828328910021732068595344565885737045900010034836345809386672230885527307\", \"price\":\"0.99\", \"size\":\"5674.91\", \"side\":\"SELL\", \"hash\":\"a2f32bed01301a690a90b59af0c0c79c7b85a88d\", \"best_bid\":\"0.69\", \"best_ask\":\"0.7\"}], \"timestamp\":\"1785126963023\", \"event_type\":\"price_change\"}","received_at":"2026-07-27T04:36:03.698960Z","schema_version":"clob-market-ws.price_change.v1","sequence":null,"server_hash":null,"server_timestamp":"1785126963023","session_id":"e9443c7415a0419799bee9cfbb1a9e4d","source":"clob_market_ws"},"received_at":"2026-07-27T04:36:03.698960Z","record_id":"0e231c4fa5fdbe7edacd4e399fe6224d8b137eae175eb34205cedf769d73e09b","schema_fingerprint":"4aa3821a28b0b7c2400bc59aba4bcc0a76e971dadd19610d3ad38c768e124dc7","schema_version":"edge-lab-recorder.raw.v1","sequence":null,"source":"clob_market_ws"}
{"event_at":"2026-07-27T04:36:03.029000Z","event_fingerprint":"ab9650048ea216feb6a5eeac8691895ae2dbd911bc466e5bffd63f6604bbabd8","payload":{"connection_id":"0f4979d6978d463e9660b042fdcf555f","event_at":"2026-07-27T04:36:03.029000Z","event_type":"price_change","frame_hash":"eade264deba78de3c7a176eb6ca99e0ab2b665cf4758d1c382d7f72ffb37d3b5","frame_index":0,"kind":"data","monotonic_ns":228946972939750,"payload":{"event_type":"price_change","market":"0xeb66215f2e9faa6449e30a02bab5b8ed7b79a38bf961f6b24d0073c9c2419250","price_changes":[{"asset_id":"69697746896130839564035629862476347944307040470122503199396727085502753297492","best_ask":"0.31","best_bid":"0.3","hash":"e38380b9c8cd13e898d06523b3565f28813d137a","price":"0.01","side":"BUY","size":"5679.91"},{"asset_id":"60386828328910021732068595344565885737045900010034836345809386672230885527307","best_ask":"0.7","best_bid":"0.69","hash":"59a1b543e44dda45878d8f2e91efd6a2042f3e87","price":"0.99","side":"SELL","size":"5679.91"}],"timestamp":"1785126963029"},"payload_hash":"c4f614e3a68b599987f68828dbd2f1912bc8718be8f81d620e6d0d6e5d822054","raw_frame":"{\"market\":\"0xeb66215f2e9faa6449e30a02bab5b8ed7b79a38bf961f6b24d0073c9c2419250\", \"price_changes\":[{\"asset_id\":\"69697746896130839564035629862476347944307040470122503199396727085502753297492\", \"price\":\"0.01\", \"size\":\"5679.91\", \"side\":\"BUY\", \"hash\":\"e38380b9c8cd13e898d06523b3565f28813d137a\", \"best_bid\":\"0.3\", \"best_ask\":\"0.31\"}, {\"asset_id\":\"60386828328910021732068595344565885737045900010034836345809386672230885527307\", \"price\":\"0.99\", \"size\":\"5679.91\", \"side\":\"SELL\", \"hash\":\"59a1b543e44dda45878d8f2e91efd6a2042f3e87\", \"best_bid\":\"0.69\", \"best_ask\":\"0.7\"}], \"timestamp\":\"1785126963029\", \"event_type\":\"price_change\"}","received_at":"2026-07-27T04:36:03.706254Z","schema_version":"clob-market-ws.price_change.v1","sequence":null,"server_hash":null,"server_timestamp":"1785126963029","session_id":"e9443c7415a0419799bee9cfbb1a9e4d","source":"clob_market_ws"},"received_at":"2026-07-27T04:36:03.706254Z","record_id":"be85e5300403e505a6c094db5c3f4d8019e4438a0d86122125bce56f0c87a7ec","schema_fingerprint":"4aa3821a28b0b7c2400bc59aba4bcc0a76e971dadd19610d3ad38c768e124dc7","schema_version":"edge-lab-recorder.raw.v1","sequence":null,"source":"clob_market_ws"}
{"event_at":"2026-07-27T04:36:03.033000Z","event_fingerprint":"a9acbbf6e62bf0f81f274d6fe851e497715831155e95cb449745ddf9a9f161cc","payload":{"connection_id":"0f4979d6978d463e9660b042fdcf555f","event_at":"2026-07-27T04:36:03.033000Z","event_type":"price_change","frame_hash":"6206c422bb70bea7a947c47fa1648e435b99d5310f9f9960ab553e98ff3f6285","frame_index":0,"kind":"data","monotonic_ns":228946981948916,"payload":{"event_type":"price_change","market":"0xeb66215f2e9faa6449e30a02bab5b8ed7b79a38bf961f6b24d0073c9c2419250","price_changes":[{"asset_id":"69697746896130839564035629862476347944307040470122503199396727085502753297492","best_ask":"0.31","best_bid":"0.3","hash":"c33b577d3a10e10c9292bb17144a78b434f6ead9","price":"0.22","side":"BUY","size":"189.5"},{"asset_id":"60386828328910021732068595344565885737045900010034836345809386672230885527307","best_ask":"0.7","best_bid":"0.69","hash":"84de760ea2de941a801e3cea275881007459cdf0","price":"0.78","side":"SELL","size":"189.5"}],"timestamp":"1785126963033"},"payload_hash":"63beca6053ca53240431e1bd49f40450a133296505a2633f225c95d14406c6fd","raw_frame":"{\"market\":\"0xeb66215f2e9faa6449e30a02bab5b8ed7b79a38bf961f6b24d0073c9c2419250\", \"price_changes\":[{\"asset_id\":\"69697746896130839564035629862476347944307040470122503199396727085502753297492\", \"price\":\"0.22\", \"size\":\"189.5\", \"side\":\"BUY\", \"hash\":\"c33b577d3a10e10c9292bb17144a78b434f6ead9\", \"best_bid\":\"0.3\", \"best_ask\":\"0.31\"}, {\"asset_id\":\"60386828328910021732068595344565885737045900010034836345809386672230885527307\", \"price\":\"0.78\", \"size\":\"189.5\", \"side\":\"SELL\", \"hash\":\"84de760ea2de941a801e3cea275881007459cdf0\", \"best_bid\":\"0.69\", \"best_ask\":\"0.7\"}], \"timestamp\":\"1785126963033\", \"event_type\":\"price_change\"}","received_at":"2026-07-27T04:36:03.715267Z","schema_version":"clob-market-ws.price_change.v1","sequence":null,"server_hash":null,"server_timestamp":"1785126963033","session_id":"e9443c7415a0419799bee9cfbb1a9e4d","source":"clob_market_ws"},"received_at":"2026-07-27T04:36:03.715267Z","record_id":"8fdecd15daa14aa0e6fb16e2d3f36e2a8d85f490b1f11343a1270a1479a3e814","schema_fingerprint":"4aa3821a28b0b7c2400bc59aba4bcc0a76e971dadd19610d3ad38c768e124dc7","schema_version":"edge-lab-recorder.raw.v1","sequence":null,"source":"clob_market_ws"}
{"event_at":"2026-07-27T04:36:03.049000Z","event_fingerprint":"fb55d313e374d6f8a06b2d5354931847ba57cd1928498058c7185534b96f12dc","payload":{"connection_id":"0f4979d6978d463e9660b042fdcf555f","event_at":"2026-07-27T04:36:03.049000Z","event_type":"price_change","frame_hash":"9e7d8f8cdd88c1a1b784bcb2be4b267edbad6678441a9e41ccc63fde65b76703","frame_index":0,"kind":"data","monotonic_ns":228946987968166,"payload":{"event_type":"price_change","market":"0xeb66215f2e9faa6449e30a02bab5b8ed7b79a38bf961f6b24d0073c9c2419250","price_changes":[{"asset_id":"69697746896130839564035629862476347944307040470122503199396727085502753297492","best_ask":"0.31","best_bid":"0.3","hash":"44c23b56c5585c0821a2596fb06cfb25d8178709","price":"0.01","side":"BUY","size":"5674.91"},{"asset_id":"60386828328910021732068595344565885737045900010034836345809386672230885527307","best_ask":"0.7","best_bid":"0.69","hash":"e3b06f9f2bded1ee464f4870e03440c669392d1c","price":"0.99","side":"SELL","size":"5674.91"}],"timestamp":"1785126963049"},"payload_hash":"7be4c9325801f47c5a114ebf5a0daaade64c30097dc5c751dc87da3f287817b0","raw_frame":"{\"market\":\"0xeb66215f2e9faa6449e30a02bab5b8ed7b79a38bf961f6b24d0073c9c2419250\", \"price_changes\":[{\"asset_id\":\"69697746896130839564035629862476347944307040470122503199396727085502753297492\", \"price\":\"0.01\", \"size\":\"5674.91\", \"side\":\"BUY\", \"hash\":\"44c23b56c5585c0821a2596fb06cfb25d8178709\", \"best_bid\":\"0.3\", \"best_ask\":\"0.31\"}, {\"asset_id\":\"60386828328910021732068595344565885737045900010034836345809386672230885527307\", \"price\":\"0.99\", \"size\":\"5674.91\", \"side\":\"SELL\", \"hash\":\"e3b06f9f2bded1ee464f4870e03440c669392d1c\", \"best_bid\":\"0.69\", \"best_ask\":\"0.7\"}], \"timestamp\":\"1785126963049\", \"event_type\":\"price_change\"}","received_at":"2026-07-27T04:36:03.721282Z","schema_version":"clob-market-ws.price_change.v1","sequence":null,"server_hash":null,"server_timestamp":"1785126963049","session_id":"e9443c7415a0419799bee9cfbb1a9e4d","source":"clob_market_ws"},"received_at":"2026-07-27T04:36:03.721282Z","record_id":"a137ab5ed1c450415ccd8a158f1928128e54019dadecb752d11b94a79936e082","schema_fingerprint":"4aa3821a28b0b7c2400bc59aba4bcc0a76e971dadd19610d3ad38c768e124dc7","schema_version":"edge-lab-recorder.raw.v1","sequence":null,"source":"clob_market_ws"}
{"event_at":"2026-07-27T04:36:03.052000Z","event_fingerprint":"2a79e368480e63fe2bff046f11a988efcb81fd7161c0dd5def38b7ad2f5d5db4","payload":{"connection_id":"0f4979d6978d463e9660b042fdcf555f","event_at":"2026-07-27T04:36:03.052000Z","event_type":"price_change","frame_hash":"c15ddd0f75e62086eec81a888fe387f57ebfd449db16b258fc0bbea1268cf6b7","frame_index":0,"kind":"data","monotonic_ns":228946995328041,"payload":{"event_type":"price_change","market":"0xeb66215f2e9faa6449e30a02bab5b8ed7b79a38bf961f6b24d0073c9c2419250","price_changes":[{"asset_id":"60386828328910021732068595344565885737045900010034836345809386672230885527307","best_ask":"0.7","best_bid":"0.69","hash":"4739a987e6417ee28614f157f344a2c8613b81df","price":"0.53","side":"BUY","size":"348.88"},{"asset_id":"69697746896130839564035629862476347944307040470122503199396727085502753297492","best_ask":"0.31","best_bid":"0.3","hash":"acea1faf2162b70c570fdf0007eea1773134628e","price":"0.47","side":"SELL","size":"348.88"}],"timestamp":"1785126963052"},"payload_hash":"a6f2af315ab08287562192f6f9256a9106cd9f778e883b2470cdbc1dfc54e5b0","raw_frame":"{\"market\":\"0xeb66215f2e9faa6449e30a02bab5b8ed7b79a38bf961f6b24d0073c9c2419250\", \"price_changes\":[{\"asset_id\":\"60386828328910021732068595344565885737045900010034836345809386672230885527307\", \"price\":\"0.53\", \"size\":\"348.88\", \"side\":\"BUY\", \"hash\":\"4739a987e6417ee28614f157f344a2c8613b81df\", \"best_bid\":\"0.69\", \"best_ask\":\"0.7\"}, {\"asset_id\":\"69697746896130839564035629862476347944307040470122503199396727085502753297492\", \"price\":\"0.47\", \"size\":\"348.88\", \"side\":\"SELL\", \"hash\":\"acea1faf2162b70c570fdf0007eea1773134628e\", \"best_bid\":\"0.3\", \"best_ask\":\"0.31\"}], \"timestamp\":\"1785126963052\", \"event_type\":\"price_change\"}","received_at":"2026-07-27T04:36:03.728646Z","schema_version":"clob-market-ws.price_change.v1","sequence":null,"server_hash":null,"server_timestamp":"1785126963052","session_id":"e9443c7415a0419799bee9cfbb1a9e4d","source":"clob_market_ws"},"received_at":"2026-07-27T04:36:03.728646Z","record_id":"0351d2d09945eecb3927414c69d58503a46114b6659e330fa8bd177f0f1b4b54","schema_fingerprint":"4aa3821a28b0b7c2400bc59aba4bcc0a76e971dadd19610d3ad38c768e124dc7","schema_version":"edge-lab-recorder.raw.v1","sequence":null,"source":"clob_market_ws"}
{"event_at":"2026-07-27T04:36:03.053000Z","event_fingerprint":"e59f85578cfec375b89afee1f43fbbedd10319d5d8d9f67ad23f705635470df7","payload":{"connection_id":"0f4979d6978d463e9660b042fdcf555f","event_at":"2026-07-27T04:36:03.053000Z","event_type":"price_change","frame_hash":"20592a2e277114d818a20e2d7b9ca5515e8163f15194c9c4d8eef7ad9a6b0e6f","frame_index":0,"kind":"data","monotonic_ns":228947004342291,"payload":{"event_type":"price_change","market":"0xeb66215f2e9faa6449e30a02bab5b8ed7b79a38bf961f6b24d0073c9c2419250","price_changes":[{"asset_id":"69697746896130839564035629862476347944307040470122503199396727085502753297492","best_ask":"0.31","best_bid":"0.3","hash":"945cf50944a892e1e1efdb13822b521ace208023","price":"0.25","side":"BUY","size":"57.62"},{"asset_id":"60386828328910021732068595344565885737045900010034836345809386672230885527307","best_ask":"0.7","best_bid":"0.69","hash":"09705299d02feea84bf82cdd773b9adee04c1a9f","price":"0.75","side":"SELL","size":"57.62"}],"timestamp":"1785126963053"},"payload_hash":"69591caa256cb0edca909f78513ce7c157abefda1320e825633205f29c19325f","raw_frame":"{\"market\":\"0xeb66215f2e9faa6449e30a02bab5b8ed7b79a38bf961f6b24d0073c9c2419250\", \"price_changes\":[{\"asset_id\":\"69697746896130839564035629862476347944307040470122503199396727085502753297492\", \"price\":\"0.25\", \"size\":\"57.62\", \"side\":\"BUY\", \"hash\":\"945cf50944a892e1e1efdb13822b521ace208023\", \"best_bid\":\"0.3\", \"best_ask\":\"0.31\"}, {\"asset_id\":\"60386828328910021732068595344565885737045900010034836345809386672230885527307\", \"price\":\"0.75\", \"size\":\"57.62\", \"side\":\"SELL\", \"hash\":\"09705299d02feea84bf82cdd773b9adee04c1a9f\", \"best_bid\":\"0.69\", \"best_ask\":\"0.7\"}], \"timestamp\":\"1785126963053\", \"event_type\":\"price_change\"}","received_at":"2026-07-27T04:36:03.737657Z","schema_version":"clob-market-ws.price_change.v1","sequence":null,"server_hash":null,"server_timestamp":"1785126963053","session_id":"e9443c7415a0419799bee9cfbb1a9e4d","source":"clob_market_ws"},"received_at":"2026-07-27T04:36:03.737657Z","record_id":"2f21bae4c9d21f16bee0bd3b9181858c71f232e2f0cb40da1d2228ccc2b06574","schema_fingerprint":"4aa3821a28b0b7c2400bc59aba4bcc0a76e971dadd19610d3ad38c768e124dc7","schema_version":"edge-lab-recorder.raw.v1","sequence":null,"source":"clob_market_ws"}
{"event_at":"2026-07-27T04:36:03.061000Z","event_fingerprint":"10e44cc629cc3dcb394b3a3af109fca4b7b058955a1cbe1e2b62a0a7ab66195e","payload":{"connection_id":"0f4979d6978d463e9660b042fdcf555f","event_at":"2026-07-27T04:36:03.061000Z","event_type":"price_change","frame_hash":"c353740d30932ac927f94191638cfa7ae7f2bfaadae490ce2fd9ca4b336eed0d","frame_index":0,"kind":"data","monotonic_ns":228947011403625,"payload":{"event_type":"price_change","market":"0xeb66215f2e9faa6449e30a02bab5b8ed7b79a38bf961f6b24d0073c9c2419250","price_changes":[{"asset_id":"60386828328910021732068595344565885737045900010034836345809386672230885527307","best_ask":"0.7","best_bid":"0.69","hash":"a86bb08f44527216116ccd1b5ed87072de3a2b4a","price":"0.04","side":"BUY","size":"583.09"},{"asset_id":"69697746896130839564035629862476347944307040470122503199396727085502753297492","best_ask":"0.31","best_bid":"0.3","hash":"885df7d414f90c92598539aa4288050ed699584b","price":"0.96","side":"SELL","size":"583.09"}],"timestamp":"1785126963061"},"payload_hash":"6cabfe9d0581f151b7af91543faadfd3024f649230549907f9d969c588cec4b2","raw_frame":"{\"market\":\"0xeb66215f2e9faa6449e30a02bab5b8ed7b79a38bf961f6b24d0073c9c2419250\", \"price_changes\":[{\"asset_id\":\"60386828328910021732068595344565885737045900010034836345809386672230885527307\", \"price\":\"0.04\", \"size\":\"583.09\", \"side\":\"BUY\", \"hash\":\"a86bb08f44527216116ccd1b5ed87072de3a2b4a\", \"best_bid\":\"0.69\", \"best_ask\":\"0.7\"}, {\"asset_id\":\"69697746896130839564035629862476347944307040470122503199396727085502753297492\", \"price\":\"0.96\", \"size\":\"583.09\", \"side\":\"SELL\", \"hash\":\"885df7d414f90c92598539aa4288050ed699584b\", \"best_bid\":\"0.3\", \"best_ask\":\"0.31\"}], \"timestamp\":\"1785126963061\", \"event_type\":\"price_change\"}","received_at":"2026-07-27T04:36:03.744721Z","schema_version":"clob-market-ws.price_change.v1","sequence":null,"server_hash":null,"server_timestamp":"1785126963061","session_id":"e9443c7415a0419799bee9cfbb1a9e4d","source":"clob_market_ws"},"received_at":"2026-07-27T04:36:03.744721Z","record_id":"92c9bdb066d2607df72b94dd4de2410bad5817ace7936b69bfda183cebfadf6c","schema_fingerprint":"4aa3821a28b0b7c2400bc59aba4bcc0a76e971dadd19610d3ad38c768e124dc7","schema_version":"edge-lab-recorder.raw.v1","sequence":null,"source":"clob_market_ws"}
{"event_at":"2026-07-27T04:36:03.081000Z","event_fingerprint":"cb092635b004e5d6e8b36e3be8fbc60aba46c2ef7475a64610dd55e371db39d6","payload":{"connection_id":"0f4979d6978d463e9660b042fdcf555f","event_at":"2026-07-27T04:36:03.081000Z","event_type":"price_change","frame_hash":"2941790411540af1b0d4bb3075ae09dd2cfb2ec5ee8ac7b8326de2bc6a4ff195","frame_index":0,"kind":"data","monotonic_ns":228947016839666,"payload":{"event_type":"price_change","market":"0xeb66215f2e9faa6449e30a02bab5b8ed7b79a38bf961f6b24d0073c9c2419250","price_changes":[{"asset_id":"69697746896130839564035629862476347944307040470122503199396727085502753297492","best_ask":"0.31","best_bid":"0.3","hash":"a659269fc8f29340e388e49c1eba6473ad0d273c","price":"0.15","side":"BUY","size":"202.65"},{"asset_id":"60386828328910021732068595344565885737045900010034836345809386672230885527307","best_ask":"0.7","best_bid":"0.69","hash":"6cb7048f7e4053c8e0403f4a4f2eff62a50c03c6","price":"0.85","side":"SELL","size":"202.65"}],"timestamp":"1785126963081"},"payload_hash":"b4e0d47d80a86d6b334edaa2201a5e18ce739706ad4139275dab5bb3afa79c0d","raw_frame":"{\"market\":\"0xeb66215f2e9faa6449e30a02bab5b8ed7b79a38bf961f6b24d0073c9c2419250\", \"price_changes\":[{\"asset_id\":\"69697746896130839564035629862476347944307040470122503199396727085502753297492\", \"price\":\"0.15\", \"size\":\"202.65\", \"side\":\"BUY\", \"hash\":\"a659269fc8f29340e388e49c1eba6473ad0d273c\", \"best_bid\":\"0.3\", \"best_ask\":\"0.31\"}, {\"asset_id\":\"60386828328910021732068595344565885737045900010034836345809386672230885527307\", \"price\":\"0.85\", \"size\":\"202.65\", \"side\":\"SELL\", \"hash\":\"6cb7048f7e4053c8e0403f4a4f2eff62a50c03c6\", \"best_bid\":\"0.69\", \"best_ask\":\"0.7\"}], \"timestamp\":\"1785126963081\", \"event_type\":\"price_change\"}","received_at":"2026-07-27T04:36:03.750156Z","schema_version":"clob-market-ws.price_change.v1","sequence":null,"server_hash":null,"server_timestamp":"1785126963081","session_id":"e9443c7415a0419799bee9cfbb1a9e4d","source":"clob_market_ws"},"received_at":"2026-07-27T04:36:03.750156Z","record_id":"98ffc07f06cfecb1c2ec34e0e39be2db804ee9df29131ac2f68313a6af0e4467","schema_fingerprint":"4aa3821a28b0b7c2400bc59aba4bcc0a76e971dadd19610d3ad38c768e124dc7","schema_version":"edge-lab-recorder.raw.v1","sequence":null,"source":"clob_market_ws"}
{"event_at":"2026-07-27T04:36:03.092000Z","event_fingerprint":"f17bc9ae7a5b73dbde98f35eaab14c71e735b3a6f521a894ce7b317cedc2b46f","payload":{"connection_id":"0f4979d6978d463e9660b042fdcf555f","event_at":"2026-07-27T04:36:03.092000Z","event_type":"price_change","frame_hash":"815f3d06e1f541886e23786d1ce4fe2d61fa1032bb7bdbabc25d7fce188950ab","frame_index":0,"kind":"data","monotonic_ns":228947023102458,"payload":{"event_type":"price_change","market":"0xeb66215f2e9faa6449e30a02bab5b8ed7b79a38bf961f6b24d0073c9c2419250","price_changes":[{"asset_id":"69697746896130839564035629862476347944307040470122503199396727085502753297492","best_ask":"0.31","best_bid":"0.3","hash":"592aea81320eabd48a93902fd32f7c29dfbf7493","price":"0.24","side":"BUY","size":"218.39"},{"asset_id":"60386828328910021732068595344565885737045900010034836345809386672230885527307","best_ask":"0.7","best_bid":"0.69","hash":"da11ac2a4664ffa4fe1164b81a18c030a518e038","price":"0.76","side":"SELL","size":"218.39"}],"timestamp":"1785126963092"},"payload_hash":"b8e4f896d1ecb418ad2a5a1b25b0810d889bbe2f91aaee1719d98227d4f7f69c","raw_frame":"{\"market\":\"0xeb66215f2e9faa6449e30a02bab5b8ed7b79a38bf961f6b24d0073c9c2419250\", \"price_changes\":[{\"asset_id\":\"69697746896130839564035629862476347944307040470122503199396727085502753297492\", \"price\":\"0.24\", \"size\":\"218.39\", \"side\":\"BUY\", \"hash\":\"592aea81320eabd48a93902fd32f7c29dfbf7493\", \"best_bid\":\"0.3\", \"best_ask\":\"0.31\"}, {\"asset_id\":\"60386828328910021732068595344565885737045900010034836345809386672230885527307\", \"price\":\"0.76\", \"size\":\"218.39\", \"side\":\"SELL\", \"hash\":\"da11ac2a4664ffa4fe1164b81a18c030a518e038\", \"best_bid\":\"0.69\", \"best_ask\":\"0.7\"}], \"timestamp\":\"1785126963092\", \"event_type\":\"price_change\"}","received_at":"2026-07-27T04:36:03.756418Z","schema_version":"clob-market-ws.price_change.v1","sequence":null,"server_hash":null,"server_timestamp":"1785126963092","session_id":"e9443c7415a0419799bee9cfbb1a9e4d","source":"clob_market_ws"},"received_at":"2026-07-27T04:36:03.756418Z","record_id":"02523491976eede8ec7474f8b4b8d952793e86dd1907ea6e8f324a57f513bd80","schema_fingerprint":"4aa3821a28b0b7c2400bc59aba4bcc0a76e971dadd19610d3ad38c768e124dc7","schema_version":"edge-lab-recorder.raw.v1","sequence":null,"source":"clob_market_ws"}
{"event_at":"2026-07-27T04:36:03.093000Z","event_fingerprint":"7fcfee5d044a275535f1a7466f79fe0197109a923a84c1de653070087c888fb8","payload":{"connection_id":"0f4979d6978d463e9660b042fdcf555f","event_at":"2026-07-27T04:36:03.093000Z","event_type":"price_change","frame_hash":"05ce4b605ec4807b184f83a6e36b25d80d17e0b7860fcaf403cf0d25c51ed014","frame_index":0,"kind":"data","monotonic_ns":228947034119083,"payload":{"event_type":"price_change","market":"0xeb66215f2e9faa6449e30a02bab5b8ed7b79a38bf961f6b24d0073c9c2419250","price_changes":[{"asset_id":"69697746896130839564035629862476347944307040470122503199396727085502753297492","best_ask":"0.31","best_bid":"0.3","hash":"3e33371cf6d41773fbe589098fd5e62f343877a2","price":"0.28","side":"BUY","size":"297.6"},{"asset_id":"60386828328910021732068595344565885737045900010034836345809386672230885527307","best_ask":"0.7","best_bid":"0.69","hash":"c955ed24b8269064f520f96cf0d4a4317fe729bc","price":"0.72","side":"SELL","size":"297.6"}],"timestamp":"1785126963093"},"payload_hash":"199078277ecea3b6527d4ff42ec59ac4335e96cf70445ca0fe58ee0dabef85f5","raw_frame":"{\"market\":\"0xeb66215f2e9faa6449e30a02bab5b8ed7b79a38bf961f6b24d0073c9c2419250\", \"price_changes\":[{\"asset_id\":\"69697746896130839564035629862476347944307040470122503199396727085502753297492\", \"price\":\"0.28\", \"size\":\"297.6\", \"side\":\"BUY\", \"hash\":\"3e33371cf6d41773fbe589098fd5e62f343877a2\", \"best_bid\":\"0.3\", \"best_ask\":\"0.31\"}, {\"asset_id\":\"60386828328910021732068595344565885737045900010034836345809386672230885527307\", \"price\":\"0.72\", \"size\":\"297.6\", \"side\":\"SELL\", \"hash\":\"c955ed24b8269064f520f96cf0d4a4317fe729bc\", \"best_bid\":\"0.69\", \"best_ask\":\"0.7\"}], \"timestamp\":\"1785126963093\", \"event_type\":\"price_change\"}","received_at":"2026-07-27T04:36:03.767437Z","schema_version":"clob-market-ws.price_change.v1","sequence":null,"server_hash":null,"server_timestamp":"1785126963093","session_id":"e9443c7415a0419799bee9cfbb1a9e4d","source":"clob_market_ws"},"received_at":"2026-07-27T04:36:03.767437Z","record_id":"b6c993b7a48d184aa204a521e63f8fc601fae271978ed65ac4a3a525284e095d","schema_fingerprint":"4aa3821a28b0b7c2400bc59aba4bcc0a76e971dadd19610d3ad38c768e124dc7","schema_version":"edge-lab-recorder.raw.v1","sequence":null,"source":"clob_market_ws"}
{"event_at":"2026-07-27T04:36:03.098000Z","event_fingerprint":"59be9d859b58a0b5e1790e0dc98976b84d1eb8d1b41a6439f655ad32991d19c3","payload":{"connection_id":"0f4979d6978d463e9660b042fdcf555f","event_at":"2026-07-27T04:36:03.098000Z","event_type":"price_change","frame_hash":"344c5944470bd5d0e670ca984246c529a0c7b0af90733bb7edfdd2adb14636c2","frame_index":0,"kind":"data","monotonic_ns":228947042381708,"payload":{"event_type":"price_change","market":"0xeb66215f2e9faa6449e30a02bab5b8ed7b79a38bf961f6b24d0073c9c2419250","price_changes":[{"asset_id":"60386828328910021732068595344565885737045900010034836345809386672230885527307","best_ask":"0.7","best_bid":"0.69","hash":"4c08dfe0322893271c098e8b8080f76bea29f60d","price":"0.54","side":"BUY","size":"35"},{"asset_id":"69697746896130839564035629862476347944307040470122503199396727085502753297492","best_ask":"0.31","best_bid":"0.3","hash":"710d58931de8a650d5f7b76735b3ec4105f3d9ba","price":"0.46","side":"SELL","size":"35"}],"timestamp":"1785126963098"},"payload_hash":"23669853d958738de6de8c00291db028444ee549056622d0eaf27f50219edc8b","raw_frame":"{\"market\":\"0xeb66215f2e9faa6449e30a02bab5b8ed7b79a38bf961f6b24d0073c9c2419250\", \"price_changes\":[{\"asset_id\":\"60386828328910021732068595344565885737045900010034836345809386672230885527307\", \"price\":\"0.54\", \"size\":\"35\", \"side\":\"BUY\", \"hash\":\"4c08dfe0322893271c098e8b8080f76bea29f60d\", \"best_bid\":\"0.69\", \"best_ask\":\"0.7\"}, {\"asset_id\":\"69697746896130839564035629862476347944307040470122503199396727085502753297492\", \"price\":\"0.46\", \"size\":\"35\", \"side\":\"SELL\", \"hash\":\"710d58931de8a650d5f7b76735b3ec4105f3d9ba\", \"best_bid\":\"0.3\", \"best_ask\":\"0.31\"}], \"timestamp\":\"1785126963098\", \"event_type\":\"price_change\"}","received_at":"2026-07-27T04:36:03.775700Z","schema_version":"clob-market-ws.price_change.v1","sequence":null,"server_hash":null,"server_timestamp":"1785126963098","session_id":"e9443c7415a0419799bee9cfbb1a9e4d","source":"clob_market_ws"},"received_at":"2026-07-27T04:36:03.775700Z","record_id":"991916f25a18e41ad0496fb9bf5ca60f705080aee99adc2ebcd1281e28d1590a","schema_fingerprint":"4aa3821a28b0b7c2400bc59aba4bcc0a76e971dadd19610d3ad38c768e124dc7","schema_version":"edge-lab-recorder.raw.v1","sequence":null,"source":"clob_market_ws"}
{"event_at":"2026-07-27T04:36:03.099000Z","event_fingerprint":"900a05418d6cc48d6364b7a91423d2dde39f7599e909e57580e85baa4fb0c41d","payload":{"connection_id":"0f4979d6978d463e9660b042fdcf555f","event_at":"2026-07-27T04:36:03.099000Z","event_type":"price_change","frame_hash":"b74df618efaeef958f8b035ec914d19a605be226f7f1cab52f8b612498f824af","frame_index":0,"kind":"data","monotonic_ns":228947048128375,"payload":{"event_type":"price_change","market":"0xeb66215f2e9faa6449e30a02bab5b8ed7b79a38bf961f6b24d0073c9c2419250","price_changes":[{"asset_id":"69697746896130839564035629862476347944307040470122503199396727085502753297492","best_ask":"0.31","best_bid":"0.3","hash":"52dc0d157f528e4868729d22ab2d0690d6d56050","price":"0.24","side":"BUY","size":"234.12"},{"asset_id":"60386828328910021732068595344565885737045900010034836345809386672230885527307","best_ask":"0.7","best_bid":"0.69","hash":"76f3e539500666fa7b52a757eb05ab7c58be6177","price":"0.76","side":"SELL","size":"234.12"}],"timestamp":"1785126963099"},"payload_hash":"faf97b457aa3b5196c2daf77be45587b3c51e18a7e9ff020420603168dac8be0","raw_frame":"{\"market\":\"0xeb66215f2e9faa6449e30a02bab5b8ed7b79a38bf961f6b24d0073c9c2419250\", \"price_changes\":[{\"asset_id\":\"69697746896130839564035629862476347944307040470122503199396727085502753297492\", \"price\":\"0.24\", \"size\":\"234.12\", \"side\":\"BUY\", \"hash\":\"52dc0d157f528e4868729d22ab2d0690d6d56050\", \"best_bid\":\"0.3\", \"best_ask\":\"0.31\"}, {\"asset_id\":\"60386828328910021732068595344565885737045900010034836345809386672230885527307\", \"price\":\"0.76\", \"size\":\"234.12\", \"side\":\"SELL\", \"hash\":\"76f3e539500666fa7b52a757eb05ab7c58be6177\", \"best_bid\":\"0.69\", \"best_ask\":\"0.7\"}], \"timestamp\":\"1785126963099\", \"event_type\":\"price_change\"}","received_at":"2026-07-27T04:36:03.781447Z","schema_version":"clob-market-ws.price_change.v1","sequence":null,"server_hash":null,"server_timestamp":"1785126963099","session_id":"e9443c7415a0419799bee9cfbb1a9e4d","source":"clob_market_ws"},"received_at":"2026-07-27T04:36:03.781447Z","record_id":"4640139101a61d65f8e8c282307bf974be7e87d55c540c8c1081cea2b0018b4d","schema_fingerprint":"4aa3821a28b0b7c2400bc59aba4bcc0a76e971dadd19610d3ad38c768e124dc7","schema_version":"edge-lab-recorder.raw.v1","sequence":null,"source":"clob_market_ws"}
{"event_at":"2026-07-27T04:36:03.104000Z","event_fingerprint":"e81dd352436501d9f633c50437481cd79e4f62d674b81812397890fd01adb442","payload":{"connection_id":"0f4979d6978d463e9660b042fdcf555f","event_at":"2026-07-27T04:36:03.104000Z","event_type":"price_change","frame_hash":"05cd66fa3e2fd444217f1675eab5fa278e16b3d2f9b48dfc34b4c2feed794f22","frame_index":0,"kind":"data","monotonic_ns":228947056227791,"payload":{"event_type":"price_change","market":"0xeb66215f2e9faa6449e30a02bab5b8ed7b79a38bf961f6b24d0073c9c2419250","price_changes":[{"asset_id":"60386828328910021732068595344565885737045900010034836345809386672230885527307","best_ask":"0.7","best_bid":"0.69","hash":"13ff77953e9cd6d49e7fa68feb09a374a1f93c1a","price":"0.53","side":"BUY","size":"308.88"},{"asset_id":"69697746896130839564035629862476347944307040470122503199396727085502753297492","best_ask":"0.31","best_bid":"0.3","hash":"0ea87bcde6e14f1f2550445452a904acddbd6a26","price":"0.47","side":"SELL","size":"308.88"}],"timestamp":"1785126963104"},"payload_hash":"dd37801eed8a72605bd4ff83b437d85a99cd4371eb569c1f2bda05c1eec4cf01","raw_frame":"{\"market\":\"0xeb66215f2e9faa6449e30a02bab5b8ed7b79a38bf961f6b24d0073c9c2419250\", \"price_changes\":[{\"asset_id\":\"60386828328910021732068595344565885737045900010034836345809386672230885527307\", \"price\":\"0.53\", \"size\":\"308.88\", \"side\":\"BUY\", \"hash\":\"13ff77953e9cd6d49e7fa68feb09a374a1f93c1a\", \"best_bid\":\"0.69\", \"best_ask\":\"0.7\"}, {\"asset_id\":\"69697746896130839564035629862476347944307040470122503199396727085502753297492\", \"price\":\"0.47\", \"size\":\"308.88\", \"side\":\"SELL\", \"hash\":\"0ea87bcde6e14f1f2550445452a904acddbd6a26\", \"best_bid\":\"0.3\", \"best_ask\":\"0.31\"}], \"timestamp\":\"1785126963104\", \"event_type\":\"price_change\"}","received_at":"2026-07-27T04:36:03.789545Z","schema_version":"clob-market-ws.price_change.v1","sequence":null,"server_hash":null,"server_timestamp":"1785126963104","session_id":"e9443c7415a0419799bee9cfbb1a9e4d","source":"clob_market_ws"},"received_at":"2026-07-27T04:36:03.789545Z","record_id":"3646a45bb5055808c08a55cb890ea943ffc1c530092937d7116be6261be92369","schema_fingerprint":"4aa3821a28b0b7c2400bc59aba4bcc0a76e971dadd19610d3ad38c768e124dc7","schema_version":"edge-lab-recorder.raw.v1","sequence":null,"source":"clob_market_ws"}
{"event_at":"2026-07-27T04:36:03.120000Z","event_fingerprint":"1336e674d0161f51d67db556c8e2cb2b38f8acc065545936e21b7e601fedfb9f","payload":{"connection_id":"0f4979d6978d463e9660b042fdcf555f","event_at":"2026-07-27T04:36:03.120000Z","event_type":"price_change","frame_hash":"65f115dc03f0c38b8f711c84dec888f02bc4a0618f1aee9420342d1f6d5bdf00","frame_index":0,"kind":"data","monotonic_ns":228947063094750,"payload":{"event_type":"price_change","market":"0xeb66215f2e9faa6449e30a02bab5b8ed7b79a38bf961f6b24d0073c9c2419250","price_changes":[{"asset_id":"69697746896130839564035629862476347944307040470122503199396727085502753297492","best_ask":"0.31","best_bid":"0.3","hash":"13b9475c01bfd32addbdd9fa802cd440f5cfeaa4","price":"0.26","side":"BUY","size":"60.63"},{"asset_id":"60386828328910021732068595344565885737045900010034836345809386672230885527307","best_ask":"0.7","best_bid":"0.69","hash":"6fabce5ffde459e55f5a135f6e3966231e51fa30","price":"0.74","side":"SELL","size":"60.63"}],"timestamp":"1785126963120"},"payload_hash":"ba84784adf86ad848bde7af5d6e6752063553a57c6304e80e8a04b7930b3f4b6","raw_frame":"{\"market\":\"0xeb66215f2e9faa6449e30a02bab5b8ed7b79a38bf961f6b24d0073c9c2419250\", \"price_changes\":[{\"asset_id\":\"69697746896130839564035629862476347944307040470122503199396727085502753297492\", \"price\":\"0.26\", \"size\":\"60.63\", \"side\":\"BUY\", \"hash\":\"13b9475c01bfd32addbdd9fa802cd440f5cfeaa4\", \"best_bid\":\"0.3\", \"best_ask\":\"0.31\"}, {\"asset_id\":\"60386828328910021732068595344565885737045900010034836345809386672230885527307\", \"price\":\"0.74\", \"size\":\"60.63\", \"side\":\"SELL\", \"hash\":\"6fabce5ffde459e55f5a135f6e3966231e51fa30\", \"best_bid\":\"0.69\", \"best_ask\":\"0.7\"}], \"timestamp\":\"1785126963120\", \"event_type\":\"price_change\"}","received_at":"2026-07-27T04:36:03.796413Z","schema_version":"clob-market-ws.price_change.v1","sequence":null,"server_hash":null,"server_timestamp":"1785126963120","session_id":"e9443c7415a0419799bee9cfbb1a9e4d","source":"clob_market_ws"},"received_at":"2026-07-27T04:36:03.796413Z","record_id":"fdd0e0aeb37592a3c61970f400a5397939c3369c57a8ee92f7eaeb7affae534d","schema_fingerprint":"4aa3821a28b0b7c2400bc59aba4bcc0a76e971dadd19610d3ad38c768e124dc7","schema_version":"edge-lab-recorder.raw.v1","sequence":null,"source":"clob_market_ws"}
{"event_at":"2026-07-27T04:36:03.120000Z","event_fingerprint":"76953a0e0cfb8e9acf3f9afc0022c510ad5aad7421017530fcb087e76d783947","payload":{"connection_id":"0f4979d6978d463e9660b042fdcf555f","event_at":"2026-07-27T04:36:03.120000Z","event_type":"price_change","frame_hash":"f3e866012b82b88c289c404d3f6c509d724b0ccbd3b20b7b37b793e38de05326","frame_index":0,"kind":"data","monotonic_ns":228947068892708,"payload":{"event_type":"price_change","market":"0xeb66215f2e9faa6449e30a02bab5b8ed7b79a38bf961f6b24d0073c9c2419250","price_changes":[{"asset_id":"60386828328910021732068595344565885737045900010034836345809386672230885527307","best_ask":"0.7","best_bid":"0.69","hash":"84c79004c49d791140c1e581c5e632ae167318ea","price":"0.67","side":"BUY","size":"48.56"},{"asset_id":"69697746896130839564035629862476347944307040470122503199396727085502753297492","best_ask":"0.31","best_bid":"0.3","hash":"b03343f3db082e54d15007f16e8ed18607310ad7","price":"0.33","side":"SELL","size":"48.56"}],"timestamp":"1785126963120"},"payload_hash":"79fbf328efdc394645222ae0cd915fab170bbfd2ed2ec332a9472cb384ee36ff","raw_frame":"{\"market\":\"0xeb66215f2e9faa6449e30a02bab5b8ed7b79a38bf961f6b24d0073c9c2419250\", \"price_changes\":[{\"asset_id\":\"60386828328910021732068595344565885737045900010034836345809386672230885527307\", \"price\":\"0.67\", \"size\":\"48.56\", \"side\":\"BUY\", \"hash\":\"84c79004c49d791140c1e581c5e632ae167318ea\", \"best_bid\":\"0.69\", \"best_ask\":\"0.7\"}, {\"asset_id\":\"69697746896130839564035629862476347944307040470122503199396727085502753297492\", \"price\":\"0.33\", \"size\":\"48.56\", \"side\":\"SELL\", \"hash\":\"b03343f3db082e54d15007f16e8ed18607310ad7\", \"best_bid\":\"0.3\", \"best_ask\":\"0.31\"}], \"timestamp\":\"1785126963120\", \"event_type\":\"price_change\"}","received_at":"2026-07-27T04:36:03.802211Z","schema_version":"clob-market-ws.price_change.v1","sequence":null,"server_hash":null,"server_timestamp":"1785126963120","session_id":"e9443c7415a0419799bee9cfbb1a9e4d","source":"clob_market_ws"},"received_at":"2026-07-27T04:36:03.802211Z","record_id":"e62d40e2adf626a663cc9ac309596c81a1f1d0810205f18ad9c78503e43a6531","schema_fingerprint":"4aa3821a28b0b7c2400bc59aba4bcc0a76e971dadd19610d3ad38c768e124dc7","schema_version":"edge-lab-recorder.raw.v1","sequence":null,"source":"clob_market_ws"}
{"event_at":"2026-07-27T04:36:03.121000Z","event_fingerprint":"24e59363801709bbd8db464bfca21c6153f44dad4e754f6d80da6f4b162adfef","payload":{"connection_id":"0f4979d6978d463e9660b042fdcf555f","event_at":"2026-07-27T04:36:03.121000Z","event_type":"price_change","frame_hash":"80199734b722190a48014b8b5fc2bace6f1a8c2bb02b026113924c4b36dacf3a","frame_index":0,"kind":"data","monotonic_ns":228947076574875,"payload":{"event_type":"price_change","market":"0xeb66215f2e9faa6449e30a02bab5b8ed7b79a38bf961f6b24d0073c9c2419250","price_changes":[{"asset_id":"60386828328910021732068595344565885737045900010034836345809386672230885527307","best_ask":"0.7","best_bid":"0.69","hash":"09853f4132bab61c15fbee40c3057946285b627e","price":"0.67","side":"BUY","size":"318.56"},{"asset_id":"69697746896130839564035629862476347944307040470122503199396727085502753297492","best_ask":"0.31","best_bid":"0.3","hash":"230507737ecc5027d32f427a378a486857fc588a","price":"0.33","side":"SELL","size":"318.56"}],"timestamp":"1785126963121"},"payload_hash":"73dc0b2046bfc9e44b78c3af5dc31025a84f44763d34fb5f85ee948aef016758","raw_frame":"{\"market\":\"0xeb66215f2e9faa6449e30a02bab5b8ed7b79a38bf961f6b24d0073c9c2419250\", \"price_changes\":[{\"asset_id\":\"60386828328910021732068595344565885737045900010034836345809386672230885527307\", \"price\":\"0.67\", \"size\":\"318.56\", \"side\":\"BUY\", \"hash\":\"09853f4132bab61c15fbee40c3057946285b627e\", \"best_bid\":\"0.69\", \"best_ask\":\"0.7\"}, {\"asset_id\":\"69697746896130839564035629862476347944307040470122503199396727085502753297492\", \"price\":\"0.33\", \"size\":\"318.56\", \"side\":\"SELL\", \"hash\":\"230507737ecc5027d32f427a378a486857fc588a\", \"best_bid\":\"0.3\", \"best_ask\":\"0.31\"}], \"timestamp\":\"1785126963121\", \"event_type\":\"price_change\"}","received_at":"2026-07-27T04:36:03.809892Z","schema_version":"clob-market-ws.price_change.v1","sequence":null,"server_hash":null,"server_timestamp":"1785126963121","session_id":"e9443c7415a0419799bee9cfbb1a9e4d","source":"clob_market_ws"},"received_at":"2026-07-27T04:36:03.809892Z","record_id":"5beff695e62f8a0fc5d3e379fbc0177159977dc5cb4ead8d41160922cb00f761","schema_fingerprint":"4aa3821a28b0b7c2400bc59aba4bcc0a76e971dadd19610d3ad38c768e124dc7","schema_version":"edge-lab-recorder.raw.v1","sequence":null,"source":"clob_market_ws"}
{"event_at":"2026-07-27T04:36:03.122000Z","event_fingerprint":"9270fae0b815c17fde82fb1ad2954d2a46fbb69b9caa8fc9d23308edcec0e127","payload":{"connection_id":"0f4979d6978d463e9660b042fdcf555f","event_at":"2026-07-27T04:36:03.122000Z","event_type":"price_change","frame_hash":"03c012bf23da8bc35974099c1d9ed6687eb1f31a5291aaecdd2b22e3289cb13d","frame_index":0,"kind":"data","monotonic_ns":228947082052291,"payload":{"event_type":"price_change","market":"0xeb66215f2e9faa6449e30a02bab5b8ed7b79a38bf961f6b24d0073c9c2419250","price_changes":[{"asset_id":"60386828328910021732068595344565885737045900010034836345809386672230885527307","best_ask":"0.7","best_bid":"0.69","hash":"4aed7eed13bfd844d6472e5dfddf997b78eec48b","price":"0.74","side":"SELL","size":"55.63"},{"asset_id":"69697746896130839564035629862476347944307040470122503199396727085502753297492","best_ask":"0.31","best_bid":"0.3","hash":"f11081e38e1ce5731f3156a0294758753ce0c80f","price":"0.26","side":"BUY","size":"55.63"}],"timestamp":"1785126963122"},"payload_hash":"f91a3b0812b3c918f14214c83d660cbf2bc51d5a13725e8f043052d3c9adcf24","raw_frame":"{\"market\":\"0xeb66215f2e9faa6449e30a02bab5b8ed7b79a38bf961f6b24d0073c9c2419250\", \"price_changes\":[{\"asset_id\":\"60386828328910021732068595344565885737045900010034836345809386672230885527307\", \"price\":\"0.74\", \"size\":\"55.63\", \"side\":\"SELL\", \"hash\":\"4aed7eed13bfd844d6472e5dfddf997b78eec48b\", \"best_bid\":\"0.69\", \"best_ask\":\"0.7\"}, {\"asset_id\":\"69697746896130839564035629862476347944307040470122503199396727085502753297492\", \"price\":\"0.26\", \"size\":\"55.63\", \"side\":\"BUY\", \"hash\":\"f11081e38e1ce5731f3156a0294758753ce0c80f\", \"best_bid\":\"0.3\", \"best_ask\":\"0.31\"}], \"timestamp\":\"1785126963122\", \"event_type\":\"price_change\"}","received_at":"2026-07-27T04:36:03.815371Z","schema_version":"clob-market-ws.price_change.v1","sequence":null,"server_hash":null,"server_timestamp":"1785126963122","session_id":"e9443c7415a0419799bee9cfbb1a9e4d","source":"clob_market_ws"},"received_at":"2026-07-27T04:36:03.815371Z","record_id":"ac9625ab2d6fcb8a042a82e93fdbff53b091e89daef1a87b09519d86874c34d4","schema_fingerprint":"4aa3821a28b0b7c2400bc59aba4bcc0a76e971dadd19610d3ad38c768e124dc7","schema_version":"edge-lab-recorder.raw.v1","sequence":null,"source":"clob_market_ws"}
{"event_at":"2026-07-27T04:36:03.123000Z","event_fingerprint":"c32a760da3868765daf53079f9dddbf1751b48c47e862c44a2082b5fe73801a8","payload":{"connection_id":"0f4979d6978d463e9660b042fdcf555f","event_at":"2026-07-27T04:36:03.123000Z","event_type":"price_change","frame_hash":"bbeb519dd6e8564533af3a8a70c508a6592a80613e6f4ae3994bf64bf3184cbe","frame_index":0,"kind":"data","monotonic_ns":228947086062458,"payload":{"event_type":"price_change","market":"0xeb66215f2e9faa6449e30a02bab5b8ed7b79a38bf961f6b24d0073c9c2419250","price_changes":[{"asset_id":"60386828328910021732068595344565885737045900010034836345809386672230885527307","best_ask":"0.7","best_bid":"0.69","hash":"c84f5236296adff5835116fbc29c3154ed259b57","price":"0.04","side":"BUY","size":"578.09"},{"asset_id":"69697746896130839564035629862476347944307040470122503199396727085502753297492","best_ask":"0.31","best_bid":"0.3","hash":"c23efdb924a4624de66c9fbabffa83544effe5ac","price":"0.96","side":"SELL","size":"578.09"}],"timestamp":"1785126963123"},"payload_hash":"5993debb84f19c51b948cb70eb6a77289df09c1dd738cbe15c07784f5d5be852","raw_frame":"{\"market\":\"0xeb66215f2e9faa6449e30a02bab5b8ed7b79a38bf961f6b24d0073c9c2419250\", \"price_changes\":[{\"asset_id\":\"60386828328910021732068595344565885737045900010034836345809386672230885527307\", \"price\":\"0.04\", \"size\":\"578.09\", \"side\":\"BUY\", \"hash\":\"c84f5236296adff5835116fbc29c3154ed259b57\", \"best_bid\":\"0.69\", \"best_ask\":\"0.7\"}, {\"asset_id\":\"69697746896130839564035629862476347944307040470122503199396727085502753297492\", \"price\":\"0.96\", \"size\":\"578.09\", \"side\":\"SELL\", \"hash\":\"c23efdb924a4624de66c9fbabffa83544effe5ac\", \"best_bid\":\"0.3\", \"best_ask\":\"0.31\"}], \"timestamp\":\"1785126963123\", \"event_type\":\"price_change\"}","received_at":"2026-07-27T04:36:03.819381Z","schema_version":"clob-market-ws.price_change.v1","sequence":null,"server_hash":null,"server_timestamp":"1785126963123","session_id":"e9443c7415a0419799bee9cfbb1a9e4d","source":"clob_market_ws"},"received_at":"2026-07-27T04:36:03.819381Z","record_id":"59048e13feef4715838740628db2ccf2ebbb7be9e5cb7aa9fb0a79909d0a74d6","schema_fingerprint":"4aa3821a28b0b7c2400bc59aba4bcc0a76e971dadd19610d3ad38c768e124dc7","schema_version":"edge-lab-recorder.raw.v1","sequence":null,"source":"clob_market_ws"}
{"event_at":"2026-07-27T04:36:03.123000Z","event_fingerprint":"b218cd22905eee1a7e55b69196093d44c92c818dfadc439d15506def89c63dab","payload":{"connection_id":"0f4979d6978d463e9660b042fdcf555f","event_at":"2026-07-27T04:36:03.123000Z","event_type":"price_change","frame_hash":"a74d3402fd243e6100a9afcd38366c0c0ce4c660a1ab2e429e478801ac931119","frame_index":0,"kind":"data","monotonic_ns":228947092000375,"payload":{"event_type":"price_change","market":"0xeb66215f2e9faa6449e30a02bab5b8ed7b79a38bf961f6b24d0073c9c2419250","price_changes":[{"asset_id":"60386828328910021732068595344565885737045900010034836345809386672230885527307","best_ask":"0.7","best_bid":"0.69","hash":"72a0a2286f8ba769a4c06a228fb31e86b25d78b3","price":"0.67","side":"BUY","size":"414.56"},{"asset_id":"69697746896130839564035629862476347944307040470122503199396727085502753297492","best_ask":"0.31","best_bid":"0.3","hash":"fc939cd1fac5e71a04aa240c17d17e1d2158025c","price":"0.33","side":"SELL","size":"414.56"}],"timestamp":"1785126963123"},"payload_hash":"12d855d2ad898c7bc2e9adc8b635c0463ebad4972ad6b8bcbb64b58d5e6da759","raw_frame":"{\"market\":\"0xeb66215f2e9faa6449e30a02bab5b8ed7b79a38bf961f6b24d0073c9c2419250\", \"price_changes\":[{\"asset_id\":\"60386828328910021732068595344565885737045900010034836345809386672230885527307\", \"price\":\"0.67\", \"size\":\"414.56\", \"side\":\"BUY\", \"hash\":\"72a0a2286f8ba769a4c06a228fb31e86b25d78b3\", \"best_bid\":\"0.69\", \"best_ask\":\"0.7\"}, {\"asset_id\":\"69697746896130839564035629862476347944307040470122503199396727085502753297492\", \"price\":\"0.33\", \"size\":\"414.56\", \"side\":\"SELL\", \"hash\":\"fc939cd1fac5e71a04aa240c17d17e1d2158025c\", \"best_bid\":\"0.3\", \"best_ask\":\"0.31\"}], \"timestamp\":\"1785126963123\", \"event_type\":\"price_change\"}","received_at":"2026-07-27T04:36:03.825319Z","schema_version":"clob-market-ws.price_change.v1","sequence":null,"server_hash":null,"server_timestamp":"1785126963123","session_id":"e9443c7415a0419799bee9cfbb1a9e4d","source":"clob_market_ws"},"received_at":"2026-07-27T04:36:03.825319Z","record_id":"f58b2083fffcfa18a5d03a96b651be390a1923f3bf4bdcb83dc540afedaefc2d","schema_fingerprint":"4aa3821a28b0b7c2400bc59aba4bcc0a76e971dadd19610d3ad38c768e124dc7","schema_version":"edge-lab-recorder.raw.v1","sequence":null,"source":"clob_market_ws"}
{"event_at":"2026-07-27T04:36:03.124000Z","event_fingerprint":"6b2b02b270929c657f31977110b99687201b3e54d9029c71767f9da6d25ed3c6","payload":{"connection_id":"0f4979d6978d463e9660b042fdcf555f","event_at":"2026-07-27T04:36:03.124000Z","event_type":"price_change","frame_hash":"1b62b441df691e12ed72ee7f2374a0acc5019a6784e3192fc4a38aa8adc4b391","frame_index":0,"kind":"data","monotonic_ns":228947099146958,"payload":{"event_type":"price_change","market":"0xeb66215f2e9faa6449e30a02bab5b8ed7b79a38bf961f6b24d0073c9c2419250","price_changes":[{"asset_id":"69697746896130839564035629862476347944307040470122503199396727085502753297492","best_ask":"0.31","best_bid":"0.3","hash":"cb14bdecfc828a4a40c744033346df80f413cd64","price":"0.33","side":"SELL","size":"444.6"},{"asset_id":"60386828328910021732068595344565885737045900010034836345809386672230885527307","best_ask":"0.7","best_bid":"0.69","hash":"87f05159dc65c6c68c2694bd3884c98931d5ced9","price":"0.67","side":"BUY","size":"444.6"}],"timestamp":"1785126963124"},"payload_hash":"aef0c5d9e6a5fc405a5973b00c1aa1206a2a096e804258b122fd83380873f1a4","raw_frame":"{\"market\":\"0xeb66215f2e9faa6449e30a02bab5b8ed7b79a38bf961f6b24d0073c9c2419250\", \"price_changes\":[{\"asset_id\":\"69697746896130839564035629862476347944307040470122503199396727085502753297492\", \"price\":\"0.33\", \"size\":\"444.6\", \"side\":\"SELL\", \"hash\":\"cb14bdecfc828a4a40c744033346df80f413cd64\", \"best_bid\":\"0.3\", \"best_ask\":\"0.31\"}, {\"asset_id\":\"60386828328910021732068595344565885737045900010034836345809386672230885527307\", \"price\":\"0.67\", \"size\":\"444.6\", \"side\":\"BUY\", \"hash\":\"87f05159dc65c6c68c2694bd3884c98931d5ced9\", \"best_bid\":\"0.69\", \"best_ask\":\"0.7\"}], \"timestamp\":\"1785126963124\", \"event_type\":\"price_change\"}","received_at":"2026-07-27T04:36:03.832465Z","schema_version":"clob-market-ws.price_change.v1","sequence":null,"server_hash":null,"server_timestamp":"1785126963124","session_id":"e9443c7415a0419799bee9cfbb1a9e4d","source":"clob_market_ws"},"received_at":"2026-07-27T04:36:03.832465Z","record_id":"c11f02c78cdca38eb41b29d0ca837383da0cdacbd38c3e6cfe2d74a7b8339821","schema_fingerprint":"4aa3821a28b0b7c2400bc59aba4bcc0a76e971dadd19610d3ad38c768e124dc7","schema_version":"edge-lab-recorder.raw.v1","sequence":null,"source":"clob_market_ws"}
{"event_at":"2026-07-27T04:36:03.131000Z","event_fingerprint":"7ed45310966e34e486ea04f1284b9721357fea6ef437cebd743a051533e204cc","payload":{"connection_id":"0f4979d6978d463e9660b042fdcf555f","event_at":"2026-07-27T04:36:03.131000Z","event_type":"price_change","frame_hash":"9ecb857c75bf41df2994815506d5b26d65049ea967fa2cefeafc90ba34288afa","frame_index":0,"kind":"data","monotonic_ns":228947104998208,"payload":{"event_type":"price_change","market":"0xeb66215f2e9faa6449e30a02bab5b8ed7b79a38bf961f6b24d0073c9c2419250","price_changes":[{"asset_id":"69697746896130839564035629862476347944307040470122503199396727085502753297492","best_ask":"0.31","best_bid":"0.3","hash":"78db1ea1e1fe5cc96735a6ff4a95fd82c7511e1d","price":"0.28","side":"BUY","size":"27.6"},{"asset_id":"60386828328910021732068595344565885737045900010034836345809386672230885527307","best_ask":"0.7","best_bid":"0.69","hash":"1eca5f7d7d09e714cff2cdee7bab2c24b92eb75b","price":"0.72","side":"SELL","size":"27.6"}],"timestamp":"1785126963131"},"payload_hash":"071825b982cf9e1d84b9dde0526423b4d5e1b9c24d614dcbcdddbeaa18f4ceab","raw_frame":"{\"market\":\"0xeb66215f2e9faa6449e30a02bab5b8ed7b79a38bf961f6b24d0073c9c2419250\", \"price_changes\":[{\"asset_id\":\"69697746896130839564035629862476347944307040470122503199396727085502753297492\", \"price\":\"0.28\", \"size\":\"27.6\", \"side\":\"BUY\", \"hash\":\"78db1ea1e1fe5cc96735a6ff4a95fd82c7511e1d\", \"best_bid\":\"0.3\", \"best_ask\":\"0.31\"}, {\"asset_id\":\"60386828328910021732068595344565885737045900010034836345809386672230885527307\", \"price\":\"0.72\", \"size\":\"27.6\", \"side\":\"SELL\", \"hash\":\"1eca5f7d7d09e714cff2cdee7bab2c24b92eb75b\", \"best_bid\":\"0.69\", \"best_ask\":\"0.7\"}], \"timestamp\":\"1785126963131\", \"event_type\":\"price_change\"}","received_at":"2026-07-27T04:36:03.838316Z","schema_version":"clob-market-ws.price_change.v1","sequence":null,"server_hash":null,"server_timestamp":"1785126963131","session_id":"e9443c7415a0419799bee9cfbb1a9e4d","source":"clob_market_ws"},"received_at":"2026-07-27T04:36:03.838316Z","record_id":"06adaccedbdac60e983ab6b6df59cdb4807d2be7f4805a54bc8266700b057c98","schema_fingerprint":"4aa3821a28b0b7c2400bc59aba4bcc0a76e971dadd19610d3ad38c768e124dc7","schema_version":"edge-lab-recorder.raw.v1","sequence":null,"source":"clob_market_ws"}
{"event_at":"2026-07-27T04:36:03.132000Z","event_fingerprint":"035f413a3242583577f830fa1b58759238ff85332f231d9b2dbc8b15a196cc94","payload":{"connection_id":"0f4979d6978d463e9660b042fdcf555f","event_at":"2026-07-27T04:36:03.132000Z","event_type":"price_change","frame_hash":"055a51c5a0f020260a218b9630ee7e43ecc8a6a65ca7f62fa3f53cf319afb165","frame_index":0,"kind":"data","monotonic_ns":228947111323166,"payload":{"event_type":"price_change","market":"0xeb66215f2e9faa6449e30a02bab5b8ed7b79a38bf961f6b24d0073c9c2419250","price_changes":[{"asset_id":"60386828328910021732068595344565885737045900010034836345809386672230885527307","best_ask":"0.7","best_bid":"0.69","hash":"9b3eb7e898b03b80fe2e9333bf430f29d101a7af","price":"0.54","side":"BUY","size":"75"},{"asset_id":"69697746896130839564035629862476347944307040470122503199396727085502753297492","best_ask":"0.31","best_bid":"0.3","hash":"26be71aa561cfbcba2a3eed4645e4e0e841f081f","price":"0.46","side":"SELL","size":"75"}],"timestamp":"1785126963132"},"payload_hash":"aff5b726dfa5318a10746cdd2352dc8cf735ee3676a22f0cbb2e83c54aa5d685","raw_frame":"{\"market\":\"0xeb66215f2e9faa6449e30a02bab5b8ed7b79a38bf961f6b24d0073c9c2419250\", \"price_changes\":[{\"asset_id\":\"60386828328910021732068595344565885737045900010034836345809386672230885527307\", \"price\":\"0.54\", \"size\":\"75\", \"side\":\"BUY\", \"hash\":\"9b3eb7e898b03b80fe2e9333bf430f29d101a7af\", \"best_bid\":\"0.69\", \"best_ask\":\"0.7\"}, {\"asset_id\":\"69697746896130839564035629862476347944307040470122503199396727085502753297492\", \"price\":\"0.46\", \"size\":\"75\", \"side\":\"SELL\", \"hash\":\"26be71aa561cfbcba2a3eed4645e4e0e841f081f\", \"best_bid\":\"0.3\", \"best_ask\":\"0.31\"}], \"timestamp\":\"1785126963132\", \"event_type\":\"price_change\"}","received_at":"2026-07-27T04:36:03.844640Z","schema_version":"clob-market-ws.price_change.v1","sequence":null,"server_hash":null,"server_timestamp":"1785126963132","session_id":"e9443c7415a0419799bee9cfbb1a9e4d","source":"clob_market_ws"},"received_at":"2026-07-27T04:36:03.844640Z","record_id":"2a16fcd3f9f5c2925970f3c680fac8cbca40beac523c0f4a13c9a5ebe60d420c","schema_fingerprint":"4aa3821a28b0b7c2400bc59aba4bcc0a76e971dadd19610d3ad38c768e124dc7","schema_version":"edge-lab-recorder.raw.v1","sequence":null,"source":"clob_market_ws"}
{"event_at":"2026-07-27T04:36:03.149000Z","event_fingerprint":"b1b03e38eee137d264201bdf01dc7b1d70c4d687954985a5b05916998984e989","payload":{"connection_id":"0f4979d6978d463e9660b042fdcf555f","event_at":"2026-07-27T04:36:03.149000Z","event_type":"price_change","frame_hash":"1e23e8249fb824f4ade3a416033892005650fcf4e3fa8f908df2245552ff3482","frame_index":0,"kind":"data","monotonic_ns":228947121451958,"payload":{"event_type":"price_change","market":"0xeb66215f2e9faa6449e30a02bab5b8ed7b79a38bf961f6b24d0073c9c2419250","price_changes":[{"asset_id":"69697746896130839564035629862476347944307040470122503199396727085502753297492","best_ask":"0.31","best_bid":"0.3","hash":"8da50b6317aa231b1388fa1f2858672fc690b2b5","price":"0.01","side":"BUY","size":"5669.91"},{"asset_id":"60386828328910021732068595344565885737045900010034836345809386672230885527307","best_ask":"0.7","best_bid":"0.69","hash":"d5a1fbdfe82e867fb1e6f51120d5d16422a1381c","price":"0.99","side":"SELL","size":"5669.91"}],"timestamp":"1785126963149"},"payload_hash":"0bddbcd3751ac3a083d73cd27b916fabdbdd88a890d193fc70303d3aca6cda45","raw_frame":"{\"market\":\"0xeb66215f2e9faa6449e30a02bab5b8ed7b79a38bf961f6b24d0073c9c2419250\", \"price_changes\":[{\"asset_id\":\"69697746896130839564035629862476347944307040470122503199396727085502753297492\", \"price\":\"0.01\", \"size\":\"5669.91\", \"side\":\"BUY\", \"hash\":\"8da50b6317aa231b1388fa1f2858672fc690b2b5\", \"best_bid\":\"0.3\", \"best_ask\":\"0.31\"}, {\"asset_id\":\"60386828328910021732068595344565885737045900010034836345809386672230885527307\", \"price\":\"0.99\", \"size\":\"5669.91\", \"side\":\"SELL\", \"hash\":\"d5a1fbdfe82e867fb1e6f51120d5d16422a1381c\", \"best_bid\":\"0.69\", \"best_ask\":\"0.7\"}], \"timestamp\":\"1785126963149\", \"event_type\":\"price_change\"}","received_at":"2026-07-27T04:36:03.854771Z","schema_version":"clob-market-ws.price_change.v1","sequence":null,"server_hash":null,"server_timestamp":"1785126963149","session_id":"e9443c7415a0419799bee9cfbb1a9e4d","source":"clob_market_ws"},"received_at":"2026-07-27T04:36:03.854771Z","record_id":"cc6616ab59bf1562ce8321914ab04c1e0f6f2dddb962ef1655e6ae1d5a6ba935","schema_fingerprint":"4aa3821a28b0b7c2400bc59aba4bcc0a76e971dadd19610d3ad38c768e124dc7","schema_version":"edge-lab-recorder.raw.v1","sequence":null,"source":"clob_market_ws"}
{"event_at":"2026-07-27T04:36:03.166000Z","event_fingerprint":"a1415629749b4917eb01ef4e9b952e8c4f62233a87c10b7487b9a51a4b176282","payload":{"connection_id":"0f4979d6978d463e9660b042fdcf555f","event_at":"2026-07-27T04:36:03.166000Z","event_type":"price_change","frame_hash":"d9307327ce9e037b77a31626825607ca6c295b0c2269cd80fe071950ac39588e","frame_index":0,"kind":"data","monotonic_ns":228947144743041,"payload":{"event_type":"price_change","market":"0xeb66215f2e9faa6449e30a02bab5b8ed7b79a38bf961f6b24d0073c9c2419250","price_changes":[{"asset_id":"60386828328910021732068595344565885737045900010034836345809386672230885527307","best_ask":"0.7","best_bid":"0.69","hash":"dfe9e59de23b1f1eca1d7a1df486641e46bc3e15","price":"0.66","side":"BUY","size":"27.96"},{"asset_id":"69697746896130839564035629862476347944307040470122503199396727085502753297492","best_ask":"0.31","best_bid":"0.3","hash":"3a48ea523a4cc2068b9cbabc142e5624ad58582f","price":"0.34","side":"SELL","size":"27.96"}],"timestamp":"1785126963166"},"payload_hash":"c54b3ba8b788a300033f49525bbce238e0895ac75ce2f7c2f71cf0a31c400295","raw_frame":"{\"market\":\"0xeb66215f2e9faa6449e30a02bab5b8ed7b79a38bf961f6b24d0073c9c2419250\", \"price_changes\":[{\"asset_id\":\"60386828328910021732068595344565885737045900010034836345809386672230885527307\", \"price\":\"0.66\", \"size\":\"27.96\", \"side\":\"BUY\", \"hash\":\"dfe9e59de23b1f1eca1d7a1df486641e46bc3e15\", \"best_bid\":\"0.69\", \"best_ask\":\"0.7\"}, {\"asset_id\":\"69697746896130839564035629862476347944307040470122503199396727085502753297492\", \"price\":\"0.34\", \"size\":\"27.96\", \"side\":\"SELL\", \"hash\":\"3a48ea523a4cc2068b9cbabc142e5624ad58582f\", \"best_bid\":\"0.3\", \"best_ask\":\"0.31\"}], \"timestamp\":\"1785126963166\", \"event_type\":\"price_change\"}","received_at":"2026-07-27T04:36:03.878058Z","schema_version":"clob-market-ws.price_change.v1","sequence":null,"server_hash":null,"server_timestamp":"1785126963166","session_id":"e9443c7415a0419799bee9cfbb1a9e4d","source":"clob_market_ws"},"received_at":"2026-07-27T04:36:03.878058Z","record_id":"4e88422e23eb39b8417abbbab64c98ae0d9035d47eaae097981b3adee8ff427c","schema_fingerprint":"4aa3821a28b0b7c2400bc59aba4bcc0a76e971dadd19610d3ad38c768e124dc7","schema_version":"edge-lab-recorder.raw.v1","sequence":null,"source":"clob_market_ws"}
{"event_at":"2026-07-27T04:36:03.166000Z","event_fingerprint":"57a261974468304f734dbc63367f5ed5eb54b71be7237d7f484d1e6705113c1d","payload":{"connection_id":"0f4979d6978d463e9660b042fdcf555f","event_at":"2026-07-27T04:36:03.166000Z","event_type":"price_change","frame_hash":"dfc23d4fcb5262849740eab35d5e04f63ed7512b42ade6b47e722aad59494cba","frame_index":0,"kind":"data","monotonic_ns":228947151295708,"payload":{"event_type":"price_change","market":"0xeb66215f2e9faa6449e30a02bab5b8ed7b79a38bf961f6b24d0073c9c2419250","price_changes":[{"asset_id":"69697746896130839564035629862476347944307040470122503199396727085502753297492","best_ask":"0.31","best_bid":"0.3","hash":"3a48ea523a4cc2068b9cbabc142e5624ad58582f","price":"0.27","side":"BUY","size":"203.12"},{"asset_id":"60386828328910021732068595344565885737045900010034836345809386672230885527307","best_ask":"0.7","best_bid":"0.69","hash":"dfe9e59de23b1f1eca1d7a1df486641e46bc3e15","price":"0.73","side":"SELL","size":"203.12"}],"timestamp":"1785126963166"},"payload_hash":"9255188aebe9d9b8501607994fb56d7b721bc5a03b3ff18ac0814428adb6a754","raw_frame":"{\"market\":\"0xeb66215f2e9faa6449e30a02bab5b8ed7b79a38bf961f6b24d0073c9c2419250\", \"price_changes\":[{\"asset_id\":\"69697746896130839564035629862476347944307040470122503199396727085502753297492\", \"price\":\"0.27\", \"size\":\"203.12\", \"side\":\"BUY\", \"hash\":\"3a48ea523a4cc2068b9cbabc142e5624ad58582f\", \"best_bid\":\"0.3\", \"best_ask\":\"0.31\"}, {\"asset_id\":\"60386828328910021732068595344565885737045900010034836345809386672230885527307\", \"price\":\"0.73\", \"size\":\"203.12\", \"side\":\"SELL\", \"hash\":\"dfe9e59de23b1f1eca1d7a1df486641e46bc3e15\", \"best_bid\":\"0.69\", \"best_ask\":\"0.7\"}], \"timestamp\":\"1785126963166\", \"event_type\":\"price_change\"}","received_at":"2026-07-27T04:36:03.884614Z","schema_version":"clob-market-ws.price_change.v1","sequence":null,"server_hash":null,"server_timestamp":"1785126963166","session_id":"e9443c7415a0419799bee9cfbb1a9e4d","source":"clob_market_ws"},"received_at":"2026-07-27T04:36:03.884614Z","record_id":"68a4f0865566f773989556b16a158fe5f5e48c9d6df20749867017b98f0da5fb","schema_fingerprint":"4aa3821a28b0b7c2400bc59aba4bcc0a76e971dadd19610d3ad38c768e124dc7","schema_version":"edge-lab-recorder.raw.v1","sequence":null,"source":"clob_market_ws"}
{"event_at":"2026-07-27T04:36:03.193000Z","event_fingerprint":"569566809dbb3bead2db0014301d50d9720a048db8228a7c9996b3e5dc46f61b","payload":{"connection_id":"0f4979d6978d463e9660b042fdcf555f","event_at":"2026-07-27T04:36:03.193000Z","event_type":"price_change","frame_hash":"28c6e54732764e1c347c3b1140ed8f0dc2c90cf9cf46f387813b5de034300d5d","frame_index":0,"kind":"data","monotonic_ns":228947159293083,"payload":{"event_type":"price_change","market":"0xeb66215f2e9faa6449e30a02bab5b8ed7b79a38bf961f6b24d0073c9c2419250","price_changes":[{"asset_id":"60386828328910021732068595344565885737045900010034836345809386672230885527307","best_ask":"0.7","best_bid":"0.69","hash":"363eb71b505560b0bd16df0e42757512c7e2c50a","price":"0.65","side":"BUY","size":"51.77"},{"asset_id":"69697746896130839564035629862476347944307040470122503199396727085502753297492","best_ask":"0.31","best_bid":"0.3","hash":"35529a4954f250df0603d071784ff445d27ec8af","price":"0.35","side":"SELL","size":"51.77"}],"timestamp":"1785126963193"},"payload_hash":"3c4dabbd1f7f3c7f7eed43379b8002bd5a434028c3740a605d51c55ae7f4a842","raw_frame":"{\"market\":\"0xeb66215f2e9faa6449e30a02bab5b8ed7b79a38bf961f6b24d0073c9c2419250\", \"price_changes\":[{\"asset_id\":\"60386828328910021732068595344565885737045900010034836345809386672230885527307\", \"price\":\"0.65\", \"size\":\"51.77\", \"side\":\"BUY\", \"hash\":\"363eb71b505560b0bd16df0e42757512c7e2c50a\", \"best_bid\":\"0.69\", \"best_ask\":\"0.7\"}, {\"asset_id\":\"69697746896130839564035629862476347944307040470122503199396727085502753297492\", \"price\":\"0.35\", \"size\":\"51.77\", \"side\":\"SELL\", \"hash\":\"35529a4954f250df0603d071784ff445d27ec8af\", \"best_bid\":\"0.3\", \"best_ask\":\"0.31\"}], \"timestamp\":\"1785126963193\", \"event_type\":\"price_change\"}","received_at":"2026-07-27T04:36:03.892611Z","schema_version":"clob-market-ws.price_change.v1","sequence":null,"server_hash":null,"server_timestamp":"1785126963193","session_id":"e9443c7415a0419799bee9cfbb1a9e4d","source":"clob_market_ws"},"received_at":"2026-07-27T04:36:03.892611Z","record_id":"be3a37196fd313148b44d95b8dc775f711be376c50355f6ba5357f7f15827b12","schema_fingerprint":"4aa3821a28b0b7c2400bc59aba4bcc0a76e971dadd19610d3ad38c768e124dc7","schema_version":"edge-lab-recorder.raw.v1","sequence":null,"source":"clob_market_ws"}
{"event_at":"2026-07-27T04:36:03.194000Z","event_fingerprint":"67c13bf8a8e8fc1ad9982fb8e164ac0e5ce013004997b289a000cd83982e157a","payload":{"connection_id":"0f4979d6978d463e9660b042fdcf555f","event_at":"2026-07-27T04:36:03.194000Z","event_type":"price_change","frame_hash":"aed7a6f97f7c906f8edcd25ce8ab1f6fc764ec35bd56461dadf92528e8bae4e5","frame_index":0,"kind":"data","monotonic_ns":228947167638875,"payload":{"event_type":"price_change","market":"0xeb66215f2e9faa6449e30a02bab5b8ed7b79a38bf961f6b24d0073c9c2419250","price_changes":[{"asset_id":"69697746896130839564035629862476347944307040470122503199396727085502753297492","best_ask":"0.31","best_bid":"0.3","hash":"35431975bb49b390f5656bcb1f361b6036b99f69","price":"0.28","side":"BUY","size":"37.6"},{"asset_id":"60386828328910021732068595344565885737045900010034836345809386672230885527307","best_ask":"0.7","best_bid":"0.69","hash":"b8e969c1cd649c8adc47d7bd5828377f26b231d5","price":"0.72","side":"SELL","size":"37.6"}],"timestamp":"1785126963194"},"payload_hash":"59a350e530c3bdc8180f6685e09c55fccf49caf5ba10a0583da0ff3a4e0484f7","raw_frame":"{\"market\":\"0xeb66215f2e9faa6449e30a02bab5b8ed7b79a38bf961f6b24d0073c9c2419250\", \"price_changes\":[{\"asset_id\":\"69697746896130839564035629862476347944307040470122503199396727085502753297492\", \"price\":\"0.28\", \"size\":\"37.6\", \"side\":\"BUY\", \"hash\":\"35431975bb49b390f5656bcb1f361b6036b99f69\", \"best_bid\":\"0.3\", \"best_ask\":\"0.31\"}, {\"asset_id\":\"60386828328910021732068595344565885737045900010034836345809386672230885527307\", \"price\":\"0.72\", \"size\":\"37.6\", \"side\":\"SELL\", \"hash\":\"b8e969c1cd649c8adc47d7bd5828377f26b231d5\", \"best_bid\":\"0.69\", \"best_ask\":\"0.7\"}], \"timestamp\":\"1785126963194\", \"event_type\":\"price_change\"}","received_at":"2026-07-27T04:36:03.900959Z","schema_version":"clob-market-ws.price_change.v1","sequence":null,"server_hash":null,"server_timestamp":"1785126963194","session_id":"e9443c7415a0419799bee9cfbb1a9e4d","source":"clob_market_ws"},"received_at":"2026-07-27T04:36:03.900959Z","record_id":"de5b3adb15d7f31baeed4741da68901f5ed0ba8dcf29769fdd8d0ae9c2ff31f9","schema_fingerprint":"4aa3821a28b0b7c2400bc59aba4bcc0a76e971dadd19610d3ad38c768e124dc7","schema_version":"edge-lab-recorder.raw.v1","sequence":null,"source":"clob_market_ws"}
{"event_at":"2026-07-27T04:36:03.219000Z","event_fingerprint":"f73814c3732c3253f47b2a5ddc2c64ed99ff7aa76694c01cf60317cc1158c177","payload":{"connection_id":"0f4979d6978d463e9660b042fdcf555f","event_at":"2026-07-27T04:36:03.219000Z","event_type":"price_change","frame_hash":"f460d5dad904d090cc831c241b1adbab9562f39ee98a3a94446af0979a46f20e","frame_index":0,"kind":"data","monotonic_ns":228947174329125,"payload":{"event_type":"price_change","market":"0xeb66215f2e9faa6449e30a02bab5b8ed7b79a38bf961f6b24d0073c9c2419250","price_changes":[{"asset_id":"60386828328910021732068595344565885737045900010034836345809386672230885527307","best_ask":"0.7","best_bid":"0.69","hash":"19a27ca6257acea3f62aeb2cacf0742ea8553267","price":"0.03","side":"BUY","size":"648.1"},{"asset_id":"69697746896130839564035629862476347944307040470122503199396727085502753297492","best_ask":"0.31","best_bid":"0.3","hash":"16f90cf3bf670878f6ebbf552486bd90a196fb01","price":"0.97","side":"SELL","size":"648.1"}],"timestamp":"1785126963219"},"payload_hash":"ceb21b4002f4789a4162061e3c1e44e00ed365093a7b6e2f0788e62962c865cd","raw_frame":"{\"market\":\"0xeb66215f2e9faa6449e30a02bab5b8ed7b79a38bf961f6b24d0073c9c2419250\", \"price_changes\":[{\"asset_id\":\"60386828328910021732068595344565885737045900010034836345809386672230885527307\", \"price\":\"0.03\", \"size\":\"648.1\", \"side\":\"BUY\", \"hash\":\"19a27ca6257acea3f62aeb2cacf0742ea8553267\", \"best_bid\":\"0.69\", \"best_ask\":\"0.7\"}, {\"asset_id\":\"69697746896130839564035629862476347944307040470122503199396727085502753297492\", \"price\":\"0.97\", \"size\":\"648.1\", \"side\":\"SELL\", \"hash\":\"16f90cf3bf670878f6ebbf552486bd90a196fb01\", \"best_bid\":\"0.3\", \"best_ask\":\"0.31\"}], \"timestamp\":\"1785126963219\", \"event_type\":\"price_change\"}","received_at":"2026-07-27T04:36:03.907646Z","schema_version":"clob-market-ws.price_change.v1","sequence":null,"server_hash":null,"server_timestamp":"1785126963219","session_id":"e9443c7415a0419799bee9cfbb1a9e4d","source":"clob_market_ws"},"received_at":"2026-07-27T04:36:03.907646Z","record_id":"a6c6e87c5fa187236af1d647f91c0ed7ca74653ea252834eb98d9085f902d225","schema_fingerprint":"4aa3821a28b0b7c2400bc59aba4bcc0a76e971dadd19610d3ad38c768e124dc7","schema_version":"edge-lab-recorder.raw.v1","sequence":null,"source":"clob_market_ws"}
{"event_at":"2026-07-27T04:36:03.234000Z","event_fingerprint":"df3b713adf8641122a062312c2fb3a21af6645cd3d07a4f0105698aa2cb0f4f7","payload":{"connection_id":"0f4979d6978d463e9660b042fdcf555f","event_at":"2026-07-27T04:36:03.234000Z","event_type":"price_change","frame_hash":"8053d58b65f6a13dd1a2cf7edd608d06aa25c4c4ef132be85c057741e9c981b9","frame_index":0,"kind":"data","monotonic_ns":228947181238791,"payload":{"event_type":"price_change","market":"0xeb66215f2e9faa6449e30a02bab5b8ed7b79a38bf961f6b24d0073c9c2419250","price_changes":[{"asset_id":"69697746896130839564035629862476347944307040470122503199396727085502753297492","best_ask":"0.31","best_bid":"0.3","hash":"577db1c2682e04ab0bd42fd3e23baaa54b43362f","price":"0.33","side":"SELL","size":"414.56"},{"asset_id":"60386828328910021732068595344565885737045900010034836345809386672230885527307","best_ask":"0.7","best_bid":"0.69","hash":"0de94c64cf5200314e2776d6df1737a280021e58","price":"0.67","side":"BUY","size":"414.56"}],"timestamp":"1785126963234"},"payload_hash":"0ec04bcb44f451dfcf618c46680e7b2bf210cb8254edd7458a721e71b3748769","raw_frame":"{\"market\":\"0xeb66215f2e9faa6449e30a02bab5b8ed7b79a38bf961f6b24d0073c9c2419250\", \"price_changes\":[{\"asset_id\":\"69697746896130839564035629862476347944307040470122503199396727085502753297492\", \"price\":\"0.33\", \"size\":\"414.56\", \"side\":\"SELL\", \"hash\":\"577db1c2682e04ab0bd42fd3e23baaa54b43362f\", \"best_bid\":\"0.3\", \"best_ask\":\"0.31\"}, {\"asset_id\":\"60386828328910021732068595344565885737045900010034836345809386672230885527307\", \"price\":\"0.67\", \"size\":\"414.56\", \"side\":\"BUY\", \"hash\":\"0de94c64cf5200314e2776d6df1737a280021e58\", \"best_bid\":\"0.69\", \"best_ask\":\"0.7\"}], \"timestamp\":\"1785126963234\", \"event_type\":\"price_change\"}","received_at":"2026-07-27T04:36:03.914557Z","schema_version":"clob-market-ws.price_change.v1","sequence":null,"server_hash":null,"server_timestamp":"1785126963234","session_id":"e9443c7415a0419799bee9cfbb1a9e4d","source":"clob_market_ws"},"received_at":"2026-07-27T04:36:03.914557Z","record_id":"76e37376ca7a294c6099b90e5085b1b318b97eb1b1516e8f89f5793e0bd7ede6","schema_fingerprint":"4aa3821a28b0b7c2400bc59aba4bcc0a76e971dadd19610d3ad38c768e124dc7","schema_version":"edge-lab-recorder.raw.v1","sequence":null,"source":"clob_market_ws"}
{"event_at":"2026-07-27T04:36:03.241000Z","event_fingerprint":"831879ed02bd271a2d5dd956371b6d167795ea3f51712a3e623145f5b45581a3","payload":{"connection_id":"0f4979d6978d463e9660b042fdcf555f","event_at":"2026-07-27T04:36:03.241000Z","event_type":"price_change","frame_hash":"2e368da5583e1bae33b71edd3adb0a8cee36725913fc62592e4b889daaafcca9","frame_index":0,"kind":"data","monotonic_ns":228947187928333,"payload":{"event_type":"price_change","market":"0xeb66215f2e9faa6449e30a02bab5b8ed7b79a38bf961f6b24d0073c9c2419250","price_changes":[{"asset_id":"60386828328910021732068595344565885737045900010034836345809386672230885527307","best_ask":"0.7","best_bid":"0.69","hash":"8906032652cbc5e0be9a14146f97aa10bdf47710","price":"0.74","side":"SELL","size":"60.63"},{"asset_id":"69697746896130839564035629862476347944307040470122503199396727085502753297492","best_ask":"0.31","best_bid":"0.3","hash":"979b4223e8fcf7cd8ddba0986447a319cd36ff82","price":"0.26","side":"BUY","size":"60.63"}],"timestamp":"1785126963241"},"payload_hash":"b856ff73d7bc2ff15bbe83d973867e65981c85ae79b383c03c11a51fcc858396","raw_frame":"{\"market\":\"0xeb66215f2e9faa6449e30a02bab5b8ed7b79a38bf961f6b24d0073c9c2419250\", \"price_changes\":[{\"asset_id\":\"60386828328910021732068595344565885737045900010034836345809386672230885527307\", \"price\":\"0.74\", \"size\":\"60.63\", \"side\":\"SELL\", \"hash\":\"8906032652cbc5e0be9a14146f97aa10bdf47710\", \"best_bid\":\"0.69\", \"best_ask\":\"0.7\"}, {\"asset_id\":\"69697746896130839564035629862476347944307040470122503199396727085502753297492\", \"price\":\"0.26\", \"size\":\"60.63\", \"side\":\"BUY\", \"hash\":\"979b4223e8fcf7cd8ddba0986447a319cd36ff82\", \"best_bid\":\"0.3\", \"best_ask\":\"0.31\"}], \"timestamp\":\"1785126963241\", \"event_type\":\"price_change\"}","received_at":"2026-07-27T04:36:03.921245Z","schema_version":"clob-market-ws.price_change.v1","sequence":null,"server_hash":null,"server_timestamp":"1785126963241","session_id":"e9443c7415a0419799bee9cfbb1a9e4d","source":"clob_market_ws"},"received_at":"2026-07-27T04:36:03.921245Z","record_id":"bc9244a6d22d3d669d8a4707652996e92d68737c6ad63121136f645b473ecc96","schema_fingerprint":"4aa3821a28b0b7c2400bc59aba4bcc0a76e971dadd19610d3ad38c768e124dc7","schema_version":"edge-lab-recorder.raw.v1","sequence":null,"source":"clob_market_ws"}
{"event_at":"2026-07-27T04:36:03.247000Z","event_fingerprint":"b3de2ab85bf18d05b0afec43c8daf9750b30c89fb3c8d4c0e737ecc077b5ac2e","payload":{"connection_id":"0f4979d6978d463e9660b042fdcf555f","event_at":"2026-07-27T04:36:03.247000Z","event_type":"price_change","frame_hash":"557c773d35cf3760a86b2a770df51c0baeca151c6b184c5a5d27d39fdd9f7bd7","frame_index":0,"kind":"data","monotonic_ns":228947193046916,"payload":{"event_type":"price_change","market":"0xeb66215f2e9faa6449e30a02bab5b8ed7b79a38bf961f6b24d0073c9c2419250","price_changes":[{"asset_id":"60386828328910021732068595344565885737045900010034836345809386672230885527307","best_ask":"0.7","best_bid":"0.69","hash":"19fb83a6dfafea283ee41bea75e2f4ce57afc4af","price":"0.67","side":"BUY","size":"445.6"},{"asset_id":"69697746896130839564035629862476347944307040470122503199396727085502753297492","best_ask":"0.31","best_bid":"0.3","hash":"8caa87a84ccd04d258b7eda60429cdb664d004a1","price":"0.33","side":"SELL","size":"445.6"}],"timestamp":"1785126963247"},"payload_hash":"6ddff60c2ec47875a38a5f60062d740e31236d0842161b598d316b84a1947f45","raw_frame":"{\"market\":\"0xeb66215f2e9faa6449e30a02bab5b8ed7b79a38bf961f6b24d0073c9c2419250\", \"price_changes\":[{\"asset_id\":\"60386828328910021732068595344565885737045900010034836345809386672230885527307\", \"price\":\"0.67\", \"size\":\"445.6\", \"side\":\"BUY\", \"hash\":\"19fb83a6dfafea283ee41bea75e2f4ce57afc4af\", \"best_bid\":\"0.69\", \"best_ask\":\"0.7\"}, {\"asset_id\":\"69697746896130839564035629862476347944307040470122503199396727085502753297492\", \"price\":\"0.33\", \"size\":\"445.6\", \"side\":\"SELL\", \"hash\":\"8caa87a84ccd04d258b7eda60429cdb664d004a1\", \"best_bid\":\"0.3\", \"best_ask\":\"0.31\"}], \"timestamp\":\"1785126963247\", \"event_type\":\"price_change\"}","received_at":"2026-07-27T04:36:03.926366Z","schema_version":"clob-market-ws.price_change.v1","sequence":null,"server_hash":null,"server_timestamp":"1785126963247","session_id":"e9443c7415a0419799bee9cfbb1a9e4d","source":"clob_market_ws"},"received_at":"2026-07-27T04:36:03.926366Z","record_id":"02cb21023191302e4af414273b9dcfa944e34a84135008006dcbfa64b5f5ef1d","schema_fingerprint":"4aa3821a28b0b7c2400bc59aba4bcc0a76e971dadd19610d3ad38c768e124dc7","schema_version":"edge-lab-recorder.raw.v1","sequence":null,"source":"clob_market_ws"}
{"event_at":"2026-07-27T04:36:03.253000Z","event_fingerprint":"46c0f3f38c6813180123ea2e271ad9bf22947b9fb371dc783702a2fd4033f45d","payload":{"connection_id":"0f4979d6978d463e9660b042fdcf555f","event_at":"2026-07-27T04:36:03.253000Z","event_type":"price_change","frame_hash":"440826682f75f122d4ededbf4e69833d9f72aa6666574d6a577f83ecaa9e3a09","frame_index":0,"kind":"data","monotonic_ns":228947198667500,"payload":{"event_type":"price_change","market":"0xeb66215f2e9faa6449e30a02bab5b8ed7b79a38bf961f6b24d0073c9c2419250","price_changes":[{"asset_id":"60386828328910021732068595344565885737045900010034836345809386672230885527307","best_ask":"0.7","best_bid":"0.69","hash":"9c6171554913f50ac8df7f95124a95c70f9d2851","price":"0.01","side":"BUY","size":"5458.02"},{"asset_id":"69697746896130839564035629862476347944307040470122503199396727085502753297492","best_ask":"0.31","best_bid":"0.3","hash":"40840bc398fca966af1f1f1de16b783daf8350c3","price":"0.99","side":"SELL","size":"5458.02"}],"timestamp":"1785126963253"},"payload_hash":"32588a8d9715da96e3eee5d8c3b2d32ba3e2c36e21f85629f763935002a3359a","raw_frame":"{\"market\":\"0xeb66215f2e9faa6449e30a02bab5b8ed7b79a38bf961f6b24d0073c9c2419250\", \"price_changes\":[{\"asset_id\":\"60386828328910021732068595344565885737045900010034836345809386672230885527307\", \"price\":\"0.01\", \"size\":\"5458.02\", \"side\":\"BUY\", \"hash\":\"9c6171554913f50ac8df7f95124a95c70f9d2851\", \"best_bid\":\"0.69\", \"best_ask\":\"0.7\"}, {\"asset_id\":\"69697746896130839564035629862476347944307040470122503199396727085502753297492\", \"price\":\"0.99\", \"size\":\"5458.02\", \"side\":\"SELL\", \"hash\":\"40840bc398fca966af1f1f1de16b783daf8350c3\", \"best_bid\":\"0.3\", \"best_ask\":\"0.31\"}], \"timestamp\":\"1785126963253\", \"event_type\":\"price_change\"}","received_at":"2026-07-27T04:36:03.931988Z","schema_version":"clob-market-ws.price_change.v1","sequence":null,"server_hash":null,"server_timestamp":"1785126963253","session_id":"e9443c7415a0419799bee9cfbb1a9e4d","source":"clob_market_ws"},"received_at":"2026-07-27T04:36:03.931988Z","record_id":"bc93784e586c63aa03ca3b7affb821dd4e4bedfd4d92dadd7590abf89cb09081","schema_fingerprint":"4aa3821a28b0b7c2400bc59aba4bcc0a76e971dadd19610d3ad38c768e124dc7","schema_version":"edge-lab-recorder.raw.v1","sequence":null,"source":"clob_market_ws"}
{"event_at":"2026-07-27T04:36:03.270000Z","event_fingerprint":"5039bd83061bc763bba341951de9ca75847fa0be98ab2e038470bcc3745c9496","payload":{"connection_id":"0f4979d6978d463e9660b042fdcf555f","event_at":"2026-07-27T04:36:03.270000Z","event_type":"price_change","frame_hash":"87b5309b657b4f6967bd3a5d6cb1017a4b9bad2cd53df0eb43f8da60842c682e","frame_index":0,"kind":"data","monotonic_ns":228947209113416,"payload":{"event_type":"price_change","market":"0xeb66215f2e9faa6449e30a02bab5b8ed7b79a38bf961f6b24d0073c9c2419250","price_changes":[{"asset_id":"60386828328910021732068595344565885737045900010034836345809386672230885527307","best_ask":"0.7","best_bid":"0.69","hash":"10882dd16e42ca145c0cc8e8ee9c93f9001ec515","price":"0.03","side":"BUY","size":"643.1"},{"asset_id":"69697746896130839564035629862476347944307040470122503199396727085502753297492","best_ask":"0.31","best_bid":"0.3","hash":"2256484517e47cc2a74da999e330293dd3ee9849","price":"0.97","side":"SELL","size":"643.1"}],"timestamp":"1785126963270"},"payload_hash":"53d1bb998cff4efa02bab0e82b37f93300a6013c68fb31884d28312c858bc480","raw_frame":"{\"market\":\"0xeb66215f2e9faa6449e30a02bab5b8ed7b79a38bf961f6b24d0073c9c2419250\", \"price_changes\":[{\"asset_id\":\"60386828328910021732068595344565885737045900010034836345809386672230885527307\", \"price\":\"0.03\", \"size\":\"643.1\", \"side\":\"BUY\", \"hash\":\"10882dd16e42ca145c0cc8e8ee9c93f9001ec515\", \"best_bid\":\"0.69\", \"best_ask\":\"0.7\"}, {\"asset_id\":\"69697746896130839564035629862476347944307040470122503199396727085502753297492\", \"price\":\"0.97\", \"size\":\"643.1\", \"side\":\"SELL\", \"hash\":\"2256484517e47cc2a74da999e330293dd3ee9849\", \"best_bid\":\"0.3\", \"best_ask\":\"0.31\"}], \"timestamp\":\"1785126963270\", \"event_type\":\"price_change\"}","received_at":"2026-07-27T04:36:03.942432Z","schema_version":"clob-market-ws.price_change.v1","sequence":null,"server_hash":null,"server_timestamp":"1785126963270","session_id":"e9443c7415a0419799bee9cfbb1a9e4d","source":"clob_market_ws"},"received_at":"2026-07-27T04:36:03.942432Z","record_id":"e532893d008b4b82d6088d369273c5eac73b4169d2938c4f918ead5545dbea70","schema_fingerprint":"4aa3821a28b0b7c2400bc59aba4bcc0a76e971dadd19610d3ad38c768e124dc7","schema_version":"edge-lab-recorder.raw.v1","sequence":null,"source":"clob_market_ws"}
{"event_at":"2026-07-27T04:36:03.307000Z","event_fingerprint":"a1bf3151f1160eb9615a6df92f7cdce8612a121a6f508e07fddc93431c9b92f3","payload":{"connection_id":"0f4979d6978d463e9660b042fdcf555f","event_at":"2026-07-27T04:36:03.307000Z","event_type":"price_change","frame_hash":"cef13178aa5376bd550c69d2c4f5e13bfabbbca9474d5061119244f7267a3c6f","frame_index":0,"kind":"data","monotonic_ns":228947216041250,"payload":{"event_type":"price_change","market":"0xeb66215f2e9faa6449e30a02bab5b8ed7b79a38bf961f6b24d0073c9c2419250","price_changes":[{"asset_id":"60386828328910021732068595344565885737045900010034836345809386672230885527307","best_ask":"0.7","best_bid":"0.69","hash":"41ee7d479ab36333a5f99d892d8e68a18fbf8cd9","price":"0.01","side":"BUY","size":"5453.02"},{"asset_id":"69697746896130839564035629862476347944307040470122503199396727085502753297492","best_ask":"0.31","best_bid":"0.3","hash":"366406eb6dee33269ec999eb4920b7a6e525afa7","price":"0.99","side":"SELL","size":"5453.02"}],"timestamp":"1785126963307"},"payload_hash":"016cc393e0cbb369fc7d9af73c5cbc0f7b214bf7fc6327f8fa14c6fde420ccf3","raw_frame":"{\"market\":\"0xeb66215f2e9faa6449e30a02bab5b8ed7b79a38bf961f6b24d0073c9c2419250\", \"price_changes\":[{\"asset_id\":\"60386828328910021732068595344565885737045900010034836345809386672230885527307\", \"price\":\"0.01\", \"size\":\"5453.02\", \"side\":\"BUY\", \"hash\":\"41ee7d479ab36333a5f99d892d8e68a18fbf8cd9\", \"best_bid\":\"0.69\", \"best_ask\":\"0.7\"}, {\"asset_id\":\"69697746896130839564035629862476347944307040470122503199396727085502753297492\", \"price\":\"0.99\", \"size\":\"5453.02\", \"side\":\"SELL\", \"hash\":\"366406eb6dee33269ec999eb4920b7a6e525afa7\", \"best_bid\":\"0.3\", \"best_ask\":\"0.31\"}], \"timestamp\":\"1785126963307\", \"event_type\":\"price_change\"}","received_at":"2026-07-27T04:36:03.949362Z","schema_version":"clob-market-ws.price_change.v1","sequence":null,"server_hash":null,"server_timestamp":"1785126963307","session_id":"e9443c7415a0419799bee9cfbb1a9e4d","source":"clob_market_ws"},"received_at":"2026-07-27T04:36:03.949362Z","record_id":"9370b068c023cd69734f1b1c822661236deaa8276911e52a9e541543e7f406af","schema_fingerprint":"4aa3821a28b0b7c2400bc59aba4bcc0a76e971dadd19610d3ad38c768e124dc7","schema_version":"edge-lab-recorder.raw.v1","sequence":null,"source":"clob_market_ws"}
{"event_at":"2026-07-27T04:36:03.340000Z","event_fingerprint":"a7d5e370b0ff57511865d1e008751b34deab2c8df7c1db5d57f1a6c806b054a6","payload":{"connection_id":"0f4979d6978d463e9660b042fdcf555f","event_at":"2026-07-27T04:36:03.340000Z","event_type":"price_change","frame_hash":"6bd4b0a6e983d5755df770a8087636c19b8012f90601afc919e064a357cad90f","frame_index":0,"kind":"data","monotonic_ns":228947223897875,"payload":{"event_type":"price_change","market":"0xeb66215f2e9faa6449e30a02bab5b8ed7b79a38bf961f6b24d0073c9c2419250","price_changes":[{"asset_id":"60386828328910021732068595344565885737045900010034836345809386672230885527307","best_ask":"0.7","best_bid":"0.69","hash":"b345c1826db5171482c378773de80dc57309ab38","price":"0.67","side":"BUY","size":"414.56"},{"asset_id":"69697746896130839564035629862476347944307040470122503199396727085502753297492","best_ask":"0.31","best_bid":"0.3","hash":"0b7c65bb2a45fda6b94d87ee4c8f6d3b431e96a7","price":"0.33","side":"SELL","size":"414.56"}],"timestamp":"1785126963340"},"payload_hash":"48a0e808d03a40d30dfb6d932dace045477b92d7e9316fa09789e98c78f8778f","raw_frame":"{\"market\":\"0xeb66215f2e9faa6449e30a02bab5b8ed7b79a38bf961f6b24d0073c9c2419250\", \"price_changes\":[{\"asset_id\":\"60386828328910021732068595344565885737045900010034836345809386672230885527307\", \"price\":\"0.67\", \"size\":\"414.56\", \"side\":\"BUY\", \"hash\":\"b345c1826db5171482c378773de80dc57309ab38\", \"best_bid\":\"0.69\", \"best_ask\":\"0.7\"}, {\"asset_id\":\"69697746896130839564035629862476347944307040470122503199396727085502753297492\", \"price\":\"0.33\", \"size\":\"414.56\", \"side\":\"SELL\", \"hash\":\"0b7c65bb2a45fda6b94d87ee4c8f6d3b431e96a7\", \"best_bid\":\"0.3\", \"best_ask\":\"0.31\"}], \"timestamp\":\"1785126963340\", \"event_type\":\"price_change\"}","received_at":"2026-07-27T04:36:03.957217Z","schema_version":"clob-market-ws.price_change.v1","sequence":null,"server_hash":null,"server_timestamp":"1785126963340","session_id":"e9443c7415a0419799bee9cfbb1a9e4d","source":"clob_market_ws"},"received_at":"2026-07-27T04:36:03.957217Z","record_id":"1fef23c5f07d6e2d4e5787f18b69eb2959bcc98b9b5786a4dd8fcc7e31999859","schema_fingerprint":"4aa3821a28b0b7c2400bc59aba4bcc0a76e971dadd19610d3ad38c768e124dc7","schema_version":"edge-lab-recorder.raw.v1","sequence":null,"source":"clob_market_ws"}
{"event_at":"2026-07-27T04:36:03.343000Z","event_fingerprint":"25e831ac9d6691012e1076dba0e6403e05814ff8973cf566540f5cc82f0776e6","payload":{"connection_id":"0f4979d6978d463e9660b042fdcf555f","event_at":"2026-07-27T04:36:03.343000Z","event_type":"price_change","frame_hash":"806490cf153327536fc0e6b7582ea172bfea682c0234e6e0da32fab74805a9a1","frame_index":0,"kind":"data","monotonic_ns":228947232021083,"payload":{"event_type":"price_change","market":"0xeb66215f2e9faa6449e30a02bab5b8ed7b79a38bf961f6b24d0073c9c2419250","price_changes":[{"asset_id":"69697746896130839564035629862476347944307040470122503199396727085502753297492","best_ask":"0.31","best_bid":"0.3","hash":"dada828436d46e8d33117cb305d9c4943eb3bef7","price":"0.33","side":"SELL","size":"444.6"},{"asset_id":"60386828328910021732068595344565885737045900010034836345809386672230885527307","best_ask":"0.7","best_bid":"0.69","hash":"ed6eca44a992ca323f8fec7f25e10d518ec4a4ac","price":"0.67","side":"BUY","size":"444.6"}],"timestamp":"1785126963343"},"payload_hash":"2f92c54bfd8fda17fd273ce371e1de99d9572278872d26f9ae3a23d2749f075d","raw_frame":"{\"market\":\"0xeb66215f2e9faa6449e30a02bab5b8ed7b79a38bf961f6b24d0073c9c2419250\", \"price_changes\":[{\"asset_id\":\"69697746896130839564035629862476347944307040470122503199396727085502753297492\", \"price\":\"0.33\", \"size\":\"444.6\", \"side\":\"SELL\", \"hash\":\"dada828436d46e8d33117cb305d9c4943eb3bef7\", \"best_bid\":\"0.3\", \"best_ask\":\"0.31\"}, {\"asset_id\":\"60386828328910021732068595344565885737045900010034836345809386672230885527307\", \"price\":\"0.67\", \"size\":\"444.6\", \"side\":\"BUY\", \"hash\":\"ed6eca44a992ca323f8fec7f25e10d518ec4a4ac\", \"best_bid\":\"0.69\", \"best_ask\":\"0.7\"}], \"timestamp\":\"1785126963343\", \"event_type\":\"price_change\"}","received_at":"2026-07-27T04:36:03.965341Z","schema_version":"clob-market-ws.price_change.v1","sequence":null,"server_hash":null,"server_timestamp":"1785126963343","session_id":"e9443c7415a0419799bee9cfbb1a9e4d","source":"clob_market_ws"},"received_at":"2026-07-27T04:36:03.965341Z","record_id":"0edc1ec25fe335e36f4d0fbad99d50efaa9a61d7eadb528b270b9aa2d5366b69","schema_fingerprint":"4aa3821a28b0b7c2400bc59aba4bcc0a76e971dadd19610d3ad38c768e124dc7","schema_version":"edge-lab-recorder.raw.v1","sequence":null,"source":"clob_market_ws"}
{"event_at":"2026-07-27T04:36:03.344000Z","event_fingerprint":"a74bd6a91a1345ba00d44094c4fc5852da3fe76146b05e6ceafe0f3bc7e71e87","payload":{"connection_id":"0f4979d6978d463e9660b042fdcf555f","event_at":"2026-07-27T04:36:03.344000Z","event_type":"price_change","frame_hash":"f3007df4ac0f57361c2434d86b37833524bd27beeebde2bdb5c2342851448503","frame_index":0,"kind":"data","monotonic_ns":228947239477125,"payload":{"event_type":"price_change","market":"0xeb66215f2e9faa6449e30a02bab5b8ed7b79a38bf961f6b24d0073c9c2419250","price_changes":[{"asset_id":"69697746896130839564035629862476347944307040470122503199396727085502753297492","best_ask":"0.31","best_bid":"0.3","hash":"91a29fe0a6aab702bc2d2e6ee4cac3db32b0adfd","price":"0.26","side":"BUY","size":"66.59"},{"asset_id":"60386828328910021732068595344565885737045900010034836345809386672230885527307","best_ask":"0.7","best_bid":"0.69","hash":"36ffb1c7f74fa08122aff9ec31cbde578a14973c","price":"0.74","side":"SELL","size":"66.59"}],"timestamp":"1785126963344"},"payload_hash":"b62963b7722bc3aec7059d228a2b2271e5835a442da80adefa88e2155fc941c8","raw_frame":"{\"market\":\"0xeb66215f2e9faa6449e30a02bab5b8ed7b79a38bf961f6b24d0073c9c2419250\", \"price_changes\":[{\"asset_id\":\"69697746896130839564035629862476347944307040470122503199396727085502753297492\", \"price\":\"0.26\", \"size\":\"66.59\", \"side\":\"BUY\", \"hash\":\"91a29fe0a6aab702bc2d2e6ee4cac3db32b0adfd\", \"best_bid\":\"0.3\", \"best_ask\":\"0.31\"}, {\"asset_id\":\"60386828328910021732068595344565885737045900010034836345809386672230885527307\", \"price\":\"0.74\", \"size\":\"66.59\", \"side\":\"SELL\", \"hash\":\"36ffb1c7f74fa08122aff9ec31cbde578a14973c\", \"best_bid\":\"0.69\", \"best_ask\":\"0.7\"}], \"timestamp\":\"1785126963344\", \"event_type\":\"price_change\"}","received_at":"2026-07-27T04:36:03.972795Z","schema_version":"clob-market-ws.price_change.v1","sequence":null,"server_hash":null,"server_timestamp":"1785126963344","session_id":"e9443c7415a0419799bee9cfbb1a9e4d","source":"clob_market_ws"},"received_at":"2026-07-27T04:36:03.972795Z","record_id":"b7234870bd80c4e47ca50d0ca979fad5ff0dafcd5775b625be571866cedefdfa","schema_fingerprint":"4aa3821a28b0b7c2400bc59aba4bcc0a76e971dadd19610d3ad38c768e124dc7","schema_version":"edge-lab-recorder.raw.v1","sequence":null,"source":"clob_market_ws"}
{"event_at":"2026-07-27T04:36:03.367000Z","event_fingerprint":"78bffbf1d2e04ea8483efd00940a931e4ec626a4d53a394b50def4bc22687249","payload":{"connection_id":"0f4979d6978d463e9660b042fdcf555f","event_at":"2026-07-27T04:36:03.367000Z","event_type":"price_change","frame_hash":"a9aece98f89c8f66e96ed988eaf820a07f101aa7341f3bf404f2c99dc58ad041","frame_index":0,"kind":"data","monotonic_ns":228947244714875,"payload":{"event_type":"price_change","market":"0xeb66215f2e9faa6449e30a02bab5b8ed7b79a38bf961f6b24d0073c9c2419250","price_changes":[{"asset_id":"60386828328910021732068595344565885737045900010034836345809386672230885527307","best_ask":"0.7","best_bid":"0.69","hash":"4948337f117349baab2906b4f7fb522006445444","price":"0.04","side":"BUY","size":"583.09"},{"asset_id":"69697746896130839564035629862476347944307040470122503199396727085502753297492","best_ask":"0.31","best_bid":"0.3","hash":"6e25246a81bf9ed6f8bf27c1b0ee56865f3561eb","price":"0.96","side":"SELL","size":"583.09"}],"timestamp":"1785126963367"},"payload_hash":"bfc990426fcd6264b4fcffa7ccb6461862f891fb7199926b5ebecfed8e47ecda","raw_frame":"{\"market\":\"0xeb66215f2e9faa6449e30a02bab5b8ed7b79a38bf961f6b24d0073c9c2419250\", \"price_changes\":[{\"asset_id\":\"60386828328910021732068595344565885737045900010034836345809386672230885527307\", \"price\":\"0.04\", \"size\":\"583.09\", \"side\":\"BUY\", \"hash\":\"4948337f117349baab2906b4f7fb522006445444\", \"best_bid\":\"0.69\", \"best_ask\":\"0.7\"}, {\"asset_id\":\"69697746896130839564035629862476347944307040470122503199396727085502753297492\", \"price\":\"0.96\", \"size\":\"583.09\", \"side\":\"SELL\", \"hash\":\"6e25246a81bf9ed6f8bf27c1b0ee56865f3561eb\", \"best_bid\":\"0.3\", \"best_ask\":\"0.31\"}], \"timestamp\":\"1785126963367\", \"event_type\":\"price_change\"}","received_at":"2026-07-27T04:36:03.978035Z","schema_version":"clob-market-ws.price_change.v1","sequence":null,"server_hash":null,"server_timestamp":"1785126963367","session_id":"e9443c7415a0419799bee9cfbb1a9e4d","source":"clob_market_ws"},"received_at":"2026-07-27T04:36:03.978035Z","record_id":"0d5235808476b6810129481027348fb1ee24df26b5d6b4049253db3f0b700451","schema_fingerprint":"4aa3821a28b0b7c2400bc59aba4bcc0a76e971dadd19610d3ad38c768e124dc7","schema_version":"edge-lab-recorder.raw.v1","sequence":null,"source":"clob_market_ws"}
{"event_at":"2026-07-27T04:36:03.401000Z","event_fingerprint":"67ed31111c08c6be8b9ebb224b1db74373df94325ea78cbbc44e6596052b5731","payload":{"connection_id":"0f4979d6978d463e9660b042fdcf555f","event_at":"2026-07-27T04:36:03.401000Z","event_type":"price_change","frame_hash":"66d85c7b375bd90175a3a9ecc4a7c54fd57f1f7249b34689e854b150112dd31b","frame_index":0,"kind":"data","monotonic_ns":228947250754541,"payload":{"event_type":"price_change","market":"0xeb66215f2e9faa6449e30a02bab5b8ed7b79a38bf961f6b24d0073c9c2419250","price_changes":[{"asset_id":"69697746896130839564035629862476347944307040470122503199396727085502753297492","best_ask":"0.31","best_bid":"0.3","hash":"841076a8722432eda2c69dcc17f6477e5b00e006","price":"0.24","side":"BUY","size":"218.39"},{"asset_id":"60386828328910021732068595344565885737045900010034836345809386672230885527307","best_ask":"0.7","best_bid":"0.69","hash":"1f65ab8b0f214cf49bf164841d64095c1c6cb677","price":"0.76","side":"SELL","size":"218.39"}],"timestamp":"1785126963401"},"payload_hash":"387e35d73b545e5d037415a5390fd89dacc16cd095fce24e5e61f0456ce130ed","raw_frame":"{\"market\":\"0xeb66215f2e9faa6449e30a02bab5b8ed7b79a38bf961f6b24d0073c9c2419250\", \"price_changes\":[{\"asset_id\":\"69697746896130839564035629862476347944307040470122503199396727085502753297492\", \"price\":\"0.24\", \"size\":\"218.39\", \"side\":\"BUY\", \"hash\":\"841076a8722432eda2c69dcc17f6477e5b00e006\", \"best_bid\":\"0.3\", \"best_ask\":\"0.31\"}, {\"asset_id\":\"60386828328910021732068595344565885737045900010034836345809386672230885527307\", \"price\":\"0.76\", \"size\":\"218.39\", \"side\":\"SELL\", \"hash\":\"1f65ab8b0f214cf49bf164841d64095c1c6cb677\", \"best_bid\":\"0.69\", \"best_ask\":\"0.7\"}], \"timestamp\":\"1785126963401\", \"event_type\":\"price_change\"}","received_at":"2026-07-27T04:36:03.984073Z","schema_version":"clob-market-ws.price_change.v1","sequence":null,"server_hash":null,"server_timestamp":"1785126963401","session_id":"e9443c7415a0419799bee9cfbb1a9e4d","source":"clob_market_ws"},"received_at":"2026-07-27T04:36:03.984073Z","record_id":"c9e1ab5560fde60497d83f42fdf334853c265ce0da7e22c6bc6cfda7a6bb5b9f","schema_fingerprint":"4aa3821a28b0b7c2400bc59aba4bcc0a76e971dadd19610d3ad38c768e124dc7","schema_version":"edge-lab-recorder.raw.v1","sequence":null,"source":"clob_market_ws"}
{"event_at":"2026-07-27T04:36:03.401000Z","event_fingerprint":"d8d8f8fea1a45e333d52ac60d10af68cabc13186e39c4cc02ce692d24b748671","payload":{"connection_id":"0f4979d6978d463e9660b042fdcf555f","event_at":"2026-07-27T04:36:03.401000Z","event_type":"price_change","frame_hash":"624984118fce9ae2a1d53776a8ca3a037372d1b700f56510b4c2b258cd3189e6","frame_index":0,"kind":"data","monotonic_ns":228947256114000,"payload":{"event_type":"price_change","market":"0xeb66215f2e9faa6449e30a02bab5b8ed7b79a38bf961f6b24d0073c9c2419250","price_changes":[{"asset_id":"60386828328910021732068595344565885737045900010034836345809386672230885527307","best_ask":"0.7","best_bid":"0.69","hash":"1f65ab8b0f214cf49bf164841d64095c1c6cb677","price":"0.65","side":"BUY","size":"38.91"},{"asset_id":"69697746896130839564035629862476347944307040470122503199396727085502753297492","best_ask":"0.31","best_bid":"0.3","hash":"841076a8722432eda2c69dcc17f6477e5b00e006","price":"0.35","side":"SELL","size":"38.91"}],"timestamp":"1785126963401"},"payload_hash":"7a67c9eefd6315ab3c32523aec579a5942eaa9e7b2a197ec1def10942118a6c8","raw_frame":"{\"market\":\"0xeb66215f2e9faa6449e30a02bab5b8ed7b79a38bf961f6b24d0073c9c2419250\", \"price_changes\":[{\"asset_id\":\"60386828328910021732068595344565885737045900010034836345809386672230885527307\", \"price\":\"0.65\", \"size\":\"38.91\", \"side\":\"BUY\", \"hash\":\"1f65ab8b0f214cf49bf164841d64095c1c6cb677\", \"best_bid\":\"0.69\", \"best_ask\":\"0.7\"}, {\"asset_id\":\"69697746896130839564035629862476347944307040470122503199396727085502753297492\", \"price\":\"0.35\", \"size\":\"38.91\", \"side\":\"SELL\", \"hash\":\"841076a8722432eda2c69dcc17f6477e5b00e006\", \"best_bid\":\"0.3\", \"best_ask\":\"0.31\"}], \"timestamp\":\"1785126963401\", \"event_type\":\"price_change\"}","received_at":"2026-07-27T04:36:03.989433Z","schema_version":"clob-market-ws.price_change.v1","sequence":null,"server_hash":null,"server_timestamp":"1785126963401","session_id":"e9443c7415a0419799bee9cfbb1a9e4d","source":"clob_market_ws"},"received_at":"2026-07-27T04:36:03.989433Z","record_id":"895b14bea4f3bdb4d8ddd3c2646b81afedfb78ef532c791fdf16271070c13dbd","schema_fingerprint":"4aa3821a28b0b7c2400bc59aba4bcc0a76e971dadd19610d3ad38c768e124dc7","schema_version":"edge-lab-recorder.raw.v1","sequence":null,"source":"clob_market_ws"}
{"event_at":"2026-07-27T04:36:03.407000Z","event_fingerprint":"501fe60627a593b81c8ec1bfc7030f32a16c22ce2ff790fcca3092779ece92da","payload":{"connection_id":"0f4979d6978d463e9660b042fdcf555f","event_at":"2026-07-27T04:36:03.407000Z","event_type":"price_change","frame_hash":"018b351d3e392796c464c7cd581880c1b5ccf536b5482404d29f9c8c39191322","frame_index":0,"kind":"data","monotonic_ns":228947267017583,"payload":{"event_type":"price_change","market":"0xeb66215f2e9faa6449e30a02bab5b8ed7b79a38bf961f6b24d0073c9c2419250","price_changes":[{"asset_id":"69697746896130839564035629862476347944307040470122503199396727085502753297492","best_ask":"0.31","best_bid":"0.3","hash":"f44fbb69e8af27a6605958e170a23776fa98b3cb","price":"0.28","side":"BUY","size":"52.2"},{"asset_id":"60386828328910021732068595344565885737045900010034836345809386672230885527307","best_ask":"0.7","best_bid":"0.69","hash":"66612f02333f0d7d040ac3e349b247a471c1d768","price":"0.72","side":"SELL","size":"52.2"}],"timestamp":"1785126963407"},"payload_hash":"39651c9784df724b9d16903b1134b7d13dbe470d0ba0477015dbbb5888daf54b","raw_frame":"{\"market\":\"0xeb66215f2e9faa6449e30a02bab5b8ed7b79a38bf961f6b24d0073c9c2419250\", \"price_changes\":[{\"asset_id\":\"69697746896130839564035629862476347944307040470122503199396727085502753297492\", \"price\":\"0.28\", \"size\":\"52.2\", \"side\":\"BUY\", \"hash\":\"f44fbb69e8af27a6605958e170a23776fa98b3cb\", \"best_bid\":\"0.3\", \"best_ask\":\"0.31\"}, {\"asset_id\":\"60386828328910021732068595344565885737045900010034836345809386672230885527307\", \"price\":\"0.72\", \"size\":\"52.2\", \"side\":\"SELL\", \"hash\":\"66612f02333f0d7d040ac3e349b247a471c1d768\", \"best_bid\":\"0.69\", \"best_ask\":\"0.7\"}], \"timestamp\":\"1785126963407\", \"event_type\":\"price_change\"}","received_at":"2026-07-27T04:36:04.000338Z","schema_version":"clob-market-ws.price_change.v1","sequence":null,"server_hash":null,"server_timestamp":"1785126963407","session_id":"e9443c7415a0419799bee9cfbb1a9e4d","source":"clob_market_ws"},"received_at":"2026-07-27T04:36:04.000338Z","record_id":"df6294047bcb36c2f1b36343b63ccb0886492436578570fe25d693a9799514f9","schema_fingerprint":"4aa3821a28b0b7c2400bc59aba4bcc0a76e971dadd19610d3ad38c768e124dc7","schema_version":"edge-lab-recorder.raw.v1","sequence":null,"source":"clob_market_ws"}
{"event_at":"2026-07-27T04:36:03.408000Z","event_fingerprint":"4e42334558a2084ffb53548342d03fbf23aa7bd393fb150196d57881a62580c9","payload":{"connection_id":"0f4979d6978d463e9660b042fdcf555f","event_at":"2026-07-27T04:36:03.408000Z","event_type":"price_change","frame_hash":"1fe6e1572f319d7e7793c2438c5047e9a1cdbaa0ed8d4a4deb477ccc009e33bb","frame_index":0,"kind":"data","monotonic_ns":228947287177291,"payload":{"event_type":"price_change","market":"0xeb66215f2e9faa6449e30a02bab5b8ed7b79a38bf961f6b24d0073c9c2419250","price_changes":[{"asset_id":"60386828328910021732068595344565885737045900010034836345809386672230885527307","best_ask":"0.7","best_bid":"0.69","hash":"e01dd5211e511c1cad1ebf93538d998fc2a26a32","price":"0.61","side":"BUY","size":"125.5"},{"asset_id":"69697746896130839564035629862476347944307040470122503199396727085502753297492","best_ask":"0.31","best_bid":"0.3","hash":"c8ab2f3fa5ed4543a36082d417d541e91afa6356","price":"0.39","side":"SELL","size":"125.5"}],"timestamp":"1785126963408"},"payload_hash":"a85fdc92c595ea797d640fc09ce1f71d34e3950ba48c224e9bd429929f894bf8","raw_frame":"{\"market\":\"0xeb66215f2e9faa6449e30a02bab5b8ed7b79a38bf961f6b24d0073c9c2419250\", \"price_changes\":[{\"asset_id\":\"60386828328910021732068595344565885737045900010034836345809386672230885527307\", \"price\":\"0.61\", \"size\":\"125.5\", \"side\":\"BUY\", \"hash\":\"e01dd5211e511c1cad1ebf93538d998fc2a26a32\", \"best_bid\":\"0.69\", \"best_ask\":\"0.7\"}, {\"asset_id\":\"69697746896130839564035629862476347944307040470122503199396727085502753297492\", \"price\":\"0.39\", \"size\":\"125.5\", \"side\":\"SELL\", \"hash\":\"c8ab2f3fa5ed4543a36082d417d541e91afa6356\", \"best_bid\":\"0.3\", \"best_ask\":\"0.31\"}], \"timestamp\":\"1785126963408\", \"event_type\":\"price_change\"}","received_at":"2026-07-27T04:36:04.020494Z","schema_version":"clob-market-ws.price_change.v1","sequence":null,"server_hash":null,"server_timestamp":"1785126963408","session_id":"e9443c7415a0419799bee9cfbb1a9e4d","source":"clob_market_ws"},"received_at":"2026-07-27T04:36:04.020494Z","record_id":"ede7274cfc95ee9fcac94622dae23f34620479986a9be7d0e821e1bdcd86fe7b","schema_fingerprint":"4aa3821a28b0b7c2400bc59aba4bcc0a76e971dadd19610d3ad38c768e124dc7","schema_version":"edge-lab-recorder.raw.v1","sequence":null,"source":"clob_market_ws"}
{"event_at":"2026-07-27T04:36:03.433000Z","event_fingerprint":"b1b5c0321a987107f9464451fe45c3d133b47bfac47223c69d73fe82bbbc7711","payload":{"connection_id":"0f4979d6978d463e9660b042fdcf555f","event_at":"2026-07-27T04:36:03.433000Z","event_type":"price_change","frame_hash":"e69f9286c3b1439afb22905ebed701b80eca8aee6eabde338b2a468c084101bc","frame_index":0,"kind":"data","monotonic_ns":228947292097875,"payload":{"event_type":"price_change","market":"0xeb66215f2e9faa6449e30a02bab5b8ed7b79a38bf961f6b24d0073c9c2419250","price_changes":[{"asset_id":"60386828328910021732068595344565885737045900010034836345809386672230885527307","best_ask":"0.7","best_bid":"0.69","hash":"980de33e758536ecb1523a6469303da1289b16ec","price":"0.04","side":"BUY","size":"578.09"},{"asset_id":"69697746896130839564035629862476347944307040470122503199396727085502753297492","best_ask":"0.31","best_bid":"0.3","hash":"ac13e02ff71a5f719ee210f6ab743122356e1b57","price":"0.96","side":"SELL","size":"578.09"}],"timestamp":"1785126963433"},"payload_hash":"bdc1a0736245368e33a1f18bb0eca8195856844f64ed894ff021c7ac6b25f764","raw_frame":"{\"market\":\"0xeb66215f2e9faa6449e30a02bab5b8ed7b79a38bf961f6b24d0073c9c2419250\", \"price_changes\":[{\"asset_id\":\"60386828328910021732068595344565885737045900010034836345809386672230885527307\", \"price\":\"0.04\", \"size\":\"578.09\", \"side\":\"BUY\", \"hash\":\"980de33e758536ecb1523a6469303da1289b16ec\", \"best_bid\":\"0.69\", \"best_ask\":\"0.7\"}, {\"asset_id\":\"69697746896130839564035629862476347944307040470122503199396727085502753297492\", \"price\":\"0.96\", \"size\":\"578.09\", \"side\":\"SELL\", \"hash\":\"ac13e02ff71a5f719ee210f6ab743122356e1b57\", \"best_bid\":\"0.3\", \"best_ask\":\"0.31\"}], \"timestamp\":\"1785126963433\", \"event_type\":\"price_change\"}","received_at":"2026-07-27T04:36:04.025419Z","schema_version":"clob-market-ws.price_change.v1","sequence":null,"server_hash":null,"server_timestamp":"1785126963433","session_id":"e9443c7415a0419799bee9cfbb1a9e4d","source":"clob_market_ws"},"received_at":"2026-07-27T04:36:04.025419Z","record_id":"5be6492d9a970c7dcb587b4d2eefbbb8e1981e9368b07621be977d5c20b50533","schema_fingerprint":"4aa3821a28b0b7c2400bc59aba4bcc0a76e971dadd19610d3ad38c768e124dc7","schema_version":"edge-lab-recorder.raw.v1","sequence":null,"source":"clob_market_ws"}
{"event_at":"2026-07-27T04:36:03.456000Z","event_fingerprint":"08a59b15b620741758baaf328e66f90ebc5b3e9fd19bc6bc061b0934003a76a5","payload":{"connection_id":"0f4979d6978d463e9660b042fdcf555f","event_at":"2026-07-27T04:36:03.456000Z","event_type":"price_change","frame_hash":"13fd60266bed255e1cc72fde82df16e53c732ae47a859018f00323cea0fdc4dd","frame_index":0,"kind":"data","monotonic_ns":228947298102125,"payload":{"event_type":"price_change","market":"0xeb66215f2e9faa6449e30a02bab5b8ed7b79a38bf961f6b24d0073c9c2419250","price_changes":[{"asset_id":"69697746896130839564035629862476347944307040470122503199396727085502753297492","best_ask":"0.31","best_bid":"0.3","hash":"7672389cc53d79d08febbfb5d5cb624e5d753027","price":"0.33","side":"SELL","size":"414.56"},{"asset_id":"60386828328910021732068595344565885737045900010034836345809386672230885527307","best_ask":"0.7","best_bid":"0.69","hash":"a6bfb07f10a431de69adf3903d263f305cba7dd8","price":"0.67","side":"BUY","size":"414.56"}],"timestamp":"1785126963456"},"payload_hash":"8aa10191095999eb05c7dcc69d7e88bc5909705460fc80196d06b088d7d14b29","raw_frame":"{\"market\":\"0xeb66215f2e9faa6449e30a02bab5b8ed7b79a38bf961f6b24d0073c9c2419250\", \"price_changes\":[{\"asset_id\":\"69697746896130839564035629862476347944307040470122503199396727085502753297492\", \"price\":\"0.33\", \"size\":\"414.56\", \"side\":\"SELL\", \"hash\":\"7672389cc53d79d08febbfb5d5cb624e5d753027\", \"best_bid\":\"0.3\", \"best_ask\":\"0.31\"}, {\"asset_id\":\"60386828328910021732068595344565885737045900010034836345809386672230885527307\", \"price\":\"0.67\", \"size\":\"414.56\", \"side\":\"BUY\", \"hash\":\"a6bfb07f10a431de69adf3903d263f305cba7dd8\", \"best_bid\":\"0.69\", \"best_ask\":\"0.7\"}], \"timestamp\":\"1785126963456\", \"event_type\":\"price_change\"}","received_at":"2026-07-27T04:36:04.031423Z","schema_version":"clob-market-ws.price_change.v1","sequence":null,"server_hash":null,"server_timestamp":"1785126963456","session_id":"e9443c7415a0419799bee9cfbb1a9e4d","source":"clob_market_ws"},"received_at":"2026-07-27T04:36:04.031423Z","record_id":"5d0b6a38d0a59c0c8876651c80941bc5656e51a71c954c6526737126e4f738fc","schema_fingerprint":"4aa3821a28b0b7c2400bc59aba4bcc0a76e971dadd19610d3ad38c768e124dc7","schema_version":"edge-lab-recorder.raw.v1","sequence":null,"source":"clob_market_ws"}
{"event_at":"2026-07-27T04:36:03.461000Z","event_fingerprint":"5255ae10ae7966933635faa79bdd6bad5a5fc25dbd58a61d2e6e6a6bad4e9855","payload":{"connection_id":"0f4979d6978d463e9660b042fdcf555f","event_at":"2026-07-27T04:36:03.461000Z","event_type":"price_change","frame_hash":"977dc640a84312a76a3c56318ce1bb6d8c8510c0ccc6cfec911334dcee9499cf","frame_index":0,"kind":"data","monotonic_ns":228947302515166,"payload":{"event_type":"price_change","market":"0xeb66215f2e9faa6449e30a02bab5b8ed7b79a38bf961f6b24d0073c9c2419250","price_changes":[{"asset_id":"60386828328910021732068595344565885737045900010034836345809386672230885527307","best_ask":"0.7","best_bid":"0.69","hash":"5396e311cc33986eab38ec6a5bb5b6ca94d9d637","price":"0.67","side":"BUY","size":"444.6"},{"asset_id":"69697746896130839564035629862476347944307040470122503199396727085502753297492","best_ask":"0.31","best_bid":"0.3","hash":"193258062f00bee4de506ed503862d195be49e62","price":"0.33","side":"SELL","size":"444.6"}],"timestamp":"1785126963461"},"payload_hash":"73fab993a516038ac1fb858f896b3337b36ec22e1951a1bacb2aa317ae7dcdc1","raw_frame":"{\"market\":\"0xeb66215f2e9faa6449e30a02bab5b8ed7b79a38bf961f6b24d0073c9c2419250\", \"price_changes\":[{\"asset_id\":\"60386828328910021732068595344565885737045900010034836345809386672230885527307\", \"price\":\"0.67\", \"size\":\"444.6\", \"side\":\"BUY\", \"hash\":\"5396e311cc33986eab38ec6a5bb5b6ca94d9d637\", \"best_bid\":\"0.69\", \"best_ask\":\"0.7\"}, {\"asset_id\":\"69697746896130839564035629862476347944307040470122503199396727085502753297492\", \"price\":\"0.33\", \"size\":\"444.6\", \"side\":\"SELL\", \"hash\":\"193258062f00bee4de506ed503862d195be49e62\", \"best_bid\":\"0.3\", \"best_ask\":\"0.31\"}], \"timestamp\":\"1785126963461\", \"event_type\":\"price_change\"}","received_at":"2026-07-27T04:36:04.035838Z","schema_version":"clob-market-ws.price_change.v1","sequence":null,"server_hash":null,"server_timestamp":"1785126963461","session_id":"e9443c7415a0419799bee9cfbb1a9e4d","source":"clob_market_ws"},"received_at":"2026-07-27T04:36:04.035838Z","record_id":"06064d6a109d822fd7e7f15ceb2ca469f0659aec0f539249f8490472e29af567","schema_fingerprint":"4aa3821a28b0b7c2400bc59aba4bcc0a76e971dadd19610d3ad38c768e124dc7","schema_version":"edge-lab-recorder.raw.v1","sequence":null,"source":"clob_market_ws"}
{"event_at":"2026-07-27T04:36:03.461000Z","event_fingerprint":"b22cb83df855afd64f11da01a260fc9de19220b6619d837f4763164af5510e9a","payload":{"connection_id":"0f4979d6978d463e9660b042fdcf555f","event_at":"2026-07-27T04:36:03.461000Z","event_type":"price_change","frame_hash":"bd99ca5b59247f088b7f08aa7fd56208bc6d610c48beb4677899597dffdf5a5e","frame_index":0,"kind":"data","monotonic_ns":228947309904083,"payload":{"event_type":"price_change","market":"0xeb66215f2e9faa6449e30a02bab5b8ed7b79a38bf961f6b24d0073c9c2419250","price_changes":[{"asset_id":"60386828328910021732068595344565885737045900010034836345809386672230885527307","best_ask":"0.7","best_bid":"0.69","hash":"6c6c2ea7c5221d05ab85820a9ec96e89958793b8","price":"0.01","side":"BUY","size":"5458.02"},{"asset_id":"69697746896130839564035629862476347944307040470122503199396727085502753297492","best_ask":"0.31","best_bid":"0.3","hash":"4911325059dd74834b3525667ee9089d5e840f81","price":"0.99","side":"SELL","size":"5458.02"}],"timestamp":"1785126963461"},"payload_hash":"6ab8300d45e8c983da29e37fe96debda96b6d7bc064ec74a0c21d0360a0b5e78","raw_frame":"{\"market\":\"0xeb66215f2e9faa6449e30a02bab5b8ed7b79a38bf961f6b24d0073c9c2419250\", \"price_changes\":[{\"asset_id\":\"60386828328910021732068595344565885737045900010034836345809386672230885527307\", \"price\":\"0.01\", \"size\":\"5458.02\", \"side\":\"BUY\", \"hash\":\"6c6c2ea7c5221d05ab85820a9ec96e89958793b8\", \"best_bid\":\"0.69\", \"best_ask\":\"0.7\"}, {\"asset_id\":\"69697746896130839564035629862476347944307040470122503199396727085502753297492\", \"price\":\"0.99\", \"size\":\"5458.02\", \"side\":\"SELL\", \"hash\":\"4911325059dd74834b3525667ee9089d5e840f81\", \"best_bid\":\"0.3\", \"best_ask\":\"0.31\"}], \"timestamp\":\"1785126963461\", \"event_type\":\"price_change\"}","received_at":"2026-07-27T04:36:04.043224Z","schema_version":"clob-market-ws.price_change.v1","sequence":null,"server_hash":null,"server_timestamp":"1785126963461","session_id":"e9443c7415a0419799bee9cfbb1a9e4d","source":"clob_market_ws"},"received_at":"2026-07-27T04:36:04.043224Z","record_id":"6451723f623e6a530f562b4923f8d7489827adf68592f4f7900bf31f022d8c7d","schema_fingerprint":"4aa3821a28b0b7c2400bc59aba4bcc0a76e971dadd19610d3ad38c768e124dc7","schema_version":"edge-lab-recorder.raw.v1","sequence":null,"source":"clob_market_ws"}
{"event_at":"2026-07-27T04:36:03.478000Z","event_fingerprint":"38ecdc4c0b3d16697f3cce685c8eb85fd6711c53273fcf1bbb97bec6e8d0e755","payload":{"connection_id":"0f4979d6978d463e9660b042fdcf555f","event_at":"2026-07-27T04:36:03.478000Z","event_type":"price_change","frame_hash":"58a913d0abcf60736512da596de61013259e2addf9b38c9f68121907b839b2ab","frame_index":0,"kind":"data","monotonic_ns":228947313625625,"payload":{"event_type":"price_change","market":"0xeb66215f2e9faa6449e30a02bab5b8ed7b79a38bf961f6b24d0073c9c2419250","price_changes":[{"asset_id":"60386828328910021732068595344565885737045900010034836345809386672230885527307","best_ask":"0.7","best_bid":"0.69","hash":"af309e394ecc39786749c071af36d64c5a6fa44c","price":"0.52","side":"BUY","size":"17"},{"asset_id":"69697746896130839564035629862476347944307040470122503199396727085502753297492","best_ask":"0.31","best_bid":"0.3","hash":"a5625031f530ab5fba360ef913b293291fbea8d4","price":"0.48","side":"SELL","size":"17"}],"timestamp":"1785126963478"},"payload_hash":"5689a7af817071e2f2f596d505b8423aafff69e0e3f47f4ddf6e47fe20076c9d","raw_frame":"{\"market\":\"0xeb66215f2e9faa6449e30a02bab5b8ed7b79a38bf961f6b24d0073c9c2419250\", \"price_changes\":[{\"asset_id\":\"60386828328910021732068595344565885737045900010034836345809386672230885527307\", \"price\":\"0.52\", \"size\":\"17\", \"side\":\"BUY\", \"hash\":\"af309e394ecc39786749c071af36d64c5a6fa44c\", \"best_bid\":\"0.69\", \"best_ask\":\"0.7\"}, {\"asset_id\":\"69697746896130839564035629862476347944307040470122503199396727085502753297492\", \"price\":\"0.48\", \"size\":\"17\", \"side\":\"SELL\", \"hash\":\"a5625031f530ab5fba360ef913b293291fbea8d4\", \"best_bid\":\"0.3\", \"best_ask\":\"0.31\"}], \"timestamp\":\"1785126963478\", \"event_type\":\"price_change\"}","received_at":"2026-07-27T04:36:04.046946Z","schema_version":"clob-market-ws.price_change.v1","sequence":null,"server_hash":null,"server_timestamp":"1785126963478","session_id":"e9443c7415a0419799bee9cfbb1a9e4d","source":"clob_market_ws"},"received_at":"2026-07-27T04:36:04.046946Z","record_id":"3b2bcf3c5a68a94ba99fd851026d26fb13600e8fcaeec9fa054491f4dc29b544","schema_fingerprint":"4aa3821a28b0b7c2400bc59aba4bcc0a76e971dadd19610d3ad38c768e124dc7","schema_version":"edge-lab-recorder.raw.v1","sequence":null,"source":"clob_market_ws"}
{"event_at":"2026-07-27T04:36:03.491000Z","event_fingerprint":"dde219417aca7d8a3d6948f884bfca3415a8e83a95e8fd617cb9f1bc8a301ab4","payload":{"connection_id":"0f4979d6978d463e9660b042fdcf555f","event_at":"2026-07-27T04:36:03.491000Z","event_type":"price_change","frame_hash":"17cf1e85c836fd74bf8a49a3d7002544cd65ade6e41bdeb74d53f506a9cac34d","frame_index":0,"kind":"data","monotonic_ns":228947318912458,"payload":{"event_type":"price_change","market":"0xeb66215f2e9faa6449e30a02bab5b8ed7b79a38bf961f6b24d0073c9c2419250","price_changes":[{"asset_id":"60386828328910021732068595344565885737045900010034836345809386672230885527307","best_ask":"0.7","best_bid":"0.69","hash":"ff71738829cd8e2d05a6613e83c8768495a767f3","price":"0.01","side":"BUY","size":"5453.02"},{"asset_id":"69697746896130839564035629862476347944307040470122503199396727085502753297492","best_ask":"0.31","best_bid":"0.3","hash":"5c7c4c33540c7a18069d8943baa0aa3c402cdc6f","price":"0.99","side":"SELL","size":"5453.02"}],"timestamp":"1785126963491"},"payload_hash":"a7107580745e50122ca82d140b8472058171965298779f4931fef27d6ab19bea","raw_frame":"{\"market\":\"0xeb66215f2e9faa6449e30a02bab5b8ed7b79a38bf961f6b24d0073c9c2419250\", \"price_changes\":[{\"asset_id\":\"60386828328910021732068595344565885737045900010034836345809386672230885527307\", \"price\":\"0.01\", \"size\":\"5453.02\", \"side\":\"BUY\", \"hash\":\"ff71738829cd8e2d05a6613e83c8768495a767f3\", \"best_bid\":\"0.69\", \"best_ask\":\"0.7\"}, {\"asset_id\":\"69697746896130839564035629862476347944307040470122503199396727085502753297492\", \"price\":\"0.99\", \"size\":\"5453.02\", \"side\":\"SELL\", \"hash\":\"5c7c4c33540c7a18069d8943baa0aa3c402cdc6f\", \"best_bid\":\"0.3\", \"best_ask\":\"0.31\"}], \"timestamp\":\"1785126963491\", \"event_type\":\"price_change\"}","received_at":"2026-07-27T04:36:04.052234Z","schema_version":"clob-market-ws.price_change.v1","sequence":null,"server_hash":null,"server_timestamp":"1785126963491","session_id":"e9443c7415a0419799bee9cfbb1a9e4d","source":"clob_market_ws"},"received_at":"2026-07-27T04:36:04.052234Z","record_id":"8c531d4c0cc1e602c94d37e2780a2359d4542c3488c562f79d6a909d25b97c23","schema_fingerprint":"4aa3821a28b0b7c2400bc59aba4bcc0a76e971dadd19610d3ad38c768e124dc7","schema_version":"edge-lab-recorder.raw.v1","sequence":null,"source":"clob_market_ws"}
{"event_at":"2026-07-27T04:36:03.492000Z","event_fingerprint":"67ab95a386c4a6a3c55cd713894a4e87067f5e6f1c89eaf6781b99a99fc3c68d","payload":{"connection_id":"0f4979d6978d463e9660b042fdcf555f","event_at":"2026-07-27T04:36:03.492000Z","event_type":"price_change","frame_hash":"8456588403666e82066cac21fa913f4f2e20ac5ba3c722037bdf98114c26f429","frame_index":0,"kind":"data","monotonic_ns":228947324722041,"payload":{"event_type":"price_change","market":"0xeb66215f2e9faa6449e30a02bab5b8ed7b79a38bf961f6b24d0073c9c2419250","price_changes":[{"asset_id":"60386828328910021732068595344565885737045900010034836345809386672230885527307","best_ask":"0.7","best_bid":"0.69","hash":"109cd7f4334c1ad14fd876c0462350030f066ca2","price":"0.43","side":"BUY","size":"17.2"},{"asset_id":"69697746896130839564035629862476347944307040470122503199396727085502753297492","best_ask":"0.31","best_bid":"0.3","hash":"3a03b3232fa2e7de344cb282c9c50f96b04053ae","price":"0.57","side":"SELL","size":"17.2"}],"timestamp":"1785126963492"},"payload_hash":"29fb8b1eeb0c7dfd9617501507e009eba37d11222117e24a39fde507c83ae2cb","raw_frame":"{\"market\":\"0xeb66215f2e9faa6449e30a02bab5b8ed7b79a38bf961f6b24d0073c9c2419250\", \"price_changes\":[{\"asset_id\":\"60386828328910021732068595344565885737045900010034836345809386672230885527307\", \"price\":\"0.43\", \"size\":\"17.2\", \"side\":\"BUY\", \"hash\":\"109cd7f4334c1ad14fd876c0462350030f066ca2\", \"best_bid\":\"0.69\", \"best_ask\":\"0.7\"}, {\"asset_id\":\"69697746896130839564035629862476347944307040470122503199396727085502753297492\", \"price\":\"0.57\", \"size\":\"17.2\", \"side\":\"SELL\", \"hash\":\"3a03b3232fa2e7de344cb282c9c50f96b04053ae\", \"best_bid\":\"0.3\", \"best_ask\":\"0.31\"}], \"timestamp\":\"1785126963492\", \"event_type\":\"price_change\"}","received_at":"2026-07-27T04:36:04.058041Z","schema_version":"clob-market-ws.price_change.v1","sequence":null,"server_hash":null,"server_timestamp":"1785126963492","session_id":"e9443c7415a0419799bee9cfbb1a9e4d","source":"clob_market_ws"},"received_at":"2026-07-27T04:36:04.058041Z","record_id":"e5b7548192b3e8f2b242682c2f8fb86a3c3f8c610a03929bee18286d991de36b","schema_fingerprint":"4aa3821a28b0b7c2400bc59aba4bcc0a76e971dadd19610d3ad38c768e124dc7","schema_version":"edge-lab-recorder.raw.v1","sequence":null,"source":"clob_market_ws"}
{"event_at":"2026-07-27T04:36:03.519000Z","event_fingerprint":"bc303c3767da9a47849413aada07b2084f9c1376a39afd0b89127540fcd4204f","payload":{"connection_id":"0f4979d6978d463e9660b042fdcf555f","event_at":"2026-07-27T04:36:03.519000Z","event_type":"price_change","frame_hash":"ef9bfa14515a997273fbcb2a7322f3d957242e382f5217736049410479c01cf4","frame_index":0,"kind":"data","monotonic_ns":228947332762166,"payload":{"event_type":"price_change","market":"0xeb66215f2e9faa6449e30a02bab5b8ed7b79a38bf961f6b24d0073c9c2419250","price_changes":[{"asset_id":"60386828328910021732068595344565885737045900010034836345809386672230885527307","best_ask":"0.7","best_bid":"0.69","hash":"c0cb5c980b38c93c8db36914c49fc47fd7c18552","price":"0.52","side":"BUY","size":"22"},{"asset_id":"69697746896130839564035629862476347944307040470122503199396727085502753297492","best_ask":"0.31","best_bid":"0.3","hash":"b48ba1955144a04f1c7fe2493017f51354edfe15","price":"0.48","side":"SELL","size":"22"}],"timestamp":"1785126963519"},"payload_hash":"f84ffb91fceef8c65876de0a4da01167b9c85376f44058c6fed667ffac2d7669","raw_frame":"{\"market\":\"0xeb66215f2e9faa6449e30a02bab5b8ed7b79a38bf961f6b24d0073c9c2419250\", \"price_changes\":[{\"asset_id\":\"60386828328910021732068595344565885737045900010034836345809386672230885527307\", \"price\":\"0.52\", \"size\":\"22\", \"side\":\"BUY\", \"hash\":\"c0cb5c980b38c93c8db36914c49fc47fd7c18552\", \"best_bid\":\"0.69\", \"best_ask\":\"0.7\"}, {\"asset_id\":\"69697746896130839564035629862476347944307040470122503199396727085502753297492\", \"price\":\"0.48\", \"size\":\"22\", \"side\":\"SELL\", \"hash\":\"b48ba1955144a04f1c7fe2493017f51354edfe15\", \"best_bid\":\"0.3\", \"best_ask\":\"0.31\"}], \"timestamp\":\"1785126963519\", \"event_type\":\"price_change\"}","received_at":"2026-07-27T04:36:04.066082Z","schema_version":"clob-market-ws.price_change.v1","sequence":null,"server_hash":null,"server_timestamp":"1785126963519","session_id":"e9443c7415a0419799bee9cfbb1a9e4d","source":"clob_market_ws"},"received_at":"2026-07-27T04:36:04.066082Z","record_id":"41fdebedeaf43e381fdef66e1b6d5ddba0fa69578e9b48136fefe4f8c5ecff84","schema_fingerprint":"4aa3821a28b0b7c2400bc59aba4bcc0a76e971dadd19610d3ad38c768e124dc7","schema_version":"edge-lab-recorder.raw.v1","sequence":null,"source":"clob_market_ws"}
{"event_at":"2026-07-27T04:36:03.527000Z","event_fingerprint":"1373d9ba60dfc005e0a51d122706f323d5135454f984454cd74f9ca8f2647f4e","payload":{"connection_id":"0f4979d6978d463e9660b042fdcf555f","event_at":"2026-07-27T04:36:03.527000Z","event_type":"price_change","frame_hash":"ffc1217bbdc055bdb662071bd80881637c1b353cb6c1d0ecfe6c6e214b1eca1f","frame_index":0,"kind":"data","monotonic_ns":228947338746916,"payload":{"event_type":"price_change","market":"0xeb66215f2e9faa6449e30a02bab5b8ed7b79a38bf961f6b24d0073c9c2419250","price_changes":[{"asset_id":"60386828328910021732068595344565885737045900010034836345809386672230885527307","best_ask":"0.7","best_bid":"0.69","hash":"b3c4f2ac4166c48def3f13b0341a6b1f1e27a5b7","price":"0.03","side":"BUY","size":"648.1"},{"asset_id":"69697746896130839564035629862476347944307040470122503199396727085502753297492","best_ask":"0.31","best_bid":"0.3","hash":"2f317fd7f97a5b8d6b85a1cec5cd3365ab0a8aaa","price":"0.97","side":"SELL","size":"648.1"}],"timestamp":"1785126963527"},"payload_hash":"469afe19fb70a76a49ffbb7c28ca6a44b7ae2d73bca922b3c25a328abf325df0","raw_frame":"{\"market\":\"0xeb66215f2e9faa6449e30a02bab5b8ed7b79a38bf961f6b24d0073c9c2419250\", \"price_changes\":[{\"asset_id\":\"60386828328910021732068595344565885737045900010034836345809386672230885527307\", \"price\":\"0.03\", \"size\":\"648.1\", \"side\":\"BUY\", \"hash\":\"b3c4f2ac4166c48def3f13b0341a6b1f1e27a5b7\", \"best_bid\":\"0.69\", \"best_ask\":\"0.7\"}, {\"asset_id\":\"69697746896130839564035629862476347944307040470122503199396727085502753297492\", \"price\":\"0.97\", \"size\":\"648.1\", \"side\":\"SELL\", \"hash\":\"2f317fd7f97a5b8d6b85a1cec5cd3365ab0a8aaa\", \"best_bid\":\"0.3\", \"best_ask\":\"0.31\"}], \"timestamp\":\"1785126963527\", \"event_type\":\"price_change\"}","received_at":"2026-07-27T04:36:04.072068Z","schema_version":"clob-market-ws.price_change.v1","sequence":null,"server_hash":null,"server_timestamp":"1785126963527","session_id":"e9443c7415a0419799bee9cfbb1a9e4d","source":"clob_market_ws"},"received_at":"2026-07-27T04:36:04.072068Z","record_id":"0f90c811aa2fda8517149392d21655bfe4849420b330536f21da71693be7a3af","schema_fingerprint":"4aa3821a28b0b7c2400bc59aba4bcc0a76e971dadd19610d3ad38c768e124dc7","schema_version":"edge-lab-recorder.raw.v1","sequence":null,"source":"clob_market_ws"}
{"event_at":"2026-07-27T04:36:03.563000Z","event_fingerprint":"59e7beee2f4b021dba1c48001ca96fd6cc641bb17fa90b893c1584a43e19a11a","payload":{"connection_id":"0f4979d6978d463e9660b042fdcf555f","event_at":"2026-07-27T04:36:03.563000Z","event_type":"price_change","frame_hash":"d9486f0371c001bb7137bc890a9c8900711498b3e9f14fdf253220f1673f6790","frame_index":0,"kind":"data","monotonic_ns":228947344369791,"payload":{"event_type":"price_change","market":"0xeb66215f2e9faa6449e30a02bab5b8ed7b79a38bf961f6b24d0073c9c2419250","price_changes":[{"asset_id":"60386828328910021732068595344565885737045900010034836345809386672230885527307","best_ask":"0.7","best_bid":"0.69","hash":"a95c14d3f0b8573015adf8c9e73bc3341c18268d","price":"0.67","side":"BUY","size":"414.56"},{"asset_id":"69697746896130839564035629862476347944307040470122503199396727085502753297492","best_ask":"0.31","best_bid":"0.3","hash":"7c44501ef6ab24698d7f5507c006da79e3b1b1b1","price":"0.33","side":"SELL","size":"414.56"}],"timestamp":"1785126963563"},"payload_hash":"2e1564f2cc644002be296a8b8b5e3e02e27656c5e8430076940aab3d459db3fb","raw_frame":"{\"market\":\"0xeb66215f2e9faa6449e30a02bab5b8ed7b79a38bf961f6b24d0073c9c2419250\", \"price_changes\":[{\"asset_id\":\"60386828328910021732068595344565885737045900010034836345809386672230885527307\", \"price\":\"0.67\", \"size\":\"414.56\", \"side\":\"BUY\", \"hash\":\"a95c14d3f0b8573015adf8c9e73bc3341c18268d\", \"best_bid\":\"0.69\", \"best_ask\":\"0.7\"}, {\"asset_id\":\"69697746896130839564035629862476347944307040470122503199396727085502753297492\", \"price\":\"0.33\", \"size\":\"414.56\", \"side\":\"SELL\", \"hash\":\"7c44501ef6ab24698d7f5507c006da79e3b1b1b1\", \"best_bid\":\"0.3\", \"best_ask\":\"0.31\"}], \"timestamp\":\"1785126963563\", \"event_type\":\"price_change\"}","received_at":"2026-07-27T04:36:04.077692Z","schema_version":"clob-market-ws.price_change.v1","sequence":null,"server_hash":null,"server_timestamp":"1785126963563","session_id":"e9443c7415a0419799bee9cfbb1a9e4d","source":"clob_market_ws"},"received_at":"2026-07-27T04:36:04.077692Z","record_id":"c1be03306be950d0c3e62acc63a5704226a2d8a3c8833538696f6c62e498e0e2","schema_fingerprint":"4aa3821a28b0b7c2400bc59aba4bcc0a76e971dadd19610d3ad38c768e124dc7","schema_version":"edge-lab-recorder.raw.v1","sequence":null,"source":"clob_market_ws"}
{"event_at":"2026-07-27T04:36:03.570000Z","event_fingerprint":"e25776bb3ea0a45877fa874a01f3d43d2d5c0b49eeef01b0202ff72a07672260","payload":{"connection_id":"0f4979d6978d463e9660b042fdcf555f","event_at":"2026-07-27T04:36:03.570000Z","event_type":"price_change","frame_hash":"5dba8335cd53e6dc274c4bd0ca5b440ce9bc040bd0f0bd5a0c1acc012ffc632b","frame_index":0,"kind":"data","monotonic_ns":228947348710125,"payload":{"event_type":"price_change","market":"0xeb66215f2e9faa6449e30a02bab5b8ed7b79a38bf961f6b24d0073c9c2419250","price_changes":[{"asset_id":"69697746896130839564035629862476347944307040470122503199396727085502753297492","best_ask":"0.31","best_bid":"0.3","hash":"4097198fc40a01d4f9d680aea12fdfbc5c04581d","price":"0.33","side":"SELL","size":"444.6"},{"asset_id":"60386828328910021732068595344565885737045900010034836345809386672230885527307","best_ask":"0.7","best_bid":"0.69","hash":"88ef6eae5016e67e2ac44d73ff5cb47c8a11dc55","price":"0.67","side":"BUY","size":"444.6"}],"timestamp":"1785126963570"},"payload_hash":"1d8e69e2ad6064f5295018fb5099dd52e20db9149d61b9ceeb4e857bfe21da43","raw_frame":"{\"market\":\"0xeb66215f2e9faa6449e30a02bab5b8ed7b79a38bf961f6b24d0073c9c2419250\", \"price_changes\":[{\"asset_id\":\"69697746896130839564035629862476347944307040470122503199396727085502753297492\", \"price\":\"0.33\", \"size\":\"444.6\", \"side\":\"SELL\", \"hash\":\"4097198fc40a01d4f9d680aea12fdfbc5c04581d\", \"best_bid\":\"0.3\", \"best_ask\":\"0.31\"}, {\"asset_id\":\"60386828328910021732068595344565885737045900010034836345809386672230885527307\", \"price\":\"0.67\", \"size\":\"444.6\", \"side\":\"BUY\", \"hash\":\"88ef6eae5016e67e2ac44d73ff5cb47c8a11dc55\", \"best_bid\":\"0.69\", \"best_ask\":\"0.7\"}], \"timestamp\":\"1785126963570\", \"event_type\":\"price_change\"}","received_at":"2026-07-27T04:36:04.082032Z","schema_version":"clob-market-ws.price_change.v1","sequence":null,"server_hash":null,"server_timestamp":"1785126963570","session_id":"e9443c7415a0419799bee9cfbb1a9e4d","source":"clob_market_ws"},"received_at":"2026-07-27T04:36:04.082032Z","record_id":"7f4080c9f9a90b8717be64bbff0ff9f842d2e3873a3cb1e71c7c13185e0250c5","schema_fingerprint":"4aa3821a28b0b7c2400bc59aba4bcc0a76e971dadd19610d3ad38c768e124dc7","schema_version":"edge-lab-recorder.raw.v1","sequence":null,"source":"clob_market_ws"}
{"event_at":"2026-07-27T04:36:03.588000Z","event_fingerprint":"ca0266fa1aae064b2d6bc09377bcc13c1abad0e43b5860c3e1be06e992ec2cb1","payload":{"connection_id":"0f4979d6978d463e9660b042fdcf555f","event_at":"2026-07-27T04:36:03.588000Z","event_type":"price_change","frame_hash":"6b401a1ef2e874596cbca2cccfdb8b2adf492146e5e17c1915724d117260489c","frame_index":0,"kind":"data","monotonic_ns":228947353186375,"payload":{"event_type":"price_change","market":"0xeb66215f2e9faa6449e30a02bab5b8ed7b79a38bf961f6b24d0073c9c2419250","price_changes":[{"asset_id":"60386828328910021732068595344565885737045900010034836345809386672230885527307","best_ask":"0.7","best_bid":"0.69","hash":"190aeed6d90be48bd376b98131b9726be69193d1","price":"0.03","side":"BUY","size":"643.1"},{"asset_id":"69697746896130839564035629862476347944307040470122503199396727085502753297492","best_ask":"0.31","best_bid":"0.3","hash":"22412a18681a5a766b21fa4754a64453fa085733","price":"0.97","side":"SELL","size":"643.1"}],"timestamp":"1785126963588"},"payload_hash":"9680b6b58b098e090bb62e14a82931f826c96ed986cc3a4d1a34e950dcee525e","raw_frame":"{\"market\":\"0xeb66215f2e9faa6449e30a02bab5b8ed7b79a38bf961f6b24d0073c9c2419250\", \"price_changes\":[{\"asset_id\":\"60386828328910021732068595344565885737045900010034836345809386672230885527307\", \"price\":\"0.03\", \"size\":\"643.1\", \"side\":\"BUY\", \"hash\":\"190aeed6d90be48bd376b98131b9726be69193d1\", \"best_bid\":\"0.69\", \"best_ask\":\"0.7\"}, {\"asset_id\":\"69697746896130839564035629862476347944307040470122503199396727085502753297492\", \"price\":\"0.97\", \"size\":\"643.1\", \"side\":\"SELL\", \"hash\":\"22412a18681a5a766b21fa4754a64453fa085733\", \"best_bid\":\"0.3\", \"best_ask\":\"0.31\"}], \"timestamp\":\"1785126963588\", \"event_type\":\"price_change\"}","received_at":"2026-07-27T04:36:04.086507Z","schema_version":"clob-market-ws.price_change.v1","sequence":null,"server_hash":null,"server_timestamp":"1785126963588","session_id":"e9443c7415a0419799bee9cfbb1a9e4d","source":"clob_market_ws"},"received_at":"2026-07-27T04:36:04.086507Z","record_id":"4f40a6dc509a329a4de433781db4571e94ea78ff3ad72280ead3ca32b25e0eb0","schema_fingerprint":"4aa3821a28b0b7c2400bc59aba4bcc0a76e971dadd19610d3ad38c768e124dc7","schema_version":"edge-lab-recorder.raw.v1","sequence":null,"source":"clob_market_ws"}
{"event_at":"2026-07-27T04:36:03.649000Z","event_fingerprint":"e999c29426b48ec921a03c28d85e85b71aa844ee4c1d2c5ee9c95125987f6f16","payload":{"connection_id":"0f4979d6978d463e9660b042fdcf555f","event_at":"2026-07-27T04:36:03.649000Z","event_type":"price_change","frame_hash":"19be6a0f43ea2c896cddd5d60f886115a6d5aca4a54cb3117c1116ae2f6ef8eb","frame_index":0,"kind":"data","monotonic_ns":228947359537458,"payload":{"event_type":"price_change","market":"0xeb66215f2e9faa6449e30a02bab5b8ed7b79a38bf961f6b24d0073c9c2419250","price_changes":[{"asset_id":"60386828328910021732068595344565885737045900010034836345809386672230885527307","best_ask":"0.7","best_bid":"0.69","hash":"72c768c118598242efbba02e2ad876eebd5bdf0d","price":"0.01","side":"BUY","size":"5458.02"},{"asset_id":"69697746896130839564035629862476347944307040470122503199396727085502753297492","best_ask":"0.31","best_bid":"0.3","hash":"2b58a06490f1662d694eae6a88d519cdc4fd323a","price":"0.99","side":"SELL","size":"5458.02"}],"timestamp":"1785126963649"},"payload_hash":"0d500a4f7e79053d4b9201affb5ea799445cee121efe0801ad5479688f50f33d","raw_frame":"{\"market\":\"0xeb66215f2e9faa6449e30a02bab5b8ed7b79a38bf961f6b24d0073c9c2419250\", \"price_changes\":[{\"asset_id\":\"60386828328910021732068595344565885737045900010034836345809386672230885527307\", \"price\":\"0.01\", \"size\":\"5458.02\", \"side\":\"BUY\", \"hash\":\"72c768c118598242efbba02e2ad876eebd5bdf0d\", \"best_bid\":\"0.69\", \"best_ask\":\"0.7\"}, {\"asset_id\":\"69697746896130839564035629862476347944307040470122503199396727085502753297492\", \"price\":\"0.99\", \"size\":\"5458.02\", \"side\":\"SELL\", \"hash\":\"2b58a06490f1662d694eae6a88d519cdc4fd323a\", \"best_bid\":\"0.3\", \"best_ask\":\"0.31\"}], \"timestamp\":\"1785126963649\", \"event_type\":\"price_change\"}","received_at":"2026-07-27T04:36:04.092858Z","schema_version":"clob-market-ws.price_change.v1","sequence":null,"server_hash":null,"server_timestamp":"1785126963649","session_id":"e9443c7415a0419799bee9cfbb1a9e4d","source":"clob_market_ws"},"received_at":"2026-07-27T04:36:04.092858Z","record_id":"2734a0edd544017c811e51f85e27253d3d1cf5232a33202367c46e5f75701728","schema_fingerprint":"4aa3821a28b0b7c2400bc59aba4bcc0a76e971dadd19610d3ad38c768e124dc7","schema_version":"edge-lab-recorder.raw.v1","sequence":null,"source":"clob_market_ws"}
{"event_at":"2026-07-27T04:36:03.668000Z","event_fingerprint":"d3825c01be79ce6b158302ff3c089671d35f5e387e4ab13a9e04680f235359cd","payload":{"connection_id":"0f4979d6978d463e9660b042fdcf555f","event_at":"2026-07-27T04:36:03.668000Z","event_type":"price_change","frame_hash":"fdae56d8fbe118b554b6a2a120ebe976b2254c6a028fa1737e68c3b5c2c28bc1","frame_index":0,"kind":"data","monotonic_ns":228947365073666,"payload":{"event_type":"price_change","market":"0xeb66215f2e9faa6449e30a02bab5b8ed7b79a38bf961f6b24d0073c9c2419250","price_changes":[{"asset_id":"69697746896130839564035629862476347944307040470122503199396727085502753297492","best_ask":"0.31","best_bid":"0.3","hash":"5ac8c4cb6ace23ceb4a9ae4c9d8c382b12c33d5e","price":"0.33","side":"SELL","size":"414.56"},{"asset_id":"60386828328910021732068595344565885737045900010034836345809386672230885527307","best_ask":"0.7","best_bid":"0.69","hash":"20153da4b62fface52831e59e05a08c10992fbc9","price":"0.67","side":"BUY","size":"414.56"}],"timestamp":"1785126963668"},"payload_hash":"4adf2593b40b1c2076340eb1457c085c6e78deb7bd0ce883a0c080964031efec","raw_frame":"{\"market\":\"0xeb66215f2e9faa6449e30a02bab5b8ed7b79a38bf961f6b24d0073c9c2419250\", \"price_changes\":[{\"asset_id\":\"69697746896130839564035629862476347944307040470122503199396727085502753297492\", \"price\":\"0.33\", \"size\":\"414.56\", \"side\":\"SELL\", \"hash\":\"5ac8c4cb6ace23ceb4a9ae4c9d8c382b12c33d5e\", \"best_bid\":\"0.3\", \"best_ask\":\"0.31\"}, {\"asset_id\":\"60386828328910021732068595344565885737045900010034836345809386672230885527307\", \"price\":\"0.67\", \"size\":\"414.56\", \"side\":\"BUY\", \"hash\":\"20153da4b62fface52831e59e05a08c10992fbc9\", \"best_bid\":\"0.69\", \"best_ask\":\"0.7\"}], \"timestamp\":\"1785126963668\", \"event_type\":\"price_change\"}","received_at":"2026-07-27T04:36:04.098394Z","schema_version":"clob-market-ws.price_change.v1","sequence":null,"server_hash":null,"server_timestamp":"1785126963668","session_id":"e9443c7415a0419799bee9cfbb1a9e4d","source":"clob_market_ws"},"received_at":"2026-07-27T04:36:04.098394Z","record_id":"c28b5ce04847a58d3b952f768229d607567214fe8884def8ffa34dcf31d8ca08","schema_fingerprint":"4aa3821a28b0b7c2400bc59aba4bcc0a76e971dadd19610d3ad38c768e124dc7","schema_version":"edge-lab-recorder.raw.v1","sequence":null,"source":"clob_market_ws"}
{"event_at":"2026-07-27T04:36:03.669000Z","event_fingerprint":"2ee27136697862995951c9f36199aff81350dd1484386711c93c084287da8935","payload":{"connection_id":"0f4979d6978d463e9660b042fdcf555f","event_at":"2026-07-27T04:36:03.669000Z","event_type":"price_change","frame_hash":"d0354d02ba0de6b560707ead23fdac7e47b29a916abf13f46b45456aec320850","frame_index":0,"kind":"data","monotonic_ns":228947373241750,"payload":{"event_type":"price_change","market":"0xeb66215f2e9faa6449e30a02bab5b8ed7b79a38bf961f6b24d0073c9c2419250","price_changes":[{"asset_id":"60386828328910021732068595344565885737045900010034836345809386672230885527307","best_ask":"0.7","best_bid":"0.69","hash":"f7c7579068f43e63384f8aeb8092073946aa7bb5","price":"0.01","side":"BUY","size":"5453.02"},{"asset_id":"69697746896130839564035629862476347944307040470122503199396727085502753297492","best_ask":"0.31","best_bid":"0.3","hash":"49e09393ee564d5c69e7b47b35d0a8f7d35d00e4","price":"0.99","side":"SELL","size":"5453.02"}],"timestamp":"1785126963669"},"payload_hash":"ee2d86d1c447e8e130b41911c1686507baa4084460f153793fe791af749caf55","raw_frame":"{\"market\":\"0xeb66215f2e9faa6449e30a02bab5b8ed7b79a38bf961f6b24d0073c9c2419250\", \"price_changes\":[{\"asset_id\":\"60386828328910021732068595344565885737045900010034836345809386672230885527307\", \"price\":\"0.01\", \"size\":\"5453.02\", \"side\":\"BUY\", \"hash\":\"f7c7579068f43e63384f8aeb8092073946aa7bb5\", \"best_bid\":\"0.69\", \"best_ask\":\"0.7\"}, {\"asset_id\":\"69697746896130839564035629862476347944307040470122503199396727085502753297492\", \"price\":\"0.99\", \"size\":\"5453.02\", \"side\":\"SELL\", \"hash\":\"49e09393ee564d5c69e7b47b35d0a8f7d35d00e4\", \"best_bid\":\"0.3\", \"best_ask\":\"0.31\"}], \"timestamp\":\"1785126963669\", \"event_type\":\"price_change\"}","received_at":"2026-07-27T04:36:04.106562Z","schema_version":"clob-market-ws.price_change.v1","sequence":null,"server_hash":null,"server_timestamp":"1785126963669","session_id":"e9443c7415a0419799bee9cfbb1a9e4d","source":"clob_market_ws"},"received_at":"2026-07-27T04:36:04.106562Z","record_id":"da734b1638ab8efd8df364da23b56aea151ddeed10b0a8c3905949d1e02aa01d","schema_fingerprint":"4aa3821a28b0b7c2400bc59aba4bcc0a76e971dadd19610d3ad38c768e124dc7","schema_version":"edge-lab-recorder.raw.v1","sequence":null,"source":"clob_market_ws"}
{"event_at":"2026-07-27T04:36:03.669000Z","event_fingerprint":"83f5e97af1ddb94cd309582b760c68933c14059a33f95e96fea97b826dbdb3a7","payload":{"connection_id":"0f4979d6978d463e9660b042fdcf555f","event_at":"2026-07-27T04:36:03.669000Z","event_type":"price_change","frame_hash":"6bc444674d9f7093e1ee5a12fb1e3fe81e5315e738fa7cc14f006a0e94e1eb77","frame_index":0,"kind":"data","monotonic_ns":228947379701958,"payload":{"event_type":"price_change","market":"0xeb66215f2e9faa6449e30a02bab5b8ed7b79a38bf961f6b24d0073c9c2419250","price_changes":[{"asset_id":"60386828328910021732068595344565885737045900010034836345809386672230885527307","best_ask":"0.7","best_bid":"0.69","hash":"616955466ad785aeb4365b203f8ea3cb7360fda1","price":"0.67","side":"BUY","size":"445.6"},{"asset_id":"69697746896130839564035629862476347944307040470122503199396727085502753297492","best_ask":"0.31","best_bid":"0.3","hash":"44a861d266a5ffca2580aa0717413d928f72e08d","price":"0.33","side":"SELL","size":"445.6"}],"timestamp":"1785126963669"},"payload_hash":"120335cc7556e8e2c3f76d773df10f21ca361938389be231061f2934fe5761f3","raw_frame":"{\"market\":\"0xeb66215f2e9faa6449e30a02bab5b8ed7b79a38bf961f6b24d0073c9c2419250\", \"price_changes\":[{\"asset_id\":\"60386828328910021732068595344565885737045900010034836345809386672230885527307\", \"price\":\"0.67\", \"size\":\"445.6\", \"side\":\"BUY\", \"hash\":\"616955466ad785aeb4365b203f8ea3cb7360fda1\", \"best_bid\":\"0.69\", \"best_ask\":\"0.7\"}, {\"asset_id\":\"69697746896130839564035629862476347944307040470122503199396727085502753297492\", \"price\":\"0.33\", \"size\":\"445.6\", \"side\":\"SELL\", \"hash\":\"44a861d266a5ffca2580aa0717413d928f72e08d\", \"best_bid\":\"0.3\", \"best_ask\":\"0.31\"}], \"timestamp\":\"1785126963669\", \"event_type\":\"price_change\"}","received_at":"2026-07-27T04:36:04.113023Z","schema_version":"clob-market-ws.price_change.v1","sequence":null,"server_hash":null,"server_timestamp":"1785126963669","session_id":"e9443c7415a0419799bee9cfbb1a9e4d","source":"clob_market_ws"},"received_at":"2026-07-27T04:36:04.113023Z","record_id":"2737b59fff07a3ab987d09d6cf9be856e9fa3ea9a0148fa7b12388a0f004f6cb","schema_fingerprint":"4aa3821a28b0b7c2400bc59aba4bcc0a76e971dadd19610d3ad38c768e124dc7","schema_version":"edge-lab-recorder.raw.v1","sequence":null,"source":"clob_market_ws"}
{"event_at":"2026-07-27T04:36:03.676000Z","event_fingerprint":"1a1d05d68f407988e86a88c78e34b615163f6a5ce5f1f88eb7a95d0061be7055","payload":{"connection_id":"0f4979d6978d463e9660b042fdcf555f","event_at":"2026-07-27T04:36:03.676000Z","event_type":"price_change","frame_hash":"d5cf9e590970a5807c61fa22ed97adc273f33d06b59d1a7b7232eabe42510e8e","frame_index":0,"kind":"data","monotonic_ns":228947384180583,"payload":{"event_type":"price_change","market":"0xeb66215f2e9faa6449e30a02bab5b8ed7b79a38bf961f6b24d0073c9c2419250","price_changes":[{"asset_id":"60386828328910021732068595344565885737045900010034836345809386672230885527307","best_ask":"0.7","best_bid":"0.69","hash":"e8543ee6021d760fa4728e1cdd3b7e9ca1334794","price":"0.02","side":"BUY","size":"688.1"},{"asset_id":"69697746896130839564035629862476347944307040470122503199396727085502753297492","best_ask":"0.31","best_bid":"0.3","hash":"6a16b3aededff6b5a2737b0b9f960494202cd7ef","price":"0.98","side":"SELL","size":"688.1"}],"timestamp":"1785126963676"},"payload_hash":"4abe4179bdc8fecd9195d24ccf98b960a9588cdc7ae1effd9654f780e9b7ca24","raw_frame":"{\"market\":\"0xeb66215f2e9faa6449e30a02bab5b8ed7b79a38bf961f6b24d0073c9c2419250\", \"price_changes\":[{\"asset_id\":\"60386828328910021732068595344565885737045900010034836345809386672230885527307\", \"price\":\"0.02\", \"size\":\"688.1\", \"side\":\"BUY\", \"hash\":\"e8543ee6021d760fa4728e1cdd3b7e9ca1334794\", \"best_bid\":\"0.69\", \"best_ask\":\"0.7\"}, {\"asset_id\":\"69697746896130839564035629862476347944307040470122503199396727085502753297492\", \"price\":\"0.98\", \"size\":\"688.1\", \"side\":\"SELL\", \"hash\":\"6a16b3aededff6b5a2737b0b9f960494202cd7ef\", \"best_bid\":\"0.3\", \"best_ask\":\"0.31\"}], \"timestamp\":\"1785126963676\", \"event_type\":\"price_change\"}","received_at":"2026-07-27T04:36:04.117501Z","schema_version":"clob-market-ws.price_change.v1","sequence":null,"server_hash":null,"server_timestamp":"1785126963676","session_id":"e9443c7415a0419799bee9cfbb1a9e4d","source":"clob_market_ws"},"received_at":"2026-07-27T04:36:04.117501Z","record_id":"8ab51fd456864a7eb26f285bf46cae852097c72b16116bb93378b43a36c24d58","schema_fingerprint":"4aa3821a28b0b7c2400bc59aba4bcc0a76e971dadd19610d3ad38c768e124dc7","schema_version":"edge-lab-recorder.raw.v1","sequence":null,"source":"clob_market_ws"}
{"event_at":"2026-07-27T04:36:03.756000Z","event_fingerprint":"e591accbb905913fbcc011c90ac9a4c64650d0fe53359b81daac27accefe49a3","payload":{"connection_id":"0f4979d6978d463e9660b042fdcf555f","event_at":"2026-07-27T04:36:03.756000Z","event_type":"price_change","frame_hash":"ffe3cb9232e57647083526f3215822877f40173099db1be06e6369a9fcbd509e","frame_index":0,"kind":"data","monotonic_ns":228947390873041,"payload":{"event_type":"price_change","market":"0xeb66215f2e9faa6449e30a02bab5b8ed7b79a38bf961f6b24d0073c9c2419250","price_changes":[{"asset_id":"60386828328910021732068595344565885737045900010034836345809386672230885527307","best_ask":"0.7","best_bid":"0.69","hash":"e828b22bf26a6146b5893d9637969b7a2d5f8b63","price":"0.54","side":"BUY","size":"175"},{"asset_id":"69697746896130839564035629862476347944307040470122503199396727085502753297492","best_ask":"0.31","best_bid":"0.3","hash":"c82fc640f76ebecab29061818bfd2fcb9e5c515b","price":"0.46","side":"SELL","size":"175"}],"timestamp":"1785126963756"},"payload_hash":"1258968913f80fd42f149dc4bb5eac823535f4dbb50960408fd85de32048c0ff","raw_frame":"{\"market\":\"0xeb66215f2e9faa6449e30a02bab5b8ed7b79a38bf961f6b24d0073c9c2419250\", \"price_changes\":[{\"asset_id\":\"60386828328910021732068595344565885737045900010034836345809386672230885527307\", \"price\":\"0.54\", \"size\":\"175\", \"side\":\"BUY\", \"hash\":\"e828b22bf26a6146b5893d9637969b7a2d5f8b63\", \"best_bid\":\"0.69\", \"best_ask\":\"0.7\"}, {\"asset_id\":\"69697746896130839564035629862476347944307040470122503199396727085502753297492\", \"price\":\"0.46\", \"size\":\"175\", \"side\":\"SELL\", \"hash\":\"c82fc640f76ebecab29061818bfd2fcb9e5c515b\", \"best_bid\":\"0.3\", \"best_ask\":\"0.31\"}], \"timestamp\":\"1785126963756\", \"event_type\":\"price_change\"}","received_at":"2026-07-27T04:36:04.124196Z","schema_version":"clob-market-ws.price_change.v1","sequence":null,"server_hash":null,"server_timestamp":"1785126963756","session_id":"e9443c7415a0419799bee9cfbb1a9e4d","source":"clob_market_ws"},"received_at":"2026-07-27T04:36:04.124196Z","record_id":"8c070735620e94e381bdbe44d25a7c000932d75eadef5547ff8d49b772350275","schema_fingerprint":"4aa3821a28b0b7c2400bc59aba4bcc0a76e971dadd19610d3ad38c768e124dc7","schema_version":"edge-lab-recorder.raw.v1","sequence":null,"source":"clob_market_ws"}
{"event_at":"2026-07-27T04:36:03.765000Z","event_fingerprint":"564d4bcc714ea94acb763c67b272ba4678dc174b2e2448a4e08f4a496db4a66b","payload":{"connection_id":"0f4979d6978d463e9660b042fdcf555f","event_at":"2026-07-27T04:36:03.765000Z","event_type":"price_change","frame_hash":"94871b7bddee1a18e3441b7587a4b278ed8a2890669554f2722f491483e4a17d","frame_index":0,"kind":"data","monotonic_ns":228947395590125,"payload":{"event_type":"price_change","market":"0xeb66215f2e9faa6449e30a02bab5b8ed7b79a38bf961f6b24d0073c9c2419250","price_changes":[{"asset_id":"60386828328910021732068595344565885737045900010034836345809386672230885527307","best_ask":"0.7","best_bid":"0.69","hash":"b966000ec37881e676764d0f3544fca8e80e9a38","price":"0.67","side":"BUY","size":"414.56"},{"asset_id":"69697746896130839564035629862476347944307040470122503199396727085502753297492","best_ask":"0.31","best_bid":"0.3","hash":"405f778ead929ae8d08941afce3532b479cd8ca4","price":"0.33","side":"SELL","size":"414.56"}],"timestamp":"1785126963765"},"payload_hash":"28875a866d1c1bc0fae3825f4e9bd72986b236f1b081c6b3f95926eac8b37769","raw_frame":"{\"market\":\"0xeb66215f2e9faa6449e30a02bab5b8ed7b79a38bf961f6b24d0073c9c2419250\", \"price_changes\":[{\"asset_id\":\"60386828328910021732068595344565885737045900010034836345809386672230885527307\", \"price\":\"0.67\", \"size\":\"414.56\", \"side\":\"BUY\", \"hash\":\"b966000ec37881e676764d0f3544fca8e80e9a38\", \"best_bid\":\"0.69\", \"best_ask\":\"0.7\"}, {\"asset_id\":\"69697746896130839564035629862476347944307040470122503199396727085502753297492\", \"price\":\"0.33\", \"size\":\"414.56\", \"side\":\"SELL\", \"hash\":\"405f778ead929ae8d08941afce3532b479cd8ca4\", \"best_bid\":\"0.3\", \"best_ask\":\"0.31\"}], \"timestamp\":\"1785126963765\", \"event_type\":\"price_change\"}","received_at":"2026-07-27T04:36:04.128911Z","schema_version":"clob-market-ws.price_change.v1","sequence":null,"server_hash":null,"server_timestamp":"1785126963765","session_id":"e9443c7415a0419799bee9cfbb1a9e4d","source":"clob_market_ws"},"received_at":"2026-07-27T04:36:04.128911Z","record_id":"7b6870609c41eea82d6766eb4d5c624bdfc372726aa12c248258753be3c09f0a","schema_fingerprint":"4aa3821a28b0b7c2400bc59aba4bcc0a76e971dadd19610d3ad38c768e124dc7","schema_version":"edge-lab-recorder.raw.v1","sequence":null,"source":"clob_market_ws"}
{"event_at":"2026-07-27T04:36:03.769000Z","event_fingerprint":"0f3fc06a17eafaeed031a2b1c1f05da45dec549485f67e42dc0ab4593b62d139","payload":{"connection_id":"0f4979d6978d463e9660b042fdcf555f","event_at":"2026-07-27T04:36:03.769000Z","event_type":"price_change","frame_hash":"cc433bb1a9a76398dce96d868534a5df1a3e2dfa1bcea63e250f7842b47b57c7","frame_index":0,"kind":"data","monotonic_ns":228947400322458,"payload":{"event_type":"price_change","market":"0xeb66215f2e9faa6449e30a02bab5b8ed7b79a38bf961f6b24d0073c9c2419250","price_changes":[{"asset_id":"69697746896130839564035629862476347944307040470122503199396727085502753297492","best_ask":"0.31","best_bid":"0.3","hash":"1922f0d6efd326a85bf913280f1acd7c2fb1e23a","price":"0.33","side":"SELL","size":"444.6"},{"asset_id":"60386828328910021732068595344565885737045900010034836345809386672230885527307","best_ask":"0.7","best_bid":"0.69","hash":"4859b6013e96b2fd164bbcb06cf810ee76fce56c","price":"0.67","side":"BUY","size":"444.6"}],"timestamp":"1785126963769"},"payload_hash":"a44ce90c2fdc9b5dcdc04eaf651208a687c55d2dd06984161b152316206579fc","raw_frame":"{\"market\":\"0xeb66215f2e9faa6449e30a02bab5b8ed7b79a38bf961f6b24d0073c9c2419250\", \"price_changes\":[{\"asset_id\":\"69697746896130839564035629862476347944307040470122503199396727085502753297492\", \"price\":\"0.33\", \"size\":\"444.6\", \"side\":\"SELL\", \"hash\":\"1922f0d6efd326a85bf913280f1acd7c2fb1e23a\", \"best_bid\":\"0.3\", \"best_ask\":\"0.31\"}, {\"asset_id\":\"60386828328910021732068595344565885737045900010034836345809386672230885527307\", \"price\":\"0.67\", \"size\":\"444.6\", \"side\":\"BUY\", \"hash\":\"4859b6013e96b2fd164bbcb06cf810ee76fce56c\", \"best_bid\":\"0.69\", \"best_ask\":\"0.7\"}], \"timestamp\":\"1785126963769\", \"event_type\":\"price_change\"}","received_at":"2026-07-27T04:36:04.133643Z","schema_version":"clob-market-ws.price_change.v1","sequence":null,"server_hash":null,"server_timestamp":"1785126963769","session_id":"e9443c7415a0419799bee9cfbb1a9e4d","source":"clob_market_ws"},"received_at":"2026-07-27T04:36:04.133643Z","record_id":"2fb1b8ccae50ad26eda1702deaf90217bf0dad42e31e1ffdd984c2600e7e77cf","schema_fingerprint":"4aa3821a28b0b7c2400bc59aba4bcc0a76e971dadd19610d3ad38c768e124dc7","schema_version":"edge-lab-recorder.raw.v1","sequence":null,"source":"clob_market_ws"}
{"event_at":"2026-07-27T04:36:03.806000Z","event_fingerprint":"9bf97559be937266ad8bef7c18fb4e399b6292343a138e97ba05420fad78be27","payload":{"connection_id":"0f4979d6978d463e9660b042fdcf555f","event_at":"2026-07-27T04:36:03.806000Z","event_type":"price_change","frame_hash":"641db53976900c7461c24c1fff2929d8ceea6c63d8347a93666cab2e0142ec52","frame_index":0,"kind":"data","monotonic_ns":228947408049750,"payload":{"event_type":"price_change","market":"0xeb66215f2e9faa6449e30a02bab5b8ed7b79a38bf961f6b24d0073c9c2419250","price_changes":[{"asset_id":"60386828328910021732068595344565885737045900010034836345809386672230885527307","best_ask":"0.7","best_bid":"0.69","hash":"ee44a478fdf1288d2c04f3ad172232053c056c8e","price":"0.02","side":"BUY","size":"683.1"},{"asset_id":"69697746896130839564035629862476347944307040470122503199396727085502753297492","best_ask":"0.31","best_bid":"0.3","hash":"f380fcab97c5de0234e864830f4d0209b18cc78f","price":"0.98","side":"SELL","size":"683.1"}],"timestamp":"1785126963806"},"payload_hash":"4948015b8bcdb878d7eff11d4c5ccfc88c4953ddebbfc2bd870881da2892ccba","raw_frame":"{\"market\":\"0xeb66215f2e9faa6449e30a02bab5b8ed7b79a38bf961f6b24d0073c9c2419250\", \"price_changes\":[{\"asset_id\":\"60386828328910021732068595344565885737045900010034836345809386672230885527307\", \"price\":\"0.02\", \"size\":\"683.1\", \"side\":\"BUY\", \"hash\":\"ee44a478fdf1288d2c04f3ad172232053c056c8e\", \"best_bid\":\"0.69\", \"best_ask\":\"0.7\"}, {\"asset_id\":\"69697746896130839564035629862476347944307040470122503199396727085502753297492\", \"price\":\"0.98\", \"size\":\"683.1\", \"side\":\"SELL\", \"hash\":\"f380fcab97c5de0234e864830f4d0209b18cc78f\", \"best_bid\":\"0.3\", \"best_ask\":\"0.31\"}], \"timestamp\":\"1785126963806\", \"event_type\":\"price_change\"}","received_at":"2026-07-27T04:36:04.141371Z","schema_version":"clob-market-ws.price_change.v1","sequence":null,"server_hash":null,"server_timestamp":"1785126963806","session_id":"e9443c7415a0419799bee9cfbb1a9e4d","source":"clob_market_ws"},"received_at":"2026-07-27T04:36:04.141371Z","record_id":"5f4c084c7ce88690a453a04aa5d7f423e5a9802cef2bf7b4d385496c17536140","schema_fingerprint":"4aa3821a28b0b7c2400bc59aba4bcc0a76e971dadd19610d3ad38c768e124dc7","schema_version":"edge-lab-recorder.raw.v1","sequence":null,"source":"clob_market_ws"}
{"event_at":"2026-07-27T04:36:03.873000Z","event_fingerprint":"2bcf79b8ede2df3c772a7bd6134e5135518b91a283fe51dfd1b364852c31b995","payload":{"connection_id":"0f4979d6978d463e9660b042fdcf555f","event_at":"2026-07-27T04:36:03.873000Z","event_type":"price_change","frame_hash":"908ea554da451445782782c084710e6f3cbc5ae99904aaa9fe7b4d005dfa17e1","frame_index":0,"kind":"data","monotonic_ns":228947413409041,"payload":{"event_type":"price_change","market":"0xeb66215f2e9faa6449e30a02bab5b8ed7b79a38bf961f6b24d0073c9c2419250","price_changes":[{"asset_id":"60386828328910021732068595344565885737045900010034836345809386672230885527307","best_ask":"0.7","best_bid":"0.69","hash":"d326eb24830e43f5f5c05d6f62abf2de27301992","price":"0.67","side":"BUY","size":"475.64"},{"asset_id":"69697746896130839564035629862476347944307040470122503199396727085502753297492","best_ask":"0.31","best_bid":"0.3","hash":"2ab4af398bedf0bb89c8d6ba0a667e329f963de5","price":"0.33","side":"SELL","size":"475.64"}],"timestamp":"1785126963873"},"payload_hash":"3c9b53f87377f1d85498d17034808d3943807739752306e24b0a81504916df0c","raw_frame":"{\"market\":\"0xeb66215f2e9faa6449e30a02bab5b8ed7b79a38bf961f6b24d0073c9c2419250\", \"price_changes\":[{\"asset_id\":\"60386828328910021732068595344565885737045900010034836345809386672230885527307\", \"price\":\"0.67\", \"size\":\"475.64\", \"side\":\"BUY\", \"hash\":\"d326eb24830e43f5f5c05d6f62abf2de27301992\", \"best_bid\":\"0.69\", \"best_ask\":\"0.7\"}, {\"asset_id\":\"69697746896130839564035629862476347944307040470122503199396727085502753297492\", \"price\":\"0.33\", \"size\":\"475.64\", \"side\":\"SELL\", \"hash\":\"2ab4af398bedf0bb89c8d6ba0a667e329f963de5\", \"best_bid\":\"0.3\", \"best_ask\":\"0.31\"}], \"timestamp\":\"1785126963873\", \"event_type\":\"price_change\"}","received_at":"2026-07-27T04:36:04.146728Z","schema_version":"clob-market-ws.price_change.v1","sequence":null,"server_hash":null,"server_timestamp":"1785126963873","session_id":"e9443c7415a0419799bee9cfbb1a9e4d","source":"clob_market_ws"},"received_at":"2026-07-27T04:36:04.146728Z","record_id":"62585adc96f810a96202d5a7f3b01f4d8d218df41c78fdec26c13e12593596b6","schema_fingerprint":"4aa3821a28b0b7c2400bc59aba4bcc0a76e971dadd19610d3ad38c768e124dc7","schema_version":"edge-lab-recorder.raw.v1","sequence":null,"source":"clob_market_ws"}
{"event_at":"2026-07-27T04:36:03.874000Z","event_fingerprint":"68fb01fac9a667c53cf63214223f521dc541c07ae5bca96f434705d55da8226a","payload":{"connection_id":"0f4979d6978d463e9660b042fdcf555f","event_at":"2026-07-27T04:36:03.874000Z","event_type":"price_change","frame_hash":"930f8964a6e00db05e3d3896adb02f72271786a409d870d215975e1b3222d7ee","frame_index":0,"kind":"data","monotonic_ns":228947419828625,"payload":{"event_type":"price_change","market":"0xeb66215f2e9faa6449e30a02bab5b8ed7b79a38bf961f6b24d0073c9c2419250","price_changes":[{"asset_id":"69697746896130839564035629862476347944307040470122503199396727085502753297492","best_ask":"0.31","best_bid":"0.3","hash":"10f8cfe43d4c0a3be56d05ed699635d000f46511","price":"0.33","side":"SELL","size":"445.6"},{"asset_id":"60386828328910021732068595344565885737045900010034836345809386672230885527307","best_ask":"0.7","best_bid":"0.69","hash":"45af89688421cb2d219ea04b7a37b1b367b92181","price":"0.67","side":"BUY","size":"445.6"}],"timestamp":"1785126963874"},"payload_hash":"5450aae75d6a5bcb415c8fd5c6fe7dc1001e495dd717a37a5ed706c316deca0d","raw_frame":"{\"market\":\"0xeb66215f2e9faa6449e30a02bab5b8ed7b79a38bf961f6b24d0073c9c2419250\", \"price_changes\":[{\"asset_id\":\"69697746896130839564035629862476347944307040470122503199396727085502753297492\", \"price\":\"0.33\", \"size\":\"445.6\", \"side\":\"SELL\", \"hash\":\"10f8cfe43d4c0a3be56d05ed699635d000f46511\", \"best_bid\":\"0.3\", \"best_ask\":\"0.31\"}, {\"asset_id\":\"60386828328910021732068595344565885737045900010034836345809386672230885527307\", \"price\":\"0.67\", \"size\":\"445.6\", \"side\":\"BUY\", \"hash\":\"45af89688421cb2d219ea04b7a37b1b367b92181\", \"best_bid\":\"0.69\", \"best_ask\":\"0.7\"}], \"timestamp\":\"1785126963874\", \"event_type\":\"price_change\"}","received_at":"2026-07-27T04:36:04.153146Z","schema_version":"clob-market-ws.price_change.v1","sequence":null,"server_hash":null,"server_timestamp":"1785126963874","session_id":"e9443c7415a0419799bee9cfbb1a9e4d","source":"clob_market_ws"},"received_at":"2026-07-27T04:36:04.153146Z","record_id":"00b93c28a1e4b4a5d160c0b999b7e41c5ccb070540dd26ea02a9f47854e737ff","schema_fingerprint":"4aa3821a28b0b7c2400bc59aba4bcc0a76e971dadd19610d3ad38c768e124dc7","schema_version":"edge-lab-recorder.raw.v1","sequence":null,"source":"clob_market_ws"}
{"event_at":"2026-07-27T04:36:03.898000Z","event_fingerprint":"2e6af87f298fcae8a1ab836d7ec82fabb59af166566752c8ee11b0c565783f8e","payload":{"connection_id":"0f4979d6978d463e9660b042fdcf555f","event_at":"2026-07-27T04:36:03.898000Z","event_type":"price_change","frame_hash":"caaad5259b202fdbd0c57de4ad680802c668b0287d302efe364cc785952710bb","frame_index":0,"kind":"data","monotonic_ns":228947424263791,"payload":{"event_type":"price_change","market":"0xeb66215f2e9faa6449e30a02bab5b8ed7b79a38bf961f6b24d0073c9c2419250","price_changes":[{"asset_id":"60386828328910021732068595344565885737045900010034836345809386672230885527307","best_ask":"0.7","best_bid":"0.69","hash":"21d380aa811b6b30228777b9ef8a9d9c3a85b719","price":"0.04","side":"BUY","size":"583.09"},{"asset_id":"69697746896130839564035629862476347944307040470122503199396727085502753297492","best_ask":"0.31","best_bid":"0.3","hash":"0d97cabfa6df8cca7b3f71a46cdb4d1eb7eb0199","price":"0.96","side":"SELL","size":"583.09"}],"timestamp":"1785126963898"},"payload_hash":"8e982230cc25ec1476ed93f44245b0633f17fadb0ae3779ae10921806ffee176","raw_frame":"{\"market\":\"0xeb66215f2e9faa6449e30a02bab5b8ed7b79a38bf961f6b24d0073c9c2419250\", \"price_changes\":[{\"asset_id\":\"60386828328910021732068595344565885737045900010034836345809386672230885527307\", \"price\":\"0.04\", \"size\":\"583.09\", \"side\":\"BUY\", \"hash\":\"21d380aa811b6b30228777b9ef8a9d9c3a85b719\", \"best_bid\":\"0.69\", \"best_ask\":\"0.7\"}, {\"asset_id\":\"69697746896130839564035629862476347944307040470122503199396727085502753297492\", \"price\":\"0.96\", \"size\":\"583.09\", \"side\":\"SELL\", \"hash\":\"0d97cabfa6df8cca7b3f71a46cdb4d1eb7eb0199\", \"best_bid\":\"0.3\", \"best_ask\":\"0.31\"}], \"timestamp\":\"1785126963898\", \"event_type\":\"price_change\"}","received_at":"2026-07-27T04:36:04.157585Z","schema_version":"clob-market-ws.price_change.v1","sequence":null,"server_hash":null,"server_timestamp":"1785126963898","session_id":"e9443c7415a0419799bee9cfbb1a9e4d","source":"clob_market_ws"},"received_at":"2026-07-27T04:36:04.157585Z","record_id":"eec1c5541470eda1fd6cabbe2dfa967abc028bd9e5c6893aa78c41cd2bc4afe8","schema_fingerprint":"4aa3821a28b0b7c2400bc59aba4bcc0a76e971dadd19610d3ad38c768e124dc7","schema_version":"edge-lab-recorder.raw.v1","sequence":null,"source":"clob_market_ws"}
{"event_at":"2026-07-27T04:36:03.910000Z","event_fingerprint":"347e9d7722e9e33dd6e04c19c360f4eb8413ea7086e79aa10dd8e6d0d37e34fa","payload":{"connection_id":"0f4979d6978d463e9660b042fdcf555f","event_at":"2026-07-27T04:36:03.910000Z","event_type":"price_change","frame_hash":"5520d76549ece88ab142f380508998bf95f32fc1484dc3c2eba91ea9f2d024a5","frame_index":0,"kind":"data","monotonic_ns":228947431477625,"payload":{"event_type":"price_change","market":"0xeb66215f2e9faa6449e30a02bab5b8ed7b79a38bf961f6b24d0073c9c2419250","price_changes":[{"asset_id":"69697746896130839564035629862476347944307040470122503199396727085502753297492","best_ask":"0.31","best_bid":"0.3","hash":"752b1e85b669aae3ed3090c035d04787e9b68b5f","price":"0.3","side":"BUY","size":"47"},{"asset_id":"60386828328910021732068595344565885737045900010034836345809386672230885527307","best_ask":"0.7","best_bid":"0.69","hash":"ef6e3428b22891fad0f89e9b9de5cf76e7d7df2c","price":"0.7","side":"SELL","size":"47"}],"timestamp":"1785126963910"},"payload_hash":"34f0a4beea286b4bd87f3271f7055935dd716ad1dfa4ff651b5f282e2430dc5d","raw_frame":"{\"market\":\"0xeb66215f2e9faa6449e30a02bab5b8ed7b79a38bf961f6b24d0073c9c2419250\", \"price_changes\":[{\"asset_id\":\"69697746896130839564035629862476347944307040470122503199396727085502753297492\", \"price\":\"0.3\", \"size\":\"47\", \"side\":\"BUY\", \"hash\":\"752b1e85b669aae3ed3090c035d04787e9b68b5f\", \"best_bid\":\"0.3\", \"best_ask\":\"0.31\"}, {\"asset_id\":\"60386828328910021732068595344565885737045900010034836345809386672230885527307\", \"price\":\"0.7\", \"size\":\"47\", \"side\":\"SELL\", \"hash\":\"ef6e3428b22891fad0f89e9b9de5cf76e7d7df2c\", \"best_bid\":\"0.69\", \"best_ask\":\"0.7\"}], \"timestamp\":\"1785126963910\", \"event_type\":\"price_change\"}","received_at":"2026-07-27T04:36:04.164799Z","schema_version":"clob-market-ws.price_change.v1","sequence":null,"server_hash":null,"server_timestamp":"1785126963910","session_id":"e9443c7415a0419799bee9cfbb1a9e4d","source":"clob_market_ws"},"received_at":"2026-07-27T04:36:04.164799Z","record_id":"dcb82020ff5345b05454ef7cf2b221dacf49040a48aa3e81b3b29c5f190a51e4","schema_fingerprint":"4aa3821a28b0b7c2400bc59aba4bcc0a76e971dadd19610d3ad38c768e124dc7","schema_version":"edge-lab-recorder.raw.v1","sequence":null,"source":"clob_market_ws"}
