{"event_at":"2026-07-27T04:30:27.151000Z","event_fingerprint":"9bf5cbdbbc90906a754d516190e2baa6e9dd605dcd2989bfaf8960c0fcb797a6","payload":{"connection_id":"0f4979d6978d463e9660b042fdcf555f","event_at":"2026-07-27T04:30:27.151000Z","event_type":"price_change","frame_hash":"16ccaebcca5e544c44818e04516bd827f2927954b14892b8a84f664c90aca215","frame_index":0,"kind":"data","monotonic_ns":228611967068250,"payload":{"event_type":"price_change","market":"0xeb66215f2e9faa6449e30a02bab5b8ed7b79a38bf961f6b24d0073c9c2419250","price_changes":[{"asset_id":"69697746896130839564035629862476347944307040470122503199396727085502753297492","best_ask":"0.41","best_bid":"0.4","hash":"41cc4ee92ad90f1c4d65c5782748b010afc5e1ad","price":"0.35","side":"BUY","size":"35"},{"asset_id":"60386828328910021732068595344565885737045900010034836345809386672230885527307","best_ask":"0.6","best_bid":"0.59","hash":"e748ae71b9f6a8ed4242aeaad1f77b5b9e5d8373","price":"0.65","side":"SELL","size":"35"}],"timestamp":"1785126627151"},"payload_hash":"74f1ec33798fd89ffa30d6b8b620341b0595e425f8321eaa37ee204dcb313be6","raw_frame":"{\"market\":\"0xeb66215f2e9faa6449e30a02bab5b8ed7b79a38bf961f6b24d0073c9c2419250\", \"price_changes\":[{\"asset_id\":\"69697746896130839564035629862476347944307040470122503199396727085502753297492\", \"price\":\"0.35\", \"size\":\"35\", \"side\":\"BUY\", \"hash\":\"41cc4ee92ad90f1c4d65c5782748b010afc5e1ad\", \"best_bid\":\"0.4\", \"best_ask\":\"0.41\"}, {\"asset_id\":\"60386828328910021732068595344565885737045900010034836345809386672230885527307\", \"price\":\"0.65\", \"size\":\"35\", \"side\":\"SELL\", \"hash\":\"e748ae71b9f6a8ed4242aeaad1f77b5b9e5d8373\", \"best_bid\":\"0.59\", \"best_ask\":\"0.6\"}], \"timestamp\":\"1785126627151\", \"event_type\":\"price_change\"}","received_at":"2026-07-27T04:30:28.697479Z","schema_version":"clob-market-ws.price_change.v1","sequence":null,"server_hash":null,"server_timestamp":"1785126627151","session_id":"e9443c7415a0419799bee9cfbb1a9e4d","source":"clob_market_ws"},"received_at":"2026-07-27T04:30:28.697479Z","record_id":"983dd8e3a3104fc6e44f06f57fe14d2a8666215032a77bcfe6523a1e16616c6d","schema_fingerprint":"4aa3821a28b0b7c2400bc59aba4bcc0a76e971dadd19610d3ad38c768e124dc7","schema_version":"edge-lab-recorder.raw.v1","sequence":null,"source":"clob_market_ws"}
{"event_at":"2026-07-27T04:30:27.156000Z","event_fingerprint":"30d22faedec41b76e85f91b29931e5ebca60498118dfb6792e72bb364e188691","payload":{"connection_id":"0f4979d6978d463e9660b042fdcf555f","event_at":"2026-07-27T04:30:27.156000Z","event_type":"price_change","frame_hash":"40471390824d7d1dca45ac32a3da20c25d8a7406aab461707474f03720f8aee2","frame_index":0,"kind":"data","monotonic_ns":228611998442916,"payload":{"event_type":"price_change","market":"0xeb66215f2e9faa6449e30a02bab5b8ed7b79a38bf961f6b24d0073c9c2419250","price_changes":[{"asset_id":"69697746896130839564035629862476347944307040470122503199396727085502753297492","best_ask":"0.41","best_bid":"0.4","hash":"8223651fee36890fc0082b8be79bf646b207e28c","price":"0.3","side":"BUY","size":"299.22"},{"asset_id":"60386828328910021732068595344565885737045900010034836345809386672230885527307","best_ask":"0.6","best_bid":"0.59","hash":"c894c8ee2206525b6ee7310ec17b77d854647978","price":"0.7","side":"SELL","size":"299.22"}],"timestamp":"1785126627156"},"payload_hash":"9e3efc9c13c1122ba25c1a91da9466c679b4b12703b9d54a7908bcc02ded77a1","raw_frame":"{\"market\":\"0xeb66215f2e9faa6449e30a02bab5b8ed7b79a38bf961f6b24d0073c9c2419250\", \"price_changes\":[{\"asset_id\":\"69697746896130839564035629862476347944307040470122503199396727085502753297492\", \"price\":\"0.3\", \"size\":\"299.22\", \"side\":\"BUY\", \"hash\":\"8223651fee36890fc0082b8be79bf646b207e28c\", \"best_bid\":\"0.4\", \"best_ask\":\"0.41\"}, {\"asset_id\":\"60386828328910021732068595344565885737045900010034836345809386672230885527307\", \"price\":\"0.7\", \"size\":\"299.22\", \"side\":\"SELL\", \"hash\":\"c894c8ee2206525b6ee7310ec17b77d854647978\", \"best_bid\":\"0.59\", \"best_ask\":\"0.6\"}], \"timestamp\":\"1785126627156\", \"event_type\":\"price_change\"}","received_at":"2026-07-27T04:30:28.728854Z","schema_version":"clob-market-ws.price_change.v1","sequence":null,"server_hash":null,"server_timestamp":"1785126627156","session_id":"e9443c7415a0419799bee9cfbb1a9e4d","source":"clob_market_ws"},"received_at":"2026-07-27T04:30:28.728854Z","record_id":"4174459ad330eb32da36c98c64a5ca3afd7495003750e183cc043ac29a671819","schema_fingerprint":"4aa3821a28b0b7c2400bc59aba4bcc0a76e971dadd19610d3ad38c768e124dc7","schema_version":"edge-lab-recorder.raw.v1","sequence":null,"source":"clob_market_ws"}
{"event_at":"2026-07-27T04:30:27.169000Z","event_fingerprint":"3f2488f901c47e563c69334310d13f33f9612b31767d35a2b58d7b385873df92","payload":{"connection_id":"0f4979d6978d463e9660b042fdcf555f","event_at":"2026-07-27T04:30:27.169000Z","event_type":"price_change","frame_hash":"cd11187323e2e01737236dc9671dfbe78c972e63dcd5878fb55586d3116deb14","frame_index":0,"kind":"data","monotonic_ns":228612009748500,"payload":{"event_type":"price_change","market":"0xeb66215f2e9faa6449e30a02bab5b8ed7b79a38bf961f6b24d0073c9c2419250","price_changes":[{"asset_id":"60386828328910021732068595344565885737045900010034836345809386672230885527307","best_ask":"0.6","best_bid":"0.59","hash":"4e70a55e9a6d754b961ce94e45dd9eadd0ff72bc","price":"0.55","side":"BUY","size":"30.68"},{"asset_id":"69697746896130839564035629862476347944307040470122503199396727085502753297492","best_ask":"0.41","best_bid":"0.4","hash":"d5a2bdc770d9ad1446678e1c8380db8c8373578d","price":"0.45","side":"SELL","size":"30.68"}],"timestamp":"1785126627169"},"payload_hash":"2c87ee44ded1e2179014c580529cb9ace330619698eda889cb665acddf60412d","raw_frame":"{\"market\":\"0xeb66215f2e9faa6449e30a02bab5b8ed7b79a38bf961f6b24d0073c9c2419250\", \"price_changes\":[{\"asset_id\":\"60386828328910021732068595344565885737045900010034836345809386672230885527307\", \"price\":\"0.55\", \"size\":\"30.68\", \"side\":\"BUY\", \"hash\":\"4e70a55e9a6d754b961ce94e45dd9eadd0ff72bc\", \"best_bid\":\"0.59\", \"best_ask\":\"0.6\"}, {\"asset_id\":\"69697746896130839564035629862476347944307040470122503199396727085502753297492\", \"price\":\"0.45\", \"size\":\"30.68\", \"side\":\"SELL\", \"hash\":\"d5a2bdc770d9ad1446678e1c8380db8c8373578d\", \"best_bid\":\"0.4\", \"best_ask\":\"0.41\"}], \"timestamp\":\"1785126627169\", \"event_type\":\"price_change\"}","received_at":"2026-07-27T04:30:28.740160Z","schema_version":"clob-market-ws.price_change.v1","sequence":null,"server_hash":null,"server_timestamp":"1785126627169","session_id":"e9443c7415a0419799bee9cfbb1a9e4d","source":"clob_market_ws"},"received_at":"2026-07-27T04:30:28.740160Z","record_id":"c22cc5d9459c59b18a2ff2572bc5963af33e94aa74f296ed0fe6f0ae8a2c1ff9","schema_fingerprint":"4aa3821a28b0b7c2400bc59aba4bcc0a76e971dadd19610d3ad38c768e124dc7","schema_version":"edge-lab-recorder.raw.v1","sequence":null,"source":"clob_market_ws"}
{"event_at":"2026-07-27T04:30:27.191000Z","event_fingerprint":"a86b02ebc5d9014b326e6521735e3142eaceb6fc620952c9ce6b3e4738164840","payload":{"connection_id":"0f4979d6978d463e9660b042fdcf555f","event_at":"2026-07-27T04:30:27.191000Z","event_type":"price_change","frame_hash":"a88e59ffec4170bb1484b93f29d3fa785756900c72a4ae0ee6c0a25da1d38ca6","frame_index":0,"kind":"data","monotonic_ns":228612016228041,"payload":{"event_type":"price_change","market":"0xeb66215f2e9faa6449e30a02bab5b8ed7b79a38bf961f6b24d0073c9c2419250","price_changes":[{"asset_id":"69697746896130839564035629862476347944307040470122503199396727085502753297492","best_ask":"0.41","best_bid":"0.4","hash":"34c3acd26f8139de11569b4a1ff10d2a256abe1c","price":"0.42","side":"SELL","size":"35.01"},{"asset_id":"60386828328910021732068595344565885737045900010034836345809386672230885527307","best_ask":"0.6","best_bid":"0.59","hash":"3258cfce25c02de09e3b4d8be223f03008f2a753","price":"0.58","side":"BUY","size":"35.01"}],"timestamp":"1785126627191"},"payload_hash":"e2568fc32764b2f27fe520c797a562658d5dbc9f2033486eaa967800ec667668","raw_frame":"{\"market\":\"0xeb66215f2e9faa6449e30a02bab5b8ed7b79a38bf961f6b24d0073c9c2419250\", \"price_changes\":[{\"asset_id\":\"69697746896130839564035629862476347944307040470122503199396727085502753297492\", \"price\":\"0.42\", \"size\":\"35.01\", \"side\":\"SELL\", \"hash\":\"34c3acd26f8139de11569b4a1ff10d2a256abe1c\", \"best_bid\":\"0.4\", \"best_ask\":\"0.41\"}, {\"asset_id\":\"60386828328910021732068595344565885737045900010034836345809386672230885527307\", \"price\":\"0.58\", \"size\":\"35.01\", \"side\":\"BUY\", \"hash\":\"3258cfce25c02de09e3b4d8be223f03008f2a753\", \"best_bid\":\"0.59\", \"best_ask\":\"0.6\"}], \"timestamp\":\"1785126627191\", \"event_type\":\"price_change\"}","received_at":"2026-07-27T04:30:28.746640Z","schema_version":"clob-market-ws.price_change.v1","sequence":null,"server_hash":null,"server_timestamp":"1785126627191","session_id":"e9443c7415a0419799bee9cfbb1a9e4d","source":"clob_market_ws"},"received_at":"2026-07-27T04:30:28.746640Z","record_id":"191191cfa7fd7a798bfccd9ee91357abcbad3abde6bb6ac08baa2f3903bb160b","schema_fingerprint":"4aa3821a28b0b7c2400bc59aba4bcc0a76e971dadd19610d3ad38c768e124dc7","schema_version":"edge-lab-recorder.raw.v1","sequence":null,"source":"clob_market_ws"}
{"event_at":"2026-07-27T04:30:27.193000Z","event_fingerprint":"e5124649ee8e6f460fa029caa77dad357e6ec00c354b6ad75619704bc76b918a","payload":{"connection_id":"0f4979d6978d463e9660b042fdcf555f","event_at":"2026-07-27T04:30:27.193000Z","event_type":"price_change","frame_hash":"8c8c628dbb8d884ebb22b46cf925e22cd0b1285436abf85fa40c938f295fb53b","frame_index":0,"kind":"data","monotonic_ns":228612024953541,"payload":{"event_type":"price_change","market":"0xeb66215f2e9faa6449e30a02bab5b8ed7b79a38bf961f6b24d0073c9c2419250","price_changes":[{"asset_id":"69697746896130839564035629862476347944307040470122503199396727085502753297492","best_ask":"0.41","best_bid":"0.4","hash":"8c5e7676a848dfe0a3869de6f24efa8e8a6c0519","price":"0.36","side":"BUY","size":"26.87"},{"asset_id":"60386828328910021732068595344565885737045900010034836345809386672230885527307","best_ask":"0.6","best_bid":"0.59","hash":"1f72abace0899934b95b2b2c308f1bb0ebfaa50d","price":"0.64","side":"SELL","size":"26.87"}],"timestamp":"1785126627193"},"payload_hash":"fad575e58f2e0522382d524713274beb024cd9a705e1a926ff9ffc25740d99cb","raw_frame":"{\"market\":\"0xeb66215f2e9faa6449e30a02bab5b8ed7b79a38bf961f6b24d0073c9c2419250\", \"price_changes\":[{\"asset_id\":\"69697746896130839564035629862476347944307040470122503199396727085502753297492\", \"price\":\"0.36\", \"size\":\"26.87\", \"side\":\"BUY\", \"hash\":\"8c5e7676a848dfe0a3869de6f24efa8e8a6c0519\", \"best_bid\":\"0.4\", \"best_ask\":\"0.41\"}, {\"asset_id\":\"60386828328910021732068595344565885737045900010034836345809386672230885527307\", \"price\":\"0.64\", \"size\":\"26.87\", \"side\":\"SELL\", \"hash\":\"1f72abace0899934b95b2b2c308f1bb0ebfaa50d\", \"best_bid\":\"0.59\", \"best_ask\":\"0.6\"}], \"timestamp\":\"1785126627193\", \"event_type\":\"price_change\"}","received_at":"2026-07-27T04:30:28.755363Z","schema_version":"clob-market-ws.price_change.v1","sequence":null,"server_hash":null,"server_timestamp":"1785126627193","session_id":"e9443c7415a0419799bee9cfbb1a9e4d","source":"clob_market_ws"},"received_at":"2026-07-27T04:30:28.755363Z","record_id":"44ac94c597229addbadba302dfffbe03cd39812081d3b8883862332cf5ef167a","schema_fingerprint":"4aa3821a28b0b7c2400bc59aba4bcc0a76e971dadd19610d3ad38c768e124dc7","schema_version":"edge-lab-recorder.raw.v1","sequence":null,"source":"clob_market_ws"}
{"event_at":"2026-07-27T04:30:27.200000Z","event_fingerprint":"cd350660606a23e6550e62fc23a5b9517fbfa45d3af55830d6bf183226c2efa7","payload":{"connection_id":"0f4979d6978d463e9660b042fdcf555f","event_at":"2026-07-27T04:30:27.200000Z","event_type":"price_change","frame_hash":"f9b109d62ff614dd35fd64b045a65a27825550a029a6f18a40b803e2e3bbea91","frame_index":0,"kind":"data","monotonic_ns":228612034313708,"payload":{"event_type":"price_change","market":"0xeb66215f2e9faa6449e30a02bab5b8ed7b79a38bf961f6b24d0073c9c2419250","price_changes":[{"asset_id":"69697746896130839564035629862476347944307040470122503199396727085502753297492","best_ask":"0.41","best_bid":"0.4","hash":"dac7293e11a955887512cbe6846241f9ab02d2f2","price":"0.38","side":"BUY","size":"13"},{"asset_id":"60386828328910021732068595344565885737045900010034836345809386672230885527307","best_ask":"0.6","best_bid":"0.59","hash":"821a0e1087fa7afb1094fa5681b4d7311f0f2101","price":"0.62","side":"SELL","size":"13"}],"timestamp":"1785126627200"},"payload_hash":"0d1f57bb5729ffcf87c029568b84fc9972043607bc0712afdf261c2fd5ab3139","raw_frame":"{\"market\":\"0xeb66215f2e9faa6449e30a02bab5b8ed7b79a38bf961f6b24d0073c9c2419250\", \"price_changes\":[{\"asset_id\":\"69697746896130839564035629862476347944307040470122503199396727085502753297492\", \"price\":\"0.38\", \"size\":\"13\", \"side\":\"BUY\", \"hash\":\"dac7293e11a955887512cbe6846241f9ab02d2f2\", \"best_bid\":\"0.4\", \"best_ask\":\"0.41\"}, {\"asset_id\":\"60386828328910021732068595344565885737045900010034836345809386672230885527307\", \"price\":\"0.62\", \"size\":\"13\", \"side\":\"SELL\", \"hash\":\"821a0e1087fa7afb1094fa5681b4d7311f0f2101\", \"best_bid\":\"0.59\", \"best_ask\":\"0.6\"}], \"timestamp\":\"1785126627200\", \"event_type\":\"price_change\"}","received_at":"2026-07-27T04:30:28.764722Z","schema_version":"clob-market-ws.price_change.v1","sequence":null,"server_hash":null,"server_timestamp":"1785126627200","session_id":"e9443c7415a0419799bee9cfbb1a9e4d","source":"clob_market_ws"},"received_at":"2026-07-27T04:30:28.764722Z","record_id":"f853660ecec7656e15d07dbd00fd95e0728bfd9e30d72982d5fc5f683795b972","schema_fingerprint":"4aa3821a28b0b7c2400bc59aba4bcc0a76e971dadd19610d3ad38c768e124dc7","schema_version":"edge-lab-recorder.raw.v1","sequence":null,"source":"clob_market_ws"}
{"event_at":"2026-07-27T04:30:27.216000Z","event_fingerprint":"9b6ddc1eeb8fc562faab6eb9fc82b3bba188a5251c5370630eae6ee6b93ba726","payload":{"connection_id":"0f4979d6978d463e9660b042fdcf555f","event_at":"2026-07-27T04:30:27.216000Z","event_type":"price_change","frame_hash":"69803dd7c4a7d0badf64b1f0925d354c0291471f50f242328904e99e83182909","frame_index":0,"kind":"data","monotonic_ns":228612047722583,"payload":{"event_type":"price_change","market":"0xeb66215f2e9faa6449e30a02bab5b8ed7b79a38bf961f6b24d0073c9c2419250","price_changes":[{"asset_id":"69697746896130839564035629862476347944307040470122503199396727085502753297492","best_ask":"0.41","best_bid":"0.4","hash":"a5e1309ecfaf6cb288675cef18df0f668b6f868f","price":"0.3","side":"BUY","size":"269.22"},{"asset_id":"60386828328910021732068595344565885737045900010034836345809386672230885527307","best_ask":"0.6","best_bid":"0.59","hash":"c1dc4b5d485777ec742cb3c32b0c033fe0e04702","price":"0.7","side":"SELL","size":"269.22"}],"timestamp":"1785126627216"},"payload_hash":"045ff30e7c319b34380bc8f5cc2a708732eb2552a39c229c437d76fecd318bbe","raw_frame":"{\"market\":\"0xeb66215f2e9faa6449e30a02bab5b8ed7b79a38bf961f6b24d0073c9c2419250\", \"price_changes\":[{\"asset_id\":\"69697746896130839564035629862476347944307040470122503199396727085502753297492\", \"price\":\"0.3\", \"size\":\"269.22\", \"side\":\"BUY\", \"hash\":\"a5e1309ecfaf6cb288675cef18df0f668b6f868f\", \"best_bid\":\"0.4\", \"best_ask\":\"0.41\"}, {\"asset_id\":\"60386828328910021732068595344565885737045900010034836345809386672230885527307\", \"price\":\"0.7\", \"size\":\"269.22\", \"side\":\"SELL\", \"hash\":\"c1dc4b5d485777ec742cb3c32b0c033fe0e04702\", \"best_bid\":\"0.59\", \"best_ask\":\"0.6\"}], \"timestamp\":\"1785126627216\", \"event_type\":\"price_change\"}","received_at":"2026-07-27T04:30:28.778135Z","schema_version":"clob-market-ws.price_change.v1","sequence":null,"server_hash":null,"server_timestamp":"1785126627216","session_id":"e9443c7415a0419799bee9cfbb1a9e4d","source":"clob_market_ws"},"received_at":"2026-07-27T04:30:28.778135Z","record_id":"20312695298f9209eb6c9086821b9597cf5d1287d163239dfa5640d3c9630601","schema_fingerprint":"4aa3821a28b0b7c2400bc59aba4bcc0a76e971dadd19610d3ad38c768e124dc7","schema_version":"edge-lab-recorder.raw.v1","sequence":null,"source":"clob_market_ws"}
{"event_at":"2026-07-27T04:30:27.257000Z","event_fingerprint":"009acd512b37406b5b95ac82cfc68ca26a8cd55609b88a30968eaae9a1b380f3","payload":{"connection_id":"0f4979d6978d463e9660b042fdcf555f","event_at":"2026-07-27T04:30:27.257000Z","event_type":"price_change","frame_hash":"48160f376e8e10f4ccfa9ebbe49103bbaae31746d19e82cdd9acad523ba4e4c9","frame_index":0,"kind":"data","monotonic_ns":228612058408166,"payload":{"event_type":"price_change","market":"0xeb66215f2e9faa6449e30a02bab5b8ed7b79a38bf961f6b24d0073c9c2419250","price_changes":[{"asset_id":"69697746896130839564035629862476347944307040470122503199396727085502753297492","best_ask":"0.41","best_bid":"0.4","hash":"cedb7bb0e4b3baa918eb938d7bcb37ccf87a2f27","price":"0.28","side":"BUY","size":"123.66"},{"asset_id":"60386828328910021732068595344565885737045900010034836345809386672230885527307","best_ask":"0.6","best_bid":"0.59","hash":"960b76bc9bfa61b2685fbb122e5d3f623d31644d","price":"0.72","side":"SELL","size":"123.66"}],"timestamp":"1785126627257"},"payload_hash":"2257b9e4c80d7cb0a2200d9efbf9f7be337633f2880a0a53b016f9b67802a8f8","raw_frame":"{\"market\":\"0xeb66215f2e9faa6449e30a02bab5b8ed7b79a38bf961f6b24d0073c9c2419250\", \"price_changes\":[{\"asset_id\":\"69697746896130839564035629862476347944307040470122503199396727085502753297492\", \"price\":\"0.28\", \"size\":\"123.66\", \"side\":\"BUY\", \"hash\":\"cedb7bb0e4b3baa918eb938d7bcb37ccf87a2f27\", \"best_bid\":\"0.4\", \"best_ask\":\"0.41\"}, {\"asset_id\":\"60386828328910021732068595344565885737045900010034836345809386672230885527307\", \"price\":\"0.72\", \"size\":\"123.66\", \"side\":\"SELL\", \"hash\":\"960b76bc9bfa61b2685fbb122e5d3f623d31644d\", \"best_bid\":\"0.59\", \"best_ask\":\"0.6\"}], \"timestamp\":\"1785126627257\", \"event_type\":\"price_change\"}","received_at":"2026-07-27T04:30:28.788821Z","schema_version":"clob-market-ws.price_change.v1","sequence":null,"server_hash":null,"server_timestamp":"1785126627257","session_id":"e9443c7415a0419799bee9cfbb1a9e4d","source":"clob_market_ws"},"received_at":"2026-07-27T04:30:28.788821Z","record_id":"3e1c3ac826ad67298d0ec32c69f7fedd1b4cbc1666625b2a076650b9c343f858","schema_fingerprint":"4aa3821a28b0b7c2400bc59aba4bcc0a76e971dadd19610d3ad38c768e124dc7","schema_version":"edge-lab-recorder.raw.v1","sequence":null,"source":"clob_market_ws"}
{"event_at":"2026-07-27T04:30:27.266000Z","event_fingerprint":"0301cf5689c9fa4000df109401ae3fc4097a2d38825233052eca8a6dc359f69f","payload":{"connection_id":"0f4979d6978d463e9660b042fdcf555f","event_at":"2026-07-27T04:30:27.266000Z","event_type":"price_change","frame_hash":"37fb8be22db7493eefedbbf93974fae338760563dc3df3423c27df3bb0981a5a","frame_index":0,"kind":"data","monotonic_ns":228612067250916,"payload":{"event_type":"price_change","market":"0xeb66215f2e9faa6449e30a02bab5b8ed7b79a38bf961f6b24d0073c9c2419250","price_changes":[{"asset_id":"69697746896130839564035629862476347944307040470122503199396727085502753297492","best_ask":"0.41","best_bid":"0.4","hash":"34efff893e500cbc4b204dbbf45103ca4856d844","price":"0.39","side":"BUY","size":"0"},{"asset_id":"60386828328910021732068595344565885737045900010034836345809386672230885527307","best_ask":"0.6","best_bid":"0.59","hash":"451c3599fc3e105b5254291af02a60808d0e9f50","price":"0.61","side":"SELL","size":"0"}],"timestamp":"1785126627266"},"payload_hash":"dca32ed03991616486aae996256750a28f2d94b15a5869ed1a6e7ece658d0883","raw_frame":"{\"market\":\"0xeb66215f2e9faa6449e30a02bab5b8ed7b79a38bf961f6b24d0073c9c2419250\", \"price_changes\":[{\"asset_id\":\"69697746896130839564035629862476347944307040470122503199396727085502753297492\", \"price\":\"0.39\", \"size\":\"0\", \"side\":\"BUY\", \"hash\":\"34efff893e500cbc4b204dbbf45103ca4856d844\", \"best_bid\":\"0.4\", \"best_ask\":\"0.41\"}, {\"asset_id\":\"60386828328910021732068595344565885737045900010034836345809386672230885527307\", \"price\":\"0.61\", \"size\":\"0\", \"side\":\"SELL\", \"hash\":\"451c3599fc3e105b5254291af02a60808d0e9f50\", \"best_bid\":\"0.59\", \"best_ask\":\"0.6\"}], \"timestamp\":\"1785126627266\", \"event_type\":\"price_change\"}","received_at":"2026-07-27T04:30:28.797663Z","schema_version":"clob-market-ws.price_change.v1","sequence":null,"server_hash":null,"server_timestamp":"1785126627266","session_id":"e9443c7415a0419799bee9cfbb1a9e4d","source":"clob_market_ws"},"received_at":"2026-07-27T04:30:28.797663Z","record_id":"5647c0a98ec9aa2676c17f2b3bceb6bb7957712cfd906c2f346afb6a171ca99f","schema_fingerprint":"4aa3821a28b0b7c2400bc59aba4bcc0a76e971dadd19610d3ad38c768e124dc7","schema_version":"edge-lab-recorder.raw.v1","sequence":null,"source":"clob_market_ws"}
{"event_at":"2026-07-27T04:30:27.281000Z","event_fingerprint":"9c5e55322463351096c1e7bd99e52a707658c2004e7870c536cc36ec5b1f4002","payload":{"connection_id":"0f4979d6978d463e9660b042fdcf555f","event_at":"2026-07-27T04:30:27.281000Z","event_type":"price_change","frame_hash":"1ab229e5c0469fa188e56a135e078bded8baa78cf7962a5d1d6b59c52489ba4b","frame_index":0,"kind":"data","monotonic_ns":228612086478416,"payload":{"event_type":"price_change","market":"0xeb66215f2e9faa6449e30a02bab5b8ed7b79a38bf961f6b24d0073c9c2419250","price_changes":[{"asset_id":"60386828328910021732068595344565885737045900010034836345809386672230885527307","best_ask":"0.6","best_bid":"0.59","hash":"0abed9a76bf98fe2d9c703f3db6c5ff0897e37aa","price":"0.47","side":"BUY","size":"152.84"},{"asset_id":"69697746896130839564035629862476347944307040470122503199396727085502753297492","best_ask":"0.41","best_bid":"0.4","hash":"a5226d766d3d544cd00f9c39d9f99860d269365f","price":"0.53","side":"SELL","size":"152.84"}],"timestamp":"1785126627281"},"payload_hash":"eb6d7a468d69a3a6f87c3b7fdbbd1e80c9d482ee6634523a0e37f28091d1b04a","raw_frame":"{\"market\":\"0xeb66215f2e9faa6449e30a02bab5b8ed7b79a38bf961f6b24d0073c9c2419250\", \"price_changes\":[{\"asset_id\":\"60386828328910021732068595344565885737045900010034836345809386672230885527307\", \"price\":\"0.47\", \"size\":\"152.84\", \"side\":\"BUY\", \"hash\":\"0abed9a76bf98fe2d9c703f3db6c5ff0897e37aa\", \"best_bid\":\"0.59\", \"best_ask\":\"0.6\"}, {\"asset_id\":\"69697746896130839564035629862476347944307040470122503199396727085502753297492\", \"price\":\"0.53\", \"size\":\"152.84\", \"side\":\"SELL\", \"hash\":\"a5226d766d3d544cd00f9c39d9f99860d269365f\", \"best_bid\":\"0.4\", \"best_ask\":\"0.41\"}], \"timestamp\":\"1785126627281\", \"event_type\":\"price_change\"}","received_at":"2026-07-27T04:30:28.816891Z","schema_version":"clob-market-ws.price_change.v1","sequence":null,"server_hash":null,"server_timestamp":"1785126627281","session_id":"e9443c7415a0419799bee9cfbb1a9e4d","source":"clob_market_ws"},"received_at":"2026-07-27T04:30:28.816891Z","record_id":"97906d7b42dc922eb35d991b3b24552aa7022889608c930a58035af49f118af2","schema_fingerprint":"4aa3821a28b0b7c2400bc59aba4bcc0a76e971dadd19610d3ad38c768e124dc7","schema_version":"edge-lab-recorder.raw.v1","sequence":null,"source":"clob_market_ws"}
{"event_at":"2026-07-27T04:30:27.292000Z","event_fingerprint":"f3cc1816cabb3aeb79e0a814b8133f909847e79aa98f479021ac8fd6b077c906","payload":{"connection_id":"0f4979d6978d463e9660b042fdcf555f","event_at":"2026-07-27T04:30:27.292000Z","event_type":"price_change","frame_hash":"5776a592734b219c5e8f2fa0cefc18201b3fd0c1d5633addd7d703bfc337a4c7","frame_index":0,"kind":"data","monotonic_ns":228612098055583,"payload":{"event_type":"price_change","market":"0xeb66215f2e9faa6449e30a02bab5b8ed7b79a38bf961f6b24d0073c9c2419250","price_changes":[{"asset_id":"60386828328910021732068595344565885737045900010034836345809386672230885527307","best_ask":"0.6","best_bid":"0.59","hash":"6dcfd8dbd2aba1f8275d29686b2cbc7fc04b581f","price":"0.54","side":"BUY","size":"326.64"},{"asset_id":"69697746896130839564035629862476347944307040470122503199396727085502753297492","best_ask":"0.41","best_bid":"0.4","hash":"c69e60f19af87562a1c786e5f49fd1d43c811ba3","price":"0.46","side":"SELL","size":"326.64"}],"timestamp":"1785126627292"},"payload_hash":"f0decdb6a44240a307280c383496551b2f4d1b39e2d7cf16efc30aaac5d9fe86","raw_frame":"{\"market\":\"0xeb66215f2e9faa6449e30a02bab5b8ed7b79a38bf961f6b24d0073c9c2419250\", \"price_changes\":[{\"asset_id\":\"60386828328910021732068595344565885737045900010034836345809386672230885527307\", \"price\":\"0.54\", \"size\":\"326.64\", \"side\":\"BUY\", \"hash\":\"6dcfd8dbd2aba1f8275d29686b2cbc7fc04b581f\", \"best_bid\":\"0.59\", \"best_ask\":\"0.6\"}, {\"asset_id\":\"69697746896130839564035629862476347944307040470122503199396727085502753297492\", \"price\":\"0.46\", \"size\":\"326.64\", \"side\":\"SELL\", \"hash\":\"c69e60f19af87562a1c786e5f49fd1d43c811ba3\", \"best_bid\":\"0.4\", \"best_ask\":\"0.41\"}], \"timestamp\":\"1785126627292\", \"event_type\":\"price_change\"}","received_at":"2026-07-27T04:30:28.828469Z","schema_version":"clob-market-ws.price_change.v1","sequence":null,"server_hash":null,"server_timestamp":"1785126627292","session_id":"e9443c7415a0419799bee9cfbb1a9e4d","source":"clob_market_ws"},"received_at":"2026-07-27T04:30:28.828469Z","record_id":"bca8e076481d106d931be853a794c02be73e5a4d746d0953f0de5f2bd66d6834","schema_fingerprint":"4aa3821a28b0b7c2400bc59aba4bcc0a76e971dadd19610d3ad38c768e124dc7","schema_version":"edge-lab-recorder.raw.v1","sequence":null,"source":"clob_market_ws"}
{"event_at":"2026-07-27T04:30:27.296000Z","event_fingerprint":"e056620b24f94db3d4c1dd24eb45797579e8e91efce21becd7807dbd2ba0aa2c","payload":{"connection_id":"0f4979d6978d463e9660b042fdcf555f","event_at":"2026-07-27T04:30:27.296000Z","event_type":"price_change","frame_hash":"f2e90141bbb5fad38790b6a81c44711a895962a75de6c464198fe2def5e7e965","frame_index":0,"kind":"data","monotonic_ns":228612108977875,"payload":{"event_type":"price_change","market":"0xeb66215f2e9faa6449e30a02bab5b8ed7b79a38bf961f6b24d0073c9c2419250","price_changes":[{"asset_id":"60386828328910021732068595344565885737045900010034836345809386672230885527307","best_ask":"0.6","best_bid":"0.59","hash":"3c1841ab7d9f23ca0e08c99fbb7472b85dd1469e","price":"0.58","side":"BUY","size":"44.01"},{"asset_id":"69697746896130839564035629862476347944307040470122503199396727085502753297492","best_ask":"0.41","best_bid":"0.4","hash":"1036053f09b85efcc6b38332ba5ba3008a52b5da","price":"0.42","side":"SELL","size":"44.01"}],"timestamp":"1785126627296"},"payload_hash":"f0a868cb9c2959441da34e03b7a8cfeab3b94ae77a24d8d1865aa0f07ecff8e1","raw_frame":"{\"market\":\"0xeb66215f2e9faa6449e30a02bab5b8ed7b79a38bf961f6b24d0073c9c2419250\", \"price_changes\":[{\"asset_id\":\"60386828328910021732068595344565885737045900010034836345809386672230885527307\", \"price\":\"0.58\", \"size\":\"44.01\", \"side\":\"BUY\", \"hash\":\"3c1841ab7d9f23ca0e08c99fbb7472b85dd1469e\", \"best_bid\":\"0.59\", \"best_ask\":\"0.6\"}, {\"asset_id\":\"69697746896130839564035629862476347944307040470122503199396727085502753297492\", \"price\":\"0.42\", \"size\":\"44.01\", \"side\":\"SELL\", \"hash\":\"1036053f09b85efcc6b38332ba5ba3008a52b5da\", \"best_bid\":\"0.4\", \"best_ask\":\"0.41\"}], \"timestamp\":\"1785126627296\", \"event_type\":\"price_change\"}","received_at":"2026-07-27T04:30:28.839391Z","schema_version":"clob-market-ws.price_change.v1","sequence":null,"server_hash":null,"server_timestamp":"1785126627296","session_id":"e9443c7415a0419799bee9cfbb1a9e4d","source":"clob_market_ws"},"received_at":"2026-07-27T04:30:28.839391Z","record_id":"eab72802d62078efe09ed5f393d71749fa561ab5e1abbce765a4474973d06931","schema_fingerprint":"4aa3821a28b0b7c2400bc59aba4bcc0a76e971dadd19610d3ad38c768e124dc7","schema_version":"edge-lab-recorder.raw.v1","sequence":null,"source":"clob_market_ws"}
{"event_at":"2026-07-27T04:30:27.358000Z","event_fingerprint":"8023e27e90fe10d0a9d42bceb76f57a0a6ed135b9315826f7299eadfe070862f","payload":{"connection_id":"0f4979d6978d463e9660b042fdcf555f","event_at":"2026-07-27T04:30:27.358000Z","event_type":"price_change","frame_hash":"3fee0a5efdce1576adec46787a4b6495c37ce4e23e2ff52b8fcbcc6e4ed63ffa","frame_index":0,"kind":"data","monotonic_ns":228612113795583,"payload":{"event_type":"price_change","market":"0xeb66215f2e9faa6449e30a02bab5b8ed7b79a38bf961f6b24d0073c9c2419250","price_changes":[{"asset_id":"60386828328910021732068595344565885737045900010034836345809386672230885527307","best_ask":"0.6","best_bid":"0.59","hash":"fc7e562507426107b4d40f5d59a10922420584b7","price":"0.47","side":"BUY","size":"81.92"},{"asset_id":"69697746896130839564035629862476347944307040470122503199396727085502753297492","best_ask":"0.41","best_bid":"0.4","hash":"b0931480ac7c6b5e8dc26734110603605ac9b16c","price":"0.53","side":"SELL","size":"81.92"}],"timestamp":"1785126627358"},"payload_hash":"10bd651c003304a7926616565f4b10f98dbba208375e66161c74a2db8cc5f69d","raw_frame":"{\"market\":\"0xeb66215f2e9faa6449e30a02bab5b8ed7b79a38bf961f6b24d0073c9c2419250\", \"price_changes\":[{\"asset_id\":\"60386828328910021732068595344565885737045900010034836345809386672230885527307\", \"price\":\"0.47\", \"size\":\"81.92\", \"side\":\"BUY\", \"hash\":\"fc7e562507426107b4d40f5d59a10922420584b7\", \"best_bid\":\"0.59\", \"best_ask\":\"0.6\"}, {\"asset_id\":\"69697746896130839564035629862476347944307040470122503199396727085502753297492\", \"price\":\"0.53\", \"size\":\"81.92\", \"side\":\"SELL\", \"hash\":\"b0931480ac7c6b5e8dc26734110603605ac9b16c\", \"best_bid\":\"0.4\", \"best_ask\":\"0.41\"}], \"timestamp\":\"1785126627358\", \"event_type\":\"price_change\"}","received_at":"2026-07-27T04:30:28.844211Z","schema_version":"clob-market-ws.price_change.v1","sequence":null,"server_hash":null,"server_timestamp":"1785126627358","session_id":"e9443c7415a0419799bee9cfbb1a9e4d","source":"clob_market_ws"},"received_at":"2026-07-27T04:30:28.844211Z","record_id":"ddc077ad7a4f62f2f9de1300fa9790f86565d3907bbb01637ea3b440c2fdf655","schema_fingerprint":"4aa3821a28b0b7c2400bc59aba4bcc0a76e971dadd19610d3ad38c768e124dc7","schema_version":"edge-lab-recorder.raw.v1","sequence":null,"source":"clob_market_ws"}
{"event_at":"2026-07-27T04:30:27.362000Z","event_fingerprint":"1c6846d51bb4fc388224cc635eb07093bff7cf9a2d5145c771a3e6a7544e64f9","payload":{"connection_id":"0f4979d6978d463e9660b042fdcf555f","event_at":"2026-07-27T04:30:27.362000Z","event_type":"price_change","frame_hash":"f96f7dfd92dff64ad1c4ee810d127b4e187d13aaa36715af55a47cc32cfdb039","frame_index":0,"kind":"data","monotonic_ns":228612124409875,"payload":{"event_type":"price_change","market":"0xeb66215f2e9faa6449e30a02bab5b8ed7b79a38bf961f6b24d0073c9c2419250","price_changes":[{"asset_id":"60386828328910021732068595344565885737045900010034836345809386672230885527307","best_ask":"0.6","best_bid":"0.59","hash":"e45dd5121627a07954270184b436bcbe59f57f37","price":"0.54","side":"BUY","size":"296.64"},{"asset_id":"69697746896130839564035629862476347944307040470122503199396727085502753297492","best_ask":"0.41","best_bid":"0.4","hash":"06df0d7b881333c58b3072ae0dc08bcd27d890be","price":"0.46","side":"SELL","size":"296.64"}],"timestamp":"1785126627362"},"payload_hash":"ea0584c15a7724d5eee83f954d8e584be6c93706621ff9a7dd8443f36661b84d","raw_frame":"{\"market\":\"0xeb66215f2e9faa6449e30a02bab5b8ed7b79a38bf961f6b24d0073c9c2419250\", \"price_changes\":[{\"asset_id\":\"60386828328910021732068595344565885737045900010034836345809386672230885527307\", \"price\":\"0.54\", \"size\":\"296.64\", \"side\":\"BUY\", \"hash\":\"e45dd5121627a07954270184b436bcbe59f57f37\", \"best_bid\":\"0.59\", \"best_ask\":\"0.6\"}, {\"asset_id\":\"69697746896130839564035629862476347944307040470122503199396727085502753297492\", \"price\":\"0.46\", \"size\":\"296.64\", \"side\":\"SELL\", \"hash\":\"06df0d7b881333c58b3072ae0dc08bcd27d890be\", \"best_bid\":\"0.4\", \"best_ask\":\"0.41\"}], \"timestamp\":\"1785126627362\", \"event_type\":\"price_change\"}","received_at":"2026-07-27T04:30:28.854822Z","schema_version":"clob-market-ws.price_change.v1","sequence":null,"server_hash":null,"server_timestamp":"1785126627362","session_id":"e9443c7415a0419799bee9cfbb1a9e4d","source":"clob_market_ws"},"received_at":"2026-07-27T04:30:28.854822Z","record_id":"dfca5c97d3441f0d8d4b2567eabf8ec3172a45bb4002bcacfd6452f4cb819278","schema_fingerprint":"4aa3821a28b0b7c2400bc59aba4bcc0a76e971dadd19610d3ad38c768e124dc7","schema_version":"edge-lab-recorder.raw.v1","sequence":null,"source":"clob_market_ws"}
{"event_at":"2026-07-27T04:30:27.420000Z","event_fingerprint":"2749f98bfa581bf62c8165002adcc945c291e6db8272c43f77e8246975008644","payload":{"connection_id":"0f4979d6978d463e9660b042fdcf555f","event_at":"2026-07-27T04:30:27.420000Z","event_type":"price_change","frame_hash":"84cd396da880fccc7ed604783a308a3cda0e6342ab17ab23100da4c288acad81","frame_index":0,"kind":"data","monotonic_ns":228612127684416,"payload":{"event_type":"price_change","market":"0xeb66215f2e9faa6449e30a02bab5b8ed7b79a38bf961f6b24d0073c9c2419250","price_changes":[{"asset_id":"60386828328910021732068595344565885737045900010034836345809386672230885527307","best_ask":"0.6","best_bid":"0.59","hash":"7c132d6f58a83a9860410fc316b0e6ed033322a4","price":"0.57","side":"BUY","size":"68.57"},{"asset_id":"69697746896130839564035629862476347944307040470122503199396727085502753297492","best_ask":"0.41","best_bid":"0.4","hash":"450a94cfa707c8d1bd57be4fb4abfde6ab0df2e3","price":"0.43","side":"SELL","size":"68.57"}],"timestamp":"1785126627420"},"payload_hash":"305b8d748837926b7e53763902b757a69c5ee2fde2a8e596bbdcaa9ba39ebb8f","raw_frame":"{\"market\":\"0xeb66215f2e9faa6449e30a02bab5b8ed7b79a38bf961f6b24d0073c9c2419250\", \"price_changes\":[{\"asset_id\":\"60386828328910021732068595344565885737045900010034836345809386672230885527307\", \"price\":\"0.57\", \"size\":\"68.57\", \"side\":\"BUY\", \"hash\":\"7c132d6f58a83a9860410fc316b0e6ed033322a4\", \"best_bid\":\"0.59\", \"best_ask\":\"0.6\"}, {\"asset_id\":\"69697746896130839564035629862476347944307040470122503199396727085502753297492\", \"price\":\"0.43\", \"size\":\"68.57\", \"side\":\"SELL\", \"hash\":\"450a94cfa707c8d1bd57be4fb4abfde6ab0df2e3\", \"best_bid\":\"0.4\", \"best_ask\":\"0.41\"}], \"timestamp\":\"1785126627420\", \"event_type\":\"price_change\"}","received_at":"2026-07-27T04:30:28.858098Z","schema_version":"clob-market-ws.price_change.v1","sequence":null,"server_hash":null,"server_timestamp":"1785126627420","session_id":"e9443c7415a0419799bee9cfbb1a9e4d","source":"clob_market_ws"},"received_at":"2026-07-27T04:30:28.858098Z","record_id":"e265bb8f82cc0760fb98cbb32edc55b729057253343aaa882bebb522e5b3a8d4","schema_fingerprint":"4aa3821a28b0b7c2400bc59aba4bcc0a76e971dadd19610d3ad38c768e124dc7","schema_version":"edge-lab-recorder.raw.v1","sequence":null,"source":"clob_market_ws"}
{"event_at":"2026-07-27T04:30:27.476000Z","event_fingerprint":"ca96f04baa74e36370f958a1f5ab6f90cfd154ca386e91c5f40f14689fe4fb3b","payload":{"connection_id":"0f4979d6978d463e9660b042fdcf555f","event_at":"2026-07-27T04:30:27.476000Z","event_type":"price_change","frame_hash":"cfca954c61f78e1372debcfa0eeb640b6167f5a50ddbc4c1d50757a96bc93ba8","frame_index":0,"kind":"data","monotonic_ns":228612134896500,"payload":{"event_type":"price_change","market":"0xeb66215f2e9faa6449e30a02bab5b8ed7b79a38bf961f6b24d0073c9c2419250","price_changes":[{"asset_id":"69697746896130839564035629862476347944307040470122503199396727085502753297492","best_ask":"0.41","best_bid":"0.4","hash":"4be2a3be81a23e6c382856d32d0edb6c25431a16","price":"0.21","side":"BUY","size":"8"},{"asset_id":"60386828328910021732068595344565885737045900010034836345809386672230885527307","best_ask":"0.6","best_bid":"0.59","hash":"6505d4d2cd1e1415f050774429a3137dae382a43","price":"0.79","side":"SELL","size":"8"}],"timestamp":"1785126627476"},"payload_hash":"9a1b9fb1444c1a3e1deeb2a6df032bfcca7dd1cd45caa8d29f99a669b185a63a","raw_frame":"{\"market\":\"0xeb66215f2e9faa6449e30a02bab5b8ed7b79a38bf961f6b24d0073c9c2419250\", \"price_changes\":[{\"asset_id\":\"69697746896130839564035629862476347944307040470122503199396727085502753297492\", \"price\":\"0.21\", \"size\":\"8\", \"side\":\"BUY\", \"hash\":\"4be2a3be81a23e6c382856d32d0edb6c25431a16\", \"best_bid\":\"0.4\", \"best_ask\":\"0.41\"}, {\"asset_id\":\"60386828328910021732068595344565885737045900010034836345809386672230885527307\", \"price\":\"0.79\", \"size\":\"8\", \"side\":\"SELL\", \"hash\":\"6505d4d2cd1e1415f050774429a3137dae382a43\", \"best_bid\":\"0.59\", \"best_ask\":\"0.6\"}], \"timestamp\":\"1785126627476\", \"event_type\":\"price_change\"}","received_at":"2026-07-27T04:30:28.865300Z","schema_version":"clob-market-ws.price_change.v1","sequence":null,"server_hash":null,"server_timestamp":"1785126627476","session_id":"e9443c7415a0419799bee9cfbb1a9e4d","source":"clob_market_ws"},"received_at":"2026-07-27T04:30:28.865300Z","record_id":"7eed3891c259f176deeb9270ab7530676fa548487a077037bbeb6ad7d85ba235","schema_fingerprint":"4aa3821a28b0b7c2400bc59aba4bcc0a76e971dadd19610d3ad38c768e124dc7","schema_version":"edge-lab-recorder.raw.v1","sequence":null,"source":"clob_market_ws"}
{"event_at":"2026-07-27T04:30:27.476000Z","event_fingerprint":"465159874d66b084c5fde40dffa444b077a1f97b9836594cae1a1219eaa4c30b","payload":{"connection_id":"0f4979d6978d463e9660b042fdcf555f","event_at":"2026-07-27T04:30:27.476000Z","event_type":"price_change","frame_hash":"7bf3ff06d558787c63bffcaecc93f6311dab6e6bdd90a490a907a32071f29763","frame_index":0,"kind":"data","monotonic_ns":228612158940375,"payload":{"event_type":"price_change","market":"0xeb66215f2e9faa6449e30a02bab5b8ed7b79a38bf961f6b24d0073c9c2419250","price_changes":[{"asset_id":"60386828328910021732068595344565885737045900010034836345809386672230885527307","best_ask":"0.6","best_bid":"0.59","hash":"55d01f01a8b9f7c7d0b571cdd4ffd94190757c2e","price":"0.47","side":"BUY","size":"11"},{"asset_id":"69697746896130839564035629862476347944307040470122503199396727085502753297492","best_ask":"0.41","best_bid":"0.4","hash":"dae39d80cdf7af37fa27fb7aca2a6f42bf4261e5","price":"0.53","side":"SELL","size":"11"}],"timestamp":"1785126627476"},"payload_hash":"631cd70aa1e7f0d6417e23b52138addf0d81c90b627655e63355344d6c710690","raw_frame":"{\"market\":\"0xeb66215f2e9faa6449e30a02bab5b8ed7b79a38bf961f6b24d0073c9c2419250\", \"price_changes\":[{\"asset_id\":\"60386828328910021732068595344565885737045900010034836345809386672230885527307\", \"price\":\"0.47\", \"size\":\"11\", \"side\":\"BUY\", \"hash\":\"55d01f01a8b9f7c7d0b571cdd4ffd94190757c2e\", \"best_bid\":\"0.59\", \"best_ask\":\"0.6\"}, {\"asset_id\":\"69697746896130839564035629862476347944307040470122503199396727085502753297492\", \"price\":\"0.53\", \"size\":\"11\", \"side\":\"SELL\", \"hash\":\"dae39d80cdf7af37fa27fb7aca2a6f42bf4261e5\", \"best_bid\":\"0.4\", \"best_ask\":\"0.41\"}], \"timestamp\":\"1785126627476\", \"event_type\":\"price_change\"}","received_at":"2026-07-27T04:30:28.889354Z","schema_version":"clob-market-ws.price_change.v1","sequence":null,"server_hash":null,"server_timestamp":"1785126627476","session_id":"e9443c7415a0419799bee9cfbb1a9e4d","source":"clob_market_ws"},"received_at":"2026-07-27T04:30:28.889354Z","record_id":"e9f09b5e532a610b1d3c0969170c754990604bda6a409765d0c2b2f1f041045d","schema_fingerprint":"4aa3821a28b0b7c2400bc59aba4bcc0a76e971dadd19610d3ad38c768e124dc7","schema_version":"edge-lab-recorder.raw.v1","sequence":null,"source":"clob_market_ws"}
{"event_at":"2026-07-27T04:30:27.476000Z","event_fingerprint":"cb26f65202f42d156322bfbc4b7776ae4f0cf00f72dc5fba7a3ab0baaa5f9132","payload":{"connection_id":"0f4979d6978d463e9660b042fdcf555f","event_at":"2026-07-27T04:30:27.476000Z","event_type":"price_change","frame_hash":"ffce567a028c931bc90570b4d9d43ea4f705e66da9ce0fc845be074ae4dad8b0","frame_index":0,"kind":"data","monotonic_ns":228612165026416,"payload":{"event_type":"price_change","market":"0xeb66215f2e9faa6449e30a02bab5b8ed7b79a38bf961f6b24d0073c9c2419250","price_changes":[{"asset_id":"60386828328910021732068595344565885737045900010034836345809386672230885527307","best_ask":"0.6","best_bid":"0.59","hash":"06b5ecf7232f71bef4d43d6f0649f66cb26ca410","price":"0.5","side":"BUY","size":"240"},{"asset_id":"69697746896130839564035629862476347944307040470122503199396727085502753297492","best_ask":"0.41","best_bid":"0.4","hash":"08df3f993646a719dfbb9c0ad1602380b6a71ed6","price":"0.5","side":"SELL","size":"240"}],"timestamp":"1785126627476"},"payload_hash":"50df7832d94747344670f2f4b620abc89ca3779ea24f5faf9e946ef85346f34c","raw_frame":"{\"market\":\"0xeb66215f2e9faa6449e30a02bab5b8ed7b79a38bf961f6b24d0073c9c2419250\", \"price_changes\":[{\"asset_id\":\"60386828328910021732068595344565885737045900010034836345809386672230885527307\", \"price\":\"0.5\", \"size\":\"240\", \"side\":\"BUY\", \"hash\":\"06b5ecf7232f71bef4d43d6f0649f66cb26ca410\", \"best_bid\":\"0.59\", \"best_ask\":\"0.6\"}, {\"asset_id\":\"69697746896130839564035629862476347944307040470122503199396727085502753297492\", \"price\":\"0.5\", \"size\":\"240\", \"side\":\"SELL\", \"hash\":\"08df3f993646a719dfbb9c0ad1602380b6a71ed6\", \"best_bid\":\"0.4\", \"best_ask\":\"0.41\"}], \"timestamp\":\"1785126627476\", \"event_type\":\"price_change\"}","received_at":"2026-07-27T04:30:28.895440Z","schema_version":"clob-market-ws.price_change.v1","sequence":null,"server_hash":null,"server_timestamp":"1785126627476","session_id":"e9443c7415a0419799bee9cfbb1a9e4d","source":"clob_market_ws"},"received_at":"2026-07-27T04:30:28.895440Z","record_id":"8f24ad7b9ae5ad77da36149dd41eaa7b25952931b47d3fed035f94943020cd04","schema_fingerprint":"4aa3821a28b0b7c2400bc59aba4bcc0a76e971dadd19610d3ad38c768e124dc7","schema_version":"edge-lab-recorder.raw.v1","sequence":null,"source":"clob_market_ws"}
{"event_at":"2026-07-27T04:30:27.476000Z","event_fingerprint":"48285cccdcd205dd78f3ea987038d4ea9eb4377e37bbad963a7049e99763b570","payload":{"connection_id":"0f4979d6978d463e9660b042fdcf555f","event_at":"2026-07-27T04:30:27.476000Z","event_type":"price_change","frame_hash":"1e6186c242540677e2f7b69f5e56be58ffbeabb3573cca6e0ec63816bfe7e5c2","frame_index":0,"kind":"data","monotonic_ns":228612173509166,"payload":{"event_type":"price_change","market":"0xeb66215f2e9faa6449e30a02bab5b8ed7b79a38bf961f6b24d0073c9c2419250","price_changes":[{"asset_id":"69697746896130839564035629862476347944307040470122503199396727085502753297492","best_ask":"0.41","best_bid":"0.4","hash":"bd32cce5054a6edfef6066d77845c7dab465b936","price":"0.3","side":"BUY","size":"158.11"},{"asset_id":"60386828328910021732068595344565885737045900010034836345809386672230885527307","best_ask":"0.6","best_bid":"0.59","hash":"f0c5105d7eb0fb9fb15ef7eef504ec33828da89c","price":"0.7","side":"SELL","size":"158.11"}],"timestamp":"1785126627476"},"payload_hash":"364756c66167f0bda9812093fbcc90d77419350d457f586baac9f621c6f8f010","raw_frame":"{\"market\":\"0xeb66215f2e9faa6449e30a02bab5b8ed7b79a38bf961f6b24d0073c9c2419250\", \"price_changes\":[{\"asset_id\":\"69697746896130839564035629862476347944307040470122503199396727085502753297492\", \"price\":\"0.3\", \"size\":\"158.11\", \"side\":\"BUY\", \"hash\":\"bd32cce5054a6edfef6066d77845c7dab465b936\", \"best_bid\":\"0.4\", \"best_ask\":\"0.41\"}, {\"asset_id\":\"60386828328910021732068595344565885737045900010034836345809386672230885527307\", \"price\":\"0.7\", \"size\":\"158.11\", \"side\":\"SELL\", \"hash\":\"f0c5105d7eb0fb9fb15ef7eef504ec33828da89c\", \"best_bid\":\"0.59\", \"best_ask\":\"0.6\"}], \"timestamp\":\"1785126627476\", \"event_type\":\"price_change\"}","received_at":"2026-07-27T04:30:28.903921Z","schema_version":"clob-market-ws.price_change.v1","sequence":null,"server_hash":null,"server_timestamp":"1785126627476","session_id":"e9443c7415a0419799bee9cfbb1a9e4d","source":"clob_market_ws"},"received_at":"2026-07-27T04:30:28.903921Z","record_id":"3eb3075aa42ea6490c42d0424a620b72be8480395c793d8036ebcd2751ea79d4","schema_fingerprint":"4aa3821a28b0b7c2400bc59aba4bcc0a76e971dadd19610d3ad38c768e124dc7","schema_version":"edge-lab-recorder.raw.v1","sequence":null,"source":"clob_market_ws"}
{"event_at":"2026-07-27T04:30:27.476000Z","event_fingerprint":"6044d7903bd96bc30188cb682aedf38da8258c92355cba711febeb58f0558ede","payload":{"connection_id":"0f4979d6978d463e9660b042fdcf555f","event_at":"2026-07-27T04:30:27.476000Z","event_type":"price_change","frame_hash":"1344292d7c7e216c294d36cae93f575f0ef358344a0ad4abbb82f111cf4399c1","frame_index":0,"kind":"data","monotonic_ns":228612187910833,"payload":{"event_type":"price_change","market":"0xeb66215f2e9faa6449e30a02bab5b8ed7b79a38bf961f6b24d0073c9c2419250","price_changes":[{"asset_id":"60386828328910021732068595344565885737045900010034836345809386672230885527307","best_ask":"0.6","best_bid":"0.59","hash":"043289792f137ed3d588138be579858597d4382b","price":"0.5","side":"BUY","size":"210"},{"asset_id":"69697746896130839564035629862476347944307040470122503199396727085502753297492","best_ask":"0.41","best_bid":"0.4","hash":"1d15b6d99d3cbff31bcb86aff60eedad138a195c","price":"0.5","side":"SELL","size":"210"}],"timestamp":"1785126627476"},"payload_hash":"2e2613a260451d81750a6ddbd17ffecd37d08b50c131411fb55c9a3d810ed104","raw_frame":"{\"market\":\"0xeb66215f2e9faa6449e30a02bab5b8ed7b79a38bf961f6b24d0073c9c2419250\", \"price_changes\":[{\"asset_id\":\"60386828328910021732068595344565885737045900010034836345809386672230885527307\", \"price\":\"0.5\", \"size\":\"210\", \"side\":\"BUY\", \"hash\":\"043289792f137ed3d588138be579858597d4382b\", \"best_bid\":\"0.59\", \"best_ask\":\"0.6\"}, {\"asset_id\":\"69697746896130839564035629862476347944307040470122503199396727085502753297492\", \"price\":\"0.5\", \"size\":\"210\", \"side\":\"SELL\", \"hash\":\"1d15b6d99d3cbff31bcb86aff60eedad138a195c\", \"best_bid\":\"0.4\", \"best_ask\":\"0.41\"}], \"timestamp\":\"1785126627476\", \"event_type\":\"price_change\"}","received_at":"2026-07-27T04:30:28.918322Z","schema_version":"clob-market-ws.price_change.v1","sequence":null,"server_hash":null,"server_timestamp":"1785126627476","session_id":"e9443c7415a0419799bee9cfbb1a9e4d","source":"clob_market_ws"},"received_at":"2026-07-27T04:30:28.918322Z","record_id":"75b00537799b141a19bd5cd2d4c0c8cfb8e5f08324157f8934725dfd23efe27f","schema_fingerprint":"4aa3821a28b0b7c2400bc59aba4bcc0a76e971dadd19610d3ad38c768e124dc7","schema_version":"edge-lab-recorder.raw.v1","sequence":null,"source":"clob_market_ws"}
{"event_at":"2026-07-27T04:30:27.477000Z","event_fingerprint":"ce9819e137898e1cf492b3f8243851ca20f72ece8782bfdebb264002f9e07008","payload":{"connection_id":"0f4979d6978d463e9660b042fdcf555f","event_at":"2026-07-27T04:30:27.477000Z","event_type":"price_change","frame_hash":"6a7c26fbe4c702fc9da85f0a7709a5fdc8546a453c95dab29a52596f563c821a","frame_index":0,"kind":"data","monotonic_ns":228612197689250,"payload":{"event_type":"price_change","market":"0xeb66215f2e9faa6449e30a02bab5b8ed7b79a38bf961f6b24d0073c9c2419250","price_changes":[{"asset_id":"69697746896130839564035629862476347944307040470122503199396727085502753297492","best_ask":"0.41","best_bid":"0.4","hash":"35c7fb98f58f8145dedaacf010ab00a4cde45589","price":"0.31","side":"BUY","size":"52"},{"asset_id":"60386828328910021732068595344565885737045900010034836345809386672230885527307","best_ask":"0.6","best_bid":"0.59","hash":"3e28f1672795bbfc9d5ad12f2c3ac825a1ca0526","price":"0.69","side":"SELL","size":"52"}],"timestamp":"1785126627477"},"payload_hash":"6414dfc56d1e962b3dea8bfd1a5e50c1fbbe06ebd4b65ce1232b853b295c6dd4","raw_frame":"{\"market\":\"0xeb66215f2e9faa6449e30a02bab5b8ed7b79a38bf961f6b24d0073c9c2419250\", \"price_changes\":[{\"asset_id\":\"69697746896130839564035629862476347944307040470122503199396727085502753297492\", \"price\":\"0.31\", \"size\":\"52\", \"side\":\"BUY\", \"hash\":\"35c7fb98f58f8145dedaacf010ab00a4cde45589\", \"best_bid\":\"0.4\", \"best_ask\":\"0.41\"}, {\"asset_id\":\"60386828328910021732068595344565885737045900010034836345809386672230885527307\", \"price\":\"0.69\", \"size\":\"52\", \"side\":\"SELL\", \"hash\":\"3e28f1672795bbfc9d5ad12f2c3ac825a1ca0526\", \"best_bid\":\"0.59\", \"best_ask\":\"0.6\"}], \"timestamp\":\"1785126627477\", \"event_type\":\"price_change\"}","received_at":"2026-07-27T04:30:28.928102Z","schema_version":"clob-market-ws.price_change.v1","sequence":null,"server_hash":null,"server_timestamp":"1785126627477","session_id":"e9443c7415a0419799bee9cfbb1a9e4d","source":"clob_market_ws"},"received_at":"2026-07-27T04:30:28.928102Z","record_id":"4342b4db52f2d6ae2da15f8486508308a829795bd0ef57cb36e18e8556f2e32e","schema_fingerprint":"4aa3821a28b0b7c2400bc59aba4bcc0a76e971dadd19610d3ad38c768e124dc7","schema_version":"edge-lab-recorder.raw.v1","sequence":null,"source":"clob_market_ws"}
{"event_at":"2026-07-27T04:30:27.477000Z","event_fingerprint":"8de894fe5af40518f8677a77b297be435355e0bbad3156947883b89eaf120c67","payload":{"connection_id":"0f4979d6978d463e9660b042fdcf555f","event_at":"2026-07-27T04:30:27.477000Z","event_type":"price_change","frame_hash":"42d89016cf98e2cbaac3288c4d97b813315afcedd6bec2aefcf8f7a78eb5c934","frame_index":0,"kind":"data","monotonic_ns":228612214468833,"payload":{"event_type":"price_change","market":"0xeb66215f2e9faa6449e30a02bab5b8ed7b79a38bf961f6b24d0073c9c2419250","price_changes":[{"asset_id":"60386828328910021732068595344565885737045900010034836345809386672230885527307","best_ask":"0.6","best_bid":"0.59","hash":"3e28f1672795bbfc9d5ad12f2c3ac825a1ca0526","price":"0.46","side":"BUY","size":"21"},{"asset_id":"69697746896130839564035629862476347944307040470122503199396727085502753297492","best_ask":"0.41","best_bid":"0.4","hash":"35c7fb98f58f8145dedaacf010ab00a4cde45589","price":"0.54","side":"SELL","size":"21"}],"timestamp":"1785126627477"},"payload_hash":"34fb64ef3898480ce9a94e0aad598ac09100bca9fae2a93646742a14cbad7030","raw_frame":"{\"market\":\"0xeb66215f2e9faa6449e30a02bab5b8ed7b79a38bf961f6b24d0073c9c2419250\", \"price_changes\":[{\"asset_id\":\"60386828328910021732068595344565885737045900010034836345809386672230885527307\", \"price\":\"0.46\", \"size\":\"21\", \"side\":\"BUY\", \"hash\":\"3e28f1672795bbfc9d5ad12f2c3ac825a1ca0526\", \"best_bid\":\"0.59\", \"best_ask\":\"0.6\"}, {\"asset_id\":\"69697746896130839564035629862476347944307040470122503199396727085502753297492\", \"price\":\"0.54\", \"size\":\"21\", \"side\":\"SELL\", \"hash\":\"35c7fb98f58f8145dedaacf010ab00a4cde45589\", \"best_bid\":\"0.4\", \"best_ask\":\"0.41\"}], \"timestamp\":\"1785126627477\", \"event_type\":\"price_change\"}","received_at":"2026-07-27T04:30:28.944882Z","schema_version":"clob-market-ws.price_change.v1","sequence":null,"server_hash":null,"server_timestamp":"1785126627477","session_id":"e9443c7415a0419799bee9cfbb1a9e4d","source":"clob_market_ws"},"received_at":"2026-07-27T04:30:28.944882Z","record_id":"1888da07831d83ac908236cb12fa16bb77af46c3ec9ebcaa2b566e4cb7fa3acc","schema_fingerprint":"4aa3821a28b0b7c2400bc59aba4bcc0a76e971dadd19610d3ad38c768e124dc7","schema_version":"edge-lab-recorder.raw.v1","sequence":null,"source":"clob_market_ws"}
{"event_at":"2026-07-27T04:30:27.477000Z","event_fingerprint":"842a904cc6908a7577f90d87a3640c8d78fce3b78617dc95c683aec6e7078fef","payload":{"connection_id":"0f4979d6978d463e9660b042fdcf555f","event_at":"2026-07-27T04:30:27.477000Z","event_type":"price_change","frame_hash":"80bddf3e1da6076c4a6ecc78eef648b0e815e612ddc9cbef99d14891ca67e52b","frame_index":0,"kind":"data","monotonic_ns":228612220899625,"payload":{"event_type":"price_change","market":"0xeb66215f2e9faa6449e30a02bab5b8ed7b79a38bf961f6b24d0073c9c2419250","price_changes":[{"asset_id":"60386828328910021732068595344565885737045900010034836345809386672230885527307","best_ask":"0.6","best_bid":"0.59","hash":"9067b8cfea011cc0d84cfb3fc8bfb98335dff7e7","price":"0.5","side":"BUY","size":"180"},{"asset_id":"69697746896130839564035629862476347944307040470122503199396727085502753297492","best_ask":"0.41","best_bid":"0.4","hash":"a31c40db418736ab30ff4485bee5a26d1ce6cd9c","price":"0.5","side":"SELL","size":"180"}],"timestamp":"1785126627477"},"payload_hash":"1b44271ae977f3afe63e1feaf1d28247628a4b7b4edcfdd8939557db6f75dcc4","raw_frame":"{\"market\":\"0xeb66215f2e9faa6449e30a02bab5b8ed7b79a38bf961f6b24d0073c9c2419250\", \"price_changes\":[{\"asset_id\":\"60386828328910021732068595344565885737045900010034836345809386672230885527307\", \"price\":\"0.5\", \"size\":\"180\", \"side\":\"BUY\", \"hash\":\"9067b8cfea011cc0d84cfb3fc8bfb98335dff7e7\", \"best_bid\":\"0.59\", \"best_ask\":\"0.6\"}, {\"asset_id\":\"69697746896130839564035629862476347944307040470122503199396727085502753297492\", \"price\":\"0.5\", \"size\":\"180\", \"side\":\"SELL\", \"hash\":\"a31c40db418736ab30ff4485bee5a26d1ce6cd9c\", \"best_bid\":\"0.4\", \"best_ask\":\"0.41\"}], \"timestamp\":\"1785126627477\", \"event_type\":\"price_change\"}","received_at":"2026-07-27T04:30:28.951313Z","schema_version":"clob-market-ws.price_change.v1","sequence":null,"server_hash":null,"server_timestamp":"1785126627477","session_id":"e9443c7415a0419799bee9cfbb1a9e4d","source":"clob_market_ws"},"received_at":"2026-07-27T04:30:28.951313Z","record_id":"07ab52f27a4aaaff90af2ee540b92c83acf1bf42ee3a6ae0f269a8283e8da501","schema_fingerprint":"4aa3821a28b0b7c2400bc59aba4bcc0a76e971dadd19610d3ad38c768e124dc7","schema_version":"edge-lab-recorder.raw.v1","sequence":null,"source":"clob_market_ws"}
{"event_at":"2026-07-27T04:30:27.477000Z","event_fingerprint":"0040a2eec88be5293699791ff1a7dd7f5dd6f8ac0a6ded3c91683cf935f5d761","payload":{"connection_id":"0f4979d6978d463e9660b042fdcf555f","event_at":"2026-07-27T04:30:27.477000Z","event_type":"price_change","frame_hash":"89f2cda25b38b6a19999112fbeab2c93082f6864691f62c3dced9b268507b994","frame_index":0,"kind":"data","monotonic_ns":228612232872416,"payload":{"event_type":"price_change","market":"0xeb66215f2e9faa6449e30a02bab5b8ed7b79a38bf961f6b24d0073c9c2419250","price_changes":[{"asset_id":"69697746896130839564035629862476347944307040470122503199396727085502753297492","best_ask":"0.41","best_bid":"0.4","hash":"6a09ddd05850cb94ae51e644d0b7d832248126ed","price":"0.3","side":"BUY","size":"47"},{"asset_id":"60386828328910021732068595344565885737045900010034836345809386672230885527307","best_ask":"0.6","best_bid":"0.59","hash":"ba17a4eeffd9d20969ab0a9218948bb0ab414d45","price":"0.7","side":"SELL","size":"47"}],"timestamp":"1785126627477"},"payload_hash":"45853e886dfbbfcb7d26317df293a6150d623161930500b9d8053c24229e72eb","raw_frame":"{\"market\":\"0xeb66215f2e9faa6449e30a02bab5b8ed7b79a38bf961f6b24d0073c9c2419250\", \"price_changes\":[{\"asset_id\":\"69697746896130839564035629862476347944307040470122503199396727085502753297492\", \"price\":\"0.3\", \"size\":\"47\", \"side\":\"BUY\", \"hash\":\"6a09ddd05850cb94ae51e644d0b7d832248126ed\", \"best_bid\":\"0.4\", \"best_ask\":\"0.41\"}, {\"asset_id\":\"60386828328910021732068595344565885737045900010034836345809386672230885527307\", \"price\":\"0.7\", \"size\":\"47\", \"side\":\"SELL\", \"hash\":\"ba17a4eeffd9d20969ab0a9218948bb0ab414d45\", \"best_bid\":\"0.59\", \"best_ask\":\"0.6\"}], \"timestamp\":\"1785126627477\", \"event_type\":\"price_change\"}","received_at":"2026-07-27T04:30:28.963286Z","schema_version":"clob-market-ws.price_change.v1","sequence":null,"server_hash":null,"server_timestamp":"1785126627477","session_id":"e9443c7415a0419799bee9cfbb1a9e4d","source":"clob_market_ws"},"received_at":"2026-07-27T04:30:28.963286Z","record_id":"4aad4257213e971d4bd4f52917d626dd321746dd424ffb1d8c00c215b0313470","schema_fingerprint":"4aa3821a28b0b7c2400bc59aba4bcc0a76e971dadd19610d3ad38c768e124dc7","schema_version":"edge-lab-recorder.raw.v1","sequence":null,"source":"clob_market_ws"}
{"event_at":"2026-07-27T04:30:27.477000Z","event_fingerprint":"63be11aa75d364f8a8b59af16d501b296ab0a43dda05dc74097040df28da09ce","payload":{"connection_id":"0f4979d6978d463e9660b042fdcf555f","event_at":"2026-07-27T04:30:27.477000Z","event_type":"price_change","frame_hash":"9695eb7af4eb4859b50e1c32fc7094f3d7e3162e6c63ddbed0e150460afdbfe9","frame_index":0,"kind":"data","monotonic_ns":228612242583333,"payload":{"event_type":"price_change","market":"0xeb66215f2e9faa6449e30a02bab5b8ed7b79a38bf961f6b24d0073c9c2419250","price_changes":[{"asset_id":"60386828328910021732068595344565885737045900010034836345809386672230885527307","best_ask":"0.6","best_bid":"0.59","hash":"3b1ca1c4a25086d6b37bb46274ee4bcbccc6d214","price":"0.54","side":"BUY","size":"266.64"},{"asset_id":"69697746896130839564035629862476347944307040470122503199396727085502753297492","best_ask":"0.41","best_bid":"0.4","hash":"8331f72b56ec4b9b10d85ce15feab3f73c04ffb9","price":"0.46","side":"SELL","size":"266.64"}],"timestamp":"1785126627477"},"payload_hash":"e3ec120756a808c36016431f4acfd46d3fde10ca9e7685d294a2650c705b1768","raw_frame":"{\"market\":\"0xeb66215f2e9faa6449e30a02bab5b8ed7b79a38bf961f6b24d0073c9c2419250\", \"price_changes\":[{\"asset_id\":\"60386828328910021732068595344565885737045900010034836345809386672230885527307\", \"price\":\"0.54\", \"size\":\"266.64\", \"side\":\"BUY\", \"hash\":\"3b1ca1c4a25086d6b37bb46274ee4bcbccc6d214\", \"best_bid\":\"0.59\", \"best_ask\":\"0.6\"}, {\"asset_id\":\"69697746896130839564035629862476347944307040470122503199396727085502753297492\", \"price\":\"0.46\", \"size\":\"266.64\", \"side\":\"SELL\", \"hash\":\"8331f72b56ec4b9b10d85ce15feab3f73c04ffb9\", \"best_bid\":\"0.4\", \"best_ask\":\"0.41\"}], \"timestamp\":\"1785126627477\", \"event_type\":\"price_change\"}","received_at":"2026-07-27T04:30:28.972998Z","schema_version":"clob-market-ws.price_change.v1","sequence":null,"server_hash":null,"server_timestamp":"1785126627477","session_id":"e9443c7415a0419799bee9cfbb1a9e4d","source":"clob_market_ws"},"received_at":"2026-07-27T04:30:28.972998Z","record_id":"7f8a1f855c28cdba6136759d82f0df69a63ff37056f00db82e828e654a13c289","schema_fingerprint":"4aa3821a28b0b7c2400bc59aba4bcc0a76e971dadd19610d3ad38c768e124dc7","schema_version":"edge-lab-recorder.raw.v1","sequence":null,"source":"clob_market_ws"}
{"event_at":"2026-07-27T04:30:27.477000Z","event_fingerprint":"8799629fad326965cbd3e46f8fe5420a779a5a2e5fa9b0829ff71edf94a6dcb2","payload":{"connection_id":"0f4979d6978d463e9660b042fdcf555f","event_at":"2026-07-27T04:30:27.477000Z","event_type":"price_change","frame_hash":"234d26d8515be2315e7d9591f7a4b31fec2bb2ea8c2f01a4b0acb4f1637ae5a6","frame_index":0,"kind":"data","monotonic_ns":228612249364500,"payload":{"event_type":"price_change","market":"0xeb66215f2e9faa6449e30a02bab5b8ed7b79a38bf961f6b24d0073c9c2419250","price_changes":[{"asset_id":"60386828328910021732068595344565885737045900010034836345809386672230885527307","best_ask":"0.6","best_bid":"0.59","hash":"093ad9d7bc5d60b1cb442ebe4e8721c2e7021216","price":"0.49","side":"BUY","size":"94.02"},{"asset_id":"69697746896130839564035629862476347944307040470122503199396727085502753297492","best_ask":"0.41","best_bid":"0.4","hash":"4ff00e77055682dad0bedfd09dd7cb3277263b3a","price":"0.51","side":"SELL","size":"94.02"}],"timestamp":"1785126627477"},"payload_hash":"9095f82692b940598a59da6634aedd21a7eeda022730992f26aa74ca79462a30","raw_frame":"{\"market\":\"0xeb66215f2e9faa6449e30a02bab5b8ed7b79a38bf961f6b24d0073c9c2419250\", \"price_changes\":[{\"asset_id\":\"60386828328910021732068595344565885737045900010034836345809386672230885527307\", \"price\":\"0.49\", \"size\":\"94.02\", \"side\":\"BUY\", \"hash\":\"093ad9d7bc5d60b1cb442ebe4e8721c2e7021216\", \"best_bid\":\"0.59\", \"best_ask\":\"0.6\"}, {\"asset_id\":\"69697746896130839564035629862476347944307040470122503199396727085502753297492\", \"price\":\"0.51\", \"size\":\"94.02\", \"side\":\"SELL\", \"hash\":\"4ff00e77055682dad0bedfd09dd7cb3277263b3a\", \"best_bid\":\"0.4\", \"best_ask\":\"0.41\"}], \"timestamp\":\"1785126627477\", \"event_type\":\"price_change\"}","received_at":"2026-07-27T04:30:28.979776Z","schema_version":"clob-market-ws.price_change.v1","sequence":null,"server_hash":null,"server_timestamp":"1785126627477","session_id":"e9443c7415a0419799bee9cfbb1a9e4d","source":"clob_market_ws"},"received_at":"2026-07-27T04:30:28.979776Z","record_id":"29b53c6b9075304b3345255e07a11e6e5ef5aa8190028a53a548d08672963547","schema_fingerprint":"4aa3821a28b0b7c2400bc59aba4bcc0a76e971dadd19610d3ad38c768e124dc7","schema_version":"edge-lab-recorder.raw.v1","sequence":null,"source":"clob_market_ws"}
{"event_at":"2026-07-27T04:30:27.576000Z","event_fingerprint":"320d53dea70d01377d64fbf0fe95c25190a17490e666e0907ed2bb650f1c22e5","payload":{"connection_id":"0f4979d6978d463e9660b042fdcf555f","event_at":"2026-07-27T04:30:27.576000Z","event_type":"price_change","frame_hash":"b24799b8eb7ee823bfd24ec07cdf8d90b3f2a6258e7ae194d80a95b42fc32af8","frame_index":0,"kind":"data","monotonic_ns":228612257201666,"payload":{"event_type":"price_change","market":"0xeb66215f2e9faa6449e30a02bab5b8ed7b79a38bf961f6b24d0073c9c2419250","price_changes":[{"asset_id":"69697746896130839564035629862476347944307040470122503199396727085502753297492","best_ask":"0.41","best_bid":"0.4","hash":"06ea717e53d61fc7934aaeb974f6cf766b6285ac","price":"0.35","side":"BUY","size":"27"},{"asset_id":"60386828328910021732068595344565885737045900010034836345809386672230885527307","best_ask":"0.6","best_bid":"0.59","hash":"2e98362f537f6a36c404bbd47d3c99e3aaf296ed","price":"0.65","side":"SELL","size":"27"}],"timestamp":"1785126627576"},"payload_hash":"1638e05bc5051b5939013937d6db6cc6f57dd218fb0bf6078d6d10de0f3cfe5b","raw_frame":"{\"market\":\"0xeb66215f2e9faa6449e30a02bab5b8ed7b79a38bf961f6b24d0073c9c2419250\", \"price_changes\":[{\"asset_id\":\"69697746896130839564035629862476347944307040470122503199396727085502753297492\", \"price\":\"0.35\", \"size\":\"27\", \"side\":\"BUY\", \"hash\":\"06ea717e53d61fc7934aaeb974f6cf766b6285ac\", \"best_bid\":\"0.4\", \"best_ask\":\"0.41\"}, {\"asset_id\":\"60386828328910021732068595344565885737045900010034836345809386672230885527307\", \"price\":\"0.65\", \"size\":\"27\", \"side\":\"SELL\", \"hash\":\"2e98362f537f6a36c404bbd47d3c99e3aaf296ed\", \"best_bid\":\"0.59\", \"best_ask\":\"0.6\"}], \"timestamp\":\"1785126627576\", \"event_type\":\"price_change\"}","received_at":"2026-07-27T04:30:28.987616Z","schema_version":"clob-market-ws.price_change.v1","sequence":null,"server_hash":null,"server_timestamp":"1785126627576","session_id":"e9443c7415a0419799bee9cfbb1a9e4d","source":"clob_market_ws"},"received_at":"2026-07-27T04:30:28.987616Z","record_id":"b89b24a9812d12ea09ade020c3c07c0a688e9e51bdf04619152e53b147c01c8d","schema_fingerprint":"4aa3821a28b0b7c2400bc59aba4bcc0a76e971dadd19610d3ad38c768e124dc7","schema_version":"edge-lab-recorder.raw.v1","sequence":null,"source":"clob_market_ws"}
{"event_at":"2026-07-27T04:30:27.576000Z","event_fingerprint":"c0b6cbfebb67279133abdc6d8164c9074e27621e9e1051d80749d14aa0e3af9b","payload":{"connection_id":"0f4979d6978d463e9660b042fdcf555f","event_at":"2026-07-27T04:30:27.576000Z","event_type":"price_change","frame_hash":"e136c9702ae2375846c7e5ceefc5e2848e2303e1b5f1329f61bc84c6b6da2131","frame_index":0,"kind":"data","monotonic_ns":228612264284625,"payload":{"event_type":"price_change","market":"0xeb66215f2e9faa6449e30a02bab5b8ed7b79a38bf961f6b24d0073c9c2419250","price_changes":[{"asset_id":"69697746896130839564035629862476347944307040470122503199396727085502753297492","best_ask":"0.41","best_bid":"0.4","hash":"06ea717e53d61fc7934aaeb974f6cf766b6285ac","price":"0.37","side":"BUY","size":"26.74"},{"asset_id":"60386828328910021732068595344565885737045900010034836345809386672230885527307","best_ask":"0.6","best_bid":"0.59","hash":"2e98362f537f6a36c404bbd47d3c99e3aaf296ed","price":"0.63","side":"SELL","size":"26.74"}],"timestamp":"1785126627576"},"payload_hash":"c121a2516ee45da1a8d4354071003d4568df913083f23b80b9f0289e63a3d850","raw_frame":"{\"market\":\"0xeb66215f2e9faa6449e30a02bab5b8ed7b79a38bf961f6b24d0073c9c2419250\", \"price_changes\":[{\"asset_id\":\"69697746896130839564035629862476347944307040470122503199396727085502753297492\", \"price\":\"0.37\", \"size\":\"26.74\", \"side\":\"BUY\", \"hash\":\"06ea717e53d61fc7934aaeb974f6cf766b6285ac\", \"best_bid\":\"0.4\", \"best_ask\":\"0.41\"}, {\"asset_id\":\"60386828328910021732068595344565885737045900010034836345809386672230885527307\", \"price\":\"0.63\", \"size\":\"26.74\", \"side\":\"SELL\", \"hash\":\"2e98362f537f6a36c404bbd47d3c99e3aaf296ed\", \"best_bid\":\"0.59\", \"best_ask\":\"0.6\"}], \"timestamp\":\"1785126627576\", \"event_type\":\"price_change\"}","received_at":"2026-07-27T04:30:28.994699Z","schema_version":"clob-market-ws.price_change.v1","sequence":null,"server_hash":null,"server_timestamp":"1785126627576","session_id":"e9443c7415a0419799bee9cfbb1a9e4d","source":"clob_market_ws"},"received_at":"2026-07-27T04:30:28.994699Z","record_id":"22e66c9041cd265b85bd97b557f62f0f08fe5d0a63dd429e4a1a74a2cccfde20","schema_fingerprint":"4aa3821a28b0b7c2400bc59aba4bcc0a76e971dadd19610d3ad38c768e124dc7","schema_version":"edge-lab-recorder.raw.v1","sequence":null,"source":"clob_market_ws"}
{"event_at":"2026-07-27T04:30:27.576000Z","event_fingerprint":"c274381d350b53dbdb2d57a14343c30330c883a64305647cd1adefcbc2d99038","payload":{"connection_id":"0f4979d6978d463e9660b042fdcf555f","event_at":"2026-07-27T04:30:27.576000Z","event_type":"price_change","frame_hash":"4e7746f554db9d74a5ced745b6b3247d03a05105ac7f515502c86987bd972914","frame_index":0,"kind":"data","monotonic_ns":228612276320250,"payload":{"event_type":"price_change","market":"0xeb66215f2e9faa6449e30a02bab5b8ed7b79a38bf961f6b24d0073c9c2419250","price_changes":[{"asset_id":"60386828328910021732068595344565885737045900010034836345809386672230885527307","best_ask":"0.6","best_bid":"0.59","hash":"2e98362f537f6a36c404bbd47d3c99e3aaf296ed","price":"0.56","side":"BUY","size":"97.52"},{"asset_id":"69697746896130839564035629862476347944307040470122503199396727085502753297492","best_ask":"0.41","best_bid":"0.4","hash":"06ea717e53d61fc7934aaeb974f6cf766b6285ac","price":"0.44","side":"SELL","size":"97.52"}],"timestamp":"1785126627576"},"payload_hash":"58c009f9bd974b9f782d0646457607ea4a49e3912972521b41bb041929b1e1a1","raw_frame":"{\"market\":\"0xeb66215f2e9faa6449e30a02bab5b8ed7b79a38bf961f6b24d0073c9c2419250\", \"price_changes\":[{\"asset_id\":\"60386828328910021732068595344565885737045900010034836345809386672230885527307\", \"price\":\"0.56\", \"size\":\"97.52\", \"side\":\"BUY\", \"hash\":\"2e98362f537f6a36c404bbd47d3c99e3aaf296ed\", \"best_bid\":\"0.59\", \"best_ask\":\"0.6\"}, {\"asset_id\":\"69697746896130839564035629862476347944307040470122503199396727085502753297492\", \"price\":\"0.44\", \"size\":\"97.52\", \"side\":\"SELL\", \"hash\":\"06ea717e53d61fc7934aaeb974f6cf766b6285ac\", \"best_bid\":\"0.4\", \"best_ask\":\"0.41\"}], \"timestamp\":\"1785126627576\", \"event_type\":\"price_change\"}","received_at":"2026-07-27T04:30:29.006734Z","schema_version":"clob-market-ws.price_change.v1","sequence":null,"server_hash":null,"server_timestamp":"1785126627576","session_id":"e9443c7415a0419799bee9cfbb1a9e4d","source":"clob_market_ws"},"received_at":"2026-07-27T04:30:29.006734Z","record_id":"444406f0001d25343c1091e34af9134672fc9623645127f437cd592490254d52","schema_fingerprint":"4aa3821a28b0b7c2400bc59aba4bcc0a76e971dadd19610d3ad38c768e124dc7","schema_version":"edge-lab-recorder.raw.v1","sequence":null,"source":"clob_market_ws"}
{"event_at":"2026-07-27T04:30:27.576000Z","event_fingerprint":"098848d29a7718f4ab467f6ccf54bff851f03ce8fb99d92b42edb75a13fab759","payload":{"connection_id":"0f4979d6978d463e9660b042fdcf555f","event_at":"2026-07-27T04:30:27.576000Z","event_type":"price_change","frame_hash":"fa4ebbf127ecb82e3a4aecaa9520c6fed0fa08cef6e6260976e8bdea3447ee8a","frame_index":0,"kind":"data","monotonic_ns":228612284828458,"payload":{"event_type":"price_change","market":"0xeb66215f2e9faa6449e30a02bab5b8ed7b79a38bf961f6b24d0073c9c2419250","price_changes":[{"asset_id":"69697746896130839564035629862476347944307040470122503199396727085502753297492","best_ask":"0.41","best_bid":"0.4","hash":"06ea717e53d61fc7934aaeb974f6cf766b6285ac","price":"0.33","side":"BUY","size":"15"},{"asset_id":"60386828328910021732068595344565885737045900010034836345809386672230885527307","best_ask":"0.6","best_bid":"0.59","hash":"2e98362f537f6a36c404bbd47d3c99e3aaf296ed","price":"0.67","side":"SELL","size":"15"}],"timestamp":"1785126627576"},"payload_hash":"d4c996fc2a03ae9ae8603638b9f9c800f4d9022f1d9832bd0337e69ce4650f27","raw_frame":"{\"market\":\"0xeb66215f2e9faa6449e30a02bab5b8ed7b79a38bf961f6b24d0073c9c2419250\", \"price_changes\":[{\"asset_id\":\"69697746896130839564035629862476347944307040470122503199396727085502753297492\", \"price\":\"0.33\", \"size\":\"15\", \"side\":\"BUY\", \"hash\":\"06ea717e53d61fc7934aaeb974f6cf766b6285ac\", \"best_bid\":\"0.4\", \"best_ask\":\"0.41\"}, {\"asset_id\":\"60386828328910021732068595344565885737045900010034836345809386672230885527307\", \"price\":\"0.67\", \"size\":\"15\", \"side\":\"SELL\", \"hash\":\"2e98362f537f6a36c404bbd47d3c99e3aaf296ed\", \"best_bid\":\"0.59\", \"best_ask\":\"0.6\"}], \"timestamp\":\"1785126627576\", \"event_type\":\"price_change\"}","received_at":"2026-07-27T04:30:29.015242Z","schema_version":"clob-market-ws.price_change.v1","sequence":null,"server_hash":null,"server_timestamp":"1785126627576","session_id":"e9443c7415a0419799bee9cfbb1a9e4d","source":"clob_market_ws"},"received_at":"2026-07-27T04:30:29.015242Z","record_id":"300c8f573f434f90e00a8853559ce3e6cb368eb4e35b1e6219481600a3694081","schema_fingerprint":"4aa3821a28b0b7c2400bc59aba4bcc0a76e971dadd19610d3ad38c768e124dc7","schema_version":"edge-lab-recorder.raw.v1","sequence":null,"source":"clob_market_ws"}
{"event_at":"2026-07-27T04:30:27.576000Z","event_fingerprint":"2d8642497a22600cbf694aaf594d69a9ae5895477392d8af3cb70845b9163d0f","payload":{"connection_id":"0f4979d6978d463e9660b042fdcf555f","event_at":"2026-07-27T04:30:27.576000Z","event_type":"price_change","frame_hash":"7a003e5ef7bb118c5cbdb33df0ef9d764f9242bba8ee01c96459c318f33727bb","frame_index":0,"kind":"data","monotonic_ns":228612294863583,"payload":{"event_type":"price_change","market":"0xeb66215f2e9faa6449e30a02bab5b8ed7b79a38bf961f6b24d0073c9c2419250","price_changes":[{"asset_id":"60386828328910021732068595344565885737045900010034836345809386672230885527307","best_ask":"0.6","best_bid":"0.59","hash":"2e98362f537f6a36c404bbd47d3c99e3aaf296ed","price":"0.58","side":"BUY","size":"39.01"},{"asset_id":"69697746896130839564035629862476347944307040470122503199396727085502753297492","best_ask":"0.41","best_bid":"0.4","hash":"06ea717e53d61fc7934aaeb974f6cf766b6285ac","price":"0.42","side":"SELL","size":"39.01"}],"timestamp":"1785126627576"},"payload_hash":"7236fdeddb1eebfffa91ba7ed286d22fd1d949e5582ac0466bc497643ee249ac","raw_frame":"{\"market\":\"0xeb66215f2e9faa6449e30a02bab5b8ed7b79a38bf961f6b24d0073c9c2419250\", \"price_changes\":[{\"asset_id\":\"60386828328910021732068595344565885737045900010034836345809386672230885527307\", \"price\":\"0.58\", \"size\":\"39.01\", \"side\":\"BUY\", \"hash\":\"2e98362f537f6a36c404bbd47d3c99e3aaf296ed\", \"best_bid\":\"0.59\", \"best_ask\":\"0.6\"}, {\"asset_id\":\"69697746896130839564035629862476347944307040470122503199396727085502753297492\", \"price\":\"0.42\", \"size\":\"39.01\", \"side\":\"SELL\", \"hash\":\"06ea717e53d61fc7934aaeb974f6cf766b6285ac\", \"best_bid\":\"0.4\", \"best_ask\":\"0.41\"}], \"timestamp\":\"1785126627576\", \"event_type\":\"price_change\"}","received_at":"2026-07-27T04:30:29.025276Z","schema_version":"clob-market-ws.price_change.v1","sequence":null,"server_hash":null,"server_timestamp":"1785126627576","session_id":"e9443c7415a0419799bee9cfbb1a9e4d","source":"clob_market_ws"},"received_at":"2026-07-27T04:30:29.025276Z","record_id":"0a4581e606d72de6590525aec15a2219654f09062295503294d6046ef25c7c32","schema_fingerprint":"4aa3821a28b0b7c2400bc59aba4bcc0a76e971dadd19610d3ad38c768e124dc7","schema_version":"edge-lab-recorder.raw.v1","sequence":null,"source":"clob_market_ws"}
{"event_at":"2026-07-27T04:30:27.584000Z","event_fingerprint":"43d815ad92fe43aee6561eba0110a5dddbc460cd186c47f0867369896bf332fc","payload":{"connection_id":"0f4979d6978d463e9660b042fdcf555f","event_at":"2026-07-27T04:30:27.584000Z","event_type":"best_bid_ask","frame_hash":"e8ad57e3e83ef90b90fa054d55c1e6b53a03384b4934af61b5c73fb2d5f9552c","frame_index":0,"kind":"data","monotonic_ns":228612309636666,"payload":{"asset_id":"69697746896130839564035629862476347944307040470122503199396727085502753297492","best_ask":"0.41","best_bid":"0.4","event_type":"best_bid_ask","market":"0xeb66215f2e9faa6449e30a02bab5b8ed7b79a38bf961f6b24d0073c9c2419250","spread":"0.01","timestamp":"1785126627584"},"payload_hash":"2f59cc261166940e0355bac0d1a91f2e6acd2b6311ec4efd45a3c100ef7962f4","raw_frame":"{\"market\":\"0xeb66215f2e9faa6449e30a02bab5b8ed7b79a38bf961f6b24d0073c9c2419250\", \"asset_id\":\"69697746896130839564035629862476347944307040470122503199396727085502753297492\", \"best_bid\":\"0.4\", \"best_ask\":\"0.41\", \"spread\":\"0.01\", \"timestamp\":\"1785126627584\", \"event_type\":\"best_bid_ask\"}","received_at":"2026-07-27T04:30:29.040052Z","schema_version":"clob-market-ws.best_bid_ask.v1","sequence":null,"server_hash":null,"server_timestamp":"1785126627584","session_id":"e9443c7415a0419799bee9cfbb1a9e4d","source":"clob_market_ws"},"received_at":"2026-07-27T04:30:29.040052Z","record_id":"89b22ad65d0623605641022ccaae25e601491258bc17049c7ad67330f7c115fd","schema_fingerprint":"8488399f31b0337811b13b266be932db7062827c2470b78bd8e9e99bab51d17d","schema_version":"edge-lab-recorder.raw.v1","sequence":null,"source":"clob_market_ws"}
{"event_at":"2026-07-27T04:30:27.584000Z","event_fingerprint":"1867111574c2d76a0f7fb0fa6324f741df373e39c521854ed1b74d302c0c6163","payload":{"connection_id":"0f4979d6978d463e9660b042fdcf555f","event_at":"2026-07-27T04:30:27.584000Z","event_type":"best_bid_ask","frame_hash":"983a0d0cdb3c36e1f2a0b0130765df0e2d7884f17ad248bed00336967604d467","frame_index":0,"kind":"data","monotonic_ns":228612317148083,"payload":{"asset_id":"60386828328910021732068595344565885737045900010034836345809386672230885527307","best_ask":"0.6","best_bid":"0.59","event_type":"best_bid_ask","market":"0xeb66215f2e9faa6449e30a02bab5b8ed7b79a38bf961f6b24d0073c9c2419250","spread":"0.01","timestamp":"1785126627584"},"payload_hash":"4c8efa8d7932d2fa181f85ee8f7e78fde9b6e6905527f078bd149a7ee2219623","raw_frame":"{\"market\":\"0xeb66215f2e9faa6449e30a02bab5b8ed7b79a38bf961f6b24d0073c9c2419250\", \"asset_id\":\"60386828328910021732068595344565885737045900010034836345809386672230885527307\", \"best_bid\":\"0.59\", \"best_ask\":\"0.6\", \"spread\":\"0.01\", \"timestamp\":\"1785126627584\", \"event_type\":\"best_bid_ask\"}","received_at":"2026-07-27T04:30:29.047562Z","schema_version":"clob-market-ws.best_bid_ask.v1","sequence":null,"server_hash":null,"server_timestamp":"1785126627584","session_id":"e9443c7415a0419799bee9cfbb1a9e4d","source":"clob_market_ws"},"received_at":"2026-07-27T04:30:29.047562Z","record_id":"6e299475c8aa6ffaf1218f0a8d9e014fb993c8cd0f2b9052afecad7fba01bb12","schema_fingerprint":"8488399f31b0337811b13b266be932db7062827c2470b78bd8e9e99bab51d17d","schema_version":"edge-lab-recorder.raw.v1","sequence":null,"source":"clob_market_ws"}
{"event_at":"2026-07-27T04:30:27.584000Z","event_fingerprint":"1d12b6d2769ecc7f574093cb503d019c970755084b65d46a526c05580e539218","payload":{"connection_id":"0f4979d6978d463e9660b042fdcf555f","event_at":"2026-07-27T04:30:27.584000Z","event_type":"price_change","frame_hash":"6789e84d017efb29b5ef5104f00f4cf354dbfc38ef5367abf3d40e823944a534","frame_index":0,"kind":"data","monotonic_ns":228612326017583,"payload":{"event_type":"price_change","market":"0xeb66215f2e9faa6449e30a02bab5b8ed7b79a38bf961f6b24d0073c9c2419250","price_changes":[{"asset_id":"69697746896130839564035629862476347944307040470122503199396727085502753297492","best_ask":"0.41","best_bid":"0.4","hash":"45f5f40dad860b626f4a9411bddab64a0405a133","price":"0.4","side":"BUY","size":"1.46"},{"asset_id":"60386828328910021732068595344565885737045900010034836345809386672230885527307","best_ask":"0.6","best_bid":"0.59","hash":"e1955bb8c955c7cf5ab0d68569ff20f13ba44a5a","price":"0.6","side":"SELL","size":"1.46"}],"timestamp":"1785126627584"},"payload_hash":"681a2b731858320d9c49b9c16dba4469172b2901756b52594097bb4c1a0c8b20","raw_frame":"{\"market\":\"0xeb66215f2e9faa6449e30a02bab5b8ed7b79a38bf961f6b24d0073c9c2419250\", \"price_changes\":[{\"asset_id\":\"69697746896130839564035629862476347944307040470122503199396727085502753297492\", \"price\":\"0.4\", \"size\":\"1.46\", \"side\":\"BUY\", \"hash\":\"45f5f40dad860b626f4a9411bddab64a0405a133\", \"best_bid\":\"0.4\", \"best_ask\":\"0.41\"}, {\"asset_id\":\"60386828328910021732068595344565885737045900010034836345809386672230885527307\", \"price\":\"0.6\", \"size\":\"1.46\", \"side\":\"SELL\", \"hash\":\"e1955bb8c955c7cf5ab0d68569ff20f13ba44a5a\", \"best_bid\":\"0.59\", \"best_ask\":\"0.6\"}], \"timestamp\":\"1785126627584\", \"event_type\":\"price_change\"}","received_at":"2026-07-27T04:30:29.056431Z","schema_version":"clob-market-ws.price_change.v1","sequence":null,"server_hash":null,"server_timestamp":"1785126627584","session_id":"e9443c7415a0419799bee9cfbb1a9e4d","source":"clob_market_ws"},"received_at":"2026-07-27T04:30:29.056431Z","record_id":"af54cc0aec71ecb02c1f820fded68179e7ac026e52a48bb07d1844fc023fa687","schema_fingerprint":"4aa3821a28b0b7c2400bc59aba4bcc0a76e971dadd19610d3ad38c768e124dc7","schema_version":"edge-lab-recorder.raw.v1","sequence":null,"source":"clob_market_ws"}
{"event_at":"2026-07-27T04:30:27.584000Z","event_fingerprint":"f91a453331d3e92836a78191f074231a4c3e271cc3d2db83217a868193ba5ad9","payload":{"connection_id":"0f4979d6978d463e9660b042fdcf555f","event_at":"2026-07-27T04:30:27.584000Z","event_type":"book","frame_hash":"7fd11436a14cad574c25fbcc6fcc5f8f356e47706a27e8efad46b9d36fa70141","frame_index":0,"kind":"data","monotonic_ns":228612334285666,"payload":{"asks":[{"price":"0.99","size":"7703.02"},{"price":"0.98","size":"1733.1"},{"price":"0.97","size":"1063.1"},{"price":"0.96","size":"838.09"},{"price":"0.95","size":"858.2"},{"price":"0.94","size":"719"},{"price":"0.93","size":"507.14"},{"price":"0.92","size":"591"},{"price":"0.91","size":"530"},{"price":"0.9","size":"216"},{"price":"0.88","size":"30"},{"price":"0.85","size":"77"},{"price":"0.82","size":"30"},{"price":"0.8","size":"35"},{"price":"0.79","size":"30"},{"price":"0.76","size":"30"},{"price":"0.75","size":"28"},{"price":"0.74","size":"6"},{"price":"0.73","size":"36"},{"price":"0.72","size":"6"},{"price":"0.71","size":"6"},{"price":"0.7","size":"60"},{"price":"0.69","size":"6"},{"price":"0.68","size":"11.97"},{"price":"0.67","size":"36"},{"price":"0.66","size":"6"},{"price":"0.65","size":"25"},{"price":"0.64","size":"35"},{"price":"0.63","size":"53.93"},{"price":"0.62","size":"18"},{"price":"0.61","size":"48"},{"price":"0.6","size":"36"},{"price":"0.59","size":"23"},{"price":"0.58","size":"52"},{"price":"0.57","size":"27"},{"price":"0.56","size":"107"},{"price":"0.55","size":"68"},{"price":"0.54","size":"21"},{"price":"0.53","size":"11"},{"price":"0.52","size":"57"},{"price":"0.51","size":"94.02"},{"price":"0.5","size":"180"},{"price":"0.49","size":"72.64"},{"price":"0.48","size":"122"},{"price":"0.47","size":"145.86"},{"price":"0.46","size":"266.64"},{"price":"0.45","size":"30.68"},{"price":"0.44","size":"97.52"},{"price":"0.43","size":"68.57"},{"price":"0.42","size":"39.01"},{"price":"0.41","size":"153.42"}],"asset_id":"69697746896130839564035629862476347944307040470122503199396727085502753297492","bids":[{"price":"0.01","size":"7733.02"},{"price":"0.02","size":"1723.1"},{"price":"0.03","size":"1166.43"},{"price":"0.04","size":"868.09"},{"price":"0.05","size":"618.2"},{"price":"0.06","size":"689"},{"price":"0.07","size":"556.14"},{"price":"0.08","size":"608"},{"price":"0.09","size":"515"},{"price":"0.1","size":"190"},{"price":"0.11","size":"13"},{"price":"0.12","size":"12"},{"price":"0.13","size":"41"},{"price":"0.14","size":"10"},{"price":"0.15","size":"10"},{"price":"0.16","size":"39"},{"price":"0.17","size":"9"},{"price":"0.18","size":"8"},{"price":"0.19","size":"38"},{"price":"0.2","size":"43"},{"price":"0.21","size":"8"},{"price":"0.22","size":"37"},{"price":"0.23","size":"7"},{"price":"0.24","size":"7"},{"price":"0.25","size":"265"},{"price":"0.26","size":"106"},{"price":"0.27","size":"6"},{"price":"0.28","size":"123.66"},{"price":"0.29","size":"123"},{"price":"0.3","size":"47"},{"price":"0.31","size":"52"},{"price":"0.32","size":"22"},{"price":"0.33","size":"15"},{"price":"0.34","size":"51"},{"price":"0.35","size":"27"},{"price":"0.36","size":"26.87"},{"price":"0.37","size":"26.74"},{"price":"0.38","size":"13"},{"price":"0.4","size":"1.46"}],"event_type":"book","hash":"45f5f40dad860b626f4a9411bddab64a0405a133","market":"0xeb66215f2e9faa6449e30a02bab5b8ed7b79a38bf961f6b24d0073c9c2419250","timestamp":"1785126627584"},"payload_hash":"ab0d0e8e2039e3994fe94f87f9ad288c14584b862eee797b110d672346ed0b06","raw_frame":"{\"market\":\"0xeb66215f2e9faa6449e30a02bab5b8ed7b79a38bf961f6b24d0073c9c2419250\", \"asset_id\":\"69697746896130839564035629862476347944307040470122503199396727085502753297492\", \"bids\":[{\"price\":\"0.01\", \"size\":\"7733.02\"}, {\"price\":\"0.02\", \"size\":\"1723.1\"}, {\"price\":\"0.03\", \"size\":\"1166.43\"}, {\"price\":\"0.04\", \"size\":\"868.09\"}, {\"price\":\"0.05\", \"size\":\"618.2\"}, {\"price\":\"0.06\", \"size\":\"689\"}, {\"price\":\"0.07\", \"size\":\"556.14\"}, {\"price\":\"0.08\", \"size\":\"608\"}, {\"price\":\"0.09\", \"size\":\"515\"}, {\"price\":\"0.1\", \"size\":\"190\"}, {\"price\":\"0.11\", \"size\":\"13\"}, {\"price\":\"0.12\", \"size\":\"12\"}, {\"price\":\"0.13\", \"size\":\"41\"}, {\"price\":\"0.14\", \"size\":\"10\"}, {\"price\":\"0.15\", \"size\":\"10\"}, {\"price\":\"0.16\", \"size\":\"39\"}, {\"price\":\"0.17\", \"size\":\"9\"}, {\"price\":\"0.18\", \"size\":\"8\"}, {\"price\":\"0.19\", \"size\":\"38\"}, {\"price\":\"0.2\", \"size\":\"43\"}, {\"price\":\"0.21\", \"size\":\"8\"}, {\"price\":\"0.22\", \"size\":\"37\"}, {\"price\":\"0.23\", \"size\":\"7\"}, {\"price\":\"0.24\", \"size\":\"7\"}, {\"price\":\"0.25\", \"size\":\"265\"}, {\"price\":\"0.26\", \"size\":\"106\"}, {\"price\":\"0.27\", \"size\":\"6\"}, {\"price\":\"0.28\", \"size\":\"123.66\"}, {\"price\":\"0.29\", \"size\":\"123\"}, {\"price\":\"0.3\", \"size\":\"47\"}, {\"price\":\"0.31\", \"size\":\"52\"}, {\"price\":\"0.32\", \"size\":\"22\"}, {\"price\":\"0.33\", \"size\":\"15\"}, {\"price\":\"0.34\", \"size\":\"51\"}, {\"price\":\"0.35\", \"size\":\"27\"}, {\"price\":\"0.36\", \"size\":\"26.87\"}, {\"price\":\"0.37\", \"size\":\"26.74\"}, {\"price\":\"0.38\", \"size\":\"13\"}, {\"price\":\"0.4\", \"size\":\"1.46\"}], \"asks\":[{\"price\":\"0.99\", \"size\":\"7703.02\"}, {\"price\":\"0.98\", \"size\":\"1733.1\"}, {\"price\":\"0.97\", \"size\":\"1063.1\"}, {\"price\":\"0.96\", \"size\":\"838.09\"}, {\"price\":\"0.95\", \"size\":\"858.2\"}, {\"price\":\"0.94\", \"size\":\"719\"}, {\"price\":\"0.93\", \"size\":\"507.14\"}, {\"price\":\"0.92\", \"size\":\"591\"}, {\"price\":\"0.91\", \"size\":\"530\"}, {\"price\":\"0.9\", \"size\":\"216\"}, {\"price\":\"0.88\", \"size\":\"30\"}, {\"price\":\"0.85\", \"size\":\"77\"}, {\"price\":\"0.82\", \"size\":\"30\"}, {\"price\":\"0.8\", \"size\":\"35\"}, {\"price\":\"0.79\", \"size\":\"30\"}, {\"price\":\"0.76\", \"size\":\"30\"}, {\"price\":\"0.75\", \"size\":\"28\"}, {\"price\":\"0.74\", \"size\":\"6\"}, {\"price\":\"0.73\", \"size\":\"36\"}, {\"price\":\"0.72\", \"size\":\"6\"}, {\"price\":\"0.71\", \"size\":\"6\"}, {\"price\":\"0.7\", \"size\":\"60\"}, {\"price\":\"0.69\", \"size\":\"6\"}, {\"price\":\"0.68\", \"size\":\"11.97\"}, {\"price\":\"0.67\", \"size\":\"36\"}, {\"price\":\"0.66\", \"size\":\"6\"}, {\"price\":\"0.65\", \"size\":\"25\"}, {\"price\":\"0.64\", \"size\":\"35\"}, {\"price\":\"0.63\", \"size\":\"53.93\"}, {\"price\":\"0.62\", \"size\":\"18\"}, {\"price\":\"0.61\", \"size\":\"48\"}, {\"price\":\"0.6\", \"size\":\"36\"}, {\"price\":\"0.59\", \"size\":\"23\"}, {\"price\":\"0.58\", \"size\":\"52\"}, {\"price\":\"0.57\", \"size\":\"27\"}, {\"price\":\"0.56\", \"size\":\"107\"}, {\"price\":\"0.55\", \"size\":\"68\"}, {\"price\":\"0.54\", \"size\":\"21\"}, {\"price\":\"0.53\", \"size\":\"11\"}, {\"price\":\"0.52\", \"size\":\"57\"}, {\"price\":\"0.51\", \"size\":\"94.02\"}, {\"price\":\"0.5\", \"size\":\"180\"}, {\"price\":\"0.49\", \"size\":\"72.64\"}, {\"price\":\"0.48\", \"size\":\"122\"}, {\"price\":\"0.47\", \"size\":\"145.86\"}, {\"price\":\"0.46\", \"size\":\"266.64\"}, {\"price\":\"0.45\", \"size\":\"30.68\"}, {\"price\":\"0.44\", \"size\":\"97.52\"}, {\"price\":\"0.43\", \"size\":\"68.57\"}, {\"price\":\"0.42\", \"size\":\"39.01\"}, {\"price\":\"0.41\", \"size\":\"153.42\"}], \"hash\":\"45f5f40dad860b626f4a9411bddab64a0405a133\", \"timestamp\":\"1785126627584\", \"event_type\":\"book\"}","received_at":"2026-07-27T04:30:29.064685Z","schema_version":"clob-market-ws.book.v1","sequence":null,"server_hash":"45f5f40dad860b626f4a9411bddab64a0405a133","server_timestamp":"1785126627584","session_id":"e9443c7415a0419799bee9cfbb1a9e4d","source":"clob_market_ws"},"received_at":"2026-07-27T04:30:29.064685Z","record_id":"93e6412d939daaa93e9e1134abcf39100a54b470e068913cc10385a9802f9516","schema_fingerprint":"dc2caa1c89c6a7426e2e07ff925910cd4d0a8a223a515d4092d91d6d127aacb6","schema_version":"edge-lab-recorder.raw.v1","sequence":null,"source":"clob_market_ws"}
{"event_at":"2026-07-27T04:30:27.584000Z","event_fingerprint":"549eac0502ffc8fbf49036e53bcbf82c0de3bc552b6cf6f73571682978f9ae18","payload":{"connection_id":"0f4979d6978d463e9660b042fdcf555f","event_at":"2026-07-27T04:30:27.584000Z","event_type":"book","frame_hash":"8e9bd4807ad3fdec82d3b201479d70baae99765753d6652efe4f7fefd69d73f1","frame_index":0,"kind":"data","monotonic_ns":228612351723041,"payload":{"asks":[{"price":"0.99","size":"7733.02"},{"price":"0.98","size":"1723.1"},{"price":"0.97","size":"1166.43"},{"price":"0.96","size":"868.09"},{"price":"0.95","size":"618.2"},{"price":"0.94","size":"689"},{"price":"0.93","size":"556.14"},{"price":"0.92","size":"608"},{"price":"0.91","size":"515"},{"price":"0.9","size":"190"},{"price":"0.89","size":"13"},{"price":"0.88","size":"12"},{"price":"0.87","size":"41"},{"price":"0.86","size":"10"},{"price":"0.85","size":"10"},{"price":"0.84","size":"39"},{"price":"0.83","size":"9"},{"price":"0.82","size":"8"},{"price":"0.81","size":"38"},{"price":"0.8","size":"43"},{"price":"0.79","size":"8"},{"price":"0.78","size":"37"},{"price":"0.77","size":"7"},{"price":"0.76","size":"7"},{"price":"0.75","size":"265"},{"price":"0.74","size":"106"},{"price":"0.73","size":"6"},{"price":"0.72","size":"123.66"},{"price":"0.71","size":"123"},{"price":"0.7","size":"47"},{"price":"0.69","size":"52"},{"price":"0.68","size":"22"},{"price":"0.67","size":"15"},{"price":"0.66","size":"51"},{"price":"0.65","size":"27"},{"price":"0.64","size":"26.87"},{"price":"0.63","size":"26.74"},{"price":"0.62","size":"13"},{"price":"0.6","size":"1.46"}],"asset_id":"60386828328910021732068595344565885737045900010034836345809386672230885527307","bids":[{"price":"0.01","size":"7703.02"},{"price":"0.02","size":"1733.1"},{"price":"0.03","size":"1063.1"},{"price":"0.04","size":"838.09"},{"price":"0.05","size":"858.2"},{"price":"0.06","size":"719"},{"price":"0.07","size":"507.14"},{"price":"0.08","size":"591"},{"price":"0.09","size":"530"},{"price":"0.1","size":"216"},{"price":"0.12","size":"30"},{"price":"0.15","size":"77"},{"price":"0.18","size":"30"},{"price":"0.2","size":"35"},{"price":"0.21","size":"30"},{"price":"0.24","size":"30"},{"price":"0.25","size":"28"},{"price":"0.26","size":"6"},{"price":"0.27","size":"36"},{"price":"0.28","size":"6"},{"price":"0.29","size":"6"},{"price":"0.3","size":"60"},{"price":"0.31","size":"6"},{"price":"0.32","size":"11.97"},{"price":"0.33","size":"36"},{"price":"0.34","size":"6"},{"price":"0.35","size":"25"},{"price":"0.36","size":"35"},{"price":"0.37","size":"53.93"},{"price":"0.38","size":"18"},{"price":"0.39","size":"48"},{"price":"0.4","size":"36"},{"price":"0.41","size":"23"},{"price":"0.42","size":"52"},{"price":"0.43","size":"27"},{"price":"0.44","size":"107"},{"price":"0.45","size":"68"},{"price":"0.46","size":"21"},{"price":"0.47","size":"11"},{"price":"0.48","size":"57"},{"price":"0.49","size":"94.02"},{"price":"0.5","size":"180"},{"price":"0.51","size":"72.64"},{"price":"0.52","size":"122"},{"price":"0.53","size":"145.86"},{"price":"0.54","size":"266.64"},{"price":"0.55","size":"30.68"},{"price":"0.56","size":"97.52"},{"price":"0.57","size":"68.57"},{"price":"0.58","size":"39.01"},{"price":"0.59","size":"153.42"}],"event_type":"book","hash":"e1955bb8c955c7cf5ab0d68569ff20f13ba44a5a","market":"0xeb66215f2e9faa6449e30a02bab5b8ed7b79a38bf961f6b24d0073c9c2419250","timestamp":"1785126627584"},"payload_hash":"89836a78e144b1fad78ec53112ee65f30859785372238fec6dab9ccd4a8fedc6","raw_frame":"{\"market\":\"0xeb66215f2e9faa6449e30a02bab5b8ed7b79a38bf961f6b24d0073c9c2419250\", \"asset_id\":\"60386828328910021732068595344565885737045900010034836345809386672230885527307\", \"bids\":[{\"price\":\"0.01\", \"size\":\"7703.02\"}, {\"price\":\"0.02\", \"size\":\"1733.1\"}, {\"price\":\"0.03\", \"size\":\"1063.1\"}, {\"price\":\"0.04\", \"size\":\"838.09\"}, {\"price\":\"0.05\", \"size\":\"858.2\"}, {\"price\":\"0.06\", \"size\":\"719\"}, {\"price\":\"0.07\", \"size\":\"507.14\"}, {\"price\":\"0.08\", \"size\":\"591\"}, {\"price\":\"0.09\", \"size\":\"530\"}, {\"price\":\"0.1\", \"size\":\"216\"}, {\"price\":\"0.12\", \"size\":\"30\"}, {\"price\":\"0.15\", \"size\":\"77\"}, {\"price\":\"0.18\", \"size\":\"30\"}, {\"price\":\"0.2\", \"size\":\"35\"}, {\"price\":\"0.21\", \"size\":\"30\"}, {\"price\":\"0.24\", \"size\":\"30\"}, {\"price\":\"0.25\", \"size\":\"28\"}, {\"price\":\"0.26\", \"size\":\"6\"}, {\"price\":\"0.27\", \"size\":\"36\"}, {\"price\":\"0.28\", \"size\":\"6\"}, {\"price\":\"0.29\", \"size\":\"6\"}, {\"price\":\"0.3\", \"size\":\"60\"}, {\"price\":\"0.31\", \"size\":\"6\"}, {\"price\":\"0.32\", \"size\":\"11.97\"}, {\"price\":\"0.33\", \"size\":\"36\"}, {\"price\":\"0.34\", \"size\":\"6\"}, {\"price\":\"0.35\", \"size\":\"25\"}, {\"price\":\"0.36\", \"size\":\"35\"}, {\"price\":\"0.37\", \"size\":\"53.93\"}, {\"price\":\"0.38\", \"size\":\"18\"}, {\"price\":\"0.39\", \"size\":\"48\"}, {\"price\":\"0.4\", \"size\":\"36\"}, {\"price\":\"0.41\", \"size\":\"23\"}, {\"price\":\"0.42\", \"size\":\"52\"}, {\"price\":\"0.43\", \"size\":\"27\"}, {\"price\":\"0.44\", \"size\":\"107\"}, {\"price\":\"0.45\", \"size\":\"68\"}, {\"price\":\"0.46\", \"size\":\"21\"}, {\"price\":\"0.47\", \"size\":\"11\"}, {\"price\":\"0.48\", \"size\":\"57\"}, {\"price\":\"0.49\", \"size\":\"94.02\"}, {\"price\":\"0.5\", \"size\":\"180\"}, {\"price\":\"0.51\", \"size\":\"72.64\"}, {\"price\":\"0.52\", \"size\":\"122\"}, {\"price\":\"0.53\", \"size\":\"145.86\"}, {\"price\":\"0.54\", \"size\":\"266.64\"}, {\"price\":\"0.55\", \"size\":\"30.68\"}, {\"price\":\"0.56\", \"size\":\"97.52\"}, {\"price\":\"0.57\", \"size\":\"68.57\"}, {\"price\":\"0.58\", \"size\":\"39.01\"}, {\"price\":\"0.59\", \"size\":\"153.42\"}], \"asks\":[{\"price\":\"0.99\", \"size\":\"7733.02\"}, {\"price\":\"0.98\", \"size\":\"1723.1\"}, {\"price\":\"0.97\", \"size\":\"1166.43\"}, {\"price\":\"0.96\", \"size\":\"868.09\"}, {\"price\":\"0.95\", \"size\":\"618.2\"}, {\"price\":\"0.94\", \"size\":\"689\"}, {\"price\":\"0.93\", \"size\":\"556.14\"}, {\"price\":\"0.92\", \"size\":\"608\"}, {\"price\":\"0.91\", \"size\":\"515\"}, {\"price\":\"0.9\", \"size\":\"190\"}, {\"price\":\"0.89\", \"size\":\"13\"}, {\"price\":\"0.88\", \"size\":\"12\"}, {\"price\":\"0.87\", \"size\":\"41\"}, {\"price\":\"0.86\", \"size\":\"10\"}, {\"price\":\"0.85\", \"size\":\"10\"}, {\"price\":\"0.84\", \"size\":\"39\"}, {\"price\":\"0.83\", \"size\":\"9\"}, {\"price\":\"0.82\", \"size\":\"8\"}, {\"price\":\"0.81\", \"size\":\"38\"}, {\"price\":\"0.8\", \"size\":\"43\"}, {\"price\":\"0.79\", \"size\":\"8\"}, {\"price\":\"0.78\", \"size\":\"37\"}, {\"price\":\"0.77\", \"size\":\"7\"}, {\"price\":\"0.76\", \"size\":\"7\"}, {\"price\":\"0.75\", \"size\":\"265\"}, {\"price\":\"0.74\", \"size\":\"106\"}, {\"price\":\"0.73\", \"size\":\"6\"}, {\"price\":\"0.72\", \"size\":\"123.66\"}, {\"price\":\"0.71\", \"size\":\"123\"}, {\"price\":\"0.7\", \"size\":\"47\"}, {\"price\":\"0.69\", \"size\":\"52\"}, {\"price\":\"0.68\", \"size\":\"22\"}, {\"price\":\"0.67\", \"size\":\"15\"}, {\"price\":\"0.66\", \"size\":\"51\"}, {\"price\":\"0.65\", \"size\":\"27\"}, {\"price\":\"0.64\", \"size\":\"26.87\"}, {\"price\":\"0.63\", \"size\":\"26.74\"}, {\"price\":\"0.62\", \"size\":\"13\"}, {\"price\":\"0.6\", \"size\":\"1.46\"}], \"hash\":\"e1955bb8c955c7cf5ab0d68569ff20f13ba44a5a\", \"timestamp\":\"1785126627584\", \"event_type\":\"book\"}","received_at":"2026-07-27T04:30:29.082137Z","schema_version":"clob-market-ws.book.v1","sequence":null,"server_hash":"e1955bb8c955c7cf5ab0d68569ff20f13ba44a5a","server_timestamp":"1785126627584","session_id":"e9443c7415a0419799bee9cfbb1a9e4d","source":"clob_market_ws"},"received_at":"2026-07-27T04:30:29.082137Z","record_id":"cf67d19fd0694c7254a193e09e2c731eb742b25c62feec3ababc0fb82eb212df","schema_fingerprint":"dc2caa1c89c6a7426e2e07ff925910cd4d0a8a223a515d4092d91d6d127aacb6","schema_version":"edge-lab-recorder.raw.v1","sequence":null,"source":"clob_market_ws"}
{"event_at":"2026-07-27T04:30:27.592000Z","event_fingerprint":"8d7712a29044c45733d73b5ff73e4a4a66fd78a1f6e1601feb692ffea10a9827","payload":{"connection_id":"0f4979d6978d463e9660b042fdcf555f","event_at":"2026-07-27T04:30:27.592000Z","event_type":"price_change","frame_hash":"2c1e04b246a5fe84c5d029e97c6a3ce075068b5b18d0528ce535c5eb240f8620","frame_index":0,"kind":"data","monotonic_ns":228612390083916,"payload":{"event_type":"price_change","market":"0xeb66215f2e9faa6449e30a02bab5b8ed7b79a38bf961f6b24d0073c9c2419250","price_changes":[{"asset_id":"60386828328910021732068595344565885737045900010034836345809386672230885527307","best_ask":"0.6","best_bid":"0.59","hash":"627da2d81b07b8b9b033c5adbbdfe3772ed5ae7d","price":"0.48","side":"BUY","size":"157"},{"asset_id":"69697746896130839564035629862476347944307040470122503199396727085502753297492","best_ask":"0.41","best_bid":"0.4","hash":"a24b5cc390ed5f7cd8b73c8368b1a6dd0914e570","price":"0.52","side":"SELL","size":"157"}],"timestamp":"1785126627592"},"payload_hash":"05e8ca5975e97e18ece7b99b5434a42937a29988439eb85240abf97d080ef8e0","raw_frame":"{\"market\":\"0xeb66215f2e9faa6449e30a02bab5b8ed7b79a38bf961f6b24d0073c9c2419250\", \"price_changes\":[{\"asset_id\":\"60386828328910021732068595344565885737045900010034836345809386672230885527307\", \"price\":\"0.48\", \"size\":\"157\", \"side\":\"BUY\", \"hash\":\"627da2d81b07b8b9b033c5adbbdfe3772ed5ae7d\", \"best_bid\":\"0.59\", \"best_ask\":\"0.6\"}, {\"asset_id\":\"69697746896130839564035629862476347944307040470122503199396727085502753297492\", \"price\":\"0.52\", \"size\":\"157\", \"side\":\"SELL\", \"hash\":\"a24b5cc390ed5f7cd8b73c8368b1a6dd0914e570\", \"best_bid\":\"0.4\", \"best_ask\":\"0.41\"}], \"timestamp\":\"1785126627592\", \"event_type\":\"price_change\"}","received_at":"2026-07-27T04:30:29.120495Z","schema_version":"clob-market-ws.price_change.v1","sequence":null,"server_hash":null,"server_timestamp":"1785126627592","session_id":"e9443c7415a0419799bee9cfbb1a9e4d","source":"clob_market_ws"},"received_at":"2026-07-27T04:30:29.120495Z","record_id":"43c21bd1273578807fc483215d7d1524b10ba2005158bc54781a31b6c334a96f","schema_fingerprint":"4aa3821a28b0b7c2400bc59aba4bcc0a76e971dadd19610d3ad38c768e124dc7","schema_version":"edge-lab-recorder.raw.v1","sequence":null,"source":"clob_market_ws"}
{"event_at":"2026-07-27T04:30:27.593000Z","event_fingerprint":"e81b0b251af7af543e0f07558d167a38b7c9c515444829c87ba8bfdaa4eab471","payload":{"connection_id":"0f4979d6978d463e9660b042fdcf555f","event_at":"2026-07-27T04:30:27.593000Z","event_type":"price_change","frame_hash":"3b2838ba4af2f737c969900c34ab5f0088061db6a4a4a2545593e4b7e2bbdae5","frame_index":0,"kind":"data","monotonic_ns":228612400653666,"payload":{"event_type":"price_change","market":"0xeb66215f2e9faa6449e30a02bab5b8ed7b79a38bf961f6b24d0073c9c2419250","price_changes":[{"asset_id":"60386828328910021732068595344565885737045900010034836345809386672230885527307","best_ask":"0.6","best_bid":"0.59","hash":"de76ada4ad0b54004bf2bb05c3285f3c9914ba5b","price":"0.32","side":"BUY","size":"6"},{"asset_id":"69697746896130839564035629862476347944307040470122503199396727085502753297492","best_ask":"0.41","best_bid":"0.4","hash":"454db2137ec3e9671b2a02c9ccba802a60b7ccb4","price":"0.68","side":"SELL","size":"6"}],"timestamp":"1785126627593"},"payload_hash":"28958cd031d650ae3bb71941ed28430addc3e73fec6630fc447c74aeb7f2a29c","raw_frame":"{\"market\":\"0xeb66215f2e9faa6449e30a02bab5b8ed7b79a38bf961f6b24d0073c9c2419250\", \"price_changes\":[{\"asset_id\":\"60386828328910021732068595344565885737045900010034836345809386672230885527307\", \"price\":\"0.32\", \"size\":\"6\", \"side\":\"BUY\", \"hash\":\"de76ada4ad0b54004bf2bb05c3285f3c9914ba5b\", \"best_bid\":\"0.59\", \"best_ask\":\"0.6\"}, {\"asset_id\":\"69697746896130839564035629862476347944307040470122503199396727085502753297492\", \"price\":\"0.68\", \"size\":\"6\", \"side\":\"SELL\", \"hash\":\"454db2137ec3e9671b2a02c9ccba802a60b7ccb4\", \"best_bid\":\"0.4\", \"best_ask\":\"0.41\"}], \"timestamp\":\"1785126627593\", \"event_type\":\"price_change\"}","received_at":"2026-07-27T04:30:29.131068Z","schema_version":"clob-market-ws.price_change.v1","sequence":null,"server_hash":null,"server_timestamp":"1785126627593","session_id":"e9443c7415a0419799bee9cfbb1a9e4d","source":"clob_market_ws"},"received_at":"2026-07-27T04:30:29.131068Z","record_id":"13625b75d9f674f252d5bee4a6c82cb5bb0777fd077dd0406a62e8383651120c","schema_fingerprint":"4aa3821a28b0b7c2400bc59aba4bcc0a76e971dadd19610d3ad38c768e124dc7","schema_version":"edge-lab-recorder.raw.v1","sequence":null,"source":"clob_market_ws"}
{"event_at":"2026-07-27T04:30:27.593000Z","event_fingerprint":"2cb1e7e5d50f1828d8feb9cec050e2cea393f4332596a1b152d7f872f0e537f8","payload":{"connection_id":"0f4979d6978d463e9660b042fdcf555f","event_at":"2026-07-27T04:30:27.593000Z","event_type":"price_change","frame_hash":"7a9742749c7cdfeb9bdb93ec331503b853b07a68ffb5dc9fe58d399dcc525c84","frame_index":0,"kind":"data","monotonic_ns":228612412298916,"payload":{"event_type":"price_change","market":"0xeb66215f2e9faa6449e30a02bab5b8ed7b79a38bf961f6b24d0073c9c2419250","price_changes":[{"asset_id":"69697746896130839564035629862476347944307040470122503199396727085502753297492","best_ask":"0.41","best_bid":"0.4","hash":"6cb7292675ed90611626c1b2036925d23dac19cc","price":"0.06","side":"BUY","size":"742.2"},{"asset_id":"60386828328910021732068595344565885737045900010034836345809386672230885527307","best_ask":"0.6","best_bid":"0.59","hash":"33963a3870298a7d6b4a0001ce5556cbd1b25f40","price":"0.94","side":"SELL","size":"742.2"}],"timestamp":"1785126627593"},"payload_hash":"8ef9da5b7bbf7aaaae209aa239a011f2ea8e423a4df4dcaf09d717f989cdd878","raw_frame":"{\"market\":\"0xeb66215f2e9faa6449e30a02bab5b8ed7b79a38bf961f6b24d0073c9c2419250\", \"price_changes\":[{\"asset_id\":\"69697746896130839564035629862476347944307040470122503199396727085502753297492\", \"price\":\"0.06\", \"size\":\"742.2\", \"side\":\"BUY\", \"hash\":\"6cb7292675ed90611626c1b2036925d23dac19cc\", \"best_bid\":\"0.4\", \"best_ask\":\"0.41\"}, {\"asset_id\":\"60386828328910021732068595344565885737045900010034836345809386672230885527307\", \"price\":\"0.94\", \"size\":\"742.2\", \"side\":\"SELL\", \"hash\":\"33963a3870298a7d6b4a0001ce5556cbd1b25f40\", \"best_bid\":\"0.59\", \"best_ask\":\"0.6\"}], \"timestamp\":\"1785126627593\", \"event_type\":\"price_change\"}","received_at":"2026-07-27T04:30:29.142714Z","schema_version":"clob-market-ws.price_change.v1","sequence":null,"server_hash":null,"server_timestamp":"1785126627593","session_id":"e9443c7415a0419799bee9cfbb1a9e4d","source":"clob_market_ws"},"received_at":"2026-07-27T04:30:29.142714Z","record_id":"949a1b6f1eaa30c5f293d9e247970f30ae498756755e46676cd58eb674cdee90","schema_fingerprint":"4aa3821a28b0b7c2400bc59aba4bcc0a76e971dadd19610d3ad38c768e124dc7","schema_version":"edge-lab-recorder.raw.v1","sequence":null,"source":"clob_market_ws"}
{"event_at":"2026-07-27T04:30:27.599000Z","event_fingerprint":"5d88e7d19697c9d70a7e18ad9b8c5e233b4a3b45a0bc1930439531093cfaf11c","payload":{"connection_id":"0f4979d6978d463e9660b042fdcf555f","event_at":"2026-07-27T04:30:27.599000Z","event_type":"price_change","frame_hash":"2f1d53329106bb599058b120fbec38467ff2fe29df540ebbe8d3c0ea94c53131","frame_index":0,"kind":"data","monotonic_ns":228612421010458,"payload":{"event_type":"price_change","market":"0xeb66215f2e9faa6449e30a02bab5b8ed7b79a38bf961f6b24d0073c9c2419250","price_changes":[{"asset_id":"69697746896130839564035629862476347944307040470122503199396727085502753297492","best_ask":"0.41","best_bid":"0.4","hash":"361dffed55fe7ea78983b7583ff827a95b2162a6","price":"0.38","side":"BUY","size":"0"},{"asset_id":"60386828328910021732068595344565885737045900010034836345809386672230885527307","best_ask":"0.6","best_bid":"0.59","hash":"b604c59f5a54af8ccf402d3869b10558131e29a9","price":"0.62","side":"SELL","size":"0"}],"timestamp":"1785126627599"},"payload_hash":"0f93206d57eff6dacd0bd686cb381e75c6e4eb963969512b61ba13f42661e2e8","raw_frame":"{\"market\":\"0xeb66215f2e9faa6449e30a02bab5b8ed7b79a38bf961f6b24d0073c9c2419250\", \"price_changes\":[{\"asset_id\":\"69697746896130839564035629862476347944307040470122503199396727085502753297492\", \"price\":\"0.38\", \"size\":\"0\", \"side\":\"BUY\", \"hash\":\"361dffed55fe7ea78983b7583ff827a95b2162a6\", \"best_bid\":\"0.4\", \"best_ask\":\"0.41\"}, {\"asset_id\":\"60386828328910021732068595344565885737045900010034836345809386672230885527307\", \"price\":\"0.62\", \"size\":\"0\", \"side\":\"SELL\", \"hash\":\"b604c59f5a54af8ccf402d3869b10558131e29a9\", \"best_bid\":\"0.59\", \"best_ask\":\"0.6\"}], \"timestamp\":\"1785126627599\", \"event_type\":\"price_change\"}","received_at":"2026-07-27T04:30:29.151426Z","schema_version":"clob-market-ws.price_change.v1","sequence":null,"server_hash":null,"server_timestamp":"1785126627599","session_id":"e9443c7415a0419799bee9cfbb1a9e4d","source":"clob_market_ws"},"received_at":"2026-07-27T04:30:29.151426Z","record_id":"8fe50690814fca0764959e569de0e29f424739f67943b5212037cdc555df9191","schema_fingerprint":"4aa3821a28b0b7c2400bc59aba4bcc0a76e971dadd19610d3ad38c768e124dc7","schema_version":"edge-lab-recorder.raw.v1","sequence":null,"source":"clob_market_ws"}
{"event_at":"2026-07-27T04:30:27.600000Z","event_fingerprint":"abb42c4c3911d49c591ab7c808818044454127f6aa0299487135959083d86351","payload":{"connection_id":"0f4979d6978d463e9660b042fdcf555f","event_at":"2026-07-27T04:30:27.600000Z","event_type":"price_change","frame_hash":"35fd05d34f316ea9b0b7ae8119b6d877001dbb015c4f33d9aebe32065ec73469","frame_index":0,"kind":"data","monotonic_ns":228612432254875,"payload":{"event_type":"price_change","market":"0xeb66215f2e9faa6449e30a02bab5b8ed7b79a38bf961f6b24d0073c9c2419250","price_changes":[{"asset_id":"69697746896130839564035629862476347944307040470122503199396727085502753297492","best_ask":"0.41","best_bid":"0.4","hash":"728ea44c4dfba3da6d208bac17a3ec10fee48d04","price":"0.37","side":"BUY","size":"12.74"},{"asset_id":"60386828328910021732068595344565885737045900010034836345809386672230885527307","best_ask":"0.6","best_bid":"0.59","hash":"5359e7edd4d14c96d7f049bf9385f2b03fd3ce83","price":"0.63","side":"SELL","size":"12.74"}],"timestamp":"1785126627600"},"payload_hash":"79e9337233f8845ac224bd5d9e58138aef4a4e1f2ed61da43b32e00d5e5c6e9d","raw_frame":"{\"market\":\"0xeb66215f2e9faa6449e30a02bab5b8ed7b79a38bf961f6b24d0073c9c2419250\", \"price_changes\":[{\"asset_id\":\"69697746896130839564035629862476347944307040470122503199396727085502753297492\", \"price\":\"0.37\", \"size\":\"12.74\", \"side\":\"BUY\", \"hash\":\"728ea44c4dfba3da6d208bac17a3ec10fee48d04\", \"best_bid\":\"0.4\", \"best_ask\":\"0.41\"}, {\"asset_id\":\"60386828328910021732068595344565885737045900010034836345809386672230885527307\", \"price\":\"0.63\", \"size\":\"12.74\", \"side\":\"SELL\", \"hash\":\"5359e7edd4d14c96d7f049bf9385f2b03fd3ce83\", \"best_bid\":\"0.59\", \"best_ask\":\"0.6\"}], \"timestamp\":\"1785126627600\", \"event_type\":\"price_change\"}","received_at":"2026-07-27T04:30:29.162669Z","schema_version":"clob-market-ws.price_change.v1","sequence":null,"server_hash":null,"server_timestamp":"1785126627600","session_id":"e9443c7415a0419799bee9cfbb1a9e4d","source":"clob_market_ws"},"received_at":"2026-07-27T04:30:29.162669Z","record_id":"4732209b9e8a3161217fa11241ff695a89fa912a9fc4056a31de362d5ed1306c","schema_fingerprint":"4aa3821a28b0b7c2400bc59aba4bcc0a76e971dadd19610d3ad38c768e124dc7","schema_version":"edge-lab-recorder.raw.v1","sequence":null,"source":"clob_market_ws"}
{"event_at":"2026-07-27T04:30:27.600000Z","event_fingerprint":"3e13f00162dba3b3fedd5e654df919303a9e2916b8c1707deab38a5f0735cb13","payload":{"connection_id":"0f4979d6978d463e9660b042fdcf555f","event_at":"2026-07-27T04:30:27.600000Z","event_type":"price_change","frame_hash":"ec89b94ee2c314162c800b76768966a263dbe3c920cc345f7871a91942d12c22","frame_index":0,"kind":"data","monotonic_ns":228612443199875,"payload":{"event_type":"price_change","market":"0xeb66215f2e9faa6449e30a02bab5b8ed7b79a38bf961f6b24d0073c9c2419250","price_changes":[{"asset_id":"69697746896130839564035629862476347944307040470122503199396727085502753297492","best_ask":"0.41","best_bid":"0.4","hash":"e920a51acbdf81bc2adc2d6267b80165abb430bf","price":"0.37","side":"BUY","size":"0"},{"asset_id":"60386828328910021732068595344565885737045900010034836345809386672230885527307","best_ask":"0.6","best_bid":"0.59","hash":"b91270001f61fc4bc27ce0116a3e5e7176e5aea3","price":"0.63","side":"SELL","size":"0"}],"timestamp":"1785126627600"},"payload_hash":"117a1655647bd8e996b3786fd8c45440d2667637b5bc416c34bac5d68e1bbb67","raw_frame":"{\"market\":\"0xeb66215f2e9faa6449e30a02bab5b8ed7b79a38bf961f6b24d0073c9c2419250\", \"price_changes\":[{\"asset_id\":\"69697746896130839564035629862476347944307040470122503199396727085502753297492\", \"price\":\"0.37\", \"size\":\"0\", \"side\":\"BUY\", \"hash\":\"e920a51acbdf81bc2adc2d6267b80165abb430bf\", \"best_bid\":\"0.4\", \"best_ask\":\"0.41\"}, {\"asset_id\":\"60386828328910021732068595344565885737045900010034836345809386672230885527307\", \"price\":\"0.63\", \"size\":\"0\", \"side\":\"SELL\", \"hash\":\"b91270001f61fc4bc27ce0116a3e5e7176e5aea3\", \"best_bid\":\"0.59\", \"best_ask\":\"0.6\"}], \"timestamp\":\"1785126627600\", \"event_type\":\"price_change\"}","received_at":"2026-07-27T04:30:29.173614Z","schema_version":"clob-market-ws.price_change.v1","sequence":null,"server_hash":null,"server_timestamp":"1785126627600","session_id":"e9443c7415a0419799bee9cfbb1a9e4d","source":"clob_market_ws"},"received_at":"2026-07-27T04:30:29.173614Z","record_id":"379b34a696991d152700ebfa865ac90261c96eea91c34fa725a6cfef36af15e7","schema_fingerprint":"4aa3821a28b0b7c2400bc59aba4bcc0a76e971dadd19610d3ad38c768e124dc7","schema_version":"edge-lab-recorder.raw.v1","sequence":null,"source":"clob_market_ws"}
{"event_at":"2026-07-27T04:30:27.600000Z","event_fingerprint":"d0b77121fbfd6da36a201ba0521e039319617704f3a47e04f8f07a94716c5333","payload":{"connection_id":"0f4979d6978d463e9660b042fdcf555f","event_at":"2026-07-27T04:30:27.600000Z","event_type":"price_change","frame_hash":"185b4c1d3bf4ee3e605a2c409582ba77864b7dbc52ee37e1374a39efee92839f","frame_index":0,"kind":"data","monotonic_ns":228612451626500,"payload":{"event_type":"price_change","market":"0xeb66215f2e9faa6449e30a02bab5b8ed7b79a38bf961f6b24d0073c9c2419250","price_changes":[{"asset_id":"69697746896130839564035629862476347944307040470122503199396727085502753297492","best_ask":"0.41","best_bid":"0.4","hash":"e920a51acbdf81bc2adc2d6267b80165abb430bf","price":"0.36","side":"BUY","size":"14"},{"asset_id":"60386828328910021732068595344565885737045900010034836345809386672230885527307","best_ask":"0.6","best_bid":"0.59","hash":"b91270001f61fc4bc27ce0116a3e5e7176e5aea3","price":"0.64","side":"SELL","size":"14"}],"timestamp":"1785126627600"},"payload_hash":"6f5167f511a0fc2fa57b8d5b402ab710a1bab9792482af6902a0a9dadc446e7b","raw_frame":"{\"market\":\"0xeb66215f2e9faa6449e30a02bab5b8ed7b79a38bf961f6b24d0073c9c2419250\", \"price_changes\":[{\"asset_id\":\"69697746896130839564035629862476347944307040470122503199396727085502753297492\", \"price\":\"0.36\", \"size\":\"14\", \"side\":\"BUY\", \"hash\":\"e920a51acbdf81bc2adc2d6267b80165abb430bf\", \"best_bid\":\"0.4\", \"best_ask\":\"0.41\"}, {\"asset_id\":\"60386828328910021732068595344565885737045900010034836345809386672230885527307\", \"price\":\"0.64\", \"size\":\"14\", \"side\":\"SELL\", \"hash\":\"b91270001f61fc4bc27ce0116a3e5e7176e5aea3\", \"best_bid\":\"0.59\", \"best_ask\":\"0.6\"}], \"timestamp\":\"1785126627600\", \"event_type\":\"price_change\"}","received_at":"2026-07-27T04:30:29.182041Z","schema_version":"clob-market-ws.price_change.v1","sequence":null,"server_hash":null,"server_timestamp":"1785126627600","session_id":"e9443c7415a0419799bee9cfbb1a9e4d","source":"clob_market_ws"},"received_at":"2026-07-27T04:30:29.182041Z","record_id":"64b2b670fe06d79fc55430eb8e339f33dbcfbabdcd5967161203f426d0b26a6e","schema_fingerprint":"4aa3821a28b0b7c2400bc59aba4bcc0a76e971dadd19610d3ad38c768e124dc7","schema_version":"edge-lab-recorder.raw.v1","sequence":null,"source":"clob_market_ws"}
{"event_at":"2026-07-27T04:30:27.600000Z","event_fingerprint":"5029cd130fccfcab87716954b4a84fefb0748fb6a95cf10d9f1f99656ab542cf","payload":{"connection_id":"0f4979d6978d463e9660b042fdcf555f","event_at":"2026-07-27T04:30:27.600000Z","event_type":"price_change","frame_hash":"61e465b2eb1e4c7b768ef952c9e07356b5e6f2c6d7fdc259841597dd4e0afabe","frame_index":0,"kind":"data","monotonic_ns":228612462258208,"payload":{"event_type":"price_change","market":"0xeb66215f2e9faa6449e30a02bab5b8ed7b79a38bf961f6b24d0073c9c2419250","price_changes":[{"asset_id":"69697746896130839564035629862476347944307040470122503199396727085502753297492","best_ask":"0.41","best_bid":"0.4","hash":"e920a51acbdf81bc2adc2d6267b80165abb430bf","price":"0.35","side":"BUY","size":"14"},{"asset_id":"60386828328910021732068595344565885737045900010034836345809386672230885527307","best_ask":"0.6","best_bid":"0.59","hash":"b91270001f61fc4bc27ce0116a3e5e7176e5aea3","price":"0.65","side":"SELL","size":"14"}],"timestamp":"1785126627600"},"payload_hash":"adf455c6a00dc292d233326628eb6592b0775fc8838cfc0d1271e1ef098d903e","raw_frame":"{\"market\":\"0xeb66215f2e9faa6449e30a02bab5b8ed7b79a38bf961f6b24d0073c9c2419250\", \"price_changes\":[{\"asset_id\":\"69697746896130839564035629862476347944307040470122503199396727085502753297492\", \"price\":\"0.35\", \"size\":\"14\", \"side\":\"BUY\", \"hash\":\"e920a51acbdf81bc2adc2d6267b80165abb430bf\", \"best_bid\":\"0.4\", \"best_ask\":\"0.41\"}, {\"asset_id\":\"60386828328910021732068595344565885737045900010034836345809386672230885527307\", \"price\":\"0.65\", \"size\":\"14\", \"side\":\"SELL\", \"hash\":\"b91270001f61fc4bc27ce0116a3e5e7176e5aea3\", \"best_bid\":\"0.59\", \"best_ask\":\"0.6\"}], \"timestamp\":\"1785126627600\", \"event_type\":\"price_change\"}","received_at":"2026-07-27T04:30:29.192672Z","schema_version":"clob-market-ws.price_change.v1","sequence":null,"server_hash":null,"server_timestamp":"1785126627600","session_id":"e9443c7415a0419799bee9cfbb1a9e4d","source":"clob_market_ws"},"received_at":"2026-07-27T04:30:29.192672Z","record_id":"2cbba378c330bd37f6353d021eb531dad8b6b7ac070a7ebf49c528869f01bd5e","schema_fingerprint":"4aa3821a28b0b7c2400bc59aba4bcc0a76e971dadd19610d3ad38c768e124dc7","schema_version":"edge-lab-recorder.raw.v1","sequence":null,"source":"clob_market_ws"}
{"event_at":"2026-07-27T04:30:27.600000Z","event_fingerprint":"ec3981448bc6d1a14fa76ebec4d01a6243086badd05247ce842e0618a2232d50","payload":{"connection_id":"0f4979d6978d463e9660b042fdcf555f","event_at":"2026-07-27T04:30:27.600000Z","event_type":"price_change","frame_hash":"85b990baf348cfef80d1975d476a440e9a6f3ccb38afcada29814e7a7bdd49ec","frame_index":0,"kind":"data","monotonic_ns":228612475437583,"payload":{"event_type":"price_change","market":"0xeb66215f2e9faa6449e30a02bab5b8ed7b79a38bf961f6b24d0073c9c2419250","price_changes":[{"asset_id":"60386828328910021732068595344565885737045900010034836345809386672230885527307","best_ask":"0.6","best_bid":"0.59","hash":"34cfd81d9f5a4273767af45561de32cfac165b32","price":"0.55","side":"BUY","size":"18.6"},{"asset_id":"69697746896130839564035629862476347944307040470122503199396727085502753297492","best_ask":"0.41","best_bid":"0.4","hash":"d3b1e19a9888d64bb3716e5dd659fb8948fdcd78","price":"0.45","side":"SELL","size":"18.6"}],"timestamp":"1785126627600"},"payload_hash":"724a1c5e9bd15b4aa4924101e860bb75a71201bb4fe3088e455a1a6b0ce6bd0e","raw_frame":"{\"market\":\"0xeb66215f2e9faa6449e30a02bab5b8ed7b79a38bf961f6b24d0073c9c2419250\", \"price_changes\":[{\"asset_id\":\"60386828328910021732068595344565885737045900010034836345809386672230885527307\", \"price\":\"0.55\", \"size\":\"18.6\", \"side\":\"BUY\", \"hash\":\"34cfd81d9f5a4273767af45561de32cfac165b32\", \"best_bid\":\"0.59\", \"best_ask\":\"0.6\"}, {\"asset_id\":\"69697746896130839564035629862476347944307040470122503199396727085502753297492\", \"price\":\"0.45\", \"size\":\"18.6\", \"side\":\"SELL\", \"hash\":\"d3b1e19a9888d64bb3716e5dd659fb8948fdcd78\", \"best_bid\":\"0.4\", \"best_ask\":\"0.41\"}], \"timestamp\":\"1785126627600\", \"event_type\":\"price_change\"}","received_at":"2026-07-27T04:30:29.205853Z","schema_version":"clob-market-ws.price_change.v1","sequence":null,"server_hash":null,"server_timestamp":"1785126627600","session_id":"e9443c7415a0419799bee9cfbb1a9e4d","source":"clob_market_ws"},"received_at":"2026-07-27T04:30:29.205853Z","record_id":"5be32fa6fb8cc0c05aadb425c82411789c0990e17047c84cc5e306c18981a8c8","schema_fingerprint":"4aa3821a28b0b7c2400bc59aba4bcc0a76e971dadd19610d3ad38c768e124dc7","schema_version":"edge-lab-recorder.raw.v1","sequence":null,"source":"clob_market_ws"}
{"event_at":"2026-07-27T04:30:27.600000Z","event_fingerprint":"b24d2b35df2f1ebf0e9752d6dea6c11bfc4b33c578ab288251454f3d6b4a0cb0","payload":{"connection_id":"0f4979d6978d463e9660b042fdcf555f","event_at":"2026-07-27T04:30:27.600000Z","event_type":"price_change","frame_hash":"6a7d94f4d4a4a3d1c880401206ea8a8d0d8823f30d364ac30761eae006be3112","frame_index":0,"kind":"data","monotonic_ns":228612486215833,"payload":{"event_type":"price_change","market":"0xeb66215f2e9faa6449e30a02bab5b8ed7b79a38bf961f6b24d0073c9c2419250","price_changes":[{"asset_id":"60386828328910021732068595344565885737045900010034836345809386672230885527307","best_ask":"0.6","best_bid":"0.59","hash":"34cfd81d9f5a4273767af45561de32cfac165b32","price":"0.54","side":"BUY","size":"254.6"},{"asset_id":"69697746896130839564035629862476347944307040470122503199396727085502753297492","best_ask":"0.41","best_bid":"0.4","hash":"d3b1e19a9888d64bb3716e5dd659fb8948fdcd78","price":"0.46","side":"SELL","size":"254.6"}],"timestamp":"1785126627600"},"payload_hash":"f7eead3a43318cd9376b72aa538bfc9a7e519bf6f3625bda378c808e819e298d","raw_frame":"{\"market\":\"0xeb66215f2e9faa6449e30a02bab5b8ed7b79a38bf961f6b24d0073c9c2419250\", \"price_changes\":[{\"asset_id\":\"60386828328910021732068595344565885737045900010034836345809386672230885527307\", \"price\":\"0.54\", \"size\":\"254.6\", \"side\":\"BUY\", \"hash\":\"34cfd81d9f5a4273767af45561de32cfac165b32\", \"best_bid\":\"0.59\", \"best_ask\":\"0.6\"}, {\"asset_id\":\"69697746896130839564035629862476347944307040470122503199396727085502753297492\", \"price\":\"0.46\", \"size\":\"254.6\", \"side\":\"SELL\", \"hash\":\"d3b1e19a9888d64bb3716e5dd659fb8948fdcd78\", \"best_bid\":\"0.4\", \"best_ask\":\"0.41\"}], \"timestamp\":\"1785126627600\", \"event_type\":\"price_change\"}","received_at":"2026-07-27T04:30:29.216633Z","schema_version":"clob-market-ws.price_change.v1","sequence":null,"server_hash":null,"server_timestamp":"1785126627600","session_id":"e9443c7415a0419799bee9cfbb1a9e4d","source":"clob_market_ws"},"received_at":"2026-07-27T04:30:29.216633Z","record_id":"952ba2e1ee4f9287e710ce8da2a90d0093bac69f8a52d8cc56babccc27a40159","schema_fingerprint":"4aa3821a28b0b7c2400bc59aba4bcc0a76e971dadd19610d3ad38c768e124dc7","schema_version":"edge-lab-recorder.raw.v1","sequence":null,"source":"clob_market_ws"}
{"event_at":"2026-07-27T04:30:27.600000Z","event_fingerprint":"27343e90ef55008f936416ae03feb23a068ff03f600099700434c08987a13c78","payload":{"connection_id":"0f4979d6978d463e9660b042fdcf555f","event_at":"2026-07-27T04:30:27.600000Z","event_type":"price_change","frame_hash":"9dd228058acfe4aacb4c2034ad85eec2c2b3af059def1393fe03a6015919fdeb","frame_index":0,"kind":"data","monotonic_ns":228612495081125,"payload":{"event_type":"price_change","market":"0xeb66215f2e9faa6449e30a02bab5b8ed7b79a38bf961f6b24d0073c9c2419250","price_changes":[{"asset_id":"60386828328910021732068595344565885737045900010034836345809386672230885527307","best_ask":"0.6","best_bid":"0.59","hash":"42b753301d7955bfa7e74364d8e5c13940698e4f","price":"0.01","side":"BUY","size":"7708.02"},{"asset_id":"69697746896130839564035629862476347944307040470122503199396727085502753297492","best_ask":"0.41","best_bid":"0.4","hash":"a2473062059c45c9ef9f6abbf9a5ae2d22216cb4","price":"0.99","side":"SELL","size":"7708.02"}],"timestamp":"1785126627600"},"payload_hash":"bc839495dd99127b7e11f21020c974a2ae1120105e5066445677c849399c3965","raw_frame":"{\"market\":\"0xeb66215f2e9faa6449e30a02bab5b8ed7b79a38bf961f6b24d0073c9c2419250\", \"price_changes\":[{\"asset_id\":\"60386828328910021732068595344565885737045900010034836345809386672230885527307\", \"price\":\"0.01\", \"size\":\"7708.02\", \"side\":\"BUY\", \"hash\":\"42b753301d7955bfa7e74364d8e5c13940698e4f\", \"best_bid\":\"0.59\", \"best_ask\":\"0.6\"}, {\"asset_id\":\"69697746896130839564035629862476347944307040470122503199396727085502753297492\", \"price\":\"0.99\", \"size\":\"7708.02\", \"side\":\"SELL\", \"hash\":\"a2473062059c45c9ef9f6abbf9a5ae2d22216cb4\", \"best_bid\":\"0.4\", \"best_ask\":\"0.41\"}], \"timestamp\":\"1785126627600\", \"event_type\":\"price_change\"}","received_at":"2026-07-27T04:30:29.225494Z","schema_version":"clob-market-ws.price_change.v1","sequence":null,"server_hash":null,"server_timestamp":"1785126627600","session_id":"e9443c7415a0419799bee9cfbb1a9e4d","source":"clob_market_ws"},"received_at":"2026-07-27T04:30:29.225494Z","record_id":"f9e1190dedf316368f029b244e4784a5bd486d1089d3f370ea200da73e844be7","schema_fingerprint":"4aa3821a28b0b7c2400bc59aba4bcc0a76e971dadd19610d3ad38c768e124dc7","schema_version":"edge-lab-recorder.raw.v1","sequence":null,"source":"clob_market_ws"}
{"event_at":"2026-07-27T04:30:27.602000Z","event_fingerprint":"35625b3aaf0b728ade6c713c5a78c03d5840f35385bdb7ff3d395054680a19f7","payload":{"connection_id":"0f4979d6978d463e9660b042fdcf555f","event_at":"2026-07-27T04:30:27.602000Z","event_type":"price_change","frame_hash":"67d1310e3c76cfbb052b37e4cca9d79bf1ee716aae449725539fec993db2630e","frame_index":0,"kind":"data","monotonic_ns":228612506203541,"payload":{"event_type":"price_change","market":"0xeb66215f2e9faa6449e30a02bab5b8ed7b79a38bf961f6b24d0073c9c2419250","price_changes":[{"asset_id":"69697746896130839564035629862476347944307040470122503199396727085502753297492","best_ask":"0.41","best_bid":"0.4","hash":"229ece6f7d340105943d22b1317c31695650c7be","price":"0.41","side":"SELL","size":"158.42"},{"asset_id":"60386828328910021732068595344565885737045900010034836345809386672230885527307","best_ask":"0.6","best_bid":"0.59","hash":"5d2ae0c430be9d6a467ebea02893423dd562b57f","price":"0.59","side":"BUY","size":"158.42"}],"timestamp":"1785126627602"},"payload_hash":"607e1300a2ed8cd66b8a087316ecb4b6b869dc118d8c9d618d01e45a0c773d3c","raw_frame":"{\"market\":\"0xeb66215f2e9faa6449e30a02bab5b8ed7b79a38bf961f6b24d0073c9c2419250\", \"price_changes\":[{\"asset_id\":\"69697746896130839564035629862476347944307040470122503199396727085502753297492\", \"price\":\"0.41\", \"size\":\"158.42\", \"side\":\"SELL\", \"hash\":\"229ece6f7d340105943d22b1317c31695650c7be\", \"best_bid\":\"0.4\", \"best_ask\":\"0.41\"}, {\"asset_id\":\"60386828328910021732068595344565885737045900010034836345809386672230885527307\", \"price\":\"0.59\", \"size\":\"158.42\", \"side\":\"BUY\", \"hash\":\"5d2ae0c430be9d6a467ebea02893423dd562b57f\", \"best_bid\":\"0.59\", \"best_ask\":\"0.6\"}], \"timestamp\":\"1785126627602\", \"event_type\":\"price_change\"}","received_at":"2026-07-27T04:30:29.236617Z","schema_version":"clob-market-ws.price_change.v1","sequence":null,"server_hash":null,"server_timestamp":"1785126627602","session_id":"e9443c7415a0419799bee9cfbb1a9e4d","source":"clob_market_ws"},"received_at":"2026-07-27T04:30:29.236617Z","record_id":"157b34985371216f9dc86c9d06a2b41e7184a6e134d92d3b087bf8d0dbbd0534","schema_fingerprint":"4aa3821a28b0b7c2400bc59aba4bcc0a76e971dadd19610d3ad38c768e124dc7","schema_version":"edge-lab-recorder.raw.v1","sequence":null,"source":"clob_market_ws"}
{"event_at":"2026-07-27T04:30:27.603000Z","event_fingerprint":"c5a6742055839b413f8d020194cd4fccd15f0a439edf2832523ddf4fb75db2eb","payload":{"connection_id":"0f4979d6978d463e9660b042fdcf555f","event_at":"2026-07-27T04:30:27.603000Z","event_type":"price_change","frame_hash":"7bd18366c39ad2863ee41f39206733736ba8f5387c1f36ca2dbd1b9e7aa3b762","frame_index":0,"kind":"data","monotonic_ns":228612514623666,"payload":{"event_type":"price_change","market":"0xeb66215f2e9faa6449e30a02bab5b8ed7b79a38bf961f6b24d0073c9c2419250","price_changes":[{"asset_id":"60386828328910021732068595344565885737045900010034836345809386672230885527307","best_ask":"0.6","best_bid":"0.59","hash":"456d5ccb41973868e6c1e9bdd093b466e7f6c72c","price":"0.47","side":"BUY","size":"111"},{"asset_id":"69697746896130839564035629862476347944307040470122503199396727085502753297492","best_ask":"0.41","best_bid":"0.4","hash":"61de14347b6bbcdc4fd2a27ece3c758ca0294f6b","price":"0.53","side":"SELL","size":"111"}],"timestamp":"1785126627603"},"payload_hash":"b409b25ea1a0ce2a515e8c3421d3b5e9cfe69efcd6f6e0a3ef75bd6397c6b974","raw_frame":"{\"market\":\"0xeb66215f2e9faa6449e30a02bab5b8ed7b79a38bf961f6b24d0073c9c2419250\", \"price_changes\":[{\"asset_id\":\"60386828328910021732068595344565885737045900010034836345809386672230885527307\", \"price\":\"0.47\", \"size\":\"111\", \"side\":\"BUY\", \"hash\":\"456d5ccb41973868e6c1e9bdd093b466e7f6c72c\", \"best_bid\":\"0.59\", \"best_ask\":\"0.6\"}, {\"asset_id\":\"69697746896130839564035629862476347944307040470122503199396727085502753297492\", \"price\":\"0.53\", \"size\":\"111\", \"side\":\"SELL\", \"hash\":\"61de14347b6bbcdc4fd2a27ece3c758ca0294f6b\", \"best_bid\":\"0.4\", \"best_ask\":\"0.41\"}], \"timestamp\":\"1785126627603\", \"event_type\":\"price_change\"}","received_at":"2026-07-27T04:30:29.245040Z","schema_version":"clob-market-ws.price_change.v1","sequence":null,"server_hash":null,"server_timestamp":"1785126627603","session_id":"e9443c7415a0419799bee9cfbb1a9e4d","source":"clob_market_ws"},"received_at":"2026-07-27T04:30:29.245040Z","record_id":"b557738f53ce9b925c205ecdfe38a964f661688c6a9c69815e737ddb0f7aa1d9","schema_fingerprint":"4aa3821a28b0b7c2400bc59aba4bcc0a76e971dadd19610d3ad38c768e124dc7","schema_version":"edge-lab-recorder.raw.v1","sequence":null,"source":"clob_market_ws"}
{"event_at":"2026-07-27T04:30:27.605000Z","event_fingerprint":"5f0885bea1df79bd3fac9a38d3baaf75f4e1c2bd209bf596332dd4fd114f0eb8","payload":{"connection_id":"0f4979d6978d463e9660b042fdcf555f","event_at":"2026-07-27T04:30:27.605000Z","event_type":"price_change","frame_hash":"dfad388d217e0cc148f45021cc855110c47d8360042267495b3acc4564f726af","frame_index":0,"kind":"data","monotonic_ns":228612526968875,"payload":{"event_type":"price_change","market":"0xeb66215f2e9faa6449e30a02bab5b8ed7b79a38bf961f6b24d0073c9c2419250","price_changes":[{"asset_id":"69697746896130839564035629862476347944307040470122503199396727085502753297492","best_ask":"0.41","best_bid":"0.4","hash":"a8023414cdb5a223cef820c4a0b12a2872356153","price":"0.27","side":"BUY","size":"106"},{"asset_id":"60386828328910021732068595344565885737045900010034836345809386672230885527307","best_ask":"0.6","best_bid":"0.59","hash":"9904f4a406e8e5b84f9a42004c7fcc70aa5eca79","price":"0.73","side":"SELL","size":"106"}],"timestamp":"1785126627605"},"payload_hash":"6872dd2387421b927160a63e1b4ae86d521e087ce31a06703d5bcd0711cff6df","raw_frame":"{\"market\":\"0xeb66215f2e9faa6449e30a02bab5b8ed7b79a38bf961f6b24d0073c9c2419250\", \"price_changes\":[{\"asset_id\":\"69697746896130839564035629862476347944307040470122503199396727085502753297492\", \"price\":\"0.27\", \"size\":\"106\", \"side\":\"BUY\", \"hash\":\"a8023414cdb5a223cef820c4a0b12a2872356153\", \"best_bid\":\"0.4\", \"best_ask\":\"0.41\"}, {\"asset_id\":\"60386828328910021732068595344565885737045900010034836345809386672230885527307\", \"price\":\"0.73\", \"size\":\"106\", \"side\":\"SELL\", \"hash\":\"9904f4a406e8e5b84f9a42004c7fcc70aa5eca79\", \"best_bid\":\"0.59\", \"best_ask\":\"0.6\"}], \"timestamp\":\"1785126627605\", \"event_type\":\"price_change\"}","received_at":"2026-07-27T04:30:29.257384Z","schema_version":"clob-market-ws.price_change.v1","sequence":null,"server_hash":null,"server_timestamp":"1785126627605","session_id":"e9443c7415a0419799bee9cfbb1a9e4d","source":"clob_market_ws"},"received_at":"2026-07-27T04:30:29.257384Z","record_id":"1b1ea8a63abc70adc8b2fee9a515302aefad162061c282ea3efb1970d2063915","schema_fingerprint":"4aa3821a28b0b7c2400bc59aba4bcc0a76e971dadd19610d3ad38c768e124dc7","schema_version":"edge-lab-recorder.raw.v1","sequence":null,"source":"clob_market_ws"}
{"event_at":"2026-07-27T04:30:27.608000Z","event_fingerprint":"ccbcb984b92f393043c72b592a3ea518610fe9271c62cb19295296e34a1f80cc","payload":{"connection_id":"0f4979d6978d463e9660b042fdcf555f","event_at":"2026-07-27T04:30:27.608000Z","event_type":"price_change","frame_hash":"a54ada3128e81e5b5e1f2c073f6ebcb2a669de941d31d8d1578da3102f520166","frame_index":0,"kind":"data","monotonic_ns":228612535703833,"payload":{"event_type":"price_change","market":"0xeb66215f2e9faa6449e30a02bab5b8ed7b79a38bf961f6b24d0073c9c2419250","price_changes":[{"asset_id":"69697746896130839564035629862476347944307040470122503199396727085502753297492","best_ask":"0.41","best_bid":"0.4","hash":"aa49e8e14affc90c581241c89899d11c5e787595","price":"0.27","side":"BUY","size":"229.45"},{"asset_id":"60386828328910021732068595344565885737045900010034836345809386672230885527307","best_ask":"0.6","best_bid":"0.59","hash":"e5fbe898b861461217b369dacb0c737f12d3337b","price":"0.73","side":"SELL","size":"229.45"}],"timestamp":"1785126627608"},"payload_hash":"bac63fe0ceb892835a8517ceccc9e4cf1cd375d909d11e334b761d856e477a92","raw_frame":"{\"market\":\"0xeb66215f2e9faa6449e30a02bab5b8ed7b79a38bf961f6b24d0073c9c2419250\", \"price_changes\":[{\"asset_id\":\"69697746896130839564035629862476347944307040470122503199396727085502753297492\", \"price\":\"0.27\", \"size\":\"229.45\", \"side\":\"BUY\", \"hash\":\"aa49e8e14affc90c581241c89899d11c5e787595\", \"best_bid\":\"0.4\", \"best_ask\":\"0.41\"}, {\"asset_id\":\"60386828328910021732068595344565885737045900010034836345809386672230885527307\", \"price\":\"0.73\", \"size\":\"229.45\", \"side\":\"SELL\", \"hash\":\"e5fbe898b861461217b369dacb0c737f12d3337b\", \"best_bid\":\"0.59\", \"best_ask\":\"0.6\"}], \"timestamp\":\"1785126627608\", \"event_type\":\"price_change\"}","received_at":"2026-07-27T04:30:29.266120Z","schema_version":"clob-market-ws.price_change.v1","sequence":null,"server_hash":null,"server_timestamp":"1785126627608","session_id":"e9443c7415a0419799bee9cfbb1a9e4d","source":"clob_market_ws"},"received_at":"2026-07-27T04:30:29.266120Z","record_id":"2706c6ee84f2d21c7dacaa1026ad91721abe618f30ee713c4a1f60d1f45f6c0e","schema_fingerprint":"4aa3821a28b0b7c2400bc59aba4bcc0a76e971dadd19610d3ad38c768e124dc7","schema_version":"edge-lab-recorder.raw.v1","sequence":null,"source":"clob_market_ws"}
{"event_at":"2026-07-27T04:30:27.610000Z","event_fingerprint":"fc67c68e35b494efb7ee4e2edf3668766ed0dd62e6f847aefba8bee5826dac5b","payload":{"connection_id":"0f4979d6978d463e9660b042fdcf555f","event_at":"2026-07-27T04:30:27.610000Z","event_type":"price_change","frame_hash":"875623b465f7d4392a709fed7bfd4dbf00414bb48c73858482695a69745c8f1e","frame_index":0,"kind":"data","monotonic_ns":228612542496083,"payload":{"event_type":"price_change","market":"0xeb66215f2e9faa6449e30a02bab5b8ed7b79a38bf961f6b24d0073c9c2419250","price_changes":[{"asset_id":"60386828328910021732068595344565885737045900010034836345809386672230885527307","best_ask":"0.6","best_bid":"0.59","hash":"da6ea8d903db8a3f9640ccad7bbbd3379780e11d","price":"0.5","side":"BUY","size":"280"},{"asset_id":"69697746896130839564035629862476347944307040470122503199396727085502753297492","best_ask":"0.41","best_bid":"0.4","hash":"505ffbc31640008517b71d65357e2b302ad060d5","price":"0.5","side":"SELL","size":"280"}],"timestamp":"1785126627610"},"payload_hash":"b780c2a507cf41bc4c30cc6a535ec0bace26ea19dadc00bffaf4373e39a508d3","raw_frame":"{\"market\":\"0xeb66215f2e9faa6449e30a02bab5b8ed7b79a38bf961f6b24d0073c9c2419250\", \"price_changes\":[{\"asset_id\":\"60386828328910021732068595344565885737045900010034836345809386672230885527307\", \"price\":\"0.5\", \"size\":\"280\", \"side\":\"BUY\", \"hash\":\"da6ea8d903db8a3f9640ccad7bbbd3379780e11d\", \"best_bid\":\"0.59\", \"best_ask\":\"0.6\"}, {\"asset_id\":\"69697746896130839564035629862476347944307040470122503199396727085502753297492\", \"price\":\"0.5\", \"size\":\"280\", \"side\":\"SELL\", \"hash\":\"505ffbc31640008517b71d65357e2b302ad060d5\", \"best_bid\":\"0.4\", \"best_ask\":\"0.41\"}], \"timestamp\":\"1785126627610\", \"event_type\":\"price_change\"}","received_at":"2026-07-27T04:30:29.272912Z","schema_version":"clob-market-ws.price_change.v1","sequence":null,"server_hash":null,"server_timestamp":"1785126627610","session_id":"e9443c7415a0419799bee9cfbb1a9e4d","source":"clob_market_ws"},"received_at":"2026-07-27T04:30:29.272912Z","record_id":"3b0a00241cd7a27814972b29a02ab67527939b009214138adb14c8284bfe3b6c","schema_fingerprint":"4aa3821a28b0b7c2400bc59aba4bcc0a76e971dadd19610d3ad38c768e124dc7","schema_version":"edge-lab-recorder.raw.v1","sequence":null,"source":"clob_market_ws"}
{"event_at":"2026-07-27T04:30:27.612000Z","event_fingerprint":"0d3056caf3cd99d985464e8c2fd27f4f61ac48a6bd894627d8fe05585e084d30","payload":{"connection_id":"0f4979d6978d463e9660b042fdcf555f","event_at":"2026-07-27T04:30:27.612000Z","event_type":"price_change","frame_hash":"72e814e25765d7d708ccb5ca15866e004e4ffbb12312f3fe1cbdf90058504ade","frame_index":0,"kind":"data","monotonic_ns":228612553666916,"payload":{"event_type":"price_change","market":"0xeb66215f2e9faa6449e30a02bab5b8ed7b79a38bf961f6b24d0073c9c2419250","price_changes":[{"asset_id":"60386828328910021732068595344565885737045900010034836345809386672230885527307","best_ask":"0.6","best_bid":"0.59","hash":"09f332777249f3c7371d4280df6406303e4f6109","price":"0.51","side":"BUY","size":"172.64"},{"asset_id":"69697746896130839564035629862476347944307040470122503199396727085502753297492","best_ask":"0.41","best_bid":"0.4","hash":"8ff92075799eaa11be70a9907921b9ad1ab98338","price":"0.49","side":"SELL","size":"172.64"}],"timestamp":"1785126627612"},"payload_hash":"b6429b713429abce4b2334cc7b9e1024d9ae90be81b02113261e63316cfa0f2a","raw_frame":"{\"market\":\"0xeb66215f2e9faa6449e30a02bab5b8ed7b79a38bf961f6b24d0073c9c2419250\", \"price_changes\":[{\"asset_id\":\"60386828328910021732068595344565885737045900010034836345809386672230885527307\", \"price\":\"0.51\", \"size\":\"172.64\", \"side\":\"BUY\", \"hash\":\"09f332777249f3c7371d4280df6406303e4f6109\", \"best_bid\":\"0.59\", \"best_ask\":\"0.6\"}, {\"asset_id\":\"69697746896130839564035629862476347944307040470122503199396727085502753297492\", \"price\":\"0.49\", \"size\":\"172.64\", \"side\":\"SELL\", \"hash\":\"8ff92075799eaa11be70a9907921b9ad1ab98338\", \"best_bid\":\"0.4\", \"best_ask\":\"0.41\"}], \"timestamp\":\"1785126627612\", \"event_type\":\"price_change\"}","received_at":"2026-07-27T04:30:29.284080Z","schema_version":"clob-market-ws.price_change.v1","sequence":null,"server_hash":null,"server_timestamp":"1785126627612","session_id":"e9443c7415a0419799bee9cfbb1a9e4d","source":"clob_market_ws"},"received_at":"2026-07-27T04:30:29.284080Z","record_id":"050920aa8754e3072376e20ae27ac6a182098d37a2849e74819eda14004c85ec","schema_fingerprint":"4aa3821a28b0b7c2400bc59aba4bcc0a76e971dadd19610d3ad38c768e124dc7","schema_version":"edge-lab-recorder.raw.v1","sequence":null,"source":"clob_market_ws"}
{"event_at":"2026-07-27T04:30:27.614000Z","event_fingerprint":"9aebb525512c14ce0e308fd09693039ff0c1518143adc12c2087f8979248a1f0","payload":{"connection_id":"0f4979d6978d463e9660b042fdcf555f","event_at":"2026-07-27T04:30:27.614000Z","event_type":"price_change","frame_hash":"fc8278c3169571ee39d046064ae02c5759b69c7523fe325358baa312b2a5b345","frame_index":0,"kind":"data","monotonic_ns":228612565001166,"payload":{"event_type":"price_change","market":"0xeb66215f2e9faa6449e30a02bab5b8ed7b79a38bf961f6b24d0073c9c2419250","price_changes":[{"asset_id":"69697746896130839564035629862476347944307040470122503199396727085502753297492","best_ask":"0.41","best_bid":"0.4","hash":"1f9ed01b5db00aa57b3a740e61a3e0400fef32d9","price":"0.07","side":"BUY","size":"602.24"},{"asset_id":"60386828328910021732068595344565885737045900010034836345809386672230885527307","best_ask":"0.6","best_bid":"0.59","hash":"a72070a90184e2637ba75ae946db2da90562ebd0","price":"0.93","side":"SELL","size":"602.24"}],"timestamp":"1785126627614"},"payload_hash":"c8f02760f9125b334c3f8746eac2f0aa118b400193405ac56995ac11469391bf","raw_frame":"{\"market\":\"0xeb66215f2e9faa6449e30a02bab5b8ed7b79a38bf961f6b24d0073c9c2419250\", \"price_changes\":[{\"asset_id\":\"69697746896130839564035629862476347944307040470122503199396727085502753297492\", \"price\":\"0.07\", \"size\":\"602.24\", \"side\":\"BUY\", \"hash\":\"1f9ed01b5db00aa57b3a740e61a3e0400fef32d9\", \"best_bid\":\"0.4\", \"best_ask\":\"0.41\"}, {\"asset_id\":\"60386828328910021732068595344565885737045900010034836345809386672230885527307\", \"price\":\"0.93\", \"size\":\"602.24\", \"side\":\"SELL\", \"hash\":\"a72070a90184e2637ba75ae946db2da90562ebd0\", \"best_bid\":\"0.59\", \"best_ask\":\"0.6\"}], \"timestamp\":\"1785126627614\", \"event_type\":\"price_change\"}","received_at":"2026-07-27T04:30:29.295418Z","schema_version":"clob-market-ws.price_change.v1","sequence":null,"server_hash":null,"server_timestamp":"1785126627614","session_id":"e9443c7415a0419799bee9cfbb1a9e4d","source":"clob_market_ws"},"received_at":"2026-07-27T04:30:29.295418Z","record_id":"866c390a8a95938d84bbdc32546faec949318e34f8de0cb2e34322f6730800f9","schema_fingerprint":"4aa3821a28b0b7c2400bc59aba4bcc0a76e971dadd19610d3ad38c768e124dc7","schema_version":"edge-lab-recorder.raw.v1","sequence":null,"source":"clob_market_ws"}
{"event_at":"2026-07-27T04:30:27.620000Z","event_fingerprint":"e319e6743565c0e4f8663134da1ccdd939e30ec081d0658c1bc935081e805630","payload":{"connection_id":"0f4979d6978d463e9660b042fdcf555f","event_at":"2026-07-27T04:30:27.620000Z","event_type":"price_change","frame_hash":"caedd4ab86a56f7f36b394aa3308f3349b426094f811191ef6663f83a78040c8","frame_index":0,"kind":"data","monotonic_ns":228612572679916,"payload":{"event_type":"price_change","market":"0xeb66215f2e9faa6449e30a02bab5b8ed7b79a38bf961f6b24d0073c9c2419250","price_changes":[{"asset_id":"60386828328910021732068595344565885737045900010034836345809386672230885527307","best_ask":"0.6","best_bid":"0.59","hash":"1e60f4443ea4df29b7ceed39652d291cd9a631b4","price":"0.01","side":"BUY","size":"7713.02"},{"asset_id":"69697746896130839564035629862476347944307040470122503199396727085502753297492","best_ask":"0.41","best_bid":"0.4","hash":"96780e59211578a6ecd1f0510adb3d9be7c64bcd","price":"0.99","side":"SELL","size":"7713.02"}],"timestamp":"1785126627620"},"payload_hash":"a64de6e8fcbf0dea4c4d83ea0022b1c87499061ace577c4af207caf5d91306dd","raw_frame":"{\"market\":\"0xeb66215f2e9faa6449e30a02bab5b8ed7b79a38bf961f6b24d0073c9c2419250\", \"price_changes\":[{\"asset_id\":\"60386828328910021732068595344565885737045900010034836345809386672230885527307\", \"price\":\"0.01\", \"size\":\"7713.02\", \"side\":\"BUY\", \"hash\":\"1e60f4443ea4df29b7ceed39652d291cd9a631b4\", \"best_bid\":\"0.59\", \"best_ask\":\"0.6\"}, {\"asset_id\":\"69697746896130839564035629862476347944307040470122503199396727085502753297492\", \"price\":\"0.99\", \"size\":\"7713.02\", \"side\":\"SELL\", \"hash\":\"96780e59211578a6ecd1f0510adb3d9be7c64bcd\", \"best_bid\":\"0.4\", \"best_ask\":\"0.41\"}], \"timestamp\":\"1785126627620\", \"event_type\":\"price_change\"}","received_at":"2026-07-27T04:30:29.303093Z","schema_version":"clob-market-ws.price_change.v1","sequence":null,"server_hash":null,"server_timestamp":"1785126627620","session_id":"e9443c7415a0419799bee9cfbb1a9e4d","source":"clob_market_ws"},"received_at":"2026-07-27T04:30:29.303093Z","record_id":"06eb73e6d06769b35bf11bb5b1ff9628e30cbbeac6394041b39f388d8fd912da","schema_fingerprint":"4aa3821a28b0b7c2400bc59aba4bcc0a76e971dadd19610d3ad38c768e124dc7","schema_version":"edge-lab-recorder.raw.v1","sequence":null,"source":"clob_market_ws"}
{"event_at":"2026-07-27T04:30:27.623000Z","event_fingerprint":"6422f54c80f401ccda62ce9d96b6383b1aed1574cf8454eb7bdb8079f2dcba66","payload":{"connection_id":"0f4979d6978d463e9660b042fdcf555f","event_at":"2026-07-27T04:30:27.623000Z","event_type":"price_change","frame_hash":"43d03e68c88f945a11f1bd2dd44352e9f4bdb7a3cc6ac04244e7f065a7b107ec","frame_index":0,"kind":"data","monotonic_ns":228612578653166,"payload":{"event_type":"price_change","market":"0xeb66215f2e9faa6449e30a02bab5b8ed7b79a38bf961f6b24d0073c9c2419250","price_changes":[{"asset_id":"69697746896130839564035629862476347944307040470122503199396727085502753297492","best_ask":"0.41","best_bid":"0.4","hash":"1da333ee66bf89a88b73907ed1734a9573d6623f","price":"0.34","side":"BUY","size":"45"},{"asset_id":"60386828328910021732068595344565885737045900010034836345809386672230885527307","best_ask":"0.6","best_bid":"0.59","hash":"8e3050ae89723c3a09fff3f7177b7cdb1680719d","price":"0.66","side":"SELL","size":"45"}],"timestamp":"1785126627623"},"payload_hash":"d892b87b28314641303a4fd5e0f06dd45201a2defae58c79767fbe7ae8ffc02d","raw_frame":"{\"market\":\"0xeb66215f2e9faa6449e30a02bab5b8ed7b79a38bf961f6b24d0073c9c2419250\", \"price_changes\":[{\"asset_id\":\"69697746896130839564035629862476347944307040470122503199396727085502753297492\", \"price\":\"0.34\", \"size\":\"45\", \"side\":\"BUY\", \"hash\":\"1da333ee66bf89a88b73907ed1734a9573d6623f\", \"best_bid\":\"0.4\", \"best_ask\":\"0.41\"}, {\"asset_id\":\"60386828328910021732068595344565885737045900010034836345809386672230885527307\", \"price\":\"0.66\", \"size\":\"45\", \"side\":\"SELL\", \"hash\":\"8e3050ae89723c3a09fff3f7177b7cdb1680719d\", \"best_bid\":\"0.59\", \"best_ask\":\"0.6\"}], \"timestamp\":\"1785126627623\", \"event_type\":\"price_change\"}","received_at":"2026-07-27T04:30:29.309069Z","schema_version":"clob-market-ws.price_change.v1","sequence":null,"server_hash":null,"server_timestamp":"1785126627623","session_id":"e9443c7415a0419799bee9cfbb1a9e4d","source":"clob_market_ws"},"received_at":"2026-07-27T04:30:29.309069Z","record_id":"43f2d5fda20804a1a7cee15adb2c03889a084f4161e62216aab44b7f94461abe","schema_fingerprint":"4aa3821a28b0b7c2400bc59aba4bcc0a76e971dadd19610d3ad38c768e124dc7","schema_version":"edge-lab-recorder.raw.v1","sequence":null,"source":"clob_market_ws"}
{"event_at":"2026-07-27T04:30:27.623000Z","event_fingerprint":"7a9ee189cb2c49185cb8e56b961abe4c44131b8eb8dcbe4cc30c7c6cfa247990","payload":{"connection_id":"0f4979d6978d463e9660b042fdcf555f","event_at":"2026-07-27T04:30:27.623000Z","event_type":"price_change","frame_hash":"b52cb5d121568ffb418b9540ef50e0f8538170db3d8d361dfc926b4c45e61833","frame_index":0,"kind":"data","monotonic_ns":228612587602250,"payload":{"event_type":"price_change","market":"0xeb66215f2e9faa6449e30a02bab5b8ed7b79a38bf961f6b24d0073c9c2419250","price_changes":[{"asset_id":"69697746896130839564035629862476347944307040470122503199396727085502753297492","best_ask":"0.41","best_bid":"0.4","hash":"5d1e2dabc79db192ddf62b675e606fc57f5a7da8","price":"0.27","side":"BUY","size":"106"},{"asset_id":"60386828328910021732068595344565885737045900010034836345809386672230885527307","best_ask":"0.6","best_bid":"0.59","hash":"742311ec5203c96a1b4acaeea1a98aaf343da54e","price":"0.73","side":"SELL","size":"106"}],"timestamp":"1785126627623"},"payload_hash":"553278678b705ec473871b512c7951d77b5c90b2e4112a14e1491d62d8e669f5","raw_frame":"{\"market\":\"0xeb66215f2e9faa6449e30a02bab5b8ed7b79a38bf961f6b24d0073c9c2419250\", \"price_changes\":[{\"asset_id\":\"69697746896130839564035629862476347944307040470122503199396727085502753297492\", \"price\":\"0.27\", \"size\":\"106\", \"side\":\"BUY\", \"hash\":\"5d1e2dabc79db192ddf62b675e606fc57f5a7da8\", \"best_bid\":\"0.4\", \"best_ask\":\"0.41\"}, {\"asset_id\":\"60386828328910021732068595344565885737045900010034836345809386672230885527307\", \"price\":\"0.73\", \"size\":\"106\", \"side\":\"SELL\", \"hash\":\"742311ec5203c96a1b4acaeea1a98aaf343da54e\", \"best_bid\":\"0.59\", \"best_ask\":\"0.6\"}], \"timestamp\":\"1785126627623\", \"event_type\":\"price_change\"}","received_at":"2026-07-27T04:30:29.318018Z","schema_version":"clob-market-ws.price_change.v1","sequence":null,"server_hash":null,"server_timestamp":"1785126627623","session_id":"e9443c7415a0419799bee9cfbb1a9e4d","source":"clob_market_ws"},"received_at":"2026-07-27T04:30:29.318018Z","record_id":"2350a324855b3bece923e9651fce16fd0e854a325c2879c5adb4b1fa26834de6","schema_fingerprint":"4aa3821a28b0b7c2400bc59aba4bcc0a76e971dadd19610d3ad38c768e124dc7","schema_version":"edge-lab-recorder.raw.v1","sequence":null,"source":"clob_market_ws"}
{"event_at":"2026-07-27T04:30:27.627000Z","event_fingerprint":"bf4f218a28c9e82dc1c5cd140c84f9ae22c25b5f7f2c2112129c5fdc62b77a5d","payload":{"connection_id":"0f4979d6978d463e9660b042fdcf555f","event_at":"2026-07-27T04:30:27.627000Z","event_type":"price_change","frame_hash":"42a22179b4c1595c2c4159e18b7d0146b3ad71c3bcb9ef4190ba00eb1ae75e36","frame_index":0,"kind":"data","monotonic_ns":228612596127583,"payload":{"event_type":"price_change","market":"0xeb66215f2e9faa6449e30a02bab5b8ed7b79a38bf961f6b24d0073c9c2419250","price_changes":[{"asset_id":"69697746896130839564035629862476347944307040470122503199396727085502753297492","best_ask":"0.41","best_bid":"0.4","hash":"06450fa17edadb8f6a15023d94bb2fc16a736a6a","price":"0.25","side":"BUY","size":"165"},{"asset_id":"60386828328910021732068595344565885737045900010034836345809386672230885527307","best_ask":"0.6","best_bid":"0.59","hash":"24d7872401e99219a170649c6ba45a1f5e052b01","price":"0.75","side":"SELL","size":"165"}],"timestamp":"1785126627627"},"payload_hash":"11502ed152943116a836d6aee82d286f049d4a8bc36781979a42c84040a633a5","raw_frame":"{\"market\":\"0xeb66215f2e9faa6449e30a02bab5b8ed7b79a38bf961f6b24d0073c9c2419250\", \"price_changes\":[{\"asset_id\":\"69697746896130839564035629862476347944307040470122503199396727085502753297492\", \"price\":\"0.25\", \"size\":\"165\", \"side\":\"BUY\", \"hash\":\"06450fa17edadb8f6a15023d94bb2fc16a736a6a\", \"best_bid\":\"0.4\", \"best_ask\":\"0.41\"}, {\"asset_id\":\"60386828328910021732068595344565885737045900010034836345809386672230885527307\", \"price\":\"0.75\", \"size\":\"165\", \"side\":\"SELL\", \"hash\":\"24d7872401e99219a170649c6ba45a1f5e052b01\", \"best_bid\":\"0.59\", \"best_ask\":\"0.6\"}], \"timestamp\":\"1785126627627\", \"event_type\":\"price_change\"}","received_at":"2026-07-27T04:30:29.326544Z","schema_version":"clob-market-ws.price_change.v1","sequence":null,"server_hash":null,"server_timestamp":"1785126627627","session_id":"e9443c7415a0419799bee9cfbb1a9e4d","source":"clob_market_ws"},"received_at":"2026-07-27T04:30:29.326544Z","record_id":"9a69bcc513fbd92547a55c53d405a42f55979030110246c06f6b3cf77dd51483","schema_fingerprint":"4aa3821a28b0b7c2400bc59aba4bcc0a76e971dadd19610d3ad38c768e124dc7","schema_version":"edge-lab-recorder.raw.v1","sequence":null,"source":"clob_market_ws"}
{"event_at":"2026-07-27T04:30:27.633000Z","event_fingerprint":"3ac8092531691e2872d90a02ca0369c3407932d76d2beea2473a6c80f8546c21","payload":{"connection_id":"0f4979d6978d463e9660b042fdcf555f","event_at":"2026-07-27T04:30:27.633000Z","event_type":"price_change","frame_hash":"524f2eee0bd9f2c7babe2f43a49da49c7b47ff4e84f85d9a5272a5ab18416eeb","frame_index":0,"kind":"data","monotonic_ns":228612604408875,"payload":{"event_type":"price_change","market":"0xeb66215f2e9faa6449e30a02bab5b8ed7b79a38bf961f6b24d0073c9c2419250","price_changes":[{"asset_id":"60386828328910021732068595344565885737045900010034836345809386672230885527307","best_ask":"0.6","best_bid":"0.59","hash":"9b58370178976f4aed08cc03cfb9c837f8a258de","price":"0.55","side":"BUY","size":"38.6"},{"asset_id":"69697746896130839564035629862476347944307040470122503199396727085502753297492","best_ask":"0.41","best_bid":"0.4","hash":"b993bccb300fd798c065b05f40f33c0fe215934b","price":"0.45","side":"SELL","size":"38.6"}],"timestamp":"1785126627633"},"payload_hash":"67f3b13e7e30fe6c1ab6cc2ec4df0d21fa21c32dcc8ebe40dabc16c7b841355b","raw_frame":"{\"market\":\"0xeb66215f2e9faa6449e30a02bab5b8ed7b79a38bf961f6b24d0073c9c2419250\", \"price_changes\":[{\"asset_id\":\"60386828328910021732068595344565885737045900010034836345809386672230885527307\", \"price\":\"0.55\", \"size\":\"38.6\", \"side\":\"BUY\", \"hash\":\"9b58370178976f4aed08cc03cfb9c837f8a258de\", \"best_bid\":\"0.59\", \"best_ask\":\"0.6\"}, {\"asset_id\":\"69697746896130839564035629862476347944307040470122503199396727085502753297492\", \"price\":\"0.45\", \"size\":\"38.6\", \"side\":\"SELL\", \"hash\":\"b993bccb300fd798c065b05f40f33c0fe215934b\", \"best_bid\":\"0.4\", \"best_ask\":\"0.41\"}], \"timestamp\":\"1785126627633\", \"event_type\":\"price_change\"}","received_at":"2026-07-27T04:30:29.334826Z","schema_version":"clob-market-ws.price_change.v1","sequence":null,"server_hash":null,"server_timestamp":"1785126627633","session_id":"e9443c7415a0419799bee9cfbb1a9e4d","source":"clob_market_ws"},"received_at":"2026-07-27T04:30:29.334826Z","record_id":"67dd84cd4aca30f20d49d74ffda026b1d7dad3e7508a230d620f0bf03a77b5fe","schema_fingerprint":"4aa3821a28b0b7c2400bc59aba4bcc0a76e971dadd19610d3ad38c768e124dc7","schema_version":"edge-lab-recorder.raw.v1","sequence":null,"source":"clob_market_ws"}
{"event_at":"2026-07-27T04:30:27.639000Z","event_fingerprint":"1c3e440a473810f2dd8193ab5144c737c48170bc603f4e729a8782d33a364632","payload":{"connection_id":"0f4979d6978d463e9660b042fdcf555f","event_at":"2026-07-27T04:30:27.639000Z","event_type":"price_change","frame_hash":"bad566a76d70a73819233de95a1fa9fedd9bde1c44ffb008ab6aebffc505d9a9","frame_index":0,"kind":"data","monotonic_ns":228612621112958,"payload":{"event_type":"price_change","market":"0xeb66215f2e9faa6449e30a02bab5b8ed7b79a38bf961f6b24d0073c9c2419250","price_changes":[{"asset_id":"60386828328910021732068595344565885737045900010034836345809386672230885527307","best_ask":"0.6","best_bid":"0.59","hash":"1daa5ac3f1c5b7e5ec561f62608306e3144f5d44","price":"0.01","side":"BUY","size":"7708.02"},{"asset_id":"69697746896130839564035629862476347944307040470122503199396727085502753297492","best_ask":"0.41","best_bid":"0.4","hash":"d3e2a9973171c191e78d51c6dedfc9a6a579cbe0","price":"0.99","side":"SELL","size":"7708.02"}],"timestamp":"1785126627639"},"payload_hash":"246ddfeec4c310592b8c0724d629b94c71c964fd86cac03f45a7c155b1491f73","raw_frame":"{\"market\":\"0xeb66215f2e9faa6449e30a02bab5b8ed7b79a38bf961f6b24d0073c9c2419250\", \"price_changes\":[{\"asset_id\":\"60386828328910021732068595344565885737045900010034836345809386672230885527307\", \"price\":\"0.01\", \"size\":\"7708.02\", \"side\":\"BUY\", \"hash\":\"1daa5ac3f1c5b7e5ec561f62608306e3144f5d44\", \"best_bid\":\"0.59\", \"best_ask\":\"0.6\"}, {\"asset_id\":\"69697746896130839564035629862476347944307040470122503199396727085502753297492\", \"price\":\"0.99\", \"size\":\"7708.02\", \"side\":\"SELL\", \"hash\":\"d3e2a9973171c191e78d51c6dedfc9a6a579cbe0\", \"best_bid\":\"0.4\", \"best_ask\":\"0.41\"}], \"timestamp\":\"1785126627639\", \"event_type\":\"price_change\"}","received_at":"2026-07-27T04:30:29.351530Z","schema_version":"clob-market-ws.price_change.v1","sequence":null,"server_hash":null,"server_timestamp":"1785126627639","session_id":"e9443c7415a0419799bee9cfbb1a9e4d","source":"clob_market_ws"},"received_at":"2026-07-27T04:30:29.351530Z","record_id":"d35c8ed5a35a2f494aef3d2b6890379e4175a448f27b44a4dd709b3e973a4327","schema_fingerprint":"4aa3821a28b0b7c2400bc59aba4bcc0a76e971dadd19610d3ad38c768e124dc7","schema_version":"edge-lab-recorder.raw.v1","sequence":null,"source":"clob_market_ws"}
{"event_at":"2026-07-27T04:30:27.642000Z","event_fingerprint":"4bbf2a52d3d6144e7ae8c23d5282ec2211c3e0aee0aa6d897caee722260bc286","payload":{"connection_id":"0f4979d6978d463e9660b042fdcf555f","event_at":"2026-07-27T04:30:27.642000Z","event_type":"price_change","frame_hash":"f008e651b717e8dd45cb4706e121744ce8db6310504c7ec512c479d01e018330","frame_index":0,"kind":"data","monotonic_ns":228612630007666,"payload":{"event_type":"price_change","market":"0xeb66215f2e9faa6449e30a02bab5b8ed7b79a38bf961f6b24d0073c9c2419250","price_changes":[{"asset_id":"69697746896130839564035629862476347944307040470122503199396727085502753297492","best_ask":"0.41","best_bid":"0.4","hash":"923eef89fcc61608ccae1e9a7672adcfd47d55d0","price":"0.28","side":"BUY","size":"223.66"},{"asset_id":"60386828328910021732068595344565885737045900010034836345809386672230885527307","best_ask":"0.6","best_bid":"0.59","hash":"e5f3eda3e54fbd923db0c054e0c93a4bcdda72ca","price":"0.72","side":"SELL","size":"223.66"}],"timestamp":"1785126627642"},"payload_hash":"ba308cd6a57bf2197bb7aea65853ba57a3c47ac011f6f576e63748aa1b0f1c56","raw_frame":"{\"market\":\"0xeb66215f2e9faa6449e30a02bab5b8ed7b79a38bf961f6b24d0073c9c2419250\", \"price_changes\":[{\"asset_id\":\"69697746896130839564035629862476347944307040470122503199396727085502753297492\", \"price\":\"0.28\", \"size\":\"223.66\", \"side\":\"BUY\", \"hash\":\"923eef89fcc61608ccae1e9a7672adcfd47d55d0\", \"best_bid\":\"0.4\", \"best_ask\":\"0.41\"}, {\"asset_id\":\"60386828328910021732068595344565885737045900010034836345809386672230885527307\", \"price\":\"0.72\", \"size\":\"223.66\", \"side\":\"SELL\", \"hash\":\"e5f3eda3e54fbd923db0c054e0c93a4bcdda72ca\", \"best_bid\":\"0.59\", \"best_ask\":\"0.6\"}], \"timestamp\":\"1785126627642\", \"event_type\":\"price_change\"}","received_at":"2026-07-27T04:30:29.360423Z","schema_version":"clob-market-ws.price_change.v1","sequence":null,"server_hash":null,"server_timestamp":"1785126627642","session_id":"e9443c7415a0419799bee9cfbb1a9e4d","source":"clob_market_ws"},"received_at":"2026-07-27T04:30:29.360423Z","record_id":"817d53520c30f0de5e07031b0d39fc3018383cd73e5e3c6d72d9afd606eb86bc","schema_fingerprint":"4aa3821a28b0b7c2400bc59aba4bcc0a76e971dadd19610d3ad38c768e124dc7","schema_version":"edge-lab-recorder.raw.v1","sequence":null,"source":"clob_market_ws"}
{"event_at":"2026-07-27T04:30:27.664000Z","event_fingerprint":"8f8930784c0ab313deac7504d7738920002ea5f627c81e3c1e231f81a80291d4","payload":{"connection_id":"0f4979d6978d463e9660b042fdcf555f","event_at":"2026-07-27T04:30:27.664000Z","event_type":"price_change","frame_hash":"407c56851ed9bd04c75cdfc8511e78cdeda1ecb5cdb12f78c759eb375f049041","frame_index":0,"kind":"data","monotonic_ns":228612642046375,"payload":{"event_type":"price_change","market":"0xeb66215f2e9faa6449e30a02bab5b8ed7b79a38bf961f6b24d0073c9c2419250","price_changes":[{"asset_id":"69697746896130839564035629862476347944307040470122503199396727085502753297492","best_ask":"0.41","best_bid":"0.4","hash":"73414a5e0c98d33c7eb52d7d6870c47be17dacfa","price":"0.41","side":"SELL","size":"163.42"},{"asset_id":"60386828328910021732068595344565885737045900010034836345809386672230885527307","best_ask":"0.6","best_bid":"0.59","hash":"03828aff13048240138be765cc89676f85016f7e","price":"0.59","side":"BUY","size":"163.42"}],"timestamp":"1785126627664"},"payload_hash":"b1207420ac372623ec66150863bc30624f20c4bbbf9260e1a3809f4bec44d242","raw_frame":"{\"market\":\"0xeb66215f2e9faa6449e30a02bab5b8ed7b79a38bf961f6b24d0073c9c2419250\", \"price_changes\":[{\"asset_id\":\"69697746896130839564035629862476347944307040470122503199396727085502753297492\", \"price\":\"0.41\", \"size\":\"163.42\", \"side\":\"SELL\", \"hash\":\"73414a5e0c98d33c7eb52d7d6870c47be17dacfa\", \"best_bid\":\"0.4\", \"best_ask\":\"0.41\"}, {\"asset_id\":\"60386828328910021732068595344565885737045900010034836345809386672230885527307\", \"price\":\"0.59\", \"size\":\"163.42\", \"side\":\"BUY\", \"hash\":\"03828aff13048240138be765cc89676f85016f7e\", \"best_bid\":\"0.59\", \"best_ask\":\"0.6\"}], \"timestamp\":\"1785126627664\", \"event_type\":\"price_change\"}","received_at":"2026-07-27T04:30:29.372462Z","schema_version":"clob-market-ws.price_change.v1","sequence":null,"server_hash":null,"server_timestamp":"1785126627664","session_id":"e9443c7415a0419799bee9cfbb1a9e4d","source":"clob_market_ws"},"received_at":"2026-07-27T04:30:29.372462Z","record_id":"865fca85dc0b502a45a2c7303e5b1cca3dcd8090b33e355102a8ea6188fcf4a4","schema_fingerprint":"4aa3821a28b0b7c2400bc59aba4bcc0a76e971dadd19610d3ad38c768e124dc7","schema_version":"edge-lab-recorder.raw.v1","sequence":null,"source":"clob_market_ws"}
{"event_at":"2026-07-27T04:30:27.665000Z","event_fingerprint":"1a5ca44e44d2c7874a5111bf5cdc15c6c4d769ab2d520d616660aeda0b35b070","payload":{"connection_id":"0f4979d6978d463e9660b042fdcf555f","event_at":"2026-07-27T04:30:27.665000Z","event_type":"price_change","frame_hash":"e36e6f3a98b9467647ad12d0a2e301821d6d9aca5881641e5a4dd726b0f7f539","frame_index":0,"kind":"data","monotonic_ns":228612654380708,"payload":{"event_type":"price_change","market":"0xeb66215f2e9faa6449e30a02bab5b8ed7b79a38bf961f6b24d0073c9c2419250","price_changes":[{"asset_id":"60386828328910021732068595344565885737045900010034836345809386672230885527307","best_ask":"0.6","best_bid":"0.59","hash":"29bab10dd2169e37b7b308369449e89ca6f2c8a7","price":"0.54","side":"BUY","size":"154.6"},{"asset_id":"69697746896130839564035629862476347944307040470122503199396727085502753297492","best_ask":"0.41","best_bid":"0.4","hash":"6e744d6b39c2b97c1909c5aed5d5ee995b58219c","price":"0.46","side":"SELL","size":"154.6"}],"timestamp":"1785126627665"},"payload_hash":"1d28d232ecb47bb0ee2d7ee70f0a563d597269915dd3aa93685360eebd1c1e1e","raw_frame":"{\"market\":\"0xeb66215f2e9faa6449e30a02bab5b8ed7b79a38bf961f6b24d0073c9c2419250\", \"price_changes\":[{\"asset_id\":\"60386828328910021732068595344565885737045900010034836345809386672230885527307\", \"price\":\"0.54\", \"size\":\"154.6\", \"side\":\"BUY\", \"hash\":\"29bab10dd2169e37b7b308369449e89ca6f2c8a7\", \"best_bid\":\"0.59\", \"best_ask\":\"0.6\"}, {\"asset_id\":\"69697746896130839564035629862476347944307040470122503199396727085502753297492\", \"price\":\"0.46\", \"size\":\"154.6\", \"side\":\"SELL\", \"hash\":\"6e744d6b39c2b97c1909c5aed5d5ee995b58219c\", \"best_bid\":\"0.4\", \"best_ask\":\"0.41\"}], \"timestamp\":\"1785126627665\", \"event_type\":\"price_change\"}","received_at":"2026-07-27T04:30:29.384799Z","schema_version":"clob-market-ws.price_change.v1","sequence":null,"server_hash":null,"server_timestamp":"1785126627665","session_id":"e9443c7415a0419799bee9cfbb1a9e4d","source":"clob_market_ws"},"received_at":"2026-07-27T04:30:29.384799Z","record_id":"c34c1ccddca84f3e9d49941e085193fadb481dfb7f7f6b5756e0216a3b45a248","schema_fingerprint":"4aa3821a28b0b7c2400bc59aba4bcc0a76e971dadd19610d3ad38c768e124dc7","schema_version":"edge-lab-recorder.raw.v1","sequence":null,"source":"clob_market_ws"}
{"event_at":"2026-07-27T04:30:27.665000Z","event_fingerprint":"1ef277c7191fa8d3e2ac08dc9f49115c1898b07a771e198b7f79e49d17305833","payload":{"connection_id":"0f4979d6978d463e9660b042fdcf555f","event_at":"2026-07-27T04:30:27.665000Z","event_type":"price_change","frame_hash":"da4d5f92d722df4458a18f50ac3507c52c0187a49aba18333c9c55f961cf3c95","frame_index":0,"kind":"data","monotonic_ns":228612663848583,"payload":{"event_type":"price_change","market":"0xeb66215f2e9faa6449e30a02bab5b8ed7b79a38bf961f6b24d0073c9c2419250","price_changes":[{"asset_id":"69697746896130839564035629862476347944307040470122503199396727085502753297492","best_ask":"0.41","best_bid":"0.4","hash":"6e744d6b39c2b97c1909c5aed5d5ee995b58219c","price":"0.25","side":"BUY","size":"65"},{"asset_id":"60386828328910021732068595344565885737045900010034836345809386672230885527307","best_ask":"0.6","best_bid":"0.59","hash":"29bab10dd2169e37b7b308369449e89ca6f2c8a7","price":"0.75","side":"SELL","size":"65"}],"timestamp":"1785126627665"},"payload_hash":"81974ef7f8fc093f663149e13a6ce7292750508cd10d0e38d8477beaf2d5731d","raw_frame":"{\"market\":\"0xeb66215f2e9faa6449e30a02bab5b8ed7b79a38bf961f6b24d0073c9c2419250\", \"price_changes\":[{\"asset_id\":\"69697746896130839564035629862476347944307040470122503199396727085502753297492\", \"price\":\"0.25\", \"size\":\"65\", \"side\":\"BUY\", \"hash\":\"6e744d6b39c2b97c1909c5aed5d5ee995b58219c\", \"best_bid\":\"0.4\", \"best_ask\":\"0.41\"}, {\"asset_id\":\"60386828328910021732068595344565885737045900010034836345809386672230885527307\", \"price\":\"0.75\", \"size\":\"65\", \"side\":\"SELL\", \"hash\":\"29bab10dd2169e37b7b308369449e89ca6f2c8a7\", \"best_bid\":\"0.59\", \"best_ask\":\"0.6\"}], \"timestamp\":\"1785126627665\", \"event_type\":\"price_change\"}","received_at":"2026-07-27T04:30:29.394266Z","schema_version":"clob-market-ws.price_change.v1","sequence":null,"server_hash":null,"server_timestamp":"1785126627665","session_id":"e9443c7415a0419799bee9cfbb1a9e4d","source":"clob_market_ws"},"received_at":"2026-07-27T04:30:29.394266Z","record_id":"7ade526717406c81ab8ebb821c8faaa0ad59e6dd44b5cb2fee63c5d4cb1b6de6","schema_fingerprint":"4aa3821a28b0b7c2400bc59aba4bcc0a76e971dadd19610d3ad38c768e124dc7","schema_version":"edge-lab-recorder.raw.v1","sequence":null,"source":"clob_market_ws"}
{"event_at":"2026-07-27T04:30:27.666000Z","event_fingerprint":"596c470e10d764964099bca0329d6e147436357a455563f96d058ea83e148b6f","payload":{"connection_id":"0f4979d6978d463e9660b042fdcf555f","event_at":"2026-07-27T04:30:27.666000Z","event_type":"price_change","frame_hash":"49c3bcf203d54fc53d53f1fdc2c4698eac635109418debbf39eb7f1441ae7a3c","frame_index":0,"kind":"data","monotonic_ns":228612685244916,"payload":{"event_type":"price_change","market":"0xeb66215f2e9faa6449e30a02bab5b8ed7b79a38bf961f6b24d0073c9c2419250","price_changes":[{"asset_id":"60386828328910021732068595344565885737045900010034836345809386672230885527307","best_ask":"0.6","best_bid":"0.59","hash":"05c13b4e086c91bef8c247986c6d87d766315984","price":"0.01","side":"BUY","size":"7703.02"},{"asset_id":"69697746896130839564035629862476347944307040470122503199396727085502753297492","best_ask":"0.41","best_bid":"0.4","hash":"e5cfbe7e92b31fc7483b56817f65c1ce379f923e","price":"0.99","side":"SELL","size":"7703.02"}],"timestamp":"1785126627666"},"payload_hash":"893179a818f9b89f28966e4357625acdc23ea119b248d62c7ecaf440b25f9263","raw_frame":"{\"market\":\"0xeb66215f2e9faa6449e30a02bab5b8ed7b79a38bf961f6b24d0073c9c2419250\", \"price_changes\":[{\"asset_id\":\"60386828328910021732068595344565885737045900010034836345809386672230885527307\", \"price\":\"0.01\", \"size\":\"7703.02\", \"side\":\"BUY\", \"hash\":\"05c13b4e086c91bef8c247986c6d87d766315984\", \"best_bid\":\"0.59\", \"best_ask\":\"0.6\"}, {\"asset_id\":\"69697746896130839564035629862476347944307040470122503199396727085502753297492\", \"price\":\"0.99\", \"size\":\"7703.02\", \"side\":\"SELL\", \"hash\":\"e5cfbe7e92b31fc7483b56817f65c1ce379f923e\", \"best_bid\":\"0.4\", \"best_ask\":\"0.41\"}], \"timestamp\":\"1785126627666\", \"event_type\":\"price_change\"}","received_at":"2026-07-27T04:30:29.415664Z","schema_version":"clob-market-ws.price_change.v1","sequence":null,"server_hash":null,"server_timestamp":"1785126627666","session_id":"e9443c7415a0419799bee9cfbb1a9e4d","source":"clob_market_ws"},"received_at":"2026-07-27T04:30:29.415664Z","record_id":"4358154017f12be4c6cdc0851aaecc140c3ac3531640e0265664d4013d931292","schema_fingerprint":"4aa3821a28b0b7c2400bc59aba4bcc0a76e971dadd19610d3ad38c768e124dc7","schema_version":"edge-lab-recorder.raw.v1","sequence":null,"source":"clob_market_ws"}
{"event_at":"2026-07-27T04:30:27.667000Z","event_fingerprint":"9dfde58dde6d85a7627a7d6fc54702e7c0a9d77b37a153c2e3edfbbd69c959e4","payload":{"connection_id":"0f4979d6978d463e9660b042fdcf555f","event_at":"2026-07-27T04:30:27.667000Z","event_type":"price_change","frame_hash":"70aca6a3bd36782569503c201bb3e3f00b6d272990f13ab44fa54b0ad8da0358","frame_index":0,"kind":"data","monotonic_ns":228612698852791,"payload":{"event_type":"price_change","market":"0xeb66215f2e9faa6449e30a02bab5b8ed7b79a38bf961f6b24d0073c9c2419250","price_changes":[{"asset_id":"60386828328910021732068595344565885737045900010034836345809386672230885527307","best_ask":"0.6","best_bid":"0.59","hash":"3d11d2c2ec82ec823da2a9d9b68a3cd100d01799","price":"0.52","side":"BUY","size":"127"},{"asset_id":"69697746896130839564035629862476347944307040470122503199396727085502753297492","best_ask":"0.41","best_bid":"0.4","hash":"7537df4cd0f632802bd5f62c98e7025be419dda5","price":"0.48","side":"SELL","size":"127"}],"timestamp":"1785126627667"},"payload_hash":"87abc6a4d7a6096bcf37a57b88b916db8b128046c25e11ae68200945bbaac20d","raw_frame":"{\"market\":\"0xeb66215f2e9faa6449e30a02bab5b8ed7b79a38bf961f6b24d0073c9c2419250\", \"price_changes\":[{\"asset_id\":\"60386828328910021732068595344565885737045900010034836345809386672230885527307\", \"price\":\"0.52\", \"size\":\"127\", \"side\":\"BUY\", \"hash\":\"3d11d2c2ec82ec823da2a9d9b68a3cd100d01799\", \"best_bid\":\"0.59\", \"best_ask\":\"0.6\"}, {\"asset_id\":\"69697746896130839564035629862476347944307040470122503199396727085502753297492\", \"price\":\"0.48\", \"size\":\"127\", \"side\":\"SELL\", \"hash\":\"7537df4cd0f632802bd5f62c98e7025be419dda5\", \"best_bid\":\"0.4\", \"best_ask\":\"0.41\"}], \"timestamp\":\"1785126627667\", \"event_type\":\"price_change\"}","received_at":"2026-07-27T04:30:29.429270Z","schema_version":"clob-market-ws.price_change.v1","sequence":null,"server_hash":null,"server_timestamp":"1785126627667","session_id":"e9443c7415a0419799bee9cfbb1a9e4d","source":"clob_market_ws"},"received_at":"2026-07-27T04:30:29.429270Z","record_id":"6346b2661712402061e2519363cc846eb813201a9fd996d0109e609802a8bae8","schema_fingerprint":"4aa3821a28b0b7c2400bc59aba4bcc0a76e971dadd19610d3ad38c768e124dc7","schema_version":"edge-lab-recorder.raw.v1","sequence":null,"source":"clob_market_ws"}
{"event_at":"2026-07-27T04:30:27.668000Z","event_fingerprint":"f0a74910b88152e898822dbb8a3329b96a80aa02045788112023985ae3849866","payload":{"connection_id":"0f4979d6978d463e9660b042fdcf555f","event_at":"2026-07-27T04:30:27.668000Z","event_type":"price_change","frame_hash":"bbea0aba553ed392ef060c31f15a01365cfa1ab617c178acf5ce6190c5e5b732","frame_index":0,"kind":"data","monotonic_ns":228612710885916,"payload":{"event_type":"price_change","market":"0xeb66215f2e9faa6449e30a02bab5b8ed7b79a38bf961f6b24d0073c9c2419250","price_changes":[{"asset_id":"60386828328910021732068595344565885737045900010034836345809386672230885527307","best_ask":"0.6","best_bid":"0.59","hash":"690cc48e0712abf637f74b0a1469960b4e5194d8","price":"0.53","side":"BUY","size":"150.86"},{"asset_id":"69697746896130839564035629862476347944307040470122503199396727085502753297492","best_ask":"0.41","best_bid":"0.4","hash":"69448ec4f429699de7ff8ef6ec408b661377d62d","price":"0.47","side":"SELL","size":"150.86"}],"timestamp":"1785126627668"},"payload_hash":"81a5bf8870facafd2e1dfe185b9575af551b91e9b7a66ddd0cec334358c38225","raw_frame":"{\"market\":\"0xeb66215f2e9faa6449e30a02bab5b8ed7b79a38bf961f6b24d0073c9c2419250\", \"price_changes\":[{\"asset_id\":\"60386828328910021732068595344565885737045900010034836345809386672230885527307\", \"price\":\"0.53\", \"size\":\"150.86\", \"side\":\"BUY\", \"hash\":\"690cc48e0712abf637f74b0a1469960b4e5194d8\", \"best_bid\":\"0.59\", \"best_ask\":\"0.6\"}, {\"asset_id\":\"69697746896130839564035629862476347944307040470122503199396727085502753297492\", \"price\":\"0.47\", \"size\":\"150.86\", \"side\":\"SELL\", \"hash\":\"69448ec4f429699de7ff8ef6ec408b661377d62d\", \"best_bid\":\"0.4\", \"best_ask\":\"0.41\"}], \"timestamp\":\"1785126627668\", \"event_type\":\"price_change\"}","received_at":"2026-07-27T04:30:29.441300Z","schema_version":"clob-market-ws.price_change.v1","sequence":null,"server_hash":null,"server_timestamp":"1785126627668","session_id":"e9443c7415a0419799bee9cfbb1a9e4d","source":"clob_market_ws"},"received_at":"2026-07-27T04:30:29.441300Z","record_id":"97ac594160777f3f6eb471cf2bb84a1704f3d49cef376f8c4aa686281a7c37ee","schema_fingerprint":"4aa3821a28b0b7c2400bc59aba4bcc0a76e971dadd19610d3ad38c768e124dc7","schema_version":"edge-lab-recorder.raw.v1","sequence":null,"source":"clob_market_ws"}
{"event_at":"2026-07-27T04:30:27.675000Z","event_fingerprint":"7862f212efab12e167cd381080f31e129e6610ef099c8f3b5470e2754a2b1dda","payload":{"connection_id":"0f4979d6978d463e9660b042fdcf555f","event_at":"2026-07-27T04:30:27.675000Z","event_type":"best_bid_ask","frame_hash":"0d61f592f73a0559029821e0ac674b4fa2b1c9440e8a281ebdf7c64d61e3bece","frame_index":0,"kind":"data","monotonic_ns":228612719515333,"payload":{"asset_id":"69697746896130839564035629862476347944307040470122503199396727085502753297492","best_ask":"0.41","best_bid":"0.36","event_type":"best_bid_ask","market":"0xeb66215f2e9faa6449e30a02bab5b8ed7b79a38bf961f6b24d0073c9c2419250","spread":"0.05","timestamp":"1785126627675"},"payload_hash":"b421f93a2428878fcb41fe52fc1e554c2fd39507b5ed2d310c89829253933d4c","raw_frame":"{\"market\":\"0xeb66215f2e9faa6449e30a02bab5b8ed7b79a38bf961f6b24d0073c9c2419250\", \"asset_id\":\"69697746896130839564035629862476347944307040470122503199396727085502753297492\", \"best_bid\":\"0.36\", \"best_ask\":\"0.41\", \"spread\":\"0.05\", \"timestamp\":\"1785126627675\", \"event_type\":\"best_bid_ask\"}","received_at":"2026-07-27T04:30:29.449934Z","schema_version":"clob-market-ws.best_bid_ask.v1","sequence":null,"server_hash":null,"server_timestamp":"1785126627675","session_id":"e9443c7415a0419799bee9cfbb1a9e4d","source":"clob_market_ws"},"received_at":"2026-07-27T04:30:29.449934Z","record_id":"d20915983a6bf2e3fdc4370e60bb980d01c25eea73482cb4169051e843fe27af","schema_fingerprint":"8488399f31b0337811b13b266be932db7062827c2470b78bd8e9e99bab51d17d","schema_version":"edge-lab-recorder.raw.v1","sequence":null,"source":"clob_market_ws"}
{"event_at":"2026-07-27T04:30:27.675000Z","event_fingerprint":"44783b717eb4641e60f93fbfe81d47ab81657cf8257516d6e9e79848a73d835d","payload":{"connection_id":"0f4979d6978d463e9660b042fdcf555f","event_at":"2026-07-27T04:30:27.675000Z","event_type":"best_bid_ask","frame_hash":"772fbfe86295359df82ee4eb270c2f2d2e1d4e23c6e4a06344c760b4371d30aa","frame_index":0,"kind":"data","monotonic_ns":228612738207083,"payload":{"asset_id":"60386828328910021732068595344565885737045900010034836345809386672230885527307","best_ask":"0.64","best_bid":"0.59","event_type":"best_bid_ask","market":"0xeb66215f2e9faa6449e30a02bab5b8ed7b79a38bf961f6b24d0073c9c2419250","spread":"0.05","timestamp":"1785126627675"},"payload_hash":"150d66df72cc8535e50d993c654b1e8a37c2b2d8bf7a0ce2da2a6339a7b31d99","raw_frame":"{\"market\":\"0xeb66215f2e9faa6449e30a02bab5b8ed7b79a38bf961f6b24d0073c9c2419250\", \"asset_id\":\"60386828328910021732068595344565885737045900010034836345809386672230885527307\", \"best_bid\":\"0.59\", \"best_ask\":\"0.64\", \"spread\":\"0.05\", \"timestamp\":\"1785126627675\", \"event_type\":\"best_bid_ask\"}","received_at":"2026-07-27T04:30:29.468622Z","schema_version":"clob-market-ws.best_bid_ask.v1","sequence":null,"server_hash":null,"server_timestamp":"1785126627675","session_id":"e9443c7415a0419799bee9cfbb1a9e4d","source":"clob_market_ws"},"received_at":"2026-07-27T04:30:29.468622Z","record_id":"f1b96a10b72b1a54c53ec00dc5f14359ba0c115738118c9d87fff6d880b696c7","schema_fingerprint":"8488399f31b0337811b13b266be932db7062827c2470b78bd8e9e99bab51d17d","schema_version":"edge-lab-recorder.raw.v1","sequence":null,"source":"clob_market_ws"}
{"event_at":"2026-07-27T04:30:27.675000Z","event_fingerprint":"85fce87dc896e1b9a68748b247db19f432593e5f0c121bf2aa384d2f85c88930","payload":{"connection_id":"0f4979d6978d463e9660b042fdcf555f","event_at":"2026-07-27T04:30:27.675000Z","event_type":"price_change","frame_hash":"7c59fb21c09fb21ecb12735405aca04f8421bc2eaccf81dc7123a46ac0132a44","frame_index":0,"kind":"data","monotonic_ns":228612752970833,"payload":{"event_type":"price_change","market":"0xeb66215f2e9faa6449e30a02bab5b8ed7b79a38bf961f6b24d0073c9c2419250","price_changes":[{"asset_id":"69697746896130839564035629862476347944307040470122503199396727085502753297492","best_ask":"0.41","best_bid":"0.36","hash":"c40f69fb7c32b52cfa834395bad5f7451a062ac4","price":"0.4","side":"BUY","size":"0"},{"asset_id":"60386828328910021732068595344565885737045900010034836345809386672230885527307","best_ask":"0.64","best_bid":"0.59","hash":"00321adb391b60eb184e0d7e7d332e0c16870245","price":"0.6","side":"SELL","size":"0"}],"timestamp":"1785126627675"},"payload_hash":"447fe01cc989ec122de2acca328088287f3d3c2418bd8bd033dceb02d76e6941","raw_frame":"{\"market\":\"0xeb66215f2e9faa6449e30a02bab5b8ed7b79a38bf961f6b24d0073c9c2419250\", \"price_changes\":[{\"asset_id\":\"69697746896130839564035629862476347944307040470122503199396727085502753297492\", \"price\":\"0.4\", \"size\":\"0\", \"side\":\"BUY\", \"hash\":\"c40f69fb7c32b52cfa834395bad5f7451a062ac4\", \"best_bid\":\"0.36\", \"best_ask\":\"0.41\"}, {\"asset_id\":\"60386828328910021732068595344565885737045900010034836345809386672230885527307\", \"price\":\"0.6\", \"size\":\"0\", \"side\":\"SELL\", \"hash\":\"00321adb391b60eb184e0d7e7d332e0c16870245\", \"best_bid\":\"0.59\", \"best_ask\":\"0.64\"}], \"timestamp\":\"1785126627675\", \"event_type\":\"price_change\"}","received_at":"2026-07-27T04:30:29.483386Z","schema_version":"clob-market-ws.price_change.v1","sequence":null,"server_hash":null,"server_timestamp":"1785126627675","session_id":"e9443c7415a0419799bee9cfbb1a9e4d","source":"clob_market_ws"},"received_at":"2026-07-27T04:30:29.483386Z","record_id":"53073fdcf07f744f0f20fdf884ef3eba71820e277b61431879571bb8993d9513","schema_fingerprint":"4aa3821a28b0b7c2400bc59aba4bcc0a76e971dadd19610d3ad38c768e124dc7","schema_version":"edge-lab-recorder.raw.v1","sequence":null,"source":"clob_market_ws"}
