{"event_at":null,"event_fingerprint":"0cee66063543d37712b60a326a8b667f9ff64d92c0c99b6022d37341d3d3a2cf","payload":{"connection_id":"0f4979d6978d463e9660b042fdcf555f","detail":{"connection_number":1,"url":"wss://ws-subscriptions-clob.polymarket.com/ws/market"},"event_type":"connected","kind":"lifecycle","monotonic_ns":228342365203333,"received_at":"2026-07-27T04:25:59.093268Z","schema_version":"edge-lab-recorder.lifecycle.v1","session_id":"e9443c7415a0419799bee9cfbb1a9e4d","source":"clob_market_ws"},"received_at":"2026-07-27T04:25:59.093268Z","record_id":"8386005a86c576ef8a260eb6baebd25f1ee84e95e5082bc3685287cc8156babd","schema_fingerprint":"55796180566b13b76a84121638a57ef403d9319ab253f490d610e05227425126","schema_version":"edge-lab-recorder.raw.v1","sequence":null,"source":"clob_market_ws"}
{"event_at":null,"event_fingerprint":"02a1427c50b13a55f4b114470d7b72285dc1ba60731aa265b199cc709175bfcc","payload":{"connection_id":"0f4979d6978d463e9660b042fdcf555f","detail":{"subscription":{"assets_ids":["69697746896130839564035629862476347944307040470122503199396727085502753297492","60386828328910021732068595344565885737045900010034836345809386672230885527307"],"custom_feature_enabled":true,"type":"market"}},"event_type":"subscribed","kind":"lifecycle","monotonic_ns":228342367546958,"received_at":"2026-07-27T04:25:59.095617Z","schema_version":"edge-lab-recorder.lifecycle.v1","session_id":"e9443c7415a0419799bee9cfbb1a9e4d","source":"clob_market_ws"},"received_at":"2026-07-27T04:25:59.095617Z","record_id":"bb606bc7888d025f6f227f74a95178ec8ea858cfb111948679bfbf23e5c13ef6","schema_fingerprint":"b75a00837e5ec1c947d19ddcc8d68c4b066cd91e376ddfb07f3243c8653c02ea","schema_version":"edge-lab-recorder.raw.v1","sequence":null,"source":"clob_market_ws"}
{"event_at":null,"event_fingerprint":"e6564d3e25b5d4bbb9b694a9d79610430b48206c48c8d8e1886640884b148dbd","payload":{"connection_id":"0f4979d6978d463e9660b042fdcf555f","detail":{"connection_number":1},"event_type":"resync_begin","kind":"lifecycle","monotonic_ns":228342368589583,"received_at":"2026-07-27T04:25:59.096660Z","schema_version":"edge-lab-recorder.lifecycle.v1","session_id":"e9443c7415a0419799bee9cfbb1a9e4d","source":"clob_market_ws"},"received_at":"2026-07-27T04:25:59.096660Z","record_id":"94777260daab9f8115690595dd6e044de153a85ee1a4373258116005808294ab","schema_fingerprint":"16efb6e904eff9642268f91e8fb4718646b6f037026603a8520e9d118f1aea24","schema_version":"edge-lab-recorder.raw.v1","sequence":null,"source":"clob_market_ws"}
{"event_at":"2026-07-27T04:25:51.661000Z","event_fingerprint":"6a09729594b6b4bea544cdc6360373aa349c5dc88bdf8c0f2b9a5befd9e6f0bb","payload":{"connection_id":"0f4979d6978d463e9660b042fdcf555f","event_at":"2026-07-27T04:25:51.661000Z","event_type":"book","frame_hash":"beabb9c648339793cfb1e24ba657c169c811d55e36caf30d14b985f0e22c4442","frame_index":0,"kind":"quarantine","monotonic_ns":228342573048958,"payload":{"asks":[{"price":"0.99","size":"97895.02"},{"price":"0.98","size":"16850"},{"price":"0.97","size":"11088"},{"price":"0.96","size":"800"},{"price":"0.95","size":"5391"},{"price":"0.94","size":"671"},{"price":"0.93","size":"564"},{"price":"0.92","size":"626"},{"price":"0.91","size":"530"},{"price":"0.9","size":"2426"},{"price":"0.89","size":"21"},{"price":"0.88","size":"20"},{"price":"0.87","size":"18"},{"price":"0.86","size":"16"},{"price":"0.85","size":"1634"},{"price":"0.84","size":"12"},{"price":"0.83","size":"31"},{"price":"0.82","size":"10"},{"price":"0.81","size":"28"},{"price":"0.8","size":"1205"},{"price":"0.79","size":"245"},{"price":"0.78","size":"25"},{"price":"0.77","size":"5"},{"price":"0.76","size":"205"},{"price":"0.75","size":"965"},{"price":"0.74","size":"345"},{"price":"0.73","size":"25"},{"price":"0.72","size":"290"},{"price":"0.71","size":"55"},{"price":"0.7","size":"1045"},{"price":"0.69","size":"5"},{"price":"0.68","size":"125"},{"price":"0.67","size":"576"},{"price":"0.66","size":"160"},{"price":"0.65","size":"15"},{"price":"0.64","size":"759"},{"price":"0.62","size":"306.63"},{"price":"0.61","size":"48"},{"price":"0.6","size":"82"},{"price":"0.59","size":"47"},{"price":"0.58","size":"218"},{"price":"0.57","size":"350"},{"price":"0.56","size":"330.68"},{"price":"0.55","size":"115.33"},{"price":"0.54","size":"125"},{"price":"0.53","size":"64.67"},{"price":"0.52","size":"50"},{"price":"0.51","size":"11"},{"price":"0.5","size":"20"},{"price":"0.49","size":"25"},{"price":"0.48","size":"200.83"},{"price":"0.47","size":"200"},{"price":"0.46","size":"425.42"}],"asset_id":"69697746896130839564035629862476347944307040470122503199396727085502753297492","bids":[{"price":"0.01","size":"97895.02"},{"price":"0.02","size":"16850"},{"price":"0.03","size":"11088"},{"price":"0.04","size":"800"},{"price":"0.05","size":"5391"},{"price":"0.06","size":"671"},{"price":"0.07","size":"564"},{"price":"0.08","size":"626"},{"price":"0.09","size":"530"},{"price":"0.1","size":"2426"},{"price":"0.11","size":"21"},{"price":"0.12","size":"20"},{"price":"0.13","size":"18"},{"price":"0.14","size":"16"},{"price":"0.15","size":"1634"},{"price":"0.16","size":"12"},{"price":"0.17","size":"31"},{"price":"0.18","size":"10"},{"price":"0.19","size":"28"},{"price":"0.2","size":"1205"},{"price":"0.21","size":"245"},{"price":"0.22","size":"170"},{"price":"0.23","size":"5"},{"price":"0.24","size":"205"},{"price":"0.25","size":"965"},{"price":"0.26","size":"345"},{"price":"0.27","size":"170"},{"price":"0.28","size":"145"},{"price":"0.29","size":"55"},{"price":"0.3","size":"1045"},{"price":"0.31","size":"5"},{"price":"0.32","size":"270"},{"price":"0.33","size":"431"},{"price":"0.34","size":"160"},{"price":"0.35","size":"15"},{"price":"0.36","size":"765"},{"price":"0.37","size":"145"},{"price":"0.38","size":"167.63"},{"price":"0.39","size":"48"},{"price":"0.4","size":"185"},{"price":"0.41","size":"156"},{"price":"0.42","size":"322"},{"price":"0.43","size":"410"},{"price":"0.44","size":"455.68"},{"price":"0.45","size":"192.95"}],"event_type":"book","hash":"dff7d2261859f1c7424ffb30f695b707a29bd164","last_trade_price":"0.450","market":"0xeb66215f2e9faa6449e30a02bab5b8ed7b79a38bf961f6b24d0073c9c2419250","tick_size":"0.01","timestamp":"1785126351661"},"payload_hash":"a6700590ba0af478440b69a88cf982adba8e5ade730d44825e65e31447022470","raw_frame":"[{\"market\":\"0xeb66215f2e9faa6449e30a02bab5b8ed7b79a38bf961f6b24d0073c9c2419250\",\"asset_id\":\"69697746896130839564035629862476347944307040470122503199396727085502753297492\",\"timestamp\":\"1785126351661\",\"hash\":\"dff7d2261859f1c7424ffb30f695b707a29bd164\",\"bids\":[{\"price\":\"0.01\",\"size\":\"97895.02\"},{\"price\":\"0.02\",\"size\":\"16850\"},{\"price\":\"0.03\",\"size\":\"11088\"},{\"price\":\"0.04\",\"size\":\"800\"},{\"price\":\"0.05\",\"size\":\"5391\"},{\"price\":\"0.06\",\"size\":\"671\"},{\"price\":\"0.07\",\"size\":\"564\"},{\"price\":\"0.08\",\"size\":\"626\"},{\"price\":\"0.09\",\"size\":\"530\"},{\"price\":\"0.1\",\"size\":\"2426\"},{\"price\":\"0.11\",\"size\":\"21\"},{\"price\":\"0.12\",\"size\":\"20\"},{\"price\":\"0.13\",\"size\":\"18\"},{\"price\":\"0.14\",\"size\":\"16\"},{\"price\":\"0.15\",\"size\":\"1634\"},{\"price\":\"0.16\",\"size\":\"12\"},{\"price\":\"0.17\",\"size\":\"31\"},{\"price\":\"0.18\",\"size\":\"10\"},{\"price\":\"0.19\",\"size\":\"28\"},{\"price\":\"0.2\",\"size\":\"1205\"},{\"price\":\"0.21\",\"size\":\"245\"},{\"price\":\"0.22\",\"size\":\"170\"},{\"price\":\"0.23\",\"size\":\"5\"},{\"price\":\"0.24\",\"size\":\"205\"},{\"price\":\"0.25\",\"size\":\"965\"},{\"price\":\"0.26\",\"size\":\"345\"},{\"price\":\"0.27\",\"size\":\"170\"},{\"price\":\"0.28\",\"size\":\"145\"},{\"price\":\"0.29\",\"size\":\"55\"},{\"price\":\"0.3\",\"size\":\"1045\"},{\"price\":\"0.31\",\"size\":\"5\"},{\"price\":\"0.32\",\"size\":\"270\"},{\"price\":\"0.33\",\"size\":\"431\"},{\"price\":\"0.34\",\"size\":\"160\"},{\"price\":\"0.35\",\"size\":\"15\"},{\"price\":\"0.36\",\"size\":\"765\"},{\"price\":\"0.37\",\"size\":\"145\"},{\"price\":\"0.38\",\"size\":\"167.63\"},{\"price\":\"0.39\",\"size\":\"48\"},{\"price\":\"0.4\",\"size\":\"185\"},{\"price\":\"0.41\",\"size\":\"156\"},{\"price\":\"0.42\",\"size\":\"322\"},{\"price\":\"0.43\",\"size\":\"410\"},{\"price\":\"0.44\",\"size\":\"455.68\"},{\"price\":\"0.45\",\"size\":\"192.95\"}],\"asks\":[{\"price\":\"0.99\",\"size\":\"97895.02\"},{\"price\":\"0.98\",\"size\":\"16850\"},{\"price\":\"0.97\",\"size\":\"11088\"},{\"price\":\"0.96\",\"size\":\"800\"},{\"price\":\"0.95\",\"size\":\"5391\"},{\"price\":\"0.94\",\"size\":\"671\"},{\"price\":\"0.93\",\"size\":\"564\"},{\"price\":\"0.92\",\"size\":\"626\"},{\"price\":\"0.91\",\"size\":\"530\"},{\"price\":\"0.9\",\"size\":\"2426\"},{\"price\":\"0.89\",\"size\":\"21\"},{\"price\":\"0.88\",\"size\":\"20\"},{\"price\":\"0.87\",\"size\":\"18\"},{\"price\":\"0.86\",\"size\":\"16\"},{\"price\":\"0.85\",\"size\":\"1634\"},{\"price\":\"0.84\",\"size\":\"12\"},{\"price\":\"0.83\",\"size\":\"31\"},{\"price\":\"0.82\",\"size\":\"10\"},{\"price\":\"0.81\",\"size\":\"28\"},{\"price\":\"0.8\",\"size\":\"1205\"},{\"price\":\"0.79\",\"size\":\"245\"},{\"price\":\"0.78\",\"size\":\"25\"},{\"price\":\"0.77\",\"size\":\"5\"},{\"price\":\"0.76\",\"size\":\"205\"},{\"price\":\"0.75\",\"size\":\"965\"},{\"price\":\"0.74\",\"size\":\"345\"},{\"price\":\"0.73\",\"size\":\"25\"},{\"price\":\"0.72\",\"size\":\"290\"},{\"price\":\"0.71\",\"size\":\"55\"},{\"price\":\"0.7\",\"size\":\"1045\"},{\"price\":\"0.69\",\"size\":\"5\"},{\"price\":\"0.68\",\"size\":\"125\"},{\"price\":\"0.67\",\"size\":\"576\"},{\"price\":\"0.66\",\"size\":\"160\"},{\"price\":\"0.65\",\"size\":\"15\"},{\"price\":\"0.64\",\"size\":\"759\"},{\"price\":\"0.62\",\"size\":\"306.63\"},{\"price\":\"0.61\",\"size\":\"48\"},{\"price\":\"0.6\",\"size\":\"82\"},{\"price\":\"0.59\",\"size\":\"47\"},{\"price\":\"0.58\",\"size\":\"218\"},{\"price\":\"0.57\",\"size\":\"350\"},{\"price\":\"0.56\",\"size\":\"330.68\"},{\"price\":\"0.55\",\"size\":\"115.33\"},{\"price\":\"0.54\",\"size\":\"125\"},{\"price\":\"0.53\",\"size\":\"64.67\"},{\"price\":\"0.52\",\"size\":\"50\"},{\"price\":\"0.51\",\"size\":\"11\"},{\"price\":\"0.5\",\"size\":\"20\"},{\"price\":\"0.49\",\"size\":\"25\"},{\"price\":\"0.48\",\"size\":\"200.83\"},{\"price\":\"0.47\",\"size\":\"200\"},{\"price\":\"0.46\",\"size\":\"425.42\"}],\"tick_size\":\"0.01\",\"event_type\":\"book\",\"last_trade_price\":\"0.450\"},{\"market\":\"0xeb66215f2e9faa6449e30a02bab5b8ed7b79a38bf961f6b24d0073c9c2419250\",\"asset_id\":\"60386828328910021732068595344565885737045900010034836345809386672230885527307\",\"timestamp\":\"1785126351661\",\"hash\":\"4074f6407e2c5568413ae9eab60d1e0a712de1fa\",\"bids\":[{\"price\":\"0.01\",\"size\":\"97895.02\"},{\"price\":\"0.02\",\"size\":\"16850\"},{\"price\":\"0.03\",\"size\":\"11088\"},{\"price\":\"0.04\",\"size\":\"800\"},{\"price\":\"0.05\",\"size\":\"5391\"},{\"price\":\"0.06\",\"size\":\"671\"},{\"price\":\"0.07\",\"size\":\"564\"},{\"price\":\"0.08\",\"size\":\"626\"},{\"price\":\"0.09\",\"size\":\"530\"},{\"price\":\"0.1\",\"size\":\"2426\"},{\"price\":\"0.11\",\"size\":\"21\"},{\"price\":\"0.12\",\"size\":\"20\"},{\"price\":\"0.13\",\"size\":\"18\"},{\"price\":\"0.14\",\"size\":\"16\"},{\"price\":\"0.15\",\"size\":\"1634\"},{\"price\":\"0.16\",\"size\":\"12\"},{\"price\":\"0.17\",\"size\":\"31\"},{\"price\":\"0.18\",\"size\":\"10\"},{\"price\":\"0.19\",\"size\":\"28\"},{\"price\":\"0.2\",\"size\":\"1205\"},{\"price\":\"0.21\",\"size\":\"245\"},{\"price\":\"0.22\",\"size\":\"25\"},{\"price\":\"0.23\",\"size\":\"5\"},{\"price\":\"0.24\",\"size\":\"205\"},{\"price\":\"0.25\",\"size\":\"965\"},{\"price\":\"0.26\",\"size\":\"345\"},{\"price\":\"0.27\",\"size\":\"25\"},{\"price\":\"0.28\",\"size\":\"290\"},{\"price\":\"0.29\",\"size\":\"55\"},{\"price\":\"0.3\",\"size\":\"1045\"},{\"price\":\"0.31\",\"size\":\"5\"},{\"price\":\"0.32\",\"size\":\"125\"},{\"price\":\"0.33\",\"size\":\"576\"},{\"price\":\"0.34\",\"size\":\"160\"},{\"price\":\"0.35\",\"size\":\"15\"},{\"price\":\"0.36\",\"size\":\"759\"},{\"price\":\"0.38\",\"size\":\"306.63\"},{\"price\":\"0.39\",\"size\":\"48\"},{\"price\":\"0.4\",\"size\":\"82\"},{\"price\":\"0.41\",\"size\":\"47\"},{\"price\":\"0.42\",\"size\":\"218\"},{\"price\":\"0.43\",\"size\":\"350\"},{\"price\":\"0.44\",\"size\":\"330.68\"},{\"price\":\"0.45\",\"size\":\"115.33\"},{\"price\":\"0.46\",\"size\":\"125\"},{\"price\":\"0.47\",\"size\":\"64.67\"},{\"price\":\"0.48\",\"size\":\"50\"},{\"price\":\"0.49\",\"size\":\"11\"},{\"price\":\"0.5\",\"size\":\"20\"},{\"price\":\"0.51\",\"size\":\"25\"},{\"price\":\"0.52\",\"size\":\"200.83\"},{\"price\":\"0.53\",\"size\":\"200\"},{\"price\":\"0.54\",\"size\":\"425.42\"}],\"asks\":[{\"price\":\"0.99\",\"size\":\"97895.02\"},{\"price\":\"0.98\",\"size\":\"16850\"},{\"price\":\"0.97\",\"size\":\"11088\"},{\"price\":\"0.96\",\"size\":\"800\"},{\"price\":\"0.95\",\"size\":\"5391\"},{\"price\":\"0.94\",\"size\":\"671\"},{\"price\":\"0.93\",\"size\":\"564\"},{\"price\":\"0.92\",\"size\":\"626\"},{\"price\":\"0.91\",\"size\":\"530\"},{\"price\":\"0.9\",\"size\":\"2426\"},{\"price\":\"0.89\",\"size\":\"21\"},{\"price\":\"0.88\",\"size\":\"20\"},{\"price\":\"0.87\",\"size\":\"18\"},{\"price\":\"0.86\",\"size\":\"16\"},{\"price\":\"0.85\",\"size\":\"1634\"},{\"price\":\"0.84\",\"size\":\"12\"},{\"price\":\"0.83\",\"size\":\"31\"},{\"price\":\"0.82\",\"size\":\"10\"},{\"price\":\"0.81\",\"size\":\"28\"},{\"price\":\"0.8\",\"size\":\"1205\"},{\"price\":\"0.79\",\"size\":\"245\"},{\"price\":\"0.78\",\"size\":\"170\"},{\"price\":\"0.77\",\"size\":\"5\"},{\"price\":\"0.76\",\"size\":\"205\"},{\"price\":\"0.75\",\"size\":\"965\"},{\"price\":\"0.74\",\"size\":\"345\"},{\"price\":\"0.73\",\"size\":\"170\"},{\"price\":\"0.72\",\"size\":\"145\"},{\"price\":\"0.71\",\"size\":\"55\"},{\"price\":\"0.7\",\"size\":\"1045\"},{\"price\":\"0.69\",\"size\":\"5\"},{\"price\":\"0.68\",\"size\":\"270\"},{\"price\":\"0.67\",\"size\":\"431\"},{\"price\":\"0.66\",\"size\":\"160\"},{\"price\":\"0.65\",\"size\":\"15\"},{\"price\":\"0.64\",\"size\":\"765\"},{\"price\":\"0.63\",\"size\":\"145\"},{\"price\":\"0.62\",\"size\":\"167.63\"},{\"price\":\"0.61\",\"size\":\"48\"},{\"price\":\"0.6\",\"size\":\"185\"},{\"price\":\"0.59\",\"size\":\"156\"},{\"price\":\"0.58\",\"size\":\"322\"},{\"price\":\"0.57\",\"size\":\"410\"},{\"price\":\"0.56\",\"size\":\"455.68\"},{\"price\":\"0.55\",\"size\":\"192.95\"}],\"tick_size\":\"0.01\",\"event_type\":\"book\",\"last_trade_price\":\"0.450\"}]\n","received_at":"2026-07-27T04:25:59.301116Z","replay_eligible":false,"resync_asset_ids":["69697746896130839564035629862476347944307040470122503199396727085502753297492"],"resync_asset_watermarks_ns":{"69697746896130839564035629862476347944307040470122503199396727085502753297492":1785126363605000000},"resync_buffered":true,"resync_status":"success","resync_watermark_ns":1785126363605000000,"schema_version":"clob-market-ws.book.v1","sequence":null,"server_hash":"dff7d2261859f1c7424ffb30f695b707a29bd164","server_timestamp":"1785126351661","session_id":"e9443c7415a0419799bee9cfbb1a9e4d","source":"clob_market_ws"},"received_at":"2026-07-27T04:25:59.301116Z","record_id":"a601bc02b36ae1c9544c2b593bd9d61a931fbd06f41ded2afcd3dbdb99e44cae","schema_fingerprint":"2fd167682ccd8f3c0d11d8d0b8181bd61407ee63d4a4d4f7fd9005b66c0e91a8","schema_version":"edge-lab-recorder.raw.v1","sequence":null,"source":"clob_market_ws"}
{"event_at":"2026-07-27T04:25:51.661000Z","event_fingerprint":"68b5df379e7abe611985268dadfce811a15ef2ae086645fbbdbb6c2fb1157390","payload":{"connection_id":"0f4979d6978d463e9660b042fdcf555f","event_at":"2026-07-27T04:25:51.661000Z","event_type":"book","frame_hash":"beabb9c648339793cfb1e24ba657c169c811d55e36caf30d14b985f0e22c4442","frame_index":1,"kind":"quarantine","monotonic_ns":228342573048958,"payload":{"asks":[{"price":"0.99","size":"97895.02"},{"price":"0.98","size":"16850"},{"price":"0.97","size":"11088"},{"price":"0.96","size":"800"},{"price":"0.95","size":"5391"},{"price":"0.94","size":"671"},{"price":"0.93","size":"564"},{"price":"0.92","size":"626"},{"price":"0.91","size":"530"},{"price":"0.9","size":"2426"},{"price":"0.89","size":"21"},{"price":"0.88","size":"20"},{"price":"0.87","size":"18"},{"price":"0.86","size":"16"},{"price":"0.85","size":"1634"},{"price":"0.84","size":"12"},{"price":"0.83","size":"31"},{"price":"0.82","size":"10"},{"price":"0.81","size":"28"},{"price":"0.8","size":"1205"},{"price":"0.79","size":"245"},{"price":"0.78","size":"170"},{"price":"0.77","size":"5"},{"price":"0.76","size":"205"},{"price":"0.75","size":"965"},{"price":"0.74","size":"345"},{"price":"0.73","size":"170"},{"price":"0.72","size":"145"},{"price":"0.71","size":"55"},{"price":"0.7","size":"1045"},{"price":"0.69","size":"5"},{"price":"0.68","size":"270"},{"price":"0.67","size":"431"},{"price":"0.66","size":"160"},{"price":"0.65","size":"15"},{"price":"0.64","size":"765"},{"price":"0.63","size":"145"},{"price":"0.62","size":"167.63"},{"price":"0.61","size":"48"},{"price":"0.6","size":"185"},{"price":"0.59","size":"156"},{"price":"0.58","size":"322"},{"price":"0.57","size":"410"},{"price":"0.56","size":"455.68"},{"price":"0.55","size":"192.95"}],"asset_id":"60386828328910021732068595344565885737045900010034836345809386672230885527307","bids":[{"price":"0.01","size":"97895.02"},{"price":"0.02","size":"16850"},{"price":"0.03","size":"11088"},{"price":"0.04","size":"800"},{"price":"0.05","size":"5391"},{"price":"0.06","size":"671"},{"price":"0.07","size":"564"},{"price":"0.08","size":"626"},{"price":"0.09","size":"530"},{"price":"0.1","size":"2426"},{"price":"0.11","size":"21"},{"price":"0.12","size":"20"},{"price":"0.13","size":"18"},{"price":"0.14","size":"16"},{"price":"0.15","size":"1634"},{"price":"0.16","size":"12"},{"price":"0.17","size":"31"},{"price":"0.18","size":"10"},{"price":"0.19","size":"28"},{"price":"0.2","size":"1205"},{"price":"0.21","size":"245"},{"price":"0.22","size":"25"},{"price":"0.23","size":"5"},{"price":"0.24","size":"205"},{"price":"0.25","size":"965"},{"price":"0.26","size":"345"},{"price":"0.27","size":"25"},{"price":"0.28","size":"290"},{"price":"0.29","size":"55"},{"price":"0.3","size":"1045"},{"price":"0.31","size":"5"},{"price":"0.32","size":"125"},{"price":"0.33","size":"576"},{"price":"0.34","size":"160"},{"price":"0.35","size":"15"},{"price":"0.36","size":"759"},{"price":"0.38","size":"306.63"},{"price":"0.39","size":"48"},{"price":"0.4","size":"82"},{"price":"0.41","size":"47"},{"price":"0.42","size":"218"},{"price":"0.43","size":"350"},{"price":"0.44","size":"330.68"},{"price":"0.45","size":"115.33"},{"price":"0.46","size":"125"},{"price":"0.47","size":"64.67"},{"price":"0.48","size":"50"},{"price":"0.49","size":"11"},{"price":"0.5","size":"20"},{"price":"0.51","size":"25"},{"price":"0.52","size":"200.83"},{"price":"0.53","size":"200"},{"price":"0.54","size":"425.42"}],"event_type":"book","hash":"4074f6407e2c5568413ae9eab60d1e0a712de1fa","last_trade_price":"0.450","market":"0xeb66215f2e9faa6449e30a02bab5b8ed7b79a38bf961f6b24d0073c9c2419250","tick_size":"0.01","timestamp":"1785126351661"},"payload_hash":"6be4fdba910a04098f21fcb8a4d63f06b58c10d94feec027888de9f022547f7c","raw_frame":"[{\"market\":\"0xeb66215f2e9faa6449e30a02bab5b8ed7b79a38bf961f6b24d0073c9c2419250\",\"asset_id\":\"69697746896130839564035629862476347944307040470122503199396727085502753297492\",\"timestamp\":\"1785126351661\",\"hash\":\"dff7d2261859f1c7424ffb30f695b707a29bd164\",\"bids\":[{\"price\":\"0.01\",\"size\":\"97895.02\"},{\"price\":\"0.02\",\"size\":\"16850\"},{\"price\":\"0.03\",\"size\":\"11088\"},{\"price\":\"0.04\",\"size\":\"800\"},{\"price\":\"0.05\",\"size\":\"5391\"},{\"price\":\"0.06\",\"size\":\"671\"},{\"price\":\"0.07\",\"size\":\"564\"},{\"price\":\"0.08\",\"size\":\"626\"},{\"price\":\"0.09\",\"size\":\"530\"},{\"price\":\"0.1\",\"size\":\"2426\"},{\"price\":\"0.11\",\"size\":\"21\"},{\"price\":\"0.12\",\"size\":\"20\"},{\"price\":\"0.13\",\"size\":\"18\"},{\"price\":\"0.14\",\"size\":\"16\"},{\"price\":\"0.15\",\"size\":\"1634\"},{\"price\":\"0.16\",\"size\":\"12\"},{\"price\":\"0.17\",\"size\":\"31\"},{\"price\":\"0.18\",\"size\":\"10\"},{\"price\":\"0.19\",\"size\":\"28\"},{\"price\":\"0.2\",\"size\":\"1205\"},{\"price\":\"0.21\",\"size\":\"245\"},{\"price\":\"0.22\",\"size\":\"170\"},{\"price\":\"0.23\",\"size\":\"5\"},{\"price\":\"0.24\",\"size\":\"205\"},{\"price\":\"0.25\",\"size\":\"965\"},{\"price\":\"0.26\",\"size\":\"345\"},{\"price\":\"0.27\",\"size\":\"170\"},{\"price\":\"0.28\",\"size\":\"145\"},{\"price\":\"0.29\",\"size\":\"55\"},{\"price\":\"0.3\",\"size\":\"1045\"},{\"price\":\"0.31\",\"size\":\"5\"},{\"price\":\"0.32\",\"size\":\"270\"},{\"price\":\"0.33\",\"size\":\"431\"},{\"price\":\"0.34\",\"size\":\"160\"},{\"price\":\"0.35\",\"size\":\"15\"},{\"price\":\"0.36\",\"size\":\"765\"},{\"price\":\"0.37\",\"size\":\"145\"},{\"price\":\"0.38\",\"size\":\"167.63\"},{\"price\":\"0.39\",\"size\":\"48\"},{\"price\":\"0.4\",\"size\":\"185\"},{\"price\":\"0.41\",\"size\":\"156\"},{\"price\":\"0.42\",\"size\":\"322\"},{\"price\":\"0.43\",\"size\":\"410\"},{\"price\":\"0.44\",\"size\":\"455.68\"},{\"price\":\"0.45\",\"size\":\"192.95\"}],\"asks\":[{\"price\":\"0.99\",\"size\":\"97895.02\"},{\"price\":\"0.98\",\"size\":\"16850\"},{\"price\":\"0.97\",\"size\":\"11088\"},{\"price\":\"0.96\",\"size\":\"800\"},{\"price\":\"0.95\",\"size\":\"5391\"},{\"price\":\"0.94\",\"size\":\"671\"},{\"price\":\"0.93\",\"size\":\"564\"},{\"price\":\"0.92\",\"size\":\"626\"},{\"price\":\"0.91\",\"size\":\"530\"},{\"price\":\"0.9\",\"size\":\"2426\"},{\"price\":\"0.89\",\"size\":\"21\"},{\"price\":\"0.88\",\"size\":\"20\"},{\"price\":\"0.87\",\"size\":\"18\"},{\"price\":\"0.86\",\"size\":\"16\"},{\"price\":\"0.85\",\"size\":\"1634\"},{\"price\":\"0.84\",\"size\":\"12\"},{\"price\":\"0.83\",\"size\":\"31\"},{\"price\":\"0.82\",\"size\":\"10\"},{\"price\":\"0.81\",\"size\":\"28\"},{\"price\":\"0.8\",\"size\":\"1205\"},{\"price\":\"0.79\",\"size\":\"245\"},{\"price\":\"0.78\",\"size\":\"25\"},{\"price\":\"0.77\",\"size\":\"5\"},{\"price\":\"0.76\",\"size\":\"205\"},{\"price\":\"0.75\",\"size\":\"965\"},{\"price\":\"0.74\",\"size\":\"345\"},{\"price\":\"0.73\",\"size\":\"25\"},{\"price\":\"0.72\",\"size\":\"290\"},{\"price\":\"0.71\",\"size\":\"55\"},{\"price\":\"0.7\",\"size\":\"1045\"},{\"price\":\"0.69\",\"size\":\"5\"},{\"price\":\"0.68\",\"size\":\"125\"},{\"price\":\"0.67\",\"size\":\"576\"},{\"price\":\"0.66\",\"size\":\"160\"},{\"price\":\"0.65\",\"size\":\"15\"},{\"price\":\"0.64\",\"size\":\"759\"},{\"price\":\"0.62\",\"size\":\"306.63\"},{\"price\":\"0.61\",\"size\":\"48\"},{\"price\":\"0.6\",\"size\":\"82\"},{\"price\":\"0.59\",\"size\":\"47\"},{\"price\":\"0.58\",\"size\":\"218\"},{\"price\":\"0.57\",\"size\":\"350\"},{\"price\":\"0.56\",\"size\":\"330.68\"},{\"price\":\"0.55\",\"size\":\"115.33\"},{\"price\":\"0.54\",\"size\":\"125\"},{\"price\":\"0.53\",\"size\":\"64.67\"},{\"price\":\"0.52\",\"size\":\"50\"},{\"price\":\"0.51\",\"size\":\"11\"},{\"price\":\"0.5\",\"size\":\"20\"},{\"price\":\"0.49\",\"size\":\"25\"},{\"price\":\"0.48\",\"size\":\"200.83\"},{\"price\":\"0.47\",\"size\":\"200\"},{\"price\":\"0.46\",\"size\":\"425.42\"}],\"tick_size\":\"0.01\",\"event_type\":\"book\",\"last_trade_price\":\"0.450\"},{\"market\":\"0xeb66215f2e9faa6449e30a02bab5b8ed7b79a38bf961f6b24d0073c9c2419250\",\"asset_id\":\"60386828328910021732068595344565885737045900010034836345809386672230885527307\",\"timestamp\":\"1785126351661\",\"hash\":\"4074f6407e2c5568413ae9eab60d1e0a712de1fa\",\"bids\":[{\"price\":\"0.01\",\"size\":\"97895.02\"},{\"price\":\"0.02\",\"size\":\"16850\"},{\"price\":\"0.03\",\"size\":\"11088\"},{\"price\":\"0.04\",\"size\":\"800\"},{\"price\":\"0.05\",\"size\":\"5391\"},{\"price\":\"0.06\",\"size\":\"671\"},{\"price\":\"0.07\",\"size\":\"564\"},{\"price\":\"0.08\",\"size\":\"626\"},{\"price\":\"0.09\",\"size\":\"530\"},{\"price\":\"0.1\",\"size\":\"2426\"},{\"price\":\"0.11\",\"size\":\"21\"},{\"price\":\"0.12\",\"size\":\"20\"},{\"price\":\"0.13\",\"size\":\"18\"},{\"price\":\"0.14\",\"size\":\"16\"},{\"price\":\"0.15\",\"size\":\"1634\"},{\"price\":\"0.16\",\"size\":\"12\"},{\"price\":\"0.17\",\"size\":\"31\"},{\"price\":\"0.18\",\"size\":\"10\"},{\"price\":\"0.19\",\"size\":\"28\"},{\"price\":\"0.2\",\"size\":\"1205\"},{\"price\":\"0.21\",\"size\":\"245\"},{\"price\":\"0.22\",\"size\":\"25\"},{\"price\":\"0.23\",\"size\":\"5\"},{\"price\":\"0.24\",\"size\":\"205\"},{\"price\":\"0.25\",\"size\":\"965\"},{\"price\":\"0.26\",\"size\":\"345\"},{\"price\":\"0.27\",\"size\":\"25\"},{\"price\":\"0.28\",\"size\":\"290\"},{\"price\":\"0.29\",\"size\":\"55\"},{\"price\":\"0.3\",\"size\":\"1045\"},{\"price\":\"0.31\",\"size\":\"5\"},{\"price\":\"0.32\",\"size\":\"125\"},{\"price\":\"0.33\",\"size\":\"576\"},{\"price\":\"0.34\",\"size\":\"160\"},{\"price\":\"0.35\",\"size\":\"15\"},{\"price\":\"0.36\",\"size\":\"759\"},{\"price\":\"0.38\",\"size\":\"306.63\"},{\"price\":\"0.39\",\"size\":\"48\"},{\"price\":\"0.4\",\"size\":\"82\"},{\"price\":\"0.41\",\"size\":\"47\"},{\"price\":\"0.42\",\"size\":\"218\"},{\"price\":\"0.43\",\"size\":\"350\"},{\"price\":\"0.44\",\"size\":\"330.68\"},{\"price\":\"0.45\",\"size\":\"115.33\"},{\"price\":\"0.46\",\"size\":\"125\"},{\"price\":\"0.47\",\"size\":\"64.67\"},{\"price\":\"0.48\",\"size\":\"50\"},{\"price\":\"0.49\",\"size\":\"11\"},{\"price\":\"0.5\",\"size\":\"20\"},{\"price\":\"0.51\",\"size\":\"25\"},{\"price\":\"0.52\",\"size\":\"200.83\"},{\"price\":\"0.53\",\"size\":\"200\"},{\"price\":\"0.54\",\"size\":\"425.42\"}],\"asks\":[{\"price\":\"0.99\",\"size\":\"97895.02\"},{\"price\":\"0.98\",\"size\":\"16850\"},{\"price\":\"0.97\",\"size\":\"11088\"},{\"price\":\"0.96\",\"size\":\"800\"},{\"price\":\"0.95\",\"size\":\"5391\"},{\"price\":\"0.94\",\"size\":\"671\"},{\"price\":\"0.93\",\"size\":\"564\"},{\"price\":\"0.92\",\"size\":\"626\"},{\"price\":\"0.91\",\"size\":\"530\"},{\"price\":\"0.9\",\"size\":\"2426\"},{\"price\":\"0.89\",\"size\":\"21\"},{\"price\":\"0.88\",\"size\":\"20\"},{\"price\":\"0.87\",\"size\":\"18\"},{\"price\":\"0.86\",\"size\":\"16\"},{\"price\":\"0.85\",\"size\":\"1634\"},{\"price\":\"0.84\",\"size\":\"12\"},{\"price\":\"0.83\",\"size\":\"31\"},{\"price\":\"0.82\",\"size\":\"10\"},{\"price\":\"0.81\",\"size\":\"28\"},{\"price\":\"0.8\",\"size\":\"1205\"},{\"price\":\"0.79\",\"size\":\"245\"},{\"price\":\"0.78\",\"size\":\"170\"},{\"price\":\"0.77\",\"size\":\"5\"},{\"price\":\"0.76\",\"size\":\"205\"},{\"price\":\"0.75\",\"size\":\"965\"},{\"price\":\"0.74\",\"size\":\"345\"},{\"price\":\"0.73\",\"size\":\"170\"},{\"price\":\"0.72\",\"size\":\"145\"},{\"price\":\"0.71\",\"size\":\"55\"},{\"price\":\"0.7\",\"size\":\"1045\"},{\"price\":\"0.69\",\"size\":\"5\"},{\"price\":\"0.68\",\"size\":\"270\"},{\"price\":\"0.67\",\"size\":\"431\"},{\"price\":\"0.66\",\"size\":\"160\"},{\"price\":\"0.65\",\"size\":\"15\"},{\"price\":\"0.64\",\"size\":\"765\"},{\"price\":\"0.63\",\"size\":\"145\"},{\"price\":\"0.62\",\"size\":\"167.63\"},{\"price\":\"0.61\",\"size\":\"48\"},{\"price\":\"0.6\",\"size\":\"185\"},{\"price\":\"0.59\",\"size\":\"156\"},{\"price\":\"0.58\",\"size\":\"322\"},{\"price\":\"0.57\",\"size\":\"410\"},{\"price\":\"0.56\",\"size\":\"455.68\"},{\"price\":\"0.55\",\"size\":\"192.95\"}],\"tick_size\":\"0.01\",\"event_type\":\"book\",\"last_trade_price\":\"0.450\"}]\n","received_at":"2026-07-27T04:25:59.301116Z","replay_eligible":false,"resync_asset_ids":["60386828328910021732068595344565885737045900010034836345809386672230885527307"],"resync_asset_watermarks_ns":{"60386828328910021732068595344565885737045900010034836345809386672230885527307":1785126367331000000},"resync_buffered":true,"resync_status":"success","resync_watermark_ns":1785126367331000000,"schema_version":"clob-market-ws.book.v1","sequence":null,"server_hash":"4074f6407e2c5568413ae9eab60d1e0a712de1fa","server_timestamp":"1785126351661","session_id":"e9443c7415a0419799bee9cfbb1a9e4d","source":"clob_market_ws"},"received_at":"2026-07-27T04:25:59.301116Z","record_id":"c37beb51efc4356bd0159e436786c06c25df7e395b014054520041460610490c","schema_fingerprint":"64ddbb75e2ff311a0f7f26c7fff30ab73924824daf49bfed69103bbdd2393fcc","schema_version":"edge-lab-recorder.raw.v1","sequence":null,"source":"clob_market_ws"}
{"event_at":"2026-07-27T04:26:00.594000Z","event_fingerprint":"9ccdaadff68158953d8d00ec248b711a85c6543b6c74efbbc180ef3b58d30044","payload":{"connection_id":"0f4979d6978d463e9660b042fdcf555f","event_at":"2026-07-27T04:26:00.594000Z","event_type":"price_change","frame_hash":"c100c9852c5996f2f42779f8099a7c8b1e6bf7cec1ac1cb28a64ee5d29c2e2dd","frame_index":0,"kind":"quarantine","monotonic_ns":228343808340750,"payload":{"event_type":"price_change","market":"0xeb66215f2e9faa6449e30a02bab5b8ed7b79a38bf961f6b24d0073c9c2419250","price_changes":[{"asset_id":"69697746896130839564035629862476347944307040470122503199396727085502753297492","best_ask":"0.46","best_bid":"0.45","hash":"f97cc55ebbd3ada95fa717c603aa5158c0abaa59","price":"0.23","side":"BUY","size":"26.74"},{"asset_id":"60386828328910021732068595344565885737045900010034836345809386672230885527307","best_ask":"0.55","best_bid":"0.54","hash":"52e0c1f75fbdc7207937e34c801c551b921abb99","price":"0.77","side":"SELL","size":"26.74"}],"timestamp":"1785126360594"},"payload_hash":"af2527ff435428e37d9e7576e5aad3058a7127ab2319ee49accbf5b6439a151b","raw_frame":"{\"market\":\"0xeb66215f2e9faa6449e30a02bab5b8ed7b79a38bf961f6b24d0073c9c2419250\", \"price_changes\":[{\"asset_id\":\"69697746896130839564035629862476347944307040470122503199396727085502753297492\", \"price\":\"0.23\", \"size\":\"26.74\", \"side\":\"BUY\", \"hash\":\"f97cc55ebbd3ada95fa717c603aa5158c0abaa59\", \"best_bid\":\"0.45\", \"best_ask\":\"0.46\"}, {\"asset_id\":\"60386828328910021732068595344565885737045900010034836345809386672230885527307\", \"price\":\"0.77\", \"size\":\"26.74\", \"side\":\"SELL\", \"hash\":\"52e0c1f75fbdc7207937e34c801c551b921abb99\", \"best_bid\":\"0.54\", \"best_ask\":\"0.55\"}], \"timestamp\":\"1785126360594\", \"event_type\":\"price_change\"}","received_at":"2026-07-27T04:26:00.536426Z","replay_eligible":false,"resync_asset_ids":["60386828328910021732068595344565885737045900010034836345809386672230885527307","69697746896130839564035629862476347944307040470122503199396727085502753297492"],"resync_asset_watermarks_ns":{"60386828328910021732068595344565885737045900010034836345809386672230885527307":1785126367331000000,"69697746896130839564035629862476347944307040470122503199396727085502753297492":1785126363605000000},"resync_buffered":true,"resync_status":"success","resync_watermark_ns":1785126367331000000,"schema_version":"clob-market-ws.price_change.v1","sequence":null,"server_hash":null,"server_timestamp":"1785126360594","session_id":"e9443c7415a0419799bee9cfbb1a9e4d","source":"clob_market_ws"},"received_at":"2026-07-27T04:26:00.536426Z","record_id":"465d2c4ec9c154d9943fae0526e64ca627159570cab353b821af5429e855ae47","schema_fingerprint":"a522b3829e2baa1444da15da10771d4b0020c6969989c3325606306f55b0b63e","schema_version":"edge-lab-recorder.raw.v1","sequence":null,"source":"clob_market_ws"}
{"event_at":"2026-07-27T04:26:00.594000Z","event_fingerprint":"3de92292c7e0c7e0300e8cccd19d21d2ea814e26e0f2a11e6136f0de68512639","payload":{"connection_id":"0f4979d6978d463e9660b042fdcf555f","event_at":"2026-07-27T04:26:00.594000Z","event_type":"price_change","frame_hash":"c478ea472214d614f4c23aed07c5b1b80746d8b26201cf9115fbe9524093ff76","frame_index":0,"kind":"quarantine","monotonic_ns":228343808366916,"payload":{"event_type":"price_change","market":"0xeb66215f2e9faa6449e30a02bab5b8ed7b79a38bf961f6b24d0073c9c2419250","price_changes":[{"asset_id":"69697746896130839564035629862476347944307040470122503199396727085502753297492","best_ask":"0.46","best_bid":"0.45","hash":"3c12354bf3601a31e9818ad8369835d8c035e165","price":"0.06","side":"BUY","size":"754.34"},{"asset_id":"60386828328910021732068595344565885737045900010034836345809386672230885527307","best_ask":"0.55","best_bid":"0.54","hash":"18eee19e15ffe1817dcaf10a85f569343eb31c89","price":"0.94","side":"SELL","size":"754.34"}],"timestamp":"1785126360594"},"payload_hash":"58eae25337565ca0e48c51413232951def2de06849b35a9db359d73d45c031d9","raw_frame":"{\"market\":\"0xeb66215f2e9faa6449e30a02bab5b8ed7b79a38bf961f6b24d0073c9c2419250\", \"price_changes\":[{\"asset_id\":\"69697746896130839564035629862476347944307040470122503199396727085502753297492\", \"price\":\"0.06\", \"size\":\"754.34\", \"side\":\"BUY\", \"hash\":\"3c12354bf3601a31e9818ad8369835d8c035e165\", \"best_bid\":\"0.45\", \"best_ask\":\"0.46\"}, {\"asset_id\":\"60386828328910021732068595344565885737045900010034836345809386672230885527307\", \"price\":\"0.94\", \"size\":\"754.34\", \"side\":\"SELL\", \"hash\":\"18eee19e15ffe1817dcaf10a85f569343eb31c89\", \"best_bid\":\"0.54\", \"best_ask\":\"0.55\"}], \"timestamp\":\"1785126360594\", \"event_type\":\"price_change\"}","received_at":"2026-07-27T04:26:00.536454Z","replay_eligible":false,"resync_asset_ids":["60386828328910021732068595344565885737045900010034836345809386672230885527307","69697746896130839564035629862476347944307040470122503199396727085502753297492"],"resync_asset_watermarks_ns":{"60386828328910021732068595344565885737045900010034836345809386672230885527307":1785126367331000000,"69697746896130839564035629862476347944307040470122503199396727085502753297492":1785126363605000000},"resync_buffered":true,"resync_status":"success","resync_watermark_ns":1785126367331000000,"schema_version":"clob-market-ws.price_change.v1","sequence":null,"server_hash":null,"server_timestamp":"1785126360594","session_id":"e9443c7415a0419799bee9cfbb1a9e4d","source":"clob_market_ws"},"received_at":"2026-07-27T04:26:00.536454Z","record_id":"00b270993e2f075d4920fb8ac82f0075c8ce51eb8b756fc22e4133c4645f22cf","schema_fingerprint":"a522b3829e2baa1444da15da10771d4b0020c6969989c3325606306f55b0b63e","schema_version":"edge-lab-recorder.raw.v1","sequence":null,"source":"clob_market_ws"}
{"event_at":"2026-07-27T04:26:00.595000Z","event_fingerprint":"279a5951353c44fe0316d7b549bdb05fb6571c7086701adbd750e88db07ace61","payload":{"connection_id":"0f4979d6978d463e9660b042fdcf555f","event_at":"2026-07-27T04:26:00.595000Z","event_type":"price_change","frame_hash":"a9ad2e616f4631dbfaed78b2b9346d2a1dce712bba8aa154386012735f66f84b","frame_index":0,"kind":"quarantine","monotonic_ns":228343810281083,"payload":{"event_type":"price_change","market":"0xeb66215f2e9faa6449e30a02bab5b8ed7b79a38bf961f6b24d0073c9c2419250","price_changes":[{"asset_id":"60386828328910021732068595344565885737045900010034836345809386672230885527307","best_ask":"0.55","best_bid":"0.54","hash":"7d7c47b24747e2abe97933e0f77b6f2461ab2ca3","price":"0.11","side":"BUY","size":"66.46"},{"asset_id":"69697746896130839564035629862476347944307040470122503199396727085502753297492","best_ask":"0.46","best_bid":"0.45","hash":"16671fda60b121cb558f9d3889199df3b503446f","price":"0.89","side":"SELL","size":"66.46"}],"timestamp":"1785126360595"},"payload_hash":"bf79afddf16d36c5650c03cf18e4d3d5970553209196c1141fd14c05b50bab8e","raw_frame":"{\"market\":\"0xeb66215f2e9faa6449e30a02bab5b8ed7b79a38bf961f6b24d0073c9c2419250\", \"price_changes\":[{\"asset_id\":\"60386828328910021732068595344565885737045900010034836345809386672230885527307\", \"price\":\"0.11\", \"size\":\"66.46\", \"side\":\"BUY\", \"hash\":\"7d7c47b24747e2abe97933e0f77b6f2461ab2ca3\", \"best_bid\":\"0.54\", \"best_ask\":\"0.55\"}, {\"asset_id\":\"69697746896130839564035629862476347944307040470122503199396727085502753297492\", \"price\":\"0.89\", \"size\":\"66.46\", \"side\":\"SELL\", \"hash\":\"16671fda60b121cb558f9d3889199df3b503446f\", \"best_bid\":\"0.45\", \"best_ask\":\"0.46\"}], \"timestamp\":\"1785126360595\", \"event_type\":\"price_change\"}","received_at":"2026-07-27T04:26:00.538362Z","replay_eligible":false,"resync_asset_ids":["60386828328910021732068595344565885737045900010034836345809386672230885527307","69697746896130839564035629862476347944307040470122503199396727085502753297492"],"resync_asset_watermarks_ns":{"60386828328910021732068595344565885737045900010034836345809386672230885527307":1785126367331000000,"69697746896130839564035629862476347944307040470122503199396727085502753297492":1785126363605000000},"resync_buffered":true,"resync_status":"success","resync_watermark_ns":1785126367331000000,"schema_version":"clob-market-ws.price_change.v1","sequence":null,"server_hash":null,"server_timestamp":"1785126360595","session_id":"e9443c7415a0419799bee9cfbb1a9e4d","source":"clob_market_ws"},"received_at":"2026-07-27T04:26:00.538362Z","record_id":"4a6f7fcafc11251b98557f02d6ab9b76fc07877783e82f36fa0016d3acd83266","schema_fingerprint":"a522b3829e2baa1444da15da10771d4b0020c6969989c3325606306f55b0b63e","schema_version":"edge-lab-recorder.raw.v1","sequence":null,"source":"clob_market_ws"}
{"event_at":"2026-07-27T04:26:00.634000Z","event_fingerprint":"0f27b25c7e17ed1320919527db01264bba894ef12a0522f6ae5e84bf64ae765f","payload":{"connection_id":"0f4979d6978d463e9660b042fdcf555f","event_at":"2026-07-27T04:26:00.634000Z","event_type":"price_change","frame_hash":"1615f313feba8c840080d4df2e12c706b8fcf28fe9d3f8449eed303104f19abe","frame_index":0,"kind":"quarantine","monotonic_ns":228343848210000,"payload":{"event_type":"price_change","market":"0xeb66215f2e9faa6449e30a02bab5b8ed7b79a38bf961f6b24d0073c9c2419250","price_changes":[{"asset_id":"69697746896130839564035629862476347944307040470122503199396727085502753297492","best_ask":"0.46","best_bid":"0.45","hash":"2c59e6c58e875e9e2c2b577fbbdb65aa255b25e8","price":"0.11","side":"BUY","size":"66.46"},{"asset_id":"60386828328910021732068595344565885737045900010034836345809386672230885527307","best_ask":"0.55","best_bid":"0.54","hash":"1d3d98efbf2e489a643b9ffd4bdd4462528c85c4","price":"0.89","side":"SELL","size":"66.46"}],"timestamp":"1785126360634"},"payload_hash":"ba78f78f0c5e5fc24cb2a86c9fc8604476ed4c86570caa5dbf1fcf8d02a7e07e","raw_frame":"{\"market\":\"0xeb66215f2e9faa6449e30a02bab5b8ed7b79a38bf961f6b24d0073c9c2419250\", \"price_changes\":[{\"asset_id\":\"69697746896130839564035629862476347944307040470122503199396727085502753297492\", \"price\":\"0.11\", \"size\":\"66.46\", \"side\":\"BUY\", \"hash\":\"2c59e6c58e875e9e2c2b577fbbdb65aa255b25e8\", \"best_bid\":\"0.45\", \"best_ask\":\"0.46\"}, {\"asset_id\":\"60386828328910021732068595344565885737045900010034836345809386672230885527307\", \"price\":\"0.89\", \"size\":\"66.46\", \"side\":\"SELL\", \"hash\":\"1d3d98efbf2e489a643b9ffd4bdd4462528c85c4\", \"best_bid\":\"0.54\", \"best_ask\":\"0.55\"}], \"timestamp\":\"1785126360634\", \"event_type\":\"price_change\"}","received_at":"2026-07-27T04:26:00.576295Z","replay_eligible":false,"resync_asset_ids":["60386828328910021732068595344565885737045900010034836345809386672230885527307","69697746896130839564035629862476347944307040470122503199396727085502753297492"],"resync_asset_watermarks_ns":{"60386828328910021732068595344565885737045900010034836345809386672230885527307":1785126367331000000,"69697746896130839564035629862476347944307040470122503199396727085502753297492":1785126363605000000},"resync_buffered":true,"resync_status":"success","resync_watermark_ns":1785126367331000000,"schema_version":"clob-market-ws.price_change.v1","sequence":null,"server_hash":null,"server_timestamp":"1785126360634","session_id":"e9443c7415a0419799bee9cfbb1a9e4d","source":"clob_market_ws"},"received_at":"2026-07-27T04:26:00.576295Z","record_id":"b4d9c6ad5d0a96679ecdac5bb59f3219f7f88c4a8f08ebf88b0f2a68ca11f6c6","schema_fingerprint":"a522b3829e2baa1444da15da10771d4b0020c6969989c3325606306f55b0b63e","schema_version":"edge-lab-recorder.raw.v1","sequence":null,"source":"clob_market_ws"}
{"event_at":"2026-07-27T04:26:00.679000Z","event_fingerprint":"64f3a5f0ba1c68aa88c5f3e958721eace396fc0ef136522ceddb6ecf00a4b931","payload":{"connection_id":"0f4979d6978d463e9660b042fdcf555f","event_at":"2026-07-27T04:26:00.679000Z","event_type":"price_change","frame_hash":"48b303181e11ef0df4215aaa762bfe433ffc2533ca4ba369df7af2babdb377c3","frame_index":0,"kind":"quarantine","monotonic_ns":228343894398833,"payload":{"event_type":"price_change","market":"0xeb66215f2e9faa6449e30a02bab5b8ed7b79a38bf961f6b24d0073c9c2419250","price_changes":[{"asset_id":"69697746896130839564035629862476347944307040470122503199396727085502753297492","best_ask":"0.46","best_bid":"0.45","hash":"4b476f1a69acd5264c65608909ec2d0a7b537a1e","price":"0.29","side":"BUY","size":"72.25"},{"asset_id":"60386828328910021732068595344565885737045900010034836345809386672230885527307","best_ask":"0.55","best_bid":"0.54","hash":"c220ce174d641a52b386b84c9f91df5a24e9cb5e","price":"0.71","side":"SELL","size":"72.25"}],"timestamp":"1785126360679"},"payload_hash":"69ebccffd1af8af7b11da6f1d403e1a7a648146254d4bc5904b499dd928b2b0e","raw_frame":"{\"market\":\"0xeb66215f2e9faa6449e30a02bab5b8ed7b79a38bf961f6b24d0073c9c2419250\", \"price_changes\":[{\"asset_id\":\"69697746896130839564035629862476347944307040470122503199396727085502753297492\", \"price\":\"0.29\", \"size\":\"72.25\", \"side\":\"BUY\", \"hash\":\"4b476f1a69acd5264c65608909ec2d0a7b537a1e\", \"best_bid\":\"0.45\", \"best_ask\":\"0.46\"}, {\"asset_id\":\"60386828328910021732068595344565885737045900010034836345809386672230885527307\", \"price\":\"0.71\", \"size\":\"72.25\", \"side\":\"SELL\", \"hash\":\"c220ce174d641a52b386b84c9f91df5a24e9cb5e\", \"best_bid\":\"0.54\", \"best_ask\":\"0.55\"}], \"timestamp\":\"1785126360679\", \"event_type\":\"price_change\"}","received_at":"2026-07-27T04:26:00.622482Z","replay_eligible":false,"resync_asset_ids":["60386828328910021732068595344565885737045900010034836345809386672230885527307","69697746896130839564035629862476347944307040470122503199396727085502753297492"],"resync_asset_watermarks_ns":{"60386828328910021732068595344565885737045900010034836345809386672230885527307":1785126367331000000,"69697746896130839564035629862476347944307040470122503199396727085502753297492":1785126363605000000},"resync_buffered":true,"resync_status":"success","resync_watermark_ns":1785126367331000000,"schema_version":"clob-market-ws.price_change.v1","sequence":null,"server_hash":null,"server_timestamp":"1785126360679","session_id":"e9443c7415a0419799bee9cfbb1a9e4d","source":"clob_market_ws"},"received_at":"2026-07-27T04:26:00.622482Z","record_id":"ad85438be9f4468e333cf8f6d88782963b94235701d1c1df4ecc002652553a0f","schema_fingerprint":"a522b3829e2baa1444da15da10771d4b0020c6969989c3325606306f55b0b63e","schema_version":"edge-lab-recorder.raw.v1","sequence":null,"source":"clob_market_ws"}
{"event_at":"2026-07-27T04:26:00.680000Z","event_fingerprint":"fb01615be1d65b205351c625467dc162c105a850d726bf2b98492b3fb7c7aef3","payload":{"connection_id":"0f4979d6978d463e9660b042fdcf555f","event_at":"2026-07-27T04:26:00.680000Z","event_type":"price_change","frame_hash":"f77f4b786bdc3157d16012d804ef2396757b1f220ea843e5ecaa8b9fa256fb21","frame_index":0,"kind":"quarantine","monotonic_ns":228343894426541,"payload":{"event_type":"price_change","market":"0xeb66215f2e9faa6449e30a02bab5b8ed7b79a38bf961f6b24d0073c9c2419250","price_changes":[{"asset_id":"60386828328910021732068595344565885737045900010034836345809386672230885527307","best_ask":"0.55","best_bid":"0.54","hash":"291164cf9196de2177e544d6f6c7a6091cf01500","price":"0.29","side":"BUY","size":"72.25"},{"asset_id":"69697746896130839564035629862476347944307040470122503199396727085502753297492","best_ask":"0.46","best_bid":"0.45","hash":"f88ec275a67bc2541a994fca42dce09714453d26","price":"0.71","side":"SELL","size":"72.25"}],"timestamp":"1785126360680"},"payload_hash":"5890232a9aa872cfb48c7ff713b6357cd47874030e7800d53ac4a876f9b410b0","raw_frame":"{\"market\":\"0xeb66215f2e9faa6449e30a02bab5b8ed7b79a38bf961f6b24d0073c9c2419250\", \"price_changes\":[{\"asset_id\":\"60386828328910021732068595344565885737045900010034836345809386672230885527307\", \"price\":\"0.29\", \"size\":\"72.25\", \"side\":\"BUY\", \"hash\":\"291164cf9196de2177e544d6f6c7a6091cf01500\", \"best_bid\":\"0.54\", \"best_ask\":\"0.55\"}, {\"asset_id\":\"69697746896130839564035629862476347944307040470122503199396727085502753297492\", \"price\":\"0.71\", \"size\":\"72.25\", \"side\":\"SELL\", \"hash\":\"f88ec275a67bc2541a994fca42dce09714453d26\", \"best_bid\":\"0.45\", \"best_ask\":\"0.46\"}], \"timestamp\":\"1785126360680\", \"event_type\":\"price_change\"}","received_at":"2026-07-27T04:26:00.622515Z","replay_eligible":false,"resync_asset_ids":["60386828328910021732068595344565885737045900010034836345809386672230885527307","69697746896130839564035629862476347944307040470122503199396727085502753297492"],"resync_asset_watermarks_ns":{"60386828328910021732068595344565885737045900010034836345809386672230885527307":1785126367331000000,"69697746896130839564035629862476347944307040470122503199396727085502753297492":1785126363605000000},"resync_buffered":true,"resync_status":"success","resync_watermark_ns":1785126367331000000,"schema_version":"clob-market-ws.price_change.v1","sequence":null,"server_hash":null,"server_timestamp":"1785126360680","session_id":"e9443c7415a0419799bee9cfbb1a9e4d","source":"clob_market_ws"},"received_at":"2026-07-27T04:26:00.622515Z","record_id":"b47ee7e1b91c824ca3706c7b08fbbf118831c9f217d60a4f77814a414da20433","schema_fingerprint":"a522b3829e2baa1444da15da10771d4b0020c6969989c3325606306f55b0b63e","schema_version":"edge-lab-recorder.raw.v1","sequence":null,"source":"clob_market_ws"}
{"event_at":"2026-07-27T04:26:00.681000Z","event_fingerprint":"761f7bd35889eb9f2ebb60e9de7e72fb77224cf3ca06e267202b490b7e0105b0","payload":{"connection_id":"0f4979d6978d463e9660b042fdcf555f","event_at":"2026-07-27T04:26:00.681000Z","event_type":"price_change","frame_hash":"d04f5fdbd5e36b68b50f5d540bee37640f22bf58d58875b279a3bc811801a529","frame_index":0,"kind":"quarantine","monotonic_ns":228343896571291,"payload":{"event_type":"price_change","market":"0xeb66215f2e9faa6449e30a02bab5b8ed7b79a38bf961f6b24d0073c9c2419250","price_changes":[{"asset_id":"60386828328910021732068595344565885737045900010034836345809386672230885527307","best_ask":"0.55","best_bid":"0.54","hash":"3a11c14f9b95038b8adb1dd5b81f21987d19df2f","price":"0.38","side":"BUY","size":"319.79"},{"asset_id":"69697746896130839564035629862476347944307040470122503199396727085502753297492","best_ask":"0.46","best_bid":"0.45","hash":"0d41c804c7382bc9fab37b6365985cb812f7fa99","price":"0.62","side":"SELL","size":"319.79"}],"timestamp":"1785126360681"},"payload_hash":"714baab0b192ca76725b0ed50fe33dddfd60a64dcc4d00988cf99b49d4b01e89","raw_frame":"{\"market\":\"0xeb66215f2e9faa6449e30a02bab5b8ed7b79a38bf961f6b24d0073c9c2419250\", \"price_changes\":[{\"asset_id\":\"60386828328910021732068595344565885737045900010034836345809386672230885527307\", \"price\":\"0.38\", \"size\":\"319.79\", \"side\":\"BUY\", \"hash\":\"3a11c14f9b95038b8adb1dd5b81f21987d19df2f\", \"best_bid\":\"0.54\", \"best_ask\":\"0.55\"}, {\"asset_id\":\"69697746896130839564035629862476347944307040470122503199396727085502753297492\", \"price\":\"0.62\", \"size\":\"319.79\", \"side\":\"SELL\", \"hash\":\"0d41c804c7382bc9fab37b6365985cb812f7fa99\", \"best_bid\":\"0.45\", \"best_ask\":\"0.46\"}], \"timestamp\":\"1785126360681\", \"event_type\":\"price_change\"}","received_at":"2026-07-27T04:26:00.624657Z","replay_eligible":false,"resync_asset_ids":["60386828328910021732068595344565885737045900010034836345809386672230885527307","69697746896130839564035629862476347944307040470122503199396727085502753297492"],"resync_asset_watermarks_ns":{"60386828328910021732068595344565885737045900010034836345809386672230885527307":1785126367331000000,"69697746896130839564035629862476347944307040470122503199396727085502753297492":1785126363605000000},"resync_buffered":true,"resync_status":"success","resync_watermark_ns":1785126367331000000,"schema_version":"clob-market-ws.price_change.v1","sequence":null,"server_hash":null,"server_timestamp":"1785126360681","session_id":"e9443c7415a0419799bee9cfbb1a9e4d","source":"clob_market_ws"},"received_at":"2026-07-27T04:26:00.624657Z","record_id":"c5303bd59fdc279acd7b4efd4a6079d157d38e62213129cccf35859566496afb","schema_fingerprint":"a522b3829e2baa1444da15da10771d4b0020c6969989c3325606306f55b0b63e","schema_version":"edge-lab-recorder.raw.v1","sequence":null,"source":"clob_market_ws"}
{"event_at":"2026-07-27T04:26:00.720000Z","event_fingerprint":"db4e9afdc3a3fb144ce70aa14fa268e80376abac7245b893b0cd6ddf315697c4","payload":{"connection_id":"0f4979d6978d463e9660b042fdcf555f","event_at":"2026-07-27T04:26:00.720000Z","event_type":"price_change","frame_hash":"5d85383265c4a543ef3226d5f97244d5e58cdf14d49185a63282d9c6d98887e0","frame_index":0,"kind":"quarantine","monotonic_ns":228343936071125,"payload":{"event_type":"price_change","market":"0xeb66215f2e9faa6449e30a02bab5b8ed7b79a38bf961f6b24d0073c9c2419250","price_changes":[{"asset_id":"69697746896130839564035629862476347944307040470122503199396727085502753297492","best_ask":"0.46","best_bid":"0.45","hash":"a2f400d622ce87c25582588e12108ca4c8629765","price":"0.38","side":"BUY","size":"180.79"},{"asset_id":"60386828328910021732068595344565885737045900010034836345809386672230885527307","best_ask":"0.55","best_bid":"0.54","hash":"3352908f58ec754a0b962c7a19cc3cd6d7dfc541","price":"0.62","side":"SELL","size":"180.79"}],"timestamp":"1785126360720"},"payload_hash":"976d6ef472c2212cfe2d173a8ee00c5ac7aa69b00c47c893d2b7799923ce3e57","raw_frame":"{\"market\":\"0xeb66215f2e9faa6449e30a02bab5b8ed7b79a38bf961f6b24d0073c9c2419250\", \"price_changes\":[{\"asset_id\":\"69697746896130839564035629862476347944307040470122503199396727085502753297492\", \"price\":\"0.38\", \"size\":\"180.79\", \"side\":\"BUY\", \"hash\":\"a2f400d622ce87c25582588e12108ca4c8629765\", \"best_bid\":\"0.45\", \"best_ask\":\"0.46\"}, {\"asset_id\":\"60386828328910021732068595344565885737045900010034836345809386672230885527307\", \"price\":\"0.62\", \"size\":\"180.79\", \"side\":\"SELL\", \"hash\":\"3352908f58ec754a0b962c7a19cc3cd6d7dfc541\", \"best_bid\":\"0.54\", \"best_ask\":\"0.55\"}], \"timestamp\":\"1785126360720\", \"event_type\":\"price_change\"}","received_at":"2026-07-27T04:26:00.664157Z","replay_eligible":false,"resync_asset_ids":["60386828328910021732068595344565885737045900010034836345809386672230885527307","69697746896130839564035629862476347944307040470122503199396727085502753297492"],"resync_asset_watermarks_ns":{"60386828328910021732068595344565885737045900010034836345809386672230885527307":1785126367331000000,"69697746896130839564035629862476347944307040470122503199396727085502753297492":1785126363605000000},"resync_buffered":true,"resync_status":"success","resync_watermark_ns":1785126367331000000,"schema_version":"clob-market-ws.price_change.v1","sequence":null,"server_hash":null,"server_timestamp":"1785126360720","session_id":"e9443c7415a0419799bee9cfbb1a9e4d","source":"clob_market_ws"},"received_at":"2026-07-27T04:26:00.664157Z","record_id":"56b751372d87a74766bcbdfa89dae30db9b2c8f5a89a546afffc790fd155fd85","schema_fingerprint":"a522b3829e2baa1444da15da10771d4b0020c6969989c3325606306f55b0b63e","schema_version":"edge-lab-recorder.raw.v1","sequence":null,"source":"clob_market_ws"}
{"event_at":"2026-07-27T04:26:00.759000Z","event_fingerprint":"e0d21eaeeedf6c03d575d797f3ec2f0ecb8bba2a11aaa41cca3b988068d5a677","payload":{"connection_id":"0f4979d6978d463e9660b042fdcf555f","event_at":"2026-07-27T04:26:00.759000Z","event_type":"price_change","frame_hash":"ce34067d82abc0d3b569326906b6198ecbbf6d97fc43c5204ea292baecaff90b","frame_index":0,"kind":"quarantine","monotonic_ns":228343974498666,"payload":{"event_type":"price_change","market":"0xeb66215f2e9faa6449e30a02bab5b8ed7b79a38bf961f6b24d0073c9c2419250","price_changes":[{"asset_id":"69697746896130839564035629862476347944307040470122503199396727085502753297492","best_ask":"0.46","best_bid":"0.45","hash":"b2de87f3e70b312f9ccc78aa16cbc803410d3ce7","price":"0.17","side":"BUY","size":"60.42"},{"asset_id":"60386828328910021732068595344565885737045900010034836345809386672230885527307","best_ask":"0.55","best_bid":"0.54","hash":"31a05e4702daa40419c648d97162327149cbe3f0","price":"0.83","side":"SELL","size":"60.42"}],"timestamp":"1785126360759"},"payload_hash":"5cb3213a61485264455c7eef84a8178840454d35be7629b4c427af5475503a0a","raw_frame":"{\"market\":\"0xeb66215f2e9faa6449e30a02bab5b8ed7b79a38bf961f6b24d0073c9c2419250\", \"price_changes\":[{\"asset_id\":\"69697746896130839564035629862476347944307040470122503199396727085502753297492\", \"price\":\"0.17\", \"size\":\"60.42\", \"side\":\"BUY\", \"hash\":\"b2de87f3e70b312f9ccc78aa16cbc803410d3ce7\", \"best_bid\":\"0.45\", \"best_ask\":\"0.46\"}, {\"asset_id\":\"60386828328910021732068595344565885737045900010034836345809386672230885527307\", \"price\":\"0.83\", \"size\":\"60.42\", \"side\":\"SELL\", \"hash\":\"31a05e4702daa40419c648d97162327149cbe3f0\", \"best_bid\":\"0.54\", \"best_ask\":\"0.55\"}], \"timestamp\":\"1785126360759\", \"event_type\":\"price_change\"}","received_at":"2026-07-27T04:26:00.702590Z","replay_eligible":false,"resync_asset_ids":["60386828328910021732068595344565885737045900010034836345809386672230885527307","69697746896130839564035629862476347944307040470122503199396727085502753297492"],"resync_asset_watermarks_ns":{"60386828328910021732068595344565885737045900010034836345809386672230885527307":1785126367331000000,"69697746896130839564035629862476347944307040470122503199396727085502753297492":1785126363605000000},"resync_buffered":true,"resync_status":"success","resync_watermark_ns":1785126367331000000,"schema_version":"clob-market-ws.price_change.v1","sequence":null,"server_hash":null,"server_timestamp":"1785126360759","session_id":"e9443c7415a0419799bee9cfbb1a9e4d","source":"clob_market_ws"},"received_at":"2026-07-27T04:26:00.702590Z","record_id":"faec74db02363b219a8100f16792f39f8f6fffb98c6a9f8256958404c960cec3","schema_fingerprint":"a522b3829e2baa1444da15da10771d4b0020c6969989c3325606306f55b0b63e","schema_version":"edge-lab-recorder.raw.v1","sequence":null,"source":"clob_market_ws"}
{"event_at":"2026-07-27T04:26:00.760000Z","event_fingerprint":"c98d51e14e7c4744faec507dd3ce11bef01db030e5a0747566761e14dfb50e2d","payload":{"connection_id":"0f4979d6978d463e9660b042fdcf555f","event_at":"2026-07-27T04:26:00.760000Z","event_type":"price_change","frame_hash":"c357a03bc98837f6cb44eba041c96bb93120a5aa6aba7978800b5a35bd104591","frame_index":0,"kind":"quarantine","monotonic_ns":228343974508791,"payload":{"event_type":"price_change","market":"0xeb66215f2e9faa6449e30a02bab5b8ed7b79a38bf961f6b24d0073c9c2419250","price_changes":[{"asset_id":"60386828328910021732068595344565885737045900010034836345809386672230885527307","best_ask":"0.55","best_bid":"0.54","hash":"da0a62796db05f77cd971790aed67c018f7a2c74","price":"0.17","side":"BUY","size":"60.42"},{"asset_id":"69697746896130839564035629862476347944307040470122503199396727085502753297492","best_ask":"0.46","best_bid":"0.45","hash":"b5ba0bcf976cb327843381cd6230070f3e736cd6","price":"0.83","side":"SELL","size":"60.42"}],"timestamp":"1785126360760"},"payload_hash":"da533969fb9ba5b927b1ecf3b359dbf7a1d09748e676f5f81ee660182fa24d7c","raw_frame":"{\"market\":\"0xeb66215f2e9faa6449e30a02bab5b8ed7b79a38bf961f6b24d0073c9c2419250\", \"price_changes\":[{\"asset_id\":\"60386828328910021732068595344565885737045900010034836345809386672230885527307\", \"price\":\"0.17\", \"size\":\"60.42\", \"side\":\"BUY\", \"hash\":\"da0a62796db05f77cd971790aed67c018f7a2c74\", \"best_bid\":\"0.54\", \"best_ask\":\"0.55\"}, {\"asset_id\":\"69697746896130839564035629862476347944307040470122503199396727085502753297492\", \"price\":\"0.83\", \"size\":\"60.42\", \"side\":\"SELL\", \"hash\":\"b5ba0bcf976cb327843381cd6230070f3e736cd6\", \"best_bid\":\"0.45\", \"best_ask\":\"0.46\"}], \"timestamp\":\"1785126360760\", \"event_type\":\"price_change\"}","received_at":"2026-07-27T04:26:00.702602Z","replay_eligible":false,"resync_asset_ids":["60386828328910021732068595344565885737045900010034836345809386672230885527307","69697746896130839564035629862476347944307040470122503199396727085502753297492"],"resync_asset_watermarks_ns":{"60386828328910021732068595344565885737045900010034836345809386672230885527307":1785126367331000000,"69697746896130839564035629862476347944307040470122503199396727085502753297492":1785126363605000000},"resync_buffered":true,"resync_status":"success","resync_watermark_ns":1785126367331000000,"schema_version":"clob-market-ws.price_change.v1","sequence":null,"server_hash":null,"server_timestamp":"1785126360760","session_id":"e9443c7415a0419799bee9cfbb1a9e4d","source":"clob_market_ws"},"received_at":"2026-07-27T04:26:00.702602Z","record_id":"70f4d34f6a021d09e48221694ea8ad62651c46e8f60b8bfcb0f1b026c6448f7a","schema_fingerprint":"a522b3829e2baa1444da15da10771d4b0020c6969989c3325606306f55b0b63e","schema_version":"edge-lab-recorder.raw.v1","sequence":null,"source":"clob_market_ws"}
{"event_at":"2026-07-27T04:26:00.761000Z","event_fingerprint":"21b2c738c5a80fd1700fd4b2f9de071419efe5e281e1e7667e6a944940a09a55","payload":{"connection_id":"0f4979d6978d463e9660b042fdcf555f","event_at":"2026-07-27T04:26:00.761000Z","event_type":"price_change","frame_hash":"f9a6e6b28384c2d8ddec8a36a255ee64b016bbc583c8aca6fbfbbfa7018fd300","frame_index":0,"kind":"quarantine","monotonic_ns":228343998081375,"payload":{"event_type":"price_change","market":"0xeb66215f2e9faa6449e30a02bab5b8ed7b79a38bf961f6b24d0073c9c2419250","price_changes":[{"asset_id":"60386828328910021732068595344565885737045900010034836345809386672230885527307","best_ask":"0.55","best_bid":"0.54","hash":"3aa2d842303b62b146b6b6f07b188c3604be2335","price":"0.23","side":"BUY","size":"26.74"},{"asset_id":"69697746896130839564035629862476347944307040470122503199396727085502753297492","best_ask":"0.46","best_bid":"0.45","hash":"d6153f789c7791afed6bc5f2cfb272cd484592bc","price":"0.77","side":"SELL","size":"26.74"}],"timestamp":"1785126360761"},"payload_hash":"f3690ac923da68330972dec698a8c1b93e3a722f0c985d1411ab2e8be4b556ef","raw_frame":"{\"market\":\"0xeb66215f2e9faa6449e30a02bab5b8ed7b79a38bf961f6b24d0073c9c2419250\", \"price_changes\":[{\"asset_id\":\"60386828328910021732068595344565885737045900010034836345809386672230885527307\", \"price\":\"0.23\", \"size\":\"26.74\", \"side\":\"BUY\", \"hash\":\"3aa2d842303b62b146b6b6f07b188c3604be2335\", \"best_bid\":\"0.54\", \"best_ask\":\"0.55\"}, {\"asset_id\":\"69697746896130839564035629862476347944307040470122503199396727085502753297492\", \"price\":\"0.77\", \"size\":\"26.74\", \"side\":\"SELL\", \"hash\":\"d6153f789c7791afed6bc5f2cfb272cd484592bc\", \"best_bid\":\"0.45\", \"best_ask\":\"0.46\"}], \"timestamp\":\"1785126360761\", \"event_type\":\"price_change\"}","received_at":"2026-07-27T04:26:00.726172Z","replay_eligible":false,"resync_asset_ids":["60386828328910021732068595344565885737045900010034836345809386672230885527307","69697746896130839564035629862476347944307040470122503199396727085502753297492"],"resync_asset_watermarks_ns":{"60386828328910021732068595344565885737045900010034836345809386672230885527307":1785126367331000000,"69697746896130839564035629862476347944307040470122503199396727085502753297492":1785126363605000000},"resync_buffered":true,"resync_status":"success","resync_watermark_ns":1785126367331000000,"schema_version":"clob-market-ws.price_change.v1","sequence":null,"server_hash":null,"server_timestamp":"1785126360761","session_id":"e9443c7415a0419799bee9cfbb1a9e4d","source":"clob_market_ws"},"received_at":"2026-07-27T04:26:00.726172Z","record_id":"0a4c3c02d5c48cfd4fe894266263932bcc890b51b386a53a7e53010633968ded","schema_fingerprint":"a522b3829e2baa1444da15da10771d4b0020c6969989c3325606306f55b0b63e","schema_version":"edge-lab-recorder.raw.v1","sequence":null,"source":"clob_market_ws"}
{"event_at":"2026-07-27T04:26:00.797000Z","event_fingerprint":"ce79cf99e71c2a61ac1174d868d7143a956d603b0f424abb44a7e70ade29d1dc","payload":{"connection_id":"0f4979d6978d463e9660b042fdcf555f","event_at":"2026-07-27T04:26:00.797000Z","event_type":"price_change","frame_hash":"eba0c1440fdb62addb96025ee8b5047e889685355e736cce7fe702489abffb7b","frame_index":0,"kind":"quarantine","monotonic_ns":228344010977083,"payload":{"event_type":"price_change","market":"0xeb66215f2e9faa6449e30a02bab5b8ed7b79a38bf961f6b24d0073c9c2419250","price_changes":[{"asset_id":"60386828328910021732068595344565885737045900010034836345809386672230885527307","best_ask":"0.55","best_bid":"0.54","hash":"30219a0334871983c68f6334e82fbe7bb5b1ede1","price":"0.06","side":"BUY","size":"754.34"},{"asset_id":"69697746896130839564035629862476347944307040470122503199396727085502753297492","best_ask":"0.46","best_bid":"0.45","hash":"d6855d6671aa5bef8fb5a62531dcd3ee5df61486","price":"0.94","side":"SELL","size":"754.34"}],"timestamp":"1785126360797"},"payload_hash":"d4c2f4dc8ceee74ba9d0672e03573a55cebd6836214f914c9d0821b8d8b1f4fb","raw_frame":"{\"market\":\"0xeb66215f2e9faa6449e30a02bab5b8ed7b79a38bf961f6b24d0073c9c2419250\", \"price_changes\":[{\"asset_id\":\"60386828328910021732068595344565885737045900010034836345809386672230885527307\", \"price\":\"0.06\", \"size\":\"754.34\", \"side\":\"BUY\", \"hash\":\"30219a0334871983c68f6334e82fbe7bb5b1ede1\", \"best_bid\":\"0.54\", \"best_ask\":\"0.55\"}, {\"asset_id\":\"69697746896130839564035629862476347944307040470122503199396727085502753297492\", \"price\":\"0.94\", \"size\":\"754.34\", \"side\":\"SELL\", \"hash\":\"d6855d6671aa5bef8fb5a62531dcd3ee5df61486\", \"best_bid\":\"0.45\", \"best_ask\":\"0.46\"}], \"timestamp\":\"1785126360797\", \"event_type\":\"price_change\"}","received_at":"2026-07-27T04:26:00.739063Z","replay_eligible":false,"resync_asset_ids":["60386828328910021732068595344565885737045900010034836345809386672230885527307","69697746896130839564035629862476347944307040470122503199396727085502753297492"],"resync_asset_watermarks_ns":{"60386828328910021732068595344565885737045900010034836345809386672230885527307":1785126367331000000,"69697746896130839564035629862476347944307040470122503199396727085502753297492":1785126363605000000},"resync_buffered":true,"resync_status":"success","resync_watermark_ns":1785126367331000000,"schema_version":"clob-market-ws.price_change.v1","sequence":null,"server_hash":null,"server_timestamp":"1785126360797","session_id":"e9443c7415a0419799bee9cfbb1a9e4d","source":"clob_market_ws"},"received_at":"2026-07-27T04:26:00.739063Z","record_id":"253456207b4e1a913d14c2adc532a40dd54a0c14a86dae57d13f0ab44bc4d16f","schema_fingerprint":"a522b3829e2baa1444da15da10771d4b0020c6969989c3325606306f55b0b63e","schema_version":"edge-lab-recorder.raw.v1","sequence":null,"source":"clob_market_ws"}
{"event_at":"2026-07-27T04:26:00.811000Z","event_fingerprint":"d6a83c7db49ff5da4ad312f795ff557fc1547f2246b7685e56ac3cddbbde8e9d","payload":{"connection_id":"0f4979d6978d463e9660b042fdcf555f","event_at":"2026-07-27T04:26:00.811000Z","event_type":"price_change","frame_hash":"01695a8cdc35e5eb2a10959081f32cf637bc46afa8841fb2e1fd8f841101ff7e","frame_index":0,"kind":"quarantine","monotonic_ns":228344028042666,"payload":{"event_type":"price_change","market":"0xeb66215f2e9faa6449e30a02bab5b8ed7b79a38bf961f6b24d0073c9c2419250","price_changes":[{"asset_id":"60386828328910021732068595344565885737045900010034836345809386672230885527307","best_ask":"0.55","best_bid":"0.54","hash":"9f1c5dc40dd451165dc3d1bb866dc11860d384fc","price":"0.1","side":"BUY","size":"3194"},{"asset_id":"69697746896130839564035629862476347944307040470122503199396727085502753297492","best_ask":"0.46","best_bid":"0.45","hash":"cba50414987478ecb5f4cf5190bca527b5cb041f","price":"0.9","side":"SELL","size":"3194"}],"timestamp":"1785126360811"},"payload_hash":"4cdfb6af280ec20d780a86f7571da06954b3771d7f2c3886816b430816e6cfe3","raw_frame":"{\"market\":\"0xeb66215f2e9faa6449e30a02bab5b8ed7b79a38bf961f6b24d0073c9c2419250\", \"price_changes\":[{\"asset_id\":\"60386828328910021732068595344565885737045900010034836345809386672230885527307\", \"price\":\"0.1\", \"size\":\"3194\", \"side\":\"BUY\", \"hash\":\"9f1c5dc40dd451165dc3d1bb866dc11860d384fc\", \"best_bid\":\"0.54\", \"best_ask\":\"0.55\"}, {\"asset_id\":\"69697746896130839564035629862476347944307040470122503199396727085502753297492\", \"price\":\"0.9\", \"size\":\"3194\", \"side\":\"SELL\", \"hash\":\"cba50414987478ecb5f4cf5190bca527b5cb041f\", \"best_bid\":\"0.45\", \"best_ask\":\"0.46\"}], \"timestamp\":\"1785126360811\", \"event_type\":\"price_change\"}","received_at":"2026-07-27T04:26:00.756130Z","replay_eligible":false,"resync_asset_ids":["60386828328910021732068595344565885737045900010034836345809386672230885527307","69697746896130839564035629862476347944307040470122503199396727085502753297492"],"resync_asset_watermarks_ns":{"60386828328910021732068595344565885737045900010034836345809386672230885527307":1785126367331000000,"69697746896130839564035629862476347944307040470122503199396727085502753297492":1785126363605000000},"resync_buffered":true,"resync_status":"success","resync_watermark_ns":1785126367331000000,"schema_version":"clob-market-ws.price_change.v1","sequence":null,"server_hash":null,"server_timestamp":"1785126360811","session_id":"e9443c7415a0419799bee9cfbb1a9e4d","source":"clob_market_ws"},"received_at":"2026-07-27T04:26:00.756130Z","record_id":"30e6ed0ff0270ae1e64b1f600e8bdc3f9dc1d8ab88250bb5b6e74a6ca5614391","schema_fingerprint":"a522b3829e2baa1444da15da10771d4b0020c6969989c3325606306f55b0b63e","schema_version":"edge-lab-recorder.raw.v1","sequence":null,"source":"clob_market_ws"}
{"event_at":"2026-07-27T04:26:00.812000Z","event_fingerprint":"afe08869e80342a10332568e4d90e381f99d7bcf2f79083b570b30bb4c0e7224","payload":{"connection_id":"0f4979d6978d463e9660b042fdcf555f","event_at":"2026-07-27T04:26:00.812000Z","event_type":"price_change","frame_hash":"46d9b03fc079e60dac14141814156141b29521364cced63be8536310cd136006","frame_index":0,"kind":"quarantine","monotonic_ns":228344028065916,"payload":{"event_type":"price_change","market":"0xeb66215f2e9faa6449e30a02bab5b8ed7b79a38bf961f6b24d0073c9c2419250","price_changes":[{"asset_id":"69697746896130839564035629862476347944307040470122503199396727085502753297492","best_ask":"0.46","best_bid":"0.45","hash":"d3decfd8a6a8329f7ac82defac0afa2925130aec","price":"0.05","side":"BUY","size":"6799"},{"asset_id":"60386828328910021732068595344565885737045900010034836345809386672230885527307","best_ask":"0.55","best_bid":"0.54","hash":"999eaf5f5f8c881c847d27102361edef0daa89f0","price":"0.95","side":"SELL","size":"6799"}],"timestamp":"1785126360812"},"payload_hash":"67817c5382e6dbfb5a79908d6e83cfbea5e904074544172f45b6c5131d6178b0","raw_frame":"{\"market\":\"0xeb66215f2e9faa6449e30a02bab5b8ed7b79a38bf961f6b24d0073c9c2419250\", \"price_changes\":[{\"asset_id\":\"69697746896130839564035629862476347944307040470122503199396727085502753297492\", \"price\":\"0.05\", \"size\":\"6799\", \"side\":\"BUY\", \"hash\":\"d3decfd8a6a8329f7ac82defac0afa2925130aec\", \"best_bid\":\"0.45\", \"best_ask\":\"0.46\"}, {\"asset_id\":\"60386828328910021732068595344565885737045900010034836345809386672230885527307\", \"price\":\"0.95\", \"size\":\"6799\", \"side\":\"SELL\", \"hash\":\"999eaf5f5f8c881c847d27102361edef0daa89f0\", \"best_bid\":\"0.54\", \"best_ask\":\"0.55\"}], \"timestamp\":\"1785126360812\", \"event_type\":\"price_change\"}","received_at":"2026-07-27T04:26:00.756156Z","replay_eligible":false,"resync_asset_ids":["60386828328910021732068595344565885737045900010034836345809386672230885527307","69697746896130839564035629862476347944307040470122503199396727085502753297492"],"resync_asset_watermarks_ns":{"60386828328910021732068595344565885737045900010034836345809386672230885527307":1785126367331000000,"69697746896130839564035629862476347944307040470122503199396727085502753297492":1785126363605000000},"resync_buffered":true,"resync_status":"success","resync_watermark_ns":1785126367331000000,"schema_version":"clob-market-ws.price_change.v1","sequence":null,"server_hash":null,"server_timestamp":"1785126360812","session_id":"e9443c7415a0419799bee9cfbb1a9e4d","source":"clob_market_ws"},"received_at":"2026-07-27T04:26:00.756156Z","record_id":"9c8d024296afa588799801d430cd1dc56ae88d7b372e5693632bffbeebcbfea6","schema_fingerprint":"a522b3829e2baa1444da15da10771d4b0020c6969989c3325606306f55b0b63e","schema_version":"edge-lab-recorder.raw.v1","sequence":null,"source":"clob_market_ws"}
{"event_at":"2026-07-27T04:26:00.823000Z","event_fingerprint":"5fd20d8f17a83ff9aad3d031c9016bfc04fe2f27c54bc4231ec7dd1fa56fde0e","payload":{"connection_id":"0f4979d6978d463e9660b042fdcf555f","event_at":"2026-07-27T04:26:00.823000Z","event_type":"price_change","frame_hash":"6f2ed58da4fa0a0ec3bca6adc81b857d200fa6e9b3219de5a0aa58cf927e394c","frame_index":0,"kind":"quarantine","monotonic_ns":228344039195750,"payload":{"event_type":"price_change","market":"0xeb66215f2e9faa6449e30a02bab5b8ed7b79a38bf961f6b24d0073c9c2419250","price_changes":[{"asset_id":"69697746896130839564035629862476347944307040470122503199396727085502753297492","best_ask":"0.46","best_bid":"0.45","hash":"1b79e1f6626298308f70d70654e5f3f80444c5df","price":"0.2","side":"BUY","size":"1749"},{"asset_id":"60386828328910021732068595344565885737045900010034836345809386672230885527307","best_ask":"0.55","best_bid":"0.54","hash":"319211c259b984cda25c5c794fa068308d496a70","price":"0.8","side":"SELL","size":"1749"}],"timestamp":"1785126360823"},"payload_hash":"1f4f35de4f8d8e147464acf773879c1b862c93cff4dcd9d36c14ff1af66b8690","raw_frame":"{\"market\":\"0xeb66215f2e9faa6449e30a02bab5b8ed7b79a38bf961f6b24d0073c9c2419250\", \"price_changes\":[{\"asset_id\":\"69697746896130839564035629862476347944307040470122503199396727085502753297492\", \"price\":\"0.2\", \"size\":\"1749\", \"side\":\"BUY\", \"hash\":\"1b79e1f6626298308f70d70654e5f3f80444c5df\", \"best_bid\":\"0.45\", \"best_ask\":\"0.46\"}, {\"asset_id\":\"60386828328910021732068595344565885737045900010034836345809386672230885527307\", \"price\":\"0.8\", \"size\":\"1749\", \"side\":\"SELL\", \"hash\":\"319211c259b984cda25c5c794fa068308d496a70\", \"best_bid\":\"0.54\", \"best_ask\":\"0.55\"}], \"timestamp\":\"1785126360823\", \"event_type\":\"price_change\"}","received_at":"2026-07-27T04:26:00.767280Z","replay_eligible":false,"resync_asset_ids":["60386828328910021732068595344565885737045900010034836345809386672230885527307","69697746896130839564035629862476347944307040470122503199396727085502753297492"],"resync_asset_watermarks_ns":{"60386828328910021732068595344565885737045900010034836345809386672230885527307":1785126367331000000,"69697746896130839564035629862476347944307040470122503199396727085502753297492":1785126363605000000},"resync_buffered":true,"resync_status":"success","resync_watermark_ns":1785126367331000000,"schema_version":"clob-market-ws.price_change.v1","sequence":null,"server_hash":null,"server_timestamp":"1785126360823","session_id":"e9443c7415a0419799bee9cfbb1a9e4d","source":"clob_market_ws"},"received_at":"2026-07-27T04:26:00.767280Z","record_id":"89ea146aaa3b493d581d8b23bad5084ca7654ad8f9f0ae5bacdcaf0a99463ef0","schema_fingerprint":"a522b3829e2baa1444da15da10771d4b0020c6969989c3325606306f55b0b63e","schema_version":"edge-lab-recorder.raw.v1","sequence":null,"source":"clob_market_ws"}
{"event_at":"2026-07-27T04:26:00.832000Z","event_fingerprint":"cef5727f1249200084629fd9b2a5a38487df2cc72529355d273f5d4d24443880","payload":{"connection_id":"0f4979d6978d463e9660b042fdcf555f","event_at":"2026-07-27T04:26:00.832000Z","event_type":"price_change","frame_hash":"57b3753479000ebec3928ce1252f77405133581fac3205f642c3ca3138e8a656","frame_index":0,"kind":"quarantine","monotonic_ns":228344048810708,"payload":{"event_type":"price_change","market":"0xeb66215f2e9faa6449e30a02bab5b8ed7b79a38bf961f6b24d0073c9c2419250","price_changes":[{"asset_id":"69697746896130839564035629862476347944307040470122503199396727085502753297492","best_ask":"0.46","best_bid":"0.45","hash":"90eea611d4345bc94e641e5b44389c7ac6d53f6c","price":"0.1","side":"BUY","size":"3194"},{"asset_id":"60386828328910021732068595344565885737045900010034836345809386672230885527307","best_ask":"0.55","best_bid":"0.54","hash":"b1f5933743064d77a8577bf89dff88ac5ada4940","price":"0.9","side":"SELL","size":"3194"}],"timestamp":"1785126360832"},"payload_hash":"67c6050f3d08a07ef273466864192a8b03420d77b3eb147ec620522e79357a4f","raw_frame":"{\"market\":\"0xeb66215f2e9faa6449e30a02bab5b8ed7b79a38bf961f6b24d0073c9c2419250\", \"price_changes\":[{\"asset_id\":\"69697746896130839564035629862476347944307040470122503199396727085502753297492\", \"price\":\"0.1\", \"size\":\"3194\", \"side\":\"BUY\", \"hash\":\"90eea611d4345bc94e641e5b44389c7ac6d53f6c\", \"best_bid\":\"0.45\", \"best_ask\":\"0.46\"}, {\"asset_id\":\"60386828328910021732068595344565885737045900010034836345809386672230885527307\", \"price\":\"0.9\", \"size\":\"3194\", \"side\":\"SELL\", \"hash\":\"b1f5933743064d77a8577bf89dff88ac5ada4940\", \"best_bid\":\"0.54\", \"best_ask\":\"0.55\"}], \"timestamp\":\"1785126360832\", \"event_type\":\"price_change\"}","received_at":"2026-07-27T04:26:00.776901Z","replay_eligible":false,"resync_asset_ids":["60386828328910021732068595344565885737045900010034836345809386672230885527307","69697746896130839564035629862476347944307040470122503199396727085502753297492"],"resync_asset_watermarks_ns":{"60386828328910021732068595344565885737045900010034836345809386672230885527307":1785126367331000000,"69697746896130839564035629862476347944307040470122503199396727085502753297492":1785126363605000000},"resync_buffered":true,"resync_status":"success","resync_watermark_ns":1785126367331000000,"schema_version":"clob-market-ws.price_change.v1","sequence":null,"server_hash":null,"server_timestamp":"1785126360832","session_id":"e9443c7415a0419799bee9cfbb1a9e4d","source":"clob_market_ws"},"received_at":"2026-07-27T04:26:00.776901Z","record_id":"3a3f9368d8a05bb88fafc9bdfd69d3258b4a37ca214e691ecee3ac652416b1c8","schema_fingerprint":"a522b3829e2baa1444da15da10771d4b0020c6969989c3325606306f55b0b63e","schema_version":"edge-lab-recorder.raw.v1","sequence":null,"source":"clob_market_ws"}
{"event_at":"2026-07-27T04:26:00.893000Z","event_fingerprint":"f12cb6370a68ec5ce5820a3e4102609fb583ed871965fc7d4451f64543b19817","payload":{"connection_id":"0f4979d6978d463e9660b042fdcf555f","event_at":"2026-07-27T04:26:00.893000Z","event_type":"price_change","frame_hash":"1fd122b0a7cf05757e56d492d9882fc0327e2266210903573314e1db254841af","frame_index":0,"kind":"quarantine","monotonic_ns":228344107829166,"payload":{"event_type":"price_change","market":"0xeb66215f2e9faa6449e30a02bab5b8ed7b79a38bf961f6b24d0073c9c2419250","price_changes":[{"asset_id":"69697746896130839564035629862476347944307040470122503199396727085502753297492","best_ask":"0.46","best_bid":"0.45","hash":"46968cf0cdc84e4c3b9bf7703fc67d670370384d","price":"0.24","side":"BUY","size":"818.34"},{"asset_id":"60386828328910021732068595344565885737045900010034836345809386672230885527307","best_ask":"0.55","best_bid":"0.54","hash":"2482eb7ee062d7d174e25ba51e05b3eacb393c4d","price":"0.76","side":"SELL","size":"818.34"}],"timestamp":"1785126360893"},"payload_hash":"eb8465efb7246ae9bf3ffebc92c6c6fb1dc16ad0b881ddf2b102449fc877e9d5","raw_frame":"{\"market\":\"0xeb66215f2e9faa6449e30a02bab5b8ed7b79a38bf961f6b24d0073c9c2419250\", \"price_changes\":[{\"asset_id\":\"69697746896130839564035629862476347944307040470122503199396727085502753297492\", \"price\":\"0.24\", \"size\":\"818.34\", \"side\":\"BUY\", \"hash\":\"46968cf0cdc84e4c3b9bf7703fc67d670370384d\", \"best_bid\":\"0.45\", \"best_ask\":\"0.46\"}, {\"asset_id\":\"60386828328910021732068595344565885737045900010034836345809386672230885527307\", \"price\":\"0.76\", \"size\":\"818.34\", \"side\":\"SELL\", \"hash\":\"2482eb7ee062d7d174e25ba51e05b3eacb393c4d\", \"best_bid\":\"0.54\", \"best_ask\":\"0.55\"}], \"timestamp\":\"1785126360893\", \"event_type\":\"price_change\"}","received_at":"2026-07-27T04:26:00.835919Z","replay_eligible":false,"resync_asset_ids":["60386828328910021732068595344565885737045900010034836345809386672230885527307","69697746896130839564035629862476347944307040470122503199396727085502753297492"],"resync_asset_watermarks_ns":{"60386828328910021732068595344565885737045900010034836345809386672230885527307":1785126367331000000,"69697746896130839564035629862476347944307040470122503199396727085502753297492":1785126363605000000},"resync_buffered":true,"resync_status":"success","resync_watermark_ns":1785126367331000000,"schema_version":"clob-market-ws.price_change.v1","sequence":null,"server_hash":null,"server_timestamp":"1785126360893","session_id":"e9443c7415a0419799bee9cfbb1a9e4d","source":"clob_market_ws"},"received_at":"2026-07-27T04:26:00.835919Z","record_id":"4642ee0b1fc00e7ecd225980c9778455c683b13f8c914b3b1b8ae11b4ecee74b","schema_fingerprint":"a522b3829e2baa1444da15da10771d4b0020c6969989c3325606306f55b0b63e","schema_version":"edge-lab-recorder.raw.v1","sequence":null,"source":"clob_market_ws"}
{"event_at":"2026-07-27T04:26:00.899000Z","event_fingerprint":"4ae591be6bdfd6d35ad39f64288c6e9137e830d4230b373c4932a96431fdba5c","payload":{"connection_id":"0f4979d6978d463e9660b042fdcf555f","event_at":"2026-07-27T04:26:00.899000Z","event_type":"price_change","frame_hash":"a789e9d0074717f0bd49db7dcbeeb60f5d3c557fc894870699989c8c4a7af9bb","frame_index":0,"kind":"quarantine","monotonic_ns":228344112791166,"payload":{"event_type":"price_change","market":"0xeb66215f2e9faa6449e30a02bab5b8ed7b79a38bf961f6b24d0073c9c2419250","price_changes":[{"asset_id":"60386828328910021732068595344565885737045900010034836345809386672230885527307","best_ask":"0.55","best_bid":"0.54","hash":"cabae3989ab6b91f9ff31fc5a44818b7cdc22f83","price":"0.24","side":"BUY","size":"818.34"},{"asset_id":"69697746896130839564035629862476347944307040470122503199396727085502753297492","best_ask":"0.46","best_bid":"0.45","hash":"7b3ff1725e4c218f5df695bbe2eb20abd293616b","price":"0.76","side":"SELL","size":"818.34"}],"timestamp":"1785126360899"},"payload_hash":"f23747286b9b2fb658b15372c6a2066a91183e6a38e9de515226ddfd0f103007","raw_frame":"{\"market\":\"0xeb66215f2e9faa6449e30a02bab5b8ed7b79a38bf961f6b24d0073c9c2419250\", \"price_changes\":[{\"asset_id\":\"60386828328910021732068595344565885737045900010034836345809386672230885527307\", \"price\":\"0.24\", \"size\":\"818.34\", \"side\":\"BUY\", \"hash\":\"cabae3989ab6b91f9ff31fc5a44818b7cdc22f83\", \"best_bid\":\"0.54\", \"best_ask\":\"0.55\"}, {\"asset_id\":\"69697746896130839564035629862476347944307040470122503199396727085502753297492\", \"price\":\"0.76\", \"size\":\"818.34\", \"side\":\"SELL\", \"hash\":\"7b3ff1725e4c218f5df695bbe2eb20abd293616b\", \"best_bid\":\"0.45\", \"best_ask\":\"0.46\"}], \"timestamp\":\"1785126360899\", \"event_type\":\"price_change\"}","received_at":"2026-07-27T04:26:00.840879Z","replay_eligible":false,"resync_asset_ids":["60386828328910021732068595344565885737045900010034836345809386672230885527307","69697746896130839564035629862476347944307040470122503199396727085502753297492"],"resync_asset_watermarks_ns":{"60386828328910021732068595344565885737045900010034836345809386672230885527307":1785126367331000000,"69697746896130839564035629862476347944307040470122503199396727085502753297492":1785126363605000000},"resync_buffered":true,"resync_status":"success","resync_watermark_ns":1785126367331000000,"schema_version":"clob-market-ws.price_change.v1","sequence":null,"server_hash":null,"server_timestamp":"1785126360899","session_id":"e9443c7415a0419799bee9cfbb1a9e4d","source":"clob_market_ws"},"received_at":"2026-07-27T04:26:00.840879Z","record_id":"699f392f4c65bbaf9f70509da034c59ac1b3ae81a58baadb830ebe4981039330","schema_fingerprint":"a522b3829e2baa1444da15da10771d4b0020c6969989c3325606306f55b0b63e","schema_version":"edge-lab-recorder.raw.v1","sequence":null,"source":"clob_market_ws"}
{"event_at":"2026-07-27T04:26:00.900000Z","event_fingerprint":"e5661301677c605c0768e81aefc88a7b20e2ff4ff86da7aa4aff179f78168eb1","payload":{"connection_id":"0f4979d6978d463e9660b042fdcf555f","event_at":"2026-07-27T04:26:00.900000Z","event_type":"price_change","frame_hash":"7e4b794a4fdf91a5bf0176f93846b31160afe1c3be86390a2d581fd004ca5976","frame_index":0,"kind":"quarantine","monotonic_ns":228344115014250,"payload":{"event_type":"price_change","market":"0xeb66215f2e9faa6449e30a02bab5b8ed7b79a38bf961f6b24d0073c9c2419250","price_changes":[{"asset_id":"60386828328910021732068595344565885737045900010034836345809386672230885527307","best_ask":"0.55","best_bid":"0.54","hash":"680a837bdc611e3c76a5428b7f823690b18b1aae","price":"0.32","side":"BUY","size":"585"},{"asset_id":"69697746896130839564035629862476347944307040470122503199396727085502753297492","best_ask":"0.46","best_bid":"0.45","hash":"bf1ee460605f1a1798c1d0b12f03732cd1bce85c","price":"0.68","side":"SELL","size":"585"}],"timestamp":"1785126360900"},"payload_hash":"9bea8159e99a4ddde131acdbda3b2658348838e34b3881631f3613e5d0c90d45","raw_frame":"{\"market\":\"0xeb66215f2e9faa6449e30a02bab5b8ed7b79a38bf961f6b24d0073c9c2419250\", \"price_changes\":[{\"asset_id\":\"60386828328910021732068595344565885737045900010034836345809386672230885527307\", \"price\":\"0.32\", \"size\":\"585\", \"side\":\"BUY\", \"hash\":\"680a837bdc611e3c76a5428b7f823690b18b1aae\", \"best_bid\":\"0.54\", \"best_ask\":\"0.55\"}, {\"asset_id\":\"69697746896130839564035629862476347944307040470122503199396727085502753297492\", \"price\":\"0.68\", \"size\":\"585\", \"side\":\"SELL\", \"hash\":\"bf1ee460605f1a1798c1d0b12f03732cd1bce85c\", \"best_bid\":\"0.45\", \"best_ask\":\"0.46\"}], \"timestamp\":\"1785126360900\", \"event_type\":\"price_change\"}","received_at":"2026-07-27T04:26:00.843100Z","replay_eligible":false,"resync_asset_ids":["60386828328910021732068595344565885737045900010034836345809386672230885527307","69697746896130839564035629862476347944307040470122503199396727085502753297492"],"resync_asset_watermarks_ns":{"60386828328910021732068595344565885737045900010034836345809386672230885527307":1785126367331000000,"69697746896130839564035629862476347944307040470122503199396727085502753297492":1785126363605000000},"resync_buffered":true,"resync_status":"success","resync_watermark_ns":1785126367331000000,"schema_version":"clob-market-ws.price_change.v1","sequence":null,"server_hash":null,"server_timestamp":"1785126360900","session_id":"e9443c7415a0419799bee9cfbb1a9e4d","source":"clob_market_ws"},"received_at":"2026-07-27T04:26:00.843100Z","record_id":"656e360d582a6768c273272edf5441e97448af7e91417e25ab08be166c611ccd","schema_fingerprint":"a522b3829e2baa1444da15da10771d4b0020c6969989c3325606306f55b0b63e","schema_version":"edge-lab-recorder.raw.v1","sequence":null,"source":"clob_market_ws"}
{"event_at":"2026-07-27T04:26:00.915000Z","event_fingerprint":"3dcfc3b0e6423b3238d4bf4030f331c53d9c80580237915a08e57cbfcb64edcc","payload":{"connection_id":"0f4979d6978d463e9660b042fdcf555f","event_at":"2026-07-27T04:26:00.915000Z","event_type":"price_change","frame_hash":"8bb16d1a5475323f3b2fda2ec82d297d966b0ea46f42d9f3fb7628266989b38f","frame_index":0,"kind":"quarantine","monotonic_ns":228344135420458,"payload":{"event_type":"price_change","market":"0xeb66215f2e9faa6449e30a02bab5b8ed7b79a38bf961f6b24d0073c9c2419250","price_changes":[{"asset_id":"69697746896130839564035629862476347944307040470122503199396727085502753297492","best_ask":"0.46","best_bid":"0.45","hash":"5bf7319698b48968ef8e56711d8daa17a10e541d","price":"0.32","side":"BUY","size":"730"},{"asset_id":"60386828328910021732068595344565885737045900010034836345809386672230885527307","best_ask":"0.55","best_bid":"0.54","hash":"5339fd9c0fb4d35c1096c21170dab9a018ca326f","price":"0.68","side":"SELL","size":"730"}],"timestamp":"1785126360915"},"payload_hash":"5cc62e134e37188ae60b5341457be33f847dda2294122bc75844faa2bb49174c","raw_frame":"{\"market\":\"0xeb66215f2e9faa6449e30a02bab5b8ed7b79a38bf961f6b24d0073c9c2419250\", \"price_changes\":[{\"asset_id\":\"69697746896130839564035629862476347944307040470122503199396727085502753297492\", \"price\":\"0.32\", \"size\":\"730\", \"side\":\"BUY\", \"hash\":\"5bf7319698b48968ef8e56711d8daa17a10e541d\", \"best_bid\":\"0.45\", \"best_ask\":\"0.46\"}, {\"asset_id\":\"60386828328910021732068595344565885737045900010034836345809386672230885527307\", \"price\":\"0.68\", \"size\":\"730\", \"side\":\"SELL\", \"hash\":\"5339fd9c0fb4d35c1096c21170dab9a018ca326f\", \"best_bid\":\"0.54\", \"best_ask\":\"0.55\"}], \"timestamp\":\"1785126360915\", \"event_type\":\"price_change\"}","received_at":"2026-07-27T04:26:00.863511Z","replay_eligible":false,"resync_asset_ids":["60386828328910021732068595344565885737045900010034836345809386672230885527307","69697746896130839564035629862476347944307040470122503199396727085502753297492"],"resync_asset_watermarks_ns":{"60386828328910021732068595344565885737045900010034836345809386672230885527307":1785126367331000000,"69697746896130839564035629862476347944307040470122503199396727085502753297492":1785126363605000000},"resync_buffered":true,"resync_status":"success","resync_watermark_ns":1785126367331000000,"schema_version":"clob-market-ws.price_change.v1","sequence":null,"server_hash":null,"server_timestamp":"1785126360915","session_id":"e9443c7415a0419799bee9cfbb1a9e4d","source":"clob_market_ws"},"received_at":"2026-07-27T04:26:00.863511Z","record_id":"a775894c1ef68f9f4b2fc31a652afa4bf31e492355389e11c3e698aa8dd8840f","schema_fingerprint":"a522b3829e2baa1444da15da10771d4b0020c6969989c3325606306f55b0b63e","schema_version":"edge-lab-recorder.raw.v1","sequence":null,"source":"clob_market_ws"}
{"event_at":null,"event_fingerprint":"8c1f3dfc18d0e1d938055c35b3dd14764fb16c9d10ac65750c58e849df243a6b","payload":{"connection_id":"0f4979d6978d463e9660b042fdcf555f","detail":{"interval_seconds":10.0,"message":"PING"},"event_type":"heartbeat","kind":"lifecycle","monotonic_ns":228352377237291,"received_at":"2026-07-27T04:26:09.105393Z","schema_version":"edge-lab-recorder.lifecycle.v1","session_id":"e9443c7415a0419799bee9cfbb1a9e4d","source":"clob_market_ws"},"received_at":"2026-07-27T04:26:09.105393Z","record_id":"86da94df67c634c00d404a8d592effa3780b8bac27686f30dc5d46309fa965de","schema_fingerprint":"cb8aa3aa4cb168a4b724fd9077bee6ecfb9bc586c57cfdf0ab89f00d82045e3c","schema_version":"edge-lab-recorder.raw.v1","sequence":null,"source":"clob_market_ws"}
{"event_at":"2026-07-27T04:26:00.971000Z","event_fingerprint":"df2294d67c2432ce84cdde9b2131c0e37120003b8c29e4909e087f2d0ad80b7f","payload":{"connection_id":"0f4979d6978d463e9660b042fdcf555f","event_at":"2026-07-27T04:26:00.971000Z","event_type":"price_change","frame_hash":"739593d773b94a67eb3cb5c9343cb48c15102a43307097a8d3af7f026f8daefe","frame_index":0,"kind":"quarantine","monotonic_ns":228344186723666,"payload":{"event_type":"price_change","market":"0xeb66215f2e9faa6449e30a02bab5b8ed7b79a38bf961f6b24d0073c9c2419250","price_changes":[{"asset_id":"60386828328910021732068595344565885737045900010034836345809386672230885527307","best_ask":"0.55","best_bid":"0.54","hash":"bf37a43fe4d75512b7dc923db7cf47c5f022e02d","price":"0.15","side":"BUY","size":"2231.34"},{"asset_id":"69697746896130839564035629862476347944307040470122503199396727085502753297492","best_ask":"0.46","best_bid":"0.45","hash":"4947a56c9b19f811bf695d6b8f6852904e1de5f5","price":"0.85","side":"SELL","size":"2231.34"}],"timestamp":"1785126360971"},"payload_hash":"90a26bc1c7dd5cf269102ad131717b73f9f14eca2386955feef55f3176bd1a5f","raw_frame":"{\"market\":\"0xeb66215f2e9faa6449e30a02bab5b8ed7b79a38bf961f6b24d0073c9c2419250\", \"price_changes\":[{\"asset_id\":\"60386828328910021732068595344565885737045900010034836345809386672230885527307\", \"price\":\"0.15\", \"size\":\"2231.34\", \"side\":\"BUY\", \"hash\":\"bf37a43fe4d75512b7dc923db7cf47c5f022e02d\", \"best_bid\":\"0.54\", \"best_ask\":\"0.55\"}, {\"asset_id\":\"69697746896130839564035629862476347944307040470122503199396727085502753297492\", \"price\":\"0.85\", \"size\":\"2231.34\", \"side\":\"SELL\", \"hash\":\"4947a56c9b19f811bf695d6b8f6852904e1de5f5\", \"best_bid\":\"0.45\", \"best_ask\":\"0.46\"}], \"timestamp\":\"1785126360971\", \"event_type\":\"price_change\"}","received_at":"2026-07-27T04:26:00.914810Z","replay_eligible":false,"resync_asset_ids":["60386828328910021732068595344565885737045900010034836345809386672230885527307","69697746896130839564035629862476347944307040470122503199396727085502753297492"],"resync_asset_watermarks_ns":{"60386828328910021732068595344565885737045900010034836345809386672230885527307":1785126367331000000,"69697746896130839564035629862476347944307040470122503199396727085502753297492":1785126363605000000},"resync_buffered":true,"resync_status":"success","resync_watermark_ns":1785126367331000000,"schema_version":"clob-market-ws.price_change.v1","sequence":null,"server_hash":null,"server_timestamp":"1785126360971","session_id":"e9443c7415a0419799bee9cfbb1a9e4d","source":"clob_market_ws"},"received_at":"2026-07-27T04:26:00.914810Z","record_id":"9110c07024b7e58e2d68dac3f65d745c78688c3bbd5ac0848091795038563fe1","schema_fingerprint":"a522b3829e2baa1444da15da10771d4b0020c6969989c3325606306f55b0b63e","schema_version":"edge-lab-recorder.raw.v1","sequence":null,"source":"clob_market_ws"}
{"event_at":"2026-07-27T04:26:00.973000Z","event_fingerprint":"acf760df4c6c8a37e0e4cbccd6cb667006375439c67d24279892db707627039f","payload":{"connection_id":"0f4979d6978d463e9660b042fdcf555f","event_at":"2026-07-27T04:26:00.973000Z","event_type":"price_change","frame_hash":"1ae5513bab5b2d348f03136611cf86a8c668b04a54068cb629c3af023d245429","frame_index":0,"kind":"quarantine","monotonic_ns":228344186750000,"payload":{"event_type":"price_change","market":"0xeb66215f2e9faa6449e30a02bab5b8ed7b79a38bf961f6b24d0073c9c2419250","price_changes":[{"asset_id":"69697746896130839564035629862476347944307040470122503199396727085502753297492","best_ask":"0.46","best_bid":"0.45","hash":"0ac4c22a333db62e2f07067d471cbb881cf5df02","price":"0.15","side":"BUY","size":"2231.34"},{"asset_id":"60386828328910021732068595344565885737045900010034836345809386672230885527307","best_ask":"0.55","best_bid":"0.54","hash":"a5545d43b0643a46993825ce7587230410008642","price":"0.85","side":"SELL","size":"2231.34"}],"timestamp":"1785126360973"},"payload_hash":"ab9010632bc72f762e6f606d376276318c554efa948808cc8a58e0c907f6f2bd","raw_frame":"{\"market\":\"0xeb66215f2e9faa6449e30a02bab5b8ed7b79a38bf961f6b24d0073c9c2419250\", \"price_changes\":[{\"asset_id\":\"69697746896130839564035629862476347944307040470122503199396727085502753297492\", \"price\":\"0.15\", \"size\":\"2231.34\", \"side\":\"BUY\", \"hash\":\"0ac4c22a333db62e2f07067d471cbb881cf5df02\", \"best_bid\":\"0.45\", \"best_ask\":\"0.46\"}, {\"asset_id\":\"60386828328910021732068595344565885737045900010034836345809386672230885527307\", \"price\":\"0.85\", \"size\":\"2231.34\", \"side\":\"SELL\", \"hash\":\"a5545d43b0643a46993825ce7587230410008642\", \"best_bid\":\"0.54\", \"best_ask\":\"0.55\"}], \"timestamp\":\"1785126360973\", \"event_type\":\"price_change\"}","received_at":"2026-07-27T04:26:00.914841Z","replay_eligible":false,"resync_asset_ids":["60386828328910021732068595344565885737045900010034836345809386672230885527307","69697746896130839564035629862476347944307040470122503199396727085502753297492"],"resync_asset_watermarks_ns":{"60386828328910021732068595344565885737045900010034836345809386672230885527307":1785126367331000000,"69697746896130839564035629862476347944307040470122503199396727085502753297492":1785126363605000000},"resync_buffered":true,"resync_status":"success","resync_watermark_ns":1785126367331000000,"schema_version":"clob-market-ws.price_change.v1","sequence":null,"server_hash":null,"server_timestamp":"1785126360973","session_id":"e9443c7415a0419799bee9cfbb1a9e4d","source":"clob_market_ws"},"received_at":"2026-07-27T04:26:00.914841Z","record_id":"e53820d485b7415834f9d7563aae4ea8509984c22341e5a4eac29c9d903fe70a","schema_fingerprint":"a522b3829e2baa1444da15da10771d4b0020c6969989c3325606306f55b0b63e","schema_version":"edge-lab-recorder.raw.v1","sequence":null,"source":"clob_market_ws"}
{"event_at":"2026-07-27T04:26:00.979000Z","event_fingerprint":"63482d3f0768aea80adff297e3526b7336db50d9bce392ea803b0b4f0d0baebb","payload":{"connection_id":"0f4979d6978d463e9660b042fdcf555f","event_at":"2026-07-27T04:26:00.979000Z","event_type":"price_change","frame_hash":"fbdfe91159c2659b5b17722aa2302ed5df6c700f7221bbde3025d050cf9f9fbc","frame_index":0,"kind":"quarantine","monotonic_ns":228344194301000,"payload":{"event_type":"price_change","market":"0xeb66215f2e9faa6449e30a02bab5b8ed7b79a38bf961f6b24d0073c9c2419250","price_changes":[{"asset_id":"60386828328910021732068595344565885737045900010034836345809386672230885527307","best_ask":"0.55","best_bid":"0.54","hash":"e4245e7a5969be01696007fc82dda12efab825ca","price":"0.2","side":"BUY","size":"1749"},{"asset_id":"69697746896130839564035629862476347944307040470122503199396727085502753297492","best_ask":"0.46","best_bid":"0.45","hash":"0664bcaeab9e6a83f66a66822f6d5fa426085a1d","price":"0.8","side":"SELL","size":"1749"}],"timestamp":"1785126360979"},"payload_hash":"ce686f361e61957d45af720af3ef599530875f1027ad2fc730efc2c1cff92b91","raw_frame":"{\"market\":\"0xeb66215f2e9faa6449e30a02bab5b8ed7b79a38bf961f6b24d0073c9c2419250\", \"price_changes\":[{\"asset_id\":\"60386828328910021732068595344565885737045900010034836345809386672230885527307\", \"price\":\"0.2\", \"size\":\"1749\", \"side\":\"BUY\", \"hash\":\"e4245e7a5969be01696007fc82dda12efab825ca\", \"best_bid\":\"0.54\", \"best_ask\":\"0.55\"}, {\"asset_id\":\"69697746896130839564035629862476347944307040470122503199396727085502753297492\", \"price\":\"0.8\", \"size\":\"1749\", \"side\":\"SELL\", \"hash\":\"0664bcaeab9e6a83f66a66822f6d5fa426085a1d\", \"best_bid\":\"0.45\", \"best_ask\":\"0.46\"}], \"timestamp\":\"1785126360979\", \"event_type\":\"price_change\"}","received_at":"2026-07-27T04:26:00.922390Z","replay_eligible":false,"resync_asset_ids":["60386828328910021732068595344565885737045900010034836345809386672230885527307","69697746896130839564035629862476347944307040470122503199396727085502753297492"],"resync_asset_watermarks_ns":{"60386828328910021732068595344565885737045900010034836345809386672230885527307":1785126367331000000,"69697746896130839564035629862476347944307040470122503199396727085502753297492":1785126363605000000},"resync_buffered":true,"resync_status":"success","resync_watermark_ns":1785126367331000000,"schema_version":"clob-market-ws.price_change.v1","sequence":null,"server_hash":null,"server_timestamp":"1785126360979","session_id":"e9443c7415a0419799bee9cfbb1a9e4d","source":"clob_market_ws"},"received_at":"2026-07-27T04:26:00.922390Z","record_id":"b96412d941a2124dd1a94a49a043d9c67c41483d34154bc65fbf029167562dca","schema_fingerprint":"a522b3829e2baa1444da15da10771d4b0020c6969989c3325606306f55b0b63e","schema_version":"edge-lab-recorder.raw.v1","sequence":null,"source":"clob_market_ws"}
{"event_at":"2026-07-27T04:26:00.983000Z","event_fingerprint":"213fa2ad9563eeb946887bcc2054bb03c9797eb93083e602d693ac83583041dd","payload":{"connection_id":"0f4979d6978d463e9660b042fdcf555f","event_at":"2026-07-27T04:26:00.983000Z","event_type":"price_change","frame_hash":"bc274deca25f5a6787706a19210e3f5ccc14dd5b44e64d306dba572c9a3df809","frame_index":0,"kind":"quarantine","monotonic_ns":228344197655083,"payload":{"event_type":"price_change","market":"0xeb66215f2e9faa6449e30a02bab5b8ed7b79a38bf961f6b24d0073c9c2419250","price_changes":[{"asset_id":"60386828328910021732068595344565885737045900010034836345809386672230885527307","best_ask":"0.55","best_bid":"0.54","hash":"38b565d789458fed1f9d5f28bc18f689782c9698","price":"0.05","side":"BUY","size":"6799"},{"asset_id":"69697746896130839564035629862476347944307040470122503199396727085502753297492","best_ask":"0.46","best_bid":"0.45","hash":"b960971885c5fcf27265694db1ad2a64a00c645a","price":"0.95","side":"SELL","size":"6799"}],"timestamp":"1785126360983"},"payload_hash":"9f46402e4ce9dce77cbabc0ce7d5c726d57dfac48c4000ebb9c4e524f0edcedd","raw_frame":"{\"market\":\"0xeb66215f2e9faa6449e30a02bab5b8ed7b79a38bf961f6b24d0073c9c2419250\", \"price_changes\":[{\"asset_id\":\"60386828328910021732068595344565885737045900010034836345809386672230885527307\", \"price\":\"0.05\", \"size\":\"6799\", \"side\":\"BUY\", \"hash\":\"38b565d789458fed1f9d5f28bc18f689782c9698\", \"best_bid\":\"0.54\", \"best_ask\":\"0.55\"}, {\"asset_id\":\"69697746896130839564035629862476347944307040470122503199396727085502753297492\", \"price\":\"0.95\", \"size\":\"6799\", \"side\":\"SELL\", \"hash\":\"b960971885c5fcf27265694db1ad2a64a00c645a\", \"best_bid\":\"0.45\", \"best_ask\":\"0.46\"}], \"timestamp\":\"1785126360983\", \"event_type\":\"price_change\"}","received_at":"2026-07-27T04:26:00.925739Z","replay_eligible":false,"resync_asset_ids":["60386828328910021732068595344565885737045900010034836345809386672230885527307","69697746896130839564035629862476347944307040470122503199396727085502753297492"],"resync_asset_watermarks_ns":{"60386828328910021732068595344565885737045900010034836345809386672230885527307":1785126367331000000,"69697746896130839564035629862476347944307040470122503199396727085502753297492":1785126363605000000},"resync_buffered":true,"resync_status":"success","resync_watermark_ns":1785126367331000000,"schema_version":"clob-market-ws.price_change.v1","sequence":null,"server_hash":null,"server_timestamp":"1785126360983","session_id":"e9443c7415a0419799bee9cfbb1a9e4d","source":"clob_market_ws"},"received_at":"2026-07-27T04:26:00.925739Z","record_id":"77c592289a7edc24ba2fca00a12a80f195dbf6dd3b0142c309dd192f748cca65","schema_fingerprint":"a522b3829e2baa1444da15da10771d4b0020c6969989c3325606306f55b0b63e","schema_version":"edge-lab-recorder.raw.v1","sequence":null,"source":"clob_market_ws"}
{"event_at":"2026-07-27T04:26:01.204000Z","event_fingerprint":"8a3b3f4752e4cf65a36b087fa2e90c4479d58801a1429d3cd804493395a5f4b9","payload":{"connection_id":"0f4979d6978d463e9660b042fdcf555f","event_at":"2026-07-27T04:26:01.204000Z","event_type":"price_change","frame_hash":"b924de193ca9f794794645b5bb59e327c54d6774e4726aaf563ac61d33ffad1e","frame_index":0,"kind":"quarantine","monotonic_ns":228344418398125,"payload":{"event_type":"price_change","market":"0xeb66215f2e9faa6449e30a02bab5b8ed7b79a38bf961f6b24d0073c9c2419250","price_changes":[{"asset_id":"60386828328910021732068595344565885737045900010034836345809386672230885527307","best_ask":"0.55","best_bid":"0.54","hash":"91ada577c3210257dc8c62c60ba5985fb66459bf","price":"0.12","side":"BUY","size":"61.67"},{"asset_id":"69697746896130839564035629862476347944307040470122503199396727085502753297492","best_ask":"0.46","best_bid":"0.45","hash":"d36d777657e0ceb218be99d48862d29288b87989","price":"0.88","side":"SELL","size":"61.67"}],"timestamp":"1785126361204"},"payload_hash":"23e03fd51926c8d320015e33ed730caaf0f0af0cbe76b53927d9a27c6c8006df","raw_frame":"{\"market\":\"0xeb66215f2e9faa6449e30a02bab5b8ed7b79a38bf961f6b24d0073c9c2419250\", \"price_changes\":[{\"asset_id\":\"60386828328910021732068595344565885737045900010034836345809386672230885527307\", \"price\":\"0.12\", \"size\":\"61.67\", \"side\":\"BUY\", \"hash\":\"91ada577c3210257dc8c62c60ba5985fb66459bf\", \"best_bid\":\"0.54\", \"best_ask\":\"0.55\"}, {\"asset_id\":\"69697746896130839564035629862476347944307040470122503199396727085502753297492\", \"price\":\"0.88\", \"size\":\"61.67\", \"side\":\"SELL\", \"hash\":\"d36d777657e0ceb218be99d48862d29288b87989\", \"best_bid\":\"0.45\", \"best_ask\":\"0.46\"}], \"timestamp\":\"1785126361204\", \"event_type\":\"price_change\"}","received_at":"2026-07-27T04:26:01.146490Z","replay_eligible":false,"resync_asset_ids":["60386828328910021732068595344565885737045900010034836345809386672230885527307","69697746896130839564035629862476347944307040470122503199396727085502753297492"],"resync_asset_watermarks_ns":{"60386828328910021732068595344565885737045900010034836345809386672230885527307":1785126367331000000,"69697746896130839564035629862476347944307040470122503199396727085502753297492":1785126363605000000},"resync_buffered":true,"resync_status":"success","resync_watermark_ns":1785126367331000000,"schema_version":"clob-market-ws.price_change.v1","sequence":null,"server_hash":null,"server_timestamp":"1785126361204","session_id":"e9443c7415a0419799bee9cfbb1a9e4d","source":"clob_market_ws"},"received_at":"2026-07-27T04:26:01.146490Z","record_id":"afdb44bfed6de06ef6bb3e7be0a66550ecd0d5a209eaea90c25e919a4f991a63","schema_fingerprint":"a522b3829e2baa1444da15da10771d4b0020c6969989c3325606306f55b0b63e","schema_version":"edge-lab-recorder.raw.v1","sequence":null,"source":"clob_market_ws"}
{"event_at":"2026-07-27T04:26:01.205000Z","event_fingerprint":"f1442553f8705b059526a6d98ebad286f09f2de69c35e05176197f79765583dd","payload":{"connection_id":"0f4979d6978d463e9660b042fdcf555f","event_at":"2026-07-27T04:26:01.205000Z","event_type":"price_change","frame_hash":"8379e59e7d53115451472b52848a9d3353b04afb7294e7d03348cd845a403e57","frame_index":0,"kind":"quarantine","monotonic_ns":228344418424125,"payload":{"event_type":"price_change","market":"0xeb66215f2e9faa6449e30a02bab5b8ed7b79a38bf961f6b24d0073c9c2419250","price_changes":[{"asset_id":"69697746896130839564035629862476347944307040470122503199396727085502753297492","best_ask":"0.46","best_bid":"0.45","hash":"58f15b30bf0d0c021923c4de048505bb3efb2bca","price":"0.06","side":"BUY","size":"837.68"},{"asset_id":"60386828328910021732068595344565885737045900010034836345809386672230885527307","best_ask":"0.55","best_bid":"0.54","hash":"84e8176fc6553f8d7754a9440284d8640f6a00eb","price":"0.94","side":"SELL","size":"837.68"}],"timestamp":"1785126361205"},"payload_hash":"0920eb9b8fd7765a4db1e5b27898f6c1d3ef9c3d56730c9240b5edba6b4456ca","raw_frame":"{\"market\":\"0xeb66215f2e9faa6449e30a02bab5b8ed7b79a38bf961f6b24d0073c9c2419250\", \"price_changes\":[{\"asset_id\":\"69697746896130839564035629862476347944307040470122503199396727085502753297492\", \"price\":\"0.06\", \"size\":\"837.68\", \"side\":\"BUY\", \"hash\":\"58f15b30bf0d0c021923c4de048505bb3efb2bca\", \"best_bid\":\"0.45\", \"best_ask\":\"0.46\"}, {\"asset_id\":\"60386828328910021732068595344565885737045900010034836345809386672230885527307\", \"price\":\"0.94\", \"size\":\"837.68\", \"side\":\"SELL\", \"hash\":\"84e8176fc6553f8d7754a9440284d8640f6a00eb\", \"best_bid\":\"0.54\", \"best_ask\":\"0.55\"}], \"timestamp\":\"1785126361205\", \"event_type\":\"price_change\"}","received_at":"2026-07-27T04:26:01.146517Z","replay_eligible":false,"resync_asset_ids":["60386828328910021732068595344565885737045900010034836345809386672230885527307","69697746896130839564035629862476347944307040470122503199396727085502753297492"],"resync_asset_watermarks_ns":{"60386828328910021732068595344565885737045900010034836345809386672230885527307":1785126367331000000,"69697746896130839564035629862476347944307040470122503199396727085502753297492":1785126363605000000},"resync_buffered":true,"resync_status":"success","resync_watermark_ns":1785126367331000000,"schema_version":"clob-market-ws.price_change.v1","sequence":null,"server_hash":null,"server_timestamp":"1785126361205","session_id":"e9443c7415a0419799bee9cfbb1a9e4d","source":"clob_market_ws"},"received_at":"2026-07-27T04:26:01.146517Z","record_id":"20c05f217b0362d72d67244835e17c9016fb504b79db60ea2f3a81608653ab13","schema_fingerprint":"a522b3829e2baa1444da15da10771d4b0020c6969989c3325606306f55b0b63e","schema_version":"edge-lab-recorder.raw.v1","sequence":null,"source":"clob_market_ws"}
{"event_at":"2026-07-27T04:26:01.206000Z","event_fingerprint":"76afb07adbe1e93bc546c66b8343d01655086bb3c35d68e3b009ea62bd2c655d","payload":{"connection_id":"0f4979d6978d463e9660b042fdcf555f","event_at":"2026-07-27T04:26:01.206000Z","event_type":"price_change","frame_hash":"eded7fd48d68bf0489d20cdd7f285de1001fd2c6e6bae6d5c671f125acdff8f3","frame_index":0,"kind":"quarantine","monotonic_ns":228344420465666,"payload":{"event_type":"price_change","market":"0xeb66215f2e9faa6449e30a02bab5b8ed7b79a38bf961f6b24d0073c9c2419250","price_changes":[{"asset_id":"69697746896130839564035629862476347944307040470122503199396727085502753297492","best_ask":"0.46","best_bid":"0.45","hash":"ed9fd9d9ba6a5d9afb3fa1da62909669196e6fc2","price":"0.24","side":"BUY","size":"839.18"},{"asset_id":"60386828328910021732068595344565885737045900010034836345809386672230885527307","best_ask":"0.55","best_bid":"0.54","hash":"68e4e105bb41e2cb7ddf1c209538c0c41a055087","price":"0.76","side":"SELL","size":"839.18"}],"timestamp":"1785126361206"},"payload_hash":"98cfd000d1350094d4af2ffc4284f0943bbdeb802bb8f5f049605574ca11885b","raw_frame":"{\"market\":\"0xeb66215f2e9faa6449e30a02bab5b8ed7b79a38bf961f6b24d0073c9c2419250\", \"price_changes\":[{\"asset_id\":\"69697746896130839564035629862476347944307040470122503199396727085502753297492\", \"price\":\"0.24\", \"size\":\"839.18\", \"side\":\"BUY\", \"hash\":\"ed9fd9d9ba6a5d9afb3fa1da62909669196e6fc2\", \"best_bid\":\"0.45\", \"best_ask\":\"0.46\"}, {\"asset_id\":\"60386828328910021732068595344565885737045900010034836345809386672230885527307\", \"price\":\"0.76\", \"size\":\"839.18\", \"side\":\"SELL\", \"hash\":\"68e4e105bb41e2cb7ddf1c209538c0c41a055087\", \"best_bid\":\"0.54\", \"best_ask\":\"0.55\"}], \"timestamp\":\"1785126361206\", \"event_type\":\"price_change\"}","received_at":"2026-07-27T04:26:01.148554Z","replay_eligible":false,"resync_asset_ids":["60386828328910021732068595344565885737045900010034836345809386672230885527307","69697746896130839564035629862476347944307040470122503199396727085502753297492"],"resync_asset_watermarks_ns":{"60386828328910021732068595344565885737045900010034836345809386672230885527307":1785126367331000000,"69697746896130839564035629862476347944307040470122503199396727085502753297492":1785126363605000000},"resync_buffered":true,"resync_status":"success","resync_watermark_ns":1785126367331000000,"schema_version":"clob-market-ws.price_change.v1","sequence":null,"server_hash":null,"server_timestamp":"1785126361206","session_id":"e9443c7415a0419799bee9cfbb1a9e4d","source":"clob_market_ws"},"received_at":"2026-07-27T04:26:01.148554Z","record_id":"f94192e7ce4fe4ed321afa4e51bef43c6ce03d381ea3bb8c086ad35ed53e11d6","schema_fingerprint":"a522b3829e2baa1444da15da10771d4b0020c6969989c3325606306f55b0b63e","schema_version":"edge-lab-recorder.raw.v1","sequence":null,"source":"clob_market_ws"}
{"event_at":"2026-07-27T04:26:01.277000Z","event_fingerprint":"b4c6226b2cdec6d11b8a6a7422ba034aae0c4a101387950fef769608ba24e405","payload":{"connection_id":"0f4979d6978d463e9660b042fdcf555f","event_at":"2026-07-27T04:26:01.277000Z","event_type":"price_change","frame_hash":"b489d4678cfa2a2ea433856884773e34418dfd4dc40bcc4e77b2ec005d1def99","frame_index":0,"kind":"quarantine","monotonic_ns":228344492543000,"payload":{"event_type":"price_change","market":"0xeb66215f2e9faa6449e30a02bab5b8ed7b79a38bf961f6b24d0073c9c2419250","price_changes":[{"asset_id":"69697746896130839564035629862476347944307040470122503199396727085502753297492","best_ask":"0.46","best_bid":"0.45","hash":"9ea91097555edbf527b53d44f05f035d48627cbb","price":"0.12","side":"BUY","size":"61.67"},{"asset_id":"60386828328910021732068595344565885737045900010034836345809386672230885527307","best_ask":"0.55","best_bid":"0.54","hash":"e1a2d780b44d3f47b01ea2dffef964405f4c49f7","price":"0.88","side":"SELL","size":"61.67"}],"timestamp":"1785126361277"},"payload_hash":"c5779a43e553c15da8bfcd55e9a7d3e1ba805a50db0d4d9be7496c699b53ea8f","raw_frame":"{\"market\":\"0xeb66215f2e9faa6449e30a02bab5b8ed7b79a38bf961f6b24d0073c9c2419250\", \"price_changes\":[{\"asset_id\":\"69697746896130839564035629862476347944307040470122503199396727085502753297492\", \"price\":\"0.12\", \"size\":\"61.67\", \"side\":\"BUY\", \"hash\":\"9ea91097555edbf527b53d44f05f035d48627cbb\", \"best_bid\":\"0.45\", \"best_ask\":\"0.46\"}, {\"asset_id\":\"60386828328910021732068595344565885737045900010034836345809386672230885527307\", \"price\":\"0.88\", \"size\":\"61.67\", \"side\":\"SELL\", \"hash\":\"e1a2d780b44d3f47b01ea2dffef964405f4c49f7\", \"best_bid\":\"0.54\", \"best_ask\":\"0.55\"}], \"timestamp\":\"1785126361277\", \"event_type\":\"price_change\"}","received_at":"2026-07-27T04:26:01.220635Z","replay_eligible":false,"resync_asset_ids":["60386828328910021732068595344565885737045900010034836345809386672230885527307","69697746896130839564035629862476347944307040470122503199396727085502753297492"],"resync_asset_watermarks_ns":{"60386828328910021732068595344565885737045900010034836345809386672230885527307":1785126367331000000,"69697746896130839564035629862476347944307040470122503199396727085502753297492":1785126363605000000},"resync_buffered":true,"resync_status":"success","resync_watermark_ns":1785126367331000000,"schema_version":"clob-market-ws.price_change.v1","sequence":null,"server_hash":null,"server_timestamp":"1785126361277","session_id":"e9443c7415a0419799bee9cfbb1a9e4d","source":"clob_market_ws"},"received_at":"2026-07-27T04:26:01.220635Z","record_id":"841f26b9fde0df73c7fc6912241f7d9652c7ae098108d0d348903a6e6b0fd138","schema_fingerprint":"a522b3829e2baa1444da15da10771d4b0020c6969989c3325606306f55b0b63e","schema_version":"edge-lab-recorder.raw.v1","sequence":null,"source":"clob_market_ws"}
{"event_at":"2026-07-27T04:26:01.364000Z","event_fingerprint":"1508926215786098ae2aa968b9b2e83ec1d6a133b18755f115dbe483678be73c","payload":{"connection_id":"0f4979d6978d463e9660b042fdcf555f","event_at":"2026-07-27T04:26:01.364000Z","event_type":"price_change","frame_hash":"e60d8ddc00402b09ca6b0455f19f566a8dfa0a6ce4e1135deb9c24214f48513f","frame_index":0,"kind":"quarantine","monotonic_ns":228344579409416,"payload":{"event_type":"price_change","market":"0xeb66215f2e9faa6449e30a02bab5b8ed7b79a38bf961f6b24d0073c9c2419250","price_changes":[{"asset_id":"60386828328910021732068595344565885737045900010034836345809386672230885527307","best_ask":"0.55","best_bid":"0.54","hash":"c3447193ada4d864e369bba0ca1962839de2a879","price":"0.31","side":"BUY","size":"21.13"},{"asset_id":"69697746896130839564035629862476347944307040470122503199396727085502753297492","best_ask":"0.46","best_bid":"0.45","hash":"6766e74ae1183d83cb69ba06527c059a45434c62","price":"0.69","side":"SELL","size":"21.13"}],"timestamp":"1785126361364"},"payload_hash":"58eee542799511ef0a0db36f513bf77374947ac8429fac12f55f7118face9832","raw_frame":"{\"market\":\"0xeb66215f2e9faa6449e30a02bab5b8ed7b79a38bf961f6b24d0073c9c2419250\", \"price_changes\":[{\"asset_id\":\"60386828328910021732068595344565885737045900010034836345809386672230885527307\", \"price\":\"0.31\", \"size\":\"21.13\", \"side\":\"BUY\", \"hash\":\"c3447193ada4d864e369bba0ca1962839de2a879\", \"best_bid\":\"0.54\", \"best_ask\":\"0.55\"}, {\"asset_id\":\"69697746896130839564035629862476347944307040470122503199396727085502753297492\", \"price\":\"0.69\", \"size\":\"21.13\", \"side\":\"SELL\", \"hash\":\"6766e74ae1183d83cb69ba06527c059a45434c62\", \"best_bid\":\"0.45\", \"best_ask\":\"0.46\"}], \"timestamp\":\"1785126361364\", \"event_type\":\"price_change\"}","received_at":"2026-07-27T04:26:01.307507Z","replay_eligible":false,"resync_asset_ids":["60386828328910021732068595344565885737045900010034836345809386672230885527307","69697746896130839564035629862476347944307040470122503199396727085502753297492"],"resync_asset_watermarks_ns":{"60386828328910021732068595344565885737045900010034836345809386672230885527307":1785126367331000000,"69697746896130839564035629862476347944307040470122503199396727085502753297492":1785126363605000000},"resync_buffered":true,"resync_status":"success","resync_watermark_ns":1785126367331000000,"schema_version":"clob-market-ws.price_change.v1","sequence":null,"server_hash":null,"server_timestamp":"1785126361364","session_id":"e9443c7415a0419799bee9cfbb1a9e4d","source":"clob_market_ws"},"received_at":"2026-07-27T04:26:01.307507Z","record_id":"2873fba09e2437a94accc7a599c80c5eaacd9062bdfaa7aa7b8190963daea60d","schema_fingerprint":"a522b3829e2baa1444da15da10771d4b0020c6969989c3325606306f55b0b63e","schema_version":"edge-lab-recorder.raw.v1","sequence":null,"source":"clob_market_ws"}
{"event_at":"2026-07-27T04:26:01.364000Z","event_fingerprint":"e7eb1e83a648d2a33a1161b137570c7b5e3b7ae2ff94fda73969b79eb4fee069","payload":{"connection_id":"0f4979d6978d463e9660b042fdcf555f","event_at":"2026-07-27T04:26:01.364000Z","event_type":"price_change","frame_hash":"37bd64d4b73aec50c7f2687f79addfd5072d42371c6e790b1ad2af1a2ba9469f","frame_index":0,"kind":"quarantine","monotonic_ns":228344580350333,"payload":{"event_type":"price_change","market":"0xeb66215f2e9faa6449e30a02bab5b8ed7b79a38bf961f6b24d0073c9c2419250","price_changes":[{"asset_id":"69697746896130839564035629862476347944307040470122503199396727085502753297492","best_ask":"0.46","best_bid":"0.45","hash":"28613483f38e1b516d25393ec4446450f3234be4","price":"0.31","side":"BUY","size":"21.13"},{"asset_id":"60386828328910021732068595344565885737045900010034836345809386672230885527307","best_ask":"0.55","best_bid":"0.54","hash":"e0eaadce3107c30501da02cc1b775b7cba6fbcf5","price":"0.69","side":"SELL","size":"21.13"}],"timestamp":"1785126361364"},"payload_hash":"44ab2cd57e17a552bb49b57b828b042d2bca3639c1c72ec5aaf0c3b756a677c9","raw_frame":"{\"market\":\"0xeb66215f2e9faa6449e30a02bab5b8ed7b79a38bf961f6b24d0073c9c2419250\", \"price_changes\":[{\"asset_id\":\"69697746896130839564035629862476347944307040470122503199396727085502753297492\", \"price\":\"0.31\", \"size\":\"21.13\", \"side\":\"BUY\", \"hash\":\"28613483f38e1b516d25393ec4446450f3234be4\", \"best_bid\":\"0.45\", \"best_ask\":\"0.46\"}, {\"asset_id\":\"60386828328910021732068595344565885737045900010034836345809386672230885527307\", \"price\":\"0.69\", \"size\":\"21.13\", \"side\":\"SELL\", \"hash\":\"e0eaadce3107c30501da02cc1b775b7cba6fbcf5\", \"best_bid\":\"0.54\", \"best_ask\":\"0.55\"}], \"timestamp\":\"1785126361364\", \"event_type\":\"price_change\"}","received_at":"2026-07-27T04:26:01.308447Z","replay_eligible":false,"resync_asset_ids":["60386828328910021732068595344565885737045900010034836345809386672230885527307","69697746896130839564035629862476347944307040470122503199396727085502753297492"],"resync_asset_watermarks_ns":{"60386828328910021732068595344565885737045900010034836345809386672230885527307":1785126367331000000,"69697746896130839564035629862476347944307040470122503199396727085502753297492":1785126363605000000},"resync_buffered":true,"resync_status":"success","resync_watermark_ns":1785126367331000000,"schema_version":"clob-market-ws.price_change.v1","sequence":null,"server_hash":null,"server_timestamp":"1785126361364","session_id":"e9443c7415a0419799bee9cfbb1a9e4d","source":"clob_market_ws"},"received_at":"2026-07-27T04:26:01.308447Z","record_id":"ed65a314c973b7409232053e12b43dd8cdda0fd3fe0cf66db9d079eba4f01fee","schema_fingerprint":"a522b3829e2baa1444da15da10771d4b0020c6969989c3325606306f55b0b63e","schema_version":"edge-lab-recorder.raw.v1","sequence":null,"source":"clob_market_ws"}
{"event_at":"2026-07-27T04:26:01.365000Z","event_fingerprint":"e60733508d9f207e119bfb68b12acde5ddd2823eae4c9c8b3644ab16a1968031","payload":{"connection_id":"0f4979d6978d463e9660b042fdcf555f","event_at":"2026-07-27T04:26:01.365000Z","event_type":"price_change","frame_hash":"bdcab4e9296764fc148a74ccf771509e7189f5b77c43e295ce49ed5997a00d95","frame_index":0,"kind":"quarantine","monotonic_ns":228344580360208,"payload":{"event_type":"price_change","market":"0xeb66215f2e9faa6449e30a02bab5b8ed7b79a38bf961f6b24d0073c9c2419250","price_changes":[{"asset_id":"60386828328910021732068595344565885737045900010034836345809386672230885527307","best_ask":"0.55","best_bid":"0.54","hash":"2d6a5e8009b930848224cee23891b2a8234807ea","price":"0.41","side":"BUY","size":"59.2"},{"asset_id":"69697746896130839564035629862476347944307040470122503199396727085502753297492","best_ask":"0.46","best_bid":"0.45","hash":"33cee6fdde57e6d4a4268aa56c9eda4bb9a92f0f","price":"0.59","side":"SELL","size":"59.2"}],"timestamp":"1785126361365"},"payload_hash":"cfc1926668a6a1ac50c470f99e7a92bb49f84a3c3282eff4233147c4e8374212","raw_frame":"{\"market\":\"0xeb66215f2e9faa6449e30a02bab5b8ed7b79a38bf961f6b24d0073c9c2419250\", \"price_changes\":[{\"asset_id\":\"60386828328910021732068595344565885737045900010034836345809386672230885527307\", \"price\":\"0.41\", \"size\":\"59.2\", \"side\":\"BUY\", \"hash\":\"2d6a5e8009b930848224cee23891b2a8234807ea\", \"best_bid\":\"0.54\", \"best_ask\":\"0.55\"}, {\"asset_id\":\"69697746896130839564035629862476347944307040470122503199396727085502753297492\", \"price\":\"0.59\", \"size\":\"59.2\", \"side\":\"SELL\", \"hash\":\"33cee6fdde57e6d4a4268aa56c9eda4bb9a92f0f\", \"best_bid\":\"0.45\", \"best_ask\":\"0.46\"}], \"timestamp\":\"1785126361365\", \"event_type\":\"price_change\"}","received_at":"2026-07-27T04:26:01.308458Z","replay_eligible":false,"resync_asset_ids":["60386828328910021732068595344565885737045900010034836345809386672230885527307","69697746896130839564035629862476347944307040470122503199396727085502753297492"],"resync_asset_watermarks_ns":{"60386828328910021732068595344565885737045900010034836345809386672230885527307":1785126367331000000,"69697746896130839564035629862476347944307040470122503199396727085502753297492":1785126363605000000},"resync_buffered":true,"resync_status":"success","resync_watermark_ns":1785126367331000000,"schema_version":"clob-market-ws.price_change.v1","sequence":null,"server_hash":null,"server_timestamp":"1785126361365","session_id":"e9443c7415a0419799bee9cfbb1a9e4d","source":"clob_market_ws"},"received_at":"2026-07-27T04:26:01.308458Z","record_id":"a16125cc0a8784cdfaf813d7fabaca5be33c82f19a3ae0843167862eb1b9523e","schema_fingerprint":"a522b3829e2baa1444da15da10771d4b0020c6969989c3325606306f55b0b63e","schema_version":"edge-lab-recorder.raw.v1","sequence":null,"source":"clob_market_ws"}
{"event_at":"2026-07-27T04:26:01.441000Z","event_fingerprint":"c7bacdb1cdb8ff3aa0a9068d950e1c4dceeb6aa498bb9f2684eb8118dd5e3c4e","payload":{"connection_id":"0f4979d6978d463e9660b042fdcf555f","event_at":"2026-07-27T04:26:01.441000Z","event_type":"price_change","frame_hash":"ae1a26c30913c5d6f5d40f0e98a463d3695458518d62a5c9eeb2f63b2587ca54","frame_index":0,"kind":"quarantine","monotonic_ns":228344656079791,"payload":{"event_type":"price_change","market":"0xeb66215f2e9faa6449e30a02bab5b8ed7b79a38bf961f6b24d0073c9c2419250","price_changes":[{"asset_id":"69697746896130839564035629862476347944307040470122503199396727085502753297492","best_ask":"0.46","best_bid":"0.45","hash":"21d6bded009991d114c4026c3bc4611748c74f70","price":"0.41","side":"BUY","size":"168.2"},{"asset_id":"60386828328910021732068595344565885737045900010034836345809386672230885527307","best_ask":"0.55","best_bid":"0.54","hash":"b7802bb6a6ba01b9c39f89616fe431b10d146847","price":"0.59","side":"SELL","size":"168.2"}],"timestamp":"1785126361441"},"payload_hash":"64bf45c02d91956f8c0a862908b9c1fa79a18236856b78e61edd7892c2199c91","raw_frame":"{\"market\":\"0xeb66215f2e9faa6449e30a02bab5b8ed7b79a38bf961f6b24d0073c9c2419250\", \"price_changes\":[{\"asset_id\":\"69697746896130839564035629862476347944307040470122503199396727085502753297492\", \"price\":\"0.41\", \"size\":\"168.2\", \"side\":\"BUY\", \"hash\":\"21d6bded009991d114c4026c3bc4611748c74f70\", \"best_bid\":\"0.45\", \"best_ask\":\"0.46\"}, {\"asset_id\":\"60386828328910021732068595344565885737045900010034836345809386672230885527307\", \"price\":\"0.59\", \"size\":\"168.2\", \"side\":\"SELL\", \"hash\":\"b7802bb6a6ba01b9c39f89616fe431b10d146847\", \"best_bid\":\"0.54\", \"best_ask\":\"0.55\"}], \"timestamp\":\"1785126361441\", \"event_type\":\"price_change\"}","received_at":"2026-07-27T04:26:01.384167Z","replay_eligible":false,"resync_asset_ids":["60386828328910021732068595344565885737045900010034836345809386672230885527307","69697746896130839564035629862476347944307040470122503199396727085502753297492"],"resync_asset_watermarks_ns":{"60386828328910021732068595344565885737045900010034836345809386672230885527307":1785126367331000000,"69697746896130839564035629862476347944307040470122503199396727085502753297492":1785126363605000000},"resync_buffered":true,"resync_status":"success","resync_watermark_ns":1785126367331000000,"schema_version":"clob-market-ws.price_change.v1","sequence":null,"server_hash":null,"server_timestamp":"1785126361441","session_id":"e9443c7415a0419799bee9cfbb1a9e4d","source":"clob_market_ws"},"received_at":"2026-07-27T04:26:01.384167Z","record_id":"2d64445c179a73e29390d91525932bdbab420e0a41d43714724ecb299bb8b612","schema_fingerprint":"a522b3829e2baa1444da15da10771d4b0020c6969989c3325606306f55b0b63e","schema_version":"edge-lab-recorder.raw.v1","sequence":null,"source":"clob_market_ws"}
{"event_at":"2026-07-27T04:26:01.514000Z","event_fingerprint":"f9ee3a29f8156ebc447a48043360cb511f88519df3833cde2008d6f27bd94553","payload":{"connection_id":"0f4979d6978d463e9660b042fdcf555f","event_at":"2026-07-27T04:26:01.514000Z","event_type":"price_change","frame_hash":"2b61ac0c8fbf5268832d3817be1589a49b61be62b3ecc2a4149d337275f7c580","frame_index":0,"kind":"quarantine","monotonic_ns":228344729430750,"payload":{"event_type":"price_change","market":"0xeb66215f2e9faa6449e30a02bab5b8ed7b79a38bf961f6b24d0073c9c2419250","price_changes":[{"asset_id":"69697746896130839564035629862476347944307040470122503199396727085502753297492","best_ask":"0.46","best_bid":"0.45","hash":"cc29fe099e5a9fb62acbb557783680bb65321549","price":"0.18","side":"BUY","size":"37.78"},{"asset_id":"60386828328910021732068595344565885737045900010034836345809386672230885527307","best_ask":"0.55","best_bid":"0.54","hash":"808f8dc4c3491b1d40c7b1a9ecbde9833976756e","price":"0.82","side":"SELL","size":"37.78"}],"timestamp":"1785126361514"},"payload_hash":"04865de46211f6599357c3285d0e6f74b3cfb86f28ccde5d31b8b51bf455f96c","raw_frame":"{\"market\":\"0xeb66215f2e9faa6449e30a02bab5b8ed7b79a38bf961f6b24d0073c9c2419250\", \"price_changes\":[{\"asset_id\":\"69697746896130839564035629862476347944307040470122503199396727085502753297492\", \"price\":\"0.18\", \"size\":\"37.78\", \"side\":\"BUY\", \"hash\":\"cc29fe099e5a9fb62acbb557783680bb65321549\", \"best_bid\":\"0.45\", \"best_ask\":\"0.46\"}, {\"asset_id\":\"60386828328910021732068595344565885737045900010034836345809386672230885527307\", \"price\":\"0.82\", \"size\":\"37.78\", \"side\":\"SELL\", \"hash\":\"808f8dc4c3491b1d40c7b1a9ecbde9833976756e\", \"best_bid\":\"0.54\", \"best_ask\":\"0.55\"}], \"timestamp\":\"1785126361514\", \"event_type\":\"price_change\"}","received_at":"2026-07-27T04:26:01.457522Z","replay_eligible":false,"resync_asset_ids":["60386828328910021732068595344565885737045900010034836345809386672230885527307","69697746896130839564035629862476347944307040470122503199396727085502753297492"],"resync_asset_watermarks_ns":{"60386828328910021732068595344565885737045900010034836345809386672230885527307":1785126367331000000,"69697746896130839564035629862476347944307040470122503199396727085502753297492":1785126363605000000},"resync_buffered":true,"resync_status":"success","resync_watermark_ns":1785126367331000000,"schema_version":"clob-market-ws.price_change.v1","sequence":null,"server_hash":null,"server_timestamp":"1785126361514","session_id":"e9443c7415a0419799bee9cfbb1a9e4d","source":"clob_market_ws"},"received_at":"2026-07-27T04:26:01.457522Z","record_id":"8b55df173f93b74205a520afc54e8c6d7f00556741a5666f850c31f94db156ae","schema_fingerprint":"a522b3829e2baa1444da15da10771d4b0020c6969989c3325606306f55b0b63e","schema_version":"edge-lab-recorder.raw.v1","sequence":null,"source":"clob_market_ws"}
{"event_at":"2026-07-27T04:26:01.515000Z","event_fingerprint":"4dde0d46154ec8d36f14d8c284183cb0a041893e21fcfeb32ff7db60010fea78","payload":{"connection_id":"0f4979d6978d463e9660b042fdcf555f","event_at":"2026-07-27T04:26:01.515000Z","event_type":"price_change","frame_hash":"352102beacc34d0ea497321cc176e7016244f2802384ff025efe8736986be13d","frame_index":0,"kind":"quarantine","monotonic_ns":228344729458416,"payload":{"event_type":"price_change","market":"0xeb66215f2e9faa6449e30a02bab5b8ed7b79a38bf961f6b24d0073c9c2419250","price_changes":[{"asset_id":"60386828328910021732068595344565885737045900010034836345809386672230885527307","best_ask":"0.55","best_bid":"0.54","hash":"b30c61362959c0d49bf5f9eb0a375ba2fb2d91c2","price":"0.18","side":"BUY","size":"37.78"},{"asset_id":"69697746896130839564035629862476347944307040470122503199396727085502753297492","best_ask":"0.46","best_bid":"0.45","hash":"e2460e9749d492f968f9fe437e06fdd321c5cb25","price":"0.82","side":"SELL","size":"37.78"}],"timestamp":"1785126361515"},"payload_hash":"1bba9226dde54faa52253f1c9d47df8c8e6d97ecd567a7af92fc22abe727ef57","raw_frame":"{\"market\":\"0xeb66215f2e9faa6449e30a02bab5b8ed7b79a38bf961f6b24d0073c9c2419250\", \"price_changes\":[{\"asset_id\":\"60386828328910021732068595344565885737045900010034836345809386672230885527307\", \"price\":\"0.18\", \"size\":\"37.78\", \"side\":\"BUY\", \"hash\":\"b30c61362959c0d49bf5f9eb0a375ba2fb2d91c2\", \"best_bid\":\"0.54\", \"best_ask\":\"0.55\"}, {\"asset_id\":\"69697746896130839564035629862476347944307040470122503199396727085502753297492\", \"price\":\"0.82\", \"size\":\"37.78\", \"side\":\"SELL\", \"hash\":\"e2460e9749d492f968f9fe437e06fdd321c5cb25\", \"best_bid\":\"0.45\", \"best_ask\":\"0.46\"}], \"timestamp\":\"1785126361515\", \"event_type\":\"price_change\"}","received_at":"2026-07-27T04:26:01.457554Z","replay_eligible":false,"resync_asset_ids":["60386828328910021732068595344565885737045900010034836345809386672230885527307","69697746896130839564035629862476347944307040470122503199396727085502753297492"],"resync_asset_watermarks_ns":{"60386828328910021732068595344565885737045900010034836345809386672230885527307":1785126367331000000,"69697746896130839564035629862476347944307040470122503199396727085502753297492":1785126363605000000},"resync_buffered":true,"resync_status":"success","resync_watermark_ns":1785126367331000000,"schema_version":"clob-market-ws.price_change.v1","sequence":null,"server_hash":null,"server_timestamp":"1785126361515","session_id":"e9443c7415a0419799bee9cfbb1a9e4d","source":"clob_market_ws"},"received_at":"2026-07-27T04:26:01.457554Z","record_id":"e30f54f139e733882aa0808aa82a3941279461a2baa5abebf09fcb3aac8b7341","schema_fingerprint":"a522b3829e2baa1444da15da10771d4b0020c6969989c3325606306f55b0b63e","schema_version":"edge-lab-recorder.raw.v1","sequence":null,"source":"clob_market_ws"}
{"event_at":"2026-07-27T04:26:01.588000Z","event_fingerprint":"bbfd83f04517324da771a36e957ca067f9833512314b6c5281a21389d4e25fdc","payload":{"connection_id":"0f4979d6978d463e9660b042fdcf555f","event_at":"2026-07-27T04:26:01.588000Z","event_type":"price_change","frame_hash":"8547a291ec32f6d2ab4cc79a315af437abf0b069b16b7e91554c615584e6e002","frame_index":0,"kind":"quarantine","monotonic_ns":228344802215791,"payload":{"event_type":"price_change","market":"0xeb66215f2e9faa6449e30a02bab5b8ed7b79a38bf961f6b24d0073c9c2419250","price_changes":[{"asset_id":"60386828328910021732068595344565885737045900010034836345809386672230885527307","best_ask":"0.55","best_bid":"0.54","hash":"5247b45391372a995f7c8c3be052f9cd481006d8","price":"0.06","side":"BUY","size":"837.68"},{"asset_id":"69697746896130839564035629862476347944307040470122503199396727085502753297492","best_ask":"0.46","best_bid":"0.45","hash":"9d7feb2dc493d692dbc00bc3212932497192f303","price":"0.94","side":"SELL","size":"837.68"}],"timestamp":"1785126361588"},"payload_hash":"e1b1ea378d806428a43ee5565cbe03abf7c615d14e3677833753d0a537e364f6","raw_frame":"{\"market\":\"0xeb66215f2e9faa6449e30a02bab5b8ed7b79a38bf961f6b24d0073c9c2419250\", \"price_changes\":[{\"asset_id\":\"60386828328910021732068595344565885737045900010034836345809386672230885527307\", \"price\":\"0.06\", \"size\":\"837.68\", \"side\":\"BUY\", \"hash\":\"5247b45391372a995f7c8c3be052f9cd481006d8\", \"best_bid\":\"0.54\", \"best_ask\":\"0.55\"}, {\"asset_id\":\"69697746896130839564035629862476347944307040470122503199396727085502753297492\", \"price\":\"0.94\", \"size\":\"837.68\", \"side\":\"SELL\", \"hash\":\"9d7feb2dc493d692dbc00bc3212932497192f303\", \"best_bid\":\"0.45\", \"best_ask\":\"0.46\"}], \"timestamp\":\"1785126361588\", \"event_type\":\"price_change\"}","received_at":"2026-07-27T04:26:01.530310Z","replay_eligible":false,"resync_asset_ids":["60386828328910021732068595344565885737045900010034836345809386672230885527307","69697746896130839564035629862476347944307040470122503199396727085502753297492"],"resync_asset_watermarks_ns":{"60386828328910021732068595344565885737045900010034836345809386672230885527307":1785126367331000000,"69697746896130839564035629862476347944307040470122503199396727085502753297492":1785126363605000000},"resync_buffered":true,"resync_status":"success","resync_watermark_ns":1785126367331000000,"schema_version":"clob-market-ws.price_change.v1","sequence":null,"server_hash":null,"server_timestamp":"1785126361588","session_id":"e9443c7415a0419799bee9cfbb1a9e4d","source":"clob_market_ws"},"received_at":"2026-07-27T04:26:01.530310Z","record_id":"18102fcb3003b0099281e775b37c7d2cbf3736744394a9ddc84dd9e134e317fc","schema_fingerprint":"a522b3829e2baa1444da15da10771d4b0020c6969989c3325606306f55b0b63e","schema_version":"edge-lab-recorder.raw.v1","sequence":null,"source":"clob_market_ws"}
{"event_at":"2026-07-27T04:26:01.589000Z","event_fingerprint":"53ebda35ed01116c4bde7717d4b23ba1741ca0d2b436613acd7e5cd70b4ca964","payload":{"connection_id":"0f4979d6978d463e9660b042fdcf555f","event_at":"2026-07-27T04:26:01.589000Z","event_type":"price_change","frame_hash":"c58006d8ad5e40d315fed172caf9260a95d324a93e677b42880059dd0f49666f","frame_index":0,"kind":"quarantine","monotonic_ns":228344804463916,"payload":{"event_type":"price_change","market":"0xeb66215f2e9faa6449e30a02bab5b8ed7b79a38bf961f6b24d0073c9c2419250","price_changes":[{"asset_id":"60386828328910021732068595344565885737045900010034836345809386672230885527307","best_ask":"0.55","best_bid":"0.54","hash":"8fb2b951d16a3c95af07010f70c650ee1a645b8a","price":"0.24","side":"BUY","size":"839.18"},{"asset_id":"69697746896130839564035629862476347944307040470122503199396727085502753297492","best_ask":"0.46","best_bid":"0.45","hash":"cd9c6b2b48486b46a61cb415339ac34e725b5a7e","price":"0.76","side":"SELL","size":"839.18"}],"timestamp":"1785126361589"},"payload_hash":"4f720173326f6fc1552dbe15bfc736c14815a150fabc7fac206d8f886f097b9e","raw_frame":"{\"market\":\"0xeb66215f2e9faa6449e30a02bab5b8ed7b79a38bf961f6b24d0073c9c2419250\", \"price_changes\":[{\"asset_id\":\"60386828328910021732068595344565885737045900010034836345809386672230885527307\", \"price\":\"0.24\", \"size\":\"839.18\", \"side\":\"BUY\", \"hash\":\"8fb2b951d16a3c95af07010f70c650ee1a645b8a\", \"best_bid\":\"0.54\", \"best_ask\":\"0.55\"}, {\"asset_id\":\"69697746896130839564035629862476347944307040470122503199396727085502753297492\", \"price\":\"0.76\", \"size\":\"839.18\", \"side\":\"SELL\", \"hash\":\"cd9c6b2b48486b46a61cb415339ac34e725b5a7e\", \"best_bid\":\"0.45\", \"best_ask\":\"0.46\"}], \"timestamp\":\"1785126361589\", \"event_type\":\"price_change\"}","received_at":"2026-07-27T04:26:01.532560Z","replay_eligible":false,"resync_asset_ids":["60386828328910021732068595344565885737045900010034836345809386672230885527307","69697746896130839564035629862476347944307040470122503199396727085502753297492"],"resync_asset_watermarks_ns":{"60386828328910021732068595344565885737045900010034836345809386672230885527307":1785126367331000000,"69697746896130839564035629862476347944307040470122503199396727085502753297492":1785126363605000000},"resync_buffered":true,"resync_status":"success","resync_watermark_ns":1785126367331000000,"schema_version":"clob-market-ws.price_change.v1","sequence":null,"server_hash":null,"server_timestamp":"1785126361589","session_id":"e9443c7415a0419799bee9cfbb1a9e4d","source":"clob_market_ws"},"received_at":"2026-07-27T04:26:01.532560Z","record_id":"df76d4ce87a37c89f2feaa55460a272cd389a306ca71d38dbd2f01b9e47688bd","schema_fingerprint":"a522b3829e2baa1444da15da10771d4b0020c6969989c3325606306f55b0b63e","schema_version":"edge-lab-recorder.raw.v1","sequence":null,"source":"clob_market_ws"}
{"event_at":"2026-07-27T04:26:02.788000Z","event_fingerprint":"88c623f151aceed9daf0f6403aa8323dba5ebb84259be09e0d0ea5b49528a18c","payload":{"connection_id":"0f4979d6978d463e9660b042fdcf555f","event_at":"2026-07-27T04:26:02.788000Z","event_type":"price_change","frame_hash":"34c4b51d761671437d5787cc3b4c059ace1b5434c556072c9fb8bd5a697ec70f","frame_index":0,"kind":"quarantine","monotonic_ns":228346003423625,"payload":{"event_type":"price_change","market":"0xeb66215f2e9faa6449e30a02bab5b8ed7b79a38bf961f6b24d0073c9c2419250","price_changes":[{"asset_id":"69697746896130839564035629862476347944307040470122503199396727085502753297492","best_ask":"0.46","best_bid":"0.45","hash":"79c2ac28d159df4576f4bb33f764a322d436583c","price":"0.01","side":"BUY","size":"97900.02"},{"asset_id":"60386828328910021732068595344565885737045900010034836345809386672230885527307","best_ask":"0.55","best_bid":"0.54","hash":"b5c128a1b08d3cb30e2566e7350f0fab985a2eca","price":"0.99","side":"SELL","size":"97900.02"}],"timestamp":"1785126362788"},"payload_hash":"c9456e2f4d5492c0e453cc7827b917150b92ce9840e4e50546e3e6a081e35b69","raw_frame":"{\"market\":\"0xeb66215f2e9faa6449e30a02bab5b8ed7b79a38bf961f6b24d0073c9c2419250\", \"price_changes\":[{\"asset_id\":\"69697746896130839564035629862476347944307040470122503199396727085502753297492\", \"price\":\"0.01\", \"size\":\"97900.02\", \"side\":\"BUY\", \"hash\":\"79c2ac28d159df4576f4bb33f764a322d436583c\", \"best_bid\":\"0.45\", \"best_ask\":\"0.46\"}, {\"asset_id\":\"60386828328910021732068595344565885737045900010034836345809386672230885527307\", \"price\":\"0.99\", \"size\":\"97900.02\", \"side\":\"SELL\", \"hash\":\"b5c128a1b08d3cb30e2566e7350f0fab985a2eca\", \"best_bid\":\"0.54\", \"best_ask\":\"0.55\"}], \"timestamp\":\"1785126362788\", \"event_type\":\"price_change\"}","received_at":"2026-07-27T04:26:02.731526Z","replay_eligible":false,"resync_asset_ids":["60386828328910021732068595344565885737045900010034836345809386672230885527307","69697746896130839564035629862476347944307040470122503199396727085502753297492"],"resync_asset_watermarks_ns":{"60386828328910021732068595344565885737045900010034836345809386672230885527307":1785126367331000000,"69697746896130839564035629862476347944307040470122503199396727085502753297492":1785126363605000000},"resync_buffered":true,"resync_status":"success","resync_watermark_ns":1785126367331000000,"schema_version":"clob-market-ws.price_change.v1","sequence":null,"server_hash":null,"server_timestamp":"1785126362788","session_id":"e9443c7415a0419799bee9cfbb1a9e4d","source":"clob_market_ws"},"received_at":"2026-07-27T04:26:02.731526Z","record_id":"95966e0a1dcc70b1e8db8ab247f71f1aa53b4a057cba00920d325cf9f6215089","schema_fingerprint":"a522b3829e2baa1444da15da10771d4b0020c6969989c3325606306f55b0b63e","schema_version":"edge-lab-recorder.raw.v1","sequence":null,"source":"clob_market_ws"}
{"event_at":"2026-07-27T04:26:03.605000Z","event_fingerprint":"cab46f233ad944bcd906e5d9c1ef65d0c2dfbdabc2ae54fa8811095f14da8570","payload":{"connection_id":"0f4979d6978d463e9660b042fdcf555f","event_at":"2026-07-27T04:26:03.605000Z","event_type":"price_change","frame_hash":"c755bdd2732706f89f542ddb64444515729645f5220a8e6500c1a2ae77f0cc67","frame_index":0,"kind":"quarantine","monotonic_ns":228346820645333,"payload":{"event_type":"price_change","market":"0xeb66215f2e9faa6449e30a02bab5b8ed7b79a38bf961f6b24d0073c9c2419250","price_changes":[{"asset_id":"69697746896130839564035629862476347944307040470122503199396727085502753297492","best_ask":"0.46","best_bid":"0.45","hash":"69a5ec359fa50868290f2814eafbc76833733f44","price":"0.01","side":"BUY","size":"97895.02"},{"asset_id":"60386828328910021732068595344565885737045900010034836345809386672230885527307","best_ask":"0.55","best_bid":"0.54","hash":"7d7f4db8037ecc4004a7ecf595c629276f18f14b","price":"0.99","side":"SELL","size":"97895.02"}],"timestamp":"1785126363605"},"payload_hash":"43097647f696086b6c5dea55efed1aa0bbe2f18529a28c4b0d75aae2cad00514","raw_frame":"{\"market\":\"0xeb66215f2e9faa6449e30a02bab5b8ed7b79a38bf961f6b24d0073c9c2419250\", \"price_changes\":[{\"asset_id\":\"69697746896130839564035629862476347944307040470122503199396727085502753297492\", \"price\":\"0.01\", \"size\":\"97895.02\", \"side\":\"BUY\", \"hash\":\"69a5ec359fa50868290f2814eafbc76833733f44\", \"best_bid\":\"0.45\", \"best_ask\":\"0.46\"}, {\"asset_id\":\"60386828328910021732068595344565885737045900010034836345809386672230885527307\", \"price\":\"0.99\", \"size\":\"97895.02\", \"side\":\"SELL\", \"hash\":\"7d7f4db8037ecc4004a7ecf595c629276f18f14b\", \"best_bid\":\"0.54\", \"best_ask\":\"0.55\"}], \"timestamp\":\"1785126363605\", \"event_type\":\"price_change\"}","received_at":"2026-07-27T04:26:03.548758Z","replay_eligible":false,"resync_asset_ids":["60386828328910021732068595344565885737045900010034836345809386672230885527307","69697746896130839564035629862476347944307040470122503199396727085502753297492"],"resync_asset_watermarks_ns":{"60386828328910021732068595344565885737045900010034836345809386672230885527307":1785126367331000000,"69697746896130839564035629862476347944307040470122503199396727085502753297492":1785126363605000000},"resync_buffered":true,"resync_status":"success","resync_watermark_ns":1785126367331000000,"schema_version":"clob-market-ws.price_change.v1","sequence":null,"server_hash":null,"server_timestamp":"1785126363605","session_id":"e9443c7415a0419799bee9cfbb1a9e4d","source":"clob_market_ws"},"received_at":"2026-07-27T04:26:03.548758Z","record_id":"3d37c6fb22018e5a15f9cc509026eeaf9cff02a843604166f6485a793852aef6","schema_fingerprint":"a522b3829e2baa1444da15da10771d4b0020c6969989c3325606306f55b0b63e","schema_version":"edge-lab-recorder.raw.v1","sequence":null,"source":"clob_market_ws"}
{"event_at":"2026-07-27T04:26:07.331000Z","event_fingerprint":"f2e72f7692c645af04c43fd4dc24df7fbbc9d2bbd776abad8957383519312fbe","payload":{"connection_id":"0f4979d6978d463e9660b042fdcf555f","event_at":"2026-07-27T04:26:07.331000Z","event_type":"best_bid_ask","frame_hash":"dd10fe11a00f6782e181376d54fb5195667ca450b05b2bfa0c30b2fbff086d2e","frame_index":0,"kind":"data","monotonic_ns":228350545734375,"payload":{"asset_id":"69697746896130839564035629862476347944307040470122503199396727085502753297492","best_ask":"0.46","best_bid":"0.45","event_type":"best_bid_ask","market":"0xeb66215f2e9faa6449e30a02bab5b8ed7b79a38bf961f6b24d0073c9c2419250","spread":"0.01","timestamp":"1785126367331"},"payload_hash":"849e1a65f656c18b5c4e91b9236ea9f9f93fcee905afaaae1127f60f4b28f5da","raw_frame":"{\"market\":\"0xeb66215f2e9faa6449e30a02bab5b8ed7b79a38bf961f6b24d0073c9c2419250\", \"asset_id\":\"69697746896130839564035629862476347944307040470122503199396727085502753297492\", \"best_bid\":\"0.45\", \"best_ask\":\"0.46\", \"spread\":\"0.01\", \"timestamp\":\"1785126367331\", \"event_type\":\"best_bid_ask\"}","received_at":"2026-07-27T04:26:07.273880Z","replay_eligible":true,"resync_asset_ids":["69697746896130839564035629862476347944307040470122503199396727085502753297492"],"resync_asset_watermarks_ns":{"69697746896130839564035629862476347944307040470122503199396727085502753297492":1785126363605000000},"resync_buffered":true,"resync_status":"success","resync_watermark_ns":1785126363605000000,"schema_version":"clob-market-ws.best_bid_ask.v1","sequence":null,"server_hash":null,"server_timestamp":"1785126367331","session_id":"e9443c7415a0419799bee9cfbb1a9e4d","source":"clob_market_ws"},"received_at":"2026-07-27T04:26:07.273880Z","record_id":"ea1a3aa088b749d79f90a129f64e467beb4fc2f878554cec7aa6777dfcc636e3","schema_fingerprint":"f14f4da98ca968e5ad81835ee6fa59169391d83e7f109fe340a2d33a3cb5ec99","schema_version":"edge-lab-recorder.raw.v1","sequence":null,"source":"clob_market_ws"}
{"event_at":"2026-07-27T04:26:07.331000Z","event_fingerprint":"ac3b30748f45119358ef6f2461987007abdd1c3cb90a30c1f3a9c2dcbcf08091","payload":{"connection_id":"0f4979d6978d463e9660b042fdcf555f","event_at":"2026-07-27T04:26:07.331000Z","event_type":"best_bid_ask","frame_hash":"ae8200af138ddfd09b117463af58b22044a49857a246418dd11f65faf5814561","frame_index":0,"kind":"quarantine","monotonic_ns":228350545754166,"payload":{"asset_id":"60386828328910021732068595344565885737045900010034836345809386672230885527307","best_ask":"0.55","best_bid":"0.54","event_type":"best_bid_ask","market":"0xeb66215f2e9faa6449e30a02bab5b8ed7b79a38bf961f6b24d0073c9c2419250","spread":"0.01","timestamp":"1785126367331"},"payload_hash":"8c599d50b0020ea72f7ed4881986f07ecdbf61b3a9583b5b6dc8ca05b0906cef","raw_frame":"{\"market\":\"0xeb66215f2e9faa6449e30a02bab5b8ed7b79a38bf961f6b24d0073c9c2419250\", \"asset_id\":\"60386828328910021732068595344565885737045900010034836345809386672230885527307\", \"best_bid\":\"0.54\", \"best_ask\":\"0.55\", \"spread\":\"0.01\", \"timestamp\":\"1785126367331\", \"event_type\":\"best_bid_ask\"}","received_at":"2026-07-27T04:26:07.273901Z","replay_eligible":false,"resync_asset_ids":["60386828328910021732068595344565885737045900010034836345809386672230885527307"],"resync_asset_watermarks_ns":{"60386828328910021732068595344565885737045900010034836345809386672230885527307":1785126367331000000},"resync_buffered":true,"resync_status":"success","resync_watermark_ns":1785126367331000000,"schema_version":"clob-market-ws.best_bid_ask.v1","sequence":null,"server_hash":null,"server_timestamp":"1785126367331","session_id":"e9443c7415a0419799bee9cfbb1a9e4d","source":"clob_market_ws"},"received_at":"2026-07-27T04:26:07.273901Z","record_id":"91ed96ca12a65cf294d4b1213e72f30c359056660ca1f9d9facd20b3cb3d3a53","schema_fingerprint":"16e55948ec66a45eb042374748841018c983081d232cf886a0c2bc228e131413","schema_version":"edge-lab-recorder.raw.v1","sequence":null,"source":"clob_market_ws"}
{"event_at":"2026-07-27T04:26:07.331000Z","event_fingerprint":"a7d70e8095c85aeb72956bd1858ab3b04eb70e89370b53f720e03b33d97a64c9","payload":{"connection_id":"0f4979d6978d463e9660b042fdcf555f","event_at":"2026-07-27T04:26:07.331000Z","event_type":"price_change","frame_hash":"729e70d669fc1c371b8bd75303506a0c2ef7868f195964341cdcc59c43aee592","frame_index":0,"kind":"quarantine","monotonic_ns":228350545771625,"payload":{"event_type":"price_change","market":"0xeb66215f2e9faa6449e30a02bab5b8ed7b79a38bf961f6b24d0073c9c2419250","price_changes":[{"asset_id":"69697746896130839564035629862476347944307040470122503199396727085502753297492","best_ask":"0.46","best_bid":"0.45","hash":"94f22778a71cb8aa95a5708a97e5045796cf610b","price":"0.45","side":"BUY","size":"172.95"},{"asset_id":"60386828328910021732068595344565885737045900010034836345809386672230885527307","best_ask":"0.55","best_bid":"0.54","hash":"1d7fdb0a190da447456f0ffa39b65e775f0ba946","price":"0.55","side":"SELL","size":"172.95"}],"timestamp":"1785126367331"},"payload_hash":"8fa3ccde96051755524a24083ea5e42bb4fd60e81905400bce371557255ce6c6","raw_frame":"{\"market\":\"0xeb66215f2e9faa6449e30a02bab5b8ed7b79a38bf961f6b24d0073c9c2419250\", \"price_changes\":[{\"asset_id\":\"69697746896130839564035629862476347944307040470122503199396727085502753297492\", \"price\":\"0.45\", \"size\":\"172.95\", \"side\":\"BUY\", \"hash\":\"94f22778a71cb8aa95a5708a97e5045796cf610b\", \"best_bid\":\"0.45\", \"best_ask\":\"0.46\"}, {\"asset_id\":\"60386828328910021732068595344565885737045900010034836345809386672230885527307\", \"price\":\"0.55\", \"size\":\"172.95\", \"side\":\"SELL\", \"hash\":\"1d7fdb0a190da447456f0ffa39b65e775f0ba946\", \"best_bid\":\"0.54\", \"best_ask\":\"0.55\"}], \"timestamp\":\"1785126367331\", \"event_type\":\"price_change\"}","received_at":"2026-07-27T04:26:07.273919Z","replay_eligible":false,"resync_asset_ids":["60386828328910021732068595344565885737045900010034836345809386672230885527307","69697746896130839564035629862476347944307040470122503199396727085502753297492"],"resync_asset_watermarks_ns":{"60386828328910021732068595344565885737045900010034836345809386672230885527307":1785126367331000000,"69697746896130839564035629862476347944307040470122503199396727085502753297492":1785126363605000000},"resync_buffered":true,"resync_status":"success","resync_watermark_ns":1785126367331000000,"schema_version":"clob-market-ws.price_change.v1","sequence":null,"server_hash":null,"server_timestamp":"1785126367331","session_id":"e9443c7415a0419799bee9cfbb1a9e4d","source":"clob_market_ws"},"received_at":"2026-07-27T04:26:07.273919Z","record_id":"46e50413d1b714010b48af3372bfd243c3ce9e6eb4630ffa733a6f45f7af9bb5","schema_fingerprint":"a522b3829e2baa1444da15da10771d4b0020c6969989c3325606306f55b0b63e","schema_version":"edge-lab-recorder.raw.v1","sequence":null,"source":"clob_market_ws"}
{"event_at":"2026-07-27T04:26:07.331000Z","event_fingerprint":"49cf404dee173ecc4dedba72c317572846a17d071c79cc0faf0e468bd1195256","payload":{"connection_id":"0f4979d6978d463e9660b042fdcf555f","event_at":"2026-07-27T04:26:07.331000Z","event_type":"book","frame_hash":"b350a62510e06f0742abad3591b816d1d4e65210a2aaa693ab6bd07d514fe284","frame_index":0,"kind":"data","monotonic_ns":228350548240750,"payload":{"asks":[{"price":"0.99","size":"97895.02"},{"price":"0.98","size":"16850"},{"price":"0.97","size":"11088"},{"price":"0.96","size":"800"},{"price":"0.95","size":"6799"},{"price":"0.94","size":"837.68"},{"price":"0.93","size":"564"},{"price":"0.92","size":"626"},{"price":"0.91","size":"530"},{"price":"0.9","size":"3194"},{"price":"0.89","size":"66.46"},{"price":"0.88","size":"61.67"},{"price":"0.87","size":"18"},{"price":"0.86","size":"16"},{"price":"0.85","size":"2231.34"},{"price":"0.84","size":"12"},{"price":"0.83","size":"60.42"},{"price":"0.82","size":"37.78"},{"price":"0.81","size":"28"},{"price":"0.8","size":"1749"},{"price":"0.79","size":"245"},{"price":"0.78","size":"25"},{"price":"0.77","size":"26.74"},{"price":"0.76","size":"839.18"},{"price":"0.75","size":"965"},{"price":"0.74","size":"345"},{"price":"0.73","size":"25"},{"price":"0.72","size":"290"},{"price":"0.71","size":"72.25"},{"price":"0.7","size":"1045"},{"price":"0.69","size":"21.13"},{"price":"0.68","size":"585"},{"price":"0.67","size":"576"},{"price":"0.66","size":"160"},{"price":"0.65","size":"15"},{"price":"0.64","size":"759"},{"price":"0.62","size":"319.79"},{"price":"0.61","size":"48"},{"price":"0.6","size":"82"},{"price":"0.59","size":"59.2"},{"price":"0.58","size":"218"},{"price":"0.57","size":"350"},{"price":"0.56","size":"330.68"},{"price":"0.55","size":"115.33"},{"price":"0.54","size":"125"},{"price":"0.53","size":"64.67"},{"price":"0.52","size":"50"},{"price":"0.51","size":"11"},{"price":"0.5","size":"20"},{"price":"0.49","size":"25"},{"price":"0.48","size":"200.83"},{"price":"0.47","size":"200"},{"price":"0.46","size":"425.42"}],"asset_id":"69697746896130839564035629862476347944307040470122503199396727085502753297492","bids":[{"price":"0.01","size":"97895.02"},{"price":"0.02","size":"16850"},{"price":"0.03","size":"11088"},{"price":"0.04","size":"800"},{"price":"0.05","size":"6799"},{"price":"0.06","size":"837.68"},{"price":"0.07","size":"564"},{"price":"0.08","size":"626"},{"price":"0.09","size":"530"},{"price":"0.1","size":"3194"},{"price":"0.11","size":"66.46"},{"price":"0.12","size":"61.67"},{"price":"0.13","size":"18"},{"price":"0.14","size":"16"},{"price":"0.15","size":"2231.34"},{"price":"0.16","size":"12"},{"price":"0.17","size":"60.42"},{"price":"0.18","size":"37.78"},{"price":"0.19","size":"28"},{"price":"0.2","size":"1749"},{"price":"0.21","size":"245"},{"price":"0.22","size":"170"},{"price":"0.23","size":"26.74"},{"price":"0.24","size":"839.18"},{"price":"0.25","size":"965"},{"price":"0.26","size":"345"},{"price":"0.27","size":"170"},{"price":"0.28","size":"145"},{"price":"0.29","size":"72.25"},{"price":"0.3","size":"1045"},{"price":"0.31","size":"21.13"},{"price":"0.32","size":"730"},{"price":"0.33","size":"431"},{"price":"0.34","size":"160"},{"price":"0.35","size":"15"},{"price":"0.36","size":"765"},{"price":"0.37","size":"145"},{"price":"0.38","size":"180.79"},{"price":"0.39","size":"48"},{"price":"0.4","size":"185"},{"price":"0.41","size":"168.2"},{"price":"0.42","size":"322"},{"price":"0.43","size":"410"},{"price":"0.44","size":"455.68"},{"price":"0.45","size":"172.95"}],"event_type":"book","hash":"94f22778a71cb8aa95a5708a97e5045796cf610b","market":"0xeb66215f2e9faa6449e30a02bab5b8ed7b79a38bf961f6b24d0073c9c2419250","timestamp":"1785126367331"},"payload_hash":"746bc0e28836310a0cd02b9c640f359ab2b3c6a6bc50ba0e26f6b8cb1f233351","raw_frame":"{\"market\":\"0xeb66215f2e9faa6449e30a02bab5b8ed7b79a38bf961f6b24d0073c9c2419250\", \"asset_id\":\"69697746896130839564035629862476347944307040470122503199396727085502753297492\", \"bids\":[{\"price\":\"0.01\", \"size\":\"97895.02\"}, {\"price\":\"0.02\", \"size\":\"16850\"}, {\"price\":\"0.03\", \"size\":\"11088\"}, {\"price\":\"0.04\", \"size\":\"800\"}, {\"price\":\"0.05\", \"size\":\"6799\"}, {\"price\":\"0.06\", \"size\":\"837.68\"}, {\"price\":\"0.07\", \"size\":\"564\"}, {\"price\":\"0.08\", \"size\":\"626\"}, {\"price\":\"0.09\", \"size\":\"530\"}, {\"price\":\"0.1\", \"size\":\"3194\"}, {\"price\":\"0.11\", \"size\":\"66.46\"}, {\"price\":\"0.12\", \"size\":\"61.67\"}, {\"price\":\"0.13\", \"size\":\"18\"}, {\"price\":\"0.14\", \"size\":\"16\"}, {\"price\":\"0.15\", \"size\":\"2231.34\"}, {\"price\":\"0.16\", \"size\":\"12\"}, {\"price\":\"0.17\", \"size\":\"60.42\"}, {\"price\":\"0.18\", \"size\":\"37.78\"}, {\"price\":\"0.19\", \"size\":\"28\"}, {\"price\":\"0.2\", \"size\":\"1749\"}, {\"price\":\"0.21\", \"size\":\"245\"}, {\"price\":\"0.22\", \"size\":\"170\"}, {\"price\":\"0.23\", \"size\":\"26.74\"}, {\"price\":\"0.24\", \"size\":\"839.18\"}, {\"price\":\"0.25\", \"size\":\"965\"}, {\"price\":\"0.26\", \"size\":\"345\"}, {\"price\":\"0.27\", \"size\":\"170\"}, {\"price\":\"0.28\", \"size\":\"145\"}, {\"price\":\"0.29\", \"size\":\"72.25\"}, {\"price\":\"0.3\", \"size\":\"1045\"}, {\"price\":\"0.31\", \"size\":\"21.13\"}, {\"price\":\"0.32\", \"size\":\"730\"}, {\"price\":\"0.33\", \"size\":\"431\"}, {\"price\":\"0.34\", \"size\":\"160\"}, {\"price\":\"0.35\", \"size\":\"15\"}, {\"price\":\"0.36\", \"size\":\"765\"}, {\"price\":\"0.37\", \"size\":\"145\"}, {\"price\":\"0.38\", \"size\":\"180.79\"}, {\"price\":\"0.39\", \"size\":\"48\"}, {\"price\":\"0.4\", \"size\":\"185\"}, {\"price\":\"0.41\", \"size\":\"168.2\"}, {\"price\":\"0.42\", \"size\":\"322\"}, {\"price\":\"0.43\", \"size\":\"410\"}, {\"price\":\"0.44\", \"size\":\"455.68\"}, {\"price\":\"0.45\", \"size\":\"172.95\"}], \"asks\":[{\"price\":\"0.99\", \"size\":\"97895.02\"}, {\"price\":\"0.98\", \"size\":\"16850\"}, {\"price\":\"0.97\", \"size\":\"11088\"}, {\"price\":\"0.96\", \"size\":\"800\"}, {\"price\":\"0.95\", \"size\":\"6799\"}, {\"price\":\"0.94\", \"size\":\"837.68\"}, {\"price\":\"0.93\", \"size\":\"564\"}, {\"price\":\"0.92\", \"size\":\"626\"}, {\"price\":\"0.91\", \"size\":\"530\"}, {\"price\":\"0.9\", \"size\":\"3194\"}, {\"price\":\"0.89\", \"size\":\"66.46\"}, {\"price\":\"0.88\", \"size\":\"61.67\"}, {\"price\":\"0.87\", \"size\":\"18\"}, {\"price\":\"0.86\", \"size\":\"16\"}, {\"price\":\"0.85\", \"size\":\"2231.34\"}, {\"price\":\"0.84\", \"size\":\"12\"}, {\"price\":\"0.83\", \"size\":\"60.42\"}, {\"price\":\"0.82\", \"size\":\"37.78\"}, {\"price\":\"0.81\", \"size\":\"28\"}, {\"price\":\"0.8\", \"size\":\"1749\"}, {\"price\":\"0.79\", \"size\":\"245\"}, {\"price\":\"0.78\", \"size\":\"25\"}, {\"price\":\"0.77\", \"size\":\"26.74\"}, {\"price\":\"0.76\", \"size\":\"839.18\"}, {\"price\":\"0.75\", \"size\":\"965\"}, {\"price\":\"0.74\", \"size\":\"345\"}, {\"price\":\"0.73\", \"size\":\"25\"}, {\"price\":\"0.72\", \"size\":\"290\"}, {\"price\":\"0.71\", \"size\":\"72.25\"}, {\"price\":\"0.7\", \"size\":\"1045\"}, {\"price\":\"0.69\", \"size\":\"21.13\"}, {\"price\":\"0.68\", \"size\":\"585\"}, {\"price\":\"0.67\", \"size\":\"576\"}, {\"price\":\"0.66\", \"size\":\"160\"}, {\"price\":\"0.65\", \"size\":\"15\"}, {\"price\":\"0.64\", \"size\":\"759\"}, {\"price\":\"0.62\", \"size\":\"319.79\"}, {\"price\":\"0.61\", \"size\":\"48\"}, {\"price\":\"0.6\", \"size\":\"82\"}, {\"price\":\"0.59\", \"size\":\"59.2\"}, {\"price\":\"0.58\", \"size\":\"218\"}, {\"price\":\"0.57\", \"size\":\"350\"}, {\"price\":\"0.56\", \"size\":\"330.68\"}, {\"price\":\"0.55\", \"size\":\"115.33\"}, {\"price\":\"0.54\", \"size\":\"125\"}, {\"price\":\"0.53\", \"size\":\"64.67\"}, {\"price\":\"0.52\", \"size\":\"50\"}, {\"price\":\"0.51\", \"size\":\"11\"}, {\"price\":\"0.5\", \"size\":\"20\"}, {\"price\":\"0.49\", \"size\":\"25\"}, {\"price\":\"0.48\", \"size\":\"200.83\"}, {\"price\":\"0.47\", \"size\":\"200\"}, {\"price\":\"0.46\", \"size\":\"425.42\"}], \"hash\":\"94f22778a71cb8aa95a5708a97e5045796cf610b\", \"timestamp\":\"1785126367331\", \"event_type\":\"book\"}","received_at":"2026-07-27T04:26:07.276388Z","replay_eligible":true,"resync_asset_ids":["69697746896130839564035629862476347944307040470122503199396727085502753297492"],"resync_asset_watermarks_ns":{"69697746896130839564035629862476347944307040470122503199396727085502753297492":1785126363605000000},"resync_buffered":true,"resync_status":"success","resync_watermark_ns":1785126363605000000,"schema_version":"clob-market-ws.book.v1","sequence":null,"server_hash":"94f22778a71cb8aa95a5708a97e5045796cf610b","server_timestamp":"1785126367331","session_id":"e9443c7415a0419799bee9cfbb1a9e4d","source":"clob_market_ws"},"received_at":"2026-07-27T04:26:07.276388Z","record_id":"20f6ffe34e90512457cf07a00b2373fc367ea1faf089cdcdb5c1848402a2724b","schema_fingerprint":"801b3beaeb455559a5d40e9db75f3ccf7c70162757b957ccd432a95126932449","schema_version":"edge-lab-recorder.raw.v1","sequence":null,"source":"clob_market_ws"}
{"event_at":"2026-07-27T04:26:07.331000Z","event_fingerprint":"7d476f8af9473d449cb754526e258b274edc648b671b079e751f74cb429bd46f","payload":{"connection_id":"0f4979d6978d463e9660b042fdcf555f","event_at":"2026-07-27T04:26:07.331000Z","event_type":"book","frame_hash":"65e92d28aa2b5e08db3bc696d5f89689b79b4715607dc99cdaf12cb9a775cd7f","frame_index":0,"kind":"quarantine","monotonic_ns":228350548260000,"payload":{"asks":[{"price":"0.99","size":"97895.02"},{"price":"0.98","size":"16850"},{"price":"0.97","size":"11088"},{"price":"0.96","size":"800"},{"price":"0.95","size":"6799"},{"price":"0.94","size":"837.68"},{"price":"0.93","size":"564"},{"price":"0.92","size":"626"},{"price":"0.91","size":"530"},{"price":"0.9","size":"3194"},{"price":"0.89","size":"66.46"},{"price":"0.88","size":"61.67"},{"price":"0.87","size":"18"},{"price":"0.86","size":"16"},{"price":"0.85","size":"2231.34"},{"price":"0.84","size":"12"},{"price":"0.83","size":"60.42"},{"price":"0.82","size":"37.78"},{"price":"0.81","size":"28"},{"price":"0.8","size":"1749"},{"price":"0.79","size":"245"},{"price":"0.78","size":"170"},{"price":"0.77","size":"26.74"},{"price":"0.76","size":"839.18"},{"price":"0.75","size":"965"},{"price":"0.74","size":"345"},{"price":"0.73","size":"170"},{"price":"0.72","size":"145"},{"price":"0.71","size":"72.25"},{"price":"0.7","size":"1045"},{"price":"0.69","size":"21.13"},{"price":"0.68","size":"730"},{"price":"0.67","size":"431"},{"price":"0.66","size":"160"},{"price":"0.65","size":"15"},{"price":"0.64","size":"765"},{"price":"0.63","size":"145"},{"price":"0.62","size":"180.79"},{"price":"0.61","size":"48"},{"price":"0.6","size":"185"},{"price":"0.59","size":"168.2"},{"price":"0.58","size":"322"},{"price":"0.57","size":"410"},{"price":"0.56","size":"455.68"},{"price":"0.55","size":"172.95"}],"asset_id":"60386828328910021732068595344565885737045900010034836345809386672230885527307","bids":[{"price":"0.01","size":"97895.02"},{"price":"0.02","size":"16850"},{"price":"0.03","size":"11088"},{"price":"0.04","size":"800"},{"price":"0.05","size":"6799"},{"price":"0.06","size":"837.68"},{"price":"0.07","size":"564"},{"price":"0.08","size":"626"},{"price":"0.09","size":"530"},{"price":"0.1","size":"3194"},{"price":"0.11","size":"66.46"},{"price":"0.12","size":"61.67"},{"price":"0.13","size":"18"},{"price":"0.14","size":"16"},{"price":"0.15","size":"2231.34"},{"price":"0.16","size":"12"},{"price":"0.17","size":"60.42"},{"price":"0.18","size":"37.78"},{"price":"0.19","size":"28"},{"price":"0.2","size":"1749"},{"price":"0.21","size":"245"},{"price":"0.22","size":"25"},{"price":"0.23","size":"26.74"},{"price":"0.24","size":"839.18"},{"price":"0.25","size":"965"},{"price":"0.26","size":"345"},{"price":"0.27","size":"25"},{"price":"0.28","size":"290"},{"price":"0.29","size":"72.25"},{"price":"0.3","size":"1045"},{"price":"0.31","size":"21.13"},{"price":"0.32","size":"585"},{"price":"0.33","size":"576"},{"price":"0.34","size":"160"},{"price":"0.35","size":"15"},{"price":"0.36","size":"759"},{"price":"0.38","size":"319.79"},{"price":"0.39","size":"48"},{"price":"0.4","size":"82"},{"price":"0.41","size":"59.2"},{"price":"0.42","size":"218"},{"price":"0.43","size":"350"},{"price":"0.44","size":"330.68"},{"price":"0.45","size":"115.33"},{"price":"0.46","size":"125"},{"price":"0.47","size":"64.67"},{"price":"0.48","size":"50"},{"price":"0.49","size":"11"},{"price":"0.5","size":"20"},{"price":"0.51","size":"25"},{"price":"0.52","size":"200.83"},{"price":"0.53","size":"200"},{"price":"0.54","size":"425.42"}],"event_type":"book","hash":"1d7fdb0a190da447456f0ffa39b65e775f0ba946","market":"0xeb66215f2e9faa6449e30a02bab5b8ed7b79a38bf961f6b24d0073c9c2419250","timestamp":"1785126367331"},"payload_hash":"5d6936b2bc55918ab91b659786001ad7ca5371c536241f0dd3e4df4a707e8b68","raw_frame":"{\"market\":\"0xeb66215f2e9faa6449e30a02bab5b8ed7b79a38bf961f6b24d0073c9c2419250\", \"asset_id\":\"60386828328910021732068595344565885737045900010034836345809386672230885527307\", \"bids\":[{\"price\":\"0.01\", \"size\":\"97895.02\"}, {\"price\":\"0.02\", \"size\":\"16850\"}, {\"price\":\"0.03\", \"size\":\"11088\"}, {\"price\":\"0.04\", \"size\":\"800\"}, {\"price\":\"0.05\", \"size\":\"6799\"}, {\"price\":\"0.06\", \"size\":\"837.68\"}, {\"price\":\"0.07\", \"size\":\"564\"}, {\"price\":\"0.08\", \"size\":\"626\"}, {\"price\":\"0.09\", \"size\":\"530\"}, {\"price\":\"0.1\", \"size\":\"3194\"}, {\"price\":\"0.11\", \"size\":\"66.46\"}, {\"price\":\"0.12\", \"size\":\"61.67\"}, {\"price\":\"0.13\", \"size\":\"18\"}, {\"price\":\"0.14\", \"size\":\"16\"}, {\"price\":\"0.15\", \"size\":\"2231.34\"}, {\"price\":\"0.16\", \"size\":\"12\"}, {\"price\":\"0.17\", \"size\":\"60.42\"}, {\"price\":\"0.18\", \"size\":\"37.78\"}, {\"price\":\"0.19\", \"size\":\"28\"}, {\"price\":\"0.2\", \"size\":\"1749\"}, {\"price\":\"0.21\", \"size\":\"245\"}, {\"price\":\"0.22\", \"size\":\"25\"}, {\"price\":\"0.23\", \"size\":\"26.74\"}, {\"price\":\"0.24\", \"size\":\"839.18\"}, {\"price\":\"0.25\", \"size\":\"965\"}, {\"price\":\"0.26\", \"size\":\"345\"}, {\"price\":\"0.27\", \"size\":\"25\"}, {\"price\":\"0.28\", \"size\":\"290\"}, {\"price\":\"0.29\", \"size\":\"72.25\"}, {\"price\":\"0.3\", \"size\":\"1045\"}, {\"price\":\"0.31\", \"size\":\"21.13\"}, {\"price\":\"0.32\", \"size\":\"585\"}, {\"price\":\"0.33\", \"size\":\"576\"}, {\"price\":\"0.34\", \"size\":\"160\"}, {\"price\":\"0.35\", \"size\":\"15\"}, {\"price\":\"0.36\", \"size\":\"759\"}, {\"price\":\"0.38\", \"size\":\"319.79\"}, {\"price\":\"0.39\", \"size\":\"48\"}, {\"price\":\"0.4\", \"size\":\"82\"}, {\"price\":\"0.41\", \"size\":\"59.2\"}, {\"price\":\"0.42\", \"size\":\"218\"}, {\"price\":\"0.43\", \"size\":\"350\"}, {\"price\":\"0.44\", \"size\":\"330.68\"}, {\"price\":\"0.45\", \"size\":\"115.33\"}, {\"price\":\"0.46\", \"size\":\"125\"}, {\"price\":\"0.47\", \"size\":\"64.67\"}, {\"price\":\"0.48\", \"size\":\"50\"}, {\"price\":\"0.49\", \"size\":\"11\"}, {\"price\":\"0.5\", \"size\":\"20\"}, {\"price\":\"0.51\", \"size\":\"25\"}, {\"price\":\"0.52\", \"size\":\"200.83\"}, {\"price\":\"0.53\", \"size\":\"200\"}, {\"price\":\"0.54\", \"size\":\"425.42\"}], \"asks\":[{\"price\":\"0.99\", \"size\":\"97895.02\"}, {\"price\":\"0.98\", \"size\":\"16850\"}, {\"price\":\"0.97\", \"size\":\"11088\"}, {\"price\":\"0.96\", \"size\":\"800\"}, {\"price\":\"0.95\", \"size\":\"6799\"}, {\"price\":\"0.94\", \"size\":\"837.68\"}, {\"price\":\"0.93\", \"size\":\"564\"}, {\"price\":\"0.92\", \"size\":\"626\"}, {\"price\":\"0.91\", \"size\":\"530\"}, {\"price\":\"0.9\", \"size\":\"3194\"}, {\"price\":\"0.89\", \"size\":\"66.46\"}, {\"price\":\"0.88\", \"size\":\"61.67\"}, {\"price\":\"0.87\", \"size\":\"18\"}, {\"price\":\"0.86\", \"size\":\"16\"}, {\"price\":\"0.85\", \"size\":\"2231.34\"}, {\"price\":\"0.84\", \"size\":\"12\"}, {\"price\":\"0.83\", \"size\":\"60.42\"}, {\"price\":\"0.82\", \"size\":\"37.78\"}, {\"price\":\"0.81\", \"size\":\"28\"}, {\"price\":\"0.8\", \"size\":\"1749\"}, {\"price\":\"0.79\", \"size\":\"245\"}, {\"price\":\"0.78\", \"size\":\"170\"}, {\"price\":\"0.77\", \"size\":\"26.74\"}, {\"price\":\"0.76\", \"size\":\"839.18\"}, {\"price\":\"0.75\", \"size\":\"965\"}, {\"price\":\"0.74\", \"size\":\"345\"}, {\"price\":\"0.73\", \"size\":\"170\"}, {\"price\":\"0.72\", \"size\":\"145\"}, {\"price\":\"0.71\", \"size\":\"72.25\"}, {\"price\":\"0.7\", \"size\":\"1045\"}, {\"price\":\"0.69\", \"size\":\"21.13\"}, {\"price\":\"0.68\", \"size\":\"730\"}, {\"price\":\"0.67\", \"size\":\"431\"}, {\"price\":\"0.66\", \"size\":\"160\"}, {\"price\":\"0.65\", \"size\":\"15\"}, {\"price\":\"0.64\", \"size\":\"765\"}, {\"price\":\"0.63\", \"size\":\"145\"}, {\"price\":\"0.62\", \"size\":\"180.79\"}, {\"price\":\"0.61\", \"size\":\"48\"}, {\"price\":\"0.6\", \"size\":\"185\"}, {\"price\":\"0.59\", \"size\":\"168.2\"}, {\"price\":\"0.58\", \"size\":\"322\"}, {\"price\":\"0.57\", \"size\":\"410\"}, {\"price\":\"0.56\", \"size\":\"455.68\"}, {\"price\":\"0.55\", \"size\":\"172.95\"}], \"hash\":\"1d7fdb0a190da447456f0ffa39b65e775f0ba946\", \"timestamp\":\"1785126367331\", \"event_type\":\"book\"}","received_at":"2026-07-27T04:26:07.276408Z","replay_eligible":false,"resync_asset_ids":["60386828328910021732068595344565885737045900010034836345809386672230885527307"],"resync_asset_watermarks_ns":{"60386828328910021732068595344565885737045900010034836345809386672230885527307":1785126367331000000},"resync_buffered":true,"resync_status":"success","resync_watermark_ns":1785126367331000000,"schema_version":"clob-market-ws.book.v1","sequence":null,"server_hash":"1d7fdb0a190da447456f0ffa39b65e775f0ba946","server_timestamp":"1785126367331","session_id":"e9443c7415a0419799bee9cfbb1a9e4d","source":"clob_market_ws"},"received_at":"2026-07-27T04:26:07.276408Z","record_id":"7eaa0613303c4676ebc315e9fc7ad62ac14ceedcd50326fe2d7498deeb90b111","schema_fingerprint":"6fb926c284214b0f2180b64adc424d4b54a3140a5c6f65cf717c79545e1aa96a","schema_version":"edge-lab-recorder.raw.v1","sequence":null,"source":"clob_market_ws"}
{"event_at":"2026-07-27T04:26:07.443000Z","event_fingerprint":"6f1c5ac1c7659dc77e1d55f4ddae720343d9cc66ac535bd29986e17f9ef13d72","payload":{"connection_id":"0f4979d6978d463e9660b042fdcf555f","event_at":"2026-07-27T04:26:07.443000Z","event_type":"last_trade_price","frame_hash":"91a963d509b58e2e898bd8cc09cf865ba05895b36b6f9595b977745ddf98a8ee","frame_index":0,"kind":"data","monotonic_ns":228350673926625,"payload":{"asset_id":"60386828328910021732068595344565885737045900010034836345809386672230885527307","event_type":"last_trade_price","fee_rate_bps":"0","market":"0xeb66215f2e9faa6449e30a02bab5b8ed7b79a38bf961f6b24d0073c9c2419250","price":"0.55","side":"BUY","size":"20","timestamp":"1785126367443","transaction_hash":"0xdeea0b4174a1f9619286f2259ad96de57352755234bd427dce42b8e127f0082a"},"payload_hash":"8900fb11908bad46b34fa7a0e3f01c0dec611b9e5f40dca8f952356b540638fb","raw_frame":"{\"market\":\"0xeb66215f2e9faa6449e30a02bab5b8ed7b79a38bf961f6b24d0073c9c2419250\", \"asset_id\":\"60386828328910021732068595344565885737045900010034836345809386672230885527307\", \"price\":\"0.55\", \"size\":\"20\", \"fee_rate_bps\":\"0\", \"side\":\"BUY\", \"timestamp\":\"1785126367443\", \"event_type\":\"last_trade_price\", \"transaction_hash\":\"0xdeea0b4174a1f9619286f2259ad96de57352755234bd427dce42b8e127f0082a\"}","received_at":"2026-07-27T04:26:07.402066Z","replay_eligible":true,"resync_asset_ids":["60386828328910021732068595344565885737045900010034836345809386672230885527307"],"resync_asset_watermarks_ns":{"60386828328910021732068595344565885737045900010034836345809386672230885527307":1785126367331000000},"resync_buffered":true,"resync_status":"success","resync_watermark_ns":1785126367331000000,"schema_version":"clob-market-ws.last_trade_price.v1","sequence":null,"server_hash":null,"server_timestamp":"1785126367443","session_id":"e9443c7415a0419799bee9cfbb1a9e4d","source":"clob_market_ws"},"received_at":"2026-07-27T04:26:07.402066Z","record_id":"e59b003dbfda0086d0049b0850486713524d5c28b69621f432c0983c4e05f4e3","schema_fingerprint":"191733ba2ca53a565a77448e902c4805586c9424f99009817704dd636c1d5f9a","schema_version":"edge-lab-recorder.raw.v1","sequence":null,"source":"clob_market_ws"}
{"event_at":null,"event_fingerprint":"b3607fe5a3bab972787a7d07c0860be2805f459dcfaf076b9893a4859588169e","payload":{"connection_id":"0f4979d6978d463e9660b042fdcf555f","detail":{"asset_watermarks_ns":{"60386828328910021732068595344565885737045900010034836345809386672230885527307":1785126367331000000,"69697746896130839564035629862476347944307040470122503199396727085502753297492":1785126363605000000},"buffered_count":45,"connection_number":1,"watermark_ns":1785126367331000000},"event_type":"resync_complete","kind":"lifecycle","monotonic_ns":228352621088875,"received_at":"2026-07-27T04:26:09.349249Z","schema_version":"edge-lab-recorder.lifecycle.v1","session_id":"e9443c7415a0419799bee9cfbb1a9e4d","source":"clob_market_ws"},"received_at":"2026-07-27T04:26:09.349249Z","record_id":"a9d128f51c40110326e4e912a2a03c4b4c1fd6feb31a08b1ef3cf59faf1eab9f","schema_fingerprint":"227e2a2db42f2942ea7c91e46ecf8139a147064862b22af4c42edc2465172e38","schema_version":"edge-lab-recorder.raw.v1","sequence":null,"source":"clob_market_ws"}
