{"event_at":"2026-07-27T04:33:59.468000Z","event_fingerprint":"d23a0b69edc3f41dade0c8811d0d8c912936ce6576e16e8ec7bb1903b5bcaaf7","payload":{"connection_id":"0f4979d6978d463e9660b042fdcf555f","event_at":"2026-07-27T04:33:59.468000Z","event_type":"price_change","frame_hash":"52395556161daa17e249c7971d8f3070e24866487997ac3dafedf2f9ee7602e9","frame_index":0,"kind":"data","monotonic_ns":228822688748291,"payload":{"event_type":"price_change","market":"0xeb66215f2e9faa6449e30a02bab5b8ed7b79a38bf961f6b24d0073c9c2419250","price_changes":[{"asset_id":"60386828328910021732068595344565885737045900010034836345809386672230885527307","best_ask":"0.77","best_bid":"0.76","hash":"d94966b21808bd91c9fb9030f97953908fb3df9d","price":"0.55","side":"BUY","size":"42.35"},{"asset_id":"69697746896130839564035629862476347944307040470122503199396727085502753297492","best_ask":"0.24","best_bid":"0.23","hash":"486863a0d444a31116391b98e5bdf6207f138408","price":"0.45","side":"SELL","size":"42.35"}],"timestamp":"1785126839468"},"payload_hash":"a4666fb4d272dee1b97ad4652c71952c97eadacc00bca47da119906e9ad1a5cf","raw_frame":"{\"market\":\"0xeb66215f2e9faa6449e30a02bab5b8ed7b79a38bf961f6b24d0073c9c2419250\", \"price_changes\":[{\"asset_id\":\"60386828328910021732068595344565885737045900010034836345809386672230885527307\", \"price\":\"0.55\", \"size\":\"42.35\", \"side\":\"BUY\", \"hash\":\"d94966b21808bd91c9fb9030f97953908fb3df9d\", \"best_bid\":\"0.76\", \"best_ask\":\"0.77\"}, {\"asset_id\":\"69697746896130839564035629862476347944307040470122503199396727085502753297492\", \"price\":\"0.45\", \"size\":\"42.35\", \"side\":\"SELL\", \"hash\":\"486863a0d444a31116391b98e5bdf6207f138408\", \"best_bid\":\"0.23\", \"best_ask\":\"0.24\"}], \"timestamp\":\"1785126839468\", \"event_type\":\"price_change\"}","received_at":"2026-07-27T04:33:59.420983Z","schema_version":"clob-market-ws.price_change.v1","sequence":null,"server_hash":null,"server_timestamp":"1785126839468","session_id":"e9443c7415a0419799bee9cfbb1a9e4d","source":"clob_market_ws"},"received_at":"2026-07-27T04:33:59.420983Z","record_id":"ec985ddc499c63a29b94e88884f4319a8d09bc11ce5fa2d25dd14a3fa4c9f91a","schema_fingerprint":"4aa3821a28b0b7c2400bc59aba4bcc0a76e971dadd19610d3ad38c768e124dc7","schema_version":"edge-lab-recorder.raw.v1","sequence":null,"source":"clob_market_ws"}
{"event_at":"2026-07-27T04:33:59.469000Z","event_fingerprint":"9c503c4e09e3f8307d7594416062836842c8d19094586117e87034b2588b28dc","payload":{"connection_id":"0f4979d6978d463e9660b042fdcf555f","event_at":"2026-07-27T04:33:59.469000Z","event_type":"price_change","frame_hash":"76c1a92086850f702abff7109614e9597ce956c9c7aced60bd6ffd1c3d517f19","frame_index":0,"kind":"data","monotonic_ns":228822690982500,"payload":{"event_type":"price_change","market":"0xeb66215f2e9faa6449e30a02bab5b8ed7b79a38bf961f6b24d0073c9c2419250","price_changes":[{"asset_id":"60386828328910021732068595344565885737045900010034836345809386672230885527307","best_ask":"0.77","best_bid":"0.76","hash":"fb7be07febdf1cf6120b918effa1db0bd8aa3bda","price":"0.01","side":"BUY","size":"7703.02"},{"asset_id":"69697746896130839564035629862476347944307040470122503199396727085502753297492","best_ask":"0.24","best_bid":"0.23","hash":"bb4684d2c392bed3559bf35809387f0f8fc9d810","price":"0.99","side":"SELL","size":"7703.02"}],"timestamp":"1785126839469"},"payload_hash":"2bfa4c4be3bf3c9ab7c3c0f5a22b25cc6fc307bd9d532fcbb614b177851cb68d","raw_frame":"{\"market\":\"0xeb66215f2e9faa6449e30a02bab5b8ed7b79a38bf961f6b24d0073c9c2419250\", \"price_changes\":[{\"asset_id\":\"60386828328910021732068595344565885737045900010034836345809386672230885527307\", \"price\":\"0.01\", \"size\":\"7703.02\", \"side\":\"BUY\", \"hash\":\"fb7be07febdf1cf6120b918effa1db0bd8aa3bda\", \"best_bid\":\"0.76\", \"best_ask\":\"0.77\"}, {\"asset_id\":\"69697746896130839564035629862476347944307040470122503199396727085502753297492\", \"price\":\"0.99\", \"size\":\"7703.02\", \"side\":\"SELL\", \"hash\":\"bb4684d2c392bed3559bf35809387f0f8fc9d810\", \"best_bid\":\"0.23\", \"best_ask\":\"0.24\"}], \"timestamp\":\"1785126839469\", \"event_type\":\"price_change\"}","received_at":"2026-07-27T04:33:59.423220Z","schema_version":"clob-market-ws.price_change.v1","sequence":null,"server_hash":null,"server_timestamp":"1785126839469","session_id":"e9443c7415a0419799bee9cfbb1a9e4d","source":"clob_market_ws"},"received_at":"2026-07-27T04:33:59.423220Z","record_id":"73a9440ce68685842eb5f0a5623263eb393a6f79cebc4c782665833b606a3cf1","schema_fingerprint":"4aa3821a28b0b7c2400bc59aba4bcc0a76e971dadd19610d3ad38c768e124dc7","schema_version":"edge-lab-recorder.raw.v1","sequence":null,"source":"clob_market_ws"}
{"event_at":"2026-07-27T04:33:59.494000Z","event_fingerprint":"34f7bb2715839e512dcb1cd83a74800784566fa5bc448a8c8b3c0f7b3b2abd9c","payload":{"connection_id":"0f4979d6978d463e9660b042fdcf555f","event_at":"2026-07-27T04:33:59.494000Z","event_type":"price_change","frame_hash":"df423c3e2b40a94db4fb1b9fc9aed41da70acf8018046d1632939d526cf508dc","frame_index":0,"kind":"data","monotonic_ns":228822706655791,"payload":{"event_type":"price_change","market":"0xeb66215f2e9faa6449e30a02bab5b8ed7b79a38bf961f6b24d0073c9c2419250","price_changes":[{"asset_id":"60386828328910021732068595344565885737045900010034836345809386672230885527307","best_ask":"0.77","best_bid":"0.76","hash":"cae178b21edfa18ee4dc911ea7fa1787d516a7e4","price":"0.03","side":"BUY","size":"643.1"},{"asset_id":"69697746896130839564035629862476347944307040470122503199396727085502753297492","best_ask":"0.24","best_bid":"0.23","hash":"6713a44b5509b76912ed2586d01b25991bd4c702","price":"0.97","side":"SELL","size":"643.1"}],"timestamp":"1785126839494"},"payload_hash":"907ae2f234ec917636a99af42b178269672b8dc083c9fe614d50363017c9d17b","raw_frame":"{\"market\":\"0xeb66215f2e9faa6449e30a02bab5b8ed7b79a38bf961f6b24d0073c9c2419250\", \"price_changes\":[{\"asset_id\":\"60386828328910021732068595344565885737045900010034836345809386672230885527307\", \"price\":\"0.03\", \"size\":\"643.1\", \"side\":\"BUY\", \"hash\":\"cae178b21edfa18ee4dc911ea7fa1787d516a7e4\", \"best_bid\":\"0.76\", \"best_ask\":\"0.77\"}, {\"asset_id\":\"69697746896130839564035629862476347944307040470122503199396727085502753297492\", \"price\":\"0.97\", \"size\":\"643.1\", \"side\":\"SELL\", \"hash\":\"6713a44b5509b76912ed2586d01b25991bd4c702\", \"best_bid\":\"0.23\", \"best_ask\":\"0.24\"}], \"timestamp\":\"1785126839494\", \"event_type\":\"price_change\"}","received_at":"2026-07-27T04:33:59.438890Z","schema_version":"clob-market-ws.price_change.v1","sequence":null,"server_hash":null,"server_timestamp":"1785126839494","session_id":"e9443c7415a0419799bee9cfbb1a9e4d","source":"clob_market_ws"},"received_at":"2026-07-27T04:33:59.438890Z","record_id":"1a715146538a632ac96f2c721ee851543734de4b865d89affbab8f0774b203f4","schema_fingerprint":"4aa3821a28b0b7c2400bc59aba4bcc0a76e971dadd19610d3ad38c768e124dc7","schema_version":"edge-lab-recorder.raw.v1","sequence":null,"source":"clob_market_ws"}
{"event_at":"2026-07-27T04:33:59.511000Z","event_fingerprint":"ca5ad0e13310525d4f60e399f5251e6e10cb963be06c222d5999ffb7b0acc7e9","payload":{"connection_id":"0f4979d6978d463e9660b042fdcf555f","event_at":"2026-07-27T04:33:59.511000Z","event_type":"price_change","frame_hash":"29eaf6546f5ac8a5f562d017f6c55dcd7af43384e4740ffd157e36e6d54aa15d","frame_index":0,"kind":"data","monotonic_ns":228822727799250,"payload":{"event_type":"price_change","market":"0xeb66215f2e9faa6449e30a02bab5b8ed7b79a38bf961f6b24d0073c9c2419250","price_changes":[{"asset_id":"69697746896130839564035629862476347944307040470122503199396727085502753297492","best_ask":"0.24","best_bid":"0.23","hash":"8bdd76694bacc1177a878a50af383ae37f0e15ab","price":"0.2","side":"BUY","size":"51.31"},{"asset_id":"60386828328910021732068595344565885737045900010034836345809386672230885527307","best_ask":"0.77","best_bid":"0.76","hash":"355668bc3b3845ddfeb28da18ffcc050007737fc","price":"0.8","side":"SELL","size":"51.31"}],"timestamp":"1785126839511"},"payload_hash":"0ad89cd762eacde33c6f1451b6c2c731f01ee1e7a7364d54d256a87f3927cb17","raw_frame":"{\"market\":\"0xeb66215f2e9faa6449e30a02bab5b8ed7b79a38bf961f6b24d0073c9c2419250\", \"price_changes\":[{\"asset_id\":\"69697746896130839564035629862476347944307040470122503199396727085502753297492\", \"price\":\"0.2\", \"size\":\"51.31\", \"side\":\"BUY\", \"hash\":\"8bdd76694bacc1177a878a50af383ae37f0e15ab\", \"best_bid\":\"0.23\", \"best_ask\":\"0.24\"}, {\"asset_id\":\"60386828328910021732068595344565885737045900010034836345809386672230885527307\", \"price\":\"0.8\", \"size\":\"51.31\", \"side\":\"SELL\", \"hash\":\"355668bc3b3845ddfeb28da18ffcc050007737fc\", \"best_bid\":\"0.76\", \"best_ask\":\"0.77\"}], \"timestamp\":\"1785126839511\", \"event_type\":\"price_change\"}","received_at":"2026-07-27T04:33:59.460035Z","schema_version":"clob-market-ws.price_change.v1","sequence":null,"server_hash":null,"server_timestamp":"1785126839511","session_id":"e9443c7415a0419799bee9cfbb1a9e4d","source":"clob_market_ws"},"received_at":"2026-07-27T04:33:59.460035Z","record_id":"04ff0c619b05d711b807b176e74abd0014246f9753aa3f88429842fa2545bab7","schema_fingerprint":"4aa3821a28b0b7c2400bc59aba4bcc0a76e971dadd19610d3ad38c768e124dc7","schema_version":"edge-lab-recorder.raw.v1","sequence":null,"source":"clob_market_ws"}
{"event_at":"2026-07-27T04:33:59.512000Z","event_fingerprint":"1aefcd6b61402713f402010081926789f972a50954bc4c7eac47d3ed02ed0300","payload":{"connection_id":"0f4979d6978d463e9660b042fdcf555f","event_at":"2026-07-27T04:33:59.512000Z","event_type":"price_change","frame_hash":"4e77d71e871e0aa4f16fb1e39487610856b33c5a6f9b8e8e9718f3b8c3faaa3e","frame_index":0,"kind":"data","monotonic_ns":228822729478750,"payload":{"event_type":"price_change","market":"0xeb66215f2e9faa6449e30a02bab5b8ed7b79a38bf961f6b24d0073c9c2419250","price_changes":[{"asset_id":"60386828328910021732068595344565885737045900010034836345809386672230885527307","best_ask":"0.77","best_bid":"0.76","hash":"a90d741361b266a4db2b4defdfb143e1caab422c","price":"0.77","side":"SELL","size":"401"},{"asset_id":"69697746896130839564035629862476347944307040470122503199396727085502753297492","best_ask":"0.24","best_bid":"0.23","hash":"39eb499957a3850488dcc45f6895e9044959a06a","price":"0.23","side":"BUY","size":"401"}],"timestamp":"1785126839512"},"payload_hash":"59cf823b5b57ff4c53f2496054c64532ff8412d214e8127b46e828d275521ab0","raw_frame":"{\"market\":\"0xeb66215f2e9faa6449e30a02bab5b8ed7b79a38bf961f6b24d0073c9c2419250\", \"price_changes\":[{\"asset_id\":\"60386828328910021732068595344565885737045900010034836345809386672230885527307\", \"price\":\"0.77\", \"size\":\"401\", \"side\":\"SELL\", \"hash\":\"a90d741361b266a4db2b4defdfb143e1caab422c\", \"best_bid\":\"0.76\", \"best_ask\":\"0.77\"}, {\"asset_id\":\"69697746896130839564035629862476347944307040470122503199396727085502753297492\", \"price\":\"0.23\", \"size\":\"401\", \"side\":\"BUY\", \"hash\":\"39eb499957a3850488dcc45f6895e9044959a06a\", \"best_bid\":\"0.23\", \"best_ask\":\"0.24\"}], \"timestamp\":\"1785126839512\", \"event_type\":\"price_change\"}","received_at":"2026-07-27T04:33:59.461716Z","schema_version":"clob-market-ws.price_change.v1","sequence":null,"server_hash":null,"server_timestamp":"1785126839512","session_id":"e9443c7415a0419799bee9cfbb1a9e4d","source":"clob_market_ws"},"received_at":"2026-07-27T04:33:59.461716Z","record_id":"bc5297d4a9f25801366e4e9cf2d1ef6f0fc9ed4f04c7d1f5f676bdcb44195cbc","schema_fingerprint":"4aa3821a28b0b7c2400bc59aba4bcc0a76e971dadd19610d3ad38c768e124dc7","schema_version":"edge-lab-recorder.raw.v1","sequence":null,"source":"clob_market_ws"}
{"event_at":"2026-07-27T04:33:59.516000Z","event_fingerprint":"46da1ff741c47615c6be2a9a039c6186b13373cb87947ef345e6b395727a8423","payload":{"connection_id":"0f4979d6978d463e9660b042fdcf555f","event_at":"2026-07-27T04:33:59.516000Z","event_type":"price_change","frame_hash":"f3e26dffdcc04ed59a67551fbdb238885e1ef4cf51c95b7ea92f68eb246e88c1","frame_index":0,"kind":"data","monotonic_ns":228822731213500,"payload":{"event_type":"price_change","market":"0xeb66215f2e9faa6449e30a02bab5b8ed7b79a38bf961f6b24d0073c9c2419250","price_changes":[{"asset_id":"60386828328910021732068595344565885737045900010034836345809386672230885527307","best_ask":"0.77","best_bid":"0.76","hash":"384ef5fffb5e72dc53f331a276d9999793b0b157","price":"0.77","side":"SELL","size":"396"},{"asset_id":"69697746896130839564035629862476347944307040470122503199396727085502753297492","best_ask":"0.24","best_bid":"0.23","hash":"03abfc7c308085c6c398440fe1370f7ce7d50dd8","price":"0.23","side":"BUY","size":"396"}],"timestamp":"1785126839516"},"payload_hash":"7ec77014b988d2098fb8876a1d9afae42a9fe5cd9323fb86d6048b3e6c532c7b","raw_frame":"{\"market\":\"0xeb66215f2e9faa6449e30a02bab5b8ed7b79a38bf961f6b24d0073c9c2419250\", \"price_changes\":[{\"asset_id\":\"60386828328910021732068595344565885737045900010034836345809386672230885527307\", \"price\":\"0.77\", \"size\":\"396\", \"side\":\"SELL\", \"hash\":\"384ef5fffb5e72dc53f331a276d9999793b0b157\", \"best_bid\":\"0.76\", \"best_ask\":\"0.77\"}, {\"asset_id\":\"69697746896130839564035629862476347944307040470122503199396727085502753297492\", \"price\":\"0.23\", \"size\":\"396\", \"side\":\"BUY\", \"hash\":\"03abfc7c308085c6c398440fe1370f7ce7d50dd8\", \"best_bid\":\"0.23\", \"best_ask\":\"0.24\"}], \"timestamp\":\"1785126839516\", \"event_type\":\"price_change\"}","received_at":"2026-07-27T04:33:59.463451Z","schema_version":"clob-market-ws.price_change.v1","sequence":null,"server_hash":null,"server_timestamp":"1785126839516","session_id":"e9443c7415a0419799bee9cfbb1a9e4d","source":"clob_market_ws"},"received_at":"2026-07-27T04:33:59.463451Z","record_id":"9aaf767a5df4d202039e2c922d2a537006fb9f8137dda182ab2d0e9f81013f49","schema_fingerprint":"4aa3821a28b0b7c2400bc59aba4bcc0a76e971dadd19610d3ad38c768e124dc7","schema_version":"edge-lab-recorder.raw.v1","sequence":null,"source":"clob_market_ws"}
{"event_at":"2026-07-27T04:33:59.522000Z","event_fingerprint":"fa71fa9dfe0fee6589e5f61ef93c1c3b766068f04aef26cfd050e2d8d6a06d63","payload":{"connection_id":"0f4979d6978d463e9660b042fdcf555f","event_at":"2026-07-27T04:33:59.522000Z","event_type":"price_change","frame_hash":"07c61ab1730c9644e367d7a90c6adb6f000fa86ffc8687310f55c4da46af5077","frame_index":0,"kind":"data","monotonic_ns":228822733482500,"payload":{"event_type":"price_change","market":"0xeb66215f2e9faa6449e30a02bab5b8ed7b79a38bf961f6b24d0073c9c2419250","price_changes":[{"asset_id":"60386828328910021732068595344565885737045900010034836345809386672230885527307","best_ask":"0.77","best_bid":"0.76","hash":"e4ece9f01001344cffebf68c0798fa155ea8064c","price":"0.71","side":"BUY","size":"37.02"},{"asset_id":"69697746896130839564035629862476347944307040470122503199396727085502753297492","best_ask":"0.24","best_bid":"0.23","hash":"0d0f3ae3d98c6eedddfeacb1a76b34821c7a118d","price":"0.29","side":"SELL","size":"37.02"}],"timestamp":"1785126839522"},"payload_hash":"d56dba524d3ae417853a3500b707fcdf4a11516937155b8329b91c0d46a37423","raw_frame":"{\"market\":\"0xeb66215f2e9faa6449e30a02bab5b8ed7b79a38bf961f6b24d0073c9c2419250\", \"price_changes\":[{\"asset_id\":\"60386828328910021732068595344565885737045900010034836345809386672230885527307\", \"price\":\"0.71\", \"size\":\"37.02\", \"side\":\"BUY\", \"hash\":\"e4ece9f01001344cffebf68c0798fa155ea8064c\", \"best_bid\":\"0.76\", \"best_ask\":\"0.77\"}, {\"asset_id\":\"69697746896130839564035629862476347944307040470122503199396727085502753297492\", \"price\":\"0.29\", \"size\":\"37.02\", \"side\":\"SELL\", \"hash\":\"0d0f3ae3d98c6eedddfeacb1a76b34821c7a118d\", \"best_bid\":\"0.23\", \"best_ask\":\"0.24\"}], \"timestamp\":\"1785126839522\", \"event_type\":\"price_change\"}","received_at":"2026-07-27T04:33:59.465726Z","schema_version":"clob-market-ws.price_change.v1","sequence":null,"server_hash":null,"server_timestamp":"1785126839522","session_id":"e9443c7415a0419799bee9cfbb1a9e4d","source":"clob_market_ws"},"received_at":"2026-07-27T04:33:59.465726Z","record_id":"442745826865d8153647975166cc63acc2dec022f1a0abfe9cb94f19f89998cc","schema_fingerprint":"4aa3821a28b0b7c2400bc59aba4bcc0a76e971dadd19610d3ad38c768e124dc7","schema_version":"edge-lab-recorder.raw.v1","sequence":null,"source":"clob_market_ws"}
{"event_at":"2026-07-27T04:33:59.522000Z","event_fingerprint":"b5d9f746e9dc0fc4f379b69da1880661adcfc522e7b0cf5933c3488ad9691779","payload":{"connection_id":"0f4979d6978d463e9660b042fdcf555f","event_at":"2026-07-27T04:33:59.522000Z","event_type":"price_change","frame_hash":"3ac9929c387c00d3b9a0aa0334427ae691d074d77abfdb3a9e5897cc4eb0b851","frame_index":0,"kind":"data","monotonic_ns":228822734071583,"payload":{"event_type":"price_change","market":"0xeb66215f2e9faa6449e30a02bab5b8ed7b79a38bf961f6b24d0073c9c2419250","price_changes":[{"asset_id":"69697746896130839564035629862476347944307040470122503199396727085502753297492","best_ask":"0.24","best_bid":"0.23","hash":"0d0f3ae3d98c6eedddfeacb1a76b34821c7a118d","price":"0.22","side":"BUY","size":"9.6"},{"asset_id":"60386828328910021732068595344565885737045900010034836345809386672230885527307","best_ask":"0.77","best_bid":"0.76","hash":"e4ece9f01001344cffebf68c0798fa155ea8064c","price":"0.78","side":"SELL","size":"9.6"}],"timestamp":"1785126839522"},"payload_hash":"28ec27f4ef58f3a402a1248050000a829547a3289b9ab9a629be3e6c4e0157ab","raw_frame":"{\"market\":\"0xeb66215f2e9faa6449e30a02bab5b8ed7b79a38bf961f6b24d0073c9c2419250\", \"price_changes\":[{\"asset_id\":\"69697746896130839564035629862476347944307040470122503199396727085502753297492\", \"price\":\"0.22\", \"size\":\"9.6\", \"side\":\"BUY\", \"hash\":\"0d0f3ae3d98c6eedddfeacb1a76b34821c7a118d\", \"best_bid\":\"0.23\", \"best_ask\":\"0.24\"}, {\"asset_id\":\"60386828328910021732068595344565885737045900010034836345809386672230885527307\", \"price\":\"0.78\", \"size\":\"9.6\", \"side\":\"SELL\", \"hash\":\"e4ece9f01001344cffebf68c0798fa155ea8064c\", \"best_bid\":\"0.76\", \"best_ask\":\"0.77\"}], \"timestamp\":\"1785126839522\", \"event_type\":\"price_change\"}","received_at":"2026-07-27T04:33:59.466317Z","schema_version":"clob-market-ws.price_change.v1","sequence":null,"server_hash":null,"server_timestamp":"1785126839522","session_id":"e9443c7415a0419799bee9cfbb1a9e4d","source":"clob_market_ws"},"received_at":"2026-07-27T04:33:59.466317Z","record_id":"2be9f19b638b1e841c7d9d149203e90908b81aa9c7b89148e00ed9c6d0bfec4c","schema_fingerprint":"4aa3821a28b0b7c2400bc59aba4bcc0a76e971dadd19610d3ad38c768e124dc7","schema_version":"edge-lab-recorder.raw.v1","sequence":null,"source":"clob_market_ws"}
{"event_at":"2026-07-27T04:33:59.546000Z","event_fingerprint":"c534a2d64dc647c6e3362b6e56a3fd9cfa7d98a49bdf1c8c493f74699d1ff2f5","payload":{"connection_id":"0f4979d6978d463e9660b042fdcf555f","event_at":"2026-07-27T04:33:59.546000Z","event_type":"price_change","frame_hash":"16f4227c7ef37f666adfd61196ec6420640977c7263de4344657ccb9a45ac50e","frame_index":0,"kind":"data","monotonic_ns":228822758693875,"payload":{"event_type":"price_change","market":"0xeb66215f2e9faa6449e30a02bab5b8ed7b79a38bf961f6b24d0073c9c2419250","price_changes":[{"asset_id":"69697746896130839564035629862476347944307040470122503199396727085502753297492","best_ask":"0.24","best_bid":"0.23","hash":"40a680fb894031252994b1aa7a89622576afba71","price":"0.21","side":"BUY","size":"66.6"},{"asset_id":"60386828328910021732068595344565885737045900010034836345809386672230885527307","best_ask":"0.77","best_bid":"0.76","hash":"477384f2088d19b38ca11dc9fc12ecfe06599fe2","price":"0.79","side":"SELL","size":"66.6"}],"timestamp":"1785126839546"},"payload_hash":"350490ec840266230357887a39d90d09c7445075323bf2a725cfb5de58eeb91f","raw_frame":"{\"market\":\"0xeb66215f2e9faa6449e30a02bab5b8ed7b79a38bf961f6b24d0073c9c2419250\", \"price_changes\":[{\"asset_id\":\"69697746896130839564035629862476347944307040470122503199396727085502753297492\", \"price\":\"0.21\", \"size\":\"66.6\", \"side\":\"BUY\", \"hash\":\"40a680fb894031252994b1aa7a89622576afba71\", \"best_bid\":\"0.23\", \"best_ask\":\"0.24\"}, {\"asset_id\":\"60386828328910021732068595344565885737045900010034836345809386672230885527307\", \"price\":\"0.79\", \"size\":\"66.6\", \"side\":\"SELL\", \"hash\":\"477384f2088d19b38ca11dc9fc12ecfe06599fe2\", \"best_bid\":\"0.76\", \"best_ask\":\"0.77\"}], \"timestamp\":\"1785126839546\", \"event_type\":\"price_change\"}","received_at":"2026-07-27T04:33:59.490923Z","schema_version":"clob-market-ws.price_change.v1","sequence":null,"server_hash":null,"server_timestamp":"1785126839546","session_id":"e9443c7415a0419799bee9cfbb1a9e4d","source":"clob_market_ws"},"received_at":"2026-07-27T04:33:59.490923Z","record_id":"c2c1a14884aa2bd025abbf8b213830892cbd3fc0b9b63ca4582371faba3d5252","schema_fingerprint":"4aa3821a28b0b7c2400bc59aba4bcc0a76e971dadd19610d3ad38c768e124dc7","schema_version":"edge-lab-recorder.raw.v1","sequence":null,"source":"clob_market_ws"}
{"event_at":"2026-07-27T04:33:59.549000Z","event_fingerprint":"ba70ea63c80a7d3376ecc96e59266e956e7abdb48589ad7267017e97f1db4ae4","payload":{"connection_id":"0f4979d6978d463e9660b042fdcf555f","event_at":"2026-07-27T04:33:59.549000Z","event_type":"price_change","frame_hash":"2860b6a203ddb3fe783a0d03643d4eadbf73de8d54a53226009885dd0e32c2d7","frame_index":0,"kind":"data","monotonic_ns":228822760876458,"payload":{"event_type":"price_change","market":"0xeb66215f2e9faa6449e30a02bab5b8ed7b79a38bf961f6b24d0073c9c2419250","price_changes":[{"asset_id":"60386828328910021732068595344565885737045900010034836345809386672230885527307","best_ask":"0.77","best_bid":"0.76","hash":"658a531d034bbde1fab04500d32d0369a1dccf5a","price":"0.72","side":"BUY","size":"32.2"},{"asset_id":"69697746896130839564035629862476347944307040470122503199396727085502753297492","best_ask":"0.24","best_bid":"0.23","hash":"717869ba94c1256e884723050c93d8854061941f","price":"0.28","side":"SELL","size":"32.2"}],"timestamp":"1785126839549"},"payload_hash":"9e553d6954dace985b5f6a82fe80cf94c3af8d9c328cae49152ff1d8a057c9b2","raw_frame":"{\"market\":\"0xeb66215f2e9faa6449e30a02bab5b8ed7b79a38bf961f6b24d0073c9c2419250\", \"price_changes\":[{\"asset_id\":\"60386828328910021732068595344565885737045900010034836345809386672230885527307\", \"price\":\"0.72\", \"size\":\"32.2\", \"side\":\"BUY\", \"hash\":\"658a531d034bbde1fab04500d32d0369a1dccf5a\", \"best_bid\":\"0.76\", \"best_ask\":\"0.77\"}, {\"asset_id\":\"69697746896130839564035629862476347944307040470122503199396727085502753297492\", \"price\":\"0.28\", \"size\":\"32.2\", \"side\":\"SELL\", \"hash\":\"717869ba94c1256e884723050c93d8854061941f\", \"best_bid\":\"0.23\", \"best_ask\":\"0.24\"}], \"timestamp\":\"1785126839549\", \"event_type\":\"price_change\"}","received_at":"2026-07-27T04:33:59.493109Z","schema_version":"clob-market-ws.price_change.v1","sequence":null,"server_hash":null,"server_timestamp":"1785126839549","session_id":"e9443c7415a0419799bee9cfbb1a9e4d","source":"clob_market_ws"},"received_at":"2026-07-27T04:33:59.493109Z","record_id":"fa43eda4495120dcfb93b96b3ee1e456750502b04e82a23ed43255d732f9b397","schema_fingerprint":"4aa3821a28b0b7c2400bc59aba4bcc0a76e971dadd19610d3ad38c768e124dc7","schema_version":"edge-lab-recorder.raw.v1","sequence":null,"source":"clob_market_ws"}
{"event_at":"2026-07-27T04:33:59.559000Z","event_fingerprint":"a8ee174dd72dc1d26011c626a25d70242a57adc2109ecada0154943ab5716a91","payload":{"connection_id":"0f4979d6978d463e9660b042fdcf555f","event_at":"2026-07-27T04:33:59.559000Z","event_type":"price_change","frame_hash":"4767571f6ab3ad6d0b9070581aea0bb854b3bf1fbabcef4da955794740e15619","frame_index":0,"kind":"data","monotonic_ns":228822770918833,"payload":{"event_type":"price_change","market":"0xeb66215f2e9faa6449e30a02bab5b8ed7b79a38bf961f6b24d0073c9c2419250","price_changes":[{"asset_id":"69697746896130839564035629862476347944307040470122503199396727085502753297492","best_ask":"0.24","best_bid":"0.23","hash":"4c4827b3e044ef22f13fa1c84f9c17e2ecab3936","price":"0.27","side":"SELL","size":"378.02"},{"asset_id":"60386828328910021732068595344565885737045900010034836345809386672230885527307","best_ask":"0.77","best_bid":"0.76","hash":"39f6d1189e2c2207c65ea59f5ecb241e5808a86c","price":"0.73","side":"BUY","size":"378.02"}],"timestamp":"1785126839559"},"payload_hash":"ffb354bd28ccc3d55e188191f3cd71262a6c81d9317cae42d594d49b8f9c83a2","raw_frame":"{\"market\":\"0xeb66215f2e9faa6449e30a02bab5b8ed7b79a38bf961f6b24d0073c9c2419250\", \"price_changes\":[{\"asset_id\":\"69697746896130839564035629862476347944307040470122503199396727085502753297492\", \"price\":\"0.27\", \"size\":\"378.02\", \"side\":\"SELL\", \"hash\":\"4c4827b3e044ef22f13fa1c84f9c17e2ecab3936\", \"best_bid\":\"0.23\", \"best_ask\":\"0.24\"}, {\"asset_id\":\"60386828328910021732068595344565885737045900010034836345809386672230885527307\", \"price\":\"0.73\", \"size\":\"378.02\", \"side\":\"BUY\", \"hash\":\"39f6d1189e2c2207c65ea59f5ecb241e5808a86c\", \"best_bid\":\"0.76\", \"best_ask\":\"0.77\"}], \"timestamp\":\"1785126839559\", \"event_type\":\"price_change\"}","received_at":"2026-07-27T04:33:59.503157Z","schema_version":"clob-market-ws.price_change.v1","sequence":null,"server_hash":null,"server_timestamp":"1785126839559","session_id":"e9443c7415a0419799bee9cfbb1a9e4d","source":"clob_market_ws"},"received_at":"2026-07-27T04:33:59.503157Z","record_id":"bb6d3f0fb18e823d37da3d48598345b22adf1fefb9ab3ae44064a7a830d1dd08","schema_fingerprint":"4aa3821a28b0b7c2400bc59aba4bcc0a76e971dadd19610d3ad38c768e124dc7","schema_version":"edge-lab-recorder.raw.v1","sequence":null,"source":"clob_market_ws"}
{"event_at":"2026-07-27T04:33:59.561000Z","event_fingerprint":"ec29fe252ccdcadd920a7f65463b98330388d290bed4eee355f0a0a266f070b5","payload":{"connection_id":"0f4979d6978d463e9660b042fdcf555f","event_at":"2026-07-27T04:33:59.561000Z","event_type":"price_change","frame_hash":"d70623fba94eab1e56a4018fa991d5cf29c55935e45233ee92469b88ae054aa1","frame_index":0,"kind":"data","monotonic_ns":228822773690500,"payload":{"event_type":"price_change","market":"0xeb66215f2e9faa6449e30a02bab5b8ed7b79a38bf961f6b24d0073c9c2419250","price_changes":[{"asset_id":"60386828328910021732068595344565885737045900010034836345809386672230885527307","best_ask":"0.77","best_bid":"0.76","hash":"99cdf157845d9343e84648329876ec107039913a","price":"0.8","side":"SELL","size":"46.27"},{"asset_id":"69697746896130839564035629862476347944307040470122503199396727085502753297492","best_ask":"0.24","best_bid":"0.23","hash":"86f6c5ad9285d8b67bf7ce64f28bd51ffd6ab477","price":"0.2","side":"BUY","size":"46.27"}],"timestamp":"1785126839561"},"payload_hash":"98085a7f048fe5ecf52396a818c9209d2af1a94e5544180bdf43e1f15074d81e","raw_frame":"{\"market\":\"0xeb66215f2e9faa6449e30a02bab5b8ed7b79a38bf961f6b24d0073c9c2419250\", \"price_changes\":[{\"asset_id\":\"60386828328910021732068595344565885737045900010034836345809386672230885527307\", \"price\":\"0.8\", \"size\":\"46.27\", \"side\":\"SELL\", \"hash\":\"99cdf157845d9343e84648329876ec107039913a\", \"best_bid\":\"0.76\", \"best_ask\":\"0.77\"}, {\"asset_id\":\"69697746896130839564035629862476347944307040470122503199396727085502753297492\", \"price\":\"0.2\", \"size\":\"46.27\", \"side\":\"BUY\", \"hash\":\"86f6c5ad9285d8b67bf7ce64f28bd51ffd6ab477\", \"best_bid\":\"0.23\", \"best_ask\":\"0.24\"}], \"timestamp\":\"1785126839561\", \"event_type\":\"price_change\"}","received_at":"2026-07-27T04:33:59.505929Z","schema_version":"clob-market-ws.price_change.v1","sequence":null,"server_hash":null,"server_timestamp":"1785126839561","session_id":"e9443c7415a0419799bee9cfbb1a9e4d","source":"clob_market_ws"},"received_at":"2026-07-27T04:33:59.505929Z","record_id":"9197f135188a4a00d8f7a76d974a8714125dd5893dfa7d13af2f12a3d4566339","schema_fingerprint":"4aa3821a28b0b7c2400bc59aba4bcc0a76e971dadd19610d3ad38c768e124dc7","schema_version":"edge-lab-recorder.raw.v1","sequence":null,"source":"clob_market_ws"}
{"event_at":"2026-07-27T04:33:59.568000Z","event_fingerprint":"13920e05e5c54244f88944555816bc8600e52d521a04243b1991521f24f1a14f","payload":{"connection_id":"0f4979d6978d463e9660b042fdcf555f","event_at":"2026-07-27T04:33:59.568000Z","event_type":"price_change","frame_hash":"3c3f51f02fcad48b12175baaf6c4016a8ef8fa70cd9ea6220f576accd14dfafc","frame_index":0,"kind":"data","monotonic_ns":228822780660083,"payload":{"event_type":"price_change","market":"0xeb66215f2e9faa6449e30a02bab5b8ed7b79a38bf961f6b24d0073c9c2419250","price_changes":[{"asset_id":"60386828328910021732068595344565885737045900010034836345809386672230885527307","best_ask":"0.77","best_bid":"0.76","hash":"afcaa509dcad3d41e3a94aa8155936fd3a03f841","price":"0.73","side":"BUY","size":"409.06"},{"asset_id":"69697746896130839564035629862476347944307040470122503199396727085502753297492","best_ask":"0.24","best_bid":"0.23","hash":"247bcbf564becaebe09c4f6b84aa5665d4c6150c","price":"0.27","side":"SELL","size":"409.06"}],"timestamp":"1785126839568"},"payload_hash":"9c465ad2ec3b07dfd54ba17332c4d2625c351763f5396b79310496b29c825ad4","raw_frame":"{\"market\":\"0xeb66215f2e9faa6449e30a02bab5b8ed7b79a38bf961f6b24d0073c9c2419250\", \"price_changes\":[{\"asset_id\":\"60386828328910021732068595344565885737045900010034836345809386672230885527307\", \"price\":\"0.73\", \"size\":\"409.06\", \"side\":\"BUY\", \"hash\":\"afcaa509dcad3d41e3a94aa8155936fd3a03f841\", \"best_bid\":\"0.76\", \"best_ask\":\"0.77\"}, {\"asset_id\":\"69697746896130839564035629862476347944307040470122503199396727085502753297492\", \"price\":\"0.27\", \"size\":\"409.06\", \"side\":\"SELL\", \"hash\":\"247bcbf564becaebe09c4f6b84aa5665d4c6150c\", \"best_bid\":\"0.23\", \"best_ask\":\"0.24\"}], \"timestamp\":\"1785126839568\", \"event_type\":\"price_change\"}","received_at":"2026-07-27T04:33:59.512898Z","schema_version":"clob-market-ws.price_change.v1","sequence":null,"server_hash":null,"server_timestamp":"1785126839568","session_id":"e9443c7415a0419799bee9cfbb1a9e4d","source":"clob_market_ws"},"received_at":"2026-07-27T04:33:59.512898Z","record_id":"722b2e5688574cedaa345f2b0fb81ef07384af1344d63034e4f0571d7d51df09","schema_fingerprint":"4aa3821a28b0b7c2400bc59aba4bcc0a76e971dadd19610d3ad38c768e124dc7","schema_version":"edge-lab-recorder.raw.v1","sequence":null,"source":"clob_market_ws"}
{"event_at":"2026-07-27T04:33:59.572000Z","event_fingerprint":"6353b5b0637dae65509681fe167eaa4836a2a0d6a66df4bb386e45cb2567ccff","payload":{"connection_id":"0f4979d6978d463e9660b042fdcf555f","event_at":"2026-07-27T04:33:59.572000Z","event_type":"price_change","frame_hash":"0addc9eb75af863bbed933b7d4ef4f11344cb44c219fb0fb481579d7efca4d68","frame_index":0,"kind":"data","monotonic_ns":228822786041083,"payload":{"event_type":"price_change","market":"0xeb66215f2e9faa6449e30a02bab5b8ed7b79a38bf961f6b24d0073c9c2419250","price_changes":[{"asset_id":"60386828328910021732068595344565885737045900010034836345809386672230885527307","best_ask":"0.77","best_bid":"0.76","hash":"4b83ee0b1dd0d60705041074091a334c47a4af54","price":"0.03","side":"BUY","size":"648.1"},{"asset_id":"69697746896130839564035629862476347944307040470122503199396727085502753297492","best_ask":"0.24","best_bid":"0.23","hash":"12a2f262df4efeeeb2a74aad4f66dd7a5488c992","price":"0.97","side":"SELL","size":"648.1"}],"timestamp":"1785126839572"},"payload_hash":"7ea4d8357764e93c99ee72cfc27758495b78155ba5f553c71a32684335d70bb1","raw_frame":"{\"market\":\"0xeb66215f2e9faa6449e30a02bab5b8ed7b79a38bf961f6b24d0073c9c2419250\", \"price_changes\":[{\"asset_id\":\"60386828328910021732068595344565885737045900010034836345809386672230885527307\", \"price\":\"0.03\", \"size\":\"648.1\", \"side\":\"BUY\", \"hash\":\"4b83ee0b1dd0d60705041074091a334c47a4af54\", \"best_bid\":\"0.76\", \"best_ask\":\"0.77\"}, {\"asset_id\":\"69697746896130839564035629862476347944307040470122503199396727085502753297492\", \"price\":\"0.97\", \"size\":\"648.1\", \"side\":\"SELL\", \"hash\":\"12a2f262df4efeeeb2a74aad4f66dd7a5488c992\", \"best_bid\":\"0.23\", \"best_ask\":\"0.24\"}], \"timestamp\":\"1785126839572\", \"event_type\":\"price_change\"}","received_at":"2026-07-27T04:33:59.518276Z","schema_version":"clob-market-ws.price_change.v1","sequence":null,"server_hash":null,"server_timestamp":"1785126839572","session_id":"e9443c7415a0419799bee9cfbb1a9e4d","source":"clob_market_ws"},"received_at":"2026-07-27T04:33:59.518276Z","record_id":"efe7aff4d9331f3723607e58d9d7b4cd9d38dc088e7d7352ab873acc2e932d28","schema_fingerprint":"4aa3821a28b0b7c2400bc59aba4bcc0a76e971dadd19610d3ad38c768e124dc7","schema_version":"edge-lab-recorder.raw.v1","sequence":null,"source":"clob_market_ws"}
{"event_at":"2026-07-27T04:33:59.669000Z","event_fingerprint":"a59d98ced5a20283375fdd43c8ab7c5abe3a1a88e21177d763d5f9c79560ca85","payload":{"connection_id":"0f4979d6978d463e9660b042fdcf555f","event_at":"2026-07-27T04:33:59.669000Z","event_type":"price_change","frame_hash":"7ed534907ccdb56c785e756bf2728b39bcae1f20779ac15c8eb18bafe0c6be77","frame_index":0,"kind":"data","monotonic_ns":228822882626166,"payload":{"event_type":"price_change","market":"0xeb66215f2e9faa6449e30a02bab5b8ed7b79a38bf961f6b24d0073c9c2419250","price_changes":[{"asset_id":"60386828328910021732068595344565885737045900010034836345809386672230885527307","best_ask":"0.77","best_bid":"0.76","hash":"e2b9ba4df4ca516ba34e2880284b0b21d896bdae","price":"0.73","side":"BUY","size":"378.02"},{"asset_id":"69697746896130839564035629862476347944307040470122503199396727085502753297492","best_ask":"0.24","best_bid":"0.23","hash":"0f07580d854b9ec25461a9ac78c09645e7bf9ec9","price":"0.27","side":"SELL","size":"378.02"}],"timestamp":"1785126839669"},"payload_hash":"284d0a63bff121e91ca67783ecd3e0bcd7e430fccc75c28bb285757f42b27e9d","raw_frame":"{\"market\":\"0xeb66215f2e9faa6449e30a02bab5b8ed7b79a38bf961f6b24d0073c9c2419250\", \"price_changes\":[{\"asset_id\":\"60386828328910021732068595344565885737045900010034836345809386672230885527307\", \"price\":\"0.73\", \"size\":\"378.02\", \"side\":\"BUY\", \"hash\":\"e2b9ba4df4ca516ba34e2880284b0b21d896bdae\", \"best_bid\":\"0.76\", \"best_ask\":\"0.77\"}, {\"asset_id\":\"69697746896130839564035629862476347944307040470122503199396727085502753297492\", \"price\":\"0.27\", \"size\":\"378.02\", \"side\":\"SELL\", \"hash\":\"0f07580d854b9ec25461a9ac78c09645e7bf9ec9\", \"best_bid\":\"0.23\", \"best_ask\":\"0.24\"}], \"timestamp\":\"1785126839669\", \"event_type\":\"price_change\"}","received_at":"2026-07-27T04:33:59.614854Z","schema_version":"clob-market-ws.price_change.v1","sequence":null,"server_hash":null,"server_timestamp":"1785126839669","session_id":"e9443c7415a0419799bee9cfbb1a9e4d","source":"clob_market_ws"},"received_at":"2026-07-27T04:33:59.614854Z","record_id":"2f7daea503aaae6a7315422191d4db7f1068491e7cf977927afffd3e7b8c6f36","schema_fingerprint":"4aa3821a28b0b7c2400bc59aba4bcc0a76e971dadd19610d3ad38c768e124dc7","schema_version":"edge-lab-recorder.raw.v1","sequence":null,"source":"clob_market_ws"}
{"event_at":"2026-07-27T04:33:59.673000Z","event_fingerprint":"ca10f33f30f25394fe7aa255d83a0b4223759c58bc3af1b71b5ee37fa6f9f49d","payload":{"connection_id":"0f4979d6978d463e9660b042fdcf555f","event_at":"2026-07-27T04:33:59.673000Z","event_type":"price_change","frame_hash":"00ccbf6622321325e613f4c1d20316f462acb8ca7e266e91d34c0b757191d149","frame_index":0,"kind":"data","monotonic_ns":228822885977791,"payload":{"event_type":"price_change","market":"0xeb66215f2e9faa6449e30a02bab5b8ed7b79a38bf961f6b24d0073c9c2419250","price_changes":[{"asset_id":"69697746896130839564035629862476347944307040470122503199396727085502753297492","best_ask":"0.24","best_bid":"0.23","hash":"10bb6bece080cb143d13646c434f3322787bdf02","price":"0.27","side":"SELL","size":"408.06"},{"asset_id":"60386828328910021732068595344565885737045900010034836345809386672230885527307","best_ask":"0.77","best_bid":"0.76","hash":"3431b65df413a7db911260b6784400f6e72969f0","price":"0.73","side":"BUY","size":"408.06"}],"timestamp":"1785126839673"},"payload_hash":"82fa7219da9651173ea3f8b012ce120ae5cfb3ba904dd4663305001df3c9fd27","raw_frame":"{\"market\":\"0xeb66215f2e9faa6449e30a02bab5b8ed7b79a38bf961f6b24d0073c9c2419250\", \"price_changes\":[{\"asset_id\":\"69697746896130839564035629862476347944307040470122503199396727085502753297492\", \"price\":\"0.27\", \"size\":\"408.06\", \"side\":\"SELL\", \"hash\":\"10bb6bece080cb143d13646c434f3322787bdf02\", \"best_bid\":\"0.23\", \"best_ask\":\"0.24\"}, {\"asset_id\":\"60386828328910021732068595344565885737045900010034836345809386672230885527307\", \"price\":\"0.73\", \"size\":\"408.06\", \"side\":\"BUY\", \"hash\":\"3431b65df413a7db911260b6784400f6e72969f0\", \"best_bid\":\"0.76\", \"best_ask\":\"0.77\"}], \"timestamp\":\"1785126839673\", \"event_type\":\"price_change\"}","received_at":"2026-07-27T04:33:59.618212Z","schema_version":"clob-market-ws.price_change.v1","sequence":null,"server_hash":null,"server_timestamp":"1785126839673","session_id":"e9443c7415a0419799bee9cfbb1a9e4d","source":"clob_market_ws"},"received_at":"2026-07-27T04:33:59.618212Z","record_id":"cadd2d5babd9fb3e13d8ba54096bb40920a38dc717cffe3ee0c58b976032ca48","schema_fingerprint":"4aa3821a28b0b7c2400bc59aba4bcc0a76e971dadd19610d3ad38c768e124dc7","schema_version":"edge-lab-recorder.raw.v1","sequence":null,"source":"clob_market_ws"}
{"event_at":"2026-07-27T04:33:59.676000Z","event_fingerprint":"70e4a2722ec47962bce4ff2073a83e9d8913edd1f48fa97583a859180e0ca870","payload":{"connection_id":"0f4979d6978d463e9660b042fdcf555f","event_at":"2026-07-27T04:33:59.676000Z","event_type":"price_change","frame_hash":"f84f9abe0aee45bf658fa1d02b303a15ec1fc482f1fedc00281d8ebeeb6fd915","frame_index":0,"kind":"data","monotonic_ns":228822888632791,"payload":{"event_type":"price_change","market":"0xeb66215f2e9faa6449e30a02bab5b8ed7b79a38bf961f6b24d0073c9c2419250","price_changes":[{"asset_id":"60386828328910021732068595344565885737045900010034836345809386672230885527307","best_ask":"0.77","best_bid":"0.76","hash":"e5affeb67a508454e8a33c1a964c3277849a86e3","price":"0.8","side":"SELL","size":"51.31"},{"asset_id":"69697746896130839564035629862476347944307040470122503199396727085502753297492","best_ask":"0.24","best_bid":"0.23","hash":"1e3fd7c5708e23fe6846019f52fbfd42bebf8239","price":"0.2","side":"BUY","size":"51.31"}],"timestamp":"1785126839676"},"payload_hash":"d84fd8c69b4c11c3867784d12a0929f5e5382b82baf7c66fce5ed790a4874011","raw_frame":"{\"market\":\"0xeb66215f2e9faa6449e30a02bab5b8ed7b79a38bf961f6b24d0073c9c2419250\", \"price_changes\":[{\"asset_id\":\"60386828328910021732068595344565885737045900010034836345809386672230885527307\", \"price\":\"0.8\", \"size\":\"51.31\", \"side\":\"SELL\", \"hash\":\"e5affeb67a508454e8a33c1a964c3277849a86e3\", \"best_bid\":\"0.76\", \"best_ask\":\"0.77\"}, {\"asset_id\":\"69697746896130839564035629862476347944307040470122503199396727085502753297492\", \"price\":\"0.2\", \"size\":\"51.31\", \"side\":\"BUY\", \"hash\":\"1e3fd7c5708e23fe6846019f52fbfd42bebf8239\", \"best_bid\":\"0.23\", \"best_ask\":\"0.24\"}], \"timestamp\":\"1785126839676\", \"event_type\":\"price_change\"}","received_at":"2026-07-27T04:33:59.620869Z","schema_version":"clob-market-ws.price_change.v1","sequence":null,"server_hash":null,"server_timestamp":"1785126839676","session_id":"e9443c7415a0419799bee9cfbb1a9e4d","source":"clob_market_ws"},"received_at":"2026-07-27T04:33:59.620869Z","record_id":"0e86273c56e83f52d7e4ca18061f07b72662b792ea918dd98b9e59e331b442ec","schema_fingerprint":"4aa3821a28b0b7c2400bc59aba4bcc0a76e971dadd19610d3ad38c768e124dc7","schema_version":"edge-lab-recorder.raw.v1","sequence":null,"source":"clob_market_ws"}
{"event_at":"2026-07-27T04:33:59.693000Z","event_fingerprint":"d6d2919890b7b4188ce64b463575a5a1c32861b0b43e841975854ee10af9abc9","payload":{"connection_id":"0f4979d6978d463e9660b042fdcf555f","event_at":"2026-07-27T04:33:59.693000Z","event_type":"price_change","frame_hash":"2aadff56c1224c72b3e60c2051941c4f0a6cb15e8b70070db758719b0b08c413","frame_index":0,"kind":"data","monotonic_ns":228822905325916,"payload":{"event_type":"price_change","market":"0xeb66215f2e9faa6449e30a02bab5b8ed7b79a38bf961f6b24d0073c9c2419250","price_changes":[{"asset_id":"60386828328910021732068595344565885737045900010034836345809386672230885527307","best_ask":"0.77","best_bid":"0.76","hash":"f0087f82ec4b56bfb66e75b1459106fd75236012","price":"0.03","side":"BUY","size":"643.1"},{"asset_id":"69697746896130839564035629862476347944307040470122503199396727085502753297492","best_ask":"0.24","best_bid":"0.23","hash":"01dd2c00a84c9653fc88cbcc687262841c1a1981","price":"0.97","side":"SELL","size":"643.1"}],"timestamp":"1785126839693"},"payload_hash":"f379553b7beae29b9049d1dd295ffde0c4a0952818b732def58d84b125d7c628","raw_frame":"{\"market\":\"0xeb66215f2e9faa6449e30a02bab5b8ed7b79a38bf961f6b24d0073c9c2419250\", \"price_changes\":[{\"asset_id\":\"60386828328910021732068595344565885737045900010034836345809386672230885527307\", \"price\":\"0.03\", \"size\":\"643.1\", \"side\":\"BUY\", \"hash\":\"f0087f82ec4b56bfb66e75b1459106fd75236012\", \"best_bid\":\"0.76\", \"best_ask\":\"0.77\"}, {\"asset_id\":\"69697746896130839564035629862476347944307040470122503199396727085502753297492\", \"price\":\"0.97\", \"size\":\"643.1\", \"side\":\"SELL\", \"hash\":\"01dd2c00a84c9653fc88cbcc687262841c1a1981\", \"best_bid\":\"0.23\", \"best_ask\":\"0.24\"}], \"timestamp\":\"1785126839693\", \"event_type\":\"price_change\"}","received_at":"2026-07-27T04:33:59.637561Z","schema_version":"clob-market-ws.price_change.v1","sequence":null,"server_hash":null,"server_timestamp":"1785126839693","session_id":"e9443c7415a0419799bee9cfbb1a9e4d","source":"clob_market_ws"},"received_at":"2026-07-27T04:33:59.637561Z","record_id":"93c6ac003374a37c23c48a428c2e883272d35c264bc8ec797dfe49461f6048f5","schema_fingerprint":"4aa3821a28b0b7c2400bc59aba4bcc0a76e971dadd19610d3ad38c768e124dc7","schema_version":"edge-lab-recorder.raw.v1","sequence":null,"source":"clob_market_ws"}
{"event_at":"2026-07-27T04:33:59.767000Z","event_fingerprint":"6dbcafe365fdd5bdcc709c6c7951c1b13037999bdfbfbcc74663e8e998dcefb4","payload":{"connection_id":"0f4979d6978d463e9660b042fdcf555f","event_at":"2026-07-27T04:33:59.767000Z","event_type":"price_change","frame_hash":"eef9aabbe6fe554361b4e8be9f4ada71c25fda48efc96f1c7a963746c2743e5a","frame_index":0,"kind":"data","monotonic_ns":228822979242166,"payload":{"event_type":"price_change","market":"0xeb66215f2e9faa6449e30a02bab5b8ed7b79a38bf961f6b24d0073c9c2419250","price_changes":[{"asset_id":"60386828328910021732068595344565885737045900010034836345809386672230885527307","best_ask":"0.77","best_bid":"0.76","hash":"0b1471012a4df21ec14f5062927bb034b77255f4","price":"0.8","side":"SELL","size":"46.27"},{"asset_id":"69697746896130839564035629862476347944307040470122503199396727085502753297492","best_ask":"0.24","best_bid":"0.23","hash":"93e115da8588f4b012b63c4ecf0d74114b18f093","price":"0.2","side":"BUY","size":"46.27"}],"timestamp":"1785126839767"},"payload_hash":"8f44855c1218b87bdef12bd8cc5453e53cbb45ebaa92f02481a878b7e8cea8c1","raw_frame":"{\"market\":\"0xeb66215f2e9faa6449e30a02bab5b8ed7b79a38bf961f6b24d0073c9c2419250\", \"price_changes\":[{\"asset_id\":\"60386828328910021732068595344565885737045900010034836345809386672230885527307\", \"price\":\"0.8\", \"size\":\"46.27\", \"side\":\"SELL\", \"hash\":\"0b1471012a4df21ec14f5062927bb034b77255f4\", \"best_bid\":\"0.76\", \"best_ask\":\"0.77\"}, {\"asset_id\":\"69697746896130839564035629862476347944307040470122503199396727085502753297492\", \"price\":\"0.2\", \"size\":\"46.27\", \"side\":\"BUY\", \"hash\":\"93e115da8588f4b012b63c4ecf0d74114b18f093\", \"best_bid\":\"0.23\", \"best_ask\":\"0.24\"}], \"timestamp\":\"1785126839767\", \"event_type\":\"price_change\"}","received_at":"2026-07-27T04:33:59.711466Z","schema_version":"clob-market-ws.price_change.v1","sequence":null,"server_hash":null,"server_timestamp":"1785126839767","session_id":"e9443c7415a0419799bee9cfbb1a9e4d","source":"clob_market_ws"},"received_at":"2026-07-27T04:33:59.711466Z","record_id":"7123c36f2dc8e43de288faddddfd63f5be91bf9436ad620c38a6885e8468c3af","schema_fingerprint":"4aa3821a28b0b7c2400bc59aba4bcc0a76e971dadd19610d3ad38c768e124dc7","schema_version":"edge-lab-recorder.raw.v1","sequence":null,"source":"clob_market_ws"}
{"event_at":"2026-07-27T04:33:59.767000Z","event_fingerprint":"e8b73aa08857c6608f1d93af5195380b48e9c3b95006a5c09960d5abee7bf4fb","payload":{"connection_id":"0f4979d6978d463e9660b042fdcf555f","event_at":"2026-07-27T04:33:59.767000Z","event_type":"price_change","frame_hash":"fcdee284ae812461a5b3722bbea11eb546213af4be52cda679dad03d41e85c40","frame_index":0,"kind":"data","monotonic_ns":228822981345375,"payload":{"event_type":"price_change","market":"0xeb66215f2e9faa6449e30a02bab5b8ed7b79a38bf961f6b24d0073c9c2419250","price_changes":[{"asset_id":"69697746896130839564035629862476347944307040470122503199396727085502753297492","best_ask":"0.24","best_bid":"0.23","hash":"cfd1c1cd753da97f8e127373b0501e810f297576","price":"0.27","side":"SELL","size":"378.02"},{"asset_id":"60386828328910021732068595344565885737045900010034836345809386672230885527307","best_ask":"0.77","best_bid":"0.76","hash":"eef8424a3252a2c67ae9b1fc3db3832c303a7761","price":"0.73","side":"BUY","size":"378.02"}],"timestamp":"1785126839767"},"payload_hash":"ac4a70fed13073f3d76382c96509f6a66181ee70b9a2fdd963fce5bff78a7639","raw_frame":"{\"market\":\"0xeb66215f2e9faa6449e30a02bab5b8ed7b79a38bf961f6b24d0073c9c2419250\", \"price_changes\":[{\"asset_id\":\"69697746896130839564035629862476347944307040470122503199396727085502753297492\", \"price\":\"0.27\", \"size\":\"378.02\", \"side\":\"SELL\", \"hash\":\"cfd1c1cd753da97f8e127373b0501e810f297576\", \"best_bid\":\"0.23\", \"best_ask\":\"0.24\"}, {\"asset_id\":\"60386828328910021732068595344565885737045900010034836345809386672230885527307\", \"price\":\"0.73\", \"size\":\"378.02\", \"side\":\"BUY\", \"hash\":\"eef8424a3252a2c67ae9b1fc3db3832c303a7761\", \"best_bid\":\"0.76\", \"best_ask\":\"0.77\"}], \"timestamp\":\"1785126839767\", \"event_type\":\"price_change\"}","received_at":"2026-07-27T04:33:59.713586Z","schema_version":"clob-market-ws.price_change.v1","sequence":null,"server_hash":null,"server_timestamp":"1785126839767","session_id":"e9443c7415a0419799bee9cfbb1a9e4d","source":"clob_market_ws"},"received_at":"2026-07-27T04:33:59.713586Z","record_id":"46193af0668b829dd6512c7edfa33a8b3605e0bcaf2faa843990455b7eda1b70","schema_fingerprint":"4aa3821a28b0b7c2400bc59aba4bcc0a76e971dadd19610d3ad38c768e124dc7","schema_version":"edge-lab-recorder.raw.v1","sequence":null,"source":"clob_market_ws"}
{"event_at":"2026-07-27T04:33:59.773000Z","event_fingerprint":"1eb397736c8298aa1d45a419e9eb638497e2b8b07cfab6b5d52a08915b0f69eb","payload":{"connection_id":"0f4979d6978d463e9660b042fdcf555f","event_at":"2026-07-27T04:33:59.773000Z","event_type":"price_change","frame_hash":"654bf00d98a5fa33cc471bae4c7787e8492bb046b879e2f3b62863af94a0ad30","frame_index":0,"kind":"data","monotonic_ns":228822986141041,"payload":{"event_type":"price_change","market":"0xeb66215f2e9faa6449e30a02bab5b8ed7b79a38bf961f6b24d0073c9c2419250","price_changes":[{"asset_id":"60386828328910021732068595344565885737045900010034836345809386672230885527307","best_ask":"0.77","best_bid":"0.76","hash":"7a587b22712993e801ebd792b328647fe2491973","price":"0.73","side":"BUY","size":"409.06"},{"asset_id":"69697746896130839564035629862476347944307040470122503199396727085502753297492","best_ask":"0.24","best_bid":"0.23","hash":"2350777474e085c4b3065bd80459393200ea3844","price":"0.27","side":"SELL","size":"409.06"}],"timestamp":"1785126839773"},"payload_hash":"ce47f34b6f66ef498cee2a2cc2cd64c977b37e3ade89d2d7fda9f2c8c7f30b7c","raw_frame":"{\"market\":\"0xeb66215f2e9faa6449e30a02bab5b8ed7b79a38bf961f6b24d0073c9c2419250\", \"price_changes\":[{\"asset_id\":\"60386828328910021732068595344565885737045900010034836345809386672230885527307\", \"price\":\"0.73\", \"size\":\"409.06\", \"side\":\"BUY\", \"hash\":\"7a587b22712993e801ebd792b328647fe2491973\", \"best_bid\":\"0.76\", \"best_ask\":\"0.77\"}, {\"asset_id\":\"69697746896130839564035629862476347944307040470122503199396727085502753297492\", \"price\":\"0.27\", \"size\":\"409.06\", \"side\":\"SELL\", \"hash\":\"2350777474e085c4b3065bd80459393200ea3844\", \"best_bid\":\"0.23\", \"best_ask\":\"0.24\"}], \"timestamp\":\"1785126839773\", \"event_type\":\"price_change\"}","received_at":"2026-07-27T04:33:59.718379Z","schema_version":"clob-market-ws.price_change.v1","sequence":null,"server_hash":null,"server_timestamp":"1785126839773","session_id":"e9443c7415a0419799bee9cfbb1a9e4d","source":"clob_market_ws"},"received_at":"2026-07-27T04:33:59.718379Z","record_id":"5f0d498767531daffe3995563edb24e05b0b95e6f7a8f38514c299519b40d8ae","schema_fingerprint":"4aa3821a28b0b7c2400bc59aba4bcc0a76e971dadd19610d3ad38c768e124dc7","schema_version":"edge-lab-recorder.raw.v1","sequence":null,"source":"clob_market_ws"}
{"event_at":"2026-07-27T04:33:59.793000Z","event_fingerprint":"81c1753d62c34a2e8c7e9b177f586ed416e5fdf7ab0fe0324a9f28a261aa91f2","payload":{"connection_id":"0f4979d6978d463e9660b042fdcf555f","event_at":"2026-07-27T04:33:59.793000Z","event_type":"price_change","frame_hash":"125b2f3bd6ce32e7676d914646270828c058e7a345e4d9cd4283fda1600fd9c7","frame_index":0,"kind":"data","monotonic_ns":228823007158125,"payload":{"event_type":"price_change","market":"0xeb66215f2e9faa6449e30a02bab5b8ed7b79a38bf961f6b24d0073c9c2419250","price_changes":[{"asset_id":"60386828328910021732068595344565885737045900010034836345809386672230885527307","best_ask":"0.77","best_bid":"0.76","hash":"16cc31fb01f8970c94eb0359af647c74962c120e","price":"0.02","side":"BUY","size":"738.1"},{"asset_id":"69697746896130839564035629862476347944307040470122503199396727085502753297492","best_ask":"0.24","best_bid":"0.23","hash":"fee8f57459a1e52a9261bf3bd1b57f632f1fee68","price":"0.98","side":"SELL","size":"738.1"}],"timestamp":"1785126839793"},"payload_hash":"9f275d3ca8d4ea48d2f090afef6a78e26bea857bbd18c006c27f3d52762ac6ab","raw_frame":"{\"market\":\"0xeb66215f2e9faa6449e30a02bab5b8ed7b79a38bf961f6b24d0073c9c2419250\", \"price_changes\":[{\"asset_id\":\"60386828328910021732068595344565885737045900010034836345809386672230885527307\", \"price\":\"0.02\", \"size\":\"738.1\", \"side\":\"BUY\", \"hash\":\"16cc31fb01f8970c94eb0359af647c74962c120e\", \"best_bid\":\"0.76\", \"best_ask\":\"0.77\"}, {\"asset_id\":\"69697746896130839564035629862476347944307040470122503199396727085502753297492\", \"price\":\"0.98\", \"size\":\"738.1\", \"side\":\"SELL\", \"hash\":\"fee8f57459a1e52a9261bf3bd1b57f632f1fee68\", \"best_bid\":\"0.23\", \"best_ask\":\"0.24\"}], \"timestamp\":\"1785126839793\", \"event_type\":\"price_change\"}","received_at":"2026-07-27T04:33:59.739394Z","schema_version":"clob-market-ws.price_change.v1","sequence":null,"server_hash":null,"server_timestamp":"1785126839793","session_id":"e9443c7415a0419799bee9cfbb1a9e4d","source":"clob_market_ws"},"received_at":"2026-07-27T04:33:59.739394Z","record_id":"efe88332cc32cbebb63a67f9b0fa3703a930d98d5d87b6bf3b2c6771777488e1","schema_fingerprint":"4aa3821a28b0b7c2400bc59aba4bcc0a76e971dadd19610d3ad38c768e124dc7","schema_version":"edge-lab-recorder.raw.v1","sequence":null,"source":"clob_market_ws"}
{"event_at":"2026-07-27T04:33:59.816000Z","event_fingerprint":"5c6d47b96aebcf4731d79ea05a57839705cda4f2977488207c201093a14a62c2","payload":{"connection_id":"0f4979d6978d463e9660b042fdcf555f","event_at":"2026-07-27T04:33:59.816000Z","event_type":"price_change","frame_hash":"2ee5f95e4bb5922cf1f722134ac49cb6545aae538ebd9df3f05fc196a14d603d","frame_index":0,"kind":"data","monotonic_ns":228823028641000,"payload":{"event_type":"price_change","market":"0xeb66215f2e9faa6449e30a02bab5b8ed7b79a38bf961f6b24d0073c9c2419250","price_changes":[{"asset_id":"60386828328910021732068595344565885737045900010034836345809386672230885527307","best_ask":"0.77","best_bid":"0.76","hash":"adbf91d13a1f3e4e62b47e2f5675a067782279ad","price":"0.01","side":"BUY","size":"7708.02"},{"asset_id":"69697746896130839564035629862476347944307040470122503199396727085502753297492","best_ask":"0.24","best_bid":"0.23","hash":"efa23e7685b7eec4ec77255a6bf4544e68cfdbe6","price":"0.99","side":"SELL","size":"7708.02"}],"timestamp":"1785126839816"},"payload_hash":"03af61baf561ac5fb0e97b3b3878e495e527d77b4f31d2a4d870538172686f98","raw_frame":"{\"market\":\"0xeb66215f2e9faa6449e30a02bab5b8ed7b79a38bf961f6b24d0073c9c2419250\", \"price_changes\":[{\"asset_id\":\"60386828328910021732068595344565885737045900010034836345809386672230885527307\", \"price\":\"0.01\", \"size\":\"7708.02\", \"side\":\"BUY\", \"hash\":\"adbf91d13a1f3e4e62b47e2f5675a067782279ad\", \"best_bid\":\"0.76\", \"best_ask\":\"0.77\"}, {\"asset_id\":\"69697746896130839564035629862476347944307040470122503199396727085502753297492\", \"price\":\"0.99\", \"size\":\"7708.02\", \"side\":\"SELL\", \"hash\":\"efa23e7685b7eec4ec77255a6bf4544e68cfdbe6\", \"best_bid\":\"0.23\", \"best_ask\":\"0.24\"}], \"timestamp\":\"1785126839816\", \"event_type\":\"price_change\"}","received_at":"2026-07-27T04:33:59.760878Z","schema_version":"clob-market-ws.price_change.v1","sequence":null,"server_hash":null,"server_timestamp":"1785126839816","session_id":"e9443c7415a0419799bee9cfbb1a9e4d","source":"clob_market_ws"},"received_at":"2026-07-27T04:33:59.760878Z","record_id":"7f959e8721c28a7fd401c607b96a6705d27a7725e9b7b822a6fb79c3bb180ae2","schema_fingerprint":"4aa3821a28b0b7c2400bc59aba4bcc0a76e971dadd19610d3ad38c768e124dc7","schema_version":"edge-lab-recorder.raw.v1","sequence":null,"source":"clob_market_ws"}
{"event_at":"2026-07-27T04:33:59.835000Z","event_fingerprint":"18bec1b92125c6e399f52544e06317d2a88968286ce44b668de3021d769badbd","payload":{"connection_id":"0f4979d6978d463e9660b042fdcf555f","event_at":"2026-07-27T04:33:59.835000Z","event_type":"price_change","frame_hash":"0a7939e5c700fd006d83335d6fdfd9211fc69dc99679f1cd08d961e2bf1127df","frame_index":0,"kind":"data","monotonic_ns":228823047102291,"payload":{"event_type":"price_change","market":"0xeb66215f2e9faa6449e30a02bab5b8ed7b79a38bf961f6b24d0073c9c2419250","price_changes":[{"asset_id":"69697746896130839564035629862476347944307040470122503199396727085502753297492","best_ask":"0.24","best_bid":"0.23","hash":"91d4b94435eae7c16f7c1ea7417f1fe61675671e","price":"0.23","side":"BUY","size":"391"},{"asset_id":"60386828328910021732068595344565885737045900010034836345809386672230885527307","best_ask":"0.77","best_bid":"0.76","hash":"0f07fcb98da32319e47751cb89fc3a9c2f2edf9d","price":"0.77","side":"SELL","size":"391"}],"timestamp":"1785126839835"},"payload_hash":"25d0dd36c91d9413d83b9819e62ac14ac260cef6847587fec7287e609d46c7f3","raw_frame":"{\"market\":\"0xeb66215f2e9faa6449e30a02bab5b8ed7b79a38bf961f6b24d0073c9c2419250\", \"price_changes\":[{\"asset_id\":\"69697746896130839564035629862476347944307040470122503199396727085502753297492\", \"price\":\"0.23\", \"size\":\"391\", \"side\":\"BUY\", \"hash\":\"91d4b94435eae7c16f7c1ea7417f1fe61675671e\", \"best_bid\":\"0.23\", \"best_ask\":\"0.24\"}, {\"asset_id\":\"60386828328910021732068595344565885737045900010034836345809386672230885527307\", \"price\":\"0.77\", \"size\":\"391\", \"side\":\"SELL\", \"hash\":\"0f07fcb98da32319e47751cb89fc3a9c2f2edf9d\", \"best_bid\":\"0.76\", \"best_ask\":\"0.77\"}], \"timestamp\":\"1785126839835\", \"event_type\":\"price_change\"}","received_at":"2026-07-27T04:33:59.779335Z","schema_version":"clob-market-ws.price_change.v1","sequence":null,"server_hash":null,"server_timestamp":"1785126839835","session_id":"e9443c7415a0419799bee9cfbb1a9e4d","source":"clob_market_ws"},"received_at":"2026-07-27T04:33:59.779335Z","record_id":"acbf8bf32a36ff8e7660676b1ce7ca8d7ad9e30b78ff97568e6ba699b9b57b2f","schema_fingerprint":"4aa3821a28b0b7c2400bc59aba4bcc0a76e971dadd19610d3ad38c768e124dc7","schema_version":"edge-lab-recorder.raw.v1","sequence":null,"source":"clob_market_ws"}
{"event_at":"2026-07-27T04:33:59.844000Z","event_fingerprint":"bcfa6a858f58e2397da2cfed2023bf46687d9f1f7a2d06738c32e637091ca407","payload":{"connection_id":"0f4979d6978d463e9660b042fdcf555f","event_at":"2026-07-27T04:33:59.844000Z","event_type":"price_change","frame_hash":"9bc366f85b48658115c07c3bd87f070216d3db49c67f07fad52e0fe8acc497d8","frame_index":0,"kind":"data","monotonic_ns":228823059840458,"payload":{"event_type":"price_change","market":"0xeb66215f2e9faa6449e30a02bab5b8ed7b79a38bf961f6b24d0073c9c2419250","price_changes":[{"asset_id":"60386828328910021732068595344565885737045900010034836345809386672230885527307","best_ask":"0.77","best_bid":"0.76","hash":"2ed9913b37af21bbc86f3ccafc22a8770bdce980","price":"0.01","side":"BUY","size":"7703.02"},{"asset_id":"69697746896130839564035629862476347944307040470122503199396727085502753297492","best_ask":"0.24","best_bid":"0.23","hash":"472dbe2884b571445547cfa274195594a2830237","price":"0.99","side":"SELL","size":"7703.02"}],"timestamp":"1785126839844"},"payload_hash":"162c483c0533f4dd952b576bb76f0bb795a0491be8701f8dd932d3b7a0ce6ccf","raw_frame":"{\"market\":\"0xeb66215f2e9faa6449e30a02bab5b8ed7b79a38bf961f6b24d0073c9c2419250\", \"price_changes\":[{\"asset_id\":\"60386828328910021732068595344565885737045900010034836345809386672230885527307\", \"price\":\"0.01\", \"size\":\"7703.02\", \"side\":\"BUY\", \"hash\":\"2ed9913b37af21bbc86f3ccafc22a8770bdce980\", \"best_bid\":\"0.76\", \"best_ask\":\"0.77\"}, {\"asset_id\":\"69697746896130839564035629862476347944307040470122503199396727085502753297492\", \"price\":\"0.99\", \"size\":\"7703.02\", \"side\":\"SELL\", \"hash\":\"472dbe2884b571445547cfa274195594a2830237\", \"best_bid\":\"0.23\", \"best_ask\":\"0.24\"}], \"timestamp\":\"1785126839844\", \"event_type\":\"price_change\"}","received_at":"2026-07-27T04:33:59.792076Z","schema_version":"clob-market-ws.price_change.v1","sequence":null,"server_hash":null,"server_timestamp":"1785126839844","session_id":"e9443c7415a0419799bee9cfbb1a9e4d","source":"clob_market_ws"},"received_at":"2026-07-27T04:33:59.792076Z","record_id":"1c5f56da1f54ab3042985dc22851cfe3a0c6994ac0c098531a4aff0047ac2344","schema_fingerprint":"4aa3821a28b0b7c2400bc59aba4bcc0a76e971dadd19610d3ad38c768e124dc7","schema_version":"edge-lab-recorder.raw.v1","sequence":null,"source":"clob_market_ws"}
{"event_at":"2026-07-27T04:33:59.848000Z","event_fingerprint":"0b31ccdd651d0a5bf1275b49151951c4674a090c5ac928a69a9a1310f70635e2","payload":{"connection_id":"0f4979d6978d463e9660b042fdcf555f","event_at":"2026-07-27T04:33:59.848000Z","event_type":"price_change","frame_hash":"c571e1628bed8ce6a24c70ef7b0dfaa075eefcb25e953af0a4806a8d2aeec9eb","frame_index":0,"kind":"data","monotonic_ns":228823062698250,"payload":{"event_type":"price_change","market":"0xeb66215f2e9faa6449e30a02bab5b8ed7b79a38bf961f6b24d0073c9c2419250","price_changes":[{"asset_id":"60386828328910021732068595344565885737045900010034836345809386672230885527307","best_ask":"0.77","best_bid":"0.76","hash":"d21ac1dda626e1d708fff5c9f35f74be7464467f","price":"0.01","side":"BUY","size":"7708.02"},{"asset_id":"69697746896130839564035629862476347944307040470122503199396727085502753297492","best_ask":"0.24","best_bid":"0.23","hash":"12bb271ea003ac8bf85ac24f939b1a7dcd044607","price":"0.99","side":"SELL","size":"7708.02"}],"timestamp":"1785126839848"},"payload_hash":"5806a5234d8f110cb61a351b4a281115ce7890dd9ac5ef55ebbbb9fe89df6ae9","raw_frame":"{\"market\":\"0xeb66215f2e9faa6449e30a02bab5b8ed7b79a38bf961f6b24d0073c9c2419250\", \"price_changes\":[{\"asset_id\":\"60386828328910021732068595344565885737045900010034836345809386672230885527307\", \"price\":\"0.01\", \"size\":\"7708.02\", \"side\":\"BUY\", \"hash\":\"d21ac1dda626e1d708fff5c9f35f74be7464467f\", \"best_bid\":\"0.76\", \"best_ask\":\"0.77\"}, {\"asset_id\":\"69697746896130839564035629862476347944307040470122503199396727085502753297492\", \"price\":\"0.99\", \"size\":\"7708.02\", \"side\":\"SELL\", \"hash\":\"12bb271ea003ac8bf85ac24f939b1a7dcd044607\", \"best_bid\":\"0.23\", \"best_ask\":\"0.24\"}], \"timestamp\":\"1785126839848\", \"event_type\":\"price_change\"}","received_at":"2026-07-27T04:33:59.794937Z","schema_version":"clob-market-ws.price_change.v1","sequence":null,"server_hash":null,"server_timestamp":"1785126839848","session_id":"e9443c7415a0419799bee9cfbb1a9e4d","source":"clob_market_ws"},"received_at":"2026-07-27T04:33:59.794937Z","record_id":"3febbe7a561760a487c3bb5d8af2fd9699ec4448d1cae306fea71412dc89d4b8","schema_fingerprint":"4aa3821a28b0b7c2400bc59aba4bcc0a76e971dadd19610d3ad38c768e124dc7","schema_version":"edge-lab-recorder.raw.v1","sequence":null,"source":"clob_market_ws"}
{"event_at":"2026-07-27T04:33:59.863000Z","event_fingerprint":"53dfdc6177fd83ed73d68027f28a624a91997ff9582cec9080f725614e9ff91d","payload":{"connection_id":"0f4979d6978d463e9660b042fdcf555f","event_at":"2026-07-27T04:33:59.863000Z","event_type":"price_change","frame_hash":"4c2172059abcfe0ecbf41379c3fe7a7008731394beec438b64c8517c6783a047","frame_index":0,"kind":"data","monotonic_ns":228823075228291,"payload":{"event_type":"price_change","market":"0xeb66215f2e9faa6449e30a02bab5b8ed7b79a38bf961f6b24d0073c9c2419250","price_changes":[{"asset_id":"60386828328910021732068595344565885737045900010034836345809386672230885527307","best_ask":"0.77","best_bid":"0.76","hash":"6a3eaac971231f64deaeccbc5787e4af33813abf","price":"0.02","side":"BUY","size":"733.1"},{"asset_id":"69697746896130839564035629862476347944307040470122503199396727085502753297492","best_ask":"0.24","best_bid":"0.23","hash":"f7646db7a882403b3811869bd71108056e00ccfb","price":"0.98","side":"SELL","size":"733.1"}],"timestamp":"1785126839863"},"payload_hash":"64ecd4b2f049420b38860aef8b74149b4204e18761c7876a69f6a82c83e212c6","raw_frame":"{\"market\":\"0xeb66215f2e9faa6449e30a02bab5b8ed7b79a38bf961f6b24d0073c9c2419250\", \"price_changes\":[{\"asset_id\":\"60386828328910021732068595344565885737045900010034836345809386672230885527307\", \"price\":\"0.02\", \"size\":\"733.1\", \"side\":\"BUY\", \"hash\":\"6a3eaac971231f64deaeccbc5787e4af33813abf\", \"best_bid\":\"0.76\", \"best_ask\":\"0.77\"}, {\"asset_id\":\"69697746896130839564035629862476347944307040470122503199396727085502753297492\", \"price\":\"0.98\", \"size\":\"733.1\", \"side\":\"SELL\", \"hash\":\"f7646db7a882403b3811869bd71108056e00ccfb\", \"best_bid\":\"0.23\", \"best_ask\":\"0.24\"}], \"timestamp\":\"1785126839863\", \"event_type\":\"price_change\"}","received_at":"2026-07-27T04:33:59.807468Z","schema_version":"clob-market-ws.price_change.v1","sequence":null,"server_hash":null,"server_timestamp":"1785126839863","session_id":"e9443c7415a0419799bee9cfbb1a9e4d","source":"clob_market_ws"},"received_at":"2026-07-27T04:33:59.807468Z","record_id":"cb250f349dc81590a2d6678f3e4018b6bf61699d5d615d4a8494723eac199adc","schema_fingerprint":"4aa3821a28b0b7c2400bc59aba4bcc0a76e971dadd19610d3ad38c768e124dc7","schema_version":"edge-lab-recorder.raw.v1","sequence":null,"source":"clob_market_ws"}
{"event_at":"2026-07-27T04:33:59.865000Z","event_fingerprint":"c164ec5cc5bd6a0d5e9ada488792751f4453ff9be2a135cb2cf9da7419ddf9e7","payload":{"connection_id":"0f4979d6978d463e9660b042fdcf555f","event_at":"2026-07-27T04:33:59.865000Z","event_type":"price_change","frame_hash":"8be4bb63c5ca89aa4075fbb5654095b5c86f0b739e05af27db22ace867fec538","frame_index":0,"kind":"data","monotonic_ns":228823077347750,"payload":{"event_type":"price_change","market":"0xeb66215f2e9faa6449e30a02bab5b8ed7b79a38bf961f6b24d0073c9c2419250","price_changes":[{"asset_id":"60386828328910021732068595344565885737045900010034836345809386672230885527307","best_ask":"0.77","best_bid":"0.76","hash":"2e597fa3c3e251b86e5b003e0f28ea8dba76771a","price":"0.01","side":"BUY","size":"7703.02"},{"asset_id":"69697746896130839564035629862476347944307040470122503199396727085502753297492","best_ask":"0.24","best_bid":"0.23","hash":"0c7e911555fa4e222227e57bc64ef7c9529763b2","price":"0.99","side":"SELL","size":"7703.02"}],"timestamp":"1785126839865"},"payload_hash":"386a02a26da6f69b7f1a3a596908068d86d69231a19b4671d8159b1bc3225e79","raw_frame":"{\"market\":\"0xeb66215f2e9faa6449e30a02bab5b8ed7b79a38bf961f6b24d0073c9c2419250\", \"price_changes\":[{\"asset_id\":\"60386828328910021732068595344565885737045900010034836345809386672230885527307\", \"price\":\"0.01\", \"size\":\"7703.02\", \"side\":\"BUY\", \"hash\":\"2e597fa3c3e251b86e5b003e0f28ea8dba76771a\", \"best_bid\":\"0.76\", \"best_ask\":\"0.77\"}, {\"asset_id\":\"69697746896130839564035629862476347944307040470122503199396727085502753297492\", \"price\":\"0.99\", \"size\":\"7703.02\", \"side\":\"SELL\", \"hash\":\"0c7e911555fa4e222227e57bc64ef7c9529763b2\", \"best_bid\":\"0.23\", \"best_ask\":\"0.24\"}], \"timestamp\":\"1785126839865\", \"event_type\":\"price_change\"}","received_at":"2026-07-27T04:33:59.809583Z","schema_version":"clob-market-ws.price_change.v1","sequence":null,"server_hash":null,"server_timestamp":"1785126839865","session_id":"e9443c7415a0419799bee9cfbb1a9e4d","source":"clob_market_ws"},"received_at":"2026-07-27T04:33:59.809583Z","record_id":"ca3a84898a3494acb9b58000c8de583f8eabac558b73f0b0e70168895d35f57b","schema_fingerprint":"4aa3821a28b0b7c2400bc59aba4bcc0a76e971dadd19610d3ad38c768e124dc7","schema_version":"edge-lab-recorder.raw.v1","sequence":null,"source":"clob_market_ws"}
{"event_at":"2026-07-27T04:33:59.880000Z","event_fingerprint":"c2ba030b220c8fc6a8d8112f9eb17e833103a2c03f531733753863ddaf3ad645","payload":{"connection_id":"0f4979d6978d463e9660b042fdcf555f","event_at":"2026-07-27T04:33:59.880000Z","event_type":"price_change","frame_hash":"172a8e5054c1ca02b8a79e16bdfdb941b2206435cc86ee6cd3a9b50b092ed7a0","frame_index":0,"kind":"data","monotonic_ns":228823093308125,"payload":{"event_type":"price_change","market":"0xeb66215f2e9faa6449e30a02bab5b8ed7b79a38bf961f6b24d0073c9c2419250","price_changes":[{"asset_id":"60386828328910021732068595344565885737045900010034836345809386672230885527307","best_ask":"0.77","best_bid":"0.76","hash":"c1b5493d31abbbce4acec8859a69c3d75da7abda","price":"0.73","side":"BUY","size":"378.02"},{"asset_id":"69697746896130839564035629862476347944307040470122503199396727085502753297492","best_ask":"0.24","best_bid":"0.23","hash":"8c2fff03b7ab35098d428d0b6e7e385f44f500c2","price":"0.27","side":"SELL","size":"378.02"}],"timestamp":"1785126839880"},"payload_hash":"d9e6fb104a01dd49665c2d253f0831724a4281f00255b4f5aad94be0f9d0e1da","raw_frame":"{\"market\":\"0xeb66215f2e9faa6449e30a02bab5b8ed7b79a38bf961f6b24d0073c9c2419250\", \"price_changes\":[{\"asset_id\":\"60386828328910021732068595344565885737045900010034836345809386672230885527307\", \"price\":\"0.73\", \"size\":\"378.02\", \"side\":\"BUY\", \"hash\":\"c1b5493d31abbbce4acec8859a69c3d75da7abda\", \"best_bid\":\"0.76\", \"best_ask\":\"0.77\"}, {\"asset_id\":\"69697746896130839564035629862476347944307040470122503199396727085502753297492\", \"price\":\"0.27\", \"size\":\"378.02\", \"side\":\"SELL\", \"hash\":\"8c2fff03b7ab35098d428d0b6e7e385f44f500c2\", \"best_bid\":\"0.23\", \"best_ask\":\"0.24\"}], \"timestamp\":\"1785126839880\", \"event_type\":\"price_change\"}","received_at":"2026-07-27T04:33:59.825547Z","schema_version":"clob-market-ws.price_change.v1","sequence":null,"server_hash":null,"server_timestamp":"1785126839880","session_id":"e9443c7415a0419799bee9cfbb1a9e4d","source":"clob_market_ws"},"received_at":"2026-07-27T04:33:59.825547Z","record_id":"5dc70f50078ccf6fd9b7e7aaa491a7276e94da4a58156bb3e814dc2ee0d2bc13","schema_fingerprint":"4aa3821a28b0b7c2400bc59aba4bcc0a76e971dadd19610d3ad38c768e124dc7","schema_version":"edge-lab-recorder.raw.v1","sequence":null,"source":"clob_market_ws"}
{"event_at":"2026-07-27T04:33:59.884000Z","event_fingerprint":"e8f40f7044b70068cd88ec88881c1aaf8a0e11538ff84e1725ab5c16f54de05e","payload":{"connection_id":"0f4979d6978d463e9660b042fdcf555f","event_at":"2026-07-27T04:33:59.884000Z","event_type":"price_change","frame_hash":"ef731428d857be638e569ddf96d88da82cbc1866a348819b32833a143f688e39","frame_index":0,"kind":"data","monotonic_ns":228823095586333,"payload":{"event_type":"price_change","market":"0xeb66215f2e9faa6449e30a02bab5b8ed7b79a38bf961f6b24d0073c9c2419250","price_changes":[{"asset_id":"60386828328910021732068595344565885737045900010034836345809386672230885527307","best_ask":"0.77","best_bid":"0.76","hash":"f0282164d7d92be01ed83960fe2b80ac27c051b5","price":"0.8","side":"SELL","size":"51.31"},{"asset_id":"69697746896130839564035629862476347944307040470122503199396727085502753297492","best_ask":"0.24","best_bid":"0.23","hash":"a63926a00448a7ac76cce11b31f6408966159bcc","price":"0.2","side":"BUY","size":"51.31"}],"timestamp":"1785126839884"},"payload_hash":"871d6b765d782bdb11ddf6b3fa1d86bf46c2675915f91a36852fb8a4b6c31c2e","raw_frame":"{\"market\":\"0xeb66215f2e9faa6449e30a02bab5b8ed7b79a38bf961f6b24d0073c9c2419250\", \"price_changes\":[{\"asset_id\":\"60386828328910021732068595344565885737045900010034836345809386672230885527307\", \"price\":\"0.8\", \"size\":\"51.31\", \"side\":\"SELL\", \"hash\":\"f0282164d7d92be01ed83960fe2b80ac27c051b5\", \"best_bid\":\"0.76\", \"best_ask\":\"0.77\"}, {\"asset_id\":\"69697746896130839564035629862476347944307040470122503199396727085502753297492\", \"price\":\"0.2\", \"size\":\"51.31\", \"side\":\"BUY\", \"hash\":\"a63926a00448a7ac76cce11b31f6408966159bcc\", \"best_bid\":\"0.23\", \"best_ask\":\"0.24\"}], \"timestamp\":\"1785126839884\", \"event_type\":\"price_change\"}","received_at":"2026-07-27T04:33:59.827827Z","schema_version":"clob-market-ws.price_change.v1","sequence":null,"server_hash":null,"server_timestamp":"1785126839884","session_id":"e9443c7415a0419799bee9cfbb1a9e4d","source":"clob_market_ws"},"received_at":"2026-07-27T04:33:59.827827Z","record_id":"4767b8f503fd80eba6085a6530b56eb9b55b60114fc544868ab56660646b08ad","schema_fingerprint":"4aa3821a28b0b7c2400bc59aba4bcc0a76e971dadd19610d3ad38c768e124dc7","schema_version":"edge-lab-recorder.raw.v1","sequence":null,"source":"clob_market_ws"}
{"event_at":"2026-07-27T04:33:59.884000Z","event_fingerprint":"c907ddbe0a90f6e7b43d2e7614f832cc638bbb37152c50db8cff7364b3fa6c76","payload":{"connection_id":"0f4979d6978d463e9660b042fdcf555f","event_at":"2026-07-27T04:33:59.884000Z","event_type":"price_change","frame_hash":"ec61b594db78f4554a2821966ba537b8ff4bbd61c8f4412e1634e2dbf97d416f","frame_index":0,"kind":"data","monotonic_ns":228823097860000,"payload":{"event_type":"price_change","market":"0xeb66215f2e9faa6449e30a02bab5b8ed7b79a38bf961f6b24d0073c9c2419250","price_changes":[{"asset_id":"69697746896130839564035629862476347944307040470122503199396727085502753297492","best_ask":"0.24","best_bid":"0.23","hash":"e583bfd2edccf111598f48c8b139c3052eea6078","price":"0.27","side":"SELL","size":"408.06"},{"asset_id":"60386828328910021732068595344565885737045900010034836345809386672230885527307","best_ask":"0.77","best_bid":"0.76","hash":"388ccbc85ed67effb32e27df6e6a688555754512","price":"0.73","side":"BUY","size":"408.06"}],"timestamp":"1785126839884"},"payload_hash":"c6dc865388256970215088ae3d5313ad9f1ed59f2dbc4af1d1015f7c5f281f58","raw_frame":"{\"market\":\"0xeb66215f2e9faa6449e30a02bab5b8ed7b79a38bf961f6b24d0073c9c2419250\", \"price_changes\":[{\"asset_id\":\"69697746896130839564035629862476347944307040470122503199396727085502753297492\", \"price\":\"0.27\", \"size\":\"408.06\", \"side\":\"SELL\", \"hash\":\"e583bfd2edccf111598f48c8b139c3052eea6078\", \"best_bid\":\"0.23\", \"best_ask\":\"0.24\"}, {\"asset_id\":\"60386828328910021732068595344565885737045900010034836345809386672230885527307\", \"price\":\"0.73\", \"size\":\"408.06\", \"side\":\"BUY\", \"hash\":\"388ccbc85ed67effb32e27df6e6a688555754512\", \"best_bid\":\"0.76\", \"best_ask\":\"0.77\"}], \"timestamp\":\"1785126839884\", \"event_type\":\"price_change\"}","received_at":"2026-07-27T04:33:59.830099Z","schema_version":"clob-market-ws.price_change.v1","sequence":null,"server_hash":null,"server_timestamp":"1785126839884","session_id":"e9443c7415a0419799bee9cfbb1a9e4d","source":"clob_market_ws"},"received_at":"2026-07-27T04:33:59.830099Z","record_id":"0eafd106c6eebafc8e0a31c25a218a7ccf8daad101bfa2b78e38cbf4d2d95c75","schema_fingerprint":"4aa3821a28b0b7c2400bc59aba4bcc0a76e971dadd19610d3ad38c768e124dc7","schema_version":"edge-lab-recorder.raw.v1","sequence":null,"source":"clob_market_ws"}
{"event_at":"2026-07-27T04:34:00.005000Z","event_fingerprint":"1459d86d1f24aeebc9713e0fb412924e7e4b909e5f1bd32ea743a58c0323fefc","payload":{"connection_id":"0f4979d6978d463e9660b042fdcf555f","event_at":"2026-07-27T04:34:00.005000Z","event_type":"price_change","frame_hash":"60d0ff54ad3619e4f0307eaa4f757afdf0518e0c087b2569762ae9a224948c03","frame_index":0,"kind":"data","monotonic_ns":228823220183166,"payload":{"event_type":"price_change","market":"0xeb66215f2e9faa6449e30a02bab5b8ed7b79a38bf961f6b24d0073c9c2419250","price_changes":[{"asset_id":"60386828328910021732068595344565885737045900010034836345809386672230885527307","best_ask":"0.77","best_bid":"0.76","hash":"94fc617487c283b29efb2dd77cef6f6fbf7f007e","price":"0.01","side":"BUY","size":"7708.02"},{"asset_id":"69697746896130839564035629862476347944307040470122503199396727085502753297492","best_ask":"0.24","best_bid":"0.23","hash":"5ff4acc90b16bff81933a4750854b2fff49f0f09","price":"0.99","side":"SELL","size":"7708.02"}],"timestamp":"1785126840005"},"payload_hash":"fc6261f30947946cf8da2a979710911f7413beae3df63ab79af8d49049d3dd48","raw_frame":"{\"market\":\"0xeb66215f2e9faa6449e30a02bab5b8ed7b79a38bf961f6b24d0073c9c2419250\", \"price_changes\":[{\"asset_id\":\"60386828328910021732068595344565885737045900010034836345809386672230885527307\", \"price\":\"0.01\", \"size\":\"7708.02\", \"side\":\"BUY\", \"hash\":\"94fc617487c283b29efb2dd77cef6f6fbf7f007e\", \"best_bid\":\"0.76\", \"best_ask\":\"0.77\"}, {\"asset_id\":\"69697746896130839564035629862476347944307040470122503199396727085502753297492\", \"price\":\"0.99\", \"size\":\"7708.02\", \"side\":\"SELL\", \"hash\":\"5ff4acc90b16bff81933a4750854b2fff49f0f09\", \"best_bid\":\"0.23\", \"best_ask\":\"0.24\"}], \"timestamp\":\"1785126840005\", \"event_type\":\"price_change\"}","received_at":"2026-07-27T04:33:59.952432Z","schema_version":"clob-market-ws.price_change.v1","sequence":null,"server_hash":null,"server_timestamp":"1785126840005","session_id":"e9443c7415a0419799bee9cfbb1a9e4d","source":"clob_market_ws"},"received_at":"2026-07-27T04:33:59.952432Z","record_id":"a92b6b90776013888542afb1a5a4ce2768cf1ba97a34e36fdea42ef9b869c5a1","schema_fingerprint":"4aa3821a28b0b7c2400bc59aba4bcc0a76e971dadd19610d3ad38c768e124dc7","schema_version":"edge-lab-recorder.raw.v1","sequence":null,"source":"clob_market_ws"}
{"event_at":"2026-07-27T04:34:00.019000Z","event_fingerprint":"2a6765e0cd4d11521d39661ed357ab4d9c934c993e8c570de70f12ba21983fd0","payload":{"connection_id":"0f4979d6978d463e9660b042fdcf555f","event_at":"2026-07-27T04:34:00.019000Z","event_type":"price_change","frame_hash":"bb7e8d9e39907b992ade63eb5adcf778bebf441635a349452d6f54fd0e0805c0","frame_index":0,"kind":"data","monotonic_ns":228823241472333,"payload":{"event_type":"price_change","market":"0xeb66215f2e9faa6449e30a02bab5b8ed7b79a38bf961f6b24d0073c9c2419250","price_changes":[{"asset_id":"69697746896130839564035629862476347944307040470122503199396727085502753297492","best_ask":"0.24","best_bid":"0.23","hash":"cfb1d25b7741dc90565e89adbe5a87f88f995a96","price":"0.01","side":"BUY","size":"8019.91"},{"asset_id":"60386828328910021732068595344565885737045900010034836345809386672230885527307","best_ask":"0.77","best_bid":"0.76","hash":"a169c2200a31d3c32f0db953dad994ea7e0dbe96","price":"0.99","side":"SELL","size":"8019.91"}],"timestamp":"1785126840019"},"payload_hash":"27e831be1158c071751bdf296f7eb9ae7b8ac2f824325712df80c235f6b3c55e","raw_frame":"{\"market\":\"0xeb66215f2e9faa6449e30a02bab5b8ed7b79a38bf961f6b24d0073c9c2419250\", \"price_changes\":[{\"asset_id\":\"69697746896130839564035629862476347944307040470122503199396727085502753297492\", \"price\":\"0.01\", \"size\":\"8019.91\", \"side\":\"BUY\", \"hash\":\"cfb1d25b7741dc90565e89adbe5a87f88f995a96\", \"best_bid\":\"0.23\", \"best_ask\":\"0.24\"}, {\"asset_id\":\"60386828328910021732068595344565885737045900010034836345809386672230885527307\", \"price\":\"0.99\", \"size\":\"8019.91\", \"side\":\"SELL\", \"hash\":\"a169c2200a31d3c32f0db953dad994ea7e0dbe96\", \"best_bid\":\"0.76\", \"best_ask\":\"0.77\"}], \"timestamp\":\"1785126840019\", \"event_type\":\"price_change\"}","received_at":"2026-07-27T04:33:59.973716Z","schema_version":"clob-market-ws.price_change.v1","sequence":null,"server_hash":null,"server_timestamp":"1785126840019","session_id":"e9443c7415a0419799bee9cfbb1a9e4d","source":"clob_market_ws"},"received_at":"2026-07-27T04:33:59.973716Z","record_id":"6763297fed98964d030ff65ac4aa6fdff88ea729ff9a4ee39dd0001b942fd3ee","schema_fingerprint":"4aa3821a28b0b7c2400bc59aba4bcc0a76e971dadd19610d3ad38c768e124dc7","schema_version":"edge-lab-recorder.raw.v1","sequence":null,"source":"clob_market_ws"}
{"event_at":"2026-07-27T04:34:00.022000Z","event_fingerprint":"45844c0b3fdfeb0565217ec94e1770f1be14e163bedb9ef36f597e3e4e42b43a","payload":{"connection_id":"0f4979d6978d463e9660b042fdcf555f","event_at":"2026-07-27T04:34:00.022000Z","event_type":"price_change","frame_hash":"857ca31669cd4e4a81c503f8f6da3b2731d70629a6404088cff78100c01ebf56","frame_index":0,"kind":"data","monotonic_ns":228823283662583,"payload":{"event_type":"price_change","market":"0xeb66215f2e9faa6449e30a02bab5b8ed7b79a38bf961f6b24d0073c9c2419250","price_changes":[{"asset_id":"60386828328910021732068595344565885737045900010034836345809386672230885527307","best_ask":"0.77","best_bid":"0.76","hash":"b8db8b41942025688b2a3f20c06a2a76f79638d6","price":"0.72","side":"BUY","size":"72.2"},{"asset_id":"69697746896130839564035629862476347944307040470122503199396727085502753297492","best_ask":"0.24","best_bid":"0.23","hash":"0066db9533b7b5d67c6a4d9a31a8ffe0fb25b8da","price":"0.28","side":"SELL","size":"72.2"}],"timestamp":"1785126840022"},"payload_hash":"ba1b2fcce2199aa563800d2ae18e068c8fd4aa3668fd2a9bc3fad63db215078b","raw_frame":"{\"market\":\"0xeb66215f2e9faa6449e30a02bab5b8ed7b79a38bf961f6b24d0073c9c2419250\", \"price_changes\":[{\"asset_id\":\"60386828328910021732068595344565885737045900010034836345809386672230885527307\", \"price\":\"0.72\", \"size\":\"72.2\", \"side\":\"BUY\", \"hash\":\"b8db8b41942025688b2a3f20c06a2a76f79638d6\", \"best_bid\":\"0.76\", \"best_ask\":\"0.77\"}, {\"asset_id\":\"69697746896130839564035629862476347944307040470122503199396727085502753297492\", \"price\":\"0.28\", \"size\":\"72.2\", \"side\":\"SELL\", \"hash\":\"0066db9533b7b5d67c6a4d9a31a8ffe0fb25b8da\", \"best_bid\":\"0.23\", \"best_ask\":\"0.24\"}], \"timestamp\":\"1785126840022\", \"event_type\":\"price_change\"}","received_at":"2026-07-27T04:34:00.015894Z","schema_version":"clob-market-ws.price_change.v1","sequence":null,"server_hash":null,"server_timestamp":"1785126840022","session_id":"e9443c7415a0419799bee9cfbb1a9e4d","source":"clob_market_ws"},"received_at":"2026-07-27T04:34:00.015894Z","record_id":"ab892a2976d97bb29468fc6460508d614f6384684cd2d91f4b74ae5d17c3704a","schema_fingerprint":"4aa3821a28b0b7c2400bc59aba4bcc0a76e971dadd19610d3ad38c768e124dc7","schema_version":"edge-lab-recorder.raw.v1","sequence":null,"source":"clob_market_ws"}
{"event_at":"2026-07-27T04:34:00.025000Z","event_fingerprint":"ae042feb9448ebacab52741cdf6fd6b63c387ad9dbad0c9e2c6c1b106a1bc255","payload":{"connection_id":"0f4979d6978d463e9660b042fdcf555f","event_at":"2026-07-27T04:34:00.025000Z","event_type":"price_change","frame_hash":"fb9a90f1d8309aec12538b84a29441579fdfe215dec677c672b063749bb4a9e5","frame_index":0,"kind":"data","monotonic_ns":228823285241000,"payload":{"event_type":"price_change","market":"0xeb66215f2e9faa6449e30a02bab5b8ed7b79a38bf961f6b24d0073c9c2419250","price_changes":[{"asset_id":"69697746896130839564035629862476347944307040470122503199396727085502753297492","best_ask":"0.24","best_bid":"0.23","hash":"b6a19cd1c67959c03d84bb159d0cbea35ee0f9bd","price":"0.01","side":"BUY","size":"8024.91"},{"asset_id":"60386828328910021732068595344565885737045900010034836345809386672230885527307","best_ask":"0.77","best_bid":"0.76","hash":"6ab295225341c3a740e7ad947e804030b1f547f5","price":"0.99","side":"SELL","size":"8024.91"}],"timestamp":"1785126840025"},"payload_hash":"95f2fea0c47176a8c209e6d0a026715e1c2cc0d5c26c120aab8999c55ca3031e","raw_frame":"{\"market\":\"0xeb66215f2e9faa6449e30a02bab5b8ed7b79a38bf961f6b24d0073c9c2419250\", \"price_changes\":[{\"asset_id\":\"69697746896130839564035629862476347944307040470122503199396727085502753297492\", \"price\":\"0.01\", \"size\":\"8024.91\", \"side\":\"BUY\", \"hash\":\"b6a19cd1c67959c03d84bb159d0cbea35ee0f9bd\", \"best_bid\":\"0.23\", \"best_ask\":\"0.24\"}, {\"asset_id\":\"60386828328910021732068595344565885737045900010034836345809386672230885527307\", \"price\":\"0.99\", \"size\":\"8024.91\", \"side\":\"SELL\", \"hash\":\"6ab295225341c3a740e7ad947e804030b1f547f5\", \"best_bid\":\"0.76\", \"best_ask\":\"0.77\"}], \"timestamp\":\"1785126840025\", \"event_type\":\"price_change\"}","received_at":"2026-07-27T04:34:00.017485Z","schema_version":"clob-market-ws.price_change.v1","sequence":null,"server_hash":null,"server_timestamp":"1785126840025","session_id":"e9443c7415a0419799bee9cfbb1a9e4d","source":"clob_market_ws"},"received_at":"2026-07-27T04:34:00.017485Z","record_id":"83c73d5fc22276eadc693252e1a1b4d19f4c49fc96df76886334585a56842cbd","schema_fingerprint":"4aa3821a28b0b7c2400bc59aba4bcc0a76e971dadd19610d3ad38c768e124dc7","schema_version":"edge-lab-recorder.raw.v1","sequence":null,"source":"clob_market_ws"}
{"event_at":"2026-07-27T04:34:00.029000Z","event_fingerprint":"35a379d43bdccfaef7bf05c29a85423bbaaa3eea314749badb8a54ab4e943740","payload":{"connection_id":"0f4979d6978d463e9660b042fdcf555f","event_at":"2026-07-27T04:34:00.029000Z","event_type":"price_change","frame_hash":"7cc4c454bc2d734c51c3defd896546c2eebf659dbe00c54a7aaaca9b6886d111","frame_index":0,"kind":"data","monotonic_ns":228823286424666,"payload":{"event_type":"price_change","market":"0xeb66215f2e9faa6449e30a02bab5b8ed7b79a38bf961f6b24d0073c9c2419250","price_changes":[{"asset_id":"69697746896130839564035629862476347944307040470122503199396727085502753297492","best_ask":"0.24","best_bid":"0.23","hash":"c2dea10a04817f46f0f1b7e7b8964a66f7a14f75","price":"0.14","side":"BUY","size":"157.65"},{"asset_id":"60386828328910021732068595344565885737045900010034836345809386672230885527307","best_ask":"0.77","best_bid":"0.76","hash":"e6f75f54d4a7d255aa7b9364663f31c4179873e5","price":"0.86","side":"SELL","size":"157.65"}],"timestamp":"1785126840029"},"payload_hash":"914493555f81efe0205efd25f768ebc5342165cf7c24f8373639c8d1a5dc7ebb","raw_frame":"{\"market\":\"0xeb66215f2e9faa6449e30a02bab5b8ed7b79a38bf961f6b24d0073c9c2419250\", \"price_changes\":[{\"asset_id\":\"69697746896130839564035629862476347944307040470122503199396727085502753297492\", \"price\":\"0.14\", \"size\":\"157.65\", \"side\":\"BUY\", \"hash\":\"c2dea10a04817f46f0f1b7e7b8964a66f7a14f75\", \"best_bid\":\"0.23\", \"best_ask\":\"0.24\"}, {\"asset_id\":\"60386828328910021732068595344565885737045900010034836345809386672230885527307\", \"price\":\"0.86\", \"size\":\"157.65\", \"side\":\"SELL\", \"hash\":\"e6f75f54d4a7d255aa7b9364663f31c4179873e5\", \"best_bid\":\"0.76\", \"best_ask\":\"0.77\"}], \"timestamp\":\"1785126840029\", \"event_type\":\"price_change\"}","received_at":"2026-07-27T04:34:00.018666Z","schema_version":"clob-market-ws.price_change.v1","sequence":null,"server_hash":null,"server_timestamp":"1785126840029","session_id":"e9443c7415a0419799bee9cfbb1a9e4d","source":"clob_market_ws"},"received_at":"2026-07-27T04:34:00.018666Z","record_id":"439bdb1ae4a08b9f811af6da90be8f343175a46fdd0c959c990b8c449c699ff6","schema_fingerprint":"4aa3821a28b0b7c2400bc59aba4bcc0a76e971dadd19610d3ad38c768e124dc7","schema_version":"edge-lab-recorder.raw.v1","sequence":null,"source":"clob_market_ws"}
{"event_at":"2026-07-27T04:34:00.030000Z","event_fingerprint":"bcfbe867705b0d4753d5cc08d468c887909b079d56964681dd9896a9b81cc797","payload":{"connection_id":"0f4979d6978d463e9660b042fdcf555f","event_at":"2026-07-27T04:34:00.030000Z","event_type":"price_change","frame_hash":"5027d75c9b594e3db85887d1a7a715f8a97c3e595fad8fdd4b25f9e4f631ded6","frame_index":0,"kind":"data","monotonic_ns":228823287281333,"payload":{"event_type":"price_change","market":"0xeb66215f2e9faa6449e30a02bab5b8ed7b79a38bf961f6b24d0073c9c2419250","price_changes":[{"asset_id":"60386828328910021732068595344565885737045900010034836345809386672230885527307","best_ask":"0.77","best_bid":"0.76","hash":"d9bb176b2112902a432da7c171874d158de853f6","price":"0.8","side":"SELL","size":"46.27"},{"asset_id":"69697746896130839564035629862476347944307040470122503199396727085502753297492","best_ask":"0.24","best_bid":"0.23","hash":"f5e54c077a968344ecc8855567ce882932eb10e4","price":"0.2","side":"BUY","size":"46.27"}],"timestamp":"1785126840030"},"payload_hash":"3a6573a07aa6fc33adfc4ba6644fba501e638c6db5e6ef6fc13908785954f004","raw_frame":"{\"market\":\"0xeb66215f2e9faa6449e30a02bab5b8ed7b79a38bf961f6b24d0073c9c2419250\", \"price_changes\":[{\"asset_id\":\"60386828328910021732068595344565885737045900010034836345809386672230885527307\", \"price\":\"0.8\", \"size\":\"46.27\", \"side\":\"SELL\", \"hash\":\"d9bb176b2112902a432da7c171874d158de853f6\", \"best_bid\":\"0.76\", \"best_ask\":\"0.77\"}, {\"asset_id\":\"69697746896130839564035629862476347944307040470122503199396727085502753297492\", \"price\":\"0.2\", \"size\":\"46.27\", \"side\":\"BUY\", \"hash\":\"f5e54c077a968344ecc8855567ce882932eb10e4\", \"best_bid\":\"0.23\", \"best_ask\":\"0.24\"}], \"timestamp\":\"1785126840030\", \"event_type\":\"price_change\"}","received_at":"2026-07-27T04:34:00.019528Z","schema_version":"clob-market-ws.price_change.v1","sequence":null,"server_hash":null,"server_timestamp":"1785126840030","session_id":"e9443c7415a0419799bee9cfbb1a9e4d","source":"clob_market_ws"},"received_at":"2026-07-27T04:34:00.019528Z","record_id":"055127d32218b4c3d608ebc1d5d041c5bae53328642a1ea67caa2323063e4571","schema_fingerprint":"4aa3821a28b0b7c2400bc59aba4bcc0a76e971dadd19610d3ad38c768e124dc7","schema_version":"edge-lab-recorder.raw.v1","sequence":null,"source":"clob_market_ws"}
{"event_at":"2026-07-27T04:34:00.030000Z","event_fingerprint":"906c682b4dca4b9fce727c8f88924ff05e09ada7e357198aca4334b1822372e1","payload":{"connection_id":"0f4979d6978d463e9660b042fdcf555f","event_at":"2026-07-27T04:34:00.030000Z","event_type":"price_change","frame_hash":"fe80a327406b320f7e6551d24ee495ce7317bab5e75e75375bfef636587d6913","frame_index":0,"kind":"data","monotonic_ns":228823288271750,"payload":{"event_type":"price_change","market":"0xeb66215f2e9faa6449e30a02bab5b8ed7b79a38bf961f6b24d0073c9c2419250","price_changes":[{"asset_id":"60386828328910021732068595344565885737045900010034836345809386672230885527307","best_ask":"0.77","best_bid":"0.76","hash":"d9bb176b2112902a432da7c171874d158de853f6","price":"0.7","side":"BUY","size":"209.74"},{"asset_id":"69697746896130839564035629862476347944307040470122503199396727085502753297492","best_ask":"0.24","best_bid":"0.23","hash":"f5e54c077a968344ecc8855567ce882932eb10e4","price":"0.3","side":"SELL","size":"209.74"}],"timestamp":"1785126840030"},"payload_hash":"2cdeeb8dfda7ff2d246b8210cd3a8bfe370c214198fbf0ff2c3a38533529d2b3","raw_frame":"{\"market\":\"0xeb66215f2e9faa6449e30a02bab5b8ed7b79a38bf961f6b24d0073c9c2419250\", \"price_changes\":[{\"asset_id\":\"60386828328910021732068595344565885737045900010034836345809386672230885527307\", \"price\":\"0.7\", \"size\":\"209.74\", \"side\":\"BUY\", \"hash\":\"d9bb176b2112902a432da7c171874d158de853f6\", \"best_bid\":\"0.76\", \"best_ask\":\"0.77\"}, {\"asset_id\":\"69697746896130839564035629862476347944307040470122503199396727085502753297492\", \"price\":\"0.3\", \"size\":\"209.74\", \"side\":\"SELL\", \"hash\":\"f5e54c077a968344ecc8855567ce882932eb10e4\", \"best_bid\":\"0.23\", \"best_ask\":\"0.24\"}], \"timestamp\":\"1785126840030\", \"event_type\":\"price_change\"}","received_at":"2026-07-27T04:34:00.020519Z","schema_version":"clob-market-ws.price_change.v1","sequence":null,"server_hash":null,"server_timestamp":"1785126840030","session_id":"e9443c7415a0419799bee9cfbb1a9e4d","source":"clob_market_ws"},"received_at":"2026-07-27T04:34:00.020519Z","record_id":"d064f333c1b69105e5f7419cbcb8c2e1e5f382ccaa91bfcd25a5df759d8ff416","schema_fingerprint":"4aa3821a28b0b7c2400bc59aba4bcc0a76e971dadd19610d3ad38c768e124dc7","schema_version":"edge-lab-recorder.raw.v1","sequence":null,"source":"clob_market_ws"}
{"event_at":"2026-07-27T04:34:00.030000Z","event_fingerprint":"1aab4d3dd7239b1166a05b5ccbc3bf0e44446fdfb50b29cc8589a7f9782e1680","payload":{"connection_id":"0f4979d6978d463e9660b042fdcf555f","event_at":"2026-07-27T04:34:00.030000Z","event_type":"price_change","frame_hash":"7ae775d10ab5cdebff9bef63821cdfbcbef1bd01f036cf048c4bfe764a30a2c4","frame_index":0,"kind":"data","monotonic_ns":228823289275958,"payload":{"event_type":"price_change","market":"0xeb66215f2e9faa6449e30a02bab5b8ed7b79a38bf961f6b24d0073c9c2419250","price_changes":[{"asset_id":"60386828328910021732068595344565885737045900010034836345809386672230885527307","best_ask":"0.77","best_bid":"0.76","hash":"d9bb176b2112902a432da7c171874d158de853f6","price":"0.73","side":"BUY","size":"367.06"},{"asset_id":"69697746896130839564035629862476347944307040470122503199396727085502753297492","best_ask":"0.24","best_bid":"0.23","hash":"f5e54c077a968344ecc8855567ce882932eb10e4","price":"0.27","side":"SELL","size":"367.06"}],"timestamp":"1785126840030"},"payload_hash":"27c8bb39591a8ef7e492f0191874bfae3c8fae6cab352f1de3bd28bb7d356a12","raw_frame":"{\"market\":\"0xeb66215f2e9faa6449e30a02bab5b8ed7b79a38bf961f6b24d0073c9c2419250\", \"price_changes\":[{\"asset_id\":\"60386828328910021732068595344565885737045900010034836345809386672230885527307\", \"price\":\"0.73\", \"size\":\"367.06\", \"side\":\"BUY\", \"hash\":\"d9bb176b2112902a432da7c171874d158de853f6\", \"best_bid\":\"0.76\", \"best_ask\":\"0.77\"}, {\"asset_id\":\"69697746896130839564035629862476347944307040470122503199396727085502753297492\", \"price\":\"0.27\", \"size\":\"367.06\", \"side\":\"SELL\", \"hash\":\"f5e54c077a968344ecc8855567ce882932eb10e4\", \"best_bid\":\"0.23\", \"best_ask\":\"0.24\"}], \"timestamp\":\"1785126840030\", \"event_type\":\"price_change\"}","received_at":"2026-07-27T04:34:00.021524Z","schema_version":"clob-market-ws.price_change.v1","sequence":null,"server_hash":null,"server_timestamp":"1785126840030","session_id":"e9443c7415a0419799bee9cfbb1a9e4d","source":"clob_market_ws"},"received_at":"2026-07-27T04:34:00.021524Z","record_id":"5f92b592841dc1a4dd1bd06da67aac2f649eef641f000b1221fcfb4c512ca378","schema_fingerprint":"4aa3821a28b0b7c2400bc59aba4bcc0a76e971dadd19610d3ad38c768e124dc7","schema_version":"edge-lab-recorder.raw.v1","sequence":null,"source":"clob_market_ws"}
{"event_at":"2026-07-27T04:34:00.030000Z","event_fingerprint":"338a49a8e8bd29a316ea1ae95d9cb7bbb8f983098dfff622b9da58d27b480754","payload":{"connection_id":"0f4979d6978d463e9660b042fdcf555f","event_at":"2026-07-27T04:34:00.030000Z","event_type":"price_change","frame_hash":"93417c14445cb4e844a56de5dda785df4cdcd8aed32ed25a1ff7fafe5e37fc93","frame_index":0,"kind":"data","monotonic_ns":228823290219083,"payload":{"event_type":"price_change","market":"0xeb66215f2e9faa6449e30a02bab5b8ed7b79a38bf961f6b24d0073c9c2419250","price_changes":[{"asset_id":"69697746896130839564035629862476347944307040470122503199396727085502753297492","best_ask":"0.24","best_bid":"0.23","hash":"f5e54c077a968344ecc8855567ce882932eb10e4","price":"0.27","side":"SELL","size":"367.06"},{"asset_id":"60386828328910021732068595344565885737045900010034836345809386672230885527307","best_ask":"0.77","best_bid":"0.76","hash":"d9bb176b2112902a432da7c171874d158de853f6","price":"0.73","side":"BUY","size":"367.06"}],"timestamp":"1785126840030"},"payload_hash":"a7106b79eea4451d404ab4ba7f8d06b9a3d2e29c4ce47c4c910668b851460e40","raw_frame":"{\"market\":\"0xeb66215f2e9faa6449e30a02bab5b8ed7b79a38bf961f6b24d0073c9c2419250\", \"price_changes\":[{\"asset_id\":\"69697746896130839564035629862476347944307040470122503199396727085502753297492\", \"price\":\"0.27\", \"size\":\"367.06\", \"side\":\"SELL\", \"hash\":\"f5e54c077a968344ecc8855567ce882932eb10e4\", \"best_bid\":\"0.23\", \"best_ask\":\"0.24\"}, {\"asset_id\":\"60386828328910021732068595344565885737045900010034836345809386672230885527307\", \"price\":\"0.73\", \"size\":\"367.06\", \"side\":\"BUY\", \"hash\":\"d9bb176b2112902a432da7c171874d158de853f6\", \"best_bid\":\"0.76\", \"best_ask\":\"0.77\"}], \"timestamp\":\"1785126840030\", \"event_type\":\"price_change\"}","received_at":"2026-07-27T04:34:00.022467Z","schema_version":"clob-market-ws.price_change.v1","sequence":null,"server_hash":null,"server_timestamp":"1785126840030","session_id":"e9443c7415a0419799bee9cfbb1a9e4d","source":"clob_market_ws"},"received_at":"2026-07-27T04:34:00.022467Z","record_id":"2bf98ae76f7931b89a39577c32a7652eb1810894e6e9ceb99ea305faf89acfd4","schema_fingerprint":"4aa3821a28b0b7c2400bc59aba4bcc0a76e971dadd19610d3ad38c768e124dc7","schema_version":"edge-lab-recorder.raw.v1","sequence":null,"source":"clob_market_ws"}
{"event_at":"2026-07-27T04:34:00.033000Z","event_fingerprint":"8ae4a1f46cd5f684056b8c956fbf7c5803b917eec5f78cfb36ca3095985b32e3","payload":{"connection_id":"0f4979d6978d463e9660b042fdcf555f","event_at":"2026-07-27T04:34:00.033000Z","event_type":"price_change","frame_hash":"b8bdcfa003f7e561d5684203df38528cc8337b0ecb6d7bc4b0cd1b8bc37cd529","frame_index":0,"kind":"data","monotonic_ns":228823291156083,"payload":{"event_type":"price_change","market":"0xeb66215f2e9faa6449e30a02bab5b8ed7b79a38bf961f6b24d0073c9c2419250","price_changes":[{"asset_id":"69697746896130839564035629862476347944307040470122503199396727085502753297492","best_ask":"0.24","best_bid":"0.23","hash":"f908b681c2df2e104b5abfaa69d7c3f4ddb50535","price":"0.17","side":"BUY","size":"154.81"},{"asset_id":"60386828328910021732068595344565885737045900010034836345809386672230885527307","best_ask":"0.77","best_bid":"0.76","hash":"ac3208ba3ec1cc4b343149d5d966abd8a4fb4d83","price":"0.83","side":"SELL","size":"154.81"}],"timestamp":"1785126840033"},"payload_hash":"94e39d286b86f6823d3eccf6e7ae3b3506eb71583177150213b0283ddf1187d2","raw_frame":"{\"market\":\"0xeb66215f2e9faa6449e30a02bab5b8ed7b79a38bf961f6b24d0073c9c2419250\", \"price_changes\":[{\"asset_id\":\"69697746896130839564035629862476347944307040470122503199396727085502753297492\", \"price\":\"0.17\", \"size\":\"154.81\", \"side\":\"BUY\", \"hash\":\"f908b681c2df2e104b5abfaa69d7c3f4ddb50535\", \"best_bid\":\"0.23\", \"best_ask\":\"0.24\"}, {\"asset_id\":\"60386828328910021732068595344565885737045900010034836345809386672230885527307\", \"price\":\"0.83\", \"size\":\"154.81\", \"side\":\"SELL\", \"hash\":\"ac3208ba3ec1cc4b343149d5d966abd8a4fb4d83\", \"best_bid\":\"0.76\", \"best_ask\":\"0.77\"}], \"timestamp\":\"1785126840033\", \"event_type\":\"price_change\"}","received_at":"2026-07-27T04:34:00.023404Z","schema_version":"clob-market-ws.price_change.v1","sequence":null,"server_hash":null,"server_timestamp":"1785126840033","session_id":"e9443c7415a0419799bee9cfbb1a9e4d","source":"clob_market_ws"},"received_at":"2026-07-27T04:34:00.023404Z","record_id":"3a7afd781d9f7bcc344c5a028ad371c8920e14308b6dc6a4ecede08aeb08e917","schema_fingerprint":"4aa3821a28b0b7c2400bc59aba4bcc0a76e971dadd19610d3ad38c768e124dc7","schema_version":"edge-lab-recorder.raw.v1","sequence":null,"source":"clob_market_ws"}
{"event_at":"2026-07-27T04:34:00.034000Z","event_fingerprint":"13159ff4639251d5e7086114876a36efdbabf48f759174dd0999ac4871294842","payload":{"connection_id":"0f4979d6978d463e9660b042fdcf555f","event_at":"2026-07-27T04:34:00.034000Z","event_type":"price_change","frame_hash":"424c06cac23ebcae843c6444992545ea33dff18a51829659c0032d870e8dc8bb","frame_index":0,"kind":"data","monotonic_ns":228823292023083,"payload":{"event_type":"price_change","market":"0xeb66215f2e9faa6449e30a02bab5b8ed7b79a38bf961f6b24d0073c9c2419250","price_changes":[{"asset_id":"69697746896130839564035629862476347944307040470122503199396727085502753297492","best_ask":"0.24","best_bid":"0.23","hash":"fc22447311a56fe9ae3c4f07cc478ecc12ed0a02","price":"0.18","side":"BUY","size":"170.82"},{"asset_id":"60386828328910021732068595344565885737045900010034836345809386672230885527307","best_ask":"0.77","best_bid":"0.76","hash":"7343b6f73dde515ab7a5d5a492a68805d31f3551","price":"0.82","side":"SELL","size":"170.82"}],"timestamp":"1785126840034"},"payload_hash":"050588ad508777abf2ddf8b924152a0bd5d13ab51608a95e649155c93b328a04","raw_frame":"{\"market\":\"0xeb66215f2e9faa6449e30a02bab5b8ed7b79a38bf961f6b24d0073c9c2419250\", \"price_changes\":[{\"asset_id\":\"69697746896130839564035629862476347944307040470122503199396727085502753297492\", \"price\":\"0.18\", \"size\":\"170.82\", \"side\":\"BUY\", \"hash\":\"fc22447311a56fe9ae3c4f07cc478ecc12ed0a02\", \"best_bid\":\"0.23\", \"best_ask\":\"0.24\"}, {\"asset_id\":\"60386828328910021732068595344565885737045900010034836345809386672230885527307\", \"price\":\"0.82\", \"size\":\"170.82\", \"side\":\"SELL\", \"hash\":\"7343b6f73dde515ab7a5d5a492a68805d31f3551\", \"best_bid\":\"0.76\", \"best_ask\":\"0.77\"}], \"timestamp\":\"1785126840034\", \"event_type\":\"price_change\"}","received_at":"2026-07-27T04:34:00.024272Z","schema_version":"clob-market-ws.price_change.v1","sequence":null,"server_hash":null,"server_timestamp":"1785126840034","session_id":"e9443c7415a0419799bee9cfbb1a9e4d","source":"clob_market_ws"},"received_at":"2026-07-27T04:34:00.024272Z","record_id":"4fac23c5ea23c02b9511aa10c3c3058a271dd1afba53521445d92375567fe595","schema_fingerprint":"4aa3821a28b0b7c2400bc59aba4bcc0a76e971dadd19610d3ad38c768e124dc7","schema_version":"edge-lab-recorder.raw.v1","sequence":null,"source":"clob_market_ws"}
{"event_at":"2026-07-27T04:34:00.038000Z","event_fingerprint":"001577baac7a1e5eae3fe86a75efe38ff716da6b35f2626c2ceaeab5f065099b","payload":{"connection_id":"0f4979d6978d463e9660b042fdcf555f","event_at":"2026-07-27T04:34:00.038000Z","event_type":"price_change","frame_hash":"bc204786a1480f73c0834d44394944a01073d3644e814f512dfc235317af066a","frame_index":0,"kind":"data","monotonic_ns":228823292771875,"payload":{"event_type":"price_change","market":"0xeb66215f2e9faa6449e30a02bab5b8ed7b79a38bf961f6b24d0073c9c2419250","price_changes":[{"asset_id":"69697746896130839564035629862476347944307040470122503199396727085502753297492","best_ask":"0.24","best_bid":"0.23","hash":"d8de13a643aeede0a86f3a6d0fcd0ab2626bfc5f","price":"0.01","side":"BUY","size":"8019.91"},{"asset_id":"60386828328910021732068595344565885737045900010034836345809386672230885527307","best_ask":"0.77","best_bid":"0.76","hash":"54524948b5fcce980d0eeb489a45d0436299cd9a","price":"0.99","side":"SELL","size":"8019.91"}],"timestamp":"1785126840038"},"payload_hash":"c43bbfe9ea68eda6b4248f4286392c9074e4d10f39f2071c5521c2d0c4a7f053","raw_frame":"{\"market\":\"0xeb66215f2e9faa6449e30a02bab5b8ed7b79a38bf961f6b24d0073c9c2419250\", \"price_changes\":[{\"asset_id\":\"69697746896130839564035629862476347944307040470122503199396727085502753297492\", \"price\":\"0.01\", \"size\":\"8019.91\", \"side\":\"BUY\", \"hash\":\"d8de13a643aeede0a86f3a6d0fcd0ab2626bfc5f\", \"best_bid\":\"0.23\", \"best_ask\":\"0.24\"}, {\"asset_id\":\"60386828328910021732068595344565885737045900010034836345809386672230885527307\", \"price\":\"0.99\", \"size\":\"8019.91\", \"side\":\"SELL\", \"hash\":\"54524948b5fcce980d0eeb489a45d0436299cd9a\", \"best_bid\":\"0.76\", \"best_ask\":\"0.77\"}], \"timestamp\":\"1785126840038\", \"event_type\":\"price_change\"}","received_at":"2026-07-27T04:34:00.025021Z","schema_version":"clob-market-ws.price_change.v1","sequence":null,"server_hash":null,"server_timestamp":"1785126840038","session_id":"e9443c7415a0419799bee9cfbb1a9e4d","source":"clob_market_ws"},"received_at":"2026-07-27T04:34:00.025021Z","record_id":"b45c7ce5f4a9de23f9503e52369585c1b52df390225656bd0027faebe50f03c0","schema_fingerprint":"4aa3821a28b0b7c2400bc59aba4bcc0a76e971dadd19610d3ad38c768e124dc7","schema_version":"edge-lab-recorder.raw.v1","sequence":null,"source":"clob_market_ws"}
{"event_at":"2026-07-27T04:34:00.047000Z","event_fingerprint":"1fd96f679f1f7d380ffb28e10febb9410beda42ad46d1d42245b573c8029b599","payload":{"connection_id":"0f4979d6978d463e9660b042fdcf555f","event_at":"2026-07-27T04:34:00.047000Z","event_type":"price_change","frame_hash":"bf682886a39c0ccfb052ea057f0b97eb69765f2405878264ee36815dc92669d9","frame_index":0,"kind":"data","monotonic_ns":228823293567875,"payload":{"event_type":"price_change","market":"0xeb66215f2e9faa6449e30a02bab5b8ed7b79a38bf961f6b24d0073c9c2419250","price_changes":[{"asset_id":"69697746896130839564035629862476347944307040470122503199396727085502753297492","best_ask":"0.24","best_bid":"0.23","hash":"18a8a6fa2edd78b33dd42a19d6fa164696c117df","price":"0.01","side":"BUY","size":"8014.91"},{"asset_id":"60386828328910021732068595344565885737045900010034836345809386672230885527307","best_ask":"0.77","best_bid":"0.76","hash":"edc40edec5982613e67fec979622442e0af09a26","price":"0.99","side":"SELL","size":"8014.91"}],"timestamp":"1785126840047"},"payload_hash":"f3f3768ec43c7cd00e30b5a1c0d4ade2e876699066a7e0feeec968c1f016cfd9","raw_frame":"{\"market\":\"0xeb66215f2e9faa6449e30a02bab5b8ed7b79a38bf961f6b24d0073c9c2419250\", \"price_changes\":[{\"asset_id\":\"69697746896130839564035629862476347944307040470122503199396727085502753297492\", \"price\":\"0.01\", \"size\":\"8014.91\", \"side\":\"BUY\", \"hash\":\"18a8a6fa2edd78b33dd42a19d6fa164696c117df\", \"best_bid\":\"0.23\", \"best_ask\":\"0.24\"}, {\"asset_id\":\"60386828328910021732068595344565885737045900010034836345809386672230885527307\", \"price\":\"0.99\", \"size\":\"8014.91\", \"side\":\"SELL\", \"hash\":\"edc40edec5982613e67fec979622442e0af09a26\", \"best_bid\":\"0.76\", \"best_ask\":\"0.77\"}], \"timestamp\":\"1785126840047\", \"event_type\":\"price_change\"}","received_at":"2026-07-27T04:34:00.025814Z","schema_version":"clob-market-ws.price_change.v1","sequence":null,"server_hash":null,"server_timestamp":"1785126840047","session_id":"e9443c7415a0419799bee9cfbb1a9e4d","source":"clob_market_ws"},"received_at":"2026-07-27T04:34:00.025814Z","record_id":"306ec07306148f19f0c024775e1247619efbc9a134cc5e355c1471338663d592","schema_fingerprint":"4aa3821a28b0b7c2400bc59aba4bcc0a76e971dadd19610d3ad38c768e124dc7","schema_version":"edge-lab-recorder.raw.v1","sequence":null,"source":"clob_market_ws"}
{"event_at":"2026-07-27T04:34:00.069000Z","event_fingerprint":"5babef360771bee9fb69da60b76bd3b87f9e39a013dfa57d41e5cdb1f0d95fb1","payload":{"connection_id":"0f4979d6978d463e9660b042fdcf555f","event_at":"2026-07-27T04:34:00.069000Z","event_type":"price_change","frame_hash":"ad280b2ac2f32e5b56d392b4238f5c0d19eb7e0f5f3a1095388400b7fa2b969e","frame_index":0,"kind":"data","monotonic_ns":228823294453041,"payload":{"event_type":"price_change","market":"0xeb66215f2e9faa6449e30a02bab5b8ed7b79a38bf961f6b24d0073c9c2419250","price_changes":[{"asset_id":"69697746896130839564035629862476347944307040470122503199396727085502753297492","best_ask":"0.24","best_bid":"0.23","hash":"0fb10ee593880bb1a7426afd26557c42c560a1f9","price":"0.18","side":"BUY","size":"150.52"},{"asset_id":"60386828328910021732068595344565885737045900010034836345809386672230885527307","best_ask":"0.77","best_bid":"0.76","hash":"5f07e623ba579ac432b58cbf58497524e78ab66e","price":"0.82","side":"SELL","size":"150.52"}],"timestamp":"1785126840069"},"payload_hash":"567c64e6e87a1cc6674dd49445b2e82520623fbb9322415ae88c0086520c8dba","raw_frame":"{\"market\":\"0xeb66215f2e9faa6449e30a02bab5b8ed7b79a38bf961f6b24d0073c9c2419250\", \"price_changes\":[{\"asset_id\":\"69697746896130839564035629862476347944307040470122503199396727085502753297492\", \"price\":\"0.18\", \"size\":\"150.52\", \"side\":\"BUY\", \"hash\":\"0fb10ee593880bb1a7426afd26557c42c560a1f9\", \"best_bid\":\"0.23\", \"best_ask\":\"0.24\"}, {\"asset_id\":\"60386828328910021732068595344565885737045900010034836345809386672230885527307\", \"price\":\"0.82\", \"size\":\"150.52\", \"side\":\"SELL\", \"hash\":\"5f07e623ba579ac432b58cbf58497524e78ab66e\", \"best_bid\":\"0.76\", \"best_ask\":\"0.77\"}], \"timestamp\":\"1785126840069\", \"event_type\":\"price_change\"}","received_at":"2026-07-27T04:34:00.026702Z","schema_version":"clob-market-ws.price_change.v1","sequence":null,"server_hash":null,"server_timestamp":"1785126840069","session_id":"e9443c7415a0419799bee9cfbb1a9e4d","source":"clob_market_ws"},"received_at":"2026-07-27T04:34:00.026702Z","record_id":"f304b0084386174e1839662f17f697c3d7f224fc0cf2638f280a13a87c2a9fe4","schema_fingerprint":"4aa3821a28b0b7c2400bc59aba4bcc0a76e971dadd19610d3ad38c768e124dc7","schema_version":"edge-lab-recorder.raw.v1","sequence":null,"source":"clob_market_ws"}
{"event_at":"2026-07-27T04:34:00.073000Z","event_fingerprint":"c5a4af1aa0a600dbb20a06d7b1522662528bcaaf3b0c3006f82526e1f1d1f9a0","payload":{"connection_id":"0f4979d6978d463e9660b042fdcf555f","event_at":"2026-07-27T04:34:00.073000Z","event_type":"price_change","frame_hash":"1e50870bbad66f72f7b57f8cb97be6cfa001c5c36ad0e2f7e206b146766e7382","frame_index":0,"kind":"data","monotonic_ns":228823309294083,"payload":{"event_type":"price_change","market":"0xeb66215f2e9faa6449e30a02bab5b8ed7b79a38bf961f6b24d0073c9c2419250","price_changes":[{"asset_id":"69697746896130839564035629862476347944307040470122503199396727085502753297492","best_ask":"0.24","best_bid":"0.23","hash":"7a106b0e8d728029c8dd4fdcf40fa8dfa5dcde91","price":"0.16","side":"BUY","size":"794.26"},{"asset_id":"60386828328910021732068595344565885737045900010034836345809386672230885527307","best_ask":"0.77","best_bid":"0.76","hash":"eef1e85cd44853e91eba5c67b11899c5e7685b89","price":"0.84","side":"SELL","size":"794.26"}],"timestamp":"1785126840073"},"payload_hash":"9c4770a75d84191633937d004c48f273320ac20b1acfdd7aa4924f0e70fdc1b5","raw_frame":"{\"market\":\"0xeb66215f2e9faa6449e30a02bab5b8ed7b79a38bf961f6b24d0073c9c2419250\", \"price_changes\":[{\"asset_id\":\"69697746896130839564035629862476347944307040470122503199396727085502753297492\", \"price\":\"0.16\", \"size\":\"794.26\", \"side\":\"BUY\", \"hash\":\"7a106b0e8d728029c8dd4fdcf40fa8dfa5dcde91\", \"best_bid\":\"0.23\", \"best_ask\":\"0.24\"}, {\"asset_id\":\"60386828328910021732068595344565885737045900010034836345809386672230885527307\", \"price\":\"0.84\", \"size\":\"794.26\", \"side\":\"SELL\", \"hash\":\"eef1e85cd44853e91eba5c67b11899c5e7685b89\", \"best_bid\":\"0.76\", \"best_ask\":\"0.77\"}], \"timestamp\":\"1785126840073\", \"event_type\":\"price_change\"}","received_at":"2026-07-27T04:34:00.041529Z","schema_version":"clob-market-ws.price_change.v1","sequence":null,"server_hash":null,"server_timestamp":"1785126840073","session_id":"e9443c7415a0419799bee9cfbb1a9e4d","source":"clob_market_ws"},"received_at":"2026-07-27T04:34:00.041529Z","record_id":"b7ccb9e54c72914bac0f57f36c2a9b0a906096d99b765fd805cbe0e0b519922e","schema_fingerprint":"4aa3821a28b0b7c2400bc59aba4bcc0a76e971dadd19610d3ad38c768e124dc7","schema_version":"edge-lab-recorder.raw.v1","sequence":null,"source":"clob_market_ws"}
{"event_at":"2026-07-27T04:34:00.078000Z","event_fingerprint":"793e30e75cfe23f15772458fb608fbb6f9cc1af487f26b087cab9d315b45047a","payload":{"connection_id":"0f4979d6978d463e9660b042fdcf555f","event_at":"2026-07-27T04:34:00.078000Z","event_type":"price_change","frame_hash":"1c8312ed018964a52eb5f9e49e80a82784aa765402e1780202c05c66cce5cda1","frame_index":0,"kind":"data","monotonic_ns":228823311182750,"payload":{"event_type":"price_change","market":"0xeb66215f2e9faa6449e30a02bab5b8ed7b79a38bf961f6b24d0073c9c2419250","price_changes":[{"asset_id":"69697746896130839564035629862476347944307040470122503199396727085502753297492","best_ask":"0.24","best_bid":"0.23","hash":"340766d8ee7596b1d103842cd109d550682053c5","price":"0.13","side":"BUY","size":"206.5"},{"asset_id":"60386828328910021732068595344565885737045900010034836345809386672230885527307","best_ask":"0.77","best_bid":"0.76","hash":"6b7d9b73bcef5cd642275ba8b4c3480a36f14d07","price":"0.87","side":"SELL","size":"206.5"}],"timestamp":"1785126840078"},"payload_hash":"f2d1fc8fb81bea413b6e2dbd20d10a0bfa7f78e18598718d881cba474666d9a5","raw_frame":"{\"market\":\"0xeb66215f2e9faa6449e30a02bab5b8ed7b79a38bf961f6b24d0073c9c2419250\", \"price_changes\":[{\"asset_id\":\"69697746896130839564035629862476347944307040470122503199396727085502753297492\", \"price\":\"0.13\", \"size\":\"206.5\", \"side\":\"BUY\", \"hash\":\"340766d8ee7596b1d103842cd109d550682053c5\", \"best_bid\":\"0.23\", \"best_ask\":\"0.24\"}, {\"asset_id\":\"60386828328910021732068595344565885737045900010034836345809386672230885527307\", \"price\":\"0.87\", \"size\":\"206.5\", \"side\":\"SELL\", \"hash\":\"6b7d9b73bcef5cd642275ba8b4c3480a36f14d07\", \"best_bid\":\"0.76\", \"best_ask\":\"0.77\"}], \"timestamp\":\"1785126840078\", \"event_type\":\"price_change\"}","received_at":"2026-07-27T04:34:00.043424Z","schema_version":"clob-market-ws.price_change.v1","sequence":null,"server_hash":null,"server_timestamp":"1785126840078","session_id":"e9443c7415a0419799bee9cfbb1a9e4d","source":"clob_market_ws"},"received_at":"2026-07-27T04:34:00.043424Z","record_id":"bb179751185a13d757acfa8831b1c95f3933730112b56d48ca43fd5665460db7","schema_fingerprint":"4aa3821a28b0b7c2400bc59aba4bcc0a76e971dadd19610d3ad38c768e124dc7","schema_version":"edge-lab-recorder.raw.v1","sequence":null,"source":"clob_market_ws"}
{"event_at":"2026-07-27T04:34:00.102000Z","event_fingerprint":"8d296314ac8d88b7db24813c0fe708999d5f89e0dfe24a97270400c7df7e58c2","payload":{"connection_id":"0f4979d6978d463e9660b042fdcf555f","event_at":"2026-07-27T04:34:00.102000Z","event_type":"price_change","frame_hash":"34a2a73500b247090fa83cb645920863312fe6e8cf9e8b3a46a6bba8e7d842d1","frame_index":0,"kind":"data","monotonic_ns":228823340225875,"payload":{"event_type":"price_change","market":"0xeb66215f2e9faa6449e30a02bab5b8ed7b79a38bf961f6b24d0073c9c2419250","price_changes":[{"asset_id":"60386828328910021732068595344565885737045900010034836345809386672230885527307","best_ask":"0.77","best_bid":"0.76","hash":"5b37312cf9a0b48eaa117d80aa29c5398924c51b","price":"0.01","side":"BUY","size":"7703.02"},{"asset_id":"69697746896130839564035629862476347944307040470122503199396727085502753297492","best_ask":"0.24","best_bid":"0.23","hash":"072249ab0310c5ccf29bd4cc4c617f92c83e1553","price":"0.99","side":"SELL","size":"7703.02"}],"timestamp":"1785126840102"},"payload_hash":"da7261c1f7a20a7e8bec40744348eb970e31809264099692a261cb0b30764a17","raw_frame":"{\"market\":\"0xeb66215f2e9faa6449e30a02bab5b8ed7b79a38bf961f6b24d0073c9c2419250\", \"price_changes\":[{\"asset_id\":\"60386828328910021732068595344565885737045900010034836345809386672230885527307\", \"price\":\"0.01\", \"size\":\"7703.02\", \"side\":\"BUY\", \"hash\":\"5b37312cf9a0b48eaa117d80aa29c5398924c51b\", \"best_bid\":\"0.76\", \"best_ask\":\"0.77\"}, {\"asset_id\":\"69697746896130839564035629862476347944307040470122503199396727085502753297492\", \"price\":\"0.99\", \"size\":\"7703.02\", \"side\":\"SELL\", \"hash\":\"072249ab0310c5ccf29bd4cc4c617f92c83e1553\", \"best_bid\":\"0.23\", \"best_ask\":\"0.24\"}], \"timestamp\":\"1785126840102\", \"event_type\":\"price_change\"}","received_at":"2026-07-27T04:34:00.072467Z","schema_version":"clob-market-ws.price_change.v1","sequence":null,"server_hash":null,"server_timestamp":"1785126840102","session_id":"e9443c7415a0419799bee9cfbb1a9e4d","source":"clob_market_ws"},"received_at":"2026-07-27T04:34:00.072467Z","record_id":"7af9ff74a51dc81a7935d8dfcb22b6355e019900a81e68b889833789b72cb5ca","schema_fingerprint":"4aa3821a28b0b7c2400bc59aba4bcc0a76e971dadd19610d3ad38c768e124dc7","schema_version":"edge-lab-recorder.raw.v1","sequence":null,"source":"clob_market_ws"}
{"event_at":"2026-07-27T04:34:00.130000Z","event_fingerprint":"89def83e5e021fc23cade95a7dec366a361a0c15d28a37bc8570830a02f0970b","payload":{"connection_id":"0f4979d6978d463e9660b042fdcf555f","event_at":"2026-07-27T04:34:00.130000Z","event_type":"price_change","frame_hash":"39add8aa981e2e1ccaec8ba9ff6942268724b76f7302467ae5a225841e60313d","frame_index":0,"kind":"data","monotonic_ns":228823353107458,"payload":{"event_type":"price_change","market":"0xeb66215f2e9faa6449e30a02bab5b8ed7b79a38bf961f6b24d0073c9c2419250","price_changes":[{"asset_id":"60386828328910021732068595344565885737045900010034836345809386672230885527307","best_ask":"0.77","best_bid":"0.76","hash":"298ee58c206175a7b566bfa021dbe7735bc35573","price":"0.72","side":"BUY","size":"32.2"},{"asset_id":"69697746896130839564035629862476347944307040470122503199396727085502753297492","best_ask":"0.24","best_bid":"0.23","hash":"a6f796e3485d7b02f3941c42206b526ceaadb2d5","price":"0.28","side":"SELL","size":"32.2"}],"timestamp":"1785126840130"},"payload_hash":"ca432ae00279226ef7e1cf536472c7558da54678b072b4e819110de03bd05f45","raw_frame":"{\"market\":\"0xeb66215f2e9faa6449e30a02bab5b8ed7b79a38bf961f6b24d0073c9c2419250\", \"price_changes\":[{\"asset_id\":\"60386828328910021732068595344565885737045900010034836345809386672230885527307\", \"price\":\"0.72\", \"size\":\"32.2\", \"side\":\"BUY\", \"hash\":\"298ee58c206175a7b566bfa021dbe7735bc35573\", \"best_bid\":\"0.76\", \"best_ask\":\"0.77\"}, {\"asset_id\":\"69697746896130839564035629862476347944307040470122503199396727085502753297492\", \"price\":\"0.28\", \"size\":\"32.2\", \"side\":\"SELL\", \"hash\":\"a6f796e3485d7b02f3941c42206b526ceaadb2d5\", \"best_bid\":\"0.23\", \"best_ask\":\"0.24\"}], \"timestamp\":\"1785126840130\", \"event_type\":\"price_change\"}","received_at":"2026-07-27T04:34:00.085344Z","schema_version":"clob-market-ws.price_change.v1","sequence":null,"server_hash":null,"server_timestamp":"1785126840130","session_id":"e9443c7415a0419799bee9cfbb1a9e4d","source":"clob_market_ws"},"received_at":"2026-07-27T04:34:00.085344Z","record_id":"f5ff2be358f8753280b80b2a6e6a3888b46f05e0dcb9a3ec3f416fb1fc2a61ae","schema_fingerprint":"4aa3821a28b0b7c2400bc59aba4bcc0a76e971dadd19610d3ad38c768e124dc7","schema_version":"edge-lab-recorder.raw.v1","sequence":null,"source":"clob_market_ws"}
{"event_at":"2026-07-27T04:34:00.136000Z","event_fingerprint":"ae1671cf9124a16c0aeed30fb2f3f14d34bcc92892a351246ddd8b809a14fccd","payload":{"connection_id":"0f4979d6978d463e9660b042fdcf555f","event_at":"2026-07-27T04:34:00.136000Z","event_type":"price_change","frame_hash":"8f09e3f8dcedfccaf715a0f05e1a7225cc3ee4d52891c78fd1398a0fa842d4c8","frame_index":0,"kind":"data","monotonic_ns":228823354019166,"payload":{"event_type":"price_change","market":"0xeb66215f2e9faa6449e30a02bab5b8ed7b79a38bf961f6b24d0073c9c2419250","price_changes":[{"asset_id":"60386828328910021732068595344565885737045900010034836345809386672230885527307","best_ask":"0.77","best_bid":"0.76","hash":"dfdf2364a28614d5a07884f9a66cb343b51a3ce4","price":"0.72","side":"BUY","size":"43.16"},{"asset_id":"69697746896130839564035629862476347944307040470122503199396727085502753297492","best_ask":"0.24","best_bid":"0.23","hash":"7bc070049956a8e8d19a270cc6d2d5bd61baccd6","price":"0.28","side":"SELL","size":"43.16"}],"timestamp":"1785126840136"},"payload_hash":"c5bd263609a84dadc5ff8f3a548a2ee80b48be5266dc8fb391277d53742ad1c4","raw_frame":"{\"market\":\"0xeb66215f2e9faa6449e30a02bab5b8ed7b79a38bf961f6b24d0073c9c2419250\", \"price_changes\":[{\"asset_id\":\"60386828328910021732068595344565885737045900010034836345809386672230885527307\", \"price\":\"0.72\", \"size\":\"43.16\", \"side\":\"BUY\", \"hash\":\"dfdf2364a28614d5a07884f9a66cb343b51a3ce4\", \"best_bid\":\"0.76\", \"best_ask\":\"0.77\"}, {\"asset_id\":\"69697746896130839564035629862476347944307040470122503199396727085502753297492\", \"price\":\"0.28\", \"size\":\"43.16\", \"side\":\"SELL\", \"hash\":\"7bc070049956a8e8d19a270cc6d2d5bd61baccd6\", \"best_bid\":\"0.23\", \"best_ask\":\"0.24\"}], \"timestamp\":\"1785126840136\", \"event_type\":\"price_change\"}","received_at":"2026-07-27T04:34:00.086270Z","schema_version":"clob-market-ws.price_change.v1","sequence":null,"server_hash":null,"server_timestamp":"1785126840136","session_id":"e9443c7415a0419799bee9cfbb1a9e4d","source":"clob_market_ws"},"received_at":"2026-07-27T04:34:00.086270Z","record_id":"1950c6fdff0293d25f3c5c243fdfff05fca62f5c99efbdaf6573e1ef49a5f437","schema_fingerprint":"4aa3821a28b0b7c2400bc59aba4bcc0a76e971dadd19610d3ad38c768e124dc7","schema_version":"edge-lab-recorder.raw.v1","sequence":null,"source":"clob_market_ws"}
{"event_at":"2026-07-27T04:34:00.136000Z","event_fingerprint":"fb387782845b78294b37c71bb41a0cbe507303f2abad450155c7543585f68266","payload":{"connection_id":"0f4979d6978d463e9660b042fdcf555f","event_at":"2026-07-27T04:34:00.136000Z","event_type":"price_change","frame_hash":"3279ccb532afdd3cb038d806d043168bea0dc3093895e8e4db38170eafb47837","frame_index":0,"kind":"data","monotonic_ns":228823354690916,"payload":{"event_type":"price_change","market":"0xeb66215f2e9faa6449e30a02bab5b8ed7b79a38bf961f6b24d0073c9c2419250","price_changes":[{"asset_id":"60386828328910021732068595344565885737045900010034836345809386672230885527307","best_ask":"0.77","best_bid":"0.76","hash":"bb8383bc64cbbbc9099c09eefa7ad2f36d4e4d40","price":"0.8","side":"SELL","size":"51.31"},{"asset_id":"69697746896130839564035629862476347944307040470122503199396727085502753297492","best_ask":"0.24","best_bid":"0.23","hash":"86d5a3094a6a0124b714d7136c097f253f5f2cda","price":"0.2","side":"BUY","size":"51.31"}],"timestamp":"1785126840136"},"payload_hash":"f9a88b96d7f6d6d0a38e196773f68633510569b50fc3666178a52aa2f3504ce9","raw_frame":"{\"market\":\"0xeb66215f2e9faa6449e30a02bab5b8ed7b79a38bf961f6b24d0073c9c2419250\", \"price_changes\":[{\"asset_id\":\"60386828328910021732068595344565885737045900010034836345809386672230885527307\", \"price\":\"0.8\", \"size\":\"51.31\", \"side\":\"SELL\", \"hash\":\"bb8383bc64cbbbc9099c09eefa7ad2f36d4e4d40\", \"best_bid\":\"0.76\", \"best_ask\":\"0.77\"}, {\"asset_id\":\"69697746896130839564035629862476347944307040470122503199396727085502753297492\", \"price\":\"0.2\", \"size\":\"51.31\", \"side\":\"BUY\", \"hash\":\"86d5a3094a6a0124b714d7136c097f253f5f2cda\", \"best_bid\":\"0.23\", \"best_ask\":\"0.24\"}], \"timestamp\":\"1785126840136\", \"event_type\":\"price_change\"}","received_at":"2026-07-27T04:34:00.086936Z","schema_version":"clob-market-ws.price_change.v1","sequence":null,"server_hash":null,"server_timestamp":"1785126840136","session_id":"e9443c7415a0419799bee9cfbb1a9e4d","source":"clob_market_ws"},"received_at":"2026-07-27T04:34:00.086936Z","record_id":"b42ce51d06e471df95734369821da642cf239f751c48837859e286e1339289dd","schema_fingerprint":"4aa3821a28b0b7c2400bc59aba4bcc0a76e971dadd19610d3ad38c768e124dc7","schema_version":"edge-lab-recorder.raw.v1","sequence":null,"source":"clob_market_ws"}
{"event_at":"2026-07-27T04:34:00.137000Z","event_fingerprint":"84080e9cbf66fd72b10f8a4873c0997db3fd2ebababda3b8015e8d538bfc14f3","payload":{"connection_id":"0f4979d6978d463e9660b042fdcf555f","event_at":"2026-07-27T04:34:00.137000Z","event_type":"price_change","frame_hash":"1f085498e40189da6e4c775d79e1558deb5deaf98fde07d283377e44df35f3a0","frame_index":0,"kind":"data","monotonic_ns":228823356821916,"payload":{"event_type":"price_change","market":"0xeb66215f2e9faa6449e30a02bab5b8ed7b79a38bf961f6b24d0073c9c2419250","price_changes":[{"asset_id":"69697746896130839564035629862476347944307040470122503199396727085502753297492","best_ask":"0.24","best_bid":"0.23","hash":"2ad3b8e22976142f8d96bc5c52f8f19174711a6a","price":"0.28","side":"SELL","size":"73.2"},{"asset_id":"60386828328910021732068595344565885737045900010034836345809386672230885527307","best_ask":"0.77","best_bid":"0.76","hash":"ead4351e8c2e8fb145e4cbed88893c996593a4a8","price":"0.72","side":"BUY","size":"73.2"}],"timestamp":"1785126840137"},"payload_hash":"b71854460eddab275de809c386ff0787bd8c948be69663ab5451ada03adf3d24","raw_frame":"{\"market\":\"0xeb66215f2e9faa6449e30a02bab5b8ed7b79a38bf961f6b24d0073c9c2419250\", \"price_changes\":[{\"asset_id\":\"69697746896130839564035629862476347944307040470122503199396727085502753297492\", \"price\":\"0.28\", \"size\":\"73.2\", \"side\":\"SELL\", \"hash\":\"2ad3b8e22976142f8d96bc5c52f8f19174711a6a\", \"best_bid\":\"0.23\", \"best_ask\":\"0.24\"}, {\"asset_id\":\"60386828328910021732068595344565885737045900010034836345809386672230885527307\", \"price\":\"0.72\", \"size\":\"73.2\", \"side\":\"BUY\", \"hash\":\"ead4351e8c2e8fb145e4cbed88893c996593a4a8\", \"best_bid\":\"0.76\", \"best_ask\":\"0.77\"}], \"timestamp\":\"1785126840137\", \"event_type\":\"price_change\"}","received_at":"2026-07-27T04:34:00.089064Z","schema_version":"clob-market-ws.price_change.v1","sequence":null,"server_hash":null,"server_timestamp":"1785126840137","session_id":"e9443c7415a0419799bee9cfbb1a9e4d","source":"clob_market_ws"},"received_at":"2026-07-27T04:34:00.089064Z","record_id":"a1256023b990f986496cc67c3b5891df54c0ee6cc52cb75dec1e3f5e29bc1b9f","schema_fingerprint":"4aa3821a28b0b7c2400bc59aba4bcc0a76e971dadd19610d3ad38c768e124dc7","schema_version":"edge-lab-recorder.raw.v1","sequence":null,"source":"clob_market_ws"}
{"event_at":"2026-07-27T04:34:00.138000Z","event_fingerprint":"13f67b3782716c223885716d68e539af7b57ac7ab5455e4a36bb446831dad097","payload":{"connection_id":"0f4979d6978d463e9660b042fdcf555f","event_at":"2026-07-27T04:34:00.138000Z","event_type":"price_change","frame_hash":"ca2864a32478b5b99281ad2ce95301282e77e0db4dea25fd295ae40212ca6d9f","frame_index":0,"kind":"data","monotonic_ns":228823358405541,"payload":{"event_type":"price_change","market":"0xeb66215f2e9faa6449e30a02bab5b8ed7b79a38bf961f6b24d0073c9c2419250","price_changes":[{"asset_id":"60386828328910021732068595344565885737045900010034836345809386672230885527307","best_ask":"0.77","best_bid":"0.76","hash":"e0f4720157ea4e47d973f7a9542303571b429876","price":"0.7","side":"BUY","size":"218.74"},{"asset_id":"69697746896130839564035629862476347944307040470122503199396727085502753297492","best_ask":"0.24","best_bid":"0.23","hash":"2a12d8d8d2c109a49e6df45359fc3ff6cffe8f90","price":"0.3","side":"SELL","size":"218.74"}],"timestamp":"1785126840138"},"payload_hash":"dca71cdb6da8c805cf10e5ad4aedb12f93b02adb9376a401572de8fe092b33ef","raw_frame":"{\"market\":\"0xeb66215f2e9faa6449e30a02bab5b8ed7b79a38bf961f6b24d0073c9c2419250\", \"price_changes\":[{\"asset_id\":\"60386828328910021732068595344565885737045900010034836345809386672230885527307\", \"price\":\"0.7\", \"size\":\"218.74\", \"side\":\"BUY\", \"hash\":\"e0f4720157ea4e47d973f7a9542303571b429876\", \"best_bid\":\"0.76\", \"best_ask\":\"0.77\"}, {\"asset_id\":\"69697746896130839564035629862476347944307040470122503199396727085502753297492\", \"price\":\"0.3\", \"size\":\"218.74\", \"side\":\"SELL\", \"hash\":\"2a12d8d8d2c109a49e6df45359fc3ff6cffe8f90\", \"best_bid\":\"0.23\", \"best_ask\":\"0.24\"}], \"timestamp\":\"1785126840138\", \"event_type\":\"price_change\"}","received_at":"2026-07-27T04:34:00.090650Z","schema_version":"clob-market-ws.price_change.v1","sequence":null,"server_hash":null,"server_timestamp":"1785126840138","session_id":"e9443c7415a0419799bee9cfbb1a9e4d","source":"clob_market_ws"},"received_at":"2026-07-27T04:34:00.090650Z","record_id":"3107ca7deb5217f7c8397986d5e9590170a97be1b84447f7f7098bae26c307c7","schema_fingerprint":"4aa3821a28b0b7c2400bc59aba4bcc0a76e971dadd19610d3ad38c768e124dc7","schema_version":"edge-lab-recorder.raw.v1","sequence":null,"source":"clob_market_ws"}
{"event_at":"2026-07-27T04:34:00.139000Z","event_fingerprint":"14f0de922a6649ff948974c102f114153711f55fcf6ab307bf4971a45457dd3a","payload":{"connection_id":"0f4979d6978d463e9660b042fdcf555f","event_at":"2026-07-27T04:34:00.139000Z","event_type":"price_change","frame_hash":"6ed22c164cbe0ec67d11d6ffe9eb45641187da669a8c6a508e8184506f85ce0a","frame_index":0,"kind":"data","monotonic_ns":228823359908333,"payload":{"event_type":"price_change","market":"0xeb66215f2e9faa6449e30a02bab5b8ed7b79a38bf961f6b24d0073c9c2419250","price_changes":[{"asset_id":"69697746896130839564035629862476347944307040470122503199396727085502753297492","best_ask":"0.24","best_bid":"0.23","hash":"4745901e11ee2c48edd4641ca3d6395251848de8","price":"0.17","side":"BUY","size":"184.81"},{"asset_id":"60386828328910021732068595344565885737045900010034836345809386672230885527307","best_ask":"0.77","best_bid":"0.76","hash":"8a9ae7d99628dc25da0483d232204831a72df83c","price":"0.83","side":"SELL","size":"184.81"}],"timestamp":"1785126840139"},"payload_hash":"24ed8277585bcffd6d3c775072d19d49231526d5fa285b2abecb4d4ac1a64d42","raw_frame":"{\"market\":\"0xeb66215f2e9faa6449e30a02bab5b8ed7b79a38bf961f6b24d0073c9c2419250\", \"price_changes\":[{\"asset_id\":\"69697746896130839564035629862476347944307040470122503199396727085502753297492\", \"price\":\"0.17\", \"size\":\"184.81\", \"side\":\"BUY\", \"hash\":\"4745901e11ee2c48edd4641ca3d6395251848de8\", \"best_bid\":\"0.23\", \"best_ask\":\"0.24\"}, {\"asset_id\":\"60386828328910021732068595344565885737045900010034836345809386672230885527307\", \"price\":\"0.83\", \"size\":\"184.81\", \"side\":\"SELL\", \"hash\":\"8a9ae7d99628dc25da0483d232204831a72df83c\", \"best_bid\":\"0.76\", \"best_ask\":\"0.77\"}], \"timestamp\":\"1785126840139\", \"event_type\":\"price_change\"}","received_at":"2026-07-27T04:34:00.092154Z","schema_version":"clob-market-ws.price_change.v1","sequence":null,"server_hash":null,"server_timestamp":"1785126840139","session_id":"e9443c7415a0419799bee9cfbb1a9e4d","source":"clob_market_ws"},"received_at":"2026-07-27T04:34:00.092154Z","record_id":"dd6dec9fc3fc78f18e0cf1cdbac00f0f29a0b97b90ccc4f24b8d20de56e96ef2","schema_fingerprint":"4aa3821a28b0b7c2400bc59aba4bcc0a76e971dadd19610d3ad38c768e124dc7","schema_version":"edge-lab-recorder.raw.v1","sequence":null,"source":"clob_market_ws"}
{"event_at":"2026-07-27T04:34:00.140000Z","event_fingerprint":"2fc7b18ab6896d58cdbccfd7e41f4303ad413e15753f947d51c258c50343e294","payload":{"connection_id":"0f4979d6978d463e9660b042fdcf555f","event_at":"2026-07-27T04:34:00.140000Z","event_type":"price_change","frame_hash":"3ac5e8f148ca0780b9ee2c0f5d10ea86dc595dd80209d1b386a05f1da162643f","frame_index":0,"kind":"data","monotonic_ns":228823361391083,"payload":{"event_type":"price_change","market":"0xeb66215f2e9faa6449e30a02bab5b8ed7b79a38bf961f6b24d0073c9c2419250","price_changes":[{"asset_id":"60386828328910021732068595344565885737045900010034836345809386672230885527307","best_ask":"0.77","best_bid":"0.76","hash":"2be405a907b3da58eb30344413d361a53ec6c252","price":"0.55","side":"BUY","size":"37.1"},{"asset_id":"69697746896130839564035629862476347944307040470122503199396727085502753297492","best_ask":"0.24","best_bid":"0.23","hash":"3bf790bc46282bfeec0791aec3cffa732a4210a7","price":"0.45","side":"SELL","size":"37.1"}],"timestamp":"1785126840140"},"payload_hash":"b19b7bd4c51aae4b46eb666e66806bff66d1572f8c8fb52bbbbb87044cb67c0d","raw_frame":"{\"market\":\"0xeb66215f2e9faa6449e30a02bab5b8ed7b79a38bf961f6b24d0073c9c2419250\", \"price_changes\":[{\"asset_id\":\"60386828328910021732068595344565885737045900010034836345809386672230885527307\", \"price\":\"0.55\", \"size\":\"37.1\", \"side\":\"BUY\", \"hash\":\"2be405a907b3da58eb30344413d361a53ec6c252\", \"best_bid\":\"0.76\", \"best_ask\":\"0.77\"}, {\"asset_id\":\"69697746896130839564035629862476347944307040470122503199396727085502753297492\", \"price\":\"0.45\", \"size\":\"37.1\", \"side\":\"SELL\", \"hash\":\"3bf790bc46282bfeec0791aec3cffa732a4210a7\", \"best_bid\":\"0.23\", \"best_ask\":\"0.24\"}], \"timestamp\":\"1785126840140\", \"event_type\":\"price_change\"}","received_at":"2026-07-27T04:34:00.093637Z","schema_version":"clob-market-ws.price_change.v1","sequence":null,"server_hash":null,"server_timestamp":"1785126840140","session_id":"e9443c7415a0419799bee9cfbb1a9e4d","source":"clob_market_ws"},"received_at":"2026-07-27T04:34:00.093637Z","record_id":"9d693dfcebb56882ccb99684bfac8bb561a292c25ed1f184eb7a45fd4e15995b","schema_fingerprint":"4aa3821a28b0b7c2400bc59aba4bcc0a76e971dadd19610d3ad38c768e124dc7","schema_version":"edge-lab-recorder.raw.v1","sequence":null,"source":"clob_market_ws"}
{"event_at":"2026-07-27T04:34:00.205000Z","event_fingerprint":"115763806ae92e1c18e8e4d0e3897d948d5762b743221f85fb19b5722567730d","payload":{"connection_id":"0f4979d6978d463e9660b042fdcf555f","event_at":"2026-07-27T04:34:00.205000Z","event_type":"price_change","frame_hash":"878ce09f3e9969552345736cf489e03c272e4d55c0b2eaa51faba1453fdc15a8","frame_index":0,"kind":"data","monotonic_ns":228823418893541,"payload":{"event_type":"price_change","market":"0xeb66215f2e9faa6449e30a02bab5b8ed7b79a38bf961f6b24d0073c9c2419250","price_changes":[{"asset_id":"60386828328910021732068595344565885737045900010034836345809386672230885527307","best_ask":"0.77","best_bid":"0.76","hash":"72ae2ffa42b8d7c8a44d97470956bfb06644abf5","price":"0.01","side":"BUY","size":"7708.02"},{"asset_id":"69697746896130839564035629862476347944307040470122503199396727085502753297492","best_ask":"0.24","best_bid":"0.23","hash":"a396fd72eeadd6cfa5f4906b6dd92f5b1c784eff","price":"0.99","side":"SELL","size":"7708.02"}],"timestamp":"1785126840205"},"payload_hash":"3e1554fd1687a663ef55ce40ec88c2aa536e68c92b0289db6373ba47b778c8c1","raw_frame":"{\"market\":\"0xeb66215f2e9faa6449e30a02bab5b8ed7b79a38bf961f6b24d0073c9c2419250\", \"price_changes\":[{\"asset_id\":\"60386828328910021732068595344565885737045900010034836345809386672230885527307\", \"price\":\"0.01\", \"size\":\"7708.02\", \"side\":\"BUY\", \"hash\":\"72ae2ffa42b8d7c8a44d97470956bfb06644abf5\", \"best_bid\":\"0.76\", \"best_ask\":\"0.77\"}, {\"asset_id\":\"69697746896130839564035629862476347944307040470122503199396727085502753297492\", \"price\":\"0.99\", \"size\":\"7708.02\", \"side\":\"SELL\", \"hash\":\"a396fd72eeadd6cfa5f4906b6dd92f5b1c784eff\", \"best_bid\":\"0.23\", \"best_ask\":\"0.24\"}], \"timestamp\":\"1785126840205\", \"event_type\":\"price_change\"}","received_at":"2026-07-27T04:34:00.151141Z","schema_version":"clob-market-ws.price_change.v1","sequence":null,"server_hash":null,"server_timestamp":"1785126840205","session_id":"e9443c7415a0419799bee9cfbb1a9e4d","source":"clob_market_ws"},"received_at":"2026-07-27T04:34:00.151141Z","record_id":"e50624f497f42174cb6e7b73642070f6ca777b3157aaf4506d717d27e4929847","schema_fingerprint":"4aa3821a28b0b7c2400bc59aba4bcc0a76e971dadd19610d3ad38c768e124dc7","schema_version":"edge-lab-recorder.raw.v1","sequence":null,"source":"clob_market_ws"}
{"event_at":"2026-07-27T04:34:00.250000Z","event_fingerprint":"ddda4bdcfc1ca2926436ac920d7de0ef2477e656871469e778dc707bc97def29","payload":{"connection_id":"0f4979d6978d463e9660b042fdcf555f","event_at":"2026-07-27T04:34:00.250000Z","event_type":"price_change","frame_hash":"33b6fb2b7bcbac77de50929bc9df652f03a998184e25707f3bb334858a71ed45","frame_index":0,"kind":"data","monotonic_ns":228823464114458,"payload":{"event_type":"price_change","market":"0xeb66215f2e9faa6449e30a02bab5b8ed7b79a38bf961f6b24d0073c9c2419250","price_changes":[{"asset_id":"60386828328910021732068595344565885737045900010034836345809386672230885527307","best_ask":"0.77","best_bid":"0.76","hash":"12f595d278834352a65e179c166c93e3b8e700bc","price":"0.8","side":"SELL","size":"46.27"},{"asset_id":"69697746896130839564035629862476347944307040470122503199396727085502753297492","best_ask":"0.24","best_bid":"0.23","hash":"b9a6141fa799f99092d5d1531c3a00faa8c1e6c2","price":"0.2","side":"BUY","size":"46.27"}],"timestamp":"1785126840250"},"payload_hash":"11c5c112af2aa100ff2a9c8db67c25d592d0cc364891a5bbe10035911bddfaae","raw_frame":"{\"market\":\"0xeb66215f2e9faa6449e30a02bab5b8ed7b79a38bf961f6b24d0073c9c2419250\", \"price_changes\":[{\"asset_id\":\"60386828328910021732068595344565885737045900010034836345809386672230885527307\", \"price\":\"0.8\", \"size\":\"46.27\", \"side\":\"SELL\", \"hash\":\"12f595d278834352a65e179c166c93e3b8e700bc\", \"best_bid\":\"0.76\", \"best_ask\":\"0.77\"}, {\"asset_id\":\"69697746896130839564035629862476347944307040470122503199396727085502753297492\", \"price\":\"0.2\", \"size\":\"46.27\", \"side\":\"BUY\", \"hash\":\"b9a6141fa799f99092d5d1531c3a00faa8c1e6c2\", \"best_bid\":\"0.23\", \"best_ask\":\"0.24\"}], \"timestamp\":\"1785126840250\", \"event_type\":\"price_change\"}","received_at":"2026-07-27T04:34:00.196360Z","schema_version":"clob-market-ws.price_change.v1","sequence":null,"server_hash":null,"server_timestamp":"1785126840250","session_id":"e9443c7415a0419799bee9cfbb1a9e4d","source":"clob_market_ws"},"received_at":"2026-07-27T04:34:00.196360Z","record_id":"3cd0093877d7eecffb07fbef87d330c79a9de90de648c2c3af073f6e5ff82ca8","schema_fingerprint":"4aa3821a28b0b7c2400bc59aba4bcc0a76e971dadd19610d3ad38c768e124dc7","schema_version":"edge-lab-recorder.raw.v1","sequence":null,"source":"clob_market_ws"}
{"event_at":"2026-07-27T04:34:00.252000Z","event_fingerprint":"0e2ae5f59052cc3b43dbbc65a1f1585d5dccddff0e26a47a82ec674a0dbe65d0","payload":{"connection_id":"0f4979d6978d463e9660b042fdcf555f","event_at":"2026-07-27T04:34:00.252000Z","event_type":"price_change","frame_hash":"1953fdbb3848eeb5552b56e922042fb228d69d964e1a21ff5419d137b91c38cd","frame_index":0,"kind":"data","monotonic_ns":228823468990458,"payload":{"event_type":"price_change","market":"0xeb66215f2e9faa6449e30a02bab5b8ed7b79a38bf961f6b24d0073c9c2419250","price_changes":[{"asset_id":"69697746896130839564035629862476347944307040470122503199396727085502753297492","best_ask":"0.24","best_bid":"0.23","hash":"60c0639963f919b5e6b8b98946a626315ac5c5f0","price":"0.28","side":"SELL","size":"43.16"},{"asset_id":"60386828328910021732068595344565885737045900010034836345809386672230885527307","best_ask":"0.77","best_bid":"0.76","hash":"96ac562195dcdc1af32edd25e9fa918b811c6090","price":"0.72","side":"BUY","size":"43.16"}],"timestamp":"1785126840252"},"payload_hash":"b87eda44123cce85e0b36a012d57638cdbbbd70d0ebe4ff845fe39ea83a9666b","raw_frame":"{\"market\":\"0xeb66215f2e9faa6449e30a02bab5b8ed7b79a38bf961f6b24d0073c9c2419250\", \"price_changes\":[{\"asset_id\":\"69697746896130839564035629862476347944307040470122503199396727085502753297492\", \"price\":\"0.28\", \"size\":\"43.16\", \"side\":\"SELL\", \"hash\":\"60c0639963f919b5e6b8b98946a626315ac5c5f0\", \"best_bid\":\"0.23\", \"best_ask\":\"0.24\"}, {\"asset_id\":\"60386828328910021732068595344565885737045900010034836345809386672230885527307\", \"price\":\"0.72\", \"size\":\"43.16\", \"side\":\"BUY\", \"hash\":\"96ac562195dcdc1af32edd25e9fa918b811c6090\", \"best_bid\":\"0.76\", \"best_ask\":\"0.77\"}], \"timestamp\":\"1785126840252\", \"event_type\":\"price_change\"}","received_at":"2026-07-27T04:34:00.201236Z","schema_version":"clob-market-ws.price_change.v1","sequence":null,"server_hash":null,"server_timestamp":"1785126840252","session_id":"e9443c7415a0419799bee9cfbb1a9e4d","source":"clob_market_ws"},"received_at":"2026-07-27T04:34:00.201236Z","record_id":"849e5add990bbb8818467e75affdf9a43807b638c64f9eeb51c4b08b85c53d1b","schema_fingerprint":"4aa3821a28b0b7c2400bc59aba4bcc0a76e971dadd19610d3ad38c768e124dc7","schema_version":"edge-lab-recorder.raw.v1","sequence":null,"source":"clob_market_ws"}
{"event_at":"2026-07-27T04:34:00.253000Z","event_fingerprint":"433c8d597bdc37cbab65f38bf6b5ed17ce23026a1c8907dd6f999631411841c9","payload":{"connection_id":"0f4979d6978d463e9660b042fdcf555f","event_at":"2026-07-27T04:34:00.253000Z","event_type":"price_change","frame_hash":"86bd1b6dacaaccaee6ee79e3e774da2aa819cf07a083f0a6f76abbafcaea0c88","frame_index":0,"kind":"data","monotonic_ns":228823473686708,"payload":{"event_type":"price_change","market":"0xeb66215f2e9faa6449e30a02bab5b8ed7b79a38bf961f6b24d0073c9c2419250","price_changes":[{"asset_id":"60386828328910021732068595344565885737045900010034836345809386672230885527307","best_ask":"0.77","best_bid":"0.76","hash":"e8e590ab754ebcdd30422c99830e816fa0aab906","price":"0.01","side":"BUY","size":"7713.02"},{"asset_id":"69697746896130839564035629862476347944307040470122503199396727085502753297492","best_ask":"0.24","best_bid":"0.23","hash":"79300d34c468b7cc96176c3c595e0df491f81acb","price":"0.99","side":"SELL","size":"7713.02"}],"timestamp":"1785126840253"},"payload_hash":"b7642fe60f6804ebd9fe3bac878f27843a062ffdfdf1f8c8845109fcc9b7aedc","raw_frame":"{\"market\":\"0xeb66215f2e9faa6449e30a02bab5b8ed7b79a38bf961f6b24d0073c9c2419250\", \"price_changes\":[{\"asset_id\":\"60386828328910021732068595344565885737045900010034836345809386672230885527307\", \"price\":\"0.01\", \"size\":\"7713.02\", \"side\":\"BUY\", \"hash\":\"e8e590ab754ebcdd30422c99830e816fa0aab906\", \"best_bid\":\"0.76\", \"best_ask\":\"0.77\"}, {\"asset_id\":\"69697746896130839564035629862476347944307040470122503199396727085502753297492\", \"price\":\"0.99\", \"size\":\"7713.02\", \"side\":\"SELL\", \"hash\":\"79300d34c468b7cc96176c3c595e0df491f81acb\", \"best_bid\":\"0.23\", \"best_ask\":\"0.24\"}], \"timestamp\":\"1785126840253\", \"event_type\":\"price_change\"}","received_at":"2026-07-27T04:34:00.205933Z","schema_version":"clob-market-ws.price_change.v1","sequence":null,"server_hash":null,"server_timestamp":"1785126840253","session_id":"e9443c7415a0419799bee9cfbb1a9e4d","source":"clob_market_ws"},"received_at":"2026-07-27T04:34:00.205933Z","record_id":"4c6e273f866c081d2608617b124df82fc3534046bacf8e0af465f1a4d2aec026","schema_fingerprint":"4aa3821a28b0b7c2400bc59aba4bcc0a76e971dadd19610d3ad38c768e124dc7","schema_version":"edge-lab-recorder.raw.v1","sequence":null,"source":"clob_market_ws"}
{"event_at":"2026-07-27T04:34:00.261000Z","event_fingerprint":"e2171f43ecb06e971976f7400e97e54102cbfc2ff3b0a5c86718eeed2ee22925","payload":{"connection_id":"0f4979d6978d463e9660b042fdcf555f","event_at":"2026-07-27T04:34:00.261000Z","event_type":"price_change","frame_hash":"aba02bd1860d22432f887bd5f123cea52c3188995becfba639391ef7ed8daee8","frame_index":0,"kind":"data","monotonic_ns":228823478031333,"payload":{"event_type":"price_change","market":"0xeb66215f2e9faa6449e30a02bab5b8ed7b79a38bf961f6b24d0073c9c2419250","price_changes":[{"asset_id":"60386828328910021732068595344565885737045900010034836345809386672230885527307","best_ask":"0.77","best_bid":"0.76","hash":"776b8ff55714d20ca646946c18b6f4101ca5f92e","price":"0.73","side":"BUY","size":"411.06"},{"asset_id":"69697746896130839564035629862476347944307040470122503199396727085502753297492","best_ask":"0.24","best_bid":"0.23","hash":"a22765f7a2bc9468a62bc17db1f739b4731e3015","price":"0.27","side":"SELL","size":"411.06"}],"timestamp":"1785126840261"},"payload_hash":"bffc4f22ef6e147d8c50a002b46cd6fb080ee25cbe711104f3cd204a3f37d118","raw_frame":"{\"market\":\"0xeb66215f2e9faa6449e30a02bab5b8ed7b79a38bf961f6b24d0073c9c2419250\", \"price_changes\":[{\"asset_id\":\"60386828328910021732068595344565885737045900010034836345809386672230885527307\", \"price\":\"0.73\", \"size\":\"411.06\", \"side\":\"BUY\", \"hash\":\"776b8ff55714d20ca646946c18b6f4101ca5f92e\", \"best_bid\":\"0.76\", \"best_ask\":\"0.77\"}, {\"asset_id\":\"69697746896130839564035629862476347944307040470122503199396727085502753297492\", \"price\":\"0.27\", \"size\":\"411.06\", \"side\":\"SELL\", \"hash\":\"a22765f7a2bc9468a62bc17db1f739b4731e3015\", \"best_bid\":\"0.23\", \"best_ask\":\"0.24\"}], \"timestamp\":\"1785126840261\", \"event_type\":\"price_change\"}","received_at":"2026-07-27T04:34:00.210278Z","schema_version":"clob-market-ws.price_change.v1","sequence":null,"server_hash":null,"server_timestamp":"1785126840261","session_id":"e9443c7415a0419799bee9cfbb1a9e4d","source":"clob_market_ws"},"received_at":"2026-07-27T04:34:00.210278Z","record_id":"79216c888c04dacbcefe9bcb599edb053d2846c7234b5b49be8a918af6cecfa9","schema_fingerprint":"4aa3821a28b0b7c2400bc59aba4bcc0a76e971dadd19610d3ad38c768e124dc7","schema_version":"edge-lab-recorder.raw.v1","sequence":null,"source":"clob_market_ws"}
{"event_at":"2026-07-27T04:34:00.272000Z","event_fingerprint":"7023d3a4ca19a4aa74adceb4daf4f4ebd443df9a40a990172054476e0cf0f1dc","payload":{"connection_id":"0f4979d6978d463e9660b042fdcf555f","event_at":"2026-07-27T04:34:00.272000Z","event_type":"price_change","frame_hash":"cacd12c915a16c9b4d2bc98cbc4c55a816357a5c0dc3708155f449dc5de69842","frame_index":0,"kind":"data","monotonic_ns":228823484818250,"payload":{"event_type":"price_change","market":"0xeb66215f2e9faa6449e30a02bab5b8ed7b79a38bf961f6b24d0073c9c2419250","price_changes":[{"asset_id":"60386828328910021732068595344565885737045900010034836345809386672230885527307","best_ask":"0.77","best_bid":"0.76","hash":"7de96687cecf846b1958422c8e82eb9ac6825e7a","price":"0.01","side":"BUY","size":"7708.02"},{"asset_id":"69697746896130839564035629862476347944307040470122503199396727085502753297492","best_ask":"0.24","best_bid":"0.23","hash":"90fcabb2b505651e25a4621f9d11413cb56beb0d","price":"0.99","side":"SELL","size":"7708.02"}],"timestamp":"1785126840272"},"payload_hash":"768da417ba66532940e228862cb1b3e8f1dfd605ce7cb073816cc89a03d7bcd1","raw_frame":"{\"market\":\"0xeb66215f2e9faa6449e30a02bab5b8ed7b79a38bf961f6b24d0073c9c2419250\", \"price_changes\":[{\"asset_id\":\"60386828328910021732068595344565885737045900010034836345809386672230885527307\", \"price\":\"0.01\", \"size\":\"7708.02\", \"side\":\"BUY\", \"hash\":\"7de96687cecf846b1958422c8e82eb9ac6825e7a\", \"best_bid\":\"0.76\", \"best_ask\":\"0.77\"}, {\"asset_id\":\"69697746896130839564035629862476347944307040470122503199396727085502753297492\", \"price\":\"0.99\", \"size\":\"7708.02\", \"side\":\"SELL\", \"hash\":\"90fcabb2b505651e25a4621f9d11413cb56beb0d\", \"best_bid\":\"0.23\", \"best_ask\":\"0.24\"}], \"timestamp\":\"1785126840272\", \"event_type\":\"price_change\"}","received_at":"2026-07-27T04:34:00.217064Z","schema_version":"clob-market-ws.price_change.v1","sequence":null,"server_hash":null,"server_timestamp":"1785126840272","session_id":"e9443c7415a0419799bee9cfbb1a9e4d","source":"clob_market_ws"},"received_at":"2026-07-27T04:34:00.217064Z","record_id":"4ded88653836b25d57325a11581660b9722fa9761996dac0df3bbff739ebb898","schema_fingerprint":"4aa3821a28b0b7c2400bc59aba4bcc0a76e971dadd19610d3ad38c768e124dc7","schema_version":"edge-lab-recorder.raw.v1","sequence":null,"source":"clob_market_ws"}
{"event_at":"2026-07-27T04:34:00.298000Z","event_fingerprint":"48ccb4effd738f189da878ac8f1fbdc3b98c12efbc3b3fb6062e27884ac5b6e9","payload":{"connection_id":"0f4979d6978d463e9660b042fdcf555f","event_at":"2026-07-27T04:34:00.298000Z","event_type":"price_change","frame_hash":"ae7f9cdf4c378fac3d42830df588c5e8e653126afa8bc1d9b3185657ddc20671","frame_index":0,"kind":"data","monotonic_ns":228823514430541,"payload":{"event_type":"price_change","market":"0xeb66215f2e9faa6449e30a02bab5b8ed7b79a38bf961f6b24d0073c9c2419250","price_changes":[{"asset_id":"60386828328910021732068595344565885737045900010034836345809386672230885527307","best_ask":"0.77","best_bid":"0.76","hash":"01457fe71a8e88c8df729c06d7f8691222081f9d","price":"0.01","side":"BUY","size":"7703.02"},{"asset_id":"69697746896130839564035629862476347944307040470122503199396727085502753297492","best_ask":"0.24","best_bid":"0.23","hash":"084cffbb7ef2799730e5bb7e4b117ca885da88ea","price":"0.99","side":"SELL","size":"7703.02"}],"timestamp":"1785126840298"},"payload_hash":"e2e791bdb10196664a1168302c4160816bf3d8cfafe77f71293e1b1d059cb49c","raw_frame":"{\"market\":\"0xeb66215f2e9faa6449e30a02bab5b8ed7b79a38bf961f6b24d0073c9c2419250\", \"price_changes\":[{\"asset_id\":\"60386828328910021732068595344565885737045900010034836345809386672230885527307\", \"price\":\"0.01\", \"size\":\"7703.02\", \"side\":\"BUY\", \"hash\":\"01457fe71a8e88c8df729c06d7f8691222081f9d\", \"best_bid\":\"0.76\", \"best_ask\":\"0.77\"}, {\"asset_id\":\"69697746896130839564035629862476347944307040470122503199396727085502753297492\", \"price\":\"0.99\", \"size\":\"7703.02\", \"side\":\"SELL\", \"hash\":\"084cffbb7ef2799730e5bb7e4b117ca885da88ea\", \"best_bid\":\"0.23\", \"best_ask\":\"0.24\"}], \"timestamp\":\"1785126840298\", \"event_type\":\"price_change\"}","received_at":"2026-07-27T04:34:00.246674Z","schema_version":"clob-market-ws.price_change.v1","sequence":null,"server_hash":null,"server_timestamp":"1785126840298","session_id":"e9443c7415a0419799bee9cfbb1a9e4d","source":"clob_market_ws"},"received_at":"2026-07-27T04:34:00.246674Z","record_id":"851eb6961aaba30d785c41836032b361dc65674bc8be5dad62b4c0f1a4460613","schema_fingerprint":"4aa3821a28b0b7c2400bc59aba4bcc0a76e971dadd19610d3ad38c768e124dc7","schema_version":"edge-lab-recorder.raw.v1","sequence":null,"source":"clob_market_ws"}
{"event_at":"2026-07-27T04:34:00.308000Z","event_fingerprint":"f0d229e268a36b0bbab6603be48c7af9482ad1b27e5493d718f71fb0b272f357","payload":{"connection_id":"0f4979d6978d463e9660b042fdcf555f","event_at":"2026-07-27T04:34:00.308000Z","event_type":"price_change","frame_hash":"b35e679f034cfefd47ceb2f6053f8a71d3ab88d392713506226e74ecb276c626","frame_index":0,"kind":"data","monotonic_ns":228823519861750,"payload":{"event_type":"price_change","market":"0xeb66215f2e9faa6449e30a02bab5b8ed7b79a38bf961f6b24d0073c9c2419250","price_changes":[{"asset_id":"60386828328910021732068595344565885737045900010034836345809386672230885527307","best_ask":"0.77","best_bid":"0.76","hash":"c0ddf189bc586d77321a246dc60ed53128617df2","price":"0.01","side":"BUY","size":"7708.02"},{"asset_id":"69697746896130839564035629862476347944307040470122503199396727085502753297492","best_ask":"0.24","best_bid":"0.23","hash":"6a9fb5a64d9b6d8a27d69b31733302ecfb399086","price":"0.99","side":"SELL","size":"7708.02"}],"timestamp":"1785126840308"},"payload_hash":"22ec726d0a967e4741ceefec0dc5f03c82c7f6698831446f0b80c5f2bd0a977b","raw_frame":"{\"market\":\"0xeb66215f2e9faa6449e30a02bab5b8ed7b79a38bf961f6b24d0073c9c2419250\", \"price_changes\":[{\"asset_id\":\"60386828328910021732068595344565885737045900010034836345809386672230885527307\", \"price\":\"0.01\", \"size\":\"7708.02\", \"side\":\"BUY\", \"hash\":\"c0ddf189bc586d77321a246dc60ed53128617df2\", \"best_bid\":\"0.76\", \"best_ask\":\"0.77\"}, {\"asset_id\":\"69697746896130839564035629862476347944307040470122503199396727085502753297492\", \"price\":\"0.99\", \"size\":\"7708.02\", \"side\":\"SELL\", \"hash\":\"6a9fb5a64d9b6d8a27d69b31733302ecfb399086\", \"best_bid\":\"0.23\", \"best_ask\":\"0.24\"}], \"timestamp\":\"1785126840308\", \"event_type\":\"price_change\"}","received_at":"2026-07-27T04:34:00.252109Z","schema_version":"clob-market-ws.price_change.v1","sequence":null,"server_hash":null,"server_timestamp":"1785126840308","session_id":"e9443c7415a0419799bee9cfbb1a9e4d","source":"clob_market_ws"},"received_at":"2026-07-27T04:34:00.252109Z","record_id":"b26397a1bf66e75e1df310b862e55d57d806081167b2c6eedb045d2b6283368f","schema_fingerprint":"4aa3821a28b0b7c2400bc59aba4bcc0a76e971dadd19610d3ad38c768e124dc7","schema_version":"edge-lab-recorder.raw.v1","sequence":null,"source":"clob_market_ws"}
{"event_at":"2026-07-27T04:34:00.328000Z","event_fingerprint":"5ca43da763f300f5832bb7987d140ed8238c1402a1eacb1a5e882fff7e0eabf9","payload":{"connection_id":"0f4979d6978d463e9660b042fdcf555f","event_at":"2026-07-27T04:34:00.328000Z","event_type":"price_change","frame_hash":"8949d21525ab09e1acf3efd20cdca87f06046b68666a75c3d2b9decd065584f1","frame_index":0,"kind":"data","monotonic_ns":228823541662541,"payload":{"event_type":"price_change","market":"0xeb66215f2e9faa6449e30a02bab5b8ed7b79a38bf961f6b24d0073c9c2419250","price_changes":[{"asset_id":"60386828328910021732068595344565885737045900010034836345809386672230885527307","best_ask":"0.77","best_bid":"0.76","hash":"fd1321b6b2283d7b151d2bd3326f7f1926438e5d","price":"0.01","side":"BUY","size":"7703.02"},{"asset_id":"69697746896130839564035629862476347944307040470122503199396727085502753297492","best_ask":"0.24","best_bid":"0.23","hash":"bb1b503723e771d1a71cbeaf716e0bfa54946988","price":"0.99","side":"SELL","size":"7703.02"}],"timestamp":"1785126840328"},"payload_hash":"4f1ed093c931fff7140beec245ca6c2da5ec40095374bf3262b956233ccfb187","raw_frame":"{\"market\":\"0xeb66215f2e9faa6449e30a02bab5b8ed7b79a38bf961f6b24d0073c9c2419250\", \"price_changes\":[{\"asset_id\":\"60386828328910021732068595344565885737045900010034836345809386672230885527307\", \"price\":\"0.01\", \"size\":\"7703.02\", \"side\":\"BUY\", \"hash\":\"fd1321b6b2283d7b151d2bd3326f7f1926438e5d\", \"best_bid\":\"0.76\", \"best_ask\":\"0.77\"}, {\"asset_id\":\"69697746896130839564035629862476347944307040470122503199396727085502753297492\", \"price\":\"0.99\", \"size\":\"7703.02\", \"side\":\"SELL\", \"hash\":\"bb1b503723e771d1a71cbeaf716e0bfa54946988\", \"best_bid\":\"0.23\", \"best_ask\":\"0.24\"}], \"timestamp\":\"1785126840328\", \"event_type\":\"price_change\"}","received_at":"2026-07-27T04:34:00.273903Z","schema_version":"clob-market-ws.price_change.v1","sequence":null,"server_hash":null,"server_timestamp":"1785126840328","session_id":"e9443c7415a0419799bee9cfbb1a9e4d","source":"clob_market_ws"},"received_at":"2026-07-27T04:34:00.273903Z","record_id":"d9a8c17538f1f24917b28b5e9f656b3fdf9b35aaefb96e7021acee369aaf7fe7","schema_fingerprint":"4aa3821a28b0b7c2400bc59aba4bcc0a76e971dadd19610d3ad38c768e124dc7","schema_version":"edge-lab-recorder.raw.v1","sequence":null,"source":"clob_market_ws"}
{"event_at":"2026-07-27T04:34:00.358000Z","event_fingerprint":"55a12803ba93a0f4e9588063d667afe8f0b8b02f071ab09160ae7248485ae21d","payload":{"connection_id":"0f4979d6978d463e9660b042fdcf555f","event_at":"2026-07-27T04:34:00.358000Z","event_type":"price_change","frame_hash":"2130520fd0a697f6af8fbfd3b4041b28ed93ce4efb0c3a06c39afedfa07683bb","frame_index":0,"kind":"data","monotonic_ns":228823573089000,"payload":{"event_type":"price_change","market":"0xeb66215f2e9faa6449e30a02bab5b8ed7b79a38bf961f6b24d0073c9c2419250","price_changes":[{"asset_id":"60386828328910021732068595344565885737045900010034836345809386672230885527307","best_ask":"0.77","best_bid":"0.76","hash":"909c77e7af063b986a33dd34daa8f25fd6543391","price":"0.73","side":"BUY","size":"367.06"},{"asset_id":"69697746896130839564035629862476347944307040470122503199396727085502753297492","best_ask":"0.24","best_bid":"0.23","hash":"08d436817d2fa5b247ecf514fe0ed625658dd263","price":"0.27","side":"SELL","size":"367.06"}],"timestamp":"1785126840358"},"payload_hash":"4b325f7bb73060c510a4c3803885148980be1d0eb9f13c8ecde2f26998fadf4d","raw_frame":"{\"market\":\"0xeb66215f2e9faa6449e30a02bab5b8ed7b79a38bf961f6b24d0073c9c2419250\", \"price_changes\":[{\"asset_id\":\"60386828328910021732068595344565885737045900010034836345809386672230885527307\", \"price\":\"0.73\", \"size\":\"367.06\", \"side\":\"BUY\", \"hash\":\"909c77e7af063b986a33dd34daa8f25fd6543391\", \"best_bid\":\"0.76\", \"best_ask\":\"0.77\"}, {\"asset_id\":\"69697746896130839564035629862476347944307040470122503199396727085502753297492\", \"price\":\"0.27\", \"size\":\"367.06\", \"side\":\"SELL\", \"hash\":\"08d436817d2fa5b247ecf514fe0ed625658dd263\", \"best_bid\":\"0.23\", \"best_ask\":\"0.24\"}], \"timestamp\":\"1785126840358\", \"event_type\":\"price_change\"}","received_at":"2026-07-27T04:34:00.305329Z","schema_version":"clob-market-ws.price_change.v1","sequence":null,"server_hash":null,"server_timestamp":"1785126840358","session_id":"e9443c7415a0419799bee9cfbb1a9e4d","source":"clob_market_ws"},"received_at":"2026-07-27T04:34:00.305329Z","record_id":"a20e53b4ada6b3289a350a4c3c222e2b8fa90ae1481ec677412797ee7cf7d038","schema_fingerprint":"4aa3821a28b0b7c2400bc59aba4bcc0a76e971dadd19610d3ad38c768e124dc7","schema_version":"edge-lab-recorder.raw.v1","sequence":null,"source":"clob_market_ws"}
{"event_at":"2026-07-27T04:34:00.362000Z","event_fingerprint":"6d192b4e70906459ca587baeec15a07df19d18dc349f7d447c2cde11625ff479","payload":{"connection_id":"0f4979d6978d463e9660b042fdcf555f","event_at":"2026-07-27T04:34:00.362000Z","event_type":"price_change","frame_hash":"787893903595e078f16014c101af84e5b0ea57e561d6259ec2b6c7d239b0fae7","frame_index":0,"kind":"data","monotonic_ns":228823575529333,"payload":{"event_type":"price_change","market":"0xeb66215f2e9faa6449e30a02bab5b8ed7b79a38bf961f6b24d0073c9c2419250","price_changes":[{"asset_id":"60386828328910021732068595344565885737045900010034836345809386672230885527307","best_ask":"0.77","best_bid":"0.76","hash":"709b1eb08b2fb33c1b4615b10e3dde63790b00a4","price":"0.8","side":"SELL","size":"51.31"},{"asset_id":"69697746896130839564035629862476347944307040470122503199396727085502753297492","best_ask":"0.24","best_bid":"0.23","hash":"b88ae9a57661d23d923bd790ddf85aaba5a7de6c","price":"0.2","side":"BUY","size":"51.31"}],"timestamp":"1785126840362"},"payload_hash":"6f7492354a6ac6c8f720b329c2c2e09e29728b82ba3a6ee896f2f0e1e646eeb3","raw_frame":"{\"market\":\"0xeb66215f2e9faa6449e30a02bab5b8ed7b79a38bf961f6b24d0073c9c2419250\", \"price_changes\":[{\"asset_id\":\"60386828328910021732068595344565885737045900010034836345809386672230885527307\", \"price\":\"0.8\", \"size\":\"51.31\", \"side\":\"SELL\", \"hash\":\"709b1eb08b2fb33c1b4615b10e3dde63790b00a4\", \"best_bid\":\"0.76\", \"best_ask\":\"0.77\"}, {\"asset_id\":\"69697746896130839564035629862476347944307040470122503199396727085502753297492\", \"price\":\"0.2\", \"size\":\"51.31\", \"side\":\"BUY\", \"hash\":\"b88ae9a57661d23d923bd790ddf85aaba5a7de6c\", \"best_bid\":\"0.23\", \"best_ask\":\"0.24\"}], \"timestamp\":\"1785126840362\", \"event_type\":\"price_change\"}","received_at":"2026-07-27T04:34:00.307772Z","schema_version":"clob-market-ws.price_change.v1","sequence":null,"server_hash":null,"server_timestamp":"1785126840362","session_id":"e9443c7415a0419799bee9cfbb1a9e4d","source":"clob_market_ws"},"received_at":"2026-07-27T04:34:00.307772Z","record_id":"a5ff11ce5aa4d4df1a501ab827023d4b41d1d4119533eb9d0a809ab4e65c6325","schema_fingerprint":"4aa3821a28b0b7c2400bc59aba4bcc0a76e971dadd19610d3ad38c768e124dc7","schema_version":"edge-lab-recorder.raw.v1","sequence":null,"source":"clob_market_ws"}
{"event_at":"2026-07-27T04:34:00.365000Z","event_fingerprint":"1a1f533918bf864587ee49b2dd566c0d12640601451759be96bbe02eb9da62b2","payload":{"connection_id":"0f4979d6978d463e9660b042fdcf555f","event_at":"2026-07-27T04:34:00.365000Z","event_type":"price_change","frame_hash":"710592d1cb1f90831730142cf5dae3335f8a3dc459186502b8a06a1ae6df0d67","frame_index":0,"kind":"data","monotonic_ns":228823578331916,"payload":{"event_type":"price_change","market":"0xeb66215f2e9faa6449e30a02bab5b8ed7b79a38bf961f6b24d0073c9c2419250","price_changes":[{"asset_id":"60386828328910021732068595344565885737045900010034836345809386672230885527307","best_ask":"0.77","best_bid":"0.76","hash":"6155b845a4b36eff695aab28b4c72340e29a2221","price":"0.73","side":"BUY","size":"381.02"},{"asset_id":"69697746896130839564035629862476347944307040470122503199396727085502753297492","best_ask":"0.24","best_bid":"0.23","hash":"f09d36f288effe5a0382fba38a36823c05bc3fc9","price":"0.27","side":"SELL","size":"381.02"}],"timestamp":"1785126840365"},"payload_hash":"14f773b319e438b3f5382dada394eb8b39c1b986ba9717d6f5c6c799b9c35c20","raw_frame":"{\"market\":\"0xeb66215f2e9faa6449e30a02bab5b8ed7b79a38bf961f6b24d0073c9c2419250\", \"price_changes\":[{\"asset_id\":\"60386828328910021732068595344565885737045900010034836345809386672230885527307\", \"price\":\"0.73\", \"size\":\"381.02\", \"side\":\"BUY\", \"hash\":\"6155b845a4b36eff695aab28b4c72340e29a2221\", \"best_bid\":\"0.76\", \"best_ask\":\"0.77\"}, {\"asset_id\":\"69697746896130839564035629862476347944307040470122503199396727085502753297492\", \"price\":\"0.27\", \"size\":\"381.02\", \"side\":\"SELL\", \"hash\":\"f09d36f288effe5a0382fba38a36823c05bc3fc9\", \"best_bid\":\"0.23\", \"best_ask\":\"0.24\"}], \"timestamp\":\"1785126840365\", \"event_type\":\"price_change\"}","received_at":"2026-07-27T04:34:00.310574Z","schema_version":"clob-market-ws.price_change.v1","sequence":null,"server_hash":null,"server_timestamp":"1785126840365","session_id":"e9443c7415a0419799bee9cfbb1a9e4d","source":"clob_market_ws"},"received_at":"2026-07-27T04:34:00.310574Z","record_id":"08a6bdc5f2d6cb559e20b01fdcc9f41d020a606c9f027286cf9abb2b40f90815","schema_fingerprint":"4aa3821a28b0b7c2400bc59aba4bcc0a76e971dadd19610d3ad38c768e124dc7","schema_version":"edge-lab-recorder.raw.v1","sequence":null,"source":"clob_market_ws"}
{"event_at":"2026-07-27T04:34:00.371000Z","event_fingerprint":"edd1a5eab8f0f7d77b762a6b493b65d3f9c87e3f07f5791691c70b5e4cae7c25","payload":{"connection_id":"0f4979d6978d463e9660b042fdcf555f","event_at":"2026-07-27T04:34:00.371000Z","event_type":"price_change","frame_hash":"c18aa035d5ec764145ff5b224d2829dae9e6383e3313ee54560ca5a0ee087c08","frame_index":0,"kind":"data","monotonic_ns":228823583275750,"payload":{"event_type":"price_change","market":"0xeb66215f2e9faa6449e30a02bab5b8ed7b79a38bf961f6b24d0073c9c2419250","price_changes":[{"asset_id":"69697746896130839564035629862476347944307040470122503199396727085502753297492","best_ask":"0.24","best_bid":"0.23","hash":"ccde09af4857c74d1dacf3e7de6dcdd72cc75744","price":"0.27","side":"SELL","size":"411.06"},{"asset_id":"60386828328910021732068595344565885737045900010034836345809386672230885527307","best_ask":"0.77","best_bid":"0.76","hash":"cc2e1096025e04605d9baa61455725cecc1f0a67","price":"0.73","side":"BUY","size":"411.06"}],"timestamp":"1785126840371"},"payload_hash":"6f70772a43961c8b7d652a2c6a8a7af407497cb8d121d53ecdffe8fb6a16f8e4","raw_frame":"{\"market\":\"0xeb66215f2e9faa6449e30a02bab5b8ed7b79a38bf961f6b24d0073c9c2419250\", \"price_changes\":[{\"asset_id\":\"69697746896130839564035629862476347944307040470122503199396727085502753297492\", \"price\":\"0.27\", \"size\":\"411.06\", \"side\":\"SELL\", \"hash\":\"ccde09af4857c74d1dacf3e7de6dcdd72cc75744\", \"best_bid\":\"0.23\", \"best_ask\":\"0.24\"}, {\"asset_id\":\"60386828328910021732068595344565885737045900010034836345809386672230885527307\", \"price\":\"0.73\", \"size\":\"411.06\", \"side\":\"BUY\", \"hash\":\"cc2e1096025e04605d9baa61455725cecc1f0a67\", \"best_bid\":\"0.76\", \"best_ask\":\"0.77\"}], \"timestamp\":\"1785126840371\", \"event_type\":\"price_change\"}","received_at":"2026-07-27T04:34:00.315524Z","schema_version":"clob-market-ws.price_change.v1","sequence":null,"server_hash":null,"server_timestamp":"1785126840371","session_id":"e9443c7415a0419799bee9cfbb1a9e4d","source":"clob_market_ws"},"received_at":"2026-07-27T04:34:00.315524Z","record_id":"ba7ba026c13e07d7ad18e4a2f4db21d6ba4dad091c6faafabce3840641ea561e","schema_fingerprint":"4aa3821a28b0b7c2400bc59aba4bcc0a76e971dadd19610d3ad38c768e124dc7","schema_version":"edge-lab-recorder.raw.v1","sequence":null,"source":"clob_market_ws"}
{"event_at":"2026-07-27T04:34:00.384000Z","event_fingerprint":"53dcc301be278869198ee8af2015313b96f15ea8e904dcbb12a5cd61aec24149","payload":{"connection_id":"0f4979d6978d463e9660b042fdcf555f","event_at":"2026-07-27T04:34:00.384000Z","event_type":"price_change","frame_hash":"c460488e71dc41538e0d2a2da2dc9727931ed5df5eb49d145b9b4863cd52bad5","frame_index":0,"kind":"data","monotonic_ns":228823596216000,"payload":{"event_type":"price_change","market":"0xeb66215f2e9faa6449e30a02bab5b8ed7b79a38bf961f6b24d0073c9c2419250","price_changes":[{"asset_id":"69697746896130839564035629862476347944307040470122503199396727085502753297492","best_ask":"0.24","best_bid":"0.23","hash":"ab1e2bc9579b78a5ddbe3d9cbe2b57ddd4b71289","price":"0.22","side":"BUY","size":"0"},{"asset_id":"60386828328910021732068595344565885737045900010034836345809386672230885527307","best_ask":"0.77","best_bid":"0.76","hash":"a091ab5d6dd470be454aa7e66dae8a914314dd74","price":"0.78","side":"SELL","size":"0"}],"timestamp":"1785126840384"},"payload_hash":"1c672c4e1041ccc48c36d3e630f7541d70bbd64ea0410606a7bef835bccb0e40","raw_frame":"{\"market\":\"0xeb66215f2e9faa6449e30a02bab5b8ed7b79a38bf961f6b24d0073c9c2419250\", \"price_changes\":[{\"asset_id\":\"69697746896130839564035629862476347944307040470122503199396727085502753297492\", \"price\":\"0.22\", \"size\":\"0\", \"side\":\"BUY\", \"hash\":\"ab1e2bc9579b78a5ddbe3d9cbe2b57ddd4b71289\", \"best_bid\":\"0.23\", \"best_ask\":\"0.24\"}, {\"asset_id\":\"60386828328910021732068595344565885737045900010034836345809386672230885527307\", \"price\":\"0.78\", \"size\":\"0\", \"side\":\"SELL\", \"hash\":\"a091ab5d6dd470be454aa7e66dae8a914314dd74\", \"best_bid\":\"0.76\", \"best_ask\":\"0.77\"}], \"timestamp\":\"1785126840384\", \"event_type\":\"price_change\"}","received_at":"2026-07-27T04:34:00.328458Z","schema_version":"clob-market-ws.price_change.v1","sequence":null,"server_hash":null,"server_timestamp":"1785126840384","session_id":"e9443c7415a0419799bee9cfbb1a9e4d","source":"clob_market_ws"},"received_at":"2026-07-27T04:34:00.328458Z","record_id":"54aa746cb1764941201b044228c169a9c03cdde7daa2e18c7dfc438fe9217338","schema_fingerprint":"4aa3821a28b0b7c2400bc59aba4bcc0a76e971dadd19610d3ad38c768e124dc7","schema_version":"edge-lab-recorder.raw.v1","sequence":null,"source":"clob_market_ws"}
{"event_at":"2026-07-27T04:34:00.386000Z","event_fingerprint":"3d857c02f4197b166f71a69bf15654ba78929080ca29daa123dc34ac35053c0c","payload":{"connection_id":"0f4979d6978d463e9660b042fdcf555f","event_at":"2026-07-27T04:34:00.386000Z","event_type":"price_change","frame_hash":"dd677104f9f8b338e9c2b73f5c98eeae88835fdec58deb203c495a94bf4aec1a","frame_index":0,"kind":"data","monotonic_ns":228823598531666,"payload":{"event_type":"price_change","market":"0xeb66215f2e9faa6449e30a02bab5b8ed7b79a38bf961f6b24d0073c9c2419250","price_changes":[{"asset_id":"60386828328910021732068595344565885737045900010034836345809386672230885527307","best_ask":"0.77","best_bid":"0.76","hash":"7a60821b2132a52fa6597ef4939298ff15bfe217","price":"0.02","side":"BUY","size":"738.1"},{"asset_id":"69697746896130839564035629862476347944307040470122503199396727085502753297492","best_ask":"0.24","best_bid":"0.23","hash":"f3e537289f44b2c5933878c475fb59358dfa3a91","price":"0.98","side":"SELL","size":"738.1"}],"timestamp":"1785126840386"},"payload_hash":"12f08e75bf81bfe11440186fdaaf243ded75d492532cc8544db1811702e4a300","raw_frame":"{\"market\":\"0xeb66215f2e9faa6449e30a02bab5b8ed7b79a38bf961f6b24d0073c9c2419250\", \"price_changes\":[{\"asset_id\":\"60386828328910021732068595344565885737045900010034836345809386672230885527307\", \"price\":\"0.02\", \"size\":\"738.1\", \"side\":\"BUY\", \"hash\":\"7a60821b2132a52fa6597ef4939298ff15bfe217\", \"best_bid\":\"0.76\", \"best_ask\":\"0.77\"}, {\"asset_id\":\"69697746896130839564035629862476347944307040470122503199396727085502753297492\", \"price\":\"0.98\", \"size\":\"738.1\", \"side\":\"SELL\", \"hash\":\"f3e537289f44b2c5933878c475fb59358dfa3a91\", \"best_bid\":\"0.23\", \"best_ask\":\"0.24\"}], \"timestamp\":\"1785126840386\", \"event_type\":\"price_change\"}","received_at":"2026-07-27T04:34:00.330772Z","schema_version":"clob-market-ws.price_change.v1","sequence":null,"server_hash":null,"server_timestamp":"1785126840386","session_id":"e9443c7415a0419799bee9cfbb1a9e4d","source":"clob_market_ws"},"received_at":"2026-07-27T04:34:00.330772Z","record_id":"3f1cc60baa91b7e8736be6649a120d1c6eecf7090844018635c087f5e0caab24","schema_fingerprint":"4aa3821a28b0b7c2400bc59aba4bcc0a76e971dadd19610d3ad38c768e124dc7","schema_version":"edge-lab-recorder.raw.v1","sequence":null,"source":"clob_market_ws"}
{"event_at":"2026-07-27T04:34:00.408000Z","event_fingerprint":"de6340db7df8449754a3192335fc9db39a8ef1bdb97e4a48e05deb7e0cacd3cc","payload":{"connection_id":"0f4979d6978d463e9660b042fdcf555f","event_at":"2026-07-27T04:34:00.408000Z","event_type":"price_change","frame_hash":"6fdb02a59b56c0a9fece964c797f5a2003ea8c2c5a582b0b4b7c468b75affe0b","frame_index":0,"kind":"data","monotonic_ns":228823621251000,"payload":{"event_type":"price_change","market":"0xeb66215f2e9faa6449e30a02bab5b8ed7b79a38bf961f6b24d0073c9c2419250","price_changes":[{"asset_id":"60386828328910021732068595344565885737045900010034836345809386672230885527307","best_ask":"0.77","best_bid":"0.76","hash":"bd95d37da2ad647e90f1c090bd2368522ab7e081","price":"0.7","side":"BUY","size":"205"},{"asset_id":"69697746896130839564035629862476347944307040470122503199396727085502753297492","best_ask":"0.24","best_bid":"0.23","hash":"1457ad84ae5241cce62f98ea422855a2b8a71d38","price":"0.3","side":"SELL","size":"205"}],"timestamp":"1785126840408"},"payload_hash":"adb7467ac494b9b2dbfb34b5b6375d7e2bd8b3784c7d569f89357c2afdb7d4a6","raw_frame":"{\"market\":\"0xeb66215f2e9faa6449e30a02bab5b8ed7b79a38bf961f6b24d0073c9c2419250\", \"price_changes\":[{\"asset_id\":\"60386828328910021732068595344565885737045900010034836345809386672230885527307\", \"price\":\"0.7\", \"size\":\"205\", \"side\":\"BUY\", \"hash\":\"bd95d37da2ad647e90f1c090bd2368522ab7e081\", \"best_bid\":\"0.76\", \"best_ask\":\"0.77\"}, {\"asset_id\":\"69697746896130839564035629862476347944307040470122503199396727085502753297492\", \"price\":\"0.3\", \"size\":\"205\", \"side\":\"SELL\", \"hash\":\"1457ad84ae5241cce62f98ea422855a2b8a71d38\", \"best_bid\":\"0.23\", \"best_ask\":\"0.24\"}], \"timestamp\":\"1785126840408\", \"event_type\":\"price_change\"}","received_at":"2026-07-27T04:34:00.353497Z","schema_version":"clob-market-ws.price_change.v1","sequence":null,"server_hash":null,"server_timestamp":"1785126840408","session_id":"e9443c7415a0419799bee9cfbb1a9e4d","source":"clob_market_ws"},"received_at":"2026-07-27T04:34:00.353497Z","record_id":"2b80cf279bc5d791646f4fdcaf01374a9e2e95d5567bbd127310bd5afa55d6c0","schema_fingerprint":"4aa3821a28b0b7c2400bc59aba4bcc0a76e971dadd19610d3ad38c768e124dc7","schema_version":"edge-lab-recorder.raw.v1","sequence":null,"source":"clob_market_ws"}
{"event_at":"2026-07-27T04:34:00.449000Z","event_fingerprint":"f0a707d5a87ce9ded85d1179f7027b4970e81f796420eb6bd4863ab475b0986a","payload":{"connection_id":"0f4979d6978d463e9660b042fdcf555f","event_at":"2026-07-27T04:34:00.449000Z","event_type":"price_change","frame_hash":"4c3420da2c1bf883954a0990d9e024536bdd38ed7bd1b2d90d78ed3d0f4ac8c0","frame_index":0,"kind":"data","monotonic_ns":228823662699833,"payload":{"event_type":"price_change","market":"0xeb66215f2e9faa6449e30a02bab5b8ed7b79a38bf961f6b24d0073c9c2419250","price_changes":[{"asset_id":"60386828328910021732068595344565885737045900010034836345809386672230885527307","best_ask":"0.77","best_bid":"0.76","hash":"483294aa8b2cda62b36c73d533912b1b054e1a61","price":"0.63","side":"BUY","size":"147.9"},{"asset_id":"69697746896130839564035629862476347944307040470122503199396727085502753297492","best_ask":"0.24","best_bid":"0.23","hash":"4353da685a0d79491884afdffa966ba7bd3db6f0","price":"0.37","side":"SELL","size":"147.9"}],"timestamp":"1785126840449"},"payload_hash":"2cc458e34ca1a8434c6c422c806da038949dd3f98556b7b15fd422ad89d27af4","raw_frame":"{\"market\":\"0xeb66215f2e9faa6449e30a02bab5b8ed7b79a38bf961f6b24d0073c9c2419250\", \"price_changes\":[{\"asset_id\":\"60386828328910021732068595344565885737045900010034836345809386672230885527307\", \"price\":\"0.63\", \"size\":\"147.9\", \"side\":\"BUY\", \"hash\":\"483294aa8b2cda62b36c73d533912b1b054e1a61\", \"best_bid\":\"0.76\", \"best_ask\":\"0.77\"}, {\"asset_id\":\"69697746896130839564035629862476347944307040470122503199396727085502753297492\", \"price\":\"0.37\", \"size\":\"147.9\", \"side\":\"SELL\", \"hash\":\"4353da685a0d79491884afdffa966ba7bd3db6f0\", \"best_bid\":\"0.23\", \"best_ask\":\"0.24\"}], \"timestamp\":\"1785126840449\", \"event_type\":\"price_change\"}","received_at":"2026-07-27T04:34:00.394946Z","schema_version":"clob-market-ws.price_change.v1","sequence":null,"server_hash":null,"server_timestamp":"1785126840449","session_id":"e9443c7415a0419799bee9cfbb1a9e4d","source":"clob_market_ws"},"received_at":"2026-07-27T04:34:00.394946Z","record_id":"798ea584bbbafe7994e5810b17967cd90bc3d27c749328a6ced3686e48870ed6","schema_fingerprint":"4aa3821a28b0b7c2400bc59aba4bcc0a76e971dadd19610d3ad38c768e124dc7","schema_version":"edge-lab-recorder.raw.v1","sequence":null,"source":"clob_market_ws"}
{"event_at":"2026-07-27T04:34:00.453000Z","event_fingerprint":"8d0d60c62d14d6d05ca00614c9c408ae4401edf9ede1ccd4e4690b85b388251a","payload":{"connection_id":"0f4979d6978d463e9660b042fdcf555f","event_at":"2026-07-27T04:34:00.453000Z","event_type":"price_change","frame_hash":"ded4ecbfd1339cf811e938fc5ec97eee6bb0e8325612e835af6544139e59bc85","frame_index":0,"kind":"data","monotonic_ns":228823665877375,"payload":{"event_type":"price_change","market":"0xeb66215f2e9faa6449e30a02bab5b8ed7b79a38bf961f6b24d0073c9c2419250","price_changes":[{"asset_id":"60386828328910021732068595344565885737045900010034836345809386672230885527307","best_ask":"0.77","best_bid":"0.76","hash":"0260e9af7234df48aa51092dc07761fc1d0321e7","price":"0.02","side":"BUY","size":"733.1"},{"asset_id":"69697746896130839564035629862476347944307040470122503199396727085502753297492","best_ask":"0.24","best_bid":"0.23","hash":"8d816c1e71b6055b43caec0a495b65ce5a3ae608","price":"0.98","side":"SELL","size":"733.1"}],"timestamp":"1785126840453"},"payload_hash":"690c0d31ead9e2e118daccbd675c89a29024564e134cbf0c68fc54a3aa084066","raw_frame":"{\"market\":\"0xeb66215f2e9faa6449e30a02bab5b8ed7b79a38bf961f6b24d0073c9c2419250\", \"price_changes\":[{\"asset_id\":\"60386828328910021732068595344565885737045900010034836345809386672230885527307\", \"price\":\"0.02\", \"size\":\"733.1\", \"side\":\"BUY\", \"hash\":\"0260e9af7234df48aa51092dc07761fc1d0321e7\", \"best_bid\":\"0.76\", \"best_ask\":\"0.77\"}, {\"asset_id\":\"69697746896130839564035629862476347944307040470122503199396727085502753297492\", \"price\":\"0.98\", \"size\":\"733.1\", \"side\":\"SELL\", \"hash\":\"8d816c1e71b6055b43caec0a495b65ce5a3ae608\", \"best_bid\":\"0.23\", \"best_ask\":\"0.24\"}], \"timestamp\":\"1785126840453\", \"event_type\":\"price_change\"}","received_at":"2026-07-27T04:34:00.398124Z","schema_version":"clob-market-ws.price_change.v1","sequence":null,"server_hash":null,"server_timestamp":"1785126840453","session_id":"e9443c7415a0419799bee9cfbb1a9e4d","source":"clob_market_ws"},"received_at":"2026-07-27T04:34:00.398124Z","record_id":"4816fa75b408f2c08de60620802fa2d448e1c817e80832972dbe8d57f618742d","schema_fingerprint":"4aa3821a28b0b7c2400bc59aba4bcc0a76e971dadd19610d3ad38c768e124dc7","schema_version":"edge-lab-recorder.raw.v1","sequence":null,"source":"clob_market_ws"}
{"event_at":"2026-07-27T04:34:00.478000Z","event_fingerprint":"02d04db1fad456056c147b2b29032f6aebf79cba0c9726bda43930f8460de239","payload":{"connection_id":"0f4979d6978d463e9660b042fdcf555f","event_at":"2026-07-27T04:34:00.478000Z","event_type":"price_change","frame_hash":"58f290a0274dc159eec32167a11cef94027848e997cc01dbcf1b1d6efc11195e","frame_index":0,"kind":"data","monotonic_ns":228823690153208,"payload":{"event_type":"price_change","market":"0xeb66215f2e9faa6449e30a02bab5b8ed7b79a38bf961f6b24d0073c9c2419250","price_changes":[{"asset_id":"69697746896130839564035629862476347944307040470122503199396727085502753297492","best_ask":"0.24","best_bid":"0.23","hash":"2b5ea61d5705cb0e1d91f87aab34ecc5b23a7dd0","price":"0.27","side":"SELL","size":"381.02"},{"asset_id":"60386828328910021732068595344565885737045900010034836345809386672230885527307","best_ask":"0.77","best_bid":"0.76","hash":"f8ab88d440f6a687e15efa636d3954244767702e","price":"0.73","side":"BUY","size":"381.02"}],"timestamp":"1785126840478"},"payload_hash":"ba08278d152bd4ecac9f266def4676ffbc437db3226c2d91e0ead45050020f9e","raw_frame":"{\"market\":\"0xeb66215f2e9faa6449e30a02bab5b8ed7b79a38bf961f6b24d0073c9c2419250\", \"price_changes\":[{\"asset_id\":\"69697746896130839564035629862476347944307040470122503199396727085502753297492\", \"price\":\"0.27\", \"size\":\"381.02\", \"side\":\"SELL\", \"hash\":\"2b5ea61d5705cb0e1d91f87aab34ecc5b23a7dd0\", \"best_bid\":\"0.23\", \"best_ask\":\"0.24\"}, {\"asset_id\":\"60386828328910021732068595344565885737045900010034836345809386672230885527307\", \"price\":\"0.73\", \"size\":\"381.02\", \"side\":\"BUY\", \"hash\":\"f8ab88d440f6a687e15efa636d3954244767702e\", \"best_bid\":\"0.76\", \"best_ask\":\"0.77\"}], \"timestamp\":\"1785126840478\", \"event_type\":\"price_change\"}","received_at":"2026-07-27T04:34:00.422394Z","schema_version":"clob-market-ws.price_change.v1","sequence":null,"server_hash":null,"server_timestamp":"1785126840478","session_id":"e9443c7415a0419799bee9cfbb1a9e4d","source":"clob_market_ws"},"received_at":"2026-07-27T04:34:00.422394Z","record_id":"7243f478d4ff8d269e692d5a999f039b7392b12c3de9e08b74d02f0cb92e0544","schema_fingerprint":"4aa3821a28b0b7c2400bc59aba4bcc0a76e971dadd19610d3ad38c768e124dc7","schema_version":"edge-lab-recorder.raw.v1","sequence":null,"source":"clob_market_ws"}
{"event_at":"2026-07-27T04:34:00.478000Z","event_fingerprint":"375a23560eb91220e0e0178e306affe6aedd1c74d0057bbce3736c51bc02e0e1","payload":{"connection_id":"0f4979d6978d463e9660b042fdcf555f","event_at":"2026-07-27T04:34:00.478000Z","event_type":"price_change","frame_hash":"ab72013b00304121c0906301a480c3f7ba838dcce3d3b37ca57f12cde58c4e6c","frame_index":0,"kind":"data","monotonic_ns":228823691866083,"payload":{"event_type":"price_change","market":"0xeb66215f2e9faa6449e30a02bab5b8ed7b79a38bf961f6b24d0073c9c2419250","price_changes":[{"asset_id":"60386828328910021732068595344565885737045900010034836345809386672230885527307","best_ask":"0.77","best_bid":"0.76","hash":"52c3ef48f33bb31eba462725cb943fc23d62d107","price":"0.8","side":"SELL","size":"46.27"},{"asset_id":"69697746896130839564035629862476347944307040470122503199396727085502753297492","best_ask":"0.24","best_bid":"0.23","hash":"6f9e508c5c6bf76d701aa510f493e45a0a85b2b4","price":"0.2","side":"BUY","size":"46.27"}],"timestamp":"1785126840478"},"payload_hash":"de1b8a6d6697c40da1725d24c23d2fed800536ea66ce5f27b753810f8f46c22a","raw_frame":"{\"market\":\"0xeb66215f2e9faa6449e30a02bab5b8ed7b79a38bf961f6b24d0073c9c2419250\", \"price_changes\":[{\"asset_id\":\"60386828328910021732068595344565885737045900010034836345809386672230885527307\", \"price\":\"0.8\", \"size\":\"46.27\", \"side\":\"SELL\", \"hash\":\"52c3ef48f33bb31eba462725cb943fc23d62d107\", \"best_bid\":\"0.76\", \"best_ask\":\"0.77\"}, {\"asset_id\":\"69697746896130839564035629862476347944307040470122503199396727085502753297492\", \"price\":\"0.2\", \"size\":\"46.27\", \"side\":\"BUY\", \"hash\":\"6f9e508c5c6bf76d701aa510f493e45a0a85b2b4\", \"best_bid\":\"0.23\", \"best_ask\":\"0.24\"}], \"timestamp\":\"1785126840478\", \"event_type\":\"price_change\"}","received_at":"2026-07-27T04:34:00.424111Z","schema_version":"clob-market-ws.price_change.v1","sequence":null,"server_hash":null,"server_timestamp":"1785126840478","session_id":"e9443c7415a0419799bee9cfbb1a9e4d","source":"clob_market_ws"},"received_at":"2026-07-27T04:34:00.424111Z","record_id":"a26e21b41fbbbf40ba43a47e1511171e1f1cb5fd0fb7bd3648c8bb923388dc6c","schema_fingerprint":"4aa3821a28b0b7c2400bc59aba4bcc0a76e971dadd19610d3ad38c768e124dc7","schema_version":"edge-lab-recorder.raw.v1","sequence":null,"source":"clob_market_ws"}
{"event_at":"2026-07-27T04:34:00.482000Z","event_fingerprint":"00f6b1bd18343612d202171d4d5ce8a778ee0c8f221d5adf9b4c59a484f300bd","payload":{"connection_id":"0f4979d6978d463e9660b042fdcf555f","event_at":"2026-07-27T04:34:00.482000Z","event_type":"price_change","frame_hash":"1db7d82b4334a5c70bcefba70a7571ba3f34d205661e4f14a221ea665bc6f5bc","frame_index":0,"kind":"data","monotonic_ns":228823694059166,"payload":{"event_type":"price_change","market":"0xeb66215f2e9faa6449e30a02bab5b8ed7b79a38bf961f6b24d0073c9c2419250","price_changes":[{"asset_id":"60386828328910021732068595344565885737045900010034836345809386672230885527307","best_ask":"0.77","best_bid":"0.76","hash":"280c241dbcc9a06f2cfc0d1f475131757fdd8f6e","price":"0.74","side":"BUY","size":"110.79"},{"asset_id":"69697746896130839564035629862476347944307040470122503199396727085502753297492","best_ask":"0.24","best_bid":"0.23","hash":"9b79ebb354b3ce23e1c48022e8ed1af99553bd65","price":"0.26","side":"SELL","size":"110.79"}],"timestamp":"1785126840482"},"payload_hash":"cb82b08f636ae2b5780c84cf8df4c0534d4d822aa8f196690b30e7e09e260e40","raw_frame":"{\"market\":\"0xeb66215f2e9faa6449e30a02bab5b8ed7b79a38bf961f6b24d0073c9c2419250\", \"price_changes\":[{\"asset_id\":\"60386828328910021732068595344565885737045900010034836345809386672230885527307\", \"price\":\"0.74\", \"size\":\"110.79\", \"side\":\"BUY\", \"hash\":\"280c241dbcc9a06f2cfc0d1f475131757fdd8f6e\", \"best_bid\":\"0.76\", \"best_ask\":\"0.77\"}, {\"asset_id\":\"69697746896130839564035629862476347944307040470122503199396727085502753297492\", \"price\":\"0.26\", \"size\":\"110.79\", \"side\":\"SELL\", \"hash\":\"9b79ebb354b3ce23e1c48022e8ed1af99553bd65\", \"best_bid\":\"0.23\", \"best_ask\":\"0.24\"}], \"timestamp\":\"1785126840482\", \"event_type\":\"price_change\"}","received_at":"2026-07-27T04:34:00.426307Z","schema_version":"clob-market-ws.price_change.v1","sequence":null,"server_hash":null,"server_timestamp":"1785126840482","session_id":"e9443c7415a0419799bee9cfbb1a9e4d","source":"clob_market_ws"},"received_at":"2026-07-27T04:34:00.426307Z","record_id":"4f4f8537a008d149281015899446fd7ceb822a7696ccb3eee5d485b205785ff8","schema_fingerprint":"4aa3821a28b0b7c2400bc59aba4bcc0a76e971dadd19610d3ad38c768e124dc7","schema_version":"edge-lab-recorder.raw.v1","sequence":null,"source":"clob_market_ws"}
{"event_at":"2026-07-27T04:34:00.483000Z","event_fingerprint":"59bf4330da10fa8e9c02881f8236646b3ce3678ca7a5f3ddff300be6fc2c486c","payload":{"connection_id":"0f4979d6978d463e9660b042fdcf555f","event_at":"2026-07-27T04:34:00.483000Z","event_type":"price_change","frame_hash":"71921fd3ac5b3b529e81e2d707ab93656604bf9de89ab036f63751850c377f4d","frame_index":0,"kind":"data","monotonic_ns":228823696300041,"payload":{"event_type":"price_change","market":"0xeb66215f2e9faa6449e30a02bab5b8ed7b79a38bf961f6b24d0073c9c2419250","price_changes":[{"asset_id":"60386828328910021732068595344565885737045900010034836345809386672230885527307","best_ask":"0.77","best_bid":"0.76","hash":"26c491e166ec9a53a19765643d1872fa466e8b3a","price":"0.73","side":"BUY","size":"411.06"},{"asset_id":"69697746896130839564035629862476347944307040470122503199396727085502753297492","best_ask":"0.24","best_bid":"0.23","hash":"3864175a89f9f7907c7ae6c959aaad134e2def0b","price":"0.27","side":"SELL","size":"411.06"}],"timestamp":"1785126840483"},"payload_hash":"2fd6d4b88831a153fd8bd62cd62c7bed854861711607ba948cde956a943eff88","raw_frame":"{\"market\":\"0xeb66215f2e9faa6449e30a02bab5b8ed7b79a38bf961f6b24d0073c9c2419250\", \"price_changes\":[{\"asset_id\":\"60386828328910021732068595344565885737045900010034836345809386672230885527307\", \"price\":\"0.73\", \"size\":\"411.06\", \"side\":\"BUY\", \"hash\":\"26c491e166ec9a53a19765643d1872fa466e8b3a\", \"best_bid\":\"0.76\", \"best_ask\":\"0.77\"}, {\"asset_id\":\"69697746896130839564035629862476347944307040470122503199396727085502753297492\", \"price\":\"0.27\", \"size\":\"411.06\", \"side\":\"SELL\", \"hash\":\"3864175a89f9f7907c7ae6c959aaad134e2def0b\", \"best_bid\":\"0.23\", \"best_ask\":\"0.24\"}], \"timestamp\":\"1785126840483\", \"event_type\":\"price_change\"}","received_at":"2026-07-27T04:34:00.428547Z","schema_version":"clob-market-ws.price_change.v1","sequence":null,"server_hash":null,"server_timestamp":"1785126840483","session_id":"e9443c7415a0419799bee9cfbb1a9e4d","source":"clob_market_ws"},"received_at":"2026-07-27T04:34:00.428547Z","record_id":"20c068f047e82c0c07c0d9dfa95f467105bc1301e3ca891b9b5dcfe02779be98","schema_fingerprint":"4aa3821a28b0b7c2400bc59aba4bcc0a76e971dadd19610d3ad38c768e124dc7","schema_version":"edge-lab-recorder.raw.v1","sequence":null,"source":"clob_market_ws"}
{"event_at":"2026-07-27T04:34:00.573000Z","event_fingerprint":"39f9d6aaf8e5789ef7c1b2058372cb2ecbbcabbc0081fdf6624fbfc8352cacd0","payload":{"connection_id":"0f4979d6978d463e9660b042fdcf555f","event_at":"2026-07-27T04:34:00.573000Z","event_type":"best_bid_ask","frame_hash":"59fb45754787874957c2e4ee452ed90b90b0fde5ee3876b8f8c81039ed9b0153","frame_index":0,"kind":"data","monotonic_ns":228823785815083,"payload":{"asset_id":"69697746896130839564035629862476347944307040470122503199396727085502753297492","best_ask":"0.24","best_bid":"0.23","event_type":"best_bid_ask","market":"0xeb66215f2e9faa6449e30a02bab5b8ed7b79a38bf961f6b24d0073c9c2419250","spread":"0.01","timestamp":"1785126840573"},"payload_hash":"c2e57f4dcd400221092a6753d7da8cea1f5ed206869c04be03901f4da619913c","raw_frame":"{\"market\":\"0xeb66215f2e9faa6449e30a02bab5b8ed7b79a38bf961f6b24d0073c9c2419250\", \"asset_id\":\"69697746896130839564035629862476347944307040470122503199396727085502753297492\", \"best_bid\":\"0.23\", \"best_ask\":\"0.24\", \"spread\":\"0.01\", \"timestamp\":\"1785126840573\", \"event_type\":\"best_bid_ask\"}","received_at":"2026-07-27T04:34:00.518040Z","schema_version":"clob-market-ws.best_bid_ask.v1","sequence":null,"server_hash":null,"server_timestamp":"1785126840573","session_id":"e9443c7415a0419799bee9cfbb1a9e4d","source":"clob_market_ws"},"received_at":"2026-07-27T04:34:00.518040Z","record_id":"31e9dde36ceb9d15da47a6fb3ebba081dc1e795f3e8e1b00835df5366df40269","schema_fingerprint":"8488399f31b0337811b13b266be932db7062827c2470b78bd8e9e99bab51d17d","schema_version":"edge-lab-recorder.raw.v1","sequence":null,"source":"clob_market_ws"}
{"event_at":"2026-07-27T04:34:00.573000Z","event_fingerprint":"d8dd845c50abf4b16413068e2c16fc2bf452a33efb33403e8d15fe8d9f821342","payload":{"connection_id":"0f4979d6978d463e9660b042fdcf555f","event_at":"2026-07-27T04:34:00.573000Z","event_type":"best_bid_ask","frame_hash":"48ce16effcad89165cc281dd3c6622aa9f557fbed71f4f0e4547e00e3afb6a2a","frame_index":0,"kind":"data","monotonic_ns":228823788129125,"payload":{"asset_id":"60386828328910021732068595344565885737045900010034836345809386672230885527307","best_ask":"0.77","best_bid":"0.76","event_type":"best_bid_ask","market":"0xeb66215f2e9faa6449e30a02bab5b8ed7b79a38bf961f6b24d0073c9c2419250","spread":"0.01","timestamp":"1785126840573"},"payload_hash":"015208ccc1ba00300cb06fd384626916e48453b5453c84589b0feaa52ff19ac0","raw_frame":"{\"market\":\"0xeb66215f2e9faa6449e30a02bab5b8ed7b79a38bf961f6b24d0073c9c2419250\", \"asset_id\":\"60386828328910021732068595344565885737045900010034836345809386672230885527307\", \"best_bid\":\"0.76\", \"best_ask\":\"0.77\", \"spread\":\"0.01\", \"timestamp\":\"1785126840573\", \"event_type\":\"best_bid_ask\"}","received_at":"2026-07-27T04:34:00.520371Z","schema_version":"clob-market-ws.best_bid_ask.v1","sequence":null,"server_hash":null,"server_timestamp":"1785126840573","session_id":"e9443c7415a0419799bee9cfbb1a9e4d","source":"clob_market_ws"},"received_at":"2026-07-27T04:34:00.520371Z","record_id":"1b82a4ff6fa8aa36e195cc05ffa4bbd706c582bbaa39b2ab980bdc03126b832f","schema_fingerprint":"8488399f31b0337811b13b266be932db7062827c2470b78bd8e9e99bab51d17d","schema_version":"edge-lab-recorder.raw.v1","sequence":null,"source":"clob_market_ws"}
{"event_at":"2026-07-27T04:34:00.573000Z","event_fingerprint":"fa9d15b1bb483ce85084ab7656b6c2c211f7f82fa2f75b093cab2bebc7178a4c","payload":{"connection_id":"0f4979d6978d463e9660b042fdcf555f","event_at":"2026-07-27T04:34:00.573000Z","event_type":"price_change","frame_hash":"b5d4e1de82678b91abc637279d55d8f273affe53a190e4b01f5acde1bf453892","frame_index":0,"kind":"data","monotonic_ns":228823789406791,"payload":{"event_type":"price_change","market":"0xeb66215f2e9faa6449e30a02bab5b8ed7b79a38bf961f6b24d0073c9c2419250","price_changes":[{"asset_id":"69697746896130839564035629862476347944307040470122503199396727085502753297492","best_ask":"0.24","best_bid":"0.23","hash":"3ab423c6e10b9691590612f4b15bc0dcf27854e7","price":"0.23","side":"BUY","size":"384.5"},{"asset_id":"60386828328910021732068595344565885737045900010034836345809386672230885527307","best_ask":"0.77","best_bid":"0.76","hash":"04ab09b9bf1cc8516d5ae5fe6ca609b22cad9ccb","price":"0.77","side":"SELL","size":"384.5"}],"timestamp":"1785126840573"},"payload_hash":"33cfef2224aca9e948f291390ec3a8d4fdd35688f8087d853e2fedffc6760e99","raw_frame":"{\"market\":\"0xeb66215f2e9faa6449e30a02bab5b8ed7b79a38bf961f6b24d0073c9c2419250\", \"price_changes\":[{\"asset_id\":\"69697746896130839564035629862476347944307040470122503199396727085502753297492\", \"price\":\"0.23\", \"size\":\"384.5\", \"side\":\"BUY\", \"hash\":\"3ab423c6e10b9691590612f4b15bc0dcf27854e7\", \"best_bid\":\"0.23\", \"best_ask\":\"0.24\"}, {\"asset_id\":\"60386828328910021732068595344565885737045900010034836345809386672230885527307\", \"price\":\"0.77\", \"size\":\"384.5\", \"side\":\"SELL\", \"hash\":\"04ab09b9bf1cc8516d5ae5fe6ca609b22cad9ccb\", \"best_bid\":\"0.76\", \"best_ask\":\"0.77\"}], \"timestamp\":\"1785126840573\", \"event_type\":\"price_change\"}","received_at":"2026-07-27T04:34:00.521653Z","schema_version":"clob-market-ws.price_change.v1","sequence":null,"server_hash":null,"server_timestamp":"1785126840573","session_id":"e9443c7415a0419799bee9cfbb1a9e4d","source":"clob_market_ws"},"received_at":"2026-07-27T04:34:00.521653Z","record_id":"4c912082046742f28741dc7e658d11d62f7d9a9267bc1688774423f7f004c804","schema_fingerprint":"4aa3821a28b0b7c2400bc59aba4bcc0a76e971dadd19610d3ad38c768e124dc7","schema_version":"edge-lab-recorder.raw.v1","sequence":null,"source":"clob_market_ws"}
