{"event_at":"2026-07-27T04:37:39.154000Z","event_fingerprint":"5617c8bcda900f08da1a254e75a4ec0212d829c23d999d8e5c004bbd1d0e792a","payload":{"connection_id":"0f4979d6978d463e9660b042fdcf555f","event_at":"2026-07-27T04:37:39.154000Z","event_type":"price_change","frame_hash":"e8cd764e257dddc7cc026b47db38337869532fbae44d6d9de02e3ec898a63462","frame_index":0,"kind":"data","monotonic_ns":229042365338958,"payload":{"event_type":"price_change","market":"0xeb66215f2e9faa6449e30a02bab5b8ed7b79a38bf961f6b24d0073c9c2419250","price_changes":[{"asset_id":"69697746896130839564035629862476347944307040470122503199396727085502753297492","best_ask":"0.62","best_bid":"0.61","hash":"9f298a511402f2c8d1fce1445c51bd688f1a071c","price":"0.53","side":"BUY","size":"45"},{"asset_id":"60386828328910021732068595344565885737045900010034836345809386672230885527307","best_ask":"0.39","best_bid":"0.38","hash":"227134c802fb2fe5d7c068d15c826cedb01fccd1","price":"0.47","side":"SELL","size":"45"}],"timestamp":"1785127059154"},"payload_hash":"ee32128755733393c7fda6fb2d6f587420ebaf1a20aed1323744165bf4f75a13","raw_frame":"{\"market\":\"0xeb66215f2e9faa6449e30a02bab5b8ed7b79a38bf961f6b24d0073c9c2419250\", \"price_changes\":[{\"asset_id\":\"69697746896130839564035629862476347944307040470122503199396727085502753297492\", \"price\":\"0.53\", \"size\":\"45\", \"side\":\"BUY\", \"hash\":\"9f298a511402f2c8d1fce1445c51bd688f1a071c\", \"best_bid\":\"0.61\", \"best_ask\":\"0.62\"}, {\"asset_id\":\"60386828328910021732068595344565885737045900010034836345809386672230885527307\", \"price\":\"0.47\", \"size\":\"45\", \"side\":\"SELL\", \"hash\":\"227134c802fb2fe5d7c068d15c826cedb01fccd1\", \"best_bid\":\"0.38\", \"best_ask\":\"0.39\"}], \"timestamp\":\"1785127059154\", \"event_type\":\"price_change\"}","received_at":"2026-07-27T04:37:39.099486Z","schema_version":"clob-market-ws.price_change.v1","sequence":null,"server_hash":null,"server_timestamp":"1785127059154","session_id":"e9443c7415a0419799bee9cfbb1a9e4d","source":"clob_market_ws"},"received_at":"2026-07-27T04:37:39.099486Z","record_id":"0a7b3288f8dc357c87a89e43ad9380cf47d33c631d7873806a0d072615cdd7cc","schema_fingerprint":"4aa3821a28b0b7c2400bc59aba4bcc0a76e971dadd19610d3ad38c768e124dc7","schema_version":"edge-lab-recorder.raw.v1","sequence":null,"source":"clob_market_ws"}
{"event_at":"2026-07-27T04:37:39.154000Z","event_fingerprint":"8cfe7fa44c960c980606ed6415a4ecca945f16de6a781684a14dd56f1482d5e2","payload":{"connection_id":"0f4979d6978d463e9660b042fdcf555f","event_at":"2026-07-27T04:37:39.154000Z","event_type":"price_change","frame_hash":"f95598658ef18295d4651f78aabc0545b316b88abc2c2d4b2b96cb054399df22","frame_index":0,"kind":"data","monotonic_ns":229042366630583,"payload":{"event_type":"price_change","market":"0xeb66215f2e9faa6449e30a02bab5b8ed7b79a38bf961f6b24d0073c9c2419250","price_changes":[{"asset_id":"60386828328910021732068595344565885737045900010034836345809386672230885527307","best_ask":"0.39","best_bid":"0.38","hash":"227134c802fb2fe5d7c068d15c826cedb01fccd1","price":"0.38","side":"BUY","size":"4.43"},{"asset_id":"69697746896130839564035629862476347944307040470122503199396727085502753297492","best_ask":"0.62","best_bid":"0.61","hash":"9f298a511402f2c8d1fce1445c51bd688f1a071c","price":"0.62","side":"SELL","size":"4.43"}],"timestamp":"1785127059154"},"payload_hash":"c87a6e573db4da3b92bc7f22d4a31a0996be7a427b9e86ebbbb2977e55125519","raw_frame":"{\"market\":\"0xeb66215f2e9faa6449e30a02bab5b8ed7b79a38bf961f6b24d0073c9c2419250\", \"price_changes\":[{\"asset_id\":\"60386828328910021732068595344565885737045900010034836345809386672230885527307\", \"price\":\"0.38\", \"size\":\"4.43\", \"side\":\"BUY\", \"hash\":\"227134c802fb2fe5d7c068d15c826cedb01fccd1\", \"best_bid\":\"0.38\", \"best_ask\":\"0.39\"}, {\"asset_id\":\"69697746896130839564035629862476347944307040470122503199396727085502753297492\", \"price\":\"0.62\", \"size\":\"4.43\", \"side\":\"SELL\", \"hash\":\"9f298a511402f2c8d1fce1445c51bd688f1a071c\", \"best_bid\":\"0.61\", \"best_ask\":\"0.62\"}], \"timestamp\":\"1785127059154\", \"event_type\":\"price_change\"}","received_at":"2026-07-27T04:37:39.100780Z","schema_version":"clob-market-ws.price_change.v1","sequence":null,"server_hash":null,"server_timestamp":"1785127059154","session_id":"e9443c7415a0419799bee9cfbb1a9e4d","source":"clob_market_ws"},"received_at":"2026-07-27T04:37:39.100780Z","record_id":"e8d8bd4910a5fc009dd04a96ae00f1943a5eb6027e62c2d09f23d5a7c7d0ffc6","schema_fingerprint":"4aa3821a28b0b7c2400bc59aba4bcc0a76e971dadd19610d3ad38c768e124dc7","schema_version":"edge-lab-recorder.raw.v1","sequence":null,"source":"clob_market_ws"}
{"event_at":"2026-07-27T04:37:39.168000Z","event_fingerprint":"5c7bc13034565662db47655dd93ad4735d6c7d880d86d630a53885ec58218dee","payload":{"connection_id":"0f4979d6978d463e9660b042fdcf555f","event_at":"2026-07-27T04:37:39.168000Z","event_type":"price_change","frame_hash":"995dd28e404ce4680eb4ebd072f2a761bc564928a0ce5abd005d588e201cd542","frame_index":0,"kind":"data","monotonic_ns":229042379817666,"payload":{"event_type":"price_change","market":"0xeb66215f2e9faa6449e30a02bab5b8ed7b79a38bf961f6b24d0073c9c2419250","price_changes":[{"asset_id":"60386828328910021732068595344565885737045900010034836345809386672230885527307","best_ask":"0.39","best_bid":"0.38","hash":"84a6d74860729fa13711654da8b8ee04dbcdf6df","price":"0.34","side":"BUY","size":"46.19"},{"asset_id":"69697746896130839564035629862476347944307040470122503199396727085502753297492","best_ask":"0.62","best_bid":"0.61","hash":"f2e8c0abed33b0ba78c01156034a640fb7656d7b","price":"0.66","side":"SELL","size":"46.19"}],"timestamp":"1785127059168"},"payload_hash":"24edfc5835d2fe8a2e8b46db126ce427df76488237bdf7d1b5ef22bde5fffe26","raw_frame":"{\"market\":\"0xeb66215f2e9faa6449e30a02bab5b8ed7b79a38bf961f6b24d0073c9c2419250\", \"price_changes\":[{\"asset_id\":\"60386828328910021732068595344565885737045900010034836345809386672230885527307\", \"price\":\"0.34\", \"size\":\"46.19\", \"side\":\"BUY\", \"hash\":\"84a6d74860729fa13711654da8b8ee04dbcdf6df\", \"best_bid\":\"0.38\", \"best_ask\":\"0.39\"}, {\"asset_id\":\"69697746896130839564035629862476347944307040470122503199396727085502753297492\", \"price\":\"0.66\", \"size\":\"46.19\", \"side\":\"SELL\", \"hash\":\"f2e8c0abed33b0ba78c01156034a640fb7656d7b\", \"best_bid\":\"0.61\", \"best_ask\":\"0.62\"}], \"timestamp\":\"1785127059168\", \"event_type\":\"price_change\"}","received_at":"2026-07-27T04:37:39.113959Z","schema_version":"clob-market-ws.price_change.v1","sequence":null,"server_hash":null,"server_timestamp":"1785127059168","session_id":"e9443c7415a0419799bee9cfbb1a9e4d","source":"clob_market_ws"},"received_at":"2026-07-27T04:37:39.113959Z","record_id":"4336b6b1df175de33b15b4cc35491c8de2bde37ef02fa8c887abc23aa70b64ae","schema_fingerprint":"4aa3821a28b0b7c2400bc59aba4bcc0a76e971dadd19610d3ad38c768e124dc7","schema_version":"edge-lab-recorder.raw.v1","sequence":null,"source":"clob_market_ws"}
{"event_at":"2026-07-27T04:37:39.169000Z","event_fingerprint":"d418c6a2a4a710e3ee848db53f081f5382c066091d4fb3dc67dfb41d02c1ebb3","payload":{"connection_id":"0f4979d6978d463e9660b042fdcf555f","event_at":"2026-07-27T04:37:39.169000Z","event_type":"price_change","frame_hash":"b25096455980fdb3bcaf4e3278384fc7358470067e48149891b387cc097d0fb4","frame_index":0,"kind":"data","monotonic_ns":229042381950875,"payload":{"event_type":"price_change","market":"0xeb66215f2e9faa6449e30a02bab5b8ed7b79a38bf961f6b24d0073c9c2419250","price_changes":[{"asset_id":"69697746896130839564035629862476347944307040470122503199396727085502753297492","best_ask":"0.62","best_bid":"0.61","hash":"3c067c84f3d2fdf9a8d9579737a03a627ed08afd","price":"0.57","side":"BUY","size":"83.16"},{"asset_id":"60386828328910021732068595344565885737045900010034836345809386672230885527307","best_ask":"0.39","best_bid":"0.38","hash":"8c85c8fd3ef1c6082ec40a63f40d312a248accfb","price":"0.43","side":"SELL","size":"83.16"}],"timestamp":"1785127059169"},"payload_hash":"ee8be2b1b775f8512aab3d8fa42166747b32e7a66e814eca2137c9e65980dadf","raw_frame":"{\"market\":\"0xeb66215f2e9faa6449e30a02bab5b8ed7b79a38bf961f6b24d0073c9c2419250\", \"price_changes\":[{\"asset_id\":\"69697746896130839564035629862476347944307040470122503199396727085502753297492\", \"price\":\"0.57\", \"size\":\"83.16\", \"side\":\"BUY\", \"hash\":\"3c067c84f3d2fdf9a8d9579737a03a627ed08afd\", \"best_bid\":\"0.61\", \"best_ask\":\"0.62\"}, {\"asset_id\":\"60386828328910021732068595344565885737045900010034836345809386672230885527307\", \"price\":\"0.43\", \"size\":\"83.16\", \"side\":\"SELL\", \"hash\":\"8c85c8fd3ef1c6082ec40a63f40d312a248accfb\", \"best_bid\":\"0.38\", \"best_ask\":\"0.39\"}], \"timestamp\":\"1785127059169\", \"event_type\":\"price_change\"}","received_at":"2026-07-27T04:37:39.116094Z","schema_version":"clob-market-ws.price_change.v1","sequence":null,"server_hash":null,"server_timestamp":"1785127059169","session_id":"e9443c7415a0419799bee9cfbb1a9e4d","source":"clob_market_ws"},"received_at":"2026-07-27T04:37:39.116094Z","record_id":"1b9ac54e3a8a96b9a8743c29fda3cfac1fcd8c6767ef555aa21f6f96d80313b2","schema_fingerprint":"4aa3821a28b0b7c2400bc59aba4bcc0a76e971dadd19610d3ad38c768e124dc7","schema_version":"edge-lab-recorder.raw.v1","sequence":null,"source":"clob_market_ws"}
{"event_at":"2026-07-27T04:37:39.171000Z","event_fingerprint":"95daa106b492635b0be40ba53c329507019acccd33b5c16176260f661fe056a8","payload":{"connection_id":"0f4979d6978d463e9660b042fdcf555f","event_at":"2026-07-27T04:37:39.171000Z","event_type":"price_change","frame_hash":"14c4a67708e923e4406519bffb2640bd3e40fcf7d1367979e3514d2cb87c763c","frame_index":0,"kind":"data","monotonic_ns":229042383563750,"payload":{"event_type":"price_change","market":"0xeb66215f2e9faa6449e30a02bab5b8ed7b79a38bf961f6b24d0073c9c2419250","price_changes":[{"asset_id":"69697746896130839564035629862476347944307040470122503199396727085502753297492","best_ask":"0.62","best_bid":"0.61","hash":"fc099947b7f18740ed693c27d75f2d59283a72da","price":"0.57","side":"BUY","size":"60.16"},{"asset_id":"60386828328910021732068595344565885737045900010034836345809386672230885527307","best_ask":"0.39","best_bid":"0.38","hash":"97b3ffb71ee245e348864bbe52858b8937535671","price":"0.43","side":"SELL","size":"60.16"}],"timestamp":"1785127059171"},"payload_hash":"91b23dda4c435c2af424b37523dfe98ed6f3d686c28e9b8d1dbd4c99441fbcac","raw_frame":"{\"market\":\"0xeb66215f2e9faa6449e30a02bab5b8ed7b79a38bf961f6b24d0073c9c2419250\", \"price_changes\":[{\"asset_id\":\"69697746896130839564035629862476347944307040470122503199396727085502753297492\", \"price\":\"0.57\", \"size\":\"60.16\", \"side\":\"BUY\", \"hash\":\"fc099947b7f18740ed693c27d75f2d59283a72da\", \"best_bid\":\"0.61\", \"best_ask\":\"0.62\"}, {\"asset_id\":\"60386828328910021732068595344565885737045900010034836345809386672230885527307\", \"price\":\"0.43\", \"size\":\"60.16\", \"side\":\"SELL\", \"hash\":\"97b3ffb71ee245e348864bbe52858b8937535671\", \"best_bid\":\"0.38\", \"best_ask\":\"0.39\"}], \"timestamp\":\"1785127059171\", \"event_type\":\"price_change\"}","received_at":"2026-07-27T04:37:39.117709Z","schema_version":"clob-market-ws.price_change.v1","sequence":null,"server_hash":null,"server_timestamp":"1785127059171","session_id":"e9443c7415a0419799bee9cfbb1a9e4d","source":"clob_market_ws"},"received_at":"2026-07-27T04:37:39.117709Z","record_id":"d3bc72c11a4404fd311c34817b5d251548bda5e54450b9403f95b3b86db97b45","schema_fingerprint":"4aa3821a28b0b7c2400bc59aba4bcc0a76e971dadd19610d3ad38c768e124dc7","schema_version":"edge-lab-recorder.raw.v1","sequence":null,"source":"clob_market_ws"}
{"event_at":"2026-07-27T04:37:39.176000Z","event_fingerprint":"c8ddb0fbe941ea69d6c227d7b76cc8510e9170a01ee6a49919c3583bbe0a150c","payload":{"connection_id":"0f4979d6978d463e9660b042fdcf555f","event_at":"2026-07-27T04:37:39.176000Z","event_type":"price_change","frame_hash":"9fd65ff6138ec132b0f69af36cef2272d571125199bfe95fb44ea897d809b69d","frame_index":0,"kind":"data","monotonic_ns":229042387551958,"payload":{"event_type":"price_change","market":"0xeb66215f2e9faa6449e30a02bab5b8ed7b79a38bf961f6b24d0073c9c2419250","price_changes":[{"asset_id":"60386828328910021732068595344565885737045900010034836345809386672230885527307","best_ask":"0.39","best_bid":"0.38","hash":"75fc1d30031f5aa13b6c97f4d5a512ce34d75db0","price":"0.37","side":"BUY","size":"26.81"},{"asset_id":"69697746896130839564035629862476347944307040470122503199396727085502753297492","best_ask":"0.62","best_bid":"0.61","hash":"dff5f7c9a78e862ebf1f1e227696b387e8992a14","price":"0.63","side":"SELL","size":"26.81"}],"timestamp":"1785127059176"},"payload_hash":"0d0b998f33cc4ee155448c3c3efbdcc15497870fe7f69cc772de6691c689a89a","raw_frame":"{\"market\":\"0xeb66215f2e9faa6449e30a02bab5b8ed7b79a38bf961f6b24d0073c9c2419250\", \"price_changes\":[{\"asset_id\":\"60386828328910021732068595344565885737045900010034836345809386672230885527307\", \"price\":\"0.37\", \"size\":\"26.81\", \"side\":\"BUY\", \"hash\":\"75fc1d30031f5aa13b6c97f4d5a512ce34d75db0\", \"best_bid\":\"0.38\", \"best_ask\":\"0.39\"}, {\"asset_id\":\"69697746896130839564035629862476347944307040470122503199396727085502753297492\", \"price\":\"0.63\", \"size\":\"26.81\", \"side\":\"SELL\", \"hash\":\"dff5f7c9a78e862ebf1f1e227696b387e8992a14\", \"best_bid\":\"0.61\", \"best_ask\":\"0.62\"}], \"timestamp\":\"1785127059176\", \"event_type\":\"price_change\"}","received_at":"2026-07-27T04:37:39.121694Z","schema_version":"clob-market-ws.price_change.v1","sequence":null,"server_hash":null,"server_timestamp":"1785127059176","session_id":"e9443c7415a0419799bee9cfbb1a9e4d","source":"clob_market_ws"},"received_at":"2026-07-27T04:37:39.121694Z","record_id":"c3f7a378c4fc26caebadbc46d35ac62105dfab415c28dfea21bb14080d8f9e96","schema_fingerprint":"4aa3821a28b0b7c2400bc59aba4bcc0a76e971dadd19610d3ad38c768e124dc7","schema_version":"edge-lab-recorder.raw.v1","sequence":null,"source":"clob_market_ws"}
{"event_at":"2026-07-27T04:37:39.176000Z","event_fingerprint":"ff590fef33f19d4c28fe18fa8067a4d1324621361ab0170ac5584125b30d3be6","payload":{"connection_id":"0f4979d6978d463e9660b042fdcf555f","event_at":"2026-07-27T04:37:39.176000Z","event_type":"price_change","frame_hash":"564210ce5e2b36364a321995fdf7d6c57d5b1d2691d62e46348d8ae19d8aa759","frame_index":0,"kind":"data","monotonic_ns":229042389111000,"payload":{"event_type":"price_change","market":"0xeb66215f2e9faa6449e30a02bab5b8ed7b79a38bf961f6b24d0073c9c2419250","price_changes":[{"asset_id":"60386828328910021732068595344565885737045900010034836345809386672230885527307","best_ask":"0.39","best_bid":"0.38","hash":"531eb1ae59852fdf4109b2cdca4208c74fc29f8b","price":"0.36","side":"BUY","size":"61.91"},{"asset_id":"69697746896130839564035629862476347944307040470122503199396727085502753297492","best_ask":"0.62","best_bid":"0.61","hash":"6957486b8bcaa3f437023e9528547b4834b45f53","price":"0.64","side":"SELL","size":"61.91"}],"timestamp":"1785127059176"},"payload_hash":"28463d1756be559cc0f1e76e2a03327efd87ef47e9f73d61f26573921b69ee13","raw_frame":"{\"market\":\"0xeb66215f2e9faa6449e30a02bab5b8ed7b79a38bf961f6b24d0073c9c2419250\", \"price_changes\":[{\"asset_id\":\"60386828328910021732068595344565885737045900010034836345809386672230885527307\", \"price\":\"0.36\", \"size\":\"61.91\", \"side\":\"BUY\", \"hash\":\"531eb1ae59852fdf4109b2cdca4208c74fc29f8b\", \"best_bid\":\"0.38\", \"best_ask\":\"0.39\"}, {\"asset_id\":\"69697746896130839564035629862476347944307040470122503199396727085502753297492\", \"price\":\"0.64\", \"size\":\"61.91\", \"side\":\"SELL\", \"hash\":\"6957486b8bcaa3f437023e9528547b4834b45f53\", \"best_bid\":\"0.61\", \"best_ask\":\"0.62\"}], \"timestamp\":\"1785127059176\", \"event_type\":\"price_change\"}","received_at":"2026-07-27T04:37:39.123250Z","schema_version":"clob-market-ws.price_change.v1","sequence":null,"server_hash":null,"server_timestamp":"1785127059176","session_id":"e9443c7415a0419799bee9cfbb1a9e4d","source":"clob_market_ws"},"received_at":"2026-07-27T04:37:39.123250Z","record_id":"f5a421f13eb2bb9e285705712baba7a9e167d59b5de493eb35582fc938ef3f77","schema_fingerprint":"4aa3821a28b0b7c2400bc59aba4bcc0a76e971dadd19610d3ad38c768e124dc7","schema_version":"edge-lab-recorder.raw.v1","sequence":null,"source":"clob_market_ws"}
{"event_at":"2026-07-27T04:37:39.179000Z","event_fingerprint":"3d11536b70a9b685a5a6b5171acf325febb9a13b7a0841f435d506a00aadd2e1","payload":{"connection_id":"0f4979d6978d463e9660b042fdcf555f","event_at":"2026-07-27T04:37:39.179000Z","event_type":"price_change","frame_hash":"a9a551fc8eca7e6a93fc582d4b98e41c9f32ec7a3e478dddbfea2b109512679f","frame_index":0,"kind":"data","monotonic_ns":229042392436083,"payload":{"event_type":"price_change","market":"0xeb66215f2e9faa6449e30a02bab5b8ed7b79a38bf961f6b24d0073c9c2419250","price_changes":[{"asset_id":"69697746896130839564035629862476347944307040470122503199396727085502753297492","best_ask":"0.62","best_bid":"0.61","hash":"2f6a45e14c8042c599a945ed58b7e2ff32737ddb","price":"0.01","side":"BUY","size":"5834.91"},{"asset_id":"60386828328910021732068595344565885737045900010034836345809386672230885527307","best_ask":"0.39","best_bid":"0.38","hash":"2d6bb783e44d2d8b724645c3937bb6dddabacd29","price":"0.99","side":"SELL","size":"5834.91"}],"timestamp":"1785127059179"},"payload_hash":"7290637646f5c6e0284819b1680035113d970f26dc3ef1bb1e0f0be148b1b37f","raw_frame":"{\"market\":\"0xeb66215f2e9faa6449e30a02bab5b8ed7b79a38bf961f6b24d0073c9c2419250\", \"price_changes\":[{\"asset_id\":\"69697746896130839564035629862476347944307040470122503199396727085502753297492\", \"price\":\"0.01\", \"size\":\"5834.91\", \"side\":\"BUY\", \"hash\":\"2f6a45e14c8042c599a945ed58b7e2ff32737ddb\", \"best_bid\":\"0.61\", \"best_ask\":\"0.62\"}, {\"asset_id\":\"60386828328910021732068595344565885737045900010034836345809386672230885527307\", \"price\":\"0.99\", \"size\":\"5834.91\", \"side\":\"SELL\", \"hash\":\"2d6bb783e44d2d8b724645c3937bb6dddabacd29\", \"best_bid\":\"0.38\", \"best_ask\":\"0.39\"}], \"timestamp\":\"1785127059179\", \"event_type\":\"price_change\"}","received_at":"2026-07-27T04:37:39.126579Z","schema_version":"clob-market-ws.price_change.v1","sequence":null,"server_hash":null,"server_timestamp":"1785127059179","session_id":"e9443c7415a0419799bee9cfbb1a9e4d","source":"clob_market_ws"},"received_at":"2026-07-27T04:37:39.126579Z","record_id":"47add4018d959e5ad29788900db6b75a9b6de822cbd7e2aaa2a8691cca13c84a","schema_fingerprint":"4aa3821a28b0b7c2400bc59aba4bcc0a76e971dadd19610d3ad38c768e124dc7","schema_version":"edge-lab-recorder.raw.v1","sequence":null,"source":"clob_market_ws"}
{"event_at":"2026-07-27T04:37:39.180000Z","event_fingerprint":"04f85ad7a7660aa8999170e84ac7e102b3db0884440032300e8ea4d604822202","payload":{"connection_id":"0f4979d6978d463e9660b042fdcf555f","event_at":"2026-07-27T04:37:39.180000Z","event_type":"price_change","frame_hash":"5e458a10efb2b69bc246689443d37ae1d0b35c881f2b0f44161c30fcce729c45","frame_index":0,"kind":"data","monotonic_ns":229042394129541,"payload":{"event_type":"price_change","market":"0xeb66215f2e9faa6449e30a02bab5b8ed7b79a38bf961f6b24d0073c9c2419250","price_changes":[{"asset_id":"60386828328910021732068595344565885737045900010034836345809386672230885527307","best_ask":"0.39","best_bid":"0.38","hash":"55d008254068ee9b0a6125414dc1efc43e06fa8f","price":"0.43","side":"SELL","size":"81.56"},{"asset_id":"69697746896130839564035629862476347944307040470122503199396727085502753297492","best_ask":"0.62","best_bid":"0.61","hash":"82785ed2c9effa8ed670405cb116836825762077","price":"0.57","side":"BUY","size":"81.56"}],"timestamp":"1785127059180"},"payload_hash":"3e1adfa5d639f78b2dcdf9f6f4c84811f27e912bcfb12628dd9b84d9e1521d93","raw_frame":"{\"market\":\"0xeb66215f2e9faa6449e30a02bab5b8ed7b79a38bf961f6b24d0073c9c2419250\", \"price_changes\":[{\"asset_id\":\"60386828328910021732068595344565885737045900010034836345809386672230885527307\", \"price\":\"0.43\", \"size\":\"81.56\", \"side\":\"SELL\", \"hash\":\"55d008254068ee9b0a6125414dc1efc43e06fa8f\", \"best_bid\":\"0.38\", \"best_ask\":\"0.39\"}, {\"asset_id\":\"69697746896130839564035629862476347944307040470122503199396727085502753297492\", \"price\":\"0.57\", \"size\":\"81.56\", \"side\":\"BUY\", \"hash\":\"82785ed2c9effa8ed670405cb116836825762077\", \"best_bid\":\"0.61\", \"best_ask\":\"0.62\"}], \"timestamp\":\"1785127059180\", \"event_type\":\"price_change\"}","received_at":"2026-07-27T04:37:39.128275Z","schema_version":"clob-market-ws.price_change.v1","sequence":null,"server_hash":null,"server_timestamp":"1785127059180","session_id":"e9443c7415a0419799bee9cfbb1a9e4d","source":"clob_market_ws"},"received_at":"2026-07-27T04:37:39.128275Z","record_id":"ec5be5b25653f2e259c198f8f393c7c97cb15a780c83aa43188b889e16a1f6ce","schema_fingerprint":"4aa3821a28b0b7c2400bc59aba4bcc0a76e971dadd19610d3ad38c768e124dc7","schema_version":"edge-lab-recorder.raw.v1","sequence":null,"source":"clob_market_ws"}
{"event_at":"2026-07-27T04:37:39.184000Z","event_fingerprint":"b53e0a09ed357c034ff6c8d8b472af50bbac6d1c0cb6f6bb6d8baa46085f99fc","payload":{"connection_id":"0f4979d6978d463e9660b042fdcf555f","event_at":"2026-07-27T04:37:39.184000Z","event_type":"price_change","frame_hash":"b64f52419b875fb88760da22bbf287d24a71ccdb1cf0ac3f88dddafd1b647c85","frame_index":0,"kind":"data","monotonic_ns":229042396289333,"payload":{"event_type":"price_change","market":"0xeb66215f2e9faa6449e30a02bab5b8ed7b79a38bf961f6b24d0073c9c2419250","price_changes":[{"asset_id":"60386828328910021732068595344565885737045900010034836345809386672230885527307","best_ask":"0.39","best_bid":"0.38","hash":"9db08f4d7e6555644d22aa669769c0c2580571d2","price":"0.35","side":"BUY","size":"403.07"},{"asset_id":"69697746896130839564035629862476347944307040470122503199396727085502753297492","best_ask":"0.62","best_bid":"0.61","hash":"97f9fcc3cc002da1f5d219b9ed15955130e4ce6c","price":"0.65","side":"SELL","size":"403.07"}],"timestamp":"1785127059184"},"payload_hash":"6928b243a0a449b694691cf8afd8a6fa41ab4a92569bd2da4d1c3a3a8c83f2b7","raw_frame":"{\"market\":\"0xeb66215f2e9faa6449e30a02bab5b8ed7b79a38bf961f6b24d0073c9c2419250\", \"price_changes\":[{\"asset_id\":\"60386828328910021732068595344565885737045900010034836345809386672230885527307\", \"price\":\"0.35\", \"size\":\"403.07\", \"side\":\"BUY\", \"hash\":\"9db08f4d7e6555644d22aa669769c0c2580571d2\", \"best_bid\":\"0.38\", \"best_ask\":\"0.39\"}, {\"asset_id\":\"69697746896130839564035629862476347944307040470122503199396727085502753297492\", \"price\":\"0.65\", \"size\":\"403.07\", \"side\":\"SELL\", \"hash\":\"97f9fcc3cc002da1f5d219b9ed15955130e4ce6c\", \"best_bid\":\"0.61\", \"best_ask\":\"0.62\"}], \"timestamp\":\"1785127059184\", \"event_type\":\"price_change\"}","received_at":"2026-07-27T04:37:39.130431Z","schema_version":"clob-market-ws.price_change.v1","sequence":null,"server_hash":null,"server_timestamp":"1785127059184","session_id":"e9443c7415a0419799bee9cfbb1a9e4d","source":"clob_market_ws"},"received_at":"2026-07-27T04:37:39.130431Z","record_id":"4ec7d1935c65051ba76534fe3b072cc7561044086c890ed89cf1e379cba19731","schema_fingerprint":"4aa3821a28b0b7c2400bc59aba4bcc0a76e971dadd19610d3ad38c768e124dc7","schema_version":"edge-lab-recorder.raw.v1","sequence":null,"source":"clob_market_ws"}
{"event_at":"2026-07-27T04:37:39.203000Z","event_fingerprint":"d381da5e1301ebd30347ea3595b5dec52f5bee4ff86c992379754d7dcbe921fa","payload":{"connection_id":"0f4979d6978d463e9660b042fdcf555f","event_at":"2026-07-27T04:37:39.203000Z","event_type":"price_change","frame_hash":"df466cc6c38b01de2890b5f71a61219ded717ebce1a1d5071917e7d50cb19046","frame_index":0,"kind":"data","monotonic_ns":229042414536458,"payload":{"event_type":"price_change","market":"0xeb66215f2e9faa6449e30a02bab5b8ed7b79a38bf961f6b24d0073c9c2419250","price_changes":[{"asset_id":"60386828328910021732068595344565885737045900010034836345809386672230885527307","best_ask":"0.39","best_bid":"0.38","hash":"389f44fe0e2695295aeb348bde595be24e2fdba9","price":"0.36","side":"BUY","size":"71.91"},{"asset_id":"69697746896130839564035629862476347944307040470122503199396727085502753297492","best_ask":"0.62","best_bid":"0.61","hash":"49fc04009706dfda4394a0f53599465ad724382a","price":"0.64","side":"SELL","size":"71.91"}],"timestamp":"1785127059203"},"payload_hash":"080856a177d1e572b99323412affbfd6aa74c2747fe77065a3e30799114752b6","raw_frame":"{\"market\":\"0xeb66215f2e9faa6449e30a02bab5b8ed7b79a38bf961f6b24d0073c9c2419250\", \"price_changes\":[{\"asset_id\":\"60386828328910021732068595344565885737045900010034836345809386672230885527307\", \"price\":\"0.36\", \"size\":\"71.91\", \"side\":\"BUY\", \"hash\":\"389f44fe0e2695295aeb348bde595be24e2fdba9\", \"best_bid\":\"0.38\", \"best_ask\":\"0.39\"}, {\"asset_id\":\"69697746896130839564035629862476347944307040470122503199396727085502753297492\", \"price\":\"0.64\", \"size\":\"71.91\", \"side\":\"SELL\", \"hash\":\"49fc04009706dfda4394a0f53599465ad724382a\", \"best_bid\":\"0.61\", \"best_ask\":\"0.62\"}], \"timestamp\":\"1785127059203\", \"event_type\":\"price_change\"}","received_at":"2026-07-27T04:37:39.148674Z","schema_version":"clob-market-ws.price_change.v1","sequence":null,"server_hash":null,"server_timestamp":"1785127059203","session_id":"e9443c7415a0419799bee9cfbb1a9e4d","source":"clob_market_ws"},"received_at":"2026-07-27T04:37:39.148674Z","record_id":"8bd9639e9e18d298da29339ace53073b4c71a025bdde5d8ad07938f9a9e99941","schema_fingerprint":"4aa3821a28b0b7c2400bc59aba4bcc0a76e971dadd19610d3ad38c768e124dc7","schema_version":"edge-lab-recorder.raw.v1","sequence":null,"source":"clob_market_ws"}
{"event_at":"2026-07-27T04:37:39.228000Z","event_fingerprint":"d8f2e5a2c14f8aee6d6844107e594dcad060a1e94c08a2b07d4b00b8fbfbcaae","payload":{"connection_id":"0f4979d6978d463e9660b042fdcf555f","event_at":"2026-07-27T04:37:39.228000Z","event_type":"price_change","frame_hash":"d31d7e5630f251c8c0a7aa8228a61db6c2d6fc9092a5b0ffc65cc8f7d63b82a8","frame_index":0,"kind":"data","monotonic_ns":229042440107958,"payload":{"event_type":"price_change","market":"0xeb66215f2e9faa6449e30a02bab5b8ed7b79a38bf961f6b24d0073c9c2419250","price_changes":[{"asset_id":"69697746896130839564035629862476347944307040470122503199396727085502753297492","best_ask":"0.62","best_bid":"0.61","hash":"fbed6d528ec25fe6a820cc636fc4c9abebe72fc3","price":"0.65","side":"SELL","size":"425.87"},{"asset_id":"60386828328910021732068595344565885737045900010034836345809386672230885527307","best_ask":"0.39","best_bid":"0.38","hash":"514f3906337c261f3864af96addf2d6b832b67d8","price":"0.35","side":"BUY","size":"425.87"}],"timestamp":"1785127059228"},"payload_hash":"31bde3d0e0d6d03586ff1dbbbd79439b2d21e4703f7c93e54cc4872f2587f715","raw_frame":"{\"market\":\"0xeb66215f2e9faa6449e30a02bab5b8ed7b79a38bf961f6b24d0073c9c2419250\", \"price_changes\":[{\"asset_id\":\"69697746896130839564035629862476347944307040470122503199396727085502753297492\", \"price\":\"0.65\", \"size\":\"425.87\", \"side\":\"SELL\", \"hash\":\"fbed6d528ec25fe6a820cc636fc4c9abebe72fc3\", \"best_bid\":\"0.61\", \"best_ask\":\"0.62\"}, {\"asset_id\":\"60386828328910021732068595344565885737045900010034836345809386672230885527307\", \"price\":\"0.35\", \"size\":\"425.87\", \"side\":\"BUY\", \"hash\":\"514f3906337c261f3864af96addf2d6b832b67d8\", \"best_bid\":\"0.38\", \"best_ask\":\"0.39\"}], \"timestamp\":\"1785127059228\", \"event_type\":\"price_change\"}","received_at":"2026-07-27T04:37:39.174247Z","schema_version":"clob-market-ws.price_change.v1","sequence":null,"server_hash":null,"server_timestamp":"1785127059228","session_id":"e9443c7415a0419799bee9cfbb1a9e4d","source":"clob_market_ws"},"received_at":"2026-07-27T04:37:39.174247Z","record_id":"265de3c88d4d98082b69232f4d79e903f84e7b4e2152c51a797361abfc2af9d5","schema_fingerprint":"4aa3821a28b0b7c2400bc59aba4bcc0a76e971dadd19610d3ad38c768e124dc7","schema_version":"edge-lab-recorder.raw.v1","sequence":null,"source":"clob_market_ws"}
{"event_at":"2026-07-27T04:37:39.229000Z","event_fingerprint":"fbb2eb315fde120e1c843b0dda678211dbbf4732848ffc32ed3756c007d6567a","payload":{"connection_id":"0f4979d6978d463e9660b042fdcf555f","event_at":"2026-07-27T04:37:39.229000Z","event_type":"price_change","frame_hash":"67ad0d0edd9f1dbd0309d59952b15f36056f6b40ecbe59751e68c291851dd5ba","frame_index":0,"kind":"data","monotonic_ns":229042442199666,"payload":{"event_type":"price_change","market":"0xeb66215f2e9faa6449e30a02bab5b8ed7b79a38bf961f6b24d0073c9c2419250","price_changes":[{"asset_id":"60386828328910021732068595344565885737045900010034836345809386672230885527307","best_ask":"0.39","best_bid":"0.38","hash":"fd77cd86715c53494b3a0057ca7264349f62e9ce","price":"0.35","side":"BUY","size":"450.87"},{"asset_id":"69697746896130839564035629862476347944307040470122503199396727085502753297492","best_ask":"0.62","best_bid":"0.61","hash":"d8d52d38de027d89ec16f3675fae9004a6ef27c8","price":"0.65","side":"SELL","size":"450.87"}],"timestamp":"1785127059229"},"payload_hash":"7d7a03c9f471d98e2f8d1c3a2ee224fe31da3d0a552b9540252acc6d6c961c3a","raw_frame":"{\"market\":\"0xeb66215f2e9faa6449e30a02bab5b8ed7b79a38bf961f6b24d0073c9c2419250\", \"price_changes\":[{\"asset_id\":\"60386828328910021732068595344565885737045900010034836345809386672230885527307\", \"price\":\"0.35\", \"size\":\"450.87\", \"side\":\"BUY\", \"hash\":\"fd77cd86715c53494b3a0057ca7264349f62e9ce\", \"best_bid\":\"0.38\", \"best_ask\":\"0.39\"}, {\"asset_id\":\"69697746896130839564035629862476347944307040470122503199396727085502753297492\", \"price\":\"0.65\", \"size\":\"450.87\", \"side\":\"SELL\", \"hash\":\"d8d52d38de027d89ec16f3675fae9004a6ef27c8\", \"best_bid\":\"0.61\", \"best_ask\":\"0.62\"}], \"timestamp\":\"1785127059229\", \"event_type\":\"price_change\"}","received_at":"2026-07-27T04:37:39.176343Z","schema_version":"clob-market-ws.price_change.v1","sequence":null,"server_hash":null,"server_timestamp":"1785127059229","session_id":"e9443c7415a0419799bee9cfbb1a9e4d","source":"clob_market_ws"},"received_at":"2026-07-27T04:37:39.176343Z","record_id":"617c80e88236dd5a8a8ab0c3d1064c5950c086f8eeeae3e5520960128530cc3f","schema_fingerprint":"4aa3821a28b0b7c2400bc59aba4bcc0a76e971dadd19610d3ad38c768e124dc7","schema_version":"edge-lab-recorder.raw.v1","sequence":null,"source":"clob_market_ws"}
{"event_at":"2026-07-27T04:37:39.232000Z","event_fingerprint":"3c2b886b1168cf9b00524ce3d39926abd2673cd9eda0696f36138b6539120d3e","payload":{"connection_id":"0f4979d6978d463e9660b042fdcf555f","event_at":"2026-07-27T04:37:39.232000Z","event_type":"price_change","frame_hash":"0db02e7bb7fa7d81f4771601ba0e9aec813f766a84d3dfe6d3bf39a169c8f66b","frame_index":0,"kind":"data","monotonic_ns":229042446367250,"payload":{"event_type":"price_change","market":"0xeb66215f2e9faa6449e30a02bab5b8ed7b79a38bf961f6b24d0073c9c2419250","price_changes":[{"asset_id":"60386828328910021732068595344565885737045900010034836345809386672230885527307","best_ask":"0.39","best_bid":"0.38","hash":"031c2b0e9fc58957fe82337210eea499b4d0995a","price":"0.43","side":"SELL","size":"51.16"},{"asset_id":"69697746896130839564035629862476347944307040470122503199396727085502753297492","best_ask":"0.62","best_bid":"0.61","hash":"8473d58877da2d7790dd56628b61abcc020c2daa","price":"0.57","side":"BUY","size":"51.16"}],"timestamp":"1785127059232"},"payload_hash":"8ef658f0cc60f640dd6a9efe19272984f0fda20a5de1c4c919658c87c63465cc","raw_frame":"{\"market\":\"0xeb66215f2e9faa6449e30a02bab5b8ed7b79a38bf961f6b24d0073c9c2419250\", \"price_changes\":[{\"asset_id\":\"60386828328910021732068595344565885737045900010034836345809386672230885527307\", \"price\":\"0.43\", \"size\":\"51.16\", \"side\":\"SELL\", \"hash\":\"031c2b0e9fc58957fe82337210eea499b4d0995a\", \"best_bid\":\"0.38\", \"best_ask\":\"0.39\"}, {\"asset_id\":\"69697746896130839564035629862476347944307040470122503199396727085502753297492\", \"price\":\"0.57\", \"size\":\"51.16\", \"side\":\"BUY\", \"hash\":\"8473d58877da2d7790dd56628b61abcc020c2daa\", \"best_bid\":\"0.61\", \"best_ask\":\"0.62\"}], \"timestamp\":\"1785127059232\", \"event_type\":\"price_change\"}","received_at":"2026-07-27T04:37:39.180512Z","schema_version":"clob-market-ws.price_change.v1","sequence":null,"server_hash":null,"server_timestamp":"1785127059232","session_id":"e9443c7415a0419799bee9cfbb1a9e4d","source":"clob_market_ws"},"received_at":"2026-07-27T04:37:39.180512Z","record_id":"91e0382d91c4cd090212666d98b6af254e628bdb59a01404cf03de8e24f2d777","schema_fingerprint":"4aa3821a28b0b7c2400bc59aba4bcc0a76e971dadd19610d3ad38c768e124dc7","schema_version":"edge-lab-recorder.raw.v1","sequence":null,"source":"clob_market_ws"}
{"event_at":"2026-07-27T04:37:39.232000Z","event_fingerprint":"79a189f647514775a033005cca5f4ab359b65632fb646d41b50c045daf54ff4d","payload":{"connection_id":"0f4979d6978d463e9660b042fdcf555f","event_at":"2026-07-27T04:37:39.232000Z","event_type":"price_change","frame_hash":"324c0b6b727e6740092618a977f8113b862d6adabed59ef0b43f145415ab6ebd","frame_index":0,"kind":"data","monotonic_ns":229042447894333,"payload":{"event_type":"price_change","market":"0xeb66215f2e9faa6449e30a02bab5b8ed7b79a38bf961f6b24d0073c9c2419250","price_changes":[{"asset_id":"60386828328910021732068595344565885737045900010034836345809386672230885527307","best_ask":"0.39","best_bid":"0.38","hash":"031c2b0e9fc58957fe82337210eea499b4d0995a","price":"0.33","side":"BUY","size":"96.6"},{"asset_id":"69697746896130839564035629862476347944307040470122503199396727085502753297492","best_ask":"0.62","best_bid":"0.61","hash":"8473d58877da2d7790dd56628b61abcc020c2daa","price":"0.67","side":"SELL","size":"96.6"}],"timestamp":"1785127059232"},"payload_hash":"55779eb663873d3d216f660f748b44c651cdf32403ba14cc021c4dbcaf1d6386","raw_frame":"{\"market\":\"0xeb66215f2e9faa6449e30a02bab5b8ed7b79a38bf961f6b24d0073c9c2419250\", \"price_changes\":[{\"asset_id\":\"60386828328910021732068595344565885737045900010034836345809386672230885527307\", \"price\":\"0.33\", \"size\":\"96.6\", \"side\":\"BUY\", \"hash\":\"031c2b0e9fc58957fe82337210eea499b4d0995a\", \"best_bid\":\"0.38\", \"best_ask\":\"0.39\"}, {\"asset_id\":\"69697746896130839564035629862476347944307040470122503199396727085502753297492\", \"price\":\"0.67\", \"size\":\"96.6\", \"side\":\"SELL\", \"hash\":\"8473d58877da2d7790dd56628b61abcc020c2daa\", \"best_bid\":\"0.61\", \"best_ask\":\"0.62\"}], \"timestamp\":\"1785127059232\", \"event_type\":\"price_change\"}","received_at":"2026-07-27T04:37:39.182040Z","schema_version":"clob-market-ws.price_change.v1","sequence":null,"server_hash":null,"server_timestamp":"1785127059232","session_id":"e9443c7415a0419799bee9cfbb1a9e4d","source":"clob_market_ws"},"received_at":"2026-07-27T04:37:39.182040Z","record_id":"b71e42935f31e7bde1204c5bb4b79037fe0bcc1cd7eb2f4b1f280bc5c2b82b01","schema_fingerprint":"4aa3821a28b0b7c2400bc59aba4bcc0a76e971dadd19610d3ad38c768e124dc7","schema_version":"edge-lab-recorder.raw.v1","sequence":null,"source":"clob_market_ws"}
{"event_at":"2026-07-27T04:37:39.232000Z","event_fingerprint":"072e0f12eb998c7810b440df4b5107df197c17f19d2b16e2b316ef6eefc2b70d","payload":{"connection_id":"0f4979d6978d463e9660b042fdcf555f","event_at":"2026-07-27T04:37:39.232000Z","event_type":"price_change","frame_hash":"2ae802b4456e7fbd81c02da94ea84f925284e10f976e29b686d47e08d8905e83","frame_index":0,"kind":"data","monotonic_ns":229042450953708,"payload":{"event_type":"price_change","market":"0xeb66215f2e9faa6449e30a02bab5b8ed7b79a38bf961f6b24d0073c9c2419250","price_changes":[{"asset_id":"69697746896130839564035629862476347944307040470122503199396727085502753297492","best_ask":"0.62","best_bid":"0.61","hash":"8473d58877da2d7790dd56628b61abcc020c2daa","price":"0.66","side":"SELL","size":"40.19"},{"asset_id":"60386828328910021732068595344565885737045900010034836345809386672230885527307","best_ask":"0.39","best_bid":"0.38","hash":"031c2b0e9fc58957fe82337210eea499b4d0995a","price":"0.34","side":"BUY","size":"40.19"}],"timestamp":"1785127059232"},"payload_hash":"a951dda6682bcc4870eb6514d2269017e06223eeaad6270bc42f8ed3c8a07bb9","raw_frame":"{\"market\":\"0xeb66215f2e9faa6449e30a02bab5b8ed7b79a38bf961f6b24d0073c9c2419250\", \"price_changes\":[{\"asset_id\":\"69697746896130839564035629862476347944307040470122503199396727085502753297492\", \"price\":\"0.66\", \"size\":\"40.19\", \"side\":\"SELL\", \"hash\":\"8473d58877da2d7790dd56628b61abcc020c2daa\", \"best_bid\":\"0.61\", \"best_ask\":\"0.62\"}, {\"asset_id\":\"60386828328910021732068595344565885737045900010034836345809386672230885527307\", \"price\":\"0.34\", \"size\":\"40.19\", \"side\":\"BUY\", \"hash\":\"031c2b0e9fc58957fe82337210eea499b4d0995a\", \"best_bid\":\"0.38\", \"best_ask\":\"0.39\"}], \"timestamp\":\"1785127059232\", \"event_type\":\"price_change\"}","received_at":"2026-07-27T04:37:39.185098Z","schema_version":"clob-market-ws.price_change.v1","sequence":null,"server_hash":null,"server_timestamp":"1785127059232","session_id":"e9443c7415a0419799bee9cfbb1a9e4d","source":"clob_market_ws"},"received_at":"2026-07-27T04:37:39.185098Z","record_id":"9198bee866dfd5357b5580f25d9d9a1df39cbd7f5564384e35c0b8b348c4ec0c","schema_fingerprint":"4aa3821a28b0b7c2400bc59aba4bcc0a76e971dadd19610d3ad38c768e124dc7","schema_version":"edge-lab-recorder.raw.v1","sequence":null,"source":"clob_market_ws"}
{"event_at":"2026-07-27T04:37:39.232000Z","event_fingerprint":"0994af77952bd3fda39721f0c8b4eb8ff576bbcd49ed42a3b7171ab6acd81a3c","payload":{"connection_id":"0f4979d6978d463e9660b042fdcf555f","event_at":"2026-07-27T04:37:39.232000Z","event_type":"price_change","frame_hash":"a046dd9e2348e91c5ecfbd8c7a91f1ed15df879743ed89c1f57fb2142f93c8d4","frame_index":0,"kind":"data","monotonic_ns":229042452700333,"payload":{"event_type":"price_change","market":"0xeb66215f2e9faa6449e30a02bab5b8ed7b79a38bf961f6b24d0073c9c2419250","price_changes":[{"asset_id":"69697746896130839564035629862476347944307040470122503199396727085502753297492","best_ask":"0.62","best_bid":"0.61","hash":"8473d58877da2d7790dd56628b61abcc020c2daa","price":"0.42","side":"BUY","size":"117.3"},{"asset_id":"60386828328910021732068595344565885737045900010034836345809386672230885527307","best_ask":"0.39","best_bid":"0.38","hash":"031c2b0e9fc58957fe82337210eea499b4d0995a","price":"0.58","side":"SELL","size":"117.3"}],"timestamp":"1785127059232"},"payload_hash":"3825fe49aabe2689ccee7f54112875ae1f42d21360a8a4677e0babb5e5d16735","raw_frame":"{\"market\":\"0xeb66215f2e9faa6449e30a02bab5b8ed7b79a38bf961f6b24d0073c9c2419250\", \"price_changes\":[{\"asset_id\":\"69697746896130839564035629862476347944307040470122503199396727085502753297492\", \"price\":\"0.42\", \"size\":\"117.3\", \"side\":\"BUY\", \"hash\":\"8473d58877da2d7790dd56628b61abcc020c2daa\", \"best_bid\":\"0.61\", \"best_ask\":\"0.62\"}, {\"asset_id\":\"60386828328910021732068595344565885737045900010034836345809386672230885527307\", \"price\":\"0.58\", \"size\":\"117.3\", \"side\":\"SELL\", \"hash\":\"031c2b0e9fc58957fe82337210eea499b4d0995a\", \"best_bid\":\"0.38\", \"best_ask\":\"0.39\"}], \"timestamp\":\"1785127059232\", \"event_type\":\"price_change\"}","received_at":"2026-07-27T04:37:39.186844Z","schema_version":"clob-market-ws.price_change.v1","sequence":null,"server_hash":null,"server_timestamp":"1785127059232","session_id":"e9443c7415a0419799bee9cfbb1a9e4d","source":"clob_market_ws"},"received_at":"2026-07-27T04:37:39.186844Z","record_id":"01ae80bc2e33829a9f3a67c505e7272f4ba39896fd7b86852f0f900b3b22b44c","schema_fingerprint":"4aa3821a28b0b7c2400bc59aba4bcc0a76e971dadd19610d3ad38c768e124dc7","schema_version":"edge-lab-recorder.raw.v1","sequence":null,"source":"clob_market_ws"}
{"event_at":"2026-07-27T04:37:39.241000Z","event_fingerprint":"20ff6d0204e456c64f2af7d6172d3d4f27ae5892b342570d4c563d2048be2f5e","payload":{"connection_id":"0f4979d6978d463e9660b042fdcf555f","event_at":"2026-07-27T04:37:39.241000Z","event_type":"price_change","frame_hash":"7196971574060f7da50586322f998cd4ff79f768ac8673fea7d5acc14e10c038","frame_index":0,"kind":"data","monotonic_ns":229042454357250,"payload":{"event_type":"price_change","market":"0xeb66215f2e9faa6449e30a02bab5b8ed7b79a38bf961f6b24d0073c9c2419250","price_changes":[{"asset_id":"69697746896130839564035629862476347944307040470122503199396727085502753297492","best_ask":"0.62","best_bid":"0.61","hash":"90154df5fbd9df7db3e3956d23ad5f06c8dd0a43","price":"0.58","side":"BUY","size":"56.4"},{"asset_id":"60386828328910021732068595344565885737045900010034836345809386672230885527307","best_ask":"0.39","best_bid":"0.38","hash":"bc4604c0e151b52ee234d1538bb6ebe92b12ba54","price":"0.42","side":"SELL","size":"56.4"}],"timestamp":"1785127059241"},"payload_hash":"1f82bbb5ad5c695f1066887a71410b14c0116a5890ab2ce61144e34911849524","raw_frame":"{\"market\":\"0xeb66215f2e9faa6449e30a02bab5b8ed7b79a38bf961f6b24d0073c9c2419250\", \"price_changes\":[{\"asset_id\":\"69697746896130839564035629862476347944307040470122503199396727085502753297492\", \"price\":\"0.58\", \"size\":\"56.4\", \"side\":\"BUY\", \"hash\":\"90154df5fbd9df7db3e3956d23ad5f06c8dd0a43\", \"best_bid\":\"0.61\", \"best_ask\":\"0.62\"}, {\"asset_id\":\"60386828328910021732068595344565885737045900010034836345809386672230885527307\", \"price\":\"0.42\", \"size\":\"56.4\", \"side\":\"SELL\", \"hash\":\"bc4604c0e151b52ee234d1538bb6ebe92b12ba54\", \"best_bid\":\"0.38\", \"best_ask\":\"0.39\"}], \"timestamp\":\"1785127059241\", \"event_type\":\"price_change\"}","received_at":"2026-07-27T04:37:39.188501Z","schema_version":"clob-market-ws.price_change.v1","sequence":null,"server_hash":null,"server_timestamp":"1785127059241","session_id":"e9443c7415a0419799bee9cfbb1a9e4d","source":"clob_market_ws"},"received_at":"2026-07-27T04:37:39.188501Z","record_id":"3bc27c426e517aa6659ecd82d506d534c1b6aa368f65acc0fbf4d6b19d7e7a97","schema_fingerprint":"4aa3821a28b0b7c2400bc59aba4bcc0a76e971dadd19610d3ad38c768e124dc7","schema_version":"edge-lab-recorder.raw.v1","sequence":null,"source":"clob_market_ws"}
{"event_at":"2026-07-27T04:37:39.242000Z","event_fingerprint":"6d237adad0989c1caad04584df250676a1f17ab8eed12cd00339ffda07d710e3","payload":{"connection_id":"0f4979d6978d463e9660b042fdcf555f","event_at":"2026-07-27T04:37:39.242000Z","event_type":"price_change","frame_hash":"ea422c4d38788696b5df3da5ae197c7494511945bf0d2016770ae75c44b1e7c2","frame_index":0,"kind":"data","monotonic_ns":229042456002750,"payload":{"event_type":"price_change","market":"0xeb66215f2e9faa6449e30a02bab5b8ed7b79a38bf961f6b24d0073c9c2419250","price_changes":[{"asset_id":"60386828328910021732068595344565885737045900010034836345809386672230885527307","best_ask":"0.39","best_bid":"0.38","hash":"0be9473f0ea0669a9acf6e44a1b27593394b7a7e","price":"0.42","side":"SELL","size":"65.4"},{"asset_id":"69697746896130839564035629862476347944307040470122503199396727085502753297492","best_ask":"0.62","best_bid":"0.61","hash":"4371a4f7eaee45a6880e996344e6d70cb180ef8d","price":"0.58","side":"BUY","size":"65.4"}],"timestamp":"1785127059242"},"payload_hash":"0cb4a7590a13b402200d756a20b600e05d1e9e12b8d8c2cc40ae79ebe4120b5c","raw_frame":"{\"market\":\"0xeb66215f2e9faa6449e30a02bab5b8ed7b79a38bf961f6b24d0073c9c2419250\", \"price_changes\":[{\"asset_id\":\"60386828328910021732068595344565885737045900010034836345809386672230885527307\", \"price\":\"0.42\", \"size\":\"65.4\", \"side\":\"SELL\", \"hash\":\"0be9473f0ea0669a9acf6e44a1b27593394b7a7e\", \"best_bid\":\"0.38\", \"best_ask\":\"0.39\"}, {\"asset_id\":\"69697746896130839564035629862476347944307040470122503199396727085502753297492\", \"price\":\"0.58\", \"size\":\"65.4\", \"side\":\"BUY\", \"hash\":\"4371a4f7eaee45a6880e996344e6d70cb180ef8d\", \"best_bid\":\"0.61\", \"best_ask\":\"0.62\"}], \"timestamp\":\"1785127059242\", \"event_type\":\"price_change\"}","received_at":"2026-07-27T04:37:39.190148Z","schema_version":"clob-market-ws.price_change.v1","sequence":null,"server_hash":null,"server_timestamp":"1785127059242","session_id":"e9443c7415a0419799bee9cfbb1a9e4d","source":"clob_market_ws"},"received_at":"2026-07-27T04:37:39.190148Z","record_id":"72620b92da6ffc6cc94705af371550b58987a8a39cdfdbfb9c264e0b5093481d","schema_fingerprint":"4aa3821a28b0b7c2400bc59aba4bcc0a76e971dadd19610d3ad38c768e124dc7","schema_version":"edge-lab-recorder.raw.v1","sequence":null,"source":"clob_market_ws"}
{"event_at":"2026-07-27T04:37:39.243000Z","event_fingerprint":"9d600a6f8e6d18a5822573f5d2fc57fd0ef551ec089b3eb78c5429bf9f158573","payload":{"connection_id":"0f4979d6978d463e9660b042fdcf555f","event_at":"2026-07-27T04:37:39.243000Z","event_type":"price_change","frame_hash":"24c32246f979833b262990cc8d6908411c861a0e26eec61f685be5e53721d752","frame_index":0,"kind":"data","monotonic_ns":229042457487625,"payload":{"event_type":"price_change","market":"0xeb66215f2e9faa6449e30a02bab5b8ed7b79a38bf961f6b24d0073c9c2419250","price_changes":[{"asset_id":"69697746896130839564035629862476347944307040470122503199396727085502753297492","best_ask":"0.62","best_bid":"0.61","hash":"b5d835937e95c8c25a913b85a22043098b33e158","price":"0.57","side":"BUY","size":"58.16"},{"asset_id":"60386828328910021732068595344565885737045900010034836345809386672230885527307","best_ask":"0.39","best_bid":"0.38","hash":"d6d5819e286ef6ff03ed1a3a369bb3fa764cba62","price":"0.43","side":"SELL","size":"58.16"}],"timestamp":"1785127059243"},"payload_hash":"c03c49b93a695a7a554c46601b8254edff41bc71a7693d30be73541003ffc430","raw_frame":"{\"market\":\"0xeb66215f2e9faa6449e30a02bab5b8ed7b79a38bf961f6b24d0073c9c2419250\", \"price_changes\":[{\"asset_id\":\"69697746896130839564035629862476347944307040470122503199396727085502753297492\", \"price\":\"0.57\", \"size\":\"58.16\", \"side\":\"BUY\", \"hash\":\"b5d835937e95c8c25a913b85a22043098b33e158\", \"best_bid\":\"0.61\", \"best_ask\":\"0.62\"}, {\"asset_id\":\"60386828328910021732068595344565885737045900010034836345809386672230885527307\", \"price\":\"0.43\", \"size\":\"58.16\", \"side\":\"SELL\", \"hash\":\"d6d5819e286ef6ff03ed1a3a369bb3fa764cba62\", \"best_bid\":\"0.38\", \"best_ask\":\"0.39\"}], \"timestamp\":\"1785127059243\", \"event_type\":\"price_change\"}","received_at":"2026-07-27T04:37:39.191633Z","schema_version":"clob-market-ws.price_change.v1","sequence":null,"server_hash":null,"server_timestamp":"1785127059243","session_id":"e9443c7415a0419799bee9cfbb1a9e4d","source":"clob_market_ws"},"received_at":"2026-07-27T04:37:39.191633Z","record_id":"062821df717bf8c3646cab8c8cbf1fe1c560ebb4ca5fe902da89e8823dcc7f62","schema_fingerprint":"4aa3821a28b0b7c2400bc59aba4bcc0a76e971dadd19610d3ad38c768e124dc7","schema_version":"edge-lab-recorder.raw.v1","sequence":null,"source":"clob_market_ws"}
{"event_at":"2026-07-27T04:37:39.243000Z","event_fingerprint":"11346b59a403a21d0f9a9acbd0af7562a0ebfe0e9a5774015b75cb9a65a7d54d","payload":{"connection_id":"0f4979d6978d463e9660b042fdcf555f","event_at":"2026-07-27T04:37:39.243000Z","event_type":"price_change","frame_hash":"c4ef7b55adf147e438cba0b2e5e31424ee1a454c5d7f5a8391022a8d4203923f","frame_index":0,"kind":"data","monotonic_ns":229042458961625,"payload":{"event_type":"price_change","market":"0xeb66215f2e9faa6449e30a02bab5b8ed7b79a38bf961f6b24d0073c9c2419250","price_changes":[{"asset_id":"60386828328910021732068595344565885737045900010034836345809386672230885527307","best_ask":"0.39","best_bid":"0.38","hash":"f715e20c645416845e7adb3838f948e5ae63c456","price":"0.31","side":"BUY","size":"50"},{"asset_id":"69697746896130839564035629862476347944307040470122503199396727085502753297492","best_ask":"0.62","best_bid":"0.61","hash":"67492e3ccabface742da8791560f2687f17d3d8c","price":"0.69","side":"SELL","size":"50"}],"timestamp":"1785127059243"},"payload_hash":"8a526cd85db6f1ce7a2ed18c4d9189f110a17b1763194bd2a7042ea07b4c8180","raw_frame":"{\"market\":\"0xeb66215f2e9faa6449e30a02bab5b8ed7b79a38bf961f6b24d0073c9c2419250\", \"price_changes\":[{\"asset_id\":\"60386828328910021732068595344565885737045900010034836345809386672230885527307\", \"price\":\"0.31\", \"size\":\"50\", \"side\":\"BUY\", \"hash\":\"f715e20c645416845e7adb3838f948e5ae63c456\", \"best_bid\":\"0.38\", \"best_ask\":\"0.39\"}, {\"asset_id\":\"69697746896130839564035629862476347944307040470122503199396727085502753297492\", \"price\":\"0.69\", \"size\":\"50\", \"side\":\"SELL\", \"hash\":\"67492e3ccabface742da8791560f2687f17d3d8c\", \"best_bid\":\"0.61\", \"best_ask\":\"0.62\"}], \"timestamp\":\"1785127059243\", \"event_type\":\"price_change\"}","received_at":"2026-07-27T04:37:39.193104Z","schema_version":"clob-market-ws.price_change.v1","sequence":null,"server_hash":null,"server_timestamp":"1785127059243","session_id":"e9443c7415a0419799bee9cfbb1a9e4d","source":"clob_market_ws"},"received_at":"2026-07-27T04:37:39.193104Z","record_id":"32c7722764a713c547244b302ada0d0f65d27c24f3740db792aa38974bc8b41f","schema_fingerprint":"4aa3821a28b0b7c2400bc59aba4bcc0a76e971dadd19610d3ad38c768e124dc7","schema_version":"edge-lab-recorder.raw.v1","sequence":null,"source":"clob_market_ws"}
{"event_at":"2026-07-27T04:37:39.256000Z","event_fingerprint":"f7eb00e17857d6cb6b36026344070c24abc0f3c3236bd95413daa48404dc9911","payload":{"connection_id":"0f4979d6978d463e9660b042fdcf555f","event_at":"2026-07-27T04:37:39.256000Z","event_type":"price_change","frame_hash":"434b0b54452d234a740e55f919b2bf3d3a82d06ba7a8ed015465301777fb17b5","frame_index":0,"kind":"data","monotonic_ns":229042467390333,"payload":{"event_type":"price_change","market":"0xeb66215f2e9faa6449e30a02bab5b8ed7b79a38bf961f6b24d0073c9c2419250","price_changes":[{"asset_id":"69697746896130839564035629862476347944307040470122503199396727085502753297492","best_ask":"0.62","best_bid":"0.61","hash":"888ac50c3b78769c9c8872c10f89ac15c92a956c","price":"0.01","side":"BUY","size":"5829.91"},{"asset_id":"60386828328910021732068595344565885737045900010034836345809386672230885527307","best_ask":"0.39","best_bid":"0.38","hash":"e0ff194340430967fc7262faf3d71a8a652c35e1","price":"0.99","side":"SELL","size":"5829.91"}],"timestamp":"1785127059256"},"payload_hash":"3485632c8eebbd8097d29e4a47ec6d71c3f494b6bcd15cd570315cdf1e8bd6a9","raw_frame":"{\"market\":\"0xeb66215f2e9faa6449e30a02bab5b8ed7b79a38bf961f6b24d0073c9c2419250\", \"price_changes\":[{\"asset_id\":\"69697746896130839564035629862476347944307040470122503199396727085502753297492\", \"price\":\"0.01\", \"size\":\"5829.91\", \"side\":\"BUY\", \"hash\":\"888ac50c3b78769c9c8872c10f89ac15c92a956c\", \"best_bid\":\"0.61\", \"best_ask\":\"0.62\"}, {\"asset_id\":\"60386828328910021732068595344565885737045900010034836345809386672230885527307\", \"price\":\"0.99\", \"size\":\"5829.91\", \"side\":\"SELL\", \"hash\":\"e0ff194340430967fc7262faf3d71a8a652c35e1\", \"best_bid\":\"0.38\", \"best_ask\":\"0.39\"}], \"timestamp\":\"1785127059256\", \"event_type\":\"price_change\"}","received_at":"2026-07-27T04:37:39.201534Z","schema_version":"clob-market-ws.price_change.v1","sequence":null,"server_hash":null,"server_timestamp":"1785127059256","session_id":"e9443c7415a0419799bee9cfbb1a9e4d","source":"clob_market_ws"},"received_at":"2026-07-27T04:37:39.201534Z","record_id":"2eacab7f1567852f6026175789ae3c5c45d3478eaf9e05800e629af98fd6e51d","schema_fingerprint":"4aa3821a28b0b7c2400bc59aba4bcc0a76e971dadd19610d3ad38c768e124dc7","schema_version":"edge-lab-recorder.raw.v1","sequence":null,"source":"clob_market_ws"}
{"event_at":"2026-07-27T04:37:39.343000Z","event_fingerprint":"54496ce2f4f036c001cd9087f5ddcaeeebffc5411de2fc582e17038aa8ddd930","payload":{"connection_id":"0f4979d6978d463e9660b042fdcf555f","event_at":"2026-07-27T04:37:39.343000Z","event_type":"price_change","frame_hash":"e4923b1944d8e7741e1ab6bf0ccd6bcf9f585721963a61aad188506ccdc62ec1","frame_index":0,"kind":"data","monotonic_ns":229042554668333,"payload":{"event_type":"price_change","market":"0xeb66215f2e9faa6449e30a02bab5b8ed7b79a38bf961f6b24d0073c9c2419250","price_changes":[{"asset_id":"69697746896130839564035629862476347944307040470122503199396727085502753297492","best_ask":"0.62","best_bid":"0.61","hash":"d050cb5d2cddc7543b6112bbc378b24ca4a82f33","price":"0.58","side":"BUY","size":"44.4"},{"asset_id":"60386828328910021732068595344565885737045900010034836345809386672230885527307","best_ask":"0.39","best_bid":"0.38","hash":"20db29bcc4d491f8e9a6c1d9979d12651b1149a3","price":"0.42","side":"SELL","size":"44.4"}],"timestamp":"1785127059343"},"payload_hash":"469489cfc6ecf3ba5f2a8077d1e26e82354614a0dea857f0c5365639b974df1b","raw_frame":"{\"market\":\"0xeb66215f2e9faa6449e30a02bab5b8ed7b79a38bf961f6b24d0073c9c2419250\", \"price_changes\":[{\"asset_id\":\"69697746896130839564035629862476347944307040470122503199396727085502753297492\", \"price\":\"0.58\", \"size\":\"44.4\", \"side\":\"BUY\", \"hash\":\"d050cb5d2cddc7543b6112bbc378b24ca4a82f33\", \"best_bid\":\"0.61\", \"best_ask\":\"0.62\"}, {\"asset_id\":\"60386828328910021732068595344565885737045900010034836345809386672230885527307\", \"price\":\"0.42\", \"size\":\"44.4\", \"side\":\"SELL\", \"hash\":\"20db29bcc4d491f8e9a6c1d9979d12651b1149a3\", \"best_bid\":\"0.38\", \"best_ask\":\"0.39\"}], \"timestamp\":\"1785127059343\", \"event_type\":\"price_change\"}","received_at":"2026-07-27T04:37:39.288808Z","schema_version":"clob-market-ws.price_change.v1","sequence":null,"server_hash":null,"server_timestamp":"1785127059343","session_id":"e9443c7415a0419799bee9cfbb1a9e4d","source":"clob_market_ws"},"received_at":"2026-07-27T04:37:39.288808Z","record_id":"eaf13e750904f8cf9ce5b0626a3eb4fa5490f7759f485761c9a9c1b9670e9b98","schema_fingerprint":"4aa3821a28b0b7c2400bc59aba4bcc0a76e971dadd19610d3ad38c768e124dc7","schema_version":"edge-lab-recorder.raw.v1","sequence":null,"source":"clob_market_ws"}
{"event_at":"2026-07-27T04:37:39.348000Z","event_fingerprint":"d127e866ed5507b4cea3e6a0f511cc1015a274ef981bd73cb5053a17dcb69acf","payload":{"connection_id":"0f4979d6978d463e9660b042fdcf555f","event_at":"2026-07-27T04:37:39.348000Z","event_type":"price_change","frame_hash":"cae79cfad3d1ec5934579e0870204814de4c09593e0ea574825db8d4600427b3","frame_index":0,"kind":"data","monotonic_ns":229042559708875,"payload":{"event_type":"price_change","market":"0xeb66215f2e9faa6449e30a02bab5b8ed7b79a38bf961f6b24d0073c9c2419250","price_changes":[{"asset_id":"60386828328910021732068595344565885737045900010034836345809386672230885527307","best_ask":"0.39","best_bid":"0.38","hash":"2b08366977a7ce649dc9b3a5958bdc20b1ffd373","price":"0.42","side":"SELL","size":"65.4"},{"asset_id":"69697746896130839564035629862476347944307040470122503199396727085502753297492","best_ask":"0.62","best_bid":"0.61","hash":"336dd919878dc5842f29eca50c9dc7304f6dc103","price":"0.58","side":"BUY","size":"65.4"}],"timestamp":"1785127059348"},"payload_hash":"a9db24bea8075a45b6860939b586784ecd054f289d545338d5581e1e91385e05","raw_frame":"{\"market\":\"0xeb66215f2e9faa6449e30a02bab5b8ed7b79a38bf961f6b24d0073c9c2419250\", \"price_changes\":[{\"asset_id\":\"60386828328910021732068595344565885737045900010034836345809386672230885527307\", \"price\":\"0.42\", \"size\":\"65.4\", \"side\":\"SELL\", \"hash\":\"2b08366977a7ce649dc9b3a5958bdc20b1ffd373\", \"best_bid\":\"0.38\", \"best_ask\":\"0.39\"}, {\"asset_id\":\"69697746896130839564035629862476347944307040470122503199396727085502753297492\", \"price\":\"0.58\", \"size\":\"65.4\", \"side\":\"BUY\", \"hash\":\"336dd919878dc5842f29eca50c9dc7304f6dc103\", \"best_bid\":\"0.61\", \"best_ask\":\"0.62\"}], \"timestamp\":\"1785127059348\", \"event_type\":\"price_change\"}","received_at":"2026-07-27T04:37:39.293854Z","schema_version":"clob-market-ws.price_change.v1","sequence":null,"server_hash":null,"server_timestamp":"1785127059348","session_id":"e9443c7415a0419799bee9cfbb1a9e4d","source":"clob_market_ws"},"received_at":"2026-07-27T04:37:39.293854Z","record_id":"8b8242db756cac0d41b617f5c38c1624de917e0dc2873427ad6c8e0a445c1266","schema_fingerprint":"4aa3821a28b0b7c2400bc59aba4bcc0a76e971dadd19610d3ad38c768e124dc7","schema_version":"edge-lab-recorder.raw.v1","sequence":null,"source":"clob_market_ws"}
{"event_at":"2026-07-27T04:37:39.350000Z","event_fingerprint":"f598f9eee9ade95b30396c7d181f3e96f0abd583b7512197f1c93834e2be8bf9","payload":{"connection_id":"0f4979d6978d463e9660b042fdcf555f","event_at":"2026-07-27T04:37:39.350000Z","event_type":"price_change","frame_hash":"eab200d9de2251ff8e82435f90a0531e753c7af207027d14c4d7154d6119746d","frame_index":0,"kind":"data","monotonic_ns":229042562082541,"payload":{"event_type":"price_change","market":"0xeb66215f2e9faa6449e30a02bab5b8ed7b79a38bf961f6b24d0073c9c2419250","price_changes":[{"asset_id":"69697746896130839564035629862476347944307040470122503199396727085502753297492","best_ask":"0.62","best_bid":"0.61","hash":"c9022dbf28322a9dcea8b18167500952ee4a34b3","price":"0.68","side":"SELL","size":"155"},{"asset_id":"60386828328910021732068595344565885737045900010034836345809386672230885527307","best_ask":"0.39","best_bid":"0.38","hash":"66dea545eda19c4aab9174c33d2d69091356d8d7","price":"0.32","side":"BUY","size":"155"}],"timestamp":"1785127059350"},"payload_hash":"7c397d6288bad13456a44693093b600dfe74e952063bdb74958e22b73b71833a","raw_frame":"{\"market\":\"0xeb66215f2e9faa6449e30a02bab5b8ed7b79a38bf961f6b24d0073c9c2419250\", \"price_changes\":[{\"asset_id\":\"69697746896130839564035629862476347944307040470122503199396727085502753297492\", \"price\":\"0.68\", \"size\":\"155\", \"side\":\"SELL\", \"hash\":\"c9022dbf28322a9dcea8b18167500952ee4a34b3\", \"best_bid\":\"0.61\", \"best_ask\":\"0.62\"}, {\"asset_id\":\"60386828328910021732068595344565885737045900010034836345809386672230885527307\", \"price\":\"0.32\", \"size\":\"155\", \"side\":\"BUY\", \"hash\":\"66dea545eda19c4aab9174c33d2d69091356d8d7\", \"best_bid\":\"0.38\", \"best_ask\":\"0.39\"}], \"timestamp\":\"1785127059350\", \"event_type\":\"price_change\"}","received_at":"2026-07-27T04:37:39.296226Z","schema_version":"clob-market-ws.price_change.v1","sequence":null,"server_hash":null,"server_timestamp":"1785127059350","session_id":"e9443c7415a0419799bee9cfbb1a9e4d","source":"clob_market_ws"},"received_at":"2026-07-27T04:37:39.296226Z","record_id":"2f82b451be968d4bd257792439d1851c8eb09b57aabb998d17730bc93da026be","schema_fingerprint":"4aa3821a28b0b7c2400bc59aba4bcc0a76e971dadd19610d3ad38c768e124dc7","schema_version":"edge-lab-recorder.raw.v1","sequence":null,"source":"clob_market_ws"}
{"event_at":"2026-07-27T04:37:39.369000Z","event_fingerprint":"605e0bbf784034a6bc9d1a2dbfe12142ae171ecf8677f16f5794dc876fce7281","payload":{"connection_id":"0f4979d6978d463e9660b042fdcf555f","event_at":"2026-07-27T04:37:39.369000Z","event_type":"price_change","frame_hash":"fa4f9e08673b8a5fe8b6a1d6361956071d411576c193795299894f635796d9fc","frame_index":0,"kind":"data","monotonic_ns":229042580526916,"payload":{"event_type":"price_change","market":"0xeb66215f2e9faa6449e30a02bab5b8ed7b79a38bf961f6b24d0073c9c2419250","price_changes":[{"asset_id":"69697746896130839564035629862476347944307040470122503199396727085502753297492","best_ask":"0.62","best_bid":"0.61","hash":"77161e70acb67d21f84e360472112d1836f2a890","price":"0.04","side":"BUY","size":"613.09"},{"asset_id":"60386828328910021732068595344565885737045900010034836345809386672230885527307","best_ask":"0.39","best_bid":"0.38","hash":"039a659c698d74d5af3e866d53e3f843e647d712","price":"0.96","side":"SELL","size":"613.09"}],"timestamp":"1785127059369"},"payload_hash":"708a9ad62e2da1279e4e67248a5156756e2673e602abd2d3219ef52b0cd20b07","raw_frame":"{\"market\":\"0xeb66215f2e9faa6449e30a02bab5b8ed7b79a38bf961f6b24d0073c9c2419250\", \"price_changes\":[{\"asset_id\":\"69697746896130839564035629862476347944307040470122503199396727085502753297492\", \"price\":\"0.04\", \"size\":\"613.09\", \"side\":\"BUY\", \"hash\":\"77161e70acb67d21f84e360472112d1836f2a890\", \"best_bid\":\"0.61\", \"best_ask\":\"0.62\"}, {\"asset_id\":\"60386828328910021732068595344565885737045900010034836345809386672230885527307\", \"price\":\"0.96\", \"size\":\"613.09\", \"side\":\"SELL\", \"hash\":\"039a659c698d74d5af3e866d53e3f843e647d712\", \"best_bid\":\"0.38\", \"best_ask\":\"0.39\"}], \"timestamp\":\"1785127059369\", \"event_type\":\"price_change\"}","received_at":"2026-07-27T04:37:39.314671Z","schema_version":"clob-market-ws.price_change.v1","sequence":null,"server_hash":null,"server_timestamp":"1785127059369","session_id":"e9443c7415a0419799bee9cfbb1a9e4d","source":"clob_market_ws"},"received_at":"2026-07-27T04:37:39.314671Z","record_id":"dae9a63038ae84bb804b7b74d0a9ca7e6dff1176a051a3a4bd31c75405c0f1be","schema_fingerprint":"4aa3821a28b0b7c2400bc59aba4bcc0a76e971dadd19610d3ad38c768e124dc7","schema_version":"edge-lab-recorder.raw.v1","sequence":null,"source":"clob_market_ws"}
{"event_at":"2026-07-27T04:37:39.375000Z","event_fingerprint":"9b75030605b7b5e74ff4e394841085ddf0bc890bfe5f2aa762586cba796df970","payload":{"connection_id":"0f4979d6978d463e9660b042fdcf555f","event_at":"2026-07-27T04:37:39.375000Z","event_type":"price_change","frame_hash":"1b05b9a83cfb24bfd2e1845caa364b981200fc192d5d34e4829c397fc0720354","frame_index":0,"kind":"data","monotonic_ns":229042588374333,"payload":{"event_type":"price_change","market":"0xeb66215f2e9faa6449e30a02bab5b8ed7b79a38bf961f6b24d0073c9c2419250","price_changes":[{"asset_id":"60386828328910021732068595344565885737045900010034836345809386672230885527307","best_ask":"0.39","best_bid":"0.38","hash":"d28ac960a8ff53e844301c5cc0759ea4e535f5fc","price":"0.3","side":"BUY","size":"237"},{"asset_id":"69697746896130839564035629862476347944307040470122503199396727085502753297492","best_ask":"0.62","best_bid":"0.61","hash":"4314e0cd97f7e8324279cd19137a932e1c891757","price":"0.7","side":"SELL","size":"237"}],"timestamp":"1785127059375"},"payload_hash":"9ec5664dc2db42311f11d4bff0ddce4c70cd3e1749746ad01263ed249eacc3ee","raw_frame":"{\"market\":\"0xeb66215f2e9faa6449e30a02bab5b8ed7b79a38bf961f6b24d0073c9c2419250\", \"price_changes\":[{\"asset_id\":\"60386828328910021732068595344565885737045900010034836345809386672230885527307\", \"price\":\"0.3\", \"size\":\"237\", \"side\":\"BUY\", \"hash\":\"d28ac960a8ff53e844301c5cc0759ea4e535f5fc\", \"best_bid\":\"0.38\", \"best_ask\":\"0.39\"}, {\"asset_id\":\"69697746896130839564035629862476347944307040470122503199396727085502753297492\", \"price\":\"0.7\", \"size\":\"237\", \"side\":\"SELL\", \"hash\":\"4314e0cd97f7e8324279cd19137a932e1c891757\", \"best_bid\":\"0.61\", \"best_ask\":\"0.62\"}], \"timestamp\":\"1785127059375\", \"event_type\":\"price_change\"}","received_at":"2026-07-27T04:37:39.322515Z","schema_version":"clob-market-ws.price_change.v1","sequence":null,"server_hash":null,"server_timestamp":"1785127059375","session_id":"e9443c7415a0419799bee9cfbb1a9e4d","source":"clob_market_ws"},"received_at":"2026-07-27T04:37:39.322515Z","record_id":"f52e2cb7f385d74668ee304d16fb4e04d03de4ebf626b80eaf98d1de8bca0614","schema_fingerprint":"4aa3821a28b0b7c2400bc59aba4bcc0a76e971dadd19610d3ad38c768e124dc7","schema_version":"edge-lab-recorder.raw.v1","sequence":null,"source":"clob_market_ws"}
