{"event_at":"2026-07-27T04:34:38.398000Z","event_fingerprint":"a48343548806b936a1409148b8b8f847dae3f173ce430f4fbfc482a56012e844","payload":{"connection_id":"0f4979d6978d463e9660b042fdcf555f","event_at":"2026-07-27T04:34:38.398000Z","event_type":"price_change","frame_hash":"e654b993587306a2c5d32dac9a2a55ec6beec1a33db55a35b54ca8e913a7485c","frame_index":0,"kind":"data","monotonic_ns":228861703274583,"payload":{"event_type":"price_change","market":"0xeb66215f2e9faa6449e30a02bab5b8ed7b79a38bf961f6b24d0073c9c2419250","price_changes":[{"asset_id":"69697746896130839564035629862476347944307040470122503199396727085502753297492","best_ask":"0.24","best_bid":"0.23","hash":"47171f7c48e0dd66ec29990a67a392edd4a450b2","price":"0.2","side":"BUY","size":"47.6"},{"asset_id":"60386828328910021732068595344565885737045900010034836345809386672230885527307","best_ask":"0.77","best_bid":"0.76","hash":"13f44c22027b8d76e440c4d2d4046284fccdff25","price":"0.8","side":"SELL","size":"47.6"}],"timestamp":"1785126878398"},"payload_hash":"73f9d87e7acd86230179500049f964a2af8dadfdddaddd224a1e60b6914f10ff","raw_frame":"{\"market\":\"0xeb66215f2e9faa6449e30a02bab5b8ed7b79a38bf961f6b24d0073c9c2419250\", \"price_changes\":[{\"asset_id\":\"69697746896130839564035629862476347944307040470122503199396727085502753297492\", \"price\":\"0.2\", \"size\":\"47.6\", \"side\":\"BUY\", \"hash\":\"47171f7c48e0dd66ec29990a67a392edd4a450b2\", \"best_bid\":\"0.23\", \"best_ask\":\"0.24\"}, {\"asset_id\":\"60386828328910021732068595344565885737045900010034836345809386672230885527307\", \"price\":\"0.8\", \"size\":\"47.6\", \"side\":\"SELL\", \"hash\":\"13f44c22027b8d76e440c4d2d4046284fccdff25\", \"best_bid\":\"0.76\", \"best_ask\":\"0.77\"}], \"timestamp\":\"1785126878398\", \"event_type\":\"price_change\"}","received_at":"2026-07-27T04:34:38.435845Z","schema_version":"clob-market-ws.price_change.v1","sequence":null,"server_hash":null,"server_timestamp":"1785126878398","session_id":"e9443c7415a0419799bee9cfbb1a9e4d","source":"clob_market_ws"},"received_at":"2026-07-27T04:34:38.435845Z","record_id":"57e6d1a6a91a484b681e9cb2463e747e6ede590bb3a3bb0e98e94c3eb10d1b32","schema_fingerprint":"4aa3821a28b0b7c2400bc59aba4bcc0a76e971dadd19610d3ad38c768e124dc7","schema_version":"edge-lab-recorder.raw.v1","sequence":null,"source":"clob_market_ws"}
{"event_at":"2026-07-27T04:34:38.398000Z","event_fingerprint":"d10f0b60d00507198ac508c33b3066eb848de01699bdee875f5f0f844bd4b063","payload":{"connection_id":"0f4979d6978d463e9660b042fdcf555f","event_at":"2026-07-27T04:34:38.398000Z","event_type":"price_change","frame_hash":"b2db40b9b9df20025d5ca38b16131977fa2fd19b6c2b65962df807876120742c","frame_index":0,"kind":"data","monotonic_ns":228861705354708,"payload":{"event_type":"price_change","market":"0xeb66215f2e9faa6449e30a02bab5b8ed7b79a38bf961f6b24d0073c9c2419250","price_changes":[{"asset_id":"60386828328910021732068595344565885737045900010034836345809386672230885527307","best_ask":"0.77","best_bid":"0.76","hash":"13f44c22027b8d76e440c4d2d4046284fccdff25","price":"0.69","side":"BUY","size":"143"},{"asset_id":"69697746896130839564035629862476347944307040470122503199396727085502753297492","best_ask":"0.24","best_bid":"0.23","hash":"47171f7c48e0dd66ec29990a67a392edd4a450b2","price":"0.31","side":"SELL","size":"143"}],"timestamp":"1785126878398"},"payload_hash":"a147a9baa61abc63f166d4427bd7b7dfdcb6f3f874424860bb6c8ed67b33c4f6","raw_frame":"{\"market\":\"0xeb66215f2e9faa6449e30a02bab5b8ed7b79a38bf961f6b24d0073c9c2419250\", \"price_changes\":[{\"asset_id\":\"60386828328910021732068595344565885737045900010034836345809386672230885527307\", \"price\":\"0.69\", \"size\":\"143\", \"side\":\"BUY\", \"hash\":\"13f44c22027b8d76e440c4d2d4046284fccdff25\", \"best_bid\":\"0.76\", \"best_ask\":\"0.77\"}, {\"asset_id\":\"69697746896130839564035629862476347944307040470122503199396727085502753297492\", \"price\":\"0.31\", \"size\":\"143\", \"side\":\"SELL\", \"hash\":\"47171f7c48e0dd66ec29990a67a392edd4a450b2\", \"best_bid\":\"0.23\", \"best_ask\":\"0.24\"}], \"timestamp\":\"1785126878398\", \"event_type\":\"price_change\"}","received_at":"2026-07-27T04:34:38.437935Z","schema_version":"clob-market-ws.price_change.v1","sequence":null,"server_hash":null,"server_timestamp":"1785126878398","session_id":"e9443c7415a0419799bee9cfbb1a9e4d","source":"clob_market_ws"},"received_at":"2026-07-27T04:34:38.437935Z","record_id":"de4d2a46a9f4e1f6b5b0cf5a732e9e20382373877eaca879bf2d44196c594da7","schema_fingerprint":"4aa3821a28b0b7c2400bc59aba4bcc0a76e971dadd19610d3ad38c768e124dc7","schema_version":"edge-lab-recorder.raw.v1","sequence":null,"source":"clob_market_ws"}
{"event_at":"2026-07-27T04:34:38.398000Z","event_fingerprint":"963c3a9a46a65d31af58d6df548d9ad66d6da6c61457d16009927473f9abe62e","payload":{"connection_id":"0f4979d6978d463e9660b042fdcf555f","event_at":"2026-07-27T04:34:38.398000Z","event_type":"price_change","frame_hash":"0ffa2b90ba5fe1eeb6c56801cc67b73cca4fdba52dec24278141d506eea685c6","frame_index":0,"kind":"data","monotonic_ns":228861706683916,"payload":{"event_type":"price_change","market":"0xeb66215f2e9faa6449e30a02bab5b8ed7b79a38bf961f6b24d0073c9c2419250","price_changes":[{"asset_id":"60386828328910021732068595344565885737045900010034836345809386672230885527307","best_ask":"0.77","best_bid":"0.76","hash":"13f44c22027b8d76e440c4d2d4046284fccdff25","price":"0.68","side":"BUY","size":"13"},{"asset_id":"69697746896130839564035629862476347944307040470122503199396727085502753297492","best_ask":"0.24","best_bid":"0.23","hash":"47171f7c48e0dd66ec29990a67a392edd4a450b2","price":"0.32","side":"SELL","size":"13"}],"timestamp":"1785126878398"},"payload_hash":"e05ac86e1b06f28cf9889481b3c26193809102910ed967812b1081111363636b","raw_frame":"{\"market\":\"0xeb66215f2e9faa6449e30a02bab5b8ed7b79a38bf961f6b24d0073c9c2419250\", \"price_changes\":[{\"asset_id\":\"60386828328910021732068595344565885737045900010034836345809386672230885527307\", \"price\":\"0.68\", \"size\":\"13\", \"side\":\"BUY\", \"hash\":\"13f44c22027b8d76e440c4d2d4046284fccdff25\", \"best_bid\":\"0.76\", \"best_ask\":\"0.77\"}, {\"asset_id\":\"69697746896130839564035629862476347944307040470122503199396727085502753297492\", \"price\":\"0.32\", \"size\":\"13\", \"side\":\"SELL\", \"hash\":\"47171f7c48e0dd66ec29990a67a392edd4a450b2\", \"best_bid\":\"0.23\", \"best_ask\":\"0.24\"}], \"timestamp\":\"1785126878398\", \"event_type\":\"price_change\"}","received_at":"2026-07-27T04:34:38.439259Z","schema_version":"clob-market-ws.price_change.v1","sequence":null,"server_hash":null,"server_timestamp":"1785126878398","session_id":"e9443c7415a0419799bee9cfbb1a9e4d","source":"clob_market_ws"},"received_at":"2026-07-27T04:34:38.439259Z","record_id":"9b178c0a4dc9dcb8294c00596ce45cf0e5f37ccab2e819da89ce05e4e6e8b919","schema_fingerprint":"4aa3821a28b0b7c2400bc59aba4bcc0a76e971dadd19610d3ad38c768e124dc7","schema_version":"edge-lab-recorder.raw.v1","sequence":null,"source":"clob_market_ws"}
{"event_at":"2026-07-27T04:34:38.400000Z","event_fingerprint":"8ca49822af274af3a14f6f3593082007079ac0041f632153305bcbdd4c99d000","payload":{"connection_id":"0f4979d6978d463e9660b042fdcf555f","event_at":"2026-07-27T04:34:38.400000Z","event_type":"price_change","frame_hash":"c33f192dbc2e245a319de3ac36cfe12549af9c534e938186db0ff6811fb53756","frame_index":0,"kind":"data","monotonic_ns":228861708238958,"payload":{"event_type":"price_change","market":"0xeb66215f2e9faa6449e30a02bab5b8ed7b79a38bf961f6b24d0073c9c2419250","price_changes":[{"asset_id":"60386828328910021732068595344565885737045900010034836345809386672230885527307","best_ask":"0.77","best_bid":"0.76","hash":"d0b27d9e6370f41fedefd32099129d665dc8e356","price":"0.72","side":"BUY","size":"79.64"},{"asset_id":"69697746896130839564035629862476347944307040470122503199396727085502753297492","best_ask":"0.24","best_bid":"0.23","hash":"a99bb0406dd2acc1a5c9b11367b0f9b0d0805cd0","price":"0.28","side":"SELL","size":"79.64"}],"timestamp":"1785126878400"},"payload_hash":"79efa8fca4c634b93d30f5ae0de1abf1d36243d58b7635a86fc3b93bddaed665","raw_frame":"{\"market\":\"0xeb66215f2e9faa6449e30a02bab5b8ed7b79a38bf961f6b24d0073c9c2419250\", \"price_changes\":[{\"asset_id\":\"60386828328910021732068595344565885737045900010034836345809386672230885527307\", \"price\":\"0.72\", \"size\":\"79.64\", \"side\":\"BUY\", \"hash\":\"d0b27d9e6370f41fedefd32099129d665dc8e356\", \"best_bid\":\"0.76\", \"best_ask\":\"0.77\"}, {\"asset_id\":\"69697746896130839564035629862476347944307040470122503199396727085502753297492\", \"price\":\"0.28\", \"size\":\"79.64\", \"side\":\"SELL\", \"hash\":\"a99bb0406dd2acc1a5c9b11367b0f9b0d0805cd0\", \"best_bid\":\"0.23\", \"best_ask\":\"0.24\"}], \"timestamp\":\"1785126878400\", \"event_type\":\"price_change\"}","received_at":"2026-07-27T04:34:38.440816Z","schema_version":"clob-market-ws.price_change.v1","sequence":null,"server_hash":null,"server_timestamp":"1785126878400","session_id":"e9443c7415a0419799bee9cfbb1a9e4d","source":"clob_market_ws"},"received_at":"2026-07-27T04:34:38.440816Z","record_id":"9556b89479a2f1cad2ccd62c52dbbcc7224b2cbd104d8c292334c5ec38f6a04d","schema_fingerprint":"4aa3821a28b0b7c2400bc59aba4bcc0a76e971dadd19610d3ad38c768e124dc7","schema_version":"edge-lab-recorder.raw.v1","sequence":null,"source":"clob_market_ws"}
{"event_at":"2026-07-27T04:34:38.401000Z","event_fingerprint":"50c0ca86e52d710c38fad8b0573a08765a98e72648f0d79c4fc53a2afaa006d5","payload":{"connection_id":"0f4979d6978d463e9660b042fdcf555f","event_at":"2026-07-27T04:34:38.401000Z","event_type":"price_change","frame_hash":"8f2958d8d0a6f67bd3d713e54dd2f76159dfc0b16af4ec64d31c65440635468d","frame_index":0,"kind":"data","monotonic_ns":228861709709750,"payload":{"event_type":"price_change","market":"0xeb66215f2e9faa6449e30a02bab5b8ed7b79a38bf961f6b24d0073c9c2419250","price_changes":[{"asset_id":"60386828328910021732068595344565885737045900010034836345809386672230885527307","best_ask":"0.77","best_bid":"0.76","hash":"df4eb55f9cf00b985fa2d241115360baa2d6ec32","price":"0.58","side":"BUY","size":"22.3"},{"asset_id":"69697746896130839564035629862476347944307040470122503199396727085502753297492","best_ask":"0.24","best_bid":"0.23","hash":"cb2f64702374e7cab16eb0a14b71828ce5d8df17","price":"0.42","side":"SELL","size":"22.3"}],"timestamp":"1785126878401"},"payload_hash":"7df9a987d75f5e302e63c068eb2c2ab8d69c1247dea4ec312c31161397f6a712","raw_frame":"{\"market\":\"0xeb66215f2e9faa6449e30a02bab5b8ed7b79a38bf961f6b24d0073c9c2419250\", \"price_changes\":[{\"asset_id\":\"60386828328910021732068595344565885737045900010034836345809386672230885527307\", \"price\":\"0.58\", \"size\":\"22.3\", \"side\":\"BUY\", \"hash\":\"df4eb55f9cf00b985fa2d241115360baa2d6ec32\", \"best_bid\":\"0.76\", \"best_ask\":\"0.77\"}, {\"asset_id\":\"69697746896130839564035629862476347944307040470122503199396727085502753297492\", \"price\":\"0.42\", \"size\":\"22.3\", \"side\":\"SELL\", \"hash\":\"cb2f64702374e7cab16eb0a14b71828ce5d8df17\", \"best_bid\":\"0.23\", \"best_ask\":\"0.24\"}], \"timestamp\":\"1785126878401\", \"event_type\":\"price_change\"}","received_at":"2026-07-27T04:34:38.442288Z","schema_version":"clob-market-ws.price_change.v1","sequence":null,"server_hash":null,"server_timestamp":"1785126878401","session_id":"e9443c7415a0419799bee9cfbb1a9e4d","source":"clob_market_ws"},"received_at":"2026-07-27T04:34:38.442288Z","record_id":"beaaf90a2c8b79ac56dc48cdc1667fdc222eb8daff7c23d1fdeed9b671541412","schema_fingerprint":"4aa3821a28b0b7c2400bc59aba4bcc0a76e971dadd19610d3ad38c768e124dc7","schema_version":"edge-lab-recorder.raw.v1","sequence":null,"source":"clob_market_ws"}
{"event_at":"2026-07-27T04:34:38.402000Z","event_fingerprint":"c4f8008025a9fd82c16b97b748651a01742add0cb4f84a7e461083d4d8b6218c","payload":{"connection_id":"0f4979d6978d463e9660b042fdcf555f","event_at":"2026-07-27T04:34:38.402000Z","event_type":"price_change","frame_hash":"3733dd3d67afcef9071a0afe2f26c5d9c362daf4c4cf8c581baddd0b7e16aff6","frame_index":0,"kind":"data","monotonic_ns":228861711175416,"payload":{"event_type":"price_change","market":"0xeb66215f2e9faa6449e30a02bab5b8ed7b79a38bf961f6b24d0073c9c2419250","price_changes":[{"asset_id":"60386828328910021732068595344565885737045900010034836345809386672230885527307","best_ask":"0.77","best_bid":"0.76","hash":"dc48c5b261118b8a628cea00d9fa0384e196ecb9","price":"0.68","side":"BUY","size":"43"},{"asset_id":"69697746896130839564035629862476347944307040470122503199396727085502753297492","best_ask":"0.24","best_bid":"0.23","hash":"336f537ba5567b539dc5344e9c2bc8a3866a5d4d","price":"0.32","side":"SELL","size":"43"}],"timestamp":"1785126878402"},"payload_hash":"b7376731728febfe6f59cbe1720a106251057fc434634791583fa31a4c084367","raw_frame":"{\"market\":\"0xeb66215f2e9faa6449e30a02bab5b8ed7b79a38bf961f6b24d0073c9c2419250\", \"price_changes\":[{\"asset_id\":\"60386828328910021732068595344565885737045900010034836345809386672230885527307\", \"price\":\"0.68\", \"size\":\"43\", \"side\":\"BUY\", \"hash\":\"dc48c5b261118b8a628cea00d9fa0384e196ecb9\", \"best_bid\":\"0.76\", \"best_ask\":\"0.77\"}, {\"asset_id\":\"69697746896130839564035629862476347944307040470122503199396727085502753297492\", \"price\":\"0.32\", \"size\":\"43\", \"side\":\"SELL\", \"hash\":\"336f537ba5567b539dc5344e9c2bc8a3866a5d4d\", \"best_bid\":\"0.23\", \"best_ask\":\"0.24\"}], \"timestamp\":\"1785126878402\", \"event_type\":\"price_change\"}","received_at":"2026-07-27T04:34:38.443754Z","schema_version":"clob-market-ws.price_change.v1","sequence":null,"server_hash":null,"server_timestamp":"1785126878402","session_id":"e9443c7415a0419799bee9cfbb1a9e4d","source":"clob_market_ws"},"received_at":"2026-07-27T04:34:38.443754Z","record_id":"ab5a87f5f35565306d5c0a4f582d270223816c9bb2231b67dfa5e82854028ddc","schema_fingerprint":"4aa3821a28b0b7c2400bc59aba4bcc0a76e971dadd19610d3ad38c768e124dc7","schema_version":"edge-lab-recorder.raw.v1","sequence":null,"source":"clob_market_ws"}
{"event_at":"2026-07-27T04:34:38.403000Z","event_fingerprint":"86bebcd224dc859d9446c083e19e3e830ce5ef2f4dbf833574e7471225977954","payload":{"connection_id":"0f4979d6978d463e9660b042fdcf555f","event_at":"2026-07-27T04:34:38.403000Z","event_type":"price_change","frame_hash":"29277fe1d0fda683787c77f7220ee7603dab96baf2ab9e5937b78617b4de0db8","frame_index":0,"kind":"data","monotonic_ns":228861712631291,"payload":{"event_type":"price_change","market":"0xeb66215f2e9faa6449e30a02bab5b8ed7b79a38bf961f6b24d0073c9c2419250","price_changes":[{"asset_id":"60386828328910021732068595344565885737045900010034836345809386672230885527307","best_ask":"0.77","best_bid":"0.76","hash":"20243b408b19d75eb9f05d06cefdf5bebb31b111","price":"0.68","side":"BUY","size":"73"},{"asset_id":"69697746896130839564035629862476347944307040470122503199396727085502753297492","best_ask":"0.24","best_bid":"0.23","hash":"b1355b91821bb3485e738f058f7249c5cf340b05","price":"0.32","side":"SELL","size":"73"}],"timestamp":"1785126878403"},"payload_hash":"7197b7aefa65120d49e8fce4151e09d80f1a3336dd52052f54a982ba23dd9a3a","raw_frame":"{\"market\":\"0xeb66215f2e9faa6449e30a02bab5b8ed7b79a38bf961f6b24d0073c9c2419250\", \"price_changes\":[{\"asset_id\":\"60386828328910021732068595344565885737045900010034836345809386672230885527307\", \"price\":\"0.68\", \"size\":\"73\", \"side\":\"BUY\", \"hash\":\"20243b408b19d75eb9f05d06cefdf5bebb31b111\", \"best_bid\":\"0.76\", \"best_ask\":\"0.77\"}, {\"asset_id\":\"69697746896130839564035629862476347944307040470122503199396727085502753297492\", \"price\":\"0.32\", \"size\":\"73\", \"side\":\"SELL\", \"hash\":\"b1355b91821bb3485e738f058f7249c5cf340b05\", \"best_bid\":\"0.23\", \"best_ask\":\"0.24\"}], \"timestamp\":\"1785126878403\", \"event_type\":\"price_change\"}","received_at":"2026-07-27T04:34:38.445209Z","schema_version":"clob-market-ws.price_change.v1","sequence":null,"server_hash":null,"server_timestamp":"1785126878403","session_id":"e9443c7415a0419799bee9cfbb1a9e4d","source":"clob_market_ws"},"received_at":"2026-07-27T04:34:38.445209Z","record_id":"f3e0949262c595fd21dfa85846176312dfffd6ac20395b881d188168414aa31e","schema_fingerprint":"4aa3821a28b0b7c2400bc59aba4bcc0a76e971dadd19610d3ad38c768e124dc7","schema_version":"edge-lab-recorder.raw.v1","sequence":null,"source":"clob_market_ws"}
{"event_at":"2026-07-27T04:34:38.403000Z","event_fingerprint":"4e1d8880c8b58b42a8e6d5c0431eb2f5668dc069ed0889dfb39a005052a0ceb8","payload":{"connection_id":"0f4979d6978d463e9660b042fdcf555f","event_at":"2026-07-27T04:34:38.403000Z","event_type":"price_change","frame_hash":"eed3776316276b3c242fb63604d474eac0b92d17c8a37def93c8c5161defbf6e","frame_index":0,"kind":"data","monotonic_ns":228861714152333,"payload":{"event_type":"price_change","market":"0xeb66215f2e9faa6449e30a02bab5b8ed7b79a38bf961f6b24d0073c9c2419250","price_changes":[{"asset_id":"69697746896130839564035629862476347944307040470122503199396727085502753297492","best_ask":"0.24","best_bid":"0.23","hash":"a478a29cd69c6052d37d872913ea205402e65da2","price":"0.21","side":"BUY","size":"57.4"},{"asset_id":"60386828328910021732068595344565885737045900010034836345809386672230885527307","best_ask":"0.77","best_bid":"0.76","hash":"3e35d963cf11cd491b3b98973fcd07b2d88f9c85","price":"0.79","side":"SELL","size":"57.4"}],"timestamp":"1785126878403"},"payload_hash":"3c1c40eb59c7ae9d5bacd27242fbab01d8f685ba0457f61c31dd7d7e4536396a","raw_frame":"{\"market\":\"0xeb66215f2e9faa6449e30a02bab5b8ed7b79a38bf961f6b24d0073c9c2419250\", \"price_changes\":[{\"asset_id\":\"69697746896130839564035629862476347944307040470122503199396727085502753297492\", \"price\":\"0.21\", \"size\":\"57.4\", \"side\":\"BUY\", \"hash\":\"a478a29cd69c6052d37d872913ea205402e65da2\", \"best_bid\":\"0.23\", \"best_ask\":\"0.24\"}, {\"asset_id\":\"60386828328910021732068595344565885737045900010034836345809386672230885527307\", \"price\":\"0.79\", \"size\":\"57.4\", \"side\":\"SELL\", \"hash\":\"3e35d963cf11cd491b3b98973fcd07b2d88f9c85\", \"best_bid\":\"0.76\", \"best_ask\":\"0.77\"}], \"timestamp\":\"1785126878403\", \"event_type\":\"price_change\"}","received_at":"2026-07-27T04:34:38.446729Z","schema_version":"clob-market-ws.price_change.v1","sequence":null,"server_hash":null,"server_timestamp":"1785126878403","session_id":"e9443c7415a0419799bee9cfbb1a9e4d","source":"clob_market_ws"},"received_at":"2026-07-27T04:34:38.446729Z","record_id":"b0b61507661d02cdb8da6f5cfcc2b31ff95bff61758c13647d52ef0a97503eec","schema_fingerprint":"4aa3821a28b0b7c2400bc59aba4bcc0a76e971dadd19610d3ad38c768e124dc7","schema_version":"edge-lab-recorder.raw.v1","sequence":null,"source":"clob_market_ws"}
{"event_at":"2026-07-27T04:34:38.405000Z","event_fingerprint":"ef6acba5adc6a5a8043047201b73d3fcd1b27ecb945b23b15eb50d23cd895422","payload":{"connection_id":"0f4979d6978d463e9660b042fdcf555f","event_at":"2026-07-27T04:34:38.405000Z","event_type":"price_change","frame_hash":"3c67ea3459ff0c0b35229283a4f42fa93892c1a93b5f0f0bc26b7064373e82d7","frame_index":0,"kind":"data","monotonic_ns":228861715694916,"payload":{"event_type":"price_change","market":"0xeb66215f2e9faa6449e30a02bab5b8ed7b79a38bf961f6b24d0073c9c2419250","price_changes":[{"asset_id":"69697746896130839564035629862476347944307040470122503199396727085502753297492","best_ask":"0.24","best_bid":"0.23","hash":"138dbfe0087bfec7ff40d8eaf129871d683f67f6","price":"0.28","side":"SELL","size":"49.6"},{"asset_id":"60386828328910021732068595344565885737045900010034836345809386672230885527307","best_ask":"0.77","best_bid":"0.76","hash":"1c007ba5b8d867b5eed47c5147ca7a81ae2cd08b","price":"0.72","side":"BUY","size":"49.6"}],"timestamp":"1785126878405"},"payload_hash":"9fe6b24bf9749fdb4fae7c95c5d40be9ca53e500a28f92158280b7a74547efa6","raw_frame":"{\"market\":\"0xeb66215f2e9faa6449e30a02bab5b8ed7b79a38bf961f6b24d0073c9c2419250\", \"price_changes\":[{\"asset_id\":\"69697746896130839564035629862476347944307040470122503199396727085502753297492\", \"price\":\"0.28\", \"size\":\"49.6\", \"side\":\"SELL\", \"hash\":\"138dbfe0087bfec7ff40d8eaf129871d683f67f6\", \"best_bid\":\"0.23\", \"best_ask\":\"0.24\"}, {\"asset_id\":\"60386828328910021732068595344565885737045900010034836345809386672230885527307\", \"price\":\"0.72\", \"size\":\"49.6\", \"side\":\"BUY\", \"hash\":\"1c007ba5b8d867b5eed47c5147ca7a81ae2cd08b\", \"best_bid\":\"0.76\", \"best_ask\":\"0.77\"}], \"timestamp\":\"1785126878405\", \"event_type\":\"price_change\"}","received_at":"2026-07-27T04:34:38.448273Z","schema_version":"clob-market-ws.price_change.v1","sequence":null,"server_hash":null,"server_timestamp":"1785126878405","session_id":"e9443c7415a0419799bee9cfbb1a9e4d","source":"clob_market_ws"},"received_at":"2026-07-27T04:34:38.448273Z","record_id":"84f93ef1b5a21320279577635b2cecef04dcca3ee1afd4dc43f2cf5c0be9d7b4","schema_fingerprint":"4aa3821a28b0b7c2400bc59aba4bcc0a76e971dadd19610d3ad38c768e124dc7","schema_version":"edge-lab-recorder.raw.v1","sequence":null,"source":"clob_market_ws"}
{"event_at":"2026-07-27T04:34:38.407000Z","event_fingerprint":"baa81cd241fa166dcd990814530a6f13c6271b243ddc9023c1143d75e2064813","payload":{"connection_id":"0f4979d6978d463e9660b042fdcf555f","event_at":"2026-07-27T04:34:38.407000Z","event_type":"price_change","frame_hash":"8e23fb4b7a6a396a563eb57f3958d01915f62909bc3a70885aa49c08440bd578","frame_index":0,"kind":"data","monotonic_ns":228861717174875,"payload":{"event_type":"price_change","market":"0xeb66215f2e9faa6449e30a02bab5b8ed7b79a38bf961f6b24d0073c9c2419250","price_changes":[{"asset_id":"60386828328910021732068595344565885737045900010034836345809386672230885527307","best_ask":"0.77","best_bid":"0.76","hash":"4b7315246f956c85316920f89d8af25fc622e263","price":"0.71","side":"BUY","size":"47.04"},{"asset_id":"69697746896130839564035629862476347944307040470122503199396727085502753297492","best_ask":"0.24","best_bid":"0.23","hash":"ab6067516d3c5a1392a112e8cea584243674edb7","price":"0.29","side":"SELL","size":"47.04"}],"timestamp":"1785126878407"},"payload_hash":"0132a466e68e5ade952bfe735d280cb8a631e7606787844fc18693a377fa9b19","raw_frame":"{\"market\":\"0xeb66215f2e9faa6449e30a02bab5b8ed7b79a38bf961f6b24d0073c9c2419250\", \"price_changes\":[{\"asset_id\":\"60386828328910021732068595344565885737045900010034836345809386672230885527307\", \"price\":\"0.71\", \"size\":\"47.04\", \"side\":\"BUY\", \"hash\":\"4b7315246f956c85316920f89d8af25fc622e263\", \"best_bid\":\"0.76\", \"best_ask\":\"0.77\"}, {\"asset_id\":\"69697746896130839564035629862476347944307040470122503199396727085502753297492\", \"price\":\"0.29\", \"size\":\"47.04\", \"side\":\"SELL\", \"hash\":\"ab6067516d3c5a1392a112e8cea584243674edb7\", \"best_bid\":\"0.23\", \"best_ask\":\"0.24\"}], \"timestamp\":\"1785126878407\", \"event_type\":\"price_change\"}","received_at":"2026-07-27T04:34:38.449753Z","schema_version":"clob-market-ws.price_change.v1","sequence":null,"server_hash":null,"server_timestamp":"1785126878407","session_id":"e9443c7415a0419799bee9cfbb1a9e4d","source":"clob_market_ws"},"received_at":"2026-07-27T04:34:38.449753Z","record_id":"f5092e4877722f4e7d760bbec41764739778c277a4766a094f9be5b8d87805e7","schema_fingerprint":"4aa3821a28b0b7c2400bc59aba4bcc0a76e971dadd19610d3ad38c768e124dc7","schema_version":"edge-lab-recorder.raw.v1","sequence":null,"source":"clob_market_ws"}
{"event_at":"2026-07-27T04:34:38.408000Z","event_fingerprint":"e9aa1a9072558d82c64e7cba23bff7600ae9af5ef435cd62403c70e529cf7558","payload":{"connection_id":"0f4979d6978d463e9660b042fdcf555f","event_at":"2026-07-27T04:34:38.408000Z","event_type":"price_change","frame_hash":"a5b3e2847c9cbc7e0cb304ee3aeda8007290f92d55d57027100197a2f9942d08","frame_index":0,"kind":"data","monotonic_ns":228861718614875,"payload":{"event_type":"price_change","market":"0xeb66215f2e9faa6449e30a02bab5b8ed7b79a38bf961f6b24d0073c9c2419250","price_changes":[{"asset_id":"60386828328910021732068595344565885737045900010034836345809386672230885527307","best_ask":"0.77","best_bid":"0.76","hash":"8f2c042b56755fc14a20e3b3633b2a013a5639d3","price":"0.76","side":"BUY","size":"25.24"},{"asset_id":"69697746896130839564035629862476347944307040470122503199396727085502753297492","best_ask":"0.24","best_bid":"0.23","hash":"69ada685b37584a25ea5616ea9f320d9a8b3b320","price":"0.24","side":"SELL","size":"25.24"}],"timestamp":"1785126878408"},"payload_hash":"0b2b2f7785affba23d8813e63a6c7396505fb733a199cfb662ce2824193fc376","raw_frame":"{\"market\":\"0xeb66215f2e9faa6449e30a02bab5b8ed7b79a38bf961f6b24d0073c9c2419250\", \"price_changes\":[{\"asset_id\":\"60386828328910021732068595344565885737045900010034836345809386672230885527307\", \"price\":\"0.76\", \"size\":\"25.24\", \"side\":\"BUY\", \"hash\":\"8f2c042b56755fc14a20e3b3633b2a013a5639d3\", \"best_bid\":\"0.76\", \"best_ask\":\"0.77\"}, {\"asset_id\":\"69697746896130839564035629862476347944307040470122503199396727085502753297492\", \"price\":\"0.24\", \"size\":\"25.24\", \"side\":\"SELL\", \"hash\":\"69ada685b37584a25ea5616ea9f320d9a8b3b320\", \"best_bid\":\"0.23\", \"best_ask\":\"0.24\"}], \"timestamp\":\"1785126878408\", \"event_type\":\"price_change\"}","received_at":"2026-07-27T04:34:38.451193Z","schema_version":"clob-market-ws.price_change.v1","sequence":null,"server_hash":null,"server_timestamp":"1785126878408","session_id":"e9443c7415a0419799bee9cfbb1a9e4d","source":"clob_market_ws"},"received_at":"2026-07-27T04:34:38.451193Z","record_id":"2d45870a1f3f95de92ce9914606a702556411acfad21d5f8f680ce6fa9b5d3dc","schema_fingerprint":"4aa3821a28b0b7c2400bc59aba4bcc0a76e971dadd19610d3ad38c768e124dc7","schema_version":"edge-lab-recorder.raw.v1","sequence":null,"source":"clob_market_ws"}
{"event_at":"2026-07-27T04:34:38.408000Z","event_fingerprint":"3b7630aaef5fa0a22e6c8b29c047249a0d86cbe8c8f46e7c4831947c806ca064","payload":{"connection_id":"0f4979d6978d463e9660b042fdcf555f","event_at":"2026-07-27T04:34:38.408000Z","event_type":"price_change","frame_hash":"f22d23db43220e401e14721aa9b90afa298b439b5acd84c524d02a0305d6d0cc","frame_index":0,"kind":"data","monotonic_ns":228861720429458,"payload":{"event_type":"price_change","market":"0xeb66215f2e9faa6449e30a02bab5b8ed7b79a38bf961f6b24d0073c9c2419250","price_changes":[{"asset_id":"60386828328910021732068595344565885737045900010034836345809386672230885527307","best_ask":"0.77","best_bid":"0.76","hash":"e82fc3d83395c038d31c43ae3ec695943300e675","price":"0.8","side":"SELL","size":"52.64"},{"asset_id":"69697746896130839564035629862476347944307040470122503199396727085502753297492","best_ask":"0.24","best_bid":"0.23","hash":"16d6a4ca402328512b656e37cbe9187e98aea6d3","price":"0.2","side":"BUY","size":"52.64"}],"timestamp":"1785126878408"},"payload_hash":"8dd161a3c32e65f14e41bac92aeaab66f8d855467d8c330cdc13c796d06e5237","raw_frame":"{\"market\":\"0xeb66215f2e9faa6449e30a02bab5b8ed7b79a38bf961f6b24d0073c9c2419250\", \"price_changes\":[{\"asset_id\":\"60386828328910021732068595344565885737045900010034836345809386672230885527307\", \"price\":\"0.8\", \"size\":\"52.64\", \"side\":\"SELL\", \"hash\":\"e82fc3d83395c038d31c43ae3ec695943300e675\", \"best_bid\":\"0.76\", \"best_ask\":\"0.77\"}, {\"asset_id\":\"69697746896130839564035629862476347944307040470122503199396727085502753297492\", \"price\":\"0.2\", \"size\":\"52.64\", \"side\":\"BUY\", \"hash\":\"16d6a4ca402328512b656e37cbe9187e98aea6d3\", \"best_bid\":\"0.23\", \"best_ask\":\"0.24\"}], \"timestamp\":\"1785126878408\", \"event_type\":\"price_change\"}","received_at":"2026-07-27T04:34:38.453003Z","schema_version":"clob-market-ws.price_change.v1","sequence":null,"server_hash":null,"server_timestamp":"1785126878408","session_id":"e9443c7415a0419799bee9cfbb1a9e4d","source":"clob_market_ws"},"received_at":"2026-07-27T04:34:38.453003Z","record_id":"65a299645173a2417dc1ea4e6f2707c1b99c42da24733091f7d1d59dc70df752","schema_fingerprint":"4aa3821a28b0b7c2400bc59aba4bcc0a76e971dadd19610d3ad38c768e124dc7","schema_version":"edge-lab-recorder.raw.v1","sequence":null,"source":"clob_market_ws"}
{"event_at":"2026-07-27T04:34:38.409000Z","event_fingerprint":"f47b666095749a9692c917ec70fad17700a6e790cc93c8dc7cd61c706d8b9d85","payload":{"connection_id":"0f4979d6978d463e9660b042fdcf555f","event_at":"2026-07-27T04:34:38.409000Z","event_type":"price_change","frame_hash":"43cf81d9334e9a40e0651b38f12b5e35b920c92080252d9b815012bb3c3d2df5","frame_index":0,"kind":"data","monotonic_ns":228861721932416,"payload":{"event_type":"price_change","market":"0xeb66215f2e9faa6449e30a02bab5b8ed7b79a38bf961f6b24d0073c9c2419250","price_changes":[{"asset_id":"60386828328910021732068595344565885737045900010034836345809386672230885527307","best_ask":"0.77","best_bid":"0.76","hash":"396b4daccb8f903b843e21267c28c4471690c09d","price":"0.73","side":"BUY","size":"50"},{"asset_id":"69697746896130839564035629862476347944307040470122503199396727085502753297492","best_ask":"0.24","best_bid":"0.23","hash":"8fb486d6109fc972e8fadd93b8fffe3994d2ada6","price":"0.27","side":"SELL","size":"50"}],"timestamp":"1785126878409"},"payload_hash":"54ea6e4798f448b9d45433d90feb82428701375cc3051bb772f6801e6ef0a33b","raw_frame":"{\"market\":\"0xeb66215f2e9faa6449e30a02bab5b8ed7b79a38bf961f6b24d0073c9c2419250\", \"price_changes\":[{\"asset_id\":\"60386828328910021732068595344565885737045900010034836345809386672230885527307\", \"price\":\"0.73\", \"size\":\"50\", \"side\":\"BUY\", \"hash\":\"396b4daccb8f903b843e21267c28c4471690c09d\", \"best_bid\":\"0.76\", \"best_ask\":\"0.77\"}, {\"asset_id\":\"69697746896130839564035629862476347944307040470122503199396727085502753297492\", \"price\":\"0.27\", \"size\":\"50\", \"side\":\"SELL\", \"hash\":\"8fb486d6109fc972e8fadd93b8fffe3994d2ada6\", \"best_bid\":\"0.23\", \"best_ask\":\"0.24\"}], \"timestamp\":\"1785126878409\", \"event_type\":\"price_change\"}","received_at":"2026-07-27T04:34:38.454514Z","schema_version":"clob-market-ws.price_change.v1","sequence":null,"server_hash":null,"server_timestamp":"1785126878409","session_id":"e9443c7415a0419799bee9cfbb1a9e4d","source":"clob_market_ws"},"received_at":"2026-07-27T04:34:38.454514Z","record_id":"1f5a9f2ba7f5164cfdab43ccc4b461c1000df79bb718b2e447ff7a29a750a196","schema_fingerprint":"4aa3821a28b0b7c2400bc59aba4bcc0a76e971dadd19610d3ad38c768e124dc7","schema_version":"edge-lab-recorder.raw.v1","sequence":null,"source":"clob_market_ws"}
{"event_at":"2026-07-27T04:34:38.411000Z","event_fingerprint":"3d18c761e624d67c59c5683bdc090cac061dc8ca41d0ef82b71a66cc7a65fd68","payload":{"connection_id":"0f4979d6978d463e9660b042fdcf555f","event_at":"2026-07-27T04:34:38.411000Z","event_type":"price_change","frame_hash":"1bb8c61b3fb7c91ca015319e24e79d0c65f296f1715f9a006c04451a289dbb3f","frame_index":0,"kind":"data","monotonic_ns":228861722685916,"payload":{"event_type":"price_change","market":"0xeb66215f2e9faa6449e30a02bab5b8ed7b79a38bf961f6b24d0073c9c2419250","price_changes":[{"asset_id":"69697746896130839564035629862476347944307040470122503199396727085502753297492","best_ask":"0.24","best_bid":"0.23","hash":"c396e7516ef6d6c562e2e44a08cffa207e3956a2","price":"0.16","side":"BUY","size":"530.63"},{"asset_id":"60386828328910021732068595344565885737045900010034836345809386672230885527307","best_ask":"0.77","best_bid":"0.76","hash":"f4be83bc62124bd79ca223cbe4676f91b8d06a64","price":"0.84","side":"SELL","size":"530.63"}],"timestamp":"1785126878411"},"payload_hash":"1e53f58fe8ae72377956ad480aa8f7522b31fc9a8ea30729ad2c4b8a145f12c0","raw_frame":"{\"market\":\"0xeb66215f2e9faa6449e30a02bab5b8ed7b79a38bf961f6b24d0073c9c2419250\", \"price_changes\":[{\"asset_id\":\"69697746896130839564035629862476347944307040470122503199396727085502753297492\", \"price\":\"0.16\", \"size\":\"530.63\", \"side\":\"BUY\", \"hash\":\"c396e7516ef6d6c562e2e44a08cffa207e3956a2\", \"best_bid\":\"0.23\", \"best_ask\":\"0.24\"}, {\"asset_id\":\"60386828328910021732068595344565885737045900010034836345809386672230885527307\", \"price\":\"0.84\", \"size\":\"530.63\", \"side\":\"SELL\", \"hash\":\"f4be83bc62124bd79ca223cbe4676f91b8d06a64\", \"best_bid\":\"0.76\", \"best_ask\":\"0.77\"}], \"timestamp\":\"1785126878411\", \"event_type\":\"price_change\"}","received_at":"2026-07-27T04:34:38.455268Z","schema_version":"clob-market-ws.price_change.v1","sequence":null,"server_hash":null,"server_timestamp":"1785126878411","session_id":"e9443c7415a0419799bee9cfbb1a9e4d","source":"clob_market_ws"},"received_at":"2026-07-27T04:34:38.455268Z","record_id":"129424e92646ae1897cb434175124de9af5270c8733599d536b3582620f5e532","schema_fingerprint":"4aa3821a28b0b7c2400bc59aba4bcc0a76e971dadd19610d3ad38c768e124dc7","schema_version":"edge-lab-recorder.raw.v1","sequence":null,"source":"clob_market_ws"}
{"event_at":"2026-07-27T04:34:38.412000Z","event_fingerprint":"1e03297b5146f490ccc5a44b8f5cbce5f07f2bdba3c91f1aa6dcd85822d7c319","payload":{"connection_id":"0f4979d6978d463e9660b042fdcf555f","event_at":"2026-07-27T04:34:38.412000Z","event_type":"price_change","frame_hash":"c66d4ad349463755da7028d35ed8c6b8b6a06b896ec202da16aaaa40937f374c","frame_index":0,"kind":"data","monotonic_ns":228861724048125,"payload":{"event_type":"price_change","market":"0xeb66215f2e9faa6449e30a02bab5b8ed7b79a38bf961f6b24d0073c9c2419250","price_changes":[{"asset_id":"69697746896130839564035629862476347944307040470122503199396727085502753297492","best_ask":"0.24","best_bid":"0.23","hash":"ed683e78d39632cfe4aaae8fe2a29ccaa6de1d83","price":"0.17","side":"BUY","size":"263.26"},{"asset_id":"60386828328910021732068595344565885737045900010034836345809386672230885527307","best_ask":"0.77","best_bid":"0.76","hash":"bf5b036b75a8490a84cb07b0491da3b2cd40940c","price":"0.83","side":"SELL","size":"263.26"}],"timestamp":"1785126878412"},"payload_hash":"6077a5d67b82ed2dfa708b3e7eacfc827457d582b793803b2229fa372fee4e54","raw_frame":"{\"market\":\"0xeb66215f2e9faa6449e30a02bab5b8ed7b79a38bf961f6b24d0073c9c2419250\", \"price_changes\":[{\"asset_id\":\"69697746896130839564035629862476347944307040470122503199396727085502753297492\", \"price\":\"0.17\", \"size\":\"263.26\", \"side\":\"BUY\", \"hash\":\"ed683e78d39632cfe4aaae8fe2a29ccaa6de1d83\", \"best_bid\":\"0.23\", \"best_ask\":\"0.24\"}, {\"asset_id\":\"60386828328910021732068595344565885737045900010034836345809386672230885527307\", \"price\":\"0.83\", \"size\":\"263.26\", \"side\":\"SELL\", \"hash\":\"bf5b036b75a8490a84cb07b0491da3b2cd40940c\", \"best_bid\":\"0.76\", \"best_ask\":\"0.77\"}], \"timestamp\":\"1785126878412\", \"event_type\":\"price_change\"}","received_at":"2026-07-27T04:34:38.456625Z","schema_version":"clob-market-ws.price_change.v1","sequence":null,"server_hash":null,"server_timestamp":"1785126878412","session_id":"e9443c7415a0419799bee9cfbb1a9e4d","source":"clob_market_ws"},"received_at":"2026-07-27T04:34:38.456625Z","record_id":"5d23ee37555e0c586a6d58561e6c6890d13d46480ad82adf5bc0fb754988256f","schema_fingerprint":"4aa3821a28b0b7c2400bc59aba4bcc0a76e971dadd19610d3ad38c768e124dc7","schema_version":"edge-lab-recorder.raw.v1","sequence":null,"source":"clob_market_ws"}
{"event_at":"2026-07-27T04:34:38.412000Z","event_fingerprint":"857e860c1b5bcc573e8a5b82c1fdee3df1dff4210f28b4108dfc81debafa84a5","payload":{"connection_id":"0f4979d6978d463e9660b042fdcf555f","event_at":"2026-07-27T04:34:38.412000Z","event_type":"price_change","frame_hash":"6da654b245c333602c470e0101f87ae852023e4cdf0d4c3e13607dbf208234dc","frame_index":0,"kind":"data","monotonic_ns":228861725561458,"payload":{"event_type":"price_change","market":"0xeb66215f2e9faa6449e30a02bab5b8ed7b79a38bf961f6b24d0073c9c2419250","price_changes":[{"asset_id":"69697746896130839564035629862476347944307040470122503199396727085502753297492","best_ask":"0.24","best_bid":"0.23","hash":"693d17b503fa9f2f572d442a5eb6ab92fb462f93","price":"0.21","side":"BUY","size":"67.4"},{"asset_id":"60386828328910021732068595344565885737045900010034836345809386672230885527307","best_ask":"0.77","best_bid":"0.76","hash":"20fc7fd88579e57a3ca35c2200e143bb70627c4d","price":"0.79","side":"SELL","size":"67.4"}],"timestamp":"1785126878412"},"payload_hash":"12969134250a7fbd3f91839d3ae09483e1a8f7c4c548c858cf7857311c278774","raw_frame":"{\"market\":\"0xeb66215f2e9faa6449e30a02bab5b8ed7b79a38bf961f6b24d0073c9c2419250\", \"price_changes\":[{\"asset_id\":\"69697746896130839564035629862476347944307040470122503199396727085502753297492\", \"price\":\"0.21\", \"size\":\"67.4\", \"side\":\"BUY\", \"hash\":\"693d17b503fa9f2f572d442a5eb6ab92fb462f93\", \"best_bid\":\"0.23\", \"best_ask\":\"0.24\"}, {\"asset_id\":\"60386828328910021732068595344565885737045900010034836345809386672230885527307\", \"price\":\"0.79\", \"size\":\"67.4\", \"side\":\"SELL\", \"hash\":\"20fc7fd88579e57a3ca35c2200e143bb70627c4d\", \"best_bid\":\"0.76\", \"best_ask\":\"0.77\"}], \"timestamp\":\"1785126878412\", \"event_type\":\"price_change\"}","received_at":"2026-07-27T04:34:38.458137Z","schema_version":"clob-market-ws.price_change.v1","sequence":null,"server_hash":null,"server_timestamp":"1785126878412","session_id":"e9443c7415a0419799bee9cfbb1a9e4d","source":"clob_market_ws"},"received_at":"2026-07-27T04:34:38.458137Z","record_id":"604e8edde65c7ac0ca04ce5b7e359c5a7f6872dc71e378f4f7087c8db9667c9d","schema_fingerprint":"4aa3821a28b0b7c2400bc59aba4bcc0a76e971dadd19610d3ad38c768e124dc7","schema_version":"edge-lab-recorder.raw.v1","sequence":null,"source":"clob_market_ws"}
{"event_at":"2026-07-27T04:34:38.413000Z","event_fingerprint":"6afe5cdb3eb2ee90eb62a8c9d7398bbec963f0c177637dce4685ef766d00687e","payload":{"connection_id":"0f4979d6978d463e9660b042fdcf555f","event_at":"2026-07-27T04:34:38.413000Z","event_type":"price_change","frame_hash":"06b709b7a944ebb3b1c459566ab0a0e0b715edfe2c914721ea8ab5872d533d6e","frame_index":0,"kind":"data","monotonic_ns":228861727148875,"payload":{"event_type":"price_change","market":"0xeb66215f2e9faa6449e30a02bab5b8ed7b79a38bf961f6b24d0073c9c2419250","price_changes":[{"asset_id":"69697746896130839564035629862476347944307040470122503199396727085502753297492","best_ask":"0.24","best_bid":"0.23","hash":"5b7c5a21f5d7b6cf4f5b23cf69f30e2333677de8","price":"0.17","side":"BUY","size":"282.77"},{"asset_id":"60386828328910021732068595344565885737045900010034836345809386672230885527307","best_ask":"0.77","best_bid":"0.76","hash":"8a98e4d349ea42288d88b8f5402f0e4f9de6cfb6","price":"0.83","side":"SELL","size":"282.77"}],"timestamp":"1785126878413"},"payload_hash":"b5e8ad66a843863401f76c7301b2813eb9e72d757cad1a261beee4f9fc77cc71","raw_frame":"{\"market\":\"0xeb66215f2e9faa6449e30a02bab5b8ed7b79a38bf961f6b24d0073c9c2419250\", \"price_changes\":[{\"asset_id\":\"69697746896130839564035629862476347944307040470122503199396727085502753297492\", \"price\":\"0.17\", \"size\":\"282.77\", \"side\":\"BUY\", \"hash\":\"5b7c5a21f5d7b6cf4f5b23cf69f30e2333677de8\", \"best_bid\":\"0.23\", \"best_ask\":\"0.24\"}, {\"asset_id\":\"60386828328910021732068595344565885737045900010034836345809386672230885527307\", \"price\":\"0.83\", \"size\":\"282.77\", \"side\":\"SELL\", \"hash\":\"8a98e4d349ea42288d88b8f5402f0e4f9de6cfb6\", \"best_bid\":\"0.76\", \"best_ask\":\"0.77\"}], \"timestamp\":\"1785126878413\", \"event_type\":\"price_change\"}","received_at":"2026-07-27T04:34:38.459726Z","schema_version":"clob-market-ws.price_change.v1","sequence":null,"server_hash":null,"server_timestamp":"1785126878413","session_id":"e9443c7415a0419799bee9cfbb1a9e4d","source":"clob_market_ws"},"received_at":"2026-07-27T04:34:38.459726Z","record_id":"c1a28ccfb300205f205d49400ed55829cc13bf4056f524d45a2303c30536e2f7","schema_fingerprint":"4aa3821a28b0b7c2400bc59aba4bcc0a76e971dadd19610d3ad38c768e124dc7","schema_version":"edge-lab-recorder.raw.v1","sequence":null,"source":"clob_market_ws"}
{"event_at":"2026-07-27T04:34:38.414000Z","event_fingerprint":"e134390ad2083d74d86c7591bcdcbaa1063a230ae28a1dcba3e6f2a7aa651768","payload":{"connection_id":"0f4979d6978d463e9660b042fdcf555f","event_at":"2026-07-27T04:34:38.414000Z","event_type":"price_change","frame_hash":"215f945c834826334663ca0e0625898db46dcd918d7d3a21f85a2ff3269090d8","frame_index":0,"kind":"data","monotonic_ns":228861728636416,"payload":{"event_type":"price_change","market":"0xeb66215f2e9faa6449e30a02bab5b8ed7b79a38bf961f6b24d0073c9c2419250","price_changes":[{"asset_id":"69697746896130839564035629862476347944307040470122503199396727085502753297492","best_ask":"0.24","best_bid":"0.23","hash":"75fe68fcd347130aa631544af93667191c5ad0e8","price":"0.17","side":"BUY","size":"87.77"},{"asset_id":"60386828328910021732068595344565885737045900010034836345809386672230885527307","best_ask":"0.77","best_bid":"0.76","hash":"dd147f19f0ca5bbe4b6b58dfc44e07ad16728571","price":"0.83","side":"SELL","size":"87.77"}],"timestamp":"1785126878414"},"payload_hash":"a29b98a2221041e5d05fa1028ae5026cd68c0cfa2b6cc7f339b2f08178c73e5d","raw_frame":"{\"market\":\"0xeb66215f2e9faa6449e30a02bab5b8ed7b79a38bf961f6b24d0073c9c2419250\", \"price_changes\":[{\"asset_id\":\"69697746896130839564035629862476347944307040470122503199396727085502753297492\", \"price\":\"0.17\", \"size\":\"87.77\", \"side\":\"BUY\", \"hash\":\"75fe68fcd347130aa631544af93667191c5ad0e8\", \"best_bid\":\"0.23\", \"best_ask\":\"0.24\"}, {\"asset_id\":\"60386828328910021732068595344565885737045900010034836345809386672230885527307\", \"price\":\"0.83\", \"size\":\"87.77\", \"side\":\"SELL\", \"hash\":\"dd147f19f0ca5bbe4b6b58dfc44e07ad16728571\", \"best_bid\":\"0.76\", \"best_ask\":\"0.77\"}], \"timestamp\":\"1785126878414\", \"event_type\":\"price_change\"}","received_at":"2026-07-27T04:34:38.461214Z","schema_version":"clob-market-ws.price_change.v1","sequence":null,"server_hash":null,"server_timestamp":"1785126878414","session_id":"e9443c7415a0419799bee9cfbb1a9e4d","source":"clob_market_ws"},"received_at":"2026-07-27T04:34:38.461214Z","record_id":"6bd148d9ccce4dcf125c88f278c03491fa7f7711f6f7f9b3698ae031bdc46071","schema_fingerprint":"4aa3821a28b0b7c2400bc59aba4bcc0a76e971dadd19610d3ad38c768e124dc7","schema_version":"edge-lab-recorder.raw.v1","sequence":null,"source":"clob_market_ws"}
{"event_at":"2026-07-27T04:34:38.414000Z","event_fingerprint":"ed13b5310be1d42b54af5c31b1f86c0e695005df71c7605e5022f45c366e48b8","payload":{"connection_id":"0f4979d6978d463e9660b042fdcf555f","event_at":"2026-07-27T04:34:38.414000Z","event_type":"price_change","frame_hash":"3fc25265eeb404c82cd2a96f8c823541c29ae408c986781d7a2ffc65482bcc0d","frame_index":0,"kind":"data","monotonic_ns":228861730123000,"payload":{"event_type":"price_change","market":"0xeb66215f2e9faa6449e30a02bab5b8ed7b79a38bf961f6b24d0073c9c2419250","price_changes":[{"asset_id":"60386828328910021732068595344565885737045900010034836345809386672230885527307","best_ask":"0.77","best_bid":"0.76","hash":"ef212e14f690bf82d4a6dcc089f0f16c91567146","price":"0.02","side":"BUY","size":"733.1"},{"asset_id":"69697746896130839564035629862476347944307040470122503199396727085502753297492","best_ask":"0.24","best_bid":"0.23","hash":"f39594f30d0fb689c75dcc380b20c0f6679a19ea","price":"0.98","side":"SELL","size":"733.1"}],"timestamp":"1785126878414"},"payload_hash":"193cf29ede3e6af3d7e86a7c194ec9a65fb1670d101114e4691faab36c0e23a8","raw_frame":"{\"market\":\"0xeb66215f2e9faa6449e30a02bab5b8ed7b79a38bf961f6b24d0073c9c2419250\", \"price_changes\":[{\"asset_id\":\"60386828328910021732068595344565885737045900010034836345809386672230885527307\", \"price\":\"0.02\", \"size\":\"733.1\", \"side\":\"BUY\", \"hash\":\"ef212e14f690bf82d4a6dcc089f0f16c91567146\", \"best_bid\":\"0.76\", \"best_ask\":\"0.77\"}, {\"asset_id\":\"69697746896130839564035629862476347944307040470122503199396727085502753297492\", \"price\":\"0.98\", \"size\":\"733.1\", \"side\":\"SELL\", \"hash\":\"f39594f30d0fb689c75dcc380b20c0f6679a19ea\", \"best_bid\":\"0.23\", \"best_ask\":\"0.24\"}], \"timestamp\":\"1785126878414\", \"event_type\":\"price_change\"}","received_at":"2026-07-27T04:34:38.462701Z","schema_version":"clob-market-ws.price_change.v1","sequence":null,"server_hash":null,"server_timestamp":"1785126878414","session_id":"e9443c7415a0419799bee9cfbb1a9e4d","source":"clob_market_ws"},"received_at":"2026-07-27T04:34:38.462701Z","record_id":"9595c531c5d4818ccfd534bf4d3385d30f0809c18a773b51d818b87ecbceb694","schema_fingerprint":"4aa3821a28b0b7c2400bc59aba4bcc0a76e971dadd19610d3ad38c768e124dc7","schema_version":"edge-lab-recorder.raw.v1","sequence":null,"source":"clob_market_ws"}
{"event_at":"2026-07-27T04:34:38.414000Z","event_fingerprint":"20e2efe8dbc609e93da10db91b133b8ed4ebaaffe7a698d4bb26064ff61431f8","payload":{"connection_id":"0f4979d6978d463e9660b042fdcf555f","event_at":"2026-07-27T04:34:38.414000Z","event_type":"price_change","frame_hash":"52c3799065dbd8fee4a85df0c24d0cb6b12d3b839f85563fb175c14e1b169687","frame_index":0,"kind":"data","monotonic_ns":228861731600083,"payload":{"event_type":"price_change","market":"0xeb66215f2e9faa6449e30a02bab5b8ed7b79a38bf961f6b24d0073c9c2419250","price_changes":[{"asset_id":"60386828328910021732068595344565885737045900010034836345809386672230885527307","best_ask":"0.77","best_bid":"0.76","hash":"d88abdac346833520d2174a08b098d4f5631778a","price":"0.72","side":"BUY","size":"63.99"},{"asset_id":"69697746896130839564035629862476347944307040470122503199396727085502753297492","best_ask":"0.24","best_bid":"0.23","hash":"2e3e201f4859f76135804a032f137fea8160da38","price":"0.28","side":"SELL","size":"63.99"}],"timestamp":"1785126878414"},"payload_hash":"f4d85f6afb3f59914340c6e8e5abe4b12d5feec341bd79fc22e4814843d18abd","raw_frame":"{\"market\":\"0xeb66215f2e9faa6449e30a02bab5b8ed7b79a38bf961f6b24d0073c9c2419250\", \"price_changes\":[{\"asset_id\":\"60386828328910021732068595344565885737045900010034836345809386672230885527307\", \"price\":\"0.72\", \"size\":\"63.99\", \"side\":\"BUY\", \"hash\":\"d88abdac346833520d2174a08b098d4f5631778a\", \"best_bid\":\"0.76\", \"best_ask\":\"0.77\"}, {\"asset_id\":\"69697746896130839564035629862476347944307040470122503199396727085502753297492\", \"price\":\"0.28\", \"size\":\"63.99\", \"side\":\"SELL\", \"hash\":\"2e3e201f4859f76135804a032f137fea8160da38\", \"best_bid\":\"0.23\", \"best_ask\":\"0.24\"}], \"timestamp\":\"1785126878414\", \"event_type\":\"price_change\"}","received_at":"2026-07-27T04:34:38.464179Z","schema_version":"clob-market-ws.price_change.v1","sequence":null,"server_hash":null,"server_timestamp":"1785126878414","session_id":"e9443c7415a0419799bee9cfbb1a9e4d","source":"clob_market_ws"},"received_at":"2026-07-27T04:34:38.464179Z","record_id":"2afd87fec2d73a24fee83218cd8cb6bed2e36e002406977cd94aea7525c26023","schema_fingerprint":"4aa3821a28b0b7c2400bc59aba4bcc0a76e971dadd19610d3ad38c768e124dc7","schema_version":"edge-lab-recorder.raw.v1","sequence":null,"source":"clob_market_ws"}
{"event_at":"2026-07-27T04:34:38.415000Z","event_fingerprint":"dd50fc2ebb78eecdab3fbc4e791b17e97a4e0c8fff47a37209d4a3dcf397a507","payload":{"connection_id":"0f4979d6978d463e9660b042fdcf555f","event_at":"2026-07-27T04:34:38.415000Z","event_type":"price_change","frame_hash":"384c671dff13dd683c08353cecd0211bfe9c23a0d61efa247d923f64be7af581","frame_index":0,"kind":"data","monotonic_ns":228861733041958,"payload":{"event_type":"price_change","market":"0xeb66215f2e9faa6449e30a02bab5b8ed7b79a38bf961f6b24d0073c9c2419250","price_changes":[{"asset_id":"60386828328910021732068595344565885737045900010034836345809386672230885527307","best_ask":"0.77","best_bid":"0.76","hash":"520c7a9a30a3579351d13a4db121460419670fda","price":"0.73","side":"BUY","size":"64.66"},{"asset_id":"69697746896130839564035629862476347944307040470122503199396727085502753297492","best_ask":"0.24","best_bid":"0.23","hash":"1f9f17f3a7baae08d41ff198d5260f8bdedc5f70","price":"0.27","side":"SELL","size":"64.66"}],"timestamp":"1785126878415"},"payload_hash":"9331ed29bc1325eddf3d63c499956b63682f8e527dc400c5ae5fab6e2d888f2c","raw_frame":"{\"market\":\"0xeb66215f2e9faa6449e30a02bab5b8ed7b79a38bf961f6b24d0073c9c2419250\", \"price_changes\":[{\"asset_id\":\"60386828328910021732068595344565885737045900010034836345809386672230885527307\", \"price\":\"0.73\", \"size\":\"64.66\", \"side\":\"BUY\", \"hash\":\"520c7a9a30a3579351d13a4db121460419670fda\", \"best_bid\":\"0.76\", \"best_ask\":\"0.77\"}, {\"asset_id\":\"69697746896130839564035629862476347944307040470122503199396727085502753297492\", \"price\":\"0.27\", \"size\":\"64.66\", \"side\":\"SELL\", \"hash\":\"1f9f17f3a7baae08d41ff198d5260f8bdedc5f70\", \"best_bid\":\"0.23\", \"best_ask\":\"0.24\"}], \"timestamp\":\"1785126878415\", \"event_type\":\"price_change\"}","received_at":"2026-07-27T04:34:38.465620Z","schema_version":"clob-market-ws.price_change.v1","sequence":null,"server_hash":null,"server_timestamp":"1785126878415","session_id":"e9443c7415a0419799bee9cfbb1a9e4d","source":"clob_market_ws"},"received_at":"2026-07-27T04:34:38.465620Z","record_id":"61fd28cd0f01a3bc85e1302406f5066aa6a6239f0c3add2a563da264a58d8005","schema_fingerprint":"4aa3821a28b0b7c2400bc59aba4bcc0a76e971dadd19610d3ad38c768e124dc7","schema_version":"edge-lab-recorder.raw.v1","sequence":null,"source":"clob_market_ws"}
{"event_at":"2026-07-27T04:34:38.416000Z","event_fingerprint":"7d0a131ac24ff1fd6c57113ec0ebeb9a5eb974ff64ac24bdd1a0488d72d2ee9c","payload":{"connection_id":"0f4979d6978d463e9660b042fdcf555f","event_at":"2026-07-27T04:34:38.416000Z","event_type":"price_change","frame_hash":"d7beda3b8fd5153b807ce4519834225f23a3d2b5fe605d670753fb6bc1fbf89a","frame_index":0,"kind":"data","monotonic_ns":228861734493375,"payload":{"event_type":"price_change","market":"0xeb66215f2e9faa6449e30a02bab5b8ed7b79a38bf961f6b24d0073c9c2419250","price_changes":[{"asset_id":"60386828328910021732068595344565885737045900010034836345809386672230885527307","best_ask":"0.77","best_bid":"0.76","hash":"21c19311a3e8ddffd8c633dac1f63efbebdabff8","price":"0.74","side":"BUY","size":"7"},{"asset_id":"69697746896130839564035629862476347944307040470122503199396727085502753297492","best_ask":"0.24","best_bid":"0.23","hash":"1836cfa5cbca815d3262392c498e51a8f9a3fab8","price":"0.26","side":"SELL","size":"7"}],"timestamp":"1785126878416"},"payload_hash":"2c0d0c3659b80db922cc901c0332ca47da3d01929b50da4ad58d659e2ee04867","raw_frame":"{\"market\":\"0xeb66215f2e9faa6449e30a02bab5b8ed7b79a38bf961f6b24d0073c9c2419250\", \"price_changes\":[{\"asset_id\":\"60386828328910021732068595344565885737045900010034836345809386672230885527307\", \"price\":\"0.74\", \"size\":\"7\", \"side\":\"BUY\", \"hash\":\"21c19311a3e8ddffd8c633dac1f63efbebdabff8\", \"best_bid\":\"0.76\", \"best_ask\":\"0.77\"}, {\"asset_id\":\"69697746896130839564035629862476347944307040470122503199396727085502753297492\", \"price\":\"0.26\", \"size\":\"7\", \"side\":\"SELL\", \"hash\":\"1836cfa5cbca815d3262392c498e51a8f9a3fab8\", \"best_bid\":\"0.23\", \"best_ask\":\"0.24\"}], \"timestamp\":\"1785126878416\", \"event_type\":\"price_change\"}","received_at":"2026-07-27T04:34:38.467072Z","schema_version":"clob-market-ws.price_change.v1","sequence":null,"server_hash":null,"server_timestamp":"1785126878416","session_id":"e9443c7415a0419799bee9cfbb1a9e4d","source":"clob_market_ws"},"received_at":"2026-07-27T04:34:38.467072Z","record_id":"dce6c8ab37840881b495fc3d1364eef21331fbdff6f36698ae87b20b46db8d46","schema_fingerprint":"4aa3821a28b0b7c2400bc59aba4bcc0a76e971dadd19610d3ad38c768e124dc7","schema_version":"edge-lab-recorder.raw.v1","sequence":null,"source":"clob_market_ws"}
{"event_at":"2026-07-27T04:34:38.422000Z","event_fingerprint":"78bea362c0b23fa974470bb0985a3b939154f4cad73210a87e595b24f4fea6fe","payload":{"connection_id":"0f4979d6978d463e9660b042fdcf555f","event_at":"2026-07-27T04:34:38.422000Z","event_type":"price_change","frame_hash":"7dfd81547ae46c8f39e3662c3e2349f7557f8fc8e2ee51bea16f92968d91e52e","frame_index":0,"kind":"data","monotonic_ns":228861736161375,"payload":{"event_type":"price_change","market":"0xeb66215f2e9faa6449e30a02bab5b8ed7b79a38bf961f6b24d0073c9c2419250","price_changes":[{"asset_id":"60386828328910021732068595344565885737045900010034836345809386672230885527307","best_ask":"0.77","best_bid":"0.76","hash":"d56029e3cbfbb9f429409ed2f7b78af61b80ecd4","price":"0.72","side":"BUY","size":"68.99"},{"asset_id":"69697746896130839564035629862476347944307040470122503199396727085502753297492","best_ask":"0.24","best_bid":"0.23","hash":"9a0c9e8ac04b5c6b302e15af5038bd6634e796d8","price":"0.28","side":"SELL","size":"68.99"}],"timestamp":"1785126878422"},"payload_hash":"fda40aed90673536a98d83290327fa89e8ae072cb3d1cb0bf829b930ede319b3","raw_frame":"{\"market\":\"0xeb66215f2e9faa6449e30a02bab5b8ed7b79a38bf961f6b24d0073c9c2419250\", \"price_changes\":[{\"asset_id\":\"60386828328910021732068595344565885737045900010034836345809386672230885527307\", \"price\":\"0.72\", \"size\":\"68.99\", \"side\":\"BUY\", \"hash\":\"d56029e3cbfbb9f429409ed2f7b78af61b80ecd4\", \"best_bid\":\"0.76\", \"best_ask\":\"0.77\"}, {\"asset_id\":\"69697746896130839564035629862476347944307040470122503199396727085502753297492\", \"price\":\"0.28\", \"size\":\"68.99\", \"side\":\"SELL\", \"hash\":\"9a0c9e8ac04b5c6b302e15af5038bd6634e796d8\", \"best_bid\":\"0.23\", \"best_ask\":\"0.24\"}], \"timestamp\":\"1785126878422\", \"event_type\":\"price_change\"}","received_at":"2026-07-27T04:34:38.468738Z","schema_version":"clob-market-ws.price_change.v1","sequence":null,"server_hash":null,"server_timestamp":"1785126878422","session_id":"e9443c7415a0419799bee9cfbb1a9e4d","source":"clob_market_ws"},"received_at":"2026-07-27T04:34:38.468738Z","record_id":"eb2c7be942f8695fe1205a89de29006b5a5570c036f1222cff494ddfce5f5931","schema_fingerprint":"4aa3821a28b0b7c2400bc59aba4bcc0a76e971dadd19610d3ad38c768e124dc7","schema_version":"edge-lab-recorder.raw.v1","sequence":null,"source":"clob_market_ws"}
{"event_at":"2026-07-27T04:34:38.424000Z","event_fingerprint":"ca6474918a4c18b009d25d7f08e6fd2c9f7f97defc2fcf2a9ce5248de2b44f73","payload":{"connection_id":"0f4979d6978d463e9660b042fdcf555f","event_at":"2026-07-27T04:34:38.424000Z","event_type":"price_change","frame_hash":"f43c7caf86a1da07d3d20982fab68afade03fc895cdacb5ca9c453d7334d02e3","frame_index":0,"kind":"data","monotonic_ns":228861737897625,"payload":{"event_type":"price_change","market":"0xeb66215f2e9faa6449e30a02bab5b8ed7b79a38bf961f6b24d0073c9c2419250","price_changes":[{"asset_id":"60386828328910021732068595344565885737045900010034836345809386672230885527307","best_ask":"0.77","best_bid":"0.76","hash":"d96677bc88241c000c328c6f5ff3f8e1760a8805","price":"0.77","side":"SELL","size":"50"},{"asset_id":"69697746896130839564035629862476347944307040470122503199396727085502753297492","best_ask":"0.24","best_bid":"0.23","hash":"2be44e3464fb42dde669cf0c5b96cc21a71b1439","price":"0.23","side":"BUY","size":"50"}],"timestamp":"1785126878424"},"payload_hash":"53b20e4a0bda6cc7e12ca1642a117fcaa640c667c5225cd486b37ac43abb3dd0","raw_frame":"{\"market\":\"0xeb66215f2e9faa6449e30a02bab5b8ed7b79a38bf961f6b24d0073c9c2419250\", \"price_changes\":[{\"asset_id\":\"60386828328910021732068595344565885737045900010034836345809386672230885527307\", \"price\":\"0.77\", \"size\":\"50\", \"side\":\"SELL\", \"hash\":\"d96677bc88241c000c328c6f5ff3f8e1760a8805\", \"best_bid\":\"0.76\", \"best_ask\":\"0.77\"}, {\"asset_id\":\"69697746896130839564035629862476347944307040470122503199396727085502753297492\", \"price\":\"0.23\", \"size\":\"50\", \"side\":\"BUY\", \"hash\":\"2be44e3464fb42dde669cf0c5b96cc21a71b1439\", \"best_bid\":\"0.23\", \"best_ask\":\"0.24\"}], \"timestamp\":\"1785126878424\", \"event_type\":\"price_change\"}","received_at":"2026-07-27T04:34:38.470476Z","schema_version":"clob-market-ws.price_change.v1","sequence":null,"server_hash":null,"server_timestamp":"1785126878424","session_id":"e9443c7415a0419799bee9cfbb1a9e4d","source":"clob_market_ws"},"received_at":"2026-07-27T04:34:38.470476Z","record_id":"851a23a9f58a955606f5d54877e412378535869930ac02d88cf19725edf2d2c1","schema_fingerprint":"4aa3821a28b0b7c2400bc59aba4bcc0a76e971dadd19610d3ad38c768e124dc7","schema_version":"edge-lab-recorder.raw.v1","sequence":null,"source":"clob_market_ws"}
{"event_at":"2026-07-27T04:34:38.432000Z","event_fingerprint":"6fcf41f89209d84e9c618faa6ee4efbdbb63f2b435d1bf86b20560e54b752b7b","payload":{"connection_id":"0f4979d6978d463e9660b042fdcf555f","event_at":"2026-07-27T04:34:38.432000Z","event_type":"price_change","frame_hash":"e9ef6dccfadfe879d5f811fc3e036e558a5146811251f394d6eb0fe2b62fdcb1","frame_index":0,"kind":"data","monotonic_ns":228861739485666,"payload":{"event_type":"price_change","market":"0xeb66215f2e9faa6449e30a02bab5b8ed7b79a38bf961f6b24d0073c9c2419250","price_changes":[{"asset_id":"60386828328910021732068595344565885737045900010034836345809386672230885527307","best_ask":"0.77","best_bid":"0.76","hash":"20405c090fc72715fbdd5f85dc26ec603951627c","price":"0.69","side":"BUY","size":"173"},{"asset_id":"69697746896130839564035629862476347944307040470122503199396727085502753297492","best_ask":"0.24","best_bid":"0.23","hash":"db344fa0ed68426cf97a15aecec571f63f73afae","price":"0.31","side":"SELL","size":"173"}],"timestamp":"1785126878432"},"payload_hash":"77e5fd0d7bc9fcec87a0034dfbc3c98df2a42ace823ac71196df2bf4e03b1fda","raw_frame":"{\"market\":\"0xeb66215f2e9faa6449e30a02bab5b8ed7b79a38bf961f6b24d0073c9c2419250\", \"price_changes\":[{\"asset_id\":\"60386828328910021732068595344565885737045900010034836345809386672230885527307\", \"price\":\"0.69\", \"size\":\"173\", \"side\":\"BUY\", \"hash\":\"20405c090fc72715fbdd5f85dc26ec603951627c\", \"best_bid\":\"0.76\", \"best_ask\":\"0.77\"}, {\"asset_id\":\"69697746896130839564035629862476347944307040470122503199396727085502753297492\", \"price\":\"0.31\", \"size\":\"173\", \"side\":\"SELL\", \"hash\":\"db344fa0ed68426cf97a15aecec571f63f73afae\", \"best_bid\":\"0.23\", \"best_ask\":\"0.24\"}], \"timestamp\":\"1785126878432\", \"event_type\":\"price_change\"}","received_at":"2026-07-27T04:34:38.472064Z","schema_version":"clob-market-ws.price_change.v1","sequence":null,"server_hash":null,"server_timestamp":"1785126878432","session_id":"e9443c7415a0419799bee9cfbb1a9e4d","source":"clob_market_ws"},"received_at":"2026-07-27T04:34:38.472064Z","record_id":"14b40be0fb5e0f6512d1e7878495101c3d402c4829dfe046fb569a2e702ad43c","schema_fingerprint":"4aa3821a28b0b7c2400bc59aba4bcc0a76e971dadd19610d3ad38c768e124dc7","schema_version":"edge-lab-recorder.raw.v1","sequence":null,"source":"clob_market_ws"}
{"event_at":"2026-07-27T04:34:38.441000Z","event_fingerprint":"497d623aec89f59dc248ac921830f88c3df40b05a9a486e8bd299502301667a0","payload":{"connection_id":"0f4979d6978d463e9660b042fdcf555f","event_at":"2026-07-27T04:34:38.441000Z","event_type":"price_change","frame_hash":"9d42407084bbb39f3d35fceaf20875648df52475630654224c717eeb87987db5","frame_index":0,"kind":"data","monotonic_ns":228861740949583,"payload":{"event_type":"price_change","market":"0xeb66215f2e9faa6449e30a02bab5b8ed7b79a38bf961f6b24d0073c9c2419250","price_changes":[{"asset_id":"60386828328910021732068595344565885737045900010034836345809386672230885527307","best_ask":"0.77","best_bid":"0.76","hash":"8527ed07baefdb1aaae778b5a57c6b0c0d3f0e66","price":"0.68","side":"BUY","size":"43"},{"asset_id":"69697746896130839564035629862476347944307040470122503199396727085502753297492","best_ask":"0.24","best_bid":"0.23","hash":"3d2a831ab58079aacc2c91bed09fc5e7dc988e3f","price":"0.32","side":"SELL","size":"43"}],"timestamp":"1785126878441"},"payload_hash":"d1857969368fda5009877eb5c97c852de1cd7d4ac044f85eb2115104cb390865","raw_frame":"{\"market\":\"0xeb66215f2e9faa6449e30a02bab5b8ed7b79a38bf961f6b24d0073c9c2419250\", \"price_changes\":[{\"asset_id\":\"60386828328910021732068595344565885737045900010034836345809386672230885527307\", \"price\":\"0.68\", \"size\":\"43\", \"side\":\"BUY\", \"hash\":\"8527ed07baefdb1aaae778b5a57c6b0c0d3f0e66\", \"best_bid\":\"0.76\", \"best_ask\":\"0.77\"}, {\"asset_id\":\"69697746896130839564035629862476347944307040470122503199396727085502753297492\", \"price\":\"0.32\", \"size\":\"43\", \"side\":\"SELL\", \"hash\":\"3d2a831ab58079aacc2c91bed09fc5e7dc988e3f\", \"best_bid\":\"0.23\", \"best_ask\":\"0.24\"}], \"timestamp\":\"1785126878441\", \"event_type\":\"price_change\"}","received_at":"2026-07-27T04:34:38.473527Z","schema_version":"clob-market-ws.price_change.v1","sequence":null,"server_hash":null,"server_timestamp":"1785126878441","session_id":"e9443c7415a0419799bee9cfbb1a9e4d","source":"clob_market_ws"},"received_at":"2026-07-27T04:34:38.473527Z","record_id":"daf7e1d0c31c9f2bf8de89fc44bb9a082f21d34214a01fb234ae859c2cfd4d53","schema_fingerprint":"4aa3821a28b0b7c2400bc59aba4bcc0a76e971dadd19610d3ad38c768e124dc7","schema_version":"edge-lab-recorder.raw.v1","sequence":null,"source":"clob_market_ws"}
{"event_at":"2026-07-27T04:34:38.442000Z","event_fingerprint":"f0f768cc50d566ad1a5040e625c8a0df390a4bf0d88937a6da466adf14892f04","payload":{"connection_id":"0f4979d6978d463e9660b042fdcf555f","event_at":"2026-07-27T04:34:38.442000Z","event_type":"price_change","frame_hash":"43838abf111596775c549809d8ca8311b3cfb3851a59195cd33fed781baf5b7d","frame_index":0,"kind":"data","monotonic_ns":228861742414958,"payload":{"event_type":"price_change","market":"0xeb66215f2e9faa6449e30a02bab5b8ed7b79a38bf961f6b24d0073c9c2419250","price_changes":[{"asset_id":"69697746896130839564035629862476347944307040470122503199396727085502753297492","best_ask":"0.24","best_bid":"0.23","hash":"5a3996739dae03406cc9d7331e1f574ece147fc4","price":"0.15","side":"BUY","size":"371.46"},{"asset_id":"60386828328910021732068595344565885737045900010034836345809386672230885527307","best_ask":"0.77","best_bid":"0.76","hash":"f55513ccc59cfcafdf6a88ae154922d9b9159ab1","price":"0.85","side":"SELL","size":"371.46"}],"timestamp":"1785126878442"},"payload_hash":"4285b1f25b4faac416842e3f19c929e28a1f05e1a8216cdcc0ddd0249ce5fa70","raw_frame":"{\"market\":\"0xeb66215f2e9faa6449e30a02bab5b8ed7b79a38bf961f6b24d0073c9c2419250\", \"price_changes\":[{\"asset_id\":\"69697746896130839564035629862476347944307040470122503199396727085502753297492\", \"price\":\"0.15\", \"size\":\"371.46\", \"side\":\"BUY\", \"hash\":\"5a3996739dae03406cc9d7331e1f574ece147fc4\", \"best_bid\":\"0.23\", \"best_ask\":\"0.24\"}, {\"asset_id\":\"60386828328910021732068595344565885737045900010034836345809386672230885527307\", \"price\":\"0.85\", \"size\":\"371.46\", \"side\":\"SELL\", \"hash\":\"f55513ccc59cfcafdf6a88ae154922d9b9159ab1\", \"best_bid\":\"0.76\", \"best_ask\":\"0.77\"}], \"timestamp\":\"1785126878442\", \"event_type\":\"price_change\"}","received_at":"2026-07-27T04:34:38.474994Z","schema_version":"clob-market-ws.price_change.v1","sequence":null,"server_hash":null,"server_timestamp":"1785126878442","session_id":"e9443c7415a0419799bee9cfbb1a9e4d","source":"clob_market_ws"},"received_at":"2026-07-27T04:34:38.474994Z","record_id":"abc6b39cd1ca91f9be492c1134aaf15c6b6301d66a294395082acbd92c76ad0e","schema_fingerprint":"4aa3821a28b0b7c2400bc59aba4bcc0a76e971dadd19610d3ad38c768e124dc7","schema_version":"edge-lab-recorder.raw.v1","sequence":null,"source":"clob_market_ws"}
{"event_at":"2026-07-27T04:34:38.459000Z","event_fingerprint":"a03c437a3e72f48a1992b4e3d2b9052bfa1cbb0ad3715d4e335c2e9d535a7904","payload":{"connection_id":"0f4979d6978d463e9660b042fdcf555f","event_at":"2026-07-27T04:34:38.459000Z","event_type":"price_change","frame_hash":"9f5e86400181337cbcb121051ec01a78a1c22ca554f70bb4b39a4a57f62984cf","frame_index":0,"kind":"data","monotonic_ns":228861743861625,"payload":{"event_type":"price_change","market":"0xeb66215f2e9faa6449e30a02bab5b8ed7b79a38bf961f6b24d0073c9c2419250","price_changes":[{"asset_id":"69697746896130839564035629862476347944307040470122503199396727085502753297492","best_ask":"0.24","best_bid":"0.23","hash":"1210647d8611e8de65252c51d7c3cd615cca4a0c","price":"0.21","side":"BUY","size":"72.4"},{"asset_id":"60386828328910021732068595344565885737045900010034836345809386672230885527307","best_ask":"0.77","best_bid":"0.76","hash":"706fd40e63c1baee7c1ba730e0e5fed9c2cacda1","price":"0.79","side":"SELL","size":"72.4"}],"timestamp":"1785126878459"},"payload_hash":"0ec46a43590fc002082592c973a73756a59aba5581b346d1b4b7b7a1746fc670","raw_frame":"{\"market\":\"0xeb66215f2e9faa6449e30a02bab5b8ed7b79a38bf961f6b24d0073c9c2419250\", \"price_changes\":[{\"asset_id\":\"69697746896130839564035629862476347944307040470122503199396727085502753297492\", \"price\":\"0.21\", \"size\":\"72.4\", \"side\":\"BUY\", \"hash\":\"1210647d8611e8de65252c51d7c3cd615cca4a0c\", \"best_bid\":\"0.23\", \"best_ask\":\"0.24\"}, {\"asset_id\":\"60386828328910021732068595344565885737045900010034836345809386672230885527307\", \"price\":\"0.79\", \"size\":\"72.4\", \"side\":\"SELL\", \"hash\":\"706fd40e63c1baee7c1ba730e0e5fed9c2cacda1\", \"best_bid\":\"0.76\", \"best_ask\":\"0.77\"}], \"timestamp\":\"1785126878459\", \"event_type\":\"price_change\"}","received_at":"2026-07-27T04:34:38.476439Z","schema_version":"clob-market-ws.price_change.v1","sequence":null,"server_hash":null,"server_timestamp":"1785126878459","session_id":"e9443c7415a0419799bee9cfbb1a9e4d","source":"clob_market_ws"},"received_at":"2026-07-27T04:34:38.476439Z","record_id":"cda1826998f704e8e6fe382dc1bf55fc9cf74e101976057db6beb2f5d0bd096c","schema_fingerprint":"4aa3821a28b0b7c2400bc59aba4bcc0a76e971dadd19610d3ad38c768e124dc7","schema_version":"edge-lab-recorder.raw.v1","sequence":null,"source":"clob_market_ws"}
{"event_at":"2026-07-27T04:34:38.460000Z","event_fingerprint":"ef47978861f96196ef421dc0a1774a165f0b488d8c650f82e94ee6fffd85d05d","payload":{"connection_id":"0f4979d6978d463e9660b042fdcf555f","event_at":"2026-07-27T04:34:38.460000Z","event_type":"price_change","frame_hash":"1dbf1733456ec35714eb7363b42aabb4ea7ab336b058b9fa2c16478e41195f46","frame_index":0,"kind":"data","monotonic_ns":228861745314916,"payload":{"event_type":"price_change","market":"0xeb66215f2e9faa6449e30a02bab5b8ed7b79a38bf961f6b24d0073c9c2419250","price_changes":[{"asset_id":"69697746896130839564035629862476347944307040470122503199396727085502753297492","best_ask":"0.24","best_bid":"0.23","hash":"560b145a6d5f6276f37f371fb0c6d595273499f1","price":"0.22","side":"BUY","size":"298"},{"asset_id":"60386828328910021732068595344565885737045900010034836345809386672230885527307","best_ask":"0.77","best_bid":"0.76","hash":"bb47db1dd7ad1c273007218cbd9001954d574cf6","price":"0.78","side":"SELL","size":"298"}],"timestamp":"1785126878460"},"payload_hash":"f634a628fe830b5d3d713e94da52846113eef2603f267d335588a3eb58ed314c","raw_frame":"{\"market\":\"0xeb66215f2e9faa6449e30a02bab5b8ed7b79a38bf961f6b24d0073c9c2419250\", \"price_changes\":[{\"asset_id\":\"69697746896130839564035629862476347944307040470122503199396727085502753297492\", \"price\":\"0.22\", \"size\":\"298\", \"side\":\"BUY\", \"hash\":\"560b145a6d5f6276f37f371fb0c6d595273499f1\", \"best_bid\":\"0.23\", \"best_ask\":\"0.24\"}, {\"asset_id\":\"60386828328910021732068595344565885737045900010034836345809386672230885527307\", \"price\":\"0.78\", \"size\":\"298\", \"side\":\"SELL\", \"hash\":\"bb47db1dd7ad1c273007218cbd9001954d574cf6\", \"best_bid\":\"0.76\", \"best_ask\":\"0.77\"}], \"timestamp\":\"1785126878460\", \"event_type\":\"price_change\"}","received_at":"2026-07-27T04:34:38.477893Z","schema_version":"clob-market-ws.price_change.v1","sequence":null,"server_hash":null,"server_timestamp":"1785126878460","session_id":"e9443c7415a0419799bee9cfbb1a9e4d","source":"clob_market_ws"},"received_at":"2026-07-27T04:34:38.477893Z","record_id":"4437a69bf16905b7dd34d8a98393ceab45d8070a7116138b4f7d259674710e9f","schema_fingerprint":"4aa3821a28b0b7c2400bc59aba4bcc0a76e971dadd19610d3ad38c768e124dc7","schema_version":"edge-lab-recorder.raw.v1","sequence":null,"source":"clob_market_ws"}
{"event_at":"2026-07-27T04:34:38.474000Z","event_fingerprint":"fbe9ce5288566ee759a8efe9eacfd4040396bd9662b228f8d5b0fdd95d066b8b","payload":{"connection_id":"0f4979d6978d463e9660b042fdcf555f","event_at":"2026-07-27T04:34:38.474000Z","event_type":"price_change","frame_hash":"a709264c910557335cf759f63b18e83e47dfb5c09e63d7b06f3e6ee07ae00b8b","frame_index":0,"kind":"data","monotonic_ns":228861746772041,"payload":{"event_type":"price_change","market":"0xeb66215f2e9faa6449e30a02bab5b8ed7b79a38bf961f6b24d0073c9c2419250","price_changes":[{"asset_id":"60386828328910021732068595344565885737045900010034836345809386672230885527307","best_ask":"0.77","best_bid":"0.76","hash":"b8e0a7c04fed00984af3fbdfb94d31296201db52","price":"0.69","side":"BUY","size":"203"},{"asset_id":"69697746896130839564035629862476347944307040470122503199396727085502753297492","best_ask":"0.24","best_bid":"0.23","hash":"73238e340d941f3c97cbee1d56c0a640c0c67cdf","price":"0.31","side":"SELL","size":"203"}],"timestamp":"1785126878474"},"payload_hash":"937c7a05df94f35ea00ce58ea980dc6180f9aec250d900c5c1ec27d8b763e287","raw_frame":"{\"market\":\"0xeb66215f2e9faa6449e30a02bab5b8ed7b79a38bf961f6b24d0073c9c2419250\", \"price_changes\":[{\"asset_id\":\"60386828328910021732068595344565885737045900010034836345809386672230885527307\", \"price\":\"0.69\", \"size\":\"203\", \"side\":\"BUY\", \"hash\":\"b8e0a7c04fed00984af3fbdfb94d31296201db52\", \"best_bid\":\"0.76\", \"best_ask\":\"0.77\"}, {\"asset_id\":\"69697746896130839564035629862476347944307040470122503199396727085502753297492\", \"price\":\"0.31\", \"size\":\"203\", \"side\":\"SELL\", \"hash\":\"73238e340d941f3c97cbee1d56c0a640c0c67cdf\", \"best_bid\":\"0.23\", \"best_ask\":\"0.24\"}], \"timestamp\":\"1785126878474\", \"event_type\":\"price_change\"}","received_at":"2026-07-27T04:34:38.479351Z","schema_version":"clob-market-ws.price_change.v1","sequence":null,"server_hash":null,"server_timestamp":"1785126878474","session_id":"e9443c7415a0419799bee9cfbb1a9e4d","source":"clob_market_ws"},"received_at":"2026-07-27T04:34:38.479351Z","record_id":"518748716171c749d85b0a0f7e6e47d4623524ed4afbcd4584fa1cd724ff2fbb","schema_fingerprint":"4aa3821a28b0b7c2400bc59aba4bcc0a76e971dadd19610d3ad38c768e124dc7","schema_version":"edge-lab-recorder.raw.v1","sequence":null,"source":"clob_market_ws"}
{"event_at":"2026-07-27T04:34:38.480000Z","event_fingerprint":"cdb65616d38702f8b2d18a8101e15bf8bbb2c868756d18b53978b09e38cddc4c","payload":{"connection_id":"0f4979d6978d463e9660b042fdcf555f","event_at":"2026-07-27T04:34:38.480000Z","event_type":"price_change","frame_hash":"d9923216ecf0e54ea7ccd1a9b957c281baee70fbfaee48143d3233f00d686f4a","frame_index":0,"kind":"data","monotonic_ns":228861748242000,"payload":{"event_type":"price_change","market":"0xeb66215f2e9faa6449e30a02bab5b8ed7b79a38bf961f6b24d0073c9c2419250","price_changes":[{"asset_id":"69697746896130839564035629862476347944307040470122503199396727085502753297492","best_ask":"0.24","best_bid":"0.23","hash":"986c29b9916938085668a10fdda446d2076084bb","price":"0.15","side":"BUY","size":"401.46"},{"asset_id":"60386828328910021732068595344565885737045900010034836345809386672230885527307","best_ask":"0.77","best_bid":"0.76","hash":"7aae412bcc58e546b71ced6472b797900dfa024d","price":"0.85","side":"SELL","size":"401.46"}],"timestamp":"1785126878480"},"payload_hash":"289c4388c1d8037a9426199b5ac321cd0732233b81b416a82b9a30148853465b","raw_frame":"{\"market\":\"0xeb66215f2e9faa6449e30a02bab5b8ed7b79a38bf961f6b24d0073c9c2419250\", \"price_changes\":[{\"asset_id\":\"69697746896130839564035629862476347944307040470122503199396727085502753297492\", \"price\":\"0.15\", \"size\":\"401.46\", \"side\":\"BUY\", \"hash\":\"986c29b9916938085668a10fdda446d2076084bb\", \"best_bid\":\"0.23\", \"best_ask\":\"0.24\"}, {\"asset_id\":\"60386828328910021732068595344565885737045900010034836345809386672230885527307\", \"price\":\"0.85\", \"size\":\"401.46\", \"side\":\"SELL\", \"hash\":\"7aae412bcc58e546b71ced6472b797900dfa024d\", \"best_bid\":\"0.76\", \"best_ask\":\"0.77\"}], \"timestamp\":\"1785126878480\", \"event_type\":\"price_change\"}","received_at":"2026-07-27T04:34:38.480821Z","schema_version":"clob-market-ws.price_change.v1","sequence":null,"server_hash":null,"server_timestamp":"1785126878480","session_id":"e9443c7415a0419799bee9cfbb1a9e4d","source":"clob_market_ws"},"received_at":"2026-07-27T04:34:38.480821Z","record_id":"3c6398559ec1412881c23efa29588a8da4d44290d83706b0fe4121a754948ed5","schema_fingerprint":"4aa3821a28b0b7c2400bc59aba4bcc0a76e971dadd19610d3ad38c768e124dc7","schema_version":"edge-lab-recorder.raw.v1","sequence":null,"source":"clob_market_ws"}
{"event_at":"2026-07-27T04:34:38.486000Z","event_fingerprint":"494efa6bf41faf301a9e5d8a1617167a1429aa3fcb585fab7945e411ac7f48ac","payload":{"connection_id":"0f4979d6978d463e9660b042fdcf555f","event_at":"2026-07-27T04:34:38.486000Z","event_type":"price_change","frame_hash":"c30701c84c59649e76c66555b2057582f511b11adf80f6e3db2233a268b337d8","frame_index":0,"kind":"data","monotonic_ns":228861749660083,"payload":{"event_type":"price_change","market":"0xeb66215f2e9faa6449e30a02bab5b8ed7b79a38bf961f6b24d0073c9c2419250","price_changes":[{"asset_id":"69697746896130839564035629862476347944307040470122503199396727085502753297492","best_ask":"0.24","best_bid":"0.23","hash":"b1674723b92f23f95cd8ffb77d73be495402bc0e","price":"0.18","side":"BUY","size":"119.61"},{"asset_id":"60386828328910021732068595344565885737045900010034836345809386672230885527307","best_ask":"0.77","best_bid":"0.76","hash":"40e1eb2066b023138a379ba2d0b1a71b706227c7","price":"0.82","side":"SELL","size":"119.61"}],"timestamp":"1785126878486"},"payload_hash":"cc1b2b6e8c9b831b3e6e0db709c69cb53c8b414cd3dac208ff88c52b920853a1","raw_frame":"{\"market\":\"0xeb66215f2e9faa6449e30a02bab5b8ed7b79a38bf961f6b24d0073c9c2419250\", \"price_changes\":[{\"asset_id\":\"69697746896130839564035629862476347944307040470122503199396727085502753297492\", \"price\":\"0.18\", \"size\":\"119.61\", \"side\":\"BUY\", \"hash\":\"b1674723b92f23f95cd8ffb77d73be495402bc0e\", \"best_bid\":\"0.23\", \"best_ask\":\"0.24\"}, {\"asset_id\":\"60386828328910021732068595344565885737045900010034836345809386672230885527307\", \"price\":\"0.82\", \"size\":\"119.61\", \"side\":\"SELL\", \"hash\":\"40e1eb2066b023138a379ba2d0b1a71b706227c7\", \"best_bid\":\"0.76\", \"best_ask\":\"0.77\"}], \"timestamp\":\"1785126878486\", \"event_type\":\"price_change\"}","received_at":"2026-07-27T04:34:38.482238Z","schema_version":"clob-market-ws.price_change.v1","sequence":null,"server_hash":null,"server_timestamp":"1785126878486","session_id":"e9443c7415a0419799bee9cfbb1a9e4d","source":"clob_market_ws"},"received_at":"2026-07-27T04:34:38.482238Z","record_id":"0d7bfee89ef02b95ccf1bd76f7303a0994373c2ad3fee1e632dd9573b2c82401","schema_fingerprint":"4aa3821a28b0b7c2400bc59aba4bcc0a76e971dadd19610d3ad38c768e124dc7","schema_version":"edge-lab-recorder.raw.v1","sequence":null,"source":"clob_market_ws"}
{"event_at":"2026-07-27T04:34:38.489000Z","event_fingerprint":"208997ad5941faa6fe493a561ecb6ba16fd2d87e7a72232cb4e1f4bc3ac7eb28","payload":{"connection_id":"0f4979d6978d463e9660b042fdcf555f","event_at":"2026-07-27T04:34:38.489000Z","event_type":"price_change","frame_hash":"b6ffa6ba21a508175b222ad825816af431e78e4f8a0026202d8a3632057163b2","frame_index":0,"kind":"data","monotonic_ns":228861751205000,"payload":{"event_type":"price_change","market":"0xeb66215f2e9faa6449e30a02bab5b8ed7b79a38bf961f6b24d0073c9c2419250","price_changes":[{"asset_id":"69697746896130839564035629862476347944307040470122503199396727085502753297492","best_ask":"0.24","best_bid":"0.23","hash":"0fcdf8e80f71f24087280d73300c0172c8ba007c","price":"0.18","side":"BUY","size":"149.61"},{"asset_id":"60386828328910021732068595344565885737045900010034836345809386672230885527307","best_ask":"0.77","best_bid":"0.76","hash":"3c5e53527b47420df555ab57d487b0f8aa263128","price":"0.82","side":"SELL","size":"149.61"}],"timestamp":"1785126878489"},"payload_hash":"4582fe5fe4f564ae0140109a4ea4c324d8ef184e2fae5dd512427f4a74c1ba3f","raw_frame":"{\"market\":\"0xeb66215f2e9faa6449e30a02bab5b8ed7b79a38bf961f6b24d0073c9c2419250\", \"price_changes\":[{\"asset_id\":\"69697746896130839564035629862476347944307040470122503199396727085502753297492\", \"price\":\"0.18\", \"size\":\"149.61\", \"side\":\"BUY\", \"hash\":\"0fcdf8e80f71f24087280d73300c0172c8ba007c\", \"best_bid\":\"0.23\", \"best_ask\":\"0.24\"}, {\"asset_id\":\"60386828328910021732068595344565885737045900010034836345809386672230885527307\", \"price\":\"0.82\", \"size\":\"149.61\", \"side\":\"SELL\", \"hash\":\"3c5e53527b47420df555ab57d487b0f8aa263128\", \"best_bid\":\"0.76\", \"best_ask\":\"0.77\"}], \"timestamp\":\"1785126878489\", \"event_type\":\"price_change\"}","received_at":"2026-07-27T04:34:38.483781Z","schema_version":"clob-market-ws.price_change.v1","sequence":null,"server_hash":null,"server_timestamp":"1785126878489","session_id":"e9443c7415a0419799bee9cfbb1a9e4d","source":"clob_market_ws"},"received_at":"2026-07-27T04:34:38.483781Z","record_id":"150b5b5ec86a8dfd095b9abb112dcadb60792132812da2bcf4b2ffd1eb36fdfa","schema_fingerprint":"4aa3821a28b0b7c2400bc59aba4bcc0a76e971dadd19610d3ad38c768e124dc7","schema_version":"edge-lab-recorder.raw.v1","sequence":null,"source":"clob_market_ws"}
{"event_at":"2026-07-27T04:34:38.501000Z","event_fingerprint":"d1dece9b32988b73d9e594775eee7ad4224444dc7b4a8022cdc4717cea12892f","payload":{"connection_id":"0f4979d6978d463e9660b042fdcf555f","event_at":"2026-07-27T04:34:38.501000Z","event_type":"price_change","frame_hash":"317e1200da0a3898e85aea8654968489d3ca47f2afbd735152897e6f08fccf05","frame_index":0,"kind":"data","monotonic_ns":228861753178541,"payload":{"event_type":"price_change","market":"0xeb66215f2e9faa6449e30a02bab5b8ed7b79a38bf961f6b24d0073c9c2419250","price_changes":[{"asset_id":"60386828328910021732068595344565885737045900010034836345809386672230885527307","best_ask":"0.77","best_bid":"0.76","hash":"334ac81d43d26f0d8b5cab499515a5638e55e02c","price":"0.01","side":"BUY","size":"5708.02"},{"asset_id":"69697746896130839564035629862476347944307040470122503199396727085502753297492","best_ask":"0.24","best_bid":"0.23","hash":"2ba24f39f61fbb5a111b87e4d5a0d41a423cc772","price":"0.99","side":"SELL","size":"5708.02"}],"timestamp":"1785126878501"},"payload_hash":"3d99354490a7d67a3a4ba5228858ffca3e54220bf49e8c246d53462851467a0d","raw_frame":"{\"market\":\"0xeb66215f2e9faa6449e30a02bab5b8ed7b79a38bf961f6b24d0073c9c2419250\", \"price_changes\":[{\"asset_id\":\"60386828328910021732068595344565885737045900010034836345809386672230885527307\", \"price\":\"0.01\", \"size\":\"5708.02\", \"side\":\"BUY\", \"hash\":\"334ac81d43d26f0d8b5cab499515a5638e55e02c\", \"best_bid\":\"0.76\", \"best_ask\":\"0.77\"}, {\"asset_id\":\"69697746896130839564035629862476347944307040470122503199396727085502753297492\", \"price\":\"0.99\", \"size\":\"5708.02\", \"side\":\"SELL\", \"hash\":\"2ba24f39f61fbb5a111b87e4d5a0d41a423cc772\", \"best_bid\":\"0.23\", \"best_ask\":\"0.24\"}], \"timestamp\":\"1785126878501\", \"event_type\":\"price_change\"}","received_at":"2026-07-27T04:34:38.485753Z","schema_version":"clob-market-ws.price_change.v1","sequence":null,"server_hash":null,"server_timestamp":"1785126878501","session_id":"e9443c7415a0419799bee9cfbb1a9e4d","source":"clob_market_ws"},"received_at":"2026-07-27T04:34:38.485753Z","record_id":"63141b8ef27e082880e547383a481eaae2fd375c14190294d7a272435852217c","schema_fingerprint":"4aa3821a28b0b7c2400bc59aba4bcc0a76e971dadd19610d3ad38c768e124dc7","schema_version":"edge-lab-recorder.raw.v1","sequence":null,"source":"clob_market_ws"}
{"event_at":"2026-07-27T04:34:38.504000Z","event_fingerprint":"91764d9d2ca3dc65f7feb93c39d4535f75d422581c107e992fd0e59cf3ba498a","payload":{"connection_id":"0f4979d6978d463e9660b042fdcf555f","event_at":"2026-07-27T04:34:38.504000Z","event_type":"price_change","frame_hash":"d5827ff7b91dba2a757dd22bec581547ce3dacc9771081c265cac4acfedaf0ef","frame_index":0,"kind":"data","monotonic_ns":228861754716333,"payload":{"event_type":"price_change","market":"0xeb66215f2e9faa6449e30a02bab5b8ed7b79a38bf961f6b24d0073c9c2419250","price_changes":[{"asset_id":"60386828328910021732068595344565885737045900010034836345809386672230885527307","best_ask":"0.77","best_bid":"0.76","hash":"a1123446918300473e84807f83acbd57e827fe50","price":"0.73","side":"BUY","size":"21.66"},{"asset_id":"69697746896130839564035629862476347944307040470122503199396727085502753297492","best_ask":"0.24","best_bid":"0.23","hash":"bfd9730dff6dcbe312ae0bed95213b9990bbc249","price":"0.27","side":"SELL","size":"21.66"}],"timestamp":"1785126878504"},"payload_hash":"1af30bfd47876d0f12c8195d5ec2e5f44a3fa584dfc260ee1f702b596c991dca","raw_frame":"{\"market\":\"0xeb66215f2e9faa6449e30a02bab5b8ed7b79a38bf961f6b24d0073c9c2419250\", \"price_changes\":[{\"asset_id\":\"60386828328910021732068595344565885737045900010034836345809386672230885527307\", \"price\":\"0.73\", \"size\":\"21.66\", \"side\":\"BUY\", \"hash\":\"a1123446918300473e84807f83acbd57e827fe50\", \"best_bid\":\"0.76\", \"best_ask\":\"0.77\"}, {\"asset_id\":\"69697746896130839564035629862476347944307040470122503199396727085502753297492\", \"price\":\"0.27\", \"size\":\"21.66\", \"side\":\"SELL\", \"hash\":\"bfd9730dff6dcbe312ae0bed95213b9990bbc249\", \"best_bid\":\"0.23\", \"best_ask\":\"0.24\"}], \"timestamp\":\"1785126878504\", \"event_type\":\"price_change\"}","received_at":"2026-07-27T04:34:38.487293Z","schema_version":"clob-market-ws.price_change.v1","sequence":null,"server_hash":null,"server_timestamp":"1785126878504","session_id":"e9443c7415a0419799bee9cfbb1a9e4d","source":"clob_market_ws"},"received_at":"2026-07-27T04:34:38.487293Z","record_id":"622b10b6fcf51fe0132951605525ad2328dbd0eedfec0bfc78aecbd0b3baf70c","schema_fingerprint":"4aa3821a28b0b7c2400bc59aba4bcc0a76e971dadd19610d3ad38c768e124dc7","schema_version":"edge-lab-recorder.raw.v1","sequence":null,"source":"clob_market_ws"}
{"event_at":"2026-07-27T04:34:38.510000Z","event_fingerprint":"6aa7fac6d09e7eed98c4fdc205fec9949523ccc7166cab0916c2e9128a00ff84","payload":{"connection_id":"0f4979d6978d463e9660b042fdcf555f","event_at":"2026-07-27T04:34:38.510000Z","event_type":"price_change","frame_hash":"6bce06c0740bca68760f79fbba324169c6017ac93e1da2c29818ba36687af79f","frame_index":0,"kind":"data","monotonic_ns":228861756204750,"payload":{"event_type":"price_change","market":"0xeb66215f2e9faa6449e30a02bab5b8ed7b79a38bf961f6b24d0073c9c2419250","price_changes":[{"asset_id":"60386828328910021732068595344565885737045900010034836345809386672230885527307","best_ask":"0.77","best_bid":"0.76","hash":"839b0eea5d8de87bb6335b117c2f1a5e4c586e0f","price":"0.8","side":"SELL","size":"47.6"},{"asset_id":"69697746896130839564035629862476347944307040470122503199396727085502753297492","best_ask":"0.24","best_bid":"0.23","hash":"faaacdb69b94a000371231cbfad25d3b65ad1fe0","price":"0.2","side":"BUY","size":"47.6"}],"timestamp":"1785126878510"},"payload_hash":"cf429ef5ff42a9d91ac035f34e13190aa35dd541dbc53552e4b790142080dc6d","raw_frame":"{\"market\":\"0xeb66215f2e9faa6449e30a02bab5b8ed7b79a38bf961f6b24d0073c9c2419250\", \"price_changes\":[{\"asset_id\":\"60386828328910021732068595344565885737045900010034836345809386672230885527307\", \"price\":\"0.8\", \"size\":\"47.6\", \"side\":\"SELL\", \"hash\":\"839b0eea5d8de87bb6335b117c2f1a5e4c586e0f\", \"best_bid\":\"0.76\", \"best_ask\":\"0.77\"}, {\"asset_id\":\"69697746896130839564035629862476347944307040470122503199396727085502753297492\", \"price\":\"0.2\", \"size\":\"47.6\", \"side\":\"BUY\", \"hash\":\"faaacdb69b94a000371231cbfad25d3b65ad1fe0\", \"best_bid\":\"0.23\", \"best_ask\":\"0.24\"}], \"timestamp\":\"1785126878510\", \"event_type\":\"price_change\"}","received_at":"2026-07-27T04:34:38.488782Z","schema_version":"clob-market-ws.price_change.v1","sequence":null,"server_hash":null,"server_timestamp":"1785126878510","session_id":"e9443c7415a0419799bee9cfbb1a9e4d","source":"clob_market_ws"},"received_at":"2026-07-27T04:34:38.488782Z","record_id":"fdc74a53415774b2831118cd975fd7ee600c6b7f9412298f59d69c1caaeeb4d5","schema_fingerprint":"4aa3821a28b0b7c2400bc59aba4bcc0a76e971dadd19610d3ad38c768e124dc7","schema_version":"edge-lab-recorder.raw.v1","sequence":null,"source":"clob_market_ws"}
{"event_at":"2026-07-27T04:34:38.512000Z","event_fingerprint":"e5c0b61bbfd05fbbf0dbf29528e62c2099536b82a3b56a8110fe6d1b47e5be9a","payload":{"connection_id":"0f4979d6978d463e9660b042fdcf555f","event_at":"2026-07-27T04:34:38.512000Z","event_type":"price_change","frame_hash":"7aeb035722014cae3ffa3235668b607b59fe117258f47ddfd49d7d26be6c2d64","frame_index":0,"kind":"data","monotonic_ns":228861757725791,"payload":{"event_type":"price_change","market":"0xeb66215f2e9faa6449e30a02bab5b8ed7b79a38bf961f6b24d0073c9c2419250","price_changes":[{"asset_id":"69697746896130839564035629862476347944307040470122503199396727085502753297492","best_ask":"0.24","best_bid":"0.23","hash":"0815b3b5d53e01547b7c133c8694bf4c27c66db9","price":"0.27","side":"SELL","size":"51.7"},{"asset_id":"60386828328910021732068595344565885737045900010034836345809386672230885527307","best_ask":"0.77","best_bid":"0.76","hash":"80ffc5a569987d91e1a4a47efe2e4ee22d94e14e","price":"0.73","side":"BUY","size":"51.7"}],"timestamp":"1785126878512"},"payload_hash":"fc50969125302c64e043a717f04b1bdcf432aa5f6b8473d5d0a7028eb24cd11e","raw_frame":"{\"market\":\"0xeb66215f2e9faa6449e30a02bab5b8ed7b79a38bf961f6b24d0073c9c2419250\", \"price_changes\":[{\"asset_id\":\"69697746896130839564035629862476347944307040470122503199396727085502753297492\", \"price\":\"0.27\", \"size\":\"51.7\", \"side\":\"SELL\", \"hash\":\"0815b3b5d53e01547b7c133c8694bf4c27c66db9\", \"best_bid\":\"0.23\", \"best_ask\":\"0.24\"}, {\"asset_id\":\"60386828328910021732068595344565885737045900010034836345809386672230885527307\", \"price\":\"0.73\", \"size\":\"51.7\", \"side\":\"BUY\", \"hash\":\"80ffc5a569987d91e1a4a47efe2e4ee22d94e14e\", \"best_bid\":\"0.76\", \"best_ask\":\"0.77\"}], \"timestamp\":\"1785126878512\", \"event_type\":\"price_change\"}","received_at":"2026-07-27T04:34:38.490302Z","schema_version":"clob-market-ws.price_change.v1","sequence":null,"server_hash":null,"server_timestamp":"1785126878512","session_id":"e9443c7415a0419799bee9cfbb1a9e4d","source":"clob_market_ws"},"received_at":"2026-07-27T04:34:38.490302Z","record_id":"02875cfd69540cce4036053591766789bdfe422ef52601d9b372cfdab6e759de","schema_fingerprint":"4aa3821a28b0b7c2400bc59aba4bcc0a76e971dadd19610d3ad38c768e124dc7","schema_version":"edge-lab-recorder.raw.v1","sequence":null,"source":"clob_market_ws"}
{"event_at":"2026-07-27T04:34:38.513000Z","event_fingerprint":"e5847d5b59f815aa33f1c24e4a49bc7961312075c2247b5cae14218340ce286e","payload":{"connection_id":"0f4979d6978d463e9660b042fdcf555f","event_at":"2026-07-27T04:34:38.513000Z","event_type":"price_change","frame_hash":"143d8344a1a13fb2797a4025c9d63d13fe7684fa3cdeed476b142c9575853ba0","frame_index":0,"kind":"data","monotonic_ns":228861759240291,"payload":{"event_type":"price_change","market":"0xeb66215f2e9faa6449e30a02bab5b8ed7b79a38bf961f6b24d0073c9c2419250","price_changes":[{"asset_id":"60386828328910021732068595344565885737045900010034836345809386672230885527307","best_ask":"0.77","best_bid":"0.76","hash":"1cd8c1469b7330f7048b86a79e1d94da47033ba6","price":"0.73","side":"BUY","size":"64.66"},{"asset_id":"69697746896130839564035629862476347944307040470122503199396727085502753297492","best_ask":"0.24","best_bid":"0.23","hash":"942e8e4144b89d16b7b6fe372114d62af2c0c9be","price":"0.27","side":"SELL","size":"64.66"}],"timestamp":"1785126878513"},"payload_hash":"b3af87dd5837cd755f6286ba645edb02949762c84be19cd9de99c54b85f7014f","raw_frame":"{\"market\":\"0xeb66215f2e9faa6449e30a02bab5b8ed7b79a38bf961f6b24d0073c9c2419250\", \"price_changes\":[{\"asset_id\":\"60386828328910021732068595344565885737045900010034836345809386672230885527307\", \"price\":\"0.73\", \"size\":\"64.66\", \"side\":\"BUY\", \"hash\":\"1cd8c1469b7330f7048b86a79e1d94da47033ba6\", \"best_bid\":\"0.76\", \"best_ask\":\"0.77\"}, {\"asset_id\":\"69697746896130839564035629862476347944307040470122503199396727085502753297492\", \"price\":\"0.27\", \"size\":\"64.66\", \"side\":\"SELL\", \"hash\":\"942e8e4144b89d16b7b6fe372114d62af2c0c9be\", \"best_bid\":\"0.23\", \"best_ask\":\"0.24\"}], \"timestamp\":\"1785126878513\", \"event_type\":\"price_change\"}","received_at":"2026-07-27T04:34:38.491815Z","schema_version":"clob-market-ws.price_change.v1","sequence":null,"server_hash":null,"server_timestamp":"1785126878513","session_id":"e9443c7415a0419799bee9cfbb1a9e4d","source":"clob_market_ws"},"received_at":"2026-07-27T04:34:38.491815Z","record_id":"a5e63fba4d17381dec91b8be4f2038bf460d63d662fb7d28235dd077ba042306","schema_fingerprint":"4aa3821a28b0b7c2400bc59aba4bcc0a76e971dadd19610d3ad38c768e124dc7","schema_version":"edge-lab-recorder.raw.v1","sequence":null,"source":"clob_market_ws"}
{"event_at":"2026-07-27T04:34:38.525000Z","event_fingerprint":"6863c2e87f500ef8aec727cd480beb0fd1540ef80920013bf49ce5742e79204c","payload":{"connection_id":"0f4979d6978d463e9660b042fdcf555f","event_at":"2026-07-27T04:34:38.525000Z","event_type":"price_change","frame_hash":"75c5ee526b6628ad0a0f11b9af2a40e30cee8a0ff2370ebe80583c23b2e68a8e","frame_index":0,"kind":"data","monotonic_ns":228861760757250,"payload":{"event_type":"price_change","market":"0xeb66215f2e9faa6449e30a02bab5b8ed7b79a38bf961f6b24d0073c9c2419250","price_changes":[{"asset_id":"69697746896130839564035629862476347944307040470122503199396727085502753297492","best_ask":"0.24","best_bid":"0.23","hash":"b6d03d891559c4d7b1620bd4ed75b945a8b19ce1","price":"0.18","side":"BUY","size":"169.91"},{"asset_id":"60386828328910021732068595344565885737045900010034836345809386672230885527307","best_ask":"0.77","best_bid":"0.76","hash":"d9c52574fc1cce454efa91914f89ecf62617454f","price":"0.82","side":"SELL","size":"169.91"}],"timestamp":"1785126878525"},"payload_hash":"a261381e0435b8b79e8a9d4fc73d5916f0a0a66db3ac395abaa378cdd88ab803","raw_frame":"{\"market\":\"0xeb66215f2e9faa6449e30a02bab5b8ed7b79a38bf961f6b24d0073c9c2419250\", \"price_changes\":[{\"asset_id\":\"69697746896130839564035629862476347944307040470122503199396727085502753297492\", \"price\":\"0.18\", \"size\":\"169.91\", \"side\":\"BUY\", \"hash\":\"b6d03d891559c4d7b1620bd4ed75b945a8b19ce1\", \"best_bid\":\"0.23\", \"best_ask\":\"0.24\"}, {\"asset_id\":\"60386828328910021732068595344565885737045900010034836345809386672230885527307\", \"price\":\"0.82\", \"size\":\"169.91\", \"side\":\"SELL\", \"hash\":\"d9c52574fc1cce454efa91914f89ecf62617454f\", \"best_bid\":\"0.76\", \"best_ask\":\"0.77\"}], \"timestamp\":\"1785126878525\", \"event_type\":\"price_change\"}","received_at":"2026-07-27T04:34:38.493336Z","schema_version":"clob-market-ws.price_change.v1","sequence":null,"server_hash":null,"server_timestamp":"1785126878525","session_id":"e9443c7415a0419799bee9cfbb1a9e4d","source":"clob_market_ws"},"received_at":"2026-07-27T04:34:38.493336Z","record_id":"9075140750765b2e409799e53e56cc29eb74d1bbb08e633698a2b411f5e622e8","schema_fingerprint":"4aa3821a28b0b7c2400bc59aba4bcc0a76e971dadd19610d3ad38c768e124dc7","schema_version":"edge-lab-recorder.raw.v1","sequence":null,"source":"clob_market_ws"}
{"event_at":"2026-07-27T04:34:38.555000Z","event_fingerprint":"bfbbe73d0332996c6ff168675af43d407e65b98ccc1565136d944a098d7d960b","payload":{"connection_id":"0f4979d6978d463e9660b042fdcf555f","event_at":"2026-07-27T04:34:38.555000Z","event_type":"price_change","frame_hash":"99826de58864c21e811766c8ef67b8ef8552a1a6869fc1961983b82cfd7b7736","frame_index":0,"kind":"data","monotonic_ns":228861767654500,"payload":{"event_type":"price_change","market":"0xeb66215f2e9faa6449e30a02bab5b8ed7b79a38bf961f6b24d0073c9c2419250","price_changes":[{"asset_id":"60386828328910021732068595344565885737045900010034836345809386672230885527307","best_ask":"0.77","best_bid":"0.76","hash":"4ed8d384b151361534b5dcb0bf1b7bbd25e79a01","price":"0.01","side":"BUY","size":"5703.02"},{"asset_id":"69697746896130839564035629862476347944307040470122503199396727085502753297492","best_ask":"0.24","best_bid":"0.23","hash":"582e950c9324c2afad9ac9b5185aeed687410445","price":"0.99","side":"SELL","size":"5703.02"}],"timestamp":"1785126878555"},"payload_hash":"44043468e2b615716676119765d176d1a0b16e0360fd62c1257d13ef249404c1","raw_frame":"{\"market\":\"0xeb66215f2e9faa6449e30a02bab5b8ed7b79a38bf961f6b24d0073c9c2419250\", \"price_changes\":[{\"asset_id\":\"60386828328910021732068595344565885737045900010034836345809386672230885527307\", \"price\":\"0.01\", \"size\":\"5703.02\", \"side\":\"BUY\", \"hash\":\"4ed8d384b151361534b5dcb0bf1b7bbd25e79a01\", \"best_bid\":\"0.76\", \"best_ask\":\"0.77\"}, {\"asset_id\":\"69697746896130839564035629862476347944307040470122503199396727085502753297492\", \"price\":\"0.99\", \"size\":\"5703.02\", \"side\":\"SELL\", \"hash\":\"582e950c9324c2afad9ac9b5185aeed687410445\", \"best_bid\":\"0.23\", \"best_ask\":\"0.24\"}], \"timestamp\":\"1785126878555\", \"event_type\":\"price_change\"}","received_at":"2026-07-27T04:34:38.500226Z","schema_version":"clob-market-ws.price_change.v1","sequence":null,"server_hash":null,"server_timestamp":"1785126878555","session_id":"e9443c7415a0419799bee9cfbb1a9e4d","source":"clob_market_ws"},"received_at":"2026-07-27T04:34:38.500226Z","record_id":"e01b57d19998f3484ec497ab9cdb362e9e91a0f25fbedcda7eb485fccfa16760","schema_fingerprint":"4aa3821a28b0b7c2400bc59aba4bcc0a76e971dadd19610d3ad38c768e124dc7","schema_version":"edge-lab-recorder.raw.v1","sequence":null,"source":"clob_market_ws"}
{"event_at":"2026-07-27T04:34:38.559000Z","event_fingerprint":"e95be7da893eb6e16eadfca24bafa107dbdaa70db7ab26345458d5b5cd5fbe43","payload":{"connection_id":"0f4979d6978d463e9660b042fdcf555f","event_at":"2026-07-27T04:34:38.559000Z","event_type":"price_change","frame_hash":"de918b9a5375c3f75e50c7404cee085e27f624c5bdcfb42ef9d37e1f4025e121","frame_index":0,"kind":"data","monotonic_ns":228861771410041,"payload":{"event_type":"price_change","market":"0xeb66215f2e9faa6449e30a02bab5b8ed7b79a38bf961f6b24d0073c9c2419250","price_changes":[{"asset_id":"69697746896130839564035629862476347944307040470122503199396727085502753297492","best_ask":"0.24","best_bid":"0.23","hash":"dcd04a21d1c6d7d7ebe640a001238bbffb7d34cc","price":"0.15","side":"BUY","size":"371.46"},{"asset_id":"60386828328910021732068595344565885737045900010034836345809386672230885527307","best_ask":"0.77","best_bid":"0.76","hash":"88aa541c3c2b3038ae15163bbe6a39555f952f41","price":"0.85","side":"SELL","size":"371.46"}],"timestamp":"1785126878559"},"payload_hash":"b0a091522a179f660b3dd74098c8eb67dca19b3ae17763af74ccabd562c97077","raw_frame":"{\"market\":\"0xeb66215f2e9faa6449e30a02bab5b8ed7b79a38bf961f6b24d0073c9c2419250\", \"price_changes\":[{\"asset_id\":\"69697746896130839564035629862476347944307040470122503199396727085502753297492\", \"price\":\"0.15\", \"size\":\"371.46\", \"side\":\"BUY\", \"hash\":\"dcd04a21d1c6d7d7ebe640a001238bbffb7d34cc\", \"best_bid\":\"0.23\", \"best_ask\":\"0.24\"}, {\"asset_id\":\"60386828328910021732068595344565885737045900010034836345809386672230885527307\", \"price\":\"0.85\", \"size\":\"371.46\", \"side\":\"SELL\", \"hash\":\"88aa541c3c2b3038ae15163bbe6a39555f952f41\", \"best_bid\":\"0.76\", \"best_ask\":\"0.77\"}], \"timestamp\":\"1785126878559\", \"event_type\":\"price_change\"}","received_at":"2026-07-27T04:34:38.503984Z","schema_version":"clob-market-ws.price_change.v1","sequence":null,"server_hash":null,"server_timestamp":"1785126878559","session_id":"e9443c7415a0419799bee9cfbb1a9e4d","source":"clob_market_ws"},"received_at":"2026-07-27T04:34:38.503984Z","record_id":"4a967363bd4ee31357340a2e704d8f38075f638b9704499a48afeb4f54efcf39","schema_fingerprint":"4aa3821a28b0b7c2400bc59aba4bcc0a76e971dadd19610d3ad38c768e124dc7","schema_version":"edge-lab-recorder.raw.v1","sequence":null,"source":"clob_market_ws"}
{"event_at":"2026-07-27T04:34:38.560000Z","event_fingerprint":"cbf6ac1879b1ea3849075680f0ef6ae4844e6ef5826604ab7d7c74f7e10fd099","payload":{"connection_id":"0f4979d6978d463e9660b042fdcf555f","event_at":"2026-07-27T04:34:38.560000Z","event_type":"price_change","frame_hash":"942558a773578346939995ae9edad5e223ca0af8d673e30186bae47d965bb1f2","frame_index":0,"kind":"data","monotonic_ns":228861773032416,"payload":{"event_type":"price_change","market":"0xeb66215f2e9faa6449e30a02bab5b8ed7b79a38bf961f6b24d0073c9c2419250","price_changes":[{"asset_id":"69697746896130839564035629862476347944307040470122503199396727085502753297492","best_ask":"0.24","best_bid":"0.23","hash":"45e2ae76f776cc0f95d877c3b4a3196fb88dec77","price":"0.18","side":"BUY","size":"139.91"},{"asset_id":"60386828328910021732068595344565885737045900010034836345809386672230885527307","best_ask":"0.77","best_bid":"0.76","hash":"f93eccca9538f70cb16b7e32092069d882a2d093","price":"0.82","side":"SELL","size":"139.91"}],"timestamp":"1785126878560"},"payload_hash":"3fe183314e8ee82816f8d7f03718340c83d7932af20811339ad9c86f547d6a41","raw_frame":"{\"market\":\"0xeb66215f2e9faa6449e30a02bab5b8ed7b79a38bf961f6b24d0073c9c2419250\", \"price_changes\":[{\"asset_id\":\"69697746896130839564035629862476347944307040470122503199396727085502753297492\", \"price\":\"0.18\", \"size\":\"139.91\", \"side\":\"BUY\", \"hash\":\"45e2ae76f776cc0f95d877c3b4a3196fb88dec77\", \"best_bid\":\"0.23\", \"best_ask\":\"0.24\"}, {\"asset_id\":\"60386828328910021732068595344565885737045900010034836345809386672230885527307\", \"price\":\"0.82\", \"size\":\"139.91\", \"side\":\"SELL\", \"hash\":\"f93eccca9538f70cb16b7e32092069d882a2d093\", \"best_bid\":\"0.76\", \"best_ask\":\"0.77\"}], \"timestamp\":\"1785126878560\", \"event_type\":\"price_change\"}","received_at":"2026-07-27T04:34:38.505610Z","schema_version":"clob-market-ws.price_change.v1","sequence":null,"server_hash":null,"server_timestamp":"1785126878560","session_id":"e9443c7415a0419799bee9cfbb1a9e4d","source":"clob_market_ws"},"received_at":"2026-07-27T04:34:38.505610Z","record_id":"81380f1b96485f6e5a4ecd9e269e4b68b2eff8ed5a3dd907a37f4e4e32330d2b","schema_fingerprint":"4aa3821a28b0b7c2400bc59aba4bcc0a76e971dadd19610d3ad38c768e124dc7","schema_version":"edge-lab-recorder.raw.v1","sequence":null,"source":"clob_market_ws"}
{"event_at":"2026-07-27T04:34:38.563000Z","event_fingerprint":"269698bb8a49ac4434e072a379152ba19a0acbd520331951ce3bac21f19e30bc","payload":{"connection_id":"0f4979d6978d463e9660b042fdcf555f","event_at":"2026-07-27T04:34:38.563000Z","event_type":"price_change","frame_hash":"fa52538ceebef9cd7f1e34a493d804bd6c5b2eb409757a33ce7b80a8ae8c508e","frame_index":0,"kind":"data","monotonic_ns":228861776250791,"payload":{"event_type":"price_change","market":"0xeb66215f2e9faa6449e30a02bab5b8ed7b79a38bf961f6b24d0073c9c2419250","price_changes":[{"asset_id":"60386828328910021732068595344565885737045900010034836345809386672230885527307","best_ask":"0.77","best_bid":"0.76","hash":"72b910b5be3b96fb024bcf2ec4668e22822f9bac","price":"0.73","side":"BUY","size":"334.66"},{"asset_id":"69697746896130839564035629862476347944307040470122503199396727085502753297492","best_ask":"0.24","best_bid":"0.23","hash":"ccea9a587d43dd5df48b65b6f956e9b97bc3f18a","price":"0.27","side":"SELL","size":"334.66"}],"timestamp":"1785126878563"},"payload_hash":"f36c443c7e03b1322539a0d97d081e922da28af042691bf0e8789e002e6f1cf5","raw_frame":"{\"market\":\"0xeb66215f2e9faa6449e30a02bab5b8ed7b79a38bf961f6b24d0073c9c2419250\", \"price_changes\":[{\"asset_id\":\"60386828328910021732068595344565885737045900010034836345809386672230885527307\", \"price\":\"0.73\", \"size\":\"334.66\", \"side\":\"BUY\", \"hash\":\"72b910b5be3b96fb024bcf2ec4668e22822f9bac\", \"best_bid\":\"0.76\", \"best_ask\":\"0.77\"}, {\"asset_id\":\"69697746896130839564035629862476347944307040470122503199396727085502753297492\", \"price\":\"0.27\", \"size\":\"334.66\", \"side\":\"SELL\", \"hash\":\"ccea9a587d43dd5df48b65b6f956e9b97bc3f18a\", \"best_bid\":\"0.23\", \"best_ask\":\"0.24\"}], \"timestamp\":\"1785126878563\", \"event_type\":\"price_change\"}","received_at":"2026-07-27T04:34:38.508826Z","schema_version":"clob-market-ws.price_change.v1","sequence":null,"server_hash":null,"server_timestamp":"1785126878563","session_id":"e9443c7415a0419799bee9cfbb1a9e4d","source":"clob_market_ws"},"received_at":"2026-07-27T04:34:38.508826Z","record_id":"9639c703848913762b9e0efd7258d68a515996047488bec42147496a285797d8","schema_fingerprint":"4aa3821a28b0b7c2400bc59aba4bcc0a76e971dadd19610d3ad38c768e124dc7","schema_version":"edge-lab-recorder.raw.v1","sequence":null,"source":"clob_market_ws"}
{"event_at":"2026-07-27T04:34:38.569000Z","event_fingerprint":"8f4c23c4e807d623cea85f8f228e952eff9f14b670fabbdc4823b9c39e202860","payload":{"connection_id":"0f4979d6978d463e9660b042fdcf555f","event_at":"2026-07-27T04:34:38.569000Z","event_type":"price_change","frame_hash":"1f252482b7faf0007846c1ef29015ee151e648e431af510b0a8d320ae0477c30","frame_index":0,"kind":"data","monotonic_ns":228861782378708,"payload":{"event_type":"price_change","market":"0xeb66215f2e9faa6449e30a02bab5b8ed7b79a38bf961f6b24d0073c9c2419250","price_changes":[{"asset_id":"69697746896130839564035629862476347944307040470122503199396727085502753297492","best_ask":"0.24","best_bid":"0.23","hash":"18d3d40c7b5fdc1f90618ae655cb55cc989b1592","price":"0.15","side":"BUY","size":"566.46"},{"asset_id":"60386828328910021732068595344565885737045900010034836345809386672230885527307","best_ask":"0.77","best_bid":"0.76","hash":"dc1fb7bc3368e6fbd6909d9a913d2aeef802c3de","price":"0.85","side":"SELL","size":"566.46"}],"timestamp":"1785126878569"},"payload_hash":"f30afbf849d8f68cf1d3fd7c1a58d60c1c51510fa5708c485ac39a72a6b19161","raw_frame":"{\"market\":\"0xeb66215f2e9faa6449e30a02bab5b8ed7b79a38bf961f6b24d0073c9c2419250\", \"price_changes\":[{\"asset_id\":\"69697746896130839564035629862476347944307040470122503199396727085502753297492\", \"price\":\"0.15\", \"size\":\"566.46\", \"side\":\"BUY\", \"hash\":\"18d3d40c7b5fdc1f90618ae655cb55cc989b1592\", \"best_bid\":\"0.23\", \"best_ask\":\"0.24\"}, {\"asset_id\":\"60386828328910021732068595344565885737045900010034836345809386672230885527307\", \"price\":\"0.85\", \"size\":\"566.46\", \"side\":\"SELL\", \"hash\":\"dc1fb7bc3368e6fbd6909d9a913d2aeef802c3de\", \"best_bid\":\"0.76\", \"best_ask\":\"0.77\"}], \"timestamp\":\"1785126878569\", \"event_type\":\"price_change\"}","received_at":"2026-07-27T04:34:38.514953Z","schema_version":"clob-market-ws.price_change.v1","sequence":null,"server_hash":null,"server_timestamp":"1785126878569","session_id":"e9443c7415a0419799bee9cfbb1a9e4d","source":"clob_market_ws"},"received_at":"2026-07-27T04:34:38.514953Z","record_id":"9ae936dc36fd04c6a05337046dd3471501b7ed911204f03d224f3b200dad27c0","schema_fingerprint":"4aa3821a28b0b7c2400bc59aba4bcc0a76e971dadd19610d3ad38c768e124dc7","schema_version":"edge-lab-recorder.raw.v1","sequence":null,"source":"clob_market_ws"}
{"event_at":"2026-07-27T04:34:38.572000Z","event_fingerprint":"04f132bc64aa74a3e8a1ff5fde7e2f8f092bf9935f1f9a9a2bcb47606107002e","payload":{"connection_id":"0f4979d6978d463e9660b042fdcf555f","event_at":"2026-07-27T04:34:38.572000Z","event_type":"price_change","frame_hash":"1315094bf55c57ee784af9ea5643059d934518eaf8f5203e57a0bdfbaaefedb3","frame_index":0,"kind":"data","monotonic_ns":228861786265791,"payload":{"event_type":"price_change","market":"0xeb66215f2e9faa6449e30a02bab5b8ed7b79a38bf961f6b24d0073c9c2419250","price_changes":[{"asset_id":"69697746896130839564035629862476347944307040470122503199396727085502753297492","best_ask":"0.24","best_bid":"0.23","hash":"7c298b46ee214cbd9c715d21cd5b2ff0b8e9899d","price":"0.22","side":"BUY","size":"307.6"},{"asset_id":"60386828328910021732068595344565885737045900010034836345809386672230885527307","best_ask":"0.77","best_bid":"0.76","hash":"bafb5d6dd9e22ae0740ca8b8cf6f84fc504c5f9c","price":"0.78","side":"SELL","size":"307.6"}],"timestamp":"1785126878572"},"payload_hash":"d3dd08173d77e3200b2416bc56ce38d80b3a8fae2963caf0d8562a90daa59def","raw_frame":"{\"market\":\"0xeb66215f2e9faa6449e30a02bab5b8ed7b79a38bf961f6b24d0073c9c2419250\", \"price_changes\":[{\"asset_id\":\"69697746896130839564035629862476347944307040470122503199396727085502753297492\", \"price\":\"0.22\", \"size\":\"307.6\", \"side\":\"BUY\", \"hash\":\"7c298b46ee214cbd9c715d21cd5b2ff0b8e9899d\", \"best_bid\":\"0.23\", \"best_ask\":\"0.24\"}, {\"asset_id\":\"60386828328910021732068595344565885737045900010034836345809386672230885527307\", \"price\":\"0.78\", \"size\":\"307.6\", \"side\":\"SELL\", \"hash\":\"bafb5d6dd9e22ae0740ca8b8cf6f84fc504c5f9c\", \"best_bid\":\"0.76\", \"best_ask\":\"0.77\"}], \"timestamp\":\"1785126878572\", \"event_type\":\"price_change\"}","received_at":"2026-07-27T04:34:38.518839Z","schema_version":"clob-market-ws.price_change.v1","sequence":null,"server_hash":null,"server_timestamp":"1785126878572","session_id":"e9443c7415a0419799bee9cfbb1a9e4d","source":"clob_market_ws"},"received_at":"2026-07-27T04:34:38.518839Z","record_id":"54b87b57c3212ae3bc55e740a40ab44c19ddbf20a49dd7688ed3fa7a3480fbd5","schema_fingerprint":"4aa3821a28b0b7c2400bc59aba4bcc0a76e971dadd19610d3ad38c768e124dc7","schema_version":"edge-lab-recorder.raw.v1","sequence":null,"source":"clob_market_ws"}
{"event_at":"2026-07-27T04:34:38.582000Z","event_fingerprint":"4783ca5ef3f8fc509863e641040b9847214dc1728d153ebad4db4dbfc2154707","payload":{"connection_id":"0f4979d6978d463e9660b042fdcf555f","event_at":"2026-07-27T04:34:38.582000Z","event_type":"price_change","frame_hash":"42d9ba0cab0b4c4208337410a8387bd72b3cce939bd87c902aee7315b76ba15d","frame_index":0,"kind":"data","monotonic_ns":228861795083416,"payload":{"event_type":"price_change","market":"0xeb66215f2e9faa6449e30a02bab5b8ed7b79a38bf961f6b24d0073c9c2419250","price_changes":[{"asset_id":"69697746896130839564035629862476347944307040470122503199396727085502753297492","best_ask":"0.24","best_bid":"0.23","hash":"c6a623569e6f8c73ecb8528e91a034523384af81","price":"0.14","side":"BUY","size":"219.9"},{"asset_id":"60386828328910021732068595344565885737045900010034836345809386672230885527307","best_ask":"0.77","best_bid":"0.76","hash":"a6e352eda89e6233d32e221eb82de38523129efb","price":"0.86","side":"SELL","size":"219.9"}],"timestamp":"1785126878582"},"payload_hash":"72138dcc388b0c10ee1ad8618bd5a08c2e5a74bc358991721246ac9689bac237","raw_frame":"{\"market\":\"0xeb66215f2e9faa6449e30a02bab5b8ed7b79a38bf961f6b24d0073c9c2419250\", \"price_changes\":[{\"asset_id\":\"69697746896130839564035629862476347944307040470122503199396727085502753297492\", \"price\":\"0.14\", \"size\":\"219.9\", \"side\":\"BUY\", \"hash\":\"c6a623569e6f8c73ecb8528e91a034523384af81\", \"best_bid\":\"0.23\", \"best_ask\":\"0.24\"}, {\"asset_id\":\"60386828328910021732068595344565885737045900010034836345809386672230885527307\", \"price\":\"0.86\", \"size\":\"219.9\", \"side\":\"SELL\", \"hash\":\"a6e352eda89e6233d32e221eb82de38523129efb\", \"best_bid\":\"0.76\", \"best_ask\":\"0.77\"}], \"timestamp\":\"1785126878582\", \"event_type\":\"price_change\"}","received_at":"2026-07-27T04:34:38.527657Z","schema_version":"clob-market-ws.price_change.v1","sequence":null,"server_hash":null,"server_timestamp":"1785126878582","session_id":"e9443c7415a0419799bee9cfbb1a9e4d","source":"clob_market_ws"},"received_at":"2026-07-27T04:34:38.527657Z","record_id":"795e83f2ad222098f0d116a7281736b9e348bf6ce4d513fe5b8bb7f6e63c6d8c","schema_fingerprint":"4aa3821a28b0b7c2400bc59aba4bcc0a76e971dadd19610d3ad38c768e124dc7","schema_version":"edge-lab-recorder.raw.v1","sequence":null,"source":"clob_market_ws"}
{"event_at":"2026-07-27T04:34:38.588000Z","event_fingerprint":"76ee4d2c03dd9f07ca420446fc569c0c90325c7509271b498d70b941c7b84bf2","payload":{"connection_id":"0f4979d6978d463e9660b042fdcf555f","event_at":"2026-07-27T04:34:38.588000Z","event_type":"price_change","frame_hash":"1c850ad6643ef2f657f269aa619a30b0a20177d546436486f1500a13e8462ae7","frame_index":0,"kind":"data","monotonic_ns":228861800880208,"payload":{"event_type":"price_change","market":"0xeb66215f2e9faa6449e30a02bab5b8ed7b79a38bf961f6b24d0073c9c2419250","price_changes":[{"asset_id":"69697746896130839564035629862476347944307040470122503199396727085502753297492","best_ask":"0.24","best_bid":"0.23","hash":"bdc71b11aa1d5d413f54cb58d6f52adedf65127a","price":"0.17","side":"BUY","size":"117.77"},{"asset_id":"60386828328910021732068595344565885737045900010034836345809386672230885527307","best_ask":"0.77","best_bid":"0.76","hash":"42f1b3888d782cf603b5eb76ed2f19b2689aea29","price":"0.83","side":"SELL","size":"117.77"}],"timestamp":"1785126878588"},"payload_hash":"0daf7872b6b3c04032643f6e9c3d629037e3e3b169f83eb23bb2cce6e2f6690b","raw_frame":"{\"market\":\"0xeb66215f2e9faa6449e30a02bab5b8ed7b79a38bf961f6b24d0073c9c2419250\", \"price_changes\":[{\"asset_id\":\"69697746896130839564035629862476347944307040470122503199396727085502753297492\", \"price\":\"0.17\", \"size\":\"117.77\", \"side\":\"BUY\", \"hash\":\"bdc71b11aa1d5d413f54cb58d6f52adedf65127a\", \"best_bid\":\"0.23\", \"best_ask\":\"0.24\"}, {\"asset_id\":\"60386828328910021732068595344565885737045900010034836345809386672230885527307\", \"price\":\"0.83\", \"size\":\"117.77\", \"side\":\"SELL\", \"hash\":\"42f1b3888d782cf603b5eb76ed2f19b2689aea29\", \"best_bid\":\"0.76\", \"best_ask\":\"0.77\"}], \"timestamp\":\"1785126878588\", \"event_type\":\"price_change\"}","received_at":"2026-07-27T04:34:38.533456Z","schema_version":"clob-market-ws.price_change.v1","sequence":null,"server_hash":null,"server_timestamp":"1785126878588","session_id":"e9443c7415a0419799bee9cfbb1a9e4d","source":"clob_market_ws"},"received_at":"2026-07-27T04:34:38.533456Z","record_id":"7909f5ffd3d2b318d00fbdc52b143cfb013c9504368efb15157e716e4afdbb45","schema_fingerprint":"4aa3821a28b0b7c2400bc59aba4bcc0a76e971dadd19610d3ad38c768e124dc7","schema_version":"edge-lab-recorder.raw.v1","sequence":null,"source":"clob_market_ws"}
{"event_at":"2026-07-27T04:34:38.589000Z","event_fingerprint":"c6e82bd27acee54e66b132adf8cabf982fdd727a4ab52a9d81df14f7c862d062","payload":{"connection_id":"0f4979d6978d463e9660b042fdcf555f","event_at":"2026-07-27T04:34:38.589000Z","event_type":"price_change","frame_hash":"da0a40cc386c297a3a33526947507353d239dbf7735df3e0b9ee63fc63df0bf9","frame_index":0,"kind":"data","monotonic_ns":228861802418375,"payload":{"event_type":"price_change","market":"0xeb66215f2e9faa6449e30a02bab5b8ed7b79a38bf961f6b24d0073c9c2419250","price_changes":[{"asset_id":"69697746896130839564035629862476347944307040470122503199396727085502753297492","best_ask":"0.24","best_bid":"0.23","hash":"ac239274c524f32c43acc1c9787341ebd9919f1f","price":"0.19","side":"BUY","size":"160.91"},{"asset_id":"60386828328910021732068595344565885737045900010034836345809386672230885527307","best_ask":"0.77","best_bid":"0.76","hash":"3cb9ed2bda5ca1fe5ebf613b369f8162db5ce3da","price":"0.81","side":"SELL","size":"160.91"}],"timestamp":"1785126878589"},"payload_hash":"d3a393f01a2f8fa4dfa2eb00e30a0e2e83a095dd99d4be9ef6f7119bf901654d","raw_frame":"{\"market\":\"0xeb66215f2e9faa6449e30a02bab5b8ed7b79a38bf961f6b24d0073c9c2419250\", \"price_changes\":[{\"asset_id\":\"69697746896130839564035629862476347944307040470122503199396727085502753297492\", \"price\":\"0.19\", \"size\":\"160.91\", \"side\":\"BUY\", \"hash\":\"ac239274c524f32c43acc1c9787341ebd9919f1f\", \"best_bid\":\"0.23\", \"best_ask\":\"0.24\"}, {\"asset_id\":\"60386828328910021732068595344565885737045900010034836345809386672230885527307\", \"price\":\"0.81\", \"size\":\"160.91\", \"side\":\"SELL\", \"hash\":\"3cb9ed2bda5ca1fe5ebf613b369f8162db5ce3da\", \"best_bid\":\"0.76\", \"best_ask\":\"0.77\"}], \"timestamp\":\"1785126878589\", \"event_type\":\"price_change\"}","received_at":"2026-07-27T04:34:38.534996Z","schema_version":"clob-market-ws.price_change.v1","sequence":null,"server_hash":null,"server_timestamp":"1785126878589","session_id":"e9443c7415a0419799bee9cfbb1a9e4d","source":"clob_market_ws"},"received_at":"2026-07-27T04:34:38.534996Z","record_id":"723c950f2eceecb97066b2c73a6c8afd1f516bc435819b1be454d8a94ead8d9e","schema_fingerprint":"4aa3821a28b0b7c2400bc59aba4bcc0a76e971dadd19610d3ad38c768e124dc7","schema_version":"edge-lab-recorder.raw.v1","sequence":null,"source":"clob_market_ws"}
{"event_at":"2026-07-27T04:34:38.609000Z","event_fingerprint":"2dec30fee26d9b8c208bf28eb2acc99d1d05e3e46e833d108ffa216e9692d516","payload":{"connection_id":"0f4979d6978d463e9660b042fdcf555f","event_at":"2026-07-27T04:34:38.609000Z","event_type":"price_change","frame_hash":"bcd594b05f3a5ce90e2a9946f46684c0b6edf36732b06006ab79e80ae149f371","frame_index":0,"kind":"data","monotonic_ns":228861822693041,"payload":{"event_type":"price_change","market":"0xeb66215f2e9faa6449e30a02bab5b8ed7b79a38bf961f6b24d0073c9c2419250","price_changes":[{"asset_id":"69697746896130839564035629862476347944307040470122503199396727085502753297492","best_ask":"0.24","best_bid":"0.23","hash":"f2a2f7456b9a58b86079cfc4b59e4d33c7282cd6","price":"0.27","side":"SELL","size":"304.62"},{"asset_id":"60386828328910021732068595344565885737045900010034836345809386672230885527307","best_ask":"0.77","best_bid":"0.76","hash":"6176af37e9df984586993f09fb4573c9702eadb6","price":"0.73","side":"BUY","size":"304.62"}],"timestamp":"1785126878609"},"payload_hash":"a89363b4beff8dcf7bf436ed2a26f3c89aa28b50002ebfc3e50a7ba44f16ca61","raw_frame":"{\"market\":\"0xeb66215f2e9faa6449e30a02bab5b8ed7b79a38bf961f6b24d0073c9c2419250\", \"price_changes\":[{\"asset_id\":\"69697746896130839564035629862476347944307040470122503199396727085502753297492\", \"price\":\"0.27\", \"size\":\"304.62\", \"side\":\"SELL\", \"hash\":\"f2a2f7456b9a58b86079cfc4b59e4d33c7282cd6\", \"best_bid\":\"0.23\", \"best_ask\":\"0.24\"}, {\"asset_id\":\"60386828328910021732068595344565885737045900010034836345809386672230885527307\", \"price\":\"0.73\", \"size\":\"304.62\", \"side\":\"BUY\", \"hash\":\"6176af37e9df984586993f09fb4573c9702eadb6\", \"best_bid\":\"0.76\", \"best_ask\":\"0.77\"}], \"timestamp\":\"1785126878609\", \"event_type\":\"price_change\"}","received_at":"2026-07-27T04:34:38.555268Z","schema_version":"clob-market-ws.price_change.v1","sequence":null,"server_hash":null,"server_timestamp":"1785126878609","session_id":"e9443c7415a0419799bee9cfbb1a9e4d","source":"clob_market_ws"},"received_at":"2026-07-27T04:34:38.555268Z","record_id":"a0468c007e250217deb739d84b066ee27c2941c793d94c087f57b2e10bdc119f","schema_fingerprint":"4aa3821a28b0b7c2400bc59aba4bcc0a76e971dadd19610d3ad38c768e124dc7","schema_version":"edge-lab-recorder.raw.v1","sequence":null,"source":"clob_market_ws"}
{"event_at":"2026-07-27T04:34:38.611000Z","event_fingerprint":"f5eb8cd47d37ceb0d168ecf2daf66bc5b03e57949bf2c92e088698097c8f3579","payload":{"connection_id":"0f4979d6978d463e9660b042fdcf555f","event_at":"2026-07-27T04:34:38.611000Z","event_type":"price_change","frame_hash":"e35c7c9bd4892bcd55c19dd0b9ab2260375f3aa8920f22e0f1360b7abb704d66","frame_index":0,"kind":"data","monotonic_ns":228861824866083,"payload":{"event_type":"price_change","market":"0xeb66215f2e9faa6449e30a02bab5b8ed7b79a38bf961f6b24d0073c9c2419250","price_changes":[{"asset_id":"60386828328910021732068595344565885737045900010034836345809386672230885527307","best_ask":"0.77","best_bid":"0.76","hash":"580ebb763fe27b29dc8a43083628e0517dcd6c62","price":"0.8","side":"SELL","size":"52.64"},{"asset_id":"69697746896130839564035629862476347944307040470122503199396727085502753297492","best_ask":"0.24","best_bid":"0.23","hash":"75c49a56fe8a3fef69d43c1a2d3b33faf2b9ce99","price":"0.2","side":"BUY","size":"52.64"}],"timestamp":"1785126878611"},"payload_hash":"d9fa9c55e9be0cbd98a1235f7f2de2a8189b6a82af16b682cd849c0d879e915e","raw_frame":"{\"market\":\"0xeb66215f2e9faa6449e30a02bab5b8ed7b79a38bf961f6b24d0073c9c2419250\", \"price_changes\":[{\"asset_id\":\"60386828328910021732068595344565885737045900010034836345809386672230885527307\", \"price\":\"0.8\", \"size\":\"52.64\", \"side\":\"SELL\", \"hash\":\"580ebb763fe27b29dc8a43083628e0517dcd6c62\", \"best_bid\":\"0.76\", \"best_ask\":\"0.77\"}, {\"asset_id\":\"69697746896130839564035629862476347944307040470122503199396727085502753297492\", \"price\":\"0.2\", \"size\":\"52.64\", \"side\":\"BUY\", \"hash\":\"75c49a56fe8a3fef69d43c1a2d3b33faf2b9ce99\", \"best_bid\":\"0.23\", \"best_ask\":\"0.24\"}], \"timestamp\":\"1785126878611\", \"event_type\":\"price_change\"}","received_at":"2026-07-27T04:34:38.557441Z","schema_version":"clob-market-ws.price_change.v1","sequence":null,"server_hash":null,"server_timestamp":"1785126878611","session_id":"e9443c7415a0419799bee9cfbb1a9e4d","source":"clob_market_ws"},"received_at":"2026-07-27T04:34:38.557441Z","record_id":"e2487d7c7831000575b576e3adb3ecd5068872f4805da2283a77b54a3db85040","schema_fingerprint":"4aa3821a28b0b7c2400bc59aba4bcc0a76e971dadd19610d3ad38c768e124dc7","schema_version":"edge-lab-recorder.raw.v1","sequence":null,"source":"clob_market_ws"}
{"event_at":"2026-07-27T04:34:38.612000Z","event_fingerprint":"c0137885b0ed6fcdfcce6c6eef9bcf2fa8d31e37dd4906112fae2da5d3f3a199","payload":{"connection_id":"0f4979d6978d463e9660b042fdcf555f","event_at":"2026-07-27T04:34:38.612000Z","event_type":"price_change","frame_hash":"c8b2964f41900dc69b45a1297a2527d2b51151566e1890496d61989e3c2671a8","frame_index":0,"kind":"data","monotonic_ns":228861826419583,"payload":{"event_type":"price_change","market":"0xeb66215f2e9faa6449e30a02bab5b8ed7b79a38bf961f6b24d0073c9c2419250","price_changes":[{"asset_id":"60386828328910021732068595344565885737045900010034836345809386672230885527307","best_ask":"0.77","best_bid":"0.76","hash":"b76d30fbe2ee2845a50b6f9dcc2ba7458d0678c7","price":"0.73","side":"BUY","size":"334.66"},{"asset_id":"69697746896130839564035629862476347944307040470122503199396727085502753297492","best_ask":"0.24","best_bid":"0.23","hash":"704167159b00e73bf60961c5664f09b109c587a3","price":"0.27","side":"SELL","size":"334.66"}],"timestamp":"1785126878612"},"payload_hash":"ed7fa275ddfef82e854e7005d91617d5ec3c881d08dffa4ff6f7e103387dbe6f","raw_frame":"{\"market\":\"0xeb66215f2e9faa6449e30a02bab5b8ed7b79a38bf961f6b24d0073c9c2419250\", \"price_changes\":[{\"asset_id\":\"60386828328910021732068595344565885737045900010034836345809386672230885527307\", \"price\":\"0.73\", \"size\":\"334.66\", \"side\":\"BUY\", \"hash\":\"b76d30fbe2ee2845a50b6f9dcc2ba7458d0678c7\", \"best_bid\":\"0.76\", \"best_ask\":\"0.77\"}, {\"asset_id\":\"69697746896130839564035629862476347944307040470122503199396727085502753297492\", \"price\":\"0.27\", \"size\":\"334.66\", \"side\":\"SELL\", \"hash\":\"704167159b00e73bf60961c5664f09b109c587a3\", \"best_bid\":\"0.23\", \"best_ask\":\"0.24\"}], \"timestamp\":\"1785126878612\", \"event_type\":\"price_change\"}","received_at":"2026-07-27T04:34:38.558996Z","schema_version":"clob-market-ws.price_change.v1","sequence":null,"server_hash":null,"server_timestamp":"1785126878612","session_id":"e9443c7415a0419799bee9cfbb1a9e4d","source":"clob_market_ws"},"received_at":"2026-07-27T04:34:38.558996Z","record_id":"84421ae5a3c17b38f4bf4dddcddc8d8d1c400d70b5e8fb1e0ea463d5f0f613b6","schema_fingerprint":"4aa3821a28b0b7c2400bc59aba4bcc0a76e971dadd19610d3ad38c768e124dc7","schema_version":"edge-lab-recorder.raw.v1","sequence":null,"source":"clob_market_ws"}
{"event_at":"2026-07-27T04:34:38.620000Z","event_fingerprint":"954b8cc558ff010eb679b73e7dd9058d26786d758d81b1f48a4822a38ec7b8df","payload":{"connection_id":"0f4979d6978d463e9660b042fdcf555f","event_at":"2026-07-27T04:34:38.620000Z","event_type":"price_change","frame_hash":"63d5c39bfdd246cd9144dc19e58181049a69bc68c4474de75a38b97ae47caea3","frame_index":0,"kind":"data","monotonic_ns":228861833861416,"payload":{"event_type":"price_change","market":"0xeb66215f2e9faa6449e30a02bab5b8ed7b79a38bf961f6b24d0073c9c2419250","price_changes":[{"asset_id":"69697746896130839564035629862476347944307040470122503199396727085502753297492","best_ask":"0.24","best_bid":"0.23","hash":"0ca53be2e7638f9ecfc404327237cd35238030a8","price":"0.18","side":"BUY","size":"144.91"},{"asset_id":"60386828328910021732068595344565885737045900010034836345809386672230885527307","best_ask":"0.77","best_bid":"0.76","hash":"4eedd5ff19c3d4e61d8262101d38b575af4a52ef","price":"0.82","side":"SELL","size":"144.91"}],"timestamp":"1785126878620"},"payload_hash":"b1a48af610b6096e7f9068fdc63d82ff66f2312024c207576f5a22ac675c400c","raw_frame":"{\"market\":\"0xeb66215f2e9faa6449e30a02bab5b8ed7b79a38bf961f6b24d0073c9c2419250\", \"price_changes\":[{\"asset_id\":\"69697746896130839564035629862476347944307040470122503199396727085502753297492\", \"price\":\"0.18\", \"size\":\"144.91\", \"side\":\"BUY\", \"hash\":\"0ca53be2e7638f9ecfc404327237cd35238030a8\", \"best_bid\":\"0.23\", \"best_ask\":\"0.24\"}, {\"asset_id\":\"60386828328910021732068595344565885737045900010034836345809386672230885527307\", \"price\":\"0.82\", \"size\":\"144.91\", \"side\":\"SELL\", \"hash\":\"4eedd5ff19c3d4e61d8262101d38b575af4a52ef\", \"best_bid\":\"0.76\", \"best_ask\":\"0.77\"}], \"timestamp\":\"1785126878620\", \"event_type\":\"price_change\"}","received_at":"2026-07-27T04:34:38.566437Z","schema_version":"clob-market-ws.price_change.v1","sequence":null,"server_hash":null,"server_timestamp":"1785126878620","session_id":"e9443c7415a0419799bee9cfbb1a9e4d","source":"clob_market_ws"},"received_at":"2026-07-27T04:34:38.566437Z","record_id":"9cd23437068e86bc4d5398346ac963440fac48c10ae5a6bfe26ed6c990c814d1","schema_fingerprint":"4aa3821a28b0b7c2400bc59aba4bcc0a76e971dadd19610d3ad38c768e124dc7","schema_version":"edge-lab-recorder.raw.v1","sequence":null,"source":"clob_market_ws"}
{"event_at":"2026-07-27T04:34:38.621000Z","event_fingerprint":"af781e27b279c67358e9696791866401708f6fcadce73e6384355417473d948c","payload":{"connection_id":"0f4979d6978d463e9660b042fdcf555f","event_at":"2026-07-27T04:34:38.621000Z","event_type":"price_change","frame_hash":"f597cca1520cc819d5bd039241dfc1f129c7dda1028ad829c934692014176313","frame_index":0,"kind":"data","monotonic_ns":228861835383541,"payload":{"event_type":"price_change","market":"0xeb66215f2e9faa6449e30a02bab5b8ed7b79a38bf961f6b24d0073c9c2419250","price_changes":[{"asset_id":"60386828328910021732068595344565885737045900010034836345809386672230885527307","best_ask":"0.77","best_bid":"0.76","hash":"2f1e5075b49f390b244eb7cc09656bb9dd816472","price":"0.74","side":"BUY","size":"32"},{"asset_id":"69697746896130839564035629862476347944307040470122503199396727085502753297492","best_ask":"0.24","best_bid":"0.23","hash":"19fef579c5f44c6846e01cb37f58938c78d9c5f6","price":"0.26","side":"SELL","size":"32"}],"timestamp":"1785126878621"},"payload_hash":"c9bc62a88ed733c96afd17d8857046762a4bd7e2a432c640a3757858d464adb8","raw_frame":"{\"market\":\"0xeb66215f2e9faa6449e30a02bab5b8ed7b79a38bf961f6b24d0073c9c2419250\", \"price_changes\":[{\"asset_id\":\"60386828328910021732068595344565885737045900010034836345809386672230885527307\", \"price\":\"0.74\", \"size\":\"32\", \"side\":\"BUY\", \"hash\":\"2f1e5075b49f390b244eb7cc09656bb9dd816472\", \"best_bid\":\"0.76\", \"best_ask\":\"0.77\"}, {\"asset_id\":\"69697746896130839564035629862476347944307040470122503199396727085502753297492\", \"price\":\"0.26\", \"size\":\"32\", \"side\":\"SELL\", \"hash\":\"19fef579c5f44c6846e01cb37f58938c78d9c5f6\", \"best_bid\":\"0.23\", \"best_ask\":\"0.24\"}], \"timestamp\":\"1785126878621\", \"event_type\":\"price_change\"}","received_at":"2026-07-27T04:34:38.567962Z","schema_version":"clob-market-ws.price_change.v1","sequence":null,"server_hash":null,"server_timestamp":"1785126878621","session_id":"e9443c7415a0419799bee9cfbb1a9e4d","source":"clob_market_ws"},"received_at":"2026-07-27T04:34:38.567962Z","record_id":"466186b8d0e8d67d17385192995e3a0b666f11299d0f0f992796f7128e4fced4","schema_fingerprint":"4aa3821a28b0b7c2400bc59aba4bcc0a76e971dadd19610d3ad38c768e124dc7","schema_version":"edge-lab-recorder.raw.v1","sequence":null,"source":"clob_market_ws"}
{"event_at":"2026-07-27T04:34:38.622000Z","event_fingerprint":"819d3661f4f46d5385808f92bc38234a88afc054f4e830c4522502b6e0224aec","payload":{"connection_id":"0f4979d6978d463e9660b042fdcf555f","event_at":"2026-07-27T04:34:38.622000Z","event_type":"price_change","frame_hash":"527c4c9c861bd6542e96844ebac67d1e27a03e459d076687f76e1045a11096a7","frame_index":0,"kind":"data","monotonic_ns":228861836982916,"payload":{"event_type":"price_change","market":"0xeb66215f2e9faa6449e30a02bab5b8ed7b79a38bf961f6b24d0073c9c2419250","price_changes":[{"asset_id":"60386828328910021732068595344565885737045900010034836345809386672230885527307","best_ask":"0.77","best_bid":"0.76","hash":"cb0855460aee23aa428c2d1c4f50f9b16c331106","price":"0.77","side":"SELL","size":"25"},{"asset_id":"69697746896130839564035629862476347944307040470122503199396727085502753297492","best_ask":"0.24","best_bid":"0.23","hash":"6c07b987787e9bc911d4f40b7e1f26967cf58368","price":"0.23","side":"BUY","size":"25"}],"timestamp":"1785126878622"},"payload_hash":"e0e49b57d5f1b088cbf85f11838cbbcbe86715cb865304704e4d89023d394746","raw_frame":"{\"market\":\"0xeb66215f2e9faa6449e30a02bab5b8ed7b79a38bf961f6b24d0073c9c2419250\", \"price_changes\":[{\"asset_id\":\"60386828328910021732068595344565885737045900010034836345809386672230885527307\", \"price\":\"0.77\", \"size\":\"25\", \"side\":\"SELL\", \"hash\":\"cb0855460aee23aa428c2d1c4f50f9b16c331106\", \"best_bid\":\"0.76\", \"best_ask\":\"0.77\"}, {\"asset_id\":\"69697746896130839564035629862476347944307040470122503199396727085502753297492\", \"price\":\"0.23\", \"size\":\"25\", \"side\":\"BUY\", \"hash\":\"6c07b987787e9bc911d4f40b7e1f26967cf58368\", \"best_bid\":\"0.23\", \"best_ask\":\"0.24\"}], \"timestamp\":\"1785126878622\", \"event_type\":\"price_change\"}","received_at":"2026-07-27T04:34:38.569561Z","schema_version":"clob-market-ws.price_change.v1","sequence":null,"server_hash":null,"server_timestamp":"1785126878622","session_id":"e9443c7415a0419799bee9cfbb1a9e4d","source":"clob_market_ws"},"received_at":"2026-07-27T04:34:38.569561Z","record_id":"a05fff14c9611bdb790bc296045dbd4ca48dd38ed95b07751d9e0ff54064f23f","schema_fingerprint":"4aa3821a28b0b7c2400bc59aba4bcc0a76e971dadd19610d3ad38c768e124dc7","schema_version":"edge-lab-recorder.raw.v1","sequence":null,"source":"clob_market_ws"}
{"event_at":"2026-07-27T04:34:38.625000Z","event_fingerprint":"69d0924fdef4b1cbf91f5230497535ef8fd1736a59f76fe13bc87f9a21bc16df","payload":{"connection_id":"0f4979d6978d463e9660b042fdcf555f","event_at":"2026-07-27T04:34:38.625000Z","event_type":"best_bid_ask","frame_hash":"957b8d5375a7673f72c04d073fc2f3027750e73ec468ea6c0b12ab392a222544","frame_index":0,"kind":"data","monotonic_ns":228861839199250,"payload":{"asset_id":"69697746896130839564035629862476347944307040470122503199396727085502753297492","best_ask":"0.24","best_bid":"0.22","event_type":"best_bid_ask","market":"0xeb66215f2e9faa6449e30a02bab5b8ed7b79a38bf961f6b24d0073c9c2419250","spread":"0.02","timestamp":"1785126878625"},"payload_hash":"94d99964ff497fa68192d2765fca63fcb11ca301da466ecc484e789e2690bd1e","raw_frame":"{\"market\":\"0xeb66215f2e9faa6449e30a02bab5b8ed7b79a38bf961f6b24d0073c9c2419250\", \"asset_id\":\"69697746896130839564035629862476347944307040470122503199396727085502753297492\", \"best_bid\":\"0.22\", \"best_ask\":\"0.24\", \"spread\":\"0.02\", \"timestamp\":\"1785126878625\", \"event_type\":\"best_bid_ask\"}","received_at":"2026-07-27T04:34:38.571778Z","schema_version":"clob-market-ws.best_bid_ask.v1","sequence":null,"server_hash":null,"server_timestamp":"1785126878625","session_id":"e9443c7415a0419799bee9cfbb1a9e4d","source":"clob_market_ws"},"received_at":"2026-07-27T04:34:38.571778Z","record_id":"f95b9499a867013ca03af282e04b72d1a7482a50fe3da03389861590a8bf0280","schema_fingerprint":"8488399f31b0337811b13b266be932db7062827c2470b78bd8e9e99bab51d17d","schema_version":"edge-lab-recorder.raw.v1","sequence":null,"source":"clob_market_ws"}
{"event_at":"2026-07-27T04:34:38.625000Z","event_fingerprint":"c9e0457880b404678181012999e79c928ee28c650ab273f1c0d152ee9732e3a9","payload":{"connection_id":"0f4979d6978d463e9660b042fdcf555f","event_at":"2026-07-27T04:34:38.625000Z","event_type":"best_bid_ask","frame_hash":"3b7f1a55d803aa454c7052810e2e41f0afe0d377123fa13c55aed1a9558281cd","frame_index":0,"kind":"data","monotonic_ns":228861840276708,"payload":{"asset_id":"60386828328910021732068595344565885737045900010034836345809386672230885527307","best_ask":"0.78","best_bid":"0.76","event_type":"best_bid_ask","market":"0xeb66215f2e9faa6449e30a02bab5b8ed7b79a38bf961f6b24d0073c9c2419250","spread":"0.02","timestamp":"1785126878625"},"payload_hash":"e765a1dd9d6a626b5acdb61d061a0a010cc9b35069402a1edcee37f438221f12","raw_frame":"{\"market\":\"0xeb66215f2e9faa6449e30a02bab5b8ed7b79a38bf961f6b24d0073c9c2419250\", \"asset_id\":\"60386828328910021732068595344565885737045900010034836345809386672230885527307\", \"best_bid\":\"0.76\", \"best_ask\":\"0.78\", \"spread\":\"0.02\", \"timestamp\":\"1785126878625\", \"event_type\":\"best_bid_ask\"}","received_at":"2026-07-27T04:34:38.572857Z","schema_version":"clob-market-ws.best_bid_ask.v1","sequence":null,"server_hash":null,"server_timestamp":"1785126878625","session_id":"e9443c7415a0419799bee9cfbb1a9e4d","source":"clob_market_ws"},"received_at":"2026-07-27T04:34:38.572857Z","record_id":"dafd85fe8821da56e442053688a26f574f5e2629af428a174a1c2623c0e1fee6","schema_fingerprint":"8488399f31b0337811b13b266be932db7062827c2470b78bd8e9e99bab51d17d","schema_version":"edge-lab-recorder.raw.v1","sequence":null,"source":"clob_market_ws"}
{"event_at":"2026-07-27T04:34:38.625000Z","event_fingerprint":"aa58127f0d721470df0a6613bb707bc63be58ed4c0141952bf6b81bd92af6e18","payload":{"connection_id":"0f4979d6978d463e9660b042fdcf555f","event_at":"2026-07-27T04:34:38.625000Z","event_type":"price_change","frame_hash":"9ed9344e8e5c098c1a1fa5b8daee95ebfc3c0497268cbd963f18e582f6b04558","frame_index":0,"kind":"data","monotonic_ns":228861841377291,"payload":{"event_type":"price_change","market":"0xeb66215f2e9faa6449e30a02bab5b8ed7b79a38bf961f6b24d0073c9c2419250","price_changes":[{"asset_id":"69697746896130839564035629862476347944307040470122503199396727085502753297492","best_ask":"0.24","best_bid":"0.22","hash":"66ce6d4a44011aec8bf5dd702993433c9a7eef2c","price":"0.23","side":"BUY","size":"0"},{"asset_id":"60386828328910021732068595344565885737045900010034836345809386672230885527307","best_ask":"0.78","best_bid":"0.76","hash":"5f8bbc3b49ab51b9fd62453bcb8652b3411bcf08","price":"0.77","side":"SELL","size":"0"}],"timestamp":"1785126878625"},"payload_hash":"1f61145f43655113a7ad01ca40d31d023bdc482585c12218a4284625901431b5","raw_frame":"{\"market\":\"0xeb66215f2e9faa6449e30a02bab5b8ed7b79a38bf961f6b24d0073c9c2419250\", \"price_changes\":[{\"asset_id\":\"69697746896130839564035629862476347944307040470122503199396727085502753297492\", \"price\":\"0.23\", \"size\":\"0\", \"side\":\"BUY\", \"hash\":\"66ce6d4a44011aec8bf5dd702993433c9a7eef2c\", \"best_bid\":\"0.22\", \"best_ask\":\"0.24\"}, {\"asset_id\":\"60386828328910021732068595344565885737045900010034836345809386672230885527307\", \"price\":\"0.77\", \"size\":\"0\", \"side\":\"SELL\", \"hash\":\"5f8bbc3b49ab51b9fd62453bcb8652b3411bcf08\", \"best_bid\":\"0.76\", \"best_ask\":\"0.78\"}], \"timestamp\":\"1785126878625\", \"event_type\":\"price_change\"}","received_at":"2026-07-27T04:34:38.573953Z","schema_version":"clob-market-ws.price_change.v1","sequence":null,"server_hash":null,"server_timestamp":"1785126878625","session_id":"e9443c7415a0419799bee9cfbb1a9e4d","source":"clob_market_ws"},"received_at":"2026-07-27T04:34:38.573953Z","record_id":"dd9f4511e831267ef0342c17eab466be470f142909f819f4b007289adea21d9c","schema_fingerprint":"4aa3821a28b0b7c2400bc59aba4bcc0a76e971dadd19610d3ad38c768e124dc7","schema_version":"edge-lab-recorder.raw.v1","sequence":null,"source":"clob_market_ws"}
{"event_at":"2026-07-27T04:34:38.631000Z","event_fingerprint":"942d2578ac1edb263edc1a35bf2a81958b68f9d0e9c654ff4a72d9956421fac0","payload":{"connection_id":"0f4979d6978d463e9660b042fdcf555f","event_at":"2026-07-27T04:34:38.631000Z","event_type":"price_change","frame_hash":"613b2c4b715953b6bef5a3a7d4dbec4e2cd28a4f01a34683940f2987f53badb0","frame_index":0,"kind":"data","monotonic_ns":228861843900416,"payload":{"event_type":"price_change","market":"0xeb66215f2e9faa6449e30a02bab5b8ed7b79a38bf961f6b24d0073c9c2419250","price_changes":[{"asset_id":"69697746896130839564035629862476347944307040470122503199396727085502753297492","best_ask":"0.24","best_bid":"0.22","hash":"d4db040717294bd5ab0c14c74424e9c70125d5f9","price":"0.26","side":"SELL","size":"57"},{"asset_id":"60386828328910021732068595344565885737045900010034836345809386672230885527307","best_ask":"0.78","best_bid":"0.76","hash":"0395ff648071108f0c90244675cae305060cc062","price":"0.74","side":"BUY","size":"57"}],"timestamp":"1785126878631"},"payload_hash":"c79c6827ccf037f4855dbc818d17096eb3671f9ec4742b666d8d8774cb7cb780","raw_frame":"{\"market\":\"0xeb66215f2e9faa6449e30a02bab5b8ed7b79a38bf961f6b24d0073c9c2419250\", \"price_changes\":[{\"asset_id\":\"69697746896130839564035629862476347944307040470122503199396727085502753297492\", \"price\":\"0.26\", \"size\":\"57\", \"side\":\"SELL\", \"hash\":\"d4db040717294bd5ab0c14c74424e9c70125d5f9\", \"best_bid\":\"0.22\", \"best_ask\":\"0.24\"}, {\"asset_id\":\"60386828328910021732068595344565885737045900010034836345809386672230885527307\", \"price\":\"0.74\", \"size\":\"57\", \"side\":\"BUY\", \"hash\":\"0395ff648071108f0c90244675cae305060cc062\", \"best_bid\":\"0.76\", \"best_ask\":\"0.78\"}], \"timestamp\":\"1785126878631\", \"event_type\":\"price_change\"}","received_at":"2026-07-27T04:34:38.576479Z","schema_version":"clob-market-ws.price_change.v1","sequence":null,"server_hash":null,"server_timestamp":"1785126878631","session_id":"e9443c7415a0419799bee9cfbb1a9e4d","source":"clob_market_ws"},"received_at":"2026-07-27T04:34:38.576479Z","record_id":"8430976fd49810346647461e7b840bcb5f30df2cc1f3df5804dbb8c3cfe7d5eb","schema_fingerprint":"4aa3821a28b0b7c2400bc59aba4bcc0a76e971dadd19610d3ad38c768e124dc7","schema_version":"edge-lab-recorder.raw.v1","sequence":null,"source":"clob_market_ws"}
{"event_at":"2026-07-27T04:34:38.634000Z","event_fingerprint":"013f6e0627c68912f9b70016cc91bc5ea2ef398c7ce17a3fe51344d55cc84424","payload":{"connection_id":"0f4979d6978d463e9660b042fdcf555f","event_at":"2026-07-27T04:34:38.634000Z","event_type":"best_bid_ask","frame_hash":"d70d9581d00749fe614f121f254fb3ec4324a380eee73045e8cf823befb6160f","frame_index":0,"kind":"data","monotonic_ns":228861847466333,"payload":{"asset_id":"69697746896130839564035629862476347944307040470122503199396727085502753297492","best_ask":"0.23","best_bid":"0.22","event_type":"best_bid_ask","market":"0xeb66215f2e9faa6449e30a02bab5b8ed7b79a38bf961f6b24d0073c9c2419250","spread":"0.01","timestamp":"1785126878634"},"payload_hash":"51ef953759159ca9a5b569429d4af89d9b2a5334d55dd5c8b795e384f740fb72","raw_frame":"{\"market\":\"0xeb66215f2e9faa6449e30a02bab5b8ed7b79a38bf961f6b24d0073c9c2419250\", \"asset_id\":\"69697746896130839564035629862476347944307040470122503199396727085502753297492\", \"best_bid\":\"0.22\", \"best_ask\":\"0.23\", \"spread\":\"0.01\", \"timestamp\":\"1785126878634\", \"event_type\":\"best_bid_ask\"}","received_at":"2026-07-27T04:34:38.580043Z","schema_version":"clob-market-ws.best_bid_ask.v1","sequence":null,"server_hash":null,"server_timestamp":"1785126878634","session_id":"e9443c7415a0419799bee9cfbb1a9e4d","source":"clob_market_ws"},"received_at":"2026-07-27T04:34:38.580043Z","record_id":"b452d562c89b32a3bb0e77df77b990e232c0944fe633d2bbed15e1ac13c657ef","schema_fingerprint":"8488399f31b0337811b13b266be932db7062827c2470b78bd8e9e99bab51d17d","schema_version":"edge-lab-recorder.raw.v1","sequence":null,"source":"clob_market_ws"}
{"event_at":"2026-07-27T04:34:38.634000Z","event_fingerprint":"86ee305557c3fd704357bc9e667880290a6e23d881eb31053918ac83977c7e24","payload":{"connection_id":"0f4979d6978d463e9660b042fdcf555f","event_at":"2026-07-27T04:34:38.634000Z","event_type":"best_bid_ask","frame_hash":"f833c7a406966d4dc4fcb146a9e1df15a3f45575405b62732bc2a47354d9ed06","frame_index":0,"kind":"data","monotonic_ns":228861848532625,"payload":{"asset_id":"60386828328910021732068595344565885737045900010034836345809386672230885527307","best_ask":"0.78","best_bid":"0.77","event_type":"best_bid_ask","market":"0xeb66215f2e9faa6449e30a02bab5b8ed7b79a38bf961f6b24d0073c9c2419250","spread":"0.01","timestamp":"1785126878634"},"payload_hash":"3bbdcdcc1acad6e0c20f24ac72cc4032f1da69515d88193d6e453be597851b42","raw_frame":"{\"market\":\"0xeb66215f2e9faa6449e30a02bab5b8ed7b79a38bf961f6b24d0073c9c2419250\", \"asset_id\":\"60386828328910021732068595344565885737045900010034836345809386672230885527307\", \"best_bid\":\"0.77\", \"best_ask\":\"0.78\", \"spread\":\"0.01\", \"timestamp\":\"1785126878634\", \"event_type\":\"best_bid_ask\"}","received_at":"2026-07-27T04:34:38.581110Z","schema_version":"clob-market-ws.best_bid_ask.v1","sequence":null,"server_hash":null,"server_timestamp":"1785126878634","session_id":"e9443c7415a0419799bee9cfbb1a9e4d","source":"clob_market_ws"},"received_at":"2026-07-27T04:34:38.581110Z","record_id":"251846d6a0c07e67e6b49120c830e24d6766a0a172db1cca1d107c449e5aad6d","schema_fingerprint":"8488399f31b0337811b13b266be932db7062827c2470b78bd8e9e99bab51d17d","schema_version":"edge-lab-recorder.raw.v1","sequence":null,"source":"clob_market_ws"}
{"event_at":"2026-07-27T04:34:38.634000Z","event_fingerprint":"2eeff00cf54d781c26d7e84506ae7bc337576dc69fde294f08992cd3c5440382","payload":{"connection_id":"0f4979d6978d463e9660b042fdcf555f","event_at":"2026-07-27T04:34:38.634000Z","event_type":"price_change","frame_hash":"51eca25e68e87aac290cd5274a98558644491eef3d494634791b8eca4b25f6ac","frame_index":0,"kind":"data","monotonic_ns":228861849720666,"payload":{"event_type":"price_change","market":"0xeb66215f2e9faa6449e30a02bab5b8ed7b79a38bf961f6b24d0073c9c2419250","price_changes":[{"asset_id":"60386828328910021732068595344565885737045900010034836345809386672230885527307","best_ask":"0.78","best_bid":"0.77","hash":"daca3babe8ba21f012813fa4e05a5f8855bae3b1","price":"0.77","side":"BUY","size":"40"},{"asset_id":"69697746896130839564035629862476347944307040470122503199396727085502753297492","best_ask":"0.23","best_bid":"0.22","hash":"ec02e9b5c0e8b7c621ed28fa0b1e0d2e662f3f17","price":"0.23","side":"SELL","size":"40"}],"timestamp":"1785126878634"},"payload_hash":"4cc22997644049108a6a2e01c549973f9f77240f1f0775e637bcaa92c43c5cd6","raw_frame":"{\"market\":\"0xeb66215f2e9faa6449e30a02bab5b8ed7b79a38bf961f6b24d0073c9c2419250\", \"price_changes\":[{\"asset_id\":\"60386828328910021732068595344565885737045900010034836345809386672230885527307\", \"price\":\"0.77\", \"size\":\"40\", \"side\":\"BUY\", \"hash\":\"daca3babe8ba21f012813fa4e05a5f8855bae3b1\", \"best_bid\":\"0.77\", \"best_ask\":\"0.78\"}, {\"asset_id\":\"69697746896130839564035629862476347944307040470122503199396727085502753297492\", \"price\":\"0.23\", \"size\":\"40\", \"side\":\"SELL\", \"hash\":\"ec02e9b5c0e8b7c621ed28fa0b1e0d2e662f3f17\", \"best_bid\":\"0.22\", \"best_ask\":\"0.23\"}], \"timestamp\":\"1785126878634\", \"event_type\":\"price_change\"}","received_at":"2026-07-27T04:34:38.582300Z","schema_version":"clob-market-ws.price_change.v1","sequence":null,"server_hash":null,"server_timestamp":"1785126878634","session_id":"e9443c7415a0419799bee9cfbb1a9e4d","source":"clob_market_ws"},"received_at":"2026-07-27T04:34:38.582300Z","record_id":"c6c28e4cce4533950b9ffa19375f12aeabd8ef29ed8802f4d81957a7bc58a9f6","schema_fingerprint":"4aa3821a28b0b7c2400bc59aba4bcc0a76e971dadd19610d3ad38c768e124dc7","schema_version":"edge-lab-recorder.raw.v1","sequence":null,"source":"clob_market_ws"}
{"event_at":"2026-07-27T04:34:38.635000Z","event_fingerprint":"b9eccf2bf32c66e69396f9cee7f62355ed0e7c5780e38986b31148801ef16f0f","payload":{"connection_id":"0f4979d6978d463e9660b042fdcf555f","event_at":"2026-07-27T04:34:38.635000Z","event_type":"price_change","frame_hash":"d663994698fc7d2070766d619de649ed141e7f2a6eb447453e05806725161a43","frame_index":0,"kind":"data","monotonic_ns":228861851241500,"payload":{"event_type":"price_change","market":"0xeb66215f2e9faa6449e30a02bab5b8ed7b79a38bf961f6b24d0073c9c2419250","price_changes":[{"asset_id":"60386828328910021732068595344565885737045900010034836345809386672230885527307","best_ask":"0.78","best_bid":"0.77","hash":"9e67d748ce8223edbc3c61e874cf2db519807a4e","price":"0.01","side":"BUY","size":"5708.02"},{"asset_id":"69697746896130839564035629862476347944307040470122503199396727085502753297492","best_ask":"0.23","best_bid":"0.22","hash":"0cebed83b0914beb7d07778bf593686848d0d842","price":"0.99","side":"SELL","size":"5708.02"}],"timestamp":"1785126878635"},"payload_hash":"d3f8c1bd77ca75f79abdce504d83637a5faf0130efa3285ed7a73334c20384b5","raw_frame":"{\"market\":\"0xeb66215f2e9faa6449e30a02bab5b8ed7b79a38bf961f6b24d0073c9c2419250\", \"price_changes\":[{\"asset_id\":\"60386828328910021732068595344565885737045900010034836345809386672230885527307\", \"price\":\"0.01\", \"size\":\"5708.02\", \"side\":\"BUY\", \"hash\":\"9e67d748ce8223edbc3c61e874cf2db519807a4e\", \"best_bid\":\"0.77\", \"best_ask\":\"0.78\"}, {\"asset_id\":\"69697746896130839564035629862476347944307040470122503199396727085502753297492\", \"price\":\"0.99\", \"size\":\"5708.02\", \"side\":\"SELL\", \"hash\":\"0cebed83b0914beb7d07778bf593686848d0d842\", \"best_bid\":\"0.22\", \"best_ask\":\"0.23\"}], \"timestamp\":\"1785126878635\", \"event_type\":\"price_change\"}","received_at":"2026-07-27T04:34:38.583821Z","schema_version":"clob-market-ws.price_change.v1","sequence":null,"server_hash":null,"server_timestamp":"1785126878635","session_id":"e9443c7415a0419799bee9cfbb1a9e4d","source":"clob_market_ws"},"received_at":"2026-07-27T04:34:38.583821Z","record_id":"945004188e93ce376181ad1bb3f72cf4635ff301a405c6fd70adfecb5fb8ebfd","schema_fingerprint":"4aa3821a28b0b7c2400bc59aba4bcc0a76e971dadd19610d3ad38c768e124dc7","schema_version":"edge-lab-recorder.raw.v1","sequence":null,"source":"clob_market_ws"}
{"event_at":"2026-07-27T04:34:38.644000Z","event_fingerprint":"ece2c5422a78afbd0e6952a94797f1f4e896c1bf4624493012458eddc7b8add8","payload":{"connection_id":"0f4979d6978d463e9660b042fdcf555f","event_at":"2026-07-27T04:34:38.644000Z","event_type":"price_change","frame_hash":"e01d5af94cdc03bc3f9710c958ded81ff0db124c6ee42d5f985bc11485706457","frame_index":0,"kind":"data","monotonic_ns":228861860175250,"payload":{"event_type":"price_change","market":"0xeb66215f2e9faa6449e30a02bab5b8ed7b79a38bf961f6b24d0073c9c2419250","price_changes":[{"asset_id":"60386828328910021732068595344565885737045900010034836345809386672230885527307","best_ask":"0.78","best_bid":"0.77","hash":"4ea5603b6bf106e2968224faeadd55691a844bfb","price":"0.78","side":"SELL","size":"332.6"},{"asset_id":"69697746896130839564035629862476347944307040470122503199396727085502753297492","best_ask":"0.23","best_bid":"0.22","hash":"9bff49c9df9680eddd23150611f3562cc421cedc","price":"0.22","side":"BUY","size":"332.6"}],"timestamp":"1785126878644"},"payload_hash":"b730c94f163bfb5f31753e86d6e7cb5d59888d4e3b7bfb4b10e02e999c509072","raw_frame":"{\"market\":\"0xeb66215f2e9faa6449e30a02bab5b8ed7b79a38bf961f6b24d0073c9c2419250\", \"price_changes\":[{\"asset_id\":\"60386828328910021732068595344565885737045900010034836345809386672230885527307\", \"price\":\"0.78\", \"size\":\"332.6\", \"side\":\"SELL\", \"hash\":\"4ea5603b6bf106e2968224faeadd55691a844bfb\", \"best_bid\":\"0.77\", \"best_ask\":\"0.78\"}, {\"asset_id\":\"69697746896130839564035629862476347944307040470122503199396727085502753297492\", \"price\":\"0.22\", \"size\":\"332.6\", \"side\":\"BUY\", \"hash\":\"9bff49c9df9680eddd23150611f3562cc421cedc\", \"best_bid\":\"0.22\", \"best_ask\":\"0.23\"}], \"timestamp\":\"1785126878644\", \"event_type\":\"price_change\"}","received_at":"2026-07-27T04:34:38.592750Z","schema_version":"clob-market-ws.price_change.v1","sequence":null,"server_hash":null,"server_timestamp":"1785126878644","session_id":"e9443c7415a0419799bee9cfbb1a9e4d","source":"clob_market_ws"},"received_at":"2026-07-27T04:34:38.592750Z","record_id":"c7e1e00a0c95f8fce80f2566d553b8e071380c0039ee805e4309ae271ff23ff8","schema_fingerprint":"4aa3821a28b0b7c2400bc59aba4bcc0a76e971dadd19610d3ad38c768e124dc7","schema_version":"edge-lab-recorder.raw.v1","sequence":null,"source":"clob_market_ws"}
{"event_at":"2026-07-27T04:34:38.648000Z","event_fingerprint":"de85750a86e90b51bdc7a57a48a510937983678371914a3743113a46d96f6c7f","payload":{"connection_id":"0f4979d6978d463e9660b042fdcf555f","event_at":"2026-07-27T04:34:38.648000Z","event_type":"price_change","frame_hash":"430f979325df7085d4ea419eede19d68c415a6385d4f7a3f3ed00b3fb20c0788","frame_index":0,"kind":"data","monotonic_ns":228861861713208,"payload":{"event_type":"price_change","market":"0xeb66215f2e9faa6449e30a02bab5b8ed7b79a38bf961f6b24d0073c9c2419250","price_changes":[{"asset_id":"69697746896130839564035629862476347944307040470122503199396727085502753297492","best_ask":"0.23","best_bid":"0.22","hash":"e981a103a951d31c76967ca99e03677c55fd5bd5","price":"0.16","side":"BUY","size":"525.63"},{"asset_id":"60386828328910021732068595344565885737045900010034836345809386672230885527307","best_ask":"0.78","best_bid":"0.77","hash":"c07cfeed080e69b671e0cbd34227ddf1bb473f4c","price":"0.84","side":"SELL","size":"525.63"}],"timestamp":"1785126878648"},"payload_hash":"e7a4c69d356fbac0f02c5293180ba76cc9b1af150a66260d1aacd9bd87fe544a","raw_frame":"{\"market\":\"0xeb66215f2e9faa6449e30a02bab5b8ed7b79a38bf961f6b24d0073c9c2419250\", \"price_changes\":[{\"asset_id\":\"69697746896130839564035629862476347944307040470122503199396727085502753297492\", \"price\":\"0.16\", \"size\":\"525.63\", \"side\":\"BUY\", \"hash\":\"e981a103a951d31c76967ca99e03677c55fd5bd5\", \"best_bid\":\"0.22\", \"best_ask\":\"0.23\"}, {\"asset_id\":\"60386828328910021732068595344565885737045900010034836345809386672230885527307\", \"price\":\"0.84\", \"size\":\"525.63\", \"side\":\"SELL\", \"hash\":\"c07cfeed080e69b671e0cbd34227ddf1bb473f4c\", \"best_bid\":\"0.77\", \"best_ask\":\"0.78\"}], \"timestamp\":\"1785126878648\", \"event_type\":\"price_change\"}","received_at":"2026-07-27T04:34:38.594292Z","schema_version":"clob-market-ws.price_change.v1","sequence":null,"server_hash":null,"server_timestamp":"1785126878648","session_id":"e9443c7415a0419799bee9cfbb1a9e4d","source":"clob_market_ws"},"received_at":"2026-07-27T04:34:38.594292Z","record_id":"75df495fbbd015eb98cb2e00a24c0f440c32d169ee4168e8dfe4e9dad453c509","schema_fingerprint":"4aa3821a28b0b7c2400bc59aba4bcc0a76e971dadd19610d3ad38c768e124dc7","schema_version":"edge-lab-recorder.raw.v1","sequence":null,"source":"clob_market_ws"}
{"event_at":"2026-07-27T04:34:38.648000Z","event_fingerprint":"ca6219ba647ec6fad29eb0d01ac929898cdaa0ad2e9c5ef7366cc6faf1acd849","payload":{"connection_id":"0f4979d6978d463e9660b042fdcf555f","event_at":"2026-07-27T04:34:38.648000Z","event_type":"price_change","frame_hash":"d493a991e1474487a20d4f2d928e90a7b70b21ddf6221665c4a21e1645ea949e","frame_index":0,"kind":"data","monotonic_ns":228861863341125,"payload":{"event_type":"price_change","market":"0xeb66215f2e9faa6449e30a02bab5b8ed7b79a38bf961f6b24d0073c9c2419250","price_changes":[{"asset_id":"69697746896130839564035629862476347944307040470122503199396727085502753297492","best_ask":"0.23","best_bid":"0.22","hash":"0a9f4a0f0052a2c24d434c368be057843b593e2c","price":"0.22","side":"BUY","size":"357.6"},{"asset_id":"60386828328910021732068595344565885737045900010034836345809386672230885527307","best_ask":"0.78","best_bid":"0.77","hash":"97eba79518e056dfb161d9850287f223759d5470","price":"0.78","side":"SELL","size":"357.6"}],"timestamp":"1785126878648"},"payload_hash":"a17cdf0856a17f521d1813deff7e6e5cb9f7a9551717a1ecac814b8ec3d93e53","raw_frame":"{\"market\":\"0xeb66215f2e9faa6449e30a02bab5b8ed7b79a38bf961f6b24d0073c9c2419250\", \"price_changes\":[{\"asset_id\":\"69697746896130839564035629862476347944307040470122503199396727085502753297492\", \"price\":\"0.22\", \"size\":\"357.6\", \"side\":\"BUY\", \"hash\":\"0a9f4a0f0052a2c24d434c368be057843b593e2c\", \"best_bid\":\"0.22\", \"best_ask\":\"0.23\"}, {\"asset_id\":\"60386828328910021732068595344565885737045900010034836345809386672230885527307\", \"price\":\"0.78\", \"size\":\"357.6\", \"side\":\"SELL\", \"hash\":\"97eba79518e056dfb161d9850287f223759d5470\", \"best_bid\":\"0.77\", \"best_ask\":\"0.78\"}], \"timestamp\":\"1785126878648\", \"event_type\":\"price_change\"}","received_at":"2026-07-27T04:34:38.595919Z","schema_version":"clob-market-ws.price_change.v1","sequence":null,"server_hash":null,"server_timestamp":"1785126878648","session_id":"e9443c7415a0419799bee9cfbb1a9e4d","source":"clob_market_ws"},"received_at":"2026-07-27T04:34:38.595919Z","record_id":"c03f3e4524db2b9e8fc1ce4f9d862c87db7ca3c886a91dd78d83cf75e6e0af54","schema_fingerprint":"4aa3821a28b0b7c2400bc59aba4bcc0a76e971dadd19610d3ad38c768e124dc7","schema_version":"edge-lab-recorder.raw.v1","sequence":null,"source":"clob_market_ws"}
{"event_at":"2026-07-27T04:34:38.650000Z","event_fingerprint":"9ddd115a00b88d20f152ab3e7f35a011c708c1889add64aa04e34db321deb74d","payload":{"connection_id":"0f4979d6978d463e9660b042fdcf555f","event_at":"2026-07-27T04:34:38.650000Z","event_type":"price_change","frame_hash":"a7cc12a4d03e72fd8b72c7af86407dc2df8e1a5182f87cd858f0070fb450f6f5","frame_index":0,"kind":"data","monotonic_ns":228861864841458,"payload":{"event_type":"price_change","market":"0xeb66215f2e9faa6449e30a02bab5b8ed7b79a38bf961f6b24d0073c9c2419250","price_changes":[{"asset_id":"60386828328910021732068595344565885737045900010034836345809386672230885527307","best_ask":"0.78","best_bid":"0.77","hash":"82da7e12fd303bb9ba1f50f2ea572e22b2fc8f49","price":"0.58","side":"BUY","size":"17.3"},{"asset_id":"69697746896130839564035629862476347944307040470122503199396727085502753297492","best_ask":"0.23","best_bid":"0.22","hash":"4e3ac1aa988c5af8dcc880a0851efa6651de16b0","price":"0.42","side":"SELL","size":"17.3"}],"timestamp":"1785126878650"},"payload_hash":"56b0beb44e6f61c44d1fc951d3005e9f64b238e3b204f6fc01d8419ee26c386e","raw_frame":"{\"market\":\"0xeb66215f2e9faa6449e30a02bab5b8ed7b79a38bf961f6b24d0073c9c2419250\", \"price_changes\":[{\"asset_id\":\"60386828328910021732068595344565885737045900010034836345809386672230885527307\", \"price\":\"0.58\", \"size\":\"17.3\", \"side\":\"BUY\", \"hash\":\"82da7e12fd303bb9ba1f50f2ea572e22b2fc8f49\", \"best_bid\":\"0.77\", \"best_ask\":\"0.78\"}, {\"asset_id\":\"69697746896130839564035629862476347944307040470122503199396727085502753297492\", \"price\":\"0.42\", \"size\":\"17.3\", \"side\":\"SELL\", \"hash\":\"4e3ac1aa988c5af8dcc880a0851efa6651de16b0\", \"best_bid\":\"0.22\", \"best_ask\":\"0.23\"}], \"timestamp\":\"1785126878650\", \"event_type\":\"price_change\"}","received_at":"2026-07-27T04:34:38.597419Z","schema_version":"clob-market-ws.price_change.v1","sequence":null,"server_hash":null,"server_timestamp":"1785126878650","session_id":"e9443c7415a0419799bee9cfbb1a9e4d","source":"clob_market_ws"},"received_at":"2026-07-27T04:34:38.597419Z","record_id":"f2944e8e189bcbf1e5a523b2522b863078645a8dd022ca93552a77e902bcf448","schema_fingerprint":"4aa3821a28b0b7c2400bc59aba4bcc0a76e971dadd19610d3ad38c768e124dc7","schema_version":"edge-lab-recorder.raw.v1","sequence":null,"source":"clob_market_ws"}
{"event_at":"2026-07-27T04:34:38.653000Z","event_fingerprint":"ec33bfe6cbcd4be8808fd72c4fd9d881eb23c923d24b15c9789ed7ff6c734fb6","payload":{"connection_id":"0f4979d6978d463e9660b042fdcf555f","event_at":"2026-07-27T04:34:38.653000Z","event_type":"price_change","frame_hash":"143399bd31aff29b198c1a1c1774de321eed3ac9cc96fe4eb8f11f0324d43ea0","frame_index":0,"kind":"data","monotonic_ns":228861866423291,"payload":{"event_type":"price_change","market":"0xeb66215f2e9faa6449e30a02bab5b8ed7b79a38bf961f6b24d0073c9c2419250","price_changes":[{"asset_id":"69697746896130839564035629862476347944307040470122503199396727085502753297492","best_ask":"0.23","best_bid":"0.22","hash":"b909c48d5bdedea7f25151a8a5b5b6746b18543b","price":"0.22","side":"BUY","size":"374.4"},{"asset_id":"60386828328910021732068595344565885737045900010034836345809386672230885527307","best_ask":"0.78","best_bid":"0.77","hash":"a0489c00fd50bd35c34ef3874bde2232a93a9c6f","price":"0.78","side":"SELL","size":"374.4"}],"timestamp":"1785126878653"},"payload_hash":"b0203cbac77a6605571c9124b2321e91e23bfec2eea75a1d85a63c896be7224f","raw_frame":"{\"market\":\"0xeb66215f2e9faa6449e30a02bab5b8ed7b79a38bf961f6b24d0073c9c2419250\", \"price_changes\":[{\"asset_id\":\"69697746896130839564035629862476347944307040470122503199396727085502753297492\", \"price\":\"0.22\", \"size\":\"374.4\", \"side\":\"BUY\", \"hash\":\"b909c48d5bdedea7f25151a8a5b5b6746b18543b\", \"best_bid\":\"0.22\", \"best_ask\":\"0.23\"}, {\"asset_id\":\"60386828328910021732068595344565885737045900010034836345809386672230885527307\", \"price\":\"0.78\", \"size\":\"374.4\", \"side\":\"SELL\", \"hash\":\"a0489c00fd50bd35c34ef3874bde2232a93a9c6f\", \"best_bid\":\"0.77\", \"best_ask\":\"0.78\"}], \"timestamp\":\"1785126878653\", \"event_type\":\"price_change\"}","received_at":"2026-07-27T04:34:38.599003Z","schema_version":"clob-market-ws.price_change.v1","sequence":null,"server_hash":null,"server_timestamp":"1785126878653","session_id":"e9443c7415a0419799bee9cfbb1a9e4d","source":"clob_market_ws"},"received_at":"2026-07-27T04:34:38.599003Z","record_id":"46e90299788a49ca6d91e5d5df21da1b1b1ae2b3775f26c611588479604d37a3","schema_fingerprint":"4aa3821a28b0b7c2400bc59aba4bcc0a76e971dadd19610d3ad38c768e124dc7","schema_version":"edge-lab-recorder.raw.v1","sequence":null,"source":"clob_market_ws"}
{"event_at":"2026-07-27T04:34:38.655000Z","event_fingerprint":"1708b0e548b831e18d7f1acb31bb07841c73504029f5b069f6339aa4377406ce","payload":{"connection_id":"0f4979d6978d463e9660b042fdcf555f","event_at":"2026-07-27T04:34:38.655000Z","event_type":"price_change","frame_hash":"ef6ad0de0504c7ab85c2e1e289ea0cca2db4d54b22175d655a5336f075e56808","frame_index":0,"kind":"data","monotonic_ns":228861868595833,"payload":{"event_type":"price_change","market":"0xeb66215f2e9faa6449e30a02bab5b8ed7b79a38bf961f6b24d0073c9c2419250","price_changes":[{"asset_id":"69697746896130839564035629862476347944307040470122503199396727085502753297492","best_ask":"0.23","best_bid":"0.22","hash":"63e3a643c288db7c60e4504ff4d91ac4c6937d54","price":"0.18","side":"BUY","size":"152.91"},{"asset_id":"60386828328910021732068595344565885737045900010034836345809386672230885527307","best_ask":"0.78","best_bid":"0.77","hash":"8108fda419f4c6147bba1c73a3b085352333b0f1","price":"0.82","side":"SELL","size":"152.91"}],"timestamp":"1785126878655"},"payload_hash":"8be10b486d7d6f052c20887e869b1c029c327440a2e339995ed2261f4955b305","raw_frame":"{\"market\":\"0xeb66215f2e9faa6449e30a02bab5b8ed7b79a38bf961f6b24d0073c9c2419250\", \"price_changes\":[{\"asset_id\":\"69697746896130839564035629862476347944307040470122503199396727085502753297492\", \"price\":\"0.18\", \"size\":\"152.91\", \"side\":\"BUY\", \"hash\":\"63e3a643c288db7c60e4504ff4d91ac4c6937d54\", \"best_bid\":\"0.22\", \"best_ask\":\"0.23\"}, {\"asset_id\":\"60386828328910021732068595344565885737045900010034836345809386672230885527307\", \"price\":\"0.82\", \"size\":\"152.91\", \"side\":\"SELL\", \"hash\":\"8108fda419f4c6147bba1c73a3b085352333b0f1\", \"best_bid\":\"0.77\", \"best_ask\":\"0.78\"}], \"timestamp\":\"1785126878655\", \"event_type\":\"price_change\"}","received_at":"2026-07-27T04:34:38.601172Z","schema_version":"clob-market-ws.price_change.v1","sequence":null,"server_hash":null,"server_timestamp":"1785126878655","session_id":"e9443c7415a0419799bee9cfbb1a9e4d","source":"clob_market_ws"},"received_at":"2026-07-27T04:34:38.601172Z","record_id":"a33abebbf9bc62807d3d86d0302841dbc9fe555746b3df479f46adb4e441f2b3","schema_fingerprint":"4aa3821a28b0b7c2400bc59aba4bcc0a76e971dadd19610d3ad38c768e124dc7","schema_version":"edge-lab-recorder.raw.v1","sequence":null,"source":"clob_market_ws"}
{"event_at":"2026-07-27T04:34:38.657000Z","event_fingerprint":"4d065da12c1a24f9d7c5aa21beb4d9a499f908fbd8ffbf2e200b7a8f40c1f397","payload":{"connection_id":"0f4979d6978d463e9660b042fdcf555f","event_at":"2026-07-27T04:34:38.657000Z","event_type":"price_change","frame_hash":"658a5afdc4bc5d7492abd3c716283a56ef9a2c3dbc3fb8952b1d4ebee40b7a4c","frame_index":0,"kind":"data","monotonic_ns":228861870228000,"payload":{"event_type":"price_change","market":"0xeb66215f2e9faa6449e30a02bab5b8ed7b79a38bf961f6b24d0073c9c2419250","price_changes":[{"asset_id":"60386828328910021732068595344565885737045900010034836345809386672230885527307","best_ask":"0.78","best_bid":"0.77","hash":"a435b9986daba4f49611a4cc8ef42c0d8ba309ae","price":"0.01","side":"BUY","size":"5713.02"},{"asset_id":"69697746896130839564035629862476347944307040470122503199396727085502753297492","best_ask":"0.23","best_bid":"0.22","hash":"05e4779d4e3cee0bce948cf02c46a1e5a8176345","price":"0.99","side":"SELL","size":"5713.02"}],"timestamp":"1785126878657"},"payload_hash":"15c043acb5b3507e4769b6108f7eb205d167af3c49722b7810089d1d577fc285","raw_frame":"{\"market\":\"0xeb66215f2e9faa6449e30a02bab5b8ed7b79a38bf961f6b24d0073c9c2419250\", \"price_changes\":[{\"asset_id\":\"60386828328910021732068595344565885737045900010034836345809386672230885527307\", \"price\":\"0.01\", \"size\":\"5713.02\", \"side\":\"BUY\", \"hash\":\"a435b9986daba4f49611a4cc8ef42c0d8ba309ae\", \"best_bid\":\"0.77\", \"best_ask\":\"0.78\"}, {\"asset_id\":\"69697746896130839564035629862476347944307040470122503199396727085502753297492\", \"price\":\"0.99\", \"size\":\"5713.02\", \"side\":\"SELL\", \"hash\":\"05e4779d4e3cee0bce948cf02c46a1e5a8176345\", \"best_bid\":\"0.22\", \"best_ask\":\"0.23\"}], \"timestamp\":\"1785126878657\", \"event_type\":\"price_change\"}","received_at":"2026-07-27T04:34:38.602806Z","schema_version":"clob-market-ws.price_change.v1","sequence":null,"server_hash":null,"server_timestamp":"1785126878657","session_id":"e9443c7415a0419799bee9cfbb1a9e4d","source":"clob_market_ws"},"received_at":"2026-07-27T04:34:38.602806Z","record_id":"55b446ea3f80085a2f974f058204c16858d552d6187e87bc27c4180911a641ea","schema_fingerprint":"4aa3821a28b0b7c2400bc59aba4bcc0a76e971dadd19610d3ad38c768e124dc7","schema_version":"edge-lab-recorder.raw.v1","sequence":null,"source":"clob_market_ws"}
{"event_at":"2026-07-27T04:34:38.659000Z","event_fingerprint":"ec8afa8f8020c7a5c9b809848db963920e5637b058426e807f95a33669a22a47","payload":{"connection_id":"0f4979d6978d463e9660b042fdcf555f","event_at":"2026-07-27T04:34:38.659000Z","event_type":"price_change","frame_hash":"3cd8999f60e0551c3442c92bdcfa126529f65f798c6a7072b2736bb790c188ff","frame_index":0,"kind":"data","monotonic_ns":228861871810458,"payload":{"event_type":"price_change","market":"0xeb66215f2e9faa6449e30a02bab5b8ed7b79a38bf961f6b24d0073c9c2419250","price_changes":[{"asset_id":"69697746896130839564035629862476347944307040470122503199396727085502753297492","best_ask":"0.23","best_bid":"0.22","hash":"70abae23179b3e979d5b733995c39ad49021aa0d","price":"0.22","side":"BUY","size":"379.4"},{"asset_id":"60386828328910021732068595344565885737045900010034836345809386672230885527307","best_ask":"0.78","best_bid":"0.77","hash":"53861eee9b6ef9602fd6f969d81e3751134a4b1c","price":"0.78","side":"SELL","size":"379.4"}],"timestamp":"1785126878659"},"payload_hash":"0c36b2c4ff39f1d378a742ee7ac9b4d466ea7ddc7831d37f109da115bc9e0ece","raw_frame":"{\"market\":\"0xeb66215f2e9faa6449e30a02bab5b8ed7b79a38bf961f6b24d0073c9c2419250\", \"price_changes\":[{\"asset_id\":\"69697746896130839564035629862476347944307040470122503199396727085502753297492\", \"price\":\"0.22\", \"size\":\"379.4\", \"side\":\"BUY\", \"hash\":\"70abae23179b3e979d5b733995c39ad49021aa0d\", \"best_bid\":\"0.22\", \"best_ask\":\"0.23\"}, {\"asset_id\":\"60386828328910021732068595344565885737045900010034836345809386672230885527307\", \"price\":\"0.78\", \"size\":\"379.4\", \"side\":\"SELL\", \"hash\":\"53861eee9b6ef9602fd6f969d81e3751134a4b1c\", \"best_bid\":\"0.77\", \"best_ask\":\"0.78\"}], \"timestamp\":\"1785126878659\", \"event_type\":\"price_change\"}","received_at":"2026-07-27T04:34:38.604389Z","schema_version":"clob-market-ws.price_change.v1","sequence":null,"server_hash":null,"server_timestamp":"1785126878659","session_id":"e9443c7415a0419799bee9cfbb1a9e4d","source":"clob_market_ws"},"received_at":"2026-07-27T04:34:38.604389Z","record_id":"720f2b68ee69e50f419aeb63f73061762d8be210fae9396b244a05ba5f50e93c","schema_fingerprint":"4aa3821a28b0b7c2400bc59aba4bcc0a76e971dadd19610d3ad38c768e124dc7","schema_version":"edge-lab-recorder.raw.v1","sequence":null,"source":"clob_market_ws"}
{"event_at":"2026-07-27T04:34:38.662000Z","event_fingerprint":"d4cc5cc0b5030ada06c20e60c4beb227c33eca1f36f60cbf5a91f23400291e5a","payload":{"connection_id":"0f4979d6978d463e9660b042fdcf555f","event_at":"2026-07-27T04:34:38.662000Z","event_type":"price_change","frame_hash":"a1789c27a26f8323d45ab24d57d7d9775b2f650bcc626e972c79352971ed7ff5","frame_index":0,"kind":"data","monotonic_ns":228861875199500,"payload":{"event_type":"price_change","market":"0xeb66215f2e9faa6449e30a02bab5b8ed7b79a38bf961f6b24d0073c9c2419250","price_changes":[{"asset_id":"69697746896130839564035629862476347944307040470122503199396727085502753297492","best_ask":"0.23","best_bid":"0.22","hash":"13a64e42c1978a9f9c09c6d7df46ed15a7a71e71","price":"0.21","side":"BUY","size":"65.4"},{"asset_id":"60386828328910021732068595344565885737045900010034836345809386672230885527307","best_ask":"0.78","best_bid":"0.77","hash":"bba6fdf04ee719fe46e48c65b1deb4241862a3af","price":"0.79","side":"SELL","size":"65.4"}],"timestamp":"1785126878662"},"payload_hash":"e57c3c1cf5db7c55bb9c931a4d809541e226eaf83b3cbc2060e02126d76d5253","raw_frame":"{\"market\":\"0xeb66215f2e9faa6449e30a02bab5b8ed7b79a38bf961f6b24d0073c9c2419250\", \"price_changes\":[{\"asset_id\":\"69697746896130839564035629862476347944307040470122503199396727085502753297492\", \"price\":\"0.21\", \"size\":\"65.4\", \"side\":\"BUY\", \"hash\":\"13a64e42c1978a9f9c09c6d7df46ed15a7a71e71\", \"best_bid\":\"0.22\", \"best_ask\":\"0.23\"}, {\"asset_id\":\"60386828328910021732068595344565885737045900010034836345809386672230885527307\", \"price\":\"0.79\", \"size\":\"65.4\", \"side\":\"SELL\", \"hash\":\"bba6fdf04ee719fe46e48c65b1deb4241862a3af\", \"best_bid\":\"0.77\", \"best_ask\":\"0.78\"}], \"timestamp\":\"1785126878662\", \"event_type\":\"price_change\"}","received_at":"2026-07-27T04:34:38.607776Z","schema_version":"clob-market-ws.price_change.v1","sequence":null,"server_hash":null,"server_timestamp":"1785126878662","session_id":"e9443c7415a0419799bee9cfbb1a9e4d","source":"clob_market_ws"},"received_at":"2026-07-27T04:34:38.607776Z","record_id":"155e7d3499e7bfce450f3b614a2446323295153f24930767f6ab7ecdf53dd79c","schema_fingerprint":"4aa3821a28b0b7c2400bc59aba4bcc0a76e971dadd19610d3ad38c768e124dc7","schema_version":"edge-lab-recorder.raw.v1","sequence":null,"source":"clob_market_ws"}
{"event_at":"2026-07-27T04:34:38.666000Z","event_fingerprint":"55920a8d68a2a7c9e50d6f095ed9a03d9657d21cdf40ddb140c7f82fe6038299","payload":{"connection_id":"0f4979d6978d463e9660b042fdcf555f","event_at":"2026-07-27T04:34:38.666000Z","event_type":"price_change","frame_hash":"4cf9dd35ba7321c14e31ef647a2ae961a0128c4ccdf9cdb046c6ae9738bcfcb2","frame_index":0,"kind":"data","monotonic_ns":228861879209958,"payload":{"event_type":"price_change","market":"0xeb66215f2e9faa6449e30a02bab5b8ed7b79a38bf961f6b24d0073c9c2419250","price_changes":[{"asset_id":"69697746896130839564035629862476347944307040470122503199396727085502753297492","best_ask":"0.23","best_bid":"0.22","hash":"75f662595bd576fe908e3c4f3ed2864003f78a63","price":"0.17","side":"BUY","size":"217.77"},{"asset_id":"60386828328910021732068595344565885737045900010034836345809386672230885527307","best_ask":"0.78","best_bid":"0.77","hash":"9168d7820b57899e4f7eaad49f0a51b50fb4e57e","price":"0.83","side":"SELL","size":"217.77"}],"timestamp":"1785126878666"},"payload_hash":"afc77d01b698448d7f369adcf6bd5c744fa35ac4b454bae44bdd91bb0f6c58ed","raw_frame":"{\"market\":\"0xeb66215f2e9faa6449e30a02bab5b8ed7b79a38bf961f6b24d0073c9c2419250\", \"price_changes\":[{\"asset_id\":\"69697746896130839564035629862476347944307040470122503199396727085502753297492\", \"price\":\"0.17\", \"size\":\"217.77\", \"side\":\"BUY\", \"hash\":\"75f662595bd576fe908e3c4f3ed2864003f78a63\", \"best_bid\":\"0.22\", \"best_ask\":\"0.23\"}, {\"asset_id\":\"60386828328910021732068595344565885737045900010034836345809386672230885527307\", \"price\":\"0.83\", \"size\":\"217.77\", \"side\":\"SELL\", \"hash\":\"9168d7820b57899e4f7eaad49f0a51b50fb4e57e\", \"best_bid\":\"0.77\", \"best_ask\":\"0.78\"}], \"timestamp\":\"1785126878666\", \"event_type\":\"price_change\"}","received_at":"2026-07-27T04:34:38.611787Z","schema_version":"clob-market-ws.price_change.v1","sequence":null,"server_hash":null,"server_timestamp":"1785126878666","session_id":"e9443c7415a0419799bee9cfbb1a9e4d","source":"clob_market_ws"},"received_at":"2026-07-27T04:34:38.611787Z","record_id":"b625298e4c4a074cb3c86d4c0c72e93529f066d7f608f9985a941b6551f5a22a","schema_fingerprint":"4aa3821a28b0b7c2400bc59aba4bcc0a76e971dadd19610d3ad38c768e124dc7","schema_version":"edge-lab-recorder.raw.v1","sequence":null,"source":"clob_market_ws"}
{"event_at":"2026-07-27T04:34:38.670000Z","event_fingerprint":"84453faa4e1aa68da3f8b644d7b8db851b62521b35647087323e0f236a0ccda0","payload":{"connection_id":"0f4979d6978d463e9660b042fdcf555f","event_at":"2026-07-27T04:34:38.670000Z","event_type":"best_bid_ask","frame_hash":"d4e1d7ef0a3810005c67581cfd45632fe4954b6d72e0b6993898a4319d93c26f","frame_index":0,"kind":"data","monotonic_ns":228861883152625,"payload":{"asset_id":"69697746896130839564035629862476347944307040470122503199396727085502753297492","best_ask":"0.24","best_bid":"0.22","event_type":"best_bid_ask","market":"0xeb66215f2e9faa6449e30a02bab5b8ed7b79a38bf961f6b24d0073c9c2419250","spread":"0.02","timestamp":"1785126878670"},"payload_hash":"48f28d52aa947549816679535f41528b564be9976dd7afdecca7687e6b3154f4","raw_frame":"{\"market\":\"0xeb66215f2e9faa6449e30a02bab5b8ed7b79a38bf961f6b24d0073c9c2419250\", \"asset_id\":\"69697746896130839564035629862476347944307040470122503199396727085502753297492\", \"best_bid\":\"0.22\", \"best_ask\":\"0.24\", \"spread\":\"0.02\", \"timestamp\":\"1785126878670\", \"event_type\":\"best_bid_ask\"}","received_at":"2026-07-27T04:34:38.615729Z","schema_version":"clob-market-ws.best_bid_ask.v1","sequence":null,"server_hash":null,"server_timestamp":"1785126878670","session_id":"e9443c7415a0419799bee9cfbb1a9e4d","source":"clob_market_ws"},"received_at":"2026-07-27T04:34:38.615729Z","record_id":"6eafa7cf96a368e6c1ac8a3ce4741c62a29e43f51d3f4a335b77a55b0c4fca4c","schema_fingerprint":"8488399f31b0337811b13b266be932db7062827c2470b78bd8e9e99bab51d17d","schema_version":"edge-lab-recorder.raw.v1","sequence":null,"source":"clob_market_ws"}
{"event_at":"2026-07-27T04:34:38.670000Z","event_fingerprint":"170683f9e6494d156571633e566055260cd483becb153e96a76ad3bf1103dfa0","payload":{"connection_id":"0f4979d6978d463e9660b042fdcf555f","event_at":"2026-07-27T04:34:38.670000Z","event_type":"best_bid_ask","frame_hash":"bfcf757be662f4e672c2dd35701c7d6b24346075aa43e6da4bdad1f64f096fc7","frame_index":0,"kind":"data","monotonic_ns":228861884326875,"payload":{"asset_id":"60386828328910021732068595344565885737045900010034836345809386672230885527307","best_ask":"0.78","best_bid":"0.76","event_type":"best_bid_ask","market":"0xeb66215f2e9faa6449e30a02bab5b8ed7b79a38bf961f6b24d0073c9c2419250","spread":"0.02","timestamp":"1785126878670"},"payload_hash":"e3475c193383bab6f06120d899cce2e0d1361be02a9fc76eb7c2b48447ed238b","raw_frame":"{\"market\":\"0xeb66215f2e9faa6449e30a02bab5b8ed7b79a38bf961f6b24d0073c9c2419250\", \"asset_id\":\"60386828328910021732068595344565885737045900010034836345809386672230885527307\", \"best_bid\":\"0.76\", \"best_ask\":\"0.78\", \"spread\":\"0.02\", \"timestamp\":\"1785126878670\", \"event_type\":\"best_bid_ask\"}","received_at":"2026-07-27T04:34:38.616904Z","schema_version":"clob-market-ws.best_bid_ask.v1","sequence":null,"server_hash":null,"server_timestamp":"1785126878670","session_id":"e9443c7415a0419799bee9cfbb1a9e4d","source":"clob_market_ws"},"received_at":"2026-07-27T04:34:38.616904Z","record_id":"0d57c5428a6a3c8aa99d493ce6e481cca732bc10df7faf452d4659e126aaace2","schema_fingerprint":"8488399f31b0337811b13b266be932db7062827c2470b78bd8e9e99bab51d17d","schema_version":"edge-lab-recorder.raw.v1","sequence":null,"source":"clob_market_ws"}
{"event_at":"2026-07-27T04:34:38.670000Z","event_fingerprint":"d5dbd8664d98f78e5f2a5ba891f031a36230d6ba7c90d2eb4f9bc7098936f95b","payload":{"connection_id":"0f4979d6978d463e9660b042fdcf555f","event_at":"2026-07-27T04:34:38.670000Z","event_type":"price_change","frame_hash":"7208d56da3885df9d3e362f634a104b8bc5acb5ed9f917cee46c27295c232b95","frame_index":0,"kind":"data","monotonic_ns":228861885435583,"payload":{"event_type":"price_change","market":"0xeb66215f2e9faa6449e30a02bab5b8ed7b79a38bf961f6b24d0073c9c2419250","price_changes":[{"asset_id":"60386828328910021732068595344565885737045900010034836345809386672230885527307","best_ask":"0.78","best_bid":"0.76","hash":"0da8b673c3bc5334c5486c3ded24c6e746dbe323","price":"0.77","side":"BUY","size":"0"},{"asset_id":"69697746896130839564035629862476347944307040470122503199396727085502753297492","best_ask":"0.24","best_bid":"0.22","hash":"6e6d56a2a9c545b7d8729d9c1bd991dbab7372af","price":"0.23","side":"SELL","size":"0"}],"timestamp":"1785126878670"},"payload_hash":"f01bf16be176ce456220aceee1fec7c7d802843edaa692e81893170f8e82ea8d","raw_frame":"{\"market\":\"0xeb66215f2e9faa6449e30a02bab5b8ed7b79a38bf961f6b24d0073c9c2419250\", \"price_changes\":[{\"asset_id\":\"60386828328910021732068595344565885737045900010034836345809386672230885527307\", \"price\":\"0.77\", \"size\":\"0\", \"side\":\"BUY\", \"hash\":\"0da8b673c3bc5334c5486c3ded24c6e746dbe323\", \"best_bid\":\"0.76\", \"best_ask\":\"0.78\"}, {\"asset_id\":\"69697746896130839564035629862476347944307040470122503199396727085502753297492\", \"price\":\"0.23\", \"size\":\"0\", \"side\":\"SELL\", \"hash\":\"6e6d56a2a9c545b7d8729d9c1bd991dbab7372af\", \"best_bid\":\"0.22\", \"best_ask\":\"0.24\"}], \"timestamp\":\"1785126878670\", \"event_type\":\"price_change\"}","received_at":"2026-07-27T04:34:38.618014Z","schema_version":"clob-market-ws.price_change.v1","sequence":null,"server_hash":null,"server_timestamp":"1785126878670","session_id":"e9443c7415a0419799bee9cfbb1a9e4d","source":"clob_market_ws"},"received_at":"2026-07-27T04:34:38.618014Z","record_id":"3c9ffdabb54d54196896bff7572228c60ba58c1943a3b519cd80f9bd87b1f80f","schema_fingerprint":"4aa3821a28b0b7c2400bc59aba4bcc0a76e971dadd19610d3ad38c768e124dc7","schema_version":"edge-lab-recorder.raw.v1","sequence":null,"source":"clob_market_ws"}
{"event_at":"2026-07-27T04:34:38.674000Z","event_fingerprint":"55362ca165d47bf892f0f418f75614737a55b7015647d9695ed2af234829b01c","payload":{"connection_id":"0f4979d6978d463e9660b042fdcf555f","event_at":"2026-07-27T04:34:38.674000Z","event_type":"price_change","frame_hash":"f5853b1e410f204227a39ad77d3e381f666e8c3fcfc244a03481c3a3d5dce72c","frame_index":0,"kind":"data","monotonic_ns":228861887178625,"payload":{"event_type":"price_change","market":"0xeb66215f2e9faa6449e30a02bab5b8ed7b79a38bf961f6b24d0073c9c2419250","price_changes":[{"asset_id":"60386828328910021732068595344565885737045900010034836345809386672230885527307","best_ask":"0.78","best_bid":"0.76","hash":"8368253e470837a40bfd31229e7c76b3bd9816a1","price":"0.01","side":"BUY","size":"5708.02"},{"asset_id":"69697746896130839564035629862476347944307040470122503199396727085502753297492","best_ask":"0.24","best_bid":"0.22","hash":"01d4d3da98ca47cb90f1943d07ddb530d6c43450","price":"0.99","side":"SELL","size":"5708.02"}],"timestamp":"1785126878674"},"payload_hash":"f4c2f1a75b985f9487434a3c0301560689a3ce19779541bdc8bb6019cf3cd56b","raw_frame":"{\"market\":\"0xeb66215f2e9faa6449e30a02bab5b8ed7b79a38bf961f6b24d0073c9c2419250\", \"price_changes\":[{\"asset_id\":\"60386828328910021732068595344565885737045900010034836345809386672230885527307\", \"price\":\"0.01\", \"size\":\"5708.02\", \"side\":\"BUY\", \"hash\":\"8368253e470837a40bfd31229e7c76b3bd9816a1\", \"best_bid\":\"0.76\", \"best_ask\":\"0.78\"}, {\"asset_id\":\"69697746896130839564035629862476347944307040470122503199396727085502753297492\", \"price\":\"0.99\", \"size\":\"5708.02\", \"side\":\"SELL\", \"hash\":\"01d4d3da98ca47cb90f1943d07ddb530d6c43450\", \"best_bid\":\"0.22\", \"best_ask\":\"0.24\"}], \"timestamp\":\"1785126878674\", \"event_type\":\"price_change\"}","received_at":"2026-07-27T04:34:38.619756Z","schema_version":"clob-market-ws.price_change.v1","sequence":null,"server_hash":null,"server_timestamp":"1785126878674","session_id":"e9443c7415a0419799bee9cfbb1a9e4d","source":"clob_market_ws"},"received_at":"2026-07-27T04:34:38.619756Z","record_id":"c0d5e101a6267274c81f817618d089725917fcecf76bbb4ebf37e8cebb33ef05","schema_fingerprint":"4aa3821a28b0b7c2400bc59aba4bcc0a76e971dadd19610d3ad38c768e124dc7","schema_version":"edge-lab-recorder.raw.v1","sequence":null,"source":"clob_market_ws"}
{"event_at":"2026-07-27T04:34:38.684000Z","event_fingerprint":"a3a591f741d9202e2f16e685648647f11941eaa17bd56c3e392223155357c747","payload":{"connection_id":"0f4979d6978d463e9660b042fdcf555f","event_at":"2026-07-27T04:34:38.684000Z","event_type":"price_change","frame_hash":"3ab14ab42dbb5a7b42869cc411589f942ab5975ebea560587c87d772c43094b3","frame_index":0,"kind":"data","monotonic_ns":228861897783583,"payload":{"event_type":"price_change","market":"0xeb66215f2e9faa6449e30a02bab5b8ed7b79a38bf961f6b24d0073c9c2419250","price_changes":[{"asset_id":"60386828328910021732068595344565885737045900010034836345809386672230885527307","best_ask":"0.78","best_bid":"0.76","hash":"a1b43b79968769aed887f37e6d56cbdb053f8832","price":"0.59","side":"BUY","size":"78.89"},{"asset_id":"69697746896130839564035629862476347944307040470122503199396727085502753297492","best_ask":"0.24","best_bid":"0.22","hash":"c798b7be65510d50b5c8eb8e5d5df1d84704f580","price":"0.41","side":"SELL","size":"78.89"}],"timestamp":"1785126878684"},"payload_hash":"408f682f25a9ba11f00012f21be06e30b942381c62ded2c4b1d62aa9768248dc","raw_frame":"{\"market\":\"0xeb66215f2e9faa6449e30a02bab5b8ed7b79a38bf961f6b24d0073c9c2419250\", \"price_changes\":[{\"asset_id\":\"60386828328910021732068595344565885737045900010034836345809386672230885527307\", \"price\":\"0.59\", \"size\":\"78.89\", \"side\":\"BUY\", \"hash\":\"a1b43b79968769aed887f37e6d56cbdb053f8832\", \"best_bid\":\"0.76\", \"best_ask\":\"0.78\"}, {\"asset_id\":\"69697746896130839564035629862476347944307040470122503199396727085502753297492\", \"price\":\"0.41\", \"size\":\"78.89\", \"side\":\"SELL\", \"hash\":\"c798b7be65510d50b5c8eb8e5d5df1d84704f580\", \"best_bid\":\"0.22\", \"best_ask\":\"0.24\"}], \"timestamp\":\"1785126878684\", \"event_type\":\"price_change\"}","received_at":"2026-07-27T04:34:38.630361Z","schema_version":"clob-market-ws.price_change.v1","sequence":null,"server_hash":null,"server_timestamp":"1785126878684","session_id":"e9443c7415a0419799bee9cfbb1a9e4d","source":"clob_market_ws"},"received_at":"2026-07-27T04:34:38.630361Z","record_id":"210b97452c894f93e071da6b5916e69229e86b9ee294924a1187c7f1d025d96c","schema_fingerprint":"4aa3821a28b0b7c2400bc59aba4bcc0a76e971dadd19610d3ad38c768e124dc7","schema_version":"edge-lab-recorder.raw.v1","sequence":null,"source":"clob_market_ws"}
{"event_at":"2026-07-27T04:34:38.685000Z","event_fingerprint":"05ca303feb27d5196eefb21f15312b11750b35dc898825139ad618cca9ea0132","payload":{"connection_id":"0f4979d6978d463e9660b042fdcf555f","event_at":"2026-07-27T04:34:38.685000Z","event_type":"price_change","frame_hash":"e2fa570a56b5cf987a38fe36823f70c9cc24e107a3f23f03779ade6239597be9","frame_index":0,"kind":"data","monotonic_ns":228861899304875,"payload":{"event_type":"price_change","market":"0xeb66215f2e9faa6449e30a02bab5b8ed7b79a38bf961f6b24d0073c9c2419250","price_changes":[{"asset_id":"60386828328910021732068595344565885737045900010034836345809386672230885527307","best_ask":"0.78","best_bid":"0.76","hash":"75fb9d0ac23bf88f6b076ed8861cb8cb97074282","price":"0.01","side":"BUY","size":"5703.02"},{"asset_id":"69697746896130839564035629862476347944307040470122503199396727085502753297492","best_ask":"0.24","best_bid":"0.22","hash":"ed26b942b77956674bf56019610a1c6d3bd2e718","price":"0.99","side":"SELL","size":"5703.02"}],"timestamp":"1785126878685"},"payload_hash":"11fbb50a382b7c0236574d038fa9be27cbd5bf52fe783204461f58260276aee8","raw_frame":"{\"market\":\"0xeb66215f2e9faa6449e30a02bab5b8ed7b79a38bf961f6b24d0073c9c2419250\", \"price_changes\":[{\"asset_id\":\"60386828328910021732068595344565885737045900010034836345809386672230885527307\", \"price\":\"0.01\", \"size\":\"5703.02\", \"side\":\"BUY\", \"hash\":\"75fb9d0ac23bf88f6b076ed8861cb8cb97074282\", \"best_bid\":\"0.76\", \"best_ask\":\"0.78\"}, {\"asset_id\":\"69697746896130839564035629862476347944307040470122503199396727085502753297492\", \"price\":\"0.99\", \"size\":\"5703.02\", \"side\":\"SELL\", \"hash\":\"ed26b942b77956674bf56019610a1c6d3bd2e718\", \"best_bid\":\"0.22\", \"best_ask\":\"0.24\"}], \"timestamp\":\"1785126878685\", \"event_type\":\"price_change\"}","received_at":"2026-07-27T04:34:38.631884Z","schema_version":"clob-market-ws.price_change.v1","sequence":null,"server_hash":null,"server_timestamp":"1785126878685","session_id":"e9443c7415a0419799bee9cfbb1a9e4d","source":"clob_market_ws"},"received_at":"2026-07-27T04:34:38.631884Z","record_id":"851f07755d9c205ff918ed4aca03ec3a6da5ae97281e660dd96bb6e771d17d8e","schema_fingerprint":"4aa3821a28b0b7c2400bc59aba4bcc0a76e971dadd19610d3ad38c768e124dc7","schema_version":"edge-lab-recorder.raw.v1","sequence":null,"source":"clob_market_ws"}
{"event_at":"2026-07-27T04:34:38.685000Z","event_fingerprint":"c7c352ce30711c023b97cc7045739ca522e2ba6b834fae5b69879976a39caa70","payload":{"connection_id":"0f4979d6978d463e9660b042fdcf555f","event_at":"2026-07-27T04:34:38.685000Z","event_type":"price_change","frame_hash":"8101d13c2b8fb51b83637d28726b5ca2afa94ea30ae35464157ae03e5714fec5","frame_index":0,"kind":"data","monotonic_ns":228861900790541,"payload":{"event_type":"price_change","market":"0xeb66215f2e9faa6449e30a02bab5b8ed7b79a38bf961f6b24d0073c9c2419250","price_changes":[{"asset_id":"69697746896130839564035629862476347944307040470122503199396727085502753297492","best_ask":"0.24","best_bid":"0.22","hash":"c5f015077598c67c81ab5e6c6165a3a4ffa72205","price":"0.22","side":"BUY","size":"374.4"},{"asset_id":"60386828328910021732068595344565885737045900010034836345809386672230885527307","best_ask":"0.78","best_bid":"0.76","hash":"425accd1fa3347f2ce21b044042161c77bb8d99f","price":"0.78","side":"SELL","size":"374.4"}],"timestamp":"1785126878685"},"payload_hash":"3688dc69c0b706b84a233ae44562cc8cc7627478d13e28d1eaa414c7b7731db8","raw_frame":"{\"market\":\"0xeb66215f2e9faa6449e30a02bab5b8ed7b79a38bf961f6b24d0073c9c2419250\", \"price_changes\":[{\"asset_id\":\"69697746896130839564035629862476347944307040470122503199396727085502753297492\", \"price\":\"0.22\", \"size\":\"374.4\", \"side\":\"BUY\", \"hash\":\"c5f015077598c67c81ab5e6c6165a3a4ffa72205\", \"best_bid\":\"0.22\", \"best_ask\":\"0.24\"}, {\"asset_id\":\"60386828328910021732068595344565885737045900010034836345809386672230885527307\", \"price\":\"0.78\", \"size\":\"374.4\", \"side\":\"SELL\", \"hash\":\"425accd1fa3347f2ce21b044042161c77bb8d99f\", \"best_bid\":\"0.76\", \"best_ask\":\"0.78\"}], \"timestamp\":\"1785126878685\", \"event_type\":\"price_change\"}","received_at":"2026-07-27T04:34:38.633369Z","schema_version":"clob-market-ws.price_change.v1","sequence":null,"server_hash":null,"server_timestamp":"1785126878685","session_id":"e9443c7415a0419799bee9cfbb1a9e4d","source":"clob_market_ws"},"received_at":"2026-07-27T04:34:38.633369Z","record_id":"96215abbf341cd3e1295bcb43996f4b7a0c2b0aacc6b1d90bec9037189473326","schema_fingerprint":"4aa3821a28b0b7c2400bc59aba4bcc0a76e971dadd19610d3ad38c768e124dc7","schema_version":"edge-lab-recorder.raw.v1","sequence":null,"source":"clob_market_ws"}
{"event_at":"2026-07-27T04:34:38.743000Z","event_fingerprint":"5cd031dd1fc5d7e5ad8714ea990fe836019b222106e27e21873c1db2e292f99d","payload":{"connection_id":"0f4979d6978d463e9660b042fdcf555f","event_at":"2026-07-27T04:34:38.743000Z","event_type":"price_change","frame_hash":"cfa2819951c55fce8271ed2977c4e8da78b4bdabfa61dee8482fa402e1560dc8","frame_index":0,"kind":"data","monotonic_ns":228861956241666,"payload":{"event_type":"price_change","market":"0xeb66215f2e9faa6449e30a02bab5b8ed7b79a38bf961f6b24d0073c9c2419250","price_changes":[{"asset_id":"60386828328910021732068595344565885737045900010034836345809386672230885527307","best_ask":"0.78","best_bid":"0.76","hash":"47fedd27876e557176597e8afaa6e20202b3d492","price":"0.73","side":"BUY","size":"304.62"},{"asset_id":"69697746896130839564035629862476347944307040470122503199396727085502753297492","best_ask":"0.24","best_bid":"0.22","hash":"e6d1723f66c3f4984eae63a6321f4c5bc79c1467","price":"0.27","side":"SELL","size":"304.62"}],"timestamp":"1785126878743"},"payload_hash":"af85af8a6be68da18e23472d424eaf5c3b2bdf2546faadca88d2f0dedda5027e","raw_frame":"{\"market\":\"0xeb66215f2e9faa6449e30a02bab5b8ed7b79a38bf961f6b24d0073c9c2419250\", \"price_changes\":[{\"asset_id\":\"60386828328910021732068595344565885737045900010034836345809386672230885527307\", \"price\":\"0.73\", \"size\":\"304.62\", \"side\":\"BUY\", \"hash\":\"47fedd27876e557176597e8afaa6e20202b3d492\", \"best_bid\":\"0.76\", \"best_ask\":\"0.78\"}, {\"asset_id\":\"69697746896130839564035629862476347944307040470122503199396727085502753297492\", \"price\":\"0.27\", \"size\":\"304.62\", \"side\":\"SELL\", \"hash\":\"e6d1723f66c3f4984eae63a6321f4c5bc79c1467\", \"best_bid\":\"0.22\", \"best_ask\":\"0.24\"}], \"timestamp\":\"1785126878743\", \"event_type\":\"price_change\"}","received_at":"2026-07-27T04:34:38.688813Z","schema_version":"clob-market-ws.price_change.v1","sequence":null,"server_hash":null,"server_timestamp":"1785126878743","session_id":"e9443c7415a0419799bee9cfbb1a9e4d","source":"clob_market_ws"},"received_at":"2026-07-27T04:34:38.688813Z","record_id":"08e3ba1d4db9ffb770088e51e19310cd81409c5457c3d531787101981cdeb7fb","schema_fingerprint":"4aa3821a28b0b7c2400bc59aba4bcc0a76e971dadd19610d3ad38c768e124dc7","schema_version":"edge-lab-recorder.raw.v1","sequence":null,"source":"clob_market_ws"}
{"event_at":"2026-07-27T04:34:38.752000Z","event_fingerprint":"c7dfe758814d543499fa1f53bf4b0d4acc5781acdcfb224983856108fce894b8","payload":{"connection_id":"0f4979d6978d463e9660b042fdcf555f","event_at":"2026-07-27T04:34:38.752000Z","event_type":"price_change","frame_hash":"ef30b6e6145f9c20c1ee728459e35ab28a1f50a5f0aadb86d0d6b935c0d56d99","frame_index":0,"kind":"data","monotonic_ns":228861964845625,"payload":{"event_type":"price_change","market":"0xeb66215f2e9faa6449e30a02bab5b8ed7b79a38bf961f6b24d0073c9c2419250","price_changes":[{"asset_id":"69697746896130839564035629862476347944307040470122503199396727085502753297492","best_ask":"0.24","best_bid":"0.22","hash":"e21d5b883b9fa3c03a869b90d11511a0c8ab3abc","price":"0.27","side":"SELL","size":"334.66"},{"asset_id":"60386828328910021732068595344565885737045900010034836345809386672230885527307","best_ask":"0.78","best_bid":"0.76","hash":"bd83be7ebb25a97fa55a1f4498db686abedbed37","price":"0.73","side":"BUY","size":"334.66"}],"timestamp":"1785126878752"},"payload_hash":"a1416f83c58a769e500ae4bef5ddd4040e3ff33317c9610a3205beb930154a2b","raw_frame":"{\"market\":\"0xeb66215f2e9faa6449e30a02bab5b8ed7b79a38bf961f6b24d0073c9c2419250\", \"price_changes\":[{\"asset_id\":\"69697746896130839564035629862476347944307040470122503199396727085502753297492\", \"price\":\"0.27\", \"size\":\"334.66\", \"side\":\"SELL\", \"hash\":\"e21d5b883b9fa3c03a869b90d11511a0c8ab3abc\", \"best_bid\":\"0.22\", \"best_ask\":\"0.24\"}, {\"asset_id\":\"60386828328910021732068595344565885737045900010034836345809386672230885527307\", \"price\":\"0.73\", \"size\":\"334.66\", \"side\":\"BUY\", \"hash\":\"bd83be7ebb25a97fa55a1f4498db686abedbed37\", \"best_bid\":\"0.76\", \"best_ask\":\"0.78\"}], \"timestamp\":\"1785126878752\", \"event_type\":\"price_change\"}","received_at":"2026-07-27T04:34:38.697423Z","schema_version":"clob-market-ws.price_change.v1","sequence":null,"server_hash":null,"server_timestamp":"1785126878752","session_id":"e9443c7415a0419799bee9cfbb1a9e4d","source":"clob_market_ws"},"received_at":"2026-07-27T04:34:38.697423Z","record_id":"c9db1f13420c2589b705300ef0ffbb651f9c20438dc9bee95cc22c48746088de","schema_fingerprint":"4aa3821a28b0b7c2400bc59aba4bcc0a76e971dadd19610d3ad38c768e124dc7","schema_version":"edge-lab-recorder.raw.v1","sequence":null,"source":"clob_market_ws"}
{"event_at":"2026-07-27T04:34:38.755000Z","event_fingerprint":"f10d944c7c73680c90f5afe263554a517a62d9a5d09fd40f6749debcb4635886","payload":{"connection_id":"0f4979d6978d463e9660b042fdcf555f","event_at":"2026-07-27T04:34:38.755000Z","event_type":"price_change","frame_hash":"a0fdc968b476f45e8c1d2d082c4e82789f51b628ab00344c1896c9eb1e922db9","frame_index":0,"kind":"data","monotonic_ns":228861967810375,"payload":{"event_type":"price_change","market":"0xeb66215f2e9faa6449e30a02bab5b8ed7b79a38bf961f6b24d0073c9c2419250","price_changes":[{"asset_id":"60386828328910021732068595344565885737045900010034836345809386672230885527307","best_ask":"0.78","best_bid":"0.76","hash":"928ea2bf680a44841699717157e50cde2de5792d","price":"0.8","side":"SELL","size":"47.6"},{"asset_id":"69697746896130839564035629862476347944307040470122503199396727085502753297492","best_ask":"0.24","best_bid":"0.22","hash":"04bcae74bb22ff94135c4d6227af695695c855ec","price":"0.2","side":"BUY","size":"47.6"}],"timestamp":"1785126878755"},"payload_hash":"88510673da90ac94585b85e096cdf670f7ad0447fdcbed75a01c2d21f68923d5","raw_frame":"{\"market\":\"0xeb66215f2e9faa6449e30a02bab5b8ed7b79a38bf961f6b24d0073c9c2419250\", \"price_changes\":[{\"asset_id\":\"60386828328910021732068595344565885737045900010034836345809386672230885527307\", \"price\":\"0.8\", \"size\":\"47.6\", \"side\":\"SELL\", \"hash\":\"928ea2bf680a44841699717157e50cde2de5792d\", \"best_bid\":\"0.76\", \"best_ask\":\"0.78\"}, {\"asset_id\":\"69697746896130839564035629862476347944307040470122503199396727085502753297492\", \"price\":\"0.2\", \"size\":\"47.6\", \"side\":\"BUY\", \"hash\":\"04bcae74bb22ff94135c4d6227af695695c855ec\", \"best_bid\":\"0.22\", \"best_ask\":\"0.24\"}], \"timestamp\":\"1785126878755\", \"event_type\":\"price_change\"}","received_at":"2026-07-27T04:34:38.700389Z","schema_version":"clob-market-ws.price_change.v1","sequence":null,"server_hash":null,"server_timestamp":"1785126878755","session_id":"e9443c7415a0419799bee9cfbb1a9e4d","source":"clob_market_ws"},"received_at":"2026-07-27T04:34:38.700389Z","record_id":"fca3f72a1bf22ce240f1f67f5e7e3327b2252a134a6a011779d1cdca7f6207a5","schema_fingerprint":"4aa3821a28b0b7c2400bc59aba4bcc0a76e971dadd19610d3ad38c768e124dc7","schema_version":"edge-lab-recorder.raw.v1","sequence":null,"source":"clob_market_ws"}
{"event_at":"2026-07-27T04:34:38.769000Z","event_fingerprint":"108b055014f800cde00919269e57fbc414c42ed973790d2e832071d3c74677dc","payload":{"connection_id":"0f4979d6978d463e9660b042fdcf555f","event_at":"2026-07-27T04:34:38.769000Z","event_type":"price_change","frame_hash":"5adf1e559c1ca1d705b4d3c67b4ec359c6a691d8b790ebcf540e7189318d6a83","frame_index":0,"kind":"data","monotonic_ns":228861981700833,"payload":{"event_type":"price_change","market":"0xeb66215f2e9faa6449e30a02bab5b8ed7b79a38bf961f6b24d0073c9c2419250","price_changes":[{"asset_id":"60386828328910021732068595344565885737045900010034836345809386672230885527307","best_ask":"0.78","best_bid":"0.76","hash":"8e4141f3040b361f9bdd43bbba0274ea7f918fd3","price":"0.01","side":"BUY","size":"5708.02"},{"asset_id":"69697746896130839564035629862476347944307040470122503199396727085502753297492","best_ask":"0.24","best_bid":"0.22","hash":"a6ca8d3edc521e2f581032ba22d698639eedf6d4","price":"0.99","side":"SELL","size":"5708.02"}],"timestamp":"1785126878769"},"payload_hash":"11edb977b15f8e366fa7a1545dd7fdd4ad278e08cc0f11797324c5b8922b7f57","raw_frame":"{\"market\":\"0xeb66215f2e9faa6449e30a02bab5b8ed7b79a38bf961f6b24d0073c9c2419250\", \"price_changes\":[{\"asset_id\":\"60386828328910021732068595344565885737045900010034836345809386672230885527307\", \"price\":\"0.01\", \"size\":\"5708.02\", \"side\":\"BUY\", \"hash\":\"8e4141f3040b361f9bdd43bbba0274ea7f918fd3\", \"best_bid\":\"0.76\", \"best_ask\":\"0.78\"}, {\"asset_id\":\"69697746896130839564035629862476347944307040470122503199396727085502753297492\", \"price\":\"0.99\", \"size\":\"5708.02\", \"side\":\"SELL\", \"hash\":\"a6ca8d3edc521e2f581032ba22d698639eedf6d4\", \"best_bid\":\"0.22\", \"best_ask\":\"0.24\"}], \"timestamp\":\"1785126878769\", \"event_type\":\"price_change\"}","received_at":"2026-07-27T04:34:38.714276Z","schema_version":"clob-market-ws.price_change.v1","sequence":null,"server_hash":null,"server_timestamp":"1785126878769","session_id":"e9443c7415a0419799bee9cfbb1a9e4d","source":"clob_market_ws"},"received_at":"2026-07-27T04:34:38.714276Z","record_id":"91ab4d38518e1e82db77af7a3d0fbcf15adb62b61aa7a00ccac572ea7c5187ef","schema_fingerprint":"4aa3821a28b0b7c2400bc59aba4bcc0a76e971dadd19610d3ad38c768e124dc7","schema_version":"edge-lab-recorder.raw.v1","sequence":null,"source":"clob_market_ws"}
{"event_at":"2026-07-27T04:34:38.781000Z","event_fingerprint":"af54cd9e2c9b42623466b47cd0a1e81ee23c3b62e7c0b6ef1da25246d84b90df","payload":{"connection_id":"0f4979d6978d463e9660b042fdcf555f","event_at":"2026-07-27T04:34:38.781000Z","event_type":"price_change","frame_hash":"92d33b31d4300f515ade2ce43d9e12b3a4608d079bb8ca9012f35c8d2c284519","frame_index":0,"kind":"data","monotonic_ns":228861992895875,"payload":{"event_type":"price_change","market":"0xeb66215f2e9faa6449e30a02bab5b8ed7b79a38bf961f6b24d0073c9c2419250","price_changes":[{"asset_id":"60386828328910021732068595344565885737045900010034836345809386672230885527307","best_ask":"0.78","best_bid":"0.76","hash":"41d857efdb62972b3be401000217b7515503d4e5","price":"0.6","side":"BUY","size":"57.5"},{"asset_id":"69697746896130839564035629862476347944307040470122503199396727085502753297492","best_ask":"0.24","best_bid":"0.22","hash":"ce8710f7197a85ae8337ab6615f6124eb2ad40b0","price":"0.4","side":"SELL","size":"57.5"}],"timestamp":"1785126878781"},"payload_hash":"3303dd22bee8fb907f78a86bc953cb58ce90a21c688cb68f2cd3b0ae46ced474","raw_frame":"{\"market\":\"0xeb66215f2e9faa6449e30a02bab5b8ed7b79a38bf961f6b24d0073c9c2419250\", \"price_changes\":[{\"asset_id\":\"60386828328910021732068595344565885737045900010034836345809386672230885527307\", \"price\":\"0.6\", \"size\":\"57.5\", \"side\":\"BUY\", \"hash\":\"41d857efdb62972b3be401000217b7515503d4e5\", \"best_bid\":\"0.76\", \"best_ask\":\"0.78\"}, {\"asset_id\":\"69697746896130839564035629862476347944307040470122503199396727085502753297492\", \"price\":\"0.4\", \"size\":\"57.5\", \"side\":\"SELL\", \"hash\":\"ce8710f7197a85ae8337ab6615f6124eb2ad40b0\", \"best_bid\":\"0.22\", \"best_ask\":\"0.24\"}], \"timestamp\":\"1785126878781\", \"event_type\":\"price_change\"}","received_at":"2026-07-27T04:34:38.725474Z","schema_version":"clob-market-ws.price_change.v1","sequence":null,"server_hash":null,"server_timestamp":"1785126878781","session_id":"e9443c7415a0419799bee9cfbb1a9e4d","source":"clob_market_ws"},"received_at":"2026-07-27T04:34:38.725474Z","record_id":"8b770791224709f561337030878653f1eb4574f2903094076d632ac8a479aeaa","schema_fingerprint":"4aa3821a28b0b7c2400bc59aba4bcc0a76e971dadd19610d3ad38c768e124dc7","schema_version":"edge-lab-recorder.raw.v1","sequence":null,"source":"clob_market_ws"}
{"event_at":"2026-07-27T04:34:38.799000Z","event_fingerprint":"bdc8ba9c519eb72a0f1fc76a7bf186a66106864db5f33a658985a62fec3bbdd5","payload":{"connection_id":"0f4979d6978d463e9660b042fdcf555f","event_at":"2026-07-27T04:34:38.799000Z","event_type":"best_bid_ask","frame_hash":"46bb9f99f8740848fedef48819f94f97e9f1380d48acc900a1255758492eb5af","frame_index":0,"kind":"data","monotonic_ns":228862011592250,"payload":{"asset_id":"69697746896130839564035629862476347944307040470122503199396727085502753297492","best_ask":"0.24","best_bid":"0.23","event_type":"best_bid_ask","market":"0xeb66215f2e9faa6449e30a02bab5b8ed7b79a38bf961f6b24d0073c9c2419250","spread":"0.01","timestamp":"1785126878799"},"payload_hash":"911d8c47f46046f2e1b05eaa3de41d8d2c3fa9ac6c55da55ad054eacc7f10032","raw_frame":"{\"market\":\"0xeb66215f2e9faa6449e30a02bab5b8ed7b79a38bf961f6b24d0073c9c2419250\", \"asset_id\":\"69697746896130839564035629862476347944307040470122503199396727085502753297492\", \"best_bid\":\"0.23\", \"best_ask\":\"0.24\", \"spread\":\"0.01\", \"timestamp\":\"1785126878799\", \"event_type\":\"best_bid_ask\"}","received_at":"2026-07-27T04:34:38.744170Z","schema_version":"clob-market-ws.best_bid_ask.v1","sequence":null,"server_hash":null,"server_timestamp":"1785126878799","session_id":"e9443c7415a0419799bee9cfbb1a9e4d","source":"clob_market_ws"},"received_at":"2026-07-27T04:34:38.744170Z","record_id":"33f2ee5bdd146cd80555904b9929fd902ef827e45b1d47dad0786f3df40eb9c9","schema_fingerprint":"8488399f31b0337811b13b266be932db7062827c2470b78bd8e9e99bab51d17d","schema_version":"edge-lab-recorder.raw.v1","sequence":null,"source":"clob_market_ws"}
{"event_at":"2026-07-27T04:34:38.799000Z","event_fingerprint":"d1ebee158a67c6d827061abc18f4452581541637050b770b2befad8dae825c1e","payload":{"connection_id":"0f4979d6978d463e9660b042fdcf555f","event_at":"2026-07-27T04:34:38.799000Z","event_type":"best_bid_ask","frame_hash":"655078204c18b29f95d83b0b5d4f486423f8f7323561e93c68e7a6a4aef60f67","frame_index":0,"kind":"data","monotonic_ns":228862012725666,"payload":{"asset_id":"60386828328910021732068595344565885737045900010034836345809386672230885527307","best_ask":"0.77","best_bid":"0.76","event_type":"best_bid_ask","market":"0xeb66215f2e9faa6449e30a02bab5b8ed7b79a38bf961f6b24d0073c9c2419250","spread":"0.01","timestamp":"1785126878799"},"payload_hash":"e21d06f2a161be3705154f8175398637f8d619285a55b4a8d596a9bd958bc13c","raw_frame":"{\"market\":\"0xeb66215f2e9faa6449e30a02bab5b8ed7b79a38bf961f6b24d0073c9c2419250\", \"asset_id\":\"60386828328910021732068595344565885737045900010034836345809386672230885527307\", \"best_bid\":\"0.76\", \"best_ask\":\"0.77\", \"spread\":\"0.01\", \"timestamp\":\"1785126878799\", \"event_type\":\"best_bid_ask\"}","received_at":"2026-07-27T04:34:38.745304Z","schema_version":"clob-market-ws.best_bid_ask.v1","sequence":null,"server_hash":null,"server_timestamp":"1785126878799","session_id":"e9443c7415a0419799bee9cfbb1a9e4d","source":"clob_market_ws"},"received_at":"2026-07-27T04:34:38.745304Z","record_id":"7566e8c0fa65c234823c28f6444685ab9cd1a4c2446c96c82ed27bb44333725f","schema_fingerprint":"8488399f31b0337811b13b266be932db7062827c2470b78bd8e9e99bab51d17d","schema_version":"edge-lab-recorder.raw.v1","sequence":null,"source":"clob_market_ws"}
{"event_at":"2026-07-27T04:34:38.799000Z","event_fingerprint":"11d49785ae65c4dcdf415134ef657699a2a103a14051e5b15d02539dae1ea5c4","payload":{"connection_id":"0f4979d6978d463e9660b042fdcf555f","event_at":"2026-07-27T04:34:38.799000Z","event_type":"price_change","frame_hash":"6d3e6e581aeb00caf5c8c449c2d3f6d29e173dacfa5e2bf0ae29842911da5718","frame_index":0,"kind":"data","monotonic_ns":228862013859500,"payload":{"event_type":"price_change","market":"0xeb66215f2e9faa6449e30a02bab5b8ed7b79a38bf961f6b24d0073c9c2419250","price_changes":[{"asset_id":"69697746896130839564035629862476347944307040470122503199396727085502753297492","best_ask":"0.24","best_bid":"0.23","hash":"ede90f77295e90631183ae38a1990c0a6b043d8b","price":"0.23","side":"BUY","size":"5"},{"asset_id":"60386828328910021732068595344565885737045900010034836345809386672230885527307","best_ask":"0.77","best_bid":"0.76","hash":"d8269ccfd621c3320a7220319b25259b30b4071b","price":"0.77","side":"SELL","size":"5"}],"timestamp":"1785126878799"},"payload_hash":"bd6d7231649e579e4d4e938cbc52facdc17942a98532dfa2d5d42a11247291e5","raw_frame":"{\"market\":\"0xeb66215f2e9faa6449e30a02bab5b8ed7b79a38bf961f6b24d0073c9c2419250\", \"price_changes\":[{\"asset_id\":\"69697746896130839564035629862476347944307040470122503199396727085502753297492\", \"price\":\"0.23\", \"size\":\"5\", \"side\":\"BUY\", \"hash\":\"ede90f77295e90631183ae38a1990c0a6b043d8b\", \"best_bid\":\"0.23\", \"best_ask\":\"0.24\"}, {\"asset_id\":\"60386828328910021732068595344565885737045900010034836345809386672230885527307\", \"price\":\"0.77\", \"size\":\"5\", \"side\":\"SELL\", \"hash\":\"d8269ccfd621c3320a7220319b25259b30b4071b\", \"best_bid\":\"0.76\", \"best_ask\":\"0.77\"}], \"timestamp\":\"1785126878799\", \"event_type\":\"price_change\"}","received_at":"2026-07-27T04:34:38.746437Z","schema_version":"clob-market-ws.price_change.v1","sequence":null,"server_hash":null,"server_timestamp":"1785126878799","session_id":"e9443c7415a0419799bee9cfbb1a9e4d","source":"clob_market_ws"},"received_at":"2026-07-27T04:34:38.746437Z","record_id":"cb02c0f7e180c7b203110b7a0066a45b1816ba7ca89cca5f714f1ee5d1c4c11d","schema_fingerprint":"4aa3821a28b0b7c2400bc59aba4bcc0a76e971dadd19610d3ad38c768e124dc7","schema_version":"edge-lab-recorder.raw.v1","sequence":null,"source":"clob_market_ws"}
{"event_at":"2026-07-27T04:34:38.819000Z","event_fingerprint":"b26b79733afe16bdb93cb4a41f6024c113417443e5b7d0c0d318f913cd9fb34c","payload":{"connection_id":"0f4979d6978d463e9660b042fdcf555f","event_at":"2026-07-27T04:34:38.819000Z","event_type":"best_bid_ask","frame_hash":"26de5c20d165285b274084dda51ff5bdb1a21508433e95373f3d54c3005227bf","frame_index":0,"kind":"data","monotonic_ns":228862031255666,"payload":{"asset_id":"69697746896130839564035629862476347944307040470122503199396727085502753297492","best_ask":"0.24","best_bid":"0.22","event_type":"best_bid_ask","market":"0xeb66215f2e9faa6449e30a02bab5b8ed7b79a38bf961f6b24d0073c9c2419250","spread":"0.02","timestamp":"1785126878819"},"payload_hash":"f6a205de6d0a640af8a90ca54f77b960dddd0587e60fedbe87e93a9814e09484","raw_frame":"{\"market\":\"0xeb66215f2e9faa6449e30a02bab5b8ed7b79a38bf961f6b24d0073c9c2419250\", \"asset_id\":\"69697746896130839564035629862476347944307040470122503199396727085502753297492\", \"best_bid\":\"0.22\", \"best_ask\":\"0.24\", \"spread\":\"0.02\", \"timestamp\":\"1785126878819\", \"event_type\":\"best_bid_ask\"}","received_at":"2026-07-27T04:34:38.763831Z","schema_version":"clob-market-ws.best_bid_ask.v1","sequence":null,"server_hash":null,"server_timestamp":"1785126878819","session_id":"e9443c7415a0419799bee9cfbb1a9e4d","source":"clob_market_ws"},"received_at":"2026-07-27T04:34:38.763831Z","record_id":"82c17482cb59a4094f94494986f60f01033891475de81ae67a04fa2f7d6737bc","schema_fingerprint":"8488399f31b0337811b13b266be932db7062827c2470b78bd8e9e99bab51d17d","schema_version":"edge-lab-recorder.raw.v1","sequence":null,"source":"clob_market_ws"}
