{"event_at":"2026-07-27T04:33:18.361000Z","event_fingerprint":"364484d843cda3c2447a12ddbf2a8afb0f18d31d91dc6da7f1555f87b902ac70","payload":{"connection_id":"0f4979d6978d463e9660b042fdcf555f","event_at":"2026-07-27T04:33:18.361000Z","event_type":"price_change","frame_hash":"ef192815f504e82c7f4ec5cb6007092110b0b1c4251050c6ece2fec83080e59d","frame_index":0,"kind":"data","monotonic_ns":228781575160000,"payload":{"event_type":"price_change","market":"0xeb66215f2e9faa6449e30a02bab5b8ed7b79a38bf961f6b24d0073c9c2419250","price_changes":[{"asset_id":"69697746896130839564035629862476347944307040470122503199396727085502753297492","best_ask":"0.13","best_bid":"0.12","hash":"97ebc4e888cf98a2bb8f200654d76ea5cd9eb3bf","price":"0.06","side":"BUY","size":"880.84"},{"asset_id":"60386828328910021732068595344565885737045900010034836345809386672230885527307","best_ask":"0.88","best_bid":"0.87","hash":"3718efed528653d9eed7d2993fc4c28ca658f5fe","price":"0.94","side":"SELL","size":"880.84"}],"timestamp":"1785126798361"},"payload_hash":"071b2d98cb05f963ae715b8c13c91bb9213113f5b464cb91f269720a10ce0ec8","raw_frame":"{\"market\":\"0xeb66215f2e9faa6449e30a02bab5b8ed7b79a38bf961f6b24d0073c9c2419250\", \"price_changes\":[{\"asset_id\":\"69697746896130839564035629862476347944307040470122503199396727085502753297492\", \"price\":\"0.06\", \"size\":\"880.84\", \"side\":\"BUY\", \"hash\":\"97ebc4e888cf98a2bb8f200654d76ea5cd9eb3bf\", \"best_bid\":\"0.12\", \"best_ask\":\"0.13\"}, {\"asset_id\":\"60386828328910021732068595344565885737045900010034836345809386672230885527307\", \"price\":\"0.94\", \"size\":\"880.84\", \"side\":\"SELL\", \"hash\":\"3718efed528653d9eed7d2993fc4c28ca658f5fe\", \"best_bid\":\"0.87\", \"best_ask\":\"0.88\"}], \"timestamp\":\"1785126798361\", \"event_type\":\"price_change\"}","received_at":"2026-07-27T04:33:18.307035Z","schema_version":"clob-market-ws.price_change.v1","sequence":null,"server_hash":null,"server_timestamp":"1785126798361","session_id":"e9443c7415a0419799bee9cfbb1a9e4d","source":"clob_market_ws"},"received_at":"2026-07-27T04:33:18.307035Z","record_id":"0b4f6165c3fb3464324639787ca1a4abf6f089151b84b566465c86914d65e3ef","schema_fingerprint":"4aa3821a28b0b7c2400bc59aba4bcc0a76e971dadd19610d3ad38c768e124dc7","schema_version":"edge-lab-recorder.raw.v1","sequence":null,"source":"clob_market_ws"}
{"event_at":"2026-07-27T04:33:18.362000Z","event_fingerprint":"aced6e5bd575e3418e3a97e5a4e02d87c01a703f317a62619b8c88a0109165d0","payload":{"connection_id":"0f4979d6978d463e9660b042fdcf555f","event_at":"2026-07-27T04:33:18.362000Z","event_type":"price_change","frame_hash":"ac1a682adc4811c6de2589e85bd3d6803b5896a9b94ebda1dc4f143bbfe51410","frame_index":0,"kind":"data","monotonic_ns":228781577850791,"payload":{"event_type":"price_change","market":"0xeb66215f2e9faa6449e30a02bab5b8ed7b79a38bf961f6b24d0073c9c2419250","price_changes":[{"asset_id":"60386828328910021732068595344565885737045900010034836345809386672230885527307","best_ask":"0.88","best_bid":"0.87","hash":"8cbfce4940f2de32b165a8867a320472c5597717","price":"0.73","side":"BUY","size":"258.18"},{"asset_id":"69697746896130839564035629862476347944307040470122503199396727085502753297492","best_ask":"0.13","best_bid":"0.12","hash":"cb3da4b425cd313f926db9bd6be035da3426da8e","price":"0.27","side":"SELL","size":"258.18"}],"timestamp":"1785126798362"},"payload_hash":"c7dae99e30b611661bd8249bf5e47a0eac60375ae00c9e0cb638e8c2e44604e1","raw_frame":"{\"market\":\"0xeb66215f2e9faa6449e30a02bab5b8ed7b79a38bf961f6b24d0073c9c2419250\", \"price_changes\":[{\"asset_id\":\"60386828328910021732068595344565885737045900010034836345809386672230885527307\", \"price\":\"0.73\", \"size\":\"258.18\", \"side\":\"BUY\", \"hash\":\"8cbfce4940f2de32b165a8867a320472c5597717\", \"best_bid\":\"0.87\", \"best_ask\":\"0.88\"}, {\"asset_id\":\"69697746896130839564035629862476347944307040470122503199396727085502753297492\", \"price\":\"0.27\", \"size\":\"258.18\", \"side\":\"SELL\", \"hash\":\"cb3da4b425cd313f926db9bd6be035da3426da8e\", \"best_bid\":\"0.12\", \"best_ask\":\"0.13\"}], \"timestamp\":\"1785126798362\", \"event_type\":\"price_change\"}","received_at":"2026-07-27T04:33:18.309730Z","schema_version":"clob-market-ws.price_change.v1","sequence":null,"server_hash":null,"server_timestamp":"1785126798362","session_id":"e9443c7415a0419799bee9cfbb1a9e4d","source":"clob_market_ws"},"received_at":"2026-07-27T04:33:18.309730Z","record_id":"23bac9407b1fc9f1cc0281d40c46ec1663b80c112bf8d4441eb7dec4f8f5c158","schema_fingerprint":"4aa3821a28b0b7c2400bc59aba4bcc0a76e971dadd19610d3ad38c768e124dc7","schema_version":"edge-lab-recorder.raw.v1","sequence":null,"source":"clob_market_ws"}
{"event_at":"2026-07-27T04:33:18.374000Z","event_fingerprint":"a63071bb898cc7efe4c9aa2d8a2e802f32ff667b4a36b6a1ea715eab0c96ef0a","payload":{"connection_id":"0f4979d6978d463e9660b042fdcf555f","event_at":"2026-07-27T04:33:18.374000Z","event_type":"price_change","frame_hash":"3a2192096bbdd61c3b49e6594fe0dcdf0b5e2469fea5cdf452c8e6a22afaca3b","frame_index":0,"kind":"data","monotonic_ns":228781586566916,"payload":{"event_type":"price_change","market":"0xeb66215f2e9faa6449e30a02bab5b8ed7b79a38bf961f6b24d0073c9c2419250","price_changes":[{"asset_id":"69697746896130839564035629862476347944307040470122503199396727085502753297492","best_ask":"0.13","best_bid":"0.12","hash":"4646e06196a0c3d06fc580ca7c65ecc91d161f5e","price":"0.02","side":"BUY","size":"973.1"},{"asset_id":"60386828328910021732068595344565885737045900010034836345809386672230885527307","best_ask":"0.88","best_bid":"0.87","hash":"0f0f75a9cb486b64c1debfc65ff4322deaf3fa55","price":"0.98","side":"SELL","size":"973.1"}],"timestamp":"1785126798374"},"payload_hash":"445ba9943960582f1e5ef3fea66f8932a6d125faab82a8df1d203e3c46da9f97","raw_frame":"{\"market\":\"0xeb66215f2e9faa6449e30a02bab5b8ed7b79a38bf961f6b24d0073c9c2419250\", \"price_changes\":[{\"asset_id\":\"69697746896130839564035629862476347944307040470122503199396727085502753297492\", \"price\":\"0.02\", \"size\":\"973.1\", \"side\":\"BUY\", \"hash\":\"4646e06196a0c3d06fc580ca7c65ecc91d161f5e\", \"best_bid\":\"0.12\", \"best_ask\":\"0.13\"}, {\"asset_id\":\"60386828328910021732068595344565885737045900010034836345809386672230885527307\", \"price\":\"0.98\", \"size\":\"973.1\", \"side\":\"SELL\", \"hash\":\"0f0f75a9cb486b64c1debfc65ff4322deaf3fa55\", \"best_bid\":\"0.87\", \"best_ask\":\"0.88\"}], \"timestamp\":\"1785126798374\", \"event_type\":\"price_change\"}","received_at":"2026-07-27T04:33:18.318444Z","schema_version":"clob-market-ws.price_change.v1","sequence":null,"server_hash":null,"server_timestamp":"1785126798374","session_id":"e9443c7415a0419799bee9cfbb1a9e4d","source":"clob_market_ws"},"received_at":"2026-07-27T04:33:18.318444Z","record_id":"ebf6f31fdaa09fa6403c93e5ce2e5aa17b4b65b63aebde3e45c63d42c929d7e4","schema_fingerprint":"4aa3821a28b0b7c2400bc59aba4bcc0a76e971dadd19610d3ad38c768e124dc7","schema_version":"edge-lab-recorder.raw.v1","sequence":null,"source":"clob_market_ws"}
{"event_at":"2026-07-27T04:33:18.374000Z","event_fingerprint":"f6bcd95ae77ba2b5cea4188dd5b9ab0a32b391ac6fbcafe9529115da66b7d1d8","payload":{"connection_id":"0f4979d6978d463e9660b042fdcf555f","event_at":"2026-07-27T04:33:18.374000Z","event_type":"price_change","frame_hash":"5eff3121b87fb7cbd3c3164551baaa16813217134db8ec68e78fc282c367b4b0","frame_index":0,"kind":"data","monotonic_ns":228781589956750,"payload":{"event_type":"price_change","market":"0xeb66215f2e9faa6449e30a02bab5b8ed7b79a38bf961f6b24d0073c9c2419250","price_changes":[{"asset_id":"69697746896130839564035629862476347944307040470122503199396727085502753297492","best_ask":"0.13","best_bid":"0.12","hash":"17aa3e055560db892905f8cb6dd9cfb2da3415ec","price":"0.12","side":"BUY","size":"25"},{"asset_id":"60386828328910021732068595344565885737045900010034836345809386672230885527307","best_ask":"0.88","best_bid":"0.87","hash":"cba5886a84836b98b8a9d7df071ec44f45167721","price":"0.88","side":"SELL","size":"25"}],"timestamp":"1785126798374"},"payload_hash":"1aa6447bbae31d656a38d80cdd2c8e1e80aba80ef23d91c5a6efa929a7825f50","raw_frame":"{\"market\":\"0xeb66215f2e9faa6449e30a02bab5b8ed7b79a38bf961f6b24d0073c9c2419250\", \"price_changes\":[{\"asset_id\":\"69697746896130839564035629862476347944307040470122503199396727085502753297492\", \"price\":\"0.12\", \"size\":\"25\", \"side\":\"BUY\", \"hash\":\"17aa3e055560db892905f8cb6dd9cfb2da3415ec\", \"best_bid\":\"0.12\", \"best_ask\":\"0.13\"}, {\"asset_id\":\"60386828328910021732068595344565885737045900010034836345809386672230885527307\", \"price\":\"0.88\", \"size\":\"25\", \"side\":\"SELL\", \"hash\":\"cba5886a84836b98b8a9d7df071ec44f45167721\", \"best_bid\":\"0.87\", \"best_ask\":\"0.88\"}], \"timestamp\":\"1785126798374\", \"event_type\":\"price_change\"}","received_at":"2026-07-27T04:33:18.321838Z","schema_version":"clob-market-ws.price_change.v1","sequence":null,"server_hash":null,"server_timestamp":"1785126798374","session_id":"e9443c7415a0419799bee9cfbb1a9e4d","source":"clob_market_ws"},"received_at":"2026-07-27T04:33:18.321838Z","record_id":"0da64c0aa1bbe19bf52c6b3a1f6328a1495141eeded779bc5059a03c263ebb4c","schema_fingerprint":"4aa3821a28b0b7c2400bc59aba4bcc0a76e971dadd19610d3ad38c768e124dc7","schema_version":"edge-lab-recorder.raw.v1","sequence":null,"source":"clob_market_ws"}
{"event_at":"2026-07-27T04:33:18.378000Z","event_fingerprint":"f1023df896ddc7a3b1b9201dc8dbd836a12f7fd9b9f5a6fefa1c1db2c3935838","payload":{"connection_id":"0f4979d6978d463e9660b042fdcf555f","event_at":"2026-07-27T04:33:18.378000Z","event_type":"price_change","frame_hash":"4ebe9a701c0b302ba79a4b29ec914a28daa08ca8662871b2de341dfa896853f4","frame_index":0,"kind":"data","monotonic_ns":228781593237583,"payload":{"event_type":"price_change","market":"0xeb66215f2e9faa6449e30a02bab5b8ed7b79a38bf961f6b24d0073c9c2419250","price_changes":[{"asset_id":"60386828328910021732068595344565885737045900010034836345809386672230885527307","best_ask":"0.88","best_bid":"0.87","hash":"99e53eee4615f9d4402e8832e0c55a1fab9c2ba8","price":"0.86","side":"BUY","size":"143.31"},{"asset_id":"69697746896130839564035629862476347944307040470122503199396727085502753297492","best_ask":"0.13","best_bid":"0.12","hash":"6043128755d94d38af87f954f3dfb6605fb0914d","price":"0.14","side":"SELL","size":"143.31"}],"timestamp":"1785126798378"},"payload_hash":"58728b232a9a8645ceedb06fc332826b9f7d7f23a6e55e1adbf4db4a23353ba9","raw_frame":"{\"market\":\"0xeb66215f2e9faa6449e30a02bab5b8ed7b79a38bf961f6b24d0073c9c2419250\", \"price_changes\":[{\"asset_id\":\"60386828328910021732068595344565885737045900010034836345809386672230885527307\", \"price\":\"0.86\", \"size\":\"143.31\", \"side\":\"BUY\", \"hash\":\"99e53eee4615f9d4402e8832e0c55a1fab9c2ba8\", \"best_bid\":\"0.87\", \"best_ask\":\"0.88\"}, {\"asset_id\":\"69697746896130839564035629862476347944307040470122503199396727085502753297492\", \"price\":\"0.14\", \"size\":\"143.31\", \"side\":\"SELL\", \"hash\":\"6043128755d94d38af87f954f3dfb6605fb0914d\", \"best_bid\":\"0.12\", \"best_ask\":\"0.13\"}], \"timestamp\":\"1785126798378\", \"event_type\":\"price_change\"}","received_at":"2026-07-27T04:33:18.325119Z","schema_version":"clob-market-ws.price_change.v1","sequence":null,"server_hash":null,"server_timestamp":"1785126798378","session_id":"e9443c7415a0419799bee9cfbb1a9e4d","source":"clob_market_ws"},"received_at":"2026-07-27T04:33:18.325119Z","record_id":"f511f9e0f7a6e2c7e911535887aec93931e187b252d3b95794df77e5a6511dbb","schema_fingerprint":"4aa3821a28b0b7c2400bc59aba4bcc0a76e971dadd19610d3ad38c768e124dc7","schema_version":"edge-lab-recorder.raw.v1","sequence":null,"source":"clob_market_ws"}
{"event_at":"2026-07-27T04:33:18.379000Z","event_fingerprint":"d591b9a9712c7acd2493d599c2ac172fc3072ead7422f16f6ad06f0cbf1dcbcd","payload":{"connection_id":"0f4979d6978d463e9660b042fdcf555f","event_at":"2026-07-27T04:33:18.379000Z","event_type":"price_change","frame_hash":"429a1b53f1f2deed67f09ffa3574db0eb2a4f6adbb112a57c45f1cac48c6be9e","frame_index":0,"kind":"data","monotonic_ns":228781596545625,"payload":{"event_type":"price_change","market":"0xeb66215f2e9faa6449e30a02bab5b8ed7b79a38bf961f6b24d0073c9c2419250","price_changes":[{"asset_id":"69697746896130839564035629862476347944307040470122503199396727085502753297492","best_ask":"0.13","best_bid":"0.12","hash":"184a0c77172382962cd403f9d9fab3262f706544","price":"0.09","side":"BUY","size":"1049.6"},{"asset_id":"60386828328910021732068595344565885737045900010034836345809386672230885527307","best_ask":"0.88","best_bid":"0.87","hash":"5984fc8c129627732fd79971de1dcdc14bb9b409","price":"0.91","side":"SELL","size":"1049.6"}],"timestamp":"1785126798379"},"payload_hash":"8f7df1aa1ceaea42e9799fbd49bc3746c40ffaf28b5d3b2a1a6aaf4db725d15b","raw_frame":"{\"market\":\"0xeb66215f2e9faa6449e30a02bab5b8ed7b79a38bf961f6b24d0073c9c2419250\", \"price_changes\":[{\"asset_id\":\"69697746896130839564035629862476347944307040470122503199396727085502753297492\", \"price\":\"0.09\", \"size\":\"1049.6\", \"side\":\"BUY\", \"hash\":\"184a0c77172382962cd403f9d9fab3262f706544\", \"best_bid\":\"0.12\", \"best_ask\":\"0.13\"}, {\"asset_id\":\"60386828328910021732068595344565885737045900010034836345809386672230885527307\", \"price\":\"0.91\", \"size\":\"1049.6\", \"side\":\"SELL\", \"hash\":\"5984fc8c129627732fd79971de1dcdc14bb9b409\", \"best_bid\":\"0.87\", \"best_ask\":\"0.88\"}], \"timestamp\":\"1785126798379\", \"event_type\":\"price_change\"}","received_at":"2026-07-27T04:33:18.328427Z","schema_version":"clob-market-ws.price_change.v1","sequence":null,"server_hash":null,"server_timestamp":"1785126798379","session_id":"e9443c7415a0419799bee9cfbb1a9e4d","source":"clob_market_ws"},"received_at":"2026-07-27T04:33:18.328427Z","record_id":"05d2cda089e1c43fd4baf06184380bcd3cb783d8c8338d02d3f2c478d6f8f756","schema_fingerprint":"4aa3821a28b0b7c2400bc59aba4bcc0a76e971dadd19610d3ad38c768e124dc7","schema_version":"edge-lab-recorder.raw.v1","sequence":null,"source":"clob_market_ws"}
{"event_at":"2026-07-27T04:33:18.393000Z","event_fingerprint":"11d1a8f458b798f46cc7e37e2705b1a62d803c67e6c97398bb6c20cbac8cc6c5","payload":{"connection_id":"0f4979d6978d463e9660b042fdcf555f","event_at":"2026-07-27T04:33:18.393000Z","event_type":"price_change","frame_hash":"7365595f1a06ced11734183ec5ebc65938f2a42c63c2dc9246a133aa3de4792b","frame_index":0,"kind":"data","monotonic_ns":228781606489125,"payload":{"event_type":"price_change","market":"0xeb66215f2e9faa6449e30a02bab5b8ed7b79a38bf961f6b24d0073c9c2419250","price_changes":[{"asset_id":"60386828328910021732068595344565885737045900010034836345809386672230885527307","best_ask":"0.88","best_bid":"0.87","hash":"8f321972ae4e005497c01348e40706b5d4421d82","price":"0.74","side":"BUY","size":"126.6"},{"asset_id":"69697746896130839564035629862476347944307040470122503199396727085502753297492","best_ask":"0.13","best_bid":"0.12","hash":"ca7656afa1e242b511aa63f90f66aa5a023154b8","price":"0.26","side":"SELL","size":"126.6"}],"timestamp":"1785126798393"},"payload_hash":"af792a1759b5f2c6fdd20c3b13637fa3ae712920c66e83cd681398c3588724be","raw_frame":"{\"market\":\"0xeb66215f2e9faa6449e30a02bab5b8ed7b79a38bf961f6b24d0073c9c2419250\", \"price_changes\":[{\"asset_id\":\"60386828328910021732068595344565885737045900010034836345809386672230885527307\", \"price\":\"0.74\", \"size\":\"126.6\", \"side\":\"BUY\", \"hash\":\"8f321972ae4e005497c01348e40706b5d4421d82\", \"best_bid\":\"0.87\", \"best_ask\":\"0.88\"}, {\"asset_id\":\"69697746896130839564035629862476347944307040470122503199396727085502753297492\", \"price\":\"0.26\", \"size\":\"126.6\", \"side\":\"SELL\", \"hash\":\"ca7656afa1e242b511aa63f90f66aa5a023154b8\", \"best_bid\":\"0.12\", \"best_ask\":\"0.13\"}], \"timestamp\":\"1785126798393\", \"event_type\":\"price_change\"}","received_at":"2026-07-27T04:33:18.338370Z","schema_version":"clob-market-ws.price_change.v1","sequence":null,"server_hash":null,"server_timestamp":"1785126798393","session_id":"e9443c7415a0419799bee9cfbb1a9e4d","source":"clob_market_ws"},"received_at":"2026-07-27T04:33:18.338370Z","record_id":"60a6422547d9a63c532ccacee0727ee34e3422a7ef7dd0295405a05f2849f3f0","schema_fingerprint":"4aa3821a28b0b7c2400bc59aba4bcc0a76e971dadd19610d3ad38c768e124dc7","schema_version":"edge-lab-recorder.raw.v1","sequence":null,"source":"clob_market_ws"}
{"event_at":"2026-07-27T04:33:18.394000Z","event_fingerprint":"b9503735126e1fcee6da60b76b0b363b090bfd69753b9e011a7b4e46098dace5","payload":{"connection_id":"0f4979d6978d463e9660b042fdcf555f","event_at":"2026-07-27T04:33:18.394000Z","event_type":"price_change","frame_hash":"b93aacb474fb0c17286d89ccea25694193e258d5f9f650a0946b2ed6b53de4b8","frame_index":0,"kind":"data","monotonic_ns":228781609575583,"payload":{"event_type":"price_change","market":"0xeb66215f2e9faa6449e30a02bab5b8ed7b79a38bf961f6b24d0073c9c2419250","price_changes":[{"asset_id":"60386828328910021732068595344565885737045900010034836345809386672230885527307","best_ask":"0.88","best_bid":"0.87","hash":"a0416069d3338e40fd50b630cd4c8e03057a43fb","price":"0.89","side":"SELL","size":"439.6"},{"asset_id":"69697746896130839564035629862476347944307040470122503199396727085502753297492","best_ask":"0.13","best_bid":"0.12","hash":"84f62ce817ba3226b862de429e07724d0027fad6","price":"0.11","side":"BUY","size":"439.6"}],"timestamp":"1785126798394"},"payload_hash":"93e74ba79ba387f7df22c5985b70282d530f2db8bf458398cbb06417074138dd","raw_frame":"{\"market\":\"0xeb66215f2e9faa6449e30a02bab5b8ed7b79a38bf961f6b24d0073c9c2419250\", \"price_changes\":[{\"asset_id\":\"60386828328910021732068595344565885737045900010034836345809386672230885527307\", \"price\":\"0.89\", \"size\":\"439.6\", \"side\":\"SELL\", \"hash\":\"a0416069d3338e40fd50b630cd4c8e03057a43fb\", \"best_bid\":\"0.87\", \"best_ask\":\"0.88\"}, {\"asset_id\":\"69697746896130839564035629862476347944307040470122503199396727085502753297492\", \"price\":\"0.11\", \"size\":\"439.6\", \"side\":\"BUY\", \"hash\":\"84f62ce817ba3226b862de429e07724d0027fad6\", \"best_bid\":\"0.12\", \"best_ask\":\"0.13\"}], \"timestamp\":\"1785126798394\", \"event_type\":\"price_change\"}","received_at":"2026-07-27T04:33:18.341459Z","schema_version":"clob-market-ws.price_change.v1","sequence":null,"server_hash":null,"server_timestamp":"1785126798394","session_id":"e9443c7415a0419799bee9cfbb1a9e4d","source":"clob_market_ws"},"received_at":"2026-07-27T04:33:18.341459Z","record_id":"e5b907f52e479e5649485858729ac3a583a72164ae187418d3dc7b5e4e30faa1","schema_fingerprint":"4aa3821a28b0b7c2400bc59aba4bcc0a76e971dadd19610d3ad38c768e124dc7","schema_version":"edge-lab-recorder.raw.v1","sequence":null,"source":"clob_market_ws"}
{"event_at":"2026-07-27T04:33:18.396000Z","event_fingerprint":"6d5aa4dd561ddced1c971eb50a6835d2a57bc7a22fe54dcce51ffc59f11180c4","payload":{"connection_id":"0f4979d6978d463e9660b042fdcf555f","event_at":"2026-07-27T04:33:18.396000Z","event_type":"best_bid_ask","frame_hash":"ebfb64f826146688ae06f5ccc79947bc444cd61feadacc5e7b5fbb2f4f74c509","frame_index":0,"kind":"data","monotonic_ns":228781611354416,"payload":{"asset_id":"69697746896130839564035629862476347944307040470122503199396727085502753297492","best_ask":"0.13","best_bid":"0.11","event_type":"best_bid_ask","market":"0xeb66215f2e9faa6449e30a02bab5b8ed7b79a38bf961f6b24d0073c9c2419250","spread":"0.02","timestamp":"1785126798396"},"payload_hash":"91f2959c864aae8d4582b469d72cc9159113ebb6e65f4e31c09b7130192cc136","raw_frame":"{\"market\":\"0xeb66215f2e9faa6449e30a02bab5b8ed7b79a38bf961f6b24d0073c9c2419250\", \"asset_id\":\"69697746896130839564035629862476347944307040470122503199396727085502753297492\", \"best_bid\":\"0.11\", \"best_ask\":\"0.13\", \"spread\":\"0.02\", \"timestamp\":\"1785126798396\", \"event_type\":\"best_bid_ask\"}","received_at":"2026-07-27T04:33:18.343235Z","schema_version":"clob-market-ws.best_bid_ask.v1","sequence":null,"server_hash":null,"server_timestamp":"1785126798396","session_id":"e9443c7415a0419799bee9cfbb1a9e4d","source":"clob_market_ws"},"received_at":"2026-07-27T04:33:18.343235Z","record_id":"3facf58827f6b89afe6276897a3d70145418c7615932016e6cb3b6b08b0e59f5","schema_fingerprint":"8488399f31b0337811b13b266be932db7062827c2470b78bd8e9e99bab51d17d","schema_version":"edge-lab-recorder.raw.v1","sequence":null,"source":"clob_market_ws"}
{"event_at":"2026-07-27T04:33:18.396000Z","event_fingerprint":"1d6c122c52daad3b3606206f3bea1e5a7b93071cfd7441659465859e31db5da7","payload":{"connection_id":"0f4979d6978d463e9660b042fdcf555f","event_at":"2026-07-27T04:33:18.396000Z","event_type":"best_bid_ask","frame_hash":"6a3080b86d36ff076ad030f2e8f9c688af959b73bed6a40b470290da12482cdd","frame_index":0,"kind":"data","monotonic_ns":228781612460958,"payload":{"asset_id":"60386828328910021732068595344565885737045900010034836345809386672230885527307","best_ask":"0.89","best_bid":"0.87","event_type":"best_bid_ask","market":"0xeb66215f2e9faa6449e30a02bab5b8ed7b79a38bf961f6b24d0073c9c2419250","spread":"0.02","timestamp":"1785126798396"},"payload_hash":"982709d286bfced6905ea4c043d1414c94492f5f641002617291eabb4aa4b959","raw_frame":"{\"market\":\"0xeb66215f2e9faa6449e30a02bab5b8ed7b79a38bf961f6b24d0073c9c2419250\", \"asset_id\":\"60386828328910021732068595344565885737045900010034836345809386672230885527307\", \"best_bid\":\"0.87\", \"best_ask\":\"0.89\", \"spread\":\"0.02\", \"timestamp\":\"1785126798396\", \"event_type\":\"best_bid_ask\"}","received_at":"2026-07-27T04:33:18.344343Z","schema_version":"clob-market-ws.best_bid_ask.v1","sequence":null,"server_hash":null,"server_timestamp":"1785126798396","session_id":"e9443c7415a0419799bee9cfbb1a9e4d","source":"clob_market_ws"},"received_at":"2026-07-27T04:33:18.344343Z","record_id":"97f010301432c7e4fce7d7fae5b148e87eaa825d9fb8b851a5b7f23cdf255241","schema_fingerprint":"8488399f31b0337811b13b266be932db7062827c2470b78bd8e9e99bab51d17d","schema_version":"edge-lab-recorder.raw.v1","sequence":null,"source":"clob_market_ws"}
{"event_at":"2026-07-27T04:33:18.396000Z","event_fingerprint":"d48f92a11c9e3b02ed085d89c63c70a0dfb23458e9feb225a752137660a90d41","payload":{"connection_id":"0f4979d6978d463e9660b042fdcf555f","event_at":"2026-07-27T04:33:18.396000Z","event_type":"price_change","frame_hash":"fe9ac21c4f88c549c6f931a66cbb2eba2ae0991e145863d3e4265088e98ddb4c","frame_index":0,"kind":"data","monotonic_ns":228781613612791,"payload":{"event_type":"price_change","market":"0xeb66215f2e9faa6449e30a02bab5b8ed7b79a38bf961f6b24d0073c9c2419250","price_changes":[{"asset_id":"69697746896130839564035629862476347944307040470122503199396727085502753297492","best_ask":"0.13","best_bid":"0.11","hash":"98a96c502fe58b514c5f2aa9bf98f3f81a10873d","price":"0.12","side":"BUY","size":"0"},{"asset_id":"60386828328910021732068595344565885737045900010034836345809386672230885527307","best_ask":"0.89","best_bid":"0.87","hash":"e81701e072bdbbed49741793392959d10c2f04e8","price":"0.88","side":"SELL","size":"0"}],"timestamp":"1785126798396"},"payload_hash":"296235679dbf91b42e4015ddf9e3d7edd6c7058a3548a868435a15b742d6d838","raw_frame":"{\"market\":\"0xeb66215f2e9faa6449e30a02bab5b8ed7b79a38bf961f6b24d0073c9c2419250\", \"price_changes\":[{\"asset_id\":\"69697746896130839564035629862476347944307040470122503199396727085502753297492\", \"price\":\"0.12\", \"size\":\"0\", \"side\":\"BUY\", \"hash\":\"98a96c502fe58b514c5f2aa9bf98f3f81a10873d\", \"best_bid\":\"0.11\", \"best_ask\":\"0.13\"}, {\"asset_id\":\"60386828328910021732068595344565885737045900010034836345809386672230885527307\", \"price\":\"0.88\", \"size\":\"0\", \"side\":\"SELL\", \"hash\":\"e81701e072bdbbed49741793392959d10c2f04e8\", \"best_bid\":\"0.87\", \"best_ask\":\"0.89\"}], \"timestamp\":\"1785126798396\", \"event_type\":\"price_change\"}","received_at":"2026-07-27T04:33:18.345495Z","schema_version":"clob-market-ws.price_change.v1","sequence":null,"server_hash":null,"server_timestamp":"1785126798396","session_id":"e9443c7415a0419799bee9cfbb1a9e4d","source":"clob_market_ws"},"received_at":"2026-07-27T04:33:18.345495Z","record_id":"58ddef9a4f80124abf9ae734e4c6d49fcb6c1edc086c90895ed28ae6f0465614","schema_fingerprint":"4aa3821a28b0b7c2400bc59aba4bcc0a76e971dadd19610d3ad38c768e124dc7","schema_version":"edge-lab-recorder.raw.v1","sequence":null,"source":"clob_market_ws"}
{"event_at":"2026-07-27T04:33:18.400000Z","event_fingerprint":"652d87f494991da4609bbd12b80e2d88a5b30ac52310beb16d849c53b95b5225","payload":{"connection_id":"0f4979d6978d463e9660b042fdcf555f","event_at":"2026-07-27T04:33:18.400000Z","event_type":"price_change","frame_hash":"680cfc9090994ed54489f6d4285262797419cc1bd0249c09815f8691f9f498fd","frame_index":0,"kind":"data","monotonic_ns":228781615119625,"payload":{"event_type":"price_change","market":"0xeb66215f2e9faa6449e30a02bab5b8ed7b79a38bf961f6b24d0073c9c2419250","price_changes":[{"asset_id":"69697746896130839564035629862476347944307040470122503199396727085502753297492","best_ask":"0.13","best_bid":"0.11","hash":"ef3baaa397f5b29ad5687bed8398cc2443314c9d","price":"0.14","side":"SELL","size":"168.31"},{"asset_id":"60386828328910021732068595344565885737045900010034836345809386672230885527307","best_ask":"0.89","best_bid":"0.87","hash":"01b8bfd1f78f93b77dddb3ca9edc3ab33d0db2a5","price":"0.86","side":"BUY","size":"168.31"}],"timestamp":"1785126798400"},"payload_hash":"e015ded167738f7217d0a7e7d9fe5fcad630b2ac4cdca3abe92bc3f90cdbf5ab","raw_frame":"{\"market\":\"0xeb66215f2e9faa6449e30a02bab5b8ed7b79a38bf961f6b24d0073c9c2419250\", \"price_changes\":[{\"asset_id\":\"69697746896130839564035629862476347944307040470122503199396727085502753297492\", \"price\":\"0.14\", \"size\":\"168.31\", \"side\":\"SELL\", \"hash\":\"ef3baaa397f5b29ad5687bed8398cc2443314c9d\", \"best_bid\":\"0.11\", \"best_ask\":\"0.13\"}, {\"asset_id\":\"60386828328910021732068595344565885737045900010034836345809386672230885527307\", \"price\":\"0.86\", \"size\":\"168.31\", \"side\":\"BUY\", \"hash\":\"01b8bfd1f78f93b77dddb3ca9edc3ab33d0db2a5\", \"best_bid\":\"0.87\", \"best_ask\":\"0.89\"}], \"timestamp\":\"1785126798400\", \"event_type\":\"price_change\"}","received_at":"2026-07-27T04:33:18.347002Z","schema_version":"clob-market-ws.price_change.v1","sequence":null,"server_hash":null,"server_timestamp":"1785126798400","session_id":"e9443c7415a0419799bee9cfbb1a9e4d","source":"clob_market_ws"},"received_at":"2026-07-27T04:33:18.347002Z","record_id":"9253db7cfc52c48115f2ca9523dae31addaedfa1e831b5ec5dbe0d055133024e","schema_fingerprint":"4aa3821a28b0b7c2400bc59aba4bcc0a76e971dadd19610d3ad38c768e124dc7","schema_version":"edge-lab-recorder.raw.v1","sequence":null,"source":"clob_market_ws"}
{"event_at":"2026-07-27T04:33:18.413000Z","event_fingerprint":"ae07f8ac50b9aa2e6e34a98f0d13a05376eecf80432d0c782298a874730495b2","payload":{"connection_id":"0f4979d6978d463e9660b042fdcf555f","event_at":"2026-07-27T04:33:18.413000Z","event_type":"best_bid_ask","frame_hash":"80df2a0d1fca459ca75d962e00be73da5d59f96f7f32d95c1bbcb740d53eb021","frame_index":0,"kind":"data","monotonic_ns":228781640562083,"payload":{"asset_id":"69697746896130839564035629862476347944307040470122503199396727085502753297492","best_ask":"0.12","best_bid":"0.11","event_type":"best_bid_ask","market":"0xeb66215f2e9faa6449e30a02bab5b8ed7b79a38bf961f6b24d0073c9c2419250","spread":"0.01","timestamp":"1785126798413"},"payload_hash":"97b690935d8f1f88b0a302a3591af9a2675635ece0150c23e184aae8ce1cc908","raw_frame":"{\"market\":\"0xeb66215f2e9faa6449e30a02bab5b8ed7b79a38bf961f6b24d0073c9c2419250\", \"asset_id\":\"69697746896130839564035629862476347944307040470122503199396727085502753297492\", \"best_bid\":\"0.11\", \"best_ask\":\"0.12\", \"spread\":\"0.01\", \"timestamp\":\"1785126798413\", \"event_type\":\"best_bid_ask\"}","received_at":"2026-07-27T04:33:18.372439Z","schema_version":"clob-market-ws.best_bid_ask.v1","sequence":null,"server_hash":null,"server_timestamp":"1785126798413","session_id":"e9443c7415a0419799bee9cfbb1a9e4d","source":"clob_market_ws"},"received_at":"2026-07-27T04:33:18.372439Z","record_id":"c68f9c38c6c502bea9e414d602ef3bd784183eff5f9c4d5fd9e13664327598cb","schema_fingerprint":"8488399f31b0337811b13b266be932db7062827c2470b78bd8e9e99bab51d17d","schema_version":"edge-lab-recorder.raw.v1","sequence":null,"source":"clob_market_ws"}
{"event_at":"2026-07-27T04:33:18.413000Z","event_fingerprint":"9a780f447ae3af11f82d218035ef423e1dce2aacb671a9b3ac5d380a219ee3e0","payload":{"connection_id":"0f4979d6978d463e9660b042fdcf555f","event_at":"2026-07-27T04:33:18.413000Z","event_type":"best_bid_ask","frame_hash":"410cbf242a9b51bcb0fb42d193e675670900afa3fbd7b3c204652b4939d9f67e","frame_index":0,"kind":"data","monotonic_ns":228781644488250,"payload":{"asset_id":"60386828328910021732068595344565885737045900010034836345809386672230885527307","best_ask":"0.89","best_bid":"0.88","event_type":"best_bid_ask","market":"0xeb66215f2e9faa6449e30a02bab5b8ed7b79a38bf961f6b24d0073c9c2419250","spread":"0.01","timestamp":"1785126798413"},"payload_hash":"9f1ead0274f649e5e40470b4475451d4fe8800ee3ed8e757601ba99c7c9d2eff","raw_frame":"{\"market\":\"0xeb66215f2e9faa6449e30a02bab5b8ed7b79a38bf961f6b24d0073c9c2419250\", \"asset_id\":\"60386828328910021732068595344565885737045900010034836345809386672230885527307\", \"best_bid\":\"0.88\", \"best_ask\":\"0.89\", \"spread\":\"0.01\", \"timestamp\":\"1785126798413\", \"event_type\":\"best_bid_ask\"}","received_at":"2026-07-27T04:33:18.376373Z","schema_version":"clob-market-ws.best_bid_ask.v1","sequence":null,"server_hash":null,"server_timestamp":"1785126798413","session_id":"e9443c7415a0419799bee9cfbb1a9e4d","source":"clob_market_ws"},"received_at":"2026-07-27T04:33:18.376373Z","record_id":"a46ae1068c05743e63e32a0c1a4d95b050a19a9ef51612e5d2ff2f956d37d0a9","schema_fingerprint":"8488399f31b0337811b13b266be932db7062827c2470b78bd8e9e99bab51d17d","schema_version":"edge-lab-recorder.raw.v1","sequence":null,"source":"clob_market_ws"}
{"event_at":"2026-07-27T04:33:18.412000Z","event_fingerprint":"a33dfa5ad6c4f1a707a56d2f73f6ff50af21c6a5cf10f576a3e6dbd53aaeca59","payload":{"connection_id":"0f4979d6978d463e9660b042fdcf555f","event_at":"2026-07-27T04:33:18.412000Z","event_type":"price_change","frame_hash":"3ffbaacc610adc8fdb81c91350f7b2c04caa6aff7272d6f2aff81516bab81ab0","frame_index":0,"kind":"data","monotonic_ns":228781645820416,"payload":{"event_type":"price_change","market":"0xeb66215f2e9faa6449e30a02bab5b8ed7b79a38bf961f6b24d0073c9c2419250","price_changes":[{"asset_id":"60386828328910021732068595344565885737045900010034836345809386672230885527307","best_ask":"0.89","best_bid":"0.88","hash":"1743ca93e1d16f4f9ca606e7b994961eaf50c3d7","price":"0.88","side":"BUY","size":"5"},{"asset_id":"69697746896130839564035629862476347944307040470122503199396727085502753297492","best_ask":"0.12","best_bid":"0.11","hash":"a4f829a3b4b82a6249340aeeb0ca15d5f0d8b3a7","price":"0.12","side":"SELL","size":"5"}],"timestamp":"1785126798412"},"payload_hash":"15b22aaf7884ec69f69272ed8ac5d372a48ee1a2f245547f459b2f011ce4d2a2","raw_frame":"{\"market\":\"0xeb66215f2e9faa6449e30a02bab5b8ed7b79a38bf961f6b24d0073c9c2419250\", \"price_changes\":[{\"asset_id\":\"60386828328910021732068595344565885737045900010034836345809386672230885527307\", \"price\":\"0.88\", \"size\":\"5\", \"side\":\"BUY\", \"hash\":\"1743ca93e1d16f4f9ca606e7b994961eaf50c3d7\", \"best_bid\":\"0.88\", \"best_ask\":\"0.89\"}, {\"asset_id\":\"69697746896130839564035629862476347944307040470122503199396727085502753297492\", \"price\":\"0.12\", \"size\":\"5\", \"side\":\"SELL\", \"hash\":\"a4f829a3b4b82a6249340aeeb0ca15d5f0d8b3a7\", \"best_bid\":\"0.11\", \"best_ask\":\"0.12\"}], \"timestamp\":\"1785126798412\", \"event_type\":\"price_change\"}","received_at":"2026-07-27T04:33:18.377708Z","schema_version":"clob-market-ws.price_change.v1","sequence":null,"server_hash":null,"server_timestamp":"1785126798412","session_id":"e9443c7415a0419799bee9cfbb1a9e4d","source":"clob_market_ws"},"received_at":"2026-07-27T04:33:18.377708Z","record_id":"09d51126372b0b4148ce29333a8cd7d446829ef8b78c9990184709361df28d7c","schema_fingerprint":"4aa3821a28b0b7c2400bc59aba4bcc0a76e971dadd19610d3ad38c768e124dc7","schema_version":"edge-lab-recorder.raw.v1","sequence":null,"source":"clob_market_ws"}
{"event_at":"2026-07-27T04:33:18.415000Z","event_fingerprint":"3c5ee1575400e86cbf0363363781079b8e2085ad33050f2e3c06cb9774983ee8","payload":{"connection_id":"0f4979d6978d463e9660b042fdcf555f","event_at":"2026-07-27T04:33:18.415000Z","event_type":"price_change","frame_hash":"579476f11edafe7714493d3cdbfd93225ac677bda462f135b338cb1976bd8882","frame_index":0,"kind":"data","monotonic_ns":228781646950666,"payload":{"event_type":"price_change","market":"0xeb66215f2e9faa6449e30a02bab5b8ed7b79a38bf961f6b24d0073c9c2419250","price_changes":[{"asset_id":"60386828328910021732068595344565885737045900010034836345809386672230885527307","best_ask":"0.89","best_bid":"0.88","hash":"04bdddc6e1cd111a84eb5773b54fc46e88581908","price":"0.88","side":"BUY","size":"10"},{"asset_id":"69697746896130839564035629862476347944307040470122503199396727085502753297492","best_ask":"0.12","best_bid":"0.11","hash":"54bcc7715ea86cf638dd46fc800a291a49af865f","price":"0.12","side":"SELL","size":"10"}],"timestamp":"1785126798415"},"payload_hash":"498eea4badd5a63de8451f8bc7ff1f5d117828a5d814582963b5819eeb0f0618","raw_frame":"{\"market\":\"0xeb66215f2e9faa6449e30a02bab5b8ed7b79a38bf961f6b24d0073c9c2419250\", \"price_changes\":[{\"asset_id\":\"60386828328910021732068595344565885737045900010034836345809386672230885527307\", \"price\":\"0.88\", \"size\":\"10\", \"side\":\"BUY\", \"hash\":\"04bdddc6e1cd111a84eb5773b54fc46e88581908\", \"best_bid\":\"0.88\", \"best_ask\":\"0.89\"}, {\"asset_id\":\"69697746896130839564035629862476347944307040470122503199396727085502753297492\", \"price\":\"0.12\", \"size\":\"10\", \"side\":\"SELL\", \"hash\":\"54bcc7715ea86cf638dd46fc800a291a49af865f\", \"best_bid\":\"0.11\", \"best_ask\":\"0.12\"}], \"timestamp\":\"1785126798415\", \"event_type\":\"price_change\"}","received_at":"2026-07-27T04:33:18.378839Z","schema_version":"clob-market-ws.price_change.v1","sequence":null,"server_hash":null,"server_timestamp":"1785126798415","session_id":"e9443c7415a0419799bee9cfbb1a9e4d","source":"clob_market_ws"},"received_at":"2026-07-27T04:33:18.378839Z","record_id":"30eeee2c5fc9aa9b4ca2687921fff088917b126639061ed74257065642ef6b4e","schema_fingerprint":"4aa3821a28b0b7c2400bc59aba4bcc0a76e971dadd19610d3ad38c768e124dc7","schema_version":"edge-lab-recorder.raw.v1","sequence":null,"source":"clob_market_ws"}
{"event_at":"2026-07-27T04:33:18.417000Z","event_fingerprint":"c7d86995733ced34cd5b30f694ffd35a7f02904fec6a561f7d5eb2b888374a88","payload":{"connection_id":"0f4979d6978d463e9660b042fdcf555f","event_at":"2026-07-27T04:33:18.417000Z","event_type":"price_change","frame_hash":"c99af83362102cd7320b823c0af2a94f43ba79f04ce7bf75a7a22e45a18f82d5","frame_index":0,"kind":"data","monotonic_ns":228781648482583,"payload":{"event_type":"price_change","market":"0xeb66215f2e9faa6449e30a02bab5b8ed7b79a38bf961f6b24d0073c9c2419250","price_changes":[{"asset_id":"69697746896130839564035629862476347944307040470122503199396727085502753297492","best_ask":"0.12","best_bid":"0.11","hash":"fbf87c0cde9d2a18a78e737f3a613d23141c96d6","price":"0.11","side":"BUY","size":"464.6"},{"asset_id":"60386828328910021732068595344565885737045900010034836345809386672230885527307","best_ask":"0.89","best_bid":"0.88","hash":"42a66ade987325ed1295a6fe1fb2d3b38d710040","price":"0.89","side":"SELL","size":"464.6"}],"timestamp":"1785126798417"},"payload_hash":"9c96c3e47d9adc71e60473bd56b8aff68fc923b7062f527f13d42dbb45f5aa6f","raw_frame":"{\"market\":\"0xeb66215f2e9faa6449e30a02bab5b8ed7b79a38bf961f6b24d0073c9c2419250\", \"price_changes\":[{\"asset_id\":\"69697746896130839564035629862476347944307040470122503199396727085502753297492\", \"price\":\"0.11\", \"size\":\"464.6\", \"side\":\"BUY\", \"hash\":\"fbf87c0cde9d2a18a78e737f3a613d23141c96d6\", \"best_bid\":\"0.11\", \"best_ask\":\"0.12\"}, {\"asset_id\":\"60386828328910021732068595344565885737045900010034836345809386672230885527307\", \"price\":\"0.89\", \"size\":\"464.6\", \"side\":\"SELL\", \"hash\":\"42a66ade987325ed1295a6fe1fb2d3b38d710040\", \"best_bid\":\"0.88\", \"best_ask\":\"0.89\"}], \"timestamp\":\"1785126798417\", \"event_type\":\"price_change\"}","received_at":"2026-07-27T04:33:18.380371Z","schema_version":"clob-market-ws.price_change.v1","sequence":null,"server_hash":null,"server_timestamp":"1785126798417","session_id":"e9443c7415a0419799bee9cfbb1a9e4d","source":"clob_market_ws"},"received_at":"2026-07-27T04:33:18.380371Z","record_id":"ae45da137a16d313a268ee5c84683df5860800194b924770579d84054457d801","schema_fingerprint":"4aa3821a28b0b7c2400bc59aba4bcc0a76e971dadd19610d3ad38c768e124dc7","schema_version":"edge-lab-recorder.raw.v1","sequence":null,"source":"clob_market_ws"}
{"event_at":"2026-07-27T04:33:18.419000Z","event_fingerprint":"74da63698a6026fda0e2076c307eb7db4baeeceb2ca30301d6a13b1e849f91de","payload":{"connection_id":"0f4979d6978d463e9660b042fdcf555f","event_at":"2026-07-27T04:33:18.419000Z","event_type":"price_change","frame_hash":"bc250ba08c6a8fce2b47c194ad3f652001066150d46a3bf9c055b72498c8d895","frame_index":0,"kind":"data","monotonic_ns":228781649139458,"payload":{"event_type":"price_change","market":"0xeb66215f2e9faa6449e30a02bab5b8ed7b79a38bf961f6b24d0073c9c2419250","price_changes":[{"asset_id":"60386828328910021732068595344565885737045900010034836345809386672230885527307","best_ask":"0.89","best_bid":"0.88","hash":"48f8a4809f066415404d1c14dff2b531a3c1b913","price":"0.02","side":"BUY","size":"738.1"},{"asset_id":"69697746896130839564035629862476347944307040470122503199396727085502753297492","best_ask":"0.12","best_bid":"0.11","hash":"9ef6e128cd92ceb7a2ae18f5671ef09426275d00","price":"0.98","side":"SELL","size":"738.1"}],"timestamp":"1785126798419"},"payload_hash":"36e7998b1af8801993d67ff20545ebc91fce6079f147f2a6ef4605b498f62383","raw_frame":"{\"market\":\"0xeb66215f2e9faa6449e30a02bab5b8ed7b79a38bf961f6b24d0073c9c2419250\", \"price_changes\":[{\"asset_id\":\"60386828328910021732068595344565885737045900010034836345809386672230885527307\", \"price\":\"0.02\", \"size\":\"738.1\", \"side\":\"BUY\", \"hash\":\"48f8a4809f066415404d1c14dff2b531a3c1b913\", \"best_bid\":\"0.88\", \"best_ask\":\"0.89\"}, {\"asset_id\":\"69697746896130839564035629862476347944307040470122503199396727085502753297492\", \"price\":\"0.98\", \"size\":\"738.1\", \"side\":\"SELL\", \"hash\":\"9ef6e128cd92ceb7a2ae18f5671ef09426275d00\", \"best_bid\":\"0.11\", \"best_ask\":\"0.12\"}], \"timestamp\":\"1785126798419\", \"event_type\":\"price_change\"}","received_at":"2026-07-27T04:33:18.381028Z","schema_version":"clob-market-ws.price_change.v1","sequence":null,"server_hash":null,"server_timestamp":"1785126798419","session_id":"e9443c7415a0419799bee9cfbb1a9e4d","source":"clob_market_ws"},"received_at":"2026-07-27T04:33:18.381028Z","record_id":"3ab9bace283807d6ad721aaf4c0416550c8fe14c487c8368020c6f9452244278","schema_fingerprint":"4aa3821a28b0b7c2400bc59aba4bcc0a76e971dadd19610d3ad38c768e124dc7","schema_version":"edge-lab-recorder.raw.v1","sequence":null,"source":"clob_market_ws"}
{"event_at":"2026-07-27T04:33:18.420000Z","event_fingerprint":"6c7f42e15c80ee266208528a876ff0da3e8781d4192aca15b95287976ec84418","payload":{"connection_id":"0f4979d6978d463e9660b042fdcf555f","event_at":"2026-07-27T04:33:18.420000Z","event_type":"price_change","frame_hash":"de8836cccb090e16c15700be956a79a9e829fab8fa4a84ef36982164049eaba7","frame_index":0,"kind":"data","monotonic_ns":228781649713458,"payload":{"event_type":"price_change","market":"0xeb66215f2e9faa6449e30a02bab5b8ed7b79a38bf961f6b24d0073c9c2419250","price_changes":[{"asset_id":"60386828328910021732068595344565885737045900010034836345809386672230885527307","best_ask":"0.89","best_bid":"0.88","hash":"909e1caca0e104764a37b02c46a6f02d0843b311","price":"0.88","side":"BUY","size":"15.17"},{"asset_id":"69697746896130839564035629862476347944307040470122503199396727085502753297492","best_ask":"0.12","best_bid":"0.11","hash":"30bbd0c5dd0ac09c44355e076c61b5fca66a2720","price":"0.12","side":"SELL","size":"15.17"}],"timestamp":"1785126798420"},"payload_hash":"874d9e6e161bfe61b0441000e3179a50d94f7e05e284031b3fdff398a01fcbb7","raw_frame":"{\"market\":\"0xeb66215f2e9faa6449e30a02bab5b8ed7b79a38bf961f6b24d0073c9c2419250\", \"price_changes\":[{\"asset_id\":\"60386828328910021732068595344565885737045900010034836345809386672230885527307\", \"price\":\"0.88\", \"size\":\"15.17\", \"side\":\"BUY\", \"hash\":\"909e1caca0e104764a37b02c46a6f02d0843b311\", \"best_bid\":\"0.88\", \"best_ask\":\"0.89\"}, {\"asset_id\":\"69697746896130839564035629862476347944307040470122503199396727085502753297492\", \"price\":\"0.12\", \"size\":\"15.17\", \"side\":\"SELL\", \"hash\":\"30bbd0c5dd0ac09c44355e076c61b5fca66a2720\", \"best_bid\":\"0.11\", \"best_ask\":\"0.12\"}], \"timestamp\":\"1785126798420\", \"event_type\":\"price_change\"}","received_at":"2026-07-27T04:33:18.381602Z","schema_version":"clob-market-ws.price_change.v1","sequence":null,"server_hash":null,"server_timestamp":"1785126798420","session_id":"e9443c7415a0419799bee9cfbb1a9e4d","source":"clob_market_ws"},"received_at":"2026-07-27T04:33:18.381602Z","record_id":"a0289fe2ddcbefc480f7cfc93380132d65ab822a4cee721795a1e134e773e1a6","schema_fingerprint":"4aa3821a28b0b7c2400bc59aba4bcc0a76e971dadd19610d3ad38c768e124dc7","schema_version":"edge-lab-recorder.raw.v1","sequence":null,"source":"clob_market_ws"}
{"event_at":"2026-07-27T04:33:18.421000Z","event_fingerprint":"dbc4bdcdb12400d93f69c9b5252764cdb7c8f01c3c0d8ab25a951c9aa1860c19","payload":{"connection_id":"0f4979d6978d463e9660b042fdcf555f","event_at":"2026-07-27T04:33:18.421000Z","event_type":"price_change","frame_hash":"c2954f62e4942fdf9264def54cd4314a17bdc0d3289e688a67c7401a728c72e6","frame_index":0,"kind":"data","monotonic_ns":228781650350166,"payload":{"event_type":"price_change","market":"0xeb66215f2e9faa6449e30a02bab5b8ed7b79a38bf961f6b24d0073c9c2419250","price_changes":[{"asset_id":"60386828328910021732068595344565885737045900010034836345809386672230885527307","best_ask":"0.89","best_bid":"0.88","hash":"3c44b0fccfd34c34bff249c29dc889cf19988e40","price":"0.88","side":"BUY","size":"20.34"},{"asset_id":"69697746896130839564035629862476347944307040470122503199396727085502753297492","best_ask":"0.12","best_bid":"0.11","hash":"aa3cc40d28b4f69ae2495c6621e50fe040e17fb0","price":"0.12","side":"SELL","size":"20.34"}],"timestamp":"1785126798421"},"payload_hash":"a091c781cc042a05e356c25149699bf0ba58a92fd6330359ac1df84e977b2fab","raw_frame":"{\"market\":\"0xeb66215f2e9faa6449e30a02bab5b8ed7b79a38bf961f6b24d0073c9c2419250\", \"price_changes\":[{\"asset_id\":\"60386828328910021732068595344565885737045900010034836345809386672230885527307\", \"price\":\"0.88\", \"size\":\"20.34\", \"side\":\"BUY\", \"hash\":\"3c44b0fccfd34c34bff249c29dc889cf19988e40\", \"best_bid\":\"0.88\", \"best_ask\":\"0.89\"}, {\"asset_id\":\"69697746896130839564035629862476347944307040470122503199396727085502753297492\", \"price\":\"0.12\", \"size\":\"20.34\", \"side\":\"SELL\", \"hash\":\"aa3cc40d28b4f69ae2495c6621e50fe040e17fb0\", \"best_bid\":\"0.11\", \"best_ask\":\"0.12\"}], \"timestamp\":\"1785126798421\", \"event_type\":\"price_change\"}","received_at":"2026-07-27T04:33:18.382239Z","schema_version":"clob-market-ws.price_change.v1","sequence":null,"server_hash":null,"server_timestamp":"1785126798421","session_id":"e9443c7415a0419799bee9cfbb1a9e4d","source":"clob_market_ws"},"received_at":"2026-07-27T04:33:18.382239Z","record_id":"4929decd13cab2e6ab9fc1e78722822627c822e079b24e532c5fa50e641f2783","schema_fingerprint":"4aa3821a28b0b7c2400bc59aba4bcc0a76e971dadd19610d3ad38c768e124dc7","schema_version":"edge-lab-recorder.raw.v1","sequence":null,"source":"clob_market_ws"}
{"event_at":"2026-07-27T04:33:18.422000Z","event_fingerprint":"55e13a117229df59374732aee7836ff7e3a9c67472f912a2da08c11ced426008","payload":{"connection_id":"0f4979d6978d463e9660b042fdcf555f","event_at":"2026-07-27T04:33:18.422000Z","event_type":"price_change","frame_hash":"a9e0acaa451ac5b82a8375d6e44d14195acbabc91fb42981174fa85243387928","frame_index":0,"kind":"data","monotonic_ns":228781650908708,"payload":{"event_type":"price_change","market":"0xeb66215f2e9faa6449e30a02bab5b8ed7b79a38bf961f6b24d0073c9c2419250","price_changes":[{"asset_id":"60386828328910021732068595344565885737045900010034836345809386672230885527307","best_ask":"0.89","best_bid":"0.88","hash":"e6dd352b1f552e37934fff43d356ca49a2f5a610","price":"0.88","side":"BUY","size":"25.34"},{"asset_id":"69697746896130839564035629862476347944307040470122503199396727085502753297492","best_ask":"0.12","best_bid":"0.11","hash":"474786903a3211ad13adea51c49fcf3c8b466160","price":"0.12","side":"SELL","size":"25.34"}],"timestamp":"1785126798422"},"payload_hash":"a108615c85a8e3db232d5b4e434939ea234986460bbc8815dad5f882d61e5102","raw_frame":"{\"market\":\"0xeb66215f2e9faa6449e30a02bab5b8ed7b79a38bf961f6b24d0073c9c2419250\", \"price_changes\":[{\"asset_id\":\"60386828328910021732068595344565885737045900010034836345809386672230885527307\", \"price\":\"0.88\", \"size\":\"25.34\", \"side\":\"BUY\", \"hash\":\"e6dd352b1f552e37934fff43d356ca49a2f5a610\", \"best_bid\":\"0.88\", \"best_ask\":\"0.89\"}, {\"asset_id\":\"69697746896130839564035629862476347944307040470122503199396727085502753297492\", \"price\":\"0.12\", \"size\":\"25.34\", \"side\":\"SELL\", \"hash\":\"474786903a3211ad13adea51c49fcf3c8b466160\", \"best_bid\":\"0.11\", \"best_ask\":\"0.12\"}], \"timestamp\":\"1785126798422\", \"event_type\":\"price_change\"}","received_at":"2026-07-27T04:33:18.382798Z","schema_version":"clob-market-ws.price_change.v1","sequence":null,"server_hash":null,"server_timestamp":"1785126798422","session_id":"e9443c7415a0419799bee9cfbb1a9e4d","source":"clob_market_ws"},"received_at":"2026-07-27T04:33:18.382798Z","record_id":"16e6219f4b89d985b152715555f175356dbfe3ab04d8d5582a4531ba583c90fa","schema_fingerprint":"4aa3821a28b0b7c2400bc59aba4bcc0a76e971dadd19610d3ad38c768e124dc7","schema_version":"edge-lab-recorder.raw.v1","sequence":null,"source":"clob_market_ws"}
{"event_at":"2026-07-27T04:33:18.422000Z","event_fingerprint":"6157b64ec11fe15c6198e30a0cfec1441bd2e286a03814d27a606016cdcb3d94","payload":{"connection_id":"0f4979d6978d463e9660b042fdcf555f","event_at":"2026-07-27T04:33:18.422000Z","event_type":"price_change","frame_hash":"897cb835772d6f5bb5b5a5c6419c56590f4eda0be91541fa10840242baa66898","frame_index":0,"kind":"data","monotonic_ns":228781651467541,"payload":{"event_type":"price_change","market":"0xeb66215f2e9faa6449e30a02bab5b8ed7b79a38bf961f6b24d0073c9c2419250","price_changes":[{"asset_id":"69697746896130839564035629862476347944307040470122503199396727085502753297492","best_ask":"0.12","best_bid":"0.11","hash":"513047024ec419f51eeb904c58e6925ad075f995","price":"0.11","side":"BUY","size":"481.4"},{"asset_id":"60386828328910021732068595344565885737045900010034836345809386672230885527307","best_ask":"0.89","best_bid":"0.88","hash":"cc06eb44b67f7755fa1b0c34296759622bfc5d99","price":"0.89","side":"SELL","size":"481.4"}],"timestamp":"1785126798422"},"payload_hash":"fb11d8f7af647a2e1a7e9bd86ee232b773a4ffe3a56250c9dbfd6b5808b67bf5","raw_frame":"{\"market\":\"0xeb66215f2e9faa6449e30a02bab5b8ed7b79a38bf961f6b24d0073c9c2419250\", \"price_changes\":[{\"asset_id\":\"69697746896130839564035629862476347944307040470122503199396727085502753297492\", \"price\":\"0.11\", \"size\":\"481.4\", \"side\":\"BUY\", \"hash\":\"513047024ec419f51eeb904c58e6925ad075f995\", \"best_bid\":\"0.11\", \"best_ask\":\"0.12\"}, {\"asset_id\":\"60386828328910021732068595344565885737045900010034836345809386672230885527307\", \"price\":\"0.89\", \"size\":\"481.4\", \"side\":\"SELL\", \"hash\":\"cc06eb44b67f7755fa1b0c34296759622bfc5d99\", \"best_bid\":\"0.88\", \"best_ask\":\"0.89\"}], \"timestamp\":\"1785126798422\", \"event_type\":\"price_change\"}","received_at":"2026-07-27T04:33:18.383355Z","schema_version":"clob-market-ws.price_change.v1","sequence":null,"server_hash":null,"server_timestamp":"1785126798422","session_id":"e9443c7415a0419799bee9cfbb1a9e4d","source":"clob_market_ws"},"received_at":"2026-07-27T04:33:18.383355Z","record_id":"d9a90b9fb7eef285661c971c52b2a9f953fec3c34e38ec92827a871220a1c7f9","schema_fingerprint":"4aa3821a28b0b7c2400bc59aba4bcc0a76e971dadd19610d3ad38c768e124dc7","schema_version":"edge-lab-recorder.raw.v1","sequence":null,"source":"clob_market_ws"}
{"event_at":"2026-07-27T04:33:18.428000Z","event_fingerprint":"c9e36cdfdf264edacc6906aa5f6713d4e35429ee5583cff3de8635e476b50408","payload":{"connection_id":"0f4979d6978d463e9660b042fdcf555f","event_at":"2026-07-27T04:33:18.428000Z","event_type":"price_change","frame_hash":"dc80343af9919d94aa0c4e5df20144a072a8ae5c11a1532a23bcfe141624fc99","frame_index":0,"kind":"data","monotonic_ns":228781652034083,"payload":{"event_type":"price_change","market":"0xeb66215f2e9faa6449e30a02bab5b8ed7b79a38bf961f6b24d0073c9c2419250","price_changes":[{"asset_id":"69697746896130839564035629862476347944307040470122503199396727085502753297492","best_ask":"0.12","best_bid":"0.11","hash":"6d345864bcf00d5175baddc99694abe56b642533","price":"0.1","side":"BUY","size":"141"},{"asset_id":"60386828328910021732068595344565885737045900010034836345809386672230885527307","best_ask":"0.89","best_bid":"0.88","hash":"257a0ea323ddda4cf3b1929ca6393962a30ebeba","price":"0.9","side":"SELL","size":"141"}],"timestamp":"1785126798428"},"payload_hash":"62afcc62bd633e64df33d5054ef4ceda6020aaa5c71b9b809d2db9f5bbbca88d","raw_frame":"{\"market\":\"0xeb66215f2e9faa6449e30a02bab5b8ed7b79a38bf961f6b24d0073c9c2419250\", \"price_changes\":[{\"asset_id\":\"69697746896130839564035629862476347944307040470122503199396727085502753297492\", \"price\":\"0.1\", \"size\":\"141\", \"side\":\"BUY\", \"hash\":\"6d345864bcf00d5175baddc99694abe56b642533\", \"best_bid\":\"0.11\", \"best_ask\":\"0.12\"}, {\"asset_id\":\"60386828328910021732068595344565885737045900010034836345809386672230885527307\", \"price\":\"0.9\", \"size\":\"141\", \"side\":\"SELL\", \"hash\":\"257a0ea323ddda4cf3b1929ca6393962a30ebeba\", \"best_bid\":\"0.88\", \"best_ask\":\"0.89\"}], \"timestamp\":\"1785126798428\", \"event_type\":\"price_change\"}","received_at":"2026-07-27T04:33:18.383923Z","schema_version":"clob-market-ws.price_change.v1","sequence":null,"server_hash":null,"server_timestamp":"1785126798428","session_id":"e9443c7415a0419799bee9cfbb1a9e4d","source":"clob_market_ws"},"received_at":"2026-07-27T04:33:18.383923Z","record_id":"ab997ff98b25eb290238638f2ba84cf05edb6cdef3a34b67196d20285d737423","schema_fingerprint":"4aa3821a28b0b7c2400bc59aba4bcc0a76e971dadd19610d3ad38c768e124dc7","schema_version":"edge-lab-recorder.raw.v1","sequence":null,"source":"clob_market_ws"}
{"event_at":"2026-07-27T04:33:18.437000Z","event_fingerprint":"5639b1ba064bc22d60fa68733dd9eb0cf7d76e56ad67c4c5fcf88ebbbd748adc","payload":{"connection_id":"0f4979d6978d463e9660b042fdcf555f","event_at":"2026-07-27T04:33:18.437000Z","event_type":"price_change","frame_hash":"47647d036bb1de05aefe630596d62ed2518d22864dc39fd80a03801b86c1a43e","frame_index":0,"kind":"data","monotonic_ns":228781652654958,"payload":{"event_type":"price_change","market":"0xeb66215f2e9faa6449e30a02bab5b8ed7b79a38bf961f6b24d0073c9c2419250","price_changes":[{"asset_id":"69697746896130839564035629862476347944307040470122503199396727085502753297492","best_ask":"0.12","best_bid":"0.11","hash":"728e74a949b8c0ad3cdb5e136304deb82a1e3e19","price":"0.07","side":"BUY","size":"816.14"},{"asset_id":"60386828328910021732068595344565885737045900010034836345809386672230885527307","best_ask":"0.89","best_bid":"0.88","hash":"33111fb7c8ec1020d38130e3bc60050b9ee42ebf","price":"0.93","side":"SELL","size":"816.14"}],"timestamp":"1785126798437"},"payload_hash":"65bc806befbe8ccb93cb05a517ac274e4ae61b95eb09abc42e720d6315a9e5e0","raw_frame":"{\"market\":\"0xeb66215f2e9faa6449e30a02bab5b8ed7b79a38bf961f6b24d0073c9c2419250\", \"price_changes\":[{\"asset_id\":\"69697746896130839564035629862476347944307040470122503199396727085502753297492\", \"price\":\"0.07\", \"size\":\"816.14\", \"side\":\"BUY\", \"hash\":\"728e74a949b8c0ad3cdb5e136304deb82a1e3e19\", \"best_bid\":\"0.11\", \"best_ask\":\"0.12\"}, {\"asset_id\":\"60386828328910021732068595344565885737045900010034836345809386672230885527307\", \"price\":\"0.93\", \"size\":\"816.14\", \"side\":\"SELL\", \"hash\":\"33111fb7c8ec1020d38130e3bc60050b9ee42ebf\", \"best_bid\":\"0.88\", \"best_ask\":\"0.89\"}], \"timestamp\":\"1785126798437\", \"event_type\":\"price_change\"}","received_at":"2026-07-27T04:33:18.384544Z","schema_version":"clob-market-ws.price_change.v1","sequence":null,"server_hash":null,"server_timestamp":"1785126798437","session_id":"e9443c7415a0419799bee9cfbb1a9e4d","source":"clob_market_ws"},"received_at":"2026-07-27T04:33:18.384544Z","record_id":"6c166eb9fc06ecb47b144f38f3bead4f7fc5e6bda23a437c15764eaa476d5e0d","schema_fingerprint":"4aa3821a28b0b7c2400bc59aba4bcc0a76e971dadd19610d3ad38c768e124dc7","schema_version":"edge-lab-recorder.raw.v1","sequence":null,"source":"clob_market_ws"}
{"event_at":"2026-07-27T04:33:18.439000Z","event_fingerprint":"151020ada07d8139c1f4fdb3195a994693bbf73e76f32d4b595e2af9f44d2216","payload":{"connection_id":"0f4979d6978d463e9660b042fdcf555f","event_at":"2026-07-27T04:33:18.439000Z","event_type":"price_change","frame_hash":"bde0b845ba9ff241b69a7610bbb8f3ec85114e25b1013b58fb42e44fbdfb6122","frame_index":0,"kind":"data","monotonic_ns":228781653200708,"payload":{"event_type":"price_change","market":"0xeb66215f2e9faa6449e30a02bab5b8ed7b79a38bf961f6b24d0073c9c2419250","price_changes":[{"asset_id":"60386828328910021732068595344565885737045900010034836345809386672230885527307","best_ask":"0.89","best_bid":"0.88","hash":"7c7cb26f78cc176a5eadbaf9afe396436b573dcc","price":"0.82","side":"BUY","size":"234"},{"asset_id":"69697746896130839564035629862476347944307040470122503199396727085502753297492","best_ask":"0.12","best_bid":"0.11","hash":"6974930bc1e161ecc086312042cacd9a6bf29225","price":"0.18","side":"SELL","size":"234"}],"timestamp":"1785126798439"},"payload_hash":"f221f2b5864f9a1e25c8395251360ddb72f895e1bc205ae062317d47c727b1d6","raw_frame":"{\"market\":\"0xeb66215f2e9faa6449e30a02bab5b8ed7b79a38bf961f6b24d0073c9c2419250\", \"price_changes\":[{\"asset_id\":\"60386828328910021732068595344565885737045900010034836345809386672230885527307\", \"price\":\"0.82\", \"size\":\"234\", \"side\":\"BUY\", \"hash\":\"7c7cb26f78cc176a5eadbaf9afe396436b573dcc\", \"best_bid\":\"0.88\", \"best_ask\":\"0.89\"}, {\"asset_id\":\"69697746896130839564035629862476347944307040470122503199396727085502753297492\", \"price\":\"0.18\", \"size\":\"234\", \"side\":\"SELL\", \"hash\":\"6974930bc1e161ecc086312042cacd9a6bf29225\", \"best_bid\":\"0.11\", \"best_ask\":\"0.12\"}], \"timestamp\":\"1785126798439\", \"event_type\":\"price_change\"}","received_at":"2026-07-27T04:33:18.385090Z","schema_version":"clob-market-ws.price_change.v1","sequence":null,"server_hash":null,"server_timestamp":"1785126798439","session_id":"e9443c7415a0419799bee9cfbb1a9e4d","source":"clob_market_ws"},"received_at":"2026-07-27T04:33:18.385090Z","record_id":"ccd7372875381357f30a0416d43b76e3533731b2bf26865437a67fe326d8ecc6","schema_fingerprint":"4aa3821a28b0b7c2400bc59aba4bcc0a76e971dadd19610d3ad38c768e124dc7","schema_version":"edge-lab-recorder.raw.v1","sequence":null,"source":"clob_market_ws"}
{"event_at":"2026-07-27T04:33:18.442000Z","event_fingerprint":"6e5c52751005b0982aefe0de7e6ffcfa56fd41e9fed1aacf1db63f323398a3f0","payload":{"connection_id":"0f4979d6978d463e9660b042fdcf555f","event_at":"2026-07-27T04:33:18.442000Z","event_type":"price_change","frame_hash":"446d6139dfe95fec111d3e681845dbc89c0e8b1e23ed9d44b074bd98cf7a7173","frame_index":0,"kind":"data","monotonic_ns":228781658661750,"payload":{"event_type":"price_change","market":"0xeb66215f2e9faa6449e30a02bab5b8ed7b79a38bf961f6b24d0073c9c2419250","price_changes":[{"asset_id":"60386828328910021732068595344565885737045900010034836345809386672230885527307","best_ask":"0.89","best_bid":"0.88","hash":"d2bd0affbc35bd488be9c56e4756bac5f4286c0f","price":"0.82","side":"BUY","size":"224.4"},{"asset_id":"69697746896130839564035629862476347944307040470122503199396727085502753297492","best_ask":"0.12","best_bid":"0.11","hash":"dfc06efb8b653fe8e25526b2f4dde8b773e5499c","price":"0.18","side":"SELL","size":"224.4"}],"timestamp":"1785126798442"},"payload_hash":"1805f2ce0c630176f428bf7c0a02bd21de024cc707eb9cb62676b8a8ff114646","raw_frame":"{\"market\":\"0xeb66215f2e9faa6449e30a02bab5b8ed7b79a38bf961f6b24d0073c9c2419250\", \"price_changes\":[{\"asset_id\":\"60386828328910021732068595344565885737045900010034836345809386672230885527307\", \"price\":\"0.82\", \"size\":\"224.4\", \"side\":\"BUY\", \"hash\":\"d2bd0affbc35bd488be9c56e4756bac5f4286c0f\", \"best_bid\":\"0.88\", \"best_ask\":\"0.89\"}, {\"asset_id\":\"69697746896130839564035629862476347944307040470122503199396727085502753297492\", \"price\":\"0.18\", \"size\":\"224.4\", \"side\":\"SELL\", \"hash\":\"dfc06efb8b653fe8e25526b2f4dde8b773e5499c\", \"best_bid\":\"0.11\", \"best_ask\":\"0.12\"}], \"timestamp\":\"1785126798442\", \"event_type\":\"price_change\"}","received_at":"2026-07-27T04:33:18.390548Z","schema_version":"clob-market-ws.price_change.v1","sequence":null,"server_hash":null,"server_timestamp":"1785126798442","session_id":"e9443c7415a0419799bee9cfbb1a9e4d","source":"clob_market_ws"},"received_at":"2026-07-27T04:33:18.390548Z","record_id":"008c95c5c3b9d6704a4fb5599447a866aad82f76820c87ed4370d3605fae829b","schema_fingerprint":"4aa3821a28b0b7c2400bc59aba4bcc0a76e971dadd19610d3ad38c768e124dc7","schema_version":"edge-lab-recorder.raw.v1","sequence":null,"source":"clob_market_ws"}
{"event_at":"2026-07-27T04:33:18.443000Z","event_fingerprint":"2bd9741fb03392299684e09ce0c68d7f408cc40e436ba631ea6f703c3d1ea2d7","payload":{"connection_id":"0f4979d6978d463e9660b042fdcf555f","event_at":"2026-07-27T04:33:18.443000Z","event_type":"price_change","frame_hash":"37af78ce09a8182090fe3cbcc49c724ae8a24f56b75f58002a2d6a328dec4834","frame_index":0,"kind":"data","monotonic_ns":228781659261458,"payload":{"event_type":"price_change","market":"0xeb66215f2e9faa6449e30a02bab5b8ed7b79a38bf961f6b24d0073c9c2419250","price_changes":[{"asset_id":"60386828328910021732068595344565885737045900010034836345809386672230885527307","best_ask":"0.89","best_bid":"0.88","hash":"565f92d7bd0ba3ed115af4b7095d3821c4ba8621","price":"0.88","side":"BUY","size":"20.34"},{"asset_id":"69697746896130839564035629862476347944307040470122503199396727085502753297492","best_ask":"0.12","best_bid":"0.11","hash":"9716fe8d83b883a362d51a502c8813b818d664cd","price":"0.12","side":"SELL","size":"20.34"}],"timestamp":"1785126798443"},"payload_hash":"3c3439f46ed63341d56432f59c76b859c9d02e1f753fd432f9b6c7b86f400c12","raw_frame":"{\"market\":\"0xeb66215f2e9faa6449e30a02bab5b8ed7b79a38bf961f6b24d0073c9c2419250\", \"price_changes\":[{\"asset_id\":\"60386828328910021732068595344565885737045900010034836345809386672230885527307\", \"price\":\"0.88\", \"size\":\"20.34\", \"side\":\"BUY\", \"hash\":\"565f92d7bd0ba3ed115af4b7095d3821c4ba8621\", \"best_bid\":\"0.88\", \"best_ask\":\"0.89\"}, {\"asset_id\":\"69697746896130839564035629862476347944307040470122503199396727085502753297492\", \"price\":\"0.12\", \"size\":\"20.34\", \"side\":\"SELL\", \"hash\":\"9716fe8d83b883a362d51a502c8813b818d664cd\", \"best_bid\":\"0.11\", \"best_ask\":\"0.12\"}], \"timestamp\":\"1785126798443\", \"event_type\":\"price_change\"}","received_at":"2026-07-27T04:33:18.391149Z","schema_version":"clob-market-ws.price_change.v1","sequence":null,"server_hash":null,"server_timestamp":"1785126798443","session_id":"e9443c7415a0419799bee9cfbb1a9e4d","source":"clob_market_ws"},"received_at":"2026-07-27T04:33:18.391149Z","record_id":"7de89883db543179ab5356831db2c9fd7658d4e3f46d7d9d8c31e47c1ce987cb","schema_fingerprint":"4aa3821a28b0b7c2400bc59aba4bcc0a76e971dadd19610d3ad38c768e124dc7","schema_version":"edge-lab-recorder.raw.v1","sequence":null,"source":"clob_market_ws"}
{"event_at":"2026-07-27T04:33:18.448000Z","event_fingerprint":"008c9a9b7c3d8927082abea4dc7dbc0155284fdca7ceda757adf57f5b54e87e4","payload":{"connection_id":"0f4979d6978d463e9660b042fdcf555f","event_at":"2026-07-27T04:33:18.448000Z","event_type":"price_change","frame_hash":"0782c41520f3fac0abf198eb5df52c9f5e7814029ae532f9b1b2980fd33ddcf2","frame_index":0,"kind":"data","monotonic_ns":228781667119958,"payload":{"event_type":"price_change","market":"0xeb66215f2e9faa6449e30a02bab5b8ed7b79a38bf961f6b24d0073c9c2419250","price_changes":[{"asset_id":"60386828328910021732068595344565885737045900010034836345809386672230885527307","best_ask":"0.89","best_bid":"0.88","hash":"7fb9fce11767db8194a36106177cd72b82fbac25","price":"0.88","side":"BUY","size":"15.34"},{"asset_id":"69697746896130839564035629862476347944307040470122503199396727085502753297492","best_ask":"0.12","best_bid":"0.11","hash":"7059c6755288673b2963e266d3af5a874ba92a88","price":"0.12","side":"SELL","size":"15.34"}],"timestamp":"1785126798448"},"payload_hash":"0f029472c5d79d260cd0f069171ddf1b7498df8d6105eda0522ef0c5579b15c5","raw_frame":"{\"market\":\"0xeb66215f2e9faa6449e30a02bab5b8ed7b79a38bf961f6b24d0073c9c2419250\", \"price_changes\":[{\"asset_id\":\"60386828328910021732068595344565885737045900010034836345809386672230885527307\", \"price\":\"0.88\", \"size\":\"15.34\", \"side\":\"BUY\", \"hash\":\"7fb9fce11767db8194a36106177cd72b82fbac25\", \"best_bid\":\"0.88\", \"best_ask\":\"0.89\"}, {\"asset_id\":\"69697746896130839564035629862476347944307040470122503199396727085502753297492\", \"price\":\"0.12\", \"size\":\"15.34\", \"side\":\"SELL\", \"hash\":\"7059c6755288673b2963e266d3af5a874ba92a88\", \"best_bid\":\"0.11\", \"best_ask\":\"0.12\"}], \"timestamp\":\"1785126798448\", \"event_type\":\"price_change\"}","received_at":"2026-07-27T04:33:18.399001Z","schema_version":"clob-market-ws.price_change.v1","sequence":null,"server_hash":null,"server_timestamp":"1785126798448","session_id":"e9443c7415a0419799bee9cfbb1a9e4d","source":"clob_market_ws"},"received_at":"2026-07-27T04:33:18.399001Z","record_id":"54990d8bf050792416517bd7ad79312296e26e6261aec5b26f385e99a5a048d4","schema_fingerprint":"4aa3821a28b0b7c2400bc59aba4bcc0a76e971dadd19610d3ad38c768e124dc7","schema_version":"edge-lab-recorder.raw.v1","sequence":null,"source":"clob_market_ws"}
{"event_at":"2026-07-27T04:33:18.448000Z","event_fingerprint":"6971b91a1bd4eda702c5c322a90b4dda9117d150ce023cc1176adc49d4879ee9","payload":{"connection_id":"0f4979d6978d463e9660b042fdcf555f","event_at":"2026-07-27T04:33:18.448000Z","event_type":"price_change","frame_hash":"578498d6d81cb0fd7e8aeb74233250ba1214a316426e1e050348b476629ba3ae","frame_index":0,"kind":"data","monotonic_ns":228781668784083,"payload":{"event_type":"price_change","market":"0xeb66215f2e9faa6449e30a02bab5b8ed7b79a38bf961f6b24d0073c9c2419250","price_changes":[{"asset_id":"60386828328910021732068595344565885737045900010034836345809386672230885527307","best_ask":"0.89","best_bid":"0.88","hash":"e188aa81841ee944b0e1c78abb2c43d3bb7a2f29","price":"0.86","side":"BUY","size":"163.14"},{"asset_id":"69697746896130839564035629862476347944307040470122503199396727085502753297492","best_ask":"0.12","best_bid":"0.11","hash":"bead99fe89d6c81931569660edf9bcedee6144e9","price":"0.14","side":"SELL","size":"163.14"}],"timestamp":"1785126798448"},"payload_hash":"0cae40d9c28a55bbabed1842ab7fbac8ae0d0dd99f82969d51e96a2369a97ee4","raw_frame":"{\"market\":\"0xeb66215f2e9faa6449e30a02bab5b8ed7b79a38bf961f6b24d0073c9c2419250\", \"price_changes\":[{\"asset_id\":\"60386828328910021732068595344565885737045900010034836345809386672230885527307\", \"price\":\"0.86\", \"size\":\"163.14\", \"side\":\"BUY\", \"hash\":\"e188aa81841ee944b0e1c78abb2c43d3bb7a2f29\", \"best_bid\":\"0.88\", \"best_ask\":\"0.89\"}, {\"asset_id\":\"69697746896130839564035629862476347944307040470122503199396727085502753297492\", \"price\":\"0.14\", \"size\":\"163.14\", \"side\":\"SELL\", \"hash\":\"bead99fe89d6c81931569660edf9bcedee6144e9\", \"best_bid\":\"0.11\", \"best_ask\":\"0.12\"}], \"timestamp\":\"1785126798448\", \"event_type\":\"price_change\"}","received_at":"2026-07-27T04:33:18.400667Z","schema_version":"clob-market-ws.price_change.v1","sequence":null,"server_hash":null,"server_timestamp":"1785126798448","session_id":"e9443c7415a0419799bee9cfbb1a9e4d","source":"clob_market_ws"},"received_at":"2026-07-27T04:33:18.400667Z","record_id":"d84d629429fff5c934e4535dca1e13c7097be0efd0769a25587c62836eb29312","schema_fingerprint":"4aa3821a28b0b7c2400bc59aba4bcc0a76e971dadd19610d3ad38c768e124dc7","schema_version":"edge-lab-recorder.raw.v1","sequence":null,"source":"clob_market_ws"}
{"event_at":"2026-07-27T04:33:18.450000Z","event_fingerprint":"f50a6117ec397426b40d3746b7144bfb451b5573ed74cd83830703e1692640c3","payload":{"connection_id":"0f4979d6978d463e9660b042fdcf555f","event_at":"2026-07-27T04:33:18.450000Z","event_type":"price_change","frame_hash":"a0a0349b45770b6c74be1be40be806cb273a754474abb39677d3f0b2a1ecdd64","frame_index":0,"kind":"data","monotonic_ns":228781669675791,"payload":{"event_type":"price_change","market":"0xeb66215f2e9faa6449e30a02bab5b8ed7b79a38bf961f6b24d0073c9c2419250","price_changes":[{"asset_id":"60386828328910021732068595344565885737045900010034836345809386672230885527307","best_ask":"0.89","best_bid":"0.88","hash":"b42f4071598ea1879607b84a19a3939c335481e0","price":"0.86","side":"BUY","size":"157.97"},{"asset_id":"69697746896130839564035629862476347944307040470122503199396727085502753297492","best_ask":"0.12","best_bid":"0.11","hash":"c79e34a79e80b161f0dbd818e7c256dddda417fc","price":"0.14","side":"SELL","size":"157.97"}],"timestamp":"1785126798450"},"payload_hash":"e6df7ab87aae214b1706593f5a07ea0d7ee873e22df6620dcbfcaac54d3fdf33","raw_frame":"{\"market\":\"0xeb66215f2e9faa6449e30a02bab5b8ed7b79a38bf961f6b24d0073c9c2419250\", \"price_changes\":[{\"asset_id\":\"60386828328910021732068595344565885737045900010034836345809386672230885527307\", \"price\":\"0.86\", \"size\":\"157.97\", \"side\":\"BUY\", \"hash\":\"b42f4071598ea1879607b84a19a3939c335481e0\", \"best_bid\":\"0.88\", \"best_ask\":\"0.89\"}, {\"asset_id\":\"69697746896130839564035629862476347944307040470122503199396727085502753297492\", \"price\":\"0.14\", \"size\":\"157.97\", \"side\":\"SELL\", \"hash\":\"c79e34a79e80b161f0dbd818e7c256dddda417fc\", \"best_bid\":\"0.11\", \"best_ask\":\"0.12\"}], \"timestamp\":\"1785126798450\", \"event_type\":\"price_change\"}","received_at":"2026-07-27T04:33:18.401565Z","schema_version":"clob-market-ws.price_change.v1","sequence":null,"server_hash":null,"server_timestamp":"1785126798450","session_id":"e9443c7415a0419799bee9cfbb1a9e4d","source":"clob_market_ws"},"received_at":"2026-07-27T04:33:18.401565Z","record_id":"a0573c071fe13e2dd7ceba446fbd07369db38f0413997b4118160fef1281c0c4","schema_fingerprint":"4aa3821a28b0b7c2400bc59aba4bcc0a76e971dadd19610d3ad38c768e124dc7","schema_version":"edge-lab-recorder.raw.v1","sequence":null,"source":"clob_market_ws"}
{"event_at":"2026-07-27T04:33:18.450000Z","event_fingerprint":"21db47a0edf0ed2a741fc98f440268663f555416803cd7dee1ba2a5d9d33e0b1","payload":{"connection_id":"0f4979d6978d463e9660b042fdcf555f","event_at":"2026-07-27T04:33:18.450000Z","event_type":"price_change","frame_hash":"7cb081c94645c95b799f8dccaced3307634c48aeac52ba6b235d1acea8b3dfe8","frame_index":0,"kind":"data","monotonic_ns":228781670244458,"payload":{"event_type":"price_change","market":"0xeb66215f2e9faa6449e30a02bab5b8ed7b79a38bf961f6b24d0073c9c2419250","price_changes":[{"asset_id":"60386828328910021732068595344565885737045900010034836345809386672230885527307","best_ask":"0.89","best_bid":"0.88","hash":"b1336bb89c7311846ec29544ca643528bee2695a","price":"0.86","side":"BUY","size":"152.97"},{"asset_id":"69697746896130839564035629862476347944307040470122503199396727085502753297492","best_ask":"0.12","best_bid":"0.11","hash":"bde6f95b09ee3852d460b211c85bf2beb2548833","price":"0.14","side":"SELL","size":"152.97"}],"timestamp":"1785126798450"},"payload_hash":"c0191130b1da1d327b80a8886c5eeb9443b7d520d53a05ee00ad063df17040d7","raw_frame":"{\"market\":\"0xeb66215f2e9faa6449e30a02bab5b8ed7b79a38bf961f6b24d0073c9c2419250\", \"price_changes\":[{\"asset_id\":\"60386828328910021732068595344565885737045900010034836345809386672230885527307\", \"price\":\"0.86\", \"size\":\"152.97\", \"side\":\"BUY\", \"hash\":\"b1336bb89c7311846ec29544ca643528bee2695a\", \"best_bid\":\"0.88\", \"best_ask\":\"0.89\"}, {\"asset_id\":\"69697746896130839564035629862476347944307040470122503199396727085502753297492\", \"price\":\"0.14\", \"size\":\"152.97\", \"side\":\"SELL\", \"hash\":\"bde6f95b09ee3852d460b211c85bf2beb2548833\", \"best_bid\":\"0.11\", \"best_ask\":\"0.12\"}], \"timestamp\":\"1785126798450\", \"event_type\":\"price_change\"}","received_at":"2026-07-27T04:33:18.402134Z","schema_version":"clob-market-ws.price_change.v1","sequence":null,"server_hash":null,"server_timestamp":"1785126798450","session_id":"e9443c7415a0419799bee9cfbb1a9e4d","source":"clob_market_ws"},"received_at":"2026-07-27T04:33:18.402134Z","record_id":"5f561e950eae828b638013a1011613f09d819bd16ec4ee0168a56ddff8c7cc56","schema_fingerprint":"4aa3821a28b0b7c2400bc59aba4bcc0a76e971dadd19610d3ad38c768e124dc7","schema_version":"edge-lab-recorder.raw.v1","sequence":null,"source":"clob_market_ws"}
{"event_at":"2026-07-27T04:33:18.469000Z","event_fingerprint":"2ce4187e97dcc6a35e493750118e4b84c10856b7290bf8356743bc26bfa75bb3","payload":{"connection_id":"0f4979d6978d463e9660b042fdcf555f","event_at":"2026-07-27T04:33:18.469000Z","event_type":"price_change","frame_hash":"087421f62babb190e6437782fa235f27102d91f1792d40cae5a10657594349e5","frame_index":0,"kind":"data","monotonic_ns":228781681494875,"payload":{"event_type":"price_change","market":"0xeb66215f2e9faa6449e30a02bab5b8ed7b79a38bf961f6b24d0073c9c2419250","price_changes":[{"asset_id":"60386828328910021732068595344565885737045900010034836345809386672230885527307","best_ask":"0.89","best_bid":"0.88","hash":"7b8450c0351ba43feb9c396127e01349ee65d6c4","price":"0.02","side":"BUY","size":"733.1"},{"asset_id":"69697746896130839564035629862476347944307040470122503199396727085502753297492","best_ask":"0.12","best_bid":"0.11","hash":"b8cbbd4dc4d57615eea5e02a0ed1663f7e21f933","price":"0.98","side":"SELL","size":"733.1"}],"timestamp":"1785126798469"},"payload_hash":"e0b75e59cc03cbe52de77cd23b7cf54bbb01fc796d86ea9f6fe2dcaf3ffda176","raw_frame":"{\"market\":\"0xeb66215f2e9faa6449e30a02bab5b8ed7b79a38bf961f6b24d0073c9c2419250\", \"price_changes\":[{\"asset_id\":\"60386828328910021732068595344565885737045900010034836345809386672230885527307\", \"price\":\"0.02\", \"size\":\"733.1\", \"side\":\"BUY\", \"hash\":\"7b8450c0351ba43feb9c396127e01349ee65d6c4\", \"best_bid\":\"0.88\", \"best_ask\":\"0.89\"}, {\"asset_id\":\"69697746896130839564035629862476347944307040470122503199396727085502753297492\", \"price\":\"0.98\", \"size\":\"733.1\", \"side\":\"SELL\", \"hash\":\"b8cbbd4dc4d57615eea5e02a0ed1663f7e21f933\", \"best_bid\":\"0.11\", \"best_ask\":\"0.12\"}], \"timestamp\":\"1785126798469\", \"event_type\":\"price_change\"}","received_at":"2026-07-27T04:33:18.413376Z","schema_version":"clob-market-ws.price_change.v1","sequence":null,"server_hash":null,"server_timestamp":"1785126798469","session_id":"e9443c7415a0419799bee9cfbb1a9e4d","source":"clob_market_ws"},"received_at":"2026-07-27T04:33:18.413376Z","record_id":"86bf2c4e30da6e4445dbf887fc9860d6fd26df833f3946ab6ae9484b6579ab4f","schema_fingerprint":"4aa3821a28b0b7c2400bc59aba4bcc0a76e971dadd19610d3ad38c768e124dc7","schema_version":"edge-lab-recorder.raw.v1","sequence":null,"source":"clob_market_ws"}
{"event_at":"2026-07-27T04:33:18.522000Z","event_fingerprint":"196dae9510a514636d7b6f7f87481507150111a6724e7e9efe2b99d01357bb64","payload":{"connection_id":"0f4979d6978d463e9660b042fdcf555f","event_at":"2026-07-27T04:33:18.522000Z","event_type":"price_change","frame_hash":"43c359801031595b91defae1ad32d4e8cf650bffc39386cb8d1834296e3bc6b0","frame_index":0,"kind":"data","monotonic_ns":228781735948250,"payload":{"event_type":"price_change","market":"0xeb66215f2e9faa6449e30a02bab5b8ed7b79a38bf961f6b24d0073c9c2419250","price_changes":[{"asset_id":"60386828328910021732068595344565885737045900010034836345809386672230885527307","best_ask":"0.89","best_bid":"0.88","hash":"6b78e791cbf1b39a1c38b6c5ad0855e3aa943e83","price":"0.86","side":"BUY","size":"147.97"},{"asset_id":"69697746896130839564035629862476347944307040470122503199396727085502753297492","best_ask":"0.12","best_bid":"0.11","hash":"ab7a7c92f13739a623ab49b0dc5420c81e318b25","price":"0.14","side":"SELL","size":"147.97"}],"timestamp":"1785126798522"},"payload_hash":"88ae3ccfa488ccf9557c1d99cadd4b927afd4ce1f9a3ff1294bd8a720fc55b30","raw_frame":"{\"market\":\"0xeb66215f2e9faa6449e30a02bab5b8ed7b79a38bf961f6b24d0073c9c2419250\", \"price_changes\":[{\"asset_id\":\"60386828328910021732068595344565885737045900010034836345809386672230885527307\", \"price\":\"0.86\", \"size\":\"147.97\", \"side\":\"BUY\", \"hash\":\"6b78e791cbf1b39a1c38b6c5ad0855e3aa943e83\", \"best_bid\":\"0.88\", \"best_ask\":\"0.89\"}, {\"asset_id\":\"69697746896130839564035629862476347944307040470122503199396727085502753297492\", \"price\":\"0.14\", \"size\":\"147.97\", \"side\":\"SELL\", \"hash\":\"ab7a7c92f13739a623ab49b0dc5420c81e318b25\", \"best_bid\":\"0.11\", \"best_ask\":\"0.12\"}], \"timestamp\":\"1785126798522\", \"event_type\":\"price_change\"}","received_at":"2026-07-27T04:33:18.467830Z","schema_version":"clob-market-ws.price_change.v1","sequence":null,"server_hash":null,"server_timestamp":"1785126798522","session_id":"e9443c7415a0419799bee9cfbb1a9e4d","source":"clob_market_ws"},"received_at":"2026-07-27T04:33:18.467830Z","record_id":"2bba5690e7f845e59b64f45c7dcada09a07c5d325793eac401f952c8dba87363","schema_fingerprint":"4aa3821a28b0b7c2400bc59aba4bcc0a76e971dadd19610d3ad38c768e124dc7","schema_version":"edge-lab-recorder.raw.v1","sequence":null,"source":"clob_market_ws"}
{"event_at":"2026-07-27T04:33:18.523000Z","event_fingerprint":"d163587ddb44dabfe58aac03438f3de3a65ec5d3f133f51a2a197fe68c4a266e","payload":{"connection_id":"0f4979d6978d463e9660b042fdcf555f","event_at":"2026-07-27T04:33:18.523000Z","event_type":"price_change","frame_hash":"e6e9a87871f66133aba1b6b1818e72f3e56bf016c4ab4552a9bd861c4d302d70","frame_index":0,"kind":"data","monotonic_ns":228781737919833,"payload":{"event_type":"price_change","market":"0xeb66215f2e9faa6449e30a02bab5b8ed7b79a38bf961f6b24d0073c9c2419250","price_changes":[{"asset_id":"60386828328910021732068595344565885737045900010034836345809386672230885527307","best_ask":"0.89","best_bid":"0.88","hash":"0a7d225437fb9a7229fd157f60432eecfae98a94","price":"0.86","side":"BUY","size":"120.37"},{"asset_id":"69697746896130839564035629862476347944307040470122503199396727085502753297492","best_ask":"0.12","best_bid":"0.11","hash":"91daf3d761e25aa9e1ddd83b92617d10fa129a07","price":"0.14","side":"SELL","size":"120.37"}],"timestamp":"1785126798523"},"payload_hash":"6e1ff0a291fb3ab618e532e0b6a98bf9554e60ebae3c0ebcc06f39cbe2efede4","raw_frame":"{\"market\":\"0xeb66215f2e9faa6449e30a02bab5b8ed7b79a38bf961f6b24d0073c9c2419250\", \"price_changes\":[{\"asset_id\":\"60386828328910021732068595344565885737045900010034836345809386672230885527307\", \"price\":\"0.86\", \"size\":\"120.37\", \"side\":\"BUY\", \"hash\":\"0a7d225437fb9a7229fd157f60432eecfae98a94\", \"best_bid\":\"0.88\", \"best_ask\":\"0.89\"}, {\"asset_id\":\"69697746896130839564035629862476347944307040470122503199396727085502753297492\", \"price\":\"0.14\", \"size\":\"120.37\", \"side\":\"SELL\", \"hash\":\"91daf3d761e25aa9e1ddd83b92617d10fa129a07\", \"best_bid\":\"0.11\", \"best_ask\":\"0.12\"}], \"timestamp\":\"1785126798523\", \"event_type\":\"price_change\"}","received_at":"2026-07-27T04:33:18.469802Z","schema_version":"clob-market-ws.price_change.v1","sequence":null,"server_hash":null,"server_timestamp":"1785126798523","session_id":"e9443c7415a0419799bee9cfbb1a9e4d","source":"clob_market_ws"},"received_at":"2026-07-27T04:33:18.469802Z","record_id":"21f2facd63b70b1662bb309d11974045c1a5c11edb9a16ed040489ab98d170e1","schema_fingerprint":"4aa3821a28b0b7c2400bc59aba4bcc0a76e971dadd19610d3ad38c768e124dc7","schema_version":"edge-lab-recorder.raw.v1","sequence":null,"source":"clob_market_ws"}
{"event_at":"2026-07-27T04:33:18.523000Z","event_fingerprint":"23821fea7827fd824abb62a4c807a2022927486bedfeeb442c0972a0ec92973f","payload":{"connection_id":"0f4979d6978d463e9660b042fdcf555f","event_at":"2026-07-27T04:33:18.523000Z","event_type":"price_change","frame_hash":"d17f399a315a1ed2e54da563d69c572286cfb13ef0e47acd8c046d4cc2c2b13e","frame_index":0,"kind":"data","monotonic_ns":228781739458625,"payload":{"event_type":"price_change","market":"0xeb66215f2e9faa6449e30a02bab5b8ed7b79a38bf961f6b24d0073c9c2419250","price_changes":[{"asset_id":"60386828328910021732068595344565885737045900010034836345809386672230885527307","best_ask":"0.89","best_bid":"0.88","hash":"f77bcc7ba7c56093f27a37c7e10372ffc848efb5","price":"0.83","side":"BUY","size":"123.62"},{"asset_id":"69697746896130839564035629862476347944307040470122503199396727085502753297492","best_ask":"0.12","best_bid":"0.11","hash":"c8528703b80f5e27d71cd99f581f9498c9b06868","price":"0.17","side":"SELL","size":"123.62"}],"timestamp":"1785126798523"},"payload_hash":"ae1634db28fa9a00cf59626cc58bd3ab01d89ceb84b98a083e1208f351ef091e","raw_frame":"{\"market\":\"0xeb66215f2e9faa6449e30a02bab5b8ed7b79a38bf961f6b24d0073c9c2419250\", \"price_changes\":[{\"asset_id\":\"60386828328910021732068595344565885737045900010034836345809386672230885527307\", \"price\":\"0.83\", \"size\":\"123.62\", \"side\":\"BUY\", \"hash\":\"f77bcc7ba7c56093f27a37c7e10372ffc848efb5\", \"best_bid\":\"0.88\", \"best_ask\":\"0.89\"}, {\"asset_id\":\"69697746896130839564035629862476347944307040470122503199396727085502753297492\", \"price\":\"0.17\", \"size\":\"123.62\", \"side\":\"SELL\", \"hash\":\"c8528703b80f5e27d71cd99f581f9498c9b06868\", \"best_bid\":\"0.11\", \"best_ask\":\"0.12\"}], \"timestamp\":\"1785126798523\", \"event_type\":\"price_change\"}","received_at":"2026-07-27T04:33:18.471342Z","schema_version":"clob-market-ws.price_change.v1","sequence":null,"server_hash":null,"server_timestamp":"1785126798523","session_id":"e9443c7415a0419799bee9cfbb1a9e4d","source":"clob_market_ws"},"received_at":"2026-07-27T04:33:18.471342Z","record_id":"150952cce5cf6ef549ab5261ad829ca024abc31723736092661e45597d8504a5","schema_fingerprint":"4aa3821a28b0b7c2400bc59aba4bcc0a76e971dadd19610d3ad38c768e124dc7","schema_version":"edge-lab-recorder.raw.v1","sequence":null,"source":"clob_market_ws"}
{"event_at":"2026-07-27T04:33:18.525000Z","event_fingerprint":"08fe86c906f76fb7e422ee426a34d4e351b0242a844f0bdf043124bdc34ded1e","payload":{"connection_id":"0f4979d6978d463e9660b042fdcf555f","event_at":"2026-07-27T04:33:18.525000Z","event_type":"price_change","frame_hash":"bc857c617591c6815c9fe90c88b977601875c1ab6ed42488c51fc8587e2dd7f1","frame_index":0,"kind":"data","monotonic_ns":228781742237791,"payload":{"event_type":"price_change","market":"0xeb66215f2e9faa6449e30a02bab5b8ed7b79a38bf961f6b24d0073c9c2419250","price_changes":[{"asset_id":"60386828328910021732068595344565885737045900010034836345809386672230885527307","best_ask":"0.89","best_bid":"0.88","hash":"08cd3e58ef0d47046f06e564396b2476ddc243e3","price":"0.83","side":"BUY","size":"93.62"},{"asset_id":"69697746896130839564035629862476347944307040470122503199396727085502753297492","best_ask":"0.12","best_bid":"0.11","hash":"b8934b70f9b882411bb05d3dbd8b08b93291bf41","price":"0.17","side":"SELL","size":"93.62"}],"timestamp":"1785126798525"},"payload_hash":"4d8633d9fe56f755791e0eecafba7ba1263edaace014ed193f9dbdb75f61cfeb","raw_frame":"{\"market\":\"0xeb66215f2e9faa6449e30a02bab5b8ed7b79a38bf961f6b24d0073c9c2419250\", \"price_changes\":[{\"asset_id\":\"60386828328910021732068595344565885737045900010034836345809386672230885527307\", \"price\":\"0.83\", \"size\":\"93.62\", \"side\":\"BUY\", \"hash\":\"08cd3e58ef0d47046f06e564396b2476ddc243e3\", \"best_bid\":\"0.88\", \"best_ask\":\"0.89\"}, {\"asset_id\":\"69697746896130839564035629862476347944307040470122503199396727085502753297492\", \"price\":\"0.17\", \"size\":\"93.62\", \"side\":\"SELL\", \"hash\":\"b8934b70f9b882411bb05d3dbd8b08b93291bf41\", \"best_bid\":\"0.11\", \"best_ask\":\"0.12\"}], \"timestamp\":\"1785126798525\", \"event_type\":\"price_change\"}","received_at":"2026-07-27T04:33:18.474120Z","schema_version":"clob-market-ws.price_change.v1","sequence":null,"server_hash":null,"server_timestamp":"1785126798525","session_id":"e9443c7415a0419799bee9cfbb1a9e4d","source":"clob_market_ws"},"received_at":"2026-07-27T04:33:18.474120Z","record_id":"8efa93db42f914d54f5d6aa052aa9bb0f5067041c5286d99ca46eedad3990eb3","schema_fingerprint":"4aa3821a28b0b7c2400bc59aba4bcc0a76e971dadd19610d3ad38c768e124dc7","schema_version":"edge-lab-recorder.raw.v1","sequence":null,"source":"clob_market_ws"}
{"event_at":"2026-07-27T04:33:18.527000Z","event_fingerprint":"26a3f84637f8420b251855e0fcb5c028cc18ef5c0b420274a24b44e6cf5707bd","payload":{"connection_id":"0f4979d6978d463e9660b042fdcf555f","event_at":"2026-07-27T04:33:18.527000Z","event_type":"price_change","frame_hash":"a4c579bae088020644d5f6a8661d99860315d4730af92a9238b231f2eeb665d4","frame_index":0,"kind":"data","monotonic_ns":228781743767166,"payload":{"event_type":"price_change","market":"0xeb66215f2e9faa6449e30a02bab5b8ed7b79a38bf961f6b24d0073c9c2419250","price_changes":[{"asset_id":"60386828328910021732068595344565885737045900010034836345809386672230885527307","best_ask":"0.89","best_bid":"0.88","hash":"04c102a990496edf1f82a945d531ceb6326bad50","price":"0.83","side":"BUY","size":"63.62"},{"asset_id":"69697746896130839564035629862476347944307040470122503199396727085502753297492","best_ask":"0.12","best_bid":"0.11","hash":"ae2e954c8bb0ef1b5ab686dc3ff8eda6d44c100c","price":"0.17","side":"SELL","size":"63.62"}],"timestamp":"1785126798527"},"payload_hash":"8c2e837300c784445e5f0415e46c5f7bf8a9b721632e81adbc122ce52ff4cf72","raw_frame":"{\"market\":\"0xeb66215f2e9faa6449e30a02bab5b8ed7b79a38bf961f6b24d0073c9c2419250\", \"price_changes\":[{\"asset_id\":\"60386828328910021732068595344565885737045900010034836345809386672230885527307\", \"price\":\"0.83\", \"size\":\"63.62\", \"side\":\"BUY\", \"hash\":\"04c102a990496edf1f82a945d531ceb6326bad50\", \"best_bid\":\"0.88\", \"best_ask\":\"0.89\"}, {\"asset_id\":\"69697746896130839564035629862476347944307040470122503199396727085502753297492\", \"price\":\"0.17\", \"size\":\"63.62\", \"side\":\"SELL\", \"hash\":\"ae2e954c8bb0ef1b5ab686dc3ff8eda6d44c100c\", \"best_bid\":\"0.11\", \"best_ask\":\"0.12\"}], \"timestamp\":\"1785126798527\", \"event_type\":\"price_change\"}","received_at":"2026-07-27T04:33:18.475650Z","schema_version":"clob-market-ws.price_change.v1","sequence":null,"server_hash":null,"server_timestamp":"1785126798527","session_id":"e9443c7415a0419799bee9cfbb1a9e4d","source":"clob_market_ws"},"received_at":"2026-07-27T04:33:18.475650Z","record_id":"f34aec28c7fe47ce4a11d26171d41ea281e6a15eb541d8116f57a4da70130f96","schema_fingerprint":"4aa3821a28b0b7c2400bc59aba4bcc0a76e971dadd19610d3ad38c768e124dc7","schema_version":"edge-lab-recorder.raw.v1","sequence":null,"source":"clob_market_ws"}
{"event_at":"2026-07-27T04:33:18.538000Z","event_fingerprint":"2dc2038ca3430da02216a09091ca1cf95474321449628ffdbfd832e991cd1ae9","payload":{"connection_id":"0f4979d6978d463e9660b042fdcf555f","event_at":"2026-07-27T04:33:18.538000Z","event_type":"price_change","frame_hash":"744469b79484fdf88fac9e2987bcb30923abb66715144a20a1cd93043be965a4","frame_index":0,"kind":"data","monotonic_ns":228781751851333,"payload":{"event_type":"price_change","market":"0xeb66215f2e9faa6449e30a02bab5b8ed7b79a38bf961f6b24d0073c9c2419250","price_changes":[{"asset_id":"60386828328910021732068595344565885737045900010034836345809386672230885527307","best_ask":"0.89","best_bid":"0.88","hash":"3350c15dc373357d914cf258052b0ae14b8d1a2f","price":"0.89","side":"SELL","size":"486.44"},{"asset_id":"69697746896130839564035629862476347944307040470122503199396727085502753297492","best_ask":"0.12","best_bid":"0.11","hash":"061579b1fd121856c3965321afb66d01714521eb","price":"0.11","side":"BUY","size":"486.44"}],"timestamp":"1785126798538"},"payload_hash":"9ca3a1b9e0007eab49ede481f02dbb80b4f2c627b59690af0917e824efef83e5","raw_frame":"{\"market\":\"0xeb66215f2e9faa6449e30a02bab5b8ed7b79a38bf961f6b24d0073c9c2419250\", \"price_changes\":[{\"asset_id\":\"60386828328910021732068595344565885737045900010034836345809386672230885527307\", \"price\":\"0.89\", \"size\":\"486.44\", \"side\":\"SELL\", \"hash\":\"3350c15dc373357d914cf258052b0ae14b8d1a2f\", \"best_bid\":\"0.88\", \"best_ask\":\"0.89\"}, {\"asset_id\":\"69697746896130839564035629862476347944307040470122503199396727085502753297492\", \"price\":\"0.11\", \"size\":\"486.44\", \"side\":\"BUY\", \"hash\":\"061579b1fd121856c3965321afb66d01714521eb\", \"best_bid\":\"0.11\", \"best_ask\":\"0.12\"}], \"timestamp\":\"1785126798538\", \"event_type\":\"price_change\"}","received_at":"2026-07-27T04:33:18.483733Z","schema_version":"clob-market-ws.price_change.v1","sequence":null,"server_hash":null,"server_timestamp":"1785126798538","session_id":"e9443c7415a0419799bee9cfbb1a9e4d","source":"clob_market_ws"},"received_at":"2026-07-27T04:33:18.483733Z","record_id":"21821651f27b9e29cc19a3086d60fc4649aaf3724bdffc33e9fa7a8997b623e2","schema_fingerprint":"4aa3821a28b0b7c2400bc59aba4bcc0a76e971dadd19610d3ad38c768e124dc7","schema_version":"edge-lab-recorder.raw.v1","sequence":null,"source":"clob_market_ws"}
{"event_at":"2026-07-27T04:33:18.546000Z","event_fingerprint":"a197734081f86eeb57cb0557eb6301ef1170f29daec9fb4694e18492ddac73e5","payload":{"connection_id":"0f4979d6978d463e9660b042fdcf555f","event_at":"2026-07-27T04:33:18.546000Z","event_type":"price_change","frame_hash":"f679f54792b02464020e4fab2b78b85a6f9a41f4e56126673e3878a47aeaa83d","frame_index":0,"kind":"data","monotonic_ns":228781759298625,"payload":{"event_type":"price_change","market":"0xeb66215f2e9faa6449e30a02bab5b8ed7b79a38bf961f6b24d0073c9c2419250","price_changes":[{"asset_id":"60386828328910021732068595344565885737045900010034836345809386672230885527307","best_ask":"0.89","best_bid":"0.88","hash":"74c691384a518d89fc2de96ce51b75bed9735535","price":"0.03","side":"BUY","size":"648.1"},{"asset_id":"69697746896130839564035629862476347944307040470122503199396727085502753297492","best_ask":"0.12","best_bid":"0.11","hash":"995a1d6a0bf82043b62aea02806a8761310185c6","price":"0.97","side":"SELL","size":"648.1"}],"timestamp":"1785126798546"},"payload_hash":"7ccff8ecdf194b3fc4841c3816761b0dc9a3b1af45a78ccd5d0b4db99c0187fb","raw_frame":"{\"market\":\"0xeb66215f2e9faa6449e30a02bab5b8ed7b79a38bf961f6b24d0073c9c2419250\", \"price_changes\":[{\"asset_id\":\"60386828328910021732068595344565885737045900010034836345809386672230885527307\", \"price\":\"0.03\", \"size\":\"648.1\", \"side\":\"BUY\", \"hash\":\"74c691384a518d89fc2de96ce51b75bed9735535\", \"best_bid\":\"0.88\", \"best_ask\":\"0.89\"}, {\"asset_id\":\"69697746896130839564035629862476347944307040470122503199396727085502753297492\", \"price\":\"0.97\", \"size\":\"648.1\", \"side\":\"SELL\", \"hash\":\"995a1d6a0bf82043b62aea02806a8761310185c6\", \"best_bid\":\"0.11\", \"best_ask\":\"0.12\"}], \"timestamp\":\"1785126798546\", \"event_type\":\"price_change\"}","received_at":"2026-07-27T04:33:18.491181Z","schema_version":"clob-market-ws.price_change.v1","sequence":null,"server_hash":null,"server_timestamp":"1785126798546","session_id":"e9443c7415a0419799bee9cfbb1a9e4d","source":"clob_market_ws"},"received_at":"2026-07-27T04:33:18.491181Z","record_id":"1b84cd733c6cbb94c186da7bb645519014001730623a3d7edeb9ffc3f9df3b08","schema_fingerprint":"4aa3821a28b0b7c2400bc59aba4bcc0a76e971dadd19610d3ad38c768e124dc7","schema_version":"edge-lab-recorder.raw.v1","sequence":null,"source":"clob_market_ws"}
{"event_at":"2026-07-27T04:33:18.547000Z","event_fingerprint":"65f94a35ddc7546b4ff206df506e05f66f0b1ccb7e70e1007cb555091ca85a4c","payload":{"connection_id":"0f4979d6978d463e9660b042fdcf555f","event_at":"2026-07-27T04:33:18.547000Z","event_type":"price_change","frame_hash":"01d2e40d7e0bf12a9d85e511d560e316ffc2e69cf60523c8f7ebedc4f8ad7df4","frame_index":0,"kind":"data","monotonic_ns":228781761362375,"payload":{"event_type":"price_change","market":"0xeb66215f2e9faa6449e30a02bab5b8ed7b79a38bf961f6b24d0073c9c2419250","price_changes":[{"asset_id":"60386828328910021732068595344565885737045900010034836345809386672230885527307","best_ask":"0.89","best_bid":"0.88","hash":"52d484fbaafb7c2bbbb2f1064bac2c2ca85fe369","price":"0.84","side":"BUY","size":"128.61"},{"asset_id":"69697746896130839564035629862476347944307040470122503199396727085502753297492","best_ask":"0.12","best_bid":"0.11","hash":"e0bdc0205eb656beb6bc2aa6696eaeced59b0ac6","price":"0.16","side":"SELL","size":"128.61"}],"timestamp":"1785126798547"},"payload_hash":"aa2ac75e574beb137805c9d77c50e70b0d6644b113fd5bd944bcd47871195043","raw_frame":"{\"market\":\"0xeb66215f2e9faa6449e30a02bab5b8ed7b79a38bf961f6b24d0073c9c2419250\", \"price_changes\":[{\"asset_id\":\"60386828328910021732068595344565885737045900010034836345809386672230885527307\", \"price\":\"0.84\", \"size\":\"128.61\", \"side\":\"BUY\", \"hash\":\"52d484fbaafb7c2bbbb2f1064bac2c2ca85fe369\", \"best_bid\":\"0.88\", \"best_ask\":\"0.89\"}, {\"asset_id\":\"69697746896130839564035629862476347944307040470122503199396727085502753297492\", \"price\":\"0.16\", \"size\":\"128.61\", \"side\":\"SELL\", \"hash\":\"e0bdc0205eb656beb6bc2aa6696eaeced59b0ac6\", \"best_bid\":\"0.11\", \"best_ask\":\"0.12\"}], \"timestamp\":\"1785126798547\", \"event_type\":\"price_change\"}","received_at":"2026-07-27T04:33:18.493246Z","schema_version":"clob-market-ws.price_change.v1","sequence":null,"server_hash":null,"server_timestamp":"1785126798547","session_id":"e9443c7415a0419799bee9cfbb1a9e4d","source":"clob_market_ws"},"received_at":"2026-07-27T04:33:18.493246Z","record_id":"4bd3385baa62b53daa08fc3419b7a7192e39730b6b5b20c6d1cc735614e8d357","schema_fingerprint":"4aa3821a28b0b7c2400bc59aba4bcc0a76e971dadd19610d3ad38c768e124dc7","schema_version":"edge-lab-recorder.raw.v1","sequence":null,"source":"clob_market_ws"}
{"event_at":"2026-07-27T04:33:18.551000Z","event_fingerprint":"672628b231e9de0a8d7b87910c714f2f2d000938f7c1781fb42c137d3d714786","payload":{"connection_id":"0f4979d6978d463e9660b042fdcf555f","event_at":"2026-07-27T04:33:18.551000Z","event_type":"price_change","frame_hash":"8d66c5ee89d982bec87c66af9cd426c83b1650dcf71de4acca6b7efac2b53624","frame_index":0,"kind":"data","monotonic_ns":228781765425416,"payload":{"event_type":"price_change","market":"0xeb66215f2e9faa6449e30a02bab5b8ed7b79a38bf961f6b24d0073c9c2419250","price_changes":[{"asset_id":"60386828328910021732068595344565885737045900010034836345809386672230885527307","best_ask":"0.89","best_bid":"0.88","hash":"e071d987999c040b8af71032fd6af6c9707dbcfb","price":"0.87","side":"BUY","size":"29.31"},{"asset_id":"69697746896130839564035629862476347944307040470122503199396727085502753297492","best_ask":"0.12","best_bid":"0.11","hash":"5499746a58501c7be975307f83e50b8ac0c3b4f6","price":"0.13","side":"SELL","size":"29.31"}],"timestamp":"1785126798551"},"payload_hash":"ccd374256361ba34e6fd9891af5dbe0239e441db936f07b75d2e60f1a5a79dfa","raw_frame":"{\"market\":\"0xeb66215f2e9faa6449e30a02bab5b8ed7b79a38bf961f6b24d0073c9c2419250\", \"price_changes\":[{\"asset_id\":\"60386828328910021732068595344565885737045900010034836345809386672230885527307\", \"price\":\"0.87\", \"size\":\"29.31\", \"side\":\"BUY\", \"hash\":\"e071d987999c040b8af71032fd6af6c9707dbcfb\", \"best_bid\":\"0.88\", \"best_ask\":\"0.89\"}, {\"asset_id\":\"69697746896130839564035629862476347944307040470122503199396727085502753297492\", \"price\":\"0.13\", \"size\":\"29.31\", \"side\":\"SELL\", \"hash\":\"5499746a58501c7be975307f83e50b8ac0c3b4f6\", \"best_bid\":\"0.11\", \"best_ask\":\"0.12\"}], \"timestamp\":\"1785126798551\", \"event_type\":\"price_change\"}","received_at":"2026-07-27T04:33:18.497308Z","schema_version":"clob-market-ws.price_change.v1","sequence":null,"server_hash":null,"server_timestamp":"1785126798551","session_id":"e9443c7415a0419799bee9cfbb1a9e4d","source":"clob_market_ws"},"received_at":"2026-07-27T04:33:18.497308Z","record_id":"760a2ffcbb6d1c0d0f7b58d000ff062f02257d09427ee151cf57dfab4433c438","schema_fingerprint":"4aa3821a28b0b7c2400bc59aba4bcc0a76e971dadd19610d3ad38c768e124dc7","schema_version":"edge-lab-recorder.raw.v1","sequence":null,"source":"clob_market_ws"}
{"event_at":"2026-07-27T04:33:18.555000Z","event_fingerprint":"70dbb06d37701dc533859c3100dd120bb58b77bce2ef472387897b55d40d7e0d","payload":{"connection_id":"0f4979d6978d463e9660b042fdcf555f","event_at":"2026-07-27T04:33:18.555000Z","event_type":"price_change","frame_hash":"2326904c78fa6831e41db17ccccee2d072e8b443bf2583a6f103a8e66aca690f","frame_index":0,"kind":"data","monotonic_ns":228781768583000,"payload":{"event_type":"price_change","market":"0xeb66215f2e9faa6449e30a02bab5b8ed7b79a38bf961f6b24d0073c9c2419250","price_changes":[{"asset_id":"69697746896130839564035629862476347944307040470122503199396727085502753297492","best_ask":"0.12","best_bid":"0.11","hash":"cb2380b0851a881f4d8a96a791c78bf645d63d66","price":"0.09","side":"BUY","size":"949.6"},{"asset_id":"60386828328910021732068595344565885737045900010034836345809386672230885527307","best_ask":"0.89","best_bid":"0.88","hash":"babb87af2f5eacd0c872a6a93262c4e13c3c535c","price":"0.91","side":"SELL","size":"949.6"}],"timestamp":"1785126798555"},"payload_hash":"225a58f728a03d1ca5b4f52797f2a3af1213f43a0d14aa1d6af202915a2484f7","raw_frame":"{\"market\":\"0xeb66215f2e9faa6449e30a02bab5b8ed7b79a38bf961f6b24d0073c9c2419250\", \"price_changes\":[{\"asset_id\":\"69697746896130839564035629862476347944307040470122503199396727085502753297492\", \"price\":\"0.09\", \"size\":\"949.6\", \"side\":\"BUY\", \"hash\":\"cb2380b0851a881f4d8a96a791c78bf645d63d66\", \"best_bid\":\"0.11\", \"best_ask\":\"0.12\"}, {\"asset_id\":\"60386828328910021732068595344565885737045900010034836345809386672230885527307\", \"price\":\"0.91\", \"size\":\"949.6\", \"side\":\"SELL\", \"hash\":\"babb87af2f5eacd0c872a6a93262c4e13c3c535c\", \"best_bid\":\"0.88\", \"best_ask\":\"0.89\"}], \"timestamp\":\"1785126798555\", \"event_type\":\"price_change\"}","received_at":"2026-07-27T04:33:18.500463Z","schema_version":"clob-market-ws.price_change.v1","sequence":null,"server_hash":null,"server_timestamp":"1785126798555","session_id":"e9443c7415a0419799bee9cfbb1a9e4d","source":"clob_market_ws"},"received_at":"2026-07-27T04:33:18.500463Z","record_id":"7a765d0c150023b90218d78a85452197be61928facf4ff7cc6f7d854e043e8e3","schema_fingerprint":"4aa3821a28b0b7c2400bc59aba4bcc0a76e971dadd19610d3ad38c768e124dc7","schema_version":"edge-lab-recorder.raw.v1","sequence":null,"source":"clob_market_ws"}
{"event_at":"2026-07-27T04:33:18.556000Z","event_fingerprint":"89d889cd85ce9dd30ccb6e5032eea0a0a1a0e5d834dd122e3534403fd290ab8c","payload":{"connection_id":"0f4979d6978d463e9660b042fdcf555f","event_at":"2026-07-27T04:33:18.556000Z","event_type":"price_change","frame_hash":"f55cb7d0098fbd35561f36e9659e41ed739acd41d9d7c75b16f0379a85fa2580","frame_index":0,"kind":"data","monotonic_ns":228781770392958,"payload":{"event_type":"price_change","market":"0xeb66215f2e9faa6449e30a02bab5b8ed7b79a38bf961f6b24d0073c9c2419250","price_changes":[{"asset_id":"60386828328910021732068595344565885737045900010034836345809386672230885527307","best_ask":"0.89","best_bid":"0.88","hash":"6904fbe020ea2c459f93259a826159f5d80c792b","price":"0.84","side":"BUY","size":"158.61"},{"asset_id":"69697746896130839564035629862476347944307040470122503199396727085502753297492","best_ask":"0.12","best_bid":"0.11","hash":"4a1bbae927f4c2e2acd39c32ba441de6caf4ff8a","price":"0.16","side":"SELL","size":"158.61"}],"timestamp":"1785126798556"},"payload_hash":"ceab31ba50167e0b89f7605d4807687bcf77841257c623649a57326ae47fd94a","raw_frame":"{\"market\":\"0xeb66215f2e9faa6449e30a02bab5b8ed7b79a38bf961f6b24d0073c9c2419250\", \"price_changes\":[{\"asset_id\":\"60386828328910021732068595344565885737045900010034836345809386672230885527307\", \"price\":\"0.84\", \"size\":\"158.61\", \"side\":\"BUY\", \"hash\":\"6904fbe020ea2c459f93259a826159f5d80c792b\", \"best_bid\":\"0.88\", \"best_ask\":\"0.89\"}, {\"asset_id\":\"69697746896130839564035629862476347944307040470122503199396727085502753297492\", \"price\":\"0.16\", \"size\":\"158.61\", \"side\":\"SELL\", \"hash\":\"4a1bbae927f4c2e2acd39c32ba441de6caf4ff8a\", \"best_bid\":\"0.11\", \"best_ask\":\"0.12\"}], \"timestamp\":\"1785126798556\", \"event_type\":\"price_change\"}","received_at":"2026-07-27T04:33:18.502273Z","schema_version":"clob-market-ws.price_change.v1","sequence":null,"server_hash":null,"server_timestamp":"1785126798556","session_id":"e9443c7415a0419799bee9cfbb1a9e4d","source":"clob_market_ws"},"received_at":"2026-07-27T04:33:18.502273Z","record_id":"695bdf35feb3b7542d7aad4e083499e125c50ce5dce3d6e394a2af9bf5644e49","schema_fingerprint":"4aa3821a28b0b7c2400bc59aba4bcc0a76e971dadd19610d3ad38c768e124dc7","schema_version":"edge-lab-recorder.raw.v1","sequence":null,"source":"clob_market_ws"}
{"event_at":"2026-07-27T04:33:18.557000Z","event_fingerprint":"d5c90c2104583cb18c31aba0042a3d51249637ce01653b7b144f823a50d6394d","payload":{"connection_id":"0f4979d6978d463e9660b042fdcf555f","event_at":"2026-07-27T04:33:18.557000Z","event_type":"price_change","frame_hash":"dd5b9e5fef2053bbfdc83207bd091da83ecd0b3e9b0040d5c263a8b71d3d64f8","frame_index":0,"kind":"data","monotonic_ns":228781770938958,"payload":{"event_type":"price_change","market":"0xeb66215f2e9faa6449e30a02bab5b8ed7b79a38bf961f6b24d0073c9c2419250","price_changes":[{"asset_id":"60386828328910021732068595344565885737045900010034836345809386672230885527307","best_ask":"0.89","best_bid":"0.88","hash":"e9a3c4fbf7c906c18a3fe787c9c9ce140ea32538","price":"0.84","side":"BUY","size":"188.61"},{"asset_id":"69697746896130839564035629862476347944307040470122503199396727085502753297492","best_ask":"0.12","best_bid":"0.11","hash":"b0860fd234e70f4a58da2a3652b917698bb1ae22","price":"0.16","side":"SELL","size":"188.61"}],"timestamp":"1785126798557"},"payload_hash":"f9cf39d40533b749e936c5d6412d191945dfd077299842d9b28a269ab9434491","raw_frame":"{\"market\":\"0xeb66215f2e9faa6449e30a02bab5b8ed7b79a38bf961f6b24d0073c9c2419250\", \"price_changes\":[{\"asset_id\":\"60386828328910021732068595344565885737045900010034836345809386672230885527307\", \"price\":\"0.84\", \"size\":\"188.61\", \"side\":\"BUY\", \"hash\":\"e9a3c4fbf7c906c18a3fe787c9c9ce140ea32538\", \"best_bid\":\"0.88\", \"best_ask\":\"0.89\"}, {\"asset_id\":\"69697746896130839564035629862476347944307040470122503199396727085502753297492\", \"price\":\"0.16\", \"size\":\"188.61\", \"side\":\"SELL\", \"hash\":\"b0860fd234e70f4a58da2a3652b917698bb1ae22\", \"best_bid\":\"0.11\", \"best_ask\":\"0.12\"}], \"timestamp\":\"1785126798557\", \"event_type\":\"price_change\"}","received_at":"2026-07-27T04:33:18.502830Z","schema_version":"clob-market-ws.price_change.v1","sequence":null,"server_hash":null,"server_timestamp":"1785126798557","session_id":"e9443c7415a0419799bee9cfbb1a9e4d","source":"clob_market_ws"},"received_at":"2026-07-27T04:33:18.502830Z","record_id":"e6de06447a270cc7246b7d70131c6fd395e717537e07ab776d9288726c960cf1","schema_fingerprint":"4aa3821a28b0b7c2400bc59aba4bcc0a76e971dadd19610d3ad38c768e124dc7","schema_version":"edge-lab-recorder.raw.v1","sequence":null,"source":"clob_market_ws"}
{"event_at":"2026-07-27T04:33:18.558000Z","event_fingerprint":"3eaf2c10bd33d6013d67dbb563a9d315f6ac08444a58cf19a53a916b0243fa12","payload":{"connection_id":"0f4979d6978d463e9660b042fdcf555f","event_at":"2026-07-27T04:33:18.558000Z","event_type":"price_change","frame_hash":"6d7bd477b2964cfa466f890df54aecfae966a5c2740e7fd0afc479abef921edb","frame_index":0,"kind":"data","monotonic_ns":228781772625541,"payload":{"event_type":"price_change","market":"0xeb66215f2e9faa6449e30a02bab5b8ed7b79a38bf961f6b24d0073c9c2419250","price_changes":[{"asset_id":"60386828328910021732068595344565885737045900010034836345809386672230885527307","best_ask":"0.89","best_bid":"0.88","hash":"cb76639b938351364c2fcb6952822e8507eb23b8","price":"0.87","side":"BUY","size":"34.31"},{"asset_id":"69697746896130839564035629862476347944307040470122503199396727085502753297492","best_ask":"0.12","best_bid":"0.11","hash":"0a1f82208f191e0e45a8a02ef13aa9cd43090b01","price":"0.13","side":"SELL","size":"34.31"}],"timestamp":"1785126798558"},"payload_hash":"01e1089c2abc7ed3d9df4e8e6943600958c5c5923f9315a4ddf5d823c079a303","raw_frame":"{\"market\":\"0xeb66215f2e9faa6449e30a02bab5b8ed7b79a38bf961f6b24d0073c9c2419250\", \"price_changes\":[{\"asset_id\":\"60386828328910021732068595344565885737045900010034836345809386672230885527307\", \"price\":\"0.87\", \"size\":\"34.31\", \"side\":\"BUY\", \"hash\":\"cb76639b938351364c2fcb6952822e8507eb23b8\", \"best_bid\":\"0.88\", \"best_ask\":\"0.89\"}, {\"asset_id\":\"69697746896130839564035629862476347944307040470122503199396727085502753297492\", \"price\":\"0.13\", \"size\":\"34.31\", \"side\":\"SELL\", \"hash\":\"0a1f82208f191e0e45a8a02ef13aa9cd43090b01\", \"best_bid\":\"0.11\", \"best_ask\":\"0.12\"}], \"timestamp\":\"1785126798558\", \"event_type\":\"price_change\"}","received_at":"2026-07-27T04:33:18.504507Z","schema_version":"clob-market-ws.price_change.v1","sequence":null,"server_hash":null,"server_timestamp":"1785126798558","session_id":"e9443c7415a0419799bee9cfbb1a9e4d","source":"clob_market_ws"},"received_at":"2026-07-27T04:33:18.504507Z","record_id":"2c8856e27fa5d346ff3c0acde2eb9148d4d57e3070ddc8d129dfb6b2c89cfdd7","schema_fingerprint":"4aa3821a28b0b7c2400bc59aba4bcc0a76e971dadd19610d3ad38c768e124dc7","schema_version":"edge-lab-recorder.raw.v1","sequence":null,"source":"clob_market_ws"}
{"event_at":"2026-07-27T04:33:18.603000Z","event_fingerprint":"5d91e25e4acffcf75667a90a7c4531006911d31b076becaa06df535d3a263741","payload":{"connection_id":"0f4979d6978d463e9660b042fdcf555f","event_at":"2026-07-27T04:33:18.603000Z","event_type":"price_change","frame_hash":"2383385068a3ae501f00f0899b9e540530f6549e1b04cd29c02b609af82c8acb","frame_index":0,"kind":"data","monotonic_ns":228781818304916,"payload":{"event_type":"price_change","market":"0xeb66215f2e9faa6449e30a02bab5b8ed7b79a38bf961f6b24d0073c9c2419250","price_changes":[{"asset_id":"60386828328910021732068595344565885737045900010034836345809386672230885527307","best_ask":"0.89","best_bid":"0.88","hash":"7aed248d47adba5a9313c0fda2c622b80c8142d9","price":"0.03","side":"BUY","size":"643.1"},{"asset_id":"69697746896130839564035629862476347944307040470122503199396727085502753297492","best_ask":"0.12","best_bid":"0.11","hash":"3bdcd03cd8651b5dcd909a33c35642e175e4a379","price":"0.97","side":"SELL","size":"643.1"}],"timestamp":"1785126798603"},"payload_hash":"0b2692542b756fddd397a2f01d2431c117db1e441fc877ef93781a4ddc750408","raw_frame":"{\"market\":\"0xeb66215f2e9faa6449e30a02bab5b8ed7b79a38bf961f6b24d0073c9c2419250\", \"price_changes\":[{\"asset_id\":\"60386828328910021732068595344565885737045900010034836345809386672230885527307\", \"price\":\"0.03\", \"size\":\"643.1\", \"side\":\"BUY\", \"hash\":\"7aed248d47adba5a9313c0fda2c622b80c8142d9\", \"best_bid\":\"0.88\", \"best_ask\":\"0.89\"}, {\"asset_id\":\"69697746896130839564035629862476347944307040470122503199396727085502753297492\", \"price\":\"0.97\", \"size\":\"643.1\", \"side\":\"SELL\", \"hash\":\"3bdcd03cd8651b5dcd909a33c35642e175e4a379\", \"best_bid\":\"0.11\", \"best_ask\":\"0.12\"}], \"timestamp\":\"1785126798603\", \"event_type\":\"price_change\"}","received_at":"2026-07-27T04:33:18.550188Z","schema_version":"clob-market-ws.price_change.v1","sequence":null,"server_hash":null,"server_timestamp":"1785126798603","session_id":"e9443c7415a0419799bee9cfbb1a9e4d","source":"clob_market_ws"},"received_at":"2026-07-27T04:33:18.550188Z","record_id":"a4b70e2d5efc2a40196c409e3c8e0e8a6787ff9af443dcca70354c0907667f0b","schema_fingerprint":"4aa3821a28b0b7c2400bc59aba4bcc0a76e971dadd19610d3ad38c768e124dc7","schema_version":"edge-lab-recorder.raw.v1","sequence":null,"source":"clob_market_ws"}
{"event_at":"2026-07-27T04:33:18.630000Z","event_fingerprint":"c954f4c627ac61ceca0cb2b14a5f100506f6e6b83816040f037d9a6ea3a2aeaf","payload":{"connection_id":"0f4979d6978d463e9660b042fdcf555f","event_at":"2026-07-27T04:33:18.630000Z","event_type":"price_change","frame_hash":"4470af6ce29a91f47bbb4fe8e7efcdaf1caad1c6a38b00ae99901fec6c664d21","frame_index":0,"kind":"data","monotonic_ns":228781843572916,"payload":{"event_type":"price_change","market":"0xeb66215f2e9faa6449e30a02bab5b8ed7b79a38bf961f6b24d0073c9c2419250","price_changes":[{"asset_id":"60386828328910021732068595344565885737045900010034836345809386672230885527307","best_ask":"0.89","best_bid":"0.88","hash":"fd0851117893b804a6f39682be0734f5b26db9f4","price":"0.89","side":"SELL","size":"481.4"},{"asset_id":"69697746896130839564035629862476347944307040470122503199396727085502753297492","best_ask":"0.12","best_bid":"0.11","hash":"9b0929ea39b18339d8eebd8f4e6371062d509250","price":"0.11","side":"BUY","size":"481.4"}],"timestamp":"1785126798630"},"payload_hash":"e39c490ee928cb4d5a438493191054793b3ced6592bf49b4292a85211cc263a8","raw_frame":"{\"market\":\"0xeb66215f2e9faa6449e30a02bab5b8ed7b79a38bf961f6b24d0073c9c2419250\", \"price_changes\":[{\"asset_id\":\"60386828328910021732068595344565885737045900010034836345809386672230885527307\", \"price\":\"0.89\", \"size\":\"481.4\", \"side\":\"SELL\", \"hash\":\"fd0851117893b804a6f39682be0734f5b26db9f4\", \"best_bid\":\"0.88\", \"best_ask\":\"0.89\"}, {\"asset_id\":\"69697746896130839564035629862476347944307040470122503199396727085502753297492\", \"price\":\"0.11\", \"size\":\"481.4\", \"side\":\"BUY\", \"hash\":\"9b0929ea39b18339d8eebd8f4e6371062d509250\", \"best_bid\":\"0.11\", \"best_ask\":\"0.12\"}], \"timestamp\":\"1785126798630\", \"event_type\":\"price_change\"}","received_at":"2026-07-27T04:33:18.575458Z","schema_version":"clob-market-ws.price_change.v1","sequence":null,"server_hash":null,"server_timestamp":"1785126798630","session_id":"e9443c7415a0419799bee9cfbb1a9e4d","source":"clob_market_ws"},"received_at":"2026-07-27T04:33:18.575458Z","record_id":"18bbae4ff3554ed1d646bc31ac21b2a500319eae3e16f7b32123d74080a4998f","schema_fingerprint":"4aa3821a28b0b7c2400bc59aba4bcc0a76e971dadd19610d3ad38c768e124dc7","schema_version":"edge-lab-recorder.raw.v1","sequence":null,"source":"clob_market_ws"}
{"event_at":"2026-07-27T04:33:18.650000Z","event_fingerprint":"9323856c5779845d8e6fc21ab6ff60c054d9a77defebd2b9ab987ffeb927cf1f","payload":{"connection_id":"0f4979d6978d463e9660b042fdcf555f","event_at":"2026-07-27T04:33:18.650000Z","event_type":"price_change","frame_hash":"b819cc24ba7924f8b51bd4e796d70f662d1450b234cddeb794800fd707b13dc6","frame_index":0,"kind":"data","monotonic_ns":228781866114625,"payload":{"event_type":"price_change","market":"0xeb66215f2e9faa6449e30a02bab5b8ed7b79a38bf961f6b24d0073c9c2419250","price_changes":[{"asset_id":"60386828328910021732068595344565885737045900010034836345809386672230885527307","best_ask":"0.89","best_bid":"0.88","hash":"4af89db1975d694ab0647a6cd256a46376990dd3","price":"0.01","side":"BUY","size":"7708.02"},{"asset_id":"69697746896130839564035629862476347944307040470122503199396727085502753297492","best_ask":"0.12","best_bid":"0.11","hash":"9d0402af57c97488d2f14dcfaa673b5b0a3021b2","price":"0.99","side":"SELL","size":"7708.02"}],"timestamp":"1785126798650"},"payload_hash":"921c8c25894b4de64f64b059c7b73bb0d769e60d939e63df378367c8864c3822","raw_frame":"{\"market\":\"0xeb66215f2e9faa6449e30a02bab5b8ed7b79a38bf961f6b24d0073c9c2419250\", \"price_changes\":[{\"asset_id\":\"60386828328910021732068595344565885737045900010034836345809386672230885527307\", \"price\":\"0.01\", \"size\":\"7708.02\", \"side\":\"BUY\", \"hash\":\"4af89db1975d694ab0647a6cd256a46376990dd3\", \"best_bid\":\"0.88\", \"best_ask\":\"0.89\"}, {\"asset_id\":\"69697746896130839564035629862476347944307040470122503199396727085502753297492\", \"price\":\"0.99\", \"size\":\"7708.02\", \"side\":\"SELL\", \"hash\":\"9d0402af57c97488d2f14dcfaa673b5b0a3021b2\", \"best_bid\":\"0.11\", \"best_ask\":\"0.12\"}], \"timestamp\":\"1785126798650\", \"event_type\":\"price_change\"}","received_at":"2026-07-27T04:33:18.597996Z","schema_version":"clob-market-ws.price_change.v1","sequence":null,"server_hash":null,"server_timestamp":"1785126798650","session_id":"e9443c7415a0419799bee9cfbb1a9e4d","source":"clob_market_ws"},"received_at":"2026-07-27T04:33:18.597996Z","record_id":"6f891203a35c0f599865dfcca91c24faf3a3c8d8298bca54b9989b49508138c7","schema_fingerprint":"4aa3821a28b0b7c2400bc59aba4bcc0a76e971dadd19610d3ad38c768e124dc7","schema_version":"edge-lab-recorder.raw.v1","sequence":null,"source":"clob_market_ws"}
{"event_at":"2026-07-27T04:33:18.674000Z","event_fingerprint":"c4a0e034e823739d49fd234e01b5130b6dc0511ac8c99036fe542a0cd1fb9127","payload":{"connection_id":"0f4979d6978d463e9660b042fdcf555f","event_at":"2026-07-27T04:33:18.674000Z","event_type":"price_change","frame_hash":"8f903c86ccc32275a5e644c10e31a5675116602ab7ecfe48f8a8df4bb31d47f1","frame_index":0,"kind":"data","monotonic_ns":228781885832250,"payload":{"event_type":"price_change","market":"0xeb66215f2e9faa6449e30a02bab5b8ed7b79a38bf961f6b24d0073c9c2419250","price_changes":[{"asset_id":"60386828328910021732068595344565885737045900010034836345809386672230885527307","best_ask":"0.89","best_bid":"0.88","hash":"77c242b13942070289b86794e49e68f9d634d1ee","price":"0.01","side":"BUY","size":"7703.02"},{"asset_id":"69697746896130839564035629862476347944307040470122503199396727085502753297492","best_ask":"0.12","best_bid":"0.11","hash":"c65774ca7b599f43adfbb3ca37e4ead4c69b46ff","price":"0.99","side":"SELL","size":"7703.02"}],"timestamp":"1785126798674"},"payload_hash":"396b1d13c1ea4098aaee30c4742e85649456a5a44687e207aa3bcaa7d3844875","raw_frame":"{\"market\":\"0xeb66215f2e9faa6449e30a02bab5b8ed7b79a38bf961f6b24d0073c9c2419250\", \"price_changes\":[{\"asset_id\":\"60386828328910021732068595344565885737045900010034836345809386672230885527307\", \"price\":\"0.01\", \"size\":\"7703.02\", \"side\":\"BUY\", \"hash\":\"77c242b13942070289b86794e49e68f9d634d1ee\", \"best_bid\":\"0.88\", \"best_ask\":\"0.89\"}, {\"asset_id\":\"69697746896130839564035629862476347944307040470122503199396727085502753297492\", \"price\":\"0.99\", \"size\":\"7703.02\", \"side\":\"SELL\", \"hash\":\"c65774ca7b599f43adfbb3ca37e4ead4c69b46ff\", \"best_bid\":\"0.11\", \"best_ask\":\"0.12\"}], \"timestamp\":\"1785126798674\", \"event_type\":\"price_change\"}","received_at":"2026-07-27T04:33:18.617715Z","schema_version":"clob-market-ws.price_change.v1","sequence":null,"server_hash":null,"server_timestamp":"1785126798674","session_id":"e9443c7415a0419799bee9cfbb1a9e4d","source":"clob_market_ws"},"received_at":"2026-07-27T04:33:18.617715Z","record_id":"1f4159682d17b72c1bd32bf1d440ddb1df05dfb3a40c0c87d33e2a5a719ee5e2","schema_fingerprint":"4aa3821a28b0b7c2400bc59aba4bcc0a76e971dadd19610d3ad38c768e124dc7","schema_version":"edge-lab-recorder.raw.v1","sequence":null,"source":"clob_market_ws"}
{"event_at":"2026-07-27T04:33:18.700000Z","event_fingerprint":"be5db083e89773648a51899133afca2a4a6a9635b88b71ba2ddb8cd0204f886d","payload":{"connection_id":"0f4979d6978d463e9660b042fdcf555f","event_at":"2026-07-27T04:33:18.700000Z","event_type":"price_change","frame_hash":"35e2d5e5acfc633d9f7e8b18f2c8e5cd51195834a27f17d082cd632b50c47b05","frame_index":0,"kind":"data","monotonic_ns":228781912946916,"payload":{"event_type":"price_change","market":"0xeb66215f2e9faa6449e30a02bab5b8ed7b79a38bf961f6b24d0073c9c2419250","price_changes":[{"asset_id":"60386828328910021732068595344565885737045900010034836345809386672230885527307","best_ask":"0.89","best_bid":"0.88","hash":"9076dca41e9bc077878bff010c1237ead662fe51","price":"0.01","side":"BUY","size":"7708.02"},{"asset_id":"69697746896130839564035629862476347944307040470122503199396727085502753297492","best_ask":"0.12","best_bid":"0.11","hash":"3dc15dbb95186f003865662770dfe0b3407b3ce7","price":"0.99","side":"SELL","size":"7708.02"}],"timestamp":"1785126798700"},"payload_hash":"4b348dd8ee2c11aa76d3bb55962456ea2bd6e920905f8556c7c7663117f97971","raw_frame":"{\"market\":\"0xeb66215f2e9faa6449e30a02bab5b8ed7b79a38bf961f6b24d0073c9c2419250\", \"price_changes\":[{\"asset_id\":\"60386828328910021732068595344565885737045900010034836345809386672230885527307\", \"price\":\"0.01\", \"size\":\"7708.02\", \"side\":\"BUY\", \"hash\":\"9076dca41e9bc077878bff010c1237ead662fe51\", \"best_bid\":\"0.88\", \"best_ask\":\"0.89\"}, {\"asset_id\":\"69697746896130839564035629862476347944307040470122503199396727085502753297492\", \"price\":\"0.99\", \"size\":\"7708.02\", \"side\":\"SELL\", \"hash\":\"3dc15dbb95186f003865662770dfe0b3407b3ce7\", \"best_bid\":\"0.11\", \"best_ask\":\"0.12\"}], \"timestamp\":\"1785126798700\", \"event_type\":\"price_change\"}","received_at":"2026-07-27T04:33:18.644829Z","schema_version":"clob-market-ws.price_change.v1","sequence":null,"server_hash":null,"server_timestamp":"1785126798700","session_id":"e9443c7415a0419799bee9cfbb1a9e4d","source":"clob_market_ws"},"received_at":"2026-07-27T04:33:18.644829Z","record_id":"b3978deebc9db0b3d43a8249d833184d7689c6296da4d21801d87f403a74db96","schema_fingerprint":"4aa3821a28b0b7c2400bc59aba4bcc0a76e971dadd19610d3ad38c768e124dc7","schema_version":"edge-lab-recorder.raw.v1","sequence":null,"source":"clob_market_ws"}
{"event_at":"2026-07-27T04:33:18.713000Z","event_fingerprint":"1000c64a493f3719eba8cdc764baba1c0165c6bf8268d971c51d550489908a60","payload":{"connection_id":"0f4979d6978d463e9660b042fdcf555f","event_at":"2026-07-27T04:33:18.713000Z","event_type":"price_change","frame_hash":"7d7d3dd819ce257e383da20c23bd7ed68c7366d1cda1b1e4b758c49c690a6965","frame_index":0,"kind":"data","monotonic_ns":228781931683750,"payload":{"event_type":"price_change","market":"0xeb66215f2e9faa6449e30a02bab5b8ed7b79a38bf961f6b24d0073c9c2419250","price_changes":[{"asset_id":"60386828328910021732068595344565885737045900010034836345809386672230885527307","best_ask":"0.89","best_bid":"0.88","hash":"c9372ba5c5d4eae5fde0d8316738d581edad474b","price":"0.67","side":"BUY","size":"19.6"},{"asset_id":"69697746896130839564035629862476347944307040470122503199396727085502753297492","best_ask":"0.12","best_bid":"0.11","hash":"57a626322df9f0db414c67a72162b9badc693acd","price":"0.33","side":"SELL","size":"19.6"}],"timestamp":"1785126798713"},"payload_hash":"6f313d47f3f859486a2e61090277f40115a790d9b5b2040cc946ff39f5165b3c","raw_frame":"{\"market\":\"0xeb66215f2e9faa6449e30a02bab5b8ed7b79a38bf961f6b24d0073c9c2419250\", \"price_changes\":[{\"asset_id\":\"60386828328910021732068595344565885737045900010034836345809386672230885527307\", \"price\":\"0.67\", \"size\":\"19.6\", \"side\":\"BUY\", \"hash\":\"c9372ba5c5d4eae5fde0d8316738d581edad474b\", \"best_bid\":\"0.88\", \"best_ask\":\"0.89\"}, {\"asset_id\":\"69697746896130839564035629862476347944307040470122503199396727085502753297492\", \"price\":\"0.33\", \"size\":\"19.6\", \"side\":\"SELL\", \"hash\":\"57a626322df9f0db414c67a72162b9badc693acd\", \"best_bid\":\"0.11\", \"best_ask\":\"0.12\"}], \"timestamp\":\"1785126798713\", \"event_type\":\"price_change\"}","received_at":"2026-07-27T04:33:18.663561Z","schema_version":"clob-market-ws.price_change.v1","sequence":null,"server_hash":null,"server_timestamp":"1785126798713","session_id":"e9443c7415a0419799bee9cfbb1a9e4d","source":"clob_market_ws"},"received_at":"2026-07-27T04:33:18.663561Z","record_id":"1bd31b3671c1f95c8ffa7b9f2a53acd3fdf72f08d10cb24e116b5ae6506d12ad","schema_fingerprint":"4aa3821a28b0b7c2400bc59aba4bcc0a76e971dadd19610d3ad38c768e124dc7","schema_version":"edge-lab-recorder.raw.v1","sequence":null,"source":"clob_market_ws"}
{"event_at":"2026-07-27T04:33:18.746000Z","event_fingerprint":"7941d98dc32d48f180bfdb4dde545d49ca5ec70b41383d24aaea2c76dfd7bb35","payload":{"connection_id":"0f4979d6978d463e9660b042fdcf555f","event_at":"2026-07-27T04:33:18.746000Z","event_type":"price_change","frame_hash":"1ff317614a1a03964b76d4175aee84e0700ddad6ef37b30a726d200e27c8280a","frame_index":0,"kind":"data","monotonic_ns":228781958457666,"payload":{"event_type":"price_change","market":"0xeb66215f2e9faa6449e30a02bab5b8ed7b79a38bf961f6b24d0073c9c2419250","price_changes":[{"asset_id":"60386828328910021732068595344565885737045900010034836345809386672230885527307","best_ask":"0.89","best_bid":"0.88","hash":"f745d34c681e213b6030924255629a6254ad6c81","price":"0.89","side":"SELL","size":"486.44"},{"asset_id":"69697746896130839564035629862476347944307040470122503199396727085502753297492","best_ask":"0.12","best_bid":"0.11","hash":"0203220db72190e0ac859492cf15bd3c29a10daf","price":"0.11","side":"BUY","size":"486.44"}],"timestamp":"1785126798746"},"payload_hash":"3a4308d416405ef4adeb0aa4aac06c4c7e77b805db36a08ff88eb17ac66f740a","raw_frame":"{\"market\":\"0xeb66215f2e9faa6449e30a02bab5b8ed7b79a38bf961f6b24d0073c9c2419250\", \"price_changes\":[{\"asset_id\":\"60386828328910021732068595344565885737045900010034836345809386672230885527307\", \"price\":\"0.89\", \"size\":\"486.44\", \"side\":\"SELL\", \"hash\":\"f745d34c681e213b6030924255629a6254ad6c81\", \"best_bid\":\"0.88\", \"best_ask\":\"0.89\"}, {\"asset_id\":\"69697746896130839564035629862476347944307040470122503199396727085502753297492\", \"price\":\"0.11\", \"size\":\"486.44\", \"side\":\"BUY\", \"hash\":\"0203220db72190e0ac859492cf15bd3c29a10daf\", \"best_bid\":\"0.11\", \"best_ask\":\"0.12\"}], \"timestamp\":\"1785126798746\", \"event_type\":\"price_change\"}","received_at":"2026-07-27T04:33:18.690335Z","schema_version":"clob-market-ws.price_change.v1","sequence":null,"server_hash":null,"server_timestamp":"1785126798746","session_id":"e9443c7415a0419799bee9cfbb1a9e4d","source":"clob_market_ws"},"received_at":"2026-07-27T04:33:18.690335Z","record_id":"9ed864bd604802965188ec9c9bbc566db882ef9646375af251faac94356a0087","schema_fingerprint":"4aa3821a28b0b7c2400bc59aba4bcc0a76e971dadd19610d3ad38c768e124dc7","schema_version":"edge-lab-recorder.raw.v1","sequence":null,"source":"clob_market_ws"}
{"event_at":"2026-07-27T04:33:18.770000Z","event_fingerprint":"9146e18a2b39fe0d118ce85b71d6a137a0b22715fc9bf0bfb3262802f5bc4e22","payload":{"connection_id":"0f4979d6978d463e9660b042fdcf555f","event_at":"2026-07-27T04:33:18.770000Z","event_type":"price_change","frame_hash":"b31b90dbc38cb3ef8faec501eb125e426cb545a3f9e687b5d448e895417ad975","frame_index":0,"kind":"data","monotonic_ns":228781985126500,"payload":{"event_type":"price_change","market":"0xeb66215f2e9faa6449e30a02bab5b8ed7b79a38bf961f6b24d0073c9c2419250","price_changes":[{"asset_id":"60386828328910021732068595344565885737045900010034836345809386672230885527307","best_ask":"0.89","best_bid":"0.88","hash":"8a4dacc300f95180737ef93efdbeda2821cba28b","price":"0.8","side":"BUY","size":"19"},{"asset_id":"69697746896130839564035629862476347944307040470122503199396727085502753297492","best_ask":"0.12","best_bid":"0.11","hash":"2e640b4004eb8f3758e26107ae5bc229acb82f65","price":"0.2","side":"SELL","size":"19"}],"timestamp":"1785126798770"},"payload_hash":"2e023d144599984005b27c77acb88aa8f4c7cc17573ed660cf1576d38db41aa2","raw_frame":"{\"market\":\"0xeb66215f2e9faa6449e30a02bab5b8ed7b79a38bf961f6b24d0073c9c2419250\", \"price_changes\":[{\"asset_id\":\"60386828328910021732068595344565885737045900010034836345809386672230885527307\", \"price\":\"0.8\", \"size\":\"19\", \"side\":\"BUY\", \"hash\":\"8a4dacc300f95180737ef93efdbeda2821cba28b\", \"best_bid\":\"0.88\", \"best_ask\":\"0.89\"}, {\"asset_id\":\"69697746896130839564035629862476347944307040470122503199396727085502753297492\", \"price\":\"0.2\", \"size\":\"19\", \"side\":\"SELL\", \"hash\":\"2e640b4004eb8f3758e26107ae5bc229acb82f65\", \"best_bid\":\"0.11\", \"best_ask\":\"0.12\"}], \"timestamp\":\"1785126798770\", \"event_type\":\"price_change\"}","received_at":"2026-07-27T04:33:18.717010Z","schema_version":"clob-market-ws.price_change.v1","sequence":null,"server_hash":null,"server_timestamp":"1785126798770","session_id":"e9443c7415a0419799bee9cfbb1a9e4d","source":"clob_market_ws"},"received_at":"2026-07-27T04:33:18.717010Z","record_id":"948cd9caefc9bdde665ef6fafbba3ab5aaaa108eb6051eeb200ec803092fe539","schema_fingerprint":"4aa3821a28b0b7c2400bc59aba4bcc0a76e971dadd19610d3ad38c768e124dc7","schema_version":"edge-lab-recorder.raw.v1","sequence":null,"source":"clob_market_ws"}
{"event_at":"2026-07-27T04:33:18.772000Z","event_fingerprint":"c84be65b32a21bd896bf0676bae3e5d2205c91698a8ede6ff874bc49c2f5dc5d","payload":{"connection_id":"0f4979d6978d463e9660b042fdcf555f","event_at":"2026-07-27T04:33:18.772000Z","event_type":"price_change","frame_hash":"4fdcee82e60aa1c3ab5e9374d794c02c13a492a5cf32b466986de451d4f072f3","frame_index":0,"kind":"data","monotonic_ns":228781986778458,"payload":{"event_type":"price_change","market":"0xeb66215f2e9faa6449e30a02bab5b8ed7b79a38bf961f6b24d0073c9c2419250","price_changes":[{"asset_id":"60386828328910021732068595344565885737045900010034836345809386672230885527307","best_ask":"0.89","best_bid":"0.88","hash":"785be1f6c6de21a79274bb07e810309931348e40","price":"0.01","side":"BUY","size":"7703.02"},{"asset_id":"69697746896130839564035629862476347944307040470122503199396727085502753297492","best_ask":"0.12","best_bid":"0.11","hash":"00ddac50bb5c4321c842101d91c7c02b94272f28","price":"0.99","side":"SELL","size":"7703.02"}],"timestamp":"1785126798772"},"payload_hash":"78e8cb9c582edcfa8331607e58ed54772eeb6066c184e3e116484b905cc75580","raw_frame":"{\"market\":\"0xeb66215f2e9faa6449e30a02bab5b8ed7b79a38bf961f6b24d0073c9c2419250\", \"price_changes\":[{\"asset_id\":\"60386828328910021732068595344565885737045900010034836345809386672230885527307\", \"price\":\"0.01\", \"size\":\"7703.02\", \"side\":\"BUY\", \"hash\":\"785be1f6c6de21a79274bb07e810309931348e40\", \"best_bid\":\"0.88\", \"best_ask\":\"0.89\"}, {\"asset_id\":\"69697746896130839564035629862476347944307040470122503199396727085502753297492\", \"price\":\"0.99\", \"size\":\"7703.02\", \"side\":\"SELL\", \"hash\":\"00ddac50bb5c4321c842101d91c7c02b94272f28\", \"best_bid\":\"0.11\", \"best_ask\":\"0.12\"}], \"timestamp\":\"1785126798772\", \"event_type\":\"price_change\"}","received_at":"2026-07-27T04:33:18.718664Z","schema_version":"clob-market-ws.price_change.v1","sequence":null,"server_hash":null,"server_timestamp":"1785126798772","session_id":"e9443c7415a0419799bee9cfbb1a9e4d","source":"clob_market_ws"},"received_at":"2026-07-27T04:33:18.718664Z","record_id":"b8ca37e3e1d34177b23cd98f6a1c5ad6b02eed51e4a154255909450ed0504188","schema_fingerprint":"4aa3821a28b0b7c2400bc59aba4bcc0a76e971dadd19610d3ad38c768e124dc7","schema_version":"edge-lab-recorder.raw.v1","sequence":null,"source":"clob_market_ws"}
{"event_at":"2026-07-27T04:33:18.796000Z","event_fingerprint":"448b76a9665258996baacea0aaa7f511b3783f2056b566ac92be480168d73e6f","payload":{"connection_id":"0f4979d6978d463e9660b042fdcf555f","event_at":"2026-07-27T04:33:18.796000Z","event_type":"price_change","frame_hash":"34bb5cf4de9042cd72c1492d1d3eb81b5f7d5d3d1469c250e3c9ac67679a031d","frame_index":0,"kind":"data","monotonic_ns":228782009079458,"payload":{"event_type":"price_change","market":"0xeb66215f2e9faa6449e30a02bab5b8ed7b79a38bf961f6b24d0073c9c2419250","price_changes":[{"asset_id":"60386828328910021732068595344565885737045900010034836345809386672230885527307","best_ask":"0.89","best_bid":"0.88","hash":"e9619651ca68a8168ffcc6bf49ffe31d41db3e0f","price":"0.01","side":"BUY","size":"7708.02"},{"asset_id":"69697746896130839564035629862476347944307040470122503199396727085502753297492","best_ask":"0.12","best_bid":"0.11","hash":"78aa2db8029c96a5df7e838b774c40cd9cae1dde","price":"0.99","side":"SELL","size":"7708.02"}],"timestamp":"1785126798796"},"payload_hash":"84353122b37310ea6d94e2bfa64dfd0a4a9dfb8e940847cc960474936d042dea","raw_frame":"{\"market\":\"0xeb66215f2e9faa6449e30a02bab5b8ed7b79a38bf961f6b24d0073c9c2419250\", \"price_changes\":[{\"asset_id\":\"60386828328910021732068595344565885737045900010034836345809386672230885527307\", \"price\":\"0.01\", \"size\":\"7708.02\", \"side\":\"BUY\", \"hash\":\"e9619651ca68a8168ffcc6bf49ffe31d41db3e0f\", \"best_bid\":\"0.88\", \"best_ask\":\"0.89\"}, {\"asset_id\":\"69697746896130839564035629862476347944307040470122503199396727085502753297492\", \"price\":\"0.99\", \"size\":\"7708.02\", \"side\":\"SELL\", \"hash\":\"78aa2db8029c96a5df7e838b774c40cd9cae1dde\", \"best_bid\":\"0.11\", \"best_ask\":\"0.12\"}], \"timestamp\":\"1785126798796\", \"event_type\":\"price_change\"}","received_at":"2026-07-27T04:33:18.740962Z","schema_version":"clob-market-ws.price_change.v1","sequence":null,"server_hash":null,"server_timestamp":"1785126798796","session_id":"e9443c7415a0419799bee9cfbb1a9e4d","source":"clob_market_ws"},"received_at":"2026-07-27T04:33:18.740962Z","record_id":"bf06657a84c03ea74528e84bea48ae178311a969cecb919dc3693e02cdf5235c","schema_fingerprint":"4aa3821a28b0b7c2400bc59aba4bcc0a76e971dadd19610d3ad38c768e124dc7","schema_version":"edge-lab-recorder.raw.v1","sequence":null,"source":"clob_market_ws"}
{"event_at":"2026-07-27T04:33:18.825000Z","event_fingerprint":"e6d18efa6dbae33a21073703daeb19a668005a080d44b178728e5f1ffc7333c7","payload":{"connection_id":"0f4979d6978d463e9660b042fdcf555f","event_at":"2026-07-27T04:33:18.825000Z","event_type":"price_change","frame_hash":"d935f0a9f67a45a6ca047737055e5174f15ce87f0b69f0286cbb114531ecf3fb","frame_index":0,"kind":"data","monotonic_ns":228782036925791,"payload":{"event_type":"price_change","market":"0xeb66215f2e9faa6449e30a02bab5b8ed7b79a38bf961f6b24d0073c9c2419250","price_changes":[{"asset_id":"60386828328910021732068595344565885737045900010034836345809386672230885527307","best_ask":"0.89","best_bid":"0.88","hash":"94cc7000f65fc8e246e273cd176499bdba40aa8f","price":"0.01","side":"BUY","size":"7703.02"},{"asset_id":"69697746896130839564035629862476347944307040470122503199396727085502753297492","best_ask":"0.12","best_bid":"0.11","hash":"16d3561ca4b2dfb9d838c9085002d8b926f8afe7","price":"0.99","side":"SELL","size":"7703.02"}],"timestamp":"1785126798825"},"payload_hash":"8e02c9010104c7eae831e55cc346bd50e84c26807ec3e329a1bb257a3f388cb5","raw_frame":"{\"market\":\"0xeb66215f2e9faa6449e30a02bab5b8ed7b79a38bf961f6b24d0073c9c2419250\", \"price_changes\":[{\"asset_id\":\"60386828328910021732068595344565885737045900010034836345809386672230885527307\", \"price\":\"0.01\", \"size\":\"7703.02\", \"side\":\"BUY\", \"hash\":\"94cc7000f65fc8e246e273cd176499bdba40aa8f\", \"best_bid\":\"0.88\", \"best_ask\":\"0.89\"}, {\"asset_id\":\"69697746896130839564035629862476347944307040470122503199396727085502753297492\", \"price\":\"0.99\", \"size\":\"7703.02\", \"side\":\"SELL\", \"hash\":\"16d3561ca4b2dfb9d838c9085002d8b926f8afe7\", \"best_bid\":\"0.11\", \"best_ask\":\"0.12\"}], \"timestamp\":\"1785126798825\", \"event_type\":\"price_change\"}","received_at":"2026-07-27T04:33:18.768796Z","schema_version":"clob-market-ws.price_change.v1","sequence":null,"server_hash":null,"server_timestamp":"1785126798825","session_id":"e9443c7415a0419799bee9cfbb1a9e4d","source":"clob_market_ws"},"received_at":"2026-07-27T04:33:18.768796Z","record_id":"b28f3d8c2e43c33529675f71322a6f2c48ac8544979eae0981b6d364c144351d","schema_fingerprint":"4aa3821a28b0b7c2400bc59aba4bcc0a76e971dadd19610d3ad38c768e124dc7","schema_version":"edge-lab-recorder.raw.v1","sequence":null,"source":"clob_market_ws"}
{"event_at":"2026-07-27T04:33:18.834000Z","event_fingerprint":"c51165ca4dfa51b65ab6873bddba52374166ae6aafcb32a376a671eebec4c011","payload":{"connection_id":"0f4979d6978d463e9660b042fdcf555f","event_at":"2026-07-27T04:33:18.834000Z","event_type":"price_change","frame_hash":"f6b6b2efdd34b6ab865c21b616c1c70f35021aec52ce34cf72403991e17734f7","frame_index":0,"kind":"data","monotonic_ns":228782046676250,"payload":{"event_type":"price_change","market":"0xeb66215f2e9faa6449e30a02bab5b8ed7b79a38bf961f6b24d0073c9c2419250","price_changes":[{"asset_id":"60386828328910021732068595344565885737045900010034836345809386672230885527307","best_ask":"0.89","best_bid":"0.88","hash":"ff4b83f2197fb29459df06351e1d8daa785fcc9d","price":"0.89","side":"SELL","size":"481.4"},{"asset_id":"69697746896130839564035629862476347944307040470122503199396727085502753297492","best_ask":"0.12","best_bid":"0.11","hash":"b2669ee68d2f472eee7933a7140bcdca6630d0a3","price":"0.11","side":"BUY","size":"481.4"}],"timestamp":"1785126798834"},"payload_hash":"33ed1683b9946bf89da631af4afca98cbd6a205700f17b5c8986bfa7a46dd710","raw_frame":"{\"market\":\"0xeb66215f2e9faa6449e30a02bab5b8ed7b79a38bf961f6b24d0073c9c2419250\", \"price_changes\":[{\"asset_id\":\"60386828328910021732068595344565885737045900010034836345809386672230885527307\", \"price\":\"0.89\", \"size\":\"481.4\", \"side\":\"SELL\", \"hash\":\"ff4b83f2197fb29459df06351e1d8daa785fcc9d\", \"best_bid\":\"0.88\", \"best_ask\":\"0.89\"}, {\"asset_id\":\"69697746896130839564035629862476347944307040470122503199396727085502753297492\", \"price\":\"0.11\", \"size\":\"481.4\", \"side\":\"BUY\", \"hash\":\"b2669ee68d2f472eee7933a7140bcdca6630d0a3\", \"best_bid\":\"0.11\", \"best_ask\":\"0.12\"}], \"timestamp\":\"1785126798834\", \"event_type\":\"price_change\"}","received_at":"2026-07-27T04:33:18.778565Z","schema_version":"clob-market-ws.price_change.v1","sequence":null,"server_hash":null,"server_timestamp":"1785126798834","session_id":"e9443c7415a0419799bee9cfbb1a9e4d","source":"clob_market_ws"},"received_at":"2026-07-27T04:33:18.778565Z","record_id":"6821031bb750533316a9a856d942a4385d5b511f32a898dc9e135a9768755964","schema_fingerprint":"4aa3821a28b0b7c2400bc59aba4bcc0a76e971dadd19610d3ad38c768e124dc7","schema_version":"edge-lab-recorder.raw.v1","sequence":null,"source":"clob_market_ws"}
{"event_at":"2026-07-27T04:33:18.851000Z","event_fingerprint":"16791de52e886b499a775705923045eb9d4b0658c6f88f8aea71ee0a2c425751","payload":{"connection_id":"0f4979d6978d463e9660b042fdcf555f","event_at":"2026-07-27T04:33:18.851000Z","event_type":"price_change","frame_hash":"52432aaf3fe875696839fcb35bd6ff7eaf1ebc248970b64957020dc036037b23","frame_index":0,"kind":"data","monotonic_ns":228782063394916,"payload":{"event_type":"price_change","market":"0xeb66215f2e9faa6449e30a02bab5b8ed7b79a38bf961f6b24d0073c9c2419250","price_changes":[{"asset_id":"60386828328910021732068595344565885737045900010034836345809386672230885527307","best_ask":"0.89","best_bid":"0.88","hash":"ecdf4729443f5d446c208583d73f5696fc9d9926","price":"0.04","side":"BUY","size":"633.09"},{"asset_id":"69697746896130839564035629862476347944307040470122503199396727085502753297492","best_ask":"0.12","best_bid":"0.11","hash":"f4538295f79e55e74e3cb00f059b093c4731b8f5","price":"0.96","side":"SELL","size":"633.09"}],"timestamp":"1785126798851"},"payload_hash":"9c83c8725dfd43d057c6ff464ef1a75087795a7913cd4775d041c945d5a88b96","raw_frame":"{\"market\":\"0xeb66215f2e9faa6449e30a02bab5b8ed7b79a38bf961f6b24d0073c9c2419250\", \"price_changes\":[{\"asset_id\":\"60386828328910021732068595344565885737045900010034836345809386672230885527307\", \"price\":\"0.04\", \"size\":\"633.09\", \"side\":\"BUY\", \"hash\":\"ecdf4729443f5d446c208583d73f5696fc9d9926\", \"best_bid\":\"0.88\", \"best_ask\":\"0.89\"}, {\"asset_id\":\"69697746896130839564035629862476347944307040470122503199396727085502753297492\", \"price\":\"0.96\", \"size\":\"633.09\", \"side\":\"SELL\", \"hash\":\"f4538295f79e55e74e3cb00f059b093c4731b8f5\", \"best_bid\":\"0.11\", \"best_ask\":\"0.12\"}], \"timestamp\":\"1785126798851\", \"event_type\":\"price_change\"}","received_at":"2026-07-27T04:33:18.795282Z","schema_version":"clob-market-ws.price_change.v1","sequence":null,"server_hash":null,"server_timestamp":"1785126798851","session_id":"e9443c7415a0419799bee9cfbb1a9e4d","source":"clob_market_ws"},"received_at":"2026-07-27T04:33:18.795282Z","record_id":"5ddcdbe7a22b4ba0b5912d05336138656603874cd87b249cea2ad9b43e99f8d3","schema_fingerprint":"4aa3821a28b0b7c2400bc59aba4bcc0a76e971dadd19610d3ad38c768e124dc7","schema_version":"edge-lab-recorder.raw.v1","sequence":null,"source":"clob_market_ws"}
{"event_at":"2026-07-27T04:33:18.907000Z","event_fingerprint":"061e2c24b46d9aa266d696e2417318afaf2360d0c0878ce4468d6218040f5e28","payload":{"connection_id":"0f4979d6978d463e9660b042fdcf555f","event_at":"2026-07-27T04:33:18.907000Z","event_type":"price_change","frame_hash":"3fe5bc476de62e9d044812f5f5941d454c6b062e69a278635d5617a9a833be97","frame_index":0,"kind":"data","monotonic_ns":228782119769541,"payload":{"event_type":"price_change","market":"0xeb66215f2e9faa6449e30a02bab5b8ed7b79a38bf961f6b24d0073c9c2419250","price_changes":[{"asset_id":"60386828328910021732068595344565885737045900010034836345809386672230885527307","best_ask":"0.89","best_bid":"0.88","hash":"e2883910347f1a22bd0f17fc0f3f4e2f2b916a44","price":"0.04","side":"BUY","size":"628.09"},{"asset_id":"69697746896130839564035629862476347944307040470122503199396727085502753297492","best_ask":"0.12","best_bid":"0.11","hash":"81775ad8ac2fa6db0e318c3b46f4d296b7d5781f","price":"0.96","side":"SELL","size":"628.09"}],"timestamp":"1785126798907"},"payload_hash":"ff4db803ca929c46ca368477e3aee102cec7bc41a5fbe96643651cb56d45a1a5","raw_frame":"{\"market\":\"0xeb66215f2e9faa6449e30a02bab5b8ed7b79a38bf961f6b24d0073c9c2419250\", \"price_changes\":[{\"asset_id\":\"60386828328910021732068595344565885737045900010034836345809386672230885527307\", \"price\":\"0.04\", \"size\":\"628.09\", \"side\":\"BUY\", \"hash\":\"e2883910347f1a22bd0f17fc0f3f4e2f2b916a44\", \"best_bid\":\"0.88\", \"best_ask\":\"0.89\"}, {\"asset_id\":\"69697746896130839564035629862476347944307040470122503199396727085502753297492\", \"price\":\"0.96\", \"size\":\"628.09\", \"side\":\"SELL\", \"hash\":\"81775ad8ac2fa6db0e318c3b46f4d296b7d5781f\", \"best_bid\":\"0.11\", \"best_ask\":\"0.12\"}], \"timestamp\":\"1785126798907\", \"event_type\":\"price_change\"}","received_at":"2026-07-27T04:33:18.851655Z","schema_version":"clob-market-ws.price_change.v1","sequence":null,"server_hash":null,"server_timestamp":"1785126798907","session_id":"e9443c7415a0419799bee9cfbb1a9e4d","source":"clob_market_ws"},"received_at":"2026-07-27T04:33:18.851655Z","record_id":"029daeeb88b18a4c33fe80e500caeeb7a83752355e0046465729a1acac749dcc","schema_fingerprint":"4aa3821a28b0b7c2400bc59aba4bcc0a76e971dadd19610d3ad38c768e124dc7","schema_version":"edge-lab-recorder.raw.v1","sequence":null,"source":"clob_market_ws"}
{"event_at":"2026-07-27T04:33:18.942000Z","event_fingerprint":"e440d677d899e58056043c84b582db07c1aa486907d9cbc2a1066c7acd7add48","payload":{"connection_id":"0f4979d6978d463e9660b042fdcf555f","event_at":"2026-07-27T04:33:18.942000Z","event_type":"price_change","frame_hash":"bbd0343068d91fd07991817f86c399a5b00901b1aab5cc18e6a2140f9e4dcd29","frame_index":0,"kind":"data","monotonic_ns":228782153968208,"payload":{"event_type":"price_change","market":"0xeb66215f2e9faa6449e30a02bab5b8ed7b79a38bf961f6b24d0073c9c2419250","price_changes":[{"asset_id":"60386828328910021732068595344565885737045900010034836345809386672230885527307","best_ask":"0.89","best_bid":"0.88","hash":"79a622e30edb139fe34ef53d2feceafe9027bcb8","price":"0.89","side":"SELL","size":"486.44"},{"asset_id":"69697746896130839564035629862476347944307040470122503199396727085502753297492","best_ask":"0.12","best_bid":"0.11","hash":"a45cbe6f1fec5781418fb32fb37a9e1ee9e6acb7","price":"0.11","side":"BUY","size":"486.44"}],"timestamp":"1785126798942"},"payload_hash":"0732cbf2715083b06217c443dea320ad28437490b566a50df227011985d4eae7","raw_frame":"{\"market\":\"0xeb66215f2e9faa6449e30a02bab5b8ed7b79a38bf961f6b24d0073c9c2419250\", \"price_changes\":[{\"asset_id\":\"60386828328910021732068595344565885737045900010034836345809386672230885527307\", \"price\":\"0.89\", \"size\":\"486.44\", \"side\":\"SELL\", \"hash\":\"79a622e30edb139fe34ef53d2feceafe9027bcb8\", \"best_bid\":\"0.88\", \"best_ask\":\"0.89\"}, {\"asset_id\":\"69697746896130839564035629862476347944307040470122503199396727085502753297492\", \"price\":\"0.11\", \"size\":\"486.44\", \"side\":\"BUY\", \"hash\":\"a45cbe6f1fec5781418fb32fb37a9e1ee9e6acb7\", \"best_bid\":\"0.11\", \"best_ask\":\"0.12\"}], \"timestamp\":\"1785126798942\", \"event_type\":\"price_change\"}","received_at":"2026-07-27T04:33:18.885859Z","schema_version":"clob-market-ws.price_change.v1","sequence":null,"server_hash":null,"server_timestamp":"1785126798942","session_id":"e9443c7415a0419799bee9cfbb1a9e4d","source":"clob_market_ws"},"received_at":"2026-07-27T04:33:18.885859Z","record_id":"eb3d610fcbee9f829d8a0bb129abb757a88baa472f437bbfcb0c7a0549f87b9a","schema_fingerprint":"4aa3821a28b0b7c2400bc59aba4bcc0a76e971dadd19610d3ad38c768e124dc7","schema_version":"edge-lab-recorder.raw.v1","sequence":null,"source":"clob_market_ws"}
{"event_at":"2026-07-27T04:33:18.982000Z","event_fingerprint":"b2f847ca8e2ab729f59eccde606cea296b6f5fdc6d456a64d40c4adc1ca179e4","payload":{"connection_id":"0f4979d6978d463e9660b042fdcf555f","event_at":"2026-07-27T04:33:18.982000Z","event_type":"price_change","frame_hash":"d6f55d3b6875e78e2c8dbf4f16397ad61c9e7f6e44b7ee6c2a96a0674bb5cb32","frame_index":0,"kind":"data","monotonic_ns":228782193830333,"payload":{"event_type":"price_change","market":"0xeb66215f2e9faa6449e30a02bab5b8ed7b79a38bf961f6b24d0073c9c2419250","price_changes":[{"asset_id":"60386828328910021732068595344565885737045900010034836345809386672230885527307","best_ask":"0.89","best_bid":"0.88","hash":"36a1def1e88f0733f71ebeedb7d4fa57420f7ae7","price":"0.78","side":"BUY","size":"43"},{"asset_id":"69697746896130839564035629862476347944307040470122503199396727085502753297492","best_ask":"0.12","best_bid":"0.11","hash":"9f1de5d0a04c35fdf9ae057aad70c546927e9abe","price":"0.22","side":"SELL","size":"43"}],"timestamp":"1785126798982"},"payload_hash":"ec21bcbce595516cadd6a700bbc68509164edb04892079e854eb725a52a616b1","raw_frame":"{\"market\":\"0xeb66215f2e9faa6449e30a02bab5b8ed7b79a38bf961f6b24d0073c9c2419250\", \"price_changes\":[{\"asset_id\":\"60386828328910021732068595344565885737045900010034836345809386672230885527307\", \"price\":\"0.78\", \"size\":\"43\", \"side\":\"BUY\", \"hash\":\"36a1def1e88f0733f71ebeedb7d4fa57420f7ae7\", \"best_bid\":\"0.88\", \"best_ask\":\"0.89\"}, {\"asset_id\":\"69697746896130839564035629862476347944307040470122503199396727085502753297492\", \"price\":\"0.22\", \"size\":\"43\", \"side\":\"SELL\", \"hash\":\"9f1de5d0a04c35fdf9ae057aad70c546927e9abe\", \"best_bid\":\"0.11\", \"best_ask\":\"0.12\"}], \"timestamp\":\"1785126798982\", \"event_type\":\"price_change\"}","received_at":"2026-07-27T04:33:18.925718Z","schema_version":"clob-market-ws.price_change.v1","sequence":null,"server_hash":null,"server_timestamp":"1785126798982","session_id":"e9443c7415a0419799bee9cfbb1a9e4d","source":"clob_market_ws"},"received_at":"2026-07-27T04:33:18.925718Z","record_id":"49fc316f090c1c39193010b769944ff602f7f132b5af009f3b8e56cc1308a8e9","schema_fingerprint":"4aa3821a28b0b7c2400bc59aba4bcc0a76e971dadd19610d3ad38c768e124dc7","schema_version":"edge-lab-recorder.raw.v1","sequence":null,"source":"clob_market_ws"}
{"event_at":"2026-07-27T04:33:19.010000Z","event_fingerprint":"1fd3fd09634169eb81af6545c0aac580ee76ef8a383a1207aced59bc5a88ee23","payload":{"connection_id":"0f4979d6978d463e9660b042fdcf555f","event_at":"2026-07-27T04:33:19.010000Z","event_type":"price_change","frame_hash":"6adf650b83c9f553b6a9d653c2c103409784406dc2e2789091cdb67d772b29b9","frame_index":0,"kind":"data","monotonic_ns":228782242238041,"payload":{"event_type":"price_change","market":"0xeb66215f2e9faa6449e30a02bab5b8ed7b79a38bf961f6b24d0073c9c2419250","price_changes":[{"asset_id":"60386828328910021732068595344565885737045900010034836345809386672230885527307","best_ask":"0.89","best_bid":"0.88","hash":"bf1ebbcf6143d49d41a70068360d0e4b48d43216","price":"0.01","side":"BUY","size":"7708.02"},{"asset_id":"69697746896130839564035629862476347944307040470122503199396727085502753297492","best_ask":"0.12","best_bid":"0.11","hash":"51360e9b9f65e2f0a807fc72bca9a122e7cd5369","price":"0.99","side":"SELL","size":"7708.02"}],"timestamp":"1785126799010"},"payload_hash":"e983b3ff593af5bbc7e6b9678102128c433f213cec2221e150b2204b9bbab784","raw_frame":"{\"market\":\"0xeb66215f2e9faa6449e30a02bab5b8ed7b79a38bf961f6b24d0073c9c2419250\", \"price_changes\":[{\"asset_id\":\"60386828328910021732068595344565885737045900010034836345809386672230885527307\", \"price\":\"0.01\", \"size\":\"7708.02\", \"side\":\"BUY\", \"hash\":\"bf1ebbcf6143d49d41a70068360d0e4b48d43216\", \"best_bid\":\"0.88\", \"best_ask\":\"0.89\"}, {\"asset_id\":\"69697746896130839564035629862476347944307040470122503199396727085502753297492\", \"price\":\"0.99\", \"size\":\"7708.02\", \"side\":\"SELL\", \"hash\":\"51360e9b9f65e2f0a807fc72bca9a122e7cd5369\", \"best_bid\":\"0.11\", \"best_ask\":\"0.12\"}], \"timestamp\":\"1785126799010\", \"event_type\":\"price_change\"}","received_at":"2026-07-27T04:33:18.974124Z","schema_version":"clob-market-ws.price_change.v1","sequence":null,"server_hash":null,"server_timestamp":"1785126799010","session_id":"e9443c7415a0419799bee9cfbb1a9e4d","source":"clob_market_ws"},"received_at":"2026-07-27T04:33:18.974124Z","record_id":"0d6a203e2d6072b225d9a73f67f06fa2fa28812bc3c4abb25bdbb2eec3c0a6ac","schema_fingerprint":"4aa3821a28b0b7c2400bc59aba4bcc0a76e971dadd19610d3ad38c768e124dc7","schema_version":"edge-lab-recorder.raw.v1","sequence":null,"source":"clob_market_ws"}
{"event_at":"2026-07-27T04:33:19.023000Z","event_fingerprint":"b7fc3fe236fd02a8fbcf23100014b737fa245044a666a1aca7d93e22a9613376","payload":{"connection_id":"0f4979d6978d463e9660b042fdcf555f","event_at":"2026-07-27T04:33:19.023000Z","event_type":"price_change","frame_hash":"ca23e78bfe002363049d8c2a7c56f85be9eb3fb97e77d08c55088f6133fed975","frame_index":0,"kind":"data","monotonic_ns":228782245424458,"payload":{"event_type":"price_change","market":"0xeb66215f2e9faa6449e30a02bab5b8ed7b79a38bf961f6b24d0073c9c2419250","price_changes":[{"asset_id":"69697746896130839564035629862476347944307040470122503199396727085502753297492","best_ask":"0.12","best_bid":"0.11","hash":"9f5481f989d9ecfccc893a81194bd44030f06049","price":"0.01","side":"BUY","size":"8019.91"},{"asset_id":"60386828328910021732068595344565885737045900010034836345809386672230885527307","best_ask":"0.89","best_bid":"0.88","hash":"abe7e27180b93884db274f1db6c334cf9de3315a","price":"0.99","side":"SELL","size":"8019.91"}],"timestamp":"1785126799023"},"payload_hash":"ee6dfce1483ddbd9eb2ba52b1aac014884f1d1fe1007f6bc8b4c5e63e903aa24","raw_frame":"{\"market\":\"0xeb66215f2e9faa6449e30a02bab5b8ed7b79a38bf961f6b24d0073c9c2419250\", \"price_changes\":[{\"asset_id\":\"69697746896130839564035629862476347944307040470122503199396727085502753297492\", \"price\":\"0.01\", \"size\":\"8019.91\", \"side\":\"BUY\", \"hash\":\"9f5481f989d9ecfccc893a81194bd44030f06049\", \"best_bid\":\"0.11\", \"best_ask\":\"0.12\"}, {\"asset_id\":\"60386828328910021732068595344565885737045900010034836345809386672230885527307\", \"price\":\"0.99\", \"size\":\"8019.91\", \"side\":\"SELL\", \"hash\":\"abe7e27180b93884db274f1db6c334cf9de3315a\", \"best_bid\":\"0.88\", \"best_ask\":\"0.89\"}], \"timestamp\":\"1785126799023\", \"event_type\":\"price_change\"}","received_at":"2026-07-27T04:33:18.977311Z","schema_version":"clob-market-ws.price_change.v1","sequence":null,"server_hash":null,"server_timestamp":"1785126799023","session_id":"e9443c7415a0419799bee9cfbb1a9e4d","source":"clob_market_ws"},"received_at":"2026-07-27T04:33:18.977311Z","record_id":"eedae79ae3f18ef6a5ab64446c89871fb6ac7caf39e41f6c7b24c50e2ff95818","schema_fingerprint":"4aa3821a28b0b7c2400bc59aba4bcc0a76e971dadd19610d3ad38c768e124dc7","schema_version":"edge-lab-recorder.raw.v1","sequence":null,"source":"clob_market_ws"}
{"event_at":"2026-07-27T04:33:19.027000Z","event_fingerprint":"dadc6a333f2ae14087aae9f19bbdb36536c9e01f53ad8b71a0be313e89eedfc9","payload":{"connection_id":"0f4979d6978d463e9660b042fdcf555f","event_at":"2026-07-27T04:33:19.027000Z","event_type":"price_change","frame_hash":"5ed351158efcb14a7420aacadcac846f222ee2e91fd3e0436029976a7afbd543","frame_index":0,"kind":"data","monotonic_ns":228782249855125,"payload":{"event_type":"price_change","market":"0xeb66215f2e9faa6449e30a02bab5b8ed7b79a38bf961f6b24d0073c9c2419250","price_changes":[{"asset_id":"69697746896130839564035629862476347944307040470122503199396727085502753297492","best_ask":"0.12","best_bid":"0.11","hash":"b246258ea405efa6d9d15d8c473a9926501425dc","price":"0.01","side":"BUY","size":"8024.91"},{"asset_id":"60386828328910021732068595344565885737045900010034836345809386672230885527307","best_ask":"0.89","best_bid":"0.88","hash":"d8fd6c9b2e81ccdf3e4a1a17a956e95d2f423985","price":"0.99","side":"SELL","size":"8024.91"}],"timestamp":"1785126799027"},"payload_hash":"21ad2b2793d3ef1d5a9dfa83c6e305d2eea854c881348f27df3f35a5dfd1c07b","raw_frame":"{\"market\":\"0xeb66215f2e9faa6449e30a02bab5b8ed7b79a38bf961f6b24d0073c9c2419250\", \"price_changes\":[{\"asset_id\":\"69697746896130839564035629862476347944307040470122503199396727085502753297492\", \"price\":\"0.01\", \"size\":\"8024.91\", \"side\":\"BUY\", \"hash\":\"b246258ea405efa6d9d15d8c473a9926501425dc\", \"best_bid\":\"0.11\", \"best_ask\":\"0.12\"}, {\"asset_id\":\"60386828328910021732068595344565885737045900010034836345809386672230885527307\", \"price\":\"0.99\", \"size\":\"8024.91\", \"side\":\"SELL\", \"hash\":\"d8fd6c9b2e81ccdf3e4a1a17a956e95d2f423985\", \"best_bid\":\"0.88\", \"best_ask\":\"0.89\"}], \"timestamp\":\"1785126799027\", \"event_type\":\"price_change\"}","received_at":"2026-07-27T04:33:18.981745Z","schema_version":"clob-market-ws.price_change.v1","sequence":null,"server_hash":null,"server_timestamp":"1785126799027","session_id":"e9443c7415a0419799bee9cfbb1a9e4d","source":"clob_market_ws"},"received_at":"2026-07-27T04:33:18.981745Z","record_id":"2c008c01ffc463a8002b824246a4a4b66de5052867711bcedf1d72b59dd45896","schema_fingerprint":"4aa3821a28b0b7c2400bc59aba4bcc0a76e971dadd19610d3ad38c768e124dc7","schema_version":"edge-lab-recorder.raw.v1","sequence":null,"source":"clob_market_ws"}
{"event_at":"2026-07-27T04:33:19.033000Z","event_fingerprint":"f3df68b37c883070ede4bb05d4fcb5ba3258b3ccd0c68ab5864b3280d298b85d","payload":{"connection_id":"0f4979d6978d463e9660b042fdcf555f","event_at":"2026-07-27T04:33:19.033000Z","event_type":"price_change","frame_hash":"472da38b0e935b93728eea79e2c30e5f01848fc7435ac5a6b31adf7ae6d7e478","frame_index":0,"kind":"data","monotonic_ns":228782252502083,"payload":{"event_type":"price_change","market":"0xeb66215f2e9faa6449e30a02bab5b8ed7b79a38bf961f6b24d0073c9c2419250","price_changes":[{"asset_id":"60386828328910021732068595344565885737045900010034836345809386672230885527307","best_ask":"0.89","best_bid":"0.88","hash":"3647c3abb0535ddb229aaa8d798a017a64b26ee6","price":"0.89","side":"SELL","size":"481.4"},{"asset_id":"69697746896130839564035629862476347944307040470122503199396727085502753297492","best_ask":"0.12","best_bid":"0.11","hash":"e0f39aeffb55bc46cb50d01aa95c5a5fc75bebae","price":"0.11","side":"BUY","size":"481.4"}],"timestamp":"1785126799033"},"payload_hash":"ad937b782b7cc0b294995dcd5191961d47ad744a28c8e21eddd11a0d724d69c2","raw_frame":"{\"market\":\"0xeb66215f2e9faa6449e30a02bab5b8ed7b79a38bf961f6b24d0073c9c2419250\", \"price_changes\":[{\"asset_id\":\"60386828328910021732068595344565885737045900010034836345809386672230885527307\", \"price\":\"0.89\", \"size\":\"481.4\", \"side\":\"SELL\", \"hash\":\"3647c3abb0535ddb229aaa8d798a017a64b26ee6\", \"best_bid\":\"0.88\", \"best_ask\":\"0.89\"}, {\"asset_id\":\"69697746896130839564035629862476347944307040470122503199396727085502753297492\", \"price\":\"0.11\", \"size\":\"481.4\", \"side\":\"BUY\", \"hash\":\"e0f39aeffb55bc46cb50d01aa95c5a5fc75bebae\", \"best_bid\":\"0.11\", \"best_ask\":\"0.12\"}], \"timestamp\":\"1785126799033\", \"event_type\":\"price_change\"}","received_at":"2026-07-27T04:33:18.984391Z","schema_version":"clob-market-ws.price_change.v1","sequence":null,"server_hash":null,"server_timestamp":"1785126799033","session_id":"e9443c7415a0419799bee9cfbb1a9e4d","source":"clob_market_ws"},"received_at":"2026-07-27T04:33:18.984391Z","record_id":"04fe487a9e30c9ff50d1c39388e18b90f2003434495f4235b583f7253580a14f","schema_fingerprint":"4aa3821a28b0b7c2400bc59aba4bcc0a76e971dadd19610d3ad38c768e124dc7","schema_version":"edge-lab-recorder.raw.v1","sequence":null,"source":"clob_market_ws"}
{"event_at":"2026-07-27T04:33:19.048000Z","event_fingerprint":"f8ba0bbc715c17df67dab4cce875d38b17fed1cdace4bbb55a05ce498d465c17","payload":{"connection_id":"0f4979d6978d463e9660b042fdcf555f","event_at":"2026-07-27T04:33:19.048000Z","event_type":"price_change","frame_hash":"44315885c0b6dbecf1ee49856e3936b23c0ddaf6ffc58815abaacdc5138e903a","frame_index":0,"kind":"data","monotonic_ns":228782261553541,"payload":{"event_type":"price_change","market":"0xeb66215f2e9faa6449e30a02bab5b8ed7b79a38bf961f6b24d0073c9c2419250","price_changes":[{"asset_id":"69697746896130839564035629862476347944307040470122503199396727085502753297492","best_ask":"0.12","best_bid":"0.11","hash":"7e37d52f34c351552df23da3f6169110759a0e32","price":"0.01","side":"BUY","size":"8019.91"},{"asset_id":"60386828328910021732068595344565885737045900010034836345809386672230885527307","best_ask":"0.89","best_bid":"0.88","hash":"c8dfb9083600a497656f16cdd7f133e163ed8f00","price":"0.99","side":"SELL","size":"8019.91"}],"timestamp":"1785126799048"},"payload_hash":"0fd5784566ce393ab84ab853fa5360b70842e7f49bb5e4d175cf77802dfd87d6","raw_frame":"{\"market\":\"0xeb66215f2e9faa6449e30a02bab5b8ed7b79a38bf961f6b24d0073c9c2419250\", \"price_changes\":[{\"asset_id\":\"69697746896130839564035629862476347944307040470122503199396727085502753297492\", \"price\":\"0.01\", \"size\":\"8019.91\", \"side\":\"BUY\", \"hash\":\"7e37d52f34c351552df23da3f6169110759a0e32\", \"best_bid\":\"0.11\", \"best_ask\":\"0.12\"}, {\"asset_id\":\"60386828328910021732068595344565885737045900010034836345809386672230885527307\", \"price\":\"0.99\", \"size\":\"8019.91\", \"side\":\"SELL\", \"hash\":\"c8dfb9083600a497656f16cdd7f133e163ed8f00\", \"best_bid\":\"0.88\", \"best_ask\":\"0.89\"}], \"timestamp\":\"1785126799048\", \"event_type\":\"price_change\"}","received_at":"2026-07-27T04:33:18.993441Z","schema_version":"clob-market-ws.price_change.v1","sequence":null,"server_hash":null,"server_timestamp":"1785126799048","session_id":"e9443c7415a0419799bee9cfbb1a9e4d","source":"clob_market_ws"},"received_at":"2026-07-27T04:33:18.993441Z","record_id":"347e0f2877d2360e802f605c223f2e690a91af827477fb012fa05c0af36bd04b","schema_fingerprint":"4aa3821a28b0b7c2400bc59aba4bcc0a76e971dadd19610d3ad38c768e124dc7","schema_version":"edge-lab-recorder.raw.v1","sequence":null,"source":"clob_market_ws"}
{"event_at":"2026-07-27T04:33:19.050000Z","event_fingerprint":"37496511dd3d0515e28199f69c7bf99626828c62fd1a3bae6dc053d058785b48","payload":{"connection_id":"0f4979d6978d463e9660b042fdcf555f","event_at":"2026-07-27T04:33:19.050000Z","event_type":"price_change","frame_hash":"be78d3b06352c7ddbbc46e8fb4b3f9d55cec0ac22cc84c5a5537ef18d88ebfb8","frame_index":0,"kind":"data","monotonic_ns":228782264712708,"payload":{"event_type":"price_change","market":"0xeb66215f2e9faa6449e30a02bab5b8ed7b79a38bf961f6b24d0073c9c2419250","price_changes":[{"asset_id":"60386828328910021732068595344565885737045900010034836345809386672230885527307","best_ask":"0.89","best_bid":"0.88","hash":"e65fd3977000233db27946026298c03131b9e437","price":"0.01","side":"BUY","size":"7713.02"},{"asset_id":"69697746896130839564035629862476347944307040470122503199396727085502753297492","best_ask":"0.12","best_bid":"0.11","hash":"9abcefd966c7c3252cbd060434cecaf3580e8e07","price":"0.99","side":"SELL","size":"7713.02"}],"timestamp":"1785126799050"},"payload_hash":"2e7694a8b1b5b5ebcd25c5d081b91c1e3010fdcc5d336d7b7469f80f1b2f5380","raw_frame":"{\"market\":\"0xeb66215f2e9faa6449e30a02bab5b8ed7b79a38bf961f6b24d0073c9c2419250\", \"price_changes\":[{\"asset_id\":\"60386828328910021732068595344565885737045900010034836345809386672230885527307\", \"price\":\"0.01\", \"size\":\"7713.02\", \"side\":\"BUY\", \"hash\":\"e65fd3977000233db27946026298c03131b9e437\", \"best_bid\":\"0.88\", \"best_ask\":\"0.89\"}, {\"asset_id\":\"69697746896130839564035629862476347944307040470122503199396727085502753297492\", \"price\":\"0.99\", \"size\":\"7713.02\", \"side\":\"SELL\", \"hash\":\"9abcefd966c7c3252cbd060434cecaf3580e8e07\", \"best_bid\":\"0.11\", \"best_ask\":\"0.12\"}], \"timestamp\":\"1785126799050\", \"event_type\":\"price_change\"}","received_at":"2026-07-27T04:33:18.996601Z","schema_version":"clob-market-ws.price_change.v1","sequence":null,"server_hash":null,"server_timestamp":"1785126799050","session_id":"e9443c7415a0419799bee9cfbb1a9e4d","source":"clob_market_ws"},"received_at":"2026-07-27T04:33:18.996601Z","record_id":"939535404ac226f9c04d5fc12998b0ed674785a19bb27ac6f2b66b3f443e74dc","schema_fingerprint":"4aa3821a28b0b7c2400bc59aba4bcc0a76e971dadd19610d3ad38c768e124dc7","schema_version":"edge-lab-recorder.raw.v1","sequence":null,"source":"clob_market_ws"}
{"event_at":"2026-07-27T04:33:19.053000Z","event_fingerprint":"0b0923157da7b9412f05b9bcf523fcdb7904b07c297cba95bcda351f21e7c830","payload":{"connection_id":"0f4979d6978d463e9660b042fdcf555f","event_at":"2026-07-27T04:33:19.053000Z","event_type":"price_change","frame_hash":"a795f945f20e97154e911f85375f56206b826340548aa15ff48171b028eae0d2","frame_index":0,"kind":"data","monotonic_ns":228782266417833,"payload":{"event_type":"price_change","market":"0xeb66215f2e9faa6449e30a02bab5b8ed7b79a38bf961f6b24d0073c9c2419250","price_changes":[{"asset_id":"60386828328910021732068595344565885737045900010034836345809386672230885527307","best_ask":"0.89","best_bid":"0.88","hash":"1a0f94febb39d73b2acec471b10880bfe0c3e1d9","price":"0.01","side":"BUY","size":"7708.02"},{"asset_id":"69697746896130839564035629862476347944307040470122503199396727085502753297492","best_ask":"0.12","best_bid":"0.11","hash":"ab2f8ae3eeed8096e87d0fab516df661dadc9010","price":"0.99","side":"SELL","size":"7708.02"}],"timestamp":"1785126799053"},"payload_hash":"dd9146c5c07fc560e033225e046bb9715466bb37229076ed4ebcb7d41a3daf2e","raw_frame":"{\"market\":\"0xeb66215f2e9faa6449e30a02bab5b8ed7b79a38bf961f6b24d0073c9c2419250\", \"price_changes\":[{\"asset_id\":\"60386828328910021732068595344565885737045900010034836345809386672230885527307\", \"price\":\"0.01\", \"size\":\"7708.02\", \"side\":\"BUY\", \"hash\":\"1a0f94febb39d73b2acec471b10880bfe0c3e1d9\", \"best_bid\":\"0.88\", \"best_ask\":\"0.89\"}, {\"asset_id\":\"69697746896130839564035629862476347944307040470122503199396727085502753297492\", \"price\":\"0.99\", \"size\":\"7708.02\", \"side\":\"SELL\", \"hash\":\"ab2f8ae3eeed8096e87d0fab516df661dadc9010\", \"best_bid\":\"0.11\", \"best_ask\":\"0.12\"}], \"timestamp\":\"1785126799053\", \"event_type\":\"price_change\"}","received_at":"2026-07-27T04:33:18.998306Z","schema_version":"clob-market-ws.price_change.v1","sequence":null,"server_hash":null,"server_timestamp":"1785126799053","session_id":"e9443c7415a0419799bee9cfbb1a9e4d","source":"clob_market_ws"},"received_at":"2026-07-27T04:33:18.998306Z","record_id":"8dbbe9cf23d5d92f8336092a611c050ca30ff25a48a037b113c573efc7ad39c8","schema_fingerprint":"4aa3821a28b0b7c2400bc59aba4bcc0a76e971dadd19610d3ad38c768e124dc7","schema_version":"edge-lab-recorder.raw.v1","sequence":null,"source":"clob_market_ws"}
{"event_at":"2026-07-27T04:33:19.068000Z","event_fingerprint":"a429e6f6653f66d17ce317b90d84e1124b788715a18f7ffaf89bff2ca9d44a12","payload":{"connection_id":"0f4979d6978d463e9660b042fdcf555f","event_at":"2026-07-27T04:33:19.068000Z","event_type":"price_change","frame_hash":"9d37013525e742882b5ed63c219a530fb9dce1793dede5815d1fe5a3e106c4f1","frame_index":0,"kind":"data","monotonic_ns":228782280286000,"payload":{"event_type":"price_change","market":"0xeb66215f2e9faa6449e30a02bab5b8ed7b79a38bf961f6b24d0073c9c2419250","price_changes":[{"asset_id":"60386828328910021732068595344565885737045900010034836345809386672230885527307","best_ask":"0.89","best_bid":"0.88","hash":"e30cbe9544c0b92df84ffdc744e54efabb03bbc4","price":"0.01","side":"BUY","size":"7703.02"},{"asset_id":"69697746896130839564035629862476347944307040470122503199396727085502753297492","best_ask":"0.12","best_bid":"0.11","hash":"d00c96c0dd799fc324ab6a7f87a191c3ebbe9d20","price":"0.99","side":"SELL","size":"7703.02"}],"timestamp":"1785126799068"},"payload_hash":"48c5d53263cac2c74968e34cd1552fdcef1f12287e22b3aa598489102be3b10f","raw_frame":"{\"market\":\"0xeb66215f2e9faa6449e30a02bab5b8ed7b79a38bf961f6b24d0073c9c2419250\", \"price_changes\":[{\"asset_id\":\"60386828328910021732068595344565885737045900010034836345809386672230885527307\", \"price\":\"0.01\", \"size\":\"7703.02\", \"side\":\"BUY\", \"hash\":\"e30cbe9544c0b92df84ffdc744e54efabb03bbc4\", \"best_bid\":\"0.88\", \"best_ask\":\"0.89\"}, {\"asset_id\":\"69697746896130839564035629862476347944307040470122503199396727085502753297492\", \"price\":\"0.99\", \"size\":\"7703.02\", \"side\":\"SELL\", \"hash\":\"d00c96c0dd799fc324ab6a7f87a191c3ebbe9d20\", \"best_bid\":\"0.11\", \"best_ask\":\"0.12\"}], \"timestamp\":\"1785126799068\", \"event_type\":\"price_change\"}","received_at":"2026-07-27T04:33:19.012172Z","schema_version":"clob-market-ws.price_change.v1","sequence":null,"server_hash":null,"server_timestamp":"1785126799068","session_id":"e9443c7415a0419799bee9cfbb1a9e4d","source":"clob_market_ws"},"received_at":"2026-07-27T04:33:19.012172Z","record_id":"382ac8bcebe4bb68b5583a5f221280a033acecfe34f8432b6c64145de7d9e808","schema_fingerprint":"4aa3821a28b0b7c2400bc59aba4bcc0a76e971dadd19610d3ad38c768e124dc7","schema_version":"edge-lab-recorder.raw.v1","sequence":null,"source":"clob_market_ws"}
{"event_at":"2026-07-27T04:33:19.121000Z","event_fingerprint":"016e02b3d2667bbf8d2c4e94924d92214ce69dad6d0028dac3725e7955b2b451","payload":{"connection_id":"0f4979d6978d463e9660b042fdcf555f","event_at":"2026-07-27T04:33:19.121000Z","event_type":"price_change","frame_hash":"8faab30ae27b07a36859091ee1377d26dbd2ca0a3f13260d7d9f041cca2484f4","frame_index":0,"kind":"data","monotonic_ns":228782337071375,"payload":{"event_type":"price_change","market":"0xeb66215f2e9faa6449e30a02bab5b8ed7b79a38bf961f6b24d0073c9c2419250","price_changes":[{"asset_id":"69697746896130839564035629862476347944307040470122503199396727085502753297492","best_ask":"0.12","best_bid":"0.11","hash":"e88c913867376fa94a8cd8a1b85bffad5cb08d39","price":"0.01","side":"BUY","size":"8014.91"},{"asset_id":"60386828328910021732068595344565885737045900010034836345809386672230885527307","best_ask":"0.89","best_bid":"0.88","hash":"05452934f10f68c100491ccccb361191a83b16d1","price":"0.99","side":"SELL","size":"8014.91"}],"timestamp":"1785126799121"},"payload_hash":"bfcc109d73b87a5a43e84c0c570a27cbc308c7544e9b755ac1a681e748ad5972","raw_frame":"{\"market\":\"0xeb66215f2e9faa6449e30a02bab5b8ed7b79a38bf961f6b24d0073c9c2419250\", \"price_changes\":[{\"asset_id\":\"69697746896130839564035629862476347944307040470122503199396727085502753297492\", \"price\":\"0.01\", \"size\":\"8014.91\", \"side\":\"BUY\", \"hash\":\"e88c913867376fa94a8cd8a1b85bffad5cb08d39\", \"best_bid\":\"0.11\", \"best_ask\":\"0.12\"}, {\"asset_id\":\"60386828328910021732068595344565885737045900010034836345809386672230885527307\", \"price\":\"0.99\", \"size\":\"8014.91\", \"side\":\"SELL\", \"hash\":\"05452934f10f68c100491ccccb361191a83b16d1\", \"best_bid\":\"0.88\", \"best_ask\":\"0.89\"}], \"timestamp\":\"1785126799121\", \"event_type\":\"price_change\"}","received_at":"2026-07-27T04:33:19.068952Z","schema_version":"clob-market-ws.price_change.v1","sequence":null,"server_hash":null,"server_timestamp":"1785126799121","session_id":"e9443c7415a0419799bee9cfbb1a9e4d","source":"clob_market_ws"},"received_at":"2026-07-27T04:33:19.068952Z","record_id":"ce0511a7c9cf25af675b19053faa9273498c30a0b4d04276bb2e6d47326bc003","schema_fingerprint":"4aa3821a28b0b7c2400bc59aba4bcc0a76e971dadd19610d3ad38c768e124dc7","schema_version":"edge-lab-recorder.raw.v1","sequence":null,"source":"clob_market_ws"}
{"event_at":"2026-07-27T04:33:19.138000Z","event_fingerprint":"75ddf9f96aaa1583668376a8fc4bcc5b3352e7653c20490fe36051be735f19b4","payload":{"connection_id":"0f4979d6978d463e9660b042fdcf555f","event_at":"2026-07-27T04:33:19.138000Z","event_type":"price_change","frame_hash":"a1c9d394c9bb644a85fbd55050626f923f53f6e76dd9bcca8e6a96a71f9ddda6","frame_index":0,"kind":"data","monotonic_ns":228782351500333,"payload":{"event_type":"price_change","market":"0xeb66215f2e9faa6449e30a02bab5b8ed7b79a38bf961f6b24d0073c9c2419250","price_changes":[{"asset_id":"69697746896130839564035629862476347944307040470122503199396727085502753297492","best_ask":"0.12","best_bid":"0.11","hash":"7d305345b0043e89e4be648a8c21638d829277c7","price":"0.11","side":"BUY","size":"472.4"},{"asset_id":"60386828328910021732068595344565885737045900010034836345809386672230885527307","best_ask":"0.89","best_bid":"0.88","hash":"ba6dd75bed2380874847420f10eef51c68b6f499","price":"0.89","side":"SELL","size":"472.4"}],"timestamp":"1785126799138"},"payload_hash":"1db932e6d78a77a6920b6cb3c4bca214becd3dc55f90c58ffc5ddc64e5262290","raw_frame":"{\"market\":\"0xeb66215f2e9faa6449e30a02bab5b8ed7b79a38bf961f6b24d0073c9c2419250\", \"price_changes\":[{\"asset_id\":\"69697746896130839564035629862476347944307040470122503199396727085502753297492\", \"price\":\"0.11\", \"size\":\"472.4\", \"side\":\"BUY\", \"hash\":\"7d305345b0043e89e4be648a8c21638d829277c7\", \"best_bid\":\"0.11\", \"best_ask\":\"0.12\"}, {\"asset_id\":\"60386828328910021732068595344565885737045900010034836345809386672230885527307\", \"price\":\"0.89\", \"size\":\"472.4\", \"side\":\"SELL\", \"hash\":\"ba6dd75bed2380874847420f10eef51c68b6f499\", \"best_bid\":\"0.88\", \"best_ask\":\"0.89\"}], \"timestamp\":\"1785126799138\", \"event_type\":\"price_change\"}","received_at":"2026-07-27T04:33:19.083392Z","schema_version":"clob-market-ws.price_change.v1","sequence":null,"server_hash":null,"server_timestamp":"1785126799138","session_id":"e9443c7415a0419799bee9cfbb1a9e4d","source":"clob_market_ws"},"received_at":"2026-07-27T04:33:19.083392Z","record_id":"679b66abfbbff52db18f7f585df57bbfdffba8842961d96d204df19e1024f537","schema_fingerprint":"4aa3821a28b0b7c2400bc59aba4bcc0a76e971dadd19610d3ad38c768e124dc7","schema_version":"edge-lab-recorder.raw.v1","sequence":null,"source":"clob_market_ws"}
{"event_at":"2026-07-27T04:33:19.146000Z","event_fingerprint":"b4e0f89dade3348acee9a2065a98eca59ceb48768be6720dd7857f246d5154e0","payload":{"connection_id":"0f4979d6978d463e9660b042fdcf555f","event_at":"2026-07-27T04:33:19.146000Z","event_type":"price_change","frame_hash":"f7471ab2ed8ca99c43981247227ad57d977e459533b01c6e285b8ac7ef3fd678","frame_index":0,"kind":"data","monotonic_ns":228782358309125,"payload":{"event_type":"price_change","market":"0xeb66215f2e9faa6449e30a02bab5b8ed7b79a38bf961f6b24d0073c9c2419250","price_changes":[{"asset_id":"60386828328910021732068595344565885737045900010034836345809386672230885527307","best_ask":"0.89","best_bid":"0.88","hash":"8a79992e8060a50c61387b3018098b88ffa51165","price":"0.04","side":"BUY","size":"633.09"},{"asset_id":"69697746896130839564035629862476347944307040470122503199396727085502753297492","best_ask":"0.12","best_bid":"0.11","hash":"b461d6de8c2ed7e4c45132c120c1291006e92156","price":"0.96","side":"SELL","size":"633.09"}],"timestamp":"1785126799146"},"payload_hash":"59928c5d1e570b8f5da2daa875f11063dc9a491b0a88474082a9d3d96a300642","raw_frame":"{\"market\":\"0xeb66215f2e9faa6449e30a02bab5b8ed7b79a38bf961f6b24d0073c9c2419250\", \"price_changes\":[{\"asset_id\":\"60386828328910021732068595344565885737045900010034836345809386672230885527307\", \"price\":\"0.04\", \"size\":\"633.09\", \"side\":\"BUY\", \"hash\":\"8a79992e8060a50c61387b3018098b88ffa51165\", \"best_bid\":\"0.88\", \"best_ask\":\"0.89\"}, {\"asset_id\":\"69697746896130839564035629862476347944307040470122503199396727085502753297492\", \"price\":\"0.96\", \"size\":\"633.09\", \"side\":\"SELL\", \"hash\":\"b461d6de8c2ed7e4c45132c120c1291006e92156\", \"best_bid\":\"0.11\", \"best_ask\":\"0.12\"}], \"timestamp\":\"1785126799146\", \"event_type\":\"price_change\"}","received_at":"2026-07-27T04:33:19.090194Z","schema_version":"clob-market-ws.price_change.v1","sequence":null,"server_hash":null,"server_timestamp":"1785126799146","session_id":"e9443c7415a0419799bee9cfbb1a9e4d","source":"clob_market_ws"},"received_at":"2026-07-27T04:33:19.090194Z","record_id":"22b41612b1ec586229026f3ea50aa9178b1445c2a034ee5db312777d0e2760c0","schema_fingerprint":"4aa3821a28b0b7c2400bc59aba4bcc0a76e971dadd19610d3ad38c768e124dc7","schema_version":"edge-lab-recorder.raw.v1","sequence":null,"source":"clob_market_ws"}
{"event_at":"2026-07-27T04:33:19.149000Z","event_fingerprint":"d42ab9342170b5f19931db06f6efb92c8e36a9003d364b41c540e5eeafb34b1e","payload":{"connection_id":"0f4979d6978d463e9660b042fdcf555f","event_at":"2026-07-27T04:33:19.149000Z","event_type":"price_change","frame_hash":"abda73267b8e0688e01cda68d5ff41aabf7554c7495f8eac0a2331368f015260","frame_index":0,"kind":"data","monotonic_ns":228782361382458,"payload":{"event_type":"price_change","market":"0xeb66215f2e9faa6449e30a02bab5b8ed7b79a38bf961f6b24d0073c9c2419250","price_changes":[{"asset_id":"60386828328910021732068595344565885737045900010034836345809386672230885527307","best_ask":"0.89","best_bid":"0.88","hash":"d8f8901cd4c6dc88d7a6b475b064a652532cfbea","price":"0.89","side":"SELL","size":"477.4"},{"asset_id":"69697746896130839564035629862476347944307040470122503199396727085502753297492","best_ask":"0.12","best_bid":"0.11","hash":"0a7ec590341e98da8232fc3be0ab1436c3a218c2","price":"0.11","side":"BUY","size":"477.4"}],"timestamp":"1785126799149"},"payload_hash":"14521656fc19489b36c8eac5bd2183bddb0ba9f48257a8e0091d29e798278df9","raw_frame":"{\"market\":\"0xeb66215f2e9faa6449e30a02bab5b8ed7b79a38bf961f6b24d0073c9c2419250\", \"price_changes\":[{\"asset_id\":\"60386828328910021732068595344565885737045900010034836345809386672230885527307\", \"price\":\"0.89\", \"size\":\"477.4\", \"side\":\"SELL\", \"hash\":\"d8f8901cd4c6dc88d7a6b475b064a652532cfbea\", \"best_bid\":\"0.88\", \"best_ask\":\"0.89\"}, {\"asset_id\":\"69697746896130839564035629862476347944307040470122503199396727085502753297492\", \"price\":\"0.11\", \"size\":\"477.4\", \"side\":\"BUY\", \"hash\":\"0a7ec590341e98da8232fc3be0ab1436c3a218c2\", \"best_bid\":\"0.11\", \"best_ask\":\"0.12\"}], \"timestamp\":\"1785126799149\", \"event_type\":\"price_change\"}","received_at":"2026-07-27T04:33:19.093268Z","schema_version":"clob-market-ws.price_change.v1","sequence":null,"server_hash":null,"server_timestamp":"1785126799149","session_id":"e9443c7415a0419799bee9cfbb1a9e4d","source":"clob_market_ws"},"received_at":"2026-07-27T04:33:19.093268Z","record_id":"4923ef035476499fb1e2c01dfe29789c5f9abc0e4d41b32a847c03e11c7da927","schema_fingerprint":"4aa3821a28b0b7c2400bc59aba4bcc0a76e971dadd19610d3ad38c768e124dc7","schema_version":"edge-lab-recorder.raw.v1","sequence":null,"source":"clob_market_ws"}
{"event_at":"2026-07-27T04:33:19.184000Z","event_fingerprint":"b75ef56bc96c3a37e3f49b4515dd3296aab5d09cf0a7db66a5c2cf9f131bf251","payload":{"connection_id":"0f4979d6978d463e9660b042fdcf555f","event_at":"2026-07-27T04:33:19.184000Z","event_type":"price_change","frame_hash":"8b6c143bc9ecac9b6a532228bd1cd2112eba84f19502a492bb1d6ec27394ac22","frame_index":0,"kind":"data","monotonic_ns":228782397242458,"payload":{"event_type":"price_change","market":"0xeb66215f2e9faa6449e30a02bab5b8ed7b79a38bf961f6b24d0073c9c2419250","price_changes":[{"asset_id":"60386828328910021732068595344565885737045900010034836345809386672230885527307","best_ask":"0.89","best_bid":"0.88","hash":"d2024e0991904135d9474f6f7325c984276882cc","price":"0.86","side":"BUY","size":"216.37"},{"asset_id":"69697746896130839564035629862476347944307040470122503199396727085502753297492","best_ask":"0.12","best_bid":"0.11","hash":"31bad10a47366c0a2be4b533fd72cb98c51ce8ab","price":"0.14","side":"SELL","size":"216.37"}],"timestamp":"1785126799184"},"payload_hash":"e32c717ddd0863894ec5b200af3eb8bff9c5c81a5e67d653c36cc32607b5ccc5","raw_frame":"{\"market\":\"0xeb66215f2e9faa6449e30a02bab5b8ed7b79a38bf961f6b24d0073c9c2419250\", \"price_changes\":[{\"asset_id\":\"60386828328910021732068595344565885737045900010034836345809386672230885527307\", \"price\":\"0.86\", \"size\":\"216.37\", \"side\":\"BUY\", \"hash\":\"d2024e0991904135d9474f6f7325c984276882cc\", \"best_bid\":\"0.88\", \"best_ask\":\"0.89\"}, {\"asset_id\":\"69697746896130839564035629862476347944307040470122503199396727085502753297492\", \"price\":\"0.14\", \"size\":\"216.37\", \"side\":\"SELL\", \"hash\":\"31bad10a47366c0a2be4b533fd72cb98c51ce8ab\", \"best_bid\":\"0.11\", \"best_ask\":\"0.12\"}], \"timestamp\":\"1785126799184\", \"event_type\":\"price_change\"}","received_at":"2026-07-27T04:33:19.129128Z","schema_version":"clob-market-ws.price_change.v1","sequence":null,"server_hash":null,"server_timestamp":"1785126799184","session_id":"e9443c7415a0419799bee9cfbb1a9e4d","source":"clob_market_ws"},"received_at":"2026-07-27T04:33:19.129128Z","record_id":"7c5659e42155a2258d3edd417d339b63e845e7b3f85961442b3667477ead2ce8","schema_fingerprint":"4aa3821a28b0b7c2400bc59aba4bcc0a76e971dadd19610d3ad38c768e124dc7","schema_version":"edge-lab-recorder.raw.v1","sequence":null,"source":"clob_market_ws"}
{"event_at":"2026-07-27T04:33:19.189000Z","event_fingerprint":"1e7690cd440b7e15eca4d2d2be474369134caf973c67a44c056f96a251c42ae5","payload":{"connection_id":"0f4979d6978d463e9660b042fdcf555f","event_at":"2026-07-27T04:33:19.189000Z","event_type":"price_change","frame_hash":"47c2c000c3dbd0f4e158693cda3849e5ad0741ece1869b588aca761aa9dee96b","frame_index":0,"kind":"data","monotonic_ns":228782400794250,"payload":{"event_type":"price_change","market":"0xeb66215f2e9faa6449e30a02bab5b8ed7b79a38bf961f6b24d0073c9c2419250","price_changes":[{"asset_id":"60386828328910021732068595344565885737045900010034836345809386672230885527307","best_ask":"0.89","best_bid":"0.88","hash":"8a4716ffd1bf8f8be0f79191e98619e8bd4abdc1","price":"0.85","side":"BUY","size":"325.94"},{"asset_id":"69697746896130839564035629862476347944307040470122503199396727085502753297492","best_ask":"0.12","best_bid":"0.11","hash":"af45d33496cb09c0a92daeb25c775e4bc76b544d","price":"0.15","side":"SELL","size":"325.94"}],"timestamp":"1785126799189"},"payload_hash":"19ddf87b6e01d3db88035ba2b58769ab41866e2b3681cdfbbc40a7cd327c31c8","raw_frame":"{\"market\":\"0xeb66215f2e9faa6449e30a02bab5b8ed7b79a38bf961f6b24d0073c9c2419250\", \"price_changes\":[{\"asset_id\":\"60386828328910021732068595344565885737045900010034836345809386672230885527307\", \"price\":\"0.85\", \"size\":\"325.94\", \"side\":\"BUY\", \"hash\":\"8a4716ffd1bf8f8be0f79191e98619e8bd4abdc1\", \"best_bid\":\"0.88\", \"best_ask\":\"0.89\"}, {\"asset_id\":\"69697746896130839564035629862476347944307040470122503199396727085502753297492\", \"price\":\"0.15\", \"size\":\"325.94\", \"side\":\"SELL\", \"hash\":\"af45d33496cb09c0a92daeb25c775e4bc76b544d\", \"best_bid\":\"0.11\", \"best_ask\":\"0.12\"}], \"timestamp\":\"1785126799189\", \"event_type\":\"price_change\"}","received_at":"2026-07-27T04:33:19.132683Z","schema_version":"clob-market-ws.price_change.v1","sequence":null,"server_hash":null,"server_timestamp":"1785126799189","session_id":"e9443c7415a0419799bee9cfbb1a9e4d","source":"clob_market_ws"},"received_at":"2026-07-27T04:33:19.132683Z","record_id":"7fda040e0fb0ee1bc2cec00300c84ebed008f8d2b1b4aa4736cc43aa5490b691","schema_fingerprint":"4aa3821a28b0b7c2400bc59aba4bcc0a76e971dadd19610d3ad38c768e124dc7","schema_version":"edge-lab-recorder.raw.v1","sequence":null,"source":"clob_market_ws"}
{"event_at":"2026-07-27T04:33:19.203000Z","event_fingerprint":"60eb0980129ad919883cad0ffc43be1b170eb0c12c29fc7c11e1828bca9c165c","payload":{"connection_id":"0f4979d6978d463e9660b042fdcf555f","event_at":"2026-07-27T04:33:19.203000Z","event_type":"price_change","frame_hash":"6f164468d1327b1e6d0752f3cca326f880ea013dc227ebb9e541590ace8b6342","frame_index":0,"kind":"data","monotonic_ns":228782415100375,"payload":{"event_type":"price_change","market":"0xeb66215f2e9faa6449e30a02bab5b8ed7b79a38bf961f6b24d0073c9c2419250","price_changes":[{"asset_id":"60386828328910021732068595344565885737045900010034836345809386672230885527307","best_ask":"0.89","best_bid":"0.88","hash":"f4f4ad6a17815868a03397e23639e0dc8529edd6","price":"0.04","side":"BUY","size":"628.09"},{"asset_id":"69697746896130839564035629862476347944307040470122503199396727085502753297492","best_ask":"0.12","best_bid":"0.11","hash":"f9d6d3b3dcaf40689006d06c98a17dfaded63009","price":"0.96","side":"SELL","size":"628.09"}],"timestamp":"1785126799203"},"payload_hash":"35348d780a5eeb733b3d5ca92622f9bdcc8a94105f712d8e388db276359c7176","raw_frame":"{\"market\":\"0xeb66215f2e9faa6449e30a02bab5b8ed7b79a38bf961f6b24d0073c9c2419250\", \"price_changes\":[{\"asset_id\":\"60386828328910021732068595344565885737045900010034836345809386672230885527307\", \"price\":\"0.04\", \"size\":\"628.09\", \"side\":\"BUY\", \"hash\":\"f4f4ad6a17815868a03397e23639e0dc8529edd6\", \"best_bid\":\"0.88\", \"best_ask\":\"0.89\"}, {\"asset_id\":\"69697746896130839564035629862476347944307040470122503199396727085502753297492\", \"price\":\"0.96\", \"size\":\"628.09\", \"side\":\"SELL\", \"hash\":\"f9d6d3b3dcaf40689006d06c98a17dfaded63009\", \"best_bid\":\"0.11\", \"best_ask\":\"0.12\"}], \"timestamp\":\"1785126799203\", \"event_type\":\"price_change\"}","received_at":"2026-07-27T04:33:19.146986Z","schema_version":"clob-market-ws.price_change.v1","sequence":null,"server_hash":null,"server_timestamp":"1785126799203","session_id":"e9443c7415a0419799bee9cfbb1a9e4d","source":"clob_market_ws"},"received_at":"2026-07-27T04:33:19.146986Z","record_id":"f2bb4371261698046eafeaa2091f41f2e698fc875afe64dd18b7f06de6d67bdc","schema_fingerprint":"4aa3821a28b0b7c2400bc59aba4bcc0a76e971dadd19610d3ad38c768e124dc7","schema_version":"edge-lab-recorder.raw.v1","sequence":null,"source":"clob_market_ws"}
{"event_at":"2026-07-27T04:33:19.217000Z","event_fingerprint":"103436a3649d5562659af2b5f6169d7041537b5333c484de11869426c8d60755","payload":{"connection_id":"0f4979d6978d463e9660b042fdcf555f","event_at":"2026-07-27T04:33:19.217000Z","event_type":"price_change","frame_hash":"c700d10f411b506aa26c6cb1388fd17cb8599980d653d170a3254f86116ec722","frame_index":0,"kind":"data","monotonic_ns":228782429275875,"payload":{"event_type":"price_change","market":"0xeb66215f2e9faa6449e30a02bab5b8ed7b79a38bf961f6b24d0073c9c2419250","price_changes":[{"asset_id":"69697746896130839564035629862476347944307040470122503199396727085502753297492","best_ask":"0.12","best_bid":"0.11","hash":"6404d9f69bea97b75b5173e1068428a738300fba","price":"0.11","side":"BUY","size":"467.4"},{"asset_id":"60386828328910021732068595344565885737045900010034836345809386672230885527307","best_ask":"0.89","best_bid":"0.88","hash":"ddaad9d65068a125ed0297404379587bed409d8b","price":"0.89","side":"SELL","size":"467.4"}],"timestamp":"1785126799217"},"payload_hash":"e78e966d1eb6ac87bfb7a32ca780d572e2be47f0f029d4aa480dd43e4f825384","raw_frame":"{\"market\":\"0xeb66215f2e9faa6449e30a02bab5b8ed7b79a38bf961f6b24d0073c9c2419250\", \"price_changes\":[{\"asset_id\":\"69697746896130839564035629862476347944307040470122503199396727085502753297492\", \"price\":\"0.11\", \"size\":\"467.4\", \"side\":\"BUY\", \"hash\":\"6404d9f69bea97b75b5173e1068428a738300fba\", \"best_bid\":\"0.11\", \"best_ask\":\"0.12\"}, {\"asset_id\":\"60386828328910021732068595344565885737045900010034836345809386672230885527307\", \"price\":\"0.89\", \"size\":\"467.4\", \"side\":\"SELL\", \"hash\":\"ddaad9d65068a125ed0297404379587bed409d8b\", \"best_bid\":\"0.88\", \"best_ask\":\"0.89\"}], \"timestamp\":\"1785126799217\", \"event_type\":\"price_change\"}","received_at":"2026-07-27T04:33:19.161162Z","schema_version":"clob-market-ws.price_change.v1","sequence":null,"server_hash":null,"server_timestamp":"1785126799217","session_id":"e9443c7415a0419799bee9cfbb1a9e4d","source":"clob_market_ws"},"received_at":"2026-07-27T04:33:19.161162Z","record_id":"b58c9c8fe7913a3f0e8ce1fd376b3a99e2651201063962dc0609369c12231938","schema_fingerprint":"4aa3821a28b0b7c2400bc59aba4bcc0a76e971dadd19610d3ad38c768e124dc7","schema_version":"edge-lab-recorder.raw.v1","sequence":null,"source":"clob_market_ws"}
{"event_at":"2026-07-27T04:33:19.241000Z","event_fingerprint":"32379e84e434a5c8fe37d48b5c0e6091939b7c67d67bc8fedaa203048338cfa3","payload":{"connection_id":"0f4979d6978d463e9660b042fdcf555f","event_at":"2026-07-27T04:33:19.241000Z","event_type":"price_change","frame_hash":"ce1ab6196cc5c7a2776e77b0551f7963793096daaec78e9aebc0858419f5b142","frame_index":0,"kind":"data","monotonic_ns":228782454001458,"payload":{"event_type":"price_change","market":"0xeb66215f2e9faa6449e30a02bab5b8ed7b79a38bf961f6b24d0073c9c2419250","price_changes":[{"asset_id":"69697746896130839564035629862476347944307040470122503199396727085502753297492","best_ask":"0.12","best_bid":"0.11","hash":"6c122d282094686fd98d486df24748099f1964a0","price":"0.1","side":"BUY","size":"151"},{"asset_id":"60386828328910021732068595344565885737045900010034836345809386672230885527307","best_ask":"0.89","best_bid":"0.88","hash":"14fc61830c6133412357d6ff10ec11a651befdc0","price":"0.9","side":"SELL","size":"151"}],"timestamp":"1785126799241"},"payload_hash":"f586b7c5242a16d73fb6b48a7868b81a03b82a2c97f381d425e4f8be392b2b95","raw_frame":"{\"market\":\"0xeb66215f2e9faa6449e30a02bab5b8ed7b79a38bf961f6b24d0073c9c2419250\", \"price_changes\":[{\"asset_id\":\"69697746896130839564035629862476347944307040470122503199396727085502753297492\", \"price\":\"0.1\", \"size\":\"151\", \"side\":\"BUY\", \"hash\":\"6c122d282094686fd98d486df24748099f1964a0\", \"best_bid\":\"0.11\", \"best_ask\":\"0.12\"}, {\"asset_id\":\"60386828328910021732068595344565885737045900010034836345809386672230885527307\", \"price\":\"0.9\", \"size\":\"151\", \"side\":\"SELL\", \"hash\":\"14fc61830c6133412357d6ff10ec11a651befdc0\", \"best_bid\":\"0.88\", \"best_ask\":\"0.89\"}], \"timestamp\":\"1785126799241\", \"event_type\":\"price_change\"}","received_at":"2026-07-27T04:33:19.185886Z","schema_version":"clob-market-ws.price_change.v1","sequence":null,"server_hash":null,"server_timestamp":"1785126799241","session_id":"e9443c7415a0419799bee9cfbb1a9e4d","source":"clob_market_ws"},"received_at":"2026-07-27T04:33:19.185886Z","record_id":"cf77d25e0c11a60a2b63673f2955191851bf8033842fc735aa6ca1b947b2455d","schema_fingerprint":"4aa3821a28b0b7c2400bc59aba4bcc0a76e971dadd19610d3ad38c768e124dc7","schema_version":"edge-lab-recorder.raw.v1","sequence":null,"source":"clob_market_ws"}
{"event_at":"2026-07-27T04:33:19.272000Z","event_fingerprint":"a1d28270799ae9714e79a7a42bb1b1bf7a19341f550a4d32b5daac53cbaaeb85","payload":{"connection_id":"0f4979d6978d463e9660b042fdcf555f","event_at":"2026-07-27T04:33:19.272000Z","event_type":"price_change","frame_hash":"b85ae6812f6517826f48f2ff0bf1a8c5c66fc862ef88159f129899816438dae7","frame_index":0,"kind":"data","monotonic_ns":228782484319791,"payload":{"event_type":"price_change","market":"0xeb66215f2e9faa6449e30a02bab5b8ed7b79a38bf961f6b24d0073c9c2419250","price_changes":[{"asset_id":"69697746896130839564035629862476347944307040470122503199396727085502753297492","best_ask":"0.12","best_bid":"0.11","hash":"6bc71260d4a4efe5be24a89cb3fc376873988b12","price":"0.06","side":"BUY","size":"850.84"},{"asset_id":"60386828328910021732068595344565885737045900010034836345809386672230885527307","best_ask":"0.89","best_bid":"0.88","hash":"ec93702a956a908003af727fcfd19d764821c6c1","price":"0.94","side":"SELL","size":"850.84"}],"timestamp":"1785126799272"},"payload_hash":"1bbd3f8fffd5bb0f0f84c15aa6be4a0b078c60a0c451150e87d0102bad5f1678","raw_frame":"{\"market\":\"0xeb66215f2e9faa6449e30a02bab5b8ed7b79a38bf961f6b24d0073c9c2419250\", \"price_changes\":[{\"asset_id\":\"69697746896130839564035629862476347944307040470122503199396727085502753297492\", \"price\":\"0.06\", \"size\":\"850.84\", \"side\":\"BUY\", \"hash\":\"6bc71260d4a4efe5be24a89cb3fc376873988b12\", \"best_bid\":\"0.11\", \"best_ask\":\"0.12\"}, {\"asset_id\":\"60386828328910021732068595344565885737045900010034836345809386672230885527307\", \"price\":\"0.94\", \"size\":\"850.84\", \"side\":\"SELL\", \"hash\":\"ec93702a956a908003af727fcfd19d764821c6c1\", \"best_bid\":\"0.88\", \"best_ask\":\"0.89\"}], \"timestamp\":\"1785126799272\", \"event_type\":\"price_change\"}","received_at":"2026-07-27T04:33:19.216206Z","schema_version":"clob-market-ws.price_change.v1","sequence":null,"server_hash":null,"server_timestamp":"1785126799272","session_id":"e9443c7415a0419799bee9cfbb1a9e4d","source":"clob_market_ws"},"received_at":"2026-07-27T04:33:19.216206Z","record_id":"1d75f8057129925bdd89abf6865564f2bbd973179e5c8daa47792bcd4f74cc72","schema_fingerprint":"4aa3821a28b0b7c2400bc59aba4bcc0a76e971dadd19610d3ad38c768e124dc7","schema_version":"edge-lab-recorder.raw.v1","sequence":null,"source":"clob_market_ws"}
{"event_at":"2026-07-27T04:33:19.279000Z","event_fingerprint":"49d0ddc6685c04d540da967b500e1a8bd840e1a43a239eff39b9b485b122a8f7","payload":{"connection_id":"0f4979d6978d463e9660b042fdcf555f","event_at":"2026-07-27T04:33:19.279000Z","event_type":"price_change","frame_hash":"ce8df1d05a1d78849480d593baa701eb7b9d61eb9ac55c074a440cebcd4d961a","frame_index":0,"kind":"data","monotonic_ns":228782492870000,"payload":{"event_type":"price_change","market":"0xeb66215f2e9faa6449e30a02bab5b8ed7b79a38bf961f6b24d0073c9c2419250","price_changes":[{"asset_id":"69697746896130839564035629862476347944307040470122503199396727085502753297492","best_ask":"0.12","best_bid":"0.11","hash":"bee957eee4e9ad2447d270548315d54e972befdd","price":"0.06","side":"BUY","size":"820.84"},{"asset_id":"60386828328910021732068595344565885737045900010034836345809386672230885527307","best_ask":"0.89","best_bid":"0.88","hash":"8642dc4fd163245c4b0560e633eb290c9ebd6394","price":"0.94","side":"SELL","size":"820.84"}],"timestamp":"1785126799279"},"payload_hash":"76c025083a06c8d8edc9acdf6d09a34d143b380a581c6fc39b75c50313fab408","raw_frame":"{\"market\":\"0xeb66215f2e9faa6449e30a02bab5b8ed7b79a38bf961f6b24d0073c9c2419250\", \"price_changes\":[{\"asset_id\":\"69697746896130839564035629862476347944307040470122503199396727085502753297492\", \"price\":\"0.06\", \"size\":\"820.84\", \"side\":\"BUY\", \"hash\":\"bee957eee4e9ad2447d270548315d54e972befdd\", \"best_bid\":\"0.11\", \"best_ask\":\"0.12\"}, {\"asset_id\":\"60386828328910021732068595344565885737045900010034836345809386672230885527307\", \"price\":\"0.94\", \"size\":\"820.84\", \"side\":\"SELL\", \"hash\":\"8642dc4fd163245c4b0560e633eb290c9ebd6394\", \"best_bid\":\"0.88\", \"best_ask\":\"0.89\"}], \"timestamp\":\"1785126799279\", \"event_type\":\"price_change\"}","received_at":"2026-07-27T04:33:19.224758Z","schema_version":"clob-market-ws.price_change.v1","sequence":null,"server_hash":null,"server_timestamp":"1785126799279","session_id":"e9443c7415a0419799bee9cfbb1a9e4d","source":"clob_market_ws"},"received_at":"2026-07-27T04:33:19.224758Z","record_id":"78a61af9340047fc6d46fe50b4a8a23231eb70070deaf8b84f7ce81e6e821f37","schema_fingerprint":"4aa3821a28b0b7c2400bc59aba4bcc0a76e971dadd19610d3ad38c768e124dc7","schema_version":"edge-lab-recorder.raw.v1","sequence":null,"source":"clob_market_ws"}
{"event_at":"2026-07-27T04:33:19.284000Z","event_fingerprint":"590fd0d90b70a9bdf1bf062df359ea08c21a1b3ce8025c22b2370068d52ec173","payload":{"connection_id":"0f4979d6978d463e9660b042fdcf555f","event_at":"2026-07-27T04:33:19.284000Z","event_type":"price_change","frame_hash":"e67e5601a0e02f5b722e304ddbf8989de212c5d4b6350dc51f31dd07f2678441","frame_index":0,"kind":"data","monotonic_ns":228782497502583,"payload":{"event_type":"price_change","market":"0xeb66215f2e9faa6449e30a02bab5b8ed7b79a38bf961f6b24d0073c9c2419250","price_changes":[{"asset_id":"69697746896130839564035629862476347944307040470122503199396727085502753297492","best_ask":"0.12","best_bid":"0.11","hash":"8fe2fc44848af810decc2709066eca300c4e348b","price":"0.08","side":"BUY","size":"201.25"},{"asset_id":"60386828328910021732068595344565885737045900010034836345809386672230885527307","best_ask":"0.89","best_bid":"0.88","hash":"5c060facede042bf7a47edc33bae6724eb2ce76a","price":"0.92","side":"SELL","size":"201.25"}],"timestamp":"1785126799284"},"payload_hash":"e6ee953afbbabc1bdc0a70e1597243f45fcd95810b0f9cb0e9e2d0c9300e52c6","raw_frame":"{\"market\":\"0xeb66215f2e9faa6449e30a02bab5b8ed7b79a38bf961f6b24d0073c9c2419250\", \"price_changes\":[{\"asset_id\":\"69697746896130839564035629862476347944307040470122503199396727085502753297492\", \"price\":\"0.08\", \"size\":\"201.25\", \"side\":\"BUY\", \"hash\":\"8fe2fc44848af810decc2709066eca300c4e348b\", \"best_bid\":\"0.11\", \"best_ask\":\"0.12\"}, {\"asset_id\":\"60386828328910021732068595344565885737045900010034836345809386672230885527307\", \"price\":\"0.92\", \"size\":\"201.25\", \"side\":\"SELL\", \"hash\":\"5c060facede042bf7a47edc33bae6724eb2ce76a\", \"best_bid\":\"0.88\", \"best_ask\":\"0.89\"}], \"timestamp\":\"1785126799284\", \"event_type\":\"price_change\"}","received_at":"2026-07-27T04:33:19.229391Z","schema_version":"clob-market-ws.price_change.v1","sequence":null,"server_hash":null,"server_timestamp":"1785126799284","session_id":"e9443c7415a0419799bee9cfbb1a9e4d","source":"clob_market_ws"},"received_at":"2026-07-27T04:33:19.229391Z","record_id":"a493387f5ab44c391b15f33be408392e531148e3648e7d167113b378f9dc3fe4","schema_fingerprint":"4aa3821a28b0b7c2400bc59aba4bcc0a76e971dadd19610d3ad38c768e124dc7","schema_version":"edge-lab-recorder.raw.v1","sequence":null,"source":"clob_market_ws"}
{"event_at":"2026-07-27T04:33:19.294000Z","event_fingerprint":"ed43fa29ec66777cc87e711535e83d794ac47fb9da71821aa0c23df7e773a987","payload":{"connection_id":"0f4979d6978d463e9660b042fdcf555f","event_at":"2026-07-27T04:33:19.294000Z","event_type":"price_change","frame_hash":"675d369f9e15b158e22b742530dda805438ff70a67c9f5eb4976caf3cf001eb9","frame_index":0,"kind":"data","monotonic_ns":228782507992458,"payload":{"event_type":"price_change","market":"0xeb66215f2e9faa6449e30a02bab5b8ed7b79a38bf961f6b24d0073c9c2419250","price_changes":[{"asset_id":"60386828328910021732068595344565885737045900010034836345809386672230885527307","best_ask":"0.89","best_bid":"0.88","hash":"9ff28e3ed825f8f8bd884946e25ad458bdcddfc8","price":"0.01","side":"BUY","size":"7708.02"},{"asset_id":"69697746896130839564035629862476347944307040470122503199396727085502753297492","best_ask":"0.12","best_bid":"0.11","hash":"68098c2c718dde34c8193365f3cddbe72e2cbf11","price":"0.99","side":"SELL","size":"7708.02"}],"timestamp":"1785126799294"},"payload_hash":"5263a7af21236f142199166d84ea70daa8518b9872b0816a0c0d367340f28dba","raw_frame":"{\"market\":\"0xeb66215f2e9faa6449e30a02bab5b8ed7b79a38bf961f6b24d0073c9c2419250\", \"price_changes\":[{\"asset_id\":\"60386828328910021732068595344565885737045900010034836345809386672230885527307\", \"price\":\"0.01\", \"size\":\"7708.02\", \"side\":\"BUY\", \"hash\":\"9ff28e3ed825f8f8bd884946e25ad458bdcddfc8\", \"best_bid\":\"0.88\", \"best_ask\":\"0.89\"}, {\"asset_id\":\"69697746896130839564035629862476347944307040470122503199396727085502753297492\", \"price\":\"0.99\", \"size\":\"7708.02\", \"side\":\"SELL\", \"hash\":\"68098c2c718dde34c8193365f3cddbe72e2cbf11\", \"best_bid\":\"0.11\", \"best_ask\":\"0.12\"}], \"timestamp\":\"1785126799294\", \"event_type\":\"price_change\"}","received_at":"2026-07-27T04:33:19.239882Z","schema_version":"clob-market-ws.price_change.v1","sequence":null,"server_hash":null,"server_timestamp":"1785126799294","session_id":"e9443c7415a0419799bee9cfbb1a9e4d","source":"clob_market_ws"},"received_at":"2026-07-27T04:33:19.239882Z","record_id":"0455c97ca465dfd289f2404593339c276a719bf99d25932263200c37ea107084","schema_fingerprint":"4aa3821a28b0b7c2400bc59aba4bcc0a76e971dadd19610d3ad38c768e124dc7","schema_version":"edge-lab-recorder.raw.v1","sequence":null,"source":"clob_market_ws"}
{"event_at":"2026-07-27T04:33:19.299000Z","event_fingerprint":"e2c93071a63ff7b69a706124f811ecb87117fbed8ffa36ea890787f5cc489350","payload":{"connection_id":"0f4979d6978d463e9660b042fdcf555f","event_at":"2026-07-27T04:33:19.299000Z","event_type":"price_change","frame_hash":"71167d9894332fae32373875a6c6b765b008ccdf24254b29106358620bc82d3c","frame_index":0,"kind":"data","monotonic_ns":228782511474458,"payload":{"event_type":"price_change","market":"0xeb66215f2e9faa6449e30a02bab5b8ed7b79a38bf961f6b24d0073c9c2419250","price_changes":[{"asset_id":"60386828328910021732068595344565885737045900010034836345809386672230885527307","best_ask":"0.89","best_bid":"0.88","hash":"ba2c4fe1ce815a9aab2d03568be2e58e534b06ad","price":"0.04","side":"BUY","size":"633.09"},{"asset_id":"69697746896130839564035629862476347944307040470122503199396727085502753297492","best_ask":"0.12","best_bid":"0.11","hash":"e0a06fbe737b93f78beb497f877e48227de8fefc","price":"0.96","side":"SELL","size":"633.09"}],"timestamp":"1785126799299"},"payload_hash":"5ff88800e517e88a128f5cf3b5ca6d47426cd6020251fb23eb0ab1e5cdb0c840","raw_frame":"{\"market\":\"0xeb66215f2e9faa6449e30a02bab5b8ed7b79a38bf961f6b24d0073c9c2419250\", \"price_changes\":[{\"asset_id\":\"60386828328910021732068595344565885737045900010034836345809386672230885527307\", \"price\":\"0.04\", \"size\":\"633.09\", \"side\":\"BUY\", \"hash\":\"ba2c4fe1ce815a9aab2d03568be2e58e534b06ad\", \"best_bid\":\"0.88\", \"best_ask\":\"0.89\"}, {\"asset_id\":\"69697746896130839564035629862476347944307040470122503199396727085502753297492\", \"price\":\"0.96\", \"size\":\"633.09\", \"side\":\"SELL\", \"hash\":\"e0a06fbe737b93f78beb497f877e48227de8fefc\", \"best_bid\":\"0.11\", \"best_ask\":\"0.12\"}], \"timestamp\":\"1785126799299\", \"event_type\":\"price_change\"}","received_at":"2026-07-27T04:33:19.243358Z","schema_version":"clob-market-ws.price_change.v1","sequence":null,"server_hash":null,"server_timestamp":"1785126799299","session_id":"e9443c7415a0419799bee9cfbb1a9e4d","source":"clob_market_ws"},"received_at":"2026-07-27T04:33:19.243358Z","record_id":"4c57562477f1f64f273040233cff12266d2be48182d7a57893e48905ba65a91e","schema_fingerprint":"4aa3821a28b0b7c2400bc59aba4bcc0a76e971dadd19610d3ad38c768e124dc7","schema_version":"edge-lab-recorder.raw.v1","sequence":null,"source":"clob_market_ws"}
{"event_at":"2026-07-27T04:33:19.316000Z","event_fingerprint":"d8a10cc20b03e13ec5a4c5c9c833a71e28f81bf612510a6201b8636bc301b051","payload":{"connection_id":"0f4979d6978d463e9660b042fdcf555f","event_at":"2026-07-27T04:33:19.316000Z","event_type":"price_change","frame_hash":"b21c5cb0de29b62f390b4f060a6a52d5d1a20677b699f06c67d98c810f804aa8","frame_index":0,"kind":"data","monotonic_ns":228782529487041,"payload":{"event_type":"price_change","market":"0xeb66215f2e9faa6449e30a02bab5b8ed7b79a38bf961f6b24d0073c9c2419250","price_changes":[{"asset_id":"60386828328910021732068595344565885737045900010034836345809386672230885527307","best_ask":"0.89","best_bid":"0.88","hash":"e397b939efb36fa332c53571c39f04959c4fabf9","price":"0.01","side":"BUY","size":"7703.02"},{"asset_id":"69697746896130839564035629862476347944307040470122503199396727085502753297492","best_ask":"0.12","best_bid":"0.11","hash":"b9a64a3156e48d59692fa18120d0cf21ebc241a9","price":"0.99","side":"SELL","size":"7703.02"}],"timestamp":"1785126799316"},"payload_hash":"834f9ebe9ff637bfb59d44164c0966064721c818b8e1d6e550b7a895b23676cf","raw_frame":"{\"market\":\"0xeb66215f2e9faa6449e30a02bab5b8ed7b79a38bf961f6b24d0073c9c2419250\", \"price_changes\":[{\"asset_id\":\"60386828328910021732068595344565885737045900010034836345809386672230885527307\", \"price\":\"0.01\", \"size\":\"7703.02\", \"side\":\"BUY\", \"hash\":\"e397b939efb36fa332c53571c39f04959c4fabf9\", \"best_bid\":\"0.88\", \"best_ask\":\"0.89\"}, {\"asset_id\":\"69697746896130839564035629862476347944307040470122503199396727085502753297492\", \"price\":\"0.99\", \"size\":\"7703.02\", \"side\":\"SELL\", \"hash\":\"b9a64a3156e48d59692fa18120d0cf21ebc241a9\", \"best_bid\":\"0.11\", \"best_ask\":\"0.12\"}], \"timestamp\":\"1785126799316\", \"event_type\":\"price_change\"}","received_at":"2026-07-27T04:33:19.261376Z","schema_version":"clob-market-ws.price_change.v1","sequence":null,"server_hash":null,"server_timestamp":"1785126799316","session_id":"e9443c7415a0419799bee9cfbb1a9e4d","source":"clob_market_ws"},"received_at":"2026-07-27T04:33:19.261376Z","record_id":"5f6eb871b81102d77c2e16a89dc4c029f0c99a512ef5f323a7ab7300db2edbef","schema_fingerprint":"4aa3821a28b0b7c2400bc59aba4bcc0a76e971dadd19610d3ad38c768e124dc7","schema_version":"edge-lab-recorder.raw.v1","sequence":null,"source":"clob_market_ws"}
{"event_at":"2026-07-27T04:33:19.323000Z","event_fingerprint":"8b38567498df7527ef317f73ccf4c8f9af8cca57bd064bfa8a488b173ef259a3","payload":{"connection_id":"0f4979d6978d463e9660b042fdcf555f","event_at":"2026-07-27T04:33:19.323000Z","event_type":"price_change","frame_hash":"d19ec1f58a3e73157321371d9129ec5faad065d5b6157005b0653fc99556d39f","frame_index":0,"kind":"data","monotonic_ns":228782536494000,"payload":{"event_type":"price_change","market":"0xeb66215f2e9faa6449e30a02bab5b8ed7b79a38bf961f6b24d0073c9c2419250","price_changes":[{"asset_id":"69697746896130839564035629862476347944307040470122503199396727085502753297492","best_ask":"0.12","best_bid":"0.11","hash":"08abb83331cd097cb56944694d8356c84bcfaeb5","price":"0.1","side":"BUY","size":"141"},{"asset_id":"60386828328910021732068595344565885737045900010034836345809386672230885527307","best_ask":"0.89","best_bid":"0.88","hash":"90d2607a80445ecc1748ba34465d0b2d42570099","price":"0.9","side":"SELL","size":"141"}],"timestamp":"1785126799323"},"payload_hash":"02f8e50abeea19daf79522d5b933367662379344267bcdd04d1921a967f7a1c7","raw_frame":"{\"market\":\"0xeb66215f2e9faa6449e30a02bab5b8ed7b79a38bf961f6b24d0073c9c2419250\", \"price_changes\":[{\"asset_id\":\"69697746896130839564035629862476347944307040470122503199396727085502753297492\", \"price\":\"0.1\", \"size\":\"141\", \"side\":\"BUY\", \"hash\":\"08abb83331cd097cb56944694d8356c84bcfaeb5\", \"best_bid\":\"0.11\", \"best_ask\":\"0.12\"}, {\"asset_id\":\"60386828328910021732068595344565885737045900010034836345809386672230885527307\", \"price\":\"0.9\", \"size\":\"141\", \"side\":\"SELL\", \"hash\":\"90d2607a80445ecc1748ba34465d0b2d42570099\", \"best_bid\":\"0.88\", \"best_ask\":\"0.89\"}], \"timestamp\":\"1785126799323\", \"event_type\":\"price_change\"}","received_at":"2026-07-27T04:33:19.268376Z","schema_version":"clob-market-ws.price_change.v1","sequence":null,"server_hash":null,"server_timestamp":"1785126799323","session_id":"e9443c7415a0419799bee9cfbb1a9e4d","source":"clob_market_ws"},"received_at":"2026-07-27T04:33:19.268376Z","record_id":"7f6cc3c1debef6ac2240b1eaa89d5d6807876abef584b19592a6f9d8944d6dc7","schema_fingerprint":"4aa3821a28b0b7c2400bc59aba4bcc0a76e971dadd19610d3ad38c768e124dc7","schema_version":"edge-lab-recorder.raw.v1","sequence":null,"source":"clob_market_ws"}
{"event_at":"2026-07-27T04:33:19.325000Z","event_fingerprint":"dd0c042c4477f51413a3cc4102fb3fa4c47e342810418ba864b48cea1cf5cbd6","payload":{"connection_id":"0f4979d6978d463e9660b042fdcf555f","event_at":"2026-07-27T04:33:19.325000Z","event_type":"price_change","frame_hash":"197ac71db0d8268faa9f46d148159a2cf44a738eb8a3dcea906ca11d3b00e272","frame_index":0,"kind":"data","monotonic_ns":228782538612416,"payload":{"event_type":"price_change","market":"0xeb66215f2e9faa6449e30a02bab5b8ed7b79a38bf961f6b24d0073c9c2419250","price_changes":[{"asset_id":"69697746896130839564035629862476347944307040470122503199396727085502753297492","best_ask":"0.12","best_bid":"0.11","hash":"9e4857290f09dba769a9c19a8c88b365dd46ef15","price":"0.11","side":"BUY","size":"477.36"},{"asset_id":"60386828328910021732068595344565885737045900010034836345809386672230885527307","best_ask":"0.89","best_bid":"0.88","hash":"204cb97ee9900c6087a73c94825fae0cf14c2216","price":"0.89","side":"SELL","size":"477.36"}],"timestamp":"1785126799325"},"payload_hash":"717e60e72eb9d6ba6ec5cbc7696a1e899ee7e5786b47164b78a754589009ba41","raw_frame":"{\"market\":\"0xeb66215f2e9faa6449e30a02bab5b8ed7b79a38bf961f6b24d0073c9c2419250\", \"price_changes\":[{\"asset_id\":\"69697746896130839564035629862476347944307040470122503199396727085502753297492\", \"price\":\"0.11\", \"size\":\"477.36\", \"side\":\"BUY\", \"hash\":\"9e4857290f09dba769a9c19a8c88b365dd46ef15\", \"best_bid\":\"0.11\", \"best_ask\":\"0.12\"}, {\"asset_id\":\"60386828328910021732068595344565885737045900010034836345809386672230885527307\", \"price\":\"0.89\", \"size\":\"477.36\", \"side\":\"SELL\", \"hash\":\"204cb97ee9900c6087a73c94825fae0cf14c2216\", \"best_bid\":\"0.88\", \"best_ask\":\"0.89\"}], \"timestamp\":\"1785126799325\", \"event_type\":\"price_change\"}","received_at":"2026-07-27T04:33:19.270501Z","schema_version":"clob-market-ws.price_change.v1","sequence":null,"server_hash":null,"server_timestamp":"1785126799325","session_id":"e9443c7415a0419799bee9cfbb1a9e4d","source":"clob_market_ws"},"received_at":"2026-07-27T04:33:19.270501Z","record_id":"febc0454b49ca5e3792dd356b4c3027e2af3391c63428c8d95f09556856c69c4","schema_fingerprint":"4aa3821a28b0b7c2400bc59aba4bcc0a76e971dadd19610d3ad38c768e124dc7","schema_version":"edge-lab-recorder.raw.v1","sequence":null,"source":"clob_market_ws"}
{"event_at":"2026-07-27T04:33:19.348000Z","event_fingerprint":"5929cee1ab419afd9f75178cd305ba5c6db6b7b9b16a742745c5d6c71ad81632","payload":{"connection_id":"0f4979d6978d463e9660b042fdcf555f","event_at":"2026-07-27T04:33:19.348000Z","event_type":"price_change","frame_hash":"e7c9273a694fd7140d9b7b28d42eec2c044c88e66ee77a04007994cc91397474","frame_index":0,"kind":"data","monotonic_ns":228782561520541,"payload":{"event_type":"price_change","market":"0xeb66215f2e9faa6449e30a02bab5b8ed7b79a38bf961f6b24d0073c9c2419250","price_changes":[{"asset_id":"60386828328910021732068595344565885737045900010034836345809386672230885527307","best_ask":"0.89","best_bid":"0.88","hash":"7654dae2fc3767bb9fd35d7c1eb396931c6cec9e","price":"0.04","side":"BUY","size":"628.09"},{"asset_id":"69697746896130839564035629862476347944307040470122503199396727085502753297492","best_ask":"0.12","best_bid":"0.11","hash":"1decf91535684950b4519261fd7d05dcce7ddea0","price":"0.96","side":"SELL","size":"628.09"}],"timestamp":"1785126799348"},"payload_hash":"bbde54f2f79d460fe434c3dd8d1eca6454c6c56dfba95c223d6989bf9859b4ca","raw_frame":"{\"market\":\"0xeb66215f2e9faa6449e30a02bab5b8ed7b79a38bf961f6b24d0073c9c2419250\", \"price_changes\":[{\"asset_id\":\"60386828328910021732068595344565885737045900010034836345809386672230885527307\", \"price\":\"0.04\", \"size\":\"628.09\", \"side\":\"BUY\", \"hash\":\"7654dae2fc3767bb9fd35d7c1eb396931c6cec9e\", \"best_bid\":\"0.88\", \"best_ask\":\"0.89\"}, {\"asset_id\":\"69697746896130839564035629862476347944307040470122503199396727085502753297492\", \"price\":\"0.96\", \"size\":\"628.09\", \"side\":\"SELL\", \"hash\":\"1decf91535684950b4519261fd7d05dcce7ddea0\", \"best_bid\":\"0.11\", \"best_ask\":\"0.12\"}], \"timestamp\":\"1785126799348\", \"event_type\":\"price_change\"}","received_at":"2026-07-27T04:33:19.293409Z","schema_version":"clob-market-ws.price_change.v1","sequence":null,"server_hash":null,"server_timestamp":"1785126799348","session_id":"e9443c7415a0419799bee9cfbb1a9e4d","source":"clob_market_ws"},"received_at":"2026-07-27T04:33:19.293409Z","record_id":"ec0e610d645de35dce6fa55433351b950d6ee74274f3e7e1331ca7c1babc7177","schema_fingerprint":"4aa3821a28b0b7c2400bc59aba4bcc0a76e971dadd19610d3ad38c768e124dc7","schema_version":"edge-lab-recorder.raw.v1","sequence":null,"source":"clob_market_ws"}
