{"event_at":"2026-07-27T04:39:52.894000Z","event_fingerprint":"dd8f79117303e257557dafb1848fcd655a6093bcbe30122a89ab0567abefbcb9","payload":{"connection_id":"0f4979d6978d463e9660b042fdcf555f","event_at":"2026-07-27T04:39:52.894000Z","event_type":"price_change","frame_hash":"4251b07ed4cf05d3058b34a292581162c7f44c32025bd92eb3b8882e936d683e","frame_index":0,"kind":"data","monotonic_ns":229176126647375,"payload":{"event_type":"price_change","market":"0xeb66215f2e9faa6449e30a02bab5b8ed7b79a38bf961f6b24d0073c9c2419250","price_changes":[{"asset_id":"60386828328910021732068595344565885737045900010034836345809386672230885527307","best_ask":"0.34","best_bid":"0.33","hash":"0be4b8dbbbea8dbf467500264457b909800422c4","price":"0.4","side":"SELL","size":"70.41"},{"asset_id":"69697746896130839564035629862476347944307040470122503199396727085502753297492","best_ask":"0.67","best_bid":"0.66","hash":"c583a6a7b8225dcec161103958e93a2a4defabab","price":"0.6","side":"BUY","size":"70.41"}],"timestamp":"1785127192894"},"payload_hash":"796ec6cd0e8125a94dc905f70f0ff9c0d5dd1a8a4c71e5e19f89ae1d37ce7dcc","raw_frame":"{\"market\":\"0xeb66215f2e9faa6449e30a02bab5b8ed7b79a38bf961f6b24d0073c9c2419250\", \"price_changes\":[{\"asset_id\":\"60386828328910021732068595344565885737045900010034836345809386672230885527307\", \"price\":\"0.4\", \"size\":\"70.41\", \"side\":\"SELL\", \"hash\":\"0be4b8dbbbea8dbf467500264457b909800422c4\", \"best_bid\":\"0.33\", \"best_ask\":\"0.34\"}, {\"asset_id\":\"69697746896130839564035629862476347944307040470122503199396727085502753297492\", \"price\":\"0.6\", \"size\":\"70.41\", \"side\":\"BUY\", \"hash\":\"c583a6a7b8225dcec161103958e93a2a4defabab\", \"best_bid\":\"0.66\", \"best_ask\":\"0.67\"}], \"timestamp\":\"1785127192894\", \"event_type\":\"price_change\"}","received_at":"2026-07-27T04:39:52.861941Z","schema_version":"clob-market-ws.price_change.v1","sequence":null,"server_hash":null,"server_timestamp":"1785127192894","session_id":"e9443c7415a0419799bee9cfbb1a9e4d","source":"clob_market_ws"},"received_at":"2026-07-27T04:39:52.861941Z","record_id":"aa49fdecc4ff98f1780f5d74737039010fbc40b343f6a9e505b399c2c37d690a","schema_fingerprint":"4aa3821a28b0b7c2400bc59aba4bcc0a76e971dadd19610d3ad38c768e124dc7","schema_version":"edge-lab-recorder.raw.v1","sequence":null,"source":"clob_market_ws"}
{"event_at":"2026-07-27T04:39:52.901000Z","event_fingerprint":"5704374eb1db473e6edddaf4c45339ddf810ead48f0972da60b1c04ca0999fbb","payload":{"connection_id":"0f4979d6978d463e9660b042fdcf555f","event_at":"2026-07-27T04:39:52.901000Z","event_type":"price_change","frame_hash":"0c986e0bce37324e0ad035f04085327246bcaffb2a93529a93bbab4999545d4f","frame_index":0,"kind":"data","monotonic_ns":229176129144333,"payload":{"event_type":"price_change","market":"0xeb66215f2e9faa6449e30a02bab5b8ed7b79a38bf961f6b24d0073c9c2419250","price_changes":[{"asset_id":"69697746896130839564035629862476347944307040470122503199396727085502753297492","best_ask":"0.67","best_bid":"0.66","hash":"f7d8382e5d70d7f5ff606e2a44fbd8697b0dcf65","price":"0.01","side":"BUY","size":"5638.02"},{"asset_id":"60386828328910021732068595344565885737045900010034836345809386672230885527307","best_ask":"0.34","best_bid":"0.33","hash":"b120f1f80188b2dbdff73f36e684adf9b823af20","price":"0.99","side":"SELL","size":"5638.02"}],"timestamp":"1785127192901"},"payload_hash":"5f2b2586fa346ad94e5a60a71ad8a139c10258c4327d871fccdb3eae56921248","raw_frame":"{\"market\":\"0xeb66215f2e9faa6449e30a02bab5b8ed7b79a38bf961f6b24d0073c9c2419250\", \"price_changes\":[{\"asset_id\":\"69697746896130839564035629862476347944307040470122503199396727085502753297492\", \"price\":\"0.01\", \"size\":\"5638.02\", \"side\":\"BUY\", \"hash\":\"f7d8382e5d70d7f5ff606e2a44fbd8697b0dcf65\", \"best_bid\":\"0.66\", \"best_ask\":\"0.67\"}, {\"asset_id\":\"60386828328910021732068595344565885737045900010034836345809386672230885527307\", \"price\":\"0.99\", \"size\":\"5638.02\", \"side\":\"SELL\", \"hash\":\"b120f1f80188b2dbdff73f36e684adf9b823af20\", \"best_bid\":\"0.33\", \"best_ask\":\"0.34\"}], \"timestamp\":\"1785127192901\", \"event_type\":\"price_change\"}","received_at":"2026-07-27T04:39:52.864448Z","schema_version":"clob-market-ws.price_change.v1","sequence":null,"server_hash":null,"server_timestamp":"1785127192901","session_id":"e9443c7415a0419799bee9cfbb1a9e4d","source":"clob_market_ws"},"received_at":"2026-07-27T04:39:52.864448Z","record_id":"fd2d8d8be0374c8f8bdbfba8df9d60d1d39ab46214593639d2e923d56a9a7813","schema_fingerprint":"4aa3821a28b0b7c2400bc59aba4bcc0a76e971dadd19610d3ad38c768e124dc7","schema_version":"edge-lab-recorder.raw.v1","sequence":null,"source":"clob_market_ws"}
{"event_at":"2026-07-27T04:39:53.003000Z","event_fingerprint":"99e3f409b34d267772d1104b57ad07723afb4c0322ac01357e50a49a14d68880","payload":{"connection_id":"0f4979d6978d463e9660b042fdcf555f","event_at":"2026-07-27T04:39:53.003000Z","event_type":"price_change","frame_hash":"d4a59972a3498bba702061e8e317b44b0f602c63c59058a2709bb38ec620bd38","frame_index":0,"kind":"data","monotonic_ns":229176215607041,"payload":{"event_type":"price_change","market":"0xeb66215f2e9faa6449e30a02bab5b8ed7b79a38bf961f6b24d0073c9c2419250","price_changes":[{"asset_id":"69697746896130839564035629862476347944307040470122503199396727085502753297492","best_ask":"0.67","best_bid":"0.66","hash":"b66d4013d1304a6e317f48352af7b08311cc5bee","price":"0.01","side":"BUY","size":"5643.02"},{"asset_id":"60386828328910021732068595344565885737045900010034836345809386672230885527307","best_ask":"0.34","best_bid":"0.33","hash":"ff1738514f5b119f05d218c65b93ec731bcf3800","price":"0.99","side":"SELL","size":"5643.02"}],"timestamp":"1785127193003"},"payload_hash":"9cead220e3dc38ff11592580cee3c1cdf67107ce035fdcfec2732e4fb6afd7e3","raw_frame":"{\"market\":\"0xeb66215f2e9faa6449e30a02bab5b8ed7b79a38bf961f6b24d0073c9c2419250\", \"price_changes\":[{\"asset_id\":\"69697746896130839564035629862476347944307040470122503199396727085502753297492\", \"price\":\"0.01\", \"size\":\"5643.02\", \"side\":\"BUY\", \"hash\":\"b66d4013d1304a6e317f48352af7b08311cc5bee\", \"best_bid\":\"0.66\", \"best_ask\":\"0.67\"}, {\"asset_id\":\"60386828328910021732068595344565885737045900010034836345809386672230885527307\", \"price\":\"0.99\", \"size\":\"5643.02\", \"side\":\"SELL\", \"hash\":\"ff1738514f5b119f05d218c65b93ec731bcf3800\", \"best_bid\":\"0.33\", \"best_ask\":\"0.34\"}], \"timestamp\":\"1785127193003\", \"event_type\":\"price_change\"}","received_at":"2026-07-27T04:39:52.950910Z","schema_version":"clob-market-ws.price_change.v1","sequence":null,"server_hash":null,"server_timestamp":"1785127193003","session_id":"e9443c7415a0419799bee9cfbb1a9e4d","source":"clob_market_ws"},"received_at":"2026-07-27T04:39:52.950910Z","record_id":"09db2549364be7e70c42306d1aa499551315d7817d9c03b19b4b1d9a0f0c9cc5","schema_fingerprint":"4aa3821a28b0b7c2400bc59aba4bcc0a76e971dadd19610d3ad38c768e124dc7","schema_version":"edge-lab-recorder.raw.v1","sequence":null,"source":"clob_market_ws"}
{"event_at":"2026-07-27T04:39:53.005000Z","event_fingerprint":"c16e4398107712edc10b7411e4e8d1122b7fca28dba3eddc01d9072f1c86835e","payload":{"connection_id":"0f4979d6978d463e9660b042fdcf555f","event_at":"2026-07-27T04:39:53.005000Z","event_type":"price_change","frame_hash":"c7e02eb58e675415d49bb485fa318b4251bcdc23e5102f633f19af15a1569a57","frame_index":0,"kind":"data","monotonic_ns":229176219662166,"payload":{"event_type":"price_change","market":"0xeb66215f2e9faa6449e30a02bab5b8ed7b79a38bf961f6b24d0073c9c2419250","price_changes":[{"asset_id":"69697746896130839564035629862476347944307040470122503199396727085502753297492","best_ask":"0.67","best_bid":"0.66","hash":"dafa9506994e71dc57c89850c6f236ac593bbf06","price":"0.01","side":"BUY","size":"5638.02"},{"asset_id":"60386828328910021732068595344565885737045900010034836345809386672230885527307","best_ask":"0.34","best_bid":"0.33","hash":"4a0637463a08258131a267c601d86022e7421753","price":"0.99","side":"SELL","size":"5638.02"}],"timestamp":"1785127193005"},"payload_hash":"54a77bec17695e289bcf95064f94df63aed56845693201719c5b0ddbd5892851","raw_frame":"{\"market\":\"0xeb66215f2e9faa6449e30a02bab5b8ed7b79a38bf961f6b24d0073c9c2419250\", \"price_changes\":[{\"asset_id\":\"69697746896130839564035629862476347944307040470122503199396727085502753297492\", \"price\":\"0.01\", \"size\":\"5638.02\", \"side\":\"BUY\", \"hash\":\"dafa9506994e71dc57c89850c6f236ac593bbf06\", \"best_bid\":\"0.66\", \"best_ask\":\"0.67\"}, {\"asset_id\":\"60386828328910021732068595344565885737045900010034836345809386672230885527307\", \"price\":\"0.99\", \"size\":\"5638.02\", \"side\":\"SELL\", \"hash\":\"4a0637463a08258131a267c601d86022e7421753\", \"best_bid\":\"0.33\", \"best_ask\":\"0.34\"}], \"timestamp\":\"1785127193005\", \"event_type\":\"price_change\"}","received_at":"2026-07-27T04:39:52.954962Z","schema_version":"clob-market-ws.price_change.v1","sequence":null,"server_hash":null,"server_timestamp":"1785127193005","session_id":"e9443c7415a0419799bee9cfbb1a9e4d","source":"clob_market_ws"},"received_at":"2026-07-27T04:39:52.954962Z","record_id":"2812dc0453502f0290f9eb40497e7c3a0ce961a1b91e1d91f128b8afcb0ff1d2","schema_fingerprint":"4aa3821a28b0b7c2400bc59aba4bcc0a76e971dadd19610d3ad38c768e124dc7","schema_version":"edge-lab-recorder.raw.v1","sequence":null,"source":"clob_market_ws"}
{"event_at":"2026-07-27T04:39:53.021000Z","event_fingerprint":"7964206636f7962c7f88897bbe9d32bc17b90c727b024dcef6fb7ef495399b6b","payload":{"connection_id":"0f4979d6978d463e9660b042fdcf555f","event_at":"2026-07-27T04:39:53.021000Z","event_type":"price_change","frame_hash":"3c63d7b41da56a478387a97b5a1d9d281aeb1a6b046c07de70bc61cc5e18e0fd","frame_index":0,"kind":"data","monotonic_ns":229176236437000,"payload":{"event_type":"price_change","market":"0xeb66215f2e9faa6449e30a02bab5b8ed7b79a38bf961f6b24d0073c9c2419250","price_changes":[{"asset_id":"60386828328910021732068595344565885737045900010034836345809386672230885527307","best_ask":"0.34","best_bid":"0.33","hash":"5d825574f7b18ccde21fd3c76c44d7ccfb1fec44","price":"0.25","side":"BUY","size":"235"},{"asset_id":"69697746896130839564035629862476347944307040470122503199396727085502753297492","best_ask":"0.67","best_bid":"0.66","hash":"b11cb53d8c9d1de69cc58e9fb4c54f290d8cbb53","price":"0.75","side":"SELL","size":"235"}],"timestamp":"1785127193021"},"payload_hash":"931d88a0893b6c07cf3f352dff0fba795a7e8d7d7d7c53618aa9073dec5200b3","raw_frame":"{\"market\":\"0xeb66215f2e9faa6449e30a02bab5b8ed7b79a38bf961f6b24d0073c9c2419250\", \"price_changes\":[{\"asset_id\":\"60386828328910021732068595344565885737045900010034836345809386672230885527307\", \"price\":\"0.25\", \"size\":\"235\", \"side\":\"BUY\", \"hash\":\"5d825574f7b18ccde21fd3c76c44d7ccfb1fec44\", \"best_bid\":\"0.33\", \"best_ask\":\"0.34\"}, {\"asset_id\":\"69697746896130839564035629862476347944307040470122503199396727085502753297492\", \"price\":\"0.75\", \"size\":\"235\", \"side\":\"SELL\", \"hash\":\"b11cb53d8c9d1de69cc58e9fb4c54f290d8cbb53\", \"best_bid\":\"0.66\", \"best_ask\":\"0.67\"}], \"timestamp\":\"1785127193021\", \"event_type\":\"price_change\"}","received_at":"2026-07-27T04:39:52.971740Z","schema_version":"clob-market-ws.price_change.v1","sequence":null,"server_hash":null,"server_timestamp":"1785127193021","session_id":"e9443c7415a0419799bee9cfbb1a9e4d","source":"clob_market_ws"},"received_at":"2026-07-27T04:39:52.971740Z","record_id":"e18e0d38477108cd00830faa2ff5b8ae21691fd1cd112415b80ae3b01f74ecb8","schema_fingerprint":"4aa3821a28b0b7c2400bc59aba4bcc0a76e971dadd19610d3ad38c768e124dc7","schema_version":"edge-lab-recorder.raw.v1","sequence":null,"source":"clob_market_ws"}
{"event_at":"2026-07-27T04:39:53.021000Z","event_fingerprint":"19c4932e778e5d73920ff20f3cdaafe719074e235c250c29520ca6b59ee1d60b","payload":{"connection_id":"0f4979d6978d463e9660b042fdcf555f","event_at":"2026-07-27T04:39:53.021000Z","event_type":"price_change","frame_hash":"a9051cdb6c37cf49aa257e8875e2082007221d09e4efb7b87c9a06a9f282f404","frame_index":0,"kind":"data","monotonic_ns":229176239588208,"payload":{"event_type":"price_change","market":"0xeb66215f2e9faa6449e30a02bab5b8ed7b79a38bf961f6b24d0073c9c2419250","price_changes":[{"asset_id":"69697746896130839564035629862476347944307040470122503199396727085502753297492","best_ask":"0.67","best_bid":"0.66","hash":"98b2c2a8e44761e930e56693b241784bffbabba4","price":"0.58","side":"BUY","size":"47.3"},{"asset_id":"60386828328910021732068595344565885737045900010034836345809386672230885527307","best_ask":"0.34","best_bid":"0.33","hash":"c9d9eca824b1073acdb4daf65b491422fc27342a","price":"0.42","side":"SELL","size":"47.3"}],"timestamp":"1785127193021"},"payload_hash":"f3cf1274cf69082c3a811f33e6f9c1ab988c91466bd95b8c13313bb3e2bc9cca","raw_frame":"{\"market\":\"0xeb66215f2e9faa6449e30a02bab5b8ed7b79a38bf961f6b24d0073c9c2419250\", \"price_changes\":[{\"asset_id\":\"69697746896130839564035629862476347944307040470122503199396727085502753297492\", \"price\":\"0.58\", \"size\":\"47.3\", \"side\":\"BUY\", \"hash\":\"98b2c2a8e44761e930e56693b241784bffbabba4\", \"best_bid\":\"0.66\", \"best_ask\":\"0.67\"}, {\"asset_id\":\"60386828328910021732068595344565885737045900010034836345809386672230885527307\", \"price\":\"0.42\", \"size\":\"47.3\", \"side\":\"SELL\", \"hash\":\"c9d9eca824b1073acdb4daf65b491422fc27342a\", \"best_bid\":\"0.33\", \"best_ask\":\"0.34\"}], \"timestamp\":\"1785127193021\", \"event_type\":\"price_change\"}","received_at":"2026-07-27T04:39:52.974892Z","schema_version":"clob-market-ws.price_change.v1","sequence":null,"server_hash":null,"server_timestamp":"1785127193021","session_id":"e9443c7415a0419799bee9cfbb1a9e4d","source":"clob_market_ws"},"received_at":"2026-07-27T04:39:52.974892Z","record_id":"e836a94c1e2b151abdbef9bfeb4e58f0a9cf59b5603a0435cbdd53ca7f9860a8","schema_fingerprint":"4aa3821a28b0b7c2400bc59aba4bcc0a76e971dadd19610d3ad38c768e124dc7","schema_version":"edge-lab-recorder.raw.v1","sequence":null,"source":"clob_market_ws"}
{"event_at":"2026-07-27T04:39:53.023000Z","event_fingerprint":"6e0d290a6f73e1073ec8b81c954c59b4a485f870a0bad0bf9ac57bdd41708be1","payload":{"connection_id":"0f4979d6978d463e9660b042fdcf555f","event_at":"2026-07-27T04:39:53.023000Z","event_type":"price_change","frame_hash":"cd308bb12220d51108adc5a5987da9a3f1785bb7201996f8cd90a4d2142fe374","frame_index":0,"kind":"data","monotonic_ns":229176243513083,"payload":{"event_type":"price_change","market":"0xeb66215f2e9faa6449e30a02bab5b8ed7b79a38bf961f6b24d0073c9c2419250","price_changes":[{"asset_id":"60386828328910021732068595344565885737045900010034836345809386672230885527307","best_ask":"0.34","best_bid":"0.33","hash":"9c9177feacd29cd577d9aca8da2821b70ee391c9","price":"0.01","side":"BUY","size":"5598.02"},{"asset_id":"69697746896130839564035629862476347944307040470122503199396727085502753297492","best_ask":"0.67","best_bid":"0.66","hash":"d6aa7f7425283eba0216fbcb0d7a738c5bf95f6a","price":"0.99","side":"SELL","size":"5598.02"}],"timestamp":"1785127193023"},"payload_hash":"236bb222ff5cedf162da053b8249057f01505ea1f2b1bf9056d9eb792281b98c","raw_frame":"{\"market\":\"0xeb66215f2e9faa6449e30a02bab5b8ed7b79a38bf961f6b24d0073c9c2419250\", \"price_changes\":[{\"asset_id\":\"60386828328910021732068595344565885737045900010034836345809386672230885527307\", \"price\":\"0.01\", \"size\":\"5598.02\", \"side\":\"BUY\", \"hash\":\"9c9177feacd29cd577d9aca8da2821b70ee391c9\", \"best_bid\":\"0.33\", \"best_ask\":\"0.34\"}, {\"asset_id\":\"69697746896130839564035629862476347944307040470122503199396727085502753297492\", \"price\":\"0.99\", \"size\":\"5598.02\", \"side\":\"SELL\", \"hash\":\"d6aa7f7425283eba0216fbcb0d7a738c5bf95f6a\", \"best_bid\":\"0.66\", \"best_ask\":\"0.67\"}], \"timestamp\":\"1785127193023\", \"event_type\":\"price_change\"}","received_at":"2026-07-27T04:39:52.978820Z","schema_version":"clob-market-ws.price_change.v1","sequence":null,"server_hash":null,"server_timestamp":"1785127193023","session_id":"e9443c7415a0419799bee9cfbb1a9e4d","source":"clob_market_ws"},"received_at":"2026-07-27T04:39:52.978820Z","record_id":"87c2b3faab1b5344a117845c4dd24d5a27f048d4dc2c760e4d7510cab0721df5","schema_fingerprint":"4aa3821a28b0b7c2400bc59aba4bcc0a76e971dadd19610d3ad38c768e124dc7","schema_version":"edge-lab-recorder.raw.v1","sequence":null,"source":"clob_market_ws"}
{"event_at":"2026-07-27T04:39:53.025000Z","event_fingerprint":"92907c8300162cb7e434dcc3f56b75e425096f32602c13fd4536a1530bf51771","payload":{"connection_id":"0f4979d6978d463e9660b042fdcf555f","event_at":"2026-07-27T04:39:53.025000Z","event_type":"price_change","frame_hash":"4af9bd5132b9d4e68eaec4c5fd7a3803e2385812f1c33c8033bf12c43e4e3383","frame_index":0,"kind":"data","monotonic_ns":229176247357416,"payload":{"event_type":"price_change","market":"0xeb66215f2e9faa6449e30a02bab5b8ed7b79a38bf961f6b24d0073c9c2419250","price_changes":[{"asset_id":"60386828328910021732068595344565885737045900010034836345809386672230885527307","best_ask":"0.34","best_bid":"0.33","hash":"067d0ee40630fa3d4d3ea6cce9bbb9b261589202","price":"0.01","side":"BUY","size":"5603.02"},{"asset_id":"69697746896130839564035629862476347944307040470122503199396727085502753297492","best_ask":"0.67","best_bid":"0.66","hash":"ad6067a1faec5b55fa20de47f5f122b18a68a752","price":"0.99","side":"SELL","size":"5603.02"}],"timestamp":"1785127193025"},"payload_hash":"205b72d4d9a3998e50e4332dea7705b9e5c3859a8a6c91bcc3968afa26f88b96","raw_frame":"{\"market\":\"0xeb66215f2e9faa6449e30a02bab5b8ed7b79a38bf961f6b24d0073c9c2419250\", \"price_changes\":[{\"asset_id\":\"60386828328910021732068595344565885737045900010034836345809386672230885527307\", \"price\":\"0.01\", \"size\":\"5603.02\", \"side\":\"BUY\", \"hash\":\"067d0ee40630fa3d4d3ea6cce9bbb9b261589202\", \"best_bid\":\"0.33\", \"best_ask\":\"0.34\"}, {\"asset_id\":\"69697746896130839564035629862476347944307040470122503199396727085502753297492\", \"price\":\"0.99\", \"size\":\"5603.02\", \"side\":\"SELL\", \"hash\":\"ad6067a1faec5b55fa20de47f5f122b18a68a752\", \"best_bid\":\"0.66\", \"best_ask\":\"0.67\"}], \"timestamp\":\"1785127193025\", \"event_type\":\"price_change\"}","received_at":"2026-07-27T04:39:52.982663Z","schema_version":"clob-market-ws.price_change.v1","sequence":null,"server_hash":null,"server_timestamp":"1785127193025","session_id":"e9443c7415a0419799bee9cfbb1a9e4d","source":"clob_market_ws"},"received_at":"2026-07-27T04:39:52.982663Z","record_id":"8cabb85db23acc0e428dff48d6ac4cc8dd28d697fc90cfd9d8a88c0ddd43c72c","schema_fingerprint":"4aa3821a28b0b7c2400bc59aba4bcc0a76e971dadd19610d3ad38c768e124dc7","schema_version":"edge-lab-recorder.raw.v1","sequence":null,"source":"clob_market_ws"}
{"event_at":"2026-07-27T04:39:53.026000Z","event_fingerprint":"9a4885af9f7e2bdd042c63e8607c15c0aeb3d046c5de31e955dac4731fa7f675","payload":{"connection_id":"0f4979d6978d463e9660b042fdcf555f","event_at":"2026-07-27T04:39:53.026000Z","event_type":"price_change","frame_hash":"d7e92fff857dbf9264da8f8ac79441671c4c7df5a093c130182da387de8c674e","frame_index":0,"kind":"data","monotonic_ns":229176250458666,"payload":{"event_type":"price_change","market":"0xeb66215f2e9faa6449e30a02bab5b8ed7b79a38bf961f6b24d0073c9c2419250","price_changes":[{"asset_id":"69697746896130839564035629862476347944307040470122503199396727085502753297492","best_ask":"0.67","best_bid":"0.66","hash":"70f1aab6febae8b0bfe2a217d39dcdbeea8ff221","price":"0.01","side":"BUY","size":"5633.02"},{"asset_id":"60386828328910021732068595344565885737045900010034836345809386672230885527307","best_ask":"0.34","best_bid":"0.33","hash":"36ce46b593d0d7cde923059abcaa75f1ec2cebee","price":"0.99","side":"SELL","size":"5633.02"}],"timestamp":"1785127193026"},"payload_hash":"f4b45d82e404baf120839cbda01ced579c77f8aefb233f1e227e1d8dd68c68bd","raw_frame":"{\"market\":\"0xeb66215f2e9faa6449e30a02bab5b8ed7b79a38bf961f6b24d0073c9c2419250\", \"price_changes\":[{\"asset_id\":\"69697746896130839564035629862476347944307040470122503199396727085502753297492\", \"price\":\"0.01\", \"size\":\"5633.02\", \"side\":\"BUY\", \"hash\":\"70f1aab6febae8b0bfe2a217d39dcdbeea8ff221\", \"best_bid\":\"0.66\", \"best_ask\":\"0.67\"}, {\"asset_id\":\"60386828328910021732068595344565885737045900010034836345809386672230885527307\", \"price\":\"0.99\", \"size\":\"5633.02\", \"side\":\"SELL\", \"hash\":\"36ce46b593d0d7cde923059abcaa75f1ec2cebee\", \"best_bid\":\"0.33\", \"best_ask\":\"0.34\"}], \"timestamp\":\"1785127193026\", \"event_type\":\"price_change\"}","received_at":"2026-07-27T04:39:52.985762Z","schema_version":"clob-market-ws.price_change.v1","sequence":null,"server_hash":null,"server_timestamp":"1785127193026","session_id":"e9443c7415a0419799bee9cfbb1a9e4d","source":"clob_market_ws"},"received_at":"2026-07-27T04:39:52.985762Z","record_id":"bf65b6bbdd6fce48067516adc5e4353ef9a777de324ad77a4d31609e16dee081","schema_fingerprint":"4aa3821a28b0b7c2400bc59aba4bcc0a76e971dadd19610d3ad38c768e124dc7","schema_version":"edge-lab-recorder.raw.v1","sequence":null,"source":"clob_market_ws"}
{"event_at":"2026-07-27T04:39:53.026000Z","event_fingerprint":"9d11407f48b9a1096ebd14ba98c70d1500d4ab800b0e74256565640848652dc8","payload":{"connection_id":"0f4979d6978d463e9660b042fdcf555f","event_at":"2026-07-27T04:39:53.026000Z","event_type":"price_change","frame_hash":"9977d1a570baf0e21025c861bebebecd4fb2e2fe631844df8249faa51a0c5b5a","frame_index":0,"kind":"data","monotonic_ns":229176252685916,"payload":{"event_type":"price_change","market":"0xeb66215f2e9faa6449e30a02bab5b8ed7b79a38bf961f6b24d0073c9c2419250","price_changes":[{"asset_id":"60386828328910021732068595344565885737045900010034836345809386672230885527307","best_ask":"0.34","best_bid":"0.33","hash":"e4b8123bddb45b934edac27dd5df3b226a898290","price":"0.4","side":"SELL","size":"20.34"},{"asset_id":"69697746896130839564035629862476347944307040470122503199396727085502753297492","best_ask":"0.67","best_bid":"0.66","hash":"6ae936b441f1b923d07967f24254457caf238fe4","price":"0.6","side":"BUY","size":"20.34"}],"timestamp":"1785127193026"},"payload_hash":"a9b980bafd1ab152707a0b2d22ab9095d89cdefd3ac1459a73113b304f56a928","raw_frame":"{\"market\":\"0xeb66215f2e9faa6449e30a02bab5b8ed7b79a38bf961f6b24d0073c9c2419250\", \"price_changes\":[{\"asset_id\":\"60386828328910021732068595344565885737045900010034836345809386672230885527307\", \"price\":\"0.4\", \"size\":\"20.34\", \"side\":\"SELL\", \"hash\":\"e4b8123bddb45b934edac27dd5df3b226a898290\", \"best_bid\":\"0.33\", \"best_ask\":\"0.34\"}, {\"asset_id\":\"69697746896130839564035629862476347944307040470122503199396727085502753297492\", \"price\":\"0.6\", \"size\":\"20.34\", \"side\":\"BUY\", \"hash\":\"6ae936b441f1b923d07967f24254457caf238fe4\", \"best_bid\":\"0.66\", \"best_ask\":\"0.67\"}], \"timestamp\":\"1785127193026\", \"event_type\":\"price_change\"}","received_at":"2026-07-27T04:39:52.987993Z","schema_version":"clob-market-ws.price_change.v1","sequence":null,"server_hash":null,"server_timestamp":"1785127193026","session_id":"e9443c7415a0419799bee9cfbb1a9e4d","source":"clob_market_ws"},"received_at":"2026-07-27T04:39:52.987993Z","record_id":"8ab348dcc920b42b3a8ef243a723bf2a68d8f4bec87d8ea99f351dcfa6d3901d","schema_fingerprint":"4aa3821a28b0b7c2400bc59aba4bcc0a76e971dadd19610d3ad38c768e124dc7","schema_version":"edge-lab-recorder.raw.v1","sequence":null,"source":"clob_market_ws"}
{"event_at":"2026-07-27T04:39:53.029000Z","event_fingerprint":"92b010eba0d45748e3218f1a37dcdc913382b8b53c5f8ae99efd3bc5af38f9a2","payload":{"connection_id":"0f4979d6978d463e9660b042fdcf555f","event_at":"2026-07-27T04:39:53.029000Z","event_type":"price_change","frame_hash":"24e2565de05e719114c5db31bd1d975d1e95049b4c2b8d4d4b55cd404fd8e6a4","frame_index":0,"kind":"data","monotonic_ns":229176255908416,"payload":{"event_type":"price_change","market":"0xeb66215f2e9faa6449e30a02bab5b8ed7b79a38bf961f6b24d0073c9c2419250","price_changes":[{"asset_id":"69697746896130839564035629862476347944307040470122503199396727085502753297492","best_ask":"0.67","best_bid":"0.66","hash":"a69ca3f76e6b9175e4b424b2e7a688d88afa895d","price":"0.6","side":"BUY","size":"69.41"},{"asset_id":"60386828328910021732068595344565885737045900010034836345809386672230885527307","best_ask":"0.34","best_bid":"0.33","hash":"ccf4c72587c138a1b7e8441290cede24074e549b","price":"0.4","side":"SELL","size":"69.41"}],"timestamp":"1785127193029"},"payload_hash":"ff0f24ebc27d9a16c2416176ba163a6525b926fdca2cc531f2ac3ae610a7ff50","raw_frame":"{\"market\":\"0xeb66215f2e9faa6449e30a02bab5b8ed7b79a38bf961f6b24d0073c9c2419250\", \"price_changes\":[{\"asset_id\":\"69697746896130839564035629862476347944307040470122503199396727085502753297492\", \"price\":\"0.6\", \"size\":\"69.41\", \"side\":\"BUY\", \"hash\":\"a69ca3f76e6b9175e4b424b2e7a688d88afa895d\", \"best_bid\":\"0.66\", \"best_ask\":\"0.67\"}, {\"asset_id\":\"60386828328910021732068595344565885737045900010034836345809386672230885527307\", \"price\":\"0.4\", \"size\":\"69.41\", \"side\":\"SELL\", \"hash\":\"ccf4c72587c138a1b7e8441290cede24074e549b\", \"best_bid\":\"0.33\", \"best_ask\":\"0.34\"}], \"timestamp\":\"1785127193029\", \"event_type\":\"price_change\"}","received_at":"2026-07-27T04:39:52.991213Z","schema_version":"clob-market-ws.price_change.v1","sequence":null,"server_hash":null,"server_timestamp":"1785127193029","session_id":"e9443c7415a0419799bee9cfbb1a9e4d","source":"clob_market_ws"},"received_at":"2026-07-27T04:39:52.991213Z","record_id":"1c7bd2889fd2032839b2adcca670fe1246568f88da3269069af634f4b8b8ba18","schema_fingerprint":"4aa3821a28b0b7c2400bc59aba4bcc0a76e971dadd19610d3ad38c768e124dc7","schema_version":"edge-lab-recorder.raw.v1","sequence":null,"source":"clob_market_ws"}
{"event_at":"2026-07-27T04:39:53.038000Z","event_fingerprint":"d5ef175ed30c2e8835b97eecc16bbec7f84f75401f00dec18e12b4cc33eebb6e","payload":{"connection_id":"0f4979d6978d463e9660b042fdcf555f","event_at":"2026-07-27T04:39:53.038000Z","event_type":"price_change","frame_hash":"c47558057ffac1de9b981dfef8fc1d3cfb1638b7323adabf8ae74ca7d3d4ade6","frame_index":0,"kind":"data","monotonic_ns":229176258228333,"payload":{"event_type":"price_change","market":"0xeb66215f2e9faa6449e30a02bab5b8ed7b79a38bf961f6b24d0073c9c2419250","price_changes":[{"asset_id":"69697746896130839564035629862476347944307040470122503199396727085502753297492","best_ask":"0.67","best_bid":"0.66","hash":"e46be31cdeec1872e71832cd2824dab98756f95d","price":"0.59","side":"BUY","size":"10"},{"asset_id":"60386828328910021732068595344565885737045900010034836345809386672230885527307","best_ask":"0.34","best_bid":"0.33","hash":"9e4a23d2232750f09982330ca9d01a0ecbb22e9f","price":"0.41","side":"SELL","size":"10"}],"timestamp":"1785127193038"},"payload_hash":"bca07148ccb49c674cca2f98dde467a3caf2c01db5e5c55d6a41d89c1044dfe0","raw_frame":"{\"market\":\"0xeb66215f2e9faa6449e30a02bab5b8ed7b79a38bf961f6b24d0073c9c2419250\", \"price_changes\":[{\"asset_id\":\"69697746896130839564035629862476347944307040470122503199396727085502753297492\", \"price\":\"0.59\", \"size\":\"10\", \"side\":\"BUY\", \"hash\":\"e46be31cdeec1872e71832cd2824dab98756f95d\", \"best_bid\":\"0.66\", \"best_ask\":\"0.67\"}, {\"asset_id\":\"60386828328910021732068595344565885737045900010034836345809386672230885527307\", \"price\":\"0.41\", \"size\":\"10\", \"side\":\"SELL\", \"hash\":\"9e4a23d2232750f09982330ca9d01a0ecbb22e9f\", \"best_bid\":\"0.33\", \"best_ask\":\"0.34\"}], \"timestamp\":\"1785127193038\", \"event_type\":\"price_change\"}","received_at":"2026-07-27T04:39:52.993534Z","schema_version":"clob-market-ws.price_change.v1","sequence":null,"server_hash":null,"server_timestamp":"1785127193038","session_id":"e9443c7415a0419799bee9cfbb1a9e4d","source":"clob_market_ws"},"received_at":"2026-07-27T04:39:52.993534Z","record_id":"a231b5bd053d63cb83255887764af195b232195f9d8300ffb1b96864c9a3f1fb","schema_fingerprint":"4aa3821a28b0b7c2400bc59aba4bcc0a76e971dadd19610d3ad38c768e124dc7","schema_version":"edge-lab-recorder.raw.v1","sequence":null,"source":"clob_market_ws"}
{"event_at":"2026-07-27T04:39:53.044000Z","event_fingerprint":"fe40ffd824b42c549061ccd6f9f4445be0a76434d97d1701ccb312b0ede79fa6","payload":{"connection_id":"0f4979d6978d463e9660b042fdcf555f","event_at":"2026-07-27T04:39:53.044000Z","event_type":"price_change","frame_hash":"2815ae7d68eebb392c1cef04ee4f16716fecd139ed2d6c21f72836c969aaecea","frame_index":0,"kind":"data","monotonic_ns":229176261146500,"payload":{"event_type":"price_change","market":"0xeb66215f2e9faa6449e30a02bab5b8ed7b79a38bf961f6b24d0073c9c2419250","price_changes":[{"asset_id":"60386828328910021732068595344565885737045900010034836345809386672230885527307","best_ask":"0.34","best_bid":"0.33","hash":"e6b09b2db0d495903ba42fc7db8063cdb1bf761e","price":"0.01","side":"BUY","size":"5598.02"},{"asset_id":"69697746896130839564035629862476347944307040470122503199396727085502753297492","best_ask":"0.67","best_bid":"0.66","hash":"8ca3158dc629d3ad04a831530018f7fed89a9e27","price":"0.99","side":"SELL","size":"5598.02"}],"timestamp":"1785127193044"},"payload_hash":"dee64171b79a2a041c1a254a167150b729f6d2db34437006b4b8cdb14892fe90","raw_frame":"{\"market\":\"0xeb66215f2e9faa6449e30a02bab5b8ed7b79a38bf961f6b24d0073c9c2419250\", \"price_changes\":[{\"asset_id\":\"60386828328910021732068595344565885737045900010034836345809386672230885527307\", \"price\":\"0.01\", \"size\":\"5598.02\", \"side\":\"BUY\", \"hash\":\"e6b09b2db0d495903ba42fc7db8063cdb1bf761e\", \"best_bid\":\"0.33\", \"best_ask\":\"0.34\"}, {\"asset_id\":\"69697746896130839564035629862476347944307040470122503199396727085502753297492\", \"price\":\"0.99\", \"size\":\"5598.02\", \"side\":\"SELL\", \"hash\":\"8ca3158dc629d3ad04a831530018f7fed89a9e27\", \"best_bid\":\"0.66\", \"best_ask\":\"0.67\"}], \"timestamp\":\"1785127193044\", \"event_type\":\"price_change\"}","received_at":"2026-07-27T04:39:52.996453Z","schema_version":"clob-market-ws.price_change.v1","sequence":null,"server_hash":null,"server_timestamp":"1785127193044","session_id":"e9443c7415a0419799bee9cfbb1a9e4d","source":"clob_market_ws"},"received_at":"2026-07-27T04:39:52.996453Z","record_id":"09b1a36132038b94b6471a70c7ebb1dc6db5afad3cdaa8a32739bee88cee80d6","schema_fingerprint":"4aa3821a28b0b7c2400bc59aba4bcc0a76e971dadd19610d3ad38c768e124dc7","schema_version":"edge-lab-recorder.raw.v1","sequence":null,"source":"clob_market_ws"}
{"event_at":"2026-07-27T04:39:53.047000Z","event_fingerprint":"d27cec7dfd3dea67469cc388e4c73043284ade94a660cf7285f24df2c09eaede","payload":{"connection_id":"0f4979d6978d463e9660b042fdcf555f","event_at":"2026-07-27T04:39:53.047000Z","event_type":"price_change","frame_hash":"937c75ca414ac037b435828815ce2254b6eedbb35f3997b1565ad3acca3d3605","frame_index":0,"kind":"data","monotonic_ns":229176263424791,"payload":{"event_type":"price_change","market":"0xeb66215f2e9faa6449e30a02bab5b8ed7b79a38bf961f6b24d0073c9c2419250","price_changes":[{"asset_id":"69697746896130839564035629862476347944307040470122503199396727085502753297492","best_ask":"0.67","best_bid":"0.66","hash":"d111e68da67418d1e9f6c7266dbe07d5ab504a78","price":"0.57","side":"BUY","size":"147.2"},{"asset_id":"60386828328910021732068595344565885737045900010034836345809386672230885527307","best_ask":"0.34","best_bid":"0.33","hash":"3164d314a142140952091f4173b75f6efb0d1c7c","price":"0.43","side":"SELL","size":"147.2"}],"timestamp":"1785127193047"},"payload_hash":"b549214a974488ecc2c2a6777125daf752592c7c8e935fbc35d5d24766864515","raw_frame":"{\"market\":\"0xeb66215f2e9faa6449e30a02bab5b8ed7b79a38bf961f6b24d0073c9c2419250\", \"price_changes\":[{\"asset_id\":\"69697746896130839564035629862476347944307040470122503199396727085502753297492\", \"price\":\"0.57\", \"size\":\"147.2\", \"side\":\"BUY\", \"hash\":\"d111e68da67418d1e9f6c7266dbe07d5ab504a78\", \"best_bid\":\"0.66\", \"best_ask\":\"0.67\"}, {\"asset_id\":\"60386828328910021732068595344565885737045900010034836345809386672230885527307\", \"price\":\"0.43\", \"size\":\"147.2\", \"side\":\"SELL\", \"hash\":\"3164d314a142140952091f4173b75f6efb0d1c7c\", \"best_bid\":\"0.33\", \"best_ask\":\"0.34\"}], \"timestamp\":\"1785127193047\", \"event_type\":\"price_change\"}","received_at":"2026-07-27T04:39:52.998730Z","schema_version":"clob-market-ws.price_change.v1","sequence":null,"server_hash":null,"server_timestamp":"1785127193047","session_id":"e9443c7415a0419799bee9cfbb1a9e4d","source":"clob_market_ws"},"received_at":"2026-07-27T04:39:52.998730Z","record_id":"9a887c62fd6de875071db7534241109d74f19ba98495ddb00c7c6daf8b4b8e6f","schema_fingerprint":"4aa3821a28b0b7c2400bc59aba4bcc0a76e971dadd19610d3ad38c768e124dc7","schema_version":"edge-lab-recorder.raw.v1","sequence":null,"source":"clob_market_ws"}
{"event_at":"2026-07-27T04:39:53.051000Z","event_fingerprint":"75d91dd2c95b45a81b5d08f278f72b5fec9f26b513d688997965e84a94b16e0f","payload":{"connection_id":"0f4979d6978d463e9660b042fdcf555f","event_at":"2026-07-27T04:39:53.051000Z","event_type":"price_change","frame_hash":"be45faa3afa0c54be9ea40dce3c84fbd10872d203df141a18c6c98f051cd8221","frame_index":0,"kind":"data","monotonic_ns":229176267787458,"payload":{"event_type":"price_change","market":"0xeb66215f2e9faa6449e30a02bab5b8ed7b79a38bf961f6b24d0073c9c2419250","price_changes":[{"asset_id":"69697746896130839564035629862476347944307040470122503199396727085502753297492","best_ask":"0.67","best_bid":"0.66","hash":"1bb4bc956b4cc15aa42dbcedcdafee06356be30a","price":"0.01","side":"BUY","size":"5638.02"},{"asset_id":"60386828328910021732068595344565885737045900010034836345809386672230885527307","best_ask":"0.34","best_bid":"0.33","hash":"eee3710354a4e22155e5cee6b91e2bdf174ec360","price":"0.99","side":"SELL","size":"5638.02"}],"timestamp":"1785127193051"},"payload_hash":"24f7a87271a32fcf51d89f933cf376a852a5391b8805cc1b2c7205c6019c4bfe","raw_frame":"{\"market\":\"0xeb66215f2e9faa6449e30a02bab5b8ed7b79a38bf961f6b24d0073c9c2419250\", \"price_changes\":[{\"asset_id\":\"69697746896130839564035629862476347944307040470122503199396727085502753297492\", \"price\":\"0.01\", \"size\":\"5638.02\", \"side\":\"BUY\", \"hash\":\"1bb4bc956b4cc15aa42dbcedcdafee06356be30a\", \"best_bid\":\"0.66\", \"best_ask\":\"0.67\"}, {\"asset_id\":\"60386828328910021732068595344565885737045900010034836345809386672230885527307\", \"price\":\"0.99\", \"size\":\"5638.02\", \"side\":\"SELL\", \"hash\":\"eee3710354a4e22155e5cee6b91e2bdf174ec360\", \"best_bid\":\"0.33\", \"best_ask\":\"0.34\"}], \"timestamp\":\"1785127193051\", \"event_type\":\"price_change\"}","received_at":"2026-07-27T04:39:53.003093Z","schema_version":"clob-market-ws.price_change.v1","sequence":null,"server_hash":null,"server_timestamp":"1785127193051","session_id":"e9443c7415a0419799bee9cfbb1a9e4d","source":"clob_market_ws"},"received_at":"2026-07-27T04:39:53.003093Z","record_id":"35db63d369eec30c30901bf2a39a17e78841b62246fca5429552b10374461fa6","schema_fingerprint":"4aa3821a28b0b7c2400bc59aba4bcc0a76e971dadd19610d3ad38c768e124dc7","schema_version":"edge-lab-recorder.raw.v1","sequence":null,"source":"clob_market_ws"}
{"event_at":"2026-07-27T04:39:53.054000Z","event_fingerprint":"1ac3e5db45d5c7a69b62c9af4ffc4e7440d3c60bc076fbf6cf03501278555837","payload":{"connection_id":"0f4979d6978d463e9660b042fdcf555f","event_at":"2026-07-27T04:39:53.054000Z","event_type":"price_change","frame_hash":"ef0d6068ec023681691296f0e045e48fbca97affa226278eb6981ef0b8eb051f","frame_index":0,"kind":"data","monotonic_ns":229176270440791,"payload":{"event_type":"price_change","market":"0xeb66215f2e9faa6449e30a02bab5b8ed7b79a38bf961f6b24d0073c9c2419250","price_changes":[{"asset_id":"60386828328910021732068595344565885737045900010034836345809386672230885527307","best_ask":"0.34","best_bid":"0.33","hash":"66aa1b754bf21269bdaea17943a4495e579fb83d","price":"0.24","side":"BUY","size":"248"},{"asset_id":"69697746896130839564035629862476347944307040470122503199396727085502753297492","best_ask":"0.67","best_bid":"0.66","hash":"f1a9189ae09d1f272a4ffab6e468bd26012ff102","price":"0.76","side":"SELL","size":"248"}],"timestamp":"1785127193054"},"payload_hash":"741238b624a5c03d00e81c9da2abbd6656d4a2bf7de63df733f6d6d63940166f","raw_frame":"{\"market\":\"0xeb66215f2e9faa6449e30a02bab5b8ed7b79a38bf961f6b24d0073c9c2419250\", \"price_changes\":[{\"asset_id\":\"60386828328910021732068595344565885737045900010034836345809386672230885527307\", \"price\":\"0.24\", \"size\":\"248\", \"side\":\"BUY\", \"hash\":\"66aa1b754bf21269bdaea17943a4495e579fb83d\", \"best_bid\":\"0.33\", \"best_ask\":\"0.34\"}, {\"asset_id\":\"69697746896130839564035629862476347944307040470122503199396727085502753297492\", \"price\":\"0.76\", \"size\":\"248\", \"side\":\"SELL\", \"hash\":\"f1a9189ae09d1f272a4ffab6e468bd26012ff102\", \"best_bid\":\"0.66\", \"best_ask\":\"0.67\"}], \"timestamp\":\"1785127193054\", \"event_type\":\"price_change\"}","received_at":"2026-07-27T04:39:53.005748Z","schema_version":"clob-market-ws.price_change.v1","sequence":null,"server_hash":null,"server_timestamp":"1785127193054","session_id":"e9443c7415a0419799bee9cfbb1a9e4d","source":"clob_market_ws"},"received_at":"2026-07-27T04:39:53.005748Z","record_id":"c552532d37103ef7f8cf5c851d39a7d004dd28469ff82567116f9616de20bfe1","schema_fingerprint":"4aa3821a28b0b7c2400bc59aba4bcc0a76e971dadd19610d3ad38c768e124dc7","schema_version":"edge-lab-recorder.raw.v1","sequence":null,"source":"clob_market_ws"}
{"event_at":"2026-07-27T04:39:53.072000Z","event_fingerprint":"e139512ae7130c425a79a8cbfde8986a6832f3982c8716734b4834f8d5dd4c6c","payload":{"connection_id":"0f4979d6978d463e9660b042fdcf555f","event_at":"2026-07-27T04:39:53.072000Z","event_type":"price_change","frame_hash":"87fc4803497e24390356df1c8233f74ddb1ca5ec53147b127ee50fdd647b9659","frame_index":0,"kind":"data","monotonic_ns":229176285574208,"payload":{"event_type":"price_change","market":"0xeb66215f2e9faa6449e30a02bab5b8ed7b79a38bf961f6b24d0073c9c2419250","price_changes":[{"asset_id":"69697746896130839564035629862476347944307040470122503199396727085502753297492","best_ask":"0.67","best_bid":"0.66","hash":"3cead7618f37e28bd6483f36562e88d91a3c2a9e","price":"0.01","side":"BUY","size":"5633.02"},{"asset_id":"60386828328910021732068595344565885737045900010034836345809386672230885527307","best_ask":"0.34","best_bid":"0.33","hash":"bd6172dd5761f0adc40bfbb1c68086749a6c2a21","price":"0.99","side":"SELL","size":"5633.02"}],"timestamp":"1785127193072"},"payload_hash":"5bb5461f18f3e472f6d670aa003f2b8b16a95d1b93c7e9c36ad3f07c9b57b6a1","raw_frame":"{\"market\":\"0xeb66215f2e9faa6449e30a02bab5b8ed7b79a38bf961f6b24d0073c9c2419250\", \"price_changes\":[{\"asset_id\":\"69697746896130839564035629862476347944307040470122503199396727085502753297492\", \"price\":\"0.01\", \"size\":\"5633.02\", \"side\":\"BUY\", \"hash\":\"3cead7618f37e28bd6483f36562e88d91a3c2a9e\", \"best_bid\":\"0.66\", \"best_ask\":\"0.67\"}, {\"asset_id\":\"60386828328910021732068595344565885737045900010034836345809386672230885527307\", \"price\":\"0.99\", \"size\":\"5633.02\", \"side\":\"SELL\", \"hash\":\"bd6172dd5761f0adc40bfbb1c68086749a6c2a21\", \"best_bid\":\"0.33\", \"best_ask\":\"0.34\"}], \"timestamp\":\"1785127193072\", \"event_type\":\"price_change\"}","received_at":"2026-07-27T04:39:53.020876Z","schema_version":"clob-market-ws.price_change.v1","sequence":null,"server_hash":null,"server_timestamp":"1785127193072","session_id":"e9443c7415a0419799bee9cfbb1a9e4d","source":"clob_market_ws"},"received_at":"2026-07-27T04:39:53.020876Z","record_id":"afaad0c119a2c783342625bf31b2cb67c97f9e0e99e0e250f07597fa3a7fc678","schema_fingerprint":"4aa3821a28b0b7c2400bc59aba4bcc0a76e971dadd19610d3ad38c768e124dc7","schema_version":"edge-lab-recorder.raw.v1","sequence":null,"source":"clob_market_ws"}
{"event_at":"2026-07-27T04:39:53.093000Z","event_fingerprint":"f1b9383e5b21949e026646efc61f9a2dfa7bb88fea0fe914544d77f84e98449e","payload":{"connection_id":"0f4979d6978d463e9660b042fdcf555f","event_at":"2026-07-27T04:39:53.093000Z","event_type":"price_change","frame_hash":"044fd120479a07090a448bea11d2393681c008ba66d3d999d8ad1d02f5cb8f04","frame_index":0,"kind":"data","monotonic_ns":229176305672500,"payload":{"event_type":"price_change","market":"0xeb66215f2e9faa6449e30a02bab5b8ed7b79a38bf961f6b24d0073c9c2419250","price_changes":[{"asset_id":"60386828328910021732068595344565885737045900010034836345809386672230885527307","best_ask":"0.34","best_bid":"0.33","hash":"5276dde8e07a52f8d0da318293b9d58ffd4d12db","price":"0.01","side":"BUY","size":"5593.02"},{"asset_id":"69697746896130839564035629862476347944307040470122503199396727085502753297492","best_ask":"0.67","best_bid":"0.66","hash":"351933199f2f38a63aa414fee7b1344e426c3bcc","price":"0.99","side":"SELL","size":"5593.02"}],"timestamp":"1785127193093"},"payload_hash":"9d6b770c078d8b6f722b9457634b55b583d0dbd725dc537911887afe2aae061b","raw_frame":"{\"market\":\"0xeb66215f2e9faa6449e30a02bab5b8ed7b79a38bf961f6b24d0073c9c2419250\", \"price_changes\":[{\"asset_id\":\"60386828328910021732068595344565885737045900010034836345809386672230885527307\", \"price\":\"0.01\", \"size\":\"5593.02\", \"side\":\"BUY\", \"hash\":\"5276dde8e07a52f8d0da318293b9d58ffd4d12db\", \"best_bid\":\"0.33\", \"best_ask\":\"0.34\"}, {\"asset_id\":\"69697746896130839564035629862476347944307040470122503199396727085502753297492\", \"price\":\"0.99\", \"size\":\"5593.02\", \"side\":\"SELL\", \"hash\":\"351933199f2f38a63aa414fee7b1344e426c3bcc\", \"best_bid\":\"0.66\", \"best_ask\":\"0.67\"}], \"timestamp\":\"1785127193093\", \"event_type\":\"price_change\"}","received_at":"2026-07-27T04:39:53.040976Z","schema_version":"clob-market-ws.price_change.v1","sequence":null,"server_hash":null,"server_timestamp":"1785127193093","session_id":"e9443c7415a0419799bee9cfbb1a9e4d","source":"clob_market_ws"},"received_at":"2026-07-27T04:39:53.040976Z","record_id":"6e28d6d9e31ae326288588ba51a0a6437a05f596c2df70bd6de723a5998a752d","schema_fingerprint":"4aa3821a28b0b7c2400bc59aba4bcc0a76e971dadd19610d3ad38c768e124dc7","schema_version":"edge-lab-recorder.raw.v1","sequence":null,"source":"clob_market_ws"}
{"event_at":"2026-07-27T04:39:53.096000Z","event_fingerprint":"a979360dacecd6022e546d88d2fedffc92ad5867d7d748da40f7fc33aa03a0a4","payload":{"connection_id":"0f4979d6978d463e9660b042fdcf555f","event_at":"2026-07-27T04:39:53.096000Z","event_type":"price_change","frame_hash":"d8a1e7102c90c4fe37098e9415129401b2bf732a7fed63c4cff1b77fe29716b4","frame_index":0,"kind":"data","monotonic_ns":229176308442375,"payload":{"event_type":"price_change","market":"0xeb66215f2e9faa6449e30a02bab5b8ed7b79a38bf961f6b24d0073c9c2419250","price_changes":[{"asset_id":"69697746896130839564035629862476347944307040470122503199396727085502753297492","best_ask":"0.67","best_bid":"0.66","hash":"4bc30d65dd8a20e68b0e22638b1b69f85f5f3990","price":"0.02","side":"BUY","size":"688.1"},{"asset_id":"60386828328910021732068595344565885737045900010034836345809386672230885527307","best_ask":"0.34","best_bid":"0.33","hash":"32ce189d7fb87ce263ef7bc9f2fe0aceef97742c","price":"0.98","side":"SELL","size":"688.1"}],"timestamp":"1785127193096"},"payload_hash":"4ced5c8d6c89479bd3d5a0530baf56f9c3eb11c5c568dacadfa0c9be7d445605","raw_frame":"{\"market\":\"0xeb66215f2e9faa6449e30a02bab5b8ed7b79a38bf961f6b24d0073c9c2419250\", \"price_changes\":[{\"asset_id\":\"69697746896130839564035629862476347944307040470122503199396727085502753297492\", \"price\":\"0.02\", \"size\":\"688.1\", \"side\":\"BUY\", \"hash\":\"4bc30d65dd8a20e68b0e22638b1b69f85f5f3990\", \"best_bid\":\"0.66\", \"best_ask\":\"0.67\"}, {\"asset_id\":\"60386828328910021732068595344565885737045900010034836345809386672230885527307\", \"price\":\"0.98\", \"size\":\"688.1\", \"side\":\"SELL\", \"hash\":\"32ce189d7fb87ce263ef7bc9f2fe0aceef97742c\", \"best_bid\":\"0.33\", \"best_ask\":\"0.34\"}], \"timestamp\":\"1785127193096\", \"event_type\":\"price_change\"}","received_at":"2026-07-27T04:39:53.043746Z","schema_version":"clob-market-ws.price_change.v1","sequence":null,"server_hash":null,"server_timestamp":"1785127193096","session_id":"e9443c7415a0419799bee9cfbb1a9e4d","source":"clob_market_ws"},"received_at":"2026-07-27T04:39:53.043746Z","record_id":"d69c43f64980ea8979b5a82116f24efe7707a31ad5dfca6506eff326bc861490","schema_fingerprint":"4aa3821a28b0b7c2400bc59aba4bcc0a76e971dadd19610d3ad38c768e124dc7","schema_version":"edge-lab-recorder.raw.v1","sequence":null,"source":"clob_market_ws"}
{"event_at":"2026-07-27T04:39:53.143000Z","event_fingerprint":"8ad05e71f9fd6dbf01c6174c071263c3f80b239aaabd2cf09dcd3e82fb60f1c7","payload":{"connection_id":"0f4979d6978d463e9660b042fdcf555f","event_at":"2026-07-27T04:39:53.143000Z","event_type":"price_change","frame_hash":"c1b2b93ed4ef71514631f7e6f1ae5f7c390953d5dd06a21fab15ede36c57ebef","frame_index":0,"kind":"data","monotonic_ns":229176358509416,"payload":{"event_type":"price_change","market":"0xeb66215f2e9faa6449e30a02bab5b8ed7b79a38bf961f6b24d0073c9c2419250","price_changes":[{"asset_id":"69697746896130839564035629862476347944307040470122503199396727085502753297492","best_ask":"0.67","best_bid":"0.66","hash":"27699e6a38b77cc4ba33d0cad2a9e082147af649","price":"0.6","side":"BUY","size":"20.34"},{"asset_id":"60386828328910021732068595344565885737045900010034836345809386672230885527307","best_ask":"0.34","best_bid":"0.33","hash":"c7361def0f478ed741d5e9eaca6255b93a438020","price":"0.4","side":"SELL","size":"20.34"}],"timestamp":"1785127193143"},"payload_hash":"5c6c012106dd712b91542ca63a9edebd022e014c0d8a00ebf69a649dee2a32ab","raw_frame":"{\"market\":\"0xeb66215f2e9faa6449e30a02bab5b8ed7b79a38bf961f6b24d0073c9c2419250\", \"price_changes\":[{\"asset_id\":\"69697746896130839564035629862476347944307040470122503199396727085502753297492\", \"price\":\"0.6\", \"size\":\"20.34\", \"side\":\"BUY\", \"hash\":\"27699e6a38b77cc4ba33d0cad2a9e082147af649\", \"best_bid\":\"0.66\", \"best_ask\":\"0.67\"}, {\"asset_id\":\"60386828328910021732068595344565885737045900010034836345809386672230885527307\", \"price\":\"0.4\", \"size\":\"20.34\", \"side\":\"SELL\", \"hash\":\"c7361def0f478ed741d5e9eaca6255b93a438020\", \"best_bid\":\"0.33\", \"best_ask\":\"0.34\"}], \"timestamp\":\"1785127193143\", \"event_type\":\"price_change\"}","received_at":"2026-07-27T04:39:53.093808Z","schema_version":"clob-market-ws.price_change.v1","sequence":null,"server_hash":null,"server_timestamp":"1785127193143","session_id":"e9443c7415a0419799bee9cfbb1a9e4d","source":"clob_market_ws"},"received_at":"2026-07-27T04:39:53.093808Z","record_id":"f9bc9483472b470e927562109bc5ead78411efeb5ac9ee45f420d922b192c5a3","schema_fingerprint":"4aa3821a28b0b7c2400bc59aba4bcc0a76e971dadd19610d3ad38c768e124dc7","schema_version":"edge-lab-recorder.raw.v1","sequence":null,"source":"clob_market_ws"}
{"event_at":"2026-07-27T04:39:53.150000Z","event_fingerprint":"838edd949d4c0c93a6b0ec5da2ddd41fb9a0cac7fb43564c28ebfb7a5d4cc14c","payload":{"connection_id":"0f4979d6978d463e9660b042fdcf555f","event_at":"2026-07-27T04:39:53.150000Z","event_type":"price_change","frame_hash":"c5c166f4dc36f7a4e4b457d65904a7e3b32561a7c8e457bf080138e05d4e6d90","frame_index":0,"kind":"data","monotonic_ns":229176362461208,"payload":{"event_type":"price_change","market":"0xeb66215f2e9faa6449e30a02bab5b8ed7b79a38bf961f6b24d0073c9c2419250","price_changes":[{"asset_id":"60386828328910021732068595344565885737045900010034836345809386672230885527307","best_ask":"0.34","best_bid":"0.33","hash":"60557338dffd7a96bf163cea6bab56473178e5c9","price":"0.4","side":"SELL","size":"70.41"},{"asset_id":"69697746896130839564035629862476347944307040470122503199396727085502753297492","best_ask":"0.67","best_bid":"0.66","hash":"88cc5aca405a5019f63a4d8dc6f4b7afe736967e","price":"0.6","side":"BUY","size":"70.41"}],"timestamp":"1785127193150"},"payload_hash":"8bddf0850b111162f6314fe5e4836ac860334762259fa95a8e31654bcba052e1","raw_frame":"{\"market\":\"0xeb66215f2e9faa6449e30a02bab5b8ed7b79a38bf961f6b24d0073c9c2419250\", \"price_changes\":[{\"asset_id\":\"60386828328910021732068595344565885737045900010034836345809386672230885527307\", \"price\":\"0.4\", \"size\":\"70.41\", \"side\":\"SELL\", \"hash\":\"60557338dffd7a96bf163cea6bab56473178e5c9\", \"best_bid\":\"0.33\", \"best_ask\":\"0.34\"}, {\"asset_id\":\"69697746896130839564035629862476347944307040470122503199396727085502753297492\", \"price\":\"0.6\", \"size\":\"70.41\", \"side\":\"BUY\", \"hash\":\"88cc5aca405a5019f63a4d8dc6f4b7afe736967e\", \"best_bid\":\"0.66\", \"best_ask\":\"0.67\"}], \"timestamp\":\"1785127193150\", \"event_type\":\"price_change\"}","received_at":"2026-07-27T04:39:53.097765Z","schema_version":"clob-market-ws.price_change.v1","sequence":null,"server_hash":null,"server_timestamp":"1785127193150","session_id":"e9443c7415a0419799bee9cfbb1a9e4d","source":"clob_market_ws"},"received_at":"2026-07-27T04:39:53.097765Z","record_id":"8202253ef8c91a54db86b740fb1ac1de5056f82068d64f5c650ee3546c31f998","schema_fingerprint":"4aa3821a28b0b7c2400bc59aba4bcc0a76e971dadd19610d3ad38c768e124dc7","schema_version":"edge-lab-recorder.raw.v1","sequence":null,"source":"clob_market_ws"}
{"event_at":"2026-07-27T04:39:53.168000Z","event_fingerprint":"4593f1bfb530faa194018a726b16c8ee71e408f927a8b20d07e59e52870efe7b","payload":{"connection_id":"0f4979d6978d463e9660b042fdcf555f","event_at":"2026-07-27T04:39:53.168000Z","event_type":"price_change","frame_hash":"a7699854e0f7fc9475cada5888640a19528aa3e9ad36c9a764b2b35ba8b58b90","frame_index":0,"kind":"data","monotonic_ns":229176380591958,"payload":{"event_type":"price_change","market":"0xeb66215f2e9faa6449e30a02bab5b8ed7b79a38bf961f6b24d0073c9c2419250","price_changes":[{"asset_id":"69697746896130839564035629862476347944307040470122503199396727085502753297492","best_ask":"0.67","best_bid":"0.66","hash":"4d4dd50ea1f78ebdf7a4026efe9329523758ed58","price":"0.02","side":"BUY","size":"683.1"},{"asset_id":"60386828328910021732068595344565885737045900010034836345809386672230885527307","best_ask":"0.34","best_bid":"0.33","hash":"7db803521d99af061ba18ee3180c583e43e93bfa","price":"0.98","side":"SELL","size":"683.1"}],"timestamp":"1785127193168"},"payload_hash":"f50d6864aff41cd932d8a632fa4ab1932884b7dd58355654cf16f2c787ffb761","raw_frame":"{\"market\":\"0xeb66215f2e9faa6449e30a02bab5b8ed7b79a38bf961f6b24d0073c9c2419250\", \"price_changes\":[{\"asset_id\":\"69697746896130839564035629862476347944307040470122503199396727085502753297492\", \"price\":\"0.02\", \"size\":\"683.1\", \"side\":\"BUY\", \"hash\":\"4d4dd50ea1f78ebdf7a4026efe9329523758ed58\", \"best_bid\":\"0.66\", \"best_ask\":\"0.67\"}, {\"asset_id\":\"60386828328910021732068595344565885737045900010034836345809386672230885527307\", \"price\":\"0.98\", \"size\":\"683.1\", \"side\":\"SELL\", \"hash\":\"7db803521d99af061ba18ee3180c583e43e93bfa\", \"best_bid\":\"0.33\", \"best_ask\":\"0.34\"}], \"timestamp\":\"1785127193168\", \"event_type\":\"price_change\"}","received_at":"2026-07-27T04:39:53.115897Z","schema_version":"clob-market-ws.price_change.v1","sequence":null,"server_hash":null,"server_timestamp":"1785127193168","session_id":"e9443c7415a0419799bee9cfbb1a9e4d","source":"clob_market_ws"},"received_at":"2026-07-27T04:39:53.115897Z","record_id":"8b7346ab62ca0146433b7554bad4d3b453936919cc5fe3956daba4fac0d4f9eb","schema_fingerprint":"4aa3821a28b0b7c2400bc59aba4bcc0a76e971dadd19610d3ad38c768e124dc7","schema_version":"edge-lab-recorder.raw.v1","sequence":null,"source":"clob_market_ws"}
{"event_at":"2026-07-27T04:39:53.248000Z","event_fingerprint":"183ffef9a7de53171af38a07141be1261cf344150e773c6d0a555275a1b59f03","payload":{"connection_id":"0f4979d6978d463e9660b042fdcf555f","event_at":"2026-07-27T04:39:53.248000Z","event_type":"price_change","frame_hash":"cf1ac579c875f89219a93c83a93430cae84006dea3b729fb660a9fcf8cda38d1","frame_index":0,"kind":"data","monotonic_ns":229176461540083,"payload":{"event_type":"price_change","market":"0xeb66215f2e9faa6449e30a02bab5b8ed7b79a38bf961f6b24d0073c9c2419250","price_changes":[{"asset_id":"60386828328910021732068595344565885737045900010034836345809386672230885527307","best_ask":"0.34","best_bid":"0.33","hash":"a4571c555b9b5a2cd0d1fbf1c39dce0634c84f4f","price":"0.4","side":"SELL","size":"20.34"},{"asset_id":"69697746896130839564035629862476347944307040470122503199396727085502753297492","best_ask":"0.67","best_bid":"0.66","hash":"286f8540f1e8cbc3c72e3b852cda8dfb41cbc0db","price":"0.6","side":"BUY","size":"20.34"}],"timestamp":"1785127193248"},"payload_hash":"f8490e1fcf132bd957de4ccd69cf09e1160bc2817cf281543114bd7f15285672","raw_frame":"{\"market\":\"0xeb66215f2e9faa6449e30a02bab5b8ed7b79a38bf961f6b24d0073c9c2419250\", \"price_changes\":[{\"asset_id\":\"60386828328910021732068595344565885737045900010034836345809386672230885527307\", \"price\":\"0.4\", \"size\":\"20.34\", \"side\":\"SELL\", \"hash\":\"a4571c555b9b5a2cd0d1fbf1c39dce0634c84f4f\", \"best_bid\":\"0.33\", \"best_ask\":\"0.34\"}, {\"asset_id\":\"69697746896130839564035629862476347944307040470122503199396727085502753297492\", \"price\":\"0.6\", \"size\":\"20.34\", \"side\":\"BUY\", \"hash\":\"286f8540f1e8cbc3c72e3b852cda8dfb41cbc0db\", \"best_bid\":\"0.66\", \"best_ask\":\"0.67\"}], \"timestamp\":\"1785127193248\", \"event_type\":\"price_change\"}","received_at":"2026-07-27T04:39:53.196840Z","schema_version":"clob-market-ws.price_change.v1","sequence":null,"server_hash":null,"server_timestamp":"1785127193248","session_id":"e9443c7415a0419799bee9cfbb1a9e4d","source":"clob_market_ws"},"received_at":"2026-07-27T04:39:53.196840Z","record_id":"5ec4debf2870d889bf1ad4ec71d9ec0c2025253088551b65d2483b153831ec97","schema_fingerprint":"4aa3821a28b0b7c2400bc59aba4bcc0a76e971dadd19610d3ad38c768e124dc7","schema_version":"edge-lab-recorder.raw.v1","sequence":null,"source":"clob_market_ws"}
{"event_at":"2026-07-27T04:39:53.255000Z","event_fingerprint":"e6c359dddf9a584e23630807c314c1642860e2c465323d7beb7f27e58f6e255a","payload":{"connection_id":"0f4979d6978d463e9660b042fdcf555f","event_at":"2026-07-27T04:39:53.255000Z","event_type":"price_change","frame_hash":"fc232571cc74ef43ddb28376dc1a90ceeb8d483c8ae879c8afae019b39bab405","frame_index":0,"kind":"data","monotonic_ns":229176467434958,"payload":{"event_type":"price_change","market":"0xeb66215f2e9faa6449e30a02bab5b8ed7b79a38bf961f6b24d0073c9c2419250","price_changes":[{"asset_id":"69697746896130839564035629862476347944307040470122503199396727085502753297492","best_ask":"0.67","best_bid":"0.66","hash":"e0b2879aab363688eb41d98c5d3fbfcb071282f1","price":"0.59","side":"BUY","size":"22.4"},{"asset_id":"60386828328910021732068595344565885737045900010034836345809386672230885527307","best_ask":"0.34","best_bid":"0.33","hash":"35049b901d62aa439c85f1c4a5f62030e07f1543","price":"0.41","side":"SELL","size":"22.4"}],"timestamp":"1785127193255"},"payload_hash":"5655a8af32816d76eb9117b652913b47d79097ff15da0b2ba1a70bbddb011c36","raw_frame":"{\"market\":\"0xeb66215f2e9faa6449e30a02bab5b8ed7b79a38bf961f6b24d0073c9c2419250\", \"price_changes\":[{\"asset_id\":\"69697746896130839564035629862476347944307040470122503199396727085502753297492\", \"price\":\"0.59\", \"size\":\"22.4\", \"side\":\"BUY\", \"hash\":\"e0b2879aab363688eb41d98c5d3fbfcb071282f1\", \"best_bid\":\"0.66\", \"best_ask\":\"0.67\"}, {\"asset_id\":\"60386828328910021732068595344565885737045900010034836345809386672230885527307\", \"price\":\"0.41\", \"size\":\"22.4\", \"side\":\"SELL\", \"hash\":\"35049b901d62aa439c85f1c4a5f62030e07f1543\", \"best_bid\":\"0.33\", \"best_ask\":\"0.34\"}], \"timestamp\":\"1785127193255\", \"event_type\":\"price_change\"}","received_at":"2026-07-27T04:39:53.202739Z","schema_version":"clob-market-ws.price_change.v1","sequence":null,"server_hash":null,"server_timestamp":"1785127193255","session_id":"e9443c7415a0419799bee9cfbb1a9e4d","source":"clob_market_ws"},"received_at":"2026-07-27T04:39:53.202739Z","record_id":"fa8f5af5a8e2febebc5b87114ef449586a4015cb23cda176e8dc9b9241f1a72e","schema_fingerprint":"4aa3821a28b0b7c2400bc59aba4bcc0a76e971dadd19610d3ad38c768e124dc7","schema_version":"edge-lab-recorder.raw.v1","sequence":null,"source":"clob_market_ws"}
{"event_at":"2026-07-27T04:39:53.257000Z","event_fingerprint":"5bcd106d4bc5d62faa7390e2908f0ffa5d649ab3e8dfdf480f089d760648e2f0","payload":{"connection_id":"0f4979d6978d463e9660b042fdcf555f","event_at":"2026-07-27T04:39:53.257000Z","event_type":"price_change","frame_hash":"f4784ef0ea9ca235762b0d31a71a46e9e6e165c1f5cb763e4ad1880dc82b9f67","frame_index":0,"kind":"data","monotonic_ns":229176469742875,"payload":{"event_type":"price_change","market":"0xeb66215f2e9faa6449e30a02bab5b8ed7b79a38bf961f6b24d0073c9c2419250","price_changes":[{"asset_id":"69697746896130839564035629862476347944307040470122503199396727085502753297492","best_ask":"0.67","best_bid":"0.66","hash":"a9dbc10eb5ef041779aadebc93e7b508edaf81ba","price":"0.6","side":"BUY","size":"70.41"},{"asset_id":"60386828328910021732068595344565885737045900010034836345809386672230885527307","best_ask":"0.34","best_bid":"0.33","hash":"f52bc4a1270b5c61d238e11c2ba33a67e0e6f951","price":"0.4","side":"SELL","size":"70.41"}],"timestamp":"1785127193257"},"payload_hash":"f53910ec987736136e1b882341272cb5c633efee7e6db08ab6fa008524992c22","raw_frame":"{\"market\":\"0xeb66215f2e9faa6449e30a02bab5b8ed7b79a38bf961f6b24d0073c9c2419250\", \"price_changes\":[{\"asset_id\":\"69697746896130839564035629862476347944307040470122503199396727085502753297492\", \"price\":\"0.6\", \"size\":\"70.41\", \"side\":\"BUY\", \"hash\":\"a9dbc10eb5ef041779aadebc93e7b508edaf81ba\", \"best_bid\":\"0.66\", \"best_ask\":\"0.67\"}, {\"asset_id\":\"60386828328910021732068595344565885737045900010034836345809386672230885527307\", \"price\":\"0.4\", \"size\":\"70.41\", \"side\":\"SELL\", \"hash\":\"f52bc4a1270b5c61d238e11c2ba33a67e0e6f951\", \"best_bid\":\"0.33\", \"best_ask\":\"0.34\"}], \"timestamp\":\"1785127193257\", \"event_type\":\"price_change\"}","received_at":"2026-07-27T04:39:53.205046Z","schema_version":"clob-market-ws.price_change.v1","sequence":null,"server_hash":null,"server_timestamp":"1785127193257","session_id":"e9443c7415a0419799bee9cfbb1a9e4d","source":"clob_market_ws"},"received_at":"2026-07-27T04:39:53.205046Z","record_id":"3c30cddbaf1e55fdc4bb394b1862ce75e4312ac5af30887aea7b345c90ff60a8","schema_fingerprint":"4aa3821a28b0b7c2400bc59aba4bcc0a76e971dadd19610d3ad38c768e124dc7","schema_version":"edge-lab-recorder.raw.v1","sequence":null,"source":"clob_market_ws"}
{"event_at":"2026-07-27T04:39:53.274000Z","event_fingerprint":"a654351420e54d12e84913a2e632666a4aebcffa74c3fa688b4ee95432dad38e","payload":{"connection_id":"0f4979d6978d463e9660b042fdcf555f","event_at":"2026-07-27T04:39:53.274000Z","event_type":"price_change","frame_hash":"088eaaa0074ffc280034ca3ff147627df02e249ee170f28518327fea604da2c1","frame_index":0,"kind":"data","monotonic_ns":229176485815750,"payload":{"event_type":"price_change","market":"0xeb66215f2e9faa6449e30a02bab5b8ed7b79a38bf961f6b24d0073c9c2419250","price_changes":[{"asset_id":"69697746896130839564035629862476347944307040470122503199396727085502753297492","best_ask":"0.67","best_bid":"0.66","hash":"34a2de3a2b6c383b4baf23af653272a5c413c39d","price":"0.04","side":"BUY","size":"613.09"},{"asset_id":"60386828328910021732068595344565885737045900010034836345809386672230885527307","best_ask":"0.34","best_bid":"0.33","hash":"bf0261765f46223307d17b3083ab33189272c657","price":"0.96","side":"SELL","size":"613.09"}],"timestamp":"1785127193274"},"payload_hash":"a17d2c13f85674112ff1264a81e81d3af1b468ce0f6e9bb434efd602ec11062e","raw_frame":"{\"market\":\"0xeb66215f2e9faa6449e30a02bab5b8ed7b79a38bf961f6b24d0073c9c2419250\", \"price_changes\":[{\"asset_id\":\"69697746896130839564035629862476347944307040470122503199396727085502753297492\", \"price\":\"0.04\", \"size\":\"613.09\", \"side\":\"BUY\", \"hash\":\"34a2de3a2b6c383b4baf23af653272a5c413c39d\", \"best_bid\":\"0.66\", \"best_ask\":\"0.67\"}, {\"asset_id\":\"60386828328910021732068595344565885737045900010034836345809386672230885527307\", \"price\":\"0.96\", \"size\":\"613.09\", \"side\":\"SELL\", \"hash\":\"bf0261765f46223307d17b3083ab33189272c657\", \"best_bid\":\"0.33\", \"best_ask\":\"0.34\"}], \"timestamp\":\"1785127193274\", \"event_type\":\"price_change\"}","received_at":"2026-07-27T04:39:53.221116Z","schema_version":"clob-market-ws.price_change.v1","sequence":null,"server_hash":null,"server_timestamp":"1785127193274","session_id":"e9443c7415a0419799bee9cfbb1a9e4d","source":"clob_market_ws"},"received_at":"2026-07-27T04:39:53.221116Z","record_id":"fff6b16777f997314e2066dfcedf2bf10ff76aeb55aafbc56e70c124537dc64a","schema_fingerprint":"4aa3821a28b0b7c2400bc59aba4bcc0a76e971dadd19610d3ad38c768e124dc7","schema_version":"edge-lab-recorder.raw.v1","sequence":null,"source":"clob_market_ws"}
{"event_at":"2026-07-27T04:39:53.353000Z","event_fingerprint":"614fe24a6612f8456ccc9e4192e42bd8e154922c4352e4d104f403d2d313da5e","payload":{"connection_id":"0f4979d6978d463e9660b042fdcf555f","event_at":"2026-07-27T04:39:53.353000Z","event_type":"price_change","frame_hash":"a187502e90d63112b63d7aa40a6b97737a64069447f8649d22416a509a83f6aa","frame_index":0,"kind":"data","monotonic_ns":229176566256500,"payload":{"event_type":"price_change","market":"0xeb66215f2e9faa6449e30a02bab5b8ed7b79a38bf961f6b24d0073c9c2419250","price_changes":[{"asset_id":"69697746896130839564035629862476347944307040470122503199396727085502753297492","best_ask":"0.67","best_bid":"0.66","hash":"965acc4b4a85a3c8655498dc8ee02ad5b8594631","price":"0.6","side":"BUY","size":"20.34"},{"asset_id":"60386828328910021732068595344565885737045900010034836345809386672230885527307","best_ask":"0.34","best_bid":"0.33","hash":"a7baa1fa63bf1ead2504f1b2f0cc409b653a43a6","price":"0.4","side":"SELL","size":"20.34"}],"timestamp":"1785127193353"},"payload_hash":"5a68f6917f887460485c8fcc2e6c9ac5f99ca59b0707546f7557db01dd92b7b3","raw_frame":"{\"market\":\"0xeb66215f2e9faa6449e30a02bab5b8ed7b79a38bf961f6b24d0073c9c2419250\", \"price_changes\":[{\"asset_id\":\"69697746896130839564035629862476347944307040470122503199396727085502753297492\", \"price\":\"0.6\", \"size\":\"20.34\", \"side\":\"BUY\", \"hash\":\"965acc4b4a85a3c8655498dc8ee02ad5b8594631\", \"best_bid\":\"0.66\", \"best_ask\":\"0.67\"}, {\"asset_id\":\"60386828328910021732068595344565885737045900010034836345809386672230885527307\", \"price\":\"0.4\", \"size\":\"20.34\", \"side\":\"SELL\", \"hash\":\"a7baa1fa63bf1ead2504f1b2f0cc409b653a43a6\", \"best_bid\":\"0.33\", \"best_ask\":\"0.34\"}], \"timestamp\":\"1785127193353\", \"event_type\":\"price_change\"}","received_at":"2026-07-27T04:39:53.301551Z","schema_version":"clob-market-ws.price_change.v1","sequence":null,"server_hash":null,"server_timestamp":"1785127193353","session_id":"e9443c7415a0419799bee9cfbb1a9e4d","source":"clob_market_ws"},"received_at":"2026-07-27T04:39:53.301551Z","record_id":"f8b82b3c3554fb802f80161e8701775b8b446885c81ffd424a70dd689569abc1","schema_fingerprint":"4aa3821a28b0b7c2400bc59aba4bcc0a76e971dadd19610d3ad38c768e124dc7","schema_version":"edge-lab-recorder.raw.v1","sequence":null,"source":"clob_market_ws"}
{"event_at":"2026-07-27T04:39:53.358000Z","event_fingerprint":"9f8952e726e748a9f79e44a46cc76aa4a0218466ae015960ddc760aa72523b18","payload":{"connection_id":"0f4979d6978d463e9660b042fdcf555f","event_at":"2026-07-27T04:39:53.358000Z","event_type":"price_change","frame_hash":"c38dfbe5b3f8f2fc911a07fdf04be7b4bbf26698eb24b2eddc30d84756468c70","frame_index":0,"kind":"data","monotonic_ns":229176570846958,"payload":{"event_type":"price_change","market":"0xeb66215f2e9faa6449e30a02bab5b8ed7b79a38bf961f6b24d0073c9c2419250","price_changes":[{"asset_id":"60386828328910021732068595344565885737045900010034836345809386672230885527307","best_ask":"0.34","best_bid":"0.33","hash":"4ca842f37c7ddbc5a6850d7a61d697173d73690a","price":"0.4","side":"SELL","size":"70.41"},{"asset_id":"69697746896130839564035629862476347944307040470122503199396727085502753297492","best_ask":"0.67","best_bid":"0.66","hash":"55dcb9b67da0d14807947cce35d874f069c828f0","price":"0.6","side":"BUY","size":"70.41"}],"timestamp":"1785127193358"},"payload_hash":"8c8cdacc1d49b859301265eda798d62092d500c64115d953495cc997bbf428fa","raw_frame":"{\"market\":\"0xeb66215f2e9faa6449e30a02bab5b8ed7b79a38bf961f6b24d0073c9c2419250\", \"price_changes\":[{\"asset_id\":\"60386828328910021732068595344565885737045900010034836345809386672230885527307\", \"price\":\"0.4\", \"size\":\"70.41\", \"side\":\"SELL\", \"hash\":\"4ca842f37c7ddbc5a6850d7a61d697173d73690a\", \"best_bid\":\"0.33\", \"best_ask\":\"0.34\"}, {\"asset_id\":\"69697746896130839564035629862476347944307040470122503199396727085502753297492\", \"price\":\"0.6\", \"size\":\"70.41\", \"side\":\"BUY\", \"hash\":\"55dcb9b67da0d14807947cce35d874f069c828f0\", \"best_bid\":\"0.66\", \"best_ask\":\"0.67\"}], \"timestamp\":\"1785127193358\", \"event_type\":\"price_change\"}","received_at":"2026-07-27T04:39:53.306153Z","schema_version":"clob-market-ws.price_change.v1","sequence":null,"server_hash":null,"server_timestamp":"1785127193358","session_id":"e9443c7415a0419799bee9cfbb1a9e4d","source":"clob_market_ws"},"received_at":"2026-07-27T04:39:53.306153Z","record_id":"de73e89e510cb319ec7a66143fe3a0f53cd664ae2d0092d5cb181cde5628e4f2","schema_fingerprint":"4aa3821a28b0b7c2400bc59aba4bcc0a76e971dadd19610d3ad38c768e124dc7","schema_version":"edge-lab-recorder.raw.v1","sequence":null,"source":"clob_market_ws"}
{"event_at":"2026-07-27T04:39:53.360000Z","event_fingerprint":"65039a73d5eab0e36dba20c702e47223919a6723de5907949080c8781fdedb13","payload":{"connection_id":"0f4979d6978d463e9660b042fdcf555f","event_at":"2026-07-27T04:39:53.360000Z","event_type":"price_change","frame_hash":"87fa1c35046704b62b1b84b8ec08691af0d1b761591a97cd158da7689bd7977f","frame_index":0,"kind":"data","monotonic_ns":229176571846583,"payload":{"event_type":"price_change","market":"0xeb66215f2e9faa6449e30a02bab5b8ed7b79a38bf961f6b24d0073c9c2419250","price_changes":[{"asset_id":"69697746896130839564035629862476347944307040470122503199396727085502753297492","best_ask":"0.67","best_bid":"0.66","hash":"3bc1da57de094832db433a2f57b177935a721d60","price":"0.58","side":"BUY","size":"56.3"},{"asset_id":"60386828328910021732068595344565885737045900010034836345809386672230885527307","best_ask":"0.34","best_bid":"0.33","hash":"85c97e8ef5eae1a6aa72631a49fe9eecf560a544","price":"0.42","side":"SELL","size":"56.3"}],"timestamp":"1785127193360"},"payload_hash":"4ff2fa4b3ef4290687a6e7f53d54dcb38d072b15fc801d54963077fd3e2463d7","raw_frame":"{\"market\":\"0xeb66215f2e9faa6449e30a02bab5b8ed7b79a38bf961f6b24d0073c9c2419250\", \"price_changes\":[{\"asset_id\":\"69697746896130839564035629862476347944307040470122503199396727085502753297492\", \"price\":\"0.58\", \"size\":\"56.3\", \"side\":\"BUY\", \"hash\":\"3bc1da57de094832db433a2f57b177935a721d60\", \"best_bid\":\"0.66\", \"best_ask\":\"0.67\"}, {\"asset_id\":\"60386828328910021732068595344565885737045900010034836345809386672230885527307\", \"price\":\"0.42\", \"size\":\"56.3\", \"side\":\"SELL\", \"hash\":\"85c97e8ef5eae1a6aa72631a49fe9eecf560a544\", \"best_bid\":\"0.33\", \"best_ask\":\"0.34\"}], \"timestamp\":\"1785127193360\", \"event_type\":\"price_change\"}","received_at":"2026-07-27T04:39:53.307152Z","schema_version":"clob-market-ws.price_change.v1","sequence":null,"server_hash":null,"server_timestamp":"1785127193360","session_id":"e9443c7415a0419799bee9cfbb1a9e4d","source":"clob_market_ws"},"received_at":"2026-07-27T04:39:53.307152Z","record_id":"5f74fbe53f4ada74533c2f675c07df16a9fbdc2c9de5d047080e1eed02739ae7","schema_fingerprint":"4aa3821a28b0b7c2400bc59aba4bcc0a76e971dadd19610d3ad38c768e124dc7","schema_version":"edge-lab-recorder.raw.v1","sequence":null,"source":"clob_market_ws"}
{"event_at":"2026-07-27T04:39:53.382000Z","event_fingerprint":"d3dc243c5de62f663ef3570fa7f1448f6ebabc1a5fc35040869c41562d2f98e8","payload":{"connection_id":"0f4979d6978d463e9660b042fdcf555f","event_at":"2026-07-27T04:39:53.382000Z","event_type":"price_change","frame_hash":"efd815c38a8f9268eeab07da0514679b5c1e643e555f29c4be8be892f629679f","frame_index":0,"kind":"data","monotonic_ns":229176593812916,"payload":{"event_type":"price_change","market":"0xeb66215f2e9faa6449e30a02bab5b8ed7b79a38bf961f6b24d0073c9c2419250","price_changes":[{"asset_id":"69697746896130839564035629862476347944307040470122503199396727085502753297492","best_ask":"0.67","best_bid":"0.66","hash":"508da6fd170ea5f54b2f5ee69eb12f4ecaba509b","price":"0.04","side":"BUY","size":"608.09"},{"asset_id":"60386828328910021732068595344565885737045900010034836345809386672230885527307","best_ask":"0.34","best_bid":"0.33","hash":"5f69301ec5d49fcc50f6ba496cbb0c54d2feca16","price":"0.96","side":"SELL","size":"608.09"}],"timestamp":"1785127193382"},"payload_hash":"21d52c8553b167a816e08fddbec08d242e047bdff7817f0bdb0a57d1357ba661","raw_frame":"{\"market\":\"0xeb66215f2e9faa6449e30a02bab5b8ed7b79a38bf961f6b24d0073c9c2419250\", \"price_changes\":[{\"asset_id\":\"69697746896130839564035629862476347944307040470122503199396727085502753297492\", \"price\":\"0.04\", \"size\":\"608.09\", \"side\":\"BUY\", \"hash\":\"508da6fd170ea5f54b2f5ee69eb12f4ecaba509b\", \"best_bid\":\"0.66\", \"best_ask\":\"0.67\"}, {\"asset_id\":\"60386828328910021732068595344565885737045900010034836345809386672230885527307\", \"price\":\"0.96\", \"size\":\"608.09\", \"side\":\"SELL\", \"hash\":\"5f69301ec5d49fcc50f6ba496cbb0c54d2feca16\", \"best_bid\":\"0.33\", \"best_ask\":\"0.34\"}], \"timestamp\":\"1785127193382\", \"event_type\":\"price_change\"}","received_at":"2026-07-27T04:39:53.329119Z","schema_version":"clob-market-ws.price_change.v1","sequence":null,"server_hash":null,"server_timestamp":"1785127193382","session_id":"e9443c7415a0419799bee9cfbb1a9e4d","source":"clob_market_ws"},"received_at":"2026-07-27T04:39:53.329119Z","record_id":"c3368de70f39f397586541814045271c0815032bf2629f7894d35bd018acf67f","schema_fingerprint":"4aa3821a28b0b7c2400bc59aba4bcc0a76e971dadd19610d3ad38c768e124dc7","schema_version":"edge-lab-recorder.raw.v1","sequence":null,"source":"clob_market_ws"}
{"event_at":"2026-07-27T04:39:53.453000Z","event_fingerprint":"3d357b30abb38a070c6548515987b2f6b838076691a479ab5a3f399293a6b5da","payload":{"connection_id":"0f4979d6978d463e9660b042fdcf555f","event_at":"2026-07-27T04:39:53.453000Z","event_type":"price_change","frame_hash":"281830d39c3420e9cf3d61b8c5f7803d1101d5de904b1d396137f9669f507b74","frame_index":0,"kind":"data","monotonic_ns":229176666440708,"payload":{"event_type":"price_change","market":"0xeb66215f2e9faa6449e30a02bab5b8ed7b79a38bf961f6b24d0073c9c2419250","price_changes":[{"asset_id":"69697746896130839564035629862476347944307040470122503199396727085502753297492","best_ask":"0.67","best_bid":"0.66","hash":"b10f18c0240f1095d7726ff2d989b2962df9ef6e","price":"0.01","side":"BUY","size":"5638.02"},{"asset_id":"60386828328910021732068595344565885737045900010034836345809386672230885527307","best_ask":"0.34","best_bid":"0.33","hash":"23a89ec041e0aadd54819f8aab3dc3c544ba342b","price":"0.99","side":"SELL","size":"5638.02"}],"timestamp":"1785127193453"},"payload_hash":"13f652c5c69aa402b5635dfd2920e23ddc1ef06b3f186355fa8fe84f326360e9","raw_frame":"{\"market\":\"0xeb66215f2e9faa6449e30a02bab5b8ed7b79a38bf961f6b24d0073c9c2419250\", \"price_changes\":[{\"asset_id\":\"69697746896130839564035629862476347944307040470122503199396727085502753297492\", \"price\":\"0.01\", \"size\":\"5638.02\", \"side\":\"BUY\", \"hash\":\"b10f18c0240f1095d7726ff2d989b2962df9ef6e\", \"best_bid\":\"0.66\", \"best_ask\":\"0.67\"}, {\"asset_id\":\"60386828328910021732068595344565885737045900010034836345809386672230885527307\", \"price\":\"0.99\", \"size\":\"5638.02\", \"side\":\"SELL\", \"hash\":\"23a89ec041e0aadd54819f8aab3dc3c544ba342b\", \"best_bid\":\"0.33\", \"best_ask\":\"0.34\"}], \"timestamp\":\"1785127193453\", \"event_type\":\"price_change\"}","received_at":"2026-07-27T04:39:53.401735Z","schema_version":"clob-market-ws.price_change.v1","sequence":null,"server_hash":null,"server_timestamp":"1785127193453","session_id":"e9443c7415a0419799bee9cfbb1a9e4d","source":"clob_market_ws"},"received_at":"2026-07-27T04:39:53.401735Z","record_id":"0569a538356fe42de2964e18ea9480f12d8d8077682e245bb0ee5403aa37d354","schema_fingerprint":"4aa3821a28b0b7c2400bc59aba4bcc0a76e971dadd19610d3ad38c768e124dc7","schema_version":"edge-lab-recorder.raw.v1","sequence":null,"source":"clob_market_ws"}
{"event_at":"2026-07-27T04:39:53.469000Z","event_fingerprint":"2909e27d41c92d034ec249e7a6d9f3554b036228604adea84955b33cffe4ed9f","payload":{"connection_id":"0f4979d6978d463e9660b042fdcf555f","event_at":"2026-07-27T04:39:53.469000Z","event_type":"price_change","frame_hash":"77d5f946f935003933ee8bc3584bb8f8888fdfa93c05eeb615dc4a1491f8c8c8","frame_index":0,"kind":"data","monotonic_ns":229176680424541,"payload":{"event_type":"price_change","market":"0xeb66215f2e9faa6449e30a02bab5b8ed7b79a38bf961f6b24d0073c9c2419250","price_changes":[{"asset_id":"60386828328910021732068595344565885737045900010034836345809386672230885527307","best_ask":"0.34","best_bid":"0.33","hash":"3e8af81705a924580344be4e90ee5d5afb041d3f","price":"0.4","side":"SELL","size":"20.34"},{"asset_id":"69697746896130839564035629862476347944307040470122503199396727085502753297492","best_ask":"0.67","best_bid":"0.66","hash":"cef1f349e0971b89b0b255cf9f8fef8098cecd76","price":"0.6","side":"BUY","size":"20.34"}],"timestamp":"1785127193469"},"payload_hash":"0b13bacf9bee666d126ec489f0fcb3d8b7270338266f6ae201218b8006f54a3f","raw_frame":"{\"market\":\"0xeb66215f2e9faa6449e30a02bab5b8ed7b79a38bf961f6b24d0073c9c2419250\", \"price_changes\":[{\"asset_id\":\"60386828328910021732068595344565885737045900010034836345809386672230885527307\", \"price\":\"0.4\", \"size\":\"20.34\", \"side\":\"SELL\", \"hash\":\"3e8af81705a924580344be4e90ee5d5afb041d3f\", \"best_bid\":\"0.33\", \"best_ask\":\"0.34\"}, {\"asset_id\":\"69697746896130839564035629862476347944307040470122503199396727085502753297492\", \"price\":\"0.6\", \"size\":\"20.34\", \"side\":\"BUY\", \"hash\":\"cef1f349e0971b89b0b255cf9f8fef8098cecd76\", \"best_bid\":\"0.66\", \"best_ask\":\"0.67\"}], \"timestamp\":\"1785127193469\", \"event_type\":\"price_change\"}","received_at":"2026-07-27T04:39:53.415721Z","schema_version":"clob-market-ws.price_change.v1","sequence":null,"server_hash":null,"server_timestamp":"1785127193469","session_id":"e9443c7415a0419799bee9cfbb1a9e4d","source":"clob_market_ws"},"received_at":"2026-07-27T04:39:53.415721Z","record_id":"9b2f8c3208a389afaf0363b79b849b64edd9a2e839dde7f91b31e80c7094f712","schema_fingerprint":"4aa3821a28b0b7c2400bc59aba4bcc0a76e971dadd19610d3ad38c768e124dc7","schema_version":"edge-lab-recorder.raw.v1","sequence":null,"source":"clob_market_ws"}
{"event_at":"2026-07-27T04:39:53.469000Z","event_fingerprint":"15296ec1c1cf156ddf8b50b6cc45c4d0f850fad2d4f09f0b6c9f560fdd578b16","payload":{"connection_id":"0f4979d6978d463e9660b042fdcf555f","event_at":"2026-07-27T04:39:53.469000Z","event_type":"price_change","frame_hash":"d7b7a7d4d0e6c2dbfaea0231b87a7e073f02aa40ff3cc8c2cebd9668ead293f4","frame_index":0,"kind":"data","monotonic_ns":229176682325000,"payload":{"event_type":"price_change","market":"0xeb66215f2e9faa6449e30a02bab5b8ed7b79a38bf961f6b24d0073c9c2419250","price_changes":[{"asset_id":"69697746896130839564035629862476347944307040470122503199396727085502753297492","best_ask":"0.67","best_bid":"0.66","hash":"10686e5d723a04a2de72ffeaf8568778c4eb489c","price":"0.01","side":"BUY","size":"5633.02"},{"asset_id":"60386828328910021732068595344565885737045900010034836345809386672230885527307","best_ask":"0.34","best_bid":"0.33","hash":"8e156e3dc7a248c57067877a668adc1b59db6ee8","price":"0.99","side":"SELL","size":"5633.02"}],"timestamp":"1785127193469"},"payload_hash":"a60313dc4b7e1d605b13e95bcc104b07e2e7ebcba38ac5fa3f246e80db5e4681","raw_frame":"{\"market\":\"0xeb66215f2e9faa6449e30a02bab5b8ed7b79a38bf961f6b24d0073c9c2419250\", \"price_changes\":[{\"asset_id\":\"69697746896130839564035629862476347944307040470122503199396727085502753297492\", \"price\":\"0.01\", \"size\":\"5633.02\", \"side\":\"BUY\", \"hash\":\"10686e5d723a04a2de72ffeaf8568778c4eb489c\", \"best_bid\":\"0.66\", \"best_ask\":\"0.67\"}, {\"asset_id\":\"60386828328910021732068595344565885737045900010034836345809386672230885527307\", \"price\":\"0.99\", \"size\":\"5633.02\", \"side\":\"SELL\", \"hash\":\"8e156e3dc7a248c57067877a668adc1b59db6ee8\", \"best_bid\":\"0.33\", \"best_ask\":\"0.34\"}], \"timestamp\":\"1785127193469\", \"event_type\":\"price_change\"}","received_at":"2026-07-27T04:39:53.417627Z","schema_version":"clob-market-ws.price_change.v1","sequence":null,"server_hash":null,"server_timestamp":"1785127193469","session_id":"e9443c7415a0419799bee9cfbb1a9e4d","source":"clob_market_ws"},"received_at":"2026-07-27T04:39:53.417627Z","record_id":"1f12bdc108bf697325b42295d4c3fd4486ceb5aad4bc8f9f3c02a2f926dde699","schema_fingerprint":"4aa3821a28b0b7c2400bc59aba4bcc0a76e971dadd19610d3ad38c768e124dc7","schema_version":"edge-lab-recorder.raw.v1","sequence":null,"source":"clob_market_ws"}
{"event_at":"2026-07-27T04:39:53.470000Z","event_fingerprint":"50abd5e695c0952d60985b1468147d475d07e9ecf43660754d85f6aeabd3e2b6","payload":{"connection_id":"0f4979d6978d463e9660b042fdcf555f","event_at":"2026-07-27T04:39:53.470000Z","event_type":"price_change","frame_hash":"e808ecd2a7cad4d9af1d0678e2ed5490a87b9df03f3d77118fadbc7b4f81e1e9","frame_index":0,"kind":"data","monotonic_ns":229176684154916,"payload":{"event_type":"price_change","market":"0xeb66215f2e9faa6449e30a02bab5b8ed7b79a38bf961f6b24d0073c9c2419250","price_changes":[{"asset_id":"69697746896130839564035629862476347944307040470122503199396727085502753297492","best_ask":"0.67","best_bid":"0.66","hash":"0c5f03a107bb243604fa0072fb50e89202718162","price":"0.58","side":"BUY","size":"47.3"},{"asset_id":"60386828328910021732068595344565885737045900010034836345809386672230885527307","best_ask":"0.34","best_bid":"0.33","hash":"d9d463d2bbff1bafb1229fe6f81e9def4ec68400","price":"0.42","side":"SELL","size":"47.3"}],"timestamp":"1785127193470"},"payload_hash":"f400178b05b1848afb6c434a530ac428df69b3783e9d3667ffeefb8b86aeb87d","raw_frame":"{\"market\":\"0xeb66215f2e9faa6449e30a02bab5b8ed7b79a38bf961f6b24d0073c9c2419250\", \"price_changes\":[{\"asset_id\":\"69697746896130839564035629862476347944307040470122503199396727085502753297492\", \"price\":\"0.58\", \"size\":\"47.3\", \"side\":\"BUY\", \"hash\":\"0c5f03a107bb243604fa0072fb50e89202718162\", \"best_bid\":\"0.66\", \"best_ask\":\"0.67\"}, {\"asset_id\":\"60386828328910021732068595344565885737045900010034836345809386672230885527307\", \"price\":\"0.42\", \"size\":\"47.3\", \"side\":\"SELL\", \"hash\":\"d9d463d2bbff1bafb1229fe6f81e9def4ec68400\", \"best_bid\":\"0.33\", \"best_ask\":\"0.34\"}], \"timestamp\":\"1785127193470\", \"event_type\":\"price_change\"}","received_at":"2026-07-27T04:39:53.419463Z","schema_version":"clob-market-ws.price_change.v1","sequence":null,"server_hash":null,"server_timestamp":"1785127193470","session_id":"e9443c7415a0419799bee9cfbb1a9e4d","source":"clob_market_ws"},"received_at":"2026-07-27T04:39:53.419463Z","record_id":"68b6950854054c8c3d667f80da9c8f22f8f5582184a0e8b444a1d7c6be070ca0","schema_fingerprint":"4aa3821a28b0b7c2400bc59aba4bcc0a76e971dadd19610d3ad38c768e124dc7","schema_version":"edge-lab-recorder.raw.v1","sequence":null,"source":"clob_market_ws"}
{"event_at":"2026-07-27T04:39:53.476000Z","event_fingerprint":"2dc8a58c7f4ec243f09cf36c9881446dfa5bef439498ce51c18b56f33841bd14","payload":{"connection_id":"0f4979d6978d463e9660b042fdcf555f","event_at":"2026-07-27T04:39:53.476000Z","event_type":"price_change","frame_hash":"5d11d33f1a3c3daa07ca55140c98d2e42b258f2debd7fccbc8247ff3a966cf9f","frame_index":0,"kind":"data","monotonic_ns":229176688460666,"payload":{"event_type":"price_change","market":"0xeb66215f2e9faa6449e30a02bab5b8ed7b79a38bf961f6b24d0073c9c2419250","price_changes":[{"asset_id":"69697746896130839564035629862476347944307040470122503199396727085502753297492","best_ask":"0.67","best_bid":"0.66","hash":"0e894d62f7e0f4887115f58e0b596d9c9b7f9574","price":"0.6","side":"BUY","size":"69.41"},{"asset_id":"60386828328910021732068595344565885737045900010034836345809386672230885527307","best_ask":"0.34","best_bid":"0.33","hash":"74a4750f539a11b03498c060e7694ff0d2a2bae3","price":"0.4","side":"SELL","size":"69.41"}],"timestamp":"1785127193476"},"payload_hash":"ee239012c464be378da83be91d4dd14b020d6372f0fff08a4dfab3d86d40af26","raw_frame":"{\"market\":\"0xeb66215f2e9faa6449e30a02bab5b8ed7b79a38bf961f6b24d0073c9c2419250\", \"price_changes\":[{\"asset_id\":\"69697746896130839564035629862476347944307040470122503199396727085502753297492\", \"price\":\"0.6\", \"size\":\"69.41\", \"side\":\"BUY\", \"hash\":\"0e894d62f7e0f4887115f58e0b596d9c9b7f9574\", \"best_bid\":\"0.66\", \"best_ask\":\"0.67\"}, {\"asset_id\":\"60386828328910021732068595344565885737045900010034836345809386672230885527307\", \"price\":\"0.4\", \"size\":\"69.41\", \"side\":\"SELL\", \"hash\":\"74a4750f539a11b03498c060e7694ff0d2a2bae3\", \"best_bid\":\"0.33\", \"best_ask\":\"0.34\"}], \"timestamp\":\"1785127193476\", \"event_type\":\"price_change\"}","received_at":"2026-07-27T04:39:53.423769Z","schema_version":"clob-market-ws.price_change.v1","sequence":null,"server_hash":null,"server_timestamp":"1785127193476","session_id":"e9443c7415a0419799bee9cfbb1a9e4d","source":"clob_market_ws"},"received_at":"2026-07-27T04:39:53.423769Z","record_id":"cfb7233516b138f3e3780d05cd7ffdd92d89dc2adc00c0d6920c845c14987133","schema_fingerprint":"4aa3821a28b0b7c2400bc59aba4bcc0a76e971dadd19610d3ad38c768e124dc7","schema_version":"edge-lab-recorder.raw.v1","sequence":null,"source":"clob_market_ws"}
{"event_at":"2026-07-27T04:39:53.479000Z","event_fingerprint":"3fab0f03951310ac8676815f9f0e41dd2acf712146f4f722d390299227c13969","payload":{"connection_id":"0f4979d6978d463e9660b042fdcf555f","event_at":"2026-07-27T04:39:53.479000Z","event_type":"price_change","frame_hash":"95e88df1cd564e2fd5335ea32dde6cd7ff842ff16043594728b9d49d4d2fb615","frame_index":0,"kind":"data","monotonic_ns":229176693308791,"payload":{"event_type":"price_change","market":"0xeb66215f2e9faa6449e30a02bab5b8ed7b79a38bf961f6b24d0073c9c2419250","price_changes":[{"asset_id":"69697746896130839564035629862476347944307040470122503199396727085502753297492","best_ask":"0.67","best_bid":"0.66","hash":"a365e8d28705ccb56d13b4ca45e73b1f22061bea","price":"0.03","side":"BUY","size":"618.1"},{"asset_id":"60386828328910021732068595344565885737045900010034836345809386672230885527307","best_ask":"0.34","best_bid":"0.33","hash":"cb6c88747b029d40e58cf73e86778a6b56d65ab8","price":"0.97","side":"SELL","size":"618.1"}],"timestamp":"1785127193479"},"payload_hash":"291a5bf7d52d2679e9284203ddc1a2149173be9e3c5f047cb3fc746566c491fd","raw_frame":"{\"market\":\"0xeb66215f2e9faa6449e30a02bab5b8ed7b79a38bf961f6b24d0073c9c2419250\", \"price_changes\":[{\"asset_id\":\"69697746896130839564035629862476347944307040470122503199396727085502753297492\", \"price\":\"0.03\", \"size\":\"618.1\", \"side\":\"BUY\", \"hash\":\"a365e8d28705ccb56d13b4ca45e73b1f22061bea\", \"best_bid\":\"0.66\", \"best_ask\":\"0.67\"}, {\"asset_id\":\"60386828328910021732068595344565885737045900010034836345809386672230885527307\", \"price\":\"0.97\", \"size\":\"618.1\", \"side\":\"SELL\", \"hash\":\"cb6c88747b029d40e58cf73e86778a6b56d65ab8\", \"best_bid\":\"0.33\", \"best_ask\":\"0.34\"}], \"timestamp\":\"1785127193479\", \"event_type\":\"price_change\"}","received_at":"2026-07-27T04:39:53.428617Z","schema_version":"clob-market-ws.price_change.v1","sequence":null,"server_hash":null,"server_timestamp":"1785127193479","session_id":"e9443c7415a0419799bee9cfbb1a9e4d","source":"clob_market_ws"},"received_at":"2026-07-27T04:39:53.428617Z","record_id":"0b0cbc8f2b5b4dae7295b4d9a6ba9a9c30d6ec3fdf93418c37c89a6f223ad45e","schema_fingerprint":"4aa3821a28b0b7c2400bc59aba4bcc0a76e971dadd19610d3ad38c768e124dc7","schema_version":"edge-lab-recorder.raw.v1","sequence":null,"source":"clob_market_ws"}
{"event_at":"2026-07-27T04:39:53.501000Z","event_fingerprint":"8bc86a01450755766ab15062e6abd51b04d2c7c9df0d0c1f75db8a34671f721f","payload":{"connection_id":"0f4979d6978d463e9660b042fdcf555f","event_at":"2026-07-27T04:39:53.501000Z","event_type":"price_change","frame_hash":"265811089d1c83125e909183b9e1bf0a5ee8697b3dc0c1192b99600911d3a69a","frame_index":0,"kind":"data","monotonic_ns":229176713532833,"payload":{"event_type":"price_change","market":"0xeb66215f2e9faa6449e30a02bab5b8ed7b79a38bf961f6b24d0073c9c2419250","price_changes":[{"asset_id":"69697746896130839564035629862476347944307040470122503199396727085502753297492","best_ask":"0.67","best_bid":"0.66","hash":"f2946ee2ec939f6781e5f90fbf5c7132fc42101d","price":"0.01","side":"BUY","size":"5638.02"},{"asset_id":"60386828328910021732068595344565885737045900010034836345809386672230885527307","best_ask":"0.34","best_bid":"0.33","hash":"32f78f433ce2ebe7b7575a51e7d14d4a93b7de26","price":"0.99","side":"SELL","size":"5638.02"}],"timestamp":"1785127193501"},"payload_hash":"84382b4b66708776c901831ff854caf3ac38b51eb3d4d70be68a2ec57ef67e17","raw_frame":"{\"market\":\"0xeb66215f2e9faa6449e30a02bab5b8ed7b79a38bf961f6b24d0073c9c2419250\", \"price_changes\":[{\"asset_id\":\"69697746896130839564035629862476347944307040470122503199396727085502753297492\", \"price\":\"0.01\", \"size\":\"5638.02\", \"side\":\"BUY\", \"hash\":\"f2946ee2ec939f6781e5f90fbf5c7132fc42101d\", \"best_bid\":\"0.66\", \"best_ask\":\"0.67\"}, {\"asset_id\":\"60386828328910021732068595344565885737045900010034836345809386672230885527307\", \"price\":\"0.99\", \"size\":\"5638.02\", \"side\":\"SELL\", \"hash\":\"32f78f433ce2ebe7b7575a51e7d14d4a93b7de26\", \"best_bid\":\"0.33\", \"best_ask\":\"0.34\"}], \"timestamp\":\"1785127193501\", \"event_type\":\"price_change\"}","received_at":"2026-07-27T04:39:53.448838Z","schema_version":"clob-market-ws.price_change.v1","sequence":null,"server_hash":null,"server_timestamp":"1785127193501","session_id":"e9443c7415a0419799bee9cfbb1a9e4d","source":"clob_market_ws"},"received_at":"2026-07-27T04:39:53.448838Z","record_id":"3758d6c3923b8fdd5f499f504f053ad062354890487c21e491821c43ae0c4f3f","schema_fingerprint":"4aa3821a28b0b7c2400bc59aba4bcc0a76e971dadd19610d3ad38c768e124dc7","schema_version":"edge-lab-recorder.raw.v1","sequence":null,"source":"clob_market_ws"}
{"event_at":"2026-07-27T04:39:53.522000Z","event_fingerprint":"236114b9d9ed6e30bce28bb417376348f139ee023ad3a06f969e908892787461","payload":{"connection_id":"0f4979d6978d463e9660b042fdcf555f","event_at":"2026-07-27T04:39:53.522000Z","event_type":"price_change","frame_hash":"f7931b777214c0e4a7621f3c801c72e42f64ea12dec98069338b1a179f5b91a3","frame_index":0,"kind":"data","monotonic_ns":229176734337833,"payload":{"event_type":"price_change","market":"0xeb66215f2e9faa6449e30a02bab5b8ed7b79a38bf961f6b24d0073c9c2419250","price_changes":[{"asset_id":"69697746896130839564035629862476347944307040470122503199396727085502753297492","best_ask":"0.67","best_bid":"0.66","hash":"5f181c869b48694a9555f1ee1b98a0732d0dc861","price":"0.01","side":"BUY","size":"5633.02"},{"asset_id":"60386828328910021732068595344565885737045900010034836345809386672230885527307","best_ask":"0.34","best_bid":"0.33","hash":"14652ec04ea7f984d2b8fc09ecc1975e7dedc3ae","price":"0.99","side":"SELL","size":"5633.02"}],"timestamp":"1785127193522"},"payload_hash":"4e9f6c7bfe214d2d7182073e9affd060e2e69b5379f990ba57a4c946577e6f09","raw_frame":"{\"market\":\"0xeb66215f2e9faa6449e30a02bab5b8ed7b79a38bf961f6b24d0073c9c2419250\", \"price_changes\":[{\"asset_id\":\"69697746896130839564035629862476347944307040470122503199396727085502753297492\", \"price\":\"0.01\", \"size\":\"5633.02\", \"side\":\"BUY\", \"hash\":\"5f181c869b48694a9555f1ee1b98a0732d0dc861\", \"best_bid\":\"0.66\", \"best_ask\":\"0.67\"}, {\"asset_id\":\"60386828328910021732068595344565885737045900010034836345809386672230885527307\", \"price\":\"0.99\", \"size\":\"5633.02\", \"side\":\"SELL\", \"hash\":\"14652ec04ea7f984d2b8fc09ecc1975e7dedc3ae\", \"best_bid\":\"0.33\", \"best_ask\":\"0.34\"}], \"timestamp\":\"1785127193522\", \"event_type\":\"price_change\"}","received_at":"2026-07-27T04:39:53.469641Z","schema_version":"clob-market-ws.price_change.v1","sequence":null,"server_hash":null,"server_timestamp":"1785127193522","session_id":"e9443c7415a0419799bee9cfbb1a9e4d","source":"clob_market_ws"},"received_at":"2026-07-27T04:39:53.469641Z","record_id":"23990c960184f237bcf04f9e449d9e0ddd2a197e6a0268f311a08309a361212e","schema_fingerprint":"4aa3821a28b0b7c2400bc59aba4bcc0a76e971dadd19610d3ad38c768e124dc7","schema_version":"edge-lab-recorder.raw.v1","sequence":null,"source":"clob_market_ws"}
{"event_at":"2026-07-27T04:39:53.548000Z","event_fingerprint":"cdff7ead4ddf3bc34a95fe82d1f01e8707b9953cca98b6c65dfc0676a657c75f","payload":{"connection_id":"0f4979d6978d463e9660b042fdcf555f","event_at":"2026-07-27T04:39:53.548000Z","event_type":"price_change","frame_hash":"a6347d14705cc1fade937abfdf9006760336ef97f775ccb7315d2f047ea6d297","frame_index":0,"kind":"data","monotonic_ns":229176761705708,"payload":{"event_type":"price_change","market":"0xeb66215f2e9faa6449e30a02bab5b8ed7b79a38bf961f6b24d0073c9c2419250","price_changes":[{"asset_id":"69697746896130839564035629862476347944307040470122503199396727085502753297492","best_ask":"0.67","best_bid":"0.66","hash":"6cf9efdcfc4ffa10f9b6408b2c2d240750ae52a8","price":"0.03","side":"BUY","size":"613.1"},{"asset_id":"60386828328910021732068595344565885737045900010034836345809386672230885527307","best_ask":"0.34","best_bid":"0.33","hash":"ab6870d50a77d13dccad750f730c9c3e8c0a0369","price":"0.97","side":"SELL","size":"613.1"}],"timestamp":"1785127193548"},"payload_hash":"b9e60e8170a43dbd43675d002b22f8fdef820210c2378b653edbfc91aacce090","raw_frame":"{\"market\":\"0xeb66215f2e9faa6449e30a02bab5b8ed7b79a38bf961f6b24d0073c9c2419250\", \"price_changes\":[{\"asset_id\":\"69697746896130839564035629862476347944307040470122503199396727085502753297492\", \"price\":\"0.03\", \"size\":\"613.1\", \"side\":\"BUY\", \"hash\":\"6cf9efdcfc4ffa10f9b6408b2c2d240750ae52a8\", \"best_bid\":\"0.66\", \"best_ask\":\"0.67\"}, {\"asset_id\":\"60386828328910021732068595344565885737045900010034836345809386672230885527307\", \"price\":\"0.97\", \"size\":\"613.1\", \"side\":\"SELL\", \"hash\":\"ab6870d50a77d13dccad750f730c9c3e8c0a0369\", \"best_bid\":\"0.33\", \"best_ask\":\"0.34\"}], \"timestamp\":\"1785127193548\", \"event_type\":\"price_change\"}","received_at":"2026-07-27T04:39:53.497008Z","schema_version":"clob-market-ws.price_change.v1","sequence":null,"server_hash":null,"server_timestamp":"1785127193548","session_id":"e9443c7415a0419799bee9cfbb1a9e4d","source":"clob_market_ws"},"received_at":"2026-07-27T04:39:53.497008Z","record_id":"ee7811bdb8f17fbd0b4e4059e776e25c4461488cf2f7d99589d8f57daed1233e","schema_fingerprint":"4aa3821a28b0b7c2400bc59aba4bcc0a76e971dadd19610d3ad38c768e124dc7","schema_version":"edge-lab-recorder.raw.v1","sequence":null,"source":"clob_market_ws"}
{"event_at":"2026-07-27T04:39:53.551000Z","event_fingerprint":"de67e0ed89b3888cc61ffaf0a297444a2af2a0a29b6f1ef033974e181a373238","payload":{"connection_id":"0f4979d6978d463e9660b042fdcf555f","event_at":"2026-07-27T04:39:53.551000Z","event_type":"price_change","frame_hash":"d49c54fbb48b2a147adca288eddf722a48d0d04e265e5ad1e59ff110545e9e0e","frame_index":0,"kind":"data","monotonic_ns":229176763632916,"payload":{"event_type":"price_change","market":"0xeb66215f2e9faa6449e30a02bab5b8ed7b79a38bf961f6b24d0073c9c2419250","price_changes":[{"asset_id":"60386828328910021732068595344565885737045900010034836345809386672230885527307","best_ask":"0.34","best_bid":"0.33","hash":"87635b75546dcac4ce90a8801aae8522a20a65d6","price":"0.31","side":"BUY","size":"23"},{"asset_id":"69697746896130839564035629862476347944307040470122503199396727085502753297492","best_ask":"0.67","best_bid":"0.66","hash":"ad7aad2e3d1a433477438244bf4108eb5f3a9303","price":"0.69","side":"SELL","size":"23"}],"timestamp":"1785127193551"},"payload_hash":"eebb95b99a6eba29ebbf9e03ddcddc7c2bdea3d1e741c29bfebe22c45727cce6","raw_frame":"{\"market\":\"0xeb66215f2e9faa6449e30a02bab5b8ed7b79a38bf961f6b24d0073c9c2419250\", \"price_changes\":[{\"asset_id\":\"60386828328910021732068595344565885737045900010034836345809386672230885527307\", \"price\":\"0.31\", \"size\":\"23\", \"side\":\"BUY\", \"hash\":\"87635b75546dcac4ce90a8801aae8522a20a65d6\", \"best_bid\":\"0.33\", \"best_ask\":\"0.34\"}, {\"asset_id\":\"69697746896130839564035629862476347944307040470122503199396727085502753297492\", \"price\":\"0.69\", \"size\":\"23\", \"side\":\"SELL\", \"hash\":\"ad7aad2e3d1a433477438244bf4108eb5f3a9303\", \"best_bid\":\"0.66\", \"best_ask\":\"0.67\"}], \"timestamp\":\"1785127193551\", \"event_type\":\"price_change\"}","received_at":"2026-07-27T04:39:53.498942Z","schema_version":"clob-market-ws.price_change.v1","sequence":null,"server_hash":null,"server_timestamp":"1785127193551","session_id":"e9443c7415a0419799bee9cfbb1a9e4d","source":"clob_market_ws"},"received_at":"2026-07-27T04:39:53.498942Z","record_id":"63d9b7a6160f5c048f26754d4d70f9b49dda3ab0999dda01721f014bbd982341","schema_fingerprint":"4aa3821a28b0b7c2400bc59aba4bcc0a76e971dadd19610d3ad38c768e124dc7","schema_version":"edge-lab-recorder.raw.v1","sequence":null,"source":"clob_market_ws"}
{"event_at":"2026-07-27T04:39:53.573000Z","event_fingerprint":"73a8cc8d285f40e2dd1ef7d763d931f35b9b7773363cdaa98e503f3fe2a6cd30","payload":{"connection_id":"0f4979d6978d463e9660b042fdcf555f","event_at":"2026-07-27T04:39:53.573000Z","event_type":"price_change","frame_hash":"6807bc1a9ed428da7933505ff0339e515366e222a084c3e356ecb3d8eb6bb9b8","frame_index":0,"kind":"data","monotonic_ns":229176785447333,"payload":{"event_type":"price_change","market":"0xeb66215f2e9faa6449e30a02bab5b8ed7b79a38bf961f6b24d0073c9c2419250","price_changes":[{"asset_id":"69697746896130839564035629862476347944307040470122503199396727085502753297492","best_ask":"0.67","best_bid":"0.66","hash":"e2c2f19cfdccdd7950b0e749a441f7847443544a","price":"0.6","side":"BUY","size":"20.34"},{"asset_id":"60386828328910021732068595344565885737045900010034836345809386672230885527307","best_ask":"0.34","best_bid":"0.33","hash":"9d38742cfb2000292bac12627736dad6c2a8fb79","price":"0.4","side":"SELL","size":"20.34"}],"timestamp":"1785127193573"},"payload_hash":"5f42e2fb1ebc40acffaf85dc7c5d3f0eb5744f5e3fc891391da4c5179f80ac6c","raw_frame":"{\"market\":\"0xeb66215f2e9faa6449e30a02bab5b8ed7b79a38bf961f6b24d0073c9c2419250\", \"price_changes\":[{\"asset_id\":\"69697746896130839564035629862476347944307040470122503199396727085502753297492\", \"price\":\"0.6\", \"size\":\"20.34\", \"side\":\"BUY\", \"hash\":\"e2c2f19cfdccdd7950b0e749a441f7847443544a\", \"best_bid\":\"0.66\", \"best_ask\":\"0.67\"}, {\"asset_id\":\"60386828328910021732068595344565885737045900010034836345809386672230885527307\", \"price\":\"0.4\", \"size\":\"20.34\", \"side\":\"SELL\", \"hash\":\"9d38742cfb2000292bac12627736dad6c2a8fb79\", \"best_bid\":\"0.33\", \"best_ask\":\"0.34\"}], \"timestamp\":\"1785127193573\", \"event_type\":\"price_change\"}","received_at":"2026-07-27T04:39:53.520751Z","schema_version":"clob-market-ws.price_change.v1","sequence":null,"server_hash":null,"server_timestamp":"1785127193573","session_id":"e9443c7415a0419799bee9cfbb1a9e4d","source":"clob_market_ws"},"received_at":"2026-07-27T04:39:53.520751Z","record_id":"1531d98a6d76383ffb48dcae2005600b6a5a9df53ae02f68fb9b67b8cf5fb5bb","schema_fingerprint":"4aa3821a28b0b7c2400bc59aba4bcc0a76e971dadd19610d3ad38c768e124dc7","schema_version":"edge-lab-recorder.raw.v1","sequence":null,"source":"clob_market_ws"}
{"event_at":"2026-07-27T04:39:53.580000Z","event_fingerprint":"71715eebe6d12ed953ec2560408a1cb3ec4e94a0bf0f30a7a920024b881326b0","payload":{"connection_id":"0f4979d6978d463e9660b042fdcf555f","event_at":"2026-07-27T04:39:53.580000Z","event_type":"price_change","frame_hash":"a66b788facee442df57b54115ce0aac49864750d555c42e75ebb871a02101254","frame_index":0,"kind":"data","monotonic_ns":229176792681458,"payload":{"event_type":"price_change","market":"0xeb66215f2e9faa6449e30a02bab5b8ed7b79a38bf961f6b24d0073c9c2419250","price_changes":[{"asset_id":"69697746896130839564035629862476347944307040470122503199396727085502753297492","best_ask":"0.67","best_bid":"0.66","hash":"a6c52f019f5f31f84d82e88ffa3230f8d3fd363f","price":"0.58","side":"BUY","size":"56.3"},{"asset_id":"60386828328910021732068595344565885737045900010034836345809386672230885527307","best_ask":"0.34","best_bid":"0.33","hash":"e90dcc6e87af1b9deb903cdb22dcdbd0ed661d24","price":"0.42","side":"SELL","size":"56.3"}],"timestamp":"1785127193580"},"payload_hash":"9234ce8b1141252d289102884616dcf6970758c67980fa60b698c3fb69372cff","raw_frame":"{\"market\":\"0xeb66215f2e9faa6449e30a02bab5b8ed7b79a38bf961f6b24d0073c9c2419250\", \"price_changes\":[{\"asset_id\":\"69697746896130839564035629862476347944307040470122503199396727085502753297492\", \"price\":\"0.58\", \"size\":\"56.3\", \"side\":\"BUY\", \"hash\":\"a6c52f019f5f31f84d82e88ffa3230f8d3fd363f\", \"best_bid\":\"0.66\", \"best_ask\":\"0.67\"}, {\"asset_id\":\"60386828328910021732068595344565885737045900010034836345809386672230885527307\", \"price\":\"0.42\", \"size\":\"56.3\", \"side\":\"SELL\", \"hash\":\"e90dcc6e87af1b9deb903cdb22dcdbd0ed661d24\", \"best_bid\":\"0.33\", \"best_ask\":\"0.34\"}], \"timestamp\":\"1785127193580\", \"event_type\":\"price_change\"}","received_at":"2026-07-27T04:39:53.527986Z","schema_version":"clob-market-ws.price_change.v1","sequence":null,"server_hash":null,"server_timestamp":"1785127193580","session_id":"e9443c7415a0419799bee9cfbb1a9e4d","source":"clob_market_ws"},"received_at":"2026-07-27T04:39:53.527986Z","record_id":"f8b6e906041b10bce8f1bca4f1be3df2e511572f0b3f77d6f1f41e9737ec9369","schema_fingerprint":"4aa3821a28b0b7c2400bc59aba4bcc0a76e971dadd19610d3ad38c768e124dc7","schema_version":"edge-lab-recorder.raw.v1","sequence":null,"source":"clob_market_ws"}
{"event_at":"2026-07-27T04:39:53.584000Z","event_fingerprint":"a20429d10eb25b559adffbb7087dbbc8d06071068dd405d6735ea77a94dc2bbe","payload":{"connection_id":"0f4979d6978d463e9660b042fdcf555f","event_at":"2026-07-27T04:39:53.584000Z","event_type":"price_change","frame_hash":"11b1816ac946e5005addff6b69e62dcaca2a7e08359e56b8bf5890886afedbf6","frame_index":0,"kind":"data","monotonic_ns":229176797647708,"payload":{"event_type":"price_change","market":"0xeb66215f2e9faa6449e30a02bab5b8ed7b79a38bf961f6b24d0073c9c2419250","price_changes":[{"asset_id":"60386828328910021732068595344565885737045900010034836345809386672230885527307","best_ask":"0.34","best_bid":"0.33","hash":"126104c6ca451e2dbae52f279045e70fd1d8c33f","price":"0.4","side":"SELL","size":"70.41"},{"asset_id":"69697746896130839564035629862476347944307040470122503199396727085502753297492","best_ask":"0.67","best_bid":"0.66","hash":"c82a42e711dffa9ff25ab8975364722582ef1871","price":"0.6","side":"BUY","size":"70.41"}],"timestamp":"1785127193584"},"payload_hash":"ae005234afc02c9b1943e649722307bc9f8c8a496b2930f3deeb1347c88d9262","raw_frame":"{\"market\":\"0xeb66215f2e9faa6449e30a02bab5b8ed7b79a38bf961f6b24d0073c9c2419250\", \"price_changes\":[{\"asset_id\":\"60386828328910021732068595344565885737045900010034836345809386672230885527307\", \"price\":\"0.4\", \"size\":\"70.41\", \"side\":\"SELL\", \"hash\":\"126104c6ca451e2dbae52f279045e70fd1d8c33f\", \"best_bid\":\"0.33\", \"best_ask\":\"0.34\"}, {\"asset_id\":\"69697746896130839564035629862476347944307040470122503199396727085502753297492\", \"price\":\"0.6\", \"size\":\"70.41\", \"side\":\"BUY\", \"hash\":\"c82a42e711dffa9ff25ab8975364722582ef1871\", \"best_bid\":\"0.66\", \"best_ask\":\"0.67\"}], \"timestamp\":\"1785127193584\", \"event_type\":\"price_change\"}","received_at":"2026-07-27T04:39:53.532955Z","schema_version":"clob-market-ws.price_change.v1","sequence":null,"server_hash":null,"server_timestamp":"1785127193584","session_id":"e9443c7415a0419799bee9cfbb1a9e4d","source":"clob_market_ws"},"received_at":"2026-07-27T04:39:53.532955Z","record_id":"2d00a25962730012cef48c3225907a6ff6631d6b1d28eab62caccbc33bb20596","schema_fingerprint":"4aa3821a28b0b7c2400bc59aba4bcc0a76e971dadd19610d3ad38c768e124dc7","schema_version":"edge-lab-recorder.raw.v1","sequence":null,"source":"clob_market_ws"}
{"event_at":"2026-07-27T04:39:53.622000Z","event_fingerprint":"731d6065507568532f26eb9ca5f0b018053d0b39c1a096e1c92fc82386815060","payload":{"connection_id":"0f4979d6978d463e9660b042fdcf555f","event_at":"2026-07-27T04:39:53.622000Z","event_type":"price_change","frame_hash":"7a99a79773d53caf74d1c122cd3182832d0f7aaa8c5f60977e35093cf201271e","frame_index":0,"kind":"data","monotonic_ns":229176833882083,"payload":{"event_type":"price_change","market":"0xeb66215f2e9faa6449e30a02bab5b8ed7b79a38bf961f6b24d0073c9c2419250","price_changes":[{"asset_id":"69697746896130839564035629862476347944307040470122503199396727085502753297492","best_ask":"0.67","best_bid":"0.66","hash":"d6e63f75a66060b72e71296048351f73f2865841","price":"0.54","side":"BUY","size":"162.1"},{"asset_id":"60386828328910021732068595344565885737045900010034836345809386672230885527307","best_ask":"0.34","best_bid":"0.33","hash":"f24566c5aebd4e021f046b9cc286f02fa949e960","price":"0.46","side":"SELL","size":"162.1"}],"timestamp":"1785127193622"},"payload_hash":"3810a5489f401434c5225369394ab9a78c289bec2c7cdb8ab768aa284daea79d","raw_frame":"{\"market\":\"0xeb66215f2e9faa6449e30a02bab5b8ed7b79a38bf961f6b24d0073c9c2419250\", \"price_changes\":[{\"asset_id\":\"69697746896130839564035629862476347944307040470122503199396727085502753297492\", \"price\":\"0.54\", \"size\":\"162.1\", \"side\":\"BUY\", \"hash\":\"d6e63f75a66060b72e71296048351f73f2865841\", \"best_bid\":\"0.66\", \"best_ask\":\"0.67\"}, {\"asset_id\":\"60386828328910021732068595344565885737045900010034836345809386672230885527307\", \"price\":\"0.46\", \"size\":\"162.1\", \"side\":\"SELL\", \"hash\":\"f24566c5aebd4e021f046b9cc286f02fa949e960\", \"best_bid\":\"0.33\", \"best_ask\":\"0.34\"}], \"timestamp\":\"1785127193622\", \"event_type\":\"price_change\"}","received_at":"2026-07-27T04:39:53.569189Z","schema_version":"clob-market-ws.price_change.v1","sequence":null,"server_hash":null,"server_timestamp":"1785127193622","session_id":"e9443c7415a0419799bee9cfbb1a9e4d","source":"clob_market_ws"},"received_at":"2026-07-27T04:39:53.569189Z","record_id":"5270e9d282ebf20d1a4a124a70e99cf312bbd771083a5b42f054f9405ffcad55","schema_fingerprint":"4aa3821a28b0b7c2400bc59aba4bcc0a76e971dadd19610d3ad38c768e124dc7","schema_version":"edge-lab-recorder.raw.v1","sequence":null,"source":"clob_market_ws"}
{"event_at":"2026-07-27T04:39:53.641000Z","event_fingerprint":"49a57ea438313fefa1e7be8cbffeb74dcc0655ac406d0d6a70e0a3c384f1d486","payload":{"connection_id":"0f4979d6978d463e9660b042fdcf555f","event_at":"2026-07-27T04:39:53.641000Z","event_type":"price_change","frame_hash":"8abfdb874c5fe81cf479d3fc0eb6083517bb5f46d8ecfb5385bfa4bcee70c249","frame_index":0,"kind":"data","monotonic_ns":229176852181333,"payload":{"event_type":"price_change","market":"0xeb66215f2e9faa6449e30a02bab5b8ed7b79a38bf961f6b24d0073c9c2419250","price_changes":[{"asset_id":"60386828328910021732068595344565885737045900010034836345809386672230885527307","best_ask":"0.34","best_bid":"0.33","hash":"5e22587ef4dfbea19513f9f557261a2fcc045733","price":"0.33","side":"BUY","size":"160.6"},{"asset_id":"69697746896130839564035629862476347944307040470122503199396727085502753297492","best_ask":"0.67","best_bid":"0.66","hash":"ed4152eaba4de9eb0cf0f3233f28e0db12ab9cc0","price":"0.67","side":"SELL","size":"160.6"}],"timestamp":"1785127193641"},"payload_hash":"8da80a377216d7ce9a14e7e9d4787de9f394d127f837e4eebb5ef8a7c344839a","raw_frame":"{\"market\":\"0xeb66215f2e9faa6449e30a02bab5b8ed7b79a38bf961f6b24d0073c9c2419250\", \"price_changes\":[{\"asset_id\":\"60386828328910021732068595344565885737045900010034836345809386672230885527307\", \"price\":\"0.33\", \"size\":\"160.6\", \"side\":\"BUY\", \"hash\":\"5e22587ef4dfbea19513f9f557261a2fcc045733\", \"best_bid\":\"0.33\", \"best_ask\":\"0.34\"}, {\"asset_id\":\"69697746896130839564035629862476347944307040470122503199396727085502753297492\", \"price\":\"0.67\", \"size\":\"160.6\", \"side\":\"SELL\", \"hash\":\"ed4152eaba4de9eb0cf0f3233f28e0db12ab9cc0\", \"best_bid\":\"0.66\", \"best_ask\":\"0.67\"}], \"timestamp\":\"1785127193641\", \"event_type\":\"price_change\"}","received_at":"2026-07-27T04:39:53.587496Z","schema_version":"clob-market-ws.price_change.v1","sequence":null,"server_hash":null,"server_timestamp":"1785127193641","session_id":"e9443c7415a0419799bee9cfbb1a9e4d","source":"clob_market_ws"},"received_at":"2026-07-27T04:39:53.587496Z","record_id":"5f80f025fdc6f67f5b12910b994303ce74be1d5684854d10f2eb9d332b340e26","schema_fingerprint":"4aa3821a28b0b7c2400bc59aba4bcc0a76e971dadd19610d3ad38c768e124dc7","schema_version":"edge-lab-recorder.raw.v1","sequence":null,"source":"clob_market_ws"}
{"event_at":"2026-07-27T04:39:53.647000Z","event_fingerprint":"5c87367421a0597613a7581d7a6918088c8eea344965e7eea2ab7ebb9e215b7a","payload":{"connection_id":"0f4979d6978d463e9660b042fdcf555f","event_at":"2026-07-27T04:39:53.647000Z","event_type":"price_change","frame_hash":"6c1a32affa56125c4f185aff2f42b784eb68da4d79964a556d221322bd743392","frame_index":0,"kind":"data","monotonic_ns":229176862619250,"payload":{"event_type":"price_change","market":"0xeb66215f2e9faa6449e30a02bab5b8ed7b79a38bf961f6b24d0073c9c2419250","price_changes":[{"asset_id":"69697746896130839564035629862476347944307040470122503199396727085502753297492","best_ask":"0.67","best_bid":"0.66","hash":"84d92b56dcbfb21174d0aef1a4d3e82623770a9d","price":"0.03","side":"BUY","size":"618.1"},{"asset_id":"60386828328910021732068595344565885737045900010034836345809386672230885527307","best_ask":"0.34","best_bid":"0.33","hash":"1370ff458d5e0e19fdaca03cb989b36a1ffb929e","price":"0.97","side":"SELL","size":"618.1"}],"timestamp":"1785127193647"},"payload_hash":"641fe63e13e1d5ae455f3bae0c65991103c9f42426c5cdab3fa228c15ec20dbe","raw_frame":"{\"market\":\"0xeb66215f2e9faa6449e30a02bab5b8ed7b79a38bf961f6b24d0073c9c2419250\", \"price_changes\":[{\"asset_id\":\"69697746896130839564035629862476347944307040470122503199396727085502753297492\", \"price\":\"0.03\", \"size\":\"618.1\", \"side\":\"BUY\", \"hash\":\"84d92b56dcbfb21174d0aef1a4d3e82623770a9d\", \"best_bid\":\"0.66\", \"best_ask\":\"0.67\"}, {\"asset_id\":\"60386828328910021732068595344565885737045900010034836345809386672230885527307\", \"price\":\"0.97\", \"size\":\"618.1\", \"side\":\"SELL\", \"hash\":\"1370ff458d5e0e19fdaca03cb989b36a1ffb929e\", \"best_bid\":\"0.33\", \"best_ask\":\"0.34\"}], \"timestamp\":\"1785127193647\", \"event_type\":\"price_change\"}","received_at":"2026-07-27T04:39:53.597928Z","schema_version":"clob-market-ws.price_change.v1","sequence":null,"server_hash":null,"server_timestamp":"1785127193647","session_id":"e9443c7415a0419799bee9cfbb1a9e4d","source":"clob_market_ws"},"received_at":"2026-07-27T04:39:53.597928Z","record_id":"a9da33b3144e5d705737a156fab2653479eb02d5061dac47ae3f8ec318b70480","schema_fingerprint":"4aa3821a28b0b7c2400bc59aba4bcc0a76e971dadd19610d3ad38c768e124dc7","schema_version":"edge-lab-recorder.raw.v1","sequence":null,"source":"clob_market_ws"}
{"event_at":"2026-07-27T04:39:53.689000Z","event_fingerprint":"99e8c408a7bd7d468b64f355074c92b57edcf1b69c4ff495036c5474002f0704","payload":{"connection_id":"0f4979d6978d463e9660b042fdcf555f","event_at":"2026-07-27T04:39:53.689000Z","event_type":"price_change","frame_hash":"1b1c26584709ada82e63fdf7ec82a26821b8fd8950e2e91b9ea40d365b8c2fb4","frame_index":0,"kind":"data","monotonic_ns":229176901404125,"payload":{"event_type":"price_change","market":"0xeb66215f2e9faa6449e30a02bab5b8ed7b79a38bf961f6b24d0073c9c2419250","price_changes":[{"asset_id":"69697746896130839564035629862476347944307040470122503199396727085502753297492","best_ask":"0.67","best_bid":"0.66","hash":"53a422dd44619fcf77cb6f91593ccb625cd4189a","price":"0.57","side":"BUY","size":"152.2"},{"asset_id":"60386828328910021732068595344565885737045900010034836345809386672230885527307","best_ask":"0.34","best_bid":"0.33","hash":"3628c58149743ad92e8d78a797845bd2774c53e6","price":"0.43","side":"SELL","size":"152.2"}],"timestamp":"1785127193689"},"payload_hash":"8aadf5fa4b2ef73feb1f921f002579852ac54e2ec95a524e22bfbc89acc9cfcc","raw_frame":"{\"market\":\"0xeb66215f2e9faa6449e30a02bab5b8ed7b79a38bf961f6b24d0073c9c2419250\", \"price_changes\":[{\"asset_id\":\"69697746896130839564035629862476347944307040470122503199396727085502753297492\", \"price\":\"0.57\", \"size\":\"152.2\", \"side\":\"BUY\", \"hash\":\"53a422dd44619fcf77cb6f91593ccb625cd4189a\", \"best_bid\":\"0.66\", \"best_ask\":\"0.67\"}, {\"asset_id\":\"60386828328910021732068595344565885737045900010034836345809386672230885527307\", \"price\":\"0.43\", \"size\":\"152.2\", \"side\":\"SELL\", \"hash\":\"3628c58149743ad92e8d78a797845bd2774c53e6\", \"best_bid\":\"0.33\", \"best_ask\":\"0.34\"}], \"timestamp\":\"1785127193689\", \"event_type\":\"price_change\"}","received_at":"2026-07-27T04:39:53.636718Z","schema_version":"clob-market-ws.price_change.v1","sequence":null,"server_hash":null,"server_timestamp":"1785127193689","session_id":"e9443c7415a0419799bee9cfbb1a9e4d","source":"clob_market_ws"},"received_at":"2026-07-27T04:39:53.636718Z","record_id":"46e226400f6110fb5765d3afc64d78b1542e3f290a30e991c898a7699de85b40","schema_fingerprint":"4aa3821a28b0b7c2400bc59aba4bcc0a76e971dadd19610d3ad38c768e124dc7","schema_version":"edge-lab-recorder.raw.v1","sequence":null,"source":"clob_market_ws"}
{"event_at":"2026-07-27T04:39:53.706000Z","event_fingerprint":"67f8910228954fc7ae414c05e5f8024673c057c9c311c71f937ae8315aa767a6","payload":{"connection_id":"0f4979d6978d463e9660b042fdcf555f","event_at":"2026-07-27T04:39:53.706000Z","event_type":"price_change","frame_hash":"2c75568b9884b86182b82c94f3ed00573a406fe47d4a4b4748d58185a17c9836","frame_index":0,"kind":"data","monotonic_ns":229176918311750,"payload":{"event_type":"price_change","market":"0xeb66215f2e9faa6449e30a02bab5b8ed7b79a38bf961f6b24d0073c9c2419250","price_changes":[{"asset_id":"69697746896130839564035629862476347944307040470122503199396727085502753297492","best_ask":"0.67","best_bid":"0.66","hash":"91bb3880f9dbed41708824376a558622ad949e11","price":"0.03","side":"BUY","size":"613.1"},{"asset_id":"60386828328910021732068595344565885737045900010034836345809386672230885527307","best_ask":"0.34","best_bid":"0.33","hash":"49ba9be75bc4fa10bb544235da3adf967f8518fe","price":"0.97","side":"SELL","size":"613.1"}],"timestamp":"1785127193706"},"payload_hash":"a75bf0f28f2907391621e13766d04a504be5593b987d89578051cc0fae4e9bf2","raw_frame":"{\"market\":\"0xeb66215f2e9faa6449e30a02bab5b8ed7b79a38bf961f6b24d0073c9c2419250\", \"price_changes\":[{\"asset_id\":\"69697746896130839564035629862476347944307040470122503199396727085502753297492\", \"price\":\"0.03\", \"size\":\"613.1\", \"side\":\"BUY\", \"hash\":\"91bb3880f9dbed41708824376a558622ad949e11\", \"best_bid\":\"0.66\", \"best_ask\":\"0.67\"}, {\"asset_id\":\"60386828328910021732068595344565885737045900010034836345809386672230885527307\", \"price\":\"0.97\", \"size\":\"613.1\", \"side\":\"SELL\", \"hash\":\"49ba9be75bc4fa10bb544235da3adf967f8518fe\", \"best_bid\":\"0.33\", \"best_ask\":\"0.34\"}], \"timestamp\":\"1785127193706\", \"event_type\":\"price_change\"}","received_at":"2026-07-27T04:39:53.653620Z","schema_version":"clob-market-ws.price_change.v1","sequence":null,"server_hash":null,"server_timestamp":"1785127193706","session_id":"e9443c7415a0419799bee9cfbb1a9e4d","source":"clob_market_ws"},"received_at":"2026-07-27T04:39:53.653620Z","record_id":"64dbc8d75d01eda7c9dd74584f11226d550d4a257cef6d385d99e685c5e3c7ba","schema_fingerprint":"4aa3821a28b0b7c2400bc59aba4bcc0a76e971dadd19610d3ad38c768e124dc7","schema_version":"edge-lab-recorder.raw.v1","sequence":null,"source":"clob_market_ws"}
{"event_at":"2026-07-27T04:39:53.723000Z","event_fingerprint":"cb1338ea920fc1feacf633e3aaaaae2cfca0e711543b51cd0c8571cf16548b1c","payload":{"connection_id":"0f4979d6978d463e9660b042fdcf555f","event_at":"2026-07-27T04:39:53.723000Z","event_type":"price_change","frame_hash":"6be7748f09fa3b2f2af1ab68e200340cf102c4ca4a38f4a84bc5cf6b779acc7d","frame_index":0,"kind":"data","monotonic_ns":229176933801291,"payload":{"event_type":"price_change","market":"0xeb66215f2e9faa6449e30a02bab5b8ed7b79a38bf961f6b24d0073c9c2419250","price_changes":[{"asset_id":"60386828328910021732068595344565885737045900010034836345809386672230885527307","best_ask":"0.34","best_bid":"0.33","hash":"46a3f8abfeb833d520b0eedd8d4950cf64c76548","price":"0.4","side":"SELL","size":"20.34"},{"asset_id":"69697746896130839564035629862476347944307040470122503199396727085502753297492","best_ask":"0.67","best_bid":"0.66","hash":"b35aaf5c717689a7222d4caa18adc51fcabcb5fd","price":"0.6","side":"BUY","size":"20.34"}],"timestamp":"1785127193723"},"payload_hash":"51181b3cfd66a8429174c10e113233ae8aaf2ea6de15dd3c3d476ea7752959b8","raw_frame":"{\"market\":\"0xeb66215f2e9faa6449e30a02bab5b8ed7b79a38bf961f6b24d0073c9c2419250\", \"price_changes\":[{\"asset_id\":\"60386828328910021732068595344565885737045900010034836345809386672230885527307\", \"price\":\"0.4\", \"size\":\"20.34\", \"side\":\"SELL\", \"hash\":\"46a3f8abfeb833d520b0eedd8d4950cf64c76548\", \"best_bid\":\"0.33\", \"best_ask\":\"0.34\"}, {\"asset_id\":\"69697746896130839564035629862476347944307040470122503199396727085502753297492\", \"price\":\"0.6\", \"size\":\"20.34\", \"side\":\"BUY\", \"hash\":\"b35aaf5c717689a7222d4caa18adc51fcabcb5fd\", \"best_bid\":\"0.66\", \"best_ask\":\"0.67\"}], \"timestamp\":\"1785127193723\", \"event_type\":\"price_change\"}","received_at":"2026-07-27T04:39:53.669107Z","schema_version":"clob-market-ws.price_change.v1","sequence":null,"server_hash":null,"server_timestamp":"1785127193723","session_id":"e9443c7415a0419799bee9cfbb1a9e4d","source":"clob_market_ws"},"received_at":"2026-07-27T04:39:53.669107Z","record_id":"bd8f1c17b8c30dcd5e1d21c1a4abb3875824f09ca15b3f315e897c4f125f4faf","schema_fingerprint":"4aa3821a28b0b7c2400bc59aba4bcc0a76e971dadd19610d3ad38c768e124dc7","schema_version":"edge-lab-recorder.raw.v1","sequence":null,"source":"clob_market_ws"}
{"event_at":"2026-07-27T04:39:53.725000Z","event_fingerprint":"e7f75e8139cbc701d62bd15fbc5b76f96d10fee278e207e3f65c6df17e8f0024","payload":{"connection_id":"0f4979d6978d463e9660b042fdcf555f","event_at":"2026-07-27T04:39:53.725000Z","event_type":"price_change","frame_hash":"54575fd18cebaf05990e15070bf493cc025cdde1b5878bd78cda1b05db9d8895","frame_index":0,"kind":"data","monotonic_ns":229176936257416,"payload":{"event_type":"price_change","market":"0xeb66215f2e9faa6449e30a02bab5b8ed7b79a38bf961f6b24d0073c9c2419250","price_changes":[{"asset_id":"69697746896130839564035629862476347944307040470122503199396727085502753297492","best_ask":"0.67","best_bid":"0.66","hash":"74aba328ddbe7f3fb3fbbe4be21685c6fc970649","price":"0.58","side":"BUY","size":"47.3"},{"asset_id":"60386828328910021732068595344565885737045900010034836345809386672230885527307","best_ask":"0.34","best_bid":"0.33","hash":"884b119471a0dafd6300ba0bbde7b61b6e987cf1","price":"0.42","side":"SELL","size":"47.3"}],"timestamp":"1785127193725"},"payload_hash":"450949b941b21acede037bb773169e235c486b4666f44396681caaf1166807fd","raw_frame":"{\"market\":\"0xeb66215f2e9faa6449e30a02bab5b8ed7b79a38bf961f6b24d0073c9c2419250\", \"price_changes\":[{\"asset_id\":\"69697746896130839564035629862476347944307040470122503199396727085502753297492\", \"price\":\"0.58\", \"size\":\"47.3\", \"side\":\"BUY\", \"hash\":\"74aba328ddbe7f3fb3fbbe4be21685c6fc970649\", \"best_bid\":\"0.66\", \"best_ask\":\"0.67\"}, {\"asset_id\":\"60386828328910021732068595344565885737045900010034836345809386672230885527307\", \"price\":\"0.42\", \"size\":\"47.3\", \"side\":\"SELL\", \"hash\":\"884b119471a0dafd6300ba0bbde7b61b6e987cf1\", \"best_bid\":\"0.33\", \"best_ask\":\"0.34\"}], \"timestamp\":\"1785127193725\", \"event_type\":\"price_change\"}","received_at":"2026-07-27T04:39:53.671565Z","schema_version":"clob-market-ws.price_change.v1","sequence":null,"server_hash":null,"server_timestamp":"1785127193725","session_id":"e9443c7415a0419799bee9cfbb1a9e4d","source":"clob_market_ws"},"received_at":"2026-07-27T04:39:53.671565Z","record_id":"919551ff2c8d84c98b1831966b17d14d4ad5a857e606e2c8897a11140b9e810c","schema_fingerprint":"4aa3821a28b0b7c2400bc59aba4bcc0a76e971dadd19610d3ad38c768e124dc7","schema_version":"edge-lab-recorder.raw.v1","sequence":null,"source":"clob_market_ws"}
{"event_at":"2026-07-27T04:39:53.729000Z","event_fingerprint":"dc6329f33375215f87af53fe7d2d5fd74a4cdf21c1edff935cab6e870862c0bf","payload":{"connection_id":"0f4979d6978d463e9660b042fdcf555f","event_at":"2026-07-27T04:39:53.729000Z","event_type":"price_change","frame_hash":"bdbebf7c36ba71fcb7574b74e414facc18603700fdd9a0098bfc0ecbf78181cd","frame_index":0,"kind":"data","monotonic_ns":229176940115208,"payload":{"event_type":"price_change","market":"0xeb66215f2e9faa6449e30a02bab5b8ed7b79a38bf961f6b24d0073c9c2419250","price_changes":[{"asset_id":"69697746896130839564035629862476347944307040470122503199396727085502753297492","best_ask":"0.67","best_bid":"0.66","hash":"15505cf94779fe7cd1aa98509de876638bc8d738","price":"0.6","side":"BUY","size":"69.41"},{"asset_id":"60386828328910021732068595344565885737045900010034836345809386672230885527307","best_ask":"0.34","best_bid":"0.33","hash":"dfcc31ea6c5bf288df204c47b477f07f1445d450","price":"0.4","side":"SELL","size":"69.41"}],"timestamp":"1785127193729"},"payload_hash":"0e00be95c3618635f6a95472c85a892e33d59b683466a376853d13f23cb2979c","raw_frame":"{\"market\":\"0xeb66215f2e9faa6449e30a02bab5b8ed7b79a38bf961f6b24d0073c9c2419250\", \"price_changes\":[{\"asset_id\":\"69697746896130839564035629862476347944307040470122503199396727085502753297492\", \"price\":\"0.6\", \"size\":\"69.41\", \"side\":\"BUY\", \"hash\":\"15505cf94779fe7cd1aa98509de876638bc8d738\", \"best_bid\":\"0.66\", \"best_ask\":\"0.67\"}, {\"asset_id\":\"60386828328910021732068595344565885737045900010034836345809386672230885527307\", \"price\":\"0.4\", \"size\":\"69.41\", \"side\":\"SELL\", \"hash\":\"dfcc31ea6c5bf288df204c47b477f07f1445d450\", \"best_bid\":\"0.33\", \"best_ask\":\"0.34\"}], \"timestamp\":\"1785127193729\", \"event_type\":\"price_change\"}","received_at":"2026-07-27T04:39:53.675424Z","schema_version":"clob-market-ws.price_change.v1","sequence":null,"server_hash":null,"server_timestamp":"1785127193729","session_id":"e9443c7415a0419799bee9cfbb1a9e4d","source":"clob_market_ws"},"received_at":"2026-07-27T04:39:53.675424Z","record_id":"c479a6eb4d52df1e4b58744be1fd112a9754d37a8c079fc0c034f498e0d8b3cb","schema_fingerprint":"4aa3821a28b0b7c2400bc59aba4bcc0a76e971dadd19610d3ad38c768e124dc7","schema_version":"edge-lab-recorder.raw.v1","sequence":null,"source":"clob_market_ws"}
{"event_at":"2026-07-27T04:39:53.792000Z","event_fingerprint":"2c44ed7df025854243006fa2854d37ca72e71b89d100c8ca62137a5372c89d65","payload":{"connection_id":"0f4979d6978d463e9660b042fdcf555f","event_at":"2026-07-27T04:39:53.792000Z","event_type":"price_change","frame_hash":"c05a472c6c2f24f2ad4e598349bc9177dd4ae8c8410ddd179f68d200525357a0","frame_index":0,"kind":"data","monotonic_ns":229177003934833,"payload":{"event_type":"price_change","market":"0xeb66215f2e9faa6449e30a02bab5b8ed7b79a38bf961f6b24d0073c9c2419250","price_changes":[{"asset_id":"69697746896130839564035629862476347944307040470122503199396727085502753297492","best_ask":"0.67","best_bid":"0.66","hash":"8111e2ebc30e574343c91457dcd402ca8c9c5ac4","price":"0.6","side":"BUY","size":"56.99"},{"asset_id":"60386828328910021732068595344565885737045900010034836345809386672230885527307","best_ask":"0.34","best_bid":"0.33","hash":"052d80dbbec451bb5ff7a475468122d6b3f44037","price":"0.4","side":"SELL","size":"56.99"}],"timestamp":"1785127193792"},"payload_hash":"eff3abb9c8f21b0e90f140c1f255aaea4818c2a01e29b0744b9f1ce44a91be97","raw_frame":"{\"market\":\"0xeb66215f2e9faa6449e30a02bab5b8ed7b79a38bf961f6b24d0073c9c2419250\", \"price_changes\":[{\"asset_id\":\"69697746896130839564035629862476347944307040470122503199396727085502753297492\", \"price\":\"0.6\", \"size\":\"56.99\", \"side\":\"BUY\", \"hash\":\"8111e2ebc30e574343c91457dcd402ca8c9c5ac4\", \"best_bid\":\"0.66\", \"best_ask\":\"0.67\"}, {\"asset_id\":\"60386828328910021732068595344565885737045900010034836345809386672230885527307\", \"price\":\"0.4\", \"size\":\"56.99\", \"side\":\"SELL\", \"hash\":\"052d80dbbec451bb5ff7a475468122d6b3f44037\", \"best_bid\":\"0.33\", \"best_ask\":\"0.34\"}], \"timestamp\":\"1785127193792\", \"event_type\":\"price_change\"}","received_at":"2026-07-27T04:39:53.739246Z","schema_version":"clob-market-ws.price_change.v1","sequence":null,"server_hash":null,"server_timestamp":"1785127193792","session_id":"e9443c7415a0419799bee9cfbb1a9e4d","source":"clob_market_ws"},"received_at":"2026-07-27T04:39:53.739246Z","record_id":"7f4c370615fd4cd5df615d74b120071483c543a8cd102d504f1f6a86e9524f82","schema_fingerprint":"4aa3821a28b0b7c2400bc59aba4bcc0a76e971dadd19610d3ad38c768e124dc7","schema_version":"edge-lab-recorder.raw.v1","sequence":null,"source":"clob_market_ws"}
{"event_at":"2026-07-27T04:39:53.798000Z","event_fingerprint":"2ff5756673b63d1d061f724777a1fed622cac91ab3034411ef759670f5be397d","payload":{"connection_id":"0f4979d6978d463e9660b042fdcf555f","event_at":"2026-07-27T04:39:53.798000Z","event_type":"price_change","frame_hash":"65efe2a4b2914b72ff252a25b3b901a00e0db2af4c7717f4cc475889f14fa094","frame_index":0,"kind":"data","monotonic_ns":229177009424791,"payload":{"event_type":"price_change","market":"0xeb66215f2e9faa6449e30a02bab5b8ed7b79a38bf961f6b24d0073c9c2419250","price_changes":[{"asset_id":"69697746896130839564035629862476347944307040470122503199396727085502753297492","best_ask":"0.67","best_bid":"0.66","hash":"75fbbe9e1e60ee2b28459d6bf36707de9b64780b","price":"0.64","side":"BUY","size":"118.35"},{"asset_id":"60386828328910021732068595344565885737045900010034836345809386672230885527307","best_ask":"0.34","best_bid":"0.33","hash":"a2b5b71aa40d5f24053512225977553ee94dad2f","price":"0.36","side":"SELL","size":"118.35"}],"timestamp":"1785127193798"},"payload_hash":"165fb94d3235886c8227d84f6f3532f7703d43ae44a690515cd585e53eeed0f3","raw_frame":"{\"market\":\"0xeb66215f2e9faa6449e30a02bab5b8ed7b79a38bf961f6b24d0073c9c2419250\", \"price_changes\":[{\"asset_id\":\"69697746896130839564035629862476347944307040470122503199396727085502753297492\", \"price\":\"0.64\", \"size\":\"118.35\", \"side\":\"BUY\", \"hash\":\"75fbbe9e1e60ee2b28459d6bf36707de9b64780b\", \"best_bid\":\"0.66\", \"best_ask\":\"0.67\"}, {\"asset_id\":\"60386828328910021732068595344565885737045900010034836345809386672230885527307\", \"price\":\"0.36\", \"size\":\"118.35\", \"side\":\"SELL\", \"hash\":\"a2b5b71aa40d5f24053512225977553ee94dad2f\", \"best_bid\":\"0.33\", \"best_ask\":\"0.34\"}], \"timestamp\":\"1785127193798\", \"event_type\":\"price_change\"}","received_at":"2026-07-27T04:39:53.744734Z","schema_version":"clob-market-ws.price_change.v1","sequence":null,"server_hash":null,"server_timestamp":"1785127193798","session_id":"e9443c7415a0419799bee9cfbb1a9e4d","source":"clob_market_ws"},"received_at":"2026-07-27T04:39:53.744734Z","record_id":"396a29220d8a672262fe7c2e0b8663280149cd622612c05e003738f399f0dee1","schema_fingerprint":"4aa3821a28b0b7c2400bc59aba4bcc0a76e971dadd19610d3ad38c768e124dc7","schema_version":"edge-lab-recorder.raw.v1","sequence":null,"source":"clob_market_ws"}
{"event_at":"2026-07-27T04:39:53.802000Z","event_fingerprint":"bdbfbeece347a07aa2cc84cccedca8d6c1b7e3b6ba403e5aaa35c0052c3bd225","payload":{"connection_id":"0f4979d6978d463e9660b042fdcf555f","event_at":"2026-07-27T04:39:53.802000Z","event_type":"price_change","frame_hash":"58539a3725b32e61587f262bd59dd96c4e62de3826309ead631f1efe92886bb8","frame_index":0,"kind":"data","monotonic_ns":229177013632666,"payload":{"event_type":"price_change","market":"0xeb66215f2e9faa6449e30a02bab5b8ed7b79a38bf961f6b24d0073c9c2419250","price_changes":[{"asset_id":"69697746896130839564035629862476347944307040470122503199396727085502753297492","best_ask":"0.67","best_bid":"0.66","hash":"e6a6624336fb3bb5b516005706ee185264962f35","price":"0.01","side":"BUY","size":"5638.02"},{"asset_id":"60386828328910021732068595344565885737045900010034836345809386672230885527307","best_ask":"0.34","best_bid":"0.33","hash":"35d8973d7117a983ef94e54c91613b2e1a47291f","price":"0.99","side":"SELL","size":"5638.02"}],"timestamp":"1785127193802"},"payload_hash":"e7652fc1fbee224be8ea95284f7a63b74cf66a7674dafd62068b3eaf56309c54","raw_frame":"{\"market\":\"0xeb66215f2e9faa6449e30a02bab5b8ed7b79a38bf961f6b24d0073c9c2419250\", \"price_changes\":[{\"asset_id\":\"69697746896130839564035629862476347944307040470122503199396727085502753297492\", \"price\":\"0.01\", \"size\":\"5638.02\", \"side\":\"BUY\", \"hash\":\"e6a6624336fb3bb5b516005706ee185264962f35\", \"best_bid\":\"0.66\", \"best_ask\":\"0.67\"}, {\"asset_id\":\"60386828328910021732068595344565885737045900010034836345809386672230885527307\", \"price\":\"0.99\", \"size\":\"5638.02\", \"side\":\"SELL\", \"hash\":\"35d8973d7117a983ef94e54c91613b2e1a47291f\", \"best_bid\":\"0.33\", \"best_ask\":\"0.34\"}], \"timestamp\":\"1785127193802\", \"event_type\":\"price_change\"}","received_at":"2026-07-27T04:39:53.748945Z","schema_version":"clob-market-ws.price_change.v1","sequence":null,"server_hash":null,"server_timestamp":"1785127193802","session_id":"e9443c7415a0419799bee9cfbb1a9e4d","source":"clob_market_ws"},"received_at":"2026-07-27T04:39:53.748945Z","record_id":"1527757723d75bc5ed55a3b401a2bf8badc6f306539cc2cc1e669bf2bc5e7339","schema_fingerprint":"4aa3821a28b0b7c2400bc59aba4bcc0a76e971dadd19610d3ad38c768e124dc7","schema_version":"edge-lab-recorder.raw.v1","sequence":null,"source":"clob_market_ws"}
{"event_at":"2026-07-27T04:39:53.850000Z","event_fingerprint":"3d7110594a6d36864b380f057a259806b2a57bcf7e2d4c161ca97d8e1b237b66","payload":{"connection_id":"0f4979d6978d463e9660b042fdcf555f","event_at":"2026-07-27T04:39:53.850000Z","event_type":"price_change","frame_hash":"8ff354ad5d2475f1892a9c67a7b5a844c2b31320d7c1102bd8ce8c66d0e7eb05","frame_index":0,"kind":"data","monotonic_ns":229177066922083,"payload":{"event_type":"price_change","market":"0xeb66215f2e9faa6449e30a02bab5b8ed7b79a38bf961f6b24d0073c9c2419250","price_changes":[{"asset_id":"69697746896130839564035629862476347944307040470122503199396727085502753297492","best_ask":"0.67","best_bid":"0.66","hash":"a2a54f4e8d4c9d32cf4a26ff05d78eb79bc47d0d","price":"0.01","side":"BUY","size":"5643.02"},{"asset_id":"60386828328910021732068595344565885737045900010034836345809386672230885527307","best_ask":"0.34","best_bid":"0.33","hash":"ee3f04619bbaff694d98b63a5be83f5de21d8169","price":"0.99","side":"SELL","size":"5643.02"}],"timestamp":"1785127193850"},"payload_hash":"3038ff13cee92e27f609c03d410346e9e08a10b3596abe380f9da122178257ab","raw_frame":"{\"market\":\"0xeb66215f2e9faa6449e30a02bab5b8ed7b79a38bf961f6b24d0073c9c2419250\", \"price_changes\":[{\"asset_id\":\"69697746896130839564035629862476347944307040470122503199396727085502753297492\", \"price\":\"0.01\", \"size\":\"5643.02\", \"side\":\"BUY\", \"hash\":\"a2a54f4e8d4c9d32cf4a26ff05d78eb79bc47d0d\", \"best_bid\":\"0.66\", \"best_ask\":\"0.67\"}, {\"asset_id\":\"60386828328910021732068595344565885737045900010034836345809386672230885527307\", \"price\":\"0.99\", \"size\":\"5643.02\", \"side\":\"SELL\", \"hash\":\"ee3f04619bbaff694d98b63a5be83f5de21d8169\", \"best_bid\":\"0.33\", \"best_ask\":\"0.34\"}], \"timestamp\":\"1785127193850\", \"event_type\":\"price_change\"}","received_at":"2026-07-27T04:39:53.802234Z","schema_version":"clob-market-ws.price_change.v1","sequence":null,"server_hash":null,"server_timestamp":"1785127193850","session_id":"e9443c7415a0419799bee9cfbb1a9e4d","source":"clob_market_ws"},"received_at":"2026-07-27T04:39:53.802234Z","record_id":"8bb64bdf7d2bf71533618abe5efdc9b00c73be564d53ed1231bd21c8ce97e00d","schema_fingerprint":"4aa3821a28b0b7c2400bc59aba4bcc0a76e971dadd19610d3ad38c768e124dc7","schema_version":"edge-lab-recorder.raw.v1","sequence":null,"source":"clob_market_ws"}
{"event_at":"2026-07-27T04:39:53.854000Z","event_fingerprint":"3174148fcc9535ee67858e04c1b4d0a25ea6267a31ec3e74f0bb6898632c00a3","payload":{"connection_id":"0f4979d6978d463e9660b042fdcf555f","event_at":"2026-07-27T04:39:53.854000Z","event_type":"price_change","frame_hash":"87baac6a57eb95970cbf123b846d753ea3426aae72533b3840cca0b7d125aff2","frame_index":0,"kind":"data","monotonic_ns":229177070211291,"payload":{"event_type":"price_change","market":"0xeb66215f2e9faa6449e30a02bab5b8ed7b79a38bf961f6b24d0073c9c2419250","price_changes":[{"asset_id":"69697746896130839564035629862476347944307040470122503199396727085502753297492","best_ask":"0.67","best_bid":"0.66","hash":"407f1cfd739da63c177ea4c10d256fb0da6193c3","price":"0.6","side":"BUY","size":"7.92"},{"asset_id":"60386828328910021732068595344565885737045900010034836345809386672230885527307","best_ask":"0.34","best_bid":"0.33","hash":"0a5723638e5710510fc93023728ffadb9baa2daa","price":"0.4","side":"SELL","size":"7.92"}],"timestamp":"1785127193854"},"payload_hash":"8c4cdb225f187bd1fe6282ac1347b88bbc60d73ca13abd833149c9418dd21cc2","raw_frame":"{\"market\":\"0xeb66215f2e9faa6449e30a02bab5b8ed7b79a38bf961f6b24d0073c9c2419250\", \"price_changes\":[{\"asset_id\":\"69697746896130839564035629862476347944307040470122503199396727085502753297492\", \"price\":\"0.6\", \"size\":\"7.92\", \"side\":\"BUY\", \"hash\":\"407f1cfd739da63c177ea4c10d256fb0da6193c3\", \"best_bid\":\"0.66\", \"best_ask\":\"0.67\"}, {\"asset_id\":\"60386828328910021732068595344565885737045900010034836345809386672230885527307\", \"price\":\"0.4\", \"size\":\"7.92\", \"side\":\"SELL\", \"hash\":\"0a5723638e5710510fc93023728ffadb9baa2daa\", \"best_bid\":\"0.33\", \"best_ask\":\"0.34\"}], \"timestamp\":\"1785127193854\", \"event_type\":\"price_change\"}","received_at":"2026-07-27T04:39:53.805524Z","schema_version":"clob-market-ws.price_change.v1","sequence":null,"server_hash":null,"server_timestamp":"1785127193854","session_id":"e9443c7415a0419799bee9cfbb1a9e4d","source":"clob_market_ws"},"received_at":"2026-07-27T04:39:53.805524Z","record_id":"12ee2a910647a8a0f447ab941160ae2ded292a2626c3f756ea9d2d91f1df552e","schema_fingerprint":"4aa3821a28b0b7c2400bc59aba4bcc0a76e971dadd19610d3ad38c768e124dc7","schema_version":"edge-lab-recorder.raw.v1","sequence":null,"source":"clob_market_ws"}
{"event_at":"2026-07-27T04:39:53.860000Z","event_fingerprint":"cc26900f4c0130d19946012afa97cc5c16d4f5737fde18ed4b478c8d8390f117","payload":{"connection_id":"0f4979d6978d463e9660b042fdcf555f","event_at":"2026-07-27T04:39:53.860000Z","event_type":"price_change","frame_hash":"357fcc79652c80c2efb365e57a1adb7ab0eb680596f728b269ec377537edf985","frame_index":0,"kind":"data","monotonic_ns":229177073407791,"payload":{"event_type":"price_change","market":"0xeb66215f2e9faa6449e30a02bab5b8ed7b79a38bf961f6b24d0073c9c2419250","price_changes":[{"asset_id":"69697746896130839564035629862476347944307040470122503199396727085502753297492","best_ask":"0.67","best_bid":"0.66","hash":"89e1da5146431d8321ac2b28e04dc0712d41795c","price":"0.58","side":"BUY","size":"56.3"},{"asset_id":"60386828328910021732068595344565885737045900010034836345809386672230885527307","best_ask":"0.34","best_bid":"0.33","hash":"1c22809490b746fb29f4d05754cd2612dd597c06","price":"0.42","side":"SELL","size":"56.3"}],"timestamp":"1785127193860"},"payload_hash":"90f9737e741aa961ab7346f160965187ccd8fc2d346a02db7569f531e909f44d","raw_frame":"{\"market\":\"0xeb66215f2e9faa6449e30a02bab5b8ed7b79a38bf961f6b24d0073c9c2419250\", \"price_changes\":[{\"asset_id\":\"69697746896130839564035629862476347944307040470122503199396727085502753297492\", \"price\":\"0.58\", \"size\":\"56.3\", \"side\":\"BUY\", \"hash\":\"89e1da5146431d8321ac2b28e04dc0712d41795c\", \"best_bid\":\"0.66\", \"best_ask\":\"0.67\"}, {\"asset_id\":\"60386828328910021732068595344565885737045900010034836345809386672230885527307\", \"price\":\"0.42\", \"size\":\"56.3\", \"side\":\"SELL\", \"hash\":\"1c22809490b746fb29f4d05754cd2612dd597c06\", \"best_bid\":\"0.33\", \"best_ask\":\"0.34\"}], \"timestamp\":\"1785127193860\", \"event_type\":\"price_change\"}","received_at":"2026-07-27T04:39:53.808722Z","schema_version":"clob-market-ws.price_change.v1","sequence":null,"server_hash":null,"server_timestamp":"1785127193860","session_id":"e9443c7415a0419799bee9cfbb1a9e4d","source":"clob_market_ws"},"received_at":"2026-07-27T04:39:53.808722Z","record_id":"03e02aaaf042de4747e99b63bba01e29bfdea2c9f0e431da6e89e8fae44e1be7","schema_fingerprint":"4aa3821a28b0b7c2400bc59aba4bcc0a76e971dadd19610d3ad38c768e124dc7","schema_version":"edge-lab-recorder.raw.v1","sequence":null,"source":"clob_market_ws"}
{"event_at":"2026-07-27T04:39:53.864000Z","event_fingerprint":"0c99cecbf7527a7b8c1a85b4ab26ba2036aa8cd200002690406d5581ccad0b25","payload":{"connection_id":"0f4979d6978d463e9660b042fdcf555f","event_at":"2026-07-27T04:39:53.864000Z","event_type":"price_change","frame_hash":"2bf7cf83d4dc09d427778878b90bf921895815f64885fcdda18de506625bffb4","frame_index":0,"kind":"data","monotonic_ns":229177076450791,"payload":{"event_type":"price_change","market":"0xeb66215f2e9faa6449e30a02bab5b8ed7b79a38bf961f6b24d0073c9c2419250","price_changes":[{"asset_id":"60386828328910021732068595344565885737045900010034836345809386672230885527307","best_ask":"0.34","best_bid":"0.33","hash":"1133b712b0f59cd53ad4627c57c19fe772cbc664","price":"0.4","side":"SELL","size":"57.99"},{"asset_id":"69697746896130839564035629862476347944307040470122503199396727085502753297492","best_ask":"0.67","best_bid":"0.66","hash":"ba6f6e2a508500d6c0a863b02422c45082ffeb70","price":"0.6","side":"BUY","size":"57.99"}],"timestamp":"1785127193864"},"payload_hash":"8f60e707873a444f9f8f4ad490e9b2916e97f172b3e154927e73144dffaeea3e","raw_frame":"{\"market\":\"0xeb66215f2e9faa6449e30a02bab5b8ed7b79a38bf961f6b24d0073c9c2419250\", \"price_changes\":[{\"asset_id\":\"60386828328910021732068595344565885737045900010034836345809386672230885527307\", \"price\":\"0.4\", \"size\":\"57.99\", \"side\":\"SELL\", \"hash\":\"1133b712b0f59cd53ad4627c57c19fe772cbc664\", \"best_bid\":\"0.33\", \"best_ask\":\"0.34\"}, {\"asset_id\":\"69697746896130839564035629862476347944307040470122503199396727085502753297492\", \"price\":\"0.6\", \"size\":\"57.99\", \"side\":\"BUY\", \"hash\":\"ba6f6e2a508500d6c0a863b02422c45082ffeb70\", \"best_bid\":\"0.66\", \"best_ask\":\"0.67\"}], \"timestamp\":\"1785127193864\", \"event_type\":\"price_change\"}","received_at":"2026-07-27T04:39:53.811762Z","schema_version":"clob-market-ws.price_change.v1","sequence":null,"server_hash":null,"server_timestamp":"1785127193864","session_id":"e9443c7415a0419799bee9cfbb1a9e4d","source":"clob_market_ws"},"received_at":"2026-07-27T04:39:53.811762Z","record_id":"2a46b545100c9ac6f1f8c416b1060ab0aea186547699e5c8a573e9d6d2d09bbd","schema_fingerprint":"4aa3821a28b0b7c2400bc59aba4bcc0a76e971dadd19610d3ad38c768e124dc7","schema_version":"edge-lab-recorder.raw.v1","sequence":null,"source":"clob_market_ws"}
{"event_at":"2026-07-27T04:39:53.868000Z","event_fingerprint":"13d9e8254df08910844a6838c86b6152511809619b72ea8fd506f39d7bc8dc9c","payload":{"connection_id":"0f4979d6978d463e9660b042fdcf555f","event_at":"2026-07-27T04:39:53.868000Z","event_type":"price_change","frame_hash":"ef6e2aab2832382e35266a24c2289cc1a1be5cbff4ce97fed7c7974bfcd89dc8","frame_index":0,"kind":"data","monotonic_ns":229177078618416,"payload":{"event_type":"price_change","market":"0xeb66215f2e9faa6449e30a02bab5b8ed7b79a38bf961f6b24d0073c9c2419250","price_changes":[{"asset_id":"69697746896130839564035629862476347944307040470122503199396727085502753297492","best_ask":"0.67","best_bid":"0.66","hash":"b18c5685f71d2bf5347875f421a9ac5933dc42d3","price":"0.01","side":"BUY","size":"5638.02"},{"asset_id":"60386828328910021732068595344565885737045900010034836345809386672230885527307","best_ask":"0.34","best_bid":"0.33","hash":"0df45bc1182ec5bc09973b97b438268468bbdbf0","price":"0.99","side":"SELL","size":"5638.02"}],"timestamp":"1785127193868"},"payload_hash":"5bf61d8146cfb988faf86cadf3b6734938a2838ce025e3e355bcdbfc44331b96","raw_frame":"{\"market\":\"0xeb66215f2e9faa6449e30a02bab5b8ed7b79a38bf961f6b24d0073c9c2419250\", \"price_changes\":[{\"asset_id\":\"69697746896130839564035629862476347944307040470122503199396727085502753297492\", \"price\":\"0.01\", \"size\":\"5638.02\", \"side\":\"BUY\", \"hash\":\"b18c5685f71d2bf5347875f421a9ac5933dc42d3\", \"best_bid\":\"0.66\", \"best_ask\":\"0.67\"}, {\"asset_id\":\"60386828328910021732068595344565885737045900010034836345809386672230885527307\", \"price\":\"0.99\", \"size\":\"5638.02\", \"side\":\"SELL\", \"hash\":\"0df45bc1182ec5bc09973b97b438268468bbdbf0\", \"best_bid\":\"0.33\", \"best_ask\":\"0.34\"}], \"timestamp\":\"1785127193868\", \"event_type\":\"price_change\"}","received_at":"2026-07-27T04:39:53.813929Z","schema_version":"clob-market-ws.price_change.v1","sequence":null,"server_hash":null,"server_timestamp":"1785127193868","session_id":"e9443c7415a0419799bee9cfbb1a9e4d","source":"clob_market_ws"},"received_at":"2026-07-27T04:39:53.813929Z","record_id":"f5bf2ef3bea4256affb73ab4d2678f16508f8a44650df3902ce288a5214757c1","schema_fingerprint":"4aa3821a28b0b7c2400bc59aba4bcc0a76e971dadd19610d3ad38c768e124dc7","schema_version":"edge-lab-recorder.raw.v1","sequence":null,"source":"clob_market_ws"}
{"event_at":"2026-07-27T04:39:53.878000Z","event_fingerprint":"88627b9bb5508ccaff44c1fe813e928f0726cbe1cd56b8e56c21e15ef5edc342","payload":{"connection_id":"0f4979d6978d463e9660b042fdcf555f","event_at":"2026-07-27T04:39:53.878000Z","event_type":"price_change","frame_hash":"42e4fcf900dc06955882b1d4a75346e043eadcc66a24eb5b6d6bd20cd851a233","frame_index":0,"kind":"data","monotonic_ns":229177089151500,"payload":{"event_type":"price_change","market":"0xeb66215f2e9faa6449e30a02bab5b8ed7b79a38bf961f6b24d0073c9c2419250","price_changes":[{"asset_id":"69697746896130839564035629862476347944307040470122503199396727085502753297492","best_ask":"0.67","best_bid":"0.66","hash":"e1bd486ddc369c8c20ee01020ceec1d7e32e6c03","price":"0.01","side":"BUY","size":"5633.02"},{"asset_id":"60386828328910021732068595344565885737045900010034836345809386672230885527307","best_ask":"0.34","best_bid":"0.33","hash":"00e83031212c04db60a202cafb6db128cf33ff9d","price":"0.99","side":"SELL","size":"5633.02"}],"timestamp":"1785127193878"},"payload_hash":"886277ba3e967077653f7ef0659982b15762e4132010010d5b987cb597ef832a","raw_frame":"{\"market\":\"0xeb66215f2e9faa6449e30a02bab5b8ed7b79a38bf961f6b24d0073c9c2419250\", \"price_changes\":[{\"asset_id\":\"69697746896130839564035629862476347944307040470122503199396727085502753297492\", \"price\":\"0.01\", \"size\":\"5633.02\", \"side\":\"BUY\", \"hash\":\"e1bd486ddc369c8c20ee01020ceec1d7e32e6c03\", \"best_bid\":\"0.66\", \"best_ask\":\"0.67\"}, {\"asset_id\":\"60386828328910021732068595344565885737045900010034836345809386672230885527307\", \"price\":\"0.99\", \"size\":\"5633.02\", \"side\":\"SELL\", \"hash\":\"00e83031212c04db60a202cafb6db128cf33ff9d\", \"best_bid\":\"0.33\", \"best_ask\":\"0.34\"}], \"timestamp\":\"1785127193878\", \"event_type\":\"price_change\"}","received_at":"2026-07-27T04:39:53.824461Z","schema_version":"clob-market-ws.price_change.v1","sequence":null,"server_hash":null,"server_timestamp":"1785127193878","session_id":"e9443c7415a0419799bee9cfbb1a9e4d","source":"clob_market_ws"},"received_at":"2026-07-27T04:39:53.824461Z","record_id":"240d2c719f83fa134730dfcb49caca423480ef2b57842d22bb38b06a7f813cd6","schema_fingerprint":"4aa3821a28b0b7c2400bc59aba4bcc0a76e971dadd19610d3ad38c768e124dc7","schema_version":"edge-lab-recorder.raw.v1","sequence":null,"source":"clob_market_ws"}
{"event_at":"2026-07-27T04:39:53.915000Z","event_fingerprint":"b3df8b8b083daa05d86293c0a3b02ba65730042fd0f273aaab77b35521fe2b4d","payload":{"connection_id":"0f4979d6978d463e9660b042fdcf555f","event_at":"2026-07-27T04:39:53.915000Z","event_type":"price_change","frame_hash":"fd2428906b62a8d19d434612761b941abc22d9c29ecf744cffa0648344ba0fdc","frame_index":0,"kind":"data","monotonic_ns":229177127030041,"payload":{"event_type":"price_change","market":"0xeb66215f2e9faa6449e30a02bab5b8ed7b79a38bf961f6b24d0073c9c2419250","price_changes":[{"asset_id":"69697746896130839564035629862476347944307040470122503199396727085502753297492","best_ask":"0.67","best_bid":"0.66","hash":"740795bd503e15e5ccad55edd91428dc534343e9","price":"0.66","side":"BUY","size":"15"},{"asset_id":"60386828328910021732068595344565885737045900010034836345809386672230885527307","best_ask":"0.34","best_bid":"0.33","hash":"2729fa1ede6167fe80786ce9db1419191f98f26a","price":"0.34","side":"SELL","size":"15"}],"timestamp":"1785127193915"},"payload_hash":"5e576d795cd25e99b4a15c93a9698796c44f388a42f1f3303fa0e7a75143550e","raw_frame":"{\"market\":\"0xeb66215f2e9faa6449e30a02bab5b8ed7b79a38bf961f6b24d0073c9c2419250\", \"price_changes\":[{\"asset_id\":\"69697746896130839564035629862476347944307040470122503199396727085502753297492\", \"price\":\"0.66\", \"size\":\"15\", \"side\":\"BUY\", \"hash\":\"740795bd503e15e5ccad55edd91428dc534343e9\", \"best_bid\":\"0.66\", \"best_ask\":\"0.67\"}, {\"asset_id\":\"60386828328910021732068595344565885737045900010034836345809386672230885527307\", \"price\":\"0.34\", \"size\":\"15\", \"side\":\"SELL\", \"hash\":\"2729fa1ede6167fe80786ce9db1419191f98f26a\", \"best_bid\":\"0.33\", \"best_ask\":\"0.34\"}], \"timestamp\":\"1785127193915\", \"event_type\":\"price_change\"}","received_at":"2026-07-27T04:39:53.862338Z","schema_version":"clob-market-ws.price_change.v1","sequence":null,"server_hash":null,"server_timestamp":"1785127193915","session_id":"e9443c7415a0419799bee9cfbb1a9e4d","source":"clob_market_ws"},"received_at":"2026-07-27T04:39:53.862338Z","record_id":"2ef6557afe7221590c557cb163306a5668b3a7279add0d7fac4cbf6c6d9748c6","schema_fingerprint":"4aa3821a28b0b7c2400bc59aba4bcc0a76e971dadd19610d3ad38c768e124dc7","schema_version":"edge-lab-recorder.raw.v1","sequence":null,"source":"clob_market_ws"}
{"event_at":"2026-07-27T04:39:53.952000Z","event_fingerprint":"8a96f1b735c50f51ce1ac316cc3715851f9cb3cc22bb2b3e28468a1ce8c508d4","payload":{"connection_id":"0f4979d6978d463e9660b042fdcf555f","event_at":"2026-07-27T04:39:53.952000Z","event_type":"price_change","frame_hash":"489b58fea1a91c7ff94f58685bb78daa37c1548b74e58e4cc8b0cffd0919da9e","frame_index":0,"kind":"data","monotonic_ns":229177167404250,"payload":{"event_type":"price_change","market":"0xeb66215f2e9faa6449e30a02bab5b8ed7b79a38bf961f6b24d0073c9c2419250","price_changes":[{"asset_id":"60386828328910021732068595344565885737045900010034836345809386672230885527307","best_ask":"0.34","best_bid":"0.33","hash":"966a4e86e12bcd5237f8adc18be36d95756db7ea","price":"0.4","side":"SELL","size":"7.92"},{"asset_id":"69697746896130839564035629862476347944307040470122503199396727085502753297492","best_ask":"0.67","best_bid":"0.66","hash":"c59c7dba7fd51a5eef8841a287a729d52e77111d","price":"0.6","side":"BUY","size":"7.92"}],"timestamp":"1785127193952"},"payload_hash":"bf80d3396ce99660143dcadcf29c03de76f748eae598d38811eb1de2bdff16d1","raw_frame":"{\"market\":\"0xeb66215f2e9faa6449e30a02bab5b8ed7b79a38bf961f6b24d0073c9c2419250\", \"price_changes\":[{\"asset_id\":\"60386828328910021732068595344565885737045900010034836345809386672230885527307\", \"price\":\"0.4\", \"size\":\"7.92\", \"side\":\"SELL\", \"hash\":\"966a4e86e12bcd5237f8adc18be36d95756db7ea\", \"best_bid\":\"0.33\", \"best_ask\":\"0.34\"}, {\"asset_id\":\"69697746896130839564035629862476347944307040470122503199396727085502753297492\", \"price\":\"0.6\", \"size\":\"7.92\", \"side\":\"BUY\", \"hash\":\"c59c7dba7fd51a5eef8841a287a729d52e77111d\", \"best_bid\":\"0.66\", \"best_ask\":\"0.67\"}], \"timestamp\":\"1785127193952\", \"event_type\":\"price_change\"}","received_at":"2026-07-27T04:39:53.902716Z","schema_version":"clob-market-ws.price_change.v1","sequence":null,"server_hash":null,"server_timestamp":"1785127193952","session_id":"e9443c7415a0419799bee9cfbb1a9e4d","source":"clob_market_ws"},"received_at":"2026-07-27T04:39:53.902716Z","record_id":"392f304e3db57ad1338d2b494693f302618e03be6cf7c567de91dfafb09ceff8","schema_fingerprint":"4aa3821a28b0b7c2400bc59aba4bcc0a76e971dadd19610d3ad38c768e124dc7","schema_version":"edge-lab-recorder.raw.v1","sequence":null,"source":"clob_market_ws"}
{"event_at":"2026-07-27T04:39:53.958000Z","event_fingerprint":"0c201dba26a8bdfc2ed49d3f59634d8e8589f41516fb06d735859dd74355fbb4","payload":{"connection_id":"0f4979d6978d463e9660b042fdcf555f","event_at":"2026-07-27T04:39:53.958000Z","event_type":"price_change","frame_hash":"e6ee92ce052cff3925b127c20148c6d8c7a790f0280e082846a82a5ae625859b","frame_index":0,"kind":"data","monotonic_ns":229177171346291,"payload":{"event_type":"price_change","market":"0xeb66215f2e9faa6449e30a02bab5b8ed7b79a38bf961f6b24d0073c9c2419250","price_changes":[{"asset_id":"69697746896130839564035629862476347944307040470122503199396727085502753297492","best_ask":"0.67","best_bid":"0.66","hash":"40473e7b09cb48d9346a8fe7872ab5512a40c949","price":"0.58","side":"BUY","size":"47.3"},{"asset_id":"60386828328910021732068595344565885737045900010034836345809386672230885527307","best_ask":"0.34","best_bid":"0.33","hash":"74fed8980e799620b460f6af4cf4f9ddf0a6adac","price":"0.42","side":"SELL","size":"47.3"}],"timestamp":"1785127193958"},"payload_hash":"79347251b12e40b4aa27c285e34ba642b78d4b676964023adfbf0703e3be2cf3","raw_frame":"{\"market\":\"0xeb66215f2e9faa6449e30a02bab5b8ed7b79a38bf961f6b24d0073c9c2419250\", \"price_changes\":[{\"asset_id\":\"69697746896130839564035629862476347944307040470122503199396727085502753297492\", \"price\":\"0.58\", \"size\":\"47.3\", \"side\":\"BUY\", \"hash\":\"40473e7b09cb48d9346a8fe7872ab5512a40c949\", \"best_bid\":\"0.66\", \"best_ask\":\"0.67\"}, {\"asset_id\":\"60386828328910021732068595344565885737045900010034836345809386672230885527307\", \"price\":\"0.42\", \"size\":\"47.3\", \"side\":\"SELL\", \"hash\":\"74fed8980e799620b460f6af4cf4f9ddf0a6adac\", \"best_bid\":\"0.33\", \"best_ask\":\"0.34\"}], \"timestamp\":\"1785127193958\", \"event_type\":\"price_change\"}","received_at":"2026-07-27T04:39:53.906660Z","schema_version":"clob-market-ws.price_change.v1","sequence":null,"server_hash":null,"server_timestamp":"1785127193958","session_id":"e9443c7415a0419799bee9cfbb1a9e4d","source":"clob_market_ws"},"received_at":"2026-07-27T04:39:53.906660Z","record_id":"b49baa74f43432ca9f98df1553dd49c44ef5dd2d0dcf2ec059c52e5c5be1a9a5","schema_fingerprint":"4aa3821a28b0b7c2400bc59aba4bcc0a76e971dadd19610d3ad38c768e124dc7","schema_version":"edge-lab-recorder.raw.v1","sequence":null,"source":"clob_market_ws"}
{"event_at":"2026-07-27T04:39:53.959000Z","event_fingerprint":"ea017d488b38b1f9b9b57018df94c006d85eccb681b7cf3863187440e18072d0","payload":{"connection_id":"0f4979d6978d463e9660b042fdcf555f","event_at":"2026-07-27T04:39:53.959000Z","event_type":"price_change","frame_hash":"1fabf386981e58c24d3791b354b590305da7524b2c572aa46449c6f922257d59","frame_index":0,"kind":"data","monotonic_ns":229177172880416,"payload":{"event_type":"price_change","market":"0xeb66215f2e9faa6449e30a02bab5b8ed7b79a38bf961f6b24d0073c9c2419250","price_changes":[{"asset_id":"69697746896130839564035629862476347944307040470122503199396727085502753297492","best_ask":"0.67","best_bid":"0.66","hash":"d3faed93057b4cdced297d2d42ce730c802df386","price":"0.6","side":"BUY","size":"56.99"},{"asset_id":"60386828328910021732068595344565885737045900010034836345809386672230885527307","best_ask":"0.34","best_bid":"0.33","hash":"fc987765a5a9caa13a7673a8ae16660364d4d910","price":"0.4","side":"SELL","size":"56.99"}],"timestamp":"1785127193959"},"payload_hash":"48f3fa8d477ab792d351fdc003d3cfff2d406aabcca1bef7119bfa9826612cf4","raw_frame":"{\"market\":\"0xeb66215f2e9faa6449e30a02bab5b8ed7b79a38bf961f6b24d0073c9c2419250\", \"price_changes\":[{\"asset_id\":\"69697746896130839564035629862476347944307040470122503199396727085502753297492\", \"price\":\"0.6\", \"size\":\"56.99\", \"side\":\"BUY\", \"hash\":\"d3faed93057b4cdced297d2d42ce730c802df386\", \"best_bid\":\"0.66\", \"best_ask\":\"0.67\"}, {\"asset_id\":\"60386828328910021732068595344565885737045900010034836345809386672230885527307\", \"price\":\"0.4\", \"size\":\"56.99\", \"side\":\"SELL\", \"hash\":\"fc987765a5a9caa13a7673a8ae16660364d4d910\", \"best_bid\":\"0.33\", \"best_ask\":\"0.34\"}], \"timestamp\":\"1785127193959\", \"event_type\":\"price_change\"}","received_at":"2026-07-27T04:39:53.908193Z","schema_version":"clob-market-ws.price_change.v1","sequence":null,"server_hash":null,"server_timestamp":"1785127193959","session_id":"e9443c7415a0419799bee9cfbb1a9e4d","source":"clob_market_ws"},"received_at":"2026-07-27T04:39:53.908193Z","record_id":"9e6b31e5adb43a7101ec9de6326affe6cd354d0124efa2dcce590818659dbf40","schema_fingerprint":"4aa3821a28b0b7c2400bc59aba4bcc0a76e971dadd19610d3ad38c768e124dc7","schema_version":"edge-lab-recorder.raw.v1","sequence":null,"source":"clob_market_ws"}
{"event_at":"2026-07-27T04:39:53.981000Z","event_fingerprint":"811ef01dfee2819b47e640607773367e15f45bb156dbc95b9bce67e490780398","payload":{"connection_id":"0f4979d6978d463e9660b042fdcf555f","event_at":"2026-07-27T04:39:53.981000Z","event_type":"price_change","frame_hash":"e4be1e63e85860f149416746d221ec1b094869bc703182ffcb10fb1c459ed323","frame_index":0,"kind":"data","monotonic_ns":229177192786708,"payload":{"event_type":"price_change","market":"0xeb66215f2e9faa6449e30a02bab5b8ed7b79a38bf961f6b24d0073c9c2419250","price_changes":[{"asset_id":"69697746896130839564035629862476347944307040470122503199396727085502753297492","best_ask":"0.67","best_bid":"0.66","hash":"2d0dafbce968fa6dc8fe2695df6a7412860014e4","price":"0.03","side":"BUY","size":"618.1"},{"asset_id":"60386828328910021732068595344565885737045900010034836345809386672230885527307","best_ask":"0.34","best_bid":"0.33","hash":"cf16831b827a780237dac43ee4c0956fd614a244","price":"0.97","side":"SELL","size":"618.1"}],"timestamp":"1785127193981"},"payload_hash":"e36a1ad4fa406e86b5f3f46c1c1928e9c7e8a55e161ecab9d9c680afcffbd894","raw_frame":"{\"market\":\"0xeb66215f2e9faa6449e30a02bab5b8ed7b79a38bf961f6b24d0073c9c2419250\", \"price_changes\":[{\"asset_id\":\"69697746896130839564035629862476347944307040470122503199396727085502753297492\", \"price\":\"0.03\", \"size\":\"618.1\", \"side\":\"BUY\", \"hash\":\"2d0dafbce968fa6dc8fe2695df6a7412860014e4\", \"best_bid\":\"0.66\", \"best_ask\":\"0.67\"}, {\"asset_id\":\"60386828328910021732068595344565885737045900010034836345809386672230885527307\", \"price\":\"0.97\", \"size\":\"618.1\", \"side\":\"SELL\", \"hash\":\"cf16831b827a780237dac43ee4c0956fd614a244\", \"best_bid\":\"0.33\", \"best_ask\":\"0.34\"}], \"timestamp\":\"1785127193981\", \"event_type\":\"price_change\"}","received_at":"2026-07-27T04:39:53.928093Z","schema_version":"clob-market-ws.price_change.v1","sequence":null,"server_hash":null,"server_timestamp":"1785127193981","session_id":"e9443c7415a0419799bee9cfbb1a9e4d","source":"clob_market_ws"},"received_at":"2026-07-27T04:39:53.928093Z","record_id":"f5e505f91f4fbc2dbd24c2430d4a9833d6e6bbbedd7e15aedb340bb12c0ec534","schema_fingerprint":"4aa3821a28b0b7c2400bc59aba4bcc0a76e971dadd19610d3ad38c768e124dc7","schema_version":"edge-lab-recorder.raw.v1","sequence":null,"source":"clob_market_ws"}
{"event_at":"2026-07-27T04:39:54.010000Z","event_fingerprint":"a752f934940c591d4359f67f3de5077980a0df256f25814e564991d04370783c","payload":{"connection_id":"0f4979d6978d463e9660b042fdcf555f","event_at":"2026-07-27T04:39:54.010000Z","event_type":"price_change","frame_hash":"a0e51cc257e80e717fe11e60a7fe0c50bc99041873e2bb527979174b5d6afc0e","frame_index":0,"kind":"data","monotonic_ns":229177222445291,"payload":{"event_type":"price_change","market":"0xeb66215f2e9faa6449e30a02bab5b8ed7b79a38bf961f6b24d0073c9c2419250","price_changes":[{"asset_id":"69697746896130839564035629862476347944307040470122503199396727085502753297492","best_ask":"0.67","best_bid":"0.66","hash":"ba934778422d13e618fa3a4d2aac0039008200a9","price":"0.01","side":"BUY","size":"5638.02"},{"asset_id":"60386828328910021732068595344565885737045900010034836345809386672230885527307","best_ask":"0.34","best_bid":"0.33","hash":"3ca9b5bfc80cbbfed6fb922aaa2d2b6bffdcfe42","price":"0.99","side":"SELL","size":"5638.02"}],"timestamp":"1785127194010"},"payload_hash":"2ae1f85a2d9b85eb5c7a2f24745f6ef39813ec47902bdeb83256832653a7023e","raw_frame":"{\"market\":\"0xeb66215f2e9faa6449e30a02bab5b8ed7b79a38bf961f6b24d0073c9c2419250\", \"price_changes\":[{\"asset_id\":\"69697746896130839564035629862476347944307040470122503199396727085502753297492\", \"price\":\"0.01\", \"size\":\"5638.02\", \"side\":\"BUY\", \"hash\":\"ba934778422d13e618fa3a4d2aac0039008200a9\", \"best_bid\":\"0.66\", \"best_ask\":\"0.67\"}, {\"asset_id\":\"60386828328910021732068595344565885737045900010034836345809386672230885527307\", \"price\":\"0.99\", \"size\":\"5638.02\", \"side\":\"SELL\", \"hash\":\"3ca9b5bfc80cbbfed6fb922aaa2d2b6bffdcfe42\", \"best_bid\":\"0.33\", \"best_ask\":\"0.34\"}], \"timestamp\":\"1785127194010\", \"event_type\":\"price_change\"}","received_at":"2026-07-27T04:39:53.957758Z","schema_version":"clob-market-ws.price_change.v1","sequence":null,"server_hash":null,"server_timestamp":"1785127194010","session_id":"e9443c7415a0419799bee9cfbb1a9e4d","source":"clob_market_ws"},"received_at":"2026-07-27T04:39:53.957758Z","record_id":"3c0a0ac639c3a6673df481b28eadf93c9799e5c04290b3fe4b7933897639449d","schema_fingerprint":"4aa3821a28b0b7c2400bc59aba4bcc0a76e971dadd19610d3ad38c768e124dc7","schema_version":"edge-lab-recorder.raw.v1","sequence":null,"source":"clob_market_ws"}
{"event_at":"2026-07-27T04:39:54.011000Z","event_fingerprint":"93ebf2231662e747fcf9bd50958c62993f958079806d06085eeee1b684af595b","payload":{"connection_id":"0f4979d6978d463e9660b042fdcf555f","event_at":"2026-07-27T04:39:54.011000Z","event_type":"price_change","frame_hash":"f7c657cb300ecf392b8f82f4031323b3b76fd44d0400b8a622d8e80138c66b4e","frame_index":0,"kind":"data","monotonic_ns":229177224513333,"payload":{"event_type":"price_change","market":"0xeb66215f2e9faa6449e30a02bab5b8ed7b79a38bf961f6b24d0073c9c2419250","price_changes":[{"asset_id":"60386828328910021732068595344565885737045900010034836345809386672230885527307","best_ask":"0.34","best_bid":"0.33","hash":"a218a2e34feba51144427455d81d50df57129884","price":"0.3","side":"BUY","size":"59.14"},{"asset_id":"69697746896130839564035629862476347944307040470122503199396727085502753297492","best_ask":"0.67","best_bid":"0.66","hash":"5dfa0679b08f15b4690397fc35f59a8c236dd778","price":"0.7","side":"SELL","size":"59.14"}],"timestamp":"1785127194011"},"payload_hash":"84f35409bf1d880a5dcc4c155e2d84c45ae969dcc10da09def49498560cdf44f","raw_frame":"{\"market\":\"0xeb66215f2e9faa6449e30a02bab5b8ed7b79a38bf961f6b24d0073c9c2419250\", \"price_changes\":[{\"asset_id\":\"60386828328910021732068595344565885737045900010034836345809386672230885527307\", \"price\":\"0.3\", \"size\":\"59.14\", \"side\":\"BUY\", \"hash\":\"a218a2e34feba51144427455d81d50df57129884\", \"best_bid\":\"0.33\", \"best_ask\":\"0.34\"}, {\"asset_id\":\"69697746896130839564035629862476347944307040470122503199396727085502753297492\", \"price\":\"0.7\", \"size\":\"59.14\", \"side\":\"SELL\", \"hash\":\"5dfa0679b08f15b4690397fc35f59a8c236dd778\", \"best_bid\":\"0.66\", \"best_ask\":\"0.67\"}], \"timestamp\":\"1785127194011\", \"event_type\":\"price_change\"}","received_at":"2026-07-27T04:39:53.959826Z","schema_version":"clob-market-ws.price_change.v1","sequence":null,"server_hash":null,"server_timestamp":"1785127194011","session_id":"e9443c7415a0419799bee9cfbb1a9e4d","source":"clob_market_ws"},"received_at":"2026-07-27T04:39:53.959826Z","record_id":"3f8f36a3bd2b1f0b671ce7a5ddbb2b393d76f7a163c2a9be485afed7bf5a6a8e","schema_fingerprint":"4aa3821a28b0b7c2400bc59aba4bcc0a76e971dadd19610d3ad38c768e124dc7","schema_version":"edge-lab-recorder.raw.v1","sequence":null,"source":"clob_market_ws"}
{"event_at":"2026-07-27T04:39:54.011000Z","event_fingerprint":"6a98b9fc90164038d39513c1f9675c28767cef636f41540a4829b473da78a08f","payload":{"connection_id":"0f4979d6978d463e9660b042fdcf555f","event_at":"2026-07-27T04:39:54.011000Z","event_type":"price_change","frame_hash":"9d99c4ba4e8bc173b0789ab24b4b2ef6217ea0f0ade850cdd712e10b803f80a2","frame_index":0,"kind":"data","monotonic_ns":229177226185541,"payload":{"event_type":"price_change","market":"0xeb66215f2e9faa6449e30a02bab5b8ed7b79a38bf961f6b24d0073c9c2419250","price_changes":[{"asset_id":"60386828328910021732068595344565885737045900010034836345809386672230885527307","best_ask":"0.34","best_bid":"0.33","hash":"59b9623b20b12cb9587bcc1921843958e8974dfc","price":"0.28","side":"BUY","size":"34.56"},{"asset_id":"69697746896130839564035629862476347944307040470122503199396727085502753297492","best_ask":"0.67","best_bid":"0.66","hash":"6f32a9741dbf63ef3a29ed7ac1d29fa4ea46af81","price":"0.72","side":"SELL","size":"34.56"}],"timestamp":"1785127194011"},"payload_hash":"5a64065ce7c2cedba56c7e7ad16e647fd8f034adf5455999be18d646838019ba","raw_frame":"{\"market\":\"0xeb66215f2e9faa6449e30a02bab5b8ed7b79a38bf961f6b24d0073c9c2419250\", \"price_changes\":[{\"asset_id\":\"60386828328910021732068595344565885737045900010034836345809386672230885527307\", \"price\":\"0.28\", \"size\":\"34.56\", \"side\":\"BUY\", \"hash\":\"59b9623b20b12cb9587bcc1921843958e8974dfc\", \"best_bid\":\"0.33\", \"best_ask\":\"0.34\"}, {\"asset_id\":\"69697746896130839564035629862476347944307040470122503199396727085502753297492\", \"price\":\"0.72\", \"size\":\"34.56\", \"side\":\"SELL\", \"hash\":\"6f32a9741dbf63ef3a29ed7ac1d29fa4ea46af81\", \"best_bid\":\"0.66\", \"best_ask\":\"0.67\"}], \"timestamp\":\"1785127194011\", \"event_type\":\"price_change\"}","received_at":"2026-07-27T04:39:53.961500Z","schema_version":"clob-market-ws.price_change.v1","sequence":null,"server_hash":null,"server_timestamp":"1785127194011","session_id":"e9443c7415a0419799bee9cfbb1a9e4d","source":"clob_market_ws"},"received_at":"2026-07-27T04:39:53.961500Z","record_id":"8616bd9e0e4686e9dcc872b73a0e0c0c4e9e69cde77b729d5e14af2b716613ef","schema_fingerprint":"4aa3821a28b0b7c2400bc59aba4bcc0a76e971dadd19610d3ad38c768e124dc7","schema_version":"edge-lab-recorder.raw.v1","sequence":null,"source":"clob_market_ws"}
{"event_at":"2026-07-27T04:39:54.014000Z","event_fingerprint":"3be16bb49a5ff597e44bce6a55a40e478612db30c56fd7b3af1d09af12876755","payload":{"connection_id":"0f4979d6978d463e9660b042fdcf555f","event_at":"2026-07-27T04:39:54.014000Z","event_type":"price_change","frame_hash":"2771a6084bcc2ef8af3790ef9e9172ea5efbac2d027894ab5a12bd48364c695e","frame_index":0,"kind":"data","monotonic_ns":229177227857458,"payload":{"event_type":"price_change","market":"0xeb66215f2e9faa6449e30a02bab5b8ed7b79a38bf961f6b24d0073c9c2419250","price_changes":[{"asset_id":"60386828328910021732068595344565885737045900010034836345809386672230885527307","best_ask":"0.34","best_bid":"0.33","hash":"80f6d0adab4a62478a4e7847a388b9ff72bec56f","price":"0.26","side":"BUY","size":"112.56"},{"asset_id":"69697746896130839564035629862476347944307040470122503199396727085502753297492","best_ask":"0.67","best_bid":"0.66","hash":"c1d7732158862621aeb590168cf7b0cb8a05bea6","price":"0.74","side":"SELL","size":"112.56"}],"timestamp":"1785127194014"},"payload_hash":"2326d44f2eb966b9ae361efcd0dc85dc0d71ebe2e4fc0308435b184ce0322e19","raw_frame":"{\"market\":\"0xeb66215f2e9faa6449e30a02bab5b8ed7b79a38bf961f6b24d0073c9c2419250\", \"price_changes\":[{\"asset_id\":\"60386828328910021732068595344565885737045900010034836345809386672230885527307\", \"price\":\"0.26\", \"size\":\"112.56\", \"side\":\"BUY\", \"hash\":\"80f6d0adab4a62478a4e7847a388b9ff72bec56f\", \"best_bid\":\"0.33\", \"best_ask\":\"0.34\"}, {\"asset_id\":\"69697746896130839564035629862476347944307040470122503199396727085502753297492\", \"price\":\"0.74\", \"size\":\"112.56\", \"side\":\"SELL\", \"hash\":\"c1d7732158862621aeb590168cf7b0cb8a05bea6\", \"best_bid\":\"0.66\", \"best_ask\":\"0.67\"}], \"timestamp\":\"1785127194014\", \"event_type\":\"price_change\"}","received_at":"2026-07-27T04:39:53.963172Z","schema_version":"clob-market-ws.price_change.v1","sequence":null,"server_hash":null,"server_timestamp":"1785127194014","session_id":"e9443c7415a0419799bee9cfbb1a9e4d","source":"clob_market_ws"},"received_at":"2026-07-27T04:39:53.963172Z","record_id":"bfc78ef215875aaa444562b18374aadeaefbc7de1f14383741ddfecec56af51e","schema_fingerprint":"4aa3821a28b0b7c2400bc59aba4bcc0a76e971dadd19610d3ad38c768e124dc7","schema_version":"edge-lab-recorder.raw.v1","sequence":null,"source":"clob_market_ws"}
{"event_at":"2026-07-27T04:39:54.014000Z","event_fingerprint":"068c956ca3e3432353eabda0545736cccdf7395ff5ea62c3394cefaf633c952a","payload":{"connection_id":"0f4979d6978d463e9660b042fdcf555f","event_at":"2026-07-27T04:39:54.014000Z","event_type":"price_change","frame_hash":"f36ff27b2e62f799efc46f1923bf41fb139a7097b9fcbd2c7d0945c085da4f3d","frame_index":0,"kind":"data","monotonic_ns":229177229380500,"payload":{"event_type":"price_change","market":"0xeb66215f2e9faa6449e30a02bab5b8ed7b79a38bf961f6b24d0073c9c2419250","price_changes":[{"asset_id":"60386828328910021732068595344565885737045900010034836345809386672230885527307","best_ask":"0.34","best_bid":"0.33","hash":"b899a53c73a8511990ba118bedfc3f4987355dbc","price":"0.24","side":"BUY","size":"227"},{"asset_id":"69697746896130839564035629862476347944307040470122503199396727085502753297492","best_ask":"0.67","best_bid":"0.66","hash":"32d562ef767f61b6d25efe5857eaa63e4242841f","price":"0.76","side":"SELL","size":"227"}],"timestamp":"1785127194014"},"payload_hash":"d01768ef1173d012684fa7338454d9b1bd6d3489023881102dac178dd3d707ef","raw_frame":"{\"market\":\"0xeb66215f2e9faa6449e30a02bab5b8ed7b79a38bf961f6b24d0073c9c2419250\", \"price_changes\":[{\"asset_id\":\"60386828328910021732068595344565885737045900010034836345809386672230885527307\", \"price\":\"0.24\", \"size\":\"227\", \"side\":\"BUY\", \"hash\":\"b899a53c73a8511990ba118bedfc3f4987355dbc\", \"best_bid\":\"0.33\", \"best_ask\":\"0.34\"}, {\"asset_id\":\"69697746896130839564035629862476347944307040470122503199396727085502753297492\", \"price\":\"0.76\", \"size\":\"227\", \"side\":\"SELL\", \"hash\":\"32d562ef767f61b6d25efe5857eaa63e4242841f\", \"best_bid\":\"0.66\", \"best_ask\":\"0.67\"}], \"timestamp\":\"1785127194014\", \"event_type\":\"price_change\"}","received_at":"2026-07-27T04:39:53.964693Z","schema_version":"clob-market-ws.price_change.v1","sequence":null,"server_hash":null,"server_timestamp":"1785127194014","session_id":"e9443c7415a0419799bee9cfbb1a9e4d","source":"clob_market_ws"},"received_at":"2026-07-27T04:39:53.964693Z","record_id":"b0068b21bfcd04faef094729da3664b6df650b39bcab798210a7974492152d14","schema_fingerprint":"4aa3821a28b0b7c2400bc59aba4bcc0a76e971dadd19610d3ad38c768e124dc7","schema_version":"edge-lab-recorder.raw.v1","sequence":null,"source":"clob_market_ws"}
{"event_at":"2026-07-27T04:39:54.014000Z","event_fingerprint":"2546ff3db6c6954dbd65945e3696b26ea589083dc513cd47bea57e6773248622","payload":{"connection_id":"0f4979d6978d463e9660b042fdcf555f","event_at":"2026-07-27T04:39:54.014000Z","event_type":"price_change","frame_hash":"8e216710058a2c144766942d115d6a7a30a81319f2ac77440761bdc4163b7e2d","frame_index":0,"kind":"data","monotonic_ns":229177230993041,"payload":{"event_type":"price_change","market":"0xeb66215f2e9faa6449e30a02bab5b8ed7b79a38bf961f6b24d0073c9c2419250","price_changes":[{"asset_id":"60386828328910021732068595344565885737045900010034836345809386672230885527307","best_ask":"0.34","best_bid":"0.33","hash":"b07916a299ff9f0abebf1722ed8284d27de58cf8","price":"0.27","side":"BUY","size":"78.43"},{"asset_id":"69697746896130839564035629862476347944307040470122503199396727085502753297492","best_ask":"0.67","best_bid":"0.66","hash":"ee4eeba9e2a20d44365c270f9f90c60a8234c9c4","price":"0.73","side":"SELL","size":"78.43"}],"timestamp":"1785127194014"},"payload_hash":"13fc724c2cd4c7e43fd22d521faf89c64227bd7735e828414c752b67cac68723","raw_frame":"{\"market\":\"0xeb66215f2e9faa6449e30a02bab5b8ed7b79a38bf961f6b24d0073c9c2419250\", \"price_changes\":[{\"asset_id\":\"60386828328910021732068595344565885737045900010034836345809386672230885527307\", \"price\":\"0.27\", \"size\":\"78.43\", \"side\":\"BUY\", \"hash\":\"b07916a299ff9f0abebf1722ed8284d27de58cf8\", \"best_bid\":\"0.33\", \"best_ask\":\"0.34\"}, {\"asset_id\":\"69697746896130839564035629862476347944307040470122503199396727085502753297492\", \"price\":\"0.73\", \"size\":\"78.43\", \"side\":\"SELL\", \"hash\":\"ee4eeba9e2a20d44365c270f9f90c60a8234c9c4\", \"best_bid\":\"0.66\", \"best_ask\":\"0.67\"}], \"timestamp\":\"1785127194014\", \"event_type\":\"price_change\"}","received_at":"2026-07-27T04:39:53.966299Z","schema_version":"clob-market-ws.price_change.v1","sequence":null,"server_hash":null,"server_timestamp":"1785127194014","session_id":"e9443c7415a0419799bee9cfbb1a9e4d","source":"clob_market_ws"},"received_at":"2026-07-27T04:39:53.966299Z","record_id":"b49d0d1be5de1d00f1d335b0ada9da03d50c1399faabbec2727284015269e764","schema_fingerprint":"4aa3821a28b0b7c2400bc59aba4bcc0a76e971dadd19610d3ad38c768e124dc7","schema_version":"edge-lab-recorder.raw.v1","sequence":null,"source":"clob_market_ws"}
{"event_at":"2026-07-27T04:39:54.016000Z","event_fingerprint":"06b735eea8a3d8a56f56e97214bf3cf986c6e3c62c634e7697ae0d67af1ff35c","payload":{"connection_id":"0f4979d6978d463e9660b042fdcf555f","event_at":"2026-07-27T04:39:54.016000Z","event_type":"price_change","frame_hash":"e4cc02cd3f67d89ddf2bb16b12a97187fc969a87029cf8b2643e079e19d86e93","frame_index":0,"kind":"data","monotonic_ns":229177232608791,"payload":{"event_type":"price_change","market":"0xeb66215f2e9faa6449e30a02bab5b8ed7b79a38bf961f6b24d0073c9c2419250","price_changes":[{"asset_id":"60386828328910021732068595344565885737045900010034836345809386672230885527307","best_ask":"0.34","best_bid":"0.33","hash":"a1a1b454df5309727a81d4db23735872f4e2cdca","price":"0.25","side":"BUY","size":"215"},{"asset_id":"69697746896130839564035629862476347944307040470122503199396727085502753297492","best_ask":"0.67","best_bid":"0.66","hash":"315479a2643c8144090647e1cd697563c897ddcc","price":"0.75","side":"SELL","size":"215"}],"timestamp":"1785127194016"},"payload_hash":"e7756b84f511cfb34d1fec5d72fd2470a16ceb7219f987f13a16e6050f29663e","raw_frame":"{\"market\":\"0xeb66215f2e9faa6449e30a02bab5b8ed7b79a38bf961f6b24d0073c9c2419250\", \"price_changes\":[{\"asset_id\":\"60386828328910021732068595344565885737045900010034836345809386672230885527307\", \"price\":\"0.25\", \"size\":\"215\", \"side\":\"BUY\", \"hash\":\"a1a1b454df5309727a81d4db23735872f4e2cdca\", \"best_bid\":\"0.33\", \"best_ask\":\"0.34\"}, {\"asset_id\":\"69697746896130839564035629862476347944307040470122503199396727085502753297492\", \"price\":\"0.75\", \"size\":\"215\", \"side\":\"SELL\", \"hash\":\"315479a2643c8144090647e1cd697563c897ddcc\", \"best_bid\":\"0.66\", \"best_ask\":\"0.67\"}], \"timestamp\":\"1785127194016\", \"event_type\":\"price_change\"}","received_at":"2026-07-27T04:39:53.967923Z","schema_version":"clob-market-ws.price_change.v1","sequence":null,"server_hash":null,"server_timestamp":"1785127194016","session_id":"e9443c7415a0419799bee9cfbb1a9e4d","source":"clob_market_ws"},"received_at":"2026-07-27T04:39:53.967923Z","record_id":"0f4b2ce03376dddb63d6b5831163673446bc5841fe99254a850eb6d492102793","schema_fingerprint":"4aa3821a28b0b7c2400bc59aba4bcc0a76e971dadd19610d3ad38c768e124dc7","schema_version":"edge-lab-recorder.raw.v1","sequence":null,"source":"clob_market_ws"}
{"event_at":"2026-07-27T04:39:54.016000Z","event_fingerprint":"33bfb8d33df713f01c1ba30f866cf56d85ed8018c489da598ac792c0d745cd37","payload":{"connection_id":"0f4979d6978d463e9660b042fdcf555f","event_at":"2026-07-27T04:39:54.016000Z","event_type":"price_change","frame_hash":"ab2d046f4d958594d7f900d7a981c8f96ed0ac5421d79b54e40e5f9ace0bde3d","frame_index":0,"kind":"data","monotonic_ns":229177234315041,"payload":{"event_type":"price_change","market":"0xeb66215f2e9faa6449e30a02bab5b8ed7b79a38bf961f6b24d0073c9c2419250","price_changes":[{"asset_id":"60386828328910021732068595344565885737045900010034836345809386672230885527307","best_ask":"0.34","best_bid":"0.33","hash":"f076ea4c30e795b7366553f690dc05b7b0a16e4e","price":"0.23","side":"BUY","size":"107"},{"asset_id":"69697746896130839564035629862476347944307040470122503199396727085502753297492","best_ask":"0.67","best_bid":"0.66","hash":"b1d4311973d7eac2f0fee4b1a13769b84a8eb04d","price":"0.77","side":"SELL","size":"107"}],"timestamp":"1785127194016"},"payload_hash":"664d5f71b5bb3b21052ec7459bce8d30906c26ffec85815aeccbabbd52bf5a7e","raw_frame":"{\"market\":\"0xeb66215f2e9faa6449e30a02bab5b8ed7b79a38bf961f6b24d0073c9c2419250\", \"price_changes\":[{\"asset_id\":\"60386828328910021732068595344565885737045900010034836345809386672230885527307\", \"price\":\"0.23\", \"size\":\"107\", \"side\":\"BUY\", \"hash\":\"f076ea4c30e795b7366553f690dc05b7b0a16e4e\", \"best_bid\":\"0.33\", \"best_ask\":\"0.34\"}, {\"asset_id\":\"69697746896130839564035629862476347944307040470122503199396727085502753297492\", \"price\":\"0.77\", \"size\":\"107\", \"side\":\"SELL\", \"hash\":\"b1d4311973d7eac2f0fee4b1a13769b84a8eb04d\", \"best_bid\":\"0.66\", \"best_ask\":\"0.67\"}], \"timestamp\":\"1785127194016\", \"event_type\":\"price_change\"}","received_at":"2026-07-27T04:39:53.969629Z","schema_version":"clob-market-ws.price_change.v1","sequence":null,"server_hash":null,"server_timestamp":"1785127194016","session_id":"e9443c7415a0419799bee9cfbb1a9e4d","source":"clob_market_ws"},"received_at":"2026-07-27T04:39:53.969629Z","record_id":"60907f475ea8c2801a17c57efdf784025fc5a99e68fed30d9b028e1b6ec99291","schema_fingerprint":"4aa3821a28b0b7c2400bc59aba4bcc0a76e971dadd19610d3ad38c768e124dc7","schema_version":"edge-lab-recorder.raw.v1","sequence":null,"source":"clob_market_ws"}
{"event_at":"2026-07-27T04:39:54.017000Z","event_fingerprint":"aeebbfddc4dabe3a907a95c6e3df5f78cc187da8e1cdbce47b35c088d30a4a6f","payload":{"connection_id":"0f4979d6978d463e9660b042fdcf555f","event_at":"2026-07-27T04:39:54.017000Z","event_type":"price_change","frame_hash":"204265b5297b98f482db2f1d2e74a867425d92a9c26329a6450b4028730a1b23","frame_index":0,"kind":"data","monotonic_ns":229177236102791,"payload":{"event_type":"price_change","market":"0xeb66215f2e9faa6449e30a02bab5b8ed7b79a38bf961f6b24d0073c9c2419250","price_changes":[{"asset_id":"60386828328910021732068595344565885737045900010034836345809386672230885527307","best_ask":"0.34","best_bid":"0.33","hash":"3fffeb25c4e9fc5bec778ffaf92580b0dfa4fc58","price":"0.31","side":"BUY","size":"7"},{"asset_id":"69697746896130839564035629862476347944307040470122503199396727085502753297492","best_ask":"0.67","best_bid":"0.66","hash":"c2a42e938605eb857588c8bbfdca81e7198d18da","price":"0.69","side":"SELL","size":"7"}],"timestamp":"1785127194017"},"payload_hash":"9a4abeeea735d4a046614e5378c861169c99387bb3ec1c8e6991696cdc1af24e","raw_frame":"{\"market\":\"0xeb66215f2e9faa6449e30a02bab5b8ed7b79a38bf961f6b24d0073c9c2419250\", \"price_changes\":[{\"asset_id\":\"60386828328910021732068595344565885737045900010034836345809386672230885527307\", \"price\":\"0.31\", \"size\":\"7\", \"side\":\"BUY\", \"hash\":\"3fffeb25c4e9fc5bec778ffaf92580b0dfa4fc58\", \"best_bid\":\"0.33\", \"best_ask\":\"0.34\"}, {\"asset_id\":\"69697746896130839564035629862476347944307040470122503199396727085502753297492\", \"price\":\"0.69\", \"size\":\"7\", \"side\":\"SELL\", \"hash\":\"c2a42e938605eb857588c8bbfdca81e7198d18da\", \"best_bid\":\"0.66\", \"best_ask\":\"0.67\"}], \"timestamp\":\"1785127194017\", \"event_type\":\"price_change\"}","received_at":"2026-07-27T04:39:53.971415Z","schema_version":"clob-market-ws.price_change.v1","sequence":null,"server_hash":null,"server_timestamp":"1785127194017","session_id":"e9443c7415a0419799bee9cfbb1a9e4d","source":"clob_market_ws"},"received_at":"2026-07-27T04:39:53.971415Z","record_id":"1ce03c274a8c5f53c76995a2216cdac05300436dd0dbf5b50ad4a2e693af941e","schema_fingerprint":"4aa3821a28b0b7c2400bc59aba4bcc0a76e971dadd19610d3ad38c768e124dc7","schema_version":"edge-lab-recorder.raw.v1","sequence":null,"source":"clob_market_ws"}
{"event_at":"2026-07-27T04:39:54.022000Z","event_fingerprint":"bbf30fe836e341d12fee63d55ac40a3f13633ca5318b2e6e1882c5eee09f88fc","payload":{"connection_id":"0f4979d6978d463e9660b042fdcf555f","event_at":"2026-07-27T04:39:54.022000Z","event_type":"price_change","frame_hash":"130cd78f4052769d9e14e36348be7645a072e3faf7c448819a347bd975879e31","frame_index":0,"kind":"data","monotonic_ns":229177237655375,"payload":{"event_type":"price_change","market":"0xeb66215f2e9faa6449e30a02bab5b8ed7b79a38bf961f6b24d0073c9c2419250","price_changes":[{"asset_id":"60386828328910021732068595344565885737045900010034836345809386672230885527307","best_ask":"0.34","best_bid":"0.33","hash":"a271fc9e29202af86524e81813aeac9fe9bba908","price":"0.29","side":"BUY","size":"39.27"},{"asset_id":"69697746896130839564035629862476347944307040470122503199396727085502753297492","best_ask":"0.67","best_bid":"0.66","hash":"a0ba6f109cecfc1738eaf6e8b514c0225305a718","price":"0.71","side":"SELL","size":"39.27"}],"timestamp":"1785127194022"},"payload_hash":"037517590205778686201effe68559164e1c2c1fd6125d70c500cead98792595","raw_frame":"{\"market\":\"0xeb66215f2e9faa6449e30a02bab5b8ed7b79a38bf961f6b24d0073c9c2419250\", \"price_changes\":[{\"asset_id\":\"60386828328910021732068595344565885737045900010034836345809386672230885527307\", \"price\":\"0.29\", \"size\":\"39.27\", \"side\":\"BUY\", \"hash\":\"a271fc9e29202af86524e81813aeac9fe9bba908\", \"best_bid\":\"0.33\", \"best_ask\":\"0.34\"}, {\"asset_id\":\"69697746896130839564035629862476347944307040470122503199396727085502753297492\", \"price\":\"0.71\", \"size\":\"39.27\", \"side\":\"SELL\", \"hash\":\"a0ba6f109cecfc1738eaf6e8b514c0225305a718\", \"best_bid\":\"0.66\", \"best_ask\":\"0.67\"}], \"timestamp\":\"1785127194022\", \"event_type\":\"price_change\"}","received_at":"2026-07-27T04:39:53.972969Z","schema_version":"clob-market-ws.price_change.v1","sequence":null,"server_hash":null,"server_timestamp":"1785127194022","session_id":"e9443c7415a0419799bee9cfbb1a9e4d","source":"clob_market_ws"},"received_at":"2026-07-27T04:39:53.972969Z","record_id":"849a91c7b5dfe3ddc7bbe33b4a9f07a3a2c275dc218b552cfdcde0f40ff50e5d","schema_fingerprint":"4aa3821a28b0b7c2400bc59aba4bcc0a76e971dadd19610d3ad38c768e124dc7","schema_version":"edge-lab-recorder.raw.v1","sequence":null,"source":"clob_market_ws"}
{"event_at":"2026-07-27T04:39:54.030000Z","event_fingerprint":"cf6645868ae043f0db6401b268f832206c3347351a3351399d6b9e6f8b705fd2","payload":{"connection_id":"0f4979d6978d463e9660b042fdcf555f","event_at":"2026-07-27T04:39:54.030000Z","event_type":"price_change","frame_hash":"4d90d234860809cc907710efa8f9a5d5dd4e5b1e6b006d633950ab72bd94bbac","frame_index":0,"kind":"data","monotonic_ns":229177242470541,"payload":{"event_type":"price_change","market":"0xeb66215f2e9faa6449e30a02bab5b8ed7b79a38bf961f6b24d0073c9c2419250","price_changes":[{"asset_id":"60386828328910021732068595344565885737045900010034836345809386672230885527307","best_ask":"0.34","best_bid":"0.33","hash":"e070a399280dc9dea8d45a6e8a1b0ce42ee969ca","price":"0.01","side":"BUY","size":"5598.02"},{"asset_id":"69697746896130839564035629862476347944307040470122503199396727085502753297492","best_ask":"0.67","best_bid":"0.66","hash":"42d4df7d46835a0c157900696ff61d1d5f5dd2dc","price":"0.99","side":"SELL","size":"5598.02"}],"timestamp":"1785127194030"},"payload_hash":"b7ea50bf41d5d80784f770ce8e900b86cd44f99f94dafc68587636819159c464","raw_frame":"{\"market\":\"0xeb66215f2e9faa6449e30a02bab5b8ed7b79a38bf961f6b24d0073c9c2419250\", \"price_changes\":[{\"asset_id\":\"60386828328910021732068595344565885737045900010034836345809386672230885527307\", \"price\":\"0.01\", \"size\":\"5598.02\", \"side\":\"BUY\", \"hash\":\"e070a399280dc9dea8d45a6e8a1b0ce42ee969ca\", \"best_bid\":\"0.33\", \"best_ask\":\"0.34\"}, {\"asset_id\":\"69697746896130839564035629862476347944307040470122503199396727085502753297492\", \"price\":\"0.99\", \"size\":\"5598.02\", \"side\":\"SELL\", \"hash\":\"42d4df7d46835a0c157900696ff61d1d5f5dd2dc\", \"best_bid\":\"0.66\", \"best_ask\":\"0.67\"}], \"timestamp\":\"1785127194030\", \"event_type\":\"price_change\"}","received_at":"2026-07-27T04:39:53.977785Z","schema_version":"clob-market-ws.price_change.v1","sequence":null,"server_hash":null,"server_timestamp":"1785127194030","session_id":"e9443c7415a0419799bee9cfbb1a9e4d","source":"clob_market_ws"},"received_at":"2026-07-27T04:39:53.977785Z","record_id":"eb275069392a47afa476ba8f39f446ac92020e311eee2c349dd357bcaf8baa29","schema_fingerprint":"4aa3821a28b0b7c2400bc59aba4bcc0a76e971dadd19610d3ad38c768e124dc7","schema_version":"edge-lab-recorder.raw.v1","sequence":null,"source":"clob_market_ws"}
{"event_at":"2026-07-27T04:39:54.035000Z","event_fingerprint":"3b1f163f0d0300a7f32147c69374eb3729b1932e86f071652814f01b1ec13114","payload":{"connection_id":"0f4979d6978d463e9660b042fdcf555f","event_at":"2026-07-27T04:39:54.035000Z","event_type":"price_change","frame_hash":"bd0f69284e6ce96d67739d666f2b1a632125a15b8dfe58bfbb774aff5f061e74","frame_index":0,"kind":"data","monotonic_ns":229177247897166,"payload":{"event_type":"price_change","market":"0xeb66215f2e9faa6449e30a02bab5b8ed7b79a38bf961f6b24d0073c9c2419250","price_changes":[{"asset_id":"69697746896130839564035629862476347944307040470122503199396727085502753297492","best_ask":"0.67","best_bid":"0.66","hash":"2af8539db27621a9312dfd6000ddda4ab38025c0","price":"0.01","side":"BUY","size":"5633.02"},{"asset_id":"60386828328910021732068595344565885737045900010034836345809386672230885527307","best_ask":"0.34","best_bid":"0.33","hash":"ea1a47e6c534f2c7363a1e8e204b41feb5a90df9","price":"0.99","side":"SELL","size":"5633.02"}],"timestamp":"1785127194035"},"payload_hash":"f56d84174acf18b46d1c50551496f2c60ef97c45b43acec8affdd331d3271abe","raw_frame":"{\"market\":\"0xeb66215f2e9faa6449e30a02bab5b8ed7b79a38bf961f6b24d0073c9c2419250\", \"price_changes\":[{\"asset_id\":\"69697746896130839564035629862476347944307040470122503199396727085502753297492\", \"price\":\"0.01\", \"size\":\"5633.02\", \"side\":\"BUY\", \"hash\":\"2af8539db27621a9312dfd6000ddda4ab38025c0\", \"best_bid\":\"0.66\", \"best_ask\":\"0.67\"}, {\"asset_id\":\"60386828328910021732068595344565885737045900010034836345809386672230885527307\", \"price\":\"0.99\", \"size\":\"5633.02\", \"side\":\"SELL\", \"hash\":\"ea1a47e6c534f2c7363a1e8e204b41feb5a90df9\", \"best_bid\":\"0.33\", \"best_ask\":\"0.34\"}], \"timestamp\":\"1785127194035\", \"event_type\":\"price_change\"}","received_at":"2026-07-27T04:39:53.983208Z","schema_version":"clob-market-ws.price_change.v1","sequence":null,"server_hash":null,"server_timestamp":"1785127194035","session_id":"e9443c7415a0419799bee9cfbb1a9e4d","source":"clob_market_ws"},"received_at":"2026-07-27T04:39:53.983208Z","record_id":"501740aeef4d6a9f42264f24fa7474e91b651ae101f0fbf80d9b728592de52fb","schema_fingerprint":"4aa3821a28b0b7c2400bc59aba4bcc0a76e971dadd19610d3ad38c768e124dc7","schema_version":"edge-lab-recorder.raw.v1","sequence":null,"source":"clob_market_ws"}
{"event_at":"2026-07-27T04:39:54.036000Z","event_fingerprint":"a821af2e5cfb26325ca80c434dc899daae2f4bd6e3355434dfa5b67f66aa1e34","payload":{"connection_id":"0f4979d6978d463e9660b042fdcf555f","event_at":"2026-07-27T04:39:54.036000Z","event_type":"price_change","frame_hash":"b74bdd6c822a597095086905f66f828ebb8d54be607b44af78e5e12113696cf5","frame_index":0,"kind":"data","monotonic_ns":229177249585041,"payload":{"event_type":"price_change","market":"0xeb66215f2e9faa6449e30a02bab5b8ed7b79a38bf961f6b24d0073c9c2419250","price_changes":[{"asset_id":"69697746896130839564035629862476347944307040470122503199396727085502753297492","best_ask":"0.67","best_bid":"0.66","hash":"15b2d8d40ce67b4974a9f9472afede590d7db3a5","price":"0.59","side":"BUY","size":"10"},{"asset_id":"60386828328910021732068595344565885737045900010034836345809386672230885527307","best_ask":"0.34","best_bid":"0.33","hash":"0aba771da41753a2b42d03e78b9536697487b366","price":"0.41","side":"SELL","size":"10"}],"timestamp":"1785127194036"},"payload_hash":"da10767ea52d6d0025f56dc112a9d9fd7566b03ad2c3ac674f16b2f01d69839b","raw_frame":"{\"market\":\"0xeb66215f2e9faa6449e30a02bab5b8ed7b79a38bf961f6b24d0073c9c2419250\", \"price_changes\":[{\"asset_id\":\"69697746896130839564035629862476347944307040470122503199396727085502753297492\", \"price\":\"0.59\", \"size\":\"10\", \"side\":\"BUY\", \"hash\":\"15b2d8d40ce67b4974a9f9472afede590d7db3a5\", \"best_bid\":\"0.66\", \"best_ask\":\"0.67\"}, {\"asset_id\":\"60386828328910021732068595344565885737045900010034836345809386672230885527307\", \"price\":\"0.41\", \"size\":\"10\", \"side\":\"SELL\", \"hash\":\"0aba771da41753a2b42d03e78b9536697487b366\", \"best_bid\":\"0.33\", \"best_ask\":\"0.34\"}], \"timestamp\":\"1785127194036\", \"event_type\":\"price_change\"}","received_at":"2026-07-27T04:39:53.984899Z","schema_version":"clob-market-ws.price_change.v1","sequence":null,"server_hash":null,"server_timestamp":"1785127194036","session_id":"e9443c7415a0419799bee9cfbb1a9e4d","source":"clob_market_ws"},"received_at":"2026-07-27T04:39:53.984899Z","record_id":"d45e71159cfd20112eb9fcd696b6b6466ccbef507b4604ed5fdda3e133adb01a","schema_fingerprint":"4aa3821a28b0b7c2400bc59aba4bcc0a76e971dadd19610d3ad38c768e124dc7","schema_version":"edge-lab-recorder.raw.v1","sequence":null,"source":"clob_market_ws"}
{"event_at":"2026-07-27T04:39:54.036000Z","event_fingerprint":"c41df810d021fcf649fb74c81b606b49b03524c92930254e0d1759496cfad0e7","payload":{"connection_id":"0f4979d6978d463e9660b042fdcf555f","event_at":"2026-07-27T04:39:54.036000Z","event_type":"price_change","frame_hash":"0031753b78a3bbe68ff13a4cc44348225e3099e738822267c0005feaf99469ad","frame_index":0,"kind":"data","monotonic_ns":229177251153208,"payload":{"event_type":"price_change","market":"0xeb66215f2e9faa6449e30a02bab5b8ed7b79a38bf961f6b24d0073c9c2419250","price_changes":[{"asset_id":"60386828328910021732068595344565885737045900010034836345809386672230885527307","best_ask":"0.34","best_bid":"0.33","hash":"8484305c53e68e8bdc4707863f80af6f9ceb8ada","price":"0.01","side":"BUY","size":"5603.02"},{"asset_id":"69697746896130839564035629862476347944307040470122503199396727085502753297492","best_ask":"0.67","best_bid":"0.66","hash":"c6019008203b136359dcf22f5b5f996cf290b230","price":"0.99","side":"SELL","size":"5603.02"}],"timestamp":"1785127194036"},"payload_hash":"867efcb8ee021bb638d3770c122a2318c847afa42ae4d8e65e0a557bccf90cb6","raw_frame":"{\"market\":\"0xeb66215f2e9faa6449e30a02bab5b8ed7b79a38bf961f6b24d0073c9c2419250\", \"price_changes\":[{\"asset_id\":\"60386828328910021732068595344565885737045900010034836345809386672230885527307\", \"price\":\"0.01\", \"size\":\"5603.02\", \"side\":\"BUY\", \"hash\":\"8484305c53e68e8bdc4707863f80af6f9ceb8ada\", \"best_bid\":\"0.33\", \"best_ask\":\"0.34\"}, {\"asset_id\":\"69697746896130839564035629862476347944307040470122503199396727085502753297492\", \"price\":\"0.99\", \"size\":\"5603.02\", \"side\":\"SELL\", \"hash\":\"c6019008203b136359dcf22f5b5f996cf290b230\", \"best_bid\":\"0.66\", \"best_ask\":\"0.67\"}], \"timestamp\":\"1785127194036\", \"event_type\":\"price_change\"}","received_at":"2026-07-27T04:39:53.986467Z","schema_version":"clob-market-ws.price_change.v1","sequence":null,"server_hash":null,"server_timestamp":"1785127194036","session_id":"e9443c7415a0419799bee9cfbb1a9e4d","source":"clob_market_ws"},"received_at":"2026-07-27T04:39:53.986467Z","record_id":"39ea0032d114d9f208e2db6097a352a6cdcdb42181a77eaf9db0255c513a79b1","schema_fingerprint":"4aa3821a28b0b7c2400bc59aba4bcc0a76e971dadd19610d3ad38c768e124dc7","schema_version":"edge-lab-recorder.raw.v1","sequence":null,"source":"clob_market_ws"}
{"event_at":"2026-07-27T04:39:54.039000Z","event_fingerprint":"75e944468a363dfdcac0cfd83dc0d88cd28e032506461b2623dc48349d73dd09","payload":{"connection_id":"0f4979d6978d463e9660b042fdcf555f","event_at":"2026-07-27T04:39:54.039000Z","event_type":"price_change","frame_hash":"1a47beb78f67144362a22f1647045f15c529aa85fd4fd60326f1172f14412fee","frame_index":0,"kind":"data","monotonic_ns":229177253282083,"payload":{"event_type":"price_change","market":"0xeb66215f2e9faa6449e30a02bab5b8ed7b79a38bf961f6b24d0073c9c2419250","price_changes":[{"asset_id":"69697746896130839564035629862476347944307040470122503199396727085502753297492","best_ask":"0.67","best_bid":"0.66","hash":"f9d9d88fb19377568ef5dfc0a62c45477eabb8de","price":"0.03","side":"BUY","size":"613.1"},{"asset_id":"60386828328910021732068595344565885737045900010034836345809386672230885527307","best_ask":"0.34","best_bid":"0.33","hash":"bb5029e1eaf0c0f3bb2d8dd9b0bdc8b2b832cd64","price":"0.97","side":"SELL","size":"613.1"}],"timestamp":"1785127194039"},"payload_hash":"e9747964ded76a6879c677cca60bec65e2f3f700783168cd53adebb0b2e4651f","raw_frame":"{\"market\":\"0xeb66215f2e9faa6449e30a02bab5b8ed7b79a38bf961f6b24d0073c9c2419250\", \"price_changes\":[{\"asset_id\":\"69697746896130839564035629862476347944307040470122503199396727085502753297492\", \"price\":\"0.03\", \"size\":\"613.1\", \"side\":\"BUY\", \"hash\":\"f9d9d88fb19377568ef5dfc0a62c45477eabb8de\", \"best_bid\":\"0.66\", \"best_ask\":\"0.67\"}, {\"asset_id\":\"60386828328910021732068595344565885737045900010034836345809386672230885527307\", \"price\":\"0.97\", \"size\":\"613.1\", \"side\":\"SELL\", \"hash\":\"bb5029e1eaf0c0f3bb2d8dd9b0bdc8b2b832cd64\", \"best_bid\":\"0.33\", \"best_ask\":\"0.34\"}], \"timestamp\":\"1785127194039\", \"event_type\":\"price_change\"}","received_at":"2026-07-27T04:39:53.988598Z","schema_version":"clob-market-ws.price_change.v1","sequence":null,"server_hash":null,"server_timestamp":"1785127194039","session_id":"e9443c7415a0419799bee9cfbb1a9e4d","source":"clob_market_ws"},"received_at":"2026-07-27T04:39:53.988598Z","record_id":"bac6d8b961a64e8e2405e41bcbefddc4cec84c347de7be9c0ef234ca24a1c3e9","schema_fingerprint":"4aa3821a28b0b7c2400bc59aba4bcc0a76e971dadd19610d3ad38c768e124dc7","schema_version":"edge-lab-recorder.raw.v1","sequence":null,"source":"clob_market_ws"}
{"event_at":"2026-07-27T04:39:54.041000Z","event_fingerprint":"2630e8db0e8bfd796fc878dd7722b27d5e98bc11f17a227703b43da938fdbc8c","payload":{"connection_id":"0f4979d6978d463e9660b042fdcf555f","event_at":"2026-07-27T04:39:54.041000Z","event_type":"price_change","frame_hash":"c081e6d422098ab220305501fc9d36ef2197ffd73b522b1818acea8af0c1eddd","frame_index":0,"kind":"data","monotonic_ns":229177254361291,"payload":{"event_type":"price_change","market":"0xeb66215f2e9faa6449e30a02bab5b8ed7b79a38bf961f6b24d0073c9c2419250","price_changes":[{"asset_id":"60386828328910021732068595344565885737045900010034836345809386672230885527307","best_ask":"0.34","best_bid":"0.33","hash":"9eda40a1f1c00e6246cea08267de49bf07c8645f","price":"0.32","side":"BUY","size":"279.6"},{"asset_id":"69697746896130839564035629862476347944307040470122503199396727085502753297492","best_ask":"0.67","best_bid":"0.66","hash":"339c603a8edc45c3a09c18860de68f24205eb1f0","price":"0.68","side":"SELL","size":"279.6"}],"timestamp":"1785127194041"},"payload_hash":"1a6134f226f146fba0288b69a8c6ca3863ee459f819007353ca7ee809fdfd920","raw_frame":"{\"market\":\"0xeb66215f2e9faa6449e30a02bab5b8ed7b79a38bf961f6b24d0073c9c2419250\", \"price_changes\":[{\"asset_id\":\"60386828328910021732068595344565885737045900010034836345809386672230885527307\", \"price\":\"0.32\", \"size\":\"279.6\", \"side\":\"BUY\", \"hash\":\"9eda40a1f1c00e6246cea08267de49bf07c8645f\", \"best_bid\":\"0.33\", \"best_ask\":\"0.34\"}, {\"asset_id\":\"69697746896130839564035629862476347944307040470122503199396727085502753297492\", \"price\":\"0.68\", \"size\":\"279.6\", \"side\":\"SELL\", \"hash\":\"339c603a8edc45c3a09c18860de68f24205eb1f0\", \"best_bid\":\"0.66\", \"best_ask\":\"0.67\"}], \"timestamp\":\"1785127194041\", \"event_type\":\"price_change\"}","received_at":"2026-07-27T04:39:53.989675Z","schema_version":"clob-market-ws.price_change.v1","sequence":null,"server_hash":null,"server_timestamp":"1785127194041","session_id":"e9443c7415a0419799bee9cfbb1a9e4d","source":"clob_market_ws"},"received_at":"2026-07-27T04:39:53.989675Z","record_id":"f79af2b4d8782257a1bfcdf86b6f58bbf11e78f11ee44ce3b369f82b86a2be87","schema_fingerprint":"4aa3821a28b0b7c2400bc59aba4bcc0a76e971dadd19610d3ad38c768e124dc7","schema_version":"edge-lab-recorder.raw.v1","sequence":null,"source":"clob_market_ws"}
{"event_at":"2026-07-27T04:39:54.043000Z","event_fingerprint":"68c161d93c3b6848b9a05df953365b2541e16c479e299f203efe7b6cc6f48c23","payload":{"connection_id":"0f4979d6978d463e9660b042fdcf555f","event_at":"2026-07-27T04:39:54.043000Z","event_type":"price_change","frame_hash":"218924226421563205f10b0c7620a19ec8e515127c1241f5712d9c436c3723c8","frame_index":0,"kind":"data","monotonic_ns":229177259262500,"payload":{"event_type":"price_change","market":"0xeb66215f2e9faa6449e30a02bab5b8ed7b79a38bf961f6b24d0073c9c2419250","price_changes":[{"asset_id":"60386828328910021732068595344565885737045900010034836345809386672230885527307","best_ask":"0.34","best_bid":"0.33","hash":"bbf5ee0fe8b22f483b45719af6e91398742b31f9","price":"0.33","side":"BUY","size":"151"},{"asset_id":"69697746896130839564035629862476347944307040470122503199396727085502753297492","best_ask":"0.67","best_bid":"0.66","hash":"a59ae4dc1fc5bc98c7b000b848ea0a353731a030","price":"0.67","side":"SELL","size":"151"}],"timestamp":"1785127194043"},"payload_hash":"73a1de3dd5bf00fbd2f9ca374875d56bb54cd1c3c7789f2fc983758ed532b157","raw_frame":"{\"market\":\"0xeb66215f2e9faa6449e30a02bab5b8ed7b79a38bf961f6b24d0073c9c2419250\", \"price_changes\":[{\"asset_id\":\"60386828328910021732068595344565885737045900010034836345809386672230885527307\", \"price\":\"0.33\", \"size\":\"151\", \"side\":\"BUY\", \"hash\":\"bbf5ee0fe8b22f483b45719af6e91398742b31f9\", \"best_bid\":\"0.33\", \"best_ask\":\"0.34\"}, {\"asset_id\":\"69697746896130839564035629862476347944307040470122503199396727085502753297492\", \"price\":\"0.67\", \"size\":\"151\", \"side\":\"SELL\", \"hash\":\"a59ae4dc1fc5bc98c7b000b848ea0a353731a030\", \"best_bid\":\"0.66\", \"best_ask\":\"0.67\"}], \"timestamp\":\"1785127194043\", \"event_type\":\"price_change\"}","received_at":"2026-07-27T04:39:53.994575Z","schema_version":"clob-market-ws.price_change.v1","sequence":null,"server_hash":null,"server_timestamp":"1785127194043","session_id":"e9443c7415a0419799bee9cfbb1a9e4d","source":"clob_market_ws"},"received_at":"2026-07-27T04:39:53.994575Z","record_id":"0b5a3c093c8c64f554384f9d5234c6f67023fad8444f42960b1d1bd4a247e863","schema_fingerprint":"4aa3821a28b0b7c2400bc59aba4bcc0a76e971dadd19610d3ad38c768e124dc7","schema_version":"edge-lab-recorder.raw.v1","sequence":null,"source":"clob_market_ws"}
{"event_at":"2026-07-27T04:39:54.060000Z","event_fingerprint":"5464462ced48816d57a0f9419f934830e963be71a5e864eaa30e5bc5599a008c","payload":{"connection_id":"0f4979d6978d463e9660b042fdcf555f","event_at":"2026-07-27T04:39:54.060000Z","event_type":"price_change","frame_hash":"fe094bc48f8f2b911884ebdb3e2ff613c9238b19438c5cf5d8b66210bda517b0","frame_index":0,"kind":"data","monotonic_ns":229177272558750,"payload":{"event_type":"price_change","market":"0xeb66215f2e9faa6449e30a02bab5b8ed7b79a38bf961f6b24d0073c9c2419250","price_changes":[{"asset_id":"60386828328910021732068595344565885737045900010034836345809386672230885527307","best_ask":"0.34","best_bid":"0.33","hash":"751b802a05bf34951c6c46a4096f5b81c4110722","price":"0.01","side":"BUY","size":"5598.02"},{"asset_id":"69697746896130839564035629862476347944307040470122503199396727085502753297492","best_ask":"0.67","best_bid":"0.66","hash":"00e99b18d23f40f01ac13e1eeebe3ddcf10425d5","price":"0.99","side":"SELL","size":"5598.02"}],"timestamp":"1785127194060"},"payload_hash":"dc25fdbfdffb665f031bb718272d8f152e4bed9cbf7f07b918e8e116960d483c","raw_frame":"{\"market\":\"0xeb66215f2e9faa6449e30a02bab5b8ed7b79a38bf961f6b24d0073c9c2419250\", \"price_changes\":[{\"asset_id\":\"60386828328910021732068595344565885737045900010034836345809386672230885527307\", \"price\":\"0.01\", \"size\":\"5598.02\", \"side\":\"BUY\", \"hash\":\"751b802a05bf34951c6c46a4096f5b81c4110722\", \"best_bid\":\"0.33\", \"best_ask\":\"0.34\"}, {\"asset_id\":\"69697746896130839564035629862476347944307040470122503199396727085502753297492\", \"price\":\"0.99\", \"size\":\"5598.02\", \"side\":\"SELL\", \"hash\":\"00e99b18d23f40f01ac13e1eeebe3ddcf10425d5\", \"best_bid\":\"0.66\", \"best_ask\":\"0.67\"}], \"timestamp\":\"1785127194060\", \"event_type\":\"price_change\"}","received_at":"2026-07-27T04:39:54.007873Z","schema_version":"clob-market-ws.price_change.v1","sequence":null,"server_hash":null,"server_timestamp":"1785127194060","session_id":"e9443c7415a0419799bee9cfbb1a9e4d","source":"clob_market_ws"},"received_at":"2026-07-27T04:39:54.007873Z","record_id":"559b53acb4d5fb4c847e2fdf4cb539b8d91b0cd6b017fd89797994748f704502","schema_fingerprint":"4aa3821a28b0b7c2400bc59aba4bcc0a76e971dadd19610d3ad38c768e124dc7","schema_version":"edge-lab-recorder.raw.v1","sequence":null,"source":"clob_market_ws"}
{"event_at":"2026-07-27T04:39:54.064000Z","event_fingerprint":"dab3ef1234dbeb2f45f76b346438b0b57869b53a7caa49bf7b17b82fc9c6859e","payload":{"connection_id":"0f4979d6978d463e9660b042fdcf555f","event_at":"2026-07-27T04:39:54.064000Z","event_type":"price_change","frame_hash":"09eed578c79e6d4bbe24265d45a0649dfc37e9d4ac3322c0fa01a5dc5c6fabd9","frame_index":0,"kind":"data","monotonic_ns":229177275698583,"payload":{"event_type":"price_change","market":"0xeb66215f2e9faa6449e30a02bab5b8ed7b79a38bf961f6b24d0073c9c2419250","price_changes":[{"asset_id":"60386828328910021732068595344565885737045900010034836345809386672230885527307","best_ask":"0.34","best_bid":"0.33","hash":"f51404468a822a6a610420c7b9281390d7d8536d","price":"0.22","side":"BUY","size":"107"},{"asset_id":"69697746896130839564035629862476347944307040470122503199396727085502753297492","best_ask":"0.67","best_bid":"0.66","hash":"9249976b6a3c4b3ef1ec2e1112c2934db40bdea3","price":"0.78","side":"SELL","size":"107"}],"timestamp":"1785127194064"},"payload_hash":"ac3782fb8b7c2236dacaafe352b01e1df031771a464cd3b6eb2c927d42507ca3","raw_frame":"{\"market\":\"0xeb66215f2e9faa6449e30a02bab5b8ed7b79a38bf961f6b24d0073c9c2419250\", \"price_changes\":[{\"asset_id\":\"60386828328910021732068595344565885737045900010034836345809386672230885527307\", \"price\":\"0.22\", \"size\":\"107\", \"side\":\"BUY\", \"hash\":\"f51404468a822a6a610420c7b9281390d7d8536d\", \"best_bid\":\"0.33\", \"best_ask\":\"0.34\"}, {\"asset_id\":\"69697746896130839564035629862476347944307040470122503199396727085502753297492\", \"price\":\"0.78\", \"size\":\"107\", \"side\":\"SELL\", \"hash\":\"9249976b6a3c4b3ef1ec2e1112c2934db40bdea3\", \"best_bid\":\"0.66\", \"best_ask\":\"0.67\"}], \"timestamp\":\"1785127194064\", \"event_type\":\"price_change\"}","received_at":"2026-07-27T04:39:54.011013Z","schema_version":"clob-market-ws.price_change.v1","sequence":null,"server_hash":null,"server_timestamp":"1785127194064","session_id":"e9443c7415a0419799bee9cfbb1a9e4d","source":"clob_market_ws"},"received_at":"2026-07-27T04:39:54.011013Z","record_id":"43a2ccc2dc8e267afb1e6ffb4f195f8f3035ab98c658742580fa65ae725e6fff","schema_fingerprint":"4aa3821a28b0b7c2400bc59aba4bcc0a76e971dadd19610d3ad38c768e124dc7","schema_version":"edge-lab-recorder.raw.v1","sequence":null,"source":"clob_market_ws"}
{"event_at":"2026-07-27T04:39:54.089000Z","event_fingerprint":"c6faf0722e76472af31a19080994006bfbb23385398a19b5370a7122bfd7052a","payload":{"connection_id":"0f4979d6978d463e9660b042fdcf555f","event_at":"2026-07-27T04:39:54.089000Z","event_type":"price_change","frame_hash":"58d8d1b15ae0023da986b51c72cc85ee2acba6b9ccaa63fc9774b864025c5065","frame_index":0,"kind":"data","monotonic_ns":229177300881541,"payload":{"event_type":"price_change","market":"0xeb66215f2e9faa6449e30a02bab5b8ed7b79a38bf961f6b24d0073c9c2419250","price_changes":[{"asset_id":"60386828328910021732068595344565885737045900010034836345809386672230885527307","best_ask":"0.34","best_bid":"0.33","hash":"d3eb650836469e9ad463566880899a438e6fbccf","price":"0.32","side":"BUY","size":"9.6"},{"asset_id":"69697746896130839564035629862476347944307040470122503199396727085502753297492","best_ask":"0.67","best_bid":"0.66","hash":"488394497573b6a06c7f9525f93bf3dec4277e16","price":"0.68","side":"SELL","size":"9.6"}],"timestamp":"1785127194089"},"payload_hash":"7665f9fde0111920cb127b0d262a91df6e0fe61eea852a9dd518e7a10fea08c9","raw_frame":"{\"market\":\"0xeb66215f2e9faa6449e30a02bab5b8ed7b79a38bf961f6b24d0073c9c2419250\", \"price_changes\":[{\"asset_id\":\"60386828328910021732068595344565885737045900010034836345809386672230885527307\", \"price\":\"0.32\", \"size\":\"9.6\", \"side\":\"BUY\", \"hash\":\"d3eb650836469e9ad463566880899a438e6fbccf\", \"best_bid\":\"0.33\", \"best_ask\":\"0.34\"}, {\"asset_id\":\"69697746896130839564035629862476347944307040470122503199396727085502753297492\", \"price\":\"0.68\", \"size\":\"9.6\", \"side\":\"SELL\", \"hash\":\"488394497573b6a06c7f9525f93bf3dec4277e16\", \"best_bid\":\"0.66\", \"best_ask\":\"0.67\"}], \"timestamp\":\"1785127194089\", \"event_type\":\"price_change\"}","received_at":"2026-07-27T04:39:54.036195Z","schema_version":"clob-market-ws.price_change.v1","sequence":null,"server_hash":null,"server_timestamp":"1785127194089","session_id":"e9443c7415a0419799bee9cfbb1a9e4d","source":"clob_market_ws"},"received_at":"2026-07-27T04:39:54.036195Z","record_id":"a7ae1472a873a93c7ac98495c2aeaa9f750d6d7b43cfb7dac41be3f8aef2b1e2","schema_fingerprint":"4aa3821a28b0b7c2400bc59aba4bcc0a76e971dadd19610d3ad38c768e124dc7","schema_version":"edge-lab-recorder.raw.v1","sequence":null,"source":"clob_market_ws"}
