{"event_at":"2026-07-27T04:44:14.611000Z","event_fingerprint":"dbaca5686e4aa62e7e2d1bed0241c903da8d06c9c6925291f8ff0d0d059ca600","payload":{"connection_id":"0f4979d6978d463e9660b042fdcf555f","event_at":"2026-07-27T04:44:14.611000Z","event_type":"price_change","frame_hash":"02d8b48c6c352e483c25f48443b12768c6fcee71fc278d12f0c6c6e1c8afd59e","frame_index":0,"kind":"data","monotonic_ns":229437839288666,"payload":{"event_type":"price_change","market":"0xeb66215f2e9faa6449e30a02bab5b8ed7b79a38bf961f6b24d0073c9c2419250","price_changes":[{"asset_id":"60386828328910021732068595344565885737045900010034836345809386672230885527307","best_ask":"0.004","best_bid":"0.001","hash":"f4054c43405c2d8188a77c8eb60dcec8da2b13ac","price":"0.003","side":"SELL","size":"0"},{"asset_id":"69697746896130839564035629862476347944307040470122503199396727085502753297492","best_ask":"0.999","best_bid":"0.996","hash":"18b217eb36205574bb2e55f572dddf9abd6122a1","price":"0.997","side":"BUY","size":"0"}],"timestamp":"1785127454611"},"payload_hash":"94e28703eef536b540d336c89e65c2a8921b2fe9b2394c85e630e25b702055d1","raw_frame":"{\"market\":\"0xeb66215f2e9faa6449e30a02bab5b8ed7b79a38bf961f6b24d0073c9c2419250\", \"price_changes\":[{\"asset_id\":\"60386828328910021732068595344565885737045900010034836345809386672230885527307\", \"price\":\"0.003\", \"size\":\"0\", \"side\":\"SELL\", \"hash\":\"f4054c43405c2d8188a77c8eb60dcec8da2b13ac\", \"best_bid\":\"0.001\", \"best_ask\":\"0.004\"}, {\"asset_id\":\"69697746896130839564035629862476347944307040470122503199396727085502753297492\", \"price\":\"0.997\", \"size\":\"0\", \"side\":\"BUY\", \"hash\":\"18b217eb36205574bb2e55f572dddf9abd6122a1\", \"best_bid\":\"0.996\", \"best_ask\":\"0.999\"}], \"timestamp\":\"1785127454611\", \"event_type\":\"price_change\"}","received_at":"2026-07-27T04:44:14.576856Z","schema_version":"clob-market-ws.price_change.v1","sequence":null,"server_hash":null,"server_timestamp":"1785127454611","session_id":"e9443c7415a0419799bee9cfbb1a9e4d","source":"clob_market_ws"},"received_at":"2026-07-27T04:44:14.576856Z","record_id":"afcc5a29e2d8c6f9db336ad9b1eb059dcc2038f1da013859daa21d69ee26a523","schema_fingerprint":"4aa3821a28b0b7c2400bc59aba4bcc0a76e971dadd19610d3ad38c768e124dc7","schema_version":"edge-lab-recorder.raw.v1","sequence":null,"source":"clob_market_ws"}
{"event_at":"2026-07-27T04:44:14.623000Z","event_fingerprint":"53303a97b14121ff0693b96b19ee17169e10d42d35945ef8686a03fe37e78c99","payload":{"connection_id":"0f4979d6978d463e9660b042fdcf555f","event_at":"2026-07-27T04:44:14.623000Z","event_type":"price_change","frame_hash":"34205d4b30f1371e3b35cc1b754b2efa28152b0383de1a368891777e774dad29","frame_index":0,"kind":"data","monotonic_ns":229437843269625,"payload":{"event_type":"price_change","market":"0xeb66215f2e9faa6449e30a02bab5b8ed7b79a38bf961f6b24d0073c9c2419250","price_changes":[{"asset_id":"69697746896130839564035629862476347944307040470122503199396727085502753297492","best_ask":"0.999","best_bid":"0.996","hash":"13a7dc9e6bf9fb04c9e7a8e0045a13795227b4cf","price":"0.01","side":"BUY","size":"5320"},{"asset_id":"60386828328910021732068595344565885737045900010034836345809386672230885527307","best_ask":"0.004","best_bid":"0.001","hash":"ad112819e1d2d9ef2b3deda9ec181d0d9523a79b","price":"0.99","side":"SELL","size":"5320"}],"timestamp":"1785127454623"},"payload_hash":"67401fd9944edde1625c216d2dcece49e8d822bfa8662f9d844f5780b1f9db32","raw_frame":"{\"market\":\"0xeb66215f2e9faa6449e30a02bab5b8ed7b79a38bf961f6b24d0073c9c2419250\", \"price_changes\":[{\"asset_id\":\"69697746896130839564035629862476347944307040470122503199396727085502753297492\", \"price\":\"0.01\", \"size\":\"5320\", \"side\":\"BUY\", \"hash\":\"13a7dc9e6bf9fb04c9e7a8e0045a13795227b4cf\", \"best_bid\":\"0.996\", \"best_ask\":\"0.999\"}, {\"asset_id\":\"60386828328910021732068595344565885737045900010034836345809386672230885527307\", \"price\":\"0.99\", \"size\":\"5320\", \"side\":\"SELL\", \"hash\":\"ad112819e1d2d9ef2b3deda9ec181d0d9523a79b\", \"best_bid\":\"0.001\", \"best_ask\":\"0.004\"}], \"timestamp\":\"1785127454623\", \"event_type\":\"price_change\"}","received_at":"2026-07-27T04:44:14.580837Z","schema_version":"clob-market-ws.price_change.v1","sequence":null,"server_hash":null,"server_timestamp":"1785127454623","session_id":"e9443c7415a0419799bee9cfbb1a9e4d","source":"clob_market_ws"},"received_at":"2026-07-27T04:44:14.580837Z","record_id":"be7b6e0f7122999b40866615a5b7fda1769cbe6e107ae0a02cf073b891561843","schema_fingerprint":"4aa3821a28b0b7c2400bc59aba4bcc0a76e971dadd19610d3ad38c768e124dc7","schema_version":"edge-lab-recorder.raw.v1","sequence":null,"source":"clob_market_ws"}
{"event_at":"2026-07-27T04:44:14.643000Z","event_fingerprint":"f6f13e36f1a6d5d16fca6354c1615ba63c9915dd7e78f4456ec9d83d564fffb7","payload":{"connection_id":"0f4979d6978d463e9660b042fdcf555f","event_at":"2026-07-27T04:44:14.643000Z","event_type":"best_bid_ask","frame_hash":"79824abc7d2520485aa0c118d0c5721ae7bec9711ae19f8297b3eb06d73c3b2c","frame_index":0,"kind":"data","monotonic_ns":229437855466958,"payload":{"asset_id":"69697746896130839564035629862476347944307040470122503199396727085502753297492","best_ask":"0.999","best_bid":"0.997","event_type":"best_bid_ask","market":"0xeb66215f2e9faa6449e30a02bab5b8ed7b79a38bf961f6b24d0073c9c2419250","spread":"0.002","timestamp":"1785127454643"},"payload_hash":"9c36c17afa915219e0c8dbec77951628d7f2931da56eeb165579054d9c30c707","raw_frame":"{\"market\":\"0xeb66215f2e9faa6449e30a02bab5b8ed7b79a38bf961f6b24d0073c9c2419250\", \"asset_id\":\"69697746896130839564035629862476347944307040470122503199396727085502753297492\", \"best_bid\":\"0.997\", \"best_ask\":\"0.999\", \"spread\":\"0.002\", \"timestamp\":\"1785127454643\", \"event_type\":\"best_bid_ask\"}","received_at":"2026-07-27T04:44:14.593033Z","schema_version":"clob-market-ws.best_bid_ask.v1","sequence":null,"server_hash":null,"server_timestamp":"1785127454643","session_id":"e9443c7415a0419799bee9cfbb1a9e4d","source":"clob_market_ws"},"received_at":"2026-07-27T04:44:14.593033Z","record_id":"024aa4a47b739a424f7c2fc6559968e21c75ee15716f2ce4053917844000abd3","schema_fingerprint":"8488399f31b0337811b13b266be932db7062827c2470b78bd8e9e99bab51d17d","schema_version":"edge-lab-recorder.raw.v1","sequence":null,"source":"clob_market_ws"}
{"event_at":"2026-07-27T04:44:14.643000Z","event_fingerprint":"d9468a7232b8c7bc184c01659e91725f890a3207a222efd94b2070a83ca78c17","payload":{"connection_id":"0f4979d6978d463e9660b042fdcf555f","event_at":"2026-07-27T04:44:14.643000Z","event_type":"best_bid_ask","frame_hash":"858dc4adb33793b5474308f72775e942ac21a268383eda418ec422fef3e004db","frame_index":0,"kind":"data","monotonic_ns":229437856629375,"payload":{"asset_id":"60386828328910021732068595344565885737045900010034836345809386672230885527307","best_ask":"0.003","best_bid":"0.001","event_type":"best_bid_ask","market":"0xeb66215f2e9faa6449e30a02bab5b8ed7b79a38bf961f6b24d0073c9c2419250","spread":"0.002","timestamp":"1785127454643"},"payload_hash":"fb12564161edb3de3afc0601578c9cc743a9004fa531e493b6e691c58f452c6f","raw_frame":"{\"market\":\"0xeb66215f2e9faa6449e30a02bab5b8ed7b79a38bf961f6b24d0073c9c2419250\", \"asset_id\":\"60386828328910021732068595344565885737045900010034836345809386672230885527307\", \"best_bid\":\"0.001\", \"best_ask\":\"0.003\", \"spread\":\"0.002\", \"timestamp\":\"1785127454643\", \"event_type\":\"best_bid_ask\"}","received_at":"2026-07-27T04:44:14.594197Z","schema_version":"clob-market-ws.best_bid_ask.v1","sequence":null,"server_hash":null,"server_timestamp":"1785127454643","session_id":"e9443c7415a0419799bee9cfbb1a9e4d","source":"clob_market_ws"},"received_at":"2026-07-27T04:44:14.594197Z","record_id":"4af6db3fbb7898a01456fac5343b955bd0646098ff0196bfd4089ba78ea61604","schema_fingerprint":"8488399f31b0337811b13b266be932db7062827c2470b78bd8e9e99bab51d17d","schema_version":"edge-lab-recorder.raw.v1","sequence":null,"source":"clob_market_ws"}
{"event_at":"2026-07-27T04:44:14.643000Z","event_fingerprint":"b24fbc4b56fe4efbffd3f18b1cf26a326a8f4da572dc5741fa2e26565c6a33fe","payload":{"connection_id":"0f4979d6978d463e9660b042fdcf555f","event_at":"2026-07-27T04:44:14.643000Z","event_type":"price_change","frame_hash":"ee02da96f2395316cb57b8f6203442faae13b50f49a162b86526fdd50cf090ac","frame_index":0,"kind":"data","monotonic_ns":229437857053541,"payload":{"event_type":"price_change","market":"0xeb66215f2e9faa6449e30a02bab5b8ed7b79a38bf961f6b24d0073c9c2419250","price_changes":[{"asset_id":"60386828328910021732068595344565885737045900010034836345809386672230885527307","best_ask":"0.003","best_bid":"0.001","hash":"e3cb3291983f44dc90b747e3dde94055d234f5a6","price":"0.003","side":"SELL","size":"275.12"},{"asset_id":"69697746896130839564035629862476347944307040470122503199396727085502753297492","best_ask":"0.999","best_bid":"0.997","hash":"81bd40bc8c7d7545e2e0bf3fddc3481908e07580","price":"0.997","side":"BUY","size":"275.12"}],"timestamp":"1785127454643"},"payload_hash":"5aed9a6fdeccf159390999f2dd9d2cca1a25dbb53307e007a5a1368aa18df680","raw_frame":"{\"market\":\"0xeb66215f2e9faa6449e30a02bab5b8ed7b79a38bf961f6b24d0073c9c2419250\", \"price_changes\":[{\"asset_id\":\"60386828328910021732068595344565885737045900010034836345809386672230885527307\", \"price\":\"0.003\", \"size\":\"275.12\", \"side\":\"SELL\", \"hash\":\"e3cb3291983f44dc90b747e3dde94055d234f5a6\", \"best_bid\":\"0.001\", \"best_ask\":\"0.003\"}, {\"asset_id\":\"69697746896130839564035629862476347944307040470122503199396727085502753297492\", \"price\":\"0.997\", \"size\":\"275.12\", \"side\":\"BUY\", \"hash\":\"81bd40bc8c7d7545e2e0bf3fddc3481908e07580\", \"best_bid\":\"0.997\", \"best_ask\":\"0.999\"}], \"timestamp\":\"1785127454643\", \"event_type\":\"price_change\"}","received_at":"2026-07-27T04:44:14.594629Z","schema_version":"clob-market-ws.price_change.v1","sequence":null,"server_hash":null,"server_timestamp":"1785127454643","session_id":"e9443c7415a0419799bee9cfbb1a9e4d","source":"clob_market_ws"},"received_at":"2026-07-27T04:44:14.594629Z","record_id":"abac1b875bc381a77057e25242c8c7383d7c3edd108e9f2244a31e6d57e21281","schema_fingerprint":"4aa3821a28b0b7c2400bc59aba4bcc0a76e971dadd19610d3ad38c768e124dc7","schema_version":"edge-lab-recorder.raw.v1","sequence":null,"source":"clob_market_ws"}
{"event_at":"2026-07-27T04:44:14.650000Z","event_fingerprint":"6e1fc5798dc3cbacfdb86db370d29a5934bd6d3e95f5df6ea02de58c32b96f1c","payload":{"connection_id":"0f4979d6978d463e9660b042fdcf555f","event_at":"2026-07-27T04:44:14.650000Z","event_type":"price_change","frame_hash":"5cdc23130ee0f9341f36d52c94e15a91b0d64bbf3029d6fd51a4e6e61b288000","frame_index":0,"kind":"data","monotonic_ns":229437860888875,"payload":{"event_type":"price_change","market":"0xeb66215f2e9faa6449e30a02bab5b8ed7b79a38bf961f6b24d0073c9c2419250","price_changes":[{"asset_id":"69697746896130839564035629862476347944307040470122503199396727085502753297492","best_ask":"0.999","best_bid":"0.997","hash":"050fc9a49dadb94b16d9f1e873aebcb62025f6a5","price":"0.01","side":"BUY","size":"5315"},{"asset_id":"60386828328910021732068595344565885737045900010034836345809386672230885527307","best_ask":"0.003","best_bid":"0.001","hash":"a6e3a723c4c95d0ba0d061f777a425c2a16efa96","price":"0.99","side":"SELL","size":"5315"}],"timestamp":"1785127454650"},"payload_hash":"dd665701dfbfb92d6b32b75fc1a651c6cbbbb9ce0a03421c7c7333cc4bd32e14","raw_frame":"{\"market\":\"0xeb66215f2e9faa6449e30a02bab5b8ed7b79a38bf961f6b24d0073c9c2419250\", \"price_changes\":[{\"asset_id\":\"69697746896130839564035629862476347944307040470122503199396727085502753297492\", \"price\":\"0.01\", \"size\":\"5315\", \"side\":\"BUY\", \"hash\":\"050fc9a49dadb94b16d9f1e873aebcb62025f6a5\", \"best_bid\":\"0.997\", \"best_ask\":\"0.999\"}, {\"asset_id\":\"60386828328910021732068595344565885737045900010034836345809386672230885527307\", \"price\":\"0.99\", \"size\":\"5315\", \"side\":\"SELL\", \"hash\":\"a6e3a723c4c95d0ba0d061f777a425c2a16efa96\", \"best_bid\":\"0.001\", \"best_ask\":\"0.003\"}], \"timestamp\":\"1785127454650\", \"event_type\":\"price_change\"}","received_at":"2026-07-27T04:44:14.598456Z","schema_version":"clob-market-ws.price_change.v1","sequence":null,"server_hash":null,"server_timestamp":"1785127454650","session_id":"e9443c7415a0419799bee9cfbb1a9e4d","source":"clob_market_ws"},"received_at":"2026-07-27T04:44:14.598456Z","record_id":"e36704a723c2344f0f265cd274ea19e881522fcc943f7192f981ac72894ed830","schema_fingerprint":"4aa3821a28b0b7c2400bc59aba4bcc0a76e971dadd19610d3ad38c768e124dc7","schema_version":"edge-lab-recorder.raw.v1","sequence":null,"source":"clob_market_ws"}
{"event_at":"2026-07-27T04:44:14.664000Z","event_fingerprint":"dab6b340c55f3c5b8c1843bb7f60edd1a1e9c80436de560490066df92fced4fb","payload":{"connection_id":"0f4979d6978d463e9660b042fdcf555f","event_at":"2026-07-27T04:44:14.664000Z","event_type":"best_bid_ask","frame_hash":"7ce5915c8cceab7c4836d8acb9a57a0935d3127e9d03ecd8663728322939a7b2","frame_index":0,"kind":"data","monotonic_ns":229437876648500,"payload":{"asset_id":"69697746896130839564035629862476347944307040470122503199396727085502753297492","best_ask":"0.999","best_bid":"0.996","event_type":"best_bid_ask","market":"0xeb66215f2e9faa6449e30a02bab5b8ed7b79a38bf961f6b24d0073c9c2419250","spread":"0.003","timestamp":"1785127454664"},"payload_hash":"db3220bd5f788030e1d244655e177092bd79b836515a78b05a0bab568787c5ba","raw_frame":"{\"market\":\"0xeb66215f2e9faa6449e30a02bab5b8ed7b79a38bf961f6b24d0073c9c2419250\", \"asset_id\":\"69697746896130839564035629862476347944307040470122503199396727085502753297492\", \"best_bid\":\"0.996\", \"best_ask\":\"0.999\", \"spread\":\"0.003\", \"timestamp\":\"1785127454664\", \"event_type\":\"best_bid_ask\"}","received_at":"2026-07-27T04:44:14.614216Z","schema_version":"clob-market-ws.best_bid_ask.v1","sequence":null,"server_hash":null,"server_timestamp":"1785127454664","session_id":"e9443c7415a0419799bee9cfbb1a9e4d","source":"clob_market_ws"},"received_at":"2026-07-27T04:44:14.614216Z","record_id":"96420d761b5073cc345b93d13b51db5f45297cfc7ad662607f40a343189dbe6d","schema_fingerprint":"8488399f31b0337811b13b266be932db7062827c2470b78bd8e9e99bab51d17d","schema_version":"edge-lab-recorder.raw.v1","sequence":null,"source":"clob_market_ws"}
{"event_at":"2026-07-27T04:44:14.664000Z","event_fingerprint":"e48a22fe47819d4eeff61bc5650251d43798d9db7dc79d5c9f2e5396f8a7b8e1","payload":{"connection_id":"0f4979d6978d463e9660b042fdcf555f","event_at":"2026-07-27T04:44:14.664000Z","event_type":"best_bid_ask","frame_hash":"d91a0de45e9a09935e15199efea8a0b193b800ecf16e1d27599bf0a408502795","frame_index":0,"kind":"data","monotonic_ns":229437879067666,"payload":{"asset_id":"60386828328910021732068595344565885737045900010034836345809386672230885527307","best_ask":"0.004","best_bid":"0.001","event_type":"best_bid_ask","market":"0xeb66215f2e9faa6449e30a02bab5b8ed7b79a38bf961f6b24d0073c9c2419250","spread":"0.003","timestamp":"1785127454664"},"payload_hash":"77573dcd6c01fe0cda71bbc2b31a2b6da3e4698f92c0b2d080acd4d0a330ebf7","raw_frame":"{\"market\":\"0xeb66215f2e9faa6449e30a02bab5b8ed7b79a38bf961f6b24d0073c9c2419250\", \"asset_id\":\"60386828328910021732068595344565885737045900010034836345809386672230885527307\", \"best_bid\":\"0.001\", \"best_ask\":\"0.004\", \"spread\":\"0.003\", \"timestamp\":\"1785127454664\", \"event_type\":\"best_bid_ask\"}","received_at":"2026-07-27T04:44:14.616643Z","schema_version":"clob-market-ws.best_bid_ask.v1","sequence":null,"server_hash":null,"server_timestamp":"1785127454664","session_id":"e9443c7415a0419799bee9cfbb1a9e4d","source":"clob_market_ws"},"received_at":"2026-07-27T04:44:14.616643Z","record_id":"6c34bd487423b7023b22782647822bd05af2e1fdf9b877a4736de4a77a2521cf","schema_fingerprint":"8488399f31b0337811b13b266be932db7062827c2470b78bd8e9e99bab51d17d","schema_version":"edge-lab-recorder.raw.v1","sequence":null,"source":"clob_market_ws"}
{"event_at":"2026-07-27T04:44:14.664000Z","event_fingerprint":"b8e1fac2558f0497a71e43d18c524618ccbeffc06b089078df3118db60ed9292","payload":{"connection_id":"0f4979d6978d463e9660b042fdcf555f","event_at":"2026-07-27T04:44:14.664000Z","event_type":"price_change","frame_hash":"55d0c79a0fefb7eb22aca30315dd885fb15ff1d7177c5dec35002ef6563bf66b","frame_index":0,"kind":"data","monotonic_ns":229437879748833,"payload":{"event_type":"price_change","market":"0xeb66215f2e9faa6449e30a02bab5b8ed7b79a38bf961f6b24d0073c9c2419250","price_changes":[{"asset_id":"60386828328910021732068595344565885737045900010034836345809386672230885527307","best_ask":"0.004","best_bid":"0.001","hash":"b33263f929b0582581185cad1e235cb7e5c66faa","price":"0.003","side":"SELL","size":"0"},{"asset_id":"69697746896130839564035629862476347944307040470122503199396727085502753297492","best_ask":"0.999","best_bid":"0.996","hash":"9e841c82e80b6f3f3888dded4964616428c506b8","price":"0.997","side":"BUY","size":"0"}],"timestamp":"1785127454664"},"payload_hash":"ef7043cebdb54f81b5e483c346aff25c22b82d5bf4000d3aa0cddad84ccfbf2f","raw_frame":"{\"market\":\"0xeb66215f2e9faa6449e30a02bab5b8ed7b79a38bf961f6b24d0073c9c2419250\", \"price_changes\":[{\"asset_id\":\"60386828328910021732068595344565885737045900010034836345809386672230885527307\", \"price\":\"0.003\", \"size\":\"0\", \"side\":\"SELL\", \"hash\":\"b33263f929b0582581185cad1e235cb7e5c66faa\", \"best_bid\":\"0.001\", \"best_ask\":\"0.004\"}, {\"asset_id\":\"69697746896130839564035629862476347944307040470122503199396727085502753297492\", \"price\":\"0.997\", \"size\":\"0\", \"side\":\"BUY\", \"hash\":\"9e841c82e80b6f3f3888dded4964616428c506b8\", \"best_bid\":\"0.996\", \"best_ask\":\"0.999\"}], \"timestamp\":\"1785127454664\", \"event_type\":\"price_change\"}","received_at":"2026-07-27T04:44:14.617324Z","schema_version":"clob-market-ws.price_change.v1","sequence":null,"server_hash":null,"server_timestamp":"1785127454664","session_id":"e9443c7415a0419799bee9cfbb1a9e4d","source":"clob_market_ws"},"received_at":"2026-07-27T04:44:14.617324Z","record_id":"8d4fb99f6522df4e9b26eb594840f9100251e999bb732fea89d4f2cf89badd21","schema_fingerprint":"4aa3821a28b0b7c2400bc59aba4bcc0a76e971dadd19610d3ad38c768e124dc7","schema_version":"edge-lab-recorder.raw.v1","sequence":null,"source":"clob_market_ws"}
{"event_at":"2026-07-27T04:44:14.672000Z","event_fingerprint":"819dc6a72a81c754f174776c6bf86bf2cccba7f7d746ad93b301f3796a7467b7","payload":{"connection_id":"0f4979d6978d463e9660b042fdcf555f","event_at":"2026-07-27T04:44:14.672000Z","event_type":"price_change","frame_hash":"1351d2cad722d79c58ec8318896e7acd7f2d4f4fb11e787a29cc3ce5a9d9072f","frame_index":0,"kind":"data","monotonic_ns":229437882003916,"payload":{"event_type":"price_change","market":"0xeb66215f2e9faa6449e30a02bab5b8ed7b79a38bf961f6b24d0073c9c2419250","price_changes":[{"asset_id":"69697746896130839564035629862476347944307040470122503199396727085502753297492","best_ask":"0.999","best_bid":"0.996","hash":"78eb07db7d731c8f48a02f70d2ba2a6562798b30","price":"0.01","side":"BUY","size":"5320"},{"asset_id":"60386828328910021732068595344565885737045900010034836345809386672230885527307","best_ask":"0.004","best_bid":"0.001","hash":"2d5bb6426061242f452d9f23905ae7e14289b438","price":"0.99","side":"SELL","size":"5320"}],"timestamp":"1785127454672"},"payload_hash":"72a85c3afd912691aa3109fa52e9d18a9f1e03d2db6c51a74b7c95a8f4267f0a","raw_frame":"{\"market\":\"0xeb66215f2e9faa6449e30a02bab5b8ed7b79a38bf961f6b24d0073c9c2419250\", \"price_changes\":[{\"asset_id\":\"69697746896130839564035629862476347944307040470122503199396727085502753297492\", \"price\":\"0.01\", \"size\":\"5320\", \"side\":\"BUY\", \"hash\":\"78eb07db7d731c8f48a02f70d2ba2a6562798b30\", \"best_bid\":\"0.996\", \"best_ask\":\"0.999\"}, {\"asset_id\":\"60386828328910021732068595344565885737045900010034836345809386672230885527307\", \"price\":\"0.99\", \"size\":\"5320\", \"side\":\"SELL\", \"hash\":\"2d5bb6426061242f452d9f23905ae7e14289b438\", \"best_bid\":\"0.001\", \"best_ask\":\"0.004\"}], \"timestamp\":\"1785127454672\", \"event_type\":\"price_change\"}","received_at":"2026-07-27T04:44:14.619579Z","schema_version":"clob-market-ws.price_change.v1","sequence":null,"server_hash":null,"server_timestamp":"1785127454672","session_id":"e9443c7415a0419799bee9cfbb1a9e4d","source":"clob_market_ws"},"received_at":"2026-07-27T04:44:14.619579Z","record_id":"c2f2bd2189141f51ec7f813fddb4f6d70bbb1a26d33f710b7a77b620d0e6fb29","schema_fingerprint":"4aa3821a28b0b7c2400bc59aba4bcc0a76e971dadd19610d3ad38c768e124dc7","schema_version":"edge-lab-recorder.raw.v1","sequence":null,"source":"clob_market_ws"}
{"event_at":"2026-07-27T04:44:14.695000Z","event_fingerprint":"3f742bf676933aa056d772eaafb04a1163cac3d7036df6ca8cfdb30ff1f6a1f1","payload":{"connection_id":"0f4979d6978d463e9660b042fdcf555f","event_at":"2026-07-27T04:44:14.695000Z","event_type":"best_bid_ask","frame_hash":"aa4899f860c3aec6ef502d15ed1abd67ed869f8072e0acf3a39adab5f65694a4","frame_index":0,"kind":"data","monotonic_ns":229437905472416,"payload":{"asset_id":"69697746896130839564035629862476347944307040470122503199396727085502753297492","best_ask":"0.999","best_bid":"0.997","event_type":"best_bid_ask","market":"0xeb66215f2e9faa6449e30a02bab5b8ed7b79a38bf961f6b24d0073c9c2419250","spread":"0.002","timestamp":"1785127454695"},"payload_hash":"627874788f034761aaa220eeb8ceee630210a3fca5e9c50d273e0a914e1c3925","raw_frame":"{\"market\":\"0xeb66215f2e9faa6449e30a02bab5b8ed7b79a38bf961f6b24d0073c9c2419250\", \"asset_id\":\"69697746896130839564035629862476347944307040470122503199396727085502753297492\", \"best_bid\":\"0.997\", \"best_ask\":\"0.999\", \"spread\":\"0.002\", \"timestamp\":\"1785127454695\", \"event_type\":\"best_bid_ask\"}","received_at":"2026-07-27T04:44:14.643040Z","schema_version":"clob-market-ws.best_bid_ask.v1","sequence":null,"server_hash":null,"server_timestamp":"1785127454695","session_id":"e9443c7415a0419799bee9cfbb1a9e4d","source":"clob_market_ws"},"received_at":"2026-07-27T04:44:14.643040Z","record_id":"f345f694f6e9afb19d538ed0606f1c2796ebc86c70e8348d13d594a6bdd7c840","schema_fingerprint":"8488399f31b0337811b13b266be932db7062827c2470b78bd8e9e99bab51d17d","schema_version":"edge-lab-recorder.raw.v1","sequence":null,"source":"clob_market_ws"}
{"event_at":"2026-07-27T04:44:14.695000Z","event_fingerprint":"7231eb99c9de3f432894281412311e1ae9f87d4bfec27a784abdbb280e8699e6","payload":{"connection_id":"0f4979d6978d463e9660b042fdcf555f","event_at":"2026-07-27T04:44:14.695000Z","event_type":"best_bid_ask","frame_hash":"875dcfeeb32b7398e18dc91fae58ebe3b6df24c1f33c49ff16930c442d893d03","frame_index":0,"kind":"data","monotonic_ns":229437906657333,"payload":{"asset_id":"60386828328910021732068595344565885737045900010034836345809386672230885527307","best_ask":"0.003","best_bid":"0.001","event_type":"best_bid_ask","market":"0xeb66215f2e9faa6449e30a02bab5b8ed7b79a38bf961f6b24d0073c9c2419250","spread":"0.002","timestamp":"1785127454695"},"payload_hash":"1f35f143445849cf72af88436ef366a116d7fa6a4a4ae5e0e2c571538387e7fb","raw_frame":"{\"market\":\"0xeb66215f2e9faa6449e30a02bab5b8ed7b79a38bf961f6b24d0073c9c2419250\", \"asset_id\":\"60386828328910021732068595344565885737045900010034836345809386672230885527307\", \"best_bid\":\"0.001\", \"best_ask\":\"0.003\", \"spread\":\"0.002\", \"timestamp\":\"1785127454695\", \"event_type\":\"best_bid_ask\"}","received_at":"2026-07-27T04:44:14.644225Z","schema_version":"clob-market-ws.best_bid_ask.v1","sequence":null,"server_hash":null,"server_timestamp":"1785127454695","session_id":"e9443c7415a0419799bee9cfbb1a9e4d","source":"clob_market_ws"},"received_at":"2026-07-27T04:44:14.644225Z","record_id":"3525f2f3b7dce45f1769365762178cd7b60cc46eb230f43ada0ac84c84c4f2a0","schema_fingerprint":"8488399f31b0337811b13b266be932db7062827c2470b78bd8e9e99bab51d17d","schema_version":"edge-lab-recorder.raw.v1","sequence":null,"source":"clob_market_ws"}
{"event_at":"2026-07-27T04:44:14.695000Z","event_fingerprint":"9d73477f02cf7254be3f65ee5ce8ea1ee9f59ca7f80deaa1a92e8f55fec81624","payload":{"connection_id":"0f4979d6978d463e9660b042fdcf555f","event_at":"2026-07-27T04:44:14.695000Z","event_type":"price_change","frame_hash":"0367c9bf0629ce3bbdad6ba9dc4d625b5c98d990215c6c2becaf647994ae917c","frame_index":0,"kind":"data","monotonic_ns":229437907787750,"payload":{"event_type":"price_change","market":"0xeb66215f2e9faa6449e30a02bab5b8ed7b79a38bf961f6b24d0073c9c2419250","price_changes":[{"asset_id":"60386828328910021732068595344565885737045900010034836345809386672230885527307","best_ask":"0.003","best_bid":"0.001","hash":"6a08d01e74d1966fbba0e972044ee6f1edd9db9d","price":"0.003","side":"SELL","size":"275.12"},{"asset_id":"69697746896130839564035629862476347944307040470122503199396727085502753297492","best_ask":"0.999","best_bid":"0.997","hash":"77931209c828019c5491add660328a90555f222e","price":"0.997","side":"BUY","size":"275.12"}],"timestamp":"1785127454695"},"payload_hash":"f209eb3a5d021d45a6c0a41ccb1967f222c0c523e6257d047db9c02c44155c8d","raw_frame":"{\"market\":\"0xeb66215f2e9faa6449e30a02bab5b8ed7b79a38bf961f6b24d0073c9c2419250\", \"price_changes\":[{\"asset_id\":\"60386828328910021732068595344565885737045900010034836345809386672230885527307\", \"price\":\"0.003\", \"size\":\"275.12\", \"side\":\"SELL\", \"hash\":\"6a08d01e74d1966fbba0e972044ee6f1edd9db9d\", \"best_bid\":\"0.001\", \"best_ask\":\"0.003\"}, {\"asset_id\":\"69697746896130839564035629862476347944307040470122503199396727085502753297492\", \"price\":\"0.997\", \"size\":\"275.12\", \"side\":\"BUY\", \"hash\":\"77931209c828019c5491add660328a90555f222e\", \"best_bid\":\"0.997\", \"best_ask\":\"0.999\"}], \"timestamp\":\"1785127454695\", \"event_type\":\"price_change\"}","received_at":"2026-07-27T04:44:14.645359Z","schema_version":"clob-market-ws.price_change.v1","sequence":null,"server_hash":null,"server_timestamp":"1785127454695","session_id":"e9443c7415a0419799bee9cfbb1a9e4d","source":"clob_market_ws"},"received_at":"2026-07-27T04:44:14.645359Z","record_id":"678f540d2b94a079c601065310d6c9ae61818dd28f7a5549dc777f0a06fdf2ef","schema_fingerprint":"4aa3821a28b0b7c2400bc59aba4bcc0a76e971dadd19610d3ad38c768e124dc7","schema_version":"edge-lab-recorder.raw.v1","sequence":null,"source":"clob_market_ws"}
{"event_at":"2026-07-27T04:44:14.718000Z","event_fingerprint":"14cddfcae3eaf163f950c385c44097cb2a61dc1513abb53c30f2278efc4c843b","payload":{"connection_id":"0f4979d6978d463e9660b042fdcf555f","event_at":"2026-07-27T04:44:14.718000Z","event_type":"best_bid_ask","frame_hash":"c374f397012649b52a38a1d3dbaf572d3dfd9a712335ba0f3c7708405a383b49","frame_index":0,"kind":"data","monotonic_ns":229437927720083,"payload":{"asset_id":"69697746896130839564035629862476347944307040470122503199396727085502753297492","best_ask":"0.999","best_bid":"0.996","event_type":"best_bid_ask","market":"0xeb66215f2e9faa6449e30a02bab5b8ed7b79a38bf961f6b24d0073c9c2419250","spread":"0.003","timestamp":"1785127454718"},"payload_hash":"67b4e131144bc6be0912e3cd07d9733cea8a3f39ed59cf2080bd968a464cec9f","raw_frame":"{\"market\":\"0xeb66215f2e9faa6449e30a02bab5b8ed7b79a38bf961f6b24d0073c9c2419250\", \"asset_id\":\"69697746896130839564035629862476347944307040470122503199396727085502753297492\", \"best_bid\":\"0.996\", \"best_ask\":\"0.999\", \"spread\":\"0.003\", \"timestamp\":\"1785127454718\", \"event_type\":\"best_bid_ask\"}","received_at":"2026-07-27T04:44:14.665288Z","schema_version":"clob-market-ws.best_bid_ask.v1","sequence":null,"server_hash":null,"server_timestamp":"1785127454718","session_id":"e9443c7415a0419799bee9cfbb1a9e4d","source":"clob_market_ws"},"received_at":"2026-07-27T04:44:14.665288Z","record_id":"852f98b1c8965958d78da6a718217094779f973289f5186fbcf3caf78a3019c7","schema_fingerprint":"8488399f31b0337811b13b266be932db7062827c2470b78bd8e9e99bab51d17d","schema_version":"edge-lab-recorder.raw.v1","sequence":null,"source":"clob_market_ws"}
{"event_at":"2026-07-27T04:44:14.718000Z","event_fingerprint":"b2e039fb16ddd2dac81902c5376bb6b091b306e75f55da0ba7d5f2cf23d05235","payload":{"connection_id":"0f4979d6978d463e9660b042fdcf555f","event_at":"2026-07-27T04:44:14.718000Z","event_type":"best_bid_ask","frame_hash":"ed325170411d251a61f30389b629f38a680b8fe8aef95856bd5d443d3ebd0f56","frame_index":0,"kind":"data","monotonic_ns":229437930033000,"payload":{"asset_id":"60386828328910021732068595344565885737045900010034836345809386672230885527307","best_ask":"0.004","best_bid":"0.001","event_type":"best_bid_ask","market":"0xeb66215f2e9faa6449e30a02bab5b8ed7b79a38bf961f6b24d0073c9c2419250","spread":"0.003","timestamp":"1785127454718"},"payload_hash":"ca0b5a9d6afe9e5dc6c8388298dfcf15aa51889b796f79184a63819e0725f101","raw_frame":"{\"market\":\"0xeb66215f2e9faa6449e30a02bab5b8ed7b79a38bf961f6b24d0073c9c2419250\", \"asset_id\":\"60386828328910021732068595344565885737045900010034836345809386672230885527307\", \"best_bid\":\"0.001\", \"best_ask\":\"0.004\", \"spread\":\"0.003\", \"timestamp\":\"1785127454718\", \"event_type\":\"best_bid_ask\"}","received_at":"2026-07-27T04:44:14.667603Z","schema_version":"clob-market-ws.best_bid_ask.v1","sequence":null,"server_hash":null,"server_timestamp":"1785127454718","session_id":"e9443c7415a0419799bee9cfbb1a9e4d","source":"clob_market_ws"},"received_at":"2026-07-27T04:44:14.667603Z","record_id":"6e509fda21e70fefa9bae5328d4136b4dc73f9808ec6ab8f0f1e24cad5763146","schema_fingerprint":"8488399f31b0337811b13b266be932db7062827c2470b78bd8e9e99bab51d17d","schema_version":"edge-lab-recorder.raw.v1","sequence":null,"source":"clob_market_ws"}
{"event_at":"2026-07-27T04:44:14.718000Z","event_fingerprint":"ed0c5b3215afa252fd2a53cccf99205ef3ebd527204d14a26593d84905c08eea","payload":{"connection_id":"0f4979d6978d463e9660b042fdcf555f","event_at":"2026-07-27T04:44:14.718000Z","event_type":"price_change","frame_hash":"646c4f01ac2522bd61b02e9220f75b179246348c3c2e2c9c21b3706967931810","frame_index":0,"kind":"data","monotonic_ns":229437931090166,"payload":{"event_type":"price_change","market":"0xeb66215f2e9faa6449e30a02bab5b8ed7b79a38bf961f6b24d0073c9c2419250","price_changes":[{"asset_id":"60386828328910021732068595344565885737045900010034836345809386672230885527307","best_ask":"0.004","best_bid":"0.001","hash":"941fa3926acaab87d2f8c6c4f600f8e0cf177eac","price":"0.003","side":"SELL","size":"0"},{"asset_id":"69697746896130839564035629862476347944307040470122503199396727085502753297492","best_ask":"0.999","best_bid":"0.996","hash":"9e12208ab6600805725c6e1bc58d85117073fc59","price":"0.997","side":"BUY","size":"0"}],"timestamp":"1785127454718"},"payload_hash":"e19c595ad8d054cb2a0c774b3cec01875d9461590a17ffb51524f7757cc47c64","raw_frame":"{\"market\":\"0xeb66215f2e9faa6449e30a02bab5b8ed7b79a38bf961f6b24d0073c9c2419250\", \"price_changes\":[{\"asset_id\":\"60386828328910021732068595344565885737045900010034836345809386672230885527307\", \"price\":\"0.003\", \"size\":\"0\", \"side\":\"SELL\", \"hash\":\"941fa3926acaab87d2f8c6c4f600f8e0cf177eac\", \"best_bid\":\"0.001\", \"best_ask\":\"0.004\"}, {\"asset_id\":\"69697746896130839564035629862476347944307040470122503199396727085502753297492\", \"price\":\"0.997\", \"size\":\"0\", \"side\":\"BUY\", \"hash\":\"9e12208ab6600805725c6e1bc58d85117073fc59\", \"best_bid\":\"0.996\", \"best_ask\":\"0.999\"}], \"timestamp\":\"1785127454718\", \"event_type\":\"price_change\"}","received_at":"2026-07-27T04:44:14.668660Z","schema_version":"clob-market-ws.price_change.v1","sequence":null,"server_hash":null,"server_timestamp":"1785127454718","session_id":"e9443c7415a0419799bee9cfbb1a9e4d","source":"clob_market_ws"},"received_at":"2026-07-27T04:44:14.668660Z","record_id":"6e72a60ec656b26ab9a4ab0470954dff28f93ae457d14c518629e9d284048181","schema_fingerprint":"4aa3821a28b0b7c2400bc59aba4bcc0a76e971dadd19610d3ad38c768e124dc7","schema_version":"edge-lab-recorder.raw.v1","sequence":null,"source":"clob_market_ws"}
{"event_at":"2026-07-27T04:44:14.726000Z","event_fingerprint":"fee8ca3e7472462943a010d89261e6020f0f3eb1864e2355ae6180ea4e870005","payload":{"connection_id":"0f4979d6978d463e9660b042fdcf555f","event_at":"2026-07-27T04:44:14.726000Z","event_type":"price_change","frame_hash":"a9d0a9027b1d8eeaf2b7c7490281688ac4f4fe549104305bbc51d24b18352627","frame_index":0,"kind":"data","monotonic_ns":229437936126833,"payload":{"event_type":"price_change","market":"0xeb66215f2e9faa6449e30a02bab5b8ed7b79a38bf961f6b24d0073c9c2419250","price_changes":[{"asset_id":"69697746896130839564035629862476347944307040470122503199396727085502753297492","best_ask":"0.999","best_bid":"0.996","hash":"77cca2b1b4dd12829507205fbc59e5bd5c939455","price":"0.01","side":"BUY","size":"5315"},{"asset_id":"60386828328910021732068595344565885737045900010034836345809386672230885527307","best_ask":"0.004","best_bid":"0.001","hash":"49d5f9cf52d29dfe824b67e0f24ccee57250663c","price":"0.99","side":"SELL","size":"5315"}],"timestamp":"1785127454726"},"payload_hash":"b8fb27541160767a17e76113cfdceb014ccaddc1bb4922d409ef80fc1fa6dfc6","raw_frame":"{\"market\":\"0xeb66215f2e9faa6449e30a02bab5b8ed7b79a38bf961f6b24d0073c9c2419250\", \"price_changes\":[{\"asset_id\":\"69697746896130839564035629862476347944307040470122503199396727085502753297492\", \"price\":\"0.01\", \"size\":\"5315\", \"side\":\"BUY\", \"hash\":\"77cca2b1b4dd12829507205fbc59e5bd5c939455\", \"best_bid\":\"0.996\", \"best_ask\":\"0.999\"}, {\"asset_id\":\"60386828328910021732068595344565885737045900010034836345809386672230885527307\", \"price\":\"0.99\", \"size\":\"5315\", \"side\":\"SELL\", \"hash\":\"49d5f9cf52d29dfe824b67e0f24ccee57250663c\", \"best_bid\":\"0.001\", \"best_ask\":\"0.004\"}], \"timestamp\":\"1785127454726\", \"event_type\":\"price_change\"}","received_at":"2026-07-27T04:44:14.673698Z","schema_version":"clob-market-ws.price_change.v1","sequence":null,"server_hash":null,"server_timestamp":"1785127454726","session_id":"e9443c7415a0419799bee9cfbb1a9e4d","source":"clob_market_ws"},"received_at":"2026-07-27T04:44:14.673698Z","record_id":"af2d927f29cb32a9ec275cf899fb8b13ece632762e3216be18adee7b919b8d62","schema_fingerprint":"4aa3821a28b0b7c2400bc59aba4bcc0a76e971dadd19610d3ad38c768e124dc7","schema_version":"edge-lab-recorder.raw.v1","sequence":null,"source":"clob_market_ws"}
{"event_at":"2026-07-27T04:44:14.748000Z","event_fingerprint":"cda1e008299e4af1de11a47f01891d1c0c875505b439435b4d0b4bbf9cbe187f","payload":{"connection_id":"0f4979d6978d463e9660b042fdcf555f","event_at":"2026-07-27T04:44:14.748000Z","event_type":"best_bid_ask","frame_hash":"36cc1516a650bd4939fd6c2f8057ff37b1d724778b010b4237cadeefadc32972","frame_index":0,"kind":"data","monotonic_ns":229437958385791,"payload":{"asset_id":"69697746896130839564035629862476347944307040470122503199396727085502753297492","best_ask":"0.999","best_bid":"0.997","event_type":"best_bid_ask","market":"0xeb66215f2e9faa6449e30a02bab5b8ed7b79a38bf961f6b24d0073c9c2419250","spread":"0.002","timestamp":"1785127454748"},"payload_hash":"afda4062d6b21edafee6f92841682d573b0029583661d214c3455eba90abe2e5","raw_frame":"{\"market\":\"0xeb66215f2e9faa6449e30a02bab5b8ed7b79a38bf961f6b24d0073c9c2419250\", \"asset_id\":\"69697746896130839564035629862476347944307040470122503199396727085502753297492\", \"best_bid\":\"0.997\", \"best_ask\":\"0.999\", \"spread\":\"0.002\", \"timestamp\":\"1785127454748\", \"event_type\":\"best_bid_ask\"}","received_at":"2026-07-27T04:44:14.695954Z","schema_version":"clob-market-ws.best_bid_ask.v1","sequence":null,"server_hash":null,"server_timestamp":"1785127454748","session_id":"e9443c7415a0419799bee9cfbb1a9e4d","source":"clob_market_ws"},"received_at":"2026-07-27T04:44:14.695954Z","record_id":"882a48f4671783e2ff8e38f26e8af14f85aa599295fa7409f21bec99ecc14b54","schema_fingerprint":"8488399f31b0337811b13b266be932db7062827c2470b78bd8e9e99bab51d17d","schema_version":"edge-lab-recorder.raw.v1","sequence":null,"source":"clob_market_ws"}
{"event_at":"2026-07-27T04:44:14.748000Z","event_fingerprint":"93c35c6c512a508782e0bd0d0a538116ed407c696600798f11159d5e309c0e99","payload":{"connection_id":"0f4979d6978d463e9660b042fdcf555f","event_at":"2026-07-27T04:44:14.748000Z","event_type":"best_bid_ask","frame_hash":"e3c26c8d78cd072fb823b992a5056521de13fe87439a6473c02682bd867483ac","frame_index":0,"kind":"data","monotonic_ns":229437959518000,"payload":{"asset_id":"60386828328910021732068595344565885737045900010034836345809386672230885527307","best_ask":"0.003","best_bid":"0.001","event_type":"best_bid_ask","market":"0xeb66215f2e9faa6449e30a02bab5b8ed7b79a38bf961f6b24d0073c9c2419250","spread":"0.002","timestamp":"1785127454748"},"payload_hash":"134b58e6be6afe54f8cb8fcc6d36c94e7e532957c127ad8f4c3340466688a22c","raw_frame":"{\"market\":\"0xeb66215f2e9faa6449e30a02bab5b8ed7b79a38bf961f6b24d0073c9c2419250\", \"asset_id\":\"60386828328910021732068595344565885737045900010034836345809386672230885527307\", \"best_bid\":\"0.001\", \"best_ask\":\"0.003\", \"spread\":\"0.002\", \"timestamp\":\"1785127454748\", \"event_type\":\"best_bid_ask\"}","received_at":"2026-07-27T04:44:14.697087Z","schema_version":"clob-market-ws.best_bid_ask.v1","sequence":null,"server_hash":null,"server_timestamp":"1785127454748","session_id":"e9443c7415a0419799bee9cfbb1a9e4d","source":"clob_market_ws"},"received_at":"2026-07-27T04:44:14.697087Z","record_id":"cd15754f61e67097fc1a16c058265512726fda3ae5316624bd8c8c3af62b0bf4","schema_fingerprint":"8488399f31b0337811b13b266be932db7062827c2470b78bd8e9e99bab51d17d","schema_version":"edge-lab-recorder.raw.v1","sequence":null,"source":"clob_market_ws"}
{"event_at":"2026-07-27T04:44:14.748000Z","event_fingerprint":"783fc12bbcfcb799c9cedb3959e61af31ff3627fbac0fa9406b78e7adf5ad929","payload":{"connection_id":"0f4979d6978d463e9660b042fdcf555f","event_at":"2026-07-27T04:44:14.748000Z","event_type":"price_change","frame_hash":"7505ef5048aaac01946a4cad51d4f667cfd373be4ef4185275170b331d1051f7","frame_index":0,"kind":"data","monotonic_ns":229437960666583,"payload":{"event_type":"price_change","market":"0xeb66215f2e9faa6449e30a02bab5b8ed7b79a38bf961f6b24d0073c9c2419250","price_changes":[{"asset_id":"60386828328910021732068595344565885737045900010034836345809386672230885527307","best_ask":"0.003","best_bid":"0.001","hash":"4b102d3e7900d815b7bc7588656d2e0901ecf229","price":"0.003","side":"SELL","size":"275.12"},{"asset_id":"69697746896130839564035629862476347944307040470122503199396727085502753297492","best_ask":"0.999","best_bid":"0.997","hash":"0e23fe99573db7445c694198e2fbb45d4e1ab44c","price":"0.997","side":"BUY","size":"275.12"}],"timestamp":"1785127454748"},"payload_hash":"beb1b74c0bffe81a0fba9507675c8c02e14dc6e542288aaf76e1ef4f8cdfe2d0","raw_frame":"{\"market\":\"0xeb66215f2e9faa6449e30a02bab5b8ed7b79a38bf961f6b24d0073c9c2419250\", \"price_changes\":[{\"asset_id\":\"60386828328910021732068595344565885737045900010034836345809386672230885527307\", \"price\":\"0.003\", \"size\":\"275.12\", \"side\":\"SELL\", \"hash\":\"4b102d3e7900d815b7bc7588656d2e0901ecf229\", \"best_bid\":\"0.001\", \"best_ask\":\"0.003\"}, {\"asset_id\":\"69697746896130839564035629862476347944307040470122503199396727085502753297492\", \"price\":\"0.997\", \"size\":\"275.12\", \"side\":\"BUY\", \"hash\":\"0e23fe99573db7445c694198e2fbb45d4e1ab44c\", \"best_bid\":\"0.997\", \"best_ask\":\"0.999\"}], \"timestamp\":\"1785127454748\", \"event_type\":\"price_change\"}","received_at":"2026-07-27T04:44:14.698234Z","schema_version":"clob-market-ws.price_change.v1","sequence":null,"server_hash":null,"server_timestamp":"1785127454748","session_id":"e9443c7415a0419799bee9cfbb1a9e4d","source":"clob_market_ws"},"received_at":"2026-07-27T04:44:14.698234Z","record_id":"34d152a2d63e412288a801675dc63bfdc4f71ba68b01f6d6ec7d980ead5fe4e5","schema_fingerprint":"4aa3821a28b0b7c2400bc59aba4bcc0a76e971dadd19610d3ad38c768e124dc7","schema_version":"edge-lab-recorder.raw.v1","sequence":null,"source":"clob_market_ws"}
{"event_at":"2026-07-27T04:44:14.770000Z","event_fingerprint":"d0fa12d6249e7c3382b2b7ec26c2660a7f6942dd54ffea38d3ff06d9dfdc0684","payload":{"connection_id":"0f4979d6978d463e9660b042fdcf555f","event_at":"2026-07-27T04:44:14.770000Z","event_type":"best_bid_ask","frame_hash":"26c289a2952b046391088f21b1da0065df4000ab1e4a995dbc69899a6e86fd06","frame_index":0,"kind":"data","monotonic_ns":229437980925416,"payload":{"asset_id":"69697746896130839564035629862476347944307040470122503199396727085502753297492","best_ask":"0.999","best_bid":"0.996","event_type":"best_bid_ask","market":"0xeb66215f2e9faa6449e30a02bab5b8ed7b79a38bf961f6b24d0073c9c2419250","spread":"0.003","timestamp":"1785127454770"},"payload_hash":"1c3a2a3fdbd512f25867183b078c4ea4166b379254ed0442c48ea723c0ae51ce","raw_frame":"{\"market\":\"0xeb66215f2e9faa6449e30a02bab5b8ed7b79a38bf961f6b24d0073c9c2419250\", \"asset_id\":\"69697746896130839564035629862476347944307040470122503199396727085502753297492\", \"best_bid\":\"0.996\", \"best_ask\":\"0.999\", \"spread\":\"0.003\", \"timestamp\":\"1785127454770\", \"event_type\":\"best_bid_ask\"}","received_at":"2026-07-27T04:44:14.718498Z","schema_version":"clob-market-ws.best_bid_ask.v1","sequence":null,"server_hash":null,"server_timestamp":"1785127454770","session_id":"e9443c7415a0419799bee9cfbb1a9e4d","source":"clob_market_ws"},"received_at":"2026-07-27T04:44:14.718498Z","record_id":"3f248c4176d44b82b6d721b387ce5c7d3cf0ec2556d337a01688fa65314a8c5e","schema_fingerprint":"8488399f31b0337811b13b266be932db7062827c2470b78bd8e9e99bab51d17d","schema_version":"edge-lab-recorder.raw.v1","sequence":null,"source":"clob_market_ws"}
{"event_at":"2026-07-27T04:44:14.770000Z","event_fingerprint":"ae5416edcff2c7c88ff048e3c08b96f56d78a59628e237173fc5c0fb9ba09133","payload":{"connection_id":"0f4979d6978d463e9660b042fdcf555f","event_at":"2026-07-27T04:44:14.770000Z","event_type":"best_bid_ask","frame_hash":"3232784686b95a12fae924c565eaa5ed0b16efd368b0d7959fb02be2972fdd79","frame_index":0,"kind":"data","monotonic_ns":229437981479166,"payload":{"asset_id":"60386828328910021732068595344565885737045900010034836345809386672230885527307","best_ask":"0.004","best_bid":"0.001","event_type":"best_bid_ask","market":"0xeb66215f2e9faa6449e30a02bab5b8ed7b79a38bf961f6b24d0073c9c2419250","spread":"0.003","timestamp":"1785127454770"},"payload_hash":"b9996e76928f565d7176b98b58364851afd6060702bc0c26c1f0687bebe44580","raw_frame":"{\"market\":\"0xeb66215f2e9faa6449e30a02bab5b8ed7b79a38bf961f6b24d0073c9c2419250\", \"asset_id\":\"60386828328910021732068595344565885737045900010034836345809386672230885527307\", \"best_bid\":\"0.001\", \"best_ask\":\"0.004\", \"spread\":\"0.003\", \"timestamp\":\"1785127454770\", \"event_type\":\"best_bid_ask\"}","received_at":"2026-07-27T04:44:14.719054Z","schema_version":"clob-market-ws.best_bid_ask.v1","sequence":null,"server_hash":null,"server_timestamp":"1785127454770","session_id":"e9443c7415a0419799bee9cfbb1a9e4d","source":"clob_market_ws"},"received_at":"2026-07-27T04:44:14.719054Z","record_id":"2264cc91324f7fefb92d6dd5cf321e588590afc2fe3493101f462283cc9221e5","schema_fingerprint":"8488399f31b0337811b13b266be932db7062827c2470b78bd8e9e99bab51d17d","schema_version":"edge-lab-recorder.raw.v1","sequence":null,"source":"clob_market_ws"}
{"event_at":"2026-07-27T04:44:14.770000Z","event_fingerprint":"19e21cfe5945e0281a15d31e85e4017c079ea4f0022da9b6467cb772fa742adc","payload":{"connection_id":"0f4979d6978d463e9660b042fdcf555f","event_at":"2026-07-27T04:44:14.770000Z","event_type":"price_change","frame_hash":"1aae18d068e369a0a5ece46169bb3d5f5db61e4370f12a51b982a1e0a96a967e","frame_index":0,"kind":"data","monotonic_ns":229437981995500,"payload":{"event_type":"price_change","market":"0xeb66215f2e9faa6449e30a02bab5b8ed7b79a38bf961f6b24d0073c9c2419250","price_changes":[{"asset_id":"60386828328910021732068595344565885737045900010034836345809386672230885527307","best_ask":"0.004","best_bid":"0.001","hash":"c0effe21efe81664fa6ef3854185b81ff772d209","price":"0.003","side":"SELL","size":"0"},{"asset_id":"69697746896130839564035629862476347944307040470122503199396727085502753297492","best_ask":"0.999","best_bid":"0.996","hash":"03814af9e7b0dfcc3471df2ffa6c6378bef65c0e","price":"0.997","side":"BUY","size":"0"}],"timestamp":"1785127454770"},"payload_hash":"b1f0de9b969ce55ba479ccdccec50e238189f7ad70a540a8ee9bba9bd17b97d8","raw_frame":"{\"market\":\"0xeb66215f2e9faa6449e30a02bab5b8ed7b79a38bf961f6b24d0073c9c2419250\", \"price_changes\":[{\"asset_id\":\"60386828328910021732068595344565885737045900010034836345809386672230885527307\", \"price\":\"0.003\", \"size\":\"0\", \"side\":\"SELL\", \"hash\":\"c0effe21efe81664fa6ef3854185b81ff772d209\", \"best_bid\":\"0.001\", \"best_ask\":\"0.004\"}, {\"asset_id\":\"69697746896130839564035629862476347944307040470122503199396727085502753297492\", \"price\":\"0.997\", \"size\":\"0\", \"side\":\"BUY\", \"hash\":\"03814af9e7b0dfcc3471df2ffa6c6378bef65c0e\", \"best_bid\":\"0.996\", \"best_ask\":\"0.999\"}], \"timestamp\":\"1785127454770\", \"event_type\":\"price_change\"}","received_at":"2026-07-27T04:44:14.719571Z","schema_version":"clob-market-ws.price_change.v1","sequence":null,"server_hash":null,"server_timestamp":"1785127454770","session_id":"e9443c7415a0419799bee9cfbb1a9e4d","source":"clob_market_ws"},"received_at":"2026-07-27T04:44:14.719571Z","record_id":"56df5fa565748585fe38d3f10f39546783d558573adebfbcf818948c4a66d4c7","schema_fingerprint":"4aa3821a28b0b7c2400bc59aba4bcc0a76e971dadd19610d3ad38c768e124dc7","schema_version":"edge-lab-recorder.raw.v1","sequence":null,"source":"clob_market_ws"}
{"event_at":"2026-07-27T04:44:14.804000Z","event_fingerprint":"4ec74555b7e360b812cc3fc53bcfd888cb2a90252c0f617b8918e7065e601e2a","payload":{"connection_id":"0f4979d6978d463e9660b042fdcf555f","event_at":"2026-07-27T04:44:14.804000Z","event_type":"best_bid_ask","frame_hash":"b58a3d5d08b78a24ded8240fead7a4d039699f64dfa3423620a97d936f4c46e9","frame_index":0,"kind":"data","monotonic_ns":229438013550333,"payload":{"asset_id":"69697746896130839564035629862476347944307040470122503199396727085502753297492","best_ask":"0.999","best_bid":"0.997","event_type":"best_bid_ask","market":"0xeb66215f2e9faa6449e30a02bab5b8ed7b79a38bf961f6b24d0073c9c2419250","spread":"0.002","timestamp":"1785127454804"},"payload_hash":"df4b132d0e3e53c9a17693aace2351cadc0e314877c4447e1598238f57ad3484","raw_frame":"{\"market\":\"0xeb66215f2e9faa6449e30a02bab5b8ed7b79a38bf961f6b24d0073c9c2419250\", \"asset_id\":\"69697746896130839564035629862476347944307040470122503199396727085502753297492\", \"best_bid\":\"0.997\", \"best_ask\":\"0.999\", \"spread\":\"0.002\", \"timestamp\":\"1785127454804\", \"event_type\":\"best_bid_ask\"}","received_at":"2026-07-27T04:44:14.751122Z","schema_version":"clob-market-ws.best_bid_ask.v1","sequence":null,"server_hash":null,"server_timestamp":"1785127454804","session_id":"e9443c7415a0419799bee9cfbb1a9e4d","source":"clob_market_ws"},"received_at":"2026-07-27T04:44:14.751122Z","record_id":"c56a1d40f4b3de4b8ccb68834148425ac81ae8212de375cdd8eab5fb8e3e35e7","schema_fingerprint":"8488399f31b0337811b13b266be932db7062827c2470b78bd8e9e99bab51d17d","schema_version":"edge-lab-recorder.raw.v1","sequence":null,"source":"clob_market_ws"}
{"event_at":"2026-07-27T04:44:14.804000Z","event_fingerprint":"b5be185b9be93b5c76cc5a1b66f37aae77c7a9a2fa9c4205e1a9137aef760994","payload":{"connection_id":"0f4979d6978d463e9660b042fdcf555f","event_at":"2026-07-27T04:44:14.804000Z","event_type":"best_bid_ask","frame_hash":"3a7426bf6a129fb38c66471e4e29607481f87eb48c7f942490c19f2da5d29ebd","frame_index":0,"kind":"data","monotonic_ns":229438014079208,"payload":{"asset_id":"60386828328910021732068595344565885737045900010034836345809386672230885527307","best_ask":"0.003","best_bid":"0.001","event_type":"best_bid_ask","market":"0xeb66215f2e9faa6449e30a02bab5b8ed7b79a38bf961f6b24d0073c9c2419250","spread":"0.002","timestamp":"1785127454804"},"payload_hash":"3e4232f9ac695f4f494d5f56d04c57945115f1ae2d06d29f706072aa612aa7bd","raw_frame":"{\"market\":\"0xeb66215f2e9faa6449e30a02bab5b8ed7b79a38bf961f6b24d0073c9c2419250\", \"asset_id\":\"60386828328910021732068595344565885737045900010034836345809386672230885527307\", \"best_bid\":\"0.001\", \"best_ask\":\"0.003\", \"spread\":\"0.002\", \"timestamp\":\"1785127454804\", \"event_type\":\"best_bid_ask\"}","received_at":"2026-07-27T04:44:14.751655Z","schema_version":"clob-market-ws.best_bid_ask.v1","sequence":null,"server_hash":null,"server_timestamp":"1785127454804","session_id":"e9443c7415a0419799bee9cfbb1a9e4d","source":"clob_market_ws"},"received_at":"2026-07-27T04:44:14.751655Z","record_id":"76d6b6d52a613105fd9452d8ec3b7eba48a16cd059213d253424883444dc8d5c","schema_fingerprint":"8488399f31b0337811b13b266be932db7062827c2470b78bd8e9e99bab51d17d","schema_version":"edge-lab-recorder.raw.v1","sequence":null,"source":"clob_market_ws"}
{"event_at":"2026-07-27T04:44:14.803000Z","event_fingerprint":"602aa337da4ba3104c9b084a72f85fdd98ed699998d8b8a8b20dfb7d78f8a0e0","payload":{"connection_id":"0f4979d6978d463e9660b042fdcf555f","event_at":"2026-07-27T04:44:14.803000Z","event_type":"price_change","frame_hash":"6eb25aac0366e25490dd6791065a58c9855da23ca09783728c93b4d95728022b","frame_index":0,"kind":"data","monotonic_ns":229438014481833,"payload":{"event_type":"price_change","market":"0xeb66215f2e9faa6449e30a02bab5b8ed7b79a38bf961f6b24d0073c9c2419250","price_changes":[{"asset_id":"60386828328910021732068595344565885737045900010034836345809386672230885527307","best_ask":"0.003","best_bid":"0.001","hash":"875cfb91c3edf1c5587b23aaf2176cd19e5efd3f","price":"0.003","side":"SELL","size":"275.12"},{"asset_id":"69697746896130839564035629862476347944307040470122503199396727085502753297492","best_ask":"0.999","best_bid":"0.997","hash":"d90f99b09a44059db2c2034a817b1ebef8a6f4b4","price":"0.997","side":"BUY","size":"275.12"}],"timestamp":"1785127454803"},"payload_hash":"c223e1219fbd8842913285e7d400f376f8055d7e01c7f69be8297ec72b384bf3","raw_frame":"{\"market\":\"0xeb66215f2e9faa6449e30a02bab5b8ed7b79a38bf961f6b24d0073c9c2419250\", \"price_changes\":[{\"asset_id\":\"60386828328910021732068595344565885737045900010034836345809386672230885527307\", \"price\":\"0.003\", \"size\":\"275.12\", \"side\":\"SELL\", \"hash\":\"875cfb91c3edf1c5587b23aaf2176cd19e5efd3f\", \"best_bid\":\"0.001\", \"best_ask\":\"0.003\"}, {\"asset_id\":\"69697746896130839564035629862476347944307040470122503199396727085502753297492\", \"price\":\"0.997\", \"size\":\"275.12\", \"side\":\"BUY\", \"hash\":\"d90f99b09a44059db2c2034a817b1ebef8a6f4b4\", \"best_bid\":\"0.997\", \"best_ask\":\"0.999\"}], \"timestamp\":\"1785127454803\", \"event_type\":\"price_change\"}","received_at":"2026-07-27T04:44:14.752057Z","schema_version":"clob-market-ws.price_change.v1","sequence":null,"server_hash":null,"server_timestamp":"1785127454803","session_id":"e9443c7415a0419799bee9cfbb1a9e4d","source":"clob_market_ws"},"received_at":"2026-07-27T04:44:14.752057Z","record_id":"f202f625304184fa2d22515570bbacf2fcd25d81658c1f6258bcb3fb983b66c8","schema_fingerprint":"4aa3821a28b0b7c2400bc59aba4bcc0a76e971dadd19610d3ad38c768e124dc7","schema_version":"edge-lab-recorder.raw.v1","sequence":null,"source":"clob_market_ws"}
{"event_at":null,"event_fingerprint":"79611f5021ab81a41ffa83cba99712ca11290fab3c9e53d9de4a45a643fadcba","payload":{"connection_id":"0f4979d6978d463e9660b042fdcf555f","detail":{"interval_seconds":10.0,"message":"PING"},"event_type":"heartbeat","kind":"lifecycle","monotonic_ns":229438023737416,"received_at":"2026-07-27T04:44:14.761306Z","schema_version":"edge-lab-recorder.lifecycle.v1","session_id":"e9443c7415a0419799bee9cfbb1a9e4d","source":"clob_market_ws"},"received_at":"2026-07-27T04:44:14.761306Z","record_id":"e9908b6f4d3c380c63e8b8fd92aa55d22b4e62f46ccba9d68fdb67a8bea8b050","schema_fingerprint":"cb8aa3aa4cb168a4b724fd9077bee6ecfb9bc586c57cfdf0ab89f00d82045e3c","schema_version":"edge-lab-recorder.raw.v1","sequence":null,"source":"clob_market_ws"}
{"event_at":"2026-07-27T04:44:14.825000Z","event_fingerprint":"807dd0f8d8362fbe13f7f1f01b064f1cc21211b419949ac148ec53d9d44caeb8","payload":{"connection_id":"0f4979d6978d463e9660b042fdcf555f","event_at":"2026-07-27T04:44:14.825000Z","event_type":"best_bid_ask","frame_hash":"c174043c0747bad657f87e9c170f6176a018c9571bba6b52617be17f4788e822","frame_index":0,"kind":"data","monotonic_ns":229438035219875,"payload":{"asset_id":"69697746896130839564035629862476347944307040470122503199396727085502753297492","best_ask":"0.999","best_bid":"0.996","event_type":"best_bid_ask","market":"0xeb66215f2e9faa6449e30a02bab5b8ed7b79a38bf961f6b24d0073c9c2419250","spread":"0.003","timestamp":"1785127454825"},"payload_hash":"17f688242409aabfd0838f0f502d51a0c830c3dbee2e7b8687d449871a1f3ba5","raw_frame":"{\"market\":\"0xeb66215f2e9faa6449e30a02bab5b8ed7b79a38bf961f6b24d0073c9c2419250\", \"asset_id\":\"69697746896130839564035629862476347944307040470122503199396727085502753297492\", \"best_bid\":\"0.996\", \"best_ask\":\"0.999\", \"spread\":\"0.003\", \"timestamp\":\"1785127454825\", \"event_type\":\"best_bid_ask\"}","received_at":"2026-07-27T04:44:14.772795Z","schema_version":"clob-market-ws.best_bid_ask.v1","sequence":null,"server_hash":null,"server_timestamp":"1785127454825","session_id":"e9443c7415a0419799bee9cfbb1a9e4d","source":"clob_market_ws"},"received_at":"2026-07-27T04:44:14.772795Z","record_id":"9e38c128f3a08c96e59124c7210a696c81637e055983641c5bd9ed91a39c5c71","schema_fingerprint":"8488399f31b0337811b13b266be932db7062827c2470b78bd8e9e99bab51d17d","schema_version":"edge-lab-recorder.raw.v1","sequence":null,"source":"clob_market_ws"}
{"event_at":"2026-07-27T04:44:14.825000Z","event_fingerprint":"384834ffa4d942d651d50c11b7d7b2aeee24f4ddd3e121f6a156932dab4f2263","payload":{"connection_id":"0f4979d6978d463e9660b042fdcf555f","event_at":"2026-07-27T04:44:14.825000Z","event_type":"best_bid_ask","frame_hash":"45b2f0dbfa8e867b40d9152eb102b07482a398af8952eb438d6fdd941821f59d","frame_index":0,"kind":"data","monotonic_ns":229438035722208,"payload":{"asset_id":"60386828328910021732068595344565885737045900010034836345809386672230885527307","best_ask":"0.004","best_bid":"0.001","event_type":"best_bid_ask","market":"0xeb66215f2e9faa6449e30a02bab5b8ed7b79a38bf961f6b24d0073c9c2419250","spread":"0.003","timestamp":"1785127454825"},"payload_hash":"63549446abe1fb6ad2f700666810c45df072d75d34ddcec63b2215db6661426c","raw_frame":"{\"market\":\"0xeb66215f2e9faa6449e30a02bab5b8ed7b79a38bf961f6b24d0073c9c2419250\", \"asset_id\":\"60386828328910021732068595344565885737045900010034836345809386672230885527307\", \"best_bid\":\"0.001\", \"best_ask\":\"0.004\", \"spread\":\"0.003\", \"timestamp\":\"1785127454825\", \"event_type\":\"best_bid_ask\"}","received_at":"2026-07-27T04:44:14.773299Z","schema_version":"clob-market-ws.best_bid_ask.v1","sequence":null,"server_hash":null,"server_timestamp":"1785127454825","session_id":"e9443c7415a0419799bee9cfbb1a9e4d","source":"clob_market_ws"},"received_at":"2026-07-27T04:44:14.773299Z","record_id":"db0ceb9be567ec4c748ac12fc5136f31bceb4056c82a4cbcf50cbfc092ae90b4","schema_fingerprint":"8488399f31b0337811b13b266be932db7062827c2470b78bd8e9e99bab51d17d","schema_version":"edge-lab-recorder.raw.v1","sequence":null,"source":"clob_market_ws"}
{"event_at":"2026-07-27T04:44:14.825000Z","event_fingerprint":"938483f6bd874f85741338380a3c704cbd9ac754a641e65008b51295b905638e","payload":{"connection_id":"0f4979d6978d463e9660b042fdcf555f","event_at":"2026-07-27T04:44:14.825000Z","event_type":"price_change","frame_hash":"30b2a3477124f801790b98d7b5b938600a3ec3e81ee5862427cf3e0813db5222","frame_index":0,"kind":"data","monotonic_ns":229438036587291,"payload":{"event_type":"price_change","market":"0xeb66215f2e9faa6449e30a02bab5b8ed7b79a38bf961f6b24d0073c9c2419250","price_changes":[{"asset_id":"60386828328910021732068595344565885737045900010034836345809386672230885527307","best_ask":"0.004","best_bid":"0.001","hash":"41868fd4ab0fd4f2f45b9ed5486dc83c47af49fb","price":"0.003","side":"SELL","size":"0"},{"asset_id":"69697746896130839564035629862476347944307040470122503199396727085502753297492","best_ask":"0.999","best_bid":"0.996","hash":"24497c9048c5ef97cd8887b941cac45a6db5fdec","price":"0.997","side":"BUY","size":"0"}],"timestamp":"1785127454825"},"payload_hash":"93577fadbee0ca0d9f5894853ac2892ed37e48992c25758483e1d6c710f23fb4","raw_frame":"{\"market\":\"0xeb66215f2e9faa6449e30a02bab5b8ed7b79a38bf961f6b24d0073c9c2419250\", \"price_changes\":[{\"asset_id\":\"60386828328910021732068595344565885737045900010034836345809386672230885527307\", \"price\":\"0.003\", \"size\":\"0\", \"side\":\"SELL\", \"hash\":\"41868fd4ab0fd4f2f45b9ed5486dc83c47af49fb\", \"best_bid\":\"0.001\", \"best_ask\":\"0.004\"}, {\"asset_id\":\"69697746896130839564035629862476347944307040470122503199396727085502753297492\", \"price\":\"0.997\", \"size\":\"0\", \"side\":\"BUY\", \"hash\":\"24497c9048c5ef97cd8887b941cac45a6db5fdec\", \"best_bid\":\"0.996\", \"best_ask\":\"0.999\"}], \"timestamp\":\"1785127454825\", \"event_type\":\"price_change\"}","received_at":"2026-07-27T04:44:14.774157Z","schema_version":"clob-market-ws.price_change.v1","sequence":null,"server_hash":null,"server_timestamp":"1785127454825","session_id":"e9443c7415a0419799bee9cfbb1a9e4d","source":"clob_market_ws"},"received_at":"2026-07-27T04:44:14.774157Z","record_id":"7963c5cf3ef084da41ad14d9c6db68f8bd823aa708070dc65f4757b1ae45e2ed","schema_fingerprint":"4aa3821a28b0b7c2400bc59aba4bcc0a76e971dadd19610d3ad38c768e124dc7","schema_version":"edge-lab-recorder.raw.v1","sequence":null,"source":"clob_market_ws"}
{"event_at":"2026-07-27T04:44:14.831000Z","event_fingerprint":"01f7c4413b88b0e00f8398b712c45de4c5302ec7256ffc83db6acff9a310adc6","payload":{"connection_id":"0f4979d6978d463e9660b042fdcf555f","event_at":"2026-07-27T04:44:14.831000Z","event_type":"price_change","frame_hash":"91b2b8fb6ca93e7a186acf082b27f3f851fe47d8b7a083e9a01730381f44e1a8","frame_index":0,"kind":"data","monotonic_ns":229438041392833,"payload":{"event_type":"price_change","market":"0xeb66215f2e9faa6449e30a02bab5b8ed7b79a38bf961f6b24d0073c9c2419250","price_changes":[{"asset_id":"69697746896130839564035629862476347944307040470122503199396727085502753297492","best_ask":"0.999","best_bid":"0.996","hash":"09d486ed17601bd76dbcdd69e6d3c4472d863971","price":"0.04","side":"BUY","size":"535"},{"asset_id":"60386828328910021732068595344565885737045900010034836345809386672230885527307","best_ask":"0.004","best_bid":"0.001","hash":"ae8dcf2fd7ac65371a12934a363f2f8098b3b227","price":"0.96","side":"SELL","size":"535"}],"timestamp":"1785127454831"},"payload_hash":"d8993fa9b66479d26e22d979d89ec4e52ac19fc31fa5d50bef6eabed6afaf2a6","raw_frame":"{\"market\":\"0xeb66215f2e9faa6449e30a02bab5b8ed7b79a38bf961f6b24d0073c9c2419250\", \"price_changes\":[{\"asset_id\":\"69697746896130839564035629862476347944307040470122503199396727085502753297492\", \"price\":\"0.04\", \"size\":\"535\", \"side\":\"BUY\", \"hash\":\"09d486ed17601bd76dbcdd69e6d3c4472d863971\", \"best_bid\":\"0.996\", \"best_ask\":\"0.999\"}, {\"asset_id\":\"60386828328910021732068595344565885737045900010034836345809386672230885527307\", \"price\":\"0.96\", \"size\":\"535\", \"side\":\"SELL\", \"hash\":\"ae8dcf2fd7ac65371a12934a363f2f8098b3b227\", \"best_bid\":\"0.001\", \"best_ask\":\"0.004\"}], \"timestamp\":\"1785127454831\", \"event_type\":\"price_change\"}","received_at":"2026-07-27T04:44:14.778967Z","schema_version":"clob-market-ws.price_change.v1","sequence":null,"server_hash":null,"server_timestamp":"1785127454831","session_id":"e9443c7415a0419799bee9cfbb1a9e4d","source":"clob_market_ws"},"received_at":"2026-07-27T04:44:14.778967Z","record_id":"847d1a774e5274f020cc3601c52b6e84904b1a28d62ec5981d4058cb19cb1991","schema_fingerprint":"4aa3821a28b0b7c2400bc59aba4bcc0a76e971dadd19610d3ad38c768e124dc7","schema_version":"edge-lab-recorder.raw.v1","sequence":null,"source":"clob_market_ws"}
{"event_at":"2026-07-27T04:44:14.856000Z","event_fingerprint":"33059489cee2270fd335802ba5f2da3fb7920198708c4e212b905822dd7ff5c0","payload":{"connection_id":"0f4979d6978d463e9660b042fdcf555f","event_at":"2026-07-27T04:44:14.856000Z","event_type":"price_change","frame_hash":"5fe7ff1db20b9c128e91a80af7840f9c12a0d185652383c1ed3fba5b899d21e2","frame_index":0,"kind":"data","monotonic_ns":229438066469041,"payload":{"event_type":"price_change","market":"0xeb66215f2e9faa6449e30a02bab5b8ed7b79a38bf961f6b24d0073c9c2419250","price_changes":[{"asset_id":"69697746896130839564035629862476347944307040470122503199396727085502753297492","best_ask":"0.999","best_bid":"0.996","hash":"e5c7ae2d0e798c2655b3dd681321a8248fff682c","price":"0.01","side":"BUY","size":"5320"},{"asset_id":"60386828328910021732068595344565885737045900010034836345809386672230885527307","best_ask":"0.004","best_bid":"0.001","hash":"4b591670cff29e72ebd167cf1b181c0aaca6f112","price":"0.99","side":"SELL","size":"5320"}],"timestamp":"1785127454856"},"payload_hash":"cbaed987c4cc7315a8823690417902809fed790e0a562ad3c58a4070838e9cfc","raw_frame":"{\"market\":\"0xeb66215f2e9faa6449e30a02bab5b8ed7b79a38bf961f6b24d0073c9c2419250\", \"price_changes\":[{\"asset_id\":\"69697746896130839564035629862476347944307040470122503199396727085502753297492\", \"price\":\"0.01\", \"size\":\"5320\", \"side\":\"BUY\", \"hash\":\"e5c7ae2d0e798c2655b3dd681321a8248fff682c\", \"best_bid\":\"0.996\", \"best_ask\":\"0.999\"}, {\"asset_id\":\"60386828328910021732068595344565885737045900010034836345809386672230885527307\", \"price\":\"0.99\", \"size\":\"5320\", \"side\":\"SELL\", \"hash\":\"4b591670cff29e72ebd167cf1b181c0aaca6f112\", \"best_bid\":\"0.001\", \"best_ask\":\"0.004\"}], \"timestamp\":\"1785127454856\", \"event_type\":\"price_change\"}","received_at":"2026-07-27T04:44:14.804035Z","schema_version":"clob-market-ws.price_change.v1","sequence":null,"server_hash":null,"server_timestamp":"1785127454856","session_id":"e9443c7415a0419799bee9cfbb1a9e4d","source":"clob_market_ws"},"received_at":"2026-07-27T04:44:14.804035Z","record_id":"d1ee5bc0602c7603b68aaadf9849418cfceb4a484b46f09ee9e97a1fa98040cb","schema_fingerprint":"4aa3821a28b0b7c2400bc59aba4bcc0a76e971dadd19610d3ad38c768e124dc7","schema_version":"edge-lab-recorder.raw.v1","sequence":null,"source":"clob_market_ws"}
{"event_at":"2026-07-27T04:44:14.864000Z","event_fingerprint":"aad6399668935b3b8dfe1bc2d099bc73a77481aebdf35e64c40d9d21e9c8cd1f","payload":{"connection_id":"0f4979d6978d463e9660b042fdcf555f","event_at":"2026-07-27T04:44:14.864000Z","event_type":"best_bid_ask","frame_hash":"a5a501dab6c96df1eeddf0ac52acf0f6d8fb145104700961acd510cf96cd4fb3","frame_index":0,"kind":"data","monotonic_ns":229438074334166,"payload":{"asset_id":"69697746896130839564035629862476347944307040470122503199396727085502753297492","best_ask":"0.999","best_bid":"0.997","event_type":"best_bid_ask","market":"0xeb66215f2e9faa6449e30a02bab5b8ed7b79a38bf961f6b24d0073c9c2419250","spread":"0.002","timestamp":"1785127454864"},"payload_hash":"7080bb74484a159986d714e94ef8e666115b6a893e102daab182a48e7b968fac","raw_frame":"{\"market\":\"0xeb66215f2e9faa6449e30a02bab5b8ed7b79a38bf961f6b24d0073c9c2419250\", \"asset_id\":\"69697746896130839564035629862476347944307040470122503199396727085502753297492\", \"best_bid\":\"0.997\", \"best_ask\":\"0.999\", \"spread\":\"0.002\", \"timestamp\":\"1785127454864\", \"event_type\":\"best_bid_ask\"}","received_at":"2026-07-27T04:44:14.811900Z","schema_version":"clob-market-ws.best_bid_ask.v1","sequence":null,"server_hash":null,"server_timestamp":"1785127454864","session_id":"e9443c7415a0419799bee9cfbb1a9e4d","source":"clob_market_ws"},"received_at":"2026-07-27T04:44:14.811900Z","record_id":"caf0e701b13f125f72f9b094fc1c52538b80420717a91d0d7ebfc9dfa423bbcd","schema_fingerprint":"8488399f31b0337811b13b266be932db7062827c2470b78bd8e9e99bab51d17d","schema_version":"edge-lab-recorder.raw.v1","sequence":null,"source":"clob_market_ws"}
{"event_at":"2026-07-27T04:44:14.864000Z","event_fingerprint":"b96e0aa0db5575f0c97506a40a27e2eeb3f8b2b4f9bdb02fa0113b3a1597e451","payload":{"connection_id":"0f4979d6978d463e9660b042fdcf555f","event_at":"2026-07-27T04:44:14.864000Z","event_type":"best_bid_ask","frame_hash":"f48fff0d5e93ead86bd316efa1c7a8f53c13cae237bc9046ddaff2fc54320756","frame_index":0,"kind":"data","monotonic_ns":229438075542333,"payload":{"asset_id":"60386828328910021732068595344565885737045900010034836345809386672230885527307","best_ask":"0.003","best_bid":"0.001","event_type":"best_bid_ask","market":"0xeb66215f2e9faa6449e30a02bab5b8ed7b79a38bf961f6b24d0073c9c2419250","spread":"0.002","timestamp":"1785127454864"},"payload_hash":"cad64b4b6db45fc9afc234a05c3aed989341cbcd8b2a1ccc1128eb363879d68d","raw_frame":"{\"market\":\"0xeb66215f2e9faa6449e30a02bab5b8ed7b79a38bf961f6b24d0073c9c2419250\", \"asset_id\":\"60386828328910021732068595344565885737045900010034836345809386672230885527307\", \"best_bid\":\"0.001\", \"best_ask\":\"0.003\", \"spread\":\"0.002\", \"timestamp\":\"1785127454864\", \"event_type\":\"best_bid_ask\"}","received_at":"2026-07-27T04:44:14.813113Z","schema_version":"clob-market-ws.best_bid_ask.v1","sequence":null,"server_hash":null,"server_timestamp":"1785127454864","session_id":"e9443c7415a0419799bee9cfbb1a9e4d","source":"clob_market_ws"},"received_at":"2026-07-27T04:44:14.813113Z","record_id":"1e5dcf00d9c18126c8b0a1a306dee9024b39847b53f28bbc1afd5f7d9a9d77ec","schema_fingerprint":"8488399f31b0337811b13b266be932db7062827c2470b78bd8e9e99bab51d17d","schema_version":"edge-lab-recorder.raw.v1","sequence":null,"source":"clob_market_ws"}
{"event_at":"2026-07-27T04:44:14.864000Z","event_fingerprint":"bae9ff2481372eea88da81bea8e3f2be34d9975c3f1b47781687f5407c153e01","payload":{"connection_id":"0f4979d6978d463e9660b042fdcf555f","event_at":"2026-07-27T04:44:14.864000Z","event_type":"price_change","frame_hash":"c887820d92ee8616e7a67c16101b941b8683ab85580aa937f00aa9e10cf53cc7","frame_index":0,"kind":"data","monotonic_ns":229438076644708,"payload":{"event_type":"price_change","market":"0xeb66215f2e9faa6449e30a02bab5b8ed7b79a38bf961f6b24d0073c9c2419250","price_changes":[{"asset_id":"60386828328910021732068595344565885737045900010034836345809386672230885527307","best_ask":"0.003","best_bid":"0.001","hash":"74915a1cff11c50e80f14afcdb1534991fadd08a","price":"0.003","side":"SELL","size":"275.12"},{"asset_id":"69697746896130839564035629862476347944307040470122503199396727085502753297492","best_ask":"0.999","best_bid":"0.997","hash":"df4b3c727c9be4845fe83848d9838eea872c24f7","price":"0.997","side":"BUY","size":"275.12"}],"timestamp":"1785127454864"},"payload_hash":"65d739de1f1f4536c856618a40ed7b4c460538fccc16d8629a0efb0be4df7369","raw_frame":"{\"market\":\"0xeb66215f2e9faa6449e30a02bab5b8ed7b79a38bf961f6b24d0073c9c2419250\", \"price_changes\":[{\"asset_id\":\"60386828328910021732068595344565885737045900010034836345809386672230885527307\", \"price\":\"0.003\", \"size\":\"275.12\", \"side\":\"SELL\", \"hash\":\"74915a1cff11c50e80f14afcdb1534991fadd08a\", \"best_bid\":\"0.001\", \"best_ask\":\"0.003\"}, {\"asset_id\":\"69697746896130839564035629862476347944307040470122503199396727085502753297492\", \"price\":\"0.997\", \"size\":\"275.12\", \"side\":\"BUY\", \"hash\":\"df4b3c727c9be4845fe83848d9838eea872c24f7\", \"best_bid\":\"0.997\", \"best_ask\":\"0.999\"}], \"timestamp\":\"1785127454864\", \"event_type\":\"price_change\"}","received_at":"2026-07-27T04:44:14.814216Z","schema_version":"clob-market-ws.price_change.v1","sequence":null,"server_hash":null,"server_timestamp":"1785127454864","session_id":"e9443c7415a0419799bee9cfbb1a9e4d","source":"clob_market_ws"},"received_at":"2026-07-27T04:44:14.814216Z","record_id":"96dd3c2ddbf1bd839ae388ab8126529911236ecf383ae90a73b5546c3d3ae9ec","schema_fingerprint":"4aa3821a28b0b7c2400bc59aba4bcc0a76e971dadd19610d3ad38c768e124dc7","schema_version":"edge-lab-recorder.raw.v1","sequence":null,"source":"clob_market_ws"}
{"event_at":"2026-07-27T04:44:14.878000Z","event_fingerprint":"e3de2af993621da85e4686f8cabca6434bc47904523f52cf82b1ce360f761378","payload":{"connection_id":"0f4979d6978d463e9660b042fdcf555f","event_at":"2026-07-27T04:44:14.878000Z","event_type":"price_change","frame_hash":"9cafc4efc04ee5b5af2443453d2fc64c7e140bc8621337be82d700fbe86c254b","frame_index":0,"kind":"data","monotonic_ns":229438088911083,"payload":{"event_type":"price_change","market":"0xeb66215f2e9faa6449e30a02bab5b8ed7b79a38bf961f6b24d0073c9c2419250","price_changes":[{"asset_id":"69697746896130839564035629862476347944307040470122503199396727085502753297492","best_ask":"0.999","best_bid":"0.997","hash":"88be1bc9d76195d97c4dee3d09c7400fb5df3d57","price":"0.01","side":"BUY","size":"5315"},{"asset_id":"60386828328910021732068595344565885737045900010034836345809386672230885527307","best_ask":"0.003","best_bid":"0.001","hash":"dd30ecc92fe2ac1743c196393aea349ecc2022c6","price":"0.99","side":"SELL","size":"5315"}],"timestamp":"1785127454878"},"payload_hash":"af863ff27fabd5d58fbd3cc2814bb6a5aeef789d7182f4a3da9da11aebcfffc5","raw_frame":"{\"market\":\"0xeb66215f2e9faa6449e30a02bab5b8ed7b79a38bf961f6b24d0073c9c2419250\", \"price_changes\":[{\"asset_id\":\"69697746896130839564035629862476347944307040470122503199396727085502753297492\", \"price\":\"0.01\", \"size\":\"5315\", \"side\":\"BUY\", \"hash\":\"88be1bc9d76195d97c4dee3d09c7400fb5df3d57\", \"best_bid\":\"0.997\", \"best_ask\":\"0.999\"}, {\"asset_id\":\"60386828328910021732068595344565885737045900010034836345809386672230885527307\", \"price\":\"0.99\", \"size\":\"5315\", \"side\":\"SELL\", \"hash\":\"dd30ecc92fe2ac1743c196393aea349ecc2022c6\", \"best_bid\":\"0.001\", \"best_ask\":\"0.003\"}], \"timestamp\":\"1785127454878\", \"event_type\":\"price_change\"}","received_at":"2026-07-27T04:44:14.826472Z","schema_version":"clob-market-ws.price_change.v1","sequence":null,"server_hash":null,"server_timestamp":"1785127454878","session_id":"e9443c7415a0419799bee9cfbb1a9e4d","source":"clob_market_ws"},"received_at":"2026-07-27T04:44:14.826472Z","record_id":"c1b77dabb35644fdd8f8ea6534540dae6b86d78b434b2945689589d63d0f57de","schema_fingerprint":"4aa3821a28b0b7c2400bc59aba4bcc0a76e971dadd19610d3ad38c768e124dc7","schema_version":"edge-lab-recorder.raw.v1","sequence":null,"source":"clob_market_ws"}
{"event_at":"2026-07-27T04:44:14.882000Z","event_fingerprint":"e8d6bfdc01e155315bed7b9a23885b8dd72883c2079a4c3a9beaa93762cf29d9","payload":{"connection_id":"0f4979d6978d463e9660b042fdcf555f","event_at":"2026-07-27T04:44:14.882000Z","event_type":"best_bid_ask","frame_hash":"ef1075fd260755a75f88c8d71c67be22908094e9f0bf7b1b5a6ea734f12537b7","frame_index":0,"kind":"data","monotonic_ns":229438094163416,"payload":{"asset_id":"69697746896130839564035629862476347944307040470122503199396727085502753297492","best_ask":"0.999","best_bid":"0.996","event_type":"best_bid_ask","market":"0xeb66215f2e9faa6449e30a02bab5b8ed7b79a38bf961f6b24d0073c9c2419250","spread":"0.003","timestamp":"1785127454882"},"payload_hash":"98b0a84700d6f1c6afa4169c2077423b644018440303920348563c004d0702f3","raw_frame":"{\"market\":\"0xeb66215f2e9faa6449e30a02bab5b8ed7b79a38bf961f6b24d0073c9c2419250\", \"asset_id\":\"69697746896130839564035629862476347944307040470122503199396727085502753297492\", \"best_bid\":\"0.996\", \"best_ask\":\"0.999\", \"spread\":\"0.003\", \"timestamp\":\"1785127454882\", \"event_type\":\"best_bid_ask\"}","received_at":"2026-07-27T04:44:14.831734Z","schema_version":"clob-market-ws.best_bid_ask.v1","sequence":null,"server_hash":null,"server_timestamp":"1785127454882","session_id":"e9443c7415a0419799bee9cfbb1a9e4d","source":"clob_market_ws"},"received_at":"2026-07-27T04:44:14.831734Z","record_id":"84d6be75208262d528b1248593e2f7d4e44f86e89915308f6e494777f2024280","schema_fingerprint":"8488399f31b0337811b13b266be932db7062827c2470b78bd8e9e99bab51d17d","schema_version":"edge-lab-recorder.raw.v1","sequence":null,"source":"clob_market_ws"}
{"event_at":"2026-07-27T04:44:14.882000Z","event_fingerprint":"38e4aa614ce1d547d3eeb23f75298acf4785a50d706ad23ae3807d5dbb2a4df1","payload":{"connection_id":"0f4979d6978d463e9660b042fdcf555f","event_at":"2026-07-27T04:44:14.882000Z","event_type":"best_bid_ask","frame_hash":"4173fb47319cb0d5ed7f7d4b6e2f70580160a1e26f68514267e6f86a90a707dc","frame_index":0,"kind":"data","monotonic_ns":229438095284708,"payload":{"asset_id":"60386828328910021732068595344565885737045900010034836345809386672230885527307","best_ask":"0.004","best_bid":"0.001","event_type":"best_bid_ask","market":"0xeb66215f2e9faa6449e30a02bab5b8ed7b79a38bf961f6b24d0073c9c2419250","spread":"0.003","timestamp":"1785127454882"},"payload_hash":"59ee8629ec35ee43740e79f36ab9daeea69deb105584a73bf14e2177dd4ec5b5","raw_frame":"{\"market\":\"0xeb66215f2e9faa6449e30a02bab5b8ed7b79a38bf961f6b24d0073c9c2419250\", \"asset_id\":\"60386828328910021732068595344565885737045900010034836345809386672230885527307\", \"best_bid\":\"0.001\", \"best_ask\":\"0.004\", \"spread\":\"0.003\", \"timestamp\":\"1785127454882\", \"event_type\":\"best_bid_ask\"}","received_at":"2026-07-27T04:44:14.832857Z","schema_version":"clob-market-ws.best_bid_ask.v1","sequence":null,"server_hash":null,"server_timestamp":"1785127454882","session_id":"e9443c7415a0419799bee9cfbb1a9e4d","source":"clob_market_ws"},"received_at":"2026-07-27T04:44:14.832857Z","record_id":"ff72156e60fd5aea4aff15870eaff3ed6dd5866518284c8b30076bcd44bcea0c","schema_fingerprint":"8488399f31b0337811b13b266be932db7062827c2470b78bd8e9e99bab51d17d","schema_version":"edge-lab-recorder.raw.v1","sequence":null,"source":"clob_market_ws"}
{"event_at":"2026-07-27T04:44:14.882000Z","event_fingerprint":"4387e30f7ddddd11cb7c966749898dc0afe11a51c9c77fd20c8582a3c95e842d","payload":{"connection_id":"0f4979d6978d463e9660b042fdcf555f","event_at":"2026-07-27T04:44:14.882000Z","event_type":"price_change","frame_hash":"27b24932de0fc2577bf7ed8fe8850d378a7943ba4ef4e12eb2124263d8897e32","frame_index":0,"kind":"data","monotonic_ns":229438096321375,"payload":{"event_type":"price_change","market":"0xeb66215f2e9faa6449e30a02bab5b8ed7b79a38bf961f6b24d0073c9c2419250","price_changes":[{"asset_id":"60386828328910021732068595344565885737045900010034836345809386672230885527307","best_ask":"0.004","best_bid":"0.001","hash":"a4e02b9b17022af14d3223c1128cbb3f0b6c1a97","price":"0.003","side":"SELL","size":"0"},{"asset_id":"69697746896130839564035629862476347944307040470122503199396727085502753297492","best_ask":"0.999","best_bid":"0.996","hash":"a82b69870b46497e1b20bcdbb6d674cef1c6fcac","price":"0.997","side":"BUY","size":"0"}],"timestamp":"1785127454882"},"payload_hash":"5012e11e72692b352cb3f76b0af93246febd330a96c4a3dc2ff4fa513415dc48","raw_frame":"{\"market\":\"0xeb66215f2e9faa6449e30a02bab5b8ed7b79a38bf961f6b24d0073c9c2419250\", \"price_changes\":[{\"asset_id\":\"60386828328910021732068595344565885737045900010034836345809386672230885527307\", \"price\":\"0.003\", \"size\":\"0\", \"side\":\"SELL\", \"hash\":\"a4e02b9b17022af14d3223c1128cbb3f0b6c1a97\", \"best_bid\":\"0.001\", \"best_ask\":\"0.004\"}, {\"asset_id\":\"69697746896130839564035629862476347944307040470122503199396727085502753297492\", \"price\":\"0.997\", \"size\":\"0\", \"side\":\"BUY\", \"hash\":\"a82b69870b46497e1b20bcdbb6d674cef1c6fcac\", \"best_bid\":\"0.996\", \"best_ask\":\"0.999\"}], \"timestamp\":\"1785127454882\", \"event_type\":\"price_change\"}","received_at":"2026-07-27T04:44:14.833892Z","schema_version":"clob-market-ws.price_change.v1","sequence":null,"server_hash":null,"server_timestamp":"1785127454882","session_id":"e9443c7415a0419799bee9cfbb1a9e4d","source":"clob_market_ws"},"received_at":"2026-07-27T04:44:14.833892Z","record_id":"024dba6c56d37262da4e142746c50f0d419f6b5012b75f8f4ccc059ea24edbdd","schema_fingerprint":"4aa3821a28b0b7c2400bc59aba4bcc0a76e971dadd19610d3ad38c768e124dc7","schema_version":"edge-lab-recorder.raw.v1","sequence":null,"source":"clob_market_ws"}
{"event_at":"2026-07-27T04:44:14.892000Z","event_fingerprint":"f724e7071a6021cd1a5050056beb9b160b70a80cb958a9a92628de1933146a5e","payload":{"connection_id":"0f4979d6978d463e9660b042fdcf555f","event_at":"2026-07-27T04:44:14.892000Z","event_type":"price_change","frame_hash":"47105d0b403266c8bde664e79457b84f498362aea44ce19c8372a43066d78d84","frame_index":0,"kind":"data","monotonic_ns":229438101673208,"payload":{"event_type":"price_change","market":"0xeb66215f2e9faa6449e30a02bab5b8ed7b79a38bf961f6b24d0073c9c2419250","price_changes":[{"asset_id":"69697746896130839564035629862476347944307040470122503199396727085502753297492","best_ask":"0.999","best_bid":"0.996","hash":"366a3e7fd03de697bcd2b0ede3740a33815db21d","price":"0.04","side":"BUY","size":"530"},{"asset_id":"60386828328910021732068595344565885737045900010034836345809386672230885527307","best_ask":"0.004","best_bid":"0.001","hash":"6d71e5ecacf1e685e5b1eedea4cd1c95221fda0e","price":"0.96","side":"SELL","size":"530"}],"timestamp":"1785127454892"},"payload_hash":"3b7334b4d99e5c2e7bb863801ef17a3a66ab93fb8b2ab0d5f6a56a3d36c30ccf","raw_frame":"{\"market\":\"0xeb66215f2e9faa6449e30a02bab5b8ed7b79a38bf961f6b24d0073c9c2419250\", \"price_changes\":[{\"asset_id\":\"69697746896130839564035629862476347944307040470122503199396727085502753297492\", \"price\":\"0.04\", \"size\":\"530\", \"side\":\"BUY\", \"hash\":\"366a3e7fd03de697bcd2b0ede3740a33815db21d\", \"best_bid\":\"0.996\", \"best_ask\":\"0.999\"}, {\"asset_id\":\"60386828328910021732068595344565885737045900010034836345809386672230885527307\", \"price\":\"0.96\", \"size\":\"530\", \"side\":\"SELL\", \"hash\":\"6d71e5ecacf1e685e5b1eedea4cd1c95221fda0e\", \"best_bid\":\"0.001\", \"best_ask\":\"0.004\"}], \"timestamp\":\"1785127454892\", \"event_type\":\"price_change\"}","received_at":"2026-07-27T04:44:14.839242Z","schema_version":"clob-market-ws.price_change.v1","sequence":null,"server_hash":null,"server_timestamp":"1785127454892","session_id":"e9443c7415a0419799bee9cfbb1a9e4d","source":"clob_market_ws"},"received_at":"2026-07-27T04:44:14.839242Z","record_id":"3c0e2dd488c9aa594d7f563412e5f259212ae8983c2806ec416d122bb4c16cf0","schema_fingerprint":"4aa3821a28b0b7c2400bc59aba4bcc0a76e971dadd19610d3ad38c768e124dc7","schema_version":"edge-lab-recorder.raw.v1","sequence":null,"source":"clob_market_ws"}
{"event_at":"2026-07-27T04:44:14.919000Z","event_fingerprint":"de7a7b56b63c6bf73bbfcb31648696cfff29ae1cab0cbff0fbb5058e532178cd","payload":{"connection_id":"0f4979d6978d463e9660b042fdcf555f","event_at":"2026-07-27T04:44:14.919000Z","event_type":"best_bid_ask","frame_hash":"8a38013b28e9e90beaf5f8d1145726842c75c852c6a1809b1118edc2d213e6e1","frame_index":0,"kind":"data","monotonic_ns":229438129506750,"payload":{"asset_id":"69697746896130839564035629862476347944307040470122503199396727085502753297492","best_ask":"0.999","best_bid":"0.997","event_type":"best_bid_ask","market":"0xeb66215f2e9faa6449e30a02bab5b8ed7b79a38bf961f6b24d0073c9c2419250","spread":"0.002","timestamp":"1785127454919"},"payload_hash":"66540f2a607e4dc70166470a9c5b43766cee882d80a3056a0ffac461be3ebb6b","raw_frame":"{\"market\":\"0xeb66215f2e9faa6449e30a02bab5b8ed7b79a38bf961f6b24d0073c9c2419250\", \"asset_id\":\"69697746896130839564035629862476347944307040470122503199396727085502753297492\", \"best_bid\":\"0.997\", \"best_ask\":\"0.999\", \"spread\":\"0.002\", \"timestamp\":\"1785127454919\", \"event_type\":\"best_bid_ask\"}","received_at":"2026-07-27T04:44:14.867076Z","schema_version":"clob-market-ws.best_bid_ask.v1","sequence":null,"server_hash":null,"server_timestamp":"1785127454919","session_id":"e9443c7415a0419799bee9cfbb1a9e4d","source":"clob_market_ws"},"received_at":"2026-07-27T04:44:14.867076Z","record_id":"c0953c8feda8002a6ba724ce2c182483e157d199e10dad68822d962275026e60","schema_fingerprint":"8488399f31b0337811b13b266be932db7062827c2470b78bd8e9e99bab51d17d","schema_version":"edge-lab-recorder.raw.v1","sequence":null,"source":"clob_market_ws"}
{"event_at":"2026-07-27T04:44:14.919000Z","event_fingerprint":"0aae2f7ee0fa9696685ff1e882302a43fa9dbf26e9dbbff830a723402b53dac5","payload":{"connection_id":"0f4979d6978d463e9660b042fdcf555f","event_at":"2026-07-27T04:44:14.919000Z","event_type":"best_bid_ask","frame_hash":"f46d8c85c89dfb185217dff7853020257dc77f54fc9e0b725f948901807c66c2","frame_index":0,"kind":"data","monotonic_ns":229438130653666,"payload":{"asset_id":"60386828328910021732068595344565885737045900010034836345809386672230885527307","best_ask":"0.003","best_bid":"0.001","event_type":"best_bid_ask","market":"0xeb66215f2e9faa6449e30a02bab5b8ed7b79a38bf961f6b24d0073c9c2419250","spread":"0.002","timestamp":"1785127454919"},"payload_hash":"3f829bec096799f8bc61bcce3bb3ef7c6a7c39af77db64a05080b15bac5d5775","raw_frame":"{\"market\":\"0xeb66215f2e9faa6449e30a02bab5b8ed7b79a38bf961f6b24d0073c9c2419250\", \"asset_id\":\"60386828328910021732068595344565885737045900010034836345809386672230885527307\", \"best_bid\":\"0.001\", \"best_ask\":\"0.003\", \"spread\":\"0.002\", \"timestamp\":\"1785127454919\", \"event_type\":\"best_bid_ask\"}","received_at":"2026-07-27T04:44:14.868226Z","schema_version":"clob-market-ws.best_bid_ask.v1","sequence":null,"server_hash":null,"server_timestamp":"1785127454919","session_id":"e9443c7415a0419799bee9cfbb1a9e4d","source":"clob_market_ws"},"received_at":"2026-07-27T04:44:14.868226Z","record_id":"09b2f7d37519cef3c0b6480c0531d4606661eec5135492b9bad0cb23d7edad52","schema_fingerprint":"8488399f31b0337811b13b266be932db7062827c2470b78bd8e9e99bab51d17d","schema_version":"edge-lab-recorder.raw.v1","sequence":null,"source":"clob_market_ws"}
{"event_at":"2026-07-27T04:44:14.919000Z","event_fingerprint":"40c49a4da7e760bbcb0aefbd433473aaa592c9dcb525db7c8d9e1e344d48cb13","payload":{"connection_id":"0f4979d6978d463e9660b042fdcf555f","event_at":"2026-07-27T04:44:14.919000Z","event_type":"price_change","frame_hash":"c03e27fd8d5eb414db7697785a8c01e52be2121e4f4567c62dc092a0af7fbb1f","frame_index":0,"kind":"data","monotonic_ns":229438131703833,"payload":{"event_type":"price_change","market":"0xeb66215f2e9faa6449e30a02bab5b8ed7b79a38bf961f6b24d0073c9c2419250","price_changes":[{"asset_id":"60386828328910021732068595344565885737045900010034836345809386672230885527307","best_ask":"0.003","best_bid":"0.001","hash":"a30e39bd537eac89a356ae73f27a6a3c4ef1b916","price":"0.003","side":"SELL","size":"275.12"},{"asset_id":"69697746896130839564035629862476347944307040470122503199396727085502753297492","best_ask":"0.999","best_bid":"0.997","hash":"d4ff789b9722115782adcdeebcff69c7b44688c4","price":"0.997","side":"BUY","size":"275.12"}],"timestamp":"1785127454919"},"payload_hash":"19eb58184c379d5119b8f30e04da4a8f7976743d5971c1faaf727e8a72422437","raw_frame":"{\"market\":\"0xeb66215f2e9faa6449e30a02bab5b8ed7b79a38bf961f6b24d0073c9c2419250\", \"price_changes\":[{\"asset_id\":\"60386828328910021732068595344565885737045900010034836345809386672230885527307\", \"price\":\"0.003\", \"size\":\"275.12\", \"side\":\"SELL\", \"hash\":\"a30e39bd537eac89a356ae73f27a6a3c4ef1b916\", \"best_bid\":\"0.001\", \"best_ask\":\"0.003\"}, {\"asset_id\":\"69697746896130839564035629862476347944307040470122503199396727085502753297492\", \"price\":\"0.997\", \"size\":\"275.12\", \"side\":\"BUY\", \"hash\":\"d4ff789b9722115782adcdeebcff69c7b44688c4\", \"best_bid\":\"0.997\", \"best_ask\":\"0.999\"}], \"timestamp\":\"1785127454919\", \"event_type\":\"price_change\"}","received_at":"2026-07-27T04:44:14.869274Z","schema_version":"clob-market-ws.price_change.v1","sequence":null,"server_hash":null,"server_timestamp":"1785127454919","session_id":"e9443c7415a0419799bee9cfbb1a9e4d","source":"clob_market_ws"},"received_at":"2026-07-27T04:44:14.869274Z","record_id":"483a66770e36fee21282fe1d982929fa5c0d62b10b0757564bb206b1406a41f4","schema_fingerprint":"4aa3821a28b0b7c2400bc59aba4bcc0a76e971dadd19610d3ad38c768e124dc7","schema_version":"edge-lab-recorder.raw.v1","sequence":null,"source":"clob_market_ws"}
{"event_at":"2026-07-27T04:44:14.934000Z","event_fingerprint":"2509f472eaf8f8f1f4e09ea2feb76009f9abc790ea14056d41d6ec71689e7ea2","payload":{"connection_id":"0f4979d6978d463e9660b042fdcf555f","event_at":"2026-07-27T04:44:14.934000Z","event_type":"best_bid_ask","frame_hash":"b92abf73963b31f278e1b902771bb33ee6f5ddbc0fa57442671ee060fb78b363","frame_index":0,"kind":"data","monotonic_ns":229438144407416,"payload":{"asset_id":"69697746896130839564035629862476347944307040470122503199396727085502753297492","best_ask":"0.999","best_bid":"0.996","event_type":"best_bid_ask","market":"0xeb66215f2e9faa6449e30a02bab5b8ed7b79a38bf961f6b24d0073c9c2419250","spread":"0.003","timestamp":"1785127454934"},"payload_hash":"18856f5ec4ff50d8cbb957e4112215a7c719ac0c23cf6f4d30ff8ea35b253cd6","raw_frame":"{\"market\":\"0xeb66215f2e9faa6449e30a02bab5b8ed7b79a38bf961f6b24d0073c9c2419250\", \"asset_id\":\"69697746896130839564035629862476347944307040470122503199396727085502753297492\", \"best_bid\":\"0.996\", \"best_ask\":\"0.999\", \"spread\":\"0.003\", \"timestamp\":\"1785127454934\", \"event_type\":\"best_bid_ask\"}","received_at":"2026-07-27T04:44:14.881978Z","schema_version":"clob-market-ws.best_bid_ask.v1","sequence":null,"server_hash":null,"server_timestamp":"1785127454934","session_id":"e9443c7415a0419799bee9cfbb1a9e4d","source":"clob_market_ws"},"received_at":"2026-07-27T04:44:14.881978Z","record_id":"857cbad6d97a90c484b9d6101e18d77ae05f9131872eaff31c3d8a117ce8913d","schema_fingerprint":"8488399f31b0337811b13b266be932db7062827c2470b78bd8e9e99bab51d17d","schema_version":"edge-lab-recorder.raw.v1","sequence":null,"source":"clob_market_ws"}
{"event_at":"2026-07-27T04:44:14.934000Z","event_fingerprint":"61047e1936e65b87765d6ff70a63c362e85c19d6285989471e082dd2f4471063","payload":{"connection_id":"0f4979d6978d463e9660b042fdcf555f","event_at":"2026-07-27T04:44:14.934000Z","event_type":"best_bid_ask","frame_hash":"a0399521ac2c7cfd1eeed6e8bbea24d0a5ff69c9c45c26c401cdae9e08742c43","frame_index":0,"kind":"data","monotonic_ns":229438145570625,"payload":{"asset_id":"60386828328910021732068595344565885737045900010034836345809386672230885527307","best_ask":"0.004","best_bid":"0.001","event_type":"best_bid_ask","market":"0xeb66215f2e9faa6449e30a02bab5b8ed7b79a38bf961f6b24d0073c9c2419250","spread":"0.003","timestamp":"1785127454934"},"payload_hash":"1c8e23d39b7dc43e95a8c485a17530a533c311785e5e352f424dd5c4acb6b421","raw_frame":"{\"market\":\"0xeb66215f2e9faa6449e30a02bab5b8ed7b79a38bf961f6b24d0073c9c2419250\", \"asset_id\":\"60386828328910021732068595344565885737045900010034836345809386672230885527307\", \"best_bid\":\"0.001\", \"best_ask\":\"0.004\", \"spread\":\"0.003\", \"timestamp\":\"1785127454934\", \"event_type\":\"best_bid_ask\"}","received_at":"2026-07-27T04:44:14.883143Z","schema_version":"clob-market-ws.best_bid_ask.v1","sequence":null,"server_hash":null,"server_timestamp":"1785127454934","session_id":"e9443c7415a0419799bee9cfbb1a9e4d","source":"clob_market_ws"},"received_at":"2026-07-27T04:44:14.883143Z","record_id":"984501e2ca643c2abbc16b0acb2087ee83f8d7d9a8665e4050fc7be7413cfda6","schema_fingerprint":"8488399f31b0337811b13b266be932db7062827c2470b78bd8e9e99bab51d17d","schema_version":"edge-lab-recorder.raw.v1","sequence":null,"source":"clob_market_ws"}
{"event_at":"2026-07-27T04:44:14.934000Z","event_fingerprint":"91c0dcd27811382d96c79108b8b747ad7a131f753901a90e970f00fd2e21c20b","payload":{"connection_id":"0f4979d6978d463e9660b042fdcf555f","event_at":"2026-07-27T04:44:14.934000Z","event_type":"price_change","frame_hash":"f07f244e1f2ee62589809b5ba0a309d24592847977bc9f1ef577da2e8f662a2c","frame_index":0,"kind":"data","monotonic_ns":229438146694833,"payload":{"event_type":"price_change","market":"0xeb66215f2e9faa6449e30a02bab5b8ed7b79a38bf961f6b24d0073c9c2419250","price_changes":[{"asset_id":"60386828328910021732068595344565885737045900010034836345809386672230885527307","best_ask":"0.004","best_bid":"0.001","hash":"a9cf5f80e18e7f1a58911b15e8ef0f3846d27080","price":"0.003","side":"SELL","size":"0"},{"asset_id":"69697746896130839564035629862476347944307040470122503199396727085502753297492","best_ask":"0.999","best_bid":"0.996","hash":"717d803bc36ec61acff2c2358d4fc1f6e01ee30b","price":"0.997","side":"BUY","size":"0"}],"timestamp":"1785127454934"},"payload_hash":"71a6e7f3c27689fecc05ff0c1943d341e72172546cc942de8c072054993fee89","raw_frame":"{\"market\":\"0xeb66215f2e9faa6449e30a02bab5b8ed7b79a38bf961f6b24d0073c9c2419250\", \"price_changes\":[{\"asset_id\":\"60386828328910021732068595344565885737045900010034836345809386672230885527307\", \"price\":\"0.003\", \"size\":\"0\", \"side\":\"SELL\", \"hash\":\"a9cf5f80e18e7f1a58911b15e8ef0f3846d27080\", \"best_bid\":\"0.001\", \"best_ask\":\"0.004\"}, {\"asset_id\":\"69697746896130839564035629862476347944307040470122503199396727085502753297492\", \"price\":\"0.997\", \"size\":\"0\", \"side\":\"BUY\", \"hash\":\"717d803bc36ec61acff2c2358d4fc1f6e01ee30b\", \"best_bid\":\"0.996\", \"best_ask\":\"0.999\"}], \"timestamp\":\"1785127454934\", \"event_type\":\"price_change\"}","received_at":"2026-07-27T04:44:14.884265Z","schema_version":"clob-market-ws.price_change.v1","sequence":null,"server_hash":null,"server_timestamp":"1785127454934","session_id":"e9443c7415a0419799bee9cfbb1a9e4d","source":"clob_market_ws"},"received_at":"2026-07-27T04:44:14.884265Z","record_id":"9951dfaff108e624314ac81e0bf1844520f88639c1c092cefa9bd3278cf39acd","schema_fingerprint":"4aa3821a28b0b7c2400bc59aba4bcc0a76e971dadd19610d3ad38c768e124dc7","schema_version":"edge-lab-recorder.raw.v1","sequence":null,"source":"clob_market_ws"}
{"event_at":"2026-07-27T04:44:14.966000Z","event_fingerprint":"486fe24a76b985ec1628ec9007598ab1d27d290ac5481489f3134b54abd5c136","payload":{"connection_id":"0f4979d6978d463e9660b042fdcf555f","event_at":"2026-07-27T04:44:14.966000Z","event_type":"best_bid_ask","frame_hash":"ddfd195e717fe99f09c6837ce51d5f6b199390e74fc565c74f365e09141e5525","frame_index":0,"kind":"data","monotonic_ns":229438177076250,"payload":{"asset_id":"69697746896130839564035629862476347944307040470122503199396727085502753297492","best_ask":"0.999","best_bid":"0.997","event_type":"best_bid_ask","market":"0xeb66215f2e9faa6449e30a02bab5b8ed7b79a38bf961f6b24d0073c9c2419250","spread":"0.002","timestamp":"1785127454966"},"payload_hash":"06ed02da4ceaae7c9cd12a64430d335a97753a9358408ab46f55c2e8ab017c3b","raw_frame":"{\"market\":\"0xeb66215f2e9faa6449e30a02bab5b8ed7b79a38bf961f6b24d0073c9c2419250\", \"asset_id\":\"69697746896130839564035629862476347944307040470122503199396727085502753297492\", \"best_bid\":\"0.997\", \"best_ask\":\"0.999\", \"spread\":\"0.002\", \"timestamp\":\"1785127454966\", \"event_type\":\"best_bid_ask\"}","received_at":"2026-07-27T04:44:14.914651Z","schema_version":"clob-market-ws.best_bid_ask.v1","sequence":null,"server_hash":null,"server_timestamp":"1785127454966","session_id":"e9443c7415a0419799bee9cfbb1a9e4d","source":"clob_market_ws"},"received_at":"2026-07-27T04:44:14.914651Z","record_id":"af90bcb8837e58b8d16d9f68dd9940153728eeb1e9b45080a20adb24ad1b752d","schema_fingerprint":"8488399f31b0337811b13b266be932db7062827c2470b78bd8e9e99bab51d17d","schema_version":"edge-lab-recorder.raw.v1","sequence":null,"source":"clob_market_ws"}
{"event_at":"2026-07-27T04:44:14.966000Z","event_fingerprint":"c715e0443d6b04f0e1f1715219d49cc998a70896f82cae51891eecd527ce3ab7","payload":{"connection_id":"0f4979d6978d463e9660b042fdcf555f","event_at":"2026-07-27T04:44:14.966000Z","event_type":"best_bid_ask","frame_hash":"edffd3f9dbb8b2c5a1a305f6e7f4355e0ca082b834acc9618b54a98f1da38d83","frame_index":0,"kind":"data","monotonic_ns":229438177525458,"payload":{"asset_id":"60386828328910021732068595344565885737045900010034836345809386672230885527307","best_ask":"0.003","best_bid":"0.001","event_type":"best_bid_ask","market":"0xeb66215f2e9faa6449e30a02bab5b8ed7b79a38bf961f6b24d0073c9c2419250","spread":"0.002","timestamp":"1785127454966"},"payload_hash":"300a2a54470fc26eb032446f7deb0a0e7c6ec73d5ff98b572742cbe2e0b66673","raw_frame":"{\"market\":\"0xeb66215f2e9faa6449e30a02bab5b8ed7b79a38bf961f6b24d0073c9c2419250\", \"asset_id\":\"60386828328910021732068595344565885737045900010034836345809386672230885527307\", \"best_bid\":\"0.001\", \"best_ask\":\"0.003\", \"spread\":\"0.002\", \"timestamp\":\"1785127454966\", \"event_type\":\"best_bid_ask\"}","received_at":"2026-07-27T04:44:14.915104Z","schema_version":"clob-market-ws.best_bid_ask.v1","sequence":null,"server_hash":null,"server_timestamp":"1785127454966","session_id":"e9443c7415a0419799bee9cfbb1a9e4d","source":"clob_market_ws"},"received_at":"2026-07-27T04:44:14.915104Z","record_id":"f3fcc263abf2a4c67ed1ce6acea75d6970df9af03fda056861631214505e73a3","schema_fingerprint":"8488399f31b0337811b13b266be932db7062827c2470b78bd8e9e99bab51d17d","schema_version":"edge-lab-recorder.raw.v1","sequence":null,"source":"clob_market_ws"}
{"event_at":"2026-07-27T04:44:14.966000Z","event_fingerprint":"e35378dba50ec7923eaa8503663e09db7861bc121b1314a00477ccfc695f450c","payload":{"connection_id":"0f4979d6978d463e9660b042fdcf555f","event_at":"2026-07-27T04:44:14.966000Z","event_type":"price_change","frame_hash":"8e198cfb8cb8ec10a61dc177e9302bc0c47d49c26e5c44f81d2b8348e4e3ac1b","frame_index":0,"kind":"data","monotonic_ns":229438178331666,"payload":{"event_type":"price_change","market":"0xeb66215f2e9faa6449e30a02bab5b8ed7b79a38bf961f6b24d0073c9c2419250","price_changes":[{"asset_id":"60386828328910021732068595344565885737045900010034836345809386672230885527307","best_ask":"0.003","best_bid":"0.001","hash":"33766f58f58b6ef1a3402e2927e6a6fe92cc85ad","price":"0.003","side":"SELL","size":"275.12"},{"asset_id":"69697746896130839564035629862476347944307040470122503199396727085502753297492","best_ask":"0.999","best_bid":"0.997","hash":"68eb5699355c099cd78c0d42aa576cde4bc81761","price":"0.997","side":"BUY","size":"275.12"}],"timestamp":"1785127454966"},"payload_hash":"74e216fb05252b2162563143f58234ec3ed4c07b34da61a0997e44334f54a820","raw_frame":"{\"market\":\"0xeb66215f2e9faa6449e30a02bab5b8ed7b79a38bf961f6b24d0073c9c2419250\", \"price_changes\":[{\"asset_id\":\"60386828328910021732068595344565885737045900010034836345809386672230885527307\", \"price\":\"0.003\", \"size\":\"275.12\", \"side\":\"SELL\", \"hash\":\"33766f58f58b6ef1a3402e2927e6a6fe92cc85ad\", \"best_bid\":\"0.001\", \"best_ask\":\"0.003\"}, {\"asset_id\":\"69697746896130839564035629862476347944307040470122503199396727085502753297492\", \"price\":\"0.997\", \"size\":\"275.12\", \"side\":\"BUY\", \"hash\":\"68eb5699355c099cd78c0d42aa576cde4bc81761\", \"best_bid\":\"0.997\", \"best_ask\":\"0.999\"}], \"timestamp\":\"1785127454966\", \"event_type\":\"price_change\"}","received_at":"2026-07-27T04:44:14.915904Z","schema_version":"clob-market-ws.price_change.v1","sequence":null,"server_hash":null,"server_timestamp":"1785127454966","session_id":"e9443c7415a0419799bee9cfbb1a9e4d","source":"clob_market_ws"},"received_at":"2026-07-27T04:44:14.915904Z","record_id":"3a55459bf0b55a150ee108c9440259f0844cdb1b09d351e8ec7ec16e14bbe38d","schema_fingerprint":"4aa3821a28b0b7c2400bc59aba4bcc0a76e971dadd19610d3ad38c768e124dc7","schema_version":"edge-lab-recorder.raw.v1","sequence":null,"source":"clob_market_ws"}
{"event_at":"2026-07-27T04:44:14.986000Z","event_fingerprint":"9248e3757a2f8ea8e0db005750526218238054ceb03cffbac6156f98ba5489b8","payload":{"connection_id":"0f4979d6978d463e9660b042fdcf555f","event_at":"2026-07-27T04:44:14.986000Z","event_type":"best_bid_ask","frame_hash":"a0b719f242c6af5a517eb97f701c1e8948461d60f924a5101961277ea853d2f6","frame_index":0,"kind":"data","monotonic_ns":229438198050541,"payload":{"asset_id":"69697746896130839564035629862476347944307040470122503199396727085502753297492","best_ask":"0.999","best_bid":"0.996","event_type":"best_bid_ask","market":"0xeb66215f2e9faa6449e30a02bab5b8ed7b79a38bf961f6b24d0073c9c2419250","spread":"0.003","timestamp":"1785127454986"},"payload_hash":"a31de6dae3ee81c9581aeb596e253a06acce8ea4b394f2ad2db3512c40005e89","raw_frame":"{\"market\":\"0xeb66215f2e9faa6449e30a02bab5b8ed7b79a38bf961f6b24d0073c9c2419250\", \"asset_id\":\"69697746896130839564035629862476347944307040470122503199396727085502753297492\", \"best_bid\":\"0.996\", \"best_ask\":\"0.999\", \"spread\":\"0.003\", \"timestamp\":\"1785127454986\", \"event_type\":\"best_bid_ask\"}","received_at":"2026-07-27T04:44:14.935622Z","schema_version":"clob-market-ws.best_bid_ask.v1","sequence":null,"server_hash":null,"server_timestamp":"1785127454986","session_id":"e9443c7415a0419799bee9cfbb1a9e4d","source":"clob_market_ws"},"received_at":"2026-07-27T04:44:14.935622Z","record_id":"4a55fe9a3f869ba9ab47bb6545d302a9db272c31a9fb30931bffce3cc2108154","schema_fingerprint":"8488399f31b0337811b13b266be932db7062827c2470b78bd8e9e99bab51d17d","schema_version":"edge-lab-recorder.raw.v1","sequence":null,"source":"clob_market_ws"}
{"event_at":"2026-07-27T04:44:14.986000Z","event_fingerprint":"71a1fc9517d8e05d9d8dda786d0c82364f6b848d7b4959b1716d8cc3084c13d1","payload":{"connection_id":"0f4979d6978d463e9660b042fdcf555f","event_at":"2026-07-27T04:44:14.986000Z","event_type":"best_bid_ask","frame_hash":"6497d53a5cdbb062c9edd09040ee164a122fc1111483c2ed04061c6ffea53de5","frame_index":0,"kind":"data","monotonic_ns":229438198656500,"payload":{"asset_id":"60386828328910021732068595344565885737045900010034836345809386672230885527307","best_ask":"0.004","best_bid":"0.001","event_type":"best_bid_ask","market":"0xeb66215f2e9faa6449e30a02bab5b8ed7b79a38bf961f6b24d0073c9c2419250","spread":"0.003","timestamp":"1785127454986"},"payload_hash":"461416abe44c86bd6741bd8bbfe962137e7983d71fe3b13fe3de24096aab9f14","raw_frame":"{\"market\":\"0xeb66215f2e9faa6449e30a02bab5b8ed7b79a38bf961f6b24d0073c9c2419250\", \"asset_id\":\"60386828328910021732068595344565885737045900010034836345809386672230885527307\", \"best_bid\":\"0.001\", \"best_ask\":\"0.004\", \"spread\":\"0.003\", \"timestamp\":\"1785127454986\", \"event_type\":\"best_bid_ask\"}","received_at":"2026-07-27T04:44:14.936233Z","schema_version":"clob-market-ws.best_bid_ask.v1","sequence":null,"server_hash":null,"server_timestamp":"1785127454986","session_id":"e9443c7415a0419799bee9cfbb1a9e4d","source":"clob_market_ws"},"received_at":"2026-07-27T04:44:14.936233Z","record_id":"6b89902d4a1e9bf33028e1bb26d3c3df077230eedf98b4b7ebb8bf09346147a4","schema_fingerprint":"8488399f31b0337811b13b266be932db7062827c2470b78bd8e9e99bab51d17d","schema_version":"edge-lab-recorder.raw.v1","sequence":null,"source":"clob_market_ws"}
{"event_at":"2026-07-27T04:44:14.986000Z","event_fingerprint":"f0371fa3bab0c6d455ab9849094572c7702ca92944c202faea077afabe8138b8","payload":{"connection_id":"0f4979d6978d463e9660b042fdcf555f","event_at":"2026-07-27T04:44:14.986000Z","event_type":"price_change","frame_hash":"af18e9e29d4c798f963858f35c893406fa104c303d2e8bc339073241def19c95","frame_index":0,"kind":"data","monotonic_ns":229438199108208,"payload":{"event_type":"price_change","market":"0xeb66215f2e9faa6449e30a02bab5b8ed7b79a38bf961f6b24d0073c9c2419250","price_changes":[{"asset_id":"60386828328910021732068595344565885737045900010034836345809386672230885527307","best_ask":"0.004","best_bid":"0.001","hash":"ebc5fdd8666b1ea914e734814dbca1a260dc2979","price":"0.003","side":"SELL","size":"0"},{"asset_id":"69697746896130839564035629862476347944307040470122503199396727085502753297492","best_ask":"0.999","best_bid":"0.996","hash":"a156cf12e342a46fd7962b58069b650f04d49b5e","price":"0.997","side":"BUY","size":"0"}],"timestamp":"1785127454986"},"payload_hash":"381ebd7d5e29491ed2d63d31f9a8ec651174f77ccc4836b563fa69e18c9ab877","raw_frame":"{\"market\":\"0xeb66215f2e9faa6449e30a02bab5b8ed7b79a38bf961f6b24d0073c9c2419250\", \"price_changes\":[{\"asset_id\":\"60386828328910021732068595344565885737045900010034836345809386672230885527307\", \"price\":\"0.003\", \"size\":\"0\", \"side\":\"SELL\", \"hash\":\"ebc5fdd8666b1ea914e734814dbca1a260dc2979\", \"best_bid\":\"0.001\", \"best_ask\":\"0.004\"}, {\"asset_id\":\"69697746896130839564035629862476347944307040470122503199396727085502753297492\", \"price\":\"0.997\", \"size\":\"0\", \"side\":\"BUY\", \"hash\":\"a156cf12e342a46fd7962b58069b650f04d49b5e\", \"best_bid\":\"0.996\", \"best_ask\":\"0.999\"}], \"timestamp\":\"1785127454986\", \"event_type\":\"price_change\"}","received_at":"2026-07-27T04:44:14.936687Z","schema_version":"clob-market-ws.price_change.v1","sequence":null,"server_hash":null,"server_timestamp":"1785127454986","session_id":"e9443c7415a0419799bee9cfbb1a9e4d","source":"clob_market_ws"},"received_at":"2026-07-27T04:44:14.936687Z","record_id":"7c3f07dfe7e7a1b0048433e582a62cfdf062e18b52808f5a666dc0bb98df84b2","schema_fingerprint":"4aa3821a28b0b7c2400bc59aba4bcc0a76e971dadd19610d3ad38c768e124dc7","schema_version":"edge-lab-recorder.raw.v1","sequence":null,"source":"clob_market_ws"}
{"event_at":"2026-07-27T04:44:14.999000Z","event_fingerprint":"b1dcaf9a77e3532b86e00cb7d13d4fce612d59c7036cea650ad558b57b4053ac","payload":{"connection_id":"0f4979d6978d463e9660b042fdcf555f","event_at":"2026-07-27T04:44:14.999000Z","event_type":"price_change","frame_hash":"2e73c9cc7ab7ecfaa636f358ef4a9b686831c2135b4306a36bbf1f4e2fd7f2b9","frame_index":0,"kind":"data","monotonic_ns":229438210501041,"payload":{"event_type":"price_change","market":"0xeb66215f2e9faa6449e30a02bab5b8ed7b79a38bf961f6b24d0073c9c2419250","price_changes":[{"asset_id":"69697746896130839564035629862476347944307040470122503199396727085502753297492","best_ask":"0.999","best_bid":"0.996","hash":"f6684d0e0335fecc450bba56a54183080756f17e","price":"0.04","side":"BUY","size":"535"},{"asset_id":"60386828328910021732068595344565885737045900010034836345809386672230885527307","best_ask":"0.004","best_bid":"0.001","hash":"bf3c86421058c9f59355c2ca5f6d25111d0b93a8","price":"0.96","side":"SELL","size":"535"}],"timestamp":"1785127454999"},"payload_hash":"8726c4d8d7d5714752f5c035fbaadd45cf21ce89b29688420b74a03ee1d29c96","raw_frame":"{\"market\":\"0xeb66215f2e9faa6449e30a02bab5b8ed7b79a38bf961f6b24d0073c9c2419250\", \"price_changes\":[{\"asset_id\":\"69697746896130839564035629862476347944307040470122503199396727085502753297492\", \"price\":\"0.04\", \"size\":\"535\", \"side\":\"BUY\", \"hash\":\"f6684d0e0335fecc450bba56a54183080756f17e\", \"best_bid\":\"0.996\", \"best_ask\":\"0.999\"}, {\"asset_id\":\"60386828328910021732068595344565885737045900010034836345809386672230885527307\", \"price\":\"0.96\", \"size\":\"535\", \"side\":\"SELL\", \"hash\":\"bf3c86421058c9f59355c2ca5f6d25111d0b93a8\", \"best_bid\":\"0.001\", \"best_ask\":\"0.004\"}], \"timestamp\":\"1785127454999\", \"event_type\":\"price_change\"}","received_at":"2026-07-27T04:44:14.948076Z","schema_version":"clob-market-ws.price_change.v1","sequence":null,"server_hash":null,"server_timestamp":"1785127454999","session_id":"e9443c7415a0419799bee9cfbb1a9e4d","source":"clob_market_ws"},"received_at":"2026-07-27T04:44:14.948076Z","record_id":"d52edb0ac0f7f7cbbf5a4dddddaf6a1cf07ee5dbbbd28613e0d3c5f453cbe35a","schema_fingerprint":"4aa3821a28b0b7c2400bc59aba4bcc0a76e971dadd19610d3ad38c768e124dc7","schema_version":"edge-lab-recorder.raw.v1","sequence":null,"source":"clob_market_ws"}
{"event_at":null,"event_fingerprint":"84b94e19f325b7239556fa92a1d49b600b53288094d9716322d3c94fa13d4165","payload":{"connection_id":"0f4979d6978d463e9660b042fdcf555f","event_type":"heartbeat_ack","frame_hash":"95784973cc639977bff93619700168505cb8f7855e44fa643d34622a43706c87","kind":"lifecycle","monotonic_ns":229438223962375,"raw_frame":"PONG","received_at":"2026-07-27T04:44:14.961539Z","schema_version":"edge-lab-recorder.heartbeat-ack.v1","session_id":"e9443c7415a0419799bee9cfbb1a9e4d","source":"clob_market_ws"},"received_at":"2026-07-27T04:44:14.961539Z","record_id":"c7c5404ea186a6ab4f5fb8311834fcb721cb514c43edfe16861eec2789a5aebf","schema_fingerprint":"c14ee1aab3ca674ee738e5268877b544d74c41ad3c427cedc09236467dc68ba1","schema_version":"edge-lab-recorder.raw.v1","sequence":null,"source":"clob_market_ws"}
{"event_at":"2026-07-27T04:44:15.015000Z","event_fingerprint":"e82f4db103c7adb5c757c259e969736de5f27f049475ea92119e32431f64bbfc","payload":{"connection_id":"0f4979d6978d463e9660b042fdcf555f","event_at":"2026-07-27T04:44:15.015000Z","event_type":"best_bid_ask","frame_hash":"fb790389e80df1bad4128c1e23bc3c36d8b823d568cf59cac1bba2c8fae8aa66","frame_index":0,"kind":"data","monotonic_ns":229438225183375,"payload":{"asset_id":"69697746896130839564035629862476347944307040470122503199396727085502753297492","best_ask":"0.999","best_bid":"0.997","event_type":"best_bid_ask","market":"0xeb66215f2e9faa6449e30a02bab5b8ed7b79a38bf961f6b24d0073c9c2419250","spread":"0.002","timestamp":"1785127455015"},"payload_hash":"6da15403503005f56ceb95a870403fb05e8bc96241dc3e921d32bdd800afbe89","raw_frame":"{\"market\":\"0xeb66215f2e9faa6449e30a02bab5b8ed7b79a38bf961f6b24d0073c9c2419250\", \"asset_id\":\"69697746896130839564035629862476347944307040470122503199396727085502753297492\", \"best_bid\":\"0.997\", \"best_ask\":\"0.999\", \"spread\":\"0.002\", \"timestamp\":\"1785127455015\", \"event_type\":\"best_bid_ask\"}","received_at":"2026-07-27T04:44:14.962752Z","schema_version":"clob-market-ws.best_bid_ask.v1","sequence":null,"server_hash":null,"server_timestamp":"1785127455015","session_id":"e9443c7415a0419799bee9cfbb1a9e4d","source":"clob_market_ws"},"received_at":"2026-07-27T04:44:14.962752Z","record_id":"bd03810e06e17372fd13d4a7aa526514bd256bbaaf15ca8464341dea43160762","schema_fingerprint":"8488399f31b0337811b13b266be932db7062827c2470b78bd8e9e99bab51d17d","schema_version":"edge-lab-recorder.raw.v1","sequence":null,"source":"clob_market_ws"}
{"event_at":"2026-07-27T04:44:15.015000Z","event_fingerprint":"4b5a82723f18b5722c066c7ab91816ebe93e6532d3e5f9f07288b49bb6819af0","payload":{"connection_id":"0f4979d6978d463e9660b042fdcf555f","event_at":"2026-07-27T04:44:15.015000Z","event_type":"best_bid_ask","frame_hash":"ce8418c8193b266d220446f1ee1d4cf9a801d19c7575c6a0ced3fe25e32f3cb8","frame_index":0,"kind":"data","monotonic_ns":229438226915416,"payload":{"asset_id":"60386828328910021732068595344565885737045900010034836345809386672230885527307","best_ask":"0.003","best_bid":"0.001","event_type":"best_bid_ask","market":"0xeb66215f2e9faa6449e30a02bab5b8ed7b79a38bf961f6b24d0073c9c2419250","spread":"0.002","timestamp":"1785127455015"},"payload_hash":"1e4741ef1e094e7d134a07b77b870eb444c848dd2a147c73602b96aad59a018f","raw_frame":"{\"market\":\"0xeb66215f2e9faa6449e30a02bab5b8ed7b79a38bf961f6b24d0073c9c2419250\", \"asset_id\":\"60386828328910021732068595344565885737045900010034836345809386672230885527307\", \"best_bid\":\"0.001\", \"best_ask\":\"0.003\", \"spread\":\"0.002\", \"timestamp\":\"1785127455015\", \"event_type\":\"best_bid_ask\"}","received_at":"2026-07-27T04:44:14.964494Z","schema_version":"clob-market-ws.best_bid_ask.v1","sequence":null,"server_hash":null,"server_timestamp":"1785127455015","session_id":"e9443c7415a0419799bee9cfbb1a9e4d","source":"clob_market_ws"},"received_at":"2026-07-27T04:44:14.964494Z","record_id":"198fed8dd50785f2fa96a78d26430e56321746cd4f4decf151a0ae922bf38fed","schema_fingerprint":"8488399f31b0337811b13b266be932db7062827c2470b78bd8e9e99bab51d17d","schema_version":"edge-lab-recorder.raw.v1","sequence":null,"source":"clob_market_ws"}
{"event_at":"2026-07-27T04:44:15.015000Z","event_fingerprint":"ad756ce73656a552c8f669d5a76877dd5845b87b23224096f53b256fb6ce6357","payload":{"connection_id":"0f4979d6978d463e9660b042fdcf555f","event_at":"2026-07-27T04:44:15.015000Z","event_type":"price_change","frame_hash":"fd6e614d05412afaed8494526f0017591e5afb283d6b8ac7ce814f8934be9285","frame_index":0,"kind":"data","monotonic_ns":229438227393041,"payload":{"event_type":"price_change","market":"0xeb66215f2e9faa6449e30a02bab5b8ed7b79a38bf961f6b24d0073c9c2419250","price_changes":[{"asset_id":"60386828328910021732068595344565885737045900010034836345809386672230885527307","best_ask":"0.003","best_bid":"0.001","hash":"85ba1202ab5774ed9ea582a023692562df0d325c","price":"0.003","side":"SELL","size":"275.12"},{"asset_id":"69697746896130839564035629862476347944307040470122503199396727085502753297492","best_ask":"0.999","best_bid":"0.997","hash":"855473bd99c004160150f3dc1f64fe47e446273d","price":"0.997","side":"BUY","size":"275.12"}],"timestamp":"1785127455015"},"payload_hash":"4a68e3f2c069cf12ad30ecf9266316b16ebc08e0b17c5f2fad8b527ede3d7c2a","raw_frame":"{\"market\":\"0xeb66215f2e9faa6449e30a02bab5b8ed7b79a38bf961f6b24d0073c9c2419250\", \"price_changes\":[{\"asset_id\":\"60386828328910021732068595344565885737045900010034836345809386672230885527307\", \"price\":\"0.003\", \"size\":\"275.12\", \"side\":\"SELL\", \"hash\":\"85ba1202ab5774ed9ea582a023692562df0d325c\", \"best_bid\":\"0.001\", \"best_ask\":\"0.003\"}, {\"asset_id\":\"69697746896130839564035629862476347944307040470122503199396727085502753297492\", \"price\":\"0.997\", \"size\":\"275.12\", \"side\":\"BUY\", \"hash\":\"855473bd99c004160150f3dc1f64fe47e446273d\", \"best_bid\":\"0.997\", \"best_ask\":\"0.999\"}], \"timestamp\":\"1785127455015\", \"event_type\":\"price_change\"}","received_at":"2026-07-27T04:44:14.964971Z","schema_version":"clob-market-ws.price_change.v1","sequence":null,"server_hash":null,"server_timestamp":"1785127455015","session_id":"e9443c7415a0419799bee9cfbb1a9e4d","source":"clob_market_ws"},"received_at":"2026-07-27T04:44:14.964971Z","record_id":"c6dc207ad0397d107b48303b4c344ac71abe1b3161d77802d41de39b8b04aa56","schema_fingerprint":"4aa3821a28b0b7c2400bc59aba4bcc0a76e971dadd19610d3ad38c768e124dc7","schema_version":"edge-lab-recorder.raw.v1","sequence":null,"source":"clob_market_ws"}
{"event_at":"2026-07-27T04:44:15.018000Z","event_fingerprint":"4eb2856ceaa18047171ebe3e079fb3347ce7673ad241a5e1579df9249281c13b","payload":{"connection_id":"0f4979d6978d463e9660b042fdcf555f","event_at":"2026-07-27T04:44:15.018000Z","event_type":"price_change","frame_hash":"637ff4a125c2c4943fd339a52b6e12891e01431c1842a5d1dc246af2fafffa61","frame_index":0,"kind":"data","monotonic_ns":229438228889375,"payload":{"event_type":"price_change","market":"0xeb66215f2e9faa6449e30a02bab5b8ed7b79a38bf961f6b24d0073c9c2419250","price_changes":[{"asset_id":"69697746896130839564035629862476347944307040470122503199396727085502753297492","best_ask":"0.999","best_bid":"0.997","hash":"515e69e9f91b0d4307454be397d3de393bc81bb1","price":"0.994","side":"BUY","size":"0"},{"asset_id":"60386828328910021732068595344565885737045900010034836345809386672230885527307","best_ask":"0.003","best_bid":"0.001","hash":"c78ff26e15d78ee66d53b2c1e53f5db34238411a","price":"0.006","side":"SELL","size":"0"}],"timestamp":"1785127455018"},"payload_hash":"0d287662d6dcaf23db2df5a98d0226c5320de47ac433ad1634d93f6c1613c4e5","raw_frame":"{\"market\":\"0xeb66215f2e9faa6449e30a02bab5b8ed7b79a38bf961f6b24d0073c9c2419250\", \"price_changes\":[{\"asset_id\":\"69697746896130839564035629862476347944307040470122503199396727085502753297492\", \"price\":\"0.994\", \"size\":\"0\", \"side\":\"BUY\", \"hash\":\"515e69e9f91b0d4307454be397d3de393bc81bb1\", \"best_bid\":\"0.997\", \"best_ask\":\"0.999\"}, {\"asset_id\":\"60386828328910021732068595344565885737045900010034836345809386672230885527307\", \"price\":\"0.006\", \"size\":\"0\", \"side\":\"SELL\", \"hash\":\"c78ff26e15d78ee66d53b2c1e53f5db34238411a\", \"best_bid\":\"0.001\", \"best_ask\":\"0.003\"}], \"timestamp\":\"1785127455018\", \"event_type\":\"price_change\"}","received_at":"2026-07-27T04:44:14.966466Z","schema_version":"clob-market-ws.price_change.v1","sequence":null,"server_hash":null,"server_timestamp":"1785127455018","session_id":"e9443c7415a0419799bee9cfbb1a9e4d","source":"clob_market_ws"},"received_at":"2026-07-27T04:44:14.966466Z","record_id":"cc2b44edb62bd4c0d69c90a0a582d6e407f492a4db4bda90e7b2cc32e612a993","schema_fingerprint":"4aa3821a28b0b7c2400bc59aba4bcc0a76e971dadd19610d3ad38c768e124dc7","schema_version":"edge-lab-recorder.raw.v1","sequence":null,"source":"clob_market_ws"}
{"event_at":"2026-07-27T04:44:15.035000Z","event_fingerprint":"18251a7759173ecdca38bf05a085626575f1e83220667ba0032f1a1edefb7d9b","payload":{"connection_id":"0f4979d6978d463e9660b042fdcf555f","event_at":"2026-07-27T04:44:15.035000Z","event_type":"best_bid_ask","frame_hash":"2dccdff1f099b1f664cabc0013cd5b7b3b0df9f8fa1788ac58799ae135e9fa25","frame_index":0,"kind":"data","monotonic_ns":229438246313625,"payload":{"asset_id":"69697746896130839564035629862476347944307040470122503199396727085502753297492","best_ask":"0.999","best_bid":"0.996","event_type":"best_bid_ask","market":"0xeb66215f2e9faa6449e30a02bab5b8ed7b79a38bf961f6b24d0073c9c2419250","spread":"0.003","timestamp":"1785127455035"},"payload_hash":"4b08f518cec20e7aef5d6531e64b3834a696aef6176e6171edca2eb846a9bfd9","raw_frame":"{\"market\":\"0xeb66215f2e9faa6449e30a02bab5b8ed7b79a38bf961f6b24d0073c9c2419250\", \"asset_id\":\"69697746896130839564035629862476347944307040470122503199396727085502753297492\", \"best_bid\":\"0.996\", \"best_ask\":\"0.999\", \"spread\":\"0.003\", \"timestamp\":\"1785127455035\", \"event_type\":\"best_bid_ask\"}","received_at":"2026-07-27T04:44:14.983881Z","schema_version":"clob-market-ws.best_bid_ask.v1","sequence":null,"server_hash":null,"server_timestamp":"1785127455035","session_id":"e9443c7415a0419799bee9cfbb1a9e4d","source":"clob_market_ws"},"received_at":"2026-07-27T04:44:14.983881Z","record_id":"45107681720dfc1da39b55e938d50e17ea120fdb5badf239ba951acec23c6f71","schema_fingerprint":"8488399f31b0337811b13b266be932db7062827c2470b78bd8e9e99bab51d17d","schema_version":"edge-lab-recorder.raw.v1","sequence":null,"source":"clob_market_ws"}
{"event_at":"2026-07-27T04:44:15.035000Z","event_fingerprint":"2af15151f45183db5959ad070b9e932a6aa67e7664afa5ee4878ce8873261c02","payload":{"connection_id":"0f4979d6978d463e9660b042fdcf555f","event_at":"2026-07-27T04:44:15.035000Z","event_type":"best_bid_ask","frame_hash":"d8cf3511b57288584af2e2c3d0854348df30696f9df63e7b7640ce3ab40e8876","frame_index":0,"kind":"data","monotonic_ns":229438247561750,"payload":{"asset_id":"60386828328910021732068595344565885737045900010034836345809386672230885527307","best_ask":"0.004","best_bid":"0.001","event_type":"best_bid_ask","market":"0xeb66215f2e9faa6449e30a02bab5b8ed7b79a38bf961f6b24d0073c9c2419250","spread":"0.003","timestamp":"1785127455035"},"payload_hash":"48ce6e93d79188746c8f2393f8714facabbc93fd45d2ed6f8f1f24da9f7b173d","raw_frame":"{\"market\":\"0xeb66215f2e9faa6449e30a02bab5b8ed7b79a38bf961f6b24d0073c9c2419250\", \"asset_id\":\"60386828328910021732068595344565885737045900010034836345809386672230885527307\", \"best_bid\":\"0.001\", \"best_ask\":\"0.004\", \"spread\":\"0.003\", \"timestamp\":\"1785127455035\", \"event_type\":\"best_bid_ask\"}","received_at":"2026-07-27T04:44:14.985134Z","schema_version":"clob-market-ws.best_bid_ask.v1","sequence":null,"server_hash":null,"server_timestamp":"1785127455035","session_id":"e9443c7415a0419799bee9cfbb1a9e4d","source":"clob_market_ws"},"received_at":"2026-07-27T04:44:14.985134Z","record_id":"ef28255542fac4a7224ed20aaa9ed03b5d98c52872478cc6c1830a9cef1b2d6f","schema_fingerprint":"8488399f31b0337811b13b266be932db7062827c2470b78bd8e9e99bab51d17d","schema_version":"edge-lab-recorder.raw.v1","sequence":null,"source":"clob_market_ws"}
{"event_at":"2026-07-27T04:44:15.035000Z","event_fingerprint":"d4aa106ce52c33df03edb75a5d177456c76b7e041386307aa62f9346780d84c7","payload":{"connection_id":"0f4979d6978d463e9660b042fdcf555f","event_at":"2026-07-27T04:44:15.035000Z","event_type":"price_change","frame_hash":"3a6b5aeb065759306221ecadeb4283055c8dd88491d3ecd9ff165272b632067d","frame_index":0,"kind":"data","monotonic_ns":229438248755458,"payload":{"event_type":"price_change","market":"0xeb66215f2e9faa6449e30a02bab5b8ed7b79a38bf961f6b24d0073c9c2419250","price_changes":[{"asset_id":"60386828328910021732068595344565885737045900010034836345809386672230885527307","best_ask":"0.004","best_bid":"0.001","hash":"05dcdc61cca144ecd5e7d20f675c605c509010c0","price":"0.003","side":"SELL","size":"0"},{"asset_id":"69697746896130839564035629862476347944307040470122503199396727085502753297492","best_ask":"0.999","best_bid":"0.996","hash":"474f7c813c99eb9d7c381499b159b9d3714fa88e","price":"0.997","side":"BUY","size":"0"}],"timestamp":"1785127455035"},"payload_hash":"4c30093df8877ab5e06faaa27a8df68ad0d5d358539be1e1b3f4b2e99e800180","raw_frame":"{\"market\":\"0xeb66215f2e9faa6449e30a02bab5b8ed7b79a38bf961f6b24d0073c9c2419250\", \"price_changes\":[{\"asset_id\":\"60386828328910021732068595344565885737045900010034836345809386672230885527307\", \"price\":\"0.003\", \"size\":\"0\", \"side\":\"SELL\", \"hash\":\"05dcdc61cca144ecd5e7d20f675c605c509010c0\", \"best_bid\":\"0.001\", \"best_ask\":\"0.004\"}, {\"asset_id\":\"69697746896130839564035629862476347944307040470122503199396727085502753297492\", \"price\":\"0.997\", \"size\":\"0\", \"side\":\"BUY\", \"hash\":\"474f7c813c99eb9d7c381499b159b9d3714fa88e\", \"best_bid\":\"0.996\", \"best_ask\":\"0.999\"}], \"timestamp\":\"1785127455035\", \"event_type\":\"price_change\"}","received_at":"2026-07-27T04:44:14.986327Z","schema_version":"clob-market-ws.price_change.v1","sequence":null,"server_hash":null,"server_timestamp":"1785127455035","session_id":"e9443c7415a0419799bee9cfbb1a9e4d","source":"clob_market_ws"},"received_at":"2026-07-27T04:44:14.986327Z","record_id":"58a47ae85909082f6f0b86c9d68a7f311f0fda8681b6f560fc191179c1d3f09e","schema_fingerprint":"4aa3821a28b0b7c2400bc59aba4bcc0a76e971dadd19610d3ad38c768e124dc7","schema_version":"edge-lab-recorder.raw.v1","sequence":null,"source":"clob_market_ws"}
{"event_at":"2026-07-27T04:44:15.050000Z","event_fingerprint":"48d8920a55de5b7d462ce9fe0bbdf685a3af13564a67b4752c20c3c0a27781fa","payload":{"connection_id":"0f4979d6978d463e9660b042fdcf555f","event_at":"2026-07-27T04:44:15.050000Z","event_type":"price_change","frame_hash":"f686c22cc06e746eadcea2e3c90c902f764926205cc0afc4ec4322aaa1f70258","frame_index":0,"kind":"data","monotonic_ns":229438260213875,"payload":{"event_type":"price_change","market":"0xeb66215f2e9faa6449e30a02bab5b8ed7b79a38bf961f6b24d0073c9c2419250","price_changes":[{"asset_id":"69697746896130839564035629862476347944307040470122503199396727085502753297492","best_ask":"0.999","best_bid":"0.996","hash":"2c1283dae9db513ca85070cd3c0838c59ea7f251","price":"0.04","side":"BUY","size":"530"},{"asset_id":"60386828328910021732068595344565885737045900010034836345809386672230885527307","best_ask":"0.004","best_bid":"0.001","hash":"e13d995de96a0fa8a5164b939d35f4874ca2ea95","price":"0.96","side":"SELL","size":"530"}],"timestamp":"1785127455050"},"payload_hash":"3ad9de41ad2c1790fad0be7719fb76c7322c68721f7dcf5d0cc7344b1616228c","raw_frame":"{\"market\":\"0xeb66215f2e9faa6449e30a02bab5b8ed7b79a38bf961f6b24d0073c9c2419250\", \"price_changes\":[{\"asset_id\":\"69697746896130839564035629862476347944307040470122503199396727085502753297492\", \"price\":\"0.04\", \"size\":\"530\", \"side\":\"BUY\", \"hash\":\"2c1283dae9db513ca85070cd3c0838c59ea7f251\", \"best_bid\":\"0.996\", \"best_ask\":\"0.999\"}, {\"asset_id\":\"60386828328910021732068595344565885737045900010034836345809386672230885527307\", \"price\":\"0.96\", \"size\":\"530\", \"side\":\"SELL\", \"hash\":\"e13d995de96a0fa8a5164b939d35f4874ca2ea95\", \"best_bid\":\"0.001\", \"best_ask\":\"0.004\"}], \"timestamp\":\"1785127455050\", \"event_type\":\"price_change\"}","received_at":"2026-07-27T04:44:14.997778Z","schema_version":"clob-market-ws.price_change.v1","sequence":null,"server_hash":null,"server_timestamp":"1785127455050","session_id":"e9443c7415a0419799bee9cfbb1a9e4d","source":"clob_market_ws"},"received_at":"2026-07-27T04:44:14.997778Z","record_id":"9708a3d0735a7545fccfbb3b3547a53e27d598001032a2460cd8ad1c592bc13c","schema_fingerprint":"4aa3821a28b0b7c2400bc59aba4bcc0a76e971dadd19610d3ad38c768e124dc7","schema_version":"edge-lab-recorder.raw.v1","sequence":null,"source":"clob_market_ws"}
{"event_at":"2026-07-27T04:44:15.069000Z","event_fingerprint":"52fe9c1428ac118d5456215d824155170d10d1894dcc52a6554ba7e08b1911b2","payload":{"connection_id":"0f4979d6978d463e9660b042fdcf555f","event_at":"2026-07-27T04:44:15.069000Z","event_type":"best_bid_ask","frame_hash":"9ddd076349fb40cdeb3837ca35746261f2aa650f4de8f7dd333d018f003419a0","frame_index":0,"kind":"data","monotonic_ns":229438279066541,"payload":{"asset_id":"69697746896130839564035629862476347944307040470122503199396727085502753297492","best_ask":"0.999","best_bid":"0.997","event_type":"best_bid_ask","market":"0xeb66215f2e9faa6449e30a02bab5b8ed7b79a38bf961f6b24d0073c9c2419250","spread":"0.002","timestamp":"1785127455069"},"payload_hash":"27ccd704ae96b590510be6fbbc0f600cd7a2b138848558905fef52cbea476cba","raw_frame":"{\"market\":\"0xeb66215f2e9faa6449e30a02bab5b8ed7b79a38bf961f6b24d0073c9c2419250\", \"asset_id\":\"69697746896130839564035629862476347944307040470122503199396727085502753297492\", \"best_bid\":\"0.997\", \"best_ask\":\"0.999\", \"spread\":\"0.002\", \"timestamp\":\"1785127455069\", \"event_type\":\"best_bid_ask\"}","received_at":"2026-07-27T04:44:15.016638Z","schema_version":"clob-market-ws.best_bid_ask.v1","sequence":null,"server_hash":null,"server_timestamp":"1785127455069","session_id":"e9443c7415a0419799bee9cfbb1a9e4d","source":"clob_market_ws"},"received_at":"2026-07-27T04:44:15.016638Z","record_id":"3d3a0fb8c17f0e7bea5f90e0dbb01384de88009ae25c3037d5cc386bc8224679","schema_fingerprint":"8488399f31b0337811b13b266be932db7062827c2470b78bd8e9e99bab51d17d","schema_version":"edge-lab-recorder.raw.v1","sequence":null,"source":"clob_market_ws"}
{"event_at":"2026-07-27T04:44:15.069000Z","event_fingerprint":"916a8f1d55cb52f186ac304aaf938cd58854c726f92720754eca88d815b011e8","payload":{"connection_id":"0f4979d6978d463e9660b042fdcf555f","event_at":"2026-07-27T04:44:15.069000Z","event_type":"best_bid_ask","frame_hash":"728360e29a6489835bd4120334c33329050c00e067b1f9f4f494e52de9f7b5f4","frame_index":0,"kind":"data","monotonic_ns":229438280448000,"payload":{"asset_id":"60386828328910021732068595344565885737045900010034836345809386672230885527307","best_ask":"0.003","best_bid":"0.001","event_type":"best_bid_ask","market":"0xeb66215f2e9faa6449e30a02bab5b8ed7b79a38bf961f6b24d0073c9c2419250","spread":"0.002","timestamp":"1785127455069"},"payload_hash":"fba369e6a37bb732e85bd3bbcce8298002080d1cd50d93df0ad7848a04fdb6f3","raw_frame":"{\"market\":\"0xeb66215f2e9faa6449e30a02bab5b8ed7b79a38bf961f6b24d0073c9c2419250\", \"asset_id\":\"60386828328910021732068595344565885737045900010034836345809386672230885527307\", \"best_bid\":\"0.001\", \"best_ask\":\"0.003\", \"spread\":\"0.002\", \"timestamp\":\"1785127455069\", \"event_type\":\"best_bid_ask\"}","received_at":"2026-07-27T04:44:15.018019Z","schema_version":"clob-market-ws.best_bid_ask.v1","sequence":null,"server_hash":null,"server_timestamp":"1785127455069","session_id":"e9443c7415a0419799bee9cfbb1a9e4d","source":"clob_market_ws"},"received_at":"2026-07-27T04:44:15.018019Z","record_id":"733dca7fe075766c28f717cbc78c5fa430cc5f11d131a1cab72fa063d01927d9","schema_fingerprint":"8488399f31b0337811b13b266be932db7062827c2470b78bd8e9e99bab51d17d","schema_version":"edge-lab-recorder.raw.v1","sequence":null,"source":"clob_market_ws"}
{"event_at":"2026-07-27T04:44:15.069000Z","event_fingerprint":"5bd631956c3bd57cc515501638527de9b7fd2e4d3c71e6ef11ff7cb2a4384c05","payload":{"connection_id":"0f4979d6978d463e9660b042fdcf555f","event_at":"2026-07-27T04:44:15.069000Z","event_type":"price_change","frame_hash":"7202a27105a17f6ef6cdfc2e85f2c08319dab2bdedfe502e86294860fc27add1","frame_index":0,"kind":"data","monotonic_ns":229438281617125,"payload":{"event_type":"price_change","market":"0xeb66215f2e9faa6449e30a02bab5b8ed7b79a38bf961f6b24d0073c9c2419250","price_changes":[{"asset_id":"60386828328910021732068595344565885737045900010034836345809386672230885527307","best_ask":"0.003","best_bid":"0.001","hash":"f6cec38749eeb88b9310211447ec218861df38d5","price":"0.003","side":"SELL","size":"275.12"},{"asset_id":"69697746896130839564035629862476347944307040470122503199396727085502753297492","best_ask":"0.999","best_bid":"0.997","hash":"2a073f15f66ddde0c0ff543e42f002bbb777dca7","price":"0.997","side":"BUY","size":"275.12"}],"timestamp":"1785127455069"},"payload_hash":"4f8ad2af964de0cd26bd0a82e978ee281a753ad099d61b7f2953fb345ce1ad97","raw_frame":"{\"market\":\"0xeb66215f2e9faa6449e30a02bab5b8ed7b79a38bf961f6b24d0073c9c2419250\", \"price_changes\":[{\"asset_id\":\"60386828328910021732068595344565885737045900010034836345809386672230885527307\", \"price\":\"0.003\", \"size\":\"275.12\", \"side\":\"SELL\", \"hash\":\"f6cec38749eeb88b9310211447ec218861df38d5\", \"best_bid\":\"0.001\", \"best_ask\":\"0.003\"}, {\"asset_id\":\"69697746896130839564035629862476347944307040470122503199396727085502753297492\", \"price\":\"0.997\", \"size\":\"275.12\", \"side\":\"BUY\", \"hash\":\"2a073f15f66ddde0c0ff543e42f002bbb777dca7\", \"best_bid\":\"0.997\", \"best_ask\":\"0.999\"}], \"timestamp\":\"1785127455069\", \"event_type\":\"price_change\"}","received_at":"2026-07-27T04:44:15.019191Z","schema_version":"clob-market-ws.price_change.v1","sequence":null,"server_hash":null,"server_timestamp":"1785127455069","session_id":"e9443c7415a0419799bee9cfbb1a9e4d","source":"clob_market_ws"},"received_at":"2026-07-27T04:44:15.019191Z","record_id":"4ab2f5125bedcd94263d0e925007f0bf5168d2f7f5404136fd7b171a0bd02b2f","schema_fingerprint":"4aa3821a28b0b7c2400bc59aba4bcc0a76e971dadd19610d3ad38c768e124dc7","schema_version":"edge-lab-recorder.raw.v1","sequence":null,"source":"clob_market_ws"}
{"event_at":"2026-07-27T04:44:15.094000Z","event_fingerprint":"061bea4f3bae74f3d67a42cd5bfe9c4629a4465996e492e3461cb54275cd81e1","payload":{"connection_id":"0f4979d6978d463e9660b042fdcf555f","event_at":"2026-07-27T04:44:15.094000Z","event_type":"best_bid_ask","frame_hash":"da0af7f42f80839cecd09647709742899b9c441363cb40cefe1ec2dd9d139ab1","frame_index":0,"kind":"data","monotonic_ns":229438305967375,"payload":{"asset_id":"69697746896130839564035629862476347944307040470122503199396727085502753297492","best_ask":"0.999","best_bid":"0.996","event_type":"best_bid_ask","market":"0xeb66215f2e9faa6449e30a02bab5b8ed7b79a38bf961f6b24d0073c9c2419250","spread":"0.003","timestamp":"1785127455094"},"payload_hash":"30725c8fe689ce768500807000d7b790c897d2a007d2730468227d6df3d6e0f3","raw_frame":"{\"market\":\"0xeb66215f2e9faa6449e30a02bab5b8ed7b79a38bf961f6b24d0073c9c2419250\", \"asset_id\":\"69697746896130839564035629862476347944307040470122503199396727085502753297492\", \"best_bid\":\"0.996\", \"best_ask\":\"0.999\", \"spread\":\"0.003\", \"timestamp\":\"1785127455094\", \"event_type\":\"best_bid_ask\"}","received_at":"2026-07-27T04:44:15.043533Z","schema_version":"clob-market-ws.best_bid_ask.v1","sequence":null,"server_hash":null,"server_timestamp":"1785127455094","session_id":"e9443c7415a0419799bee9cfbb1a9e4d","source":"clob_market_ws"},"received_at":"2026-07-27T04:44:15.043533Z","record_id":"7d76d1b9a7dcc9e60035b053fdfea9942bdaebb3c3f62dadb5a6e0c5e266246f","schema_fingerprint":"8488399f31b0337811b13b266be932db7062827c2470b78bd8e9e99bab51d17d","schema_version":"edge-lab-recorder.raw.v1","sequence":null,"source":"clob_market_ws"}
{"event_at":"2026-07-27T04:44:15.094000Z","event_fingerprint":"b46b893eb0f9a1cd35ae524717cfd7bfe81bb4c954f915129f07df9423eb3015","payload":{"connection_id":"0f4979d6978d463e9660b042fdcf555f","event_at":"2026-07-27T04:44:15.094000Z","event_type":"best_bid_ask","frame_hash":"4972f9b44d275b13d56b3ae5b8b2b984958c5b828316541dea2f899a00e533a2","frame_index":0,"kind":"data","monotonic_ns":229438307350083,"payload":{"asset_id":"60386828328910021732068595344565885737045900010034836345809386672230885527307","best_ask":"0.004","best_bid":"0.001","event_type":"best_bid_ask","market":"0xeb66215f2e9faa6449e30a02bab5b8ed7b79a38bf961f6b24d0073c9c2419250","spread":"0.003","timestamp":"1785127455094"},"payload_hash":"a4dbe62179c8005e3a6ad7662e813569e5a7c35549ee78820927f31777c276f9","raw_frame":"{\"market\":\"0xeb66215f2e9faa6449e30a02bab5b8ed7b79a38bf961f6b24d0073c9c2419250\", \"asset_id\":\"60386828328910021732068595344565885737045900010034836345809386672230885527307\", \"best_bid\":\"0.001\", \"best_ask\":\"0.004\", \"spread\":\"0.003\", \"timestamp\":\"1785127455094\", \"event_type\":\"best_bid_ask\"}","received_at":"2026-07-27T04:44:15.044919Z","schema_version":"clob-market-ws.best_bid_ask.v1","sequence":null,"server_hash":null,"server_timestamp":"1785127455094","session_id":"e9443c7415a0419799bee9cfbb1a9e4d","source":"clob_market_ws"},"received_at":"2026-07-27T04:44:15.044919Z","record_id":"ca64aa7c62316dc137a0b477708fc2f41abc0c9b9df4669dcd752aff4ab6e7ea","schema_fingerprint":"8488399f31b0337811b13b266be932db7062827c2470b78bd8e9e99bab51d17d","schema_version":"edge-lab-recorder.raw.v1","sequence":null,"source":"clob_market_ws"}
{"event_at":"2026-07-27T04:44:15.094000Z","event_fingerprint":"6aba6c7f1c9f05a3a680d68f6a3774115d7e0c9aedc342b20632869a4eeb8a41","payload":{"connection_id":"0f4979d6978d463e9660b042fdcf555f","event_at":"2026-07-27T04:44:15.094000Z","event_type":"price_change","frame_hash":"e9798ebe3f672d20bf93eada8c67f6ef0861e73722bcf7c1136883415bd1a1a4","frame_index":0,"kind":"data","monotonic_ns":229438308543875,"payload":{"event_type":"price_change","market":"0xeb66215f2e9faa6449e30a02bab5b8ed7b79a38bf961f6b24d0073c9c2419250","price_changes":[{"asset_id":"60386828328910021732068595344565885737045900010034836345809386672230885527307","best_ask":"0.004","best_bid":"0.001","hash":"c8d6cf726c7c7e9710b4a7503a9e317b4f9cd2e5","price":"0.003","side":"SELL","size":"0"},{"asset_id":"69697746896130839564035629862476347944307040470122503199396727085502753297492","best_ask":"0.999","best_bid":"0.996","hash":"a6e7396cf71172de207a0b5b698487f148ca0994","price":"0.997","side":"BUY","size":"0"}],"timestamp":"1785127455094"},"payload_hash":"2edb69696d78271dc00cf60ad840c078d39caf5b7f14708f28ce3e128dfc7c17","raw_frame":"{\"market\":\"0xeb66215f2e9faa6449e30a02bab5b8ed7b79a38bf961f6b24d0073c9c2419250\", \"price_changes\":[{\"asset_id\":\"60386828328910021732068595344565885737045900010034836345809386672230885527307\", \"price\":\"0.003\", \"size\":\"0\", \"side\":\"SELL\", \"hash\":\"c8d6cf726c7c7e9710b4a7503a9e317b4f9cd2e5\", \"best_bid\":\"0.001\", \"best_ask\":\"0.004\"}, {\"asset_id\":\"69697746896130839564035629862476347944307040470122503199396727085502753297492\", \"price\":\"0.997\", \"size\":\"0\", \"side\":\"BUY\", \"hash\":\"a6e7396cf71172de207a0b5b698487f148ca0994\", \"best_bid\":\"0.996\", \"best_ask\":\"0.999\"}], \"timestamp\":\"1785127455094\", \"event_type\":\"price_change\"}","received_at":"2026-07-27T04:44:15.046117Z","schema_version":"clob-market-ws.price_change.v1","sequence":null,"server_hash":null,"server_timestamp":"1785127455094","session_id":"e9443c7415a0419799bee9cfbb1a9e4d","source":"clob_market_ws"},"received_at":"2026-07-27T04:44:15.046117Z","record_id":"aa41e446b980d886388618916cb7fb5a703d41753eaecf3199e49d3d80483a62","schema_fingerprint":"4aa3821a28b0b7c2400bc59aba4bcc0a76e971dadd19610d3ad38c768e124dc7","schema_version":"edge-lab-recorder.raw.v1","sequence":null,"source":"clob_market_ws"}
{"event_at":"2026-07-27T04:44:15.115000Z","event_fingerprint":"e8737e8d519e749286e5cd4e69d4e79d38f3bdc4b9a9169be3b92f5be2ced49e","payload":{"connection_id":"0f4979d6978d463e9660b042fdcf555f","event_at":"2026-07-27T04:44:15.115000Z","event_type":"price_change","frame_hash":"62de7ec97cf70c028cd20928e5cad60d4355a144d6bb335bc0644b613f8fc0e3","frame_index":0,"kind":"data","monotonic_ns":229438327201583,"payload":{"event_type":"price_change","market":"0xeb66215f2e9faa6449e30a02bab5b8ed7b79a38bf961f6b24d0073c9c2419250","price_changes":[{"asset_id":"69697746896130839564035629862476347944307040470122503199396727085502753297492","best_ask":"0.999","best_bid":"0.996","hash":"3d2e6c7689334f022425a5a51a06b81d05d6979f","price":"0.01","side":"BUY","size":"5320"},{"asset_id":"60386828328910021732068595344565885737045900010034836345809386672230885527307","best_ask":"0.004","best_bid":"0.001","hash":"2508532d8cb0eb7723802485f965ba9a84c56d5a","price":"0.99","side":"SELL","size":"5320"}],"timestamp":"1785127455115"},"payload_hash":"c2aa87b7ac1f41fda86b6f324daf73a910aa707f1e97edd6d4ff08c9221b15b5","raw_frame":"{\"market\":\"0xeb66215f2e9faa6449e30a02bab5b8ed7b79a38bf961f6b24d0073c9c2419250\", \"price_changes\":[{\"asset_id\":\"69697746896130839564035629862476347944307040470122503199396727085502753297492\", \"price\":\"0.01\", \"size\":\"5320\", \"side\":\"BUY\", \"hash\":\"3d2e6c7689334f022425a5a51a06b81d05d6979f\", \"best_bid\":\"0.996\", \"best_ask\":\"0.999\"}, {\"asset_id\":\"60386828328910021732068595344565885737045900010034836345809386672230885527307\", \"price\":\"0.99\", \"size\":\"5320\", \"side\":\"SELL\", \"hash\":\"2508532d8cb0eb7723802485f965ba9a84c56d5a\", \"best_bid\":\"0.001\", \"best_ask\":\"0.004\"}], \"timestamp\":\"1785127455115\", \"event_type\":\"price_change\"}","received_at":"2026-07-27T04:44:15.064773Z","schema_version":"clob-market-ws.price_change.v1","sequence":null,"server_hash":null,"server_timestamp":"1785127455115","session_id":"e9443c7415a0419799bee9cfbb1a9e4d","source":"clob_market_ws"},"received_at":"2026-07-27T04:44:15.064773Z","record_id":"7d4caca44d610e956c1b12bb75d905e1f83cf0d15a6bbfc3c1f8353265ac51ec","schema_fingerprint":"4aa3821a28b0b7c2400bc59aba4bcc0a76e971dadd19610d3ad38c768e124dc7","schema_version":"edge-lab-recorder.raw.v1","sequence":null,"source":"clob_market_ws"}
{"event_at":"2026-07-27T04:44:15.120000Z","event_fingerprint":"62a9ec03b0fe788055659ad04a26643677c1d29ea6a87923d991ca6c71f0b771","payload":{"connection_id":"0f4979d6978d463e9660b042fdcf555f","event_at":"2026-07-27T04:44:15.120000Z","event_type":"best_bid_ask","frame_hash":"fedbf779d9cddd2eb6717899886227923893c4ef94d10d18dd62c1ede37307fd","frame_index":0,"kind":"data","monotonic_ns":229438330213583,"payload":{"asset_id":"69697746896130839564035629862476347944307040470122503199396727085502753297492","best_ask":"0.999","best_bid":"0.997","event_type":"best_bid_ask","market":"0xeb66215f2e9faa6449e30a02bab5b8ed7b79a38bf961f6b24d0073c9c2419250","spread":"0.002","timestamp":"1785127455120"},"payload_hash":"19c51e195336dc9c7076095ba35cdcd31ade9482f9f502916981e7f22d85b2eb","raw_frame":"{\"market\":\"0xeb66215f2e9faa6449e30a02bab5b8ed7b79a38bf961f6b24d0073c9c2419250\", \"asset_id\":\"69697746896130839564035629862476347944307040470122503199396727085502753297492\", \"best_bid\":\"0.997\", \"best_ask\":\"0.999\", \"spread\":\"0.002\", \"timestamp\":\"1785127455120\", \"event_type\":\"best_bid_ask\"}","received_at":"2026-07-27T04:44:15.067786Z","schema_version":"clob-market-ws.best_bid_ask.v1","sequence":null,"server_hash":null,"server_timestamp":"1785127455120","session_id":"e9443c7415a0419799bee9cfbb1a9e4d","source":"clob_market_ws"},"received_at":"2026-07-27T04:44:15.067786Z","record_id":"807384b28e02b050afee4736548363695e11032ac3656d17ea452c94248a3dbe","schema_fingerprint":"8488399f31b0337811b13b266be932db7062827c2470b78bd8e9e99bab51d17d","schema_version":"edge-lab-recorder.raw.v1","sequence":null,"source":"clob_market_ws"}
{"event_at":"2026-07-27T04:44:15.120000Z","event_fingerprint":"6a010b00b57566033986d44e6ff0ed3b0f6e54ba6d4addddb1ffdf466c13a5d4","payload":{"connection_id":"0f4979d6978d463e9660b042fdcf555f","event_at":"2026-07-27T04:44:15.120000Z","event_type":"best_bid_ask","frame_hash":"e8b833b040d438a47c9a21aea5090d725db2f79e70196bd252067b606ee1aaca","frame_index":0,"kind":"data","monotonic_ns":229438331353375,"payload":{"asset_id":"60386828328910021732068595344565885737045900010034836345809386672230885527307","best_ask":"0.003","best_bid":"0.001","event_type":"best_bid_ask","market":"0xeb66215f2e9faa6449e30a02bab5b8ed7b79a38bf961f6b24d0073c9c2419250","spread":"0.002","timestamp":"1785127455120"},"payload_hash":"441a8c70e2095515d275096638f17ef9f7a5a216b6e0832472f53922cccd7e78","raw_frame":"{\"market\":\"0xeb66215f2e9faa6449e30a02bab5b8ed7b79a38bf961f6b24d0073c9c2419250\", \"asset_id\":\"60386828328910021732068595344565885737045900010034836345809386672230885527307\", \"best_bid\":\"0.001\", \"best_ask\":\"0.003\", \"spread\":\"0.002\", \"timestamp\":\"1785127455120\", \"event_type\":\"best_bid_ask\"}","received_at":"2026-07-27T04:44:15.068926Z","schema_version":"clob-market-ws.best_bid_ask.v1","sequence":null,"server_hash":null,"server_timestamp":"1785127455120","session_id":"e9443c7415a0419799bee9cfbb1a9e4d","source":"clob_market_ws"},"received_at":"2026-07-27T04:44:15.068926Z","record_id":"26f67204d137ef34de11e585ef924c8fc7ecf96168a4d6a0ab42832cfdc2ab5a","schema_fingerprint":"8488399f31b0337811b13b266be932db7062827c2470b78bd8e9e99bab51d17d","schema_version":"edge-lab-recorder.raw.v1","sequence":null,"source":"clob_market_ws"}
{"event_at":"2026-07-27T04:44:15.120000Z","event_fingerprint":"7522ab7aed215b34685bf5e016244516df146e9d79bacea042345fdc73e15b10","payload":{"connection_id":"0f4979d6978d463e9660b042fdcf555f","event_at":"2026-07-27T04:44:15.120000Z","event_type":"price_change","frame_hash":"44c342ccc7467476b13f6e7a69c29734e4498fb8e9c04b9b2a092dbd6ab9a1d2","frame_index":0,"kind":"data","monotonic_ns":229438332489541,"payload":{"event_type":"price_change","market":"0xeb66215f2e9faa6449e30a02bab5b8ed7b79a38bf961f6b24d0073c9c2419250","price_changes":[{"asset_id":"60386828328910021732068595344565885737045900010034836345809386672230885527307","best_ask":"0.003","best_bid":"0.001","hash":"13cd5f13e78b1094e49bcaff6eeec4a973c87f11","price":"0.003","side":"SELL","size":"275.12"},{"asset_id":"69697746896130839564035629862476347944307040470122503199396727085502753297492","best_ask":"0.999","best_bid":"0.997","hash":"6c2cb1e372d33056db2e466cdca4bdec44272e3e","price":"0.997","side":"BUY","size":"275.12"}],"timestamp":"1785127455120"},"payload_hash":"ed1000977e8ba07bcc6c9bc35ed2b3de0c0059454b3d6e4ee67d81a81bd0b040","raw_frame":"{\"market\":\"0xeb66215f2e9faa6449e30a02bab5b8ed7b79a38bf961f6b24d0073c9c2419250\", \"price_changes\":[{\"asset_id\":\"60386828328910021732068595344565885737045900010034836345809386672230885527307\", \"price\":\"0.003\", \"size\":\"275.12\", \"side\":\"SELL\", \"hash\":\"13cd5f13e78b1094e49bcaff6eeec4a973c87f11\", \"best_bid\":\"0.001\", \"best_ask\":\"0.003\"}, {\"asset_id\":\"69697746896130839564035629862476347944307040470122503199396727085502753297492\", \"price\":\"0.997\", \"size\":\"275.12\", \"side\":\"BUY\", \"hash\":\"6c2cb1e372d33056db2e466cdca4bdec44272e3e\", \"best_bid\":\"0.997\", \"best_ask\":\"0.999\"}], \"timestamp\":\"1785127455120\", \"event_type\":\"price_change\"}","received_at":"2026-07-27T04:44:15.070058Z","schema_version":"clob-market-ws.price_change.v1","sequence":null,"server_hash":null,"server_timestamp":"1785127455120","session_id":"e9443c7415a0419799bee9cfbb1a9e4d","source":"clob_market_ws"},"received_at":"2026-07-27T04:44:15.070058Z","record_id":"206df2c3d8c77c260b755ed77a3d6ac3a8f9260152154d3dcf0eaf5798726f0a","schema_fingerprint":"4aa3821a28b0b7c2400bc59aba4bcc0a76e971dadd19610d3ad38c768e124dc7","schema_version":"edge-lab-recorder.raw.v1","sequence":null,"source":"clob_market_ws"}
{"event_at":"2026-07-27T04:44:15.135000Z","event_fingerprint":"2470797cccccff71e47c8528c946501a12fa3d4e437887462013262fa8075844","payload":{"connection_id":"0f4979d6978d463e9660b042fdcf555f","event_at":"2026-07-27T04:44:15.135000Z","event_type":"price_change","frame_hash":"ba7f3ccd7909b89dd953b8fa537ae41f00772cb91d3e77510c9d041cbaa2b57f","frame_index":0,"kind":"data","monotonic_ns":229438345701916,"payload":{"event_type":"price_change","market":"0xeb66215f2e9faa6449e30a02bab5b8ed7b79a38bf961f6b24d0073c9c2419250","price_changes":[{"asset_id":"69697746896130839564035629862476347944307040470122503199396727085502753297492","best_ask":"0.999","best_bid":"0.997","hash":"324475d9caade37390bc74b6871baa0507252bd3","price":"0.01","side":"BUY","size":"5315"},{"asset_id":"60386828328910021732068595344565885737045900010034836345809386672230885527307","best_ask":"0.003","best_bid":"0.001","hash":"04caa81cec3100c710b3f2eb389dfa3a0fc8e2bc","price":"0.99","side":"SELL","size":"5315"}],"timestamp":"1785127455135"},"payload_hash":"b07382f5ae9a9058d022e73e350dbc3abeb90d7ec8ea72e8a29906b1ee36b362","raw_frame":"{\"market\":\"0xeb66215f2e9faa6449e30a02bab5b8ed7b79a38bf961f6b24d0073c9c2419250\", \"price_changes\":[{\"asset_id\":\"69697746896130839564035629862476347944307040470122503199396727085502753297492\", \"price\":\"0.01\", \"size\":\"5315\", \"side\":\"BUY\", \"hash\":\"324475d9caade37390bc74b6871baa0507252bd3\", \"best_bid\":\"0.997\", \"best_ask\":\"0.999\"}, {\"asset_id\":\"60386828328910021732068595344565885737045900010034836345809386672230885527307\", \"price\":\"0.99\", \"size\":\"5315\", \"side\":\"SELL\", \"hash\":\"04caa81cec3100c710b3f2eb389dfa3a0fc8e2bc\", \"best_bid\":\"0.001\", \"best_ask\":\"0.003\"}], \"timestamp\":\"1785127455135\", \"event_type\":\"price_change\"}","received_at":"2026-07-27T04:44:15.083280Z","schema_version":"clob-market-ws.price_change.v1","sequence":null,"server_hash":null,"server_timestamp":"1785127455135","session_id":"e9443c7415a0419799bee9cfbb1a9e4d","source":"clob_market_ws"},"received_at":"2026-07-27T04:44:15.083280Z","record_id":"c1b6eb94fd6b7b7b9076d7b31e5e0cae739f4e467cd0f1474ed85409cd423401","schema_fingerprint":"4aa3821a28b0b7c2400bc59aba4bcc0a76e971dadd19610d3ad38c768e124dc7","schema_version":"edge-lab-recorder.raw.v1","sequence":null,"source":"clob_market_ws"}
{"event_at":"2026-07-27T04:44:15.142000Z","event_fingerprint":"48d26a62917ada595f4ce2371e2136d4f55a953da7052afc9b17f971db167cdd","payload":{"connection_id":"0f4979d6978d463e9660b042fdcf555f","event_at":"2026-07-27T04:44:15.142000Z","event_type":"best_bid_ask","frame_hash":"bc436ee9f4624ab386ed7b4cfb2219037e8bb42539e639d83355b414e84cd649","frame_index":0,"kind":"data","monotonic_ns":229438352601125,"payload":{"asset_id":"69697746896130839564035629862476347944307040470122503199396727085502753297492","best_ask":"0.999","best_bid":"0.996","event_type":"best_bid_ask","market":"0xeb66215f2e9faa6449e30a02bab5b8ed7b79a38bf961f6b24d0073c9c2419250","spread":"0.003","timestamp":"1785127455142"},"payload_hash":"9a27f33cbbc67500cd766089b8634b2481ec707af454e55c999630749becc5fe","raw_frame":"{\"market\":\"0xeb66215f2e9faa6449e30a02bab5b8ed7b79a38bf961f6b24d0073c9c2419250\", \"asset_id\":\"69697746896130839564035629862476347944307040470122503199396727085502753297492\", \"best_bid\":\"0.996\", \"best_ask\":\"0.999\", \"spread\":\"0.003\", \"timestamp\":\"1785127455142\", \"event_type\":\"best_bid_ask\"}","received_at":"2026-07-27T04:44:15.090179Z","schema_version":"clob-market-ws.best_bid_ask.v1","sequence":null,"server_hash":null,"server_timestamp":"1785127455142","session_id":"e9443c7415a0419799bee9cfbb1a9e4d","source":"clob_market_ws"},"received_at":"2026-07-27T04:44:15.090179Z","record_id":"db11eb8c4f127f37f9f60548641541f01e3faa5edaedff999a097be844ef1818","schema_fingerprint":"8488399f31b0337811b13b266be932db7062827c2470b78bd8e9e99bab51d17d","schema_version":"edge-lab-recorder.raw.v1","sequence":null,"source":"clob_market_ws"}
{"event_at":"2026-07-27T04:44:15.142000Z","event_fingerprint":"7cb9dc901a681b8d3cdca4058d19e588adf822b0195bfa616ef2a5fdf51db416","payload":{"connection_id":"0f4979d6978d463e9660b042fdcf555f","event_at":"2026-07-27T04:44:15.142000Z","event_type":"best_bid_ask","frame_hash":"161edf424351e3bb8f38c584c0401928ca4e2c97e61900332a0760ceea045b8a","frame_index":0,"kind":"data","monotonic_ns":229438353052041,"payload":{"asset_id":"60386828328910021732068595344565885737045900010034836345809386672230885527307","best_ask":"0.004","best_bid":"0.001","event_type":"best_bid_ask","market":"0xeb66215f2e9faa6449e30a02bab5b8ed7b79a38bf961f6b24d0073c9c2419250","spread":"0.003","timestamp":"1785127455142"},"payload_hash":"481890a18eedd4385b33b3db78b709b9f0fe291259cc20ca71e0477da78d6f4b","raw_frame":"{\"market\":\"0xeb66215f2e9faa6449e30a02bab5b8ed7b79a38bf961f6b24d0073c9c2419250\", \"asset_id\":\"60386828328910021732068595344565885737045900010034836345809386672230885527307\", \"best_bid\":\"0.001\", \"best_ask\":\"0.004\", \"spread\":\"0.003\", \"timestamp\":\"1785127455142\", \"event_type\":\"best_bid_ask\"}","received_at":"2026-07-27T04:44:15.090632Z","schema_version":"clob-market-ws.best_bid_ask.v1","sequence":null,"server_hash":null,"server_timestamp":"1785127455142","session_id":"e9443c7415a0419799bee9cfbb1a9e4d","source":"clob_market_ws"},"received_at":"2026-07-27T04:44:15.090632Z","record_id":"8afac39b4748ac5b1726282420dae0fcde1913d09a2367bc8224fd5c39094d72","schema_fingerprint":"8488399f31b0337811b13b266be932db7062827c2470b78bd8e9e99bab51d17d","schema_version":"edge-lab-recorder.raw.v1","sequence":null,"source":"clob_market_ws"}
{"event_at":"2026-07-27T04:44:15.142000Z","event_fingerprint":"bbe492f195e9b7e5f23ecc3a4277cc5bcae432e536e2746eedc78e8143e643a0","payload":{"connection_id":"0f4979d6978d463e9660b042fdcf555f","event_at":"2026-07-27T04:44:15.142000Z","event_type":"price_change","frame_hash":"e94da86e0598337135a0d1ed2f40868f765f5ad59468d57572881d9c4fd53a4d","frame_index":0,"kind":"data","monotonic_ns":229438353451125,"payload":{"event_type":"price_change","market":"0xeb66215f2e9faa6449e30a02bab5b8ed7b79a38bf961f6b24d0073c9c2419250","price_changes":[{"asset_id":"60386828328910021732068595344565885737045900010034836345809386672230885527307","best_ask":"0.004","best_bid":"0.001","hash":"e51fd917f3ef09d7624938364c20903f0763516c","price":"0.003","side":"SELL","size":"0"},{"asset_id":"69697746896130839564035629862476347944307040470122503199396727085502753297492","best_ask":"0.999","best_bid":"0.996","hash":"63bbb6d60ea8b22e50dd2f19ecd7aa26a6433be2","price":"0.997","side":"BUY","size":"0"}],"timestamp":"1785127455142"},"payload_hash":"ed18ba4d0ce0034678fa563373efeb1aca8c5736407f087c3b393883a14204a3","raw_frame":"{\"market\":\"0xeb66215f2e9faa6449e30a02bab5b8ed7b79a38bf961f6b24d0073c9c2419250\", \"price_changes\":[{\"asset_id\":\"60386828328910021732068595344565885737045900010034836345809386672230885527307\", \"price\":\"0.003\", \"size\":\"0\", \"side\":\"SELL\", \"hash\":\"e51fd917f3ef09d7624938364c20903f0763516c\", \"best_bid\":\"0.001\", \"best_ask\":\"0.004\"}, {\"asset_id\":\"69697746896130839564035629862476347944307040470122503199396727085502753297492\", \"price\":\"0.997\", \"size\":\"0\", \"side\":\"BUY\", \"hash\":\"63bbb6d60ea8b22e50dd2f19ecd7aa26a6433be2\", \"best_bid\":\"0.996\", \"best_ask\":\"0.999\"}], \"timestamp\":\"1785127455142\", \"event_type\":\"price_change\"}","received_at":"2026-07-27T04:44:15.091031Z","schema_version":"clob-market-ws.price_change.v1","sequence":null,"server_hash":null,"server_timestamp":"1785127455142","session_id":"e9443c7415a0419799bee9cfbb1a9e4d","source":"clob_market_ws"},"received_at":"2026-07-27T04:44:15.091031Z","record_id":"a0a4bace6e6128124b9406872a8887f80610c8d507708a3cecbf21f99a58b445","schema_fingerprint":"4aa3821a28b0b7c2400bc59aba4bcc0a76e971dadd19610d3ad38c768e124dc7","schema_version":"edge-lab-recorder.raw.v1","sequence":null,"source":"clob_market_ws"}
{"event_at":"2026-07-27T04:44:15.145000Z","event_fingerprint":"8545322be4419308886e4684f33a0e16db4e6dd1180ec626090c8408dd6dddb6","payload":{"connection_id":"0f4979d6978d463e9660b042fdcf555f","event_at":"2026-07-27T04:44:15.145000Z","event_type":"price_change","frame_hash":"4780ba02b8993afb448124fdff16c7094089a9bd8df984fb5eae22e8d91c7ede","frame_index":0,"kind":"data","monotonic_ns":229438357118833,"payload":{"event_type":"price_change","market":"0xeb66215f2e9faa6449e30a02bab5b8ed7b79a38bf961f6b24d0073c9c2419250","price_changes":[{"asset_id":"69697746896130839564035629862476347944307040470122503199396727085502753297492","best_ask":"0.999","best_bid":"0.996","hash":"343a1eb1ff76194acbdc18b64a214200bc8466da","price":"0.02","side":"BUY","size":"530"},{"asset_id":"60386828328910021732068595344565885737045900010034836345809386672230885527307","best_ask":"0.004","best_bid":"0.001","hash":"79b4cfcb5aa6fc6020b54cbc3deda4228800fc1a","price":"0.98","side":"SELL","size":"530"}],"timestamp":"1785127455145"},"payload_hash":"08aed1cb0bc3ac8ce1bae47c8b5581e2707258c367b023a57902727d3f6f07dd","raw_frame":"{\"market\":\"0xeb66215f2e9faa6449e30a02bab5b8ed7b79a38bf961f6b24d0073c9c2419250\", \"price_changes\":[{\"asset_id\":\"69697746896130839564035629862476347944307040470122503199396727085502753297492\", \"price\":\"0.02\", \"size\":\"530\", \"side\":\"BUY\", \"hash\":\"343a1eb1ff76194acbdc18b64a214200bc8466da\", \"best_bid\":\"0.996\", \"best_ask\":\"0.999\"}, {\"asset_id\":\"60386828328910021732068595344565885737045900010034836345809386672230885527307\", \"price\":\"0.98\", \"size\":\"530\", \"side\":\"SELL\", \"hash\":\"79b4cfcb5aa6fc6020b54cbc3deda4228800fc1a\", \"best_bid\":\"0.001\", \"best_ask\":\"0.004\"}], \"timestamp\":\"1785127455145\", \"event_type\":\"price_change\"}","received_at":"2026-07-27T04:44:15.094698Z","schema_version":"clob-market-ws.price_change.v1","sequence":null,"server_hash":null,"server_timestamp":"1785127455145","session_id":"e9443c7415a0419799bee9cfbb1a9e4d","source":"clob_market_ws"},"received_at":"2026-07-27T04:44:15.094698Z","record_id":"53e73ba0a8fa2e21bc8f8f9d80fb6173b9b892c07776bac30f2a73d6f2b3b471","schema_fingerprint":"4aa3821a28b0b7c2400bc59aba4bcc0a76e971dadd19610d3ad38c768e124dc7","schema_version":"edge-lab-recorder.raw.v1","sequence":null,"source":"clob_market_ws"}
{"event_at":"2026-07-27T04:44:15.175000Z","event_fingerprint":"ab1b694f5ec3a3d656882e70cafb47f7b2354b22d9cf376038c2d2b8c82e2892","payload":{"connection_id":"0f4979d6978d463e9660b042fdcf555f","event_at":"2026-07-27T04:44:15.175000Z","event_type":"best_bid_ask","frame_hash":"f4a362d80da51c594a0830d9bd591862a7720a635eb4dffde623579d05ab0d78","frame_index":0,"kind":"data","monotonic_ns":229438385346208,"payload":{"asset_id":"69697746896130839564035629862476347944307040470122503199396727085502753297492","best_ask":"0.999","best_bid":"0.997","event_type":"best_bid_ask","market":"0xeb66215f2e9faa6449e30a02bab5b8ed7b79a38bf961f6b24d0073c9c2419250","spread":"0.002","timestamp":"1785127455175"},"payload_hash":"f7d39ab1c00db3311d0de2c6e3aaedacc06b96ae5aaa9a270bd26574565642f7","raw_frame":"{\"market\":\"0xeb66215f2e9faa6449e30a02bab5b8ed7b79a38bf961f6b24d0073c9c2419250\", \"asset_id\":\"69697746896130839564035629862476347944307040470122503199396727085502753297492\", \"best_bid\":\"0.997\", \"best_ask\":\"0.999\", \"spread\":\"0.002\", \"timestamp\":\"1785127455175\", \"event_type\":\"best_bid_ask\"}","received_at":"2026-07-27T04:44:15.122917Z","schema_version":"clob-market-ws.best_bid_ask.v1","sequence":null,"server_hash":null,"server_timestamp":"1785127455175","session_id":"e9443c7415a0419799bee9cfbb1a9e4d","source":"clob_market_ws"},"received_at":"2026-07-27T04:44:15.122917Z","record_id":"fb720f44f263a86e039829cec03fbb50fe84cd64e3a94caa11c515646d04e03c","schema_fingerprint":"8488399f31b0337811b13b266be932db7062827c2470b78bd8e9e99bab51d17d","schema_version":"edge-lab-recorder.raw.v1","sequence":null,"source":"clob_market_ws"}
{"event_at":"2026-07-27T04:44:15.175000Z","event_fingerprint":"8aeaad87a52e30b74b226c5f8acee9496e35bdd9d430523d7c4ccfc7f4678e19","payload":{"connection_id":"0f4979d6978d463e9660b042fdcf555f","event_at":"2026-07-27T04:44:15.175000Z","event_type":"best_bid_ask","frame_hash":"b2f9314f8575ec0fc2e52ab3b7d2562129282169fb78f5d360d45978c6ed5e3d","frame_index":0,"kind":"data","monotonic_ns":229438386500208,"payload":{"asset_id":"60386828328910021732068595344565885737045900010034836345809386672230885527307","best_ask":"0.003","best_bid":"0.001","event_type":"best_bid_ask","market":"0xeb66215f2e9faa6449e30a02bab5b8ed7b79a38bf961f6b24d0073c9c2419250","spread":"0.002","timestamp":"1785127455175"},"payload_hash":"e2f1b1c8eb558052a89f81e9b5a0e8e793467d81fa8c7ef073ffd15eb8643b34","raw_frame":"{\"market\":\"0xeb66215f2e9faa6449e30a02bab5b8ed7b79a38bf961f6b24d0073c9c2419250\", \"asset_id\":\"60386828328910021732068595344565885737045900010034836345809386672230885527307\", \"best_bid\":\"0.001\", \"best_ask\":\"0.003\", \"spread\":\"0.002\", \"timestamp\":\"1785127455175\", \"event_type\":\"best_bid_ask\"}","received_at":"2026-07-27T04:44:15.124074Z","schema_version":"clob-market-ws.best_bid_ask.v1","sequence":null,"server_hash":null,"server_timestamp":"1785127455175","session_id":"e9443c7415a0419799bee9cfbb1a9e4d","source":"clob_market_ws"},"received_at":"2026-07-27T04:44:15.124074Z","record_id":"e39191ec9725a9bf8f10dd847f723aad39b6305114b0cfd8577834675853359a","schema_fingerprint":"8488399f31b0337811b13b266be932db7062827c2470b78bd8e9e99bab51d17d","schema_version":"edge-lab-recorder.raw.v1","sequence":null,"source":"clob_market_ws"}
{"event_at":"2026-07-27T04:44:15.175000Z","event_fingerprint":"cac8db84dea95f294be918bfab4a1a11ba1198e0c0bfedfd67f868b621af9978","payload":{"connection_id":"0f4979d6978d463e9660b042fdcf555f","event_at":"2026-07-27T04:44:15.175000Z","event_type":"price_change","frame_hash":"df2d906c7ea5fe7a81d193fbff127b63b9ac8f2dd738076e01e3a0c57ae4cd05","frame_index":0,"kind":"data","monotonic_ns":229438389129791,"payload":{"event_type":"price_change","market":"0xeb66215f2e9faa6449e30a02bab5b8ed7b79a38bf961f6b24d0073c9c2419250","price_changes":[{"asset_id":"60386828328910021732068595344565885737045900010034836345809386672230885527307","best_ask":"0.003","best_bid":"0.001","hash":"4ee6f703bf67b9e1a54c2733099ef1f679cd1010","price":"0.003","side":"SELL","size":"275.12"},{"asset_id":"69697746896130839564035629862476347944307040470122503199396727085502753297492","best_ask":"0.999","best_bid":"0.997","hash":"b4a7eb2e080cf2ce0e4b913df596223656cc5491","price":"0.997","side":"BUY","size":"275.12"}],"timestamp":"1785127455175"},"payload_hash":"9d8b52a37780d5fcd85d28ec97bb52380bbdee4f4dea555d5f2d207db2f0b151","raw_frame":"{\"market\":\"0xeb66215f2e9faa6449e30a02bab5b8ed7b79a38bf961f6b24d0073c9c2419250\", \"price_changes\":[{\"asset_id\":\"60386828328910021732068595344565885737045900010034836345809386672230885527307\", \"price\":\"0.003\", \"size\":\"275.12\", \"side\":\"SELL\", \"hash\":\"4ee6f703bf67b9e1a54c2733099ef1f679cd1010\", \"best_bid\":\"0.001\", \"best_ask\":\"0.003\"}, {\"asset_id\":\"69697746896130839564035629862476347944307040470122503199396727085502753297492\", \"price\":\"0.997\", \"size\":\"275.12\", \"side\":\"BUY\", \"hash\":\"b4a7eb2e080cf2ce0e4b913df596223656cc5491\", \"best_bid\":\"0.997\", \"best_ask\":\"0.999\"}], \"timestamp\":\"1785127455175\", \"event_type\":\"price_change\"}","received_at":"2026-07-27T04:44:15.126700Z","schema_version":"clob-market-ws.price_change.v1","sequence":null,"server_hash":null,"server_timestamp":"1785127455175","session_id":"e9443c7415a0419799bee9cfbb1a9e4d","source":"clob_market_ws"},"received_at":"2026-07-27T04:44:15.126700Z","record_id":"895d0ab6cf6e8af60665d858f09e0327b5d8f2e89a79e557007a4ba79c6a729d","schema_fingerprint":"4aa3821a28b0b7c2400bc59aba4bcc0a76e971dadd19610d3ad38c768e124dc7","schema_version":"edge-lab-recorder.raw.v1","sequence":null,"source":"clob_market_ws"}
{"event_at":"2026-07-27T04:44:15.192000Z","event_fingerprint":"c1e755edefab388e170c8572ef814f25dbb8f662d9b35525a9185efb9017c3cb","payload":{"connection_id":"0f4979d6978d463e9660b042fdcf555f","event_at":"2026-07-27T04:44:15.192000Z","event_type":"best_bid_ask","frame_hash":"bef1e0a5625743163e38dfe5e90773a601f68b25b2ddd0480a199abf89c6e333","frame_index":0,"kind":"data","monotonic_ns":229438402694666,"payload":{"asset_id":"69697746896130839564035629862476347944307040470122503199396727085502753297492","best_ask":"0.999","best_bid":"0.996","event_type":"best_bid_ask","market":"0xeb66215f2e9faa6449e30a02bab5b8ed7b79a38bf961f6b24d0073c9c2419250","spread":"0.003","timestamp":"1785127455192"},"payload_hash":"56a9b96d82e767efeb8bb6b6ca8f1b267db8379a1d1c6407c2ee7a7766a8811b","raw_frame":"{\"market\":\"0xeb66215f2e9faa6449e30a02bab5b8ed7b79a38bf961f6b24d0073c9c2419250\", \"asset_id\":\"69697746896130839564035629862476347944307040470122503199396727085502753297492\", \"best_bid\":\"0.996\", \"best_ask\":\"0.999\", \"spread\":\"0.003\", \"timestamp\":\"1785127455192\", \"event_type\":\"best_bid_ask\"}","received_at":"2026-07-27T04:44:15.140266Z","schema_version":"clob-market-ws.best_bid_ask.v1","sequence":null,"server_hash":null,"server_timestamp":"1785127455192","session_id":"e9443c7415a0419799bee9cfbb1a9e4d","source":"clob_market_ws"},"received_at":"2026-07-27T04:44:15.140266Z","record_id":"654c52c7ab1e9ef9df65b5782c1c2dc14328e2ba20ce115534383dd965326fef","schema_fingerprint":"8488399f31b0337811b13b266be932db7062827c2470b78bd8e9e99bab51d17d","schema_version":"edge-lab-recorder.raw.v1","sequence":null,"source":"clob_market_ws"}
{"event_at":"2026-07-27T04:44:15.192000Z","event_fingerprint":"0af34f4fafa4c8f77d94a423b61f022b0b26ffd5a8f21ef0d14910ccefa1a4f5","payload":{"connection_id":"0f4979d6978d463e9660b042fdcf555f","event_at":"2026-07-27T04:44:15.192000Z","event_type":"best_bid_ask","frame_hash":"36af28864d6acdeece0d54260b555b46da9da6337b74c8981e8225de7bf71ae6","frame_index":0,"kind":"data","monotonic_ns":229438403894375,"payload":{"asset_id":"60386828328910021732068595344565885737045900010034836345809386672230885527307","best_ask":"0.004","best_bid":"0.001","event_type":"best_bid_ask","market":"0xeb66215f2e9faa6449e30a02bab5b8ed7b79a38bf961f6b24d0073c9c2419250","spread":"0.003","timestamp":"1785127455192"},"payload_hash":"0295a6f861ecc0133a782087da85849cd1757fc43897fa4e0d6ffcaabce139bd","raw_frame":"{\"market\":\"0xeb66215f2e9faa6449e30a02bab5b8ed7b79a38bf961f6b24d0073c9c2419250\", \"asset_id\":\"60386828328910021732068595344565885737045900010034836345809386672230885527307\", \"best_bid\":\"0.001\", \"best_ask\":\"0.004\", \"spread\":\"0.003\", \"timestamp\":\"1785127455192\", \"event_type\":\"best_bid_ask\"}","received_at":"2026-07-27T04:44:15.141459Z","schema_version":"clob-market-ws.best_bid_ask.v1","sequence":null,"server_hash":null,"server_timestamp":"1785127455192","session_id":"e9443c7415a0419799bee9cfbb1a9e4d","source":"clob_market_ws"},"received_at":"2026-07-27T04:44:15.141459Z","record_id":"1c5fb5b92be1d07cbb02154f9ce1e84a62147f91c0bb79a47022a0c54febf27e","schema_fingerprint":"8488399f31b0337811b13b266be932db7062827c2470b78bd8e9e99bab51d17d","schema_version":"edge-lab-recorder.raw.v1","sequence":null,"source":"clob_market_ws"}
{"event_at":"2026-07-27T04:44:15.192000Z","event_fingerprint":"ef3f5564380ef481080d70aa2f5cd8a8ba8e0cba835ea3ea39480b28e398e8e2","payload":{"connection_id":"0f4979d6978d463e9660b042fdcf555f","event_at":"2026-07-27T04:44:15.192000Z","event_type":"price_change","frame_hash":"77fca6c0f3e6da905a0b6fd5f9913c99c277ea7707a27a0086cbc21eee423d11","frame_index":0,"kind":"data","monotonic_ns":229438404572166,"payload":{"event_type":"price_change","market":"0xeb66215f2e9faa6449e30a02bab5b8ed7b79a38bf961f6b24d0073c9c2419250","price_changes":[{"asset_id":"60386828328910021732068595344565885737045900010034836345809386672230885527307","best_ask":"0.004","best_bid":"0.001","hash":"2cbbca8d3fdafe658c1529809d9ac371471d9c0e","price":"0.003","side":"SELL","size":"0"},{"asset_id":"69697746896130839564035629862476347944307040470122503199396727085502753297492","best_ask":"0.999","best_bid":"0.996","hash":"8837b67a7edc89877b4987b7ebc179bd48248792","price":"0.997","side":"BUY","size":"0"}],"timestamp":"1785127455192"},"payload_hash":"a0c3861e3064978faa1d335759d07f7833bee33e70abbaa0bad563d05185d47e","raw_frame":"{\"market\":\"0xeb66215f2e9faa6449e30a02bab5b8ed7b79a38bf961f6b24d0073c9c2419250\", \"price_changes\":[{\"asset_id\":\"60386828328910021732068595344565885737045900010034836345809386672230885527307\", \"price\":\"0.003\", \"size\":\"0\", \"side\":\"SELL\", \"hash\":\"2cbbca8d3fdafe658c1529809d9ac371471d9c0e\", \"best_bid\":\"0.001\", \"best_ask\":\"0.004\"}, {\"asset_id\":\"69697746896130839564035629862476347944307040470122503199396727085502753297492\", \"price\":\"0.997\", \"size\":\"0\", \"side\":\"BUY\", \"hash\":\"8837b67a7edc89877b4987b7ebc179bd48248792\", \"best_bid\":\"0.996\", \"best_ask\":\"0.999\"}], \"timestamp\":\"1785127455192\", \"event_type\":\"price_change\"}","received_at":"2026-07-27T04:44:15.142153Z","schema_version":"clob-market-ws.price_change.v1","sequence":null,"server_hash":null,"server_timestamp":"1785127455192","session_id":"e9443c7415a0419799bee9cfbb1a9e4d","source":"clob_market_ws"},"received_at":"2026-07-27T04:44:15.142153Z","record_id":"77bb119ea6e65976ce1f4b0e1b5b23cec133bee71bf422a9335cfc65a8edb0d7","schema_fingerprint":"4aa3821a28b0b7c2400bc59aba4bcc0a76e971dadd19610d3ad38c768e124dc7","schema_version":"edge-lab-recorder.raw.v1","sequence":null,"source":"clob_market_ws"}
{"event_at":"2026-07-27T04:44:15.205000Z","event_fingerprint":"1313bd1b9420d5a531dec57615c40a8a4263d4d44bdc5a02e5da57bf8b78a097","payload":{"connection_id":"0f4979d6978d463e9660b042fdcf555f","event_at":"2026-07-27T04:44:15.205000Z","event_type":"price_change","frame_hash":"76b0151d31d4f4da69b4ad85f3b311370f5dd21a6cd96fba38b120e47d8ea6b4","frame_index":0,"kind":"data","monotonic_ns":229438416381791,"payload":{"event_type":"price_change","market":"0xeb66215f2e9faa6449e30a02bab5b8ed7b79a38bf961f6b24d0073c9c2419250","price_changes":[{"asset_id":"69697746896130839564035629862476347944307040470122503199396727085502753297492","best_ask":"0.999","best_bid":"0.996","hash":"9562737882664774a3256644956222b0dd4b2448","price":"0.02","side":"BUY","size":"525"},{"asset_id":"60386828328910021732068595344565885737045900010034836345809386672230885527307","best_ask":"0.004","best_bid":"0.001","hash":"d6fa765a6e5c624d3f75bc5dba131aeb1ce31443","price":"0.98","side":"SELL","size":"525"}],"timestamp":"1785127455205"},"payload_hash":"e964e190b74908676e401934732f6afbeea0cc0669eb23889aed3a093a96eb10","raw_frame":"{\"market\":\"0xeb66215f2e9faa6449e30a02bab5b8ed7b79a38bf961f6b24d0073c9c2419250\", \"price_changes\":[{\"asset_id\":\"69697746896130839564035629862476347944307040470122503199396727085502753297492\", \"price\":\"0.02\", \"size\":\"525\", \"side\":\"BUY\", \"hash\":\"9562737882664774a3256644956222b0dd4b2448\", \"best_bid\":\"0.996\", \"best_ask\":\"0.999\"}, {\"asset_id\":\"60386828328910021732068595344565885737045900010034836345809386672230885527307\", \"price\":\"0.98\", \"size\":\"525\", \"side\":\"SELL\", \"hash\":\"d6fa765a6e5c624d3f75bc5dba131aeb1ce31443\", \"best_bid\":\"0.001\", \"best_ask\":\"0.004\"}], \"timestamp\":\"1785127455205\", \"event_type\":\"price_change\"}","received_at":"2026-07-27T04:44:15.153954Z","schema_version":"clob-market-ws.price_change.v1","sequence":null,"server_hash":null,"server_timestamp":"1785127455205","session_id":"e9443c7415a0419799bee9cfbb1a9e4d","source":"clob_market_ws"},"received_at":"2026-07-27T04:44:15.153954Z","record_id":"6a6f3d094087fbf38930132b2415297c64d178b55b6f1b46495db911d96cb68f","schema_fingerprint":"4aa3821a28b0b7c2400bc59aba4bcc0a76e971dadd19610d3ad38c768e124dc7","schema_version":"edge-lab-recorder.raw.v1","sequence":null,"source":"clob_market_ws"}
{"event_at":"2026-07-27T04:44:15.223000Z","event_fingerprint":"a046a68d17417a978e508ccd59f4390ad6c0fb41e378001be52c01117e292282","payload":{"connection_id":"0f4979d6978d463e9660b042fdcf555f","event_at":"2026-07-27T04:44:15.223000Z","event_type":"best_bid_ask","frame_hash":"9311d838bcd46ca69d8cd69419083d11101718c919541e3fcb8ae2c569d2c394","frame_index":0,"kind":"data","monotonic_ns":229438433798541,"payload":{"asset_id":"69697746896130839564035629862476347944307040470122503199396727085502753297492","best_ask":"0.999","best_bid":"0.997","event_type":"best_bid_ask","market":"0xeb66215f2e9faa6449e30a02bab5b8ed7b79a38bf961f6b24d0073c9c2419250","spread":"0.002","timestamp":"1785127455223"},"payload_hash":"0c28e5f31caa63a98f16ed4512ebc343770b0a410072faedb665f0d6a2e712d1","raw_frame":"{\"market\":\"0xeb66215f2e9faa6449e30a02bab5b8ed7b79a38bf961f6b24d0073c9c2419250\", \"asset_id\":\"69697746896130839564035629862476347944307040470122503199396727085502753297492\", \"best_bid\":\"0.997\", \"best_ask\":\"0.999\", \"spread\":\"0.002\", \"timestamp\":\"1785127455223\", \"event_type\":\"best_bid_ask\"}","received_at":"2026-07-27T04:44:15.171370Z","schema_version":"clob-market-ws.best_bid_ask.v1","sequence":null,"server_hash":null,"server_timestamp":"1785127455223","session_id":"e9443c7415a0419799bee9cfbb1a9e4d","source":"clob_market_ws"},"received_at":"2026-07-27T04:44:15.171370Z","record_id":"71938393e3ef7f45a83871b8bb2ffd250c2479806321272da72473df939eea6a","schema_fingerprint":"8488399f31b0337811b13b266be932db7062827c2470b78bd8e9e99bab51d17d","schema_version":"edge-lab-recorder.raw.v1","sequence":null,"source":"clob_market_ws"}
{"event_at":"2026-07-27T04:44:15.223000Z","event_fingerprint":"e2637c193cc08cbce69dd3b62908726e09592becea2c2fb002b36947b4962f00","payload":{"connection_id":"0f4979d6978d463e9660b042fdcf555f","event_at":"2026-07-27T04:44:15.223000Z","event_type":"best_bid_ask","frame_hash":"0172d1d7357e1500c2ab2a47b42d06cb7d59a72a07db82163d441eb5a9711d51","frame_index":0,"kind":"data","monotonic_ns":229438434264958,"payload":{"asset_id":"60386828328910021732068595344565885737045900010034836345809386672230885527307","best_ask":"0.003","best_bid":"0.001","event_type":"best_bid_ask","market":"0xeb66215f2e9faa6449e30a02bab5b8ed7b79a38bf961f6b24d0073c9c2419250","spread":"0.002","timestamp":"1785127455223"},"payload_hash":"537f942d00a977ce83cb287348afe14c62e1789a5d6a62f3c91e1b807b849bc7","raw_frame":"{\"market\":\"0xeb66215f2e9faa6449e30a02bab5b8ed7b79a38bf961f6b24d0073c9c2419250\", \"asset_id\":\"60386828328910021732068595344565885737045900010034836345809386672230885527307\", \"best_bid\":\"0.001\", \"best_ask\":\"0.003\", \"spread\":\"0.002\", \"timestamp\":\"1785127455223\", \"event_type\":\"best_bid_ask\"}","received_at":"2026-07-27T04:44:15.171846Z","schema_version":"clob-market-ws.best_bid_ask.v1","sequence":null,"server_hash":null,"server_timestamp":"1785127455223","session_id":"e9443c7415a0419799bee9cfbb1a9e4d","source":"clob_market_ws"},"received_at":"2026-07-27T04:44:15.171846Z","record_id":"5870fde5293ce69d46539f1bcadf28fbd468a3123075d044e556770fe751bf24","schema_fingerprint":"8488399f31b0337811b13b266be932db7062827c2470b78bd8e9e99bab51d17d","schema_version":"edge-lab-recorder.raw.v1","sequence":null,"source":"clob_market_ws"}
{"event_at":"2026-07-27T04:44:15.223000Z","event_fingerprint":"7910030c340f16b86ce2ccfc8d59fd89eff9a5ca17634eaaed6497fc571d6367","payload":{"connection_id":"0f4979d6978d463e9660b042fdcf555f","event_at":"2026-07-27T04:44:15.223000Z","event_type":"price_change","frame_hash":"885b2ef244db63344feb1f3c3e100c028b040aa06d36429c260181d2b4667e4c","frame_index":0,"kind":"data","monotonic_ns":229438435174958,"payload":{"event_type":"price_change","market":"0xeb66215f2e9faa6449e30a02bab5b8ed7b79a38bf961f6b24d0073c9c2419250","price_changes":[{"asset_id":"60386828328910021732068595344565885737045900010034836345809386672230885527307","best_ask":"0.003","best_bid":"0.001","hash":"7aaaeb811d0a4fbe3584f454555106f49f06ed6e","price":"0.003","side":"SELL","size":"275.12"},{"asset_id":"69697746896130839564035629862476347944307040470122503199396727085502753297492","best_ask":"0.999","best_bid":"0.997","hash":"a7d71316b95890f20edb6145c346cc43d5415a5a","price":"0.997","side":"BUY","size":"275.12"}],"timestamp":"1785127455223"},"payload_hash":"a7da26d139fa11c7ba4c635ad9498322692a3356551f296a0e89d6e87025e8fd","raw_frame":"{\"market\":\"0xeb66215f2e9faa6449e30a02bab5b8ed7b79a38bf961f6b24d0073c9c2419250\", \"price_changes\":[{\"asset_id\":\"60386828328910021732068595344565885737045900010034836345809386672230885527307\", \"price\":\"0.003\", \"size\":\"275.12\", \"side\":\"SELL\", \"hash\":\"7aaaeb811d0a4fbe3584f454555106f49f06ed6e\", \"best_bid\":\"0.001\", \"best_ask\":\"0.003\"}, {\"asset_id\":\"69697746896130839564035629862476347944307040470122503199396727085502753297492\", \"price\":\"0.997\", \"size\":\"275.12\", \"side\":\"BUY\", \"hash\":\"a7d71316b95890f20edb6145c346cc43d5415a5a\", \"best_bid\":\"0.997\", \"best_ask\":\"0.999\"}], \"timestamp\":\"1785127455223\", \"event_type\":\"price_change\"}","received_at":"2026-07-27T04:44:15.172746Z","schema_version":"clob-market-ws.price_change.v1","sequence":null,"server_hash":null,"server_timestamp":"1785127455223","session_id":"e9443c7415a0419799bee9cfbb1a9e4d","source":"clob_market_ws"},"received_at":"2026-07-27T04:44:15.172746Z","record_id":"6f0b8412e6090104bb6b08464543776a5e6b4c53dc372f8012bc26cd31bc8b72","schema_fingerprint":"4aa3821a28b0b7c2400bc59aba4bcc0a76e971dadd19610d3ad38c768e124dc7","schema_version":"edge-lab-recorder.raw.v1","sequence":null,"source":"clob_market_ws"}
{"event_at":"2026-07-27T04:44:15.249000Z","event_fingerprint":"3a95893d0fdf4a57dca84ab46d9f0939e17a55d79c5dd730bbe58ddbf5e366b4","payload":{"connection_id":"0f4979d6978d463e9660b042fdcf555f","event_at":"2026-07-27T04:44:15.249000Z","event_type":"best_bid_ask","frame_hash":"06bd936b3ebade67813c4497210f6f11ae1461f52fd647018ad946f34de1924e","frame_index":0,"kind":"data","monotonic_ns":229438459942416,"payload":{"asset_id":"69697746896130839564035629862476347944307040470122503199396727085502753297492","best_ask":"0.999","best_bid":"0.996","event_type":"best_bid_ask","market":"0xeb66215f2e9faa6449e30a02bab5b8ed7b79a38bf961f6b24d0073c9c2419250","spread":"0.003","timestamp":"1785127455249"},"payload_hash":"16fd5aafcca9bea532d12335bf9964a2c35db8fb901380095ad4155b49cb9c17","raw_frame":"{\"market\":\"0xeb66215f2e9faa6449e30a02bab5b8ed7b79a38bf961f6b24d0073c9c2419250\", \"asset_id\":\"69697746896130839564035629862476347944307040470122503199396727085502753297492\", \"best_bid\":\"0.996\", \"best_ask\":\"0.999\", \"spread\":\"0.003\", \"timestamp\":\"1785127455249\", \"event_type\":\"best_bid_ask\"}","received_at":"2026-07-27T04:44:15.197515Z","schema_version":"clob-market-ws.best_bid_ask.v1","sequence":null,"server_hash":null,"server_timestamp":"1785127455249","session_id":"e9443c7415a0419799bee9cfbb1a9e4d","source":"clob_market_ws"},"received_at":"2026-07-27T04:44:15.197515Z","record_id":"79076d2c84a18841778dfb94dd9622fcfcff89205e7b0a06c9af4cc6384d9ecb","schema_fingerprint":"8488399f31b0337811b13b266be932db7062827c2470b78bd8e9e99bab51d17d","schema_version":"edge-lab-recorder.raw.v1","sequence":null,"source":"clob_market_ws"}
{"event_at":"2026-07-27T04:44:15.249000Z","event_fingerprint":"cb14e5a326f8ada467865fc5be8fde9628303f133c44ca050efe7c1b524feb45","payload":{"connection_id":"0f4979d6978d463e9660b042fdcf555f","event_at":"2026-07-27T04:44:15.249000Z","event_type":"best_bid_ask","frame_hash":"12af4e59688c934c8667104d9b19296f6b9318cb634682a7682383de405aa4ef","frame_index":0,"kind":"data","monotonic_ns":229438462650458,"payload":{"asset_id":"60386828328910021732068595344565885737045900010034836345809386672230885527307","best_ask":"0.004","best_bid":"0.001","event_type":"best_bid_ask","market":"0xeb66215f2e9faa6449e30a02bab5b8ed7b79a38bf961f6b24d0073c9c2419250","spread":"0.003","timestamp":"1785127455249"},"payload_hash":"58cbb8f2585d6c232191e89798da8acb67eb0381dff3fc18ad1b7f37d18ae077","raw_frame":"{\"market\":\"0xeb66215f2e9faa6449e30a02bab5b8ed7b79a38bf961f6b24d0073c9c2419250\", \"asset_id\":\"60386828328910021732068595344565885737045900010034836345809386672230885527307\", \"best_bid\":\"0.001\", \"best_ask\":\"0.004\", \"spread\":\"0.003\", \"timestamp\":\"1785127455249\", \"event_type\":\"best_bid_ask\"}","received_at":"2026-07-27T04:44:15.200225Z","schema_version":"clob-market-ws.best_bid_ask.v1","sequence":null,"server_hash":null,"server_timestamp":"1785127455249","session_id":"e9443c7415a0419799bee9cfbb1a9e4d","source":"clob_market_ws"},"received_at":"2026-07-27T04:44:15.200225Z","record_id":"e24292295416b271f2ed7e40c3a214c3d896f283742759f5ef97abf26c16f551","schema_fingerprint":"8488399f31b0337811b13b266be932db7062827c2470b78bd8e9e99bab51d17d","schema_version":"edge-lab-recorder.raw.v1","sequence":null,"source":"clob_market_ws"}
{"event_at":"2026-07-27T04:44:15.249000Z","event_fingerprint":"b7a6aac5fdab4ae48185c6599c10ea652b702e64bfc9899e12f7a2a186516a71","payload":{"connection_id":"0f4979d6978d463e9660b042fdcf555f","event_at":"2026-07-27T04:44:15.249000Z","event_type":"price_change","frame_hash":"6f17c78f4d37d6d9bcbf1f2143ff58e2a95a2c61edcf636434a20effe5393d10","frame_index":0,"kind":"data","monotonic_ns":229438465185541,"payload":{"event_type":"price_change","market":"0xeb66215f2e9faa6449e30a02bab5b8ed7b79a38bf961f6b24d0073c9c2419250","price_changes":[{"asset_id":"60386828328910021732068595344565885737045900010034836345809386672230885527307","best_ask":"0.004","best_bid":"0.001","hash":"24d07ad6134683992957629f30ccbbb9cf19ff6e","price":"0.003","side":"SELL","size":"0"},{"asset_id":"69697746896130839564035629862476347944307040470122503199396727085502753297492","best_ask":"0.999","best_bid":"0.996","hash":"925a882b384c80bf703418177159840c351729ef","price":"0.997","side":"BUY","size":"0"}],"timestamp":"1785127455249"},"payload_hash":"6ba1c49f516410fbf4731d380631428d39dadba30d1826db227f8a8e77066da3","raw_frame":"{\"market\":\"0xeb66215f2e9faa6449e30a02bab5b8ed7b79a38bf961f6b24d0073c9c2419250\", \"price_changes\":[{\"asset_id\":\"60386828328910021732068595344565885737045900010034836345809386672230885527307\", \"price\":\"0.003\", \"size\":\"0\", \"side\":\"SELL\", \"hash\":\"24d07ad6134683992957629f30ccbbb9cf19ff6e\", \"best_bid\":\"0.001\", \"best_ask\":\"0.004\"}, {\"asset_id\":\"69697746896130839564035629862476347944307040470122503199396727085502753297492\", \"price\":\"0.997\", \"size\":\"0\", \"side\":\"BUY\", \"hash\":\"925a882b384c80bf703418177159840c351729ef\", \"best_bid\":\"0.996\", \"best_ask\":\"0.999\"}], \"timestamp\":\"1785127455249\", \"event_type\":\"price_change\"}","received_at":"2026-07-27T04:44:15.202761Z","schema_version":"clob-market-ws.price_change.v1","sequence":null,"server_hash":null,"server_timestamp":"1785127455249","session_id":"e9443c7415a0419799bee9cfbb1a9e4d","source":"clob_market_ws"},"received_at":"2026-07-27T04:44:15.202761Z","record_id":"c3f67bf98a10d4f10ae5909b02fcfb9a61d6828098858eaa436b23391f160028","schema_fingerprint":"4aa3821a28b0b7c2400bc59aba4bcc0a76e971dadd19610d3ad38c768e124dc7","schema_version":"edge-lab-recorder.raw.v1","sequence":null,"source":"clob_market_ws"}
{"event_at":"2026-07-27T04:44:15.257000Z","event_fingerprint":"32c3122f7fc20c35d017396d440beab7ace37cae5146e36dd2ae8bc11f2acecb","payload":{"connection_id":"0f4979d6978d463e9660b042fdcf555f","event_at":"2026-07-27T04:44:15.257000Z","event_type":"price_change","frame_hash":"7ba53360bd0bc6c0d3e9b38b13a15f7d44676d4ffb22d365819be7896ce6774e","frame_index":0,"kind":"data","monotonic_ns":229438467329958,"payload":{"event_type":"price_change","market":"0xeb66215f2e9faa6449e30a02bab5b8ed7b79a38bf961f6b24d0073c9c2419250","price_changes":[{"asset_id":"69697746896130839564035629862476347944307040470122503199396727085502753297492","best_ask":"0.999","best_bid":"0.996","hash":"a87809b8fa7dce96c4a81ba10d6f9c1981aaf6a0","price":"0.01","side":"BUY","size":"5320"},{"asset_id":"60386828328910021732068595344565885737045900010034836345809386672230885527307","best_ask":"0.004","best_bid":"0.001","hash":"8c28a3f3d9d3f3dec89546e8db51c90b5cfd17c5","price":"0.99","side":"SELL","size":"5320"}],"timestamp":"1785127455257"},"payload_hash":"9d074bb1457d95c2d887b4c68caaeb74b9533cc573031651787aa0018907a63f","raw_frame":"{\"market\":\"0xeb66215f2e9faa6449e30a02bab5b8ed7b79a38bf961f6b24d0073c9c2419250\", \"price_changes\":[{\"asset_id\":\"69697746896130839564035629862476347944307040470122503199396727085502753297492\", \"price\":\"0.01\", \"size\":\"5320\", \"side\":\"BUY\", \"hash\":\"a87809b8fa7dce96c4a81ba10d6f9c1981aaf6a0\", \"best_bid\":\"0.996\", \"best_ask\":\"0.999\"}, {\"asset_id\":\"60386828328910021732068595344565885737045900010034836345809386672230885527307\", \"price\":\"0.99\", \"size\":\"5320\", \"side\":\"SELL\", \"hash\":\"8c28a3f3d9d3f3dec89546e8db51c90b5cfd17c5\", \"best_bid\":\"0.001\", \"best_ask\":\"0.004\"}], \"timestamp\":\"1785127455257\", \"event_type\":\"price_change\"}","received_at":"2026-07-27T04:44:15.204910Z","schema_version":"clob-market-ws.price_change.v1","sequence":null,"server_hash":null,"server_timestamp":"1785127455257","session_id":"e9443c7415a0419799bee9cfbb1a9e4d","source":"clob_market_ws"},"received_at":"2026-07-27T04:44:15.204910Z","record_id":"163f2263e490732716abcb154ee5f4113bbb5774dd1b958f63871987181841ca","schema_fingerprint":"4aa3821a28b0b7c2400bc59aba4bcc0a76e971dadd19610d3ad38c768e124dc7","schema_version":"edge-lab-recorder.raw.v1","sequence":null,"source":"clob_market_ws"}
{"event_at":"2026-07-27T04:44:15.276000Z","event_fingerprint":"334d8d8e9b04ed89cf0a8beebaa4e10f9ab78bcaf366a2bacd3705e4b38776d0","payload":{"connection_id":"0f4979d6978d463e9660b042fdcf555f","event_at":"2026-07-27T04:44:15.276000Z","event_type":"best_bid_ask","frame_hash":"2f52b9af6e0f969c18540c1f3bef0bf4caf8e845f80076d3175755aafb1e10a0","frame_index":0,"kind":"data","monotonic_ns":229438486435541,"payload":{"asset_id":"69697746896130839564035629862476347944307040470122503199396727085502753297492","best_ask":"0.999","best_bid":"0.997","event_type":"best_bid_ask","market":"0xeb66215f2e9faa6449e30a02bab5b8ed7b79a38bf961f6b24d0073c9c2419250","spread":"0.002","timestamp":"1785127455276"},"payload_hash":"499deea56d98432ea53d70144111e31e6a07d8ea3aacda937bca9ac1a3f80747","raw_frame":"{\"market\":\"0xeb66215f2e9faa6449e30a02bab5b8ed7b79a38bf961f6b24d0073c9c2419250\", \"asset_id\":\"69697746896130839564035629862476347944307040470122503199396727085502753297492\", \"best_bid\":\"0.997\", \"best_ask\":\"0.999\", \"spread\":\"0.002\", \"timestamp\":\"1785127455276\", \"event_type\":\"best_bid_ask\"}","received_at":"2026-07-27T04:44:15.224006Z","schema_version":"clob-market-ws.best_bid_ask.v1","sequence":null,"server_hash":null,"server_timestamp":"1785127455276","session_id":"e9443c7415a0419799bee9cfbb1a9e4d","source":"clob_market_ws"},"received_at":"2026-07-27T04:44:15.224006Z","record_id":"34fb6bffe3a3a1b234aa742fbdb7cc80124095abceea0c25d498742f0fb7de0b","schema_fingerprint":"8488399f31b0337811b13b266be932db7062827c2470b78bd8e9e99bab51d17d","schema_version":"edge-lab-recorder.raw.v1","sequence":null,"source":"clob_market_ws"}
{"event_at":"2026-07-27T04:44:15.276000Z","event_fingerprint":"8e596d86123a753821af03d8f1b4b57772a8501cddc34f0aaeaf8f4a432e36e9","payload":{"connection_id":"0f4979d6978d463e9660b042fdcf555f","event_at":"2026-07-27T04:44:15.276000Z","event_type":"best_bid_ask","frame_hash":"45e56fa5f08db3172db363bea5de65e4dac5997a2fc5eda765c399b6521a0e93","frame_index":0,"kind":"data","monotonic_ns":229438487622708,"payload":{"asset_id":"60386828328910021732068595344565885737045900010034836345809386672230885527307","best_ask":"0.003","best_bid":"0.001","event_type":"best_bid_ask","market":"0xeb66215f2e9faa6449e30a02bab5b8ed7b79a38bf961f6b24d0073c9c2419250","spread":"0.002","timestamp":"1785127455276"},"payload_hash":"e32134f4cab2e96673389f885b7f09ef39e3ce3ea1ce5c06bc353b10b30695ab","raw_frame":"{\"market\":\"0xeb66215f2e9faa6449e30a02bab5b8ed7b79a38bf961f6b24d0073c9c2419250\", \"asset_id\":\"60386828328910021732068595344565885737045900010034836345809386672230885527307\", \"best_bid\":\"0.001\", \"best_ask\":\"0.003\", \"spread\":\"0.002\", \"timestamp\":\"1785127455276\", \"event_type\":\"best_bid_ask\"}","received_at":"2026-07-27T04:44:15.225197Z","schema_version":"clob-market-ws.best_bid_ask.v1","sequence":null,"server_hash":null,"server_timestamp":"1785127455276","session_id":"e9443c7415a0419799bee9cfbb1a9e4d","source":"clob_market_ws"},"received_at":"2026-07-27T04:44:15.225197Z","record_id":"09b7932051d4128d95dd26ede957981d43285b68d59186a38ce7a47eba9e4f9a","schema_fingerprint":"8488399f31b0337811b13b266be932db7062827c2470b78bd8e9e99bab51d17d","schema_version":"edge-lab-recorder.raw.v1","sequence":null,"source":"clob_market_ws"}
{"event_at":"2026-07-27T04:44:15.276000Z","event_fingerprint":"0a48428ebd9b2a93e7ccc31bbf672427b584dcdbcd8c99fc97ae8b021c80b8e1","payload":{"connection_id":"0f4979d6978d463e9660b042fdcf555f","event_at":"2026-07-27T04:44:15.276000Z","event_type":"price_change","frame_hash":"c250ef0ac4123cc4288960fafd9625d1bbe9f547e7c94b508d9f33ac0efbabcb","frame_index":0,"kind":"data","monotonic_ns":229438488782000,"payload":{"event_type":"price_change","market":"0xeb66215f2e9faa6449e30a02bab5b8ed7b79a38bf961f6b24d0073c9c2419250","price_changes":[{"asset_id":"60386828328910021732068595344565885737045900010034836345809386672230885527307","best_ask":"0.003","best_bid":"0.001","hash":"eeeac90e1ac122e5e4f1e9326217157980f7a7a6","price":"0.003","side":"SELL","size":"275.12"},{"asset_id":"69697746896130839564035629862476347944307040470122503199396727085502753297492","best_ask":"0.999","best_bid":"0.997","hash":"683df16fc2165aa6fafef9468652719d19189b7e","price":"0.997","side":"BUY","size":"275.12"}],"timestamp":"1785127455276"},"payload_hash":"49778a6111035fd914e618a39cbd694fbdd40cde63d3d91d5c932d785c1db92b","raw_frame":"{\"market\":\"0xeb66215f2e9faa6449e30a02bab5b8ed7b79a38bf961f6b24d0073c9c2419250\", \"price_changes\":[{\"asset_id\":\"60386828328910021732068595344565885737045900010034836345809386672230885527307\", \"price\":\"0.003\", \"size\":\"275.12\", \"side\":\"SELL\", \"hash\":\"eeeac90e1ac122e5e4f1e9326217157980f7a7a6\", \"best_bid\":\"0.001\", \"best_ask\":\"0.003\"}, {\"asset_id\":\"69697746896130839564035629862476347944307040470122503199396727085502753297492\", \"price\":\"0.997\", \"size\":\"275.12\", \"side\":\"BUY\", \"hash\":\"683df16fc2165aa6fafef9468652719d19189b7e\", \"best_bid\":\"0.997\", \"best_ask\":\"0.999\"}], \"timestamp\":\"1785127455276\", \"event_type\":\"price_change\"}","received_at":"2026-07-27T04:44:15.226356Z","schema_version":"clob-market-ws.price_change.v1","sequence":null,"server_hash":null,"server_timestamp":"1785127455276","session_id":"e9443c7415a0419799bee9cfbb1a9e4d","source":"clob_market_ws"},"received_at":"2026-07-27T04:44:15.226356Z","record_id":"146e3da6d13d729db36f3e61deedceb1147bdf26fb1a327ec87d11c0aa6e34e1","schema_fingerprint":"4aa3821a28b0b7c2400bc59aba4bcc0a76e971dadd19610d3ad38c768e124dc7","schema_version":"edge-lab-recorder.raw.v1","sequence":null,"source":"clob_market_ws"}
{"event_at":"2026-07-27T04:44:15.277000Z","event_fingerprint":"c6b855bbdbff78b3a270ca9cc2808aaf99904d3d3e628d0e3ff4d503dc15df60","payload":{"connection_id":"0f4979d6978d463e9660b042fdcf555f","event_at":"2026-07-27T04:44:15.277000Z","event_type":"price_change","frame_hash":"5010bcb3de99cfff7ed9f3d2d1c03c90b93e782146791dad7dfdd1336a95cd47","frame_index":0,"kind":"data","monotonic_ns":229438490345291,"payload":{"event_type":"price_change","market":"0xeb66215f2e9faa6449e30a02bab5b8ed7b79a38bf961f6b24d0073c9c2419250","price_changes":[{"asset_id":"69697746896130839564035629862476347944307040470122503199396727085502753297492","best_ask":"0.999","best_bid":"0.997","hash":"65991708fefc280970971daacdb3ce6922263c5e","price":"0.01","side":"BUY","size":"5315"},{"asset_id":"60386828328910021732068595344565885737045900010034836345809386672230885527307","best_ask":"0.003","best_bid":"0.001","hash":"791f829bbab2dba96bcf3a7c6264dc47514a31d8","price":"0.99","side":"SELL","size":"5315"}],"timestamp":"1785127455277"},"payload_hash":"0919d673d3fdb327e5225ba6a23ba091d822ed4b7c55330c93dadfe22e016e67","raw_frame":"{\"market\":\"0xeb66215f2e9faa6449e30a02bab5b8ed7b79a38bf961f6b24d0073c9c2419250\", \"price_changes\":[{\"asset_id\":\"69697746896130839564035629862476347944307040470122503199396727085502753297492\", \"price\":\"0.01\", \"size\":\"5315\", \"side\":\"BUY\", \"hash\":\"65991708fefc280970971daacdb3ce6922263c5e\", \"best_bid\":\"0.997\", \"best_ask\":\"0.999\"}, {\"asset_id\":\"60386828328910021732068595344565885737045900010034836345809386672230885527307\", \"price\":\"0.99\", \"size\":\"5315\", \"side\":\"SELL\", \"hash\":\"791f829bbab2dba96bcf3a7c6264dc47514a31d8\", \"best_bid\":\"0.001\", \"best_ask\":\"0.003\"}], \"timestamp\":\"1785127455277\", \"event_type\":\"price_change\"}","received_at":"2026-07-27T04:44:15.227919Z","schema_version":"clob-market-ws.price_change.v1","sequence":null,"server_hash":null,"server_timestamp":"1785127455277","session_id":"e9443c7415a0419799bee9cfbb1a9e4d","source":"clob_market_ws"},"received_at":"2026-07-27T04:44:15.227919Z","record_id":"8c873c9ae98d7725b2baf68a51f94d8934cc453fa161c23c2a9900a7465ddd40","schema_fingerprint":"4aa3821a28b0b7c2400bc59aba4bcc0a76e971dadd19610d3ad38c768e124dc7","schema_version":"edge-lab-recorder.raw.v1","sequence":null,"source":"clob_market_ws"}
{"event_at":"2026-07-27T04:44:15.297000Z","event_fingerprint":"93a9c01c7e7e802669b81498fce172ba3533586508abf4d406e013326ccd6127","payload":{"connection_id":"0f4979d6978d463e9660b042fdcf555f","event_at":"2026-07-27T04:44:15.297000Z","event_type":"best_bid_ask","frame_hash":"a37a8fa30fbdaeff13206bb44c42121a832595de3d54508f85de63dd9ff971f4","frame_index":0,"kind":"data","monotonic_ns":229438506867875,"payload":{"asset_id":"69697746896130839564035629862476347944307040470122503199396727085502753297492","best_ask":"0.999","best_bid":"0.996","event_type":"best_bid_ask","market":"0xeb66215f2e9faa6449e30a02bab5b8ed7b79a38bf961f6b24d0073c9c2419250","spread":"0.003","timestamp":"1785127455297"},"payload_hash":"384f3ba076ca5d64dedeadf5b155db5037a4127b1766973bb7d9280fd2f0ad9d","raw_frame":"{\"market\":\"0xeb66215f2e9faa6449e30a02bab5b8ed7b79a38bf961f6b24d0073c9c2419250\", \"asset_id\":\"69697746896130839564035629862476347944307040470122503199396727085502753297492\", \"best_bid\":\"0.996\", \"best_ask\":\"0.999\", \"spread\":\"0.003\", \"timestamp\":\"1785127455297\", \"event_type\":\"best_bid_ask\"}","received_at":"2026-07-27T04:44:15.244437Z","schema_version":"clob-market-ws.best_bid_ask.v1","sequence":null,"server_hash":null,"server_timestamp":"1785127455297","session_id":"e9443c7415a0419799bee9cfbb1a9e4d","source":"clob_market_ws"},"received_at":"2026-07-27T04:44:15.244437Z","record_id":"907a4e73cf73b6697750f4c96c77e3f520207df2245fa8ecc21d42493c656303","schema_fingerprint":"8488399f31b0337811b13b266be932db7062827c2470b78bd8e9e99bab51d17d","schema_version":"edge-lab-recorder.raw.v1","sequence":null,"source":"clob_market_ws"}
{"event_at":"2026-07-27T04:44:15.297000Z","event_fingerprint":"b6a15086128813346ddd23578f8ca7a6f803eec0a131347388b3a4e9ba6a4c4f","payload":{"connection_id":"0f4979d6978d463e9660b042fdcf555f","event_at":"2026-07-27T04:44:15.297000Z","event_type":"best_bid_ask","frame_hash":"839d799f0d35e1a7254fa0f97477fa958707bd591baefe2cfa43336ee2539bf6","frame_index":0,"kind":"data","monotonic_ns":229438508060375,"payload":{"asset_id":"60386828328910021732068595344565885737045900010034836345809386672230885527307","best_ask":"0.004","best_bid":"0.001","event_type":"best_bid_ask","market":"0xeb66215f2e9faa6449e30a02bab5b8ed7b79a38bf961f6b24d0073c9c2419250","spread":"0.003","timestamp":"1785127455297"},"payload_hash":"240096ddd8a28b74c079cfc00c45fd01f86117389dfe609ee6256370243bde82","raw_frame":"{\"market\":\"0xeb66215f2e9faa6449e30a02bab5b8ed7b79a38bf961f6b24d0073c9c2419250\", \"asset_id\":\"60386828328910021732068595344565885737045900010034836345809386672230885527307\", \"best_bid\":\"0.001\", \"best_ask\":\"0.004\", \"spread\":\"0.003\", \"timestamp\":\"1785127455297\", \"event_type\":\"best_bid_ask\"}","received_at":"2026-07-27T04:44:15.245636Z","schema_version":"clob-market-ws.best_bid_ask.v1","sequence":null,"server_hash":null,"server_timestamp":"1785127455297","session_id":"e9443c7415a0419799bee9cfbb1a9e4d","source":"clob_market_ws"},"received_at":"2026-07-27T04:44:15.245636Z","record_id":"c032943588c5aadc5bd795359289f45d8eb241bae9686b7d4f5345885ff57391","schema_fingerprint":"8488399f31b0337811b13b266be932db7062827c2470b78bd8e9e99bab51d17d","schema_version":"edge-lab-recorder.raw.v1","sequence":null,"source":"clob_market_ws"}
{"event_at":"2026-07-27T04:44:15.297000Z","event_fingerprint":"3d9793870ed86374ad6503e0ec47a426b33bda61c65f4f8b38c75196b4f76dd6","payload":{"connection_id":"0f4979d6978d463e9660b042fdcf555f","event_at":"2026-07-27T04:44:15.297000Z","event_type":"price_change","frame_hash":"193d932bb845f73ca26bbcc9083dd76bc065af0fef07285528a3857bce3700d0","frame_index":0,"kind":"data","monotonic_ns":229438509150250,"payload":{"event_type":"price_change","market":"0xeb66215f2e9faa6449e30a02bab5b8ed7b79a38bf961f6b24d0073c9c2419250","price_changes":[{"asset_id":"60386828328910021732068595344565885737045900010034836345809386672230885527307","best_ask":"0.004","best_bid":"0.001","hash":"fb7e0fb109a0e1390193aa1e9098cd341e404c19","price":"0.003","side":"SELL","size":"0"},{"asset_id":"69697746896130839564035629862476347944307040470122503199396727085502753297492","best_ask":"0.999","best_bid":"0.996","hash":"a5cdf3316f806f1d728183bec42e1cee50ab5abf","price":"0.997","side":"BUY","size":"0"}],"timestamp":"1785127455297"},"payload_hash":"6ee60a0ce5328b528b1f52509eee4b87c06f3b8c18279c57c25199d130ace0c8","raw_frame":"{\"market\":\"0xeb66215f2e9faa6449e30a02bab5b8ed7b79a38bf961f6b24d0073c9c2419250\", \"price_changes\":[{\"asset_id\":\"60386828328910021732068595344565885737045900010034836345809386672230885527307\", \"price\":\"0.003\", \"size\":\"0\", \"side\":\"SELL\", \"hash\":\"fb7e0fb109a0e1390193aa1e9098cd341e404c19\", \"best_bid\":\"0.001\", \"best_ask\":\"0.004\"}, {\"asset_id\":\"69697746896130839564035629862476347944307040470122503199396727085502753297492\", \"price\":\"0.997\", \"size\":\"0\", \"side\":\"BUY\", \"hash\":\"a5cdf3316f806f1d728183bec42e1cee50ab5abf\", \"best_bid\":\"0.996\", \"best_ask\":\"0.999\"}], \"timestamp\":\"1785127455297\", \"event_type\":\"price_change\"}","received_at":"2026-07-27T04:44:15.246725Z","schema_version":"clob-market-ws.price_change.v1","sequence":null,"server_hash":null,"server_timestamp":"1785127455297","session_id":"e9443c7415a0419799bee9cfbb1a9e4d","source":"clob_market_ws"},"received_at":"2026-07-27T04:44:15.246725Z","record_id":"ae275de34a51d7c070fdd259470e9740869247bb54f03093828ba3ffe007d6dd","schema_fingerprint":"4aa3821a28b0b7c2400bc59aba4bcc0a76e971dadd19610d3ad38c768e124dc7","schema_version":"edge-lab-recorder.raw.v1","sequence":null,"source":"clob_market_ws"}
{"event_at":"2026-07-27T04:44:15.310000Z","event_fingerprint":"e5d767b4c5a85728450bf9e369a73c8455aacee4176841605e0eb62aa25d05ae","payload":{"connection_id":"0f4979d6978d463e9660b042fdcf555f","event_at":"2026-07-27T04:44:15.310000Z","event_type":"price_change","frame_hash":"0ef98377d44d96993e7763aaa5f6a6de569730dab64954d5d3fec32d8311692e","frame_index":0,"kind":"data","monotonic_ns":229438520749750,"payload":{"event_type":"price_change","market":"0xeb66215f2e9faa6449e30a02bab5b8ed7b79a38bf961f6b24d0073c9c2419250","price_changes":[{"asset_id":"69697746896130839564035629862476347944307040470122503199396727085502753297492","best_ask":"0.999","best_bid":"0.996","hash":"3cca0e994fe211f2161de5c988c9e9d4ed76bf00","price":"0.03","side":"BUY","size":"515"},{"asset_id":"60386828328910021732068595344565885737045900010034836345809386672230885527307","best_ask":"0.004","best_bid":"0.001","hash":"68023bc7c65f7237a7dd4f369b8e5fde8db4fccb","price":"0.97","side":"SELL","size":"515"}],"timestamp":"1785127455310"},"payload_hash":"914cc49fa67240dc2e5cad7b3d39fe2845284500ad10c44ffe97891e6825bc3a","raw_frame":"{\"market\":\"0xeb66215f2e9faa6449e30a02bab5b8ed7b79a38bf961f6b24d0073c9c2419250\", \"price_changes\":[{\"asset_id\":\"69697746896130839564035629862476347944307040470122503199396727085502753297492\", \"price\":\"0.03\", \"size\":\"515\", \"side\":\"BUY\", \"hash\":\"3cca0e994fe211f2161de5c988c9e9d4ed76bf00\", \"best_bid\":\"0.996\", \"best_ask\":\"0.999\"}, {\"asset_id\":\"60386828328910021732068595344565885737045900010034836345809386672230885527307\", \"price\":\"0.97\", \"size\":\"515\", \"side\":\"SELL\", \"hash\":\"68023bc7c65f7237a7dd4f369b8e5fde8db4fccb\", \"best_bid\":\"0.001\", \"best_ask\":\"0.004\"}], \"timestamp\":\"1785127455310\", \"event_type\":\"price_change\"}","received_at":"2026-07-27T04:44:15.258322Z","schema_version":"clob-market-ws.price_change.v1","sequence":null,"server_hash":null,"server_timestamp":"1785127455310","session_id":"e9443c7415a0419799bee9cfbb1a9e4d","source":"clob_market_ws"},"received_at":"2026-07-27T04:44:15.258322Z","record_id":"b47da919d7aaa279ca39f707af0c0f3a40e47e203e991af7d9eec134f081e5b3","schema_fingerprint":"4aa3821a28b0b7c2400bc59aba4bcc0a76e971dadd19610d3ad38c768e124dc7","schema_version":"edge-lab-recorder.raw.v1","sequence":null,"source":"clob_market_ws"}
{"event_at":"2026-07-27T04:44:15.327000Z","event_fingerprint":"aeb3152c4747717bda452e8f077d0dc1e97b7fd874b857566b6d9a224f2538bb","payload":{"connection_id":"0f4979d6978d463e9660b042fdcf555f","event_at":"2026-07-27T04:44:15.327000Z","event_type":"best_bid_ask","frame_hash":"47cbb6250e98ae868f5d64cc25b814a3e44b46b1bff6a2530edb6361efea8a84","frame_index":0,"kind":"data","monotonic_ns":229438537611916,"payload":{"asset_id":"69697746896130839564035629862476347944307040470122503199396727085502753297492","best_ask":"0.999","best_bid":"0.997","event_type":"best_bid_ask","market":"0xeb66215f2e9faa6449e30a02bab5b8ed7b79a38bf961f6b24d0073c9c2419250","spread":"0.002","timestamp":"1785127455327"},"payload_hash":"6851d53a5cdc6789ddbc8c850980ee860c8abc5074d3673392fe0e6635018605","raw_frame":"{\"market\":\"0xeb66215f2e9faa6449e30a02bab5b8ed7b79a38bf961f6b24d0073c9c2419250\", \"asset_id\":\"69697746896130839564035629862476347944307040470122503199396727085502753297492\", \"best_bid\":\"0.997\", \"best_ask\":\"0.999\", \"spread\":\"0.002\", \"timestamp\":\"1785127455327\", \"event_type\":\"best_bid_ask\"}","received_at":"2026-07-27T04:44:15.275182Z","schema_version":"clob-market-ws.best_bid_ask.v1","sequence":null,"server_hash":null,"server_timestamp":"1785127455327","session_id":"e9443c7415a0419799bee9cfbb1a9e4d","source":"clob_market_ws"},"received_at":"2026-07-27T04:44:15.275182Z","record_id":"e89658d23674926c51427b64f488ac598428ee2422080060ac401766bedcf822","schema_fingerprint":"8488399f31b0337811b13b266be932db7062827c2470b78bd8e9e99bab51d17d","schema_version":"edge-lab-recorder.raw.v1","sequence":null,"source":"clob_market_ws"}
{"event_at":"2026-07-27T04:44:15.327000Z","event_fingerprint":"986bae2f2be773f22ae5befb37541834e4a0e47d1e144a21ac7264430522cdeb","payload":{"connection_id":"0f4979d6978d463e9660b042fdcf555f","event_at":"2026-07-27T04:44:15.327000Z","event_type":"best_bid_ask","frame_hash":"1770f4b0cb6dbb2165a6304ebbd13e22eded959b26bfe8b791a14245020d49a5","frame_index":0,"kind":"data","monotonic_ns":229438538828083,"payload":{"asset_id":"60386828328910021732068595344565885737045900010034836345809386672230885527307","best_ask":"0.003","best_bid":"0.001","event_type":"best_bid_ask","market":"0xeb66215f2e9faa6449e30a02bab5b8ed7b79a38bf961f6b24d0073c9c2419250","spread":"0.002","timestamp":"1785127455327"},"payload_hash":"208b454b933fd10900659ab4e36dcd9546d0d4554e74c67cdafe2a990ba4ee23","raw_frame":"{\"market\":\"0xeb66215f2e9faa6449e30a02bab5b8ed7b79a38bf961f6b24d0073c9c2419250\", \"asset_id\":\"60386828328910021732068595344565885737045900010034836345809386672230885527307\", \"best_bid\":\"0.001\", \"best_ask\":\"0.003\", \"spread\":\"0.002\", \"timestamp\":\"1785127455327\", \"event_type\":\"best_bid_ask\"}","received_at":"2026-07-27T04:44:15.276403Z","schema_version":"clob-market-ws.best_bid_ask.v1","sequence":null,"server_hash":null,"server_timestamp":"1785127455327","session_id":"e9443c7415a0419799bee9cfbb1a9e4d","source":"clob_market_ws"},"received_at":"2026-07-27T04:44:15.276403Z","record_id":"f92b6e32404cf66162eda5c6b71aacbf3efa1ec432289b5c485965ac8d31549a","schema_fingerprint":"8488399f31b0337811b13b266be932db7062827c2470b78bd8e9e99bab51d17d","schema_version":"edge-lab-recorder.raw.v1","sequence":null,"source":"clob_market_ws"}
{"event_at":"2026-07-27T04:44:15.327000Z","event_fingerprint":"93ca7c07533575a1202a633b8d403af135b04879c9817954aa41324c185d4f89","payload":{"connection_id":"0f4979d6978d463e9660b042fdcf555f","event_at":"2026-07-27T04:44:15.327000Z","event_type":"price_change","frame_hash":"85c96d3c47595c1ffb2b4636dce3e2a63fc2dd816439327e66abc50daf891282","frame_index":0,"kind":"data","monotonic_ns":229438539893625,"payload":{"event_type":"price_change","market":"0xeb66215f2e9faa6449e30a02bab5b8ed7b79a38bf961f6b24d0073c9c2419250","price_changes":[{"asset_id":"60386828328910021732068595344565885737045900010034836345809386672230885527307","best_ask":"0.003","best_bid":"0.001","hash":"0ed674d158b8e2b06ff4892ad03afb9887867910","price":"0.003","side":"SELL","size":"275.12"},{"asset_id":"69697746896130839564035629862476347944307040470122503199396727085502753297492","best_ask":"0.999","best_bid":"0.997","hash":"71b200c5f4e091a8129cd8ae76341b961e30dda4","price":"0.997","side":"BUY","size":"275.12"}],"timestamp":"1785127455327"},"payload_hash":"8fe46f722a20d6b014df6904a688b0b6ea8b00f8571eeec90684ce685490e1cb","raw_frame":"{\"market\":\"0xeb66215f2e9faa6449e30a02bab5b8ed7b79a38bf961f6b24d0073c9c2419250\", \"price_changes\":[{\"asset_id\":\"60386828328910021732068595344565885737045900010034836345809386672230885527307\", \"price\":\"0.003\", \"size\":\"275.12\", \"side\":\"SELL\", \"hash\":\"0ed674d158b8e2b06ff4892ad03afb9887867910\", \"best_bid\":\"0.001\", \"best_ask\":\"0.003\"}, {\"asset_id\":\"69697746896130839564035629862476347944307040470122503199396727085502753297492\", \"price\":\"0.997\", \"size\":\"275.12\", \"side\":\"BUY\", \"hash\":\"71b200c5f4e091a8129cd8ae76341b961e30dda4\", \"best_bid\":\"0.997\", \"best_ask\":\"0.999\"}], \"timestamp\":\"1785127455327\", \"event_type\":\"price_change\"}","received_at":"2026-07-27T04:44:15.277467Z","schema_version":"clob-market-ws.price_change.v1","sequence":null,"server_hash":null,"server_timestamp":"1785127455327","session_id":"e9443c7415a0419799bee9cfbb1a9e4d","source":"clob_market_ws"},"received_at":"2026-07-27T04:44:15.277467Z","record_id":"f4a697ef67c8c3c298d2d8f795a1c1046c3dd17f25e251bb96d2f48b41250aef","schema_fingerprint":"4aa3821a28b0b7c2400bc59aba4bcc0a76e971dadd19610d3ad38c768e124dc7","schema_version":"edge-lab-recorder.raw.v1","sequence":null,"source":"clob_market_ws"}
{"event_at":"2026-07-27T04:44:15.346000Z","event_fingerprint":"473075b18f9f139de29934915219dd84351ff51b22c806a74cd97d71de78c268","payload":{"connection_id":"0f4979d6978d463e9660b042fdcf555f","event_at":"2026-07-27T04:44:15.346000Z","event_type":"best_bid_ask","frame_hash":"6778205779993d944b2019577fcabc9e3befecab53a7bab1353242cd086b5f9d","frame_index":0,"kind":"data","monotonic_ns":229438556903166,"payload":{"asset_id":"69697746896130839564035629862476347944307040470122503199396727085502753297492","best_ask":"0.999","best_bid":"0.996","event_type":"best_bid_ask","market":"0xeb66215f2e9faa6449e30a02bab5b8ed7b79a38bf961f6b24d0073c9c2419250","spread":"0.003","timestamp":"1785127455346"},"payload_hash":"4b6be1fda3867f2a46d5a261c5b2941bfb210059824aca98753bcff7d2240720","raw_frame":"{\"market\":\"0xeb66215f2e9faa6449e30a02bab5b8ed7b79a38bf961f6b24d0073c9c2419250\", \"asset_id\":\"69697746896130839564035629862476347944307040470122503199396727085502753297492\", \"best_bid\":\"0.996\", \"best_ask\":\"0.999\", \"spread\":\"0.003\", \"timestamp\":\"1785127455346\", \"event_type\":\"best_bid_ask\"}","received_at":"2026-07-27T04:44:15.294474Z","schema_version":"clob-market-ws.best_bid_ask.v1","sequence":null,"server_hash":null,"server_timestamp":"1785127455346","session_id":"e9443c7415a0419799bee9cfbb1a9e4d","source":"clob_market_ws"},"received_at":"2026-07-27T04:44:15.294474Z","record_id":"de132dfbccbd3330b0b7d1827bdb6f373cf949978bb04a30f8707c5fc8b93128","schema_fingerprint":"8488399f31b0337811b13b266be932db7062827c2470b78bd8e9e99bab51d17d","schema_version":"edge-lab-recorder.raw.v1","sequence":null,"source":"clob_market_ws"}
