{"event_at":"2026-07-27T04:33:18.198000Z","event_fingerprint":"f15e8abc169de4e99635dc0afdc1f212161e664e3a3a6dcc5a9e6462a4bb3b35","payload":{"connection_id":"0f4979d6978d463e9660b042fdcf555f","event_at":"2026-07-27T04:33:18.198000Z","event_type":"price_change","frame_hash":"5e34c9a7bb201cc945a6f39b2b732635d4740dbfe67137e661182e5f28a546ce","frame_index":0,"kind":"data","monotonic_ns":228781430202625,"payload":{"event_type":"price_change","market":"0xeb66215f2e9faa6449e30a02bab5b8ed7b79a38bf961f6b24d0073c9c2419250","price_changes":[{"asset_id":"60386828328910021732068595344565885737045900010034836345809386672230885527307","best_ask":"0.88","best_bid":"0.87","hash":"077c86c166db6f073c761d9a0f35ac9a14672fdd","price":"0.84","side":"BUY","size":"98.61"},{"asset_id":"69697746896130839564035629862476347944307040470122503199396727085502753297492","best_ask":"0.13","best_bid":"0.12","hash":"e0035fb900a78d6622d7971ee70cb620ae29fe59","price":"0.16","side":"SELL","size":"98.61"}],"timestamp":"1785126798198"},"payload_hash":"6fbe1c32a8f34861a20ebf68d21bc33652c0448c275ed13c4fe8efe86983e809","raw_frame":"{\"market\":\"0xeb66215f2e9faa6449e30a02bab5b8ed7b79a38bf961f6b24d0073c9c2419250\", \"price_changes\":[{\"asset_id\":\"60386828328910021732068595344565885737045900010034836345809386672230885527307\", \"price\":\"0.84\", \"size\":\"98.61\", \"side\":\"BUY\", \"hash\":\"077c86c166db6f073c761d9a0f35ac9a14672fdd\", \"best_bid\":\"0.87\", \"best_ask\":\"0.88\"}, {\"asset_id\":\"69697746896130839564035629862476347944307040470122503199396727085502753297492\", \"price\":\"0.16\", \"size\":\"98.61\", \"side\":\"SELL\", \"hash\":\"e0035fb900a78d6622d7971ee70cb620ae29fe59\", \"best_bid\":\"0.12\", \"best_ask\":\"0.13\"}], \"timestamp\":\"1785126798198\", \"event_type\":\"price_change\"}","received_at":"2026-07-27T04:33:18.162083Z","schema_version":"clob-market-ws.price_change.v1","sequence":null,"server_hash":null,"server_timestamp":"1785126798198","session_id":"e9443c7415a0419799bee9cfbb1a9e4d","source":"clob_market_ws"},"received_at":"2026-07-27T04:33:18.162083Z","record_id":"caa8113d22e761cdbaf5857d79ba9b7fad9b265f2185816880c0cf86d18af0d1","schema_fingerprint":"4aa3821a28b0b7c2400bc59aba4bcc0a76e971dadd19610d3ad38c768e124dc7","schema_version":"edge-lab-recorder.raw.v1","sequence":null,"source":"clob_market_ws"}
{"event_at":"2026-07-27T04:33:18.252000Z","event_fingerprint":"0936faaa5ddf1f401cf61c251b4def345a34709537beb85547137c658191078e","payload":{"connection_id":"0f4979d6978d463e9660b042fdcf555f","event_at":"2026-07-27T04:33:18.252000Z","event_type":"price_change","frame_hash":"ffa57b526f29d6c29ff3c9744177e1501fcc275169482d5248614386f7dabaec","frame_index":0,"kind":"data","monotonic_ns":228781465076833,"payload":{"event_type":"price_change","market":"0xeb66215f2e9faa6449e30a02bab5b8ed7b79a38bf961f6b24d0073c9c2419250","price_changes":[{"asset_id":"60386828328910021732068595344565885737045900010034836345809386672230885527307","best_ask":"0.88","best_bid":"0.87","hash":"cfffe490492fedc00dd6377c68a98fbe91647506","price":"0.01","side":"BUY","size":"7708.02"},{"asset_id":"69697746896130839564035629862476347944307040470122503199396727085502753297492","best_ask":"0.13","best_bid":"0.12","hash":"34c39efd8548857bb8cd5f87901b19f8c39a960f","price":"0.99","side":"SELL","size":"7708.02"}],"timestamp":"1785126798252"},"payload_hash":"d50fa10c3f187fef0a2d1e013d4492cdcaa08ecc027104ed66fab9ba8a37eb44","raw_frame":"{\"market\":\"0xeb66215f2e9faa6449e30a02bab5b8ed7b79a38bf961f6b24d0073c9c2419250\", \"price_changes\":[{\"asset_id\":\"60386828328910021732068595344565885737045900010034836345809386672230885527307\", \"price\":\"0.01\", \"size\":\"7708.02\", \"side\":\"BUY\", \"hash\":\"cfffe490492fedc00dd6377c68a98fbe91647506\", \"best_bid\":\"0.87\", \"best_ask\":\"0.88\"}, {\"asset_id\":\"69697746896130839564035629862476347944307040470122503199396727085502753297492\", \"price\":\"0.99\", \"size\":\"7708.02\", \"side\":\"SELL\", \"hash\":\"34c39efd8548857bb8cd5f87901b19f8c39a960f\", \"best_bid\":\"0.12\", \"best_ask\":\"0.13\"}], \"timestamp\":\"1785126798252\", \"event_type\":\"price_change\"}","received_at":"2026-07-27T04:33:18.196959Z","schema_version":"clob-market-ws.price_change.v1","sequence":null,"server_hash":null,"server_timestamp":"1785126798252","session_id":"e9443c7415a0419799bee9cfbb1a9e4d","source":"clob_market_ws"},"received_at":"2026-07-27T04:33:18.196959Z","record_id":"9a2a497e706f86289037a63542fc68c02a8c1386b104afc5ce4ad2ea34c1036a","schema_fingerprint":"4aa3821a28b0b7c2400bc59aba4bcc0a76e971dadd19610d3ad38c768e124dc7","schema_version":"edge-lab-recorder.raw.v1","sequence":null,"source":"clob_market_ws"}
{"event_at":"2026-07-27T04:33:18.273000Z","event_fingerprint":"1632d52a5b062fa6b5ca0409d717bea0c48dd89dfc3f89cd00e2e1d561105b11","payload":{"connection_id":"0f4979d6978d463e9660b042fdcf555f","event_at":"2026-07-27T04:33:18.273000Z","event_type":"price_change","frame_hash":"5c16fea8e7f43d45725ad458763b421471d9fa1f242656b513915d53b639ce93","frame_index":0,"kind":"data","monotonic_ns":228781485117958,"payload":{"event_type":"price_change","market":"0xeb66215f2e9faa6449e30a02bab5b8ed7b79a38bf961f6b24d0073c9c2419250","price_changes":[{"asset_id":"60386828328910021732068595344565885737045900010034836345809386672230885527307","best_ask":"0.88","best_bid":"0.87","hash":"1e893bf1fc96867e657564118ec017e50e0c2351","price":"0.01","side":"BUY","size":"7703.02"},{"asset_id":"69697746896130839564035629862476347944307040470122503199396727085502753297492","best_ask":"0.13","best_bid":"0.12","hash":"101ba00a895061936be1b6baefad25c687c90e27","price":"0.99","side":"SELL","size":"7703.02"}],"timestamp":"1785126798273"},"payload_hash":"494813f9f044405831bb604e6a4dab57e2422736d9dfc606cd97f475ed5c75f4","raw_frame":"{\"market\":\"0xeb66215f2e9faa6449e30a02bab5b8ed7b79a38bf961f6b24d0073c9c2419250\", \"price_changes\":[{\"asset_id\":\"60386828328910021732068595344565885737045900010034836345809386672230885527307\", \"price\":\"0.01\", \"size\":\"7703.02\", \"side\":\"BUY\", \"hash\":\"1e893bf1fc96867e657564118ec017e50e0c2351\", \"best_bid\":\"0.87\", \"best_ask\":\"0.88\"}, {\"asset_id\":\"69697746896130839564035629862476347944307040470122503199396727085502753297492\", \"price\":\"0.99\", \"size\":\"7703.02\", \"side\":\"SELL\", \"hash\":\"101ba00a895061936be1b6baefad25c687c90e27\", \"best_bid\":\"0.12\", \"best_ask\":\"0.13\"}], \"timestamp\":\"1785126798273\", \"event_type\":\"price_change\"}","received_at":"2026-07-27T04:33:18.217004Z","schema_version":"clob-market-ws.price_change.v1","sequence":null,"server_hash":null,"server_timestamp":"1785126798273","session_id":"e9443c7415a0419799bee9cfbb1a9e4d","source":"clob_market_ws"},"received_at":"2026-07-27T04:33:18.217004Z","record_id":"3c225dbefb769ff28aa23e896a9961c3cd6e718238e05aa7d3848df8b6034072","schema_fingerprint":"4aa3821a28b0b7c2400bc59aba4bcc0a76e971dadd19610d3ad38c768e124dc7","schema_version":"edge-lab-recorder.raw.v1","sequence":null,"source":"clob_market_ws"}
{"event_at":"2026-07-27T04:33:18.277000Z","event_fingerprint":"9fb406ce3ccb54173942dc9d061fc647c8d37ea373d508ced8650289df52b793","payload":{"connection_id":"0f4979d6978d463e9660b042fdcf555f","event_at":"2026-07-27T04:33:18.277000Z","event_type":"price_change","frame_hash":"6f8fbc50042cf6d70185045427b568eb6149c882da6f87880307d3f74ac5d1ac","frame_index":0,"kind":"data","monotonic_ns":228781490524875,"payload":{"event_type":"price_change","market":"0xeb66215f2e9faa6449e30a02bab5b8ed7b79a38bf961f6b24d0073c9c2419250","price_changes":[{"asset_id":"60386828328910021732068595344565885737045900010034836345809386672230885527307","best_ask":"0.88","best_bid":"0.87","hash":"82de78ee19570250654d44235d25b3227a6d615d","price":"0.03","side":"BUY","size":"648.1"},{"asset_id":"69697746896130839564035629862476347944307040470122503199396727085502753297492","best_ask":"0.13","best_bid":"0.12","hash":"1c8fd0c8f9a42f106debd3811f411005df6a83e9","price":"0.97","side":"SELL","size":"648.1"}],"timestamp":"1785126798277"},"payload_hash":"2c07aa00f5fca3762e081f961739674aaa7d8d52bc5702863a1d3c2693bac17e","raw_frame":"{\"market\":\"0xeb66215f2e9faa6449e30a02bab5b8ed7b79a38bf961f6b24d0073c9c2419250\", \"price_changes\":[{\"asset_id\":\"60386828328910021732068595344565885737045900010034836345809386672230885527307\", \"price\":\"0.03\", \"size\":\"648.1\", \"side\":\"BUY\", \"hash\":\"82de78ee19570250654d44235d25b3227a6d615d\", \"best_bid\":\"0.87\", \"best_ask\":\"0.88\"}, {\"asset_id\":\"69697746896130839564035629862476347944307040470122503199396727085502753297492\", \"price\":\"0.97\", \"size\":\"648.1\", \"side\":\"SELL\", \"hash\":\"1c8fd0c8f9a42f106debd3811f411005df6a83e9\", \"best_bid\":\"0.12\", \"best_ask\":\"0.13\"}], \"timestamp\":\"1785126798277\", \"event_type\":\"price_change\"}","received_at":"2026-07-27T04:33:18.222410Z","schema_version":"clob-market-ws.price_change.v1","sequence":null,"server_hash":null,"server_timestamp":"1785126798277","session_id":"e9443c7415a0419799bee9cfbb1a9e4d","source":"clob_market_ws"},"received_at":"2026-07-27T04:33:18.222410Z","record_id":"0f44cb76498545001d70cded7e14060da4bae2ba7a3ef4b2520323222d846435","schema_fingerprint":"4aa3821a28b0b7c2400bc59aba4bcc0a76e971dadd19610d3ad38c768e124dc7","schema_version":"edge-lab-recorder.raw.v1","sequence":null,"source":"clob_market_ws"}
{"event_at":"2026-07-27T04:33:18.290000Z","event_fingerprint":"57124c905d6a48e99d1128e3af4480e69b1709452239bf4f54bafc811a2d51a9","payload":{"connection_id":"0f4979d6978d463e9660b042fdcf555f","event_at":"2026-07-27T04:33:18.290000Z","event_type":"price_change","frame_hash":"71bd17f9b05bfde16c6ba33bbb66da060d3d03ffa143e4b7ceea0659cb370387","frame_index":0,"kind":"data","monotonic_ns":228781503225333,"payload":{"event_type":"price_change","market":"0xeb66215f2e9faa6449e30a02bab5b8ed7b79a38bf961f6b24d0073c9c2419250","price_changes":[{"asset_id":"60386828328910021732068595344565885737045900010034836345809386672230885527307","best_ask":"0.88","best_bid":"0.87","hash":"ddc90a40c1d9fbfe78c4031e4325648692ea2f40","price":"0.01","side":"BUY","size":"7708.02"},{"asset_id":"69697746896130839564035629862476347944307040470122503199396727085502753297492","best_ask":"0.13","best_bid":"0.12","hash":"030f824035d89be4625f33e6d7860fcaf7506b17","price":"0.99","side":"SELL","size":"7708.02"}],"timestamp":"1785126798290"},"payload_hash":"2f6873b0e87f282815831b5df2cc6d386f20f3941bd30b4e3695da33cc114704","raw_frame":"{\"market\":\"0xeb66215f2e9faa6449e30a02bab5b8ed7b79a38bf961f6b24d0073c9c2419250\", \"price_changes\":[{\"asset_id\":\"60386828328910021732068595344565885737045900010034836345809386672230885527307\", \"price\":\"0.01\", \"size\":\"7708.02\", \"side\":\"BUY\", \"hash\":\"ddc90a40c1d9fbfe78c4031e4325648692ea2f40\", \"best_bid\":\"0.87\", \"best_ask\":\"0.88\"}, {\"asset_id\":\"69697746896130839564035629862476347944307040470122503199396727085502753297492\", \"price\":\"0.99\", \"size\":\"7708.02\", \"side\":\"SELL\", \"hash\":\"030f824035d89be4625f33e6d7860fcaf7506b17\", \"best_bid\":\"0.12\", \"best_ask\":\"0.13\"}], \"timestamp\":\"1785126798290\", \"event_type\":\"price_change\"}","received_at":"2026-07-27T04:33:18.235103Z","schema_version":"clob-market-ws.price_change.v1","sequence":null,"server_hash":null,"server_timestamp":"1785126798290","session_id":"e9443c7415a0419799bee9cfbb1a9e4d","source":"clob_market_ws"},"received_at":"2026-07-27T04:33:18.235103Z","record_id":"7cef6bc0a7b697c65c58177d0bb0cdaf1e2985d8cfcbdb4d8b5be3cc993cd521","schema_fingerprint":"4aa3821a28b0b7c2400bc59aba4bcc0a76e971dadd19610d3ad38c768e124dc7","schema_version":"edge-lab-recorder.raw.v1","sequence":null,"source":"clob_market_ws"}
{"event_at":"2026-07-27T04:33:18.291000Z","event_fingerprint":"cb95251d93c64c7b37b44ba620b878f9871936b4766d34e9e2791dbe3f49286f","payload":{"connection_id":"0f4979d6978d463e9660b042fdcf555f","event_at":"2026-07-27T04:33:18.291000Z","event_type":"price_change","frame_hash":"197cedbf595da2099bbfa6cf1b0dfdcca16ce68a64eee94794f88fff6a76f128","frame_index":0,"kind":"data","monotonic_ns":228781506053250,"payload":{"event_type":"price_change","market":"0xeb66215f2e9faa6449e30a02bab5b8ed7b79a38bf961f6b24d0073c9c2419250","price_changes":[{"asset_id":"60386828328910021732068595344565885737045900010034836345809386672230885527307","best_ask":"0.88","best_bid":"0.87","hash":"161ef90566fc19ae831b297426e3a165a1bebb1d","price":"0.89","side":"SELL","size":"78.64"},{"asset_id":"69697746896130839564035629862476347944307040470122503199396727085502753297492","best_ask":"0.13","best_bid":"0.12","hash":"ef7e830755a941b202d35047c3ac4064c357773c","price":"0.11","side":"BUY","size":"78.64"}],"timestamp":"1785126798291"},"payload_hash":"c0f903979c296e6de5095b744131cca8b8251e2b711b2320522ab9940b7c5f8c","raw_frame":"{\"market\":\"0xeb66215f2e9faa6449e30a02bab5b8ed7b79a38bf961f6b24d0073c9c2419250\", \"price_changes\":[{\"asset_id\":\"60386828328910021732068595344565885737045900010034836345809386672230885527307\", \"price\":\"0.89\", \"size\":\"78.64\", \"side\":\"SELL\", \"hash\":\"161ef90566fc19ae831b297426e3a165a1bebb1d\", \"best_bid\":\"0.87\", \"best_ask\":\"0.88\"}, {\"asset_id\":\"69697746896130839564035629862476347944307040470122503199396727085502753297492\", \"price\":\"0.11\", \"size\":\"78.64\", \"side\":\"BUY\", \"hash\":\"ef7e830755a941b202d35047c3ac4064c357773c\", \"best_bid\":\"0.12\", \"best_ask\":\"0.13\"}], \"timestamp\":\"1785126798291\", \"event_type\":\"price_change\"}","received_at":"2026-07-27T04:33:18.237933Z","schema_version":"clob-market-ws.price_change.v1","sequence":null,"server_hash":null,"server_timestamp":"1785126798291","session_id":"e9443c7415a0419799bee9cfbb1a9e4d","source":"clob_market_ws"},"received_at":"2026-07-27T04:33:18.237933Z","record_id":"46616333045e778b5fe524d7df9aacc214ffa16cff51f630335bd8bb9bed3728","schema_fingerprint":"4aa3821a28b0b7c2400bc59aba4bcc0a76e971dadd19610d3ad38c768e124dc7","schema_version":"edge-lab-recorder.raw.v1","sequence":null,"source":"clob_market_ws"}
{"event_at":"2026-07-27T04:33:18.310000Z","event_fingerprint":"7fc2ccbb17cfab60042c4bb9a1f9d36e7e8a242efb4e105e9fe62675b10df445","payload":{"connection_id":"0f4979d6978d463e9660b042fdcf555f","event_at":"2026-07-27T04:33:18.310000Z","event_type":"price_change","frame_hash":"ab8b8d6ea311ce15d22620d934c286a25f975e16dad521a866728f1c15873d05","frame_index":0,"kind":"data","monotonic_ns":228781524218041,"payload":{"event_type":"price_change","market":"0xeb66215f2e9faa6449e30a02bab5b8ed7b79a38bf961f6b24d0073c9c2419250","price_changes":[{"asset_id":"60386828328910021732068595344565885737045900010034836345809386672230885527307","best_ask":"0.88","best_bid":"0.87","hash":"445b25e24b9095ed46d65a235e9251294dbc0875","price":"0.01","side":"BUY","size":"7703.02"},{"asset_id":"69697746896130839564035629862476347944307040470122503199396727085502753297492","best_ask":"0.13","best_bid":"0.12","hash":"ed067370b55591ef24be1591792b7e7d1bc14be6","price":"0.99","side":"SELL","size":"7703.02"}],"timestamp":"1785126798310"},"payload_hash":"caed9eb3b70ebb3d722ef4cd499ee04aafefbe225583f57cf4900144c97c57c6","raw_frame":"{\"market\":\"0xeb66215f2e9faa6449e30a02bab5b8ed7b79a38bf961f6b24d0073c9c2419250\", \"price_changes\":[{\"asset_id\":\"60386828328910021732068595344565885737045900010034836345809386672230885527307\", \"price\":\"0.01\", \"size\":\"7703.02\", \"side\":\"BUY\", \"hash\":\"445b25e24b9095ed46d65a235e9251294dbc0875\", \"best_bid\":\"0.87\", \"best_ask\":\"0.88\"}, {\"asset_id\":\"69697746896130839564035629862476347944307040470122503199396727085502753297492\", \"price\":\"0.99\", \"size\":\"7703.02\", \"side\":\"SELL\", \"hash\":\"ed067370b55591ef24be1591792b7e7d1bc14be6\", \"best_bid\":\"0.12\", \"best_ask\":\"0.13\"}], \"timestamp\":\"1785126798310\", \"event_type\":\"price_change\"}","received_at":"2026-07-27T04:33:18.256098Z","schema_version":"clob-market-ws.price_change.v1","sequence":null,"server_hash":null,"server_timestamp":"1785126798310","session_id":"e9443c7415a0419799bee9cfbb1a9e4d","source":"clob_market_ws"},"received_at":"2026-07-27T04:33:18.256098Z","record_id":"84ecdfcfcf63e24afcd62f846214d5517643d03c06a53c9324bbf44f6037500b","schema_fingerprint":"4aa3821a28b0b7c2400bc59aba4bcc0a76e971dadd19610d3ad38c768e124dc7","schema_version":"edge-lab-recorder.raw.v1","sequence":null,"source":"clob_market_ws"}
{"event_at":"2026-07-27T04:33:18.326000Z","event_fingerprint":"fb04f9d0322824aeeb46fa8f4b07053407507102ab679339581dedeed7d48ebb","payload":{"connection_id":"0f4979d6978d463e9660b042fdcf555f","event_at":"2026-07-27T04:33:18.326000Z","event_type":"price_change","frame_hash":"27b85d64364274d2401e527f53e804fbb463e06b15491642f84a0fba1ecb04c2","frame_index":0,"kind":"data","monotonic_ns":228781539005458,"payload":{"event_type":"price_change","market":"0xeb66215f2e9faa6449e30a02bab5b8ed7b79a38bf961f6b24d0073c9c2419250","price_changes":[{"asset_id":"69697746896130839564035629862476347944307040470122503199396727085502753297492","best_ask":"0.13","best_bid":"0.12","hash":"3ff644ce869c1e14664bf82eb7530c4b53e904b8","price":"0.12","side":"BUY","size":"161.84"},{"asset_id":"60386828328910021732068595344565885737045900010034836345809386672230885527307","best_ask":"0.88","best_bid":"0.87","hash":"f726946d9eb25ecc3d32117a0154d8717051588d","price":"0.88","side":"SELL","size":"161.84"}],"timestamp":"1785126798326"},"payload_hash":"4d1f31d51f3c4f43aa1bece90e423938b5976c00d279d07f15b1d8a7acf6c402","raw_frame":"{\"market\":\"0xeb66215f2e9faa6449e30a02bab5b8ed7b79a38bf961f6b24d0073c9c2419250\", \"price_changes\":[{\"asset_id\":\"69697746896130839564035629862476347944307040470122503199396727085502753297492\", \"price\":\"0.12\", \"size\":\"161.84\", \"side\":\"BUY\", \"hash\":\"3ff644ce869c1e14664bf82eb7530c4b53e904b8\", \"best_bid\":\"0.12\", \"best_ask\":\"0.13\"}, {\"asset_id\":\"60386828328910021732068595344565885737045900010034836345809386672230885527307\", \"price\":\"0.88\", \"size\":\"161.84\", \"side\":\"SELL\", \"hash\":\"f726946d9eb25ecc3d32117a0154d8717051588d\", \"best_bid\":\"0.87\", \"best_ask\":\"0.88\"}], \"timestamp\":\"1785126798326\", \"event_type\":\"price_change\"}","received_at":"2026-07-27T04:33:18.270884Z","schema_version":"clob-market-ws.price_change.v1","sequence":null,"server_hash":null,"server_timestamp":"1785126798326","session_id":"e9443c7415a0419799bee9cfbb1a9e4d","source":"clob_market_ws"},"received_at":"2026-07-27T04:33:18.270884Z","record_id":"bce14554970819bf9017a7570f21791526e41a2d7ed1c5b4b6be6f6ebdab5546","schema_fingerprint":"4aa3821a28b0b7c2400bc59aba4bcc0a76e971dadd19610d3ad38c768e124dc7","schema_version":"edge-lab-recorder.raw.v1","sequence":null,"source":"clob_market_ws"}
{"event_at":"2026-07-27T04:33:18.327000Z","event_fingerprint":"5d286be96dced88a71bfe164555eaab60a08edf33de0d133325b15f9e5d81302","payload":{"connection_id":"0f4979d6978d463e9660b042fdcf555f","event_at":"2026-07-27T04:33:18.327000Z","event_type":"price_change","frame_hash":"6c78ae1a5f8d32526b27ed2af8a06bf262acd454ec2a8f0bccc411bad76e13d3","frame_index":0,"kind":"data","monotonic_ns":228781540600500,"payload":{"event_type":"price_change","market":"0xeb66215f2e9faa6449e30a02bab5b8ed7b79a38bf961f6b24d0073c9c2419250","price_changes":[{"asset_id":"69697746896130839564035629862476347944307040470122503199396727085502753297492","best_ask":"0.13","best_bid":"0.12","hash":"d10db4e1c6e65bc8c42055de082f07b29ba7118a","price":"0.12","side":"BUY","size":"65.84"},{"asset_id":"60386828328910021732068595344565885737045900010034836345809386672230885527307","best_ask":"0.88","best_bid":"0.87","hash":"62a8b180081fe5f3d5d9e9aebfff9e3ed3c92790","price":"0.88","side":"SELL","size":"65.84"}],"timestamp":"1785126798327"},"payload_hash":"927d9f7eedd1c092292bb8c18c092e204e5b168ae7c1242643a96308e5dd9e6b","raw_frame":"{\"market\":\"0xeb66215f2e9faa6449e30a02bab5b8ed7b79a38bf961f6b24d0073c9c2419250\", \"price_changes\":[{\"asset_id\":\"69697746896130839564035629862476347944307040470122503199396727085502753297492\", \"price\":\"0.12\", \"size\":\"65.84\", \"side\":\"BUY\", \"hash\":\"d10db4e1c6e65bc8c42055de082f07b29ba7118a\", \"best_bid\":\"0.12\", \"best_ask\":\"0.13\"}, {\"asset_id\":\"60386828328910021732068595344565885737045900010034836345809386672230885527307\", \"price\":\"0.88\", \"size\":\"65.84\", \"side\":\"SELL\", \"hash\":\"62a8b180081fe5f3d5d9e9aebfff9e3ed3c92790\", \"best_bid\":\"0.87\", \"best_ask\":\"0.88\"}], \"timestamp\":\"1785126798327\", \"event_type\":\"price_change\"}","received_at":"2026-07-27T04:33:18.272482Z","schema_version":"clob-market-ws.price_change.v1","sequence":null,"server_hash":null,"server_timestamp":"1785126798327","session_id":"e9443c7415a0419799bee9cfbb1a9e4d","source":"clob_market_ws"},"received_at":"2026-07-27T04:33:18.272482Z","record_id":"a8b9e52bcc6e36c8f921d7598524c542bcd40118cbbad73d42033451ff5722dd","schema_fingerprint":"4aa3821a28b0b7c2400bc59aba4bcc0a76e971dadd19610d3ad38c768e124dc7","schema_version":"edge-lab-recorder.raw.v1","sequence":null,"source":"clob_market_ws"}
{"event_at":"2026-07-27T04:33:18.328000Z","event_fingerprint":"00481e52af7931e1a6f69f8ae734985d3319787fe731f42ed3189e3eb3542381","payload":{"connection_id":"0f4979d6978d463e9660b042fdcf555f","event_at":"2026-07-27T04:33:18.328000Z","event_type":"price_change","frame_hash":"48fe37b136e4d61fe84bae28733f5713ed11dc45832659478a85290e82658d88","frame_index":0,"kind":"data","monotonic_ns":228781542228208,"payload":{"event_type":"price_change","market":"0xeb66215f2e9faa6449e30a02bab5b8ed7b79a38bf961f6b24d0073c9c2419250","price_changes":[{"asset_id":"69697746896130839564035629862476347944307040470122503199396727085502753297492","best_ask":"0.13","best_bid":"0.12","hash":"4931265aca45701ec1f6a0133c998fbb9878254f","price":"0.11","side":"BUY","size":"174.64"},{"asset_id":"60386828328910021732068595344565885737045900010034836345809386672230885527307","best_ask":"0.88","best_bid":"0.87","hash":"cc37f2ba940eeece12ac8b9a75e9aa0a2b6ac8d1","price":"0.89","side":"SELL","size":"174.64"}],"timestamp":"1785126798328"},"payload_hash":"40ecb04e896fbc46a290cdb259d2db0a2881bf1d3b347cbb13e497e2dbaa4a17","raw_frame":"{\"market\":\"0xeb66215f2e9faa6449e30a02bab5b8ed7b79a38bf961f6b24d0073c9c2419250\", \"price_changes\":[{\"asset_id\":\"69697746896130839564035629862476347944307040470122503199396727085502753297492\", \"price\":\"0.11\", \"size\":\"174.64\", \"side\":\"BUY\", \"hash\":\"4931265aca45701ec1f6a0133c998fbb9878254f\", \"best_bid\":\"0.12\", \"best_ask\":\"0.13\"}, {\"asset_id\":\"60386828328910021732068595344565885737045900010034836345809386672230885527307\", \"price\":\"0.89\", \"size\":\"174.64\", \"side\":\"SELL\", \"hash\":\"cc37f2ba940eeece12ac8b9a75e9aa0a2b6ac8d1\", \"best_bid\":\"0.87\", \"best_ask\":\"0.88\"}], \"timestamp\":\"1785126798328\", \"event_type\":\"price_change\"}","received_at":"2026-07-27T04:33:18.274109Z","schema_version":"clob-market-ws.price_change.v1","sequence":null,"server_hash":null,"server_timestamp":"1785126798328","session_id":"e9443c7415a0419799bee9cfbb1a9e4d","source":"clob_market_ws"},"received_at":"2026-07-27T04:33:18.274109Z","record_id":"bbc36fbf33de7bd71d71942396fd2a02b9bc562c50694a3f833a23bd1c6730af","schema_fingerprint":"4aa3821a28b0b7c2400bc59aba4bcc0a76e971dadd19610d3ad38c768e124dc7","schema_version":"edge-lab-recorder.raw.v1","sequence":null,"source":"clob_market_ws"}
{"event_at":"2026-07-27T04:33:18.334000Z","event_fingerprint":"90aae24215a7d772d631ea676e6bf1ceefab2e211ec353690c452627c82dfc1b","payload":{"connection_id":"0f4979d6978d463e9660b042fdcf555f","event_at":"2026-07-27T04:33:18.334000Z","event_type":"price_change","frame_hash":"79873be98b5c7a88eb01167e5160139acf112010e61f854b2f8f7eb331f4264f","frame_index":0,"kind":"data","monotonic_ns":228781547587125,"payload":{"event_type":"price_change","market":"0xeb66215f2e9faa6449e30a02bab5b8ed7b79a38bf961f6b24d0073c9c2419250","price_changes":[{"asset_id":"69697746896130839564035629862476347944307040470122503199396727085502753297492","best_ask":"0.13","best_bid":"0.12","hash":"6444b8b31582b2734d4b80b402b18a05278df5c4","price":"0.07","side":"BUY","size":"805.14"},{"asset_id":"60386828328910021732068595344565885737045900010034836345809386672230885527307","best_ask":"0.88","best_bid":"0.87","hash":"1adde4b06824de0ec435d73b106774d1ba3804f3","price":"0.93","side":"SELL","size":"805.14"}],"timestamp":"1785126798334"},"payload_hash":"b9e03d93f1b3591b02ddddfcad1ff4250e8ec44665c29a1985b678d8dfec5cfd","raw_frame":"{\"market\":\"0xeb66215f2e9faa6449e30a02bab5b8ed7b79a38bf961f6b24d0073c9c2419250\", \"price_changes\":[{\"asset_id\":\"69697746896130839564035629862476347944307040470122503199396727085502753297492\", \"price\":\"0.07\", \"size\":\"805.14\", \"side\":\"BUY\", \"hash\":\"6444b8b31582b2734d4b80b402b18a05278df5c4\", \"best_bid\":\"0.12\", \"best_ask\":\"0.13\"}, {\"asset_id\":\"60386828328910021732068595344565885737045900010034836345809386672230885527307\", \"price\":\"0.93\", \"size\":\"805.14\", \"side\":\"SELL\", \"hash\":\"1adde4b06824de0ec435d73b106774d1ba3804f3\", \"best_bid\":\"0.87\", \"best_ask\":\"0.88\"}], \"timestamp\":\"1785126798334\", \"event_type\":\"price_change\"}","received_at":"2026-07-27T04:33:18.279468Z","schema_version":"clob-market-ws.price_change.v1","sequence":null,"server_hash":null,"server_timestamp":"1785126798334","session_id":"e9443c7415a0419799bee9cfbb1a9e4d","source":"clob_market_ws"},"received_at":"2026-07-27T04:33:18.279468Z","record_id":"0ed6895dfa0151763e51231fd55984acbcb7ea66121917c090204276c92bd77b","schema_fingerprint":"4aa3821a28b0b7c2400bc59aba4bcc0a76e971dadd19610d3ad38c768e124dc7","schema_version":"edge-lab-recorder.raw.v1","sequence":null,"source":"clob_market_ws"}
{"event_at":"2026-07-27T04:33:18.336000Z","event_fingerprint":"53ca6b7aad6955e097e7c71a4bc4d74baf7357041062918b3f6319cf3eb06435","payload":{"connection_id":"0f4979d6978d463e9660b042fdcf555f","event_at":"2026-07-27T04:33:18.336000Z","event_type":"price_change","frame_hash":"f185d37ad82d4c5530c38b88dba80ba79fc8cdc6bd22faf62d7b8175fe25d69e","frame_index":0,"kind":"data","monotonic_ns":228781549123166,"payload":{"event_type":"price_change","market":"0xeb66215f2e9faa6449e30a02bab5b8ed7b79a38bf961f6b24d0073c9c2419250","price_changes":[{"asset_id":"60386828328910021732068595344565885737045900010034836345809386672230885527307","best_ask":"0.88","best_bid":"0.87","hash":"20530bf6fd9ba5a2cd13cec54dfe62977f448583","price":"0.03","side":"BUY","size":"643.1"},{"asset_id":"69697746896130839564035629862476347944307040470122503199396727085502753297492","best_ask":"0.13","best_bid":"0.12","hash":"b64d0c866756e19fcde935beb3939799015e221d","price":"0.97","side":"SELL","size":"643.1"}],"timestamp":"1785126798336"},"payload_hash":"82c814f17a54bf08a1ba78952a8acaa66abebed79635392fbc436626d327cfdf","raw_frame":"{\"market\":\"0xeb66215f2e9faa6449e30a02bab5b8ed7b79a38bf961f6b24d0073c9c2419250\", \"price_changes\":[{\"asset_id\":\"60386828328910021732068595344565885737045900010034836345809386672230885527307\", \"price\":\"0.03\", \"size\":\"643.1\", \"side\":\"BUY\", \"hash\":\"20530bf6fd9ba5a2cd13cec54dfe62977f448583\", \"best_bid\":\"0.87\", \"best_ask\":\"0.88\"}, {\"asset_id\":\"69697746896130839564035629862476347944307040470122503199396727085502753297492\", \"price\":\"0.97\", \"size\":\"643.1\", \"side\":\"SELL\", \"hash\":\"b64d0c866756e19fcde935beb3939799015e221d\", \"best_bid\":\"0.12\", \"best_ask\":\"0.13\"}], \"timestamp\":\"1785126798336\", \"event_type\":\"price_change\"}","received_at":"2026-07-27T04:33:18.281003Z","schema_version":"clob-market-ws.price_change.v1","sequence":null,"server_hash":null,"server_timestamp":"1785126798336","session_id":"e9443c7415a0419799bee9cfbb1a9e4d","source":"clob_market_ws"},"received_at":"2026-07-27T04:33:18.281003Z","record_id":"f996f547f26b0ce4de2aed10a1142fb2332dd9c3df01273bc93f41f40d9826fc","schema_fingerprint":"4aa3821a28b0b7c2400bc59aba4bcc0a76e971dadd19610d3ad38c768e124dc7","schema_version":"edge-lab-recorder.raw.v1","sequence":null,"source":"clob_market_ws"}
{"event_at":"2026-07-27T04:33:18.337000Z","event_fingerprint":"55b24035030e3bf5143c5e5f7fa07d633f2f5c67cced2997e29b8767c3839fec","payload":{"connection_id":"0f4979d6978d463e9660b042fdcf555f","event_at":"2026-07-27T04:33:18.337000Z","event_type":"price_change","frame_hash":"3a7f66157f78f9a40c24fcefd305b61a379cc202028e1b704b127d970723d985","frame_index":0,"kind":"data","monotonic_ns":228781550736750,"payload":{"event_type":"price_change","market":"0xeb66215f2e9faa6449e30a02bab5b8ed7b79a38bf961f6b24d0073c9c2419250","price_changes":[{"asset_id":"69697746896130839564035629862476347944307040470122503199396727085502753297492","best_ask":"0.13","best_bid":"0.12","hash":"a2b08780f337f41ce30bfc658e0ccbad978c8cbe","price":"0.11","side":"BUY","size":"444.64"},{"asset_id":"60386828328910021732068595344565885737045900010034836345809386672230885527307","best_ask":"0.88","best_bid":"0.87","hash":"1e88af685c54dda176034cabb149e4732e4ba1b3","price":"0.89","side":"SELL","size":"444.64"}],"timestamp":"1785126798337"},"payload_hash":"e06c6a7da740cb9e422dd8f5c35a7ccc7bb0edc95701f1b422bd1cbbcbc38755","raw_frame":"{\"market\":\"0xeb66215f2e9faa6449e30a02bab5b8ed7b79a38bf961f6b24d0073c9c2419250\", \"price_changes\":[{\"asset_id\":\"69697746896130839564035629862476347944307040470122503199396727085502753297492\", \"price\":\"0.11\", \"size\":\"444.64\", \"side\":\"BUY\", \"hash\":\"a2b08780f337f41ce30bfc658e0ccbad978c8cbe\", \"best_bid\":\"0.12\", \"best_ask\":\"0.13\"}, {\"asset_id\":\"60386828328910021732068595344565885737045900010034836345809386672230885527307\", \"price\":\"0.89\", \"size\":\"444.64\", \"side\":\"SELL\", \"hash\":\"1e88af685c54dda176034cabb149e4732e4ba1b3\", \"best_bid\":\"0.87\", \"best_ask\":\"0.88\"}], \"timestamp\":\"1785126798337\", \"event_type\":\"price_change\"}","received_at":"2026-07-27T04:33:18.282619Z","schema_version":"clob-market-ws.price_change.v1","sequence":null,"server_hash":null,"server_timestamp":"1785126798337","session_id":"e9443c7415a0419799bee9cfbb1a9e4d","source":"clob_market_ws"},"received_at":"2026-07-27T04:33:18.282619Z","record_id":"798928dbbba834abd5654be5324cf11f410926a89a5e44e540777775c36e007f","schema_fingerprint":"4aa3821a28b0b7c2400bc59aba4bcc0a76e971dadd19610d3ad38c768e124dc7","schema_version":"edge-lab-recorder.raw.v1","sequence":null,"source":"clob_market_ws"}
