{"event_at":"2026-07-27T04:31:06.265000Z","event_fingerprint":"f89f70ec2965f8739eb22daf3decc5e1c6f860c52ec45afe2dae4bd2b7be2ad4","payload":{"connection_id":"0f4979d6978d463e9660b042fdcf555f","event_at":"2026-07-27T04:31:06.265000Z","event_type":"price_change","frame_hash":"ec23f9ba73c699c385d3530aae6ed5a17a0ca1d2ff4dc09d1aee5f6f6dfa6e10","frame_index":0,"kind":"data","monotonic_ns":228654945597916,"payload":{"event_type":"price_change","market":"0xeb66215f2e9faa6449e30a02bab5b8ed7b79a38bf961f6b24d0073c9c2419250","price_changes":[{"asset_id":"69697746896130839564035629862476347944307040470122503199396727085502753297492","best_ask":"0.41","best_bid":"0.4","hash":"6c02e0132c0aebd489aac828ee32d6bedeb65fd0","price":"0.38","side":"BUY","size":"92.32"},{"asset_id":"60386828328910021732068595344565885737045900010034836345809386672230885527307","best_ask":"0.6","best_bid":"0.59","hash":"9c72df22a10c913aaac8e2ead627fee8d2f200c3","price":"0.62","side":"SELL","size":"92.32"}],"timestamp":"1785126666265"},"payload_hash":"f18a2cd08d53f1f19c01e703f9d62531469f2d1d8aec3ab280919c8985b5efc1","raw_frame":"{\"market\":\"0xeb66215f2e9faa6449e30a02bab5b8ed7b79a38bf961f6b24d0073c9c2419250\", \"price_changes\":[{\"asset_id\":\"69697746896130839564035629862476347944307040470122503199396727085502753297492\", \"price\":\"0.38\", \"size\":\"92.32\", \"side\":\"BUY\", \"hash\":\"6c02e0132c0aebd489aac828ee32d6bedeb65fd0\", \"best_bid\":\"0.4\", \"best_ask\":\"0.41\"}, {\"asset_id\":\"60386828328910021732068595344565885737045900010034836345809386672230885527307\", \"price\":\"0.62\", \"size\":\"92.32\", \"side\":\"SELL\", \"hash\":\"9c72df22a10c913aaac8e2ead627fee8d2f200c3\", \"best_bid\":\"0.59\", \"best_ask\":\"0.6\"}], \"timestamp\":\"1785126666265\", \"event_type\":\"price_change\"}","received_at":"2026-07-27T04:31:11.676383Z","schema_version":"clob-market-ws.price_change.v1","sequence":null,"server_hash":null,"server_timestamp":"1785126666265","session_id":"e9443c7415a0419799bee9cfbb1a9e4d","source":"clob_market_ws"},"received_at":"2026-07-27T04:31:11.676383Z","record_id":"e1d549dce3312f83df646d7af821305b8b7a74c57dc8fc33e8589e7b670c863d","schema_fingerprint":"4aa3821a28b0b7c2400bc59aba4bcc0a76e971dadd19610d3ad38c768e124dc7","schema_version":"edge-lab-recorder.raw.v1","sequence":null,"source":"clob_market_ws"}
{"event_at":"2026-07-27T04:31:06.294000Z","event_fingerprint":"da2946d36b23eef5aad41e38011fce0e929456eb3e870481015f748dcc9a2c5e","payload":{"connection_id":"0f4979d6978d463e9660b042fdcf555f","event_at":"2026-07-27T04:31:06.294000Z","event_type":"price_change","frame_hash":"346500370426f0b0e63270ac92ba9485fa3ec54afdcc5221535b0986539f2723","frame_index":0,"kind":"data","monotonic_ns":228654968784166,"payload":{"event_type":"price_change","market":"0xeb66215f2e9faa6449e30a02bab5b8ed7b79a38bf961f6b24d0073c9c2419250","price_changes":[{"asset_id":"60386828328910021732068595344565885737045900010034836345809386672230885527307","best_ask":"0.6","best_bid":"0.59","hash":"7388d91580105e565d9c0ceecbfb0b9224bcce45","price":"0.04","side":"BUY","size":"753.09"},{"asset_id":"69697746896130839564035629862476347944307040470122503199396727085502753297492","best_ask":"0.41","best_bid":"0.4","hash":"2cceb340717a91918d14bdcda9dff2b6bb2ca6f4","price":"0.96","side":"SELL","size":"753.09"}],"timestamp":"1785126666294"},"payload_hash":"c64bc7648580de8f75966949ad2105de05bc37934b212bcf21d13cc64b2a5a09","raw_frame":"{\"market\":\"0xeb66215f2e9faa6449e30a02bab5b8ed7b79a38bf961f6b24d0073c9c2419250\", \"price_changes\":[{\"asset_id\":\"60386828328910021732068595344565885737045900010034836345809386672230885527307\", \"price\":\"0.04\", \"size\":\"753.09\", \"side\":\"BUY\", \"hash\":\"7388d91580105e565d9c0ceecbfb0b9224bcce45\", \"best_bid\":\"0.59\", \"best_ask\":\"0.6\"}, {\"asset_id\":\"69697746896130839564035629862476347944307040470122503199396727085502753297492\", \"price\":\"0.96\", \"size\":\"753.09\", \"side\":\"SELL\", \"hash\":\"2cceb340717a91918d14bdcda9dff2b6bb2ca6f4\", \"best_bid\":\"0.4\", \"best_ask\":\"0.41\"}], \"timestamp\":\"1785126666294\", \"event_type\":\"price_change\"}","received_at":"2026-07-27T04:31:11.699569Z","schema_version":"clob-market-ws.price_change.v1","sequence":null,"server_hash":null,"server_timestamp":"1785126666294","session_id":"e9443c7415a0419799bee9cfbb1a9e4d","source":"clob_market_ws"},"received_at":"2026-07-27T04:31:11.699569Z","record_id":"9bea23ffb9fab03de8f58d6c649d148835a6842e551590cf8f7c4ed7c97cfc3c","schema_fingerprint":"4aa3821a28b0b7c2400bc59aba4bcc0a76e971dadd19610d3ad38c768e124dc7","schema_version":"edge-lab-recorder.raw.v1","sequence":null,"source":"clob_market_ws"}
{"event_at":"2026-07-27T04:31:06.307000Z","event_fingerprint":"ec61b3153b3b5ab09eec0df372ff0c2f5512daa783f4f59f14b8c66a44f345f4","payload":{"connection_id":"0f4979d6978d463e9660b042fdcf555f","event_at":"2026-07-27T04:31:06.307000Z","event_type":"price_change","frame_hash":"128254c071f44390535984acf0fab543fdae1ac13f164108a800a95fbf72fd45","frame_index":0,"kind":"data","monotonic_ns":228654977728916,"payload":{"event_type":"price_change","market":"0xeb66215f2e9faa6449e30a02bab5b8ed7b79a38bf961f6b24d0073c9c2419250","price_changes":[{"asset_id":"69697746896130839564035629862476347944307040470122503199396727085502753297492","best_ask":"0.41","best_bid":"0.4","hash":"0cf420182d426efae8e2721c48afd4dd6b0d8e10","price":"0.34","side":"BUY","size":"73.4"},{"asset_id":"60386828328910021732068595344565885737045900010034836345809386672230885527307","best_ask":"0.6","best_bid":"0.59","hash":"df7c74aacdc6290983ca8cded0cee4adeb5a5552","price":"0.66","side":"SELL","size":"73.4"}],"timestamp":"1785126666307"},"payload_hash":"6f7e526eb09dc01ae35e9c73109c7a34925f038663504f275ad117022a7b2b79","raw_frame":"{\"market\":\"0xeb66215f2e9faa6449e30a02bab5b8ed7b79a38bf961f6b24d0073c9c2419250\", \"price_changes\":[{\"asset_id\":\"69697746896130839564035629862476347944307040470122503199396727085502753297492\", \"price\":\"0.34\", \"size\":\"73.4\", \"side\":\"BUY\", \"hash\":\"0cf420182d426efae8e2721c48afd4dd6b0d8e10\", \"best_bid\":\"0.4\", \"best_ask\":\"0.41\"}, {\"asset_id\":\"60386828328910021732068595344565885737045900010034836345809386672230885527307\", \"price\":\"0.66\", \"size\":\"73.4\", \"side\":\"SELL\", \"hash\":\"df7c74aacdc6290983ca8cded0cee4adeb5a5552\", \"best_bid\":\"0.59\", \"best_ask\":\"0.6\"}], \"timestamp\":\"1785126666307\", \"event_type\":\"price_change\"}","received_at":"2026-07-27T04:31:11.708515Z","schema_version":"clob-market-ws.price_change.v1","sequence":null,"server_hash":null,"server_timestamp":"1785126666307","session_id":"e9443c7415a0419799bee9cfbb1a9e4d","source":"clob_market_ws"},"received_at":"2026-07-27T04:31:11.708515Z","record_id":"d567fe2c740250e4b6f5fc362bc5ad0495f22586f7ad360dd93b928f22d462c7","schema_fingerprint":"4aa3821a28b0b7c2400bc59aba4bcc0a76e971dadd19610d3ad38c768e124dc7","schema_version":"edge-lab-recorder.raw.v1","sequence":null,"source":"clob_market_ws"}
{"event_at":"2026-07-27T04:31:06.308000Z","event_fingerprint":"8304b3a55be00defec4bc61d176a21eb4ea1ec442051d7a9815536bef8539e92","payload":{"connection_id":"0f4979d6978d463e9660b042fdcf555f","event_at":"2026-07-27T04:31:06.308000Z","event_type":"price_change","frame_hash":"4eafa555fea23daaa550903f198bf120956901ff73e001b30a72e9c335672bf7","frame_index":0,"kind":"data","monotonic_ns":228654985567458,"payload":{"event_type":"price_change","market":"0xeb66215f2e9faa6449e30a02bab5b8ed7b79a38bf961f6b24d0073c9c2419250","price_changes":[{"asset_id":"60386828328910021732068595344565885737045900010034836345809386672230885527307","best_ask":"0.6","best_bid":"0.59","hash":"68f8149f0e99732b723b88708709b0a9c310c096","price":"0.01","side":"BUY","size":"7708.02"},{"asset_id":"69697746896130839564035629862476347944307040470122503199396727085502753297492","best_ask":"0.41","best_bid":"0.4","hash":"7cf58dc4e6a60d1d9b25d3d241aa149cc7ef7d6a","price":"0.99","side":"SELL","size":"7708.02"}],"timestamp":"1785126666308"},"payload_hash":"f0eddd19b4d06133ab1ba851060bc7e68b10c939a50d891280591b6d143c40e4","raw_frame":"{\"market\":\"0xeb66215f2e9faa6449e30a02bab5b8ed7b79a38bf961f6b24d0073c9c2419250\", \"price_changes\":[{\"asset_id\":\"60386828328910021732068595344565885737045900010034836345809386672230885527307\", \"price\":\"0.01\", \"size\":\"7708.02\", \"side\":\"BUY\", \"hash\":\"68f8149f0e99732b723b88708709b0a9c310c096\", \"best_bid\":\"0.59\", \"best_ask\":\"0.6\"}, {\"asset_id\":\"69697746896130839564035629862476347944307040470122503199396727085502753297492\", \"price\":\"0.99\", \"size\":\"7708.02\", \"side\":\"SELL\", \"hash\":\"7cf58dc4e6a60d1d9b25d3d241aa149cc7ef7d6a\", \"best_bid\":\"0.4\", \"best_ask\":\"0.41\"}], \"timestamp\":\"1785126666308\", \"event_type\":\"price_change\"}","received_at":"2026-07-27T04:31:11.716352Z","schema_version":"clob-market-ws.price_change.v1","sequence":null,"server_hash":null,"server_timestamp":"1785126666308","session_id":"e9443c7415a0419799bee9cfbb1a9e4d","source":"clob_market_ws"},"received_at":"2026-07-27T04:31:11.716352Z","record_id":"9b1daede38d9cc7e56029e3daab797fe157d14cf8daa28443bda831841ee874b","schema_fingerprint":"4aa3821a28b0b7c2400bc59aba4bcc0a76e971dadd19610d3ad38c768e124dc7","schema_version":"edge-lab-recorder.raw.v1","sequence":null,"source":"clob_market_ws"}
{"event_at":"2026-07-27T04:31:06.323000Z","event_fingerprint":"2efbf3609f10c4ad4ff3cbbfe329a08614cd83af3f421c9b2b332fdf34fbf4e6","payload":{"connection_id":"0f4979d6978d463e9660b042fdcf555f","event_at":"2026-07-27T04:31:06.323000Z","event_type":"price_change","frame_hash":"8fc74ed411647accd8930a1e4cb8688c9fe7e5c515b0e0096123622757e6bbfb","frame_index":0,"kind":"data","monotonic_ns":228654996630791,"payload":{"event_type":"price_change","market":"0xeb66215f2e9faa6449e30a02bab5b8ed7b79a38bf961f6b24d0073c9c2419250","price_changes":[{"asset_id":"69697746896130839564035629862476347944307040470122503199396727085502753297492","best_ask":"0.41","best_bid":"0.4","hash":"0d9f41a1361d589337c1c8ad9bd209b22ede1410","price":"0.3","side":"BUY","size":"475.63"},{"asset_id":"60386828328910021732068595344565885737045900010034836345809386672230885527307","best_ask":"0.6","best_bid":"0.59","hash":"b90040a837a403da43f9542ea8acfccfb9c5aa54","price":"0.7","side":"SELL","size":"475.63"}],"timestamp":"1785126666323"},"payload_hash":"5c72df3b50cee6c69424880c88b3a9ca5a327ab6968eb858a05ec1a5733c7422","raw_frame":"{\"market\":\"0xeb66215f2e9faa6449e30a02bab5b8ed7b79a38bf961f6b24d0073c9c2419250\", \"price_changes\":[{\"asset_id\":\"69697746896130839564035629862476347944307040470122503199396727085502753297492\", \"price\":\"0.3\", \"size\":\"475.63\", \"side\":\"BUY\", \"hash\":\"0d9f41a1361d589337c1c8ad9bd209b22ede1410\", \"best_bid\":\"0.4\", \"best_ask\":\"0.41\"}, {\"asset_id\":\"60386828328910021732068595344565885737045900010034836345809386672230885527307\", \"price\":\"0.7\", \"size\":\"475.63\", \"side\":\"SELL\", \"hash\":\"b90040a837a403da43f9542ea8acfccfb9c5aa54\", \"best_bid\":\"0.59\", \"best_ask\":\"0.6\"}], \"timestamp\":\"1785126666323\", \"event_type\":\"price_change\"}","received_at":"2026-07-27T04:31:11.727416Z","schema_version":"clob-market-ws.price_change.v1","sequence":null,"server_hash":null,"server_timestamp":"1785126666323","session_id":"e9443c7415a0419799bee9cfbb1a9e4d","source":"clob_market_ws"},"received_at":"2026-07-27T04:31:11.727416Z","record_id":"93bf45312a5d86da104b22f34551a047ccd1c76e8e1f4c7161c16040eed0c948","schema_fingerprint":"4aa3821a28b0b7c2400bc59aba4bcc0a76e971dadd19610d3ad38c768e124dc7","schema_version":"edge-lab-recorder.raw.v1","sequence":null,"source":"clob_market_ws"}
{"event_at":"2026-07-27T04:31:06.342000Z","event_fingerprint":"300667667fbbba0d6d0245d47dddf91bf51c7886152f852298b8e0d5d18f1db6","payload":{"connection_id":"0f4979d6978d463e9660b042fdcf555f","event_at":"2026-07-27T04:31:06.342000Z","event_type":"price_change","frame_hash":"91c5825d00dc1af679eab58e8093a2e912119948f0ae0948dacc643917ddf8a5","frame_index":0,"kind":"data","monotonic_ns":228655005550083,"payload":{"event_type":"price_change","market":"0xeb66215f2e9faa6449e30a02bab5b8ed7b79a38bf961f6b24d0073c9c2419250","price_changes":[{"asset_id":"60386828328910021732068595344565885737045900010034836345809386672230885527307","best_ask":"0.6","best_bid":"0.59","hash":"d98bda64c9f82fd084576b416792dd9f9c669ebe","price":"0.01","side":"BUY","size":"7703.02"},{"asset_id":"69697746896130839564035629862476347944307040470122503199396727085502753297492","best_ask":"0.41","best_bid":"0.4","hash":"13c6f6fe9a59c7c21e7b5084589873afabe371bf","price":"0.99","side":"SELL","size":"7703.02"}],"timestamp":"1785126666342"},"payload_hash":"a0104c207fe2d4b11c19a3043f637a0a8cd08b4932a9a08589b2dc004e4c92f4","raw_frame":"{\"market\":\"0xeb66215f2e9faa6449e30a02bab5b8ed7b79a38bf961f6b24d0073c9c2419250\", \"price_changes\":[{\"asset_id\":\"60386828328910021732068595344565885737045900010034836345809386672230885527307\", \"price\":\"0.01\", \"size\":\"7703.02\", \"side\":\"BUY\", \"hash\":\"d98bda64c9f82fd084576b416792dd9f9c669ebe\", \"best_bid\":\"0.59\", \"best_ask\":\"0.6\"}, {\"asset_id\":\"69697746896130839564035629862476347944307040470122503199396727085502753297492\", \"price\":\"0.99\", \"size\":\"7703.02\", \"side\":\"SELL\", \"hash\":\"13c6f6fe9a59c7c21e7b5084589873afabe371bf\", \"best_bid\":\"0.4\", \"best_ask\":\"0.41\"}], \"timestamp\":\"1785126666342\", \"event_type\":\"price_change\"}","received_at":"2026-07-27T04:31:11.736333Z","schema_version":"clob-market-ws.price_change.v1","sequence":null,"server_hash":null,"server_timestamp":"1785126666342","session_id":"e9443c7415a0419799bee9cfbb1a9e4d","source":"clob_market_ws"},"received_at":"2026-07-27T04:31:11.736333Z","record_id":"ebe19a7fe534b5bc44ed990a2da4af35c6570ad02854c0d12afba8c32b0fc21c","schema_fingerprint":"4aa3821a28b0b7c2400bc59aba4bcc0a76e971dadd19610d3ad38c768e124dc7","schema_version":"edge-lab-recorder.raw.v1","sequence":null,"source":"clob_market_ws"}
{"event_at":"2026-07-27T04:31:06.343000Z","event_fingerprint":"7d31c403405baef8534d52c4684b5d3944ca76aeae88b744b1afc74d42abbd03","payload":{"connection_id":"0f4979d6978d463e9660b042fdcf555f","event_at":"2026-07-27T04:31:06.343000Z","event_type":"price_change","frame_hash":"4e34c1316d395873c7680f052bcd0754ac5f2913cba82a6949ed3288fe8fb85c","frame_index":0,"kind":"data","monotonic_ns":228655018482416,"payload":{"event_type":"price_change","market":"0xeb66215f2e9faa6449e30a02bab5b8ed7b79a38bf961f6b24d0073c9c2419250","price_changes":[{"asset_id":"69697746896130839564035629862476347944307040470122503199396727085502753297492","best_ask":"0.41","best_bid":"0.4","hash":"52b738ebef665c93339122ddbf902e8d1c1ead3b","price":"0.33","side":"BUY","size":"133.6"},{"asset_id":"60386828328910021732068595344565885737045900010034836345809386672230885527307","best_ask":"0.6","best_bid":"0.59","hash":"9910478411dc1b2543644d13e354b7f4c6a4378a","price":"0.67","side":"SELL","size":"133.6"}],"timestamp":"1785126666343"},"payload_hash":"8b87083410571e514c8e39bc6abc7321ba7ddce57e14bf958cccaee85fff4edd","raw_frame":"{\"market\":\"0xeb66215f2e9faa6449e30a02bab5b8ed7b79a38bf961f6b24d0073c9c2419250\", \"price_changes\":[{\"asset_id\":\"69697746896130839564035629862476347944307040470122503199396727085502753297492\", \"price\":\"0.33\", \"size\":\"133.6\", \"side\":\"BUY\", \"hash\":\"52b738ebef665c93339122ddbf902e8d1c1ead3b\", \"best_bid\":\"0.4\", \"best_ask\":\"0.41\"}, {\"asset_id\":\"60386828328910021732068595344565885737045900010034836345809386672230885527307\", \"price\":\"0.67\", \"size\":\"133.6\", \"side\":\"SELL\", \"hash\":\"9910478411dc1b2543644d13e354b7f4c6a4378a\", \"best_bid\":\"0.59\", \"best_ask\":\"0.6\"}], \"timestamp\":\"1785126666343\", \"event_type\":\"price_change\"}","received_at":"2026-07-27T04:31:11.749268Z","schema_version":"clob-market-ws.price_change.v1","sequence":null,"server_hash":null,"server_timestamp":"1785126666343","session_id":"e9443c7415a0419799bee9cfbb1a9e4d","source":"clob_market_ws"},"received_at":"2026-07-27T04:31:11.749268Z","record_id":"536fa4ee9d337879181fbc9e44b5b60d7ec4129911164ea9550268c6c0c64521","schema_fingerprint":"4aa3821a28b0b7c2400bc59aba4bcc0a76e971dadd19610d3ad38c768e124dc7","schema_version":"edge-lab-recorder.raw.v1","sequence":null,"source":"clob_market_ws"}
{"event_at":"2026-07-27T04:31:06.350000Z","event_fingerprint":"adef3614d1dbbd8e32f7bc9c431173dbb0fde47dac40fec27008ca853d53b033","payload":{"connection_id":"0f4979d6978d463e9660b042fdcf555f","event_at":"2026-07-27T04:31:06.350000Z","event_type":"price_change","frame_hash":"4b45dd5e6498d554bb20bf29bef60868a4658ab3618546e632f8204cd509363a","frame_index":0,"kind":"data","monotonic_ns":228655029020791,"payload":{"event_type":"price_change","market":"0xeb66215f2e9faa6449e30a02bab5b8ed7b79a38bf961f6b24d0073c9c2419250","price_changes":[{"asset_id":"60386828328910021732068595344565885737045900010034836345809386672230885527307","best_ask":"0.6","best_bid":"0.59","hash":"d318fb0343fea3d73f670d6d69db65395575f89b","price":"0.04","side":"BUY","size":"748.09"},{"asset_id":"69697746896130839564035629862476347944307040470122503199396727085502753297492","best_ask":"0.41","best_bid":"0.4","hash":"aee73210c811964f1b1cac3d28bc48a8617e0600","price":"0.96","side":"SELL","size":"748.09"}],"timestamp":"1785126666350"},"payload_hash":"15c29771deb27f9c3c50be33ce3b91a9ea633169bd955d555ec123922d51c375","raw_frame":"{\"market\":\"0xeb66215f2e9faa6449e30a02bab5b8ed7b79a38bf961f6b24d0073c9c2419250\", \"price_changes\":[{\"asset_id\":\"60386828328910021732068595344565885737045900010034836345809386672230885527307\", \"price\":\"0.04\", \"size\":\"748.09\", \"side\":\"BUY\", \"hash\":\"d318fb0343fea3d73f670d6d69db65395575f89b\", \"best_bid\":\"0.59\", \"best_ask\":\"0.6\"}, {\"asset_id\":\"69697746896130839564035629862476347944307040470122503199396727085502753297492\", \"price\":\"0.96\", \"size\":\"748.09\", \"side\":\"SELL\", \"hash\":\"aee73210c811964f1b1cac3d28bc48a8617e0600\", \"best_bid\":\"0.4\", \"best_ask\":\"0.41\"}], \"timestamp\":\"1785126666350\", \"event_type\":\"price_change\"}","received_at":"2026-07-27T04:31:11.759806Z","schema_version":"clob-market-ws.price_change.v1","sequence":null,"server_hash":null,"server_timestamp":"1785126666350","session_id":"e9443c7415a0419799bee9cfbb1a9e4d","source":"clob_market_ws"},"received_at":"2026-07-27T04:31:11.759806Z","record_id":"90c6ab5952f1ed571419185419410631198bc2497d8fecc39ea5a32a838ce6d1","schema_fingerprint":"4aa3821a28b0b7c2400bc59aba4bcc0a76e971dadd19610d3ad38c768e124dc7","schema_version":"edge-lab-recorder.raw.v1","sequence":null,"source":"clob_market_ws"}
{"event_at":"2026-07-27T04:31:06.372000Z","event_fingerprint":"4cabfe52e9b7ada975884e66ad1ba328be43afd586bd4c670a4501af5e99e7bb","payload":{"connection_id":"0f4979d6978d463e9660b042fdcf555f","event_at":"2026-07-27T04:31:06.372000Z","event_type":"price_change","frame_hash":"360d9ed574d67a13d2b7446d4312c1640e00c2fbc0e6b75407bbe96b8c3b0e50","frame_index":0,"kind":"data","monotonic_ns":228655036480875,"payload":{"event_type":"price_change","market":"0xeb66215f2e9faa6449e30a02bab5b8ed7b79a38bf961f6b24d0073c9c2419250","price_changes":[{"asset_id":"69697746896130839564035629862476347944307040470122503199396727085502753297492","best_ask":"0.41","best_bid":"0.4","hash":"e819c61d834c52deafa910bb606321805796206a","price":"0.41","side":"SELL","size":"28"},{"asset_id":"60386828328910021732068595344565885737045900010034836345809386672230885527307","best_ask":"0.6","best_bid":"0.59","hash":"5e85c28f754d24b7aa5e0ca8142cd1b503a10745","price":"0.59","side":"BUY","size":"28"}],"timestamp":"1785126666372"},"payload_hash":"612077d922372be42193676b2dd174ae93ef59770893256bec67ecc7bb26c362","raw_frame":"{\"market\":\"0xeb66215f2e9faa6449e30a02bab5b8ed7b79a38bf961f6b24d0073c9c2419250\", \"price_changes\":[{\"asset_id\":\"69697746896130839564035629862476347944307040470122503199396727085502753297492\", \"price\":\"0.41\", \"size\":\"28\", \"side\":\"SELL\", \"hash\":\"e819c61d834c52deafa910bb606321805796206a\", \"best_bid\":\"0.4\", \"best_ask\":\"0.41\"}, {\"asset_id\":\"60386828328910021732068595344565885737045900010034836345809386672230885527307\", \"price\":\"0.59\", \"size\":\"28\", \"side\":\"BUY\", \"hash\":\"5e85c28f754d24b7aa5e0ca8142cd1b503a10745\", \"best_bid\":\"0.59\", \"best_ask\":\"0.6\"}], \"timestamp\":\"1785126666372\", \"event_type\":\"price_change\"}","received_at":"2026-07-27T04:31:11.767261Z","schema_version":"clob-market-ws.price_change.v1","sequence":null,"server_hash":null,"server_timestamp":"1785126666372","session_id":"e9443c7415a0419799bee9cfbb1a9e4d","source":"clob_market_ws"},"received_at":"2026-07-27T04:31:11.767261Z","record_id":"5f793253187684d5a541ee5938899d4a1bda07b897187fbb4c0fe866990ba9d9","schema_fingerprint":"4aa3821a28b0b7c2400bc59aba4bcc0a76e971dadd19610d3ad38c768e124dc7","schema_version":"edge-lab-recorder.raw.v1","sequence":null,"source":"clob_market_ws"}
{"event_at":"2026-07-27T04:31:06.407000Z","event_fingerprint":"8df3008f84381b11202ede22db1b8fc315c42340f2cf1ab7235eac50737d3a12","payload":{"connection_id":"0f4979d6978d463e9660b042fdcf555f","event_at":"2026-07-27T04:31:06.407000Z","event_type":"price_change","frame_hash":"7225449d42832d92e6e7629e6039c4e50038e81432bfc7d90cb4835ed08b5d67","frame_index":0,"kind":"data","monotonic_ns":228655042555333,"payload":{"event_type":"price_change","market":"0xeb66215f2e9faa6449e30a02bab5b8ed7b79a38bf961f6b24d0073c9c2419250","price_changes":[{"asset_id":"60386828328910021732068595344565885737045900010034836345809386672230885527307","best_ask":"0.6","best_bid":"0.59","hash":"9ade9b84c6145e68142c98119e6ce6f770ef2a43","price":"0.58","side":"BUY","size":"135.6"},{"asset_id":"69697746896130839564035629862476347944307040470122503199396727085502753297492","best_ask":"0.41","best_bid":"0.4","hash":"35517f74ce9996ece4f067951fb709924f08c996","price":"0.42","side":"SELL","size":"135.6"}],"timestamp":"1785126666407"},"payload_hash":"051c141e3f95c4d28393870fb931d19b8bc2e165be89bb99be2202839409e7b6","raw_frame":"{\"market\":\"0xeb66215f2e9faa6449e30a02bab5b8ed7b79a38bf961f6b24d0073c9c2419250\", \"price_changes\":[{\"asset_id\":\"60386828328910021732068595344565885737045900010034836345809386672230885527307\", \"price\":\"0.58\", \"size\":\"135.6\", \"side\":\"BUY\", \"hash\":\"9ade9b84c6145e68142c98119e6ce6f770ef2a43\", \"best_bid\":\"0.59\", \"best_ask\":\"0.6\"}, {\"asset_id\":\"69697746896130839564035629862476347944307040470122503199396727085502753297492\", \"price\":\"0.42\", \"size\":\"135.6\", \"side\":\"SELL\", \"hash\":\"35517f74ce9996ece4f067951fb709924f08c996\", \"best_bid\":\"0.4\", \"best_ask\":\"0.41\"}], \"timestamp\":\"1785126666407\", \"event_type\":\"price_change\"}","received_at":"2026-07-27T04:31:11.773341Z","schema_version":"clob-market-ws.price_change.v1","sequence":null,"server_hash":null,"server_timestamp":"1785126666407","session_id":"e9443c7415a0419799bee9cfbb1a9e4d","source":"clob_market_ws"},"received_at":"2026-07-27T04:31:11.773341Z","record_id":"c0484903529f767d0f3e8efcde2bc1974b92bda8c76b51d5e8cb5c8857cb2182","schema_fingerprint":"4aa3821a28b0b7c2400bc59aba4bcc0a76e971dadd19610d3ad38c768e124dc7","schema_version":"edge-lab-recorder.raw.v1","sequence":null,"source":"clob_market_ws"}
{"event_at":"2026-07-27T04:31:06.409000Z","event_fingerprint":"7fe3e1f5758f3208cebe89d9047d9a29b9a2e342f45b6e93db8d6f8c82b25d92","payload":{"connection_id":"0f4979d6978d463e9660b042fdcf555f","event_at":"2026-07-27T04:31:06.409000Z","event_type":"price_change","frame_hash":"1bf879d3e600ff43210ab8df59096c32d84eb739efcd9793197455f5499218df","frame_index":0,"kind":"data","monotonic_ns":228655049580791,"payload":{"event_type":"price_change","market":"0xeb66215f2e9faa6449e30a02bab5b8ed7b79a38bf961f6b24d0073c9c2419250","price_changes":[{"asset_id":"69697746896130839564035629862476347944307040470122503199396727085502753297492","best_ask":"0.41","best_bid":"0.4","hash":"d21508978a2e6949a4047cfa701c794bdf991c39","price":"0.39","side":"BUY","size":"57.2"},{"asset_id":"60386828328910021732068595344565885737045900010034836345809386672230885527307","best_ask":"0.6","best_bid":"0.59","hash":"d4aa8b2cd99867336d1eb408574bdd23d9a599f1","price":"0.61","side":"SELL","size":"57.2"}],"timestamp":"1785126666409"},"payload_hash":"585bd90861923c85de565621ac271abd20558d52b27746fbe9a14ff2a330fc78","raw_frame":"{\"market\":\"0xeb66215f2e9faa6449e30a02bab5b8ed7b79a38bf961f6b24d0073c9c2419250\", \"price_changes\":[{\"asset_id\":\"69697746896130839564035629862476347944307040470122503199396727085502753297492\", \"price\":\"0.39\", \"size\":\"57.2\", \"side\":\"BUY\", \"hash\":\"d21508978a2e6949a4047cfa701c794bdf991c39\", \"best_bid\":\"0.4\", \"best_ask\":\"0.41\"}, {\"asset_id\":\"60386828328910021732068595344565885737045900010034836345809386672230885527307\", \"price\":\"0.61\", \"size\":\"57.2\", \"side\":\"SELL\", \"hash\":\"d4aa8b2cd99867336d1eb408574bdd23d9a599f1\", \"best_bid\":\"0.59\", \"best_ask\":\"0.6\"}], \"timestamp\":\"1785126666409\", \"event_type\":\"price_change\"}","received_at":"2026-07-27T04:31:11.780367Z","schema_version":"clob-market-ws.price_change.v1","sequence":null,"server_hash":null,"server_timestamp":"1785126666409","session_id":"e9443c7415a0419799bee9cfbb1a9e4d","source":"clob_market_ws"},"received_at":"2026-07-27T04:31:11.780367Z","record_id":"87359f3e2fec502dd8192ae11f6509d13f2520b17b094120fecb0915c84b63b2","schema_fingerprint":"4aa3821a28b0b7c2400bc59aba4bcc0a76e971dadd19610d3ad38c768e124dc7","schema_version":"edge-lab-recorder.raw.v1","sequence":null,"source":"clob_market_ws"}
{"event_at":"2026-07-27T04:31:06.412000Z","event_fingerprint":"ece193b39481825ccd79ca796c3b43bd58ab8d75c3428294efbdd05cfd630b0e","payload":{"connection_id":"0f4979d6978d463e9660b042fdcf555f","event_at":"2026-07-27T04:31:06.412000Z","event_type":"price_change","frame_hash":"dd4011b4d196e29bf5e8102c3e9286fd978540e9d9d580d266d55a4fc7835408","frame_index":0,"kind":"data","monotonic_ns":228655053780666,"payload":{"event_type":"price_change","market":"0xeb66215f2e9faa6449e30a02bab5b8ed7b79a38bf961f6b24d0073c9c2419250","price_changes":[{"asset_id":"60386828328910021732068595344565885737045900010034836345809386672230885527307","best_ask":"0.6","best_bid":"0.59","hash":"09c389f4a18af45202c591bab628015fbdc3b827","price":"0.57","side":"BUY","size":"41.4"},{"asset_id":"69697746896130839564035629862476347944307040470122503199396727085502753297492","best_ask":"0.41","best_bid":"0.4","hash":"1df35691eab408d1764edee9bbcef7e8973748d1","price":"0.43","side":"SELL","size":"41.4"}],"timestamp":"1785126666412"},"payload_hash":"2f1debab8b28f58a7bcff4b6fa3cd5345cae437fde621e0d5c03a8bb96776fa4","raw_frame":"{\"market\":\"0xeb66215f2e9faa6449e30a02bab5b8ed7b79a38bf961f6b24d0073c9c2419250\", \"price_changes\":[{\"asset_id\":\"60386828328910021732068595344565885737045900010034836345809386672230885527307\", \"price\":\"0.57\", \"size\":\"41.4\", \"side\":\"BUY\", \"hash\":\"09c389f4a18af45202c591bab628015fbdc3b827\", \"best_bid\":\"0.59\", \"best_ask\":\"0.6\"}, {\"asset_id\":\"69697746896130839564035629862476347944307040470122503199396727085502753297492\", \"price\":\"0.43\", \"size\":\"41.4\", \"side\":\"SELL\", \"hash\":\"1df35691eab408d1764edee9bbcef7e8973748d1\", \"best_bid\":\"0.4\", \"best_ask\":\"0.41\"}], \"timestamp\":\"1785126666412\", \"event_type\":\"price_change\"}","received_at":"2026-07-27T04:31:11.784566Z","schema_version":"clob-market-ws.price_change.v1","sequence":null,"server_hash":null,"server_timestamp":"1785126666412","session_id":"e9443c7415a0419799bee9cfbb1a9e4d","source":"clob_market_ws"},"received_at":"2026-07-27T04:31:11.784566Z","record_id":"b3c8dd2619e4a15a51c1dc56980d54f120dbb6bd2a3dce4abaf1c02cc6208e44","schema_fingerprint":"4aa3821a28b0b7c2400bc59aba4bcc0a76e971dadd19610d3ad38c768e124dc7","schema_version":"edge-lab-recorder.raw.v1","sequence":null,"source":"clob_market_ws"}
{"event_at":"2026-07-27T04:31:06.412000Z","event_fingerprint":"523c83b25b46d64b373adc3e27e5f27089c0a8cce132b44a92a1966e62e562cb","payload":{"connection_id":"0f4979d6978d463e9660b042fdcf555f","event_at":"2026-07-27T04:31:06.412000Z","event_type":"price_change","frame_hash":"98a2380f9f86c49db077de43ab57cbf2a1bd388e1d06990b6349a572f36af579","frame_index":0,"kind":"data","monotonic_ns":228655059242625,"payload":{"event_type":"price_change","market":"0xeb66215f2e9faa6449e30a02bab5b8ed7b79a38bf961f6b24d0073c9c2419250","price_changes":[{"asset_id":"69697746896130839564035629862476347944307040470122503199396727085502753297492","best_ask":"0.41","best_bid":"0.4","hash":"cfde1c986d55d829eb67b42e3645910a0006fb1d","price":"0.4","side":"BUY","size":"22.54"},{"asset_id":"60386828328910021732068595344565885737045900010034836345809386672230885527307","best_ask":"0.6","best_bid":"0.59","hash":"22953099914f2048d1b50a8fedd3f8961a1036e9","price":"0.6","side":"SELL","size":"22.54"}],"timestamp":"1785126666412"},"payload_hash":"078f40f99f5ef3ff6476aaf6fb98cba3377aec8ddcae4450cdb5856a280852fe","raw_frame":"{\"market\":\"0xeb66215f2e9faa6449e30a02bab5b8ed7b79a38bf961f6b24d0073c9c2419250\", \"price_changes\":[{\"asset_id\":\"69697746896130839564035629862476347944307040470122503199396727085502753297492\", \"price\":\"0.4\", \"size\":\"22.54\", \"side\":\"BUY\", \"hash\":\"cfde1c986d55d829eb67b42e3645910a0006fb1d\", \"best_bid\":\"0.4\", \"best_ask\":\"0.41\"}, {\"asset_id\":\"60386828328910021732068595344565885737045900010034836345809386672230885527307\", \"price\":\"0.6\", \"size\":\"22.54\", \"side\":\"SELL\", \"hash\":\"22953099914f2048d1b50a8fedd3f8961a1036e9\", \"best_bid\":\"0.59\", \"best_ask\":\"0.6\"}], \"timestamp\":\"1785126666412\", \"event_type\":\"price_change\"}","received_at":"2026-07-27T04:31:11.790029Z","schema_version":"clob-market-ws.price_change.v1","sequence":null,"server_hash":null,"server_timestamp":"1785126666412","session_id":"e9443c7415a0419799bee9cfbb1a9e4d","source":"clob_market_ws"},"received_at":"2026-07-27T04:31:11.790029Z","record_id":"82553cd41ace6364773a1f98691e397f329e5cbe74d05f48d1a29c2ab66b2961","schema_fingerprint":"4aa3821a28b0b7c2400bc59aba4bcc0a76e971dadd19610d3ad38c768e124dc7","schema_version":"edge-lab-recorder.raw.v1","sequence":null,"source":"clob_market_ws"}
{"event_at":"2026-07-27T04:31:06.413000Z","event_fingerprint":"f085ebc8fdc631da7dfce154b30ab8189a608ddde79a2120ab40436db7334bfa","payload":{"connection_id":"0f4979d6978d463e9660b042fdcf555f","event_at":"2026-07-27T04:31:06.413000Z","event_type":"price_change","frame_hash":"d179f5bc602f243c423646301e9f3fcab564010f47a5d75ed4862b52ac195586","frame_index":0,"kind":"data","monotonic_ns":228655067507333,"payload":{"event_type":"price_change","market":"0xeb66215f2e9faa6449e30a02bab5b8ed7b79a38bf961f6b24d0073c9c2419250","price_changes":[{"asset_id":"69697746896130839564035629862476347944307040470122503199396727085502753297492","best_ask":"0.41","best_bid":"0.4","hash":"063be82bb82278a62f49e9feb6e221abccaa6ad7","price":"0.32","side":"BUY","size":"204.8"},{"asset_id":"60386828328910021732068595344565885737045900010034836345809386672230885527307","best_ask":"0.6","best_bid":"0.59","hash":"5e31817bfa0410e5ed2494b6f8c122519e9e8a55","price":"0.68","side":"SELL","size":"204.8"}],"timestamp":"1785126666413"},"payload_hash":"e37539c0f14e566c59cd93168aaf8b1108cd7e838a4dc3d9d436d3a3479cc8bd","raw_frame":"{\"market\":\"0xeb66215f2e9faa6449e30a02bab5b8ed7b79a38bf961f6b24d0073c9c2419250\", \"price_changes\":[{\"asset_id\":\"69697746896130839564035629862476347944307040470122503199396727085502753297492\", \"price\":\"0.32\", \"size\":\"204.8\", \"side\":\"BUY\", \"hash\":\"063be82bb82278a62f49e9feb6e221abccaa6ad7\", \"best_bid\":\"0.4\", \"best_ask\":\"0.41\"}, {\"asset_id\":\"60386828328910021732068595344565885737045900010034836345809386672230885527307\", \"price\":\"0.68\", \"size\":\"204.8\", \"side\":\"SELL\", \"hash\":\"5e31817bfa0410e5ed2494b6f8c122519e9e8a55\", \"best_bid\":\"0.59\", \"best_ask\":\"0.6\"}], \"timestamp\":\"1785126666413\", \"event_type\":\"price_change\"}","received_at":"2026-07-27T04:31:11.798294Z","schema_version":"clob-market-ws.price_change.v1","sequence":null,"server_hash":null,"server_timestamp":"1785126666413","session_id":"e9443c7415a0419799bee9cfbb1a9e4d","source":"clob_market_ws"},"received_at":"2026-07-27T04:31:11.798294Z","record_id":"175515a6cf40ccac460b9bba5894ed67637a5ab49d29fbb6735637b2689358f7","schema_fingerprint":"4aa3821a28b0b7c2400bc59aba4bcc0a76e971dadd19610d3ad38c768e124dc7","schema_version":"edge-lab-recorder.raw.v1","sequence":null,"source":"clob_market_ws"}
{"event_at":"2026-07-27T04:31:06.417000Z","event_fingerprint":"f32dc19318dc7fa67a55e1136e214aa91fa2b8b7282f371fb25609a4133dfec8","payload":{"connection_id":"0f4979d6978d463e9660b042fdcf555f","event_at":"2026-07-27T04:31:06.417000Z","event_type":"price_change","frame_hash":"e09fcd1a14d8939096813f5a8468a9b9e3e68ed57be511bfd471ad3003bbaa38","frame_index":0,"kind":"data","monotonic_ns":228655074543583,"payload":{"event_type":"price_change","market":"0xeb66215f2e9faa6449e30a02bab5b8ed7b79a38bf961f6b24d0073c9c2419250","price_changes":[{"asset_id":"69697746896130839564035629862476347944307040470122503199396727085502753297492","best_ask":"0.41","best_bid":"0.4","hash":"ba9ccf8a5b05cd32535eae21f81e2640dda37d6c","price":"0.32","side":"BUY","size":"174.8"},{"asset_id":"60386828328910021732068595344565885737045900010034836345809386672230885527307","best_ask":"0.6","best_bid":"0.59","hash":"98d64583880b8d0a0c0a68f76a18407adc62e649","price":"0.68","side":"SELL","size":"174.8"}],"timestamp":"1785126666417"},"payload_hash":"c9cf1782026a0573f3d9b92bc7b5f0945af03dcb3394bfa70de3373d24afa3e5","raw_frame":"{\"market\":\"0xeb66215f2e9faa6449e30a02bab5b8ed7b79a38bf961f6b24d0073c9c2419250\", \"price_changes\":[{\"asset_id\":\"69697746896130839564035629862476347944307040470122503199396727085502753297492\", \"price\":\"0.32\", \"size\":\"174.8\", \"side\":\"BUY\", \"hash\":\"ba9ccf8a5b05cd32535eae21f81e2640dda37d6c\", \"best_bid\":\"0.4\", \"best_ask\":\"0.41\"}, {\"asset_id\":\"60386828328910021732068595344565885737045900010034836345809386672230885527307\", \"price\":\"0.68\", \"size\":\"174.8\", \"side\":\"SELL\", \"hash\":\"98d64583880b8d0a0c0a68f76a18407adc62e649\", \"best_bid\":\"0.59\", \"best_ask\":\"0.6\"}], \"timestamp\":\"1785126666417\", \"event_type\":\"price_change\"}","received_at":"2026-07-27T04:31:11.805327Z","schema_version":"clob-market-ws.price_change.v1","sequence":null,"server_hash":null,"server_timestamp":"1785126666417","session_id":"e9443c7415a0419799bee9cfbb1a9e4d","source":"clob_market_ws"},"received_at":"2026-07-27T04:31:11.805327Z","record_id":"e7811c460301fe34399808af52edaae65b5001dcb4a091f4cd43ffaa0fa3f25a","schema_fingerprint":"4aa3821a28b0b7c2400bc59aba4bcc0a76e971dadd19610d3ad38c768e124dc7","schema_version":"edge-lab-recorder.raw.v1","sequence":null,"source":"clob_market_ws"}
{"event_at":"2026-07-27T04:31:06.417000Z","event_fingerprint":"97057fee316db80c88b10e626eb613ef1134557ad23377e871ef1a47cb64f81e","payload":{"connection_id":"0f4979d6978d463e9660b042fdcf555f","event_at":"2026-07-27T04:31:06.417000Z","event_type":"price_change","frame_hash":"c44c1a0e5636651357b02e78716be222bf93dff383f9f941b771610afa5f4dc2","frame_index":0,"kind":"data","monotonic_ns":228655079872250,"payload":{"event_type":"price_change","market":"0xeb66215f2e9faa6449e30a02bab5b8ed7b79a38bf961f6b24d0073c9c2419250","price_changes":[{"asset_id":"60386828328910021732068595344565885737045900010034836345809386672230885527307","best_ask":"0.6","best_bid":"0.59","hash":"eedc9fe895522652532bb7712d4be40b38d21e39","price":"0.59","side":"BUY","size":"37.6"},{"asset_id":"69697746896130839564035629862476347944307040470122503199396727085502753297492","best_ask":"0.41","best_bid":"0.4","hash":"67d3380dfd946d15f7b86d004881a80615a97d2f","price":"0.41","side":"SELL","size":"37.6"}],"timestamp":"1785126666417"},"payload_hash":"8e585242d2d2dc6b6e879f1c71cc1460529af812e4da383f745bd3653576b9c5","raw_frame":"{\"market\":\"0xeb66215f2e9faa6449e30a02bab5b8ed7b79a38bf961f6b24d0073c9c2419250\", \"price_changes\":[{\"asset_id\":\"60386828328910021732068595344565885737045900010034836345809386672230885527307\", \"price\":\"0.59\", \"size\":\"37.6\", \"side\":\"BUY\", \"hash\":\"eedc9fe895522652532bb7712d4be40b38d21e39\", \"best_bid\":\"0.59\", \"best_ask\":\"0.6\"}, {\"asset_id\":\"69697746896130839564035629862476347944307040470122503199396727085502753297492\", \"price\":\"0.41\", \"size\":\"37.6\", \"side\":\"SELL\", \"hash\":\"67d3380dfd946d15f7b86d004881a80615a97d2f\", \"best_bid\":\"0.4\", \"best_ask\":\"0.41\"}], \"timestamp\":\"1785126666417\", \"event_type\":\"price_change\"}","received_at":"2026-07-27T04:31:11.810659Z","schema_version":"clob-market-ws.price_change.v1","sequence":null,"server_hash":null,"server_timestamp":"1785126666417","session_id":"e9443c7415a0419799bee9cfbb1a9e4d","source":"clob_market_ws"},"received_at":"2026-07-27T04:31:11.810659Z","record_id":"02b842876854a949fb22da663d78ab97060e6be44c658c7a0ddf6f4873234d05","schema_fingerprint":"4aa3821a28b0b7c2400bc59aba4bcc0a76e971dadd19610d3ad38c768e124dc7","schema_version":"edge-lab-recorder.raw.v1","sequence":null,"source":"clob_market_ws"}
{"event_at":"2026-07-27T04:31:06.419000Z","event_fingerprint":"ea632504777b3b726e51e1da0b74ebe77f00c573ce7ee43343e100599132f941","payload":{"connection_id":"0f4979d6978d463e9660b042fdcf555f","event_at":"2026-07-27T04:31:06.419000Z","event_type":"price_change","frame_hash":"7bb96e592db430f78a04178d2d6e9a9ae7a32c511ac5c11c0aa830303354cdde","frame_index":0,"kind":"data","monotonic_ns":228655087382208,"payload":{"event_type":"price_change","market":"0xeb66215f2e9faa6449e30a02bab5b8ed7b79a38bf961f6b24d0073c9c2419250","price_changes":[{"asset_id":"60386828328910021732068595344565885737045900010034836345809386672230885527307","best_ask":"0.6","best_bid":"0.59","hash":"a4972b77f68e22750ed7bf63f7827f10b0404ee3","price":"0.59","side":"BUY","size":"54.4"},{"asset_id":"69697746896130839564035629862476347944307040470122503199396727085502753297492","best_ask":"0.41","best_bid":"0.4","hash":"ed19210a06e113cfe49038e9c2929a5d9988d2af","price":"0.41","side":"SELL","size":"54.4"}],"timestamp":"1785126666419"},"payload_hash":"764456c013441bd87b0727efb2304bcf62547f97078c58abc24a45b43e775ff3","raw_frame":"{\"market\":\"0xeb66215f2e9faa6449e30a02bab5b8ed7b79a38bf961f6b24d0073c9c2419250\", \"price_changes\":[{\"asset_id\":\"60386828328910021732068595344565885737045900010034836345809386672230885527307\", \"price\":\"0.59\", \"size\":\"54.4\", \"side\":\"BUY\", \"hash\":\"a4972b77f68e22750ed7bf63f7827f10b0404ee3\", \"best_bid\":\"0.59\", \"best_ask\":\"0.6\"}, {\"asset_id\":\"69697746896130839564035629862476347944307040470122503199396727085502753297492\", \"price\":\"0.41\", \"size\":\"54.4\", \"side\":\"SELL\", \"hash\":\"ed19210a06e113cfe49038e9c2929a5d9988d2af\", \"best_bid\":\"0.4\", \"best_ask\":\"0.41\"}], \"timestamp\":\"1785126666419\", \"event_type\":\"price_change\"}","received_at":"2026-07-27T04:31:11.818168Z","schema_version":"clob-market-ws.price_change.v1","sequence":null,"server_hash":null,"server_timestamp":"1785126666419","session_id":"e9443c7415a0419799bee9cfbb1a9e4d","source":"clob_market_ws"},"received_at":"2026-07-27T04:31:11.818168Z","record_id":"398230678c50b664245f667e180335dabf3978d00ba54ea4b9c5eac1a7e89b82","schema_fingerprint":"4aa3821a28b0b7c2400bc59aba4bcc0a76e971dadd19610d3ad38c768e124dc7","schema_version":"edge-lab-recorder.raw.v1","sequence":null,"source":"clob_market_ws"}
{"event_at":"2026-07-27T04:31:06.422000Z","event_fingerprint":"d8d480867437783e0e784bafe8f7d11552aee94d94fdf7af58c9ff47de972584","payload":{"connection_id":"0f4979d6978d463e9660b042fdcf555f","event_at":"2026-07-27T04:31:06.422000Z","event_type":"price_change","frame_hash":"b25be967ca4eb53549a35a62da8943682293784103f0d9fe12f776bfdc5ea292","frame_index":0,"kind":"data","monotonic_ns":228655092572916,"payload":{"event_type":"price_change","market":"0xeb66215f2e9faa6449e30a02bab5b8ed7b79a38bf961f6b24d0073c9c2419250","price_changes":[{"asset_id":"60386828328910021732068595344565885737045900010034836345809386672230885527307","best_ask":"0.6","best_bid":"0.59","hash":"4fbfcdd9bd01492ea137c18515ca057c00c50f5b","price":"0.57","side":"BUY","size":"31.4"},{"asset_id":"69697746896130839564035629862476347944307040470122503199396727085502753297492","best_ask":"0.41","best_bid":"0.4","hash":"c16c72e0a7161705596bb7048003fcf546f89c9e","price":"0.43","side":"SELL","size":"31.4"}],"timestamp":"1785126666422"},"payload_hash":"46935f0bb7f0b32b7b0153e5bf2c7db4f6efe6393611b9baac75fa20829436eb","raw_frame":"{\"market\":\"0xeb66215f2e9faa6449e30a02bab5b8ed7b79a38bf961f6b24d0073c9c2419250\", \"price_changes\":[{\"asset_id\":\"60386828328910021732068595344565885737045900010034836345809386672230885527307\", \"price\":\"0.57\", \"size\":\"31.4\", \"side\":\"BUY\", \"hash\":\"4fbfcdd9bd01492ea137c18515ca057c00c50f5b\", \"best_bid\":\"0.59\", \"best_ask\":\"0.6\"}, {\"asset_id\":\"69697746896130839564035629862476347944307040470122503199396727085502753297492\", \"price\":\"0.43\", \"size\":\"31.4\", \"side\":\"SELL\", \"hash\":\"c16c72e0a7161705596bb7048003fcf546f89c9e\", \"best_bid\":\"0.4\", \"best_ask\":\"0.41\"}], \"timestamp\":\"1785126666422\", \"event_type\":\"price_change\"}","received_at":"2026-07-27T04:31:11.823358Z","schema_version":"clob-market-ws.price_change.v1","sequence":null,"server_hash":null,"server_timestamp":"1785126666422","session_id":"e9443c7415a0419799bee9cfbb1a9e4d","source":"clob_market_ws"},"received_at":"2026-07-27T04:31:11.823358Z","record_id":"b26d3950ec86e974f1f548bc4a22677ede092513e53e8c814982112b925f6529","schema_fingerprint":"4aa3821a28b0b7c2400bc59aba4bcc0a76e971dadd19610d3ad38c768e124dc7","schema_version":"edge-lab-recorder.raw.v1","sequence":null,"source":"clob_market_ws"}
{"event_at":"2026-07-27T04:31:06.422000Z","event_fingerprint":"dab0956503dc2c8a90d67e5e4d500945c43483d221ec8886f0a8ddc43ce41a6d","payload":{"connection_id":"0f4979d6978d463e9660b042fdcf555f","event_at":"2026-07-27T04:31:06.422000Z","event_type":"price_change","frame_hash":"966a83c64f22320ce23001f222cef69fd133a4d3899445887fe7efb12146ae9a","frame_index":0,"kind":"data","monotonic_ns":228655097552000,"payload":{"event_type":"price_change","market":"0xeb66215f2e9faa6449e30a02bab5b8ed7b79a38bf961f6b24d0073c9c2419250","price_changes":[{"asset_id":"60386828328910021732068595344565885737045900010034836345809386672230885527307","best_ask":"0.6","best_bid":"0.59","hash":"231b9b4b8ef69e2441b8390c8300a298633c7dfd","price":"0.59","side":"BUY","size":"59.4"},{"asset_id":"69697746896130839564035629862476347944307040470122503199396727085502753297492","best_ask":"0.41","best_bid":"0.4","hash":"532138b0419b45a018cc56a99975ca9b08bcc676","price":"0.41","side":"SELL","size":"59.4"}],"timestamp":"1785126666422"},"payload_hash":"eff77096ea48cc2d5ea625e4e2ed5ec6dfa40ac21a6eee0244cc87c1772577b9","raw_frame":"{\"market\":\"0xeb66215f2e9faa6449e30a02bab5b8ed7b79a38bf961f6b24d0073c9c2419250\", \"price_changes\":[{\"asset_id\":\"60386828328910021732068595344565885737045900010034836345809386672230885527307\", \"price\":\"0.59\", \"size\":\"59.4\", \"side\":\"BUY\", \"hash\":\"231b9b4b8ef69e2441b8390c8300a298633c7dfd\", \"best_bid\":\"0.59\", \"best_ask\":\"0.6\"}, {\"asset_id\":\"69697746896130839564035629862476347944307040470122503199396727085502753297492\", \"price\":\"0.41\", \"size\":\"59.4\", \"side\":\"SELL\", \"hash\":\"532138b0419b45a018cc56a99975ca9b08bcc676\", \"best_bid\":\"0.4\", \"best_ask\":\"0.41\"}], \"timestamp\":\"1785126666422\", \"event_type\":\"price_change\"}","received_at":"2026-07-27T04:31:11.828338Z","schema_version":"clob-market-ws.price_change.v1","sequence":null,"server_hash":null,"server_timestamp":"1785126666422","session_id":"e9443c7415a0419799bee9cfbb1a9e4d","source":"clob_market_ws"},"received_at":"2026-07-27T04:31:11.828338Z","record_id":"283ae5edecd5435926f720c5639cc0c3d078f99f9d7532016ba57b6763766ce7","schema_fingerprint":"4aa3821a28b0b7c2400bc59aba4bcc0a76e971dadd19610d3ad38c768e124dc7","schema_version":"edge-lab-recorder.raw.v1","sequence":null,"source":"clob_market_ws"}
{"event_at":"2026-07-27T04:31:06.425000Z","event_fingerprint":"207b2298802b47cae3323efe252636c92a45c857557f6342c5a85785cdcd5dc2","payload":{"connection_id":"0f4979d6978d463e9660b042fdcf555f","event_at":"2026-07-27T04:31:06.425000Z","event_type":"price_change","frame_hash":"614eccd98c42828f6824758c9a444a22b4813368c65c66014794e279c7ddf0f9","frame_index":0,"kind":"data","monotonic_ns":228655106368500,"payload":{"event_type":"price_change","market":"0xeb66215f2e9faa6449e30a02bab5b8ed7b79a38bf961f6b24d0073c9c2419250","price_changes":[{"asset_id":"69697746896130839564035629862476347944307040470122503199396727085502753297492","best_ask":"0.41","best_bid":"0.4","hash":"d663aeef87fce004294daf6b62e6de023db51135","price":"0.38","side":"BUY","size":"82.32"},{"asset_id":"60386828328910021732068595344565885737045900010034836345809386672230885527307","best_ask":"0.6","best_bid":"0.59","hash":"8f4d3a2e4d670ccf55b9134fb87b244838ba1b56","price":"0.62","side":"SELL","size":"82.32"}],"timestamp":"1785126666425"},"payload_hash":"0ef5a755fc98cf88ad1b288dec0a80611a6158d619e24f0dcf772017392cc2a5","raw_frame":"{\"market\":\"0xeb66215f2e9faa6449e30a02bab5b8ed7b79a38bf961f6b24d0073c9c2419250\", \"price_changes\":[{\"asset_id\":\"69697746896130839564035629862476347944307040470122503199396727085502753297492\", \"price\":\"0.38\", \"size\":\"82.32\", \"side\":\"BUY\", \"hash\":\"d663aeef87fce004294daf6b62e6de023db51135\", \"best_bid\":\"0.4\", \"best_ask\":\"0.41\"}, {\"asset_id\":\"60386828328910021732068595344565885737045900010034836345809386672230885527307\", \"price\":\"0.62\", \"size\":\"82.32\", \"side\":\"SELL\", \"hash\":\"8f4d3a2e4d670ccf55b9134fb87b244838ba1b56\", \"best_bid\":\"0.59\", \"best_ask\":\"0.6\"}], \"timestamp\":\"1785126666425\", \"event_type\":\"price_change\"}","received_at":"2026-07-27T04:31:11.837152Z","schema_version":"clob-market-ws.price_change.v1","sequence":null,"server_hash":null,"server_timestamp":"1785126666425","session_id":"e9443c7415a0419799bee9cfbb1a9e4d","source":"clob_market_ws"},"received_at":"2026-07-27T04:31:11.837152Z","record_id":"800c7984437fd30a44d0803b24200163ac2832682ce7a6fbec66796b4625a72c","schema_fingerprint":"4aa3821a28b0b7c2400bc59aba4bcc0a76e971dadd19610d3ad38c768e124dc7","schema_version":"edge-lab-recorder.raw.v1","sequence":null,"source":"clob_market_ws"}
{"event_at":"2026-07-27T04:31:06.426000Z","event_fingerprint":"c12c7751377244c6197430c388804db00a6416aa917790e571caa30d8cbe3885","payload":{"connection_id":"0f4979d6978d463e9660b042fdcf555f","event_at":"2026-07-27T04:31:06.426000Z","event_type":"price_change","frame_hash":"508a86533d9843a5d05b428d53bf1de980007bbb642b59da3537de49b3e0bed9","frame_index":0,"kind":"data","monotonic_ns":228655117061333,"payload":{"event_type":"price_change","market":"0xeb66215f2e9faa6449e30a02bab5b8ed7b79a38bf961f6b24d0073c9c2419250","price_changes":[{"asset_id":"69697746896130839564035629862476347944307040470122503199396727085502753297492","best_ask":"0.41","best_bid":"0.4","hash":"50647b4cf6ed582243bbe4d9620f257e9843b8d0","price":"0.32","side":"BUY","size":"144.8"},{"asset_id":"60386828328910021732068595344565885737045900010034836345809386672230885527307","best_ask":"0.6","best_bid":"0.59","hash":"6898c152adbb851b81f0c720f2bfc4e9526ed704","price":"0.68","side":"SELL","size":"144.8"}],"timestamp":"1785126666426"},"payload_hash":"2ff2c65ca1f898364f28eb737a422532a0c883f38149bbc11807d99cdb2b9b62","raw_frame":"{\"market\":\"0xeb66215f2e9faa6449e30a02bab5b8ed7b79a38bf961f6b24d0073c9c2419250\", \"price_changes\":[{\"asset_id\":\"69697746896130839564035629862476347944307040470122503199396727085502753297492\", \"price\":\"0.32\", \"size\":\"144.8\", \"side\":\"BUY\", \"hash\":\"50647b4cf6ed582243bbe4d9620f257e9843b8d0\", \"best_bid\":\"0.4\", \"best_ask\":\"0.41\"}, {\"asset_id\":\"60386828328910021732068595344565885737045900010034836345809386672230885527307\", \"price\":\"0.68\", \"size\":\"144.8\", \"side\":\"SELL\", \"hash\":\"6898c152adbb851b81f0c720f2bfc4e9526ed704\", \"best_bid\":\"0.59\", \"best_ask\":\"0.6\"}], \"timestamp\":\"1785126666426\", \"event_type\":\"price_change\"}","received_at":"2026-07-27T04:31:11.847848Z","schema_version":"clob-market-ws.price_change.v1","sequence":null,"server_hash":null,"server_timestamp":"1785126666426","session_id":"e9443c7415a0419799bee9cfbb1a9e4d","source":"clob_market_ws"},"received_at":"2026-07-27T04:31:11.847848Z","record_id":"7ddf3a0d52edc2428977460b0dea84432eeca87c010f5ae2eaa11e62004e964a","schema_fingerprint":"4aa3821a28b0b7c2400bc59aba4bcc0a76e971dadd19610d3ad38c768e124dc7","schema_version":"edge-lab-recorder.raw.v1","sequence":null,"source":"clob_market_ws"}
{"event_at":"2026-07-27T04:31:06.428000Z","event_fingerprint":"bbe1b96d62d40065b77a5f826d18b17a07207043f734f070110af78632c061ac","payload":{"connection_id":"0f4979d6978d463e9660b042fdcf555f","event_at":"2026-07-27T04:31:06.428000Z","event_type":"price_change","frame_hash":"1fe6614a11bbbd5c72e453055041ceee5d62ab179c6a79f2e1cb4124b0b42bfd","frame_index":0,"kind":"data","monotonic_ns":228655124452916,"payload":{"event_type":"price_change","market":"0xeb66215f2e9faa6449e30a02bab5b8ed7b79a38bf961f6b24d0073c9c2419250","price_changes":[{"asset_id":"60386828328910021732068595344565885737045900010034836345809386672230885527307","best_ask":"0.6","best_bid":"0.59","hash":"26cbc290a3e94b9379f2417f3f744b2f485d172f","price":"0.57","side":"BUY","size":"26.4"},{"asset_id":"69697746896130839564035629862476347944307040470122503199396727085502753297492","best_ask":"0.41","best_bid":"0.4","hash":"f364510d5b56d4c664a966ff9e0c1b59694ca659","price":"0.43","side":"SELL","size":"26.4"}],"timestamp":"1785126666428"},"payload_hash":"edc708e1a2ba46d4ce95cf0de2425d868bc23828455a95773d459dcb07a02666","raw_frame":"{\"market\":\"0xeb66215f2e9faa6449e30a02bab5b8ed7b79a38bf961f6b24d0073c9c2419250\", \"price_changes\":[{\"asset_id\":\"60386828328910021732068595344565885737045900010034836345809386672230885527307\", \"price\":\"0.57\", \"size\":\"26.4\", \"side\":\"BUY\", \"hash\":\"26cbc290a3e94b9379f2417f3f744b2f485d172f\", \"best_bid\":\"0.59\", \"best_ask\":\"0.6\"}, {\"asset_id\":\"69697746896130839564035629862476347944307040470122503199396727085502753297492\", \"price\":\"0.43\", \"size\":\"26.4\", \"side\":\"SELL\", \"hash\":\"f364510d5b56d4c664a966ff9e0c1b59694ca659\", \"best_bid\":\"0.4\", \"best_ask\":\"0.41\"}], \"timestamp\":\"1785126666428\", \"event_type\":\"price_change\"}","received_at":"2026-07-27T04:31:11.855239Z","schema_version":"clob-market-ws.price_change.v1","sequence":null,"server_hash":null,"server_timestamp":"1785126666428","session_id":"e9443c7415a0419799bee9cfbb1a9e4d","source":"clob_market_ws"},"received_at":"2026-07-27T04:31:11.855239Z","record_id":"4416bbd6e97209d90ea8a6315b4ec3d17886dcc5f6a14342f10b858860125c0f","schema_fingerprint":"4aa3821a28b0b7c2400bc59aba4bcc0a76e971dadd19610d3ad38c768e124dc7","schema_version":"edge-lab-recorder.raw.v1","sequence":null,"source":"clob_market_ws"}
{"event_at":"2026-07-27T04:31:06.428000Z","event_fingerprint":"3cad0613d382ea95334850fcfeeded0484e9287857c758df03a36a44f599c175","payload":{"connection_id":"0f4979d6978d463e9660b042fdcf555f","event_at":"2026-07-27T04:31:06.428000Z","event_type":"price_change","frame_hash":"9c9693f335570c8997b1e14d0ed92f022c4bdd8cdde4f33b58907a1c5a3d82a4","frame_index":0,"kind":"data","monotonic_ns":228655131364250,"payload":{"event_type":"price_change","market":"0xeb66215f2e9faa6449e30a02bab5b8ed7b79a38bf961f6b24d0073c9c2419250","price_changes":[{"asset_id":"69697746896130839564035629862476347944307040470122503199396727085502753297492","best_ask":"0.41","best_bid":"0.4","hash":"bfb59f8160b2772ff59eb6c776968758123ef1c7","price":"0.4","side":"BUY","size":"10.07"},{"asset_id":"60386828328910021732068595344565885737045900010034836345809386672230885527307","best_ask":"0.6","best_bid":"0.59","hash":"7620c0637a97f71089d64ed0bff79485961ee9ce","price":"0.6","side":"SELL","size":"10.07"}],"timestamp":"1785126666428"},"payload_hash":"9b00d71088b47ccaad795e8103c3b1f83d11a08c5b98c6cdd5eec19c9b7bb7cf","raw_frame":"{\"market\":\"0xeb66215f2e9faa6449e30a02bab5b8ed7b79a38bf961f6b24d0073c9c2419250\", \"price_changes\":[{\"asset_id\":\"69697746896130839564035629862476347944307040470122503199396727085502753297492\", \"price\":\"0.4\", \"size\":\"10.07\", \"side\":\"BUY\", \"hash\":\"bfb59f8160b2772ff59eb6c776968758123ef1c7\", \"best_bid\":\"0.4\", \"best_ask\":\"0.41\"}, {\"asset_id\":\"60386828328910021732068595344565885737045900010034836345809386672230885527307\", \"price\":\"0.6\", \"size\":\"10.07\", \"side\":\"SELL\", \"hash\":\"7620c0637a97f71089d64ed0bff79485961ee9ce\", \"best_bid\":\"0.59\", \"best_ask\":\"0.6\"}], \"timestamp\":\"1785126666428\", \"event_type\":\"price_change\"}","received_at":"2026-07-27T04:31:11.862150Z","schema_version":"clob-market-ws.price_change.v1","sequence":null,"server_hash":null,"server_timestamp":"1785126666428","session_id":"e9443c7415a0419799bee9cfbb1a9e4d","source":"clob_market_ws"},"received_at":"2026-07-27T04:31:11.862150Z","record_id":"c7594a8447328ddd44d4817cfcb373de371efdecdafe6751467c5588e75687d8","schema_fingerprint":"4aa3821a28b0b7c2400bc59aba4bcc0a76e971dadd19610d3ad38c768e124dc7","schema_version":"edge-lab-recorder.raw.v1","sequence":null,"source":"clob_market_ws"}
{"event_at":"2026-07-27T04:31:06.431000Z","event_fingerprint":"5a50119cf91445f967c6667af75b0e76a40609140f79feb4563e56e2c2e8379b","payload":{"connection_id":"0f4979d6978d463e9660b042fdcf555f","event_at":"2026-07-27T04:31:06.431000Z","event_type":"price_change","frame_hash":"529016b35ff6950e0b54350ab1ca6cbfe068aeb006bd1d8a2769e9b760e4aeb4","frame_index":0,"kind":"data","monotonic_ns":228655137873750,"payload":{"event_type":"price_change","market":"0xeb66215f2e9faa6449e30a02bab5b8ed7b79a38bf961f6b24d0073c9c2419250","price_changes":[{"asset_id":"69697746896130839564035629862476347944307040470122503199396727085502753297492","best_ask":"0.41","best_bid":"0.4","hash":"e63442dba6d6f7726215610003e071e9df6ef071","price":"0.41","side":"SELL","size":"54.4"},{"asset_id":"60386828328910021732068595344565885737045900010034836345809386672230885527307","best_ask":"0.6","best_bid":"0.59","hash":"f4895b5e1a3c834fbc4b97a4ffd2214bda698685","price":"0.59","side":"BUY","size":"54.4"}],"timestamp":"1785126666431"},"payload_hash":"f32da7a808daa3a23c5e885157765e3817a9bce643ce25ff053e724d11df6789","raw_frame":"{\"market\":\"0xeb66215f2e9faa6449e30a02bab5b8ed7b79a38bf961f6b24d0073c9c2419250\", \"price_changes\":[{\"asset_id\":\"69697746896130839564035629862476347944307040470122503199396727085502753297492\", \"price\":\"0.41\", \"size\":\"54.4\", \"side\":\"SELL\", \"hash\":\"e63442dba6d6f7726215610003e071e9df6ef071\", \"best_bid\":\"0.4\", \"best_ask\":\"0.41\"}, {\"asset_id\":\"60386828328910021732068595344565885737045900010034836345809386672230885527307\", \"price\":\"0.59\", \"size\":\"54.4\", \"side\":\"BUY\", \"hash\":\"f4895b5e1a3c834fbc4b97a4ffd2214bda698685\", \"best_bid\":\"0.59\", \"best_ask\":\"0.6\"}], \"timestamp\":\"1785126666431\", \"event_type\":\"price_change\"}","received_at":"2026-07-27T04:31:11.868658Z","schema_version":"clob-market-ws.price_change.v1","sequence":null,"server_hash":null,"server_timestamp":"1785126666431","session_id":"e9443c7415a0419799bee9cfbb1a9e4d","source":"clob_market_ws"},"received_at":"2026-07-27T04:31:11.868658Z","record_id":"8c3f0c4576a3291dcf9ebb9ff8269ae05982cf1473d3547f30adce5f585f2134","schema_fingerprint":"4aa3821a28b0b7c2400bc59aba4bcc0a76e971dadd19610d3ad38c768e124dc7","schema_version":"edge-lab-recorder.raw.v1","sequence":null,"source":"clob_market_ws"}
{"event_at":"2026-07-27T04:31:06.431000Z","event_fingerprint":"3d3ed0d9e20d3ed939c798171b4148c3572a22a4a86fdbbfd626fc88f31531bf","payload":{"connection_id":"0f4979d6978d463e9660b042fdcf555f","event_at":"2026-07-27T04:31:06.431000Z","event_type":"price_change","frame_hash":"1e036e7cab4e5664163980ce8352d1c8f716d9b0536b079aabca80d6214da32a","frame_index":0,"kind":"data","monotonic_ns":228655142408208,"payload":{"event_type":"price_change","market":"0xeb66215f2e9faa6449e30a02bab5b8ed7b79a38bf961f6b24d0073c9c2419250","price_changes":[{"asset_id":"60386828328910021732068595344565885737045900010034836345809386672230885527307","best_ask":"0.6","best_bid":"0.59","hash":"d84f0519bf785176b11c6a12d01bcd690b88dc29","price":"0.58","side":"BUY","size":"140.6"},{"asset_id":"69697746896130839564035629862476347944307040470122503199396727085502753297492","best_ask":"0.41","best_bid":"0.4","hash":"a729407fed07b22c38d94756478a6e58bf470148","price":"0.42","side":"SELL","size":"140.6"}],"timestamp":"1785126666431"},"payload_hash":"ab623aaca258533db9e9fdd3d499f5bcebe61e52156cf8d4a1f56769013b9032","raw_frame":"{\"market\":\"0xeb66215f2e9faa6449e30a02bab5b8ed7b79a38bf961f6b24d0073c9c2419250\", \"price_changes\":[{\"asset_id\":\"60386828328910021732068595344565885737045900010034836345809386672230885527307\", \"price\":\"0.58\", \"size\":\"140.6\", \"side\":\"BUY\", \"hash\":\"d84f0519bf785176b11c6a12d01bcd690b88dc29\", \"best_bid\":\"0.59\", \"best_ask\":\"0.6\"}, {\"asset_id\":\"69697746896130839564035629862476347944307040470122503199396727085502753297492\", \"price\":\"0.42\", \"size\":\"140.6\", \"side\":\"SELL\", \"hash\":\"a729407fed07b22c38d94756478a6e58bf470148\", \"best_bid\":\"0.4\", \"best_ask\":\"0.41\"}], \"timestamp\":\"1785126666431\", \"event_type\":\"price_change\"}","received_at":"2026-07-27T04:31:11.873195Z","schema_version":"clob-market-ws.price_change.v1","sequence":null,"server_hash":null,"server_timestamp":"1785126666431","session_id":"e9443c7415a0419799bee9cfbb1a9e4d","source":"clob_market_ws"},"received_at":"2026-07-27T04:31:11.873195Z","record_id":"9dab3ab5fad8966d481c7d8d732edc946452f56273e108138d00a66c89dea4a8","schema_fingerprint":"4aa3821a28b0b7c2400bc59aba4bcc0a76e971dadd19610d3ad38c768e124dc7","schema_version":"edge-lab-recorder.raw.v1","sequence":null,"source":"clob_market_ws"}
{"event_at":"2026-07-27T04:31:06.432000Z","event_fingerprint":"a5eace284a7825d45c04dbb485a5add1405de5f455c6f270f7083e30d15ad56a","payload":{"connection_id":"0f4979d6978d463e9660b042fdcf555f","event_at":"2026-07-27T04:31:06.432000Z","event_type":"price_change","frame_hash":"3ecd84444d14c77bc282795d99aee5bdc1920dcbc5a5aea8ad52530e996da62f","frame_index":0,"kind":"data","monotonic_ns":228655146617333,"payload":{"event_type":"price_change","market":"0xeb66215f2e9faa6449e30a02bab5b8ed7b79a38bf961f6b24d0073c9c2419250","price_changes":[{"asset_id":"60386828328910021732068595344565885737045900010034836345809386672230885527307","best_ask":"0.6","best_bid":"0.59","hash":"c6cdddf1cd933d3c51bced62cc5b1714bc55b5a8","price":"0.63","side":"SELL","size":"62.04"},{"asset_id":"69697746896130839564035629862476347944307040470122503199396727085502753297492","best_ask":"0.41","best_bid":"0.4","hash":"d6b0381fc7555363546fbfcb53cc14cc3e97ce1d","price":"0.37","side":"BUY","size":"62.04"}],"timestamp":"1785126666432"},"payload_hash":"d51703bf9dc558986bfea4b02a6fe2e2280bae2e3154d5f7797982cade64e210","raw_frame":"{\"market\":\"0xeb66215f2e9faa6449e30a02bab5b8ed7b79a38bf961f6b24d0073c9c2419250\", \"price_changes\":[{\"asset_id\":\"60386828328910021732068595344565885737045900010034836345809386672230885527307\", \"price\":\"0.63\", \"size\":\"62.04\", \"side\":\"SELL\", \"hash\":\"c6cdddf1cd933d3c51bced62cc5b1714bc55b5a8\", \"best_bid\":\"0.59\", \"best_ask\":\"0.6\"}, {\"asset_id\":\"69697746896130839564035629862476347944307040470122503199396727085502753297492\", \"price\":\"0.37\", \"size\":\"62.04\", \"side\":\"BUY\", \"hash\":\"d6b0381fc7555363546fbfcb53cc14cc3e97ce1d\", \"best_bid\":\"0.4\", \"best_ask\":\"0.41\"}], \"timestamp\":\"1785126666432\", \"event_type\":\"price_change\"}","received_at":"2026-07-27T04:31:11.877404Z","schema_version":"clob-market-ws.price_change.v1","sequence":null,"server_hash":null,"server_timestamp":"1785126666432","session_id":"e9443c7415a0419799bee9cfbb1a9e4d","source":"clob_market_ws"},"received_at":"2026-07-27T04:31:11.877404Z","record_id":"2638fec7b323b8bb0d816f16b8f53b0a9d9d3c74ffd8e21787b72826b1c8f729","schema_fingerprint":"4aa3821a28b0b7c2400bc59aba4bcc0a76e971dadd19610d3ad38c768e124dc7","schema_version":"edge-lab-recorder.raw.v1","sequence":null,"source":"clob_market_ws"}
{"event_at":"2026-07-27T04:31:06.432000Z","event_fingerprint":"01eab9aa8d8ebd63e333916253e201bc2859ef5d5c144373db65730b31da30ce","payload":{"connection_id":"0f4979d6978d463e9660b042fdcf555f","event_at":"2026-07-27T04:31:06.432000Z","event_type":"price_change","frame_hash":"02869b7db3c0ef3c8cf542810930f03ed5783802ba917a1c4bf2766a80b4fc1a","frame_index":0,"kind":"data","monotonic_ns":228655155223333,"payload":{"event_type":"price_change","market":"0xeb66215f2e9faa6449e30a02bab5b8ed7b79a38bf961f6b24d0073c9c2419250","price_changes":[{"asset_id":"69697746896130839564035629862476347944307040470122503199396727085502753297492","best_ask":"0.41","best_bid":"0.4","hash":"051da407a03841783b867868b84318373e510024","price":"0.39","side":"BUY","size":"40.4"},{"asset_id":"60386828328910021732068595344565885737045900010034836345809386672230885527307","best_ask":"0.6","best_bid":"0.59","hash":"8c6ea68d7969e1ff00c76de5d44c85263184e664","price":"0.61","side":"SELL","size":"40.4"}],"timestamp":"1785126666432"},"payload_hash":"576257b4ada780b1bd5b7663d344a08026d17c5179b8bd64351d9865a4b0adcb","raw_frame":"{\"market\":\"0xeb66215f2e9faa6449e30a02bab5b8ed7b79a38bf961f6b24d0073c9c2419250\", \"price_changes\":[{\"asset_id\":\"69697746896130839564035629862476347944307040470122503199396727085502753297492\", \"price\":\"0.39\", \"size\":\"40.4\", \"side\":\"BUY\", \"hash\":\"051da407a03841783b867868b84318373e510024\", \"best_bid\":\"0.4\", \"best_ask\":\"0.41\"}, {\"asset_id\":\"60386828328910021732068595344565885737045900010034836345809386672230885527307\", \"price\":\"0.61\", \"size\":\"40.4\", \"side\":\"SELL\", \"hash\":\"8c6ea68d7969e1ff00c76de5d44c85263184e664\", \"best_bid\":\"0.59\", \"best_ask\":\"0.6\"}], \"timestamp\":\"1785126666432\", \"event_type\":\"price_change\"}","received_at":"2026-07-27T04:31:11.886008Z","schema_version":"clob-market-ws.price_change.v1","sequence":null,"server_hash":null,"server_timestamp":"1785126666432","session_id":"e9443c7415a0419799bee9cfbb1a9e4d","source":"clob_market_ws"},"received_at":"2026-07-27T04:31:11.886008Z","record_id":"b0e629eed32f9aef537b5c3a6958ab6fa29684f416c8a52cd62230882e4bca0e","schema_fingerprint":"4aa3821a28b0b7c2400bc59aba4bcc0a76e971dadd19610d3ad38c768e124dc7","schema_version":"edge-lab-recorder.raw.v1","sequence":null,"source":"clob_market_ws"}
{"event_at":"2026-07-27T04:31:06.433000Z","event_fingerprint":"e5c406bd74238d44f3416753efc060b22c7668ac09f6ca9c267c0e4864107590","payload":{"connection_id":"0f4979d6978d463e9660b042fdcf555f","event_at":"2026-07-27T04:31:06.433000Z","event_type":"price_change","frame_hash":"d730ffd4656d08e8c14dc4b84ee7cf920b41e6f89c03e402cf98a31be9bcc41c","frame_index":0,"kind":"data","monotonic_ns":228655161388166,"payload":{"event_type":"price_change","market":"0xeb66215f2e9faa6449e30a02bab5b8ed7b79a38bf961f6b24d0073c9c2419250","price_changes":[{"asset_id":"69697746896130839564035629862476347944307040470122503199396727085502753297492","best_ask":"0.41","best_bid":"0.4","hash":"8152fc9bb74eedcffde8e22313a90c03fc8e75be","price":"0.39","side":"BUY","size":"30.8"},{"asset_id":"60386828328910021732068595344565885737045900010034836345809386672230885527307","best_ask":"0.6","best_bid":"0.59","hash":"1995d76885ad1bf0a6870d39f13737ba4b235b19","price":"0.61","side":"SELL","size":"30.8"}],"timestamp":"1785126666433"},"payload_hash":"cc9e8bbd0f5f92a10644db90936dd54ffb86de7b4806cb9173c479e46e3936d0","raw_frame":"{\"market\":\"0xeb66215f2e9faa6449e30a02bab5b8ed7b79a38bf961f6b24d0073c9c2419250\", \"price_changes\":[{\"asset_id\":\"69697746896130839564035629862476347944307040470122503199396727085502753297492\", \"price\":\"0.39\", \"size\":\"30.8\", \"side\":\"BUY\", \"hash\":\"8152fc9bb74eedcffde8e22313a90c03fc8e75be\", \"best_bid\":\"0.4\", \"best_ask\":\"0.41\"}, {\"asset_id\":\"60386828328910021732068595344565885737045900010034836345809386672230885527307\", \"price\":\"0.61\", \"size\":\"30.8\", \"side\":\"SELL\", \"hash\":\"1995d76885ad1bf0a6870d39f13737ba4b235b19\", \"best_bid\":\"0.59\", \"best_ask\":\"0.6\"}], \"timestamp\":\"1785126666433\", \"event_type\":\"price_change\"}","received_at":"2026-07-27T04:31:11.892176Z","schema_version":"clob-market-ws.price_change.v1","sequence":null,"server_hash":null,"server_timestamp":"1785126666433","session_id":"e9443c7415a0419799bee9cfbb1a9e4d","source":"clob_market_ws"},"received_at":"2026-07-27T04:31:11.892176Z","record_id":"85ad6b673bc099f8bb24e218e349e020e5c0af04d73ce0e5a1b6905d6916067e","schema_fingerprint":"4aa3821a28b0b7c2400bc59aba4bcc0a76e971dadd19610d3ad38c768e124dc7","schema_version":"edge-lab-recorder.raw.v1","sequence":null,"source":"clob_market_ws"}
{"event_at":"2026-07-27T04:31:06.434000Z","event_fingerprint":"12f09f55d1677907e397087faf0f9d072ddb3e241cb97f70d6cca8b75d5e5e0e","payload":{"connection_id":"0f4979d6978d463e9660b042fdcf555f","event_at":"2026-07-27T04:31:06.434000Z","event_type":"price_change","frame_hash":"196de2ebdaa82fd5dd0123832de066a53322b385163b25efbfa49edf17e894ac","frame_index":0,"kind":"data","monotonic_ns":228655166179208,"payload":{"event_type":"price_change","market":"0xeb66215f2e9faa6449e30a02bab5b8ed7b79a38bf961f6b24d0073c9c2419250","price_changes":[{"asset_id":"60386828328910021732068595344565885737045900010034836345809386672230885527307","best_ask":"0.6","best_bid":"0.59","hash":"13eabbb14b1179d0cff857d438a66dcd8ea0dfed","price":"0.04","side":"BUY","size":"753.09"},{"asset_id":"69697746896130839564035629862476347944307040470122503199396727085502753297492","best_ask":"0.41","best_bid":"0.4","hash":"bcd73f1220f020d042cb102c653cb2570c791fe6","price":"0.96","side":"SELL","size":"753.09"}],"timestamp":"1785126666434"},"payload_hash":"6b7b22143757ca39d0c20f00c7601edad274269ae59f03ece897d613bf7b127e","raw_frame":"{\"market\":\"0xeb66215f2e9faa6449e30a02bab5b8ed7b79a38bf961f6b24d0073c9c2419250\", \"price_changes\":[{\"asset_id\":\"60386828328910021732068595344565885737045900010034836345809386672230885527307\", \"price\":\"0.04\", \"size\":\"753.09\", \"side\":\"BUY\", \"hash\":\"13eabbb14b1179d0cff857d438a66dcd8ea0dfed\", \"best_bid\":\"0.59\", \"best_ask\":\"0.6\"}, {\"asset_id\":\"69697746896130839564035629862476347944307040470122503199396727085502753297492\", \"price\":\"0.96\", \"size\":\"753.09\", \"side\":\"SELL\", \"hash\":\"bcd73f1220f020d042cb102c653cb2570c791fe6\", \"best_bid\":\"0.4\", \"best_ask\":\"0.41\"}], \"timestamp\":\"1785126666434\", \"event_type\":\"price_change\"}","received_at":"2026-07-27T04:31:11.896966Z","schema_version":"clob-market-ws.price_change.v1","sequence":null,"server_hash":null,"server_timestamp":"1785126666434","session_id":"e9443c7415a0419799bee9cfbb1a9e4d","source":"clob_market_ws"},"received_at":"2026-07-27T04:31:11.896966Z","record_id":"6a1430b43dcac86ce9ac6956c86b48882d399cb8aa0745099f66ec5ec25dce63","schema_fingerprint":"4aa3821a28b0b7c2400bc59aba4bcc0a76e971dadd19610d3ad38c768e124dc7","schema_version":"edge-lab-recorder.raw.v1","sequence":null,"source":"clob_market_ws"}
{"event_at":"2026-07-27T04:31:06.437000Z","event_fingerprint":"75150f74ce1618053020e7fe8807f16351287dfb9799152be5f3acbd57ecd8eb","payload":{"connection_id":"0f4979d6978d463e9660b042fdcf555f","event_at":"2026-07-27T04:31:06.437000Z","event_type":"price_change","frame_hash":"28463b8cdc833c6b8b06c308fb96f44968553ff5884722c6cf63277b97d5d951","frame_index":0,"kind":"data","monotonic_ns":228655178039000,"payload":{"event_type":"price_change","market":"0xeb66215f2e9faa6449e30a02bab5b8ed7b79a38bf961f6b24d0073c9c2419250","price_changes":[{"asset_id":"69697746896130839564035629862476347944307040470122503199396727085502753297492","best_ask":"0.41","best_bid":"0.4","hash":"44337bcf668e8714402caf75b12e3c798337725c","price":"0.38","side":"BUY","size":"65.52"},{"asset_id":"60386828328910021732068595344565885737045900010034836345809386672230885527307","best_ask":"0.6","best_bid":"0.59","hash":"9961a5905290e88cc9d64430fc7f158180280b82","price":"0.62","side":"SELL","size":"65.52"}],"timestamp":"1785126666437"},"payload_hash":"1f0b0b078ec165ce875a850f7a0c23a9ca27c5750ac833e4d4866af21c9d33ae","raw_frame":"{\"market\":\"0xeb66215f2e9faa6449e30a02bab5b8ed7b79a38bf961f6b24d0073c9c2419250\", \"price_changes\":[{\"asset_id\":\"69697746896130839564035629862476347944307040470122503199396727085502753297492\", \"price\":\"0.38\", \"size\":\"65.52\", \"side\":\"BUY\", \"hash\":\"44337bcf668e8714402caf75b12e3c798337725c\", \"best_bid\":\"0.4\", \"best_ask\":\"0.41\"}, {\"asset_id\":\"60386828328910021732068595344565885737045900010034836345809386672230885527307\", \"price\":\"0.62\", \"size\":\"65.52\", \"side\":\"SELL\", \"hash\":\"9961a5905290e88cc9d64430fc7f158180280b82\", \"best_bid\":\"0.59\", \"best_ask\":\"0.6\"}], \"timestamp\":\"1785126666437\", \"event_type\":\"price_change\"}","received_at":"2026-07-27T04:31:11.908825Z","schema_version":"clob-market-ws.price_change.v1","sequence":null,"server_hash":null,"server_timestamp":"1785126666437","session_id":"e9443c7415a0419799bee9cfbb1a9e4d","source":"clob_market_ws"},"received_at":"2026-07-27T04:31:11.908825Z","record_id":"c6b42f40289e021414c82e83551daf96f7508845931826d833e029cf8129632a","schema_fingerprint":"4aa3821a28b0b7c2400bc59aba4bcc0a76e971dadd19610d3ad38c768e124dc7","schema_version":"edge-lab-recorder.raw.v1","sequence":null,"source":"clob_market_ws"}
{"event_at":"2026-07-27T04:31:06.442000Z","event_fingerprint":"528889d85ad84da2296b71936c135ecf0905eb944bf0a97d354eccc741739948","payload":{"connection_id":"0f4979d6978d463e9660b042fdcf555f","event_at":"2026-07-27T04:31:06.442000Z","event_type":"best_bid_ask","frame_hash":"947f5027e0c21337cd8b63c96ea337d4acc2ea3d3d9d67a5f8ef27527a91c254","frame_index":0,"kind":"data","monotonic_ns":228655184933583,"payload":{"asset_id":"69697746896130839564035629862476347944307040470122503199396727085502753297492","best_ask":"0.41","best_bid":"0.39","event_type":"best_bid_ask","market":"0xeb66215f2e9faa6449e30a02bab5b8ed7b79a38bf961f6b24d0073c9c2419250","spread":"0.02","timestamp":"1785126666442"},"payload_hash":"fd448020f693a504047a90d13ed5ebc16fc155921f5997b47afccd6fa433c665","raw_frame":"{\"market\":\"0xeb66215f2e9faa6449e30a02bab5b8ed7b79a38bf961f6b24d0073c9c2419250\", \"asset_id\":\"69697746896130839564035629862476347944307040470122503199396727085502753297492\", \"best_bid\":\"0.39\", \"best_ask\":\"0.41\", \"spread\":\"0.02\", \"timestamp\":\"1785126666442\", \"event_type\":\"best_bid_ask\"}","received_at":"2026-07-27T04:31:11.915720Z","schema_version":"clob-market-ws.best_bid_ask.v1","sequence":null,"server_hash":null,"server_timestamp":"1785126666442","session_id":"e9443c7415a0419799bee9cfbb1a9e4d","source":"clob_market_ws"},"received_at":"2026-07-27T04:31:11.915720Z","record_id":"d12f9a38eb16875dfb11f750dad2ca39aba8ed561b794b1cd552814a24b8cc86","schema_fingerprint":"8488399f31b0337811b13b266be932db7062827c2470b78bd8e9e99bab51d17d","schema_version":"edge-lab-recorder.raw.v1","sequence":null,"source":"clob_market_ws"}
{"event_at":"2026-07-27T04:31:06.442000Z","event_fingerprint":"33ed0a2a8e42da9d6eee048ac37208ba00cb810a123b39356dcb0415ccfe027c","payload":{"connection_id":"0f4979d6978d463e9660b042fdcf555f","event_at":"2026-07-27T04:31:06.442000Z","event_type":"best_bid_ask","frame_hash":"1c6ac2a1b57af12ae0ab5b4b5160e791fd30eb889c80d7f90d610af9e3ef25aa","frame_index":0,"kind":"data","monotonic_ns":228655191368416,"payload":{"asset_id":"60386828328910021732068595344565885737045900010034836345809386672230885527307","best_ask":"0.61","best_bid":"0.59","event_type":"best_bid_ask","market":"0xeb66215f2e9faa6449e30a02bab5b8ed7b79a38bf961f6b24d0073c9c2419250","spread":"0.02","timestamp":"1785126666442"},"payload_hash":"2b08e04dcdae3dfe02010158ecbe9b7c90ea9506bd6930152abb9b7082d01982","raw_frame":"{\"market\":\"0xeb66215f2e9faa6449e30a02bab5b8ed7b79a38bf961f6b24d0073c9c2419250\", \"asset_id\":\"60386828328910021732068595344565885737045900010034836345809386672230885527307\", \"best_bid\":\"0.59\", \"best_ask\":\"0.61\", \"spread\":\"0.02\", \"timestamp\":\"1785126666442\", \"event_type\":\"best_bid_ask\"}","received_at":"2026-07-27T04:31:11.922155Z","schema_version":"clob-market-ws.best_bid_ask.v1","sequence":null,"server_hash":null,"server_timestamp":"1785126666442","session_id":"e9443c7415a0419799bee9cfbb1a9e4d","source":"clob_market_ws"},"received_at":"2026-07-27T04:31:11.922155Z","record_id":"30b9ab9a9f1837a12ada541552bceaf1dbf664c614eb598cd396577e177d6ebd","schema_fingerprint":"8488399f31b0337811b13b266be932db7062827c2470b78bd8e9e99bab51d17d","schema_version":"edge-lab-recorder.raw.v1","sequence":null,"source":"clob_market_ws"}
{"event_at":"2026-07-27T04:31:06.442000Z","event_fingerprint":"0113e840fc3a0dd7f6507ff23a95969c434b92b51f7254ec9d7c7db5c972282c","payload":{"connection_id":"0f4979d6978d463e9660b042fdcf555f","event_at":"2026-07-27T04:31:06.442000Z","event_type":"price_change","frame_hash":"7a27460dbb2e6afddf0d2ba89b0ce1a66b010090e3534cef11ef21fa55c65109","frame_index":0,"kind":"data","monotonic_ns":228655196570916,"payload":{"event_type":"price_change","market":"0xeb66215f2e9faa6449e30a02bab5b8ed7b79a38bf961f6b24d0073c9c2419250","price_changes":[{"asset_id":"69697746896130839564035629862476347944307040470122503199396727085502753297492","best_ask":"0.41","best_bid":"0.39","hash":"e03eee56ee436233b5f29108cf12d50e3b839bd0","price":"0.4","side":"BUY","size":"0"},{"asset_id":"60386828328910021732068595344565885737045900010034836345809386672230885527307","best_ask":"0.61","best_bid":"0.59","hash":"28e03af172610efd32b29c378c4d48e4b13d0d70","price":"0.6","side":"SELL","size":"0"}],"timestamp":"1785126666442"},"payload_hash":"156f3acffca6296c3538b35ccb476c46472dddf587be7598e73c78ecc6199d72","raw_frame":"{\"market\":\"0xeb66215f2e9faa6449e30a02bab5b8ed7b79a38bf961f6b24d0073c9c2419250\", \"price_changes\":[{\"asset_id\":\"69697746896130839564035629862476347944307040470122503199396727085502753297492\", \"price\":\"0.4\", \"size\":\"0\", \"side\":\"BUY\", \"hash\":\"e03eee56ee436233b5f29108cf12d50e3b839bd0\", \"best_bid\":\"0.39\", \"best_ask\":\"0.41\"}, {\"asset_id\":\"60386828328910021732068595344565885737045900010034836345809386672230885527307\", \"price\":\"0.6\", \"size\":\"0\", \"side\":\"SELL\", \"hash\":\"28e03af172610efd32b29c378c4d48e4b13d0d70\", \"best_bid\":\"0.59\", \"best_ask\":\"0.61\"}], \"timestamp\":\"1785126666442\", \"event_type\":\"price_change\"}","received_at":"2026-07-27T04:31:11.927359Z","schema_version":"clob-market-ws.price_change.v1","sequence":null,"server_hash":null,"server_timestamp":"1785126666442","session_id":"e9443c7415a0419799bee9cfbb1a9e4d","source":"clob_market_ws"},"received_at":"2026-07-27T04:31:11.927359Z","record_id":"cc41aaefce74134356a968428a8665c8d0a5ca2eaf06f0938b6eab9ffd62d28f","schema_fingerprint":"4aa3821a28b0b7c2400bc59aba4bcc0a76e971dadd19610d3ad38c768e124dc7","schema_version":"edge-lab-recorder.raw.v1","sequence":null,"source":"clob_market_ws"}
{"event_at":"2026-07-27T04:31:06.445000Z","event_fingerprint":"7d6fc4ef473cbfa72c470481127738406d54775aa0ec2c807943aba500f26929","payload":{"connection_id":"0f4979d6978d463e9660b042fdcf555f","event_at":"2026-07-27T04:31:06.445000Z","event_type":"price_change","frame_hash":"d89791b3c49d89fcdfd2258a3c7f1f46963aa6ffb766cd6e13ab6b826756c2ad","frame_index":0,"kind":"data","monotonic_ns":228655202505416,"payload":{"event_type":"price_change","market":"0xeb66215f2e9faa6449e30a02bab5b8ed7b79a38bf961f6b24d0073c9c2419250","price_changes":[{"asset_id":"60386828328910021732068595344565885737045900010034836345809386672230885527307","best_ask":"0.61","best_bid":"0.59","hash":"0028a0cc7e2080c86e5238afa2d498b0d180d822","price":"0.58","side":"BUY","size":"44.6"},{"asset_id":"69697746896130839564035629862476347944307040470122503199396727085502753297492","best_ask":"0.41","best_bid":"0.39","hash":"822ce73900814f273f299b9a0d6dd8cb91cf0246","price":"0.42","side":"SELL","size":"44.6"}],"timestamp":"1785126666445"},"payload_hash":"7583f5ceb92ba97e70ddffd97927d7df2d0c7b47f61d8fc2432e42f295736c5e","raw_frame":"{\"market\":\"0xeb66215f2e9faa6449e30a02bab5b8ed7b79a38bf961f6b24d0073c9c2419250\", \"price_changes\":[{\"asset_id\":\"60386828328910021732068595344565885737045900010034836345809386672230885527307\", \"price\":\"0.58\", \"size\":\"44.6\", \"side\":\"BUY\", \"hash\":\"0028a0cc7e2080c86e5238afa2d498b0d180d822\", \"best_bid\":\"0.59\", \"best_ask\":\"0.61\"}, {\"asset_id\":\"69697746896130839564035629862476347944307040470122503199396727085502753297492\", \"price\":\"0.42\", \"size\":\"44.6\", \"side\":\"SELL\", \"hash\":\"822ce73900814f273f299b9a0d6dd8cb91cf0246\", \"best_bid\":\"0.39\", \"best_ask\":\"0.41\"}], \"timestamp\":\"1785126666445\", \"event_type\":\"price_change\"}","received_at":"2026-07-27T04:31:11.933292Z","schema_version":"clob-market-ws.price_change.v1","sequence":null,"server_hash":null,"server_timestamp":"1785126666445","session_id":"e9443c7415a0419799bee9cfbb1a9e4d","source":"clob_market_ws"},"received_at":"2026-07-27T04:31:11.933292Z","record_id":"4d1ecf44322ae82378ae2af399c2942acb40bafa9a809d47ac5c53ecff96ee43","schema_fingerprint":"4aa3821a28b0b7c2400bc59aba4bcc0a76e971dadd19610d3ad38c768e124dc7","schema_version":"edge-lab-recorder.raw.v1","sequence":null,"source":"clob_market_ws"}
{"event_at":"2026-07-27T04:31:06.447000Z","event_fingerprint":"8bdfe676392117b9809669f873cf428b4aa477240763af04a268c4d4ab12ddb7","payload":{"connection_id":"0f4979d6978d463e9660b042fdcf555f","event_at":"2026-07-27T04:31:06.447000Z","event_type":"price_change","frame_hash":"212a1982641d57d20d82be93193ac00efa35da36e049614199093d3fec6deadf","frame_index":0,"kind":"data","monotonic_ns":228655207487208,"payload":{"event_type":"price_change","market":"0xeb66215f2e9faa6449e30a02bab5b8ed7b79a38bf961f6b24d0073c9c2419250","price_changes":[{"asset_id":"60386828328910021732068595344565885737045900010034836345809386672230885527307","best_ask":"0.61","best_bid":"0.59","hash":"f471a3c35c8f96d17dacbf641594320b20aec4a5","price":"0.39","side":"BUY","size":"47.6"},{"asset_id":"69697746896130839564035629862476347944307040470122503199396727085502753297492","best_ask":"0.41","best_bid":"0.39","hash":"a44ed5cdef1ab25a3709e4e4e7b8b833d0ca2ffa","price":"0.61","side":"SELL","size":"47.6"}],"timestamp":"1785126666447"},"payload_hash":"a98adc0b9d3703986f197f05b3ab21bab10ed10cbfaa87bb73bf3271c9728062","raw_frame":"{\"market\":\"0xeb66215f2e9faa6449e30a02bab5b8ed7b79a38bf961f6b24d0073c9c2419250\", \"price_changes\":[{\"asset_id\":\"60386828328910021732068595344565885737045900010034836345809386672230885527307\", \"price\":\"0.39\", \"size\":\"47.6\", \"side\":\"BUY\", \"hash\":\"f471a3c35c8f96d17dacbf641594320b20aec4a5\", \"best_bid\":\"0.59\", \"best_ask\":\"0.61\"}, {\"asset_id\":\"69697746896130839564035629862476347944307040470122503199396727085502753297492\", \"price\":\"0.61\", \"size\":\"47.6\", \"side\":\"SELL\", \"hash\":\"a44ed5cdef1ab25a3709e4e4e7b8b833d0ca2ffa\", \"best_bid\":\"0.39\", \"best_ask\":\"0.41\"}], \"timestamp\":\"1785126666447\", \"event_type\":\"price_change\"}","received_at":"2026-07-27T04:31:11.938274Z","schema_version":"clob-market-ws.price_change.v1","sequence":null,"server_hash":null,"server_timestamp":"1785126666447","session_id":"e9443c7415a0419799bee9cfbb1a9e4d","source":"clob_market_ws"},"received_at":"2026-07-27T04:31:11.938274Z","record_id":"9fab784369bdeaf0613d5e978b6fa599dadc3fc26dca8217bf57e6079338286e","schema_fingerprint":"4aa3821a28b0b7c2400bc59aba4bcc0a76e971dadd19610d3ad38c768e124dc7","schema_version":"edge-lab-recorder.raw.v1","sequence":null,"source":"clob_market_ws"}
{"event_at":"2026-07-27T04:31:06.447000Z","event_fingerprint":"22e9c55c5e57dc11f27036de16b311d1146fcdcd1895309a5497dd91611531c6","payload":{"connection_id":"0f4979d6978d463e9660b042fdcf555f","event_at":"2026-07-27T04:31:06.447000Z","event_type":"price_change","frame_hash":"b73d2b600865308865a0045027bb3c475a2093140cb85646e2fce87c854a0d01","frame_index":0,"kind":"data","monotonic_ns":228655212164375,"payload":{"event_type":"price_change","market":"0xeb66215f2e9faa6449e30a02bab5b8ed7b79a38bf961f6b24d0073c9c2419250","price_changes":[{"asset_id":"60386828328910021732068595344565885737045900010034836345809386672230885527307","best_ask":"0.61","best_bid":"0.59","hash":"f8b09bf0ce409ae28e5c3dec4dec349ebc52d535","price":"0.42","side":"BUY","size":"140"},{"asset_id":"69697746896130839564035629862476347944307040470122503199396727085502753297492","best_ask":"0.41","best_bid":"0.39","hash":"ce011d9e07781f608943122e9e94f78c4f2662df","price":"0.58","side":"SELL","size":"140"}],"timestamp":"1785126666447"},"payload_hash":"fdf28b9ff6a5c184fb9f7c4b913a287f85d2cb276b554ad058db61c4730a7118","raw_frame":"{\"market\":\"0xeb66215f2e9faa6449e30a02bab5b8ed7b79a38bf961f6b24d0073c9c2419250\", \"price_changes\":[{\"asset_id\":\"60386828328910021732068595344565885737045900010034836345809386672230885527307\", \"price\":\"0.42\", \"size\":\"140\", \"side\":\"BUY\", \"hash\":\"f8b09bf0ce409ae28e5c3dec4dec349ebc52d535\", \"best_bid\":\"0.59\", \"best_ask\":\"0.61\"}, {\"asset_id\":\"69697746896130839564035629862476347944307040470122503199396727085502753297492\", \"price\":\"0.58\", \"size\":\"140\", \"side\":\"SELL\", \"hash\":\"ce011d9e07781f608943122e9e94f78c4f2662df\", \"best_bid\":\"0.39\", \"best_ask\":\"0.41\"}], \"timestamp\":\"1785126666447\", \"event_type\":\"price_change\"}","received_at":"2026-07-27T04:31:11.942952Z","schema_version":"clob-market-ws.price_change.v1","sequence":null,"server_hash":null,"server_timestamp":"1785126666447","session_id":"e9443c7415a0419799bee9cfbb1a9e4d","source":"clob_market_ws"},"received_at":"2026-07-27T04:31:11.942952Z","record_id":"1c846de4a06565b2921295984265304ee98f61880f388754338542c8b0545722","schema_fingerprint":"4aa3821a28b0b7c2400bc59aba4bcc0a76e971dadd19610d3ad38c768e124dc7","schema_version":"edge-lab-recorder.raw.v1","sequence":null,"source":"clob_market_ws"}
{"event_at":"2026-07-27T04:31:06.459000Z","event_fingerprint":"2476662e6f8c02e4b5dce569d76c5a69f3295d4f633781405a3a41b45b61f75b","payload":{"connection_id":"0f4979d6978d463e9660b042fdcf555f","event_at":"2026-07-27T04:31:06.459000Z","event_type":"price_change","frame_hash":"3fb45f45ee5d9483646a24b1e19ebdfd6bd4f265d32f1aa1b9efabf43b040a63","frame_index":0,"kind":"data","monotonic_ns":228655220528333,"payload":{"event_type":"price_change","market":"0xeb66215f2e9faa6449e30a02bab5b8ed7b79a38bf961f6b24d0073c9c2419250","price_changes":[{"asset_id":"60386828328910021732068595344565885737045900010034836345809386672230885527307","best_ask":"0.61","best_bid":"0.59","hash":"a9782d237eabad425075572aa2544e35b7c9b612","price":"0.43","side":"BUY","size":"117"},{"asset_id":"69697746896130839564035629862476347944307040470122503199396727085502753297492","best_ask":"0.41","best_bid":"0.39","hash":"3c38b07787947d09b50a3d1f2b2eb52b4c4b7b3d","price":"0.57","side":"SELL","size":"117"}],"timestamp":"1785126666459"},"payload_hash":"ab98dc8e2ddef56aa113544b80c84a6cda841a877d49b8d1f9c6c174379e6151","raw_frame":"{\"market\":\"0xeb66215f2e9faa6449e30a02bab5b8ed7b79a38bf961f6b24d0073c9c2419250\", \"price_changes\":[{\"asset_id\":\"60386828328910021732068595344565885737045900010034836345809386672230885527307\", \"price\":\"0.43\", \"size\":\"117\", \"side\":\"BUY\", \"hash\":\"a9782d237eabad425075572aa2544e35b7c9b612\", \"best_bid\":\"0.59\", \"best_ask\":\"0.61\"}, {\"asset_id\":\"69697746896130839564035629862476347944307040470122503199396727085502753297492\", \"price\":\"0.57\", \"size\":\"117\", \"side\":\"SELL\", \"hash\":\"3c38b07787947d09b50a3d1f2b2eb52b4c4b7b3d\", \"best_bid\":\"0.39\", \"best_ask\":\"0.41\"}], \"timestamp\":\"1785126666459\", \"event_type\":\"price_change\"}","received_at":"2026-07-27T04:31:11.951314Z","schema_version":"clob-market-ws.price_change.v1","sequence":null,"server_hash":null,"server_timestamp":"1785126666459","session_id":"e9443c7415a0419799bee9cfbb1a9e4d","source":"clob_market_ws"},"received_at":"2026-07-27T04:31:11.951314Z","record_id":"ffd20c3ccde8028f223f8fec71b8537a365549a885c6f8a762752beb4b235af9","schema_fingerprint":"4aa3821a28b0b7c2400bc59aba4bcc0a76e971dadd19610d3ad38c768e124dc7","schema_version":"edge-lab-recorder.raw.v1","sequence":null,"source":"clob_market_ws"}
{"event_at":"2026-07-27T04:31:06.460000Z","event_fingerprint":"858aa122072b41a70319369c2b11515de143cb43cb662686591d6f8c96186caa","payload":{"connection_id":"0f4979d6978d463e9660b042fdcf555f","event_at":"2026-07-27T04:31:06.460000Z","event_type":"best_bid_ask","frame_hash":"a9ccae9b4b3f27878fbebd1c8ba457787b80c93d9a64fee1beb4d12b6285538c","frame_index":0,"kind":"data","monotonic_ns":228655226783166,"payload":{"asset_id":"69697746896130839564035629862476347944307040470122503199396727085502753297492","best_ask":"0.4","best_bid":"0.39","event_type":"best_bid_ask","market":"0xeb66215f2e9faa6449e30a02bab5b8ed7b79a38bf961f6b24d0073c9c2419250","spread":"0.01","timestamp":"1785126666460"},"payload_hash":"d4e23e72bc5a12e2f2cc9c567224c00877e8844bc458df3dd3035522c2d90fa7","raw_frame":"{\"market\":\"0xeb66215f2e9faa6449e30a02bab5b8ed7b79a38bf961f6b24d0073c9c2419250\", \"asset_id\":\"69697746896130839564035629862476347944307040470122503199396727085502753297492\", \"best_bid\":\"0.39\", \"best_ask\":\"0.4\", \"spread\":\"0.01\", \"timestamp\":\"1785126666460\", \"event_type\":\"best_bid_ask\"}","received_at":"2026-07-27T04:31:11.957570Z","schema_version":"clob-market-ws.best_bid_ask.v1","sequence":null,"server_hash":null,"server_timestamp":"1785126666460","session_id":"e9443c7415a0419799bee9cfbb1a9e4d","source":"clob_market_ws"},"received_at":"2026-07-27T04:31:11.957570Z","record_id":"a91d147b71b6304664f66123a46224315576e7e4c72d55a59a9ecc2f2e0652da","schema_fingerprint":"8488399f31b0337811b13b266be932db7062827c2470b78bd8e9e99bab51d17d","schema_version":"edge-lab-recorder.raw.v1","sequence":null,"source":"clob_market_ws"}
{"event_at":"2026-07-27T04:31:06.460000Z","event_fingerprint":"a40c87e423ca48ed4b4c1a257b83827ac7ede4436553793ca7027d890a651a60","payload":{"connection_id":"0f4979d6978d463e9660b042fdcf555f","event_at":"2026-07-27T04:31:06.460000Z","event_type":"best_bid_ask","frame_hash":"674cc3d87e1aa04e9401a522a7bb700acc26ad657792e9ab1f516eba94c0e65a","frame_index":0,"kind":"data","monotonic_ns":228655233894833,"payload":{"asset_id":"60386828328910021732068595344565885737045900010034836345809386672230885527307","best_ask":"0.61","best_bid":"0.6","event_type":"best_bid_ask","market":"0xeb66215f2e9faa6449e30a02bab5b8ed7b79a38bf961f6b24d0073c9c2419250","spread":"0.01","timestamp":"1785126666460"},"payload_hash":"6236193796dc96a52d6e0d4e3fea706e3e2afb8b8d9535a47bc80206f1ef1abb","raw_frame":"{\"market\":\"0xeb66215f2e9faa6449e30a02bab5b8ed7b79a38bf961f6b24d0073c9c2419250\", \"asset_id\":\"60386828328910021732068595344565885737045900010034836345809386672230885527307\", \"best_bid\":\"0.6\", \"best_ask\":\"0.61\", \"spread\":\"0.01\", \"timestamp\":\"1785126666460\", \"event_type\":\"best_bid_ask\"}","received_at":"2026-07-27T04:31:11.964683Z","schema_version":"clob-market-ws.best_bid_ask.v1","sequence":null,"server_hash":null,"server_timestamp":"1785126666460","session_id":"e9443c7415a0419799bee9cfbb1a9e4d","source":"clob_market_ws"},"received_at":"2026-07-27T04:31:11.964683Z","record_id":"f71db9f3f3f51c852049ec2d869fce7f8b9178ded8fccc99530b5de46e7d54cf","schema_fingerprint":"8488399f31b0337811b13b266be932db7062827c2470b78bd8e9e99bab51d17d","schema_version":"edge-lab-recorder.raw.v1","sequence":null,"source":"clob_market_ws"}
{"event_at":"2026-07-27T04:31:06.460000Z","event_fingerprint":"11fce503f975fe83b8fe95bdec5f18e27f82cb1fa6f56681312ab8777c68903e","payload":{"connection_id":"0f4979d6978d463e9660b042fdcf555f","event_at":"2026-07-27T04:31:06.460000Z","event_type":"price_change","frame_hash":"98a0f180d82b89be93c3cd313b56a096d688f4673b6e61cac5734abf8f404bb6","frame_index":0,"kind":"data","monotonic_ns":228655240062541,"payload":{"event_type":"price_change","market":"0xeb66215f2e9faa6449e30a02bab5b8ed7b79a38bf961f6b24d0073c9c2419250","price_changes":[{"asset_id":"60386828328910021732068595344565885737045900010034836345809386672230885527307","best_ask":"0.61","best_bid":"0.6","hash":"8904e3d824c5c3ef10a37b7acb8ffd27ecb55c03","price":"0.6","side":"BUY","size":"44"},{"asset_id":"69697746896130839564035629862476347944307040470122503199396727085502753297492","best_ask":"0.4","best_bid":"0.39","hash":"70239b6fa346c12453749cca8f2635d0b1bc9f16","price":"0.4","side":"SELL","size":"44"}],"timestamp":"1785126666460"},"payload_hash":"bc99dac32a5ee52e606c8a79bf82d633f24065c751d22e3eaeab71a46c9e3209","raw_frame":"{\"market\":\"0xeb66215f2e9faa6449e30a02bab5b8ed7b79a38bf961f6b24d0073c9c2419250\", \"price_changes\":[{\"asset_id\":\"60386828328910021732068595344565885737045900010034836345809386672230885527307\", \"price\":\"0.6\", \"size\":\"44\", \"side\":\"BUY\", \"hash\":\"8904e3d824c5c3ef10a37b7acb8ffd27ecb55c03\", \"best_bid\":\"0.6\", \"best_ask\":\"0.61\"}, {\"asset_id\":\"69697746896130839564035629862476347944307040470122503199396727085502753297492\", \"price\":\"0.4\", \"size\":\"44\", \"side\":\"SELL\", \"hash\":\"70239b6fa346c12453749cca8f2635d0b1bc9f16\", \"best_bid\":\"0.39\", \"best_ask\":\"0.4\"}], \"timestamp\":\"1785126666460\", \"event_type\":\"price_change\"}","received_at":"2026-07-27T04:31:11.970849Z","schema_version":"clob-market-ws.price_change.v1","sequence":null,"server_hash":null,"server_timestamp":"1785126666460","session_id":"e9443c7415a0419799bee9cfbb1a9e4d","source":"clob_market_ws"},"received_at":"2026-07-27T04:31:11.970849Z","record_id":"153812f2fe7e917f0aebd1327562f0e1f0c7cae0fd6fe468be235cf89da3fd59","schema_fingerprint":"4aa3821a28b0b7c2400bc59aba4bcc0a76e971dadd19610d3ad38c768e124dc7","schema_version":"edge-lab-recorder.raw.v1","sequence":null,"source":"clob_market_ws"}
{"event_at":"2026-07-27T04:31:06.461000Z","event_fingerprint":"a6f13a5d84782a265b42f5e4c9d446134be8edb314ca408ef408491304e2f439","payload":{"connection_id":"0f4979d6978d463e9660b042fdcf555f","event_at":"2026-07-27T04:31:06.461000Z","event_type":"price_change","frame_hash":"3f471faeea3673a318ac164cc4cac7e3fcabcbde988dbf0385a61dd86bbd814e","frame_index":0,"kind":"data","monotonic_ns":228655246107166,"payload":{"event_type":"price_change","market":"0xeb66215f2e9faa6449e30a02bab5b8ed7b79a38bf961f6b24d0073c9c2419250","price_changes":[{"asset_id":"60386828328910021732068595344565885737045900010034836345809386672230885527307","best_ask":"0.61","best_bid":"0.6","hash":"674ea32e68c89f0f842fbcc1da697f263a2d6b85","price":"0.56","side":"BUY","size":"90.4"},{"asset_id":"69697746896130839564035629862476347944307040470122503199396727085502753297492","best_ask":"0.4","best_bid":"0.39","hash":"c724eb0f5051433a77e307ddfb40c53a44482faa","price":"0.44","side":"SELL","size":"90.4"}],"timestamp":"1785126666461"},"payload_hash":"e7b3467f82c8eca172fd6eb29b20f6223f9a9be0ea6c912fad38a78cf135791f","raw_frame":"{\"market\":\"0xeb66215f2e9faa6449e30a02bab5b8ed7b79a38bf961f6b24d0073c9c2419250\", \"price_changes\":[{\"asset_id\":\"60386828328910021732068595344565885737045900010034836345809386672230885527307\", \"price\":\"0.56\", \"size\":\"90.4\", \"side\":\"BUY\", \"hash\":\"674ea32e68c89f0f842fbcc1da697f263a2d6b85\", \"best_bid\":\"0.6\", \"best_ask\":\"0.61\"}, {\"asset_id\":\"69697746896130839564035629862476347944307040470122503199396727085502753297492\", \"price\":\"0.44\", \"size\":\"90.4\", \"side\":\"SELL\", \"hash\":\"c724eb0f5051433a77e307ddfb40c53a44482faa\", \"best_bid\":\"0.39\", \"best_ask\":\"0.4\"}], \"timestamp\":\"1785126666461\", \"event_type\":\"price_change\"}","received_at":"2026-07-27T04:31:11.976894Z","schema_version":"clob-market-ws.price_change.v1","sequence":null,"server_hash":null,"server_timestamp":"1785126666461","session_id":"e9443c7415a0419799bee9cfbb1a9e4d","source":"clob_market_ws"},"received_at":"2026-07-27T04:31:11.976894Z","record_id":"799cdc56ecb80fc79b456b0a1d6496b72b68b129a6aa15ad454c3ef6a58a8970","schema_fingerprint":"4aa3821a28b0b7c2400bc59aba4bcc0a76e971dadd19610d3ad38c768e124dc7","schema_version":"edge-lab-recorder.raw.v1","sequence":null,"source":"clob_market_ws"}
{"event_at":"2026-07-27T04:31:06.470000Z","event_fingerprint":"a6deb997746ad6b5923447b932d75210979c2973110e6ca479de7da7f57a511e","payload":{"connection_id":"0f4979d6978d463e9660b042fdcf555f","event_at":"2026-07-27T04:31:06.470000Z","event_type":"price_change","frame_hash":"ca053b5fd1c0f7f0bf44e8c0194895d28ea930ef8a6fb8d9cedcfb697d8ab03d","frame_index":0,"kind":"data","monotonic_ns":228655252743458,"payload":{"event_type":"price_change","market":"0xeb66215f2e9faa6449e30a02bab5b8ed7b79a38bf961f6b24d0073c9c2419250","price_changes":[{"asset_id":"60386828328910021732068595344565885737045900010034836345809386672230885527307","best_ask":"0.61","best_bid":"0.6","hash":"c1e61d246dfd85142d663eda48040cb60c6c4f1c","price":"0.01","side":"BUY","size":"7708.02"},{"asset_id":"69697746896130839564035629862476347944307040470122503199396727085502753297492","best_ask":"0.4","best_bid":"0.39","hash":"8e845beeb6f7b93e0c128aa7a003ebe2b0b52118","price":"0.99","side":"SELL","size":"7708.02"}],"timestamp":"1785126666470"},"payload_hash":"0fdda4939c27ea564b2fad3ead466ff7b6f0ff09f78a442147a763f414a6712e","raw_frame":"{\"market\":\"0xeb66215f2e9faa6449e30a02bab5b8ed7b79a38bf961f6b24d0073c9c2419250\", \"price_changes\":[{\"asset_id\":\"60386828328910021732068595344565885737045900010034836345809386672230885527307\", \"price\":\"0.01\", \"size\":\"7708.02\", \"side\":\"BUY\", \"hash\":\"c1e61d246dfd85142d663eda48040cb60c6c4f1c\", \"best_bid\":\"0.6\", \"best_ask\":\"0.61\"}, {\"asset_id\":\"69697746896130839564035629862476347944307040470122503199396727085502753297492\", \"price\":\"0.99\", \"size\":\"7708.02\", \"side\":\"SELL\", \"hash\":\"8e845beeb6f7b93e0c128aa7a003ebe2b0b52118\", \"best_bid\":\"0.39\", \"best_ask\":\"0.4\"}], \"timestamp\":\"1785126666470\", \"event_type\":\"price_change\"}","received_at":"2026-07-27T04:31:11.983531Z","schema_version":"clob-market-ws.price_change.v1","sequence":null,"server_hash":null,"server_timestamp":"1785126666470","session_id":"e9443c7415a0419799bee9cfbb1a9e4d","source":"clob_market_ws"},"received_at":"2026-07-27T04:31:11.983531Z","record_id":"bc40248bedb78ae3d6e97889d5d811c5d2eb973cac19d6b7e3b16b4b8c66252c","schema_fingerprint":"4aa3821a28b0b7c2400bc59aba4bcc0a76e971dadd19610d3ad38c768e124dc7","schema_version":"edge-lab-recorder.raw.v1","sequence":null,"source":"clob_market_ws"}
{"event_at":"2026-07-27T04:31:06.470000Z","event_fingerprint":"a47e5a90b9303a704ad6b3a9f6e868b9358aa9c7ccd077e39f19ec61b652847e","payload":{"connection_id":"0f4979d6978d463e9660b042fdcf555f","event_at":"2026-07-27T04:31:06.470000Z","event_type":"price_change","frame_hash":"f3d3ae5c1f996c335301f7f27c83fbcd96c293abd4720b7dee3660ed28becbe2","frame_index":0,"kind":"data","monotonic_ns":228655258874958,"payload":{"event_type":"price_change","market":"0xeb66215f2e9faa6449e30a02bab5b8ed7b79a38bf961f6b24d0073c9c2419250","price_changes":[{"asset_id":"69697746896130839564035629862476347944307040470122503199396727085502753297492","best_ask":"0.4","best_bid":"0.39","hash":"2044f095c7219e01935fef8c35778d14477c14bc","price":"0.37","side":"BUY","size":"32.04"},{"asset_id":"60386828328910021732068595344565885737045900010034836345809386672230885527307","best_ask":"0.61","best_bid":"0.6","hash":"a5a3209022e788c71d785365f3a53518ba057349","price":"0.63","side":"SELL","size":"32.04"}],"timestamp":"1785126666470"},"payload_hash":"3926e2b551a7e587f6e88373a376b21ebd0b88b1e5fb466532ca252caf972aac","raw_frame":"{\"market\":\"0xeb66215f2e9faa6449e30a02bab5b8ed7b79a38bf961f6b24d0073c9c2419250\", \"price_changes\":[{\"asset_id\":\"69697746896130839564035629862476347944307040470122503199396727085502753297492\", \"price\":\"0.37\", \"size\":\"32.04\", \"side\":\"BUY\", \"hash\":\"2044f095c7219e01935fef8c35778d14477c14bc\", \"best_bid\":\"0.39\", \"best_ask\":\"0.4\"}, {\"asset_id\":\"60386828328910021732068595344565885737045900010034836345809386672230885527307\", \"price\":\"0.63\", \"size\":\"32.04\", \"side\":\"SELL\", \"hash\":\"a5a3209022e788c71d785365f3a53518ba057349\", \"best_bid\":\"0.6\", \"best_ask\":\"0.61\"}], \"timestamp\":\"1785126666470\", \"event_type\":\"price_change\"}","received_at":"2026-07-27T04:31:11.989662Z","schema_version":"clob-market-ws.price_change.v1","sequence":null,"server_hash":null,"server_timestamp":"1785126666470","session_id":"e9443c7415a0419799bee9cfbb1a9e4d","source":"clob_market_ws"},"received_at":"2026-07-27T04:31:11.989662Z","record_id":"1a9a2f788e6b5ed2367ece62c2af44a6f7e7f2f63510eb07d474622308d6eeb8","schema_fingerprint":"4aa3821a28b0b7c2400bc59aba4bcc0a76e971dadd19610d3ad38c768e124dc7","schema_version":"edge-lab-recorder.raw.v1","sequence":null,"source":"clob_market_ws"}
{"event_at":"2026-07-27T04:31:06.470000Z","event_fingerprint":"cd134b6357c81a1080155048d5323efae366dd5fa97a4a60263545aa3c81b9c7","payload":{"connection_id":"0f4979d6978d463e9660b042fdcf555f","event_at":"2026-07-27T04:31:06.470000Z","event_type":"price_change","frame_hash":"47120b69818d9f0c63d119665475c6e07160f88ed70155f008dc3d0bff37fd4b","frame_index":0,"kind":"data","monotonic_ns":228655266682541,"payload":{"event_type":"price_change","market":"0xeb66215f2e9faa6449e30a02bab5b8ed7b79a38bf961f6b24d0073c9c2419250","price_changes":[{"asset_id":"60386828328910021732068595344565885737045900010034836345809386672230885527307","best_ask":"0.61","best_bid":"0.6","hash":"a04cb74e847348861fb2f8bc059a5b915b8f9979","price":"0.58","side":"BUY","size":"19.6"},{"asset_id":"69697746896130839564035629862476347944307040470122503199396727085502753297492","best_ask":"0.4","best_bid":"0.39","hash":"75b16cd15168758595a8b8e06902b734b340f30c","price":"0.42","side":"SELL","size":"19.6"}],"timestamp":"1785126666470"},"payload_hash":"dd419d0ab47e9bea648ee4a5fa6934d7d0fe1acf61089e66590fc6e852b1b9d0","raw_frame":"{\"market\":\"0xeb66215f2e9faa6449e30a02bab5b8ed7b79a38bf961f6b24d0073c9c2419250\", \"price_changes\":[{\"asset_id\":\"60386828328910021732068595344565885737045900010034836345809386672230885527307\", \"price\":\"0.58\", \"size\":\"19.6\", \"side\":\"BUY\", \"hash\":\"a04cb74e847348861fb2f8bc059a5b915b8f9979\", \"best_bid\":\"0.6\", \"best_ask\":\"0.61\"}, {\"asset_id\":\"69697746896130839564035629862476347944307040470122503199396727085502753297492\", \"price\":\"0.42\", \"size\":\"19.6\", \"side\":\"SELL\", \"hash\":\"75b16cd15168758595a8b8e06902b734b340f30c\", \"best_bid\":\"0.39\", \"best_ask\":\"0.4\"}], \"timestamp\":\"1785126666470\", \"event_type\":\"price_change\"}","received_at":"2026-07-27T04:31:11.997468Z","schema_version":"clob-market-ws.price_change.v1","sequence":null,"server_hash":null,"server_timestamp":"1785126666470","session_id":"e9443c7415a0419799bee9cfbb1a9e4d","source":"clob_market_ws"},"received_at":"2026-07-27T04:31:11.997468Z","record_id":"6005c4deb8251ef9243ee8146d15d185764b0ca279ca26c9a5fb731110dd189a","schema_fingerprint":"4aa3821a28b0b7c2400bc59aba4bcc0a76e971dadd19610d3ad38c768e124dc7","schema_version":"edge-lab-recorder.raw.v1","sequence":null,"source":"clob_market_ws"}
{"event_at":"2026-07-27T04:31:06.479000Z","event_fingerprint":"2d6ad7033c5f2883326a3db55b15751075ba737bf2719be10bb54f3493ed2e22","payload":{"connection_id":"0f4979d6978d463e9660b042fdcf555f","event_at":"2026-07-27T04:31:06.479000Z","event_type":"price_change","frame_hash":"22eaf7fd4c7b166251d95973493d8f29def62eec5ab56267e21a65a2fe18a619","frame_index":0,"kind":"data","monotonic_ns":228655273277916,"payload":{"event_type":"price_change","market":"0xeb66215f2e9faa6449e30a02bab5b8ed7b79a38bf961f6b24d0073c9c2419250","price_changes":[{"asset_id":"69697746896130839564035629862476347944307040470122503199396727085502753297492","best_ask":"0.4","best_bid":"0.39","hash":"b0c41275a463a2bd14abbd748d94a3c4a77a69e4","price":"0.23","side":"BUY","size":"123.89"},{"asset_id":"60386828328910021732068595344565885737045900010034836345809386672230885527307","best_ask":"0.61","best_bid":"0.6","hash":"12601c04b53f91c827fa55e408487ea361af9d6e","price":"0.77","side":"SELL","size":"123.89"}],"timestamp":"1785126666479"},"payload_hash":"354faa01f5e0240a8a54a03eadcccd193929cbba037da0ea4556093ae10d0f17","raw_frame":"{\"market\":\"0xeb66215f2e9faa6449e30a02bab5b8ed7b79a38bf961f6b24d0073c9c2419250\", \"price_changes\":[{\"asset_id\":\"69697746896130839564035629862476347944307040470122503199396727085502753297492\", \"price\":\"0.23\", \"size\":\"123.89\", \"side\":\"BUY\", \"hash\":\"b0c41275a463a2bd14abbd748d94a3c4a77a69e4\", \"best_bid\":\"0.39\", \"best_ask\":\"0.4\"}, {\"asset_id\":\"60386828328910021732068595344565885737045900010034836345809386672230885527307\", \"price\":\"0.77\", \"size\":\"123.89\", \"side\":\"SELL\", \"hash\":\"12601c04b53f91c827fa55e408487ea361af9d6e\", \"best_bid\":\"0.6\", \"best_ask\":\"0.61\"}], \"timestamp\":\"1785126666479\", \"event_type\":\"price_change\"}","received_at":"2026-07-27T04:31:12.004065Z","schema_version":"clob-market-ws.price_change.v1","sequence":null,"server_hash":null,"server_timestamp":"1785126666479","session_id":"e9443c7415a0419799bee9cfbb1a9e4d","source":"clob_market_ws"},"received_at":"2026-07-27T04:31:12.004065Z","record_id":"555afdbaa2e73a9f87dd62ae96161a2168ce9cf793f52d265864eba82be42037","schema_fingerprint":"4aa3821a28b0b7c2400bc59aba4bcc0a76e971dadd19610d3ad38c768e124dc7","schema_version":"edge-lab-recorder.raw.v1","sequence":null,"source":"clob_market_ws"}
{"event_at":"2026-07-27T04:31:06.487000Z","event_fingerprint":"cf2e6f0febb6d56d4862173674dbe6b7361ca199dcc28524946dd5faea188df9","payload":{"connection_id":"0f4979d6978d463e9660b042fdcf555f","event_at":"2026-07-27T04:31:06.487000Z","event_type":"price_change","frame_hash":"3080a29e53d32ab204ef8fd0bb11bacda1dbc80fff9045336c8ff80276c2bc62","frame_index":0,"kind":"data","monotonic_ns":228655278545791,"payload":{"event_type":"price_change","market":"0xeb66215f2e9faa6449e30a02bab5b8ed7b79a38bf961f6b24d0073c9c2419250","price_changes":[{"asset_id":"69697746896130839564035629862476347944307040470122503199396727085502753297492","best_ask":"0.4","best_bid":"0.39","hash":"95dbb45a9c61b6a4a7ab612c7737c24f5df22a97","price":"0.36","side":"BUY","size":"19"},{"asset_id":"60386828328910021732068595344565885737045900010034836345809386672230885527307","best_ask":"0.61","best_bid":"0.6","hash":"93f6c2c875945aa49d3ad52dddab8b96ec290623","price":"0.64","side":"SELL","size":"19"}],"timestamp":"1785126666487"},"payload_hash":"bfcd1484ff87c707a8f9bc8f2ae9f585d067e5b82edbbb7bc6ac8e1059df6975","raw_frame":"{\"market\":\"0xeb66215f2e9faa6449e30a02bab5b8ed7b79a38bf961f6b24d0073c9c2419250\", \"price_changes\":[{\"asset_id\":\"69697746896130839564035629862476347944307040470122503199396727085502753297492\", \"price\":\"0.36\", \"size\":\"19\", \"side\":\"BUY\", \"hash\":\"95dbb45a9c61b6a4a7ab612c7737c24f5df22a97\", \"best_bid\":\"0.39\", \"best_ask\":\"0.4\"}, {\"asset_id\":\"60386828328910021732068595344565885737045900010034836345809386672230885527307\", \"price\":\"0.64\", \"size\":\"19\", \"side\":\"SELL\", \"hash\":\"93f6c2c875945aa49d3ad52dddab8b96ec290623\", \"best_bid\":\"0.6\", \"best_ask\":\"0.61\"}], \"timestamp\":\"1785126666487\", \"event_type\":\"price_change\"}","received_at":"2026-07-27T04:31:12.009330Z","schema_version":"clob-market-ws.price_change.v1","sequence":null,"server_hash":null,"server_timestamp":"1785126666487","session_id":"e9443c7415a0419799bee9cfbb1a9e4d","source":"clob_market_ws"},"received_at":"2026-07-27T04:31:12.009330Z","record_id":"a433e5f3cfc8919bb5d82f8eea2f48e95ba77743d59732c11dd401f8dc32c90c","schema_fingerprint":"4aa3821a28b0b7c2400bc59aba4bcc0a76e971dadd19610d3ad38c768e124dc7","schema_version":"edge-lab-recorder.raw.v1","sequence":null,"source":"clob_market_ws"}
{"event_at":"2026-07-27T04:31:06.487000Z","event_fingerprint":"ffc57f579b6bdde9c10f7e574d2a98f08716d1c2b01195563db3e6711e303313","payload":{"connection_id":"0f4979d6978d463e9660b042fdcf555f","event_at":"2026-07-27T04:31:06.487000Z","event_type":"price_change","frame_hash":"0537083ec7eb8cb30c742cee30c358bea35443ef3271885747a2486621eef627","frame_index":0,"kind":"data","monotonic_ns":228655283698041,"payload":{"event_type":"price_change","market":"0xeb66215f2e9faa6449e30a02bab5b8ed7b79a38bf961f6b24d0073c9c2419250","price_changes":[{"asset_id":"60386828328910021732068595344565885737045900010034836345809386672230885527307","best_ask":"0.61","best_bid":"0.6","hash":"fa3d3a7492e857956382cb3dd4186c02fe4f2517","price":"0.41","side":"BUY","size":"22.4"},{"asset_id":"69697746896130839564035629862476347944307040470122503199396727085502753297492","best_ask":"0.4","best_bid":"0.39","hash":"456142f4cf3f57d2d685c373d843f628e504b2be","price":"0.59","side":"SELL","size":"22.4"}],"timestamp":"1785126666487"},"payload_hash":"79a9ec7ca82d174e935baf45faa452f039907f84d4d3f7114e629acc614a0325","raw_frame":"{\"market\":\"0xeb66215f2e9faa6449e30a02bab5b8ed7b79a38bf961f6b24d0073c9c2419250\", \"price_changes\":[{\"asset_id\":\"60386828328910021732068595344565885737045900010034836345809386672230885527307\", \"price\":\"0.41\", \"size\":\"22.4\", \"side\":\"BUY\", \"hash\":\"fa3d3a7492e857956382cb3dd4186c02fe4f2517\", \"best_bid\":\"0.6\", \"best_ask\":\"0.61\"}, {\"asset_id\":\"69697746896130839564035629862476347944307040470122503199396727085502753297492\", \"price\":\"0.59\", \"size\":\"22.4\", \"side\":\"SELL\", \"hash\":\"456142f4cf3f57d2d685c373d843f628e504b2be\", \"best_bid\":\"0.39\", \"best_ask\":\"0.4\"}], \"timestamp\":\"1785126666487\", \"event_type\":\"price_change\"}","received_at":"2026-07-27T04:31:12.014486Z","schema_version":"clob-market-ws.price_change.v1","sequence":null,"server_hash":null,"server_timestamp":"1785126666487","session_id":"e9443c7415a0419799bee9cfbb1a9e4d","source":"clob_market_ws"},"received_at":"2026-07-27T04:31:12.014486Z","record_id":"b0c1ef2e83e15985f5364f5ad682e8327e1ad7a48534d33c75ce8296b67afc98","schema_fingerprint":"4aa3821a28b0b7c2400bc59aba4bcc0a76e971dadd19610d3ad38c768e124dc7","schema_version":"edge-lab-recorder.raw.v1","sequence":null,"source":"clob_market_ws"}
{"event_at":"2026-07-27T04:31:06.489000Z","event_fingerprint":"7231d238da188bdf7c8cc5d5fcc49be14920b43185e6a80f925ddaec806e8fc6","payload":{"connection_id":"0f4979d6978d463e9660b042fdcf555f","event_at":"2026-07-27T04:31:06.489000Z","event_type":"price_change","frame_hash":"cb5cb49182ca203ea3f2e3c292ecf69c779ade634bec097d7b4c387f53f2746b","frame_index":0,"kind":"data","monotonic_ns":228655288798916,"payload":{"event_type":"price_change","market":"0xeb66215f2e9faa6449e30a02bab5b8ed7b79a38bf961f6b24d0073c9c2419250","price_changes":[{"asset_id":"60386828328910021732068595344565885737045900010034836345809386672230885527307","best_ask":"0.61","best_bid":"0.6","hash":"6c2521ed3c7a108495df83206506bd4511a3a567","price":"0.59","side":"BUY","size":"64.4"},{"asset_id":"69697746896130839564035629862476347944307040470122503199396727085502753297492","best_ask":"0.4","best_bid":"0.39","hash":"f5edb117e8a48e9f4cf2570fcf1edae39e98b497","price":"0.41","side":"SELL","size":"64.4"}],"timestamp":"1785126666489"},"payload_hash":"04a8d0d67307c270dd8702be78b8af8ac44f13e7f7a18d78ed2208fa1f0cb78b","raw_frame":"{\"market\":\"0xeb66215f2e9faa6449e30a02bab5b8ed7b79a38bf961f6b24d0073c9c2419250\", \"price_changes\":[{\"asset_id\":\"60386828328910021732068595344565885737045900010034836345809386672230885527307\", \"price\":\"0.59\", \"size\":\"64.4\", \"side\":\"BUY\", \"hash\":\"6c2521ed3c7a108495df83206506bd4511a3a567\", \"best_bid\":\"0.6\", \"best_ask\":\"0.61\"}, {\"asset_id\":\"69697746896130839564035629862476347944307040470122503199396727085502753297492\", \"price\":\"0.41\", \"size\":\"64.4\", \"side\":\"SELL\", \"hash\":\"f5edb117e8a48e9f4cf2570fcf1edae39e98b497\", \"best_bid\":\"0.39\", \"best_ask\":\"0.4\"}], \"timestamp\":\"1785126666489\", \"event_type\":\"price_change\"}","received_at":"2026-07-27T04:31:12.019584Z","schema_version":"clob-market-ws.price_change.v1","sequence":null,"server_hash":null,"server_timestamp":"1785126666489","session_id":"e9443c7415a0419799bee9cfbb1a9e4d","source":"clob_market_ws"},"received_at":"2026-07-27T04:31:12.019584Z","record_id":"eef7d719c0c6d64a7d77596022ba5f25375ff06763e928703b86b5cdb690413a","schema_fingerprint":"4aa3821a28b0b7c2400bc59aba4bcc0a76e971dadd19610d3ad38c768e124dc7","schema_version":"edge-lab-recorder.raw.v1","sequence":null,"source":"clob_market_ws"}
{"event_at":"2026-07-27T04:31:06.497000Z","event_fingerprint":"40a5b9ef5fe60bf5f98aa9691bfaedbcc0e373dd2e4e6c84ba4c7be47718c2cf","payload":{"connection_id":"0f4979d6978d463e9660b042fdcf555f","event_at":"2026-07-27T04:31:06.497000Z","event_type":"price_change","frame_hash":"781c8ba6c05d22012eaadf2c123f98c7a63951b9f8fb547e7d160f7b9a789d8a","frame_index":0,"kind":"data","monotonic_ns":228655295211083,"payload":{"event_type":"price_change","market":"0xeb66215f2e9faa6449e30a02bab5b8ed7b79a38bf961f6b24d0073c9c2419250","price_changes":[{"asset_id":"69697746896130839564035629862476347944307040470122503199396727085502753297492","best_ask":"0.4","best_bid":"0.39","hash":"a5d983b21885422089e56def2cd71d9378e75121","price":"0.39","side":"BUY","size":"17.8"},{"asset_id":"60386828328910021732068595344565885737045900010034836345809386672230885527307","best_ask":"0.61","best_bid":"0.6","hash":"2c4b35567d38fe7171b153ccb00de8734f5a7877","price":"0.61","side":"SELL","size":"17.8"}],"timestamp":"1785126666497"},"payload_hash":"d8a3812dd2faf67f7ba5a80c5be503483d3a3159e5acd174f87b94d3b02a1873","raw_frame":"{\"market\":\"0xeb66215f2e9faa6449e30a02bab5b8ed7b79a38bf961f6b24d0073c9c2419250\", \"price_changes\":[{\"asset_id\":\"69697746896130839564035629862476347944307040470122503199396727085502753297492\", \"price\":\"0.39\", \"size\":\"17.8\", \"side\":\"BUY\", \"hash\":\"a5d983b21885422089e56def2cd71d9378e75121\", \"best_bid\":\"0.39\", \"best_ask\":\"0.4\"}, {\"asset_id\":\"60386828328910021732068595344565885737045900010034836345809386672230885527307\", \"price\":\"0.61\", \"size\":\"17.8\", \"side\":\"SELL\", \"hash\":\"2c4b35567d38fe7171b153ccb00de8734f5a7877\", \"best_bid\":\"0.6\", \"best_ask\":\"0.61\"}], \"timestamp\":\"1785126666497\", \"event_type\":\"price_change\"}","received_at":"2026-07-27T04:31:12.025998Z","schema_version":"clob-market-ws.price_change.v1","sequence":null,"server_hash":null,"server_timestamp":"1785126666497","session_id":"e9443c7415a0419799bee9cfbb1a9e4d","source":"clob_market_ws"},"received_at":"2026-07-27T04:31:12.025998Z","record_id":"10c1422287526b82403f04d460e8029b7ffa42ac875c17cc309a2b06ced5e874","schema_fingerprint":"4aa3821a28b0b7c2400bc59aba4bcc0a76e971dadd19610d3ad38c768e124dc7","schema_version":"edge-lab-recorder.raw.v1","sequence":null,"source":"clob_market_ws"}
{"event_at":"2026-07-27T04:31:06.504000Z","event_fingerprint":"c7182080719ac670e970579befcd20915ea1c4def5bbe93c83dc43b309436888","payload":{"connection_id":"0f4979d6978d463e9660b042fdcf555f","event_at":"2026-07-27T04:31:06.504000Z","event_type":"price_change","frame_hash":"e1b69ae08e355ef77c0b32ff990971cd6d84036729579395dbb2dc081c35295e","frame_index":0,"kind":"data","monotonic_ns":228655303570166,"payload":{"event_type":"price_change","market":"0xeb66215f2e9faa6449e30a02bab5b8ed7b79a38bf961f6b24d0073c9c2419250","price_changes":[{"asset_id":"60386828328910021732068595344565885737045900010034836345809386672230885527307","best_ask":"0.61","best_bid":"0.6","hash":"5d25bc961c2c65b56eaa3c45db885b44385c202f","price":"0.6","side":"BUY","size":"68"},{"asset_id":"69697746896130839564035629862476347944307040470122503199396727085502753297492","best_ask":"0.4","best_bid":"0.39","hash":"6723efd12be7da6a4bddf141069e4abf2dee77bd","price":"0.4","side":"SELL","size":"68"}],"timestamp":"1785126666504"},"payload_hash":"27e387679d18f67b4e12e05204ce09edcaa1911bbb830f8c60d351ce5a8e7a7d","raw_frame":"{\"market\":\"0xeb66215f2e9faa6449e30a02bab5b8ed7b79a38bf961f6b24d0073c9c2419250\", \"price_changes\":[{\"asset_id\":\"60386828328910021732068595344565885737045900010034836345809386672230885527307\", \"price\":\"0.6\", \"size\":\"68\", \"side\":\"BUY\", \"hash\":\"5d25bc961c2c65b56eaa3c45db885b44385c202f\", \"best_bid\":\"0.6\", \"best_ask\":\"0.61\"}, {\"asset_id\":\"69697746896130839564035629862476347944307040470122503199396727085502753297492\", \"price\":\"0.4\", \"size\":\"68\", \"side\":\"SELL\", \"hash\":\"6723efd12be7da6a4bddf141069e4abf2dee77bd\", \"best_bid\":\"0.39\", \"best_ask\":\"0.4\"}], \"timestamp\":\"1785126666504\", \"event_type\":\"price_change\"}","received_at":"2026-07-27T04:31:12.034362Z","schema_version":"clob-market-ws.price_change.v1","sequence":null,"server_hash":null,"server_timestamp":"1785126666504","session_id":"e9443c7415a0419799bee9cfbb1a9e4d","source":"clob_market_ws"},"received_at":"2026-07-27T04:31:12.034362Z","record_id":"43c381c7a81aa3f7f26212e9e21c09c3db3091e132b2fe6f94e5794eaf8dec57","schema_fingerprint":"4aa3821a28b0b7c2400bc59aba4bcc0a76e971dadd19610d3ad38c768e124dc7","schema_version":"edge-lab-recorder.raw.v1","sequence":null,"source":"clob_market_ws"}
{"event_at":"2026-07-27T04:31:06.505000Z","event_fingerprint":"750dc5fa06537843b7012cb37bb878ab370804d3d9cfb7864a3a6fb67730bed8","payload":{"connection_id":"0f4979d6978d463e9660b042fdcf555f","event_at":"2026-07-27T04:31:06.505000Z","event_type":"price_change","frame_hash":"37823f13547bc4cff54bbbc3d4d8e349e0fa4fedf6223d35284c316459c05cac","frame_index":0,"kind":"data","monotonic_ns":228655308972291,"payload":{"event_type":"price_change","market":"0xeb66215f2e9faa6449e30a02bab5b8ed7b79a38bf961f6b24d0073c9c2419250","price_changes":[{"asset_id":"60386828328910021732068595344565885737045900010034836345809386672230885527307","best_ask":"0.61","best_bid":"0.6","hash":"b3ac87945455edf8cb456dc8136bf3348f2c05af","price":"0.6","side":"BUY","size":"84.8"},{"asset_id":"69697746896130839564035629862476347944307040470122503199396727085502753297492","best_ask":"0.4","best_bid":"0.39","hash":"9231bda48baded2cf9da9310d17dd8bb7e310b97","price":"0.4","side":"SELL","size":"84.8"}],"timestamp":"1785126666505"},"payload_hash":"bf020468f57ab8118805706fe77893985d4ba000663e64a50b313c6ca73114df","raw_frame":"{\"market\":\"0xeb66215f2e9faa6449e30a02bab5b8ed7b79a38bf961f6b24d0073c9c2419250\", \"price_changes\":[{\"asset_id\":\"60386828328910021732068595344565885737045900010034836345809386672230885527307\", \"price\":\"0.6\", \"size\":\"84.8\", \"side\":\"BUY\", \"hash\":\"b3ac87945455edf8cb456dc8136bf3348f2c05af\", \"best_bid\":\"0.6\", \"best_ask\":\"0.61\"}, {\"asset_id\":\"69697746896130839564035629862476347944307040470122503199396727085502753297492\", \"price\":\"0.4\", \"size\":\"84.8\", \"side\":\"SELL\", \"hash\":\"9231bda48baded2cf9da9310d17dd8bb7e310b97\", \"best_bid\":\"0.39\", \"best_ask\":\"0.4\"}], \"timestamp\":\"1785126666505\", \"event_type\":\"price_change\"}","received_at":"2026-07-27T04:31:12.039760Z","schema_version":"clob-market-ws.price_change.v1","sequence":null,"server_hash":null,"server_timestamp":"1785126666505","session_id":"e9443c7415a0419799bee9cfbb1a9e4d","source":"clob_market_ws"},"received_at":"2026-07-27T04:31:12.039760Z","record_id":"33b43fb33d30a57b55be5b1e6f9d7c92c8b28cf6b9650ebdcb378df2ff7d55cd","schema_fingerprint":"4aa3821a28b0b7c2400bc59aba4bcc0a76e971dadd19610d3ad38c768e124dc7","schema_version":"edge-lab-recorder.raw.v1","sequence":null,"source":"clob_market_ws"}
{"event_at":"2026-07-27T04:31:06.506000Z","event_fingerprint":"2ee49e120b051e48120daa6e11305356eaa26657b99a0c2d66b4094b80ca9ce8","payload":{"connection_id":"0f4979d6978d463e9660b042fdcf555f","event_at":"2026-07-27T04:31:06.506000Z","event_type":"price_change","frame_hash":"76445410aec3a62115ecc4f7c6363d8618c05a5caf9827a43242f29b9f6b84d4","frame_index":0,"kind":"data","monotonic_ns":228655314278083,"payload":{"event_type":"price_change","market":"0xeb66215f2e9faa6449e30a02bab5b8ed7b79a38bf961f6b24d0073c9c2419250","price_changes":[{"asset_id":"69697746896130839564035629862476347944307040470122503199396727085502753297492","best_ask":"0.4","best_bid":"0.39","hash":"f2fe0283f894c53106edd2555c489e48e45bcc69","price":"0.38","side":"BUY","size":"40.52"},{"asset_id":"60386828328910021732068595344565885737045900010034836345809386672230885527307","best_ask":"0.61","best_bid":"0.6","hash":"7705e7a18c88e2cb24add794bb3eedf1ccd992fa","price":"0.62","side":"SELL","size":"40.52"}],"timestamp":"1785126666506"},"payload_hash":"2d1bdd00792c8309fd4ee802cf1907772a2971749ff1bf321431110cf55d1adb","raw_frame":"{\"market\":\"0xeb66215f2e9faa6449e30a02bab5b8ed7b79a38bf961f6b24d0073c9c2419250\", \"price_changes\":[{\"asset_id\":\"69697746896130839564035629862476347944307040470122503199396727085502753297492\", \"price\":\"0.38\", \"size\":\"40.52\", \"side\":\"BUY\", \"hash\":\"f2fe0283f894c53106edd2555c489e48e45bcc69\", \"best_bid\":\"0.39\", \"best_ask\":\"0.4\"}, {\"asset_id\":\"60386828328910021732068595344565885737045900010034836345809386672230885527307\", \"price\":\"0.62\", \"size\":\"40.52\", \"side\":\"SELL\", \"hash\":\"7705e7a18c88e2cb24add794bb3eedf1ccd992fa\", \"best_bid\":\"0.6\", \"best_ask\":\"0.61\"}], \"timestamp\":\"1785126666506\", \"event_type\":\"price_change\"}","received_at":"2026-07-27T04:31:12.045067Z","schema_version":"clob-market-ws.price_change.v1","sequence":null,"server_hash":null,"server_timestamp":"1785126666506","session_id":"e9443c7415a0419799bee9cfbb1a9e4d","source":"clob_market_ws"},"received_at":"2026-07-27T04:31:12.045067Z","record_id":"e1886dee90c34c8d3068a904f4b7b353e554b9d377125227d00f493234dc2e7f","schema_fingerprint":"4aa3821a28b0b7c2400bc59aba4bcc0a76e971dadd19610d3ad38c768e124dc7","schema_version":"edge-lab-recorder.raw.v1","sequence":null,"source":"clob_market_ws"}
{"event_at":"2026-07-27T04:31:06.506000Z","event_fingerprint":"f86b884fff647c6f80cb81786c7bddf20757b1ab0fc7805387eb90f8b07a6811","payload":{"connection_id":"0f4979d6978d463e9660b042fdcf555f","event_at":"2026-07-27T04:31:06.506000Z","event_type":"price_change","frame_hash":"3a0b0380ede2f3a5ec69327660eafc69093235ebf127475415a8608e0ecd9826","frame_index":0,"kind":"data","monotonic_ns":228655322733708,"payload":{"event_type":"price_change","market":"0xeb66215f2e9faa6449e30a02bab5b8ed7b79a38bf961f6b24d0073c9c2419250","price_changes":[{"asset_id":"60386828328910021732068595344565885737045900010034836345809386672230885527307","best_ask":"0.61","best_bid":"0.6","hash":"6c8e77b55aa789c25733eaab932d645757c29521","price":"0.6","side":"BUY","size":"89.97"},{"asset_id":"69697746896130839564035629862476347944307040470122503199396727085502753297492","best_ask":"0.4","best_bid":"0.39","hash":"dc87dfb0eb84e12af29e4ad53464eec998437846","price":"0.4","side":"SELL","size":"89.97"}],"timestamp":"1785126666506"},"payload_hash":"bf3c82a5579ff9143dca81dd4c62ef4b0edb6f1f96c5bdd5585b8315e9c3c33d","raw_frame":"{\"market\":\"0xeb66215f2e9faa6449e30a02bab5b8ed7b79a38bf961f6b24d0073c9c2419250\", \"price_changes\":[{\"asset_id\":\"60386828328910021732068595344565885737045900010034836345809386672230885527307\", \"price\":\"0.6\", \"size\":\"89.97\", \"side\":\"BUY\", \"hash\":\"6c8e77b55aa789c25733eaab932d645757c29521\", \"best_bid\":\"0.6\", \"best_ask\":\"0.61\"}, {\"asset_id\":\"69697746896130839564035629862476347944307040470122503199396727085502753297492\", \"price\":\"0.4\", \"size\":\"89.97\", \"side\":\"SELL\", \"hash\":\"dc87dfb0eb84e12af29e4ad53464eec998437846\", \"best_bid\":\"0.39\", \"best_ask\":\"0.4\"}], \"timestamp\":\"1785126666506\", \"event_type\":\"price_change\"}","received_at":"2026-07-27T04:31:12.053521Z","schema_version":"clob-market-ws.price_change.v1","sequence":null,"server_hash":null,"server_timestamp":"1785126666506","session_id":"e9443c7415a0419799bee9cfbb1a9e4d","source":"clob_market_ws"},"received_at":"2026-07-27T04:31:12.053521Z","record_id":"9342bfe1e359fcf9a04cad5849fb235a61de65012696e1b4afe95dc01e81cadd","schema_fingerprint":"4aa3821a28b0b7c2400bc59aba4bcc0a76e971dadd19610d3ad38c768e124dc7","schema_version":"edge-lab-recorder.raw.v1","sequence":null,"source":"clob_market_ws"}
{"event_at":"2026-07-27T04:31:06.507000Z","event_fingerprint":"e3389de7386dc8d3ba5f8f13fe7e06fa41cc3163e80501ff309003bdb8c2bdcc","payload":{"connection_id":"0f4979d6978d463e9660b042fdcf555f","event_at":"2026-07-27T04:31:06.507000Z","event_type":"price_change","frame_hash":"f3eb7bd14cf7283350deab87b581d7164d2be590c593b8602de0fe6e556d17c0","frame_index":0,"kind":"data","monotonic_ns":228655332215416,"payload":{"event_type":"price_change","market":"0xeb66215f2e9faa6449e30a02bab5b8ed7b79a38bf961f6b24d0073c9c2419250","price_changes":[{"asset_id":"69697746896130839564035629862476347944307040470122503199396727085502753297492","best_ask":"0.4","best_bid":"0.39","hash":"c25f550b02153f06e65c942420543856574e475b","price":"0.34","side":"BUY","size":"60"},{"asset_id":"60386828328910021732068595344565885737045900010034836345809386672230885527307","best_ask":"0.61","best_bid":"0.6","hash":"d242fcfdd68122fe33d3abdff1c895b4407bce2a","price":"0.66","side":"SELL","size":"60"}],"timestamp":"1785126666507"},"payload_hash":"2c6e34f863d7b1c7e12710126ac686b606464b12e55b28efbb127bfa6639aa93","raw_frame":"{\"market\":\"0xeb66215f2e9faa6449e30a02bab5b8ed7b79a38bf961f6b24d0073c9c2419250\", \"price_changes\":[{\"asset_id\":\"69697746896130839564035629862476347944307040470122503199396727085502753297492\", \"price\":\"0.34\", \"size\":\"60\", \"side\":\"BUY\", \"hash\":\"c25f550b02153f06e65c942420543856574e475b\", \"best_bid\":\"0.39\", \"best_ask\":\"0.4\"}, {\"asset_id\":\"60386828328910021732068595344565885737045900010034836345809386672230885527307\", \"price\":\"0.66\", \"size\":\"60\", \"side\":\"SELL\", \"hash\":\"d242fcfdd68122fe33d3abdff1c895b4407bce2a\", \"best_bid\":\"0.6\", \"best_ask\":\"0.61\"}], \"timestamp\":\"1785126666507\", \"event_type\":\"price_change\"}","received_at":"2026-07-27T04:31:12.063003Z","schema_version":"clob-market-ws.price_change.v1","sequence":null,"server_hash":null,"server_timestamp":"1785126666507","session_id":"e9443c7415a0419799bee9cfbb1a9e4d","source":"clob_market_ws"},"received_at":"2026-07-27T04:31:12.063003Z","record_id":"29a282b1d733bf9f973284917860bdd72f517c67edf7f9bdcd3a20691fe54337","schema_fingerprint":"4aa3821a28b0b7c2400bc59aba4bcc0a76e971dadd19610d3ad38c768e124dc7","schema_version":"edge-lab-recorder.raw.v1","sequence":null,"source":"clob_market_ws"}
{"event_at":"2026-07-27T04:31:06.508000Z","event_fingerprint":"c80a636ab457d2bf278b39f5bb1ace86962660b392b4e9efe7ea9e5bb4f7ad31","payload":{"connection_id":"0f4979d6978d463e9660b042fdcf555f","event_at":"2026-07-27T04:31:06.508000Z","event_type":"price_change","frame_hash":"e18caa12ee2073582b6ac55743ef3811398f7ccb8755d32f893b0d0cddf8715f","frame_index":0,"kind":"data","monotonic_ns":228655342204291,"payload":{"event_type":"price_change","market":"0xeb66215f2e9faa6449e30a02bab5b8ed7b79a38bf961f6b24d0073c9c2419250","price_changes":[{"asset_id":"60386828328910021732068595344565885737045900010034836345809386672230885527307","best_ask":"0.61","best_bid":"0.6","hash":"b667d46c6161f3ed3a8e7afd3998afbb4d915ecb","price":"0.57","side":"BUY","size":"35.4"},{"asset_id":"69697746896130839564035629862476347944307040470122503199396727085502753297492","best_ask":"0.4","best_bid":"0.39","hash":"cfbbdaca093d1019f48851c916b56a060fa53c7c","price":"0.43","side":"SELL","size":"35.4"}],"timestamp":"1785126666508"},"payload_hash":"3226b2404c4790187626e66ea28a5aa13fda6776bea40c731493697313ca7aab","raw_frame":"{\"market\":\"0xeb66215f2e9faa6449e30a02bab5b8ed7b79a38bf961f6b24d0073c9c2419250\", \"price_changes\":[{\"asset_id\":\"60386828328910021732068595344565885737045900010034836345809386672230885527307\", \"price\":\"0.57\", \"size\":\"35.4\", \"side\":\"BUY\", \"hash\":\"b667d46c6161f3ed3a8e7afd3998afbb4d915ecb\", \"best_bid\":\"0.6\", \"best_ask\":\"0.61\"}, {\"asset_id\":\"69697746896130839564035629862476347944307040470122503199396727085502753297492\", \"price\":\"0.43\", \"size\":\"35.4\", \"side\":\"SELL\", \"hash\":\"cfbbdaca093d1019f48851c916b56a060fa53c7c\", \"best_bid\":\"0.39\", \"best_ask\":\"0.4\"}], \"timestamp\":\"1785126666508\", \"event_type\":\"price_change\"}","received_at":"2026-07-27T04:31:12.072988Z","schema_version":"clob-market-ws.price_change.v1","sequence":null,"server_hash":null,"server_timestamp":"1785126666508","session_id":"e9443c7415a0419799bee9cfbb1a9e4d","source":"clob_market_ws"},"received_at":"2026-07-27T04:31:12.072988Z","record_id":"a8a147b6f401d8275b0aefec160b16518bbe9ed39447aa0fdc6e2a0f300c8cf9","schema_fingerprint":"4aa3821a28b0b7c2400bc59aba4bcc0a76e971dadd19610d3ad38c768e124dc7","schema_version":"edge-lab-recorder.raw.v1","sequence":null,"source":"clob_market_ws"}
{"event_at":"2026-07-27T04:31:06.509000Z","event_fingerprint":"f75a83f9d952a6e73ffe2c571c429eee35e18d6670e89dccf225d0f42d43d886","payload":{"connection_id":"0f4979d6978d463e9660b042fdcf555f","event_at":"2026-07-27T04:31:06.509000Z","event_type":"price_change","frame_hash":"3aa2250ab7711133be67c6ab135bf2ec5c24222a7509377289a4a3ae62faef86","frame_index":0,"kind":"data","monotonic_ns":228655349962958,"payload":{"event_type":"price_change","market":"0xeb66215f2e9faa6449e30a02bab5b8ed7b79a38bf961f6b24d0073c9c2419250","price_changes":[{"asset_id":"60386828328910021732068595344565885737045900010034836345809386672230885527307","best_ask":"0.61","best_bid":"0.6","hash":"1dbc5ee310879a5b056f9e9a78013ea614f72f31","price":"0.59","side":"BUY","size":"59.4"},{"asset_id":"69697746896130839564035629862476347944307040470122503199396727085502753297492","best_ask":"0.4","best_bid":"0.39","hash":"69a4d99d1b8911bc24ef8df6fad3406bbb6be222","price":"0.41","side":"SELL","size":"59.4"}],"timestamp":"1785126666509"},"payload_hash":"b85e64632ba1a95d0c01623bdb1f625a6ac6886671dc830ba86a9a70d4da238e","raw_frame":"{\"market\":\"0xeb66215f2e9faa6449e30a02bab5b8ed7b79a38bf961f6b24d0073c9c2419250\", \"price_changes\":[{\"asset_id\":\"60386828328910021732068595344565885737045900010034836345809386672230885527307\", \"price\":\"0.59\", \"size\":\"59.4\", \"side\":\"BUY\", \"hash\":\"1dbc5ee310879a5b056f9e9a78013ea614f72f31\", \"best_bid\":\"0.6\", \"best_ask\":\"0.61\"}, {\"asset_id\":\"69697746896130839564035629862476347944307040470122503199396727085502753297492\", \"price\":\"0.41\", \"size\":\"59.4\", \"side\":\"SELL\", \"hash\":\"69a4d99d1b8911bc24ef8df6fad3406bbb6be222\", \"best_bid\":\"0.39\", \"best_ask\":\"0.4\"}], \"timestamp\":\"1785126666509\", \"event_type\":\"price_change\"}","received_at":"2026-07-27T04:31:12.080752Z","schema_version":"clob-market-ws.price_change.v1","sequence":null,"server_hash":null,"server_timestamp":"1785126666509","session_id":"e9443c7415a0419799bee9cfbb1a9e4d","source":"clob_market_ws"},"received_at":"2026-07-27T04:31:12.080752Z","record_id":"ed6b97fb6e3994977ea5eed5a71c0debf9b2ee8eb54227814d08d92a077e8b5b","schema_fingerprint":"4aa3821a28b0b7c2400bc59aba4bcc0a76e971dadd19610d3ad38c768e124dc7","schema_version":"edge-lab-recorder.raw.v1","sequence":null,"source":"clob_market_ws"}
{"event_at":"2026-07-27T04:31:06.510000Z","event_fingerprint":"7ab8b6a2be8e33853a84ad194e15cc6600ac03caa7d2ab74943b6d7961ea13fc","payload":{"connection_id":"0f4979d6978d463e9660b042fdcf555f","event_at":"2026-07-27T04:31:06.510000Z","event_type":"price_change","frame_hash":"2fd802657f403fd43d1b36aad12e512d1b35aad3e1bcadb592e3ef2799b1b61d","frame_index":0,"kind":"data","monotonic_ns":228655358548958,"payload":{"event_type":"price_change","market":"0xeb66215f2e9faa6449e30a02bab5b8ed7b79a38bf961f6b24d0073c9c2419250","price_changes":[{"asset_id":"60386828328910021732068595344565885737045900010034836345809386672230885527307","best_ask":"0.61","best_bid":"0.6","hash":"bcea3a02400b23850c161716d15e014381bb9d1e","price":"0.6","side":"BUY","size":"95.14"},{"asset_id":"69697746896130839564035629862476347944307040470122503199396727085502753297492","best_ask":"0.4","best_bid":"0.39","hash":"9e3f831054eefcc0d7ef46da72a05bf6bdfe678c","price":"0.4","side":"SELL","size":"95.14"}],"timestamp":"1785126666510"},"payload_hash":"ba700eb68f5a796cb6dabbe02f5833151fd50bd4b18fde64dc5d73fdef5aa8de","raw_frame":"{\"market\":\"0xeb66215f2e9faa6449e30a02bab5b8ed7b79a38bf961f6b24d0073c9c2419250\", \"price_changes\":[{\"asset_id\":\"60386828328910021732068595344565885737045900010034836345809386672230885527307\", \"price\":\"0.6\", \"size\":\"95.14\", \"side\":\"BUY\", \"hash\":\"bcea3a02400b23850c161716d15e014381bb9d1e\", \"best_bid\":\"0.6\", \"best_ask\":\"0.61\"}, {\"asset_id\":\"69697746896130839564035629862476347944307040470122503199396727085502753297492\", \"price\":\"0.4\", \"size\":\"95.14\", \"side\":\"SELL\", \"hash\":\"9e3f831054eefcc0d7ef46da72a05bf6bdfe678c\", \"best_bid\":\"0.39\", \"best_ask\":\"0.4\"}], \"timestamp\":\"1785126666510\", \"event_type\":\"price_change\"}","received_at":"2026-07-27T04:31:12.089337Z","schema_version":"clob-market-ws.price_change.v1","sequence":null,"server_hash":null,"server_timestamp":"1785126666510","session_id":"e9443c7415a0419799bee9cfbb1a9e4d","source":"clob_market_ws"},"received_at":"2026-07-27T04:31:12.089337Z","record_id":"cfbe0832ef26579a99b3b33e3c54b4520ed408e10b30106845f84488b0616855","schema_fingerprint":"4aa3821a28b0b7c2400bc59aba4bcc0a76e971dadd19610d3ad38c768e124dc7","schema_version":"edge-lab-recorder.raw.v1","sequence":null,"source":"clob_market_ws"}
{"event_at":"2026-07-27T04:31:06.511000Z","event_fingerprint":"a6537ab3d1e3480602d602e9d67c1703f5c03531ac968decd3c0dc6c29f705f9","payload":{"connection_id":"0f4979d6978d463e9660b042fdcf555f","event_at":"2026-07-27T04:31:06.511000Z","event_type":"price_change","frame_hash":"331612ebcc702df0f94ef67482302e59f454ea3e144c73b7d2f2087765c3f44e","frame_index":0,"kind":"data","monotonic_ns":228655364830291,"payload":{"event_type":"price_change","market":"0xeb66215f2e9faa6449e30a02bab5b8ed7b79a38bf961f6b24d0073c9c2419250","price_changes":[{"asset_id":"60386828328910021732068595344565885737045900010034836345809386672230885527307","best_ask":"0.61","best_bid":"0.6","hash":"b1042b499916b08542a1a79f055b1bf7c164c2b6","price":"0.6","side":"BUY","size":"104.74"},{"asset_id":"69697746896130839564035629862476347944307040470122503199396727085502753297492","best_ask":"0.4","best_bid":"0.39","hash":"8708bb16fef0f806437a98dc0bd1f7b644c32759","price":"0.4","side":"SELL","size":"104.74"}],"timestamp":"1785126666511"},"payload_hash":"504f0680c1e9c19a06a108f93132fa7fa58d803cf4b585cfcbaa3ce419fd3c24","raw_frame":"{\"market\":\"0xeb66215f2e9faa6449e30a02bab5b8ed7b79a38bf961f6b24d0073c9c2419250\", \"price_changes\":[{\"asset_id\":\"60386828328910021732068595344565885737045900010034836345809386672230885527307\", \"price\":\"0.6\", \"size\":\"104.74\", \"side\":\"BUY\", \"hash\":\"b1042b499916b08542a1a79f055b1bf7c164c2b6\", \"best_bid\":\"0.6\", \"best_ask\":\"0.61\"}, {\"asset_id\":\"69697746896130839564035629862476347944307040470122503199396727085502753297492\", \"price\":\"0.4\", \"size\":\"104.74\", \"side\":\"SELL\", \"hash\":\"8708bb16fef0f806437a98dc0bd1f7b644c32759\", \"best_bid\":\"0.39\", \"best_ask\":\"0.4\"}], \"timestamp\":\"1785126666511\", \"event_type\":\"price_change\"}","received_at":"2026-07-27T04:31:12.095618Z","schema_version":"clob-market-ws.price_change.v1","sequence":null,"server_hash":null,"server_timestamp":"1785126666511","session_id":"e9443c7415a0419799bee9cfbb1a9e4d","source":"clob_market_ws"},"received_at":"2026-07-27T04:31:12.095618Z","record_id":"f60992493654793808cf0047ef22726a29f76a401846e4f3a97b064cface3b87","schema_fingerprint":"4aa3821a28b0b7c2400bc59aba4bcc0a76e971dadd19610d3ad38c768e124dc7","schema_version":"edge-lab-recorder.raw.v1","sequence":null,"source":"clob_market_ws"}
{"event_at":"2026-07-27T04:31:06.511000Z","event_fingerprint":"a4a763c93215202e8cb0557b651743bfdedf9021686c88dc79337c1b95551a5a","payload":{"connection_id":"0f4979d6978d463e9660b042fdcf555f","event_at":"2026-07-27T04:31:06.511000Z","event_type":"price_change","frame_hash":"9756eadbf328024bf03288efc3f41d913729622984fbc18561c7970b939d5468","frame_index":0,"kind":"data","monotonic_ns":228655370563375,"payload":{"event_type":"price_change","market":"0xeb66215f2e9faa6449e30a02bab5b8ed7b79a38bf961f6b24d0073c9c2419250","price_changes":[{"asset_id":"60386828328910021732068595344565885737045900010034836345809386672230885527307","best_ask":"0.61","best_bid":"0.6","hash":"901123b32518de7a95c92e06ed5d1d576dea5ba0","price":"0.31","side":"BUY","size":"20"},{"asset_id":"69697746896130839564035629862476347944307040470122503199396727085502753297492","best_ask":"0.4","best_bid":"0.39","hash":"8c37f1954374f506d888043390e877389f291a66","price":"0.69","side":"SELL","size":"20"}],"timestamp":"1785126666511"},"payload_hash":"a4e4fe1f641211fe5ea10c68d06156de4e78067cacbb9324ef98fb33d222a1fa","raw_frame":"{\"market\":\"0xeb66215f2e9faa6449e30a02bab5b8ed7b79a38bf961f6b24d0073c9c2419250\", \"price_changes\":[{\"asset_id\":\"60386828328910021732068595344565885737045900010034836345809386672230885527307\", \"price\":\"0.31\", \"size\":\"20\", \"side\":\"BUY\", \"hash\":\"901123b32518de7a95c92e06ed5d1d576dea5ba0\", \"best_bid\":\"0.6\", \"best_ask\":\"0.61\"}, {\"asset_id\":\"69697746896130839564035629862476347944307040470122503199396727085502753297492\", \"price\":\"0.69\", \"size\":\"20\", \"side\":\"SELL\", \"hash\":\"8c37f1954374f506d888043390e877389f291a66\", \"best_bid\":\"0.39\", \"best_ask\":\"0.4\"}], \"timestamp\":\"1785126666511\", \"event_type\":\"price_change\"}","received_at":"2026-07-27T04:31:12.101352Z","schema_version":"clob-market-ws.price_change.v1","sequence":null,"server_hash":null,"server_timestamp":"1785126666511","session_id":"e9443c7415a0419799bee9cfbb1a9e4d","source":"clob_market_ws"},"received_at":"2026-07-27T04:31:12.101352Z","record_id":"fe09058a1652c9382a4803f89fb609f39077f8b03af8ce7e6d65011363dae651","schema_fingerprint":"4aa3821a28b0b7c2400bc59aba4bcc0a76e971dadd19610d3ad38c768e124dc7","schema_version":"edge-lab-recorder.raw.v1","sequence":null,"source":"clob_market_ws"}
{"event_at":"2026-07-27T04:31:06.511000Z","event_fingerprint":"c32b390fd98adf6d68ea859d0062afdb801c8cbea0bafb7351da991eb842cb27","payload":{"connection_id":"0f4979d6978d463e9660b042fdcf555f","event_at":"2026-07-27T04:31:06.511000Z","event_type":"price_change","frame_hash":"e98367227f346c2df9c467b6fd1844b8fa39bd5e2d1f4c9ab27b2e6cb0161da0","frame_index":0,"kind":"data","monotonic_ns":228655378791416,"payload":{"event_type":"price_change","market":"0xeb66215f2e9faa6449e30a02bab5b8ed7b79a38bf961f6b24d0073c9c2419250","price_changes":[{"asset_id":"60386828328910021732068595344565885737045900010034836345809386672230885527307","best_ask":"0.61","best_bid":"0.6","hash":"f0e527e02e93afd7f3f0c7409a92e156867a6e51","price":"0.6","side":"BUY","size":"109.74"},{"asset_id":"69697746896130839564035629862476347944307040470122503199396727085502753297492","best_ask":"0.4","best_bid":"0.39","hash":"829e53a12627f377f6db66dd45c310b6ee5673ac","price":"0.4","side":"SELL","size":"109.74"}],"timestamp":"1785126666511"},"payload_hash":"0ba933a0aef3852fe9a9e5d8b40da8d16c17b32478bef5fa61a611ff184f073f","raw_frame":"{\"market\":\"0xeb66215f2e9faa6449e30a02bab5b8ed7b79a38bf961f6b24d0073c9c2419250\", \"price_changes\":[{\"asset_id\":\"60386828328910021732068595344565885737045900010034836345809386672230885527307\", \"price\":\"0.6\", \"size\":\"109.74\", \"side\":\"BUY\", \"hash\":\"f0e527e02e93afd7f3f0c7409a92e156867a6e51\", \"best_bid\":\"0.6\", \"best_ask\":\"0.61\"}, {\"asset_id\":\"69697746896130839564035629862476347944307040470122503199396727085502753297492\", \"price\":\"0.4\", \"size\":\"109.74\", \"side\":\"SELL\", \"hash\":\"829e53a12627f377f6db66dd45c310b6ee5673ac\", \"best_bid\":\"0.39\", \"best_ask\":\"0.4\"}], \"timestamp\":\"1785126666511\", \"event_type\":\"price_change\"}","received_at":"2026-07-27T04:31:12.109580Z","schema_version":"clob-market-ws.price_change.v1","sequence":null,"server_hash":null,"server_timestamp":"1785126666511","session_id":"e9443c7415a0419799bee9cfbb1a9e4d","source":"clob_market_ws"},"received_at":"2026-07-27T04:31:12.109580Z","record_id":"a71523ee8bcffe76d715c4024a2b9177073d40a23db84ddebca85f99d90965f5","schema_fingerprint":"4aa3821a28b0b7c2400bc59aba4bcc0a76e971dadd19610d3ad38c768e124dc7","schema_version":"edge-lab-recorder.raw.v1","sequence":null,"source":"clob_market_ws"}
{"event_at":"2026-07-27T04:31:06.512000Z","event_fingerprint":"6c43c01489da4c8db7b6a79d530608612b848cabf636106cb0e34492e6b1201f","payload":{"connection_id":"0f4979d6978d463e9660b042fdcf555f","event_at":"2026-07-27T04:31:06.512000Z","event_type":"price_change","frame_hash":"599b9a149166dd6a1865736edeae146d7477f94436b579a8db33f2a80b41c846","frame_index":0,"kind":"data","monotonic_ns":228655387315666,"payload":{"event_type":"price_change","market":"0xeb66215f2e9faa6449e30a02bab5b8ed7b79a38bf961f6b24d0073c9c2419250","price_changes":[{"asset_id":"69697746896130839564035629862476347944307040470122503199396727085502753297492","best_ask":"0.4","best_bid":"0.39","hash":"47d7453753d39af3899f127ba8feb644baea8c73","price":"0.41","side":"SELL","size":"54.4"},{"asset_id":"60386828328910021732068595344565885737045900010034836345809386672230885527307","best_ask":"0.61","best_bid":"0.6","hash":"5018e5f1a25421bfb5d19288c7e59d8414287c3a","price":"0.59","side":"BUY","size":"54.4"}],"timestamp":"1785126666512"},"payload_hash":"20a8062e28ef78875b717baafafc944cd80c4eebaae30b09f8a3879bcef0fd7d","raw_frame":"{\"market\":\"0xeb66215f2e9faa6449e30a02bab5b8ed7b79a38bf961f6b24d0073c9c2419250\", \"price_changes\":[{\"asset_id\":\"69697746896130839564035629862476347944307040470122503199396727085502753297492\", \"price\":\"0.41\", \"size\":\"54.4\", \"side\":\"SELL\", \"hash\":\"47d7453753d39af3899f127ba8feb644baea8c73\", \"best_bid\":\"0.39\", \"best_ask\":\"0.4\"}, {\"asset_id\":\"60386828328910021732068595344565885737045900010034836345809386672230885527307\", \"price\":\"0.59\", \"size\":\"54.4\", \"side\":\"BUY\", \"hash\":\"5018e5f1a25421bfb5d19288c7e59d8414287c3a\", \"best_bid\":\"0.6\", \"best_ask\":\"0.61\"}], \"timestamp\":\"1785126666512\", \"event_type\":\"price_change\"}","received_at":"2026-07-27T04:31:12.118104Z","schema_version":"clob-market-ws.price_change.v1","sequence":null,"server_hash":null,"server_timestamp":"1785126666512","session_id":"e9443c7415a0419799bee9cfbb1a9e4d","source":"clob_market_ws"},"received_at":"2026-07-27T04:31:12.118104Z","record_id":"396b215ffeec207f04488be8b16db03aeb8915eaea909374d5d9a518ba11c15d","schema_fingerprint":"4aa3821a28b0b7c2400bc59aba4bcc0a76e971dadd19610d3ad38c768e124dc7","schema_version":"edge-lab-recorder.raw.v1","sequence":null,"source":"clob_market_ws"}
{"event_at":"2026-07-27T04:31:06.512000Z","event_fingerprint":"35b194cead7df012a297ba2d071f4cd63b1a5c476fd99f8c995fbd2a2363c4f4","payload":{"connection_id":"0f4979d6978d463e9660b042fdcf555f","event_at":"2026-07-27T04:31:06.512000Z","event_type":"price_change","frame_hash":"703612dc10e1cf4c74806acacb01a6e0d5973c3fa9dfa9b41da66c727fdec980","frame_index":0,"kind":"data","monotonic_ns":228655392591708,"payload":{"event_type":"price_change","market":"0xeb66215f2e9faa6449e30a02bab5b8ed7b79a38bf961f6b24d0073c9c2419250","price_changes":[{"asset_id":"69697746896130839564035629862476347944307040470122503199396727085502753297492","best_ask":"0.4","best_bid":"0.39","hash":"0798786da02ae7d736071d2613004e202971034f","price":"0.41","side":"SELL","size":"49.4"},{"asset_id":"60386828328910021732068595344565885737045900010034836345809386672230885527307","best_ask":"0.61","best_bid":"0.6","hash":"238f79a4efbf0c730682bf5f2acff68df8363002","price":"0.59","side":"BUY","size":"49.4"}],"timestamp":"1785126666512"},"payload_hash":"6b2b87668910b085aa77cb0ec88e3a5e3bac04b9c0ce4fb1d2091c9f3416b2bc","raw_frame":"{\"market\":\"0xeb66215f2e9faa6449e30a02bab5b8ed7b79a38bf961f6b24d0073c9c2419250\", \"price_changes\":[{\"asset_id\":\"69697746896130839564035629862476347944307040470122503199396727085502753297492\", \"price\":\"0.41\", \"size\":\"49.4\", \"side\":\"SELL\", \"hash\":\"0798786da02ae7d736071d2613004e202971034f\", \"best_bid\":\"0.39\", \"best_ask\":\"0.4\"}, {\"asset_id\":\"60386828328910021732068595344565885737045900010034836345809386672230885527307\", \"price\":\"0.59\", \"size\":\"49.4\", \"side\":\"BUY\", \"hash\":\"238f79a4efbf0c730682bf5f2acff68df8363002\", \"best_bid\":\"0.6\", \"best_ask\":\"0.61\"}], \"timestamp\":\"1785126666512\", \"event_type\":\"price_change\"}","received_at":"2026-07-27T04:31:12.123375Z","schema_version":"clob-market-ws.price_change.v1","sequence":null,"server_hash":null,"server_timestamp":"1785126666512","session_id":"e9443c7415a0419799bee9cfbb1a9e4d","source":"clob_market_ws"},"received_at":"2026-07-27T04:31:12.123375Z","record_id":"7ef6ebd60aaef474eadc041fde61d9491e622abc276c1c19705b158f41478be0","schema_fingerprint":"4aa3821a28b0b7c2400bc59aba4bcc0a76e971dadd19610d3ad38c768e124dc7","schema_version":"edge-lab-recorder.raw.v1","sequence":null,"source":"clob_market_ws"}
{"event_at":"2026-07-27T04:31:06.513000Z","event_fingerprint":"fb8e1f2654ac453ce92bc6734ff9403491e012a09cae8d67fc59b59e7c4d3eb6","payload":{"connection_id":"0f4979d6978d463e9660b042fdcf555f","event_at":"2026-07-27T04:31:06.513000Z","event_type":"price_change","frame_hash":"c3b54b3968f0f54ce97912e405268c30cfc14de8b5f90a9c731c7b04711b60c0","frame_index":0,"kind":"data","monotonic_ns":228655400657916,"payload":{"event_type":"price_change","market":"0xeb66215f2e9faa6449e30a02bab5b8ed7b79a38bf961f6b24d0073c9c2419250","price_changes":[{"asset_id":"60386828328910021732068595344565885737045900010034836345809386672230885527307","best_ask":"0.61","best_bid":"0.6","hash":"0aedca95cf419e2127b9425b554bce2f340a16f4","price":"0.57","side":"BUY","size":"40.4"},{"asset_id":"69697746896130839564035629862476347944307040470122503199396727085502753297492","best_ask":"0.4","best_bid":"0.39","hash":"da3a7b41d4249f07b60dc647f3f255d4a9f8abc0","price":"0.43","side":"SELL","size":"40.4"}],"timestamp":"1785126666513"},"payload_hash":"437a3e64019eabc89eab82171293da95c7e48465fcddf1708a2dc4d479945c1b","raw_frame":"{\"market\":\"0xeb66215f2e9faa6449e30a02bab5b8ed7b79a38bf961f6b24d0073c9c2419250\", \"price_changes\":[{\"asset_id\":\"60386828328910021732068595344565885737045900010034836345809386672230885527307\", \"price\":\"0.57\", \"size\":\"40.4\", \"side\":\"BUY\", \"hash\":\"0aedca95cf419e2127b9425b554bce2f340a16f4\", \"best_bid\":\"0.6\", \"best_ask\":\"0.61\"}, {\"asset_id\":\"69697746896130839564035629862476347944307040470122503199396727085502753297492\", \"price\":\"0.43\", \"size\":\"40.4\", \"side\":\"SELL\", \"hash\":\"da3a7b41d4249f07b60dc647f3f255d4a9f8abc0\", \"best_bid\":\"0.39\", \"best_ask\":\"0.4\"}], \"timestamp\":\"1785126666513\", \"event_type\":\"price_change\"}","received_at":"2026-07-27T04:31:12.131447Z","schema_version":"clob-market-ws.price_change.v1","sequence":null,"server_hash":null,"server_timestamp":"1785126666513","session_id":"e9443c7415a0419799bee9cfbb1a9e4d","source":"clob_market_ws"},"received_at":"2026-07-27T04:31:12.131447Z","record_id":"bbd4975a46c2de5db0e28f757747ba529148a3e13b7fc15da2e95ea956609523","schema_fingerprint":"4aa3821a28b0b7c2400bc59aba4bcc0a76e971dadd19610d3ad38c768e124dc7","schema_version":"edge-lab-recorder.raw.v1","sequence":null,"source":"clob_market_ws"}
{"event_at":"2026-07-27T04:31:06.514000Z","event_fingerprint":"dd20a79596c6b790fd3f54e6a359e3d4a1840029275a0d0ad028d49c5599706d","payload":{"connection_id":"0f4979d6978d463e9660b042fdcf555f","event_at":"2026-07-27T04:31:06.514000Z","event_type":"price_change","frame_hash":"4a33af9a749e1c5b9ba354549843306aee312ae188cc194b32ac5e5cc71681e1","frame_index":0,"kind":"data","monotonic_ns":228655411151541,"payload":{"event_type":"price_change","market":"0xeb66215f2e9faa6449e30a02bab5b8ed7b79a38bf961f6b24d0073c9c2419250","price_changes":[{"asset_id":"69697746896130839564035629862476347944307040470122503199396727085502753297492","best_ask":"0.4","best_bid":"0.39","hash":"a9c36a7636e9628539fcaa2f366c6bd782aa4beb","price":"0.39","side":"BUY","size":"5"},{"asset_id":"60386828328910021732068595344565885737045900010034836345809386672230885527307","best_ask":"0.61","best_bid":"0.6","hash":"e3f1cd84d1a6460a0398fcf4960812978f3ce999","price":"0.61","side":"SELL","size":"5"}],"timestamp":"1785126666514"},"payload_hash":"35638c55252e1176383f6a6e2132b153915492fe0b50adc757a84c6d57888bbb","raw_frame":"{\"market\":\"0xeb66215f2e9faa6449e30a02bab5b8ed7b79a38bf961f6b24d0073c9c2419250\", \"price_changes\":[{\"asset_id\":\"69697746896130839564035629862476347944307040470122503199396727085502753297492\", \"price\":\"0.39\", \"size\":\"5\", \"side\":\"BUY\", \"hash\":\"a9c36a7636e9628539fcaa2f366c6bd782aa4beb\", \"best_bid\":\"0.39\", \"best_ask\":\"0.4\"}, {\"asset_id\":\"60386828328910021732068595344565885737045900010034836345809386672230885527307\", \"price\":\"0.61\", \"size\":\"5\", \"side\":\"SELL\", \"hash\":\"e3f1cd84d1a6460a0398fcf4960812978f3ce999\", \"best_bid\":\"0.6\", \"best_ask\":\"0.61\"}], \"timestamp\":\"1785126666514\", \"event_type\":\"price_change\"}","received_at":"2026-07-27T04:31:12.141939Z","schema_version":"clob-market-ws.price_change.v1","sequence":null,"server_hash":null,"server_timestamp":"1785126666514","session_id":"e9443c7415a0419799bee9cfbb1a9e4d","source":"clob_market_ws"},"received_at":"2026-07-27T04:31:12.141939Z","record_id":"0547fd9cf21f01b9eb1160987ed8ca95a83e6c6096c5691d660db06db9e3ffef","schema_fingerprint":"4aa3821a28b0b7c2400bc59aba4bcc0a76e971dadd19610d3ad38c768e124dc7","schema_version":"edge-lab-recorder.raw.v1","sequence":null,"source":"clob_market_ws"}
{"event_at":"2026-07-27T04:31:06.514000Z","event_fingerprint":"4e9f30a806c2011fc6fda2018531ee991b99748c58d0361196572e412a008f02","payload":{"connection_id":"0f4979d6978d463e9660b042fdcf555f","event_at":"2026-07-27T04:31:06.514000Z","event_type":"price_change","frame_hash":"685e8c8b9933b2105a6976b151a87040cc8c4b6f13ad10cf6b7889defecf001f","frame_index":0,"kind":"data","monotonic_ns":228655416238625,"payload":{"event_type":"price_change","market":"0xeb66215f2e9faa6449e30a02bab5b8ed7b79a38bf961f6b24d0073c9c2419250","price_changes":[{"asset_id":"69697746896130839564035629862476347944307040470122503199396727085502753297492","best_ask":"0.4","best_bid":"0.39","hash":"a9c36a7636e9628539fcaa2f366c6bd782aa4beb","price":"0.38","side":"BUY","size":"27.6"},{"asset_id":"60386828328910021732068595344565885737045900010034836345809386672230885527307","best_ask":"0.61","best_bid":"0.6","hash":"e3f1cd84d1a6460a0398fcf4960812978f3ce999","price":"0.62","side":"SELL","size":"27.6"}],"timestamp":"1785126666514"},"payload_hash":"4dee31cfb78eba4a952323ce0f069146e44e065e37cbc4ef3c917d0778774d62","raw_frame":"{\"market\":\"0xeb66215f2e9faa6449e30a02bab5b8ed7b79a38bf961f6b24d0073c9c2419250\", \"price_changes\":[{\"asset_id\":\"69697746896130839564035629862476347944307040470122503199396727085502753297492\", \"price\":\"0.38\", \"size\":\"27.6\", \"side\":\"BUY\", \"hash\":\"a9c36a7636e9628539fcaa2f366c6bd782aa4beb\", \"best_bid\":\"0.39\", \"best_ask\":\"0.4\"}, {\"asset_id\":\"60386828328910021732068595344565885737045900010034836345809386672230885527307\", \"price\":\"0.62\", \"size\":\"27.6\", \"side\":\"SELL\", \"hash\":\"e3f1cd84d1a6460a0398fcf4960812978f3ce999\", \"best_bid\":\"0.6\", \"best_ask\":\"0.61\"}], \"timestamp\":\"1785126666514\", \"event_type\":\"price_change\"}","received_at":"2026-07-27T04:31:12.147027Z","schema_version":"clob-market-ws.price_change.v1","sequence":null,"server_hash":null,"server_timestamp":"1785126666514","session_id":"e9443c7415a0419799bee9cfbb1a9e4d","source":"clob_market_ws"},"received_at":"2026-07-27T04:31:12.147027Z","record_id":"4e44bb729240749c2ca0f14bdd836c273387f9680d1ef2ffa845e19658f0ea24","schema_fingerprint":"4aa3821a28b0b7c2400bc59aba4bcc0a76e971dadd19610d3ad38c768e124dc7","schema_version":"edge-lab-recorder.raw.v1","sequence":null,"source":"clob_market_ws"}
{"event_at":"2026-07-27T04:31:06.514000Z","event_fingerprint":"0228699f7a0edc2d836bf079a810f1de7158940467a6cd815d9a75faee471510","payload":{"connection_id":"0f4979d6978d463e9660b042fdcf555f","event_at":"2026-07-27T04:31:06.514000Z","event_type":"price_change","frame_hash":"e6a9162ab7144bf666bbc75104fa4074324fe13b822f7bbaa7aa56692d716935","frame_index":0,"kind":"data","monotonic_ns":228655422314250,"payload":{"event_type":"price_change","market":"0xeb66215f2e9faa6449e30a02bab5b8ed7b79a38bf961f6b24d0073c9c2419250","price_changes":[{"asset_id":"69697746896130839564035629862476347944307040470122503199396727085502753297492","best_ask":"0.4","best_bid":"0.39","hash":"a9c36a7636e9628539fcaa2f366c6bd782aa4beb","price":"0.37","side":"BUY","size":"19"},{"asset_id":"60386828328910021732068595344565885737045900010034836345809386672230885527307","best_ask":"0.61","best_bid":"0.6","hash":"e3f1cd84d1a6460a0398fcf4960812978f3ce999","price":"0.63","side":"SELL","size":"19"}],"timestamp":"1785126666514"},"payload_hash":"903693639650066bec5db677074f25f9312fa57058a3fdedc7d2a9596de0c2eb","raw_frame":"{\"market\":\"0xeb66215f2e9faa6449e30a02bab5b8ed7b79a38bf961f6b24d0073c9c2419250\", \"price_changes\":[{\"asset_id\":\"69697746896130839564035629862476347944307040470122503199396727085502753297492\", \"price\":\"0.37\", \"size\":\"19\", \"side\":\"BUY\", \"hash\":\"a9c36a7636e9628539fcaa2f366c6bd782aa4beb\", \"best_bid\":\"0.39\", \"best_ask\":\"0.4\"}, {\"asset_id\":\"60386828328910021732068595344565885737045900010034836345809386672230885527307\", \"price\":\"0.63\", \"size\":\"19\", \"side\":\"SELL\", \"hash\":\"e3f1cd84d1a6460a0398fcf4960812978f3ce999\", \"best_bid\":\"0.6\", \"best_ask\":\"0.61\"}], \"timestamp\":\"1785126666514\", \"event_type\":\"price_change\"}","received_at":"2026-07-27T04:31:12.153100Z","schema_version":"clob-market-ws.price_change.v1","sequence":null,"server_hash":null,"server_timestamp":"1785126666514","session_id":"e9443c7415a0419799bee9cfbb1a9e4d","source":"clob_market_ws"},"received_at":"2026-07-27T04:31:12.153100Z","record_id":"a856a37b51776d6c1748009be17fded218c60d3ae92e96570a86957e2353e5c7","schema_fingerprint":"4aa3821a28b0b7c2400bc59aba4bcc0a76e971dadd19610d3ad38c768e124dc7","schema_version":"edge-lab-recorder.raw.v1","sequence":null,"source":"clob_market_ws"}
{"event_at":"2026-07-27T04:31:06.514000Z","event_fingerprint":"5c2618bae752bcdb953fd7a9fb00f9f33ca91786e1650f233c556a35bf76f024","payload":{"connection_id":"0f4979d6978d463e9660b042fdcf555f","event_at":"2026-07-27T04:31:06.514000Z","event_type":"price_change","frame_hash":"b57f84b3333de87c2d0770d6e6b5a2d0b0bb713bbfe70840d9439474103caf72","frame_index":0,"kind":"data","monotonic_ns":228655430257291,"payload":{"event_type":"price_change","market":"0xeb66215f2e9faa6449e30a02bab5b8ed7b79a38bf961f6b24d0073c9c2419250","price_changes":[{"asset_id":"60386828328910021732068595344565885737045900010034836345809386672230885527307","best_ask":"0.61","best_bid":"0.6","hash":"6986b11f0b2b1c306f3e4e70d73b1b15805d11bc","price":"0.59","side":"BUY","size":"44.4"},{"asset_id":"69697746896130839564035629862476347944307040470122503199396727085502753297492","best_ask":"0.4","best_bid":"0.39","hash":"4d3b7c276cdc8ac6456184f096c9a1ba298cb6f3","price":"0.41","side":"SELL","size":"44.4"}],"timestamp":"1785126666514"},"payload_hash":"f5198dab294468be7bfba33ca82a4c507136f26d18250adfdc342daafa877036","raw_frame":"{\"market\":\"0xeb66215f2e9faa6449e30a02bab5b8ed7b79a38bf961f6b24d0073c9c2419250\", \"price_changes\":[{\"asset_id\":\"60386828328910021732068595344565885737045900010034836345809386672230885527307\", \"price\":\"0.59\", \"size\":\"44.4\", \"side\":\"BUY\", \"hash\":\"6986b11f0b2b1c306f3e4e70d73b1b15805d11bc\", \"best_bid\":\"0.6\", \"best_ask\":\"0.61\"}, {\"asset_id\":\"69697746896130839564035629862476347944307040470122503199396727085502753297492\", \"price\":\"0.41\", \"size\":\"44.4\", \"side\":\"SELL\", \"hash\":\"4d3b7c276cdc8ac6456184f096c9a1ba298cb6f3\", \"best_bid\":\"0.39\", \"best_ask\":\"0.4\"}], \"timestamp\":\"1785126666514\", \"event_type\":\"price_change\"}","received_at":"2026-07-27T04:31:12.161047Z","schema_version":"clob-market-ws.price_change.v1","sequence":null,"server_hash":null,"server_timestamp":"1785126666514","session_id":"e9443c7415a0419799bee9cfbb1a9e4d","source":"clob_market_ws"},"received_at":"2026-07-27T04:31:12.161047Z","record_id":"1bcd18a1591ada7e2c138b0283844549b3f5d731226c69a23c86bc0c98adfd23","schema_fingerprint":"4aa3821a28b0b7c2400bc59aba4bcc0a76e971dadd19610d3ad38c768e124dc7","schema_version":"edge-lab-recorder.raw.v1","sequence":null,"source":"clob_market_ws"}
{"event_at":"2026-07-27T04:31:06.514000Z","event_fingerprint":"63928a9e2fdcf0d9ba6f0b7ea03d1424637439111722556286a846e616714d02","payload":{"connection_id":"0f4979d6978d463e9660b042fdcf555f","event_at":"2026-07-27T04:31:06.514000Z","event_type":"price_change","frame_hash":"ef8617f1bd292d0473c4345b62d92dc3521ada32538cea2ee0e61004a8fde9dd","frame_index":0,"kind":"data","monotonic_ns":228655438468000,"payload":{"event_type":"price_change","market":"0xeb66215f2e9faa6449e30a02bab5b8ed7b79a38bf961f6b24d0073c9c2419250","price_changes":[{"asset_id":"69697746896130839564035629862476347944307040470122503199396727085502753297492","best_ask":"0.4","best_bid":"0.39","hash":"ae97243240ec9aebbb7c462cc57425f3ad14b250","price":"0.37","side":"BUY","size":"115"},{"asset_id":"60386828328910021732068595344565885737045900010034836345809386672230885527307","best_ask":"0.61","best_bid":"0.6","hash":"1c63ba1b54284cb479150cfee66fe956a632f324","price":"0.63","side":"SELL","size":"115"}],"timestamp":"1785126666514"},"payload_hash":"d066c8ac451d492181b782d5f6852991b4081a1e82f85a3d4742ebf96246a5ae","raw_frame":"{\"market\":\"0xeb66215f2e9faa6449e30a02bab5b8ed7b79a38bf961f6b24d0073c9c2419250\", \"price_changes\":[{\"asset_id\":\"69697746896130839564035629862476347944307040470122503199396727085502753297492\", \"price\":\"0.37\", \"size\":\"115\", \"side\":\"BUY\", \"hash\":\"ae97243240ec9aebbb7c462cc57425f3ad14b250\", \"best_bid\":\"0.39\", \"best_ask\":\"0.4\"}, {\"asset_id\":\"60386828328910021732068595344565885737045900010034836345809386672230885527307\", \"price\":\"0.63\", \"size\":\"115\", \"side\":\"SELL\", \"hash\":\"1c63ba1b54284cb479150cfee66fe956a632f324\", \"best_bid\":\"0.6\", \"best_ask\":\"0.61\"}], \"timestamp\":\"1785126666514\", \"event_type\":\"price_change\"}","received_at":"2026-07-27T04:31:12.169249Z","schema_version":"clob-market-ws.price_change.v1","sequence":null,"server_hash":null,"server_timestamp":"1785126666514","session_id":"e9443c7415a0419799bee9cfbb1a9e4d","source":"clob_market_ws"},"received_at":"2026-07-27T04:31:12.169249Z","record_id":"ab1c63c753a887831224bff7dc40ede9ad8a939f7dc1a5cee73446b010af24ad","schema_fingerprint":"4aa3821a28b0b7c2400bc59aba4bcc0a76e971dadd19610d3ad38c768e124dc7","schema_version":"edge-lab-recorder.raw.v1","sequence":null,"source":"clob_market_ws"}
{"event_at":"2026-07-27T04:31:06.516000Z","event_fingerprint":"05b2f1ff344e7f65a184f4d13e20e526d9617bd174fe4f03f263ef55d2137604","payload":{"connection_id":"0f4979d6978d463e9660b042fdcf555f","event_at":"2026-07-27T04:31:06.516000Z","event_type":"price_change","frame_hash":"3f75dc5cd63bd94015765b85fdfa59b6866e36038e5e479789868a2a37f28b68","frame_index":0,"kind":"data","monotonic_ns":228655445967375,"payload":{"event_type":"price_change","market":"0xeb66215f2e9faa6449e30a02bab5b8ed7b79a38bf961f6b24d0073c9c2419250","price_changes":[{"asset_id":"60386828328910021732068595344565885737045900010034836345809386672230885527307","best_ask":"0.61","best_bid":"0.6","hash":"868bb78771b21073d315642cb172fc80501f96a3","price":"0.04","side":"BUY","size":"748.09"},{"asset_id":"69697746896130839564035629862476347944307040470122503199396727085502753297492","best_ask":"0.4","best_bid":"0.39","hash":"d2b5426fbd2cef90c0f8543cc0c0c2ce1517155a","price":"0.96","side":"SELL","size":"748.09"}],"timestamp":"1785126666516"},"payload_hash":"274951ea8e43f4fb256fefb9240bf78517f70af098b3c9add0b60ff6b3019754","raw_frame":"{\"market\":\"0xeb66215f2e9faa6449e30a02bab5b8ed7b79a38bf961f6b24d0073c9c2419250\", \"price_changes\":[{\"asset_id\":\"60386828328910021732068595344565885737045900010034836345809386672230885527307\", \"price\":\"0.04\", \"size\":\"748.09\", \"side\":\"BUY\", \"hash\":\"868bb78771b21073d315642cb172fc80501f96a3\", \"best_bid\":\"0.6\", \"best_ask\":\"0.61\"}, {\"asset_id\":\"69697746896130839564035629862476347944307040470122503199396727085502753297492\", \"price\":\"0.96\", \"size\":\"748.09\", \"side\":\"SELL\", \"hash\":\"d2b5426fbd2cef90c0f8543cc0c0c2ce1517155a\", \"best_bid\":\"0.39\", \"best_ask\":\"0.4\"}], \"timestamp\":\"1785126666516\", \"event_type\":\"price_change\"}","received_at":"2026-07-27T04:31:12.176757Z","schema_version":"clob-market-ws.price_change.v1","sequence":null,"server_hash":null,"server_timestamp":"1785126666516","session_id":"e9443c7415a0419799bee9cfbb1a9e4d","source":"clob_market_ws"},"received_at":"2026-07-27T04:31:12.176757Z","record_id":"d96281ca587718b67ca76db97e8e9f7ab874ef7f319c5f45094276b7cbe7fe9e","schema_fingerprint":"4aa3821a28b0b7c2400bc59aba4bcc0a76e971dadd19610d3ad38c768e124dc7","schema_version":"edge-lab-recorder.raw.v1","sequence":null,"source":"clob_market_ws"}
{"event_at":"2026-07-27T04:31:06.516000Z","event_fingerprint":"c883954c813e5ee0d8e5e1826708a20cfcd7d84b97395fd6095ce627dc89ee6b","payload":{"connection_id":"0f4979d6978d463e9660b042fdcf555f","event_at":"2026-07-27T04:31:06.516000Z","event_type":"price_change","frame_hash":"4b9b5bcf879eeac26f737c323d4c014710cecb9b18466a2ca57a1c255c70a6eb","frame_index":0,"kind":"data","monotonic_ns":228655451656083,"payload":{"event_type":"price_change","market":"0xeb66215f2e9faa6449e30a02bab5b8ed7b79a38bf961f6b24d0073c9c2419250","price_changes":[{"asset_id":"60386828328910021732068595344565885737045900010034836345809386672230885527307","best_ask":"0.61","best_bid":"0.6","hash":"8f1a9de31166c369992ea3290780b8a699108767","price":"0.6","side":"BUY","size":"65.74"},{"asset_id":"69697746896130839564035629862476347944307040470122503199396727085502753297492","best_ask":"0.4","best_bid":"0.39","hash":"4ba9e445b8d11e019cfce464566c90f730a3f660","price":"0.4","side":"SELL","size":"65.74"}],"timestamp":"1785126666516"},"payload_hash":"ade4c6db3d5ab6fd3ad2e0b73b3fd14cadb0df86f0f11b390e61ccf28dda6eaf","raw_frame":"{\"market\":\"0xeb66215f2e9faa6449e30a02bab5b8ed7b79a38bf961f6b24d0073c9c2419250\", \"price_changes\":[{\"asset_id\":\"60386828328910021732068595344565885737045900010034836345809386672230885527307\", \"price\":\"0.6\", \"size\":\"65.74\", \"side\":\"BUY\", \"hash\":\"8f1a9de31166c369992ea3290780b8a699108767\", \"best_bid\":\"0.6\", \"best_ask\":\"0.61\"}, {\"asset_id\":\"69697746896130839564035629862476347944307040470122503199396727085502753297492\", \"price\":\"0.4\", \"size\":\"65.74\", \"side\":\"SELL\", \"hash\":\"4ba9e445b8d11e019cfce464566c90f730a3f660\", \"best_bid\":\"0.39\", \"best_ask\":\"0.4\"}], \"timestamp\":\"1785126666516\", \"event_type\":\"price_change\"}","received_at":"2026-07-27T04:31:12.182444Z","schema_version":"clob-market-ws.price_change.v1","sequence":null,"server_hash":null,"server_timestamp":"1785126666516","session_id":"e9443c7415a0419799bee9cfbb1a9e4d","source":"clob_market_ws"},"received_at":"2026-07-27T04:31:12.182444Z","record_id":"feebe42ef3d57f6f83da2e2c0ef093327a864558a80fce94cb34ec41b9a80dd3","schema_fingerprint":"4aa3821a28b0b7c2400bc59aba4bcc0a76e971dadd19610d3ad38c768e124dc7","schema_version":"edge-lab-recorder.raw.v1","sequence":null,"source":"clob_market_ws"}
{"event_at":"2026-07-27T04:31:06.516000Z","event_fingerprint":"f25e7cb640666dca4c4326bd52c6e8f831c16d16bac110b9b5e2d73c45f85158","payload":{"connection_id":"0f4979d6978d463e9660b042fdcf555f","event_at":"2026-07-27T04:31:06.516000Z","event_type":"price_change","frame_hash":"399fb5f70b8ac063f1880d314545ee7a06e7026d139c651c044daabbf0d6c20e","frame_index":0,"kind":"data","monotonic_ns":228655458788333,"payload":{"event_type":"price_change","market":"0xeb66215f2e9faa6449e30a02bab5b8ed7b79a38bf961f6b24d0073c9c2419250","price_changes":[{"asset_id":"69697746896130839564035629862476347944307040470122503199396727085502753297492","best_ask":"0.4","best_bid":"0.39","hash":"00364133920458a3b1b38a14740a157e5c7cfa37","price":"0.35","side":"BUY","size":"132"},{"asset_id":"60386828328910021732068595344565885737045900010034836345809386672230885527307","best_ask":"0.61","best_bid":"0.6","hash":"0442e2fabe6c223660e1fcfa5722fda35df7b335","price":"0.65","side":"SELL","size":"132"}],"timestamp":"1785126666516"},"payload_hash":"18e005d54063bef2543926531e5222566213898d2b22f905c4c9d0336e9888a5","raw_frame":"{\"market\":\"0xeb66215f2e9faa6449e30a02bab5b8ed7b79a38bf961f6b24d0073c9c2419250\", \"price_changes\":[{\"asset_id\":\"69697746896130839564035629862476347944307040470122503199396727085502753297492\", \"price\":\"0.35\", \"size\":\"132\", \"side\":\"BUY\", \"hash\":\"00364133920458a3b1b38a14740a157e5c7cfa37\", \"best_bid\":\"0.39\", \"best_ask\":\"0.4\"}, {\"asset_id\":\"60386828328910021732068595344565885737045900010034836345809386672230885527307\", \"price\":\"0.65\", \"size\":\"132\", \"side\":\"SELL\", \"hash\":\"0442e2fabe6c223660e1fcfa5722fda35df7b335\", \"best_bid\":\"0.6\", \"best_ask\":\"0.61\"}], \"timestamp\":\"1785126666516\", \"event_type\":\"price_change\"}","received_at":"2026-07-27T04:31:12.189577Z","schema_version":"clob-market-ws.price_change.v1","sequence":null,"server_hash":null,"server_timestamp":"1785126666516","session_id":"e9443c7415a0419799bee9cfbb1a9e4d","source":"clob_market_ws"},"received_at":"2026-07-27T04:31:12.189577Z","record_id":"b7d48b3084d682532e5f540c7e1689963668bc7cce8298f284634d7fa3a63cbd","schema_fingerprint":"4aa3821a28b0b7c2400bc59aba4bcc0a76e971dadd19610d3ad38c768e124dc7","schema_version":"edge-lab-recorder.raw.v1","sequence":null,"source":"clob_market_ws"}
{"event_at":"2026-07-27T04:31:06.519000Z","event_fingerprint":"30797c19a197301b9be6ca9eba2bd17e78a09d0e6c2e9b419c2ffcede2242a5c","payload":{"connection_id":"0f4979d6978d463e9660b042fdcf555f","event_at":"2026-07-27T04:31:06.519000Z","event_type":"price_change","frame_hash":"33cfa4a33c39d20d149f5bcce29f376167934890d762005682a60c9fbc238789","frame_index":0,"kind":"data","monotonic_ns":228655464328666,"payload":{"event_type":"price_change","market":"0xeb66215f2e9faa6449e30a02bab5b8ed7b79a38bf961f6b24d0073c9c2419250","price_changes":[{"asset_id":"60386828328910021732068595344565885737045900010034836345809386672230885527307","best_ask":"0.61","best_bid":"0.6","hash":"7ee6367ee15b56534837223769460db4d2a231b9","price":"0.45","side":"BUY","size":"172"},{"asset_id":"69697746896130839564035629862476347944307040470122503199396727085502753297492","best_ask":"0.4","best_bid":"0.39","hash":"a9d971ff60dd50d08af13a447b04da53d2cee29c","price":"0.55","side":"SELL","size":"172"}],"timestamp":"1785126666519"},"payload_hash":"60ee72e37e88e1e239008eaa0e4b5660de6a1e6fa2ac4bf76b7e20a4a1cbcbf6","raw_frame":"{\"market\":\"0xeb66215f2e9faa6449e30a02bab5b8ed7b79a38bf961f6b24d0073c9c2419250\", \"price_changes\":[{\"asset_id\":\"60386828328910021732068595344565885737045900010034836345809386672230885527307\", \"price\":\"0.45\", \"size\":\"172\", \"side\":\"BUY\", \"hash\":\"7ee6367ee15b56534837223769460db4d2a231b9\", \"best_bid\":\"0.6\", \"best_ask\":\"0.61\"}, {\"asset_id\":\"69697746896130839564035629862476347944307040470122503199396727085502753297492\", \"price\":\"0.55\", \"size\":\"172\", \"side\":\"SELL\", \"hash\":\"a9d971ff60dd50d08af13a447b04da53d2cee29c\", \"best_bid\":\"0.39\", \"best_ask\":\"0.4\"}], \"timestamp\":\"1785126666519\", \"event_type\":\"price_change\"}","received_at":"2026-07-27T04:31:12.195117Z","schema_version":"clob-market-ws.price_change.v1","sequence":null,"server_hash":null,"server_timestamp":"1785126666519","session_id":"e9443c7415a0419799bee9cfbb1a9e4d","source":"clob_market_ws"},"received_at":"2026-07-27T04:31:12.195117Z","record_id":"c35de33431bf4c1084729cca7c280cee916babdbbf7a6bec8f9291c427e863f1","schema_fingerprint":"4aa3821a28b0b7c2400bc59aba4bcc0a76e971dadd19610d3ad38c768e124dc7","schema_version":"edge-lab-recorder.raw.v1","sequence":null,"source":"clob_market_ws"}
{"event_at":"2026-07-27T04:31:06.520000Z","event_fingerprint":"a095380e08ac14894d76cf37642fd01f9de64cdf964c43d3b6bbab4da872183e","payload":{"connection_id":"0f4979d6978d463e9660b042fdcf555f","event_at":"2026-07-27T04:31:06.520000Z","event_type":"price_change","frame_hash":"4c376cfdae085eb5bc49feadf55e10a1340534b7801dcfdfea017ca96e151419","frame_index":0,"kind":"data","monotonic_ns":228655468006833,"payload":{"event_type":"price_change","market":"0xeb66215f2e9faa6449e30a02bab5b8ed7b79a38bf961f6b24d0073c9c2419250","price_changes":[{"asset_id":"69697746896130839564035629862476347944307040470122503199396727085502753297492","best_ask":"0.4","best_bid":"0.39","hash":"debd291d190bd0c0d0b83c144c6f3b13d1bdb2e0","price":"0.38","side":"BUY","size":"22.6"},{"asset_id":"60386828328910021732068595344565885737045900010034836345809386672230885527307","best_ask":"0.61","best_bid":"0.6","hash":"7caca97712f243eb5de2882251316b8caf709116","price":"0.62","side":"SELL","size":"22.6"}],"timestamp":"1785126666520"},"payload_hash":"ae8bfdcba7ee3b8e28b8f6a3e007ec3ebaee483e07b3b48fa9bf0070088f27a0","raw_frame":"{\"market\":\"0xeb66215f2e9faa6449e30a02bab5b8ed7b79a38bf961f6b24d0073c9c2419250\", \"price_changes\":[{\"asset_id\":\"69697746896130839564035629862476347944307040470122503199396727085502753297492\", \"price\":\"0.38\", \"size\":\"22.6\", \"side\":\"BUY\", \"hash\":\"debd291d190bd0c0d0b83c144c6f3b13d1bdb2e0\", \"best_bid\":\"0.39\", \"best_ask\":\"0.4\"}, {\"asset_id\":\"60386828328910021732068595344565885737045900010034836345809386672230885527307\", \"price\":\"0.62\", \"size\":\"22.6\", \"side\":\"SELL\", \"hash\":\"7caca97712f243eb5de2882251316b8caf709116\", \"best_bid\":\"0.6\", \"best_ask\":\"0.61\"}], \"timestamp\":\"1785126666520\", \"event_type\":\"price_change\"}","received_at":"2026-07-27T04:31:12.198797Z","schema_version":"clob-market-ws.price_change.v1","sequence":null,"server_hash":null,"server_timestamp":"1785126666520","session_id":"e9443c7415a0419799bee9cfbb1a9e4d","source":"clob_market_ws"},"received_at":"2026-07-27T04:31:12.198797Z","record_id":"b25345406cbd2f77b0492e670157f43a21fc5ca57612b256834f1238504a1fdf","schema_fingerprint":"4aa3821a28b0b7c2400bc59aba4bcc0a76e971dadd19610d3ad38c768e124dc7","schema_version":"edge-lab-recorder.raw.v1","sequence":null,"source":"clob_market_ws"}
{"event_at":"2026-07-27T04:31:06.521000Z","event_fingerprint":"e780bdbf5cb10bbde1aa855e2fa0fc0fd4630c8fb9486d7fb7da7a654202f194","payload":{"connection_id":"0f4979d6978d463e9660b042fdcf555f","event_at":"2026-07-27T04:31:06.521000Z","event_type":"price_change","frame_hash":"dbd45e724a4b5651fdf07c710da1e10c786f1288b1c26b8953527f98340613eb","frame_index":0,"kind":"data","monotonic_ns":228655477295833,"payload":{"event_type":"price_change","market":"0xeb66215f2e9faa6449e30a02bab5b8ed7b79a38bf961f6b24d0073c9c2419250","price_changes":[{"asset_id":"60386828328910021732068595344565885737045900010034836345809386672230885527307","best_ask":"0.61","best_bid":"0.6","hash":"5e81c2153a5009b370655e8aec88d37bb5300e98","price":"0.6","side":"BUY","size":"70.91"},{"asset_id":"69697746896130839564035629862476347944307040470122503199396727085502753297492","best_ask":"0.4","best_bid":"0.39","hash":"021a23278f2ac50a20e3f438e1e7e0992fb7a61e","price":"0.4","side":"SELL","size":"70.91"}],"timestamp":"1785126666521"},"payload_hash":"7b90f3acc8540f298efbd66a31a37da96cbc902c026e8428afae2ef6a712cb42","raw_frame":"{\"market\":\"0xeb66215f2e9faa6449e30a02bab5b8ed7b79a38bf961f6b24d0073c9c2419250\", \"price_changes\":[{\"asset_id\":\"60386828328910021732068595344565885737045900010034836345809386672230885527307\", \"price\":\"0.6\", \"size\":\"70.91\", \"side\":\"BUY\", \"hash\":\"5e81c2153a5009b370655e8aec88d37bb5300e98\", \"best_bid\":\"0.6\", \"best_ask\":\"0.61\"}, {\"asset_id\":\"69697746896130839564035629862476347944307040470122503199396727085502753297492\", \"price\":\"0.4\", \"size\":\"70.91\", \"side\":\"SELL\", \"hash\":\"021a23278f2ac50a20e3f438e1e7e0992fb7a61e\", \"best_bid\":\"0.39\", \"best_ask\":\"0.4\"}], \"timestamp\":\"1785126666521\", \"event_type\":\"price_change\"}","received_at":"2026-07-27T04:31:12.208086Z","schema_version":"clob-market-ws.price_change.v1","sequence":null,"server_hash":null,"server_timestamp":"1785126666521","session_id":"e9443c7415a0419799bee9cfbb1a9e4d","source":"clob_market_ws"},"received_at":"2026-07-27T04:31:12.208086Z","record_id":"67deb62fb83706ff9c0447466fbc3d460e2b16e4420ec730bea5dd8934c0d959","schema_fingerprint":"4aa3821a28b0b7c2400bc59aba4bcc0a76e971dadd19610d3ad38c768e124dc7","schema_version":"edge-lab-recorder.raw.v1","sequence":null,"source":"clob_market_ws"}
{"event_at":"2026-07-27T04:31:06.521000Z","event_fingerprint":"e9dd5df8bde3c3734bc61431e597129e5cb1c98dc5012e0b258f979ea75100fa","payload":{"connection_id":"0f4979d6978d463e9660b042fdcf555f","event_at":"2026-07-27T04:31:06.521000Z","event_type":"price_change","frame_hash":"ee7610fc66ec5718d1f9590890b5b273ad0dfc1f38c9a9e801033f316fe74200","frame_index":0,"kind":"data","monotonic_ns":228655484260791,"payload":{"event_type":"price_change","market":"0xeb66215f2e9faa6449e30a02bab5b8ed7b79a38bf961f6b24d0073c9c2419250","price_changes":[{"asset_id":"60386828328910021732068595344565885737045900010034836345809386672230885527307","best_ask":"0.61","best_bid":"0.6","hash":"faa7d21adfc2a01de5316dcea029b4da46d8a7b5","price":"0.6","side":"BUY","size":"76.08"},{"asset_id":"69697746896130839564035629862476347944307040470122503199396727085502753297492","best_ask":"0.4","best_bid":"0.39","hash":"818f5cf7daba6eaec45c1f4ee4e36c27219f5faf","price":"0.4","side":"SELL","size":"76.08"}],"timestamp":"1785126666521"},"payload_hash":"a1aff0b5b425d69b3f6a590bb795a9ed641c51e62c563002abb140a6ab2365ca","raw_frame":"{\"market\":\"0xeb66215f2e9faa6449e30a02bab5b8ed7b79a38bf961f6b24d0073c9c2419250\", \"price_changes\":[{\"asset_id\":\"60386828328910021732068595344565885737045900010034836345809386672230885527307\", \"price\":\"0.6\", \"size\":\"76.08\", \"side\":\"BUY\", \"hash\":\"faa7d21adfc2a01de5316dcea029b4da46d8a7b5\", \"best_bid\":\"0.6\", \"best_ask\":\"0.61\"}, {\"asset_id\":\"69697746896130839564035629862476347944307040470122503199396727085502753297492\", \"price\":\"0.4\", \"size\":\"76.08\", \"side\":\"SELL\", \"hash\":\"818f5cf7daba6eaec45c1f4ee4e36c27219f5faf\", \"best_bid\":\"0.39\", \"best_ask\":\"0.4\"}], \"timestamp\":\"1785126666521\", \"event_type\":\"price_change\"}","received_at":"2026-07-27T04:31:12.215051Z","schema_version":"clob-market-ws.price_change.v1","sequence":null,"server_hash":null,"server_timestamp":"1785126666521","session_id":"e9443c7415a0419799bee9cfbb1a9e4d","source":"clob_market_ws"},"received_at":"2026-07-27T04:31:12.215051Z","record_id":"240c074422f4e9ed00ebdb4ccd8c88d62f8786d8b586035b7c5c25dacdff40ca","schema_fingerprint":"4aa3821a28b0b7c2400bc59aba4bcc0a76e971dadd19610d3ad38c768e124dc7","schema_version":"edge-lab-recorder.raw.v1","sequence":null,"source":"clob_market_ws"}
{"event_at":"2026-07-27T04:31:06.522000Z","event_fingerprint":"372691c196c0907ca12b7336ba4376adc0d0abe46de645b2c63bf7252a654071","payload":{"connection_id":"0f4979d6978d463e9660b042fdcf555f","event_at":"2026-07-27T04:31:06.522000Z","event_type":"price_change","frame_hash":"a2680a7c057dd560bbdbf40387ffc75a6e5f812d937430dae7e7d74c85c6f404","frame_index":0,"kind":"data","monotonic_ns":228655491820791,"payload":{"event_type":"price_change","market":"0xeb66215f2e9faa6449e30a02bab5b8ed7b79a38bf961f6b24d0073c9c2419250","price_changes":[{"asset_id":"69697746896130839564035629862476347944307040470122503199396727085502753297492","best_ask":"0.4","best_bid":"0.39","hash":"1b35f809e30c235fb00c180f8038c87698c69d24","price":"0.29","side":"BUY","size":"146.6"},{"asset_id":"60386828328910021732068595344565885737045900010034836345809386672230885527307","best_ask":"0.61","best_bid":"0.6","hash":"50a4288a6b978ed9d35e998fd3bd48a2bdcc67d5","price":"0.71","side":"SELL","size":"146.6"}],"timestamp":"1785126666522"},"payload_hash":"02f1d0b9019e28c78346e5326ec0cb56e1a55aea37395b2047457f64777a3511","raw_frame":"{\"market\":\"0xeb66215f2e9faa6449e30a02bab5b8ed7b79a38bf961f6b24d0073c9c2419250\", \"price_changes\":[{\"asset_id\":\"69697746896130839564035629862476347944307040470122503199396727085502753297492\", \"price\":\"0.29\", \"size\":\"146.6\", \"side\":\"BUY\", \"hash\":\"1b35f809e30c235fb00c180f8038c87698c69d24\", \"best_bid\":\"0.39\", \"best_ask\":\"0.4\"}, {\"asset_id\":\"60386828328910021732068595344565885737045900010034836345809386672230885527307\", \"price\":\"0.71\", \"size\":\"146.6\", \"side\":\"SELL\", \"hash\":\"50a4288a6b978ed9d35e998fd3bd48a2bdcc67d5\", \"best_bid\":\"0.6\", \"best_ask\":\"0.61\"}], \"timestamp\":\"1785126666522\", \"event_type\":\"price_change\"}","received_at":"2026-07-27T04:31:12.222609Z","schema_version":"clob-market-ws.price_change.v1","sequence":null,"server_hash":null,"server_timestamp":"1785126666522","session_id":"e9443c7415a0419799bee9cfbb1a9e4d","source":"clob_market_ws"},"received_at":"2026-07-27T04:31:12.222609Z","record_id":"f22fa939e1b61e8ab1a23caa2bfa5d3749a60d3f4f6cebab8181ad24308e49bb","schema_fingerprint":"4aa3821a28b0b7c2400bc59aba4bcc0a76e971dadd19610d3ad38c768e124dc7","schema_version":"edge-lab-recorder.raw.v1","sequence":null,"source":"clob_market_ws"}
{"event_at":"2026-07-27T04:31:06.523000Z","event_fingerprint":"e3758bb5a1d94daa22343da527c11c1901897ae657be4044da89a767a7f03e3b","payload":{"connection_id":"0f4979d6978d463e9660b042fdcf555f","event_at":"2026-07-27T04:31:06.523000Z","event_type":"price_change","frame_hash":"ebabedbdebcdae834537f4777482caffdd4c25538fc6f36328b7d0077ed2594f","frame_index":0,"kind":"data","monotonic_ns":228655500278208,"payload":{"event_type":"price_change","market":"0xeb66215f2e9faa6449e30a02bab5b8ed7b79a38bf961f6b24d0073c9c2419250","price_changes":[{"asset_id":"60386828328910021732068595344565885737045900010034836345809386672230885527307","best_ask":"0.61","best_bid":"0.6","hash":"6e6179db9ac30201d2d3defddf5812809b50eb58","price":"0.6","side":"BUY","size":"101.08"},{"asset_id":"69697746896130839564035629862476347944307040470122503199396727085502753297492","best_ask":"0.4","best_bid":"0.39","hash":"b8851b5b7a5ab05721f582d84f460abb2a4661a4","price":"0.4","side":"SELL","size":"101.08"}],"timestamp":"1785126666523"},"payload_hash":"10b9f71f8283815daeb9579e5bb03b48db0a681f4dc6346a0d97de9d8ba58e84","raw_frame":"{\"market\":\"0xeb66215f2e9faa6449e30a02bab5b8ed7b79a38bf961f6b24d0073c9c2419250\", \"price_changes\":[{\"asset_id\":\"60386828328910021732068595344565885737045900010034836345809386672230885527307\", \"price\":\"0.6\", \"size\":\"101.08\", \"side\":\"BUY\", \"hash\":\"6e6179db9ac30201d2d3defddf5812809b50eb58\", \"best_bid\":\"0.6\", \"best_ask\":\"0.61\"}, {\"asset_id\":\"69697746896130839564035629862476347944307040470122503199396727085502753297492\", \"price\":\"0.4\", \"size\":\"101.08\", \"side\":\"SELL\", \"hash\":\"b8851b5b7a5ab05721f582d84f460abb2a4661a4\", \"best_bid\":\"0.39\", \"best_ask\":\"0.4\"}], \"timestamp\":\"1785126666523\", \"event_type\":\"price_change\"}","received_at":"2026-07-27T04:31:12.231066Z","schema_version":"clob-market-ws.price_change.v1","sequence":null,"server_hash":null,"server_timestamp":"1785126666523","session_id":"e9443c7415a0419799bee9cfbb1a9e4d","source":"clob_market_ws"},"received_at":"2026-07-27T04:31:12.231066Z","record_id":"b697d095b60e6760c536ea7f3c9113454f7e1b1ab07e685d87da18c37312a678","schema_fingerprint":"4aa3821a28b0b7c2400bc59aba4bcc0a76e971dadd19610d3ad38c768e124dc7","schema_version":"edge-lab-recorder.raw.v1","sequence":null,"source":"clob_market_ws"}
{"event_at":"2026-07-27T04:31:06.524000Z","event_fingerprint":"af972552f9c1e85427e7ae146ba0e5bb8326ca5d6ea5ccb5913913d9d5e0b89a","payload":{"connection_id":"0f4979d6978d463e9660b042fdcf555f","event_at":"2026-07-27T04:31:06.524000Z","event_type":"price_change","frame_hash":"4f3ff8d34fb4c92b12cf7132935f5fbffc122534aa9d9190d7f8014c3febb089","frame_index":0,"kind":"data","monotonic_ns":228655509838541,"payload":{"event_type":"price_change","market":"0xeb66215f2e9faa6449e30a02bab5b8ed7b79a38bf961f6b24d0073c9c2419250","price_changes":[{"asset_id":"69697746896130839564035629862476347944307040470122503199396727085502753297492","best_ask":"0.4","best_bid":"0.39","hash":"3337e085600f218758d67e41a70074499cafd98a","price":"0.33","side":"BUY","size":"138.6"},{"asset_id":"60386828328910021732068595344565885737045900010034836345809386672230885527307","best_ask":"0.61","best_bid":"0.6","hash":"dfa32aae7fa097fb8e51c67ea1efd67282433f1b","price":"0.67","side":"SELL","size":"138.6"}],"timestamp":"1785126666524"},"payload_hash":"d0cdbcaebbfd4ea72d3a3835280fd43d724c3f5448c3028b3d519db815fc166c","raw_frame":"{\"market\":\"0xeb66215f2e9faa6449e30a02bab5b8ed7b79a38bf961f6b24d0073c9c2419250\", \"price_changes\":[{\"asset_id\":\"69697746896130839564035629862476347944307040470122503199396727085502753297492\", \"price\":\"0.33\", \"size\":\"138.6\", \"side\":\"BUY\", \"hash\":\"3337e085600f218758d67e41a70074499cafd98a\", \"best_bid\":\"0.39\", \"best_ask\":\"0.4\"}, {\"asset_id\":\"60386828328910021732068595344565885737045900010034836345809386672230885527307\", \"price\":\"0.67\", \"size\":\"138.6\", \"side\":\"SELL\", \"hash\":\"dfa32aae7fa097fb8e51c67ea1efd67282433f1b\", \"best_bid\":\"0.6\", \"best_ask\":\"0.61\"}], \"timestamp\":\"1785126666524\", \"event_type\":\"price_change\"}","received_at":"2026-07-27T04:31:12.240628Z","schema_version":"clob-market-ws.price_change.v1","sequence":null,"server_hash":null,"server_timestamp":"1785126666524","session_id":"e9443c7415a0419799bee9cfbb1a9e4d","source":"clob_market_ws"},"received_at":"2026-07-27T04:31:12.240628Z","record_id":"7cb98a53578f1c2e28f0ec0cbf3ff7c6568ad6746f3692005eafff886bd6f637","schema_fingerprint":"4aa3821a28b0b7c2400bc59aba4bcc0a76e971dadd19610d3ad38c768e124dc7","schema_version":"edge-lab-recorder.raw.v1","sequence":null,"source":"clob_market_ws"}
{"event_at":"2026-07-27T04:31:06.524000Z","event_fingerprint":"060eb82469d6ebbe762c0c9e45e19ede1986928ecd8fadca9a6b7db26e290947","payload":{"connection_id":"0f4979d6978d463e9660b042fdcf555f","event_at":"2026-07-27T04:31:06.524000Z","event_type":"price_change","frame_hash":"a1cb0e9b1c4c50e9e84372fb9760a2dbce0ca5d972031a15b586e256ed938595","frame_index":0,"kind":"data","monotonic_ns":228655515568958,"payload":{"event_type":"price_change","market":"0xeb66215f2e9faa6449e30a02bab5b8ed7b79a38bf961f6b24d0073c9c2419250","price_changes":[{"asset_id":"60386828328910021732068595344565885737045900010034836345809386672230885527307","best_ask":"0.61","best_bid":"0.6","hash":"26452904109cd786a5bf9bd98f33c9a064a52c03","price":"0.01","side":"BUY","size":"7703.02"},{"asset_id":"69697746896130839564035629862476347944307040470122503199396727085502753297492","best_ask":"0.4","best_bid":"0.39","hash":"8d05b0f2f98fd9980f2ba59685284939ced6733e","price":"0.99","side":"SELL","size":"7703.02"}],"timestamp":"1785126666524"},"payload_hash":"7e7eb158d2f8377a9228d8c1558121d1bba3178d3f407ff80674a9b7c392f11f","raw_frame":"{\"market\":\"0xeb66215f2e9faa6449e30a02bab5b8ed7b79a38bf961f6b24d0073c9c2419250\", \"price_changes\":[{\"asset_id\":\"60386828328910021732068595344565885737045900010034836345809386672230885527307\", \"price\":\"0.01\", \"size\":\"7703.02\", \"side\":\"BUY\", \"hash\":\"26452904109cd786a5bf9bd98f33c9a064a52c03\", \"best_bid\":\"0.6\", \"best_ask\":\"0.61\"}, {\"asset_id\":\"69697746896130839564035629862476347944307040470122503199396727085502753297492\", \"price\":\"0.99\", \"size\":\"7703.02\", \"side\":\"SELL\", \"hash\":\"8d05b0f2f98fd9980f2ba59685284939ced6733e\", \"best_bid\":\"0.39\", \"best_ask\":\"0.4\"}], \"timestamp\":\"1785126666524\", \"event_type\":\"price_change\"}","received_at":"2026-07-27T04:31:12.246358Z","schema_version":"clob-market-ws.price_change.v1","sequence":null,"server_hash":null,"server_timestamp":"1785126666524","session_id":"e9443c7415a0419799bee9cfbb1a9e4d","source":"clob_market_ws"},"received_at":"2026-07-27T04:31:12.246358Z","record_id":"4e6b952b10e38607a2006a011513f6fe7402eae45b4ebf8cd914de3da9452f49","schema_fingerprint":"4aa3821a28b0b7c2400bc59aba4bcc0a76e971dadd19610d3ad38c768e124dc7","schema_version":"edge-lab-recorder.raw.v1","sequence":null,"source":"clob_market_ws"}
{"event_at":"2026-07-27T04:31:06.524000Z","event_fingerprint":"5b4f3e66a83b71aeaf78471f5fbefb907386a2f15e2b3556a576de1164f362f3","payload":{"connection_id":"0f4979d6978d463e9660b042fdcf555f","event_at":"2026-07-27T04:31:06.524000Z","event_type":"price_change","frame_hash":"420d65b8cddc07aeba06be42f806c067a1497496a7456f692206c50c5b5b4c92","frame_index":0,"kind":"data","monotonic_ns":228655525818500,"payload":{"event_type":"price_change","market":"0xeb66215f2e9faa6449e30a02bab5b8ed7b79a38bf961f6b24d0073c9c2419250","price_changes":[{"asset_id":"60386828328910021732068595344565885737045900010034836345809386672230885527307","best_ask":"0.61","best_bid":"0.6","hash":"8eb8fc316122602f164a6f1115073fbcbd687c3f","price":"0.49","side":"BUY","size":"86"},{"asset_id":"69697746896130839564035629862476347944307040470122503199396727085502753297492","best_ask":"0.4","best_bid":"0.39","hash":"d7cb7beb8835bfa62a76a6ec8fbb50b679958c16","price":"0.51","side":"SELL","size":"86"}],"timestamp":"1785126666524"},"payload_hash":"31855baf0dfc0290559c7c82ee35809682191d1f481950d59282a89133492817","raw_frame":"{\"market\":\"0xeb66215f2e9faa6449e30a02bab5b8ed7b79a38bf961f6b24d0073c9c2419250\", \"price_changes\":[{\"asset_id\":\"60386828328910021732068595344565885737045900010034836345809386672230885527307\", \"price\":\"0.49\", \"size\":\"86\", \"side\":\"BUY\", \"hash\":\"8eb8fc316122602f164a6f1115073fbcbd687c3f\", \"best_bid\":\"0.6\", \"best_ask\":\"0.61\"}, {\"asset_id\":\"69697746896130839564035629862476347944307040470122503199396727085502753297492\", \"price\":\"0.51\", \"size\":\"86\", \"side\":\"SELL\", \"hash\":\"d7cb7beb8835bfa62a76a6ec8fbb50b679958c16\", \"best_bid\":\"0.39\", \"best_ask\":\"0.4\"}], \"timestamp\":\"1785126666524\", \"event_type\":\"price_change\"}","received_at":"2026-07-27T04:31:12.256608Z","schema_version":"clob-market-ws.price_change.v1","sequence":null,"server_hash":null,"server_timestamp":"1785126666524","session_id":"e9443c7415a0419799bee9cfbb1a9e4d","source":"clob_market_ws"},"received_at":"2026-07-27T04:31:12.256608Z","record_id":"e8905defdb8047b3f4dfe62588959970d8dac890fbbaf51dc4056aacbc4ae636","schema_fingerprint":"4aa3821a28b0b7c2400bc59aba4bcc0a76e971dadd19610d3ad38c768e124dc7","schema_version":"edge-lab-recorder.raw.v1","sequence":null,"source":"clob_market_ws"}
{"event_at":"2026-07-27T04:31:06.525000Z","event_fingerprint":"16ad934dad6131bb2074ea129b1638634be43046c99ce2803e6ed2109a4e2db0","payload":{"connection_id":"0f4979d6978d463e9660b042fdcf555f","event_at":"2026-07-27T04:31:06.525000Z","event_type":"price_change","frame_hash":"97053c8787bbbb3b4bf8d114f397a24f2bb5ead825e8a4a2fbe3f4227e21754c","frame_index":0,"kind":"data","monotonic_ns":228655532524958,"payload":{"event_type":"price_change","market":"0xeb66215f2e9faa6449e30a02bab5b8ed7b79a38bf961f6b24d0073c9c2419250","price_changes":[{"asset_id":"60386828328910021732068595344565885737045900010034836345809386672230885527307","best_ask":"0.61","best_bid":"0.6","hash":"3ae464d3185d39c16ca3e1f5633ce7c13a705583","price":"0.53","side":"BUY","size":"89.22"},{"asset_id":"69697746896130839564035629862476347944307040470122503199396727085502753297492","best_ask":"0.4","best_bid":"0.39","hash":"e19473ce10b01fff501a673f91bbcf6ad32d5e71","price":"0.47","side":"SELL","size":"89.22"}],"timestamp":"1785126666525"},"payload_hash":"03b0ca9d816ce625757bfb28c367344e0c0181d75d75e3fc709b9aa5c6a4d44f","raw_frame":"{\"market\":\"0xeb66215f2e9faa6449e30a02bab5b8ed7b79a38bf961f6b24d0073c9c2419250\", \"price_changes\":[{\"asset_id\":\"60386828328910021732068595344565885737045900010034836345809386672230885527307\", \"price\":\"0.53\", \"size\":\"89.22\", \"side\":\"BUY\", \"hash\":\"3ae464d3185d39c16ca3e1f5633ce7c13a705583\", \"best_bid\":\"0.6\", \"best_ask\":\"0.61\"}, {\"asset_id\":\"69697746896130839564035629862476347944307040470122503199396727085502753297492\", \"price\":\"0.47\", \"size\":\"89.22\", \"side\":\"SELL\", \"hash\":\"e19473ce10b01fff501a673f91bbcf6ad32d5e71\", \"best_bid\":\"0.39\", \"best_ask\":\"0.4\"}], \"timestamp\":\"1785126666525\", \"event_type\":\"price_change\"}","received_at":"2026-07-27T04:31:12.263316Z","schema_version":"clob-market-ws.price_change.v1","sequence":null,"server_hash":null,"server_timestamp":"1785126666525","session_id":"e9443c7415a0419799bee9cfbb1a9e4d","source":"clob_market_ws"},"received_at":"2026-07-27T04:31:12.263316Z","record_id":"38f2f6de8788d43590caf184343bcebf996b2ac252af81f4b444381802b0f907","schema_fingerprint":"4aa3821a28b0b7c2400bc59aba4bcc0a76e971dadd19610d3ad38c768e124dc7","schema_version":"edge-lab-recorder.raw.v1","sequence":null,"source":"clob_market_ws"}
{"event_at":"2026-07-27T04:31:06.525000Z","event_fingerprint":"3126282bb9d6e568f24829316229a485b4023c59957553dc23f7d40f4644ad68","payload":{"connection_id":"0f4979d6978d463e9660b042fdcf555f","event_at":"2026-07-27T04:31:06.525000Z","event_type":"price_change","frame_hash":"7173b6643ce7cfadf6ad2b0f90399930243617d488e42cfa60aa85e9a81a0fb9","frame_index":0,"kind":"data","monotonic_ns":228655542209875,"payload":{"event_type":"price_change","market":"0xeb66215f2e9faa6449e30a02bab5b8ed7b79a38bf961f6b24d0073c9c2419250","price_changes":[{"asset_id":"60386828328910021732068595344565885737045900010034836345809386672230885527307","best_ask":"0.61","best_bid":"0.6","hash":"ca3a499c536a2907053102f2dd3e0a7a2f5067a1","price":"0.49","side":"BUY","size":"56"},{"asset_id":"69697746896130839564035629862476347944307040470122503199396727085502753297492","best_ask":"0.4","best_bid":"0.39","hash":"fa10178293fdec11e0fc871a4b316ec3f16e1e92","price":"0.51","side":"SELL","size":"56"}],"timestamp":"1785126666525"},"payload_hash":"7dea9c45871a2cc08f355b4d4d7869158f97dd3a2ecd9e298e89aba358b00428","raw_frame":"{\"market\":\"0xeb66215f2e9faa6449e30a02bab5b8ed7b79a38bf961f6b24d0073c9c2419250\", \"price_changes\":[{\"asset_id\":\"60386828328910021732068595344565885737045900010034836345809386672230885527307\", \"price\":\"0.49\", \"size\":\"56\", \"side\":\"BUY\", \"hash\":\"ca3a499c536a2907053102f2dd3e0a7a2f5067a1\", \"best_bid\":\"0.6\", \"best_ask\":\"0.61\"}, {\"asset_id\":\"69697746896130839564035629862476347944307040470122503199396727085502753297492\", \"price\":\"0.51\", \"size\":\"56\", \"side\":\"SELL\", \"hash\":\"fa10178293fdec11e0fc871a4b316ec3f16e1e92\", \"best_bid\":\"0.39\", \"best_ask\":\"0.4\"}], \"timestamp\":\"1785126666525\", \"event_type\":\"price_change\"}","received_at":"2026-07-27T04:31:12.273000Z","schema_version":"clob-market-ws.price_change.v1","sequence":null,"server_hash":null,"server_timestamp":"1785126666525","session_id":"e9443c7415a0419799bee9cfbb1a9e4d","source":"clob_market_ws"},"received_at":"2026-07-27T04:31:12.273000Z","record_id":"5d45a6c1099b2304d3a463cd8885eb5d5290cbbbe20700035edab31199344be1","schema_fingerprint":"4aa3821a28b0b7c2400bc59aba4bcc0a76e971dadd19610d3ad38c768e124dc7","schema_version":"edge-lab-recorder.raw.v1","sequence":null,"source":"clob_market_ws"}
{"event_at":"2026-07-27T04:31:06.525000Z","event_fingerprint":"4e46d42acbbd238850c0d93b1541a5095188ade0b051f9e59d3e052c5a3d2ca4","payload":{"connection_id":"0f4979d6978d463e9660b042fdcf555f","event_at":"2026-07-27T04:31:06.525000Z","event_type":"price_change","frame_hash":"c266689fc55045b42641888c945c60c7be9f3f4dba053b3874dfd9503f343ccb","frame_index":0,"kind":"data","monotonic_ns":228655547349875,"payload":{"event_type":"price_change","market":"0xeb66215f2e9faa6449e30a02bab5b8ed7b79a38bf961f6b24d0073c9c2419250","price_changes":[{"asset_id":"60386828328910021732068595344565885737045900010034836345809386672230885527307","best_ask":"0.61","best_bid":"0.6","hash":"51303c79b3560d3440681dff1e9e3578690f5a43","price":"0.6","side":"BUY","size":"145.08"},{"asset_id":"69697746896130839564035629862476347944307040470122503199396727085502753297492","best_ask":"0.4","best_bid":"0.39","hash":"d2487dceb8c2df98752a98a3495fbd286c51b79d","price":"0.4","side":"SELL","size":"145.08"}],"timestamp":"1785126666525"},"payload_hash":"e35b0ea6efd7fe5e6a879ea7b8956b0a15df0d0d000a871f803c4fd1df66b9b6","raw_frame":"{\"market\":\"0xeb66215f2e9faa6449e30a02bab5b8ed7b79a38bf961f6b24d0073c9c2419250\", \"price_changes\":[{\"asset_id\":\"60386828328910021732068595344565885737045900010034836345809386672230885527307\", \"price\":\"0.6\", \"size\":\"145.08\", \"side\":\"BUY\", \"hash\":\"51303c79b3560d3440681dff1e9e3578690f5a43\", \"best_bid\":\"0.6\", \"best_ask\":\"0.61\"}, {\"asset_id\":\"69697746896130839564035629862476347944307040470122503199396727085502753297492\", \"price\":\"0.4\", \"size\":\"145.08\", \"side\":\"SELL\", \"hash\":\"d2487dceb8c2df98752a98a3495fbd286c51b79d\", \"best_bid\":\"0.39\", \"best_ask\":\"0.4\"}], \"timestamp\":\"1785126666525\", \"event_type\":\"price_change\"}","received_at":"2026-07-27T04:31:12.278139Z","schema_version":"clob-market-ws.price_change.v1","sequence":null,"server_hash":null,"server_timestamp":"1785126666525","session_id":"e9443c7415a0419799bee9cfbb1a9e4d","source":"clob_market_ws"},"received_at":"2026-07-27T04:31:12.278139Z","record_id":"b0f900d60db061caf3be933708d560d2c358adf3b130933f597e6c1b78bc3591","schema_fingerprint":"4aa3821a28b0b7c2400bc59aba4bcc0a76e971dadd19610d3ad38c768e124dc7","schema_version":"edge-lab-recorder.raw.v1","sequence":null,"source":"clob_market_ws"}
{"event_at":"2026-07-27T04:31:06.526000Z","event_fingerprint":"2814c276161f0397522ecd9f19a2aeb3bfe9dc050b0e40cd821905cc1863f29b","payload":{"connection_id":"0f4979d6978d463e9660b042fdcf555f","event_at":"2026-07-27T04:31:06.526000Z","event_type":"price_change","frame_hash":"e58403f8c3c3f54f748a748df1f54095b55486af351d9ced537a4b102a0e2b32","frame_index":0,"kind":"data","monotonic_ns":228655552539291,"payload":{"event_type":"price_change","market":"0xeb66215f2e9faa6449e30a02bab5b8ed7b79a38bf961f6b24d0073c9c2419250","price_changes":[{"asset_id":"60386828328910021732068595344565885737045900010034836345809386672230885527307","best_ask":"0.61","best_bid":"0.6","hash":"42f63f45c463e271ad38e46c39b855e8148e7fd2","price":"0.53","side":"BUY","size":"59.22"},{"asset_id":"69697746896130839564035629862476347944307040470122503199396727085502753297492","best_ask":"0.4","best_bid":"0.39","hash":"567e0c89e574c1c35b5e6cdc9dec0b75acf41201","price":"0.47","side":"SELL","size":"59.22"}],"timestamp":"1785126666526"},"payload_hash":"be410f1d5799cb62e032816f5289aafddca200037420bfee9ef1392476ab36bf","raw_frame":"{\"market\":\"0xeb66215f2e9faa6449e30a02bab5b8ed7b79a38bf961f6b24d0073c9c2419250\", \"price_changes\":[{\"asset_id\":\"60386828328910021732068595344565885737045900010034836345809386672230885527307\", \"price\":\"0.53\", \"size\":\"59.22\", \"side\":\"BUY\", \"hash\":\"42f63f45c463e271ad38e46c39b855e8148e7fd2\", \"best_bid\":\"0.6\", \"best_ask\":\"0.61\"}, {\"asset_id\":\"69697746896130839564035629862476347944307040470122503199396727085502753297492\", \"price\":\"0.47\", \"size\":\"59.22\", \"side\":\"SELL\", \"hash\":\"567e0c89e574c1c35b5e6cdc9dec0b75acf41201\", \"best_bid\":\"0.39\", \"best_ask\":\"0.4\"}], \"timestamp\":\"1785126666526\", \"event_type\":\"price_change\"}","received_at":"2026-07-27T04:31:12.283326Z","schema_version":"clob-market-ws.price_change.v1","sequence":null,"server_hash":null,"server_timestamp":"1785126666526","session_id":"e9443c7415a0419799bee9cfbb1a9e4d","source":"clob_market_ws"},"received_at":"2026-07-27T04:31:12.283326Z","record_id":"b642e2a2c1dbb6575131ee7437a70b3d4781387c29e2f9bd776f93dce51851d4","schema_fingerprint":"4aa3821a28b0b7c2400bc59aba4bcc0a76e971dadd19610d3ad38c768e124dc7","schema_version":"edge-lab-recorder.raw.v1","sequence":null,"source":"clob_market_ws"}
{"event_at":"2026-07-27T04:31:06.526000Z","event_fingerprint":"efb749dac2a3eef4fda63192914fdf2cc491956c4b4b74861e06ee150babba01","payload":{"connection_id":"0f4979d6978d463e9660b042fdcf555f","event_at":"2026-07-27T04:31:06.526000Z","event_type":"price_change","frame_hash":"311c5b63354e4f70d2eb2fac9eca66b644b05dba3948d44ac458aad91b6c134c","frame_index":0,"kind":"data","monotonic_ns":228655558407125,"payload":{"event_type":"price_change","market":"0xeb66215f2e9faa6449e30a02bab5b8ed7b79a38bf961f6b24d0073c9c2419250","price_changes":[{"asset_id":"60386828328910021732068595344565885737045900010034836345809386672230885527307","best_ask":"0.61","best_bid":"0.6","hash":"b145a90d2035232809ba1e5d4724ac474f8dfe3f","price":"0.53","side":"BUY","size":"29.22"},{"asset_id":"69697746896130839564035629862476347944307040470122503199396727085502753297492","best_ask":"0.4","best_bid":"0.39","hash":"177075ae9dc0be86b3342a064acb5e0950125f77","price":"0.47","side":"SELL","size":"29.22"}],"timestamp":"1785126666526"},"payload_hash":"01ebccec0387735edf2b372cd620964886ac273ebf2df01206d7ecd1b394d4da","raw_frame":"{\"market\":\"0xeb66215f2e9faa6449e30a02bab5b8ed7b79a38bf961f6b24d0073c9c2419250\", \"price_changes\":[{\"asset_id\":\"60386828328910021732068595344565885737045900010034836345809386672230885527307\", \"price\":\"0.53\", \"size\":\"29.22\", \"side\":\"BUY\", \"hash\":\"b145a90d2035232809ba1e5d4724ac474f8dfe3f\", \"best_bid\":\"0.6\", \"best_ask\":\"0.61\"}, {\"asset_id\":\"69697746896130839564035629862476347944307040470122503199396727085502753297492\", \"price\":\"0.47\", \"size\":\"29.22\", \"side\":\"SELL\", \"hash\":\"177075ae9dc0be86b3342a064acb5e0950125f77\", \"best_bid\":\"0.39\", \"best_ask\":\"0.4\"}], \"timestamp\":\"1785126666526\", \"event_type\":\"price_change\"}","received_at":"2026-07-27T04:31:12.289197Z","schema_version":"clob-market-ws.price_change.v1","sequence":null,"server_hash":null,"server_timestamp":"1785126666526","session_id":"e9443c7415a0419799bee9cfbb1a9e4d","source":"clob_market_ws"},"received_at":"2026-07-27T04:31:12.289197Z","record_id":"fef5d08cbd0e4430aded2f7fd5620b5ccdb4971bb827ebb9592e32be7dbffca5","schema_fingerprint":"4aa3821a28b0b7c2400bc59aba4bcc0a76e971dadd19610d3ad38c768e124dc7","schema_version":"edge-lab-recorder.raw.v1","sequence":null,"source":"clob_market_ws"}
{"event_at":"2026-07-27T04:31:06.527000Z","event_fingerprint":"6bec34554a664105fd22030320c525a2a5f4d1a1e4a249cbe7ecc5b8efafddea","payload":{"connection_id":"0f4979d6978d463e9660b042fdcf555f","event_at":"2026-07-27T04:31:06.527000Z","event_type":"price_change","frame_hash":"5418466b04a973b607541ea4d13d1f4913e5005eca43ce57d74420a09070b883","frame_index":0,"kind":"data","monotonic_ns":228655565062250,"payload":{"event_type":"price_change","market":"0xeb66215f2e9faa6449e30a02bab5b8ed7b79a38bf961f6b24d0073c9c2419250","price_changes":[{"asset_id":"60386828328910021732068595344565885737045900010034836345809386672230885527307","best_ask":"0.61","best_bid":"0.6","hash":"12799ad7de6275e8292a8326bf632614f2516c9c","price":"0.49","side":"BUY","size":"26"},{"asset_id":"69697746896130839564035629862476347944307040470122503199396727085502753297492","best_ask":"0.4","best_bid":"0.39","hash":"455b7d58257130a9fa6021902cad1d2876869e80","price":"0.51","side":"SELL","size":"26"}],"timestamp":"1785126666527"},"payload_hash":"08ad7c1d17d4a5475dc198f5ba07a0384543accb668b90a34c3e38ebc3771401","raw_frame":"{\"market\":\"0xeb66215f2e9faa6449e30a02bab5b8ed7b79a38bf961f6b24d0073c9c2419250\", \"price_changes\":[{\"asset_id\":\"60386828328910021732068595344565885737045900010034836345809386672230885527307\", \"price\":\"0.49\", \"size\":\"26\", \"side\":\"BUY\", \"hash\":\"12799ad7de6275e8292a8326bf632614f2516c9c\", \"best_bid\":\"0.6\", \"best_ask\":\"0.61\"}, {\"asset_id\":\"69697746896130839564035629862476347944307040470122503199396727085502753297492\", \"price\":\"0.51\", \"size\":\"26\", \"side\":\"SELL\", \"hash\":\"455b7d58257130a9fa6021902cad1d2876869e80\", \"best_bid\":\"0.39\", \"best_ask\":\"0.4\"}], \"timestamp\":\"1785126666527\", \"event_type\":\"price_change\"}","received_at":"2026-07-27T04:31:12.295852Z","schema_version":"clob-market-ws.price_change.v1","sequence":null,"server_hash":null,"server_timestamp":"1785126666527","session_id":"e9443c7415a0419799bee9cfbb1a9e4d","source":"clob_market_ws"},"received_at":"2026-07-27T04:31:12.295852Z","record_id":"d4ecee0b4ebb4c4ff11a2cc9f18012100f82c98c76bf18b89d665ee18d11039e","schema_fingerprint":"4aa3821a28b0b7c2400bc59aba4bcc0a76e971dadd19610d3ad38c768e124dc7","schema_version":"edge-lab-recorder.raw.v1","sequence":null,"source":"clob_market_ws"}
{"event_at":"2026-07-27T04:31:06.527000Z","event_fingerprint":"14dee1e200ec2761b790d4442dcf64926179c73f0125ff6bd82c0e55fb8f303f","payload":{"connection_id":"0f4979d6978d463e9660b042fdcf555f","event_at":"2026-07-27T04:31:06.527000Z","event_type":"price_change","frame_hash":"6484d287f76e3a623f5aaae84d6305588a42e4c680610a0158357987e8d10bec","frame_index":0,"kind":"data","monotonic_ns":228655570269333,"payload":{"event_type":"price_change","market":"0xeb66215f2e9faa6449e30a02bab5b8ed7b79a38bf961f6b24d0073c9c2419250","price_changes":[{"asset_id":"60386828328910021732068595344565885737045900010034836345809386672230885527307","best_ask":"0.61","best_bid":"0.6","hash":"a63dfae5c1b7f5c6022b2274fcbd3c18e261ca24","price":"0.6","side":"BUY","size":"156.08"},{"asset_id":"69697746896130839564035629862476347944307040470122503199396727085502753297492","best_ask":"0.4","best_bid":"0.39","hash":"35ccbc29f7a3183c64d6cc0ebd0c7bcc97042924","price":"0.4","side":"SELL","size":"156.08"}],"timestamp":"1785126666527"},"payload_hash":"91906420a8903481f18f7c5461cbcad9d49995e6a0c593c193e64fcdc1521f23","raw_frame":"{\"market\":\"0xeb66215f2e9faa6449e30a02bab5b8ed7b79a38bf961f6b24d0073c9c2419250\", \"price_changes\":[{\"asset_id\":\"60386828328910021732068595344565885737045900010034836345809386672230885527307\", \"price\":\"0.6\", \"size\":\"156.08\", \"side\":\"BUY\", \"hash\":\"a63dfae5c1b7f5c6022b2274fcbd3c18e261ca24\", \"best_bid\":\"0.6\", \"best_ask\":\"0.61\"}, {\"asset_id\":\"69697746896130839564035629862476347944307040470122503199396727085502753297492\", \"price\":\"0.4\", \"size\":\"156.08\", \"side\":\"SELL\", \"hash\":\"35ccbc29f7a3183c64d6cc0ebd0c7bcc97042924\", \"best_bid\":\"0.39\", \"best_ask\":\"0.4\"}], \"timestamp\":\"1785126666527\", \"event_type\":\"price_change\"}","received_at":"2026-07-27T04:31:12.301056Z","schema_version":"clob-market-ws.price_change.v1","sequence":null,"server_hash":null,"server_timestamp":"1785126666527","session_id":"e9443c7415a0419799bee9cfbb1a9e4d","source":"clob_market_ws"},"received_at":"2026-07-27T04:31:12.301056Z","record_id":"683ec48e4450760d51e5800cb29ed71b980fc23838f7d4da3ab29daa1d6e6d7d","schema_fingerprint":"4aa3821a28b0b7c2400bc59aba4bcc0a76e971dadd19610d3ad38c768e124dc7","schema_version":"edge-lab-recorder.raw.v1","sequence":null,"source":"clob_market_ws"}
