{"event_at":"2026-07-27T04:38:04.797000Z","event_fingerprint":"2a0259bc325c76ff0acc178c145ecf431b735bb93ef711606b680b8e601041c6","payload":{"connection_id":"0f4979d6978d463e9660b042fdcf555f","event_at":"2026-07-27T04:38:04.797000Z","event_type":"price_change","frame_hash":"accc8cc8f67055f1441209e93c4c190bc483644092751bd297208d475b078742","frame_index":0,"kind":"data","monotonic_ns":229068055326083,"payload":{"event_type":"price_change","market":"0xeb66215f2e9faa6449e30a02bab5b8ed7b79a38bf961f6b24d0073c9c2419250","price_changes":[{"asset_id":"60386828328910021732068595344565885737045900010034836345809386672230885527307","best_ask":"0.17","best_bid":"0.16","hash":"8476345a07083f4ba0e2545614a8336c03cb346f","price":"0.17","side":"SELL","size":"191.39"},{"asset_id":"69697746896130839564035629862476347944307040470122503199396727085502753297492","best_ask":"0.84","best_bid":"0.83","hash":"2c747eccfd75e3b90c52bdb64cb1562228e6c82d","price":"0.83","side":"BUY","size":"191.39"}],"timestamp":"1785127084797"},"payload_hash":"cf8d77d85450583787d3efb30be2953bca0665a42db67fb3d75fe5db56878120","raw_frame":"{\"market\":\"0xeb66215f2e9faa6449e30a02bab5b8ed7b79a38bf961f6b24d0073c9c2419250\", \"price_changes\":[{\"asset_id\":\"60386828328910021732068595344565885737045900010034836345809386672230885527307\", \"price\":\"0.17\", \"size\":\"191.39\", \"side\":\"SELL\", \"hash\":\"8476345a07083f4ba0e2545614a8336c03cb346f\", \"best_bid\":\"0.16\", \"best_ask\":\"0.17\"}, {\"asset_id\":\"69697746896130839564035629862476347944307040470122503199396727085502753297492\", \"price\":\"0.83\", \"size\":\"191.39\", \"side\":\"BUY\", \"hash\":\"2c747eccfd75e3b90c52bdb64cb1562228e6c82d\", \"best_bid\":\"0.83\", \"best_ask\":\"0.84\"}], \"timestamp\":\"1785127084797\", \"event_type\":\"price_change\"}","received_at":"2026-07-27T04:38:04.789685Z","schema_version":"clob-market-ws.price_change.v1","sequence":null,"server_hash":null,"server_timestamp":"1785127084797","session_id":"e9443c7415a0419799bee9cfbb1a9e4d","source":"clob_market_ws"},"received_at":"2026-07-27T04:38:04.789685Z","record_id":"da0c993da7781882f9b7c9f1ff83a251e700addaefc675d15c2915723a80a01e","schema_fingerprint":"4aa3821a28b0b7c2400bc59aba4bcc0a76e971dadd19610d3ad38c768e124dc7","schema_version":"edge-lab-recorder.raw.v1","sequence":null,"source":"clob_market_ws"}
{"event_at":"2026-07-27T04:38:04.802000Z","event_fingerprint":"d41ab61f32312aac37cede0a14561f41bef8c9593dd5dc7e80f501e609f74f79","payload":{"connection_id":"0f4979d6978d463e9660b042fdcf555f","event_at":"2026-07-27T04:38:04.802000Z","event_type":"price_change","frame_hash":"171c94e8c1084be4db763f78f303f00ccd158da0ae3400f3cfc8b2674024d001","frame_index":0,"kind":"data","monotonic_ns":229068057874916,"payload":{"event_type":"price_change","market":"0xeb66215f2e9faa6449e30a02bab5b8ed7b79a38bf961f6b24d0073c9c2419250","price_changes":[{"asset_id":"69697746896130839564035629862476347944307040470122503199396727085502753297492","best_ask":"0.84","best_bid":"0.83","hash":"8ee4b4172ef544cd21fb484df3448b2971eda1bf","price":"0.03","side":"BUY","size":"613.1"},{"asset_id":"60386828328910021732068595344565885737045900010034836345809386672230885527307","best_ask":"0.17","best_bid":"0.16","hash":"c9cf8aeafc6705b4d3099d27ab2f7d0e5c57991a","price":"0.97","side":"SELL","size":"613.1"}],"timestamp":"1785127084802"},"payload_hash":"53bfdf9ff3f8fef268dce4f1dc072bfc0acbf56f925638934e95c7ac1633c5aa","raw_frame":"{\"market\":\"0xeb66215f2e9faa6449e30a02bab5b8ed7b79a38bf961f6b24d0073c9c2419250\", \"price_changes\":[{\"asset_id\":\"69697746896130839564035629862476347944307040470122503199396727085502753297492\", \"price\":\"0.03\", \"size\":\"613.1\", \"side\":\"BUY\", \"hash\":\"8ee4b4172ef544cd21fb484df3448b2971eda1bf\", \"best_bid\":\"0.83\", \"best_ask\":\"0.84\"}, {\"asset_id\":\"60386828328910021732068595344565885737045900010034836345809386672230885527307\", \"price\":\"0.97\", \"size\":\"613.1\", \"side\":\"SELL\", \"hash\":\"c9cf8aeafc6705b4d3099d27ab2f7d0e5c57991a\", \"best_bid\":\"0.16\", \"best_ask\":\"0.17\"}], \"timestamp\":\"1785127084802\", \"event_type\":\"price_change\"}","received_at":"2026-07-27T04:38:04.792239Z","schema_version":"clob-market-ws.price_change.v1","sequence":null,"server_hash":null,"server_timestamp":"1785127084802","session_id":"e9443c7415a0419799bee9cfbb1a9e4d","source":"clob_market_ws"},"received_at":"2026-07-27T04:38:04.792239Z","record_id":"ed9065d9aac0768820467ca66e9e87c5bd9f5b2f9d9ea61d3e1aa8a591a8c30c","schema_fingerprint":"4aa3821a28b0b7c2400bc59aba4bcc0a76e971dadd19610d3ad38c768e124dc7","schema_version":"edge-lab-recorder.raw.v1","sequence":null,"source":"clob_market_ws"}
{"event_at":"2026-07-27T04:38:04.811000Z","event_fingerprint":"52348fb1f46dbe317f8dacfbe70e152518d4d6e678feeb8651e1f01b6a805bdd","payload":{"connection_id":"0f4979d6978d463e9660b042fdcf555f","event_at":"2026-07-27T04:38:04.811000Z","event_type":"price_change","frame_hash":"e56e8bcc7298250905dd4c0fcf3aaceb46d06388a6cd0b282105fbb7e2b7a8b9","frame_index":0,"kind":"data","monotonic_ns":229068059744125,"payload":{"event_type":"price_change","market":"0xeb66215f2e9faa6449e30a02bab5b8ed7b79a38bf961f6b24d0073c9c2419250","price_changes":[{"asset_id":"69697746896130839564035629862476347944307040470122503199396727085502753297492","best_ask":"0.84","best_bid":"0.83","hash":"3174ee7d04c037ef71f42b18aad963a74f4944c7","price":"0.78","side":"BUY","size":"170.77"},{"asset_id":"60386828328910021732068595344565885737045900010034836345809386672230885527307","best_ask":"0.17","best_bid":"0.16","hash":"d9529dda92a98f0bb9cc38da9a5c50ef83622da0","price":"0.22","side":"SELL","size":"170.77"}],"timestamp":"1785127084811"},"payload_hash":"fa5015dc171aa4eb0b57dd157c17736b0df2ce5ec6b4cb3d131816bfb6b744d0","raw_frame":"{\"market\":\"0xeb66215f2e9faa6449e30a02bab5b8ed7b79a38bf961f6b24d0073c9c2419250\", \"price_changes\":[{\"asset_id\":\"69697746896130839564035629862476347944307040470122503199396727085502753297492\", \"price\":\"0.78\", \"size\":\"170.77\", \"side\":\"BUY\", \"hash\":\"3174ee7d04c037ef71f42b18aad963a74f4944c7\", \"best_bid\":\"0.83\", \"best_ask\":\"0.84\"}, {\"asset_id\":\"60386828328910021732068595344565885737045900010034836345809386672230885527307\", \"price\":\"0.22\", \"size\":\"170.77\", \"side\":\"SELL\", \"hash\":\"d9529dda92a98f0bb9cc38da9a5c50ef83622da0\", \"best_bid\":\"0.16\", \"best_ask\":\"0.17\"}], \"timestamp\":\"1785127084811\", \"event_type\":\"price_change\"}","received_at":"2026-07-27T04:38:04.794110Z","schema_version":"clob-market-ws.price_change.v1","sequence":null,"server_hash":null,"server_timestamp":"1785127084811","session_id":"e9443c7415a0419799bee9cfbb1a9e4d","source":"clob_market_ws"},"received_at":"2026-07-27T04:38:04.794110Z","record_id":"5068cc5da2b4135d8beb21eb57309c23925c516a52b9f3350f6d8c7093bf8632","schema_fingerprint":"4aa3821a28b0b7c2400bc59aba4bcc0a76e971dadd19610d3ad38c768e124dc7","schema_version":"edge-lab-recorder.raw.v1","sequence":null,"source":"clob_market_ws"}
{"event_at":null,"event_fingerprint":"ae732d0ae43e8af11d93752341a179153414fafcc8a77b2eafa4ada64edb3ccd","payload":{"connection_id":"0f4979d6978d463e9660b042fdcf555f","event_type":"heartbeat_ack","frame_hash":"95784973cc639977bff93619700168505cb8f7855e44fa643d34622a43706c87","kind":"lifecycle","monotonic_ns":229068061328500,"raw_frame":"PONG","received_at":"2026-07-27T04:38:04.795696Z","schema_version":"edge-lab-recorder.heartbeat-ack.v1","session_id":"e9443c7415a0419799bee9cfbb1a9e4d","source":"clob_market_ws"},"received_at":"2026-07-27T04:38:04.795696Z","record_id":"14d52c80fe339202ff05cda807c9386d78e5d05687e40716721377cb4c720ce5","schema_fingerprint":"c14ee1aab3ca674ee738e5268877b544d74c41ad3c427cedc09236467dc68ba1","schema_version":"edge-lab-recorder.raw.v1","sequence":null,"source":"clob_market_ws"}
{"event_at":"2026-07-27T04:38:04.834000Z","event_fingerprint":"db17fe808dbaedafb05b50bda96b650bc98a715bf4d4dc9e9b50fa0eec90a058","payload":{"connection_id":"0f4979d6978d463e9660b042fdcf555f","event_at":"2026-07-27T04:38:04.834000Z","event_type":"price_change","frame_hash":"34496689425bd5b7d40d4c114331c833cc85c544cc264c33b4930313be51ed7f","frame_index":0,"kind":"data","monotonic_ns":229068061968500,"payload":{"event_type":"price_change","market":"0xeb66215f2e9faa6449e30a02bab5b8ed7b79a38bf961f6b24d0073c9c2419250","price_changes":[{"asset_id":"69697746896130839564035629862476347944307040470122503199396727085502753297492","best_ask":"0.84","best_bid":"0.83","hash":"eac422bdfe63af3e06053778ba78b01d26b9c6b0","price":"0.82","side":"BUY","size":"38.4"},{"asset_id":"60386828328910021732068595344565885737045900010034836345809386672230885527307","best_ask":"0.17","best_bid":"0.16","hash":"6d299598a8dfa424dabeb86ded468f38586a623d","price":"0.18","side":"SELL","size":"38.4"}],"timestamp":"1785127084834"},"payload_hash":"1bb3d62ba12ff721d6407315c3f28f192aef904f07b038f47195cfa2bb6b34f6","raw_frame":"{\"market\":\"0xeb66215f2e9faa6449e30a02bab5b8ed7b79a38bf961f6b24d0073c9c2419250\", \"price_changes\":[{\"asset_id\":\"69697746896130839564035629862476347944307040470122503199396727085502753297492\", \"price\":\"0.82\", \"size\":\"38.4\", \"side\":\"BUY\", \"hash\":\"eac422bdfe63af3e06053778ba78b01d26b9c6b0\", \"best_bid\":\"0.83\", \"best_ask\":\"0.84\"}, {\"asset_id\":\"60386828328910021732068595344565885737045900010034836345809386672230885527307\", \"price\":\"0.18\", \"size\":\"38.4\", \"side\":\"SELL\", \"hash\":\"6d299598a8dfa424dabeb86ded468f38586a623d\", \"best_bid\":\"0.16\", \"best_ask\":\"0.17\"}], \"timestamp\":\"1785127084834\", \"event_type\":\"price_change\"}","received_at":"2026-07-27T04:38:04.796336Z","schema_version":"clob-market-ws.price_change.v1","sequence":null,"server_hash":null,"server_timestamp":"1785127084834","session_id":"e9443c7415a0419799bee9cfbb1a9e4d","source":"clob_market_ws"},"received_at":"2026-07-27T04:38:04.796336Z","record_id":"855b6f6cb96df86253eab15d4c40e75702856e676f25cf96fcf062b8e79f4653","schema_fingerprint":"4aa3821a28b0b7c2400bc59aba4bcc0a76e971dadd19610d3ad38c768e124dc7","schema_version":"edge-lab-recorder.raw.v1","sequence":null,"source":"clob_market_ws"}
{"event_at":"2026-07-27T04:38:04.885000Z","event_fingerprint":"5eaf4dc90dabac0acc62491325755dd3d9a70879d9369e1e4088f97f54d463e0","payload":{"connection_id":"0f4979d6978d463e9660b042fdcf555f","event_at":"2026-07-27T04:38:04.885000Z","event_type":"price_change","frame_hash":"b7eeec71f61d4116ccf60caf2f81a4392109d3f596b904bd223ac42388e0cc78","frame_index":0,"kind":"data","monotonic_ns":229068096190875,"payload":{"event_type":"price_change","market":"0xeb66215f2e9faa6449e30a02bab5b8ed7b79a38bf961f6b24d0073c9c2419250","price_changes":[{"asset_id":"69697746896130839564035629862476347944307040470122503199396727085502753297492","best_ask":"0.84","best_bid":"0.83","hash":"afe41edb88081d7fe73da79c21bf9f5ea2791039","price":"0.83","side":"BUY","size":"181.79"},{"asset_id":"60386828328910021732068595344565885737045900010034836345809386672230885527307","best_ask":"0.17","best_bid":"0.16","hash":"a22906725b814e2e3309bdcca8ef56c1cb0629cc","price":"0.17","side":"SELL","size":"181.79"}],"timestamp":"1785127084885"},"payload_hash":"b225bd3f98b255c26cb0d4913a842192ac47b0c9ab51209a15889be897b4584d","raw_frame":"{\"market\":\"0xeb66215f2e9faa6449e30a02bab5b8ed7b79a38bf961f6b24d0073c9c2419250\", \"price_changes\":[{\"asset_id\":\"69697746896130839564035629862476347944307040470122503199396727085502753297492\", \"price\":\"0.83\", \"size\":\"181.79\", \"side\":\"BUY\", \"hash\":\"afe41edb88081d7fe73da79c21bf9f5ea2791039\", \"best_bid\":\"0.83\", \"best_ask\":\"0.84\"}, {\"asset_id\":\"60386828328910021732068595344565885737045900010034836345809386672230885527307\", \"price\":\"0.17\", \"size\":\"181.79\", \"side\":\"SELL\", \"hash\":\"a22906725b814e2e3309bdcca8ef56c1cb0629cc\", \"best_bid\":\"0.16\", \"best_ask\":\"0.17\"}], \"timestamp\":\"1785127084885\", \"event_type\":\"price_change\"}","received_at":"2026-07-27T04:38:04.830551Z","schema_version":"clob-market-ws.price_change.v1","sequence":null,"server_hash":null,"server_timestamp":"1785127084885","session_id":"e9443c7415a0419799bee9cfbb1a9e4d","source":"clob_market_ws"},"received_at":"2026-07-27T04:38:04.830551Z","record_id":"0f80c3ace5c79def22518bac54151685a1c16183b71e7c6fbb9bec572fd79c76","schema_fingerprint":"4aa3821a28b0b7c2400bc59aba4bcc0a76e971dadd19610d3ad38c768e124dc7","schema_version":"edge-lab-recorder.raw.v1","sequence":null,"source":"clob_market_ws"}
{"event_at":"2026-07-27T04:38:04.886000Z","event_fingerprint":"8726139600f80beef27804eb3ecc402cf30863d3e160b2504755da679f8420cb","payload":{"connection_id":"0f4979d6978d463e9660b042fdcf555f","event_at":"2026-07-27T04:38:04.886000Z","event_type":"price_change","frame_hash":"7d1638de176ac675555431791abdeed32e25d83be2ada445d42b42c674384adb","frame_index":0,"kind":"data","monotonic_ns":229068098278333,"payload":{"event_type":"price_change","market":"0xeb66215f2e9faa6449e30a02bab5b8ed7b79a38bf961f6b24d0073c9c2419250","price_changes":[{"asset_id":"60386828328910021732068595344565885737045900010034836345809386672230885527307","best_ask":"0.17","best_bid":"0.16","hash":"e2f0e8cdfffbee5a6885ca17b5ee11ebb438cf75","price":"0.14","side":"BUY","size":"25.13"},{"asset_id":"69697746896130839564035629862476347944307040470122503199396727085502753297492","best_ask":"0.84","best_bid":"0.83","hash":"35419669349d868d7914088dd46954b06e0b8104","price":"0.86","side":"SELL","size":"25.13"}],"timestamp":"1785127084886"},"payload_hash":"702912b8b641d0bf0f652e745e6e7ae2cc29f3b64571c18722170043fb8e1076","raw_frame":"{\"market\":\"0xeb66215f2e9faa6449e30a02bab5b8ed7b79a38bf961f6b24d0073c9c2419250\", \"price_changes\":[{\"asset_id\":\"60386828328910021732068595344565885737045900010034836345809386672230885527307\", \"price\":\"0.14\", \"size\":\"25.13\", \"side\":\"BUY\", \"hash\":\"e2f0e8cdfffbee5a6885ca17b5ee11ebb438cf75\", \"best_bid\":\"0.16\", \"best_ask\":\"0.17\"}, {\"asset_id\":\"69697746896130839564035629862476347944307040470122503199396727085502753297492\", \"price\":\"0.86\", \"size\":\"25.13\", \"side\":\"SELL\", \"hash\":\"35419669349d868d7914088dd46954b06e0b8104\", \"best_bid\":\"0.83\", \"best_ask\":\"0.84\"}], \"timestamp\":\"1785127084886\", \"event_type\":\"price_change\"}","received_at":"2026-07-27T04:38:04.832643Z","schema_version":"clob-market-ws.price_change.v1","sequence":null,"server_hash":null,"server_timestamp":"1785127084886","session_id":"e9443c7415a0419799bee9cfbb1a9e4d","source":"clob_market_ws"},"received_at":"2026-07-27T04:38:04.832643Z","record_id":"e2e342bd17b7fd5adadc61ef213181b7e66d113b565ba1a4f03b4fa00d748c96","schema_fingerprint":"4aa3821a28b0b7c2400bc59aba4bcc0a76e971dadd19610d3ad38c768e124dc7","schema_version":"edge-lab-recorder.raw.v1","sequence":null,"source":"clob_market_ws"}
{"event_at":"2026-07-27T04:38:04.888000Z","event_fingerprint":"dcaf0b32b81fdb1e4e0708144a05a6c302840f284d957e8cd25b2cf3e1b02c07","payload":{"connection_id":"0f4979d6978d463e9660b042fdcf555f","event_at":"2026-07-27T04:38:04.888000Z","event_type":"price_change","frame_hash":"64435648691442339659c3f723edb02a98c6ace53d99084451bbcb9774004e41","frame_index":0,"kind":"data","monotonic_ns":229068100387291,"payload":{"event_type":"price_change","market":"0xeb66215f2e9faa6449e30a02bab5b8ed7b79a38bf961f6b24d0073c9c2419250","price_changes":[{"asset_id":"69697746896130839564035629862476347944307040470122503199396727085502753297492","best_ask":"0.84","best_bid":"0.83","hash":"7dd4047f0d9a6d78cac800d86dffffd32e5725c4","price":"0.83","side":"BUY","size":"164.99"},{"asset_id":"60386828328910021732068595344565885737045900010034836345809386672230885527307","best_ask":"0.17","best_bid":"0.16","hash":"63fe0b6f899b334089c1a1bdddb672bc66311c69","price":"0.17","side":"SELL","size":"164.99"}],"timestamp":"1785127084888"},"payload_hash":"5a111660f29e5d0e1f9a6f7c68d06c278b453f9236d20b620ee9f7aee88ea88e","raw_frame":"{\"market\":\"0xeb66215f2e9faa6449e30a02bab5b8ed7b79a38bf961f6b24d0073c9c2419250\", \"price_changes\":[{\"asset_id\":\"69697746896130839564035629862476347944307040470122503199396727085502753297492\", \"price\":\"0.83\", \"size\":\"164.99\", \"side\":\"BUY\", \"hash\":\"7dd4047f0d9a6d78cac800d86dffffd32e5725c4\", \"best_bid\":\"0.83\", \"best_ask\":\"0.84\"}, {\"asset_id\":\"60386828328910021732068595344565885737045900010034836345809386672230885527307\", \"price\":\"0.17\", \"size\":\"164.99\", \"side\":\"SELL\", \"hash\":\"63fe0b6f899b334089c1a1bdddb672bc66311c69\", \"best_bid\":\"0.16\", \"best_ask\":\"0.17\"}], \"timestamp\":\"1785127084888\", \"event_type\":\"price_change\"}","received_at":"2026-07-27T04:38:04.834752Z","schema_version":"clob-market-ws.price_change.v1","sequence":null,"server_hash":null,"server_timestamp":"1785127084888","session_id":"e9443c7415a0419799bee9cfbb1a9e4d","source":"clob_market_ws"},"received_at":"2026-07-27T04:38:04.834752Z","record_id":"16ab6a0a4db5114ff4681ca068336c24557673fe07f2be14a3ce1bb121dc54a0","schema_fingerprint":"4aa3821a28b0b7c2400bc59aba4bcc0a76e971dadd19610d3ad38c768e124dc7","schema_version":"edge-lab-recorder.raw.v1","sequence":null,"source":"clob_market_ws"}
{"event_at":"2026-07-27T04:38:04.888000Z","event_fingerprint":"c7caf637b2f3b0958354adc5a94528e0b634a27c92252cb344cca37f01cf20c3","payload":{"connection_id":"0f4979d6978d463e9660b042fdcf555f","event_at":"2026-07-27T04:38:04.888000Z","event_type":"price_change","frame_hash":"bafe7bf0f798c985be88ec8779ad340b82bddb187c62fd30a75e16a4318fee3a","frame_index":0,"kind":"data","monotonic_ns":229068102252458,"payload":{"event_type":"price_change","market":"0xeb66215f2e9faa6449e30a02bab5b8ed7b79a38bf961f6b24d0073c9c2419250","price_changes":[{"asset_id":"69697746896130839564035629862476347944307040470122503199396727085502753297492","best_ask":"0.84","best_bid":"0.83","hash":"e1d7581b0bd6630b1dba753c0749769896fa605d","price":"0.83","side":"BUY","size":"68.99"},{"asset_id":"60386828328910021732068595344565885737045900010034836345809386672230885527307","best_ask":"0.17","best_bid":"0.16","hash":"f5330e03f414b72c1aa8ff105e83df14340604d0","price":"0.17","side":"SELL","size":"68.99"}],"timestamp":"1785127084888"},"payload_hash":"c5a6c26b99f8bf027552c33e1a2b694974af7af9dd98ca914ea8219f226df2fe","raw_frame":"{\"market\":\"0xeb66215f2e9faa6449e30a02bab5b8ed7b79a38bf961f6b24d0073c9c2419250\", \"price_changes\":[{\"asset_id\":\"69697746896130839564035629862476347944307040470122503199396727085502753297492\", \"price\":\"0.83\", \"size\":\"68.99\", \"side\":\"BUY\", \"hash\":\"e1d7581b0bd6630b1dba753c0749769896fa605d\", \"best_bid\":\"0.83\", \"best_ask\":\"0.84\"}, {\"asset_id\":\"60386828328910021732068595344565885737045900010034836345809386672230885527307\", \"price\":\"0.17\", \"size\":\"68.99\", \"side\":\"SELL\", \"hash\":\"f5330e03f414b72c1aa8ff105e83df14340604d0\", \"best_bid\":\"0.16\", \"best_ask\":\"0.17\"}], \"timestamp\":\"1785127084888\", \"event_type\":\"price_change\"}","received_at":"2026-07-27T04:38:04.836616Z","schema_version":"clob-market-ws.price_change.v1","sequence":null,"server_hash":null,"server_timestamp":"1785127084888","session_id":"e9443c7415a0419799bee9cfbb1a9e4d","source":"clob_market_ws"},"received_at":"2026-07-27T04:38:04.836616Z","record_id":"ef87d69c5cc8776cfa250d07cdaf5161c210825ae3fb2a7d4371199d1aa9b01c","schema_fingerprint":"4aa3821a28b0b7c2400bc59aba4bcc0a76e971dadd19610d3ad38c768e124dc7","schema_version":"edge-lab-recorder.raw.v1","sequence":null,"source":"clob_market_ws"}
{"event_at":"2026-07-27T04:38:04.889000Z","event_fingerprint":"65eefe4d58232bacd8a00c809639439ebec36af84611591fadbb6fa26782ae02","payload":{"connection_id":"0f4979d6978d463e9660b042fdcf555f","event_at":"2026-07-27T04:38:04.889000Z","event_type":"price_change","frame_hash":"a2326764cac550cee432b61100f3c0dda2d2faae6cf8efad04ab861a63f831c6","frame_index":0,"kind":"data","monotonic_ns":229068104045000,"payload":{"event_type":"price_change","market":"0xeb66215f2e9faa6449e30a02bab5b8ed7b79a38bf961f6b24d0073c9c2419250","price_changes":[{"asset_id":"69697746896130839564035629862476347944307040470122503199396727085502753297492","best_ask":"0.84","best_bid":"0.83","hash":"79ea8d582ef6063557562e0112e91972710da2ea","price":"0.82","side":"BUY","size":"134.4"},{"asset_id":"60386828328910021732068595344565885737045900010034836345809386672230885527307","best_ask":"0.17","best_bid":"0.16","hash":"a87d206f91a3e213f616b73a25bc3adb094178b0","price":"0.18","side":"SELL","size":"134.4"}],"timestamp":"1785127084889"},"payload_hash":"ab284869abbbb3f95f09555fedbc870d35a0af3fd3d9006248f7ddc07ef1f237","raw_frame":"{\"market\":\"0xeb66215f2e9faa6449e30a02bab5b8ed7b79a38bf961f6b24d0073c9c2419250\", \"price_changes\":[{\"asset_id\":\"69697746896130839564035629862476347944307040470122503199396727085502753297492\", \"price\":\"0.82\", \"size\":\"134.4\", \"side\":\"BUY\", \"hash\":\"79ea8d582ef6063557562e0112e91972710da2ea\", \"best_bid\":\"0.83\", \"best_ask\":\"0.84\"}, {\"asset_id\":\"60386828328910021732068595344565885737045900010034836345809386672230885527307\", \"price\":\"0.18\", \"size\":\"134.4\", \"side\":\"SELL\", \"hash\":\"a87d206f91a3e213f616b73a25bc3adb094178b0\", \"best_bid\":\"0.16\", \"best_ask\":\"0.17\"}], \"timestamp\":\"1785127084889\", \"event_type\":\"price_change\"}","received_at":"2026-07-27T04:38:04.838413Z","schema_version":"clob-market-ws.price_change.v1","sequence":null,"server_hash":null,"server_timestamp":"1785127084889","session_id":"e9443c7415a0419799bee9cfbb1a9e4d","source":"clob_market_ws"},"received_at":"2026-07-27T04:38:04.838413Z","record_id":"370bedbd78c26f50c75502397790428e6528d7b4a120ef06d34e911714d70448","schema_fingerprint":"4aa3821a28b0b7c2400bc59aba4bcc0a76e971dadd19610d3ad38c768e124dc7","schema_version":"edge-lab-recorder.raw.v1","sequence":null,"source":"clob_market_ws"}
{"event_at":"2026-07-27T04:38:04.894000Z","event_fingerprint":"95e1f200a5abd654abff0877a229379310fe1bd9796a2fded04f843dcd23fd53","payload":{"connection_id":"0f4979d6978d463e9660b042fdcf555f","event_at":"2026-07-27T04:38:04.894000Z","event_type":"price_change","frame_hash":"da6b77716d1692f99449bee4fa96e82e765b624ce40be4844f4db65f5f6eee2c","frame_index":0,"kind":"data","monotonic_ns":229068105777625,"payload":{"event_type":"price_change","market":"0xeb66215f2e9faa6449e30a02bab5b8ed7b79a38bf961f6b24d0073c9c2419250","price_changes":[{"asset_id":"69697746896130839564035629862476347944307040470122503199396727085502753297492","best_ask":"0.84","best_bid":"0.83","hash":"28e6846561b39208c4354b54f9edfb81b0ecf560","price":"0.81","side":"BUY","size":"33.9"},{"asset_id":"60386828328910021732068595344565885737045900010034836345809386672230885527307","best_ask":"0.17","best_bid":"0.16","hash":"0f71394c6bd338a3e73c7260bc0dda2aa8ee7945","price":"0.19","side":"SELL","size":"33.9"}],"timestamp":"1785127084894"},"payload_hash":"92e4baa1f937df0a08c9dbb3137567b0e795317829e56e7cff5660b0a4fa6c78","raw_frame":"{\"market\":\"0xeb66215f2e9faa6449e30a02bab5b8ed7b79a38bf961f6b24d0073c9c2419250\", \"price_changes\":[{\"asset_id\":\"69697746896130839564035629862476347944307040470122503199396727085502753297492\", \"price\":\"0.81\", \"size\":\"33.9\", \"side\":\"BUY\", \"hash\":\"28e6846561b39208c4354b54f9edfb81b0ecf560\", \"best_bid\":\"0.83\", \"best_ask\":\"0.84\"}, {\"asset_id\":\"60386828328910021732068595344565885737045900010034836345809386672230885527307\", \"price\":\"0.19\", \"size\":\"33.9\", \"side\":\"SELL\", \"hash\":\"0f71394c6bd338a3e73c7260bc0dda2aa8ee7945\", \"best_bid\":\"0.16\", \"best_ask\":\"0.17\"}], \"timestamp\":\"1785127084894\", \"event_type\":\"price_change\"}","received_at":"2026-07-27T04:38:04.840144Z","schema_version":"clob-market-ws.price_change.v1","sequence":null,"server_hash":null,"server_timestamp":"1785127084894","session_id":"e9443c7415a0419799bee9cfbb1a9e4d","source":"clob_market_ws"},"received_at":"2026-07-27T04:38:04.840144Z","record_id":"5b56d394380d593f77618ba6e32b8d6eac6d741721efe160662076b0ef0ead0a","schema_fingerprint":"4aa3821a28b0b7c2400bc59aba4bcc0a76e971dadd19610d3ad38c768e124dc7","schema_version":"edge-lab-recorder.raw.v1","sequence":null,"source":"clob_market_ws"}
{"event_at":"2026-07-27T04:38:04.895000Z","event_fingerprint":"f3f5768680ca0a7d5aa88c466e072846938108482a917113affc12aff6dc9390","payload":{"connection_id":"0f4979d6978d463e9660b042fdcf555f","event_at":"2026-07-27T04:38:04.895000Z","event_type":"price_change","frame_hash":"4d45acf43777c813147ff257ba59f7fb8468252b1e004c741804943783c909a1","frame_index":0,"kind":"data","monotonic_ns":229068107618541,"payload":{"event_type":"price_change","market":"0xeb66215f2e9faa6449e30a02bab5b8ed7b79a38bf961f6b24d0073c9c2419250","price_changes":[{"asset_id":"69697746896130839564035629862476347944307040470122503199396727085502753297492","best_ask":"0.84","best_bid":"0.83","hash":"8e954289f27857441560803b836d2265bac936a4","price":"0.82","side":"BUY","size":"122.4"},{"asset_id":"60386828328910021732068595344565885737045900010034836345809386672230885527307","best_ask":"0.17","best_bid":"0.16","hash":"35d8b5fb9347d8b7d6d06f3a5c6d7b5746bf6898","price":"0.18","side":"SELL","size":"122.4"}],"timestamp":"1785127084895"},"payload_hash":"97302a0e737836865bd7c77099e110c4c4f8976131d4a44849a4d36c8bfa8747","raw_frame":"{\"market\":\"0xeb66215f2e9faa6449e30a02bab5b8ed7b79a38bf961f6b24d0073c9c2419250\", \"price_changes\":[{\"asset_id\":\"69697746896130839564035629862476347944307040470122503199396727085502753297492\", \"price\":\"0.82\", \"size\":\"122.4\", \"side\":\"BUY\", \"hash\":\"8e954289f27857441560803b836d2265bac936a4\", \"best_bid\":\"0.83\", \"best_ask\":\"0.84\"}, {\"asset_id\":\"60386828328910021732068595344565885737045900010034836345809386672230885527307\", \"price\":\"0.18\", \"size\":\"122.4\", \"side\":\"SELL\", \"hash\":\"35d8b5fb9347d8b7d6d06f3a5c6d7b5746bf6898\", \"best_bid\":\"0.16\", \"best_ask\":\"0.17\"}], \"timestamp\":\"1785127084895\", \"event_type\":\"price_change\"}","received_at":"2026-07-27T04:38:04.841985Z","schema_version":"clob-market-ws.price_change.v1","sequence":null,"server_hash":null,"server_timestamp":"1785127084895","session_id":"e9443c7415a0419799bee9cfbb1a9e4d","source":"clob_market_ws"},"received_at":"2026-07-27T04:38:04.841985Z","record_id":"38f69f38be714c3e0de085c7430205b6291307ad247843169b825b037f8e23e6","schema_fingerprint":"4aa3821a28b0b7c2400bc59aba4bcc0a76e971dadd19610d3ad38c768e124dc7","schema_version":"edge-lab-recorder.raw.v1","sequence":null,"source":"clob_market_ws"}
{"event_at":"2026-07-27T04:38:04.895000Z","event_fingerprint":"0c21d7382a806062bbb89dca957bd51491068c5aa1d84eff2df04184142ff2b5","payload":{"connection_id":"0f4979d6978d463e9660b042fdcf555f","event_at":"2026-07-27T04:38:04.895000Z","event_type":"price_change","frame_hash":"72750ac6aa340ae4b761f13e55918bd100f67c9cfc3470b38cd55d6fe5eee918","frame_index":0,"kind":"data","monotonic_ns":229068109352791,"payload":{"event_type":"price_change","market":"0xeb66215f2e9faa6449e30a02bab5b8ed7b79a38bf961f6b24d0073c9c2419250","price_changes":[{"asset_id":"60386828328910021732068595344565885737045900010034836345809386672230885527307","best_ask":"0.17","best_bid":"0.16","hash":"bbd6aa20af8d455ba14ed14e99ffa130aea9cf08","price":"0.17","side":"SELL","size":"29.59"},{"asset_id":"69697746896130839564035629862476347944307040470122503199396727085502753297492","best_ask":"0.84","best_bid":"0.83","hash":"95ba9b93e99f1fcbb6b83ad8b5d0f9326b166b6c","price":"0.83","side":"BUY","size":"29.59"}],"timestamp":"1785127084895"},"payload_hash":"da6676b54e615a6d8c47cafb946f65a8fe3df81c62a0b506a7a156f3d870d305","raw_frame":"{\"market\":\"0xeb66215f2e9faa6449e30a02bab5b8ed7b79a38bf961f6b24d0073c9c2419250\", \"price_changes\":[{\"asset_id\":\"60386828328910021732068595344565885737045900010034836345809386672230885527307\", \"price\":\"0.17\", \"size\":\"29.59\", \"side\":\"SELL\", \"hash\":\"bbd6aa20af8d455ba14ed14e99ffa130aea9cf08\", \"best_bid\":\"0.16\", \"best_ask\":\"0.17\"}, {\"asset_id\":\"69697746896130839564035629862476347944307040470122503199396727085502753297492\", \"price\":\"0.83\", \"size\":\"29.59\", \"side\":\"BUY\", \"hash\":\"95ba9b93e99f1fcbb6b83ad8b5d0f9326b166b6c\", \"best_bid\":\"0.83\", \"best_ask\":\"0.84\"}], \"timestamp\":\"1785127084895\", \"event_type\":\"price_change\"}","received_at":"2026-07-27T04:38:04.843720Z","schema_version":"clob-market-ws.price_change.v1","sequence":null,"server_hash":null,"server_timestamp":"1785127084895","session_id":"e9443c7415a0419799bee9cfbb1a9e4d","source":"clob_market_ws"},"received_at":"2026-07-27T04:38:04.843720Z","record_id":"3271b4f23278e949d6614cfc000ce8080ea8605cbd9093e65a24b1facc95a506","schema_fingerprint":"4aa3821a28b0b7c2400bc59aba4bcc0a76e971dadd19610d3ad38c768e124dc7","schema_version":"edge-lab-recorder.raw.v1","sequence":null,"source":"clob_market_ws"}
{"event_at":"2026-07-27T04:38:04.898000Z","event_fingerprint":"630c4f1c3190e834395f0cb27dda282d6c94d8e6ccc7922028f470bbcf0e1615","payload":{"connection_id":"0f4979d6978d463e9660b042fdcf555f","event_at":"2026-07-27T04:38:04.898000Z","event_type":"price_change","frame_hash":"ed9b3bddb0f46b293ff93c1f0bc03dbf6530bacd69d9ff78e6e032394d5b0b2a","frame_index":0,"kind":"data","monotonic_ns":229068110869666,"payload":{"event_type":"price_change","market":"0xeb66215f2e9faa6449e30a02bab5b8ed7b79a38bf961f6b24d0073c9c2419250","price_changes":[{"asset_id":"69697746896130839564035629862476347944307040470122503199396727085502753297492","best_ask":"0.84","best_bid":"0.83","hash":"c398bbd5df93c3c0622e1fc441e27b37bde3e65a","price":"0.8","side":"BUY","size":"54.95"},{"asset_id":"60386828328910021732068595344565885737045900010034836345809386672230885527307","best_ask":"0.17","best_bid":"0.16","hash":"2d41593a6db99078492983cdcc67c199229810b4","price":"0.2","side":"SELL","size":"54.95"}],"timestamp":"1785127084898"},"payload_hash":"3898f91033e8f45fd21545b3bd0b018a445c8fdd530af313ec39f88d3cf4f19d","raw_frame":"{\"market\":\"0xeb66215f2e9faa6449e30a02bab5b8ed7b79a38bf961f6b24d0073c9c2419250\", \"price_changes\":[{\"asset_id\":\"69697746896130839564035629862476347944307040470122503199396727085502753297492\", \"price\":\"0.8\", \"size\":\"54.95\", \"side\":\"BUY\", \"hash\":\"c398bbd5df93c3c0622e1fc441e27b37bde3e65a\", \"best_bid\":\"0.83\", \"best_ask\":\"0.84\"}, {\"asset_id\":\"60386828328910021732068595344565885737045900010034836345809386672230885527307\", \"price\":\"0.2\", \"size\":\"54.95\", \"side\":\"SELL\", \"hash\":\"2d41593a6db99078492983cdcc67c199229810b4\", \"best_bid\":\"0.16\", \"best_ask\":\"0.17\"}], \"timestamp\":\"1785127084898\", \"event_type\":\"price_change\"}","received_at":"2026-07-27T04:38:04.845238Z","schema_version":"clob-market-ws.price_change.v1","sequence":null,"server_hash":null,"server_timestamp":"1785127084898","session_id":"e9443c7415a0419799bee9cfbb1a9e4d","source":"clob_market_ws"},"received_at":"2026-07-27T04:38:04.845238Z","record_id":"a0f936ca61a3edd849858767e331befefa2fd4f0478e4d0e9b7fc6400e069aa1","schema_fingerprint":"4aa3821a28b0b7c2400bc59aba4bcc0a76e971dadd19610d3ad38c768e124dc7","schema_version":"edge-lab-recorder.raw.v1","sequence":null,"source":"clob_market_ws"}
{"event_at":"2026-07-27T04:38:04.899000Z","event_fingerprint":"2b3dcecaf07660116719aa4a92f620b320ffff054985c9ffc683c24f31704041","payload":{"connection_id":"0f4979d6978d463e9660b042fdcf555f","event_at":"2026-07-27T04:38:04.899000Z","event_type":"price_change","frame_hash":"696bc7e5a7cd82d802515719859465019e1f5f96acd9b591a8e0a74c11d06ade","frame_index":0,"kind":"data","monotonic_ns":229068112545958,"payload":{"event_type":"price_change","market":"0xeb66215f2e9faa6449e30a02bab5b8ed7b79a38bf961f6b24d0073c9c2419250","price_changes":[{"asset_id":"69697746896130839564035629862476347944307040470122503199396727085502753297492","best_ask":"0.84","best_bid":"0.83","hash":"95046fcb53ed12d75212c6abaa4106cfa3f75389","price":"0.83","side":"BUY","size":"63.92"},{"asset_id":"60386828328910021732068595344565885737045900010034836345809386672230885527307","best_ask":"0.17","best_bid":"0.16","hash":"4534f305fbd2d8a89327f1de38abd0534164ad1a","price":"0.17","side":"SELL","size":"63.92"}],"timestamp":"1785127084899"},"payload_hash":"79415f54e5d270e3bb72d0f11503453eb100e0f4d92020594bc07c48405d7a66","raw_frame":"{\"market\":\"0xeb66215f2e9faa6449e30a02bab5b8ed7b79a38bf961f6b24d0073c9c2419250\", \"price_changes\":[{\"asset_id\":\"69697746896130839564035629862476347944307040470122503199396727085502753297492\", \"price\":\"0.83\", \"size\":\"63.92\", \"side\":\"BUY\", \"hash\":\"95046fcb53ed12d75212c6abaa4106cfa3f75389\", \"best_bid\":\"0.83\", \"best_ask\":\"0.84\"}, {\"asset_id\":\"60386828328910021732068595344565885737045900010034836345809386672230885527307\", \"price\":\"0.17\", \"size\":\"63.92\", \"side\":\"SELL\", \"hash\":\"4534f305fbd2d8a89327f1de38abd0534164ad1a\", \"best_bid\":\"0.16\", \"best_ask\":\"0.17\"}], \"timestamp\":\"1785127084899\", \"event_type\":\"price_change\"}","received_at":"2026-07-27T04:38:04.846912Z","schema_version":"clob-market-ws.price_change.v1","sequence":null,"server_hash":null,"server_timestamp":"1785127084899","session_id":"e9443c7415a0419799bee9cfbb1a9e4d","source":"clob_market_ws"},"received_at":"2026-07-27T04:38:04.846912Z","record_id":"2d14a95f7fd24a9f79d569d10d2453b788922a25e62c1defd9ea11f9a0a578ba","schema_fingerprint":"4aa3821a28b0b7c2400bc59aba4bcc0a76e971dadd19610d3ad38c768e124dc7","schema_version":"edge-lab-recorder.raw.v1","sequence":null,"source":"clob_market_ws"}
