{"event_at":"2026-07-27T04:44:14.350000Z","event_fingerprint":"58c7d073e05255c30d73171c967bae66af12e0d255cecee306f095b2e7813a26","payload":{"connection_id":"0f4979d6978d463e9660b042fdcf555f","event_at":"2026-07-27T04:44:14.350000Z","event_type":"best_bid_ask","frame_hash":"29d317c6ec4c55d7c012223c008aee34136aae522ab3108953dc83966a513bde","frame_index":0,"kind":"data","monotonic_ns":229437571273833,"payload":{"asset_id":"69697746896130839564035629862476347944307040470122503199396727085502753297492","best_ask":"0.999","best_bid":"0.996","event_type":"best_bid_ask","market":"0xeb66215f2e9faa6449e30a02bab5b8ed7b79a38bf961f6b24d0073c9c2419250","spread":"0.003","timestamp":"1785127454350"},"payload_hash":"08b3480ea7fb7d3264e33d5af4213ec003b3623bf5ddc77feea1d51e8b31c04b","raw_frame":"{\"market\":\"0xeb66215f2e9faa6449e30a02bab5b8ed7b79a38bf961f6b24d0073c9c2419250\", \"asset_id\":\"69697746896130839564035629862476347944307040470122503199396727085502753297492\", \"best_bid\":\"0.996\", \"best_ask\":\"0.999\", \"spread\":\"0.003\", \"timestamp\":\"1785127454350\", \"event_type\":\"best_bid_ask\"}","received_at":"2026-07-27T04:44:14.308839Z","schema_version":"clob-market-ws.best_bid_ask.v1","sequence":null,"server_hash":null,"server_timestamp":"1785127454350","session_id":"e9443c7415a0419799bee9cfbb1a9e4d","source":"clob_market_ws"},"received_at":"2026-07-27T04:44:14.308839Z","record_id":"32a8f8a539a337eabfee6a657ca639b2073523ba156679e5e984ddfa8ec15d24","schema_fingerprint":"8488399f31b0337811b13b266be932db7062827c2470b78bd8e9e99bab51d17d","schema_version":"edge-lab-recorder.raw.v1","sequence":null,"source":"clob_market_ws"}
{"event_at":"2026-07-27T04:44:14.350000Z","event_fingerprint":"d64022ac25a9ad88424fe07838f19db7ee835a85afca6d0266c03f75eb6ab9a5","payload":{"connection_id":"0f4979d6978d463e9660b042fdcf555f","event_at":"2026-07-27T04:44:14.350000Z","event_type":"best_bid_ask","frame_hash":"d426e67720c5217e4f777d58707db931869e177764b752c9d9f467960d6cadf1","frame_index":0,"kind":"data","monotonic_ns":229437572986500,"payload":{"asset_id":"60386828328910021732068595344565885737045900010034836345809386672230885527307","best_ask":"0.004","best_bid":"0.001","event_type":"best_bid_ask","market":"0xeb66215f2e9faa6449e30a02bab5b8ed7b79a38bf961f6b24d0073c9c2419250","spread":"0.003","timestamp":"1785127454350"},"payload_hash":"c2be2a5ee5e4a018ed07b4b77186c6c6c439682b380f61250c627bd4e155de82","raw_frame":"{\"market\":\"0xeb66215f2e9faa6449e30a02bab5b8ed7b79a38bf961f6b24d0073c9c2419250\", \"asset_id\":\"60386828328910021732068595344565885737045900010034836345809386672230885527307\", \"best_bid\":\"0.001\", \"best_ask\":\"0.004\", \"spread\":\"0.003\", \"timestamp\":\"1785127454350\", \"event_type\":\"best_bid_ask\"}","received_at":"2026-07-27T04:44:14.310553Z","schema_version":"clob-market-ws.best_bid_ask.v1","sequence":null,"server_hash":null,"server_timestamp":"1785127454350","session_id":"e9443c7415a0419799bee9cfbb1a9e4d","source":"clob_market_ws"},"received_at":"2026-07-27T04:44:14.310553Z","record_id":"70557dfe24fd239aca48a06a65e1c6ac5783a8c68e81ed5b2654b34d5d99e3a3","schema_fingerprint":"8488399f31b0337811b13b266be932db7062827c2470b78bd8e9e99bab51d17d","schema_version":"edge-lab-recorder.raw.v1","sequence":null,"source":"clob_market_ws"}
{"event_at":"2026-07-27T04:44:14.350000Z","event_fingerprint":"7f2b3dfecb244b17e5f1c335b24786995357d187bf08d2ae9b39e72d16235cd2","payload":{"connection_id":"0f4979d6978d463e9660b042fdcf555f","event_at":"2026-07-27T04:44:14.350000Z","event_type":"price_change","frame_hash":"05890d98798050459f59b4870f4750254910990db5c3d00e00de6c5a050b90ed","frame_index":0,"kind":"data","monotonic_ns":229437574052791,"payload":{"event_type":"price_change","market":"0xeb66215f2e9faa6449e30a02bab5b8ed7b79a38bf961f6b24d0073c9c2419250","price_changes":[{"asset_id":"60386828328910021732068595344565885737045900010034836345809386672230885527307","best_ask":"0.004","best_bid":"0.001","hash":"33b14a69589c4cdf400038c83320ca05f214c8f0","price":"0.003","side":"SELL","size":"0"},{"asset_id":"69697746896130839564035629862476347944307040470122503199396727085502753297492","best_ask":"0.999","best_bid":"0.996","hash":"5822b3a5dcc16b9cbb65b859a2b3864b7cbd9a70","price":"0.997","side":"BUY","size":"0"}],"timestamp":"1785127454350"},"payload_hash":"c9196f653670384bee15662ca47d32a49cfe94760e957993d391f7922a35fea6","raw_frame":"{\"market\":\"0xeb66215f2e9faa6449e30a02bab5b8ed7b79a38bf961f6b24d0073c9c2419250\", \"price_changes\":[{\"asset_id\":\"60386828328910021732068595344565885737045900010034836345809386672230885527307\", \"price\":\"0.003\", \"size\":\"0\", \"side\":\"SELL\", \"hash\":\"33b14a69589c4cdf400038c83320ca05f214c8f0\", \"best_bid\":\"0.001\", \"best_ask\":\"0.004\"}, {\"asset_id\":\"69697746896130839564035629862476347944307040470122503199396727085502753297492\", \"price\":\"0.997\", \"size\":\"0\", \"side\":\"BUY\", \"hash\":\"5822b3a5dcc16b9cbb65b859a2b3864b7cbd9a70\", \"best_bid\":\"0.996\", \"best_ask\":\"0.999\"}], \"timestamp\":\"1785127454350\", \"event_type\":\"price_change\"}","received_at":"2026-07-27T04:44:14.311621Z","schema_version":"clob-market-ws.price_change.v1","sequence":null,"server_hash":null,"server_timestamp":"1785127454350","session_id":"e9443c7415a0419799bee9cfbb1a9e4d","source":"clob_market_ws"},"received_at":"2026-07-27T04:44:14.311621Z","record_id":"a8b7f0cd654dd3fb91baae3fae6bf2af0d729e19d3f93094d0d8d7a74c16e9e5","schema_fingerprint":"4aa3821a28b0b7c2400bc59aba4bcc0a76e971dadd19610d3ad38c768e124dc7","schema_version":"edge-lab-recorder.raw.v1","sequence":null,"source":"clob_market_ws"}
{"event_at":"2026-07-27T04:44:14.360000Z","event_fingerprint":"a0c171f0701b49dace8fed2c70ad6c026686ef0a4af047a591a47db99d5c8459","payload":{"connection_id":"0f4979d6978d463e9660b042fdcf555f","event_at":"2026-07-27T04:44:14.360000Z","event_type":"price_change","frame_hash":"81f35d66023efdd26413b69dd2c2c28d9961d5207a920683a88c05d55e31f796","frame_index":0,"kind":"data","monotonic_ns":229437575632875,"payload":{"event_type":"price_change","market":"0xeb66215f2e9faa6449e30a02bab5b8ed7b79a38bf961f6b24d0073c9c2419250","price_changes":[{"asset_id":"69697746896130839564035629862476347944307040470122503199396727085502753297492","best_ask":"0.999","best_bid":"0.996","hash":"dcda42d9eed72ebbf30cf8e23e1225258c01db3c","price":"0.04","side":"BUY","size":"535"},{"asset_id":"60386828328910021732068595344565885737045900010034836345809386672230885527307","best_ask":"0.004","best_bid":"0.001","hash":"4870457eccde349267e194c94e8bcd949253d0cd","price":"0.96","side":"SELL","size":"535"}],"timestamp":"1785127454360"},"payload_hash":"e4837df27d8d3d1498f8881e5db76b6529584b78def2f422df60bea30fb0707a","raw_frame":"{\"market\":\"0xeb66215f2e9faa6449e30a02bab5b8ed7b79a38bf961f6b24d0073c9c2419250\", \"price_changes\":[{\"asset_id\":\"69697746896130839564035629862476347944307040470122503199396727085502753297492\", \"price\":\"0.04\", \"size\":\"535\", \"side\":\"BUY\", \"hash\":\"dcda42d9eed72ebbf30cf8e23e1225258c01db3c\", \"best_bid\":\"0.996\", \"best_ask\":\"0.999\"}, {\"asset_id\":\"60386828328910021732068595344565885737045900010034836345809386672230885527307\", \"price\":\"0.96\", \"size\":\"535\", \"side\":\"SELL\", \"hash\":\"4870457eccde349267e194c94e8bcd949253d0cd\", \"best_bid\":\"0.001\", \"best_ask\":\"0.004\"}], \"timestamp\":\"1785127454360\", \"event_type\":\"price_change\"}","received_at":"2026-07-27T04:44:14.313201Z","schema_version":"clob-market-ws.price_change.v1","sequence":null,"server_hash":null,"server_timestamp":"1785127454360","session_id":"e9443c7415a0419799bee9cfbb1a9e4d","source":"clob_market_ws"},"received_at":"2026-07-27T04:44:14.313201Z","record_id":"567eb63e866c2fe22de0be4d2616595f4f1fc77b2a901ab1c20385e0149bab5b","schema_fingerprint":"4aa3821a28b0b7c2400bc59aba4bcc0a76e971dadd19610d3ad38c768e124dc7","schema_version":"edge-lab-recorder.raw.v1","sequence":null,"source":"clob_market_ws"}
{"event_at":"2026-07-27T04:44:14.380000Z","event_fingerprint":"b2cfe1bc9c5f8db63321bc584de6de5ff1befbf129a761cbf5ddf97804039acc","payload":{"connection_id":"0f4979d6978d463e9660b042fdcf555f","event_at":"2026-07-27T04:44:14.380000Z","event_type":"best_bid_ask","frame_hash":"49c1937a3a376ca94542a8ddcb8cb7a991d1ad7800e8d6682970cd5a62cc9d1c","frame_index":0,"kind":"data","monotonic_ns":229437591349125,"payload":{"asset_id":"69697746896130839564035629862476347944307040470122503199396727085502753297492","best_ask":"0.999","best_bid":"0.997","event_type":"best_bid_ask","market":"0xeb66215f2e9faa6449e30a02bab5b8ed7b79a38bf961f6b24d0073c9c2419250","spread":"0.002","timestamp":"1785127454380"},"payload_hash":"ed2fa9e0ab1bbf3044e82fcd97546633c33654ff074766a52c17abd461a4732f","raw_frame":"{\"market\":\"0xeb66215f2e9faa6449e30a02bab5b8ed7b79a38bf961f6b24d0073c9c2419250\", \"asset_id\":\"69697746896130839564035629862476347944307040470122503199396727085502753297492\", \"best_bid\":\"0.997\", \"best_ask\":\"0.999\", \"spread\":\"0.002\", \"timestamp\":\"1785127454380\", \"event_type\":\"best_bid_ask\"}","received_at":"2026-07-27T04:44:14.328914Z","schema_version":"clob-market-ws.best_bid_ask.v1","sequence":null,"server_hash":null,"server_timestamp":"1785127454380","session_id":"e9443c7415a0419799bee9cfbb1a9e4d","source":"clob_market_ws"},"received_at":"2026-07-27T04:44:14.328914Z","record_id":"64e05e13387a8d28688c28ec80fd7e4bdc946dc61ac5e31b8cce18c77f56cec0","schema_fingerprint":"8488399f31b0337811b13b266be932db7062827c2470b78bd8e9e99bab51d17d","schema_version":"edge-lab-recorder.raw.v1","sequence":null,"source":"clob_market_ws"}
{"event_at":"2026-07-27T04:44:14.380000Z","event_fingerprint":"e7a4debcb69cce5fcbafb1f9a5d7962e78dacf78eecc68e7f9cc394c7abcf703","payload":{"connection_id":"0f4979d6978d463e9660b042fdcf555f","event_at":"2026-07-27T04:44:14.380000Z","event_type":"best_bid_ask","frame_hash":"83477ec9c19d666a8789f4aaa3ce7cbbda7f2f7fab6eb313e6815bf000c295f2","frame_index":0,"kind":"data","monotonic_ns":229437592443791,"payload":{"asset_id":"60386828328910021732068595344565885737045900010034836345809386672230885527307","best_ask":"0.003","best_bid":"0.001","event_type":"best_bid_ask","market":"0xeb66215f2e9faa6449e30a02bab5b8ed7b79a38bf961f6b24d0073c9c2419250","spread":"0.002","timestamp":"1785127454380"},"payload_hash":"4e4ba1b4ba601d20e5667253470190199dba64a1f79a1968b5d183568bb1624a","raw_frame":"{\"market\":\"0xeb66215f2e9faa6449e30a02bab5b8ed7b79a38bf961f6b24d0073c9c2419250\", \"asset_id\":\"60386828328910021732068595344565885737045900010034836345809386672230885527307\", \"best_bid\":\"0.001\", \"best_ask\":\"0.003\", \"spread\":\"0.002\", \"timestamp\":\"1785127454380\", \"event_type\":\"best_bid_ask\"}","received_at":"2026-07-27T04:44:14.330010Z","schema_version":"clob-market-ws.best_bid_ask.v1","sequence":null,"server_hash":null,"server_timestamp":"1785127454380","session_id":"e9443c7415a0419799bee9cfbb1a9e4d","source":"clob_market_ws"},"received_at":"2026-07-27T04:44:14.330010Z","record_id":"6f0195ddb2f43232fff35807cc3cfe40f26b1e3b2afca0109a6115f75fa2adba","schema_fingerprint":"8488399f31b0337811b13b266be932db7062827c2470b78bd8e9e99bab51d17d","schema_version":"edge-lab-recorder.raw.v1","sequence":null,"source":"clob_market_ws"}
{"event_at":"2026-07-27T04:44:14.380000Z","event_fingerprint":"d40eec03ae7fd592ff50fc647f4a61246873b7ecf9f8f68a2eafbd250b765c55","payload":{"connection_id":"0f4979d6978d463e9660b042fdcf555f","event_at":"2026-07-27T04:44:14.380000Z","event_type":"price_change","frame_hash":"77529706c059efa2907e2ed3a0e3f26406a9c14a73b187abe209257ff1bcd04a","frame_index":0,"kind":"data","monotonic_ns":229437593506375,"payload":{"event_type":"price_change","market":"0xeb66215f2e9faa6449e30a02bab5b8ed7b79a38bf961f6b24d0073c9c2419250","price_changes":[{"asset_id":"60386828328910021732068595344565885737045900010034836345809386672230885527307","best_ask":"0.003","best_bid":"0.001","hash":"d0471f785ae87db46baab440707d259baaf69d26","price":"0.003","side":"SELL","size":"275.12"},{"asset_id":"69697746896130839564035629862476347944307040470122503199396727085502753297492","best_ask":"0.999","best_bid":"0.997","hash":"93fcd94a548686fc94841f43b0dac2a1d2adef18","price":"0.997","side":"BUY","size":"275.12"}],"timestamp":"1785127454380"},"payload_hash":"2ed28d0670d7966d74633ec183991c4731230c8f0fa325495b393e8e66f7bb30","raw_frame":"{\"market\":\"0xeb66215f2e9faa6449e30a02bab5b8ed7b79a38bf961f6b24d0073c9c2419250\", \"price_changes\":[{\"asset_id\":\"60386828328910021732068595344565885737045900010034836345809386672230885527307\", \"price\":\"0.003\", \"size\":\"275.12\", \"side\":\"SELL\", \"hash\":\"d0471f785ae87db46baab440707d259baaf69d26\", \"best_bid\":\"0.001\", \"best_ask\":\"0.003\"}, {\"asset_id\":\"69697746896130839564035629862476347944307040470122503199396727085502753297492\", \"price\":\"0.997\", \"size\":\"275.12\", \"side\":\"BUY\", \"hash\":\"93fcd94a548686fc94841f43b0dac2a1d2adef18\", \"best_bid\":\"0.997\", \"best_ask\":\"0.999\"}], \"timestamp\":\"1785127454380\", \"event_type\":\"price_change\"}","received_at":"2026-07-27T04:44:14.331074Z","schema_version":"clob-market-ws.price_change.v1","sequence":null,"server_hash":null,"server_timestamp":"1785127454380","session_id":"e9443c7415a0419799bee9cfbb1a9e4d","source":"clob_market_ws"},"received_at":"2026-07-27T04:44:14.331074Z","record_id":"55a2b3668c660361f19e5ae352f76d207aab29fe7bc05051adbcea7a16727584","schema_fingerprint":"4aa3821a28b0b7c2400bc59aba4bcc0a76e971dadd19610d3ad38c768e124dc7","schema_version":"edge-lab-recorder.raw.v1","sequence":null,"source":"clob_market_ws"}
{"event_at":"2026-07-27T04:44:14.401000Z","event_fingerprint":"bcecb039ab93151025d23dba82cd14dbf55d67f0de40f37dc19d397270278c64","payload":{"connection_id":"0f4979d6978d463e9660b042fdcf555f","event_at":"2026-07-27T04:44:14.401000Z","event_type":"best_bid_ask","frame_hash":"eb96ac3168596e2d41574c017f35626cc3d26828fb0bf827a130e819a4e72ca0","frame_index":0,"kind":"data","monotonic_ns":229437613005708,"payload":{"asset_id":"69697746896130839564035629862476347944307040470122503199396727085502753297492","best_ask":"0.999","best_bid":"0.996","event_type":"best_bid_ask","market":"0xeb66215f2e9faa6449e30a02bab5b8ed7b79a38bf961f6b24d0073c9c2419250","spread":"0.003","timestamp":"1785127454401"},"payload_hash":"ad3c2cd8cf1977830b1183c3a7c7a7569357f3f368f84b50ed6acb9649cbc03e","raw_frame":"{\"market\":\"0xeb66215f2e9faa6449e30a02bab5b8ed7b79a38bf961f6b24d0073c9c2419250\", \"asset_id\":\"69697746896130839564035629862476347944307040470122503199396727085502753297492\", \"best_bid\":\"0.996\", \"best_ask\":\"0.999\", \"spread\":\"0.003\", \"timestamp\":\"1785127454401\", \"event_type\":\"best_bid_ask\"}","received_at":"2026-07-27T04:44:14.350573Z","schema_version":"clob-market-ws.best_bid_ask.v1","sequence":null,"server_hash":null,"server_timestamp":"1785127454401","session_id":"e9443c7415a0419799bee9cfbb1a9e4d","source":"clob_market_ws"},"received_at":"2026-07-27T04:44:14.350573Z","record_id":"a5aa03924f170677b97796100832d7aa5ecd4c5a33b95805203cedd40318665d","schema_fingerprint":"8488399f31b0337811b13b266be932db7062827c2470b78bd8e9e99bab51d17d","schema_version":"edge-lab-recorder.raw.v1","sequence":null,"source":"clob_market_ws"}
{"event_at":"2026-07-27T04:44:14.401000Z","event_fingerprint":"e5d485978f6dc8ff10b1242269825d6f69aaad8c446ef705e850534697146467","payload":{"connection_id":"0f4979d6978d463e9660b042fdcf555f","event_at":"2026-07-27T04:44:14.401000Z","event_type":"best_bid_ask","frame_hash":"93f168a3a6603c835c5f26d5765ac6061760a7a029dd7454312419cb09873f43","frame_index":0,"kind":"data","monotonic_ns":229437614049375,"payload":{"asset_id":"60386828328910021732068595344565885737045900010034836345809386672230885527307","best_ask":"0.004","best_bid":"0.001","event_type":"best_bid_ask","market":"0xeb66215f2e9faa6449e30a02bab5b8ed7b79a38bf961f6b24d0073c9c2419250","spread":"0.003","timestamp":"1785127454401"},"payload_hash":"a1f340527a3204324da7ec3b4dc9c1c5bfda019bdab9fb4336fbd131c9ff0cab","raw_frame":"{\"market\":\"0xeb66215f2e9faa6449e30a02bab5b8ed7b79a38bf961f6b24d0073c9c2419250\", \"asset_id\":\"60386828328910021732068595344565885737045900010034836345809386672230885527307\", \"best_bid\":\"0.001\", \"best_ask\":\"0.004\", \"spread\":\"0.003\", \"timestamp\":\"1785127454401\", \"event_type\":\"best_bid_ask\"}","received_at":"2026-07-27T04:44:14.351617Z","schema_version":"clob-market-ws.best_bid_ask.v1","sequence":null,"server_hash":null,"server_timestamp":"1785127454401","session_id":"e9443c7415a0419799bee9cfbb1a9e4d","source":"clob_market_ws"},"received_at":"2026-07-27T04:44:14.351617Z","record_id":"74d089b3f3f4f6156f03b4de1cfc78947a7c98556b499513bcc803a91b94a14b","schema_fingerprint":"8488399f31b0337811b13b266be932db7062827c2470b78bd8e9e99bab51d17d","schema_version":"edge-lab-recorder.raw.v1","sequence":null,"source":"clob_market_ws"}
{"event_at":"2026-07-27T04:44:14.401000Z","event_fingerprint":"6612d2f1621b2123aa46a8a10055a1327bf91942058f4e85e97e8d677fd90944","payload":{"connection_id":"0f4979d6978d463e9660b042fdcf555f","event_at":"2026-07-27T04:44:14.401000Z","event_type":"price_change","frame_hash":"8450a2d062c7e5fef79c884942ae988d34b040f225a5b817af33ac86e72a2c27","frame_index":0,"kind":"data","monotonic_ns":229437615114833,"payload":{"event_type":"price_change","market":"0xeb66215f2e9faa6449e30a02bab5b8ed7b79a38bf961f6b24d0073c9c2419250","price_changes":[{"asset_id":"60386828328910021732068595344565885737045900010034836345809386672230885527307","best_ask":"0.004","best_bid":"0.001","hash":"b4d98259ca82da80cacd3fd31266bbc69f579fee","price":"0.003","side":"SELL","size":"0"},{"asset_id":"69697746896130839564035629862476347944307040470122503199396727085502753297492","best_ask":"0.999","best_bid":"0.996","hash":"f1cdedc5771f7c22b6b0d58efb4f384b3e2c6487","price":"0.997","side":"BUY","size":"0"}],"timestamp":"1785127454401"},"payload_hash":"81f70d7a41d2542e3f8cbbe07bbd89715eba65a9d86acfe812104b276de30138","raw_frame":"{\"market\":\"0xeb66215f2e9faa6449e30a02bab5b8ed7b79a38bf961f6b24d0073c9c2419250\", \"price_changes\":[{\"asset_id\":\"60386828328910021732068595344565885737045900010034836345809386672230885527307\", \"price\":\"0.003\", \"size\":\"0\", \"side\":\"SELL\", \"hash\":\"b4d98259ca82da80cacd3fd31266bbc69f579fee\", \"best_bid\":\"0.001\", \"best_ask\":\"0.004\"}, {\"asset_id\":\"69697746896130839564035629862476347944307040470122503199396727085502753297492\", \"price\":\"0.997\", \"size\":\"0\", \"side\":\"BUY\", \"hash\":\"f1cdedc5771f7c22b6b0d58efb4f384b3e2c6487\", \"best_bid\":\"0.996\", \"best_ask\":\"0.999\"}], \"timestamp\":\"1785127454401\", \"event_type\":\"price_change\"}","received_at":"2026-07-27T04:44:14.352683Z","schema_version":"clob-market-ws.price_change.v1","sequence":null,"server_hash":null,"server_timestamp":"1785127454401","session_id":"e9443c7415a0419799bee9cfbb1a9e4d","source":"clob_market_ws"},"received_at":"2026-07-27T04:44:14.352683Z","record_id":"8a98000254ce75173a39d5a72d1380f8e8426094e28c443f0aa1fee1134ec917","schema_fingerprint":"4aa3821a28b0b7c2400bc59aba4bcc0a76e971dadd19610d3ad38c768e124dc7","schema_version":"edge-lab-recorder.raw.v1","sequence":null,"source":"clob_market_ws"}
{"event_at":"2026-07-27T04:44:14.434000Z","event_fingerprint":"2fe291bf15014b4c477640986e3d42063da298c5347cd4ed790d221b34e47f09","payload":{"connection_id":"0f4979d6978d463e9660b042fdcf555f","event_at":"2026-07-27T04:44:14.434000Z","event_type":"price_change","frame_hash":"25fd37202473230adafc4e1031be859fd973c64e13b0382128d5cefb9112c0ac","frame_index":0,"kind":"data","monotonic_ns":229437644992541,"payload":{"event_type":"price_change","market":"0xeb66215f2e9faa6449e30a02bab5b8ed7b79a38bf961f6b24d0073c9c2419250","price_changes":[{"asset_id":"69697746896130839564035629862476347944307040470122503199396727085502753297492","best_ask":"0.999","best_bid":"0.996","hash":"933d92fcc149dcf65f49314aa82bea21c0024172","price":"0.04","side":"BUY","size":"530"},{"asset_id":"60386828328910021732068595344565885737045900010034836345809386672230885527307","best_ask":"0.004","best_bid":"0.001","hash":"b15838160e15ddb5bdf1e4d1e8132b4f0ea8766e","price":"0.96","side":"SELL","size":"530"}],"timestamp":"1785127454434"},"payload_hash":"30769fc9c8db69db2b3fa4f2e156a7ef8f86d5f8798133335d620c8e45226529","raw_frame":"{\"market\":\"0xeb66215f2e9faa6449e30a02bab5b8ed7b79a38bf961f6b24d0073c9c2419250\", \"price_changes\":[{\"asset_id\":\"69697746896130839564035629862476347944307040470122503199396727085502753297492\", \"price\":\"0.04\", \"size\":\"530\", \"side\":\"BUY\", \"hash\":\"933d92fcc149dcf65f49314aa82bea21c0024172\", \"best_bid\":\"0.996\", \"best_ask\":\"0.999\"}, {\"asset_id\":\"60386828328910021732068595344565885737045900010034836345809386672230885527307\", \"price\":\"0.96\", \"size\":\"530\", \"side\":\"SELL\", \"hash\":\"b15838160e15ddb5bdf1e4d1e8132b4f0ea8766e\", \"best_bid\":\"0.001\", \"best_ask\":\"0.004\"}], \"timestamp\":\"1785127454434\", \"event_type\":\"price_change\"}","received_at":"2026-07-27T04:44:14.382560Z","schema_version":"clob-market-ws.price_change.v1","sequence":null,"server_hash":null,"server_timestamp":"1785127454434","session_id":"e9443c7415a0419799bee9cfbb1a9e4d","source":"clob_market_ws"},"received_at":"2026-07-27T04:44:14.382560Z","record_id":"78fedf7d8fd13ef2c06525b7bf05cca663ac1f726ebd2504e83b0a5bc64b8389","schema_fingerprint":"4aa3821a28b0b7c2400bc59aba4bcc0a76e971dadd19610d3ad38c768e124dc7","schema_version":"edge-lab-recorder.raw.v1","sequence":null,"source":"clob_market_ws"}
{"event_at":"2026-07-27T04:44:14.439000Z","event_fingerprint":"b978676a943452b7df6a8a2c4d39a349f7a7cc3bc2d35947380f39e349160dd3","payload":{"connection_id":"0f4979d6978d463e9660b042fdcf555f","event_at":"2026-07-27T04:44:14.439000Z","event_type":"best_bid_ask","frame_hash":"a3c0b514bdce4f874b2d1ebd185ff66f74798c599b051b544cf9604228161de7","frame_index":0,"kind":"data","monotonic_ns":229437649043416,"payload":{"asset_id":"69697746896130839564035629862476347944307040470122503199396727085502753297492","best_ask":"0.999","best_bid":"0.997","event_type":"best_bid_ask","market":"0xeb66215f2e9faa6449e30a02bab5b8ed7b79a38bf961f6b24d0073c9c2419250","spread":"0.002","timestamp":"1785127454439"},"payload_hash":"e48b0ffe6dabddcb29c276defc538349ac446168333959e66a947bc7b573befb","raw_frame":"{\"market\":\"0xeb66215f2e9faa6449e30a02bab5b8ed7b79a38bf961f6b24d0073c9c2419250\", \"asset_id\":\"69697746896130839564035629862476347944307040470122503199396727085502753297492\", \"best_bid\":\"0.997\", \"best_ask\":\"0.999\", \"spread\":\"0.002\", \"timestamp\":\"1785127454439\", \"event_type\":\"best_bid_ask\"}","received_at":"2026-07-27T04:44:14.386609Z","schema_version":"clob-market-ws.best_bid_ask.v1","sequence":null,"server_hash":null,"server_timestamp":"1785127454439","session_id":"e9443c7415a0419799bee9cfbb1a9e4d","source":"clob_market_ws"},"received_at":"2026-07-27T04:44:14.386609Z","record_id":"8e085bd1fee6b66a801465836f651f286b1632130d336ae683b8de304adda5f0","schema_fingerprint":"8488399f31b0337811b13b266be932db7062827c2470b78bd8e9e99bab51d17d","schema_version":"edge-lab-recorder.raw.v1","sequence":null,"source":"clob_market_ws"}
{"event_at":"2026-07-27T04:44:14.439000Z","event_fingerprint":"8bf615ba2173a59f003b945026a0aea91ea6846a3d5f15ffc02481f2e9eafb0c","payload":{"connection_id":"0f4979d6978d463e9660b042fdcf555f","event_at":"2026-07-27T04:44:14.439000Z","event_type":"best_bid_ask","frame_hash":"19a2aa088b2652a9e4b6c881147df95205bf5ca67cd6cf6cc5d87d1db086760d","frame_index":0,"kind":"data","monotonic_ns":229437650103666,"payload":{"asset_id":"60386828328910021732068595344565885737045900010034836345809386672230885527307","best_ask":"0.003","best_bid":"0.001","event_type":"best_bid_ask","market":"0xeb66215f2e9faa6449e30a02bab5b8ed7b79a38bf961f6b24d0073c9c2419250","spread":"0.002","timestamp":"1785127454439"},"payload_hash":"15f153fb92639744ca0e99a3d8d86198b8d50f3dfe7f9a0d87bfeec78e64c111","raw_frame":"{\"market\":\"0xeb66215f2e9faa6449e30a02bab5b8ed7b79a38bf961f6b24d0073c9c2419250\", \"asset_id\":\"60386828328910021732068595344565885737045900010034836345809386672230885527307\", \"best_bid\":\"0.001\", \"best_ask\":\"0.003\", \"spread\":\"0.002\", \"timestamp\":\"1785127454439\", \"event_type\":\"best_bid_ask\"}","received_at":"2026-07-27T04:44:14.387678Z","schema_version":"clob-market-ws.best_bid_ask.v1","sequence":null,"server_hash":null,"server_timestamp":"1785127454439","session_id":"e9443c7415a0419799bee9cfbb1a9e4d","source":"clob_market_ws"},"received_at":"2026-07-27T04:44:14.387678Z","record_id":"f95db34d2cf758481a8965fb9e19e022f7c9cb3b15d7f3e6579ed7b0ec869056","schema_fingerprint":"8488399f31b0337811b13b266be932db7062827c2470b78bd8e9e99bab51d17d","schema_version":"edge-lab-recorder.raw.v1","sequence":null,"source":"clob_market_ws"}
{"event_at":"2026-07-27T04:44:14.439000Z","event_fingerprint":"2e87aa9e4331fc077fa603cbe2e7c4a4f6b5be439d814ad3624eccdc60084d69","payload":{"connection_id":"0f4979d6978d463e9660b042fdcf555f","event_at":"2026-07-27T04:44:14.439000Z","event_type":"price_change","frame_hash":"459c818a0d17a5f0680744f17e578670776528b9111fefa779a8cf3a36578c8e","frame_index":0,"kind":"data","monotonic_ns":229437650481833,"payload":{"event_type":"price_change","market":"0xeb66215f2e9faa6449e30a02bab5b8ed7b79a38bf961f6b24d0073c9c2419250","price_changes":[{"asset_id":"60386828328910021732068595344565885737045900010034836345809386672230885527307","best_ask":"0.003","best_bid":"0.001","hash":"ce21194cfeb8739a3824148296aa9d8c5a35277f","price":"0.003","side":"SELL","size":"275.12"},{"asset_id":"69697746896130839564035629862476347944307040470122503199396727085502753297492","best_ask":"0.999","best_bid":"0.997","hash":"8e268ea72c2d45a18e8e604674c0517f2b5c0d1d","price":"0.997","side":"BUY","size":"275.12"}],"timestamp":"1785127454439"},"payload_hash":"f8845559686c83e36b668b323a3c14d0cd3e69e03304124f1412a11761045c28","raw_frame":"{\"market\":\"0xeb66215f2e9faa6449e30a02bab5b8ed7b79a38bf961f6b24d0073c9c2419250\", \"price_changes\":[{\"asset_id\":\"60386828328910021732068595344565885737045900010034836345809386672230885527307\", \"price\":\"0.003\", \"size\":\"275.12\", \"side\":\"SELL\", \"hash\":\"ce21194cfeb8739a3824148296aa9d8c5a35277f\", \"best_bid\":\"0.001\", \"best_ask\":\"0.003\"}, {\"asset_id\":\"69697746896130839564035629862476347944307040470122503199396727085502753297492\", \"price\":\"0.997\", \"size\":\"275.12\", \"side\":\"BUY\", \"hash\":\"8e268ea72c2d45a18e8e604674c0517f2b5c0d1d\", \"best_bid\":\"0.997\", \"best_ask\":\"0.999\"}], \"timestamp\":\"1785127454439\", \"event_type\":\"price_change\"}","received_at":"2026-07-27T04:44:14.388056Z","schema_version":"clob-market-ws.price_change.v1","sequence":null,"server_hash":null,"server_timestamp":"1785127454439","session_id":"e9443c7415a0419799bee9cfbb1a9e4d","source":"clob_market_ws"},"received_at":"2026-07-27T04:44:14.388056Z","record_id":"91c8455b67d6553fdb36e6078a746004aff0f3bff93e0d225f1d2a7064d3bf0f","schema_fingerprint":"4aa3821a28b0b7c2400bc59aba4bcc0a76e971dadd19610d3ad38c768e124dc7","schema_version":"edge-lab-recorder.raw.v1","sequence":null,"source":"clob_market_ws"}
{"event_at":"2026-07-27T04:44:14.455000Z","event_fingerprint":"bb8c8250695eb00664693a48bea4874839f0aff5087dad671c87a6a5bb8a8579","payload":{"connection_id":"0f4979d6978d463e9660b042fdcf555f","event_at":"2026-07-27T04:44:14.455000Z","event_type":"price_change","frame_hash":"6cab75f5aa988825da16015a08295397541b81fa52c6a848e4b77cc82a0f63c3","frame_index":0,"kind":"data","monotonic_ns":229437664713791,"payload":{"event_type":"price_change","market":"0xeb66215f2e9faa6449e30a02bab5b8ed7b79a38bf961f6b24d0073c9c2419250","price_changes":[{"asset_id":"69697746896130839564035629862476347944307040470122503199396727085502753297492","best_ask":"0.999","best_bid":"0.997","hash":"79a86fdfe0b8c0c12e3761a349eaac0c76e0e9dd","price":"0.01","side":"BUY","size":"5320"},{"asset_id":"60386828328910021732068595344565885737045900010034836345809386672230885527307","best_ask":"0.003","best_bid":"0.001","hash":"1946c4e1ac76dc5d3cb95f168466bf0b08579a2c","price":"0.99","side":"SELL","size":"5320"}],"timestamp":"1785127454455"},"payload_hash":"31177c9343b333c92331779f2bcb3f24697aa586a0004e48d0bba6e37c513cef","raw_frame":"{\"market\":\"0xeb66215f2e9faa6449e30a02bab5b8ed7b79a38bf961f6b24d0073c9c2419250\", \"price_changes\":[{\"asset_id\":\"69697746896130839564035629862476347944307040470122503199396727085502753297492\", \"price\":\"0.01\", \"size\":\"5320\", \"side\":\"BUY\", \"hash\":\"79a86fdfe0b8c0c12e3761a349eaac0c76e0e9dd\", \"best_bid\":\"0.997\", \"best_ask\":\"0.999\"}, {\"asset_id\":\"60386828328910021732068595344565885737045900010034836345809386672230885527307\", \"price\":\"0.99\", \"size\":\"5320\", \"side\":\"SELL\", \"hash\":\"1946c4e1ac76dc5d3cb95f168466bf0b08579a2c\", \"best_bid\":\"0.001\", \"best_ask\":\"0.003\"}], \"timestamp\":\"1785127454455\", \"event_type\":\"price_change\"}","received_at":"2026-07-27T04:44:14.402282Z","schema_version":"clob-market-ws.price_change.v1","sequence":null,"server_hash":null,"server_timestamp":"1785127454455","session_id":"e9443c7415a0419799bee9cfbb1a9e4d","source":"clob_market_ws"},"received_at":"2026-07-27T04:44:14.402282Z","record_id":"04f68f613617de8dbcab96e1eab57033925b33e6fdab2b244f56323e8c8f01ca","schema_fingerprint":"4aa3821a28b0b7c2400bc59aba4bcc0a76e971dadd19610d3ad38c768e124dc7","schema_version":"edge-lab-recorder.raw.v1","sequence":null,"source":"clob_market_ws"}
{"event_at":"2026-07-27T04:44:14.457000Z","event_fingerprint":"dad20d190fe6c389bd9eb0dde71a97a7137235e8fdc2ba276eeb4f6c82949e3d","payload":{"connection_id":"0f4979d6978d463e9660b042fdcf555f","event_at":"2026-07-27T04:44:14.457000Z","event_type":"best_bid_ask","frame_hash":"792bcee15d1cc51bc5db3e3a2126894f981d04fd23a126e4c55fdee01e9201e5","frame_index":0,"kind":"data","monotonic_ns":229437668177291,"payload":{"asset_id":"69697746896130839564035629862476347944307040470122503199396727085502753297492","best_ask":"0.999","best_bid":"0.996","event_type":"best_bid_ask","market":"0xeb66215f2e9faa6449e30a02bab5b8ed7b79a38bf961f6b24d0073c9c2419250","spread":"0.003","timestamp":"1785127454457"},"payload_hash":"fe59ebfd8466a524e6b063a9d46f6607ceb3af828ad1a78cc5506d49855f2c0b","raw_frame":"{\"market\":\"0xeb66215f2e9faa6449e30a02bab5b8ed7b79a38bf961f6b24d0073c9c2419250\", \"asset_id\":\"69697746896130839564035629862476347944307040470122503199396727085502753297492\", \"best_bid\":\"0.996\", \"best_ask\":\"0.999\", \"spread\":\"0.003\", \"timestamp\":\"1785127454457\", \"event_type\":\"best_bid_ask\"}","received_at":"2026-07-27T04:44:14.405744Z","schema_version":"clob-market-ws.best_bid_ask.v1","sequence":null,"server_hash":null,"server_timestamp":"1785127454457","session_id":"e9443c7415a0419799bee9cfbb1a9e4d","source":"clob_market_ws"},"received_at":"2026-07-27T04:44:14.405744Z","record_id":"b456fe175da8498754b3874fddb38423f3faa9fded41294606c19b51e19ea3ee","schema_fingerprint":"8488399f31b0337811b13b266be932db7062827c2470b78bd8e9e99bab51d17d","schema_version":"edge-lab-recorder.raw.v1","sequence":null,"source":"clob_market_ws"}
{"event_at":"2026-07-27T04:44:14.457000Z","event_fingerprint":"d8fd4c45bc93c3fdcba34f29f435de1228d8389c109022865248ce9430852468","payload":{"connection_id":"0f4979d6978d463e9660b042fdcf555f","event_at":"2026-07-27T04:44:14.457000Z","event_type":"best_bid_ask","frame_hash":"dbbbf51e2b59733b08a63c9b7f15c3291cd74fb7f54a3e486ec1eaef000f661d","frame_index":0,"kind":"data","monotonic_ns":229437669204708,"payload":{"asset_id":"60386828328910021732068595344565885737045900010034836345809386672230885527307","best_ask":"0.004","best_bid":"0.001","event_type":"best_bid_ask","market":"0xeb66215f2e9faa6449e30a02bab5b8ed7b79a38bf961f6b24d0073c9c2419250","spread":"0.003","timestamp":"1785127454457"},"payload_hash":"8d96854f2318859df36c6189f1e406084344f8634d396948812abc8bda977b9f","raw_frame":"{\"market\":\"0xeb66215f2e9faa6449e30a02bab5b8ed7b79a38bf961f6b24d0073c9c2419250\", \"asset_id\":\"60386828328910021732068595344565885737045900010034836345809386672230885527307\", \"best_bid\":\"0.001\", \"best_ask\":\"0.004\", \"spread\":\"0.003\", \"timestamp\":\"1785127454457\", \"event_type\":\"best_bid_ask\"}","received_at":"2026-07-27T04:44:14.406773Z","schema_version":"clob-market-ws.best_bid_ask.v1","sequence":null,"server_hash":null,"server_timestamp":"1785127454457","session_id":"e9443c7415a0419799bee9cfbb1a9e4d","source":"clob_market_ws"},"received_at":"2026-07-27T04:44:14.406773Z","record_id":"6de134e5e079dfd1b7825998fbce657ec8fd5867351b9ab8cbdcd2cf0f4402c7","schema_fingerprint":"8488399f31b0337811b13b266be932db7062827c2470b78bd8e9e99bab51d17d","schema_version":"edge-lab-recorder.raw.v1","sequence":null,"source":"clob_market_ws"}
{"event_at":"2026-07-27T04:44:14.457000Z","event_fingerprint":"bb08c3684cf2db0052cd21f47a554d31b670ac7fdbcc605c078457f418557c36","payload":{"connection_id":"0f4979d6978d463e9660b042fdcf555f","event_at":"2026-07-27T04:44:14.457000Z","event_type":"price_change","frame_hash":"887441171076efe8b8f98e99619d93238f8e8048969c06ed60672681f7e2188d","frame_index":0,"kind":"data","monotonic_ns":229437670230416,"payload":{"event_type":"price_change","market":"0xeb66215f2e9faa6449e30a02bab5b8ed7b79a38bf961f6b24d0073c9c2419250","price_changes":[{"asset_id":"60386828328910021732068595344565885737045900010034836345809386672230885527307","best_ask":"0.004","best_bid":"0.001","hash":"3c2576b11e4a6ec985111a0f6a7d13fedcf7bbb9","price":"0.003","side":"SELL","size":"0"},{"asset_id":"69697746896130839564035629862476347944307040470122503199396727085502753297492","best_ask":"0.999","best_bid":"0.996","hash":"dab8324c652c69ae0cebfe790e7656821369f8c4","price":"0.997","side":"BUY","size":"0"}],"timestamp":"1785127454457"},"payload_hash":"e17ba5fcdab935da25955db399ec568213838219d70df790a7092f2e6a7c309f","raw_frame":"{\"market\":\"0xeb66215f2e9faa6449e30a02bab5b8ed7b79a38bf961f6b24d0073c9c2419250\", \"price_changes\":[{\"asset_id\":\"60386828328910021732068595344565885737045900010034836345809386672230885527307\", \"price\":\"0.003\", \"size\":\"0\", \"side\":\"SELL\", \"hash\":\"3c2576b11e4a6ec985111a0f6a7d13fedcf7bbb9\", \"best_bid\":\"0.001\", \"best_ask\":\"0.004\"}, {\"asset_id\":\"69697746896130839564035629862476347944307040470122503199396727085502753297492\", \"price\":\"0.997\", \"size\":\"0\", \"side\":\"BUY\", \"hash\":\"dab8324c652c69ae0cebfe790e7656821369f8c4\", \"best_bid\":\"0.996\", \"best_ask\":\"0.999\"}], \"timestamp\":\"1785127454457\", \"event_type\":\"price_change\"}","received_at":"2026-07-27T04:44:14.407799Z","schema_version":"clob-market-ws.price_change.v1","sequence":null,"server_hash":null,"server_timestamp":"1785127454457","session_id":"e9443c7415a0419799bee9cfbb1a9e4d","source":"clob_market_ws"},"received_at":"2026-07-27T04:44:14.407799Z","record_id":"fc419fb241eb725ae88cbe2878a16bddae04e56e8c2dc2c7c434878b5dad18d5","schema_fingerprint":"4aa3821a28b0b7c2400bc59aba4bcc0a76e971dadd19610d3ad38c768e124dc7","schema_version":"edge-lab-recorder.raw.v1","sequence":null,"source":"clob_market_ws"}
{"event_at":"2026-07-27T04:44:14.478000Z","event_fingerprint":"9caab43091ab9266b7f559faa568812e6d39a1bd9e133ab8a19e7fed26891393","payload":{"connection_id":"0f4979d6978d463e9660b042fdcf555f","event_at":"2026-07-27T04:44:14.478000Z","event_type":"price_change","frame_hash":"93bafdaa039c950d7869f0fef1660e3bf60ad8795faf96fd9d1f258c9f5befe6","frame_index":0,"kind":"data","monotonic_ns":229437688489000,"payload":{"event_type":"price_change","market":"0xeb66215f2e9faa6449e30a02bab5b8ed7b79a38bf961f6b24d0073c9c2419250","price_changes":[{"asset_id":"69697746896130839564035629862476347944307040470122503199396727085502753297492","best_ask":"0.999","best_bid":"0.996","hash":"5d3d58d1d749ac7b534f89feda03f3d68bc9a496","price":"0.01","side":"BUY","size":"5315"},{"asset_id":"60386828328910021732068595344565885737045900010034836345809386672230885527307","best_ask":"0.004","best_bid":"0.001","hash":"67b031de8a3c760397c7a337f07a9c6ba713f7f9","price":"0.99","side":"SELL","size":"5315"}],"timestamp":"1785127454478"},"payload_hash":"bacac456b7508df686921ea6b9bd5e91608fd8805421c9fd71e3e126fe224120","raw_frame":"{\"market\":\"0xeb66215f2e9faa6449e30a02bab5b8ed7b79a38bf961f6b24d0073c9c2419250\", \"price_changes\":[{\"asset_id\":\"69697746896130839564035629862476347944307040470122503199396727085502753297492\", \"price\":\"0.01\", \"size\":\"5315\", \"side\":\"BUY\", \"hash\":\"5d3d58d1d749ac7b534f89feda03f3d68bc9a496\", \"best_bid\":\"0.996\", \"best_ask\":\"0.999\"}, {\"asset_id\":\"60386828328910021732068595344565885737045900010034836345809386672230885527307\", \"price\":\"0.99\", \"size\":\"5315\", \"side\":\"SELL\", \"hash\":\"67b031de8a3c760397c7a337f07a9c6ba713f7f9\", \"best_bid\":\"0.001\", \"best_ask\":\"0.004\"}], \"timestamp\":\"1785127454478\", \"event_type\":\"price_change\"}","received_at":"2026-07-27T04:44:14.426057Z","schema_version":"clob-market-ws.price_change.v1","sequence":null,"server_hash":null,"server_timestamp":"1785127454478","session_id":"e9443c7415a0419799bee9cfbb1a9e4d","source":"clob_market_ws"},"received_at":"2026-07-27T04:44:14.426057Z","record_id":"552e45db76aba24689aaf9f07b15bdc7db740f5e903814abe480c586465d933b","schema_fingerprint":"4aa3821a28b0b7c2400bc59aba4bcc0a76e971dadd19610d3ad38c768e124dc7","schema_version":"edge-lab-recorder.raw.v1","sequence":null,"source":"clob_market_ws"}
{"event_at":"2026-07-27T04:44:14.487000Z","event_fingerprint":"2b42479a094b6dc0a6833dce08003b4f3a35db97f099ebd6d036d4f8876a14b3","payload":{"connection_id":"0f4979d6978d463e9660b042fdcf555f","event_at":"2026-07-27T04:44:14.487000Z","event_type":"best_bid_ask","frame_hash":"86cc835227ee597dbe2dbb046f80b270efd9e50132e57e9fa914fdf3063c594a","frame_index":0,"kind":"data","monotonic_ns":229437698017291,"payload":{"asset_id":"69697746896130839564035629862476347944307040470122503199396727085502753297492","best_ask":"0.999","best_bid":"0.997","event_type":"best_bid_ask","market":"0xeb66215f2e9faa6449e30a02bab5b8ed7b79a38bf961f6b24d0073c9c2419250","spread":"0.002","timestamp":"1785127454487"},"payload_hash":"b0a7b25c2d7b26e97d4641f1181061c7a9d929012a33afd7625e7719b1629a3c","raw_frame":"{\"market\":\"0xeb66215f2e9faa6449e30a02bab5b8ed7b79a38bf961f6b24d0073c9c2419250\", \"asset_id\":\"69697746896130839564035629862476347944307040470122503199396727085502753297492\", \"best_bid\":\"0.997\", \"best_ask\":\"0.999\", \"spread\":\"0.002\", \"timestamp\":\"1785127454487\", \"event_type\":\"best_bid_ask\"}","received_at":"2026-07-27T04:44:14.435586Z","schema_version":"clob-market-ws.best_bid_ask.v1","sequence":null,"server_hash":null,"server_timestamp":"1785127454487","session_id":"e9443c7415a0419799bee9cfbb1a9e4d","source":"clob_market_ws"},"received_at":"2026-07-27T04:44:14.435586Z","record_id":"f7ede90b1a43e3800be93ebdbb11ae0074037a327deba4315f0b579f178fb574","schema_fingerprint":"8488399f31b0337811b13b266be932db7062827c2470b78bd8e9e99bab51d17d","schema_version":"edge-lab-recorder.raw.v1","sequence":null,"source":"clob_market_ws"}
{"event_at":"2026-07-27T04:44:14.487000Z","event_fingerprint":"541016b4fd73bb8f26eabf74a41ac9b66030a721d395f992432ae52b0eb25bb7","payload":{"connection_id":"0f4979d6978d463e9660b042fdcf555f","event_at":"2026-07-27T04:44:14.487000Z","event_type":"best_bid_ask","frame_hash":"bf6ec5708fa3f8f0fb0dead02f328af1d280a3bc3f6ae4d4e891a068513abee8","frame_index":0,"kind":"data","monotonic_ns":229437699012916,"payload":{"asset_id":"60386828328910021732068595344565885737045900010034836345809386672230885527307","best_ask":"0.003","best_bid":"0.001","event_type":"best_bid_ask","market":"0xeb66215f2e9faa6449e30a02bab5b8ed7b79a38bf961f6b24d0073c9c2419250","spread":"0.002","timestamp":"1785127454487"},"payload_hash":"5808e30f3e900d6d9372413f10320340edc715f143e138994ba0631452b90fdb","raw_frame":"{\"market\":\"0xeb66215f2e9faa6449e30a02bab5b8ed7b79a38bf961f6b24d0073c9c2419250\", \"asset_id\":\"60386828328910021732068595344565885737045900010034836345809386672230885527307\", \"best_bid\":\"0.001\", \"best_ask\":\"0.003\", \"spread\":\"0.002\", \"timestamp\":\"1785127454487\", \"event_type\":\"best_bid_ask\"}","received_at":"2026-07-27T04:44:14.436581Z","schema_version":"clob-market-ws.best_bid_ask.v1","sequence":null,"server_hash":null,"server_timestamp":"1785127454487","session_id":"e9443c7415a0419799bee9cfbb1a9e4d","source":"clob_market_ws"},"received_at":"2026-07-27T04:44:14.436581Z","record_id":"c0c077a5a1ce8190552b52dfd7792352c83bc89886b5d76222a88c1dc0d1f86c","schema_fingerprint":"8488399f31b0337811b13b266be932db7062827c2470b78bd8e9e99bab51d17d","schema_version":"edge-lab-recorder.raw.v1","sequence":null,"source":"clob_market_ws"}
{"event_at":"2026-07-27T04:44:14.487000Z","event_fingerprint":"0d8cce72461bb50ea593d07a48ef24f471a3640d39970bf63ff4dc5d8f72db30","payload":{"connection_id":"0f4979d6978d463e9660b042fdcf555f","event_at":"2026-07-27T04:44:14.487000Z","event_type":"price_change","frame_hash":"7d4dcff9d6e4cafadc528684dc7795d31b97f19d2f81f32557a33828a337b45a","frame_index":0,"kind":"data","monotonic_ns":229437700020208,"payload":{"event_type":"price_change","market":"0xeb66215f2e9faa6449e30a02bab5b8ed7b79a38bf961f6b24d0073c9c2419250","price_changes":[{"asset_id":"60386828328910021732068595344565885737045900010034836345809386672230885527307","best_ask":"0.003","best_bid":"0.001","hash":"7f12541afb83e037165421cdc0eb07ae05d897d5","price":"0.003","side":"SELL","size":"275.12"},{"asset_id":"69697746896130839564035629862476347944307040470122503199396727085502753297492","best_ask":"0.999","best_bid":"0.997","hash":"1929d06ba5c0713bb80e3b59ddae71aeaccd54fc","price":"0.997","side":"BUY","size":"275.12"}],"timestamp":"1785127454487"},"payload_hash":"43c7307f93b7b9145da6e6938075b3b30a86115ae239fd8562db124f47125ab3","raw_frame":"{\"market\":\"0xeb66215f2e9faa6449e30a02bab5b8ed7b79a38bf961f6b24d0073c9c2419250\", \"price_changes\":[{\"asset_id\":\"60386828328910021732068595344565885737045900010034836345809386672230885527307\", \"price\":\"0.003\", \"size\":\"275.12\", \"side\":\"SELL\", \"hash\":\"7f12541afb83e037165421cdc0eb07ae05d897d5\", \"best_bid\":\"0.001\", \"best_ask\":\"0.003\"}, {\"asset_id\":\"69697746896130839564035629862476347944307040470122503199396727085502753297492\", \"price\":\"0.997\", \"size\":\"275.12\", \"side\":\"BUY\", \"hash\":\"1929d06ba5c0713bb80e3b59ddae71aeaccd54fc\", \"best_bid\":\"0.997\", \"best_ask\":\"0.999\"}], \"timestamp\":\"1785127454487\", \"event_type\":\"price_change\"}","received_at":"2026-07-27T04:44:14.437589Z","schema_version":"clob-market-ws.price_change.v1","sequence":null,"server_hash":null,"server_timestamp":"1785127454487","session_id":"e9443c7415a0419799bee9cfbb1a9e4d","source":"clob_market_ws"},"received_at":"2026-07-27T04:44:14.437589Z","record_id":"909df69b953dbfd2d0e16adf4cfd58b389e0d247d2c81b36672e9b81f5042f98","schema_fingerprint":"4aa3821a28b0b7c2400bc59aba4bcc0a76e971dadd19610d3ad38c768e124dc7","schema_version":"edge-lab-recorder.raw.v1","sequence":null,"source":"clob_market_ws"}
{"event_at":"2026-07-27T04:44:14.509000Z","event_fingerprint":"465de5dba2a39444e1780e5abad07976d06cd8f141215f34538529c6d54a8537","payload":{"connection_id":"0f4979d6978d463e9660b042fdcf555f","event_at":"2026-07-27T04:44:14.509000Z","event_type":"best_bid_ask","frame_hash":"75fa9546140e5e00a0a442de62299afe0b2a74dcb5a82e36ad75897e03756590","frame_index":0,"kind":"data","monotonic_ns":229437719190208,"payload":{"asset_id":"69697746896130839564035629862476347944307040470122503199396727085502753297492","best_ask":"0.999","best_bid":"0.996","event_type":"best_bid_ask","market":"0xeb66215f2e9faa6449e30a02bab5b8ed7b79a38bf961f6b24d0073c9c2419250","spread":"0.003","timestamp":"1785127454509"},"payload_hash":"ff1b70d1d53e0885bc8fdf28b9ec0003b94ae0a9a291e061d634448956d9f99f","raw_frame":"{\"market\":\"0xeb66215f2e9faa6449e30a02bab5b8ed7b79a38bf961f6b24d0073c9c2419250\", \"asset_id\":\"69697746896130839564035629862476347944307040470122503199396727085502753297492\", \"best_bid\":\"0.996\", \"best_ask\":\"0.999\", \"spread\":\"0.003\", \"timestamp\":\"1785127454509\", \"event_type\":\"best_bid_ask\"}","received_at":"2026-07-27T04:44:14.456758Z","schema_version":"clob-market-ws.best_bid_ask.v1","sequence":null,"server_hash":null,"server_timestamp":"1785127454509","session_id":"e9443c7415a0419799bee9cfbb1a9e4d","source":"clob_market_ws"},"received_at":"2026-07-27T04:44:14.456758Z","record_id":"541920e44100b29d58af2294b81b58ee2897e421f91c5eb273e51314d5a38c4b","schema_fingerprint":"8488399f31b0337811b13b266be932db7062827c2470b78bd8e9e99bab51d17d","schema_version":"edge-lab-recorder.raw.v1","sequence":null,"source":"clob_market_ws"}
{"event_at":"2026-07-27T04:44:14.509000Z","event_fingerprint":"34872ee5b3ff523e6218eb44d36fc9e3fa2d33a093f227f1c2fb571de2b499d8","payload":{"connection_id":"0f4979d6978d463e9660b042fdcf555f","event_at":"2026-07-27T04:44:14.509000Z","event_type":"best_bid_ask","frame_hash":"1deb49710563056275ac37a5a490ef6d5076684acbc923b33d251428961c4510","frame_index":0,"kind":"data","monotonic_ns":229437720215958,"payload":{"asset_id":"60386828328910021732068595344565885737045900010034836345809386672230885527307","best_ask":"0.004","best_bid":"0.001","event_type":"best_bid_ask","market":"0xeb66215f2e9faa6449e30a02bab5b8ed7b79a38bf961f6b24d0073c9c2419250","spread":"0.003","timestamp":"1785127454509"},"payload_hash":"ead9adf26b0d11aa50dd062942a6f9771213bdb0b659ffda5fbae752af648f3d","raw_frame":"{\"market\":\"0xeb66215f2e9faa6449e30a02bab5b8ed7b79a38bf961f6b24d0073c9c2419250\", \"asset_id\":\"60386828328910021732068595344565885737045900010034836345809386672230885527307\", \"best_bid\":\"0.001\", \"best_ask\":\"0.004\", \"spread\":\"0.003\", \"timestamp\":\"1785127454509\", \"event_type\":\"best_bid_ask\"}","received_at":"2026-07-27T04:44:14.457785Z","schema_version":"clob-market-ws.best_bid_ask.v1","sequence":null,"server_hash":null,"server_timestamp":"1785127454509","session_id":"e9443c7415a0419799bee9cfbb1a9e4d","source":"clob_market_ws"},"received_at":"2026-07-27T04:44:14.457785Z","record_id":"a420e6ff8badc057c04a026b86671999d144f9934f6eb99bcad63b10d1b9cbd8","schema_fingerprint":"8488399f31b0337811b13b266be932db7062827c2470b78bd8e9e99bab51d17d","schema_version":"edge-lab-recorder.raw.v1","sequence":null,"source":"clob_market_ws"}
{"event_at":"2026-07-27T04:44:14.509000Z","event_fingerprint":"bee1b123521688e31f16769d5de50a7658956b97aa5701c2cdb4b6f74a62ac05","payload":{"connection_id":"0f4979d6978d463e9660b042fdcf555f","event_at":"2026-07-27T04:44:14.509000Z","event_type":"price_change","frame_hash":"a88c0fe62274139e27dad86f45269cf502f0e8fc733d33e7d2cc1daf5ef01d3a","frame_index":0,"kind":"data","monotonic_ns":229437721261500,"payload":{"event_type":"price_change","market":"0xeb66215f2e9faa6449e30a02bab5b8ed7b79a38bf961f6b24d0073c9c2419250","price_changes":[{"asset_id":"60386828328910021732068595344565885737045900010034836345809386672230885527307","best_ask":"0.004","best_bid":"0.001","hash":"69808573f98f2429929cb324bd48c7a8eac95d99","price":"0.003","side":"SELL","size":"0"},{"asset_id":"69697746896130839564035629862476347944307040470122503199396727085502753297492","best_ask":"0.999","best_bid":"0.996","hash":"866de882c9fe119bee1a21dc019bbfcb066e8cf1","price":"0.997","side":"BUY","size":"0"}],"timestamp":"1785127454509"},"payload_hash":"b4a77c7341805523f3e2708e8f0f5f6da399a093c9baa92d4d6eca5dbf2beafa","raw_frame":"{\"market\":\"0xeb66215f2e9faa6449e30a02bab5b8ed7b79a38bf961f6b24d0073c9c2419250\", \"price_changes\":[{\"asset_id\":\"60386828328910021732068595344565885737045900010034836345809386672230885527307\", \"price\":\"0.003\", \"size\":\"0\", \"side\":\"SELL\", \"hash\":\"69808573f98f2429929cb324bd48c7a8eac95d99\", \"best_bid\":\"0.001\", \"best_ask\":\"0.004\"}, {\"asset_id\":\"69697746896130839564035629862476347944307040470122503199396727085502753297492\", \"price\":\"0.997\", \"size\":\"0\", \"side\":\"BUY\", \"hash\":\"866de882c9fe119bee1a21dc019bbfcb066e8cf1\", \"best_bid\":\"0.996\", \"best_ask\":\"0.999\"}], \"timestamp\":\"1785127454509\", \"event_type\":\"price_change\"}","received_at":"2026-07-27T04:44:14.458830Z","schema_version":"clob-market-ws.price_change.v1","sequence":null,"server_hash":null,"server_timestamp":"1785127454509","session_id":"e9443c7415a0419799bee9cfbb1a9e4d","source":"clob_market_ws"},"received_at":"2026-07-27T04:44:14.458830Z","record_id":"2573997ada3f32a22c1316d67a0b57e19e0ce1dafe8fdd7aa6181946f46f2d91","schema_fingerprint":"4aa3821a28b0b7c2400bc59aba4bcc0a76e971dadd19610d3ad38c768e124dc7","schema_version":"edge-lab-recorder.raw.v1","sequence":null,"source":"clob_market_ws"}
{"event_at":"2026-07-27T04:44:14.514000Z","event_fingerprint":"409c3848083b229d58f41741e492d47717d78446c91c48d2e02f20db47e01fc3","payload":{"connection_id":"0f4979d6978d463e9660b042fdcf555f","event_at":"2026-07-27T04:44:14.514000Z","event_type":"price_change","frame_hash":"6780c4320a2f6658aa5833c0dec62f616eda5b96541d104e7f27743b8505f2bd","frame_index":0,"kind":"data","monotonic_ns":229437724710375,"payload":{"event_type":"price_change","market":"0xeb66215f2e9faa6449e30a02bab5b8ed7b79a38bf961f6b24d0073c9c2419250","price_changes":[{"asset_id":"69697746896130839564035629862476347944307040470122503199396727085502753297492","best_ask":"0.999","best_bid":"0.996","hash":"9ceae9887b5b9222f250146c102d9fb17b85c63f","price":"0.02","side":"BUY","size":"530"},{"asset_id":"60386828328910021732068595344565885737045900010034836345809386672230885527307","best_ask":"0.004","best_bid":"0.001","hash":"5d24c21d554dc9b54ee16e800b308b24e6e88715","price":"0.98","side":"SELL","size":"530"}],"timestamp":"1785127454514"},"payload_hash":"447f94f6ebfe858508fd26d490e0212a669072a35cc1a770006cb8d23653c281","raw_frame":"{\"market\":\"0xeb66215f2e9faa6449e30a02bab5b8ed7b79a38bf961f6b24d0073c9c2419250\", \"price_changes\":[{\"asset_id\":\"69697746896130839564035629862476347944307040470122503199396727085502753297492\", \"price\":\"0.02\", \"size\":\"530\", \"side\":\"BUY\", \"hash\":\"9ceae9887b5b9222f250146c102d9fb17b85c63f\", \"best_bid\":\"0.996\", \"best_ask\":\"0.999\"}, {\"asset_id\":\"60386828328910021732068595344565885737045900010034836345809386672230885527307\", \"price\":\"0.98\", \"size\":\"530\", \"side\":\"SELL\", \"hash\":\"5d24c21d554dc9b54ee16e800b308b24e6e88715\", \"best_bid\":\"0.001\", \"best_ask\":\"0.004\"}], \"timestamp\":\"1785127454514\", \"event_type\":\"price_change\"}","received_at":"2026-07-27T04:44:14.462279Z","schema_version":"clob-market-ws.price_change.v1","sequence":null,"server_hash":null,"server_timestamp":"1785127454514","session_id":"e9443c7415a0419799bee9cfbb1a9e4d","source":"clob_market_ws"},"received_at":"2026-07-27T04:44:14.462279Z","record_id":"ef682fcd095fcb69e412a40e1af0cb6df04cecbb5083d36d3358df3584d31fef","schema_fingerprint":"4aa3821a28b0b7c2400bc59aba4bcc0a76e971dadd19610d3ad38c768e124dc7","schema_version":"edge-lab-recorder.raw.v1","sequence":null,"source":"clob_market_ws"}
{"event_at":"2026-07-27T04:44:14.541000Z","event_fingerprint":"ace335baa6a59d3f4d992ef3ce37a5fa430c890fe38fcfea2c12f6007c6282b3","payload":{"connection_id":"0f4979d6978d463e9660b042fdcf555f","event_at":"2026-07-27T04:44:14.541000Z","event_type":"best_bid_ask","frame_hash":"ed3a55517b9eeab0a193bc96396471de014a6c96a2ef04a14c66ddd552f5aa91","frame_index":0,"kind":"data","monotonic_ns":229437751672208,"payload":{"asset_id":"69697746896130839564035629862476347944307040470122503199396727085502753297492","best_ask":"0.999","best_bid":"0.997","event_type":"best_bid_ask","market":"0xeb66215f2e9faa6449e30a02bab5b8ed7b79a38bf961f6b24d0073c9c2419250","spread":"0.002","timestamp":"1785127454541"},"payload_hash":"8a1ee7423979e84166e352c91ce71b0f852a3d6e500e53b042006dc9b3a7677c","raw_frame":"{\"market\":\"0xeb66215f2e9faa6449e30a02bab5b8ed7b79a38bf961f6b24d0073c9c2419250\", \"asset_id\":\"69697746896130839564035629862476347944307040470122503199396727085502753297492\", \"best_bid\":\"0.997\", \"best_ask\":\"0.999\", \"spread\":\"0.002\", \"timestamp\":\"1785127454541\", \"event_type\":\"best_bid_ask\"}","received_at":"2026-07-27T04:44:14.489240Z","schema_version":"clob-market-ws.best_bid_ask.v1","sequence":null,"server_hash":null,"server_timestamp":"1785127454541","session_id":"e9443c7415a0419799bee9cfbb1a9e4d","source":"clob_market_ws"},"received_at":"2026-07-27T04:44:14.489240Z","record_id":"6b5e2a1b99646b24e981c974469f37c08429ffbdba51144c94fec1a3bd1f062f","schema_fingerprint":"8488399f31b0337811b13b266be932db7062827c2470b78bd8e9e99bab51d17d","schema_version":"edge-lab-recorder.raw.v1","sequence":null,"source":"clob_market_ws"}
{"event_at":"2026-07-27T04:44:14.541000Z","event_fingerprint":"9355db85f92ca7b674335176ba4e43f09d78d0620ee8b679e8f2ca26454d95bd","payload":{"connection_id":"0f4979d6978d463e9660b042fdcf555f","event_at":"2026-07-27T04:44:14.541000Z","event_type":"best_bid_ask","frame_hash":"fc48c5114ebb4c372085143eb12c8d4a4c24760a1d1c448720bdd6047a89511c","frame_index":0,"kind":"data","monotonic_ns":229437752846375,"payload":{"asset_id":"60386828328910021732068595344565885737045900010034836345809386672230885527307","best_ask":"0.003","best_bid":"0.001","event_type":"best_bid_ask","market":"0xeb66215f2e9faa6449e30a02bab5b8ed7b79a38bf961f6b24d0073c9c2419250","spread":"0.002","timestamp":"1785127454541"},"payload_hash":"9beb2cedc345e137c9840ecfc82d52ffb5a329c2d14aff906fbb3104abe25199","raw_frame":"{\"market\":\"0xeb66215f2e9faa6449e30a02bab5b8ed7b79a38bf961f6b24d0073c9c2419250\", \"asset_id\":\"60386828328910021732068595344565885737045900010034836345809386672230885527307\", \"best_bid\":\"0.001\", \"best_ask\":\"0.003\", \"spread\":\"0.002\", \"timestamp\":\"1785127454541\", \"event_type\":\"best_bid_ask\"}","received_at":"2026-07-27T04:44:14.490414Z","schema_version":"clob-market-ws.best_bid_ask.v1","sequence":null,"server_hash":null,"server_timestamp":"1785127454541","session_id":"e9443c7415a0419799bee9cfbb1a9e4d","source":"clob_market_ws"},"received_at":"2026-07-27T04:44:14.490414Z","record_id":"a916b15667c72d429fd80d062442966bc8a9bd884d3016fe75a1dcbb6e703b6b","schema_fingerprint":"8488399f31b0337811b13b266be932db7062827c2470b78bd8e9e99bab51d17d","schema_version":"edge-lab-recorder.raw.v1","sequence":null,"source":"clob_market_ws"}
{"event_at":"2026-07-27T04:44:14.541000Z","event_fingerprint":"dc040fce43b7b3b683ad05602bff42d004cb16ac8ca26085d939327c59c3bac0","payload":{"connection_id":"0f4979d6978d463e9660b042fdcf555f","event_at":"2026-07-27T04:44:14.541000Z","event_type":"price_change","frame_hash":"5c334faefa586742bd185c67c8def291aebe0dc1974ad2e3d3de1daf07943697","frame_index":0,"kind":"data","monotonic_ns":229437753996041,"payload":{"event_type":"price_change","market":"0xeb66215f2e9faa6449e30a02bab5b8ed7b79a38bf961f6b24d0073c9c2419250","price_changes":[{"asset_id":"60386828328910021732068595344565885737045900010034836345809386672230885527307","best_ask":"0.003","best_bid":"0.001","hash":"5a28f4cda67e61b9a728970b05f7eb0929b843ee","price":"0.003","side":"SELL","size":"275.12"},{"asset_id":"69697746896130839564035629862476347944307040470122503199396727085502753297492","best_ask":"0.999","best_bid":"0.997","hash":"eff2f02b421e6cf9d058d9598f74bd5aedaae16a","price":"0.997","side":"BUY","size":"275.12"}],"timestamp":"1785127454541"},"payload_hash":"f1fd9d1402625f8060bc33761b86011fc477e911c75b1e1a3bf7deca6773a6a9","raw_frame":"{\"market\":\"0xeb66215f2e9faa6449e30a02bab5b8ed7b79a38bf961f6b24d0073c9c2419250\", \"price_changes\":[{\"asset_id\":\"60386828328910021732068595344565885737045900010034836345809386672230885527307\", \"price\":\"0.003\", \"size\":\"275.12\", \"side\":\"SELL\", \"hash\":\"5a28f4cda67e61b9a728970b05f7eb0929b843ee\", \"best_bid\":\"0.001\", \"best_ask\":\"0.003\"}, {\"asset_id\":\"69697746896130839564035629862476347944307040470122503199396727085502753297492\", \"price\":\"0.997\", \"size\":\"275.12\", \"side\":\"BUY\", \"hash\":\"eff2f02b421e6cf9d058d9598f74bd5aedaae16a\", \"best_bid\":\"0.997\", \"best_ask\":\"0.999\"}], \"timestamp\":\"1785127454541\", \"event_type\":\"price_change\"}","received_at":"2026-07-27T04:44:14.491561Z","schema_version":"clob-market-ws.price_change.v1","sequence":null,"server_hash":null,"server_timestamp":"1785127454541","session_id":"e9443c7415a0419799bee9cfbb1a9e4d","source":"clob_market_ws"},"received_at":"2026-07-27T04:44:14.491561Z","record_id":"03ef38c70a6d87f2acc89dfcf193f68f85cfbe5d49e50923e5ee5a04a3f61a62","schema_fingerprint":"4aa3821a28b0b7c2400bc59aba4bcc0a76e971dadd19610d3ad38c768e124dc7","schema_version":"edge-lab-recorder.raw.v1","sequence":null,"source":"clob_market_ws"}
{"event_at":"2026-07-27T04:44:14.558000Z","event_fingerprint":"1059a417ae1e68aa829ef53b92f05f706ab82c7302827ff2e55842d57de20079","payload":{"connection_id":"0f4979d6978d463e9660b042fdcf555f","event_at":"2026-07-27T04:44:14.558000Z","event_type":"best_bid_ask","frame_hash":"a00331e8cec34a45ab01da97d7d094bbb74e1d47ae2a1f188cdf967569cd2ecd","frame_index":0,"kind":"data","monotonic_ns":229437769186666,"payload":{"asset_id":"69697746896130839564035629862476347944307040470122503199396727085502753297492","best_ask":"0.999","best_bid":"0.996","event_type":"best_bid_ask","market":"0xeb66215f2e9faa6449e30a02bab5b8ed7b79a38bf961f6b24d0073c9c2419250","spread":"0.003","timestamp":"1785127454558"},"payload_hash":"625d87f72775508f54c2fb5cb2924b14ce721b4b039e27a0cfe4af6be37a2f53","raw_frame":"{\"market\":\"0xeb66215f2e9faa6449e30a02bab5b8ed7b79a38bf961f6b24d0073c9c2419250\", \"asset_id\":\"69697746896130839564035629862476347944307040470122503199396727085502753297492\", \"best_bid\":\"0.996\", \"best_ask\":\"0.999\", \"spread\":\"0.003\", \"timestamp\":\"1785127454558\", \"event_type\":\"best_bid_ask\"}","received_at":"2026-07-27T04:44:14.506753Z","schema_version":"clob-market-ws.best_bid_ask.v1","sequence":null,"server_hash":null,"server_timestamp":"1785127454558","session_id":"e9443c7415a0419799bee9cfbb1a9e4d","source":"clob_market_ws"},"received_at":"2026-07-27T04:44:14.506753Z","record_id":"c2232ee20b8d0ab7f75a9c40d2c8d9848313cc9c1d9176e34fc32c9535ef1683","schema_fingerprint":"8488399f31b0337811b13b266be932db7062827c2470b78bd8e9e99bab51d17d","schema_version":"edge-lab-recorder.raw.v1","sequence":null,"source":"clob_market_ws"}
{"event_at":"2026-07-27T04:44:14.558000Z","event_fingerprint":"dbd8ecac1167f408fc07b2dcb11ca27ae17ebce47dd5293e66ff23670f603c32","payload":{"connection_id":"0f4979d6978d463e9660b042fdcf555f","event_at":"2026-07-27T04:44:14.558000Z","event_type":"best_bid_ask","frame_hash":"cc221cba60a986bdcd9bddd15d0ab916c153c0c3d2df4ea32211cc066d9e7595","frame_index":0,"kind":"data","monotonic_ns":229437770343916,"payload":{"asset_id":"60386828328910021732068595344565885737045900010034836345809386672230885527307","best_ask":"0.004","best_bid":"0.001","event_type":"best_bid_ask","market":"0xeb66215f2e9faa6449e30a02bab5b8ed7b79a38bf961f6b24d0073c9c2419250","spread":"0.003","timestamp":"1785127454558"},"payload_hash":"7da65262790f9f63fab9489503229863c6bed462905f9bcb85c63857cf02d99e","raw_frame":"{\"market\":\"0xeb66215f2e9faa6449e30a02bab5b8ed7b79a38bf961f6b24d0073c9c2419250\", \"asset_id\":\"60386828328910021732068595344565885737045900010034836345809386672230885527307\", \"best_bid\":\"0.001\", \"best_ask\":\"0.004\", \"spread\":\"0.003\", \"timestamp\":\"1785127454558\", \"event_type\":\"best_bid_ask\"}","received_at":"2026-07-27T04:44:14.507912Z","schema_version":"clob-market-ws.best_bid_ask.v1","sequence":null,"server_hash":null,"server_timestamp":"1785127454558","session_id":"e9443c7415a0419799bee9cfbb1a9e4d","source":"clob_market_ws"},"received_at":"2026-07-27T04:44:14.507912Z","record_id":"694cbae219f993fdadef7d9b3e5dabd8f080e437aeaab36a7c914450649b4f8a","schema_fingerprint":"8488399f31b0337811b13b266be932db7062827c2470b78bd8e9e99bab51d17d","schema_version":"edge-lab-recorder.raw.v1","sequence":null,"source":"clob_market_ws"}
{"event_at":"2026-07-27T04:44:14.558000Z","event_fingerprint":"e90693076bc8a165d9d10594b041598de32c5bb245dc8e6bbef5b151f07dfa55","payload":{"connection_id":"0f4979d6978d463e9660b042fdcf555f","event_at":"2026-07-27T04:44:14.558000Z","event_type":"price_change","frame_hash":"722abef8a389a76933a22a135cc8be88cdd0f2364d7fed9657489485c5397ac3","frame_index":0,"kind":"data","monotonic_ns":229437771399750,"payload":{"event_type":"price_change","market":"0xeb66215f2e9faa6449e30a02bab5b8ed7b79a38bf961f6b24d0073c9c2419250","price_changes":[{"asset_id":"60386828328910021732068595344565885737045900010034836345809386672230885527307","best_ask":"0.004","best_bid":"0.001","hash":"73fbe8352901b8d341661183323a36eb7843b7a6","price":"0.003","side":"SELL","size":"0"},{"asset_id":"69697746896130839564035629862476347944307040470122503199396727085502753297492","best_ask":"0.999","best_bid":"0.996","hash":"1a4b400a7b80b585659088a51aa97c66771550d5","price":"0.997","side":"BUY","size":"0"}],"timestamp":"1785127454558"},"payload_hash":"f3d06c4cda1d268f94499c515577d940d6e4527f24e40b36e7bbb5eea8c1ebd5","raw_frame":"{\"market\":\"0xeb66215f2e9faa6449e30a02bab5b8ed7b79a38bf961f6b24d0073c9c2419250\", \"price_changes\":[{\"asset_id\":\"60386828328910021732068595344565885737045900010034836345809386672230885527307\", \"price\":\"0.003\", \"size\":\"0\", \"side\":\"SELL\", \"hash\":\"73fbe8352901b8d341661183323a36eb7843b7a6\", \"best_bid\":\"0.001\", \"best_ask\":\"0.004\"}, {\"asset_id\":\"69697746896130839564035629862476347944307040470122503199396727085502753297492\", \"price\":\"0.997\", \"size\":\"0\", \"side\":\"BUY\", \"hash\":\"1a4b400a7b80b585659088a51aa97c66771550d5\", \"best_bid\":\"0.996\", \"best_ask\":\"0.999\"}], \"timestamp\":\"1785127454558\", \"event_type\":\"price_change\"}","received_at":"2026-07-27T04:44:14.508967Z","schema_version":"clob-market-ws.price_change.v1","sequence":null,"server_hash":null,"server_timestamp":"1785127454558","session_id":"e9443c7415a0419799bee9cfbb1a9e4d","source":"clob_market_ws"},"received_at":"2026-07-27T04:44:14.508967Z","record_id":"20342b7115127c9cf9b8c8ff3078ec3683d41cc44873b93f1d10ea66602296d7","schema_fingerprint":"4aa3821a28b0b7c2400bc59aba4bcc0a76e971dadd19610d3ad38c768e124dc7","schema_version":"edge-lab-recorder.raw.v1","sequence":null,"source":"clob_market_ws"}
{"event_at":"2026-07-27T04:44:14.573000Z","event_fingerprint":"f4227a2efe1b40a116eb6b79ec9268605c009e58cd927c05a8dc2bad97eb41fe","payload":{"connection_id":"0f4979d6978d463e9660b042fdcf555f","event_at":"2026-07-27T04:44:14.573000Z","event_type":"price_change","frame_hash":"08c494e38caa23e261860bc50d6deba8f99c0e01ed33ed14940e08713a135013","frame_index":0,"kind":"data","monotonic_ns":229437783269750,"payload":{"event_type":"price_change","market":"0xeb66215f2e9faa6449e30a02bab5b8ed7b79a38bf961f6b24d0073c9c2419250","price_changes":[{"asset_id":"69697746896130839564035629862476347944307040470122503199396727085502753297492","best_ask":"0.999","best_bid":"0.996","hash":"581c8b78b169ee126001675f3107bbc2861aea2d","price":"0.02","side":"BUY","size":"525"},{"asset_id":"60386828328910021732068595344565885737045900010034836345809386672230885527307","best_ask":"0.004","best_bid":"0.001","hash":"8641f6546e716c7600548b4b2de8330eab26d8f9","price":"0.98","side":"SELL","size":"525"}],"timestamp":"1785127454573"},"payload_hash":"529548220cb049de73386b77f616154a5d7ddaaa33095e53477a4c80d46e1163","raw_frame":"{\"market\":\"0xeb66215f2e9faa6449e30a02bab5b8ed7b79a38bf961f6b24d0073c9c2419250\", \"price_changes\":[{\"asset_id\":\"69697746896130839564035629862476347944307040470122503199396727085502753297492\", \"price\":\"0.02\", \"size\":\"525\", \"side\":\"BUY\", \"hash\":\"581c8b78b169ee126001675f3107bbc2861aea2d\", \"best_bid\":\"0.996\", \"best_ask\":\"0.999\"}, {\"asset_id\":\"60386828328910021732068595344565885737045900010034836345809386672230885527307\", \"price\":\"0.98\", \"size\":\"525\", \"side\":\"SELL\", \"hash\":\"8641f6546e716c7600548b4b2de8330eab26d8f9\", \"best_bid\":\"0.001\", \"best_ask\":\"0.004\"}], \"timestamp\":\"1785127454573\", \"event_type\":\"price_change\"}","received_at":"2026-07-27T04:44:14.520844Z","schema_version":"clob-market-ws.price_change.v1","sequence":null,"server_hash":null,"server_timestamp":"1785127454573","session_id":"e9443c7415a0419799bee9cfbb1a9e4d","source":"clob_market_ws"},"received_at":"2026-07-27T04:44:14.520844Z","record_id":"74127c5c1cb7a47748610f43365546f5fda4e190a220f3fbdb97c406f4af371a","schema_fingerprint":"4aa3821a28b0b7c2400bc59aba4bcc0a76e971dadd19610d3ad38c768e124dc7","schema_version":"edge-lab-recorder.raw.v1","sequence":null,"source":"clob_market_ws"}
{"event_at":"2026-07-27T04:44:14.591000Z","event_fingerprint":"52ed560fe78a1175b541c55b4f7e6965cbc6e59f328dbc4dd2bcb51a2e5419a8","payload":{"connection_id":"0f4979d6978d463e9660b042fdcf555f","event_at":"2026-07-27T04:44:14.591000Z","event_type":"best_bid_ask","frame_hash":"3f570d1a8ac225a79086091a279606fcdaf809ac0bcd91220c542046af5f43c1","frame_index":0,"kind":"data","monotonic_ns":229437801584208,"payload":{"asset_id":"69697746896130839564035629862476347944307040470122503199396727085502753297492","best_ask":"0.999","best_bid":"0.997","event_type":"best_bid_ask","market":"0xeb66215f2e9faa6449e30a02bab5b8ed7b79a38bf961f6b24d0073c9c2419250","spread":"0.002","timestamp":"1785127454591"},"payload_hash":"1d3597baa00d43b2092dc928103e977e6ba5f020d1fdafd76f70fe239db924a7","raw_frame":"{\"market\":\"0xeb66215f2e9faa6449e30a02bab5b8ed7b79a38bf961f6b24d0073c9c2419250\", \"asset_id\":\"69697746896130839564035629862476347944307040470122503199396727085502753297492\", \"best_bid\":\"0.997\", \"best_ask\":\"0.999\", \"spread\":\"0.002\", \"timestamp\":\"1785127454591\", \"event_type\":\"best_bid_ask\"}","received_at":"2026-07-27T04:44:14.539152Z","schema_version":"clob-market-ws.best_bid_ask.v1","sequence":null,"server_hash":null,"server_timestamp":"1785127454591","session_id":"e9443c7415a0419799bee9cfbb1a9e4d","source":"clob_market_ws"},"received_at":"2026-07-27T04:44:14.539152Z","record_id":"e0995a1f827b561e9472396c3685c64e067fe603757969b24d7b25b28acca571","schema_fingerprint":"8488399f31b0337811b13b266be932db7062827c2470b78bd8e9e99bab51d17d","schema_version":"edge-lab-recorder.raw.v1","sequence":null,"source":"clob_market_ws"}
{"event_at":"2026-07-27T04:44:14.591000Z","event_fingerprint":"1e477dc199e29a6696057185939cbf1f05de366780e5762a1271f553c15427e6","payload":{"connection_id":"0f4979d6978d463e9660b042fdcf555f","event_at":"2026-07-27T04:44:14.591000Z","event_type":"best_bid_ask","frame_hash":"903812ba86abf21865f909abb7948aff3fb9434a1c95e2d510d86ed2f6166c24","frame_index":0,"kind":"data","monotonic_ns":229437802697291,"payload":{"asset_id":"60386828328910021732068595344565885737045900010034836345809386672230885527307","best_ask":"0.003","best_bid":"0.001","event_type":"best_bid_ask","market":"0xeb66215f2e9faa6449e30a02bab5b8ed7b79a38bf961f6b24d0073c9c2419250","spread":"0.002","timestamp":"1785127454591"},"payload_hash":"9632e6c0f435527f5718cca9e947d3af608970ebfa3ff13fa5eea88d9c99573b","raw_frame":"{\"market\":\"0xeb66215f2e9faa6449e30a02bab5b8ed7b79a38bf961f6b24d0073c9c2419250\", \"asset_id\":\"60386828328910021732068595344565885737045900010034836345809386672230885527307\", \"best_bid\":\"0.001\", \"best_ask\":\"0.003\", \"spread\":\"0.002\", \"timestamp\":\"1785127454591\", \"event_type\":\"best_bid_ask\"}","received_at":"2026-07-27T04:44:14.540267Z","schema_version":"clob-market-ws.best_bid_ask.v1","sequence":null,"server_hash":null,"server_timestamp":"1785127454591","session_id":"e9443c7415a0419799bee9cfbb1a9e4d","source":"clob_market_ws"},"received_at":"2026-07-27T04:44:14.540267Z","record_id":"19f3f5eb356d41607dad7baef3004b69fc0ab90192b17790a5d8ef6bbcfb3bca","schema_fingerprint":"8488399f31b0337811b13b266be932db7062827c2470b78bd8e9e99bab51d17d","schema_version":"edge-lab-recorder.raw.v1","sequence":null,"source":"clob_market_ws"}
{"event_at":"2026-07-27T04:44:14.591000Z","event_fingerprint":"798c81051c8cca7e9d723329e4ba0e7a5b7412fb0df078dd230877f38da7d4d1","payload":{"connection_id":"0f4979d6978d463e9660b042fdcf555f","event_at":"2026-07-27T04:44:14.591000Z","event_type":"price_change","frame_hash":"69b085adae8fe2587b31526bfbb13843e41594019d6ee64e4a13f4d35bdba95d","frame_index":0,"kind":"data","monotonic_ns":229437803718458,"payload":{"event_type":"price_change","market":"0xeb66215f2e9faa6449e30a02bab5b8ed7b79a38bf961f6b24d0073c9c2419250","price_changes":[{"asset_id":"60386828328910021732068595344565885737045900010034836345809386672230885527307","best_ask":"0.003","best_bid":"0.001","hash":"9a98054617cbde6dac7230242c63b3fe12ab31cf","price":"0.003","side":"SELL","size":"275.12"},{"asset_id":"69697746896130839564035629862476347944307040470122503199396727085502753297492","best_ask":"0.999","best_bid":"0.997","hash":"be65fc76333a994024f089b54825f8ad3e5280ae","price":"0.997","side":"BUY","size":"275.12"}],"timestamp":"1785127454591"},"payload_hash":"6c652d422f8bcb70e653a519abc09b07c453384926593a7b8abd144e0dce1c90","raw_frame":"{\"market\":\"0xeb66215f2e9faa6449e30a02bab5b8ed7b79a38bf961f6b24d0073c9c2419250\", \"price_changes\":[{\"asset_id\":\"60386828328910021732068595344565885737045900010034836345809386672230885527307\", \"price\":\"0.003\", \"size\":\"275.12\", \"side\":\"SELL\", \"hash\":\"9a98054617cbde6dac7230242c63b3fe12ab31cf\", \"best_bid\":\"0.001\", \"best_ask\":\"0.003\"}, {\"asset_id\":\"69697746896130839564035629862476347944307040470122503199396727085502753297492\", \"price\":\"0.997\", \"size\":\"275.12\", \"side\":\"BUY\", \"hash\":\"be65fc76333a994024f089b54825f8ad3e5280ae\", \"best_bid\":\"0.997\", \"best_ask\":\"0.999\"}], \"timestamp\":\"1785127454591\", \"event_type\":\"price_change\"}","received_at":"2026-07-27T04:44:14.541287Z","schema_version":"clob-market-ws.price_change.v1","sequence":null,"server_hash":null,"server_timestamp":"1785127454591","session_id":"e9443c7415a0419799bee9cfbb1a9e4d","source":"clob_market_ws"},"received_at":"2026-07-27T04:44:14.541287Z","record_id":"a8a15f9904b5d02f5075945eb47260ca9a9b2ce50c8ce5f5f9e02bf530203ec5","schema_fingerprint":"4aa3821a28b0b7c2400bc59aba4bcc0a76e971dadd19610d3ad38c768e124dc7","schema_version":"edge-lab-recorder.raw.v1","sequence":null,"source":"clob_market_ws"}
{"event_at":"2026-07-27T04:44:14.611000Z","event_fingerprint":"8ec925caeb67710a633a0b6ee78c9f60be7b40cfd7188b6b2b6b967b4d1ed5d2","payload":{"connection_id":"0f4979d6978d463e9660b042fdcf555f","event_at":"2026-07-27T04:44:14.611000Z","event_type":"best_bid_ask","frame_hash":"9d4bd2b9a6f9e10c19740b7eaae8436570c8bea671bece386251a63e382dd45b","frame_index":0,"kind":"data","monotonic_ns":229437821308833,"payload":{"asset_id":"69697746896130839564035629862476347944307040470122503199396727085502753297492","best_ask":"0.999","best_bid":"0.996","event_type":"best_bid_ask","market":"0xeb66215f2e9faa6449e30a02bab5b8ed7b79a38bf961f6b24d0073c9c2419250","spread":"0.003","timestamp":"1785127454611"},"payload_hash":"f4b28a8a91f32f6e5994c5fd1c605f782ea155b3724aa3e3dac07463d1f7150a","raw_frame":"{\"market\":\"0xeb66215f2e9faa6449e30a02bab5b8ed7b79a38bf961f6b24d0073c9c2419250\", \"asset_id\":\"69697746896130839564035629862476347944307040470122503199396727085502753297492\", \"best_bid\":\"0.996\", \"best_ask\":\"0.999\", \"spread\":\"0.003\", \"timestamp\":\"1785127454611\", \"event_type\":\"best_bid_ask\"}","received_at":"2026-07-27T04:44:14.558875Z","schema_version":"clob-market-ws.best_bid_ask.v1","sequence":null,"server_hash":null,"server_timestamp":"1785127454611","session_id":"e9443c7415a0419799bee9cfbb1a9e4d","source":"clob_market_ws"},"received_at":"2026-07-27T04:44:14.558875Z","record_id":"8ca9e2102a71edf695203515e05f2acc684829faf88108e6a14932403ff188ac","schema_fingerprint":"8488399f31b0337811b13b266be932db7062827c2470b78bd8e9e99bab51d17d","schema_version":"edge-lab-recorder.raw.v1","sequence":null,"source":"clob_market_ws"}
{"event_at":"2026-07-27T04:44:14.611000Z","event_fingerprint":"b48af0974bbb21dada51fce8fa07f92bddac0a247b0f6b7eeeb05b7c66c1f9b5","payload":{"connection_id":"0f4979d6978d463e9660b042fdcf555f","event_at":"2026-07-27T04:44:14.611000Z","event_type":"best_bid_ask","frame_hash":"9ead09ed243a2533d0f19268107d3bd1aeb2e756e6e4ed1475e0fca9a20a0935","frame_index":0,"kind":"data","monotonic_ns":229437822412583,"payload":{"asset_id":"60386828328910021732068595344565885737045900010034836345809386672230885527307","best_ask":"0.004","best_bid":"0.001","event_type":"best_bid_ask","market":"0xeb66215f2e9faa6449e30a02bab5b8ed7b79a38bf961f6b24d0073c9c2419250","spread":"0.003","timestamp":"1785127454611"},"payload_hash":"d33e0d6a51e9a82a037a07308e259add14b5af8b174a946b094d870271547e5d","raw_frame":"{\"market\":\"0xeb66215f2e9faa6449e30a02bab5b8ed7b79a38bf961f6b24d0073c9c2419250\", \"asset_id\":\"60386828328910021732068595344565885737045900010034836345809386672230885527307\", \"best_bid\":\"0.001\", \"best_ask\":\"0.004\", \"spread\":\"0.003\", \"timestamp\":\"1785127454611\", \"event_type\":\"best_bid_ask\"}","received_at":"2026-07-27T04:44:14.559982Z","schema_version":"clob-market-ws.best_bid_ask.v1","sequence":null,"server_hash":null,"server_timestamp":"1785127454611","session_id":"e9443c7415a0419799bee9cfbb1a9e4d","source":"clob_market_ws"},"received_at":"2026-07-27T04:44:14.559982Z","record_id":"b02c2a2295687e11d50e28b935261c46652c9383c8bf0b7bd30494b30594170e","schema_fingerprint":"8488399f31b0337811b13b266be932db7062827c2470b78bd8e9e99bab51d17d","schema_version":"edge-lab-recorder.raw.v1","sequence":null,"source":"clob_market_ws"}
