{"event_at":null,"event_fingerprint":"5e3d66a33d571dee7be4457001812930d426b9992b9b5505d4f1cd42e1f6f4a9","payload":{"connection_id":"0f4979d6978d463e9660b042fdcf555f","event_type":"heartbeat_ack","frame_hash":"95784973cc639977bff93619700168505cb8f7855e44fa643d34622a43706c87","kind":"lifecycle","monotonic_ns":228352587956791,"raw_frame":"PONG","received_at":"2026-07-27T04:26:09.316115Z","schema_version":"edge-lab-recorder.heartbeat-ack.v1","session_id":"e9443c7415a0419799bee9cfbb1a9e4d","source":"clob_market_ws"},"received_at":"2026-07-27T04:26:09.316115Z","record_id":"36d8c3d836ea0a433f8eed421de8a25c8eb00682641e4d446475155ec8595537","schema_fingerprint":"c14ee1aab3ca674ee738e5268877b544d74c41ad3c427cedc09236467dc68ba1","schema_version":"edge-lab-recorder.raw.v1","sequence":null,"source":"clob_market_ws"}
{"event_at":"2026-07-27T04:26:10.283000Z","event_fingerprint":"4efbe3f61b65d721e8fd7f5667ce2da19952b64870ae2f1fff3778f98322cb64","payload":{"connection_id":"0f4979d6978d463e9660b042fdcf555f","event_at":"2026-07-27T04:26:10.283000Z","event_type":"price_change","frame_hash":"6739c91b0a4d7fd4855366ccc61936df5b4ff7bec373a7faf1df8c5c9e0ee644","frame_index":0,"kind":"data","monotonic_ns":228353500408500,"payload":{"event_type":"price_change","market":"0xeb66215f2e9faa6449e30a02bab5b8ed7b79a38bf961f6b24d0073c9c2419250","price_changes":[{"asset_id":"69697746896130839564035629862476347944307040470122503199396727085502753297492","best_ask":"0.46","best_bid":"0.45","hash":"da8b9024fc1ad23e2e55f320009017c9172a65cd","price":"0.42","side":"BUY","size":"222"},{"asset_id":"60386828328910021732068595344565885737045900010034836345809386672230885527307","best_ask":"0.55","best_bid":"0.54","hash":"19a8d5266ba5f03ea91f500cb3cd6d5dcf3d75f7","price":"0.58","side":"SELL","size":"222"}],"timestamp":"1785126370283"},"payload_hash":"a727eb95d1f8b08827ead2aa2e1f8c52b072b24fa59e6f63a6f8135a61e181e2","raw_frame":"{\"market\":\"0xeb66215f2e9faa6449e30a02bab5b8ed7b79a38bf961f6b24d0073c9c2419250\", \"price_changes\":[{\"asset_id\":\"69697746896130839564035629862476347944307040470122503199396727085502753297492\", \"price\":\"0.42\", \"size\":\"222\", \"side\":\"BUY\", \"hash\":\"da8b9024fc1ad23e2e55f320009017c9172a65cd\", \"best_bid\":\"0.45\", \"best_ask\":\"0.46\"}, {\"asset_id\":\"60386828328910021732068595344565885737045900010034836345809386672230885527307\", \"price\":\"0.58\", \"size\":\"222\", \"side\":\"SELL\", \"hash\":\"19a8d5266ba5f03ea91f500cb3cd6d5dcf3d75f7\", \"best_bid\":\"0.54\", \"best_ask\":\"0.55\"}], \"timestamp\":\"1785126370283\", \"event_type\":\"price_change\"}","received_at":"2026-07-27T04:26:10.228577Z","schema_version":"clob-market-ws.price_change.v1","sequence":null,"server_hash":null,"server_timestamp":"1785126370283","session_id":"e9443c7415a0419799bee9cfbb1a9e4d","source":"clob_market_ws"},"received_at":"2026-07-27T04:26:10.228577Z","record_id":"376850aa371a5129494f2b70b498c6c12dbfca6b677ff9b06eb568f0dac73da2","schema_fingerprint":"4aa3821a28b0b7c2400bc59aba4bcc0a76e971dadd19610d3ad38c768e124dc7","schema_version":"edge-lab-recorder.raw.v1","sequence":null,"source":"clob_market_ws"}
{"event_at":"2026-07-27T04:26:10.283000Z","event_fingerprint":"0a83559ec01b8410c06b5a2158dbbd9b56d72ba315a010e925dd66ba11179e8f","payload":{"connection_id":"0f4979d6978d463e9660b042fdcf555f","event_at":"2026-07-27T04:26:10.283000Z","event_type":"price_change","frame_hash":"56dcb86f55205829236110c2c048508bfac0cc0c648189138c09841531d7237f","frame_index":0,"kind":"data","monotonic_ns":228353507082625,"payload":{"event_type":"price_change","market":"0xeb66215f2e9faa6449e30a02bab5b8ed7b79a38bf961f6b24d0073c9c2419250","price_changes":[{"asset_id":"60386828328910021732068595344565885737045900010034836345809386672230885527307","best_ask":"0.55","best_bid":"0.54","hash":"19a8d5266ba5f03ea91f500cb3cd6d5dcf3d75f7","price":"0.54","side":"BUY","size":"325.42"},{"asset_id":"69697746896130839564035629862476347944307040470122503199396727085502753297492","best_ask":"0.46","best_bid":"0.45","hash":"da8b9024fc1ad23e2e55f320009017c9172a65cd","price":"0.46","side":"SELL","size":"325.42"}],"timestamp":"1785126370283"},"payload_hash":"6de501e4506b83323423c9e8ea8813bd2033cdf18f8243696201e23e072c63af","raw_frame":"{\"market\":\"0xeb66215f2e9faa6449e30a02bab5b8ed7b79a38bf961f6b24d0073c9c2419250\", \"price_changes\":[{\"asset_id\":\"60386828328910021732068595344565885737045900010034836345809386672230885527307\", \"price\":\"0.54\", \"size\":\"325.42\", \"side\":\"BUY\", \"hash\":\"19a8d5266ba5f03ea91f500cb3cd6d5dcf3d75f7\", \"best_bid\":\"0.54\", \"best_ask\":\"0.55\"}, {\"asset_id\":\"69697746896130839564035629862476347944307040470122503199396727085502753297492\", \"price\":\"0.46\", \"size\":\"325.42\", \"side\":\"SELL\", \"hash\":\"da8b9024fc1ad23e2e55f320009017c9172a65cd\", \"best_bid\":\"0.45\", \"best_ask\":\"0.46\"}], \"timestamp\":\"1785126370283\", \"event_type\":\"price_change\"}","received_at":"2026-07-27T04:26:10.235252Z","schema_version":"clob-market-ws.price_change.v1","sequence":null,"server_hash":null,"server_timestamp":"1785126370283","session_id":"e9443c7415a0419799bee9cfbb1a9e4d","source":"clob_market_ws"},"received_at":"2026-07-27T04:26:10.235252Z","record_id":"78b9f2088ef77ebc14f2473d668c6c321cff65665b7ead0122c4a494354e0cc7","schema_fingerprint":"4aa3821a28b0b7c2400bc59aba4bcc0a76e971dadd19610d3ad38c768e124dc7","schema_version":"edge-lab-recorder.raw.v1","sequence":null,"source":"clob_market_ws"}
{"event_at":"2026-07-27T04:26:10.284000Z","event_fingerprint":"9ffc53ab3abe3f556bfdf3f6274d2bfb1e6d1b12609f43bd262bafaf97ca2fac","payload":{"connection_id":"0f4979d6978d463e9660b042fdcf555f","event_at":"2026-07-27T04:26:10.284000Z","event_type":"price_change","frame_hash":"617ad29c45075548dde7ac4d81394b9e488a93d3cace38c4a19c92fcf53f8853","frame_index":0,"kind":"data","monotonic_ns":228353513961875,"payload":{"event_type":"price_change","market":"0xeb66215f2e9faa6449e30a02bab5b8ed7b79a38bf961f6b24d0073c9c2419250","price_changes":[{"asset_id":"69697746896130839564035629862476347944307040470122503199396727085502753297492","best_ask":"0.46","best_bid":"0.45","hash":"1d388e59b276a7d631b7622808b5127425c31590","price":"0.42","side":"BUY","size":"122"},{"asset_id":"60386828328910021732068595344565885737045900010034836345809386672230885527307","best_ask":"0.55","best_bid":"0.54","hash":"cfaab359710eb8682668b3c9d6dcdecb8ff9c47a","price":"0.58","side":"SELL","size":"122"}],"timestamp":"1785126370284"},"payload_hash":"9f1c6b56374a959e185d28f10da7d72b4c92f49c1cc7c400bcce804dcd428ba0","raw_frame":"{\"market\":\"0xeb66215f2e9faa6449e30a02bab5b8ed7b79a38bf961f6b24d0073c9c2419250\", \"price_changes\":[{\"asset_id\":\"69697746896130839564035629862476347944307040470122503199396727085502753297492\", \"price\":\"0.42\", \"size\":\"122\", \"side\":\"BUY\", \"hash\":\"1d388e59b276a7d631b7622808b5127425c31590\", \"best_bid\":\"0.45\", \"best_ask\":\"0.46\"}, {\"asset_id\":\"60386828328910021732068595344565885737045900010034836345809386672230885527307\", \"price\":\"0.58\", \"size\":\"122\", \"side\":\"SELL\", \"hash\":\"cfaab359710eb8682668b3c9d6dcdecb8ff9c47a\", \"best_bid\":\"0.54\", \"best_ask\":\"0.55\"}], \"timestamp\":\"1785126370284\", \"event_type\":\"price_change\"}","received_at":"2026-07-27T04:26:10.242132Z","schema_version":"clob-market-ws.price_change.v1","sequence":null,"server_hash":null,"server_timestamp":"1785126370284","session_id":"e9443c7415a0419799bee9cfbb1a9e4d","source":"clob_market_ws"},"received_at":"2026-07-27T04:26:10.242132Z","record_id":"82129dc5b022692530bb87906bacd83ca9240165e43d48958072b21ed987dddb","schema_fingerprint":"4aa3821a28b0b7c2400bc59aba4bcc0a76e971dadd19610d3ad38c768e124dc7","schema_version":"edge-lab-recorder.raw.v1","sequence":null,"source":"clob_market_ws"}
{"event_at":"2026-07-27T04:26:10.284000Z","event_fingerprint":"8f9ab25d6ef0c16b7230c5cb34383e79ed7fc860441764e604cfbf7e44758a73","payload":{"connection_id":"0f4979d6978d463e9660b042fdcf555f","event_at":"2026-07-27T04:26:10.284000Z","event_type":"price_change","frame_hash":"5022b9a10065ff82c981b538f79be7a07037d86b0f2e7a217712dac601668d50","frame_index":0,"kind":"data","monotonic_ns":228353520112958,"payload":{"event_type":"price_change","market":"0xeb66215f2e9faa6449e30a02bab5b8ed7b79a38bf961f6b24d0073c9c2419250","price_changes":[{"asset_id":"60386828328910021732068595344565885737045900010034836345809386672230885527307","best_ask":"0.55","best_bid":"0.54","hash":"cfaab359710eb8682668b3c9d6dcdecb8ff9c47a","price":"0.54","side":"BUY","size":"225.42"},{"asset_id":"69697746896130839564035629862476347944307040470122503199396727085502753297492","best_ask":"0.46","best_bid":"0.45","hash":"1d388e59b276a7d631b7622808b5127425c31590","price":"0.46","side":"SELL","size":"225.42"}],"timestamp":"1785126370284"},"payload_hash":"0e3c03d864f6633789c32e91a41d2f6f1bdebb3ed9902dbecad4d78eff4b5bfb","raw_frame":"{\"market\":\"0xeb66215f2e9faa6449e30a02bab5b8ed7b79a38bf961f6b24d0073c9c2419250\", \"price_changes\":[{\"asset_id\":\"60386828328910021732068595344565885737045900010034836345809386672230885527307\", \"price\":\"0.54\", \"size\":\"225.42\", \"side\":\"BUY\", \"hash\":\"cfaab359710eb8682668b3c9d6dcdecb8ff9c47a\", \"best_bid\":\"0.54\", \"best_ask\":\"0.55\"}, {\"asset_id\":\"69697746896130839564035629862476347944307040470122503199396727085502753297492\", \"price\":\"0.46\", \"size\":\"225.42\", \"side\":\"SELL\", \"hash\":\"1d388e59b276a7d631b7622808b5127425c31590\", \"best_bid\":\"0.45\", \"best_ask\":\"0.46\"}], \"timestamp\":\"1785126370284\", \"event_type\":\"price_change\"}","received_at":"2026-07-27T04:26:10.248283Z","schema_version":"clob-market-ws.price_change.v1","sequence":null,"server_hash":null,"server_timestamp":"1785126370284","session_id":"e9443c7415a0419799bee9cfbb1a9e4d","source":"clob_market_ws"},"received_at":"2026-07-27T04:26:10.248283Z","record_id":"994c70961b583cee73fed6e373c9f65f1cb6b52b4e6bd879f4662da861cb3151","schema_fingerprint":"4aa3821a28b0b7c2400bc59aba4bcc0a76e971dadd19610d3ad38c768e124dc7","schema_version":"edge-lab-recorder.raw.v1","sequence":null,"source":"clob_market_ws"}
{"event_at":"2026-07-27T04:26:10.338000Z","event_fingerprint":"847441424ecd848601bf73c0911bd5ed48105c584bf44be86dd160d02895cc6b","payload":{"connection_id":"0f4979d6978d463e9660b042fdcf555f","event_at":"2026-07-27T04:26:10.338000Z","event_type":"price_change","frame_hash":"0b698bef7f635f0fd96c7db54cbdb14e2bbdf55ef245d535d66c46355ee14690","frame_index":0,"kind":"data","monotonic_ns":228353558012208,"payload":{"event_type":"price_change","market":"0xeb66215f2e9faa6449e30a02bab5b8ed7b79a38bf961f6b24d0073c9c2419250","price_changes":[{"asset_id":"60386828328910021732068595344565885737045900010034836345809386672230885527307","best_ask":"0.55","best_bid":"0.54","hash":"6e3af95b573fd351c430d86656ec04a7851041c0","price":"0.51","side":"BUY","size":"30"},{"asset_id":"69697746896130839564035629862476347944307040470122503199396727085502753297492","best_ask":"0.46","best_bid":"0.45","hash":"f49710ad3756c5d22d961f9574efe488885c644a","price":"0.49","side":"SELL","size":"30"}],"timestamp":"1785126370338"},"payload_hash":"2cfd5e32bdabb412aa13ab5af64e2655c781b7ceb583d5db0b143733264abeff","raw_frame":"{\"market\":\"0xeb66215f2e9faa6449e30a02bab5b8ed7b79a38bf961f6b24d0073c9c2419250\", \"price_changes\":[{\"asset_id\":\"60386828328910021732068595344565885737045900010034836345809386672230885527307\", \"price\":\"0.51\", \"size\":\"30\", \"side\":\"BUY\", \"hash\":\"6e3af95b573fd351c430d86656ec04a7851041c0\", \"best_bid\":\"0.54\", \"best_ask\":\"0.55\"}, {\"asset_id\":\"69697746896130839564035629862476347944307040470122503199396727085502753297492\", \"price\":\"0.49\", \"size\":\"30\", \"side\":\"SELL\", \"hash\":\"f49710ad3756c5d22d961f9574efe488885c644a\", \"best_bid\":\"0.45\", \"best_ask\":\"0.46\"}], \"timestamp\":\"1785126370338\", \"event_type\":\"price_change\"}","received_at":"2026-07-27T04:26:10.286182Z","schema_version":"clob-market-ws.price_change.v1","sequence":null,"server_hash":null,"server_timestamp":"1785126370338","session_id":"e9443c7415a0419799bee9cfbb1a9e4d","source":"clob_market_ws"},"received_at":"2026-07-27T04:26:10.286182Z","record_id":"3ae6e17f09e2210920242c3aa64b6ed012f38d8b800ea5631740cfe0f96f958a","schema_fingerprint":"4aa3821a28b0b7c2400bc59aba4bcc0a76e971dadd19610d3ad38c768e124dc7","schema_version":"edge-lab-recorder.raw.v1","sequence":null,"source":"clob_market_ws"}
{"event_at":"2026-07-27T04:26:10.339000Z","event_fingerprint":"149f239e577a7e51d6167f01cee0bf74b49780c12043a2ec605d871e20467e74","payload":{"connection_id":"0f4979d6978d463e9660b042fdcf555f","event_at":"2026-07-27T04:26:10.339000Z","event_type":"price_change","frame_hash":"5e1623a3215b5804b98d0a374eca2243e4db6184d0edbb4a47eaa822fce11c33","frame_index":0,"kind":"data","monotonic_ns":228353566118833,"payload":{"event_type":"price_change","market":"0xeb66215f2e9faa6449e30a02bab5b8ed7b79a38bf961f6b24d0073c9c2419250","price_changes":[{"asset_id":"60386828328910021732068595344565885737045900010034836345809386672230885527307","best_ask":"0.55","best_bid":"0.54","hash":"cf763db7a153f11cfa4c30e1cc5bfba650a9ed8b","price":"0.51","side":"BUY","size":"35"},{"asset_id":"69697746896130839564035629862476347944307040470122503199396727085502753297492","best_ask":"0.46","best_bid":"0.45","hash":"0ae9a9d449fb4b39a45b162e5357c6472389d70b","price":"0.49","side":"SELL","size":"35"}],"timestamp":"1785126370339"},"payload_hash":"ea3a7e2aba44a08587478bf12b46e81627bc4f1aec9e179531631e728591d237","raw_frame":"{\"market\":\"0xeb66215f2e9faa6449e30a02bab5b8ed7b79a38bf961f6b24d0073c9c2419250\", \"price_changes\":[{\"asset_id\":\"60386828328910021732068595344565885737045900010034836345809386672230885527307\", \"price\":\"0.51\", \"size\":\"35\", \"side\":\"BUY\", \"hash\":\"cf763db7a153f11cfa4c30e1cc5bfba650a9ed8b\", \"best_bid\":\"0.54\", \"best_ask\":\"0.55\"}, {\"asset_id\":\"69697746896130839564035629862476347944307040470122503199396727085502753297492\", \"price\":\"0.49\", \"size\":\"35\", \"side\":\"SELL\", \"hash\":\"0ae9a9d449fb4b39a45b162e5357c6472389d70b\", \"best_bid\":\"0.45\", \"best_ask\":\"0.46\"}], \"timestamp\":\"1785126370339\", \"event_type\":\"price_change\"}","received_at":"2026-07-27T04:26:10.294289Z","schema_version":"clob-market-ws.price_change.v1","sequence":null,"server_hash":null,"server_timestamp":"1785126370339","session_id":"e9443c7415a0419799bee9cfbb1a9e4d","source":"clob_market_ws"},"received_at":"2026-07-27T04:26:10.294289Z","record_id":"79bb358cb650baf1ac7bb3bf4208c7a2b8d58d82713fd7597aaffcacad8fe351","schema_fingerprint":"4aa3821a28b0b7c2400bc59aba4bcc0a76e971dadd19610d3ad38c768e124dc7","schema_version":"edge-lab-recorder.raw.v1","sequence":null,"source":"clob_market_ws"}
{"event_at":"2026-07-27T04:26:10.340000Z","event_fingerprint":"8540f077e5b551cf59130aa185d63bbece495d2ec54f260b3f6cd2d044e5e41f","payload":{"connection_id":"0f4979d6978d463e9660b042fdcf555f","event_at":"2026-07-27T04:26:10.340000Z","event_type":"price_change","frame_hash":"50e027de8dacf049c924182ad047440dc362a20eb005ea6da36cf1c8e2bde114","frame_index":0,"kind":"data","monotonic_ns":228353574860041,"payload":{"event_type":"price_change","market":"0xeb66215f2e9faa6449e30a02bab5b8ed7b79a38bf961f6b24d0073c9c2419250","price_changes":[{"asset_id":"60386828328910021732068595344565885737045900010034836345809386672230885527307","best_ask":"0.55","best_bid":"0.54","hash":"6b392cffe00d1ec711966d589e3d6d0ce761accf","price":"0.51","side":"BUY","size":"40"},{"asset_id":"69697746896130839564035629862476347944307040470122503199396727085502753297492","best_ask":"0.46","best_bid":"0.45","hash":"447c7c7d9e548d06070927a99d8e54526c238071","price":"0.49","side":"SELL","size":"40"}],"timestamp":"1785126370340"},"payload_hash":"6a1fc9f04a5cbacd91c56e2656a4c0aa506311020f762b46252521bc3e5f5625","raw_frame":"{\"market\":\"0xeb66215f2e9faa6449e30a02bab5b8ed7b79a38bf961f6b24d0073c9c2419250\", \"price_changes\":[{\"asset_id\":\"60386828328910021732068595344565885737045900010034836345809386672230885527307\", \"price\":\"0.51\", \"size\":\"40\", \"side\":\"BUY\", \"hash\":\"6b392cffe00d1ec711966d589e3d6d0ce761accf\", \"best_bid\":\"0.54\", \"best_ask\":\"0.55\"}, {\"asset_id\":\"69697746896130839564035629862476347944307040470122503199396727085502753297492\", \"price\":\"0.49\", \"size\":\"40\", \"side\":\"SELL\", \"hash\":\"447c7c7d9e548d06070927a99d8e54526c238071\", \"best_bid\":\"0.45\", \"best_ask\":\"0.46\"}], \"timestamp\":\"1785126370340\", \"event_type\":\"price_change\"}","received_at":"2026-07-27T04:26:10.303030Z","schema_version":"clob-market-ws.price_change.v1","sequence":null,"server_hash":null,"server_timestamp":"1785126370340","session_id":"e9443c7415a0419799bee9cfbb1a9e4d","source":"clob_market_ws"},"received_at":"2026-07-27T04:26:10.303030Z","record_id":"95f2e90d3bcbf26eb38d07b066aa1aa90fb9a9b9fea6abdbb59b16a62b7074f3","schema_fingerprint":"4aa3821a28b0b7c2400bc59aba4bcc0a76e971dadd19610d3ad38c768e124dc7","schema_version":"edge-lab-recorder.raw.v1","sequence":null,"source":"clob_market_ws"}
{"event_at":"2026-07-27T04:26:10.340000Z","event_fingerprint":"d1185abf47369de4cbfd9192c9660063e651f5e18a6fa04a82d8b14d2f71cda2","payload":{"connection_id":"0f4979d6978d463e9660b042fdcf555f","event_at":"2026-07-27T04:26:10.340000Z","event_type":"price_change","frame_hash":"07b0d22fbcdcc12746ff6e15ee95174258059d78b7ad227f43cd0e2fbe89c6ff","frame_index":0,"kind":"data","monotonic_ns":228353587288500,"payload":{"event_type":"price_change","market":"0xeb66215f2e9faa6449e30a02bab5b8ed7b79a38bf961f6b24d0073c9c2419250","price_changes":[{"asset_id":"60386828328910021732068595344565885737045900010034836345809386672230885527307","best_ask":"0.55","best_bid":"0.54","hash":"886a1427679ab6b19bc5ef89bc83d605fbd28cce","price":"0.51","side":"BUY","size":"45"},{"asset_id":"69697746896130839564035629862476347944307040470122503199396727085502753297492","best_ask":"0.46","best_bid":"0.45","hash":"9a173f35efa27450b5cae106c5270ad12631424f","price":"0.49","side":"SELL","size":"45"}],"timestamp":"1785126370340"},"payload_hash":"c21f47e8c10214c3876b3a604b159af2dde33262293ed5aa8b77e259e8960277","raw_frame":"{\"market\":\"0xeb66215f2e9faa6449e30a02bab5b8ed7b79a38bf961f6b24d0073c9c2419250\", \"price_changes\":[{\"asset_id\":\"60386828328910021732068595344565885737045900010034836345809386672230885527307\", \"price\":\"0.51\", \"size\":\"45\", \"side\":\"BUY\", \"hash\":\"886a1427679ab6b19bc5ef89bc83d605fbd28cce\", \"best_bid\":\"0.54\", \"best_ask\":\"0.55\"}, {\"asset_id\":\"69697746896130839564035629862476347944307040470122503199396727085502753297492\", \"price\":\"0.49\", \"size\":\"45\", \"side\":\"SELL\", \"hash\":\"9a173f35efa27450b5cae106c5270ad12631424f\", \"best_bid\":\"0.45\", \"best_ask\":\"0.46\"}], \"timestamp\":\"1785126370340\", \"event_type\":\"price_change\"}","received_at":"2026-07-27T04:26:10.315459Z","schema_version":"clob-market-ws.price_change.v1","sequence":null,"server_hash":null,"server_timestamp":"1785126370340","session_id":"e9443c7415a0419799bee9cfbb1a9e4d","source":"clob_market_ws"},"received_at":"2026-07-27T04:26:10.315459Z","record_id":"af3a456adf876fcc25935d90d2b294f09dcfa557392335c5bef1ede866fb1fcb","schema_fingerprint":"4aa3821a28b0b7c2400bc59aba4bcc0a76e971dadd19610d3ad38c768e124dc7","schema_version":"edge-lab-recorder.raw.v1","sequence":null,"source":"clob_market_ws"}
{"event_at":"2026-07-27T04:26:10.341000Z","event_fingerprint":"30aedd70eab3d680379bbf94b071aef04b890cccce5e742855d9e5c3cdb8f34d","payload":{"connection_id":"0f4979d6978d463e9660b042fdcf555f","event_at":"2026-07-27T04:26:10.341000Z","event_type":"price_change","frame_hash":"b2624ba9c55add87e85ebb7e09b2a4a9c7409d3188842f0c895b109f398f22b9","frame_index":0,"kind":"data","monotonic_ns":228353604530875,"payload":{"event_type":"price_change","market":"0xeb66215f2e9faa6449e30a02bab5b8ed7b79a38bf961f6b24d0073c9c2419250","price_changes":[{"asset_id":"60386828328910021732068595344565885737045900010034836345809386672230885527307","best_ask":"0.55","best_bid":"0.54","hash":"1c20421f2b68c3da110694a08ec2cc98b35f3790","price":"0.51","side":"BUY","size":"50"},{"asset_id":"69697746896130839564035629862476347944307040470122503199396727085502753297492","best_ask":"0.46","best_bid":"0.45","hash":"4a4e67a7bb0f3127d7e571ff3e850ef2d020052f","price":"0.49","side":"SELL","size":"50"}],"timestamp":"1785126370341"},"payload_hash":"e0badc22ed89c64a23f07d2b0a6ee49f086f2c33fc8be0f0c1105af147d54ce3","raw_frame":"{\"market\":\"0xeb66215f2e9faa6449e30a02bab5b8ed7b79a38bf961f6b24d0073c9c2419250\", \"price_changes\":[{\"asset_id\":\"60386828328910021732068595344565885737045900010034836345809386672230885527307\", \"price\":\"0.51\", \"size\":\"50\", \"side\":\"BUY\", \"hash\":\"1c20421f2b68c3da110694a08ec2cc98b35f3790\", \"best_bid\":\"0.54\", \"best_ask\":\"0.55\"}, {\"asset_id\":\"69697746896130839564035629862476347944307040470122503199396727085502753297492\", \"price\":\"0.49\", \"size\":\"50\", \"side\":\"SELL\", \"hash\":\"4a4e67a7bb0f3127d7e571ff3e850ef2d020052f\", \"best_bid\":\"0.45\", \"best_ask\":\"0.46\"}], \"timestamp\":\"1785126370341\", \"event_type\":\"price_change\"}","received_at":"2026-07-27T04:26:10.332702Z","schema_version":"clob-market-ws.price_change.v1","sequence":null,"server_hash":null,"server_timestamp":"1785126370341","session_id":"e9443c7415a0419799bee9cfbb1a9e4d","source":"clob_market_ws"},"received_at":"2026-07-27T04:26:10.332702Z","record_id":"3be3cf225de09fdeaa674479636c46d0b7fa0cd9c69d71abda9255594cc7c5c4","schema_fingerprint":"4aa3821a28b0b7c2400bc59aba4bcc0a76e971dadd19610d3ad38c768e124dc7","schema_version":"edge-lab-recorder.raw.v1","sequence":null,"source":"clob_market_ws"}
{"event_at":"2026-07-27T04:26:10.343000Z","event_fingerprint":"2880a7f403095d7dc01a5a2a528038295e3670b6100eda31dc5a831a39be941c","payload":{"connection_id":"0f4979d6978d463e9660b042fdcf555f","event_at":"2026-07-27T04:26:10.343000Z","event_type":"price_change","frame_hash":"c23c61c62ed016cfa2978255a91f1fccaded01e33287d2dcd2f14d5c54f6c858","frame_index":0,"kind":"data","monotonic_ns":228353614856166,"payload":{"event_type":"price_change","market":"0xeb66215f2e9faa6449e30a02bab5b8ed7b79a38bf961f6b24d0073c9c2419250","price_changes":[{"asset_id":"69697746896130839564035629862476347944307040470122503199396727085502753297492","best_ask":"0.46","best_bid":"0.45","hash":"bb74368e3611ea1cba07ce4b96ccdc049ca8daa8","price":"0.45","side":"BUY","size":"177.95"},{"asset_id":"60386828328910021732068595344565885737045900010034836345809386672230885527307","best_ask":"0.55","best_bid":"0.54","hash":"2fcbd5c5ac0c26dac355a12a672ddff089fbe255","price":"0.55","side":"SELL","size":"177.95"}],"timestamp":"1785126370343"},"payload_hash":"be1f4be7475a7ae516e68bc729135ca6ad0314a158a352abfc500c2eca3bfae1","raw_frame":"{\"market\":\"0xeb66215f2e9faa6449e30a02bab5b8ed7b79a38bf961f6b24d0073c9c2419250\", \"price_changes\":[{\"asset_id\":\"69697746896130839564035629862476347944307040470122503199396727085502753297492\", \"price\":\"0.45\", \"size\":\"177.95\", \"side\":\"BUY\", \"hash\":\"bb74368e3611ea1cba07ce4b96ccdc049ca8daa8\", \"best_bid\":\"0.45\", \"best_ask\":\"0.46\"}, {\"asset_id\":\"60386828328910021732068595344565885737045900010034836345809386672230885527307\", \"price\":\"0.55\", \"size\":\"177.95\", \"side\":\"SELL\", \"hash\":\"2fcbd5c5ac0c26dac355a12a672ddff089fbe255\", \"best_bid\":\"0.54\", \"best_ask\":\"0.55\"}], \"timestamp\":\"1785126370343\", \"event_type\":\"price_change\"}","received_at":"2026-07-27T04:26:10.343026Z","schema_version":"clob-market-ws.price_change.v1","sequence":null,"server_hash":null,"server_timestamp":"1785126370343","session_id":"e9443c7415a0419799bee9cfbb1a9e4d","source":"clob_market_ws"},"received_at":"2026-07-27T04:26:10.343026Z","record_id":"77353c7883ea5d8602f32bd4765f96385cb9b51cd2c85b1d26117d968e2df6be","schema_fingerprint":"4aa3821a28b0b7c2400bc59aba4bcc0a76e971dadd19610d3ad38c768e124dc7","schema_version":"edge-lab-recorder.raw.v1","sequence":null,"source":"clob_market_ws"}
{"event_at":"2026-07-27T04:26:10.344000Z","event_fingerprint":"8213c26d7b6a12e91e3d3ac40e0fb92aebd5f30f8f3959db0db197f3623405af","payload":{"connection_id":"0f4979d6978d463e9660b042fdcf555f","event_at":"2026-07-27T04:26:10.344000Z","event_type":"price_change","frame_hash":"f8d2f4bdcc64cedf8fe488a9dd0eef7b572f1134d884689a12ecebfa7094c0e7","frame_index":0,"kind":"data","monotonic_ns":228353622266041,"payload":{"event_type":"price_change","market":"0xeb66215f2e9faa6449e30a02bab5b8ed7b79a38bf961f6b24d0073c9c2419250","price_changes":[{"asset_id":"69697746896130839564035629862476347944307040470122503199396727085502753297492","best_ask":"0.46","best_bid":"0.45","hash":"3f94a1c08d8917ac74cf48de09a4f9b3ebc4d725","price":"0.45","side":"BUY","size":"182.95"},{"asset_id":"60386828328910021732068595344565885737045900010034836345809386672230885527307","best_ask":"0.55","best_bid":"0.54","hash":"1a438c9ae58e9d13c10c5ca270135c97ab1e053b","price":"0.55","side":"SELL","size":"182.95"}],"timestamp":"1785126370344"},"payload_hash":"5048ae0347b654235dbd22daab54b91e97b6b202cc32dcb10977e0460617029c","raw_frame":"{\"market\":\"0xeb66215f2e9faa6449e30a02bab5b8ed7b79a38bf961f6b24d0073c9c2419250\", \"price_changes\":[{\"asset_id\":\"69697746896130839564035629862476347944307040470122503199396727085502753297492\", \"price\":\"0.45\", \"size\":\"182.95\", \"side\":\"BUY\", \"hash\":\"3f94a1c08d8917ac74cf48de09a4f9b3ebc4d725\", \"best_bid\":\"0.45\", \"best_ask\":\"0.46\"}, {\"asset_id\":\"60386828328910021732068595344565885737045900010034836345809386672230885527307\", \"price\":\"0.55\", \"size\":\"182.95\", \"side\":\"SELL\", \"hash\":\"1a438c9ae58e9d13c10c5ca270135c97ab1e053b\", \"best_bid\":\"0.54\", \"best_ask\":\"0.55\"}], \"timestamp\":\"1785126370344\", \"event_type\":\"price_change\"}","received_at":"2026-07-27T04:26:10.350437Z","schema_version":"clob-market-ws.price_change.v1","sequence":null,"server_hash":null,"server_timestamp":"1785126370344","session_id":"e9443c7415a0419799bee9cfbb1a9e4d","source":"clob_market_ws"},"received_at":"2026-07-27T04:26:10.350437Z","record_id":"b69c8d5659ee93b5db7e22e03057aafa172c8bd350553687d3c6d7a9be6f9849","schema_fingerprint":"4aa3821a28b0b7c2400bc59aba4bcc0a76e971dadd19610d3ad38c768e124dc7","schema_version":"edge-lab-recorder.raw.v1","sequence":null,"source":"clob_market_ws"}
{"event_at":"2026-07-27T04:26:10.345000Z","event_fingerprint":"1a917439f12860ece951c18a305b14ca68404cd49e5746a89c36f21f85d7c919","payload":{"connection_id":"0f4979d6978d463e9660b042fdcf555f","event_at":"2026-07-27T04:26:10.345000Z","event_type":"price_change","frame_hash":"fea187c8edb5aa99151bfcbf7eca7bb779aae7c3573f9c5e9cbdafe3abc2fcb5","frame_index":0,"kind":"data","monotonic_ns":228353690354125,"payload":{"event_type":"price_change","market":"0xeb66215f2e9faa6449e30a02bab5b8ed7b79a38bf961f6b24d0073c9c2419250","price_changes":[{"asset_id":"69697746896130839564035629862476347944307040470122503199396727085502753297492","best_ask":"0.46","best_bid":"0.45","hash":"33f0c22a378463a42497aaa36d286e6e96b7f50e","price":"0.45","side":"BUY","size":"187.95"},{"asset_id":"60386828328910021732068595344565885737045900010034836345809386672230885527307","best_ask":"0.55","best_bid":"0.54","hash":"13e0ba44fe8177a4211fa3e8ccf96c53b04df318","price":"0.55","side":"SELL","size":"187.95"}],"timestamp":"1785126370345"},"payload_hash":"6876d0f215b509a3e58fc1f6ab4b980669978a548e625e2fd45604e871de42e5","raw_frame":"{\"market\":\"0xeb66215f2e9faa6449e30a02bab5b8ed7b79a38bf961f6b24d0073c9c2419250\", \"price_changes\":[{\"asset_id\":\"69697746896130839564035629862476347944307040470122503199396727085502753297492\", \"price\":\"0.45\", \"size\":\"187.95\", \"side\":\"BUY\", \"hash\":\"33f0c22a378463a42497aaa36d286e6e96b7f50e\", \"best_bid\":\"0.45\", \"best_ask\":\"0.46\"}, {\"asset_id\":\"60386828328910021732068595344565885737045900010034836345809386672230885527307\", \"price\":\"0.55\", \"size\":\"187.95\", \"side\":\"SELL\", \"hash\":\"13e0ba44fe8177a4211fa3e8ccf96c53b04df318\", \"best_bid\":\"0.54\", \"best_ask\":\"0.55\"}], \"timestamp\":\"1785126370345\", \"event_type\":\"price_change\"}","received_at":"2026-07-27T04:26:10.418527Z","schema_version":"clob-market-ws.price_change.v1","sequence":null,"server_hash":null,"server_timestamp":"1785126370345","session_id":"e9443c7415a0419799bee9cfbb1a9e4d","source":"clob_market_ws"},"received_at":"2026-07-27T04:26:10.418527Z","record_id":"c30515a2afa5eee9bcd793cda5f51887eb7acf99ef15472623c175bca042a501","schema_fingerprint":"4aa3821a28b0b7c2400bc59aba4bcc0a76e971dadd19610d3ad38c768e124dc7","schema_version":"edge-lab-recorder.raw.v1","sequence":null,"source":"clob_market_ws"}
{"event_at":"2026-07-27T04:26:10.346000Z","event_fingerprint":"d08dea4ac7879390a1a37ccd722ee29b40a814bbe029dfe7dd30f0fcd48c9038","payload":{"connection_id":"0f4979d6978d463e9660b042fdcf555f","event_at":"2026-07-27T04:26:10.346000Z","event_type":"price_change","frame_hash":"1e90b6ebc30566375897f77319946d38c5d54ce210078c3bcd799ffe9a28f28f","frame_index":0,"kind":"data","monotonic_ns":228353695396708,"payload":{"event_type":"price_change","market":"0xeb66215f2e9faa6449e30a02bab5b8ed7b79a38bf961f6b24d0073c9c2419250","price_changes":[{"asset_id":"69697746896130839564035629862476347944307040470122503199396727085502753297492","best_ask":"0.46","best_bid":"0.45","hash":"cc6ba569e86bed0f9c714645cae9c619e8c14c1f","price":"0.45","side":"BUY","size":"192.95"},{"asset_id":"60386828328910021732068595344565885737045900010034836345809386672230885527307","best_ask":"0.55","best_bid":"0.54","hash":"b4451b7910333120fcd86f93a0fc9fc284f6f02a","price":"0.55","side":"SELL","size":"192.95"}],"timestamp":"1785126370346"},"payload_hash":"ef31c908adb322650996f08006244130f6f3f847bd415ee6aa9929339605e744","raw_frame":"{\"market\":\"0xeb66215f2e9faa6449e30a02bab5b8ed7b79a38bf961f6b24d0073c9c2419250\", \"price_changes\":[{\"asset_id\":\"69697746896130839564035629862476347944307040470122503199396727085502753297492\", \"price\":\"0.45\", \"size\":\"192.95\", \"side\":\"BUY\", \"hash\":\"cc6ba569e86bed0f9c714645cae9c619e8c14c1f\", \"best_bid\":\"0.45\", \"best_ask\":\"0.46\"}, {\"asset_id\":\"60386828328910021732068595344565885737045900010034836345809386672230885527307\", \"price\":\"0.55\", \"size\":\"192.95\", \"side\":\"SELL\", \"hash\":\"b4451b7910333120fcd86f93a0fc9fc284f6f02a\", \"best_bid\":\"0.54\", \"best_ask\":\"0.55\"}], \"timestamp\":\"1785126370346\", \"event_type\":\"price_change\"}","received_at":"2026-07-27T04:26:10.423568Z","schema_version":"clob-market-ws.price_change.v1","sequence":null,"server_hash":null,"server_timestamp":"1785126370346","session_id":"e9443c7415a0419799bee9cfbb1a9e4d","source":"clob_market_ws"},"received_at":"2026-07-27T04:26:10.423568Z","record_id":"f25d30c8496bdc1c8fb56a1a8b63ba0efd22cb68c333fd69d053c6dedb043626","schema_fingerprint":"4aa3821a28b0b7c2400bc59aba4bcc0a76e971dadd19610d3ad38c768e124dc7","schema_version":"edge-lab-recorder.raw.v1","sequence":null,"source":"clob_market_ws"}
{"event_at":"2026-07-27T04:26:10.346000Z","event_fingerprint":"459bba848916686172a614fda1a5a0b867b16932d4391c529fd8a119e0c71ad5","payload":{"connection_id":"0f4979d6978d463e9660b042fdcf555f","event_at":"2026-07-27T04:26:10.346000Z","event_type":"price_change","frame_hash":"7fd7d1ca8831161f479ed66903ceac4dab0d2a7c81ca272cd2f30d1cc649f778","frame_index":0,"kind":"data","monotonic_ns":228353700773916,"payload":{"event_type":"price_change","market":"0xeb66215f2e9faa6449e30a02bab5b8ed7b79a38bf961f6b24d0073c9c2419250","price_changes":[{"asset_id":"69697746896130839564035629862476347944307040470122503199396727085502753297492","best_ask":"0.46","best_bid":"0.45","hash":"db982b405e64c2f239eb9df620ae2108141ffb24","price":"0.45","side":"BUY","size":"197.95"},{"asset_id":"60386828328910021732068595344565885737045900010034836345809386672230885527307","best_ask":"0.55","best_bid":"0.54","hash":"e296ab2844a748dc8bd61bcb2944b71eb3548b67","price":"0.55","side":"SELL","size":"197.95"}],"timestamp":"1785126370346"},"payload_hash":"a398cd70425079647d3dc0fbc43e2c82d964e5cd640d6b8a0c35efb4c55e713b","raw_frame":"{\"market\":\"0xeb66215f2e9faa6449e30a02bab5b8ed7b79a38bf961f6b24d0073c9c2419250\", \"price_changes\":[{\"asset_id\":\"69697746896130839564035629862476347944307040470122503199396727085502753297492\", \"price\":\"0.45\", \"size\":\"197.95\", \"side\":\"BUY\", \"hash\":\"db982b405e64c2f239eb9df620ae2108141ffb24\", \"best_bid\":\"0.45\", \"best_ask\":\"0.46\"}, {\"asset_id\":\"60386828328910021732068595344565885737045900010034836345809386672230885527307\", \"price\":\"0.55\", \"size\":\"197.95\", \"side\":\"SELL\", \"hash\":\"e296ab2844a748dc8bd61bcb2944b71eb3548b67\", \"best_bid\":\"0.54\", \"best_ask\":\"0.55\"}], \"timestamp\":\"1785126370346\", \"event_type\":\"price_change\"}","received_at":"2026-07-27T04:26:10.428945Z","schema_version":"clob-market-ws.price_change.v1","sequence":null,"server_hash":null,"server_timestamp":"1785126370346","session_id":"e9443c7415a0419799bee9cfbb1a9e4d","source":"clob_market_ws"},"received_at":"2026-07-27T04:26:10.428945Z","record_id":"c59ceeae08ca8dada8c77702adb9f6df8946c4aff6e59cb6a819570048d9bbf8","schema_fingerprint":"4aa3821a28b0b7c2400bc59aba4bcc0a76e971dadd19610d3ad38c768e124dc7","schema_version":"edge-lab-recorder.raw.v1","sequence":null,"source":"clob_market_ws"}
{"event_at":"2026-07-27T04:26:10.355000Z","event_fingerprint":"265f437b4d4b1a7e886e927898cdc940ca89d9aa9defc53714ca47538844beb7","payload":{"connection_id":"0f4979d6978d463e9660b042fdcf555f","event_at":"2026-07-27T04:26:10.355000Z","event_type":"price_change","frame_hash":"ece9806635e18deae0c78dca4818551bbc0b3ad553548383c6e0f2ea41db4c1f","frame_index":0,"kind":"data","monotonic_ns":228353707705708,"payload":{"event_type":"price_change","market":"0xeb66215f2e9faa6449e30a02bab5b8ed7b79a38bf961f6b24d0073c9c2419250","price_changes":[{"asset_id":"60386828328910021732068595344565885737045900010034836345809386672230885527307","best_ask":"0.55","best_bid":"0.54","hash":"ffa0e3a4ee90b79a3656c98a079af2f11db903e4","price":"0.51","side":"BUY","size":"55"},{"asset_id":"69697746896130839564035629862476347944307040470122503199396727085502753297492","best_ask":"0.46","best_bid":"0.45","hash":"a855665899f57cf0c2f1e3e01a161f3b73f03e49","price":"0.49","side":"SELL","size":"55"}],"timestamp":"1785126370355"},"payload_hash":"8e855e280dc113abaa51d583c9e6905a375d8c665fca03222ac6e14771a0d022","raw_frame":"{\"market\":\"0xeb66215f2e9faa6449e30a02bab5b8ed7b79a38bf961f6b24d0073c9c2419250\", \"price_changes\":[{\"asset_id\":\"60386828328910021732068595344565885737045900010034836345809386672230885527307\", \"price\":\"0.51\", \"size\":\"55\", \"side\":\"BUY\", \"hash\":\"ffa0e3a4ee90b79a3656c98a079af2f11db903e4\", \"best_bid\":\"0.54\", \"best_ask\":\"0.55\"}, {\"asset_id\":\"69697746896130839564035629862476347944307040470122503199396727085502753297492\", \"price\":\"0.49\", \"size\":\"55\", \"side\":\"SELL\", \"hash\":\"a855665899f57cf0c2f1e3e01a161f3b73f03e49\", \"best_bid\":\"0.45\", \"best_ask\":\"0.46\"}], \"timestamp\":\"1785126370355\", \"event_type\":\"price_change\"}","received_at":"2026-07-27T04:26:10.435870Z","schema_version":"clob-market-ws.price_change.v1","sequence":null,"server_hash":null,"server_timestamp":"1785126370355","session_id":"e9443c7415a0419799bee9cfbb1a9e4d","source":"clob_market_ws"},"received_at":"2026-07-27T04:26:10.435870Z","record_id":"8a73fb2d9df659420ff8e89248580e8d1add2f997331eb7b3c058504e9f59378","schema_fingerprint":"4aa3821a28b0b7c2400bc59aba4bcc0a76e971dadd19610d3ad38c768e124dc7","schema_version":"edge-lab-recorder.raw.v1","sequence":null,"source":"clob_market_ws"}
{"event_at":"2026-07-27T04:26:10.356000Z","event_fingerprint":"b00c6cf206ca8261c37c1934520c466cd39b80818903a99a258f23b57c94d7d3","payload":{"connection_id":"0f4979d6978d463e9660b042fdcf555f","event_at":"2026-07-27T04:26:10.356000Z","event_type":"price_change","frame_hash":"44999e2c6ee73cd6b0ca9dd1b0f242bb022721b8a5c88b7a5fab969cd921a4cd","frame_index":0,"kind":"data","monotonic_ns":228353715259208,"payload":{"event_type":"price_change","market":"0xeb66215f2e9faa6449e30a02bab5b8ed7b79a38bf961f6b24d0073c9c2419250","price_changes":[{"asset_id":"60386828328910021732068595344565885737045900010034836345809386672230885527307","best_ask":"0.55","best_bid":"0.54","hash":"f4ebf605d2e351cf7504c387ad9968391aaeb7a3","price":"0.51","side":"BUY","size":"60"},{"asset_id":"69697746896130839564035629862476347944307040470122503199396727085502753297492","best_ask":"0.46","best_bid":"0.45","hash":"62f364e2d4a29ba07eb3160fc7a753b42455123e","price":"0.49","side":"SELL","size":"60"}],"timestamp":"1785126370356"},"payload_hash":"24f794ee93dc0afdbcaecf7d79bae867340ebe8ec780dd746238a45c1b89f397","raw_frame":"{\"market\":\"0xeb66215f2e9faa6449e30a02bab5b8ed7b79a38bf961f6b24d0073c9c2419250\", \"price_changes\":[{\"asset_id\":\"60386828328910021732068595344565885737045900010034836345809386672230885527307\", \"price\":\"0.51\", \"size\":\"60\", \"side\":\"BUY\", \"hash\":\"f4ebf605d2e351cf7504c387ad9968391aaeb7a3\", \"best_bid\":\"0.54\", \"best_ask\":\"0.55\"}, {\"asset_id\":\"69697746896130839564035629862476347944307040470122503199396727085502753297492\", \"price\":\"0.49\", \"size\":\"60\", \"side\":\"SELL\", \"hash\":\"62f364e2d4a29ba07eb3160fc7a753b42455123e\", \"best_bid\":\"0.45\", \"best_ask\":\"0.46\"}], \"timestamp\":\"1785126370356\", \"event_type\":\"price_change\"}","received_at":"2026-07-27T04:26:10.443431Z","schema_version":"clob-market-ws.price_change.v1","sequence":null,"server_hash":null,"server_timestamp":"1785126370356","session_id":"e9443c7415a0419799bee9cfbb1a9e4d","source":"clob_market_ws"},"received_at":"2026-07-27T04:26:10.443431Z","record_id":"593649486af9756e4182e06319b6aa2dec69b3d2d374033da7b43cf78d20a206","schema_fingerprint":"4aa3821a28b0b7c2400bc59aba4bcc0a76e971dadd19610d3ad38c768e124dc7","schema_version":"edge-lab-recorder.raw.v1","sequence":null,"source":"clob_market_ws"}
{"event_at":"2026-07-27T04:26:10.357000Z","event_fingerprint":"c0824b08b795d7da48b84e5d36ad1534e73300f09594970fd3972673ef9eae06","payload":{"connection_id":"0f4979d6978d463e9660b042fdcf555f","event_at":"2026-07-27T04:26:10.357000Z","event_type":"price_change","frame_hash":"1f4759a5dafef4ab184141cf809f16a7fe22199d76d9736f0f30bd3c3470aade","frame_index":0,"kind":"data","monotonic_ns":228353720363958,"payload":{"event_type":"price_change","market":"0xeb66215f2e9faa6449e30a02bab5b8ed7b79a38bf961f6b24d0073c9c2419250","price_changes":[{"asset_id":"60386828328910021732068595344565885737045900010034836345809386672230885527307","best_ask":"0.55","best_bid":"0.54","hash":"56f48f3b17b6d9c9c436eacfbab014383417171e","price":"0.51","side":"BUY","size":"65"},{"asset_id":"69697746896130839564035629862476347944307040470122503199396727085502753297492","best_ask":"0.46","best_bid":"0.45","hash":"846a41ffcda85587c33853b76c915ca9207472c5","price":"0.49","side":"SELL","size":"65"}],"timestamp":"1785126370357"},"payload_hash":"799787ff26255502f8f14dfbdb42cb68ff486677b8e3d1484499293ead63bfbe","raw_frame":"{\"market\":\"0xeb66215f2e9faa6449e30a02bab5b8ed7b79a38bf961f6b24d0073c9c2419250\", \"price_changes\":[{\"asset_id\":\"60386828328910021732068595344565885737045900010034836345809386672230885527307\", \"price\":\"0.51\", \"size\":\"65\", \"side\":\"BUY\", \"hash\":\"56f48f3b17b6d9c9c436eacfbab014383417171e\", \"best_bid\":\"0.54\", \"best_ask\":\"0.55\"}, {\"asset_id\":\"69697746896130839564035629862476347944307040470122503199396727085502753297492\", \"price\":\"0.49\", \"size\":\"65\", \"side\":\"SELL\", \"hash\":\"846a41ffcda85587c33853b76c915ca9207472c5\", \"best_bid\":\"0.45\", \"best_ask\":\"0.46\"}], \"timestamp\":\"1785126370357\", \"event_type\":\"price_change\"}","received_at":"2026-07-27T04:26:10.448535Z","schema_version":"clob-market-ws.price_change.v1","sequence":null,"server_hash":null,"server_timestamp":"1785126370357","session_id":"e9443c7415a0419799bee9cfbb1a9e4d","source":"clob_market_ws"},"received_at":"2026-07-27T04:26:10.448535Z","record_id":"8f3937accc5ee345f5e6a860c82d92a0c54e24eecb1fe797a79fceac5f026ee8","schema_fingerprint":"4aa3821a28b0b7c2400bc59aba4bcc0a76e971dadd19610d3ad38c768e124dc7","schema_version":"edge-lab-recorder.raw.v1","sequence":null,"source":"clob_market_ws"}
{"event_at":"2026-07-27T04:26:10.358000Z","event_fingerprint":"fb3b363b1f35c868e320e5bea1b919b30a4f6d98e69b802b3f60a78102726fcd","payload":{"connection_id":"0f4979d6978d463e9660b042fdcf555f","event_at":"2026-07-27T04:26:10.358000Z","event_type":"price_change","frame_hash":"ae63610612b185c4affa079fca14c0eb80707aeb8c9344c51d9aba6e51b97444","frame_index":0,"kind":"data","monotonic_ns":228353727322833,"payload":{"event_type":"price_change","market":"0xeb66215f2e9faa6449e30a02bab5b8ed7b79a38bf961f6b24d0073c9c2419250","price_changes":[{"asset_id":"60386828328910021732068595344565885737045900010034836345809386672230885527307","best_ask":"0.55","best_bid":"0.54","hash":"b50f2da4f8c4b7018ca102a3b04a728596931bab","price":"0.51","side":"BUY","size":"70"},{"asset_id":"69697746896130839564035629862476347944307040470122503199396727085502753297492","best_ask":"0.46","best_bid":"0.45","hash":"a3edd2b50ea2513e105475501d5fa09c9da06f2c","price":"0.49","side":"SELL","size":"70"}],"timestamp":"1785126370358"},"payload_hash":"a072a40d8c1facc7f8767ae5357065419a1b254018143d900524ad90a9f119ca","raw_frame":"{\"market\":\"0xeb66215f2e9faa6449e30a02bab5b8ed7b79a38bf961f6b24d0073c9c2419250\", \"price_changes\":[{\"asset_id\":\"60386828328910021732068595344565885737045900010034836345809386672230885527307\", \"price\":\"0.51\", \"size\":\"70\", \"side\":\"BUY\", \"hash\":\"b50f2da4f8c4b7018ca102a3b04a728596931bab\", \"best_bid\":\"0.54\", \"best_ask\":\"0.55\"}, {\"asset_id\":\"69697746896130839564035629862476347944307040470122503199396727085502753297492\", \"price\":\"0.49\", \"size\":\"70\", \"side\":\"SELL\", \"hash\":\"a3edd2b50ea2513e105475501d5fa09c9da06f2c\", \"best_bid\":\"0.45\", \"best_ask\":\"0.46\"}], \"timestamp\":\"1785126370358\", \"event_type\":\"price_change\"}","received_at":"2026-07-27T04:26:10.455495Z","schema_version":"clob-market-ws.price_change.v1","sequence":null,"server_hash":null,"server_timestamp":"1785126370358","session_id":"e9443c7415a0419799bee9cfbb1a9e4d","source":"clob_market_ws"},"received_at":"2026-07-27T04:26:10.455495Z","record_id":"86a7a739677403548f5e604de475150559f4b93412c083489bbc34669e09a871","schema_fingerprint":"4aa3821a28b0b7c2400bc59aba4bcc0a76e971dadd19610d3ad38c768e124dc7","schema_version":"edge-lab-recorder.raw.v1","sequence":null,"source":"clob_market_ws"}
{"event_at":"2026-07-27T04:26:10.359000Z","event_fingerprint":"97b68462d532d885910c4aba9fc4e6fd9bf82b0531f18d67894ca76fe5630e6c","payload":{"connection_id":"0f4979d6978d463e9660b042fdcf555f","event_at":"2026-07-27T04:26:10.359000Z","event_type":"price_change","frame_hash":"dc4e9be61c49b0a9cc69c9b12bb7f0a1787e668845a415f085b0fbb316ce623f","frame_index":0,"kind":"data","monotonic_ns":228353734555000,"payload":{"event_type":"price_change","market":"0xeb66215f2e9faa6449e30a02bab5b8ed7b79a38bf961f6b24d0073c9c2419250","price_changes":[{"asset_id":"60386828328910021732068595344565885737045900010034836345809386672230885527307","best_ask":"0.55","best_bid":"0.54","hash":"67ca1625cea2d1ca46a60c5caedf09cdfa60b97d","price":"0.51","side":"BUY","size":"75"},{"asset_id":"69697746896130839564035629862476347944307040470122503199396727085502753297492","best_ask":"0.46","best_bid":"0.45","hash":"02437b2e58bc256e26dc6d71b9946d6be477bd2d","price":"0.49","side":"SELL","size":"75"}],"timestamp":"1785126370359"},"payload_hash":"af6d9e9ea63e4ebd8463549e3898f46328044e43bb5046e215699ffc1606bc27","raw_frame":"{\"market\":\"0xeb66215f2e9faa6449e30a02bab5b8ed7b79a38bf961f6b24d0073c9c2419250\", \"price_changes\":[{\"asset_id\":\"60386828328910021732068595344565885737045900010034836345809386672230885527307\", \"price\":\"0.51\", \"size\":\"75\", \"side\":\"BUY\", \"hash\":\"67ca1625cea2d1ca46a60c5caedf09cdfa60b97d\", \"best_bid\":\"0.54\", \"best_ask\":\"0.55\"}, {\"asset_id\":\"69697746896130839564035629862476347944307040470122503199396727085502753297492\", \"price\":\"0.49\", \"size\":\"75\", \"side\":\"SELL\", \"hash\":\"02437b2e58bc256e26dc6d71b9946d6be477bd2d\", \"best_bid\":\"0.45\", \"best_ask\":\"0.46\"}], \"timestamp\":\"1785126370359\", \"event_type\":\"price_change\"}","received_at":"2026-07-27T04:26:10.462725Z","schema_version":"clob-market-ws.price_change.v1","sequence":null,"server_hash":null,"server_timestamp":"1785126370359","session_id":"e9443c7415a0419799bee9cfbb1a9e4d","source":"clob_market_ws"},"received_at":"2026-07-27T04:26:10.462725Z","record_id":"72e6168e5b62019f970c8da2b7838abb0159f4554e92a97c2b1941ca40321b90","schema_fingerprint":"4aa3821a28b0b7c2400bc59aba4bcc0a76e971dadd19610d3ad38c768e124dc7","schema_version":"edge-lab-recorder.raw.v1","sequence":null,"source":"clob_market_ws"}
{"event_at":"2026-07-27T04:26:10.361000Z","event_fingerprint":"f3d413075ec90942c42e8109408424e1bf43d7b399a40d966089c395d9b378e4","payload":{"connection_id":"0f4979d6978d463e9660b042fdcf555f","event_at":"2026-07-27T04:26:10.361000Z","event_type":"price_change","frame_hash":"e657beead6a3999b206ce7baf2bfda63218cf1c117f5f507006482e3c37b5587","frame_index":0,"kind":"data","monotonic_ns":228353741351916,"payload":{"event_type":"price_change","market":"0xeb66215f2e9faa6449e30a02bab5b8ed7b79a38bf961f6b24d0073c9c2419250","price_changes":[{"asset_id":"69697746896130839564035629862476347944307040470122503199396727085502753297492","best_ask":"0.46","best_bid":"0.45","hash":"f4b95ecbe3b055714bd29dbf4fe82d8b6f0a7562","price":"0.45","side":"BUY","size":"202.95"},{"asset_id":"60386828328910021732068595344565885737045900010034836345809386672230885527307","best_ask":"0.55","best_bid":"0.54","hash":"2eed8dab03f1602113996a220437638a237bcdb1","price":"0.55","side":"SELL","size":"202.95"}],"timestamp":"1785126370361"},"payload_hash":"a72f714ddffc2de6be4ca8baae19cd8668e12961749564625d471e73fdcf6d3c","raw_frame":"{\"market\":\"0xeb66215f2e9faa6449e30a02bab5b8ed7b79a38bf961f6b24d0073c9c2419250\", \"price_changes\":[{\"asset_id\":\"69697746896130839564035629862476347944307040470122503199396727085502753297492\", \"price\":\"0.45\", \"size\":\"202.95\", \"side\":\"BUY\", \"hash\":\"f4b95ecbe3b055714bd29dbf4fe82d8b6f0a7562\", \"best_bid\":\"0.45\", \"best_ask\":\"0.46\"}, {\"asset_id\":\"60386828328910021732068595344565885737045900010034836345809386672230885527307\", \"price\":\"0.55\", \"size\":\"202.95\", \"side\":\"SELL\", \"hash\":\"2eed8dab03f1602113996a220437638a237bcdb1\", \"best_bid\":\"0.54\", \"best_ask\":\"0.55\"}], \"timestamp\":\"1785126370361\", \"event_type\":\"price_change\"}","received_at":"2026-07-27T04:26:10.469524Z","schema_version":"clob-market-ws.price_change.v1","sequence":null,"server_hash":null,"server_timestamp":"1785126370361","session_id":"e9443c7415a0419799bee9cfbb1a9e4d","source":"clob_market_ws"},"received_at":"2026-07-27T04:26:10.469524Z","record_id":"b46ff87de746f694d7b79031cfee609c67c73330dbc184ef4535f29a844d0067","schema_fingerprint":"4aa3821a28b0b7c2400bc59aba4bcc0a76e971dadd19610d3ad38c768e124dc7","schema_version":"edge-lab-recorder.raw.v1","sequence":null,"source":"clob_market_ws"}
{"event_at":"2026-07-27T04:26:10.362000Z","event_fingerprint":"474576d6fe05c4a516af48b64683748b01188924d1fb33f94d458c9b1a42ec31","payload":{"connection_id":"0f4979d6978d463e9660b042fdcf555f","event_at":"2026-07-27T04:26:10.362000Z","event_type":"price_change","frame_hash":"46c4eede3adf08f8ea65aeb7b0e0fc45a639629f8ee52011c88ca5632c54e22c","frame_index":0,"kind":"data","monotonic_ns":228353748287875,"payload":{"event_type":"price_change","market":"0xeb66215f2e9faa6449e30a02bab5b8ed7b79a38bf961f6b24d0073c9c2419250","price_changes":[{"asset_id":"69697746896130839564035629862476347944307040470122503199396727085502753297492","best_ask":"0.46","best_bid":"0.45","hash":"c95c9a225b07e626860657b52a664c477e2eb63b","price":"0.45","side":"BUY","size":"207.95"},{"asset_id":"60386828328910021732068595344565885737045900010034836345809386672230885527307","best_ask":"0.55","best_bid":"0.54","hash":"c660ae7eac30e715e4949f6e92d1077159b454b3","price":"0.55","side":"SELL","size":"207.95"}],"timestamp":"1785126370362"},"payload_hash":"7b52f2847e611bc29c145b7715ec4a4d9d9dc4490f7aa12ac213d29d1e9df57c","raw_frame":"{\"market\":\"0xeb66215f2e9faa6449e30a02bab5b8ed7b79a38bf961f6b24d0073c9c2419250\", \"price_changes\":[{\"asset_id\":\"69697746896130839564035629862476347944307040470122503199396727085502753297492\", \"price\":\"0.45\", \"size\":\"207.95\", \"side\":\"BUY\", \"hash\":\"c95c9a225b07e626860657b52a664c477e2eb63b\", \"best_bid\":\"0.45\", \"best_ask\":\"0.46\"}, {\"asset_id\":\"60386828328910021732068595344565885737045900010034836345809386672230885527307\", \"price\":\"0.55\", \"size\":\"207.95\", \"side\":\"SELL\", \"hash\":\"c660ae7eac30e715e4949f6e92d1077159b454b3\", \"best_bid\":\"0.54\", \"best_ask\":\"0.55\"}], \"timestamp\":\"1785126370362\", \"event_type\":\"price_change\"}","received_at":"2026-07-27T04:26:10.476458Z","schema_version":"clob-market-ws.price_change.v1","sequence":null,"server_hash":null,"server_timestamp":"1785126370362","session_id":"e9443c7415a0419799bee9cfbb1a9e4d","source":"clob_market_ws"},"received_at":"2026-07-27T04:26:10.476458Z","record_id":"3f624647e0c785bb9125720926a4cb9e8b8d45b480be0e8c32721a7abfac1f28","schema_fingerprint":"4aa3821a28b0b7c2400bc59aba4bcc0a76e971dadd19610d3ad38c768e124dc7","schema_version":"edge-lab-recorder.raw.v1","sequence":null,"source":"clob_market_ws"}
{"event_at":"2026-07-27T04:26:10.363000Z","event_fingerprint":"861d1ce07db71f6bfed265fb79071ef5744953594cac05cdc1947e37a714444d","payload":{"connection_id":"0f4979d6978d463e9660b042fdcf555f","event_at":"2026-07-27T04:26:10.363000Z","event_type":"price_change","frame_hash":"b274e28cbeea0bab4f114b0868f3bbba0ecd98072a7762120440b3fac525a155","frame_index":0,"kind":"data","monotonic_ns":228353755334166,"payload":{"event_type":"price_change","market":"0xeb66215f2e9faa6449e30a02bab5b8ed7b79a38bf961f6b24d0073c9c2419250","price_changes":[{"asset_id":"69697746896130839564035629862476347944307040470122503199396727085502753297492","best_ask":"0.46","best_bid":"0.45","hash":"f9da65f716b1a1d153b2e9249cccd39924fb1ef6","price":"0.45","side":"BUY","size":"212.95"},{"asset_id":"60386828328910021732068595344565885737045900010034836345809386672230885527307","best_ask":"0.55","best_bid":"0.54","hash":"387c3dcd2238e1030f955eeedd8ec84d85c6c389","price":"0.55","side":"SELL","size":"212.95"}],"timestamp":"1785126370363"},"payload_hash":"ccfbccec9342abc252d01b559e912eed0600f91c309741012a66cc8f8ae7cb6d","raw_frame":"{\"market\":\"0xeb66215f2e9faa6449e30a02bab5b8ed7b79a38bf961f6b24d0073c9c2419250\", \"price_changes\":[{\"asset_id\":\"69697746896130839564035629862476347944307040470122503199396727085502753297492\", \"price\":\"0.45\", \"size\":\"212.95\", \"side\":\"BUY\", \"hash\":\"f9da65f716b1a1d153b2e9249cccd39924fb1ef6\", \"best_bid\":\"0.45\", \"best_ask\":\"0.46\"}, {\"asset_id\":\"60386828328910021732068595344565885737045900010034836345809386672230885527307\", \"price\":\"0.55\", \"size\":\"212.95\", \"side\":\"SELL\", \"hash\":\"387c3dcd2238e1030f955eeedd8ec84d85c6c389\", \"best_bid\":\"0.54\", \"best_ask\":\"0.55\"}], \"timestamp\":\"1785126370363\", \"event_type\":\"price_change\"}","received_at":"2026-07-27T04:26:10.483502Z","schema_version":"clob-market-ws.price_change.v1","sequence":null,"server_hash":null,"server_timestamp":"1785126370363","session_id":"e9443c7415a0419799bee9cfbb1a9e4d","source":"clob_market_ws"},"received_at":"2026-07-27T04:26:10.483502Z","record_id":"33673b725da832a497f27e6f877eda7e60f5a0cb0ddc3d437691f5feb1a85758","schema_fingerprint":"4aa3821a28b0b7c2400bc59aba4bcc0a76e971dadd19610d3ad38c768e124dc7","schema_version":"edge-lab-recorder.raw.v1","sequence":null,"source":"clob_market_ws"}
{"event_at":"2026-07-27T04:26:10.364000Z","event_fingerprint":"52e6f5a64d6f5d03b11fcaa896082fb54c057f01f02c85eff56081f2a8c0128c","payload":{"connection_id":"0f4979d6978d463e9660b042fdcf555f","event_at":"2026-07-27T04:26:10.364000Z","event_type":"price_change","frame_hash":"4abdb0025cc984c4820ca11e2ee506e986714107b13b28a60a5d1b0bcfc6c841","frame_index":0,"kind":"data","monotonic_ns":228353763271000,"payload":{"event_type":"price_change","market":"0xeb66215f2e9faa6449e30a02bab5b8ed7b79a38bf961f6b24d0073c9c2419250","price_changes":[{"asset_id":"69697746896130839564035629862476347944307040470122503199396727085502753297492","best_ask":"0.46","best_bid":"0.45","hash":"11f9e0252124d90c80db3801476d5f6d217d8595","price":"0.45","side":"BUY","size":"217.95"},{"asset_id":"60386828328910021732068595344565885737045900010034836345809386672230885527307","best_ask":"0.55","best_bid":"0.54","hash":"4d4469a66a7d9d1d17581e2722c47260857ff231","price":"0.55","side":"SELL","size":"217.95"}],"timestamp":"1785126370364"},"payload_hash":"c9927408bb436b365e4f9f54f02cebba66d30cd0876174a89777c77b51516f00","raw_frame":"{\"market\":\"0xeb66215f2e9faa6449e30a02bab5b8ed7b79a38bf961f6b24d0073c9c2419250\", \"price_changes\":[{\"asset_id\":\"69697746896130839564035629862476347944307040470122503199396727085502753297492\", \"price\":\"0.45\", \"size\":\"217.95\", \"side\":\"BUY\", \"hash\":\"11f9e0252124d90c80db3801476d5f6d217d8595\", \"best_bid\":\"0.45\", \"best_ask\":\"0.46\"}, {\"asset_id\":\"60386828328910021732068595344565885737045900010034836345809386672230885527307\", \"price\":\"0.55\", \"size\":\"217.95\", \"side\":\"SELL\", \"hash\":\"4d4469a66a7d9d1d17581e2722c47260857ff231\", \"best_bid\":\"0.54\", \"best_ask\":\"0.55\"}], \"timestamp\":\"1785126370364\", \"event_type\":\"price_change\"}","received_at":"2026-07-27T04:26:10.491442Z","schema_version":"clob-market-ws.price_change.v1","sequence":null,"server_hash":null,"server_timestamp":"1785126370364","session_id":"e9443c7415a0419799bee9cfbb1a9e4d","source":"clob_market_ws"},"received_at":"2026-07-27T04:26:10.491442Z","record_id":"a3873a766c0c70a3b3d9b6b3c90db037a4214806875a0f73de53d3c13a9662bf","schema_fingerprint":"4aa3821a28b0b7c2400bc59aba4bcc0a76e971dadd19610d3ad38c768e124dc7","schema_version":"edge-lab-recorder.raw.v1","sequence":null,"source":"clob_market_ws"}
{"event_at":"2026-07-27T04:26:10.364000Z","event_fingerprint":"aa7c1d721f4f60788622b9160cdae736742277dbf944d0f4b4c82f51d4f39edb","payload":{"connection_id":"0f4979d6978d463e9660b042fdcf555f","event_at":"2026-07-27T04:26:10.364000Z","event_type":"price_change","frame_hash":"9b8a32c6136526310f98f6d690324519f569f34243608ad39e0d0227483f3c40","frame_index":0,"kind":"data","monotonic_ns":228353771522958,"payload":{"event_type":"price_change","market":"0xeb66215f2e9faa6449e30a02bab5b8ed7b79a38bf961f6b24d0073c9c2419250","price_changes":[{"asset_id":"69697746896130839564035629862476347944307040470122503199396727085502753297492","best_ask":"0.46","best_bid":"0.45","hash":"1d876e0012f5d237fce9ddba2c63d7ddf22dfe0f","price":"0.45","side":"BUY","size":"222.95"},{"asset_id":"60386828328910021732068595344565885737045900010034836345809386672230885527307","best_ask":"0.55","best_bid":"0.54","hash":"bb9aeff24ec2b2545851d3baa45e5ed3459261bd","price":"0.55","side":"SELL","size":"222.95"}],"timestamp":"1785126370364"},"payload_hash":"8f5eda124f9317486cf41faf70db3fc902ecc5509b5acb7919e538bcc8d4cd14","raw_frame":"{\"market\":\"0xeb66215f2e9faa6449e30a02bab5b8ed7b79a38bf961f6b24d0073c9c2419250\", \"price_changes\":[{\"asset_id\":\"69697746896130839564035629862476347944307040470122503199396727085502753297492\", \"price\":\"0.45\", \"size\":\"222.95\", \"side\":\"BUY\", \"hash\":\"1d876e0012f5d237fce9ddba2c63d7ddf22dfe0f\", \"best_bid\":\"0.45\", \"best_ask\":\"0.46\"}, {\"asset_id\":\"60386828328910021732068595344565885737045900010034836345809386672230885527307\", \"price\":\"0.55\", \"size\":\"222.95\", \"side\":\"SELL\", \"hash\":\"bb9aeff24ec2b2545851d3baa45e5ed3459261bd\", \"best_bid\":\"0.54\", \"best_ask\":\"0.55\"}], \"timestamp\":\"1785126370364\", \"event_type\":\"price_change\"}","received_at":"2026-07-27T04:26:10.499695Z","schema_version":"clob-market-ws.price_change.v1","sequence":null,"server_hash":null,"server_timestamp":"1785126370364","session_id":"e9443c7415a0419799bee9cfbb1a9e4d","source":"clob_market_ws"},"received_at":"2026-07-27T04:26:10.499695Z","record_id":"1e594e77c0726b82072b6665f4665f26915a7ef98d6f32f37886b3cb67aa7f45","schema_fingerprint":"4aa3821a28b0b7c2400bc59aba4bcc0a76e971dadd19610d3ad38c768e124dc7","schema_version":"edge-lab-recorder.raw.v1","sequence":null,"source":"clob_market_ws"}
{"event_at":"2026-07-27T04:26:10.373000Z","event_fingerprint":"9ab88c833db1d3771daa8769e68e36efdee95295c1f9cabc94465f5750bdf4f7","payload":{"connection_id":"0f4979d6978d463e9660b042fdcf555f","event_at":"2026-07-27T04:26:10.373000Z","event_type":"price_change","frame_hash":"13917ee387f7dc086f557e7b160596512fc1a71bffcb1ba4603f23697c7d072b","frame_index":0,"kind":"data","monotonic_ns":228353777510916,"payload":{"event_type":"price_change","market":"0xeb66215f2e9faa6449e30a02bab5b8ed7b79a38bf961f6b24d0073c9c2419250","price_changes":[{"asset_id":"60386828328910021732068595344565885737045900010034836345809386672230885527307","best_ask":"0.55","best_bid":"0.54","hash":"257101dbd3c4ede4caaad712e27c1e1edc42a95d","price":"0.51","side":"BUY","size":"80"},{"asset_id":"69697746896130839564035629862476347944307040470122503199396727085502753297492","best_ask":"0.46","best_bid":"0.45","hash":"096fe6439cf377a9073ecfe133978ca567a8e257","price":"0.49","side":"SELL","size":"80"}],"timestamp":"1785126370373"},"payload_hash":"f6420e6a9f9f723ea57e9a55dd4949d080230a7bfae8232e3294e73c066fbab6","raw_frame":"{\"market\":\"0xeb66215f2e9faa6449e30a02bab5b8ed7b79a38bf961f6b24d0073c9c2419250\", \"price_changes\":[{\"asset_id\":\"60386828328910021732068595344565885737045900010034836345809386672230885527307\", \"price\":\"0.51\", \"size\":\"80\", \"side\":\"BUY\", \"hash\":\"257101dbd3c4ede4caaad712e27c1e1edc42a95d\", \"best_bid\":\"0.54\", \"best_ask\":\"0.55\"}, {\"asset_id\":\"69697746896130839564035629862476347944307040470122503199396727085502753297492\", \"price\":\"0.49\", \"size\":\"80\", \"side\":\"SELL\", \"hash\":\"096fe6439cf377a9073ecfe133978ca567a8e257\", \"best_bid\":\"0.45\", \"best_ask\":\"0.46\"}], \"timestamp\":\"1785126370373\", \"event_type\":\"price_change\"}","received_at":"2026-07-27T04:26:10.505686Z","schema_version":"clob-market-ws.price_change.v1","sequence":null,"server_hash":null,"server_timestamp":"1785126370373","session_id":"e9443c7415a0419799bee9cfbb1a9e4d","source":"clob_market_ws"},"received_at":"2026-07-27T04:26:10.505686Z","record_id":"bb3be990afc109c67383fc1ea19d407f6ed923dea008be0ea83576283aed3317","schema_fingerprint":"4aa3821a28b0b7c2400bc59aba4bcc0a76e971dadd19610d3ad38c768e124dc7","schema_version":"edge-lab-recorder.raw.v1","sequence":null,"source":"clob_market_ws"}
{"event_at":"2026-07-27T04:26:10.374000Z","event_fingerprint":"e135610ca58384693dbb2343286c518cba28f539cedbfb1f133e31dd0419dc9a","payload":{"connection_id":"0f4979d6978d463e9660b042fdcf555f","event_at":"2026-07-27T04:26:10.374000Z","event_type":"price_change","frame_hash":"b27aeddbd3e34f30c3fed931693a38c65e9fa9dc233e6ebe0c65b6bb03283feb","frame_index":0,"kind":"data","monotonic_ns":228353781900208,"payload":{"event_type":"price_change","market":"0xeb66215f2e9faa6449e30a02bab5b8ed7b79a38bf961f6b24d0073c9c2419250","price_changes":[{"asset_id":"60386828328910021732068595344565885737045900010034836345809386672230885527307","best_ask":"0.55","best_bid":"0.54","hash":"3a0aca7d64d14dc949b9dd1550835ed0251715b7","price":"0.51","side":"BUY","size":"85"},{"asset_id":"69697746896130839564035629862476347944307040470122503199396727085502753297492","best_ask":"0.46","best_bid":"0.45","hash":"8250dd4e5db209c27ac0ce8229546a1dafb688fb","price":"0.49","side":"SELL","size":"85"}],"timestamp":"1785126370374"},"payload_hash":"429d565af0a313be8858c82ffa7fcde3b0536d1f2a82d95d7ad0841faf0853c9","raw_frame":"{\"market\":\"0xeb66215f2e9faa6449e30a02bab5b8ed7b79a38bf961f6b24d0073c9c2419250\", \"price_changes\":[{\"asset_id\":\"60386828328910021732068595344565885737045900010034836345809386672230885527307\", \"price\":\"0.51\", \"size\":\"85\", \"side\":\"BUY\", \"hash\":\"3a0aca7d64d14dc949b9dd1550835ed0251715b7\", \"best_bid\":\"0.54\", \"best_ask\":\"0.55\"}, {\"asset_id\":\"69697746896130839564035629862476347944307040470122503199396727085502753297492\", \"price\":\"0.49\", \"size\":\"85\", \"side\":\"SELL\", \"hash\":\"8250dd4e5db209c27ac0ce8229546a1dafb688fb\", \"best_bid\":\"0.45\", \"best_ask\":\"0.46\"}], \"timestamp\":\"1785126370374\", \"event_type\":\"price_change\"}","received_at":"2026-07-27T04:26:10.510078Z","schema_version":"clob-market-ws.price_change.v1","sequence":null,"server_hash":null,"server_timestamp":"1785126370374","session_id":"e9443c7415a0419799bee9cfbb1a9e4d","source":"clob_market_ws"},"received_at":"2026-07-27T04:26:10.510078Z","record_id":"8c3329fe2842f4d393a5faa957fafcfc03b16d309609c3cc58f6ed9755981dae","schema_fingerprint":"4aa3821a28b0b7c2400bc59aba4bcc0a76e971dadd19610d3ad38c768e124dc7","schema_version":"edge-lab-recorder.raw.v1","sequence":null,"source":"clob_market_ws"}
{"event_at":"2026-07-27T04:26:10.375000Z","event_fingerprint":"23cc88c5b3cf67fdd21e8eaa5a310e10a966f5d838f72777253cd03126182073","payload":{"connection_id":"0f4979d6978d463e9660b042fdcf555f","event_at":"2026-07-27T04:26:10.375000Z","event_type":"price_change","frame_hash":"84cf289527c21a5ad9648b3e3df7a3de3db0481be10cd15c08bde046729c9e92","frame_index":0,"kind":"data","monotonic_ns":228353783906833,"payload":{"event_type":"price_change","market":"0xeb66215f2e9faa6449e30a02bab5b8ed7b79a38bf961f6b24d0073c9c2419250","price_changes":[{"asset_id":"60386828328910021732068595344565885737045900010034836345809386672230885527307","best_ask":"0.55","best_bid":"0.54","hash":"e6e8e4db3104fdef1f78e14603287f70474ff695","price":"0.51","side":"BUY","size":"90"},{"asset_id":"69697746896130839564035629862476347944307040470122503199396727085502753297492","best_ask":"0.46","best_bid":"0.45","hash":"2320b8194e7f943011aefcb0e4bb0d1543ffdf77","price":"0.49","side":"SELL","size":"90"}],"timestamp":"1785126370375"},"payload_hash":"444dc0ba29423878e3baa3d8578888843338cb90a3ae02761ae9d1e628105111","raw_frame":"{\"market\":\"0xeb66215f2e9faa6449e30a02bab5b8ed7b79a38bf961f6b24d0073c9c2419250\", \"price_changes\":[{\"asset_id\":\"60386828328910021732068595344565885737045900010034836345809386672230885527307\", \"price\":\"0.51\", \"size\":\"90\", \"side\":\"BUY\", \"hash\":\"e6e8e4db3104fdef1f78e14603287f70474ff695\", \"best_bid\":\"0.54\", \"best_ask\":\"0.55\"}, {\"asset_id\":\"69697746896130839564035629862476347944307040470122503199396727085502753297492\", \"price\":\"0.49\", \"size\":\"90\", \"side\":\"SELL\", \"hash\":\"2320b8194e7f943011aefcb0e4bb0d1543ffdf77\", \"best_bid\":\"0.45\", \"best_ask\":\"0.46\"}], \"timestamp\":\"1785126370375\", \"event_type\":\"price_change\"}","received_at":"2026-07-27T04:26:10.512084Z","schema_version":"clob-market-ws.price_change.v1","sequence":null,"server_hash":null,"server_timestamp":"1785126370375","session_id":"e9443c7415a0419799bee9cfbb1a9e4d","source":"clob_market_ws"},"received_at":"2026-07-27T04:26:10.512084Z","record_id":"85171f9cc75e43ab721e4ebc91c82d2a1f4a3b3fb4de90d400898dd6dbb3bd98","schema_fingerprint":"4aa3821a28b0b7c2400bc59aba4bcc0a76e971dadd19610d3ad38c768e124dc7","schema_version":"edge-lab-recorder.raw.v1","sequence":null,"source":"clob_market_ws"}
{"event_at":"2026-07-27T04:26:10.375000Z","event_fingerprint":"8b0cc4a34de12b7eb24d8b56c976b416cff3a9ec7f1ce6f25ea66ee1139ce0df","payload":{"connection_id":"0f4979d6978d463e9660b042fdcf555f","event_at":"2026-07-27T04:26:10.375000Z","event_type":"price_change","frame_hash":"a89fad94cc9f83f7313a3fe9af2d2c9804de4d920c4933af93e09e488cfd9dc1","frame_index":0,"kind":"data","monotonic_ns":228353789374208,"payload":{"event_type":"price_change","market":"0xeb66215f2e9faa6449e30a02bab5b8ed7b79a38bf961f6b24d0073c9c2419250","price_changes":[{"asset_id":"60386828328910021732068595344565885737045900010034836345809386672230885527307","best_ask":"0.55","best_bid":"0.54","hash":"da3b745b7e32ba1d0f6088eba6d8145d9bd8aeed","price":"0.51","side":"BUY","size":"95"},{"asset_id":"69697746896130839564035629862476347944307040470122503199396727085502753297492","best_ask":"0.46","best_bid":"0.45","hash":"77fd49e333814cc98fa5fdff8af6448a097dd29e","price":"0.49","side":"SELL","size":"95"}],"timestamp":"1785126370375"},"payload_hash":"e53a36f2dc2ab2b6dc7c7a3dc6320aeb37c5b3a10b541782a779e27db72892d2","raw_frame":"{\"market\":\"0xeb66215f2e9faa6449e30a02bab5b8ed7b79a38bf961f6b24d0073c9c2419250\", \"price_changes\":[{\"asset_id\":\"60386828328910021732068595344565885737045900010034836345809386672230885527307\", \"price\":\"0.51\", \"size\":\"95\", \"side\":\"BUY\", \"hash\":\"da3b745b7e32ba1d0f6088eba6d8145d9bd8aeed\", \"best_bid\":\"0.54\", \"best_ask\":\"0.55\"}, {\"asset_id\":\"69697746896130839564035629862476347944307040470122503199396727085502753297492\", \"price\":\"0.49\", \"size\":\"95\", \"side\":\"SELL\", \"hash\":\"77fd49e333814cc98fa5fdff8af6448a097dd29e\", \"best_bid\":\"0.45\", \"best_ask\":\"0.46\"}], \"timestamp\":\"1785126370375\", \"event_type\":\"price_change\"}","received_at":"2026-07-27T04:26:10.517552Z","schema_version":"clob-market-ws.price_change.v1","sequence":null,"server_hash":null,"server_timestamp":"1785126370375","session_id":"e9443c7415a0419799bee9cfbb1a9e4d","source":"clob_market_ws"},"received_at":"2026-07-27T04:26:10.517552Z","record_id":"e6f6cde965eb49ab17c7cc352d57a3077a233fb8b699d62e74904cbb6bde9151","schema_fingerprint":"4aa3821a28b0b7c2400bc59aba4bcc0a76e971dadd19610d3ad38c768e124dc7","schema_version":"edge-lab-recorder.raw.v1","sequence":null,"source":"clob_market_ws"}
{"event_at":"2026-07-27T04:26:10.376000Z","event_fingerprint":"cac8f7817a2b67276da72929114b450788a6d03ebfd695305372c332e391250d","payload":{"connection_id":"0f4979d6978d463e9660b042fdcf555f","event_at":"2026-07-27T04:26:10.376000Z","event_type":"price_change","frame_hash":"7a1f75322b67de854e881d5d5b9a9edec3dbbf33dddc254c4dc21a963ed2b73b","frame_index":0,"kind":"data","monotonic_ns":228353795952291,"payload":{"event_type":"price_change","market":"0xeb66215f2e9faa6449e30a02bab5b8ed7b79a38bf961f6b24d0073c9c2419250","price_changes":[{"asset_id":"60386828328910021732068595344565885737045900010034836345809386672230885527307","best_ask":"0.55","best_bid":"0.54","hash":"7fee77c24a679338609f2882c24bea806879387a","price":"0.51","side":"BUY","size":"100"},{"asset_id":"69697746896130839564035629862476347944307040470122503199396727085502753297492","best_ask":"0.46","best_bid":"0.45","hash":"cd7a18a13c6dba7742c5a521ed99313992fc4140","price":"0.49","side":"SELL","size":"100"}],"timestamp":"1785126370376"},"payload_hash":"fea3976fc773794ebb11f52f4db082b56e51e8c5d1d89d8f2b18eb0cb19f1e2a","raw_frame":"{\"market\":\"0xeb66215f2e9faa6449e30a02bab5b8ed7b79a38bf961f6b24d0073c9c2419250\", \"price_changes\":[{\"asset_id\":\"60386828328910021732068595344565885737045900010034836345809386672230885527307\", \"price\":\"0.51\", \"size\":\"100\", \"side\":\"BUY\", \"hash\":\"7fee77c24a679338609f2882c24bea806879387a\", \"best_bid\":\"0.54\", \"best_ask\":\"0.55\"}, {\"asset_id\":\"69697746896130839564035629862476347944307040470122503199396727085502753297492\", \"price\":\"0.49\", \"size\":\"100\", \"side\":\"SELL\", \"hash\":\"cd7a18a13c6dba7742c5a521ed99313992fc4140\", \"best_bid\":\"0.45\", \"best_ask\":\"0.46\"}], \"timestamp\":\"1785126370376\", \"event_type\":\"price_change\"}","received_at":"2026-07-27T04:26:10.524124Z","schema_version":"clob-market-ws.price_change.v1","sequence":null,"server_hash":null,"server_timestamp":"1785126370376","session_id":"e9443c7415a0419799bee9cfbb1a9e4d","source":"clob_market_ws"},"received_at":"2026-07-27T04:26:10.524124Z","record_id":"de622eda623ec4bd650d182310c20c6e51768e62e4236d93c4fad89b333b4636","schema_fingerprint":"4aa3821a28b0b7c2400bc59aba4bcc0a76e971dadd19610d3ad38c768e124dc7","schema_version":"edge-lab-recorder.raw.v1","sequence":null,"source":"clob_market_ws"}
{"event_at":"2026-07-27T04:26:10.377000Z","event_fingerprint":"273dd0d0aafc716415254f13bebb06deddf7964e78102362db4468b897c9e2b0","payload":{"connection_id":"0f4979d6978d463e9660b042fdcf555f","event_at":"2026-07-27T04:26:10.377000Z","event_type":"price_change","frame_hash":"9606a7b0dac156631ccd79cd57e022ba47aa587367bb05148812b140dd0899ec","frame_index":0,"kind":"data","monotonic_ns":228353804725875,"payload":{"event_type":"price_change","market":"0xeb66215f2e9faa6449e30a02bab5b8ed7b79a38bf961f6b24d0073c9c2419250","price_changes":[{"asset_id":"60386828328910021732068595344565885737045900010034836345809386672230885527307","best_ask":"0.55","best_bid":"0.54","hash":"9a387fd84a4d63dcc6ba16c19fc1cb3d106c240d","price":"0.51","side":"BUY","size":"105"},{"asset_id":"69697746896130839564035629862476347944307040470122503199396727085502753297492","best_ask":"0.46","best_bid":"0.45","hash":"2d6585bb5cd1910d5e03f721f3c839bc1355c6c2","price":"0.49","side":"SELL","size":"105"}],"timestamp":"1785126370377"},"payload_hash":"084301fd2200268d753a4faaaf3ccec86e44401c4579e94b3c567c0427a860d8","raw_frame":"{\"market\":\"0xeb66215f2e9faa6449e30a02bab5b8ed7b79a38bf961f6b24d0073c9c2419250\", \"price_changes\":[{\"asset_id\":\"60386828328910021732068595344565885737045900010034836345809386672230885527307\", \"price\":\"0.51\", \"size\":\"105\", \"side\":\"BUY\", \"hash\":\"9a387fd84a4d63dcc6ba16c19fc1cb3d106c240d\", \"best_bid\":\"0.54\", \"best_ask\":\"0.55\"}, {\"asset_id\":\"69697746896130839564035629862476347944307040470122503199396727085502753297492\", \"price\":\"0.49\", \"size\":\"105\", \"side\":\"SELL\", \"hash\":\"2d6585bb5cd1910d5e03f721f3c839bc1355c6c2\", \"best_bid\":\"0.45\", \"best_ask\":\"0.46\"}], \"timestamp\":\"1785126370377\", \"event_type\":\"price_change\"}","received_at":"2026-07-27T04:26:10.532898Z","schema_version":"clob-market-ws.price_change.v1","sequence":null,"server_hash":null,"server_timestamp":"1785126370377","session_id":"e9443c7415a0419799bee9cfbb1a9e4d","source":"clob_market_ws"},"received_at":"2026-07-27T04:26:10.532898Z","record_id":"eceba53313aeb7c5a1a1424929d1ed16707412f999898a5ce82fa031b1b2649a","schema_fingerprint":"4aa3821a28b0b7c2400bc59aba4bcc0a76e971dadd19610d3ad38c768e124dc7","schema_version":"edge-lab-recorder.raw.v1","sequence":null,"source":"clob_market_ws"}
{"event_at":"2026-07-27T04:26:10.378000Z","event_fingerprint":"2f2d9c08b38f25c74c2116696acfeafdac066b62fd8d7fb1e9e2e33dae000507","payload":{"connection_id":"0f4979d6978d463e9660b042fdcf555f","event_at":"2026-07-27T04:26:10.378000Z","event_type":"price_change","frame_hash":"4da0aead7697e81f107da49b74e180984f2a813f96dab2cf976db3b0ae41d634","frame_index":0,"kind":"data","monotonic_ns":228353811543041,"payload":{"event_type":"price_change","market":"0xeb66215f2e9faa6449e30a02bab5b8ed7b79a38bf961f6b24d0073c9c2419250","price_changes":[{"asset_id":"69697746896130839564035629862476347944307040470122503199396727085502753297492","best_ask":"0.46","best_bid":"0.45","hash":"681cb64b3d59f88603ae5eaad92220793ded8831","price":"0.45","side":"BUY","size":"227.95"},{"asset_id":"60386828328910021732068595344565885737045900010034836345809386672230885527307","best_ask":"0.55","best_bid":"0.54","hash":"4b59e4817602e28c24160d83908f23a159f1d5ce","price":"0.55","side":"SELL","size":"227.95"}],"timestamp":"1785126370378"},"payload_hash":"fc1207da3aa9336109a98f35a3759634b2828d1db6a7d883cbabd74b7769711e","raw_frame":"{\"market\":\"0xeb66215f2e9faa6449e30a02bab5b8ed7b79a38bf961f6b24d0073c9c2419250\", \"price_changes\":[{\"asset_id\":\"69697746896130839564035629862476347944307040470122503199396727085502753297492\", \"price\":\"0.45\", \"size\":\"227.95\", \"side\":\"BUY\", \"hash\":\"681cb64b3d59f88603ae5eaad92220793ded8831\", \"best_bid\":\"0.45\", \"best_ask\":\"0.46\"}, {\"asset_id\":\"60386828328910021732068595344565885737045900010034836345809386672230885527307\", \"price\":\"0.55\", \"size\":\"227.95\", \"side\":\"SELL\", \"hash\":\"4b59e4817602e28c24160d83908f23a159f1d5ce\", \"best_bid\":\"0.54\", \"best_ask\":\"0.55\"}], \"timestamp\":\"1785126370378\", \"event_type\":\"price_change\"}","received_at":"2026-07-27T04:26:10.539716Z","schema_version":"clob-market-ws.price_change.v1","sequence":null,"server_hash":null,"server_timestamp":"1785126370378","session_id":"e9443c7415a0419799bee9cfbb1a9e4d","source":"clob_market_ws"},"received_at":"2026-07-27T04:26:10.539716Z","record_id":"c9b1ef19696d2c641557d5cb4dfedc012f5bc9d66a75e3345bb47797c7257eaa","schema_fingerprint":"4aa3821a28b0b7c2400bc59aba4bcc0a76e971dadd19610d3ad38c768e124dc7","schema_version":"edge-lab-recorder.raw.v1","sequence":null,"source":"clob_market_ws"}
{"event_at":"2026-07-27T04:26:10.378000Z","event_fingerprint":"e89ec36bc494894d3e60dfa7a9b4b1a38adbea8151e17bd3a591d93740a516d4","payload":{"connection_id":"0f4979d6978d463e9660b042fdcf555f","event_at":"2026-07-27T04:26:10.378000Z","event_type":"price_change","frame_hash":"5c43e66b68e78e5668ddfe4a48eb814e111454c133e076a98310e6e39e84be78","frame_index":0,"kind":"data","monotonic_ns":228353818238250,"payload":{"event_type":"price_change","market":"0xeb66215f2e9faa6449e30a02bab5b8ed7b79a38bf961f6b24d0073c9c2419250","price_changes":[{"asset_id":"60386828328910021732068595344565885737045900010034836345809386672230885527307","best_ask":"0.55","best_bid":"0.54","hash":"1d42bd50293b82b944219e1f26b7528b854281a2","price":"0.51","side":"BUY","size":"110"},{"asset_id":"69697746896130839564035629862476347944307040470122503199396727085502753297492","best_ask":"0.46","best_bid":"0.45","hash":"7698fe0350db6a607eca4282ba127425e39f79f3","price":"0.49","side":"SELL","size":"110"}],"timestamp":"1785126370378"},"payload_hash":"d74816a3938b1f0f79d72423e18df9b9eb165bab9cc301337e4d56a8758eae1b","raw_frame":"{\"market\":\"0xeb66215f2e9faa6449e30a02bab5b8ed7b79a38bf961f6b24d0073c9c2419250\", \"price_changes\":[{\"asset_id\":\"60386828328910021732068595344565885737045900010034836345809386672230885527307\", \"price\":\"0.51\", \"size\":\"110\", \"side\":\"BUY\", \"hash\":\"1d42bd50293b82b944219e1f26b7528b854281a2\", \"best_bid\":\"0.54\", \"best_ask\":\"0.55\"}, {\"asset_id\":\"69697746896130839564035629862476347944307040470122503199396727085502753297492\", \"price\":\"0.49\", \"size\":\"110\", \"side\":\"SELL\", \"hash\":\"7698fe0350db6a607eca4282ba127425e39f79f3\", \"best_bid\":\"0.45\", \"best_ask\":\"0.46\"}], \"timestamp\":\"1785126370378\", \"event_type\":\"price_change\"}","received_at":"2026-07-27T04:26:10.546411Z","schema_version":"clob-market-ws.price_change.v1","sequence":null,"server_hash":null,"server_timestamp":"1785126370378","session_id":"e9443c7415a0419799bee9cfbb1a9e4d","source":"clob_market_ws"},"received_at":"2026-07-27T04:26:10.546411Z","record_id":"3b0c65710323b39e1c00ff4d3d305f20c81b4ec0c8c31a2f262edc4e7b4f6367","schema_fingerprint":"4aa3821a28b0b7c2400bc59aba4bcc0a76e971dadd19610d3ad38c768e124dc7","schema_version":"edge-lab-recorder.raw.v1","sequence":null,"source":"clob_market_ws"}
{"event_at":"2026-07-27T04:26:10.379000Z","event_fingerprint":"ce25f179b5e34782d358b493310742eb400fad749e81b8350fcc54d71a07b170","payload":{"connection_id":"0f4979d6978d463e9660b042fdcf555f","event_at":"2026-07-27T04:26:10.379000Z","event_type":"price_change","frame_hash":"2ac9d5a4b87661400ad227a0bf848090b381a2554be453ffbc07ac14dff45e61","frame_index":0,"kind":"data","monotonic_ns":228353822965583,"payload":{"event_type":"price_change","market":"0xeb66215f2e9faa6449e30a02bab5b8ed7b79a38bf961f6b24d0073c9c2419250","price_changes":[{"asset_id":"69697746896130839564035629862476347944307040470122503199396727085502753297492","best_ask":"0.46","best_bid":"0.45","hash":"6977c41fb4efdc32cb1ab8d4e347c0530ab597f6","price":"0.45","side":"BUY","size":"232.95"},{"asset_id":"60386828328910021732068595344565885737045900010034836345809386672230885527307","best_ask":"0.55","best_bid":"0.54","hash":"8a61daba2f13e89758ecc724abdfc6dbc9033448","price":"0.55","side":"SELL","size":"232.95"}],"timestamp":"1785126370379"},"payload_hash":"dd2162247b926b7a81090ec6ab9961e37d1ca7542553bce5d1ac3df98035a8a9","raw_frame":"{\"market\":\"0xeb66215f2e9faa6449e30a02bab5b8ed7b79a38bf961f6b24d0073c9c2419250\", \"price_changes\":[{\"asset_id\":\"69697746896130839564035629862476347944307040470122503199396727085502753297492\", \"price\":\"0.45\", \"size\":\"232.95\", \"side\":\"BUY\", \"hash\":\"6977c41fb4efdc32cb1ab8d4e347c0530ab597f6\", \"best_bid\":\"0.45\", \"best_ask\":\"0.46\"}, {\"asset_id\":\"60386828328910021732068595344565885737045900010034836345809386672230885527307\", \"price\":\"0.55\", \"size\":\"232.95\", \"side\":\"SELL\", \"hash\":\"8a61daba2f13e89758ecc724abdfc6dbc9033448\", \"best_bid\":\"0.54\", \"best_ask\":\"0.55\"}], \"timestamp\":\"1785126370379\", \"event_type\":\"price_change\"}","received_at":"2026-07-27T04:26:10.551143Z","schema_version":"clob-market-ws.price_change.v1","sequence":null,"server_hash":null,"server_timestamp":"1785126370379","session_id":"e9443c7415a0419799bee9cfbb1a9e4d","source":"clob_market_ws"},"received_at":"2026-07-27T04:26:10.551143Z","record_id":"60236a4c9f39d03029070d3e4fd8cbd6af2b25171383a83256fdcb240c8a8156","schema_fingerprint":"4aa3821a28b0b7c2400bc59aba4bcc0a76e971dadd19610d3ad38c768e124dc7","schema_version":"edge-lab-recorder.raw.v1","sequence":null,"source":"clob_market_ws"}
{"event_at":"2026-07-27T04:26:10.380000Z","event_fingerprint":"56c536b7f0a4d11d095fa85ac128b502cc0c07897aa7c28124c13c21b0b6828f","payload":{"connection_id":"0f4979d6978d463e9660b042fdcf555f","event_at":"2026-07-27T04:26:10.380000Z","event_type":"price_change","frame_hash":"4ff8d7bfb798ba1a23c8fb38634c9a6a1e81254d09ef7c1c215f499e376cc13b","frame_index":0,"kind":"data","monotonic_ns":228353827547875,"payload":{"event_type":"price_change","market":"0xeb66215f2e9faa6449e30a02bab5b8ed7b79a38bf961f6b24d0073c9c2419250","price_changes":[{"asset_id":"60386828328910021732068595344565885737045900010034836345809386672230885527307","best_ask":"0.55","best_bid":"0.54","hash":"e0c0a894d296fe50b2403a48458345cb4423f0a2","price":"0.51","side":"BUY","size":"115"},{"asset_id":"69697746896130839564035629862476347944307040470122503199396727085502753297492","best_ask":"0.46","best_bid":"0.45","hash":"6bfd785b8d797053b3b64513cf5f990d3a05e75e","price":"0.49","side":"SELL","size":"115"}],"timestamp":"1785126370380"},"payload_hash":"8e9e48474b1bce9fb0346c7ff3f7b6669bb9f9d99266944ce05b48b9684bdbd1","raw_frame":"{\"market\":\"0xeb66215f2e9faa6449e30a02bab5b8ed7b79a38bf961f6b24d0073c9c2419250\", \"price_changes\":[{\"asset_id\":\"60386828328910021732068595344565885737045900010034836345809386672230885527307\", \"price\":\"0.51\", \"size\":\"115\", \"side\":\"BUY\", \"hash\":\"e0c0a894d296fe50b2403a48458345cb4423f0a2\", \"best_bid\":\"0.54\", \"best_ask\":\"0.55\"}, {\"asset_id\":\"69697746896130839564035629862476347944307040470122503199396727085502753297492\", \"price\":\"0.49\", \"size\":\"115\", \"side\":\"SELL\", \"hash\":\"6bfd785b8d797053b3b64513cf5f990d3a05e75e\", \"best_bid\":\"0.45\", \"best_ask\":\"0.46\"}], \"timestamp\":\"1785126370380\", \"event_type\":\"price_change\"}","received_at":"2026-07-27T04:26:10.555720Z","schema_version":"clob-market-ws.price_change.v1","sequence":null,"server_hash":null,"server_timestamp":"1785126370380","session_id":"e9443c7415a0419799bee9cfbb1a9e4d","source":"clob_market_ws"},"received_at":"2026-07-27T04:26:10.555720Z","record_id":"c08dde061a95f8d86ad530312e741e73d287de95ce528774c481c732a496e2b2","schema_fingerprint":"4aa3821a28b0b7c2400bc59aba4bcc0a76e971dadd19610d3ad38c768e124dc7","schema_version":"edge-lab-recorder.raw.v1","sequence":null,"source":"clob_market_ws"}
{"event_at":"2026-07-27T04:26:10.381000Z","event_fingerprint":"9983cddba2f64e9bccae238b4a8b1c92e9e79b70b7c6a92b2173d4a76ba560c4","payload":{"connection_id":"0f4979d6978d463e9660b042fdcf555f","event_at":"2026-07-27T04:26:10.381000Z","event_type":"price_change","frame_hash":"1c57e36d883f7f412fa5e75b1a74423f1cc466e5d20219e64317e8a4b26e051c","frame_index":0,"kind":"data","monotonic_ns":228353836213541,"payload":{"event_type":"price_change","market":"0xeb66215f2e9faa6449e30a02bab5b8ed7b79a38bf961f6b24d0073c9c2419250","price_changes":[{"asset_id":"69697746896130839564035629862476347944307040470122503199396727085502753297492","best_ask":"0.46","best_bid":"0.45","hash":"5fe4e3511d7017766046307197cb348ba9cd3529","price":"0.45","side":"BUY","size":"237.95"},{"asset_id":"60386828328910021732068595344565885737045900010034836345809386672230885527307","best_ask":"0.55","best_bid":"0.54","hash":"c14ae7ac1d528081370b5cd20df2200e01bb79ae","price":"0.55","side":"SELL","size":"237.95"}],"timestamp":"1785126370381"},"payload_hash":"46d47ae3b4ec436b1540127d3c5dc71c85f27d4d300011ffcd02eeee2cc0f7c4","raw_frame":"{\"market\":\"0xeb66215f2e9faa6449e30a02bab5b8ed7b79a38bf961f6b24d0073c9c2419250\", \"price_changes\":[{\"asset_id\":\"69697746896130839564035629862476347944307040470122503199396727085502753297492\", \"price\":\"0.45\", \"size\":\"237.95\", \"side\":\"BUY\", \"hash\":\"5fe4e3511d7017766046307197cb348ba9cd3529\", \"best_bid\":\"0.45\", \"best_ask\":\"0.46\"}, {\"asset_id\":\"60386828328910021732068595344565885737045900010034836345809386672230885527307\", \"price\":\"0.55\", \"size\":\"237.95\", \"side\":\"SELL\", \"hash\":\"c14ae7ac1d528081370b5cd20df2200e01bb79ae\", \"best_bid\":\"0.54\", \"best_ask\":\"0.55\"}], \"timestamp\":\"1785126370381\", \"event_type\":\"price_change\"}","received_at":"2026-07-27T04:26:10.564386Z","schema_version":"clob-market-ws.price_change.v1","sequence":null,"server_hash":null,"server_timestamp":"1785126370381","session_id":"e9443c7415a0419799bee9cfbb1a9e4d","source":"clob_market_ws"},"received_at":"2026-07-27T04:26:10.564386Z","record_id":"c592c568e65c457fcc21303a420baad484dec2789c3c26c2bc9915e738f86303","schema_fingerprint":"4aa3821a28b0b7c2400bc59aba4bcc0a76e971dadd19610d3ad38c768e124dc7","schema_version":"edge-lab-recorder.raw.v1","sequence":null,"source":"clob_market_ws"}
{"event_at":"2026-07-27T04:26:10.381000Z","event_fingerprint":"399e6ab24fefdff20ded5798dc5427ade569a1607dca58b52ac72b2e28056fab","payload":{"connection_id":"0f4979d6978d463e9660b042fdcf555f","event_at":"2026-07-27T04:26:10.381000Z","event_type":"price_change","frame_hash":"a46c06f4a150b1f590fe83ee4680260e42bb1ea0ed91bb69fe8e7da40077be2a","frame_index":0,"kind":"data","monotonic_ns":228353841876333,"payload":{"event_type":"price_change","market":"0xeb66215f2e9faa6449e30a02bab5b8ed7b79a38bf961f6b24d0073c9c2419250","price_changes":[{"asset_id":"60386828328910021732068595344565885737045900010034836345809386672230885527307","best_ask":"0.55","best_bid":"0.54","hash":"e3157804d5435493a5618c96baead9d74e460d48","price":"0.51","side":"BUY","size":"120"},{"asset_id":"69697746896130839564035629862476347944307040470122503199396727085502753297492","best_ask":"0.46","best_bid":"0.45","hash":"0f1ce829fda66f7786d6414957990c932bcbc1e5","price":"0.49","side":"SELL","size":"120"}],"timestamp":"1785126370381"},"payload_hash":"45ba2417184895d55b32de54edfc8ade0bb26fb75f4f8bad6ba909313924382e","raw_frame":"{\"market\":\"0xeb66215f2e9faa6449e30a02bab5b8ed7b79a38bf961f6b24d0073c9c2419250\", \"price_changes\":[{\"asset_id\":\"60386828328910021732068595344565885737045900010034836345809386672230885527307\", \"price\":\"0.51\", \"size\":\"120\", \"side\":\"BUY\", \"hash\":\"e3157804d5435493a5618c96baead9d74e460d48\", \"best_bid\":\"0.54\", \"best_ask\":\"0.55\"}, {\"asset_id\":\"69697746896130839564035629862476347944307040470122503199396727085502753297492\", \"price\":\"0.49\", \"size\":\"120\", \"side\":\"SELL\", \"hash\":\"0f1ce829fda66f7786d6414957990c932bcbc1e5\", \"best_bid\":\"0.45\", \"best_ask\":\"0.46\"}], \"timestamp\":\"1785126370381\", \"event_type\":\"price_change\"}","received_at":"2026-07-27T04:26:10.570050Z","schema_version":"clob-market-ws.price_change.v1","sequence":null,"server_hash":null,"server_timestamp":"1785126370381","session_id":"e9443c7415a0419799bee9cfbb1a9e4d","source":"clob_market_ws"},"received_at":"2026-07-27T04:26:10.570050Z","record_id":"c73fe20c4e5de0048df6a3fd4f96af4ee17840b8be73efc28d8ec810fbef4cd6","schema_fingerprint":"4aa3821a28b0b7c2400bc59aba4bcc0a76e971dadd19610d3ad38c768e124dc7","schema_version":"edge-lab-recorder.raw.v1","sequence":null,"source":"clob_market_ws"}
{"event_at":"2026-07-27T04:26:10.382000Z","event_fingerprint":"3c82776341d362576c0bdcdc85ecfd9f6405ba14fd347978f0bed85c70eea24b","payload":{"connection_id":"0f4979d6978d463e9660b042fdcf555f","event_at":"2026-07-27T04:26:10.382000Z","event_type":"price_change","frame_hash":"7eca521a71029e7d267b4c16acdc66b7311434d331a87f05bb7c2cb8d146fc42","frame_index":0,"kind":"data","monotonic_ns":228353849788916,"payload":{"event_type":"price_change","market":"0xeb66215f2e9faa6449e30a02bab5b8ed7b79a38bf961f6b24d0073c9c2419250","price_changes":[{"asset_id":"69697746896130839564035629862476347944307040470122503199396727085502753297492","best_ask":"0.46","best_bid":"0.45","hash":"1cdf65ab19353508ccb86cc710c3558922daa492","price":"0.45","side":"BUY","size":"242.95"},{"asset_id":"60386828328910021732068595344565885737045900010034836345809386672230885527307","best_ask":"0.55","best_bid":"0.54","hash":"55f72a1bea86a7a1cb78be4c24ea3d684adddfd2","price":"0.55","side":"SELL","size":"242.95"}],"timestamp":"1785126370382"},"payload_hash":"d389ac1364947bb95c85f2e5d6ac27f420e242f1545800afdee87ca0be398081","raw_frame":"{\"market\":\"0xeb66215f2e9faa6449e30a02bab5b8ed7b79a38bf961f6b24d0073c9c2419250\", \"price_changes\":[{\"asset_id\":\"69697746896130839564035629862476347944307040470122503199396727085502753297492\", \"price\":\"0.45\", \"size\":\"242.95\", \"side\":\"BUY\", \"hash\":\"1cdf65ab19353508ccb86cc710c3558922daa492\", \"best_bid\":\"0.45\", \"best_ask\":\"0.46\"}, {\"asset_id\":\"60386828328910021732068595344565885737045900010034836345809386672230885527307\", \"price\":\"0.55\", \"size\":\"242.95\", \"side\":\"SELL\", \"hash\":\"55f72a1bea86a7a1cb78be4c24ea3d684adddfd2\", \"best_bid\":\"0.54\", \"best_ask\":\"0.55\"}], \"timestamp\":\"1785126370382\", \"event_type\":\"price_change\"}","received_at":"2026-07-27T04:26:10.577962Z","schema_version":"clob-market-ws.price_change.v1","sequence":null,"server_hash":null,"server_timestamp":"1785126370382","session_id":"e9443c7415a0419799bee9cfbb1a9e4d","source":"clob_market_ws"},"received_at":"2026-07-27T04:26:10.577962Z","record_id":"e883ab0433db394971263582b74037990fe35f72992a200f88c3fffc3e7c0224","schema_fingerprint":"4aa3821a28b0b7c2400bc59aba4bcc0a76e971dadd19610d3ad38c768e124dc7","schema_version":"edge-lab-recorder.raw.v1","sequence":null,"source":"clob_market_ws"}
{"event_at":"2026-07-27T04:26:10.383000Z","event_fingerprint":"065821b9591eaef5d581d7d07b40ff00ec46b0e8144379b08c967686718dffd4","payload":{"connection_id":"0f4979d6978d463e9660b042fdcf555f","event_at":"2026-07-27T04:26:10.383000Z","event_type":"price_change","frame_hash":"7e210ec7533080979c092e2c8660eff7f8588c811f365aa1bb2ddca2efc7ae6e","frame_index":0,"kind":"data","monotonic_ns":228353856855666,"payload":{"event_type":"price_change","market":"0xeb66215f2e9faa6449e30a02bab5b8ed7b79a38bf961f6b24d0073c9c2419250","price_changes":[{"asset_id":"60386828328910021732068595344565885737045900010034836345809386672230885527307","best_ask":"0.55","best_bid":"0.54","hash":"bf6fef5ee5b1b35d5ccb2043038bd65512ac6f92","price":"0.51","side":"BUY","size":"125"},{"asset_id":"69697746896130839564035629862476347944307040470122503199396727085502753297492","best_ask":"0.46","best_bid":"0.45","hash":"17d4cb7a1a474fa9548ed986e7acd27e2f81c43e","price":"0.49","side":"SELL","size":"125"}],"timestamp":"1785126370383"},"payload_hash":"949ec4333766af3d56b3c4597fc7f2db699055cd58090ee5f028a9c6dd2da4da","raw_frame":"{\"market\":\"0xeb66215f2e9faa6449e30a02bab5b8ed7b79a38bf961f6b24d0073c9c2419250\", \"price_changes\":[{\"asset_id\":\"60386828328910021732068595344565885737045900010034836345809386672230885527307\", \"price\":\"0.51\", \"size\":\"125\", \"side\":\"BUY\", \"hash\":\"bf6fef5ee5b1b35d5ccb2043038bd65512ac6f92\", \"best_bid\":\"0.54\", \"best_ask\":\"0.55\"}, {\"asset_id\":\"69697746896130839564035629862476347944307040470122503199396727085502753297492\", \"price\":\"0.49\", \"size\":\"125\", \"side\":\"SELL\", \"hash\":\"17d4cb7a1a474fa9548ed986e7acd27e2f81c43e\", \"best_bid\":\"0.45\", \"best_ask\":\"0.46\"}], \"timestamp\":\"1785126370383\", \"event_type\":\"price_change\"}","received_at":"2026-07-27T04:26:10.585034Z","schema_version":"clob-market-ws.price_change.v1","sequence":null,"server_hash":null,"server_timestamp":"1785126370383","session_id":"e9443c7415a0419799bee9cfbb1a9e4d","source":"clob_market_ws"},"received_at":"2026-07-27T04:26:10.585034Z","record_id":"e6f8dcc7a42e09466309193b886b45b57c8beb9c4436f5de7c901d4ab9c36565","schema_fingerprint":"4aa3821a28b0b7c2400bc59aba4bcc0a76e971dadd19610d3ad38c768e124dc7","schema_version":"edge-lab-recorder.raw.v1","sequence":null,"source":"clob_market_ws"}
{"event_at":"2026-07-27T04:26:10.384000Z","event_fingerprint":"e170215303b457c7a92a885e7ccc0099b147021168df3c9e6f2763f2c59f78fe","payload":{"connection_id":"0f4979d6978d463e9660b042fdcf555f","event_at":"2026-07-27T04:26:10.384000Z","event_type":"price_change","frame_hash":"27b7a005337454f5e5534213aa6cb12b7db3bb655bc1416bb469c25e184d1bf1","frame_index":0,"kind":"data","monotonic_ns":228353862398666,"payload":{"event_type":"price_change","market":"0xeb66215f2e9faa6449e30a02bab5b8ed7b79a38bf961f6b24d0073c9c2419250","price_changes":[{"asset_id":"69697746896130839564035629862476347944307040470122503199396727085502753297492","best_ask":"0.46","best_bid":"0.45","hash":"0a5680269d6fd8806e8c4b0dac0c5aeb1cd4b39b","price":"0.45","side":"BUY","size":"247.95"},{"asset_id":"60386828328910021732068595344565885737045900010034836345809386672230885527307","best_ask":"0.55","best_bid":"0.54","hash":"e74e4e4f1495e31c877944e9516fa5d92c978abf","price":"0.55","side":"SELL","size":"247.95"}],"timestamp":"1785126370384"},"payload_hash":"b7b44c2cef49a6bc04778ae47adf9c9e4844f10d170025d7df19e49930adf9da","raw_frame":"{\"market\":\"0xeb66215f2e9faa6449e30a02bab5b8ed7b79a38bf961f6b24d0073c9c2419250\", \"price_changes\":[{\"asset_id\":\"69697746896130839564035629862476347944307040470122503199396727085502753297492\", \"price\":\"0.45\", \"size\":\"247.95\", \"side\":\"BUY\", \"hash\":\"0a5680269d6fd8806e8c4b0dac0c5aeb1cd4b39b\", \"best_bid\":\"0.45\", \"best_ask\":\"0.46\"}, {\"asset_id\":\"60386828328910021732068595344565885737045900010034836345809386672230885527307\", \"price\":\"0.55\", \"size\":\"247.95\", \"side\":\"SELL\", \"hash\":\"e74e4e4f1495e31c877944e9516fa5d92c978abf\", \"best_bid\":\"0.54\", \"best_ask\":\"0.55\"}], \"timestamp\":\"1785126370384\", \"event_type\":\"price_change\"}","received_at":"2026-07-27T04:26:10.590570Z","schema_version":"clob-market-ws.price_change.v1","sequence":null,"server_hash":null,"server_timestamp":"1785126370384","session_id":"e9443c7415a0419799bee9cfbb1a9e4d","source":"clob_market_ws"},"received_at":"2026-07-27T04:26:10.590570Z","record_id":"d584ba615d294f13423c76719a22708b5d02b4af95e31a44fd3fe0e187cc1966","schema_fingerprint":"4aa3821a28b0b7c2400bc59aba4bcc0a76e971dadd19610d3ad38c768e124dc7","schema_version":"edge-lab-recorder.raw.v1","sequence":null,"source":"clob_market_ws"}
{"event_at":"2026-07-27T04:26:10.385000Z","event_fingerprint":"e061e1707781def39d84a571985ba9f690c7167b537aa0f063c5522211c33c13","payload":{"connection_id":"0f4979d6978d463e9660b042fdcf555f","event_at":"2026-07-27T04:26:10.385000Z","event_type":"price_change","frame_hash":"0f6a858a551266690ad18c434fb216266e8bc139b77763280fe397c0c20482aa","frame_index":0,"kind":"data","monotonic_ns":228353868806333,"payload":{"event_type":"price_change","market":"0xeb66215f2e9faa6449e30a02bab5b8ed7b79a38bf961f6b24d0073c9c2419250","price_changes":[{"asset_id":"60386828328910021732068595344565885737045900010034836345809386672230885527307","best_ask":"0.55","best_bid":"0.54","hash":"7d5373ff0b16eb4c981761d343aaa6fc7fc1e2b8","price":"0.51","side":"BUY","size":"130"},{"asset_id":"69697746896130839564035629862476347944307040470122503199396727085502753297492","best_ask":"0.46","best_bid":"0.45","hash":"c4b2c98ee14cc18747e020c8a27f5341c76f251c","price":"0.49","side":"SELL","size":"130"}],"timestamp":"1785126370385"},"payload_hash":"d3edd34ac64aebfa3f87350f2fb31b1757c35bcd3b8a4ab053a3ba877b6eb307","raw_frame":"{\"market\":\"0xeb66215f2e9faa6449e30a02bab5b8ed7b79a38bf961f6b24d0073c9c2419250\", \"price_changes\":[{\"asset_id\":\"60386828328910021732068595344565885737045900010034836345809386672230885527307\", \"price\":\"0.51\", \"size\":\"130\", \"side\":\"BUY\", \"hash\":\"7d5373ff0b16eb4c981761d343aaa6fc7fc1e2b8\", \"best_bid\":\"0.54\", \"best_ask\":\"0.55\"}, {\"asset_id\":\"69697746896130839564035629862476347944307040470122503199396727085502753297492\", \"price\":\"0.49\", \"size\":\"130\", \"side\":\"SELL\", \"hash\":\"c4b2c98ee14cc18747e020c8a27f5341c76f251c\", \"best_bid\":\"0.45\", \"best_ask\":\"0.46\"}], \"timestamp\":\"1785126370385\", \"event_type\":\"price_change\"}","received_at":"2026-07-27T04:26:10.596984Z","schema_version":"clob-market-ws.price_change.v1","sequence":null,"server_hash":null,"server_timestamp":"1785126370385","session_id":"e9443c7415a0419799bee9cfbb1a9e4d","source":"clob_market_ws"},"received_at":"2026-07-27T04:26:10.596984Z","record_id":"ea35be36ea110ef1c4a82ed8e29d72aa729353d83f849bc82464f44f5cbaa9d7","schema_fingerprint":"4aa3821a28b0b7c2400bc59aba4bcc0a76e971dadd19610d3ad38c768e124dc7","schema_version":"edge-lab-recorder.raw.v1","sequence":null,"source":"clob_market_ws"}
{"event_at":"2026-07-27T04:26:10.385000Z","event_fingerprint":"6860ab7f8b19c8a82f0568de0e5e30c7e33f5ae582039415ec0960eec9bfda31","payload":{"connection_id":"0f4979d6978d463e9660b042fdcf555f","event_at":"2026-07-27T04:26:10.385000Z","event_type":"price_change","frame_hash":"c96071c4bee2575bf924c45a98205c55991b42f7c33cb19e71f08da9d17853a7","frame_index":0,"kind":"data","monotonic_ns":228353874014875,"payload":{"event_type":"price_change","market":"0xeb66215f2e9faa6449e30a02bab5b8ed7b79a38bf961f6b24d0073c9c2419250","price_changes":[{"asset_id":"69697746896130839564035629862476347944307040470122503199396727085502753297492","best_ask":"0.46","best_bid":"0.45","hash":"d64265e4e507e9ca5d0d6766e400eb07dc8d12a0","price":"0.45","side":"BUY","size":"252.95"},{"asset_id":"60386828328910021732068595344565885737045900010034836345809386672230885527307","best_ask":"0.55","best_bid":"0.54","hash":"09150c068007b9c6b516913ce4677c434d28094b","price":"0.55","side":"SELL","size":"252.95"}],"timestamp":"1785126370385"},"payload_hash":"0786f2f948c3b102d39c4813c53f244010c044ed6d0b96bf969e044cead369ad","raw_frame":"{\"market\":\"0xeb66215f2e9faa6449e30a02bab5b8ed7b79a38bf961f6b24d0073c9c2419250\", \"price_changes\":[{\"asset_id\":\"69697746896130839564035629862476347944307040470122503199396727085502753297492\", \"price\":\"0.45\", \"size\":\"252.95\", \"side\":\"BUY\", \"hash\":\"d64265e4e507e9ca5d0d6766e400eb07dc8d12a0\", \"best_bid\":\"0.45\", \"best_ask\":\"0.46\"}, {\"asset_id\":\"60386828328910021732068595344565885737045900010034836345809386672230885527307\", \"price\":\"0.55\", \"size\":\"252.95\", \"side\":\"SELL\", \"hash\":\"09150c068007b9c6b516913ce4677c434d28094b\", \"best_bid\":\"0.54\", \"best_ask\":\"0.55\"}], \"timestamp\":\"1785126370385\", \"event_type\":\"price_change\"}","received_at":"2026-07-27T04:26:10.602192Z","schema_version":"clob-market-ws.price_change.v1","sequence":null,"server_hash":null,"server_timestamp":"1785126370385","session_id":"e9443c7415a0419799bee9cfbb1a9e4d","source":"clob_market_ws"},"received_at":"2026-07-27T04:26:10.602192Z","record_id":"da7814f158cebc6b6d0cd3403b0b3fb594219b3339c5382d842dda7eff9af375","schema_fingerprint":"4aa3821a28b0b7c2400bc59aba4bcc0a76e971dadd19610d3ad38c768e124dc7","schema_version":"edge-lab-recorder.raw.v1","sequence":null,"source":"clob_market_ws"}
{"event_at":"2026-07-27T04:26:10.386000Z","event_fingerprint":"88f75f18fc3822989f69658d7ad5aafd4b8309dc1744a2780c096fe520213d15","payload":{"connection_id":"0f4979d6978d463e9660b042fdcf555f","event_at":"2026-07-27T04:26:10.386000Z","event_type":"price_change","frame_hash":"298065c645d1ff32cb52cc2249f5d91392a25ea2c41c11efdc74536cbccd5e95","frame_index":0,"kind":"data","monotonic_ns":228353878243166,"payload":{"event_type":"price_change","market":"0xeb66215f2e9faa6449e30a02bab5b8ed7b79a38bf961f6b24d0073c9c2419250","price_changes":[{"asset_id":"60386828328910021732068595344565885737045900010034836345809386672230885527307","best_ask":"0.55","best_bid":"0.54","hash":"67a61115bdbb5538657b0640e0eb4b08f40ea486","price":"0.51","side":"BUY","size":"135"},{"asset_id":"69697746896130839564035629862476347944307040470122503199396727085502753297492","best_ask":"0.46","best_bid":"0.45","hash":"935d299aaa971fb07212f75e03a12b41198edf4b","price":"0.49","side":"SELL","size":"135"}],"timestamp":"1785126370386"},"payload_hash":"03393838c4a4525f85bbcf4e934cb005eee4ea6e3d12eabb34ef058366bc8bae","raw_frame":"{\"market\":\"0xeb66215f2e9faa6449e30a02bab5b8ed7b79a38bf961f6b24d0073c9c2419250\", \"price_changes\":[{\"asset_id\":\"60386828328910021732068595344565885737045900010034836345809386672230885527307\", \"price\":\"0.51\", \"size\":\"135\", \"side\":\"BUY\", \"hash\":\"67a61115bdbb5538657b0640e0eb4b08f40ea486\", \"best_bid\":\"0.54\", \"best_ask\":\"0.55\"}, {\"asset_id\":\"69697746896130839564035629862476347944307040470122503199396727085502753297492\", \"price\":\"0.49\", \"size\":\"135\", \"side\":\"SELL\", \"hash\":\"935d299aaa971fb07212f75e03a12b41198edf4b\", \"best_bid\":\"0.45\", \"best_ask\":\"0.46\"}], \"timestamp\":\"1785126370386\", \"event_type\":\"price_change\"}","received_at":"2026-07-27T04:26:10.606415Z","schema_version":"clob-market-ws.price_change.v1","sequence":null,"server_hash":null,"server_timestamp":"1785126370386","session_id":"e9443c7415a0419799bee9cfbb1a9e4d","source":"clob_market_ws"},"received_at":"2026-07-27T04:26:10.606415Z","record_id":"032210cbeebe75a51acd3d87ce65645d22be8086068ef7d107a7a949f9678d5d","schema_fingerprint":"4aa3821a28b0b7c2400bc59aba4bcc0a76e971dadd19610d3ad38c768e124dc7","schema_version":"edge-lab-recorder.raw.v1","sequence":null,"source":"clob_market_ws"}
{"event_at":"2026-07-27T04:26:10.387000Z","event_fingerprint":"d76c32642b3f50ad298e92017650799923a90095253ec84bf49b780768d9794a","payload":{"connection_id":"0f4979d6978d463e9660b042fdcf555f","event_at":"2026-07-27T04:26:10.387000Z","event_type":"price_change","frame_hash":"50a5147d6f1177e6e830c97687c7d832bb6bd6d4d310f860b398089e25f41ff3","frame_index":0,"kind":"data","monotonic_ns":228353883293458,"payload":{"event_type":"price_change","market":"0xeb66215f2e9faa6449e30a02bab5b8ed7b79a38bf961f6b24d0073c9c2419250","price_changes":[{"asset_id":"69697746896130839564035629862476347944307040470122503199396727085502753297492","best_ask":"0.46","best_bid":"0.45","hash":"32a8aa42d23a2ca84162be329483102bc012eb18","price":"0.45","side":"BUY","size":"257.95"},{"asset_id":"60386828328910021732068595344565885737045900010034836345809386672230885527307","best_ask":"0.55","best_bid":"0.54","hash":"84fce7c501718b8e16dc1d38db37cb6aa4082fa1","price":"0.55","side":"SELL","size":"257.95"}],"timestamp":"1785126370387"},"payload_hash":"1ce54be8e36e8386db0f3b8222dc4ccb480c311afe26133c618bf0a56d1e2272","raw_frame":"{\"market\":\"0xeb66215f2e9faa6449e30a02bab5b8ed7b79a38bf961f6b24d0073c9c2419250\", \"price_changes\":[{\"asset_id\":\"69697746896130839564035629862476347944307040470122503199396727085502753297492\", \"price\":\"0.45\", \"size\":\"257.95\", \"side\":\"BUY\", \"hash\":\"32a8aa42d23a2ca84162be329483102bc012eb18\", \"best_bid\":\"0.45\", \"best_ask\":\"0.46\"}, {\"asset_id\":\"60386828328910021732068595344565885737045900010034836345809386672230885527307\", \"price\":\"0.55\", \"size\":\"257.95\", \"side\":\"SELL\", \"hash\":\"84fce7c501718b8e16dc1d38db37cb6aa4082fa1\", \"best_bid\":\"0.54\", \"best_ask\":\"0.55\"}], \"timestamp\":\"1785126370387\", \"event_type\":\"price_change\"}","received_at":"2026-07-27T04:26:10.611466Z","schema_version":"clob-market-ws.price_change.v1","sequence":null,"server_hash":null,"server_timestamp":"1785126370387","session_id":"e9443c7415a0419799bee9cfbb1a9e4d","source":"clob_market_ws"},"received_at":"2026-07-27T04:26:10.611466Z","record_id":"ab411644665f546c2fc774e947e3d860260f1b2a1a9333ec0981a7db29934837","schema_fingerprint":"4aa3821a28b0b7c2400bc59aba4bcc0a76e971dadd19610d3ad38c768e124dc7","schema_version":"edge-lab-recorder.raw.v1","sequence":null,"source":"clob_market_ws"}
{"event_at":"2026-07-27T04:26:10.387000Z","event_fingerprint":"cf3ca8c48ba4b5713083ef33e0d06622282eede1abffe1e6b3c33e0a1f91c0ef","payload":{"connection_id":"0f4979d6978d463e9660b042fdcf555f","event_at":"2026-07-27T04:26:10.387000Z","event_type":"price_change","frame_hash":"f9572a28962d86cbba088e1c103078e8fd5ab32a7eda736ea1764186343f7b6a","frame_index":0,"kind":"data","monotonic_ns":228353887269666,"payload":{"event_type":"price_change","market":"0xeb66215f2e9faa6449e30a02bab5b8ed7b79a38bf961f6b24d0073c9c2419250","price_changes":[{"asset_id":"60386828328910021732068595344565885737045900010034836345809386672230885527307","best_ask":"0.55","best_bid":"0.54","hash":"2eedcc3c7c66f120683ea0bbe0a46109ae5cc669","price":"0.51","side":"BUY","size":"140"},{"asset_id":"69697746896130839564035629862476347944307040470122503199396727085502753297492","best_ask":"0.46","best_bid":"0.45","hash":"e92fc0c4f54f46b33f85e6f748f50ea57a5de0f5","price":"0.49","side":"SELL","size":"140"}],"timestamp":"1785126370387"},"payload_hash":"22265e9a97e14ad160b8c02010416e2bd4088d82b7c6aa7360032738c7fe0a2e","raw_frame":"{\"market\":\"0xeb66215f2e9faa6449e30a02bab5b8ed7b79a38bf961f6b24d0073c9c2419250\", \"price_changes\":[{\"asset_id\":\"60386828328910021732068595344565885737045900010034836345809386672230885527307\", \"price\":\"0.51\", \"size\":\"140\", \"side\":\"BUY\", \"hash\":\"2eedcc3c7c66f120683ea0bbe0a46109ae5cc669\", \"best_bid\":\"0.54\", \"best_ask\":\"0.55\"}, {\"asset_id\":\"69697746896130839564035629862476347944307040470122503199396727085502753297492\", \"price\":\"0.49\", \"size\":\"140\", \"side\":\"SELL\", \"hash\":\"e92fc0c4f54f46b33f85e6f748f50ea57a5de0f5\", \"best_bid\":\"0.45\", \"best_ask\":\"0.46\"}], \"timestamp\":\"1785126370387\", \"event_type\":\"price_change\"}","received_at":"2026-07-27T04:26:10.615443Z","schema_version":"clob-market-ws.price_change.v1","sequence":null,"server_hash":null,"server_timestamp":"1785126370387","session_id":"e9443c7415a0419799bee9cfbb1a9e4d","source":"clob_market_ws"},"received_at":"2026-07-27T04:26:10.615443Z","record_id":"40531c8fdbc8c6c127e0e1b71da98c930dee8fb48c585af3f4c2a1329e7a4be7","schema_fingerprint":"4aa3821a28b0b7c2400bc59aba4bcc0a76e971dadd19610d3ad38c768e124dc7","schema_version":"edge-lab-recorder.raw.v1","sequence":null,"source":"clob_market_ws"}
{"event_at":"2026-07-27T04:26:10.388000Z","event_fingerprint":"d41dbe554ef8d929f7a4790a7922470784c1dc50d134cdaa5f818f04b8b215de","payload":{"connection_id":"0f4979d6978d463e9660b042fdcf555f","event_at":"2026-07-27T04:26:10.388000Z","event_type":"price_change","frame_hash":"406453c1793f1cbe82ca42fbfaee40a0d84af826e97afcd5b9403bbee2717f8f","frame_index":0,"kind":"data","monotonic_ns":228353891759375,"payload":{"event_type":"price_change","market":"0xeb66215f2e9faa6449e30a02bab5b8ed7b79a38bf961f6b24d0073c9c2419250","price_changes":[{"asset_id":"69697746896130839564035629862476347944307040470122503199396727085502753297492","best_ask":"0.46","best_bid":"0.45","hash":"da88b8ee8fe9005860b5e3805bad768f091570b7","price":"0.45","side":"BUY","size":"262.95"},{"asset_id":"60386828328910021732068595344565885737045900010034836345809386672230885527307","best_ask":"0.55","best_bid":"0.54","hash":"4b4e8e8fa7d1ccbb8f9f21f31d3dce2b1c12b0c0","price":"0.55","side":"SELL","size":"262.95"}],"timestamp":"1785126370388"},"payload_hash":"40ef70196c0dfe6b9b809856bc5921c831364aa98bf4410f7533a6e086dee472","raw_frame":"{\"market\":\"0xeb66215f2e9faa6449e30a02bab5b8ed7b79a38bf961f6b24d0073c9c2419250\", \"price_changes\":[{\"asset_id\":\"69697746896130839564035629862476347944307040470122503199396727085502753297492\", \"price\":\"0.45\", \"size\":\"262.95\", \"side\":\"BUY\", \"hash\":\"da88b8ee8fe9005860b5e3805bad768f091570b7\", \"best_bid\":\"0.45\", \"best_ask\":\"0.46\"}, {\"asset_id\":\"60386828328910021732068595344565885737045900010034836345809386672230885527307\", \"price\":\"0.55\", \"size\":\"262.95\", \"side\":\"SELL\", \"hash\":\"4b4e8e8fa7d1ccbb8f9f21f31d3dce2b1c12b0c0\", \"best_bid\":\"0.54\", \"best_ask\":\"0.55\"}], \"timestamp\":\"1785126370388\", \"event_type\":\"price_change\"}","received_at":"2026-07-27T04:26:10.619935Z","schema_version":"clob-market-ws.price_change.v1","sequence":null,"server_hash":null,"server_timestamp":"1785126370388","session_id":"e9443c7415a0419799bee9cfbb1a9e4d","source":"clob_market_ws"},"received_at":"2026-07-27T04:26:10.619935Z","record_id":"6b2d3043e2321e0297a12adacd57e43c7155d62bd50417eb6e41fa26ef552a7c","schema_fingerprint":"4aa3821a28b0b7c2400bc59aba4bcc0a76e971dadd19610d3ad38c768e124dc7","schema_version":"edge-lab-recorder.raw.v1","sequence":null,"source":"clob_market_ws"}
{"event_at":"2026-07-27T04:26:10.389000Z","event_fingerprint":"6042e335ea656622afdeaefb482199c71e3779b746de9de23e95ad7b30fa93bb","payload":{"connection_id":"0f4979d6978d463e9660b042fdcf555f","event_at":"2026-07-27T04:26:10.389000Z","event_type":"price_change","frame_hash":"9456963535541ba739e82bb8c59101ed43e0eaf1dad119d97a91c0b25f088659","frame_index":0,"kind":"data","monotonic_ns":228353897569250,"payload":{"event_type":"price_change","market":"0xeb66215f2e9faa6449e30a02bab5b8ed7b79a38bf961f6b24d0073c9c2419250","price_changes":[{"asset_id":"60386828328910021732068595344565885737045900010034836345809386672230885527307","best_ask":"0.55","best_bid":"0.54","hash":"da958c0790a83591e70023cffdc40d7d93207a76","price":"0.51","side":"BUY","size":"145"},{"asset_id":"69697746896130839564035629862476347944307040470122503199396727085502753297492","best_ask":"0.46","best_bid":"0.45","hash":"e545485ec86be8c95a8938320fea7f4008dfbe4c","price":"0.49","side":"SELL","size":"145"}],"timestamp":"1785126370389"},"payload_hash":"c372f40a5a14d2514ae498be16dc84450530a28db1ffdc75c569ea1faee03032","raw_frame":"{\"market\":\"0xeb66215f2e9faa6449e30a02bab5b8ed7b79a38bf961f6b24d0073c9c2419250\", \"price_changes\":[{\"asset_id\":\"60386828328910021732068595344565885737045900010034836345809386672230885527307\", \"price\":\"0.51\", \"size\":\"145\", \"side\":\"BUY\", \"hash\":\"da958c0790a83591e70023cffdc40d7d93207a76\", \"best_bid\":\"0.54\", \"best_ask\":\"0.55\"}, {\"asset_id\":\"69697746896130839564035629862476347944307040470122503199396727085502753297492\", \"price\":\"0.49\", \"size\":\"145\", \"side\":\"SELL\", \"hash\":\"e545485ec86be8c95a8938320fea7f4008dfbe4c\", \"best_bid\":\"0.45\", \"best_ask\":\"0.46\"}], \"timestamp\":\"1785126370389\", \"event_type\":\"price_change\"}","received_at":"2026-07-27T04:26:10.625739Z","schema_version":"clob-market-ws.price_change.v1","sequence":null,"server_hash":null,"server_timestamp":"1785126370389","session_id":"e9443c7415a0419799bee9cfbb1a9e4d","source":"clob_market_ws"},"received_at":"2026-07-27T04:26:10.625739Z","record_id":"be37e4820471efd1b6184a67b4dd3c8166e004dd8b90259f70b36c1ec43048cf","schema_fingerprint":"4aa3821a28b0b7c2400bc59aba4bcc0a76e971dadd19610d3ad38c768e124dc7","schema_version":"edge-lab-recorder.raw.v1","sequence":null,"source":"clob_market_ws"}
{"event_at":"2026-07-27T04:26:10.390000Z","event_fingerprint":"9aa5000b1d883723331c792e754bac1b6e878e50e2aedb469ac1eccb211d60dc","payload":{"connection_id":"0f4979d6978d463e9660b042fdcf555f","event_at":"2026-07-27T04:26:10.390000Z","event_type":"price_change","frame_hash":"63d4bb93edcfefe8409b8af5b1df7a44e2992a634f774dfcd418cec517e2da51","frame_index":0,"kind":"data","monotonic_ns":228353906631458,"payload":{"event_type":"price_change","market":"0xeb66215f2e9faa6449e30a02bab5b8ed7b79a38bf961f6b24d0073c9c2419250","price_changes":[{"asset_id":"69697746896130839564035629862476347944307040470122503199396727085502753297492","best_ask":"0.46","best_bid":"0.45","hash":"6e5d93e558a9e4861573db338601bd1b792e2e67","price":"0.45","side":"BUY","size":"267.95"},{"asset_id":"60386828328910021732068595344565885737045900010034836345809386672230885527307","best_ask":"0.55","best_bid":"0.54","hash":"df537b35a73e5c995d6faf361be6e646c2dcc284","price":"0.55","side":"SELL","size":"267.95"}],"timestamp":"1785126370390"},"payload_hash":"42886e4cd73e5e6691ed52334d44e9f5bdd0e43b23897162ecc31e6a1e7bcfdf","raw_frame":"{\"market\":\"0xeb66215f2e9faa6449e30a02bab5b8ed7b79a38bf961f6b24d0073c9c2419250\", \"price_changes\":[{\"asset_id\":\"69697746896130839564035629862476347944307040470122503199396727085502753297492\", \"price\":\"0.45\", \"size\":\"267.95\", \"side\":\"BUY\", \"hash\":\"6e5d93e558a9e4861573db338601bd1b792e2e67\", \"best_bid\":\"0.45\", \"best_ask\":\"0.46\"}, {\"asset_id\":\"60386828328910021732068595344565885737045900010034836345809386672230885527307\", \"price\":\"0.55\", \"size\":\"267.95\", \"side\":\"SELL\", \"hash\":\"df537b35a73e5c995d6faf361be6e646c2dcc284\", \"best_bid\":\"0.54\", \"best_ask\":\"0.55\"}], \"timestamp\":\"1785126370390\", \"event_type\":\"price_change\"}","received_at":"2026-07-27T04:26:10.634802Z","schema_version":"clob-market-ws.price_change.v1","sequence":null,"server_hash":null,"server_timestamp":"1785126370390","session_id":"e9443c7415a0419799bee9cfbb1a9e4d","source":"clob_market_ws"},"received_at":"2026-07-27T04:26:10.634802Z","record_id":"d2a5f5c35dd0f4d6a3488c615fefc1cdc52bd689bc6c092de4d121b5ccc967cc","schema_fingerprint":"4aa3821a28b0b7c2400bc59aba4bcc0a76e971dadd19610d3ad38c768e124dc7","schema_version":"edge-lab-recorder.raw.v1","sequence":null,"source":"clob_market_ws"}
{"event_at":"2026-07-27T04:26:10.391000Z","event_fingerprint":"a3f6ba8a0e1be863bc0c37c232f9c19588c34599d095653405f9d8d7ac015266","payload":{"connection_id":"0f4979d6978d463e9660b042fdcf555f","event_at":"2026-07-27T04:26:10.391000Z","event_type":"price_change","frame_hash":"035c39f35de415912d23f72db65bfbbde16e604ceef876bf14dd4deb59771b72","frame_index":0,"kind":"data","monotonic_ns":228353913051208,"payload":{"event_type":"price_change","market":"0xeb66215f2e9faa6449e30a02bab5b8ed7b79a38bf961f6b24d0073c9c2419250","price_changes":[{"asset_id":"60386828328910021732068595344565885737045900010034836345809386672230885527307","best_ask":"0.55","best_bid":"0.54","hash":"3424434810b29d5a16e822c6e1e7ab0312418257","price":"0.51","side":"BUY","size":"150"},{"asset_id":"69697746896130839564035629862476347944307040470122503199396727085502753297492","best_ask":"0.46","best_bid":"0.45","hash":"96a0cd8274ba3e93486f0460db0d9eb3ca9009e1","price":"0.49","side":"SELL","size":"150"}],"timestamp":"1785126370391"},"payload_hash":"c456d13eaec1fdd3d35264b2db8f9af4dc9e67f572b8591a080a710e3581c7cb","raw_frame":"{\"market\":\"0xeb66215f2e9faa6449e30a02bab5b8ed7b79a38bf961f6b24d0073c9c2419250\", \"price_changes\":[{\"asset_id\":\"60386828328910021732068595344565885737045900010034836345809386672230885527307\", \"price\":\"0.51\", \"size\":\"150\", \"side\":\"BUY\", \"hash\":\"3424434810b29d5a16e822c6e1e7ab0312418257\", \"best_bid\":\"0.54\", \"best_ask\":\"0.55\"}, {\"asset_id\":\"69697746896130839564035629862476347944307040470122503199396727085502753297492\", \"price\":\"0.49\", \"size\":\"150\", \"side\":\"SELL\", \"hash\":\"96a0cd8274ba3e93486f0460db0d9eb3ca9009e1\", \"best_bid\":\"0.45\", \"best_ask\":\"0.46\"}], \"timestamp\":\"1785126370391\", \"event_type\":\"price_change\"}","received_at":"2026-07-27T04:26:10.641224Z","schema_version":"clob-market-ws.price_change.v1","sequence":null,"server_hash":null,"server_timestamp":"1785126370391","session_id":"e9443c7415a0419799bee9cfbb1a9e4d","source":"clob_market_ws"},"received_at":"2026-07-27T04:26:10.641224Z","record_id":"370d9a588677fa46744a367a70e010d3574e5798ce0f9a332022cd318066f281","schema_fingerprint":"4aa3821a28b0b7c2400bc59aba4bcc0a76e971dadd19610d3ad38c768e124dc7","schema_version":"edge-lab-recorder.raw.v1","sequence":null,"source":"clob_market_ws"}
{"event_at":"2026-07-27T04:26:10.391000Z","event_fingerprint":"5ca7721edd30bd0178faad598dad66fbfd4af9cc6d6b911e10c10725c7920cfe","payload":{"connection_id":"0f4979d6978d463e9660b042fdcf555f","event_at":"2026-07-27T04:26:10.391000Z","event_type":"price_change","frame_hash":"84fe34587b898496c5450b9b051e059afa5871dbfac3c3d2a3f5f9f988aafe00","frame_index":0,"kind":"data","monotonic_ns":228353918688000,"payload":{"event_type":"price_change","market":"0xeb66215f2e9faa6449e30a02bab5b8ed7b79a38bf961f6b24d0073c9c2419250","price_changes":[{"asset_id":"69697746896130839564035629862476347944307040470122503199396727085502753297492","best_ask":"0.46","best_bid":"0.45","hash":"cc037704b8cf987c971926a708e121bf1994741b","price":"0.45","side":"BUY","size":"272.95"},{"asset_id":"60386828328910021732068595344565885737045900010034836345809386672230885527307","best_ask":"0.55","best_bid":"0.54","hash":"6a236fb3e009115624dd4b9daa5a4bd793b9bbaa","price":"0.55","side":"SELL","size":"272.95"}],"timestamp":"1785126370391"},"payload_hash":"1e501c8df63c1a101e3cf24bfc8d4c8513267e45495e9315c7b1cc2f68bdbd53","raw_frame":"{\"market\":\"0xeb66215f2e9faa6449e30a02bab5b8ed7b79a38bf961f6b24d0073c9c2419250\", \"price_changes\":[{\"asset_id\":\"69697746896130839564035629862476347944307040470122503199396727085502753297492\", \"price\":\"0.45\", \"size\":\"272.95\", \"side\":\"BUY\", \"hash\":\"cc037704b8cf987c971926a708e121bf1994741b\", \"best_bid\":\"0.45\", \"best_ask\":\"0.46\"}, {\"asset_id\":\"60386828328910021732068595344565885737045900010034836345809386672230885527307\", \"price\":\"0.55\", \"size\":\"272.95\", \"side\":\"SELL\", \"hash\":\"6a236fb3e009115624dd4b9daa5a4bd793b9bbaa\", \"best_bid\":\"0.54\", \"best_ask\":\"0.55\"}], \"timestamp\":\"1785126370391\", \"event_type\":\"price_change\"}","received_at":"2026-07-27T04:26:10.646860Z","schema_version":"clob-market-ws.price_change.v1","sequence":null,"server_hash":null,"server_timestamp":"1785126370391","session_id":"e9443c7415a0419799bee9cfbb1a9e4d","source":"clob_market_ws"},"received_at":"2026-07-27T04:26:10.646860Z","record_id":"595b4693653082b7aa9807813d252315ea4fb60049555e0a9f7172fbe8f7e8a1","schema_fingerprint":"4aa3821a28b0b7c2400bc59aba4bcc0a76e971dadd19610d3ad38c768e124dc7","schema_version":"edge-lab-recorder.raw.v1","sequence":null,"source":"clob_market_ws"}
{"event_at":"2026-07-27T04:26:10.392000Z","event_fingerprint":"040767a18e88fade524430c557044625b537616f46da3c0cb01d0c3d09b3f53b","payload":{"connection_id":"0f4979d6978d463e9660b042fdcf555f","event_at":"2026-07-27T04:26:10.392000Z","event_type":"price_change","frame_hash":"10ce57812ddcafb59542a48ba9ec1acfce2667feeea45c96b9e9a24cd1f78c6b","frame_index":0,"kind":"data","monotonic_ns":228353925288250,"payload":{"event_type":"price_change","market":"0xeb66215f2e9faa6449e30a02bab5b8ed7b79a38bf961f6b24d0073c9c2419250","price_changes":[{"asset_id":"69697746896130839564035629862476347944307040470122503199396727085502753297492","best_ask":"0.46","best_bid":"0.45","hash":"0d939eed2cd97d5c712e61368ec8158d14d12236","price":"0.45","side":"BUY","size":"277.95"},{"asset_id":"60386828328910021732068595344565885737045900010034836345809386672230885527307","best_ask":"0.55","best_bid":"0.54","hash":"771ec683572799acf217ab9e2e8f83fc6a0aee96","price":"0.55","side":"SELL","size":"277.95"}],"timestamp":"1785126370392"},"payload_hash":"b809af8dea77136a0818b9076117f4144e6ec288a081be73d452138acfa77f2b","raw_frame":"{\"market\":\"0xeb66215f2e9faa6449e30a02bab5b8ed7b79a38bf961f6b24d0073c9c2419250\", \"price_changes\":[{\"asset_id\":\"69697746896130839564035629862476347944307040470122503199396727085502753297492\", \"price\":\"0.45\", \"size\":\"277.95\", \"side\":\"BUY\", \"hash\":\"0d939eed2cd97d5c712e61368ec8158d14d12236\", \"best_bid\":\"0.45\", \"best_ask\":\"0.46\"}, {\"asset_id\":\"60386828328910021732068595344565885737045900010034836345809386672230885527307\", \"price\":\"0.55\", \"size\":\"277.95\", \"side\":\"SELL\", \"hash\":\"771ec683572799acf217ab9e2e8f83fc6a0aee96\", \"best_bid\":\"0.54\", \"best_ask\":\"0.55\"}], \"timestamp\":\"1785126370392\", \"event_type\":\"price_change\"}","received_at":"2026-07-27T04:26:10.653460Z","schema_version":"clob-market-ws.price_change.v1","sequence":null,"server_hash":null,"server_timestamp":"1785126370392","session_id":"e9443c7415a0419799bee9cfbb1a9e4d","source":"clob_market_ws"},"received_at":"2026-07-27T04:26:10.653460Z","record_id":"793bdb1acbe198ec1183a1fdb62783f9e6d4d9a010ead4074bc13d127cf578f0","schema_fingerprint":"4aa3821a28b0b7c2400bc59aba4bcc0a76e971dadd19610d3ad38c768e124dc7","schema_version":"edge-lab-recorder.raw.v1","sequence":null,"source":"clob_market_ws"}
{"event_at":"2026-07-27T04:26:10.393000Z","event_fingerprint":"4f5103101308cd5b924169c51770f5b370b18552e92313b8d25519c61359a42d","payload":{"connection_id":"0f4979d6978d463e9660b042fdcf555f","event_at":"2026-07-27T04:26:10.393000Z","event_type":"price_change","frame_hash":"7870947de592b11c68175976ecacb55199dd228efb74125c88d3e12142d3abf7","frame_index":0,"kind":"data","monotonic_ns":228353930881958,"payload":{"event_type":"price_change","market":"0xeb66215f2e9faa6449e30a02bab5b8ed7b79a38bf961f6b24d0073c9c2419250","price_changes":[{"asset_id":"69697746896130839564035629862476347944307040470122503199396727085502753297492","best_ask":"0.46","best_bid":"0.45","hash":"b4b191193731a4620fa7a15f5657488b710ba34b","price":"0.45","side":"BUY","size":"282.95"},{"asset_id":"60386828328910021732068595344565885737045900010034836345809386672230885527307","best_ask":"0.55","best_bid":"0.54","hash":"bb0f816505aa4812cc6db79c749cbe2479a67468","price":"0.55","side":"SELL","size":"282.95"}],"timestamp":"1785126370393"},"payload_hash":"d8d48127ebeea91bf4d86f210c5f7ee2b7e65f5b657dccc362a6843f9f1e7080","raw_frame":"{\"market\":\"0xeb66215f2e9faa6449e30a02bab5b8ed7b79a38bf961f6b24d0073c9c2419250\", \"price_changes\":[{\"asset_id\":\"69697746896130839564035629862476347944307040470122503199396727085502753297492\", \"price\":\"0.45\", \"size\":\"282.95\", \"side\":\"BUY\", \"hash\":\"b4b191193731a4620fa7a15f5657488b710ba34b\", \"best_bid\":\"0.45\", \"best_ask\":\"0.46\"}, {\"asset_id\":\"60386828328910021732068595344565885737045900010034836345809386672230885527307\", \"price\":\"0.55\", \"size\":\"282.95\", \"side\":\"SELL\", \"hash\":\"bb0f816505aa4812cc6db79c749cbe2479a67468\", \"best_bid\":\"0.54\", \"best_ask\":\"0.55\"}], \"timestamp\":\"1785126370393\", \"event_type\":\"price_change\"}","received_at":"2026-07-27T04:26:10.659055Z","schema_version":"clob-market-ws.price_change.v1","sequence":null,"server_hash":null,"server_timestamp":"1785126370393","session_id":"e9443c7415a0419799bee9cfbb1a9e4d","source":"clob_market_ws"},"received_at":"2026-07-27T04:26:10.659055Z","record_id":"b439d06bba8b77fe03a7407815304a30200a0d41fdd6f29012a828d55debef9b","schema_fingerprint":"4aa3821a28b0b7c2400bc59aba4bcc0a76e971dadd19610d3ad38c768e124dc7","schema_version":"edge-lab-recorder.raw.v1","sequence":null,"source":"clob_market_ws"}
{"event_at":"2026-07-27T04:26:10.394000Z","event_fingerprint":"478328e4998fb007774955a6fb415df3e4d0b5784ab8f2edd404f7b272c0fc03","payload":{"connection_id":"0f4979d6978d463e9660b042fdcf555f","event_at":"2026-07-27T04:26:10.394000Z","event_type":"price_change","frame_hash":"7e9c5b28da0382d3896a7b88f6ab6f86db55d69d60360b7ee20a40194477cd02","frame_index":0,"kind":"data","monotonic_ns":228353937424166,"payload":{"event_type":"price_change","market":"0xeb66215f2e9faa6449e30a02bab5b8ed7b79a38bf961f6b24d0073c9c2419250","price_changes":[{"asset_id":"69697746896130839564035629862476347944307040470122503199396727085502753297492","best_ask":"0.46","best_bid":"0.45","hash":"3ee4e1dd9581e3946f02e7620f09793af63e447f","price":"0.45","side":"BUY","size":"287.95"},{"asset_id":"60386828328910021732068595344565885737045900010034836345809386672230885527307","best_ask":"0.55","best_bid":"0.54","hash":"844c444a806abae6ef52d41196ebcdbe2a79ea9a","price":"0.55","side":"SELL","size":"287.95"}],"timestamp":"1785126370394"},"payload_hash":"27ae51072bcafe5cd52d9846f483e08313f68985270991612389e2791c38dbb5","raw_frame":"{\"market\":\"0xeb66215f2e9faa6449e30a02bab5b8ed7b79a38bf961f6b24d0073c9c2419250\", \"price_changes\":[{\"asset_id\":\"69697746896130839564035629862476347944307040470122503199396727085502753297492\", \"price\":\"0.45\", \"size\":\"287.95\", \"side\":\"BUY\", \"hash\":\"3ee4e1dd9581e3946f02e7620f09793af63e447f\", \"best_bid\":\"0.45\", \"best_ask\":\"0.46\"}, {\"asset_id\":\"60386828328910021732068595344565885737045900010034836345809386672230885527307\", \"price\":\"0.55\", \"size\":\"287.95\", \"side\":\"SELL\", \"hash\":\"844c444a806abae6ef52d41196ebcdbe2a79ea9a\", \"best_bid\":\"0.54\", \"best_ask\":\"0.55\"}], \"timestamp\":\"1785126370394\", \"event_type\":\"price_change\"}","received_at":"2026-07-27T04:26:10.665598Z","schema_version":"clob-market-ws.price_change.v1","sequence":null,"server_hash":null,"server_timestamp":"1785126370394","session_id":"e9443c7415a0419799bee9cfbb1a9e4d","source":"clob_market_ws"},"received_at":"2026-07-27T04:26:10.665598Z","record_id":"a386a14c0e4f6fb6dba00b1c4b5fecdeae32a2a1e703973510a22a29b3298935","schema_fingerprint":"4aa3821a28b0b7c2400bc59aba4bcc0a76e971dadd19610d3ad38c768e124dc7","schema_version":"edge-lab-recorder.raw.v1","sequence":null,"source":"clob_market_ws"}
{"event_at":"2026-07-27T04:26:10.394000Z","event_fingerprint":"dfcc4e8e5699a383b0a355d574ba2db61f100d8188ea4a02add2392e66904946","payload":{"connection_id":"0f4979d6978d463e9660b042fdcf555f","event_at":"2026-07-27T04:26:10.394000Z","event_type":"price_change","frame_hash":"4df93acfa09a2fed62d982e45bedb6a77af37d390c453de2960ec41456a3c645","frame_index":0,"kind":"data","monotonic_ns":228353945090958,"payload":{"event_type":"price_change","market":"0xeb66215f2e9faa6449e30a02bab5b8ed7b79a38bf961f6b24d0073c9c2419250","price_changes":[{"asset_id":"69697746896130839564035629862476347944307040470122503199396727085502753297492","best_ask":"0.46","best_bid":"0.45","hash":"5a9b1b6bcaf338c64440342d2ed0ce6802da0e06","price":"0.45","side":"BUY","size":"292.95"},{"asset_id":"60386828328910021732068595344565885737045900010034836345809386672230885527307","best_ask":"0.55","best_bid":"0.54","hash":"5c2ca3caf46557f62ec1d03a844d3b4b05de54e9","price":"0.55","side":"SELL","size":"292.95"}],"timestamp":"1785126370394"},"payload_hash":"bf5cb0ca29631fca1ab69961d7c0a64347d5b6dadac126c7d38bac0f10dcf06e","raw_frame":"{\"market\":\"0xeb66215f2e9faa6449e30a02bab5b8ed7b79a38bf961f6b24d0073c9c2419250\", \"price_changes\":[{\"asset_id\":\"69697746896130839564035629862476347944307040470122503199396727085502753297492\", \"price\":\"0.45\", \"size\":\"292.95\", \"side\":\"BUY\", \"hash\":\"5a9b1b6bcaf338c64440342d2ed0ce6802da0e06\", \"best_bid\":\"0.45\", \"best_ask\":\"0.46\"}, {\"asset_id\":\"60386828328910021732068595344565885737045900010034836345809386672230885527307\", \"price\":\"0.55\", \"size\":\"292.95\", \"side\":\"SELL\", \"hash\":\"5c2ca3caf46557f62ec1d03a844d3b4b05de54e9\", \"best_bid\":\"0.54\", \"best_ask\":\"0.55\"}], \"timestamp\":\"1785126370394\", \"event_type\":\"price_change\"}","received_at":"2026-07-27T04:26:10.673265Z","schema_version":"clob-market-ws.price_change.v1","sequence":null,"server_hash":null,"server_timestamp":"1785126370394","session_id":"e9443c7415a0419799bee9cfbb1a9e4d","source":"clob_market_ws"},"received_at":"2026-07-27T04:26:10.673265Z","record_id":"b7a6ab2b19f504951085ff61e39b2127ea73d29befe8b2d9b25454fabe3222da","schema_fingerprint":"4aa3821a28b0b7c2400bc59aba4bcc0a76e971dadd19610d3ad38c768e124dc7","schema_version":"edge-lab-recorder.raw.v1","sequence":null,"source":"clob_market_ws"}
{"event_at":"2026-07-27T04:26:10.395000Z","event_fingerprint":"2b3a754737854c9232ec0cdc5895d34d9137a14b31076cb76a4a98b04c8c1869","payload":{"connection_id":"0f4979d6978d463e9660b042fdcf555f","event_at":"2026-07-27T04:26:10.395000Z","event_type":"price_change","frame_hash":"7a5fd3c123828106133cf23e91242b1374b0d4801c09592ec47f95c39e892956","frame_index":0,"kind":"data","monotonic_ns":228353952507708,"payload":{"event_type":"price_change","market":"0xeb66215f2e9faa6449e30a02bab5b8ed7b79a38bf961f6b24d0073c9c2419250","price_changes":[{"asset_id":"69697746896130839564035629862476347944307040470122503199396727085502753297492","best_ask":"0.46","best_bid":"0.45","hash":"4ae3f06ff1fd53a77ea3eab714a9484955be5711","price":"0.45","side":"BUY","size":"297.95"},{"asset_id":"60386828328910021732068595344565885737045900010034836345809386672230885527307","best_ask":"0.55","best_bid":"0.54","hash":"d3aeac437aaf8a5faf477e712aaa9c2524524712","price":"0.55","side":"SELL","size":"297.95"}],"timestamp":"1785126370395"},"payload_hash":"9b3bd743f3487c9e423a15ae46dde7e4945f7557bea89e02b6dc019091da6ef7","raw_frame":"{\"market\":\"0xeb66215f2e9faa6449e30a02bab5b8ed7b79a38bf961f6b24d0073c9c2419250\", \"price_changes\":[{\"asset_id\":\"69697746896130839564035629862476347944307040470122503199396727085502753297492\", \"price\":\"0.45\", \"size\":\"297.95\", \"side\":\"BUY\", \"hash\":\"4ae3f06ff1fd53a77ea3eab714a9484955be5711\", \"best_bid\":\"0.45\", \"best_ask\":\"0.46\"}, {\"asset_id\":\"60386828328910021732068595344565885737045900010034836345809386672230885527307\", \"price\":\"0.55\", \"size\":\"297.95\", \"side\":\"SELL\", \"hash\":\"d3aeac437aaf8a5faf477e712aaa9c2524524712\", \"best_bid\":\"0.54\", \"best_ask\":\"0.55\"}], \"timestamp\":\"1785126370395\", \"event_type\":\"price_change\"}","received_at":"2026-07-27T04:26:10.680678Z","schema_version":"clob-market-ws.price_change.v1","sequence":null,"server_hash":null,"server_timestamp":"1785126370395","session_id":"e9443c7415a0419799bee9cfbb1a9e4d","source":"clob_market_ws"},"received_at":"2026-07-27T04:26:10.680678Z","record_id":"07790f6446d1f428edf413e097469bd230d703b683dacc9601cec1c351ec74b2","schema_fingerprint":"4aa3821a28b0b7c2400bc59aba4bcc0a76e971dadd19610d3ad38c768e124dc7","schema_version":"edge-lab-recorder.raw.v1","sequence":null,"source":"clob_market_ws"}
{"event_at":"2026-07-27T04:26:10.396000Z","event_fingerprint":"833a30028c9f562161c7a946199b67c3c32ad00267f3307d5c86549281a4f2d4","payload":{"connection_id":"0f4979d6978d463e9660b042fdcf555f","event_at":"2026-07-27T04:26:10.396000Z","event_type":"price_change","frame_hash":"7b8773afc86d5af04adf5473ba293cb6d5a2395b749eb194206e33d779286ec4","frame_index":0,"kind":"data","monotonic_ns":228353960783000,"payload":{"event_type":"price_change","market":"0xeb66215f2e9faa6449e30a02bab5b8ed7b79a38bf961f6b24d0073c9c2419250","price_changes":[{"asset_id":"69697746896130839564035629862476347944307040470122503199396727085502753297492","best_ask":"0.46","best_bid":"0.45","hash":"b447d8b8eaa5ceed4fe211d48a4a5eb165250bd7","price":"0.45","side":"BUY","size":"302.95"},{"asset_id":"60386828328910021732068595344565885737045900010034836345809386672230885527307","best_ask":"0.55","best_bid":"0.54","hash":"5ba53e45c5f05e7b2ca65b86bd311fbda27ca093","price":"0.55","side":"SELL","size":"302.95"}],"timestamp":"1785126370396"},"payload_hash":"f9e9d060a0da96b583472787bca4b8928d16eae3dc3404dc9bcbb4e5bd9512d0","raw_frame":"{\"market\":\"0xeb66215f2e9faa6449e30a02bab5b8ed7b79a38bf961f6b24d0073c9c2419250\", \"price_changes\":[{\"asset_id\":\"69697746896130839564035629862476347944307040470122503199396727085502753297492\", \"price\":\"0.45\", \"size\":\"302.95\", \"side\":\"BUY\", \"hash\":\"b447d8b8eaa5ceed4fe211d48a4a5eb165250bd7\", \"best_bid\":\"0.45\", \"best_ask\":\"0.46\"}, {\"asset_id\":\"60386828328910021732068595344565885737045900010034836345809386672230885527307\", \"price\":\"0.55\", \"size\":\"302.95\", \"side\":\"SELL\", \"hash\":\"5ba53e45c5f05e7b2ca65b86bd311fbda27ca093\", \"best_bid\":\"0.54\", \"best_ask\":\"0.55\"}], \"timestamp\":\"1785126370396\", \"event_type\":\"price_change\"}","received_at":"2026-07-27T04:26:10.688956Z","schema_version":"clob-market-ws.price_change.v1","sequence":null,"server_hash":null,"server_timestamp":"1785126370396","session_id":"e9443c7415a0419799bee9cfbb1a9e4d","source":"clob_market_ws"},"received_at":"2026-07-27T04:26:10.688956Z","record_id":"a764c0e405012d3f7eec4054f3cc6ac109050918299af5da4533bd80b835a5be","schema_fingerprint":"4aa3821a28b0b7c2400bc59aba4bcc0a76e971dadd19610d3ad38c768e124dc7","schema_version":"edge-lab-recorder.raw.v1","sequence":null,"source":"clob_market_ws"}
{"event_at":"2026-07-27T04:26:10.396000Z","event_fingerprint":"452934eab1156b320f0aa023ac55033436d174fedb907b394a0cf745f85f21a8","payload":{"connection_id":"0f4979d6978d463e9660b042fdcf555f","event_at":"2026-07-27T04:26:10.396000Z","event_type":"price_change","frame_hash":"ad90049c790725138c31c893c9ab64cb222d2719d3dda32eeeecdd97b9fe339f","frame_index":0,"kind":"data","monotonic_ns":228353964144666,"payload":{"event_type":"price_change","market":"0xeb66215f2e9faa6449e30a02bab5b8ed7b79a38bf961f6b24d0073c9c2419250","price_changes":[{"asset_id":"69697746896130839564035629862476347944307040470122503199396727085502753297492","best_ask":"0.46","best_bid":"0.45","hash":"619b6a381aec7fc44385325cfc705ef6363623ce","price":"0.45","side":"BUY","size":"307.95"},{"asset_id":"60386828328910021732068595344565885737045900010034836345809386672230885527307","best_ask":"0.55","best_bid":"0.54","hash":"2c35fa999e2f7f8b6d68c8bd610925021152484b","price":"0.55","side":"SELL","size":"307.95"}],"timestamp":"1785126370396"},"payload_hash":"d194aec2aaf941060c9d5070d60c8edfc80d68e1ffa339ba656e10f3003ddc47","raw_frame":"{\"market\":\"0xeb66215f2e9faa6449e30a02bab5b8ed7b79a38bf961f6b24d0073c9c2419250\", \"price_changes\":[{\"asset_id\":\"69697746896130839564035629862476347944307040470122503199396727085502753297492\", \"price\":\"0.45\", \"size\":\"307.95\", \"side\":\"BUY\", \"hash\":\"619b6a381aec7fc44385325cfc705ef6363623ce\", \"best_bid\":\"0.45\", \"best_ask\":\"0.46\"}, {\"asset_id\":\"60386828328910021732068595344565885737045900010034836345809386672230885527307\", \"price\":\"0.55\", \"size\":\"307.95\", \"side\":\"SELL\", \"hash\":\"2c35fa999e2f7f8b6d68c8bd610925021152484b\", \"best_bid\":\"0.54\", \"best_ask\":\"0.55\"}], \"timestamp\":\"1785126370396\", \"event_type\":\"price_change\"}","received_at":"2026-07-27T04:26:10.692319Z","schema_version":"clob-market-ws.price_change.v1","sequence":null,"server_hash":null,"server_timestamp":"1785126370396","session_id":"e9443c7415a0419799bee9cfbb1a9e4d","source":"clob_market_ws"},"received_at":"2026-07-27T04:26:10.692319Z","record_id":"52098e8187a646ee8e461d0ead3397c5c6504f6d0c851a931faa28a2260ee663","schema_fingerprint":"4aa3821a28b0b7c2400bc59aba4bcc0a76e971dadd19610d3ad38c768e124dc7","schema_version":"edge-lab-recorder.raw.v1","sequence":null,"source":"clob_market_ws"}
{"event_at":"2026-07-27T04:26:10.397000Z","event_fingerprint":"5adfa62034a25dff769cda1af0f9ee43d21cc5c5eac0d4e70bee4f8480099fda","payload":{"connection_id":"0f4979d6978d463e9660b042fdcf555f","event_at":"2026-07-27T04:26:10.397000Z","event_type":"price_change","frame_hash":"e588cdb10ad948b4adbde017774da63b26275503fbd55ba519d3c49c2eb70b15","frame_index":0,"kind":"data","monotonic_ns":228353969715458,"payload":{"event_type":"price_change","market":"0xeb66215f2e9faa6449e30a02bab5b8ed7b79a38bf961f6b24d0073c9c2419250","price_changes":[{"asset_id":"69697746896130839564035629862476347944307040470122503199396727085502753297492","best_ask":"0.46","best_bid":"0.45","hash":"9b3dca4bad4d5f1bde2ff13bd0a1e127524709f0","price":"0.45","side":"BUY","size":"312.95"},{"asset_id":"60386828328910021732068595344565885737045900010034836345809386672230885527307","best_ask":"0.55","best_bid":"0.54","hash":"184d0cded9981ba929426e8a97f2effbb2f9dbfe","price":"0.55","side":"SELL","size":"312.95"}],"timestamp":"1785126370397"},"payload_hash":"e08b09befc9b8284d7574fc8e1e615ce4b86ede6a0ec4d803bfbeb0330966dd5","raw_frame":"{\"market\":\"0xeb66215f2e9faa6449e30a02bab5b8ed7b79a38bf961f6b24d0073c9c2419250\", \"price_changes\":[{\"asset_id\":\"69697746896130839564035629862476347944307040470122503199396727085502753297492\", \"price\":\"0.45\", \"size\":\"312.95\", \"side\":\"BUY\", \"hash\":\"9b3dca4bad4d5f1bde2ff13bd0a1e127524709f0\", \"best_bid\":\"0.45\", \"best_ask\":\"0.46\"}, {\"asset_id\":\"60386828328910021732068595344565885737045900010034836345809386672230885527307\", \"price\":\"0.55\", \"size\":\"312.95\", \"side\":\"SELL\", \"hash\":\"184d0cded9981ba929426e8a97f2effbb2f9dbfe\", \"best_bid\":\"0.54\", \"best_ask\":\"0.55\"}], \"timestamp\":\"1785126370397\", \"event_type\":\"price_change\"}","received_at":"2026-07-27T04:26:10.697887Z","schema_version":"clob-market-ws.price_change.v1","sequence":null,"server_hash":null,"server_timestamp":"1785126370397","session_id":"e9443c7415a0419799bee9cfbb1a9e4d","source":"clob_market_ws"},"received_at":"2026-07-27T04:26:10.697887Z","record_id":"ff77db4fa3978cbbf068246c814845eb00952eeb381cb520a6cadcb8709c8d47","schema_fingerprint":"4aa3821a28b0b7c2400bc59aba4bcc0a76e971dadd19610d3ad38c768e124dc7","schema_version":"edge-lab-recorder.raw.v1","sequence":null,"source":"clob_market_ws"}
{"event_at":"2026-07-27T04:26:10.398000Z","event_fingerprint":"c53c028f247ee42be44d6896397c311d9fc2f33a4cda13998511cf53cec01bf1","payload":{"connection_id":"0f4979d6978d463e9660b042fdcf555f","event_at":"2026-07-27T04:26:10.398000Z","event_type":"price_change","frame_hash":"2f8f5e229ed74e5c3f136f830b95932e8fbe94128f43494000f96065cde95da0","frame_index":0,"kind":"data","monotonic_ns":228353976101583,"payload":{"event_type":"price_change","market":"0xeb66215f2e9faa6449e30a02bab5b8ed7b79a38bf961f6b24d0073c9c2419250","price_changes":[{"asset_id":"69697746896130839564035629862476347944307040470122503199396727085502753297492","best_ask":"0.46","best_bid":"0.45","hash":"b9cfadc6fd26db10876b6bf9623087add23c34de","price":"0.45","side":"BUY","size":"317.95"},{"asset_id":"60386828328910021732068595344565885737045900010034836345809386672230885527307","best_ask":"0.55","best_bid":"0.54","hash":"fa3462f4314bdbdc4e3513ba131a823c93f5ed79","price":"0.55","side":"SELL","size":"317.95"}],"timestamp":"1785126370398"},"payload_hash":"cefbdf9a6c564ff899d93c55898e05a46d4cf27641f97c94220c167f2103e09a","raw_frame":"{\"market\":\"0xeb66215f2e9faa6449e30a02bab5b8ed7b79a38bf961f6b24d0073c9c2419250\", \"price_changes\":[{\"asset_id\":\"69697746896130839564035629862476347944307040470122503199396727085502753297492\", \"price\":\"0.45\", \"size\":\"317.95\", \"side\":\"BUY\", \"hash\":\"b9cfadc6fd26db10876b6bf9623087add23c34de\", \"best_bid\":\"0.45\", \"best_ask\":\"0.46\"}, {\"asset_id\":\"60386828328910021732068595344565885737045900010034836345809386672230885527307\", \"price\":\"0.55\", \"size\":\"317.95\", \"side\":\"SELL\", \"hash\":\"fa3462f4314bdbdc4e3513ba131a823c93f5ed79\", \"best_bid\":\"0.54\", \"best_ask\":\"0.55\"}], \"timestamp\":\"1785126370398\", \"event_type\":\"price_change\"}","received_at":"2026-07-27T04:26:10.704274Z","schema_version":"clob-market-ws.price_change.v1","sequence":null,"server_hash":null,"server_timestamp":"1785126370398","session_id":"e9443c7415a0419799bee9cfbb1a9e4d","source":"clob_market_ws"},"received_at":"2026-07-27T04:26:10.704274Z","record_id":"3eada2a58412830c9d639312059e7c168b0263122418b8fb521cddd5acafa785","schema_fingerprint":"4aa3821a28b0b7c2400bc59aba4bcc0a76e971dadd19610d3ad38c768e124dc7","schema_version":"edge-lab-recorder.raw.v1","sequence":null,"source":"clob_market_ws"}
{"event_at":"2026-07-27T04:26:10.399000Z","event_fingerprint":"143da831a30cc9ef2f2347f3477e930c3ce75777ef88741e8fdcd32113ed0157","payload":{"connection_id":"0f4979d6978d463e9660b042fdcf555f","event_at":"2026-07-27T04:26:10.399000Z","event_type":"price_change","frame_hash":"39c2892e973f2f7f2c07bbbde7596c6f116882f7fe1aec62894de641a4bdfd26","frame_index":0,"kind":"data","monotonic_ns":228353982572833,"payload":{"event_type":"price_change","market":"0xeb66215f2e9faa6449e30a02bab5b8ed7b79a38bf961f6b24d0073c9c2419250","price_changes":[{"asset_id":"69697746896130839564035629862476347944307040470122503199396727085502753297492","best_ask":"0.46","best_bid":"0.45","hash":"9ca95c563bcf2f89a7d9ca5fa1e234de244f342b","price":"0.45","side":"BUY","size":"322.95"},{"asset_id":"60386828328910021732068595344565885737045900010034836345809386672230885527307","best_ask":"0.55","best_bid":"0.54","hash":"7853bea27b2dcd78edd4db9c9030a595bea50b17","price":"0.55","side":"SELL","size":"322.95"}],"timestamp":"1785126370399"},"payload_hash":"ea69ca19156ab3b9ad61d5668ddeb41f705e9c160e451758bfd83d3031377daa","raw_frame":"{\"market\":\"0xeb66215f2e9faa6449e30a02bab5b8ed7b79a38bf961f6b24d0073c9c2419250\", \"price_changes\":[{\"asset_id\":\"69697746896130839564035629862476347944307040470122503199396727085502753297492\", \"price\":\"0.45\", \"size\":\"322.95\", \"side\":\"BUY\", \"hash\":\"9ca95c563bcf2f89a7d9ca5fa1e234de244f342b\", \"best_bid\":\"0.45\", \"best_ask\":\"0.46\"}, {\"asset_id\":\"60386828328910021732068595344565885737045900010034836345809386672230885527307\", \"price\":\"0.55\", \"size\":\"322.95\", \"side\":\"SELL\", \"hash\":\"7853bea27b2dcd78edd4db9c9030a595bea50b17\", \"best_bid\":\"0.54\", \"best_ask\":\"0.55\"}], \"timestamp\":\"1785126370399\", \"event_type\":\"price_change\"}","received_at":"2026-07-27T04:26:10.710747Z","schema_version":"clob-market-ws.price_change.v1","sequence":null,"server_hash":null,"server_timestamp":"1785126370399","session_id":"e9443c7415a0419799bee9cfbb1a9e4d","source":"clob_market_ws"},"received_at":"2026-07-27T04:26:10.710747Z","record_id":"d0e15cca06fb199399e277fdb5dd8946a630dd6e2b5c37bb2805d7e7465d49a4","schema_fingerprint":"4aa3821a28b0b7c2400bc59aba4bcc0a76e971dadd19610d3ad38c768e124dc7","schema_version":"edge-lab-recorder.raw.v1","sequence":null,"source":"clob_market_ws"}
{"event_at":"2026-07-27T04:26:10.400000Z","event_fingerprint":"3b0ccb21ef0fc966da6a6bc148a05151ac7c46dafbb11bc0b12e5d53ae9b8f1c","payload":{"connection_id":"0f4979d6978d463e9660b042fdcf555f","event_at":"2026-07-27T04:26:10.400000Z","event_type":"price_change","frame_hash":"8e718378a001f5bd76c06a4bfe669a815c28b61a5db3aae4fbf490efffd95ebd","frame_index":0,"kind":"data","monotonic_ns":228353989130583,"payload":{"event_type":"price_change","market":"0xeb66215f2e9faa6449e30a02bab5b8ed7b79a38bf961f6b24d0073c9c2419250","price_changes":[{"asset_id":"69697746896130839564035629862476347944307040470122503199396727085502753297492","best_ask":"0.46","best_bid":"0.45","hash":"313dfc4029cceb58bb8395a3a3df076b0ccf9c3a","price":"0.45","side":"BUY","size":"327.95"},{"asset_id":"60386828328910021732068595344565885737045900010034836345809386672230885527307","best_ask":"0.55","best_bid":"0.54","hash":"e76f6f21392b4c0dedbae4b891ea8b1831de0eb5","price":"0.55","side":"SELL","size":"327.95"}],"timestamp":"1785126370400"},"payload_hash":"2ad2af0065b6b3fb3bd4c53b761eeb7d1646dd021b69f6d491aa75716ca8d864","raw_frame":"{\"market\":\"0xeb66215f2e9faa6449e30a02bab5b8ed7b79a38bf961f6b24d0073c9c2419250\", \"price_changes\":[{\"asset_id\":\"69697746896130839564035629862476347944307040470122503199396727085502753297492\", \"price\":\"0.45\", \"size\":\"327.95\", \"side\":\"BUY\", \"hash\":\"313dfc4029cceb58bb8395a3a3df076b0ccf9c3a\", \"best_bid\":\"0.45\", \"best_ask\":\"0.46\"}, {\"asset_id\":\"60386828328910021732068595344565885737045900010034836345809386672230885527307\", \"price\":\"0.55\", \"size\":\"327.95\", \"side\":\"SELL\", \"hash\":\"e76f6f21392b4c0dedbae4b891ea8b1831de0eb5\", \"best_bid\":\"0.54\", \"best_ask\":\"0.55\"}], \"timestamp\":\"1785126370400\", \"event_type\":\"price_change\"}","received_at":"2026-07-27T04:26:10.717303Z","schema_version":"clob-market-ws.price_change.v1","sequence":null,"server_hash":null,"server_timestamp":"1785126370400","session_id":"e9443c7415a0419799bee9cfbb1a9e4d","source":"clob_market_ws"},"received_at":"2026-07-27T04:26:10.717303Z","record_id":"ef6333f2ecd52431cc83404a4fb370901b7ae125ef574696d7970ea9ce1c280e","schema_fingerprint":"4aa3821a28b0b7c2400bc59aba4bcc0a76e971dadd19610d3ad38c768e124dc7","schema_version":"edge-lab-recorder.raw.v1","sequence":null,"source":"clob_market_ws"}
{"event_at":"2026-07-27T04:26:10.400000Z","event_fingerprint":"65d137c662c577d336f775ec824018e27e765584e39ffb170c66ecadb379563f","payload":{"connection_id":"0f4979d6978d463e9660b042fdcf555f","event_at":"2026-07-27T04:26:10.400000Z","event_type":"price_change","frame_hash":"01ce1fe3ff475f98233682ed8d32b95ebfd4a1cc0890bace395a52ea40ea5383","frame_index":0,"kind":"data","monotonic_ns":228353994619125,"payload":{"event_type":"price_change","market":"0xeb66215f2e9faa6449e30a02bab5b8ed7b79a38bf961f6b24d0073c9c2419250","price_changes":[{"asset_id":"60386828328910021732068595344565885737045900010034836345809386672230885527307","best_ask":"0.55","best_bid":"0.54","hash":"815b9c3d26a37f091e80796c10234721474b8835","price":"0.51","side":"BUY","size":"155"},{"asset_id":"69697746896130839564035629862476347944307040470122503199396727085502753297492","best_ask":"0.46","best_bid":"0.45","hash":"be59aca22f41bb74ec00c7af64fded8d95606b44","price":"0.49","side":"SELL","size":"155"}],"timestamp":"1785126370400"},"payload_hash":"ff95811f15a109e887601d4a2747d39697dc517255e433da0208f9d667a910c7","raw_frame":"{\"market\":\"0xeb66215f2e9faa6449e30a02bab5b8ed7b79a38bf961f6b24d0073c9c2419250\", \"price_changes\":[{\"asset_id\":\"60386828328910021732068595344565885737045900010034836345809386672230885527307\", \"price\":\"0.51\", \"size\":\"155\", \"side\":\"BUY\", \"hash\":\"815b9c3d26a37f091e80796c10234721474b8835\", \"best_bid\":\"0.54\", \"best_ask\":\"0.55\"}, {\"asset_id\":\"69697746896130839564035629862476347944307040470122503199396727085502753297492\", \"price\":\"0.49\", \"size\":\"155\", \"side\":\"SELL\", \"hash\":\"be59aca22f41bb74ec00c7af64fded8d95606b44\", \"best_bid\":\"0.45\", \"best_ask\":\"0.46\"}], \"timestamp\":\"1785126370400\", \"event_type\":\"price_change\"}","received_at":"2026-07-27T04:26:10.722793Z","schema_version":"clob-market-ws.price_change.v1","sequence":null,"server_hash":null,"server_timestamp":"1785126370400","session_id":"e9443c7415a0419799bee9cfbb1a9e4d","source":"clob_market_ws"},"received_at":"2026-07-27T04:26:10.722793Z","record_id":"485d6cca138a20a92e9e5aa9fb3953df8631326ab04659aed8b9164dc7e2e372","schema_fingerprint":"4aa3821a28b0b7c2400bc59aba4bcc0a76e971dadd19610d3ad38c768e124dc7","schema_version":"edge-lab-recorder.raw.v1","sequence":null,"source":"clob_market_ws"}
{"event_at":"2026-07-27T04:26:10.401000Z","event_fingerprint":"b5b5609935510a06378c5d0f4a1236ca651f96791acba37ea52f99a7ddb5770b","payload":{"connection_id":"0f4979d6978d463e9660b042fdcf555f","event_at":"2026-07-27T04:26:10.401000Z","event_type":"price_change","frame_hash":"9055c02d4cd45bb2e5b29f399187c5742cf3c4fe051cd3002400da1f64d13443","frame_index":0,"kind":"data","monotonic_ns":228354002375041,"payload":{"event_type":"price_change","market":"0xeb66215f2e9faa6449e30a02bab5b8ed7b79a38bf961f6b24d0073c9c2419250","price_changes":[{"asset_id":"69697746896130839564035629862476347944307040470122503199396727085502753297492","best_ask":"0.46","best_bid":"0.45","hash":"77d9f08dddb80e3829d03edeb65bec3f941f878a","price":"0.45","side":"BUY","size":"332.95"},{"asset_id":"60386828328910021732068595344565885737045900010034836345809386672230885527307","best_ask":"0.55","best_bid":"0.54","hash":"b852f9ca9bdb0f681b895ada75b1532aba6597c0","price":"0.55","side":"SELL","size":"332.95"}],"timestamp":"1785126370401"},"payload_hash":"ec9539bc7ba7f0204356665cb717d0bd5d909516a8b0b16d060e964a2c51b34f","raw_frame":"{\"market\":\"0xeb66215f2e9faa6449e30a02bab5b8ed7b79a38bf961f6b24d0073c9c2419250\", \"price_changes\":[{\"asset_id\":\"69697746896130839564035629862476347944307040470122503199396727085502753297492\", \"price\":\"0.45\", \"size\":\"332.95\", \"side\":\"BUY\", \"hash\":\"77d9f08dddb80e3829d03edeb65bec3f941f878a\", \"best_bid\":\"0.45\", \"best_ask\":\"0.46\"}, {\"asset_id\":\"60386828328910021732068595344565885737045900010034836345809386672230885527307\", \"price\":\"0.55\", \"size\":\"332.95\", \"side\":\"SELL\", \"hash\":\"b852f9ca9bdb0f681b895ada75b1532aba6597c0\", \"best_bid\":\"0.54\", \"best_ask\":\"0.55\"}], \"timestamp\":\"1785126370401\", \"event_type\":\"price_change\"}","received_at":"2026-07-27T04:26:10.730549Z","schema_version":"clob-market-ws.price_change.v1","sequence":null,"server_hash":null,"server_timestamp":"1785126370401","session_id":"e9443c7415a0419799bee9cfbb1a9e4d","source":"clob_market_ws"},"received_at":"2026-07-27T04:26:10.730549Z","record_id":"65a2e100ec509fb8698552e16958efae8d3a691b5ccb0abb7748015a8faad13e","schema_fingerprint":"4aa3821a28b0b7c2400bc59aba4bcc0a76e971dadd19610d3ad38c768e124dc7","schema_version":"edge-lab-recorder.raw.v1","sequence":null,"source":"clob_market_ws"}
{"event_at":"2026-07-27T04:26:10.402000Z","event_fingerprint":"bb7835ddbacd03117d15109ede798b1bac78b504d0a1bdadaa57f18326c7dc0a","payload":{"connection_id":"0f4979d6978d463e9660b042fdcf555f","event_at":"2026-07-27T04:26:10.402000Z","event_type":"price_change","frame_hash":"23537d3dc12e6231c33dcf225baef8a0033cad55b4e8c0a7688001ea359b25ca","frame_index":0,"kind":"data","monotonic_ns":228354010421875,"payload":{"event_type":"price_change","market":"0xeb66215f2e9faa6449e30a02bab5b8ed7b79a38bf961f6b24d0073c9c2419250","price_changes":[{"asset_id":"60386828328910021732068595344565885737045900010034836345809386672230885527307","best_ask":"0.55","best_bid":"0.54","hash":"51fdab77e855381416a0be0586283f4ae13be329","price":"0.51","side":"BUY","size":"160"},{"asset_id":"69697746896130839564035629862476347944307040470122503199396727085502753297492","best_ask":"0.46","best_bid":"0.45","hash":"41cdd72838f1f247ebf7558a6b2cb3a0adbd311e","price":"0.49","side":"SELL","size":"160"}],"timestamp":"1785126370402"},"payload_hash":"4404557364dcad0f32034ad291eecdbdf7803ddc2d03c6605ec593e0c1e79cb4","raw_frame":"{\"market\":\"0xeb66215f2e9faa6449e30a02bab5b8ed7b79a38bf961f6b24d0073c9c2419250\", \"price_changes\":[{\"asset_id\":\"60386828328910021732068595344565885737045900010034836345809386672230885527307\", \"price\":\"0.51\", \"size\":\"160\", \"side\":\"BUY\", \"hash\":\"51fdab77e855381416a0be0586283f4ae13be329\", \"best_bid\":\"0.54\", \"best_ask\":\"0.55\"}, {\"asset_id\":\"69697746896130839564035629862476347944307040470122503199396727085502753297492\", \"price\":\"0.49\", \"size\":\"160\", \"side\":\"SELL\", \"hash\":\"41cdd72838f1f247ebf7558a6b2cb3a0adbd311e\", \"best_bid\":\"0.45\", \"best_ask\":\"0.46\"}], \"timestamp\":\"1785126370402\", \"event_type\":\"price_change\"}","received_at":"2026-07-27T04:26:10.738595Z","schema_version":"clob-market-ws.price_change.v1","sequence":null,"server_hash":null,"server_timestamp":"1785126370402","session_id":"e9443c7415a0419799bee9cfbb1a9e4d","source":"clob_market_ws"},"received_at":"2026-07-27T04:26:10.738595Z","record_id":"f2f355de9181fbab55e45a9bf70e379fbeee78349b049e739487fdaec4d7996a","schema_fingerprint":"4aa3821a28b0b7c2400bc59aba4bcc0a76e971dadd19610d3ad38c768e124dc7","schema_version":"edge-lab-recorder.raw.v1","sequence":null,"source":"clob_market_ws"}
{"event_at":"2026-07-27T04:26:10.402000Z","event_fingerprint":"08aeb2eeb8eeac52cd2a2b4249a88744872973ab058bf73da37f18904cc4fb8b","payload":{"connection_id":"0f4979d6978d463e9660b042fdcf555f","event_at":"2026-07-27T04:26:10.402000Z","event_type":"price_change","frame_hash":"46ddd39b3d2b13ef14f142b3ba3808c4c0ae0c96c7bb8a59984dfd2f45950c56","frame_index":0,"kind":"data","monotonic_ns":228354015679583,"payload":{"event_type":"price_change","market":"0xeb66215f2e9faa6449e30a02bab5b8ed7b79a38bf961f6b24d0073c9c2419250","price_changes":[{"asset_id":"69697746896130839564035629862476347944307040470122503199396727085502753297492","best_ask":"0.46","best_bid":"0.45","hash":"056224c884d8c680c3cc12d136acdf6e1e406937","price":"0.45","side":"BUY","size":"337.95"},{"asset_id":"60386828328910021732068595344565885737045900010034836345809386672230885527307","best_ask":"0.55","best_bid":"0.54","hash":"6f071a7956aa594e83d10126a61e48051a3f4041","price":"0.55","side":"SELL","size":"337.95"}],"timestamp":"1785126370402"},"payload_hash":"cb69059d0165ddf359d87d3ee8ecdd7ef7d98c67a7f03e4579d0ad63d1f5918d","raw_frame":"{\"market\":\"0xeb66215f2e9faa6449e30a02bab5b8ed7b79a38bf961f6b24d0073c9c2419250\", \"price_changes\":[{\"asset_id\":\"69697746896130839564035629862476347944307040470122503199396727085502753297492\", \"price\":\"0.45\", \"size\":\"337.95\", \"side\":\"BUY\", \"hash\":\"056224c884d8c680c3cc12d136acdf6e1e406937\", \"best_bid\":\"0.45\", \"best_ask\":\"0.46\"}, {\"asset_id\":\"60386828328910021732068595344565885737045900010034836345809386672230885527307\", \"price\":\"0.55\", \"size\":\"337.95\", \"side\":\"SELL\", \"hash\":\"6f071a7956aa594e83d10126a61e48051a3f4041\", \"best_bid\":\"0.54\", \"best_ask\":\"0.55\"}], \"timestamp\":\"1785126370402\", \"event_type\":\"price_change\"}","received_at":"2026-07-27T04:26:10.743854Z","schema_version":"clob-market-ws.price_change.v1","sequence":null,"server_hash":null,"server_timestamp":"1785126370402","session_id":"e9443c7415a0419799bee9cfbb1a9e4d","source":"clob_market_ws"},"received_at":"2026-07-27T04:26:10.743854Z","record_id":"04bb8ef05cb48e7122672c542b02dab5eb39797d00f1775ba067bf4f8b3bdcc8","schema_fingerprint":"4aa3821a28b0b7c2400bc59aba4bcc0a76e971dadd19610d3ad38c768e124dc7","schema_version":"edge-lab-recorder.raw.v1","sequence":null,"source":"clob_market_ws"}
{"event_at":"2026-07-27T04:26:10.403000Z","event_fingerprint":"14edfb75a649601b9f846e0fd7a78b9937d150b729b35435b66751c24356c741","payload":{"connection_id":"0f4979d6978d463e9660b042fdcf555f","event_at":"2026-07-27T04:26:10.403000Z","event_type":"price_change","frame_hash":"3dbfc5f44f96c02e860a558bb5f143ad5efd99fe4d457ac1c9dd8f7ea7528836","frame_index":0,"kind":"data","monotonic_ns":228354021206666,"payload":{"event_type":"price_change","market":"0xeb66215f2e9faa6449e30a02bab5b8ed7b79a38bf961f6b24d0073c9c2419250","price_changes":[{"asset_id":"60386828328910021732068595344565885737045900010034836345809386672230885527307","best_ask":"0.55","best_bid":"0.54","hash":"8db9453ccca532eba003fd4d5b870673207bdb72","price":"0.51","side":"BUY","size":"165"},{"asset_id":"69697746896130839564035629862476347944307040470122503199396727085502753297492","best_ask":"0.46","best_bid":"0.45","hash":"a10633dd2ca27e7704958c3c9dd852dcdce47b07","price":"0.49","side":"SELL","size":"165"}],"timestamp":"1785126370403"},"payload_hash":"7c71a49d02b6172541c195c3f5c36e292b0d7613a1b5a42edcf4cc0d74bc94c2","raw_frame":"{\"market\":\"0xeb66215f2e9faa6449e30a02bab5b8ed7b79a38bf961f6b24d0073c9c2419250\", \"price_changes\":[{\"asset_id\":\"60386828328910021732068595344565885737045900010034836345809386672230885527307\", \"price\":\"0.51\", \"size\":\"165\", \"side\":\"BUY\", \"hash\":\"8db9453ccca532eba003fd4d5b870673207bdb72\", \"best_bid\":\"0.54\", \"best_ask\":\"0.55\"}, {\"asset_id\":\"69697746896130839564035629862476347944307040470122503199396727085502753297492\", \"price\":\"0.49\", \"size\":\"165\", \"side\":\"SELL\", \"hash\":\"a10633dd2ca27e7704958c3c9dd852dcdce47b07\", \"best_bid\":\"0.45\", \"best_ask\":\"0.46\"}], \"timestamp\":\"1785126370403\", \"event_type\":\"price_change\"}","received_at":"2026-07-27T04:26:10.749377Z","schema_version":"clob-market-ws.price_change.v1","sequence":null,"server_hash":null,"server_timestamp":"1785126370403","session_id":"e9443c7415a0419799bee9cfbb1a9e4d","source":"clob_market_ws"},"received_at":"2026-07-27T04:26:10.749377Z","record_id":"bb2d99a9813624dfe2d22dc2bc93c12621976e050b2ace378314323daddcffd0","schema_fingerprint":"4aa3821a28b0b7c2400bc59aba4bcc0a76e971dadd19610d3ad38c768e124dc7","schema_version":"edge-lab-recorder.raw.v1","sequence":null,"source":"clob_market_ws"}
{"event_at":"2026-07-27T04:26:10.404000Z","event_fingerprint":"23af47b3159c53ba0a09ae94f17ca1669c933842a516a2b0b42f5229c2135b35","payload":{"connection_id":"0f4979d6978d463e9660b042fdcf555f","event_at":"2026-07-27T04:26:10.404000Z","event_type":"price_change","frame_hash":"8dae03b3e30c1e65e38e43fdc93b22b9150e95818c0ade21fc26297d88e0c4fc","frame_index":0,"kind":"data","monotonic_ns":228354030281541,"payload":{"event_type":"price_change","market":"0xeb66215f2e9faa6449e30a02bab5b8ed7b79a38bf961f6b24d0073c9c2419250","price_changes":[{"asset_id":"69697746896130839564035629862476347944307040470122503199396727085502753297492","best_ask":"0.46","best_bid":"0.45","hash":"b36b6e1981dae423adaa50b787bab5a2af328bd2","price":"0.45","side":"BUY","size":"342.95"},{"asset_id":"60386828328910021732068595344565885737045900010034836345809386672230885527307","best_ask":"0.55","best_bid":"0.54","hash":"013d6ccd3007da36fd1acb0e075c8667252da3bf","price":"0.55","side":"SELL","size":"342.95"}],"timestamp":"1785126370404"},"payload_hash":"ff4b4605481ec42d4fdcaafaabc071e3a00cf7d3888c1b7e96611f9f51d28138","raw_frame":"{\"market\":\"0xeb66215f2e9faa6449e30a02bab5b8ed7b79a38bf961f6b24d0073c9c2419250\", \"price_changes\":[{\"asset_id\":\"69697746896130839564035629862476347944307040470122503199396727085502753297492\", \"price\":\"0.45\", \"size\":\"342.95\", \"side\":\"BUY\", \"hash\":\"b36b6e1981dae423adaa50b787bab5a2af328bd2\", \"best_bid\":\"0.45\", \"best_ask\":\"0.46\"}, {\"asset_id\":\"60386828328910021732068595344565885737045900010034836345809386672230885527307\", \"price\":\"0.55\", \"size\":\"342.95\", \"side\":\"SELL\", \"hash\":\"013d6ccd3007da36fd1acb0e075c8667252da3bf\", \"best_bid\":\"0.54\", \"best_ask\":\"0.55\"}], \"timestamp\":\"1785126370404\", \"event_type\":\"price_change\"}","received_at":"2026-07-27T04:26:10.758455Z","schema_version":"clob-market-ws.price_change.v1","sequence":null,"server_hash":null,"server_timestamp":"1785126370404","session_id":"e9443c7415a0419799bee9cfbb1a9e4d","source":"clob_market_ws"},"received_at":"2026-07-27T04:26:10.758455Z","record_id":"3ef99a66633e07f2dd88c51061e1d5ab1e742e7254b4bbd6ea9a2cd3a689b161","schema_fingerprint":"4aa3821a28b0b7c2400bc59aba4bcc0a76e971dadd19610d3ad38c768e124dc7","schema_version":"edge-lab-recorder.raw.v1","sequence":null,"source":"clob_market_ws"}
{"event_at":"2026-07-27T04:26:10.405000Z","event_fingerprint":"1742277c9516e36c4d2428577f248ec37c97e8a8c4fb20150054f808418440b1","payload":{"connection_id":"0f4979d6978d463e9660b042fdcf555f","event_at":"2026-07-27T04:26:10.405000Z","event_type":"price_change","frame_hash":"11f0a3b07ab306b3a7e99c1815992511a08188d10020ea9b7bdcda67d652e656","frame_index":0,"kind":"data","monotonic_ns":228354041188041,"payload":{"event_type":"price_change","market":"0xeb66215f2e9faa6449e30a02bab5b8ed7b79a38bf961f6b24d0073c9c2419250","price_changes":[{"asset_id":"60386828328910021732068595344565885737045900010034836345809386672230885527307","best_ask":"0.55","best_bid":"0.54","hash":"4e16650ff9475b82c3f3f89d502153d0be82156f","price":"0.51","side":"BUY","size":"170"},{"asset_id":"69697746896130839564035629862476347944307040470122503199396727085502753297492","best_ask":"0.46","best_bid":"0.45","hash":"388287c49b116b06bc741b67cc6d3d2cde088293","price":"0.49","side":"SELL","size":"170"}],"timestamp":"1785126370405"},"payload_hash":"d97e7000b7b88b924a3942dff20a04e8e8cfa8204447fde6bea668bfb857ce65","raw_frame":"{\"market\":\"0xeb66215f2e9faa6449e30a02bab5b8ed7b79a38bf961f6b24d0073c9c2419250\", \"price_changes\":[{\"asset_id\":\"60386828328910021732068595344565885737045900010034836345809386672230885527307\", \"price\":\"0.51\", \"size\":\"170\", \"side\":\"BUY\", \"hash\":\"4e16650ff9475b82c3f3f89d502153d0be82156f\", \"best_bid\":\"0.54\", \"best_ask\":\"0.55\"}, {\"asset_id\":\"69697746896130839564035629862476347944307040470122503199396727085502753297492\", \"price\":\"0.49\", \"size\":\"170\", \"side\":\"SELL\", \"hash\":\"388287c49b116b06bc741b67cc6d3d2cde088293\", \"best_bid\":\"0.45\", \"best_ask\":\"0.46\"}], \"timestamp\":\"1785126370405\", \"event_type\":\"price_change\"}","received_at":"2026-07-27T04:26:10.769361Z","schema_version":"clob-market-ws.price_change.v1","sequence":null,"server_hash":null,"server_timestamp":"1785126370405","session_id":"e9443c7415a0419799bee9cfbb1a9e4d","source":"clob_market_ws"},"received_at":"2026-07-27T04:26:10.769361Z","record_id":"52ad793c29ad71ed8b9143b0a752d33f229675acfff45c6d7a7b30470a307aad","schema_fingerprint":"4aa3821a28b0b7c2400bc59aba4bcc0a76e971dadd19610d3ad38c768e124dc7","schema_version":"edge-lab-recorder.raw.v1","sequence":null,"source":"clob_market_ws"}
{"event_at":"2026-07-27T04:26:10.405000Z","event_fingerprint":"201b07d43ed3208b1594a707de64836b496199843d7fd6758f5bbc78aa2b15fd","payload":{"connection_id":"0f4979d6978d463e9660b042fdcf555f","event_at":"2026-07-27T04:26:10.405000Z","event_type":"price_change","frame_hash":"1d84f4a4eaf6ea0b5f342d197331322421051387b040424b37c2171107d93319","frame_index":0,"kind":"data","monotonic_ns":228354048649166,"payload":{"event_type":"price_change","market":"0xeb66215f2e9faa6449e30a02bab5b8ed7b79a38bf961f6b24d0073c9c2419250","price_changes":[{"asset_id":"69697746896130839564035629862476347944307040470122503199396727085502753297492","best_ask":"0.46","best_bid":"0.45","hash":"9feec4c22d677dcfe562539e4b7588732ce5bf54","price":"0.45","side":"BUY","size":"347.95"},{"asset_id":"60386828328910021732068595344565885737045900010034836345809386672230885527307","best_ask":"0.55","best_bid":"0.54","hash":"42ed65bbd33021d094168f50c2be4fabfcc356a1","price":"0.55","side":"SELL","size":"347.95"}],"timestamp":"1785126370405"},"payload_hash":"7fa666508e08a2dd48e9b29582b6c1d42dd6ac43095f9ecc49e5ced59914d1cb","raw_frame":"{\"market\":\"0xeb66215f2e9faa6449e30a02bab5b8ed7b79a38bf961f6b24d0073c9c2419250\", \"price_changes\":[{\"asset_id\":\"69697746896130839564035629862476347944307040470122503199396727085502753297492\", \"price\":\"0.45\", \"size\":\"347.95\", \"side\":\"BUY\", \"hash\":\"9feec4c22d677dcfe562539e4b7588732ce5bf54\", \"best_bid\":\"0.45\", \"best_ask\":\"0.46\"}, {\"asset_id\":\"60386828328910021732068595344565885737045900010034836345809386672230885527307\", \"price\":\"0.55\", \"size\":\"347.95\", \"side\":\"SELL\", \"hash\":\"42ed65bbd33021d094168f50c2be4fabfcc356a1\", \"best_bid\":\"0.54\", \"best_ask\":\"0.55\"}], \"timestamp\":\"1785126370405\", \"event_type\":\"price_change\"}","received_at":"2026-07-27T04:26:10.776823Z","schema_version":"clob-market-ws.price_change.v1","sequence":null,"server_hash":null,"server_timestamp":"1785126370405","session_id":"e9443c7415a0419799bee9cfbb1a9e4d","source":"clob_market_ws"},"received_at":"2026-07-27T04:26:10.776823Z","record_id":"08c976c6c4e1675b9c5efe32df4f33c7f16ede5fbad55650ae1e9b87735b8533","schema_fingerprint":"4aa3821a28b0b7c2400bc59aba4bcc0a76e971dadd19610d3ad38c768e124dc7","schema_version":"edge-lab-recorder.raw.v1","sequence":null,"source":"clob_market_ws"}
{"event_at":"2026-07-27T04:26:10.406000Z","event_fingerprint":"fdf0f0b54273763e156df47bfef1066fa92a68f78742ea9d21f9692aa832d11a","payload":{"connection_id":"0f4979d6978d463e9660b042fdcf555f","event_at":"2026-07-27T04:26:10.406000Z","event_type":"price_change","frame_hash":"32fb6fe9cbcb8745de32d34d06822f2621e84002eadc21ee91e7669dbdf2345c","frame_index":0,"kind":"data","monotonic_ns":228354058339041,"payload":{"event_type":"price_change","market":"0xeb66215f2e9faa6449e30a02bab5b8ed7b79a38bf961f6b24d0073c9c2419250","price_changes":[{"asset_id":"60386828328910021732068595344565885737045900010034836345809386672230885527307","best_ask":"0.55","best_bid":"0.54","hash":"74ef42bceef560ce9f272fc8014edb5312480649","price":"0.51","side":"BUY","size":"175"},{"asset_id":"69697746896130839564035629862476347944307040470122503199396727085502753297492","best_ask":"0.46","best_bid":"0.45","hash":"69720017961fa010da170698f2dc8931e430c175","price":"0.49","side":"SELL","size":"175"}],"timestamp":"1785126370406"},"payload_hash":"2fb64e393ead7b73a0ece21bc2aee4fd03d0126fe6d91225182198fefcf10603","raw_frame":"{\"market\":\"0xeb66215f2e9faa6449e30a02bab5b8ed7b79a38bf961f6b24d0073c9c2419250\", \"price_changes\":[{\"asset_id\":\"60386828328910021732068595344565885737045900010034836345809386672230885527307\", \"price\":\"0.51\", \"size\":\"175\", \"side\":\"BUY\", \"hash\":\"74ef42bceef560ce9f272fc8014edb5312480649\", \"best_bid\":\"0.54\", \"best_ask\":\"0.55\"}, {\"asset_id\":\"69697746896130839564035629862476347944307040470122503199396727085502753297492\", \"price\":\"0.49\", \"size\":\"175\", \"side\":\"SELL\", \"hash\":\"69720017961fa010da170698f2dc8931e430c175\", \"best_bid\":\"0.45\", \"best_ask\":\"0.46\"}], \"timestamp\":\"1785126370406\", \"event_type\":\"price_change\"}","received_at":"2026-07-27T04:26:10.786512Z","schema_version":"clob-market-ws.price_change.v1","sequence":null,"server_hash":null,"server_timestamp":"1785126370406","session_id":"e9443c7415a0419799bee9cfbb1a9e4d","source":"clob_market_ws"},"received_at":"2026-07-27T04:26:10.786512Z","record_id":"cf1930ff4e396b518ab8e382ac4b40497f25378abaaeb298c042eba7f402515c","schema_fingerprint":"4aa3821a28b0b7c2400bc59aba4bcc0a76e971dadd19610d3ad38c768e124dc7","schema_version":"edge-lab-recorder.raw.v1","sequence":null,"source":"clob_market_ws"}
{"event_at":"2026-07-27T04:26:10.407000Z","event_fingerprint":"22c49cffc81a9b6fb47ec68897f641b95194a71b1730b1cdaa886bd054d0fc31","payload":{"connection_id":"0f4979d6978d463e9660b042fdcf555f","event_at":"2026-07-27T04:26:10.407000Z","event_type":"price_change","frame_hash":"c5c1f704748941dacfa1f0daa82c9e6610b212d19bd7ae15219bfbe78d448ae5","frame_index":0,"kind":"data","monotonic_ns":228354063669291,"payload":{"event_type":"price_change","market":"0xeb66215f2e9faa6449e30a02bab5b8ed7b79a38bf961f6b24d0073c9c2419250","price_changes":[{"asset_id":"69697746896130839564035629862476347944307040470122503199396727085502753297492","best_ask":"0.46","best_bid":"0.45","hash":"65185b3eab6f4eea7fc7c8edf724665163be5d4c","price":"0.45","side":"BUY","size":"352.95"},{"asset_id":"60386828328910021732068595344565885737045900010034836345809386672230885527307","best_ask":"0.55","best_bid":"0.54","hash":"c41cc74a51cd34552a65492c8f400b0da1194c6a","price":"0.55","side":"SELL","size":"352.95"}],"timestamp":"1785126370407"},"payload_hash":"d76b3a4e475f11501736fa5288ff26cf8c7db3e6fc230a32cfd0bb897b181d70","raw_frame":"{\"market\":\"0xeb66215f2e9faa6449e30a02bab5b8ed7b79a38bf961f6b24d0073c9c2419250\", \"price_changes\":[{\"asset_id\":\"69697746896130839564035629862476347944307040470122503199396727085502753297492\", \"price\":\"0.45\", \"size\":\"352.95\", \"side\":\"BUY\", \"hash\":\"65185b3eab6f4eea7fc7c8edf724665163be5d4c\", \"best_bid\":\"0.45\", \"best_ask\":\"0.46\"}, {\"asset_id\":\"60386828328910021732068595344565885737045900010034836345809386672230885527307\", \"price\":\"0.55\", \"size\":\"352.95\", \"side\":\"SELL\", \"hash\":\"c41cc74a51cd34552a65492c8f400b0da1194c6a\", \"best_bid\":\"0.54\", \"best_ask\":\"0.55\"}], \"timestamp\":\"1785126370407\", \"event_type\":\"price_change\"}","received_at":"2026-07-27T04:26:10.791844Z","schema_version":"clob-market-ws.price_change.v1","sequence":null,"server_hash":null,"server_timestamp":"1785126370407","session_id":"e9443c7415a0419799bee9cfbb1a9e4d","source":"clob_market_ws"},"received_at":"2026-07-27T04:26:10.791844Z","record_id":"c5b8e68091d5ba7fd48da7eb13fbeb4de889f3bc13d301b9af03cdc28da905bd","schema_fingerprint":"4aa3821a28b0b7c2400bc59aba4bcc0a76e971dadd19610d3ad38c768e124dc7","schema_version":"edge-lab-recorder.raw.v1","sequence":null,"source":"clob_market_ws"}
{"event_at":"2026-07-27T04:26:10.407000Z","event_fingerprint":"fc14de05adde50cf7df13ab81052a69a0fd46f2fbc03e471527c60f3ca3f23b6","payload":{"connection_id":"0f4979d6978d463e9660b042fdcf555f","event_at":"2026-07-27T04:26:10.407000Z","event_type":"price_change","frame_hash":"6dc46c2eac2231a1aa07b2d4d5a5fced045b74de28186b04c83114b99ab0c700","frame_index":0,"kind":"data","monotonic_ns":228354071811541,"payload":{"event_type":"price_change","market":"0xeb66215f2e9faa6449e30a02bab5b8ed7b79a38bf961f6b24d0073c9c2419250","price_changes":[{"asset_id":"60386828328910021732068595344565885737045900010034836345809386672230885527307","best_ask":"0.55","best_bid":"0.54","hash":"636a151a2bff25680ef9646877ed69901aab7598","price":"0.51","side":"BUY","size":"180"},{"asset_id":"69697746896130839564035629862476347944307040470122503199396727085502753297492","best_ask":"0.46","best_bid":"0.45","hash":"67d632ab66836fc347842e44510c31639e05c994","price":"0.49","side":"SELL","size":"180"}],"timestamp":"1785126370407"},"payload_hash":"2431d0831f2b67f0e1a673139438749a72053803d7a8eb666c74d1095ed39b5f","raw_frame":"{\"market\":\"0xeb66215f2e9faa6449e30a02bab5b8ed7b79a38bf961f6b24d0073c9c2419250\", \"price_changes\":[{\"asset_id\":\"60386828328910021732068595344565885737045900010034836345809386672230885527307\", \"price\":\"0.51\", \"size\":\"180\", \"side\":\"BUY\", \"hash\":\"636a151a2bff25680ef9646877ed69901aab7598\", \"best_bid\":\"0.54\", \"best_ask\":\"0.55\"}, {\"asset_id\":\"69697746896130839564035629862476347944307040470122503199396727085502753297492\", \"price\":\"0.49\", \"size\":\"180\", \"side\":\"SELL\", \"hash\":\"67d632ab66836fc347842e44510c31639e05c994\", \"best_bid\":\"0.45\", \"best_ask\":\"0.46\"}], \"timestamp\":\"1785126370407\", \"event_type\":\"price_change\"}","received_at":"2026-07-27T04:26:10.799982Z","schema_version":"clob-market-ws.price_change.v1","sequence":null,"server_hash":null,"server_timestamp":"1785126370407","session_id":"e9443c7415a0419799bee9cfbb1a9e4d","source":"clob_market_ws"},"received_at":"2026-07-27T04:26:10.799982Z","record_id":"a485eb6b2563db26ee636d3d67a57e628edf1b6dbeb29e4e517b74aeecf86672","schema_fingerprint":"4aa3821a28b0b7c2400bc59aba4bcc0a76e971dadd19610d3ad38c768e124dc7","schema_version":"edge-lab-recorder.raw.v1","sequence":null,"source":"clob_market_ws"}
{"event_at":"2026-07-27T04:26:10.408000Z","event_fingerprint":"58c00966b6f26b0af5aa6d057df0d9ebad463f879b022cb8dc15b47a61e25f65","payload":{"connection_id":"0f4979d6978d463e9660b042fdcf555f","event_at":"2026-07-27T04:26:10.408000Z","event_type":"price_change","frame_hash":"82fa2eb4e38beffec76f7d9ed4d0fe3b09955fa37db0cf90d97ac35cd32d6729","frame_index":0,"kind":"data","monotonic_ns":228354081101083,"payload":{"event_type":"price_change","market":"0xeb66215f2e9faa6449e30a02bab5b8ed7b79a38bf961f6b24d0073c9c2419250","price_changes":[{"asset_id":"69697746896130839564035629862476347944307040470122503199396727085502753297492","best_ask":"0.46","best_bid":"0.45","hash":"a5194b67a6cd24168f9c123ac0e0264c98ca36d5","price":"0.45","side":"BUY","size":"357.95"},{"asset_id":"60386828328910021732068595344565885737045900010034836345809386672230885527307","best_ask":"0.55","best_bid":"0.54","hash":"511f4c5d0f4d61cae0f93341b667a68bb83f36d7","price":"0.55","side":"SELL","size":"357.95"}],"timestamp":"1785126370408"},"payload_hash":"d138426d2ee1cbc79c9a0c64b381d46550a672934e4c917e5125bc11aa70d2f6","raw_frame":"{\"market\":\"0xeb66215f2e9faa6449e30a02bab5b8ed7b79a38bf961f6b24d0073c9c2419250\", \"price_changes\":[{\"asset_id\":\"69697746896130839564035629862476347944307040470122503199396727085502753297492\", \"price\":\"0.45\", \"size\":\"357.95\", \"side\":\"BUY\", \"hash\":\"a5194b67a6cd24168f9c123ac0e0264c98ca36d5\", \"best_bid\":\"0.45\", \"best_ask\":\"0.46\"}, {\"asset_id\":\"60386828328910021732068595344565885737045900010034836345809386672230885527307\", \"price\":\"0.55\", \"size\":\"357.95\", \"side\":\"SELL\", \"hash\":\"511f4c5d0f4d61cae0f93341b667a68bb83f36d7\", \"best_bid\":\"0.54\", \"best_ask\":\"0.55\"}], \"timestamp\":\"1785126370408\", \"event_type\":\"price_change\"}","received_at":"2026-07-27T04:26:10.809276Z","schema_version":"clob-market-ws.price_change.v1","sequence":null,"server_hash":null,"server_timestamp":"1785126370408","session_id":"e9443c7415a0419799bee9cfbb1a9e4d","source":"clob_market_ws"},"received_at":"2026-07-27T04:26:10.809276Z","record_id":"57547cf1e194d03dcdbb7883f8419414f2bdc9e17dec354a1efc12fd4122ef2b","schema_fingerprint":"4aa3821a28b0b7c2400bc59aba4bcc0a76e971dadd19610d3ad38c768e124dc7","schema_version":"edge-lab-recorder.raw.v1","sequence":null,"source":"clob_market_ws"}
{"event_at":"2026-07-27T04:26:10.409000Z","event_fingerprint":"3e14aca95c89fa5c831777edea50fafed0c84f745a03cbd30458909816b7a7ba","payload":{"connection_id":"0f4979d6978d463e9660b042fdcf555f","event_at":"2026-07-27T04:26:10.409000Z","event_type":"price_change","frame_hash":"dd3f23308f7fbb0a3974d33b5f328703614e4fc0365e8efed71bd91d9ccdc6c6","frame_index":0,"kind":"data","monotonic_ns":228354088257041,"payload":{"event_type":"price_change","market":"0xeb66215f2e9faa6449e30a02bab5b8ed7b79a38bf961f6b24d0073c9c2419250","price_changes":[{"asset_id":"60386828328910021732068595344565885737045900010034836345809386672230885527307","best_ask":"0.55","best_bid":"0.54","hash":"673060b066e7257611055487832b88920222168d","price":"0.51","side":"BUY","size":"185"},{"asset_id":"69697746896130839564035629862476347944307040470122503199396727085502753297492","best_ask":"0.46","best_bid":"0.45","hash":"0bd58f6777a99ce9e8cf6df5e527dc2926d23ed5","price":"0.49","side":"SELL","size":"185"}],"timestamp":"1785126370409"},"payload_hash":"8f00b03ea2c14a02c39f423b441e73d7bfeba885b05841ac091aa555ae2eb3f1","raw_frame":"{\"market\":\"0xeb66215f2e9faa6449e30a02bab5b8ed7b79a38bf961f6b24d0073c9c2419250\", \"price_changes\":[{\"asset_id\":\"60386828328910021732068595344565885737045900010034836345809386672230885527307\", \"price\":\"0.51\", \"size\":\"185\", \"side\":\"BUY\", \"hash\":\"673060b066e7257611055487832b88920222168d\", \"best_bid\":\"0.54\", \"best_ask\":\"0.55\"}, {\"asset_id\":\"69697746896130839564035629862476347944307040470122503199396727085502753297492\", \"price\":\"0.49\", \"size\":\"185\", \"side\":\"SELL\", \"hash\":\"0bd58f6777a99ce9e8cf6df5e527dc2926d23ed5\", \"best_bid\":\"0.45\", \"best_ask\":\"0.46\"}], \"timestamp\":\"1785126370409\", \"event_type\":\"price_change\"}","received_at":"2026-07-27T04:26:10.816430Z","schema_version":"clob-market-ws.price_change.v1","sequence":null,"server_hash":null,"server_timestamp":"1785126370409","session_id":"e9443c7415a0419799bee9cfbb1a9e4d","source":"clob_market_ws"},"received_at":"2026-07-27T04:26:10.816430Z","record_id":"1b70e37b67072f1c58ea2bcf5f94c1dafc977eb5189a5700d6d265b04ee4aa09","schema_fingerprint":"4aa3821a28b0b7c2400bc59aba4bcc0a76e971dadd19610d3ad38c768e124dc7","schema_version":"edge-lab-recorder.raw.v1","sequence":null,"source":"clob_market_ws"}
{"event_at":"2026-07-27T04:26:10.410000Z","event_fingerprint":"8b4b7c2b9926b0821e5c60791554bc3e31c3b9c524832e25eed8661f77fff5df","payload":{"connection_id":"0f4979d6978d463e9660b042fdcf555f","event_at":"2026-07-27T04:26:10.410000Z","event_type":"price_change","frame_hash":"081c1a9588119884797035c8216d729bc024e5cf16a010c464c63c3858a01014","frame_index":0,"kind":"data","monotonic_ns":228354095601000,"payload":{"event_type":"price_change","market":"0xeb66215f2e9faa6449e30a02bab5b8ed7b79a38bf961f6b24d0073c9c2419250","price_changes":[{"asset_id":"69697746896130839564035629862476347944307040470122503199396727085502753297492","best_ask":"0.46","best_bid":"0.45","hash":"1b76910cc8ca1709a08c361e4bf19add658a92c9","price":"0.45","side":"BUY","size":"362.95"},{"asset_id":"60386828328910021732068595344565885737045900010034836345809386672230885527307","best_ask":"0.55","best_bid":"0.54","hash":"e6534fce69c5a15cc002a1fc9d3b059cfb7bb8af","price":"0.55","side":"SELL","size":"362.95"}],"timestamp":"1785126370410"},"payload_hash":"70a221cdcf292bbb59911ae3695b1662d6e3e7e14e79efb182aa78321e2ceb56","raw_frame":"{\"market\":\"0xeb66215f2e9faa6449e30a02bab5b8ed7b79a38bf961f6b24d0073c9c2419250\", \"price_changes\":[{\"asset_id\":\"69697746896130839564035629862476347944307040470122503199396727085502753297492\", \"price\":\"0.45\", \"size\":\"362.95\", \"side\":\"BUY\", \"hash\":\"1b76910cc8ca1709a08c361e4bf19add658a92c9\", \"best_bid\":\"0.45\", \"best_ask\":\"0.46\"}, {\"asset_id\":\"60386828328910021732068595344565885737045900010034836345809386672230885527307\", \"price\":\"0.55\", \"size\":\"362.95\", \"side\":\"SELL\", \"hash\":\"e6534fce69c5a15cc002a1fc9d3b059cfb7bb8af\", \"best_bid\":\"0.54\", \"best_ask\":\"0.55\"}], \"timestamp\":\"1785126370410\", \"event_type\":\"price_change\"}","received_at":"2026-07-27T04:26:10.823776Z","schema_version":"clob-market-ws.price_change.v1","sequence":null,"server_hash":null,"server_timestamp":"1785126370410","session_id":"e9443c7415a0419799bee9cfbb1a9e4d","source":"clob_market_ws"},"received_at":"2026-07-27T04:26:10.823776Z","record_id":"055c028ec86424e79678325b0e99c4b35333ff86eeaeaed32ec3870241fff319","schema_fingerprint":"4aa3821a28b0b7c2400bc59aba4bcc0a76e971dadd19610d3ad38c768e124dc7","schema_version":"edge-lab-recorder.raw.v1","sequence":null,"source":"clob_market_ws"}
{"event_at":"2026-07-27T04:26:10.411000Z","event_fingerprint":"559ff647152d284db337155b16218079563358ff89bff1866718bff3b0f1f72a","payload":{"connection_id":"0f4979d6978d463e9660b042fdcf555f","event_at":"2026-07-27T04:26:10.411000Z","event_type":"price_change","frame_hash":"b15e6282a58de923d96b76d24576b330da90e50f2f4aa8f7780332686196b97a","frame_index":0,"kind":"data","monotonic_ns":228354102783416,"payload":{"event_type":"price_change","market":"0xeb66215f2e9faa6449e30a02bab5b8ed7b79a38bf961f6b24d0073c9c2419250","price_changes":[{"asset_id":"60386828328910021732068595344565885737045900010034836345809386672230885527307","best_ask":"0.55","best_bid":"0.54","hash":"8bd361c855dc0ca9b86d05b629835e31fc56c818","price":"0.51","side":"BUY","size":"190"},{"asset_id":"69697746896130839564035629862476347944307040470122503199396727085502753297492","best_ask":"0.46","best_bid":"0.45","hash":"3bb5ea97c7387525fa5abc1909c171a35752d1a6","price":"0.49","side":"SELL","size":"190"}],"timestamp":"1785126370411"},"payload_hash":"39ca2cb0dd9107c067ed764e4ba77644826e10d3ec141a35626f3a11feb71756","raw_frame":"{\"market\":\"0xeb66215f2e9faa6449e30a02bab5b8ed7b79a38bf961f6b24d0073c9c2419250\", \"price_changes\":[{\"asset_id\":\"60386828328910021732068595344565885737045900010034836345809386672230885527307\", \"price\":\"0.51\", \"size\":\"190\", \"side\":\"BUY\", \"hash\":\"8bd361c855dc0ca9b86d05b629835e31fc56c818\", \"best_bid\":\"0.54\", \"best_ask\":\"0.55\"}, {\"asset_id\":\"69697746896130839564035629862476347944307040470122503199396727085502753297492\", \"price\":\"0.49\", \"size\":\"190\", \"side\":\"SELL\", \"hash\":\"3bb5ea97c7387525fa5abc1909c171a35752d1a6\", \"best_bid\":\"0.45\", \"best_ask\":\"0.46\"}], \"timestamp\":\"1785126370411\", \"event_type\":\"price_change\"}","received_at":"2026-07-27T04:26:10.830959Z","schema_version":"clob-market-ws.price_change.v1","sequence":null,"server_hash":null,"server_timestamp":"1785126370411","session_id":"e9443c7415a0419799bee9cfbb1a9e4d","source":"clob_market_ws"},"received_at":"2026-07-27T04:26:10.830959Z","record_id":"7be6712cee9ce0063e4e86bb0e01b0afad2bddbbd95c593bcccb143bdf4d19f9","schema_fingerprint":"4aa3821a28b0b7c2400bc59aba4bcc0a76e971dadd19610d3ad38c768e124dc7","schema_version":"edge-lab-recorder.raw.v1","sequence":null,"source":"clob_market_ws"}
{"event_at":"2026-07-27T04:26:10.412000Z","event_fingerprint":"00e3ea0bca1bb72cd203a0d96ece87cf626a93e16b68e7f44018880502c1aeeb","payload":{"connection_id":"0f4979d6978d463e9660b042fdcf555f","event_at":"2026-07-27T04:26:10.412000Z","event_type":"price_change","frame_hash":"75ac46b3cc226697c280674dcdad924d84ba1c8ee1aa61197cb841f08ab79827","frame_index":0,"kind":"data","monotonic_ns":228354109925416,"payload":{"event_type":"price_change","market":"0xeb66215f2e9faa6449e30a02bab5b8ed7b79a38bf961f6b24d0073c9c2419250","price_changes":[{"asset_id":"69697746896130839564035629862476347944307040470122503199396727085502753297492","best_ask":"0.46","best_bid":"0.45","hash":"7b2ed5fb7a1e2dc6006dac25561e812b7b0e75f1","price":"0.45","side":"BUY","size":"367.95"},{"asset_id":"60386828328910021732068595344565885737045900010034836345809386672230885527307","best_ask":"0.55","best_bid":"0.54","hash":"f62be5eb5fbcc8741572a48d3fe8e4da1bd47c2a","price":"0.55","side":"SELL","size":"367.95"}],"timestamp":"1785126370412"},"payload_hash":"38870842d49b421821b9d9b572e602c22db1cb315208857865370b2655031276","raw_frame":"{\"market\":\"0xeb66215f2e9faa6449e30a02bab5b8ed7b79a38bf961f6b24d0073c9c2419250\", \"price_changes\":[{\"asset_id\":\"69697746896130839564035629862476347944307040470122503199396727085502753297492\", \"price\":\"0.45\", \"size\":\"367.95\", \"side\":\"BUY\", \"hash\":\"7b2ed5fb7a1e2dc6006dac25561e812b7b0e75f1\", \"best_bid\":\"0.45\", \"best_ask\":\"0.46\"}, {\"asset_id\":\"60386828328910021732068595344565885737045900010034836345809386672230885527307\", \"price\":\"0.55\", \"size\":\"367.95\", \"side\":\"SELL\", \"hash\":\"f62be5eb5fbcc8741572a48d3fe8e4da1bd47c2a\", \"best_bid\":\"0.54\", \"best_ask\":\"0.55\"}], \"timestamp\":\"1785126370412\", \"event_type\":\"price_change\"}","received_at":"2026-07-27T04:26:10.838100Z","schema_version":"clob-market-ws.price_change.v1","sequence":null,"server_hash":null,"server_timestamp":"1785126370412","session_id":"e9443c7415a0419799bee9cfbb1a9e4d","source":"clob_market_ws"},"received_at":"2026-07-27T04:26:10.838100Z","record_id":"05a0a1f217f6351bbf6c4fc2c0ff966cedcd717c80ab7865b5cd6a60b1d1b911","schema_fingerprint":"4aa3821a28b0b7c2400bc59aba4bcc0a76e971dadd19610d3ad38c768e124dc7","schema_version":"edge-lab-recorder.raw.v1","sequence":null,"source":"clob_market_ws"}
{"event_at":"2026-07-27T04:26:10.412000Z","event_fingerprint":"5105ac9363db2d4645eea1e156dd2b999fcb2028de6a4e888e8843f7bcd82d56","payload":{"connection_id":"0f4979d6978d463e9660b042fdcf555f","event_at":"2026-07-27T04:26:10.412000Z","event_type":"price_change","frame_hash":"b4e60a755a562dadf89b25bd4478335ed3f33eb9252244a27fb0ff88424aa08f","frame_index":0,"kind":"data","monotonic_ns":228354119281375,"payload":{"event_type":"price_change","market":"0xeb66215f2e9faa6449e30a02bab5b8ed7b79a38bf961f6b24d0073c9c2419250","price_changes":[{"asset_id":"60386828328910021732068595344565885737045900010034836345809386672230885527307","best_ask":"0.55","best_bid":"0.54","hash":"aa4466cca9f3c344b4c30e2a5a7f24725453adde","price":"0.51","side":"BUY","size":"195"},{"asset_id":"69697746896130839564035629862476347944307040470122503199396727085502753297492","best_ask":"0.46","best_bid":"0.45","hash":"243f0f7a7bed999e89e3e561e3cf5ee29e3f4ee1","price":"0.49","side":"SELL","size":"195"}],"timestamp":"1785126370412"},"payload_hash":"da6d3b427a9aa2531fc5c41e4c45f95670cd0cb809b4ffc7106171f2a79580be","raw_frame":"{\"market\":\"0xeb66215f2e9faa6449e30a02bab5b8ed7b79a38bf961f6b24d0073c9c2419250\", \"price_changes\":[{\"asset_id\":\"60386828328910021732068595344565885737045900010034836345809386672230885527307\", \"price\":\"0.51\", \"size\":\"195\", \"side\":\"BUY\", \"hash\":\"aa4466cca9f3c344b4c30e2a5a7f24725453adde\", \"best_bid\":\"0.54\", \"best_ask\":\"0.55\"}, {\"asset_id\":\"69697746896130839564035629862476347944307040470122503199396727085502753297492\", \"price\":\"0.49\", \"size\":\"195\", \"side\":\"SELL\", \"hash\":\"243f0f7a7bed999e89e3e561e3cf5ee29e3f4ee1\", \"best_bid\":\"0.45\", \"best_ask\":\"0.46\"}], \"timestamp\":\"1785126370412\", \"event_type\":\"price_change\"}","received_at":"2026-07-27T04:26:10.847454Z","schema_version":"clob-market-ws.price_change.v1","sequence":null,"server_hash":null,"server_timestamp":"1785126370412","session_id":"e9443c7415a0419799bee9cfbb1a9e4d","source":"clob_market_ws"},"received_at":"2026-07-27T04:26:10.847454Z","record_id":"a64f1965e421377b29da5e106926b26c2fecadd6f0a5b1757f8f58c23f4a3757","schema_fingerprint":"4aa3821a28b0b7c2400bc59aba4bcc0a76e971dadd19610d3ad38c768e124dc7","schema_version":"edge-lab-recorder.raw.v1","sequence":null,"source":"clob_market_ws"}
{"event_at":"2026-07-27T04:26:10.413000Z","event_fingerprint":"5ba7fefe0d73c296fff92c547630b74ca687eaa0c62800325a9a7c16995ae557","payload":{"connection_id":"0f4979d6978d463e9660b042fdcf555f","event_at":"2026-07-27T04:26:10.413000Z","event_type":"price_change","frame_hash":"35609f2a2106fec4d2e450ad201f531862ba44d2c07c06b25c142b62488730b5","frame_index":0,"kind":"data","monotonic_ns":228354125589208,"payload":{"event_type":"price_change","market":"0xeb66215f2e9faa6449e30a02bab5b8ed7b79a38bf961f6b24d0073c9c2419250","price_changes":[{"asset_id":"69697746896130839564035629862476347944307040470122503199396727085502753297492","best_ask":"0.46","best_bid":"0.45","hash":"e801f16955018a0c0c9eddb51f0892a2f3e42711","price":"0.45","side":"BUY","size":"372.95"},{"asset_id":"60386828328910021732068595344565885737045900010034836345809386672230885527307","best_ask":"0.55","best_bid":"0.54","hash":"fd288f4422963271c1a9b3cd87ad88848d350848","price":"0.55","side":"SELL","size":"372.95"}],"timestamp":"1785126370413"},"payload_hash":"6ead26b7022c3522f4840c724efa87e7db58571265b109ab82d85346e6587abf","raw_frame":"{\"market\":\"0xeb66215f2e9faa6449e30a02bab5b8ed7b79a38bf961f6b24d0073c9c2419250\", \"price_changes\":[{\"asset_id\":\"69697746896130839564035629862476347944307040470122503199396727085502753297492\", \"price\":\"0.45\", \"size\":\"372.95\", \"side\":\"BUY\", \"hash\":\"e801f16955018a0c0c9eddb51f0892a2f3e42711\", \"best_bid\":\"0.45\", \"best_ask\":\"0.46\"}, {\"asset_id\":\"60386828328910021732068595344565885737045900010034836345809386672230885527307\", \"price\":\"0.55\", \"size\":\"372.95\", \"side\":\"SELL\", \"hash\":\"fd288f4422963271c1a9b3cd87ad88848d350848\", \"best_bid\":\"0.54\", \"best_ask\":\"0.55\"}], \"timestamp\":\"1785126370413\", \"event_type\":\"price_change\"}","received_at":"2026-07-27T04:26:10.853763Z","schema_version":"clob-market-ws.price_change.v1","sequence":null,"server_hash":null,"server_timestamp":"1785126370413","session_id":"e9443c7415a0419799bee9cfbb1a9e4d","source":"clob_market_ws"},"received_at":"2026-07-27T04:26:10.853763Z","record_id":"6b3749a3a1ccf24d9a62435cc9e221e8de5b2a6e54984ab3377c3616617b5d62","schema_fingerprint":"4aa3821a28b0b7c2400bc59aba4bcc0a76e971dadd19610d3ad38c768e124dc7","schema_version":"edge-lab-recorder.raw.v1","sequence":null,"source":"clob_market_ws"}
{"event_at":"2026-07-27T04:26:10.414000Z","event_fingerprint":"a94b4982b41bf7cf0b45483b3723719134d259e12fa0f64e0877cbfda167868c","payload":{"connection_id":"0f4979d6978d463e9660b042fdcf555f","event_at":"2026-07-27T04:26:10.414000Z","event_type":"price_change","frame_hash":"1ff9e13887eaa03a6d74519aac61f63fc74345e919fb36c77fc0246785e70089","frame_index":0,"kind":"data","monotonic_ns":228354130946916,"payload":{"event_type":"price_change","market":"0xeb66215f2e9faa6449e30a02bab5b8ed7b79a38bf961f6b24d0073c9c2419250","price_changes":[{"asset_id":"60386828328910021732068595344565885737045900010034836345809386672230885527307","best_ask":"0.55","best_bid":"0.54","hash":"e02f1d1a8ad692bb6402fd751bde70ab983404e8","price":"0.51","side":"BUY","size":"200"},{"asset_id":"69697746896130839564035629862476347944307040470122503199396727085502753297492","best_ask":"0.46","best_bid":"0.45","hash":"dbcf0d3513616e03ec6e7a4f9106f5b84793823e","price":"0.49","side":"SELL","size":"200"}],"timestamp":"1785126370414"},"payload_hash":"44eb88c0f3bdd0fd34d2b3addc115a60280e7ad2e187b8d84b4f4814b4bd9518","raw_frame":"{\"market\":\"0xeb66215f2e9faa6449e30a02bab5b8ed7b79a38bf961f6b24d0073c9c2419250\", \"price_changes\":[{\"asset_id\":\"60386828328910021732068595344565885737045900010034836345809386672230885527307\", \"price\":\"0.51\", \"size\":\"200\", \"side\":\"BUY\", \"hash\":\"e02f1d1a8ad692bb6402fd751bde70ab983404e8\", \"best_bid\":\"0.54\", \"best_ask\":\"0.55\"}, {\"asset_id\":\"69697746896130839564035629862476347944307040470122503199396727085502753297492\", \"price\":\"0.49\", \"size\":\"200\", \"side\":\"SELL\", \"hash\":\"dbcf0d3513616e03ec6e7a4f9106f5b84793823e\", \"best_bid\":\"0.45\", \"best_ask\":\"0.46\"}], \"timestamp\":\"1785126370414\", \"event_type\":\"price_change\"}","received_at":"2026-07-27T04:26:10.859122Z","schema_version":"clob-market-ws.price_change.v1","sequence":null,"server_hash":null,"server_timestamp":"1785126370414","session_id":"e9443c7415a0419799bee9cfbb1a9e4d","source":"clob_market_ws"},"received_at":"2026-07-27T04:26:10.859122Z","record_id":"d40724828a4aea7844a3fb11ec0d0ba5b42892e2aaab4b57fcbdd76637dc604f","schema_fingerprint":"4aa3821a28b0b7c2400bc59aba4bcc0a76e971dadd19610d3ad38c768e124dc7","schema_version":"edge-lab-recorder.raw.v1","sequence":null,"source":"clob_market_ws"}
{"event_at":"2026-07-27T04:26:10.415000Z","event_fingerprint":"1f63f6b179c7eeb62f8bb8cb3ae288162f46e4d13f21c1dbfe1155e58c168ad1","payload":{"connection_id":"0f4979d6978d463e9660b042fdcf555f","event_at":"2026-07-27T04:26:10.415000Z","event_type":"price_change","frame_hash":"59a942c779f7c656c9ab08db4276808e423065edacf0e8f4bcfcbe557aaba095","frame_index":0,"kind":"data","monotonic_ns":228354138327958,"payload":{"event_type":"price_change","market":"0xeb66215f2e9faa6449e30a02bab5b8ed7b79a38bf961f6b24d0073c9c2419250","price_changes":[{"asset_id":"60386828328910021732068595344565885737045900010034836345809386672230885527307","best_ask":"0.55","best_bid":"0.54","hash":"586e011b52325e736237fbd74dc0062c3ed78fcd","price":"0.51","side":"BUY","size":"205"},{"asset_id":"69697746896130839564035629862476347944307040470122503199396727085502753297492","best_ask":"0.46","best_bid":"0.45","hash":"ffda4eb60e3cb49b61dd8004403ed0cdc4fc8b75","price":"0.49","side":"SELL","size":"205"}],"timestamp":"1785126370415"},"payload_hash":"6e7bf1f690a31cf47470435406cd9583b7f70f18aaebd8e4c2df884b9cf4a88d","raw_frame":"{\"market\":\"0xeb66215f2e9faa6449e30a02bab5b8ed7b79a38bf961f6b24d0073c9c2419250\", \"price_changes\":[{\"asset_id\":\"60386828328910021732068595344565885737045900010034836345809386672230885527307\", \"price\":\"0.51\", \"size\":\"205\", \"side\":\"BUY\", \"hash\":\"586e011b52325e736237fbd74dc0062c3ed78fcd\", \"best_bid\":\"0.54\", \"best_ask\":\"0.55\"}, {\"asset_id\":\"69697746896130839564035629862476347944307040470122503199396727085502753297492\", \"price\":\"0.49\", \"size\":\"205\", \"side\":\"SELL\", \"hash\":\"ffda4eb60e3cb49b61dd8004403ed0cdc4fc8b75\", \"best_bid\":\"0.45\", \"best_ask\":\"0.46\"}], \"timestamp\":\"1785126370415\", \"event_type\":\"price_change\"}","received_at":"2026-07-27T04:26:10.866503Z","schema_version":"clob-market-ws.price_change.v1","sequence":null,"server_hash":null,"server_timestamp":"1785126370415","session_id":"e9443c7415a0419799bee9cfbb1a9e4d","source":"clob_market_ws"},"received_at":"2026-07-27T04:26:10.866503Z","record_id":"9bb255a7d7ee3a3e6d0dff8eff6ae17306bc293162ba17c055ecdc397f7c0a66","schema_fingerprint":"4aa3821a28b0b7c2400bc59aba4bcc0a76e971dadd19610d3ad38c768e124dc7","schema_version":"edge-lab-recorder.raw.v1","sequence":null,"source":"clob_market_ws"}
{"event_at":"2026-07-27T04:26:10.415000Z","event_fingerprint":"0f6261533eb5effad53521855ecef6edb7f5fc31e45e4d66a6c98dee35fa5d3e","payload":{"connection_id":"0f4979d6978d463e9660b042fdcf555f","event_at":"2026-07-27T04:26:10.415000Z","event_type":"price_change","frame_hash":"65788fcd38980fc4cc1958ea9474a8089dc346d3f6d5a925937013ef638881df","frame_index":0,"kind":"data","monotonic_ns":228354144523958,"payload":{"event_type":"price_change","market":"0xeb66215f2e9faa6449e30a02bab5b8ed7b79a38bf961f6b24d0073c9c2419250","price_changes":[{"asset_id":"60386828328910021732068595344565885737045900010034836345809386672230885527307","best_ask":"0.55","best_bid":"0.54","hash":"3e4031cb0f94729e26085c3b5e73fd9ac453fbff","price":"0.51","side":"BUY","size":"210"},{"asset_id":"69697746896130839564035629862476347944307040470122503199396727085502753297492","best_ask":"0.46","best_bid":"0.45","hash":"aeeaa4a3c4ae3800bbdfe3b1fe36093f171f5721","price":"0.49","side":"SELL","size":"210"}],"timestamp":"1785126370415"},"payload_hash":"ec58382092c7a846c3baca74f36669a2b6ed24225b86c1a443345faa60ff3d40","raw_frame":"{\"market\":\"0xeb66215f2e9faa6449e30a02bab5b8ed7b79a38bf961f6b24d0073c9c2419250\", \"price_changes\":[{\"asset_id\":\"60386828328910021732068595344565885737045900010034836345809386672230885527307\", \"price\":\"0.51\", \"size\":\"210\", \"side\":\"BUY\", \"hash\":\"3e4031cb0f94729e26085c3b5e73fd9ac453fbff\", \"best_bid\":\"0.54\", \"best_ask\":\"0.55\"}, {\"asset_id\":\"69697746896130839564035629862476347944307040470122503199396727085502753297492\", \"price\":\"0.49\", \"size\":\"210\", \"side\":\"SELL\", \"hash\":\"aeeaa4a3c4ae3800bbdfe3b1fe36093f171f5721\", \"best_bid\":\"0.45\", \"best_ask\":\"0.46\"}], \"timestamp\":\"1785126370415\", \"event_type\":\"price_change\"}","received_at":"2026-07-27T04:26:10.872699Z","schema_version":"clob-market-ws.price_change.v1","sequence":null,"server_hash":null,"server_timestamp":"1785126370415","session_id":"e9443c7415a0419799bee9cfbb1a9e4d","source":"clob_market_ws"},"received_at":"2026-07-27T04:26:10.872699Z","record_id":"bacaf2e898cf02a5a994cbdb0dd0ce9ba3f27f6894a149149c07277eb24d509b","schema_fingerprint":"4aa3821a28b0b7c2400bc59aba4bcc0a76e971dadd19610d3ad38c768e124dc7","schema_version":"edge-lab-recorder.raw.v1","sequence":null,"source":"clob_market_ws"}
{"event_at":"2026-07-27T04:26:10.416000Z","event_fingerprint":"4ce52b16d9d6da3db01c6e84c71c370180d73d210e420429489b35129647cacb","payload":{"connection_id":"0f4979d6978d463e9660b042fdcf555f","event_at":"2026-07-27T04:26:10.416000Z","event_type":"price_change","frame_hash":"69df4f3834c6a9bd195fcc25fc647607e3a04090078af3c2cfb634b9c376f181","frame_index":0,"kind":"data","monotonic_ns":228354149208000,"payload":{"event_type":"price_change","market":"0xeb66215f2e9faa6449e30a02bab5b8ed7b79a38bf961f6b24d0073c9c2419250","price_changes":[{"asset_id":"60386828328910021732068595344565885737045900010034836345809386672230885527307","best_ask":"0.55","best_bid":"0.54","hash":"562a31129f418d94c6d687afd0e6ab9582aba4f9","price":"0.51","side":"BUY","size":"215"},{"asset_id":"69697746896130839564035629862476347944307040470122503199396727085502753297492","best_ask":"0.46","best_bid":"0.45","hash":"5c76ce3a1bf6c1cec15b77e7b02a4587578501ee","price":"0.49","side":"SELL","size":"215"}],"timestamp":"1785126370416"},"payload_hash":"bf95fa25e0b1d80d998e55b7486354ce47ef47bd0d2d20960d5627669ca4d2ae","raw_frame":"{\"market\":\"0xeb66215f2e9faa6449e30a02bab5b8ed7b79a38bf961f6b24d0073c9c2419250\", \"price_changes\":[{\"asset_id\":\"60386828328910021732068595344565885737045900010034836345809386672230885527307\", \"price\":\"0.51\", \"size\":\"215\", \"side\":\"BUY\", \"hash\":\"562a31129f418d94c6d687afd0e6ab9582aba4f9\", \"best_bid\":\"0.54\", \"best_ask\":\"0.55\"}, {\"asset_id\":\"69697746896130839564035629862476347944307040470122503199396727085502753297492\", \"price\":\"0.49\", \"size\":\"215\", \"side\":\"SELL\", \"hash\":\"5c76ce3a1bf6c1cec15b77e7b02a4587578501ee\", \"best_bid\":\"0.45\", \"best_ask\":\"0.46\"}], \"timestamp\":\"1785126370416\", \"event_type\":\"price_change\"}","received_at":"2026-07-27T04:26:10.877384Z","schema_version":"clob-market-ws.price_change.v1","sequence":null,"server_hash":null,"server_timestamp":"1785126370416","session_id":"e9443c7415a0419799bee9cfbb1a9e4d","source":"clob_market_ws"},"received_at":"2026-07-27T04:26:10.877384Z","record_id":"98eadba58469c072afacedea6dd3a76f73b6bd25d708d659e38476900a2d7554","schema_fingerprint":"4aa3821a28b0b7c2400bc59aba4bcc0a76e971dadd19610d3ad38c768e124dc7","schema_version":"edge-lab-recorder.raw.v1","sequence":null,"source":"clob_market_ws"}
{"event_at":"2026-07-27T04:26:10.417000Z","event_fingerprint":"2f28a3ff1277d735fed5baf0262e91612fdeec78ef55e60c33644f42824fea10","payload":{"connection_id":"0f4979d6978d463e9660b042fdcf555f","event_at":"2026-07-27T04:26:10.417000Z","event_type":"price_change","frame_hash":"c4027ce1bed11819e62ef13898b4deb711f41fbf2950fa8ef71764ee303360d6","frame_index":0,"kind":"data","monotonic_ns":228354156684708,"payload":{"event_type":"price_change","market":"0xeb66215f2e9faa6449e30a02bab5b8ed7b79a38bf961f6b24d0073c9c2419250","price_changes":[{"asset_id":"60386828328910021732068595344565885737045900010034836345809386672230885527307","best_ask":"0.55","best_bid":"0.54","hash":"993e10c856e449cbcf6ea4ee3faa8cb7cc3fffc9","price":"0.51","side":"BUY","size":"220"},{"asset_id":"69697746896130839564035629862476347944307040470122503199396727085502753297492","best_ask":"0.46","best_bid":"0.45","hash":"2eaa264ebe10275206b864f2e4a8182f83d4b722","price":"0.49","side":"SELL","size":"220"}],"timestamp":"1785126370417"},"payload_hash":"a8e0db9970813865b91aa87aeb6e66d573c2ccd63a2387b73605a543f5af4cd5","raw_frame":"{\"market\":\"0xeb66215f2e9faa6449e30a02bab5b8ed7b79a38bf961f6b24d0073c9c2419250\", \"price_changes\":[{\"asset_id\":\"60386828328910021732068595344565885737045900010034836345809386672230885527307\", \"price\":\"0.51\", \"size\":\"220\", \"side\":\"BUY\", \"hash\":\"993e10c856e449cbcf6ea4ee3faa8cb7cc3fffc9\", \"best_bid\":\"0.54\", \"best_ask\":\"0.55\"}, {\"asset_id\":\"69697746896130839564035629862476347944307040470122503199396727085502753297492\", \"price\":\"0.49\", \"size\":\"220\", \"side\":\"SELL\", \"hash\":\"2eaa264ebe10275206b864f2e4a8182f83d4b722\", \"best_bid\":\"0.45\", \"best_ask\":\"0.46\"}], \"timestamp\":\"1785126370417\", \"event_type\":\"price_change\"}","received_at":"2026-07-27T04:26:10.884857Z","schema_version":"clob-market-ws.price_change.v1","sequence":null,"server_hash":null,"server_timestamp":"1785126370417","session_id":"e9443c7415a0419799bee9cfbb1a9e4d","source":"clob_market_ws"},"received_at":"2026-07-27T04:26:10.884857Z","record_id":"959055f17c95cea44b88d5af4b2941332458c29507f66b582a13795d05425fa9","schema_fingerprint":"4aa3821a28b0b7c2400bc59aba4bcc0a76e971dadd19610d3ad38c768e124dc7","schema_version":"edge-lab-recorder.raw.v1","sequence":null,"source":"clob_market_ws"}
{"event_at":"2026-07-27T04:26:10.418000Z","event_fingerprint":"674ed0292c00f97ca81cb94faea1ef7ee550b212b0d7968cba4f925300274abc","payload":{"connection_id":"0f4979d6978d463e9660b042fdcf555f","event_at":"2026-07-27T04:26:10.418000Z","event_type":"price_change","frame_hash":"35de36e977a87ba6bdc68a75ce51d82ff41779b5067ae9381b5db2700bd0e22e","frame_index":0,"kind":"data","monotonic_ns":228354165693041,"payload":{"event_type":"price_change","market":"0xeb66215f2e9faa6449e30a02bab5b8ed7b79a38bf961f6b24d0073c9c2419250","price_changes":[{"asset_id":"60386828328910021732068595344565885737045900010034836345809386672230885527307","best_ask":"0.55","best_bid":"0.54","hash":"6afad69f3914ea67d7987d869ce484d8f42d9dd3","price":"0.51","side":"BUY","size":"225"},{"asset_id":"69697746896130839564035629862476347944307040470122503199396727085502753297492","best_ask":"0.46","best_bid":"0.45","hash":"b66bbbc20a8d38fc6b649435cb187cc3520feeca","price":"0.49","side":"SELL","size":"225"}],"timestamp":"1785126370418"},"payload_hash":"35ef5987f945d715d3d5b2c5dbb72911c24d2136dd68276e357fa956280397c7","raw_frame":"{\"market\":\"0xeb66215f2e9faa6449e30a02bab5b8ed7b79a38bf961f6b24d0073c9c2419250\", \"price_changes\":[{\"asset_id\":\"60386828328910021732068595344565885737045900010034836345809386672230885527307\", \"price\":\"0.51\", \"size\":\"225\", \"side\":\"BUY\", \"hash\":\"6afad69f3914ea67d7987d869ce484d8f42d9dd3\", \"best_bid\":\"0.54\", \"best_ask\":\"0.55\"}, {\"asset_id\":\"69697746896130839564035629862476347944307040470122503199396727085502753297492\", \"price\":\"0.49\", \"size\":\"225\", \"side\":\"SELL\", \"hash\":\"b66bbbc20a8d38fc6b649435cb187cc3520feeca\", \"best_bid\":\"0.45\", \"best_ask\":\"0.46\"}], \"timestamp\":\"1785126370418\", \"event_type\":\"price_change\"}","received_at":"2026-07-27T04:26:10.893869Z","schema_version":"clob-market-ws.price_change.v1","sequence":null,"server_hash":null,"server_timestamp":"1785126370418","session_id":"e9443c7415a0419799bee9cfbb1a9e4d","source":"clob_market_ws"},"received_at":"2026-07-27T04:26:10.893869Z","record_id":"f29b2e6277a412b91b4f6add0db4e4798d1978fb9d4132204ce23c4c072d75f1","schema_fingerprint":"4aa3821a28b0b7c2400bc59aba4bcc0a76e971dadd19610d3ad38c768e124dc7","schema_version":"edge-lab-recorder.raw.v1","sequence":null,"source":"clob_market_ws"}
{"event_at":"2026-07-27T04:26:16.757000Z","event_fingerprint":"674873925ff1048c4d6c5771ec2962aec56dcc7b67c9d496f3eeb8ec12d387a7","payload":{"connection_id":"0f4979d6978d463e9660b042fdcf555f","event_at":"2026-07-27T04:26:16.757000Z","event_type":"price_change","frame_hash":"c41495238b798a6c71d9df8e764ef4d228ed8f3a1e32e63333374fb9112da052","frame_index":0,"kind":"data","monotonic_ns":228359974593750,"payload":{"event_type":"price_change","market":"0xeb66215f2e9faa6449e30a02bab5b8ed7b79a38bf961f6b24d0073c9c2419250","price_changes":[{"asset_id":"60386828328910021732068595344565885737045900010034836345809386672230885527307","best_ask":"0.55","best_bid":"0.54","hash":"a4228243450268aa8f75951ad23044958b54f3ff","price":"0.53","side":"BUY","size":"100"},{"asset_id":"69697746896130839564035629862476347944307040470122503199396727085502753297492","best_ask":"0.46","best_bid":"0.45","hash":"3b88b90fe514ea094465e551415108a8bfbaa5af","price":"0.47","side":"SELL","size":"100"}],"timestamp":"1785126376757"},"payload_hash":"6415a0f75e086264edf901f153624f2af0807e688848fd0c89fcd5e2214ce7c4","raw_frame":"{\"market\":\"0xeb66215f2e9faa6449e30a02bab5b8ed7b79a38bf961f6b24d0073c9c2419250\", \"price_changes\":[{\"asset_id\":\"60386828328910021732068595344565885737045900010034836345809386672230885527307\", \"price\":\"0.53\", \"size\":\"100\", \"side\":\"BUY\", \"hash\":\"a4228243450268aa8f75951ad23044958b54f3ff\", \"best_bid\":\"0.54\", \"best_ask\":\"0.55\"}, {\"asset_id\":\"69697746896130839564035629862476347944307040470122503199396727085502753297492\", \"price\":\"0.47\", \"size\":\"100\", \"side\":\"SELL\", \"hash\":\"3b88b90fe514ea094465e551415108a8bfbaa5af\", \"best_bid\":\"0.45\", \"best_ask\":\"0.46\"}], \"timestamp\":\"1785126376757\", \"event_type\":\"price_change\"}","received_at":"2026-07-27T04:26:16.702822Z","schema_version":"clob-market-ws.price_change.v1","sequence":null,"server_hash":null,"server_timestamp":"1785126376757","session_id":"e9443c7415a0419799bee9cfbb1a9e4d","source":"clob_market_ws"},"received_at":"2026-07-27T04:26:16.702822Z","record_id":"7448f59debffaf2c38d7cacf62f0e41737819a8cac2f18f3aa2e9452293f8de5","schema_fingerprint":"4aa3821a28b0b7c2400bc59aba4bcc0a76e971dadd19610d3ad38c768e124dc7","schema_version":"edge-lab-recorder.raw.v1","sequence":null,"source":"clob_market_ws"}
