{"event_at":"2026-07-27T04:37:39.376000Z","event_fingerprint":"3866ddd7cece3455625d955e1a6c313306825c301f8349ba30d436a609d80c4d","payload":{"connection_id":"0f4979d6978d463e9660b042fdcf555f","event_at":"2026-07-27T04:37:39.376000Z","event_type":"price_change","frame_hash":"9d16e068bf38360dfd40dd50661d65425952fb234271e6919b27e1f83366c0de","frame_index":0,"kind":"data","monotonic_ns":229042611090083,"payload":{"event_type":"price_change","market":"0xeb66215f2e9faa6449e30a02bab5b8ed7b79a38bf961f6b24d0073c9c2419250","price_changes":[{"asset_id":"60386828328910021732068595344565885737045900010034836345809386672230885527307","best_ask":"0.39","best_bid":"0.38","hash":"ad12eed656d0fb9c3c23003ec6d8ef737d5a60a0","price":"0.33","side":"BUY","size":"69"},{"asset_id":"69697746896130839564035629862476347944307040470122503199396727085502753297492","best_ask":"0.62","best_bid":"0.61","hash":"4bc5a26b34f40399f4165696f28a0ec2d88c2c8b","price":"0.67","side":"SELL","size":"69"}],"timestamp":"1785127059376"},"payload_hash":"c09d425fdf8742643ea0d4ced2146637e4b3d030c255aef76cba80d06b4ed0b6","raw_frame":"{\"market\":\"0xeb66215f2e9faa6449e30a02bab5b8ed7b79a38bf961f6b24d0073c9c2419250\", \"price_changes\":[{\"asset_id\":\"60386828328910021732068595344565885737045900010034836345809386672230885527307\", \"price\":\"0.33\", \"size\":\"69\", \"side\":\"BUY\", \"hash\":\"ad12eed656d0fb9c3c23003ec6d8ef737d5a60a0\", \"best_bid\":\"0.38\", \"best_ask\":\"0.39\"}, {\"asset_id\":\"69697746896130839564035629862476347944307040470122503199396727085502753297492\", \"price\":\"0.67\", \"size\":\"69\", \"side\":\"SELL\", \"hash\":\"4bc5a26b34f40399f4165696f28a0ec2d88c2c8b\", \"best_bid\":\"0.61\", \"best_ask\":\"0.62\"}], \"timestamp\":\"1785127059376\", \"event_type\":\"price_change\"}","received_at":"2026-07-27T04:37:39.345234Z","schema_version":"clob-market-ws.price_change.v1","sequence":null,"server_hash":null,"server_timestamp":"1785127059376","session_id":"e9443c7415a0419799bee9cfbb1a9e4d","source":"clob_market_ws"},"received_at":"2026-07-27T04:37:39.345234Z","record_id":"153dada923a905f1f87715de039faf1f4f717418eeecba9d83c5c76ca7a70502","schema_fingerprint":"4aa3821a28b0b7c2400bc59aba4bcc0a76e971dadd19610d3ad38c768e124dc7","schema_version":"edge-lab-recorder.raw.v1","sequence":null,"source":"clob_market_ws"}
{"event_at":"2026-07-27T04:37:39.377000Z","event_fingerprint":"0c4e1a9c6fdca50e6857d4216bf516a48558478228aa0dca3bc0e0ea9f97dc67","payload":{"connection_id":"0f4979d6978d463e9660b042fdcf555f","event_at":"2026-07-27T04:37:39.377000Z","event_type":"price_change","frame_hash":"d142b05feba17fef8c1cf43f98fe1f30b26bc89d0e698c04906d046673b8e88e","frame_index":0,"kind":"data","monotonic_ns":229042613379625,"payload":{"event_type":"price_change","market":"0xeb66215f2e9faa6449e30a02bab5b8ed7b79a38bf961f6b24d0073c9c2419250","price_changes":[{"asset_id":"60386828328910021732068595344565885737045900010034836345809386672230885527307","best_ask":"0.39","best_bid":"0.38","hash":"273502285b0af193d3488874315a968c279bd8b8","price":"0.3","side":"BUY","size":"207"},{"asset_id":"69697746896130839564035629862476347944307040470122503199396727085502753297492","best_ask":"0.62","best_bid":"0.61","hash":"8a39c06c7b6de0f5d436e2ae99d9c9913eb0cab2","price":"0.7","side":"SELL","size":"207"}],"timestamp":"1785127059377"},"payload_hash":"12a12dd4d22c5c982b42e4353eb530b3a992176755597d3ee973e142eb5f5cc0","raw_frame":"{\"market\":\"0xeb66215f2e9faa6449e30a02bab5b8ed7b79a38bf961f6b24d0073c9c2419250\", \"price_changes\":[{\"asset_id\":\"60386828328910021732068595344565885737045900010034836345809386672230885527307\", \"price\":\"0.3\", \"size\":\"207\", \"side\":\"BUY\", \"hash\":\"273502285b0af193d3488874315a968c279bd8b8\", \"best_bid\":\"0.38\", \"best_ask\":\"0.39\"}, {\"asset_id\":\"69697746896130839564035629862476347944307040470122503199396727085502753297492\", \"price\":\"0.7\", \"size\":\"207\", \"side\":\"SELL\", \"hash\":\"8a39c06c7b6de0f5d436e2ae99d9c9913eb0cab2\", \"best_bid\":\"0.61\", \"best_ask\":\"0.62\"}], \"timestamp\":\"1785127059377\", \"event_type\":\"price_change\"}","received_at":"2026-07-27T04:37:39.347524Z","schema_version":"clob-market-ws.price_change.v1","sequence":null,"server_hash":null,"server_timestamp":"1785127059377","session_id":"e9443c7415a0419799bee9cfbb1a9e4d","source":"clob_market_ws"},"received_at":"2026-07-27T04:37:39.347524Z","record_id":"fe517ed18e050d80f50884fe56834ee6a66ed5f4f8069eabeb7c334fe4bb30eb","schema_fingerprint":"4aa3821a28b0b7c2400bc59aba4bcc0a76e971dadd19610d3ad38c768e124dc7","schema_version":"edge-lab-recorder.raw.v1","sequence":null,"source":"clob_market_ws"}
{"event_at":"2026-07-27T04:37:39.377000Z","event_fingerprint":"faa64967450efe5efda4731b163df57fd7fd285211bae4bd069f05daf6cac3e0","payload":{"connection_id":"0f4979d6978d463e9660b042fdcf555f","event_at":"2026-07-27T04:37:39.377000Z","event_type":"price_change","frame_hash":"afd6ab49a2b865eb6f09f574a4385990f80d07e5b466a9e52a452d329c2ff7dc","frame_index":0,"kind":"data","monotonic_ns":229042614969666,"payload":{"event_type":"price_change","market":"0xeb66215f2e9faa6449e30a02bab5b8ed7b79a38bf961f6b24d0073c9c2419250","price_changes":[{"asset_id":"60386828328910021732068595344565885737045900010034836345809386672230885527307","best_ask":"0.39","best_bid":"0.38","hash":"e90fd4f300720ba6874c3359b7f9ed4486a9495e","price":"0.3","side":"BUY","size":"177"},{"asset_id":"69697746896130839564035629862476347944307040470122503199396727085502753297492","best_ask":"0.62","best_bid":"0.61","hash":"8563a310cbd8761188982190329c740bf125be51","price":"0.7","side":"SELL","size":"177"}],"timestamp":"1785127059377"},"payload_hash":"7b3c8c674cdb13ecd277cc7984bc4eb3f8d6b04227a3230b2584802359837b5e","raw_frame":"{\"market\":\"0xeb66215f2e9faa6449e30a02bab5b8ed7b79a38bf961f6b24d0073c9c2419250\", \"price_changes\":[{\"asset_id\":\"60386828328910021732068595344565885737045900010034836345809386672230885527307\", \"price\":\"0.3\", \"size\":\"177\", \"side\":\"BUY\", \"hash\":\"e90fd4f300720ba6874c3359b7f9ed4486a9495e\", \"best_bid\":\"0.38\", \"best_ask\":\"0.39\"}, {\"asset_id\":\"69697746896130839564035629862476347944307040470122503199396727085502753297492\", \"price\":\"0.7\", \"size\":\"177\", \"side\":\"SELL\", \"hash\":\"8563a310cbd8761188982190329c740bf125be51\", \"best_bid\":\"0.61\", \"best_ask\":\"0.62\"}], \"timestamp\":\"1785127059377\", \"event_type\":\"price_change\"}","received_at":"2026-07-27T04:37:39.349116Z","schema_version":"clob-market-ws.price_change.v1","sequence":null,"server_hash":null,"server_timestamp":"1785127059377","session_id":"e9443c7415a0419799bee9cfbb1a9e4d","source":"clob_market_ws"},"received_at":"2026-07-27T04:37:39.349116Z","record_id":"1ec673753c04f724ed13009715a58e21819507ce06fc7946c4175db7ce6f5629","schema_fingerprint":"4aa3821a28b0b7c2400bc59aba4bcc0a76e971dadd19610d3ad38c768e124dc7","schema_version":"edge-lab-recorder.raw.v1","sequence":null,"source":"clob_market_ws"}
{"event_at":"2026-07-27T04:37:39.377000Z","event_fingerprint":"8865fc303d659c3ff3f0911e84bf11e22a313b03317c1445dc1ba23915e94b52","payload":{"connection_id":"0f4979d6978d463e9660b042fdcf555f","event_at":"2026-07-27T04:37:39.377000Z","event_type":"price_change","frame_hash":"11f6998d5296bfa64a383658733fdd036c5c013d93cacd41b15d9fcd677026e1","frame_index":0,"kind":"data","monotonic_ns":229042616354708,"payload":{"event_type":"price_change","market":"0xeb66215f2e9faa6449e30a02bab5b8ed7b79a38bf961f6b24d0073c9c2419250","price_changes":[{"asset_id":"60386828328910021732068595344565885737045900010034836345809386672230885527307","best_ask":"0.39","best_bid":"0.38","hash":"63bbf0bcb85d16df1f1f036ebf976353b158090c","price":"0.33","side":"BUY","size":"64"},{"asset_id":"69697746896130839564035629862476347944307040470122503199396727085502753297492","best_ask":"0.62","best_bid":"0.61","hash":"cdb94019c57e6b929541d0c0fbb8c8c9adb2d566","price":"0.67","side":"SELL","size":"64"}],"timestamp":"1785127059377"},"payload_hash":"2d00ae6c741137852a2912fa840eaf534716a1dbf1aac0e455bd8e9f4941947a","raw_frame":"{\"market\":\"0xeb66215f2e9faa6449e30a02bab5b8ed7b79a38bf961f6b24d0073c9c2419250\", \"price_changes\":[{\"asset_id\":\"60386828328910021732068595344565885737045900010034836345809386672230885527307\", \"price\":\"0.33\", \"size\":\"64\", \"side\":\"BUY\", \"hash\":\"63bbf0bcb85d16df1f1f036ebf976353b158090c\", \"best_bid\":\"0.38\", \"best_ask\":\"0.39\"}, {\"asset_id\":\"69697746896130839564035629862476347944307040470122503199396727085502753297492\", \"price\":\"0.67\", \"size\":\"64\", \"side\":\"SELL\", \"hash\":\"cdb94019c57e6b929541d0c0fbb8c8c9adb2d566\", \"best_bid\":\"0.61\", \"best_ask\":\"0.62\"}], \"timestamp\":\"1785127059377\", \"event_type\":\"price_change\"}","received_at":"2026-07-27T04:37:39.350503Z","schema_version":"clob-market-ws.price_change.v1","sequence":null,"server_hash":null,"server_timestamp":"1785127059377","session_id":"e9443c7415a0419799bee9cfbb1a9e4d","source":"clob_market_ws"},"received_at":"2026-07-27T04:37:39.350503Z","record_id":"9d66b0ca2e35a521670b80ee5a6267b51c2bea74769f7cad1d275bfcd6d3a4e8","schema_fingerprint":"4aa3821a28b0b7c2400bc59aba4bcc0a76e971dadd19610d3ad38c768e124dc7","schema_version":"edge-lab-recorder.raw.v1","sequence":null,"source":"clob_market_ws"}
{"event_at":"2026-07-27T04:37:39.382000Z","event_fingerprint":"7abdc665ceaac7092d193b4c66129185842101b8b0c50fec4cf555c1bac2e3fe","payload":{"connection_id":"0f4979d6978d463e9660b042fdcf555f","event_at":"2026-07-27T04:37:39.382000Z","event_type":"price_change","frame_hash":"fff294a6aa4ce8f51b585bbda482c82b94705de7ece757811ec43ff16246e461","frame_index":0,"kind":"data","monotonic_ns":229042617648750,"payload":{"event_type":"price_change","market":"0xeb66215f2e9faa6449e30a02bab5b8ed7b79a38bf961f6b24d0073c9c2419250","price_changes":[{"asset_id":"69697746896130839564035629862476347944307040470122503199396727085502753297492","best_ask":"0.62","best_bid":"0.61","hash":"264c93d95768242c7b967deb7370a5a4d9610b0c","price":"0.6","side":"BUY","size":"9.6"},{"asset_id":"60386828328910021732068595344565885737045900010034836345809386672230885527307","best_ask":"0.39","best_bid":"0.38","hash":"b6d1ced9057adcefb8b36169563136a8a9949fd6","price":"0.4","side":"SELL","size":"9.6"}],"timestamp":"1785127059382"},"payload_hash":"868f562a13611e1c94176924bcaaac764370c69eee7496d389d2096948027e03","raw_frame":"{\"market\":\"0xeb66215f2e9faa6449e30a02bab5b8ed7b79a38bf961f6b24d0073c9c2419250\", \"price_changes\":[{\"asset_id\":\"69697746896130839564035629862476347944307040470122503199396727085502753297492\", \"price\":\"0.6\", \"size\":\"9.6\", \"side\":\"BUY\", \"hash\":\"264c93d95768242c7b967deb7370a5a4d9610b0c\", \"best_bid\":\"0.61\", \"best_ask\":\"0.62\"}, {\"asset_id\":\"60386828328910021732068595344565885737045900010034836345809386672230885527307\", \"price\":\"0.4\", \"size\":\"9.6\", \"side\":\"SELL\", \"hash\":\"b6d1ced9057adcefb8b36169563136a8a9949fd6\", \"best_bid\":\"0.38\", \"best_ask\":\"0.39\"}], \"timestamp\":\"1785127059382\", \"event_type\":\"price_change\"}","received_at":"2026-07-27T04:37:39.351797Z","schema_version":"clob-market-ws.price_change.v1","sequence":null,"server_hash":null,"server_timestamp":"1785127059382","session_id":"e9443c7415a0419799bee9cfbb1a9e4d","source":"clob_market_ws"},"received_at":"2026-07-27T04:37:39.351797Z","record_id":"3da29297ad6bb70235be3f240f9e091578d96fadc1510de739b8d56aab6856ad","schema_fingerprint":"4aa3821a28b0b7c2400bc59aba4bcc0a76e971dadd19610d3ad38c768e124dc7","schema_version":"edge-lab-recorder.raw.v1","sequence":null,"source":"clob_market_ws"}
{"event_at":"2026-07-27T04:37:39.383000Z","event_fingerprint":"bbc28aa346ba41b01aaf40b01075bef8532f6ec588d5e20b0ac01f9863bfb85c","payload":{"connection_id":"0f4979d6978d463e9660b042fdcf555f","event_at":"2026-07-27T04:37:39.383000Z","event_type":"price_change","frame_hash":"16e4db63dceb5a133ae08be06a8546004f00f0125ef6d34d50967f17e856f9f7","frame_index":0,"kind":"data","monotonic_ns":229042619375500,"payload":{"event_type":"price_change","market":"0xeb66215f2e9faa6449e30a02bab5b8ed7b79a38bf961f6b24d0073c9c2419250","price_changes":[{"asset_id":"69697746896130839564035629862476347944307040470122503199396727085502753297492","best_ask":"0.62","best_bid":"0.61","hash":"c9dd3606368915c27a7f23d972b1307e14b261f6","price":"0.6","side":"BUY","size":"17.6"},{"asset_id":"60386828328910021732068595344565885737045900010034836345809386672230885527307","best_ask":"0.39","best_bid":"0.38","hash":"0e32b5379fa6b2a3e50b1b2bb40d35fbe53813de","price":"0.4","side":"SELL","size":"17.6"}],"timestamp":"1785127059383"},"payload_hash":"0ab0148c9c5edbacafa1192ebd19ac30308d8710e3bcc18f17fb186f6864443b","raw_frame":"{\"market\":\"0xeb66215f2e9faa6449e30a02bab5b8ed7b79a38bf961f6b24d0073c9c2419250\", \"price_changes\":[{\"asset_id\":\"69697746896130839564035629862476347944307040470122503199396727085502753297492\", \"price\":\"0.6\", \"size\":\"17.6\", \"side\":\"BUY\", \"hash\":\"c9dd3606368915c27a7f23d972b1307e14b261f6\", \"best_bid\":\"0.61\", \"best_ask\":\"0.62\"}, {\"asset_id\":\"60386828328910021732068595344565885737045900010034836345809386672230885527307\", \"price\":\"0.4\", \"size\":\"17.6\", \"side\":\"SELL\", \"hash\":\"0e32b5379fa6b2a3e50b1b2bb40d35fbe53813de\", \"best_bid\":\"0.38\", \"best_ask\":\"0.39\"}], \"timestamp\":\"1785127059383\", \"event_type\":\"price_change\"}","received_at":"2026-07-27T04:37:39.353523Z","schema_version":"clob-market-ws.price_change.v1","sequence":null,"server_hash":null,"server_timestamp":"1785127059383","session_id":"e9443c7415a0419799bee9cfbb1a9e4d","source":"clob_market_ws"},"received_at":"2026-07-27T04:37:39.353523Z","record_id":"e98e6e65aaa0344eea2999940cb8f822141158e4891538ae23a6757562168f00","schema_fingerprint":"4aa3821a28b0b7c2400bc59aba4bcc0a76e971dadd19610d3ad38c768e124dc7","schema_version":"edge-lab-recorder.raw.v1","sequence":null,"source":"clob_market_ws"}
{"event_at":"2026-07-27T04:37:39.384000Z","event_fingerprint":"fbd2ee7d68044c4776c3a1486e58ab79ab6d6d6f1f5055dee3431752815b258b","payload":{"connection_id":"0f4979d6978d463e9660b042fdcf555f","event_at":"2026-07-27T04:37:39.384000Z","event_type":"price_change","frame_hash":"b3e40ccd5472986f7913e9ac2a741e6db5130dd27127a1e74812aecd5577d351","frame_index":0,"kind":"data","monotonic_ns":229042621045666,"payload":{"event_type":"price_change","market":"0xeb66215f2e9faa6449e30a02bab5b8ed7b79a38bf961f6b24d0073c9c2419250","price_changes":[{"asset_id":"60386828328910021732068595344565885737045900010034836345809386672230885527307","best_ask":"0.39","best_bid":"0.38","hash":"d94199cbb2f9293268f6d773840b4f88b041b077","price":"0.36","side":"BUY","size":"66.91"},{"asset_id":"69697746896130839564035629862476347944307040470122503199396727085502753297492","best_ask":"0.62","best_bid":"0.61","hash":"12236c0be8d7927cd03d8f49a2616f6e852c1751","price":"0.64","side":"SELL","size":"66.91"}],"timestamp":"1785127059384"},"payload_hash":"fb54bbd06f695412499d69d176596b0cfb7f255a010912e778dcceec70b4af39","raw_frame":"{\"market\":\"0xeb66215f2e9faa6449e30a02bab5b8ed7b79a38bf961f6b24d0073c9c2419250\", \"price_changes\":[{\"asset_id\":\"60386828328910021732068595344565885737045900010034836345809386672230885527307\", \"price\":\"0.36\", \"size\":\"66.91\", \"side\":\"BUY\", \"hash\":\"d94199cbb2f9293268f6d773840b4f88b041b077\", \"best_bid\":\"0.38\", \"best_ask\":\"0.39\"}, {\"asset_id\":\"69697746896130839564035629862476347944307040470122503199396727085502753297492\", \"price\":\"0.64\", \"size\":\"66.91\", \"side\":\"SELL\", \"hash\":\"12236c0be8d7927cd03d8f49a2616f6e852c1751\", \"best_bid\":\"0.61\", \"best_ask\":\"0.62\"}], \"timestamp\":\"1785127059384\", \"event_type\":\"price_change\"}","received_at":"2026-07-27T04:37:39.355189Z","schema_version":"clob-market-ws.price_change.v1","sequence":null,"server_hash":null,"server_timestamp":"1785127059384","session_id":"e9443c7415a0419799bee9cfbb1a9e4d","source":"clob_market_ws"},"received_at":"2026-07-27T04:37:39.355189Z","record_id":"eec8f52df3962cec8985279d228086d99c719a7927a3e8ad656779f0471f141c","schema_fingerprint":"4aa3821a28b0b7c2400bc59aba4bcc0a76e971dadd19610d3ad38c768e124dc7","schema_version":"edge-lab-recorder.raw.v1","sequence":null,"source":"clob_market_ws"}
{"event_at":"2026-07-27T04:37:39.401000Z","event_fingerprint":"3436ff3c4d050318aaf2f55be7462048f3f78276e6ce7b0d82ecdcf68897dd43","payload":{"connection_id":"0f4979d6978d463e9660b042fdcf555f","event_at":"2026-07-27T04:37:39.401000Z","event_type":"price_change","frame_hash":"0a09a61aa99dfd6c8244b9bf082e9df930172e527e4f61b227101c7943297b7c","frame_index":0,"kind":"data","monotonic_ns":229042622861708,"payload":{"event_type":"price_change","market":"0xeb66215f2e9faa6449e30a02bab5b8ed7b79a38bf961f6b24d0073c9c2419250","price_changes":[{"asset_id":"60386828328910021732068595344565885737045900010034836345809386672230885527307","best_ask":"0.39","best_bid":"0.38","hash":"22d9ad23f1cf2e22f0642ffd026c6452264fd3d2","price":"0.23","side":"BUY","size":"123.89"},{"asset_id":"69697746896130839564035629862476347944307040470122503199396727085502753297492","best_ask":"0.62","best_bid":"0.61","hash":"11bdd411fc7f6d01ef0c456514164ffdad9b0742","price":"0.77","side":"SELL","size":"123.89"}],"timestamp":"1785127059401"},"payload_hash":"fb4d5bf0e9d063fe664b68fd61037b2aad2f904f85850946c560a79e63563d9a","raw_frame":"{\"market\":\"0xeb66215f2e9faa6449e30a02bab5b8ed7b79a38bf961f6b24d0073c9c2419250\", \"price_changes\":[{\"asset_id\":\"60386828328910021732068595344565885737045900010034836345809386672230885527307\", \"price\":\"0.23\", \"size\":\"123.89\", \"side\":\"BUY\", \"hash\":\"22d9ad23f1cf2e22f0642ffd026c6452264fd3d2\", \"best_bid\":\"0.38\", \"best_ask\":\"0.39\"}, {\"asset_id\":\"69697746896130839564035629862476347944307040470122503199396727085502753297492\", \"price\":\"0.77\", \"size\":\"123.89\", \"side\":\"SELL\", \"hash\":\"11bdd411fc7f6d01ef0c456514164ffdad9b0742\", \"best_bid\":\"0.61\", \"best_ask\":\"0.62\"}], \"timestamp\":\"1785127059401\", \"event_type\":\"price_change\"}","received_at":"2026-07-27T04:37:39.357006Z","schema_version":"clob-market-ws.price_change.v1","sequence":null,"server_hash":null,"server_timestamp":"1785127059401","session_id":"e9443c7415a0419799bee9cfbb1a9e4d","source":"clob_market_ws"},"received_at":"2026-07-27T04:37:39.357006Z","record_id":"c08e512dbe91ad7202f45fb230d56e3d1e601fee9fcb0f13dfdbe4d9bec8be3a","schema_fingerprint":"4aa3821a28b0b7c2400bc59aba4bcc0a76e971dadd19610d3ad38c768e124dc7","schema_version":"edge-lab-recorder.raw.v1","sequence":null,"source":"clob_market_ws"}
{"event_at":"2026-07-27T04:37:39.409000Z","event_fingerprint":"9c8071be970321fb248726713804f74f5372738aedfd2c3e6e99cda724cbf39a","payload":{"connection_id":"0f4979d6978d463e9660b042fdcf555f","event_at":"2026-07-27T04:37:39.409000Z","event_type":"price_change","frame_hash":"82a8c1537ab568b353eafce4fbf0179bfdb3819438c500587a8b285f85204bcf","frame_index":0,"kind":"data","monotonic_ns":229042626502250,"payload":{"event_type":"price_change","market":"0xeb66215f2e9faa6449e30a02bab5b8ed7b79a38bf961f6b24d0073c9c2419250","price_changes":[{"asset_id":"60386828328910021732068595344565885737045900010034836345809386672230885527307","best_ask":"0.39","best_bid":"0.38","hash":"528d95443f941c87d24851d250d22d190fdce8a5","price":"0.37","side":"BUY","size":"12.81"},{"asset_id":"69697746896130839564035629862476347944307040470122503199396727085502753297492","best_ask":"0.62","best_bid":"0.61","hash":"f98e132601a272fc9f1807a252e9750fca98a722","price":"0.63","side":"SELL","size":"12.81"}],"timestamp":"1785127059409"},"payload_hash":"1b54221178bce766c9b487802a5761ee546499d72a8da71eefcef401f748f0b7","raw_frame":"{\"market\":\"0xeb66215f2e9faa6449e30a02bab5b8ed7b79a38bf961f6b24d0073c9c2419250\", \"price_changes\":[{\"asset_id\":\"60386828328910021732068595344565885737045900010034836345809386672230885527307\", \"price\":\"0.37\", \"size\":\"12.81\", \"side\":\"BUY\", \"hash\":\"528d95443f941c87d24851d250d22d190fdce8a5\", \"best_bid\":\"0.38\", \"best_ask\":\"0.39\"}, {\"asset_id\":\"69697746896130839564035629862476347944307040470122503199396727085502753297492\", \"price\":\"0.63\", \"size\":\"12.81\", \"side\":\"SELL\", \"hash\":\"f98e132601a272fc9f1807a252e9750fca98a722\", \"best_bid\":\"0.61\", \"best_ask\":\"0.62\"}], \"timestamp\":\"1785127059409\", \"event_type\":\"price_change\"}","received_at":"2026-07-27T04:37:39.360648Z","schema_version":"clob-market-ws.price_change.v1","sequence":null,"server_hash":null,"server_timestamp":"1785127059409","session_id":"e9443c7415a0419799bee9cfbb1a9e4d","source":"clob_market_ws"},"received_at":"2026-07-27T04:37:39.360648Z","record_id":"ce3382383fa3de28c5da373e71abd17cb1aadd962ec63c7c5f59edd9aa1bb07b","schema_fingerprint":"4aa3821a28b0b7c2400bc59aba4bcc0a76e971dadd19610d3ad38c768e124dc7","schema_version":"edge-lab-recorder.raw.v1","sequence":null,"source":"clob_market_ws"}
{"event_at":"2026-07-27T04:37:39.411000Z","event_fingerprint":"0da00e15d4269e0ca820dfd933efa785ee6488b7add49406b2468eae616a9c3b","payload":{"connection_id":"0f4979d6978d463e9660b042fdcf555f","event_at":"2026-07-27T04:37:39.411000Z","event_type":"price_change","frame_hash":"b1d8d4d31b8e9da93349d6f294b1d852b4d92d1ebe7ccb771925d3278169e5cf","frame_index":0,"kind":"data","monotonic_ns":229042630079500,"payload":{"event_type":"price_change","market":"0xeb66215f2e9faa6449e30a02bab5b8ed7b79a38bf961f6b24d0073c9c2419250","price_changes":[{"asset_id":"60386828328910021732068595344565885737045900010034836345809386672230885527307","best_ask":"0.39","best_bid":"0.38","hash":"600ea9daf6f98026fc6e9900da1ae171900d952d","price":"0.25","side":"BUY","size":"401.66"},{"asset_id":"69697746896130839564035629862476347944307040470122503199396727085502753297492","best_ask":"0.62","best_bid":"0.61","hash":"ee6b1cdda817af6559e34284bc6b3ad52ee803a9","price":"0.75","side":"SELL","size":"401.66"}],"timestamp":"1785127059411"},"payload_hash":"fc20398fcc3796961ddee8b762d8299d9868012e813a42af94167acf9d81f1ba","raw_frame":"{\"market\":\"0xeb66215f2e9faa6449e30a02bab5b8ed7b79a38bf961f6b24d0073c9c2419250\", \"price_changes\":[{\"asset_id\":\"60386828328910021732068595344565885737045900010034836345809386672230885527307\", \"price\":\"0.25\", \"size\":\"401.66\", \"side\":\"BUY\", \"hash\":\"600ea9daf6f98026fc6e9900da1ae171900d952d\", \"best_bid\":\"0.38\", \"best_ask\":\"0.39\"}, {\"asset_id\":\"69697746896130839564035629862476347944307040470122503199396727085502753297492\", \"price\":\"0.75\", \"size\":\"401.66\", \"side\":\"SELL\", \"hash\":\"ee6b1cdda817af6559e34284bc6b3ad52ee803a9\", \"best_bid\":\"0.61\", \"best_ask\":\"0.62\"}], \"timestamp\":\"1785127059411\", \"event_type\":\"price_change\"}","received_at":"2026-07-27T04:37:39.364224Z","schema_version":"clob-market-ws.price_change.v1","sequence":null,"server_hash":null,"server_timestamp":"1785127059411","session_id":"e9443c7415a0419799bee9cfbb1a9e4d","source":"clob_market_ws"},"received_at":"2026-07-27T04:37:39.364224Z","record_id":"2d6889b261fa9fd7900e7776c1c7a90cde2e9d305fc06134d45aadf2345f6a7d","schema_fingerprint":"4aa3821a28b0b7c2400bc59aba4bcc0a76e971dadd19610d3ad38c768e124dc7","schema_version":"edge-lab-recorder.raw.v1","sequence":null,"source":"clob_market_ws"}
{"event_at":"2026-07-27T04:37:39.412000Z","event_fingerprint":"35441928e504dbb708d80eafbd79640b3e8dbcabce135f7d22de0cf3b6bcdcfd","payload":{"connection_id":"0f4979d6978d463e9660b042fdcf555f","event_at":"2026-07-27T04:37:39.412000Z","event_type":"price_change","frame_hash":"a48e970b2065cf14a27a176836793f8617d791b84375c75f7e9edd8fa884250b","frame_index":0,"kind":"data","monotonic_ns":229042632517791,"payload":{"event_type":"price_change","market":"0xeb66215f2e9faa6449e30a02bab5b8ed7b79a38bf961f6b24d0073c9c2419250","price_changes":[{"asset_id":"69697746896130839564035629862476347944307040470122503199396727085502753297492","best_ask":"0.62","best_bid":"0.61","hash":"e9d57abc6c91377c5fc9f124038a73d94582a50e","price":"0.44","side":"BUY","size":"198.95"},{"asset_id":"60386828328910021732068595344565885737045900010034836345809386672230885527307","best_ask":"0.39","best_bid":"0.38","hash":"f945209f991088d14541b18cd342a5b46943f9b0","price":"0.56","side":"SELL","size":"198.95"}],"timestamp":"1785127059412"},"payload_hash":"427a863495b78ebbef191b3ab00a032e7196a74d302a3041fe7b8c4f30846106","raw_frame":"{\"market\":\"0xeb66215f2e9faa6449e30a02bab5b8ed7b79a38bf961f6b24d0073c9c2419250\", \"price_changes\":[{\"asset_id\":\"69697746896130839564035629862476347944307040470122503199396727085502753297492\", \"price\":\"0.44\", \"size\":\"198.95\", \"side\":\"BUY\", \"hash\":\"e9d57abc6c91377c5fc9f124038a73d94582a50e\", \"best_bid\":\"0.61\", \"best_ask\":\"0.62\"}, {\"asset_id\":\"60386828328910021732068595344565885737045900010034836345809386672230885527307\", \"price\":\"0.56\", \"size\":\"198.95\", \"side\":\"SELL\", \"hash\":\"f945209f991088d14541b18cd342a5b46943f9b0\", \"best_bid\":\"0.38\", \"best_ask\":\"0.39\"}], \"timestamp\":\"1785127059412\", \"event_type\":\"price_change\"}","received_at":"2026-07-27T04:37:39.366667Z","schema_version":"clob-market-ws.price_change.v1","sequence":null,"server_hash":null,"server_timestamp":"1785127059412","session_id":"e9443c7415a0419799bee9cfbb1a9e4d","source":"clob_market_ws"},"received_at":"2026-07-27T04:37:39.366667Z","record_id":"a18921aabdb45596aac1152e4f16e6c1dc6ad2e18dbff1291d80ab28e50b8dae","schema_fingerprint":"4aa3821a28b0b7c2400bc59aba4bcc0a76e971dadd19610d3ad38c768e124dc7","schema_version":"edge-lab-recorder.raw.v1","sequence":null,"source":"clob_market_ws"}
{"event_at":"2026-07-27T04:37:39.413000Z","event_fingerprint":"2e62ccd17293ab041f5a12a179dcbbbe46247d79147f68ffc0298304b24311f2","payload":{"connection_id":"0f4979d6978d463e9660b042fdcf555f","event_at":"2026-07-27T04:37:39.413000Z","event_type":"price_change","frame_hash":"9897431ef52c44880e09a4b8d820cd6cb2d8a3065553aed24152a10719ce4c94","frame_index":0,"kind":"data","monotonic_ns":229042633450333,"payload":{"event_type":"price_change","market":"0xeb66215f2e9faa6449e30a02bab5b8ed7b79a38bf961f6b24d0073c9c2419250","price_changes":[{"asset_id":"60386828328910021732068595344565885737045900010034836345809386672230885527307","best_ask":"0.39","best_bid":"0.38","hash":"dda41d463b725a78e8b5b1a9762e21c5d7e7c569","price":"0.25","side":"BUY","size":"268.33"},{"asset_id":"69697746896130839564035629862476347944307040470122503199396727085502753297492","best_ask":"0.62","best_bid":"0.61","hash":"209d899af6e1d9506c024fb5276d6683e61855bf","price":"0.75","side":"SELL","size":"268.33"}],"timestamp":"1785127059413"},"payload_hash":"1dd725685b7fa503c983919354b80c685d918072c5612d78724e37afd38125e8","raw_frame":"{\"market\":\"0xeb66215f2e9faa6449e30a02bab5b8ed7b79a38bf961f6b24d0073c9c2419250\", \"price_changes\":[{\"asset_id\":\"60386828328910021732068595344565885737045900010034836345809386672230885527307\", \"price\":\"0.25\", \"size\":\"268.33\", \"side\":\"BUY\", \"hash\":\"dda41d463b725a78e8b5b1a9762e21c5d7e7c569\", \"best_bid\":\"0.38\", \"best_ask\":\"0.39\"}, {\"asset_id\":\"69697746896130839564035629862476347944307040470122503199396727085502753297492\", \"price\":\"0.75\", \"size\":\"268.33\", \"side\":\"SELL\", \"hash\":\"209d899af6e1d9506c024fb5276d6683e61855bf\", \"best_bid\":\"0.61\", \"best_ask\":\"0.62\"}], \"timestamp\":\"1785127059413\", \"event_type\":\"price_change\"}","received_at":"2026-07-27T04:37:39.367601Z","schema_version":"clob-market-ws.price_change.v1","sequence":null,"server_hash":null,"server_timestamp":"1785127059413","session_id":"e9443c7415a0419799bee9cfbb1a9e4d","source":"clob_market_ws"},"received_at":"2026-07-27T04:37:39.367601Z","record_id":"ff9b9d5580d276009bbfaae047103aefec99bb2efe5f3b3dec94d2e799dffdeb","schema_fingerprint":"4aa3821a28b0b7c2400bc59aba4bcc0a76e971dadd19610d3ad38c768e124dc7","schema_version":"edge-lab-recorder.raw.v1","sequence":null,"source":"clob_market_ws"}
{"event_at":"2026-07-27T04:37:39.413000Z","event_fingerprint":"3c0e9a7139e980d44ea960f1365f7844d19982ed1bc2136a5d92f6e2b72266f0","payload":{"connection_id":"0f4979d6978d463e9660b042fdcf555f","event_at":"2026-07-27T04:37:39.413000Z","event_type":"price_change","frame_hash":"f33f1f6e6dadef89a5780122bb1f08211643b1f908f3c2e66b606fcea235b8c6","frame_index":0,"kind":"data","monotonic_ns":229042635621166,"payload":{"event_type":"price_change","market":"0xeb66215f2e9faa6449e30a02bab5b8ed7b79a38bf961f6b24d0073c9c2419250","price_changes":[{"asset_id":"69697746896130839564035629862476347944307040470122503199396727085502753297492","best_ask":"0.62","best_bid":"0.61","hash":"f77201653dd8ecddbc87186ff4aa329327dba4a7","price":"0.44","side":"BUY","size":"123.2"},{"asset_id":"60386828328910021732068595344565885737045900010034836345809386672230885527307","best_ask":"0.39","best_bid":"0.38","hash":"9463961667202ab817310bcea5d6263eae11e98b","price":"0.56","side":"SELL","size":"123.2"}],"timestamp":"1785127059413"},"payload_hash":"80f80c71ce684badaeb61156d1631fdbb2fb3d889f289c373eb891a64abb1b23","raw_frame":"{\"market\":\"0xeb66215f2e9faa6449e30a02bab5b8ed7b79a38bf961f6b24d0073c9c2419250\", \"price_changes\":[{\"asset_id\":\"69697746896130839564035629862476347944307040470122503199396727085502753297492\", \"price\":\"0.44\", \"size\":\"123.2\", \"side\":\"BUY\", \"hash\":\"f77201653dd8ecddbc87186ff4aa329327dba4a7\", \"best_bid\":\"0.61\", \"best_ask\":\"0.62\"}, {\"asset_id\":\"60386828328910021732068595344565885737045900010034836345809386672230885527307\", \"price\":\"0.56\", \"size\":\"123.2\", \"side\":\"SELL\", \"hash\":\"9463961667202ab817310bcea5d6263eae11e98b\", \"best_bid\":\"0.38\", \"best_ask\":\"0.39\"}], \"timestamp\":\"1785127059413\", \"event_type\":\"price_change\"}","received_at":"2026-07-27T04:37:39.369772Z","schema_version":"clob-market-ws.price_change.v1","sequence":null,"server_hash":null,"server_timestamp":"1785127059413","session_id":"e9443c7415a0419799bee9cfbb1a9e4d","source":"clob_market_ws"},"received_at":"2026-07-27T04:37:39.369772Z","record_id":"1c0793b66be0c623c340265c397f53eece7a9db4e50732fd6fd47dfc05b158ae","schema_fingerprint":"4aa3821a28b0b7c2400bc59aba4bcc0a76e971dadd19610d3ad38c768e124dc7","schema_version":"edge-lab-recorder.raw.v1","sequence":null,"source":"clob_market_ws"}
{"event_at":"2026-07-27T04:37:39.415000Z","event_fingerprint":"1dd9e269398a4c0a64ce5be58759d6e82d25bd99ae7ba8301ea78dad58264f17","payload":{"connection_id":"0f4979d6978d463e9660b042fdcf555f","event_at":"2026-07-27T04:37:39.415000Z","event_type":"price_change","frame_hash":"1d7b18aed9ccf479629a67b3cc1f58c366fa32540bd59c61aef799bb7cdd0b69","frame_index":0,"kind":"data","monotonic_ns":229042636714708,"payload":{"event_type":"price_change","market":"0xeb66215f2e9faa6449e30a02bab5b8ed7b79a38bf961f6b24d0073c9c2419250","price_changes":[{"asset_id":"69697746896130839564035629862476347944307040470122503199396727085502753297492","best_ask":"0.62","best_bid":"0.61","hash":"de62d1c6a538572b3b660904e1918aeca5356f81","price":"0.45","side":"BUY","size":"117.1"},{"asset_id":"60386828328910021732068595344565885737045900010034836345809386672230885527307","best_ask":"0.39","best_bid":"0.38","hash":"415e67c180b981e8277d38ddf7b324e260217868","price":"0.55","side":"SELL","size":"117.1"}],"timestamp":"1785127059415"},"payload_hash":"fcf3ae9aa3ff69d414392985ebdb9684f893e937b9f827c6d0dd0a6d54fadedc","raw_frame":"{\"market\":\"0xeb66215f2e9faa6449e30a02bab5b8ed7b79a38bf961f6b24d0073c9c2419250\", \"price_changes\":[{\"asset_id\":\"69697746896130839564035629862476347944307040470122503199396727085502753297492\", \"price\":\"0.45\", \"size\":\"117.1\", \"side\":\"BUY\", \"hash\":\"de62d1c6a538572b3b660904e1918aeca5356f81\", \"best_bid\":\"0.61\", \"best_ask\":\"0.62\"}, {\"asset_id\":\"60386828328910021732068595344565885737045900010034836345809386672230885527307\", \"price\":\"0.55\", \"size\":\"117.1\", \"side\":\"SELL\", \"hash\":\"415e67c180b981e8277d38ddf7b324e260217868\", \"best_bid\":\"0.38\", \"best_ask\":\"0.39\"}], \"timestamp\":\"1785127059415\", \"event_type\":\"price_change\"}","received_at":"2026-07-27T04:37:39.370857Z","schema_version":"clob-market-ws.price_change.v1","sequence":null,"server_hash":null,"server_timestamp":"1785127059415","session_id":"e9443c7415a0419799bee9cfbb1a9e4d","source":"clob_market_ws"},"received_at":"2026-07-27T04:37:39.370857Z","record_id":"5523dce96733e91e7aefe815b5a66f8370c163710804a95b45e037b4e9aca83d","schema_fingerprint":"4aa3821a28b0b7c2400bc59aba4bcc0a76e971dadd19610d3ad38c768e124dc7","schema_version":"edge-lab-recorder.raw.v1","sequence":null,"source":"clob_market_ws"}
{"event_at":"2026-07-27T04:37:39.416000Z","event_fingerprint":"ad219a5e6591cf3b1b6205532383783b5c84eb38f8191244239e0b5167ee1a59","payload":{"connection_id":"0f4979d6978d463e9660b042fdcf555f","event_at":"2026-07-27T04:37:39.416000Z","event_type":"price_change","frame_hash":"b81f3bf6776dcf3d47f18aca499c6b5608b874c712d9175c7a788017e8c71e2f","frame_index":0,"kind":"data","monotonic_ns":229042638375375,"payload":{"event_type":"price_change","market":"0xeb66215f2e9faa6449e30a02bab5b8ed7b79a38bf961f6b24d0073c9c2419250","price_changes":[{"asset_id":"60386828328910021732068595344565885737045900010034836345809386672230885527307","best_ask":"0.39","best_bid":"0.38","hash":"f26240f7d32ef3ba60a3b34e29166664216c74b7","price":"0.27","side":"BUY","size":"55"},{"asset_id":"69697746896130839564035629862476347944307040470122503199396727085502753297492","best_ask":"0.62","best_bid":"0.61","hash":"aeaf937c87a0988a5646da3db60b5ba0e724a01b","price":"0.73","side":"SELL","size":"55"}],"timestamp":"1785127059416"},"payload_hash":"8ff6a7e4fe44164c3518a528376f107684960522e20d1679c16751e9d6948869","raw_frame":"{\"market\":\"0xeb66215f2e9faa6449e30a02bab5b8ed7b79a38bf961f6b24d0073c9c2419250\", \"price_changes\":[{\"asset_id\":\"60386828328910021732068595344565885737045900010034836345809386672230885527307\", \"price\":\"0.27\", \"size\":\"55\", \"side\":\"BUY\", \"hash\":\"f26240f7d32ef3ba60a3b34e29166664216c74b7\", \"best_bid\":\"0.38\", \"best_ask\":\"0.39\"}, {\"asset_id\":\"69697746896130839564035629862476347944307040470122503199396727085502753297492\", \"price\":\"0.73\", \"size\":\"55\", \"side\":\"SELL\", \"hash\":\"aeaf937c87a0988a5646da3db60b5ba0e724a01b\", \"best_bid\":\"0.61\", \"best_ask\":\"0.62\"}], \"timestamp\":\"1785127059416\", \"event_type\":\"price_change\"}","received_at":"2026-07-27T04:37:39.372518Z","schema_version":"clob-market-ws.price_change.v1","sequence":null,"server_hash":null,"server_timestamp":"1785127059416","session_id":"e9443c7415a0419799bee9cfbb1a9e4d","source":"clob_market_ws"},"received_at":"2026-07-27T04:37:39.372518Z","record_id":"d1da6f2b22f9f9d7e00b800680dcebb32d6ce343e32830123040fd642439d0dd","schema_fingerprint":"4aa3821a28b0b7c2400bc59aba4bcc0a76e971dadd19610d3ad38c768e124dc7","schema_version":"edge-lab-recorder.raw.v1","sequence":null,"source":"clob_market_ws"}
{"event_at":"2026-07-27T04:37:39.418000Z","event_fingerprint":"9f5a9f24b790d386c06054bbdba82a0b7011af7d1241be78c13e3863a35970bf","payload":{"connection_id":"0f4979d6978d463e9660b042fdcf555f","event_at":"2026-07-27T04:37:39.418000Z","event_type":"price_change","frame_hash":"d997abdbf728de99d4699fe525124a92896c0ad0162d6eea2ece038f63cd0369","frame_index":0,"kind":"data","monotonic_ns":229042639878416,"payload":{"event_type":"price_change","market":"0xeb66215f2e9faa6449e30a02bab5b8ed7b79a38bf961f6b24d0073c9c2419250","price_changes":[{"asset_id":"69697746896130839564035629862476347944307040470122503199396727085502753297492","best_ask":"0.62","best_bid":"0.61","hash":"b4f8645c2104a3d18e323c838526e530d402ec3d","price":"0.49","side":"BUY","size":"127"},{"asset_id":"60386828328910021732068595344565885737045900010034836345809386672230885527307","best_ask":"0.39","best_bid":"0.38","hash":"225a72b4cdefe90f763adb68d227bc57ea41af98","price":"0.51","side":"SELL","size":"127"}],"timestamp":"1785127059418"},"payload_hash":"07b37894767004d481b8ba0a888cd02b8cc81d0d49b7278d5c6012cadd8d833a","raw_frame":"{\"market\":\"0xeb66215f2e9faa6449e30a02bab5b8ed7b79a38bf961f6b24d0073c9c2419250\", \"price_changes\":[{\"asset_id\":\"69697746896130839564035629862476347944307040470122503199396727085502753297492\", \"price\":\"0.49\", \"size\":\"127\", \"side\":\"BUY\", \"hash\":\"b4f8645c2104a3d18e323c838526e530d402ec3d\", \"best_bid\":\"0.61\", \"best_ask\":\"0.62\"}, {\"asset_id\":\"60386828328910021732068595344565885737045900010034836345809386672230885527307\", \"price\":\"0.51\", \"size\":\"127\", \"side\":\"SELL\", \"hash\":\"225a72b4cdefe90f763adb68d227bc57ea41af98\", \"best_bid\":\"0.38\", \"best_ask\":\"0.39\"}], \"timestamp\":\"1785127059418\", \"event_type\":\"price_change\"}","received_at":"2026-07-27T04:37:39.374030Z","schema_version":"clob-market-ws.price_change.v1","sequence":null,"server_hash":null,"server_timestamp":"1785127059418","session_id":"e9443c7415a0419799bee9cfbb1a9e4d","source":"clob_market_ws"},"received_at":"2026-07-27T04:37:39.374030Z","record_id":"28773c668d7a740d42524a2414b7a1b8ec5d03d21af1b427ffb3560000c8eca2","schema_fingerprint":"4aa3821a28b0b7c2400bc59aba4bcc0a76e971dadd19610d3ad38c768e124dc7","schema_version":"edge-lab-recorder.raw.v1","sequence":null,"source":"clob_market_ws"}
{"event_at":"2026-07-27T04:37:39.418000Z","event_fingerprint":"adb398aa7288a92385116508b0dc48e0a2c82dbeef63baae31ca31c6c745fe35","payload":{"connection_id":"0f4979d6978d463e9660b042fdcf555f","event_at":"2026-07-27T04:37:39.418000Z","event_type":"price_change","frame_hash":"0e9f0ca09dae3c7287221052a4bc828f44b9a307aeb0642e710ca05b1435f2d5","frame_index":0,"kind":"data","monotonic_ns":229042641606458,"payload":{"event_type":"price_change","market":"0xeb66215f2e9faa6449e30a02bab5b8ed7b79a38bf961f6b24d0073c9c2419250","price_changes":[{"asset_id":"69697746896130839564035629862476347944307040470122503199396727085502753297492","best_ask":"0.62","best_bid":"0.61","hash":"b4f8645c2104a3d18e323c838526e530d402ec3d","price":"0.48","side":"BUY","size":"58"},{"asset_id":"60386828328910021732068595344565885737045900010034836345809386672230885527307","best_ask":"0.39","best_bid":"0.38","hash":"225a72b4cdefe90f763adb68d227bc57ea41af98","price":"0.52","side":"SELL","size":"58"}],"timestamp":"1785127059418"},"payload_hash":"c253b31d3ed074c05e669b8126680beefa96f174f9bbc61af87ced6e92dc5046","raw_frame":"{\"market\":\"0xeb66215f2e9faa6449e30a02bab5b8ed7b79a38bf961f6b24d0073c9c2419250\", \"price_changes\":[{\"asset_id\":\"69697746896130839564035629862476347944307040470122503199396727085502753297492\", \"price\":\"0.48\", \"size\":\"58\", \"side\":\"BUY\", \"hash\":\"b4f8645c2104a3d18e323c838526e530d402ec3d\", \"best_bid\":\"0.61\", \"best_ask\":\"0.62\"}, {\"asset_id\":\"60386828328910021732068595344565885737045900010034836345809386672230885527307\", \"price\":\"0.52\", \"size\":\"58\", \"side\":\"SELL\", \"hash\":\"225a72b4cdefe90f763adb68d227bc57ea41af98\", \"best_bid\":\"0.38\", \"best_ask\":\"0.39\"}], \"timestamp\":\"1785127059418\", \"event_type\":\"price_change\"}","received_at":"2026-07-27T04:37:39.375754Z","schema_version":"clob-market-ws.price_change.v1","sequence":null,"server_hash":null,"server_timestamp":"1785127059418","session_id":"e9443c7415a0419799bee9cfbb1a9e4d","source":"clob_market_ws"},"received_at":"2026-07-27T04:37:39.375754Z","record_id":"a2598de58a3e24a48908327eecaf95b6d8102acaffb38ac2b68abb76e836015e","schema_fingerprint":"4aa3821a28b0b7c2400bc59aba4bcc0a76e971dadd19610d3ad38c768e124dc7","schema_version":"edge-lab-recorder.raw.v1","sequence":null,"source":"clob_market_ws"}
{"event_at":"2026-07-27T04:37:39.421000Z","event_fingerprint":"dcf3e3f34ffeba8fc880286daa671e1bc97adcce8c5f0445450dbd237d86692b","payload":{"connection_id":"0f4979d6978d463e9660b042fdcf555f","event_at":"2026-07-27T04:37:39.421000Z","event_type":"price_change","frame_hash":"553f52f88333280bfa968e8afdf4b507011e6935bd49d08346cef9577736b3f4","frame_index":0,"kind":"data","monotonic_ns":229042645037541,"payload":{"event_type":"price_change","market":"0xeb66215f2e9faa6449e30a02bab5b8ed7b79a38bf961f6b24d0073c9c2419250","price_changes":[{"asset_id":"60386828328910021732068595344565885737045900010034836345809386672230885527307","best_ask":"0.39","best_bid":"0.38","hash":"9b1a9b544806c1d6eb77b5f6eb492b98fd6f34c7","price":"0.36","side":"BUY","size":"54"},{"asset_id":"69697746896130839564035629862476347944307040470122503199396727085502753297492","best_ask":"0.62","best_bid":"0.61","hash":"e50ab9a77d9390b2f3025ae1ebeefb8911363ec1","price":"0.64","side":"SELL","size":"54"}],"timestamp":"1785127059421"},"payload_hash":"9c595688af15e43edf3a5366da38c843ff0c7433f6c7834346d0ca28d6c04962","raw_frame":"{\"market\":\"0xeb66215f2e9faa6449e30a02bab5b8ed7b79a38bf961f6b24d0073c9c2419250\", \"price_changes\":[{\"asset_id\":\"60386828328910021732068595344565885737045900010034836345809386672230885527307\", \"price\":\"0.36\", \"size\":\"54\", \"side\":\"BUY\", \"hash\":\"9b1a9b544806c1d6eb77b5f6eb492b98fd6f34c7\", \"best_bid\":\"0.38\", \"best_ask\":\"0.39\"}, {\"asset_id\":\"69697746896130839564035629862476347944307040470122503199396727085502753297492\", \"price\":\"0.64\", \"size\":\"54\", \"side\":\"SELL\", \"hash\":\"e50ab9a77d9390b2f3025ae1ebeefb8911363ec1\", \"best_bid\":\"0.61\", \"best_ask\":\"0.62\"}], \"timestamp\":\"1785127059421\", \"event_type\":\"price_change\"}","received_at":"2026-07-27T04:37:39.379183Z","schema_version":"clob-market-ws.price_change.v1","sequence":null,"server_hash":null,"server_timestamp":"1785127059421","session_id":"e9443c7415a0419799bee9cfbb1a9e4d","source":"clob_market_ws"},"received_at":"2026-07-27T04:37:39.379183Z","record_id":"59e969dd9d77c86024d067f45cc445ae9a9a6e7b52dd9fd492e9c83643acea64","schema_fingerprint":"4aa3821a28b0b7c2400bc59aba4bcc0a76e971dadd19610d3ad38c768e124dc7","schema_version":"edge-lab-recorder.raw.v1","sequence":null,"source":"clob_market_ws"}
{"event_at":"2026-07-27T04:37:39.421000Z","event_fingerprint":"c1ae30d063324c2a4e78aba72562c28c09bd97c9f733d44f1d47429db67eb3e9","payload":{"connection_id":"0f4979d6978d463e9660b042fdcf555f","event_at":"2026-07-27T04:37:39.421000Z","event_type":"price_change","frame_hash":"8d798ba6c87dddc5f0740deeab846031bfe59a55cfdafa2498a26044b5be96b9","frame_index":0,"kind":"data","monotonic_ns":229042653714916,"payload":{"event_type":"price_change","market":"0xeb66215f2e9faa6449e30a02bab5b8ed7b79a38bf961f6b24d0073c9c2419250","price_changes":[{"asset_id":"60386828328910021732068595344565885737045900010034836345809386672230885527307","best_ask":"0.39","best_bid":"0.38","hash":"9b1a9b544806c1d6eb77b5f6eb492b98fd6f34c7","price":"0.35","side":"BUY","size":"437.8"},{"asset_id":"69697746896130839564035629862476347944307040470122503199396727085502753297492","best_ask":"0.62","best_bid":"0.61","hash":"e50ab9a77d9390b2f3025ae1ebeefb8911363ec1","price":"0.65","side":"SELL","size":"437.8"}],"timestamp":"1785127059421"},"payload_hash":"f90573d6f047787fc2d1e506434e25ad6eedc81ddcf0d58dfb0302660f0f6f67","raw_frame":"{\"market\":\"0xeb66215f2e9faa6449e30a02bab5b8ed7b79a38bf961f6b24d0073c9c2419250\", \"price_changes\":[{\"asset_id\":\"60386828328910021732068595344565885737045900010034836345809386672230885527307\", \"price\":\"0.35\", \"size\":\"437.8\", \"side\":\"BUY\", \"hash\":\"9b1a9b544806c1d6eb77b5f6eb492b98fd6f34c7\", \"best_bid\":\"0.38\", \"best_ask\":\"0.39\"}, {\"asset_id\":\"69697746896130839564035629862476347944307040470122503199396727085502753297492\", \"price\":\"0.65\", \"size\":\"437.8\", \"side\":\"SELL\", \"hash\":\"e50ab9a77d9390b2f3025ae1ebeefb8911363ec1\", \"best_bid\":\"0.61\", \"best_ask\":\"0.62\"}], \"timestamp\":\"1785127059421\", \"event_type\":\"price_change\"}","received_at":"2026-07-27T04:37:39.387860Z","schema_version":"clob-market-ws.price_change.v1","sequence":null,"server_hash":null,"server_timestamp":"1785127059421","session_id":"e9443c7415a0419799bee9cfbb1a9e4d","source":"clob_market_ws"},"received_at":"2026-07-27T04:37:39.387860Z","record_id":"64ec2b4d3ccbc7e2a746d26dfad78b8547fa24d84dd5c4c0191bb5aabe5e956a","schema_fingerprint":"4aa3821a28b0b7c2400bc59aba4bcc0a76e971dadd19610d3ad38c768e124dc7","schema_version":"edge-lab-recorder.raw.v1","sequence":null,"source":"clob_market_ws"}
{"event_at":"2026-07-27T04:37:39.421000Z","event_fingerprint":"c94e3adcf3d00e1675ea5fafee0bfdf0811d589b67925b659c0bfc788899ee3d","payload":{"connection_id":"0f4979d6978d463e9660b042fdcf555f","event_at":"2026-07-27T04:37:39.421000Z","event_type":"price_change","frame_hash":"1be48146321e573a53af2fdf77951f18c7b6119f57bd718c65c912993d135722","frame_index":0,"kind":"data","monotonic_ns":229042657907458,"payload":{"event_type":"price_change","market":"0xeb66215f2e9faa6449e30a02bab5b8ed7b79a38bf961f6b24d0073c9c2419250","price_changes":[{"asset_id":"60386828328910021732068595344565885737045900010034836345809386672230885527307","best_ask":"0.39","best_bid":"0.38","hash":"9b1a9b544806c1d6eb77b5f6eb492b98fd6f34c7","price":"0.37","side":"BUY","size":"0"},{"asset_id":"69697746896130839564035629862476347944307040470122503199396727085502753297492","best_ask":"0.62","best_bid":"0.61","hash":"e50ab9a77d9390b2f3025ae1ebeefb8911363ec1","price":"0.63","side":"SELL","size":"0"}],"timestamp":"1785127059421"},"payload_hash":"5b15af6be689e8630bd797bddefc887fb485e6f53aa42d16966846658cb110cc","raw_frame":"{\"market\":\"0xeb66215f2e9faa6449e30a02bab5b8ed7b79a38bf961f6b24d0073c9c2419250\", \"price_changes\":[{\"asset_id\":\"60386828328910021732068595344565885737045900010034836345809386672230885527307\", \"price\":\"0.37\", \"size\":\"0\", \"side\":\"BUY\", \"hash\":\"9b1a9b544806c1d6eb77b5f6eb492b98fd6f34c7\", \"best_bid\":\"0.38\", \"best_ask\":\"0.39\"}, {\"asset_id\":\"69697746896130839564035629862476347944307040470122503199396727085502753297492\", \"price\":\"0.63\", \"size\":\"0\", \"side\":\"SELL\", \"hash\":\"e50ab9a77d9390b2f3025ae1ebeefb8911363ec1\", \"best_bid\":\"0.61\", \"best_ask\":\"0.62\"}], \"timestamp\":\"1785127059421\", \"event_type\":\"price_change\"}","received_at":"2026-07-27T04:37:39.392054Z","schema_version":"clob-market-ws.price_change.v1","sequence":null,"server_hash":null,"server_timestamp":"1785127059421","session_id":"e9443c7415a0419799bee9cfbb1a9e4d","source":"clob_market_ws"},"received_at":"2026-07-27T04:37:39.392054Z","record_id":"3cc44c847054210caa8e9e1df6dda2e54efcc64b2fd1d3e7344f7675dc229421","schema_fingerprint":"4aa3821a28b0b7c2400bc59aba4bcc0a76e971dadd19610d3ad38c768e124dc7","schema_version":"edge-lab-recorder.raw.v1","sequence":null,"source":"clob_market_ws"}
{"event_at":"2026-07-27T04:37:39.425000Z","event_fingerprint":"2499c58b8c3ca685fd62168fb13a203c7904172a8a695bab7db679bfe04ca550","payload":{"connection_id":"0f4979d6978d463e9660b042fdcf555f","event_at":"2026-07-27T04:37:39.425000Z","event_type":"price_change","frame_hash":"14a77cf3dc7c7e8bdbf443032de5750727e1757a063469ce2d3bcadc90c2fdf2","frame_index":0,"kind":"data","monotonic_ns":229042668898833,"payload":{"event_type":"price_change","market":"0xeb66215f2e9faa6449e30a02bab5b8ed7b79a38bf961f6b24d0073c9c2419250","price_changes":[{"asset_id":"69697746896130839564035629862476347944307040470122503199396727085502753297492","best_ask":"0.62","best_bid":"0.61","hash":"d371b13c7533591459d7650537c65f3b5f8bcdd0","price":"0.04","side":"BUY","size":"608.09"},{"asset_id":"60386828328910021732068595344565885737045900010034836345809386672230885527307","best_ask":"0.39","best_bid":"0.38","hash":"b5a467b981c86079df6895a2ba6a786cbf12efc3","price":"0.96","side":"SELL","size":"608.09"}],"timestamp":"1785127059425"},"payload_hash":"604d728336098d3a82e31d3f2be66d134394028d700911433e1f55275cb72d6e","raw_frame":"{\"market\":\"0xeb66215f2e9faa6449e30a02bab5b8ed7b79a38bf961f6b24d0073c9c2419250\", \"price_changes\":[{\"asset_id\":\"69697746896130839564035629862476347944307040470122503199396727085502753297492\", \"price\":\"0.04\", \"size\":\"608.09\", \"side\":\"BUY\", \"hash\":\"d371b13c7533591459d7650537c65f3b5f8bcdd0\", \"best_bid\":\"0.61\", \"best_ask\":\"0.62\"}, {\"asset_id\":\"60386828328910021732068595344565885737045900010034836345809386672230885527307\", \"price\":\"0.96\", \"size\":\"608.09\", \"side\":\"SELL\", \"hash\":\"b5a467b981c86079df6895a2ba6a786cbf12efc3\", \"best_bid\":\"0.38\", \"best_ask\":\"0.39\"}], \"timestamp\":\"1785127059425\", \"event_type\":\"price_change\"}","received_at":"2026-07-27T04:37:39.403045Z","schema_version":"clob-market-ws.price_change.v1","sequence":null,"server_hash":null,"server_timestamp":"1785127059425","session_id":"e9443c7415a0419799bee9cfbb1a9e4d","source":"clob_market_ws"},"received_at":"2026-07-27T04:37:39.403045Z","record_id":"b1894dee69a62af32351f575c22aa49f98d40618a6fd2886409e6fa42f467d98","schema_fingerprint":"4aa3821a28b0b7c2400bc59aba4bcc0a76e971dadd19610d3ad38c768e124dc7","schema_version":"edge-lab-recorder.raw.v1","sequence":null,"source":"clob_market_ws"}
{"event_at":"2026-07-27T04:37:39.426000Z","event_fingerprint":"b9324527e9e318032ae9f6b3562b27bcd206ae0352d309ab81cbba00d62d9fa6","payload":{"connection_id":"0f4979d6978d463e9660b042fdcf555f","event_at":"2026-07-27T04:37:39.426000Z","event_type":"price_change","frame_hash":"295db64c5ed5e0e953733e2ba740c0fac53f3c87519e280dea92f45f1d96755b","frame_index":0,"kind":"data","monotonic_ns":229042672517875,"payload":{"event_type":"price_change","market":"0xeb66215f2e9faa6449e30a02bab5b8ed7b79a38bf961f6b24d0073c9c2419250","price_changes":[{"asset_id":"69697746896130839564035629862476347944307040470122503199396727085502753297492","best_ask":"0.62","best_bid":"0.61","hash":"2f2b81a63278b86ae65765fba49ccee1e288455f","price":"0.52","side":"BUY","size":"62"},{"asset_id":"60386828328910021732068595344565885737045900010034836345809386672230885527307","best_ask":"0.39","best_bid":"0.38","hash":"6a77e33711bea4a9dc42c0161d18e929974e129d","price":"0.48","side":"SELL","size":"62"}],"timestamp":"1785127059426"},"payload_hash":"e898ec15da780141cb00e4ea1f003288c559bfaeafe24287655d3fb52203232b","raw_frame":"{\"market\":\"0xeb66215f2e9faa6449e30a02bab5b8ed7b79a38bf961f6b24d0073c9c2419250\", \"price_changes\":[{\"asset_id\":\"69697746896130839564035629862476347944307040470122503199396727085502753297492\", \"price\":\"0.52\", \"size\":\"62\", \"side\":\"BUY\", \"hash\":\"2f2b81a63278b86ae65765fba49ccee1e288455f\", \"best_bid\":\"0.61\", \"best_ask\":\"0.62\"}, {\"asset_id\":\"60386828328910021732068595344565885737045900010034836345809386672230885527307\", \"price\":\"0.48\", \"size\":\"62\", \"side\":\"SELL\", \"hash\":\"6a77e33711bea4a9dc42c0161d18e929974e129d\", \"best_bid\":\"0.38\", \"best_ask\":\"0.39\"}], \"timestamp\":\"1785127059426\", \"event_type\":\"price_change\"}","received_at":"2026-07-27T04:37:39.406664Z","schema_version":"clob-market-ws.price_change.v1","sequence":null,"server_hash":null,"server_timestamp":"1785127059426","session_id":"e9443c7415a0419799bee9cfbb1a9e4d","source":"clob_market_ws"},"received_at":"2026-07-27T04:37:39.406664Z","record_id":"aa58081f43fa2b9824c6e27ee3c35b06402f423edba1d3afc0b72cfbd060e3a9","schema_fingerprint":"4aa3821a28b0b7c2400bc59aba4bcc0a76e971dadd19610d3ad38c768e124dc7","schema_version":"edge-lab-recorder.raw.v1","sequence":null,"source":"clob_market_ws"}
{"event_at":"2026-07-27T04:37:39.427000Z","event_fingerprint":"7d969bbc6bd2642ce3b86eeda5e97fb20cd535d8d4250aea25da52c0822554ae","payload":{"connection_id":"0f4979d6978d463e9660b042fdcf555f","event_at":"2026-07-27T04:37:39.427000Z","event_type":"price_change","frame_hash":"fab6507f7deca52b37b71eb5ee9f0606096cd0100eabc52b33d81fd3848f9425","frame_index":0,"kind":"data","monotonic_ns":229042675611625,"payload":{"event_type":"price_change","market":"0xeb66215f2e9faa6449e30a02bab5b8ed7b79a38bf961f6b24d0073c9c2419250","price_changes":[{"asset_id":"60386828328910021732068595344565885737045900010034836345809386672230885527307","best_ask":"0.39","best_bid":"0.38","hash":"55be5bec27ba1fd676f3b1b2fa8c21870717f67a","price":"0.22","side":"BUY","size":"72.07"},{"asset_id":"69697746896130839564035629862476347944307040470122503199396727085502753297492","best_ask":"0.62","best_bid":"0.61","hash":"e307d2d7a574ff8871abbd229409fa5bee20bd9f","price":"0.78","side":"SELL","size":"72.07"}],"timestamp":"1785127059427"},"payload_hash":"b596adee68851e71a1278429578762a8549bd9ac48e2cf01e02239f11dc06e6f","raw_frame":"{\"market\":\"0xeb66215f2e9faa6449e30a02bab5b8ed7b79a38bf961f6b24d0073c9c2419250\", \"price_changes\":[{\"asset_id\":\"60386828328910021732068595344565885737045900010034836345809386672230885527307\", \"price\":\"0.22\", \"size\":\"72.07\", \"side\":\"BUY\", \"hash\":\"55be5bec27ba1fd676f3b1b2fa8c21870717f67a\", \"best_bid\":\"0.38\", \"best_ask\":\"0.39\"}, {\"asset_id\":\"69697746896130839564035629862476347944307040470122503199396727085502753297492\", \"price\":\"0.78\", \"size\":\"72.07\", \"side\":\"SELL\", \"hash\":\"e307d2d7a574ff8871abbd229409fa5bee20bd9f\", \"best_bid\":\"0.61\", \"best_ask\":\"0.62\"}], \"timestamp\":\"1785127059427\", \"event_type\":\"price_change\"}","received_at":"2026-07-27T04:37:39.409759Z","schema_version":"clob-market-ws.price_change.v1","sequence":null,"server_hash":null,"server_timestamp":"1785127059427","session_id":"e9443c7415a0419799bee9cfbb1a9e4d","source":"clob_market_ws"},"received_at":"2026-07-27T04:37:39.409759Z","record_id":"3f21637ae17601a0fb913d01994fa26bef3b0f077e108ce455eef20a80cd0501","schema_fingerprint":"4aa3821a28b0b7c2400bc59aba4bcc0a76e971dadd19610d3ad38c768e124dc7","schema_version":"edge-lab-recorder.raw.v1","sequence":null,"source":"clob_market_ws"}
{"event_at":"2026-07-27T04:37:39.428000Z","event_fingerprint":"63bae9428946a586142e20a92e7cf9c0305f4d1d00fa642f17ad7c1f2cbe42ef","payload":{"connection_id":"0f4979d6978d463e9660b042fdcf555f","event_at":"2026-07-27T04:37:39.428000Z","event_type":"price_change","frame_hash":"0c3eeea8e87be1c2701ac72bb85265a88fc677aa4b5ce67e73744a2323eab22e","frame_index":0,"kind":"data","monotonic_ns":229042678591666,"payload":{"event_type":"price_change","market":"0xeb66215f2e9faa6449e30a02bab5b8ed7b79a38bf961f6b24d0073c9c2419250","price_changes":[{"asset_id":"69697746896130839564035629862476347944307040470122503199396727085502753297492","best_ask":"0.62","best_bid":"0.61","hash":"0f0699f7bb53ba69632af7694b19616368882517","price":"0.57","side":"BUY","size":"38.16"},{"asset_id":"60386828328910021732068595344565885737045900010034836345809386672230885527307","best_ask":"0.39","best_bid":"0.38","hash":"844a6db387d7fb9c7ba23b72e00e7d3b142df375","price":"0.43","side":"SELL","size":"38.16"}],"timestamp":"1785127059428"},"payload_hash":"925ebc4006db1efe4f4de5efd5d8accf49d011abbb5c2db5dbd5f28d424b1579","raw_frame":"{\"market\":\"0xeb66215f2e9faa6449e30a02bab5b8ed7b79a38bf961f6b24d0073c9c2419250\", \"price_changes\":[{\"asset_id\":\"69697746896130839564035629862476347944307040470122503199396727085502753297492\", \"price\":\"0.57\", \"size\":\"38.16\", \"side\":\"BUY\", \"hash\":\"0f0699f7bb53ba69632af7694b19616368882517\", \"best_bid\":\"0.61\", \"best_ask\":\"0.62\"}, {\"asset_id\":\"60386828328910021732068595344565885737045900010034836345809386672230885527307\", \"price\":\"0.43\", \"size\":\"38.16\", \"side\":\"SELL\", \"hash\":\"844a6db387d7fb9c7ba23b72e00e7d3b142df375\", \"best_bid\":\"0.38\", \"best_ask\":\"0.39\"}], \"timestamp\":\"1785127059428\", \"event_type\":\"price_change\"}","received_at":"2026-07-27T04:37:39.412739Z","schema_version":"clob-market-ws.price_change.v1","sequence":null,"server_hash":null,"server_timestamp":"1785127059428","session_id":"e9443c7415a0419799bee9cfbb1a9e4d","source":"clob_market_ws"},"received_at":"2026-07-27T04:37:39.412739Z","record_id":"9630d385e33876fd47e6afab176a4ea00afb7f52547d045ede4fa629da35f6c2","schema_fingerprint":"4aa3821a28b0b7c2400bc59aba4bcc0a76e971dadd19610d3ad38c768e124dc7","schema_version":"edge-lab-recorder.raw.v1","sequence":null,"source":"clob_market_ws"}
{"event_at":"2026-07-27T04:37:39.428000Z","event_fingerprint":"795566c888282c80325a0d487a839b84955d1992471f65af4acca7bf5da61a88","payload":{"connection_id":"0f4979d6978d463e9660b042fdcf555f","event_at":"2026-07-27T04:37:39.428000Z","event_type":"price_change","frame_hash":"21f19a795426e1544fd952c1ca68d90d3f42fbdf1dd38b609aa913f295ca5697","frame_index":0,"kind":"data","monotonic_ns":229042681631833,"payload":{"event_type":"price_change","market":"0xeb66215f2e9faa6449e30a02bab5b8ed7b79a38bf961f6b24d0073c9c2419250","price_changes":[{"asset_id":"60386828328910021732068595344565885737045900010034836345809386672230885527307","best_ask":"0.39","best_bid":"0.38","hash":"844a6db387d7fb9c7ba23b72e00e7d3b142df375","price":"0.32","side":"BUY","size":"135"},{"asset_id":"69697746896130839564035629862476347944307040470122503199396727085502753297492","best_ask":"0.62","best_bid":"0.61","hash":"0f0699f7bb53ba69632af7694b19616368882517","price":"0.68","side":"SELL","size":"135"}],"timestamp":"1785127059428"},"payload_hash":"0b91e743a5fc607b376260830a466352a8408bcb5b29beab2e2483ff6232137b","raw_frame":"{\"market\":\"0xeb66215f2e9faa6449e30a02bab5b8ed7b79a38bf961f6b24d0073c9c2419250\", \"price_changes\":[{\"asset_id\":\"60386828328910021732068595344565885737045900010034836345809386672230885527307\", \"price\":\"0.32\", \"size\":\"135\", \"side\":\"BUY\", \"hash\":\"844a6db387d7fb9c7ba23b72e00e7d3b142df375\", \"best_bid\":\"0.38\", \"best_ask\":\"0.39\"}, {\"asset_id\":\"69697746896130839564035629862476347944307040470122503199396727085502753297492\", \"price\":\"0.68\", \"size\":\"135\", \"side\":\"SELL\", \"hash\":\"0f0699f7bb53ba69632af7694b19616368882517\", \"best_bid\":\"0.61\", \"best_ask\":\"0.62\"}], \"timestamp\":\"1785127059428\", \"event_type\":\"price_change\"}","received_at":"2026-07-27T04:37:39.415780Z","schema_version":"clob-market-ws.price_change.v1","sequence":null,"server_hash":null,"server_timestamp":"1785127059428","session_id":"e9443c7415a0419799bee9cfbb1a9e4d","source":"clob_market_ws"},"received_at":"2026-07-27T04:37:39.415780Z","record_id":"bddae13d1a8117c298c32e915104312d67a7602b89997a16a4bfffeefd3ac965","schema_fingerprint":"4aa3821a28b0b7c2400bc59aba4bcc0a76e971dadd19610d3ad38c768e124dc7","schema_version":"edge-lab-recorder.raw.v1","sequence":null,"source":"clob_market_ws"}
{"event_at":"2026-07-27T04:37:39.429000Z","event_fingerprint":"44e76a3ea71e56e5dc1b3d7156c9c80ac66e67d19b922e2f6ff87a7eed95f0a7","payload":{"connection_id":"0f4979d6978d463e9660b042fdcf555f","event_at":"2026-07-27T04:37:39.429000Z","event_type":"price_change","frame_hash":"662e92accb3f049ab1045d4342698161b62d8e699031868beb13317f0cdb5e0f","frame_index":0,"kind":"data","monotonic_ns":229042684609000,"payload":{"event_type":"price_change","market":"0xeb66215f2e9faa6449e30a02bab5b8ed7b79a38bf961f6b24d0073c9c2419250","price_changes":[{"asset_id":"60386828328910021732068595344565885737045900010034836345809386672230885527307","best_ask":"0.39","best_bid":"0.38","hash":"a6893eeee3eb8d03b76e578f5e92c773df97a5bc","price":"0.23","side":"BUY","size":"107"},{"asset_id":"69697746896130839564035629862476347944307040470122503199396727085502753297492","best_ask":"0.62","best_bid":"0.61","hash":"9b3ca41d49ba240dbe62d4620dfe60ade23b866d","price":"0.77","side":"SELL","size":"107"}],"timestamp":"1785127059429"},"payload_hash":"3fa02f9684c7685e935eb66fd925094fbe5caca34dcd686c8a5ec17e7df8d316","raw_frame":"{\"market\":\"0xeb66215f2e9faa6449e30a02bab5b8ed7b79a38bf961f6b24d0073c9c2419250\", \"price_changes\":[{\"asset_id\":\"60386828328910021732068595344565885737045900010034836345809386672230885527307\", \"price\":\"0.23\", \"size\":\"107\", \"side\":\"BUY\", \"hash\":\"a6893eeee3eb8d03b76e578f5e92c773df97a5bc\", \"best_bid\":\"0.38\", \"best_ask\":\"0.39\"}, {\"asset_id\":\"69697746896130839564035629862476347944307040470122503199396727085502753297492\", \"price\":\"0.77\", \"size\":\"107\", \"side\":\"SELL\", \"hash\":\"9b3ca41d49ba240dbe62d4620dfe60ade23b866d\", \"best_bid\":\"0.61\", \"best_ask\":\"0.62\"}], \"timestamp\":\"1785127059429\", \"event_type\":\"price_change\"}","received_at":"2026-07-27T04:37:39.418755Z","schema_version":"clob-market-ws.price_change.v1","sequence":null,"server_hash":null,"server_timestamp":"1785127059429","session_id":"e9443c7415a0419799bee9cfbb1a9e4d","source":"clob_market_ws"},"received_at":"2026-07-27T04:37:39.418755Z","record_id":"e0d64dfc3fc1f64194726a5447cedcc6e8b8412b236b6b9f4d599ee74ead6919","schema_fingerprint":"4aa3821a28b0b7c2400bc59aba4bcc0a76e971dadd19610d3ad38c768e124dc7","schema_version":"edge-lab-recorder.raw.v1","sequence":null,"source":"clob_market_ws"}
{"event_at":"2026-07-27T04:37:39.429000Z","event_fingerprint":"5c5ae2efe6bce4ebec1384a025bbf344f46c6bdcb01fafc2dfca766a2df5206e","payload":{"connection_id":"0f4979d6978d463e9660b042fdcf555f","event_at":"2026-07-27T04:37:39.429000Z","event_type":"price_change","frame_hash":"a0b37fb8344b7bc63fe9c0da862380f9f26a4c7fce3f662dbe35a365dcebfb82","frame_index":0,"kind":"data","monotonic_ns":229042687899625,"payload":{"event_type":"price_change","market":"0xeb66215f2e9faa6449e30a02bab5b8ed7b79a38bf961f6b24d0073c9c2419250","price_changes":[{"asset_id":"60386828328910021732068595344565885737045900010034836345809386672230885527307","best_ask":"0.39","best_bid":"0.38","hash":"a6893eeee3eb8d03b76e578f5e92c773df97a5bc","price":"0.24","side":"BUY","size":"137"},{"asset_id":"69697746896130839564035629862476347944307040470122503199396727085502753297492","best_ask":"0.62","best_bid":"0.61","hash":"9b3ca41d49ba240dbe62d4620dfe60ade23b866d","price":"0.76","side":"SELL","size":"137"}],"timestamp":"1785127059429"},"payload_hash":"fa5d0f3b3be8476ecb7eb8b17b74b6f55a3007a52568afeba26ba6abb9703712","raw_frame":"{\"market\":\"0xeb66215f2e9faa6449e30a02bab5b8ed7b79a38bf961f6b24d0073c9c2419250\", \"price_changes\":[{\"asset_id\":\"60386828328910021732068595344565885737045900010034836345809386672230885527307\", \"price\":\"0.24\", \"size\":\"137\", \"side\":\"BUY\", \"hash\":\"a6893eeee3eb8d03b76e578f5e92c773df97a5bc\", \"best_bid\":\"0.38\", \"best_ask\":\"0.39\"}, {\"asset_id\":\"69697746896130839564035629862476347944307040470122503199396727085502753297492\", \"price\":\"0.76\", \"size\":\"137\", \"side\":\"SELL\", \"hash\":\"9b3ca41d49ba240dbe62d4620dfe60ade23b866d\", \"best_bid\":\"0.61\", \"best_ask\":\"0.62\"}], \"timestamp\":\"1785127059429\", \"event_type\":\"price_change\"}","received_at":"2026-07-27T04:37:39.422047Z","schema_version":"clob-market-ws.price_change.v1","sequence":null,"server_hash":null,"server_timestamp":"1785127059429","session_id":"e9443c7415a0419799bee9cfbb1a9e4d","source":"clob_market_ws"},"received_at":"2026-07-27T04:37:39.422047Z","record_id":"55ef78c6fe86677b23e8ef5d32c69dc34ba69463e928d7e5ff9328dfd3cbd5f6","schema_fingerprint":"4aa3821a28b0b7c2400bc59aba4bcc0a76e971dadd19610d3ad38c768e124dc7","schema_version":"edge-lab-recorder.raw.v1","sequence":null,"source":"clob_market_ws"}
{"event_at":"2026-07-27T04:37:39.433000Z","event_fingerprint":"15d102719777dac09820bd72db109283cad3d25dc484968936548a54b60b1aa0","payload":{"connection_id":"0f4979d6978d463e9660b042fdcf555f","event_at":"2026-07-27T04:37:39.433000Z","event_type":"price_change","frame_hash":"d6c8270613e937326558ad8a0fc0cb7105250f8e76e291b311870053dcbb4908","frame_index":0,"kind":"data","monotonic_ns":229042690917375,"payload":{"event_type":"price_change","market":"0xeb66215f2e9faa6449e30a02bab5b8ed7b79a38bf961f6b24d0073c9c2419250","price_changes":[{"asset_id":"60386828328910021732068595344565885737045900010034836345809386672230885527307","best_ask":"0.39","best_bid":"0.38","hash":"3f7f31c41c0ae7759fdfcc4484e68bf921d45e8f","price":"0.22","side":"BUY","size":"64.5"},{"asset_id":"69697746896130839564035629862476347944307040470122503199396727085502753297492","best_ask":"0.62","best_bid":"0.61","hash":"320098d24e28312148ba2c3093f696d36cac9831","price":"0.78","side":"SELL","size":"64.5"}],"timestamp":"1785127059433"},"payload_hash":"5d4d46fdef88c0c192524a5ec65d534cd591580962c3abf9d3053ba47ebd4d54","raw_frame":"{\"market\":\"0xeb66215f2e9faa6449e30a02bab5b8ed7b79a38bf961f6b24d0073c9c2419250\", \"price_changes\":[{\"asset_id\":\"60386828328910021732068595344565885737045900010034836345809386672230885527307\", \"price\":\"0.22\", \"size\":\"64.5\", \"side\":\"BUY\", \"hash\":\"3f7f31c41c0ae7759fdfcc4484e68bf921d45e8f\", \"best_bid\":\"0.38\", \"best_ask\":\"0.39\"}, {\"asset_id\":\"69697746896130839564035629862476347944307040470122503199396727085502753297492\", \"price\":\"0.78\", \"size\":\"64.5\", \"side\":\"SELL\", \"hash\":\"320098d24e28312148ba2c3093f696d36cac9831\", \"best_bid\":\"0.61\", \"best_ask\":\"0.62\"}], \"timestamp\":\"1785127059433\", \"event_type\":\"price_change\"}","received_at":"2026-07-27T04:37:39.425065Z","schema_version":"clob-market-ws.price_change.v1","sequence":null,"server_hash":null,"server_timestamp":"1785127059433","session_id":"e9443c7415a0419799bee9cfbb1a9e4d","source":"clob_market_ws"},"received_at":"2026-07-27T04:37:39.425065Z","record_id":"691b7f9bb6060a2ffb4efd3c8e89716fd8da6b2d172be456a5081107c9be83e7","schema_fingerprint":"4aa3821a28b0b7c2400bc59aba4bcc0a76e971dadd19610d3ad38c768e124dc7","schema_version":"edge-lab-recorder.raw.v1","sequence":null,"source":"clob_market_ws"}
{"event_at":"2026-07-27T04:37:39.437000Z","event_fingerprint":"761cda73987a05567f829dea7745a18ddd3b20ea57e529f5a58fea1f60ff6787","payload":{"connection_id":"0f4979d6978d463e9660b042fdcf555f","event_at":"2026-07-27T04:37:39.437000Z","event_type":"price_change","frame_hash":"634468308562acd10a1779d185babb1385d1d1f5a7724743602d3c5f8cc21287","frame_index":0,"kind":"data","monotonic_ns":229042693846750,"payload":{"event_type":"price_change","market":"0xeb66215f2e9faa6449e30a02bab5b8ed7b79a38bf961f6b24d0073c9c2419250","price_changes":[{"asset_id":"60386828328910021732068595344565885737045900010034836345809386672230885527307","best_ask":"0.39","best_bid":"0.38","hash":"babff70605cd9d8704731e8aefa109be897523f2","price":"0.23","side":"BUY","size":"251.91"},{"asset_id":"69697746896130839564035629862476347944307040470122503199396727085502753297492","best_ask":"0.62","best_bid":"0.61","hash":"17a41a8e62fc20c16dcd198b402a881b5856e284","price":"0.77","side":"SELL","size":"251.91"}],"timestamp":"1785127059437"},"payload_hash":"6c7adb843369c8ce0a562081dd639c3e3368c1edcc85fd9fb3d49d4ab3ab8558","raw_frame":"{\"market\":\"0xeb66215f2e9faa6449e30a02bab5b8ed7b79a38bf961f6b24d0073c9c2419250\", \"price_changes\":[{\"asset_id\":\"60386828328910021732068595344565885737045900010034836345809386672230885527307\", \"price\":\"0.23\", \"size\":\"251.91\", \"side\":\"BUY\", \"hash\":\"babff70605cd9d8704731e8aefa109be897523f2\", \"best_bid\":\"0.38\", \"best_ask\":\"0.39\"}, {\"asset_id\":\"69697746896130839564035629862476347944307040470122503199396727085502753297492\", \"price\":\"0.77\", \"size\":\"251.91\", \"side\":\"SELL\", \"hash\":\"17a41a8e62fc20c16dcd198b402a881b5856e284\", \"best_bid\":\"0.61\", \"best_ask\":\"0.62\"}], \"timestamp\":\"1785127059437\", \"event_type\":\"price_change\"}","received_at":"2026-07-27T04:37:39.427995Z","schema_version":"clob-market-ws.price_change.v1","sequence":null,"server_hash":null,"server_timestamp":"1785127059437","session_id":"e9443c7415a0419799bee9cfbb1a9e4d","source":"clob_market_ws"},"received_at":"2026-07-27T04:37:39.427995Z","record_id":"7d59439ad5e16c51369f3ff4edc5a3b81665984416922df0c253f903f22545d4","schema_fingerprint":"4aa3821a28b0b7c2400bc59aba4bcc0a76e971dadd19610d3ad38c768e124dc7","schema_version":"edge-lab-recorder.raw.v1","sequence":null,"source":"clob_market_ws"}
{"event_at":"2026-07-27T04:37:39.439000Z","event_fingerprint":"278b5f891832053e2413e3c0088a301bb583a8706777db46730e827e777f351a","payload":{"connection_id":"0f4979d6978d463e9660b042fdcf555f","event_at":"2026-07-27T04:37:39.439000Z","event_type":"price_change","frame_hash":"2a811bb23cf48473e6f50e3bbbbae56dec6d692818a2f8d1c4e94bea82a96905","frame_index":0,"kind":"data","monotonic_ns":229042697585958,"payload":{"event_type":"price_change","market":"0xeb66215f2e9faa6449e30a02bab5b8ed7b79a38bf961f6b24d0073c9c2419250","price_changes":[{"asset_id":"60386828328910021732068595344565885737045900010034836345809386672230885527307","best_ask":"0.39","best_bid":"0.38","hash":"db0d2c8fa4a93d3ce196da63bc87497852a07e21","price":"0.31","side":"BUY","size":"30"},{"asset_id":"69697746896130839564035629862476347944307040470122503199396727085502753297492","best_ask":"0.62","best_bid":"0.61","hash":"11b073c40b898d267bb718b1ec016c209dbd1b47","price":"0.69","side":"SELL","size":"30"}],"timestamp":"1785127059439"},"payload_hash":"e8de1bfd8dd5085c1066e9e807f78041189deae0a848dcb58261c1d472c087c4","raw_frame":"{\"market\":\"0xeb66215f2e9faa6449e30a02bab5b8ed7b79a38bf961f6b24d0073c9c2419250\", \"price_changes\":[{\"asset_id\":\"60386828328910021732068595344565885737045900010034836345809386672230885527307\", \"price\":\"0.31\", \"size\":\"30\", \"side\":\"BUY\", \"hash\":\"db0d2c8fa4a93d3ce196da63bc87497852a07e21\", \"best_bid\":\"0.38\", \"best_ask\":\"0.39\"}, {\"asset_id\":\"69697746896130839564035629862476347944307040470122503199396727085502753297492\", \"price\":\"0.69\", \"size\":\"30\", \"side\":\"SELL\", \"hash\":\"11b073c40b898d267bb718b1ec016c209dbd1b47\", \"best_bid\":\"0.61\", \"best_ask\":\"0.62\"}], \"timestamp\":\"1785127059439\", \"event_type\":\"price_change\"}","received_at":"2026-07-27T04:37:39.431735Z","schema_version":"clob-market-ws.price_change.v1","sequence":null,"server_hash":null,"server_timestamp":"1785127059439","session_id":"e9443c7415a0419799bee9cfbb1a9e4d","source":"clob_market_ws"},"received_at":"2026-07-27T04:37:39.431735Z","record_id":"75b52ec1adef241dd3b8ff4b65c47a0a6ba8c20c6abfeb6265f06e2f931ac8ee","schema_fingerprint":"4aa3821a28b0b7c2400bc59aba4bcc0a76e971dadd19610d3ad38c768e124dc7","schema_version":"edge-lab-recorder.raw.v1","sequence":null,"source":"clob_market_ws"}
{"event_at":"2026-07-27T04:37:39.441000Z","event_fingerprint":"64b04dd7efa7be6606310dce1be3b4c4612e3b28081cc617546480d1fb7dbebe","payload":{"connection_id":"0f4979d6978d463e9660b042fdcf555f","event_at":"2026-07-27T04:37:39.441000Z","event_type":"price_change","frame_hash":"a3dbb3d777306e6369ec218cf7b2d8087d86ed41267fdd9dd23eea0239285d1d","frame_index":0,"kind":"data","monotonic_ns":229042699882583,"payload":{"event_type":"price_change","market":"0xeb66215f2e9faa6449e30a02bab5b8ed7b79a38bf961f6b24d0073c9c2419250","price_changes":[{"asset_id":"69697746896130839564035629862476347944307040470122503199396727085502753297492","best_ask":"0.62","best_bid":"0.61","hash":"e6a3c16af871ef9888d816e4c1c446befcc03ac1","price":"0.47","side":"BUY","size":"87.92"},{"asset_id":"60386828328910021732068595344565885737045900010034836345809386672230885527307","best_ask":"0.39","best_bid":"0.38","hash":"872e50060d734fd1e79313aafced13dcaf22560a","price":"0.53","side":"SELL","size":"87.92"}],"timestamp":"1785127059441"},"payload_hash":"370542ec53065fd7f772a1b2a8e0b7a5936d4895afc6c9e98978b59f68f25638","raw_frame":"{\"market\":\"0xeb66215f2e9faa6449e30a02bab5b8ed7b79a38bf961f6b24d0073c9c2419250\", \"price_changes\":[{\"asset_id\":\"69697746896130839564035629862476347944307040470122503199396727085502753297492\", \"price\":\"0.47\", \"size\":\"87.92\", \"side\":\"BUY\", \"hash\":\"e6a3c16af871ef9888d816e4c1c446befcc03ac1\", \"best_bid\":\"0.61\", \"best_ask\":\"0.62\"}, {\"asset_id\":\"60386828328910021732068595344565885737045900010034836345809386672230885527307\", \"price\":\"0.53\", \"size\":\"87.92\", \"side\":\"SELL\", \"hash\":\"872e50060d734fd1e79313aafced13dcaf22560a\", \"best_bid\":\"0.38\", \"best_ask\":\"0.39\"}], \"timestamp\":\"1785127059441\", \"event_type\":\"price_change\"}","received_at":"2026-07-27T04:37:39.434030Z","schema_version":"clob-market-ws.price_change.v1","sequence":null,"server_hash":null,"server_timestamp":"1785127059441","session_id":"e9443c7415a0419799bee9cfbb1a9e4d","source":"clob_market_ws"},"received_at":"2026-07-27T04:37:39.434030Z","record_id":"cf03ec86eb87c734fe0079601710f7a8b89d68ce1dbc182ed67a26d8059ab0e6","schema_fingerprint":"4aa3821a28b0b7c2400bc59aba4bcc0a76e971dadd19610d3ad38c768e124dc7","schema_version":"edge-lab-recorder.raw.v1","sequence":null,"source":"clob_market_ws"}
{"event_at":"2026-07-27T04:37:39.444000Z","event_fingerprint":"6add4bd472e7a05279c5df574b74e20e254ec4fc991d4e2e9b94a0a9011f3964","payload":{"connection_id":"0f4979d6978d463e9660b042fdcf555f","event_at":"2026-07-27T04:37:39.444000Z","event_type":"price_change","frame_hash":"0d7c86f72a378398ec477203f6567d766a51858915424e5f7565375f813e2202","frame_index":0,"kind":"data","monotonic_ns":229042703384750,"payload":{"event_type":"price_change","market":"0xeb66215f2e9faa6449e30a02bab5b8ed7b79a38bf961f6b24d0073c9c2419250","price_changes":[{"asset_id":"60386828328910021732068595344565885737045900010034836345809386672230885527307","best_ask":"0.39","best_bid":"0.38","hash":"89411b67e6d30056178f0ee0fa80ed8fa7a93fe0","price":"0.42","side":"SELL","size":"44.4"},{"asset_id":"69697746896130839564035629862476347944307040470122503199396727085502753297492","best_ask":"0.62","best_bid":"0.61","hash":"07d7cd820872c66556d7bced96b3834903598b83","price":"0.58","side":"BUY","size":"44.4"}],"timestamp":"1785127059444"},"payload_hash":"1ca238aa27bc422ec75db5c01919c9da183ea22d73b10583cc15ff0457c4d22e","raw_frame":"{\"market\":\"0xeb66215f2e9faa6449e30a02bab5b8ed7b79a38bf961f6b24d0073c9c2419250\", \"price_changes\":[{\"asset_id\":\"60386828328910021732068595344565885737045900010034836345809386672230885527307\", \"price\":\"0.42\", \"size\":\"44.4\", \"side\":\"SELL\", \"hash\":\"89411b67e6d30056178f0ee0fa80ed8fa7a93fe0\", \"best_bid\":\"0.38\", \"best_ask\":\"0.39\"}, {\"asset_id\":\"69697746896130839564035629862476347944307040470122503199396727085502753297492\", \"price\":\"0.58\", \"size\":\"44.4\", \"side\":\"BUY\", \"hash\":\"07d7cd820872c66556d7bced96b3834903598b83\", \"best_bid\":\"0.61\", \"best_ask\":\"0.62\"}], \"timestamp\":\"1785127059444\", \"event_type\":\"price_change\"}","received_at":"2026-07-27T04:37:39.437530Z","schema_version":"clob-market-ws.price_change.v1","sequence":null,"server_hash":null,"server_timestamp":"1785127059444","session_id":"e9443c7415a0419799bee9cfbb1a9e4d","source":"clob_market_ws"},"received_at":"2026-07-27T04:37:39.437530Z","record_id":"864cf4a27de073f693979fa0d9618ec309ea204255133fa190de305c80a5d3cd","schema_fingerprint":"4aa3821a28b0b7c2400bc59aba4bcc0a76e971dadd19610d3ad38c768e124dc7","schema_version":"edge-lab-recorder.raw.v1","sequence":null,"source":"clob_market_ws"}
{"event_at":"2026-07-27T04:37:39.447000Z","event_fingerprint":"c5a480e95b00c6e15ef7ea4650485fb2fb7905beaba940462ddf9274891c0e6a","payload":{"connection_id":"0f4979d6978d463e9660b042fdcf555f","event_at":"2026-07-27T04:37:39.447000Z","event_type":"price_change","frame_hash":"faec86bf61bc20ab26e3087be90df5274569a63e34061baa52b7882c365d6e01","frame_index":0,"kind":"data","monotonic_ns":229042707130500,"payload":{"event_type":"price_change","market":"0xeb66215f2e9faa6449e30a02bab5b8ed7b79a38bf961f6b24d0073c9c2419250","price_changes":[{"asset_id":"69697746896130839564035629862476347944307040470122503199396727085502753297492","best_ask":"0.62","best_bid":"0.61","hash":"43082dea1007960686dd6212d8ad42d61d2e983d","price":"0.53","side":"BUY","size":"57"},{"asset_id":"60386828328910021732068595344565885737045900010034836345809386672230885527307","best_ask":"0.39","best_bid":"0.38","hash":"01ca89b252e176c7cd3f7117991926b68a8d10c5","price":"0.47","side":"SELL","size":"57"}],"timestamp":"1785127059447"},"payload_hash":"8a47e8c8012c83d39f627cdd3b09516b834464506f81bc6f9ad4ec461da2fd67","raw_frame":"{\"market\":\"0xeb66215f2e9faa6449e30a02bab5b8ed7b79a38bf961f6b24d0073c9c2419250\", \"price_changes\":[{\"asset_id\":\"69697746896130839564035629862476347944307040470122503199396727085502753297492\", \"price\":\"0.53\", \"size\":\"57\", \"side\":\"BUY\", \"hash\":\"43082dea1007960686dd6212d8ad42d61d2e983d\", \"best_bid\":\"0.61\", \"best_ask\":\"0.62\"}, {\"asset_id\":\"60386828328910021732068595344565885737045900010034836345809386672230885527307\", \"price\":\"0.47\", \"size\":\"57\", \"side\":\"SELL\", \"hash\":\"01ca89b252e176c7cd3f7117991926b68a8d10c5\", \"best_bid\":\"0.38\", \"best_ask\":\"0.39\"}], \"timestamp\":\"1785127059447\", \"event_type\":\"price_change\"}","received_at":"2026-07-27T04:37:39.441279Z","schema_version":"clob-market-ws.price_change.v1","sequence":null,"server_hash":null,"server_timestamp":"1785127059447","session_id":"e9443c7415a0419799bee9cfbb1a9e4d","source":"clob_market_ws"},"received_at":"2026-07-27T04:37:39.441279Z","record_id":"0e7af60acb149d74745fd2d9edd43c8ed6de4bda3e3cd8537bdffd682c887fe9","schema_fingerprint":"4aa3821a28b0b7c2400bc59aba4bcc0a76e971dadd19610d3ad38c768e124dc7","schema_version":"edge-lab-recorder.raw.v1","sequence":null,"source":"clob_market_ws"}
{"event_at":"2026-07-27T04:37:39.448000Z","event_fingerprint":"c9e6c456c35869bd7462b278c781a520464916649c63f9c5e5084b36f8f3d85f","payload":{"connection_id":"0f4979d6978d463e9660b042fdcf555f","event_at":"2026-07-27T04:37:39.448000Z","event_type":"price_change","frame_hash":"cea991fb3288922cb02e4cf7c85bbf25449d234eea8cc312de1d41a5d82fdfbc","frame_index":0,"kind":"data","monotonic_ns":229042710987791,"payload":{"event_type":"price_change","market":"0xeb66215f2e9faa6449e30a02bab5b8ed7b79a38bf961f6b24d0073c9c2419250","price_changes":[{"asset_id":"69697746896130839564035629862476347944307040470122503199396727085502753297492","best_ask":"0.62","best_bid":"0.61","hash":"96e3325f42d77833df4c902ed26f7b1fbd7d63f3","price":"0.43","side":"BUY","size":"147.2"},{"asset_id":"60386828328910021732068595344565885737045900010034836345809386672230885527307","best_ask":"0.39","best_bid":"0.38","hash":"09144c403531f119bffbd8d0dfe578c1e803145d","price":"0.57","side":"SELL","size":"147.2"}],"timestamp":"1785127059448"},"payload_hash":"66c464b09e166a45705f8588b7359417276e32c26f6ae61b49dea374341e47a0","raw_frame":"{\"market\":\"0xeb66215f2e9faa6449e30a02bab5b8ed7b79a38bf961f6b24d0073c9c2419250\", \"price_changes\":[{\"asset_id\":\"69697746896130839564035629862476347944307040470122503199396727085502753297492\", \"price\":\"0.43\", \"size\":\"147.2\", \"side\":\"BUY\", \"hash\":\"96e3325f42d77833df4c902ed26f7b1fbd7d63f3\", \"best_bid\":\"0.61\", \"best_ask\":\"0.62\"}, {\"asset_id\":\"60386828328910021732068595344565885737045900010034836345809386672230885527307\", \"price\":\"0.57\", \"size\":\"147.2\", \"side\":\"SELL\", \"hash\":\"09144c403531f119bffbd8d0dfe578c1e803145d\", \"best_bid\":\"0.38\", \"best_ask\":\"0.39\"}], \"timestamp\":\"1785127059448\", \"event_type\":\"price_change\"}","received_at":"2026-07-27T04:37:39.445136Z","schema_version":"clob-market-ws.price_change.v1","sequence":null,"server_hash":null,"server_timestamp":"1785127059448","session_id":"e9443c7415a0419799bee9cfbb1a9e4d","source":"clob_market_ws"},"received_at":"2026-07-27T04:37:39.445136Z","record_id":"cb09a4e9fe07a7c409622937cfbef1535d93307a66b14cb804ccdecc36b2060c","schema_fingerprint":"4aa3821a28b0b7c2400bc59aba4bcc0a76e971dadd19610d3ad38c768e124dc7","schema_version":"edge-lab-recorder.raw.v1","sequence":null,"source":"clob_market_ws"}
{"event_at":"2026-07-27T04:37:39.450000Z","event_fingerprint":"f2d6ce0cd1ab2140a136e64dd46d46d7008c4a63451acfcdb6b6b58df3e610a7","payload":{"connection_id":"0f4979d6978d463e9660b042fdcf555f","event_at":"2026-07-27T04:37:39.450000Z","event_type":"price_change","frame_hash":"3969f6f25c12e000e1928cee77649b8908707d576a896204183a13d0418d0f9d","frame_index":0,"kind":"data","monotonic_ns":229042713272583,"payload":{"event_type":"price_change","market":"0xeb66215f2e9faa6449e30a02bab5b8ed7b79a38bf961f6b24d0073c9c2419250","price_changes":[{"asset_id":"69697746896130839564035629862476347944307040470122503199396727085502753297492","best_ask":"0.62","best_bid":"0.61","hash":"e793d57d3c34984d2a0f9a272807b6315e48651c","price":"0.01","side":"BUY","size":"5834.91"},{"asset_id":"60386828328910021732068595344565885737045900010034836345809386672230885527307","best_ask":"0.39","best_bid":"0.38","hash":"1211ac75d11dc305562c3bc6eb2c216a9c5474c7","price":"0.99","side":"SELL","size":"5834.91"}],"timestamp":"1785127059450"},"payload_hash":"0bf590a208ed93b78e5841c29c6527ee3863fe86a7a394009f14d0ae1a98c5cb","raw_frame":"{\"market\":\"0xeb66215f2e9faa6449e30a02bab5b8ed7b79a38bf961f6b24d0073c9c2419250\", \"price_changes\":[{\"asset_id\":\"69697746896130839564035629862476347944307040470122503199396727085502753297492\", \"price\":\"0.01\", \"size\":\"5834.91\", \"side\":\"BUY\", \"hash\":\"e793d57d3c34984d2a0f9a272807b6315e48651c\", \"best_bid\":\"0.61\", \"best_ask\":\"0.62\"}, {\"asset_id\":\"60386828328910021732068595344565885737045900010034836345809386672230885527307\", \"price\":\"0.99\", \"size\":\"5834.91\", \"side\":\"SELL\", \"hash\":\"1211ac75d11dc305562c3bc6eb2c216a9c5474c7\", \"best_bid\":\"0.38\", \"best_ask\":\"0.39\"}], \"timestamp\":\"1785127059450\", \"event_type\":\"price_change\"}","received_at":"2026-07-27T04:37:39.447420Z","schema_version":"clob-market-ws.price_change.v1","sequence":null,"server_hash":null,"server_timestamp":"1785127059450","session_id":"e9443c7415a0419799bee9cfbb1a9e4d","source":"clob_market_ws"},"received_at":"2026-07-27T04:37:39.447420Z","record_id":"3b0ffa9bfb5da147242d5143cb4cb39068b5cfa6377d36bcce42a58dec04e261","schema_fingerprint":"4aa3821a28b0b7c2400bc59aba4bcc0a76e971dadd19610d3ad38c768e124dc7","schema_version":"edge-lab-recorder.raw.v1","sequence":null,"source":"clob_market_ws"}
{"event_at":"2026-07-27T04:37:39.454000Z","event_fingerprint":"156a9cf7196a5bfbc366860feebe94ec2b965b5c4d413a0809fbb4a46d87344b","payload":{"connection_id":"0f4979d6978d463e9660b042fdcf555f","event_at":"2026-07-27T04:37:39.454000Z","event_type":"price_change","frame_hash":"10d41ef103501bc4682921a2ee9f2f7228f0154830497531679110ca390cc668","frame_index":0,"kind":"data","monotonic_ns":229042716289250,"payload":{"event_type":"price_change","market":"0xeb66215f2e9faa6449e30a02bab5b8ed7b79a38bf961f6b24d0073c9c2419250","price_changes":[{"asset_id":"69697746896130839564035629862476347944307040470122503199396727085502753297492","best_ask":"0.62","best_bid":"0.61","hash":"b2f1bac8a2aaf144d946dc783cfd1c6037813083","price":"0.58","side":"BUY","size":"67.99"},{"asset_id":"60386828328910021732068595344565885737045900010034836345809386672230885527307","best_ask":"0.39","best_bid":"0.38","hash":"f97288e3f8f69a871181f366bc7eb82d89274a97","price":"0.42","side":"SELL","size":"67.99"}],"timestamp":"1785127059454"},"payload_hash":"fd600a3ad724bdbaf72b3fea0517150d9772ab1a6939ced84f72a2f28179f7f2","raw_frame":"{\"market\":\"0xeb66215f2e9faa6449e30a02bab5b8ed7b79a38bf961f6b24d0073c9c2419250\", \"price_changes\":[{\"asset_id\":\"69697746896130839564035629862476347944307040470122503199396727085502753297492\", \"price\":\"0.58\", \"size\":\"67.99\", \"side\":\"BUY\", \"hash\":\"b2f1bac8a2aaf144d946dc783cfd1c6037813083\", \"best_bid\":\"0.61\", \"best_ask\":\"0.62\"}, {\"asset_id\":\"60386828328910021732068595344565885737045900010034836345809386672230885527307\", \"price\":\"0.42\", \"size\":\"67.99\", \"side\":\"SELL\", \"hash\":\"f97288e3f8f69a871181f366bc7eb82d89274a97\", \"best_bid\":\"0.38\", \"best_ask\":\"0.39\"}], \"timestamp\":\"1785127059454\", \"event_type\":\"price_change\"}","received_at":"2026-07-27T04:37:39.450437Z","schema_version":"clob-market-ws.price_change.v1","sequence":null,"server_hash":null,"server_timestamp":"1785127059454","session_id":"e9443c7415a0419799bee9cfbb1a9e4d","source":"clob_market_ws"},"received_at":"2026-07-27T04:37:39.450437Z","record_id":"3920b21c83cf6d46b8dec7111d202b83690c4211da049b238cd9443650c25261","schema_fingerprint":"4aa3821a28b0b7c2400bc59aba4bcc0a76e971dadd19610d3ad38c768e124dc7","schema_version":"edge-lab-recorder.raw.v1","sequence":null,"source":"clob_market_ws"}
{"event_at":"2026-07-27T04:37:39.455000Z","event_fingerprint":"b4862b9501066d0711e9877eb98943faffd85082df17ba12d1335f709de14557","payload":{"connection_id":"0f4979d6978d463e9660b042fdcf555f","event_at":"2026-07-27T04:37:39.455000Z","event_type":"price_change","frame_hash":"b88e98b24b8f81dc89f39f433ac52393044d67b271bc7ce8a2f2af65ae5a870b","frame_index":0,"kind":"data","monotonic_ns":229042719486000,"payload":{"event_type":"price_change","market":"0xeb66215f2e9faa6449e30a02bab5b8ed7b79a38bf961f6b24d0073c9c2419250","price_changes":[{"asset_id":"69697746896130839564035629862476347944307040470122503199396727085502753297492","best_ask":"0.62","best_bid":"0.61","hash":"d1df0c154b7f94cb01644ccf53b606bb5b836f35","price":"0.53","side":"BUY","size":"97"},{"asset_id":"60386828328910021732068595344565885737045900010034836345809386672230885527307","best_ask":"0.39","best_bid":"0.38","hash":"4ba779692aed0cbf337b09a4983278fcdf19937c","price":"0.47","side":"SELL","size":"97"}],"timestamp":"1785127059455"},"payload_hash":"b9c71c08af569de1c0b29c0b2e46673a50b789995b55d2630a0fd6aef8ab8984","raw_frame":"{\"market\":\"0xeb66215f2e9faa6449e30a02bab5b8ed7b79a38bf961f6b24d0073c9c2419250\", \"price_changes\":[{\"asset_id\":\"69697746896130839564035629862476347944307040470122503199396727085502753297492\", \"price\":\"0.53\", \"size\":\"97\", \"side\":\"BUY\", \"hash\":\"d1df0c154b7f94cb01644ccf53b606bb5b836f35\", \"best_bid\":\"0.61\", \"best_ask\":\"0.62\"}, {\"asset_id\":\"60386828328910021732068595344565885737045900010034836345809386672230885527307\", \"price\":\"0.47\", \"size\":\"97\", \"side\":\"SELL\", \"hash\":\"4ba779692aed0cbf337b09a4983278fcdf19937c\", \"best_bid\":\"0.38\", \"best_ask\":\"0.39\"}], \"timestamp\":\"1785127059455\", \"event_type\":\"price_change\"}","received_at":"2026-07-27T04:37:39.453630Z","schema_version":"clob-market-ws.price_change.v1","sequence":null,"server_hash":null,"server_timestamp":"1785127059455","session_id":"e9443c7415a0419799bee9cfbb1a9e4d","source":"clob_market_ws"},"received_at":"2026-07-27T04:37:39.453630Z","record_id":"7379b9be84424079a48bd1a5563217c145d97d08c130b668781a761b3849cdc3","schema_fingerprint":"4aa3821a28b0b7c2400bc59aba4bcc0a76e971dadd19610d3ad38c768e124dc7","schema_version":"edge-lab-recorder.raw.v1","sequence":null,"source":"clob_market_ws"}
{"event_at":"2026-07-27T04:37:39.457000Z","event_fingerprint":"f24ee79b008d6ac60234a54775302b46cf44ed30ece23bc2b00a96cf7716575a","payload":{"connection_id":"0f4979d6978d463e9660b042fdcf555f","event_at":"2026-07-27T04:37:39.457000Z","event_type":"price_change","frame_hash":"67616577ca75a40d7fec80b775ac8e956656355a90e227ca1292111d73a3e64f","frame_index":0,"kind":"data","monotonic_ns":229042722874208,"payload":{"event_type":"price_change","market":"0xeb66215f2e9faa6449e30a02bab5b8ed7b79a38bf961f6b24d0073c9c2419250","price_changes":[{"asset_id":"69697746896130839564035629862476347944307040470122503199396727085502753297492","best_ask":"0.62","best_bid":"0.61","hash":"2d51bb44a0ec8232123904e97c445745a5504012","price":"0.61","side":"BUY","size":"423"},{"asset_id":"60386828328910021732068595344565885737045900010034836345809386672230885527307","best_ask":"0.39","best_bid":"0.38","hash":"239dd7c0ce9cb8d575ba9b39985ae93daa36defb","price":"0.39","side":"SELL","size":"423"}],"timestamp":"1785127059457"},"payload_hash":"a44251efc0ea6cc63c3259280ac5977c2ebab778c4d10016e070f5c2d2fa9df1","raw_frame":"{\"market\":\"0xeb66215f2e9faa6449e30a02bab5b8ed7b79a38bf961f6b24d0073c9c2419250\", \"price_changes\":[{\"asset_id\":\"69697746896130839564035629862476347944307040470122503199396727085502753297492\", \"price\":\"0.61\", \"size\":\"423\", \"side\":\"BUY\", \"hash\":\"2d51bb44a0ec8232123904e97c445745a5504012\", \"best_bid\":\"0.61\", \"best_ask\":\"0.62\"}, {\"asset_id\":\"60386828328910021732068595344565885737045900010034836345809386672230885527307\", \"price\":\"0.39\", \"size\":\"423\", \"side\":\"SELL\", \"hash\":\"239dd7c0ce9cb8d575ba9b39985ae93daa36defb\", \"best_bid\":\"0.38\", \"best_ask\":\"0.39\"}], \"timestamp\":\"1785127059457\", \"event_type\":\"price_change\"}","received_at":"2026-07-27T04:37:39.457023Z","schema_version":"clob-market-ws.price_change.v1","sequence":null,"server_hash":null,"server_timestamp":"1785127059457","session_id":"e9443c7415a0419799bee9cfbb1a9e4d","source":"clob_market_ws"},"received_at":"2026-07-27T04:37:39.457023Z","record_id":"0b0059cdd1879baa2adc902018d2d8b48ae34abcb0debb8acbfd150f4458c754","schema_fingerprint":"4aa3821a28b0b7c2400bc59aba4bcc0a76e971dadd19610d3ad38c768e124dc7","schema_version":"edge-lab-recorder.raw.v1","sequence":null,"source":"clob_market_ws"}
{"event_at":"2026-07-27T04:37:39.458000Z","event_fingerprint":"3ba5ac5f4749c90e383af7675778404a60c196d3897aee4f241c181458d92fee","payload":{"connection_id":"0f4979d6978d463e9660b042fdcf555f","event_at":"2026-07-27T04:37:39.458000Z","event_type":"price_change","frame_hash":"3a63651a7f98e078a297ac4d35ffa6f8f4aea1f31626367477cd18b9ee284fc9","frame_index":0,"kind":"data","monotonic_ns":229042726932833,"payload":{"event_type":"price_change","market":"0xeb66215f2e9faa6449e30a02bab5b8ed7b79a38bf961f6b24d0073c9c2419250","price_changes":[{"asset_id":"69697746896130839564035629862476347944307040470122503199396727085502753297492","best_ask":"0.62","best_bid":"0.61","hash":"909f3d8fcf1b46d61fedf056aed9a1acd2719c9e","price":"0.01","side":"BUY","size":"5839.91"},{"asset_id":"60386828328910021732068595344565885737045900010034836345809386672230885527307","best_ask":"0.39","best_bid":"0.38","hash":"941a6e7a3ad4941653b9ccb565a13ad3b3bd55c2","price":"0.99","side":"SELL","size":"5839.91"}],"timestamp":"1785127059458"},"payload_hash":"ba1e10ce16384a9286e434dc08edb939ef1a15a64da62c72eb508e728e75f073","raw_frame":"{\"market\":\"0xeb66215f2e9faa6449e30a02bab5b8ed7b79a38bf961f6b24d0073c9c2419250\", \"price_changes\":[{\"asset_id\":\"69697746896130839564035629862476347944307040470122503199396727085502753297492\", \"price\":\"0.01\", \"size\":\"5839.91\", \"side\":\"BUY\", \"hash\":\"909f3d8fcf1b46d61fedf056aed9a1acd2719c9e\", \"best_bid\":\"0.61\", \"best_ask\":\"0.62\"}, {\"asset_id\":\"60386828328910021732068595344565885737045900010034836345809386672230885527307\", \"price\":\"0.99\", \"size\":\"5839.91\", \"side\":\"SELL\", \"hash\":\"941a6e7a3ad4941653b9ccb565a13ad3b3bd55c2\", \"best_bid\":\"0.38\", \"best_ask\":\"0.39\"}], \"timestamp\":\"1785127059458\", \"event_type\":\"price_change\"}","received_at":"2026-07-27T04:37:39.461078Z","schema_version":"clob-market-ws.price_change.v1","sequence":null,"server_hash":null,"server_timestamp":"1785127059458","session_id":"e9443c7415a0419799bee9cfbb1a9e4d","source":"clob_market_ws"},"received_at":"2026-07-27T04:37:39.461078Z","record_id":"cbae7da1b1158c0eea0f1ec0cbd7470eb379e3e27f4b71487f4f50eea390f3c8","schema_fingerprint":"4aa3821a28b0b7c2400bc59aba4bcc0a76e971dadd19610d3ad38c768e124dc7","schema_version":"edge-lab-recorder.raw.v1","sequence":null,"source":"clob_market_ws"}
{"event_at":"2026-07-27T04:37:39.459000Z","event_fingerprint":"8f6ea5ceee6f4bb7f6e511af91ecfced4207c490e95798b03caa6ab7edad1555","payload":{"connection_id":"0f4979d6978d463e9660b042fdcf555f","event_at":"2026-07-27T04:37:39.459000Z","event_type":"price_change","frame_hash":"7816fb797b7cce5ad948f32f3a696668dce6f5dab1fa9fa9c1dfa692d36fd78d","frame_index":0,"kind":"data","monotonic_ns":229042732708958,"payload":{"event_type":"price_change","market":"0xeb66215f2e9faa6449e30a02bab5b8ed7b79a38bf961f6b24d0073c9c2419250","price_changes":[{"asset_id":"69697746896130839564035629862476347944307040470122503199396727085502753297492","best_ask":"0.62","best_bid":"0.61","hash":"d367f40eb213156360758be03e544504680b4bd4","price":"0.54","side":"BUY","size":"14"},{"asset_id":"60386828328910021732068595344565885737045900010034836345809386672230885527307","best_ask":"0.39","best_bid":"0.38","hash":"c0f054b93af2373ff868a1a79d588314b046c0f5","price":"0.46","side":"SELL","size":"14"}],"timestamp":"1785127059459"},"payload_hash":"7fca3dcf127db9739331feb9bb1f788474ffd2bf420837513fcdedb3765a9064","raw_frame":"{\"market\":\"0xeb66215f2e9faa6449e30a02bab5b8ed7b79a38bf961f6b24d0073c9c2419250\", \"price_changes\":[{\"asset_id\":\"69697746896130839564035629862476347944307040470122503199396727085502753297492\", \"price\":\"0.54\", \"size\":\"14\", \"side\":\"BUY\", \"hash\":\"d367f40eb213156360758be03e544504680b4bd4\", \"best_bid\":\"0.61\", \"best_ask\":\"0.62\"}, {\"asset_id\":\"60386828328910021732068595344565885737045900010034836345809386672230885527307\", \"price\":\"0.46\", \"size\":\"14\", \"side\":\"SELL\", \"hash\":\"c0f054b93af2373ff868a1a79d588314b046c0f5\", \"best_bid\":\"0.38\", \"best_ask\":\"0.39\"}], \"timestamp\":\"1785127059459\", \"event_type\":\"price_change\"}","received_at":"2026-07-27T04:37:39.466856Z","schema_version":"clob-market-ws.price_change.v1","sequence":null,"server_hash":null,"server_timestamp":"1785127059459","session_id":"e9443c7415a0419799bee9cfbb1a9e4d","source":"clob_market_ws"},"received_at":"2026-07-27T04:37:39.466856Z","record_id":"0672668c5ae0658f61bbd58bcd6d45133c1945f64498229b2064a3275c73df36","schema_fingerprint":"4aa3821a28b0b7c2400bc59aba4bcc0a76e971dadd19610d3ad38c768e124dc7","schema_version":"edge-lab-recorder.raw.v1","sequence":null,"source":"clob_market_ws"}
{"event_at":"2026-07-27T04:37:39.459000Z","event_fingerprint":"b206dadbd6e90fc037578b0c28da0e36f8e80d20463413e0c52f9264af9b7f53","payload":{"connection_id":"0f4979d6978d463e9660b042fdcf555f","event_at":"2026-07-27T04:37:39.459000Z","event_type":"price_change","frame_hash":"0ffc2561194558267203f8c1d1065bbee113608139e05a7570b94fddbc1db17c","frame_index":0,"kind":"data","monotonic_ns":229042738279583,"payload":{"event_type":"price_change","market":"0xeb66215f2e9faa6449e30a02bab5b8ed7b79a38bf961f6b24d0073c9c2419250","price_changes":[{"asset_id":"69697746896130839564035629862476347944307040470122503199396727085502753297492","best_ask":"0.62","best_bid":"0.61","hash":"dfbbf678f3adfd47736cf6170ba82b062c1e7947","price":"0.31","side":"BUY","size":"50"},{"asset_id":"60386828328910021732068595344565885737045900010034836345809386672230885527307","best_ask":"0.39","best_bid":"0.38","hash":"3936993a35a2ea38aafd551fb4d5458dee0914f1","price":"0.69","side":"SELL","size":"50"}],"timestamp":"1785127059459"},"payload_hash":"d5523a15be348d1f7d59e73e28107bf1629021b74054c8cb16822bbfcd855af2","raw_frame":"{\"market\":\"0xeb66215f2e9faa6449e30a02bab5b8ed7b79a38bf961f6b24d0073c9c2419250\", \"price_changes\":[{\"asset_id\":\"69697746896130839564035629862476347944307040470122503199396727085502753297492\", \"price\":\"0.31\", \"size\":\"50\", \"side\":\"BUY\", \"hash\":\"dfbbf678f3adfd47736cf6170ba82b062c1e7947\", \"best_bid\":\"0.61\", \"best_ask\":\"0.62\"}, {\"asset_id\":\"60386828328910021732068595344565885737045900010034836345809386672230885527307\", \"price\":\"0.69\", \"size\":\"50\", \"side\":\"SELL\", \"hash\":\"3936993a35a2ea38aafd551fb4d5458dee0914f1\", \"best_bid\":\"0.38\", \"best_ask\":\"0.39\"}], \"timestamp\":\"1785127059459\", \"event_type\":\"price_change\"}","received_at":"2026-07-27T04:37:39.472428Z","schema_version":"clob-market-ws.price_change.v1","sequence":null,"server_hash":null,"server_timestamp":"1785127059459","session_id":"e9443c7415a0419799bee9cfbb1a9e4d","source":"clob_market_ws"},"received_at":"2026-07-27T04:37:39.472428Z","record_id":"1c883af93f3bbb4de01a27d58077dc209e9cc65f96376a0b09aa700e3078b600","schema_fingerprint":"4aa3821a28b0b7c2400bc59aba4bcc0a76e971dadd19610d3ad38c768e124dc7","schema_version":"edge-lab-recorder.raw.v1","sequence":null,"source":"clob_market_ws"}
{"event_at":"2026-07-27T04:37:39.460000Z","event_fingerprint":"7d8481aa92eebf0f384f5b8583cf70c14ae6d0ef61a2af35adb8ad40485c71d7","payload":{"connection_id":"0f4979d6978d463e9660b042fdcf555f","event_at":"2026-07-27T04:37:39.460000Z","event_type":"price_change","frame_hash":"b4064545f5d30f515034c98ab4b89f42b1823d6f9b5fa545c470accf4fd4e444","frame_index":0,"kind":"data","monotonic_ns":229042741683125,"payload":{"event_type":"price_change","market":"0xeb66215f2e9faa6449e30a02bab5b8ed7b79a38bf961f6b24d0073c9c2419250","price_changes":[{"asset_id":"60386828328910021732068595344565885737045900010034836345809386672230885527307","best_ask":"0.39","best_bid":"0.38","hash":"b0c5382c49242dcf06a2fe65dac74cf5051245aa","price":"0.39","side":"SELL","size":"430"},{"asset_id":"69697746896130839564035629862476347944307040470122503199396727085502753297492","best_ask":"0.62","best_bid":"0.61","hash":"99e3fb46daa0132c06e16b58ee1774648db25c6b","price":"0.61","side":"BUY","size":"430"}],"timestamp":"1785127059460"},"payload_hash":"56ad4ae17752270ba164c267de7cddeaac63e2234cfc1677358d22dfef9952da","raw_frame":"{\"market\":\"0xeb66215f2e9faa6449e30a02bab5b8ed7b79a38bf961f6b24d0073c9c2419250\", \"price_changes\":[{\"asset_id\":\"60386828328910021732068595344565885737045900010034836345809386672230885527307\", \"price\":\"0.39\", \"size\":\"430\", \"side\":\"SELL\", \"hash\":\"b0c5382c49242dcf06a2fe65dac74cf5051245aa\", \"best_bid\":\"0.38\", \"best_ask\":\"0.39\"}, {\"asset_id\":\"69697746896130839564035629862476347944307040470122503199396727085502753297492\", \"price\":\"0.61\", \"size\":\"430\", \"side\":\"BUY\", \"hash\":\"99e3fb46daa0132c06e16b58ee1774648db25c6b\", \"best_bid\":\"0.61\", \"best_ask\":\"0.62\"}], \"timestamp\":\"1785127059460\", \"event_type\":\"price_change\"}","received_at":"2026-07-27T04:37:39.475831Z","schema_version":"clob-market-ws.price_change.v1","sequence":null,"server_hash":null,"server_timestamp":"1785127059460","session_id":"e9443c7415a0419799bee9cfbb1a9e4d","source":"clob_market_ws"},"received_at":"2026-07-27T04:37:39.475831Z","record_id":"51e40a3a6852c1ca0a78affa38531d42b2b6fc931e9ed42bb65710dbec5bd5ef","schema_fingerprint":"4aa3821a28b0b7c2400bc59aba4bcc0a76e971dadd19610d3ad38c768e124dc7","schema_version":"edge-lab-recorder.raw.v1","sequence":null,"source":"clob_market_ws"}
{"event_at":"2026-07-27T04:37:39.462000Z","event_fingerprint":"d7fcc32680cbd780855952572d1d3952cf80c2f8a290aa85219dd57e2dcfdf3c","payload":{"connection_id":"0f4979d6978d463e9660b042fdcf555f","event_at":"2026-07-27T04:37:39.462000Z","event_type":"price_change","frame_hash":"d154b818545ddd8c6b214194c66e7283a5cce94621dc894cd7d5f61f043768c1","frame_index":0,"kind":"data","monotonic_ns":229042743971083,"payload":{"event_type":"price_change","market":"0xeb66215f2e9faa6449e30a02bab5b8ed7b79a38bf961f6b24d0073c9c2419250","price_changes":[{"asset_id":"60386828328910021732068595344565885737045900010034836345809386672230885527307","best_ask":"0.39","best_bid":"0.38","hash":"cee8333a17d832d93a68090a4973335bd94d9977","price":"0.25","side":"BUY","size":"135"},{"asset_id":"69697746896130839564035629862476347944307040470122503199396727085502753297492","best_ask":"0.62","best_bid":"0.61","hash":"77478c88cb6611b6b97a6e33c598c6742e13b0a3","price":"0.75","side":"SELL","size":"135"}],"timestamp":"1785127059462"},"payload_hash":"55668880f460903c0f09ff5380f263e8089100c12189eaa49931a7dca5add022","raw_frame":"{\"market\":\"0xeb66215f2e9faa6449e30a02bab5b8ed7b79a38bf961f6b24d0073c9c2419250\", \"price_changes\":[{\"asset_id\":\"60386828328910021732068595344565885737045900010034836345809386672230885527307\", \"price\":\"0.25\", \"size\":\"135\", \"side\":\"BUY\", \"hash\":\"cee8333a17d832d93a68090a4973335bd94d9977\", \"best_bid\":\"0.38\", \"best_ask\":\"0.39\"}, {\"asset_id\":\"69697746896130839564035629862476347944307040470122503199396727085502753297492\", \"price\":\"0.75\", \"size\":\"135\", \"side\":\"SELL\", \"hash\":\"77478c88cb6611b6b97a6e33c598c6742e13b0a3\", \"best_bid\":\"0.61\", \"best_ask\":\"0.62\"}], \"timestamp\":\"1785127059462\", \"event_type\":\"price_change\"}","received_at":"2026-07-27T04:37:39.478120Z","schema_version":"clob-market-ws.price_change.v1","sequence":null,"server_hash":null,"server_timestamp":"1785127059462","session_id":"e9443c7415a0419799bee9cfbb1a9e4d","source":"clob_market_ws"},"received_at":"2026-07-27T04:37:39.478120Z","record_id":"0aaff9d0f32138bf8de6ce794fdba7141aea3e68626c4181db058d45f37c6031","schema_fingerprint":"4aa3821a28b0b7c2400bc59aba4bcc0a76e971dadd19610d3ad38c768e124dc7","schema_version":"edge-lab-recorder.raw.v1","sequence":null,"source":"clob_market_ws"}
{"event_at":"2026-07-27T04:37:39.468000Z","event_fingerprint":"3009afe66dc913979345039a04d82ddedc4aa62f7224943f008420fdac77cd3d","payload":{"connection_id":"0f4979d6978d463e9660b042fdcf555f","event_at":"2026-07-27T04:37:39.468000Z","event_type":"price_change","frame_hash":"e76c4910b8445013d65df57279f47ffa4cda48c10570c6c0a1c3632e8fce535b","frame_index":0,"kind":"data","monotonic_ns":229042746969791,"payload":{"event_type":"price_change","market":"0xeb66215f2e9faa6449e30a02bab5b8ed7b79a38bf961f6b24d0073c9c2419250","price_changes":[{"asset_id":"60386828328910021732068595344565885737045900010034836345809386672230885527307","best_ask":"0.39","best_bid":"0.38","hash":"776f3ce29bdc77dec4ea4f3578bc2b91b9102676","price":"0.39","side":"SELL","size":"435"},{"asset_id":"69697746896130839564035629862476347944307040470122503199396727085502753297492","best_ask":"0.62","best_bid":"0.61","hash":"8399449025b8f0a023076e86cf45bc3a7e3da04f","price":"0.61","side":"BUY","size":"435"}],"timestamp":"1785127059468"},"payload_hash":"dccaac3bd975fc1d473af6856999c4084d60d5bb33a4ae704e1be232fbae9c74","raw_frame":"{\"market\":\"0xeb66215f2e9faa6449e30a02bab5b8ed7b79a38bf961f6b24d0073c9c2419250\", \"price_changes\":[{\"asset_id\":\"60386828328910021732068595344565885737045900010034836345809386672230885527307\", \"price\":\"0.39\", \"size\":\"435\", \"side\":\"SELL\", \"hash\":\"776f3ce29bdc77dec4ea4f3578bc2b91b9102676\", \"best_bid\":\"0.38\", \"best_ask\":\"0.39\"}, {\"asset_id\":\"69697746896130839564035629862476347944307040470122503199396727085502753297492\", \"price\":\"0.61\", \"size\":\"435\", \"side\":\"BUY\", \"hash\":\"8399449025b8f0a023076e86cf45bc3a7e3da04f\", \"best_bid\":\"0.61\", \"best_ask\":\"0.62\"}], \"timestamp\":\"1785127059468\", \"event_type\":\"price_change\"}","received_at":"2026-07-27T04:37:39.481118Z","schema_version":"clob-market-ws.price_change.v1","sequence":null,"server_hash":null,"server_timestamp":"1785127059468","session_id":"e9443c7415a0419799bee9cfbb1a9e4d","source":"clob_market_ws"},"received_at":"2026-07-27T04:37:39.481118Z","record_id":"f15dcd64cb037abfc9e6e320c3f83d481bc581a60b843d0ece91cb79637b15a2","schema_fingerprint":"4aa3821a28b0b7c2400bc59aba4bcc0a76e971dadd19610d3ad38c768e124dc7","schema_version":"edge-lab-recorder.raw.v1","sequence":null,"source":"clob_market_ws"}
{"event_at":"2026-07-27T04:37:39.469000Z","event_fingerprint":"bd71622f648b310f4a9a82000913d383ea653170f9437b5b977d09d7a7959262","payload":{"connection_id":"0f4979d6978d463e9660b042fdcf555f","event_at":"2026-07-27T04:37:39.469000Z","event_type":"price_change","frame_hash":"aa2b3a38a4782c144845dab19ef627c9cd94523d1db45b157096bb4d50b0eb92","frame_index":0,"kind":"data","monotonic_ns":229042749863708,"payload":{"event_type":"price_change","market":"0xeb66215f2e9faa6449e30a02bab5b8ed7b79a38bf961f6b24d0073c9c2419250","price_changes":[{"asset_id":"69697746896130839564035629862476347944307040470122503199396727085502753297492","best_ask":"0.62","best_bid":"0.61","hash":"de5a2c02b076940b0a0a07c2896322a2e9c8013c","price":"0.01","side":"BUY","size":"5834.91"},{"asset_id":"60386828328910021732068595344565885737045900010034836345809386672230885527307","best_ask":"0.39","best_bid":"0.38","hash":"812d95494691c123a2fec8009b2f28e06910ce9c","price":"0.99","side":"SELL","size":"5834.91"}],"timestamp":"1785127059469"},"payload_hash":"e5140f2d3b8d1ab88ac47c98964c9e9638c3cc2525e319b9f7812b21bbfb8198","raw_frame":"{\"market\":\"0xeb66215f2e9faa6449e30a02bab5b8ed7b79a38bf961f6b24d0073c9c2419250\", \"price_changes\":[{\"asset_id\":\"69697746896130839564035629862476347944307040470122503199396727085502753297492\", \"price\":\"0.01\", \"size\":\"5834.91\", \"side\":\"BUY\", \"hash\":\"de5a2c02b076940b0a0a07c2896322a2e9c8013c\", \"best_bid\":\"0.61\", \"best_ask\":\"0.62\"}, {\"asset_id\":\"60386828328910021732068595344565885737045900010034836345809386672230885527307\", \"price\":\"0.99\", \"size\":\"5834.91\", \"side\":\"SELL\", \"hash\":\"812d95494691c123a2fec8009b2f28e06910ce9c\", \"best_bid\":\"0.38\", \"best_ask\":\"0.39\"}], \"timestamp\":\"1785127059469\", \"event_type\":\"price_change\"}","received_at":"2026-07-27T04:37:39.484012Z","schema_version":"clob-market-ws.price_change.v1","sequence":null,"server_hash":null,"server_timestamp":"1785127059469","session_id":"e9443c7415a0419799bee9cfbb1a9e4d","source":"clob_market_ws"},"received_at":"2026-07-27T04:37:39.484012Z","record_id":"4f50498b5423959df6ababeac3af60f5f140cc33f609774065c86af47f8af742","schema_fingerprint":"4aa3821a28b0b7c2400bc59aba4bcc0a76e971dadd19610d3ad38c768e124dc7","schema_version":"edge-lab-recorder.raw.v1","sequence":null,"source":"clob_market_ws"}
{"event_at":"2026-07-27T04:37:39.471000Z","event_fingerprint":"9bf00c30888358e01ed99d4f084a51cb9d6cbf9f87ab0f5d7cacb102a03659b6","payload":{"connection_id":"0f4979d6978d463e9660b042fdcf555f","event_at":"2026-07-27T04:37:39.471000Z","event_type":"price_change","frame_hash":"7e8475cfbb187e82d5596cc253380da782345fbf632ec74bd4cf332ed4bd8ac5","frame_index":0,"kind":"data","monotonic_ns":229042751861250,"payload":{"event_type":"price_change","market":"0xeb66215f2e9faa6449e30a02bab5b8ed7b79a38bf961f6b24d0073c9c2419250","price_changes":[{"asset_id":"69697746896130839564035629862476347944307040470122503199396727085502753297492","best_ask":"0.62","best_bid":"0.61","hash":"13b59670135d99a63a03e92a7f2f25930c22f788","price":"0.58","side":"BUY","size":"80.22"},{"asset_id":"60386828328910021732068595344565885737045900010034836345809386672230885527307","best_ask":"0.39","best_bid":"0.38","hash":"665f439a807840ece5dfce88c2831bf4d8e04c7f","price":"0.42","side":"SELL","size":"80.22"}],"timestamp":"1785127059471"},"payload_hash":"5638670d330be48c3fc2307d95729688802f7f74919a2b69ba0a8853762f94b7","raw_frame":"{\"market\":\"0xeb66215f2e9faa6449e30a02bab5b8ed7b79a38bf961f6b24d0073c9c2419250\", \"price_changes\":[{\"asset_id\":\"69697746896130839564035629862476347944307040470122503199396727085502753297492\", \"price\":\"0.58\", \"size\":\"80.22\", \"side\":\"BUY\", \"hash\":\"13b59670135d99a63a03e92a7f2f25930c22f788\", \"best_bid\":\"0.61\", \"best_ask\":\"0.62\"}, {\"asset_id\":\"60386828328910021732068595344565885737045900010034836345809386672230885527307\", \"price\":\"0.42\", \"size\":\"80.22\", \"side\":\"SELL\", \"hash\":\"665f439a807840ece5dfce88c2831bf4d8e04c7f\", \"best_bid\":\"0.38\", \"best_ask\":\"0.39\"}], \"timestamp\":\"1785127059471\", \"event_type\":\"price_change\"}","received_at":"2026-07-27T04:37:39.486002Z","schema_version":"clob-market-ws.price_change.v1","sequence":null,"server_hash":null,"server_timestamp":"1785127059471","session_id":"e9443c7415a0419799bee9cfbb1a9e4d","source":"clob_market_ws"},"received_at":"2026-07-27T04:37:39.486002Z","record_id":"e554da30e0dd046fabc7698a6e88b657dd712321e818a313514b8eb5395189ac","schema_fingerprint":"4aa3821a28b0b7c2400bc59aba4bcc0a76e971dadd19610d3ad38c768e124dc7","schema_version":"edge-lab-recorder.raw.v1","sequence":null,"source":"clob_market_ws"}
{"event_at":"2026-07-27T04:37:39.472000Z","event_fingerprint":"90e3ba19c068bdb9f423aa5c5ef18fba49080df0d73dcfaf815a1ee61681a96c","payload":{"connection_id":"0f4979d6978d463e9660b042fdcf555f","event_at":"2026-07-27T04:37:39.472000Z","event_type":"price_change","frame_hash":"cb1a821582b69398dd1f737b1f1e6b6007c3ec3c967ab3b80a4247cf1584a7e2","frame_index":0,"kind":"data","monotonic_ns":229042755005708,"payload":{"event_type":"price_change","market":"0xeb66215f2e9faa6449e30a02bab5b8ed7b79a38bf961f6b24d0073c9c2419250","price_changes":[{"asset_id":"60386828328910021732068595344565885737045900010034836345809386672230885527307","best_ask":"0.39","best_bid":"0.38","hash":"6e4442b59cbc6892b37237588f5087f57c9147fc","price":"0.33","side":"BUY","size":"77.37"},{"asset_id":"69697746896130839564035629862476347944307040470122503199396727085502753297492","best_ask":"0.62","best_bid":"0.61","hash":"8d8c450e5c59b0844f7aec241f3e60233db43000","price":"0.67","side":"SELL","size":"77.37"}],"timestamp":"1785127059472"},"payload_hash":"29263c2c36c6c61710147e328565f4a921d9427c203cbde77e4087b3c949aa2e","raw_frame":"{\"market\":\"0xeb66215f2e9faa6449e30a02bab5b8ed7b79a38bf961f6b24d0073c9c2419250\", \"price_changes\":[{\"asset_id\":\"60386828328910021732068595344565885737045900010034836345809386672230885527307\", \"price\":\"0.33\", \"size\":\"77.37\", \"side\":\"BUY\", \"hash\":\"6e4442b59cbc6892b37237588f5087f57c9147fc\", \"best_bid\":\"0.38\", \"best_ask\":\"0.39\"}, {\"asset_id\":\"69697746896130839564035629862476347944307040470122503199396727085502753297492\", \"price\":\"0.67\", \"size\":\"77.37\", \"side\":\"SELL\", \"hash\":\"8d8c450e5c59b0844f7aec241f3e60233db43000\", \"best_bid\":\"0.61\", \"best_ask\":\"0.62\"}], \"timestamp\":\"1785127059472\", \"event_type\":\"price_change\"}","received_at":"2026-07-27T04:37:39.489152Z","schema_version":"clob-market-ws.price_change.v1","sequence":null,"server_hash":null,"server_timestamp":"1785127059472","session_id":"e9443c7415a0419799bee9cfbb1a9e4d","source":"clob_market_ws"},"received_at":"2026-07-27T04:37:39.489152Z","record_id":"7ddb083e631b7890958c1911013ea5ca984e560a2beab54d46ccbab4a9f74391","schema_fingerprint":"4aa3821a28b0b7c2400bc59aba4bcc0a76e971dadd19610d3ad38c768e124dc7","schema_version":"edge-lab-recorder.raw.v1","sequence":null,"source":"clob_market_ws"}
{"event_at":"2026-07-27T04:37:39.472000Z","event_fingerprint":"cf01bb0da5e3cf3989e17c68c890c1b1ae105642a426c94f8fabae8904c51945","payload":{"connection_id":"0f4979d6978d463e9660b042fdcf555f","event_at":"2026-07-27T04:37:39.472000Z","event_type":"price_change","frame_hash":"c4c2ec9cf1c3b8dee2fa2c6c6955b81f310c7676e8c561ba9fe1b12be8088c79","frame_index":0,"kind":"data","monotonic_ns":229042757854291,"payload":{"event_type":"price_change","market":"0xeb66215f2e9faa6449e30a02bab5b8ed7b79a38bf961f6b24d0073c9c2419250","price_changes":[{"asset_id":"60386828328910021732068595344565885737045900010034836345809386672230885527307","best_ask":"0.39","best_bid":"0.38","hash":"d8b4e663980eeb3132668b63bd08a4a58915cef5","price":"0.36","side":"BUY","size":"66.9"},{"asset_id":"69697746896130839564035629862476347944307040470122503199396727085502753297492","best_ask":"0.62","best_bid":"0.61","hash":"058eecd9457aa96e7cf2d5b31f9a63f7e42484d7","price":"0.64","side":"SELL","size":"66.9"}],"timestamp":"1785127059472"},"payload_hash":"30787e01324842c5e60ad059cc0a2c4e9cbbe990c4ce96b70da2f1e591818f82","raw_frame":"{\"market\":\"0xeb66215f2e9faa6449e30a02bab5b8ed7b79a38bf961f6b24d0073c9c2419250\", \"price_changes\":[{\"asset_id\":\"60386828328910021732068595344565885737045900010034836345809386672230885527307\", \"price\":\"0.36\", \"size\":\"66.9\", \"side\":\"BUY\", \"hash\":\"d8b4e663980eeb3132668b63bd08a4a58915cef5\", \"best_bid\":\"0.38\", \"best_ask\":\"0.39\"}, {\"asset_id\":\"69697746896130839564035629862476347944307040470122503199396727085502753297492\", \"price\":\"0.64\", \"size\":\"66.9\", \"side\":\"SELL\", \"hash\":\"058eecd9457aa96e7cf2d5b31f9a63f7e42484d7\", \"best_bid\":\"0.61\", \"best_ask\":\"0.62\"}], \"timestamp\":\"1785127059472\", \"event_type\":\"price_change\"}","received_at":"2026-07-27T04:37:39.492003Z","schema_version":"clob-market-ws.price_change.v1","sequence":null,"server_hash":null,"server_timestamp":"1785127059472","session_id":"e9443c7415a0419799bee9cfbb1a9e4d","source":"clob_market_ws"},"received_at":"2026-07-27T04:37:39.492003Z","record_id":"abd9e582cb64492d199a8a356d0f1b3506eb26ea682ce49b63b49b27e898cbe0","schema_fingerprint":"4aa3821a28b0b7c2400bc59aba4bcc0a76e971dadd19610d3ad38c768e124dc7","schema_version":"edge-lab-recorder.raw.v1","sequence":null,"source":"clob_market_ws"}
{"event_at":"2026-07-27T04:37:39.473000Z","event_fingerprint":"df43fa6c30fc409f30eca3522f15f6281f1d297d3b700122b75b20da0243bd3b","payload":{"connection_id":"0f4979d6978d463e9660b042fdcf555f","event_at":"2026-07-27T04:37:39.473000Z","event_type":"price_change","frame_hash":"3af7bc8126efa30a8f1e851d0bb2bacb5a876ab095502e7f40866678568d6575","frame_index":0,"kind":"data","monotonic_ns":229042760868208,"payload":{"event_type":"price_change","market":"0xeb66215f2e9faa6449e30a02bab5b8ed7b79a38bf961f6b24d0073c9c2419250","price_changes":[{"asset_id":"60386828328910021732068595344565885737045900010034836345809386672230885527307","best_ask":"0.39","best_bid":"0.38","hash":"5b7b676b5aa360c4d6b4c68eecb63f0738d64586","price":"0.35","side":"BUY","size":"450.85"},{"asset_id":"69697746896130839564035629862476347944307040470122503199396727085502753297492","best_ask":"0.62","best_bid":"0.61","hash":"26031bc1a4b98e94139f4a385f7e97ac3b43e904","price":"0.65","side":"SELL","size":"450.85"}],"timestamp":"1785127059473"},"payload_hash":"e51b0ab1bd18fd8bffb177054add15b05161b531c6f03af489f1640cfe1a683b","raw_frame":"{\"market\":\"0xeb66215f2e9faa6449e30a02bab5b8ed7b79a38bf961f6b24d0073c9c2419250\", \"price_changes\":[{\"asset_id\":\"60386828328910021732068595344565885737045900010034836345809386672230885527307\", \"price\":\"0.35\", \"size\":\"450.85\", \"side\":\"BUY\", \"hash\":\"5b7b676b5aa360c4d6b4c68eecb63f0738d64586\", \"best_bid\":\"0.38\", \"best_ask\":\"0.39\"}, {\"asset_id\":\"69697746896130839564035629862476347944307040470122503199396727085502753297492\", \"price\":\"0.65\", \"size\":\"450.85\", \"side\":\"SELL\", \"hash\":\"26031bc1a4b98e94139f4a385f7e97ac3b43e904\", \"best_bid\":\"0.61\", \"best_ask\":\"0.62\"}], \"timestamp\":\"1785127059473\", \"event_type\":\"price_change\"}","received_at":"2026-07-27T04:37:39.495017Z","schema_version":"clob-market-ws.price_change.v1","sequence":null,"server_hash":null,"server_timestamp":"1785127059473","session_id":"e9443c7415a0419799bee9cfbb1a9e4d","source":"clob_market_ws"},"received_at":"2026-07-27T04:37:39.495017Z","record_id":"0585ebac2b1dc5ddc35ed3382d6be81f6157242aec5ba25703bff15fad3ab5cc","schema_fingerprint":"4aa3821a28b0b7c2400bc59aba4bcc0a76e971dadd19610d3ad38c768e124dc7","schema_version":"edge-lab-recorder.raw.v1","sequence":null,"source":"clob_market_ws"}
{"event_at":"2026-07-27T04:37:39.476000Z","event_fingerprint":"51d4f3c1ea608251868ba613b13ec9b7f601c0451d66b533a6bc6aef79968f84","payload":{"connection_id":"0f4979d6978d463e9660b042fdcf555f","event_at":"2026-07-27T04:37:39.476000Z","event_type":"price_change","frame_hash":"3dddd39453b14735ec9f24cfba48410991b8935d0e42c2f1a9c9777a5c1ec607","frame_index":0,"kind":"data","monotonic_ns":229042763818083,"payload":{"event_type":"price_change","market":"0xeb66215f2e9faa6449e30a02bab5b8ed7b79a38bf961f6b24d0073c9c2419250","price_changes":[{"asset_id":"69697746896130839564035629862476347944307040470122503199396727085502753297492","best_ask":"0.62","best_bid":"0.61","hash":"292c314e3d743ff9b516d15691b1ed2238e3baf2","price":"0.49","side":"BUY","size":"122"},{"asset_id":"60386828328910021732068595344565885737045900010034836345809386672230885527307","best_ask":"0.39","best_bid":"0.38","hash":"59475ad483e7ee2c804fa53815d6865dfc0b4897","price":"0.51","side":"SELL","size":"122"}],"timestamp":"1785127059476"},"payload_hash":"c6b1a1f2b378aeb72a2aad8923fc149be938262cc5fd3f196bb11f29c746d450","raw_frame":"{\"market\":\"0xeb66215f2e9faa6449e30a02bab5b8ed7b79a38bf961f6b24d0073c9c2419250\", \"price_changes\":[{\"asset_id\":\"69697746896130839564035629862476347944307040470122503199396727085502753297492\", \"price\":\"0.49\", \"size\":\"122\", \"side\":\"BUY\", \"hash\":\"292c314e3d743ff9b516d15691b1ed2238e3baf2\", \"best_bid\":\"0.61\", \"best_ask\":\"0.62\"}, {\"asset_id\":\"60386828328910021732068595344565885737045900010034836345809386672230885527307\", \"price\":\"0.51\", \"size\":\"122\", \"side\":\"SELL\", \"hash\":\"59475ad483e7ee2c804fa53815d6865dfc0b4897\", \"best_bid\":\"0.38\", \"best_ask\":\"0.39\"}], \"timestamp\":\"1785127059476\", \"event_type\":\"price_change\"}","received_at":"2026-07-27T04:37:39.497967Z","schema_version":"clob-market-ws.price_change.v1","sequence":null,"server_hash":null,"server_timestamp":"1785127059476","session_id":"e9443c7415a0419799bee9cfbb1a9e4d","source":"clob_market_ws"},"received_at":"2026-07-27T04:37:39.497967Z","record_id":"36cc9746e1320678e76fde8ca1e26f6cce012da07bfe3e5bea935002a864ef89","schema_fingerprint":"4aa3821a28b0b7c2400bc59aba4bcc0a76e971dadd19610d3ad38c768e124dc7","schema_version":"edge-lab-recorder.raw.v1","sequence":null,"source":"clob_market_ws"}
{"event_at":"2026-07-27T04:37:39.476000Z","event_fingerprint":"4672f6de495db8f2fdda53c5b8aa298d2d7e60c6c68723b57cbc4f84abb63ede","payload":{"connection_id":"0f4979d6978d463e9660b042fdcf555f","event_at":"2026-07-27T04:37:39.476000Z","event_type":"price_change","frame_hash":"570bac8ad12736751a527602bac43d382a8491b3aceb8f954b1d881a81e8268b","frame_index":0,"kind":"data","monotonic_ns":229042766653625,"payload":{"event_type":"price_change","market":"0xeb66215f2e9faa6449e30a02bab5b8ed7b79a38bf961f6b24d0073c9c2419250","price_changes":[{"asset_id":"69697746896130839564035629862476347944307040470122503199396727085502753297492","best_ask":"0.62","best_bid":"0.61","hash":"292c314e3d743ff9b516d15691b1ed2238e3baf2","price":"0.44","side":"BUY","size":"117.2"},{"asset_id":"60386828328910021732068595344565885737045900010034836345809386672230885527307","best_ask":"0.39","best_bid":"0.38","hash":"59475ad483e7ee2c804fa53815d6865dfc0b4897","price":"0.56","side":"SELL","size":"117.2"}],"timestamp":"1785127059476"},"payload_hash":"500cd0ab14093a3131516d4c386a9c103c6edbcf9fc0a6f400d7185ef79090c3","raw_frame":"{\"market\":\"0xeb66215f2e9faa6449e30a02bab5b8ed7b79a38bf961f6b24d0073c9c2419250\", \"price_changes\":[{\"asset_id\":\"69697746896130839564035629862476347944307040470122503199396727085502753297492\", \"price\":\"0.44\", \"size\":\"117.2\", \"side\":\"BUY\", \"hash\":\"292c314e3d743ff9b516d15691b1ed2238e3baf2\", \"best_bid\":\"0.61\", \"best_ask\":\"0.62\"}, {\"asset_id\":\"60386828328910021732068595344565885737045900010034836345809386672230885527307\", \"price\":\"0.56\", \"size\":\"117.2\", \"side\":\"SELL\", \"hash\":\"59475ad483e7ee2c804fa53815d6865dfc0b4897\", \"best_bid\":\"0.38\", \"best_ask\":\"0.39\"}], \"timestamp\":\"1785127059476\", \"event_type\":\"price_change\"}","received_at":"2026-07-27T04:37:39.500802Z","schema_version":"clob-market-ws.price_change.v1","sequence":null,"server_hash":null,"server_timestamp":"1785127059476","session_id":"e9443c7415a0419799bee9cfbb1a9e4d","source":"clob_market_ws"},"received_at":"2026-07-27T04:37:39.500802Z","record_id":"cb422d28834b8bc7480e342cc7cbc87d05581141b43063557055c2dc1e627a33","schema_fingerprint":"4aa3821a28b0b7c2400bc59aba4bcc0a76e971dadd19610d3ad38c768e124dc7","schema_version":"edge-lab-recorder.raw.v1","sequence":null,"source":"clob_market_ws"}
{"event_at":"2026-07-27T04:37:39.476000Z","event_fingerprint":"1aa04f80a9901b13d4b21b5c966688bd3faf9d0eaf0a002da5bb5a9aee873ab2","payload":{"connection_id":"0f4979d6978d463e9660b042fdcf555f","event_at":"2026-07-27T04:37:39.476000Z","event_type":"price_change","frame_hash":"bcf37831f9c9bd87e3570add1ff5fa1db889f777829479e8962285337a4cc924","frame_index":0,"kind":"data","monotonic_ns":229042769760750,"payload":{"event_type":"price_change","market":"0xeb66215f2e9faa6449e30a02bab5b8ed7b79a38bf961f6b24d0073c9c2419250","price_changes":[{"asset_id":"69697746896130839564035629862476347944307040470122503199396727085502753297492","best_ask":"0.62","best_bid":"0.61","hash":"292c314e3d743ff9b516d15691b1ed2238e3baf2","price":"0.51","side":"BUY","size":"27"},{"asset_id":"60386828328910021732068595344565885737045900010034836345809386672230885527307","best_ask":"0.39","best_bid":"0.38","hash":"59475ad483e7ee2c804fa53815d6865dfc0b4897","price":"0.49","side":"SELL","size":"27"}],"timestamp":"1785127059476"},"payload_hash":"43a649f4d63d047d81e5d481b66df3074fde3510a8886d092fa7e224437e5a7f","raw_frame":"{\"market\":\"0xeb66215f2e9faa6449e30a02bab5b8ed7b79a38bf961f6b24d0073c9c2419250\", \"price_changes\":[{\"asset_id\":\"69697746896130839564035629862476347944307040470122503199396727085502753297492\", \"price\":\"0.51\", \"size\":\"27\", \"side\":\"BUY\", \"hash\":\"292c314e3d743ff9b516d15691b1ed2238e3baf2\", \"best_bid\":\"0.61\", \"best_ask\":\"0.62\"}, {\"asset_id\":\"60386828328910021732068595344565885737045900010034836345809386672230885527307\", \"price\":\"0.49\", \"size\":\"27\", \"side\":\"SELL\", \"hash\":\"59475ad483e7ee2c804fa53815d6865dfc0b4897\", \"best_bid\":\"0.38\", \"best_ask\":\"0.39\"}], \"timestamp\":\"1785127059476\", \"event_type\":\"price_change\"}","received_at":"2026-07-27T04:37:39.503909Z","schema_version":"clob-market-ws.price_change.v1","sequence":null,"server_hash":null,"server_timestamp":"1785127059476","session_id":"e9443c7415a0419799bee9cfbb1a9e4d","source":"clob_market_ws"},"received_at":"2026-07-27T04:37:39.503909Z","record_id":"e5fa2b827e73a4fe63825b5d0da3b1b5f7358806eeb02d28ddc1c99e90ce9db6","schema_fingerprint":"4aa3821a28b0b7c2400bc59aba4bcc0a76e971dadd19610d3ad38c768e124dc7","schema_version":"edge-lab-recorder.raw.v1","sequence":null,"source":"clob_market_ws"}
{"event_at":"2026-07-27T04:37:39.476000Z","event_fingerprint":"e08907cba16eb5173f45e9d9b9422c5647ae88772fb4fe0c80c3056714b611d3","payload":{"connection_id":"0f4979d6978d463e9660b042fdcf555f","event_at":"2026-07-27T04:37:39.476000Z","event_type":"price_change","frame_hash":"9e8f506b96b097e1b6e80712e90c449e468ee3d680bda99e6640c1617ebae765","frame_index":0,"kind":"data","monotonic_ns":229042772201250,"payload":{"event_type":"price_change","market":"0xeb66215f2e9faa6449e30a02bab5b8ed7b79a38bf961f6b24d0073c9c2419250","price_changes":[{"asset_id":"69697746896130839564035629862476347944307040470122503199396727085502753297492","best_ask":"0.62","best_bid":"0.61","hash":"292c314e3d743ff9b516d15691b1ed2238e3baf2","price":"0.5","side":"BUY","size":"132"},{"asset_id":"60386828328910021732068595344565885737045900010034836345809386672230885527307","best_ask":"0.39","best_bid":"0.38","hash":"59475ad483e7ee2c804fa53815d6865dfc0b4897","price":"0.5","side":"SELL","size":"132"}],"timestamp":"1785127059476"},"payload_hash":"18e2006bf60700751a575ba1baa7f8bb8e1bfa0c8535b41742e59e59d00e56f7","raw_frame":"{\"market\":\"0xeb66215f2e9faa6449e30a02bab5b8ed7b79a38bf961f6b24d0073c9c2419250\", \"price_changes\":[{\"asset_id\":\"69697746896130839564035629862476347944307040470122503199396727085502753297492\", \"price\":\"0.5\", \"size\":\"132\", \"side\":\"BUY\", \"hash\":\"292c314e3d743ff9b516d15691b1ed2238e3baf2\", \"best_bid\":\"0.61\", \"best_ask\":\"0.62\"}, {\"asset_id\":\"60386828328910021732068595344565885737045900010034836345809386672230885527307\", \"price\":\"0.5\", \"size\":\"132\", \"side\":\"SELL\", \"hash\":\"59475ad483e7ee2c804fa53815d6865dfc0b4897\", \"best_bid\":\"0.38\", \"best_ask\":\"0.39\"}], \"timestamp\":\"1785127059476\", \"event_type\":\"price_change\"}","received_at":"2026-07-27T04:37:39.506347Z","schema_version":"clob-market-ws.price_change.v1","sequence":null,"server_hash":null,"server_timestamp":"1785127059476","session_id":"e9443c7415a0419799bee9cfbb1a9e4d","source":"clob_market_ws"},"received_at":"2026-07-27T04:37:39.506347Z","record_id":"307d36368c5957083d16ab0018e471f65dbe2aec37452a1aae885b94ff2ad98e","schema_fingerprint":"4aa3821a28b0b7c2400bc59aba4bcc0a76e971dadd19610d3ad38c768e124dc7","schema_version":"edge-lab-recorder.raw.v1","sequence":null,"source":"clob_market_ws"}
{"event_at":"2026-07-27T04:37:39.476000Z","event_fingerprint":"e80d1f031a821866bb2cabbdc6c4dc2242a279c14deb13dea5fb43c954ea28ac","payload":{"connection_id":"0f4979d6978d463e9660b042fdcf555f","event_at":"2026-07-27T04:37:39.476000Z","event_type":"price_change","frame_hash":"9c56a64bd6caebf0aa56ecf74f257efc0e57c0a400d7ecd8f5cf43eceed8540c","frame_index":0,"kind":"data","monotonic_ns":229042773969166,"payload":{"event_type":"price_change","market":"0xeb66215f2e9faa6449e30a02bab5b8ed7b79a38bf961f6b24d0073c9c2419250","price_changes":[{"asset_id":"69697746896130839564035629862476347944307040470122503199396727085502753297492","best_ask":"0.62","best_bid":"0.61","hash":"292c314e3d743ff9b516d15691b1ed2238e3baf2","price":"0.53","side":"BUY","size":"91"},{"asset_id":"60386828328910021732068595344565885737045900010034836345809386672230885527307","best_ask":"0.39","best_bid":"0.38","hash":"59475ad483e7ee2c804fa53815d6865dfc0b4897","price":"0.47","side":"SELL","size":"91"}],"timestamp":"1785127059476"},"payload_hash":"026d020a34cc0c63c4623bc3ac5332d75b7153872b56857664550579dbca12a8","raw_frame":"{\"market\":\"0xeb66215f2e9faa6449e30a02bab5b8ed7b79a38bf961f6b24d0073c9c2419250\", \"price_changes\":[{\"asset_id\":\"69697746896130839564035629862476347944307040470122503199396727085502753297492\", \"price\":\"0.53\", \"size\":\"91\", \"side\":\"BUY\", \"hash\":\"292c314e3d743ff9b516d15691b1ed2238e3baf2\", \"best_bid\":\"0.61\", \"best_ask\":\"0.62\"}, {\"asset_id\":\"60386828328910021732068595344565885737045900010034836345809386672230885527307\", \"price\":\"0.47\", \"size\":\"91\", \"side\":\"SELL\", \"hash\":\"59475ad483e7ee2c804fa53815d6865dfc0b4897\", \"best_bid\":\"0.38\", \"best_ask\":\"0.39\"}], \"timestamp\":\"1785127059476\", \"event_type\":\"price_change\"}","received_at":"2026-07-27T04:37:39.508120Z","schema_version":"clob-market-ws.price_change.v1","sequence":null,"server_hash":null,"server_timestamp":"1785127059476","session_id":"e9443c7415a0419799bee9cfbb1a9e4d","source":"clob_market_ws"},"received_at":"2026-07-27T04:37:39.508120Z","record_id":"fb46029a121b529003bcbf7c4c3c44056360fe3cee431988927f7fe3052d7bfb","schema_fingerprint":"4aa3821a28b0b7c2400bc59aba4bcc0a76e971dadd19610d3ad38c768e124dc7","schema_version":"edge-lab-recorder.raw.v1","sequence":null,"source":"clob_market_ws"}
{"event_at":"2026-07-27T04:37:39.476000Z","event_fingerprint":"b3b93e26791d7b163567585ca23fd7b902d54365f833e7baf069bfc4627500b7","payload":{"connection_id":"0f4979d6978d463e9660b042fdcf555f","event_at":"2026-07-27T04:37:39.476000Z","event_type":"price_change","frame_hash":"79f53bfee44d0d18e65313948521e465da6d202ed96034e41d3819bd180debf5","frame_index":0,"kind":"data","monotonic_ns":229042776374541,"payload":{"event_type":"price_change","market":"0xeb66215f2e9faa6449e30a02bab5b8ed7b79a38bf961f6b24d0073c9c2419250","price_changes":[{"asset_id":"60386828328910021732068595344565885737045900010034836345809386672230885527307","best_ask":"0.39","best_bid":"0.38","hash":"59475ad483e7ee2c804fa53815d6865dfc0b4897","price":"0.42","side":"SELL","size":"71.22"},{"asset_id":"69697746896130839564035629862476347944307040470122503199396727085502753297492","best_ask":"0.62","best_bid":"0.61","hash":"292c314e3d743ff9b516d15691b1ed2238e3baf2","price":"0.58","side":"BUY","size":"71.22"}],"timestamp":"1785127059476"},"payload_hash":"f9c01026d048e37f715bf105ceab55dac3be1edbac95abf24397a8b699c23e47","raw_frame":"{\"market\":\"0xeb66215f2e9faa6449e30a02bab5b8ed7b79a38bf961f6b24d0073c9c2419250\", \"price_changes\":[{\"asset_id\":\"60386828328910021732068595344565885737045900010034836345809386672230885527307\", \"price\":\"0.42\", \"size\":\"71.22\", \"side\":\"SELL\", \"hash\":\"59475ad483e7ee2c804fa53815d6865dfc0b4897\", \"best_bid\":\"0.38\", \"best_ask\":\"0.39\"}, {\"asset_id\":\"69697746896130839564035629862476347944307040470122503199396727085502753297492\", \"price\":\"0.58\", \"size\":\"71.22\", \"side\":\"BUY\", \"hash\":\"292c314e3d743ff9b516d15691b1ed2238e3baf2\", \"best_bid\":\"0.61\", \"best_ask\":\"0.62\"}], \"timestamp\":\"1785127059476\", \"event_type\":\"price_change\"}","received_at":"2026-07-27T04:37:39.510523Z","schema_version":"clob-market-ws.price_change.v1","sequence":null,"server_hash":null,"server_timestamp":"1785127059476","session_id":"e9443c7415a0419799bee9cfbb1a9e4d","source":"clob_market_ws"},"received_at":"2026-07-27T04:37:39.510523Z","record_id":"abc3c0e34d4257c411f7359ffee079c2ac5337ec5fcde731cd6ca1344655d2f3","schema_fingerprint":"4aa3821a28b0b7c2400bc59aba4bcc0a76e971dadd19610d3ad38c768e124dc7","schema_version":"edge-lab-recorder.raw.v1","sequence":null,"source":"clob_market_ws"}
{"event_at":"2026-07-27T04:37:39.476000Z","event_fingerprint":"0080f4dabf1c67cb28db14296c7c0bc22632c90ad2f99d806e54a4ad363ba475","payload":{"connection_id":"0f4979d6978d463e9660b042fdcf555f","event_at":"2026-07-27T04:37:39.476000Z","event_type":"price_change","frame_hash":"b5d8fa6d6931e829f5b3b1b129e6e98f0194c4ac2377b91e5b8d3963a007435d","frame_index":0,"kind":"data","monotonic_ns":229042779144083,"payload":{"event_type":"price_change","market":"0xeb66215f2e9faa6449e30a02bab5b8ed7b79a38bf961f6b24d0073c9c2419250","price_changes":[{"asset_id":"69697746896130839564035629862476347944307040470122503199396727085502753297492","best_ask":"0.62","best_bid":"0.61","hash":"292c314e3d743ff9b516d15691b1ed2238e3baf2","price":"0.48","side":"BUY","size":"52"},{"asset_id":"60386828328910021732068595344565885737045900010034836345809386672230885527307","best_ask":"0.39","best_bid":"0.38","hash":"59475ad483e7ee2c804fa53815d6865dfc0b4897","price":"0.52","side":"SELL","size":"52"}],"timestamp":"1785127059476"},"payload_hash":"03614b1d3d906489346cb1ede1a39915c7d6ab4fcede67760752f0e495638a3e","raw_frame":"{\"market\":\"0xeb66215f2e9faa6449e30a02bab5b8ed7b79a38bf961f6b24d0073c9c2419250\", \"price_changes\":[{\"asset_id\":\"69697746896130839564035629862476347944307040470122503199396727085502753297492\", \"price\":\"0.48\", \"size\":\"52\", \"side\":\"BUY\", \"hash\":\"292c314e3d743ff9b516d15691b1ed2238e3baf2\", \"best_bid\":\"0.61\", \"best_ask\":\"0.62\"}, {\"asset_id\":\"60386828328910021732068595344565885737045900010034836345809386672230885527307\", \"price\":\"0.52\", \"size\":\"52\", \"side\":\"SELL\", \"hash\":\"59475ad483e7ee2c804fa53815d6865dfc0b4897\", \"best_bid\":\"0.38\", \"best_ask\":\"0.39\"}], \"timestamp\":\"1785127059476\", \"event_type\":\"price_change\"}","received_at":"2026-07-27T04:37:39.513295Z","schema_version":"clob-market-ws.price_change.v1","sequence":null,"server_hash":null,"server_timestamp":"1785127059476","session_id":"e9443c7415a0419799bee9cfbb1a9e4d","source":"clob_market_ws"},"received_at":"2026-07-27T04:37:39.513295Z","record_id":"7384a70c9729843a12da245fca5ebe5fd81c6ae461ccc329862f6e6024355e11","schema_fingerprint":"4aa3821a28b0b7c2400bc59aba4bcc0a76e971dadd19610d3ad38c768e124dc7","schema_version":"edge-lab-recorder.raw.v1","sequence":null,"source":"clob_market_ws"}
{"event_at":"2026-07-27T04:37:39.476000Z","event_fingerprint":"af4018d53f393207651388dd265340232f8a8e8be0153bf4877534a5d833d462","payload":{"connection_id":"0f4979d6978d463e9660b042fdcf555f","event_at":"2026-07-27T04:37:39.476000Z","event_type":"price_change","frame_hash":"68b1949e94bd4b4d6432adfcd1ab6c764deeb442a66c745ffc39d3ada70327b0","frame_index":0,"kind":"data","monotonic_ns":229042781039666,"payload":{"event_type":"price_change","market":"0xeb66215f2e9faa6449e30a02bab5b8ed7b79a38bf961f6b24d0073c9c2419250","price_changes":[{"asset_id":"60386828328910021732068595344565885737045900010034836345809386672230885527307","best_ask":"0.39","best_bid":"0.38","hash":"59475ad483e7ee2c804fa53815d6865dfc0b4897","price":"0.31","side":"BUY","size":"22"},{"asset_id":"69697746896130839564035629862476347944307040470122503199396727085502753297492","best_ask":"0.62","best_bid":"0.61","hash":"292c314e3d743ff9b516d15691b1ed2238e3baf2","price":"0.69","side":"SELL","size":"22"}],"timestamp":"1785127059476"},"payload_hash":"523684bc50ef184d1251293b87f8391ef7ed7c2252e0504f73f4e4af572b6d9e","raw_frame":"{\"market\":\"0xeb66215f2e9faa6449e30a02bab5b8ed7b79a38bf961f6b24d0073c9c2419250\", \"price_changes\":[{\"asset_id\":\"60386828328910021732068595344565885737045900010034836345809386672230885527307\", \"price\":\"0.31\", \"size\":\"22\", \"side\":\"BUY\", \"hash\":\"59475ad483e7ee2c804fa53815d6865dfc0b4897\", \"best_bid\":\"0.38\", \"best_ask\":\"0.39\"}, {\"asset_id\":\"69697746896130839564035629862476347944307040470122503199396727085502753297492\", \"price\":\"0.69\", \"size\":\"22\", \"side\":\"SELL\", \"hash\":\"292c314e3d743ff9b516d15691b1ed2238e3baf2\", \"best_bid\":\"0.61\", \"best_ask\":\"0.62\"}], \"timestamp\":\"1785127059476\", \"event_type\":\"price_change\"}","received_at":"2026-07-27T04:37:39.515191Z","schema_version":"clob-market-ws.price_change.v1","sequence":null,"server_hash":null,"server_timestamp":"1785127059476","session_id":"e9443c7415a0419799bee9cfbb1a9e4d","source":"clob_market_ws"},"received_at":"2026-07-27T04:37:39.515191Z","record_id":"56b295916f2310b225a55635436f7bc5505784a50f271eaf4e22a835e67ddddf","schema_fingerprint":"4aa3821a28b0b7c2400bc59aba4bcc0a76e971dadd19610d3ad38c768e124dc7","schema_version":"edge-lab-recorder.raw.v1","sequence":null,"source":"clob_market_ws"}
{"event_at":"2026-07-27T04:37:39.476000Z","event_fingerprint":"36debac1ee86c6894d0d197877d367a0b8f77e5b5e2e9c217edab4505d942a59","payload":{"connection_id":"0f4979d6978d463e9660b042fdcf555f","event_at":"2026-07-27T04:37:39.476000Z","event_type":"price_change","frame_hash":"7b33d5c197c05ad1556905bf7dddce72e3bda7f65bc97013624f5b5ddab95cdd","frame_index":0,"kind":"data","monotonic_ns":229042783211916,"payload":{"event_type":"price_change","market":"0xeb66215f2e9faa6449e30a02bab5b8ed7b79a38bf961f6b24d0073c9c2419250","price_changes":[{"asset_id":"69697746896130839564035629862476347944307040470122503199396727085502753297492","best_ask":"0.62","best_bid":"0.61","hash":"292c314e3d743ff9b516d15691b1ed2238e3baf2","price":"0.67","side":"SELL","size":"70.37"},{"asset_id":"60386828328910021732068595344565885737045900010034836345809386672230885527307","best_ask":"0.39","best_bid":"0.38","hash":"59475ad483e7ee2c804fa53815d6865dfc0b4897","price":"0.33","side":"BUY","size":"70.37"}],"timestamp":"1785127059476"},"payload_hash":"676cb404b42aa5e3b35abac5acd6e92ff9ed1cf56b793877277dbefb0900ae27","raw_frame":"{\"market\":\"0xeb66215f2e9faa6449e30a02bab5b8ed7b79a38bf961f6b24d0073c9c2419250\", \"price_changes\":[{\"asset_id\":\"69697746896130839564035629862476347944307040470122503199396727085502753297492\", \"price\":\"0.67\", \"size\":\"70.37\", \"side\":\"SELL\", \"hash\":\"292c314e3d743ff9b516d15691b1ed2238e3baf2\", \"best_bid\":\"0.61\", \"best_ask\":\"0.62\"}, {\"asset_id\":\"60386828328910021732068595344565885737045900010034836345809386672230885527307\", \"price\":\"0.33\", \"size\":\"70.37\", \"side\":\"BUY\", \"hash\":\"59475ad483e7ee2c804fa53815d6865dfc0b4897\", \"best_bid\":\"0.38\", \"best_ask\":\"0.39\"}], \"timestamp\":\"1785127059476\", \"event_type\":\"price_change\"}","received_at":"2026-07-27T04:37:39.517361Z","schema_version":"clob-market-ws.price_change.v1","sequence":null,"server_hash":null,"server_timestamp":"1785127059476","session_id":"e9443c7415a0419799bee9cfbb1a9e4d","source":"clob_market_ws"},"received_at":"2026-07-27T04:37:39.517361Z","record_id":"5896b294b3f93f3e0e89544017096cfc1cb280f7b4f17d93cec679aa4a5ca7dc","schema_fingerprint":"4aa3821a28b0b7c2400bc59aba4bcc0a76e971dadd19610d3ad38c768e124dc7","schema_version":"edge-lab-recorder.raw.v1","sequence":null,"source":"clob_market_ws"}
{"event_at":"2026-07-27T04:37:39.476000Z","event_fingerprint":"93033f13232f4bb5d94373b1b54950677f4129c1ebe0d6cd2b66dcac278fb87d","payload":{"connection_id":"0f4979d6978d463e9660b042fdcf555f","event_at":"2026-07-27T04:37:39.476000Z","event_type":"price_change","frame_hash":"e9ecaab25134199f932ab0b40a8cd28f2934219ab76df8396b867dd0b391fcb5","frame_index":0,"kind":"data","monotonic_ns":229042786008041,"payload":{"event_type":"price_change","market":"0xeb66215f2e9faa6449e30a02bab5b8ed7b79a38bf961f6b24d0073c9c2419250","price_changes":[{"asset_id":"60386828328910021732068595344565885737045900010034836345809386672230885527307","best_ask":"0.39","best_bid":"0.38","hash":"59475ad483e7ee2c804fa53815d6865dfc0b4897","price":"0.32","side":"BUY","size":"122"},{"asset_id":"69697746896130839564035629862476347944307040470122503199396727085502753297492","best_ask":"0.62","best_bid":"0.61","hash":"292c314e3d743ff9b516d15691b1ed2238e3baf2","price":"0.68","side":"SELL","size":"122"}],"timestamp":"1785127059476"},"payload_hash":"c21c30a7d376b3ef78fd5fc094c79e6abde9936599fee8728fe6e544f9ab6627","raw_frame":"{\"market\":\"0xeb66215f2e9faa6449e30a02bab5b8ed7b79a38bf961f6b24d0073c9c2419250\", \"price_changes\":[{\"asset_id\":\"60386828328910021732068595344565885737045900010034836345809386672230885527307\", \"price\":\"0.32\", \"size\":\"122\", \"side\":\"BUY\", \"hash\":\"59475ad483e7ee2c804fa53815d6865dfc0b4897\", \"best_bid\":\"0.38\", \"best_ask\":\"0.39\"}, {\"asset_id\":\"69697746896130839564035629862476347944307040470122503199396727085502753297492\", \"price\":\"0.68\", \"size\":\"122\", \"side\":\"SELL\", \"hash\":\"292c314e3d743ff9b516d15691b1ed2238e3baf2\", \"best_bid\":\"0.61\", \"best_ask\":\"0.62\"}], \"timestamp\":\"1785127059476\", \"event_type\":\"price_change\"}","received_at":"2026-07-27T04:37:39.520153Z","schema_version":"clob-market-ws.price_change.v1","sequence":null,"server_hash":null,"server_timestamp":"1785127059476","session_id":"e9443c7415a0419799bee9cfbb1a9e4d","source":"clob_market_ws"},"received_at":"2026-07-27T04:37:39.520153Z","record_id":"c56ea3ebdff11d73ac2780784e9ce23f82bf610ee7553a3706360760e5142685","schema_fingerprint":"4aa3821a28b0b7c2400bc59aba4bcc0a76e971dadd19610d3ad38c768e124dc7","schema_version":"edge-lab-recorder.raw.v1","sequence":null,"source":"clob_market_ws"}
{"event_at":"2026-07-27T04:37:39.476000Z","event_fingerprint":"874f3acb5f0a2c806a2da93941d32c06ca9857f41a29a4b7c39391656f7401dc","payload":{"connection_id":"0f4979d6978d463e9660b042fdcf555f","event_at":"2026-07-27T04:37:39.476000Z","event_type":"price_change","frame_hash":"cbe36a3ca2746e5dfbf03839bb17317fedf89099d16a0a4da41d24a68f5e0a52","frame_index":0,"kind":"data","monotonic_ns":229042789179750,"payload":{"event_type":"price_change","market":"0xeb66215f2e9faa6449e30a02bab5b8ed7b79a38bf961f6b24d0073c9c2419250","price_changes":[{"asset_id":"69697746896130839564035629862476347944307040470122503199396727085502753297492","best_ask":"0.62","best_bid":"0.61","hash":"292c314e3d743ff9b516d15691b1ed2238e3baf2","price":"0.68","side":"SELL","size":"122"},{"asset_id":"60386828328910021732068595344565885737045900010034836345809386672230885527307","best_ask":"0.39","best_bid":"0.38","hash":"59475ad483e7ee2c804fa53815d6865dfc0b4897","price":"0.32","side":"BUY","size":"122"}],"timestamp":"1785127059476"},"payload_hash":"9d75c8e1fef471ccac8f7c5f92d406012cfe225b00b784ea9aab6c0ae89e367c","raw_frame":"{\"market\":\"0xeb66215f2e9faa6449e30a02bab5b8ed7b79a38bf961f6b24d0073c9c2419250\", \"price_changes\":[{\"asset_id\":\"69697746896130839564035629862476347944307040470122503199396727085502753297492\", \"price\":\"0.68\", \"size\":\"122\", \"side\":\"SELL\", \"hash\":\"292c314e3d743ff9b516d15691b1ed2238e3baf2\", \"best_bid\":\"0.61\", \"best_ask\":\"0.62\"}, {\"asset_id\":\"60386828328910021732068595344565885737045900010034836345809386672230885527307\", \"price\":\"0.32\", \"size\":\"122\", \"side\":\"BUY\", \"hash\":\"59475ad483e7ee2c804fa53815d6865dfc0b4897\", \"best_bid\":\"0.38\", \"best_ask\":\"0.39\"}], \"timestamp\":\"1785127059476\", \"event_type\":\"price_change\"}","received_at":"2026-07-27T04:37:39.523326Z","schema_version":"clob-market-ws.price_change.v1","sequence":null,"server_hash":null,"server_timestamp":"1785127059476","session_id":"e9443c7415a0419799bee9cfbb1a9e4d","source":"clob_market_ws"},"received_at":"2026-07-27T04:37:39.523326Z","record_id":"f882eb1e4f9590ad617eb85593d5d2c5b9b0b8538ede801b3e208463672945eb","schema_fingerprint":"4aa3821a28b0b7c2400bc59aba4bcc0a76e971dadd19610d3ad38c768e124dc7","schema_version":"edge-lab-recorder.raw.v1","sequence":null,"source":"clob_market_ws"}
{"event_at":"2026-07-27T04:37:39.476000Z","event_fingerprint":"b14792846cf74a238492419dbdfad5369486529fbc723699b615bad749d4821c","payload":{"connection_id":"0f4979d6978d463e9660b042fdcf555f","event_at":"2026-07-27T04:37:39.476000Z","event_type":"price_change","frame_hash":"a8196a873ac6e4c72f8b330c0caed293bc88cdf506aadadba1620e58bae98520","frame_index":0,"kind":"data","monotonic_ns":229042792361500,"payload":{"event_type":"price_change","market":"0xeb66215f2e9faa6449e30a02bab5b8ed7b79a38bf961f6b24d0073c9c2419250","price_changes":[{"asset_id":"69697746896130839564035629862476347944307040470122503199396727085502753297492","best_ask":"0.62","best_bid":"0.61","hash":"292c314e3d743ff9b516d15691b1ed2238e3baf2","price":"0.52","side":"BUY","size":"57"},{"asset_id":"60386828328910021732068595344565885737045900010034836345809386672230885527307","best_ask":"0.39","best_bid":"0.38","hash":"59475ad483e7ee2c804fa53815d6865dfc0b4897","price":"0.48","side":"SELL","size":"57"}],"timestamp":"1785127059476"},"payload_hash":"8a88ca13d33219b99a58c3ec4473cf8d265725fdea31c72f2b7d4632f10370f6","raw_frame":"{\"market\":\"0xeb66215f2e9faa6449e30a02bab5b8ed7b79a38bf961f6b24d0073c9c2419250\", \"price_changes\":[{\"asset_id\":\"69697746896130839564035629862476347944307040470122503199396727085502753297492\", \"price\":\"0.52\", \"size\":\"57\", \"side\":\"BUY\", \"hash\":\"292c314e3d743ff9b516d15691b1ed2238e3baf2\", \"best_bid\":\"0.61\", \"best_ask\":\"0.62\"}, {\"asset_id\":\"60386828328910021732068595344565885737045900010034836345809386672230885527307\", \"price\":\"0.48\", \"size\":\"57\", \"side\":\"SELL\", \"hash\":\"59475ad483e7ee2c804fa53815d6865dfc0b4897\", \"best_bid\":\"0.38\", \"best_ask\":\"0.39\"}], \"timestamp\":\"1785127059476\", \"event_type\":\"price_change\"}","received_at":"2026-07-27T04:37:39.526510Z","schema_version":"clob-market-ws.price_change.v1","sequence":null,"server_hash":null,"server_timestamp":"1785127059476","session_id":"e9443c7415a0419799bee9cfbb1a9e4d","source":"clob_market_ws"},"received_at":"2026-07-27T04:37:39.526510Z","record_id":"750b3f9effdb476e1300716aa4a481b39844b75c70f17f5a9edb3199979bf895","schema_fingerprint":"4aa3821a28b0b7c2400bc59aba4bcc0a76e971dadd19610d3ad38c768e124dc7","schema_version":"edge-lab-recorder.raw.v1","sequence":null,"source":"clob_market_ws"}
{"event_at":"2026-07-27T04:37:39.481000Z","event_fingerprint":"42a3a665a973e2f580696e93154c645cf5bf3809ca40bff97dcc15a5eeee9b0b","payload":{"connection_id":"0f4979d6978d463e9660b042fdcf555f","event_at":"2026-07-27T04:37:39.481000Z","event_type":"price_change","frame_hash":"f3529354a973a0bd58a315a8859e77fa8297d20a56808132b825fc9d8efa3312","frame_index":0,"kind":"data","monotonic_ns":229042795225375,"payload":{"event_type":"price_change","market":"0xeb66215f2e9faa6449e30a02bab5b8ed7b79a38bf961f6b24d0073c9c2419250","price_changes":[{"asset_id":"60386828328910021732068595344565885737045900010034836345809386672230885527307","best_ask":"0.39","best_bid":"0.38","hash":"2631ec4dcc07bc92b56b63ecc1768e75c67f1c4d","price":"0.21","side":"BUY","size":"63.93"},{"asset_id":"69697746896130839564035629862476347944307040470122503199396727085502753297492","best_ask":"0.62","best_bid":"0.61","hash":"8b5d9b8a28dbb4683f438c569d03a98896d600fe","price":"0.79","side":"SELL","size":"63.93"}],"timestamp":"1785127059481"},"payload_hash":"ebd38f64c66e681a76e80f96bc3d48983aa4a5b0668737a826c6f350a881eeb9","raw_frame":"{\"market\":\"0xeb66215f2e9faa6449e30a02bab5b8ed7b79a38bf961f6b24d0073c9c2419250\", \"price_changes\":[{\"asset_id\":\"60386828328910021732068595344565885737045900010034836345809386672230885527307\", \"price\":\"0.21\", \"size\":\"63.93\", \"side\":\"BUY\", \"hash\":\"2631ec4dcc07bc92b56b63ecc1768e75c67f1c4d\", \"best_bid\":\"0.38\", \"best_ask\":\"0.39\"}, {\"asset_id\":\"69697746896130839564035629862476347944307040470122503199396727085502753297492\", \"price\":\"0.79\", \"size\":\"63.93\", \"side\":\"SELL\", \"hash\":\"8b5d9b8a28dbb4683f438c569d03a98896d600fe\", \"best_bid\":\"0.61\", \"best_ask\":\"0.62\"}], \"timestamp\":\"1785127059481\", \"event_type\":\"price_change\"}","received_at":"2026-07-27T04:37:39.529374Z","schema_version":"clob-market-ws.price_change.v1","sequence":null,"server_hash":null,"server_timestamp":"1785127059481","session_id":"e9443c7415a0419799bee9cfbb1a9e4d","source":"clob_market_ws"},"received_at":"2026-07-27T04:37:39.529374Z","record_id":"125885100478278f40fbd74d28184469ce20bff957df9f8cfe26a5d5009ea4d5","schema_fingerprint":"4aa3821a28b0b7c2400bc59aba4bcc0a76e971dadd19610d3ad38c768e124dc7","schema_version":"edge-lab-recorder.raw.v1","sequence":null,"source":"clob_market_ws"}
{"event_at":"2026-07-27T04:37:39.481000Z","event_fingerprint":"72f8e574aa07803a3dc0c243426f03925fa3acd62ff5e97d240b918fd66bba06","payload":{"connection_id":"0f4979d6978d463e9660b042fdcf555f","event_at":"2026-07-27T04:37:39.481000Z","event_type":"price_change","frame_hash":"9629e74373d8c6ea4457632fa8ac9f51854fe0f6777b3e5c9b028ffbacf5d4e4","frame_index":0,"kind":"data","monotonic_ns":229042798201125,"payload":{"event_type":"price_change","market":"0xeb66215f2e9faa6449e30a02bab5b8ed7b79a38bf961f6b24d0073c9c2419250","price_changes":[{"asset_id":"60386828328910021732068595344565885737045900010034836345809386672230885527307","best_ask":"0.39","best_bid":"0.38","hash":"b402cc05cd455a803bc234c8d89ad006f9b704a6","price":"0.33","side":"BUY","size":"97.97"},{"asset_id":"69697746896130839564035629862476347944307040470122503199396727085502753297492","best_ask":"0.62","best_bid":"0.61","hash":"2a4c0b16acd4bb385f78dfc5ca04119ece38f15b","price":"0.67","side":"SELL","size":"97.97"}],"timestamp":"1785127059481"},"payload_hash":"440f8f4ee1fac019a03856ee12e7106d9829fa6497a3480d5fcdeaf50eeafe82","raw_frame":"{\"market\":\"0xeb66215f2e9faa6449e30a02bab5b8ed7b79a38bf961f6b24d0073c9c2419250\", \"price_changes\":[{\"asset_id\":\"60386828328910021732068595344565885737045900010034836345809386672230885527307\", \"price\":\"0.33\", \"size\":\"97.97\", \"side\":\"BUY\", \"hash\":\"b402cc05cd455a803bc234c8d89ad006f9b704a6\", \"best_bid\":\"0.38\", \"best_ask\":\"0.39\"}, {\"asset_id\":\"69697746896130839564035629862476347944307040470122503199396727085502753297492\", \"price\":\"0.67\", \"size\":\"97.97\", \"side\":\"SELL\", \"hash\":\"2a4c0b16acd4bb385f78dfc5ca04119ece38f15b\", \"best_bid\":\"0.61\", \"best_ask\":\"0.62\"}], \"timestamp\":\"1785127059481\", \"event_type\":\"price_change\"}","received_at":"2026-07-27T04:37:39.532350Z","schema_version":"clob-market-ws.price_change.v1","sequence":null,"server_hash":null,"server_timestamp":"1785127059481","session_id":"e9443c7415a0419799bee9cfbb1a9e4d","source":"clob_market_ws"},"received_at":"2026-07-27T04:37:39.532350Z","record_id":"7d94de433d00489ed8da939d07dbdb8024accc93940adc9444bfceb267e6f1cd","schema_fingerprint":"4aa3821a28b0b7c2400bc59aba4bcc0a76e971dadd19610d3ad38c768e124dc7","schema_version":"edge-lab-recorder.raw.v1","sequence":null,"source":"clob_market_ws"}
{"event_at":"2026-07-27T04:37:39.482000Z","event_fingerprint":"dca0892421340ea473286e78bbc295623eb140304925ba9ad56e87861d0282e1","payload":{"connection_id":"0f4979d6978d463e9660b042fdcf555f","event_at":"2026-07-27T04:37:39.482000Z","event_type":"price_change","frame_hash":"ba0d606e79ad4997ce525b0f1453620dde6eb9388656e664863ac31210517be0","frame_index":0,"kind":"data","monotonic_ns":229042801270625,"payload":{"event_type":"price_change","market":"0xeb66215f2e9faa6449e30a02bab5b8ed7b79a38bf961f6b24d0073c9c2419250","price_changes":[{"asset_id":"60386828328910021732068595344565885737045900010034836345809386672230885527307","best_ask":"0.39","best_bid":"0.38","hash":"4db924c8bc10d37d318cf5cd316dd2f74ab67600","price":"0.28","side":"BUY","size":"132"},{"asset_id":"69697746896130839564035629862476347944307040470122503199396727085502753297492","best_ask":"0.62","best_bid":"0.61","hash":"c135442a0127658dcaa93875f9678367f437e3c9","price":"0.72","side":"SELL","size":"132"}],"timestamp":"1785127059482"},"payload_hash":"5f527210e88db5c1f0e5f1983bfedb27dcaae47b1939261ba850ffd82700b1b1","raw_frame":"{\"market\":\"0xeb66215f2e9faa6449e30a02bab5b8ed7b79a38bf961f6b24d0073c9c2419250\", \"price_changes\":[{\"asset_id\":\"60386828328910021732068595344565885737045900010034836345809386672230885527307\", \"price\":\"0.28\", \"size\":\"132\", \"side\":\"BUY\", \"hash\":\"4db924c8bc10d37d318cf5cd316dd2f74ab67600\", \"best_bid\":\"0.38\", \"best_ask\":\"0.39\"}, {\"asset_id\":\"69697746896130839564035629862476347944307040470122503199396727085502753297492\", \"price\":\"0.72\", \"size\":\"132\", \"side\":\"SELL\", \"hash\":\"c135442a0127658dcaa93875f9678367f437e3c9\", \"best_bid\":\"0.61\", \"best_ask\":\"0.62\"}], \"timestamp\":\"1785127059482\", \"event_type\":\"price_change\"}","received_at":"2026-07-27T04:37:39.535417Z","schema_version":"clob-market-ws.price_change.v1","sequence":null,"server_hash":null,"server_timestamp":"1785127059482","session_id":"e9443c7415a0419799bee9cfbb1a9e4d","source":"clob_market_ws"},"received_at":"2026-07-27T04:37:39.535417Z","record_id":"33b89bff06a7bbcec8cb267c1f3aab03c972b2da08e3d9b1f10e5f72f41d41e6","schema_fingerprint":"4aa3821a28b0b7c2400bc59aba4bcc0a76e971dadd19610d3ad38c768e124dc7","schema_version":"edge-lab-recorder.raw.v1","sequence":null,"source":"clob_market_ws"}
{"event_at":"2026-07-27T04:37:39.483000Z","event_fingerprint":"ba7cf5ce4108c8593fffb2852fa97d790f2cbb3decd35c5bc6bb6d45f3bfa748","payload":{"connection_id":"0f4979d6978d463e9660b042fdcf555f","event_at":"2026-07-27T04:37:39.483000Z","event_type":"price_change","frame_hash":"50a3e2b5c94cd59d8d553986cfb8608ac9a6240e0a6c6c225666e021d53bcd3f","frame_index":0,"kind":"data","monotonic_ns":229042804560000,"payload":{"event_type":"price_change","market":"0xeb66215f2e9faa6449e30a02bab5b8ed7b79a38bf961f6b24d0073c9c2419250","price_changes":[{"asset_id":"60386828328910021732068595344565885737045900010034836345809386672230885527307","best_ask":"0.39","best_bid":"0.38","hash":"f47486c4ed6c558a5754f25778aa33581b21bd06","price":"0.39","side":"SELL","size":"465.4"},{"asset_id":"69697746896130839564035629862476347944307040470122503199396727085502753297492","best_ask":"0.62","best_bid":"0.61","hash":"63dc1cb8def0bfde67532c0c11f44691528c1d83","price":"0.61","side":"BUY","size":"465.4"}],"timestamp":"1785127059483"},"payload_hash":"26315fbeb0551e67d8bc5ccff31f939b8c45a8ca7ef0aed6a76f324d0d804b13","raw_frame":"{\"market\":\"0xeb66215f2e9faa6449e30a02bab5b8ed7b79a38bf961f6b24d0073c9c2419250\", \"price_changes\":[{\"asset_id\":\"60386828328910021732068595344565885737045900010034836345809386672230885527307\", \"price\":\"0.39\", \"size\":\"465.4\", \"side\":\"SELL\", \"hash\":\"f47486c4ed6c558a5754f25778aa33581b21bd06\", \"best_bid\":\"0.38\", \"best_ask\":\"0.39\"}, {\"asset_id\":\"69697746896130839564035629862476347944307040470122503199396727085502753297492\", \"price\":\"0.61\", \"size\":\"465.4\", \"side\":\"BUY\", \"hash\":\"63dc1cb8def0bfde67532c0c11f44691528c1d83\", \"best_bid\":\"0.61\", \"best_ask\":\"0.62\"}], \"timestamp\":\"1785127059483\", \"event_type\":\"price_change\"}","received_at":"2026-07-27T04:37:39.538708Z","schema_version":"clob-market-ws.price_change.v1","sequence":null,"server_hash":null,"server_timestamp":"1785127059483","session_id":"e9443c7415a0419799bee9cfbb1a9e4d","source":"clob_market_ws"},"received_at":"2026-07-27T04:37:39.538708Z","record_id":"72a959f50b25fb1e4ebd4af65a8413ff4788b5ed9b76fe22a8d26acbdd59e99d","schema_fingerprint":"4aa3821a28b0b7c2400bc59aba4bcc0a76e971dadd19610d3ad38c768e124dc7","schema_version":"edge-lab-recorder.raw.v1","sequence":null,"source":"clob_market_ws"}
{"event_at":"2026-07-27T04:37:39.484000Z","event_fingerprint":"66040f0fff6d6f90daa7981fffdbab1184e5f551eeb89a2a48391700f41ace24","payload":{"connection_id":"0f4979d6978d463e9660b042fdcf555f","event_at":"2026-07-27T04:37:39.484000Z","event_type":"price_change","frame_hash":"dc508f90437ab5ef5c8e4951f66d26bffa88f3fb32079d0c0949b8552f17116e","frame_index":0,"kind":"data","monotonic_ns":229042807424833,"payload":{"event_type":"price_change","market":"0xeb66215f2e9faa6449e30a02bab5b8ed7b79a38bf961f6b24d0073c9c2419250","price_changes":[{"asset_id":"69697746896130839564035629862476347944307040470122503199396727085502753297492","best_ask":"0.62","best_bid":"0.61","hash":"2fe3ebc63eb6bd049233b4724e7015485604534b","price":"0.7","side":"SELL","size":"185"},{"asset_id":"60386828328910021732068595344565885737045900010034836345809386672230885527307","best_ask":"0.39","best_bid":"0.38","hash":"9e357de3ffc45644e3c9a4af86c25c5c43665398","price":"0.3","side":"BUY","size":"185"}],"timestamp":"1785127059484"},"payload_hash":"6f36c25a76d48c256888b27d1d2cb9aea29be417f129078ae5e63e4bccfcf858","raw_frame":"{\"market\":\"0xeb66215f2e9faa6449e30a02bab5b8ed7b79a38bf961f6b24d0073c9c2419250\", \"price_changes\":[{\"asset_id\":\"69697746896130839564035629862476347944307040470122503199396727085502753297492\", \"price\":\"0.7\", \"size\":\"185\", \"side\":\"SELL\", \"hash\":\"2fe3ebc63eb6bd049233b4724e7015485604534b\", \"best_bid\":\"0.61\", \"best_ask\":\"0.62\"}, {\"asset_id\":\"60386828328910021732068595344565885737045900010034836345809386672230885527307\", \"price\":\"0.3\", \"size\":\"185\", \"side\":\"BUY\", \"hash\":\"9e357de3ffc45644e3c9a4af86c25c5c43665398\", \"best_bid\":\"0.38\", \"best_ask\":\"0.39\"}], \"timestamp\":\"1785127059484\", \"event_type\":\"price_change\"}","received_at":"2026-07-27T04:37:39.541571Z","schema_version":"clob-market-ws.price_change.v1","sequence":null,"server_hash":null,"server_timestamp":"1785127059484","session_id":"e9443c7415a0419799bee9cfbb1a9e4d","source":"clob_market_ws"},"received_at":"2026-07-27T04:37:39.541571Z","record_id":"3b6eed1372ea89922a0e24898a859f0db145e4f674063319887939f28b4d1285","schema_fingerprint":"4aa3821a28b0b7c2400bc59aba4bcc0a76e971dadd19610d3ad38c768e124dc7","schema_version":"edge-lab-recorder.raw.v1","sequence":null,"source":"clob_market_ws"}
{"event_at":"2026-07-27T04:37:39.484000Z","event_fingerprint":"9384acd2cbf50bafd273b7282a3fce81b5edd8189c0a0183b2a291a2e541dce1","payload":{"connection_id":"0f4979d6978d463e9660b042fdcf555f","event_at":"2026-07-27T04:37:39.484000Z","event_type":"price_change","frame_hash":"78273e38bff618c9baea273d0633375048e22180b422e776eb11580466876222","frame_index":0,"kind":"data","monotonic_ns":229042810479833,"payload":{"event_type":"price_change","market":"0xeb66215f2e9faa6449e30a02bab5b8ed7b79a38bf961f6b24d0073c9c2419250","price_changes":[{"asset_id":"69697746896130839564035629862476347944307040470122503199396727085502753297492","best_ask":"0.62","best_bid":"0.61","hash":"3d2dc8a28e9ce741dfedc9317964fdd518572af8","price":"0.59","side":"BUY","size":"15"},{"asset_id":"60386828328910021732068595344565885737045900010034836345809386672230885527307","best_ask":"0.39","best_bid":"0.38","hash":"2e3e954a2c6f83ab29883795e6daee7c9c83d717","price":"0.41","side":"SELL","size":"15"}],"timestamp":"1785127059484"},"payload_hash":"a2018a75d1c297177b41fd1026950b0ed189fe025ed6dcb92e0400f2d0fbe719","raw_frame":"{\"market\":\"0xeb66215f2e9faa6449e30a02bab5b8ed7b79a38bf961f6b24d0073c9c2419250\", \"price_changes\":[{\"asset_id\":\"69697746896130839564035629862476347944307040470122503199396727085502753297492\", \"price\":\"0.59\", \"size\":\"15\", \"side\":\"BUY\", \"hash\":\"3d2dc8a28e9ce741dfedc9317964fdd518572af8\", \"best_bid\":\"0.61\", \"best_ask\":\"0.62\"}, {\"asset_id\":\"60386828328910021732068595344565885737045900010034836345809386672230885527307\", \"price\":\"0.41\", \"size\":\"15\", \"side\":\"SELL\", \"hash\":\"2e3e954a2c6f83ab29883795e6daee7c9c83d717\", \"best_bid\":\"0.38\", \"best_ask\":\"0.39\"}], \"timestamp\":\"1785127059484\", \"event_type\":\"price_change\"}","received_at":"2026-07-27T04:37:39.544627Z","schema_version":"clob-market-ws.price_change.v1","sequence":null,"server_hash":null,"server_timestamp":"1785127059484","session_id":"e9443c7415a0419799bee9cfbb1a9e4d","source":"clob_market_ws"},"received_at":"2026-07-27T04:37:39.544627Z","record_id":"3ff8431ccfd47fbcd409ad705a89b45cd32d6077ff15d0ffbb2015394aa06046","schema_fingerprint":"4aa3821a28b0b7c2400bc59aba4bcc0a76e971dadd19610d3ad38c768e124dc7","schema_version":"edge-lab-recorder.raw.v1","sequence":null,"source":"clob_market_ws"}
{"event_at":"2026-07-27T04:37:39.485000Z","event_fingerprint":"7358d9e88066d442ed6db874f1e77e9c2d80dbf1371da83f7a5facd7466cc1ed","payload":{"connection_id":"0f4979d6978d463e9660b042fdcf555f","event_at":"2026-07-27T04:37:39.485000Z","event_type":"price_change","frame_hash":"7b3e541d1b5f7e3cd85af9a8c5d4d3f382db1ae1c0d7adae8ad7f372a1e79ec2","frame_index":0,"kind":"data","monotonic_ns":229042813728083,"payload":{"event_type":"price_change","market":"0xeb66215f2e9faa6449e30a02bab5b8ed7b79a38bf961f6b24d0073c9c2419250","price_changes":[{"asset_id":"60386828328910021732068595344565885737045900010034836345809386672230885527307","best_ask":"0.39","best_bid":"0.38","hash":"7b746c9debe8a8029c9c9b904f4715c49c6f68d4","price":"0.3","side":"BUY","size":"215"},{"asset_id":"69697746896130839564035629862476347944307040470122503199396727085502753297492","best_ask":"0.62","best_bid":"0.61","hash":"b5c06d2caf88da4cb0ebfbb51a9218817019a26f","price":"0.7","side":"SELL","size":"215"}],"timestamp":"1785127059485"},"payload_hash":"26ec6c658888ae53dc020fbeb84aa46655e6b37951b290e0d9810054387b93ab","raw_frame":"{\"market\":\"0xeb66215f2e9faa6449e30a02bab5b8ed7b79a38bf961f6b24d0073c9c2419250\", \"price_changes\":[{\"asset_id\":\"60386828328910021732068595344565885737045900010034836345809386672230885527307\", \"price\":\"0.3\", \"size\":\"215\", \"side\":\"BUY\", \"hash\":\"7b746c9debe8a8029c9c9b904f4715c49c6f68d4\", \"best_bid\":\"0.38\", \"best_ask\":\"0.39\"}, {\"asset_id\":\"69697746896130839564035629862476347944307040470122503199396727085502753297492\", \"price\":\"0.7\", \"size\":\"215\", \"side\":\"SELL\", \"hash\":\"b5c06d2caf88da4cb0ebfbb51a9218817019a26f\", \"best_bid\":\"0.61\", \"best_ask\":\"0.62\"}], \"timestamp\":\"1785127059485\", \"event_type\":\"price_change\"}","received_at":"2026-07-27T04:37:39.547878Z","schema_version":"clob-market-ws.price_change.v1","sequence":null,"server_hash":null,"server_timestamp":"1785127059485","session_id":"e9443c7415a0419799bee9cfbb1a9e4d","source":"clob_market_ws"},"received_at":"2026-07-27T04:37:39.547878Z","record_id":"b97fdb81f85c1f0b396db3cce575819bda5d0066061b0356a52a8b510e0296ce","schema_fingerprint":"4aa3821a28b0b7c2400bc59aba4bcc0a76e971dadd19610d3ad38c768e124dc7","schema_version":"edge-lab-recorder.raw.v1","sequence":null,"source":"clob_market_ws"}
{"event_at":"2026-07-27T04:37:39.486000Z","event_fingerprint":"da2db268dab9a19a6dab968c80d75ad0ae892d5166acf277bb67c9c2ea7cc7f3","payload":{"connection_id":"0f4979d6978d463e9660b042fdcf555f","event_at":"2026-07-27T04:37:39.486000Z","event_type":"price_change","frame_hash":"a770f56786fd3b20c03f15b524bd655e628fb0d1d7098bfe071d8ff93ce6642a","frame_index":0,"kind":"data","monotonic_ns":229042816002166,"payload":{"event_type":"price_change","market":"0xeb66215f2e9faa6449e30a02bab5b8ed7b79a38bf961f6b24d0073c9c2419250","price_changes":[{"asset_id":"60386828328910021732068595344565885737045900010034836345809386672230885527307","best_ask":"0.39","best_bid":"0.38","hash":"f6e02abb7df5433bb68d9a31652a77a413a56bef","price":"0.3","side":"BUY","size":"245"},{"asset_id":"69697746896130839564035629862476347944307040470122503199396727085502753297492","best_ask":"0.62","best_bid":"0.61","hash":"f799505f35fe90405de3dce4978cdff259b513b8","price":"0.7","side":"SELL","size":"245"}],"timestamp":"1785127059486"},"payload_hash":"067535a15588ba2c7b6b0b848a7998dc5bfc64b10874e6f084ab849530ffd50d","raw_frame":"{\"market\":\"0xeb66215f2e9faa6449e30a02bab5b8ed7b79a38bf961f6b24d0073c9c2419250\", \"price_changes\":[{\"asset_id\":\"60386828328910021732068595344565885737045900010034836345809386672230885527307\", \"price\":\"0.3\", \"size\":\"245\", \"side\":\"BUY\", \"hash\":\"f6e02abb7df5433bb68d9a31652a77a413a56bef\", \"best_bid\":\"0.38\", \"best_ask\":\"0.39\"}, {\"asset_id\":\"69697746896130839564035629862476347944307040470122503199396727085502753297492\", \"price\":\"0.7\", \"size\":\"245\", \"side\":\"SELL\", \"hash\":\"f799505f35fe90405de3dce4978cdff259b513b8\", \"best_bid\":\"0.61\", \"best_ask\":\"0.62\"}], \"timestamp\":\"1785127059486\", \"event_type\":\"price_change\"}","received_at":"2026-07-27T04:37:39.550150Z","schema_version":"clob-market-ws.price_change.v1","sequence":null,"server_hash":null,"server_timestamp":"1785127059486","session_id":"e9443c7415a0419799bee9cfbb1a9e4d","source":"clob_market_ws"},"received_at":"2026-07-27T04:37:39.550150Z","record_id":"df7ef9436c73596a8e5a6feca738056a36d1c161329ca0b785842e6e8d495f7b","schema_fingerprint":"4aa3821a28b0b7c2400bc59aba4bcc0a76e971dadd19610d3ad38c768e124dc7","schema_version":"edge-lab-recorder.raw.v1","sequence":null,"source":"clob_market_ws"}
{"event_at":"2026-07-27T04:37:39.487000Z","event_fingerprint":"e5b6bacf0f314016f7416adda49bf23f01d2cc9c0449741477ed895d2e4c9c7d","payload":{"connection_id":"0f4979d6978d463e9660b042fdcf555f","event_at":"2026-07-27T04:37:39.487000Z","event_type":"price_change","frame_hash":"394e82c083736ab77dc00176482e628f74d4ec70fd43e34d5bcce4806224f91c","frame_index":0,"kind":"data","monotonic_ns":229042818941291,"payload":{"event_type":"price_change","market":"0xeb66215f2e9faa6449e30a02bab5b8ed7b79a38bf961f6b24d0073c9c2419250","price_changes":[{"asset_id":"69697746896130839564035629862476347944307040470122503199396727085502753297492","best_ask":"0.62","best_bid":"0.61","hash":"725ea05da322f7186d56991a52cfa87a7392fb73","price":"0.57","side":"BUY","size":"28.16"},{"asset_id":"60386828328910021732068595344565885737045900010034836345809386672230885527307","best_ask":"0.39","best_bid":"0.38","hash":"4b6d71c65419be1d224abf7d89d622e6b9eb66bb","price":"0.43","side":"SELL","size":"28.16"}],"timestamp":"1785127059487"},"payload_hash":"3aeb004512c33f187a4802bb39608cefec054c64e97c785257784709a39e8078","raw_frame":"{\"market\":\"0xeb66215f2e9faa6449e30a02bab5b8ed7b79a38bf961f6b24d0073c9c2419250\", \"price_changes\":[{\"asset_id\":\"69697746896130839564035629862476347944307040470122503199396727085502753297492\", \"price\":\"0.57\", \"size\":\"28.16\", \"side\":\"BUY\", \"hash\":\"725ea05da322f7186d56991a52cfa87a7392fb73\", \"best_bid\":\"0.61\", \"best_ask\":\"0.62\"}, {\"asset_id\":\"60386828328910021732068595344565885737045900010034836345809386672230885527307\", \"price\":\"0.43\", \"size\":\"28.16\", \"side\":\"SELL\", \"hash\":\"4b6d71c65419be1d224abf7d89d622e6b9eb66bb\", \"best_bid\":\"0.38\", \"best_ask\":\"0.39\"}], \"timestamp\":\"1785127059487\", \"event_type\":\"price_change\"}","received_at":"2026-07-27T04:37:39.553087Z","schema_version":"clob-market-ws.price_change.v1","sequence":null,"server_hash":null,"server_timestamp":"1785127059487","session_id":"e9443c7415a0419799bee9cfbb1a9e4d","source":"clob_market_ws"},"received_at":"2026-07-27T04:37:39.553087Z","record_id":"e35ffa4869cf2dde8cb44a909c060ec4433fbc9923cd607c8a3fa3ffd23525ac","schema_fingerprint":"4aa3821a28b0b7c2400bc59aba4bcc0a76e971dadd19610d3ad38c768e124dc7","schema_version":"edge-lab-recorder.raw.v1","sequence":null,"source":"clob_market_ws"}
{"event_at":"2026-07-27T04:37:39.487000Z","event_fingerprint":"deaae96ae61caeadb05500346a22773d2918dccfc9e83502def5c9d437e8763b","payload":{"connection_id":"0f4979d6978d463e9660b042fdcf555f","event_at":"2026-07-27T04:37:39.487000Z","event_type":"price_change","frame_hash":"087c6b9f7ba9c7a2a2a7564f461a4e24bf24ea8f29452651d05ab3d83fb28f02","frame_index":0,"kind":"data","monotonic_ns":229042822101000,"payload":{"event_type":"price_change","market":"0xeb66215f2e9faa6449e30a02bab5b8ed7b79a38bf961f6b24d0073c9c2419250","price_changes":[{"asset_id":"60386828328910021732068595344565885737045900010034836345809386672230885527307","best_ask":"0.39","best_bid":"0.38","hash":"ee924da76765fd76dd861741a4335b6bfa0d1b9a","price":"0.29","side":"BUY","size":"130"},{"asset_id":"69697746896130839564035629862476347944307040470122503199396727085502753297492","best_ask":"0.62","best_bid":"0.61","hash":"80f76dcf08bdc92633ce30819d1c29ef3e3707b7","price":"0.71","side":"SELL","size":"130"}],"timestamp":"1785127059487"},"payload_hash":"eaa7e9247784064ee663501cf627f13bc72607cd2bdb22523221defc06f34ac3","raw_frame":"{\"market\":\"0xeb66215f2e9faa6449e30a02bab5b8ed7b79a38bf961f6b24d0073c9c2419250\", \"price_changes\":[{\"asset_id\":\"60386828328910021732068595344565885737045900010034836345809386672230885527307\", \"price\":\"0.29\", \"size\":\"130\", \"side\":\"BUY\", \"hash\":\"ee924da76765fd76dd861741a4335b6bfa0d1b9a\", \"best_bid\":\"0.38\", \"best_ask\":\"0.39\"}, {\"asset_id\":\"69697746896130839564035629862476347944307040470122503199396727085502753297492\", \"price\":\"0.71\", \"size\":\"130\", \"side\":\"SELL\", \"hash\":\"80f76dcf08bdc92633ce30819d1c29ef3e3707b7\", \"best_bid\":\"0.61\", \"best_ask\":\"0.62\"}], \"timestamp\":\"1785127059487\", \"event_type\":\"price_change\"}","received_at":"2026-07-27T04:37:39.556247Z","schema_version":"clob-market-ws.price_change.v1","sequence":null,"server_hash":null,"server_timestamp":"1785127059487","session_id":"e9443c7415a0419799bee9cfbb1a9e4d","source":"clob_market_ws"},"received_at":"2026-07-27T04:37:39.556247Z","record_id":"710d4fe64aae83ee286b6d2cecc6a858f11d4c1b68e0b2b3fe015c5d9f82a2e9","schema_fingerprint":"4aa3821a28b0b7c2400bc59aba4bcc0a76e971dadd19610d3ad38c768e124dc7","schema_version":"edge-lab-recorder.raw.v1","sequence":null,"source":"clob_market_ws"}
{"event_at":"2026-07-27T04:37:39.488000Z","event_fingerprint":"7062fa1667d6d86c893f9c09cb155a58b3889dbae9a91302379a09880d172429","payload":{"connection_id":"0f4979d6978d463e9660b042fdcf555f","event_at":"2026-07-27T04:37:39.488000Z","event_type":"price_change","frame_hash":"88c78554b337a6dd6db860ec598ce6917ed811edaef2ee75180f118eb9782fbb","frame_index":0,"kind":"data","monotonic_ns":229042825790000,"payload":{"event_type":"price_change","market":"0xeb66215f2e9faa6449e30a02bab5b8ed7b79a38bf961f6b24d0073c9c2419250","price_changes":[{"asset_id":"60386828328910021732068595344565885737045900010034836345809386672230885527307","best_ask":"0.39","best_bid":"0.38","hash":"c3351248d017115c52e88846455b2e297ea1644d","price":"0.3","side":"BUY","size":"275"},{"asset_id":"69697746896130839564035629862476347944307040470122503199396727085502753297492","best_ask":"0.62","best_bid":"0.61","hash":"8469d039201d77d1b100d9352379119e2d60ff1a","price":"0.7","side":"SELL","size":"275"}],"timestamp":"1785127059488"},"payload_hash":"898a0b584e5114f22b743a18b1fa9458953361e8a810f693d68b483b5e064ef2","raw_frame":"{\"market\":\"0xeb66215f2e9faa6449e30a02bab5b8ed7b79a38bf961f6b24d0073c9c2419250\", \"price_changes\":[{\"asset_id\":\"60386828328910021732068595344565885737045900010034836345809386672230885527307\", \"price\":\"0.3\", \"size\":\"275\", \"side\":\"BUY\", \"hash\":\"c3351248d017115c52e88846455b2e297ea1644d\", \"best_bid\":\"0.38\", \"best_ask\":\"0.39\"}, {\"asset_id\":\"69697746896130839564035629862476347944307040470122503199396727085502753297492\", \"price\":\"0.7\", \"size\":\"275\", \"side\":\"SELL\", \"hash\":\"8469d039201d77d1b100d9352379119e2d60ff1a\", \"best_bid\":\"0.61\", \"best_ask\":\"0.62\"}], \"timestamp\":\"1785127059488\", \"event_type\":\"price_change\"}","received_at":"2026-07-27T04:37:39.559939Z","schema_version":"clob-market-ws.price_change.v1","sequence":null,"server_hash":null,"server_timestamp":"1785127059488","session_id":"e9443c7415a0419799bee9cfbb1a9e4d","source":"clob_market_ws"},"received_at":"2026-07-27T04:37:39.559939Z","record_id":"ee1cb8201f61d9e9119b6b64f10e52341e3b50d7d2e713a52368b7c23c740126","schema_fingerprint":"4aa3821a28b0b7c2400bc59aba4bcc0a76e971dadd19610d3ad38c768e124dc7","schema_version":"edge-lab-recorder.raw.v1","sequence":null,"source":"clob_market_ws"}
{"event_at":"2026-07-27T04:37:39.488000Z","event_fingerprint":"94d24ac9202e0adda6ddaf9c87cb5290b6e6e8853c9bd1bf8d1be05b2e6e25ec","payload":{"connection_id":"0f4979d6978d463e9660b042fdcf555f","event_at":"2026-07-27T04:37:39.488000Z","event_type":"price_change","frame_hash":"cc1f3cfa3e40bdd077cf4ebad2c5d78be4022b8854ab0fdca3d6bd4213aa827c","frame_index":0,"kind":"data","monotonic_ns":229042829034916,"payload":{"event_type":"price_change","market":"0xeb66215f2e9faa6449e30a02bab5b8ed7b79a38bf961f6b24d0073c9c2419250","price_changes":[{"asset_id":"60386828328910021732068595344565885737045900010034836345809386672230885527307","best_ask":"0.39","best_bid":"0.38","hash":"4970aaec26b571566fa9fa9e10630694be6b290b","price":"0.36","side":"BUY","size":"36.9"},{"asset_id":"69697746896130839564035629862476347944307040470122503199396727085502753297492","best_ask":"0.62","best_bid":"0.61","hash":"21877ca10b8474c1b56609b7190a7eb157da3016","price":"0.64","side":"SELL","size":"36.9"}],"timestamp":"1785127059488"},"payload_hash":"c75bf5991c011343c84ee0774d0426d1c45e039a560973470b42b7e7ecd238b2","raw_frame":"{\"market\":\"0xeb66215f2e9faa6449e30a02bab5b8ed7b79a38bf961f6b24d0073c9c2419250\", \"price_changes\":[{\"asset_id\":\"60386828328910021732068595344565885737045900010034836345809386672230885527307\", \"price\":\"0.36\", \"size\":\"36.9\", \"side\":\"BUY\", \"hash\":\"4970aaec26b571566fa9fa9e10630694be6b290b\", \"best_bid\":\"0.38\", \"best_ask\":\"0.39\"}, {\"asset_id\":\"69697746896130839564035629862476347944307040470122503199396727085502753297492\", \"price\":\"0.64\", \"size\":\"36.9\", \"side\":\"SELL\", \"hash\":\"21877ca10b8474c1b56609b7190a7eb157da3016\", \"best_bid\":\"0.61\", \"best_ask\":\"0.62\"}], \"timestamp\":\"1785127059488\", \"event_type\":\"price_change\"}","received_at":"2026-07-27T04:37:39.563183Z","schema_version":"clob-market-ws.price_change.v1","sequence":null,"server_hash":null,"server_timestamp":"1785127059488","session_id":"e9443c7415a0419799bee9cfbb1a9e4d","source":"clob_market_ws"},"received_at":"2026-07-27T04:37:39.563183Z","record_id":"dde6879cd68b7e3fa8887a249da6e31117c6e416cab77d097edd0fe4aaad9a87","schema_fingerprint":"4aa3821a28b0b7c2400bc59aba4bcc0a76e971dadd19610d3ad38c768e124dc7","schema_version":"edge-lab-recorder.raw.v1","sequence":null,"source":"clob_market_ws"}
{"event_at":"2026-07-27T04:37:39.489000Z","event_fingerprint":"d51f91b6ae8b77ef6604b533e99787f8853ba9456b909edc8851d0d4e13cb2c1","payload":{"connection_id":"0f4979d6978d463e9660b042fdcf555f","event_at":"2026-07-27T04:37:39.489000Z","event_type":"price_change","frame_hash":"cbb887d8ad0af5f15d60a413900e178d2e29c36a0c6939dcece5f4c1f828e2ce","frame_index":0,"kind":"data","monotonic_ns":229042832566500,"payload":{"event_type":"price_change","market":"0xeb66215f2e9faa6449e30a02bab5b8ed7b79a38bf961f6b24d0073c9c2419250","price_changes":[{"asset_id":"60386828328910021732068595344565885737045900010034836345809386672230885527307","best_ask":"0.39","best_bid":"0.38","hash":"1c9d0b9a91cb76093a3212d30fc74cd13b55ea11","price":"0.33","side":"BUY","size":"102.97"},{"asset_id":"69697746896130839564035629862476347944307040470122503199396727085502753297492","best_ask":"0.62","best_bid":"0.61","hash":"44fa2accf1f59de86df92691f85cd7944cb93ebe","price":"0.67","side":"SELL","size":"102.97"}],"timestamp":"1785127059489"},"payload_hash":"f6d50351c1f726f91ff07fb647324ee8429273298d89ca7d3a2c9a447acb173a","raw_frame":"{\"market\":\"0xeb66215f2e9faa6449e30a02bab5b8ed7b79a38bf961f6b24d0073c9c2419250\", \"price_changes\":[{\"asset_id\":\"60386828328910021732068595344565885737045900010034836345809386672230885527307\", \"price\":\"0.33\", \"size\":\"102.97\", \"side\":\"BUY\", \"hash\":\"1c9d0b9a91cb76093a3212d30fc74cd13b55ea11\", \"best_bid\":\"0.38\", \"best_ask\":\"0.39\"}, {\"asset_id\":\"69697746896130839564035629862476347944307040470122503199396727085502753297492\", \"price\":\"0.67\", \"size\":\"102.97\", \"side\":\"SELL\", \"hash\":\"44fa2accf1f59de86df92691f85cd7944cb93ebe\", \"best_bid\":\"0.61\", \"best_ask\":\"0.62\"}], \"timestamp\":\"1785127059489\", \"event_type\":\"price_change\"}","received_at":"2026-07-27T04:37:39.566715Z","schema_version":"clob-market-ws.price_change.v1","sequence":null,"server_hash":null,"server_timestamp":"1785127059489","session_id":"e9443c7415a0419799bee9cfbb1a9e4d","source":"clob_market_ws"},"received_at":"2026-07-27T04:37:39.566715Z","record_id":"ca5f34ae9b97800798dc973c83fc987b40bc8329fff674254df707bc0c1bbc3e","schema_fingerprint":"4aa3821a28b0b7c2400bc59aba4bcc0a76e971dadd19610d3ad38c768e124dc7","schema_version":"edge-lab-recorder.raw.v1","sequence":null,"source":"clob_market_ws"}
{"event_at":"2026-07-27T04:37:39.489000Z","event_fingerprint":"29eae47caac4617001b64da1f243dcb2808785411f7ff9fbb5943dd80004c986","payload":{"connection_id":"0f4979d6978d463e9660b042fdcf555f","event_at":"2026-07-27T04:37:39.489000Z","event_type":"price_change","frame_hash":"8f8e24409dc7efbf15faa13c709a2052a2e373aaed6d6c55ec825fbae7bcf012","frame_index":0,"kind":"data","monotonic_ns":229042834592041,"payload":{"event_type":"price_change","market":"0xeb66215f2e9faa6449e30a02bab5b8ed7b79a38bf961f6b24d0073c9c2419250","price_changes":[{"asset_id":"69697746896130839564035629862476347944307040470122503199396727085502753297492","best_ask":"0.62","best_bid":"0.61","hash":"91b063724f48f601b81ed3419fc7d78847e2b9a2","price":"0.6","side":"BUY","size":"24.6"},{"asset_id":"60386828328910021732068595344565885737045900010034836345809386672230885527307","best_ask":"0.39","best_bid":"0.38","hash":"febb43197ad20e31adb120c9b183a399596f9bf1","price":"0.4","side":"SELL","size":"24.6"}],"timestamp":"1785127059489"},"payload_hash":"2474a1e6a63304146cd8f6428d6520da57a853bc86557ded817f8cae61755454","raw_frame":"{\"market\":\"0xeb66215f2e9faa6449e30a02bab5b8ed7b79a38bf961f6b24d0073c9c2419250\", \"price_changes\":[{\"asset_id\":\"69697746896130839564035629862476347944307040470122503199396727085502753297492\", \"price\":\"0.6\", \"size\":\"24.6\", \"side\":\"BUY\", \"hash\":\"91b063724f48f601b81ed3419fc7d78847e2b9a2\", \"best_bid\":\"0.61\", \"best_ask\":\"0.62\"}, {\"asset_id\":\"60386828328910021732068595344565885737045900010034836345809386672230885527307\", \"price\":\"0.4\", \"size\":\"24.6\", \"side\":\"SELL\", \"hash\":\"febb43197ad20e31adb120c9b183a399596f9bf1\", \"best_bid\":\"0.38\", \"best_ask\":\"0.39\"}], \"timestamp\":\"1785127059489\", \"event_type\":\"price_change\"}","received_at":"2026-07-27T04:37:39.568742Z","schema_version":"clob-market-ws.price_change.v1","sequence":null,"server_hash":null,"server_timestamp":"1785127059489","session_id":"e9443c7415a0419799bee9cfbb1a9e4d","source":"clob_market_ws"},"received_at":"2026-07-27T04:37:39.568742Z","record_id":"2eee1cfb6cacd047fd0291822157a4e7069022b0072cc2ea1042ee85ed134078","schema_fingerprint":"4aa3821a28b0b7c2400bc59aba4bcc0a76e971dadd19610d3ad38c768e124dc7","schema_version":"edge-lab-recorder.raw.v1","sequence":null,"source":"clob_market_ws"}
{"event_at":"2026-07-27T04:37:39.490000Z","event_fingerprint":"628d042fca2684e1ae68dd9f85030a9a146c245302bf9a66ed8453df6ba624fb","payload":{"connection_id":"0f4979d6978d463e9660b042fdcf555f","event_at":"2026-07-27T04:37:39.490000Z","event_type":"price_change","frame_hash":"3773dc4a61fe246ab908d8f9e5a0d47cb4242f9252ae6f63340d0514b42085b6","frame_index":0,"kind":"data","monotonic_ns":229042836892500,"payload":{"event_type":"price_change","market":"0xeb66215f2e9faa6449e30a02bab5b8ed7b79a38bf961f6b24d0073c9c2419250","price_changes":[{"asset_id":"69697746896130839564035629862476347944307040470122503199396727085502753297492","best_ask":"0.62","best_bid":"0.61","hash":"0eb7e0ac48b0349258c17a9ad946d91c69a396b3","price":"0.01","side":"BUY","size":"5829.91"},{"asset_id":"60386828328910021732068595344565885737045900010034836345809386672230885527307","best_ask":"0.39","best_bid":"0.38","hash":"eab1853e6b865dac7cce05c311da12a1cc6c8745","price":"0.99","side":"SELL","size":"5829.91"}],"timestamp":"1785127059490"},"payload_hash":"62a31e49f6972ba12e20292ae84022e35b8bc373e73e18f39859e3bbd42c7be2","raw_frame":"{\"market\":\"0xeb66215f2e9faa6449e30a02bab5b8ed7b79a38bf961f6b24d0073c9c2419250\", \"price_changes\":[{\"asset_id\":\"69697746896130839564035629862476347944307040470122503199396727085502753297492\", \"price\":\"0.01\", \"size\":\"5829.91\", \"side\":\"BUY\", \"hash\":\"0eb7e0ac48b0349258c17a9ad946d91c69a396b3\", \"best_bid\":\"0.61\", \"best_ask\":\"0.62\"}, {\"asset_id\":\"60386828328910021732068595344565885737045900010034836345809386672230885527307\", \"price\":\"0.99\", \"size\":\"5829.91\", \"side\":\"SELL\", \"hash\":\"eab1853e6b865dac7cce05c311da12a1cc6c8745\", \"best_bid\":\"0.38\", \"best_ask\":\"0.39\"}], \"timestamp\":\"1785127059490\", \"event_type\":\"price_change\"}","received_at":"2026-07-27T04:37:39.571045Z","schema_version":"clob-market-ws.price_change.v1","sequence":null,"server_hash":null,"server_timestamp":"1785127059490","session_id":"e9443c7415a0419799bee9cfbb1a9e4d","source":"clob_market_ws"},"received_at":"2026-07-27T04:37:39.571045Z","record_id":"936e1cefd7e6007f180b6df4d01ecd05374fabd1d332da235104f1affaa12b3b","schema_fingerprint":"4aa3821a28b0b7c2400bc59aba4bcc0a76e971dadd19610d3ad38c768e124dc7","schema_version":"edge-lab-recorder.raw.v1","sequence":null,"source":"clob_market_ws"}
{"event_at":"2026-07-27T04:37:39.501000Z","event_fingerprint":"858e5cb79c66032a3818a779c0a8b0f3a95e4ea7aac83c1edad7933154d0b66a","payload":{"connection_id":"0f4979d6978d463e9660b042fdcf555f","event_at":"2026-07-27T04:37:39.501000Z","event_type":"price_change","frame_hash":"6c4cfc21ca74845d5548f91fdbfc90ece8e458c65dfd31b6795b4a2c770cdc23","frame_index":0,"kind":"data","monotonic_ns":229042838308625,"payload":{"event_type":"price_change","market":"0xeb66215f2e9faa6449e30a02bab5b8ed7b79a38bf961f6b24d0073c9c2419250","price_changes":[{"asset_id":"60386828328910021732068595344565885737045900010034836345809386672230885527307","best_ask":"0.39","best_bid":"0.38","hash":"c1aeaa2122acb8c4e22de67903b19cb02a3ccff3","price":"0.33","side":"BUY","size":"75.37"},{"asset_id":"69697746896130839564035629862476347944307040470122503199396727085502753297492","best_ask":"0.62","best_bid":"0.61","hash":"c67b048fb22ee30f7ff3ba2fb6eb9e19792e5085","price":"0.67","side":"SELL","size":"75.37"}],"timestamp":"1785127059501"},"payload_hash":"047df60e71529c3ac67b8cbd50ef9de832dda2c9c593948d323cbe71e65598d5","raw_frame":"{\"market\":\"0xeb66215f2e9faa6449e30a02bab5b8ed7b79a38bf961f6b24d0073c9c2419250\", \"price_changes\":[{\"asset_id\":\"60386828328910021732068595344565885737045900010034836345809386672230885527307\", \"price\":\"0.33\", \"size\":\"75.37\", \"side\":\"BUY\", \"hash\":\"c1aeaa2122acb8c4e22de67903b19cb02a3ccff3\", \"best_bid\":\"0.38\", \"best_ask\":\"0.39\"}, {\"asset_id\":\"69697746896130839564035629862476347944307040470122503199396727085502753297492\", \"price\":\"0.67\", \"size\":\"75.37\", \"side\":\"SELL\", \"hash\":\"c67b048fb22ee30f7ff3ba2fb6eb9e19792e5085\", \"best_bid\":\"0.61\", \"best_ask\":\"0.62\"}], \"timestamp\":\"1785127059501\", \"event_type\":\"price_change\"}","received_at":"2026-07-27T04:37:39.572462Z","schema_version":"clob-market-ws.price_change.v1","sequence":null,"server_hash":null,"server_timestamp":"1785127059501","session_id":"e9443c7415a0419799bee9cfbb1a9e4d","source":"clob_market_ws"},"received_at":"2026-07-27T04:37:39.572462Z","record_id":"26d0229403a0fc6a692c49a6ac650b2f9fd2bb7cec38404b0779de8b68af2802","schema_fingerprint":"4aa3821a28b0b7c2400bc59aba4bcc0a76e971dadd19610d3ad38c768e124dc7","schema_version":"edge-lab-recorder.raw.v1","sequence":null,"source":"clob_market_ws"}
{"event_at":"2026-07-27T04:37:39.502000Z","event_fingerprint":"a8b24a093d9fd4f6918b6546a359ffe6ee805672af0454e32041d5460ff87247","payload":{"connection_id":"0f4979d6978d463e9660b042fdcf555f","event_at":"2026-07-27T04:37:39.502000Z","event_type":"price_change","frame_hash":"baec587566db05892d1ed4ab8bc4ed8888a50603c54617c689ee53bf440d2a01","frame_index":0,"kind":"data","monotonic_ns":229042839654250,"payload":{"event_type":"price_change","market":"0xeb66215f2e9faa6449e30a02bab5b8ed7b79a38bf961f6b24d0073c9c2419250","price_changes":[{"asset_id":"60386828328910021732068595344565885737045900010034836345809386672230885527307","best_ask":"0.39","best_bid":"0.38","hash":"2a3de9fa7abd05589228458b7ba5fdb1a468eaa0","price":"0.35","side":"BUY","size":"180.85"},{"asset_id":"69697746896130839564035629862476347944307040470122503199396727085502753297492","best_ask":"0.62","best_bid":"0.61","hash":"6081d689f8cdcacb091cc44a491dd32c11ce8af5","price":"0.65","side":"SELL","size":"180.85"}],"timestamp":"1785127059502"},"payload_hash":"8325dbbbea066b434c2d4ac103618f6c5645d86774134284e5a565bb5742a899","raw_frame":"{\"market\":\"0xeb66215f2e9faa6449e30a02bab5b8ed7b79a38bf961f6b24d0073c9c2419250\", \"price_changes\":[{\"asset_id\":\"60386828328910021732068595344565885737045900010034836345809386672230885527307\", \"price\":\"0.35\", \"size\":\"180.85\", \"side\":\"BUY\", \"hash\":\"2a3de9fa7abd05589228458b7ba5fdb1a468eaa0\", \"best_bid\":\"0.38\", \"best_ask\":\"0.39\"}, {\"asset_id\":\"69697746896130839564035629862476347944307040470122503199396727085502753297492\", \"price\":\"0.65\", \"size\":\"180.85\", \"side\":\"SELL\", \"hash\":\"6081d689f8cdcacb091cc44a491dd32c11ce8af5\", \"best_bid\":\"0.61\", \"best_ask\":\"0.62\"}], \"timestamp\":\"1785127059502\", \"event_type\":\"price_change\"}","received_at":"2026-07-27T04:37:39.573808Z","schema_version":"clob-market-ws.price_change.v1","sequence":null,"server_hash":null,"server_timestamp":"1785127059502","session_id":"e9443c7415a0419799bee9cfbb1a9e4d","source":"clob_market_ws"},"received_at":"2026-07-27T04:37:39.573808Z","record_id":"b054d9e1dda5be004989e2617ab9e32f11c94fad874f1b62feb167f394a50027","schema_fingerprint":"4aa3821a28b0b7c2400bc59aba4bcc0a76e971dadd19610d3ad38c768e124dc7","schema_version":"edge-lab-recorder.raw.v1","sequence":null,"source":"clob_market_ws"}
{"event_at":"2026-07-27T04:37:39.504000Z","event_fingerprint":"2d403541fca4b97b4a7ccd6c629e202f1a8ed2485c82813bb851ecc000fca9c1","payload":{"connection_id":"0f4979d6978d463e9660b042fdcf555f","event_at":"2026-07-27T04:37:39.504000Z","event_type":"price_change","frame_hash":"e3f3228fa2bf0cde73327cbdb7c9ef41fb4aee86a2384875ff5f46b682c609eb","frame_index":0,"kind":"data","monotonic_ns":229042840905833,"payload":{"event_type":"price_change","market":"0xeb66215f2e9faa6449e30a02bab5b8ed7b79a38bf961f6b24d0073c9c2419250","price_changes":[{"asset_id":"60386828328910021732068595344565885737045900010034836345809386672230885527307","best_ask":"0.39","best_bid":"0.38","hash":"cd17e4d5b3f381ab3cff12a178beaf72a10c5e1f","price":"0.3","side":"BUY","size":"245"},{"asset_id":"69697746896130839564035629862476347944307040470122503199396727085502753297492","best_ask":"0.62","best_bid":"0.61","hash":"eb21d9aafafccfc175c4e77bf0344e5b80ab4e80","price":"0.7","side":"SELL","size":"245"}],"timestamp":"1785127059504"},"payload_hash":"2a87c064355b01f42ab12eb27b6060c9b75cad919af40bdb22e98aaa7221727a","raw_frame":"{\"market\":\"0xeb66215f2e9faa6449e30a02bab5b8ed7b79a38bf961f6b24d0073c9c2419250\", \"price_changes\":[{\"asset_id\":\"60386828328910021732068595344565885737045900010034836345809386672230885527307\", \"price\":\"0.3\", \"size\":\"245\", \"side\":\"BUY\", \"hash\":\"cd17e4d5b3f381ab3cff12a178beaf72a10c5e1f\", \"best_bid\":\"0.38\", \"best_ask\":\"0.39\"}, {\"asset_id\":\"69697746896130839564035629862476347944307040470122503199396727085502753297492\", \"price\":\"0.7\", \"size\":\"245\", \"side\":\"SELL\", \"hash\":\"eb21d9aafafccfc175c4e77bf0344e5b80ab4e80\", \"best_bid\":\"0.61\", \"best_ask\":\"0.62\"}], \"timestamp\":\"1785127059504\", \"event_type\":\"price_change\"}","received_at":"2026-07-27T04:37:39.575060Z","schema_version":"clob-market-ws.price_change.v1","sequence":null,"server_hash":null,"server_timestamp":"1785127059504","session_id":"e9443c7415a0419799bee9cfbb1a9e4d","source":"clob_market_ws"},"received_at":"2026-07-27T04:37:39.575060Z","record_id":"86f60dae2f45370a67481bd173c5872d2437c7065301761b56ef1f38ba69882b","schema_fingerprint":"4aa3821a28b0b7c2400bc59aba4bcc0a76e971dadd19610d3ad38c768e124dc7","schema_version":"edge-lab-recorder.raw.v1","sequence":null,"source":"clob_market_ws"}
{"event_at":"2026-07-27T04:37:39.504000Z","event_fingerprint":"821c63ea609cdadcd36c7ebc6027fe57714d9326b39124ebef15343689ce6f8a","payload":{"connection_id":"0f4979d6978d463e9660b042fdcf555f","event_at":"2026-07-27T04:37:39.504000Z","event_type":"price_change","frame_hash":"57af2ff566aae6215c7a23ad51760d0241039868c6222247f6de9150e7de1fe4","frame_index":0,"kind":"data","monotonic_ns":229042842089791,"payload":{"event_type":"price_change","market":"0xeb66215f2e9faa6449e30a02bab5b8ed7b79a38bf961f6b24d0073c9c2419250","price_changes":[{"asset_id":"60386828328910021732068595344565885737045900010034836345809386672230885527307","best_ask":"0.39","best_bid":"0.38","hash":"ab9a9cd4259bc7d83309a9fc901aff7991b2e196","price":"0.36","side":"BUY","size":"22.9"},{"asset_id":"69697746896130839564035629862476347944307040470122503199396727085502753297492","best_ask":"0.62","best_bid":"0.61","hash":"9b84e97616a5a2407fe41ada28f7c104a8dc5c6a","price":"0.64","side":"SELL","size":"22.9"}],"timestamp":"1785127059504"},"payload_hash":"15f521b1f2b2d3e6cfa923f5b2274963ae3b7f89e093bf5d4d9fffd86602bd5b","raw_frame":"{\"market\":\"0xeb66215f2e9faa6449e30a02bab5b8ed7b79a38bf961f6b24d0073c9c2419250\", \"price_changes\":[{\"asset_id\":\"60386828328910021732068595344565885737045900010034836345809386672230885527307\", \"price\":\"0.36\", \"size\":\"22.9\", \"side\":\"BUY\", \"hash\":\"ab9a9cd4259bc7d83309a9fc901aff7991b2e196\", \"best_bid\":\"0.38\", \"best_ask\":\"0.39\"}, {\"asset_id\":\"69697746896130839564035629862476347944307040470122503199396727085502753297492\", \"price\":\"0.64\", \"size\":\"22.9\", \"side\":\"SELL\", \"hash\":\"9b84e97616a5a2407fe41ada28f7c104a8dc5c6a\", \"best_bid\":\"0.61\", \"best_ask\":\"0.62\"}], \"timestamp\":\"1785127059504\", \"event_type\":\"price_change\"}","received_at":"2026-07-27T04:37:39.576244Z","schema_version":"clob-market-ws.price_change.v1","sequence":null,"server_hash":null,"server_timestamp":"1785127059504","session_id":"e9443c7415a0419799bee9cfbb1a9e4d","source":"clob_market_ws"},"received_at":"2026-07-27T04:37:39.576244Z","record_id":"34e25ba88cd5d4b8fa6e3a290142e52980c96326afaec02d29b85a2cc4438ef2","schema_fingerprint":"4aa3821a28b0b7c2400bc59aba4bcc0a76e971dadd19610d3ad38c768e124dc7","schema_version":"edge-lab-recorder.raw.v1","sequence":null,"source":"clob_market_ws"}
{"event_at":"2026-07-27T04:37:39.505000Z","event_fingerprint":"ee0c43871843cc9a91457226a0e839e7d93fed499295fa97da821f2d0035cc9c","payload":{"connection_id":"0f4979d6978d463e9660b042fdcf555f","event_at":"2026-07-27T04:37:39.505000Z","event_type":"price_change","frame_hash":"8846d4215c9a35a47566d1ee074a946af4a6065bb38eb0e201e36b9f49703846","frame_index":0,"kind":"data","monotonic_ns":229042843451833,"payload":{"event_type":"price_change","market":"0xeb66215f2e9faa6449e30a02bab5b8ed7b79a38bf961f6b24d0073c9c2419250","price_changes":[{"asset_id":"60386828328910021732068595344565885737045900010034836345809386672230885527307","best_ask":"0.39","best_bid":"0.38","hash":"784cbc54a5c66be526e2d7425eca2d259d6a952e","price":"0.34","side":"BUY","size":"310.19"},{"asset_id":"69697746896130839564035629862476347944307040470122503199396727085502753297492","best_ask":"0.62","best_bid":"0.61","hash":"69f9fe8059e825cd11c918105d1c8edcb242aece","price":"0.66","side":"SELL","size":"310.19"}],"timestamp":"1785127059505"},"payload_hash":"428b9f03940120fdbd84473e77951af56ced56a81db62dda76440cf102eaef3d","raw_frame":"{\"market\":\"0xeb66215f2e9faa6449e30a02bab5b8ed7b79a38bf961f6b24d0073c9c2419250\", \"price_changes\":[{\"asset_id\":\"60386828328910021732068595344565885737045900010034836345809386672230885527307\", \"price\":\"0.34\", \"size\":\"310.19\", \"side\":\"BUY\", \"hash\":\"784cbc54a5c66be526e2d7425eca2d259d6a952e\", \"best_bid\":\"0.38\", \"best_ask\":\"0.39\"}, {\"asset_id\":\"69697746896130839564035629862476347944307040470122503199396727085502753297492\", \"price\":\"0.66\", \"size\":\"310.19\", \"side\":\"SELL\", \"hash\":\"69f9fe8059e825cd11c918105d1c8edcb242aece\", \"best_bid\":\"0.61\", \"best_ask\":\"0.62\"}], \"timestamp\":\"1785127059505\", \"event_type\":\"price_change\"}","received_at":"2026-07-27T04:37:39.577606Z","schema_version":"clob-market-ws.price_change.v1","sequence":null,"server_hash":null,"server_timestamp":"1785127059505","session_id":"e9443c7415a0419799bee9cfbb1a9e4d","source":"clob_market_ws"},"received_at":"2026-07-27T04:37:39.577606Z","record_id":"1322e385f11b59c6af7e5d5d735e269e019750410d155db95241eacf6fdabc89","schema_fingerprint":"4aa3821a28b0b7c2400bc59aba4bcc0a76e971dadd19610d3ad38c768e124dc7","schema_version":"edge-lab-recorder.raw.v1","sequence":null,"source":"clob_market_ws"}
{"event_at":"2026-07-27T04:37:39.505000Z","event_fingerprint":"da78044c882e3c0a82b8f5be0feac7f30811aebb4df8586982b1aae8edb868e2","payload":{"connection_id":"0f4979d6978d463e9660b042fdcf555f","event_at":"2026-07-27T04:37:39.505000Z","event_type":"price_change","frame_hash":"80997da6977c79207364355f0cdf205d9ca0eb2b79cbc6f0a40a5b9739afd171","frame_index":0,"kind":"data","monotonic_ns":229042846235916,"payload":{"event_type":"price_change","market":"0xeb66215f2e9faa6449e30a02bab5b8ed7b79a38bf961f6b24d0073c9c2419250","price_changes":[{"asset_id":"60386828328910021732068595344565885737045900010034836345809386672230885527307","best_ask":"0.39","best_bid":"0.38","hash":"c40a2384ad6626c615050349d8ed64521915379d","price":"0.35","side":"BUY","size":"175.85"},{"asset_id":"69697746896130839564035629862476347944307040470122503199396727085502753297492","best_ask":"0.62","best_bid":"0.61","hash":"6e3c1bbc8e31c27b614c07e43fac9ca962fae493","price":"0.65","side":"SELL","size":"175.85"}],"timestamp":"1785127059505"},"payload_hash":"c92aea04915a0bed4aa91807ff9f937b4e809030245bec28d9d4ca81260e2c93","raw_frame":"{\"market\":\"0xeb66215f2e9faa6449e30a02bab5b8ed7b79a38bf961f6b24d0073c9c2419250\", \"price_changes\":[{\"asset_id\":\"60386828328910021732068595344565885737045900010034836345809386672230885527307\", \"price\":\"0.35\", \"size\":\"175.85\", \"side\":\"BUY\", \"hash\":\"c40a2384ad6626c615050349d8ed64521915379d\", \"best_bid\":\"0.38\", \"best_ask\":\"0.39\"}, {\"asset_id\":\"69697746896130839564035629862476347944307040470122503199396727085502753297492\", \"price\":\"0.65\", \"size\":\"175.85\", \"side\":\"SELL\", \"hash\":\"6e3c1bbc8e31c27b614c07e43fac9ca962fae493\", \"best_bid\":\"0.61\", \"best_ask\":\"0.62\"}], \"timestamp\":\"1785127059505\", \"event_type\":\"price_change\"}","received_at":"2026-07-27T04:37:39.580380Z","schema_version":"clob-market-ws.price_change.v1","sequence":null,"server_hash":null,"server_timestamp":"1785127059505","session_id":"e9443c7415a0419799bee9cfbb1a9e4d","source":"clob_market_ws"},"received_at":"2026-07-27T04:37:39.580380Z","record_id":"0f47d1d9fa8e852daaa6d5ba367af8254a58e14257029fb1acfe1518b98193dd","schema_fingerprint":"4aa3821a28b0b7c2400bc59aba4bcc0a76e971dadd19610d3ad38c768e124dc7","schema_version":"edge-lab-recorder.raw.v1","sequence":null,"source":"clob_market_ws"}
{"event_at":"2026-07-27T04:37:39.506000Z","event_fingerprint":"904858b27bbc4e6ed352821ac0577a0872d05455e48cba059d852f00a81d6e3b","payload":{"connection_id":"0f4979d6978d463e9660b042fdcf555f","event_at":"2026-07-27T04:37:39.506000Z","event_type":"price_change","frame_hash":"c05fd998877dee9b279bc631716315efcc777d6069b0775547474c57c508a809","frame_index":0,"kind":"data","monotonic_ns":229042848035333,"payload":{"event_type":"price_change","market":"0xeb66215f2e9faa6449e30a02bab5b8ed7b79a38bf961f6b24d0073c9c2419250","price_changes":[{"asset_id":"60386828328910021732068595344565885737045900010034836345809386672230885527307","best_ask":"0.39","best_bid":"0.38","hash":"e448e170e9983d2e0221024e1a43388ea04db8fb","price":"0.35","side":"BUY","size":"79.85"},{"asset_id":"69697746896130839564035629862476347944307040470122503199396727085502753297492","best_ask":"0.62","best_bid":"0.61","hash":"b69c108a478160d6a55247bcaee43fdb114ade52","price":"0.65","side":"SELL","size":"79.85"}],"timestamp":"1785127059506"},"payload_hash":"10aebe6545071e994c0a9a6fc8d55389e05508c168b1423061afc492e8d643ed","raw_frame":"{\"market\":\"0xeb66215f2e9faa6449e30a02bab5b8ed7b79a38bf961f6b24d0073c9c2419250\", \"price_changes\":[{\"asset_id\":\"60386828328910021732068595344565885737045900010034836345809386672230885527307\", \"price\":\"0.35\", \"size\":\"79.85\", \"side\":\"BUY\", \"hash\":\"e448e170e9983d2e0221024e1a43388ea04db8fb\", \"best_bid\":\"0.38\", \"best_ask\":\"0.39\"}, {\"asset_id\":\"69697746896130839564035629862476347944307040470122503199396727085502753297492\", \"price\":\"0.65\", \"size\":\"79.85\", \"side\":\"SELL\", \"hash\":\"b69c108a478160d6a55247bcaee43fdb114ade52\", \"best_bid\":\"0.61\", \"best_ask\":\"0.62\"}], \"timestamp\":\"1785127059506\", \"event_type\":\"price_change\"}","received_at":"2026-07-27T04:37:39.582182Z","schema_version":"clob-market-ws.price_change.v1","sequence":null,"server_hash":null,"server_timestamp":"1785127059506","session_id":"e9443c7415a0419799bee9cfbb1a9e4d","source":"clob_market_ws"},"received_at":"2026-07-27T04:37:39.582182Z","record_id":"7ef2ad02f1a7967466464df18e4347978004fdb214665465eeb8e8233fea1803","schema_fingerprint":"4aa3821a28b0b7c2400bc59aba4bcc0a76e971dadd19610d3ad38c768e124dc7","schema_version":"edge-lab-recorder.raw.v1","sequence":null,"source":"clob_market_ws"}
{"event_at":"2026-07-27T04:37:39.508000Z","event_fingerprint":"3c9a252c8a41933b3a4b05b4e0cd3febd955e796f7db221371180cbfc810da13","payload":{"connection_id":"0f4979d6978d463e9660b042fdcf555f","event_at":"2026-07-27T04:37:39.508000Z","event_type":"price_change","frame_hash":"cdda7f41c111fe76cd0c5cfab3c51ae4e8b627d74e8f2be58a595b2bb0087097","frame_index":0,"kind":"data","monotonic_ns":229042851078000,"payload":{"event_type":"price_change","market":"0xeb66215f2e9faa6449e30a02bab5b8ed7b79a38bf961f6b24d0073c9c2419250","price_changes":[{"asset_id":"69697746896130839564035629862476347944307040470122503199396727085502753297492","best_ask":"0.62","best_bid":"0.61","hash":"27b42bc6d3c1b6c4114aa6e863c17bd8de8252bd","price":"0.01","side":"BUY","size":"5834.91"},{"asset_id":"60386828328910021732068595344565885737045900010034836345809386672230885527307","best_ask":"0.39","best_bid":"0.38","hash":"1f2954fc59706aa1a1108f5410e3fc17c6f9634d","price":"0.99","side":"SELL","size":"5834.91"}],"timestamp":"1785127059508"},"payload_hash":"579f446bb6c0fc38ecaf3952e5851b6c314f132991ea95708c586d1a9647e008","raw_frame":"{\"market\":\"0xeb66215f2e9faa6449e30a02bab5b8ed7b79a38bf961f6b24d0073c9c2419250\", \"price_changes\":[{\"asset_id\":\"69697746896130839564035629862476347944307040470122503199396727085502753297492\", \"price\":\"0.01\", \"size\":\"5834.91\", \"side\":\"BUY\", \"hash\":\"27b42bc6d3c1b6c4114aa6e863c17bd8de8252bd\", \"best_bid\":\"0.61\", \"best_ask\":\"0.62\"}, {\"asset_id\":\"60386828328910021732068595344565885737045900010034836345809386672230885527307\", \"price\":\"0.99\", \"size\":\"5834.91\", \"side\":\"SELL\", \"hash\":\"1f2954fc59706aa1a1108f5410e3fc17c6f9634d\", \"best_bid\":\"0.38\", \"best_ask\":\"0.39\"}], \"timestamp\":\"1785127059508\", \"event_type\":\"price_change\"}","received_at":"2026-07-27T04:37:39.585226Z","schema_version":"clob-market-ws.price_change.v1","sequence":null,"server_hash":null,"server_timestamp":"1785127059508","session_id":"e9443c7415a0419799bee9cfbb1a9e4d","source":"clob_market_ws"},"received_at":"2026-07-27T04:37:39.585226Z","record_id":"064b12c915294f2170b80bd658c188c6be0320fab2bb7d911f7ecc3e1b215c7b","schema_fingerprint":"4aa3821a28b0b7c2400bc59aba4bcc0a76e971dadd19610d3ad38c768e124dc7","schema_version":"edge-lab-recorder.raw.v1","sequence":null,"source":"clob_market_ws"}
{"event_at":"2026-07-27T04:37:39.508000Z","event_fingerprint":"5f39413791cf39270c80ac58fa8e90c3a433e10362fd82b017d214bf2acbdbf3","payload":{"connection_id":"0f4979d6978d463e9660b042fdcf555f","event_at":"2026-07-27T04:37:39.508000Z","event_type":"price_change","frame_hash":"8eb5d6cbda06ed355f3ccd7c2cf6179601199daad6cbeae5e24665418ee00bc0","frame_index":0,"kind":"data","monotonic_ns":229042852228250,"payload":{"event_type":"price_change","market":"0xeb66215f2e9faa6449e30a02bab5b8ed7b79a38bf961f6b24d0073c9c2419250","price_changes":[{"asset_id":"69697746896130839564035629862476347944307040470122503199396727085502753297492","best_ask":"0.62","best_bid":"0.61","hash":"41485574a85a7b344c7ead2ee05d6d7cb71410a4","price":"0.61","side":"BUY","size":"482.2"},{"asset_id":"60386828328910021732068595344565885737045900010034836345809386672230885527307","best_ask":"0.39","best_bid":"0.38","hash":"f7c23c7e00b21e13fb0a5401dccde7f04e6fc3db","price":"0.39","side":"SELL","size":"482.2"}],"timestamp":"1785127059508"},"payload_hash":"c461d044869af69239e0da6ce8b202633475462051401bcc36f67cea8628268c","raw_frame":"{\"market\":\"0xeb66215f2e9faa6449e30a02bab5b8ed7b79a38bf961f6b24d0073c9c2419250\", \"price_changes\":[{\"asset_id\":\"69697746896130839564035629862476347944307040470122503199396727085502753297492\", \"price\":\"0.61\", \"size\":\"482.2\", \"side\":\"BUY\", \"hash\":\"41485574a85a7b344c7ead2ee05d6d7cb71410a4\", \"best_bid\":\"0.61\", \"best_ask\":\"0.62\"}, {\"asset_id\":\"60386828328910021732068595344565885737045900010034836345809386672230885527307\", \"price\":\"0.39\", \"size\":\"482.2\", \"side\":\"SELL\", \"hash\":\"f7c23c7e00b21e13fb0a5401dccde7f04e6fc3db\", \"best_bid\":\"0.38\", \"best_ask\":\"0.39\"}], \"timestamp\":\"1785127059508\", \"event_type\":\"price_change\"}","received_at":"2026-07-27T04:37:39.586383Z","schema_version":"clob-market-ws.price_change.v1","sequence":null,"server_hash":null,"server_timestamp":"1785127059508","session_id":"e9443c7415a0419799bee9cfbb1a9e4d","source":"clob_market_ws"},"received_at":"2026-07-27T04:37:39.586383Z","record_id":"6379ea3ab574784a61024d0643e64c20241dd85cc3e56aa1dacef435a879ea0f","schema_fingerprint":"4aa3821a28b0b7c2400bc59aba4bcc0a76e971dadd19610d3ad38c768e124dc7","schema_version":"edge-lab-recorder.raw.v1","sequence":null,"source":"clob_market_ws"}
{"event_at":"2026-07-27T04:37:39.509000Z","event_fingerprint":"fbd89456bbaccada2f5e65160c5dba19c87e1d8b72931486810583450387c081","payload":{"connection_id":"0f4979d6978d463e9660b042fdcf555f","event_at":"2026-07-27T04:37:39.509000Z","event_type":"price_change","frame_hash":"e93800be38b0c88ca38b6afabb09925314fcc75fac801627a6949a8df846a227","frame_index":0,"kind":"data","monotonic_ns":229042854384041,"payload":{"event_type":"price_change","market":"0xeb66215f2e9faa6449e30a02bab5b8ed7b79a38bf961f6b24d0073c9c2419250","price_changes":[{"asset_id":"60386828328910021732068595344565885737045900010034836345809386672230885527307","best_ask":"0.39","best_bid":"0.38","hash":"7fa76c033a6147f71f9746b2f78e620535fc5a80","price":"0.3","side":"BUY","size":"215"},{"asset_id":"69697746896130839564035629862476347944307040470122503199396727085502753297492","best_ask":"0.62","best_bid":"0.61","hash":"502e3cd0c05d1f2e1fef586b7bb137b0ccde2981","price":"0.7","side":"SELL","size":"215"}],"timestamp":"1785127059509"},"payload_hash":"8bdd8cddee419d0687e2b111577fe0b3b1914a3701edb4d8ceb5a0b6bf19d56a","raw_frame":"{\"market\":\"0xeb66215f2e9faa6449e30a02bab5b8ed7b79a38bf961f6b24d0073c9c2419250\", \"price_changes\":[{\"asset_id\":\"60386828328910021732068595344565885737045900010034836345809386672230885527307\", \"price\":\"0.3\", \"size\":\"215\", \"side\":\"BUY\", \"hash\":\"7fa76c033a6147f71f9746b2f78e620535fc5a80\", \"best_bid\":\"0.38\", \"best_ask\":\"0.39\"}, {\"asset_id\":\"69697746896130839564035629862476347944307040470122503199396727085502753297492\", \"price\":\"0.7\", \"size\":\"215\", \"side\":\"SELL\", \"hash\":\"502e3cd0c05d1f2e1fef586b7bb137b0ccde2981\", \"best_bid\":\"0.61\", \"best_ask\":\"0.62\"}], \"timestamp\":\"1785127059509\", \"event_type\":\"price_change\"}","received_at":"2026-07-27T04:37:39.588539Z","schema_version":"clob-market-ws.price_change.v1","sequence":null,"server_hash":null,"server_timestamp":"1785127059509","session_id":"e9443c7415a0419799bee9cfbb1a9e4d","source":"clob_market_ws"},"received_at":"2026-07-27T04:37:39.588539Z","record_id":"06b198be55129fbd0b5cd1acb603bf5313dafb4440bf8cb30fbecd9bbf56a254","schema_fingerprint":"4aa3821a28b0b7c2400bc59aba4bcc0a76e971dadd19610d3ad38c768e124dc7","schema_version":"edge-lab-recorder.raw.v1","sequence":null,"source":"clob_market_ws"}
