{"event_at":"2026-07-27T04:32:37.535000Z","event_fingerprint":"25329f1d15d9a7649f240a343e49ed072dadaebcf8b492516ccbed8a9e591a40","payload":{"connection_id":"0f4979d6978d463e9660b042fdcf555f","event_at":"2026-07-27T04:32:37.535000Z","event_type":"price_change","frame_hash":"27a17c04c49be55e52151ad99b5a72b55f89c82473981c3a57b2581e95e5af8b","frame_index":0,"kind":"data","monotonic_ns":228740977630291,"payload":{"event_type":"price_change","market":"0xeb66215f2e9faa6449e30a02bab5b8ed7b79a38bf961f6b24d0073c9c2419250","price_changes":[{"asset_id":"69697746896130839564035629862476347944307040470122503199396727085502753297492","best_ask":"0.19","best_bid":"0.18","hash":"1b933c0bced0e8569828277e46a0570ef4e8be05","price":"0.18","side":"BUY","size":"69.4"},{"asset_id":"60386828328910021732068595344565885737045900010034836345809386672230885527307","best_ask":"0.82","best_bid":"0.81","hash":"3b8f004d4bf83b61bab20cd55b4d4e12e46d7ad8","price":"0.82","side":"SELL","size":"69.4"}],"timestamp":"1785126757535"},"payload_hash":"ef7f99e42e3e1ab7c72719e4a652b81758cc80a3d3bad5293bb0c7f568a4b1a7","raw_frame":"{\"market\":\"0xeb66215f2e9faa6449e30a02bab5b8ed7b79a38bf961f6b24d0073c9c2419250\", \"price_changes\":[{\"asset_id\":\"69697746896130839564035629862476347944307040470122503199396727085502753297492\", \"price\":\"0.18\", \"size\":\"69.4\", \"side\":\"BUY\", \"hash\":\"1b933c0bced0e8569828277e46a0570ef4e8be05\", \"best_bid\":\"0.18\", \"best_ask\":\"0.19\"}, {\"asset_id\":\"60386828328910021732068595344565885737045900010034836345809386672230885527307\", \"price\":\"0.82\", \"size\":\"69.4\", \"side\":\"SELL\", \"hash\":\"3b8f004d4bf83b61bab20cd55b4d4e12e46d7ad8\", \"best_bid\":\"0.81\", \"best_ask\":\"0.82\"}], \"timestamp\":\"1785126757535\", \"event_type\":\"price_change\"}","received_at":"2026-07-27T04:32:37.709160Z","schema_version":"clob-market-ws.price_change.v1","sequence":null,"server_hash":null,"server_timestamp":"1785126757535","session_id":"e9443c7415a0419799bee9cfbb1a9e4d","source":"clob_market_ws"},"received_at":"2026-07-27T04:32:37.709160Z","record_id":"602f82253ad4c60fbb57dd467a6fbbf0ea61d4d4f65d3e39f01c743e9cac2863","schema_fingerprint":"4aa3821a28b0b7c2400bc59aba4bcc0a76e971dadd19610d3ad38c768e124dc7","schema_version":"edge-lab-recorder.raw.v1","sequence":null,"source":"clob_market_ws"}
{"event_at":"2026-07-27T04:32:37.537000Z","event_fingerprint":"325521237652032841e4312069bd781702876c75e37c94032dddbce86a85cffb","payload":{"connection_id":"0f4979d6978d463e9660b042fdcf555f","event_at":"2026-07-27T04:32:37.537000Z","event_type":"price_change","frame_hash":"185823f0cdcec744d0cfbd6c4dc6a4dbab87a95e95989231495edcc22a6fd6ed","frame_index":0,"kind":"data","monotonic_ns":228740983466000,"payload":{"event_type":"price_change","market":"0xeb66215f2e9faa6449e30a02bab5b8ed7b79a38bf961f6b24d0073c9c2419250","price_changes":[{"asset_id":"69697746896130839564035629862476347944307040470122503199396727085502753297492","best_ask":"0.19","best_bid":"0.18","hash":"46cef20ec3dddf8f9e4f46671bfca03481af38d9","price":"0.18","side":"BUY","size":"75.4"},{"asset_id":"60386828328910021732068595344565885737045900010034836345809386672230885527307","best_ask":"0.82","best_bid":"0.81","hash":"a9a8e04844733c35ec9432cf282b4000a433b16e","price":"0.82","side":"SELL","size":"75.4"}],"timestamp":"1785126757537"},"payload_hash":"4fe52c7e3ba45c22fc3c1ba4d705627db98dcae67db677edee17eee43c4bef7c","raw_frame":"{\"market\":\"0xeb66215f2e9faa6449e30a02bab5b8ed7b79a38bf961f6b24d0073c9c2419250\", \"price_changes\":[{\"asset_id\":\"69697746896130839564035629862476347944307040470122503199396727085502753297492\", \"price\":\"0.18\", \"size\":\"75.4\", \"side\":\"BUY\", \"hash\":\"46cef20ec3dddf8f9e4f46671bfca03481af38d9\", \"best_bid\":\"0.18\", \"best_ask\":\"0.19\"}, {\"asset_id\":\"60386828328910021732068595344565885737045900010034836345809386672230885527307\", \"price\":\"0.82\", \"size\":\"75.4\", \"side\":\"SELL\", \"hash\":\"a9a8e04844733c35ec9432cf282b4000a433b16e\", \"best_bid\":\"0.81\", \"best_ask\":\"0.82\"}], \"timestamp\":\"1785126757537\", \"event_type\":\"price_change\"}","received_at":"2026-07-27T04:32:37.714995Z","schema_version":"clob-market-ws.price_change.v1","sequence":null,"server_hash":null,"server_timestamp":"1785126757537","session_id":"e9443c7415a0419799bee9cfbb1a9e4d","source":"clob_market_ws"},"received_at":"2026-07-27T04:32:37.714995Z","record_id":"157cfe93c131b2b51f75d99d532e9f9a15592b2b8dd1b0c84fcb4aad5bd1e716","schema_fingerprint":"4aa3821a28b0b7c2400bc59aba4bcc0a76e971dadd19610d3ad38c768e124dc7","schema_version":"edge-lab-recorder.raw.v1","sequence":null,"source":"clob_market_ws"}
{"event_at":"2026-07-27T04:32:37.538000Z","event_fingerprint":"b4f4c6ad6c27bf95039cfd050e212a6af2aa40f6f53fe2e55728d78c52a5c3cf","payload":{"connection_id":"0f4979d6978d463e9660b042fdcf555f","event_at":"2026-07-27T04:32:37.538000Z","event_type":"price_change","frame_hash":"2c278eb59a855fe7c2d036d92ffd5cbec1d9e943987d6324e96b22bdd6ef48a3","frame_index":0,"kind":"data","monotonic_ns":228740986365208,"payload":{"event_type":"price_change","market":"0xeb66215f2e9faa6449e30a02bab5b8ed7b79a38bf961f6b24d0073c9c2419250","price_changes":[{"asset_id":"69697746896130839564035629862476347944307040470122503199396727085502753297492","best_ask":"0.19","best_bid":"0.18","hash":"a3ccd848411327a45db6b69b0292536e1be15416","price":"0.13","side":"BUY","size":"159.74"},{"asset_id":"60386828328910021732068595344565885737045900010034836345809386672230885527307","best_ask":"0.82","best_bid":"0.81","hash":"3671fcff2bd2869a11cd02bb83f3c10eef33f6a5","price":"0.87","side":"SELL","size":"159.74"}],"timestamp":"1785126757538"},"payload_hash":"69d4b1896cd477a8595f6d928efe486f80b1012e0aa047d957549bb77fb9d7c5","raw_frame":"{\"market\":\"0xeb66215f2e9faa6449e30a02bab5b8ed7b79a38bf961f6b24d0073c9c2419250\", \"price_changes\":[{\"asset_id\":\"69697746896130839564035629862476347944307040470122503199396727085502753297492\", \"price\":\"0.13\", \"size\":\"159.74\", \"side\":\"BUY\", \"hash\":\"a3ccd848411327a45db6b69b0292536e1be15416\", \"best_bid\":\"0.18\", \"best_ask\":\"0.19\"}, {\"asset_id\":\"60386828328910021732068595344565885737045900010034836345809386672230885527307\", \"price\":\"0.87\", \"size\":\"159.74\", \"side\":\"SELL\", \"hash\":\"3671fcff2bd2869a11cd02bb83f3c10eef33f6a5\", \"best_bid\":\"0.81\", \"best_ask\":\"0.82\"}], \"timestamp\":\"1785126757538\", \"event_type\":\"price_change\"}","received_at":"2026-07-27T04:32:37.717895Z","schema_version":"clob-market-ws.price_change.v1","sequence":null,"server_hash":null,"server_timestamp":"1785126757538","session_id":"e9443c7415a0419799bee9cfbb1a9e4d","source":"clob_market_ws"},"received_at":"2026-07-27T04:32:37.717895Z","record_id":"cff4b897c6859c75c92021b46d4f33f5f12c2eb9f5d1e46616bfaa8dc432ac3b","schema_fingerprint":"4aa3821a28b0b7c2400bc59aba4bcc0a76e971dadd19610d3ad38c768e124dc7","schema_version":"edge-lab-recorder.raw.v1","sequence":null,"source":"clob_market_ws"}
{"event_at":"2026-07-27T04:32:37.541000Z","event_fingerprint":"51634c74cf82c04066c0e8f8ed86ce6519b4a26f80c85e18f9bbdac32e7b387c","payload":{"connection_id":"0f4979d6978d463e9660b042fdcf555f","event_at":"2026-07-27T04:32:37.541000Z","event_type":"price_change","frame_hash":"2764eed60adec789c56cd80c347d1f862184ecd30755d6e66cf11c992562a0ab","frame_index":0,"kind":"data","monotonic_ns":228740989418875,"payload":{"event_type":"price_change","market":"0xeb66215f2e9faa6449e30a02bab5b8ed7b79a38bf961f6b24d0073c9c2419250","price_changes":[{"asset_id":"60386828328910021732068595344565885737045900010034836345809386672230885527307","best_ask":"0.82","best_bid":"0.81","hash":"83b45a51ed7a385a8d772c7c276ff7d593702b19","price":"0.83","side":"SELL","size":"421.4"},{"asset_id":"69697746896130839564035629862476347944307040470122503199396727085502753297492","best_ask":"0.19","best_bid":"0.18","hash":"403ab31a4fb2383c0d00fcda2f7f2d6b30c19f2c","price":"0.17","side":"BUY","size":"421.4"}],"timestamp":"1785126757541"},"payload_hash":"f4a2b5b1fadf7623943286262d0308efcadd946a41e17af0213ad8a0ae9187bd","raw_frame":"{\"market\":\"0xeb66215f2e9faa6449e30a02bab5b8ed7b79a38bf961f6b24d0073c9c2419250\", \"price_changes\":[{\"asset_id\":\"60386828328910021732068595344565885737045900010034836345809386672230885527307\", \"price\":\"0.83\", \"size\":\"421.4\", \"side\":\"SELL\", \"hash\":\"83b45a51ed7a385a8d772c7c276ff7d593702b19\", \"best_bid\":\"0.81\", \"best_ask\":\"0.82\"}, {\"asset_id\":\"69697746896130839564035629862476347944307040470122503199396727085502753297492\", \"price\":\"0.17\", \"size\":\"421.4\", \"side\":\"BUY\", \"hash\":\"403ab31a4fb2383c0d00fcda2f7f2d6b30c19f2c\", \"best_bid\":\"0.18\", \"best_ask\":\"0.19\"}], \"timestamp\":\"1785126757541\", \"event_type\":\"price_change\"}","received_at":"2026-07-27T04:32:37.720951Z","schema_version":"clob-market-ws.price_change.v1","sequence":null,"server_hash":null,"server_timestamp":"1785126757541","session_id":"e9443c7415a0419799bee9cfbb1a9e4d","source":"clob_market_ws"},"received_at":"2026-07-27T04:32:37.720951Z","record_id":"f5be490b2fa45b5e4c4d6c13b0eaa746c5dd787bf201f315460d4f012614c3f1","schema_fingerprint":"4aa3821a28b0b7c2400bc59aba4bcc0a76e971dadd19610d3ad38c768e124dc7","schema_version":"edge-lab-recorder.raw.v1","sequence":null,"source":"clob_market_ws"}
{"event_at":"2026-07-27T04:32:37.543000Z","event_fingerprint":"4764dcc9e020899babccd8394f8ef062463613f53f5c857a636d597e87368632","payload":{"connection_id":"0f4979d6978d463e9660b042fdcf555f","event_at":"2026-07-27T04:32:37.543000Z","event_type":"price_change","frame_hash":"60f1dcdae2bc5b4eb8ffcccf5b16924646d5597c028219f6ed1b5bf4baa31fb6","frame_index":0,"kind":"data","monotonic_ns":228740992054291,"payload":{"event_type":"price_change","market":"0xeb66215f2e9faa6449e30a02bab5b8ed7b79a38bf961f6b24d0073c9c2419250","price_changes":[{"asset_id":"69697746896130839564035629862476347944307040470122503199396727085502753297492","best_ask":"0.19","best_bid":"0.18","hash":"159f37cff7a7a45b8101807f9cf5060a24cc0500","price":"0.18","side":"BUY","size":"85.4"},{"asset_id":"60386828328910021732068595344565885737045900010034836345809386672230885527307","best_ask":"0.82","best_bid":"0.81","hash":"175badb502fb72e30ff66e763874dc731ed8dc46","price":"0.82","side":"SELL","size":"85.4"}],"timestamp":"1785126757543"},"payload_hash":"974fcd91c9d52e581f38eac090d9640466fc3c6e697ad8738e42c494e749f313","raw_frame":"{\"market\":\"0xeb66215f2e9faa6449e30a02bab5b8ed7b79a38bf961f6b24d0073c9c2419250\", \"price_changes\":[{\"asset_id\":\"69697746896130839564035629862476347944307040470122503199396727085502753297492\", \"price\":\"0.18\", \"size\":\"85.4\", \"side\":\"BUY\", \"hash\":\"159f37cff7a7a45b8101807f9cf5060a24cc0500\", \"best_bid\":\"0.18\", \"best_ask\":\"0.19\"}, {\"asset_id\":\"60386828328910021732068595344565885737045900010034836345809386672230885527307\", \"price\":\"0.82\", \"size\":\"85.4\", \"side\":\"SELL\", \"hash\":\"175badb502fb72e30ff66e763874dc731ed8dc46\", \"best_bid\":\"0.81\", \"best_ask\":\"0.82\"}], \"timestamp\":\"1785126757543\", \"event_type\":\"price_change\"}","received_at":"2026-07-27T04:32:37.723585Z","schema_version":"clob-market-ws.price_change.v1","sequence":null,"server_hash":null,"server_timestamp":"1785126757543","session_id":"e9443c7415a0419799bee9cfbb1a9e4d","source":"clob_market_ws"},"received_at":"2026-07-27T04:32:37.723585Z","record_id":"0263a6f1a9d23c5fb048d4c4128e094f603a79fb291962baee4ac9ba0e1b1aad","schema_fingerprint":"4aa3821a28b0b7c2400bc59aba4bcc0a76e971dadd19610d3ad38c768e124dc7","schema_version":"edge-lab-recorder.raw.v1","sequence":null,"source":"clob_market_ws"}
{"event_at":"2026-07-27T04:32:37.544000Z","event_fingerprint":"0c2979a06b7c4bca7e393b1c8835b65e02162866b23658da3dbfe1f440a20cb4","payload":{"connection_id":"0f4979d6978d463e9660b042fdcf555f","event_at":"2026-07-27T04:32:37.544000Z","event_type":"price_change","frame_hash":"d8e316577e3377354f9e71453e57e3f68cd682a1713140ac5b36389e81fe2db6","frame_index":0,"kind":"data","monotonic_ns":228740994977041,"payload":{"event_type":"price_change","market":"0xeb66215f2e9faa6449e30a02bab5b8ed7b79a38bf961f6b24d0073c9c2419250","price_changes":[{"asset_id":"60386828328910021732068595344565885737045900010034836345809386672230885527307","best_ask":"0.82","best_bid":"0.81","hash":"7a7801731dea91011387f2216a28fb7b6eb86e23","price":"0.81","side":"BUY","size":"5.17"},{"asset_id":"69697746896130839564035629862476347944307040470122503199396727085502753297492","best_ask":"0.19","best_bid":"0.18","hash":"3f52d0c2487674291f87a167f0008412a5bf556b","price":"0.19","side":"SELL","size":"5.17"}],"timestamp":"1785126757544"},"payload_hash":"114d6760429107042b371045d8527920d7bfcb74f98ac688f4f18cd79657d6fc","raw_frame":"{\"market\":\"0xeb66215f2e9faa6449e30a02bab5b8ed7b79a38bf961f6b24d0073c9c2419250\", \"price_changes\":[{\"asset_id\":\"60386828328910021732068595344565885737045900010034836345809386672230885527307\", \"price\":\"0.81\", \"size\":\"5.17\", \"side\":\"BUY\", \"hash\":\"7a7801731dea91011387f2216a28fb7b6eb86e23\", \"best_bid\":\"0.81\", \"best_ask\":\"0.82\"}, {\"asset_id\":\"69697746896130839564035629862476347944307040470122503199396727085502753297492\", \"price\":\"0.19\", \"size\":\"5.17\", \"side\":\"SELL\", \"hash\":\"3f52d0c2487674291f87a167f0008412a5bf556b\", \"best_bid\":\"0.18\", \"best_ask\":\"0.19\"}], \"timestamp\":\"1785126757544\", \"event_type\":\"price_change\"}","received_at":"2026-07-27T04:32:37.726507Z","schema_version":"clob-market-ws.price_change.v1","sequence":null,"server_hash":null,"server_timestamp":"1785126757544","session_id":"e9443c7415a0419799bee9cfbb1a9e4d","source":"clob_market_ws"},"received_at":"2026-07-27T04:32:37.726507Z","record_id":"cc14ad4ccdb1bcaf6a6ea1c88ac0d1552dd67565fc8e7b2e43856452b0a4528d","schema_fingerprint":"4aa3821a28b0b7c2400bc59aba4bcc0a76e971dadd19610d3ad38c768e124dc7","schema_version":"edge-lab-recorder.raw.v1","sequence":null,"source":"clob_market_ws"}
{"event_at":"2026-07-27T04:32:37.544000Z","event_fingerprint":"534ae9b25d147dfe778b4c813bf2924c1afd1f4d8c39f675e5a71c3558e68bf4","payload":{"connection_id":"0f4979d6978d463e9660b042fdcf555f","event_at":"2026-07-27T04:32:37.544000Z","event_type":"price_change","frame_hash":"e69dfabaaa67e8fd6edb3307965aaf9c07ff1f65a8e14810c72cd39e8a5c5626","frame_index":0,"kind":"data","monotonic_ns":228740997862375,"payload":{"event_type":"price_change","market":"0xeb66215f2e9faa6449e30a02bab5b8ed7b79a38bf961f6b24d0073c9c2419250","price_changes":[{"asset_id":"60386828328910021732068595344565885737045900010034836345809386672230885527307","best_ask":"0.82","best_bid":"0.81","hash":"8c205b8f407b8fb46758834784e076261a514ca0","price":"0.75","side":"BUY","size":"60"},{"asset_id":"69697746896130839564035629862476347944307040470122503199396727085502753297492","best_ask":"0.19","best_bid":"0.18","hash":"ade60e52b783d63023272974ad32f9aef770623e","price":"0.25","side":"SELL","size":"60"}],"timestamp":"1785126757544"},"payload_hash":"7527d1ec0836ffa241bc5cc01952496f2f1af701d80bc7a993a85d998060038c","raw_frame":"{\"market\":\"0xeb66215f2e9faa6449e30a02bab5b8ed7b79a38bf961f6b24d0073c9c2419250\", \"price_changes\":[{\"asset_id\":\"60386828328910021732068595344565885737045900010034836345809386672230885527307\", \"price\":\"0.75\", \"size\":\"60\", \"side\":\"BUY\", \"hash\":\"8c205b8f407b8fb46758834784e076261a514ca0\", \"best_bid\":\"0.81\", \"best_ask\":\"0.82\"}, {\"asset_id\":\"69697746896130839564035629862476347944307040470122503199396727085502753297492\", \"price\":\"0.25\", \"size\":\"60\", \"side\":\"SELL\", \"hash\":\"ade60e52b783d63023272974ad32f9aef770623e\", \"best_bid\":\"0.18\", \"best_ask\":\"0.19\"}], \"timestamp\":\"1785126757544\", \"event_type\":\"price_change\"}","received_at":"2026-07-27T04:32:37.729394Z","schema_version":"clob-market-ws.price_change.v1","sequence":null,"server_hash":null,"server_timestamp":"1785126757544","session_id":"e9443c7415a0419799bee9cfbb1a9e4d","source":"clob_market_ws"},"received_at":"2026-07-27T04:32:37.729394Z","record_id":"c9ce662b0cdcca8b2a44cc971bb0caa1656f13a24e5abbcd873e2905450ed2fb","schema_fingerprint":"4aa3821a28b0b7c2400bc59aba4bcc0a76e971dadd19610d3ad38c768e124dc7","schema_version":"edge-lab-recorder.raw.v1","sequence":null,"source":"clob_market_ws"}
{"event_at":"2026-07-27T04:32:37.545000Z","event_fingerprint":"9319bbb27144406c2cad0060ad02bc4713b98b71a69a02a4ceb82ba0ec19d008","payload":{"connection_id":"0f4979d6978d463e9660b042fdcf555f","event_at":"2026-07-27T04:32:37.545000Z","event_type":"price_change","frame_hash":"56a49175de25c4599de506817ef3549711259fb34748e410c5125d715e84962d","frame_index":0,"kind":"data","monotonic_ns":228741000764208,"payload":{"event_type":"price_change","market":"0xeb66215f2e9faa6449e30a02bab5b8ed7b79a38bf961f6b24d0073c9c2419250","price_changes":[{"asset_id":"69697746896130839564035629862476347944307040470122503199396727085502753297492","best_ask":"0.19","best_bid":"0.18","hash":"882d383e82f6da8ba04308b1ecd914320b226cb8","price":"0.22","side":"SELL","size":"56.65"},{"asset_id":"60386828328910021732068595344565885737045900010034836345809386672230885527307","best_ask":"0.82","best_bid":"0.81","hash":"3aa4f2b0596850cf17c45820daaf4ae55bec1009","price":"0.78","side":"BUY","size":"56.65"}],"timestamp":"1785126757545"},"payload_hash":"16ef2f592234d3041139e6e971574af0a84ef5d477e59d07d531331db2ace0eb","raw_frame":"{\"market\":\"0xeb66215f2e9faa6449e30a02bab5b8ed7b79a38bf961f6b24d0073c9c2419250\", \"price_changes\":[{\"asset_id\":\"69697746896130839564035629862476347944307040470122503199396727085502753297492\", \"price\":\"0.22\", \"size\":\"56.65\", \"side\":\"SELL\", \"hash\":\"882d383e82f6da8ba04308b1ecd914320b226cb8\", \"best_bid\":\"0.18\", \"best_ask\":\"0.19\"}, {\"asset_id\":\"60386828328910021732068595344565885737045900010034836345809386672230885527307\", \"price\":\"0.78\", \"size\":\"56.65\", \"side\":\"BUY\", \"hash\":\"3aa4f2b0596850cf17c45820daaf4ae55bec1009\", \"best_bid\":\"0.81\", \"best_ask\":\"0.82\"}], \"timestamp\":\"1785126757545\", \"event_type\":\"price_change\"}","received_at":"2026-07-27T04:32:37.732296Z","schema_version":"clob-market-ws.price_change.v1","sequence":null,"server_hash":null,"server_timestamp":"1785126757545","session_id":"e9443c7415a0419799bee9cfbb1a9e4d","source":"clob_market_ws"},"received_at":"2026-07-27T04:32:37.732296Z","record_id":"46e5dacd22473083b231a64cc4f289b2f490a4f3709dd3dbdea18372fe8079e4","schema_fingerprint":"4aa3821a28b0b7c2400bc59aba4bcc0a76e971dadd19610d3ad38c768e124dc7","schema_version":"edge-lab-recorder.raw.v1","sequence":null,"source":"clob_market_ws"}
{"event_at":"2026-07-27T04:32:37.546000Z","event_fingerprint":"22bcd2fee08d2ec42405be4690b580157c4009165c8895fd0fba06aee50055fe","payload":{"connection_id":"0f4979d6978d463e9660b042fdcf555f","event_at":"2026-07-27T04:32:37.546000Z","event_type":"price_change","frame_hash":"8e09d7bb1908444711cbd2548f82e8d5b17ad7464d869bc429befea3e73038b3","frame_index":0,"kind":"data","monotonic_ns":228741004015333,"payload":{"event_type":"price_change","market":"0xeb66215f2e9faa6449e30a02bab5b8ed7b79a38bf961f6b24d0073c9c2419250","price_changes":[{"asset_id":"69697746896130839564035629862476347944307040470122503199396727085502753297492","best_ask":"0.19","best_bid":"0.18","hash":"fdd3c3c44d5a6abbf6e09a119d1a45e33329102b","price":"0.09","side":"BUY","size":"737.6"},{"asset_id":"60386828328910021732068595344565885737045900010034836345809386672230885527307","best_ask":"0.82","best_bid":"0.81","hash":"fb06740a9ed12f455f99e627c6f0be2f1a294c54","price":"0.91","side":"SELL","size":"737.6"}],"timestamp":"1785126757546"},"payload_hash":"28cbebe1651752194f4f17cad11d0e8a5f4d7ee2aa2eb59c638ad77b6900ed5b","raw_frame":"{\"market\":\"0xeb66215f2e9faa6449e30a02bab5b8ed7b79a38bf961f6b24d0073c9c2419250\", \"price_changes\":[{\"asset_id\":\"69697746896130839564035629862476347944307040470122503199396727085502753297492\", \"price\":\"0.09\", \"size\":\"737.6\", \"side\":\"BUY\", \"hash\":\"fdd3c3c44d5a6abbf6e09a119d1a45e33329102b\", \"best_bid\":\"0.18\", \"best_ask\":\"0.19\"}, {\"asset_id\":\"60386828328910021732068595344565885737045900010034836345809386672230885527307\", \"price\":\"0.91\", \"size\":\"737.6\", \"side\":\"SELL\", \"hash\":\"fb06740a9ed12f455f99e627c6f0be2f1a294c54\", \"best_bid\":\"0.81\", \"best_ask\":\"0.82\"}], \"timestamp\":\"1785126757546\", \"event_type\":\"price_change\"}","received_at":"2026-07-27T04:32:37.735541Z","schema_version":"clob-market-ws.price_change.v1","sequence":null,"server_hash":null,"server_timestamp":"1785126757546","session_id":"e9443c7415a0419799bee9cfbb1a9e4d","source":"clob_market_ws"},"received_at":"2026-07-27T04:32:37.735541Z","record_id":"1e1c8c22e5012b4f7de63efbd837a3f2ea1a2261a90d1c287abe74c2d78f1632","schema_fingerprint":"4aa3821a28b0b7c2400bc59aba4bcc0a76e971dadd19610d3ad38c768e124dc7","schema_version":"edge-lab-recorder.raw.v1","sequence":null,"source":"clob_market_ws"}
{"event_at":"2026-07-27T04:32:37.548000Z","event_fingerprint":"421f3e0260cce9c332988b9c333212c148b90442e39fa6275a021ca7387fa565","payload":{"connection_id":"0f4979d6978d463e9660b042fdcf555f","event_at":"2026-07-27T04:32:37.548000Z","event_type":"price_change","frame_hash":"a1bb81ddc4a303880fc95c6629b770734b6471caf4f209b604271878f45d5888","frame_index":0,"kind":"data","monotonic_ns":228741007184750,"payload":{"event_type":"price_change","market":"0xeb66215f2e9faa6449e30a02bab5b8ed7b79a38bf961f6b24d0073c9c2419250","price_changes":[{"asset_id":"69697746896130839564035629862476347944307040470122503199396727085502753297492","best_ask":"0.19","best_bid":"0.18","hash":"f89e23e63b5045a1ce1f038352bae4d975538583","price":"0.08","side":"BUY","size":"720.79"},{"asset_id":"60386828328910021732068595344565885737045900010034836345809386672230885527307","best_ask":"0.82","best_bid":"0.81","hash":"bf6b8b041cbcfc857ede73f0fbf02251b8953ae7","price":"0.92","side":"SELL","size":"720.79"}],"timestamp":"1785126757548"},"payload_hash":"3e1512837279929630115ce1f414768b9c653aa8091f7334f0600c377a1b2bef","raw_frame":"{\"market\":\"0xeb66215f2e9faa6449e30a02bab5b8ed7b79a38bf961f6b24d0073c9c2419250\", \"price_changes\":[{\"asset_id\":\"69697746896130839564035629862476347944307040470122503199396727085502753297492\", \"price\":\"0.08\", \"size\":\"720.79\", \"side\":\"BUY\", \"hash\":\"f89e23e63b5045a1ce1f038352bae4d975538583\", \"best_bid\":\"0.18\", \"best_ask\":\"0.19\"}, {\"asset_id\":\"60386828328910021732068595344565885737045900010034836345809386672230885527307\", \"price\":\"0.92\", \"size\":\"720.79\", \"side\":\"SELL\", \"hash\":\"bf6b8b041cbcfc857ede73f0fbf02251b8953ae7\", \"best_bid\":\"0.81\", \"best_ask\":\"0.82\"}], \"timestamp\":\"1785126757548\", \"event_type\":\"price_change\"}","received_at":"2026-07-27T04:32:37.738715Z","schema_version":"clob-market-ws.price_change.v1","sequence":null,"server_hash":null,"server_timestamp":"1785126757548","session_id":"e9443c7415a0419799bee9cfbb1a9e4d","source":"clob_market_ws"},"received_at":"2026-07-27T04:32:37.738715Z","record_id":"db044b15b1ce219495c8b68a95d1d7d4bc32c9f6be98eaf99a611f8788b95466","schema_fingerprint":"4aa3821a28b0b7c2400bc59aba4bcc0a76e971dadd19610d3ad38c768e124dc7","schema_version":"edge-lab-recorder.raw.v1","sequence":null,"source":"clob_market_ws"}
{"event_at":"2026-07-27T04:32:37.550000Z","event_fingerprint":"603c1af7b135a604627fec99c8645d7901395b83cd6e3432b5bad61dd6a01391","payload":{"connection_id":"0f4979d6978d463e9660b042fdcf555f","event_at":"2026-07-27T04:32:37.550000Z","event_type":"price_change","frame_hash":"acdd8f8a23b00032d5b90116c8e40db1c8cedcf38a56a28e1f9b7ff4e8caa062","frame_index":0,"kind":"data","monotonic_ns":228741010135208,"payload":{"event_type":"price_change","market":"0xeb66215f2e9faa6449e30a02bab5b8ed7b79a38bf961f6b24d0073c9c2419250","price_changes":[{"asset_id":"69697746896130839564035629862476347944307040470122503199396727085502753297492","best_ask":"0.19","best_bid":"0.18","hash":"50b6e8bc0dc2917c259030c10b004733f1c48d11","price":"0.17","side":"BUY","size":"433.4"},{"asset_id":"60386828328910021732068595344565885737045900010034836345809386672230885527307","best_ask":"0.82","best_bid":"0.81","hash":"f8aa5f1b64dc7a2afab901643d8fc7a7983ad4fc","price":"0.83","side":"SELL","size":"433.4"}],"timestamp":"1785126757550"},"payload_hash":"d7a0c2f817cb30cdf3be2a789f4996c0411bafa769e8e52cf6be60c1b056d004","raw_frame":"{\"market\":\"0xeb66215f2e9faa6449e30a02bab5b8ed7b79a38bf961f6b24d0073c9c2419250\", \"price_changes\":[{\"asset_id\":\"69697746896130839564035629862476347944307040470122503199396727085502753297492\", \"price\":\"0.17\", \"size\":\"433.4\", \"side\":\"BUY\", \"hash\":\"50b6e8bc0dc2917c259030c10b004733f1c48d11\", \"best_bid\":\"0.18\", \"best_ask\":\"0.19\"}, {\"asset_id\":\"60386828328910021732068595344565885737045900010034836345809386672230885527307\", \"price\":\"0.83\", \"size\":\"433.4\", \"side\":\"SELL\", \"hash\":\"f8aa5f1b64dc7a2afab901643d8fc7a7983ad4fc\", \"best_bid\":\"0.81\", \"best_ask\":\"0.82\"}], \"timestamp\":\"1785126757550\", \"event_type\":\"price_change\"}","received_at":"2026-07-27T04:32:37.741665Z","schema_version":"clob-market-ws.price_change.v1","sequence":null,"server_hash":null,"server_timestamp":"1785126757550","session_id":"e9443c7415a0419799bee9cfbb1a9e4d","source":"clob_market_ws"},"received_at":"2026-07-27T04:32:37.741665Z","record_id":"15edac01d29d66f5088ebde872fe457a543cdc54d1b3360268336bc0cbacc085","schema_fingerprint":"4aa3821a28b0b7c2400bc59aba4bcc0a76e971dadd19610d3ad38c768e124dc7","schema_version":"edge-lab-recorder.raw.v1","sequence":null,"source":"clob_market_ws"}
{"event_at":"2026-07-27T04:32:37.554000Z","event_fingerprint":"6dcb28d584a39b6d72325e3a7d61b402c37c09214bd4ecea25c246d5b5d8b5dd","payload":{"connection_id":"0f4979d6978d463e9660b042fdcf555f","event_at":"2026-07-27T04:32:37.554000Z","event_type":"price_change","frame_hash":"ee0b32b6b591db9d3b99fbc9fc9a5e4e2deb242def3f77043d7b0fc4a24c9e82","frame_index":0,"kind":"data","monotonic_ns":228741014322500,"payload":{"event_type":"price_change","market":"0xeb66215f2e9faa6449e30a02bab5b8ed7b79a38bf961f6b24d0073c9c2419250","price_changes":[{"asset_id":"69697746896130839564035629862476347944307040470122503199396727085502753297492","best_ask":"0.19","best_bid":"0.18","hash":"5b317e9d04251d28a8bd8fccc4b956a090853fd5","price":"0.06","side":"BUY","size":"745.2"},{"asset_id":"60386828328910021732068595344565885737045900010034836345809386672230885527307","best_ask":"0.82","best_bid":"0.81","hash":"19345af458fd6df7e652d0f52443dde11b9c9aca","price":"0.94","side":"SELL","size":"745.2"}],"timestamp":"1785126757554"},"payload_hash":"524e09e512b8805333cbc11c7fbb75b9224e9f1c552384cd784b1a2c584f4525","raw_frame":"{\"market\":\"0xeb66215f2e9faa6449e30a02bab5b8ed7b79a38bf961f6b24d0073c9c2419250\", \"price_changes\":[{\"asset_id\":\"69697746896130839564035629862476347944307040470122503199396727085502753297492\", \"price\":\"0.06\", \"size\":\"745.2\", \"side\":\"BUY\", \"hash\":\"5b317e9d04251d28a8bd8fccc4b956a090853fd5\", \"best_bid\":\"0.18\", \"best_ask\":\"0.19\"}, {\"asset_id\":\"60386828328910021732068595344565885737045900010034836345809386672230885527307\", \"price\":\"0.94\", \"size\":\"745.2\", \"side\":\"SELL\", \"hash\":\"19345af458fd6df7e652d0f52443dde11b9c9aca\", \"best_bid\":\"0.81\", \"best_ask\":\"0.82\"}], \"timestamp\":\"1785126757554\", \"event_type\":\"price_change\"}","received_at":"2026-07-27T04:32:37.745853Z","schema_version":"clob-market-ws.price_change.v1","sequence":null,"server_hash":null,"server_timestamp":"1785126757554","session_id":"e9443c7415a0419799bee9cfbb1a9e4d","source":"clob_market_ws"},"received_at":"2026-07-27T04:32:37.745853Z","record_id":"37a54c269fa6bcb830df352a1d08b10d014aa9c1e6e9d52b89d82a58db072fea","schema_fingerprint":"4aa3821a28b0b7c2400bc59aba4bcc0a76e971dadd19610d3ad38c768e124dc7","schema_version":"edge-lab-recorder.raw.v1","sequence":null,"source":"clob_market_ws"}
{"event_at":"2026-07-27T04:32:37.554000Z","event_fingerprint":"fc9bacd757d4a468237fbf3b234ed0b1f93a6c8da12aa1c3ed74d394d5bd87fe","payload":{"connection_id":"0f4979d6978d463e9660b042fdcf555f","event_at":"2026-07-27T04:32:37.554000Z","event_type":"price_change","frame_hash":"887c18ef78deae1ab598c1e375da07725e14ffc33e49ce7b235b2d2e6de9e849","frame_index":0,"kind":"data","monotonic_ns":228741017266125,"payload":{"event_type":"price_change","market":"0xeb66215f2e9faa6449e30a02bab5b8ed7b79a38bf961f6b24d0073c9c2419250","price_changes":[{"asset_id":"69697746896130839564035629862476347944307040470122503199396727085502753297492","best_ask":"0.19","best_bid":"0.18","hash":"3a5bd6077690cfab51fa42397ca373ada30258c9","price":"0.19","side":"SELL","size":"13.17"},{"asset_id":"60386828328910021732068595344565885737045900010034836345809386672230885527307","best_ask":"0.82","best_bid":"0.81","hash":"111bc968b2ac09c6ad4469212f152a211f9c9bff","price":"0.81","side":"BUY","size":"13.17"}],"timestamp":"1785126757554"},"payload_hash":"abf2220b44c9560bb5705bc5f83fbe2e23229e1ceb3f6ccad990d0e7e803f2ba","raw_frame":"{\"market\":\"0xeb66215f2e9faa6449e30a02bab5b8ed7b79a38bf961f6b24d0073c9c2419250\", \"price_changes\":[{\"asset_id\":\"69697746896130839564035629862476347944307040470122503199396727085502753297492\", \"price\":\"0.19\", \"size\":\"13.17\", \"side\":\"SELL\", \"hash\":\"3a5bd6077690cfab51fa42397ca373ada30258c9\", \"best_bid\":\"0.18\", \"best_ask\":\"0.19\"}, {\"asset_id\":\"60386828328910021732068595344565885737045900010034836345809386672230885527307\", \"price\":\"0.81\", \"size\":\"13.17\", \"side\":\"BUY\", \"hash\":\"111bc968b2ac09c6ad4469212f152a211f9c9bff\", \"best_bid\":\"0.81\", \"best_ask\":\"0.82\"}], \"timestamp\":\"1785126757554\", \"event_type\":\"price_change\"}","received_at":"2026-07-27T04:32:37.748798Z","schema_version":"clob-market-ws.price_change.v1","sequence":null,"server_hash":null,"server_timestamp":"1785126757554","session_id":"e9443c7415a0419799bee9cfbb1a9e4d","source":"clob_market_ws"},"received_at":"2026-07-27T04:32:37.748798Z","record_id":"97db66f6ce92fdc978af08a084872d4932bd388845d8359d9df98ddf9b609879","schema_fingerprint":"4aa3821a28b0b7c2400bc59aba4bcc0a76e971dadd19610d3ad38c768e124dc7","schema_version":"edge-lab-recorder.raw.v1","sequence":null,"source":"clob_market_ws"}
