{"event_at":"2026-07-28T04:12:06.221000Z","event_fingerprint":"9e44cf7a126b945461d1a10834b6abd0c16300034f1d1f8f789ebe6de6c209fe","payload":{"connection_id":"f6725804f86a4c4eb588e4d5ed7db029","event_at":"2026-07-28T04:12:06.221000Z","event_type":"price_change","frame_hash":"11f63e87a0894ad2501a86fa2db9ac7ad94eeea2754c9d00adda178faa3aecf8","frame_index":0,"kind":"data","monotonic_ns":313911265587166,"payload":{"event_type":"price_change","market":"0xd412ce774cfcf8dc9f71164aac78783978aac7b03871702a3b8a481bd9dc9688","price_changes":[{"asset_id":"107603864457683460275633293642179940881969192120168665300712204232021063124301","best_ask":"0.58","best_bid":"0.57","hash":"dc39d36941bea9119727ef7d5e9cce919a06e503","price":"0.64","side":"SELL","size":"107"},{"asset_id":"96600821790790307414914106093858868634329285205417149685270682748367152458577","best_ask":"0.43","best_bid":"0.42","hash":"9b6366ad4e43e48e6a4f877713f7b155ef5021e2","price":"0.36","side":"BUY","size":"107"}],"timestamp":"1785211926221"},"payload_hash":"1808d381163214e1418b8219b6f2d86ee19f4a691368d3f8621f4dccde008eb0","raw_frame":"{\"market\":\"0xd412ce774cfcf8dc9f71164aac78783978aac7b03871702a3b8a481bd9dc9688\", \"price_changes\":[{\"asset_id\":\"107603864457683460275633293642179940881969192120168665300712204232021063124301\", \"price\":\"0.64\", \"size\":\"107\", \"side\":\"SELL\", \"hash\":\"dc39d36941bea9119727ef7d5e9cce919a06e503\", \"best_bid\":\"0.57\", \"best_ask\":\"0.58\"}, {\"asset_id\":\"96600821790790307414914106093858868634329285205417149685270682748367152458577\", \"price\":\"0.36\", \"size\":\"107\", \"side\":\"BUY\", \"hash\":\"9b6366ad4e43e48e6a4f877713f7b155ef5021e2\", \"best_bid\":\"0.42\", \"best_ask\":\"0.43\"}], \"timestamp\":\"1785211926221\", \"event_type\":\"price_change\"}","received_at":"2026-07-28T04:12:08.188404Z","schema_version":"clob-market-ws.price_change.v1","sequence":null,"server_hash":null,"server_timestamp":"1785211926221","session_id":"2d607381e3054cee91998cdf45a4231c","source":"clob_market_ws"},"received_at":"2026-07-28T04:12:08.188404Z","record_id":"a06db68d16a304df7a2292a431a5660f5d1f5947931dfa4e8968496398643c85","schema_fingerprint":"4aa3821a28b0b7c2400bc59aba4bcc0a76e971dadd19610d3ad38c768e124dc7","schema_version":"edge-lab-recorder.raw.v1","sequence":null,"source":"clob_market_ws"}
{"event_at":"2026-07-28T04:12:06.223000Z","event_fingerprint":"5b025f7f3e6c3e28a8f1c0c4a5a22e950b8ae21829b99610f609e6be6405c97f","payload":{"connection_id":"f6725804f86a4c4eb588e4d5ed7db029","event_at":"2026-07-28T04:12:06.223000Z","event_type":"price_change","frame_hash":"07366f374190ef6a864cd8d45969b2a443398762c4449f1f88556c820e05acd9","frame_index":0,"kind":"data","monotonic_ns":313911275551875,"payload":{"event_type":"price_change","market":"0xd412ce774cfcf8dc9f71164aac78783978aac7b03871702a3b8a481bd9dc9688","price_changes":[{"asset_id":"107603864457683460275633293642179940881969192120168665300712204232021063124301","best_ask":"0.58","best_bid":"0.57","hash":"79844c42e26b7a9d4341a1d0d0c34c460e93de9c","price":"0.65","side":"SELL","size":"76"},{"asset_id":"96600821790790307414914106093858868634329285205417149685270682748367152458577","best_ask":"0.43","best_bid":"0.42","hash":"4860773b2d4cd8c9971c045266022c57edf64abb","price":"0.35","side":"BUY","size":"76"}],"timestamp":"1785211926223"},"payload_hash":"34306c6dc05e762815725b6136041a76369ccb3f0e919fa8af8318dcafacb811","raw_frame":"{\"market\":\"0xd412ce774cfcf8dc9f71164aac78783978aac7b03871702a3b8a481bd9dc9688\", \"price_changes\":[{\"asset_id\":\"107603864457683460275633293642179940881969192120168665300712204232021063124301\", \"price\":\"0.65\", \"size\":\"76\", \"side\":\"SELL\", \"hash\":\"79844c42e26b7a9d4341a1d0d0c34c460e93de9c\", \"best_bid\":\"0.57\", \"best_ask\":\"0.58\"}, {\"asset_id\":\"96600821790790307414914106093858868634329285205417149685270682748367152458577\", \"price\":\"0.35\", \"size\":\"76\", \"side\":\"BUY\", \"hash\":\"4860773b2d4cd8c9971c045266022c57edf64abb\", \"best_bid\":\"0.42\", \"best_ask\":\"0.43\"}], \"timestamp\":\"1785211926223\", \"event_type\":\"price_change\"}","received_at":"2026-07-28T04:12:08.198369Z","schema_version":"clob-market-ws.price_change.v1","sequence":null,"server_hash":null,"server_timestamp":"1785211926223","session_id":"2d607381e3054cee91998cdf45a4231c","source":"clob_market_ws"},"received_at":"2026-07-28T04:12:08.198369Z","record_id":"7b54497843db473040db5d1ef88f11086aea147af47748b616aea424406fef2e","schema_fingerprint":"4aa3821a28b0b7c2400bc59aba4bcc0a76e971dadd19610d3ad38c768e124dc7","schema_version":"edge-lab-recorder.raw.v1","sequence":null,"source":"clob_market_ws"}
{"event_at":"2026-07-28T04:12:06.225000Z","event_fingerprint":"37e2f951044f11615b0591c5f6da811d9dda68b666e6892f3ed22ca1770412b9","payload":{"connection_id":"f6725804f86a4c4eb588e4d5ed7db029","event_at":"2026-07-28T04:12:06.225000Z","event_type":"price_change","frame_hash":"ade3e66bc43e20b04687e29118e9aeb3c144c750597956ee17d952e745827460","frame_index":0,"kind":"data","monotonic_ns":313911279702291,"payload":{"event_type":"price_change","market":"0xd412ce774cfcf8dc9f71164aac78783978aac7b03871702a3b8a481bd9dc9688","price_changes":[{"asset_id":"96600821790790307414914106093858868634329285205417149685270682748367152458577","best_ask":"0.43","best_bid":"0.42","hash":"d1f33811dc4abb64ce4fff4346f401aed3741d22","price":"0.36","side":"BUY","size":"150"},{"asset_id":"107603864457683460275633293642179940881969192120168665300712204232021063124301","best_ask":"0.58","best_bid":"0.57","hash":"9e1132ba3220b67ea19303d5ec2ae63639b632f2","price":"0.64","side":"SELL","size":"150"}],"timestamp":"1785211926225"},"payload_hash":"c97fca763dbcdb93eca0b885cad193375d6699430d1aefe6cb1d73baff3af7ff","raw_frame":"{\"market\":\"0xd412ce774cfcf8dc9f71164aac78783978aac7b03871702a3b8a481bd9dc9688\", \"price_changes\":[{\"asset_id\":\"96600821790790307414914106093858868634329285205417149685270682748367152458577\", \"price\":\"0.36\", \"size\":\"150\", \"side\":\"BUY\", \"hash\":\"d1f33811dc4abb64ce4fff4346f401aed3741d22\", \"best_bid\":\"0.42\", \"best_ask\":\"0.43\"}, {\"asset_id\":\"107603864457683460275633293642179940881969192120168665300712204232021063124301\", \"price\":\"0.64\", \"size\":\"150\", \"side\":\"SELL\", \"hash\":\"9e1132ba3220b67ea19303d5ec2ae63639b632f2\", \"best_bid\":\"0.57\", \"best_ask\":\"0.58\"}], \"timestamp\":\"1785211926225\", \"event_type\":\"price_change\"}","received_at":"2026-07-28T04:12:08.202520Z","schema_version":"clob-market-ws.price_change.v1","sequence":null,"server_hash":null,"server_timestamp":"1785211926225","session_id":"2d607381e3054cee91998cdf45a4231c","source":"clob_market_ws"},"received_at":"2026-07-28T04:12:08.202520Z","record_id":"bfbae19330e0b24e58723272fdd6814a28291dc74cd6196e821dc2ba2fd0c4c2","schema_fingerprint":"4aa3821a28b0b7c2400bc59aba4bcc0a76e971dadd19610d3ad38c768e124dc7","schema_version":"edge-lab-recorder.raw.v1","sequence":null,"source":"clob_market_ws"}
{"event_at":"2026-07-28T04:12:06.245000Z","event_fingerprint":"011b5caee1efaee7b3420475de3a9349c2d3938fdac3e98869fbe84c6fe591ad","payload":{"connection_id":"f6725804f86a4c4eb588e4d5ed7db029","event_at":"2026-07-28T04:12:06.245000Z","event_type":"price_change","frame_hash":"46e02ff1243a62689eec136f2a0392a74238b71f32f38cfb07b3eb4c33fa1865","frame_index":0,"kind":"data","monotonic_ns":313911284044166,"payload":{"event_type":"price_change","market":"0xd412ce774cfcf8dc9f71164aac78783978aac7b03871702a3b8a481bd9dc9688","price_changes":[{"asset_id":"107603864457683460275633293642179940881969192120168665300712204232021063124301","best_ask":"0.58","best_bid":"0.57","hash":"6b2d877dd9e3e215ed35b4b703a7231865483cb8","price":"0.01","side":"BUY","size":"5330.02"},{"asset_id":"96600821790790307414914106093858868634329285205417149685270682748367152458577","best_ask":"0.43","best_bid":"0.42","hash":"fc4d5e1a14d1acf2491bdd5d643c45f7ddaf719f","price":"0.99","side":"SELL","size":"5330.02"}],"timestamp":"1785211926245"},"payload_hash":"ebd471d2fab0572f6e00ab82fc229c829fac1ce3218d3a499e57b8f8af912a37","raw_frame":"{\"market\":\"0xd412ce774cfcf8dc9f71164aac78783978aac7b03871702a3b8a481bd9dc9688\", \"price_changes\":[{\"asset_id\":\"107603864457683460275633293642179940881969192120168665300712204232021063124301\", \"price\":\"0.01\", \"size\":\"5330.02\", \"side\":\"BUY\", \"hash\":\"6b2d877dd9e3e215ed35b4b703a7231865483cb8\", \"best_bid\":\"0.57\", \"best_ask\":\"0.58\"}, {\"asset_id\":\"96600821790790307414914106093858868634329285205417149685270682748367152458577\", \"price\":\"0.99\", \"size\":\"5330.02\", \"side\":\"SELL\", \"hash\":\"fc4d5e1a14d1acf2491bdd5d643c45f7ddaf719f\", \"best_bid\":\"0.42\", \"best_ask\":\"0.43\"}], \"timestamp\":\"1785211926245\", \"event_type\":\"price_change\"}","received_at":"2026-07-28T04:12:08.206862Z","schema_version":"clob-market-ws.price_change.v1","sequence":null,"server_hash":null,"server_timestamp":"1785211926245","session_id":"2d607381e3054cee91998cdf45a4231c","source":"clob_market_ws"},"received_at":"2026-07-28T04:12:08.206862Z","record_id":"1dcca78b610657fa306171917ec599c2928f59e5086d856f640299c7fb3bd72b","schema_fingerprint":"4aa3821a28b0b7c2400bc59aba4bcc0a76e971dadd19610d3ad38c768e124dc7","schema_version":"edge-lab-recorder.raw.v1","sequence":null,"source":"clob_market_ws"}
{"event_at":"2026-07-28T04:12:06.261000Z","event_fingerprint":"4c83b400004117e5c24a30dd9121637b87ad8d5dbe7a8ceeb0a83dcb741231d6","payload":{"connection_id":"f6725804f86a4c4eb588e4d5ed7db029","event_at":"2026-07-28T04:12:06.261000Z","event_type":"price_change","frame_hash":"ec9446c62e014fc46e9cf4195c98b5cab0ec323eef5979bd52f1e275d3a86037","frame_index":0,"kind":"data","monotonic_ns":313911288559083,"payload":{"event_type":"price_change","market":"0xd412ce774cfcf8dc9f71164aac78783978aac7b03871702a3b8a481bd9dc9688","price_changes":[{"asset_id":"107603864457683460275633293642179940881969192120168665300712204232021063124301","best_ask":"0.58","best_bid":"0.57","hash":"296ed4ae5573ae59799f89619f8d3f53d33a7e08","price":"0.33","side":"BUY","size":"19.36"},{"asset_id":"96600821790790307414914106093858868634329285205417149685270682748367152458577","best_ask":"0.43","best_bid":"0.42","hash":"3d799560c3299dc0e584f85616bcadf0b4073a88","price":"0.67","side":"SELL","size":"19.36"}],"timestamp":"1785211926261"},"payload_hash":"bef1c4904488a15d041bd0128a41a2d1490fcf248913fd26032d61281e02fafe","raw_frame":"{\"market\":\"0xd412ce774cfcf8dc9f71164aac78783978aac7b03871702a3b8a481bd9dc9688\", \"price_changes\":[{\"asset_id\":\"107603864457683460275633293642179940881969192120168665300712204232021063124301\", \"price\":\"0.33\", \"size\":\"19.36\", \"side\":\"BUY\", \"hash\":\"296ed4ae5573ae59799f89619f8d3f53d33a7e08\", \"best_bid\":\"0.57\", \"best_ask\":\"0.58\"}, {\"asset_id\":\"96600821790790307414914106093858868634329285205417149685270682748367152458577\", \"price\":\"0.67\", \"size\":\"19.36\", \"side\":\"SELL\", \"hash\":\"3d799560c3299dc0e584f85616bcadf0b4073a88\", \"best_bid\":\"0.42\", \"best_ask\":\"0.43\"}], \"timestamp\":\"1785211926261\", \"event_type\":\"price_change\"}","received_at":"2026-07-28T04:12:08.211376Z","schema_version":"clob-market-ws.price_change.v1","sequence":null,"server_hash":null,"server_timestamp":"1785211926261","session_id":"2d607381e3054cee91998cdf45a4231c","source":"clob_market_ws"},"received_at":"2026-07-28T04:12:08.211376Z","record_id":"65d7e0262626753d22ed8a11a3b20c63ec7d2c1374c1e5caed131e3c99179c0b","schema_fingerprint":"4aa3821a28b0b7c2400bc59aba4bcc0a76e971dadd19610d3ad38c768e124dc7","schema_version":"edge-lab-recorder.raw.v1","sequence":null,"source":"clob_market_ws"}
{"event_at":"2026-07-28T04:12:06.296000Z","event_fingerprint":"d213e73fd198c7d684881f4adce36e4f984ae3105b619e3a1f7624f5b461f27c","payload":{"connection_id":"f6725804f86a4c4eb588e4d5ed7db029","event_at":"2026-07-28T04:12:06.296000Z","event_type":"price_change","frame_hash":"e0f23921b8bc36ce2b08595d89053d9f7c3d70e11af79ba306d86e43d5218f47","frame_index":0,"kind":"data","monotonic_ns":313911291918833,"payload":{"event_type":"price_change","market":"0xd412ce774cfcf8dc9f71164aac78783978aac7b03871702a3b8a481bd9dc9688","price_changes":[{"asset_id":"96600821790790307414914106093858868634329285205417149685270682748367152458577","best_ask":"0.43","best_bid":"0.42","hash":"ed408a8673fedaba0de682b44e940be716655da4","price":"0.4","side":"BUY","size":"59.2"},{"asset_id":"107603864457683460275633293642179940881969192120168665300712204232021063124301","best_ask":"0.58","best_bid":"0.57","hash":"52b94dafef076f555ac0f0ac4d77313bf3829451","price":"0.6","side":"SELL","size":"59.2"}],"timestamp":"1785211926296"},"payload_hash":"b8d17bade61df8aa402a1a43a647c96c437ca0e2ecaffebdc4aaa5d40615a4d2","raw_frame":"{\"market\":\"0xd412ce774cfcf8dc9f71164aac78783978aac7b03871702a3b8a481bd9dc9688\", \"price_changes\":[{\"asset_id\":\"96600821790790307414914106093858868634329285205417149685270682748367152458577\", \"price\":\"0.4\", \"size\":\"59.2\", \"side\":\"BUY\", \"hash\":\"ed408a8673fedaba0de682b44e940be716655da4\", \"best_bid\":\"0.42\", \"best_ask\":\"0.43\"}, {\"asset_id\":\"107603864457683460275633293642179940881969192120168665300712204232021063124301\", \"price\":\"0.6\", \"size\":\"59.2\", \"side\":\"SELL\", \"hash\":\"52b94dafef076f555ac0f0ac4d77313bf3829451\", \"best_bid\":\"0.57\", \"best_ask\":\"0.58\"}], \"timestamp\":\"1785211926296\", \"event_type\":\"price_change\"}","received_at":"2026-07-28T04:12:08.214736Z","schema_version":"clob-market-ws.price_change.v1","sequence":null,"server_hash":null,"server_timestamp":"1785211926296","session_id":"2d607381e3054cee91998cdf45a4231c","source":"clob_market_ws"},"received_at":"2026-07-28T04:12:08.214736Z","record_id":"3b0d7edd12dfb0c9c3ba551e94ca0edce89128c1de79a02c0213512e9cc9337a","schema_fingerprint":"4aa3821a28b0b7c2400bc59aba4bcc0a76e971dadd19610d3ad38c768e124dc7","schema_version":"edge-lab-recorder.raw.v1","sequence":null,"source":"clob_market_ws"}
{"event_at":"2026-07-28T04:12:06.297000Z","event_fingerprint":"b8387100e57acd6b6d567f0cd5364ccbac297001f1e9355bdf2f8436fa11ffae","payload":{"connection_id":"f6725804f86a4c4eb588e4d5ed7db029","event_at":"2026-07-28T04:12:06.297000Z","event_type":"price_change","frame_hash":"42e44e76e9be84672b203984d638b97cdfefc8ad1f9134cbbf2075e906fae0d8","frame_index":0,"kind":"data","monotonic_ns":313911296590458,"payload":{"event_type":"price_change","market":"0xd412ce774cfcf8dc9f71164aac78783978aac7b03871702a3b8a481bd9dc9688","price_changes":[{"asset_id":"107603864457683460275633293642179940881969192120168665300712204232021063124301","best_ask":"0.58","best_bid":"0.57","hash":"e57d0a289bf6509a09eefd63824f7217bf002e13","price":"0.38","side":"BUY","size":"30"},{"asset_id":"96600821790790307414914106093858868634329285205417149685270682748367152458577","best_ask":"0.43","best_bid":"0.42","hash":"c17becd59674664ceb189ab4592d0099eb4319bd","price":"0.62","side":"SELL","size":"30"}],"timestamp":"1785211926297"},"payload_hash":"84fa2249a71499c6568f0e521041c0d3b5d26576404844abc0870cbd6bff72b0","raw_frame":"{\"market\":\"0xd412ce774cfcf8dc9f71164aac78783978aac7b03871702a3b8a481bd9dc9688\", \"price_changes\":[{\"asset_id\":\"107603864457683460275633293642179940881969192120168665300712204232021063124301\", \"price\":\"0.38\", \"size\":\"30\", \"side\":\"BUY\", \"hash\":\"e57d0a289bf6509a09eefd63824f7217bf002e13\", \"best_bid\":\"0.57\", \"best_ask\":\"0.58\"}, {\"asset_id\":\"96600821790790307414914106093858868634329285205417149685270682748367152458577\", \"price\":\"0.62\", \"size\":\"30\", \"side\":\"SELL\", \"hash\":\"c17becd59674664ceb189ab4592d0099eb4319bd\", \"best_bid\":\"0.42\", \"best_ask\":\"0.43\"}], \"timestamp\":\"1785211926297\", \"event_type\":\"price_change\"}","received_at":"2026-07-28T04:12:08.219407Z","schema_version":"clob-market-ws.price_change.v1","sequence":null,"server_hash":null,"server_timestamp":"1785211926297","session_id":"2d607381e3054cee91998cdf45a4231c","source":"clob_market_ws"},"received_at":"2026-07-28T04:12:08.219407Z","record_id":"94714d0af4642f67d2718df98a87f43cbe7c62b0b14d6fece9eb568bc27f36ae","schema_fingerprint":"4aa3821a28b0b7c2400bc59aba4bcc0a76e971dadd19610d3ad38c768e124dc7","schema_version":"edge-lab-recorder.raw.v1","sequence":null,"source":"clob_market_ws"}
{"event_at":"2026-07-28T04:12:06.304000Z","event_fingerprint":"534f115b7dc61a864e36ba6d7c6af426dbf419141b2ced6a7022fbe07fe91972","payload":{"connection_id":"f6725804f86a4c4eb588e4d5ed7db029","event_at":"2026-07-28T04:12:06.304000Z","event_type":"price_change","frame_hash":"66a243c38a6ab5efaeda99dee16ab92d99740d91f462c412134cee5663d3b7f6","frame_index":0,"kind":"data","monotonic_ns":313911300977416,"payload":{"event_type":"price_change","market":"0xd412ce774cfcf8dc9f71164aac78783978aac7b03871702a3b8a481bd9dc9688","price_changes":[{"asset_id":"96600821790790307414914106093858868634329285205417149685270682748367152458577","best_ask":"0.43","best_bid":"0.42","hash":"cc6c38d054bdaff04b76f022e6540be8f55448f1","price":"0.31","side":"BUY","size":"80"},{"asset_id":"107603864457683460275633293642179940881969192120168665300712204232021063124301","best_ask":"0.58","best_bid":"0.57","hash":"70c2ce447a64568ffc35ad3d93550620a4994e9f","price":"0.69","side":"SELL","size":"80"}],"timestamp":"1785211926304"},"payload_hash":"6dd8e3b369466be581a12b78319efc54c6022a2b88f6d60fcce366d58c6304ce","raw_frame":"{\"market\":\"0xd412ce774cfcf8dc9f71164aac78783978aac7b03871702a3b8a481bd9dc9688\", \"price_changes\":[{\"asset_id\":\"96600821790790307414914106093858868634329285205417149685270682748367152458577\", \"price\":\"0.31\", \"size\":\"80\", \"side\":\"BUY\", \"hash\":\"cc6c38d054bdaff04b76f022e6540be8f55448f1\", \"best_bid\":\"0.42\", \"best_ask\":\"0.43\"}, {\"asset_id\":\"107603864457683460275633293642179940881969192120168665300712204232021063124301\", \"price\":\"0.69\", \"size\":\"80\", \"side\":\"SELL\", \"hash\":\"70c2ce447a64568ffc35ad3d93550620a4994e9f\", \"best_bid\":\"0.57\", \"best_ask\":\"0.58\"}], \"timestamp\":\"1785211926304\", \"event_type\":\"price_change\"}","received_at":"2026-07-28T04:12:08.223792Z","schema_version":"clob-market-ws.price_change.v1","sequence":null,"server_hash":null,"server_timestamp":"1785211926304","session_id":"2d607381e3054cee91998cdf45a4231c","source":"clob_market_ws"},"received_at":"2026-07-28T04:12:08.223792Z","record_id":"61033521d0d44ec398724df26b4ba8e65a208d7f7010418c6f928d943a5908ef","schema_fingerprint":"4aa3821a28b0b7c2400bc59aba4bcc0a76e971dadd19610d3ad38c768e124dc7","schema_version":"edge-lab-recorder.raw.v1","sequence":null,"source":"clob_market_ws"}
{"event_at":"2026-07-28T04:12:06.317000Z","event_fingerprint":"3197f457e5fc8a0d720eef66bdba32625c36e39698022dcdd5c29f1f2209ad99","payload":{"connection_id":"f6725804f86a4c4eb588e4d5ed7db029","event_at":"2026-07-28T04:12:06.317000Z","event_type":"price_change","frame_hash":"51e9ff0ccf861aaec1afa6bd6dd1f50e0f88cb728b630804685396e5dcbec7c2","frame_index":0,"kind":"data","monotonic_ns":313911305394750,"payload":{"event_type":"price_change","market":"0xd412ce774cfcf8dc9f71164aac78783978aac7b03871702a3b8a481bd9dc9688","price_changes":[{"asset_id":"107603864457683460275633293642179940881969192120168665300712204232021063124301","best_ask":"0.58","best_bid":"0.57","hash":"84ec82c1d9853f9163ef557f02ebe0fa497ed7b2","price":"0.01","side":"BUY","size":"5335.02"},{"asset_id":"96600821790790307414914106093858868634329285205417149685270682748367152458577","best_ask":"0.43","best_bid":"0.42","hash":"959f8b98537581277ba8987e35078f0494cd88ca","price":"0.99","side":"SELL","size":"5335.02"}],"timestamp":"1785211926317"},"payload_hash":"24fbed3d261d0228b956ac505341456b0f82ddde9b13f1d21fb1cc61b26d2be6","raw_frame":"{\"market\":\"0xd412ce774cfcf8dc9f71164aac78783978aac7b03871702a3b8a481bd9dc9688\", \"price_changes\":[{\"asset_id\":\"107603864457683460275633293642179940881969192120168665300712204232021063124301\", \"price\":\"0.01\", \"size\":\"5335.02\", \"side\":\"BUY\", \"hash\":\"84ec82c1d9853f9163ef557f02ebe0fa497ed7b2\", \"best_bid\":\"0.57\", \"best_ask\":\"0.58\"}, {\"asset_id\":\"96600821790790307414914106093858868634329285205417149685270682748367152458577\", \"price\":\"0.99\", \"size\":\"5335.02\", \"side\":\"SELL\", \"hash\":\"959f8b98537581277ba8987e35078f0494cd88ca\", \"best_bid\":\"0.42\", \"best_ask\":\"0.43\"}], \"timestamp\":\"1785211926317\", \"event_type\":\"price_change\"}","received_at":"2026-07-28T04:12:08.228212Z","schema_version":"clob-market-ws.price_change.v1","sequence":null,"server_hash":null,"server_timestamp":"1785211926317","session_id":"2d607381e3054cee91998cdf45a4231c","source":"clob_market_ws"},"received_at":"2026-07-28T04:12:08.228212Z","record_id":"2d131d47175b08603a03387f6bd847c57b43c2872c3d3c478601dc5840ce001d","schema_fingerprint":"4aa3821a28b0b7c2400bc59aba4bcc0a76e971dadd19610d3ad38c768e124dc7","schema_version":"edge-lab-recorder.raw.v1","sequence":null,"source":"clob_market_ws"}
{"event_at":"2026-07-28T04:12:06.323000Z","event_fingerprint":"4690e65cdfe8f5eca66417b1340d4c6083f853b27fb801c63e017b9a7ea148a0","payload":{"connection_id":"f6725804f86a4c4eb588e4d5ed7db029","event_at":"2026-07-28T04:12:06.323000Z","event_type":"price_change","frame_hash":"a1b357620d4c5d1f49b84f85fce82e8e6e2c38cacb7aa903cb971f1586eb5372","frame_index":0,"kind":"data","monotonic_ns":313911309906500,"payload":{"event_type":"price_change","market":"0xd412ce774cfcf8dc9f71164aac78783978aac7b03871702a3b8a481bd9dc9688","price_changes":[{"asset_id":"107603864457683460275633293642179940881969192120168665300712204232021063124301","best_ask":"0.58","best_bid":"0.57","hash":"faf44fac3c81aaf7c6bd14e526f658b676ba220a","price":"0.01","side":"BUY","size":"5340.02"},{"asset_id":"96600821790790307414914106093858868634329285205417149685270682748367152458577","best_ask":"0.43","best_bid":"0.42","hash":"2e59a7496f00546d97201c9b60d67fc2a5116caa","price":"0.99","side":"SELL","size":"5340.02"}],"timestamp":"1785211926323"},"payload_hash":"6e4650d0fd789ab1b5fc19e3d3d5b3ce12788cf5bc5e6cc809192bfd76af2dc6","raw_frame":"{\"market\":\"0xd412ce774cfcf8dc9f71164aac78783978aac7b03871702a3b8a481bd9dc9688\", \"price_changes\":[{\"asset_id\":\"107603864457683460275633293642179940881969192120168665300712204232021063124301\", \"price\":\"0.01\", \"size\":\"5340.02\", \"side\":\"BUY\", \"hash\":\"faf44fac3c81aaf7c6bd14e526f658b676ba220a\", \"best_bid\":\"0.57\", \"best_ask\":\"0.58\"}, {\"asset_id\":\"96600821790790307414914106093858868634329285205417149685270682748367152458577\", \"price\":\"0.99\", \"size\":\"5340.02\", \"side\":\"SELL\", \"hash\":\"2e59a7496f00546d97201c9b60d67fc2a5116caa\", \"best_bid\":\"0.42\", \"best_ask\":\"0.43\"}], \"timestamp\":\"1785211926323\", \"event_type\":\"price_change\"}","received_at":"2026-07-28T04:12:08.232723Z","schema_version":"clob-market-ws.price_change.v1","sequence":null,"server_hash":null,"server_timestamp":"1785211926323","session_id":"2d607381e3054cee91998cdf45a4231c","source":"clob_market_ws"},"received_at":"2026-07-28T04:12:08.232723Z","record_id":"773a405e31f9bf3617dcca99e65952c776876574e486dcf3fc6ad01d9ec84ffb","schema_fingerprint":"4aa3821a28b0b7c2400bc59aba4bcc0a76e971dadd19610d3ad38c768e124dc7","schema_version":"edge-lab-recorder.raw.v1","sequence":null,"source":"clob_market_ws"}
{"event_at":"2026-07-28T04:12:06.326000Z","event_fingerprint":"debb3da1631fe6895787e3a5ad14787908781782f12ed361108f66629e9dce00","payload":{"connection_id":"f6725804f86a4c4eb588e4d5ed7db029","event_at":"2026-07-28T04:12:06.326000Z","event_type":"price_change","frame_hash":"63cf7bf5119a207ec76cc5780b54919e92d3e4e7b7d45bb9ec1c28d3392133d4","frame_index":0,"kind":"data","monotonic_ns":313911314263083,"payload":{"event_type":"price_change","market":"0xd412ce774cfcf8dc9f71164aac78783978aac7b03871702a3b8a481bd9dc9688","price_changes":[{"asset_id":"107603864457683460275633293642179940881969192120168665300712204232021063124301","best_ask":"0.58","best_bid":"0.57","hash":"0cbd4979fdc689659f341830a878ec7ca593d807","price":"0.01","side":"BUY","size":"5345.02"},{"asset_id":"96600821790790307414914106093858868634329285205417149685270682748367152458577","best_ask":"0.43","best_bid":"0.42","hash":"e918325dd6ee41c4ee50e22be8e26a4fdf1f7643","price":"0.99","side":"SELL","size":"5345.02"}],"timestamp":"1785211926326"},"payload_hash":"df5f2674a17143b021b36c1e7399eaee978135f5cd6de5eb147bafc07293f6f4","raw_frame":"{\"market\":\"0xd412ce774cfcf8dc9f71164aac78783978aac7b03871702a3b8a481bd9dc9688\", \"price_changes\":[{\"asset_id\":\"107603864457683460275633293642179940881969192120168665300712204232021063124301\", \"price\":\"0.01\", \"size\":\"5345.02\", \"side\":\"BUY\", \"hash\":\"0cbd4979fdc689659f341830a878ec7ca593d807\", \"best_bid\":\"0.57\", \"best_ask\":\"0.58\"}, {\"asset_id\":\"96600821790790307414914106093858868634329285205417149685270682748367152458577\", \"price\":\"0.99\", \"size\":\"5345.02\", \"side\":\"SELL\", \"hash\":\"e918325dd6ee41c4ee50e22be8e26a4fdf1f7643\", \"best_bid\":\"0.42\", \"best_ask\":\"0.43\"}], \"timestamp\":\"1785211926326\", \"event_type\":\"price_change\"}","received_at":"2026-07-28T04:12:08.237079Z","schema_version":"clob-market-ws.price_change.v1","sequence":null,"server_hash":null,"server_timestamp":"1785211926326","session_id":"2d607381e3054cee91998cdf45a4231c","source":"clob_market_ws"},"received_at":"2026-07-28T04:12:08.237079Z","record_id":"c3706b0cd2643b68fd4c8175b5d939bb3028f9c15cdfd965b68de796d2cecc8d","schema_fingerprint":"4aa3821a28b0b7c2400bc59aba4bcc0a76e971dadd19610d3ad38c768e124dc7","schema_version":"edge-lab-recorder.raw.v1","sequence":null,"source":"clob_market_ws"}
{"event_at":"2026-07-28T04:12:06.337000Z","event_fingerprint":"aa6a14fc737d4d3e0f184eac54f071347ecefd5cdd99c9ad6dd8398452698290","payload":{"connection_id":"f6725804f86a4c4eb588e4d5ed7db029","event_at":"2026-07-28T04:12:06.337000Z","event_type":"price_change","frame_hash":"dfdc1c53e240a6dfc179c4fa07de01c8dea56a459472dadd29e4f920ef4fea5d","frame_index":0,"kind":"data","monotonic_ns":313911318586500,"payload":{"event_type":"price_change","market":"0xd412ce774cfcf8dc9f71164aac78783978aac7b03871702a3b8a481bd9dc9688","price_changes":[{"asset_id":"107603864457683460275633293642179940881969192120168665300712204232021063124301","best_ask":"0.58","best_bid":"0.57","hash":"1d5d82b41e2d6c66e55d0c8e6ef295d47173e8cf","price":"0.01","side":"BUY","size":"5340.02"},{"asset_id":"96600821790790307414914106093858868634329285205417149685270682748367152458577","best_ask":"0.43","best_bid":"0.42","hash":"108a56f360343ae95fd17a1a209c4c686ad3e403","price":"0.99","side":"SELL","size":"5340.02"}],"timestamp":"1785211926337"},"payload_hash":"a10fa1653fdee9ce74e5bde54c4afc7ab02cdabdeb59c05cb6069cad4246b6e9","raw_frame":"{\"market\":\"0xd412ce774cfcf8dc9f71164aac78783978aac7b03871702a3b8a481bd9dc9688\", \"price_changes\":[{\"asset_id\":\"107603864457683460275633293642179940881969192120168665300712204232021063124301\", \"price\":\"0.01\", \"size\":\"5340.02\", \"side\":\"BUY\", \"hash\":\"1d5d82b41e2d6c66e55d0c8e6ef295d47173e8cf\", \"best_bid\":\"0.57\", \"best_ask\":\"0.58\"}, {\"asset_id\":\"96600821790790307414914106093858868634329285205417149685270682748367152458577\", \"price\":\"0.99\", \"size\":\"5340.02\", \"side\":\"SELL\", \"hash\":\"108a56f360343ae95fd17a1a209c4c686ad3e403\", \"best_bid\":\"0.42\", \"best_ask\":\"0.43\"}], \"timestamp\":\"1785211926337\", \"event_type\":\"price_change\"}","received_at":"2026-07-28T04:12:08.241403Z","schema_version":"clob-market-ws.price_change.v1","sequence":null,"server_hash":null,"server_timestamp":"1785211926337","session_id":"2d607381e3054cee91998cdf45a4231c","source":"clob_market_ws"},"received_at":"2026-07-28T04:12:08.241403Z","record_id":"bf24cc5e576c619a0c26917d6a91dbf85711bb66c0db37b9056c491a1f7afd88","schema_fingerprint":"4aa3821a28b0b7c2400bc59aba4bcc0a76e971dadd19610d3ad38c768e124dc7","schema_version":"edge-lab-recorder.raw.v1","sequence":null,"source":"clob_market_ws"}
{"event_at":"2026-07-28T04:12:06.341000Z","event_fingerprint":"127393ebabeeb093c703fbf4a5f68b261c87697f1a94bc2587af610e066745bf","payload":{"connection_id":"f6725804f86a4c4eb588e4d5ed7db029","event_at":"2026-07-28T04:12:06.341000Z","event_type":"price_change","frame_hash":"15e9d115b0272b5dc4a2a422d5d2881c829a2b2e42c51b2efd2d15c15576f9e4","frame_index":0,"kind":"data","monotonic_ns":313911322808500,"payload":{"event_type":"price_change","market":"0xd412ce774cfcf8dc9f71164aac78783978aac7b03871702a3b8a481bd9dc9688","price_changes":[{"asset_id":"96600821790790307414914106093858868634329285205417149685270682748367152458577","best_ask":"0.43","best_bid":"0.42","hash":"f74f1d1253773d954e5fa69572ecd04c73514e78","price":"0.3","side":"BUY","size":"103.19"},{"asset_id":"107603864457683460275633293642179940881969192120168665300712204232021063124301","best_ask":"0.58","best_bid":"0.57","hash":"8b3f5f5bdd5494e1851e214526ae73abc9a10d34","price":"0.7","side":"SELL","size":"103.19"}],"timestamp":"1785211926341"},"payload_hash":"fafc7a16a3627490b205d0480ad9d1d935f9fb96fc6dea99f8ac40919cf2508a","raw_frame":"{\"market\":\"0xd412ce774cfcf8dc9f71164aac78783978aac7b03871702a3b8a481bd9dc9688\", \"price_changes\":[{\"asset_id\":\"96600821790790307414914106093858868634329285205417149685270682748367152458577\", \"price\":\"0.3\", \"size\":\"103.19\", \"side\":\"BUY\", \"hash\":\"f74f1d1253773d954e5fa69572ecd04c73514e78\", \"best_bid\":\"0.42\", \"best_ask\":\"0.43\"}, {\"asset_id\":\"107603864457683460275633293642179940881969192120168665300712204232021063124301\", \"price\":\"0.7\", \"size\":\"103.19\", \"side\":\"SELL\", \"hash\":\"8b3f5f5bdd5494e1851e214526ae73abc9a10d34\", \"best_bid\":\"0.57\", \"best_ask\":\"0.58\"}], \"timestamp\":\"1785211926341\", \"event_type\":\"price_change\"}","received_at":"2026-07-28T04:12:08.245625Z","schema_version":"clob-market-ws.price_change.v1","sequence":null,"server_hash":null,"server_timestamp":"1785211926341","session_id":"2d607381e3054cee91998cdf45a4231c","source":"clob_market_ws"},"received_at":"2026-07-28T04:12:08.245625Z","record_id":"d6e61485f801225326641bb58661c5c6ca5057e3d8498b7baff251675704e30f","schema_fingerprint":"4aa3821a28b0b7c2400bc59aba4bcc0a76e971dadd19610d3ad38c768e124dc7","schema_version":"edge-lab-recorder.raw.v1","sequence":null,"source":"clob_market_ws"}
{"event_at":"2026-07-28T04:12:06.345000Z","event_fingerprint":"c6285268bea0fdbb2d2f11c0ad559e2b7cfd421d7b1a2136bdd5ac15acdac0ad","payload":{"connection_id":"f6725804f86a4c4eb588e4d5ed7db029","event_at":"2026-07-28T04:12:06.345000Z","event_type":"price_change","frame_hash":"bda4fb335735b2a596d5d7e088ceb5d1e17f32ce0a0e3d6ca1d2d653b9fae97f","frame_index":0,"kind":"data","monotonic_ns":313911327169583,"payload":{"event_type":"price_change","market":"0xd412ce774cfcf8dc9f71164aac78783978aac7b03871702a3b8a481bd9dc9688","price_changes":[{"asset_id":"107603864457683460275633293642179940881969192120168665300712204232021063124301","best_ask":"0.58","best_bid":"0.57","hash":"a8194e60b0ad7729f49b860cb54a9550b4412e04","price":"0.01","side":"BUY","size":"5335.02"},{"asset_id":"96600821790790307414914106093858868634329285205417149685270682748367152458577","best_ask":"0.43","best_bid":"0.42","hash":"93c8596f5ced98ff14b6ddec3ce2b1b64e33b80e","price":"0.99","side":"SELL","size":"5335.02"}],"timestamp":"1785211926345"},"payload_hash":"cda37bac333e5ec80bd64b43eaaacdcc6014c74ebae65cfb491f689f91c487b9","raw_frame":"{\"market\":\"0xd412ce774cfcf8dc9f71164aac78783978aac7b03871702a3b8a481bd9dc9688\", \"price_changes\":[{\"asset_id\":\"107603864457683460275633293642179940881969192120168665300712204232021063124301\", \"price\":\"0.01\", \"size\":\"5335.02\", \"side\":\"BUY\", \"hash\":\"a8194e60b0ad7729f49b860cb54a9550b4412e04\", \"best_bid\":\"0.57\", \"best_ask\":\"0.58\"}, {\"asset_id\":\"96600821790790307414914106093858868634329285205417149685270682748367152458577\", \"price\":\"0.99\", \"size\":\"5335.02\", \"side\":\"SELL\", \"hash\":\"93c8596f5ced98ff14b6ddec3ce2b1b64e33b80e\", \"best_bid\":\"0.42\", \"best_ask\":\"0.43\"}], \"timestamp\":\"1785211926345\", \"event_type\":\"price_change\"}","received_at":"2026-07-28T04:12:08.249986Z","schema_version":"clob-market-ws.price_change.v1","sequence":null,"server_hash":null,"server_timestamp":"1785211926345","session_id":"2d607381e3054cee91998cdf45a4231c","source":"clob_market_ws"},"received_at":"2026-07-28T04:12:08.249986Z","record_id":"c0662b2e3b728da48aec9bf1e604db41f3323e9761927f8842427469540a4918","schema_fingerprint":"4aa3821a28b0b7c2400bc59aba4bcc0a76e971dadd19610d3ad38c768e124dc7","schema_version":"edge-lab-recorder.raw.v1","sequence":null,"source":"clob_market_ws"}
{"event_at":"2026-07-28T04:12:06.347000Z","event_fingerprint":"2189dfbc51f43ca7476d982b5eacf4a2e0a3a45ba6ae4cec938f6b0c5382a19c","payload":{"connection_id":"f6725804f86a4c4eb588e4d5ed7db029","event_at":"2026-07-28T04:12:06.347000Z","event_type":"price_change","frame_hash":"62ee0285af639c607ea76629edb7ab2f9fe3a5e0a2638d432369583f20984ef7","frame_index":0,"kind":"data","monotonic_ns":313911332727250,"payload":{"event_type":"price_change","market":"0xd412ce774cfcf8dc9f71164aac78783978aac7b03871702a3b8a481bd9dc9688","price_changes":[{"asset_id":"96600821790790307414914106093858868634329285205417149685270682748367152458577","best_ask":"0.43","best_bid":"0.42","hash":"55e54ea5e46d2239bc218c3a38beaf8f0011b019","price":"0.36","side":"BUY","size":"107"},{"asset_id":"107603864457683460275633293642179940881969192120168665300712204232021063124301","best_ask":"0.58","best_bid":"0.57","hash":"8ac208ba7b3ea3bce0bacd1dac6b2a66ea1516ad","price":"0.64","side":"SELL","size":"107"}],"timestamp":"1785211926347"},"payload_hash":"f3cf6e9c19d7a8d749f17812f6ccf8b21c50a4661d3780f7832b8ff598306c65","raw_frame":"{\"market\":\"0xd412ce774cfcf8dc9f71164aac78783978aac7b03871702a3b8a481bd9dc9688\", \"price_changes\":[{\"asset_id\":\"96600821790790307414914106093858868634329285205417149685270682748367152458577\", \"price\":\"0.36\", \"size\":\"107\", \"side\":\"BUY\", \"hash\":\"55e54ea5e46d2239bc218c3a38beaf8f0011b019\", \"best_bid\":\"0.42\", \"best_ask\":\"0.43\"}, {\"asset_id\":\"107603864457683460275633293642179940881969192120168665300712204232021063124301\", \"price\":\"0.64\", \"size\":\"107\", \"side\":\"SELL\", \"hash\":\"8ac208ba7b3ea3bce0bacd1dac6b2a66ea1516ad\", \"best_bid\":\"0.57\", \"best_ask\":\"0.58\"}], \"timestamp\":\"1785211926347\", \"event_type\":\"price_change\"}","received_at":"2026-07-28T04:12:08.255544Z","schema_version":"clob-market-ws.price_change.v1","sequence":null,"server_hash":null,"server_timestamp":"1785211926347","session_id":"2d607381e3054cee91998cdf45a4231c","source":"clob_market_ws"},"received_at":"2026-07-28T04:12:08.255544Z","record_id":"0333c33c0f2ddf049b2d57049e830d9d744b6f70c0662dfa96056003f81fb11a","schema_fingerprint":"4aa3821a28b0b7c2400bc59aba4bcc0a76e971dadd19610d3ad38c768e124dc7","schema_version":"edge-lab-recorder.raw.v1","sequence":null,"source":"clob_market_ws"}
{"event_at":"2026-07-28T04:12:06.351000Z","event_fingerprint":"1c739cfd6ce9469445b8b9ed1f202bff723bdff3614d64e0005f6e866e7b0589","payload":{"connection_id":"f6725804f86a4c4eb588e4d5ed7db029","event_at":"2026-07-28T04:12:06.351000Z","event_type":"price_change","frame_hash":"f70034b078ab1b1782b222853033dba1d0acf007800aa7ae98b40a7f2be83f0c","frame_index":0,"kind":"data","monotonic_ns":313911338453583,"payload":{"event_type":"price_change","market":"0xd412ce774cfcf8dc9f71164aac78783978aac7b03871702a3b8a481bd9dc9688","price_changes":[{"asset_id":"107603864457683460275633293642179940881969192120168665300712204232021063124301","best_ask":"0.58","best_bid":"0.57","hash":"73106138d4ab4f5e5892d94f6dfb03ed2e7c4212","price":"0.64","side":"SELL","size":"151"},{"asset_id":"96600821790790307414914106093858868634329285205417149685270682748367152458577","best_ask":"0.43","best_bid":"0.42","hash":"15df674b4acaa90c1db39ac50bdf21b753281a5b","price":"0.36","side":"BUY","size":"151"}],"timestamp":"1785211926351"},"payload_hash":"f2086dcae578df4c95d37b5a3165869c46ac0dfb8c2bd9f0d3929fe0d96e92fe","raw_frame":"{\"market\":\"0xd412ce774cfcf8dc9f71164aac78783978aac7b03871702a3b8a481bd9dc9688\", \"price_changes\":[{\"asset_id\":\"107603864457683460275633293642179940881969192120168665300712204232021063124301\", \"price\":\"0.64\", \"size\":\"151\", \"side\":\"SELL\", \"hash\":\"73106138d4ab4f5e5892d94f6dfb03ed2e7c4212\", \"best_bid\":\"0.57\", \"best_ask\":\"0.58\"}, {\"asset_id\":\"96600821790790307414914106093858868634329285205417149685270682748367152458577\", \"price\":\"0.36\", \"size\":\"151\", \"side\":\"BUY\", \"hash\":\"15df674b4acaa90c1db39ac50bdf21b753281a5b\", \"best_bid\":\"0.42\", \"best_ask\":\"0.43\"}], \"timestamp\":\"1785211926351\", \"event_type\":\"price_change\"}","received_at":"2026-07-28T04:12:08.261270Z","schema_version":"clob-market-ws.price_change.v1","sequence":null,"server_hash":null,"server_timestamp":"1785211926351","session_id":"2d607381e3054cee91998cdf45a4231c","source":"clob_market_ws"},"received_at":"2026-07-28T04:12:08.261270Z","record_id":"cf5d09074b415ef7553f58cae86311750bfc04e869e26bccc1d5cadc529517e8","schema_fingerprint":"4aa3821a28b0b7c2400bc59aba4bcc0a76e971dadd19610d3ad38c768e124dc7","schema_version":"edge-lab-recorder.raw.v1","sequence":null,"source":"clob_market_ws"}
{"event_at":"2026-07-28T04:12:06.355000Z","event_fingerprint":"b4a76d2bb69cd34cfdf2738b4d2efda1e7b1882ef45a97f9410ab358b6b7828f","payload":{"connection_id":"f6725804f86a4c4eb588e4d5ed7db029","event_at":"2026-07-28T04:12:06.355000Z","event_type":"price_change","frame_hash":"ba758e61217968b2a6cc05bfe867cde4265c61c322ba13d86cd8e3f0a260c0d2","frame_index":0,"kind":"data","monotonic_ns":313911342412666,"payload":{"event_type":"price_change","market":"0xd412ce774cfcf8dc9f71164aac78783978aac7b03871702a3b8a481bd9dc9688","price_changes":[{"asset_id":"107603864457683460275633293642179940881969192120168665300712204232021063124301","best_ask":"0.58","best_bid":"0.57","hash":"46c5f19bbd883355bddca033b6806669b8eb5d51","price":"0.65","side":"SELL","size":"85.97"},{"asset_id":"96600821790790307414914106093858868634329285205417149685270682748367152458577","best_ask":"0.43","best_bid":"0.42","hash":"f822bd90e51b86736d53193e7ae278863c4d55d1","price":"0.35","side":"BUY","size":"85.97"}],"timestamp":"1785211926355"},"payload_hash":"83ed8dba437156263932a592bde251f9f7a0663168dd49fcab62d70f96237534","raw_frame":"{\"market\":\"0xd412ce774cfcf8dc9f71164aac78783978aac7b03871702a3b8a481bd9dc9688\", \"price_changes\":[{\"asset_id\":\"107603864457683460275633293642179940881969192120168665300712204232021063124301\", \"price\":\"0.65\", \"size\":\"85.97\", \"side\":\"SELL\", \"hash\":\"46c5f19bbd883355bddca033b6806669b8eb5d51\", \"best_bid\":\"0.57\", \"best_ask\":\"0.58\"}, {\"asset_id\":\"96600821790790307414914106093858868634329285205417149685270682748367152458577\", \"price\":\"0.35\", \"size\":\"85.97\", \"side\":\"BUY\", \"hash\":\"f822bd90e51b86736d53193e7ae278863c4d55d1\", \"best_bid\":\"0.42\", \"best_ask\":\"0.43\"}], \"timestamp\":\"1785211926355\", \"event_type\":\"price_change\"}","received_at":"2026-07-28T04:12:08.265227Z","schema_version":"clob-market-ws.price_change.v1","sequence":null,"server_hash":null,"server_timestamp":"1785211926355","session_id":"2d607381e3054cee91998cdf45a4231c","source":"clob_market_ws"},"received_at":"2026-07-28T04:12:08.265227Z","record_id":"b17364c7e5d294b57326cbcaa37914768268b3b85e32e1955bdf4570a8ca59ec","schema_fingerprint":"4aa3821a28b0b7c2400bc59aba4bcc0a76e971dadd19610d3ad38c768e124dc7","schema_version":"edge-lab-recorder.raw.v1","sequence":null,"source":"clob_market_ws"}
{"event_at":"2026-07-28T04:12:06.362000Z","event_fingerprint":"76c1e477c0ef2aaa61d04b9e3c50c090f2cd3b07b314434138aa6f8163227fdf","payload":{"connection_id":"f6725804f86a4c4eb588e4d5ed7db029","event_at":"2026-07-28T04:12:06.362000Z","event_type":"price_change","frame_hash":"f1a28fb48fb13369f4721dc81c03865ddd282ffe75edadf0526e71fdbb4deadb","frame_index":0,"kind":"data","monotonic_ns":313911346580541,"payload":{"event_type":"price_change","market":"0xd412ce774cfcf8dc9f71164aac78783978aac7b03871702a3b8a481bd9dc9688","price_changes":[{"asset_id":"96600821790790307414914106093858868634329285205417149685270682748367152458577","best_ask":"0.43","best_bid":"0.42","hash":"2d0d4ba25ad7c341d66a6f20c7688747f88a8f3b","price":"0.39","side":"BUY","size":"46.6"},{"asset_id":"107603864457683460275633293642179940881969192120168665300712204232021063124301","best_ask":"0.58","best_bid":"0.57","hash":"b1d9679bda3f2e7957dc2e636ba713062fbe5202","price":"0.61","side":"SELL","size":"46.6"}],"timestamp":"1785211926362"},"payload_hash":"ca0f4bf95f651e7a3ccd1af2ef4c82feeb62938fb55c82ee2e47c9c5778e336e","raw_frame":"{\"market\":\"0xd412ce774cfcf8dc9f71164aac78783978aac7b03871702a3b8a481bd9dc9688\", \"price_changes\":[{\"asset_id\":\"96600821790790307414914106093858868634329285205417149685270682748367152458577\", \"price\":\"0.39\", \"size\":\"46.6\", \"side\":\"BUY\", \"hash\":\"2d0d4ba25ad7c341d66a6f20c7688747f88a8f3b\", \"best_bid\":\"0.42\", \"best_ask\":\"0.43\"}, {\"asset_id\":\"107603864457683460275633293642179940881969192120168665300712204232021063124301\", \"price\":\"0.61\", \"size\":\"46.6\", \"side\":\"SELL\", \"hash\":\"b1d9679bda3f2e7957dc2e636ba713062fbe5202\", \"best_bid\":\"0.57\", \"best_ask\":\"0.58\"}], \"timestamp\":\"1785211926362\", \"event_type\":\"price_change\"}","received_at":"2026-07-28T04:12:08.269397Z","schema_version":"clob-market-ws.price_change.v1","sequence":null,"server_hash":null,"server_timestamp":"1785211926362","session_id":"2d607381e3054cee91998cdf45a4231c","source":"clob_market_ws"},"received_at":"2026-07-28T04:12:08.269397Z","record_id":"dc48d7774f4996654131b9ba7b447d0deb437eb90622cbbb4a0c17546010d60d","schema_fingerprint":"4aa3821a28b0b7c2400bc59aba4bcc0a76e971dadd19610d3ad38c768e124dc7","schema_version":"edge-lab-recorder.raw.v1","sequence":null,"source":"clob_market_ws"}
{"event_at":"2026-07-28T04:12:06.362000Z","event_fingerprint":"356662a604dd000b51c85405014819ac26737cb54a8f1086d57c207bbc083047","payload":{"connection_id":"f6725804f86a4c4eb588e4d5ed7db029","event_at":"2026-07-28T04:12:06.362000Z","event_type":"price_change","frame_hash":"84789f4a3366a272e2e7c4da7275432aa10016bbfa967168b77c0bc3acf52e73","frame_index":0,"kind":"data","monotonic_ns":313911350811791,"payload":{"event_type":"price_change","market":"0xd412ce774cfcf8dc9f71164aac78783978aac7b03871702a3b8a481bd9dc9688","price_changes":[{"asset_id":"96600821790790307414914106093858868634329285205417149685270682748367152458577","best_ask":"0.43","best_bid":"0.42","hash":"a9e43a06279624e0ff2d8b47ffba96741c799df2","price":"0.35","side":"BUY","size":"90.97"},{"asset_id":"107603864457683460275633293642179940881969192120168665300712204232021063124301","best_ask":"0.58","best_bid":"0.57","hash":"f65c356de4e06aa9e8b76dc37ca0b5cafa5dcce9","price":"0.65","side":"SELL","size":"90.97"}],"timestamp":"1785211926362"},"payload_hash":"775ad5cc644cdcdd72610e5187e4860490dd89ed241f0f556c499e39c562325a","raw_frame":"{\"market\":\"0xd412ce774cfcf8dc9f71164aac78783978aac7b03871702a3b8a481bd9dc9688\", \"price_changes\":[{\"asset_id\":\"96600821790790307414914106093858868634329285205417149685270682748367152458577\", \"price\":\"0.35\", \"size\":\"90.97\", \"side\":\"BUY\", \"hash\":\"a9e43a06279624e0ff2d8b47ffba96741c799df2\", \"best_bid\":\"0.42\", \"best_ask\":\"0.43\"}, {\"asset_id\":\"107603864457683460275633293642179940881969192120168665300712204232021063124301\", \"price\":\"0.65\", \"size\":\"90.97\", \"side\":\"SELL\", \"hash\":\"f65c356de4e06aa9e8b76dc37ca0b5cafa5dcce9\", \"best_bid\":\"0.57\", \"best_ask\":\"0.58\"}], \"timestamp\":\"1785211926362\", \"event_type\":\"price_change\"}","received_at":"2026-07-28T04:12:08.273628Z","schema_version":"clob-market-ws.price_change.v1","sequence":null,"server_hash":null,"server_timestamp":"1785211926362","session_id":"2d607381e3054cee91998cdf45a4231c","source":"clob_market_ws"},"received_at":"2026-07-28T04:12:08.273628Z","record_id":"c56136dbf880c585be88fe1715460578f7487c480579c4adadcb510125edbcc6","schema_fingerprint":"4aa3821a28b0b7c2400bc59aba4bcc0a76e971dadd19610d3ad38c768e124dc7","schema_version":"edge-lab-recorder.raw.v1","sequence":null,"source":"clob_market_ws"}
{"event_at":"2026-07-28T04:12:06.384000Z","event_fingerprint":"085a157a4f5be8cc302fdcc8be3bdde6f8f6ae4e5602f53608ff73c947a80d38","payload":{"connection_id":"f6725804f86a4c4eb588e4d5ed7db029","event_at":"2026-07-28T04:12:06.384000Z","event_type":"price_change","frame_hash":"f2db8dc9f8f39f8a96894e448e2627ac773a8cf784a843fe1a0832a903f7e2d0","frame_index":0,"kind":"data","monotonic_ns":313911355024750,"payload":{"event_type":"price_change","market":"0xd412ce774cfcf8dc9f71164aac78783978aac7b03871702a3b8a481bd9dc9688","price_changes":[{"asset_id":"107603864457683460275633293642179940881969192120168665300712204232021063124301","best_ask":"0.58","best_bid":"0.57","hash":"8a092ae286d12081d8b69df58f9848084f863461","price":"0.01","side":"BUY","size":"5330.02"},{"asset_id":"96600821790790307414914106093858868634329285205417149685270682748367152458577","best_ask":"0.43","best_bid":"0.42","hash":"bc95e14c8399aece85e6b88cbfe0b80b8b32dc79","price":"0.99","side":"SELL","size":"5330.02"}],"timestamp":"1785211926384"},"payload_hash":"29614f54b208f78cbf32b6500aef269cf96d0c618141cd320990aab88da168cd","raw_frame":"{\"market\":\"0xd412ce774cfcf8dc9f71164aac78783978aac7b03871702a3b8a481bd9dc9688\", \"price_changes\":[{\"asset_id\":\"107603864457683460275633293642179940881969192120168665300712204232021063124301\", \"price\":\"0.01\", \"size\":\"5330.02\", \"side\":\"BUY\", \"hash\":\"8a092ae286d12081d8b69df58f9848084f863461\", \"best_bid\":\"0.57\", \"best_ask\":\"0.58\"}, {\"asset_id\":\"96600821790790307414914106093858868634329285205417149685270682748367152458577\", \"price\":\"0.99\", \"size\":\"5330.02\", \"side\":\"SELL\", \"hash\":\"bc95e14c8399aece85e6b88cbfe0b80b8b32dc79\", \"best_bid\":\"0.42\", \"best_ask\":\"0.43\"}], \"timestamp\":\"1785211926384\", \"event_type\":\"price_change\"}","received_at":"2026-07-28T04:12:08.277841Z","schema_version":"clob-market-ws.price_change.v1","sequence":null,"server_hash":null,"server_timestamp":"1785211926384","session_id":"2d607381e3054cee91998cdf45a4231c","source":"clob_market_ws"},"received_at":"2026-07-28T04:12:08.277841Z","record_id":"057f16e4a7b5fb6999e50b8addf37861ef15bab868da097d812107637e935380","schema_fingerprint":"4aa3821a28b0b7c2400bc59aba4bcc0a76e971dadd19610d3ad38c768e124dc7","schema_version":"edge-lab-recorder.raw.v1","sequence":null,"source":"clob_market_ws"}
{"event_at":"2026-07-28T04:12:06.402000Z","event_fingerprint":"83f8a6f46148787cb823d39f530f577331d0519bd097aab39f0c38569c4a23e5","payload":{"connection_id":"f6725804f86a4c4eb588e4d5ed7db029","event_at":"2026-07-28T04:12:06.402000Z","event_type":"price_change","frame_hash":"f8d4067eff9a99442325b0720502f8d2181ee7f82997d3f35f1cbbabab88dfc9","frame_index":0,"kind":"data","monotonic_ns":313911359408208,"payload":{"event_type":"price_change","market":"0xd412ce774cfcf8dc9f71164aac78783978aac7b03871702a3b8a481bd9dc9688","price_changes":[{"asset_id":"107603864457683460275633293642179940881969192120168665300712204232021063124301","best_ask":"0.58","best_bid":"0.57","hash":"e4816af14b06ab23eb15310af4a953bcb0e1063c","price":"0.38","side":"BUY","size":"15"},{"asset_id":"96600821790790307414914106093858868634329285205417149685270682748367152458577","best_ask":"0.43","best_bid":"0.42","hash":"7b3576bc83fe6cc3871ea5cb3f54a34bb1a1cc1c","price":"0.62","side":"SELL","size":"15"}],"timestamp":"1785211926402"},"payload_hash":"f515176588b3d608bf3bd0c3eef63106bfd203a6bf2dacc4acc0ea5cb17c7866","raw_frame":"{\"market\":\"0xd412ce774cfcf8dc9f71164aac78783978aac7b03871702a3b8a481bd9dc9688\", \"price_changes\":[{\"asset_id\":\"107603864457683460275633293642179940881969192120168665300712204232021063124301\", \"price\":\"0.38\", \"size\":\"15\", \"side\":\"BUY\", \"hash\":\"e4816af14b06ab23eb15310af4a953bcb0e1063c\", \"best_bid\":\"0.57\", \"best_ask\":\"0.58\"}, {\"asset_id\":\"96600821790790307414914106093858868634329285205417149685270682748367152458577\", \"price\":\"0.62\", \"size\":\"15\", \"side\":\"SELL\", \"hash\":\"7b3576bc83fe6cc3871ea5cb3f54a34bb1a1cc1c\", \"best_bid\":\"0.42\", \"best_ask\":\"0.43\"}], \"timestamp\":\"1785211926402\", \"event_type\":\"price_change\"}","received_at":"2026-07-28T04:12:08.282225Z","schema_version":"clob-market-ws.price_change.v1","sequence":null,"server_hash":null,"server_timestamp":"1785211926402","session_id":"2d607381e3054cee91998cdf45a4231c","source":"clob_market_ws"},"received_at":"2026-07-28T04:12:08.282225Z","record_id":"9167f13680d2ed1a0ca46d1a7fe042a10358b0385aa55dba5755a211ebc55ec8","schema_fingerprint":"4aa3821a28b0b7c2400bc59aba4bcc0a76e971dadd19610d3ad38c768e124dc7","schema_version":"edge-lab-recorder.raw.v1","sequence":null,"source":"clob_market_ws"}
{"event_at":"2026-07-28T04:12:06.434000Z","event_fingerprint":"5fa6cb36427554c91f2c46b035922f4faa4d0af1a4d2375f1572ce34e3891e97","payload":{"connection_id":"f6725804f86a4c4eb588e4d5ed7db029","event_at":"2026-07-28T04:12:06.434000Z","event_type":"price_change","frame_hash":"0aa949930c96b48140342662b0be9b64c11566c760aad3b708a7e6d20a5a590f","frame_index":0,"kind":"data","monotonic_ns":313911365057500,"payload":{"event_type":"price_change","market":"0xd412ce774cfcf8dc9f71164aac78783978aac7b03871702a3b8a481bd9dc9688","price_changes":[{"asset_id":"107603864457683460275633293642179940881969192120168665300712204232021063124301","best_ask":"0.58","best_bid":"0.57","hash":"5e95d12efbb1197a85b48916b6c8bedf2d2f7833","price":"0.33","side":"BUY","size":"34.36"},{"asset_id":"96600821790790307414914106093858868634329285205417149685270682748367152458577","best_ask":"0.43","best_bid":"0.42","hash":"b5838b832f1c52d7d28fc7867dbe0047758fabb1","price":"0.67","side":"SELL","size":"34.36"}],"timestamp":"1785211926434"},"payload_hash":"59c075620c9077106c1d4546dfe770b35b35c88beec77e6cfe75e7e18fc133c9","raw_frame":"{\"market\":\"0xd412ce774cfcf8dc9f71164aac78783978aac7b03871702a3b8a481bd9dc9688\", \"price_changes\":[{\"asset_id\":\"107603864457683460275633293642179940881969192120168665300712204232021063124301\", \"price\":\"0.33\", \"size\":\"34.36\", \"side\":\"BUY\", \"hash\":\"5e95d12efbb1197a85b48916b6c8bedf2d2f7833\", \"best_bid\":\"0.57\", \"best_ask\":\"0.58\"}, {\"asset_id\":\"96600821790790307414914106093858868634329285205417149685270682748367152458577\", \"price\":\"0.67\", \"size\":\"34.36\", \"side\":\"SELL\", \"hash\":\"b5838b832f1c52d7d28fc7867dbe0047758fabb1\", \"best_bid\":\"0.42\", \"best_ask\":\"0.43\"}], \"timestamp\":\"1785211926434\", \"event_type\":\"price_change\"}","received_at":"2026-07-28T04:12:08.287873Z","schema_version":"clob-market-ws.price_change.v1","sequence":null,"server_hash":null,"server_timestamp":"1785211926434","session_id":"2d607381e3054cee91998cdf45a4231c","source":"clob_market_ws"},"received_at":"2026-07-28T04:12:08.287873Z","record_id":"5aedbc8a1c88938532bab3119f26decf2e646283e30270bfbc492c1b3d0d7af1","schema_fingerprint":"4aa3821a28b0b7c2400bc59aba4bcc0a76e971dadd19610d3ad38c768e124dc7","schema_version":"edge-lab-recorder.raw.v1","sequence":null,"source":"clob_market_ws"}
{"event_at":"2026-07-28T04:12:06.452000Z","event_fingerprint":"39ba8440d954e4aedf008234bca8dca2931078ec27433706086b810621a347a3","payload":{"connection_id":"f6725804f86a4c4eb588e4d5ed7db029","event_at":"2026-07-28T04:12:06.452000Z","event_type":"price_change","frame_hash":"d4706413178d67dedf60fb1928a64d28aa2d79187ea73e046695b5927443fa8d","frame_index":0,"kind":"data","monotonic_ns":313911372835333,"payload":{"event_type":"price_change","market":"0xd412ce774cfcf8dc9f71164aac78783978aac7b03871702a3b8a481bd9dc9688","price_changes":[{"asset_id":"96600821790790307414914106093858868634329285205417149685270682748367152458577","best_ask":"0.43","best_bid":"0.42","hash":"afa0ac9f61324e8e671c91ad2cdf9fcd4b61e1c3","price":"0.39","side":"BUY","size":"52.6"},{"asset_id":"107603864457683460275633293642179940881969192120168665300712204232021063124301","best_ask":"0.58","best_bid":"0.57","hash":"23a7d0b8c50ba0f04f57843158ca7146ef7a9fa0","price":"0.61","side":"SELL","size":"52.6"}],"timestamp":"1785211926452"},"payload_hash":"f57d390edd8bb12b60bc6f12eb2198479832d0af98ee5c01e680a473b013295f","raw_frame":"{\"market\":\"0xd412ce774cfcf8dc9f71164aac78783978aac7b03871702a3b8a481bd9dc9688\", \"price_changes\":[{\"asset_id\":\"96600821790790307414914106093858868634329285205417149685270682748367152458577\", \"price\":\"0.39\", \"size\":\"52.6\", \"side\":\"BUY\", \"hash\":\"afa0ac9f61324e8e671c91ad2cdf9fcd4b61e1c3\", \"best_bid\":\"0.42\", \"best_ask\":\"0.43\"}, {\"asset_id\":\"107603864457683460275633293642179940881969192120168665300712204232021063124301\", \"price\":\"0.61\", \"size\":\"52.6\", \"side\":\"SELL\", \"hash\":\"23a7d0b8c50ba0f04f57843158ca7146ef7a9fa0\", \"best_bid\":\"0.57\", \"best_ask\":\"0.58\"}], \"timestamp\":\"1785211926452\", \"event_type\":\"price_change\"}","received_at":"2026-07-28T04:12:08.295651Z","schema_version":"clob-market-ws.price_change.v1","sequence":null,"server_hash":null,"server_timestamp":"1785211926452","session_id":"2d607381e3054cee91998cdf45a4231c","source":"clob_market_ws"},"received_at":"2026-07-28T04:12:08.295651Z","record_id":"8d3e18977c77d22f9e34726e7c196bc0fcb2938373ba639df212375909d25df6","schema_fingerprint":"4aa3821a28b0b7c2400bc59aba4bcc0a76e971dadd19610d3ad38c768e124dc7","schema_version":"edge-lab-recorder.raw.v1","sequence":null,"source":"clob_market_ws"}
{"event_at":"2026-07-28T04:12:06.454000Z","event_fingerprint":"19ea00706b4ed0c0743adf715bb3c3e4c1fc8b685b2430849cd61ad394a431b3","payload":{"connection_id":"f6725804f86a4c4eb588e4d5ed7db029","event_at":"2026-07-28T04:12:06.454000Z","event_type":"price_change","frame_hash":"17ac679d34d8cb8512e7e64fdf428939b15a8bf9f434ddef69473ff0dadedc0a","frame_index":0,"kind":"data","monotonic_ns":313911385083041,"payload":{"event_type":"price_change","market":"0xd412ce774cfcf8dc9f71164aac78783978aac7b03871702a3b8a481bd9dc9688","price_changes":[{"asset_id":"96600821790790307414914106093858868634329285205417149685270682748367152458577","best_ask":"0.43","best_bid":"0.42","hash":"3bc3821e4bcea0aac45c0afb9c3165ee0f8227d2","price":"0.39","side":"BUY","size":"46.6"},{"asset_id":"107603864457683460275633293642179940881969192120168665300712204232021063124301","best_ask":"0.58","best_bid":"0.57","hash":"9aae9fec98dd193166e35bdcdade5f7f66a4e145","price":"0.61","side":"SELL","size":"46.6"}],"timestamp":"1785211926454"},"payload_hash":"5ee431bc9bf2a2b54a34af3326db54b29fd4df75b419724a6b7105436879b059","raw_frame":"{\"market\":\"0xd412ce774cfcf8dc9f71164aac78783978aac7b03871702a3b8a481bd9dc9688\", \"price_changes\":[{\"asset_id\":\"96600821790790307414914106093858868634329285205417149685270682748367152458577\", \"price\":\"0.39\", \"size\":\"46.6\", \"side\":\"BUY\", \"hash\":\"3bc3821e4bcea0aac45c0afb9c3165ee0f8227d2\", \"best_bid\":\"0.42\", \"best_ask\":\"0.43\"}, {\"asset_id\":\"107603864457683460275633293642179940881969192120168665300712204232021063124301\", \"price\":\"0.61\", \"size\":\"46.6\", \"side\":\"SELL\", \"hash\":\"9aae9fec98dd193166e35bdcdade5f7f66a4e145\", \"best_bid\":\"0.57\", \"best_ask\":\"0.58\"}], \"timestamp\":\"1785211926454\", \"event_type\":\"price_change\"}","received_at":"2026-07-28T04:12:08.307897Z","schema_version":"clob-market-ws.price_change.v1","sequence":null,"server_hash":null,"server_timestamp":"1785211926454","session_id":"2d607381e3054cee91998cdf45a4231c","source":"clob_market_ws"},"received_at":"2026-07-28T04:12:08.307897Z","record_id":"32c2cdf60ffb4e944e1aeadf8c55f3e9f3ba5d37bdd145ea89f62ee446ece14d","schema_fingerprint":"4aa3821a28b0b7c2400bc59aba4bcc0a76e971dadd19610d3ad38c768e124dc7","schema_version":"edge-lab-recorder.raw.v1","sequence":null,"source":"clob_market_ws"}
{"event_at":"2026-07-28T04:12:06.459000Z","event_fingerprint":"906d91a30687350d6f10bee5b6a384715c9cfe3d467f7380907be3d06bc3fcb8","payload":{"connection_id":"f6725804f86a4c4eb588e4d5ed7db029","event_at":"2026-07-28T04:12:06.459000Z","event_type":"price_change","frame_hash":"8c0d4af7b5100d2294d91d5ee75be12066a0b863e87573cd4a040d2cf58219fa","frame_index":0,"kind":"data","monotonic_ns":313911389792708,"payload":{"event_type":"price_change","market":"0xd412ce774cfcf8dc9f71164aac78783978aac7b03871702a3b8a481bd9dc9688","price_changes":[{"asset_id":"107603864457683460275633293642179940881969192120168665300712204232021063124301","best_ask":"0.58","best_bid":"0.57","hash":"db6d6433a7a93e7abb57d6052286dc929aa3956c","price":"0.64","side":"SELL","size":"107"},{"asset_id":"96600821790790307414914106093858868634329285205417149685270682748367152458577","best_ask":"0.43","best_bid":"0.42","hash":"372d262d9bd5fc6cadc4fc11c68139fa35537cd1","price":"0.36","side":"BUY","size":"107"}],"timestamp":"1785211926459"},"payload_hash":"7208e7e38d30a32004dff58ac0752e48e6b4cb3aaedb2ad570de6b25b59d8bc7","raw_frame":"{\"market\":\"0xd412ce774cfcf8dc9f71164aac78783978aac7b03871702a3b8a481bd9dc9688\", \"price_changes\":[{\"asset_id\":\"107603864457683460275633293642179940881969192120168665300712204232021063124301\", \"price\":\"0.64\", \"size\":\"107\", \"side\":\"SELL\", \"hash\":\"db6d6433a7a93e7abb57d6052286dc929aa3956c\", \"best_bid\":\"0.57\", \"best_ask\":\"0.58\"}, {\"asset_id\":\"96600821790790307414914106093858868634329285205417149685270682748367152458577\", \"price\":\"0.36\", \"size\":\"107\", \"side\":\"BUY\", \"hash\":\"372d262d9bd5fc6cadc4fc11c68139fa35537cd1\", \"best_bid\":\"0.42\", \"best_ask\":\"0.43\"}], \"timestamp\":\"1785211926459\", \"event_type\":\"price_change\"}","received_at":"2026-07-28T04:12:08.312608Z","schema_version":"clob-market-ws.price_change.v1","sequence":null,"server_hash":null,"server_timestamp":"1785211926459","session_id":"2d607381e3054cee91998cdf45a4231c","source":"clob_market_ws"},"received_at":"2026-07-28T04:12:08.312608Z","record_id":"0bb7b73f4546eddd122664341b9058eae7f84dffd69b313c1fe34071c95762bf","schema_fingerprint":"4aa3821a28b0b7c2400bc59aba4bcc0a76e971dadd19610d3ad38c768e124dc7","schema_version":"edge-lab-recorder.raw.v1","sequence":null,"source":"clob_market_ws"}
{"event_at":"2026-07-28T04:12:06.460000Z","event_fingerprint":"22e8a23c6ab5732d2305b0f9182a84822cf92f8ed251e78d865eba3e24f191e2","payload":{"connection_id":"f6725804f86a4c4eb588e4d5ed7db029","event_at":"2026-07-28T04:12:06.460000Z","event_type":"price_change","frame_hash":"978718701d74adc7454ae9f175d0c401a352285d6f507513096d6bae5f47fc08","frame_index":0,"kind":"data","monotonic_ns":313911395319166,"payload":{"event_type":"price_change","market":"0xd412ce774cfcf8dc9f71164aac78783978aac7b03871702a3b8a481bd9dc9688","price_changes":[{"asset_id":"107603864457683460275633293642179940881969192120168665300712204232021063124301","best_ask":"0.58","best_bid":"0.57","hash":"d104630c20cdb6bee28fc04bcd8681d43328fd51","price":"0.65","side":"SELL","size":"81"},{"asset_id":"96600821790790307414914106093858868634329285205417149685270682748367152458577","best_ask":"0.43","best_bid":"0.42","hash":"98af06a667a18f44256ff5a786f45bf4057ab4b8","price":"0.35","side":"BUY","size":"81"}],"timestamp":"1785211926460"},"payload_hash":"d8743998c5bee849cfbd8181291832ccb3afa9597aa758547c144e70a4d8d93f","raw_frame":"{\"market\":\"0xd412ce774cfcf8dc9f71164aac78783978aac7b03871702a3b8a481bd9dc9688\", \"price_changes\":[{\"asset_id\":\"107603864457683460275633293642179940881969192120168665300712204232021063124301\", \"price\":\"0.65\", \"size\":\"81\", \"side\":\"SELL\", \"hash\":\"d104630c20cdb6bee28fc04bcd8681d43328fd51\", \"best_bid\":\"0.57\", \"best_ask\":\"0.58\"}, {\"asset_id\":\"96600821790790307414914106093858868634329285205417149685270682748367152458577\", \"price\":\"0.35\", \"size\":\"81\", \"side\":\"BUY\", \"hash\":\"98af06a667a18f44256ff5a786f45bf4057ab4b8\", \"best_bid\":\"0.42\", \"best_ask\":\"0.43\"}], \"timestamp\":\"1785211926460\", \"event_type\":\"price_change\"}","received_at":"2026-07-28T04:12:08.318135Z","schema_version":"clob-market-ws.price_change.v1","sequence":null,"server_hash":null,"server_timestamp":"1785211926460","session_id":"2d607381e3054cee91998cdf45a4231c","source":"clob_market_ws"},"received_at":"2026-07-28T04:12:08.318135Z","record_id":"d872dcabd22b2ad862de3997958d64b7d44f6d4ad03171374183462872136e6e","schema_fingerprint":"4aa3821a28b0b7c2400bc59aba4bcc0a76e971dadd19610d3ad38c768e124dc7","schema_version":"edge-lab-recorder.raw.v1","sequence":null,"source":"clob_market_ws"}
{"event_at":"2026-07-28T04:12:06.464000Z","event_fingerprint":"29b6c2af472e467364dc03c84e9bc9892c187d45ab6dde0e90b2a1d68b5c05b0","payload":{"connection_id":"f6725804f86a4c4eb588e4d5ed7db029","event_at":"2026-07-28T04:12:06.464000Z","event_type":"price_change","frame_hash":"bc6ac778d9829f92c591e420c34b53d435c7fd0d37f479c3d2dab2ca494ccd53","frame_index":0,"kind":"data","monotonic_ns":313911399573166,"payload":{"event_type":"price_change","market":"0xd412ce774cfcf8dc9f71164aac78783978aac7b03871702a3b8a481bd9dc9688","price_changes":[{"asset_id":"107603864457683460275633293642179940881969192120168665300712204232021063124301","best_ask":"0.58","best_bid":"0.57","hash":"9cdc47f63ca0b591b9d9263c2c0dac4747facc0b","price":"0.33","side":"BUY","size":"19.36"},{"asset_id":"96600821790790307414914106093858868634329285205417149685270682748367152458577","best_ask":"0.43","best_bid":"0.42","hash":"7cc661835c877d79caae41fa96c84eddc6af4229","price":"0.67","side":"SELL","size":"19.36"}],"timestamp":"1785211926464"},"payload_hash":"30f48e36bee0abb83724e58acffc31ee0d99474e18f0de1c4b20e610cac59e42","raw_frame":"{\"market\":\"0xd412ce774cfcf8dc9f71164aac78783978aac7b03871702a3b8a481bd9dc9688\", \"price_changes\":[{\"asset_id\":\"107603864457683460275633293642179940881969192120168665300712204232021063124301\", \"price\":\"0.33\", \"size\":\"19.36\", \"side\":\"BUY\", \"hash\":\"9cdc47f63ca0b591b9d9263c2c0dac4747facc0b\", \"best_bid\":\"0.57\", \"best_ask\":\"0.58\"}, {\"asset_id\":\"96600821790790307414914106093858868634329285205417149685270682748367152458577\", \"price\":\"0.67\", \"size\":\"19.36\", \"side\":\"SELL\", \"hash\":\"7cc661835c877d79caae41fa96c84eddc6af4229\", \"best_bid\":\"0.42\", \"best_ask\":\"0.43\"}], \"timestamp\":\"1785211926464\", \"event_type\":\"price_change\"}","received_at":"2026-07-28T04:12:08.322390Z","schema_version":"clob-market-ws.price_change.v1","sequence":null,"server_hash":null,"server_timestamp":"1785211926464","session_id":"2d607381e3054cee91998cdf45a4231c","source":"clob_market_ws"},"received_at":"2026-07-28T04:12:08.322390Z","record_id":"db0c632c1c4a4db9f309ccbcddaab0f6149271af483318b54adda439232d9e91","schema_fingerprint":"4aa3821a28b0b7c2400bc59aba4bcc0a76e971dadd19610d3ad38c768e124dc7","schema_version":"edge-lab-recorder.raw.v1","sequence":null,"source":"clob_market_ws"}
{"event_at":"2026-07-28T04:12:06.464000Z","event_fingerprint":"87e3d42d2d1f0d57d9a2bbfea1c148f89075f36bc639ec87b144d5691ef6e64b","payload":{"connection_id":"f6725804f86a4c4eb588e4d5ed7db029","event_at":"2026-07-28T04:12:06.464000Z","event_type":"price_change","frame_hash":"97b809cd537e81a199a300f487a7d2caf1ddce42ee115212b8178e4e4b3599e0","frame_index":0,"kind":"data","monotonic_ns":313911403913000,"payload":{"event_type":"price_change","market":"0xd412ce774cfcf8dc9f71164aac78783978aac7b03871702a3b8a481bd9dc9688","price_changes":[{"asset_id":"96600821790790307414914106093858868634329285205417149685270682748367152458577","best_ask":"0.43","best_bid":"0.42","hash":"a5621c215ad54deb87bf39d81d54e9bd592b5819","price":"0.36","side":"BUY","size":"152"},{"asset_id":"107603864457683460275633293642179940881969192120168665300712204232021063124301","best_ask":"0.58","best_bid":"0.57","hash":"c2b38d3f29a15005dababc437eb0cd53cd7ec8d0","price":"0.64","side":"SELL","size":"152"}],"timestamp":"1785211926464"},"payload_hash":"9f90582b6a14c2915415cf7486be9c66e48ea723f9010b998f2493248576f9e9","raw_frame":"{\"market\":\"0xd412ce774cfcf8dc9f71164aac78783978aac7b03871702a3b8a481bd9dc9688\", \"price_changes\":[{\"asset_id\":\"96600821790790307414914106093858868634329285205417149685270682748367152458577\", \"price\":\"0.36\", \"size\":\"152\", \"side\":\"BUY\", \"hash\":\"a5621c215ad54deb87bf39d81d54e9bd592b5819\", \"best_bid\":\"0.42\", \"best_ask\":\"0.43\"}, {\"asset_id\":\"107603864457683460275633293642179940881969192120168665300712204232021063124301\", \"price\":\"0.64\", \"size\":\"152\", \"side\":\"SELL\", \"hash\":\"c2b38d3f29a15005dababc437eb0cd53cd7ec8d0\", \"best_bid\":\"0.57\", \"best_ask\":\"0.58\"}], \"timestamp\":\"1785211926464\", \"event_type\":\"price_change\"}","received_at":"2026-07-28T04:12:08.326729Z","schema_version":"clob-market-ws.price_change.v1","sequence":null,"server_hash":null,"server_timestamp":"1785211926464","session_id":"2d607381e3054cee91998cdf45a4231c","source":"clob_market_ws"},"received_at":"2026-07-28T04:12:08.326729Z","record_id":"8b5ce7c28cf9eb623499604ec92c50cb1c05530f92f11ffca5bdc529d815c634","schema_fingerprint":"4aa3821a28b0b7c2400bc59aba4bcc0a76e971dadd19610d3ad38c768e124dc7","schema_version":"edge-lab-recorder.raw.v1","sequence":null,"source":"clob_market_ws"}
{"event_at":"2026-07-28T04:12:06.477000Z","event_fingerprint":"048286f6192c2f94ae9f9293be872ec1bc1c948efbd244daa9ba355ffa4eb185","payload":{"connection_id":"f6725804f86a4c4eb588e4d5ed7db029","event_at":"2026-07-28T04:12:06.477000Z","event_type":"price_change","frame_hash":"3bf92513c45a0eba11a4ee8b5606a8febfeb0b42e3fd3ddcd4b4d30168c88588","frame_index":0,"kind":"data","monotonic_ns":313911407568333,"payload":{"event_type":"price_change","market":"0xd412ce774cfcf8dc9f71164aac78783978aac7b03871702a3b8a481bd9dc9688","price_changes":[{"asset_id":"107603864457683460275633293642179940881969192120168665300712204232021063124301","best_ask":"0.58","best_bid":"0.57","hash":"bfd36e037f873ef5e51323db607c7dbc0e848d2e","price":"0.02","side":"BUY","size":"535"},{"asset_id":"96600821790790307414914106093858868634329285205417149685270682748367152458577","best_ask":"0.43","best_bid":"0.42","hash":"5f089764715938e19b210848a00420f5a0baf47d","price":"0.98","side":"SELL","size":"535"}],"timestamp":"1785211926477"},"payload_hash":"b0c75ccdf5c6b9091d6ad7644ca6d89f65f93dec3a5205104d854d58cfc9f866","raw_frame":"{\"market\":\"0xd412ce774cfcf8dc9f71164aac78783978aac7b03871702a3b8a481bd9dc9688\", \"price_changes\":[{\"asset_id\":\"107603864457683460275633293642179940881969192120168665300712204232021063124301\", \"price\":\"0.02\", \"size\":\"535\", \"side\":\"BUY\", \"hash\":\"bfd36e037f873ef5e51323db607c7dbc0e848d2e\", \"best_bid\":\"0.57\", \"best_ask\":\"0.58\"}, {\"asset_id\":\"96600821790790307414914106093858868634329285205417149685270682748367152458577\", \"price\":\"0.98\", \"size\":\"535\", \"side\":\"SELL\", \"hash\":\"5f089764715938e19b210848a00420f5a0baf47d\", \"best_bid\":\"0.42\", \"best_ask\":\"0.43\"}], \"timestamp\":\"1785211926477\", \"event_type\":\"price_change\"}","received_at":"2026-07-28T04:12:08.330384Z","schema_version":"clob-market-ws.price_change.v1","sequence":null,"server_hash":null,"server_timestamp":"1785211926477","session_id":"2d607381e3054cee91998cdf45a4231c","source":"clob_market_ws"},"received_at":"2026-07-28T04:12:08.330384Z","record_id":"a1f9ceb8c25bb6719c642da5a5bb374b0966c8655306193fc851e893f5e92da5","schema_fingerprint":"4aa3821a28b0b7c2400bc59aba4bcc0a76e971dadd19610d3ad38c768e124dc7","schema_version":"edge-lab-recorder.raw.v1","sequence":null,"source":"clob_market_ws"}
{"event_at":"2026-07-28T04:12:06.572000Z","event_fingerprint":"07b00afe808b9f6f0be885df41f93e7547068d5053a85a77c4d2a202c237ef65","payload":{"connection_id":"f6725804f86a4c4eb588e4d5ed7db029","event_at":"2026-07-28T04:12:06.572000Z","event_type":"price_change","frame_hash":"6a4edb3c92380ff70376456d16303f89392f8c99c6c65ad434c633803eb080d1","frame_index":0,"kind":"data","monotonic_ns":313911411987875,"payload":{"event_type":"price_change","market":"0xd412ce774cfcf8dc9f71164aac78783978aac7b03871702a3b8a481bd9dc9688","price_changes":[{"asset_id":"96600821790790307414914106093858868634329285205417149685270682748367152458577","best_ask":"0.43","best_bid":"0.42","hash":"3668c315841b20882d5f6b259dd5101e55873b63","price":"0.36","side":"BUY","size":"107"},{"asset_id":"107603864457683460275633293642179940881969192120168665300712204232021063124301","best_ask":"0.58","best_bid":"0.57","hash":"18bc3776815dc9a2a1979eb7ff88cb9986bcded5","price":"0.64","side":"SELL","size":"107"}],"timestamp":"1785211926572"},"payload_hash":"c17404f3307b787d57e3dc87799450deeb1388bc8fdd020f4e69764d0bcca882","raw_frame":"{\"market\":\"0xd412ce774cfcf8dc9f71164aac78783978aac7b03871702a3b8a481bd9dc9688\", \"price_changes\":[{\"asset_id\":\"96600821790790307414914106093858868634329285205417149685270682748367152458577\", \"price\":\"0.36\", \"size\":\"107\", \"side\":\"BUY\", \"hash\":\"3668c315841b20882d5f6b259dd5101e55873b63\", \"best_bid\":\"0.42\", \"best_ask\":\"0.43\"}, {\"asset_id\":\"107603864457683460275633293642179940881969192120168665300712204232021063124301\", \"price\":\"0.64\", \"size\":\"107\", \"side\":\"SELL\", \"hash\":\"18bc3776815dc9a2a1979eb7ff88cb9986bcded5\", \"best_bid\":\"0.57\", \"best_ask\":\"0.58\"}], \"timestamp\":\"1785211926572\", \"event_type\":\"price_change\"}","received_at":"2026-07-28T04:12:08.334804Z","schema_version":"clob-market-ws.price_change.v1","sequence":null,"server_hash":null,"server_timestamp":"1785211926572","session_id":"2d607381e3054cee91998cdf45a4231c","source":"clob_market_ws"},"received_at":"2026-07-28T04:12:08.334804Z","record_id":"4c0e0bdb884f8d2c2136e1380973266ff8cff739518bd3896945af2a2812e10b","schema_fingerprint":"4aa3821a28b0b7c2400bc59aba4bcc0a76e971dadd19610d3ad38c768e124dc7","schema_version":"edge-lab-recorder.raw.v1","sequence":null,"source":"clob_market_ws"}
{"event_at":"2026-07-28T04:12:06.573000Z","event_fingerprint":"7585e292cbc98565de39ef93ba563c0134babb16901d117b8f45d0cf1437626d","payload":{"connection_id":"f6725804f86a4c4eb588e4d5ed7db029","event_at":"2026-07-28T04:12:06.573000Z","event_type":"price_change","frame_hash":"d50fd0c2791b8eb15922459482e06cbe36064b6e6c002e72aebb536c027e2353","frame_index":0,"kind":"data","monotonic_ns":313911417265458,"payload":{"event_type":"price_change","market":"0xd412ce774cfcf8dc9f71164aac78783978aac7b03871702a3b8a481bd9dc9688","price_changes":[{"asset_id":"96600821790790307414914106093858868634329285205417149685270682748367152458577","best_ask":"0.43","best_bid":"0.42","hash":"0c58d41fcd1084ff2252c4219aeffc07f02f387a","price":"0.33","side":"BUY","size":"97"},{"asset_id":"107603864457683460275633293642179940881969192120168665300712204232021063124301","best_ask":"0.58","best_bid":"0.57","hash":"a3181d23c8fbec810e31306f46971725a0e8f873","price":"0.67","side":"SELL","size":"97"}],"timestamp":"1785211926573"},"payload_hash":"310fbb569712d294faf5c069c52a76c35c1d3e7bd689de5c3ef5d6af94b1c60f","raw_frame":"{\"market\":\"0xd412ce774cfcf8dc9f71164aac78783978aac7b03871702a3b8a481bd9dc9688\", \"price_changes\":[{\"asset_id\":\"96600821790790307414914106093858868634329285205417149685270682748367152458577\", \"price\":\"0.33\", \"size\":\"97\", \"side\":\"BUY\", \"hash\":\"0c58d41fcd1084ff2252c4219aeffc07f02f387a\", \"best_bid\":\"0.42\", \"best_ask\":\"0.43\"}, {\"asset_id\":\"107603864457683460275633293642179940881969192120168665300712204232021063124301\", \"price\":\"0.67\", \"size\":\"97\", \"side\":\"SELL\", \"hash\":\"a3181d23c8fbec810e31306f46971725a0e8f873\", \"best_bid\":\"0.57\", \"best_ask\":\"0.58\"}], \"timestamp\":\"1785211926573\", \"event_type\":\"price_change\"}","received_at":"2026-07-28T04:12:08.340082Z","schema_version":"clob-market-ws.price_change.v1","sequence":null,"server_hash":null,"server_timestamp":"1785211926573","session_id":"2d607381e3054cee91998cdf45a4231c","source":"clob_market_ws"},"received_at":"2026-07-28T04:12:08.340082Z","record_id":"da55264e20990fc8d11185dcc3080da336a5ed1b0969ccf3da669ccb0403ee7e","schema_fingerprint":"4aa3821a28b0b7c2400bc59aba4bcc0a76e971dadd19610d3ad38c768e124dc7","schema_version":"edge-lab-recorder.raw.v1","sequence":null,"source":"clob_market_ws"}
{"event_at":"2026-07-28T04:12:06.573000Z","event_fingerprint":"2c6b87bceb53f5af94484745bd681edfbe7d7c1bd253edafa0cd021376f8dc53","payload":{"connection_id":"f6725804f86a4c4eb588e4d5ed7db029","event_at":"2026-07-28T04:12:06.573000Z","event_type":"price_change","frame_hash":"4a5cc763c88a24fe5205a0298f477de411bea6cdfebbef4957b3c600923fe7e1","frame_index":0,"kind":"data","monotonic_ns":313911421140500,"payload":{"event_type":"price_change","market":"0xd412ce774cfcf8dc9f71164aac78783978aac7b03871702a3b8a481bd9dc9688","price_changes":[{"asset_id":"107603864457683460275633293642179940881969192120168665300712204232021063124301","best_ask":"0.58","best_bid":"0.57","hash":"0d44711bffad00e56d542ae0e921f938cc22543f","price":"0.39","side":"BUY","size":"30"},{"asset_id":"96600821790790307414914106093858868634329285205417149685270682748367152458577","best_ask":"0.43","best_bid":"0.42","hash":"c914dbe44b8285bfd70e71affa50e0efafe5ac0e","price":"0.61","side":"SELL","size":"30"}],"timestamp":"1785211926573"},"payload_hash":"392d3036f39a7a0c0752516abbeb7d26cacf205d0c996e6d613d8bb971ba9e45","raw_frame":"{\"market\":\"0xd412ce774cfcf8dc9f71164aac78783978aac7b03871702a3b8a481bd9dc9688\", \"price_changes\":[{\"asset_id\":\"107603864457683460275633293642179940881969192120168665300712204232021063124301\", \"price\":\"0.39\", \"size\":\"30\", \"side\":\"BUY\", \"hash\":\"0d44711bffad00e56d542ae0e921f938cc22543f\", \"best_bid\":\"0.57\", \"best_ask\":\"0.58\"}, {\"asset_id\":\"96600821790790307414914106093858868634329285205417149685270682748367152458577\", \"price\":\"0.61\", \"size\":\"30\", \"side\":\"SELL\", \"hash\":\"c914dbe44b8285bfd70e71affa50e0efafe5ac0e\", \"best_bid\":\"0.42\", \"best_ask\":\"0.43\"}], \"timestamp\":\"1785211926573\", \"event_type\":\"price_change\"}","received_at":"2026-07-28T04:12:08.343956Z","schema_version":"clob-market-ws.price_change.v1","sequence":null,"server_hash":null,"server_timestamp":"1785211926573","session_id":"2d607381e3054cee91998cdf45a4231c","source":"clob_market_ws"},"received_at":"2026-07-28T04:12:08.343956Z","record_id":"1ffa9d4797d54ba2bd59862c8d3f682993b5470dfb3397da0a665edbc6b4aec9","schema_fingerprint":"4aa3821a28b0b7c2400bc59aba4bcc0a76e971dadd19610d3ad38c768e124dc7","schema_version":"edge-lab-recorder.raw.v1","sequence":null,"source":"clob_market_ws"}
{"event_at":"2026-07-28T04:12:06.575000Z","event_fingerprint":"49dfa5df76cf956e55fb1828feb4880a994ea2d43dcc2f3e62bc1288194a446c","payload":{"connection_id":"f6725804f86a4c4eb588e4d5ed7db029","event_at":"2026-07-28T04:12:06.575000Z","event_type":"price_change","frame_hash":"e4885d47e0319e0d4ce6ae3d7e7f3326da1379350277552ad7f6fb74d349654e","frame_index":0,"kind":"data","monotonic_ns":313911425490750,"payload":{"event_type":"price_change","market":"0xd412ce774cfcf8dc9f71164aac78783978aac7b03871702a3b8a481bd9dc9688","price_changes":[{"asset_id":"96600821790790307414914106093858868634329285205417149685270682748367152458577","best_ask":"0.43","best_bid":"0.42","hash":"8c48a11861172eae453264ad63bbf930aacc82a0","price":"0.61","side":"SELL","size":"55"},{"asset_id":"107603864457683460275633293642179940881969192120168665300712204232021063124301","best_ask":"0.58","best_bid":"0.57","hash":"9f46f0ad1416c4bc6491e39f6633f020d8e6faa3","price":"0.39","side":"BUY","size":"55"}],"timestamp":"1785211926575"},"payload_hash":"0527e79e0eb37299d5f16c16a83c4c57c732045d2ee7a72e1a79e2dc060dac3b","raw_frame":"{\"market\":\"0xd412ce774cfcf8dc9f71164aac78783978aac7b03871702a3b8a481bd9dc9688\", \"price_changes\":[{\"asset_id\":\"96600821790790307414914106093858868634329285205417149685270682748367152458577\", \"price\":\"0.61\", \"size\":\"55\", \"side\":\"SELL\", \"hash\":\"8c48a11861172eae453264ad63bbf930aacc82a0\", \"best_bid\":\"0.42\", \"best_ask\":\"0.43\"}, {\"asset_id\":\"107603864457683460275633293642179940881969192120168665300712204232021063124301\", \"price\":\"0.39\", \"size\":\"55\", \"side\":\"BUY\", \"hash\":\"9f46f0ad1416c4bc6491e39f6633f020d8e6faa3\", \"best_bid\":\"0.57\", \"best_ask\":\"0.58\"}], \"timestamp\":\"1785211926575\", \"event_type\":\"price_change\"}","received_at":"2026-07-28T04:12:08.348307Z","schema_version":"clob-market-ws.price_change.v1","sequence":null,"server_hash":null,"server_timestamp":"1785211926575","session_id":"2d607381e3054cee91998cdf45a4231c","source":"clob_market_ws"},"received_at":"2026-07-28T04:12:08.348307Z","record_id":"dbb6f5b5ceffe55db45687f34df4e51396af097ced165ec46c7acb2ecdc68971","schema_fingerprint":"4aa3821a28b0b7c2400bc59aba4bcc0a76e971dadd19610d3ad38c768e124dc7","schema_version":"edge-lab-recorder.raw.v1","sequence":null,"source":"clob_market_ws"}
{"event_at":"2026-07-28T04:12:06.576000Z","event_fingerprint":"ced6bc4f32e2f0272da05d6694af15424efda9f5a7036de2187ef330cbf7411a","payload":{"connection_id":"f6725804f86a4c4eb588e4d5ed7db029","event_at":"2026-07-28T04:12:06.576000Z","event_type":"price_change","frame_hash":"69880e1a41dcce1d0a7a6150bdd27ffb9f6acf7cd1eba5ed86530bfcffb679da","frame_index":0,"kind":"data","monotonic_ns":313911429796416,"payload":{"event_type":"price_change","market":"0xd412ce774cfcf8dc9f71164aac78783978aac7b03871702a3b8a481bd9dc9688","price_changes":[{"asset_id":"107603864457683460275633293642179940881969192120168665300712204232021063124301","best_ask":"0.58","best_bid":"0.57","hash":"03bcff6eca3bf8eaeba0451d5b1894342f4b1e55","price":"0.65","side":"SELL","size":"90.97"},{"asset_id":"96600821790790307414914106093858868634329285205417149685270682748367152458577","best_ask":"0.43","best_bid":"0.42","hash":"e0eca987d13b4f5fc39d8f467a9cf9e366697319","price":"0.35","side":"BUY","size":"90.97"}],"timestamp":"1785211926576"},"payload_hash":"c25f33e9e1df06aabce284c3e69c880043d94667f3d6a87c32883ba1399417b7","raw_frame":"{\"market\":\"0xd412ce774cfcf8dc9f71164aac78783978aac7b03871702a3b8a481bd9dc9688\", \"price_changes\":[{\"asset_id\":\"107603864457683460275633293642179940881969192120168665300712204232021063124301\", \"price\":\"0.65\", \"size\":\"90.97\", \"side\":\"SELL\", \"hash\":\"03bcff6eca3bf8eaeba0451d5b1894342f4b1e55\", \"best_bid\":\"0.57\", \"best_ask\":\"0.58\"}, {\"asset_id\":\"96600821790790307414914106093858868634329285205417149685270682748367152458577\", \"price\":\"0.35\", \"size\":\"90.97\", \"side\":\"BUY\", \"hash\":\"e0eca987d13b4f5fc39d8f467a9cf9e366697319\", \"best_bid\":\"0.42\", \"best_ask\":\"0.43\"}], \"timestamp\":\"1785211926576\", \"event_type\":\"price_change\"}","received_at":"2026-07-28T04:12:08.352612Z","schema_version":"clob-market-ws.price_change.v1","sequence":null,"server_hash":null,"server_timestamp":"1785211926576","session_id":"2d607381e3054cee91998cdf45a4231c","source":"clob_market_ws"},"received_at":"2026-07-28T04:12:08.352612Z","record_id":"171bc4a83d14e6e5b9acbd470739fada0770583eeacce15bc914f87239491057","schema_fingerprint":"4aa3821a28b0b7c2400bc59aba4bcc0a76e971dadd19610d3ad38c768e124dc7","schema_version":"edge-lab-recorder.raw.v1","sequence":null,"source":"clob_market_ws"}
{"event_at":"2026-07-28T04:12:06.577000Z","event_fingerprint":"e820bf179772cedd6c79e4f2d4bba1640344d879b2c5c9682b0a0efab92a0072","payload":{"connection_id":"f6725804f86a4c4eb588e4d5ed7db029","event_at":"2026-07-28T04:12:06.577000Z","event_type":"price_change","frame_hash":"a404171f75f5f500abb73f63d56bc72f55d5e76c5b968ee1dd66385c608197be","frame_index":0,"kind":"data","monotonic_ns":313911434118125,"payload":{"event_type":"price_change","market":"0xd412ce774cfcf8dc9f71164aac78783978aac7b03871702a3b8a481bd9dc9688","price_changes":[{"asset_id":"107603864457683460275633293642179940881969192120168665300712204232021063124301","best_ask":"0.58","best_bid":"0.57","hash":"090be64d5020ec891bb4746794832f471b4ebab9","price":"0.64","side":"SELL","size":"151"},{"asset_id":"96600821790790307414914106093858868634329285205417149685270682748367152458577","best_ask":"0.43","best_bid":"0.42","hash":"f3dc40a228f2ec54701d9a0e4af0260b4ff87ba2","price":"0.36","side":"BUY","size":"151"}],"timestamp":"1785211926577"},"payload_hash":"deb88ca1bb18a2507a014c03a3ab273713efb271b9ee3f495c1da9c749c8a857","raw_frame":"{\"market\":\"0xd412ce774cfcf8dc9f71164aac78783978aac7b03871702a3b8a481bd9dc9688\", \"price_changes\":[{\"asset_id\":\"107603864457683460275633293642179940881969192120168665300712204232021063124301\", \"price\":\"0.64\", \"size\":\"151\", \"side\":\"SELL\", \"hash\":\"090be64d5020ec891bb4746794832f471b4ebab9\", \"best_bid\":\"0.57\", \"best_ask\":\"0.58\"}, {\"asset_id\":\"96600821790790307414914106093858868634329285205417149685270682748367152458577\", \"price\":\"0.36\", \"size\":\"151\", \"side\":\"BUY\", \"hash\":\"f3dc40a228f2ec54701d9a0e4af0260b4ff87ba2\", \"best_bid\":\"0.42\", \"best_ask\":\"0.43\"}], \"timestamp\":\"1785211926577\", \"event_type\":\"price_change\"}","received_at":"2026-07-28T04:12:08.356934Z","schema_version":"clob-market-ws.price_change.v1","sequence":null,"server_hash":null,"server_timestamp":"1785211926577","session_id":"2d607381e3054cee91998cdf45a4231c","source":"clob_market_ws"},"received_at":"2026-07-28T04:12:08.356934Z","record_id":"e067b6a611e57199751c17bdaa3a5f90c862b811db2396d125f10ddf11cca067","schema_fingerprint":"4aa3821a28b0b7c2400bc59aba4bcc0a76e971dadd19610d3ad38c768e124dc7","schema_version":"edge-lab-recorder.raw.v1","sequence":null,"source":"clob_market_ws"}
{"event_at":"2026-07-28T04:12:06.597000Z","event_fingerprint":"283cec63e3dc2d10fec00391bfb950485a2898c89df0b03cf3b901b0c9db5620","payload":{"connection_id":"f6725804f86a4c4eb588e4d5ed7db029","event_at":"2026-07-28T04:12:06.597000Z","event_type":"price_change","frame_hash":"c4c26019b0a3a42f66c1dbc12012045ebdab5a39168bd6292882114a9fcecd76","frame_index":0,"kind":"data","monotonic_ns":313911438326625,"payload":{"event_type":"price_change","market":"0xd412ce774cfcf8dc9f71164aac78783978aac7b03871702a3b8a481bd9dc9688","price_changes":[{"asset_id":"107603864457683460275633293642179940881969192120168665300712204232021063124301","best_ask":"0.58","best_bid":"0.57","hash":"00abaa39c0f7edb62e6d414b4bfdd93ae4da4dda","price":"0.02","side":"BUY","size":"530"},{"asset_id":"96600821790790307414914106093858868634329285205417149685270682748367152458577","best_ask":"0.43","best_bid":"0.42","hash":"d5bf35d1ad74e1b1bf0d12c5c8d96fb955d5da44","price":"0.98","side":"SELL","size":"530"}],"timestamp":"1785211926597"},"payload_hash":"a8a1598b615bc0da192e9d95060c11ec43c539d7eaaa780d453e7a512ef6f1c4","raw_frame":"{\"market\":\"0xd412ce774cfcf8dc9f71164aac78783978aac7b03871702a3b8a481bd9dc9688\", \"price_changes\":[{\"asset_id\":\"107603864457683460275633293642179940881969192120168665300712204232021063124301\", \"price\":\"0.02\", \"size\":\"530\", \"side\":\"BUY\", \"hash\":\"00abaa39c0f7edb62e6d414b4bfdd93ae4da4dda\", \"best_bid\":\"0.57\", \"best_ask\":\"0.58\"}, {\"asset_id\":\"96600821790790307414914106093858868634329285205417149685270682748367152458577\", \"price\":\"0.98\", \"size\":\"530\", \"side\":\"SELL\", \"hash\":\"d5bf35d1ad74e1b1bf0d12c5c8d96fb955d5da44\", \"best_bid\":\"0.42\", \"best_ask\":\"0.43\"}], \"timestamp\":\"1785211926597\", \"event_type\":\"price_change\"}","received_at":"2026-07-28T04:12:08.361142Z","schema_version":"clob-market-ws.price_change.v1","sequence":null,"server_hash":null,"server_timestamp":"1785211926597","session_id":"2d607381e3054cee91998cdf45a4231c","source":"clob_market_ws"},"received_at":"2026-07-28T04:12:08.361142Z","record_id":"d8844998e0202879ab3e53e36195388e079ae7892a12eb3097fa3c9c0cb2c3d3","schema_fingerprint":"4aa3821a28b0b7c2400bc59aba4bcc0a76e971dadd19610d3ad38c768e124dc7","schema_version":"edge-lab-recorder.raw.v1","sequence":null,"source":"clob_market_ws"}
{"event_at":"2026-07-28T04:12:06.610000Z","event_fingerprint":"ccacb0a421f44729d2c8b8021fb4f43111177046abda2dc9b5ab9691dc6e3ebd","payload":{"connection_id":"f6725804f86a4c4eb588e4d5ed7db029","event_at":"2026-07-28T04:12:06.610000Z","event_type":"price_change","frame_hash":"b037dedec76ae081ce4c874e126c3b57d0db7d5eeb60bdeaa7c1bcd9ff6aa8e6","frame_index":0,"kind":"data","monotonic_ns":313911442609375,"payload":{"event_type":"price_change","market":"0xd412ce774cfcf8dc9f71164aac78783978aac7b03871702a3b8a481bd9dc9688","price_changes":[{"asset_id":"96600821790790307414914106093858868634329285205417149685270682748367152458577","best_ask":"0.43","best_bid":"0.42","hash":"7df4b53e4e86445bd231a4afe9378d0fb7abca02","price":"0.41","side":"BUY","size":"34"},{"asset_id":"107603864457683460275633293642179940881969192120168665300712204232021063124301","best_ask":"0.58","best_bid":"0.57","hash":"316a18224a2fc05311665572965501bb0c3b25c6","price":"0.59","side":"SELL","size":"34"}],"timestamp":"1785211926610"},"payload_hash":"84786ddeea777c8f0c632f15952e5355f149f6ee535c0eafa7981c8976047235","raw_frame":"{\"market\":\"0xd412ce774cfcf8dc9f71164aac78783978aac7b03871702a3b8a481bd9dc9688\", \"price_changes\":[{\"asset_id\":\"96600821790790307414914106093858868634329285205417149685270682748367152458577\", \"price\":\"0.41\", \"size\":\"34\", \"side\":\"BUY\", \"hash\":\"7df4b53e4e86445bd231a4afe9378d0fb7abca02\", \"best_bid\":\"0.42\", \"best_ask\":\"0.43\"}, {\"asset_id\":\"107603864457683460275633293642179940881969192120168665300712204232021063124301\", \"price\":\"0.59\", \"size\":\"34\", \"side\":\"SELL\", \"hash\":\"316a18224a2fc05311665572965501bb0c3b25c6\", \"best_bid\":\"0.57\", \"best_ask\":\"0.58\"}], \"timestamp\":\"1785211926610\", \"event_type\":\"price_change\"}","received_at":"2026-07-28T04:12:08.365425Z","schema_version":"clob-market-ws.price_change.v1","sequence":null,"server_hash":null,"server_timestamp":"1785211926610","session_id":"2d607381e3054cee91998cdf45a4231c","source":"clob_market_ws"},"received_at":"2026-07-28T04:12:08.365425Z","record_id":"2729ad4eb344d1bacbf97bbd26eb9b329da5075b993a166377cfa91162738e76","schema_fingerprint":"4aa3821a28b0b7c2400bc59aba4bcc0a76e971dadd19610d3ad38c768e124dc7","schema_version":"edge-lab-recorder.raw.v1","sequence":null,"source":"clob_market_ws"}
{"event_at":"2026-07-28T04:12:06.611000Z","event_fingerprint":"b4879105b839b67f4c8a90cbe002ecf0016aa580adb7bb8dafb988dda02b14c1","payload":{"connection_id":"f6725804f86a4c4eb588e4d5ed7db029","event_at":"2026-07-28T04:12:06.611000Z","event_type":"price_change","frame_hash":"8e9e7ef8223dd107b6e901a10deeed966c661e808ad8a189f7326eafd3cf6e9b","frame_index":0,"kind":"data","monotonic_ns":313911446984041,"payload":{"event_type":"price_change","market":"0xd412ce774cfcf8dc9f71164aac78783978aac7b03871702a3b8a481bd9dc9688","price_changes":[{"asset_id":"107603864457683460275633293642179940881969192120168665300712204232021063124301","best_ask":"0.58","best_bid":"0.57","hash":"85f8f84260604814907eb3b19dd788784f99d62b","price":"0.37","side":"BUY","size":"50"},{"asset_id":"96600821790790307414914106093858868634329285205417149685270682748367152458577","best_ask":"0.43","best_bid":"0.42","hash":"000108924a9dba89cf402830ca262b459c1d47f1","price":"0.63","side":"SELL","size":"50"}],"timestamp":"1785211926611"},"payload_hash":"44dc19e524ce8957d6c7948e32bfa47899342203242d1459aaed1217abc02009","raw_frame":"{\"market\":\"0xd412ce774cfcf8dc9f71164aac78783978aac7b03871702a3b8a481bd9dc9688\", \"price_changes\":[{\"asset_id\":\"107603864457683460275633293642179940881969192120168665300712204232021063124301\", \"price\":\"0.37\", \"size\":\"50\", \"side\":\"BUY\", \"hash\":\"85f8f84260604814907eb3b19dd788784f99d62b\", \"best_bid\":\"0.57\", \"best_ask\":\"0.58\"}, {\"asset_id\":\"96600821790790307414914106093858868634329285205417149685270682748367152458577\", \"price\":\"0.63\", \"size\":\"50\", \"side\":\"SELL\", \"hash\":\"000108924a9dba89cf402830ca262b459c1d47f1\", \"best_bid\":\"0.42\", \"best_ask\":\"0.43\"}], \"timestamp\":\"1785211926611\", \"event_type\":\"price_change\"}","received_at":"2026-07-28T04:12:08.369800Z","schema_version":"clob-market-ws.price_change.v1","sequence":null,"server_hash":null,"server_timestamp":"1785211926611","session_id":"2d607381e3054cee91998cdf45a4231c","source":"clob_market_ws"},"received_at":"2026-07-28T04:12:08.369800Z","record_id":"8486b7e5fd03778551ba1971e856d53ff62375cbb92981cad62b6ac5f790399c","schema_fingerprint":"4aa3821a28b0b7c2400bc59aba4bcc0a76e971dadd19610d3ad38c768e124dc7","schema_version":"edge-lab-recorder.raw.v1","sequence":null,"source":"clob_market_ws"}
{"event_at":"2026-07-28T04:12:06.682000Z","event_fingerprint":"9e30bc2640ddaddd0fe2dc7cc9d103faf0acb2ba97cd8105268a5b468f2e4724","payload":{"connection_id":"f6725804f86a4c4eb588e4d5ed7db029","event_at":"2026-07-28T04:12:06.682000Z","event_type":"price_change","frame_hash":"a389908d49cb24a7f4523128c7b5b8a52560e612422aa552b9e13069d249bb4e","frame_index":0,"kind":"data","monotonic_ns":313911451144166,"payload":{"event_type":"price_change","market":"0xd412ce774cfcf8dc9f71164aac78783978aac7b03871702a3b8a481bd9dc9688","price_changes":[{"asset_id":"107603864457683460275633293642179940881969192120168665300712204232021063124301","best_ask":"0.58","best_bid":"0.57","hash":"b161ffef6a8bc5bbea55771beb7ebf7a32de4377","price":"0.65","side":"SELL","size":"81"},{"asset_id":"96600821790790307414914106093858868634329285205417149685270682748367152458577","best_ask":"0.43","best_bid":"0.42","hash":"98cd2c9e167a33aa9c352313c35891742132a559","price":"0.35","side":"BUY","size":"81"}],"timestamp":"1785211926682"},"payload_hash":"7c793163ad8bf76d14dcd2988c3d5e6d5f0f8ecbff3e81b355da2a759c19f2f9","raw_frame":"{\"market\":\"0xd412ce774cfcf8dc9f71164aac78783978aac7b03871702a3b8a481bd9dc9688\", \"price_changes\":[{\"asset_id\":\"107603864457683460275633293642179940881969192120168665300712204232021063124301\", \"price\":\"0.65\", \"size\":\"81\", \"side\":\"SELL\", \"hash\":\"b161ffef6a8bc5bbea55771beb7ebf7a32de4377\", \"best_bid\":\"0.57\", \"best_ask\":\"0.58\"}, {\"asset_id\":\"96600821790790307414914106093858868634329285205417149685270682748367152458577\", \"price\":\"0.35\", \"size\":\"81\", \"side\":\"BUY\", \"hash\":\"98cd2c9e167a33aa9c352313c35891742132a559\", \"best_bid\":\"0.42\", \"best_ask\":\"0.43\"}], \"timestamp\":\"1785211926682\", \"event_type\":\"price_change\"}","received_at":"2026-07-28T04:12:08.373960Z","schema_version":"clob-market-ws.price_change.v1","sequence":null,"server_hash":null,"server_timestamp":"1785211926682","session_id":"2d607381e3054cee91998cdf45a4231c","source":"clob_market_ws"},"received_at":"2026-07-28T04:12:08.373960Z","record_id":"3e25665c5c888ec13ce9eeb6146eda5f8de3c722d7f035b5a4be7f0d4c0e84e7","schema_fingerprint":"4aa3821a28b0b7c2400bc59aba4bcc0a76e971dadd19610d3ad38c768e124dc7","schema_version":"edge-lab-recorder.raw.v1","sequence":null,"source":"clob_market_ws"}
{"event_at":"2026-07-28T04:12:06.683000Z","event_fingerprint":"1b12d81e74ece60654af90988ee36c4b6cc4d402e7b66d6d238ed3d40b044fb6","payload":{"connection_id":"f6725804f86a4c4eb588e4d5ed7db029","event_at":"2026-07-28T04:12:06.683000Z","event_type":"price_change","frame_hash":"59301dae19e4e4d11429d4a00f4cca9a85fa740ae608071f66fd1f839c0c0a94","frame_index":0,"kind":"data","monotonic_ns":313911453485750,"payload":{"event_type":"price_change","market":"0xd412ce774cfcf8dc9f71164aac78783978aac7b03871702a3b8a481bd9dc9688","price_changes":[{"asset_id":"107603864457683460275633293642179940881969192120168665300712204232021063124301","best_ask":"0.58","best_bid":"0.57","hash":"36e753cc53275cfad6521f46000c27cdf571a8d3","price":"0.64","side":"SELL","size":"107"},{"asset_id":"96600821790790307414914106093858868634329285205417149685270682748367152458577","best_ask":"0.43","best_bid":"0.42","hash":"8d7f9d4346f7affe8500533fb7050525ffbc4173","price":"0.36","side":"BUY","size":"107"}],"timestamp":"1785211926683"},"payload_hash":"d1512d2c86964ac04037d803302130bc062aa4b370e20712d97379dc59cbc31f","raw_frame":"{\"market\":\"0xd412ce774cfcf8dc9f71164aac78783978aac7b03871702a3b8a481bd9dc9688\", \"price_changes\":[{\"asset_id\":\"107603864457683460275633293642179940881969192120168665300712204232021063124301\", \"price\":\"0.64\", \"size\":\"107\", \"side\":\"SELL\", \"hash\":\"36e753cc53275cfad6521f46000c27cdf571a8d3\", \"best_bid\":\"0.57\", \"best_ask\":\"0.58\"}, {\"asset_id\":\"96600821790790307414914106093858868634329285205417149685270682748367152458577\", \"price\":\"0.36\", \"size\":\"107\", \"side\":\"BUY\", \"hash\":\"8d7f9d4346f7affe8500533fb7050525ffbc4173\", \"best_bid\":\"0.42\", \"best_ask\":\"0.43\"}], \"timestamp\":\"1785211926683\", \"event_type\":\"price_change\"}","received_at":"2026-07-28T04:12:08.376302Z","schema_version":"clob-market-ws.price_change.v1","sequence":null,"server_hash":null,"server_timestamp":"1785211926683","session_id":"2d607381e3054cee91998cdf45a4231c","source":"clob_market_ws"},"received_at":"2026-07-28T04:12:08.376302Z","record_id":"f117b51ef4ac7b3df1a075ea3eed66a0493de6347e49fbe3a5dcb9374210626b","schema_fingerprint":"4aa3821a28b0b7c2400bc59aba4bcc0a76e971dadd19610d3ad38c768e124dc7","schema_version":"edge-lab-recorder.raw.v1","sequence":null,"source":"clob_market_ws"}
{"event_at":"2026-07-28T04:12:06.686000Z","event_fingerprint":"5c0f29200782f53f0b3804b565df547101872995aa70e724259146ab2cc73182","payload":{"connection_id":"f6725804f86a4c4eb588e4d5ed7db029","event_at":"2026-07-28T04:12:06.686000Z","event_type":"price_change","frame_hash":"cf7538680c2e36a32818eb91f05867b3d9b0d15f5e4daa1297c5932877658de9","frame_index":0,"kind":"data","monotonic_ns":313911457055291,"payload":{"event_type":"price_change","market":"0xd412ce774cfcf8dc9f71164aac78783978aac7b03871702a3b8a481bd9dc9688","price_changes":[{"asset_id":"96600821790790307414914106093858868634329285205417149685270682748367152458577","best_ask":"0.43","best_bid":"0.42","hash":"1ed24087395d85785ff203d6c9da7e563a85e5bc","price":"0.36","side":"BUY","size":"151"},{"asset_id":"107603864457683460275633293642179940881969192120168665300712204232021063124301","best_ask":"0.58","best_bid":"0.57","hash":"2b2523017f883d9dc5474f98d627af1104347c81","price":"0.64","side":"SELL","size":"151"}],"timestamp":"1785211926686"},"payload_hash":"bcbaaf9d071fa04cced2223b160436b41f2eb5fd037c246975075cf32e5433c5","raw_frame":"{\"market\":\"0xd412ce774cfcf8dc9f71164aac78783978aac7b03871702a3b8a481bd9dc9688\", \"price_changes\":[{\"asset_id\":\"96600821790790307414914106093858868634329285205417149685270682748367152458577\", \"price\":\"0.36\", \"size\":\"151\", \"side\":\"BUY\", \"hash\":\"1ed24087395d85785ff203d6c9da7e563a85e5bc\", \"best_bid\":\"0.42\", \"best_ask\":\"0.43\"}, {\"asset_id\":\"107603864457683460275633293642179940881969192120168665300712204232021063124301\", \"price\":\"0.64\", \"size\":\"151\", \"side\":\"SELL\", \"hash\":\"2b2523017f883d9dc5474f98d627af1104347c81\", \"best_bid\":\"0.57\", \"best_ask\":\"0.58\"}], \"timestamp\":\"1785211926686\", \"event_type\":\"price_change\"}","received_at":"2026-07-28T04:12:08.379871Z","schema_version":"clob-market-ws.price_change.v1","sequence":null,"server_hash":null,"server_timestamp":"1785211926686","session_id":"2d607381e3054cee91998cdf45a4231c","source":"clob_market_ws"},"received_at":"2026-07-28T04:12:08.379871Z","record_id":"25d5f5bc6a0d5c69a9c96926e7a8de2c5bc4a655c7bd4c24a7244704dad42ef6","schema_fingerprint":"4aa3821a28b0b7c2400bc59aba4bcc0a76e971dadd19610d3ad38c768e124dc7","schema_version":"edge-lab-recorder.raw.v1","sequence":null,"source":"clob_market_ws"}
{"event_at":null,"event_fingerprint":"34b54309e15620c8b7c63917362580ac7c5f36bf5ce447b0a8b5e02bfb7679b6","payload":{"connection_id":"f6725804f86a4c4eb588e4d5ed7db029","event_type":"heartbeat_ack","frame_hash":"95784973cc639977bff93619700168505cb8f7855e44fa643d34622a43706c87","kind":"lifecycle","monotonic_ns":313911461259000,"raw_frame":"PONG","received_at":"2026-07-28T04:12:08.384075Z","schema_version":"edge-lab-recorder.heartbeat-ack.v1","session_id":"2d607381e3054cee91998cdf45a4231c","source":"clob_market_ws"},"received_at":"2026-07-28T04:12:08.384075Z","record_id":"ec68bddedf6b0a1ada351e138f01f7c12d07dc3468f983a62fc9f067ba3eff10","schema_fingerprint":"c14ee1aab3ca674ee738e5268877b544d74c41ad3c427cedc09236467dc68ba1","schema_version":"edge-lab-recorder.raw.v1","sequence":null,"source":"clob_market_ws"}
{"event_at":"2026-07-28T04:12:06.697000Z","event_fingerprint":"ef2609c4bf2d1aeb8f8559844f2cfe5cd8808c5e16ab3e62da8d3c28e7fe90ee","payload":{"connection_id":"f6725804f86a4c4eb588e4d5ed7db029","event_at":"2026-07-28T04:12:06.697000Z","event_type":"price_change","frame_hash":"7c581672e4649d1a9fad7c42e92daaf9c894b88c4fca36eecd4fdbdb4a44d872","frame_index":0,"kind":"data","monotonic_ns":313911464687416,"payload":{"event_type":"price_change","market":"0xd412ce774cfcf8dc9f71164aac78783978aac7b03871702a3b8a481bd9dc9688","price_changes":[{"asset_id":"107603864457683460275633293642179940881969192120168665300712204232021063124301","best_ask":"0.58","best_bid":"0.57","hash":"440fff8d234d812ae1b7d3e2d7a3c1f6a461c8a2","price":"0.02","side":"BUY","size":"535"},{"asset_id":"96600821790790307414914106093858868634329285205417149685270682748367152458577","best_ask":"0.43","best_bid":"0.42","hash":"97777e20daa0372bca75f059e3da7745c0059229","price":"0.98","side":"SELL","size":"535"}],"timestamp":"1785211926697"},"payload_hash":"099077aab4e5de2f2aebdcf390ff51f870dbfa2fd4acdb0c882adcacb1ac4b4a","raw_frame":"{\"market\":\"0xd412ce774cfcf8dc9f71164aac78783978aac7b03871702a3b8a481bd9dc9688\", \"price_changes\":[{\"asset_id\":\"107603864457683460275633293642179940881969192120168665300712204232021063124301\", \"price\":\"0.02\", \"size\":\"535\", \"side\":\"BUY\", \"hash\":\"440fff8d234d812ae1b7d3e2d7a3c1f6a461c8a2\", \"best_bid\":\"0.57\", \"best_ask\":\"0.58\"}, {\"asset_id\":\"96600821790790307414914106093858868634329285205417149685270682748367152458577\", \"price\":\"0.98\", \"size\":\"535\", \"side\":\"SELL\", \"hash\":\"97777e20daa0372bca75f059e3da7745c0059229\", \"best_bid\":\"0.42\", \"best_ask\":\"0.43\"}], \"timestamp\":\"1785211926697\", \"event_type\":\"price_change\"}","received_at":"2026-07-28T04:12:08.387501Z","schema_version":"clob-market-ws.price_change.v1","sequence":null,"server_hash":null,"server_timestamp":"1785211926697","session_id":"2d607381e3054cee91998cdf45a4231c","source":"clob_market_ws"},"received_at":"2026-07-28T04:12:08.387501Z","record_id":"86670e04feaedade3f4f626364bb5780a9e80577ae7a84471bbe16dd062135fd","schema_fingerprint":"4aa3821a28b0b7c2400bc59aba4bcc0a76e971dadd19610d3ad38c768e124dc7","schema_version":"edge-lab-recorder.raw.v1","sequence":null,"source":"clob_market_ws"}
{"event_at":"2026-07-28T04:12:06.724000Z","event_fingerprint":"aa39bf5ca51b7539f05ff93e2484e5cbdefb1cdc1520584bf336f641b9e170b9","payload":{"connection_id":"f6725804f86a4c4eb588e4d5ed7db029","event_at":"2026-07-28T04:12:06.724000Z","event_type":"price_change","frame_hash":"cfcba987d58a8d7884f347fc89bdc98208cddf0eb99ee58b28b2f9fcab94e6dc","frame_index":0,"kind":"data","monotonic_ns":313911469040416,"payload":{"event_type":"price_change","market":"0xd412ce774cfcf8dc9f71164aac78783978aac7b03871702a3b8a481bd9dc9688","price_changes":[{"asset_id":"107603864457683460275633293642179940881969192120168665300712204232021063124301","best_ask":"0.58","best_bid":"0.57","hash":"f0c91307cacb9af1a1c0a88fb05997c00bb80549","price":"0.01","side":"BUY","size":"5335.02"},{"asset_id":"96600821790790307414914106093858868634329285205417149685270682748367152458577","best_ask":"0.43","best_bid":"0.42","hash":"b562da20debc87915ccaf0f732c505b036669a8e","price":"0.99","side":"SELL","size":"5335.02"}],"timestamp":"1785211926724"},"payload_hash":"e0ff0f40d94f25858607c874d5ea50111abf40822db45513121002c1bbbb9364","raw_frame":"{\"market\":\"0xd412ce774cfcf8dc9f71164aac78783978aac7b03871702a3b8a481bd9dc9688\", \"price_changes\":[{\"asset_id\":\"107603864457683460275633293642179940881969192120168665300712204232021063124301\", \"price\":\"0.01\", \"size\":\"5335.02\", \"side\":\"BUY\", \"hash\":\"f0c91307cacb9af1a1c0a88fb05997c00bb80549\", \"best_bid\":\"0.57\", \"best_ask\":\"0.58\"}, {\"asset_id\":\"96600821790790307414914106093858868634329285205417149685270682748367152458577\", \"price\":\"0.99\", \"size\":\"5335.02\", \"side\":\"SELL\", \"hash\":\"b562da20debc87915ccaf0f732c505b036669a8e\", \"best_bid\":\"0.42\", \"best_ask\":\"0.43\"}], \"timestamp\":\"1785211926724\", \"event_type\":\"price_change\"}","received_at":"2026-07-28T04:12:08.391855Z","schema_version":"clob-market-ws.price_change.v1","sequence":null,"server_hash":null,"server_timestamp":"1785211926724","session_id":"2d607381e3054cee91998cdf45a4231c","source":"clob_market_ws"},"received_at":"2026-07-28T04:12:08.391855Z","record_id":"a24574222d7eae5af8de3e00acbd8da758039db6d60b90b6f908bad3b0c3a317","schema_fingerprint":"4aa3821a28b0b7c2400bc59aba4bcc0a76e971dadd19610d3ad38c768e124dc7","schema_version":"edge-lab-recorder.raw.v1","sequence":null,"source":"clob_market_ws"}
{"event_at":"2026-07-28T04:12:06.749000Z","event_fingerprint":"7d702f9043953001d3872d722e677cc708538ad6194ef3cc72cadd97d76a047e","payload":{"connection_id":"f6725804f86a4c4eb588e4d5ed7db029","event_at":"2026-07-28T04:12:06.749000Z","event_type":"price_change","frame_hash":"f10a5f17cb7994e7e022b0089a5ae8a85938b6a4544c25241b580fe373840efa","frame_index":0,"kind":"data","monotonic_ns":313911473997916,"payload":{"event_type":"price_change","market":"0xd412ce774cfcf8dc9f71164aac78783978aac7b03871702a3b8a481bd9dc9688","price_changes":[{"asset_id":"107603864457683460275633293642179940881969192120168665300712204232021063124301","best_ask":"0.58","best_bid":"0.57","hash":"356dd03bbf33059968732572262365acfc12b8be","price":"0.02","side":"BUY","size":"530"},{"asset_id":"96600821790790307414914106093858868634329285205417149685270682748367152458577","best_ask":"0.43","best_bid":"0.42","hash":"374f1a0ba3afb19b5340243b2a402cd7f32dbb0b","price":"0.98","side":"SELL","size":"530"}],"timestamp":"1785211926749"},"payload_hash":"252d9215695fa35b600ca4c251e5982cce781281106c809e300b468505fa4e43","raw_frame":"{\"market\":\"0xd412ce774cfcf8dc9f71164aac78783978aac7b03871702a3b8a481bd9dc9688\", \"price_changes\":[{\"asset_id\":\"107603864457683460275633293642179940881969192120168665300712204232021063124301\", \"price\":\"0.02\", \"size\":\"530\", \"side\":\"BUY\", \"hash\":\"356dd03bbf33059968732572262365acfc12b8be\", \"best_bid\":\"0.57\", \"best_ask\":\"0.58\"}, {\"asset_id\":\"96600821790790307414914106093858868634329285205417149685270682748367152458577\", \"price\":\"0.98\", \"size\":\"530\", \"side\":\"SELL\", \"hash\":\"374f1a0ba3afb19b5340243b2a402cd7f32dbb0b\", \"best_bid\":\"0.42\", \"best_ask\":\"0.43\"}], \"timestamp\":\"1785211926749\", \"event_type\":\"price_change\"}","received_at":"2026-07-28T04:12:08.396813Z","schema_version":"clob-market-ws.price_change.v1","sequence":null,"server_hash":null,"server_timestamp":"1785211926749","session_id":"2d607381e3054cee91998cdf45a4231c","source":"clob_market_ws"},"received_at":"2026-07-28T04:12:08.396813Z","record_id":"0cd3b8719771fe3f63af82f245abfbf06b197c6105e8ddab1b05e08090524d18","schema_fingerprint":"4aa3821a28b0b7c2400bc59aba4bcc0a76e971dadd19610d3ad38c768e124dc7","schema_version":"edge-lab-recorder.raw.v1","sequence":null,"source":"clob_market_ws"}
{"event_at":"2026-07-28T04:12:06.751000Z","event_fingerprint":"8280d8e54c337be3918dea3aa94ddb53bc865dc18202c8da15ae99bd6fc73ddd","payload":{"connection_id":"f6725804f86a4c4eb588e4d5ed7db029","event_at":"2026-07-28T04:12:06.751000Z","event_type":"price_change","frame_hash":"e6fb0be13439a3c5a02efaef0bfbe6b355813db4eface758f90864091cc9a9e8","frame_index":0,"kind":"data","monotonic_ns":313911478268916,"payload":{"event_type":"price_change","market":"0xd412ce774cfcf8dc9f71164aac78783978aac7b03871702a3b8a481bd9dc9688","price_changes":[{"asset_id":"107603864457683460275633293642179940881969192120168665300712204232021063124301","best_ask":"0.58","best_bid":"0.57","hash":"da91d0e969ceb9e88031883895930a16ed5f2fb0","price":"0.01","side":"BUY","size":"5330.02"},{"asset_id":"96600821790790307414914106093858868634329285205417149685270682748367152458577","best_ask":"0.43","best_bid":"0.42","hash":"4dad1e1be3402687af18ed9f5b91a9ff126aa432","price":"0.99","side":"SELL","size":"5330.02"}],"timestamp":"1785211926751"},"payload_hash":"c7c7652d536b50d1f55b9c38be6ee8513a6c78b29e21b5e9a59d5c74e2a139c2","raw_frame":"{\"market\":\"0xd412ce774cfcf8dc9f71164aac78783978aac7b03871702a3b8a481bd9dc9688\", \"price_changes\":[{\"asset_id\":\"107603864457683460275633293642179940881969192120168665300712204232021063124301\", \"price\":\"0.01\", \"size\":\"5330.02\", \"side\":\"BUY\", \"hash\":\"da91d0e969ceb9e88031883895930a16ed5f2fb0\", \"best_bid\":\"0.57\", \"best_ask\":\"0.58\"}, {\"asset_id\":\"96600821790790307414914106093858868634329285205417149685270682748367152458577\", \"price\":\"0.99\", \"size\":\"5330.02\", \"side\":\"SELL\", \"hash\":\"4dad1e1be3402687af18ed9f5b91a9ff126aa432\", \"best_bid\":\"0.42\", \"best_ask\":\"0.43\"}], \"timestamp\":\"1785211926751\", \"event_type\":\"price_change\"}","received_at":"2026-07-28T04:12:08.401084Z","schema_version":"clob-market-ws.price_change.v1","sequence":null,"server_hash":null,"server_timestamp":"1785211926751","session_id":"2d607381e3054cee91998cdf45a4231c","source":"clob_market_ws"},"received_at":"2026-07-28T04:12:08.401084Z","record_id":"eddecba3cb64b2e3a1e1b5b8af770f4dc63767912bfc709ed4dd0922a53ffca3","schema_fingerprint":"4aa3821a28b0b7c2400bc59aba4bcc0a76e971dadd19610d3ad38c768e124dc7","schema_version":"edge-lab-recorder.raw.v1","sequence":null,"source":"clob_market_ws"}
{"event_at":"2026-07-28T04:12:06.785000Z","event_fingerprint":"35b5b64598061f23971d7deb90308ae5a2d4f0d37ad3c9552d01413135d6d645","payload":{"connection_id":"f6725804f86a4c4eb588e4d5ed7db029","event_at":"2026-07-28T04:12:06.785000Z","event_type":"price_change","frame_hash":"c2602f685bc5e90fa95a973dedcd527612f75df2e330928be66d051de4d919ab","frame_index":0,"kind":"data","monotonic_ns":313911482560208,"payload":{"event_type":"price_change","market":"0xd412ce774cfcf8dc9f71164aac78783978aac7b03871702a3b8a481bd9dc9688","price_changes":[{"asset_id":"96600821790790307414914106093858868634329285205417149685270682748367152458577","best_ask":"0.43","best_bid":"0.42","hash":"efebf41198660856a6351423e3ab2ad2247127c7","price":"0.36","side":"BUY","size":"107"},{"asset_id":"107603864457683460275633293642179940881969192120168665300712204232021063124301","best_ask":"0.58","best_bid":"0.57","hash":"428d363fe516034d033f74392acc02d913d7a4a0","price":"0.64","side":"SELL","size":"107"}],"timestamp":"1785211926785"},"payload_hash":"4481ee8e8a89c44bda1fab31809afeb5f3e2e54ce32f99fd95d01a3b589fd6ff","raw_frame":"{\"market\":\"0xd412ce774cfcf8dc9f71164aac78783978aac7b03871702a3b8a481bd9dc9688\", \"price_changes\":[{\"asset_id\":\"96600821790790307414914106093858868634329285205417149685270682748367152458577\", \"price\":\"0.36\", \"size\":\"107\", \"side\":\"BUY\", \"hash\":\"efebf41198660856a6351423e3ab2ad2247127c7\", \"best_bid\":\"0.42\", \"best_ask\":\"0.43\"}, {\"asset_id\":\"107603864457683460275633293642179940881969192120168665300712204232021063124301\", \"price\":\"0.64\", \"size\":\"107\", \"side\":\"SELL\", \"hash\":\"428d363fe516034d033f74392acc02d913d7a4a0\", \"best_bid\":\"0.57\", \"best_ask\":\"0.58\"}], \"timestamp\":\"1785211926785\", \"event_type\":\"price_change\"}","received_at":"2026-07-28T04:12:08.405375Z","schema_version":"clob-market-ws.price_change.v1","sequence":null,"server_hash":null,"server_timestamp":"1785211926785","session_id":"2d607381e3054cee91998cdf45a4231c","source":"clob_market_ws"},"received_at":"2026-07-28T04:12:08.405375Z","record_id":"cbbe1615d276a1113fe374054134c780c10ab651530f8439890759c4af1a4c61","schema_fingerprint":"4aa3821a28b0b7c2400bc59aba4bcc0a76e971dadd19610d3ad38c768e124dc7","schema_version":"edge-lab-recorder.raw.v1","sequence":null,"source":"clob_market_ws"}
{"event_at":"2026-07-28T04:12:06.787000Z","event_fingerprint":"38241af36af0274def911c017712a47001adc25664351a2c6c6bbd1dda7dc3b2","payload":{"connection_id":"f6725804f86a4c4eb588e4d5ed7db029","event_at":"2026-07-28T04:12:06.787000Z","event_type":"price_change","frame_hash":"623e63638afff55b1e49efa7629f60d699c4ea7b90b0f285cc1ea1c727494fe5","frame_index":0,"kind":"data","monotonic_ns":313911486772375,"payload":{"event_type":"price_change","market":"0xd412ce774cfcf8dc9f71164aac78783978aac7b03871702a3b8a481bd9dc9688","price_changes":[{"asset_id":"107603864457683460275633293642179940881969192120168665300712204232021063124301","best_ask":"0.58","best_bid":"0.57","hash":"5f88f57824df3623630fbf68872fc09465b63d31","price":"0.64","side":"SELL","size":"151"},{"asset_id":"96600821790790307414914106093858868634329285205417149685270682748367152458577","best_ask":"0.43","best_bid":"0.42","hash":"0b612114d60fa33b23801ca2b2ebaf89f26e833d","price":"0.36","side":"BUY","size":"151"}],"timestamp":"1785211926787"},"payload_hash":"3d45f46bcea8681b12b6d809e0d17aa8724b3e26c7411a523ca7a9ae738a2601","raw_frame":"{\"market\":\"0xd412ce774cfcf8dc9f71164aac78783978aac7b03871702a3b8a481bd9dc9688\", \"price_changes\":[{\"asset_id\":\"107603864457683460275633293642179940881969192120168665300712204232021063124301\", \"price\":\"0.64\", \"size\":\"151\", \"side\":\"SELL\", \"hash\":\"5f88f57824df3623630fbf68872fc09465b63d31\", \"best_bid\":\"0.57\", \"best_ask\":\"0.58\"}, {\"asset_id\":\"96600821790790307414914106093858868634329285205417149685270682748367152458577\", \"price\":\"0.36\", \"size\":\"151\", \"side\":\"BUY\", \"hash\":\"0b612114d60fa33b23801ca2b2ebaf89f26e833d\", \"best_bid\":\"0.42\", \"best_ask\":\"0.43\"}], \"timestamp\":\"1785211926787\", \"event_type\":\"price_change\"}","received_at":"2026-07-28T04:12:08.409588Z","schema_version":"clob-market-ws.price_change.v1","sequence":null,"server_hash":null,"server_timestamp":"1785211926787","session_id":"2d607381e3054cee91998cdf45a4231c","source":"clob_market_ws"},"received_at":"2026-07-28T04:12:08.409588Z","record_id":"02a822b3b632f6ba3fc059c135c91423c2378747d04d44f783e0c5e1a8bec8e3","schema_fingerprint":"4aa3821a28b0b7c2400bc59aba4bcc0a76e971dadd19610d3ad38c768e124dc7","schema_version":"edge-lab-recorder.raw.v1","sequence":null,"source":"clob_market_ws"}
{"event_at":"2026-07-28T04:12:06.798000Z","event_fingerprint":"ebf2893c79fcb05f81d29a3eadf27edf5678ab7077451209ca8732856559c8b5","payload":{"connection_id":"f6725804f86a4c4eb588e4d5ed7db029","event_at":"2026-07-28T04:12:06.798000Z","event_type":"price_change","frame_hash":"7ca9bff015607972ad00e94b377e5ad2acad95cd61ac35cdc28e22c29109d535","frame_index":0,"kind":"data","monotonic_ns":313911491149833,"payload":{"event_type":"price_change","market":"0xd412ce774cfcf8dc9f71164aac78783978aac7b03871702a3b8a481bd9dc9688","price_changes":[{"asset_id":"107603864457683460275633293642179940881969192120168665300712204232021063124301","best_ask":"0.58","best_bid":"0.57","hash":"252e0d3cc6d91e4a8e878239d6b27bce80172f73","price":"0.65","side":"SELL","size":"90.97"},{"asset_id":"96600821790790307414914106093858868634329285205417149685270682748367152458577","best_ask":"0.43","best_bid":"0.42","hash":"d13d82bc4ae1cb28809d4627fe84a5f5f4350cb9","price":"0.35","side":"BUY","size":"90.97"}],"timestamp":"1785211926798"},"payload_hash":"9e4997f18bd87f8d5f222b2e37435db9d6d6f814ad6a605571401f479db65bda","raw_frame":"{\"market\":\"0xd412ce774cfcf8dc9f71164aac78783978aac7b03871702a3b8a481bd9dc9688\", \"price_changes\":[{\"asset_id\":\"107603864457683460275633293642179940881969192120168665300712204232021063124301\", \"price\":\"0.65\", \"size\":\"90.97\", \"side\":\"SELL\", \"hash\":\"252e0d3cc6d91e4a8e878239d6b27bce80172f73\", \"best_bid\":\"0.57\", \"best_ask\":\"0.58\"}, {\"asset_id\":\"96600821790790307414914106093858868634329285205417149685270682748367152458577\", \"price\":\"0.35\", \"size\":\"90.97\", \"side\":\"BUY\", \"hash\":\"d13d82bc4ae1cb28809d4627fe84a5f5f4350cb9\", \"best_bid\":\"0.42\", \"best_ask\":\"0.43\"}], \"timestamp\":\"1785211926798\", \"event_type\":\"price_change\"}","received_at":"2026-07-28T04:12:08.413965Z","schema_version":"clob-market-ws.price_change.v1","sequence":null,"server_hash":null,"server_timestamp":"1785211926798","session_id":"2d607381e3054cee91998cdf45a4231c","source":"clob_market_ws"},"received_at":"2026-07-28T04:12:08.413965Z","record_id":"7d95bd0fb14f79b558449b32acaacd0a44b82925386892427e5dc4cf969329b3","schema_fingerprint":"4aa3821a28b0b7c2400bc59aba4bcc0a76e971dadd19610d3ad38c768e124dc7","schema_version":"edge-lab-recorder.raw.v1","sequence":null,"source":"clob_market_ws"}
{"event_at":"2026-07-28T04:12:06.810000Z","event_fingerprint":"0f700d8fb82321986cefa382fa52cca19da65995db89990b225754ebc9c68730","payload":{"connection_id":"f6725804f86a4c4eb588e4d5ed7db029","event_at":"2026-07-28T04:12:06.810000Z","event_type":"price_change","frame_hash":"8f530b18bd8d53bdab976506349484c846c3aea8d86880012334ccb287724fdc","frame_index":0,"kind":"data","monotonic_ns":313911494033875,"payload":{"event_type":"price_change","market":"0xd412ce774cfcf8dc9f71164aac78783978aac7b03871702a3b8a481bd9dc9688","price_changes":[{"asset_id":"96600821790790307414914106093858868634329285205417149685270682748367152458577","best_ask":"0.43","best_bid":"0.42","hash":"c257f73aea241558c0bfb9d188411f426cba6329","price":"0.41","side":"BUY","size":"19"},{"asset_id":"107603864457683460275633293642179940881969192120168665300712204232021063124301","best_ask":"0.58","best_bid":"0.57","hash":"c1653a6fabc5f1a5df5eee5fb78fb320c1e831c6","price":"0.59","side":"SELL","size":"19"}],"timestamp":"1785211926810"},"payload_hash":"e97cf445fa3ee9f5ff543b001a945f068cc6acb3ac52a7a7d20d5668a1bebe6b","raw_frame":"{\"market\":\"0xd412ce774cfcf8dc9f71164aac78783978aac7b03871702a3b8a481bd9dc9688\", \"price_changes\":[{\"asset_id\":\"96600821790790307414914106093858868634329285205417149685270682748367152458577\", \"price\":\"0.41\", \"size\":\"19\", \"side\":\"BUY\", \"hash\":\"c257f73aea241558c0bfb9d188411f426cba6329\", \"best_bid\":\"0.42\", \"best_ask\":\"0.43\"}, {\"asset_id\":\"107603864457683460275633293642179940881969192120168665300712204232021063124301\", \"price\":\"0.59\", \"size\":\"19\", \"side\":\"SELL\", \"hash\":\"c1653a6fabc5f1a5df5eee5fb78fb320c1e831c6\", \"best_bid\":\"0.57\", \"best_ask\":\"0.58\"}], \"timestamp\":\"1785211926810\", \"event_type\":\"price_change\"}","received_at":"2026-07-28T04:12:08.416846Z","schema_version":"clob-market-ws.price_change.v1","sequence":null,"server_hash":null,"server_timestamp":"1785211926810","session_id":"2d607381e3054cee91998cdf45a4231c","source":"clob_market_ws"},"received_at":"2026-07-28T04:12:08.416846Z","record_id":"0fb525dd40b302e29cd8974f3a9f9ff264c49f8b8159eb4b5a49b26170bfda54","schema_fingerprint":"4aa3821a28b0b7c2400bc59aba4bcc0a76e971dadd19610d3ad38c768e124dc7","schema_version":"edge-lab-recorder.raw.v1","sequence":null,"source":"clob_market_ws"}
{"event_at":"2026-07-28T04:12:06.815000Z","event_fingerprint":"a2347007f4e21d882d07bd6aa3bcff2339c276ab28551ea0b7609cadd6de9e9d","payload":{"connection_id":"f6725804f86a4c4eb588e4d5ed7db029","event_at":"2026-07-28T04:12:06.815000Z","event_type":"price_change","frame_hash":"d581ddd2d378eb164f2a47ad91331eb2350a169802b8258fd12ff3b59d4944b6","frame_index":0,"kind":"data","monotonic_ns":313911497706375,"payload":{"event_type":"price_change","market":"0xd412ce774cfcf8dc9f71164aac78783978aac7b03871702a3b8a481bd9dc9688","price_changes":[{"asset_id":"107603864457683460275633293642179940881969192120168665300712204232021063124301","best_ask":"0.58","best_bid":"0.57","hash":"450609033cc5e52d93b2e6e072512386950879e8","price":"0.01","side":"BUY","size":"5335.02"},{"asset_id":"96600821790790307414914106093858868634329285205417149685270682748367152458577","best_ask":"0.43","best_bid":"0.42","hash":"0ee364c33599af1679dc64b41414f46b25023b0b","price":"0.99","side":"SELL","size":"5335.02"}],"timestamp":"1785211926815"},"payload_hash":"230db906362d149e030e538a1e8207ed0a3f7809469b02cbb3a7d0358748a2ff","raw_frame":"{\"market\":\"0xd412ce774cfcf8dc9f71164aac78783978aac7b03871702a3b8a481bd9dc9688\", \"price_changes\":[{\"asset_id\":\"107603864457683460275633293642179940881969192120168665300712204232021063124301\", \"price\":\"0.01\", \"size\":\"5335.02\", \"side\":\"BUY\", \"hash\":\"450609033cc5e52d93b2e6e072512386950879e8\", \"best_bid\":\"0.57\", \"best_ask\":\"0.58\"}, {\"asset_id\":\"96600821790790307414914106093858868634329285205417149685270682748367152458577\", \"price\":\"0.99\", \"size\":\"5335.02\", \"side\":\"SELL\", \"hash\":\"0ee364c33599af1679dc64b41414f46b25023b0b\", \"best_bid\":\"0.42\", \"best_ask\":\"0.43\"}], \"timestamp\":\"1785211926815\", \"event_type\":\"price_change\"}","received_at":"2026-07-28T04:12:08.420522Z","schema_version":"clob-market-ws.price_change.v1","sequence":null,"server_hash":null,"server_timestamp":"1785211926815","session_id":"2d607381e3054cee91998cdf45a4231c","source":"clob_market_ws"},"received_at":"2026-07-28T04:12:08.420522Z","record_id":"58a9f83e1f3758f3136f13e20e34c625df62e8c1bed1c0b6d513dfc97567aa0d","schema_fingerprint":"4aa3821a28b0b7c2400bc59aba4bcc0a76e971dadd19610d3ad38c768e124dc7","schema_version":"edge-lab-recorder.raw.v1","sequence":null,"source":"clob_market_ws"}
{"event_at":"2026-07-28T04:12:06.835000Z","event_fingerprint":"d9a8ab6e21a30b8915166cf9957b6da52ee41eff4637511d944e8b887aa056c2","payload":{"connection_id":"f6725804f86a4c4eb588e4d5ed7db029","event_at":"2026-07-28T04:12:06.835000Z","event_type":"price_change","frame_hash":"cb2bb239ad8f5bdd735b7325b45836ae44151edbb6e91bf7edf159adb2fb975d","frame_index":0,"kind":"data","monotonic_ns":313911501847666,"payload":{"event_type":"price_change","market":"0xd412ce774cfcf8dc9f71164aac78783978aac7b03871702a3b8a481bd9dc9688","price_changes":[{"asset_id":"107603864457683460275633293642179940881969192120168665300712204232021063124301","best_ask":"0.58","best_bid":"0.57","hash":"d98eba8a1013f82d6144187608e3ce32a60150d3","price":"0.01","side":"BUY","size":"5330.02"},{"asset_id":"96600821790790307414914106093858868634329285205417149685270682748367152458577","best_ask":"0.43","best_bid":"0.42","hash":"a32e67248b08e5a2ba92b1312cca225e96f07ccd","price":"0.99","side":"SELL","size":"5330.02"}],"timestamp":"1785211926835"},"payload_hash":"e6bb5f27ba6dadcbb0f18d1e6295ac6bd5f6ac10db07c4f6cf2c933fb5e5f99e","raw_frame":"{\"market\":\"0xd412ce774cfcf8dc9f71164aac78783978aac7b03871702a3b8a481bd9dc9688\", \"price_changes\":[{\"asset_id\":\"107603864457683460275633293642179940881969192120168665300712204232021063124301\", \"price\":\"0.01\", \"size\":\"5330.02\", \"side\":\"BUY\", \"hash\":\"d98eba8a1013f82d6144187608e3ce32a60150d3\", \"best_bid\":\"0.57\", \"best_ask\":\"0.58\"}, {\"asset_id\":\"96600821790790307414914106093858868634329285205417149685270682748367152458577\", \"price\":\"0.99\", \"size\":\"5330.02\", \"side\":\"SELL\", \"hash\":\"a32e67248b08e5a2ba92b1312cca225e96f07ccd\", \"best_bid\":\"0.42\", \"best_ask\":\"0.43\"}], \"timestamp\":\"1785211926835\", \"event_type\":\"price_change\"}","received_at":"2026-07-28T04:12:08.424663Z","schema_version":"clob-market-ws.price_change.v1","sequence":null,"server_hash":null,"server_timestamp":"1785211926835","session_id":"2d607381e3054cee91998cdf45a4231c","source":"clob_market_ws"},"received_at":"2026-07-28T04:12:08.424663Z","record_id":"ee0bcc72241c0abb65103ab86d163028797cf5f4429b146fade6730bda8a2fe8","schema_fingerprint":"4aa3821a28b0b7c2400bc59aba4bcc0a76e971dadd19610d3ad38c768e124dc7","schema_version":"edge-lab-recorder.raw.v1","sequence":null,"source":"clob_market_ws"}
{"event_at":"2026-07-28T04:12:06.843000Z","event_fingerprint":"711caef04c255cdfc9209202f606290a09f4cec793688faf9b0cc2c4e7009ed5","payload":{"connection_id":"f6725804f86a4c4eb588e4d5ed7db029","event_at":"2026-07-28T04:12:06.843000Z","event_type":"price_change","frame_hash":"4fdd924304b39fea1ad5237c00e86bb99875a1f0532537628a3047cb897985d0","frame_index":0,"kind":"data","monotonic_ns":313911506066708,"payload":{"event_type":"price_change","market":"0xd412ce774cfcf8dc9f71164aac78783978aac7b03871702a3b8a481bd9dc9688","price_changes":[{"asset_id":"107603864457683460275633293642179940881969192120168665300712204232021063124301","best_ask":"0.58","best_bid":"0.57","hash":"ccf05dae75b0a17708d8f18f6f49db4973378239","price":"0.56","side":"BUY","size":"48.6"},{"asset_id":"96600821790790307414914106093858868634329285205417149685270682748367152458577","best_ask":"0.43","best_bid":"0.42","hash":"300212ee89342b7063eb1f6dcecbb06e735f6444","price":"0.44","side":"SELL","size":"48.6"}],"timestamp":"1785211926843"},"payload_hash":"9151b45d0bd9d491a30751ea836dcaa8a0fd0a915fba15f60a35ad8bebf74ddd","raw_frame":"{\"market\":\"0xd412ce774cfcf8dc9f71164aac78783978aac7b03871702a3b8a481bd9dc9688\", \"price_changes\":[{\"asset_id\":\"107603864457683460275633293642179940881969192120168665300712204232021063124301\", \"price\":\"0.56\", \"size\":\"48.6\", \"side\":\"BUY\", \"hash\":\"ccf05dae75b0a17708d8f18f6f49db4973378239\", \"best_bid\":\"0.57\", \"best_ask\":\"0.58\"}, {\"asset_id\":\"96600821790790307414914106093858868634329285205417149685270682748367152458577\", \"price\":\"0.44\", \"size\":\"48.6\", \"side\":\"SELL\", \"hash\":\"300212ee89342b7063eb1f6dcecbb06e735f6444\", \"best_bid\":\"0.42\", \"best_ask\":\"0.43\"}], \"timestamp\":\"1785211926843\", \"event_type\":\"price_change\"}","received_at":"2026-07-28T04:12:08.428882Z","schema_version":"clob-market-ws.price_change.v1","sequence":null,"server_hash":null,"server_timestamp":"1785211926843","session_id":"2d607381e3054cee91998cdf45a4231c","source":"clob_market_ws"},"received_at":"2026-07-28T04:12:08.428882Z","record_id":"e4a9a5b21269c10c9b2e2d138903901040c6ec4ad8d2b9ec4efcc569b375eb35","schema_fingerprint":"4aa3821a28b0b7c2400bc59aba4bcc0a76e971dadd19610d3ad38c768e124dc7","schema_version":"edge-lab-recorder.raw.v1","sequence":null,"source":"clob_market_ws"}
{"event_at":"2026-07-28T04:12:06.848000Z","event_fingerprint":"aa1875ea9fff9817c6bb31f50da87efbf1f83e998df29a209aa80b8a6f952d99","payload":{"connection_id":"f6725804f86a4c4eb588e4d5ed7db029","event_at":"2026-07-28T04:12:06.848000Z","event_type":"price_change","frame_hash":"53e3011aa3b6ce918580dd384ee6facd625da2cbb82ab1f6e53f1192aa945b07","frame_index":0,"kind":"data","monotonic_ns":313911510308083,"payload":{"event_type":"price_change","market":"0xd412ce774cfcf8dc9f71164aac78783978aac7b03871702a3b8a481bd9dc9688","price_changes":[{"asset_id":"107603864457683460275633293642179940881969192120168665300712204232021063124301","best_ask":"0.58","best_bid":"0.57","hash":"5cd963648ed8e36c897db67b9cfb2f42b4a900e9","price":"0.04","side":"BUY","size":"545"},{"asset_id":"96600821790790307414914106093858868634329285205417149685270682748367152458577","best_ask":"0.43","best_bid":"0.42","hash":"c38e5d8a9a69069d764c4966ab08383336b4ed79","price":"0.96","side":"SELL","size":"545"}],"timestamp":"1785211926848"},"payload_hash":"d68c962654219ba259f42e5a55d70c1ceb07c641b0cf5020edfaf45f03ef7d4a","raw_frame":"{\"market\":\"0xd412ce774cfcf8dc9f71164aac78783978aac7b03871702a3b8a481bd9dc9688\", \"price_changes\":[{\"asset_id\":\"107603864457683460275633293642179940881969192120168665300712204232021063124301\", \"price\":\"0.04\", \"size\":\"545\", \"side\":\"BUY\", \"hash\":\"5cd963648ed8e36c897db67b9cfb2f42b4a900e9\", \"best_bid\":\"0.57\", \"best_ask\":\"0.58\"}, {\"asset_id\":\"96600821790790307414914106093858868634329285205417149685270682748367152458577\", \"price\":\"0.96\", \"size\":\"545\", \"side\":\"SELL\", \"hash\":\"c38e5d8a9a69069d764c4966ab08383336b4ed79\", \"best_bid\":\"0.42\", \"best_ask\":\"0.43\"}], \"timestamp\":\"1785211926848\", \"event_type\":\"price_change\"}","received_at":"2026-07-28T04:12:08.433123Z","schema_version":"clob-market-ws.price_change.v1","sequence":null,"server_hash":null,"server_timestamp":"1785211926848","session_id":"2d607381e3054cee91998cdf45a4231c","source":"clob_market_ws"},"received_at":"2026-07-28T04:12:08.433123Z","record_id":"9de3c808362d61dc3484a06a6b5339df312b355a0624e646700daf4e9e18c225","schema_fingerprint":"4aa3821a28b0b7c2400bc59aba4bcc0a76e971dadd19610d3ad38c768e124dc7","schema_version":"edge-lab-recorder.raw.v1","sequence":null,"source":"clob_market_ws"}
{"event_at":"2026-07-28T04:12:06.882000Z","event_fingerprint":"cdb8726ab41005c83bcd78f1da43b76fb58efbadd3ecb8b92f0c6063d5c02610","payload":{"connection_id":"f6725804f86a4c4eb588e4d5ed7db029","event_at":"2026-07-28T04:12:06.882000Z","event_type":"price_change","frame_hash":"193faed04aa08b44a61568cc3a54c783f009b71f5a2556105766c83c8d281869","frame_index":0,"kind":"data","monotonic_ns":313911514489750,"payload":{"event_type":"price_change","market":"0xd412ce774cfcf8dc9f71164aac78783978aac7b03871702a3b8a481bd9dc9688","price_changes":[{"asset_id":"107603864457683460275633293642179940881969192120168665300712204232021063124301","best_ask":"0.58","best_bid":"0.57","hash":"296243843bb5937916f0a77468a44429e7088e5c","price":"0.36","side":"BUY","size":"5"},{"asset_id":"96600821790790307414914106093858868634329285205417149685270682748367152458577","best_ask":"0.43","best_bid":"0.42","hash":"e5e7f7d1be78eacc5c3d9016a29ace715b2b5e0d","price":"0.64","side":"SELL","size":"5"}],"timestamp":"1785211926882"},"payload_hash":"283923de167cdc12d04f7c101af7c16005bbb39705419119dc7c28eaf2fd141c","raw_frame":"{\"market\":\"0xd412ce774cfcf8dc9f71164aac78783978aac7b03871702a3b8a481bd9dc9688\", \"price_changes\":[{\"asset_id\":\"107603864457683460275633293642179940881969192120168665300712204232021063124301\", \"price\":\"0.36\", \"size\":\"5\", \"side\":\"BUY\", \"hash\":\"296243843bb5937916f0a77468a44429e7088e5c\", \"best_bid\":\"0.57\", \"best_ask\":\"0.58\"}, {\"asset_id\":\"96600821790790307414914106093858868634329285205417149685270682748367152458577\", \"price\":\"0.64\", \"size\":\"5\", \"side\":\"SELL\", \"hash\":\"e5e7f7d1be78eacc5c3d9016a29ace715b2b5e0d\", \"best_bid\":\"0.42\", \"best_ask\":\"0.43\"}], \"timestamp\":\"1785211926882\", \"event_type\":\"price_change\"}","received_at":"2026-07-28T04:12:08.437305Z","schema_version":"clob-market-ws.price_change.v1","sequence":null,"server_hash":null,"server_timestamp":"1785211926882","session_id":"2d607381e3054cee91998cdf45a4231c","source":"clob_market_ws"},"received_at":"2026-07-28T04:12:08.437305Z","record_id":"73222a27691dd1b89a0550abef496f8d0fa30dc6a314d9dde555d11ffe28e524","schema_fingerprint":"4aa3821a28b0b7c2400bc59aba4bcc0a76e971dadd19610d3ad38c768e124dc7","schema_version":"edge-lab-recorder.raw.v1","sequence":null,"source":"clob_market_ws"}
{"event_at":"2026-07-28T04:12:06.891000Z","event_fingerprint":"2abc624d9ac4dc1774221c1c61c88dcf09bd7907e916409ae7c02604cad323de","payload":{"connection_id":"f6725804f86a4c4eb588e4d5ed7db029","event_at":"2026-07-28T04:12:06.891000Z","event_type":"price_change","frame_hash":"922d81cbf77b4961d79e24684bb8f51e969a907f66226ea97cd776d07d2f9330","frame_index":0,"kind":"data","monotonic_ns":313911518711458,"payload":{"event_type":"price_change","market":"0xd412ce774cfcf8dc9f71164aac78783978aac7b03871702a3b8a481bd9dc9688","price_changes":[{"asset_id":"107603864457683460275633293642179940881969192120168665300712204232021063124301","best_ask":"0.58","best_bid":"0.57","hash":"4782a92767f298518964b2b3c0eee27c9b4e897d","price":"0.64","side":"SELL","size":"107"},{"asset_id":"96600821790790307414914106093858868634329285205417149685270682748367152458577","best_ask":"0.43","best_bid":"0.42","hash":"c4a1d0008bba8af708fb6d14c282d3203aa07c2e","price":"0.36","side":"BUY","size":"107"}],"timestamp":"1785211926891"},"payload_hash":"34e58721fc224c883f9c5d55451f1d46b669fc948aa41c61506d4b4d1359d0a2","raw_frame":"{\"market\":\"0xd412ce774cfcf8dc9f71164aac78783978aac7b03871702a3b8a481bd9dc9688\", \"price_changes\":[{\"asset_id\":\"107603864457683460275633293642179940881969192120168665300712204232021063124301\", \"price\":\"0.64\", \"size\":\"107\", \"side\":\"SELL\", \"hash\":\"4782a92767f298518964b2b3c0eee27c9b4e897d\", \"best_bid\":\"0.57\", \"best_ask\":\"0.58\"}, {\"asset_id\":\"96600821790790307414914106093858868634329285205417149685270682748367152458577\", \"price\":\"0.36\", \"size\":\"107\", \"side\":\"BUY\", \"hash\":\"c4a1d0008bba8af708fb6d14c282d3203aa07c2e\", \"best_bid\":\"0.42\", \"best_ask\":\"0.43\"}], \"timestamp\":\"1785211926891\", \"event_type\":\"price_change\"}","received_at":"2026-07-28T04:12:08.441527Z","schema_version":"clob-market-ws.price_change.v1","sequence":null,"server_hash":null,"server_timestamp":"1785211926891","session_id":"2d607381e3054cee91998cdf45a4231c","source":"clob_market_ws"},"received_at":"2026-07-28T04:12:08.441527Z","record_id":"61500dd1e7c66bdfd0547b93551e09c9f93d825fad03c1af9f3ee301bce54a45","schema_fingerprint":"4aa3821a28b0b7c2400bc59aba4bcc0a76e971dadd19610d3ad38c768e124dc7","schema_version":"edge-lab-recorder.raw.v1","sequence":null,"source":"clob_market_ws"}
{"event_at":"2026-07-28T04:12:06.895000Z","event_fingerprint":"c96cf0b5c2efd29eae330b5458c967c82a29efbc67643e1bb44e8c600cf19449","payload":{"connection_id":"f6725804f86a4c4eb588e4d5ed7db029","event_at":"2026-07-28T04:12:06.895000Z","event_type":"price_change","frame_hash":"dda21493e171e7a3903a7b35b50044fb1a57e8db87adb38dbf45d87213bd42fd","frame_index":0,"kind":"data","monotonic_ns":313911522888083,"payload":{"event_type":"price_change","market":"0xd412ce774cfcf8dc9f71164aac78783978aac7b03871702a3b8a481bd9dc9688","price_changes":[{"asset_id":"107603864457683460275633293642179940881969192120168665300712204232021063124301","best_ask":"0.58","best_bid":"0.57","hash":"9bbbcfc6598938e52e9ad8515c0c4ac439874e7c","price":"0.65","side":"SELL","size":"81"},{"asset_id":"96600821790790307414914106093858868634329285205417149685270682748367152458577","best_ask":"0.43","best_bid":"0.42","hash":"9d114b9176ce9b9a9e218a2a1ca93fcd220c5f39","price":"0.35","side":"BUY","size":"81"}],"timestamp":"1785211926895"},"payload_hash":"bc8888ba88e5deb2d37aa3b4ca7a418a6163b6ac0bf1d9e52484b3313dd3c326","raw_frame":"{\"market\":\"0xd412ce774cfcf8dc9f71164aac78783978aac7b03871702a3b8a481bd9dc9688\", \"price_changes\":[{\"asset_id\":\"107603864457683460275633293642179940881969192120168665300712204232021063124301\", \"price\":\"0.65\", \"size\":\"81\", \"side\":\"SELL\", \"hash\":\"9bbbcfc6598938e52e9ad8515c0c4ac439874e7c\", \"best_bid\":\"0.57\", \"best_ask\":\"0.58\"}, {\"asset_id\":\"96600821790790307414914106093858868634329285205417149685270682748367152458577\", \"price\":\"0.35\", \"size\":\"81\", \"side\":\"BUY\", \"hash\":\"9d114b9176ce9b9a9e218a2a1ca93fcd220c5f39\", \"best_bid\":\"0.42\", \"best_ask\":\"0.43\"}], \"timestamp\":\"1785211926895\", \"event_type\":\"price_change\"}","received_at":"2026-07-28T04:12:08.445703Z","schema_version":"clob-market-ws.price_change.v1","sequence":null,"server_hash":null,"server_timestamp":"1785211926895","session_id":"2d607381e3054cee91998cdf45a4231c","source":"clob_market_ws"},"received_at":"2026-07-28T04:12:08.445703Z","record_id":"53556712949091f9f5463323637631bc5f0087e8dd2d86db2237cd60791808d5","schema_fingerprint":"4aa3821a28b0b7c2400bc59aba4bcc0a76e971dadd19610d3ad38c768e124dc7","schema_version":"edge-lab-recorder.raw.v1","sequence":null,"source":"clob_market_ws"}
{"event_at":"2026-07-28T04:12:06.903000Z","event_fingerprint":"b4b6772298119bc3b11f8bbed0fd0a03365685ace60942b9a3a08c0c704cc067","payload":{"connection_id":"f6725804f86a4c4eb588e4d5ed7db029","event_at":"2026-07-28T04:12:06.903000Z","event_type":"price_change","frame_hash":"8f40a924ae40e5ef13b5bb1d16dda04be05588b92cdbe630aebc4c3ad674965e","frame_index":0,"kind":"data","monotonic_ns":313911527082916,"payload":{"event_type":"price_change","market":"0xd412ce774cfcf8dc9f71164aac78783978aac7b03871702a3b8a481bd9dc9688","price_changes":[{"asset_id":"107603864457683460275633293642179940881969192120168665300712204232021063124301","best_ask":"0.58","best_bid":"0.57","hash":"6b9062a0b0ac776d151a4be8ddc8b71e8353a3c9","price":"0.04","side":"BUY","size":"540"},{"asset_id":"96600821790790307414914106093858868634329285205417149685270682748367152458577","best_ask":"0.43","best_bid":"0.42","hash":"e9dbcf3dd3a86d9e4d7d88caaa6ffb23d5c49aba","price":"0.96","side":"SELL","size":"540"}],"timestamp":"1785211926903"},"payload_hash":"1546f96f0a435782606ea4553f4cfa8a0c4a2790153a7d7b51a3675521062128","raw_frame":"{\"market\":\"0xd412ce774cfcf8dc9f71164aac78783978aac7b03871702a3b8a481bd9dc9688\", \"price_changes\":[{\"asset_id\":\"107603864457683460275633293642179940881969192120168665300712204232021063124301\", \"price\":\"0.04\", \"size\":\"540\", \"side\":\"BUY\", \"hash\":\"6b9062a0b0ac776d151a4be8ddc8b71e8353a3c9\", \"best_bid\":\"0.57\", \"best_ask\":\"0.58\"}, {\"asset_id\":\"96600821790790307414914106093858868634329285205417149685270682748367152458577\", \"price\":\"0.96\", \"size\":\"540\", \"side\":\"SELL\", \"hash\":\"e9dbcf3dd3a86d9e4d7d88caaa6ffb23d5c49aba\", \"best_bid\":\"0.42\", \"best_ask\":\"0.43\"}], \"timestamp\":\"1785211926903\", \"event_type\":\"price_change\"}","received_at":"2026-07-28T04:12:08.449898Z","schema_version":"clob-market-ws.price_change.v1","sequence":null,"server_hash":null,"server_timestamp":"1785211926903","session_id":"2d607381e3054cee91998cdf45a4231c","source":"clob_market_ws"},"received_at":"2026-07-28T04:12:08.449898Z","record_id":"703d8ada8113a76802398abc19b29804e7d20b30f1cf1f2a145ef8e216bd4228","schema_fingerprint":"4aa3821a28b0b7c2400bc59aba4bcc0a76e971dadd19610d3ad38c768e124dc7","schema_version":"edge-lab-recorder.raw.v1","sequence":null,"source":"clob_market_ws"}
{"event_at":"2026-07-28T04:12:06.907000Z","event_fingerprint":"30a009674f1a1defea1d207e44f0970b50a1dd064fd47a1be913ab4ee8bcc22b","payload":{"connection_id":"f6725804f86a4c4eb588e4d5ed7db029","event_at":"2026-07-28T04:12:06.907000Z","event_type":"price_change","frame_hash":"a8f8707dfe996e93fe3d1a1c0428171ab18fe0060cd051c1ba810de6197d90bb","frame_index":0,"kind":"data","monotonic_ns":313911532228375,"payload":{"event_type":"price_change","market":"0xd412ce774cfcf8dc9f71164aac78783978aac7b03871702a3b8a481bd9dc9688","price_changes":[{"asset_id":"96600821790790307414914106093858868634329285205417149685270682748367152458577","best_ask":"0.43","best_bid":"0.42","hash":"52489a7f29cb3234c54d91e9ca551c918608ff5a","price":"0.36","side":"BUY","size":"154"},{"asset_id":"107603864457683460275633293642179940881969192120168665300712204232021063124301","best_ask":"0.58","best_bid":"0.57","hash":"08f3340ec4cc88ee7db697d7538ad9171708c911","price":"0.64","side":"SELL","size":"154"}],"timestamp":"1785211926907"},"payload_hash":"752dfdb61bb872d36148dc8bd2d1e94326e20d31289fae8e32551ab2ddcc651e","raw_frame":"{\"market\":\"0xd412ce774cfcf8dc9f71164aac78783978aac7b03871702a3b8a481bd9dc9688\", \"price_changes\":[{\"asset_id\":\"96600821790790307414914106093858868634329285205417149685270682748367152458577\", \"price\":\"0.36\", \"size\":\"154\", \"side\":\"BUY\", \"hash\":\"52489a7f29cb3234c54d91e9ca551c918608ff5a\", \"best_bid\":\"0.42\", \"best_ask\":\"0.43\"}, {\"asset_id\":\"107603864457683460275633293642179940881969192120168665300712204232021063124301\", \"price\":\"0.64\", \"size\":\"154\", \"side\":\"SELL\", \"hash\":\"08f3340ec4cc88ee7db697d7538ad9171708c911\", \"best_bid\":\"0.57\", \"best_ask\":\"0.58\"}], \"timestamp\":\"1785211926907\", \"event_type\":\"price_change\"}","received_at":"2026-07-28T04:12:08.455043Z","schema_version":"clob-market-ws.price_change.v1","sequence":null,"server_hash":null,"server_timestamp":"1785211926907","session_id":"2d607381e3054cee91998cdf45a4231c","source":"clob_market_ws"},"received_at":"2026-07-28T04:12:08.455043Z","record_id":"ada8c957994642255714e8696e1666e14130eb4f213adf18cd518648b3343bb1","schema_fingerprint":"4aa3821a28b0b7c2400bc59aba4bcc0a76e971dadd19610d3ad38c768e124dc7","schema_version":"edge-lab-recorder.raw.v1","sequence":null,"source":"clob_market_ws"}
{"event_at":"2026-07-28T04:12:06.944000Z","event_fingerprint":"5fe75063173d3ecd5e0369004124cf96e80d3c1d421542c61d36a844189f3a01","payload":{"connection_id":"f6725804f86a4c4eb588e4d5ed7db029","event_at":"2026-07-28T04:12:06.944000Z","event_type":"price_change","frame_hash":"b443dfb2bcbc343c89d5d8cf27e0c46c127a56e5e24638b7fac523515ee4cd2f","frame_index":0,"kind":"data","monotonic_ns":313911536563916,"payload":{"event_type":"price_change","market":"0xd412ce774cfcf8dc9f71164aac78783978aac7b03871702a3b8a481bd9dc9688","price_changes":[{"asset_id":"107603864457683460275633293642179940881969192120168665300712204232021063124301","best_ask":"0.58","best_bid":"0.57","hash":"1210e15f1605efd8f4870fda187d6770febcfac3","price":"0.38","side":"BUY","size":"30"},{"asset_id":"96600821790790307414914106093858868634329285205417149685270682748367152458577","best_ask":"0.43","best_bid":"0.42","hash":"5733396284dd6792cade3d0d37391260cbffa23d","price":"0.62","side":"SELL","size":"30"}],"timestamp":"1785211926944"},"payload_hash":"a8a405a2a3ec76be409c35ee5b41ec387f5d1646085cf00e27ae04d9a0caa3fc","raw_frame":"{\"market\":\"0xd412ce774cfcf8dc9f71164aac78783978aac7b03871702a3b8a481bd9dc9688\", \"price_changes\":[{\"asset_id\":\"107603864457683460275633293642179940881969192120168665300712204232021063124301\", \"price\":\"0.38\", \"size\":\"30\", \"side\":\"BUY\", \"hash\":\"1210e15f1605efd8f4870fda187d6770febcfac3\", \"best_bid\":\"0.57\", \"best_ask\":\"0.58\"}, {\"asset_id\":\"96600821790790307414914106093858868634329285205417149685270682748367152458577\", \"price\":\"0.62\", \"size\":\"30\", \"side\":\"SELL\", \"hash\":\"5733396284dd6792cade3d0d37391260cbffa23d\", \"best_bid\":\"0.42\", \"best_ask\":\"0.43\"}], \"timestamp\":\"1785211926944\", \"event_type\":\"price_change\"}","received_at":"2026-07-28T04:12:08.459378Z","schema_version":"clob-market-ws.price_change.v1","sequence":null,"server_hash":null,"server_timestamp":"1785211926944","session_id":"2d607381e3054cee91998cdf45a4231c","source":"clob_market_ws"},"received_at":"2026-07-28T04:12:08.459378Z","record_id":"e24f7b9207f3251e42b137eaa81fab4fc36e7e660135a4dcf817d604ea9a5bac","schema_fingerprint":"4aa3821a28b0b7c2400bc59aba4bcc0a76e971dadd19610d3ad38c768e124dc7","schema_version":"edge-lab-recorder.raw.v1","sequence":null,"source":"clob_market_ws"}
{"event_at":"2026-07-28T04:12:06.954000Z","event_fingerprint":"9678a4bb0d2467b46b7b66be507513f732ec90ffda7e43ad7648280dd4e79b02","payload":{"connection_id":"f6725804f86a4c4eb588e4d5ed7db029","event_at":"2026-07-28T04:12:06.954000Z","event_type":"price_change","frame_hash":"b09d218795ae948b8bffd68884f15ba0f5ca5ebea4196b65cb3f77874a7de5ab","frame_index":0,"kind":"data","monotonic_ns":313911540721875,"payload":{"event_type":"price_change","market":"0xd412ce774cfcf8dc9f71164aac78783978aac7b03871702a3b8a481bd9dc9688","price_changes":[{"asset_id":"96600821790790307414914106093858868634329285205417149685270682748367152458577","best_ask":"0.43","best_bid":"0.42","hash":"3f311d3a13dff2a0c64eea7fe06207746aa39ef2","price":"0.31","side":"BUY","size":"95"},{"asset_id":"107603864457683460275633293642179940881969192120168665300712204232021063124301","best_ask":"0.58","best_bid":"0.57","hash":"5f11f22013b677a94063ee62d67856f77c67fcfa","price":"0.69","side":"SELL","size":"95"}],"timestamp":"1785211926954"},"payload_hash":"d9c51339acd10cd5b06979fb9300f8636a335ca7c338ec1815c36eae8a1cc5b4","raw_frame":"{\"market\":\"0xd412ce774cfcf8dc9f71164aac78783978aac7b03871702a3b8a481bd9dc9688\", \"price_changes\":[{\"asset_id\":\"96600821790790307414914106093858868634329285205417149685270682748367152458577\", \"price\":\"0.31\", \"size\":\"95\", \"side\":\"BUY\", \"hash\":\"3f311d3a13dff2a0c64eea7fe06207746aa39ef2\", \"best_bid\":\"0.42\", \"best_ask\":\"0.43\"}, {\"asset_id\":\"107603864457683460275633293642179940881969192120168665300712204232021063124301\", \"price\":\"0.69\", \"size\":\"95\", \"side\":\"SELL\", \"hash\":\"5f11f22013b677a94063ee62d67856f77c67fcfa\", \"best_bid\":\"0.57\", \"best_ask\":\"0.58\"}], \"timestamp\":\"1785211926954\", \"event_type\":\"price_change\"}","received_at":"2026-07-28T04:12:08.463537Z","schema_version":"clob-market-ws.price_change.v1","sequence":null,"server_hash":null,"server_timestamp":"1785211926954","session_id":"2d607381e3054cee91998cdf45a4231c","source":"clob_market_ws"},"received_at":"2026-07-28T04:12:08.463537Z","record_id":"f517717186eb7d69147ccc0f62acc0ec2aed6847e86f3ccad85b70cf22771b05","schema_fingerprint":"4aa3821a28b0b7c2400bc59aba4bcc0a76e971dadd19610d3ad38c768e124dc7","schema_version":"edge-lab-recorder.raw.v1","sequence":null,"source":"clob_market_ws"}
{"event_at":"2026-07-28T04:12:06.970000Z","event_fingerprint":"eba9bd82ce7563cac20a6d57099242c2415470930730f95b37527fc9e6925a4d","payload":{"connection_id":"f6725804f86a4c4eb588e4d5ed7db029","event_at":"2026-07-28T04:12:06.970000Z","event_type":"price_change","frame_hash":"a77f97467a9077b00af582641840a4000775bd58ed7a012f7516a2ac9f46faf5","frame_index":0,"kind":"data","monotonic_ns":313911543558083,"payload":{"event_type":"price_change","market":"0xd412ce774cfcf8dc9f71164aac78783978aac7b03871702a3b8a481bd9dc9688","price_changes":[{"asset_id":"107603864457683460275633293642179940881969192120168665300712204232021063124301","best_ask":"0.58","best_bid":"0.57","hash":"e03ecdc227377b204da2fc6720c14699a343efdc","price":"0.39","side":"BUY","size":"30"},{"asset_id":"96600821790790307414914106093858868634329285205417149685270682748367152458577","best_ask":"0.43","best_bid":"0.42","hash":"1466766b55363dd851d96e99987f8a4b88cbb758","price":"0.61","side":"SELL","size":"30"}],"timestamp":"1785211926970"},"payload_hash":"be1a59c026e67cdf6486a0324294222cd4278924dee810e23e3d073de33b375d","raw_frame":"{\"market\":\"0xd412ce774cfcf8dc9f71164aac78783978aac7b03871702a3b8a481bd9dc9688\", \"price_changes\":[{\"asset_id\":\"107603864457683460275633293642179940881969192120168665300712204232021063124301\", \"price\":\"0.39\", \"size\":\"30\", \"side\":\"BUY\", \"hash\":\"e03ecdc227377b204da2fc6720c14699a343efdc\", \"best_bid\":\"0.57\", \"best_ask\":\"0.58\"}, {\"asset_id\":\"96600821790790307414914106093858868634329285205417149685270682748367152458577\", \"price\":\"0.61\", \"size\":\"30\", \"side\":\"SELL\", \"hash\":\"1466766b55363dd851d96e99987f8a4b88cbb758\", \"best_bid\":\"0.42\", \"best_ask\":\"0.43\"}], \"timestamp\":\"1785211926970\", \"event_type\":\"price_change\"}","received_at":"2026-07-28T04:12:08.466373Z","schema_version":"clob-market-ws.price_change.v1","sequence":null,"server_hash":null,"server_timestamp":"1785211926970","session_id":"2d607381e3054cee91998cdf45a4231c","source":"clob_market_ws"},"received_at":"2026-07-28T04:12:08.466373Z","record_id":"a253b360e7ed022990cc6ce85dfdba796bc06dadd992da2382bd5359c07b5956","schema_fingerprint":"4aa3821a28b0b7c2400bc59aba4bcc0a76e971dadd19610d3ad38c768e124dc7","schema_version":"edge-lab-recorder.raw.v1","sequence":null,"source":"clob_market_ws"}
{"event_at":"2026-07-28T04:12:06.976000Z","event_fingerprint":"3eaf7e9a313f9a80e50b917ff68af22da3922402d65f13cb0056c3a7f88d9029","payload":{"connection_id":"f6725804f86a4c4eb588e4d5ed7db029","event_at":"2026-07-28T04:12:06.976000Z","event_type":"price_change","frame_hash":"24df994ad20a0e7e36dd264cb82ac0540486b26ee399a62e2ef014cc40ac0962","frame_index":0,"kind":"data","monotonic_ns":313911546534125,"payload":{"event_type":"price_change","market":"0xd412ce774cfcf8dc9f71164aac78783978aac7b03871702a3b8a481bd9dc9688","price_changes":[{"asset_id":"96600821790790307414914106093858868634329285205417149685270682748367152458577","best_ask":"0.43","best_bid":"0.42","hash":"e516cd44d676970f73047e180543b9cafd723d8c","price":"0.61","side":"SELL","size":"5"},{"asset_id":"107603864457683460275633293642179940881969192120168665300712204232021063124301","best_ask":"0.58","best_bid":"0.57","hash":"4f9a40f4b610ae5606b51101c46f8bd8a069cacc","price":"0.39","side":"BUY","size":"5"}],"timestamp":"1785211926976"},"payload_hash":"89b10f668cb9a0ef4055bbfa5a9efd680c4fd2831e806e66a21a049295df3092","raw_frame":"{\"market\":\"0xd412ce774cfcf8dc9f71164aac78783978aac7b03871702a3b8a481bd9dc9688\", \"price_changes\":[{\"asset_id\":\"96600821790790307414914106093858868634329285205417149685270682748367152458577\", \"price\":\"0.61\", \"size\":\"5\", \"side\":\"SELL\", \"hash\":\"e516cd44d676970f73047e180543b9cafd723d8c\", \"best_bid\":\"0.42\", \"best_ask\":\"0.43\"}, {\"asset_id\":\"107603864457683460275633293642179940881969192120168665300712204232021063124301\", \"price\":\"0.39\", \"size\":\"5\", \"side\":\"BUY\", \"hash\":\"4f9a40f4b610ae5606b51101c46f8bd8a069cacc\", \"best_bid\":\"0.57\", \"best_ask\":\"0.58\"}], \"timestamp\":\"1785211926976\", \"event_type\":\"price_change\"}","received_at":"2026-07-28T04:12:08.469349Z","schema_version":"clob-market-ws.price_change.v1","sequence":null,"server_hash":null,"server_timestamp":"1785211926976","session_id":"2d607381e3054cee91998cdf45a4231c","source":"clob_market_ws"},"received_at":"2026-07-28T04:12:08.469349Z","record_id":"e4bdd50503aeb7d456b480034d449743bc6b7ed1ff67b16314caba0be924bb3a","schema_fingerprint":"4aa3821a28b0b7c2400bc59aba4bcc0a76e971dadd19610d3ad38c768e124dc7","schema_version":"edge-lab-recorder.raw.v1","sequence":null,"source":"clob_market_ws"}
{"event_at":"2026-07-28T04:12:06.987000Z","event_fingerprint":"453a8c947e34b28186ed0cb5d0613dd83ef40c070084fceca80f7851fa419583","payload":{"connection_id":"f6725804f86a4c4eb588e4d5ed7db029","event_at":"2026-07-28T04:12:06.987000Z","event_type":"price_change","frame_hash":"126ed37a64c20890f4d1c949fc210c8c50792b141837d41a6d7e5ef5be04bf35","frame_index":0,"kind":"data","monotonic_ns":313911550797541,"payload":{"event_type":"price_change","market":"0xd412ce774cfcf8dc9f71164aac78783978aac7b03871702a3b8a481bd9dc9688","price_changes":[{"asset_id":"107603864457683460275633293642179940881969192120168665300712204232021063124301","best_ask":"0.58","best_bid":"0.57","hash":"7c33d0de066629b5afd00e60e75b339fb462837d","price":"0.02","side":"BUY","size":"535"},{"asset_id":"96600821790790307414914106093858868634329285205417149685270682748367152458577","best_ask":"0.43","best_bid":"0.42","hash":"a073222884b3ea71d8f738a2206231c73ddcf8f1","price":"0.98","side":"SELL","size":"535"}],"timestamp":"1785211926987"},"payload_hash":"0a7541558e6e57b44b15ca78d1d975c57f2f20de34846e9a4efc563b29f3a860","raw_frame":"{\"market\":\"0xd412ce774cfcf8dc9f71164aac78783978aac7b03871702a3b8a481bd9dc9688\", \"price_changes\":[{\"asset_id\":\"107603864457683460275633293642179940881969192120168665300712204232021063124301\", \"price\":\"0.02\", \"size\":\"535\", \"side\":\"BUY\", \"hash\":\"7c33d0de066629b5afd00e60e75b339fb462837d\", \"best_bid\":\"0.57\", \"best_ask\":\"0.58\"}, {\"asset_id\":\"96600821790790307414914106093858868634329285205417149685270682748367152458577\", \"price\":\"0.98\", \"size\":\"535\", \"side\":\"SELL\", \"hash\":\"a073222884b3ea71d8f738a2206231c73ddcf8f1\", \"best_bid\":\"0.42\", \"best_ask\":\"0.43\"}], \"timestamp\":\"1785211926987\", \"event_type\":\"price_change\"}","received_at":"2026-07-28T04:12:08.473612Z","schema_version":"clob-market-ws.price_change.v1","sequence":null,"server_hash":null,"server_timestamp":"1785211926987","session_id":"2d607381e3054cee91998cdf45a4231c","source":"clob_market_ws"},"received_at":"2026-07-28T04:12:08.473612Z","record_id":"d8f064c1720f5fd0676aa0d0d55612439700e192866d21f7196485b8d142bb20","schema_fingerprint":"4aa3821a28b0b7c2400bc59aba4bcc0a76e971dadd19610d3ad38c768e124dc7","schema_version":"edge-lab-recorder.raw.v1","sequence":null,"source":"clob_market_ws"}
{"event_at":"2026-07-28T04:12:06.992000Z","event_fingerprint":"dc1c526b155f96756fa358778847f21298f73e027009a02e89c106eb15ec2d27","payload":{"connection_id":"f6725804f86a4c4eb588e4d5ed7db029","event_at":"2026-07-28T04:12:06.992000Z","event_type":"price_change","frame_hash":"bb6858ba8a6b74c0fdc711efd2bef5cc1f8d6a69f30a376afe1080922e4fdc14","frame_index":0,"kind":"data","monotonic_ns":313911554983541,"payload":{"event_type":"price_change","market":"0xd412ce774cfcf8dc9f71164aac78783978aac7b03871702a3b8a481bd9dc9688","price_changes":[{"asset_id":"107603864457683460275633293642179940881969192120168665300712204232021063124301","best_ask":"0.58","best_bid":"0.57","hash":"7550ac859eba41afd50968d6d771725c3358e1a1","price":"0.33","side":"BUY","size":"34.36"},{"asset_id":"96600821790790307414914106093858868634329285205417149685270682748367152458577","best_ask":"0.43","best_bid":"0.42","hash":"7ed0b1138402048cbbeaf27325e3db7bd380149a","price":"0.67","side":"SELL","size":"34.36"}],"timestamp":"1785211926992"},"payload_hash":"56717989231bf87615ad0610e68172bb7e12f92d51e028afd8bd61d297c11fdc","raw_frame":"{\"market\":\"0xd412ce774cfcf8dc9f71164aac78783978aac7b03871702a3b8a481bd9dc9688\", \"price_changes\":[{\"asset_id\":\"107603864457683460275633293642179940881969192120168665300712204232021063124301\", \"price\":\"0.33\", \"size\":\"34.36\", \"side\":\"BUY\", \"hash\":\"7550ac859eba41afd50968d6d771725c3358e1a1\", \"best_bid\":\"0.57\", \"best_ask\":\"0.58\"}, {\"asset_id\":\"96600821790790307414914106093858868634329285205417149685270682748367152458577\", \"price\":\"0.67\", \"size\":\"34.36\", \"side\":\"SELL\", \"hash\":\"7ed0b1138402048cbbeaf27325e3db7bd380149a\", \"best_bid\":\"0.42\", \"best_ask\":\"0.43\"}], \"timestamp\":\"1785211926992\", \"event_type\":\"price_change\"}","received_at":"2026-07-28T04:12:08.477796Z","schema_version":"clob-market-ws.price_change.v1","sequence":null,"server_hash":null,"server_timestamp":"1785211926992","session_id":"2d607381e3054cee91998cdf45a4231c","source":"clob_market_ws"},"received_at":"2026-07-28T04:12:08.477796Z","record_id":"38b5699e00741cfbf304d9e9f35866d831ef2254f362e8b6e15bdb6f0f1400a3","schema_fingerprint":"4aa3821a28b0b7c2400bc59aba4bcc0a76e971dadd19610d3ad38c768e124dc7","schema_version":"edge-lab-recorder.raw.v1","sequence":null,"source":"clob_market_ws"}
{"event_at":"2026-07-28T04:12:06.995000Z","event_fingerprint":"65dd90a7fbb8bd0ad0127c626792955fd8fe56f8dfdd3390585a3489c54d3a5c","payload":{"connection_id":"f6725804f86a4c4eb588e4d5ed7db029","event_at":"2026-07-28T04:12:06.995000Z","event_type":"price_change","frame_hash":"f2ccb15088f64a96fb7460d1eecd84ac8240aa6e092dc937e10d023af866209f","frame_index":0,"kind":"data","monotonic_ns":313911559449416,"payload":{"event_type":"price_change","market":"0xd412ce774cfcf8dc9f71164aac78783978aac7b03871702a3b8a481bd9dc9688","price_changes":[{"asset_id":"107603864457683460275633293642179940881969192120168665300712204232021063124301","best_ask":"0.58","best_bid":"0.57","hash":"73e5dfa77a86fde3f279a619a8953de6c6fcd990","price":"0.4","side":"BUY","size":"70.41"},{"asset_id":"96600821790790307414914106093858868634329285205417149685270682748367152458577","best_ask":"0.43","best_bid":"0.42","hash":"8535325527511a898ece3ef5dca46b51567d0dde","price":"0.6","side":"SELL","size":"70.41"}],"timestamp":"1785211926995"},"payload_hash":"d57c426dfceb3b03e930871f5718c63b1c02cc5c0acefbc94d0b5655e6ff58dc","raw_frame":"{\"market\":\"0xd412ce774cfcf8dc9f71164aac78783978aac7b03871702a3b8a481bd9dc9688\", \"price_changes\":[{\"asset_id\":\"107603864457683460275633293642179940881969192120168665300712204232021063124301\", \"price\":\"0.4\", \"size\":\"70.41\", \"side\":\"BUY\", \"hash\":\"73e5dfa77a86fde3f279a619a8953de6c6fcd990\", \"best_bid\":\"0.57\", \"best_ask\":\"0.58\"}, {\"asset_id\":\"96600821790790307414914106093858868634329285205417149685270682748367152458577\", \"price\":\"0.6\", \"size\":\"70.41\", \"side\":\"SELL\", \"hash\":\"8535325527511a898ece3ef5dca46b51567d0dde\", \"best_bid\":\"0.42\", \"best_ask\":\"0.43\"}], \"timestamp\":\"1785211926995\", \"event_type\":\"price_change\"}","received_at":"2026-07-28T04:12:08.482264Z","schema_version":"clob-market-ws.price_change.v1","sequence":null,"server_hash":null,"server_timestamp":"1785211926995","session_id":"2d607381e3054cee91998cdf45a4231c","source":"clob_market_ws"},"received_at":"2026-07-28T04:12:08.482264Z","record_id":"a4fa2237520290254f765e08a9fa3ef2bd5b70a503442d0da86d69540a431f2f","schema_fingerprint":"4aa3821a28b0b7c2400bc59aba4bcc0a76e971dadd19610d3ad38c768e124dc7","schema_version":"edge-lab-recorder.raw.v1","sequence":null,"source":"clob_market_ws"}
{"event_at":"2026-07-28T04:12:07.001000Z","event_fingerprint":"568265bf049b495f8e08314bccab7665437ae5ef357188ff67feb370a4ad9bf1","payload":{"connection_id":"f6725804f86a4c4eb588e4d5ed7db029","event_at":"2026-07-28T04:12:07.001000Z","event_type":"price_change","frame_hash":"0caa6411484b1acae5c70689baba973e34efad4a75b8559d745aef74971759e6","frame_index":0,"kind":"data","monotonic_ns":313911563733000,"payload":{"event_type":"price_change","market":"0xd412ce774cfcf8dc9f71164aac78783978aac7b03871702a3b8a481bd9dc9688","price_changes":[{"asset_id":"96600821790790307414914106093858868634329285205417149685270682748367152458577","best_ask":"0.43","best_bid":"0.42","hash":"7b6d4b1794254d162c4273c8ce86a3e2b5f135af","price":"0.6","side":"SELL","size":"95.41"},{"asset_id":"107603864457683460275633293642179940881969192120168665300712204232021063124301","best_ask":"0.58","best_bid":"0.57","hash":"793ebf5debd58dceeb54352e3a29ad295510c19a","price":"0.4","side":"BUY","size":"95.41"}],"timestamp":"1785211927001"},"payload_hash":"7cd248a7260a56548ddef99fe5a39db462856cf4d355dfdb47b6cbe99200a725","raw_frame":"{\"market\":\"0xd412ce774cfcf8dc9f71164aac78783978aac7b03871702a3b8a481bd9dc9688\", \"price_changes\":[{\"asset_id\":\"96600821790790307414914106093858868634329285205417149685270682748367152458577\", \"price\":\"0.6\", \"size\":\"95.41\", \"side\":\"SELL\", \"hash\":\"7b6d4b1794254d162c4273c8ce86a3e2b5f135af\", \"best_bid\":\"0.42\", \"best_ask\":\"0.43\"}, {\"asset_id\":\"107603864457683460275633293642179940881969192120168665300712204232021063124301\", \"price\":\"0.4\", \"size\":\"95.41\", \"side\":\"BUY\", \"hash\":\"793ebf5debd58dceeb54352e3a29ad295510c19a\", \"best_bid\":\"0.57\", \"best_ask\":\"0.58\"}], \"timestamp\":\"1785211927001\", \"event_type\":\"price_change\"}","received_at":"2026-07-28T04:12:08.486543Z","schema_version":"clob-market-ws.price_change.v1","sequence":null,"server_hash":null,"server_timestamp":"1785211927001","session_id":"2d607381e3054cee91998cdf45a4231c","source":"clob_market_ws"},"received_at":"2026-07-28T04:12:08.486543Z","record_id":"75d7f7143c856775d7a28c7d4773cb1ff2e16bf51d04cb04f54431983c347c8f","schema_fingerprint":"4aa3821a28b0b7c2400bc59aba4bcc0a76e971dadd19610d3ad38c768e124dc7","schema_version":"edge-lab-recorder.raw.v1","sequence":null,"source":"clob_market_ws"}
{"event_at":"2026-07-28T04:12:07.011000Z","event_fingerprint":"51d27c582596d42b829af452a990d599dd67a99bce6f5e16e62d81ca427fc6ff","payload":{"connection_id":"f6725804f86a4c4eb588e4d5ed7db029","event_at":"2026-07-28T04:12:07.011000Z","event_type":"price_change","frame_hash":"b1b210cd17cadb882b26fd9170868b535f762bd87b35108eb371a8ab181d31aa","frame_index":0,"kind":"data","monotonic_ns":313911565972166,"payload":{"event_type":"price_change","market":"0xd412ce774cfcf8dc9f71164aac78783978aac7b03871702a3b8a481bd9dc9688","price_changes":[{"asset_id":"107603864457683460275633293642179940881969192120168665300712204232021063124301","best_ask":"0.58","best_bid":"0.57","hash":"ae13e63b7e94d73fa82fa68f43ace36532cf864a","price":"0.35","side":"BUY","size":"15"},{"asset_id":"96600821790790307414914106093858868634329285205417149685270682748367152458577","best_ask":"0.43","best_bid":"0.42","hash":"3213bba9b403cbdc9207ebb7d2410412548f740a","price":"0.65","side":"SELL","size":"15"}],"timestamp":"1785211927011"},"payload_hash":"6cbda947474224fb33c3c5de2b5c2a50e9f4afe41c6bb0a2fa1574630c9613df","raw_frame":"{\"market\":\"0xd412ce774cfcf8dc9f71164aac78783978aac7b03871702a3b8a481bd9dc9688\", \"price_changes\":[{\"asset_id\":\"107603864457683460275633293642179940881969192120168665300712204232021063124301\", \"price\":\"0.35\", \"size\":\"15\", \"side\":\"BUY\", \"hash\":\"ae13e63b7e94d73fa82fa68f43ace36532cf864a\", \"best_bid\":\"0.57\", \"best_ask\":\"0.58\"}, {\"asset_id\":\"96600821790790307414914106093858868634329285205417149685270682748367152458577\", \"price\":\"0.65\", \"size\":\"15\", \"side\":\"SELL\", \"hash\":\"3213bba9b403cbdc9207ebb7d2410412548f740a\", \"best_bid\":\"0.42\", \"best_ask\":\"0.43\"}], \"timestamp\":\"1785211927011\", \"event_type\":\"price_change\"}","received_at":"2026-07-28T04:12:08.488787Z","schema_version":"clob-market-ws.price_change.v1","sequence":null,"server_hash":null,"server_timestamp":"1785211927011","session_id":"2d607381e3054cee91998cdf45a4231c","source":"clob_market_ws"},"received_at":"2026-07-28T04:12:08.488787Z","record_id":"38ddf7a4c7338a0f5a6f86075854d605887eb55782e08af2272ecf24e9a21e3c","schema_fingerprint":"4aa3821a28b0b7c2400bc59aba4bcc0a76e971dadd19610d3ad38c768e124dc7","schema_version":"edge-lab-recorder.raw.v1","sequence":null,"source":"clob_market_ws"}
{"event_at":"2026-07-28T04:12:07.024000Z","event_fingerprint":"8c02ab38d72d07078b5fbbe3f033dcfc0bcf287f9f52d97e7a04de309af06530","payload":{"connection_id":"f6725804f86a4c4eb588e4d5ed7db029","event_at":"2026-07-28T04:12:07.024000Z","event_type":"price_change","frame_hash":"3c67db8f2c1b62f94afb13c995bb0015163509df9585e966c18af6bb7ad01c12","frame_index":0,"kind":"data","monotonic_ns":313911573113208,"payload":{"event_type":"price_change","market":"0xd412ce774cfcf8dc9f71164aac78783978aac7b03871702a3b8a481bd9dc9688","price_changes":[{"asset_id":"96600821790790307414914106093858868634329285205417149685270682748367152458577","best_ask":"0.43","best_bid":"0.42","hash":"04b062090a6fb0f1aac9ea1c88c360a3a0ec405f","price":"0.36","side":"BUY","size":"107"},{"asset_id":"107603864457683460275633293642179940881969192120168665300712204232021063124301","best_ask":"0.58","best_bid":"0.57","hash":"38e74cfff7a8f93c26eb49dc239b1584e02f818f","price":"0.64","side":"SELL","size":"107"}],"timestamp":"1785211927024"},"payload_hash":"811d9b2b95a22d68649f6149dc97f652805eac3ce07a4c2eca3aeb09f623fb9b","raw_frame":"{\"market\":\"0xd412ce774cfcf8dc9f71164aac78783978aac7b03871702a3b8a481bd9dc9688\", \"price_changes\":[{\"asset_id\":\"96600821790790307414914106093858868634329285205417149685270682748367152458577\", \"price\":\"0.36\", \"size\":\"107\", \"side\":\"BUY\", \"hash\":\"04b062090a6fb0f1aac9ea1c88c360a3a0ec405f\", \"best_bid\":\"0.42\", \"best_ask\":\"0.43\"}, {\"asset_id\":\"107603864457683460275633293642179940881969192120168665300712204232021063124301\", \"price\":\"0.64\", \"size\":\"107\", \"side\":\"SELL\", \"hash\":\"38e74cfff7a8f93c26eb49dc239b1584e02f818f\", \"best_bid\":\"0.57\", \"best_ask\":\"0.58\"}], \"timestamp\":\"1785211927024\", \"event_type\":\"price_change\"}","received_at":"2026-07-28T04:12:08.495928Z","schema_version":"clob-market-ws.price_change.v1","sequence":null,"server_hash":null,"server_timestamp":"1785211927024","session_id":"2d607381e3054cee91998cdf45a4231c","source":"clob_market_ws"},"received_at":"2026-07-28T04:12:08.495928Z","record_id":"da38585a8728364b1234aedbb0479e46a448d36c65c890017be7d44046988fcb","schema_fingerprint":"4aa3821a28b0b7c2400bc59aba4bcc0a76e971dadd19610d3ad38c768e124dc7","schema_version":"edge-lab-recorder.raw.v1","sequence":null,"source":"clob_market_ws"}
{"event_at":"2026-07-28T04:12:07.025000Z","event_fingerprint":"75ea3a24996b807e5e0259038e91bc3dfb34e1df68a35e237680323ae240177b","payload":{"connection_id":"f6725804f86a4c4eb588e4d5ed7db029","event_at":"2026-07-28T04:12:07.025000Z","event_type":"price_change","frame_hash":"8116fd7cb14584349a91455c8d9e8bf4b452a3ffc6352a78425ddd2303d8d53d","frame_index":0,"kind":"data","monotonic_ns":313911576711958,"payload":{"event_type":"price_change","market":"0xd412ce774cfcf8dc9f71164aac78783978aac7b03871702a3b8a481bd9dc9688","price_changes":[{"asset_id":"96600821790790307414914106093858868634329285205417149685270682748367152458577","best_ask":"0.43","best_bid":"0.42","hash":"d9c0e916ccef5a9c4af55514a0fc584770ba8d2e","price":"0.01","side":"BUY","size":"5295.02"},{"asset_id":"107603864457683460275633293642179940881969192120168665300712204232021063124301","best_ask":"0.58","best_bid":"0.57","hash":"bcff03394ad231971f7a0679d2942f2d67e4202d","price":"0.99","side":"SELL","size":"5295.02"}],"timestamp":"1785211927025"},"payload_hash":"bd3af7a1427c7dd408dfef0a6b40b318aa8bf0e957f660931b41376adc79907f","raw_frame":"{\"market\":\"0xd412ce774cfcf8dc9f71164aac78783978aac7b03871702a3b8a481bd9dc9688\", \"price_changes\":[{\"asset_id\":\"96600821790790307414914106093858868634329285205417149685270682748367152458577\", \"price\":\"0.01\", \"size\":\"5295.02\", \"side\":\"BUY\", \"hash\":\"d9c0e916ccef5a9c4af55514a0fc584770ba8d2e\", \"best_bid\":\"0.42\", \"best_ask\":\"0.43\"}, {\"asset_id\":\"107603864457683460275633293642179940881969192120168665300712204232021063124301\", \"price\":\"0.99\", \"size\":\"5295.02\", \"side\":\"SELL\", \"hash\":\"bcff03394ad231971f7a0679d2942f2d67e4202d\", \"best_bid\":\"0.57\", \"best_ask\":\"0.58\"}], \"timestamp\":\"1785211927025\", \"event_type\":\"price_change\"}","received_at":"2026-07-28T04:12:08.499526Z","schema_version":"clob-market-ws.price_change.v1","sequence":null,"server_hash":null,"server_timestamp":"1785211927025","session_id":"2d607381e3054cee91998cdf45a4231c","source":"clob_market_ws"},"received_at":"2026-07-28T04:12:08.499526Z","record_id":"30504bdfb629ed9d3fc68a8cebe7f17a5b88b80ea5b0865d326f2279f3d0ecc7","schema_fingerprint":"4aa3821a28b0b7c2400bc59aba4bcc0a76e971dadd19610d3ad38c768e124dc7","schema_version":"edge-lab-recorder.raw.v1","sequence":null,"source":"clob_market_ws"}
{"event_at":"2026-07-28T04:12:07.026000Z","event_fingerprint":"27027e288333ea7b0ef0dc0894d16b86f8224a058a2c3e8f1088863dbe1616fd","payload":{"connection_id":"f6725804f86a4c4eb588e4d5ed7db029","event_at":"2026-07-28T04:12:07.026000Z","event_type":"price_change","frame_hash":"15dd0e348868dd1e292ef532e016e25fd9c781d214e4a972c4c4171b27cbe98f","frame_index":0,"kind":"data","monotonic_ns":313911580909458,"payload":{"event_type":"price_change","market":"0xd412ce774cfcf8dc9f71164aac78783978aac7b03871702a3b8a481bd9dc9688","price_changes":[{"asset_id":"96600821790790307414914106093858868634329285205417149685270682748367152458577","best_ask":"0.43","best_bid":"0.42","hash":"8b07f682973175993e570b7b322d2280232a6048","price":"0.01","side":"BUY","size":"5300.02"},{"asset_id":"107603864457683460275633293642179940881969192120168665300712204232021063124301","best_ask":"0.58","best_bid":"0.57","hash":"315be2921dfb73eef4c09f62c2792fa2bff8ac3b","price":"0.99","side":"SELL","size":"5300.02"}],"timestamp":"1785211927026"},"payload_hash":"e21debc7987308023d180354f505678fd807319d3095a5547fb409a34ba972b7","raw_frame":"{\"market\":\"0xd412ce774cfcf8dc9f71164aac78783978aac7b03871702a3b8a481bd9dc9688\", \"price_changes\":[{\"asset_id\":\"96600821790790307414914106093858868634329285205417149685270682748367152458577\", \"price\":\"0.01\", \"size\":\"5300.02\", \"side\":\"BUY\", \"hash\":\"8b07f682973175993e570b7b322d2280232a6048\", \"best_bid\":\"0.42\", \"best_ask\":\"0.43\"}, {\"asset_id\":\"107603864457683460275633293642179940881969192120168665300712204232021063124301\", \"price\":\"0.99\", \"size\":\"5300.02\", \"side\":\"SELL\", \"hash\":\"315be2921dfb73eef4c09f62c2792fa2bff8ac3b\", \"best_bid\":\"0.57\", \"best_ask\":\"0.58\"}], \"timestamp\":\"1785211927026\", \"event_type\":\"price_change\"}","received_at":"2026-07-28T04:12:08.503724Z","schema_version":"clob-market-ws.price_change.v1","sequence":null,"server_hash":null,"server_timestamp":"1785211927026","session_id":"2d607381e3054cee91998cdf45a4231c","source":"clob_market_ws"},"received_at":"2026-07-28T04:12:08.503724Z","record_id":"0ff9c5f251531db6e8c836af4868b1e3b6ad1b96131c460811f097ef458cf207","schema_fingerprint":"4aa3821a28b0b7c2400bc59aba4bcc0a76e971dadd19610d3ad38c768e124dc7","schema_version":"edge-lab-recorder.raw.v1","sequence":null,"source":"clob_market_ws"}
{"event_at":"2026-07-28T04:12:07.032000Z","event_fingerprint":"5e08041a27ee8a176c04713c9e0db41b3f25b4c0c5dfe10d2277bb2e762d01ba","payload":{"connection_id":"f6725804f86a4c4eb588e4d5ed7db029","event_at":"2026-07-28T04:12:07.032000Z","event_type":"price_change","frame_hash":"cea6c5406613d002a5759e6d14fece76527f3003e920ca74a64abbe4c02490dd","frame_index":0,"kind":"data","monotonic_ns":313911585130375,"payload":{"event_type":"price_change","market":"0xd412ce774cfcf8dc9f71164aac78783978aac7b03871702a3b8a481bd9dc9688","price_changes":[{"asset_id":"96600821790790307414914106093858868634329285205417149685270682748367152458577","best_ask":"0.43","best_bid":"0.42","hash":"9885828467f0e93cb1a1d4e1563a608fa71fc484","price":"0.35","side":"BUY","size":"68"},{"asset_id":"107603864457683460275633293642179940881969192120168665300712204232021063124301","best_ask":"0.58","best_bid":"0.57","hash":"c766de00a4a8c6f170e6cf8118adbfd5b76524aa","price":"0.65","side":"SELL","size":"68"}],"timestamp":"1785211927032"},"payload_hash":"04ca9a6e8cc23b56fa5aae6eced8403c6d6ed76895afeada937d785e098cd8f5","raw_frame":"{\"market\":\"0xd412ce774cfcf8dc9f71164aac78783978aac7b03871702a3b8a481bd9dc9688\", \"price_changes\":[{\"asset_id\":\"96600821790790307414914106093858868634329285205417149685270682748367152458577\", \"price\":\"0.35\", \"size\":\"68\", \"side\":\"BUY\", \"hash\":\"9885828467f0e93cb1a1d4e1563a608fa71fc484\", \"best_bid\":\"0.42\", \"best_ask\":\"0.43\"}, {\"asset_id\":\"107603864457683460275633293642179940881969192120168665300712204232021063124301\", \"price\":\"0.65\", \"size\":\"68\", \"side\":\"SELL\", \"hash\":\"c766de00a4a8c6f170e6cf8118adbfd5b76524aa\", \"best_bid\":\"0.57\", \"best_ask\":\"0.58\"}], \"timestamp\":\"1785211927032\", \"event_type\":\"price_change\"}","received_at":"2026-07-28T04:12:08.507944Z","schema_version":"clob-market-ws.price_change.v1","sequence":null,"server_hash":null,"server_timestamp":"1785211927032","session_id":"2d607381e3054cee91998cdf45a4231c","source":"clob_market_ws"},"received_at":"2026-07-28T04:12:08.507944Z","record_id":"acb5519559a1abe079434d8fcabd830f37998e5e727379caac4e07d880b2f8b2","schema_fingerprint":"4aa3821a28b0b7c2400bc59aba4bcc0a76e971dadd19610d3ad38c768e124dc7","schema_version":"edge-lab-recorder.raw.v1","sequence":null,"source":"clob_market_ws"}
{"event_at":"2026-07-28T04:12:07.033000Z","event_fingerprint":"5587b33b9ac4121ad24b6a8d4899207d6d33728726e4e74a8dfe9fb6a629015f","payload":{"connection_id":"f6725804f86a4c4eb588e4d5ed7db029","event_at":"2026-07-28T04:12:07.033000Z","event_type":"price_change","frame_hash":"9d9001af6c897922dabc549c2b697d3abf9c345aa25e9c54fb242b7b3784106c","frame_index":0,"kind":"data","monotonic_ns":313911589288208,"payload":{"event_type":"price_change","market":"0xd412ce774cfcf8dc9f71164aac78783978aac7b03871702a3b8a481bd9dc9688","price_changes":[{"asset_id":"107603864457683460275633293642179940881969192120168665300712204232021063124301","best_ask":"0.58","best_bid":"0.57","hash":"71da67fe75d2fffff796b5cba98b76b7b6fef3be","price":"0.65","side":"SELL","size":"77.97"},{"asset_id":"96600821790790307414914106093858868634329285205417149685270682748367152458577","best_ask":"0.43","best_bid":"0.42","hash":"fd9234b41a8efb17691cd1be6a8bd1b16e788c87","price":"0.35","side":"BUY","size":"77.97"}],"timestamp":"1785211927033"},"payload_hash":"01525355b956570d9ff0a5017817e03c408fc9d65d7939a8279d47d42b46ee84","raw_frame":"{\"market\":\"0xd412ce774cfcf8dc9f71164aac78783978aac7b03871702a3b8a481bd9dc9688\", \"price_changes\":[{\"asset_id\":\"107603864457683460275633293642179940881969192120168665300712204232021063124301\", \"price\":\"0.65\", \"size\":\"77.97\", \"side\":\"SELL\", \"hash\":\"71da67fe75d2fffff796b5cba98b76b7b6fef3be\", \"best_bid\":\"0.57\", \"best_ask\":\"0.58\"}, {\"asset_id\":\"96600821790790307414914106093858868634329285205417149685270682748367152458577\", \"price\":\"0.35\", \"size\":\"77.97\", \"side\":\"BUY\", \"hash\":\"fd9234b41a8efb17691cd1be6a8bd1b16e788c87\", \"best_bid\":\"0.42\", \"best_ask\":\"0.43\"}], \"timestamp\":\"1785211927033\", \"event_type\":\"price_change\"}","received_at":"2026-07-28T04:12:08.512103Z","schema_version":"clob-market-ws.price_change.v1","sequence":null,"server_hash":null,"server_timestamp":"1785211927033","session_id":"2d607381e3054cee91998cdf45a4231c","source":"clob_market_ws"},"received_at":"2026-07-28T04:12:08.512103Z","record_id":"ed82000952ca2614e0099ce038b2d50efccc27770b83edae8c234c2f9c67bf5f","schema_fingerprint":"4aa3821a28b0b7c2400bc59aba4bcc0a76e971dadd19610d3ad38c768e124dc7","schema_version":"edge-lab-recorder.raw.v1","sequence":null,"source":"clob_market_ws"}
{"event_at":"2026-07-28T04:12:07.035000Z","event_fingerprint":"d400c83087183c5038f9405e7cd5529d8cdc35907c769ab7a38b031e59a62a09","payload":{"connection_id":"f6725804f86a4c4eb588e4d5ed7db029","event_at":"2026-07-28T04:12:07.035000Z","event_type":"price_change","frame_hash":"2b91b30532a4fa28f6c96ea8e4f5cd4279ce61174a0d265b524dbcfeaee02497","frame_index":0,"kind":"data","monotonic_ns":313911593449208,"payload":{"event_type":"price_change","market":"0xd412ce774cfcf8dc9f71164aac78783978aac7b03871702a3b8a481bd9dc9688","price_changes":[{"asset_id":"107603864457683460275633293642179940881969192120168665300712204232021063124301","best_ask":"0.58","best_bid":"0.57","hash":"33f44cd0afeba6e64bf1805738d80b45f4632f95","price":"0.64","side":"SELL","size":"151"},{"asset_id":"96600821790790307414914106093858868634329285205417149685270682748367152458577","best_ask":"0.43","best_bid":"0.42","hash":"2934119f16d5692424da305f4bd7a7f70e87dbe9","price":"0.36","side":"BUY","size":"151"}],"timestamp":"1785211927035"},"payload_hash":"5cdaabfd79b738e0241ad89ad053f0369cebbde63f5c0f95ace694e96066b9f6","raw_frame":"{\"market\":\"0xd412ce774cfcf8dc9f71164aac78783978aac7b03871702a3b8a481bd9dc9688\", \"price_changes\":[{\"asset_id\":\"107603864457683460275633293642179940881969192120168665300712204232021063124301\", \"price\":\"0.64\", \"size\":\"151\", \"side\":\"SELL\", \"hash\":\"33f44cd0afeba6e64bf1805738d80b45f4632f95\", \"best_bid\":\"0.57\", \"best_ask\":\"0.58\"}, {\"asset_id\":\"96600821790790307414914106093858868634329285205417149685270682748367152458577\", \"price\":\"0.36\", \"size\":\"151\", \"side\":\"BUY\", \"hash\":\"2934119f16d5692424da305f4bd7a7f70e87dbe9\", \"best_bid\":\"0.42\", \"best_ask\":\"0.43\"}], \"timestamp\":\"1785211927035\", \"event_type\":\"price_change\"}","received_at":"2026-07-28T04:12:08.516263Z","schema_version":"clob-market-ws.price_change.v1","sequence":null,"server_hash":null,"server_timestamp":"1785211927035","session_id":"2d607381e3054cee91998cdf45a4231c","source":"clob_market_ws"},"received_at":"2026-07-28T04:12:08.516263Z","record_id":"fe12e2706e54e9d4a8bf0948a1d4c1f6823bfc006ae5c68174b00b7dbba464cd","schema_fingerprint":"4aa3821a28b0b7c2400bc59aba4bcc0a76e971dadd19610d3ad38c768e124dc7","schema_version":"edge-lab-recorder.raw.v1","sequence":null,"source":"clob_market_ws"}
{"event_at":"2026-07-28T04:12:07.038000Z","event_fingerprint":"55c876509ac1741dc3fc725470d2180d350cad1aa9a067fbdaa22129a20f645a","payload":{"connection_id":"f6725804f86a4c4eb588e4d5ed7db029","event_at":"2026-07-28T04:12:07.038000Z","event_type":"price_change","frame_hash":"6d148d625b5cb049f0b78199cafe33583ab08dbacc399fd2d5cf450d7d3941d7","frame_index":0,"kind":"data","monotonic_ns":313911597634250,"payload":{"event_type":"price_change","market":"0xd412ce774cfcf8dc9f71164aac78783978aac7b03871702a3b8a481bd9dc9688","price_changes":[{"asset_id":"107603864457683460275633293642179940881969192120168665300712204232021063124301","best_ask":"0.58","best_bid":"0.57","hash":"9a1fe40c1ed5df97bd9624dc1ccefefb1fce5911","price":"0.02","side":"BUY","size":"530"},{"asset_id":"96600821790790307414914106093858868634329285205417149685270682748367152458577","best_ask":"0.43","best_bid":"0.42","hash":"c8f68a040074ac1e05efa9edf84000bfe94d74f5","price":"0.98","side":"SELL","size":"530"}],"timestamp":"1785211927038"},"payload_hash":"4a834de5f565cd113d0f09645b2631061040e8d211fc28463293d4d349777377","raw_frame":"{\"market\":\"0xd412ce774cfcf8dc9f71164aac78783978aac7b03871702a3b8a481bd9dc9688\", \"price_changes\":[{\"asset_id\":\"107603864457683460275633293642179940881969192120168665300712204232021063124301\", \"price\":\"0.02\", \"size\":\"530\", \"side\":\"BUY\", \"hash\":\"9a1fe40c1ed5df97bd9624dc1ccefefb1fce5911\", \"best_bid\":\"0.57\", \"best_ask\":\"0.58\"}, {\"asset_id\":\"96600821790790307414914106093858868634329285205417149685270682748367152458577\", \"price\":\"0.98\", \"size\":\"530\", \"side\":\"SELL\", \"hash\":\"c8f68a040074ac1e05efa9edf84000bfe94d74f5\", \"best_bid\":\"0.42\", \"best_ask\":\"0.43\"}], \"timestamp\":\"1785211927038\", \"event_type\":\"price_change\"}","received_at":"2026-07-28T04:12:08.520448Z","schema_version":"clob-market-ws.price_change.v1","sequence":null,"server_hash":null,"server_timestamp":"1785211927038","session_id":"2d607381e3054cee91998cdf45a4231c","source":"clob_market_ws"},"received_at":"2026-07-28T04:12:08.520448Z","record_id":"d096b3cb7c3d27b5dcca047196d64888aa527b7c669aca3c66dcc0c86a2f355f","schema_fingerprint":"4aa3821a28b0b7c2400bc59aba4bcc0a76e971dadd19610d3ad38c768e124dc7","schema_version":"edge-lab-recorder.raw.v1","sequence":null,"source":"clob_market_ws"}
{"event_at":"2026-07-28T04:12:07.048000Z","event_fingerprint":"45ebdd204d43a5a0a6829c0328fe2cce69f2189175141e05891e3e8c06a98273","payload":{"connection_id":"f6725804f86a4c4eb588e4d5ed7db029","event_at":"2026-07-28T04:12:07.048000Z","event_type":"price_change","frame_hash":"2c37f918c3b928861a3350a1f483f415d9ce1e4cb3c25f7e982a725bb0f7c4ad","frame_index":0,"kind":"data","monotonic_ns":313911601887291,"payload":{"event_type":"price_change","market":"0xd412ce774cfcf8dc9f71164aac78783978aac7b03871702a3b8a481bd9dc9688","price_changes":[{"asset_id":"96600821790790307414914106093858868634329285205417149685270682748367152458577","best_ask":"0.43","best_bid":"0.42","hash":"67952db297e2f56372ad2125ac1a57e36dda1ad0","price":"0.01","side":"BUY","size":"5295.02"},{"asset_id":"107603864457683460275633293642179940881969192120168665300712204232021063124301","best_ask":"0.58","best_bid":"0.57","hash":"39738d37eb4b943cd1a8034704188e488b9766ed","price":"0.99","side":"SELL","size":"5295.02"}],"timestamp":"1785211927048"},"payload_hash":"27b4e105889c91d8027d4f34f46850aa6c8391cd165d57c5142cb4e4f35a8fd0","raw_frame":"{\"market\":\"0xd412ce774cfcf8dc9f71164aac78783978aac7b03871702a3b8a481bd9dc9688\", \"price_changes\":[{\"asset_id\":\"96600821790790307414914106093858868634329285205417149685270682748367152458577\", \"price\":\"0.01\", \"size\":\"5295.02\", \"side\":\"BUY\", \"hash\":\"67952db297e2f56372ad2125ac1a57e36dda1ad0\", \"best_bid\":\"0.42\", \"best_ask\":\"0.43\"}, {\"asset_id\":\"107603864457683460275633293642179940881969192120168665300712204232021063124301\", \"price\":\"0.99\", \"size\":\"5295.02\", \"side\":\"SELL\", \"hash\":\"39738d37eb4b943cd1a8034704188e488b9766ed\", \"best_bid\":\"0.57\", \"best_ask\":\"0.58\"}], \"timestamp\":\"1785211927048\", \"event_type\":\"price_change\"}","received_at":"2026-07-28T04:12:08.524701Z","schema_version":"clob-market-ws.price_change.v1","sequence":null,"server_hash":null,"server_timestamp":"1785211927048","session_id":"2d607381e3054cee91998cdf45a4231c","source":"clob_market_ws"},"received_at":"2026-07-28T04:12:08.524701Z","record_id":"68d2d46f8628d685cbbbf1fd8b0ea70e326b70d6dfa41d80328ebea44c07beed","schema_fingerprint":"4aa3821a28b0b7c2400bc59aba4bcc0a76e971dadd19610d3ad38c768e124dc7","schema_version":"edge-lab-recorder.raw.v1","sequence":null,"source":"clob_market_ws"}
{"event_at":"2026-07-28T04:12:07.067000Z","event_fingerprint":"f755923361e89c1f601e9868c28567de675060fd29f8b15f7ee2dd99d38a2043","payload":{"connection_id":"f6725804f86a4c4eb588e4d5ed7db029","event_at":"2026-07-28T04:12:07.067000Z","event_type":"price_change","frame_hash":"202e30f9cb36e5679c8e22271ce4e4a7f96e160afb04f6ac9d2d072dd3e592d1","frame_index":0,"kind":"data","monotonic_ns":313911606136708,"payload":{"event_type":"price_change","market":"0xd412ce774cfcf8dc9f71164aac78783978aac7b03871702a3b8a481bd9dc9688","price_changes":[{"asset_id":"107603864457683460275633293642179940881969192120168665300712204232021063124301","best_ask":"0.58","best_bid":"0.57","hash":"8055accb037a49f6f8903411facb0c21a493e19e","price":"0.36","side":"BUY","size":"20"},{"asset_id":"96600821790790307414914106093858868634329285205417149685270682748367152458577","best_ask":"0.43","best_bid":"0.42","hash":"42ff64a0c1b264f66bdfb2adf7da63d254b829e1","price":"0.64","side":"SELL","size":"20"}],"timestamp":"1785211927067"},"payload_hash":"dfe01274c81bb08c139beb22a554c9e7d2aef76dad229921d293afdd73f3cc7a","raw_frame":"{\"market\":\"0xd412ce774cfcf8dc9f71164aac78783978aac7b03871702a3b8a481bd9dc9688\", \"price_changes\":[{\"asset_id\":\"107603864457683460275633293642179940881969192120168665300712204232021063124301\", \"price\":\"0.36\", \"size\":\"20\", \"side\":\"BUY\", \"hash\":\"8055accb037a49f6f8903411facb0c21a493e19e\", \"best_bid\":\"0.57\", \"best_ask\":\"0.58\"}, {\"asset_id\":\"96600821790790307414914106093858868634329285205417149685270682748367152458577\", \"price\":\"0.64\", \"size\":\"20\", \"side\":\"SELL\", \"hash\":\"42ff64a0c1b264f66bdfb2adf7da63d254b829e1\", \"best_bid\":\"0.42\", \"best_ask\":\"0.43\"}], \"timestamp\":\"1785211927067\", \"event_type\":\"price_change\"}","received_at":"2026-07-28T04:12:08.528951Z","schema_version":"clob-market-ws.price_change.v1","sequence":null,"server_hash":null,"server_timestamp":"1785211927067","session_id":"2d607381e3054cee91998cdf45a4231c","source":"clob_market_ws"},"received_at":"2026-07-28T04:12:08.528951Z","record_id":"dd5e4393dedfe0ed328cfda88f09aa112c3e947fb0130f3e8d8e705fba2b6955","schema_fingerprint":"4aa3821a28b0b7c2400bc59aba4bcc0a76e971dadd19610d3ad38c768e124dc7","schema_version":"edge-lab-recorder.raw.v1","sequence":null,"source":"clob_market_ws"}
{"event_at":"2026-07-28T04:12:07.113000Z","event_fingerprint":"a3630794447a43bdd7397a52564fc1f7332c979e5ab2adbcf43676e993261470","payload":{"connection_id":"f6725804f86a4c4eb588e4d5ed7db029","event_at":"2026-07-28T04:12:07.113000Z","event_type":"price_change","frame_hash":"9f274078eea775250a56be58f8d0c65fd09b6c00b690a0bb2e2e752ed151ee2b","frame_index":0,"kind":"data","monotonic_ns":313911610049750,"payload":{"event_type":"price_change","market":"0xd412ce774cfcf8dc9f71164aac78783978aac7b03871702a3b8a481bd9dc9688","price_changes":[{"asset_id":"107603864457683460275633293642179940881969192120168665300712204232021063124301","best_ask":"0.58","best_bid":"0.57","hash":"11669e19c9595802447428615308baa5668ade00","price":"0.52","side":"BUY","size":"79"},{"asset_id":"96600821790790307414914106093858868634329285205417149685270682748367152458577","best_ask":"0.43","best_bid":"0.42","hash":"b63b627977d1c15fe2c3daa7890efe54593561f1","price":"0.48","side":"SELL","size":"79"}],"timestamp":"1785211927113"},"payload_hash":"dd33c612567f690a977a8570487d57bebcc74d04512cf8734574f7d5514c8e06","raw_frame":"{\"market\":\"0xd412ce774cfcf8dc9f71164aac78783978aac7b03871702a3b8a481bd9dc9688\", \"price_changes\":[{\"asset_id\":\"107603864457683460275633293642179940881969192120168665300712204232021063124301\", \"price\":\"0.52\", \"size\":\"79\", \"side\":\"BUY\", \"hash\":\"11669e19c9595802447428615308baa5668ade00\", \"best_bid\":\"0.57\", \"best_ask\":\"0.58\"}, {\"asset_id\":\"96600821790790307414914106093858868634329285205417149685270682748367152458577\", \"price\":\"0.48\", \"size\":\"79\", \"side\":\"SELL\", \"hash\":\"b63b627977d1c15fe2c3daa7890efe54593561f1\", \"best_bid\":\"0.42\", \"best_ask\":\"0.43\"}], \"timestamp\":\"1785211927113\", \"event_type\":\"price_change\"}","received_at":"2026-07-28T04:12:08.532861Z","schema_version":"clob-market-ws.price_change.v1","sequence":null,"server_hash":null,"server_timestamp":"1785211927113","session_id":"2d607381e3054cee91998cdf45a4231c","source":"clob_market_ws"},"received_at":"2026-07-28T04:12:08.532861Z","record_id":"ea20d5e2af26d0d5eaa1f242326b1ef757949e669c64b3aff0fcc4583801f1fb","schema_fingerprint":"4aa3821a28b0b7c2400bc59aba4bcc0a76e971dadd19610d3ad38c768e124dc7","schema_version":"edge-lab-recorder.raw.v1","sequence":null,"source":"clob_market_ws"}
{"event_at":"2026-07-28T04:12:07.124000Z","event_fingerprint":"0c302c3d9428356311f7cbb69a79b37c736bd488e5ac998b85b0976b931ef5be","payload":{"connection_id":"f6725804f86a4c4eb588e4d5ed7db029","event_at":"2026-07-28T04:12:07.124000Z","event_type":"price_change","frame_hash":"84b4afcfff6b16374d77abf4a945b3abb9ff3dd2d960067aed273a3f4644357a","frame_index":0,"kind":"data","monotonic_ns":313911613977958,"payload":{"event_type":"price_change","market":"0xd412ce774cfcf8dc9f71164aac78783978aac7b03871702a3b8a481bd9dc9688","price_changes":[{"asset_id":"107603864457683460275633293642179940881969192120168665300712204232021063124301","best_ask":"0.58","best_bid":"0.57","hash":"93a306cb81ee88d660b73c539e1f7d0c3dbddb1a","price":"0.01","side":"BUY","size":"5335.02"},{"asset_id":"96600821790790307414914106093858868634329285205417149685270682748367152458577","best_ask":"0.43","best_bid":"0.42","hash":"e87b19355004e6ed94e1e1bd8134aa91a80e56d9","price":"0.99","side":"SELL","size":"5335.02"}],"timestamp":"1785211927124"},"payload_hash":"108bbd6a6f8d7641c34f0b9b2c80ba901c4d159abed6fed325de07fe9300d856","raw_frame":"{\"market\":\"0xd412ce774cfcf8dc9f71164aac78783978aac7b03871702a3b8a481bd9dc9688\", \"price_changes\":[{\"asset_id\":\"107603864457683460275633293642179940881969192120168665300712204232021063124301\", \"price\":\"0.01\", \"size\":\"5335.02\", \"side\":\"BUY\", \"hash\":\"93a306cb81ee88d660b73c539e1f7d0c3dbddb1a\", \"best_bid\":\"0.57\", \"best_ask\":\"0.58\"}, {\"asset_id\":\"96600821790790307414914106093858868634329285205417149685270682748367152458577\", \"price\":\"0.99\", \"size\":\"5335.02\", \"side\":\"SELL\", \"hash\":\"e87b19355004e6ed94e1e1bd8134aa91a80e56d9\", \"best_bid\":\"0.42\", \"best_ask\":\"0.43\"}], \"timestamp\":\"1785211927124\", \"event_type\":\"price_change\"}","received_at":"2026-07-28T04:12:08.536792Z","schema_version":"clob-market-ws.price_change.v1","sequence":null,"server_hash":null,"server_timestamp":"1785211927124","session_id":"2d607381e3054cee91998cdf45a4231c","source":"clob_market_ws"},"received_at":"2026-07-28T04:12:08.536792Z","record_id":"1a4780c0747a91e170b96cf2b856daa13d90d4d2877df01dbaac5901c7621ff4","schema_fingerprint":"4aa3821a28b0b7c2400bc59aba4bcc0a76e971dadd19610d3ad38c768e124dc7","schema_version":"edge-lab-recorder.raw.v1","sequence":null,"source":"clob_market_ws"}
{"event_at":"2026-07-28T04:12:07.136000Z","event_fingerprint":"4737d6ce3a3ee10266512b503f3879761409e15d0a10d356c49befc528a0a7af","payload":{"connection_id":"f6725804f86a4c4eb588e4d5ed7db029","event_at":"2026-07-28T04:12:07.136000Z","event_type":"price_change","frame_hash":"78728c8a5e8866d62b2f338273ff952b7eafcd1e87d32f8f901017da26cf8a73","frame_index":0,"kind":"data","monotonic_ns":313911618245791,"payload":{"event_type":"price_change","market":"0xd412ce774cfcf8dc9f71164aac78783978aac7b03871702a3b8a481bd9dc9688","price_changes":[{"asset_id":"107603864457683460275633293642179940881969192120168665300712204232021063124301","best_ask":"0.58","best_bid":"0.57","hash":"338b5ab3e06493542f3bf121526944f26a3c4584","price":"0.01","side":"BUY","size":"5340.02"},{"asset_id":"96600821790790307414914106093858868634329285205417149685270682748367152458577","best_ask":"0.43","best_bid":"0.42","hash":"e42aadeceb1ac515eb6aaa4caa2785225ff4aa76","price":"0.99","side":"SELL","size":"5340.02"}],"timestamp":"1785211927136"},"payload_hash":"261cd8de10154461f97376081df48e01694c5b3718369299317c9e39192453be","raw_frame":"{\"market\":\"0xd412ce774cfcf8dc9f71164aac78783978aac7b03871702a3b8a481bd9dc9688\", \"price_changes\":[{\"asset_id\":\"107603864457683460275633293642179940881969192120168665300712204232021063124301\", \"price\":\"0.01\", \"size\":\"5340.02\", \"side\":\"BUY\", \"hash\":\"338b5ab3e06493542f3bf121526944f26a3c4584\", \"best_bid\":\"0.57\", \"best_ask\":\"0.58\"}, {\"asset_id\":\"96600821790790307414914106093858868634329285205417149685270682748367152458577\", \"price\":\"0.99\", \"size\":\"5340.02\", \"side\":\"SELL\", \"hash\":\"e42aadeceb1ac515eb6aaa4caa2785225ff4aa76\", \"best_bid\":\"0.42\", \"best_ask\":\"0.43\"}], \"timestamp\":\"1785211927136\", \"event_type\":\"price_change\"}","received_at":"2026-07-28T04:12:08.541060Z","schema_version":"clob-market-ws.price_change.v1","sequence":null,"server_hash":null,"server_timestamp":"1785211927136","session_id":"2d607381e3054cee91998cdf45a4231c","source":"clob_market_ws"},"received_at":"2026-07-28T04:12:08.541060Z","record_id":"d3da92c0881de7073aa0b5fbcf35e8d435648c2e544a6650ec1d241e07cdfd59","schema_fingerprint":"4aa3821a28b0b7c2400bc59aba4bcc0a76e971dadd19610d3ad38c768e124dc7","schema_version":"edge-lab-recorder.raw.v1","sequence":null,"source":"clob_market_ws"}
{"event_at":"2026-07-28T04:12:07.139000Z","event_fingerprint":"2cf57ad572a9c3dadde7d2dadd84b35a01b5259da41e41704ee0244539af66d9","payload":{"connection_id":"f6725804f86a4c4eb588e4d5ed7db029","event_at":"2026-07-28T04:12:07.139000Z","event_type":"price_change","frame_hash":"e68048f27ed060e5dd1ffce3c4652f3f204665349f3fda09a9116a533b9f9c60","frame_index":0,"kind":"data","monotonic_ns":313911627174583,"payload":{"event_type":"price_change","market":"0xd412ce774cfcf8dc9f71164aac78783978aac7b03871702a3b8a481bd9dc9688","price_changes":[{"asset_id":"107603864457683460275633293642179940881969192120168665300712204232021063124301","best_ask":"0.58","best_bid":"0.57","hash":"e3eae04ea82382aa8a64ad58dab369727f0f91d5","price":"0.53","side":"BUY","size":"68"},{"asset_id":"96600821790790307414914106093858868634329285205417149685270682748367152458577","best_ask":"0.43","best_bid":"0.42","hash":"8a249ffc82bec3837d5cbfe0db6649bd5417fc8b","price":"0.47","side":"SELL","size":"68"}],"timestamp":"1785211927139"},"payload_hash":"8ae3b3a8c9454cd913711149e098b94bc5d49ff90477fa3d342a9d58d89c957b","raw_frame":"{\"market\":\"0xd412ce774cfcf8dc9f71164aac78783978aac7b03871702a3b8a481bd9dc9688\", \"price_changes\":[{\"asset_id\":\"107603864457683460275633293642179940881969192120168665300712204232021063124301\", \"price\":\"0.53\", \"size\":\"68\", \"side\":\"BUY\", \"hash\":\"e3eae04ea82382aa8a64ad58dab369727f0f91d5\", \"best_bid\":\"0.57\", \"best_ask\":\"0.58\"}, {\"asset_id\":\"96600821790790307414914106093858868634329285205417149685270682748367152458577\", \"price\":\"0.47\", \"size\":\"68\", \"side\":\"SELL\", \"hash\":\"8a249ffc82bec3837d5cbfe0db6649bd5417fc8b\", \"best_bid\":\"0.42\", \"best_ask\":\"0.43\"}], \"timestamp\":\"1785211927139\", \"event_type\":\"price_change\"}","received_at":"2026-07-28T04:12:08.549988Z","schema_version":"clob-market-ws.price_change.v1","sequence":null,"server_hash":null,"server_timestamp":"1785211927139","session_id":"2d607381e3054cee91998cdf45a4231c","source":"clob_market_ws"},"received_at":"2026-07-28T04:12:08.549988Z","record_id":"6ddba8f53e441b0f1d540834a7fbdea350bc152b908925e13cbe6cb7ff431eab","schema_fingerprint":"4aa3821a28b0b7c2400bc59aba4bcc0a76e971dadd19610d3ad38c768e124dc7","schema_version":"edge-lab-recorder.raw.v1","sequence":null,"source":"clob_market_ws"}
{"event_at":"2026-07-28T04:12:07.144000Z","event_fingerprint":"f7912ed22e4b6830460d4401f0facf93be74a8ed79a17e8f0652be292e79b85b","payload":{"connection_id":"f6725804f86a4c4eb588e4d5ed7db029","event_at":"2026-07-28T04:12:07.144000Z","event_type":"price_change","frame_hash":"c820778d3e42701c982c70f173dd3a5df43612fc92eab2f36f363b6d427fdffc","frame_index":0,"kind":"data","monotonic_ns":313911632017416,"payload":{"event_type":"price_change","market":"0xd412ce774cfcf8dc9f71164aac78783978aac7b03871702a3b8a481bd9dc9688","price_changes":[{"asset_id":"107603864457683460275633293642179940881969192120168665300712204232021063124301","best_ask":"0.58","best_bid":"0.57","hash":"706828e8fd8849842c0957c2ab7b4494d9d17de2","price":"0.01","side":"BUY","size":"5335.02"},{"asset_id":"96600821790790307414914106093858868634329285205417149685270682748367152458577","best_ask":"0.43","best_bid":"0.42","hash":"e20f60509aa1e71ea989444f12f8cdceff8bc2fd","price":"0.99","side":"SELL","size":"5335.02"}],"timestamp":"1785211927144"},"payload_hash":"c597ddf0c585fb2f0fb1942c5d65901c191f02ceca3eb51313d770074e2f048d","raw_frame":"{\"market\":\"0xd412ce774cfcf8dc9f71164aac78783978aac7b03871702a3b8a481bd9dc9688\", \"price_changes\":[{\"asset_id\":\"107603864457683460275633293642179940881969192120168665300712204232021063124301\", \"price\":\"0.01\", \"size\":\"5335.02\", \"side\":\"BUY\", \"hash\":\"706828e8fd8849842c0957c2ab7b4494d9d17de2\", \"best_bid\":\"0.57\", \"best_ask\":\"0.58\"}, {\"asset_id\":\"96600821790790307414914106093858868634329285205417149685270682748367152458577\", \"price\":\"0.99\", \"size\":\"5335.02\", \"side\":\"SELL\", \"hash\":\"e20f60509aa1e71ea989444f12f8cdceff8bc2fd\", \"best_bid\":\"0.42\", \"best_ask\":\"0.43\"}], \"timestamp\":\"1785211927144\", \"event_type\":\"price_change\"}","received_at":"2026-07-28T04:12:08.554830Z","schema_version":"clob-market-ws.price_change.v1","sequence":null,"server_hash":null,"server_timestamp":"1785211927144","session_id":"2d607381e3054cee91998cdf45a4231c","source":"clob_market_ws"},"received_at":"2026-07-28T04:12:08.554830Z","record_id":"fe000ea824f417e14e3f76a19c4102cbabe44f3e99a467b95652a10c69cdb17e","schema_fingerprint":"4aa3821a28b0b7c2400bc59aba4bcc0a76e971dadd19610d3ad38c768e124dc7","schema_version":"edge-lab-recorder.raw.v1","sequence":null,"source":"clob_market_ws"}
{"event_at":"2026-07-28T04:12:07.150000Z","event_fingerprint":"cdd1635ce6d934de91ab9260051418b4aa7c4e4d006707982b7f48d290e24e58","payload":{"connection_id":"f6725804f86a4c4eb588e4d5ed7db029","event_at":"2026-07-28T04:12:07.150000Z","event_type":"price_change","frame_hash":"fa4db41fe8340290a8e082d8b0b23d22e9368b0580280252f8fc2dc949795908","frame_index":0,"kind":"data","monotonic_ns":313911637995125,"payload":{"event_type":"price_change","market":"0xd412ce774cfcf8dc9f71164aac78783978aac7b03871702a3b8a481bd9dc9688","price_changes":[{"asset_id":"96600821790790307414914106093858868634329285205417149685270682748367152458577","best_ask":"0.43","best_bid":"0.42","hash":"3e006d2db32d3b8b3d6af7829b4ca3bbf2e18609","price":"0.01","side":"BUY","size":"5290.02"},{"asset_id":"107603864457683460275633293642179940881969192120168665300712204232021063124301","best_ask":"0.58","best_bid":"0.57","hash":"7f07e9313bf8a879d7e9df69a01bc74c373bc84c","price":"0.99","side":"SELL","size":"5290.02"}],"timestamp":"1785211927150"},"payload_hash":"1e2c5d2756d6bbd17049426fd06c4b7d66c119fa913cbd2ce3a795c584eda7cf","raw_frame":"{\"market\":\"0xd412ce774cfcf8dc9f71164aac78783978aac7b03871702a3b8a481bd9dc9688\", \"price_changes\":[{\"asset_id\":\"96600821790790307414914106093858868634329285205417149685270682748367152458577\", \"price\":\"0.01\", \"size\":\"5290.02\", \"side\":\"BUY\", \"hash\":\"3e006d2db32d3b8b3d6af7829b4ca3bbf2e18609\", \"best_bid\":\"0.42\", \"best_ask\":\"0.43\"}, {\"asset_id\":\"107603864457683460275633293642179940881969192120168665300712204232021063124301\", \"price\":\"0.99\", \"size\":\"5290.02\", \"side\":\"SELL\", \"hash\":\"7f07e9313bf8a879d7e9df69a01bc74c373bc84c\", \"best_bid\":\"0.57\", \"best_ask\":\"0.58\"}], \"timestamp\":\"1785211927150\", \"event_type\":\"price_change\"}","received_at":"2026-07-28T04:12:08.560809Z","schema_version":"clob-market-ws.price_change.v1","sequence":null,"server_hash":null,"server_timestamp":"1785211927150","session_id":"2d607381e3054cee91998cdf45a4231c","source":"clob_market_ws"},"received_at":"2026-07-28T04:12:08.560809Z","record_id":"954309f79c2c97272f0abe988467f93af22f31ac228862b58ed624bac725e61e","schema_fingerprint":"4aa3821a28b0b7c2400bc59aba4bcc0a76e971dadd19610d3ad38c768e124dc7","schema_version":"edge-lab-recorder.raw.v1","sequence":null,"source":"clob_market_ws"}
{"event_at":"2026-07-28T04:12:07.151000Z","event_fingerprint":"abc0b0bffc3245ac8e024ad7511f36b80585ceb7bd83600949144ead3a162001","payload":{"connection_id":"f6725804f86a4c4eb588e4d5ed7db029","event_at":"2026-07-28T04:12:07.151000Z","event_type":"price_change","frame_hash":"e67a0cba46d2fc9196d62ff0606ce8f3bb2d67d9005887a1c3f710d4ac45c4ca","frame_index":0,"kind":"data","monotonic_ns":313911659753750,"payload":{"event_type":"price_change","market":"0xd412ce774cfcf8dc9f71164aac78783978aac7b03871702a3b8a481bd9dc9688","price_changes":[{"asset_id":"107603864457683460275633293642179940881969192120168665300712204232021063124301","best_ask":"0.58","best_bid":"0.57","hash":"27b970588d26b9a9fb5d23498fd5c6f00c47380c","price":"0.65","side":"SELL","size":"68"},{"asset_id":"96600821790790307414914106093858868634329285205417149685270682748367152458577","best_ask":"0.43","best_bid":"0.42","hash":"2b099ddffe00650d07fde228163a9fe2a4b73ae5","price":"0.35","side":"BUY","size":"68"}],"timestamp":"1785211927151"},"payload_hash":"e5a4708a9f6c0faf81b7ea6f997fd620576083304369d20a21c60e5cf6ea08dc","raw_frame":"{\"market\":\"0xd412ce774cfcf8dc9f71164aac78783978aac7b03871702a3b8a481bd9dc9688\", \"price_changes\":[{\"asset_id\":\"107603864457683460275633293642179940881969192120168665300712204232021063124301\", \"price\":\"0.65\", \"size\":\"68\", \"side\":\"SELL\", \"hash\":\"27b970588d26b9a9fb5d23498fd5c6f00c47380c\", \"best_bid\":\"0.57\", \"best_ask\":\"0.58\"}, {\"asset_id\":\"96600821790790307414914106093858868634329285205417149685270682748367152458577\", \"price\":\"0.35\", \"size\":\"68\", \"side\":\"BUY\", \"hash\":\"2b099ddffe00650d07fde228163a9fe2a4b73ae5\", \"best_bid\":\"0.42\", \"best_ask\":\"0.43\"}], \"timestamp\":\"1785211927151\", \"event_type\":\"price_change\"}","received_at":"2026-07-28T04:12:08.582565Z","schema_version":"clob-market-ws.price_change.v1","sequence":null,"server_hash":null,"server_timestamp":"1785211927151","session_id":"2d607381e3054cee91998cdf45a4231c","source":"clob_market_ws"},"received_at":"2026-07-28T04:12:08.582565Z","record_id":"35f106077b9df8fe8e19949a9094ed6e697063f03b6f706a65667c5298e8fb7a","schema_fingerprint":"4aa3821a28b0b7c2400bc59aba4bcc0a76e971dadd19610d3ad38c768e124dc7","schema_version":"edge-lab-recorder.raw.v1","sequence":null,"source":"clob_market_ws"}
{"event_at":"2026-07-28T04:12:07.151000Z","event_fingerprint":"71754f56639b43d236ff97f606624221459de07d9c479a63733429a75ed22720","payload":{"connection_id":"f6725804f86a4c4eb588e4d5ed7db029","event_at":"2026-07-28T04:12:07.151000Z","event_type":"price_change","frame_hash":"8b051b4fa9fdbed4a29678a8e553e6530a9596e094ea41d1c0db7c42ead5b924","frame_index":0,"kind":"data","monotonic_ns":313911664955458,"payload":{"event_type":"price_change","market":"0xd412ce774cfcf8dc9f71164aac78783978aac7b03871702a3b8a481bd9dc9688","price_changes":[{"asset_id":"107603864457683460275633293642179940881969192120168665300712204232021063124301","best_ask":"0.58","best_bid":"0.57","hash":"a543e58238473030504b6e6b4a08ab3ca8199aff","price":"0.64","side":"SELL","size":"107"},{"asset_id":"96600821790790307414914106093858868634329285205417149685270682748367152458577","best_ask":"0.43","best_bid":"0.42","hash":"bd0aa59302a84887cefb88663b680362ec75a54f","price":"0.36","side":"BUY","size":"107"}],"timestamp":"1785211927151"},"payload_hash":"3897cb65b27db6fe485a4c6b55df8c1e32f894bc5f707cd63ba246366524e645","raw_frame":"{\"market\":\"0xd412ce774cfcf8dc9f71164aac78783978aac7b03871702a3b8a481bd9dc9688\", \"price_changes\":[{\"asset_id\":\"107603864457683460275633293642179940881969192120168665300712204232021063124301\", \"price\":\"0.64\", \"size\":\"107\", \"side\":\"SELL\", \"hash\":\"a543e58238473030504b6e6b4a08ab3ca8199aff\", \"best_bid\":\"0.57\", \"best_ask\":\"0.58\"}, {\"asset_id\":\"96600821790790307414914106093858868634329285205417149685270682748367152458577\", \"price\":\"0.36\", \"size\":\"107\", \"side\":\"BUY\", \"hash\":\"bd0aa59302a84887cefb88663b680362ec75a54f\", \"best_bid\":\"0.42\", \"best_ask\":\"0.43\"}], \"timestamp\":\"1785211927151\", \"event_type\":\"price_change\"}","received_at":"2026-07-28T04:12:08.587768Z","schema_version":"clob-market-ws.price_change.v1","sequence":null,"server_hash":null,"server_timestamp":"1785211927151","session_id":"2d607381e3054cee91998cdf45a4231c","source":"clob_market_ws"},"received_at":"2026-07-28T04:12:08.587768Z","record_id":"5650b9044d5d996bfdc4e9f7bdcffb19837716f950eac9a36fe4a83aefef2e61","schema_fingerprint":"4aa3821a28b0b7c2400bc59aba4bcc0a76e971dadd19610d3ad38c768e124dc7","schema_version":"edge-lab-recorder.raw.v1","sequence":null,"source":"clob_market_ws"}
{"event_at":"2026-07-28T04:12:07.156000Z","event_fingerprint":"2be6abb87c5cca43876e6c3765132d3ff4e89bbf966102caee8c09368925f677","payload":{"connection_id":"f6725804f86a4c4eb588e4d5ed7db029","event_at":"2026-07-28T04:12:07.156000Z","event_type":"price_change","frame_hash":"c44cdadce5df5eca4e469cfd336aaf2b637d2023c922130efa681173beea65a9","frame_index":0,"kind":"data","monotonic_ns":313911669614583,"payload":{"event_type":"price_change","market":"0xd412ce774cfcf8dc9f71164aac78783978aac7b03871702a3b8a481bd9dc9688","price_changes":[{"asset_id":"107603864457683460275633293642179940881969192120168665300712204232021063124301","best_ask":"0.58","best_bid":"0.57","hash":"1cb2426d5982a4c182e5944747fdfcc238346b93","price":"0.56","side":"BUY","size":"54.72"},{"asset_id":"96600821790790307414914106093858868634329285205417149685270682748367152458577","best_ask":"0.43","best_bid":"0.42","hash":"25547ae7959e1c513fb1c41a7c3b045355645682","price":"0.44","side":"SELL","size":"54.72"}],"timestamp":"1785211927156"},"payload_hash":"69a9bd012cbd954de75c89749d65ab0dac422167df9746d93cb5805984213932","raw_frame":"{\"market\":\"0xd412ce774cfcf8dc9f71164aac78783978aac7b03871702a3b8a481bd9dc9688\", \"price_changes\":[{\"asset_id\":\"107603864457683460275633293642179940881969192120168665300712204232021063124301\", \"price\":\"0.56\", \"size\":\"54.72\", \"side\":\"BUY\", \"hash\":\"1cb2426d5982a4c182e5944747fdfcc238346b93\", \"best_bid\":\"0.57\", \"best_ask\":\"0.58\"}, {\"asset_id\":\"96600821790790307414914106093858868634329285205417149685270682748367152458577\", \"price\":\"0.44\", \"size\":\"54.72\", \"side\":\"SELL\", \"hash\":\"25547ae7959e1c513fb1c41a7c3b045355645682\", \"best_bid\":\"0.42\", \"best_ask\":\"0.43\"}], \"timestamp\":\"1785211927156\", \"event_type\":\"price_change\"}","received_at":"2026-07-28T04:12:08.592425Z","schema_version":"clob-market-ws.price_change.v1","sequence":null,"server_hash":null,"server_timestamp":"1785211927156","session_id":"2d607381e3054cee91998cdf45a4231c","source":"clob_market_ws"},"received_at":"2026-07-28T04:12:08.592425Z","record_id":"de2a47ab1d9f7d436fdfb41c1c43c90c8d7474226ac8fc916bd8cbfa2d680bf2","schema_fingerprint":"4aa3821a28b0b7c2400bc59aba4bcc0a76e971dadd19610d3ad38c768e124dc7","schema_version":"edge-lab-recorder.raw.v1","sequence":null,"source":"clob_market_ws"}
