{"event_at":"2026-07-28T04:05:21.764000Z","event_fingerprint":"3653b070083b9d58597fdd15785240bbdada8dd8bd71785be1ddae3068294349","payload":{"connection_id":"f6725804f86a4c4eb588e4d5ed7db029","event_at":"2026-07-28T04:05:21.764000Z","event_type":"price_change","frame_hash":"ef3b5c663109da3047be708e11b96d286e1455c15c89a8749041535d94a8f182","frame_index":0,"kind":"data","monotonic_ns":313504790171500,"payload":{"event_type":"price_change","market":"0xd412ce774cfcf8dc9f71164aac78783978aac7b03871702a3b8a481bd9dc9688","price_changes":[{"asset_id":"107603864457683460275633293642179940881969192120168665300712204232021063124301","best_ask":"0.6","best_bid":"0.59","hash":"ecd98b40301978dace989d7761202d19aa79dfc7","price":"0.51","side":"BUY","size":"144"},{"asset_id":"96600821790790307414914106093858868634329285205417149685270682748367152458577","best_ask":"0.41","best_bid":"0.4","hash":"213bbcc60603fb406d67a743af7d32201a0dd25e","price":"0.49","side":"SELL","size":"144"}],"timestamp":"1785211521764"},"payload_hash":"510924a262392150a0c1876857bf6518c2f8101d3ce7dc5f8680f08bce6fc8dc","raw_frame":"{\"market\":\"0xd412ce774cfcf8dc9f71164aac78783978aac7b03871702a3b8a481bd9dc9688\", \"price_changes\":[{\"asset_id\":\"107603864457683460275633293642179940881969192120168665300712204232021063124301\", \"price\":\"0.51\", \"size\":\"144\", \"side\":\"BUY\", \"hash\":\"ecd98b40301978dace989d7761202d19aa79dfc7\", \"best_bid\":\"0.59\", \"best_ask\":\"0.6\"}, {\"asset_id\":\"96600821790790307414914106093858868634329285205417149685270682748367152458577\", \"price\":\"0.49\", \"size\":\"144\", \"side\":\"SELL\", \"hash\":\"213bbcc60603fb406d67a743af7d32201a0dd25e\", \"best_bid\":\"0.4\", \"best_ask\":\"0.41\"}], \"timestamp\":\"1785211521764\", \"event_type\":\"price_change\"}","received_at":"2026-07-28T04:05:21.739873Z","schema_version":"clob-market-ws.price_change.v1","sequence":null,"server_hash":null,"server_timestamp":"1785211521764","session_id":"2d607381e3054cee91998cdf45a4231c","source":"clob_market_ws"},"received_at":"2026-07-28T04:05:21.739873Z","record_id":"5d87b3860f18d67b6f69fc0f3093365578cef9432a190b22019f53a7b5155e40","schema_fingerprint":"4aa3821a28b0b7c2400bc59aba4bcc0a76e971dadd19610d3ad38c768e124dc7","schema_version":"edge-lab-recorder.raw.v1","sequence":null,"source":"clob_market_ws"}
{"event_at":"2026-07-28T04:05:21.764000Z","event_fingerprint":"c16b5c4f1bbc72b490d2af3c5872dec1e4b5ef062b09ad481a6979e10a7f1f05","payload":{"connection_id":"f6725804f86a4c4eb588e4d5ed7db029","event_at":"2026-07-28T04:05:21.764000Z","event_type":"price_change","frame_hash":"5005fe1efda647778cf03de630ec2aa805ba960cae01b604e5de98b2ecd4451d","frame_index":0,"kind":"data","monotonic_ns":313504799007916,"payload":{"event_type":"price_change","market":"0xd412ce774cfcf8dc9f71164aac78783978aac7b03871702a3b8a481bd9dc9688","price_changes":[{"asset_id":"96600821790790307414914106093858868634329285205417149685270682748367152458577","best_ask":"0.41","best_bid":"0.4","hash":"fbe0c387f541b0e395bc8fc90e103a99dbb18588","price":"0.36","side":"BUY","size":"101"},{"asset_id":"107603864457683460275633293642179940881969192120168665300712204232021063124301","best_ask":"0.6","best_bid":"0.59","hash":"432252b878f1c6d5f41eb496b6ecdd88f9db7f23","price":"0.64","side":"SELL","size":"101"}],"timestamp":"1785211521764"},"payload_hash":"f303c26acba8b5a1b616094b3ef7cf4231ffb1c158be34c72235bd8f8f396424","raw_frame":"{\"market\":\"0xd412ce774cfcf8dc9f71164aac78783978aac7b03871702a3b8a481bd9dc9688\", \"price_changes\":[{\"asset_id\":\"96600821790790307414914106093858868634329285205417149685270682748367152458577\", \"price\":\"0.36\", \"size\":\"101\", \"side\":\"BUY\", \"hash\":\"fbe0c387f541b0e395bc8fc90e103a99dbb18588\", \"best_bid\":\"0.4\", \"best_ask\":\"0.41\"}, {\"asset_id\":\"107603864457683460275633293642179940881969192120168665300712204232021063124301\", \"price\":\"0.64\", \"size\":\"101\", \"side\":\"SELL\", \"hash\":\"432252b878f1c6d5f41eb496b6ecdd88f9db7f23\", \"best_bid\":\"0.59\", \"best_ask\":\"0.6\"}], \"timestamp\":\"1785211521764\", \"event_type\":\"price_change\"}","received_at":"2026-07-28T04:05:21.748714Z","schema_version":"clob-market-ws.price_change.v1","sequence":null,"server_hash":null,"server_timestamp":"1785211521764","session_id":"2d607381e3054cee91998cdf45a4231c","source":"clob_market_ws"},"received_at":"2026-07-28T04:05:21.748714Z","record_id":"b4d676be812f586d671e0dff4c93b85e47a3ecaf634d0d7e4baf5964f3875107","schema_fingerprint":"4aa3821a28b0b7c2400bc59aba4bcc0a76e971dadd19610d3ad38c768e124dc7","schema_version":"edge-lab-recorder.raw.v1","sequence":null,"source":"clob_market_ws"}
{"event_at":"2026-07-28T04:05:21.765000Z","event_fingerprint":"0dfd3aea79d770f832fb88206cb31b0cff5e2427645158f5fdd7cc2b4fa69ea8","payload":{"connection_id":"f6725804f86a4c4eb588e4d5ed7db029","event_at":"2026-07-28T04:05:21.765000Z","event_type":"price_change","frame_hash":"cb6555fe519a89a1f122bc2628be84bc1a3b147497f63123b7d947d5642cd9e8","frame_index":0,"kind":"data","monotonic_ns":313504802864166,"payload":{"event_type":"price_change","market":"0xd412ce774cfcf8dc9f71164aac78783978aac7b03871702a3b8a481bd9dc9688","price_changes":[{"asset_id":"107603864457683460275633293642179940881969192120168665300712204232021063124301","best_ask":"0.6","best_bid":"0.59","hash":"7a9c7bb3067110db547609015ccb66221f2a3829","price":"0.03","side":"BUY","size":"618.1"},{"asset_id":"96600821790790307414914106093858868634329285205417149685270682748367152458577","best_ask":"0.41","best_bid":"0.4","hash":"54d3685397ef3a598c5141e9e003dbd008827f18","price":"0.97","side":"SELL","size":"618.1"}],"timestamp":"1785211521765"},"payload_hash":"09894ad5615820244cfd364f73d2d9f988df9c066edaf84108a944550d172ab1","raw_frame":"{\"market\":\"0xd412ce774cfcf8dc9f71164aac78783978aac7b03871702a3b8a481bd9dc9688\", \"price_changes\":[{\"asset_id\":\"107603864457683460275633293642179940881969192120168665300712204232021063124301\", \"price\":\"0.03\", \"size\":\"618.1\", \"side\":\"BUY\", \"hash\":\"7a9c7bb3067110db547609015ccb66221f2a3829\", \"best_bid\":\"0.59\", \"best_ask\":\"0.6\"}, {\"asset_id\":\"96600821790790307414914106093858868634329285205417149685270682748367152458577\", \"price\":\"0.97\", \"size\":\"618.1\", \"side\":\"SELL\", \"hash\":\"54d3685397ef3a598c5141e9e003dbd008827f18\", \"best_bid\":\"0.4\", \"best_ask\":\"0.41\"}], \"timestamp\":\"1785211521765\", \"event_type\":\"price_change\"}","received_at":"2026-07-28T04:05:21.752567Z","schema_version":"clob-market-ws.price_change.v1","sequence":null,"server_hash":null,"server_timestamp":"1785211521765","session_id":"2d607381e3054cee91998cdf45a4231c","source":"clob_market_ws"},"received_at":"2026-07-28T04:05:21.752567Z","record_id":"cf5e85be85a12a87b6fd7ff636e7b73cf2c9a205f55b145ab9c848e6379a2ef3","schema_fingerprint":"4aa3821a28b0b7c2400bc59aba4bcc0a76e971dadd19610d3ad38c768e124dc7","schema_version":"edge-lab-recorder.raw.v1","sequence":null,"source":"clob_market_ws"}
{"event_at":"2026-07-28T04:05:21.768000Z","event_fingerprint":"346c9e5e7746537bcb797861891201c267242bddc888b68b71587332c0f21167","payload":{"connection_id":"f6725804f86a4c4eb588e4d5ed7db029","event_at":"2026-07-28T04:05:21.768000Z","event_type":"price_change","frame_hash":"23e1ea806d7f0934942721baa222a716e21dbbe008fc4c53c31981d0eaaa3f3c","frame_index":0,"kind":"data","monotonic_ns":313504808075750,"payload":{"event_type":"price_change","market":"0xd412ce774cfcf8dc9f71164aac78783978aac7b03871702a3b8a481bd9dc9688","price_changes":[{"asset_id":"96600821790790307414914106093858868634329285205417149685270682748367152458577","best_ask":"0.41","best_bid":"0.4","hash":"0c79e8c5c248a773ebcdc7941f5e9cb80465454a","price":"0.36","side":"BUY","size":"107"},{"asset_id":"107603864457683460275633293642179940881969192120168665300712204232021063124301","best_ask":"0.6","best_bid":"0.59","hash":"8baff269baa78f24928a94d77a439b73aade6887","price":"0.64","side":"SELL","size":"107"}],"timestamp":"1785211521768"},"payload_hash":"3836e01e5b8bca67dcddf653d4d5991954f7bcee23978d641d0dd35c80313598","raw_frame":"{\"market\":\"0xd412ce774cfcf8dc9f71164aac78783978aac7b03871702a3b8a481bd9dc9688\", \"price_changes\":[{\"asset_id\":\"96600821790790307414914106093858868634329285205417149685270682748367152458577\", \"price\":\"0.36\", \"size\":\"107\", \"side\":\"BUY\", \"hash\":\"0c79e8c5c248a773ebcdc7941f5e9cb80465454a\", \"best_bid\":\"0.4\", \"best_ask\":\"0.41\"}, {\"asset_id\":\"107603864457683460275633293642179940881969192120168665300712204232021063124301\", \"price\":\"0.64\", \"size\":\"107\", \"side\":\"SELL\", \"hash\":\"8baff269baa78f24928a94d77a439b73aade6887\", \"best_bid\":\"0.59\", \"best_ask\":\"0.6\"}], \"timestamp\":\"1785211521768\", \"event_type\":\"price_change\"}","received_at":"2026-07-28T04:05:21.757780Z","schema_version":"clob-market-ws.price_change.v1","sequence":null,"server_hash":null,"server_timestamp":"1785211521768","session_id":"2d607381e3054cee91998cdf45a4231c","source":"clob_market_ws"},"received_at":"2026-07-28T04:05:21.757780Z","record_id":"00aa3ca81a9d5ee748fc4833233095352d5bb6fbe0fca8f0dfd96f2af5192f81","schema_fingerprint":"4aa3821a28b0b7c2400bc59aba4bcc0a76e971dadd19610d3ad38c768e124dc7","schema_version":"edge-lab-recorder.raw.v1","sequence":null,"source":"clob_market_ws"}
{"event_at":"2026-07-28T04:05:21.770000Z","event_fingerprint":"8ae27f6bb7469bc68582fcbaa74f0dba8e6eaf0939e2077972d30c6f6a8ccaea","payload":{"connection_id":"f6725804f86a4c4eb588e4d5ed7db029","event_at":"2026-07-28T04:05:21.770000Z","event_type":"price_change","frame_hash":"d9d6516a08e158080f8dfec6cae900d4c3f173f5fdaf60625e6a13823903050e","frame_index":0,"kind":"data","monotonic_ns":313504811855916,"payload":{"event_type":"price_change","market":"0xd412ce774cfcf8dc9f71164aac78783978aac7b03871702a3b8a481bd9dc9688","price_changes":[{"asset_id":"107603864457683460275633293642179940881969192120168665300712204232021063124301","best_ask":"0.6","best_bid":"0.59","hash":"c2f268d30206faa56b4160658663994a7985c247","price":"0.54","side":"BUY","size":"96.6"},{"asset_id":"96600821790790307414914106093858868634329285205417149685270682748367152458577","best_ask":"0.41","best_bid":"0.4","hash":"db407271a9852702c97a258ac9c8d4c839a2050a","price":"0.46","side":"SELL","size":"96.6"}],"timestamp":"1785211521770"},"payload_hash":"82109314135520d4788fc8c01611c2fda949e70e115ddd39b375eaf41b9ec046","raw_frame":"{\"market\":\"0xd412ce774cfcf8dc9f71164aac78783978aac7b03871702a3b8a481bd9dc9688\", \"price_changes\":[{\"asset_id\":\"107603864457683460275633293642179940881969192120168665300712204232021063124301\", \"price\":\"0.54\", \"size\":\"96.6\", \"side\":\"BUY\", \"hash\":\"c2f268d30206faa56b4160658663994a7985c247\", \"best_bid\":\"0.59\", \"best_ask\":\"0.6\"}, {\"asset_id\":\"96600821790790307414914106093858868634329285205417149685270682748367152458577\", \"price\":\"0.46\", \"size\":\"96.6\", \"side\":\"SELL\", \"hash\":\"db407271a9852702c97a258ac9c8d4c839a2050a\", \"best_bid\":\"0.4\", \"best_ask\":\"0.41\"}], \"timestamp\":\"1785211521770\", \"event_type\":\"price_change\"}","received_at":"2026-07-28T04:05:21.761559Z","schema_version":"clob-market-ws.price_change.v1","sequence":null,"server_hash":null,"server_timestamp":"1785211521770","session_id":"2d607381e3054cee91998cdf45a4231c","source":"clob_market_ws"},"received_at":"2026-07-28T04:05:21.761559Z","record_id":"77b3b4b96ec8f17447a150b6dd47cf4199ecedb3ba374d9155807c33fc911167","schema_fingerprint":"4aa3821a28b0b7c2400bc59aba4bcc0a76e971dadd19610d3ad38c768e124dc7","schema_version":"edge-lab-recorder.raw.v1","sequence":null,"source":"clob_market_ws"}
{"event_at":"2026-07-28T04:05:21.770000Z","event_fingerprint":"7a3ec34bc9d71244ea9373a7a2ac5fcaf274558e4020629e36c068971fe95f28","payload":{"connection_id":"f6725804f86a4c4eb588e4d5ed7db029","event_at":"2026-07-28T04:05:21.770000Z","event_type":"price_change","frame_hash":"9a00a0d4bf8f50974a63c2851ebaebfe317b82678832a89620887a89eccb3f18","frame_index":0,"kind":"data","monotonic_ns":313504816282666,"payload":{"event_type":"price_change","market":"0xd412ce774cfcf8dc9f71164aac78783978aac7b03871702a3b8a481bd9dc9688","price_changes":[{"asset_id":"96600821790790307414914106093858868634329285205417149685270682748367152458577","best_ask":"0.41","best_bid":"0.4","hash":"db407271a9852702c97a258ac9c8d4c839a2050a","price":"0.36","side":"BUY","size":"87"},{"asset_id":"107603864457683460275633293642179940881969192120168665300712204232021063124301","best_ask":"0.6","best_bid":"0.59","hash":"c2f268d30206faa56b4160658663994a7985c247","price":"0.64","side":"SELL","size":"87"}],"timestamp":"1785211521770"},"payload_hash":"132127497fb8e1b9cd9d546fd47702ea5a8ec844a0fd5ae3561f3e7fd4d1ed6b","raw_frame":"{\"market\":\"0xd412ce774cfcf8dc9f71164aac78783978aac7b03871702a3b8a481bd9dc9688\", \"price_changes\":[{\"asset_id\":\"96600821790790307414914106093858868634329285205417149685270682748367152458577\", \"price\":\"0.36\", \"size\":\"87\", \"side\":\"BUY\", \"hash\":\"db407271a9852702c97a258ac9c8d4c839a2050a\", \"best_bid\":\"0.4\", \"best_ask\":\"0.41\"}, {\"asset_id\":\"107603864457683460275633293642179940881969192120168665300712204232021063124301\", \"price\":\"0.64\", \"size\":\"87\", \"side\":\"SELL\", \"hash\":\"c2f268d30206faa56b4160658663994a7985c247\", \"best_bid\":\"0.59\", \"best_ask\":\"0.6\"}], \"timestamp\":\"1785211521770\", \"event_type\":\"price_change\"}","received_at":"2026-07-28T04:05:21.765987Z","schema_version":"clob-market-ws.price_change.v1","sequence":null,"server_hash":null,"server_timestamp":"1785211521770","session_id":"2d607381e3054cee91998cdf45a4231c","source":"clob_market_ws"},"received_at":"2026-07-28T04:05:21.765987Z","record_id":"a3f3a127b75214d2ee859e08a5693acdda00aa063432f2746c3db06314be3f4f","schema_fingerprint":"4aa3821a28b0b7c2400bc59aba4bcc0a76e971dadd19610d3ad38c768e124dc7","schema_version":"edge-lab-recorder.raw.v1","sequence":null,"source":"clob_market_ws"}
{"event_at":"2026-07-28T04:05:21.774000Z","event_fingerprint":"154cfdac50d02b46c129969232203fd7d4d811a224dded88177a8e2b72a46a79","payload":{"connection_id":"f6725804f86a4c4eb588e4d5ed7db029","event_at":"2026-07-28T04:05:21.774000Z","event_type":"price_change","frame_hash":"6722f5ed487e62d5c63a5464784688cef16ff8e9a1e20c3c14adf7c177b9a28b","frame_index":0,"kind":"data","monotonic_ns":313504820550708,"payload":{"event_type":"price_change","market":"0xd412ce774cfcf8dc9f71164aac78783978aac7b03871702a3b8a481bd9dc9688","price_changes":[{"asset_id":"107603864457683460275633293642179940881969192120168665300712204232021063124301","best_ask":"0.6","best_bid":"0.59","hash":"3afa3f535b2d0d69fe48f31a345539480a1cc6cb","price":"0.01","side":"BUY","size":"5888.02"},{"asset_id":"96600821790790307414914106093858868634329285205417149685270682748367152458577","best_ask":"0.41","best_bid":"0.4","hash":"da211fc9903b8bbf180f683fce8508265afd5f74","price":"0.99","side":"SELL","size":"5888.02"}],"timestamp":"1785211521774"},"payload_hash":"98da6eb8a2135ff85a8d5db58109073ccc4787ee0ea982aa22016721697f8f38","raw_frame":"{\"market\":\"0xd412ce774cfcf8dc9f71164aac78783978aac7b03871702a3b8a481bd9dc9688\", \"price_changes\":[{\"asset_id\":\"107603864457683460275633293642179940881969192120168665300712204232021063124301\", \"price\":\"0.01\", \"size\":\"5888.02\", \"side\":\"BUY\", \"hash\":\"3afa3f535b2d0d69fe48f31a345539480a1cc6cb\", \"best_bid\":\"0.59\", \"best_ask\":\"0.6\"}, {\"asset_id\":\"96600821790790307414914106093858868634329285205417149685270682748367152458577\", \"price\":\"0.99\", \"size\":\"5888.02\", \"side\":\"SELL\", \"hash\":\"da211fc9903b8bbf180f683fce8508265afd5f74\", \"best_bid\":\"0.4\", \"best_ask\":\"0.41\"}], \"timestamp\":\"1785211521774\", \"event_type\":\"price_change\"}","received_at":"2026-07-28T04:05:21.770256Z","schema_version":"clob-market-ws.price_change.v1","sequence":null,"server_hash":null,"server_timestamp":"1785211521774","session_id":"2d607381e3054cee91998cdf45a4231c","source":"clob_market_ws"},"received_at":"2026-07-28T04:05:21.770256Z","record_id":"3802adf08c9d788a0ac620dfbf25e5e50d6638bb78a9d86e1b55116c4730d5a2","schema_fingerprint":"4aa3821a28b0b7c2400bc59aba4bcc0a76e971dadd19610d3ad38c768e124dc7","schema_version":"edge-lab-recorder.raw.v1","sequence":null,"source":"clob_market_ws"}
{"event_at":"2026-07-28T04:05:21.777000Z","event_fingerprint":"77f04da0d8c700fba768cc5f61bbc46eea8e8c3b432269764cfbebf8a5747cf1","payload":{"connection_id":"f6725804f86a4c4eb588e4d5ed7db029","event_at":"2026-07-28T04:05:21.777000Z","event_type":"price_change","frame_hash":"10b59676b6e62917e6f6ace48464cc331df36a4bf15910a22d06f5671b39dc66","frame_index":0,"kind":"data","monotonic_ns":313504825086500,"payload":{"event_type":"price_change","market":"0xd412ce774cfcf8dc9f71164aac78783978aac7b03871702a3b8a481bd9dc9688","price_changes":[{"asset_id":"96600821790790307414914106093858868634329285205417149685270682748367152458577","best_ask":"0.41","best_bid":"0.4","hash":"e98d0051d8c49989d93ef54ba65c950ba626e885","price":"0.28","side":"BUY","size":"118.44"},{"asset_id":"107603864457683460275633293642179940881969192120168665300712204232021063124301","best_ask":"0.6","best_bid":"0.59","hash":"2ecc8dbdfe6a37c0e8d414dc7cfe7ea5253a3027","price":"0.72","side":"SELL","size":"118.44"}],"timestamp":"1785211521777"},"payload_hash":"338c21b596d1cf5fe8eb33e76adac39a6457099d451ce6c8492dbfe340f29f31","raw_frame":"{\"market\":\"0xd412ce774cfcf8dc9f71164aac78783978aac7b03871702a3b8a481bd9dc9688\", \"price_changes\":[{\"asset_id\":\"96600821790790307414914106093858868634329285205417149685270682748367152458577\", \"price\":\"0.28\", \"size\":\"118.44\", \"side\":\"BUY\", \"hash\":\"e98d0051d8c49989d93ef54ba65c950ba626e885\", \"best_bid\":\"0.4\", \"best_ask\":\"0.41\"}, {\"asset_id\":\"107603864457683460275633293642179940881969192120168665300712204232021063124301\", \"price\":\"0.72\", \"size\":\"118.44\", \"side\":\"SELL\", \"hash\":\"2ecc8dbdfe6a37c0e8d414dc7cfe7ea5253a3027\", \"best_bid\":\"0.59\", \"best_ask\":\"0.6\"}], \"timestamp\":\"1785211521777\", \"event_type\":\"price_change\"}","received_at":"2026-07-28T04:05:21.774791Z","schema_version":"clob-market-ws.price_change.v1","sequence":null,"server_hash":null,"server_timestamp":"1785211521777","session_id":"2d607381e3054cee91998cdf45a4231c","source":"clob_market_ws"},"received_at":"2026-07-28T04:05:21.774791Z","record_id":"5f3f7f002ac863bde77669ee5bd33ddfc29704c6196c23f5e6e66f489c74d076","schema_fingerprint":"4aa3821a28b0b7c2400bc59aba4bcc0a76e971dadd19610d3ad38c768e124dc7","schema_version":"edge-lab-recorder.raw.v1","sequence":null,"source":"clob_market_ws"}
{"event_at":"2026-07-28T04:05:21.792000Z","event_fingerprint":"2b59403113ae80deb624082485d51015c0ab734339f8936de3c993993cb0ebe1","payload":{"connection_id":"f6725804f86a4c4eb588e4d5ed7db029","event_at":"2026-07-28T04:05:21.792000Z","event_type":"price_change","frame_hash":"03264bfe93e209b03d62596251d8ed6983e28e401a3f80389a4403929c1cbb3a","frame_index":0,"kind":"data","monotonic_ns":313504829400041,"payload":{"event_type":"price_change","market":"0xd412ce774cfcf8dc9f71164aac78783978aac7b03871702a3b8a481bd9dc9688","price_changes":[{"asset_id":"107603864457683460275633293642179940881969192120168665300712204232021063124301","best_ask":"0.6","best_bid":"0.59","hash":"638a882ee63f49dd3e2d7de54508169b81273f06","price":"0.03","side":"BUY","size":"613.1"},{"asset_id":"96600821790790307414914106093858868634329285205417149685270682748367152458577","best_ask":"0.41","best_bid":"0.4","hash":"9eeee9fc2cbed61c839d9acc4d39a258ce1aefad","price":"0.97","side":"SELL","size":"613.1"}],"timestamp":"1785211521792"},"payload_hash":"fb89c36056f090b3f0313f09c1ccdce545b4132cff871e3530f57e2a78ac2c82","raw_frame":"{\"market\":\"0xd412ce774cfcf8dc9f71164aac78783978aac7b03871702a3b8a481bd9dc9688\", \"price_changes\":[{\"asset_id\":\"107603864457683460275633293642179940881969192120168665300712204232021063124301\", \"price\":\"0.03\", \"size\":\"613.1\", \"side\":\"BUY\", \"hash\":\"638a882ee63f49dd3e2d7de54508169b81273f06\", \"best_bid\":\"0.59\", \"best_ask\":\"0.6\"}, {\"asset_id\":\"96600821790790307414914106093858868634329285205417149685270682748367152458577\", \"price\":\"0.97\", \"size\":\"613.1\", \"side\":\"SELL\", \"hash\":\"9eeee9fc2cbed61c839d9acc4d39a258ce1aefad\", \"best_bid\":\"0.4\", \"best_ask\":\"0.41\"}], \"timestamp\":\"1785211521792\", \"event_type\":\"price_change\"}","received_at":"2026-07-28T04:05:21.779101Z","schema_version":"clob-market-ws.price_change.v1","sequence":null,"server_hash":null,"server_timestamp":"1785211521792","session_id":"2d607381e3054cee91998cdf45a4231c","source":"clob_market_ws"},"received_at":"2026-07-28T04:05:21.779101Z","record_id":"df2909ab0e3860c7b603b18502595de48192625c08c3eb682c47dcaa54d8b4d1","schema_fingerprint":"4aa3821a28b0b7c2400bc59aba4bcc0a76e971dadd19610d3ad38c768e124dc7","schema_version":"edge-lab-recorder.raw.v1","sequence":null,"source":"clob_market_ws"}
{"event_at":"2026-07-28T04:05:21.798000Z","event_fingerprint":"a95f08fb447a8b0fdf5921c1438ba6d40b56ece6360757ba188fc71f1f5e1f24","payload":{"connection_id":"f6725804f86a4c4eb588e4d5ed7db029","event_at":"2026-07-28T04:05:21.798000Z","event_type":"price_change","frame_hash":"64a31fd9fe55402ceb2fdd6c0766e5caacf01b6925c12c319ab58acaea22b56a","frame_index":0,"kind":"data","monotonic_ns":313504833893083,"payload":{"event_type":"price_change","market":"0xd412ce774cfcf8dc9f71164aac78783978aac7b03871702a3b8a481bd9dc9688","price_changes":[{"asset_id":"107603864457683460275633293642179940881969192120168665300712204232021063124301","best_ask":"0.6","best_bid":"0.59","hash":"7de3840b31a05b22f197dd58e45477faa143770c","price":"0.59","side":"BUY","size":"151.2"},{"asset_id":"96600821790790307414914106093858868634329285205417149685270682748367152458577","best_ask":"0.41","best_bid":"0.4","hash":"7c3582e86e51591496f75f719f1c35f0b0aecd9f","price":"0.41","side":"SELL","size":"151.2"}],"timestamp":"1785211521798"},"payload_hash":"036d5212f095f25b86e64ce472b2d8bd7436488305ce19974af393b5e616342c","raw_frame":"{\"market\":\"0xd412ce774cfcf8dc9f71164aac78783978aac7b03871702a3b8a481bd9dc9688\", \"price_changes\":[{\"asset_id\":\"107603864457683460275633293642179940881969192120168665300712204232021063124301\", \"price\":\"0.59\", \"size\":\"151.2\", \"side\":\"BUY\", \"hash\":\"7de3840b31a05b22f197dd58e45477faa143770c\", \"best_bid\":\"0.59\", \"best_ask\":\"0.6\"}, {\"asset_id\":\"96600821790790307414914106093858868634329285205417149685270682748367152458577\", \"price\":\"0.41\", \"size\":\"151.2\", \"side\":\"SELL\", \"hash\":\"7c3582e86e51591496f75f719f1c35f0b0aecd9f\", \"best_bid\":\"0.4\", \"best_ask\":\"0.41\"}], \"timestamp\":\"1785211521798\", \"event_type\":\"price_change\"}","received_at":"2026-07-28T04:05:21.783596Z","schema_version":"clob-market-ws.price_change.v1","sequence":null,"server_hash":null,"server_timestamp":"1785211521798","session_id":"2d607381e3054cee91998cdf45a4231c","source":"clob_market_ws"},"received_at":"2026-07-28T04:05:21.783596Z","record_id":"d3ecbdc4ef79ebe9003090a1d8858fbe10b0114cbeeadb645a3b29e9bf2a8c2a","schema_fingerprint":"4aa3821a28b0b7c2400bc59aba4bcc0a76e971dadd19610d3ad38c768e124dc7","schema_version":"edge-lab-recorder.raw.v1","sequence":null,"source":"clob_market_ws"}
{"event_at":"2026-07-28T04:05:21.805000Z","event_fingerprint":"931d658606c1de6dc9eecab8e41cb98a2481998c0bef4c222db26d9634ba166e","payload":{"connection_id":"f6725804f86a4c4eb588e4d5ed7db029","event_at":"2026-07-28T04:05:21.805000Z","event_type":"best_bid_ask","frame_hash":"bb396f9eee4f4913533700cbb568d9f8355f32b2ad1bff67acf91ee39f42bc54","frame_index":0,"kind":"data","monotonic_ns":313504837536458,"payload":{"asset_id":"107603864457683460275633293642179940881969192120168665300712204232021063124301","best_ask":"0.6","best_bid":"0.59","event_type":"best_bid_ask","market":"0xd412ce774cfcf8dc9f71164aac78783978aac7b03871702a3b8a481bd9dc9688","spread":"0.01","timestamp":"1785211521805"},"payload_hash":"d59b6b30a9144209cd93929b896996b6c37399c595f583a2fc8e7412033b0ae7","raw_frame":"{\"market\":\"0xd412ce774cfcf8dc9f71164aac78783978aac7b03871702a3b8a481bd9dc9688\", \"asset_id\":\"107603864457683460275633293642179940881969192120168665300712204232021063124301\", \"best_bid\":\"0.59\", \"best_ask\":\"0.6\", \"spread\":\"0.01\", \"timestamp\":\"1785211521805\", \"event_type\":\"best_bid_ask\"}","received_at":"2026-07-28T04:05:21.787240Z","schema_version":"clob-market-ws.best_bid_ask.v1","sequence":null,"server_hash":null,"server_timestamp":"1785211521805","session_id":"2d607381e3054cee91998cdf45a4231c","source":"clob_market_ws"},"received_at":"2026-07-28T04:05:21.787240Z","record_id":"3348dc4fc2fa72a58562c385acbd377df23ba8cc4cd5a92e6be65eec0e5291e2","schema_fingerprint":"8488399f31b0337811b13b266be932db7062827c2470b78bd8e9e99bab51d17d","schema_version":"edge-lab-recorder.raw.v1","sequence":null,"source":"clob_market_ws"}
{"event_at":"2026-07-28T04:05:21.805000Z","event_fingerprint":"43c81cc45ce75190acef4f77da8becc84b65c351629ab2747a3ccbf373114c5b","payload":{"connection_id":"f6725804f86a4c4eb588e4d5ed7db029","event_at":"2026-07-28T04:05:21.805000Z","event_type":"best_bid_ask","frame_hash":"30b6719624460849ce6309111bc7f4c8d3980d6a209766091533756563ad0a83","frame_index":0,"kind":"data","monotonic_ns":313504840874541,"payload":{"asset_id":"96600821790790307414914106093858868634329285205417149685270682748367152458577","best_ask":"0.41","best_bid":"0.4","event_type":"best_bid_ask","market":"0xd412ce774cfcf8dc9f71164aac78783978aac7b03871702a3b8a481bd9dc9688","spread":"0.01","timestamp":"1785211521805"},"payload_hash":"eebebcfc29b7272ffbebcc6f4a2a1051170108d6259f34451d036a4876ea6a16","raw_frame":"{\"market\":\"0xd412ce774cfcf8dc9f71164aac78783978aac7b03871702a3b8a481bd9dc9688\", \"asset_id\":\"96600821790790307414914106093858868634329285205417149685270682748367152458577\", \"best_bid\":\"0.4\", \"best_ask\":\"0.41\", \"spread\":\"0.01\", \"timestamp\":\"1785211521805\", \"event_type\":\"best_bid_ask\"}","received_at":"2026-07-28T04:05:21.790579Z","schema_version":"clob-market-ws.best_bid_ask.v1","sequence":null,"server_hash":null,"server_timestamp":"1785211521805","session_id":"2d607381e3054cee91998cdf45a4231c","source":"clob_market_ws"},"received_at":"2026-07-28T04:05:21.790579Z","record_id":"73700dc478cf5328e08459817f5977d3597cf1cf53f405b9dddc56f98fa82be3","schema_fingerprint":"8488399f31b0337811b13b266be932db7062827c2470b78bd8e9e99bab51d17d","schema_version":"edge-lab-recorder.raw.v1","sequence":null,"source":"clob_market_ws"}
{"event_at":"2026-07-28T04:05:21.804000Z","event_fingerprint":"fac075372b1b000c99950fd6bb29e13d81c1dfdb220112b347f57aab68f68c8e","payload":{"connection_id":"f6725804f86a4c4eb588e4d5ed7db029","event_at":"2026-07-28T04:05:21.804000Z","event_type":"price_change","frame_hash":"483b0a87fdfcbf3539cbe6b17f7c33743b1409f518e644f0709b5f4d0140e2a5","frame_index":0,"kind":"data","monotonic_ns":313504845503708,"payload":{"event_type":"price_change","market":"0xd412ce774cfcf8dc9f71164aac78783978aac7b03871702a3b8a481bd9dc9688","price_changes":[{"asset_id":"96600821790790307414914106093858868634329285205417149685270682748367152458577","best_ask":"0.41","best_bid":"0.4","hash":"01e7079c59cc4f754367bd557cc09d37e2ffcc13","price":"0.4","side":"BUY","size":"2.96"},{"asset_id":"107603864457683460275633293642179940881969192120168665300712204232021063124301","best_ask":"0.6","best_bid":"0.59","hash":"a4cd3545603a486b1526239d2fc9d73fd2a20aac","price":"0.6","side":"SELL","size":"2.96"}],"timestamp":"1785211521804"},"payload_hash":"cb09224d771d20c57f1c5be2ab9edfc032ef81dba35e189a631839e59e3dc122","raw_frame":"{\"market\":\"0xd412ce774cfcf8dc9f71164aac78783978aac7b03871702a3b8a481bd9dc9688\", \"price_changes\":[{\"asset_id\":\"96600821790790307414914106093858868634329285205417149685270682748367152458577\", \"price\":\"0.4\", \"size\":\"2.96\", \"side\":\"BUY\", \"hash\":\"01e7079c59cc4f754367bd557cc09d37e2ffcc13\", \"best_bid\":\"0.4\", \"best_ask\":\"0.41\"}, {\"asset_id\":\"107603864457683460275633293642179940881969192120168665300712204232021063124301\", \"price\":\"0.6\", \"size\":\"2.96\", \"side\":\"SELL\", \"hash\":\"a4cd3545603a486b1526239d2fc9d73fd2a20aac\", \"best_bid\":\"0.59\", \"best_ask\":\"0.6\"}], \"timestamp\":\"1785211521804\", \"event_type\":\"price_change\"}","received_at":"2026-07-28T04:05:21.795207Z","schema_version":"clob-market-ws.price_change.v1","sequence":null,"server_hash":null,"server_timestamp":"1785211521804","session_id":"2d607381e3054cee91998cdf45a4231c","source":"clob_market_ws"},"received_at":"2026-07-28T04:05:21.795207Z","record_id":"7fbe10a19a8c310f3bd6bb27a720ebb55fed142cfcc9d36ebe8a25ac2e98d14c","schema_fingerprint":"4aa3821a28b0b7c2400bc59aba4bcc0a76e971dadd19610d3ad38c768e124dc7","schema_version":"edge-lab-recorder.raw.v1","sequence":null,"source":"clob_market_ws"}
{"event_at":null,"event_fingerprint":"c925feab70f1653124c76087d832a08c8e3dabd323f5c50ccd080ee8a8a19a8e","payload":{"connection_id":"f6725804f86a4c4eb588e4d5ed7db029","detail":{"current_server_timestamp":"1785211521804","entity":"clob_market_ws:107603864457683460275633293642179940881969192120168665300712204232021063124301","previous_server_timestamp":"1785211521805"},"event_type":"anomaly.time_regression","kind":"diagnostic","monotonic_ns":313504848978916,"received_at":"2026-07-28T04:05:21.798684Z","schema_version":"edge-lab-recorder.anomaly.v1","session_id":"2d607381e3054cee91998cdf45a4231c","source":"clob_market_ws","trigger_frame_hash":"a0fd9475cf7051496754207c3d314cd069ed744ba3c57d535874d2fab374b021","trigger_server_hash":"a4cd3545603a486b1526239d2fc9d73fd2a20aac"},"received_at":"2026-07-28T04:05:21.798684Z","record_id":"12046e97702b7dc0851b5729df8efb2c4072b79cb3142901885d9d07700631d8","schema_fingerprint":"cb1780324c96914017c24d4692a681315845f9745a5a4a3a289c5a43388b35c3","schema_version":"edge-lab-recorder.raw.v1","sequence":null,"source":"clob_market_ws"}
{"event_at":"2026-07-28T04:05:21.804000Z","event_fingerprint":"d5c18aff86dc02f404e96c69f1dd647325bc58a5357291ff70b6747ab41e230f","payload":{"connection_id":"f6725804f86a4c4eb588e4d5ed7db029","event_at":"2026-07-28T04:05:21.804000Z","event_type":"book","frame_hash":"a0fd9475cf7051496754207c3d314cd069ed744ba3c57d535874d2fab374b021","frame_index":0,"kind":"data","monotonic_ns":313504848584583,"payload":{"asks":[{"price":"0.99","size":"5853.02"},{"price":"0.98","size":"673.1"},{"price":"0.97","size":"909.76"},{"price":"0.96","size":"588.09"},{"price":"0.95","size":"676.2"},{"price":"0.94","size":"605.2"},{"price":"0.93","size":"565.1"},{"price":"0.92","size":"567.79"},{"price":"0.91","size":"581.6"},{"price":"0.9","size":"102.29"},{"price":"0.89","size":"43.6"},{"price":"0.88","size":"176.52"},{"price":"0.87","size":"37.5"},{"price":"0.86","size":"34.9"},{"price":"0.85","size":"151.57"},{"price":"0.84","size":"137.42"},{"price":"0.83","size":"30.3"},{"price":"0.82","size":"58.3"},{"price":"0.81","size":"27.5"},{"price":"0.8","size":"640.21"},{"price":"0.79","size":"56.1"},{"price":"0.78","size":"24.5"},{"price":"0.77","size":"23.89"},{"price":"0.76","size":"59.39"},{"price":"0.75","size":"258.91"},{"price":"0.74","size":"136.1"},{"price":"0.73","size":"166.2"},{"price":"0.72","size":"118.44"},{"price":"0.71","size":"106"},{"price":"0.7","size":"176.98"},{"price":"0.69","size":"125.74"},{"price":"0.68","size":"165.68"},{"price":"0.67","size":"183"},{"price":"0.66","size":"151"},{"price":"0.65","size":"133"},{"price":"0.64","size":"87"},{"price":"0.63","size":"38.61"},{"price":"0.62","size":"19"},{"price":"0.61","size":"6"},{"price":"0.6","size":"2.96"}],"asset_id":"107603864457683460275633293642179940881969192120168665300712204232021063124301","bids":[{"price":"0.01","size":"5888.02"},{"price":"0.02","size":"683.1"},{"price":"0.03","size":"613.1"},{"price":"0.04","size":"618.09"},{"price":"0.05","size":"853.2"},{"price":"0.06","size":"553.2"},{"price":"0.07","size":"576.1"},{"price":"0.08","size":"550.79"},{"price":"0.09","size":"536.6"},{"price":"0.1","size":"118.29"},{"price":"0.11","size":"43.6"},{"price":"0.12","size":"50.4"},{"price":"0.13","size":"67.5"},{"price":"0.14","size":"34.9"},{"price":"0.15","size":"64.5"},{"price":"0.16","size":"71.3"},{"price":"0.17","size":"30.3"},{"price":"0.18","size":"28.3"},{"price":"0.19","size":"57.5"},{"price":"0.2","size":"59.8"},{"price":"0.21","size":"26.1"},{"price":"0.22","size":"54.5"},{"price":"0.23","size":"23.89"},{"price":"0.24","size":"23.39"},{"price":"0.25","size":"82"},{"price":"0.26","size":"21.6"},{"price":"0.27","size":"21.2"},{"price":"0.28","size":"50.9"},{"price":"0.29","size":"20.6"},{"price":"0.3","size":"47.3"},{"price":"0.31","size":"50"},{"price":"0.32","size":"19.8"},{"price":"0.33","size":"31.6"},{"price":"0.34","size":"49.4"},{"price":"0.35","size":"38.2"},{"price":"0.36","size":"18"},{"price":"0.37","size":"137.99"},{"price":"0.38","size":"27.7"},{"price":"0.39","size":"117.6"},{"price":"0.4","size":"161.5"},{"price":"0.41","size":"117.4"},{"price":"0.42","size":"162.63"},{"price":"0.43","size":"152.2"},{"price":"0.44","size":"117.2"},{"price":"0.45","size":"125.1"},{"price":"0.46","size":"147.1"},{"price":"0.47","size":"175"},{"price":"0.48","size":"159"},{"price":"0.49","size":"181"},{"price":"0.5","size":"160"},{"price":"0.51","size":"144"},{"price":"0.52","size":"219"},{"price":"0.53","size":"73"},{"price":"0.54","size":"96.6"},{"price":"0.55","size":"93.67"},{"price":"0.56","size":"121.32"},{"price":"0.57","size":"113.35"},{"price":"0.58","size":"99.82"},{"price":"0.59","size":"151.2"}],"event_type":"book","hash":"a4cd3545603a486b1526239d2fc9d73fd2a20aac","market":"0xd412ce774cfcf8dc9f71164aac78783978aac7b03871702a3b8a481bd9dc9688","timestamp":"1785211521804"},"payload_hash":"a3302c64c72203e0937c768b031b0e0fc449908df3acd147e1fbacf387a6f8a6","raw_frame":"{\"market\":\"0xd412ce774cfcf8dc9f71164aac78783978aac7b03871702a3b8a481bd9dc9688\", \"asset_id\":\"107603864457683460275633293642179940881969192120168665300712204232021063124301\", \"bids\":[{\"price\":\"0.01\", \"size\":\"5888.02\"}, {\"price\":\"0.02\", \"size\":\"683.1\"}, {\"price\":\"0.03\", \"size\":\"613.1\"}, {\"price\":\"0.04\", \"size\":\"618.09\"}, {\"price\":\"0.05\", \"size\":\"853.2\"}, {\"price\":\"0.06\", \"size\":\"553.2\"}, {\"price\":\"0.07\", \"size\":\"576.1\"}, {\"price\":\"0.08\", \"size\":\"550.79\"}, {\"price\":\"0.09\", \"size\":\"536.6\"}, {\"price\":\"0.1\", \"size\":\"118.29\"}, {\"price\":\"0.11\", \"size\":\"43.6\"}, {\"price\":\"0.12\", \"size\":\"50.4\"}, {\"price\":\"0.13\", \"size\":\"67.5\"}, {\"price\":\"0.14\", \"size\":\"34.9\"}, {\"price\":\"0.15\", \"size\":\"64.5\"}, {\"price\":\"0.16\", \"size\":\"71.3\"}, {\"price\":\"0.17\", \"size\":\"30.3\"}, {\"price\":\"0.18\", \"size\":\"28.3\"}, {\"price\":\"0.19\", \"size\":\"57.5\"}, {\"price\":\"0.2\", \"size\":\"59.8\"}, {\"price\":\"0.21\", \"size\":\"26.1\"}, {\"price\":\"0.22\", \"size\":\"54.5\"}, {\"price\":\"0.23\", \"size\":\"23.89\"}, {\"price\":\"0.24\", \"size\":\"23.39\"}, {\"price\":\"0.25\", \"size\":\"82\"}, {\"price\":\"0.26\", \"size\":\"21.6\"}, {\"price\":\"0.27\", \"size\":\"21.2\"}, {\"price\":\"0.28\", \"size\":\"50.9\"}, {\"price\":\"0.29\", \"size\":\"20.6\"}, {\"price\":\"0.3\", \"size\":\"47.3\"}, {\"price\":\"0.31\", \"size\":\"50\"}, {\"price\":\"0.32\", \"size\":\"19.8\"}, {\"price\":\"0.33\", \"size\":\"31.6\"}, {\"price\":\"0.34\", \"size\":\"49.4\"}, {\"price\":\"0.35\", \"size\":\"38.2\"}, {\"price\":\"0.36\", \"size\":\"18\"}, {\"price\":\"0.37\", \"size\":\"137.99\"}, {\"price\":\"0.38\", \"size\":\"27.7\"}, {\"price\":\"0.39\", \"size\":\"117.6\"}, {\"price\":\"0.4\", \"size\":\"161.5\"}, {\"price\":\"0.41\", \"size\":\"117.4\"}, {\"price\":\"0.42\", \"size\":\"162.63\"}, {\"price\":\"0.43\", \"size\":\"152.2\"}, {\"price\":\"0.44\", \"size\":\"117.2\"}, {\"price\":\"0.45\", \"size\":\"125.1\"}, {\"price\":\"0.46\", \"size\":\"147.1\"}, {\"price\":\"0.47\", \"size\":\"175\"}, {\"price\":\"0.48\", \"size\":\"159\"}, {\"price\":\"0.49\", \"size\":\"181\"}, {\"price\":\"0.5\", \"size\":\"160\"}, {\"price\":\"0.51\", \"size\":\"144\"}, {\"price\":\"0.52\", \"size\":\"219\"}, {\"price\":\"0.53\", \"size\":\"73\"}, {\"price\":\"0.54\", \"size\":\"96.6\"}, {\"price\":\"0.55\", \"size\":\"93.67\"}, {\"price\":\"0.56\", \"size\":\"121.32\"}, {\"price\":\"0.57\", \"size\":\"113.35\"}, {\"price\":\"0.58\", \"size\":\"99.82\"}, {\"price\":\"0.59\", \"size\":\"151.2\"}], \"asks\":[{\"price\":\"0.99\", \"size\":\"5853.02\"}, {\"price\":\"0.98\", \"size\":\"673.1\"}, {\"price\":\"0.97\", \"size\":\"909.76\"}, {\"price\":\"0.96\", \"size\":\"588.09\"}, {\"price\":\"0.95\", \"size\":\"676.2\"}, {\"price\":\"0.94\", \"size\":\"605.2\"}, {\"price\":\"0.93\", \"size\":\"565.1\"}, {\"price\":\"0.92\", \"size\":\"567.79\"}, {\"price\":\"0.91\", \"size\":\"581.6\"}, {\"price\":\"0.9\", \"size\":\"102.29\"}, {\"price\":\"0.89\", \"size\":\"43.6\"}, {\"price\":\"0.88\", \"size\":\"176.52\"}, {\"price\":\"0.87\", \"size\":\"37.5\"}, {\"price\":\"0.86\", \"size\":\"34.9\"}, {\"price\":\"0.85\", \"size\":\"151.57\"}, {\"price\":\"0.84\", \"size\":\"137.42\"}, {\"price\":\"0.83\", \"size\":\"30.3\"}, {\"price\":\"0.82\", \"size\":\"58.3\"}, {\"price\":\"0.81\", \"size\":\"27.5\"}, {\"price\":\"0.8\", \"size\":\"640.21\"}, {\"price\":\"0.79\", \"size\":\"56.1\"}, {\"price\":\"0.78\", \"size\":\"24.5\"}, {\"price\":\"0.77\", \"size\":\"23.89\"}, {\"price\":\"0.76\", \"size\":\"59.39\"}, {\"price\":\"0.75\", \"size\":\"258.91\"}, {\"price\":\"0.74\", \"size\":\"136.1\"}, {\"price\":\"0.73\", \"size\":\"166.2\"}, {\"price\":\"0.72\", \"size\":\"118.44\"}, {\"price\":\"0.71\", \"size\":\"106\"}, {\"price\":\"0.7\", \"size\":\"176.98\"}, {\"price\":\"0.69\", \"size\":\"125.74\"}, {\"price\":\"0.68\", \"size\":\"165.68\"}, {\"price\":\"0.67\", \"size\":\"183\"}, {\"price\":\"0.66\", \"size\":\"151\"}, {\"price\":\"0.65\", \"size\":\"133\"}, {\"price\":\"0.64\", \"size\":\"87\"}, {\"price\":\"0.63\", \"size\":\"38.61\"}, {\"price\":\"0.62\", \"size\":\"19\"}, {\"price\":\"0.61\", \"size\":\"6\"}, {\"price\":\"0.6\", \"size\":\"2.96\"}], \"hash\":\"a4cd3545603a486b1526239d2fc9d73fd2a20aac\", \"timestamp\":\"1785211521804\", \"event_type\":\"book\"}","received_at":"2026-07-28T04:05:21.798287Z","schema_version":"clob-market-ws.book.v1","sequence":null,"server_hash":"a4cd3545603a486b1526239d2fc9d73fd2a20aac","server_timestamp":"1785211521804","session_id":"2d607381e3054cee91998cdf45a4231c","source":"clob_market_ws"},"received_at":"2026-07-28T04:05:21.798287Z","record_id":"2499f182cc189816bf905f650d300286f6cf821608d814f61405794b12aa5b2c","schema_fingerprint":"dc2caa1c89c6a7426e2e07ff925910cd4d0a8a223a515d4092d91d6d127aacb6","schema_version":"edge-lab-recorder.raw.v1","sequence":null,"source":"clob_market_ws"}
{"event_at":null,"event_fingerprint":"71a5b59cab219eee084b0c571c87f56717b942a38f39f44db867c6aaa68c988c","payload":{"connection_id":"f6725804f86a4c4eb588e4d5ed7db029","detail":{"current_server_timestamp":"1785211521804","entity":"clob_market_ws:96600821790790307414914106093858868634329285205417149685270682748367152458577","previous_server_timestamp":"1785211521805"},"event_type":"anomaly.time_regression","kind":"diagnostic","monotonic_ns":313504866647958,"received_at":"2026-07-28T04:05:21.816354Z","schema_version":"edge-lab-recorder.anomaly.v1","session_id":"2d607381e3054cee91998cdf45a4231c","source":"clob_market_ws","trigger_frame_hash":"4b54763bf44b9cfd1b9ad81f1b712ecaf683e45c89f2dd0500f6282c48a66ec6","trigger_server_hash":"01e7079c59cc4f754367bd557cc09d37e2ffcc13"},"received_at":"2026-07-28T04:05:21.816354Z","record_id":"c0c59791d92aae6ec6c90531f025846d3a299e0a384e5d45d7d80485e2a435e3","schema_fingerprint":"cb1780324c96914017c24d4692a681315845f9745a5a4a3a289c5a43388b35c3","schema_version":"edge-lab-recorder.raw.v1","sequence":null,"source":"clob_market_ws"}
{"event_at":"2026-07-28T04:05:21.804000Z","event_fingerprint":"630b2c4f6d34f3f500e375f3cc8c209e749fb84e46ac5be5ff38f5e4db8809b7","payload":{"connection_id":"f6725804f86a4c4eb588e4d5ed7db029","event_at":"2026-07-28T04:05:21.804000Z","event_type":"book","frame_hash":"4b54763bf44b9cfd1b9ad81f1b712ecaf683e45c89f2dd0500f6282c48a66ec6","frame_index":0,"kind":"data","monotonic_ns":313504866289250,"payload":{"asks":[{"price":"0.99","size":"5888.02"},{"price":"0.98","size":"683.1"},{"price":"0.97","size":"613.1"},{"price":"0.96","size":"618.09"},{"price":"0.95","size":"853.2"},{"price":"0.94","size":"553.2"},{"price":"0.93","size":"576.1"},{"price":"0.92","size":"550.79"},{"price":"0.91","size":"536.6"},{"price":"0.9","size":"118.29"},{"price":"0.89","size":"43.6"},{"price":"0.88","size":"50.4"},{"price":"0.87","size":"67.5"},{"price":"0.86","size":"34.9"},{"price":"0.85","size":"64.5"},{"price":"0.84","size":"71.3"},{"price":"0.83","size":"30.3"},{"price":"0.82","size":"28.3"},{"price":"0.81","size":"57.5"},{"price":"0.8","size":"59.8"},{"price":"0.79","size":"26.1"},{"price":"0.78","size":"54.5"},{"price":"0.77","size":"23.89"},{"price":"0.76","size":"23.39"},{"price":"0.75","size":"82"},{"price":"0.74","size":"21.6"},{"price":"0.73","size":"21.2"},{"price":"0.72","size":"50.9"},{"price":"0.71","size":"20.6"},{"price":"0.7","size":"47.3"},{"price":"0.69","size":"50"},{"price":"0.68","size":"19.8"},{"price":"0.67","size":"31.6"},{"price":"0.66","size":"49.4"},{"price":"0.65","size":"38.2"},{"price":"0.64","size":"18"},{"price":"0.63","size":"137.99"},{"price":"0.62","size":"27.7"},{"price":"0.61","size":"117.6"},{"price":"0.6","size":"161.5"},{"price":"0.59","size":"117.4"},{"price":"0.58","size":"162.63"},{"price":"0.57","size":"152.2"},{"price":"0.56","size":"117.2"},{"price":"0.55","size":"125.1"},{"price":"0.54","size":"147.1"},{"price":"0.53","size":"175"},{"price":"0.52","size":"159"},{"price":"0.51","size":"181"},{"price":"0.5","size":"160"},{"price":"0.49","size":"144"},{"price":"0.48","size":"219"},{"price":"0.47","size":"73"},{"price":"0.46","size":"96.6"},{"price":"0.45","size":"93.67"},{"price":"0.44","size":"121.32"},{"price":"0.43","size":"113.35"},{"price":"0.42","size":"99.82"},{"price":"0.41","size":"151.2"}],"asset_id":"96600821790790307414914106093858868634329285205417149685270682748367152458577","bids":[{"price":"0.01","size":"5853.02"},{"price":"0.02","size":"673.1"},{"price":"0.03","size":"909.76"},{"price":"0.04","size":"588.09"},{"price":"0.05","size":"676.2"},{"price":"0.06","size":"605.2"},{"price":"0.07","size":"565.1"},{"price":"0.08","size":"567.79"},{"price":"0.09","size":"581.6"},{"price":"0.1","size":"102.29"},{"price":"0.11","size":"43.6"},{"price":"0.12","size":"176.52"},{"price":"0.13","size":"37.5"},{"price":"0.14","size":"34.9"},{"price":"0.15","size":"151.57"},{"price":"0.16","size":"137.42"},{"price":"0.17","size":"30.3"},{"price":"0.18","size":"58.3"},{"price":"0.19","size":"27.5"},{"price":"0.2","size":"640.21"},{"price":"0.21","size":"56.1"},{"price":"0.22","size":"24.5"},{"price":"0.23","size":"23.89"},{"price":"0.24","size":"59.39"},{"price":"0.25","size":"258.91"},{"price":"0.26","size":"136.1"},{"price":"0.27","size":"166.2"},{"price":"0.28","size":"118.44"},{"price":"0.29","size":"106"},{"price":"0.3","size":"176.98"},{"price":"0.31","size":"125.74"},{"price":"0.32","size":"165.68"},{"price":"0.33","size":"183"},{"price":"0.34","size":"151"},{"price":"0.35","size":"133"},{"price":"0.36","size":"87"},{"price":"0.37","size":"38.61"},{"price":"0.38","size":"19"},{"price":"0.39","size":"6"},{"price":"0.4","size":"2.96"}],"event_type":"book","hash":"01e7079c59cc4f754367bd557cc09d37e2ffcc13","market":"0xd412ce774cfcf8dc9f71164aac78783978aac7b03871702a3b8a481bd9dc9688","timestamp":"1785211521804"},"payload_hash":"edba64b99e8f3747d1253011b6eb47708cdeaec1a842045a859d8a95cb6a35c6","raw_frame":"{\"market\":\"0xd412ce774cfcf8dc9f71164aac78783978aac7b03871702a3b8a481bd9dc9688\", \"asset_id\":\"96600821790790307414914106093858868634329285205417149685270682748367152458577\", \"bids\":[{\"price\":\"0.01\", \"size\":\"5853.02\"}, {\"price\":\"0.02\", \"size\":\"673.1\"}, {\"price\":\"0.03\", \"size\":\"909.76\"}, {\"price\":\"0.04\", \"size\":\"588.09\"}, {\"price\":\"0.05\", \"size\":\"676.2\"}, {\"price\":\"0.06\", \"size\":\"605.2\"}, {\"price\":\"0.07\", \"size\":\"565.1\"}, {\"price\":\"0.08\", \"size\":\"567.79\"}, {\"price\":\"0.09\", \"size\":\"581.6\"}, {\"price\":\"0.1\", \"size\":\"102.29\"}, {\"price\":\"0.11\", \"size\":\"43.6\"}, {\"price\":\"0.12\", \"size\":\"176.52\"}, {\"price\":\"0.13\", \"size\":\"37.5\"}, {\"price\":\"0.14\", \"size\":\"34.9\"}, {\"price\":\"0.15\", \"size\":\"151.57\"}, {\"price\":\"0.16\", \"size\":\"137.42\"}, {\"price\":\"0.17\", \"size\":\"30.3\"}, {\"price\":\"0.18\", \"size\":\"58.3\"}, {\"price\":\"0.19\", \"size\":\"27.5\"}, {\"price\":\"0.2\", \"size\":\"640.21\"}, {\"price\":\"0.21\", \"size\":\"56.1\"}, {\"price\":\"0.22\", \"size\":\"24.5\"}, {\"price\":\"0.23\", \"size\":\"23.89\"}, {\"price\":\"0.24\", \"size\":\"59.39\"}, {\"price\":\"0.25\", \"size\":\"258.91\"}, {\"price\":\"0.26\", \"size\":\"136.1\"}, {\"price\":\"0.27\", \"size\":\"166.2\"}, {\"price\":\"0.28\", \"size\":\"118.44\"}, {\"price\":\"0.29\", \"size\":\"106\"}, {\"price\":\"0.3\", \"size\":\"176.98\"}, {\"price\":\"0.31\", \"size\":\"125.74\"}, {\"price\":\"0.32\", \"size\":\"165.68\"}, {\"price\":\"0.33\", \"size\":\"183\"}, {\"price\":\"0.34\", \"size\":\"151\"}, {\"price\":\"0.35\", \"size\":\"133\"}, {\"price\":\"0.36\", \"size\":\"87\"}, {\"price\":\"0.37\", \"size\":\"38.61\"}, {\"price\":\"0.38\", \"size\":\"19\"}, {\"price\":\"0.39\", \"size\":\"6\"}, {\"price\":\"0.4\", \"size\":\"2.96\"}], \"asks\":[{\"price\":\"0.99\", \"size\":\"5888.02\"}, {\"price\":\"0.98\", \"size\":\"683.1\"}, {\"price\":\"0.97\", \"size\":\"613.1\"}, {\"price\":\"0.96\", \"size\":\"618.09\"}, {\"price\":\"0.95\", \"size\":\"853.2\"}, {\"price\":\"0.94\", \"size\":\"553.2\"}, {\"price\":\"0.93\", \"size\":\"576.1\"}, {\"price\":\"0.92\", \"size\":\"550.79\"}, {\"price\":\"0.91\", \"size\":\"536.6\"}, {\"price\":\"0.9\", \"size\":\"118.29\"}, {\"price\":\"0.89\", \"size\":\"43.6\"}, {\"price\":\"0.88\", \"size\":\"50.4\"}, {\"price\":\"0.87\", \"size\":\"67.5\"}, {\"price\":\"0.86\", \"size\":\"34.9\"}, {\"price\":\"0.85\", \"size\":\"64.5\"}, {\"price\":\"0.84\", \"size\":\"71.3\"}, {\"price\":\"0.83\", \"size\":\"30.3\"}, {\"price\":\"0.82\", \"size\":\"28.3\"}, {\"price\":\"0.81\", \"size\":\"57.5\"}, {\"price\":\"0.8\", \"size\":\"59.8\"}, {\"price\":\"0.79\", \"size\":\"26.1\"}, {\"price\":\"0.78\", \"size\":\"54.5\"}, {\"price\":\"0.77\", \"size\":\"23.89\"}, {\"price\":\"0.76\", \"size\":\"23.39\"}, {\"price\":\"0.75\", \"size\":\"82\"}, {\"price\":\"0.74\", \"size\":\"21.6\"}, {\"price\":\"0.73\", \"size\":\"21.2\"}, {\"price\":\"0.72\", \"size\":\"50.9\"}, {\"price\":\"0.71\", \"size\":\"20.6\"}, {\"price\":\"0.7\", \"size\":\"47.3\"}, {\"price\":\"0.69\", \"size\":\"50\"}, {\"price\":\"0.68\", \"size\":\"19.8\"}, {\"price\":\"0.67\", \"size\":\"31.6\"}, {\"price\":\"0.66\", \"size\":\"49.4\"}, {\"price\":\"0.65\", \"size\":\"38.2\"}, {\"price\":\"0.64\", \"size\":\"18\"}, {\"price\":\"0.63\", \"size\":\"137.99\"}, {\"price\":\"0.62\", \"size\":\"27.7\"}, {\"price\":\"0.61\", \"size\":\"117.6\"}, {\"price\":\"0.6\", \"size\":\"161.5\"}, {\"price\":\"0.59\", \"size\":\"117.4\"}, {\"price\":\"0.58\", \"size\":\"162.63\"}, {\"price\":\"0.57\", \"size\":\"152.2\"}, {\"price\":\"0.56\", \"size\":\"117.2\"}, {\"price\":\"0.55\", \"size\":\"125.1\"}, {\"price\":\"0.54\", \"size\":\"147.1\"}, {\"price\":\"0.53\", \"size\":\"175\"}, {\"price\":\"0.52\", \"size\":\"159\"}, {\"price\":\"0.51\", \"size\":\"181\"}, {\"price\":\"0.5\", \"size\":\"160\"}, {\"price\":\"0.49\", \"size\":\"144\"}, {\"price\":\"0.48\", \"size\":\"219\"}, {\"price\":\"0.47\", \"size\":\"73\"}, {\"price\":\"0.46\", \"size\":\"96.6\"}, {\"price\":\"0.45\", \"size\":\"93.67\"}, {\"price\":\"0.44\", \"size\":\"121.32\"}, {\"price\":\"0.43\", \"size\":\"113.35\"}, {\"price\":\"0.42\", \"size\":\"99.82\"}, {\"price\":\"0.41\", \"size\":\"151.2\"}], \"hash\":\"01e7079c59cc4f754367bd557cc09d37e2ffcc13\", \"timestamp\":\"1785211521804\", \"event_type\":\"book\"}","received_at":"2026-07-28T04:05:21.815993Z","schema_version":"clob-market-ws.book.v1","sequence":null,"server_hash":"01e7079c59cc4f754367bd557cc09d37e2ffcc13","server_timestamp":"1785211521804","session_id":"2d607381e3054cee91998cdf45a4231c","source":"clob_market_ws"},"received_at":"2026-07-28T04:05:21.815993Z","record_id":"febdb1fe5120f202533ff9b54bebc8ea2a64479c52a2d46e96e0c01839e4a100","schema_fingerprint":"dc2caa1c89c6a7426e2e07ff925910cd4d0a8a223a515d4092d91d6d127aacb6","schema_version":"edge-lab-recorder.raw.v1","sequence":null,"source":"clob_market_ws"}
