{"event_at":"2026-07-28T04:12:06.073000Z","event_fingerprint":"e3d0ee0a28c6cf9157f397557519a3b59b69a1869dbb8e6691aaa839e2d6ab63","payload":{"connection_id":"f6725804f86a4c4eb588e4d5ed7db029","event_at":"2026-07-28T04:12:06.073000Z","event_type":"price_change","frame_hash":"a321620f282a0979d382dad1c9187a4dbc6d60912bff321dbfdbddd37657cf51","frame_index":0,"kind":"data","monotonic_ns":313911128020291,"payload":{"event_type":"price_change","market":"0xd412ce774cfcf8dc9f71164aac78783978aac7b03871702a3b8a481bd9dc9688","price_changes":[{"asset_id":"107603864457683460275633293642179940881969192120168665300712204232021063124301","best_ask":"0.58","best_bid":"0.57","hash":"c3f3f5432edd6aedcbfae3e5d56a1a9ff453d7ad","price":"0.05","side":"BUY","size":"620"},{"asset_id":"96600821790790307414914106093858868634329285205417149685270682748367152458577","best_ask":"0.43","best_bid":"0.42","hash":"8e2ae64555b9e32c05b990c844ed6ec533dc9650","price":"0.95","side":"SELL","size":"620"}],"timestamp":"1785211926073"},"payload_hash":"4e211203c997a5d6ed3702a482c05a8786bc121d927d6e8fa30a18f7d68f0469","raw_frame":"{\"market\":\"0xd412ce774cfcf8dc9f71164aac78783978aac7b03871702a3b8a481bd9dc9688\", \"price_changes\":[{\"asset_id\":\"107603864457683460275633293642179940881969192120168665300712204232021063124301\", \"price\":\"0.05\", \"size\":\"620\", \"side\":\"BUY\", \"hash\":\"c3f3f5432edd6aedcbfae3e5d56a1a9ff453d7ad\", \"best_bid\":\"0.57\", \"best_ask\":\"0.58\"}, {\"asset_id\":\"96600821790790307414914106093858868634329285205417149685270682748367152458577\", \"price\":\"0.95\", \"size\":\"620\", \"side\":\"SELL\", \"hash\":\"8e2ae64555b9e32c05b990c844ed6ec533dc9650\", \"best_bid\":\"0.42\", \"best_ask\":\"0.43\"}], \"timestamp\":\"1785211926073\", \"event_type\":\"price_change\"}","received_at":"2026-07-28T04:12:08.050838Z","schema_version":"clob-market-ws.price_change.v1","sequence":null,"server_hash":null,"server_timestamp":"1785211926073","session_id":"2d607381e3054cee91998cdf45a4231c","source":"clob_market_ws"},"received_at":"2026-07-28T04:12:08.050838Z","record_id":"ed033c2cf90774033b55beb942c81336c2ba853cde0208298a6be0bca11e5d5f","schema_fingerprint":"4aa3821a28b0b7c2400bc59aba4bcc0a76e971dadd19610d3ad38c768e124dc7","schema_version":"edge-lab-recorder.raw.v1","sequence":null,"source":"clob_market_ws"}
{"event_at":"2026-07-28T04:12:06.074000Z","event_fingerprint":"b866710bcb26fd7fb251496b359d1f1d0548f577b364edf1f3700b66837ef6de","payload":{"connection_id":"f6725804f86a4c4eb588e4d5ed7db029","event_at":"2026-07-28T04:12:06.074000Z","event_type":"price_change","frame_hash":"282d2a69b5bc58a945afcdb26aa90586cefca3f257ff9ceb17f9fb0525129448","frame_index":0,"kind":"data","monotonic_ns":313911139156125,"payload":{"event_type":"price_change","market":"0xd412ce774cfcf8dc9f71164aac78783978aac7b03871702a3b8a481bd9dc9688","price_changes":[{"asset_id":"96600821790790307414914106093858868634329285205417149685270682748367152458577","best_ask":"0.43","best_bid":"0.42","hash":"7b24ed37107ed0496a815d273329dec8b11c20e7","price":"0.03","side":"BUY","size":"673.33"},{"asset_id":"107603864457683460275633293642179940881969192120168665300712204232021063124301","best_ask":"0.58","best_bid":"0.57","hash":"97717eb100e4e87701eb543da4b5b4fc76e9bab4","price":"0.97","side":"SELL","size":"673.33"}],"timestamp":"1785211926074"},"payload_hash":"e6dfbf23105f7810c8b00f894d02328d40ba53d163721af3254c3fb5719a1634","raw_frame":"{\"market\":\"0xd412ce774cfcf8dc9f71164aac78783978aac7b03871702a3b8a481bd9dc9688\", \"price_changes\":[{\"asset_id\":\"96600821790790307414914106093858868634329285205417149685270682748367152458577\", \"price\":\"0.03\", \"size\":\"673.33\", \"side\":\"BUY\", \"hash\":\"7b24ed37107ed0496a815d273329dec8b11c20e7\", \"best_bid\":\"0.42\", \"best_ask\":\"0.43\"}, {\"asset_id\":\"107603864457683460275633293642179940881969192120168665300712204232021063124301\", \"price\":\"0.97\", \"size\":\"673.33\", \"side\":\"SELL\", \"hash\":\"97717eb100e4e87701eb543da4b5b4fc76e9bab4\", \"best_bid\":\"0.57\", \"best_ask\":\"0.58\"}], \"timestamp\":\"1785211926074\", \"event_type\":\"price_change\"}","received_at":"2026-07-28T04:12:08.061975Z","schema_version":"clob-market-ws.price_change.v1","sequence":null,"server_hash":null,"server_timestamp":"1785211926074","session_id":"2d607381e3054cee91998cdf45a4231c","source":"clob_market_ws"},"received_at":"2026-07-28T04:12:08.061975Z","record_id":"69da78bceeabf44966697076b2f68141d82de453de6cc2b7b17224e6d215217b","schema_fingerprint":"4aa3821a28b0b7c2400bc59aba4bcc0a76e971dadd19610d3ad38c768e124dc7","schema_version":"edge-lab-recorder.raw.v1","sequence":null,"source":"clob_market_ws"}
{"event_at":"2026-07-28T04:12:06.084000Z","event_fingerprint":"f7b283b48b8ee8a7c6a0d4655fed8866f22b4663045aeca07c3b6cc68c3a8f7b","payload":{"connection_id":"f6725804f86a4c4eb588e4d5ed7db029","event_at":"2026-07-28T04:12:06.084000Z","event_type":"price_change","frame_hash":"c848fec69c61f757b3a26690b7c266278a7287c01ad86770bede9625c4e61db1","frame_index":0,"kind":"data","monotonic_ns":313911143586750,"payload":{"event_type":"price_change","market":"0xd412ce774cfcf8dc9f71164aac78783978aac7b03871702a3b8a481bd9dc9688","price_changes":[{"asset_id":"96600821790790307414914106093858868634329285205417149685270682748367152458577","best_ask":"0.43","best_bid":"0.42","hash":"8520eb411067f4e8432536f6c41e406a3aa8a06c","price":"0.36","side":"BUY","size":"150"},{"asset_id":"107603864457683460275633293642179940881969192120168665300712204232021063124301","best_ask":"0.58","best_bid":"0.57","hash":"eb9b1b7b2690c4ab7542ea5f6ce8fa854026bdc6","price":"0.64","side":"SELL","size":"150"}],"timestamp":"1785211926084"},"payload_hash":"8f6747f6daeab65e5608c7e2b5775b2828ad948f8ab254ca5464cee8dea52423","raw_frame":"{\"market\":\"0xd412ce774cfcf8dc9f71164aac78783978aac7b03871702a3b8a481bd9dc9688\", \"price_changes\":[{\"asset_id\":\"96600821790790307414914106093858868634329285205417149685270682748367152458577\", \"price\":\"0.36\", \"size\":\"150\", \"side\":\"BUY\", \"hash\":\"8520eb411067f4e8432536f6c41e406a3aa8a06c\", \"best_bid\":\"0.42\", \"best_ask\":\"0.43\"}, {\"asset_id\":\"107603864457683460275633293642179940881969192120168665300712204232021063124301\", \"price\":\"0.64\", \"size\":\"150\", \"side\":\"SELL\", \"hash\":\"eb9b1b7b2690c4ab7542ea5f6ce8fa854026bdc6\", \"best_bid\":\"0.57\", \"best_ask\":\"0.58\"}], \"timestamp\":\"1785211926084\", \"event_type\":\"price_change\"}","received_at":"2026-07-28T04:12:08.066405Z","schema_version":"clob-market-ws.price_change.v1","sequence":null,"server_hash":null,"server_timestamp":"1785211926084","session_id":"2d607381e3054cee91998cdf45a4231c","source":"clob_market_ws"},"received_at":"2026-07-28T04:12:08.066405Z","record_id":"336bc6ebc7dcf0d8cb869d61843540e5c56cafd091626bd67e30bb719f9f8ace","schema_fingerprint":"4aa3821a28b0b7c2400bc59aba4bcc0a76e971dadd19610d3ad38c768e124dc7","schema_version":"edge-lab-recorder.raw.v1","sequence":null,"source":"clob_market_ws"}
{"event_at":"2026-07-28T04:12:06.101000Z","event_fingerprint":"7dd07e98f0b387b47336740ce5f9b8898e7f33e8bf9fcc58b699d1c02581eed3","payload":{"connection_id":"f6725804f86a4c4eb588e4d5ed7db029","event_at":"2026-07-28T04:12:06.101000Z","event_type":"price_change","frame_hash":"d7137379fadf9cbbf67f6729494e8da1d074125958dc9722e8faf9e91cfa1844","frame_index":0,"kind":"data","monotonic_ns":313911148098666,"payload":{"event_type":"price_change","market":"0xd412ce774cfcf8dc9f71164aac78783978aac7b03871702a3b8a481bd9dc9688","price_changes":[{"asset_id":"96600821790790307414914106093858868634329285205417149685270682748367152458577","best_ask":"0.43","best_bid":"0.42","hash":"ca5060f943ff8762c4989eb3da8206fec58cdf09","price":"0.36","side":"BUY","size":"107"},{"asset_id":"107603864457683460275633293642179940881969192120168665300712204232021063124301","best_ask":"0.58","best_bid":"0.57","hash":"df221f17bb660f1829ebfd3bb8e42fc0f9f03ae6","price":"0.64","side":"SELL","size":"107"}],"timestamp":"1785211926101"},"payload_hash":"c3cfc01280a34dc12f3e63236fe4dde0205fd9a90e7b3daa2635f1d2a518af3b","raw_frame":"{\"market\":\"0xd412ce774cfcf8dc9f71164aac78783978aac7b03871702a3b8a481bd9dc9688\", \"price_changes\":[{\"asset_id\":\"96600821790790307414914106093858868634329285205417149685270682748367152458577\", \"price\":\"0.36\", \"size\":\"107\", \"side\":\"BUY\", \"hash\":\"ca5060f943ff8762c4989eb3da8206fec58cdf09\", \"best_bid\":\"0.42\", \"best_ask\":\"0.43\"}, {\"asset_id\":\"107603864457683460275633293642179940881969192120168665300712204232021063124301\", \"price\":\"0.64\", \"size\":\"107\", \"side\":\"SELL\", \"hash\":\"df221f17bb660f1829ebfd3bb8e42fc0f9f03ae6\", \"best_bid\":\"0.57\", \"best_ask\":\"0.58\"}], \"timestamp\":\"1785211926101\", \"event_type\":\"price_change\"}","received_at":"2026-07-28T04:12:08.070917Z","schema_version":"clob-market-ws.price_change.v1","sequence":null,"server_hash":null,"server_timestamp":"1785211926101","session_id":"2d607381e3054cee91998cdf45a4231c","source":"clob_market_ws"},"received_at":"2026-07-28T04:12:08.070917Z","record_id":"337c21e6a3cbc4eb750540f59362546a860d5ffc301d91e79c1c6c772067bb2f","schema_fingerprint":"4aa3821a28b0b7c2400bc59aba4bcc0a76e971dadd19610d3ad38c768e124dc7","schema_version":"edge-lab-recorder.raw.v1","sequence":null,"source":"clob_market_ws"}
{"event_at":"2026-07-28T04:12:06.104000Z","event_fingerprint":"ccd1e1277f3a8563170c505e1a251b401e5b1fff9a484baa745208670fe783fa","payload":{"connection_id":"f6725804f86a4c4eb588e4d5ed7db029","event_at":"2026-07-28T04:12:06.104000Z","event_type":"price_change","frame_hash":"702bc4dd0f913c7bf8c0efc6c75d9f1f1a05afc3a13c640fc953bd893bdaeebf","frame_index":0,"kind":"data","monotonic_ns":313911152583291,"payload":{"event_type":"price_change","market":"0xd412ce774cfcf8dc9f71164aac78783978aac7b03871702a3b8a481bd9dc9688","price_changes":[{"asset_id":"107603864457683460275633293642179940881969192120168665300712204232021063124301","best_ask":"0.58","best_bid":"0.57","hash":"dfabafb1cf93a6d4782236498008efdd8a4396c7","price":"0.64","side":"SELL","size":"151"},{"asset_id":"96600821790790307414914106093858868634329285205417149685270682748367152458577","best_ask":"0.43","best_bid":"0.42","hash":"d07c567ccd194916007f3ee9023909d9b7f179bd","price":"0.36","side":"BUY","size":"151"}],"timestamp":"1785211926104"},"payload_hash":"e9957e0d4b14b8fe4febff4026aa77d2235126440e6de4975c5d7e3dde917fe8","raw_frame":"{\"market\":\"0xd412ce774cfcf8dc9f71164aac78783978aac7b03871702a3b8a481bd9dc9688\", \"price_changes\":[{\"asset_id\":\"107603864457683460275633293642179940881969192120168665300712204232021063124301\", \"price\":\"0.64\", \"size\":\"151\", \"side\":\"SELL\", \"hash\":\"dfabafb1cf93a6d4782236498008efdd8a4396c7\", \"best_bid\":\"0.57\", \"best_ask\":\"0.58\"}, {\"asset_id\":\"96600821790790307414914106093858868634329285205417149685270682748367152458577\", \"price\":\"0.36\", \"size\":\"151\", \"side\":\"BUY\", \"hash\":\"d07c567ccd194916007f3ee9023909d9b7f179bd\", \"best_bid\":\"0.42\", \"best_ask\":\"0.43\"}], \"timestamp\":\"1785211926104\", \"event_type\":\"price_change\"}","received_at":"2026-07-28T04:12:08.075401Z","schema_version":"clob-market-ws.price_change.v1","sequence":null,"server_hash":null,"server_timestamp":"1785211926104","session_id":"2d607381e3054cee91998cdf45a4231c","source":"clob_market_ws"},"received_at":"2026-07-28T04:12:08.075401Z","record_id":"eacbd59c5a17e5ac0bdd707c78cc39269943999cd45513d0800b7ef0cc13af3f","schema_fingerprint":"4aa3821a28b0b7c2400bc59aba4bcc0a76e971dadd19610d3ad38c768e124dc7","schema_version":"edge-lab-recorder.raw.v1","sequence":null,"source":"clob_market_ws"}
{"event_at":"2026-07-28T04:12:06.111000Z","event_fingerprint":"9d41e473247382500cc1168d737a684be6382d346775513e8cc37ebf1c785277","payload":{"connection_id":"f6725804f86a4c4eb588e4d5ed7db029","event_at":"2026-07-28T04:12:06.111000Z","event_type":"price_change","frame_hash":"ea060cfb9a65be9bbba557154974502cda7277d3da1a0d1138ac75ff39e1285d","frame_index":0,"kind":"data","monotonic_ns":313911156957000,"payload":{"event_type":"price_change","market":"0xd412ce774cfcf8dc9f71164aac78783978aac7b03871702a3b8a481bd9dc9688","price_changes":[{"asset_id":"107603864457683460275633293642179940881969192120168665300712204232021063124301","best_ask":"0.58","best_bid":"0.57","hash":"3e789b44b406a2c77f54a446b39925466518d92f","price":"0.65","side":"SELL","size":"85.97"},{"asset_id":"96600821790790307414914106093858868634329285205417149685270682748367152458577","best_ask":"0.43","best_bid":"0.42","hash":"7e6eb9cf432b3fea30539825d0c74332812ad004","price":"0.35","side":"BUY","size":"85.97"}],"timestamp":"1785211926111"},"payload_hash":"dbb8575ef69b3242112227b696e13a3466dbb300fbb85ddb538c02e92e52394d","raw_frame":"{\"market\":\"0xd412ce774cfcf8dc9f71164aac78783978aac7b03871702a3b8a481bd9dc9688\", \"price_changes\":[{\"asset_id\":\"107603864457683460275633293642179940881969192120168665300712204232021063124301\", \"price\":\"0.65\", \"size\":\"85.97\", \"side\":\"SELL\", \"hash\":\"3e789b44b406a2c77f54a446b39925466518d92f\", \"best_bid\":\"0.57\", \"best_ask\":\"0.58\"}, {\"asset_id\":\"96600821790790307414914106093858868634329285205417149685270682748367152458577\", \"price\":\"0.35\", \"size\":\"85.97\", \"side\":\"BUY\", \"hash\":\"7e6eb9cf432b3fea30539825d0c74332812ad004\", \"best_bid\":\"0.42\", \"best_ask\":\"0.43\"}], \"timestamp\":\"1785211926111\", \"event_type\":\"price_change\"}","received_at":"2026-07-28T04:12:08.079775Z","schema_version":"clob-market-ws.price_change.v1","sequence":null,"server_hash":null,"server_timestamp":"1785211926111","session_id":"2d607381e3054cee91998cdf45a4231c","source":"clob_market_ws"},"received_at":"2026-07-28T04:12:08.079775Z","record_id":"5809e4eb4d53ed7ffae9f44e075bf41edd7cc9b48f31e3d7e5dbe02044ec3d3d","schema_fingerprint":"4aa3821a28b0b7c2400bc59aba4bcc0a76e971dadd19610d3ad38c768e124dc7","schema_version":"edge-lab-recorder.raw.v1","sequence":null,"source":"clob_market_ws"}
{"event_at":"2026-07-28T04:12:06.165000Z","event_fingerprint":"18100562ee0b79067ad9bf06eb346ca6b6b5003bbd9961572c019e32e83f789e","payload":{"connection_id":"f6725804f86a4c4eb588e4d5ed7db029","event_at":"2026-07-28T04:12:06.165000Z","event_type":"price_change","frame_hash":"3520bf1bb35a3c9b9849b1b9e07183ca9c8bb2496532d3c221d932cc32fae5fa","frame_index":0,"kind":"data","monotonic_ns":313911161233250,"payload":{"event_type":"price_change","market":"0xd412ce774cfcf8dc9f71164aac78783978aac7b03871702a3b8a481bd9dc9688","price_changes":[{"asset_id":"96600821790790307414914106093858868634329285205417149685270682748367152458577","best_ask":"0.43","best_bid":"0.42","hash":"8f62e6469f6573563c388b3a23af54347fc25a2a","price":"0.4","side":"BUY","size":"44.2"},{"asset_id":"107603864457683460275633293642179940881969192120168665300712204232021063124301","best_ask":"0.58","best_bid":"0.57","hash":"35f4c6ed339bd18637c9d3562d93e365227fff6f","price":"0.6","side":"SELL","size":"44.2"}],"timestamp":"1785211926165"},"payload_hash":"ee9e8891cf85b9d9b4e1343c08c7b495c2715c16adce65e25aa46f1619ea75d2","raw_frame":"{\"market\":\"0xd412ce774cfcf8dc9f71164aac78783978aac7b03871702a3b8a481bd9dc9688\", \"price_changes\":[{\"asset_id\":\"96600821790790307414914106093858868634329285205417149685270682748367152458577\", \"price\":\"0.4\", \"size\":\"44.2\", \"side\":\"BUY\", \"hash\":\"8f62e6469f6573563c388b3a23af54347fc25a2a\", \"best_bid\":\"0.42\", \"best_ask\":\"0.43\"}, {\"asset_id\":\"107603864457683460275633293642179940881969192120168665300712204232021063124301\", \"price\":\"0.6\", \"size\":\"44.2\", \"side\":\"SELL\", \"hash\":\"35f4c6ed339bd18637c9d3562d93e365227fff6f\", \"best_bid\":\"0.57\", \"best_ask\":\"0.58\"}], \"timestamp\":\"1785211926165\", \"event_type\":\"price_change\"}","received_at":"2026-07-28T04:12:08.084051Z","schema_version":"clob-market-ws.price_change.v1","sequence":null,"server_hash":null,"server_timestamp":"1785211926165","session_id":"2d607381e3054cee91998cdf45a4231c","source":"clob_market_ws"},"received_at":"2026-07-28T04:12:08.084051Z","record_id":"73719c6c441dc8a3c95d7e0eb0ddb7664aff07077e77b41774d08f5c9c8ed0f3","schema_fingerprint":"4aa3821a28b0b7c2400bc59aba4bcc0a76e971dadd19610d3ad38c768e124dc7","schema_version":"edge-lab-recorder.raw.v1","sequence":null,"source":"clob_market_ws"}
{"event_at":"2026-07-28T04:12:06.186000Z","event_fingerprint":"b7175bbd97030f80c4056b272079f7b2f20c37e0a30c15476b54bdb86068b14a","payload":{"connection_id":"f6725804f86a4c4eb588e4d5ed7db029","event_at":"2026-07-28T04:12:06.186000Z","event_type":"price_change","frame_hash":"02985873ff50c447332a1ef2752df0c34b34491b194bbf098dad977f1fd65506","frame_index":0,"kind":"data","monotonic_ns":313911165489541,"payload":{"event_type":"price_change","market":"0xd412ce774cfcf8dc9f71164aac78783978aac7b03871702a3b8a481bd9dc9688","price_changes":[{"asset_id":"96600821790790307414914106093858868634329285205417149685270682748367152458577","best_ask":"0.43","best_bid":"0.42","hash":"f26cc6d1cd336a2af89515d97b57f64026cbf2c5","price":"0.37","side":"BUY","size":"112.6"},{"asset_id":"107603864457683460275633293642179940881969192120168665300712204232021063124301","best_ask":"0.58","best_bid":"0.57","hash":"904803b9ef0c39dbf53757c9fa2264d81ad41c83","price":"0.63","side":"SELL","size":"112.6"}],"timestamp":"1785211926186"},"payload_hash":"de3f89a4a74a81a1d0b3c41a697d8e2f7365aa30b35ffe4b30816f603cb9ca14","raw_frame":"{\"market\":\"0xd412ce774cfcf8dc9f71164aac78783978aac7b03871702a3b8a481bd9dc9688\", \"price_changes\":[{\"asset_id\":\"96600821790790307414914106093858868634329285205417149685270682748367152458577\", \"price\":\"0.37\", \"size\":\"112.6\", \"side\":\"BUY\", \"hash\":\"f26cc6d1cd336a2af89515d97b57f64026cbf2c5\", \"best_bid\":\"0.42\", \"best_ask\":\"0.43\"}, {\"asset_id\":\"107603864457683460275633293642179940881969192120168665300712204232021063124301\", \"price\":\"0.63\", \"size\":\"112.6\", \"side\":\"SELL\", \"hash\":\"904803b9ef0c39dbf53757c9fa2264d81ad41c83\", \"best_bid\":\"0.57\", \"best_ask\":\"0.58\"}], \"timestamp\":\"1785211926186\", \"event_type\":\"price_change\"}","received_at":"2026-07-28T04:12:08.088307Z","schema_version":"clob-market-ws.price_change.v1","sequence":null,"server_hash":null,"server_timestamp":"1785211926186","session_id":"2d607381e3054cee91998cdf45a4231c","source":"clob_market_ws"},"received_at":"2026-07-28T04:12:08.088307Z","record_id":"4410ebc42d938f95c346e4aa46e2cb15c9c4940dfddb86b9cd6fb7a67c7ab19f","schema_fingerprint":"4aa3821a28b0b7c2400bc59aba4bcc0a76e971dadd19610d3ad38c768e124dc7","schema_version":"edge-lab-recorder.raw.v1","sequence":null,"source":"clob_market_ws"}
{"event_at":"2026-07-28T04:12:06.191000Z","event_fingerprint":"2cfb7b7493b18d57005927aa9bb7798fef0c5917265ef8c284d1f11fa3c583b5","payload":{"connection_id":"f6725804f86a4c4eb588e4d5ed7db029","event_at":"2026-07-28T04:12:06.191000Z","event_type":"price_change","frame_hash":"c77878db9637296c84f701c1103cddda1f6ca5961d8c8986c812f62c4f4a3233","frame_index":0,"kind":"data","monotonic_ns":313911169700791,"payload":{"event_type":"price_change","market":"0xd412ce774cfcf8dc9f71164aac78783978aac7b03871702a3b8a481bd9dc9688","price_changes":[{"asset_id":"107603864457683460275633293642179940881969192120168665300712204232021063124301","best_ask":"0.58","best_bid":"0.57","hash":"139c120978f6425455bc693796668e9627d0a253","price":"0.01","side":"BUY","size":"5335.02"},{"asset_id":"96600821790790307414914106093858868634329285205417149685270682748367152458577","best_ask":"0.43","best_bid":"0.42","hash":"df2e029be4c3f61dfb7b0b237bac5679701ce3ca","price":"0.99","side":"SELL","size":"5335.02"}],"timestamp":"1785211926191"},"payload_hash":"8d14d3d0bee787e709c8ff3c1ce623830eb5b97cd752ad46827923e36c15c69d","raw_frame":"{\"market\":\"0xd412ce774cfcf8dc9f71164aac78783978aac7b03871702a3b8a481bd9dc9688\", \"price_changes\":[{\"asset_id\":\"107603864457683460275633293642179940881969192120168665300712204232021063124301\", \"price\":\"0.01\", \"size\":\"5335.02\", \"side\":\"BUY\", \"hash\":\"139c120978f6425455bc693796668e9627d0a253\", \"best_bid\":\"0.57\", \"best_ask\":\"0.58\"}, {\"asset_id\":\"96600821790790307414914106093858868634329285205417149685270682748367152458577\", \"price\":\"0.99\", \"size\":\"5335.02\", \"side\":\"SELL\", \"hash\":\"df2e029be4c3f61dfb7b0b237bac5679701ce3ca\", \"best_bid\":\"0.42\", \"best_ask\":\"0.43\"}], \"timestamp\":\"1785211926191\", \"event_type\":\"price_change\"}","received_at":"2026-07-28T04:12:08.092519Z","schema_version":"clob-market-ws.price_change.v1","sequence":null,"server_hash":null,"server_timestamp":"1785211926191","session_id":"2d607381e3054cee91998cdf45a4231c","source":"clob_market_ws"},"received_at":"2026-07-28T04:12:08.092519Z","record_id":"0ca80a67ded13912bb226b0544b35738a1e99cfc74acd649321637095cfb6a2f","schema_fingerprint":"4aa3821a28b0b7c2400bc59aba4bcc0a76e971dadd19610d3ad38c768e124dc7","schema_version":"edge-lab-recorder.raw.v1","sequence":null,"source":"clob_market_ws"}
{"event_at":"2026-07-28T04:12:06.195000Z","event_fingerprint":"be17c8a4bc522736f7ccb14b944c347a69b2750e2e51f09053396a03be2c2810","payload":{"connection_id":"f6725804f86a4c4eb588e4d5ed7db029","event_at":"2026-07-28T04:12:06.195000Z","event_type":"price_change","frame_hash":"0fa20d9ac4224a1697b5b9dd8bad6dea1f5d42ea7223240f0516b4ee01f65c8f","frame_index":0,"kind":"data","monotonic_ns":313911176871583,"payload":{"event_type":"price_change","market":"0xd412ce774cfcf8dc9f71164aac78783978aac7b03871702a3b8a481bd9dc9688","price_changes":[{"asset_id":"107603864457683460275633293642179940881969192120168665300712204232021063124301","best_ask":"0.58","best_bid":"0.57","hash":"9d949b686a3ff78310cb99de186695ebc5f9c337","price":"0.51","side":"BUY","size":"50"},{"asset_id":"96600821790790307414914106093858868634329285205417149685270682748367152458577","best_ask":"0.43","best_bid":"0.42","hash":"d951079ee262e170f692e0e520e2b7a8eedd7f04","price":"0.49","side":"SELL","size":"50"}],"timestamp":"1785211926195"},"payload_hash":"11ffc0cd7d19562476fbc2efef1711f20cceedcdba76a4f856435d7cf8d4bb02","raw_frame":"{\"market\":\"0xd412ce774cfcf8dc9f71164aac78783978aac7b03871702a3b8a481bd9dc9688\", \"price_changes\":[{\"asset_id\":\"107603864457683460275633293642179940881969192120168665300712204232021063124301\", \"price\":\"0.51\", \"size\":\"50\", \"side\":\"BUY\", \"hash\":\"9d949b686a3ff78310cb99de186695ebc5f9c337\", \"best_bid\":\"0.57\", \"best_ask\":\"0.58\"}, {\"asset_id\":\"96600821790790307414914106093858868634329285205417149685270682748367152458577\", \"price\":\"0.49\", \"size\":\"50\", \"side\":\"SELL\", \"hash\":\"d951079ee262e170f692e0e520e2b7a8eedd7f04\", \"best_bid\":\"0.42\", \"best_ask\":\"0.43\"}], \"timestamp\":\"1785211926195\", \"event_type\":\"price_change\"}","received_at":"2026-07-28T04:12:08.099690Z","schema_version":"clob-market-ws.price_change.v1","sequence":null,"server_hash":null,"server_timestamp":"1785211926195","session_id":"2d607381e3054cee91998cdf45a4231c","source":"clob_market_ws"},"received_at":"2026-07-28T04:12:08.099690Z","record_id":"a6b89c51a0df666c27c4a29e977c9b5da58df058cb607f301a909d68b2e3620f","schema_fingerprint":"4aa3821a28b0b7c2400bc59aba4bcc0a76e971dadd19610d3ad38c768e124dc7","schema_version":"edge-lab-recorder.raw.v1","sequence":null,"source":"clob_market_ws"}
