{"event_at":"2026-07-28T04:00:25.839000Z","event_fingerprint":"9ed3df6b0eeddc79ce804da9ea56d5656a4cd4edbac8d4a1f3acfa0817438926","payload":{"connection_id":"f6725804f86a4c4eb588e4d5ed7db029","event_at":"2026-07-28T04:00:25.839000Z","event_type":"price_change","frame_hash":"0621ce410c73280878df666d508fb438deaeb22afdf002b8e06b5250eb0a5116","frame_index":0,"kind":"data","monotonic_ns":313212293814208,"payload":{"event_type":"price_change","market":"0xd412ce774cfcf8dc9f71164aac78783978aac7b03871702a3b8a481bd9dc9688","price_changes":[{"asset_id":"107603864457683460275633293642179940881969192120168665300712204232021063124301","best_ask":"0.46","best_bid":"0.45","hash":"22b523a9452507f01f69a02040b9d272c81c5e00","price":"0.45","side":"BUY","size":"10"},{"asset_id":"96600821790790307414914106093858868634329285205417149685270682748367152458577","best_ask":"0.55","best_bid":"0.54","hash":"916d16b06490b06d166c472d7b132de0f0c38475","price":"0.55","side":"SELL","size":"10"}],"timestamp":"1785211225839"},"payload_hash":"dabd6df34b3bdc18d839135e140328487bdafbc88db32dc6e936f44dfcfa7c36","raw_frame":"{\"market\":\"0xd412ce774cfcf8dc9f71164aac78783978aac7b03871702a3b8a481bd9dc9688\", \"price_changes\":[{\"asset_id\":\"107603864457683460275633293642179940881969192120168665300712204232021063124301\", \"price\":\"0.45\", \"size\":\"10\", \"side\":\"BUY\", \"hash\":\"22b523a9452507f01f69a02040b9d272c81c5e00\", \"best_bid\":\"0.45\", \"best_ask\":\"0.46\"}, {\"asset_id\":\"96600821790790307414914106093858868634329285205417149685270682748367152458577\", \"price\":\"0.55\", \"size\":\"10\", \"side\":\"SELL\", \"hash\":\"916d16b06490b06d166c472d7b132de0f0c38475\", \"best_bid\":\"0.54\", \"best_ask\":\"0.55\"}], \"timestamp\":\"1785211225839\", \"event_type\":\"price_change\"}","received_at":"2026-07-28T04:00:29.245688Z","schema_version":"clob-market-ws.price_change.v1","sequence":null,"server_hash":null,"server_timestamp":"1785211225839","session_id":"2d607381e3054cee91998cdf45a4231c","source":"clob_market_ws"},"received_at":"2026-07-28T04:00:29.245688Z","record_id":"18fbbb93e4a64812fb51ff3dae70237245f468a4f2cf5b58494f27d8295e74e6","schema_fingerprint":"4aa3821a28b0b7c2400bc59aba4bcc0a76e971dadd19610d3ad38c768e124dc7","schema_version":"edge-lab-recorder.raw.v1","sequence":null,"source":"clob_market_ws"}
{"event_at":"2026-07-28T04:00:25.841000Z","event_fingerprint":"e3d295a79ec70ae0dd07fbe1bee91f9bc5d2886f23ae3d11caff2af89c800cc3","payload":{"connection_id":"f6725804f86a4c4eb588e4d5ed7db029","event_at":"2026-07-28T04:00:25.841000Z","event_type":"price_change","frame_hash":"e7b5749aed0bfbf65eae5b9b302423392fad111549665a441b51fa048e6603db","frame_index":0,"kind":"data","monotonic_ns":313212305885875,"payload":{"event_type":"price_change","market":"0xd412ce774cfcf8dc9f71164aac78783978aac7b03871702a3b8a481bd9dc9688","price_changes":[{"asset_id":"107603864457683460275633293642179940881969192120168665300712204232021063124301","best_ask":"0.46","best_bid":"0.45","hash":"b0e462958c986e0132fd2324ce886df2c1ce1ae4","price":"0.4","side":"BUY","size":"202.92"},{"asset_id":"96600821790790307414914106093858868634329285205417149685270682748367152458577","best_ask":"0.55","best_bid":"0.54","hash":"750170a3cfc6e1cc0e1c43059e22ac35572ee90c","price":"0.6","side":"SELL","size":"202.92"}],"timestamp":"1785211225841"},"payload_hash":"d87639ee74ee4b45d7c8134c61f96dc680b9febb773969791c83bf4c738ae07c","raw_frame":"{\"market\":\"0xd412ce774cfcf8dc9f71164aac78783978aac7b03871702a3b8a481bd9dc9688\", \"price_changes\":[{\"asset_id\":\"107603864457683460275633293642179940881969192120168665300712204232021063124301\", \"price\":\"0.4\", \"size\":\"202.92\", \"side\":\"BUY\", \"hash\":\"b0e462958c986e0132fd2324ce886df2c1ce1ae4\", \"best_bid\":\"0.45\", \"best_ask\":\"0.46\"}, {\"asset_id\":\"96600821790790307414914106093858868634329285205417149685270682748367152458577\", \"price\":\"0.6\", \"size\":\"202.92\", \"side\":\"SELL\", \"hash\":\"750170a3cfc6e1cc0e1c43059e22ac35572ee90c\", \"best_bid\":\"0.54\", \"best_ask\":\"0.55\"}], \"timestamp\":\"1785211225841\", \"event_type\":\"price_change\"}","received_at":"2026-07-28T04:00:29.257760Z","schema_version":"clob-market-ws.price_change.v1","sequence":null,"server_hash":null,"server_timestamp":"1785211225841","session_id":"2d607381e3054cee91998cdf45a4231c","source":"clob_market_ws"},"received_at":"2026-07-28T04:00:29.257760Z","record_id":"947c09a035089bded6ccec958792f0539ce96d57344dbbddefb612cc79ab4748","schema_fingerprint":"4aa3821a28b0b7c2400bc59aba4bcc0a76e971dadd19610d3ad38c768e124dc7","schema_version":"edge-lab-recorder.raw.v1","sequence":null,"source":"clob_market_ws"}
{"event_at":"2026-07-28T04:00:25.841000Z","event_fingerprint":"a18992f1022f1ed012dba2d89f5aadcc4501035781687190c8cf53ea9b818780","payload":{"connection_id":"f6725804f86a4c4eb588e4d5ed7db029","event_at":"2026-07-28T04:00:25.841000Z","event_type":"price_change","frame_hash":"57a2730bb4b84264f603363cf5626c8b859b7fcc8e0607f1091e09597624ce32","frame_index":0,"kind":"data","monotonic_ns":313212315740583,"payload":{"event_type":"price_change","market":"0xd412ce774cfcf8dc9f71164aac78783978aac7b03871702a3b8a481bd9dc9688","price_changes":[{"asset_id":"107603864457683460275633293642179940881969192120168665300712204232021063124301","best_ask":"0.46","best_bid":"0.45","hash":"8473f7c18c5a31b281e81705121eb1a144ddd75e","price":"0.42","side":"BUY","size":"116.27"},{"asset_id":"96600821790790307414914106093858868634329285205417149685270682748367152458577","best_ask":"0.55","best_bid":"0.54","hash":"7c84120d73367057d6185c1055cc11ef3909c773","price":"0.58","side":"SELL","size":"116.27"}],"timestamp":"1785211225841"},"payload_hash":"673bf9df7cdd7b7ac61ec6b273165c23df7b7429a114547e603b92b11673354e","raw_frame":"{\"market\":\"0xd412ce774cfcf8dc9f71164aac78783978aac7b03871702a3b8a481bd9dc9688\", \"price_changes\":[{\"asset_id\":\"107603864457683460275633293642179940881969192120168665300712204232021063124301\", \"price\":\"0.42\", \"size\":\"116.27\", \"side\":\"BUY\", \"hash\":\"8473f7c18c5a31b281e81705121eb1a144ddd75e\", \"best_bid\":\"0.45\", \"best_ask\":\"0.46\"}, {\"asset_id\":\"96600821790790307414914106093858868634329285205417149685270682748367152458577\", \"price\":\"0.58\", \"size\":\"116.27\", \"side\":\"SELL\", \"hash\":\"7c84120d73367057d6185c1055cc11ef3909c773\", \"best_bid\":\"0.54\", \"best_ask\":\"0.55\"}], \"timestamp\":\"1785211225841\", \"event_type\":\"price_change\"}","received_at":"2026-07-28T04:00:29.267613Z","schema_version":"clob-market-ws.price_change.v1","sequence":null,"server_hash":null,"server_timestamp":"1785211225841","session_id":"2d607381e3054cee91998cdf45a4231c","source":"clob_market_ws"},"received_at":"2026-07-28T04:00:29.267613Z","record_id":"38a2d44f4acc7c88177be7c9919f3eb7a80a96462551c7a1ade79d8d6fef60ee","schema_fingerprint":"4aa3821a28b0b7c2400bc59aba4bcc0a76e971dadd19610d3ad38c768e124dc7","schema_version":"edge-lab-recorder.raw.v1","sequence":null,"source":"clob_market_ws"}
{"event_at":"2026-07-28T04:00:25.843000Z","event_fingerprint":"a0cc6fd9482e280b6fc58c01a5f9073aa8950fd9a89bfa2dfda6a383fd71d193","payload":{"connection_id":"f6725804f86a4c4eb588e4d5ed7db029","event_at":"2026-07-28T04:00:25.843000Z","event_type":"price_change","frame_hash":"c2bd030b884db3057d8689400457605f1f41e28fef683f7a6901396df308d952","frame_index":0,"kind":"data","monotonic_ns":313212319706375,"payload":{"event_type":"price_change","market":"0xd412ce774cfcf8dc9f71164aac78783978aac7b03871702a3b8a481bd9dc9688","price_changes":[{"asset_id":"107603864457683460275633293642179940881969192120168665300712204232021063124301","best_ask":"0.46","best_bid":"0.45","hash":"84b3f3d8cf83da7e3430a9cb3945516f7ec0b4f5","price":"0.39","side":"BUY","size":"93.52"},{"asset_id":"96600821790790307414914106093858868634329285205417149685270682748367152458577","best_ask":"0.55","best_bid":"0.54","hash":"2201772535a70834057a9a80ace4281b0ca5b581","price":"0.61","side":"SELL","size":"93.52"}],"timestamp":"1785211225843"},"payload_hash":"8c23e7468063a006bbf2961d6960644c2f4013477cd27b31b30e37d54ff8794c","raw_frame":"{\"market\":\"0xd412ce774cfcf8dc9f71164aac78783978aac7b03871702a3b8a481bd9dc9688\", \"price_changes\":[{\"asset_id\":\"107603864457683460275633293642179940881969192120168665300712204232021063124301\", \"price\":\"0.39\", \"size\":\"93.52\", \"side\":\"BUY\", \"hash\":\"84b3f3d8cf83da7e3430a9cb3945516f7ec0b4f5\", \"best_bid\":\"0.45\", \"best_ask\":\"0.46\"}, {\"asset_id\":\"96600821790790307414914106093858868634329285205417149685270682748367152458577\", \"price\":\"0.61\", \"size\":\"93.52\", \"side\":\"SELL\", \"hash\":\"2201772535a70834057a9a80ace4281b0ca5b581\", \"best_bid\":\"0.54\", \"best_ask\":\"0.55\"}], \"timestamp\":\"1785211225843\", \"event_type\":\"price_change\"}","received_at":"2026-07-28T04:00:29.271579Z","schema_version":"clob-market-ws.price_change.v1","sequence":null,"server_hash":null,"server_timestamp":"1785211225843","session_id":"2d607381e3054cee91998cdf45a4231c","source":"clob_market_ws"},"received_at":"2026-07-28T04:00:29.271579Z","record_id":"2a5644bf0f0d01f0bfb2e42021455979c9a1f2b5c27f56c88c3e6a89777bc63b","schema_fingerprint":"4aa3821a28b0b7c2400bc59aba4bcc0a76e971dadd19610d3ad38c768e124dc7","schema_version":"edge-lab-recorder.raw.v1","sequence":null,"source":"clob_market_ws"}
{"event_at":"2026-07-28T04:00:25.843000Z","event_fingerprint":"e24cec491c120ce510721821cb6566e444206e65fc895db0a5ee271607e127c7","payload":{"connection_id":"f6725804f86a4c4eb588e4d5ed7db029","event_at":"2026-07-28T04:00:25.843000Z","event_type":"price_change","frame_hash":"5bcf95a820ad96717c6fd8114f64cd591b12847ebf66625efa5bb14cc57a8f22","frame_index":0,"kind":"data","monotonic_ns":313212323405750,"payload":{"event_type":"price_change","market":"0xd412ce774cfcf8dc9f71164aac78783978aac7b03871702a3b8a481bd9dc9688","price_changes":[{"asset_id":"96600821790790307414914106093858868634329285205417149685270682748367152458577","best_ask":"0.55","best_bid":"0.54","hash":"2b5fac1e57101c031662497411884397a66371d6","price":"0.49","side":"BUY","size":"48.58"},{"asset_id":"107603864457683460275633293642179940881969192120168665300712204232021063124301","best_ask":"0.46","best_bid":"0.45","hash":"1371f37ad563fcf86163a2bb6d6703eb51b45253","price":"0.51","side":"SELL","size":"48.58"}],"timestamp":"1785211225843"},"payload_hash":"503e49bb2197b825ba9ba26d4712a73a81811116e97dc84c32742ab953bf1592","raw_frame":"{\"market\":\"0xd412ce774cfcf8dc9f71164aac78783978aac7b03871702a3b8a481bd9dc9688\", \"price_changes\":[{\"asset_id\":\"96600821790790307414914106093858868634329285205417149685270682748367152458577\", \"price\":\"0.49\", \"size\":\"48.58\", \"side\":\"BUY\", \"hash\":\"2b5fac1e57101c031662497411884397a66371d6\", \"best_bid\":\"0.54\", \"best_ask\":\"0.55\"}, {\"asset_id\":\"107603864457683460275633293642179940881969192120168665300712204232021063124301\", \"price\":\"0.51\", \"size\":\"48.58\", \"side\":\"SELL\", \"hash\":\"1371f37ad563fcf86163a2bb6d6703eb51b45253\", \"best_bid\":\"0.45\", \"best_ask\":\"0.46\"}], \"timestamp\":\"1785211225843\", \"event_type\":\"price_change\"}","received_at":"2026-07-28T04:00:29.275280Z","schema_version":"clob-market-ws.price_change.v1","sequence":null,"server_hash":null,"server_timestamp":"1785211225843","session_id":"2d607381e3054cee91998cdf45a4231c","source":"clob_market_ws"},"received_at":"2026-07-28T04:00:29.275280Z","record_id":"535a4f74c0c7da0393d47b1df2878141eb0d0fd9eb2658cdc5bc8d828e94df03","schema_fingerprint":"4aa3821a28b0b7c2400bc59aba4bcc0a76e971dadd19610d3ad38c768e124dc7","schema_version":"edge-lab-recorder.raw.v1","sequence":null,"source":"clob_market_ws"}
{"event_at":"2026-07-28T04:00:25.843000Z","event_fingerprint":"2b4e770e3d9cf518b46c2c5d30eb3ff8289b73e979414eaa3205f5f7d88d55c8","payload":{"connection_id":"f6725804f86a4c4eb588e4d5ed7db029","event_at":"2026-07-28T04:00:25.843000Z","event_type":"price_change","frame_hash":"1ac652732ce6dc7c411da97db3614f42b3b7dafb7ccffb14bf4b5c570f9effd5","frame_index":0,"kind":"data","monotonic_ns":313212330314708,"payload":{"event_type":"price_change","market":"0xd412ce774cfcf8dc9f71164aac78783978aac7b03871702a3b8a481bd9dc9688","price_changes":[{"asset_id":"96600821790790307414914106093858868634329285205417149685270682748367152458577","best_ask":"0.55","best_bid":"0.54","hash":"2b5fac1e57101c031662497411884397a66371d6","price":"0.5","side":"BUY","size":"47.6"},{"asset_id":"107603864457683460275633293642179940881969192120168665300712204232021063124301","best_ask":"0.46","best_bid":"0.45","hash":"1371f37ad563fcf86163a2bb6d6703eb51b45253","price":"0.5","side":"SELL","size":"47.6"}],"timestamp":"1785211225843"},"payload_hash":"721d765b614fa7ea861b648a2dbe5ab478f4769b171d17e90bc9ec5f3fb38a2d","raw_frame":"{\"market\":\"0xd412ce774cfcf8dc9f71164aac78783978aac7b03871702a3b8a481bd9dc9688\", \"price_changes\":[{\"asset_id\":\"96600821790790307414914106093858868634329285205417149685270682748367152458577\", \"price\":\"0.5\", \"size\":\"47.6\", \"side\":\"BUY\", \"hash\":\"2b5fac1e57101c031662497411884397a66371d6\", \"best_bid\":\"0.54\", \"best_ask\":\"0.55\"}, {\"asset_id\":\"107603864457683460275633293642179940881969192120168665300712204232021063124301\", \"price\":\"0.5\", \"size\":\"47.6\", \"side\":\"SELL\", \"hash\":\"1371f37ad563fcf86163a2bb6d6703eb51b45253\", \"best_bid\":\"0.45\", \"best_ask\":\"0.46\"}], \"timestamp\":\"1785211225843\", \"event_type\":\"price_change\"}","received_at":"2026-07-28T04:00:29.282185Z","schema_version":"clob-market-ws.price_change.v1","sequence":null,"server_hash":null,"server_timestamp":"1785211225843","session_id":"2d607381e3054cee91998cdf45a4231c","source":"clob_market_ws"},"received_at":"2026-07-28T04:00:29.282185Z","record_id":"fd48f58fb58aac13e7e3f427758f30541766d4c6c4f954ad860ea2429f36d807","schema_fingerprint":"4aa3821a28b0b7c2400bc59aba4bcc0a76e971dadd19610d3ad38c768e124dc7","schema_version":"edge-lab-recorder.raw.v1","sequence":null,"source":"clob_market_ws"}
{"event_at":"2026-07-28T04:00:25.843000Z","event_fingerprint":"e5117b85b207f6484a893d8afbb5badd8686a03000a13e760ce501e58d468ce2","payload":{"connection_id":"f6725804f86a4c4eb588e4d5ed7db029","event_at":"2026-07-28T04:00:25.843000Z","event_type":"price_change","frame_hash":"4d265108fb2bcd7bc3655b28748d3d31af5656a2d0ad0646590f5fe63591bcae","frame_index":0,"kind":"data","monotonic_ns":313212335700041,"payload":{"event_type":"price_change","market":"0xd412ce774cfcf8dc9f71164aac78783978aac7b03871702a3b8a481bd9dc9688","price_changes":[{"asset_id":"96600821790790307414914106093858868634329285205417149685270682748367152458577","best_ask":"0.55","best_bid":"0.54","hash":"2b5fac1e57101c031662497411884397a66371d6","price":"0.51","side":"BUY","size":"31.6"},{"asset_id":"107603864457683460275633293642179940881969192120168665300712204232021063124301","best_ask":"0.46","best_bid":"0.45","hash":"1371f37ad563fcf86163a2bb6d6703eb51b45253","price":"0.49","side":"SELL","size":"31.6"}],"timestamp":"1785211225843"},"payload_hash":"e5a06450c7af82f6394d3790c0d9bdc96a586032efbdefadee69c36f31980039","raw_frame":"{\"market\":\"0xd412ce774cfcf8dc9f71164aac78783978aac7b03871702a3b8a481bd9dc9688\", \"price_changes\":[{\"asset_id\":\"96600821790790307414914106093858868634329285205417149685270682748367152458577\", \"price\":\"0.51\", \"size\":\"31.6\", \"side\":\"BUY\", \"hash\":\"2b5fac1e57101c031662497411884397a66371d6\", \"best_bid\":\"0.54\", \"best_ask\":\"0.55\"}, {\"asset_id\":\"107603864457683460275633293642179940881969192120168665300712204232021063124301\", \"price\":\"0.49\", \"size\":\"31.6\", \"side\":\"SELL\", \"hash\":\"1371f37ad563fcf86163a2bb6d6703eb51b45253\", \"best_bid\":\"0.45\", \"best_ask\":\"0.46\"}], \"timestamp\":\"1785211225843\", \"event_type\":\"price_change\"}","received_at":"2026-07-28T04:00:29.287573Z","schema_version":"clob-market-ws.price_change.v1","sequence":null,"server_hash":null,"server_timestamp":"1785211225843","session_id":"2d607381e3054cee91998cdf45a4231c","source":"clob_market_ws"},"received_at":"2026-07-28T04:00:29.287573Z","record_id":"504cb16e89c70903e551dab4c6ea114285318d8fe2c4714eeee03e2447f56b6e","schema_fingerprint":"4aa3821a28b0b7c2400bc59aba4bcc0a76e971dadd19610d3ad38c768e124dc7","schema_version":"edge-lab-recorder.raw.v1","sequence":null,"source":"clob_market_ws"}
{"event_at":"2026-07-28T04:00:25.843000Z","event_fingerprint":"e252012070226c57a74033d28daf55b8895fc06b2557d3d8c34ba2d11c4d4c49","payload":{"connection_id":"f6725804f86a4c4eb588e4d5ed7db029","event_at":"2026-07-28T04:00:25.843000Z","event_type":"price_change","frame_hash":"1a4776ad153788cb7c001208e53c2e9a79236049ec5b31ee8b9bfd21cad12c01","frame_index":0,"kind":"data","monotonic_ns":313212340281250,"payload":{"event_type":"price_change","market":"0xd412ce774cfcf8dc9f71164aac78783978aac7b03871702a3b8a481bd9dc9688","price_changes":[{"asset_id":"96600821790790307414914106093858868634329285205417149685270682748367152458577","best_ask":"0.55","best_bid":"0.54","hash":"2b5fac1e57101c031662497411884397a66371d6","price":"0.52","side":"BUY","size":"19"},{"asset_id":"107603864457683460275633293642179940881969192120168665300712204232021063124301","best_ask":"0.46","best_bid":"0.45","hash":"1371f37ad563fcf86163a2bb6d6703eb51b45253","price":"0.48","side":"SELL","size":"19"}],"timestamp":"1785211225843"},"payload_hash":"d320e673e9088ce02ae185ff0aa1ea2106f1f82b7017f3f6fbc859ccf7b30994","raw_frame":"{\"market\":\"0xd412ce774cfcf8dc9f71164aac78783978aac7b03871702a3b8a481bd9dc9688\", \"price_changes\":[{\"asset_id\":\"96600821790790307414914106093858868634329285205417149685270682748367152458577\", \"price\":\"0.52\", \"size\":\"19\", \"side\":\"BUY\", \"hash\":\"2b5fac1e57101c031662497411884397a66371d6\", \"best_bid\":\"0.54\", \"best_ask\":\"0.55\"}, {\"asset_id\":\"107603864457683460275633293642179940881969192120168665300712204232021063124301\", \"price\":\"0.48\", \"size\":\"19\", \"side\":\"SELL\", \"hash\":\"1371f37ad563fcf86163a2bb6d6703eb51b45253\", \"best_bid\":\"0.45\", \"best_ask\":\"0.46\"}], \"timestamp\":\"1785211225843\", \"event_type\":\"price_change\"}","received_at":"2026-07-28T04:00:29.292155Z","schema_version":"clob-market-ws.price_change.v1","sequence":null,"server_hash":null,"server_timestamp":"1785211225843","session_id":"2d607381e3054cee91998cdf45a4231c","source":"clob_market_ws"},"received_at":"2026-07-28T04:00:29.292155Z","record_id":"2761fd7710f9b624de65d57fb981b925fe5d7df36ac35a55399aee22d75efe28","schema_fingerprint":"4aa3821a28b0b7c2400bc59aba4bcc0a76e971dadd19610d3ad38c768e124dc7","schema_version":"edge-lab-recorder.raw.v1","sequence":null,"source":"clob_market_ws"}
{"event_at":"2026-07-28T04:00:25.845000Z","event_fingerprint":"9c3bbd6b803015edec911511c0bfd0d5f5101cef247ebe8ee6fcbce445a79444","payload":{"connection_id":"f6725804f86a4c4eb588e4d5ed7db029","event_at":"2026-07-28T04:00:25.845000Z","event_type":"price_change","frame_hash":"84be1dc4830381640e125abc7fa4c9adfefbc0d90b3768b11fa0b39fe2d31c40","frame_index":0,"kind":"data","monotonic_ns":313212344447291,"payload":{"event_type":"price_change","market":"0xd412ce774cfcf8dc9f71164aac78783978aac7b03871702a3b8a481bd9dc9688","price_changes":[{"asset_id":"107603864457683460275633293642179940881969192120168665300712204232021063124301","best_ask":"0.46","best_bid":"0.45","hash":"b4e6110eeb94f812e1ea797ecd37a3f7fddda7fc","price":"0.4","side":"BUY","size":"232.92"},{"asset_id":"96600821790790307414914106093858868634329285205417149685270682748367152458577","best_ask":"0.55","best_bid":"0.54","hash":"c9d6cdfefd1b12c9c060bca234d4e85042d83de2","price":"0.6","side":"SELL","size":"232.92"}],"timestamp":"1785211225845"},"payload_hash":"5c70ebaa10c8069a66d511b4a5803a9ee2fc1943ae6818c039f39bfffcb4dce9","raw_frame":"{\"market\":\"0xd412ce774cfcf8dc9f71164aac78783978aac7b03871702a3b8a481bd9dc9688\", \"price_changes\":[{\"asset_id\":\"107603864457683460275633293642179940881969192120168665300712204232021063124301\", \"price\":\"0.4\", \"size\":\"232.92\", \"side\":\"BUY\", \"hash\":\"b4e6110eeb94f812e1ea797ecd37a3f7fddda7fc\", \"best_bid\":\"0.45\", \"best_ask\":\"0.46\"}, {\"asset_id\":\"96600821790790307414914106093858868634329285205417149685270682748367152458577\", \"price\":\"0.6\", \"size\":\"232.92\", \"side\":\"SELL\", \"hash\":\"c9d6cdfefd1b12c9c060bca234d4e85042d83de2\", \"best_bid\":\"0.54\", \"best_ask\":\"0.55\"}], \"timestamp\":\"1785211225845\", \"event_type\":\"price_change\"}","received_at":"2026-07-28T04:00:29.296322Z","schema_version":"clob-market-ws.price_change.v1","sequence":null,"server_hash":null,"server_timestamp":"1785211225845","session_id":"2d607381e3054cee91998cdf45a4231c","source":"clob_market_ws"},"received_at":"2026-07-28T04:00:29.296322Z","record_id":"9c42628830dc03513a30d196965fc35ce97a9a24e20a194cf37ed57c24b6fc71","schema_fingerprint":"4aa3821a28b0b7c2400bc59aba4bcc0a76e971dadd19610d3ad38c768e124dc7","schema_version":"edge-lab-recorder.raw.v1","sequence":null,"source":"clob_market_ws"}
{"event_at":"2026-07-28T04:00:25.846000Z","event_fingerprint":"dd3fb072280f8552beade901d79da912f5b767e3a4998b2c62164f9f70780f9c","payload":{"connection_id":"f6725804f86a4c4eb588e4d5ed7db029","event_at":"2026-07-28T04:00:25.846000Z","event_type":"best_bid_ask","frame_hash":"09095a4b06a93ba7b2e79794dfb92fbb38dd054f6a43836d597b891e8c65a20c","frame_index":0,"kind":"data","monotonic_ns":313212348806500,"payload":{"asset_id":"107603864457683460275633293642179940881969192120168665300712204232021063124301","best_ask":"0.48","best_bid":"0.45","event_type":"best_bid_ask","market":"0xd412ce774cfcf8dc9f71164aac78783978aac7b03871702a3b8a481bd9dc9688","spread":"0.03","timestamp":"1785211225846"},"payload_hash":"fd81cb82268c5ac5e82d380691d637ff0ff601ead5c910086193ec075cfac639","raw_frame":"{\"market\":\"0xd412ce774cfcf8dc9f71164aac78783978aac7b03871702a3b8a481bd9dc9688\", \"asset_id\":\"107603864457683460275633293642179940881969192120168665300712204232021063124301\", \"best_bid\":\"0.45\", \"best_ask\":\"0.48\", \"spread\":\"0.03\", \"timestamp\":\"1785211225846\", \"event_type\":\"best_bid_ask\"}","received_at":"2026-07-28T04:00:29.300678Z","schema_version":"clob-market-ws.best_bid_ask.v1","sequence":null,"server_hash":null,"server_timestamp":"1785211225846","session_id":"2d607381e3054cee91998cdf45a4231c","source":"clob_market_ws"},"received_at":"2026-07-28T04:00:29.300678Z","record_id":"f4bc4ed7236a0e8cf2816afab21ac57c3b0e74df4c3ce85c8704c74f9096ba3a","schema_fingerprint":"8488399f31b0337811b13b266be932db7062827c2470b78bd8e9e99bab51d17d","schema_version":"edge-lab-recorder.raw.v1","sequence":null,"source":"clob_market_ws"}
{"event_at":"2026-07-28T04:00:25.846000Z","event_fingerprint":"255ce30baf91f5e9dfae605dffba51261c8449be1fd30b32b304e039eccb43ea","payload":{"connection_id":"f6725804f86a4c4eb588e4d5ed7db029","event_at":"2026-07-28T04:00:25.846000Z","event_type":"best_bid_ask","frame_hash":"ff469a41d3d0213cd318066de3033a4f8f84cad580c51b240c623d57b2393546","frame_index":0,"kind":"data","monotonic_ns":313212354282958,"payload":{"asset_id":"96600821790790307414914106093858868634329285205417149685270682748367152458577","best_ask":"0.55","best_bid":"0.52","event_type":"best_bid_ask","market":"0xd412ce774cfcf8dc9f71164aac78783978aac7b03871702a3b8a481bd9dc9688","spread":"0.03","timestamp":"1785211225846"},"payload_hash":"008c4f8033321590cc428434326f7e3b051f53c1684e55b2f0f4535e22da4174","raw_frame":"{\"market\":\"0xd412ce774cfcf8dc9f71164aac78783978aac7b03871702a3b8a481bd9dc9688\", \"asset_id\":\"96600821790790307414914106093858868634329285205417149685270682748367152458577\", \"best_bid\":\"0.52\", \"best_ask\":\"0.55\", \"spread\":\"0.03\", \"timestamp\":\"1785211225846\", \"event_type\":\"best_bid_ask\"}","received_at":"2026-07-28T04:00:29.306155Z","schema_version":"clob-market-ws.best_bid_ask.v1","sequence":null,"server_hash":null,"server_timestamp":"1785211225846","session_id":"2d607381e3054cee91998cdf45a4231c","source":"clob_market_ws"},"received_at":"2026-07-28T04:00:29.306155Z","record_id":"915ab057cf9b0c5f81eb1bb2ea9044ce231bb3bf5d924932b35b09c679358184","schema_fingerprint":"8488399f31b0337811b13b266be932db7062827c2470b78bd8e9e99bab51d17d","schema_version":"edge-lab-recorder.raw.v1","sequence":null,"source":"clob_market_ws"}
{"event_at":"2026-07-28T04:00:25.846000Z","event_fingerprint":"0ca6bdc301c69b093f3d949a43671229680486c3bb75d9838f2c7efc583237b5","payload":{"connection_id":"f6725804f86a4c4eb588e4d5ed7db029","event_at":"2026-07-28T04:00:25.846000Z","event_type":"price_change","frame_hash":"66912053a3bddb3f816d49693b87f806115cf281a276ba03b9dd4051a43f1611","frame_index":0,"kind":"data","monotonic_ns":313212361839791,"payload":{"event_type":"price_change","market":"0xd412ce774cfcf8dc9f71164aac78783978aac7b03871702a3b8a481bd9dc9688","price_changes":[{"asset_id":"96600821790790307414914106093858868634329285205417149685270682748367152458577","best_ask":"0.55","best_bid":"0.52","hash":"12017301c826e6ffef866ccd773469214de66f17","price":"0.54","side":"BUY","size":"0"},{"asset_id":"107603864457683460275633293642179940881969192120168665300712204232021063124301","best_ask":"0.48","best_bid":"0.45","hash":"b7090143b8f7841a627ceff5ef324bba041114d0","price":"0.46","side":"SELL","size":"0"}],"timestamp":"1785211225846"},"payload_hash":"874d883d940d7a952a948e2aecd79b7289a5754a1168a5e4c757c5f8508688fa","raw_frame":"{\"market\":\"0xd412ce774cfcf8dc9f71164aac78783978aac7b03871702a3b8a481bd9dc9688\", \"price_changes\":[{\"asset_id\":\"96600821790790307414914106093858868634329285205417149685270682748367152458577\", \"price\":\"0.54\", \"size\":\"0\", \"side\":\"BUY\", \"hash\":\"12017301c826e6ffef866ccd773469214de66f17\", \"best_bid\":\"0.52\", \"best_ask\":\"0.55\"}, {\"asset_id\":\"107603864457683460275633293642179940881969192120168665300712204232021063124301\", \"price\":\"0.46\", \"size\":\"0\", \"side\":\"SELL\", \"hash\":\"b7090143b8f7841a627ceff5ef324bba041114d0\", \"best_bid\":\"0.45\", \"best_ask\":\"0.48\"}], \"timestamp\":\"1785211225846\", \"event_type\":\"price_change\"}","received_at":"2026-07-28T04:00:29.313713Z","schema_version":"clob-market-ws.price_change.v1","sequence":null,"server_hash":null,"server_timestamp":"1785211225846","session_id":"2d607381e3054cee91998cdf45a4231c","source":"clob_market_ws"},"received_at":"2026-07-28T04:00:29.313713Z","record_id":"ca3b68b0741438751cac1f4046dd234771a5e9a986eb393ded1e319d1cbf696e","schema_fingerprint":"4aa3821a28b0b7c2400bc59aba4bcc0a76e971dadd19610d3ad38c768e124dc7","schema_version":"edge-lab-recorder.raw.v1","sequence":null,"source":"clob_market_ws"}
{"event_at":"2026-07-28T04:00:25.846000Z","event_fingerprint":"2aeef45a8b216580e823cd742cf2f579e7bbbc566adea15666548bfb0be79760","payload":{"connection_id":"f6725804f86a4c4eb588e4d5ed7db029","event_at":"2026-07-28T04:00:25.846000Z","event_type":"price_change","frame_hash":"921c62f3a35ecb1f2ca412c4578f6d34247ceefb8cfd40ab2b52e5a390cb795f","frame_index":0,"kind":"data","monotonic_ns":313212376945541,"payload":{"event_type":"price_change","market":"0xd412ce774cfcf8dc9f71164aac78783978aac7b03871702a3b8a481bd9dc9688","price_changes":[{"asset_id":"107603864457683460275633293642179940881969192120168665300712204232021063124301","best_ask":"0.48","best_bid":"0.45","hash":"94246407913890eabf501be21c560457625081dc","price":"0.45","side":"BUY","size":"23"},{"asset_id":"96600821790790307414914106093858868634329285205417149685270682748367152458577","best_ask":"0.55","best_bid":"0.52","hash":"e4bce106f9872f79b494343c454543f646885334","price":"0.55","side":"SELL","size":"23"}],"timestamp":"1785211225846"},"payload_hash":"3eda6cdfce337a853061d92ae033a7b43c05930088bac29d41c6edfd0ecfa80c","raw_frame":"{\"market\":\"0xd412ce774cfcf8dc9f71164aac78783978aac7b03871702a3b8a481bd9dc9688\", \"price_changes\":[{\"asset_id\":\"107603864457683460275633293642179940881969192120168665300712204232021063124301\", \"price\":\"0.45\", \"size\":\"23\", \"side\":\"BUY\", \"hash\":\"94246407913890eabf501be21c560457625081dc\", \"best_bid\":\"0.45\", \"best_ask\":\"0.48\"}, {\"asset_id\":\"96600821790790307414914106093858868634329285205417149685270682748367152458577\", \"price\":\"0.55\", \"size\":\"23\", \"side\":\"SELL\", \"hash\":\"e4bce106f9872f79b494343c454543f646885334\", \"best_bid\":\"0.52\", \"best_ask\":\"0.55\"}], \"timestamp\":\"1785211225846\", \"event_type\":\"price_change\"}","received_at":"2026-07-28T04:00:29.328818Z","schema_version":"clob-market-ws.price_change.v1","sequence":null,"server_hash":null,"server_timestamp":"1785211225846","session_id":"2d607381e3054cee91998cdf45a4231c","source":"clob_market_ws"},"received_at":"2026-07-28T04:00:29.328818Z","record_id":"fe9e251df6661e2c784c3114d2d6fd46e7f39fa47b60ccedd1ea6e1925531798","schema_fingerprint":"4aa3821a28b0b7c2400bc59aba4bcc0a76e971dadd19610d3ad38c768e124dc7","schema_version":"edge-lab-recorder.raw.v1","sequence":null,"source":"clob_market_ws"}
{"event_at":"2026-07-28T04:00:25.848000Z","event_fingerprint":"090087678cb234a2ec193242fa4fbbc114e15fdf855b4e444dc8480305b8185d","payload":{"connection_id":"f6725804f86a4c4eb588e4d5ed7db029","event_at":"2026-07-28T04:00:25.848000Z","event_type":"best_bid_ask","frame_hash":"c6358bccc1f9b7d4a71237feb991dd864c6f526a7ade803290a2a318bb2f4e17","frame_index":0,"kind":"data","monotonic_ns":313212383602625,"payload":{"asset_id":"107603864457683460275633293642179940881969192120168665300712204232021063124301","best_ask":"0.47","best_bid":"0.45","event_type":"best_bid_ask","market":"0xd412ce774cfcf8dc9f71164aac78783978aac7b03871702a3b8a481bd9dc9688","spread":"0.02","timestamp":"1785211225848"},"payload_hash":"5e2d4e4e69fec0a53e32182e3c58d7866718ef8c3e7147f45154645356d0c43e","raw_frame":"{\"market\":\"0xd412ce774cfcf8dc9f71164aac78783978aac7b03871702a3b8a481bd9dc9688\", \"asset_id\":\"107603864457683460275633293642179940881969192120168665300712204232021063124301\", \"best_bid\":\"0.45\", \"best_ask\":\"0.47\", \"spread\":\"0.02\", \"timestamp\":\"1785211225848\", \"event_type\":\"best_bid_ask\"}","received_at":"2026-07-28T04:00:29.335473Z","schema_version":"clob-market-ws.best_bid_ask.v1","sequence":null,"server_hash":null,"server_timestamp":"1785211225848","session_id":"2d607381e3054cee91998cdf45a4231c","source":"clob_market_ws"},"received_at":"2026-07-28T04:00:29.335473Z","record_id":"233b398236ff233c1cb6e0fbc5cd46bfc6e0996ca9a48309dbfe1b9eea6a26ed","schema_fingerprint":"8488399f31b0337811b13b266be932db7062827c2470b78bd8e9e99bab51d17d","schema_version":"edge-lab-recorder.raw.v1","sequence":null,"source":"clob_market_ws"}
{"event_at":"2026-07-28T04:00:25.848000Z","event_fingerprint":"48cb3aae75fdb1fd98024585d145eda99ca32e1e2f0151180322a91f0a8ceef3","payload":{"connection_id":"f6725804f86a4c4eb588e4d5ed7db029","event_at":"2026-07-28T04:00:25.848000Z","event_type":"best_bid_ask","frame_hash":"1f1f72211f8d70e29bcd353a4c74018da43e4e0606dd91da549f6661749180b5","frame_index":0,"kind":"data","monotonic_ns":313212389722916,"payload":{"asset_id":"96600821790790307414914106093858868634329285205417149685270682748367152458577","best_ask":"0.55","best_bid":"0.53","event_type":"best_bid_ask","market":"0xd412ce774cfcf8dc9f71164aac78783978aac7b03871702a3b8a481bd9dc9688","spread":"0.02","timestamp":"1785211225848"},"payload_hash":"b81768db58b83c99ce2e345eea353a422ddbc61406fa8862aeb517f6387e3152","raw_frame":"{\"market\":\"0xd412ce774cfcf8dc9f71164aac78783978aac7b03871702a3b8a481bd9dc9688\", \"asset_id\":\"96600821790790307414914106093858868634329285205417149685270682748367152458577\", \"best_bid\":\"0.53\", \"best_ask\":\"0.55\", \"spread\":\"0.02\", \"timestamp\":\"1785211225848\", \"event_type\":\"best_bid_ask\"}","received_at":"2026-07-28T04:00:29.341595Z","schema_version":"clob-market-ws.best_bid_ask.v1","sequence":null,"server_hash":null,"server_timestamp":"1785211225848","session_id":"2d607381e3054cee91998cdf45a4231c","source":"clob_market_ws"},"received_at":"2026-07-28T04:00:29.341595Z","record_id":"8d43546ebeb36ea6873ab68304833b55347d1df8ee81083ed2127ddf23f1c164","schema_fingerprint":"8488399f31b0337811b13b266be932db7062827c2470b78bd8e9e99bab51d17d","schema_version":"edge-lab-recorder.raw.v1","sequence":null,"source":"clob_market_ws"}
{"event_at":"2026-07-28T04:00:25.848000Z","event_fingerprint":"6e78c4b1e147a5fa7e9d248beaa8cacdec4558a2389d0f6fa6b3be21762cf013","payload":{"connection_id":"f6725804f86a4c4eb588e4d5ed7db029","event_at":"2026-07-28T04:00:25.848000Z","event_type":"price_change","frame_hash":"306f84e370d82760266538211e1ed3d590b9e67acf3da41b8592d6265d2f842b","frame_index":0,"kind":"data","monotonic_ns":313212395128958,"payload":{"event_type":"price_change","market":"0xd412ce774cfcf8dc9f71164aac78783978aac7b03871702a3b8a481bd9dc9688","price_changes":[{"asset_id":"96600821790790307414914106093858868634329285205417149685270682748367152458577","best_ask":"0.55","best_bid":"0.53","hash":"8f65e7b43099119338bcff2ffeb6a11fa3dfe62e","price":"0.53","side":"BUY","size":"13"},{"asset_id":"107603864457683460275633293642179940881969192120168665300712204232021063124301","best_ask":"0.47","best_bid":"0.45","hash":"d86f93fb019490007f5f9bfe4452f27fee6da312","price":"0.47","side":"SELL","size":"13"}],"timestamp":"1785211225848"},"payload_hash":"21cde9b12678498471f5747d322274f374229aa009800e7f493db8856aef96ff","raw_frame":"{\"market\":\"0xd412ce774cfcf8dc9f71164aac78783978aac7b03871702a3b8a481bd9dc9688\", \"price_changes\":[{\"asset_id\":\"96600821790790307414914106093858868634329285205417149685270682748367152458577\", \"price\":\"0.53\", \"size\":\"13\", \"side\":\"BUY\", \"hash\":\"8f65e7b43099119338bcff2ffeb6a11fa3dfe62e\", \"best_bid\":\"0.53\", \"best_ask\":\"0.55\"}, {\"asset_id\":\"107603864457683460275633293642179940881969192120168665300712204232021063124301\", \"price\":\"0.47\", \"size\":\"13\", \"side\":\"SELL\", \"hash\":\"d86f93fb019490007f5f9bfe4452f27fee6da312\", \"best_bid\":\"0.45\", \"best_ask\":\"0.47\"}], \"timestamp\":\"1785211225848\", \"event_type\":\"price_change\"}","received_at":"2026-07-28T04:00:29.347002Z","schema_version":"clob-market-ws.price_change.v1","sequence":null,"server_hash":null,"server_timestamp":"1785211225848","session_id":"2d607381e3054cee91998cdf45a4231c","source":"clob_market_ws"},"received_at":"2026-07-28T04:00:29.347002Z","record_id":"c7ac7cee56a815d1b2e83149c53784096213e7de677436e8faf3b9dde5268a0c","schema_fingerprint":"4aa3821a28b0b7c2400bc59aba4bcc0a76e971dadd19610d3ad38c768e124dc7","schema_version":"edge-lab-recorder.raw.v1","sequence":null,"source":"clob_market_ws"}
{"event_at":"2026-07-28T04:00:25.854000Z","event_fingerprint":"47fef808fa0b5b851dcff8775962ef30022ce44f71920026c3b2a64bc6fea263","payload":{"connection_id":"f6725804f86a4c4eb588e4d5ed7db029","event_at":"2026-07-28T04:00:25.854000Z","event_type":"price_change","frame_hash":"e117048f9afb2218cc0414c17cf9a1a5585b7e0d656b9ebb18e398ac55dfa0d8","frame_index":0,"kind":"data","monotonic_ns":313212406357041,"payload":{"event_type":"price_change","market":"0xd412ce774cfcf8dc9f71164aac78783978aac7b03871702a3b8a481bd9dc9688","price_changes":[{"asset_id":"107603864457683460275633293642179940881969192120168665300712204232021063124301","best_ask":"0.47","best_bid":"0.45","hash":"89941f1e38efadcf496f2828098b767b8833afc7","price":"0.45","side":"BUY","size":"29"},{"asset_id":"96600821790790307414914106093858868634329285205417149685270682748367152458577","best_ask":"0.55","best_bid":"0.53","hash":"504d2d1a62e0bb7d69bcef8bba94cbd2dc4d1843","price":"0.55","side":"SELL","size":"29"}],"timestamp":"1785211225854"},"payload_hash":"e6d42f7c90a2400cd015bbf207332db55f7180fff7eff2e9d3d0dfd7cb4d27b3","raw_frame":"{\"market\":\"0xd412ce774cfcf8dc9f71164aac78783978aac7b03871702a3b8a481bd9dc9688\", \"price_changes\":[{\"asset_id\":\"107603864457683460275633293642179940881969192120168665300712204232021063124301\", \"price\":\"0.45\", \"size\":\"29\", \"side\":\"BUY\", \"hash\":\"89941f1e38efadcf496f2828098b767b8833afc7\", \"best_bid\":\"0.45\", \"best_ask\":\"0.47\"}, {\"asset_id\":\"96600821790790307414914106093858868634329285205417149685270682748367152458577\", \"price\":\"0.55\", \"size\":\"29\", \"side\":\"SELL\", \"hash\":\"504d2d1a62e0bb7d69bcef8bba94cbd2dc4d1843\", \"best_bid\":\"0.53\", \"best_ask\":\"0.55\"}], \"timestamp\":\"1785211225854\", \"event_type\":\"price_change\"}","received_at":"2026-07-28T04:00:29.358230Z","schema_version":"clob-market-ws.price_change.v1","sequence":null,"server_hash":null,"server_timestamp":"1785211225854","session_id":"2d607381e3054cee91998cdf45a4231c","source":"clob_market_ws"},"received_at":"2026-07-28T04:00:29.358230Z","record_id":"4533ddfacd40299c80aef7c490d6c55de74854bd3e1fdef27deb9d42eaba916e","schema_fingerprint":"4aa3821a28b0b7c2400bc59aba4bcc0a76e971dadd19610d3ad38c768e124dc7","schema_version":"edge-lab-recorder.raw.v1","sequence":null,"source":"clob_market_ws"}
{"event_at":"2026-07-28T04:00:25.856000Z","event_fingerprint":"e00d351cac423820e35d324db72d8f1df6a52a1f627c4a6940b795953ff40e76","payload":{"connection_id":"f6725804f86a4c4eb588e4d5ed7db029","event_at":"2026-07-28T04:00:25.856000Z","event_type":"best_bid_ask","frame_hash":"a8e6a7ca6a43b0a69daf2b3792c9514d4551516336c83fc98987221c57e87499","frame_index":0,"kind":"data","monotonic_ns":313212412494708,"payload":{"asset_id":"107603864457683460275633293642179940881969192120168665300712204232021063124301","best_ask":"0.47","best_bid":"0.46","event_type":"best_bid_ask","market":"0xd412ce774cfcf8dc9f71164aac78783978aac7b03871702a3b8a481bd9dc9688","spread":"0.01","timestamp":"1785211225856"},"payload_hash":"db767823a1fe060d261ee21889aea93c797572472efae7b0b783cbddc1cfa6e8","raw_frame":"{\"market\":\"0xd412ce774cfcf8dc9f71164aac78783978aac7b03871702a3b8a481bd9dc9688\", \"asset_id\":\"107603864457683460275633293642179940881969192120168665300712204232021063124301\", \"best_bid\":\"0.46\", \"best_ask\":\"0.47\", \"spread\":\"0.01\", \"timestamp\":\"1785211225856\", \"event_type\":\"best_bid_ask\"}","received_at":"2026-07-28T04:00:29.364367Z","schema_version":"clob-market-ws.best_bid_ask.v1","sequence":null,"server_hash":null,"server_timestamp":"1785211225856","session_id":"2d607381e3054cee91998cdf45a4231c","source":"clob_market_ws"},"received_at":"2026-07-28T04:00:29.364367Z","record_id":"0f096954ff2b9f6e4b77533dd949eac02eafb499f168241f583ed4ef94a36e6d","schema_fingerprint":"8488399f31b0337811b13b266be932db7062827c2470b78bd8e9e99bab51d17d","schema_version":"edge-lab-recorder.raw.v1","sequence":null,"source":"clob_market_ws"}
{"event_at":"2026-07-28T04:00:25.856000Z","event_fingerprint":"229031f6259ea081457d1a75ecb5c6ba2677c3eb9f950fbf699ca5447f46b39d","payload":{"connection_id":"f6725804f86a4c4eb588e4d5ed7db029","event_at":"2026-07-28T04:00:25.856000Z","event_type":"best_bid_ask","frame_hash":"f9e4b3cffbe4ca228613313cc43ff0ef104291c1090dd77763861d38458946f8","frame_index":0,"kind":"data","monotonic_ns":313212415646375,"payload":{"asset_id":"96600821790790307414914106093858868634329285205417149685270682748367152458577","best_ask":"0.54","best_bid":"0.53","event_type":"best_bid_ask","market":"0xd412ce774cfcf8dc9f71164aac78783978aac7b03871702a3b8a481bd9dc9688","spread":"0.01","timestamp":"1785211225856"},"payload_hash":"da31018e22f693d1f9b230db4155a40ff846830ac09367d7814eabcb94810898","raw_frame":"{\"market\":\"0xd412ce774cfcf8dc9f71164aac78783978aac7b03871702a3b8a481bd9dc9688\", \"asset_id\":\"96600821790790307414914106093858868634329285205417149685270682748367152458577\", \"best_bid\":\"0.53\", \"best_ask\":\"0.54\", \"spread\":\"0.01\", \"timestamp\":\"1785211225856\", \"event_type\":\"best_bid_ask\"}","received_at":"2026-07-28T04:00:29.367520Z","schema_version":"clob-market-ws.best_bid_ask.v1","sequence":null,"server_hash":null,"server_timestamp":"1785211225856","session_id":"2d607381e3054cee91998cdf45a4231c","source":"clob_market_ws"},"received_at":"2026-07-28T04:00:29.367520Z","record_id":"8047afefae0e6fb9cc353a503d92407392bd0c42b23b3155479bbc888a56fc28","schema_fingerprint":"8488399f31b0337811b13b266be932db7062827c2470b78bd8e9e99bab51d17d","schema_version":"edge-lab-recorder.raw.v1","sequence":null,"source":"clob_market_ws"}
{"event_at":"2026-07-28T04:00:25.855000Z","event_fingerprint":"77bc216a0d45f3e14cdf699213039a369e307c7f2124183b1c86a468ef6a68de","payload":{"connection_id":"f6725804f86a4c4eb588e4d5ed7db029","event_at":"2026-07-28T04:00:25.855000Z","event_type":"price_change","frame_hash":"9da536a0a7138b06ed907fc4ac63c7a497fcc6b427810ce408a9da5d14db2b14","frame_index":0,"kind":"data","monotonic_ns":313212423009083,"payload":{"event_type":"price_change","market":"0xd412ce774cfcf8dc9f71164aac78783978aac7b03871702a3b8a481bd9dc9688","price_changes":[{"asset_id":"107603864457683460275633293642179940881969192120168665300712204232021063124301","best_ask":"0.47","best_bid":"0.46","hash":"232be5af237d1478636b24388670f0d9e4740f83","price":"0.46","side":"BUY","size":"12.6"},{"asset_id":"96600821790790307414914106093858868634329285205417149685270682748367152458577","best_ask":"0.54","best_bid":"0.53","hash":"7ff20d684f4aac102ce47be4c0542be175fafede","price":"0.54","side":"SELL","size":"12.6"}],"timestamp":"1785211225855"},"payload_hash":"093639301513855e33f222adb5087e0dd451c45f3ef5518ae0179915fcda89d9","raw_frame":"{\"market\":\"0xd412ce774cfcf8dc9f71164aac78783978aac7b03871702a3b8a481bd9dc9688\", \"price_changes\":[{\"asset_id\":\"107603864457683460275633293642179940881969192120168665300712204232021063124301\", \"price\":\"0.46\", \"size\":\"12.6\", \"side\":\"BUY\", \"hash\":\"232be5af237d1478636b24388670f0d9e4740f83\", \"best_bid\":\"0.46\", \"best_ask\":\"0.47\"}, {\"asset_id\":\"96600821790790307414914106093858868634329285205417149685270682748367152458577\", \"price\":\"0.54\", \"size\":\"12.6\", \"side\":\"SELL\", \"hash\":\"7ff20d684f4aac102ce47be4c0542be175fafede\", \"best_bid\":\"0.53\", \"best_ask\":\"0.54\"}], \"timestamp\":\"1785211225855\", \"event_type\":\"price_change\"}","received_at":"2026-07-28T04:00:29.374882Z","schema_version":"clob-market-ws.price_change.v1","sequence":null,"server_hash":null,"server_timestamp":"1785211225855","session_id":"2d607381e3054cee91998cdf45a4231c","source":"clob_market_ws"},"received_at":"2026-07-28T04:00:29.374882Z","record_id":"3afaa41c24f494126b62076d7c2be0c860218d21e9ac584b5fb6ba657524ff40","schema_fingerprint":"4aa3821a28b0b7c2400bc59aba4bcc0a76e971dadd19610d3ad38c768e124dc7","schema_version":"edge-lab-recorder.raw.v1","sequence":null,"source":"clob_market_ws"}
{"event_at":"2026-07-28T04:00:25.856000Z","event_fingerprint":"ba9d6e4b941f86a19a396644417e83d44dde1eab5ead0990cd4e8a31777d1744","payload":{"connection_id":"f6725804f86a4c4eb588e4d5ed7db029","event_at":"2026-07-28T04:00:25.856000Z","event_type":"price_change","frame_hash":"a01f05fe65d0a77f558b3d4aecf55b2566b57feb43c7d128fc198356fe16c11e","frame_index":0,"kind":"data","monotonic_ns":313212432035708,"payload":{"event_type":"price_change","market":"0xd412ce774cfcf8dc9f71164aac78783978aac7b03871702a3b8a481bd9dc9688","price_changes":[{"asset_id":"96600821790790307414914106093858868634329285205417149685270682748367152458577","best_ask":"0.54","best_bid":"0.53","hash":"f2c545d065f3afc550ef5e49bba8c85581afcc90","price":"0.5","side":"BUY","size":"41.6"},{"asset_id":"107603864457683460275633293642179940881969192120168665300712204232021063124301","best_ask":"0.47","best_bid":"0.46","hash":"f8b7cf782fc77e16f2086a91cb2994584ce29ede","price":"0.5","side":"SELL","size":"41.6"}],"timestamp":"1785211225856"},"payload_hash":"240f5cee2e1faaa6b8981ea15446e9a6ec6af41254395edffb0be22b47a20ff8","raw_frame":"{\"market\":\"0xd412ce774cfcf8dc9f71164aac78783978aac7b03871702a3b8a481bd9dc9688\", \"price_changes\":[{\"asset_id\":\"96600821790790307414914106093858868634329285205417149685270682748367152458577\", \"price\":\"0.5\", \"size\":\"41.6\", \"side\":\"BUY\", \"hash\":\"f2c545d065f3afc550ef5e49bba8c85581afcc90\", \"best_bid\":\"0.53\", \"best_ask\":\"0.54\"}, {\"asset_id\":\"107603864457683460275633293642179940881969192120168665300712204232021063124301\", \"price\":\"0.5\", \"size\":\"41.6\", \"side\":\"SELL\", \"hash\":\"f8b7cf782fc77e16f2086a91cb2994584ce29ede\", \"best_bid\":\"0.46\", \"best_ask\":\"0.47\"}], \"timestamp\":\"1785211225856\", \"event_type\":\"price_change\"}","received_at":"2026-07-28T04:00:29.383909Z","schema_version":"clob-market-ws.price_change.v1","sequence":null,"server_hash":null,"server_timestamp":"1785211225856","session_id":"2d607381e3054cee91998cdf45a4231c","source":"clob_market_ws"},"received_at":"2026-07-28T04:00:29.383909Z","record_id":"d9268fd53550f53544a60495170fa051154031bdde1b42e1782b7a28bbd33079","schema_fingerprint":"4aa3821a28b0b7c2400bc59aba4bcc0a76e971dadd19610d3ad38c768e124dc7","schema_version":"edge-lab-recorder.raw.v1","sequence":null,"source":"clob_market_ws"}
{"event_at":"2026-07-28T04:00:25.857000Z","event_fingerprint":"aa774aa19ae36c3b50dcf2dd9b984ac66b23b8ec8e93154e1fde39c6b79007c2","payload":{"connection_id":"f6725804f86a4c4eb588e4d5ed7db029","event_at":"2026-07-28T04:00:25.857000Z","event_type":"price_change","frame_hash":"b034613407a6e39b0f034b28f7f7fc6b2c351e83cb755f855f5a0025b7659530","frame_index":0,"kind":"data","monotonic_ns":313212445034791,"payload":{"event_type":"price_change","market":"0xd412ce774cfcf8dc9f71164aac78783978aac7b03871702a3b8a481bd9dc9688","price_changes":[{"asset_id":"107603864457683460275633293642179940881969192120168665300712204232021063124301","best_ask":"0.47","best_bid":"0.46","hash":"3ea6aa0fdc0f2a06a5f28e4fbf786e78c21cd34f","price":"0.45","side":"BUY","size":"19"},{"asset_id":"96600821790790307414914106093858868634329285205417149685270682748367152458577","best_ask":"0.54","best_bid":"0.53","hash":"39c83167f6e4b6cf323b61bb33a1066595807ce1","price":"0.55","side":"SELL","size":"19"}],"timestamp":"1785211225857"},"payload_hash":"59e2e246a00c2cebcd4956db78cc1239512bee3fc9130081ac8f232ac87aa022","raw_frame":"{\"market\":\"0xd412ce774cfcf8dc9f71164aac78783978aac7b03871702a3b8a481bd9dc9688\", \"price_changes\":[{\"asset_id\":\"107603864457683460275633293642179940881969192120168665300712204232021063124301\", \"price\":\"0.45\", \"size\":\"19\", \"side\":\"BUY\", \"hash\":\"3ea6aa0fdc0f2a06a5f28e4fbf786e78c21cd34f\", \"best_bid\":\"0.46\", \"best_ask\":\"0.47\"}, {\"asset_id\":\"96600821790790307414914106093858868634329285205417149685270682748367152458577\", \"price\":\"0.55\", \"size\":\"19\", \"side\":\"SELL\", \"hash\":\"39c83167f6e4b6cf323b61bb33a1066595807ce1\", \"best_bid\":\"0.53\", \"best_ask\":\"0.54\"}], \"timestamp\":\"1785211225857\", \"event_type\":\"price_change\"}","received_at":"2026-07-28T04:00:29.396907Z","schema_version":"clob-market-ws.price_change.v1","sequence":null,"server_hash":null,"server_timestamp":"1785211225857","session_id":"2d607381e3054cee91998cdf45a4231c","source":"clob_market_ws"},"received_at":"2026-07-28T04:00:29.396907Z","record_id":"dfbd666ba6dd7c888deecbbb5eae9b2527e009d660a01d7042a63eef4d5fbd27","schema_fingerprint":"4aa3821a28b0b7c2400bc59aba4bcc0a76e971dadd19610d3ad38c768e124dc7","schema_version":"edge-lab-recorder.raw.v1","sequence":null,"source":"clob_market_ws"}
{"event_at":"2026-07-28T04:00:25.858000Z","event_fingerprint":"cedfaf301e31b4cab3c7c7ff941336e377774d32ef294681cbc91e352304225c","payload":{"connection_id":"f6725804f86a4c4eb588e4d5ed7db029","event_at":"2026-07-28T04:00:25.858000Z","event_type":"price_change","frame_hash":"44176fb378028f14afba9ae4cf1e0ea3285a7d9fce7b39a2151c64ef4fe32681","frame_index":0,"kind":"data","monotonic_ns":313212449920666,"payload":{"event_type":"price_change","market":"0xd412ce774cfcf8dc9f71164aac78783978aac7b03871702a3b8a481bd9dc9688","price_changes":[{"asset_id":"107603864457683460275633293642179940881969192120168665300712204232021063124301","best_ask":"0.47","best_bid":"0.46","hash":"cff13bc8c7c2705c1213e291ca5961be1914f2e4","price":"0.45","side":"BUY","size":"24"},{"asset_id":"96600821790790307414914106093858868634329285205417149685270682748367152458577","best_ask":"0.54","best_bid":"0.53","hash":"cc96711282ea344355a604511ef5f33b12537326","price":"0.55","side":"SELL","size":"24"}],"timestamp":"1785211225858"},"payload_hash":"59bbd238415365179c5884cb8935303844ef5f521d1f39956b794983b7c6854e","raw_frame":"{\"market\":\"0xd412ce774cfcf8dc9f71164aac78783978aac7b03871702a3b8a481bd9dc9688\", \"price_changes\":[{\"asset_id\":\"107603864457683460275633293642179940881969192120168665300712204232021063124301\", \"price\":\"0.45\", \"size\":\"24\", \"side\":\"BUY\", \"hash\":\"cff13bc8c7c2705c1213e291ca5961be1914f2e4\", \"best_bid\":\"0.46\", \"best_ask\":\"0.47\"}, {\"asset_id\":\"96600821790790307414914106093858868634329285205417149685270682748367152458577\", \"price\":\"0.55\", \"size\":\"24\", \"side\":\"SELL\", \"hash\":\"cc96711282ea344355a604511ef5f33b12537326\", \"best_bid\":\"0.53\", \"best_ask\":\"0.54\"}], \"timestamp\":\"1785211225858\", \"event_type\":\"price_change\"}","received_at":"2026-07-28T04:00:29.401794Z","schema_version":"clob-market-ws.price_change.v1","sequence":null,"server_hash":null,"server_timestamp":"1785211225858","session_id":"2d607381e3054cee91998cdf45a4231c","source":"clob_market_ws"},"received_at":"2026-07-28T04:00:29.401794Z","record_id":"0aec209352ac12ee245655d23cda27ca9507bd2364b7113861b7fec9a8bbbf7d","schema_fingerprint":"4aa3821a28b0b7c2400bc59aba4bcc0a76e971dadd19610d3ad38c768e124dc7","schema_version":"edge-lab-recorder.raw.v1","sequence":null,"source":"clob_market_ws"}
{"event_at":"2026-07-28T04:00:25.859000Z","event_fingerprint":"645ecb50dd6b6f6009cdb545c644670e7037d78be07db612f8661d9128a26eef","payload":{"connection_id":"f6725804f86a4c4eb588e4d5ed7db029","event_at":"2026-07-28T04:00:25.859000Z","event_type":"price_change","frame_hash":"4fc73c88cf0b042004f254a5945812524e4c976a0faa8e44e3ce9e57e606ae50","frame_index":0,"kind":"data","monotonic_ns":313212455785166,"payload":{"event_type":"price_change","market":"0xd412ce774cfcf8dc9f71164aac78783978aac7b03871702a3b8a481bd9dc9688","price_changes":[{"asset_id":"107603864457683460275633293642179940881969192120168665300712204232021063124301","best_ask":"0.47","best_bid":"0.46","hash":"866f543333114e48e7a088279e92a47f25e99956","price":"0.42","side":"BUY","size":"110.27"},{"asset_id":"96600821790790307414914106093858868634329285205417149685270682748367152458577","best_ask":"0.54","best_bid":"0.53","hash":"bfbd8cbeedbf60299a8576612ef570b4e277d36a","price":"0.58","side":"SELL","size":"110.27"}],"timestamp":"1785211225859"},"payload_hash":"c67f1655fa556fabf7583190d646cea140ae0125dbed657ba36922829f1ea2d8","raw_frame":"{\"market\":\"0xd412ce774cfcf8dc9f71164aac78783978aac7b03871702a3b8a481bd9dc9688\", \"price_changes\":[{\"asset_id\":\"107603864457683460275633293642179940881969192120168665300712204232021063124301\", \"price\":\"0.42\", \"size\":\"110.27\", \"side\":\"BUY\", \"hash\":\"866f543333114e48e7a088279e92a47f25e99956\", \"best_bid\":\"0.46\", \"best_ask\":\"0.47\"}, {\"asset_id\":\"96600821790790307414914106093858868634329285205417149685270682748367152458577\", \"price\":\"0.58\", \"size\":\"110.27\", \"side\":\"SELL\", \"hash\":\"bfbd8cbeedbf60299a8576612ef570b4e277d36a\", \"best_bid\":\"0.53\", \"best_ask\":\"0.54\"}], \"timestamp\":\"1785211225859\", \"event_type\":\"price_change\"}","received_at":"2026-07-28T04:00:29.407658Z","schema_version":"clob-market-ws.price_change.v1","sequence":null,"server_hash":null,"server_timestamp":"1785211225859","session_id":"2d607381e3054cee91998cdf45a4231c","source":"clob_market_ws"},"received_at":"2026-07-28T04:00:29.407658Z","record_id":"a5361b874f32ee949933d99cddd4091ca50a267059fa2cff142aabdaeb3855fc","schema_fingerprint":"4aa3821a28b0b7c2400bc59aba4bcc0a76e971dadd19610d3ad38c768e124dc7","schema_version":"edge-lab-recorder.raw.v1","sequence":null,"source":"clob_market_ws"}
{"event_at":"2026-07-28T04:00:25.860000Z","event_fingerprint":"37e9da085779eee21c4a1ef9e7a9f206516656ccf5cf44ca0a9eeba70e0e1092","payload":{"connection_id":"f6725804f86a4c4eb588e4d5ed7db029","event_at":"2026-07-28T04:00:25.860000Z","event_type":"price_change","frame_hash":"c73a4a4afb5c46a2a7686a3a632a4930a0e3ca317d247ba70e5bb186d4c3359a","frame_index":0,"kind":"data","monotonic_ns":313212460338666,"payload":{"event_type":"price_change","market":"0xd412ce774cfcf8dc9f71164aac78783978aac7b03871702a3b8a481bd9dc9688","price_changes":[{"asset_id":"107603864457683460275633293642179940881969192120168665300712204232021063124301","best_ask":"0.47","best_bid":"0.46","hash":"97f3fe3a4a44b10f952d830252258629ff2db084","price":"0.43","side":"BUY","size":"137.6"},{"asset_id":"96600821790790307414914106093858868634329285205417149685270682748367152458577","best_ask":"0.54","best_bid":"0.53","hash":"c0da988abcee2b8d4be6dcca17a97785682cd7b2","price":"0.57","side":"SELL","size":"137.6"}],"timestamp":"1785211225860"},"payload_hash":"fcc97c13ec1d489449ea600733105a94e9ef511aacce8c27916363b8fad6f53d","raw_frame":"{\"market\":\"0xd412ce774cfcf8dc9f71164aac78783978aac7b03871702a3b8a481bd9dc9688\", \"price_changes\":[{\"asset_id\":\"107603864457683460275633293642179940881969192120168665300712204232021063124301\", \"price\":\"0.43\", \"size\":\"137.6\", \"side\":\"BUY\", \"hash\":\"97f3fe3a4a44b10f952d830252258629ff2db084\", \"best_bid\":\"0.46\", \"best_ask\":\"0.47\"}, {\"asset_id\":\"96600821790790307414914106093858868634329285205417149685270682748367152458577\", \"price\":\"0.57\", \"size\":\"137.6\", \"side\":\"SELL\", \"hash\":\"c0da988abcee2b8d4be6dcca17a97785682cd7b2\", \"best_bid\":\"0.53\", \"best_ask\":\"0.54\"}], \"timestamp\":\"1785211225860\", \"event_type\":\"price_change\"}","received_at":"2026-07-28T04:00:29.412212Z","schema_version":"clob-market-ws.price_change.v1","sequence":null,"server_hash":null,"server_timestamp":"1785211225860","session_id":"2d607381e3054cee91998cdf45a4231c","source":"clob_market_ws"},"received_at":"2026-07-28T04:00:29.412212Z","record_id":"d3437aaf2be6d6fd90d426a0a975db67cb1f69f0858feb51cb850512ca727c70","schema_fingerprint":"4aa3821a28b0b7c2400bc59aba4bcc0a76e971dadd19610d3ad38c768e124dc7","schema_version":"edge-lab-recorder.raw.v1","sequence":null,"source":"clob_market_ws"}
{"event_at":"2026-07-28T04:00:25.861000Z","event_fingerprint":"c3c3e717899db98e7d831c5986084c76689c150af5b4dbfece6ffa69eb8796e6","payload":{"connection_id":"f6725804f86a4c4eb588e4d5ed7db029","event_at":"2026-07-28T04:00:25.861000Z","event_type":"price_change","frame_hash":"39569ec5c49a566de2aa8bf19b053d379111644420e7a0a50534f868cbb7a74e","frame_index":0,"kind":"data","monotonic_ns":313212466122000,"payload":{"event_type":"price_change","market":"0xd412ce774cfcf8dc9f71164aac78783978aac7b03871702a3b8a481bd9dc9688","price_changes":[{"asset_id":"96600821790790307414914106093858868634329285205417149685270682748367152458577","best_ask":"0.54","best_bid":"0.53","hash":"2a7c59e19bb264f8791869412c4447036ca42514","price":"0.48","side":"BUY","size":"17"},{"asset_id":"107603864457683460275633293642179940881969192120168665300712204232021063124301","best_ask":"0.47","best_bid":"0.46","hash":"88172795c7d5084fcadc1e55bcb9e765d3a63f8e","price":"0.52","side":"SELL","size":"17"}],"timestamp":"1785211225861"},"payload_hash":"66dff62a4e6eebdf1d6c9ffb232e00e2d9c0fd7db6e34afacead58d8505c3331","raw_frame":"{\"market\":\"0xd412ce774cfcf8dc9f71164aac78783978aac7b03871702a3b8a481bd9dc9688\", \"price_changes\":[{\"asset_id\":\"96600821790790307414914106093858868634329285205417149685270682748367152458577\", \"price\":\"0.48\", \"size\":\"17\", \"side\":\"BUY\", \"hash\":\"2a7c59e19bb264f8791869412c4447036ca42514\", \"best_bid\":\"0.53\", \"best_ask\":\"0.54\"}, {\"asset_id\":\"107603864457683460275633293642179940881969192120168665300712204232021063124301\", \"price\":\"0.52\", \"size\":\"17\", \"side\":\"SELL\", \"hash\":\"88172795c7d5084fcadc1e55bcb9e765d3a63f8e\", \"best_bid\":\"0.46\", \"best_ask\":\"0.47\"}], \"timestamp\":\"1785211225861\", \"event_type\":\"price_change\"}","received_at":"2026-07-28T04:00:29.417995Z","schema_version":"clob-market-ws.price_change.v1","sequence":null,"server_hash":null,"server_timestamp":"1785211225861","session_id":"2d607381e3054cee91998cdf45a4231c","source":"clob_market_ws"},"received_at":"2026-07-28T04:00:29.417995Z","record_id":"dab5a2cff1d4fc480bd8f4ac387ed30e3af8af91c61e67eac46097aae7aef8d4","schema_fingerprint":"4aa3821a28b0b7c2400bc59aba4bcc0a76e971dadd19610d3ad38c768e124dc7","schema_version":"edge-lab-recorder.raw.v1","sequence":null,"source":"clob_market_ws"}
{"event_at":"2026-07-28T04:00:25.861000Z","event_fingerprint":"00bff861918bcc53e67cb6391cffbfaf1e8113d4785e5a7d0c27302133ba3897","payload":{"connection_id":"f6725804f86a4c4eb588e4d5ed7db029","event_at":"2026-07-28T04:00:25.861000Z","event_type":"price_change","frame_hash":"89d35240ecc253a888c696047917380a7980d168824db3ece995269a4f1efb81","frame_index":0,"kind":"data","monotonic_ns":313212472553916,"payload":{"event_type":"price_change","market":"0xd412ce774cfcf8dc9f71164aac78783978aac7b03871702a3b8a481bd9dc9688","price_changes":[{"asset_id":"96600821790790307414914106093858868634329285205417149685270682748367152458577","best_ask":"0.54","best_bid":"0.53","hash":"a2d1a82b5352b08a33e2713d7f673228db13ab8d","price":"0.53","side":"BUY","size":"19"},{"asset_id":"107603864457683460275633293642179940881969192120168665300712204232021063124301","best_ask":"0.47","best_bid":"0.46","hash":"bb56355268d41c351acabebdce1404e8b6c1869d","price":"0.47","side":"SELL","size":"19"}],"timestamp":"1785211225861"},"payload_hash":"41d9693c453d9f07bb6f0d3690b9833af356f969fa5edcbc64f0b7ba3287813d","raw_frame":"{\"market\":\"0xd412ce774cfcf8dc9f71164aac78783978aac7b03871702a3b8a481bd9dc9688\", \"price_changes\":[{\"asset_id\":\"96600821790790307414914106093858868634329285205417149685270682748367152458577\", \"price\":\"0.53\", \"size\":\"19\", \"side\":\"BUY\", \"hash\":\"a2d1a82b5352b08a33e2713d7f673228db13ab8d\", \"best_bid\":\"0.53\", \"best_ask\":\"0.54\"}, {\"asset_id\":\"107603864457683460275633293642179940881969192120168665300712204232021063124301\", \"price\":\"0.47\", \"size\":\"19\", \"side\":\"SELL\", \"hash\":\"bb56355268d41c351acabebdce1404e8b6c1869d\", \"best_bid\":\"0.46\", \"best_ask\":\"0.47\"}], \"timestamp\":\"1785211225861\", \"event_type\":\"price_change\"}","received_at":"2026-07-28T04:00:29.424427Z","schema_version":"clob-market-ws.price_change.v1","sequence":null,"server_hash":null,"server_timestamp":"1785211225861","session_id":"2d607381e3054cee91998cdf45a4231c","source":"clob_market_ws"},"received_at":"2026-07-28T04:00:29.424427Z","record_id":"41ab43bc64f537bf834fb90f72c1243fc760a576a3b2190cf7ba33af67a81a21","schema_fingerprint":"4aa3821a28b0b7c2400bc59aba4bcc0a76e971dadd19610d3ad38c768e124dc7","schema_version":"edge-lab-recorder.raw.v1","sequence":null,"source":"clob_market_ws"}
{"event_at":"2026-07-28T04:00:25.863000Z","event_fingerprint":"4b03fbca8f694371c53681d568aad91a57554168b77d34b0bcc79dada8109197","payload":{"connection_id":"f6725804f86a4c4eb588e4d5ed7db029","event_at":"2026-07-28T04:00:25.863000Z","event_type":"price_change","frame_hash":"c63f3ab36f1f41ccf89fbb8a18b48a7f7d61e1645a6d4d3f5c44e458a46e85f1","frame_index":0,"kind":"data","monotonic_ns":313212477358833,"payload":{"event_type":"price_change","market":"0xd412ce774cfcf8dc9f71164aac78783978aac7b03871702a3b8a481bd9dc9688","price_changes":[{"asset_id":"96600821790790307414914106093858868634329285205417149685270682748367152458577","best_ask":"0.54","best_bid":"0.53","hash":"8c102e0ccb24bd968ac866a1a02fe4013b049155","price":"0.56","side":"SELL","size":"136.2"},{"asset_id":"107603864457683460275633293642179940881969192120168665300712204232021063124301","best_ask":"0.47","best_bid":"0.46","hash":"937584a7c69371f585d7cbfea2420b011eec1b9a","price":"0.44","side":"BUY","size":"136.2"}],"timestamp":"1785211225863"},"payload_hash":"6a7096725cf8dcd2f553094705bbff7a03f4c559473be598c35cc3188d5e7be4","raw_frame":"{\"market\":\"0xd412ce774cfcf8dc9f71164aac78783978aac7b03871702a3b8a481bd9dc9688\", \"price_changes\":[{\"asset_id\":\"96600821790790307414914106093858868634329285205417149685270682748367152458577\", \"price\":\"0.56\", \"size\":\"136.2\", \"side\":\"SELL\", \"hash\":\"8c102e0ccb24bd968ac866a1a02fe4013b049155\", \"best_bid\":\"0.53\", \"best_ask\":\"0.54\"}, {\"asset_id\":\"107603864457683460275633293642179940881969192120168665300712204232021063124301\", \"price\":\"0.44\", \"size\":\"136.2\", \"side\":\"BUY\", \"hash\":\"937584a7c69371f585d7cbfea2420b011eec1b9a\", \"best_bid\":\"0.46\", \"best_ask\":\"0.47\"}], \"timestamp\":\"1785211225863\", \"event_type\":\"price_change\"}","received_at":"2026-07-28T04:00:29.429232Z","schema_version":"clob-market-ws.price_change.v1","sequence":null,"server_hash":null,"server_timestamp":"1785211225863","session_id":"2d607381e3054cee91998cdf45a4231c","source":"clob_market_ws"},"received_at":"2026-07-28T04:00:29.429232Z","record_id":"0201e5bce9214e5e8ad15468ff6ddc81d4164021f0aef9e309b0d108769113cc","schema_fingerprint":"4aa3821a28b0b7c2400bc59aba4bcc0a76e971dadd19610d3ad38c768e124dc7","schema_version":"edge-lab-recorder.raw.v1","sequence":null,"source":"clob_market_ws"}
{"event_at":"2026-07-28T04:00:25.863000Z","event_fingerprint":"e6c4e0f5d18ca300260c34b602655870b6462391a3910f19c9789593fa055074","payload":{"connection_id":"f6725804f86a4c4eb588e4d5ed7db029","event_at":"2026-07-28T04:00:25.863000Z","event_type":"price_change","frame_hash":"8ddb97c35feed14c472efc5a9a8112c8f830f3d1a9ef64ca738aed735a702e87","frame_index":0,"kind":"data","monotonic_ns":313212481958375,"payload":{"event_type":"price_change","market":"0xd412ce774cfcf8dc9f71164aac78783978aac7b03871702a3b8a481bd9dc9688","price_changes":[{"asset_id":"107603864457683460275633293642179940881969192120168665300712204232021063124301","best_ask":"0.47","best_bid":"0.46","hash":"549b7a8c994531b7c7dd754eb33c5fa06ef1b0d4","price":"0.43","side":"BUY","size":"143.6"},{"asset_id":"96600821790790307414914106093858868634329285205417149685270682748367152458577","best_ask":"0.54","best_bid":"0.53","hash":"017e30c5c98e98c29891324b781ee33adc4586f7","price":"0.57","side":"SELL","size":"143.6"}],"timestamp":"1785211225863"},"payload_hash":"646300aefded8b20d095ad80c2a919960d9d1014f3555227450ce0d44627ebbb","raw_frame":"{\"market\":\"0xd412ce774cfcf8dc9f71164aac78783978aac7b03871702a3b8a481bd9dc9688\", \"price_changes\":[{\"asset_id\":\"107603864457683460275633293642179940881969192120168665300712204232021063124301\", \"price\":\"0.43\", \"size\":\"143.6\", \"side\":\"BUY\", \"hash\":\"549b7a8c994531b7c7dd754eb33c5fa06ef1b0d4\", \"best_bid\":\"0.46\", \"best_ask\":\"0.47\"}, {\"asset_id\":\"96600821790790307414914106093858868634329285205417149685270682748367152458577\", \"price\":\"0.57\", \"size\":\"143.6\", \"side\":\"SELL\", \"hash\":\"017e30c5c98e98c29891324b781ee33adc4586f7\", \"best_bid\":\"0.53\", \"best_ask\":\"0.54\"}], \"timestamp\":\"1785211225863\", \"event_type\":\"price_change\"}","received_at":"2026-07-28T04:00:29.433832Z","schema_version":"clob-market-ws.price_change.v1","sequence":null,"server_hash":null,"server_timestamp":"1785211225863","session_id":"2d607381e3054cee91998cdf45a4231c","source":"clob_market_ws"},"received_at":"2026-07-28T04:00:29.433832Z","record_id":"12633c8ddac8bfd25d565f5d1f162d08909dbc302a7ba5093f50d5de501329b1","schema_fingerprint":"4aa3821a28b0b7c2400bc59aba4bcc0a76e971dadd19610d3ad38c768e124dc7","schema_version":"edge-lab-recorder.raw.v1","sequence":null,"source":"clob_market_ws"}
{"event_at":"2026-07-28T04:00:25.865000Z","event_fingerprint":"b3a1a7cb613369c1a08a0f3040d72e44f85feddec49168ce4292f41e6ec0782c","payload":{"connection_id":"f6725804f86a4c4eb588e4d5ed7db029","event_at":"2026-07-28T04:00:25.865000Z","event_type":"price_change","frame_hash":"af1e0f2bf5bf5f95c8cd98af27ac190be7fbb825a11ff8fd77eb9f6d41dfc2f6","frame_index":0,"kind":"data","monotonic_ns":313212486673875,"payload":{"event_type":"price_change","market":"0xd412ce774cfcf8dc9f71164aac78783978aac7b03871702a3b8a481bd9dc9688","price_changes":[{"asset_id":"107603864457683460275633293642179940881969192120168665300712204232021063124301","best_ask":"0.47","best_bid":"0.46","hash":"53e6313c895e955439a2dcfd073777e4ce787732","price":"0.45","side":"BUY","size":"30"},{"asset_id":"96600821790790307414914106093858868634329285205417149685270682748367152458577","best_ask":"0.54","best_bid":"0.53","hash":"44cc69e3660fb736d1114d4214029bd815c9bfcb","price":"0.55","side":"SELL","size":"30"}],"timestamp":"1785211225865"},"payload_hash":"1198db59ac5589e666dda4c06e7192af94bc7c7f6e10b252af327cb5c5774dec","raw_frame":"{\"market\":\"0xd412ce774cfcf8dc9f71164aac78783978aac7b03871702a3b8a481bd9dc9688\", \"price_changes\":[{\"asset_id\":\"107603864457683460275633293642179940881969192120168665300712204232021063124301\", \"price\":\"0.45\", \"size\":\"30\", \"side\":\"BUY\", \"hash\":\"53e6313c895e955439a2dcfd073777e4ce787732\", \"best_bid\":\"0.46\", \"best_ask\":\"0.47\"}, {\"asset_id\":\"96600821790790307414914106093858868634329285205417149685270682748367152458577\", \"price\":\"0.55\", \"size\":\"30\", \"side\":\"SELL\", \"hash\":\"44cc69e3660fb736d1114d4214029bd815c9bfcb\", \"best_bid\":\"0.53\", \"best_ask\":\"0.54\"}], \"timestamp\":\"1785211225865\", \"event_type\":\"price_change\"}","received_at":"2026-07-28T04:00:29.438547Z","schema_version":"clob-market-ws.price_change.v1","sequence":null,"server_hash":null,"server_timestamp":"1785211225865","session_id":"2d607381e3054cee91998cdf45a4231c","source":"clob_market_ws"},"received_at":"2026-07-28T04:00:29.438547Z","record_id":"67b62bebb42e09f58ea0ca770c51a5de31ad0a1fd23de7b04105313d81ef968b","schema_fingerprint":"4aa3821a28b0b7c2400bc59aba4bcc0a76e971dadd19610d3ad38c768e124dc7","schema_version":"edge-lab-recorder.raw.v1","sequence":null,"source":"clob_market_ws"}
{"event_at":"2026-07-28T04:00:25.866000Z","event_fingerprint":"94994c536b7acb1c9b1cd30557d4e9e9913e99a4f01097536c89b666cf83e6b7","payload":{"connection_id":"f6725804f86a4c4eb588e4d5ed7db029","event_at":"2026-07-28T04:00:25.866000Z","event_type":"price_change","frame_hash":"4e7c5960340f91bb35f92419442f3b7e6ee138fae21a58bf24ca8dba8e031b98","frame_index":0,"kind":"data","monotonic_ns":313212491527291,"payload":{"event_type":"price_change","market":"0xd412ce774cfcf8dc9f71164aac78783978aac7b03871702a3b8a481bd9dc9688","price_changes":[{"asset_id":"96600821790790307414914106093858868634329285205417149685270682748367152458577","best_ask":"0.54","best_bid":"0.53","hash":"486c6ced1e721dcf9468c77868b506a3b54e6b76","price":"0.53","side":"BUY","size":"13"},{"asset_id":"107603864457683460275633293642179940881969192120168665300712204232021063124301","best_ask":"0.47","best_bid":"0.46","hash":"56ba47a8e0417e3a6ba4e6d8ef26a8482181e55b","price":"0.47","side":"SELL","size":"13"}],"timestamp":"1785211225866"},"payload_hash":"019e245cc5fbfe1297405ce62af643bedd2ae72155071022ddd6d6b9fe41ca61","raw_frame":"{\"market\":\"0xd412ce774cfcf8dc9f71164aac78783978aac7b03871702a3b8a481bd9dc9688\", \"price_changes\":[{\"asset_id\":\"96600821790790307414914106093858868634329285205417149685270682748367152458577\", \"price\":\"0.53\", \"size\":\"13\", \"side\":\"BUY\", \"hash\":\"486c6ced1e721dcf9468c77868b506a3b54e6b76\", \"best_bid\":\"0.53\", \"best_ask\":\"0.54\"}, {\"asset_id\":\"107603864457683460275633293642179940881969192120168665300712204232021063124301\", \"price\":\"0.47\", \"size\":\"13\", \"side\":\"SELL\", \"hash\":\"56ba47a8e0417e3a6ba4e6d8ef26a8482181e55b\", \"best_bid\":\"0.46\", \"best_ask\":\"0.47\"}], \"timestamp\":\"1785211225866\", \"event_type\":\"price_change\"}","received_at":"2026-07-28T04:00:29.443400Z","schema_version":"clob-market-ws.price_change.v1","sequence":null,"server_hash":null,"server_timestamp":"1785211225866","session_id":"2d607381e3054cee91998cdf45a4231c","source":"clob_market_ws"},"received_at":"2026-07-28T04:00:29.443400Z","record_id":"aff621213cd4d204d43e9a579c9c539c082da1479a0a31d70348a97bf208fdd3","schema_fingerprint":"4aa3821a28b0b7c2400bc59aba4bcc0a76e971dadd19610d3ad38c768e124dc7","schema_version":"edge-lab-recorder.raw.v1","sequence":null,"source":"clob_market_ws"}
{"event_at":"2026-07-28T04:00:25.867000Z","event_fingerprint":"9151d613cb4b9e454c208c73bf68f361a708fb2efd4422bdcb127ee3677dc72c","payload":{"connection_id":"f6725804f86a4c4eb588e4d5ed7db029","event_at":"2026-07-28T04:00:25.867000Z","event_type":"price_change","frame_hash":"fb65f6136afaee3493bd378772b377fb44e0f2ef380d7a4b3244421bae4c9f48","frame_index":0,"kind":"data","monotonic_ns":313212495765083,"payload":{"event_type":"price_change","market":"0xd412ce774cfcf8dc9f71164aac78783978aac7b03871702a3b8a481bd9dc9688","price_changes":[{"asset_id":"107603864457683460275633293642179940881969192120168665300712204232021063124301","best_ask":"0.47","best_bid":"0.46","hash":"a21f4cf35cc7de77cb4ad0c74957c82e44e18b73","price":"0.45","side":"BUY","size":"74"},{"asset_id":"96600821790790307414914106093858868634329285205417149685270682748367152458577","best_ask":"0.54","best_bid":"0.53","hash":"54323230c4eb24b633b077eacdff9a2b062224e6","price":"0.55","side":"SELL","size":"74"}],"timestamp":"1785211225867"},"payload_hash":"7c6dd7d7adcc122d3a613f743dea845ecebdf114dd9256e70d9994f6ac50cd9c","raw_frame":"{\"market\":\"0xd412ce774cfcf8dc9f71164aac78783978aac7b03871702a3b8a481bd9dc9688\", \"price_changes\":[{\"asset_id\":\"107603864457683460275633293642179940881969192120168665300712204232021063124301\", \"price\":\"0.45\", \"size\":\"74\", \"side\":\"BUY\", \"hash\":\"a21f4cf35cc7de77cb4ad0c74957c82e44e18b73\", \"best_bid\":\"0.46\", \"best_ask\":\"0.47\"}, {\"asset_id\":\"96600821790790307414914106093858868634329285205417149685270682748367152458577\", \"price\":\"0.55\", \"size\":\"74\", \"side\":\"SELL\", \"hash\":\"54323230c4eb24b633b077eacdff9a2b062224e6\", \"best_bid\":\"0.53\", \"best_ask\":\"0.54\"}], \"timestamp\":\"1785211225867\", \"event_type\":\"price_change\"}","received_at":"2026-07-28T04:00:29.447638Z","schema_version":"clob-market-ws.price_change.v1","sequence":null,"server_hash":null,"server_timestamp":"1785211225867","session_id":"2d607381e3054cee91998cdf45a4231c","source":"clob_market_ws"},"received_at":"2026-07-28T04:00:29.447638Z","record_id":"8a587f351fab76d81c7b5d39264950fc484eff34dcd685b1b1bde3391a28bc69","schema_fingerprint":"4aa3821a28b0b7c2400bc59aba4bcc0a76e971dadd19610d3ad38c768e124dc7","schema_version":"edge-lab-recorder.raw.v1","sequence":null,"source":"clob_market_ws"}
{"event_at":"2026-07-28T04:00:25.869000Z","event_fingerprint":"2338c843a1c26d742cbfbeea9e8edc92d4462dfa77fe4ae09f314ff73ad37c8f","payload":{"connection_id":"f6725804f86a4c4eb588e4d5ed7db029","event_at":"2026-07-28T04:00:25.869000Z","event_type":"price_change","frame_hash":"6cd9380130835479cb889ac4784e506b1da00dee2edfedecd2478bde3ff7d519","frame_index":0,"kind":"data","monotonic_ns":313212502008500,"payload":{"event_type":"price_change","market":"0xd412ce774cfcf8dc9f71164aac78783978aac7b03871702a3b8a481bd9dc9688","price_changes":[{"asset_id":"107603864457683460275633293642179940881969192120168665300712204232021063124301","best_ask":"0.47","best_bid":"0.46","hash":"3cd5502736754da96a7cea25ee756d53e7837817","price":"0.45","side":"BUY","size":"100"},{"asset_id":"96600821790790307414914106093858868634329285205417149685270682748367152458577","best_ask":"0.54","best_bid":"0.53","hash":"5be582a15cd7330ed1105b0cfdb0e53b9a4b2ec6","price":"0.55","side":"SELL","size":"100"}],"timestamp":"1785211225869"},"payload_hash":"929990423fa9489f556ea0d90637b9318211ef40abdd0c961cbdd667ab0835d0","raw_frame":"{\"market\":\"0xd412ce774cfcf8dc9f71164aac78783978aac7b03871702a3b8a481bd9dc9688\", \"price_changes\":[{\"asset_id\":\"107603864457683460275633293642179940881969192120168665300712204232021063124301\", \"price\":\"0.45\", \"size\":\"100\", \"side\":\"BUY\", \"hash\":\"3cd5502736754da96a7cea25ee756d53e7837817\", \"best_bid\":\"0.46\", \"best_ask\":\"0.47\"}, {\"asset_id\":\"96600821790790307414914106093858868634329285205417149685270682748367152458577\", \"price\":\"0.55\", \"size\":\"100\", \"side\":\"SELL\", \"hash\":\"5be582a15cd7330ed1105b0cfdb0e53b9a4b2ec6\", \"best_bid\":\"0.53\", \"best_ask\":\"0.54\"}], \"timestamp\":\"1785211225869\", \"event_type\":\"price_change\"}","received_at":"2026-07-28T04:00:29.453882Z","schema_version":"clob-market-ws.price_change.v1","sequence":null,"server_hash":null,"server_timestamp":"1785211225869","session_id":"2d607381e3054cee91998cdf45a4231c","source":"clob_market_ws"},"received_at":"2026-07-28T04:00:29.453882Z","record_id":"37feff56ba3ae8d5d79b217c5b62ffa57042f4b8368f79ef98b472d4a72de9e9","schema_fingerprint":"4aa3821a28b0b7c2400bc59aba4bcc0a76e971dadd19610d3ad38c768e124dc7","schema_version":"edge-lab-recorder.raw.v1","sequence":null,"source":"clob_market_ws"}
{"event_at":"2026-07-28T04:00:25.871000Z","event_fingerprint":"39350d275bfcd6ef4e8981746610aa7bec90ee2aaccd70802641130cc3fccecd","payload":{"connection_id":"f6725804f86a4c4eb588e4d5ed7db029","event_at":"2026-07-28T04:00:25.871000Z","event_type":"price_change","frame_hash":"901f548626b9de0909ea85facf22da34f3fd68ddb872acef1cdeb37e32fc9993","frame_index":0,"kind":"data","monotonic_ns":313212507712208,"payload":{"event_type":"price_change","market":"0xd412ce774cfcf8dc9f71164aac78783978aac7b03871702a3b8a481bd9dc9688","price_changes":[{"asset_id":"107603864457683460275633293642179940881969192120168665300712204232021063124301","best_ask":"0.47","best_bid":"0.46","hash":"40ff8054b0caa16601012b96bb9753e0006d8542","price":"0.45","side":"BUY","size":"87"},{"asset_id":"96600821790790307414914106093858868634329285205417149685270682748367152458577","best_ask":"0.54","best_bid":"0.53","hash":"b8f20afaea1e61830a15121c74483b393cdf3bba","price":"0.55","side":"SELL","size":"87"}],"timestamp":"1785211225871"},"payload_hash":"f0867fbc283f1777f218aa7df790bcb5c1db688b26c44950d4e44fb3260f95a8","raw_frame":"{\"market\":\"0xd412ce774cfcf8dc9f71164aac78783978aac7b03871702a3b8a481bd9dc9688\", \"price_changes\":[{\"asset_id\":\"107603864457683460275633293642179940881969192120168665300712204232021063124301\", \"price\":\"0.45\", \"size\":\"87\", \"side\":\"BUY\", \"hash\":\"40ff8054b0caa16601012b96bb9753e0006d8542\", \"best_bid\":\"0.46\", \"best_ask\":\"0.47\"}, {\"asset_id\":\"96600821790790307414914106093858868634329285205417149685270682748367152458577\", \"price\":\"0.55\", \"size\":\"87\", \"side\":\"SELL\", \"hash\":\"b8f20afaea1e61830a15121c74483b393cdf3bba\", \"best_bid\":\"0.53\", \"best_ask\":\"0.54\"}], \"timestamp\":\"1785211225871\", \"event_type\":\"price_change\"}","received_at":"2026-07-28T04:00:29.459586Z","schema_version":"clob-market-ws.price_change.v1","sequence":null,"server_hash":null,"server_timestamp":"1785211225871","session_id":"2d607381e3054cee91998cdf45a4231c","source":"clob_market_ws"},"received_at":"2026-07-28T04:00:29.459586Z","record_id":"5102d4208229c140956d47bc781cef495e5f3be6dc2fbe69abfca2ae955750e9","schema_fingerprint":"4aa3821a28b0b7c2400bc59aba4bcc0a76e971dadd19610d3ad38c768e124dc7","schema_version":"edge-lab-recorder.raw.v1","sequence":null,"source":"clob_market_ws"}
{"event_at":"2026-07-28T04:00:25.871000Z","event_fingerprint":"3d1322ae4c7df88662f30da66dd754776050c7d04a967f5390160d788d68266e","payload":{"connection_id":"f6725804f86a4c4eb588e4d5ed7db029","event_at":"2026-07-28T04:00:25.871000Z","event_type":"price_change","frame_hash":"506f12057977951dd92ddad2a275131c3048ec741073e26256ff73c680ab59b3","frame_index":0,"kind":"data","monotonic_ns":313212513503708,"payload":{"event_type":"price_change","market":"0xd412ce774cfcf8dc9f71164aac78783978aac7b03871702a3b8a481bd9dc9688","price_changes":[{"asset_id":"107603864457683460275633293642179940881969192120168665300712204232021063124301","best_ask":"0.47","best_bid":"0.46","hash":"ae08a19b4856dd8fb46c480c6e1cb5aea9160917","price":"0.44","side":"BUY","size":"130.2"},{"asset_id":"96600821790790307414914106093858868634329285205417149685270682748367152458577","best_ask":"0.54","best_bid":"0.53","hash":"70e8836eccc6eed4e3224d2ad6e1df43da70b93a","price":"0.56","side":"SELL","size":"130.2"}],"timestamp":"1785211225871"},"payload_hash":"2c6e481a52939c55887eb340e66a7ebb05be1875fbde10fe34f2e2cd63608574","raw_frame":"{\"market\":\"0xd412ce774cfcf8dc9f71164aac78783978aac7b03871702a3b8a481bd9dc9688\", \"price_changes\":[{\"asset_id\":\"107603864457683460275633293642179940881969192120168665300712204232021063124301\", \"price\":\"0.44\", \"size\":\"130.2\", \"side\":\"BUY\", \"hash\":\"ae08a19b4856dd8fb46c480c6e1cb5aea9160917\", \"best_bid\":\"0.46\", \"best_ask\":\"0.47\"}, {\"asset_id\":\"96600821790790307414914106093858868634329285205417149685270682748367152458577\", \"price\":\"0.56\", \"size\":\"130.2\", \"side\":\"SELL\", \"hash\":\"70e8836eccc6eed4e3224d2ad6e1df43da70b93a\", \"best_bid\":\"0.53\", \"best_ask\":\"0.54\"}], \"timestamp\":\"1785211225871\", \"event_type\":\"price_change\"}","received_at":"2026-07-28T04:00:29.465375Z","schema_version":"clob-market-ws.price_change.v1","sequence":null,"server_hash":null,"server_timestamp":"1785211225871","session_id":"2d607381e3054cee91998cdf45a4231c","source":"clob_market_ws"},"received_at":"2026-07-28T04:00:29.465375Z","record_id":"92239edab100b28b0ad72cae369919ceac83ae5cbdb764bffe6193e88a44628b","schema_fingerprint":"4aa3821a28b0b7c2400bc59aba4bcc0a76e971dadd19610d3ad38c768e124dc7","schema_version":"edge-lab-recorder.raw.v1","sequence":null,"source":"clob_market_ws"}
{"event_at":"2026-07-28T04:00:25.871000Z","event_fingerprint":"05d4b63d408d440ac117af973baa8b2a078f8d12b4adf60ce8c0919edb7bad50","payload":{"connection_id":"f6725804f86a4c4eb588e4d5ed7db029","event_at":"2026-07-28T04:00:25.871000Z","event_type":"price_change","frame_hash":"112a16bd72bd6a74ff99cd6c6c4adc76d6c92af8d38e4e6bf6c62303c44986ea","frame_index":0,"kind":"data","monotonic_ns":313212518453166,"payload":{"event_type":"price_change","market":"0xd412ce774cfcf8dc9f71164aac78783978aac7b03871702a3b8a481bd9dc9688","price_changes":[{"asset_id":"96600821790790307414914106093858868634329285205417149685270682748367152458577","best_ask":"0.54","best_bid":"0.53","hash":"e416d9020b2bb54b24f5163b3108fa5f05da8e01","price":"0.53","side":"BUY","size":"19"},{"asset_id":"107603864457683460275633293642179940881969192120168665300712204232021063124301","best_ask":"0.47","best_bid":"0.46","hash":"6ba98d5ebdaaac1acbb7ee91767627d626f3e986","price":"0.47","side":"SELL","size":"19"}],"timestamp":"1785211225871"},"payload_hash":"6086a251e9de50d76a7d0f9590018991d9f0d00244b58f2021d02c9226783bdb","raw_frame":"{\"market\":\"0xd412ce774cfcf8dc9f71164aac78783978aac7b03871702a3b8a481bd9dc9688\", \"price_changes\":[{\"asset_id\":\"96600821790790307414914106093858868634329285205417149685270682748367152458577\", \"price\":\"0.53\", \"size\":\"19\", \"side\":\"BUY\", \"hash\":\"e416d9020b2bb54b24f5163b3108fa5f05da8e01\", \"best_bid\":\"0.53\", \"best_ask\":\"0.54\"}, {\"asset_id\":\"107603864457683460275633293642179940881969192120168665300712204232021063124301\", \"price\":\"0.47\", \"size\":\"19\", \"side\":\"SELL\", \"hash\":\"6ba98d5ebdaaac1acbb7ee91767627d626f3e986\", \"best_bid\":\"0.46\", \"best_ask\":\"0.47\"}], \"timestamp\":\"1785211225871\", \"event_type\":\"price_change\"}","received_at":"2026-07-28T04:00:29.470325Z","schema_version":"clob-market-ws.price_change.v1","sequence":null,"server_hash":null,"server_timestamp":"1785211225871","session_id":"2d607381e3054cee91998cdf45a4231c","source":"clob_market_ws"},"received_at":"2026-07-28T04:00:29.470325Z","record_id":"09a6ba5b71273b80d1b4d3e3fab403d46a08b910951f26a7eb6cdee4f176502c","schema_fingerprint":"4aa3821a28b0b7c2400bc59aba4bcc0a76e971dadd19610d3ad38c768e124dc7","schema_version":"edge-lab-recorder.raw.v1","sequence":null,"source":"clob_market_ws"}
{"event_at":"2026-07-28T04:00:25.872000Z","event_fingerprint":"45c910101795d69682832d2e539446a6f26a53f6d58dc36ab6e9ba3cb6275866","payload":{"connection_id":"f6725804f86a4c4eb588e4d5ed7db029","event_at":"2026-07-28T04:00:25.872000Z","event_type":"price_change","frame_hash":"eebed404bd2d6befaf4a0d43642b4afecdb5e44c80495f6667b23b481d730dd4","frame_index":0,"kind":"data","monotonic_ns":313212523452375,"payload":{"event_type":"price_change","market":"0xd412ce774cfcf8dc9f71164aac78783978aac7b03871702a3b8a481bd9dc9688","price_changes":[{"asset_id":"96600821790790307414914106093858868634329285205417149685270682748367152458577","best_ask":"0.54","best_bid":"0.53","hash":"d4233d704efce1a24a500d24b34196e1fc3ef2c6","price":"0.52","side":"BUY","size":"31.6"},{"asset_id":"107603864457683460275633293642179940881969192120168665300712204232021063124301","best_ask":"0.47","best_bid":"0.46","hash":"658239bf188fb1e12f6f525dcfb59b24c15155da","price":"0.48","side":"SELL","size":"31.6"}],"timestamp":"1785211225872"},"payload_hash":"8c09b01a46ae27f78bed91bdef77a5f0fa4142d7605edfac7bef5d1c52f3e84d","raw_frame":"{\"market\":\"0xd412ce774cfcf8dc9f71164aac78783978aac7b03871702a3b8a481bd9dc9688\", \"price_changes\":[{\"asset_id\":\"96600821790790307414914106093858868634329285205417149685270682748367152458577\", \"price\":\"0.52\", \"size\":\"31.6\", \"side\":\"BUY\", \"hash\":\"d4233d704efce1a24a500d24b34196e1fc3ef2c6\", \"best_bid\":\"0.53\", \"best_ask\":\"0.54\"}, {\"asset_id\":\"107603864457683460275633293642179940881969192120168665300712204232021063124301\", \"price\":\"0.48\", \"size\":\"31.6\", \"side\":\"SELL\", \"hash\":\"658239bf188fb1e12f6f525dcfb59b24c15155da\", \"best_bid\":\"0.46\", \"best_ask\":\"0.47\"}], \"timestamp\":\"1785211225872\", \"event_type\":\"price_change\"}","received_at":"2026-07-28T04:00:29.475325Z","schema_version":"clob-market-ws.price_change.v1","sequence":null,"server_hash":null,"server_timestamp":"1785211225872","session_id":"2d607381e3054cee91998cdf45a4231c","source":"clob_market_ws"},"received_at":"2026-07-28T04:00:29.475325Z","record_id":"6bbd314ff209c439d8b60e2c4b70c8eab060f6d3df7de9e1ea0dd25286690cd5","schema_fingerprint":"4aa3821a28b0b7c2400bc59aba4bcc0a76e971dadd19610d3ad38c768e124dc7","schema_version":"edge-lab-recorder.raw.v1","sequence":null,"source":"clob_market_ws"}
{"event_at":"2026-07-28T04:00:25.873000Z","event_fingerprint":"7ae306fe1da38709fb913e04594c2f5fb7168fd8337dfa5fb62609313781ea75","payload":{"connection_id":"f6725804f86a4c4eb588e4d5ed7db029","event_at":"2026-07-28T04:00:25.873000Z","event_type":"price_change","frame_hash":"62841f30156d56d47f410270d4ce0a0ed6273958d11f64764b0786cbf2969e63","frame_index":0,"kind":"data","monotonic_ns":313212528815625,"payload":{"event_type":"price_change","market":"0xd412ce774cfcf8dc9f71164aac78783978aac7b03871702a3b8a481bd9dc9688","price_changes":[{"asset_id":"107603864457683460275633293642179940881969192120168665300712204232021063124301","best_ask":"0.47","best_bid":"0.46","hash":"7d0453c77502f0df2cbb711f9cc3c63f7fa0afd7","price":"0.39","side":"BUY","size":"80.52"},{"asset_id":"96600821790790307414914106093858868634329285205417149685270682748367152458577","best_ask":"0.54","best_bid":"0.53","hash":"d611717cabe2d84d926f45f866864b78f4590522","price":"0.61","side":"SELL","size":"80.52"}],"timestamp":"1785211225873"},"payload_hash":"ec3c9321381b1f81189e3341db05ee38c43b525a1622275b7110fbf194c05307","raw_frame":"{\"market\":\"0xd412ce774cfcf8dc9f71164aac78783978aac7b03871702a3b8a481bd9dc9688\", \"price_changes\":[{\"asset_id\":\"107603864457683460275633293642179940881969192120168665300712204232021063124301\", \"price\":\"0.39\", \"size\":\"80.52\", \"side\":\"BUY\", \"hash\":\"7d0453c77502f0df2cbb711f9cc3c63f7fa0afd7\", \"best_bid\":\"0.46\", \"best_ask\":\"0.47\"}, {\"asset_id\":\"96600821790790307414914106093858868634329285205417149685270682748367152458577\", \"price\":\"0.61\", \"size\":\"80.52\", \"side\":\"SELL\", \"hash\":\"d611717cabe2d84d926f45f866864b78f4590522\", \"best_bid\":\"0.53\", \"best_ask\":\"0.54\"}], \"timestamp\":\"1785211225873\", \"event_type\":\"price_change\"}","received_at":"2026-07-28T04:00:29.480688Z","schema_version":"clob-market-ws.price_change.v1","sequence":null,"server_hash":null,"server_timestamp":"1785211225873","session_id":"2d607381e3054cee91998cdf45a4231c","source":"clob_market_ws"},"received_at":"2026-07-28T04:00:29.480688Z","record_id":"ec50f47a20a99507161620366d9bf94687483e72e6d2d326de838baa745f94e1","schema_fingerprint":"4aa3821a28b0b7c2400bc59aba4bcc0a76e971dadd19610d3ad38c768e124dc7","schema_version":"edge-lab-recorder.raw.v1","sequence":null,"source":"clob_market_ws"}
{"event_at":"2026-07-28T04:00:25.873000Z","event_fingerprint":"d39a8999e09dd953b76b1587ac2942d0b4db0e7b77def9783182ec019880eca1","payload":{"connection_id":"f6725804f86a4c4eb588e4d5ed7db029","event_at":"2026-07-28T04:00:25.873000Z","event_type":"price_change","frame_hash":"ce3b69548f3e6a754f631d7bf1625e60c8c807e3827883d24ed7a209d5d320e8","frame_index":0,"kind":"data","monotonic_ns":313212533754250,"payload":{"event_type":"price_change","market":"0xd412ce774cfcf8dc9f71164aac78783978aac7b03871702a3b8a481bd9dc9688","price_changes":[{"asset_id":"107603864457683460275633293642179940881969192120168665300712204232021063124301","best_ask":"0.47","best_bid":"0.46","hash":"844d4a60cd528ad098a48133800d0512ebe9086e","price":"0.37","side":"BUY","size":"113"},{"asset_id":"96600821790790307414914106093858868634329285205417149685270682748367152458577","best_ask":"0.54","best_bid":"0.53","hash":"3d4719c381dd60f2c4e3bf8a6f49a2e34d95b59f","price":"0.63","side":"SELL","size":"113"}],"timestamp":"1785211225873"},"payload_hash":"555e9c27e679dabb98d74b40e12fac28908c8fcd1d84c987c9844ccd6b3535b8","raw_frame":"{\"market\":\"0xd412ce774cfcf8dc9f71164aac78783978aac7b03871702a3b8a481bd9dc9688\", \"price_changes\":[{\"asset_id\":\"107603864457683460275633293642179940881969192120168665300712204232021063124301\", \"price\":\"0.37\", \"size\":\"113\", \"side\":\"BUY\", \"hash\":\"844d4a60cd528ad098a48133800d0512ebe9086e\", \"best_bid\":\"0.46\", \"best_ask\":\"0.47\"}, {\"asset_id\":\"96600821790790307414914106093858868634329285205417149685270682748367152458577\", \"price\":\"0.63\", \"size\":\"113\", \"side\":\"SELL\", \"hash\":\"3d4719c381dd60f2c4e3bf8a6f49a2e34d95b59f\", \"best_bid\":\"0.53\", \"best_ask\":\"0.54\"}], \"timestamp\":\"1785211225873\", \"event_type\":\"price_change\"}","received_at":"2026-07-28T04:00:29.485624Z","schema_version":"clob-market-ws.price_change.v1","sequence":null,"server_hash":null,"server_timestamp":"1785211225873","session_id":"2d607381e3054cee91998cdf45a4231c","source":"clob_market_ws"},"received_at":"2026-07-28T04:00:29.485624Z","record_id":"d35885c91c4d2d75b2badf5fbf99fd41a9e8466843659f0c4c4f4504a9151edd","schema_fingerprint":"4aa3821a28b0b7c2400bc59aba4bcc0a76e971dadd19610d3ad38c768e124dc7","schema_version":"edge-lab-recorder.raw.v1","sequence":null,"source":"clob_market_ws"}
{"event_at":"2026-07-28T04:00:25.874000Z","event_fingerprint":"bac2006d5982a86956d47df4d712e203f755c7eb22a49969360bc41f02994456","payload":{"connection_id":"f6725804f86a4c4eb588e4d5ed7db029","event_at":"2026-07-28T04:00:25.874000Z","event_type":"price_change","frame_hash":"d1652233a368ae64285e0523e57fb123a04657d571439fc244386eba0c5289c0","frame_index":0,"kind":"data","monotonic_ns":313212539621625,"payload":{"event_type":"price_change","market":"0xd412ce774cfcf8dc9f71164aac78783978aac7b03871702a3b8a481bd9dc9688","price_changes":[{"asset_id":"96600821790790307414914106093858868634329285205417149685270682748367152458577","best_ask":"0.54","best_bid":"0.53","hash":"748fe777497fa99a5dba5e7997f0cf0ecc107450","price":"0.52","side":"BUY","size":"37.6"},{"asset_id":"107603864457683460275633293642179940881969192120168665300712204232021063124301","best_ask":"0.47","best_bid":"0.46","hash":"2c94d9f269dd119cf5e301d1eb1c00c2f72c2015","price":"0.48","side":"SELL","size":"37.6"}],"timestamp":"1785211225874"},"payload_hash":"aba71480943a5124364cd9735aeaba6541d4af796de60a19d2bedd0036a1a009","raw_frame":"{\"market\":\"0xd412ce774cfcf8dc9f71164aac78783978aac7b03871702a3b8a481bd9dc9688\", \"price_changes\":[{\"asset_id\":\"96600821790790307414914106093858868634329285205417149685270682748367152458577\", \"price\":\"0.52\", \"size\":\"37.6\", \"side\":\"BUY\", \"hash\":\"748fe777497fa99a5dba5e7997f0cf0ecc107450\", \"best_bid\":\"0.53\", \"best_ask\":\"0.54\"}, {\"asset_id\":\"107603864457683460275633293642179940881969192120168665300712204232021063124301\", \"price\":\"0.48\", \"size\":\"37.6\", \"side\":\"SELL\", \"hash\":\"2c94d9f269dd119cf5e301d1eb1c00c2f72c2015\", \"best_bid\":\"0.46\", \"best_ask\":\"0.47\"}], \"timestamp\":\"1785211225874\", \"event_type\":\"price_change\"}","received_at":"2026-07-28T04:00:29.491494Z","schema_version":"clob-market-ws.price_change.v1","sequence":null,"server_hash":null,"server_timestamp":"1785211225874","session_id":"2d607381e3054cee91998cdf45a4231c","source":"clob_market_ws"},"received_at":"2026-07-28T04:00:29.491494Z","record_id":"becf007bddfdb955c703841e322bab77beaee7a3cf87d726233cefd23621960b","schema_fingerprint":"4aa3821a28b0b7c2400bc59aba4bcc0a76e971dadd19610d3ad38c768e124dc7","schema_version":"edge-lab-recorder.raw.v1","sequence":null,"source":"clob_market_ws"}
{"event_at":"2026-07-28T04:00:25.875000Z","event_fingerprint":"dfe79acae230679f5bc6d200d3458df5d940759469644818b85a02c34473880b","payload":{"connection_id":"f6725804f86a4c4eb588e4d5ed7db029","event_at":"2026-07-28T04:00:25.875000Z","event_type":"price_change","frame_hash":"497a9bf7f6851a6de8daad45b75dab109102a2ca29ff5efe874330293ea2acc8","frame_index":0,"kind":"data","monotonic_ns":313212545044958,"payload":{"event_type":"price_change","market":"0xd412ce774cfcf8dc9f71164aac78783978aac7b03871702a3b8a481bd9dc9688","price_changes":[{"asset_id":"107603864457683460275633293642179940881969192120168665300712204232021063124301","best_ask":"0.47","best_bid":"0.46","hash":"1e91eadba04e95fa588994659abdc9c53589db74","price":"0.46","side":"BUY","size":"18.6"},{"asset_id":"96600821790790307414914106093858868634329285205417149685270682748367152458577","best_ask":"0.54","best_bid":"0.53","hash":"ba5b1dffde581d564ecc1ef4bf9c72c449d6c963","price":"0.54","side":"SELL","size":"18.6"}],"timestamp":"1785211225875"},"payload_hash":"25c4a133f1702b24053408ce2f160d081232d602d082c3fa665dc32e335bab3f","raw_frame":"{\"market\":\"0xd412ce774cfcf8dc9f71164aac78783978aac7b03871702a3b8a481bd9dc9688\", \"price_changes\":[{\"asset_id\":\"107603864457683460275633293642179940881969192120168665300712204232021063124301\", \"price\":\"0.46\", \"size\":\"18.6\", \"side\":\"BUY\", \"hash\":\"1e91eadba04e95fa588994659abdc9c53589db74\", \"best_bid\":\"0.46\", \"best_ask\":\"0.47\"}, {\"asset_id\":\"96600821790790307414914106093858868634329285205417149685270682748367152458577\", \"price\":\"0.54\", \"size\":\"18.6\", \"side\":\"SELL\", \"hash\":\"ba5b1dffde581d564ecc1ef4bf9c72c449d6c963\", \"best_bid\":\"0.53\", \"best_ask\":\"0.54\"}], \"timestamp\":\"1785211225875\", \"event_type\":\"price_change\"}","received_at":"2026-07-28T04:00:29.496918Z","schema_version":"clob-market-ws.price_change.v1","sequence":null,"server_hash":null,"server_timestamp":"1785211225875","session_id":"2d607381e3054cee91998cdf45a4231c","source":"clob_market_ws"},"received_at":"2026-07-28T04:00:29.496918Z","record_id":"e7858a6de615cd49b2499fb3ba09c062d1d6c94657319b59ee645f1eed5f698c","schema_fingerprint":"4aa3821a28b0b7c2400bc59aba4bcc0a76e971dadd19610d3ad38c768e124dc7","schema_version":"edge-lab-recorder.raw.v1","sequence":null,"source":"clob_market_ws"}
{"event_at":"2026-07-28T04:00:25.876000Z","event_fingerprint":"cf0429061567e2dfe9106fe8720738d3814282d64a1b44eb195ab859d3d3b6c7","payload":{"connection_id":"f6725804f86a4c4eb588e4d5ed7db029","event_at":"2026-07-28T04:00:25.876000Z","event_type":"price_change","frame_hash":"89fce46b9c2e1d4579a03d3b5d48463c659b86b429bf00334fcda9819b8f1a36","frame_index":0,"kind":"data","monotonic_ns":313212549102916,"payload":{"event_type":"price_change","market":"0xd412ce774cfcf8dc9f71164aac78783978aac7b03871702a3b8a481bd9dc9688","price_changes":[{"asset_id":"107603864457683460275633293642179940881969192120168665300712204232021063124301","best_ask":"0.47","best_bid":"0.46","hash":"7824f0cc62f5bad9dca36a97d9f277bd7be43549","price":"0.4","side":"BUY","size":"262.92"},{"asset_id":"96600821790790307414914106093858868634329285205417149685270682748367152458577","best_ask":"0.54","best_bid":"0.53","hash":"6abefeb5851ca76900b7f591c73fb0877f59af1b","price":"0.6","side":"SELL","size":"262.92"}],"timestamp":"1785211225876"},"payload_hash":"5b8c880420b74adca025adcd30074e245369d702e15fc3e7c681f6385d863417","raw_frame":"{\"market\":\"0xd412ce774cfcf8dc9f71164aac78783978aac7b03871702a3b8a481bd9dc9688\", \"price_changes\":[{\"asset_id\":\"107603864457683460275633293642179940881969192120168665300712204232021063124301\", \"price\":\"0.4\", \"size\":\"262.92\", \"side\":\"BUY\", \"hash\":\"7824f0cc62f5bad9dca36a97d9f277bd7be43549\", \"best_bid\":\"0.46\", \"best_ask\":\"0.47\"}, {\"asset_id\":\"96600821790790307414914106093858868634329285205417149685270682748367152458577\", \"price\":\"0.6\", \"size\":\"262.92\", \"side\":\"SELL\", \"hash\":\"6abefeb5851ca76900b7f591c73fb0877f59af1b\", \"best_bid\":\"0.53\", \"best_ask\":\"0.54\"}], \"timestamp\":\"1785211225876\", \"event_type\":\"price_change\"}","received_at":"2026-07-28T04:00:29.500976Z","schema_version":"clob-market-ws.price_change.v1","sequence":null,"server_hash":null,"server_timestamp":"1785211225876","session_id":"2d607381e3054cee91998cdf45a4231c","source":"clob_market_ws"},"received_at":"2026-07-28T04:00:29.500976Z","record_id":"094ddd7b930c8635263ffdb0219057afaeccfa8c57bcd816dde1b30e5274f2e9","schema_fingerprint":"4aa3821a28b0b7c2400bc59aba4bcc0a76e971dadd19610d3ad38c768e124dc7","schema_version":"edge-lab-recorder.raw.v1","sequence":null,"source":"clob_market_ws"}
{"event_at":"2026-07-28T04:00:25.877000Z","event_fingerprint":"b224a7f2573029c99e3c59ec5253e6d02b8ea53c11838e298ec699c3aa0b71b0","payload":{"connection_id":"f6725804f86a4c4eb588e4d5ed7db029","event_at":"2026-07-28T04:00:25.877000Z","event_type":"price_change","frame_hash":"816be03192f360049903cc7341e785b9d9f741ae13cd2fe6952b5d3cbfad8c45","frame_index":0,"kind":"data","monotonic_ns":313212555469666,"payload":{"event_type":"price_change","market":"0xd412ce774cfcf8dc9f71164aac78783978aac7b03871702a3b8a481bd9dc9688","price_changes":[{"asset_id":"107603864457683460275633293642179940881969192120168665300712204232021063124301","best_ask":"0.47","best_bid":"0.46","hash":"fb266c16d895ef0a9767d7dac9b1026b6402d371","price":"0.45","side":"BUY","size":"92"},{"asset_id":"96600821790790307414914106093858868634329285205417149685270682748367152458577","best_ask":"0.54","best_bid":"0.53","hash":"e91f0e4867941df97349402e64890d48df062e6d","price":"0.55","side":"SELL","size":"92"}],"timestamp":"1785211225877"},"payload_hash":"d262901232ab84fa6eab4d1cd980344f8310b5aa9dd4c3c30c8de8a46ba6e199","raw_frame":"{\"market\":\"0xd412ce774cfcf8dc9f71164aac78783978aac7b03871702a3b8a481bd9dc9688\", \"price_changes\":[{\"asset_id\":\"107603864457683460275633293642179940881969192120168665300712204232021063124301\", \"price\":\"0.45\", \"size\":\"92\", \"side\":\"BUY\", \"hash\":\"fb266c16d895ef0a9767d7dac9b1026b6402d371\", \"best_bid\":\"0.46\", \"best_ask\":\"0.47\"}, {\"asset_id\":\"96600821790790307414914106093858868634329285205417149685270682748367152458577\", \"price\":\"0.55\", \"size\":\"92\", \"side\":\"SELL\", \"hash\":\"e91f0e4867941df97349402e64890d48df062e6d\", \"best_bid\":\"0.53\", \"best_ask\":\"0.54\"}], \"timestamp\":\"1785211225877\", \"event_type\":\"price_change\"}","received_at":"2026-07-28T04:00:29.507341Z","schema_version":"clob-market-ws.price_change.v1","sequence":null,"server_hash":null,"server_timestamp":"1785211225877","session_id":"2d607381e3054cee91998cdf45a4231c","source":"clob_market_ws"},"received_at":"2026-07-28T04:00:29.507341Z","record_id":"53b0a3309d7091f8a66409d517c439def25f7ec7d1645f4f70c895d579cd2693","schema_fingerprint":"4aa3821a28b0b7c2400bc59aba4bcc0a76e971dadd19610d3ad38c768e124dc7","schema_version":"edge-lab-recorder.raw.v1","sequence":null,"source":"clob_market_ws"}
{"event_at":"2026-07-28T04:00:25.878000Z","event_fingerprint":"c8ea4b9c0a9da017f0c9b572ba375221a209f29b93b11180da5b8bf59fad87a3","payload":{"connection_id":"f6725804f86a4c4eb588e4d5ed7db029","event_at":"2026-07-28T04:00:25.878000Z","event_type":"price_change","frame_hash":"1d8ea02bab2959b028afe2072db5c718cc48cbfbbfd2f4dfb9b31a610c31cbff","frame_index":0,"kind":"data","monotonic_ns":313212561175041,"payload":{"event_type":"price_change","market":"0xd412ce774cfcf8dc9f71164aac78783978aac7b03871702a3b8a481bd9dc9688","price_changes":[{"asset_id":"96600821790790307414914106093858868634329285205417149685270682748367152458577","best_ask":"0.54","best_bid":"0.53","hash":"fc4d64931694717e07d351d37088c43f8477ff92","price":"0.44","side":"BUY","size":"29"},{"asset_id":"107603864457683460275633293642179940881969192120168665300712204232021063124301","best_ask":"0.47","best_bid":"0.46","hash":"a05daa282ffe750a4b9cc1740dd2b63c76680d10","price":"0.56","side":"SELL","size":"29"}],"timestamp":"1785211225878"},"payload_hash":"ce0640f5e9c4e0a7ae352acc3768e5c72d58a8acd09b5831a2fd17e163485a7a","raw_frame":"{\"market\":\"0xd412ce774cfcf8dc9f71164aac78783978aac7b03871702a3b8a481bd9dc9688\", \"price_changes\":[{\"asset_id\":\"96600821790790307414914106093858868634329285205417149685270682748367152458577\", \"price\":\"0.44\", \"size\":\"29\", \"side\":\"BUY\", \"hash\":\"fc4d64931694717e07d351d37088c43f8477ff92\", \"best_bid\":\"0.53\", \"best_ask\":\"0.54\"}, {\"asset_id\":\"107603864457683460275633293642179940881969192120168665300712204232021063124301\", \"price\":\"0.56\", \"size\":\"29\", \"side\":\"SELL\", \"hash\":\"a05daa282ffe750a4b9cc1740dd2b63c76680d10\", \"best_bid\":\"0.46\", \"best_ask\":\"0.47\"}], \"timestamp\":\"1785211225878\", \"event_type\":\"price_change\"}","received_at":"2026-07-28T04:00:29.513047Z","schema_version":"clob-market-ws.price_change.v1","sequence":null,"server_hash":null,"server_timestamp":"1785211225878","session_id":"2d607381e3054cee91998cdf45a4231c","source":"clob_market_ws"},"received_at":"2026-07-28T04:00:29.513047Z","record_id":"1c5b25b0d72238cb184161a36e8cffcb6b6076af895710fe46376688ed0b9674","schema_fingerprint":"4aa3821a28b0b7c2400bc59aba4bcc0a76e971dadd19610d3ad38c768e124dc7","schema_version":"edge-lab-recorder.raw.v1","sequence":null,"source":"clob_market_ws"}
{"event_at":"2026-07-28T04:00:25.878000Z","event_fingerprint":"a54ca414164a0bbbfc0fa6990463c5e4790e4bc5f36d747db58a0c025a460bf7","payload":{"connection_id":"f6725804f86a4c4eb588e4d5ed7db029","event_at":"2026-07-28T04:00:25.878000Z","event_type":"price_change","frame_hash":"ac5e825bcbfe5093d82009b92d288809b4b3ab46a25801c7db04797cecfb8f70","frame_index":0,"kind":"data","monotonic_ns":313212565444833,"payload":{"event_type":"price_change","market":"0xd412ce774cfcf8dc9f71164aac78783978aac7b03871702a3b8a481bd9dc9688","price_changes":[{"asset_id":"96600821790790307414914106093858868634329285205417149685270682748367152458577","best_ask":"0.54","best_bid":"0.53","hash":"82050b7620364b807efb2817dc4f9b0053f9f709","price":"0.47","side":"BUY","size":"31"},{"asset_id":"107603864457683460275633293642179940881969192120168665300712204232021063124301","best_ask":"0.47","best_bid":"0.46","hash":"8485754c9ee157215fb8e35d4520e28e69e3d749","price":"0.53","side":"SELL","size":"31"}],"timestamp":"1785211225878"},"payload_hash":"9a9d782cb29f3d732c57b95fd17926c4f1a274874f685a2c2688f382e80a3d9b","raw_frame":"{\"market\":\"0xd412ce774cfcf8dc9f71164aac78783978aac7b03871702a3b8a481bd9dc9688\", \"price_changes\":[{\"asset_id\":\"96600821790790307414914106093858868634329285205417149685270682748367152458577\", \"price\":\"0.47\", \"size\":\"31\", \"side\":\"BUY\", \"hash\":\"82050b7620364b807efb2817dc4f9b0053f9f709\", \"best_bid\":\"0.53\", \"best_ask\":\"0.54\"}, {\"asset_id\":\"107603864457683460275633293642179940881969192120168665300712204232021063124301\", \"price\":\"0.53\", \"size\":\"31\", \"side\":\"SELL\", \"hash\":\"8485754c9ee157215fb8e35d4520e28e69e3d749\", \"best_bid\":\"0.46\", \"best_ask\":\"0.47\"}], \"timestamp\":\"1785211225878\", \"event_type\":\"price_change\"}","received_at":"2026-07-28T04:00:29.517317Z","schema_version":"clob-market-ws.price_change.v1","sequence":null,"server_hash":null,"server_timestamp":"1785211225878","session_id":"2d607381e3054cee91998cdf45a4231c","source":"clob_market_ws"},"received_at":"2026-07-28T04:00:29.517317Z","record_id":"668bc00e59a97ddde2455004921520b9aaa6f8d4abb6bc94b4a031d48bf2f8d9","schema_fingerprint":"4aa3821a28b0b7c2400bc59aba4bcc0a76e971dadd19610d3ad38c768e124dc7","schema_version":"edge-lab-recorder.raw.v1","sequence":null,"source":"clob_market_ws"}
{"event_at":"2026-07-28T04:00:25.879000Z","event_fingerprint":"eded05e1b957d2c7301f4cef936597a6aba30702d77c6f1f6dc678420f1f59aa","payload":{"connection_id":"f6725804f86a4c4eb588e4d5ed7db029","event_at":"2026-07-28T04:00:25.879000Z","event_type":"price_change","frame_hash":"78662a9b59cc88eb97be0f64269fcb2a8f71b5c6b8bd7e493f6c67d3b7ae09ba","frame_index":0,"kind":"data","monotonic_ns":313212571046500,"payload":{"event_type":"price_change","market":"0xd412ce774cfcf8dc9f71164aac78783978aac7b03871702a3b8a481bd9dc9688","price_changes":[{"asset_id":"107603864457683460275633293642179940881969192120168665300712204232021063124301","best_ask":"0.47","best_bid":"0.46","hash":"5f86600fff74f689411c20a96ce2eac715634d7f","price":"0.44","side":"BUY","size":"125.2"},{"asset_id":"96600821790790307414914106093858868634329285205417149685270682748367152458577","best_ask":"0.54","best_bid":"0.53","hash":"f69ad4db9a1038ceb8738c7dc1fddea6f36e03bc","price":"0.56","side":"SELL","size":"125.2"}],"timestamp":"1785211225879"},"payload_hash":"e51912ff33103b94ef1bf3b8de52ca3d0dcf74e48666b98c1954b15a6e29a625","raw_frame":"{\"market\":\"0xd412ce774cfcf8dc9f71164aac78783978aac7b03871702a3b8a481bd9dc9688\", \"price_changes\":[{\"asset_id\":\"107603864457683460275633293642179940881969192120168665300712204232021063124301\", \"price\":\"0.44\", \"size\":\"125.2\", \"side\":\"BUY\", \"hash\":\"5f86600fff74f689411c20a96ce2eac715634d7f\", \"best_bid\":\"0.46\", \"best_ask\":\"0.47\"}, {\"asset_id\":\"96600821790790307414914106093858868634329285205417149685270682748367152458577\", \"price\":\"0.56\", \"size\":\"125.2\", \"side\":\"SELL\", \"hash\":\"f69ad4db9a1038ceb8738c7dc1fddea6f36e03bc\", \"best_bid\":\"0.53\", \"best_ask\":\"0.54\"}], \"timestamp\":\"1785211225879\", \"event_type\":\"price_change\"}","received_at":"2026-07-28T04:00:29.522919Z","schema_version":"clob-market-ws.price_change.v1","sequence":null,"server_hash":null,"server_timestamp":"1785211225879","session_id":"2d607381e3054cee91998cdf45a4231c","source":"clob_market_ws"},"received_at":"2026-07-28T04:00:29.522919Z","record_id":"9d82c9f30f653ef670ba8d99759bbdc9e51b3d4080078314e4880380f7cc0f0f","schema_fingerprint":"4aa3821a28b0b7c2400bc59aba4bcc0a76e971dadd19610d3ad38c768e124dc7","schema_version":"edge-lab-recorder.raw.v1","sequence":null,"source":"clob_market_ws"}
{"event_at":"2026-07-28T04:00:25.880000Z","event_fingerprint":"3bb802c7da7d891c02758797b3133c03d0b58f987da42f49f3524f68f03f857e","payload":{"connection_id":"f6725804f86a4c4eb588e4d5ed7db029","event_at":"2026-07-28T04:00:25.880000Z","event_type":"price_change","frame_hash":"e4f9af6bc3cf793278b3d1b8401b7d85e02d79698837f27dc172c8758dd354d2","frame_index":0,"kind":"data","monotonic_ns":313212578045250,"payload":{"event_type":"price_change","market":"0xd412ce774cfcf8dc9f71164aac78783978aac7b03871702a3b8a481bd9dc9688","price_changes":[{"asset_id":"107603864457683460275633293642179940881969192120168665300712204232021063124301","best_ask":"0.47","best_bid":"0.46","hash":"30d8f91ead9234f8f6d94d5c54da6e2775b8b733","price":"0.46","side":"BUY","size":"23.6"},{"asset_id":"96600821790790307414914106093858868634329285205417149685270682748367152458577","best_ask":"0.54","best_bid":"0.53","hash":"57c172b3d96a831c96290e7f515c41553e564645","price":"0.54","side":"SELL","size":"23.6"}],"timestamp":"1785211225880"},"payload_hash":"e2bc28cc67eeff7d6f0b7215cb8a464813cbc9733d5c6289bbdbab22d1908f95","raw_frame":"{\"market\":\"0xd412ce774cfcf8dc9f71164aac78783978aac7b03871702a3b8a481bd9dc9688\", \"price_changes\":[{\"asset_id\":\"107603864457683460275633293642179940881969192120168665300712204232021063124301\", \"price\":\"0.46\", \"size\":\"23.6\", \"side\":\"BUY\", \"hash\":\"30d8f91ead9234f8f6d94d5c54da6e2775b8b733\", \"best_bid\":\"0.46\", \"best_ask\":\"0.47\"}, {\"asset_id\":\"96600821790790307414914106093858868634329285205417149685270682748367152458577\", \"price\":\"0.54\", \"size\":\"23.6\", \"side\":\"SELL\", \"hash\":\"57c172b3d96a831c96290e7f515c41553e564645\", \"best_bid\":\"0.53\", \"best_ask\":\"0.54\"}], \"timestamp\":\"1785211225880\", \"event_type\":\"price_change\"}","received_at":"2026-07-28T04:00:29.529919Z","schema_version":"clob-market-ws.price_change.v1","sequence":null,"server_hash":null,"server_timestamp":"1785211225880","session_id":"2d607381e3054cee91998cdf45a4231c","source":"clob_market_ws"},"received_at":"2026-07-28T04:00:29.529919Z","record_id":"f7d8060989dcef6f907b05ffd1e625957fea3e518d05bdf6457aa7ce4c28dca1","schema_fingerprint":"4aa3821a28b0b7c2400bc59aba4bcc0a76e971dadd19610d3ad38c768e124dc7","schema_version":"edge-lab-recorder.raw.v1","sequence":null,"source":"clob_market_ws"}
{"event_at":"2026-07-28T04:00:25.881000Z","event_fingerprint":"e61abd3f9cf1053f6d6f66e526832314f5c8585ed71254144e207b302498d85f","payload":{"connection_id":"f6725804f86a4c4eb588e4d5ed7db029","event_at":"2026-07-28T04:00:25.881000Z","event_type":"price_change","frame_hash":"66d507d3cefe4b74f66af3e28218fccd2499f83c3a9afb27f9edfd1641cb5564","frame_index":0,"kind":"data","monotonic_ns":313212583021166,"payload":{"event_type":"price_change","market":"0xd412ce774cfcf8dc9f71164aac78783978aac7b03871702a3b8a481bd9dc9688","price_changes":[{"asset_id":"96600821790790307414914106093858868634329285205417149685270682748367152458577","best_ask":"0.54","best_bid":"0.53","hash":"06139c200c9d9cda45e1f3eca146771464b9e950","price":"0.56","side":"SELL","size":"119.2"},{"asset_id":"107603864457683460275633293642179940881969192120168665300712204232021063124301","best_ask":"0.47","best_bid":"0.46","hash":"0999e21788b60ec226b3ee6339d086ba48ff3162","price":"0.44","side":"BUY","size":"119.2"}],"timestamp":"1785211225881"},"payload_hash":"4312ad6e52e38dfdebdd6594ee95195bdb6863d2c060a6eb96d15e7f5e54c628","raw_frame":"{\"market\":\"0xd412ce774cfcf8dc9f71164aac78783978aac7b03871702a3b8a481bd9dc9688\", \"price_changes\":[{\"asset_id\":\"96600821790790307414914106093858868634329285205417149685270682748367152458577\", \"price\":\"0.56\", \"size\":\"119.2\", \"side\":\"SELL\", \"hash\":\"06139c200c9d9cda45e1f3eca146771464b9e950\", \"best_bid\":\"0.53\", \"best_ask\":\"0.54\"}, {\"asset_id\":\"107603864457683460275633293642179940881969192120168665300712204232021063124301\", \"price\":\"0.44\", \"size\":\"119.2\", \"side\":\"BUY\", \"hash\":\"0999e21788b60ec226b3ee6339d086ba48ff3162\", \"best_bid\":\"0.46\", \"best_ask\":\"0.47\"}], \"timestamp\":\"1785211225881\", \"event_type\":\"price_change\"}","received_at":"2026-07-28T04:00:29.534890Z","schema_version":"clob-market-ws.price_change.v1","sequence":null,"server_hash":null,"server_timestamp":"1785211225881","session_id":"2d607381e3054cee91998cdf45a4231c","source":"clob_market_ws"},"received_at":"2026-07-28T04:00:29.534890Z","record_id":"fca884126f0424737a96a2a6c31f275ee1864009f24f8df84477a0e1783ce5da","schema_fingerprint":"4aa3821a28b0b7c2400bc59aba4bcc0a76e971dadd19610d3ad38c768e124dc7","schema_version":"edge-lab-recorder.raw.v1","sequence":null,"source":"clob_market_ws"}
{"event_at":"2026-07-28T04:00:25.882000Z","event_fingerprint":"47eff148a12cea5459cb827e5a891764c2aba8c9c378773edfd69df96ca8150a","payload":{"connection_id":"f6725804f86a4c4eb588e4d5ed7db029","event_at":"2026-07-28T04:00:25.882000Z","event_type":"price_change","frame_hash":"9f35033970eb7d80bbfb6211b75b829cdaa0742fbe1a2413e2c23804af9f7861","frame_index":0,"kind":"data","monotonic_ns":313212589197291,"payload":{"event_type":"price_change","market":"0xd412ce774cfcf8dc9f71164aac78783978aac7b03871702a3b8a481bd9dc9688","price_changes":[{"asset_id":"107603864457683460275633293642179940881969192120168665300712204232021063124301","best_ask":"0.47","best_bid":"0.46","hash":"c18f6c9c911762dad829536434d10163c871597d","price":"0.45","side":"BUY","size":"136"},{"asset_id":"96600821790790307414914106093858868634329285205417149685270682748367152458577","best_ask":"0.54","best_bid":"0.53","hash":"dddc98c6f97ffbe9cec82428166d39734639937d","price":"0.55","side":"SELL","size":"136"}],"timestamp":"1785211225882"},"payload_hash":"971b1a9a01cea429ace4bcdea4b22f1db4e2b9feca0959b5e563159bfff5153c","raw_frame":"{\"market\":\"0xd412ce774cfcf8dc9f71164aac78783978aac7b03871702a3b8a481bd9dc9688\", \"price_changes\":[{\"asset_id\":\"107603864457683460275633293642179940881969192120168665300712204232021063124301\", \"price\":\"0.45\", \"size\":\"136\", \"side\":\"BUY\", \"hash\":\"c18f6c9c911762dad829536434d10163c871597d\", \"best_bid\":\"0.46\", \"best_ask\":\"0.47\"}, {\"asset_id\":\"96600821790790307414914106093858868634329285205417149685270682748367152458577\", \"price\":\"0.55\", \"size\":\"136\", \"side\":\"SELL\", \"hash\":\"dddc98c6f97ffbe9cec82428166d39734639937d\", \"best_bid\":\"0.53\", \"best_ask\":\"0.54\"}], \"timestamp\":\"1785211225882\", \"event_type\":\"price_change\"}","received_at":"2026-07-28T04:00:29.541069Z","schema_version":"clob-market-ws.price_change.v1","sequence":null,"server_hash":null,"server_timestamp":"1785211225882","session_id":"2d607381e3054cee91998cdf45a4231c","source":"clob_market_ws"},"received_at":"2026-07-28T04:00:29.541069Z","record_id":"4daff186855f064c8d3c312bf3d2e65fa0a50dc3e57909ac3c50110c36443dcb","schema_fingerprint":"4aa3821a28b0b7c2400bc59aba4bcc0a76e971dadd19610d3ad38c768e124dc7","schema_version":"edge-lab-recorder.raw.v1","sequence":null,"source":"clob_market_ws"}
{"event_at":"2026-07-28T04:00:25.883000Z","event_fingerprint":"f20cfa852704f4febbcf326e65d9deaddd7ecf03a1898aee399d0f9e6d522307","payload":{"connection_id":"f6725804f86a4c4eb588e4d5ed7db029","event_at":"2026-07-28T04:00:25.883000Z","event_type":"price_change","frame_hash":"9c809c7776fe168a300488f1674b6018f9ff028e13324677f12c428422d5d2cb","frame_index":0,"kind":"data","monotonic_ns":313212595465958,"payload":{"event_type":"price_change","market":"0xd412ce774cfcf8dc9f71164aac78783978aac7b03871702a3b8a481bd9dc9688","price_changes":[{"asset_id":"107603864457683460275633293642179940881969192120168665300712204232021063124301","best_ask":"0.47","best_bid":"0.46","hash":"2cc5e47c9114edd77eda5415d610b73e77c09a3f","price":"0.44","side":"BUY","size":"114.2"},{"asset_id":"96600821790790307414914106093858868634329285205417149685270682748367152458577","best_ask":"0.54","best_bid":"0.53","hash":"0ac5cdc7d8fad2ca39709367ea2d6d48884f29fc","price":"0.56","side":"SELL","size":"114.2"}],"timestamp":"1785211225883"},"payload_hash":"97a9f78dfa42fc9b68df3159178212f58bbfb6fb6ff4d9ae7ac6315476c3a757","raw_frame":"{\"market\":\"0xd412ce774cfcf8dc9f71164aac78783978aac7b03871702a3b8a481bd9dc9688\", \"price_changes\":[{\"asset_id\":\"107603864457683460275633293642179940881969192120168665300712204232021063124301\", \"price\":\"0.44\", \"size\":\"114.2\", \"side\":\"BUY\", \"hash\":\"2cc5e47c9114edd77eda5415d610b73e77c09a3f\", \"best_bid\":\"0.46\", \"best_ask\":\"0.47\"}, {\"asset_id\":\"96600821790790307414914106093858868634329285205417149685270682748367152458577\", \"price\":\"0.56\", \"size\":\"114.2\", \"side\":\"SELL\", \"hash\":\"0ac5cdc7d8fad2ca39709367ea2d6d48884f29fc\", \"best_bid\":\"0.53\", \"best_ask\":\"0.54\"}], \"timestamp\":\"1785211225883\", \"event_type\":\"price_change\"}","received_at":"2026-07-28T04:00:29.547336Z","schema_version":"clob-market-ws.price_change.v1","sequence":null,"server_hash":null,"server_timestamp":"1785211225883","session_id":"2d607381e3054cee91998cdf45a4231c","source":"clob_market_ws"},"received_at":"2026-07-28T04:00:29.547336Z","record_id":"5b61fa98013e4e6bf6589fab558936a9da8914f9b600ec5ad5bd4619a19788db","schema_fingerprint":"4aa3821a28b0b7c2400bc59aba4bcc0a76e971dadd19610d3ad38c768e124dc7","schema_version":"edge-lab-recorder.raw.v1","sequence":null,"source":"clob_market_ws"}
{"event_at":"2026-07-28T04:00:25.883000Z","event_fingerprint":"dfd84c112a3292f5c8651340552a17fba355c59488173c8b1e77aff2edaf0733","payload":{"connection_id":"f6725804f86a4c4eb588e4d5ed7db029","event_at":"2026-07-28T04:00:25.883000Z","event_type":"price_change","frame_hash":"16e77557293dee98380643bb9e2e53b777cd20c3d85fd5645c838bcb5d338926","frame_index":0,"kind":"data","monotonic_ns":313212599722875,"payload":{"event_type":"price_change","market":"0xd412ce774cfcf8dc9f71164aac78783978aac7b03871702a3b8a481bd9dc9688","price_changes":[{"asset_id":"107603864457683460275633293642179940881969192120168665300712204232021063124301","best_ask":"0.47","best_bid":"0.46","hash":"85c8eacca704d4d623633fb8ec7166620606b839","price":"0.46","side":"BUY","size":"28.6"},{"asset_id":"96600821790790307414914106093858868634329285205417149685270682748367152458577","best_ask":"0.54","best_bid":"0.53","hash":"214b06a6893f23b88a9199fec7157002dffebe64","price":"0.54","side":"SELL","size":"28.6"}],"timestamp":"1785211225883"},"payload_hash":"357f55b5cd8b208c28d765d092cbc679239da6868708a45b30384f7c7a5e1e83","raw_frame":"{\"market\":\"0xd412ce774cfcf8dc9f71164aac78783978aac7b03871702a3b8a481bd9dc9688\", \"price_changes\":[{\"asset_id\":\"107603864457683460275633293642179940881969192120168665300712204232021063124301\", \"price\":\"0.46\", \"size\":\"28.6\", \"side\":\"BUY\", \"hash\":\"85c8eacca704d4d623633fb8ec7166620606b839\", \"best_bid\":\"0.46\", \"best_ask\":\"0.47\"}, {\"asset_id\":\"96600821790790307414914106093858868634329285205417149685270682748367152458577\", \"price\":\"0.54\", \"size\":\"28.6\", \"side\":\"SELL\", \"hash\":\"214b06a6893f23b88a9199fec7157002dffebe64\", \"best_bid\":\"0.53\", \"best_ask\":\"0.54\"}], \"timestamp\":\"1785211225883\", \"event_type\":\"price_change\"}","received_at":"2026-07-28T04:00:29.551592Z","schema_version":"clob-market-ws.price_change.v1","sequence":null,"server_hash":null,"server_timestamp":"1785211225883","session_id":"2d607381e3054cee91998cdf45a4231c","source":"clob_market_ws"},"received_at":"2026-07-28T04:00:29.551592Z","record_id":"bdeb53f61433b669bee6655b89a9e420fa1734b7a85b3f7ff2b9d625ecb940b1","schema_fingerprint":"4aa3821a28b0b7c2400bc59aba4bcc0a76e971dadd19610d3ad38c768e124dc7","schema_version":"edge-lab-recorder.raw.v1","sequence":null,"source":"clob_market_ws"}
{"event_at":"2026-07-28T04:00:25.884000Z","event_fingerprint":"66e0a33721900871de53d598b5e026693a47a5ba9f202d1b7daa2919fa07d1b5","payload":{"connection_id":"f6725804f86a4c4eb588e4d5ed7db029","event_at":"2026-07-28T04:00:25.884000Z","event_type":"price_change","frame_hash":"101319acfc95d4ea69e39e445dbbe9b5b11d1bc35a8b216a90e5518fae2e81df","frame_index":0,"kind":"data","monotonic_ns":313212605894041,"payload":{"event_type":"price_change","market":"0xd412ce774cfcf8dc9f71164aac78783978aac7b03871702a3b8a481bd9dc9688","price_changes":[{"asset_id":"107603864457683460275633293642179940881969192120168665300712204232021063124301","best_ask":"0.47","best_bid":"0.46","hash":"cbb21c0f8063d1e68e70ac8ec359197c4d9dc9eb","price":"0.39","side":"BUY","size":"74.52"},{"asset_id":"96600821790790307414914106093858868634329285205417149685270682748367152458577","best_ask":"0.54","best_bid":"0.53","hash":"8c4772f40398a15f043e001324454199a6939aec","price":"0.61","side":"SELL","size":"74.52"}],"timestamp":"1785211225884"},"payload_hash":"980e82bd96f9c2c14b4dbd7c9b48a9e3eca32d8dfd6636eaa0a4b4c41dbae9f2","raw_frame":"{\"market\":\"0xd412ce774cfcf8dc9f71164aac78783978aac7b03871702a3b8a481bd9dc9688\", \"price_changes\":[{\"asset_id\":\"107603864457683460275633293642179940881969192120168665300712204232021063124301\", \"price\":\"0.39\", \"size\":\"74.52\", \"side\":\"BUY\", \"hash\":\"cbb21c0f8063d1e68e70ac8ec359197c4d9dc9eb\", \"best_bid\":\"0.46\", \"best_ask\":\"0.47\"}, {\"asset_id\":\"96600821790790307414914106093858868634329285205417149685270682748367152458577\", \"price\":\"0.61\", \"size\":\"74.52\", \"side\":\"SELL\", \"hash\":\"8c4772f40398a15f043e001324454199a6939aec\", \"best_bid\":\"0.53\", \"best_ask\":\"0.54\"}], \"timestamp\":\"1785211225884\", \"event_type\":\"price_change\"}","received_at":"2026-07-28T04:00:29.557766Z","schema_version":"clob-market-ws.price_change.v1","sequence":null,"server_hash":null,"server_timestamp":"1785211225884","session_id":"2d607381e3054cee91998cdf45a4231c","source":"clob_market_ws"},"received_at":"2026-07-28T04:00:29.557766Z","record_id":"516f0acbb247098170a25e115300828cf7b7c6604fa7bff3b511b9dfe85da7cc","schema_fingerprint":"4aa3821a28b0b7c2400bc59aba4bcc0a76e971dadd19610d3ad38c768e124dc7","schema_version":"edge-lab-recorder.raw.v1","sequence":null,"source":"clob_market_ws"}
{"event_at":"2026-07-28T04:00:25.884000Z","event_fingerprint":"3484c3c785141be23e82110af6ed2f3040611d42ba1e71914edb7711b1cec961","payload":{"connection_id":"f6725804f86a4c4eb588e4d5ed7db029","event_at":"2026-07-28T04:00:25.884000Z","event_type":"price_change","frame_hash":"f902e0d9d055ca4401b1a1ba6ff2a42fb064566e34c2afcf0cddafabdfd2658f","frame_index":0,"kind":"data","monotonic_ns":313212609491500,"payload":{"event_type":"price_change","market":"0xd412ce774cfcf8dc9f71164aac78783978aac7b03871702a3b8a481bd9dc9688","price_changes":[{"asset_id":"107603864457683460275633293642179940881969192120168665300712204232021063124301","best_ask":"0.47","best_bid":"0.46","hash":"9ac9c75acca5e24b7c8eac8a78b7f97ca8999fba","price":"0.45","side":"BUY","size":"130"},{"asset_id":"96600821790790307414914106093858868634329285205417149685270682748367152458577","best_ask":"0.54","best_bid":"0.53","hash":"b035e46c731909d00e931d57bac404edb2b2b78a","price":"0.55","side":"SELL","size":"130"}],"timestamp":"1785211225884"},"payload_hash":"1fd63307c913e1f063c41facececebbf1346660b10898b96e079a11242560221","raw_frame":"{\"market\":\"0xd412ce774cfcf8dc9f71164aac78783978aac7b03871702a3b8a481bd9dc9688\", \"price_changes\":[{\"asset_id\":\"107603864457683460275633293642179940881969192120168665300712204232021063124301\", \"price\":\"0.45\", \"size\":\"130\", \"side\":\"BUY\", \"hash\":\"9ac9c75acca5e24b7c8eac8a78b7f97ca8999fba\", \"best_bid\":\"0.46\", \"best_ask\":\"0.47\"}, {\"asset_id\":\"96600821790790307414914106093858868634329285205417149685270682748367152458577\", \"price\":\"0.55\", \"size\":\"130\", \"side\":\"SELL\", \"hash\":\"b035e46c731909d00e931d57bac404edb2b2b78a\", \"best_bid\":\"0.53\", \"best_ask\":\"0.54\"}], \"timestamp\":\"1785211225884\", \"event_type\":\"price_change\"}","received_at":"2026-07-28T04:00:29.561363Z","schema_version":"clob-market-ws.price_change.v1","sequence":null,"server_hash":null,"server_timestamp":"1785211225884","session_id":"2d607381e3054cee91998cdf45a4231c","source":"clob_market_ws"},"received_at":"2026-07-28T04:00:29.561363Z","record_id":"2819cf38ad46bfdc83b41d145664da8f78195d205bd9d8d60e4471b53fc2dac7","schema_fingerprint":"4aa3821a28b0b7c2400bc59aba4bcc0a76e971dadd19610d3ad38c768e124dc7","schema_version":"edge-lab-recorder.raw.v1","sequence":null,"source":"clob_market_ws"}
{"event_at":"2026-07-28T04:00:25.888000Z","event_fingerprint":"5334820b8ea5645df1d7f3776cb697b92d0c37c1592c75fb4546a32a8128b1ac","payload":{"connection_id":"f6725804f86a4c4eb588e4d5ed7db029","event_at":"2026-07-28T04:00:25.888000Z","event_type":"price_change","frame_hash":"9a249de46488e717d0d89a304102e8d9e8c45092da730bcb77b1d5089b179beb","frame_index":0,"kind":"data","monotonic_ns":313212615080208,"payload":{"event_type":"price_change","market":"0xd412ce774cfcf8dc9f71164aac78783978aac7b03871702a3b8a481bd9dc9688","price_changes":[{"asset_id":"107603864457683460275633293642179940881969192120168665300712204232021063124301","best_ask":"0.47","best_bid":"0.46","hash":"8bb961ec3c5f6bbdd4f013bdd7386976e0bdee59","price":"0.45","side":"BUY","size":"142.6"},{"asset_id":"96600821790790307414914106093858868634329285205417149685270682748367152458577","best_ask":"0.54","best_bid":"0.53","hash":"437cd88e00e73b9583438d8cff21c91bd2aee0f8","price":"0.55","side":"SELL","size":"142.6"}],"timestamp":"1785211225888"},"payload_hash":"8d5d86e4b7e56cc5befd1359a2f3563c65002dd96123648a4a14437181359835","raw_frame":"{\"market\":\"0xd412ce774cfcf8dc9f71164aac78783978aac7b03871702a3b8a481bd9dc9688\", \"price_changes\":[{\"asset_id\":\"107603864457683460275633293642179940881969192120168665300712204232021063124301\", \"price\":\"0.45\", \"size\":\"142.6\", \"side\":\"BUY\", \"hash\":\"8bb961ec3c5f6bbdd4f013bdd7386976e0bdee59\", \"best_bid\":\"0.46\", \"best_ask\":\"0.47\"}, {\"asset_id\":\"96600821790790307414914106093858868634329285205417149685270682748367152458577\", \"price\":\"0.55\", \"size\":\"142.6\", \"side\":\"SELL\", \"hash\":\"437cd88e00e73b9583438d8cff21c91bd2aee0f8\", \"best_bid\":\"0.53\", \"best_ask\":\"0.54\"}], \"timestamp\":\"1785211225888\", \"event_type\":\"price_change\"}","received_at":"2026-07-28T04:00:29.566952Z","schema_version":"clob-market-ws.price_change.v1","sequence":null,"server_hash":null,"server_timestamp":"1785211225888","session_id":"2d607381e3054cee91998cdf45a4231c","source":"clob_market_ws"},"received_at":"2026-07-28T04:00:29.566952Z","record_id":"198fd40be5daa092a37e3d812eb61841160737eff12b3c5027cd5d61fd42c7f0","schema_fingerprint":"4aa3821a28b0b7c2400bc59aba4bcc0a76e971dadd19610d3ad38c768e124dc7","schema_version":"edge-lab-recorder.raw.v1","sequence":null,"source":"clob_market_ws"}
{"event_at":"2026-07-28T04:00:25.889000Z","event_fingerprint":"b41fdb9928cae389c7e4e67a426ee78b223e80c3d32c11261dabc57f23ab44c1","payload":{"connection_id":"f6725804f86a4c4eb588e4d5ed7db029","event_at":"2026-07-28T04:00:25.889000Z","event_type":"price_change","frame_hash":"62b75cd176d73ece486bf5b3fe68802f764474c5286dcc05e4d787c9579e55dd","frame_index":0,"kind":"data","monotonic_ns":313212620602875,"payload":{"event_type":"price_change","market":"0xd412ce774cfcf8dc9f71164aac78783978aac7b03871702a3b8a481bd9dc9688","price_changes":[{"asset_id":"107603864457683460275633293642179940881969192120168665300712204232021063124301","best_ask":"0.47","best_bid":"0.46","hash":"62f9b47e7ebe701051d285b3c6d8b717a471dfb2","price":"0.45","side":"BUY","size":"147.6"},{"asset_id":"96600821790790307414914106093858868634329285205417149685270682748367152458577","best_ask":"0.54","best_bid":"0.53","hash":"a91bdc905d271bf36154ffa71c199df81f2291c2","price":"0.55","side":"SELL","size":"147.6"}],"timestamp":"1785211225889"},"payload_hash":"0575e22b4b64ac3df4a5d662a47b674940929d1bd594acde0ce578c628d98b62","raw_frame":"{\"market\":\"0xd412ce774cfcf8dc9f71164aac78783978aac7b03871702a3b8a481bd9dc9688\", \"price_changes\":[{\"asset_id\":\"107603864457683460275633293642179940881969192120168665300712204232021063124301\", \"price\":\"0.45\", \"size\":\"147.6\", \"side\":\"BUY\", \"hash\":\"62f9b47e7ebe701051d285b3c6d8b717a471dfb2\", \"best_bid\":\"0.46\", \"best_ask\":\"0.47\"}, {\"asset_id\":\"96600821790790307414914106093858868634329285205417149685270682748367152458577\", \"price\":\"0.55\", \"size\":\"147.6\", \"side\":\"SELL\", \"hash\":\"a91bdc905d271bf36154ffa71c199df81f2291c2\", \"best_bid\":\"0.53\", \"best_ask\":\"0.54\"}], \"timestamp\":\"1785211225889\", \"event_type\":\"price_change\"}","received_at":"2026-07-28T04:00:29.572475Z","schema_version":"clob-market-ws.price_change.v1","sequence":null,"server_hash":null,"server_timestamp":"1785211225889","session_id":"2d607381e3054cee91998cdf45a4231c","source":"clob_market_ws"},"received_at":"2026-07-28T04:00:29.572475Z","record_id":"84ac16c94e93ee2cc8ecd9881333989db131fe1c3703eaf7417d9b378a934f56","schema_fingerprint":"4aa3821a28b0b7c2400bc59aba4bcc0a76e971dadd19610d3ad38c768e124dc7","schema_version":"edge-lab-recorder.raw.v1","sequence":null,"source":"clob_market_ws"}
{"event_at":"2026-07-28T04:00:25.891000Z","event_fingerprint":"4681dec8177319560021a06301d1ea51a9098457f9f983b522ba50e554d98280","payload":{"connection_id":"f6725804f86a4c4eb588e4d5ed7db029","event_at":"2026-07-28T04:00:25.891000Z","event_type":"price_change","frame_hash":"33b352b6b3328134832f1b78839f90ce723c2365f974b3f3cc5de4d7e70aac75","frame_index":0,"kind":"data","monotonic_ns":313212625387833,"payload":{"event_type":"price_change","market":"0xd412ce774cfcf8dc9f71164aac78783978aac7b03871702a3b8a481bd9dc9688","price_changes":[{"asset_id":"96600821790790307414914106093858868634329285205417149685270682748367152458577","best_ask":"0.54","best_bid":"0.53","hash":"875207a1041be936327386b3808166d48fc17c59","price":"0.36","side":"BUY","size":"35"},{"asset_id":"107603864457683460275633293642179940881969192120168665300712204232021063124301","best_ask":"0.47","best_bid":"0.46","hash":"11a86aa7107b1cf84c83754cb5b44d41d3e7e97e","price":"0.64","side":"SELL","size":"35"}],"timestamp":"1785211225891"},"payload_hash":"24f20574105a03138750394e9dca99d5649cd967d7f78735d225cb3f7ffb965c","raw_frame":"{\"market\":\"0xd412ce774cfcf8dc9f71164aac78783978aac7b03871702a3b8a481bd9dc9688\", \"price_changes\":[{\"asset_id\":\"96600821790790307414914106093858868634329285205417149685270682748367152458577\", \"price\":\"0.36\", \"size\":\"35\", \"side\":\"BUY\", \"hash\":\"875207a1041be936327386b3808166d48fc17c59\", \"best_bid\":\"0.53\", \"best_ask\":\"0.54\"}, {\"asset_id\":\"107603864457683460275633293642179940881969192120168665300712204232021063124301\", \"price\":\"0.64\", \"size\":\"35\", \"side\":\"SELL\", \"hash\":\"11a86aa7107b1cf84c83754cb5b44d41d3e7e97e\", \"best_bid\":\"0.46\", \"best_ask\":\"0.47\"}], \"timestamp\":\"1785211225891\", \"event_type\":\"price_change\"}","received_at":"2026-07-28T04:00:29.577260Z","schema_version":"clob-market-ws.price_change.v1","sequence":null,"server_hash":null,"server_timestamp":"1785211225891","session_id":"2d607381e3054cee91998cdf45a4231c","source":"clob_market_ws"},"received_at":"2026-07-28T04:00:29.577260Z","record_id":"517abe0a6ae7d1e2eff9b056b5cfdad84f3eaaffbc3e1e9acd2a8cb5a5ee0057","schema_fingerprint":"4aa3821a28b0b7c2400bc59aba4bcc0a76e971dadd19610d3ad38c768e124dc7","schema_version":"edge-lab-recorder.raw.v1","sequence":null,"source":"clob_market_ws"}
{"event_at":"2026-07-28T04:00:25.892000Z","event_fingerprint":"5ec0ff9315a982ef8e10d3fc4debb395558552eb7b8c1ac7db8964598286020f","payload":{"connection_id":"f6725804f86a4c4eb588e4d5ed7db029","event_at":"2026-07-28T04:00:25.892000Z","event_type":"price_change","frame_hash":"69132bec5a3a67aee788fa9a726ab07896b2482511ddb6c7a2c5d1fe930065ed","frame_index":0,"kind":"data","monotonic_ns":313212633172958,"payload":{"event_type":"price_change","market":"0xd412ce774cfcf8dc9f71164aac78783978aac7b03871702a3b8a481bd9dc9688","price_changes":[{"asset_id":"107603864457683460275633293642179940881969192120168665300712204232021063124301","best_ask":"0.47","best_bid":"0.46","hash":"4c0ccc28db3fb2222f1d8e20ed9c378994d74655","price":"0.44","side":"BUY","size":"126.2"},{"asset_id":"96600821790790307414914106093858868634329285205417149685270682748367152458577","best_ask":"0.54","best_bid":"0.53","hash":"1f71331597e703075363a2c2d186028a6fdb7835","price":"0.56","side":"SELL","size":"126.2"}],"timestamp":"1785211225892"},"payload_hash":"df098e99b1199de8e03bc096e8ea77ced09be6455763d279b6513f83999aa79f","raw_frame":"{\"market\":\"0xd412ce774cfcf8dc9f71164aac78783978aac7b03871702a3b8a481bd9dc9688\", \"price_changes\":[{\"asset_id\":\"107603864457683460275633293642179940881969192120168665300712204232021063124301\", \"price\":\"0.44\", \"size\":\"126.2\", \"side\":\"BUY\", \"hash\":\"4c0ccc28db3fb2222f1d8e20ed9c378994d74655\", \"best_bid\":\"0.46\", \"best_ask\":\"0.47\"}, {\"asset_id\":\"96600821790790307414914106093858868634329285205417149685270682748367152458577\", \"price\":\"0.56\", \"size\":\"126.2\", \"side\":\"SELL\", \"hash\":\"1f71331597e703075363a2c2d186028a6fdb7835\", \"best_bid\":\"0.53\", \"best_ask\":\"0.54\"}], \"timestamp\":\"1785211225892\", \"event_type\":\"price_change\"}","received_at":"2026-07-28T04:00:29.585045Z","schema_version":"clob-market-ws.price_change.v1","sequence":null,"server_hash":null,"server_timestamp":"1785211225892","session_id":"2d607381e3054cee91998cdf45a4231c","source":"clob_market_ws"},"received_at":"2026-07-28T04:00:29.585045Z","record_id":"1b32a86db71efff2330ca6f2323b21fdf63f6a03eeadac3c609de85d3203e3e3","schema_fingerprint":"4aa3821a28b0b7c2400bc59aba4bcc0a76e971dadd19610d3ad38c768e124dc7","schema_version":"edge-lab-recorder.raw.v1","sequence":null,"source":"clob_market_ws"}
{"event_at":"2026-07-28T04:00:25.893000Z","event_fingerprint":"503328a6acbdadd30d677b68a75091672f8a36ab1bbf0ba041615fb96bb89876","payload":{"connection_id":"f6725804f86a4c4eb588e4d5ed7db029","event_at":"2026-07-28T04:00:25.893000Z","event_type":"price_change","frame_hash":"36c088a68b4440dbd9f7ce68c402ad4b588a2b4cf21334c6e12b695bbd248f6a","frame_index":0,"kind":"data","monotonic_ns":313212640787916,"payload":{"event_type":"price_change","market":"0xd412ce774cfcf8dc9f71164aac78783978aac7b03871702a3b8a481bd9dc9688","price_changes":[{"asset_id":"96600821790790307414914106093858868634329285205417149685270682748367152458577","best_ask":"0.54","best_bid":"0.53","hash":"e1368215204d7d08aea0b9bd416e5faa191dcd30","price":"0.54","side":"SELL","size":"36.6"},{"asset_id":"107603864457683460275633293642179940881969192120168665300712204232021063124301","best_ask":"0.47","best_bid":"0.46","hash":"46d2ade5413138a268139fd12f2e3af0f5a8030a","price":"0.46","side":"BUY","size":"36.6"}],"timestamp":"1785211225893"},"payload_hash":"474fe12ef56edbe58e78f5b857bd6ca485a93c0b6a4434a9b0b38fac83832c40","raw_frame":"{\"market\":\"0xd412ce774cfcf8dc9f71164aac78783978aac7b03871702a3b8a481bd9dc9688\", \"price_changes\":[{\"asset_id\":\"96600821790790307414914106093858868634329285205417149685270682748367152458577\", \"price\":\"0.54\", \"size\":\"36.6\", \"side\":\"SELL\", \"hash\":\"e1368215204d7d08aea0b9bd416e5faa191dcd30\", \"best_bid\":\"0.53\", \"best_ask\":\"0.54\"}, {\"asset_id\":\"107603864457683460275633293642179940881969192120168665300712204232021063124301\", \"price\":\"0.46\", \"size\":\"36.6\", \"side\":\"BUY\", \"hash\":\"46d2ade5413138a268139fd12f2e3af0f5a8030a\", \"best_bid\":\"0.46\", \"best_ask\":\"0.47\"}], \"timestamp\":\"1785211225893\", \"event_type\":\"price_change\"}","received_at":"2026-07-28T04:00:29.592660Z","schema_version":"clob-market-ws.price_change.v1","sequence":null,"server_hash":null,"server_timestamp":"1785211225893","session_id":"2d607381e3054cee91998cdf45a4231c","source":"clob_market_ws"},"received_at":"2026-07-28T04:00:29.592660Z","record_id":"eddc8097434a769d7b6c19fc24dfb7b8fc312e29bcb1b874b683c16cc96adbd7","schema_fingerprint":"4aa3821a28b0b7c2400bc59aba4bcc0a76e971dadd19610d3ad38c768e124dc7","schema_version":"edge-lab-recorder.raw.v1","sequence":null,"source":"clob_market_ws"}
{"event_at":"2026-07-28T04:00:25.896000Z","event_fingerprint":"98d5b7199ab5907bcaa52dcd8d3b91854a2459c957e38faa922ca5d6174cffb0","payload":{"connection_id":"f6725804f86a4c4eb588e4d5ed7db029","event_at":"2026-07-28T04:00:25.896000Z","event_type":"price_change","frame_hash":"7c463834cf3c460cf71c23430e0e0056c42cb7b0259cb8aab66686f7a8f143fc","frame_index":0,"kind":"data","monotonic_ns":313212647576625,"payload":{"event_type":"price_change","market":"0xd412ce774cfcf8dc9f71164aac78783978aac7b03871702a3b8a481bd9dc9688","price_changes":[{"asset_id":"107603864457683460275633293642179940881969192120168665300712204232021063124301","best_ask":"0.47","best_bid":"0.46","hash":"6cb1a96bc9f592853ff519b0235eaa73847afbe2","price":"0.44","side":"BUY","size":"136.2"},{"asset_id":"96600821790790307414914106093858868634329285205417149685270682748367152458577","best_ask":"0.54","best_bid":"0.53","hash":"6ee213819b7bc6184cf171b5cacf44878b5db9ce","price":"0.56","side":"SELL","size":"136.2"}],"timestamp":"1785211225896"},"payload_hash":"25c4acb8c8cace59193928facbb4de9c453a06e257f39b161562fde954fe5686","raw_frame":"{\"market\":\"0xd412ce774cfcf8dc9f71164aac78783978aac7b03871702a3b8a481bd9dc9688\", \"price_changes\":[{\"asset_id\":\"107603864457683460275633293642179940881969192120168665300712204232021063124301\", \"price\":\"0.44\", \"size\":\"136.2\", \"side\":\"BUY\", \"hash\":\"6cb1a96bc9f592853ff519b0235eaa73847afbe2\", \"best_bid\":\"0.46\", \"best_ask\":\"0.47\"}, {\"asset_id\":\"96600821790790307414914106093858868634329285205417149685270682748367152458577\", \"price\":\"0.56\", \"size\":\"136.2\", \"side\":\"SELL\", \"hash\":\"6ee213819b7bc6184cf171b5cacf44878b5db9ce\", \"best_bid\":\"0.53\", \"best_ask\":\"0.54\"}], \"timestamp\":\"1785211225896\", \"event_type\":\"price_change\"}","received_at":"2026-07-28T04:00:29.599448Z","schema_version":"clob-market-ws.price_change.v1","sequence":null,"server_hash":null,"server_timestamp":"1785211225896","session_id":"2d607381e3054cee91998cdf45a4231c","source":"clob_market_ws"},"received_at":"2026-07-28T04:00:29.599448Z","record_id":"38b74ffe9f9054d6dfa4ccab660fd358470afb2df77dc56917f0b50e8237f381","schema_fingerprint":"4aa3821a28b0b7c2400bc59aba4bcc0a76e971dadd19610d3ad38c768e124dc7","schema_version":"edge-lab-recorder.raw.v1","sequence":null,"source":"clob_market_ws"}
{"event_at":"2026-07-28T04:00:25.904000Z","event_fingerprint":"896ba86b69bc04477797854f2b377376f3434733ddab89490c45a55287ff4cab","payload":{"connection_id":"f6725804f86a4c4eb588e4d5ed7db029","event_at":"2026-07-28T04:00:25.904000Z","event_type":"price_change","frame_hash":"c9a45dd78ae00a95aee3c8b7eb95e75b263b51fe72c7b927db0589674aff7d7f","frame_index":0,"kind":"data","monotonic_ns":313212656374833,"payload":{"event_type":"price_change","market":"0xd412ce774cfcf8dc9f71164aac78783978aac7b03871702a3b8a481bd9dc9688","price_changes":[{"asset_id":"107603864457683460275633293642179940881969192120168665300712204232021063124301","best_ask":"0.47","best_bid":"0.46","hash":"5ef85a43e1fbc56bb66f6a7bf4e2ab52f9497ff1","price":"0.26","side":"BUY","size":"134.2"},{"asset_id":"96600821790790307414914106093858868634329285205417149685270682748367152458577","best_ask":"0.54","best_bid":"0.53","hash":"021a842ef0c0daf18db724953d97071231e2535f","price":"0.74","side":"SELL","size":"134.2"}],"timestamp":"1785211225904"},"payload_hash":"2229027b0c97db19299322b7be18fc21096fa2e555f250d9a4ec99abe281e11a","raw_frame":"{\"market\":\"0xd412ce774cfcf8dc9f71164aac78783978aac7b03871702a3b8a481bd9dc9688\", \"price_changes\":[{\"asset_id\":\"107603864457683460275633293642179940881969192120168665300712204232021063124301\", \"price\":\"0.26\", \"size\":\"134.2\", \"side\":\"BUY\", \"hash\":\"5ef85a43e1fbc56bb66f6a7bf4e2ab52f9497ff1\", \"best_bid\":\"0.46\", \"best_ask\":\"0.47\"}, {\"asset_id\":\"96600821790790307414914106093858868634329285205417149685270682748367152458577\", \"price\":\"0.74\", \"size\":\"134.2\", \"side\":\"SELL\", \"hash\":\"021a842ef0c0daf18db724953d97071231e2535f\", \"best_bid\":\"0.53\", \"best_ask\":\"0.54\"}], \"timestamp\":\"1785211225904\", \"event_type\":\"price_change\"}","received_at":"2026-07-28T04:00:29.608246Z","schema_version":"clob-market-ws.price_change.v1","sequence":null,"server_hash":null,"server_timestamp":"1785211225904","session_id":"2d607381e3054cee91998cdf45a4231c","source":"clob_market_ws"},"received_at":"2026-07-28T04:00:29.608246Z","record_id":"36b975492ae58a13e081034928a8da1360ef435dba0bbb339641975501c798ba","schema_fingerprint":"4aa3821a28b0b7c2400bc59aba4bcc0a76e971dadd19610d3ad38c768e124dc7","schema_version":"edge-lab-recorder.raw.v1","sequence":null,"source":"clob_market_ws"}
{"event_at":"2026-07-28T04:00:25.905000Z","event_fingerprint":"53f37af76f7c8a74fd7bf33ccecea72edfc7aa965d82d6f2ef8045d505e0a320","payload":{"connection_id":"f6725804f86a4c4eb588e4d5ed7db029","event_at":"2026-07-28T04:00:25.905000Z","event_type":"price_change","frame_hash":"93fd9cc5c450988c200ebef330b45619ca740db5f6a0e9c19529bc2c58f3cb5a","frame_index":0,"kind":"data","monotonic_ns":313212662467791,"payload":{"event_type":"price_change","market":"0xd412ce774cfcf8dc9f71164aac78783978aac7b03871702a3b8a481bd9dc9688","price_changes":[{"asset_id":"107603864457683460275633293642179940881969192120168665300712204232021063124301","best_ask":"0.47","best_bid":"0.46","hash":"7da0d25f2573bb414671cfc5d2fd02610be1fea2","price":"0.44","side":"BUY","size":"126.2"},{"asset_id":"96600821790790307414914106093858868634329285205417149685270682748367152458577","best_ask":"0.54","best_bid":"0.53","hash":"695469b6e3d78c0ef12556e2283421047ff90e1a","price":"0.56","side":"SELL","size":"126.2"}],"timestamp":"1785211225905"},"payload_hash":"e3aba49f6567b35efa60fd93d649549c76fcfc422d5625948377291908841d2f","raw_frame":"{\"market\":\"0xd412ce774cfcf8dc9f71164aac78783978aac7b03871702a3b8a481bd9dc9688\", \"price_changes\":[{\"asset_id\":\"107603864457683460275633293642179940881969192120168665300712204232021063124301\", \"price\":\"0.44\", \"size\":\"126.2\", \"side\":\"BUY\", \"hash\":\"7da0d25f2573bb414671cfc5d2fd02610be1fea2\", \"best_bid\":\"0.46\", \"best_ask\":\"0.47\"}, {\"asset_id\":\"96600821790790307414914106093858868634329285205417149685270682748367152458577\", \"price\":\"0.56\", \"size\":\"126.2\", \"side\":\"SELL\", \"hash\":\"695469b6e3d78c0ef12556e2283421047ff90e1a\", \"best_bid\":\"0.53\", \"best_ask\":\"0.54\"}], \"timestamp\":\"1785211225905\", \"event_type\":\"price_change\"}","received_at":"2026-07-28T04:00:29.614340Z","schema_version":"clob-market-ws.price_change.v1","sequence":null,"server_hash":null,"server_timestamp":"1785211225905","session_id":"2d607381e3054cee91998cdf45a4231c","source":"clob_market_ws"},"received_at":"2026-07-28T04:00:29.614340Z","record_id":"23dc03ae467f843b69c7a2cde6e22127a2c5bbd974ed8431aa77727c651ec950","schema_fingerprint":"4aa3821a28b0b7c2400bc59aba4bcc0a76e971dadd19610d3ad38c768e124dc7","schema_version":"edge-lab-recorder.raw.v1","sequence":null,"source":"clob_market_ws"}
{"event_at":"2026-07-28T04:00:25.908000Z","event_fingerprint":"603b71de85981158c36e20bc33c214f2a8e4793fec968f142be06eb6a1de68f1","payload":{"connection_id":"f6725804f86a4c4eb588e4d5ed7db029","event_at":"2026-07-28T04:00:25.908000Z","event_type":"price_change","frame_hash":"4c6a2f49469d3ed7c5e7e91bc4e9bba44c5300e7d51f68df39c7c64604f195b7","frame_index":0,"kind":"data","monotonic_ns":313212672408583,"payload":{"event_type":"price_change","market":"0xd412ce774cfcf8dc9f71164aac78783978aac7b03871702a3b8a481bd9dc9688","price_changes":[{"asset_id":"107603864457683460275633293642179940881969192120168665300712204232021063124301","best_ask":"0.47","best_bid":"0.46","hash":"c24215447a191de7fe3130ff1cd3f18e2f98affd","price":"0.46","side":"BUY","size":"42.6"},{"asset_id":"96600821790790307414914106093858868634329285205417149685270682748367152458577","best_ask":"0.54","best_bid":"0.53","hash":"b23faf1ba7a84de1532e627ae1ac63cd5440fc75","price":"0.54","side":"SELL","size":"42.6"}],"timestamp":"1785211225908"},"payload_hash":"a0c344901655479950d62f7a689238a0b99983e147a5d7d8cc72eed1226cb3f3","raw_frame":"{\"market\":\"0xd412ce774cfcf8dc9f71164aac78783978aac7b03871702a3b8a481bd9dc9688\", \"price_changes\":[{\"asset_id\":\"107603864457683460275633293642179940881969192120168665300712204232021063124301\", \"price\":\"0.46\", \"size\":\"42.6\", \"side\":\"BUY\", \"hash\":\"c24215447a191de7fe3130ff1cd3f18e2f98affd\", \"best_bid\":\"0.46\", \"best_ask\":\"0.47\"}, {\"asset_id\":\"96600821790790307414914106093858868634329285205417149685270682748367152458577\", \"price\":\"0.54\", \"size\":\"42.6\", \"side\":\"SELL\", \"hash\":\"b23faf1ba7a84de1532e627ae1ac63cd5440fc75\", \"best_bid\":\"0.53\", \"best_ask\":\"0.54\"}], \"timestamp\":\"1785211225908\", \"event_type\":\"price_change\"}","received_at":"2026-07-28T04:00:29.624281Z","schema_version":"clob-market-ws.price_change.v1","sequence":null,"server_hash":null,"server_timestamp":"1785211225908","session_id":"2d607381e3054cee91998cdf45a4231c","source":"clob_market_ws"},"received_at":"2026-07-28T04:00:29.624281Z","record_id":"26bff1d02b960effe46d8850f4a7c5718f8a773412979a51aaf2045c932721a8","schema_fingerprint":"4aa3821a28b0b7c2400bc59aba4bcc0a76e971dadd19610d3ad38c768e124dc7","schema_version":"edge-lab-recorder.raw.v1","sequence":null,"source":"clob_market_ws"}
{"event_at":"2026-07-28T04:00:25.910000Z","event_fingerprint":"cf18655b970d67c8f15c171097945e705af47a4f8483a12df90ed49a72e63aa9","payload":{"connection_id":"f6725804f86a4c4eb588e4d5ed7db029","event_at":"2026-07-28T04:00:25.910000Z","event_type":"price_change","frame_hash":"b647c16b1cf499eef62d031d1cd7ceb4f597603abfe8d6549bf77cdcf7c073b2","frame_index":0,"kind":"data","monotonic_ns":313212715469125,"payload":{"event_type":"price_change","market":"0xd412ce774cfcf8dc9f71164aac78783978aac7b03871702a3b8a481bd9dc9688","price_changes":[{"asset_id":"107603864457683460275633293642179940881969192120168665300712204232021063124301","best_ask":"0.47","best_bid":"0.46","hash":"2729cfa0f0f5671120fd1056020816716d40a995","price":"0.46","side":"BUY","size":"47.6"},{"asset_id":"96600821790790307414914106093858868634329285205417149685270682748367152458577","best_ask":"0.54","best_bid":"0.53","hash":"15e487fafdc8a9a91e7daf6d1ecb436d556ae404","price":"0.54","side":"SELL","size":"47.6"}],"timestamp":"1785211225910"},"payload_hash":"d691c5fb7193f3fe9150d7bf3722edc115609b1a1007eeee2ab66b32f05d85e0","raw_frame":"{\"market\":\"0xd412ce774cfcf8dc9f71164aac78783978aac7b03871702a3b8a481bd9dc9688\", \"price_changes\":[{\"asset_id\":\"107603864457683460275633293642179940881969192120168665300712204232021063124301\", \"price\":\"0.46\", \"size\":\"47.6\", \"side\":\"BUY\", \"hash\":\"2729cfa0f0f5671120fd1056020816716d40a995\", \"best_bid\":\"0.46\", \"best_ask\":\"0.47\"}, {\"asset_id\":\"96600821790790307414914106093858868634329285205417149685270682748367152458577\", \"price\":\"0.54\", \"size\":\"47.6\", \"side\":\"SELL\", \"hash\":\"15e487fafdc8a9a91e7daf6d1ecb436d556ae404\", \"best_bid\":\"0.53\", \"best_ask\":\"0.54\"}], \"timestamp\":\"1785211225910\", \"event_type\":\"price_change\"}","received_at":"2026-07-28T04:00:29.667341Z","schema_version":"clob-market-ws.price_change.v1","sequence":null,"server_hash":null,"server_timestamp":"1785211225910","session_id":"2d607381e3054cee91998cdf45a4231c","source":"clob_market_ws"},"received_at":"2026-07-28T04:00:29.667341Z","record_id":"1bad0db1cc8c1394fc8d9de672f9b38e3d17d9e18936ff0bb288738660bd5e78","schema_fingerprint":"4aa3821a28b0b7c2400bc59aba4bcc0a76e971dadd19610d3ad38c768e124dc7","schema_version":"edge-lab-recorder.raw.v1","sequence":null,"source":"clob_market_ws"}
{"event_at":"2026-07-28T04:00:25.913000Z","event_fingerprint":"21b599ad081f6ca36c7b5e79805392d01b51479df3935523b9a9138f17aca586","payload":{"connection_id":"f6725804f86a4c4eb588e4d5ed7db029","event_at":"2026-07-28T04:00:25.913000Z","event_type":"price_change","frame_hash":"b9f022d0537746abd705b99dbead2ef036db011789510af7500a4d2a5009a9ec","frame_index":0,"kind":"data","monotonic_ns":313212719571041,"payload":{"event_type":"price_change","market":"0xd412ce774cfcf8dc9f71164aac78783978aac7b03871702a3b8a481bd9dc9688","price_changes":[{"asset_id":"96600821790790307414914106093858868634329285205417149685270682748367152458577","best_ask":"0.54","best_bid":"0.53","hash":"4963ee300bab5b4a176d2173cdc102cd11a68718","price":"0.54","side":"SELL","size":"54.6"},{"asset_id":"107603864457683460275633293642179940881969192120168665300712204232021063124301","best_ask":"0.47","best_bid":"0.46","hash":"82720ea17fb5c0a4185e7ffb0a0f5c6c2be6baa7","price":"0.46","side":"BUY","size":"54.6"}],"timestamp":"1785211225913"},"payload_hash":"18e0d8b5ee8f656d0fd02523fa7186b94d51474ff977786cbeab5720d17f5db1","raw_frame":"{\"market\":\"0xd412ce774cfcf8dc9f71164aac78783978aac7b03871702a3b8a481bd9dc9688\", \"price_changes\":[{\"asset_id\":\"96600821790790307414914106093858868634329285205417149685270682748367152458577\", \"price\":\"0.54\", \"size\":\"54.6\", \"side\":\"SELL\", \"hash\":\"4963ee300bab5b4a176d2173cdc102cd11a68718\", \"best_bid\":\"0.53\", \"best_ask\":\"0.54\"}, {\"asset_id\":\"107603864457683460275633293642179940881969192120168665300712204232021063124301\", \"price\":\"0.46\", \"size\":\"54.6\", \"side\":\"BUY\", \"hash\":\"82720ea17fb5c0a4185e7ffb0a0f5c6c2be6baa7\", \"best_bid\":\"0.46\", \"best_ask\":\"0.47\"}], \"timestamp\":\"1785211225913\", \"event_type\":\"price_change\"}","received_at":"2026-07-28T04:00:29.671442Z","schema_version":"clob-market-ws.price_change.v1","sequence":null,"server_hash":null,"server_timestamp":"1785211225913","session_id":"2d607381e3054cee91998cdf45a4231c","source":"clob_market_ws"},"received_at":"2026-07-28T04:00:29.671442Z","record_id":"f6f4410333d49ccfb365f87b324c4bc508478e185dbdd0006e5ebf987f79bc11","schema_fingerprint":"4aa3821a28b0b7c2400bc59aba4bcc0a76e971dadd19610d3ad38c768e124dc7","schema_version":"edge-lab-recorder.raw.v1","sequence":null,"source":"clob_market_ws"}
{"event_at":"2026-07-28T04:00:25.928000Z","event_fingerprint":"4f1b2edab27ea7382cf87412a2f872c64b288458c674bbbb8e0bea315d70d546","payload":{"connection_id":"f6725804f86a4c4eb588e4d5ed7db029","event_at":"2026-07-28T04:00:25.928000Z","event_type":"price_change","frame_hash":"e7ccb949748ecf1ee809e73afd3db64424bd405ca4dcfe130c3377e53d5dc07c","frame_index":0,"kind":"data","monotonic_ns":313212725099708,"payload":{"event_type":"price_change","market":"0xd412ce774cfcf8dc9f71164aac78783978aac7b03871702a3b8a481bd9dc9688","price_changes":[{"asset_id":"96600821790790307414914106093858868634329285205417149685270682748367152458577","best_ask":"0.54","best_bid":"0.53","hash":"61dfead9d1e205cbc7d88b3bc8fd3637f3f443c8","price":"0.34","side":"BUY","size":"13.5"},{"asset_id":"107603864457683460275633293642179940881969192120168665300712204232021063124301","best_ask":"0.47","best_bid":"0.46","hash":"7b96d1f68a54485f742feb9b4b7ace6ee6417516","price":"0.66","side":"SELL","size":"13.5"}],"timestamp":"1785211225928"},"payload_hash":"b0b6b496495fa42820b98117ceed46a8d6636fea3b4bfe5d5de328c2ba4bc351","raw_frame":"{\"market\":\"0xd412ce774cfcf8dc9f71164aac78783978aac7b03871702a3b8a481bd9dc9688\", \"price_changes\":[{\"asset_id\":\"96600821790790307414914106093858868634329285205417149685270682748367152458577\", \"price\":\"0.34\", \"size\":\"13.5\", \"side\":\"BUY\", \"hash\":\"61dfead9d1e205cbc7d88b3bc8fd3637f3f443c8\", \"best_bid\":\"0.53\", \"best_ask\":\"0.54\"}, {\"asset_id\":\"107603864457683460275633293642179940881969192120168665300712204232021063124301\", \"price\":\"0.66\", \"size\":\"13.5\", \"side\":\"SELL\", \"hash\":\"7b96d1f68a54485f742feb9b4b7ace6ee6417516\", \"best_bid\":\"0.46\", \"best_ask\":\"0.47\"}], \"timestamp\":\"1785211225928\", \"event_type\":\"price_change\"}","received_at":"2026-07-28T04:00:29.676971Z","schema_version":"clob-market-ws.price_change.v1","sequence":null,"server_hash":null,"server_timestamp":"1785211225928","session_id":"2d607381e3054cee91998cdf45a4231c","source":"clob_market_ws"},"received_at":"2026-07-28T04:00:29.676971Z","record_id":"552545410e5e65abf546b347678f56354ce91d474a70671400f03ecec72d8469","schema_fingerprint":"4aa3821a28b0b7c2400bc59aba4bcc0a76e971dadd19610d3ad38c768e124dc7","schema_version":"edge-lab-recorder.raw.v1","sequence":null,"source":"clob_market_ws"}
{"event_at":"2026-07-28T04:00:25.929000Z","event_fingerprint":"7667d63a8bfdea2a3aa4a3ff6b66e91ed6036cac20e6fbab2d7376fc6f21b8ab","payload":{"connection_id":"f6725804f86a4c4eb588e4d5ed7db029","event_at":"2026-07-28T04:00:25.929000Z","event_type":"price_change","frame_hash":"86e06cf02cadb88ff2a591395540d7522fbf8711f77d31a54bc057e711922b15","frame_index":0,"kind":"data","monotonic_ns":313212730545541,"payload":{"event_type":"price_change","market":"0xd412ce774cfcf8dc9f71164aac78783978aac7b03871702a3b8a481bd9dc9688","price_changes":[{"asset_id":"107603864457683460275633293642179940881969192120168665300712204232021063124301","best_ask":"0.47","best_bid":"0.46","hash":"1cac9caf19ead0d98ad5e5b568828ff5f203b760","price":"0.38","side":"BUY","size":"83"},{"asset_id":"96600821790790307414914106093858868634329285205417149685270682748367152458577","best_ask":"0.54","best_bid":"0.53","hash":"c710804013052e6855aaa6ca3e325f4014453198","price":"0.62","side":"SELL","size":"83"}],"timestamp":"1785211225929"},"payload_hash":"7a30f470f0b9a6fedb00e815e8889a4c99a8b69a3ff777a387f7f568c85b6885","raw_frame":"{\"market\":\"0xd412ce774cfcf8dc9f71164aac78783978aac7b03871702a3b8a481bd9dc9688\", \"price_changes\":[{\"asset_id\":\"107603864457683460275633293642179940881969192120168665300712204232021063124301\", \"price\":\"0.38\", \"size\":\"83\", \"side\":\"BUY\", \"hash\":\"1cac9caf19ead0d98ad5e5b568828ff5f203b760\", \"best_bid\":\"0.46\", \"best_ask\":\"0.47\"}, {\"asset_id\":\"96600821790790307414914106093858868634329285205417149685270682748367152458577\", \"price\":\"0.62\", \"size\":\"83\", \"side\":\"SELL\", \"hash\":\"c710804013052e6855aaa6ca3e325f4014453198\", \"best_bid\":\"0.53\", \"best_ask\":\"0.54\"}], \"timestamp\":\"1785211225929\", \"event_type\":\"price_change\"}","received_at":"2026-07-28T04:00:29.682415Z","schema_version":"clob-market-ws.price_change.v1","sequence":null,"server_hash":null,"server_timestamp":"1785211225929","session_id":"2d607381e3054cee91998cdf45a4231c","source":"clob_market_ws"},"received_at":"2026-07-28T04:00:29.682415Z","record_id":"999e200d734810ac63bc76cc05dfd8bb5fec45735b0c48a78980224291d25b4a","schema_fingerprint":"4aa3821a28b0b7c2400bc59aba4bcc0a76e971dadd19610d3ad38c768e124dc7","schema_version":"edge-lab-recorder.raw.v1","sequence":null,"source":"clob_market_ws"}
{"event_at":"2026-07-28T04:00:25.931000Z","event_fingerprint":"25ceaf873feba93fd72344713aff1a80603bbd64e01554ebc3952d0e80fae49c","payload":{"connection_id":"f6725804f86a4c4eb588e4d5ed7db029","event_at":"2026-07-28T04:00:25.931000Z","event_type":"price_change","frame_hash":"30187c12cbb748ffbe02ae9f4117c0407ccae2e39af8428001be427d98f6d3b0","frame_index":0,"kind":"data","monotonic_ns":313212736797583,"payload":{"event_type":"price_change","market":"0xd412ce774cfcf8dc9f71164aac78783978aac7b03871702a3b8a481bd9dc9688","price_changes":[{"asset_id":"107603864457683460275633293642179940881969192120168665300712204232021063124301","best_ask":"0.47","best_bid":"0.46","hash":"b977a96850ee8fcc8c2ecde79fc29844976a3bc6","price":"0.46","side":"BUY","size":"67.2"},{"asset_id":"96600821790790307414914106093858868634329285205417149685270682748367152458577","best_ask":"0.54","best_bid":"0.53","hash":"e5c852d6cd7cbe246857f8b5fb373b623c71900c","price":"0.54","side":"SELL","size":"67.2"}],"timestamp":"1785211225931"},"payload_hash":"7370d70834277df545c84d6de4261e0d9728748ef71bd41bbefafb83c937ffa6","raw_frame":"{\"market\":\"0xd412ce774cfcf8dc9f71164aac78783978aac7b03871702a3b8a481bd9dc9688\", \"price_changes\":[{\"asset_id\":\"107603864457683460275633293642179940881969192120168665300712204232021063124301\", \"price\":\"0.46\", \"size\":\"67.2\", \"side\":\"BUY\", \"hash\":\"b977a96850ee8fcc8c2ecde79fc29844976a3bc6\", \"best_bid\":\"0.46\", \"best_ask\":\"0.47\"}, {\"asset_id\":\"96600821790790307414914106093858868634329285205417149685270682748367152458577\", \"price\":\"0.54\", \"size\":\"67.2\", \"side\":\"SELL\", \"hash\":\"e5c852d6cd7cbe246857f8b5fb373b623c71900c\", \"best_bid\":\"0.53\", \"best_ask\":\"0.54\"}], \"timestamp\":\"1785211225931\", \"event_type\":\"price_change\"}","received_at":"2026-07-28T04:00:29.688668Z","schema_version":"clob-market-ws.price_change.v1","sequence":null,"server_hash":null,"server_timestamp":"1785211225931","session_id":"2d607381e3054cee91998cdf45a4231c","source":"clob_market_ws"},"received_at":"2026-07-28T04:00:29.688668Z","record_id":"9bfe2445727f2ed1cf9ee08fe3febc78065f2b71da307a6b10431b0c797d4923","schema_fingerprint":"4aa3821a28b0b7c2400bc59aba4bcc0a76e971dadd19610d3ad38c768e124dc7","schema_version":"edge-lab-recorder.raw.v1","sequence":null,"source":"clob_market_ws"}
{"event_at":"2026-07-28T04:00:25.933000Z","event_fingerprint":"d4ed67748a79a556da2fe988b01429cc49d92eb9ebbc621cff41dddc90f00f33","payload":{"connection_id":"f6725804f86a4c4eb588e4d5ed7db029","event_at":"2026-07-28T04:00:25.933000Z","event_type":"price_change","frame_hash":"30288926f4177be175db65be8a677d02612d39e4cac6f40ab5e2315094ac3d2c","frame_index":0,"kind":"data","monotonic_ns":313212742417291,"payload":{"event_type":"price_change","market":"0xd412ce774cfcf8dc9f71164aac78783978aac7b03871702a3b8a481bd9dc9688","price_changes":[{"asset_id":"107603864457683460275633293642179940881969192120168665300712204232021063124301","best_ask":"0.47","best_bid":"0.46","hash":"a658bbf3fc502a878fb5b7df40cb7e812bf5b8a2","price":"0.46","side":"BUY","size":"77.2"},{"asset_id":"96600821790790307414914106093858868634329285205417149685270682748367152458577","best_ask":"0.54","best_bid":"0.53","hash":"82f65f0bf255faaf078f27a9ae8ec80c0c16dcaf","price":"0.54","side":"SELL","size":"77.2"}],"timestamp":"1785211225933"},"payload_hash":"56fb63c0b2a086cde192197e5482ec5326b8388b2643e1229a69fb0433fa8d66","raw_frame":"{\"market\":\"0xd412ce774cfcf8dc9f71164aac78783978aac7b03871702a3b8a481bd9dc9688\", \"price_changes\":[{\"asset_id\":\"107603864457683460275633293642179940881969192120168665300712204232021063124301\", \"price\":\"0.46\", \"size\":\"77.2\", \"side\":\"BUY\", \"hash\":\"a658bbf3fc502a878fb5b7df40cb7e812bf5b8a2\", \"best_bid\":\"0.46\", \"best_ask\":\"0.47\"}, {\"asset_id\":\"96600821790790307414914106093858868634329285205417149685270682748367152458577\", \"price\":\"0.54\", \"size\":\"77.2\", \"side\":\"SELL\", \"hash\":\"82f65f0bf255faaf078f27a9ae8ec80c0c16dcaf\", \"best_bid\":\"0.53\", \"best_ask\":\"0.54\"}], \"timestamp\":\"1785211225933\", \"event_type\":\"price_change\"}","received_at":"2026-07-28T04:00:29.694290Z","schema_version":"clob-market-ws.price_change.v1","sequence":null,"server_hash":null,"server_timestamp":"1785211225933","session_id":"2d607381e3054cee91998cdf45a4231c","source":"clob_market_ws"},"received_at":"2026-07-28T04:00:29.694290Z","record_id":"4ec834e693b8667e19fd4e29d8fcc2d557d060453fde5554be3de6e08bf72074","schema_fingerprint":"4aa3821a28b0b7c2400bc59aba4bcc0a76e971dadd19610d3ad38c768e124dc7","schema_version":"edge-lab-recorder.raw.v1","sequence":null,"source":"clob_market_ws"}
{"event_at":"2026-07-28T04:00:25.946000Z","event_fingerprint":"bc9cf5f5af94403469c67ae14e833a508f1238709b17a4290c26011e00606e77","payload":{"connection_id":"f6725804f86a4c4eb588e4d5ed7db029","event_at":"2026-07-28T04:00:25.946000Z","event_type":"price_change","frame_hash":"d25540c4d1810faf12ae91b49cfa7a0ae3392bb53477a4bb72cf1695463b4863","frame_index":0,"kind":"data","monotonic_ns":313212749104125,"payload":{"event_type":"price_change","market":"0xd412ce774cfcf8dc9f71164aac78783978aac7b03871702a3b8a481bd9dc9688","price_changes":[{"asset_id":"96600821790790307414914106093858868634329285205417149685270682748367152458577","best_ask":"0.54","best_bid":"0.53","hash":"bc87c673be2310d77680e5978b5edd47253a25fa","price":"0.01","side":"BUY","size":"7550.02"},{"asset_id":"107603864457683460275633293642179940881969192120168665300712204232021063124301","best_ask":"0.47","best_bid":"0.46","hash":"df4e131e677d19063518552bd172cfbf5e062863","price":"0.99","side":"SELL","size":"7550.02"}],"timestamp":"1785211225946"},"payload_hash":"d1aecb461ad1e65000c7e9d7acb53479351e2ec95455b0c17b3104c58a4c0b71","raw_frame":"{\"market\":\"0xd412ce774cfcf8dc9f71164aac78783978aac7b03871702a3b8a481bd9dc9688\", \"price_changes\":[{\"asset_id\":\"96600821790790307414914106093858868634329285205417149685270682748367152458577\", \"price\":\"0.01\", \"size\":\"7550.02\", \"side\":\"BUY\", \"hash\":\"bc87c673be2310d77680e5978b5edd47253a25fa\", \"best_bid\":\"0.53\", \"best_ask\":\"0.54\"}, {\"asset_id\":\"107603864457683460275633293642179940881969192120168665300712204232021063124301\", \"price\":\"0.99\", \"size\":\"7550.02\", \"side\":\"SELL\", \"hash\":\"df4e131e677d19063518552bd172cfbf5e062863\", \"best_bid\":\"0.46\", \"best_ask\":\"0.47\"}], \"timestamp\":\"1785211225946\", \"event_type\":\"price_change\"}","received_at":"2026-07-28T04:00:29.700975Z","schema_version":"clob-market-ws.price_change.v1","sequence":null,"server_hash":null,"server_timestamp":"1785211225946","session_id":"2d607381e3054cee91998cdf45a4231c","source":"clob_market_ws"},"received_at":"2026-07-28T04:00:29.700975Z","record_id":"bc83ac07a1cace30703a708f2a9668e6167f5084d9bb6cf2b97ff99c4617778e","schema_fingerprint":"4aa3821a28b0b7c2400bc59aba4bcc0a76e971dadd19610d3ad38c768e124dc7","schema_version":"edge-lab-recorder.raw.v1","sequence":null,"source":"clob_market_ws"}
{"event_at":"2026-07-28T04:00:25.948000Z","event_fingerprint":"46e6e2e7e9709d8d1ed45e9af1d079df321d7b7c2fafa4184efb3175ed4ed932","payload":{"connection_id":"f6725804f86a4c4eb588e4d5ed7db029","event_at":"2026-07-28T04:00:25.948000Z","event_type":"price_change","frame_hash":"61bfb947e5361e6e7f870ec98cdd711e6483d9bddf7a3f45f41fd802471e63ee","frame_index":0,"kind":"data","monotonic_ns":313212774574166,"payload":{"event_type":"price_change","market":"0xd412ce774cfcf8dc9f71164aac78783978aac7b03871702a3b8a481bd9dc9688","price_changes":[{"asset_id":"107603864457683460275633293642179940881969192120168665300712204232021063124301","best_ask":"0.47","best_bid":"0.46","hash":"008fdf72dce9e772a184ac696de5f72a7246c274","price":"0.42","side":"BUY","size":"95.27"},{"asset_id":"96600821790790307414914106093858868634329285205417149685270682748367152458577","best_ask":"0.54","best_bid":"0.53","hash":"a6449bcf6adca012b2c3dcc05f5a5e4ed705c460","price":"0.58","side":"SELL","size":"95.27"}],"timestamp":"1785211225948"},"payload_hash":"14e0c834e71a7b63f958c6ca9918db1543722af0487e75a5db91244dbe461484","raw_frame":"{\"market\":\"0xd412ce774cfcf8dc9f71164aac78783978aac7b03871702a3b8a481bd9dc9688\", \"price_changes\":[{\"asset_id\":\"107603864457683460275633293642179940881969192120168665300712204232021063124301\", \"price\":\"0.42\", \"size\":\"95.27\", \"side\":\"BUY\", \"hash\":\"008fdf72dce9e772a184ac696de5f72a7246c274\", \"best_bid\":\"0.46\", \"best_ask\":\"0.47\"}, {\"asset_id\":\"96600821790790307414914106093858868634329285205417149685270682748367152458577\", \"price\":\"0.58\", \"size\":\"95.27\", \"side\":\"SELL\", \"hash\":\"a6449bcf6adca012b2c3dcc05f5a5e4ed705c460\", \"best_bid\":\"0.53\", \"best_ask\":\"0.54\"}], \"timestamp\":\"1785211225948\", \"event_type\":\"price_change\"}","received_at":"2026-07-28T04:00:29.726445Z","schema_version":"clob-market-ws.price_change.v1","sequence":null,"server_hash":null,"server_timestamp":"1785211225948","session_id":"2d607381e3054cee91998cdf45a4231c","source":"clob_market_ws"},"received_at":"2026-07-28T04:00:29.726445Z","record_id":"173c6244b6c17511815b38b9fed2818b3fe9b91e58f9b5d363b90b5fc6834331","schema_fingerprint":"4aa3821a28b0b7c2400bc59aba4bcc0a76e971dadd19610d3ad38c768e124dc7","schema_version":"edge-lab-recorder.raw.v1","sequence":null,"source":"clob_market_ws"}
{"event_at":"2026-07-28T04:00:25.949000Z","event_fingerprint":"076ccb52fd57c6e1804dbaf751ef035c56555b69342b6083bd1c19bd72ef6988","payload":{"connection_id":"f6725804f86a4c4eb588e4d5ed7db029","event_at":"2026-07-28T04:00:25.949000Z","event_type":"price_change","frame_hash":"c37e035cf2c54904f3b6091de11de7f1df364de5eb485083c28ba5ec628552a6","frame_index":0,"kind":"data","monotonic_ns":313212780540250,"payload":{"event_type":"price_change","market":"0xd412ce774cfcf8dc9f71164aac78783978aac7b03871702a3b8a481bd9dc9688","price_changes":[{"asset_id":"107603864457683460275633293642179940881969192120168665300712204232021063124301","best_ask":"0.47","best_bid":"0.46","hash":"9238353903aa9e9f1d64e4e88d79907f129cf5d4","price":"0.43","side":"BUY","size":"137.6"},{"asset_id":"96600821790790307414914106093858868634329285205417149685270682748367152458577","best_ask":"0.54","best_bid":"0.53","hash":"7e924b8bfbc66c8dd711d4321a5c07cff779a571","price":"0.57","side":"SELL","size":"137.6"}],"timestamp":"1785211225949"},"payload_hash":"2b526a22341810f6caec0d427b891232d36dfe6e15f9950631b8f1c894d1d6ba","raw_frame":"{\"market\":\"0xd412ce774cfcf8dc9f71164aac78783978aac7b03871702a3b8a481bd9dc9688\", \"price_changes\":[{\"asset_id\":\"107603864457683460275633293642179940881969192120168665300712204232021063124301\", \"price\":\"0.43\", \"size\":\"137.6\", \"side\":\"BUY\", \"hash\":\"9238353903aa9e9f1d64e4e88d79907f129cf5d4\", \"best_bid\":\"0.46\", \"best_ask\":\"0.47\"}, {\"asset_id\":\"96600821790790307414914106093858868634329285205417149685270682748367152458577\", \"price\":\"0.57\", \"size\":\"137.6\", \"side\":\"SELL\", \"hash\":\"7e924b8bfbc66c8dd711d4321a5c07cff779a571\", \"best_bid\":\"0.53\", \"best_ask\":\"0.54\"}], \"timestamp\":\"1785211225949\", \"event_type\":\"price_change\"}","received_at":"2026-07-28T04:00:29.732411Z","schema_version":"clob-market-ws.price_change.v1","sequence":null,"server_hash":null,"server_timestamp":"1785211225949","session_id":"2d607381e3054cee91998cdf45a4231c","source":"clob_market_ws"},"received_at":"2026-07-28T04:00:29.732411Z","record_id":"e7f0bc88a5938c17dae63c45884206eda50a2bbb07572cbdb0c8c31871ec8f73","schema_fingerprint":"4aa3821a28b0b7c2400bc59aba4bcc0a76e971dadd19610d3ad38c768e124dc7","schema_version":"edge-lab-recorder.raw.v1","sequence":null,"source":"clob_market_ws"}
{"event_at":"2026-07-28T04:00:25.951000Z","event_fingerprint":"4f12bc605694c723ef548481be60dcdcc025f813531e742f74e4f9d43fbc1377","payload":{"connection_id":"f6725804f86a4c4eb588e4d5ed7db029","event_at":"2026-07-28T04:00:25.951000Z","event_type":"price_change","frame_hash":"85948e39f1bdec6739ab55425bc046895242461eec226b712eb2de2922f26f05","frame_index":0,"kind":"data","monotonic_ns":313212789068291,"payload":{"event_type":"price_change","market":"0xd412ce774cfcf8dc9f71164aac78783978aac7b03871702a3b8a481bd9dc9688","price_changes":[{"asset_id":"107603864457683460275633293642179940881969192120168665300712204232021063124301","best_ask":"0.47","best_bid":"0.46","hash":"e88a2eca9c1f902a216a7718383c3f12ea1a8d70","price":"0.46","side":"BUY","size":"67.2"},{"asset_id":"96600821790790307414914106093858868634329285205417149685270682748367152458577","best_ask":"0.54","best_bid":"0.53","hash":"e4473ca363ccc88de2e3ff9d35ce1bcadc8e95e6","price":"0.54","side":"SELL","size":"67.2"}],"timestamp":"1785211225951"},"payload_hash":"f5e1b2664d692aa7ede5638ee070b02d19969598c7d1fe32aae0ffc4864a9e57","raw_frame":"{\"market\":\"0xd412ce774cfcf8dc9f71164aac78783978aac7b03871702a3b8a481bd9dc9688\", \"price_changes\":[{\"asset_id\":\"107603864457683460275633293642179940881969192120168665300712204232021063124301\", \"price\":\"0.46\", \"size\":\"67.2\", \"side\":\"BUY\", \"hash\":\"e88a2eca9c1f902a216a7718383c3f12ea1a8d70\", \"best_bid\":\"0.46\", \"best_ask\":\"0.47\"}, {\"asset_id\":\"96600821790790307414914106093858868634329285205417149685270682748367152458577\", \"price\":\"0.54\", \"size\":\"67.2\", \"side\":\"SELL\", \"hash\":\"e4473ca363ccc88de2e3ff9d35ce1bcadc8e95e6\", \"best_bid\":\"0.53\", \"best_ask\":\"0.54\"}], \"timestamp\":\"1785211225951\", \"event_type\":\"price_change\"}","received_at":"2026-07-28T04:00:29.740939Z","schema_version":"clob-market-ws.price_change.v1","sequence":null,"server_hash":null,"server_timestamp":"1785211225951","session_id":"2d607381e3054cee91998cdf45a4231c","source":"clob_market_ws"},"received_at":"2026-07-28T04:00:29.740939Z","record_id":"778867ec85a43e551299f7303d45ed5bd4a440efee3c95aab2abb06078bbe020","schema_fingerprint":"4aa3821a28b0b7c2400bc59aba4bcc0a76e971dadd19610d3ad38c768e124dc7","schema_version":"edge-lab-recorder.raw.v1","sequence":null,"source":"clob_market_ws"}
{"event_at":"2026-07-28T04:00:25.951000Z","event_fingerprint":"8ae1654839737abc8360eac0a0c9a120e8425788f77e754a7c209e9ac0af417f","payload":{"connection_id":"f6725804f86a4c4eb588e4d5ed7db029","event_at":"2026-07-28T04:00:25.951000Z","event_type":"price_change","frame_hash":"d7b7f0a1729abee257aa52dc59c437ba9e7cf8019eede5a712bf27d8a0f85b9d","frame_index":0,"kind":"data","monotonic_ns":313212800038500,"payload":{"event_type":"price_change","market":"0xd412ce774cfcf8dc9f71164aac78783978aac7b03871702a3b8a481bd9dc9688","price_changes":[{"asset_id":"107603864457683460275633293642179940881969192120168665300712204232021063124301","best_ask":"0.47","best_bid":"0.46","hash":"385f0d0d10bdf42f1f6dbd79003e03f122287d1c","price":"0.44","side":"BUY","size":"132.2"},{"asset_id":"96600821790790307414914106093858868634329285205417149685270682748367152458577","best_ask":"0.54","best_bid":"0.53","hash":"c81a91cbcdbd7809c2e5dd38e4bb095a9c439366","price":"0.56","side":"SELL","size":"132.2"}],"timestamp":"1785211225951"},"payload_hash":"89d35088c1cffac08186f351a830d96165e52937f336781c676712be3078594b","raw_frame":"{\"market\":\"0xd412ce774cfcf8dc9f71164aac78783978aac7b03871702a3b8a481bd9dc9688\", \"price_changes\":[{\"asset_id\":\"107603864457683460275633293642179940881969192120168665300712204232021063124301\", \"price\":\"0.44\", \"size\":\"132.2\", \"side\":\"BUY\", \"hash\":\"385f0d0d10bdf42f1f6dbd79003e03f122287d1c\", \"best_bid\":\"0.46\", \"best_ask\":\"0.47\"}, {\"asset_id\":\"96600821790790307414914106093858868634329285205417149685270682748367152458577\", \"price\":\"0.56\", \"size\":\"132.2\", \"side\":\"SELL\", \"hash\":\"c81a91cbcdbd7809c2e5dd38e4bb095a9c439366\", \"best_bid\":\"0.53\", \"best_ask\":\"0.54\"}], \"timestamp\":\"1785211225951\", \"event_type\":\"price_change\"}","received_at":"2026-07-28T04:00:29.751908Z","schema_version":"clob-market-ws.price_change.v1","sequence":null,"server_hash":null,"server_timestamp":"1785211225951","session_id":"2d607381e3054cee91998cdf45a4231c","source":"clob_market_ws"},"received_at":"2026-07-28T04:00:29.751908Z","record_id":"d7ed1b37a44951f161a3401f34ef0bab16e899a072c109d16768fee3f47ffbd9","schema_fingerprint":"4aa3821a28b0b7c2400bc59aba4bcc0a76e971dadd19610d3ad38c768e124dc7","schema_version":"edge-lab-recorder.raw.v1","sequence":null,"source":"clob_market_ws"}
{"event_at":"2026-07-28T04:00:25.953000Z","event_fingerprint":"f79a01b5b83eb3477c3f097d0c9e255997f8aafb76073013125d00eb45862879","payload":{"connection_id":"f6725804f86a4c4eb588e4d5ed7db029","event_at":"2026-07-28T04:00:25.953000Z","event_type":"price_change","frame_hash":"035c85f4bd9a849e15f4a436ab90a9ed103007ae15473d5d28999e9201c433cd","frame_index":0,"kind":"data","monotonic_ns":313212810496833,"payload":{"event_type":"price_change","market":"0xd412ce774cfcf8dc9f71164aac78783978aac7b03871702a3b8a481bd9dc9688","price_changes":[{"asset_id":"96600821790790307414914106093858868634329285205417149685270682748367152458577","best_ask":"0.54","best_bid":"0.53","hash":"2864d80afd190bace8624086b34b3cbb4329b610","price":"0.52","side":"BUY","size":"25"},{"asset_id":"107603864457683460275633293642179940881969192120168665300712204232021063124301","best_ask":"0.47","best_bid":"0.46","hash":"34ad6a1133ccd3e6abb84cc5ed05c4975984f714","price":"0.48","side":"SELL","size":"25"}],"timestamp":"1785211225953"},"payload_hash":"060ca8370cb076cbe118de8faec76fdb5a8fb36a9fb6180f37bdfe85ac47e249","raw_frame":"{\"market\":\"0xd412ce774cfcf8dc9f71164aac78783978aac7b03871702a3b8a481bd9dc9688\", \"price_changes\":[{\"asset_id\":\"96600821790790307414914106093858868634329285205417149685270682748367152458577\", \"price\":\"0.52\", \"size\":\"25\", \"side\":\"BUY\", \"hash\":\"2864d80afd190bace8624086b34b3cbb4329b610\", \"best_bid\":\"0.53\", \"best_ask\":\"0.54\"}, {\"asset_id\":\"107603864457683460275633293642179940881969192120168665300712204232021063124301\", \"price\":\"0.48\", \"size\":\"25\", \"side\":\"SELL\", \"hash\":\"34ad6a1133ccd3e6abb84cc5ed05c4975984f714\", \"best_bid\":\"0.46\", \"best_ask\":\"0.47\"}], \"timestamp\":\"1785211225953\", \"event_type\":\"price_change\"}","received_at":"2026-07-28T04:00:29.762367Z","schema_version":"clob-market-ws.price_change.v1","sequence":null,"server_hash":null,"server_timestamp":"1785211225953","session_id":"2d607381e3054cee91998cdf45a4231c","source":"clob_market_ws"},"received_at":"2026-07-28T04:00:29.762367Z","record_id":"9ddb46d92f979a0a1246698237f37d97bcb973ad172ab89bd5007cbdf1f74167","schema_fingerprint":"4aa3821a28b0b7c2400bc59aba4bcc0a76e971dadd19610d3ad38c768e124dc7","schema_version":"edge-lab-recorder.raw.v1","sequence":null,"source":"clob_market_ws"}
{"event_at":"2026-07-28T04:00:25.954000Z","event_fingerprint":"09f99f1da17102d30899d9cc4e23c0a857909720745207310116c3bc0cb25201","payload":{"connection_id":"f6725804f86a4c4eb588e4d5ed7db029","event_at":"2026-07-28T04:00:25.954000Z","event_type":"price_change","frame_hash":"2424d561640b677c3d18190f3c91b05eafefbfb0e98e9eb2ea914e77cdbe42eb","frame_index":0,"kind":"data","monotonic_ns":313212820643250,"payload":{"event_type":"price_change","market":"0xd412ce774cfcf8dc9f71164aac78783978aac7b03871702a3b8a481bd9dc9688","price_changes":[{"asset_id":"107603864457683460275633293642179940881969192120168665300712204232021063124301","best_ask":"0.47","best_bid":"0.46","hash":"ec55af97db4926739470c3dfa5e38211242056a1","price":"0.44","side":"BUY","size":"120.2"},{"asset_id":"96600821790790307414914106093858868634329285205417149685270682748367152458577","best_ask":"0.54","best_bid":"0.53","hash":"d222add47f631d8ed5c5072df01eab4e00215181","price":"0.56","side":"SELL","size":"120.2"}],"timestamp":"1785211225954"},"payload_hash":"f1711c848c66a717b5ecc426e64064de6ebc109a70fae41c750fc719f9329286","raw_frame":"{\"market\":\"0xd412ce774cfcf8dc9f71164aac78783978aac7b03871702a3b8a481bd9dc9688\", \"price_changes\":[{\"asset_id\":\"107603864457683460275633293642179940881969192120168665300712204232021063124301\", \"price\":\"0.44\", \"size\":\"120.2\", \"side\":\"BUY\", \"hash\":\"ec55af97db4926739470c3dfa5e38211242056a1\", \"best_bid\":\"0.46\", \"best_ask\":\"0.47\"}, {\"asset_id\":\"96600821790790307414914106093858868634329285205417149685270682748367152458577\", \"price\":\"0.56\", \"size\":\"120.2\", \"side\":\"SELL\", \"hash\":\"d222add47f631d8ed5c5072df01eab4e00215181\", \"best_bid\":\"0.53\", \"best_ask\":\"0.54\"}], \"timestamp\":\"1785211225954\", \"event_type\":\"price_change\"}","received_at":"2026-07-28T04:00:29.772514Z","schema_version":"clob-market-ws.price_change.v1","sequence":null,"server_hash":null,"server_timestamp":"1785211225954","session_id":"2d607381e3054cee91998cdf45a4231c","source":"clob_market_ws"},"received_at":"2026-07-28T04:00:29.772514Z","record_id":"279dd10420249a3351cc08cc9f2fccb9243fd7965760f21b3fc859b292a9fbd3","schema_fingerprint":"4aa3821a28b0b7c2400bc59aba4bcc0a76e971dadd19610d3ad38c768e124dc7","schema_version":"edge-lab-recorder.raw.v1","sequence":null,"source":"clob_market_ws"}
{"event_at":"2026-07-28T04:00:25.960000Z","event_fingerprint":"1616c20978b6b0886b0f246402541fe94119c15e4fcb2e1cb8405b8d346aebab","payload":{"connection_id":"f6725804f86a4c4eb588e4d5ed7db029","event_at":"2026-07-28T04:00:25.960000Z","event_type":"price_change","frame_hash":"ed95f40d7c86afb594f63b8e3be8a608820460ea54b382c4454db88ef0f782a8","frame_index":0,"kind":"data","monotonic_ns":313212839818041,"payload":{"event_type":"price_change","market":"0xd412ce774cfcf8dc9f71164aac78783978aac7b03871702a3b8a481bd9dc9688","price_changes":[{"asset_id":"107603864457683460275633293642179940881969192120168665300712204232021063124301","best_ask":"0.47","best_bid":"0.46","hash":"f6b3ef2e75e7f6b3ed9bf4db5bb58ff7bea84210","price":"0.46","side":"BUY","size":"75.2"},{"asset_id":"96600821790790307414914106093858868634329285205417149685270682748367152458577","best_ask":"0.54","best_bid":"0.53","hash":"f68f320ef9d692cf98af441e84ab262bcc262ca0","price":"0.54","side":"SELL","size":"75.2"}],"timestamp":"1785211225960"},"payload_hash":"8deabd7f9bc5e342b851aa5596f9aca46018742ac8302cf1454d72ad2c75e926","raw_frame":"{\"market\":\"0xd412ce774cfcf8dc9f71164aac78783978aac7b03871702a3b8a481bd9dc9688\", \"price_changes\":[{\"asset_id\":\"107603864457683460275633293642179940881969192120168665300712204232021063124301\", \"price\":\"0.46\", \"size\":\"75.2\", \"side\":\"BUY\", \"hash\":\"f6b3ef2e75e7f6b3ed9bf4db5bb58ff7bea84210\", \"best_bid\":\"0.46\", \"best_ask\":\"0.47\"}, {\"asset_id\":\"96600821790790307414914106093858868634329285205417149685270682748367152458577\", \"price\":\"0.54\", \"size\":\"75.2\", \"side\":\"SELL\", \"hash\":\"f68f320ef9d692cf98af441e84ab262bcc262ca0\", \"best_bid\":\"0.53\", \"best_ask\":\"0.54\"}], \"timestamp\":\"1785211225960\", \"event_type\":\"price_change\"}","received_at":"2026-07-28T04:00:29.791688Z","schema_version":"clob-market-ws.price_change.v1","sequence":null,"server_hash":null,"server_timestamp":"1785211225960","session_id":"2d607381e3054cee91998cdf45a4231c","source":"clob_market_ws"},"received_at":"2026-07-28T04:00:29.791688Z","record_id":"43faa97b60a09c5f10cb53af2e52fb509070c2e3c973726aece93a13e8fd89c9","schema_fingerprint":"4aa3821a28b0b7c2400bc59aba4bcc0a76e971dadd19610d3ad38c768e124dc7","schema_version":"edge-lab-recorder.raw.v1","sequence":null,"source":"clob_market_ws"}
{"event_at":"2026-07-28T04:00:25.961000Z","event_fingerprint":"4eee5cf4ca55e35b5db3d01ead16121438d183515faf80a99b906ed91f69da80","payload":{"connection_id":"f6725804f86a4c4eb588e4d5ed7db029","event_at":"2026-07-28T04:00:25.961000Z","event_type":"price_change","frame_hash":"26dfcc13dcbd961a695aebf404d7adc435160a29921ff097543c2ab1f3012ec5","frame_index":0,"kind":"data","monotonic_ns":313212844460625,"payload":{"event_type":"price_change","market":"0xd412ce774cfcf8dc9f71164aac78783978aac7b03871702a3b8a481bd9dc9688","price_changes":[{"asset_id":"107603864457683460275633293642179940881969192120168665300712204232021063124301","best_ask":"0.47","best_bid":"0.46","hash":"81821e3e45969d61f3106e3256fa96b2a30fb4cf","price":"0.45","side":"BUY","size":"152.6"},{"asset_id":"96600821790790307414914106093858868634329285205417149685270682748367152458577","best_ask":"0.54","best_bid":"0.53","hash":"f37b95dd8f7d9e3bd73cec3cc21bca793ef5949b","price":"0.55","side":"SELL","size":"152.6"}],"timestamp":"1785211225961"},"payload_hash":"52ec33a331da53c00ad05fe71823d36fd09a9362c529bd29fdb8b894b0a8f466","raw_frame":"{\"market\":\"0xd412ce774cfcf8dc9f71164aac78783978aac7b03871702a3b8a481bd9dc9688\", \"price_changes\":[{\"asset_id\":\"107603864457683460275633293642179940881969192120168665300712204232021063124301\", \"price\":\"0.45\", \"size\":\"152.6\", \"side\":\"BUY\", \"hash\":\"81821e3e45969d61f3106e3256fa96b2a30fb4cf\", \"best_bid\":\"0.46\", \"best_ask\":\"0.47\"}, {\"asset_id\":\"96600821790790307414914106093858868634329285205417149685270682748367152458577\", \"price\":\"0.55\", \"size\":\"152.6\", \"side\":\"SELL\", \"hash\":\"f37b95dd8f7d9e3bd73cec3cc21bca793ef5949b\", \"best_bid\":\"0.53\", \"best_ask\":\"0.54\"}], \"timestamp\":\"1785211225961\", \"event_type\":\"price_change\"}","received_at":"2026-07-28T04:00:29.796331Z","schema_version":"clob-market-ws.price_change.v1","sequence":null,"server_hash":null,"server_timestamp":"1785211225961","session_id":"2d607381e3054cee91998cdf45a4231c","source":"clob_market_ws"},"received_at":"2026-07-28T04:00:29.796331Z","record_id":"9124cfd0f50b00161943e3678826d2fbf23d39d3ecfd805cb89743bf9ddb1aa2","schema_fingerprint":"4aa3821a28b0b7c2400bc59aba4bcc0a76e971dadd19610d3ad38c768e124dc7","schema_version":"edge-lab-recorder.raw.v1","sequence":null,"source":"clob_market_ws"}
{"event_at":"2026-07-28T04:00:25.977000Z","event_fingerprint":"57b58b68794c4f0ade878f17a806be97fdcef0edc5ff7aeb3a157e889ba7f4df","payload":{"connection_id":"f6725804f86a4c4eb588e4d5ed7db029","event_at":"2026-07-28T04:00:25.977000Z","event_type":"price_change","frame_hash":"8ed1384e1ee72240acd8f6b8de79124f33e452cbb80d5f4470bed12a5d21c723","frame_index":0,"kind":"data","monotonic_ns":313212850073791,"payload":{"event_type":"price_change","market":"0xd412ce774cfcf8dc9f71164aac78783978aac7b03871702a3b8a481bd9dc9688","price_changes":[{"asset_id":"107603864457683460275633293642179940881969192120168665300712204232021063124301","best_ask":"0.47","best_bid":"0.46","hash":"3b8efa60162e8cfb306d46caf1097ae58582b126","price":"0.45","side":"BUY","size":"167.6"},{"asset_id":"96600821790790307414914106093858868634329285205417149685270682748367152458577","best_ask":"0.54","best_bid":"0.53","hash":"bb23efbe500165d79fa72f0a3d45673961af69bc","price":"0.55","side":"SELL","size":"167.6"}],"timestamp":"1785211225977"},"payload_hash":"e4001c190e490863510c997ed050c550bef93e721632fa657b108f4eff7a8501","raw_frame":"{\"market\":\"0xd412ce774cfcf8dc9f71164aac78783978aac7b03871702a3b8a481bd9dc9688\", \"price_changes\":[{\"asset_id\":\"107603864457683460275633293642179940881969192120168665300712204232021063124301\", \"price\":\"0.45\", \"size\":\"167.6\", \"side\":\"BUY\", \"hash\":\"3b8efa60162e8cfb306d46caf1097ae58582b126\", \"best_bid\":\"0.46\", \"best_ask\":\"0.47\"}, {\"asset_id\":\"96600821790790307414914106093858868634329285205417149685270682748367152458577\", \"price\":\"0.55\", \"size\":\"167.6\", \"side\":\"SELL\", \"hash\":\"bb23efbe500165d79fa72f0a3d45673961af69bc\", \"best_bid\":\"0.53\", \"best_ask\":\"0.54\"}], \"timestamp\":\"1785211225977\", \"event_type\":\"price_change\"}","received_at":"2026-07-28T04:00:29.801944Z","schema_version":"clob-market-ws.price_change.v1","sequence":null,"server_hash":null,"server_timestamp":"1785211225977","session_id":"2d607381e3054cee91998cdf45a4231c","source":"clob_market_ws"},"received_at":"2026-07-28T04:00:29.801944Z","record_id":"0971841d595c96f55849d877c243114670b3b341751f5d0c213e59a4fa79e8a7","schema_fingerprint":"4aa3821a28b0b7c2400bc59aba4bcc0a76e971dadd19610d3ad38c768e124dc7","schema_version":"edge-lab-recorder.raw.v1","sequence":null,"source":"clob_market_ws"}
{"event_at":"2026-07-28T04:00:25.978000Z","event_fingerprint":"07e6729c89c4924e15b15af6aa750132ce3411331074cb4592a78309ea5c3ea1","payload":{"connection_id":"f6725804f86a4c4eb588e4d5ed7db029","event_at":"2026-07-28T04:00:25.978000Z","event_type":"price_change","frame_hash":"3922cd3ead6a9331ec7c4135bf262fe235674b8a5976c71a751ebf71d107a38b","frame_index":0,"kind":"data","monotonic_ns":313212855706833,"payload":{"event_type":"price_change","market":"0xd412ce774cfcf8dc9f71164aac78783978aac7b03871702a3b8a481bd9dc9688","price_changes":[{"asset_id":"96600821790790307414914106093858868634329285205417149685270682748367152458577","best_ask":"0.54","best_bid":"0.53","hash":"0fb10e2885b0db0441cdce105586365a2333481f","price":"0.5","side":"BUY","size":"56.6"},{"asset_id":"107603864457683460275633293642179940881969192120168665300712204232021063124301","best_ask":"0.47","best_bid":"0.46","hash":"7705feb421b8e1590e5e08292aec46a6d9cd1833","price":"0.5","side":"SELL","size":"56.6"}],"timestamp":"1785211225978"},"payload_hash":"d3509322f70e813d120818b00c25fa2b8ece89446562c9fe872cfd3216bfb7a6","raw_frame":"{\"market\":\"0xd412ce774cfcf8dc9f71164aac78783978aac7b03871702a3b8a481bd9dc9688\", \"price_changes\":[{\"asset_id\":\"96600821790790307414914106093858868634329285205417149685270682748367152458577\", \"price\":\"0.5\", \"size\":\"56.6\", \"side\":\"BUY\", \"hash\":\"0fb10e2885b0db0441cdce105586365a2333481f\", \"best_bid\":\"0.53\", \"best_ask\":\"0.54\"}, {\"asset_id\":\"107603864457683460275633293642179940881969192120168665300712204232021063124301\", \"price\":\"0.5\", \"size\":\"56.6\", \"side\":\"SELL\", \"hash\":\"7705feb421b8e1590e5e08292aec46a6d9cd1833\", \"best_bid\":\"0.46\", \"best_ask\":\"0.47\"}], \"timestamp\":\"1785211225978\", \"event_type\":\"price_change\"}","received_at":"2026-07-28T04:00:29.807577Z","schema_version":"clob-market-ws.price_change.v1","sequence":null,"server_hash":null,"server_timestamp":"1785211225978","session_id":"2d607381e3054cee91998cdf45a4231c","source":"clob_market_ws"},"received_at":"2026-07-28T04:00:29.807577Z","record_id":"24e9d3fbdb0aed8d6eff5ac108cfdc254aed6dea60c1ee91f2874ab3dbcfe7c1","schema_fingerprint":"4aa3821a28b0b7c2400bc59aba4bcc0a76e971dadd19610d3ad38c768e124dc7","schema_version":"edge-lab-recorder.raw.v1","sequence":null,"source":"clob_market_ws"}
{"event_at":"2026-07-28T04:00:25.981000Z","event_fingerprint":"d453b2db1112903954cae167c3ed3de8ba0b92284cbfe28a5163fc79cc910c78","payload":{"connection_id":"f6725804f86a4c4eb588e4d5ed7db029","event_at":"2026-07-28T04:00:25.981000Z","event_type":"price_change","frame_hash":"8083b6dcaac4bff1b9aab2adb8c7fe0eaba8259cd74a6b3875eaa58a34521040","frame_index":0,"kind":"data","monotonic_ns":313212862828541,"payload":{"event_type":"price_change","market":"0xd412ce774cfcf8dc9f71164aac78783978aac7b03871702a3b8a481bd9dc9688","price_changes":[{"asset_id":"107603864457683460275633293642179940881969192120168665300712204232021063124301","best_ask":"0.47","best_bid":"0.46","hash":"517c5c4e6217ede787d8b5d83f30ef4f98e7ff82","price":"0.45","side":"BUY","size":"177.6"},{"asset_id":"96600821790790307414914106093858868634329285205417149685270682748367152458577","best_ask":"0.54","best_bid":"0.53","hash":"2140e9d71a4ac9b693ca2237b39cb44beadd4509","price":"0.55","side":"SELL","size":"177.6"}],"timestamp":"1785211225981"},"payload_hash":"2c0f2f6022e448a40f19d3a24b8c2bc8f166a498acb6db0ea8ad5d0ccf2b852c","raw_frame":"{\"market\":\"0xd412ce774cfcf8dc9f71164aac78783978aac7b03871702a3b8a481bd9dc9688\", \"price_changes\":[{\"asset_id\":\"107603864457683460275633293642179940881969192120168665300712204232021063124301\", \"price\":\"0.45\", \"size\":\"177.6\", \"side\":\"BUY\", \"hash\":\"517c5c4e6217ede787d8b5d83f30ef4f98e7ff82\", \"best_bid\":\"0.46\", \"best_ask\":\"0.47\"}, {\"asset_id\":\"96600821790790307414914106093858868634329285205417149685270682748367152458577\", \"price\":\"0.55\", \"size\":\"177.6\", \"side\":\"SELL\", \"hash\":\"2140e9d71a4ac9b693ca2237b39cb44beadd4509\", \"best_bid\":\"0.53\", \"best_ask\":\"0.54\"}], \"timestamp\":\"1785211225981\", \"event_type\":\"price_change\"}","received_at":"2026-07-28T04:00:29.814699Z","schema_version":"clob-market-ws.price_change.v1","sequence":null,"server_hash":null,"server_timestamp":"1785211225981","session_id":"2d607381e3054cee91998cdf45a4231c","source":"clob_market_ws"},"received_at":"2026-07-28T04:00:29.814699Z","record_id":"8dcf372244fbb834f2c639ff26e2f33624f66db28bc4e6b08a6d4e760d3a2ea4","schema_fingerprint":"4aa3821a28b0b7c2400bc59aba4bcc0a76e971dadd19610d3ad38c768e124dc7","schema_version":"edge-lab-recorder.raw.v1","sequence":null,"source":"clob_market_ws"}
{"event_at":"2026-07-28T04:00:25.998000Z","event_fingerprint":"68f92fbd4033bd386d405e646bfb33bc83c113cf3f43dfa73f5ad5c0c8fa7c55","payload":{"connection_id":"f6725804f86a4c4eb588e4d5ed7db029","event_at":"2026-07-28T04:00:25.998000Z","event_type":"price_change","frame_hash":"6cf785b0f4dbebfe21c60396cf19011a31754463b56e4377956e35c5d773919f","frame_index":0,"kind":"data","monotonic_ns":313212868536250,"payload":{"event_type":"price_change","market":"0xd412ce774cfcf8dc9f71164aac78783978aac7b03871702a3b8a481bd9dc9688","price_changes":[{"asset_id":"96600821790790307414914106093858868634329285205417149685270682748367152458577","best_ask":"0.54","best_bid":"0.53","hash":"c12ee7904a3afe5aed66527330cbe38e75d4ebcc","price":"0.01","side":"BUY","size":"7545.02"},{"asset_id":"107603864457683460275633293642179940881969192120168665300712204232021063124301","best_ask":"0.47","best_bid":"0.46","hash":"89aeeb2228e82052f84b522f8e214f4810340312","price":"0.99","side":"SELL","size":"7545.02"}],"timestamp":"1785211225998"},"payload_hash":"b8fcb4538d1c94eacb7d972fdc49b02f80db4510bb4620bbe1108eac739d2659","raw_frame":"{\"market\":\"0xd412ce774cfcf8dc9f71164aac78783978aac7b03871702a3b8a481bd9dc9688\", \"price_changes\":[{\"asset_id\":\"96600821790790307414914106093858868634329285205417149685270682748367152458577\", \"price\":\"0.01\", \"size\":\"7545.02\", \"side\":\"BUY\", \"hash\":\"c12ee7904a3afe5aed66527330cbe38e75d4ebcc\", \"best_bid\":\"0.53\", \"best_ask\":\"0.54\"}, {\"asset_id\":\"107603864457683460275633293642179940881969192120168665300712204232021063124301\", \"price\":\"0.99\", \"size\":\"7545.02\", \"side\":\"SELL\", \"hash\":\"89aeeb2228e82052f84b522f8e214f4810340312\", \"best_bid\":\"0.46\", \"best_ask\":\"0.47\"}], \"timestamp\":\"1785211225998\", \"event_type\":\"price_change\"}","received_at":"2026-07-28T04:00:29.820406Z","schema_version":"clob-market-ws.price_change.v1","sequence":null,"server_hash":null,"server_timestamp":"1785211225998","session_id":"2d607381e3054cee91998cdf45a4231c","source":"clob_market_ws"},"received_at":"2026-07-28T04:00:29.820406Z","record_id":"2b6e36fef0c7098bf1c6beb2f81d7e1d568cd559a459597ad9e771882f520358","schema_fingerprint":"4aa3821a28b0b7c2400bc59aba4bcc0a76e971dadd19610d3ad38c768e124dc7","schema_version":"edge-lab-recorder.raw.v1","sequence":null,"source":"clob_market_ws"}
{"event_at":"2026-07-28T04:00:26.000000Z","event_fingerprint":"3ff810547e2a8c6465801cf2f4855338e88ef5041475a3943a7194ef2d0e9bc0","payload":{"connection_id":"f6725804f86a4c4eb588e4d5ed7db029","event_at":"2026-07-28T04:00:26.000000Z","event_type":"price_change","frame_hash":"8c6841a6f7c732b95e0cd74d5b114f0a65e90eb847be8a9a03c3ca33f5f7d0a8","frame_index":0,"kind":"data","monotonic_ns":313212873783708,"payload":{"event_type":"price_change","market":"0xd412ce774cfcf8dc9f71164aac78783978aac7b03871702a3b8a481bd9dc9688","price_changes":[{"asset_id":"107603864457683460275633293642179940881969192120168665300712204232021063124301","best_ask":"0.47","best_bid":"0.46","hash":"6707d7ae675183851dbde80ae4af6acd69b35b6b","price":"0.41","side":"BUY","size":"91.34"},{"asset_id":"96600821790790307414914106093858868634329285205417149685270682748367152458577","best_ask":"0.54","best_bid":"0.53","hash":"8292b61155a2ad8c987b157c12e3be16a5be9ddb","price":"0.59","side":"SELL","size":"91.34"}],"timestamp":"1785211226000"},"payload_hash":"29b988de504099ba1cea4a0dbcbfa56276a345a8daf4c2246c518044a2feab34","raw_frame":"{\"market\":\"0xd412ce774cfcf8dc9f71164aac78783978aac7b03871702a3b8a481bd9dc9688\", \"price_changes\":[{\"asset_id\":\"107603864457683460275633293642179940881969192120168665300712204232021063124301\", \"price\":\"0.41\", \"size\":\"91.34\", \"side\":\"BUY\", \"hash\":\"6707d7ae675183851dbde80ae4af6acd69b35b6b\", \"best_bid\":\"0.46\", \"best_ask\":\"0.47\"}, {\"asset_id\":\"96600821790790307414914106093858868634329285205417149685270682748367152458577\", \"price\":\"0.59\", \"size\":\"91.34\", \"side\":\"SELL\", \"hash\":\"8292b61155a2ad8c987b157c12e3be16a5be9ddb\", \"best_bid\":\"0.53\", \"best_ask\":\"0.54\"}], \"timestamp\":\"1785211226000\", \"event_type\":\"price_change\"}","received_at":"2026-07-28T04:00:29.825654Z","schema_version":"clob-market-ws.price_change.v1","sequence":null,"server_hash":null,"server_timestamp":"1785211226000","session_id":"2d607381e3054cee91998cdf45a4231c","source":"clob_market_ws"},"received_at":"2026-07-28T04:00:29.825654Z","record_id":"4908fb7469181fdb059dcfbd3d7fdb1a49c7b40a4823f45f784ebb6dd25f1652","schema_fingerprint":"4aa3821a28b0b7c2400bc59aba4bcc0a76e971dadd19610d3ad38c768e124dc7","schema_version":"edge-lab-recorder.raw.v1","sequence":null,"source":"clob_market_ws"}
{"event_at":"2026-07-28T04:00:26.021000Z","event_fingerprint":"43e7489a640aea82180366ea25c1541cc2ff242de185514dbd8d27335f70bcfd","payload":{"connection_id":"f6725804f86a4c4eb588e4d5ed7db029","event_at":"2026-07-28T04:00:26.021000Z","event_type":"price_change","frame_hash":"1d63758ec83a89fbeca85674ec1109dc657f72fa2a4107874880ae5476c7dffd","frame_index":0,"kind":"data","monotonic_ns":313212878299708,"payload":{"event_type":"price_change","market":"0xd412ce774cfcf8dc9f71164aac78783978aac7b03871702a3b8a481bd9dc9688","price_changes":[{"asset_id":"107603864457683460275633293642179940881969192120168665300712204232021063124301","best_ask":"0.47","best_bid":"0.46","hash":"3752903bcbcd71276bfac62747d06aefad859c89","price":"0.01","side":"BUY","size":"7585.02"},{"asset_id":"96600821790790307414914106093858868634329285205417149685270682748367152458577","best_ask":"0.54","best_bid":"0.53","hash":"e290e53cd8dcc0f67278c80338f1dfb32de7b4f3","price":"0.99","side":"SELL","size":"7585.02"}],"timestamp":"1785211226021"},"payload_hash":"5f12e7be799c093216f6fa839290d39b29df07669b8716bc99e8d3b81688e552","raw_frame":"{\"market\":\"0xd412ce774cfcf8dc9f71164aac78783978aac7b03871702a3b8a481bd9dc9688\", \"price_changes\":[{\"asset_id\":\"107603864457683460275633293642179940881969192120168665300712204232021063124301\", \"price\":\"0.01\", \"size\":\"7585.02\", \"side\":\"BUY\", \"hash\":\"3752903bcbcd71276bfac62747d06aefad859c89\", \"best_bid\":\"0.46\", \"best_ask\":\"0.47\"}, {\"asset_id\":\"96600821790790307414914106093858868634329285205417149685270682748367152458577\", \"price\":\"0.99\", \"size\":\"7585.02\", \"side\":\"SELL\", \"hash\":\"e290e53cd8dcc0f67278c80338f1dfb32de7b4f3\", \"best_bid\":\"0.53\", \"best_ask\":\"0.54\"}], \"timestamp\":\"1785211226021\", \"event_type\":\"price_change\"}","received_at":"2026-07-28T04:00:29.830170Z","schema_version":"clob-market-ws.price_change.v1","sequence":null,"server_hash":null,"server_timestamp":"1785211226021","session_id":"2d607381e3054cee91998cdf45a4231c","source":"clob_market_ws"},"received_at":"2026-07-28T04:00:29.830170Z","record_id":"7aa2517116dea1e722e9370b36437d131a64739b022f17e090930f864342433e","schema_fingerprint":"4aa3821a28b0b7c2400bc59aba4bcc0a76e971dadd19610d3ad38c768e124dc7","schema_version":"edge-lab-recorder.raw.v1","sequence":null,"source":"clob_market_ws"}
{"event_at":"2026-07-28T04:00:26.023000Z","event_fingerprint":"ca8fb49a48e9a6ec28d5c6d3ec944c7d3bf9a0b5ce0a191848702b7be2683849","payload":{"connection_id":"f6725804f86a4c4eb588e4d5ed7db029","event_at":"2026-07-28T04:00:26.023000Z","event_type":"price_change","frame_hash":"1470f130fffbbe41bc2a12931235132b1c78a8dad89ff0c10542395e79f7b83d","frame_index":0,"kind":"data","monotonic_ns":313212883319291,"payload":{"event_type":"price_change","market":"0xd412ce774cfcf8dc9f71164aac78783978aac7b03871702a3b8a481bd9dc9688","price_changes":[{"asset_id":"107603864457683460275633293642179940881969192120168665300712204232021063124301","best_ask":"0.47","best_bid":"0.46","hash":"effdbc1751b8a469ef4dec32b55f21e9e75201a9","price":"0.45","side":"BUY","size":"133.6"},{"asset_id":"96600821790790307414914106093858868634329285205417149685270682748367152458577","best_ask":"0.54","best_bid":"0.53","hash":"0e787986f295c0e41601efe07e300488991a4ac8","price":"0.55","side":"SELL","size":"133.6"}],"timestamp":"1785211226023"},"payload_hash":"6bd6b4b6adb506c3da09937676cc9871372b60d59fa4fd8d689bb3f00794fb52","raw_frame":"{\"market\":\"0xd412ce774cfcf8dc9f71164aac78783978aac7b03871702a3b8a481bd9dc9688\", \"price_changes\":[{\"asset_id\":\"107603864457683460275633293642179940881969192120168665300712204232021063124301\", \"price\":\"0.45\", \"size\":\"133.6\", \"side\":\"BUY\", \"hash\":\"effdbc1751b8a469ef4dec32b55f21e9e75201a9\", \"best_bid\":\"0.46\", \"best_ask\":\"0.47\"}, {\"asset_id\":\"96600821790790307414914106093858868634329285205417149685270682748367152458577\", \"price\":\"0.55\", \"size\":\"133.6\", \"side\":\"SELL\", \"hash\":\"0e787986f295c0e41601efe07e300488991a4ac8\", \"best_bid\":\"0.53\", \"best_ask\":\"0.54\"}], \"timestamp\":\"1785211226023\", \"event_type\":\"price_change\"}","received_at":"2026-07-28T04:00:29.835189Z","schema_version":"clob-market-ws.price_change.v1","sequence":null,"server_hash":null,"server_timestamp":"1785211226023","session_id":"2d607381e3054cee91998cdf45a4231c","source":"clob_market_ws"},"received_at":"2026-07-28T04:00:29.835189Z","record_id":"602c2e1b77bf8f6d93461fe0131f22420fd7cf4b0a54378aba4ebaeac0d6ec4b","schema_fingerprint":"4aa3821a28b0b7c2400bc59aba4bcc0a76e971dadd19610d3ad38c768e124dc7","schema_version":"edge-lab-recorder.raw.v1","sequence":null,"source":"clob_market_ws"}
{"event_at":"2026-07-28T04:00:26.032000Z","event_fingerprint":"622332de6030799452e450bbe426223c403654aa2677929c05e70c694302bae7","payload":{"connection_id":"f6725804f86a4c4eb588e4d5ed7db029","event_at":"2026-07-28T04:00:26.032000Z","event_type":"price_change","frame_hash":"84817c8c5335fbc996f5a68542c9c976168cf77baeeb5c57ce5bd2e5f46b43e1","frame_index":0,"kind":"data","monotonic_ns":313212892909000,"payload":{"event_type":"price_change","market":"0xd412ce774cfcf8dc9f71164aac78783978aac7b03871702a3b8a481bd9dc9688","price_changes":[{"asset_id":"107603864457683460275633293642179940881969192120168665300712204232021063124301","best_ask":"0.47","best_bid":"0.46","hash":"11f55fa020fde4a2c196a8151ca9ae6de7aa4253","price":"0.45","side":"BUY","size":"128.6"},{"asset_id":"96600821790790307414914106093858868634329285205417149685270682748367152458577","best_ask":"0.54","best_bid":"0.53","hash":"babdb0cc96dfb06cd5a2b6f4c8b92a6adedb55cd","price":"0.55","side":"SELL","size":"128.6"}],"timestamp":"1785211226032"},"payload_hash":"890562957bf2685643cd247679ee7395cb932968ed9acfee531672fd0bbfb39d","raw_frame":"{\"market\":\"0xd412ce774cfcf8dc9f71164aac78783978aac7b03871702a3b8a481bd9dc9688\", \"price_changes\":[{\"asset_id\":\"107603864457683460275633293642179940881969192120168665300712204232021063124301\", \"price\":\"0.45\", \"size\":\"128.6\", \"side\":\"BUY\", \"hash\":\"11f55fa020fde4a2c196a8151ca9ae6de7aa4253\", \"best_bid\":\"0.46\", \"best_ask\":\"0.47\"}, {\"asset_id\":\"96600821790790307414914106093858868634329285205417149685270682748367152458577\", \"price\":\"0.55\", \"size\":\"128.6\", \"side\":\"SELL\", \"hash\":\"babdb0cc96dfb06cd5a2b6f4c8b92a6adedb55cd\", \"best_bid\":\"0.53\", \"best_ask\":\"0.54\"}], \"timestamp\":\"1785211226032\", \"event_type\":\"price_change\"}","received_at":"2026-07-28T04:00:29.844778Z","schema_version":"clob-market-ws.price_change.v1","sequence":null,"server_hash":null,"server_timestamp":"1785211226032","session_id":"2d607381e3054cee91998cdf45a4231c","source":"clob_market_ws"},"received_at":"2026-07-28T04:00:29.844778Z","record_id":"bfba0e6b41a8202f5addd1c3981aad02cde5f2dee94656f7b85843c542826c4c","schema_fingerprint":"4aa3821a28b0b7c2400bc59aba4bcc0a76e971dadd19610d3ad38c768e124dc7","schema_version":"edge-lab-recorder.raw.v1","sequence":null,"source":"clob_market_ws"}
{"event_at":"2026-07-28T04:00:26.034000Z","event_fingerprint":"d7fc35b05839009956b1dc663d1c098f06dd0ef4be262049cf61f1c78c005cac","payload":{"connection_id":"f6725804f86a4c4eb588e4d5ed7db029","event_at":"2026-07-28T04:00:26.034000Z","event_type":"price_change","frame_hash":"5b01de26bfe52e773b439fc6ff2b4b01c76e9e4e300fbc83737dc170a2687003","frame_index":0,"kind":"data","monotonic_ns":313212897401958,"payload":{"event_type":"price_change","market":"0xd412ce774cfcf8dc9f71164aac78783978aac7b03871702a3b8a481bd9dc9688","price_changes":[{"asset_id":"96600821790790307414914106093858868634329285205417149685270682748367152458577","best_ask":"0.54","best_bid":"0.53","hash":"aaaa6c0be79a9ee215faa4e2d77526bc2f35444c","price":"0.44","side":"BUY","size":"59"},{"asset_id":"107603864457683460275633293642179940881969192120168665300712204232021063124301","best_ask":"0.47","best_bid":"0.46","hash":"60dea790175726f1e55d5e9b37e54a549f416cc7","price":"0.56","side":"SELL","size":"59"}],"timestamp":"1785211226034"},"payload_hash":"88965028355c65d749cc964c147f7eadd932f2cbadb4fe65ad61b14a7c3dc928","raw_frame":"{\"market\":\"0xd412ce774cfcf8dc9f71164aac78783978aac7b03871702a3b8a481bd9dc9688\", \"price_changes\":[{\"asset_id\":\"96600821790790307414914106093858868634329285205417149685270682748367152458577\", \"price\":\"0.44\", \"size\":\"59\", \"side\":\"BUY\", \"hash\":\"aaaa6c0be79a9ee215faa4e2d77526bc2f35444c\", \"best_bid\":\"0.53\", \"best_ask\":\"0.54\"}, {\"asset_id\":\"107603864457683460275633293642179940881969192120168665300712204232021063124301\", \"price\":\"0.56\", \"size\":\"59\", \"side\":\"SELL\", \"hash\":\"60dea790175726f1e55d5e9b37e54a549f416cc7\", \"best_bid\":\"0.46\", \"best_ask\":\"0.47\"}], \"timestamp\":\"1785211226034\", \"event_type\":\"price_change\"}","received_at":"2026-07-28T04:00:29.849272Z","schema_version":"clob-market-ws.price_change.v1","sequence":null,"server_hash":null,"server_timestamp":"1785211226034","session_id":"2d607381e3054cee91998cdf45a4231c","source":"clob_market_ws"},"received_at":"2026-07-28T04:00:29.849272Z","record_id":"cd2a89001694196bfa0bf2ee42807ef506139aa97151eb3624f3ea268bf4c23f","schema_fingerprint":"4aa3821a28b0b7c2400bc59aba4bcc0a76e971dadd19610d3ad38c768e124dc7","schema_version":"edge-lab-recorder.raw.v1","sequence":null,"source":"clob_market_ws"}
{"event_at":"2026-07-28T04:00:26.035000Z","event_fingerprint":"6db04d673d06fdda8a01f344fb82e4d2b123f98ecdf8801895c1d8ca3352fcc2","payload":{"connection_id":"f6725804f86a4c4eb588e4d5ed7db029","event_at":"2026-07-28T04:00:26.035000Z","event_type":"price_change","frame_hash":"f2ce20d1d5a4c56b4757646de874acfe6ead348bb16dd9725308a195cdcb774e","frame_index":0,"kind":"data","monotonic_ns":313212903186541,"payload":{"event_type":"price_change","market":"0xd412ce774cfcf8dc9f71164aac78783978aac7b03871702a3b8a481bd9dc9688","price_changes":[{"asset_id":"107603864457683460275633293642179940881969192120168665300712204232021063124301","best_ask":"0.47","best_bid":"0.46","hash":"3d23557b17b68194a47e87eadaaae72b0d2ae6c1","price":"0.45","side":"BUY","size":"141.2"},{"asset_id":"96600821790790307414914106093858868634329285205417149685270682748367152458577","best_ask":"0.54","best_bid":"0.53","hash":"46e5d87519c70c17c1a4da867426896267808f1c","price":"0.55","side":"SELL","size":"141.2"}],"timestamp":"1785211226035"},"payload_hash":"ea70e4d3ba7f824af424739b8f255b93f164286c32845703494131907ec2e55b","raw_frame":"{\"market\":\"0xd412ce774cfcf8dc9f71164aac78783978aac7b03871702a3b8a481bd9dc9688\", \"price_changes\":[{\"asset_id\":\"107603864457683460275633293642179940881969192120168665300712204232021063124301\", \"price\":\"0.45\", \"size\":\"141.2\", \"side\":\"BUY\", \"hash\":\"3d23557b17b68194a47e87eadaaae72b0d2ae6c1\", \"best_bid\":\"0.46\", \"best_ask\":\"0.47\"}, {\"asset_id\":\"96600821790790307414914106093858868634329285205417149685270682748367152458577\", \"price\":\"0.55\", \"size\":\"141.2\", \"side\":\"SELL\", \"hash\":\"46e5d87519c70c17c1a4da867426896267808f1c\", \"best_bid\":\"0.53\", \"best_ask\":\"0.54\"}], \"timestamp\":\"1785211226035\", \"event_type\":\"price_change\"}","received_at":"2026-07-28T04:00:29.855056Z","schema_version":"clob-market-ws.price_change.v1","sequence":null,"server_hash":null,"server_timestamp":"1785211226035","session_id":"2d607381e3054cee91998cdf45a4231c","source":"clob_market_ws"},"received_at":"2026-07-28T04:00:29.855056Z","record_id":"cca479558f35be5f0acbfcff3b2347f8f7e6870431fc61a30ad45277c2288c17","schema_fingerprint":"4aa3821a28b0b7c2400bc59aba4bcc0a76e971dadd19610d3ad38c768e124dc7","schema_version":"edge-lab-recorder.raw.v1","sequence":null,"source":"clob_market_ws"}
