{"event_at":"2026-07-28T04:07:00.829000Z","event_fingerprint":"e3a5bc6730a5a272e431cda93b85cdcc57286ab4f1d17a27fcbda57ad233279a","payload":{"connection_id":"f6725804f86a4c4eb588e4d5ed7db029","event_at":"2026-07-28T04:07:00.829000Z","event_type":"price_change","frame_hash":"4a0bc75c621ee5b4f82287165174983f5aa9abcd1e28bcba09967ce96cc03874","frame_index":0,"kind":"data","monotonic_ns":313607742544916,"payload":{"event_type":"price_change","market":"0xd412ce774cfcf8dc9f71164aac78783978aac7b03871702a3b8a481bd9dc9688","price_changes":[{"asset_id":"107603864457683460275633293642179940881969192120168665300712204232021063124301","best_ask":"0.64","best_bid":"0.63","hash":"a36c8dffc5591057d3378e6eac6736af45d45ae4","price":"0.52","side":"BUY","size":"47"},{"asset_id":"96600821790790307414914106093858868634329285205417149685270682748367152458577","best_ask":"0.37","best_bid":"0.36","hash":"5a5a52123a45ebca4d42958831caaece16e52cf8","price":"0.48","side":"SELL","size":"47"}],"timestamp":"1785211620829"},"payload_hash":"6b42ab819f0c6650491ffa8f27c6f557cc35f871cffc3cf6cd8ee013769b5596","raw_frame":"{\"market\":\"0xd412ce774cfcf8dc9f71164aac78783978aac7b03871702a3b8a481bd9dc9688\", \"price_changes\":[{\"asset_id\":\"107603864457683460275633293642179940881969192120168665300712204232021063124301\", \"price\":\"0.52\", \"size\":\"47\", \"side\":\"BUY\", \"hash\":\"a36c8dffc5591057d3378e6eac6736af45d45ae4\", \"best_bid\":\"0.63\", \"best_ask\":\"0.64\"}, {\"asset_id\":\"96600821790790307414914106093858868634329285205417149685270682748367152458577\", \"price\":\"0.48\", \"size\":\"47\", \"side\":\"SELL\", \"hash\":\"5a5a52123a45ebca4d42958831caaece16e52cf8\", \"best_bid\":\"0.36\", \"best_ask\":\"0.37\"}], \"timestamp\":\"1785211620829\", \"event_type\":\"price_change\"}","received_at":"2026-07-28T04:07:04.691487Z","schema_version":"clob-market-ws.price_change.v1","sequence":null,"server_hash":null,"server_timestamp":"1785211620829","session_id":"2d607381e3054cee91998cdf45a4231c","source":"clob_market_ws"},"received_at":"2026-07-28T04:07:04.691487Z","record_id":"9a55e464105178cac4a179303ad7b17b598a185ed412382209aaeb1c76c876f7","schema_fingerprint":"4aa3821a28b0b7c2400bc59aba4bcc0a76e971dadd19610d3ad38c768e124dc7","schema_version":"edge-lab-recorder.raw.v1","sequence":null,"source":"clob_market_ws"}
{"event_at":"2026-07-28T04:07:00.830000Z","event_fingerprint":"1571f296d767fc8ce6528abec70e87cc8d03679cb76c04d19b2531025583cf9e","payload":{"connection_id":"f6725804f86a4c4eb588e4d5ed7db029","event_at":"2026-07-28T04:07:00.830000Z","event_type":"price_change","frame_hash":"81ea5a793b6737fda75b87b473946b5b256bc9ffe4d7a4c9d3a202457aef20b7","frame_index":0,"kind":"data","monotonic_ns":313607746733458,"payload":{"event_type":"price_change","market":"0xd412ce774cfcf8dc9f71164aac78783978aac7b03871702a3b8a481bd9dc9688","price_changes":[{"asset_id":"96600821790790307414914106093858868634329285205417149685270682748367152458577","best_ask":"0.37","best_bid":"0.36","hash":"d308bae979ac15fa687e197963889b26ee43afde","price":"0.32","side":"BUY","size":"70.48"},{"asset_id":"107603864457683460275633293642179940881969192120168665300712204232021063124301","best_ask":"0.64","best_bid":"0.63","hash":"ac92aebd6463d19dc01ca6cd8cabbae253d90d15","price":"0.68","side":"SELL","size":"70.48"}],"timestamp":"1785211620830"},"payload_hash":"13e9a32a9f453bc25bbaa2674591f0a73a9ec6f68e9f1aa2bee845827ad2b2c6","raw_frame":"{\"market\":\"0xd412ce774cfcf8dc9f71164aac78783978aac7b03871702a3b8a481bd9dc9688\", \"price_changes\":[{\"asset_id\":\"96600821790790307414914106093858868634329285205417149685270682748367152458577\", \"price\":\"0.32\", \"size\":\"70.48\", \"side\":\"BUY\", \"hash\":\"d308bae979ac15fa687e197963889b26ee43afde\", \"best_bid\":\"0.36\", \"best_ask\":\"0.37\"}, {\"asset_id\":\"107603864457683460275633293642179940881969192120168665300712204232021063124301\", \"price\":\"0.68\", \"size\":\"70.48\", \"side\":\"SELL\", \"hash\":\"ac92aebd6463d19dc01ca6cd8cabbae253d90d15\", \"best_bid\":\"0.63\", \"best_ask\":\"0.64\"}], \"timestamp\":\"1785211620830\", \"event_type\":\"price_change\"}","received_at":"2026-07-28T04:07:04.695679Z","schema_version":"clob-market-ws.price_change.v1","sequence":null,"server_hash":null,"server_timestamp":"1785211620830","session_id":"2d607381e3054cee91998cdf45a4231c","source":"clob_market_ws"},"received_at":"2026-07-28T04:07:04.695679Z","record_id":"9eca7a0c187130fa006c972fc0be0b82b0cdd91cacf0d9d5d946ee4dc07a022f","schema_fingerprint":"4aa3821a28b0b7c2400bc59aba4bcc0a76e971dadd19610d3ad38c768e124dc7","schema_version":"edge-lab-recorder.raw.v1","sequence":null,"source":"clob_market_ws"}
{"event_at":"2026-07-28T04:07:00.832000Z","event_fingerprint":"d782dcbf2651c0f679b818346dc78abbd4c36ed257c3c960aaaf1f9d8f2478c1","payload":{"connection_id":"f6725804f86a4c4eb588e4d5ed7db029","event_at":"2026-07-28T04:07:00.832000Z","event_type":"price_change","frame_hash":"d55e9db429b2da0b61e1f9c3ae8f9a7d5452d2da8ab087c21fe4fe16c2db0c38","frame_index":0,"kind":"data","monotonic_ns":313607751162000,"payload":{"event_type":"price_change","market":"0xd412ce774cfcf8dc9f71164aac78783978aac7b03871702a3b8a481bd9dc9688","price_changes":[{"asset_id":"96600821790790307414914106093858868634329285205417149685270682748367152458577","best_ask":"0.37","best_bid":"0.36","hash":"fdfc799c8972520199f09e458540eb3dfcff3d75","price":"0.32","side":"BUY","size":"84.01"},{"asset_id":"107603864457683460275633293642179940881969192120168665300712204232021063124301","best_ask":"0.64","best_bid":"0.63","hash":"f22be0d228d6e29a0887c01270ba66f8db87f6c6","price":"0.68","side":"SELL","size":"84.01"}],"timestamp":"1785211620832"},"payload_hash":"b6b585060b90b38857accb944a99e37d289847bf69cddbb2361efdc62dc5fa06","raw_frame":"{\"market\":\"0xd412ce774cfcf8dc9f71164aac78783978aac7b03871702a3b8a481bd9dc9688\", \"price_changes\":[{\"asset_id\":\"96600821790790307414914106093858868634329285205417149685270682748367152458577\", \"price\":\"0.32\", \"size\":\"84.01\", \"side\":\"BUY\", \"hash\":\"fdfc799c8972520199f09e458540eb3dfcff3d75\", \"best_bid\":\"0.36\", \"best_ask\":\"0.37\"}, {\"asset_id\":\"107603864457683460275633293642179940881969192120168665300712204232021063124301\", \"price\":\"0.68\", \"size\":\"84.01\", \"side\":\"SELL\", \"hash\":\"f22be0d228d6e29a0887c01270ba66f8db87f6c6\", \"best_bid\":\"0.63\", \"best_ask\":\"0.64\"}], \"timestamp\":\"1785211620832\", \"event_type\":\"price_change\"}","received_at":"2026-07-28T04:07:04.700103Z","schema_version":"clob-market-ws.price_change.v1","sequence":null,"server_hash":null,"server_timestamp":"1785211620832","session_id":"2d607381e3054cee91998cdf45a4231c","source":"clob_market_ws"},"received_at":"2026-07-28T04:07:04.700103Z","record_id":"07753ce8dff01117b263ffcf2fbd639d7422bee68f0611b48c41ad313fadd753","schema_fingerprint":"4aa3821a28b0b7c2400bc59aba4bcc0a76e971dadd19610d3ad38c768e124dc7","schema_version":"edge-lab-recorder.raw.v1","sequence":null,"source":"clob_market_ws"}
{"event_at":"2026-07-28T04:07:00.839000Z","event_fingerprint":"4eee83658eae4ee687f6210ba90210686de460b2270db414ee20515d46d627d5","payload":{"connection_id":"f6725804f86a4c4eb588e4d5ed7db029","event_at":"2026-07-28T04:07:00.839000Z","event_type":"price_change","frame_hash":"fe573a86ea1c720451374906b7bf3ec6cfb72b9232a3e520405a54cf993a42be","frame_index":0,"kind":"data","monotonic_ns":313607757332583,"payload":{"event_type":"price_change","market":"0xd412ce774cfcf8dc9f71164aac78783978aac7b03871702a3b8a481bd9dc9688","price_changes":[{"asset_id":"107603864457683460275633293642179940881969192120168665300712204232021063124301","best_ask":"0.64","best_bid":"0.63","hash":"d4b462c312140f07142117d2b822fe9e7f3af179","price":"0.55","side":"BUY","size":"243.07"},{"asset_id":"96600821790790307414914106093858868634329285205417149685270682748367152458577","best_ask":"0.37","best_bid":"0.36","hash":"09aaa328f26080c6882abd58c3cecd411e27a5d9","price":"0.45","side":"SELL","size":"243.07"}],"timestamp":"1785211620839"},"payload_hash":"8c022cd819c84c9c21de3f1d87942c051907125e61b6d40774ce4cd6740b78c7","raw_frame":"{\"market\":\"0xd412ce774cfcf8dc9f71164aac78783978aac7b03871702a3b8a481bd9dc9688\", \"price_changes\":[{\"asset_id\":\"107603864457683460275633293642179940881969192120168665300712204232021063124301\", \"price\":\"0.55\", \"size\":\"243.07\", \"side\":\"BUY\", \"hash\":\"d4b462c312140f07142117d2b822fe9e7f3af179\", \"best_bid\":\"0.63\", \"best_ask\":\"0.64\"}, {\"asset_id\":\"96600821790790307414914106093858868634329285205417149685270682748367152458577\", \"price\":\"0.45\", \"size\":\"243.07\", \"side\":\"SELL\", \"hash\":\"09aaa328f26080c6882abd58c3cecd411e27a5d9\", \"best_bid\":\"0.36\", \"best_ask\":\"0.37\"}], \"timestamp\":\"1785211620839\", \"event_type\":\"price_change\"}","received_at":"2026-07-28T04:07:04.706273Z","schema_version":"clob-market-ws.price_change.v1","sequence":null,"server_hash":null,"server_timestamp":"1785211620839","session_id":"2d607381e3054cee91998cdf45a4231c","source":"clob_market_ws"},"received_at":"2026-07-28T04:07:04.706273Z","record_id":"73e0d3e3db2f404e8852ca029d205c136979ce9ba85d89b25b9038faa2f09733","schema_fingerprint":"4aa3821a28b0b7c2400bc59aba4bcc0a76e971dadd19610d3ad38c768e124dc7","schema_version":"edge-lab-recorder.raw.v1","sequence":null,"source":"clob_market_ws"}
{"event_at":null,"event_fingerprint":"ac15d555840e45d081d10dc80ea2d0be183d828de066f970a22e9b44aaed5f0c","payload":{"connection_id":"f6725804f86a4c4eb588e4d5ed7db029","event_type":"heartbeat_ack","frame_hash":"95784973cc639977bff93619700168505cb8f7855e44fa643d34622a43706c87","kind":"lifecycle","monotonic_ns":313607768883750,"raw_frame":"PONG","received_at":"2026-07-28T04:07:04.717824Z","schema_version":"edge-lab-recorder.heartbeat-ack.v1","session_id":"2d607381e3054cee91998cdf45a4231c","source":"clob_market_ws"},"received_at":"2026-07-28T04:07:04.717824Z","record_id":"f8361632fde77354211cfe01f194f062342cd00e57d6a05ab1f90cc309de1bb0","schema_fingerprint":"c14ee1aab3ca674ee738e5268877b544d74c41ad3c427cedc09236467dc68ba1","schema_version":"edge-lab-recorder.raw.v1","sequence":null,"source":"clob_market_ws"}
{"event_at":"2026-07-28T04:07:00.861000Z","event_fingerprint":"27718b4f4a5cf583a9b608e046f4b1ce97f2875856be9ed0bdc99d6303ef82f7","payload":{"connection_id":"f6725804f86a4c4eb588e4d5ed7db029","event_at":"2026-07-28T04:07:00.861000Z","event_type":"price_change","frame_hash":"ad7302a969a79909722d541f00d7f78f5d42af18e9d0b9940fa9db5d4d1ca5e5","frame_index":0,"kind":"data","monotonic_ns":313607770013958,"payload":{"event_type":"price_change","market":"0xd412ce774cfcf8dc9f71164aac78783978aac7b03871702a3b8a481bd9dc9688","price_changes":[{"asset_id":"96600821790790307414914106093858868634329285205417149685270682748367152458577","best_ask":"0.37","best_bid":"0.36","hash":"099fc4120b45ad49e954f5b9bcf984c337ee39ff","price":"0.24","side":"BUY","size":"57.77"},{"asset_id":"107603864457683460275633293642179940881969192120168665300712204232021063124301","best_ask":"0.64","best_bid":"0.63","hash":"e4071aa8999ddf5b73dfb04417f4daa0be3481e3","price":"0.76","side":"SELL","size":"57.77"}],"timestamp":"1785211620861"},"payload_hash":"e6a93c0498df3d4cdb2d4aa8cc2119efc352b93a0f0965349f48bef1efb12801","raw_frame":"{\"market\":\"0xd412ce774cfcf8dc9f71164aac78783978aac7b03871702a3b8a481bd9dc9688\", \"price_changes\":[{\"asset_id\":\"96600821790790307414914106093858868634329285205417149685270682748367152458577\", \"price\":\"0.24\", \"size\":\"57.77\", \"side\":\"BUY\", \"hash\":\"099fc4120b45ad49e954f5b9bcf984c337ee39ff\", \"best_bid\":\"0.36\", \"best_ask\":\"0.37\"}, {\"asset_id\":\"107603864457683460275633293642179940881969192120168665300712204232021063124301\", \"price\":\"0.76\", \"size\":\"57.77\", \"side\":\"SELL\", \"hash\":\"e4071aa8999ddf5b73dfb04417f4daa0be3481e3\", \"best_bid\":\"0.63\", \"best_ask\":\"0.64\"}], \"timestamp\":\"1785211620861\", \"event_type\":\"price_change\"}","received_at":"2026-07-28T04:07:04.718960Z","schema_version":"clob-market-ws.price_change.v1","sequence":null,"server_hash":null,"server_timestamp":"1785211620861","session_id":"2d607381e3054cee91998cdf45a4231c","source":"clob_market_ws"},"received_at":"2026-07-28T04:07:04.718960Z","record_id":"56c6b05af7013a12fab8d84232103a5947721b67ab1dd1559dd22ac39417c521","schema_fingerprint":"4aa3821a28b0b7c2400bc59aba4bcc0a76e971dadd19610d3ad38c768e124dc7","schema_version":"edge-lab-recorder.raw.v1","sequence":null,"source":"clob_market_ws"}
{"event_at":"2026-07-28T04:07:00.881000Z","event_fingerprint":"4fb080af65b22f2802eaf68fa00895b184503e59652922b5836a1466c0997b9c","payload":{"connection_id":"f6725804f86a4c4eb588e4d5ed7db029","event_at":"2026-07-28T04:07:00.881000Z","event_type":"price_change","frame_hash":"0663198ec5816c12b04ee660ef6be2bce41b381b080aaa209dac248aa1f27a7f","frame_index":0,"kind":"data","monotonic_ns":313607773627750,"payload":{"event_type":"price_change","market":"0xd412ce774cfcf8dc9f71164aac78783978aac7b03871702a3b8a481bd9dc9688","price_changes":[{"asset_id":"96600821790790307414914106093858868634329285205417149685270682748367152458577","best_ask":"0.37","best_bid":"0.36","hash":"7f76e163cc2c57016c308dc1091885c1b1105b79","price":"0.27","side":"BUY","size":"141.38"},{"asset_id":"107603864457683460275633293642179940881969192120168665300712204232021063124301","best_ask":"0.64","best_bid":"0.63","hash":"b6eec8f38113ecd31d2c0e5ed384880a90001257","price":"0.73","side":"SELL","size":"141.38"}],"timestamp":"1785211620881"},"payload_hash":"febc80b3b6c6a2bb2a8e8443038270602f34e375539e67eb9024f7585baa0d21","raw_frame":"{\"market\":\"0xd412ce774cfcf8dc9f71164aac78783978aac7b03871702a3b8a481bd9dc9688\", \"price_changes\":[{\"asset_id\":\"96600821790790307414914106093858868634329285205417149685270682748367152458577\", \"price\":\"0.27\", \"size\":\"141.38\", \"side\":\"BUY\", \"hash\":\"7f76e163cc2c57016c308dc1091885c1b1105b79\", \"best_bid\":\"0.36\", \"best_ask\":\"0.37\"}, {\"asset_id\":\"107603864457683460275633293642179940881969192120168665300712204232021063124301\", \"price\":\"0.73\", \"size\":\"141.38\", \"side\":\"SELL\", \"hash\":\"b6eec8f38113ecd31d2c0e5ed384880a90001257\", \"best_bid\":\"0.63\", \"best_ask\":\"0.64\"}], \"timestamp\":\"1785211620881\", \"event_type\":\"price_change\"}","received_at":"2026-07-28T04:07:04.722568Z","schema_version":"clob-market-ws.price_change.v1","sequence":null,"server_hash":null,"server_timestamp":"1785211620881","session_id":"2d607381e3054cee91998cdf45a4231c","source":"clob_market_ws"},"received_at":"2026-07-28T04:07:04.722568Z","record_id":"692b906ff787b41def2ea0815c8d2509137e46563529ecb03c6a14d746a45c77","schema_fingerprint":"4aa3821a28b0b7c2400bc59aba4bcc0a76e971dadd19610d3ad38c768e124dc7","schema_version":"edge-lab-recorder.raw.v1","sequence":null,"source":"clob_market_ws"}
{"event_at":"2026-07-28T04:07:00.881000Z","event_fingerprint":"e6ef84a91bb838297bd27027aff4b588a679ce5a628de25af25e4080385b313e","payload":{"connection_id":"f6725804f86a4c4eb588e4d5ed7db029","event_at":"2026-07-28T04:07:00.881000Z","event_type":"price_change","frame_hash":"ca312a04d33c23cffdfae6964c9e151594c9f11b23eb260968fb1da541dcb25a","frame_index":0,"kind":"data","monotonic_ns":313607776612625,"payload":{"event_type":"price_change","market":"0xd412ce774cfcf8dc9f71164aac78783978aac7b03871702a3b8a481bd9dc9688","price_changes":[{"asset_id":"96600821790790307414914106093858868634329285205417149685270682748367152458577","best_ask":"0.37","best_bid":"0.36","hash":"b312dcb60b0ebd6e4e22f5a1a354fdffbaa87a55","price":"0.27","side":"BUY","size":"111.38"},{"asset_id":"107603864457683460275633293642179940881969192120168665300712204232021063124301","best_ask":"0.64","best_bid":"0.63","hash":"c57d0514e4ef2630edbe54d8b7c2f475cde4ae1b","price":"0.73","side":"SELL","size":"111.38"}],"timestamp":"1785211620881"},"payload_hash":"04d7569a0a40d8f53d1a21cadd955404a880742922b5723ed6ef1884339a4815","raw_frame":"{\"market\":\"0xd412ce774cfcf8dc9f71164aac78783978aac7b03871702a3b8a481bd9dc9688\", \"price_changes\":[{\"asset_id\":\"96600821790790307414914106093858868634329285205417149685270682748367152458577\", \"price\":\"0.27\", \"size\":\"111.38\", \"side\":\"BUY\", \"hash\":\"b312dcb60b0ebd6e4e22f5a1a354fdffbaa87a55\", \"best_bid\":\"0.36\", \"best_ask\":\"0.37\"}, {\"asset_id\":\"107603864457683460275633293642179940881969192120168665300712204232021063124301\", \"price\":\"0.73\", \"size\":\"111.38\", \"side\":\"SELL\", \"hash\":\"c57d0514e4ef2630edbe54d8b7c2f475cde4ae1b\", \"best_bid\":\"0.63\", \"best_ask\":\"0.64\"}], \"timestamp\":\"1785211620881\", \"event_type\":\"price_change\"}","received_at":"2026-07-28T04:07:04.725559Z","schema_version":"clob-market-ws.price_change.v1","sequence":null,"server_hash":null,"server_timestamp":"1785211620881","session_id":"2d607381e3054cee91998cdf45a4231c","source":"clob_market_ws"},"received_at":"2026-07-28T04:07:04.725559Z","record_id":"8e9a4356fc64302846f31de3968aff3dc69c608c1e2b4de1266a524e48bb3a41","schema_fingerprint":"4aa3821a28b0b7c2400bc59aba4bcc0a76e971dadd19610d3ad38c768e124dc7","schema_version":"edge-lab-recorder.raw.v1","sequence":null,"source":"clob_market_ws"}
{"event_at":"2026-07-28T04:07:00.882000Z","event_fingerprint":"8c5f446740aa4237bf65294d4655528ff3bd3b2ba698a197e0a9f7c31487cd92","payload":{"connection_id":"f6725804f86a4c4eb588e4d5ed7db029","event_at":"2026-07-28T04:07:00.882000Z","event_type":"price_change","frame_hash":"45a258ebc82da93a4c5b8618d2260612af5ea9f4721b390be33023d37d6ccc31","frame_index":0,"kind":"data","monotonic_ns":313607777911791,"payload":{"event_type":"price_change","market":"0xd412ce774cfcf8dc9f71164aac78783978aac7b03871702a3b8a481bd9dc9688","price_changes":[{"asset_id":"96600821790790307414914106093858868634329285205417149685270682748367152458577","best_ask":"0.37","best_bid":"0.36","hash":"f6c5e054b716fcce5bd8879d1b2303c4de767a9c","price":"0.27","side":"BUY","size":"81.38"},{"asset_id":"107603864457683460275633293642179940881969192120168665300712204232021063124301","best_ask":"0.64","best_bid":"0.63","hash":"412ca713df84bf09603e2b1cc0b4d99b5859a885","price":"0.73","side":"SELL","size":"81.38"}],"timestamp":"1785211620882"},"payload_hash":"00100fe252659bad28af72d552479df1bececa064663a356249cb4eb27bed5b7","raw_frame":"{\"market\":\"0xd412ce774cfcf8dc9f71164aac78783978aac7b03871702a3b8a481bd9dc9688\", \"price_changes\":[{\"asset_id\":\"96600821790790307414914106093858868634329285205417149685270682748367152458577\", \"price\":\"0.27\", \"size\":\"81.38\", \"side\":\"BUY\", \"hash\":\"f6c5e054b716fcce5bd8879d1b2303c4de767a9c\", \"best_bid\":\"0.36\", \"best_ask\":\"0.37\"}, {\"asset_id\":\"107603864457683460275633293642179940881969192120168665300712204232021063124301\", \"price\":\"0.73\", \"size\":\"81.38\", \"side\":\"SELL\", \"hash\":\"412ca713df84bf09603e2b1cc0b4d99b5859a885\", \"best_bid\":\"0.63\", \"best_ask\":\"0.64\"}], \"timestamp\":\"1785211620882\", \"event_type\":\"price_change\"}","received_at":"2026-07-28T04:07:04.726859Z","schema_version":"clob-market-ws.price_change.v1","sequence":null,"server_hash":null,"server_timestamp":"1785211620882","session_id":"2d607381e3054cee91998cdf45a4231c","source":"clob_market_ws"},"received_at":"2026-07-28T04:07:04.726859Z","record_id":"6925a57749256da650a02835719eeec23efcefdee26f7e2a454d10ce2a4b4059","schema_fingerprint":"4aa3821a28b0b7c2400bc59aba4bcc0a76e971dadd19610d3ad38c768e124dc7","schema_version":"edge-lab-recorder.raw.v1","sequence":null,"source":"clob_market_ws"}
{"event_at":"2026-07-28T04:07:00.890000Z","event_fingerprint":"93b9b555f94f74c70ad2783ec8dace0e87a4e5ecfacb872b8319a301be61a782","payload":{"connection_id":"f6725804f86a4c4eb588e4d5ed7db029","event_at":"2026-07-28T04:07:00.890000Z","event_type":"price_change","frame_hash":"e7cfb12946a1981a1ec21aa3bf7febffa904eff462ae26292cfe1e0426cf2fec","frame_index":0,"kind":"data","monotonic_ns":313607780478583,"payload":{"event_type":"price_change","market":"0xd412ce774cfcf8dc9f71164aac78783978aac7b03871702a3b8a481bd9dc9688","price_changes":[{"asset_id":"96600821790790307414914106093858868634329285205417149685270682748367152458577","best_ask":"0.37","best_bid":"0.36","hash":"08a605ec347fde33f042d44c5c7d93e43fa7206a","price":"0.31","side":"BUY","size":"66.61"},{"asset_id":"107603864457683460275633293642179940881969192120168665300712204232021063124301","best_ask":"0.64","best_bid":"0.63","hash":"2502f3171b74de8c7000a6bd001be168e0ca78c7","price":"0.69","side":"SELL","size":"66.61"}],"timestamp":"1785211620890"},"payload_hash":"b9d2910c925255ec1d3134e112052b9a2cdecffa5dc3d3286a0bf9f25e266d31","raw_frame":"{\"market\":\"0xd412ce774cfcf8dc9f71164aac78783978aac7b03871702a3b8a481bd9dc9688\", \"price_changes\":[{\"asset_id\":\"96600821790790307414914106093858868634329285205417149685270682748367152458577\", \"price\":\"0.31\", \"size\":\"66.61\", \"side\":\"BUY\", \"hash\":\"08a605ec347fde33f042d44c5c7d93e43fa7206a\", \"best_bid\":\"0.36\", \"best_ask\":\"0.37\"}, {\"asset_id\":\"107603864457683460275633293642179940881969192120168665300712204232021063124301\", \"price\":\"0.69\", \"size\":\"66.61\", \"side\":\"SELL\", \"hash\":\"2502f3171b74de8c7000a6bd001be168e0ca78c7\", \"best_bid\":\"0.63\", \"best_ask\":\"0.64\"}], \"timestamp\":\"1785211620890\", \"event_type\":\"price_change\"}","received_at":"2026-07-28T04:07:04.729420Z","schema_version":"clob-market-ws.price_change.v1","sequence":null,"server_hash":null,"server_timestamp":"1785211620890","session_id":"2d607381e3054cee91998cdf45a4231c","source":"clob_market_ws"},"received_at":"2026-07-28T04:07:04.729420Z","record_id":"a684ef933e687cb523b42c3a2c659b34575f3443e9b3db7d93858db03b829dca","schema_fingerprint":"4aa3821a28b0b7c2400bc59aba4bcc0a76e971dadd19610d3ad38c768e124dc7","schema_version":"edge-lab-recorder.raw.v1","sequence":null,"source":"clob_market_ws"}
{"event_at":"2026-07-28T04:07:00.900000Z","event_fingerprint":"c7c345b2c6eb7e43235b6b28d1c813637a96d9feeab71b3330b4a7723138bd0b","payload":{"connection_id":"f6725804f86a4c4eb588e4d5ed7db029","event_at":"2026-07-28T04:07:00.900000Z","event_type":"price_change","frame_hash":"c444ec5fa6edf21ea0c0f9fb617d1dd272e4a50f314f86ee6d4edcc6a438cb16","frame_index":0,"kind":"data","monotonic_ns":313607784020291,"payload":{"event_type":"price_change","market":"0xd412ce774cfcf8dc9f71164aac78783978aac7b03871702a3b8a481bd9dc9688","price_changes":[{"asset_id":"107603864457683460275633293642179940881969192120168665300712204232021063124301","best_ask":"0.64","best_bid":"0.63","hash":"f624a3fdd79738434fc682da298fb37b31cafa54","price":"0.54","side":"BUY","size":"154.04"},{"asset_id":"96600821790790307414914106093858868634329285205417149685270682748367152458577","best_ask":"0.37","best_bid":"0.36","hash":"c70141c5401a22a8bc71f7aed133b1c88fc0b500","price":"0.46","side":"SELL","size":"154.04"}],"timestamp":"1785211620900"},"payload_hash":"33b396915238875716e4cce46537a8a264512f83f6bc3e90214ae3617a4551ab","raw_frame":"{\"market\":\"0xd412ce774cfcf8dc9f71164aac78783978aac7b03871702a3b8a481bd9dc9688\", \"price_changes\":[{\"asset_id\":\"107603864457683460275633293642179940881969192120168665300712204232021063124301\", \"price\":\"0.54\", \"size\":\"154.04\", \"side\":\"BUY\", \"hash\":\"f624a3fdd79738434fc682da298fb37b31cafa54\", \"best_bid\":\"0.63\", \"best_ask\":\"0.64\"}, {\"asset_id\":\"96600821790790307414914106093858868634329285205417149685270682748367152458577\", \"price\":\"0.46\", \"size\":\"154.04\", \"side\":\"SELL\", \"hash\":\"c70141c5401a22a8bc71f7aed133b1c88fc0b500\", \"best_bid\":\"0.36\", \"best_ask\":\"0.37\"}], \"timestamp\":\"1785211620900\", \"event_type\":\"price_change\"}","received_at":"2026-07-28T04:07:04.732968Z","schema_version":"clob-market-ws.price_change.v1","sequence":null,"server_hash":null,"server_timestamp":"1785211620900","session_id":"2d607381e3054cee91998cdf45a4231c","source":"clob_market_ws"},"received_at":"2026-07-28T04:07:04.732968Z","record_id":"9fce0c76a84373cf7a5893a9c20e0bdb65d3788103c8a9045fdbd51ceddb0653","schema_fingerprint":"4aa3821a28b0b7c2400bc59aba4bcc0a76e971dadd19610d3ad38c768e124dc7","schema_version":"edge-lab-recorder.raw.v1","sequence":null,"source":"clob_market_ws"}
{"event_at":"2026-07-28T04:07:00.902000Z","event_fingerprint":"d7ff9dddc36d34c8d3b523ebc7e20b9d8d5d15f1d24af4456316d8927d6e8b35","payload":{"connection_id":"f6725804f86a4c4eb588e4d5ed7db029","event_at":"2026-07-28T04:07:00.902000Z","event_type":"price_change","frame_hash":"fb864b47678f6e75031120e318bfa3eb8c3cc26a052987426edf4f0291bb4a15","frame_index":0,"kind":"data","monotonic_ns":313607785252291,"payload":{"event_type":"price_change","market":"0xd412ce774cfcf8dc9f71164aac78783978aac7b03871702a3b8a481bd9dc9688","price_changes":[{"asset_id":"107603864457683460275633293642179940881969192120168665300712204232021063124301","best_ask":"0.64","best_bid":"0.63","hash":"5f41b65ca7152d032c43b91e85725f089474016f","price":"0.04","side":"BUY","size":"623.09"},{"asset_id":"96600821790790307414914106093858868634329285205417149685270682748367152458577","best_ask":"0.37","best_bid":"0.36","hash":"713d28488a7a18c5b273a0d0adb262d0585c8f24","price":"0.96","side":"SELL","size":"623.09"}],"timestamp":"1785211620902"},"payload_hash":"fb7bea2af9f7949b0c2f1c11db57d83d62fb5ca9b9df03b6530f4c57ff14286f","raw_frame":"{\"market\":\"0xd412ce774cfcf8dc9f71164aac78783978aac7b03871702a3b8a481bd9dc9688\", \"price_changes\":[{\"asset_id\":\"107603864457683460275633293642179940881969192120168665300712204232021063124301\", \"price\":\"0.04\", \"size\":\"623.09\", \"side\":\"BUY\", \"hash\":\"5f41b65ca7152d032c43b91e85725f089474016f\", \"best_bid\":\"0.63\", \"best_ask\":\"0.64\"}, {\"asset_id\":\"96600821790790307414914106093858868634329285205417149685270682748367152458577\", \"price\":\"0.96\", \"size\":\"623.09\", \"side\":\"SELL\", \"hash\":\"713d28488a7a18c5b273a0d0adb262d0585c8f24\", \"best_bid\":\"0.36\", \"best_ask\":\"0.37\"}], \"timestamp\":\"1785211620902\", \"event_type\":\"price_change\"}","received_at":"2026-07-28T04:07:04.734199Z","schema_version":"clob-market-ws.price_change.v1","sequence":null,"server_hash":null,"server_timestamp":"1785211620902","session_id":"2d607381e3054cee91998cdf45a4231c","source":"clob_market_ws"},"received_at":"2026-07-28T04:07:04.734199Z","record_id":"4e96bb7d2da5cb063cc267d6e60dd66246b200afa7ef258dd7280a461f149901","schema_fingerprint":"4aa3821a28b0b7c2400bc59aba4bcc0a76e971dadd19610d3ad38c768e124dc7","schema_version":"edge-lab-recorder.raw.v1","sequence":null,"source":"clob_market_ws"}
{"event_at":"2026-07-28T04:07:00.903000Z","event_fingerprint":"399e0073f8e22256fd820c674d90cefea638c0d02d1bdcd2bb5c409e11ccee2f","payload":{"connection_id":"f6725804f86a4c4eb588e4d5ed7db029","event_at":"2026-07-28T04:07:00.903000Z","event_type":"price_change","frame_hash":"de44cc32f6c9d6dfa1ee4720b9f12c1ce8065cdca0994972a7ee7484c0e534e7","frame_index":0,"kind":"data","monotonic_ns":313607787206291,"payload":{"event_type":"price_change","market":"0xd412ce774cfcf8dc9f71164aac78783978aac7b03871702a3b8a481bd9dc9688","price_changes":[{"asset_id":"96600821790790307414914106093858868634329285205417149685270682748367152458577","best_ask":"0.37","best_bid":"0.36","hash":"6d604a55aa22887302758d8082d76e1f859f21a1","price":"0.01","side":"BUY","size":"5598.02"},{"asset_id":"107603864457683460275633293642179940881969192120168665300712204232021063124301","best_ask":"0.64","best_bid":"0.63","hash":"a452580ffd1600085ee0d90b4d75057d9456a8c2","price":"0.99","side":"SELL","size":"5598.02"}],"timestamp":"1785211620903"},"payload_hash":"119bf7535bef4589149096d395b73fadfd88d06a743b91d18209d3aa2bfab173","raw_frame":"{\"market\":\"0xd412ce774cfcf8dc9f71164aac78783978aac7b03871702a3b8a481bd9dc9688\", \"price_changes\":[{\"asset_id\":\"96600821790790307414914106093858868634329285205417149685270682748367152458577\", \"price\":\"0.01\", \"size\":\"5598.02\", \"side\":\"BUY\", \"hash\":\"6d604a55aa22887302758d8082d76e1f859f21a1\", \"best_bid\":\"0.36\", \"best_ask\":\"0.37\"}, {\"asset_id\":\"107603864457683460275633293642179940881969192120168665300712204232021063124301\", \"price\":\"0.99\", \"size\":\"5598.02\", \"side\":\"SELL\", \"hash\":\"a452580ffd1600085ee0d90b4d75057d9456a8c2\", \"best_bid\":\"0.63\", \"best_ask\":\"0.64\"}], \"timestamp\":\"1785211620903\", \"event_type\":\"price_change\"}","received_at":"2026-07-28T04:07:04.736147Z","schema_version":"clob-market-ws.price_change.v1","sequence":null,"server_hash":null,"server_timestamp":"1785211620903","session_id":"2d607381e3054cee91998cdf45a4231c","source":"clob_market_ws"},"received_at":"2026-07-28T04:07:04.736147Z","record_id":"51ae12517dfc003a4cf67d2d0a3cd9ea20fc2d10dad9c0df40d13ba330dff74e","schema_fingerprint":"4aa3821a28b0b7c2400bc59aba4bcc0a76e971dadd19610d3ad38c768e124dc7","schema_version":"edge-lab-recorder.raw.v1","sequence":null,"source":"clob_market_ws"}
{"event_at":"2026-07-28T04:07:00.903000Z","event_fingerprint":"763123e33b8ddb5d86a4e66942e98917aa01820d5def06ae485bf7280db4348f","payload":{"connection_id":"f6725804f86a4c4eb588e4d5ed7db029","event_at":"2026-07-28T04:07:00.903000Z","event_type":"price_change","frame_hash":"c8dbbb4b03809da67baffd51895074ae610d87041e63d5ff20b2e5909d28aa7b","frame_index":0,"kind":"data","monotonic_ns":313607789142375,"payload":{"event_type":"price_change","market":"0xd412ce774cfcf8dc9f71164aac78783978aac7b03871702a3b8a481bd9dc9688","price_changes":[{"asset_id":"96600821790790307414914106093858868634329285205417149685270682748367152458577","best_ask":"0.37","best_bid":"0.36","hash":"cd8786ec291662851c28db794f3ebcb5203f7524","price":"0.29","side":"BUY","size":"10"},{"asset_id":"107603864457683460275633293642179940881969192120168665300712204232021063124301","best_ask":"0.64","best_bid":"0.63","hash":"e60f930ff85e6cc94a2911cefbf830496e6ee01f","price":"0.71","side":"SELL","size":"10"}],"timestamp":"1785211620903"},"payload_hash":"d7e2eb632900dd32772cb8c95c695cbbec427590a9caee5b537910a555447714","raw_frame":"{\"market\":\"0xd412ce774cfcf8dc9f71164aac78783978aac7b03871702a3b8a481bd9dc9688\", \"price_changes\":[{\"asset_id\":\"96600821790790307414914106093858868634329285205417149685270682748367152458577\", \"price\":\"0.29\", \"size\":\"10\", \"side\":\"BUY\", \"hash\":\"cd8786ec291662851c28db794f3ebcb5203f7524\", \"best_bid\":\"0.36\", \"best_ask\":\"0.37\"}, {\"asset_id\":\"107603864457683460275633293642179940881969192120168665300712204232021063124301\", \"price\":\"0.71\", \"size\":\"10\", \"side\":\"SELL\", \"hash\":\"e60f930ff85e6cc94a2911cefbf830496e6ee01f\", \"best_bid\":\"0.63\", \"best_ask\":\"0.64\"}], \"timestamp\":\"1785211620903\", \"event_type\":\"price_change\"}","received_at":"2026-07-28T04:07:04.738090Z","schema_version":"clob-market-ws.price_change.v1","sequence":null,"server_hash":null,"server_timestamp":"1785211620903","session_id":"2d607381e3054cee91998cdf45a4231c","source":"clob_market_ws"},"received_at":"2026-07-28T04:07:04.738090Z","record_id":"3df52eeee355b29cffbc69614648c1049cb2495295fa806141bd5eb485dab759","schema_fingerprint":"4aa3821a28b0b7c2400bc59aba4bcc0a76e971dadd19610d3ad38c768e124dc7","schema_version":"edge-lab-recorder.raw.v1","sequence":null,"source":"clob_market_ws"}
{"event_at":"2026-07-28T04:07:00.903000Z","event_fingerprint":"73538a0b639c078d906db5db798cb700d922de4db3e5e453368a20fd0a65667e","payload":{"connection_id":"f6725804f86a4c4eb588e4d5ed7db029","event_at":"2026-07-28T04:07:00.903000Z","event_type":"price_change","frame_hash":"3934a863e0f8de7b6744b4e8d9aed778e92767fb340accf7c923885a1db8e328","frame_index":0,"kind":"data","monotonic_ns":313607791592333,"payload":{"event_type":"price_change","market":"0xd412ce774cfcf8dc9f71164aac78783978aac7b03871702a3b8a481bd9dc9688","price_changes":[{"asset_id":"107603864457683460275633293642179940881969192120168665300712204232021063124301","best_ask":"0.64","best_bid":"0.63","hash":"16baed9ec6c647d01717186b4c07370794acaaae","price":"0.59","side":"BUY","size":"157"},{"asset_id":"96600821790790307414914106093858868634329285205417149685270682748367152458577","best_ask":"0.37","best_bid":"0.36","hash":"5b9f282cae493dd2c1ddac9ddf88f8e63693a18c","price":"0.41","side":"SELL","size":"157"}],"timestamp":"1785211620903"},"payload_hash":"9cd41703b10cca63d8c41e47e8a59ef33725b4e50743cce3031f74737c49875b","raw_frame":"{\"market\":\"0xd412ce774cfcf8dc9f71164aac78783978aac7b03871702a3b8a481bd9dc9688\", \"price_changes\":[{\"asset_id\":\"107603864457683460275633293642179940881969192120168665300712204232021063124301\", \"price\":\"0.59\", \"size\":\"157\", \"side\":\"BUY\", \"hash\":\"16baed9ec6c647d01717186b4c07370794acaaae\", \"best_bid\":\"0.63\", \"best_ask\":\"0.64\"}, {\"asset_id\":\"96600821790790307414914106093858868634329285205417149685270682748367152458577\", \"price\":\"0.41\", \"size\":\"157\", \"side\":\"SELL\", \"hash\":\"5b9f282cae493dd2c1ddac9ddf88f8e63693a18c\", \"best_bid\":\"0.36\", \"best_ask\":\"0.37\"}], \"timestamp\":\"1785211620903\", \"event_type\":\"price_change\"}","received_at":"2026-07-28T04:07:04.740533Z","schema_version":"clob-market-ws.price_change.v1","sequence":null,"server_hash":null,"server_timestamp":"1785211620903","session_id":"2d607381e3054cee91998cdf45a4231c","source":"clob_market_ws"},"received_at":"2026-07-28T04:07:04.740533Z","record_id":"61f3613281df70320f576c2413fa2b0eeffd5ef8a7a4eb502f7114855daf5dbe","schema_fingerprint":"4aa3821a28b0b7c2400bc59aba4bcc0a76e971dadd19610d3ad38c768e124dc7","schema_version":"edge-lab-recorder.raw.v1","sequence":null,"source":"clob_market_ws"}
{"event_at":"2026-07-28T04:07:00.903000Z","event_fingerprint":"02ba0e3766d8dbdf6d180269e066fbcacfc65e6688aea9c6383a7dc3a2818798","payload":{"connection_id":"f6725804f86a4c4eb588e4d5ed7db029","event_at":"2026-07-28T04:07:00.903000Z","event_type":"price_change","frame_hash":"816f058afe1f10559d9a5900f5872eca7b24d329e3bf06bf8bc534ff30ed3ff4","frame_index":0,"kind":"data","monotonic_ns":313607795946500,"payload":{"event_type":"price_change","market":"0xd412ce774cfcf8dc9f71164aac78783978aac7b03871702a3b8a481bd9dc9688","price_changes":[{"asset_id":"107603864457683460275633293642179940881969192120168665300712204232021063124301","best_ask":"0.64","best_bid":"0.63","hash":"bef742985c9a21515d0eb693a01099bb75db299a","price":"0.59","side":"BUY","size":"147"},{"asset_id":"96600821790790307414914106093858868634329285205417149685270682748367152458577","best_ask":"0.37","best_bid":"0.36","hash":"f7336cd06305ecabd45bc04057f7ee1ddd7edbbc","price":"0.41","side":"SELL","size":"147"}],"timestamp":"1785211620903"},"payload_hash":"ebd73348703f238c9340b564b689b3fce9ceee522a33e1c4f7e8474b51c120d3","raw_frame":"{\"market\":\"0xd412ce774cfcf8dc9f71164aac78783978aac7b03871702a3b8a481bd9dc9688\", \"price_changes\":[{\"asset_id\":\"107603864457683460275633293642179940881969192120168665300712204232021063124301\", \"price\":\"0.59\", \"size\":\"147\", \"side\":\"BUY\", \"hash\":\"bef742985c9a21515d0eb693a01099bb75db299a\", \"best_bid\":\"0.63\", \"best_ask\":\"0.64\"}, {\"asset_id\":\"96600821790790307414914106093858868634329285205417149685270682748367152458577\", \"price\":\"0.41\", \"size\":\"147\", \"side\":\"SELL\", \"hash\":\"f7336cd06305ecabd45bc04057f7ee1ddd7edbbc\", \"best_bid\":\"0.36\", \"best_ask\":\"0.37\"}], \"timestamp\":\"1785211620903\", \"event_type\":\"price_change\"}","received_at":"2026-07-28T04:07:04.744888Z","schema_version":"clob-market-ws.price_change.v1","sequence":null,"server_hash":null,"server_timestamp":"1785211620903","session_id":"2d607381e3054cee91998cdf45a4231c","source":"clob_market_ws"},"received_at":"2026-07-28T04:07:04.744888Z","record_id":"665cc61373a1b4130a039c2938a4b76c1b3b17f99db071d5762131776ff344cb","schema_fingerprint":"4aa3821a28b0b7c2400bc59aba4bcc0a76e971dadd19610d3ad38c768e124dc7","schema_version":"edge-lab-recorder.raw.v1","sequence":null,"source":"clob_market_ws"}
{"event_at":"2026-07-28T04:07:00.904000Z","event_fingerprint":"f221fb98e0de0df17f1b3efcc9a6050d2ae926f06e392a65c93623c61e30f358","payload":{"connection_id":"f6725804f86a4c4eb588e4d5ed7db029","event_at":"2026-07-28T04:07:00.904000Z","event_type":"price_change","frame_hash":"768d2f11273f5617b753c8d32b5f6f6fb2d3ef2bc159da7e0c8dc4a2a4e9a196","frame_index":0,"kind":"data","monotonic_ns":313607799011000,"payload":{"event_type":"price_change","market":"0xd412ce774cfcf8dc9f71164aac78783978aac7b03871702a3b8a481bd9dc9688","price_changes":[{"asset_id":"107603864457683460275633293642179940881969192120168665300712204232021063124301","best_ask":"0.64","best_bid":"0.63","hash":"20e5614154fff938793d1a46f026417a4a0dd078","price":"0.63","side":"BUY","size":"6"},{"asset_id":"96600821790790307414914106093858868634329285205417149685270682748367152458577","best_ask":"0.37","best_bid":"0.36","hash":"f28991dc30ced5a564cd73d34c2de6ff8aedd8a9","price":"0.37","side":"SELL","size":"6"}],"timestamp":"1785211620904"},"payload_hash":"f49965b6605301282b01391ff3b1b0d34aecf0336853c66f3d7e563ed0b7ce15","raw_frame":"{\"market\":\"0xd412ce774cfcf8dc9f71164aac78783978aac7b03871702a3b8a481bd9dc9688\", \"price_changes\":[{\"asset_id\":\"107603864457683460275633293642179940881969192120168665300712204232021063124301\", \"price\":\"0.63\", \"size\":\"6\", \"side\":\"BUY\", \"hash\":\"20e5614154fff938793d1a46f026417a4a0dd078\", \"best_bid\":\"0.63\", \"best_ask\":\"0.64\"}, {\"asset_id\":\"96600821790790307414914106093858868634329285205417149685270682748367152458577\", \"price\":\"0.37\", \"size\":\"6\", \"side\":\"SELL\", \"hash\":\"f28991dc30ced5a564cd73d34c2de6ff8aedd8a9\", \"best_bid\":\"0.36\", \"best_ask\":\"0.37\"}], \"timestamp\":\"1785211620904\", \"event_type\":\"price_change\"}","received_at":"2026-07-28T04:07:04.747958Z","schema_version":"clob-market-ws.price_change.v1","sequence":null,"server_hash":null,"server_timestamp":"1785211620904","session_id":"2d607381e3054cee91998cdf45a4231c","source":"clob_market_ws"},"received_at":"2026-07-28T04:07:04.747958Z","record_id":"6b662044f9861a315ebbf3a79b75f85ad6e2d02e633d837fec47f3760dbe0fd1","schema_fingerprint":"4aa3821a28b0b7c2400bc59aba4bcc0a76e971dadd19610d3ad38c768e124dc7","schema_version":"edge-lab-recorder.raw.v1","sequence":null,"source":"clob_market_ws"}
{"event_at":"2026-07-28T04:07:00.904000Z","event_fingerprint":"22df30cb46cac45f71697a36d0cf7866f93ee7459cfe29e6f915d99f5a0910de","payload":{"connection_id":"f6725804f86a4c4eb588e4d5ed7db029","event_at":"2026-07-28T04:07:00.904000Z","event_type":"price_change","frame_hash":"4741360df43e8455cd8f5c8573ddb455ea7bf5fe19b2e564633c7dc8671bcffb","frame_index":0,"kind":"data","monotonic_ns":313607802217833,"payload":{"event_type":"price_change","market":"0xd412ce774cfcf8dc9f71164aac78783978aac7b03871702a3b8a481bd9dc9688","price_changes":[{"asset_id":"96600821790790307414914106093858868634329285205417149685270682748367152458577","best_ask":"0.37","best_bid":"0.36","hash":"badd084481684f59c2763958bde1472bfd7efbec","price":"0.32","side":"BUY","size":"78.01"},{"asset_id":"107603864457683460275633293642179940881969192120168665300712204232021063124301","best_ask":"0.64","best_bid":"0.63","hash":"8b6a1f74dbe85322dd363fc964e5c032268667c6","price":"0.68","side":"SELL","size":"78.01"}],"timestamp":"1785211620904"},"payload_hash":"ae4575650dc2af66b753c7d702f97abab14b3dfa3c316f33ff5ba31abdbdc874","raw_frame":"{\"market\":\"0xd412ce774cfcf8dc9f71164aac78783978aac7b03871702a3b8a481bd9dc9688\", \"price_changes\":[{\"asset_id\":\"96600821790790307414914106093858868634329285205417149685270682748367152458577\", \"price\":\"0.32\", \"size\":\"78.01\", \"side\":\"BUY\", \"hash\":\"badd084481684f59c2763958bde1472bfd7efbec\", \"best_bid\":\"0.36\", \"best_ask\":\"0.37\"}, {\"asset_id\":\"107603864457683460275633293642179940881969192120168665300712204232021063124301\", \"price\":\"0.68\", \"size\":\"78.01\", \"side\":\"SELL\", \"hash\":\"8b6a1f74dbe85322dd363fc964e5c032268667c6\", \"best_bid\":\"0.63\", \"best_ask\":\"0.64\"}], \"timestamp\":\"1785211620904\", \"event_type\":\"price_change\"}","received_at":"2026-07-28T04:07:04.751158Z","schema_version":"clob-market-ws.price_change.v1","sequence":null,"server_hash":null,"server_timestamp":"1785211620904","session_id":"2d607381e3054cee91998cdf45a4231c","source":"clob_market_ws"},"received_at":"2026-07-28T04:07:04.751158Z","record_id":"1d344dc7f8816d1d9107ca90d7af23c8c388d747d0019dad90b848ab51cf902f","schema_fingerprint":"4aa3821a28b0b7c2400bc59aba4bcc0a76e971dadd19610d3ad38c768e124dc7","schema_version":"edge-lab-recorder.raw.v1","sequence":null,"source":"clob_market_ws"}
{"event_at":"2026-07-28T04:07:00.904000Z","event_fingerprint":"8deaff8f9cf2725969c816a9b045d1b96570a544b839f1fce0457c7a3c66f489","payload":{"connection_id":"f6725804f86a4c4eb588e4d5ed7db029","event_at":"2026-07-28T04:07:00.904000Z","event_type":"price_change","frame_hash":"6e4d95de32eec2347c5878bd94fe174b2d56f6f3353489ff1df7558e3ed2bf31","frame_index":0,"kind":"data","monotonic_ns":313607806879958,"payload":{"event_type":"price_change","market":"0xd412ce774cfcf8dc9f71164aac78783978aac7b03871702a3b8a481bd9dc9688","price_changes":[{"asset_id":"96600821790790307414914106093858868634329285205417149685270682748367152458577","best_ask":"0.37","best_bid":"0.36","hash":"42ef18f9f15406d43e6d154f3fe55739a1f65468","price":"0.24","side":"BUY","size":"51.77"},{"asset_id":"107603864457683460275633293642179940881969192120168665300712204232021063124301","best_ask":"0.64","best_bid":"0.63","hash":"d34f1291f7d69143479581ad4acb40c140392ea4","price":"0.76","side":"SELL","size":"51.77"}],"timestamp":"1785211620904"},"payload_hash":"1609e79335d40e7a3f92286d4ad4ad8b8ae85dd1b74553a98ca6e897af0c985c","raw_frame":"{\"market\":\"0xd412ce774cfcf8dc9f71164aac78783978aac7b03871702a3b8a481bd9dc9688\", \"price_changes\":[{\"asset_id\":\"96600821790790307414914106093858868634329285205417149685270682748367152458577\", \"price\":\"0.24\", \"size\":\"51.77\", \"side\":\"BUY\", \"hash\":\"42ef18f9f15406d43e6d154f3fe55739a1f65468\", \"best_bid\":\"0.36\", \"best_ask\":\"0.37\"}, {\"asset_id\":\"107603864457683460275633293642179940881969192120168665300712204232021063124301\", \"price\":\"0.76\", \"size\":\"51.77\", \"side\":\"SELL\", \"hash\":\"d34f1291f7d69143479581ad4acb40c140392ea4\", \"best_bid\":\"0.63\", \"best_ask\":\"0.64\"}], \"timestamp\":\"1785211620904\", \"event_type\":\"price_change\"}","received_at":"2026-07-28T04:07:04.755820Z","schema_version":"clob-market-ws.price_change.v1","sequence":null,"server_hash":null,"server_timestamp":"1785211620904","session_id":"2d607381e3054cee91998cdf45a4231c","source":"clob_market_ws"},"received_at":"2026-07-28T04:07:04.755820Z","record_id":"22549164e869111fb8f1f3f0ae14974a421f2281cec2d3683e29089e0a0cf6c1","schema_fingerprint":"4aa3821a28b0b7c2400bc59aba4bcc0a76e971dadd19610d3ad38c768e124dc7","schema_version":"edge-lab-recorder.raw.v1","sequence":null,"source":"clob_market_ws"}
{"event_at":"2026-07-28T04:07:00.904000Z","event_fingerprint":"6cea7918811cb6a7a6d26841c08c2dda910cda761291d9d81dce7aa6ec139f1d","payload":{"connection_id":"f6725804f86a4c4eb588e4d5ed7db029","event_at":"2026-07-28T04:07:00.904000Z","event_type":"price_change","frame_hash":"2a656464faedadea4cec3bfef16c63ab48f537e94e117a305d0b6d42db11456f","frame_index":0,"kind":"data","monotonic_ns":313607810836916,"payload":{"event_type":"price_change","market":"0xd412ce774cfcf8dc9f71164aac78783978aac7b03871702a3b8a481bd9dc9688","price_changes":[{"asset_id":"107603864457683460275633293642179940881969192120168665300712204232021063124301","best_ask":"0.64","best_bid":"0.63","hash":"753501b5a8b02e5942a883e1c4c3fb6010bb25d6","price":"0.53","side":"BUY","size":"43"},{"asset_id":"96600821790790307414914106093858868634329285205417149685270682748367152458577","best_ask":"0.37","best_bid":"0.36","hash":"4269f599c500f3a71e9063d554173c160a21ae45","price":"0.47","side":"SELL","size":"43"}],"timestamp":"1785211620904"},"payload_hash":"ef0055ab08661bcb5e469d2334c4998146dc81875ac2750d553d367570690ab8","raw_frame":"{\"market\":\"0xd412ce774cfcf8dc9f71164aac78783978aac7b03871702a3b8a481bd9dc9688\", \"price_changes\":[{\"asset_id\":\"107603864457683460275633293642179940881969192120168665300712204232021063124301\", \"price\":\"0.53\", \"size\":\"43\", \"side\":\"BUY\", \"hash\":\"753501b5a8b02e5942a883e1c4c3fb6010bb25d6\", \"best_bid\":\"0.63\", \"best_ask\":\"0.64\"}, {\"asset_id\":\"96600821790790307414914106093858868634329285205417149685270682748367152458577\", \"price\":\"0.47\", \"size\":\"43\", \"side\":\"SELL\", \"hash\":\"4269f599c500f3a71e9063d554173c160a21ae45\", \"best_bid\":\"0.36\", \"best_ask\":\"0.37\"}], \"timestamp\":\"1785211620904\", \"event_type\":\"price_change\"}","received_at":"2026-07-28T04:07:04.759778Z","schema_version":"clob-market-ws.price_change.v1","sequence":null,"server_hash":null,"server_timestamp":"1785211620904","session_id":"2d607381e3054cee91998cdf45a4231c","source":"clob_market_ws"},"received_at":"2026-07-28T04:07:04.759778Z","record_id":"a4934ded4b3d83c12d83d7421e34c44dfc6f7887cbb9ac3f755db265559817e6","schema_fingerprint":"4aa3821a28b0b7c2400bc59aba4bcc0a76e971dadd19610d3ad38c768e124dc7","schema_version":"edge-lab-recorder.raw.v1","sequence":null,"source":"clob_market_ws"}
{"event_at":"2026-07-28T04:07:00.905000Z","event_fingerprint":"71103a3eb701c1a8b42530c105cc5945811d21a6bb5b56c1d0e83bdd76a59035","payload":{"connection_id":"f6725804f86a4c4eb588e4d5ed7db029","event_at":"2026-07-28T04:07:00.905000Z","event_type":"price_change","frame_hash":"a27a79f0e859dfbd45078e6d26200c92d988640fb77f4d589df3ed45f2ecaab4","frame_index":0,"kind":"data","monotonic_ns":313607815301000,"payload":{"event_type":"price_change","market":"0xd412ce774cfcf8dc9f71164aac78783978aac7b03871702a3b8a481bd9dc9688","price_changes":[{"asset_id":"107603864457683460275633293642179940881969192120168665300712204232021063124301","best_ask":"0.64","best_bid":"0.63","hash":"c3443fba63509bad66e4dec77b15c79fa2106e16","price":"0.55","side":"BUY","size":"231"},{"asset_id":"96600821790790307414914106093858868634329285205417149685270682748367152458577","best_ask":"0.37","best_bid":"0.36","hash":"faab4a15abe9c8aa4ae5cb7c4dd2d2ece40b0624","price":"0.45","side":"SELL","size":"231"}],"timestamp":"1785211620905"},"payload_hash":"f43df0e76631b962086d9d16f8edaea32cd69a6800d7af71cc51992bbbb6e659","raw_frame":"{\"market\":\"0xd412ce774cfcf8dc9f71164aac78783978aac7b03871702a3b8a481bd9dc9688\", \"price_changes\":[{\"asset_id\":\"107603864457683460275633293642179940881969192120168665300712204232021063124301\", \"price\":\"0.55\", \"size\":\"231\", \"side\":\"BUY\", \"hash\":\"c3443fba63509bad66e4dec77b15c79fa2106e16\", \"best_bid\":\"0.63\", \"best_ask\":\"0.64\"}, {\"asset_id\":\"96600821790790307414914106093858868634329285205417149685270682748367152458577\", \"price\":\"0.45\", \"size\":\"231\", \"side\":\"SELL\", \"hash\":\"faab4a15abe9c8aa4ae5cb7c4dd2d2ece40b0624\", \"best_bid\":\"0.36\", \"best_ask\":\"0.37\"}], \"timestamp\":\"1785211620905\", \"event_type\":\"price_change\"}","received_at":"2026-07-28T04:07:04.764242Z","schema_version":"clob-market-ws.price_change.v1","sequence":null,"server_hash":null,"server_timestamp":"1785211620905","session_id":"2d607381e3054cee91998cdf45a4231c","source":"clob_market_ws"},"received_at":"2026-07-28T04:07:04.764242Z","record_id":"16437c7046a307ae8cde70c03fcb8df7b12f80d8510a4b3d48641d50078a5131","schema_fingerprint":"4aa3821a28b0b7c2400bc59aba4bcc0a76e971dadd19610d3ad38c768e124dc7","schema_version":"edge-lab-recorder.raw.v1","sequence":null,"source":"clob_market_ws"}
{"event_at":"2026-07-28T04:07:00.906000Z","event_fingerprint":"00044654cc3059c8b3b4f23d4e619143c84fc8cb8a1cff2da16d5c0942b7a685","payload":{"connection_id":"f6725804f86a4c4eb588e4d5ed7db029","event_at":"2026-07-28T04:07:00.906000Z","event_type":"price_change","frame_hash":"d2a6b31876d38e3f6ad4a8994c161cadce870d1f3b062de075bcebd62effb246","frame_index":0,"kind":"data","monotonic_ns":313607819599750,"payload":{"event_type":"price_change","market":"0xd412ce774cfcf8dc9f71164aac78783978aac7b03871702a3b8a481bd9dc9688","price_changes":[{"asset_id":"96600821790790307414914106093858868634329285205417149685270682748367152458577","best_ask":"0.37","best_bid":"0.36","hash":"c2b1de6d44148226b025e44f0830e17e6036886e","price":"0.18","side":"BUY","size":"172.3"},{"asset_id":"107603864457683460275633293642179940881969192120168665300712204232021063124301","best_ask":"0.64","best_bid":"0.63","hash":"428f0b04a6ca2700d23ff5340a3c738307a3a2d2","price":"0.82","side":"SELL","size":"172.3"}],"timestamp":"1785211620906"},"payload_hash":"37658db65207d018bb368f44d78b87bacdaba989b8943abe7971e03b6f51f3c2","raw_frame":"{\"market\":\"0xd412ce774cfcf8dc9f71164aac78783978aac7b03871702a3b8a481bd9dc9688\", \"price_changes\":[{\"asset_id\":\"96600821790790307414914106093858868634329285205417149685270682748367152458577\", \"price\":\"0.18\", \"size\":\"172.3\", \"side\":\"BUY\", \"hash\":\"c2b1de6d44148226b025e44f0830e17e6036886e\", \"best_bid\":\"0.36\", \"best_ask\":\"0.37\"}, {\"asset_id\":\"107603864457683460275633293642179940881969192120168665300712204232021063124301\", \"price\":\"0.82\", \"size\":\"172.3\", \"side\":\"SELL\", \"hash\":\"428f0b04a6ca2700d23ff5340a3c738307a3a2d2\", \"best_bid\":\"0.63\", \"best_ask\":\"0.64\"}], \"timestamp\":\"1785211620906\", \"event_type\":\"price_change\"}","received_at":"2026-07-28T04:07:04.768541Z","schema_version":"clob-market-ws.price_change.v1","sequence":null,"server_hash":null,"server_timestamp":"1785211620906","session_id":"2d607381e3054cee91998cdf45a4231c","source":"clob_market_ws"},"received_at":"2026-07-28T04:07:04.768541Z","record_id":"c2cf703767fe46e545185628086ecb21ed3f14b2e358eeaf3f49364c82553b33","schema_fingerprint":"4aa3821a28b0b7c2400bc59aba4bcc0a76e971dadd19610d3ad38c768e124dc7","schema_version":"edge-lab-recorder.raw.v1","sequence":null,"source":"clob_market_ws"}
{"event_at":"2026-07-28T04:07:00.906000Z","event_fingerprint":"3a55087296ec97b5c75bc3ae7acc52e701b9bc8b6312c90177fd0f9637dedea2","payload":{"connection_id":"f6725804f86a4c4eb588e4d5ed7db029","event_at":"2026-07-28T04:07:00.906000Z","event_type":"price_change","frame_hash":"9ac3f3d9eaff87b9053d7ad3c524cfee8448cadb86a7d21ebd7c495f81b0ad3c","frame_index":0,"kind":"data","monotonic_ns":313607823935500,"payload":{"event_type":"price_change","market":"0xd412ce774cfcf8dc9f71164aac78783978aac7b03871702a3b8a481bd9dc9688","price_changes":[{"asset_id":"96600821790790307414914106093858868634329285205417149685270682748367152458577","best_ask":"0.37","best_bid":"0.36","hash":"2e1a327bd6a7f1e328538182fed5f53fffb38311","price":"0.33","side":"BUY","size":"37.6"},{"asset_id":"107603864457683460275633293642179940881969192120168665300712204232021063124301","best_ask":"0.64","best_bid":"0.63","hash":"d7c3fac840eb7eadc74db23e256e2843531231f4","price":"0.67","side":"SELL","size":"37.6"}],"timestamp":"1785211620906"},"payload_hash":"163462f39cba0495625bc7e51741e9813dc1981c1792212a465271c4c836bd9a","raw_frame":"{\"market\":\"0xd412ce774cfcf8dc9f71164aac78783978aac7b03871702a3b8a481bd9dc9688\", \"price_changes\":[{\"asset_id\":\"96600821790790307414914106093858868634329285205417149685270682748367152458577\", \"price\":\"0.33\", \"size\":\"37.6\", \"side\":\"BUY\", \"hash\":\"2e1a327bd6a7f1e328538182fed5f53fffb38311\", \"best_bid\":\"0.36\", \"best_ask\":\"0.37\"}, {\"asset_id\":\"107603864457683460275633293642179940881969192120168665300712204232021063124301\", \"price\":\"0.67\", \"size\":\"37.6\", \"side\":\"SELL\", \"hash\":\"d7c3fac840eb7eadc74db23e256e2843531231f4\", \"best_bid\":\"0.63\", \"best_ask\":\"0.64\"}], \"timestamp\":\"1785211620906\", \"event_type\":\"price_change\"}","received_at":"2026-07-28T04:07:04.772875Z","schema_version":"clob-market-ws.price_change.v1","sequence":null,"server_hash":null,"server_timestamp":"1785211620906","session_id":"2d607381e3054cee91998cdf45a4231c","source":"clob_market_ws"},"received_at":"2026-07-28T04:07:04.772875Z","record_id":"78ec7a94a0f9797973cb39bc3f2b66fb9091956df099819aebc90bcc1b872deb","schema_fingerprint":"4aa3821a28b0b7c2400bc59aba4bcc0a76e971dadd19610d3ad38c768e124dc7","schema_version":"edge-lab-recorder.raw.v1","sequence":null,"source":"clob_market_ws"}
{"event_at":"2026-07-28T04:07:00.907000Z","event_fingerprint":"69637579c5c7b3ebde9d746286134ad1f93caeab5de719e5ebbfc45a76d9f9aa","payload":{"connection_id":"f6725804f86a4c4eb588e4d5ed7db029","event_at":"2026-07-28T04:07:00.907000Z","event_type":"price_change","frame_hash":"ecac81ef21eb8315a21070b53dcd776dd83df1eb5b8a52f74d6bcbf06fd36f1d","frame_index":0,"kind":"data","monotonic_ns":313607828113708,"payload":{"event_type":"price_change","market":"0xd412ce774cfcf8dc9f71164aac78783978aac7b03871702a3b8a481bd9dc9688","price_changes":[{"asset_id":"107603864457683460275633293642179940881969192120168665300712204232021063124301","best_ask":"0.64","best_bid":"0.63","hash":"32681c14ad8ca4b7b81f6615293684469081145b","price":"0.45","side":"BUY","size":"25.1"},{"asset_id":"96600821790790307414914106093858868634329285205417149685270682748367152458577","best_ask":"0.37","best_bid":"0.36","hash":"b5ee5404ed7f78f837d9c3c0b23a3629dbf035f0","price":"0.55","side":"SELL","size":"25.1"}],"timestamp":"1785211620907"},"payload_hash":"cb25c1beb375de8d0de26d07b0677b39d1b20f7e9d504c3ff045a562efece916","raw_frame":"{\"market\":\"0xd412ce774cfcf8dc9f71164aac78783978aac7b03871702a3b8a481bd9dc9688\", \"price_changes\":[{\"asset_id\":\"107603864457683460275633293642179940881969192120168665300712204232021063124301\", \"price\":\"0.45\", \"size\":\"25.1\", \"side\":\"BUY\", \"hash\":\"32681c14ad8ca4b7b81f6615293684469081145b\", \"best_bid\":\"0.63\", \"best_ask\":\"0.64\"}, {\"asset_id\":\"96600821790790307414914106093858868634329285205417149685270682748367152458577\", \"price\":\"0.55\", \"size\":\"25.1\", \"side\":\"SELL\", \"hash\":\"b5ee5404ed7f78f837d9c3c0b23a3629dbf035f0\", \"best_bid\":\"0.36\", \"best_ask\":\"0.37\"}], \"timestamp\":\"1785211620907\", \"event_type\":\"price_change\"}","received_at":"2026-07-28T04:07:04.777051Z","schema_version":"clob-market-ws.price_change.v1","sequence":null,"server_hash":null,"server_timestamp":"1785211620907","session_id":"2d607381e3054cee91998cdf45a4231c","source":"clob_market_ws"},"received_at":"2026-07-28T04:07:04.777051Z","record_id":"cbd543d48caf861baafd20b4a8ed026d3bed2ce869cb6c891f8189f51c811396","schema_fingerprint":"4aa3821a28b0b7c2400bc59aba4bcc0a76e971dadd19610d3ad38c768e124dc7","schema_version":"edge-lab-recorder.raw.v1","sequence":null,"source":"clob_market_ws"}
{"event_at":"2026-07-28T04:07:00.907000Z","event_fingerprint":"1a29936813e5e0f2ea9cad5c07fee3d27c34180b0f942aea8a2a89eb1933a248","payload":{"connection_id":"f6725804f86a4c4eb588e4d5ed7db029","event_at":"2026-07-28T04:07:00.907000Z","event_type":"price_change","frame_hash":"3570caec4c29bba0307a21dada0893d39ca4134de5e3b754c2a9aa333bac5fc2","frame_index":0,"kind":"data","monotonic_ns":313607832286750,"payload":{"event_type":"price_change","market":"0xd412ce774cfcf8dc9f71164aac78783978aac7b03871702a3b8a481bd9dc9688","price_changes":[{"asset_id":"96600821790790307414914106093858868634329285205417149685270682748367152458577","best_ask":"0.37","best_bid":"0.36","hash":"b5ee5404ed7f78f837d9c3c0b23a3629dbf035f0","price":"0.26","side":"BUY","size":"24.5"},{"asset_id":"107603864457683460275633293642179940881969192120168665300712204232021063124301","best_ask":"0.64","best_bid":"0.63","hash":"32681c14ad8ca4b7b81f6615293684469081145b","price":"0.74","side":"SELL","size":"24.5"}],"timestamp":"1785211620907"},"payload_hash":"ac3865328a459478fa9167ab872c34cfad8845925e89a883a09f30d7e61676e0","raw_frame":"{\"market\":\"0xd412ce774cfcf8dc9f71164aac78783978aac7b03871702a3b8a481bd9dc9688\", \"price_changes\":[{\"asset_id\":\"96600821790790307414914106093858868634329285205417149685270682748367152458577\", \"price\":\"0.26\", \"size\":\"24.5\", \"side\":\"BUY\", \"hash\":\"b5ee5404ed7f78f837d9c3c0b23a3629dbf035f0\", \"best_bid\":\"0.36\", \"best_ask\":\"0.37\"}, {\"asset_id\":\"107603864457683460275633293642179940881969192120168665300712204232021063124301\", \"price\":\"0.74\", \"size\":\"24.5\", \"side\":\"SELL\", \"hash\":\"32681c14ad8ca4b7b81f6615293684469081145b\", \"best_bid\":\"0.63\", \"best_ask\":\"0.64\"}], \"timestamp\":\"1785211620907\", \"event_type\":\"price_change\"}","received_at":"2026-07-28T04:07:04.781226Z","schema_version":"clob-market-ws.price_change.v1","sequence":null,"server_hash":null,"server_timestamp":"1785211620907","session_id":"2d607381e3054cee91998cdf45a4231c","source":"clob_market_ws"},"received_at":"2026-07-28T04:07:04.781226Z","record_id":"0ca5552fddbee62b3d603b64fc5a33bc06753c58883ec483985cf71fadc7599d","schema_fingerprint":"4aa3821a28b0b7c2400bc59aba4bcc0a76e971dadd19610d3ad38c768e124dc7","schema_version":"edge-lab-recorder.raw.v1","sequence":null,"source":"clob_market_ws"}
{"event_at":"2026-07-28T04:07:00.907000Z","event_fingerprint":"d2e9f9c8a89bba94435b34407bfececb63760a90aabfa7d28905c5cf7ad058f4","payload":{"connection_id":"f6725804f86a4c4eb588e4d5ed7db029","event_at":"2026-07-28T04:07:00.907000Z","event_type":"price_change","frame_hash":"0d8da3842751657f54a0df8a37e4dd04cb91daa6e4d2e8595a2d788a1a02ae4b","frame_index":0,"kind":"data","monotonic_ns":313607835863250,"payload":{"event_type":"price_change","market":"0xd412ce774cfcf8dc9f71164aac78783978aac7b03871702a3b8a481bd9dc9688","price_changes":[{"asset_id":"107603864457683460275633293642179940881969192120168665300712204232021063124301","best_ask":"0.64","best_bid":"0.63","hash":"1e7d4505da7f3f181b059f0a2bba8a31dfbd2982","price":"0.49","side":"BUY","size":"35"},{"asset_id":"96600821790790307414914106093858868634329285205417149685270682748367152458577","best_ask":"0.37","best_bid":"0.36","hash":"54cfcec366e75ff751fc55563f975906a8b75ef2","price":"0.51","side":"SELL","size":"35"}],"timestamp":"1785211620907"},"payload_hash":"af8b77ed6d51bd94e51ac01d645c44c9d9f02e0042ab7143ae0c0ad0aa69cf9f","raw_frame":"{\"market\":\"0xd412ce774cfcf8dc9f71164aac78783978aac7b03871702a3b8a481bd9dc9688\", \"price_changes\":[{\"asset_id\":\"107603864457683460275633293642179940881969192120168665300712204232021063124301\", \"price\":\"0.49\", \"size\":\"35\", \"side\":\"BUY\", \"hash\":\"1e7d4505da7f3f181b059f0a2bba8a31dfbd2982\", \"best_bid\":\"0.63\", \"best_ask\":\"0.64\"}, {\"asset_id\":\"96600821790790307414914106093858868634329285205417149685270682748367152458577\", \"price\":\"0.51\", \"size\":\"35\", \"side\":\"SELL\", \"hash\":\"54cfcec366e75ff751fc55563f975906a8b75ef2\", \"best_bid\":\"0.36\", \"best_ask\":\"0.37\"}], \"timestamp\":\"1785211620907\", \"event_type\":\"price_change\"}","received_at":"2026-07-28T04:07:04.784809Z","schema_version":"clob-market-ws.price_change.v1","sequence":null,"server_hash":null,"server_timestamp":"1785211620907","session_id":"2d607381e3054cee91998cdf45a4231c","source":"clob_market_ws"},"received_at":"2026-07-28T04:07:04.784809Z","record_id":"bdd5b636a30a50a4522bd59ef3d5de23cda2684d2c3b9d6ce833d9067379bb57","schema_fingerprint":"4aa3821a28b0b7c2400bc59aba4bcc0a76e971dadd19610d3ad38c768e124dc7","schema_version":"edge-lab-recorder.raw.v1","sequence":null,"source":"clob_market_ws"}
{"event_at":"2026-07-28T04:07:00.908000Z","event_fingerprint":"b3c4f48600fff5c22688b4967d6840bf58c6cfaa79ccd5cb73ceb542e990c254","payload":{"connection_id":"f6725804f86a4c4eb588e4d5ed7db029","event_at":"2026-07-28T04:07:00.908000Z","event_type":"price_change","frame_hash":"4dd6a65cf8ae411df08f489b3e3872b7131bbe7eceb0edcd8bc083a246bb8521","frame_index":0,"kind":"data","monotonic_ns":313607842627541,"payload":{"event_type":"price_change","market":"0xd412ce774cfcf8dc9f71164aac78783978aac7b03871702a3b8a481bd9dc9688","price_changes":[{"asset_id":"107603864457683460275633293642179940881969192120168665300712204232021063124301","best_ask":"0.64","best_bid":"0.63","hash":"cf7feae39127e968da2fd30326042185ae35063f","price":"0.61","side":"BUY","size":"41"},{"asset_id":"96600821790790307414914106093858868634329285205417149685270682748367152458577","best_ask":"0.37","best_bid":"0.36","hash":"19e8948af7ff2b628f593ae4ce1740f00f7ba884","price":"0.39","side":"SELL","size":"41"}],"timestamp":"1785211620908"},"payload_hash":"bd6b43f259dec2fea552b4e891e3bdc74aa3b9c6da0f0f234554ec65774dac21","raw_frame":"{\"market\":\"0xd412ce774cfcf8dc9f71164aac78783978aac7b03871702a3b8a481bd9dc9688\", \"price_changes\":[{\"asset_id\":\"107603864457683460275633293642179940881969192120168665300712204232021063124301\", \"price\":\"0.61\", \"size\":\"41\", \"side\":\"BUY\", \"hash\":\"cf7feae39127e968da2fd30326042185ae35063f\", \"best_bid\":\"0.63\", \"best_ask\":\"0.64\"}, {\"asset_id\":\"96600821790790307414914106093858868634329285205417149685270682748367152458577\", \"price\":\"0.39\", \"size\":\"41\", \"side\":\"SELL\", \"hash\":\"19e8948af7ff2b628f593ae4ce1740f00f7ba884\", \"best_bid\":\"0.36\", \"best_ask\":\"0.37\"}], \"timestamp\":\"1785211620908\", \"event_type\":\"price_change\"}","received_at":"2026-07-28T04:07:04.791560Z","schema_version":"clob-market-ws.price_change.v1","sequence":null,"server_hash":null,"server_timestamp":"1785211620908","session_id":"2d607381e3054cee91998cdf45a4231c","source":"clob_market_ws"},"received_at":"2026-07-28T04:07:04.791560Z","record_id":"963e8334b599dfec6a88ba6cef4d088c93d06d4a3d82490c9a29d61406d62ecd","schema_fingerprint":"4aa3821a28b0b7c2400bc59aba4bcc0a76e971dadd19610d3ad38c768e124dc7","schema_version":"edge-lab-recorder.raw.v1","sequence":null,"source":"clob_market_ws"}
{"event_at":"2026-07-28T04:07:00.909000Z","event_fingerprint":"bd0b885b35a3dcb6b7045cfc9dcc88a2f90a6e4242be145b38c151b0d305bbc8","payload":{"connection_id":"f6725804f86a4c4eb588e4d5ed7db029","event_at":"2026-07-28T04:07:00.909000Z","event_type":"price_change","frame_hash":"1c2c661f64f79e0ca37949843c7ebf55ecd4ffdaf3f11e3d03a8392ff714a18b","frame_index":0,"kind":"data","monotonic_ns":313607849972500,"payload":{"event_type":"price_change","market":"0xd412ce774cfcf8dc9f71164aac78783978aac7b03871702a3b8a481bd9dc9688","price_changes":[{"asset_id":"107603864457683460275633293642179940881969192120168665300712204232021063124301","best_ask":"0.64","best_bid":"0.63","hash":"9c6d060b7c8c2c08bee236b475b994f81fb61349","price":"0.53","side":"BUY","size":"55.01"},{"asset_id":"96600821790790307414914106093858868634329285205417149685270682748367152458577","best_ask":"0.37","best_bid":"0.36","hash":"9bf7ed176c71c013c548de8a05c45d5a1440c30f","price":"0.47","side":"SELL","size":"55.01"}],"timestamp":"1785211620909"},"payload_hash":"b8bf3fce659db9de1cc426128689713de26d83f7a19ceefcd6b5812ed26ccd6c","raw_frame":"{\"market\":\"0xd412ce774cfcf8dc9f71164aac78783978aac7b03871702a3b8a481bd9dc9688\", \"price_changes\":[{\"asset_id\":\"107603864457683460275633293642179940881969192120168665300712204232021063124301\", \"price\":\"0.53\", \"size\":\"55.01\", \"side\":\"BUY\", \"hash\":\"9c6d060b7c8c2c08bee236b475b994f81fb61349\", \"best_bid\":\"0.63\", \"best_ask\":\"0.64\"}, {\"asset_id\":\"96600821790790307414914106093858868634329285205417149685270682748367152458577\", \"price\":\"0.47\", \"size\":\"55.01\", \"side\":\"SELL\", \"hash\":\"9bf7ed176c71c013c548de8a05c45d5a1440c30f\", \"best_bid\":\"0.36\", \"best_ask\":\"0.37\"}], \"timestamp\":\"1785211620909\", \"event_type\":\"price_change\"}","received_at":"2026-07-28T04:07:04.798907Z","schema_version":"clob-market-ws.price_change.v1","sequence":null,"server_hash":null,"server_timestamp":"1785211620909","session_id":"2d607381e3054cee91998cdf45a4231c","source":"clob_market_ws"},"received_at":"2026-07-28T04:07:04.798907Z","record_id":"811d93ed2ebb3b5f479532e0f55882438de7d1aab8c7d364f9f914e4fa622ee7","schema_fingerprint":"4aa3821a28b0b7c2400bc59aba4bcc0a76e971dadd19610d3ad38c768e124dc7","schema_version":"edge-lab-recorder.raw.v1","sequence":null,"source":"clob_market_ws"}
{"event_at":"2026-07-28T04:07:00.914000Z","event_fingerprint":"70ff19a1c078aa0c5126b666a21b93206e6dc611f068ab616f097fec9a3c87ef","payload":{"connection_id":"f6725804f86a4c4eb588e4d5ed7db029","event_at":"2026-07-28T04:07:00.914000Z","event_type":"price_change","frame_hash":"8aaa9db044b9b47767eb6b1166c4f665c8b6a7840b4b694fe72ec4d00cfc7c06","frame_index":0,"kind":"data","monotonic_ns":313607854457250,"payload":{"event_type":"price_change","market":"0xd412ce774cfcf8dc9f71164aac78783978aac7b03871702a3b8a481bd9dc9688","price_changes":[{"asset_id":"107603864457683460275633293642179940881969192120168665300712204232021063124301","best_ask":"0.64","best_bid":"0.63","hash":"1acc14f353246760c977b21dd48041ca72ee5af0","price":"0.67","side":"SELL","size":"42.6"},{"asset_id":"96600821790790307414914106093858868634329285205417149685270682748367152458577","best_ask":"0.37","best_bid":"0.36","hash":"da6328c452de3755a6f578a7536fe4aa23f3e8c7","price":"0.33","side":"BUY","size":"42.6"}],"timestamp":"1785211620914"},"payload_hash":"066c07290f47fbf3bc8e8e857ec410f3813d9141ef6e73708dde992dbb0a5aeb","raw_frame":"{\"market\":\"0xd412ce774cfcf8dc9f71164aac78783978aac7b03871702a3b8a481bd9dc9688\", \"price_changes\":[{\"asset_id\":\"107603864457683460275633293642179940881969192120168665300712204232021063124301\", \"price\":\"0.67\", \"size\":\"42.6\", \"side\":\"SELL\", \"hash\":\"1acc14f353246760c977b21dd48041ca72ee5af0\", \"best_bid\":\"0.63\", \"best_ask\":\"0.64\"}, {\"asset_id\":\"96600821790790307414914106093858868634329285205417149685270682748367152458577\", \"price\":\"0.33\", \"size\":\"42.6\", \"side\":\"BUY\", \"hash\":\"da6328c452de3755a6f578a7536fe4aa23f3e8c7\", \"best_bid\":\"0.36\", \"best_ask\":\"0.37\"}], \"timestamp\":\"1785211620914\", \"event_type\":\"price_change\"}","received_at":"2026-07-28T04:07:04.803390Z","schema_version":"clob-market-ws.price_change.v1","sequence":null,"server_hash":null,"server_timestamp":"1785211620914","session_id":"2d607381e3054cee91998cdf45a4231c","source":"clob_market_ws"},"received_at":"2026-07-28T04:07:04.803390Z","record_id":"00964b1d2c2c2febc70e18dac80e96a6efda9ec83ab6484792090e432a949911","schema_fingerprint":"4aa3821a28b0b7c2400bc59aba4bcc0a76e971dadd19610d3ad38c768e124dc7","schema_version":"edge-lab-recorder.raw.v1","sequence":null,"source":"clob_market_ws"}
{"event_at":"2026-07-28T04:07:00.915000Z","event_fingerprint":"809230acd6e16b643ce3decac663d47bed69ef6da1c8f670727fefc4c41f0637","payload":{"connection_id":"f6725804f86a4c4eb588e4d5ed7db029","event_at":"2026-07-28T04:07:00.915000Z","event_type":"price_change","frame_hash":"bb6d9367c76eb37f66ed4c6bc54b5f9bf692bb0ae2170e29c59f07f0b7d3bfb7","frame_index":0,"kind":"data","monotonic_ns":313607862231666,"payload":{"event_type":"price_change","market":"0xd412ce774cfcf8dc9f71164aac78783978aac7b03871702a3b8a481bd9dc9688","price_changes":[{"asset_id":"96600821790790307414914106093858868634329285205417149685270682748367152458577","best_ask":"0.37","best_bid":"0.36","hash":"4d5e746603af9d938a565060854aa4d19c359058","price":"0.38","side":"SELL","size":"56"},{"asset_id":"107603864457683460275633293642179940881969192120168665300712204232021063124301","best_ask":"0.64","best_bid":"0.63","hash":"9a8871dcd0f6d31db5fc6251b8ccc652fdf008bd","price":"0.62","side":"BUY","size":"56"}],"timestamp":"1785211620915"},"payload_hash":"e9bf5991ca537c8d3548e06fc27adad84ac9c5eb9b2c7e4c3807925931aeb417","raw_frame":"{\"market\":\"0xd412ce774cfcf8dc9f71164aac78783978aac7b03871702a3b8a481bd9dc9688\", \"price_changes\":[{\"asset_id\":\"96600821790790307414914106093858868634329285205417149685270682748367152458577\", \"price\":\"0.38\", \"size\":\"56\", \"side\":\"SELL\", \"hash\":\"4d5e746603af9d938a565060854aa4d19c359058\", \"best_bid\":\"0.36\", \"best_ask\":\"0.37\"}, {\"asset_id\":\"107603864457683460275633293642179940881969192120168665300712204232021063124301\", \"price\":\"0.62\", \"size\":\"56\", \"side\":\"BUY\", \"hash\":\"9a8871dcd0f6d31db5fc6251b8ccc652fdf008bd\", \"best_bid\":\"0.63\", \"best_ask\":\"0.64\"}], \"timestamp\":\"1785211620915\", \"event_type\":\"price_change\"}","received_at":"2026-07-28T04:07:04.811169Z","schema_version":"clob-market-ws.price_change.v1","sequence":null,"server_hash":null,"server_timestamp":"1785211620915","session_id":"2d607381e3054cee91998cdf45a4231c","source":"clob_market_ws"},"received_at":"2026-07-28T04:07:04.811169Z","record_id":"65eb48f7ecac66bf84527437b8c6899227ffbb9e237d32f5a8049d5be61ca121","schema_fingerprint":"4aa3821a28b0b7c2400bc59aba4bcc0a76e971dadd19610d3ad38c768e124dc7","schema_version":"edge-lab-recorder.raw.v1","sequence":null,"source":"clob_market_ws"}
{"event_at":"2026-07-28T04:07:00.916000Z","event_fingerprint":"3e837bdb7da80d34ac0487d10653a5a471fc9ff2dc8edad71fb5875496b18380","payload":{"connection_id":"f6725804f86a4c4eb588e4d5ed7db029","event_at":"2026-07-28T04:07:00.916000Z","event_type":"price_change","frame_hash":"bf546fcf2d4c31b2eb479cb8273ba0dae1c3adc8676a32f92cb101438c067e61","frame_index":0,"kind":"data","monotonic_ns":313607870020833,"payload":{"event_type":"price_change","market":"0xd412ce774cfcf8dc9f71164aac78783978aac7b03871702a3b8a481bd9dc9688","price_changes":[{"asset_id":"96600821790790307414914106093858868634329285205417149685270682748367152458577","best_ask":"0.37","best_bid":"0.36","hash":"8983b02f66eb48baa1110206a6112d9a669708a2","price":"0.27","side":"BUY","size":"41.38"},{"asset_id":"107603864457683460275633293642179940881969192120168665300712204232021063124301","best_ask":"0.64","best_bid":"0.63","hash":"028c5da5f33c07e9ca81c375aeff4c2ec91f9501","price":"0.73","side":"SELL","size":"41.38"}],"timestamp":"1785211620916"},"payload_hash":"913bca619feffee9668e6a04f6d6b8db514b3e191d275119b240f29b35aecab7","raw_frame":"{\"market\":\"0xd412ce774cfcf8dc9f71164aac78783978aac7b03871702a3b8a481bd9dc9688\", \"price_changes\":[{\"asset_id\":\"96600821790790307414914106093858868634329285205417149685270682748367152458577\", \"price\":\"0.27\", \"size\":\"41.38\", \"side\":\"BUY\", \"hash\":\"8983b02f66eb48baa1110206a6112d9a669708a2\", \"best_bid\":\"0.36\", \"best_ask\":\"0.37\"}, {\"asset_id\":\"107603864457683460275633293642179940881969192120168665300712204232021063124301\", \"price\":\"0.73\", \"size\":\"41.38\", \"side\":\"SELL\", \"hash\":\"028c5da5f33c07e9ca81c375aeff4c2ec91f9501\", \"best_bid\":\"0.63\", \"best_ask\":\"0.64\"}], \"timestamp\":\"1785211620916\", \"event_type\":\"price_change\"}","received_at":"2026-07-28T04:07:04.818960Z","schema_version":"clob-market-ws.price_change.v1","sequence":null,"server_hash":null,"server_timestamp":"1785211620916","session_id":"2d607381e3054cee91998cdf45a4231c","source":"clob_market_ws"},"received_at":"2026-07-28T04:07:04.818960Z","record_id":"42798bc912dcb1ec5afb74dc41da8c0bb0fbd30a49d37bbae34bfe4449b7e900","schema_fingerprint":"4aa3821a28b0b7c2400bc59aba4bcc0a76e971dadd19610d3ad38c768e124dc7","schema_version":"edge-lab-recorder.raw.v1","sequence":null,"source":"clob_market_ws"}
{"event_at":"2026-07-28T04:07:00.916000Z","event_fingerprint":"431e2612597515f497983ed812f3c8ce4336c704fc938d81a65ecc30b2c25764","payload":{"connection_id":"f6725804f86a4c4eb588e4d5ed7db029","event_at":"2026-07-28T04:07:00.916000Z","event_type":"price_change","frame_hash":"0529196847a14138936f5250d7b91863b6e924f4854dd9b7044b2ab474044ad6","frame_index":0,"kind":"data","monotonic_ns":313607875084208,"payload":{"event_type":"price_change","market":"0xd412ce774cfcf8dc9f71164aac78783978aac7b03871702a3b8a481bd9dc9688","price_changes":[{"asset_id":"107603864457683460275633293642179940881969192120168665300712204232021063124301","best_ask":"0.64","best_bid":"0.63","hash":"0e70accfbac1991664178559d93c51d19427f3a2","price":"0.6","side":"BUY","size":"46"},{"asset_id":"96600821790790307414914106093858868634329285205417149685270682748367152458577","best_ask":"0.37","best_bid":"0.36","hash":"a1ae4790d5f2465d88b0f7f678a18fc4c05d7a6a","price":"0.4","side":"SELL","size":"46"}],"timestamp":"1785211620916"},"payload_hash":"df1b746c7949ae9173a2b2af02a7bcd774648a568a19f9d7ba9be41c8d3e4afb","raw_frame":"{\"market\":\"0xd412ce774cfcf8dc9f71164aac78783978aac7b03871702a3b8a481bd9dc9688\", \"price_changes\":[{\"asset_id\":\"107603864457683460275633293642179940881969192120168665300712204232021063124301\", \"price\":\"0.6\", \"size\":\"46\", \"side\":\"BUY\", \"hash\":\"0e70accfbac1991664178559d93c51d19427f3a2\", \"best_bid\":\"0.63\", \"best_ask\":\"0.64\"}, {\"asset_id\":\"96600821790790307414914106093858868634329285205417149685270682748367152458577\", \"price\":\"0.4\", \"size\":\"46\", \"side\":\"SELL\", \"hash\":\"a1ae4790d5f2465d88b0f7f678a18fc4c05d7a6a\", \"best_bid\":\"0.36\", \"best_ask\":\"0.37\"}], \"timestamp\":\"1785211620916\", \"event_type\":\"price_change\"}","received_at":"2026-07-28T04:07:04.824025Z","schema_version":"clob-market-ws.price_change.v1","sequence":null,"server_hash":null,"server_timestamp":"1785211620916","session_id":"2d607381e3054cee91998cdf45a4231c","source":"clob_market_ws"},"received_at":"2026-07-28T04:07:04.824025Z","record_id":"6719729528b9f91f79a60640e5f04bd802dd9d5300ddad2c2caf0eb8f35b993c","schema_fingerprint":"4aa3821a28b0b7c2400bc59aba4bcc0a76e971dadd19610d3ad38c768e124dc7","schema_version":"edge-lab-recorder.raw.v1","sequence":null,"source":"clob_market_ws"}
{"event_at":"2026-07-28T04:07:00.920000Z","event_fingerprint":"ac2b04885d069959149b65ed8ea30b57a40ee3e9fde499a4078d24454811a550","payload":{"connection_id":"f6725804f86a4c4eb588e4d5ed7db029","event_at":"2026-07-28T04:07:00.920000Z","event_type":"price_change","frame_hash":"bdf8b3e17ea11532fc5ba35187d9f635e165aa063b719efa8c1df70912ca163d","frame_index":0,"kind":"data","monotonic_ns":313607879669291,"payload":{"event_type":"price_change","market":"0xd412ce774cfcf8dc9f71164aac78783978aac7b03871702a3b8a481bd9dc9688","price_changes":[{"asset_id":"107603864457683460275633293642179940881969192120168665300712204232021063124301","best_ask":"0.64","best_bid":"0.63","hash":"6d1cc26e8855f967e53089ce3f025b1fdc88e038","price":"0.68","side":"SELL","size":"83.62"},{"asset_id":"96600821790790307414914106093858868634329285205417149685270682748367152458577","best_ask":"0.37","best_bid":"0.36","hash":"e0fc6299c3e1ccd3de558eb2cae2d04aaeb020fd","price":"0.32","side":"BUY","size":"83.62"}],"timestamp":"1785211620920"},"payload_hash":"500c23f1f7658df4c0d4747da70da438f4dd239002324921ef348ab14b89a7f1","raw_frame":"{\"market\":\"0xd412ce774cfcf8dc9f71164aac78783978aac7b03871702a3b8a481bd9dc9688\", \"price_changes\":[{\"asset_id\":\"107603864457683460275633293642179940881969192120168665300712204232021063124301\", \"price\":\"0.68\", \"size\":\"83.62\", \"side\":\"SELL\", \"hash\":\"6d1cc26e8855f967e53089ce3f025b1fdc88e038\", \"best_bid\":\"0.63\", \"best_ask\":\"0.64\"}, {\"asset_id\":\"96600821790790307414914106093858868634329285205417149685270682748367152458577\", \"price\":\"0.32\", \"size\":\"83.62\", \"side\":\"BUY\", \"hash\":\"e0fc6299c3e1ccd3de558eb2cae2d04aaeb020fd\", \"best_bid\":\"0.36\", \"best_ask\":\"0.37\"}], \"timestamp\":\"1785211620920\", \"event_type\":\"price_change\"}","received_at":"2026-07-28T04:07:04.828609Z","schema_version":"clob-market-ws.price_change.v1","sequence":null,"server_hash":null,"server_timestamp":"1785211620920","session_id":"2d607381e3054cee91998cdf45a4231c","source":"clob_market_ws"},"received_at":"2026-07-28T04:07:04.828609Z","record_id":"a2b62e499c60c239b3dfd23618bab616891c8d6d455501f639e062b31387d004","schema_fingerprint":"4aa3821a28b0b7c2400bc59aba4bcc0a76e971dadd19610d3ad38c768e124dc7","schema_version":"edge-lab-recorder.raw.v1","sequence":null,"source":"clob_market_ws"}
{"event_at":"2026-07-28T04:07:00.922000Z","event_fingerprint":"f32206cb96cc6154af05ed494d7fe22f620e5b62e4d05775d080e4cfaff261f8","payload":{"connection_id":"f6725804f86a4c4eb588e4d5ed7db029","event_at":"2026-07-28T04:07:00.922000Z","event_type":"price_change","frame_hash":"4871e68df80b29b8bcbd22924583a278319db81f2cd83275b4b4514194a65b2e","frame_index":0,"kind":"data","monotonic_ns":313607884228791,"payload":{"event_type":"price_change","market":"0xd412ce774cfcf8dc9f71164aac78783978aac7b03871702a3b8a481bd9dc9688","price_changes":[{"asset_id":"96600821790790307414914106093858868634329285205417149685270682748367152458577","best_ask":"0.37","best_bid":"0.36","hash":"c329ee26ff0de6c21b157d64dec49fc9d636ef2c","price":"0.37","side":"SELL","size":"19"},{"asset_id":"107603864457683460275633293642179940881969192120168665300712204232021063124301","best_ask":"0.64","best_bid":"0.63","hash":"7de72ce88dc124fa586363ed763e5cce218480ae","price":"0.63","side":"BUY","size":"19"}],"timestamp":"1785211620922"},"payload_hash":"cde79980ed7c673d0cd205f54a560f3c6d7a314de8995811b5b5c575d1d7c21c","raw_frame":"{\"market\":\"0xd412ce774cfcf8dc9f71164aac78783978aac7b03871702a3b8a481bd9dc9688\", \"price_changes\":[{\"asset_id\":\"96600821790790307414914106093858868634329285205417149685270682748367152458577\", \"price\":\"0.37\", \"size\":\"19\", \"side\":\"SELL\", \"hash\":\"c329ee26ff0de6c21b157d64dec49fc9d636ef2c\", \"best_bid\":\"0.36\", \"best_ask\":\"0.37\"}, {\"asset_id\":\"107603864457683460275633293642179940881969192120168665300712204232021063124301\", \"price\":\"0.63\", \"size\":\"19\", \"side\":\"BUY\", \"hash\":\"7de72ce88dc124fa586363ed763e5cce218480ae\", \"best_bid\":\"0.63\", \"best_ask\":\"0.64\"}], \"timestamp\":\"1785211620922\", \"event_type\":\"price_change\"}","received_at":"2026-07-28T04:07:04.833169Z","schema_version":"clob-market-ws.price_change.v1","sequence":null,"server_hash":null,"server_timestamp":"1785211620922","session_id":"2d607381e3054cee91998cdf45a4231c","source":"clob_market_ws"},"received_at":"2026-07-28T04:07:04.833169Z","record_id":"8f96ddd6e63f6c4ae0ce7d4f459cea8a8bb860f070cb58d85972d40c54689975","schema_fingerprint":"4aa3821a28b0b7c2400bc59aba4bcc0a76e971dadd19610d3ad38c768e124dc7","schema_version":"edge-lab-recorder.raw.v1","sequence":null,"source":"clob_market_ws"}
{"event_at":"2026-07-28T04:07:00.929000Z","event_fingerprint":"274aa8acfc620492e538686c769bfd1a4622c0080813322c3af26722dd2acd51","payload":{"connection_id":"f6725804f86a4c4eb588e4d5ed7db029","event_at":"2026-07-28T04:07:00.929000Z","event_type":"price_change","frame_hash":"88bdc01020d04bdd7462f27535e01c49cb9ad49244297313656bb7a7786b4cb1","frame_index":0,"kind":"data","monotonic_ns":313607887412833,"payload":{"event_type":"price_change","market":"0xd412ce774cfcf8dc9f71164aac78783978aac7b03871702a3b8a481bd9dc9688","price_changes":[{"asset_id":"96600821790790307414914106093858868634329285205417149685270682748367152458577","best_ask":"0.37","best_bid":"0.36","hash":"b3e10225c351624293bcd2310e36528548454aab","price":"0.25","side":"BUY","size":"96.31"},{"asset_id":"107603864457683460275633293642179940881969192120168665300712204232021063124301","best_ask":"0.64","best_bid":"0.63","hash":"6442fca5f170748e6362b60a3e5a9cfee7d72054","price":"0.75","side":"SELL","size":"96.31"}],"timestamp":"1785211620929"},"payload_hash":"5e40df0dc087499d6fc824eebfe2782d196e52cb68cf21ad4401f2e45642ae0f","raw_frame":"{\"market\":\"0xd412ce774cfcf8dc9f71164aac78783978aac7b03871702a3b8a481bd9dc9688\", \"price_changes\":[{\"asset_id\":\"96600821790790307414914106093858868634329285205417149685270682748367152458577\", \"price\":\"0.25\", \"size\":\"96.31\", \"side\":\"BUY\", \"hash\":\"b3e10225c351624293bcd2310e36528548454aab\", \"best_bid\":\"0.36\", \"best_ask\":\"0.37\"}, {\"asset_id\":\"107603864457683460275633293642179940881969192120168665300712204232021063124301\", \"price\":\"0.75\", \"size\":\"96.31\", \"side\":\"SELL\", \"hash\":\"6442fca5f170748e6362b60a3e5a9cfee7d72054\", \"best_bid\":\"0.63\", \"best_ask\":\"0.64\"}], \"timestamp\":\"1785211620929\", \"event_type\":\"price_change\"}","received_at":"2026-07-28T04:07:04.836353Z","schema_version":"clob-market-ws.price_change.v1","sequence":null,"server_hash":null,"server_timestamp":"1785211620929","session_id":"2d607381e3054cee91998cdf45a4231c","source":"clob_market_ws"},"received_at":"2026-07-28T04:07:04.836353Z","record_id":"fd930e58815e0c5458273a60f876069594050d68170ec19c34b6e1f378060d32","schema_fingerprint":"4aa3821a28b0b7c2400bc59aba4bcc0a76e971dadd19610d3ad38c768e124dc7","schema_version":"edge-lab-recorder.raw.v1","sequence":null,"source":"clob_market_ws"}
{"event_at":"2026-07-28T04:07:00.933000Z","event_fingerprint":"a3ec5e5531eddcabf094fc45bec9269a2c26c1ca66b8b4026c23e8ee97419ab7","payload":{"connection_id":"f6725804f86a4c4eb588e4d5ed7db029","event_at":"2026-07-28T04:07:00.933000Z","event_type":"price_change","frame_hash":"6dc0ac1a9ce55a58a894e6316cd7ccbda627f089204d1836effa2602b8a39350","frame_index":0,"kind":"data","monotonic_ns":313607893183000,"payload":{"event_type":"price_change","market":"0xd412ce774cfcf8dc9f71164aac78783978aac7b03871702a3b8a481bd9dc9688","price_changes":[{"asset_id":"107603864457683460275633293642179940881969192120168665300712204232021063124301","best_ask":"0.64","best_bid":"0.63","hash":"896c1f1aaee1f2bdde77f535b9d7b1d49eb04886","price":"0.63","side":"BUY","size":"13"},{"asset_id":"96600821790790307414914106093858868634329285205417149685270682748367152458577","best_ask":"0.37","best_bid":"0.36","hash":"092594ae3625b3ea59ed611f04e9f6eb28cfcaf0","price":"0.37","side":"SELL","size":"13"}],"timestamp":"1785211620933"},"payload_hash":"e09705a0d7588f600d2e14c2873d76d1129a879bac7f3bd86429da0c40bed239","raw_frame":"{\"market\":\"0xd412ce774cfcf8dc9f71164aac78783978aac7b03871702a3b8a481bd9dc9688\", \"price_changes\":[{\"asset_id\":\"107603864457683460275633293642179940881969192120168665300712204232021063124301\", \"price\":\"0.63\", \"size\":\"13\", \"side\":\"BUY\", \"hash\":\"896c1f1aaee1f2bdde77f535b9d7b1d49eb04886\", \"best_bid\":\"0.63\", \"best_ask\":\"0.64\"}, {\"asset_id\":\"96600821790790307414914106093858868634329285205417149685270682748367152458577\", \"price\":\"0.37\", \"size\":\"13\", \"side\":\"SELL\", \"hash\":\"092594ae3625b3ea59ed611f04e9f6eb28cfcaf0\", \"best_bid\":\"0.36\", \"best_ask\":\"0.37\"}], \"timestamp\":\"1785211620933\", \"event_type\":\"price_change\"}","received_at":"2026-07-28T04:07:04.842124Z","schema_version":"clob-market-ws.price_change.v1","sequence":null,"server_hash":null,"server_timestamp":"1785211620933","session_id":"2d607381e3054cee91998cdf45a4231c","source":"clob_market_ws"},"received_at":"2026-07-28T04:07:04.842124Z","record_id":"8285ede22d60d41e6779c3efe1b20911ffa9d6a47faab4e24ea6183fdcffa327","schema_fingerprint":"4aa3821a28b0b7c2400bc59aba4bcc0a76e971dadd19610d3ad38c768e124dc7","schema_version":"edge-lab-recorder.raw.v1","sequence":null,"source":"clob_market_ws"}
{"event_at":"2026-07-28T04:07:00.933000Z","event_fingerprint":"d68f36273cd6cab4483612f2cbaf915cb1bd2d0c2fbe819add891730316c4673","payload":{"connection_id":"f6725804f86a4c4eb588e4d5ed7db029","event_at":"2026-07-28T04:07:00.933000Z","event_type":"price_change","frame_hash":"104c674b371b555693967afd570d9f8e0e694e2e810613d82fae0731b3d554bb","frame_index":0,"kind":"data","monotonic_ns":313607898133875,"payload":{"event_type":"price_change","market":"0xd412ce774cfcf8dc9f71164aac78783978aac7b03871702a3b8a481bd9dc9688","price_changes":[{"asset_id":"96600821790790307414914106093858868634329285205417149685270682748367152458577","best_ask":"0.37","best_bid":"0.36","hash":"0ee501a2c459fca2498dc693ebfc1d0ad59bbc3d","price":"0.36","side":"BUY","size":"64"},{"asset_id":"107603864457683460275633293642179940881969192120168665300712204232021063124301","best_ask":"0.64","best_bid":"0.63","hash":"f0e7c930389c57950cb01c8f8dab43112eef666c","price":"0.64","side":"SELL","size":"64"}],"timestamp":"1785211620933"},"payload_hash":"3c22d012a74e23a5ea2928bd12127ab91a03b43575a2d593bafc4cf426587aaf","raw_frame":"{\"market\":\"0xd412ce774cfcf8dc9f71164aac78783978aac7b03871702a3b8a481bd9dc9688\", \"price_changes\":[{\"asset_id\":\"96600821790790307414914106093858868634329285205417149685270682748367152458577\", \"price\":\"0.36\", \"size\":\"64\", \"side\":\"BUY\", \"hash\":\"0ee501a2c459fca2498dc693ebfc1d0ad59bbc3d\", \"best_bid\":\"0.36\", \"best_ask\":\"0.37\"}, {\"asset_id\":\"107603864457683460275633293642179940881969192120168665300712204232021063124301\", \"price\":\"0.64\", \"size\":\"64\", \"side\":\"SELL\", \"hash\":\"f0e7c930389c57950cb01c8f8dab43112eef666c\", \"best_bid\":\"0.63\", \"best_ask\":\"0.64\"}], \"timestamp\":\"1785211620933\", \"event_type\":\"price_change\"}","received_at":"2026-07-28T04:07:04.847074Z","schema_version":"clob-market-ws.price_change.v1","sequence":null,"server_hash":null,"server_timestamp":"1785211620933","session_id":"2d607381e3054cee91998cdf45a4231c","source":"clob_market_ws"},"received_at":"2026-07-28T04:07:04.847074Z","record_id":"7c7bd4e57e2bd40996bc07c20c708e381de59a3dc6d149f1ac894a303ddc68fa","schema_fingerprint":"4aa3821a28b0b7c2400bc59aba4bcc0a76e971dadd19610d3ad38c768e124dc7","schema_version":"edge-lab-recorder.raw.v1","sequence":null,"source":"clob_market_ws"}
{"event_at":"2026-07-28T04:07:00.934000Z","event_fingerprint":"b079f8886d9ceccc7d00fe6d44129a4ea1fe5cb126e9f33dd69dff9cfd5a95d6","payload":{"connection_id":"f6725804f86a4c4eb588e4d5ed7db029","event_at":"2026-07-28T04:07:00.934000Z","event_type":"price_change","frame_hash":"57f2266db7cdcfc8087adeb8e457e962b4e05f4358d489f287a82d8af9cc48e2","frame_index":0,"kind":"data","monotonic_ns":313607904007416,"payload":{"event_type":"price_change","market":"0xd412ce774cfcf8dc9f71164aac78783978aac7b03871702a3b8a481bd9dc9688","price_changes":[{"asset_id":"107603864457683460275633293642179940881969192120168665300712204232021063124301","best_ask":"0.64","best_bid":"0.63","hash":"21c8e658a25ae6d70657e7c18c0413894de262cb","price":"0.01","side":"BUY","size":"5643.02"},{"asset_id":"96600821790790307414914106093858868634329285205417149685270682748367152458577","best_ask":"0.37","best_bid":"0.36","hash":"620e7732e16c531061f08dbf61378c19c124fb09","price":"0.99","side":"SELL","size":"5643.02"}],"timestamp":"1785211620934"},"payload_hash":"b00c74fc7385c1d72d89867b314ae13aed7f8b10764442b438027018a3469139","raw_frame":"{\"market\":\"0xd412ce774cfcf8dc9f71164aac78783978aac7b03871702a3b8a481bd9dc9688\", \"price_changes\":[{\"asset_id\":\"107603864457683460275633293642179940881969192120168665300712204232021063124301\", \"price\":\"0.01\", \"size\":\"5643.02\", \"side\":\"BUY\", \"hash\":\"21c8e658a25ae6d70657e7c18c0413894de262cb\", \"best_bid\":\"0.63\", \"best_ask\":\"0.64\"}, {\"asset_id\":\"96600821790790307414914106093858868634329285205417149685270682748367152458577\", \"price\":\"0.99\", \"size\":\"5643.02\", \"side\":\"SELL\", \"hash\":\"620e7732e16c531061f08dbf61378c19c124fb09\", \"best_bid\":\"0.36\", \"best_ask\":\"0.37\"}], \"timestamp\":\"1785211620934\", \"event_type\":\"price_change\"}","received_at":"2026-07-28T04:07:04.852948Z","schema_version":"clob-market-ws.price_change.v1","sequence":null,"server_hash":null,"server_timestamp":"1785211620934","session_id":"2d607381e3054cee91998cdf45a4231c","source":"clob_market_ws"},"received_at":"2026-07-28T04:07:04.852948Z","record_id":"db01e0da62b2cff8a91905df6202ebc334c7d292ccc09322901b294d3c81b26b","schema_fingerprint":"4aa3821a28b0b7c2400bc59aba4bcc0a76e971dadd19610d3ad38c768e124dc7","schema_version":"edge-lab-recorder.raw.v1","sequence":null,"source":"clob_market_ws"}
{"event_at":"2026-07-28T04:07:00.934000Z","event_fingerprint":"64ae0970dd9c7a3623d0024f7caec8e755bad087e5264263da41ad5828515699","payload":{"connection_id":"f6725804f86a4c4eb588e4d5ed7db029","event_at":"2026-07-28T04:07:00.934000Z","event_type":"price_change","frame_hash":"4e49679c916c64008b7650525c2466b6aa7f135a351cc1c6ff44097ba5f24605","frame_index":0,"kind":"data","monotonic_ns":313607909805375,"payload":{"event_type":"price_change","market":"0xd412ce774cfcf8dc9f71164aac78783978aac7b03871702a3b8a481bd9dc9688","price_changes":[{"asset_id":"107603864457683460275633293642179940881969192120168665300712204232021063124301","best_ask":"0.64","best_bid":"0.63","hash":"f3daf9ac6f1301cba2adcd6677dc76fe618725fd","price":"0.04","side":"BUY","size":"618.09"},{"asset_id":"96600821790790307414914106093858868634329285205417149685270682748367152458577","best_ask":"0.37","best_bid":"0.36","hash":"eb50f0ac5160028aa40397f1de022b06467dad8e","price":"0.96","side":"SELL","size":"618.09"}],"timestamp":"1785211620934"},"payload_hash":"6a37f691fe093747370cc9d489bb4fda9c44a96b69126d4d05ec1ac5cdffec8e","raw_frame":"{\"market\":\"0xd412ce774cfcf8dc9f71164aac78783978aac7b03871702a3b8a481bd9dc9688\", \"price_changes\":[{\"asset_id\":\"107603864457683460275633293642179940881969192120168665300712204232021063124301\", \"price\":\"0.04\", \"size\":\"618.09\", \"side\":\"BUY\", \"hash\":\"f3daf9ac6f1301cba2adcd6677dc76fe618725fd\", \"best_bid\":\"0.63\", \"best_ask\":\"0.64\"}, {\"asset_id\":\"96600821790790307414914106093858868634329285205417149685270682748367152458577\", \"price\":\"0.96\", \"size\":\"618.09\", \"side\":\"SELL\", \"hash\":\"eb50f0ac5160028aa40397f1de022b06467dad8e\", \"best_bid\":\"0.36\", \"best_ask\":\"0.37\"}], \"timestamp\":\"1785211620934\", \"event_type\":\"price_change\"}","received_at":"2026-07-28T04:07:04.858744Z","schema_version":"clob-market-ws.price_change.v1","sequence":null,"server_hash":null,"server_timestamp":"1785211620934","session_id":"2d607381e3054cee91998cdf45a4231c","source":"clob_market_ws"},"received_at":"2026-07-28T04:07:04.858744Z","record_id":"cecae1a09e05a5b79e26294e5eb1a9f266ec468b4b296b3ddb2ddf638fa56bb9","schema_fingerprint":"4aa3821a28b0b7c2400bc59aba4bcc0a76e971dadd19610d3ad38c768e124dc7","schema_version":"edge-lab-recorder.raw.v1","sequence":null,"source":"clob_market_ws"}
{"event_at":"2026-07-28T04:07:00.936000Z","event_fingerprint":"1463bc318997e5d7d3028d53e2eccc3b3d0225d70127ec72103df218cbf81dda","payload":{"connection_id":"f6725804f86a4c4eb588e4d5ed7db029","event_at":"2026-07-28T04:07:00.936000Z","event_type":"price_change","frame_hash":"9cbdd81dcdaa1afb34e7b131d0048fa24a3f29a2b51573d0f24e1737256da680","frame_index":0,"kind":"data","monotonic_ns":313607924471666,"payload":{"event_type":"price_change","market":"0xd412ce774cfcf8dc9f71164aac78783978aac7b03871702a3b8a481bd9dc9688","price_changes":[{"asset_id":"107603864457683460275633293642179940881969192120168665300712204232021063124301","best_ask":"0.64","best_bid":"0.63","hash":"7476de6066dd84bb0042cac1cf04c676c3c525de","price":"0.59","side":"BUY","size":"47"},{"asset_id":"96600821790790307414914106093858868634329285205417149685270682748367152458577","best_ask":"0.37","best_bid":"0.36","hash":"c817f56f62210533c47a973a0e580fe6163c86d4","price":"0.41","side":"SELL","size":"47"}],"timestamp":"1785211620936"},"payload_hash":"9155377e7dd70ad396b4a1666f2564ae7510714fd8cccb425df40642abde8426","raw_frame":"{\"market\":\"0xd412ce774cfcf8dc9f71164aac78783978aac7b03871702a3b8a481bd9dc9688\", \"price_changes\":[{\"asset_id\":\"107603864457683460275633293642179940881969192120168665300712204232021063124301\", \"price\":\"0.59\", \"size\":\"47\", \"side\":\"BUY\", \"hash\":\"7476de6066dd84bb0042cac1cf04c676c3c525de\", \"best_bid\":\"0.63\", \"best_ask\":\"0.64\"}, {\"asset_id\":\"96600821790790307414914106093858868634329285205417149685270682748367152458577\", \"price\":\"0.41\", \"size\":\"47\", \"side\":\"SELL\", \"hash\":\"c817f56f62210533c47a973a0e580fe6163c86d4\", \"best_bid\":\"0.36\", \"best_ask\":\"0.37\"}], \"timestamp\":\"1785211620936\", \"event_type\":\"price_change\"}","received_at":"2026-07-28T04:07:04.873412Z","schema_version":"clob-market-ws.price_change.v1","sequence":null,"server_hash":null,"server_timestamp":"1785211620936","session_id":"2d607381e3054cee91998cdf45a4231c","source":"clob_market_ws"},"received_at":"2026-07-28T04:07:04.873412Z","record_id":"d98f5adf0f09734b92a8bc031d94421ef2d89b6acc501eeff447cc4a2edaab24","schema_fingerprint":"4aa3821a28b0b7c2400bc59aba4bcc0a76e971dadd19610d3ad38c768e124dc7","schema_version":"edge-lab-recorder.raw.v1","sequence":null,"source":"clob_market_ws"}
{"event_at":"2026-07-28T04:07:00.944000Z","event_fingerprint":"8edd1dd25c128d317235f1583454051fc01e32e1b6ddbb012fcfc53bc789f905","payload":{"connection_id":"f6725804f86a4c4eb588e4d5ed7db029","event_at":"2026-07-28T04:07:00.944000Z","event_type":"price_change","frame_hash":"341f08cff328d06ea69f508bef6631d42d392f82a78fb974bcf3a533017d5f25","frame_index":0,"kind":"data","monotonic_ns":313607929029041,"payload":{"event_type":"price_change","market":"0xd412ce774cfcf8dc9f71164aac78783978aac7b03871702a3b8a481bd9dc9688","price_changes":[{"asset_id":"96600821790790307414914106093858868634329285205417149685270682748367152458577","best_ask":"0.37","best_bid":"0.36","hash":"23a6b546b6bccf0438d17d747b20f0f00b5f24b4","price":"0.36","side":"BUY","size":"74"},{"asset_id":"107603864457683460275633293642179940881969192120168665300712204232021063124301","best_ask":"0.64","best_bid":"0.63","hash":"734e01c04b60643b4533ddd32cc4bd03bf5a4552","price":"0.64","side":"SELL","size":"74"}],"timestamp":"1785211620944"},"payload_hash":"d60e8f607b50771b1e2aadd347e614196c90d667700fa4c08b20332c8bb20689","raw_frame":"{\"market\":\"0xd412ce774cfcf8dc9f71164aac78783978aac7b03871702a3b8a481bd9dc9688\", \"price_changes\":[{\"asset_id\":\"96600821790790307414914106093858868634329285205417149685270682748367152458577\", \"price\":\"0.36\", \"size\":\"74\", \"side\":\"BUY\", \"hash\":\"23a6b546b6bccf0438d17d747b20f0f00b5f24b4\", \"best_bid\":\"0.36\", \"best_ask\":\"0.37\"}, {\"asset_id\":\"107603864457683460275633293642179940881969192120168665300712204232021063124301\", \"price\":\"0.64\", \"size\":\"74\", \"side\":\"SELL\", \"hash\":\"734e01c04b60643b4533ddd32cc4bd03bf5a4552\", \"best_bid\":\"0.63\", \"best_ask\":\"0.64\"}], \"timestamp\":\"1785211620944\", \"event_type\":\"price_change\"}","received_at":"2026-07-28T04:07:04.877969Z","schema_version":"clob-market-ws.price_change.v1","sequence":null,"server_hash":null,"server_timestamp":"1785211620944","session_id":"2d607381e3054cee91998cdf45a4231c","source":"clob_market_ws"},"received_at":"2026-07-28T04:07:04.877969Z","record_id":"8408a75dfe344568f9a2def38b3dd364b6e97f67161b714cd2a4ec4f17c4289f","schema_fingerprint":"4aa3821a28b0b7c2400bc59aba4bcc0a76e971dadd19610d3ad38c768e124dc7","schema_version":"edge-lab-recorder.raw.v1","sequence":null,"source":"clob_market_ws"}
{"event_at":"2026-07-28T04:07:00.945000Z","event_fingerprint":"62bfa2ec7202c0914b94cbc0d7e6157d3b7e6cd8d95287ffa5c4e35e9172bec9","payload":{"connection_id":"f6725804f86a4c4eb588e4d5ed7db029","event_at":"2026-07-28T04:07:00.945000Z","event_type":"price_change","frame_hash":"fbc9bb518d3fb13033da528dcce82f52cbb5ca7e9b27ef082e0facb911577ecd","frame_index":0,"kind":"data","monotonic_ns":313607933882500,"payload":{"event_type":"price_change","market":"0xd412ce774cfcf8dc9f71164aac78783978aac7b03871702a3b8a481bd9dc9688","price_changes":[{"asset_id":"96600821790790307414914106093858868634329285205417149685270682748367152458577","best_ask":"0.37","best_bid":"0.36","hash":"bb4c221fa41b44ecd63bbdd8be8c7304ea4c5a5e","price":"0.3","side":"BUY","size":"55.33"},{"asset_id":"107603864457683460275633293642179940881969192120168665300712204232021063124301","best_ask":"0.64","best_bid":"0.63","hash":"8ff8648d07e98fc29e9551c173affba7e55d226d","price":"0.7","side":"SELL","size":"55.33"}],"timestamp":"1785211620945"},"payload_hash":"406bb922ccb59469b10d3284aca359beaa3aae981c494ad6ae17fad77547a9a4","raw_frame":"{\"market\":\"0xd412ce774cfcf8dc9f71164aac78783978aac7b03871702a3b8a481bd9dc9688\", \"price_changes\":[{\"asset_id\":\"96600821790790307414914106093858868634329285205417149685270682748367152458577\", \"price\":\"0.3\", \"size\":\"55.33\", \"side\":\"BUY\", \"hash\":\"bb4c221fa41b44ecd63bbdd8be8c7304ea4c5a5e\", \"best_bid\":\"0.36\", \"best_ask\":\"0.37\"}, {\"asset_id\":\"107603864457683460275633293642179940881969192120168665300712204232021063124301\", \"price\":\"0.7\", \"size\":\"55.33\", \"side\":\"SELL\", \"hash\":\"8ff8648d07e98fc29e9551c173affba7e55d226d\", \"best_bid\":\"0.63\", \"best_ask\":\"0.64\"}], \"timestamp\":\"1785211620945\", \"event_type\":\"price_change\"}","received_at":"2026-07-28T04:07:04.882821Z","schema_version":"clob-market-ws.price_change.v1","sequence":null,"server_hash":null,"server_timestamp":"1785211620945","session_id":"2d607381e3054cee91998cdf45a4231c","source":"clob_market_ws"},"received_at":"2026-07-28T04:07:04.882821Z","record_id":"4efaf3f65aabfe57baf965de0770c6e524e77bb27a06315e37e4afc18bd612cc","schema_fingerprint":"4aa3821a28b0b7c2400bc59aba4bcc0a76e971dadd19610d3ad38c768e124dc7","schema_version":"edge-lab-recorder.raw.v1","sequence":null,"source":"clob_market_ws"}
{"event_at":"2026-07-28T04:07:00.946000Z","event_fingerprint":"e812074376e520570384fccad53d54a21b0fa1a1da0265fb9ad1c64d3ff89577","payload":{"connection_id":"f6725804f86a4c4eb588e4d5ed7db029","event_at":"2026-07-28T04:07:00.946000Z","event_type":"price_change","frame_hash":"3ab93eaa77d2d3ec0a30c6344e2f735ebca71bf813c6e6170c7aa758a8c9d56f","frame_index":0,"kind":"data","monotonic_ns":313607938294333,"payload":{"event_type":"price_change","market":"0xd412ce774cfcf8dc9f71164aac78783978aac7b03871702a3b8a481bd9dc9688","price_changes":[{"asset_id":"96600821790790307414914106093858868634329285205417149685270682748367152458577","best_ask":"0.37","best_bid":"0.36","hash":"87313781375c551f7de1debded7178d8ad183dfc","price":"0.28","side":"BUY","size":"51"},{"asset_id":"107603864457683460275633293642179940881969192120168665300712204232021063124301","best_ask":"0.64","best_bid":"0.63","hash":"76ef8fd4795a49cbbec7ec05427cb0731a5c3216","price":"0.72","side":"SELL","size":"51"}],"timestamp":"1785211620946"},"payload_hash":"81770c632e933722aefa5f5eb4e73ef421ac5a344f8bf231371e89e1c7d54f56","raw_frame":"{\"market\":\"0xd412ce774cfcf8dc9f71164aac78783978aac7b03871702a3b8a481bd9dc9688\", \"price_changes\":[{\"asset_id\":\"96600821790790307414914106093858868634329285205417149685270682748367152458577\", \"price\":\"0.28\", \"size\":\"51\", \"side\":\"BUY\", \"hash\":\"87313781375c551f7de1debded7178d8ad183dfc\", \"best_bid\":\"0.36\", \"best_ask\":\"0.37\"}, {\"asset_id\":\"107603864457683460275633293642179940881969192120168665300712204232021063124301\", \"price\":\"0.72\", \"size\":\"51\", \"side\":\"SELL\", \"hash\":\"76ef8fd4795a49cbbec7ec05427cb0731a5c3216\", \"best_bid\":\"0.63\", \"best_ask\":\"0.64\"}], \"timestamp\":\"1785211620946\", \"event_type\":\"price_change\"}","received_at":"2026-07-28T04:07:04.887233Z","schema_version":"clob-market-ws.price_change.v1","sequence":null,"server_hash":null,"server_timestamp":"1785211620946","session_id":"2d607381e3054cee91998cdf45a4231c","source":"clob_market_ws"},"received_at":"2026-07-28T04:07:04.887233Z","record_id":"a84b6d7987ffbdb95599574204653e14f3e84aced5cca7e0e36c74a71927be0f","schema_fingerprint":"4aa3821a28b0b7c2400bc59aba4bcc0a76e971dadd19610d3ad38c768e124dc7","schema_version":"edge-lab-recorder.raw.v1","sequence":null,"source":"clob_market_ws"}
{"event_at":"2026-07-28T04:07:00.949000Z","event_fingerprint":"a660f623093c8109dd96486713d6bb4c073021fc7b1968025e0b016b4777a931","payload":{"connection_id":"f6725804f86a4c4eb588e4d5ed7db029","event_at":"2026-07-28T04:07:00.949000Z","event_type":"price_change","frame_hash":"1275809a6455153df7b8be0a7431d4c34d08de9aef06b9e1eca75341c0e3468c","frame_index":0,"kind":"data","monotonic_ns":313607942840666,"payload":{"event_type":"price_change","market":"0xd412ce774cfcf8dc9f71164aac78783978aac7b03871702a3b8a481bd9dc9688","price_changes":[{"asset_id":"107603864457683460275633293642179940881969192120168665300712204232021063124301","best_ask":"0.64","best_bid":"0.63","hash":"ff06e1ad61c61a4c46cb11b90a2cd158c90b7c96","price":"0.58","side":"BUY","size":"88"},{"asset_id":"96600821790790307414914106093858868634329285205417149685270682748367152458577","best_ask":"0.37","best_bid":"0.36","hash":"64783e02d2800a56c7db96db2d894c0bb387e468","price":"0.42","side":"SELL","size":"88"}],"timestamp":"1785211620949"},"payload_hash":"ad861bd7e5b93d9f7453c6f8888767b42224c1ebe1380095caf0ec698dd89fc5","raw_frame":"{\"market\":\"0xd412ce774cfcf8dc9f71164aac78783978aac7b03871702a3b8a481bd9dc9688\", \"price_changes\":[{\"asset_id\":\"107603864457683460275633293642179940881969192120168665300712204232021063124301\", \"price\":\"0.58\", \"size\":\"88\", \"side\":\"BUY\", \"hash\":\"ff06e1ad61c61a4c46cb11b90a2cd158c90b7c96\", \"best_bid\":\"0.63\", \"best_ask\":\"0.64\"}, {\"asset_id\":\"96600821790790307414914106093858868634329285205417149685270682748367152458577\", \"price\":\"0.42\", \"size\":\"88\", \"side\":\"SELL\", \"hash\":\"64783e02d2800a56c7db96db2d894c0bb387e468\", \"best_bid\":\"0.36\", \"best_ask\":\"0.37\"}], \"timestamp\":\"1785211620949\", \"event_type\":\"price_change\"}","received_at":"2026-07-28T04:07:04.891780Z","schema_version":"clob-market-ws.price_change.v1","sequence":null,"server_hash":null,"server_timestamp":"1785211620949","session_id":"2d607381e3054cee91998cdf45a4231c","source":"clob_market_ws"},"received_at":"2026-07-28T04:07:04.891780Z","record_id":"6cef98994c19a203d80570efd48a33bbd62ff3e825219fbb4bc0f5172edc6cc3","schema_fingerprint":"4aa3821a28b0b7c2400bc59aba4bcc0a76e971dadd19610d3ad38c768e124dc7","schema_version":"edge-lab-recorder.raw.v1","sequence":null,"source":"clob_market_ws"}
{"event_at":"2026-07-28T04:07:00.953000Z","event_fingerprint":"343ffaa1108c3c44aebec61d5122ec758d272ba949ca065d6f417c036d81a3a4","payload":{"connection_id":"f6725804f86a4c4eb588e4d5ed7db029","event_at":"2026-07-28T04:07:00.953000Z","event_type":"price_change","frame_hash":"f650329b2da8e8d71d5421cbd83cb88e86173e1c67ab6d2fd157f9813e89f07e","frame_index":0,"kind":"data","monotonic_ns":313607947339125,"payload":{"event_type":"price_change","market":"0xd412ce774cfcf8dc9f71164aac78783978aac7b03871702a3b8a481bd9dc9688","price_changes":[{"asset_id":"96600821790790307414914106093858868634329285205417149685270682748367152458577","best_ask":"0.37","best_bid":"0.36","hash":"b54c2e1463ea627b49c57e4b8daceaa66a9d661f","price":"0.28","side":"BUY","size":"58"},{"asset_id":"107603864457683460275633293642179940881969192120168665300712204232021063124301","best_ask":"0.64","best_bid":"0.63","hash":"59da303033cdbdb7b427d527980f6d9f89f85531","price":"0.72","side":"SELL","size":"58"}],"timestamp":"1785211620953"},"payload_hash":"216ccd13bf9c6ba269ea87ff1446006bc98cce744d7570bc33830244b187f4f1","raw_frame":"{\"market\":\"0xd412ce774cfcf8dc9f71164aac78783978aac7b03871702a3b8a481bd9dc9688\", \"price_changes\":[{\"asset_id\":\"96600821790790307414914106093858868634329285205417149685270682748367152458577\", \"price\":\"0.28\", \"size\":\"58\", \"side\":\"BUY\", \"hash\":\"b54c2e1463ea627b49c57e4b8daceaa66a9d661f\", \"best_bid\":\"0.36\", \"best_ask\":\"0.37\"}, {\"asset_id\":\"107603864457683460275633293642179940881969192120168665300712204232021063124301\", \"price\":\"0.72\", \"size\":\"58\", \"side\":\"SELL\", \"hash\":\"59da303033cdbdb7b427d527980f6d9f89f85531\", \"best_bid\":\"0.63\", \"best_ask\":\"0.64\"}], \"timestamp\":\"1785211620953\", \"event_type\":\"price_change\"}","received_at":"2026-07-28T04:07:04.896278Z","schema_version":"clob-market-ws.price_change.v1","sequence":null,"server_hash":null,"server_timestamp":"1785211620953","session_id":"2d607381e3054cee91998cdf45a4231c","source":"clob_market_ws"},"received_at":"2026-07-28T04:07:04.896278Z","record_id":"a07610001ccca2db40fe0daafaf03684bed96bb81d83d77f62baa8559666c676","schema_fingerprint":"4aa3821a28b0b7c2400bc59aba4bcc0a76e971dadd19610d3ad38c768e124dc7","schema_version":"edge-lab-recorder.raw.v1","sequence":null,"source":"clob_market_ws"}
{"event_at":"2026-07-28T04:07:00.956000Z","event_fingerprint":"4d53a062296396cacfb5a13689340f5f8fa894970bc5eca202da955deb8f9d2f","payload":{"connection_id":"f6725804f86a4c4eb588e4d5ed7db029","event_at":"2026-07-28T04:07:00.956000Z","event_type":"price_change","frame_hash":"b085f8172845acd05d5679652087502c69ae418162b57ba39882b2c972fc2d0a","frame_index":0,"kind":"data","monotonic_ns":313607950374083,"payload":{"event_type":"price_change","market":"0xd412ce774cfcf8dc9f71164aac78783978aac7b03871702a3b8a481bd9dc9688","price_changes":[{"asset_id":"107603864457683460275633293642179940881969192120168665300712204232021063124301","best_ask":"0.64","best_bid":"0.63","hash":"c900140a669365c60d52b43721487c11561fc521","price":"0.6","side":"BUY","size":"52"},{"asset_id":"96600821790790307414914106093858868634329285205417149685270682748367152458577","best_ask":"0.37","best_bid":"0.36","hash":"ca94e1f60bbea5e665c6fd72ce66f10550def311","price":"0.4","side":"SELL","size":"52"}],"timestamp":"1785211620956"},"payload_hash":"1bd36a236435a85e92a12337de5e2651736a6eb9141fb9e94e9623242f634fe8","raw_frame":"{\"market\":\"0xd412ce774cfcf8dc9f71164aac78783978aac7b03871702a3b8a481bd9dc9688\", \"price_changes\":[{\"asset_id\":\"107603864457683460275633293642179940881969192120168665300712204232021063124301\", \"price\":\"0.6\", \"size\":\"52\", \"side\":\"BUY\", \"hash\":\"c900140a669365c60d52b43721487c11561fc521\", \"best_bid\":\"0.63\", \"best_ask\":\"0.64\"}, {\"asset_id\":\"96600821790790307414914106093858868634329285205417149685270682748367152458577\", \"price\":\"0.4\", \"size\":\"52\", \"side\":\"SELL\", \"hash\":\"ca94e1f60bbea5e665c6fd72ce66f10550def311\", \"best_bid\":\"0.36\", \"best_ask\":\"0.37\"}], \"timestamp\":\"1785211620956\", \"event_type\":\"price_change\"}","received_at":"2026-07-28T04:07:04.899313Z","schema_version":"clob-market-ws.price_change.v1","sequence":null,"server_hash":null,"server_timestamp":"1785211620956","session_id":"2d607381e3054cee91998cdf45a4231c","source":"clob_market_ws"},"received_at":"2026-07-28T04:07:04.899313Z","record_id":"1db36281d0b76817ad81497bdf3828dcdfd76d3d9afc31be71ff18ff00517f8c","schema_fingerprint":"4aa3821a28b0b7c2400bc59aba4bcc0a76e971dadd19610d3ad38c768e124dc7","schema_version":"edge-lab-recorder.raw.v1","sequence":null,"source":"clob_market_ws"}
{"event_at":"2026-07-28T04:07:00.957000Z","event_fingerprint":"84c3afc3f739070a244c9bc6eeb79d7c84ccc0798b46b9301a48c87e4d297d3d","payload":{"connection_id":"f6725804f86a4c4eb588e4d5ed7db029","event_at":"2026-07-28T04:07:00.957000Z","event_type":"price_change","frame_hash":"a913f7221bd74a2a30d433dba924849f227c9a68aa3b946b7e6830ffc8f6d4af","frame_index":0,"kind":"data","monotonic_ns":313607954732791,"payload":{"event_type":"price_change","market":"0xd412ce774cfcf8dc9f71164aac78783978aac7b03871702a3b8a481bd9dc9688","price_changes":[{"asset_id":"107603864457683460275633293642179940881969192120168665300712204232021063124301","best_ask":"0.64","best_bid":"0.63","hash":"9dedae0932feba2b255e047d5a2d3ad46c641286","price":"0.55","side":"BUY","size":"261"},{"asset_id":"96600821790790307414914106093858868634329285205417149685270682748367152458577","best_ask":"0.37","best_bid":"0.36","hash":"f83151641e46d0208b568e9cdd405fc8ed436de0","price":"0.45","side":"SELL","size":"261"}],"timestamp":"1785211620957"},"payload_hash":"a16154e325f5be131afcff1d6124a5b56628a9e038e83884f8299275fae374c0","raw_frame":"{\"market\":\"0xd412ce774cfcf8dc9f71164aac78783978aac7b03871702a3b8a481bd9dc9688\", \"price_changes\":[{\"asset_id\":\"107603864457683460275633293642179940881969192120168665300712204232021063124301\", \"price\":\"0.55\", \"size\":\"261\", \"side\":\"BUY\", \"hash\":\"9dedae0932feba2b255e047d5a2d3ad46c641286\", \"best_bid\":\"0.63\", \"best_ask\":\"0.64\"}, {\"asset_id\":\"96600821790790307414914106093858868634329285205417149685270682748367152458577\", \"price\":\"0.45\", \"size\":\"261\", \"side\":\"SELL\", \"hash\":\"f83151641e46d0208b568e9cdd405fc8ed436de0\", \"best_bid\":\"0.36\", \"best_ask\":\"0.37\"}], \"timestamp\":\"1785211620957\", \"event_type\":\"price_change\"}","received_at":"2026-07-28T04:07:04.903673Z","schema_version":"clob-market-ws.price_change.v1","sequence":null,"server_hash":null,"server_timestamp":"1785211620957","session_id":"2d607381e3054cee91998cdf45a4231c","source":"clob_market_ws"},"received_at":"2026-07-28T04:07:04.903673Z","record_id":"765996f9a52dbe7edc83a36587c59751b42bd11d1504ced2af577498f9ccad5d","schema_fingerprint":"4aa3821a28b0b7c2400bc59aba4bcc0a76e971dadd19610d3ad38c768e124dc7","schema_version":"edge-lab-recorder.raw.v1","sequence":null,"source":"clob_market_ws"}
{"event_at":"2026-07-28T04:07:00.960000Z","event_fingerprint":"f7f630423b1eba59aae8ae2af0cd1c741cb7b47cf1e496dd939413f9e49fa313","payload":{"connection_id":"f6725804f86a4c4eb588e4d5ed7db029","event_at":"2026-07-28T04:07:00.960000Z","event_type":"price_change","frame_hash":"d0ca11c644b9c24816e2a1cbc4674114a18f7d34e129a1fa56f0a78661b6dcbf","frame_index":0,"kind":"data","monotonic_ns":313607959323458,"payload":{"event_type":"price_change","market":"0xd412ce774cfcf8dc9f71164aac78783978aac7b03871702a3b8a481bd9dc9688","price_changes":[{"asset_id":"96600821790790307414914106093858868634329285205417149685270682748367152458577","best_ask":"0.37","best_bid":"0.36","hash":"f7e928108d53c9d08b64df2e28a6b17495925d89","price":"0.27","side":"BUY","size":"48.38"},{"asset_id":"107603864457683460275633293642179940881969192120168665300712204232021063124301","best_ask":"0.64","best_bid":"0.63","hash":"2d0e3164266ab4e86d728f8a307a49f929557373","price":"0.73","side":"SELL","size":"48.38"}],"timestamp":"1785211620960"},"payload_hash":"c82e1840f62f603625e3f2608aeca211293025f6e0af8f45c2f3c2ab7043d9ce","raw_frame":"{\"market\":\"0xd412ce774cfcf8dc9f71164aac78783978aac7b03871702a3b8a481bd9dc9688\", \"price_changes\":[{\"asset_id\":\"96600821790790307414914106093858868634329285205417149685270682748367152458577\", \"price\":\"0.27\", \"size\":\"48.38\", \"side\":\"BUY\", \"hash\":\"f7e928108d53c9d08b64df2e28a6b17495925d89\", \"best_bid\":\"0.36\", \"best_ask\":\"0.37\"}, {\"asset_id\":\"107603864457683460275633293642179940881969192120168665300712204232021063124301\", \"price\":\"0.73\", \"size\":\"48.38\", \"side\":\"SELL\", \"hash\":\"2d0e3164266ab4e86d728f8a307a49f929557373\", \"best_bid\":\"0.63\", \"best_ask\":\"0.64\"}], \"timestamp\":\"1785211620960\", \"event_type\":\"price_change\"}","received_at":"2026-07-28T04:07:04.908259Z","schema_version":"clob-market-ws.price_change.v1","sequence":null,"server_hash":null,"server_timestamp":"1785211620960","session_id":"2d607381e3054cee91998cdf45a4231c","source":"clob_market_ws"},"received_at":"2026-07-28T04:07:04.908259Z","record_id":"acf35ffac578cdfa3bd3c918beefc3f905a289543b0b835bba0e43ee29238529","schema_fingerprint":"4aa3821a28b0b7c2400bc59aba4bcc0a76e971dadd19610d3ad38c768e124dc7","schema_version":"edge-lab-recorder.raw.v1","sequence":null,"source":"clob_market_ws"}
{"event_at":"2026-07-28T04:07:00.961000Z","event_fingerprint":"ba7dd81b74b77b9d543e243d27b6de67e2dd1b5a780944f5a3884f604afc3cd7","payload":{"connection_id":"f6725804f86a4c4eb588e4d5ed7db029","event_at":"2026-07-28T04:07:00.961000Z","event_type":"price_change","frame_hash":"7f5950c09a7d076dac648279d31eae267d7c71234b7c1ef7f1e2ca24c242778f","frame_index":0,"kind":"data","monotonic_ns":313607963843041,"payload":{"event_type":"price_change","market":"0xd412ce774cfcf8dc9f71164aac78783978aac7b03871702a3b8a481bd9dc9688","price_changes":[{"asset_id":"96600821790790307414914106093858868634329285205417149685270682748367152458577","best_ask":"0.37","best_bid":"0.36","hash":"9698c3396f972ce0edd3e4cf4ff7caf9d84d0bee","price":"0.21","side":"BUY","size":"63.1"},{"asset_id":"107603864457683460275633293642179940881969192120168665300712204232021063124301","best_ask":"0.64","best_bid":"0.63","hash":"37ddf3f231f4e832ec0b21ff35a4960f3ff1f708","price":"0.79","side":"SELL","size":"63.1"}],"timestamp":"1785211620961"},"payload_hash":"a3746faa97d78584d239b07da5d693fe6881344851a65c957efce4eed0558477","raw_frame":"{\"market\":\"0xd412ce774cfcf8dc9f71164aac78783978aac7b03871702a3b8a481bd9dc9688\", \"price_changes\":[{\"asset_id\":\"96600821790790307414914106093858868634329285205417149685270682748367152458577\", \"price\":\"0.21\", \"size\":\"63.1\", \"side\":\"BUY\", \"hash\":\"9698c3396f972ce0edd3e4cf4ff7caf9d84d0bee\", \"best_bid\":\"0.36\", \"best_ask\":\"0.37\"}, {\"asset_id\":\"107603864457683460275633293642179940881969192120168665300712204232021063124301\", \"price\":\"0.79\", \"size\":\"63.1\", \"side\":\"SELL\", \"hash\":\"37ddf3f231f4e832ec0b21ff35a4960f3ff1f708\", \"best_bid\":\"0.63\", \"best_ask\":\"0.64\"}], \"timestamp\":\"1785211620961\", \"event_type\":\"price_change\"}","received_at":"2026-07-28T04:07:04.912782Z","schema_version":"clob-market-ws.price_change.v1","sequence":null,"server_hash":null,"server_timestamp":"1785211620961","session_id":"2d607381e3054cee91998cdf45a4231c","source":"clob_market_ws"},"received_at":"2026-07-28T04:07:04.912782Z","record_id":"129de9d84d517753af25938b37c3d8e349aad2c383993523d181b7b31aa6e9e9","schema_fingerprint":"4aa3821a28b0b7c2400bc59aba4bcc0a76e971dadd19610d3ad38c768e124dc7","schema_version":"edge-lab-recorder.raw.v1","sequence":null,"source":"clob_market_ws"}
{"event_at":"2026-07-28T04:07:00.964000Z","event_fingerprint":"1639d6da768e8c224521e467c3c0578926dc70b80451963a7e9babe6d92fbb36","payload":{"connection_id":"f6725804f86a4c4eb588e4d5ed7db029","event_at":"2026-07-28T04:07:00.964000Z","event_type":"price_change","frame_hash":"59010ea2d7572883d89a52118194a3c66ed0c683678355e5d5b4e6ac271482e2","frame_index":0,"kind":"data","monotonic_ns":313607968134458,"payload":{"event_type":"price_change","market":"0xd412ce774cfcf8dc9f71164aac78783978aac7b03871702a3b8a481bd9dc9688","price_changes":[{"asset_id":"107603864457683460275633293642179940881969192120168665300712204232021063124301","best_ask":"0.64","best_bid":"0.63","hash":"7d5075d134f3fb60269945012d865e313ed34295","price":"0.01","side":"BUY","size":"5638.02"},{"asset_id":"96600821790790307414914106093858868634329285205417149685270682748367152458577","best_ask":"0.37","best_bid":"0.36","hash":"df9d2f8cb1a63e63264bb9e3bd86e7f622d3d4ca","price":"0.99","side":"SELL","size":"5638.02"}],"timestamp":"1785211620964"},"payload_hash":"c96237780333c8952838ae9a896b795a7e23b5a18e58cc62dacfdf1172daa5c3","raw_frame":"{\"market\":\"0xd412ce774cfcf8dc9f71164aac78783978aac7b03871702a3b8a481bd9dc9688\", \"price_changes\":[{\"asset_id\":\"107603864457683460275633293642179940881969192120168665300712204232021063124301\", \"price\":\"0.01\", \"size\":\"5638.02\", \"side\":\"BUY\", \"hash\":\"7d5075d134f3fb60269945012d865e313ed34295\", \"best_bid\":\"0.63\", \"best_ask\":\"0.64\"}, {\"asset_id\":\"96600821790790307414914106093858868634329285205417149685270682748367152458577\", \"price\":\"0.99\", \"size\":\"5638.02\", \"side\":\"SELL\", \"hash\":\"df9d2f8cb1a63e63264bb9e3bd86e7f622d3d4ca\", \"best_bid\":\"0.36\", \"best_ask\":\"0.37\"}], \"timestamp\":\"1785211620964\", \"event_type\":\"price_change\"}","received_at":"2026-07-28T04:07:04.917074Z","schema_version":"clob-market-ws.price_change.v1","sequence":null,"server_hash":null,"server_timestamp":"1785211620964","session_id":"2d607381e3054cee91998cdf45a4231c","source":"clob_market_ws"},"received_at":"2026-07-28T04:07:04.917074Z","record_id":"41715f922f19eeebc8f78bddeda83450d75b5c2130a0719e9d3a974d5b7a77f6","schema_fingerprint":"4aa3821a28b0b7c2400bc59aba4bcc0a76e971dadd19610d3ad38c768e124dc7","schema_version":"edge-lab-recorder.raw.v1","sequence":null,"source":"clob_market_ws"}
{"event_at":"2026-07-28T04:07:00.971000Z","event_fingerprint":"b117a87ef2e2c813c017c65e2d901bdcef615aa0504d83213f222d6a869ee895","payload":{"connection_id":"f6725804f86a4c4eb588e4d5ed7db029","event_at":"2026-07-28T04:07:00.971000Z","event_type":"price_change","frame_hash":"3ec991d3274beeb4b211850e4cfd300f05868dd18599df9b4ec8e520acc1f6dd","frame_index":0,"kind":"data","monotonic_ns":313607972734791,"payload":{"event_type":"price_change","market":"0xd412ce774cfcf8dc9f71164aac78783978aac7b03871702a3b8a481bd9dc9688","price_changes":[{"asset_id":"107603864457683460275633293642179940881969192120168665300712204232021063124301","best_ask":"0.64","best_bid":"0.63","hash":"9f4ae8dbb6818f644915ef7a730b16c006706593","price":"0.5","side":"BUY","size":"105"},{"asset_id":"96600821790790307414914106093858868634329285205417149685270682748367152458577","best_ask":"0.37","best_bid":"0.36","hash":"e9beafb0eb01ac678b52a2c2cab84108c76f378f","price":"0.5","side":"SELL","size":"105"}],"timestamp":"1785211620971"},"payload_hash":"c4aaf6cac3f48b23a0f947fe04b99660b0f6762ca5f7b510f48d6c3d4b2d9e71","raw_frame":"{\"market\":\"0xd412ce774cfcf8dc9f71164aac78783978aac7b03871702a3b8a481bd9dc9688\", \"price_changes\":[{\"asset_id\":\"107603864457683460275633293642179940881969192120168665300712204232021063124301\", \"price\":\"0.5\", \"size\":\"105\", \"side\":\"BUY\", \"hash\":\"9f4ae8dbb6818f644915ef7a730b16c006706593\", \"best_bid\":\"0.63\", \"best_ask\":\"0.64\"}, {\"asset_id\":\"96600821790790307414914106093858868634329285205417149685270682748367152458577\", \"price\":\"0.5\", \"size\":\"105\", \"side\":\"SELL\", \"hash\":\"e9beafb0eb01ac678b52a2c2cab84108c76f378f\", \"best_bid\":\"0.36\", \"best_ask\":\"0.37\"}], \"timestamp\":\"1785211620971\", \"event_type\":\"price_change\"}","received_at":"2026-07-28T04:07:04.921673Z","schema_version":"clob-market-ws.price_change.v1","sequence":null,"server_hash":null,"server_timestamp":"1785211620971","session_id":"2d607381e3054cee91998cdf45a4231c","source":"clob_market_ws"},"received_at":"2026-07-28T04:07:04.921673Z","record_id":"755dea42942f9f041a8d96e4c37835da012c720f2529168f3c317318420ad6ca","schema_fingerprint":"4aa3821a28b0b7c2400bc59aba4bcc0a76e971dadd19610d3ad38c768e124dc7","schema_version":"edge-lab-recorder.raw.v1","sequence":null,"source":"clob_market_ws"}
{"event_at":"2026-07-28T04:07:00.975000Z","event_fingerprint":"db7bd9e7cd69cc4cd40e11457cbf884daea5534f389a371b107fcfe481630edb","payload":{"connection_id":"f6725804f86a4c4eb588e4d5ed7db029","event_at":"2026-07-28T04:07:00.975000Z","event_type":"price_change","frame_hash":"1bb20488d9bd55b8ab4231b52fa3dc50982a3e5499ff7d840a0c3a743aaede5c","frame_index":0,"kind":"data","monotonic_ns":313607975621583,"payload":{"event_type":"price_change","market":"0xd412ce774cfcf8dc9f71164aac78783978aac7b03871702a3b8a481bd9dc9688","price_changes":[{"asset_id":"107603864457683460275633293642179940881969192120168665300712204232021063124301","best_ask":"0.64","best_bid":"0.63","hash":"e6814a6122d46110bcd73405cec9daeb69c17a5a","price":"0.42","side":"BUY","size":"22.63"},{"asset_id":"96600821790790307414914106093858868634329285205417149685270682748367152458577","best_ask":"0.37","best_bid":"0.36","hash":"0eb5abe0b433776465a1a192ff5a666c3c6a2d78","price":"0.58","side":"SELL","size":"22.63"}],"timestamp":"1785211620975"},"payload_hash":"a285553e67a8faebe293a73cb032b5df76e1f7aa633105e6e1739f5295646efd","raw_frame":"{\"market\":\"0xd412ce774cfcf8dc9f71164aac78783978aac7b03871702a3b8a481bd9dc9688\", \"price_changes\":[{\"asset_id\":\"107603864457683460275633293642179940881969192120168665300712204232021063124301\", \"price\":\"0.42\", \"size\":\"22.63\", \"side\":\"BUY\", \"hash\":\"e6814a6122d46110bcd73405cec9daeb69c17a5a\", \"best_bid\":\"0.63\", \"best_ask\":\"0.64\"}, {\"asset_id\":\"96600821790790307414914106093858868634329285205417149685270682748367152458577\", \"price\":\"0.58\", \"size\":\"22.63\", \"side\":\"SELL\", \"hash\":\"0eb5abe0b433776465a1a192ff5a666c3c6a2d78\", \"best_bid\":\"0.36\", \"best_ask\":\"0.37\"}], \"timestamp\":\"1785211620975\", \"event_type\":\"price_change\"}","received_at":"2026-07-28T04:07:04.924561Z","schema_version":"clob-market-ws.price_change.v1","sequence":null,"server_hash":null,"server_timestamp":"1785211620975","session_id":"2d607381e3054cee91998cdf45a4231c","source":"clob_market_ws"},"received_at":"2026-07-28T04:07:04.924561Z","record_id":"e0955dc0ba173432a43fdf3b5598082ddc498a0eda696b35d79862a51fac1527","schema_fingerprint":"4aa3821a28b0b7c2400bc59aba4bcc0a76e971dadd19610d3ad38c768e124dc7","schema_version":"edge-lab-recorder.raw.v1","sequence":null,"source":"clob_market_ws"}
{"event_at":"2026-07-28T04:07:00.980000Z","event_fingerprint":"8db0f08377a6934d523bd9e84e187175afe0c0e848b2cf8aaccf79e4a45d946d","payload":{"connection_id":"f6725804f86a4c4eb588e4d5ed7db029","event_at":"2026-07-28T04:07:00.980000Z","event_type":"price_change","frame_hash":"d4f047fcff60b9ed02fb989f7d62d67a0afa1998ebb186809fd3d145feacb7b2","frame_index":0,"kind":"data","monotonic_ns":313607980090833,"payload":{"event_type":"price_change","market":"0xd412ce774cfcf8dc9f71164aac78783978aac7b03871702a3b8a481bd9dc9688","price_changes":[{"asset_id":"96600821790790307414914106093858868634329285205417149685270682748367152458577","best_ask":"0.37","best_bid":"0.36","hash":"d92f582be7aeede9add4cc3f92001c7c15ab328f","price":"0.28","side":"BUY","size":"64.44"},{"asset_id":"107603864457683460275633293642179940881969192120168665300712204232021063124301","best_ask":"0.64","best_bid":"0.63","hash":"afbb3934a7ac46b8a05c972ec0637f980bef9321","price":"0.72","side":"SELL","size":"64.44"}],"timestamp":"1785211620980"},"payload_hash":"06981d8d51c4eed00c2a3e1b5548ea95bd480ec7f2238dad153d925cb7437ee6","raw_frame":"{\"market\":\"0xd412ce774cfcf8dc9f71164aac78783978aac7b03871702a3b8a481bd9dc9688\", \"price_changes\":[{\"asset_id\":\"96600821790790307414914106093858868634329285205417149685270682748367152458577\", \"price\":\"0.28\", \"size\":\"64.44\", \"side\":\"BUY\", \"hash\":\"d92f582be7aeede9add4cc3f92001c7c15ab328f\", \"best_bid\":\"0.36\", \"best_ask\":\"0.37\"}, {\"asset_id\":\"107603864457683460275633293642179940881969192120168665300712204232021063124301\", \"price\":\"0.72\", \"size\":\"64.44\", \"side\":\"SELL\", \"hash\":\"afbb3934a7ac46b8a05c972ec0637f980bef9321\", \"best_bid\":\"0.63\", \"best_ask\":\"0.64\"}], \"timestamp\":\"1785211620980\", \"event_type\":\"price_change\"}","received_at":"2026-07-28T04:07:04.929028Z","schema_version":"clob-market-ws.price_change.v1","sequence":null,"server_hash":null,"server_timestamp":"1785211620980","session_id":"2d607381e3054cee91998cdf45a4231c","source":"clob_market_ws"},"received_at":"2026-07-28T04:07:04.929028Z","record_id":"6f90787cb649c4a9a5af652a0911d612fd3cd6d1c2a982a1815e4cc726b1cbda","schema_fingerprint":"4aa3821a28b0b7c2400bc59aba4bcc0a76e971dadd19610d3ad38c768e124dc7","schema_version":"edge-lab-recorder.raw.v1","sequence":null,"source":"clob_market_ws"}
{"event_at":"2026-07-28T04:07:00.982000Z","event_fingerprint":"695a9ea9fcc6f8144cc77ab71073cfeec1660ab2355c015435edda7a28090ab2","payload":{"connection_id":"f6725804f86a4c4eb588e4d5ed7db029","event_at":"2026-07-28T04:07:00.982000Z","event_type":"price_change","frame_hash":"a9c5249db6ec20a5057cb1ff8c33a229d08a627fe1e51b1906978b351aa2ac1f","frame_index":0,"kind":"data","monotonic_ns":313607983867875,"payload":{"event_type":"price_change","market":"0xd412ce774cfcf8dc9f71164aac78783978aac7b03871702a3b8a481bd9dc9688","price_changes":[{"asset_id":"96600821790790307414914106093858868634329285205417149685270682748367152458577","best_ask":"0.37","best_bid":"0.36","hash":"9fc8f144dc7030e9357ef372cab925158808c016","price":"0.36","side":"BUY","size":"79"},{"asset_id":"107603864457683460275633293642179940881969192120168665300712204232021063124301","best_ask":"0.64","best_bid":"0.63","hash":"668e93bc3e41a9fe371174fae5e1043afbf4c69a","price":"0.64","side":"SELL","size":"79"}],"timestamp":"1785211620982"},"payload_hash":"83182d5b4498b8da1893defe2eda7a3c2ce76cc5033b392ee8661fd5273bf579","raw_frame":"{\"market\":\"0xd412ce774cfcf8dc9f71164aac78783978aac7b03871702a3b8a481bd9dc9688\", \"price_changes\":[{\"asset_id\":\"96600821790790307414914106093858868634329285205417149685270682748367152458577\", \"price\":\"0.36\", \"size\":\"79\", \"side\":\"BUY\", \"hash\":\"9fc8f144dc7030e9357ef372cab925158808c016\", \"best_bid\":\"0.36\", \"best_ask\":\"0.37\"}, {\"asset_id\":\"107603864457683460275633293642179940881969192120168665300712204232021063124301\", \"price\":\"0.64\", \"size\":\"79\", \"side\":\"SELL\", \"hash\":\"668e93bc3e41a9fe371174fae5e1043afbf4c69a\", \"best_bid\":\"0.63\", \"best_ask\":\"0.64\"}], \"timestamp\":\"1785211620982\", \"event_type\":\"price_change\"}","received_at":"2026-07-28T04:07:04.932808Z","schema_version":"clob-market-ws.price_change.v1","sequence":null,"server_hash":null,"server_timestamp":"1785211620982","session_id":"2d607381e3054cee91998cdf45a4231c","source":"clob_market_ws"},"received_at":"2026-07-28T04:07:04.932808Z","record_id":"211117eec3d8af1fdbbcffdeaff038b975c2526d567b0a02b57070c76cda40bd","schema_fingerprint":"4aa3821a28b0b7c2400bc59aba4bcc0a76e971dadd19610d3ad38c768e124dc7","schema_version":"edge-lab-recorder.raw.v1","sequence":null,"source":"clob_market_ws"}
{"event_at":"2026-07-28T04:07:00.998000Z","event_fingerprint":"3e0cd1c2f4c0838543c1e79da2e01bef84408307f6f533c9f214ba2b53d51f52","payload":{"connection_id":"f6725804f86a4c4eb588e4d5ed7db029","event_at":"2026-07-28T04:07:00.998000Z","event_type":"price_change","frame_hash":"5876fe5ea1b21e3134c5dcc96d85694fa6532a8c6c93c3818db5aae0eb598a50","frame_index":0,"kind":"data","monotonic_ns":313607987505208,"payload":{"event_type":"price_change","market":"0xd412ce774cfcf8dc9f71164aac78783978aac7b03871702a3b8a481bd9dc9688","price_changes":[{"asset_id":"107603864457683460275633293642179940881969192120168665300712204232021063124301","best_ask":"0.64","best_bid":"0.63","hash":"b2ed95eec7806381b875f147ed49a67e90c7c298","price":"0.57","side":"BUY","size":"59"},{"asset_id":"96600821790790307414914106093858868634329285205417149685270682748367152458577","best_ask":"0.37","best_bid":"0.36","hash":"c62d7fc25bb89d38921330745a1d2d3b9bda23c0","price":"0.43","side":"SELL","size":"59"}],"timestamp":"1785211620998"},"payload_hash":"1a11a6b71c404aaa95fabf2ccf579ef4b3e84a24dea42e285ee5cff7121455aa","raw_frame":"{\"market\":\"0xd412ce774cfcf8dc9f71164aac78783978aac7b03871702a3b8a481bd9dc9688\", \"price_changes\":[{\"asset_id\":\"107603864457683460275633293642179940881969192120168665300712204232021063124301\", \"price\":\"0.57\", \"size\":\"59\", \"side\":\"BUY\", \"hash\":\"b2ed95eec7806381b875f147ed49a67e90c7c298\", \"best_bid\":\"0.63\", \"best_ask\":\"0.64\"}, {\"asset_id\":\"96600821790790307414914106093858868634329285205417149685270682748367152458577\", \"price\":\"0.43\", \"size\":\"59\", \"side\":\"SELL\", \"hash\":\"c62d7fc25bb89d38921330745a1d2d3b9bda23c0\", \"best_bid\":\"0.36\", \"best_ask\":\"0.37\"}], \"timestamp\":\"1785211620998\", \"event_type\":\"price_change\"}","received_at":"2026-07-28T04:07:04.936445Z","schema_version":"clob-market-ws.price_change.v1","sequence":null,"server_hash":null,"server_timestamp":"1785211620998","session_id":"2d607381e3054cee91998cdf45a4231c","source":"clob_market_ws"},"received_at":"2026-07-28T04:07:04.936445Z","record_id":"b238dfea7355d135ac51e7e013e2be27949e89d3c35a4c06009d0f966817769d","schema_fingerprint":"4aa3821a28b0b7c2400bc59aba4bcc0a76e971dadd19610d3ad38c768e124dc7","schema_version":"edge-lab-recorder.raw.v1","sequence":null,"source":"clob_market_ws"}
{"event_at":"2026-07-28T04:07:01.003000Z","event_fingerprint":"341073f7e80402992844e80c3d495b918e8bc0a47fe7a8450011cac2c1adcafb","payload":{"connection_id":"f6725804f86a4c4eb588e4d5ed7db029","event_at":"2026-07-28T04:07:01.003000Z","event_type":"best_bid_ask","frame_hash":"a83336c2ce14f5843954c688f808d4b2c379ef6868f1ea328be7c79d3fb3b417","frame_index":0,"kind":"data","monotonic_ns":313607991984291,"payload":{"asset_id":"107603864457683460275633293642179940881969192120168665300712204232021063124301","best_ask":"0.64","best_bid":"0.62","event_type":"best_bid_ask","market":"0xd412ce774cfcf8dc9f71164aac78783978aac7b03871702a3b8a481bd9dc9688","spread":"0.02","timestamp":"1785211621003"},"payload_hash":"5317e5854a7cb3d73a0ba108c0334f2c3842c9c70550dd6976d347d3948f1e28","raw_frame":"{\"market\":\"0xd412ce774cfcf8dc9f71164aac78783978aac7b03871702a3b8a481bd9dc9688\", \"asset_id\":\"107603864457683460275633293642179940881969192120168665300712204232021063124301\", \"best_bid\":\"0.62\", \"best_ask\":\"0.64\", \"spread\":\"0.02\", \"timestamp\":\"1785211621003\", \"event_type\":\"best_bid_ask\"}","received_at":"2026-07-28T04:07:04.940924Z","schema_version":"clob-market-ws.best_bid_ask.v1","sequence":null,"server_hash":null,"server_timestamp":"1785211621003","session_id":"2d607381e3054cee91998cdf45a4231c","source":"clob_market_ws"},"received_at":"2026-07-28T04:07:04.940924Z","record_id":"080a77ee443df77a748d9d580adc1dcf37cafefd103e7be3b6cb5e662c216cfb","schema_fingerprint":"8488399f31b0337811b13b266be932db7062827c2470b78bd8e9e99bab51d17d","schema_version":"edge-lab-recorder.raw.v1","sequence":null,"source":"clob_market_ws"}
{"event_at":"2026-07-28T04:07:01.003000Z","event_fingerprint":"a714e77610a15f729fab2353159687c45a78b4f043868f52df499d3ee52bfd34","payload":{"connection_id":"f6725804f86a4c4eb588e4d5ed7db029","event_at":"2026-07-28T04:07:01.003000Z","event_type":"best_bid_ask","frame_hash":"e08dbb9f4aa05e30a78dde13d5c26ba5d2edeeb08a9b20f69060ac92e1d26df6","frame_index":0,"kind":"data","monotonic_ns":313607996070125,"payload":{"asset_id":"96600821790790307414914106093858868634329285205417149685270682748367152458577","best_ask":"0.38","best_bid":"0.36","event_type":"best_bid_ask","market":"0xd412ce774cfcf8dc9f71164aac78783978aac7b03871702a3b8a481bd9dc9688","spread":"0.02","timestamp":"1785211621003"},"payload_hash":"6b52ef24d8d06ab08390806a849485dee267fd94f21197fcb75d8b8cbd12d9e7","raw_frame":"{\"market\":\"0xd412ce774cfcf8dc9f71164aac78783978aac7b03871702a3b8a481bd9dc9688\", \"asset_id\":\"96600821790790307414914106093858868634329285205417149685270682748367152458577\", \"best_bid\":\"0.36\", \"best_ask\":\"0.38\", \"spread\":\"0.02\", \"timestamp\":\"1785211621003\", \"event_type\":\"best_bid_ask\"}","received_at":"2026-07-28T04:07:04.945009Z","schema_version":"clob-market-ws.best_bid_ask.v1","sequence":null,"server_hash":null,"server_timestamp":"1785211621003","session_id":"2d607381e3054cee91998cdf45a4231c","source":"clob_market_ws"},"received_at":"2026-07-28T04:07:04.945009Z","record_id":"37cdf0c06eb8f9d19ca57a50cefd51fb6f5f2ee907487852a4368da9bf203e3e","schema_fingerprint":"8488399f31b0337811b13b266be932db7062827c2470b78bd8e9e99bab51d17d","schema_version":"edge-lab-recorder.raw.v1","sequence":null,"source":"clob_market_ws"}
{"event_at":"2026-07-28T04:07:01.003000Z","event_fingerprint":"f0a63a3464ccab3d9d341a85b139788e2ea791e9f5299719ea9757c4bd5c4916","payload":{"connection_id":"f6725804f86a4c4eb588e4d5ed7db029","event_at":"2026-07-28T04:07:01.003000Z","event_type":"price_change","frame_hash":"a3a44def3df7b3b437a0af9b95598c59000024bc1c7085342364c5c71ed1d9d5","frame_index":0,"kind":"data","monotonic_ns":313607999985125,"payload":{"event_type":"price_change","market":"0xd412ce774cfcf8dc9f71164aac78783978aac7b03871702a3b8a481bd9dc9688","price_changes":[{"asset_id":"107603864457683460275633293642179940881969192120168665300712204232021063124301","best_ask":"0.64","best_bid":"0.62","hash":"8e6e7a00e739669b956d5f1771035c1c95050795","price":"0.68","side":"SELL","size":"78.01"},{"asset_id":"96600821790790307414914106093858868634329285205417149685270682748367152458577","best_ask":"0.38","best_bid":"0.36","hash":"0531cd5ce2b97109e8342eec1f41ee5c3d57e1f4","price":"0.32","side":"BUY","size":"78.01"}],"timestamp":"1785211621003"},"payload_hash":"8b94a58d1d562e18e0b1b94370ddbadf247f2f9627c813aea3fa9bfa000e1a72","raw_frame":"{\"market\":\"0xd412ce774cfcf8dc9f71164aac78783978aac7b03871702a3b8a481bd9dc9688\", \"price_changes\":[{\"asset_id\":\"107603864457683460275633293642179940881969192120168665300712204232021063124301\", \"price\":\"0.68\", \"size\":\"78.01\", \"side\":\"SELL\", \"hash\":\"8e6e7a00e739669b956d5f1771035c1c95050795\", \"best_bid\":\"0.62\", \"best_ask\":\"0.64\"}, {\"asset_id\":\"96600821790790307414914106093858868634329285205417149685270682748367152458577\", \"price\":\"0.32\", \"size\":\"78.01\", \"side\":\"BUY\", \"hash\":\"0531cd5ce2b97109e8342eec1f41ee5c3d57e1f4\", \"best_bid\":\"0.36\", \"best_ask\":\"0.38\"}], \"timestamp\":\"1785211621003\", \"event_type\":\"price_change\"}","received_at":"2026-07-28T04:07:04.948925Z","schema_version":"clob-market-ws.price_change.v1","sequence":null,"server_hash":null,"server_timestamp":"1785211621003","session_id":"2d607381e3054cee91998cdf45a4231c","source":"clob_market_ws"},"received_at":"2026-07-28T04:07:04.948925Z","record_id":"51f6ff03daceb444c05344fae0e5d19dc1d97428e27792ac164004d2d2df5419","schema_fingerprint":"4aa3821a28b0b7c2400bc59aba4bcc0a76e971dadd19610d3ad38c768e124dc7","schema_version":"edge-lab-recorder.raw.v1","sequence":null,"source":"clob_market_ws"}
{"event_at":"2026-07-28T04:07:01.003000Z","event_fingerprint":"f1f5015ce619fd4c775707ecf9ca1b11952f79f2b17cc362448ff582c1eea015","payload":{"connection_id":"f6725804f86a4c4eb588e4d5ed7db029","event_at":"2026-07-28T04:07:01.003000Z","event_type":"price_change","frame_hash":"f48b5980c192900ab72041fa867519b5cf0283bf0c7bdb969d937c868bf1058a","frame_index":0,"kind":"data","monotonic_ns":313608004259208,"payload":{"event_type":"price_change","market":"0xd412ce774cfcf8dc9f71164aac78783978aac7b03871702a3b8a481bd9dc9688","price_changes":[{"asset_id":"96600821790790307414914106093858868634329285205417149685270682748367152458577","best_ask":"0.38","best_bid":"0.36","hash":"0531cd5ce2b97109e8342eec1f41ee5c3d57e1f4","price":"0.38","side":"SELL","size":"48"},{"asset_id":"107603864457683460275633293642179940881969192120168665300712204232021063124301","best_ask":"0.64","best_bid":"0.62","hash":"8e6e7a00e739669b956d5f1771035c1c95050795","price":"0.62","side":"BUY","size":"48"}],"timestamp":"1785211621003"},"payload_hash":"aa00d4bbad73ec0242693d95fcdaad54ee32e0844f9cfecccec3552c01903251","raw_frame":"{\"market\":\"0xd412ce774cfcf8dc9f71164aac78783978aac7b03871702a3b8a481bd9dc9688\", \"price_changes\":[{\"asset_id\":\"96600821790790307414914106093858868634329285205417149685270682748367152458577\", \"price\":\"0.38\", \"size\":\"48\", \"side\":\"SELL\", \"hash\":\"0531cd5ce2b97109e8342eec1f41ee5c3d57e1f4\", \"best_bid\":\"0.36\", \"best_ask\":\"0.38\"}, {\"asset_id\":\"107603864457683460275633293642179940881969192120168665300712204232021063124301\", \"price\":\"0.62\", \"size\":\"48\", \"side\":\"BUY\", \"hash\":\"8e6e7a00e739669b956d5f1771035c1c95050795\", \"best_bid\":\"0.62\", \"best_ask\":\"0.64\"}], \"timestamp\":\"1785211621003\", \"event_type\":\"price_change\"}","received_at":"2026-07-28T04:07:04.953199Z","schema_version":"clob-market-ws.price_change.v1","sequence":null,"server_hash":null,"server_timestamp":"1785211621003","session_id":"2d607381e3054cee91998cdf45a4231c","source":"clob_market_ws"},"received_at":"2026-07-28T04:07:04.953199Z","record_id":"7e698f6eca08391638b379fdc3139e932c198990695d442681f4da20dc83eba5","schema_fingerprint":"4aa3821a28b0b7c2400bc59aba4bcc0a76e971dadd19610d3ad38c768e124dc7","schema_version":"edge-lab-recorder.raw.v1","sequence":null,"source":"clob_market_ws"}
{"event_at":"2026-07-28T04:07:01.003000Z","event_fingerprint":"41dc87244f778e5e1e1d5bee80ee23531c221e2561005d9fbc9efd884a51629a","payload":{"connection_id":"f6725804f86a4c4eb588e4d5ed7db029","event_at":"2026-07-28T04:07:01.003000Z","event_type":"price_change","frame_hash":"e0b82f3b0457316d3280c386fc5f000fe9e98e94bcc1f8bacc4c92969d6fcb26","frame_index":0,"kind":"data","monotonic_ns":313608008653333,"payload":{"event_type":"price_change","market":"0xd412ce774cfcf8dc9f71164aac78783978aac7b03871702a3b8a481bd9dc9688","price_changes":[{"asset_id":"96600821790790307414914106093858868634329285205417149685270682748367152458577","best_ask":"0.38","best_bid":"0.36","hash":"0531cd5ce2b97109e8342eec1f41ee5c3d57e1f4","price":"0.37","side":"SELL","size":"0"},{"asset_id":"107603864457683460275633293642179940881969192120168665300712204232021063124301","best_ask":"0.64","best_bid":"0.62","hash":"8e6e7a00e739669b956d5f1771035c1c95050795","price":"0.63","side":"BUY","size":"0"}],"timestamp":"1785211621003"},"payload_hash":"49e9d2c251ca79eaa06c5a41dcf6f30bda355d6d733835afd027a99c93f92302","raw_frame":"{\"market\":\"0xd412ce774cfcf8dc9f71164aac78783978aac7b03871702a3b8a481bd9dc9688\", \"price_changes\":[{\"asset_id\":\"96600821790790307414914106093858868634329285205417149685270682748367152458577\", \"price\":\"0.37\", \"size\":\"0\", \"side\":\"SELL\", \"hash\":\"0531cd5ce2b97109e8342eec1f41ee5c3d57e1f4\", \"best_bid\":\"0.36\", \"best_ask\":\"0.38\"}, {\"asset_id\":\"107603864457683460275633293642179940881969192120168665300712204232021063124301\", \"price\":\"0.63\", \"size\":\"0\", \"side\":\"BUY\", \"hash\":\"8e6e7a00e739669b956d5f1771035c1c95050795\", \"best_bid\":\"0.62\", \"best_ask\":\"0.64\"}], \"timestamp\":\"1785211621003\", \"event_type\":\"price_change\"}","received_at":"2026-07-28T04:07:04.957593Z","schema_version":"clob-market-ws.price_change.v1","sequence":null,"server_hash":null,"server_timestamp":"1785211621003","session_id":"2d607381e3054cee91998cdf45a4231c","source":"clob_market_ws"},"received_at":"2026-07-28T04:07:04.957593Z","record_id":"b894c601689a41e16731b701795db19278fa4932c93a0ba9a2b8017cc27ed66e","schema_fingerprint":"4aa3821a28b0b7c2400bc59aba4bcc0a76e971dadd19610d3ad38c768e124dc7","schema_version":"edge-lab-recorder.raw.v1","sequence":null,"source":"clob_market_ws"}
{"event_at":"2026-07-28T04:07:01.003000Z","event_fingerprint":"1c130f4aab051bc9167e5606a0a35d24ccf0b073989f575c57beb0bc5377fe97","payload":{"connection_id":"f6725804f86a4c4eb588e4d5ed7db029","event_at":"2026-07-28T04:07:01.003000Z","event_type":"price_change","frame_hash":"d36d8ddef5d31633b17f1c56e5216604b41b493bad67f696603959726af69a0d","frame_index":0,"kind":"data","monotonic_ns":313608012912125,"payload":{"event_type":"price_change","market":"0xd412ce774cfcf8dc9f71164aac78783978aac7b03871702a3b8a481bd9dc9688","price_changes":[{"asset_id":"107603864457683460275633293642179940881969192120168665300712204232021063124301","best_ask":"0.64","best_bid":"0.62","hash":"8e6e7a00e739669b956d5f1771035c1c95050795","price":"0.67","side":"SELL","size":"37.6"},{"asset_id":"96600821790790307414914106093858868634329285205417149685270682748367152458577","best_ask":"0.38","best_bid":"0.36","hash":"0531cd5ce2b97109e8342eec1f41ee5c3d57e1f4","price":"0.33","side":"BUY","size":"37.6"}],"timestamp":"1785211621003"},"payload_hash":"4dcef96443debd6d3d663633549575bd70a2efc2d9c4faa2c33fae058d124e41","raw_frame":"{\"market\":\"0xd412ce774cfcf8dc9f71164aac78783978aac7b03871702a3b8a481bd9dc9688\", \"price_changes\":[{\"asset_id\":\"107603864457683460275633293642179940881969192120168665300712204232021063124301\", \"price\":\"0.67\", \"size\":\"37.6\", \"side\":\"SELL\", \"hash\":\"8e6e7a00e739669b956d5f1771035c1c95050795\", \"best_bid\":\"0.62\", \"best_ask\":\"0.64\"}, {\"asset_id\":\"96600821790790307414914106093858868634329285205417149685270682748367152458577\", \"price\":\"0.33\", \"size\":\"37.6\", \"side\":\"BUY\", \"hash\":\"0531cd5ce2b97109e8342eec1f41ee5c3d57e1f4\", \"best_bid\":\"0.36\", \"best_ask\":\"0.38\"}], \"timestamp\":\"1785211621003\", \"event_type\":\"price_change\"}","received_at":"2026-07-28T04:07:04.961851Z","schema_version":"clob-market-ws.price_change.v1","sequence":null,"server_hash":null,"server_timestamp":"1785211621003","session_id":"2d607381e3054cee91998cdf45a4231c","source":"clob_market_ws"},"received_at":"2026-07-28T04:07:04.961851Z","record_id":"4660be79e30b54a18bf6712cf1704d48fb3043fad20ac8da567c7774e86f02d9","schema_fingerprint":"4aa3821a28b0b7c2400bc59aba4bcc0a76e971dadd19610d3ad38c768e124dc7","schema_version":"edge-lab-recorder.raw.v1","sequence":null,"source":"clob_market_ws"}
{"event_at":"2026-07-28T04:07:01.007000Z","event_fingerprint":"e75ac2c461d701776532202ddac7b9b648f8af901f44502802fd38761e9410e6","payload":{"connection_id":"f6725804f86a4c4eb588e4d5ed7db029","event_at":"2026-07-28T04:07:01.007000Z","event_type":"price_change","frame_hash":"b79c758560844ad0e304b266105f529d956c267f3e262cee565a69dcefec2f00","frame_index":0,"kind":"data","monotonic_ns":313608017213000,"payload":{"event_type":"price_change","market":"0xd412ce774cfcf8dc9f71164aac78783978aac7b03871702a3b8a481bd9dc9688","price_changes":[{"asset_id":"96600821790790307414914106093858868634329285205417149685270682748367152458577","best_ask":"0.38","best_bid":"0.36","hash":"edda3af279cb88840a87c87140dbe13382db3f70","price":"0.33","side":"BUY","size":"42.6"},{"asset_id":"107603864457683460275633293642179940881969192120168665300712204232021063124301","best_ask":"0.64","best_bid":"0.62","hash":"ce52ad6ba50217552a4b509b48751153d6752177","price":"0.67","side":"SELL","size":"42.6"}],"timestamp":"1785211621007"},"payload_hash":"e6d9a0c86c6fc94f4e01833544a6277b9dc437ad9eddf94119f448e063421071","raw_frame":"{\"market\":\"0xd412ce774cfcf8dc9f71164aac78783978aac7b03871702a3b8a481bd9dc9688\", \"price_changes\":[{\"asset_id\":\"96600821790790307414914106093858868634329285205417149685270682748367152458577\", \"price\":\"0.33\", \"size\":\"42.6\", \"side\":\"BUY\", \"hash\":\"edda3af279cb88840a87c87140dbe13382db3f70\", \"best_bid\":\"0.36\", \"best_ask\":\"0.38\"}, {\"asset_id\":\"107603864457683460275633293642179940881969192120168665300712204232021063124301\", \"price\":\"0.67\", \"size\":\"42.6\", \"side\":\"SELL\", \"hash\":\"ce52ad6ba50217552a4b509b48751153d6752177\", \"best_bid\":\"0.62\", \"best_ask\":\"0.64\"}], \"timestamp\":\"1785211621007\", \"event_type\":\"price_change\"}","received_at":"2026-07-28T04:07:04.966153Z","schema_version":"clob-market-ws.price_change.v1","sequence":null,"server_hash":null,"server_timestamp":"1785211621007","session_id":"2d607381e3054cee91998cdf45a4231c","source":"clob_market_ws"},"received_at":"2026-07-28T04:07:04.966153Z","record_id":"4cb130f81d9dde3b7a3f06a06a604e0993fe46c5e905320641305911089edd48","schema_fingerprint":"4aa3821a28b0b7c2400bc59aba4bcc0a76e971dadd19610d3ad38c768e124dc7","schema_version":"edge-lab-recorder.raw.v1","sequence":null,"source":"clob_market_ws"}
{"event_at":"2026-07-28T04:07:01.011000Z","event_fingerprint":"bb81d3f7ef4c894d2be8cadc8b823008bd5c95ec7bd146a3a04ae7846fd81b47","payload":{"connection_id":"f6725804f86a4c4eb588e4d5ed7db029","event_at":"2026-07-28T04:07:01.011000Z","event_type":"best_bid_ask","frame_hash":"55b5687ffc4679ef7b23faa91278a2e8d4e4c710124d82d10ccdaa5e8e62a7a5","frame_index":0,"kind":"data","monotonic_ns":313608021814291,"payload":{"asset_id":"107603864457683460275633293642179940881969192120168665300712204232021063124301","best_ask":"0.63","best_bid":"0.62","event_type":"best_bid_ask","market":"0xd412ce774cfcf8dc9f71164aac78783978aac7b03871702a3b8a481bd9dc9688","spread":"0.01","timestamp":"1785211621011"},"payload_hash":"3a91d9e5ca05a3c3ff8a6f8d40a7c10f086863b12954639e819d2a7d748c39ba","raw_frame":"{\"market\":\"0xd412ce774cfcf8dc9f71164aac78783978aac7b03871702a3b8a481bd9dc9688\", \"asset_id\":\"107603864457683460275633293642179940881969192120168665300712204232021063124301\", \"best_bid\":\"0.62\", \"best_ask\":\"0.63\", \"spread\":\"0.01\", \"timestamp\":\"1785211621011\", \"event_type\":\"best_bid_ask\"}","received_at":"2026-07-28T04:07:04.970754Z","schema_version":"clob-market-ws.best_bid_ask.v1","sequence":null,"server_hash":null,"server_timestamp":"1785211621011","session_id":"2d607381e3054cee91998cdf45a4231c","source":"clob_market_ws"},"received_at":"2026-07-28T04:07:04.970754Z","record_id":"006e6e11baf67729970b8e5fd9e2336f2713834c0b9ca0e47c67dc02b9904453","schema_fingerprint":"8488399f31b0337811b13b266be932db7062827c2470b78bd8e9e99bab51d17d","schema_version":"edge-lab-recorder.raw.v1","sequence":null,"source":"clob_market_ws"}
{"event_at":"2026-07-28T04:07:01.011000Z","event_fingerprint":"d51ae7193efde18d81d421fbcbfe7e0b88beca8e7bac3944284a278b7fc802c7","payload":{"connection_id":"f6725804f86a4c4eb588e4d5ed7db029","event_at":"2026-07-28T04:07:01.011000Z","event_type":"best_bid_ask","frame_hash":"6fa9ccd69e365c4d946d2cd9d4b6b5c3ba58631d8b18183fec819c33e915117d","frame_index":0,"kind":"data","monotonic_ns":313608025856083,"payload":{"asset_id":"96600821790790307414914106093858868634329285205417149685270682748367152458577","best_ask":"0.38","best_bid":"0.37","event_type":"best_bid_ask","market":"0xd412ce774cfcf8dc9f71164aac78783978aac7b03871702a3b8a481bd9dc9688","spread":"0.01","timestamp":"1785211621011"},"payload_hash":"8c7140018ad56b6add52f922148e18f2b45e80d7ffc20eb9c0f106410a057691","raw_frame":"{\"market\":\"0xd412ce774cfcf8dc9f71164aac78783978aac7b03871702a3b8a481bd9dc9688\", \"asset_id\":\"96600821790790307414914106093858868634329285205417149685270682748367152458577\", \"best_bid\":\"0.37\", \"best_ask\":\"0.38\", \"spread\":\"0.01\", \"timestamp\":\"1785211621011\", \"event_type\":\"best_bid_ask\"}","received_at":"2026-07-28T04:07:04.974796Z","schema_version":"clob-market-ws.best_bid_ask.v1","sequence":null,"server_hash":null,"server_timestamp":"1785211621011","session_id":"2d607381e3054cee91998cdf45a4231c","source":"clob_market_ws"},"received_at":"2026-07-28T04:07:04.974796Z","record_id":"909c3743adcf0ed42ca42d5bd5fcc6fd3cc15962a29cef46bf22b87e1a2ff412","schema_fingerprint":"8488399f31b0337811b13b266be932db7062827c2470b78bd8e9e99bab51d17d","schema_version":"edge-lab-recorder.raw.v1","sequence":null,"source":"clob_market_ws"}
{"event_at":"2026-07-28T04:07:01.010000Z","event_fingerprint":"7d0d3998c5833f25321364c7e121fb0dc1fd38200a4d7e06703b01474ae55a02","payload":{"connection_id":"f6725804f86a4c4eb588e4d5ed7db029","event_at":"2026-07-28T04:07:01.010000Z","event_type":"price_change","frame_hash":"f08d1c6e1214f4cec3ce926e3a23334d0d0cf6e02f4c5033759e4b5242513737","frame_index":0,"kind":"data","monotonic_ns":313608029961125,"payload":{"event_type":"price_change","market":"0xd412ce774cfcf8dc9f71164aac78783978aac7b03871702a3b8a481bd9dc9688","price_changes":[{"asset_id":"96600821790790307414914106093858868634329285205417149685270682748367152458577","best_ask":"0.38","best_bid":"0.37","hash":"2568112c297d04cf607ef5b2290f62da72f23c8a","price":"0.37","side":"BUY","size":"6"},{"asset_id":"107603864457683460275633293642179940881969192120168665300712204232021063124301","best_ask":"0.63","best_bid":"0.62","hash":"78314f9d2f9a2a8c2108fd644a5f56b702165090","price":"0.63","side":"SELL","size":"6"}],"timestamp":"1785211621010"},"payload_hash":"f84ad120851af5fa16a25b80fb7d0f4f1628746214d3aa697484091b069e4376","raw_frame":"{\"market\":\"0xd412ce774cfcf8dc9f71164aac78783978aac7b03871702a3b8a481bd9dc9688\", \"price_changes\":[{\"asset_id\":\"96600821790790307414914106093858868634329285205417149685270682748367152458577\", \"price\":\"0.37\", \"size\":\"6\", \"side\":\"BUY\", \"hash\":\"2568112c297d04cf607ef5b2290f62da72f23c8a\", \"best_bid\":\"0.37\", \"best_ask\":\"0.38\"}, {\"asset_id\":\"107603864457683460275633293642179940881969192120168665300712204232021063124301\", \"price\":\"0.63\", \"size\":\"6\", \"side\":\"SELL\", \"hash\":\"78314f9d2f9a2a8c2108fd644a5f56b702165090\", \"best_bid\":\"0.62\", \"best_ask\":\"0.63\"}], \"timestamp\":\"1785211621010\", \"event_type\":\"price_change\"}","received_at":"2026-07-28T04:07:04.978901Z","schema_version":"clob-market-ws.price_change.v1","sequence":null,"server_hash":null,"server_timestamp":"1785211621010","session_id":"2d607381e3054cee91998cdf45a4231c","source":"clob_market_ws"},"received_at":"2026-07-28T04:07:04.978901Z","record_id":"1190777539716fbeff289d863783b681d70b3ce39aaba221f5b6a14641053f28","schema_fingerprint":"4aa3821a28b0b7c2400bc59aba4bcc0a76e971dadd19610d3ad38c768e124dc7","schema_version":"edge-lab-recorder.raw.v1","sequence":null,"source":"clob_market_ws"}
{"event_at":"2026-07-28T04:07:01.018000Z","event_fingerprint":"7f62c5ea9b211f893a671d40e3a24095e860e983b9c573e846135dad6c362722","payload":{"connection_id":"f6725804f86a4c4eb588e4d5ed7db029","event_at":"2026-07-28T04:07:01.018000Z","event_type":"price_change","frame_hash":"6099d7c59df051df59936e3c0aa7ce2ca22b175bee49f4d113f100898ef8a4c7","frame_index":0,"kind":"data","monotonic_ns":313608033790291,"payload":{"event_type":"price_change","market":"0xd412ce774cfcf8dc9f71164aac78783978aac7b03871702a3b8a481bd9dc9688","price_changes":[{"asset_id":"96600821790790307414914106093858868634329285205417149685270682748367152458577","best_ask":"0.38","best_bid":"0.37","hash":"d806c2e478919bba76f0aac632524ede616d485a","price":"0.37","side":"BUY","size":"19"},{"asset_id":"107603864457683460275633293642179940881969192120168665300712204232021063124301","best_ask":"0.63","best_bid":"0.62","hash":"189b956493fb4cec70f84a873784bbed3a29cc24","price":"0.63","side":"SELL","size":"19"}],"timestamp":"1785211621018"},"payload_hash":"06f9474036712c312e808ba2ae8f9c61fb88b1fd142c31807ab0374a1219f2aa","raw_frame":"{\"market\":\"0xd412ce774cfcf8dc9f71164aac78783978aac7b03871702a3b8a481bd9dc9688\", \"price_changes\":[{\"asset_id\":\"96600821790790307414914106093858868634329285205417149685270682748367152458577\", \"price\":\"0.37\", \"size\":\"19\", \"side\":\"BUY\", \"hash\":\"d806c2e478919bba76f0aac632524ede616d485a\", \"best_bid\":\"0.37\", \"best_ask\":\"0.38\"}, {\"asset_id\":\"107603864457683460275633293642179940881969192120168665300712204232021063124301\", \"price\":\"0.63\", \"size\":\"19\", \"side\":\"SELL\", \"hash\":\"189b956493fb4cec70f84a873784bbed3a29cc24\", \"best_bid\":\"0.62\", \"best_ask\":\"0.63\"}], \"timestamp\":\"1785211621018\", \"event_type\":\"price_change\"}","received_at":"2026-07-28T04:07:04.982730Z","schema_version":"clob-market-ws.price_change.v1","sequence":null,"server_hash":null,"server_timestamp":"1785211621018","session_id":"2d607381e3054cee91998cdf45a4231c","source":"clob_market_ws"},"received_at":"2026-07-28T04:07:04.982730Z","record_id":"997e542dd676010f5593e6bd1b194ec33d56706969e03e1c5de0ebc2e9bb34db","schema_fingerprint":"4aa3821a28b0b7c2400bc59aba4bcc0a76e971dadd19610d3ad38c768e124dc7","schema_version":"edge-lab-recorder.raw.v1","sequence":null,"source":"clob_market_ws"}
{"event_at":"2026-07-28T04:07:01.019000Z","event_fingerprint":"8f4912a3e426d87e85a424354480b445eb4ade3651c425c2719e081c52740648","payload":{"connection_id":"f6725804f86a4c4eb588e4d5ed7db029","event_at":"2026-07-28T04:07:01.019000Z","event_type":"price_change","frame_hash":"438682fcf997d854cc27184893dc4938deb4fb389ff633e4e323b0fe32c016d5","frame_index":0,"kind":"data","monotonic_ns":313608037501833,"payload":{"event_type":"price_change","market":"0xd412ce774cfcf8dc9f71164aac78783978aac7b03871702a3b8a481bd9dc9688","price_changes":[{"asset_id":"107603864457683460275633293642179940881969192120168665300712204232021063124301","best_ask":"0.63","best_bid":"0.62","hash":"f0833b0b2c50625bb0556f522d7ac816b1a72d45","price":"0.64","side":"SELL","size":"72"},{"asset_id":"96600821790790307414914106093858868634329285205417149685270682748367152458577","best_ask":"0.38","best_bid":"0.37","hash":"36e8ac1295984759c96fa0386d7f122adf0767b9","price":"0.36","side":"BUY","size":"72"}],"timestamp":"1785211621019"},"payload_hash":"4922402007ee8c0cdab02bf915ac7b786075a74697dc21c332b7bc33cd15397e","raw_frame":"{\"market\":\"0xd412ce774cfcf8dc9f71164aac78783978aac7b03871702a3b8a481bd9dc9688\", \"price_changes\":[{\"asset_id\":\"107603864457683460275633293642179940881969192120168665300712204232021063124301\", \"price\":\"0.64\", \"size\":\"72\", \"side\":\"SELL\", \"hash\":\"f0833b0b2c50625bb0556f522d7ac816b1a72d45\", \"best_bid\":\"0.62\", \"best_ask\":\"0.63\"}, {\"asset_id\":\"96600821790790307414914106093858868634329285205417149685270682748367152458577\", \"price\":\"0.36\", \"size\":\"72\", \"side\":\"BUY\", \"hash\":\"36e8ac1295984759c96fa0386d7f122adf0767b9\", \"best_bid\":\"0.37\", \"best_ask\":\"0.38\"}], \"timestamp\":\"1785211621019\", \"event_type\":\"price_change\"}","received_at":"2026-07-28T04:07:04.986441Z","schema_version":"clob-market-ws.price_change.v1","sequence":null,"server_hash":null,"server_timestamp":"1785211621019","session_id":"2d607381e3054cee91998cdf45a4231c","source":"clob_market_ws"},"received_at":"2026-07-28T04:07:04.986441Z","record_id":"448549202690c0020df04b5407ef8356fe2cecbb755d5a307a6146a3fc29eec9","schema_fingerprint":"4aa3821a28b0b7c2400bc59aba4bcc0a76e971dadd19610d3ad38c768e124dc7","schema_version":"edge-lab-recorder.raw.v1","sequence":null,"source":"clob_market_ws"}
{"event_at":"2026-07-28T04:07:01.021000Z","event_fingerprint":"7f330645c2586d4beafef02f3bed24aa18852542921336cbc44661ad4173606c","payload":{"connection_id":"f6725804f86a4c4eb588e4d5ed7db029","event_at":"2026-07-28T04:07:01.021000Z","event_type":"price_change","frame_hash":"f0e67c24c42dbf5b965af7eb145e866f065c1111b8515c65be3190eab14a7b82","frame_index":0,"kind":"data","monotonic_ns":313608042222958,"payload":{"event_type":"price_change","market":"0xd412ce774cfcf8dc9f71164aac78783978aac7b03871702a3b8a481bd9dc9688","price_changes":[{"asset_id":"96600821790790307414914106093858868634329285205417149685270682748367152458577","best_ask":"0.38","best_bid":"0.37","hash":"d58f8e11c331d14a349beadf5672310c0cc32969","price":"0.36","side":"BUY","size":"62"},{"asset_id":"107603864457683460275633293642179940881969192120168665300712204232021063124301","best_ask":"0.63","best_bid":"0.62","hash":"262f4c8ffd7b83c1b6bec66b6b3fe05bdc0d4ffd","price":"0.64","side":"SELL","size":"62"}],"timestamp":"1785211621021"},"payload_hash":"b3c80b0a9190691f0f67c005e0d68cec8dbdb0932f9ffdd2b3d4f6bd972273f7","raw_frame":"{\"market\":\"0xd412ce774cfcf8dc9f71164aac78783978aac7b03871702a3b8a481bd9dc9688\", \"price_changes\":[{\"asset_id\":\"96600821790790307414914106093858868634329285205417149685270682748367152458577\", \"price\":\"0.36\", \"size\":\"62\", \"side\":\"BUY\", \"hash\":\"d58f8e11c331d14a349beadf5672310c0cc32969\", \"best_bid\":\"0.37\", \"best_ask\":\"0.38\"}, {\"asset_id\":\"107603864457683460275633293642179940881969192120168665300712204232021063124301\", \"price\":\"0.64\", \"size\":\"62\", \"side\":\"SELL\", \"hash\":\"262f4c8ffd7b83c1b6bec66b6b3fe05bdc0d4ffd\", \"best_bid\":\"0.62\", \"best_ask\":\"0.63\"}], \"timestamp\":\"1785211621021\", \"event_type\":\"price_change\"}","received_at":"2026-07-28T04:07:04.991162Z","schema_version":"clob-market-ws.price_change.v1","sequence":null,"server_hash":null,"server_timestamp":"1785211621021","session_id":"2d607381e3054cee91998cdf45a4231c","source":"clob_market_ws"},"received_at":"2026-07-28T04:07:04.991162Z","record_id":"a540e74cedcde6c2f07ca5844f1cdecc9565c9689cf31c371b107a6c0e80c247","schema_fingerprint":"4aa3821a28b0b7c2400bc59aba4bcc0a76e971dadd19610d3ad38c768e124dc7","schema_version":"edge-lab-recorder.raw.v1","sequence":null,"source":"clob_market_ws"}
{"event_at":"2026-07-28T04:07:01.021000Z","event_fingerprint":"cecfcb99ac538274df85d09b255c3b18eb98e17f4c27c7f9a0ada213d2a904bb","payload":{"connection_id":"f6725804f86a4c4eb588e4d5ed7db029","event_at":"2026-07-28T04:07:01.021000Z","event_type":"price_change","frame_hash":"dbf3d1351a436e4e2daf19427cc4e7fef486f59d9df0e6e8f6357e514edffd0d","frame_index":0,"kind":"data","monotonic_ns":313608046258666,"payload":{"event_type":"price_change","market":"0xd412ce774cfcf8dc9f71164aac78783978aac7b03871702a3b8a481bd9dc9688","price_changes":[{"asset_id":"96600821790790307414914106093858868634329285205417149685270682748367152458577","best_ask":"0.38","best_bid":"0.37","hash":"543cf9fe92a1dc80ef50715c724b19f9c397dcfe","price":"0.01","side":"BUY","size":"5603.02"},{"asset_id":"107603864457683460275633293642179940881969192120168665300712204232021063124301","best_ask":"0.63","best_bid":"0.62","hash":"fd138c32903598f617cfdbff96a3391518c75903","price":"0.99","side":"SELL","size":"5603.02"}],"timestamp":"1785211621021"},"payload_hash":"2b2345a7dafd11796af6f8cd5d1fa0f05ebe56dca429ce813e2a1d1732cb03c1","raw_frame":"{\"market\":\"0xd412ce774cfcf8dc9f71164aac78783978aac7b03871702a3b8a481bd9dc9688\", \"price_changes\":[{\"asset_id\":\"96600821790790307414914106093858868634329285205417149685270682748367152458577\", \"price\":\"0.01\", \"size\":\"5603.02\", \"side\":\"BUY\", \"hash\":\"543cf9fe92a1dc80ef50715c724b19f9c397dcfe\", \"best_bid\":\"0.37\", \"best_ask\":\"0.38\"}, {\"asset_id\":\"107603864457683460275633293642179940881969192120168665300712204232021063124301\", \"price\":\"0.99\", \"size\":\"5603.02\", \"side\":\"SELL\", \"hash\":\"fd138c32903598f617cfdbff96a3391518c75903\", \"best_bid\":\"0.62\", \"best_ask\":\"0.63\"}], \"timestamp\":\"1785211621021\", \"event_type\":\"price_change\"}","received_at":"2026-07-28T04:07:04.995199Z","schema_version":"clob-market-ws.price_change.v1","sequence":null,"server_hash":null,"server_timestamp":"1785211621021","session_id":"2d607381e3054cee91998cdf45a4231c","source":"clob_market_ws"},"received_at":"2026-07-28T04:07:04.995199Z","record_id":"bde2df71fcbc64a16785f95ca4acf2871023b2f1c3ddfa4d81f1d5a07c9ab13f","schema_fingerprint":"4aa3821a28b0b7c2400bc59aba4bcc0a76e971dadd19610d3ad38c768e124dc7","schema_version":"edge-lab-recorder.raw.v1","sequence":null,"source":"clob_market_ws"}
{"event_at":"2026-07-28T04:07:01.024000Z","event_fingerprint":"370aa6a164a8f7e0c4e4ec6ee22a65c69d69e025690c8b5e5cde515f32bef39a","payload":{"connection_id":"f6725804f86a4c4eb588e4d5ed7db029","event_at":"2026-07-28T04:07:01.024000Z","event_type":"price_change","frame_hash":"6a278630a815f0e31d69b8ae5b9426f1d7002aa7e0369b20326d698275994cf1","frame_index":0,"kind":"data","monotonic_ns":313608051328958,"payload":{"event_type":"price_change","market":"0xd412ce774cfcf8dc9f71164aac78783978aac7b03871702a3b8a481bd9dc9688","price_changes":[{"asset_id":"107603864457683460275633293642179940881969192120168665300712204232021063124301","best_ask":"0.63","best_bid":"0.62","hash":"a2c4b7c1a01841517c6c3550dc7e281236da9fdf","price":"0.64","side":"SELL","size":"55"},{"asset_id":"96600821790790307414914106093858868634329285205417149685270682748367152458577","best_ask":"0.38","best_bid":"0.37","hash":"4fcb3c9c7162c29e0188291ffe2af9728686a1b1","price":"0.36","side":"BUY","size":"55"}],"timestamp":"1785211621024"},"payload_hash":"6f32c3b433837f8e5252caaa470f198d69d07a778943eed3742a5b65da0f65a5","raw_frame":"{\"market\":\"0xd412ce774cfcf8dc9f71164aac78783978aac7b03871702a3b8a481bd9dc9688\", \"price_changes\":[{\"asset_id\":\"107603864457683460275633293642179940881969192120168665300712204232021063124301\", \"price\":\"0.64\", \"size\":\"55\", \"side\":\"SELL\", \"hash\":\"a2c4b7c1a01841517c6c3550dc7e281236da9fdf\", \"best_bid\":\"0.62\", \"best_ask\":\"0.63\"}, {\"asset_id\":\"96600821790790307414914106093858868634329285205417149685270682748367152458577\", \"price\":\"0.36\", \"size\":\"55\", \"side\":\"BUY\", \"hash\":\"4fcb3c9c7162c29e0188291ffe2af9728686a1b1\", \"best_bid\":\"0.37\", \"best_ask\":\"0.38\"}], \"timestamp\":\"1785211621024\", \"event_type\":\"price_change\"}","received_at":"2026-07-28T04:07:05.000267Z","schema_version":"clob-market-ws.price_change.v1","sequence":null,"server_hash":null,"server_timestamp":"1785211621024","session_id":"2d607381e3054cee91998cdf45a4231c","source":"clob_market_ws"},"received_at":"2026-07-28T04:07:05.000267Z","record_id":"dd304904c9b5d6bee171065d2f0361e81a6e19a3b09adfbdd6ff23d4daf0d7e0","schema_fingerprint":"4aa3821a28b0b7c2400bc59aba4bcc0a76e971dadd19610d3ad38c768e124dc7","schema_version":"edge-lab-recorder.raw.v1","sequence":null,"source":"clob_market_ws"}
{"event_at":"2026-07-28T04:07:01.026000Z","event_fingerprint":"db2ca2a309f712e8dd2ce33433eb23d4ce38ba340364b8a64b00d83313161787","payload":{"connection_id":"f6725804f86a4c4eb588e4d5ed7db029","event_at":"2026-07-28T04:07:01.026000Z","event_type":"price_change","frame_hash":"5f2eb4856a9c5b91452b81a42f570a0f6efe929676f675d00345131ca4bf2989","frame_index":0,"kind":"data","monotonic_ns":313608061468208,"payload":{"event_type":"price_change","market":"0xd412ce774cfcf8dc9f71164aac78783978aac7b03871702a3b8a481bd9dc9688","price_changes":[{"asset_id":"107603864457683460275633293642179940881969192120168665300712204232021063124301","best_ask":"0.63","best_bid":"0.62","hash":"a2461923ff989e3acf23d5ae628898aab8869472","price":"0.04","side":"BUY","size":"623.09"},{"asset_id":"96600821790790307414914106093858868634329285205417149685270682748367152458577","best_ask":"0.38","best_bid":"0.37","hash":"e99c07dee6c8241f2ca866593b4d6a3361d8ee77","price":"0.96","side":"SELL","size":"623.09"}],"timestamp":"1785211621026"},"payload_hash":"17e9ff57889195e2db4898a3da9e155c594ce5d6eb84e8b40b35e236dc7088ac","raw_frame":"{\"market\":\"0xd412ce774cfcf8dc9f71164aac78783978aac7b03871702a3b8a481bd9dc9688\", \"price_changes\":[{\"asset_id\":\"107603864457683460275633293642179940881969192120168665300712204232021063124301\", \"price\":\"0.04\", \"size\":\"623.09\", \"side\":\"BUY\", \"hash\":\"a2461923ff989e3acf23d5ae628898aab8869472\", \"best_bid\":\"0.62\", \"best_ask\":\"0.63\"}, {\"asset_id\":\"96600821790790307414914106093858868634329285205417149685270682748367152458577\", \"price\":\"0.96\", \"size\":\"623.09\", \"side\":\"SELL\", \"hash\":\"e99c07dee6c8241f2ca866593b4d6a3361d8ee77\", \"best_bid\":\"0.37\", \"best_ask\":\"0.38\"}], \"timestamp\":\"1785211621026\", \"event_type\":\"price_change\"}","received_at":"2026-07-28T04:07:05.010406Z","schema_version":"clob-market-ws.price_change.v1","sequence":null,"server_hash":null,"server_timestamp":"1785211621026","session_id":"2d607381e3054cee91998cdf45a4231c","source":"clob_market_ws"},"received_at":"2026-07-28T04:07:05.010406Z","record_id":"685f6f8f492b36813efc088e7ad4d5b6e50db3bf34452342daf90ddd2eddf9a0","schema_fingerprint":"4aa3821a28b0b7c2400bc59aba4bcc0a76e971dadd19610d3ad38c768e124dc7","schema_version":"edge-lab-recorder.raw.v1","sequence":null,"source":"clob_market_ws"}
{"event_at":"2026-07-28T04:07:01.028000Z","event_fingerprint":"85a3dffdac4cf56b6dd997d93d2e9d3a96e3d9e44636cad2fe4d08b1771d1db6","payload":{"connection_id":"f6725804f86a4c4eb588e4d5ed7db029","event_at":"2026-07-28T04:07:01.028000Z","event_type":"price_change","frame_hash":"3c5153224ff946200a4cb648f2ebe8f81a24862edc4e096b89b3578f352a04c6","frame_index":0,"kind":"data","monotonic_ns":313608067013375,"payload":{"event_type":"price_change","market":"0xd412ce774cfcf8dc9f71164aac78783978aac7b03871702a3b8a481bd9dc9688","price_changes":[{"asset_id":"96600821790790307414914106093858868634329285205417149685270682748367152458577","best_ask":"0.38","best_bid":"0.37","hash":"bae21f4ab39b692f9c094d237d32ae1f85760536","price":"0.36","side":"BUY","size":"50"},{"asset_id":"107603864457683460275633293642179940881969192120168665300712204232021063124301","best_ask":"0.63","best_bid":"0.62","hash":"901f7aeb8d9b2c792b927db5c535fa2774976f0f","price":"0.64","side":"SELL","size":"50"}],"timestamp":"1785211621028"},"payload_hash":"3b982ec1d82a3b68a5d4c43cc6e1fff81eb42bb3ccfa230bb7c1b008c5b1dec0","raw_frame":"{\"market\":\"0xd412ce774cfcf8dc9f71164aac78783978aac7b03871702a3b8a481bd9dc9688\", \"price_changes\":[{\"asset_id\":\"96600821790790307414914106093858868634329285205417149685270682748367152458577\", \"price\":\"0.36\", \"size\":\"50\", \"side\":\"BUY\", \"hash\":\"bae21f4ab39b692f9c094d237d32ae1f85760536\", \"best_bid\":\"0.37\", \"best_ask\":\"0.38\"}, {\"asset_id\":\"107603864457683460275633293642179940881969192120168665300712204232021063124301\", \"price\":\"0.64\", \"size\":\"50\", \"side\":\"SELL\", \"hash\":\"901f7aeb8d9b2c792b927db5c535fa2774976f0f\", \"best_bid\":\"0.62\", \"best_ask\":\"0.63\"}], \"timestamp\":\"1785211621028\", \"event_type\":\"price_change\"}","received_at":"2026-07-28T04:07:05.015953Z","schema_version":"clob-market-ws.price_change.v1","sequence":null,"server_hash":null,"server_timestamp":"1785211621028","session_id":"2d607381e3054cee91998cdf45a4231c","source":"clob_market_ws"},"received_at":"2026-07-28T04:07:05.015953Z","record_id":"1c29af1ddd4cb8592ff616376b986f8e6fa8b76a9bde58222ee1ebbf09e9beaf","schema_fingerprint":"4aa3821a28b0b7c2400bc59aba4bcc0a76e971dadd19610d3ad38c768e124dc7","schema_version":"edge-lab-recorder.raw.v1","sequence":null,"source":"clob_market_ws"}
{"event_at":"2026-07-28T04:07:01.028000Z","event_fingerprint":"a873e214e0562e1a450d2dd2b4dc021093022b446095daf1cd49fde49cdebe85","payload":{"connection_id":"f6725804f86a4c4eb588e4d5ed7db029","event_at":"2026-07-28T04:07:01.028000Z","event_type":"price_change","frame_hash":"dbea686b8d038323d4d68a3e76d22daabc094f6d865a4de2a44980d9d3404c48","frame_index":0,"kind":"data","monotonic_ns":313608076997875,"payload":{"event_type":"price_change","market":"0xd412ce774cfcf8dc9f71164aac78783978aac7b03871702a3b8a481bd9dc9688","price_changes":[{"asset_id":"96600821790790307414914106093858868634329285205417149685270682748367152458577","best_ask":"0.38","best_bid":"0.37","hash":"fb8d63fc912a2f2a35d5b16b5dd8e8126981a0dc","price":"0.36","side":"BUY","size":"44"},{"asset_id":"107603864457683460275633293642179940881969192120168665300712204232021063124301","best_ask":"0.63","best_bid":"0.62","hash":"b451fae716070646b9da2a27748bdf6cfffbde76","price":"0.64","side":"SELL","size":"44"}],"timestamp":"1785211621028"},"payload_hash":"4dea9cff59f7be53a8ff0e16c5de6b45c838556e597de81197376c7748bf3eb5","raw_frame":"{\"market\":\"0xd412ce774cfcf8dc9f71164aac78783978aac7b03871702a3b8a481bd9dc9688\", \"price_changes\":[{\"asset_id\":\"96600821790790307414914106093858868634329285205417149685270682748367152458577\", \"price\":\"0.36\", \"size\":\"44\", \"side\":\"BUY\", \"hash\":\"fb8d63fc912a2f2a35d5b16b5dd8e8126981a0dc\", \"best_bid\":\"0.37\", \"best_ask\":\"0.38\"}, {\"asset_id\":\"107603864457683460275633293642179940881969192120168665300712204232021063124301\", \"price\":\"0.64\", \"size\":\"44\", \"side\":\"SELL\", \"hash\":\"b451fae716070646b9da2a27748bdf6cfffbde76\", \"best_bid\":\"0.62\", \"best_ask\":\"0.63\"}], \"timestamp\":\"1785211621028\", \"event_type\":\"price_change\"}","received_at":"2026-07-28T04:07:05.025932Z","schema_version":"clob-market-ws.price_change.v1","sequence":null,"server_hash":null,"server_timestamp":"1785211621028","session_id":"2d607381e3054cee91998cdf45a4231c","source":"clob_market_ws"},"received_at":"2026-07-28T04:07:05.025932Z","record_id":"f6c496f7609b3637f9db4d54709fdb05b0e4366b3b770bed8ea37e2683d43c2d","schema_fingerprint":"4aa3821a28b0b7c2400bc59aba4bcc0a76e971dadd19610d3ad38c768e124dc7","schema_version":"edge-lab-recorder.raw.v1","sequence":null,"source":"clob_market_ws"}
{"event_at":"2026-07-28T04:07:01.043000Z","event_fingerprint":"7930fbd64cf0e05f28fe33ee6618a5abd326f79bf011b1c06a8eb300ce19066d","payload":{"connection_id":"f6725804f86a4c4eb588e4d5ed7db029","event_at":"2026-07-28T04:07:01.043000Z","event_type":"price_change","frame_hash":"fb199ce7e422b514444152221c856bd1e4e53a0b68def5ea1135daf8d36398ce","frame_index":0,"kind":"data","monotonic_ns":313608082588208,"payload":{"event_type":"price_change","market":"0xd412ce774cfcf8dc9f71164aac78783978aac7b03871702a3b8a481bd9dc9688","price_changes":[{"asset_id":"96600821790790307414914106093858868634329285205417149685270682748367152458577","best_ask":"0.38","best_bid":"0.37","hash":"a6beeb0fb0ac0312600702d1695ea236322e516a","price":"0.01","side":"BUY","size":"5598.02"},{"asset_id":"107603864457683460275633293642179940881969192120168665300712204232021063124301","best_ask":"0.63","best_bid":"0.62","hash":"a062c0c382df57c8b9822fa28d42dff59dd562e7","price":"0.99","side":"SELL","size":"5598.02"}],"timestamp":"1785211621043"},"payload_hash":"746b8334d6196bdd6103109bd1a1c4f547d6b30ef65acc7942985bcc40307955","raw_frame":"{\"market\":\"0xd412ce774cfcf8dc9f71164aac78783978aac7b03871702a3b8a481bd9dc9688\", \"price_changes\":[{\"asset_id\":\"96600821790790307414914106093858868634329285205417149685270682748367152458577\", \"price\":\"0.01\", \"size\":\"5598.02\", \"side\":\"BUY\", \"hash\":\"a6beeb0fb0ac0312600702d1695ea236322e516a\", \"best_bid\":\"0.37\", \"best_ask\":\"0.38\"}, {\"asset_id\":\"107603864457683460275633293642179940881969192120168665300712204232021063124301\", \"price\":\"0.99\", \"size\":\"5598.02\", \"side\":\"SELL\", \"hash\":\"a062c0c382df57c8b9822fa28d42dff59dd562e7\", \"best_bid\":\"0.62\", \"best_ask\":\"0.63\"}], \"timestamp\":\"1785211621043\", \"event_type\":\"price_change\"}","received_at":"2026-07-28T04:07:05.031527Z","schema_version":"clob-market-ws.price_change.v1","sequence":null,"server_hash":null,"server_timestamp":"1785211621043","session_id":"2d607381e3054cee91998cdf45a4231c","source":"clob_market_ws"},"received_at":"2026-07-28T04:07:05.031527Z","record_id":"d6e1c18858a980f3daf0064c50373dcc7233ac159511d208922ad41c87ec3daf","schema_fingerprint":"4aa3821a28b0b7c2400bc59aba4bcc0a76e971dadd19610d3ad38c768e124dc7","schema_version":"edge-lab-recorder.raw.v1","sequence":null,"source":"clob_market_ws"}
{"event_at":"2026-07-28T04:07:01.044000Z","event_fingerprint":"810ebce87c444c51aca7a652943947517c68e510614f1c95438013e3f64ab2ab","payload":{"connection_id":"f6725804f86a4c4eb588e4d5ed7db029","event_at":"2026-07-28T04:07:01.044000Z","event_type":"price_change","frame_hash":"fa1ce191df6e39e9a3723743bf1c541ebdbb9f2515240f02a4c32a15259cfc1a","frame_index":0,"kind":"data","monotonic_ns":313608094302250,"payload":{"event_type":"price_change","market":"0xd412ce774cfcf8dc9f71164aac78783978aac7b03871702a3b8a481bd9dc9688","price_changes":[{"asset_id":"107603864457683460275633293642179940881969192120168665300712204232021063124301","best_ask":"0.63","best_bid":"0.62","hash":"47d01a052b31d62b8c2ceae6a8078fab5e733e0c","price":"0.54","side":"BUY","size":"142"},{"asset_id":"96600821790790307414914106093858868634329285205417149685270682748367152458577","best_ask":"0.38","best_bid":"0.37","hash":"2c56d9938e72da54f758fdb5e9356b53759245de","price":"0.46","side":"SELL","size":"142"}],"timestamp":"1785211621044"},"payload_hash":"f1458f3e54766265ce5303a0e067b1ab92032394ff5de4cb22ab4b11ae3de4b5","raw_frame":"{\"market\":\"0xd412ce774cfcf8dc9f71164aac78783978aac7b03871702a3b8a481bd9dc9688\", \"price_changes\":[{\"asset_id\":\"107603864457683460275633293642179940881969192120168665300712204232021063124301\", \"price\":\"0.54\", \"size\":\"142\", \"side\":\"BUY\", \"hash\":\"47d01a052b31d62b8c2ceae6a8078fab5e733e0c\", \"best_bid\":\"0.62\", \"best_ask\":\"0.63\"}, {\"asset_id\":\"96600821790790307414914106093858868634329285205417149685270682748367152458577\", \"price\":\"0.46\", \"size\":\"142\", \"side\":\"SELL\", \"hash\":\"2c56d9938e72da54f758fdb5e9356b53759245de\", \"best_bid\":\"0.37\", \"best_ask\":\"0.38\"}], \"timestamp\":\"1785211621044\", \"event_type\":\"price_change\"}","received_at":"2026-07-28T04:07:05.043240Z","schema_version":"clob-market-ws.price_change.v1","sequence":null,"server_hash":null,"server_timestamp":"1785211621044","session_id":"2d607381e3054cee91998cdf45a4231c","source":"clob_market_ws"},"received_at":"2026-07-28T04:07:05.043240Z","record_id":"2ae57a3cd39b400c7ee4a7a825f68bd78242a408f7809b67d0cb08ffbf7779a4","schema_fingerprint":"4aa3821a28b0b7c2400bc59aba4bcc0a76e971dadd19610d3ad38c768e124dc7","schema_version":"edge-lab-recorder.raw.v1","sequence":null,"source":"clob_market_ws"}
{"event_at":"2026-07-28T04:07:01.046000Z","event_fingerprint":"b7fc0e265cfca749e1b099ae3baa6d0488c154568feb1e1f3d0c1bcdbc34b7fc","payload":{"connection_id":"f6725804f86a4c4eb588e4d5ed7db029","event_at":"2026-07-28T04:07:01.046000Z","event_type":"price_change","frame_hash":"7ae336909a01164def260e7e6357f6d0ccb57f1ddef87cf8077cea1e2730563a","frame_index":0,"kind":"data","monotonic_ns":313608097528625,"payload":{"event_type":"price_change","market":"0xd412ce774cfcf8dc9f71164aac78783978aac7b03871702a3b8a481bd9dc9688","price_changes":[{"asset_id":"107603864457683460275633293642179940881969192120168665300712204232021063124301","best_ask":"0.63","best_bid":"0.62","hash":"78f1ae6b6572959648891bd0c2d8eaa9ca9d0f12","price":"0.41","side":"BUY","size":"98.7"},{"asset_id":"96600821790790307414914106093858868634329285205417149685270682748367152458577","best_ask":"0.38","best_bid":"0.37","hash":"5051cccb292311a3dcf74bbcd1553113b9513588","price":"0.59","side":"SELL","size":"98.7"}],"timestamp":"1785211621046"},"payload_hash":"bed0e69f676c20bcc4666369a0c57cf5b888158e6a72e84a2559510e764390ae","raw_frame":"{\"market\":\"0xd412ce774cfcf8dc9f71164aac78783978aac7b03871702a3b8a481bd9dc9688\", \"price_changes\":[{\"asset_id\":\"107603864457683460275633293642179940881969192120168665300712204232021063124301\", \"price\":\"0.41\", \"size\":\"98.7\", \"side\":\"BUY\", \"hash\":\"78f1ae6b6572959648891bd0c2d8eaa9ca9d0f12\", \"best_bid\":\"0.62\", \"best_ask\":\"0.63\"}, {\"asset_id\":\"96600821790790307414914106093858868634329285205417149685270682748367152458577\", \"price\":\"0.59\", \"size\":\"98.7\", \"side\":\"SELL\", \"hash\":\"5051cccb292311a3dcf74bbcd1553113b9513588\", \"best_bid\":\"0.37\", \"best_ask\":\"0.38\"}], \"timestamp\":\"1785211621046\", \"event_type\":\"price_change\"}","received_at":"2026-07-28T04:07:05.046466Z","schema_version":"clob-market-ws.price_change.v1","sequence":null,"server_hash":null,"server_timestamp":"1785211621046","session_id":"2d607381e3054cee91998cdf45a4231c","source":"clob_market_ws"},"received_at":"2026-07-28T04:07:05.046466Z","record_id":"65dddd42e2788685e1b1286f906569e631f2c1694d41757a8fd579cc963e62bf","schema_fingerprint":"4aa3821a28b0b7c2400bc59aba4bcc0a76e971dadd19610d3ad38c768e124dc7","schema_version":"edge-lab-recorder.raw.v1","sequence":null,"source":"clob_market_ws"}
{"event_at":"2026-07-28T04:07:01.051000Z","event_fingerprint":"7ea0bf7f9c53fa7c70df7a0f632ee0a9b274e81cd46e3ec050e38b9f6cf3182a","payload":{"connection_id":"f6725804f86a4c4eb588e4d5ed7db029","event_at":"2026-07-28T04:07:01.051000Z","event_type":"price_change","frame_hash":"f38251b198061af2fce631d871ebace63ff4db425bb2167754e8bdb240e79af3","frame_index":0,"kind":"data","monotonic_ns":313608102879958,"payload":{"event_type":"price_change","market":"0xd412ce774cfcf8dc9f71164aac78783978aac7b03871702a3b8a481bd9dc9688","price_changes":[{"asset_id":"107603864457683460275633293642179940881969192120168665300712204232021063124301","best_ask":"0.63","best_bid":"0.62","hash":"05d524c99b6eb9862301c0b8525332ba9d716e7e","price":"0.41","side":"BUY","size":"17.4"},{"asset_id":"96600821790790307414914106093858868634329285205417149685270682748367152458577","best_ask":"0.38","best_bid":"0.37","hash":"18f906c520328e7f5adf8ebce5564a8e18d41e6a","price":"0.59","side":"SELL","size":"17.4"}],"timestamp":"1785211621051"},"payload_hash":"24aa8a0e3b6e0f50061de1eeddc9303a473e46dbe25af13193da533dae95ed7f","raw_frame":"{\"market\":\"0xd412ce774cfcf8dc9f71164aac78783978aac7b03871702a3b8a481bd9dc9688\", \"price_changes\":[{\"asset_id\":\"107603864457683460275633293642179940881969192120168665300712204232021063124301\", \"price\":\"0.41\", \"size\":\"17.4\", \"side\":\"BUY\", \"hash\":\"05d524c99b6eb9862301c0b8525332ba9d716e7e\", \"best_bid\":\"0.62\", \"best_ask\":\"0.63\"}, {\"asset_id\":\"96600821790790307414914106093858868634329285205417149685270682748367152458577\", \"price\":\"0.59\", \"size\":\"17.4\", \"side\":\"SELL\", \"hash\":\"18f906c520328e7f5adf8ebce5564a8e18d41e6a\", \"best_bid\":\"0.37\", \"best_ask\":\"0.38\"}], \"timestamp\":\"1785211621051\", \"event_type\":\"price_change\"}","received_at":"2026-07-28T04:07:05.051816Z","schema_version":"clob-market-ws.price_change.v1","sequence":null,"server_hash":null,"server_timestamp":"1785211621051","session_id":"2d607381e3054cee91998cdf45a4231c","source":"clob_market_ws"},"received_at":"2026-07-28T04:07:05.051816Z","record_id":"6289861972223d0b9b05aa9438fa6c02ff92b505fe3321937e02cff952c343d9","schema_fingerprint":"4aa3821a28b0b7c2400bc59aba4bcc0a76e971dadd19610d3ad38c768e124dc7","schema_version":"edge-lab-recorder.raw.v1","sequence":null,"source":"clob_market_ws"}
{"event_at":"2026-07-28T04:07:01.052000Z","event_fingerprint":"396a88b6402a2738af8ed55e0529e17cd38f49996b723dfae9397a4935c19f02","payload":{"connection_id":"f6725804f86a4c4eb588e4d5ed7db029","event_at":"2026-07-28T04:07:01.052000Z","event_type":"price_change","frame_hash":"8b056609455671a63a3e3795970bac45be7697dcf3219b2af4cef9ec04922e4e","frame_index":0,"kind":"data","monotonic_ns":313608107173833,"payload":{"event_type":"price_change","market":"0xd412ce774cfcf8dc9f71164aac78783978aac7b03871702a3b8a481bd9dc9688","price_changes":[{"asset_id":"96600821790790307414914106093858868634329285205417149685270682748367152458577","best_ask":"0.38","best_bid":"0.37","hash":"495b8b89fd0c1df9a1e865f73bd9fd0f65d23ac6","price":"0.12","side":"BUY","size":"176.52"},{"asset_id":"107603864457683460275633293642179940881969192120168665300712204232021063124301","best_ask":"0.63","best_bid":"0.62","hash":"67a2b3c12796b7c3db3e88f6a0cf39d9b3f38740","price":"0.88","side":"SELL","size":"176.52"}],"timestamp":"1785211621052"},"payload_hash":"d7604b7e05a66da40765fa2f9a008f0bb5a8fb4955cc3e0f19bfc78a5bf4f423","raw_frame":"{\"market\":\"0xd412ce774cfcf8dc9f71164aac78783978aac7b03871702a3b8a481bd9dc9688\", \"price_changes\":[{\"asset_id\":\"96600821790790307414914106093858868634329285205417149685270682748367152458577\", \"price\":\"0.12\", \"size\":\"176.52\", \"side\":\"BUY\", \"hash\":\"495b8b89fd0c1df9a1e865f73bd9fd0f65d23ac6\", \"best_bid\":\"0.37\", \"best_ask\":\"0.38\"}, {\"asset_id\":\"107603864457683460275633293642179940881969192120168665300712204232021063124301\", \"price\":\"0.88\", \"size\":\"176.52\", \"side\":\"SELL\", \"hash\":\"67a2b3c12796b7c3db3e88f6a0cf39d9b3f38740\", \"best_bid\":\"0.62\", \"best_ask\":\"0.63\"}], \"timestamp\":\"1785211621052\", \"event_type\":\"price_change\"}","received_at":"2026-07-28T04:07:05.056108Z","schema_version":"clob-market-ws.price_change.v1","sequence":null,"server_hash":null,"server_timestamp":"1785211621052","session_id":"2d607381e3054cee91998cdf45a4231c","source":"clob_market_ws"},"received_at":"2026-07-28T04:07:05.056108Z","record_id":"e9bf8374888478ceef382d6ea87840e5c79af57685d903b76780a4d20555343e","schema_fingerprint":"4aa3821a28b0b7c2400bc59aba4bcc0a76e971dadd19610d3ad38c768e124dc7","schema_version":"edge-lab-recorder.raw.v1","sequence":null,"source":"clob_market_ws"}
{"event_at":"2026-07-28T04:07:01.055000Z","event_fingerprint":"8408648bff5ef1f66559156e739d5fdf4676c7542f8884cd7e709e8900b36bb0","payload":{"connection_id":"f6725804f86a4c4eb588e4d5ed7db029","event_at":"2026-07-28T04:07:01.055000Z","event_type":"price_change","frame_hash":"c1611b591bb29890c20d4d215eba25ffb75b9d9f7383334e9f43a649a13b6c9b","frame_index":0,"kind":"data","monotonic_ns":313608114618583,"payload":{"event_type":"price_change","market":"0xd412ce774cfcf8dc9f71164aac78783978aac7b03871702a3b8a481bd9dc9688","price_changes":[{"asset_id":"96600821790790307414914106093858868634329285205417149685270682748367152458577","best_ask":"0.38","best_bid":"0.37","hash":"c9dfe48dfc7457b9b9a42fa2572365de89e00450","price":"0.13","side":"BUY","size":"37.5"},{"asset_id":"107603864457683460275633293642179940881969192120168665300712204232021063124301","best_ask":"0.63","best_bid":"0.62","hash":"fd2881f466d3b46caaa732838784aae34e18e5ab","price":"0.87","side":"SELL","size":"37.5"}],"timestamp":"1785211621055"},"payload_hash":"34b77c9bce02a6137a0355e44c4810b840c2350c13a64a0d448434766441add6","raw_frame":"{\"market\":\"0xd412ce774cfcf8dc9f71164aac78783978aac7b03871702a3b8a481bd9dc9688\", \"price_changes\":[{\"asset_id\":\"96600821790790307414914106093858868634329285205417149685270682748367152458577\", \"price\":\"0.13\", \"size\":\"37.5\", \"side\":\"BUY\", \"hash\":\"c9dfe48dfc7457b9b9a42fa2572365de89e00450\", \"best_bid\":\"0.37\", \"best_ask\":\"0.38\"}, {\"asset_id\":\"107603864457683460275633293642179940881969192120168665300712204232021063124301\", \"price\":\"0.87\", \"size\":\"37.5\", \"side\":\"SELL\", \"hash\":\"fd2881f466d3b46caaa732838784aae34e18e5ab\", \"best_bid\":\"0.62\", \"best_ask\":\"0.63\"}], \"timestamp\":\"1785211621055\", \"event_type\":\"price_change\"}","received_at":"2026-07-28T04:07:05.063555Z","schema_version":"clob-market-ws.price_change.v1","sequence":null,"server_hash":null,"server_timestamp":"1785211621055","session_id":"2d607381e3054cee91998cdf45a4231c","source":"clob_market_ws"},"received_at":"2026-07-28T04:07:05.063555Z","record_id":"44cb6201552940179cb05addd0fe678f0337a736030a59b8932ba8c1c0f8cc31","schema_fingerprint":"4aa3821a28b0b7c2400bc59aba4bcc0a76e971dadd19610d3ad38c768e124dc7","schema_version":"edge-lab-recorder.raw.v1","sequence":null,"source":"clob_market_ws"}
{"event_at":"2026-07-28T04:07:01.075000Z","event_fingerprint":"6ceb743dd80e084350c7310e7ce7d76c53fe42fea3f6a31c34a0d0f975768a68","payload":{"connection_id":"f6725804f86a4c4eb588e4d5ed7db029","event_at":"2026-07-28T04:07:01.075000Z","event_type":"price_change","frame_hash":"b9be28296be39073940dda74d4604d2df86be4e8d7b9dc8b9badf5d747025ee2","frame_index":0,"kind":"data","monotonic_ns":313608122634333,"payload":{"event_type":"price_change","market":"0xd412ce774cfcf8dc9f71164aac78783978aac7b03871702a3b8a481bd9dc9688","price_changes":[{"asset_id":"107603864457683460275633293642179940881969192120168665300712204232021063124301","best_ask":"0.63","best_bid":"0.62","hash":"2fdfd54fcd827e90f475d44f589c3df2d1e9630b","price":"0.04","side":"BUY","size":"618.09"},{"asset_id":"96600821790790307414914106093858868634329285205417149685270682748367152458577","best_ask":"0.38","best_bid":"0.37","hash":"a751b8891cbf6cb3d9e13f789c363b3c68871797","price":"0.96","side":"SELL","size":"618.09"}],"timestamp":"1785211621075"},"payload_hash":"fcfe72d931c4d19f17e4e36587a6c39d7db072036662da62cf2e268efae88544","raw_frame":"{\"market\":\"0xd412ce774cfcf8dc9f71164aac78783978aac7b03871702a3b8a481bd9dc9688\", \"price_changes\":[{\"asset_id\":\"107603864457683460275633293642179940881969192120168665300712204232021063124301\", \"price\":\"0.04\", \"size\":\"618.09\", \"side\":\"BUY\", \"hash\":\"2fdfd54fcd827e90f475d44f589c3df2d1e9630b\", \"best_bid\":\"0.62\", \"best_ask\":\"0.63\"}, {\"asset_id\":\"96600821790790307414914106093858868634329285205417149685270682748367152458577\", \"price\":\"0.96\", \"size\":\"618.09\", \"side\":\"SELL\", \"hash\":\"a751b8891cbf6cb3d9e13f789c363b3c68871797\", \"best_bid\":\"0.37\", \"best_ask\":\"0.38\"}], \"timestamp\":\"1785211621075\", \"event_type\":\"price_change\"}","received_at":"2026-07-28T04:07:05.071572Z","schema_version":"clob-market-ws.price_change.v1","sequence":null,"server_hash":null,"server_timestamp":"1785211621075","session_id":"2d607381e3054cee91998cdf45a4231c","source":"clob_market_ws"},"received_at":"2026-07-28T04:07:05.071572Z","record_id":"8e2288fb148ca96239bcf149767abee7b555ba03bf90336595a548c87bdaa4e9","schema_fingerprint":"4aa3821a28b0b7c2400bc59aba4bcc0a76e971dadd19610d3ad38c768e124dc7","schema_version":"edge-lab-recorder.raw.v1","sequence":null,"source":"clob_market_ws"}
{"event_at":"2026-07-28T04:07:01.105000Z","event_fingerprint":"72739c3108f7fb98ae6b50f9577bfe089040c490c0185d97e1843f44b485a7ae","payload":{"connection_id":"f6725804f86a4c4eb588e4d5ed7db029","event_at":"2026-07-28T04:07:01.105000Z","event_type":"price_change","frame_hash":"7e51db50f8ae4bdbccce925042633fb2e0e0cb02f91e97b4f7e523add3d5fc18","frame_index":0,"kind":"data","monotonic_ns":313608126812458,"payload":{"event_type":"price_change","market":"0xd412ce774cfcf8dc9f71164aac78783978aac7b03871702a3b8a481bd9dc9688","price_changes":[{"asset_id":"96600821790790307414914106093858868634329285205417149685270682748367152458577","best_ask":"0.38","best_bid":"0.37","hash":"27123dfa8f7ede84cd111827ba02c350c1e732ac","price":"0.33","side":"BUY","size":"52.6"},{"asset_id":"107603864457683460275633293642179940881969192120168665300712204232021063124301","best_ask":"0.63","best_bid":"0.62","hash":"16cff01c852c17641181bc35083f46a135f8a567","price":"0.67","side":"SELL","size":"52.6"}],"timestamp":"1785211621105"},"payload_hash":"a96834a1cce903f4fb8b6bfd82e3ea9716d3cfdbd7773481dd68008c2e64f0b4","raw_frame":"{\"market\":\"0xd412ce774cfcf8dc9f71164aac78783978aac7b03871702a3b8a481bd9dc9688\", \"price_changes\":[{\"asset_id\":\"96600821790790307414914106093858868634329285205417149685270682748367152458577\", \"price\":\"0.33\", \"size\":\"52.6\", \"side\":\"BUY\", \"hash\":\"27123dfa8f7ede84cd111827ba02c350c1e732ac\", \"best_bid\":\"0.37\", \"best_ask\":\"0.38\"}, {\"asset_id\":\"107603864457683460275633293642179940881969192120168665300712204232021063124301\", \"price\":\"0.67\", \"size\":\"52.6\", \"side\":\"SELL\", \"hash\":\"16cff01c852c17641181bc35083f46a135f8a567\", \"best_bid\":\"0.62\", \"best_ask\":\"0.63\"}], \"timestamp\":\"1785211621105\", \"event_type\":\"price_change\"}","received_at":"2026-07-28T04:07:05.075752Z","schema_version":"clob-market-ws.price_change.v1","sequence":null,"server_hash":null,"server_timestamp":"1785211621105","session_id":"2d607381e3054cee91998cdf45a4231c","source":"clob_market_ws"},"received_at":"2026-07-28T04:07:05.075752Z","record_id":"747ebfcd4d0fd6c1530140e3773392c5ca806143e13bb4ef441f7a8daf284d7c","schema_fingerprint":"4aa3821a28b0b7c2400bc59aba4bcc0a76e971dadd19610d3ad38c768e124dc7","schema_version":"edge-lab-recorder.raw.v1","sequence":null,"source":"clob_market_ws"}
{"event_at":"2026-07-28T04:07:01.107000Z","event_fingerprint":"8fc86052ec32542c4c32435a9593c983ee77152a70bc123781ea77ef561188c3","payload":{"connection_id":"f6725804f86a4c4eb588e4d5ed7db029","event_at":"2026-07-28T04:07:01.107000Z","event_type":"price_change","frame_hash":"082337cfc4645f09aab988e3e5f5d51f107c8290ce5d2bd6fb2ff1ec0abe372e","frame_index":0,"kind":"data","monotonic_ns":313608130082791,"payload":{"event_type":"price_change","market":"0xd412ce774cfcf8dc9f71164aac78783978aac7b03871702a3b8a481bd9dc9688","price_changes":[{"asset_id":"96600821790790307414914106093858868634329285205417149685270682748367152458577","best_ask":"0.38","best_bid":"0.37","hash":"07d637e0beb4db6a9058834e12252c0355e8fcfa","price":"0.25","side":"BUY","size":"112.31"},{"asset_id":"107603864457683460275633293642179940881969192120168665300712204232021063124301","best_ask":"0.63","best_bid":"0.62","hash":"21219a29441e6d017c6ace0df835406bf98c70c3","price":"0.75","side":"SELL","size":"112.31"}],"timestamp":"1785211621107"},"payload_hash":"4f9e5b79ed144aaf8ddbb9834f4444ecb93db9728883d2c95089049a9e54b069","raw_frame":"{\"market\":\"0xd412ce774cfcf8dc9f71164aac78783978aac7b03871702a3b8a481bd9dc9688\", \"price_changes\":[{\"asset_id\":\"96600821790790307414914106093858868634329285205417149685270682748367152458577\", \"price\":\"0.25\", \"size\":\"112.31\", \"side\":\"BUY\", \"hash\":\"07d637e0beb4db6a9058834e12252c0355e8fcfa\", \"best_bid\":\"0.37\", \"best_ask\":\"0.38\"}, {\"asset_id\":\"107603864457683460275633293642179940881969192120168665300712204232021063124301\", \"price\":\"0.75\", \"size\":\"112.31\", \"side\":\"SELL\", \"hash\":\"21219a29441e6d017c6ace0df835406bf98c70c3\", \"best_bid\":\"0.62\", \"best_ask\":\"0.63\"}], \"timestamp\":\"1785211621107\", \"event_type\":\"price_change\"}","received_at":"2026-07-28T04:07:05.079020Z","schema_version":"clob-market-ws.price_change.v1","sequence":null,"server_hash":null,"server_timestamp":"1785211621107","session_id":"2d607381e3054cee91998cdf45a4231c","source":"clob_market_ws"},"received_at":"2026-07-28T04:07:05.079020Z","record_id":"c33e43aa0a80da34149d6da2c13f603ab92313467c15ff34eaaf189bcae4b60f","schema_fingerprint":"4aa3821a28b0b7c2400bc59aba4bcc0a76e971dadd19610d3ad38c768e124dc7","schema_version":"edge-lab-recorder.raw.v1","sequence":null,"source":"clob_market_ws"}
{"event_at":"2026-07-28T04:07:01.108000Z","event_fingerprint":"193bfcbce4c763a63c04db63e33dd04fd79637a054e8f652c94ec69754bb6c6d","payload":{"connection_id":"f6725804f86a4c4eb588e4d5ed7db029","event_at":"2026-07-28T04:07:01.108000Z","event_type":"price_change","frame_hash":"8a3f972f54866d728eb49fd6eaf0e3484826b9883924ae0a318b77b1699bd383","frame_index":0,"kind":"data","monotonic_ns":313608138181875,"payload":{"event_type":"price_change","market":"0xd412ce774cfcf8dc9f71164aac78783978aac7b03871702a3b8a481bd9dc9688","price_changes":[{"asset_id":"107603864457683460275633293642179940881969192120168665300712204232021063124301","best_ask":"0.63","best_bid":"0.62","hash":"f8b551d1da0d06e70810903c9814566b4e25dcdc","price":"0.62","side":"BUY","size":"38"},{"asset_id":"96600821790790307414914106093858868634329285205417149685270682748367152458577","best_ask":"0.38","best_bid":"0.37","hash":"b7682bf5d0c010582a9b40527705ec3dedf00283","price":"0.38","side":"SELL","size":"38"}],"timestamp":"1785211621108"},"payload_hash":"b79cc21152216bb4529285302a479b26c4e1b5d6ac49078131fe08dea4db6ec7","raw_frame":"{\"market\":\"0xd412ce774cfcf8dc9f71164aac78783978aac7b03871702a3b8a481bd9dc9688\", \"price_changes\":[{\"asset_id\":\"107603864457683460275633293642179940881969192120168665300712204232021063124301\", \"price\":\"0.62\", \"size\":\"38\", \"side\":\"BUY\", \"hash\":\"f8b551d1da0d06e70810903c9814566b4e25dcdc\", \"best_bid\":\"0.62\", \"best_ask\":\"0.63\"}, {\"asset_id\":\"96600821790790307414914106093858868634329285205417149685270682748367152458577\", \"price\":\"0.38\", \"size\":\"38\", \"side\":\"SELL\", \"hash\":\"b7682bf5d0c010582a9b40527705ec3dedf00283\", \"best_bid\":\"0.37\", \"best_ask\":\"0.38\"}], \"timestamp\":\"1785211621108\", \"event_type\":\"price_change\"}","received_at":"2026-07-28T04:07:05.087120Z","schema_version":"clob-market-ws.price_change.v1","sequence":null,"server_hash":null,"server_timestamp":"1785211621108","session_id":"2d607381e3054cee91998cdf45a4231c","source":"clob_market_ws"},"received_at":"2026-07-28T04:07:05.087120Z","record_id":"b61c37d85ea321c42b6bc1295688abfac4a8a4619cfb9efd772089e7b4f31cb7","schema_fingerprint":"4aa3821a28b0b7c2400bc59aba4bcc0a76e971dadd19610d3ad38c768e124dc7","schema_version":"edge-lab-recorder.raw.v1","sequence":null,"source":"clob_market_ws"}
{"event_at":"2026-07-28T04:07:01.110000Z","event_fingerprint":"819a2a61e592c38842b34a668902cbe63687481dbfb18bd5236bca2ddf320610","payload":{"connection_id":"f6725804f86a4c4eb588e4d5ed7db029","event_at":"2026-07-28T04:07:01.110000Z","event_type":"price_change","frame_hash":"2b43fd8f137135086aba5f8e6d235e3853fab0a73f6cebeff4d3104b7f468860","frame_index":0,"kind":"data","monotonic_ns":313608144221708,"payload":{"event_type":"price_change","market":"0xd412ce774cfcf8dc9f71164aac78783978aac7b03871702a3b8a481bd9dc9688","price_changes":[{"asset_id":"107603864457683460275633293642179940881969192120168665300712204232021063124301","best_ask":"0.63","best_bid":"0.62","hash":"298ed7535d2cdeadd8a1bf7d8a41e33ac1748438","price":"0.68","side":"SELL","size":"83.62"},{"asset_id":"96600821790790307414914106093858868634329285205417149685270682748367152458577","best_ask":"0.38","best_bid":"0.37","hash":"85238c2b6036fdb45c8fc92679eb8452f33ebb32","price":"0.32","side":"BUY","size":"83.62"}],"timestamp":"1785211621110"},"payload_hash":"dcc8c8141b41d45e27fce6a36f06c6b8cd35d15ac1e45fc4ef8b66d4b8934b72","raw_frame":"{\"market\":\"0xd412ce774cfcf8dc9f71164aac78783978aac7b03871702a3b8a481bd9dc9688\", \"price_changes\":[{\"asset_id\":\"107603864457683460275633293642179940881969192120168665300712204232021063124301\", \"price\":\"0.68\", \"size\":\"83.62\", \"side\":\"SELL\", \"hash\":\"298ed7535d2cdeadd8a1bf7d8a41e33ac1748438\", \"best_bid\":\"0.62\", \"best_ask\":\"0.63\"}, {\"asset_id\":\"96600821790790307414914106093858868634329285205417149685270682748367152458577\", \"price\":\"0.32\", \"size\":\"83.62\", \"side\":\"BUY\", \"hash\":\"85238c2b6036fdb45c8fc92679eb8452f33ebb32\", \"best_bid\":\"0.37\", \"best_ask\":\"0.38\"}], \"timestamp\":\"1785211621110\", \"event_type\":\"price_change\"}","received_at":"2026-07-28T04:07:05.093160Z","schema_version":"clob-market-ws.price_change.v1","sequence":null,"server_hash":null,"server_timestamp":"1785211621110","session_id":"2d607381e3054cee91998cdf45a4231c","source":"clob_market_ws"},"received_at":"2026-07-28T04:07:05.093160Z","record_id":"385c3e52b3cffb8b0970e02537aa5084b416e7ff4c71cdd0facfa5c4fa6d7c50","schema_fingerprint":"4aa3821a28b0b7c2400bc59aba4bcc0a76e971dadd19610d3ad38c768e124dc7","schema_version":"edge-lab-recorder.raw.v1","sequence":null,"source":"clob_market_ws"}
{"event_at":"2026-07-28T04:07:01.112000Z","event_fingerprint":"59a2bda5bf59382cedb01f66ce746ddd58ac674eabcb7320a4f2885fa1b2c510","payload":{"connection_id":"f6725804f86a4c4eb588e4d5ed7db029","event_at":"2026-07-28T04:07:01.112000Z","event_type":"price_change","frame_hash":"ae6bb660f55de9a075cc04ed856a5e069d63c66f0040a5f267d11302ec74614e","frame_index":0,"kind":"data","monotonic_ns":313608148707041,"payload":{"event_type":"price_change","market":"0xd412ce774cfcf8dc9f71164aac78783978aac7b03871702a3b8a481bd9dc9688","price_changes":[{"asset_id":"96600821790790307414914106093858868634329285205417149685270682748367152458577","best_ask":"0.38","best_bid":"0.37","hash":"b921e392094b34de0e4913e5e8fafdc847e080e3","price":"0.38","side":"SELL","size":"59"},{"asset_id":"107603864457683460275633293642179940881969192120168665300712204232021063124301","best_ask":"0.63","best_bid":"0.62","hash":"c41ca0acba27044388b0c7f5a0d0f35863d6aba5","price":"0.62","side":"BUY","size":"59"}],"timestamp":"1785211621112"},"payload_hash":"237aa676a7e535a886ec54109e08d20c286dc81458aa7a0cf82acaec97efd33e","raw_frame":"{\"market\":\"0xd412ce774cfcf8dc9f71164aac78783978aac7b03871702a3b8a481bd9dc9688\", \"price_changes\":[{\"asset_id\":\"96600821790790307414914106093858868634329285205417149685270682748367152458577\", \"price\":\"0.38\", \"size\":\"59\", \"side\":\"SELL\", \"hash\":\"b921e392094b34de0e4913e5e8fafdc847e080e3\", \"best_bid\":\"0.37\", \"best_ask\":\"0.38\"}, {\"asset_id\":\"107603864457683460275633293642179940881969192120168665300712204232021063124301\", \"price\":\"0.62\", \"size\":\"59\", \"side\":\"BUY\", \"hash\":\"c41ca0acba27044388b0c7f5a0d0f35863d6aba5\", \"best_bid\":\"0.62\", \"best_ask\":\"0.63\"}], \"timestamp\":\"1785211621112\", \"event_type\":\"price_change\"}","received_at":"2026-07-28T04:07:05.097646Z","schema_version":"clob-market-ws.price_change.v1","sequence":null,"server_hash":null,"server_timestamp":"1785211621112","session_id":"2d607381e3054cee91998cdf45a4231c","source":"clob_market_ws"},"received_at":"2026-07-28T04:07:05.097646Z","record_id":"ff20cf312008c3f69984faf47e0cf72c435db91b97cacda119a9b8d8a80636f9","schema_fingerprint":"4aa3821a28b0b7c2400bc59aba4bcc0a76e971dadd19610d3ad38c768e124dc7","schema_version":"edge-lab-recorder.raw.v1","sequence":null,"source":"clob_market_ws"}
{"event_at":"2026-07-28T04:07:01.113000Z","event_fingerprint":"2068ef42f84434a4ac0ef586ca9d4ead46df2c939824fcb336fa08fc9d5e1cea","payload":{"connection_id":"f6725804f86a4c4eb588e4d5ed7db029","event_at":"2026-07-28T04:07:01.113000Z","event_type":"price_change","frame_hash":"560b6ed8559de8c76663508a5dcd43211ea0095aa44a890f4bb28e713136eaee","frame_index":0,"kind":"data","monotonic_ns":313608153469541,"payload":{"event_type":"price_change","market":"0xd412ce774cfcf8dc9f71164aac78783978aac7b03871702a3b8a481bd9dc9688","price_changes":[{"asset_id":"107603864457683460275633293642179940881969192120168665300712204232021063124301","best_ask":"0.63","best_bid":"0.62","hash":"41312df849e66831285e214779d0a7051366dcc2","price":"0.6","side":"BUY","size":"60"},{"asset_id":"96600821790790307414914106093858868634329285205417149685270682748367152458577","best_ask":"0.38","best_bid":"0.37","hash":"9a3337fbff93989160d29ebb325de7551d4c2464","price":"0.4","side":"SELL","size":"60"}],"timestamp":"1785211621113"},"payload_hash":"c10c092d2a85c1bf0ec419c2800087f3d6ae6034d42a552e990ea8405817d9b1","raw_frame":"{\"market\":\"0xd412ce774cfcf8dc9f71164aac78783978aac7b03871702a3b8a481bd9dc9688\", \"price_changes\":[{\"asset_id\":\"107603864457683460275633293642179940881969192120168665300712204232021063124301\", \"price\":\"0.6\", \"size\":\"60\", \"side\":\"BUY\", \"hash\":\"41312df849e66831285e214779d0a7051366dcc2\", \"best_bid\":\"0.62\", \"best_ask\":\"0.63\"}, {\"asset_id\":\"96600821790790307414914106093858868634329285205417149685270682748367152458577\", \"price\":\"0.4\", \"size\":\"60\", \"side\":\"SELL\", \"hash\":\"9a3337fbff93989160d29ebb325de7551d4c2464\", \"best_bid\":\"0.37\", \"best_ask\":\"0.38\"}], \"timestamp\":\"1785211621113\", \"event_type\":\"price_change\"}","received_at":"2026-07-28T04:07:05.102409Z","schema_version":"clob-market-ws.price_change.v1","sequence":null,"server_hash":null,"server_timestamp":"1785211621113","session_id":"2d607381e3054cee91998cdf45a4231c","source":"clob_market_ws"},"received_at":"2026-07-28T04:07:05.102409Z","record_id":"57c72d90bf82c1ba5921e4b8c82f4f15d0739fe1b14659005b30d8c7781b67b3","schema_fingerprint":"4aa3821a28b0b7c2400bc59aba4bcc0a76e971dadd19610d3ad38c768e124dc7","schema_version":"edge-lab-recorder.raw.v1","sequence":null,"source":"clob_market_ws"}
{"event_at":"2026-07-28T04:07:01.115000Z","event_fingerprint":"18cdf97ba9fa5536c223568d1648150d6c9c5b940fa77d470f658a2c7b28991c","payload":{"connection_id":"f6725804f86a4c4eb588e4d5ed7db029","event_at":"2026-07-28T04:07:01.115000Z","event_type":"price_change","frame_hash":"c092ce1430fd0707038f8c0eb118a52e438bb38969833fd430b5aef35df1c010","frame_index":0,"kind":"data","monotonic_ns":313608161165250,"payload":{"event_type":"price_change","market":"0xd412ce774cfcf8dc9f71164aac78783978aac7b03871702a3b8a481bd9dc9688","price_changes":[{"asset_id":"107603864457683460275633293642179940881969192120168665300712204232021063124301","best_ask":"0.63","best_bid":"0.62","hash":"5c8f7079435d154a1c4859c8e75f4dc99a6408c6","price":"0.67","side":"SELL","size":"57.6"},{"asset_id":"96600821790790307414914106093858868634329285205417149685270682748367152458577","best_ask":"0.38","best_bid":"0.37","hash":"3388feaecdb018e05f8cc2a4f64509d80bb30eb9","price":"0.33","side":"BUY","size":"57.6"}],"timestamp":"1785211621115"},"payload_hash":"81c13dc76a2ffbad22526ab86d69b0b528de00c5b331eaa94a06eda585ad3c5b","raw_frame":"{\"market\":\"0xd412ce774cfcf8dc9f71164aac78783978aac7b03871702a3b8a481bd9dc9688\", \"price_changes\":[{\"asset_id\":\"107603864457683460275633293642179940881969192120168665300712204232021063124301\", \"price\":\"0.67\", \"size\":\"57.6\", \"side\":\"SELL\", \"hash\":\"5c8f7079435d154a1c4859c8e75f4dc99a6408c6\", \"best_bid\":\"0.62\", \"best_ask\":\"0.63\"}, {\"asset_id\":\"96600821790790307414914106093858868634329285205417149685270682748367152458577\", \"price\":\"0.33\", \"size\":\"57.6\", \"side\":\"BUY\", \"hash\":\"3388feaecdb018e05f8cc2a4f64509d80bb30eb9\", \"best_bid\":\"0.37\", \"best_ask\":\"0.38\"}], \"timestamp\":\"1785211621115\", \"event_type\":\"price_change\"}","received_at":"2026-07-28T04:07:05.110104Z","schema_version":"clob-market-ws.price_change.v1","sequence":null,"server_hash":null,"server_timestamp":"1785211621115","session_id":"2d607381e3054cee91998cdf45a4231c","source":"clob_market_ws"},"received_at":"2026-07-28T04:07:05.110104Z","record_id":"2ebf78207153fbf24fd22b0da3ed447debc9e21298bf72ac9419596000a56df6","schema_fingerprint":"4aa3821a28b0b7c2400bc59aba4bcc0a76e971dadd19610d3ad38c768e124dc7","schema_version":"edge-lab-recorder.raw.v1","sequence":null,"source":"clob_market_ws"}
