{"event_at":"2026-07-28T04:12:40.892000Z","event_fingerprint":"3223d9de124a8b5da87211bf5a464a945923e3681f914002f3121c6c6e9bb371","payload":{"connection_id":"f6725804f86a4c4eb588e4d5ed7db029","event_at":"2026-07-28T04:12:40.892000Z","event_type":"price_change","frame_hash":"118019d8ed7435df805a7700d020b4b3caa3d28ca168c2059786a367a324543e","frame_index":0,"kind":"data","monotonic_ns":313944154982125,"payload":{"event_type":"price_change","market":"0xd412ce774cfcf8dc9f71164aac78783978aac7b03871702a3b8a481bd9dc9688","price_changes":[{"asset_id":"96600821790790307414914106093858868634329285205417149685270682748367152458577","best_ask":"0.4","best_bid":"0.38","hash":"d1801487384a9d01078a5bdbbed5f6497bcad2f3","price":"0.28","side":"BUY","size":"126"},{"asset_id":"107603864457683460275633293642179940881969192120168665300712204232021063124301","best_ask":"0.62","best_bid":"0.6","hash":"001ae3a26bf20804b6d7e6cf2771d6fc21384fbe","price":"0.72","side":"SELL","size":"126"}],"timestamp":"1785211960892"},"payload_hash":"c31327c6a1b0bf82a8664f464ae22ed4c37cdf6b8f7bf5fc302a14c81e81b1a3","raw_frame":"{\"market\":\"0xd412ce774cfcf8dc9f71164aac78783978aac7b03871702a3b8a481bd9dc9688\", \"price_changes\":[{\"asset_id\":\"96600821790790307414914106093858868634329285205417149685270682748367152458577\", \"price\":\"0.28\", \"size\":\"126\", \"side\":\"BUY\", \"hash\":\"d1801487384a9d01078a5bdbbed5f6497bcad2f3\", \"best_bid\":\"0.38\", \"best_ask\":\"0.4\"}, {\"asset_id\":\"107603864457683460275633293642179940881969192120168665300712204232021063124301\", \"price\":\"0.72\", \"size\":\"126\", \"side\":\"SELL\", \"hash\":\"001ae3a26bf20804b6d7e6cf2771d6fc21384fbe\", \"best_bid\":\"0.6\", \"best_ask\":\"0.62\"}], \"timestamp\":\"1785211960892\", \"event_type\":\"price_change\"}","received_at":"2026-07-28T04:12:41.077464Z","schema_version":"clob-market-ws.price_change.v1","sequence":null,"server_hash":null,"server_timestamp":"1785211960892","session_id":"2d607381e3054cee91998cdf45a4231c","source":"clob_market_ws"},"received_at":"2026-07-28T04:12:41.077464Z","record_id":"05239d6ffdddd8b8dc3e8dd012197441ec7d0869567db91a7fa687ad16629a23","schema_fingerprint":"4aa3821a28b0b7c2400bc59aba4bcc0a76e971dadd19610d3ad38c768e124dc7","schema_version":"edge-lab-recorder.raw.v1","sequence":null,"source":"clob_market_ws"}
{"event_at":"2026-07-28T04:12:40.914000Z","event_fingerprint":"d2c3d69b2dd5151dfcaa3744eee57559075a470bc002c38600214ae9a313e888","payload":{"connection_id":"f6725804f86a4c4eb588e4d5ed7db029","event_at":"2026-07-28T04:12:40.914000Z","event_type":"price_change","frame_hash":"9a2a22ecc21794ba8393416a43e1b6cd3102b52637bdd256767b4af3f6f898f2","frame_index":0,"kind":"data","monotonic_ns":313944171161250,"payload":{"event_type":"price_change","market":"0xd412ce774cfcf8dc9f71164aac78783978aac7b03871702a3b8a481bd9dc9688","price_changes":[{"asset_id":"107603864457683460275633293642179940881969192120168665300712204232021063124301","best_ask":"0.62","best_bid":"0.6","hash":"56c20a50e795260e3cb19b75110d451105f0404f","price":"0.45","side":"BUY","size":"195"},{"asset_id":"96600821790790307414914106093858868634329285205417149685270682748367152458577","best_ask":"0.4","best_bid":"0.38","hash":"ffd7fbf6502df009c4203eb7055a981994b9af46","price":"0.55","side":"SELL","size":"195"}],"timestamp":"1785211960914"},"payload_hash":"c63d20efb69b6a71ffbfc468bb36a1f3abe23cf298b05fa6526cde81903500b1","raw_frame":"{\"market\":\"0xd412ce774cfcf8dc9f71164aac78783978aac7b03871702a3b8a481bd9dc9688\", \"price_changes\":[{\"asset_id\":\"107603864457683460275633293642179940881969192120168665300712204232021063124301\", \"price\":\"0.45\", \"size\":\"195\", \"side\":\"BUY\", \"hash\":\"56c20a50e795260e3cb19b75110d451105f0404f\", \"best_bid\":\"0.6\", \"best_ask\":\"0.62\"}, {\"asset_id\":\"96600821790790307414914106093858868634329285205417149685270682748367152458577\", \"price\":\"0.55\", \"size\":\"195\", \"side\":\"SELL\", \"hash\":\"ffd7fbf6502df009c4203eb7055a981994b9af46\", \"best_bid\":\"0.38\", \"best_ask\":\"0.4\"}], \"timestamp\":\"1785211960914\", \"event_type\":\"price_change\"}","received_at":"2026-07-28T04:12:41.093643Z","schema_version":"clob-market-ws.price_change.v1","sequence":null,"server_hash":null,"server_timestamp":"1785211960914","session_id":"2d607381e3054cee91998cdf45a4231c","source":"clob_market_ws"},"received_at":"2026-07-28T04:12:41.093643Z","record_id":"0854c9070dc31b87810f832cdecfd20afd4c1cb057398369104465d6998f056c","schema_fingerprint":"4aa3821a28b0b7c2400bc59aba4bcc0a76e971dadd19610d3ad38c768e124dc7","schema_version":"edge-lab-recorder.raw.v1","sequence":null,"source":"clob_market_ws"}
{"event_at":"2026-07-28T04:12:40.916000Z","event_fingerprint":"5c424b390634600ee7ac3459913344ab579f2a4bea9cf928d5b7465e6396bcda","payload":{"connection_id":"f6725804f86a4c4eb588e4d5ed7db029","event_at":"2026-07-28T04:12:40.916000Z","event_type":"price_change","frame_hash":"f73c58fc022b1ec9447f1c2fe7e3a25d2845e79afdb638a49e8aea72e35998d1","frame_index":0,"kind":"data","monotonic_ns":313944174349041,"payload":{"event_type":"price_change","market":"0xd412ce774cfcf8dc9f71164aac78783978aac7b03871702a3b8a481bd9dc9688","price_changes":[{"asset_id":"96600821790790307414914106093858868634329285205417149685270682748367152458577","best_ask":"0.4","best_bid":"0.38","hash":"0c7411b45fbc42326fa1df0b3b150e81c31dfb79","price":"0.27","side":"BUY","size":"140"},{"asset_id":"107603864457683460275633293642179940881969192120168665300712204232021063124301","best_ask":"0.62","best_bid":"0.6","hash":"29fca40c8e79f61350237ff3929ec20d2340e141","price":"0.73","side":"SELL","size":"140"}],"timestamp":"1785211960916"},"payload_hash":"a0abeb5ca47eafd736296e0f41e33ab6b4aca287a1e5d49ae1fad56e9beebf7f","raw_frame":"{\"market\":\"0xd412ce774cfcf8dc9f71164aac78783978aac7b03871702a3b8a481bd9dc9688\", \"price_changes\":[{\"asset_id\":\"96600821790790307414914106093858868634329285205417149685270682748367152458577\", \"price\":\"0.27\", \"size\":\"140\", \"side\":\"BUY\", \"hash\":\"0c7411b45fbc42326fa1df0b3b150e81c31dfb79\", \"best_bid\":\"0.38\", \"best_ask\":\"0.4\"}, {\"asset_id\":\"107603864457683460275633293642179940881969192120168665300712204232021063124301\", \"price\":\"0.73\", \"size\":\"140\", \"side\":\"SELL\", \"hash\":\"29fca40c8e79f61350237ff3929ec20d2340e141\", \"best_bid\":\"0.6\", \"best_ask\":\"0.62\"}], \"timestamp\":\"1785211960916\", \"event_type\":\"price_change\"}","received_at":"2026-07-28T04:12:41.096830Z","schema_version":"clob-market-ws.price_change.v1","sequence":null,"server_hash":null,"server_timestamp":"1785211960916","session_id":"2d607381e3054cee91998cdf45a4231c","source":"clob_market_ws"},"received_at":"2026-07-28T04:12:41.096830Z","record_id":"041ef51579c351882a0f7b94f207dd1c772828d8b337041c5012758aa71d567c","schema_fingerprint":"4aa3821a28b0b7c2400bc59aba4bcc0a76e971dadd19610d3ad38c768e124dc7","schema_version":"edge-lab-recorder.raw.v1","sequence":null,"source":"clob_market_ws"}
{"event_at":"2026-07-28T04:12:40.940000Z","event_fingerprint":"1cf1571e0231fec5bb46a3f373dd87a8d5feaea822f1edc6116ad35297bc1952","payload":{"connection_id":"f6725804f86a4c4eb588e4d5ed7db029","event_at":"2026-07-28T04:12:40.940000Z","event_type":"price_change","frame_hash":"a5b1cbe3de803f5b6b6ed14a8a921b882e6f3d0b558cbf5dffb0e5ef14f8ffda","frame_index":0,"kind":"data","monotonic_ns":313944179550208,"payload":{"event_type":"price_change","market":"0xd412ce774cfcf8dc9f71164aac78783978aac7b03871702a3b8a481bd9dc9688","price_changes":[{"asset_id":"96600821790790307414914106093858868634329285205417149685270682748367152458577","best_ask":"0.4","best_bid":"0.38","hash":"0c67ae3180fdbcdd1058c56461883a2f870063de","price":"0.27","side":"BUY","size":"170"},{"asset_id":"107603864457683460275633293642179940881969192120168665300712204232021063124301","best_ask":"0.62","best_bid":"0.6","hash":"0d50250fbd4a454acccc9846249cc79d13881d5a","price":"0.73","side":"SELL","size":"170"}],"timestamp":"1785211960940"},"payload_hash":"58d0aaca21ff1b027d1688c7cafb70a32bab3c7d7308a9a65c461f5ff9b4790a","raw_frame":"{\"market\":\"0xd412ce774cfcf8dc9f71164aac78783978aac7b03871702a3b8a481bd9dc9688\", \"price_changes\":[{\"asset_id\":\"96600821790790307414914106093858868634329285205417149685270682748367152458577\", \"price\":\"0.27\", \"size\":\"170\", \"side\":\"BUY\", \"hash\":\"0c67ae3180fdbcdd1058c56461883a2f870063de\", \"best_bid\":\"0.38\", \"best_ask\":\"0.4\"}, {\"asset_id\":\"107603864457683460275633293642179940881969192120168665300712204232021063124301\", \"price\":\"0.73\", \"size\":\"170\", \"side\":\"SELL\", \"hash\":\"0d50250fbd4a454acccc9846249cc79d13881d5a\", \"best_bid\":\"0.6\", \"best_ask\":\"0.62\"}], \"timestamp\":\"1785211960940\", \"event_type\":\"price_change\"}","received_at":"2026-07-28T04:12:41.102032Z","schema_version":"clob-market-ws.price_change.v1","sequence":null,"server_hash":null,"server_timestamp":"1785211960940","session_id":"2d607381e3054cee91998cdf45a4231c","source":"clob_market_ws"},"received_at":"2026-07-28T04:12:41.102032Z","record_id":"065a34eefe9e58a51a65a9372832af89d5f9abd45fbef2b6bbcd1447408c93ee","schema_fingerprint":"4aa3821a28b0b7c2400bc59aba4bcc0a76e971dadd19610d3ad38c768e124dc7","schema_version":"edge-lab-recorder.raw.v1","sequence":null,"source":"clob_market_ws"}
{"event_at":"2026-07-28T04:12:40.941000Z","event_fingerprint":"4aebe750917c51fd2fa4d86568838769ac117f288fd336424cd9b738d06ec932","payload":{"connection_id":"f6725804f86a4c4eb588e4d5ed7db029","event_at":"2026-07-28T04:12:40.941000Z","event_type":"price_change","frame_hash":"09468eabea6ef3255dc083a663a909b0c9c4c520184c39855170b9afbf9afddd","frame_index":0,"kind":"data","monotonic_ns":313944183383791,"payload":{"event_type":"price_change","market":"0xd412ce774cfcf8dc9f71164aac78783978aac7b03871702a3b8a481bd9dc9688","price_changes":[{"asset_id":"107603864457683460275633293642179940881969192120168665300712204232021063124301","best_ask":"0.62","best_bid":"0.6","hash":"3963564c43c3b7d2c30814fd458c7c5c3902e288","price":"0.04","side":"BUY","size":"545"},{"asset_id":"96600821790790307414914106093858868634329285205417149685270682748367152458577","best_ask":"0.4","best_bid":"0.38","hash":"52f8cf08bcce95ec64d95330cae82ed7131a8e83","price":"0.96","side":"SELL","size":"545"}],"timestamp":"1785211960941"},"payload_hash":"ad32f54a1da65e803e1aa4467a982760d79fede3da4d78ebc0e59b0eaf5605bf","raw_frame":"{\"market\":\"0xd412ce774cfcf8dc9f71164aac78783978aac7b03871702a3b8a481bd9dc9688\", \"price_changes\":[{\"asset_id\":\"107603864457683460275633293642179940881969192120168665300712204232021063124301\", \"price\":\"0.04\", \"size\":\"545\", \"side\":\"BUY\", \"hash\":\"3963564c43c3b7d2c30814fd458c7c5c3902e288\", \"best_bid\":\"0.6\", \"best_ask\":\"0.62\"}, {\"asset_id\":\"96600821790790307414914106093858868634329285205417149685270682748367152458577\", \"price\":\"0.96\", \"size\":\"545\", \"side\":\"SELL\", \"hash\":\"52f8cf08bcce95ec64d95330cae82ed7131a8e83\", \"best_bid\":\"0.38\", \"best_ask\":\"0.4\"}], \"timestamp\":\"1785211960941\", \"event_type\":\"price_change\"}","received_at":"2026-07-28T04:12:41.105865Z","schema_version":"clob-market-ws.price_change.v1","sequence":null,"server_hash":null,"server_timestamp":"1785211960941","session_id":"2d607381e3054cee91998cdf45a4231c","source":"clob_market_ws"},"received_at":"2026-07-28T04:12:41.105865Z","record_id":"99d7906cba6ad053b25deef50aa923b8eba71107603b9b66bed393f7fa004ea3","schema_fingerprint":"4aa3821a28b0b7c2400bc59aba4bcc0a76e971dadd19610d3ad38c768e124dc7","schema_version":"edge-lab-recorder.raw.v1","sequence":null,"source":"clob_market_ws"}
{"event_at":"2026-07-28T04:12:40.942000Z","event_fingerprint":"0b80840e228696043a93315e1f724c53dd0f8dbc67716c8460bb62dadb7d7734","payload":{"connection_id":"f6725804f86a4c4eb588e4d5ed7db029","event_at":"2026-07-28T04:12:40.942000Z","event_type":"price_change","frame_hash":"15508de1882d2d6fede25b1e54e569d6a93ceb1d43d58995ac1fea6a64b456f6","frame_index":0,"kind":"data","monotonic_ns":313944188559583,"payload":{"event_type":"price_change","market":"0xd412ce774cfcf8dc9f71164aac78783978aac7b03871702a3b8a481bd9dc9688","price_changes":[{"asset_id":"96600821790790307414914106093858868634329285205417149685270682748367152458577","best_ask":"0.4","best_bid":"0.38","hash":"be69532efd838b34aab3d0844a40edd9b6a8c1b6","price":"0.27","side":"BUY","size":"200"},{"asset_id":"107603864457683460275633293642179940881969192120168665300712204232021063124301","best_ask":"0.62","best_bid":"0.6","hash":"aee7e15feaae5621e57eafadc303dddcee620978","price":"0.73","side":"SELL","size":"200"}],"timestamp":"1785211960942"},"payload_hash":"8eeb53b246ba2aa33089625af124e55c8f7ad01ef948c07a085045ef79e9f428","raw_frame":"{\"market\":\"0xd412ce774cfcf8dc9f71164aac78783978aac7b03871702a3b8a481bd9dc9688\", \"price_changes\":[{\"asset_id\":\"96600821790790307414914106093858868634329285205417149685270682748367152458577\", \"price\":\"0.27\", \"size\":\"200\", \"side\":\"BUY\", \"hash\":\"be69532efd838b34aab3d0844a40edd9b6a8c1b6\", \"best_bid\":\"0.38\", \"best_ask\":\"0.4\"}, {\"asset_id\":\"107603864457683460275633293642179940881969192120168665300712204232021063124301\", \"price\":\"0.73\", \"size\":\"200\", \"side\":\"SELL\", \"hash\":\"aee7e15feaae5621e57eafadc303dddcee620978\", \"best_bid\":\"0.6\", \"best_ask\":\"0.62\"}], \"timestamp\":\"1785211960942\", \"event_type\":\"price_change\"}","received_at":"2026-07-28T04:12:41.111041Z","schema_version":"clob-market-ws.price_change.v1","sequence":null,"server_hash":null,"server_timestamp":"1785211960942","session_id":"2d607381e3054cee91998cdf45a4231c","source":"clob_market_ws"},"received_at":"2026-07-28T04:12:41.111041Z","record_id":"6a53c392a0e2b38fba5e77f22c22fe4829c9a5e838151b4f8c284b229a0b36a0","schema_fingerprint":"4aa3821a28b0b7c2400bc59aba4bcc0a76e971dadd19610d3ad38c768e124dc7","schema_version":"edge-lab-recorder.raw.v1","sequence":null,"source":"clob_market_ws"}
{"event_at":"2026-07-28T04:12:40.943000Z","event_fingerprint":"82bceabfacfc17505feaf457108c23a677876b523788a3b9e36d7a327c1c9d7e","payload":{"connection_id":"f6725804f86a4c4eb588e4d5ed7db029","event_at":"2026-07-28T04:12:40.943000Z","event_type":"price_change","frame_hash":"069af188c116ad1151df5ca43b67ca0c0630f73531e768903b0a719e1c8e075b","frame_index":0,"kind":"data","monotonic_ns":313944192839708,"payload":{"event_type":"price_change","market":"0xd412ce774cfcf8dc9f71164aac78783978aac7b03871702a3b8a481bd9dc9688","price_changes":[{"asset_id":"96600821790790307414914106093858868634329285205417149685270682748367152458577","best_ask":"0.4","best_bid":"0.38","hash":"bde5ca1cd93294a7785f636cb256b488c8658e64","price":"0.32","side":"BUY","size":"104"},{"asset_id":"107603864457683460275633293642179940881969192120168665300712204232021063124301","best_ask":"0.62","best_bid":"0.6","hash":"ac0ed8bd5b6937f46a40ed1c75d1729d966619a3","price":"0.68","side":"SELL","size":"104"}],"timestamp":"1785211960943"},"payload_hash":"738ed346f83f9f73de6b5a5f5e2d28921ccf15c681d2a653e3a78811643a5689","raw_frame":"{\"market\":\"0xd412ce774cfcf8dc9f71164aac78783978aac7b03871702a3b8a481bd9dc9688\", \"price_changes\":[{\"asset_id\":\"96600821790790307414914106093858868634329285205417149685270682748367152458577\", \"price\":\"0.32\", \"size\":\"104\", \"side\":\"BUY\", \"hash\":\"bde5ca1cd93294a7785f636cb256b488c8658e64\", \"best_bid\":\"0.38\", \"best_ask\":\"0.4\"}, {\"asset_id\":\"107603864457683460275633293642179940881969192120168665300712204232021063124301\", \"price\":\"0.68\", \"size\":\"104\", \"side\":\"SELL\", \"hash\":\"ac0ed8bd5b6937f46a40ed1c75d1729d966619a3\", \"best_bid\":\"0.6\", \"best_ask\":\"0.62\"}], \"timestamp\":\"1785211960943\", \"event_type\":\"price_change\"}","received_at":"2026-07-28T04:12:41.115321Z","schema_version":"clob-market-ws.price_change.v1","sequence":null,"server_hash":null,"server_timestamp":"1785211960943","session_id":"2d607381e3054cee91998cdf45a4231c","source":"clob_market_ws"},"received_at":"2026-07-28T04:12:41.115321Z","record_id":"679fc4997dcbd74c728fe1405a4d56c9b5ece9216783f2cc56ea130d1041ab3d","schema_fingerprint":"4aa3821a28b0b7c2400bc59aba4bcc0a76e971dadd19610d3ad38c768e124dc7","schema_version":"edge-lab-recorder.raw.v1","sequence":null,"source":"clob_market_ws"}
{"event_at":"2026-07-28T04:12:40.997000Z","event_fingerprint":"934d1df6cc3acd6d5bca965a123b3fe029438242f48b326a9d4683ae4f38657f","payload":{"connection_id":"f6725804f86a4c4eb588e4d5ed7db029","event_at":"2026-07-28T04:12:40.997000Z","event_type":"price_change","frame_hash":"28a007e67b7427c3912dbf39f9549f2b949198aadc9e72230bdc9b0293056fb7","frame_index":0,"kind":"data","monotonic_ns":313944195234041,"payload":{"event_type":"price_change","market":"0xd412ce774cfcf8dc9f71164aac78783978aac7b03871702a3b8a481bd9dc9688","price_changes":[{"asset_id":"107603864457683460275633293642179940881969192120168665300712204232021063124301","best_ask":"0.62","best_bid":"0.6","hash":"0739763990754c7da73ccb211de523f786750d97","price":"0.04","side":"BUY","size":"540"},{"asset_id":"96600821790790307414914106093858868634329285205417149685270682748367152458577","best_ask":"0.4","best_bid":"0.38","hash":"0c6eb9b32f4b9294a6d91d9d34795f3ef6d15c04","price":"0.96","side":"SELL","size":"540"}],"timestamp":"1785211960997"},"payload_hash":"b677c7603a48c4118057ca12d9366d863df2676ed87701e9dfb2aa2303272fbd","raw_frame":"{\"market\":\"0xd412ce774cfcf8dc9f71164aac78783978aac7b03871702a3b8a481bd9dc9688\", \"price_changes\":[{\"asset_id\":\"107603864457683460275633293642179940881969192120168665300712204232021063124301\", \"price\":\"0.04\", \"size\":\"540\", \"side\":\"BUY\", \"hash\":\"0739763990754c7da73ccb211de523f786750d97\", \"best_bid\":\"0.6\", \"best_ask\":\"0.62\"}, {\"asset_id\":\"96600821790790307414914106093858868634329285205417149685270682748367152458577\", \"price\":\"0.96\", \"size\":\"540\", \"side\":\"SELL\", \"hash\":\"0c6eb9b32f4b9294a6d91d9d34795f3ef6d15c04\", \"best_bid\":\"0.38\", \"best_ask\":\"0.4\"}], \"timestamp\":\"1785211960997\", \"event_type\":\"price_change\"}","received_at":"2026-07-28T04:12:41.117712Z","schema_version":"clob-market-ws.price_change.v1","sequence":null,"server_hash":null,"server_timestamp":"1785211960997","session_id":"2d607381e3054cee91998cdf45a4231c","source":"clob_market_ws"},"received_at":"2026-07-28T04:12:41.117712Z","record_id":"c661ef61f7dd3666a705804c022d00bb14b858f746fa0475a36727350c1f613c","schema_fingerprint":"4aa3821a28b0b7c2400bc59aba4bcc0a76e971dadd19610d3ad38c768e124dc7","schema_version":"edge-lab-recorder.raw.v1","sequence":null,"source":"clob_market_ws"}
{"event_at":"2026-07-28T04:12:41.001000Z","event_fingerprint":"d4898638ea197286e86673231ec9d4c741492e7bbb7ccd69079426ee7706398d","payload":{"connection_id":"f6725804f86a4c4eb588e4d5ed7db029","event_at":"2026-07-28T04:12:41.001000Z","event_type":"price_change","frame_hash":"693d1bb1e6711ebe80c7cbcb2d94fc77e3368a1c09baedb300839ad5de54c52f","frame_index":0,"kind":"data","monotonic_ns":313944199681541,"payload":{"event_type":"price_change","market":"0xd412ce774cfcf8dc9f71164aac78783978aac7b03871702a3b8a481bd9dc9688","price_changes":[{"asset_id":"96600821790790307414914106093858868634329285205417149685270682748367152458577","best_ask":"0.4","best_bid":"0.38","hash":"b85203af97003d370aa7b6d2248a6f3cc004ad8c","price":"0.38","side":"BUY","size":"47"},{"asset_id":"107603864457683460275633293642179940881969192120168665300712204232021063124301","best_ask":"0.62","best_bid":"0.6","hash":"d5e146fadb3aa81991f72d58c3ac6c5096e8fea5","price":"0.62","side":"SELL","size":"47"}],"timestamp":"1785211961001"},"payload_hash":"5e118b49ec8d48be2295635cf2e49aa9e0d9093e0d79645798f8e3f0fe0ae802","raw_frame":"{\"market\":\"0xd412ce774cfcf8dc9f71164aac78783978aac7b03871702a3b8a481bd9dc9688\", \"price_changes\":[{\"asset_id\":\"96600821790790307414914106093858868634329285205417149685270682748367152458577\", \"price\":\"0.38\", \"size\":\"47\", \"side\":\"BUY\", \"hash\":\"b85203af97003d370aa7b6d2248a6f3cc004ad8c\", \"best_bid\":\"0.38\", \"best_ask\":\"0.4\"}, {\"asset_id\":\"107603864457683460275633293642179940881969192120168665300712204232021063124301\", \"price\":\"0.62\", \"size\":\"47\", \"side\":\"SELL\", \"hash\":\"d5e146fadb3aa81991f72d58c3ac6c5096e8fea5\", \"best_bid\":\"0.6\", \"best_ask\":\"0.62\"}], \"timestamp\":\"1785211961001\", \"event_type\":\"price_change\"}","received_at":"2026-07-28T04:12:41.122163Z","schema_version":"clob-market-ws.price_change.v1","sequence":null,"server_hash":null,"server_timestamp":"1785211961001","session_id":"2d607381e3054cee91998cdf45a4231c","source":"clob_market_ws"},"received_at":"2026-07-28T04:12:41.122163Z","record_id":"0552c1f9435165259ad864c48fa9bfaa5c32016409df59f1ae0753d422d47a74","schema_fingerprint":"4aa3821a28b0b7c2400bc59aba4bcc0a76e971dadd19610d3ad38c768e124dc7","schema_version":"edge-lab-recorder.raw.v1","sequence":null,"source":"clob_market_ws"}
{"event_at":"2026-07-28T04:12:41.002000Z","event_fingerprint":"8d657c38d9fc464901d1ff869224ea3648c29437363bb9fcdcfb01fe102d0128","payload":{"connection_id":"f6725804f86a4c4eb588e4d5ed7db029","event_at":"2026-07-28T04:12:41.002000Z","event_type":"price_change","frame_hash":"a32f4299558b841cd9450245c438bf0668355da632c5f5adb0e42ef2e3358287","frame_index":0,"kind":"data","monotonic_ns":313944203973666,"payload":{"event_type":"price_change","market":"0xd412ce774cfcf8dc9f71164aac78783978aac7b03871702a3b8a481bd9dc9688","price_changes":[{"asset_id":"96600821790790307414914106093858868634329285205417149685270682748367152458577","best_ask":"0.4","best_bid":"0.38","hash":"f158a2f5d26dcba1dc5ca0348c4bed1c0282e239","price":"0.36","side":"BUY","size":"38"},{"asset_id":"107603864457683460275633293642179940881969192120168665300712204232021063124301","best_ask":"0.62","best_bid":"0.6","hash":"f5b57d65d4344b48f580ff9fe70acb0c3f5a7da3","price":"0.64","side":"SELL","size":"38"}],"timestamp":"1785211961002"},"payload_hash":"e2846f4d07128d2714c2678c0d444cf8fa933f1e690e4e5ebea4ebdd7ff15282","raw_frame":"{\"market\":\"0xd412ce774cfcf8dc9f71164aac78783978aac7b03871702a3b8a481bd9dc9688\", \"price_changes\":[{\"asset_id\":\"96600821790790307414914106093858868634329285205417149685270682748367152458577\", \"price\":\"0.36\", \"size\":\"38\", \"side\":\"BUY\", \"hash\":\"f158a2f5d26dcba1dc5ca0348c4bed1c0282e239\", \"best_bid\":\"0.38\", \"best_ask\":\"0.4\"}, {\"asset_id\":\"107603864457683460275633293642179940881969192120168665300712204232021063124301\", \"price\":\"0.64\", \"size\":\"38\", \"side\":\"SELL\", \"hash\":\"f5b57d65d4344b48f580ff9fe70acb0c3f5a7da3\", \"best_bid\":\"0.6\", \"best_ask\":\"0.62\"}], \"timestamp\":\"1785211961002\", \"event_type\":\"price_change\"}","received_at":"2026-07-28T04:12:41.126455Z","schema_version":"clob-market-ws.price_change.v1","sequence":null,"server_hash":null,"server_timestamp":"1785211961002","session_id":"2d607381e3054cee91998cdf45a4231c","source":"clob_market_ws"},"received_at":"2026-07-28T04:12:41.126455Z","record_id":"cd8d6704bd6fb237dd034be4f7bb8f52b5168d76858026a82b76141650587b61","schema_fingerprint":"4aa3821a28b0b7c2400bc59aba4bcc0a76e971dadd19610d3ad38c768e124dc7","schema_version":"edge-lab-recorder.raw.v1","sequence":null,"source":"clob_market_ws"}
{"event_at":"2026-07-28T04:12:41.008000Z","event_fingerprint":"f85a641f68c0f7cf7961890a7b3c90b5a9da004607904d358b39059507c23355","payload":{"connection_id":"f6725804f86a4c4eb588e4d5ed7db029","event_at":"2026-07-28T04:12:41.008000Z","event_type":"price_change","frame_hash":"7bb8c74d0652fcd8d8a458f79f8bee2d3c2cf828ea55cb73a29504a262b1fae1","frame_index":0,"kind":"data","monotonic_ns":313944215110458,"payload":{"event_type":"price_change","market":"0xd412ce774cfcf8dc9f71164aac78783978aac7b03871702a3b8a481bd9dc9688","price_changes":[{"asset_id":"107603864457683460275633293642179940881969192120168665300712204232021063124301","best_ask":"0.62","best_bid":"0.6","hash":"0cf88c089be743dbc4890e0b8b1f80485c9d9f46","price":"0.58","side":"BUY","size":"53"},{"asset_id":"96600821790790307414914106093858868634329285205417149685270682748367152458577","best_ask":"0.4","best_bid":"0.38","hash":"c4fffd1aeb3f74870f79613af7fb979513f21687","price":"0.42","side":"SELL","size":"53"}],"timestamp":"1785211961008"},"payload_hash":"64cac79485673c8f549d5f6c920c43d28ac12e0624bf5ad415bd6a454a946331","raw_frame":"{\"market\":\"0xd412ce774cfcf8dc9f71164aac78783978aac7b03871702a3b8a481bd9dc9688\", \"price_changes\":[{\"asset_id\":\"107603864457683460275633293642179940881969192120168665300712204232021063124301\", \"price\":\"0.58\", \"size\":\"53\", \"side\":\"BUY\", \"hash\":\"0cf88c089be743dbc4890e0b8b1f80485c9d9f46\", \"best_bid\":\"0.6\", \"best_ask\":\"0.62\"}, {\"asset_id\":\"96600821790790307414914106093858868634329285205417149685270682748367152458577\", \"price\":\"0.42\", \"size\":\"53\", \"side\":\"SELL\", \"hash\":\"c4fffd1aeb3f74870f79613af7fb979513f21687\", \"best_bid\":\"0.38\", \"best_ask\":\"0.4\"}], \"timestamp\":\"1785211961008\", \"event_type\":\"price_change\"}","received_at":"2026-07-28T04:12:41.137592Z","schema_version":"clob-market-ws.price_change.v1","sequence":null,"server_hash":null,"server_timestamp":"1785211961008","session_id":"2d607381e3054cee91998cdf45a4231c","source":"clob_market_ws"},"received_at":"2026-07-28T04:12:41.137592Z","record_id":"8847e3e05805a0257b42947cf5069d53abff9175c078b34374805f6aa2665071","schema_fingerprint":"4aa3821a28b0b7c2400bc59aba4bcc0a76e971dadd19610d3ad38c768e124dc7","schema_version":"edge-lab-recorder.raw.v1","sequence":null,"source":"clob_market_ws"}
{"event_at":"2026-07-28T04:12:41.009000Z","event_fingerprint":"a589053507828100a1bdd7029e1688e016f4326f794595c837336af76638257b","payload":{"connection_id":"f6725804f86a4c4eb588e4d5ed7db029","event_at":"2026-07-28T04:12:41.009000Z","event_type":"price_change","frame_hash":"3d5291f41685fc7e38eabdd3b620b79cbe5b9d671ac27d592a198993a730388c","frame_index":0,"kind":"data","monotonic_ns":313944227881000,"payload":{"event_type":"price_change","market":"0xd412ce774cfcf8dc9f71164aac78783978aac7b03871702a3b8a481bd9dc9688","price_changes":[{"asset_id":"96600821790790307414914106093858868634329285205417149685270682748367152458577","best_ask":"0.4","best_bid":"0.38","hash":"401b002e88462d1fff79103cc0d14f8044e4a13a","price":"0.37","side":"BUY","size":"145.41"},{"asset_id":"107603864457683460275633293642179940881969192120168665300712204232021063124301","best_ask":"0.62","best_bid":"0.6","hash":"229e43c10cfd89641821635393a2f8f1240aad15","price":"0.63","side":"SELL","size":"145.41"}],"timestamp":"1785211961009"},"payload_hash":"237b7606a04a88a45adf4aa7fb667b4f2e9557d40e6d919ce5ea2f94826fc894","raw_frame":"{\"market\":\"0xd412ce774cfcf8dc9f71164aac78783978aac7b03871702a3b8a481bd9dc9688\", \"price_changes\":[{\"asset_id\":\"96600821790790307414914106093858868634329285205417149685270682748367152458577\", \"price\":\"0.37\", \"size\":\"145.41\", \"side\":\"BUY\", \"hash\":\"401b002e88462d1fff79103cc0d14f8044e4a13a\", \"best_bid\":\"0.38\", \"best_ask\":\"0.4\"}, {\"asset_id\":\"107603864457683460275633293642179940881969192120168665300712204232021063124301\", \"price\":\"0.63\", \"size\":\"145.41\", \"side\":\"SELL\", \"hash\":\"229e43c10cfd89641821635393a2f8f1240aad15\", \"best_bid\":\"0.6\", \"best_ask\":\"0.62\"}], \"timestamp\":\"1785211961009\", \"event_type\":\"price_change\"}","received_at":"2026-07-28T04:12:41.150359Z","schema_version":"clob-market-ws.price_change.v1","sequence":null,"server_hash":null,"server_timestamp":"1785211961009","session_id":"2d607381e3054cee91998cdf45a4231c","source":"clob_market_ws"},"received_at":"2026-07-28T04:12:41.150359Z","record_id":"98e22283939caf800a55e60ae46d996c94d1fa39dc062b7ca503599063b1fb67","schema_fingerprint":"4aa3821a28b0b7c2400bc59aba4bcc0a76e971dadd19610d3ad38c768e124dc7","schema_version":"edge-lab-recorder.raw.v1","sequence":null,"source":"clob_market_ws"}
{"event_at":"2026-07-28T04:12:41.010000Z","event_fingerprint":"26a6588a18a8b6ee95926b042252dd1520b25cb7d9aeadf40c94851162ad7b48","payload":{"connection_id":"f6725804f86a4c4eb588e4d5ed7db029","event_at":"2026-07-28T04:12:41.010000Z","event_type":"price_change","frame_hash":"1169a178402d57f07debc51681dcd94e0506128759bd198897099b26d52f0bc2","frame_index":0,"kind":"data","monotonic_ns":313944231523833,"payload":{"event_type":"price_change","market":"0xd412ce774cfcf8dc9f71164aac78783978aac7b03871702a3b8a481bd9dc9688","price_changes":[{"asset_id":"96600821790790307414914106093858868634329285205417149685270682748367152458577","best_ask":"0.4","best_bid":"0.38","hash":"e5bca8bba4b955938f66bdf146a14ec087a9189f","price":"0.36","side":"BUY","size":"94"},{"asset_id":"107603864457683460275633293642179940881969192120168665300712204232021063124301","best_ask":"0.62","best_bid":"0.6","hash":"fffc8f6dd932173df4a07fc766301f2860d01471","price":"0.64","side":"SELL","size":"94"}],"timestamp":"1785211961010"},"payload_hash":"824c3e97231d648a1858a2345a6190bc5b1b5e2f29bbfdcd55226117b11c2b22","raw_frame":"{\"market\":\"0xd412ce774cfcf8dc9f71164aac78783978aac7b03871702a3b8a481bd9dc9688\", \"price_changes\":[{\"asset_id\":\"96600821790790307414914106093858868634329285205417149685270682748367152458577\", \"price\":\"0.36\", \"size\":\"94\", \"side\":\"BUY\", \"hash\":\"e5bca8bba4b955938f66bdf146a14ec087a9189f\", \"best_bid\":\"0.38\", \"best_ask\":\"0.4\"}, {\"asset_id\":\"107603864457683460275633293642179940881969192120168665300712204232021063124301\", \"price\":\"0.64\", \"size\":\"94\", \"side\":\"SELL\", \"hash\":\"fffc8f6dd932173df4a07fc766301f2860d01471\", \"best_bid\":\"0.6\", \"best_ask\":\"0.62\"}], \"timestamp\":\"1785211961010\", \"event_type\":\"price_change\"}","received_at":"2026-07-28T04:12:41.154003Z","schema_version":"clob-market-ws.price_change.v1","sequence":null,"server_hash":null,"server_timestamp":"1785211961010","session_id":"2d607381e3054cee91998cdf45a4231c","source":"clob_market_ws"},"received_at":"2026-07-28T04:12:41.154003Z","record_id":"f516d9705a1b0bd17a909ea5456c7a272176c419275e01b83c04345a36955d1b","schema_fingerprint":"4aa3821a28b0b7c2400bc59aba4bcc0a76e971dadd19610d3ad38c768e124dc7","schema_version":"edge-lab-recorder.raw.v1","sequence":null,"source":"clob_market_ws"}
