{"event_at":"2026-07-28T04:10:33.920000Z","event_fingerprint":"fabc0c98a19074b518ed8be70b146aa77f72fb7897622e37a4ab78e9251a5f55","payload":{"connection_id":"f6725804f86a4c4eb588e4d5ed7db029","event_at":"2026-07-28T04:10:33.920000Z","event_type":"price_change","frame_hash":"dbab6276b94dc8cdd5f042d617c810ab0a7f14015b2c190300672a1df04b7be1","frame_index":0,"kind":"data","monotonic_ns":313816935739666,"payload":{"event_type":"price_change","market":"0xd412ce774cfcf8dc9f71164aac78783978aac7b03871702a3b8a481bd9dc9688","price_changes":[{"asset_id":"96600821790790307414914106093858868634329285205417149685270682748367152458577","best_ask":"0.37","best_bid":"0.36","hash":"3067b001b79a82b4a93180f6365a209801a5c1d6","price":"0.29","side":"BUY","size":"188"},{"asset_id":"107603864457683460275633293642179940881969192120168665300712204232021063124301","best_ask":"0.64","best_bid":"0.63","hash":"d8116d028c15126496a1252591912cda1587c71b","price":"0.71","side":"SELL","size":"188"}],"timestamp":"1785211833920"},"payload_hash":"dba7dd7ad62e9362f5f5a3841322b02608b07dee872d9f9acfd356b9583693a8","raw_frame":"{\"market\":\"0xd412ce774cfcf8dc9f71164aac78783978aac7b03871702a3b8a481bd9dc9688\", \"price_changes\":[{\"asset_id\":\"96600821790790307414914106093858868634329285205417149685270682748367152458577\", \"price\":\"0.29\", \"size\":\"188\", \"side\":\"BUY\", \"hash\":\"3067b001b79a82b4a93180f6365a209801a5c1d6\", \"best_bid\":\"0.36\", \"best_ask\":\"0.37\"}, {\"asset_id\":\"107603864457683460275633293642179940881969192120168665300712204232021063124301\", \"price\":\"0.71\", \"size\":\"188\", \"side\":\"SELL\", \"hash\":\"d8116d028c15126496a1252591912cda1587c71b\", \"best_bid\":\"0.63\", \"best_ask\":\"0.64\"}], \"timestamp\":\"1785211833920\", \"event_type\":\"price_change\"}","received_at":"2026-07-28T04:10:33.859521Z","schema_version":"clob-market-ws.price_change.v1","sequence":null,"server_hash":null,"server_timestamp":"1785211833920","session_id":"2d607381e3054cee91998cdf45a4231c","source":"clob_market_ws"},"received_at":"2026-07-28T04:10:33.859521Z","record_id":"e8952205b006e6085c4647be3674e4757bda610a20e2597b21ad038f4131ce4d","schema_fingerprint":"4aa3821a28b0b7c2400bc59aba4bcc0a76e971dadd19610d3ad38c768e124dc7","schema_version":"edge-lab-recorder.raw.v1","sequence":null,"source":"clob_market_ws"}
{"event_at":"2026-07-28T04:10:33.921000Z","event_fingerprint":"2886f0a0d5d5ec3ed30d78ce259242223fd55c6623c53b392ebf508accc3ad25","payload":{"connection_id":"f6725804f86a4c4eb588e4d5ed7db029","event_at":"2026-07-28T04:10:33.921000Z","event_type":"price_change","frame_hash":"7431f4f23ff7ffc197411e14a79a28e9204597e4342cb0fddae106153f57f2d6","frame_index":0,"kind":"data","monotonic_ns":313816948190791,"payload":{"event_type":"price_change","market":"0xd412ce774cfcf8dc9f71164aac78783978aac7b03871702a3b8a481bd9dc9688","price_changes":[{"asset_id":"107603864457683460275633293642179940881969192120168665300712204232021063124301","best_ask":"0.64","best_bid":"0.63","hash":"6b0b49194ab1cf1425c25729c82b5a184a2d7358","price":"0.57","side":"BUY","size":"119.6"},{"asset_id":"96600821790790307414914106093858868634329285205417149685270682748367152458577","best_ask":"0.37","best_bid":"0.36","hash":"467f6fde471455944213cacf3c8e92deb8d17244","price":"0.43","side":"SELL","size":"119.6"}],"timestamp":"1785211833921"},"payload_hash":"7419562161ff0f7e133db2cba5f88b80576b7dfe8497368b22f53b2d35b78dc5","raw_frame":"{\"market\":\"0xd412ce774cfcf8dc9f71164aac78783978aac7b03871702a3b8a481bd9dc9688\", \"price_changes\":[{\"asset_id\":\"107603864457683460275633293642179940881969192120168665300712204232021063124301\", \"price\":\"0.57\", \"size\":\"119.6\", \"side\":\"BUY\", \"hash\":\"6b0b49194ab1cf1425c25729c82b5a184a2d7358\", \"best_bid\":\"0.63\", \"best_ask\":\"0.64\"}, {\"asset_id\":\"96600821790790307414914106093858868634329285205417149685270682748367152458577\", \"price\":\"0.43\", \"size\":\"119.6\", \"side\":\"SELL\", \"hash\":\"467f6fde471455944213cacf3c8e92deb8d17244\", \"best_bid\":\"0.36\", \"best_ask\":\"0.37\"}], \"timestamp\":\"1785211833921\", \"event_type\":\"price_change\"}","received_at":"2026-07-28T04:10:33.871972Z","schema_version":"clob-market-ws.price_change.v1","sequence":null,"server_hash":null,"server_timestamp":"1785211833921","session_id":"2d607381e3054cee91998cdf45a4231c","source":"clob_market_ws"},"received_at":"2026-07-28T04:10:33.871972Z","record_id":"9a4b523b445b394172593cb3188d7de7707f74b460687504d9284a083bbf3c5e","schema_fingerprint":"4aa3821a28b0b7c2400bc59aba4bcc0a76e971dadd19610d3ad38c768e124dc7","schema_version":"edge-lab-recorder.raw.v1","sequence":null,"source":"clob_market_ws"}
{"event_at":"2026-07-28T04:10:33.922000Z","event_fingerprint":"b9f548799718f893f4bbcf66dbf541ea5195c94ebba62918ac159e518e9408e6","payload":{"connection_id":"f6725804f86a4c4eb588e4d5ed7db029","event_at":"2026-07-28T04:10:33.922000Z","event_type":"price_change","frame_hash":"2bb007dfec4eafcd9fb2294b920976612fd6953ea21b304a9904362ed83b6479","frame_index":0,"kind":"data","monotonic_ns":313816952559708,"payload":{"event_type":"price_change","market":"0xd412ce774cfcf8dc9f71164aac78783978aac7b03871702a3b8a481bd9dc9688","price_changes":[{"asset_id":"107603864457683460275633293642179940881969192120168665300712204232021063124301","best_ask":"0.64","best_bid":"0.63","hash":"b8293cd28cb2545f5393b97a625204065cd2bb70","price":"0.57","side":"BUY","size":"89.6"},{"asset_id":"96600821790790307414914106093858868634329285205417149685270682748367152458577","best_ask":"0.37","best_bid":"0.36","hash":"b30d41950d53472ad5e452de79c169537f40d3b0","price":"0.43","side":"SELL","size":"89.6"}],"timestamp":"1785211833922"},"payload_hash":"d40b523724a31f7f92e668c82f78de45a7f052a9f047c11f27adcdb1fbc113f3","raw_frame":"{\"market\":\"0xd412ce774cfcf8dc9f71164aac78783978aac7b03871702a3b8a481bd9dc9688\", \"price_changes\":[{\"asset_id\":\"107603864457683460275633293642179940881969192120168665300712204232021063124301\", \"price\":\"0.57\", \"size\":\"89.6\", \"side\":\"BUY\", \"hash\":\"b8293cd28cb2545f5393b97a625204065cd2bb70\", \"best_bid\":\"0.63\", \"best_ask\":\"0.64\"}, {\"asset_id\":\"96600821790790307414914106093858868634329285205417149685270682748367152458577\", \"price\":\"0.43\", \"size\":\"89.6\", \"side\":\"SELL\", \"hash\":\"b30d41950d53472ad5e452de79c169537f40d3b0\", \"best_bid\":\"0.36\", \"best_ask\":\"0.37\"}], \"timestamp\":\"1785211833922\", \"event_type\":\"price_change\"}","received_at":"2026-07-28T04:10:33.876341Z","schema_version":"clob-market-ws.price_change.v1","sequence":null,"server_hash":null,"server_timestamp":"1785211833922","session_id":"2d607381e3054cee91998cdf45a4231c","source":"clob_market_ws"},"received_at":"2026-07-28T04:10:33.876341Z","record_id":"2aba12d917641c244f94a4b3f7dc4b48ecdd6bd05f4932e937ecd21771b48e61","schema_fingerprint":"4aa3821a28b0b7c2400bc59aba4bcc0a76e971dadd19610d3ad38c768e124dc7","schema_version":"edge-lab-recorder.raw.v1","sequence":null,"source":"clob_market_ws"}
{"event_at":"2026-07-28T04:10:33.922000Z","event_fingerprint":"625d23ce4002318ab8c2b1076561d90cbf78620f53d0079664263dcb67eef4d5","payload":{"connection_id":"f6725804f86a4c4eb588e4d5ed7db029","event_at":"2026-07-28T04:10:33.922000Z","event_type":"price_change","frame_hash":"2fc63f28a7ffed76bab7afc93fd0c421baa60fbc8db476c54b345d0559b6c3bc","frame_index":0,"kind":"data","monotonic_ns":313816956310166,"payload":{"event_type":"price_change","market":"0xd412ce774cfcf8dc9f71164aac78783978aac7b03871702a3b8a481bd9dc9688","price_changes":[{"asset_id":"107603864457683460275633293642179940881969192120168665300712204232021063124301","best_ask":"0.64","best_bid":"0.63","hash":"49d359b22c3eb53c24c708d3d1cf877554f29d5b","price":"0.63","side":"BUY","size":"37.6"},{"asset_id":"96600821790790307414914106093858868634329285205417149685270682748367152458577","best_ask":"0.37","best_bid":"0.36","hash":"b14a20128534e368b154f3022ba6afd1aa0d56aa","price":"0.37","side":"SELL","size":"37.6"}],"timestamp":"1785211833922"},"payload_hash":"afb3ee32b0b0960f0b28aa6c4f3098a5ee6d84f5010ae1bfa7678b66713e276f","raw_frame":"{\"market\":\"0xd412ce774cfcf8dc9f71164aac78783978aac7b03871702a3b8a481bd9dc9688\", \"price_changes\":[{\"asset_id\":\"107603864457683460275633293642179940881969192120168665300712204232021063124301\", \"price\":\"0.63\", \"size\":\"37.6\", \"side\":\"BUY\", \"hash\":\"49d359b22c3eb53c24c708d3d1cf877554f29d5b\", \"best_bid\":\"0.63\", \"best_ask\":\"0.64\"}, {\"asset_id\":\"96600821790790307414914106093858868634329285205417149685270682748367152458577\", \"price\":\"0.37\", \"size\":\"37.6\", \"side\":\"SELL\", \"hash\":\"b14a20128534e368b154f3022ba6afd1aa0d56aa\", \"best_bid\":\"0.36\", \"best_ask\":\"0.37\"}], \"timestamp\":\"1785211833922\", \"event_type\":\"price_change\"}","received_at":"2026-07-28T04:10:33.880092Z","schema_version":"clob-market-ws.price_change.v1","sequence":null,"server_hash":null,"server_timestamp":"1785211833922","session_id":"2d607381e3054cee91998cdf45a4231c","source":"clob_market_ws"},"received_at":"2026-07-28T04:10:33.880092Z","record_id":"4d48843685e489b1f0ee29975bbf176c274025d362e4c54eba4102022cb96ff9","schema_fingerprint":"4aa3821a28b0b7c2400bc59aba4bcc0a76e971dadd19610d3ad38c768e124dc7","schema_version":"edge-lab-recorder.raw.v1","sequence":null,"source":"clob_market_ws"}
{"event_at":"2026-07-28T04:10:33.923000Z","event_fingerprint":"cf3184547db3074e89fb572609d95ed7864066c112adb162a280161effc6590e","payload":{"connection_id":"f6725804f86a4c4eb588e4d5ed7db029","event_at":"2026-07-28T04:10:33.923000Z","event_type":"price_change","frame_hash":"edd9ae547e509f70bbc899341c508e4c6efa09b4966184385fef1b69e1add746","frame_index":0,"kind":"data","monotonic_ns":313816961320500,"payload":{"event_type":"price_change","market":"0xd412ce774cfcf8dc9f71164aac78783978aac7b03871702a3b8a481bd9dc9688","price_changes":[{"asset_id":"96600821790790307414914106093858868634329285205417149685270682748367152458577","best_ask":"0.37","best_bid":"0.36","hash":"d86f15865cc1e20318f23ae7e097459e46a894c0","price":"0.33","side":"BUY","size":"138.38"},{"asset_id":"107603864457683460275633293642179940881969192120168665300712204232021063124301","best_ask":"0.64","best_bid":"0.63","hash":"e78b2d32f014bfb7722f596582260e5b8492d517","price":"0.67","side":"SELL","size":"138.38"}],"timestamp":"1785211833923"},"payload_hash":"b86b0f02326364cc6c3eaa966d8c82bef03e47f90d8f4f5ecfbf419348cf1793","raw_frame":"{\"market\":\"0xd412ce774cfcf8dc9f71164aac78783978aac7b03871702a3b8a481bd9dc9688\", \"price_changes\":[{\"asset_id\":\"96600821790790307414914106093858868634329285205417149685270682748367152458577\", \"price\":\"0.33\", \"size\":\"138.38\", \"side\":\"BUY\", \"hash\":\"d86f15865cc1e20318f23ae7e097459e46a894c0\", \"best_bid\":\"0.36\", \"best_ask\":\"0.37\"}, {\"asset_id\":\"107603864457683460275633293642179940881969192120168665300712204232021063124301\", \"price\":\"0.67\", \"size\":\"138.38\", \"side\":\"SELL\", \"hash\":\"e78b2d32f014bfb7722f596582260e5b8492d517\", \"best_bid\":\"0.63\", \"best_ask\":\"0.64\"}], \"timestamp\":\"1785211833923\", \"event_type\":\"price_change\"}","received_at":"2026-07-28T04:10:33.885100Z","schema_version":"clob-market-ws.price_change.v1","sequence":null,"server_hash":null,"server_timestamp":"1785211833923","session_id":"2d607381e3054cee91998cdf45a4231c","source":"clob_market_ws"},"received_at":"2026-07-28T04:10:33.885100Z","record_id":"7f7db44eafccb976dd9a4ae8a249d8a7cd993baf9d9f640cb805c3aaf06e64d2","schema_fingerprint":"4aa3821a28b0b7c2400bc59aba4bcc0a76e971dadd19610d3ad38c768e124dc7","schema_version":"edge-lab-recorder.raw.v1","sequence":null,"source":"clob_market_ws"}
{"event_at":"2026-07-28T04:10:33.923000Z","event_fingerprint":"aac28cb7757472c475dfbf700c29b45ab2e22fd785b35bd5d5be9d951a3deefb","payload":{"connection_id":"f6725804f86a4c4eb588e4d5ed7db029","event_at":"2026-07-28T04:10:33.923000Z","event_type":"price_change","frame_hash":"d9acd4dd5102d48698442f2a5cf1a20c49dbcc72a61c22f4a27eae4fd35181f0","frame_index":0,"kind":"data","monotonic_ns":313816965550500,"payload":{"event_type":"price_change","market":"0xd412ce774cfcf8dc9f71164aac78783978aac7b03871702a3b8a481bd9dc9688","price_changes":[{"asset_id":"107603864457683460275633293642179940881969192120168665300712204232021063124301","best_ask":"0.64","best_bid":"0.63","hash":"e513b1d25870f76ae370f72a51dc3b9a8c1a0475","price":"0.59","side":"BUY","size":"71.6"},{"asset_id":"96600821790790307414914106093858868634329285205417149685270682748367152458577","best_ask":"0.37","best_bid":"0.36","hash":"d8130311d7bbdf3194913b0eb6304e60036e3742","price":"0.41","side":"SELL","size":"71.6"}],"timestamp":"1785211833923"},"payload_hash":"954c9d64011abd4fc970bf47d67317b1b85f382bf42c39856bea1c9fd8ba5a5d","raw_frame":"{\"market\":\"0xd412ce774cfcf8dc9f71164aac78783978aac7b03871702a3b8a481bd9dc9688\", \"price_changes\":[{\"asset_id\":\"107603864457683460275633293642179940881969192120168665300712204232021063124301\", \"price\":\"0.59\", \"size\":\"71.6\", \"side\":\"BUY\", \"hash\":\"e513b1d25870f76ae370f72a51dc3b9a8c1a0475\", \"best_bid\":\"0.63\", \"best_ask\":\"0.64\"}, {\"asset_id\":\"96600821790790307414914106093858868634329285205417149685270682748367152458577\", \"price\":\"0.41\", \"size\":\"71.6\", \"side\":\"SELL\", \"hash\":\"d8130311d7bbdf3194913b0eb6304e60036e3742\", \"best_bid\":\"0.36\", \"best_ask\":\"0.37\"}], \"timestamp\":\"1785211833923\", \"event_type\":\"price_change\"}","received_at":"2026-07-28T04:10:33.889332Z","schema_version":"clob-market-ws.price_change.v1","sequence":null,"server_hash":null,"server_timestamp":"1785211833923","session_id":"2d607381e3054cee91998cdf45a4231c","source":"clob_market_ws"},"received_at":"2026-07-28T04:10:33.889332Z","record_id":"70c4a8e1e9774da5c590c1064cdf36d4c44cce70effd343b5c10c033c8e9e327","schema_fingerprint":"4aa3821a28b0b7c2400bc59aba4bcc0a76e971dadd19610d3ad38c768e124dc7","schema_version":"edge-lab-recorder.raw.v1","sequence":null,"source":"clob_market_ws"}
{"event_at":"2026-07-28T04:10:33.924000Z","event_fingerprint":"ebfb5e750d61c001e2fd02db89766f12e7be3a1803ba053f3aed1819871dbbe5","payload":{"connection_id":"f6725804f86a4c4eb588e4d5ed7db029","event_at":"2026-07-28T04:10:33.924000Z","event_type":"price_change","frame_hash":"5264f3931c65fa326c37468426e24f5d60c55fdcf15f934d99f70fb3ce023968","frame_index":0,"kind":"data","monotonic_ns":313816969130250,"payload":{"event_type":"price_change","market":"0xd412ce774cfcf8dc9f71164aac78783978aac7b03871702a3b8a481bd9dc9688","price_changes":[{"asset_id":"107603864457683460275633293642179940881969192120168665300712204232021063124301","best_ask":"0.64","best_bid":"0.63","hash":"7c360ed84cb1217b37c67a29f4bba811824205f0","price":"0.55","side":"BUY","size":"71"},{"asset_id":"96600821790790307414914106093858868634329285205417149685270682748367152458577","best_ask":"0.37","best_bid":"0.36","hash":"0caf4b49dd4c51a3543de9fa344e281d1c5f9ac5","price":"0.45","side":"SELL","size":"71"}],"timestamp":"1785211833924"},"payload_hash":"c53f8aaa63d6820247d84387c6c0406b16a1235caf8f2369fc6252b3a5ab562e","raw_frame":"{\"market\":\"0xd412ce774cfcf8dc9f71164aac78783978aac7b03871702a3b8a481bd9dc9688\", \"price_changes\":[{\"asset_id\":\"107603864457683460275633293642179940881969192120168665300712204232021063124301\", \"price\":\"0.55\", \"size\":\"71\", \"side\":\"BUY\", \"hash\":\"7c360ed84cb1217b37c67a29f4bba811824205f0\", \"best_bid\":\"0.63\", \"best_ask\":\"0.64\"}, {\"asset_id\":\"96600821790790307414914106093858868634329285205417149685270682748367152458577\", \"price\":\"0.45\", \"size\":\"71\", \"side\":\"SELL\", \"hash\":\"0caf4b49dd4c51a3543de9fa344e281d1c5f9ac5\", \"best_bid\":\"0.36\", \"best_ask\":\"0.37\"}], \"timestamp\":\"1785211833924\", \"event_type\":\"price_change\"}","received_at":"2026-07-28T04:10:33.892909Z","schema_version":"clob-market-ws.price_change.v1","sequence":null,"server_hash":null,"server_timestamp":"1785211833924","session_id":"2d607381e3054cee91998cdf45a4231c","source":"clob_market_ws"},"received_at":"2026-07-28T04:10:33.892909Z","record_id":"4a67c46308e7a74b32a44a991704b0a87b20573c13bdc493f65bebb4c30e9462","schema_fingerprint":"4aa3821a28b0b7c2400bc59aba4bcc0a76e971dadd19610d3ad38c768e124dc7","schema_version":"edge-lab-recorder.raw.v1","sequence":null,"source":"clob_market_ws"}
{"event_at":"2026-07-28T04:10:33.924000Z","event_fingerprint":"afc8e3426e53b9f612c6eb6de5c8ab41794ecfc9e60c63e49b8e0fe7d3113a71","payload":{"connection_id":"f6725804f86a4c4eb588e4d5ed7db029","event_at":"2026-07-28T04:10:33.924000Z","event_type":"price_change","frame_hash":"068c600fe1587c0ef87a016b79a60f78c62c981104f59975af4ef944d7f8328e","frame_index":0,"kind":"data","monotonic_ns":313816974311083,"payload":{"event_type":"price_change","market":"0xd412ce774cfcf8dc9f71164aac78783978aac7b03871702a3b8a481bd9dc9688","price_changes":[{"asset_id":"96600821790790307414914106093858868634329285205417149685270682748367152458577","best_ask":"0.37","best_bid":"0.36","hash":"1ccabaebe90b2e3ebf4fed6ca862f9da6661a5cd","price":"0.34","side":"BUY","size":"77.6"},{"asset_id":"107603864457683460275633293642179940881969192120168665300712204232021063124301","best_ask":"0.64","best_bid":"0.63","hash":"574605943e2996201487a84b80b622077c63b94a","price":"0.66","side":"SELL","size":"77.6"}],"timestamp":"1785211833924"},"payload_hash":"640303c9a2b937bb181aed3238478b6aa68469fe33ee910adaeb72e4184e0f9b","raw_frame":"{\"market\":\"0xd412ce774cfcf8dc9f71164aac78783978aac7b03871702a3b8a481bd9dc9688\", \"price_changes\":[{\"asset_id\":\"96600821790790307414914106093858868634329285205417149685270682748367152458577\", \"price\":\"0.34\", \"size\":\"77.6\", \"side\":\"BUY\", \"hash\":\"1ccabaebe90b2e3ebf4fed6ca862f9da6661a5cd\", \"best_bid\":\"0.36\", \"best_ask\":\"0.37\"}, {\"asset_id\":\"107603864457683460275633293642179940881969192120168665300712204232021063124301\", \"price\":\"0.66\", \"size\":\"77.6\", \"side\":\"SELL\", \"hash\":\"574605943e2996201487a84b80b622077c63b94a\", \"best_bid\":\"0.63\", \"best_ask\":\"0.64\"}], \"timestamp\":\"1785211833924\", \"event_type\":\"price_change\"}","received_at":"2026-07-28T04:10:33.898093Z","schema_version":"clob-market-ws.price_change.v1","sequence":null,"server_hash":null,"server_timestamp":"1785211833924","session_id":"2d607381e3054cee91998cdf45a4231c","source":"clob_market_ws"},"received_at":"2026-07-28T04:10:33.898093Z","record_id":"40599628ad36b212506e5390474051d9bc9660894f774ed98b360b9d32d6ca24","schema_fingerprint":"4aa3821a28b0b7c2400bc59aba4bcc0a76e971dadd19610d3ad38c768e124dc7","schema_version":"edge-lab-recorder.raw.v1","sequence":null,"source":"clob_market_ws"}
{"event_at":"2026-07-28T04:10:33.925000Z","event_fingerprint":"8ab1a0b6b4a4400a73e37478ac3891869e4b4adf530b840e1b092b948becb3f1","payload":{"connection_id":"f6725804f86a4c4eb588e4d5ed7db029","event_at":"2026-07-28T04:10:33.925000Z","event_type":"price_change","frame_hash":"421eba10295134dc76d88c68bcf6c22374edffe4186792930b689083791d74bc","frame_index":0,"kind":"data","monotonic_ns":313816978065083,"payload":{"event_type":"price_change","market":"0xd412ce774cfcf8dc9f71164aac78783978aac7b03871702a3b8a481bd9dc9688","price_changes":[{"asset_id":"107603864457683460275633293642179940881969192120168665300712204232021063124301","best_ask":"0.64","best_bid":"0.63","hash":"110164b4bac24ea7fc131b262f1eecb3ef769993","price":"0.57","side":"BUY","size":"59.6"},{"asset_id":"96600821790790307414914106093858868634329285205417149685270682748367152458577","best_ask":"0.37","best_bid":"0.36","hash":"ba3da5d94a097bd7d85846d893efae3692637fba","price":"0.43","side":"SELL","size":"59.6"}],"timestamp":"1785211833925"},"payload_hash":"a8f093dbad05b15371a9f611c726c33d18ea9e364203f0a0103fa74e723097e8","raw_frame":"{\"market\":\"0xd412ce774cfcf8dc9f71164aac78783978aac7b03871702a3b8a481bd9dc9688\", \"price_changes\":[{\"asset_id\":\"107603864457683460275633293642179940881969192120168665300712204232021063124301\", \"price\":\"0.57\", \"size\":\"59.6\", \"side\":\"BUY\", \"hash\":\"110164b4bac24ea7fc131b262f1eecb3ef769993\", \"best_bid\":\"0.63\", \"best_ask\":\"0.64\"}, {\"asset_id\":\"96600821790790307414914106093858868634329285205417149685270682748367152458577\", \"price\":\"0.43\", \"size\":\"59.6\", \"side\":\"SELL\", \"hash\":\"ba3da5d94a097bd7d85846d893efae3692637fba\", \"best_bid\":\"0.36\", \"best_ask\":\"0.37\"}], \"timestamp\":\"1785211833925\", \"event_type\":\"price_change\"}","received_at":"2026-07-28T04:10:33.901845Z","schema_version":"clob-market-ws.price_change.v1","sequence":null,"server_hash":null,"server_timestamp":"1785211833925","session_id":"2d607381e3054cee91998cdf45a4231c","source":"clob_market_ws"},"received_at":"2026-07-28T04:10:33.901845Z","record_id":"5eb4a9932ed239bf77e304fa63ff02ffe12f6bcce0ca6db33d6c732a4966157c","schema_fingerprint":"4aa3821a28b0b7c2400bc59aba4bcc0a76e971dadd19610d3ad38c768e124dc7","schema_version":"edge-lab-recorder.raw.v1","sequence":null,"source":"clob_market_ws"}
{"event_at":"2026-07-28T04:10:33.925000Z","event_fingerprint":"9f3f98002886ecab69912a33390a60e73269f46448f147a8ed4e9e2921289f0d","payload":{"connection_id":"f6725804f86a4c4eb588e4d5ed7db029","event_at":"2026-07-28T04:10:33.925000Z","event_type":"best_bid_ask","frame_hash":"a07e572adb394b6fd9a486b314c05c4f86397e12036cc04ab4420d3218d28188","frame_index":0,"kind":"data","monotonic_ns":313816982563875,"payload":{"asset_id":"107603864457683460275633293642179940881969192120168665300712204232021063124301","best_ask":"0.65","best_bid":"0.63","event_type":"best_bid_ask","market":"0xd412ce774cfcf8dc9f71164aac78783978aac7b03871702a3b8a481bd9dc9688","spread":"0.02","timestamp":"1785211833925"},"payload_hash":"e43e840db5384eb778a69fb3d14b2b34a7657dc010d8179c55ab9f94e32b65ee","raw_frame":"{\"market\":\"0xd412ce774cfcf8dc9f71164aac78783978aac7b03871702a3b8a481bd9dc9688\", \"asset_id\":\"107603864457683460275633293642179940881969192120168665300712204232021063124301\", \"best_bid\":\"0.63\", \"best_ask\":\"0.65\", \"spread\":\"0.02\", \"timestamp\":\"1785211833925\", \"event_type\":\"best_bid_ask\"}","received_at":"2026-07-28T04:10:33.906342Z","schema_version":"clob-market-ws.best_bid_ask.v1","sequence":null,"server_hash":null,"server_timestamp":"1785211833925","session_id":"2d607381e3054cee91998cdf45a4231c","source":"clob_market_ws"},"received_at":"2026-07-28T04:10:33.906342Z","record_id":"e82e4084507a40fcf1cf7a6c546990fda81ec41bc33333a03988eb1efa27dc1e","schema_fingerprint":"8488399f31b0337811b13b266be932db7062827c2470b78bd8e9e99bab51d17d","schema_version":"edge-lab-recorder.raw.v1","sequence":null,"source":"clob_market_ws"}
{"event_at":"2026-07-28T04:10:33.925000Z","event_fingerprint":"388a2b29b8a0f08a5e2d56dcfb24c943cb0b3c47b71a4514857375729e5ce0cb","payload":{"connection_id":"f6725804f86a4c4eb588e4d5ed7db029","event_at":"2026-07-28T04:10:33.925000Z","event_type":"best_bid_ask","frame_hash":"01e60ab130a4e38af112b70bcc962ca784bec5a5e17e2d396379d6c516206b82","frame_index":0,"kind":"data","monotonic_ns":313816987952333,"payload":{"asset_id":"96600821790790307414914106093858868634329285205417149685270682748367152458577","best_ask":"0.37","best_bid":"0.35","event_type":"best_bid_ask","market":"0xd412ce774cfcf8dc9f71164aac78783978aac7b03871702a3b8a481bd9dc9688","spread":"0.02","timestamp":"1785211833925"},"payload_hash":"f24bac758fcff7c41565de428d1c2cbdaae79bad9a53c493ed87b942eceb873b","raw_frame":"{\"market\":\"0xd412ce774cfcf8dc9f71164aac78783978aac7b03871702a3b8a481bd9dc9688\", \"asset_id\":\"96600821790790307414914106093858868634329285205417149685270682748367152458577\", \"best_bid\":\"0.35\", \"best_ask\":\"0.37\", \"spread\":\"0.02\", \"timestamp\":\"1785211833925\", \"event_type\":\"best_bid_ask\"}","received_at":"2026-07-28T04:10:33.911734Z","schema_version":"clob-market-ws.best_bid_ask.v1","sequence":null,"server_hash":null,"server_timestamp":"1785211833925","session_id":"2d607381e3054cee91998cdf45a4231c","source":"clob_market_ws"},"received_at":"2026-07-28T04:10:33.911734Z","record_id":"069ddf30c7e896c847491ecc2ba4435ece485aa4359b409c8096af2076a7bac2","schema_fingerprint":"8488399f31b0337811b13b266be932db7062827c2470b78bd8e9e99bab51d17d","schema_version":"edge-lab-recorder.raw.v1","sequence":null,"source":"clob_market_ws"}
{"event_at":"2026-07-28T04:10:33.925000Z","event_fingerprint":"ab5fb2e601690b0190321ade952009715a63b49e7d5c18a5d2b61b63edd85f97","payload":{"connection_id":"f6725804f86a4c4eb588e4d5ed7db029","event_at":"2026-07-28T04:10:33.925000Z","event_type":"price_change","frame_hash":"01784541fb07c3d298fe9284d79f5e7c10f9c05d143ad206c691fcebdb5f4e40","frame_index":0,"kind":"data","monotonic_ns":313816992706541,"payload":{"event_type":"price_change","market":"0xd412ce774cfcf8dc9f71164aac78783978aac7b03871702a3b8a481bd9dc9688","price_changes":[{"asset_id":"96600821790790307414914106093858868634329285205417149685270682748367152458577","best_ask":"0.37","best_bid":"0.35","hash":"56f570693132de37f54dd306b59daaddf1b48245","price":"0.36","side":"BUY","size":"0"},{"asset_id":"107603864457683460275633293642179940881969192120168665300712204232021063124301","best_ask":"0.65","best_bid":"0.63","hash":"28ed9ae2e06b24f0fe73f97bb330a1145c0f01d7","price":"0.64","side":"SELL","size":"0"}],"timestamp":"1785211833925"},"payload_hash":"c0dbb4ae33cb9e82b5031b6054e86ed8a069e1e92d4099de66b95b134edfd528","raw_frame":"{\"market\":\"0xd412ce774cfcf8dc9f71164aac78783978aac7b03871702a3b8a481bd9dc9688\", \"price_changes\":[{\"asset_id\":\"96600821790790307414914106093858868634329285205417149685270682748367152458577\", \"price\":\"0.36\", \"size\":\"0\", \"side\":\"BUY\", \"hash\":\"56f570693132de37f54dd306b59daaddf1b48245\", \"best_bid\":\"0.35\", \"best_ask\":\"0.37\"}, {\"asset_id\":\"107603864457683460275633293642179940881969192120168665300712204232021063124301\", \"price\":\"0.64\", \"size\":\"0\", \"side\":\"SELL\", \"hash\":\"28ed9ae2e06b24f0fe73f97bb330a1145c0f01d7\", \"best_bid\":\"0.63\", \"best_ask\":\"0.65\"}], \"timestamp\":\"1785211833925\", \"event_type\":\"price_change\"}","received_at":"2026-07-28T04:10:33.916488Z","schema_version":"clob-market-ws.price_change.v1","sequence":null,"server_hash":null,"server_timestamp":"1785211833925","session_id":"2d607381e3054cee91998cdf45a4231c","source":"clob_market_ws"},"received_at":"2026-07-28T04:10:33.916488Z","record_id":"4f38ecabd9081ac778037b8531a0bb8da70013cba6f43d0911b1183f78b16730","schema_fingerprint":"4aa3821a28b0b7c2400bc59aba4bcc0a76e971dadd19610d3ad38c768e124dc7","schema_version":"edge-lab-recorder.raw.v1","sequence":null,"source":"clob_market_ws"}
{"event_at":"2026-07-28T04:10:33.925000Z","event_fingerprint":"fe987e463787eeb43d01d0508cdcfbeef9dad23200019048b044c69b3694fb0c","payload":{"connection_id":"f6725804f86a4c4eb588e4d5ed7db029","event_at":"2026-07-28T04:10:33.925000Z","event_type":"price_change","frame_hash":"05a4ea6772ea06649455a8cce2d43f672095c675f26b2ecff3f4066450ab6e85","frame_index":0,"kind":"data","monotonic_ns":313816996517083,"payload":{"event_type":"price_change","market":"0xd412ce774cfcf8dc9f71164aac78783978aac7b03871702a3b8a481bd9dc9688","price_changes":[{"asset_id":"107603864457683460275633293642179940881969192120168665300712204232021063124301","best_ask":"0.65","best_bid":"0.63","hash":"58431b0573002c0ca362ff882a48827526dccfce","price":"0.63","side":"BUY","size":"50.2"},{"asset_id":"96600821790790307414914106093858868634329285205417149685270682748367152458577","best_ask":"0.37","best_bid":"0.35","hash":"e4c79680c4fad6519459a3b8158e36b09b047f2b","price":"0.37","side":"SELL","size":"50.2"}],"timestamp":"1785211833925"},"payload_hash":"8ecc6ded2d7b09cd614dfdfc634e282a6c745145f8d1d0845d33a03b598fb554","raw_frame":"{\"market\":\"0xd412ce774cfcf8dc9f71164aac78783978aac7b03871702a3b8a481bd9dc9688\", \"price_changes\":[{\"asset_id\":\"107603864457683460275633293642179940881969192120168665300712204232021063124301\", \"price\":\"0.63\", \"size\":\"50.2\", \"side\":\"BUY\", \"hash\":\"58431b0573002c0ca362ff882a48827526dccfce\", \"best_bid\":\"0.63\", \"best_ask\":\"0.65\"}, {\"asset_id\":\"96600821790790307414914106093858868634329285205417149685270682748367152458577\", \"price\":\"0.37\", \"size\":\"50.2\", \"side\":\"SELL\", \"hash\":\"e4c79680c4fad6519459a3b8158e36b09b047f2b\", \"best_bid\":\"0.35\", \"best_ask\":\"0.37\"}], \"timestamp\":\"1785211833925\", \"event_type\":\"price_change\"}","received_at":"2026-07-28T04:10:33.920298Z","schema_version":"clob-market-ws.price_change.v1","sequence":null,"server_hash":null,"server_timestamp":"1785211833925","session_id":"2d607381e3054cee91998cdf45a4231c","source":"clob_market_ws"},"received_at":"2026-07-28T04:10:33.920298Z","record_id":"e45e82aeb7e694434c86fdece662fec1aaab0db462a73bfc09f32a17c763d07c","schema_fingerprint":"4aa3821a28b0b7c2400bc59aba4bcc0a76e971dadd19610d3ad38c768e124dc7","schema_version":"edge-lab-recorder.raw.v1","sequence":null,"source":"clob_market_ws"}
