{"event_at":"2026-07-28T04:03:47.719000Z","event_fingerprint":"f87ae1dddc3b415a18b7f50d586006229ccb24c6ef60cedf241db4e651b7afed","payload":{"connection_id":"f6725804f86a4c4eb588e4d5ed7db029","event_at":"2026-07-28T04:03:47.719000Z","event_type":"price_change","frame_hash":"88417cb5261aceb7a389a2c821f7e5b2306ac6bfff23b48b3b87e5cac0d0f5ec","frame_index":0,"kind":"data","monotonic_ns":313412773466500,"payload":{"event_type":"price_change","market":"0xd412ce774cfcf8dc9f71164aac78783978aac7b03871702a3b8a481bd9dc9688","price_changes":[{"asset_id":"107603864457683460275633293642179940881969192120168665300712204232021063124301","best_ask":"0.57","best_bid":"0.56","hash":"579fcdc9aea4bdfd718e7a459e6465a8dddf28d0","price":"0.01","side":"BUY","size":"7888.02"},{"asset_id":"96600821790790307414914106093858868634329285205417149685270682748367152458577","best_ask":"0.44","best_bid":"0.43","hash":"40df8af8836284d6d980623a95070a5831945782","price":"0.99","side":"SELL","size":"7888.02"}],"timestamp":"1785211427719"},"payload_hash":"feb3bc5d0509d377075ef6341382d0600d2fba2e482e99bf4e006d313e3035f7","raw_frame":"{\"market\":\"0xd412ce774cfcf8dc9f71164aac78783978aac7b03871702a3b8a481bd9dc9688\", \"price_changes\":[{\"asset_id\":\"107603864457683460275633293642179940881969192120168665300712204232021063124301\", \"price\":\"0.01\", \"size\":\"7888.02\", \"side\":\"BUY\", \"hash\":\"579fcdc9aea4bdfd718e7a459e6465a8dddf28d0\", \"best_bid\":\"0.56\", \"best_ask\":\"0.57\"}, {\"asset_id\":\"96600821790790307414914106093858868634329285205417149685270682748367152458577\", \"price\":\"0.99\", \"size\":\"7888.02\", \"side\":\"SELL\", \"hash\":\"40df8af8836284d6d980623a95070a5831945782\", \"best_bid\":\"0.43\", \"best_ask\":\"0.44\"}], \"timestamp\":\"1785211427719\", \"event_type\":\"price_change\"}","received_at":"2026-07-28T04:03:49.723840Z","schema_version":"clob-market-ws.price_change.v1","sequence":null,"server_hash":null,"server_timestamp":"1785211427719","session_id":"2d607381e3054cee91998cdf45a4231c","source":"clob_market_ws"},"received_at":"2026-07-28T04:03:49.723840Z","record_id":"25c7bd12b22833fe82df09a5ee218694ca8bb935a07c47caf0fcd2d7046abb56","schema_fingerprint":"4aa3821a28b0b7c2400bc59aba4bcc0a76e971dadd19610d3ad38c768e124dc7","schema_version":"edge-lab-recorder.raw.v1","sequence":null,"source":"clob_market_ws"}
{"event_at":"2026-07-28T04:03:47.741000Z","event_fingerprint":"9ee8ed07b8d561066f112f4599dbd10703940727addbd717b58dc351a8743a9e","payload":{"connection_id":"f6725804f86a4c4eb588e4d5ed7db029","event_at":"2026-07-28T04:03:47.741000Z","event_type":"price_change","frame_hash":"0469bd4838f03baee31a3501bec4c7e6250fd187c1c338768c76a168d260e034","frame_index":0,"kind":"data","monotonic_ns":313412776091375,"payload":{"event_type":"price_change","market":"0xd412ce774cfcf8dc9f71164aac78783978aac7b03871702a3b8a481bd9dc9688","price_changes":[{"asset_id":"107603864457683460275633293642179940881969192120168665300712204232021063124301","best_ask":"0.57","best_bid":"0.56","hash":"1673ee4563b9d3449095d5728636d958d3323c12","price":"0.01","side":"BUY","size":"7883.02"},{"asset_id":"96600821790790307414914106093858868634329285205417149685270682748367152458577","best_ask":"0.44","best_bid":"0.43","hash":"045232984274ee091253e8a83325aaca5e1a5e48","price":"0.99","side":"SELL","size":"7883.02"}],"timestamp":"1785211427741"},"payload_hash":"74a4a35be67aa63ec588bb5f8ebb1816c956e18c87845c799171652801004b68","raw_frame":"{\"market\":\"0xd412ce774cfcf8dc9f71164aac78783978aac7b03871702a3b8a481bd9dc9688\", \"price_changes\":[{\"asset_id\":\"107603864457683460275633293642179940881969192120168665300712204232021063124301\", \"price\":\"0.01\", \"size\":\"7883.02\", \"side\":\"BUY\", \"hash\":\"1673ee4563b9d3449095d5728636d958d3323c12\", \"best_bid\":\"0.56\", \"best_ask\":\"0.57\"}, {\"asset_id\":\"96600821790790307414914106093858868634329285205417149685270682748367152458577\", \"price\":\"0.99\", \"size\":\"7883.02\", \"side\":\"SELL\", \"hash\":\"045232984274ee091253e8a83325aaca5e1a5e48\", \"best_bid\":\"0.43\", \"best_ask\":\"0.44\"}], \"timestamp\":\"1785211427741\", \"event_type\":\"price_change\"}","received_at":"2026-07-28T04:03:49.726473Z","schema_version":"clob-market-ws.price_change.v1","sequence":null,"server_hash":null,"server_timestamp":"1785211427741","session_id":"2d607381e3054cee91998cdf45a4231c","source":"clob_market_ws"},"received_at":"2026-07-28T04:03:49.726473Z","record_id":"21ff9e7e6440bdaec2c15abf701a857779877084f709a2bf9154062fb5af4b95","schema_fingerprint":"4aa3821a28b0b7c2400bc59aba4bcc0a76e971dadd19610d3ad38c768e124dc7","schema_version":"edge-lab-recorder.raw.v1","sequence":null,"source":"clob_market_ws"}
{"event_at":"2026-07-28T04:03:47.773000Z","event_fingerprint":"a9bb601f6084e8a40afd0f87fc555e10d94ed94ebab825cd370a424dacc16b28","payload":{"connection_id":"f6725804f86a4c4eb588e4d5ed7db029","event_at":"2026-07-28T04:03:47.773000Z","event_type":"price_change","frame_hash":"19ddc76bd68e1aea729c41cdfacebd7ca7a612c8a32309958a2c492422fde15e","frame_index":0,"kind":"data","monotonic_ns":313412777809125,"payload":{"event_type":"price_change","market":"0xd412ce774cfcf8dc9f71164aac78783978aac7b03871702a3b8a481bd9dc9688","price_changes":[{"asset_id":"107603864457683460275633293642179940881969192120168665300712204232021063124301","best_ask":"0.57","best_bid":"0.56","hash":"f65af01d1acb1b0e7e5e4bcdb1b147d65bcbdd4a","price":"0.03","side":"BUY","size":"613.1"},{"asset_id":"96600821790790307414914106093858868634329285205417149685270682748367152458577","best_ask":"0.44","best_bid":"0.43","hash":"4da5317c8e5aec2b3d7e68974c012a1d5b4e9e60","price":"0.97","side":"SELL","size":"613.1"}],"timestamp":"1785211427773"},"payload_hash":"8bf56d4108760e6287977e71c682a9de8f3cb7f6a48f7fa6fea29cd722478780","raw_frame":"{\"market\":\"0xd412ce774cfcf8dc9f71164aac78783978aac7b03871702a3b8a481bd9dc9688\", \"price_changes\":[{\"asset_id\":\"107603864457683460275633293642179940881969192120168665300712204232021063124301\", \"price\":\"0.03\", \"size\":\"613.1\", \"side\":\"BUY\", \"hash\":\"f65af01d1acb1b0e7e5e4bcdb1b147d65bcbdd4a\", \"best_bid\":\"0.56\", \"best_ask\":\"0.57\"}, {\"asset_id\":\"96600821790790307414914106093858868634329285205417149685270682748367152458577\", \"price\":\"0.97\", \"size\":\"613.1\", \"side\":\"SELL\", \"hash\":\"4da5317c8e5aec2b3d7e68974c012a1d5b4e9e60\", \"best_bid\":\"0.43\", \"best_ask\":\"0.44\"}], \"timestamp\":\"1785211427773\", \"event_type\":\"price_change\"}","received_at":"2026-07-28T04:03:49.728193Z","schema_version":"clob-market-ws.price_change.v1","sequence":null,"server_hash":null,"server_timestamp":"1785211427773","session_id":"2d607381e3054cee91998cdf45a4231c","source":"clob_market_ws"},"received_at":"2026-07-28T04:03:49.728193Z","record_id":"6159cc29da3e1f1eb12a3c7be44b623eca898b3ced39971443d720b77025f234","schema_fingerprint":"4aa3821a28b0b7c2400bc59aba4bcc0a76e971dadd19610d3ad38c768e124dc7","schema_version":"edge-lab-recorder.raw.v1","sequence":null,"source":"clob_market_ws"}
{"event_at":"2026-07-28T04:03:47.865000Z","event_fingerprint":"f2c533384c869319776e52136898fd539c27db86b5cff2ecf5c48dc11383f1bb","payload":{"connection_id":"f6725804f86a4c4eb588e4d5ed7db029","event_at":"2026-07-28T04:03:47.865000Z","event_type":"price_change","frame_hash":"0e847b0a7e03df4df4a8332de98553d8ed25e6d8fad3a572f0192e7507794dd8","frame_index":0,"kind":"data","monotonic_ns":313412779472416,"payload":{"event_type":"price_change","market":"0xd412ce774cfcf8dc9f71164aac78783978aac7b03871702a3b8a481bd9dc9688","price_changes":[{"asset_id":"96600821790790307414914106093858868634329285205417149685270682748367152458577","best_ask":"0.44","best_bid":"0.43","hash":"94077394edef15e4406b630ee0c13d9ab9dd570b","price":"0.45","side":"SELL","size":"108.28"},{"asset_id":"107603864457683460275633293642179940881969192120168665300712204232021063124301","best_ask":"0.57","best_bid":"0.56","hash":"d97b127d8df0996efe82ef5a366679a14af56cfa","price":"0.55","side":"BUY","size":"108.28"}],"timestamp":"1785211427865"},"payload_hash":"58ecb952c14b429dd75e32f8215128fa620dacdfa82e30f625737ca355d20f5f","raw_frame":"{\"market\":\"0xd412ce774cfcf8dc9f71164aac78783978aac7b03871702a3b8a481bd9dc9688\", \"price_changes\":[{\"asset_id\":\"96600821790790307414914106093858868634329285205417149685270682748367152458577\", \"price\":\"0.45\", \"size\":\"108.28\", \"side\":\"SELL\", \"hash\":\"94077394edef15e4406b630ee0c13d9ab9dd570b\", \"best_bid\":\"0.43\", \"best_ask\":\"0.44\"}, {\"asset_id\":\"107603864457683460275633293642179940881969192120168665300712204232021063124301\", \"price\":\"0.55\", \"size\":\"108.28\", \"side\":\"BUY\", \"hash\":\"d97b127d8df0996efe82ef5a366679a14af56cfa\", \"best_bid\":\"0.56\", \"best_ask\":\"0.57\"}], \"timestamp\":\"1785211427865\", \"event_type\":\"price_change\"}","received_at":"2026-07-28T04:03:49.729855Z","schema_version":"clob-market-ws.price_change.v1","sequence":null,"server_hash":null,"server_timestamp":"1785211427865","session_id":"2d607381e3054cee91998cdf45a4231c","source":"clob_market_ws"},"received_at":"2026-07-28T04:03:49.729855Z","record_id":"15fbaf2e879f4bef2e4b4690b7dee6c2e2688a48292da5de8c2435f44e133bf1","schema_fingerprint":"4aa3821a28b0b7c2400bc59aba4bcc0a76e971dadd19610d3ad38c768e124dc7","schema_version":"edge-lab-recorder.raw.v1","sequence":null,"source":"clob_market_ws"}
{"event_at":"2026-07-28T04:03:47.890000Z","event_fingerprint":"466b21fc3aa18a8266aa86ee1e838dee5d20ccc998c18d6ae2eb95cb640f6f71","payload":{"connection_id":"f6725804f86a4c4eb588e4d5ed7db029","event_at":"2026-07-28T04:03:47.890000Z","event_type":"price_change","frame_hash":"4dbefa59fbd9fa223770faa042fe961a577a0efe20c45609f04868df3af4a2a8","frame_index":0,"kind":"data","monotonic_ns":313412781172416,"payload":{"event_type":"price_change","market":"0xd412ce774cfcf8dc9f71164aac78783978aac7b03871702a3b8a481bd9dc9688","price_changes":[{"asset_id":"107603864457683460275633293642179940881969192120168665300712204232021063124301","best_ask":"0.57","best_bid":"0.56","hash":"47a2f2718f94c4badd74ad6572a23d9626321c26","price":"0.02","side":"BUY","size":"738.1"},{"asset_id":"96600821790790307414914106093858868634329285205417149685270682748367152458577","best_ask":"0.44","best_bid":"0.43","hash":"1145b3b79168dfbf827209381fcb6fa930bd5696","price":"0.98","side":"SELL","size":"738.1"}],"timestamp":"1785211427890"},"payload_hash":"4babd64110614ec51c6f5602067a2c7c8392143bfc89fd50d743f0b869fb812d","raw_frame":"{\"market\":\"0xd412ce774cfcf8dc9f71164aac78783978aac7b03871702a3b8a481bd9dc9688\", \"price_changes\":[{\"asset_id\":\"107603864457683460275633293642179940881969192120168665300712204232021063124301\", \"price\":\"0.02\", \"size\":\"738.1\", \"side\":\"BUY\", \"hash\":\"47a2f2718f94c4badd74ad6572a23d9626321c26\", \"best_bid\":\"0.56\", \"best_ask\":\"0.57\"}, {\"asset_id\":\"96600821790790307414914106093858868634329285205417149685270682748367152458577\", \"price\":\"0.98\", \"size\":\"738.1\", \"side\":\"SELL\", \"hash\":\"1145b3b79168dfbf827209381fcb6fa930bd5696\", \"best_bid\":\"0.43\", \"best_ask\":\"0.44\"}], \"timestamp\":\"1785211427890\", \"event_type\":\"price_change\"}","received_at":"2026-07-28T04:03:49.731559Z","schema_version":"clob-market-ws.price_change.v1","sequence":null,"server_hash":null,"server_timestamp":"1785211427890","session_id":"2d607381e3054cee91998cdf45a4231c","source":"clob_market_ws"},"received_at":"2026-07-28T04:03:49.731559Z","record_id":"7d39a199d98a38e1ba572ab7de3b243140ac41a224c42b5095703af0ea636944","schema_fingerprint":"4aa3821a28b0b7c2400bc59aba4bcc0a76e971dadd19610d3ad38c768e124dc7","schema_version":"edge-lab-recorder.raw.v1","sequence":null,"source":"clob_market_ws"}
{"event_at":"2026-07-28T04:03:47.908000Z","event_fingerprint":"95b68286f8f6229d79e2ab14539158c64b71eec35b958340f0cd57c68f833924","payload":{"connection_id":"f6725804f86a4c4eb588e4d5ed7db029","event_at":"2026-07-28T04:03:47.908000Z","event_type":"price_change","frame_hash":"e5345f095e715cfcfd4e52f372f857423d2756a3d8de6e65987a9ff9e9386224","frame_index":0,"kind":"data","monotonic_ns":313412782695500,"payload":{"event_type":"price_change","market":"0xd412ce774cfcf8dc9f71164aac78783978aac7b03871702a3b8a481bd9dc9688","price_changes":[{"asset_id":"107603864457683460275633293642179940881969192120168665300712204232021063124301","best_ask":"0.57","best_bid":"0.56","hash":"db1abd53a45f8173173947a7dd520c27ba3014e7","price":"0.01","side":"BUY","size":"7888.02"},{"asset_id":"96600821790790307414914106093858868634329285205417149685270682748367152458577","best_ask":"0.44","best_bid":"0.43","hash":"fdaed76aa7c886237409eef23642534295a99e6e","price":"0.99","side":"SELL","size":"7888.02"}],"timestamp":"1785211427908"},"payload_hash":"428575c910c0133d9c0904b536df256bdb8660ada1c5742994495f25f8bbb4c1","raw_frame":"{\"market\":\"0xd412ce774cfcf8dc9f71164aac78783978aac7b03871702a3b8a481bd9dc9688\", \"price_changes\":[{\"asset_id\":\"107603864457683460275633293642179940881969192120168665300712204232021063124301\", \"price\":\"0.01\", \"size\":\"7888.02\", \"side\":\"BUY\", \"hash\":\"db1abd53a45f8173173947a7dd520c27ba3014e7\", \"best_bid\":\"0.56\", \"best_ask\":\"0.57\"}, {\"asset_id\":\"96600821790790307414914106093858868634329285205417149685270682748367152458577\", \"price\":\"0.99\", \"size\":\"7888.02\", \"side\":\"SELL\", \"hash\":\"fdaed76aa7c886237409eef23642534295a99e6e\", \"best_bid\":\"0.43\", \"best_ask\":\"0.44\"}], \"timestamp\":\"1785211427908\", \"event_type\":\"price_change\"}","received_at":"2026-07-28T04:03:49.733081Z","schema_version":"clob-market-ws.price_change.v1","sequence":null,"server_hash":null,"server_timestamp":"1785211427908","session_id":"2d607381e3054cee91998cdf45a4231c","source":"clob_market_ws"},"received_at":"2026-07-28T04:03:49.733081Z","record_id":"4fb629919dcfd21a8eb0431d4b14f0a823a11f94cd6d7b3233b094dd335687f7","schema_fingerprint":"4aa3821a28b0b7c2400bc59aba4bcc0a76e971dadd19610d3ad38c768e124dc7","schema_version":"edge-lab-recorder.raw.v1","sequence":null,"source":"clob_market_ws"}
{"event_at":"2026-07-28T04:03:47.934000Z","event_fingerprint":"1568b2eb498c2a787b443ce552eeca87c2598feb61ecf339f8b920c1b70aecb1","payload":{"connection_id":"f6725804f86a4c4eb588e4d5ed7db029","event_at":"2026-07-28T04:03:47.934000Z","event_type":"price_change","frame_hash":"a50c4bc68dfcc678cb5a4bc8ed69aa3b90d9a1bd622a74adf0898c5ff2ae898b","frame_index":0,"kind":"data","monotonic_ns":313412784363541,"payload":{"event_type":"price_change","market":"0xd412ce774cfcf8dc9f71164aac78783978aac7b03871702a3b8a481bd9dc9688","price_changes":[{"asset_id":"107603864457683460275633293642179940881969192120168665300712204232021063124301","best_ask":"0.57","best_bid":"0.56","hash":"5daf17cd523df9c16782d70ea2d2bf4179a8ff55","price":"0.01","side":"BUY","size":"7883.02"},{"asset_id":"96600821790790307414914106093858868634329285205417149685270682748367152458577","best_ask":"0.44","best_bid":"0.43","hash":"cb560389c4b0efda1bb30f1c89343fc2c9523414","price":"0.99","side":"SELL","size":"7883.02"}],"timestamp":"1785211427934"},"payload_hash":"fb75b898bd7eba25b8349937543dc46d498601f31fc40f9e525cb8fb11c7a744","raw_frame":"{\"market\":\"0xd412ce774cfcf8dc9f71164aac78783978aac7b03871702a3b8a481bd9dc9688\", \"price_changes\":[{\"asset_id\":\"107603864457683460275633293642179940881969192120168665300712204232021063124301\", \"price\":\"0.01\", \"size\":\"7883.02\", \"side\":\"BUY\", \"hash\":\"5daf17cd523df9c16782d70ea2d2bf4179a8ff55\", \"best_bid\":\"0.56\", \"best_ask\":\"0.57\"}, {\"asset_id\":\"96600821790790307414914106093858868634329285205417149685270682748367152458577\", \"price\":\"0.99\", \"size\":\"7883.02\", \"side\":\"SELL\", \"hash\":\"cb560389c4b0efda1bb30f1c89343fc2c9523414\", \"best_bid\":\"0.43\", \"best_ask\":\"0.44\"}], \"timestamp\":\"1785211427934\", \"event_type\":\"price_change\"}","received_at":"2026-07-28T04:03:49.734749Z","schema_version":"clob-market-ws.price_change.v1","sequence":null,"server_hash":null,"server_timestamp":"1785211427934","session_id":"2d607381e3054cee91998cdf45a4231c","source":"clob_market_ws"},"received_at":"2026-07-28T04:03:49.734749Z","record_id":"8c78f319efea07e1bbe914ec169e8fa28830d7eed08977a856d3fd7c74c49052","schema_fingerprint":"4aa3821a28b0b7c2400bc59aba4bcc0a76e971dadd19610d3ad38c768e124dc7","schema_version":"edge-lab-recorder.raw.v1","sequence":null,"source":"clob_market_ws"}
{"event_at":"2026-07-28T04:03:47.967000Z","event_fingerprint":"0eb0917ab40205d1a27015a2667fb36fe09a39673491eb59a190c4e4e2375159","payload":{"connection_id":"f6725804f86a4c4eb588e4d5ed7db029","event_at":"2026-07-28T04:03:47.967000Z","event_type":"price_change","frame_hash":"3d4d1b530c8e9527194dce89539fa7fb00ac470d3aa19e2801d25161a8bb8473","frame_index":0,"kind":"data","monotonic_ns":313412785974125,"payload":{"event_type":"price_change","market":"0xd412ce774cfcf8dc9f71164aac78783978aac7b03871702a3b8a481bd9dc9688","price_changes":[{"asset_id":"107603864457683460275633293642179940881969192120168665300712204232021063124301","best_ask":"0.57","best_bid":"0.56","hash":"c5d30700e9956a213d180324edc56fe6290f8ec2","price":"0.02","side":"BUY","size":"733.1"},{"asset_id":"96600821790790307414914106093858868634329285205417149685270682748367152458577","best_ask":"0.44","best_bid":"0.43","hash":"61df29c281796b839adc78b67b0ae7c65efe1ef5","price":"0.98","side":"SELL","size":"733.1"}],"timestamp":"1785211427967"},"payload_hash":"e402d588564818c017eb1e7be28dea05228a6e74e881bff11f608156e1af9cd5","raw_frame":"{\"market\":\"0xd412ce774cfcf8dc9f71164aac78783978aac7b03871702a3b8a481bd9dc9688\", \"price_changes\":[{\"asset_id\":\"107603864457683460275633293642179940881969192120168665300712204232021063124301\", \"price\":\"0.02\", \"size\":\"733.1\", \"side\":\"BUY\", \"hash\":\"c5d30700e9956a213d180324edc56fe6290f8ec2\", \"best_bid\":\"0.56\", \"best_ask\":\"0.57\"}, {\"asset_id\":\"96600821790790307414914106093858868634329285205417149685270682748367152458577\", \"price\":\"0.98\", \"size\":\"733.1\", \"side\":\"SELL\", \"hash\":\"61df29c281796b839adc78b67b0ae7c65efe1ef5\", \"best_bid\":\"0.43\", \"best_ask\":\"0.44\"}], \"timestamp\":\"1785211427967\", \"event_type\":\"price_change\"}","received_at":"2026-07-28T04:03:49.736361Z","schema_version":"clob-market-ws.price_change.v1","sequence":null,"server_hash":null,"server_timestamp":"1785211427967","session_id":"2d607381e3054cee91998cdf45a4231c","source":"clob_market_ws"},"received_at":"2026-07-28T04:03:49.736361Z","record_id":"f696c3f11c5b0552faceac6048fd0dba6b43885cdfc56d490be0571b8d4d7c39","schema_fingerprint":"4aa3821a28b0b7c2400bc59aba4bcc0a76e971dadd19610d3ad38c768e124dc7","schema_version":"edge-lab-recorder.raw.v1","sequence":null,"source":"clob_market_ws"}
{"event_at":"2026-07-28T04:03:47.992000Z","event_fingerprint":"b483589534a9d49d9e906b7144dd71c228b6417bd31ecce2854197ea56d76630","payload":{"connection_id":"f6725804f86a4c4eb588e4d5ed7db029","event_at":"2026-07-28T04:03:47.992000Z","event_type":"price_change","frame_hash":"49a51aaa42e263f45a672948f3238106a7b126fa2f7ba12ca065bd98794f61fa","frame_index":0,"kind":"data","monotonic_ns":313412787502083,"payload":{"event_type":"price_change","market":"0xd412ce774cfcf8dc9f71164aac78783978aac7b03871702a3b8a481bd9dc9688","price_changes":[{"asset_id":"107603864457683460275633293642179940881969192120168665300712204232021063124301","best_ask":"0.57","best_bid":"0.56","hash":"5a5fb81ca94aae745d5bbf24ce8f69de1b17f570","price":"0.53","side":"BUY","size":"97.62"},{"asset_id":"96600821790790307414914106093858868634329285205417149685270682748367152458577","best_ask":"0.44","best_bid":"0.43","hash":"8b17ce99958a9b6f20f565413497ee8a25726d4e","price":"0.47","side":"SELL","size":"97.62"}],"timestamp":"1785211427992"},"payload_hash":"cee94b47a173ab7a8a573367b8633b4ddb672f020749abe40f295f0db76ebd84","raw_frame":"{\"market\":\"0xd412ce774cfcf8dc9f71164aac78783978aac7b03871702a3b8a481bd9dc9688\", \"price_changes\":[{\"asset_id\":\"107603864457683460275633293642179940881969192120168665300712204232021063124301\", \"price\":\"0.53\", \"size\":\"97.62\", \"side\":\"BUY\", \"hash\":\"5a5fb81ca94aae745d5bbf24ce8f69de1b17f570\", \"best_bid\":\"0.56\", \"best_ask\":\"0.57\"}, {\"asset_id\":\"96600821790790307414914106093858868634329285205417149685270682748367152458577\", \"price\":\"0.47\", \"size\":\"97.62\", \"side\":\"SELL\", \"hash\":\"8b17ce99958a9b6f20f565413497ee8a25726d4e\", \"best_bid\":\"0.43\", \"best_ask\":\"0.44\"}], \"timestamp\":\"1785211427992\", \"event_type\":\"price_change\"}","received_at":"2026-07-28T04:03:49.737889Z","schema_version":"clob-market-ws.price_change.v1","sequence":null,"server_hash":null,"server_timestamp":"1785211427992","session_id":"2d607381e3054cee91998cdf45a4231c","source":"clob_market_ws"},"received_at":"2026-07-28T04:03:49.737889Z","record_id":"130602a7feb02d05acc0e916b4370e7c0ea9d5073a597c626490fb5c831b0ecb","schema_fingerprint":"4aa3821a28b0b7c2400bc59aba4bcc0a76e971dadd19610d3ad38c768e124dc7","schema_version":"edge-lab-recorder.raw.v1","sequence":null,"source":"clob_market_ws"}
{"event_at":"2026-07-28T04:03:48.021000Z","event_fingerprint":"9afb130d6cd8cac9462c1888a20b51b62d3e5846ab2e85cbd546edbe6b136b2c","payload":{"connection_id":"f6725804f86a4c4eb588e4d5ed7db029","event_at":"2026-07-28T04:03:48.021000Z","event_type":"price_change","frame_hash":"83022c37654d4de0a84cb3dab562742847bfe592db49410e3344661a2ca48709","frame_index":0,"kind":"data","monotonic_ns":313412789240375,"payload":{"event_type":"price_change","market":"0xd412ce774cfcf8dc9f71164aac78783978aac7b03871702a3b8a481bd9dc9688","price_changes":[{"asset_id":"96600821790790307414914106093858868634329285205417149685270682748367152458577","best_ask":"0.44","best_bid":"0.43","hash":"722e7b21f4bee5d0bffba199fedb9d250b9171ef","price":"0.01","side":"BUY","size":"7858.02"},{"asset_id":"107603864457683460275633293642179940881969192120168665300712204232021063124301","best_ask":"0.57","best_bid":"0.56","hash":"82aec9757e0a95472ab737b353397444346c12a6","price":"0.99","side":"SELL","size":"7858.02"}],"timestamp":"1785211428021"},"payload_hash":"114bdf0660d58114e0c763ae2ae6403209b722442e80d404766dd82e6599db54","raw_frame":"{\"market\":\"0xd412ce774cfcf8dc9f71164aac78783978aac7b03871702a3b8a481bd9dc9688\", \"price_changes\":[{\"asset_id\":\"96600821790790307414914106093858868634329285205417149685270682748367152458577\", \"price\":\"0.01\", \"size\":\"7858.02\", \"side\":\"BUY\", \"hash\":\"722e7b21f4bee5d0bffba199fedb9d250b9171ef\", \"best_bid\":\"0.43\", \"best_ask\":\"0.44\"}, {\"asset_id\":\"107603864457683460275633293642179940881969192120168665300712204232021063124301\", \"price\":\"0.99\", \"size\":\"7858.02\", \"side\":\"SELL\", \"hash\":\"82aec9757e0a95472ab737b353397444346c12a6\", \"best_bid\":\"0.56\", \"best_ask\":\"0.57\"}], \"timestamp\":\"1785211428021\", \"event_type\":\"price_change\"}","received_at":"2026-07-28T04:03:49.739626Z","schema_version":"clob-market-ws.price_change.v1","sequence":null,"server_hash":null,"server_timestamp":"1785211428021","session_id":"2d607381e3054cee91998cdf45a4231c","source":"clob_market_ws"},"received_at":"2026-07-28T04:03:49.739626Z","record_id":"10de803d7f6c09302d635c2fc24611f69a72c6f2373176c3971a9058179896d7","schema_fingerprint":"4aa3821a28b0b7c2400bc59aba4bcc0a76e971dadd19610d3ad38c768e124dc7","schema_version":"edge-lab-recorder.raw.v1","sequence":null,"source":"clob_market_ws"}
{"event_at":"2026-07-28T04:03:48.023000Z","event_fingerprint":"5c0a147d0ff896b98e093ff2e877765240e05bd570ffbf3364b7664a1ff4ad05","payload":{"connection_id":"f6725804f86a4c4eb588e4d5ed7db029","event_at":"2026-07-28T04:03:48.023000Z","event_type":"price_change","frame_hash":"072658e533c70f94b63805c6c6ca29330b12c6d9e439aeb0055e80a7d76c27a8","frame_index":0,"kind":"data","monotonic_ns":313412790769041,"payload":{"event_type":"price_change","market":"0xd412ce774cfcf8dc9f71164aac78783978aac7b03871702a3b8a481bd9dc9688","price_changes":[{"asset_id":"96600821790790307414914106093858868634329285205417149685270682748367152458577","best_ask":"0.44","best_bid":"0.43","hash":"a1247acfe55fe71fea569ce76e61258656e3d6f2","price":"0.01","side":"BUY","size":"7863.02"},{"asset_id":"107603864457683460275633293642179940881969192120168665300712204232021063124301","best_ask":"0.57","best_bid":"0.56","hash":"8a5e0675d9cfa36cace4ae5b5285ace9e7370f27","price":"0.99","side":"SELL","size":"7863.02"}],"timestamp":"1785211428023"},"payload_hash":"16b45c5c10b4f405288d281d7d09aabc48701302b5da9deda5a9ca3fe6fee640","raw_frame":"{\"market\":\"0xd412ce774cfcf8dc9f71164aac78783978aac7b03871702a3b8a481bd9dc9688\", \"price_changes\":[{\"asset_id\":\"96600821790790307414914106093858868634329285205417149685270682748367152458577\", \"price\":\"0.01\", \"size\":\"7863.02\", \"side\":\"BUY\", \"hash\":\"a1247acfe55fe71fea569ce76e61258656e3d6f2\", \"best_bid\":\"0.43\", \"best_ask\":\"0.44\"}, {\"asset_id\":\"107603864457683460275633293642179940881969192120168665300712204232021063124301\", \"price\":\"0.99\", \"size\":\"7863.02\", \"side\":\"SELL\", \"hash\":\"8a5e0675d9cfa36cace4ae5b5285ace9e7370f27\", \"best_bid\":\"0.56\", \"best_ask\":\"0.57\"}], \"timestamp\":\"1785211428023\", \"event_type\":\"price_change\"}","received_at":"2026-07-28T04:03:49.741155Z","schema_version":"clob-market-ws.price_change.v1","sequence":null,"server_hash":null,"server_timestamp":"1785211428023","session_id":"2d607381e3054cee91998cdf45a4231c","source":"clob_market_ws"},"received_at":"2026-07-28T04:03:49.741155Z","record_id":"03f8ce4abea08591603a80c4d776309323cc3522f336134c0d5f350ef17faa0b","schema_fingerprint":"4aa3821a28b0b7c2400bc59aba4bcc0a76e971dadd19610d3ad38c768e124dc7","schema_version":"edge-lab-recorder.raw.v1","sequence":null,"source":"clob_market_ws"}
{"event_at":"2026-07-28T04:03:48.043000Z","event_fingerprint":"f49997593dd35378cdc02d00cbc56be23021d1cca56bc4d6da1d2c89ac149ca0","payload":{"connection_id":"f6725804f86a4c4eb588e4d5ed7db029","event_at":"2026-07-28T04:03:48.043000Z","event_type":"price_change","frame_hash":"6b41fb38085e17b53f60caaa7d3dcdb31c9245b155dfb5870192a3a4ef90a581","frame_index":0,"kind":"data","monotonic_ns":313412792413333,"payload":{"event_type":"price_change","market":"0xd412ce774cfcf8dc9f71164aac78783978aac7b03871702a3b8a481bd9dc9688","price_changes":[{"asset_id":"96600821790790307414914106093858868634329285205417149685270682748367152458577","best_ask":"0.44","best_bid":"0.43","hash":"40215614a834aef6485b5f5c3bc991aed0d7e883","price":"0.01","side":"BUY","size":"7858.02"},{"asset_id":"107603864457683460275633293642179940881969192120168665300712204232021063124301","best_ask":"0.57","best_bid":"0.56","hash":"b9d0e71d6e2a15f3b500dd9e4f45d2d5c2974e6d","price":"0.99","side":"SELL","size":"7858.02"}],"timestamp":"1785211428043"},"payload_hash":"1e578ea6232c6dace04e4d7c29963723d046f6ef470b40c8bf3f47c9133648be","raw_frame":"{\"market\":\"0xd412ce774cfcf8dc9f71164aac78783978aac7b03871702a3b8a481bd9dc9688\", \"price_changes\":[{\"asset_id\":\"96600821790790307414914106093858868634329285205417149685270682748367152458577\", \"price\":\"0.01\", \"size\":\"7858.02\", \"side\":\"BUY\", \"hash\":\"40215614a834aef6485b5f5c3bc991aed0d7e883\", \"best_bid\":\"0.43\", \"best_ask\":\"0.44\"}, {\"asset_id\":\"107603864457683460275633293642179940881969192120168665300712204232021063124301\", \"price\":\"0.99\", \"size\":\"7858.02\", \"side\":\"SELL\", \"hash\":\"b9d0e71d6e2a15f3b500dd9e4f45d2d5c2974e6d\", \"best_bid\":\"0.56\", \"best_ask\":\"0.57\"}], \"timestamp\":\"1785211428043\", \"event_type\":\"price_change\"}","received_at":"2026-07-28T04:03:49.742799Z","schema_version":"clob-market-ws.price_change.v1","sequence":null,"server_hash":null,"server_timestamp":"1785211428043","session_id":"2d607381e3054cee91998cdf45a4231c","source":"clob_market_ws"},"received_at":"2026-07-28T04:03:49.742799Z","record_id":"7bc6f3eb72fcf63ec1d4fc3895450cabbc5e50a1d049be53eddbc301333d078a","schema_fingerprint":"4aa3821a28b0b7c2400bc59aba4bcc0a76e971dadd19610d3ad38c768e124dc7","schema_version":"edge-lab-recorder.raw.v1","sequence":null,"source":"clob_market_ws"}
{"event_at":"2026-07-28T04:03:48.056000Z","event_fingerprint":"9a39500b272c1c3ee3811367656aefed9e9cad4c340eec64eee060ccf7ef688b","payload":{"connection_id":"f6725804f86a4c4eb588e4d5ed7db029","event_at":"2026-07-28T04:03:48.056000Z","event_type":"price_change","frame_hash":"4daa410c857a1fadb1c862151daaab64496d2eff7fcc1aa28c45c3d9088e530f","frame_index":0,"kind":"data","monotonic_ns":313412793912375,"payload":{"event_type":"price_change","market":"0xd412ce774cfcf8dc9f71164aac78783978aac7b03871702a3b8a481bd9dc9688","price_changes":[{"asset_id":"107603864457683460275633293642179940881969192120168665300712204232021063124301","best_ask":"0.57","best_bid":"0.56","hash":"4dd492ab30a3f0b12654be1291c6518b78676599","price":"0.03","side":"BUY","size":"618.1"},{"asset_id":"96600821790790307414914106093858868634329285205417149685270682748367152458577","best_ask":"0.44","best_bid":"0.43","hash":"443f6d2a320334322f15bbb622eaa799a8fde15d","price":"0.97","side":"SELL","size":"618.1"}],"timestamp":"1785211428056"},"payload_hash":"4ddbd315106d8c8c31cd8ee77895e51aecd7f5d0d9c620194df426e891b205b9","raw_frame":"{\"market\":\"0xd412ce774cfcf8dc9f71164aac78783978aac7b03871702a3b8a481bd9dc9688\", \"price_changes\":[{\"asset_id\":\"107603864457683460275633293642179940881969192120168665300712204232021063124301\", \"price\":\"0.03\", \"size\":\"618.1\", \"side\":\"BUY\", \"hash\":\"4dd492ab30a3f0b12654be1291c6518b78676599\", \"best_bid\":\"0.56\", \"best_ask\":\"0.57\"}, {\"asset_id\":\"96600821790790307414914106093858868634329285205417149685270682748367152458577\", \"price\":\"0.97\", \"size\":\"618.1\", \"side\":\"SELL\", \"hash\":\"443f6d2a320334322f15bbb622eaa799a8fde15d\", \"best_bid\":\"0.43\", \"best_ask\":\"0.44\"}], \"timestamp\":\"1785211428056\", \"event_type\":\"price_change\"}","received_at":"2026-07-28T04:03:49.744299Z","schema_version":"clob-market-ws.price_change.v1","sequence":null,"server_hash":null,"server_timestamp":"1785211428056","session_id":"2d607381e3054cee91998cdf45a4231c","source":"clob_market_ws"},"received_at":"2026-07-28T04:03:49.744299Z","record_id":"cccd1b399174b31a10cafddeec80e212dc777bd86b073d63eb85e314ba6c731d","schema_fingerprint":"4aa3821a28b0b7c2400bc59aba4bcc0a76e971dadd19610d3ad38c768e124dc7","schema_version":"edge-lab-recorder.raw.v1","sequence":null,"source":"clob_market_ws"}
{"event_at":"2026-07-28T04:03:48.107000Z","event_fingerprint":"aa3bae1954bb1a756ee6450780708378dff39efa8bc3e4022df9be2bc5784b50","payload":{"connection_id":"f6725804f86a4c4eb588e4d5ed7db029","event_at":"2026-07-28T04:03:48.107000Z","event_type":"price_change","frame_hash":"2334436cb6a671edb22870bf9269caa91e9da44242cb9d89ce5264a275c12301","frame_index":0,"kind":"data","monotonic_ns":313412795392916,"payload":{"event_type":"price_change","market":"0xd412ce774cfcf8dc9f71164aac78783978aac7b03871702a3b8a481bd9dc9688","price_changes":[{"asset_id":"96600821790790307414914106093858868634329285205417149685270682748367152458577","best_ask":"0.44","best_bid":"0.43","hash":"e5fac8bd0e8ba74aea4f4f9d9275282befdde9a4","price":"0.45","side":"SELL","size":"115.28"},{"asset_id":"107603864457683460275633293642179940881969192120168665300712204232021063124301","best_ask":"0.57","best_bid":"0.56","hash":"f38b3db186881a9ea05647b7164c993c7e24b07c","price":"0.55","side":"BUY","size":"115.28"}],"timestamp":"1785211428107"},"payload_hash":"73c1291b98af96633051311f8847087e94c697e79dc44077578ca64d19343b01","raw_frame":"{\"market\":\"0xd412ce774cfcf8dc9f71164aac78783978aac7b03871702a3b8a481bd9dc9688\", \"price_changes\":[{\"asset_id\":\"96600821790790307414914106093858868634329285205417149685270682748367152458577\", \"price\":\"0.45\", \"size\":\"115.28\", \"side\":\"SELL\", \"hash\":\"e5fac8bd0e8ba74aea4f4f9d9275282befdde9a4\", \"best_bid\":\"0.43\", \"best_ask\":\"0.44\"}, {\"asset_id\":\"107603864457683460275633293642179940881969192120168665300712204232021063124301\", \"price\":\"0.55\", \"size\":\"115.28\", \"side\":\"BUY\", \"hash\":\"f38b3db186881a9ea05647b7164c993c7e24b07c\", \"best_bid\":\"0.56\", \"best_ask\":\"0.57\"}], \"timestamp\":\"1785211428107\", \"event_type\":\"price_change\"}","received_at":"2026-07-28T04:03:49.745778Z","schema_version":"clob-market-ws.price_change.v1","sequence":null,"server_hash":null,"server_timestamp":"1785211428107","session_id":"2d607381e3054cee91998cdf45a4231c","source":"clob_market_ws"},"received_at":"2026-07-28T04:03:49.745778Z","record_id":"94d6c09ec1b76a6a591108d9da38ab02ea4c789a15ee17cf12f2ccdf1bf0cc40","schema_fingerprint":"4aa3821a28b0b7c2400bc59aba4bcc0a76e971dadd19610d3ad38c768e124dc7","schema_version":"edge-lab-recorder.raw.v1","sequence":null,"source":"clob_market_ws"}
{"event_at":"2026-07-28T04:03:48.117000Z","event_fingerprint":"1aa1e791a3fe9984c84bdc37a604136f379bdbe308350bb2cea662c5901ea4ca","payload":{"connection_id":"f6725804f86a4c4eb588e4d5ed7db029","event_at":"2026-07-28T04:03:48.117000Z","event_type":"price_change","frame_hash":"8dd139730b1cfb85270f55f9216eb561787ac364211a70621409248196d0af6d","frame_index":0,"kind":"data","monotonic_ns":313412796882000,"payload":{"event_type":"price_change","market":"0xd412ce774cfcf8dc9f71164aac78783978aac7b03871702a3b8a481bd9dc9688","price_changes":[{"asset_id":"107603864457683460275633293642179940881969192120168665300712204232021063124301","best_ask":"0.57","best_bid":"0.56","hash":"a9c2897fdc0ff56555f37a6b298be93c66e3d730","price":"0.01","side":"BUY","size":"7888.02"},{"asset_id":"96600821790790307414914106093858868634329285205417149685270682748367152458577","best_ask":"0.44","best_bid":"0.43","hash":"20e9a2b1a914016184710ed3b51c6a46507e8f6c","price":"0.99","side":"SELL","size":"7888.02"}],"timestamp":"1785211428117"},"payload_hash":"ca6be02b43152dc7415f06a21d2ced95bfd19489e36a210b89badfa15c9da9aa","raw_frame":"{\"market\":\"0xd412ce774cfcf8dc9f71164aac78783978aac7b03871702a3b8a481bd9dc9688\", \"price_changes\":[{\"asset_id\":\"107603864457683460275633293642179940881969192120168665300712204232021063124301\", \"price\":\"0.01\", \"size\":\"7888.02\", \"side\":\"BUY\", \"hash\":\"a9c2897fdc0ff56555f37a6b298be93c66e3d730\", \"best_bid\":\"0.56\", \"best_ask\":\"0.57\"}, {\"asset_id\":\"96600821790790307414914106093858868634329285205417149685270682748367152458577\", \"price\":\"0.99\", \"size\":\"7888.02\", \"side\":\"SELL\", \"hash\":\"20e9a2b1a914016184710ed3b51c6a46507e8f6c\", \"best_bid\":\"0.43\", \"best_ask\":\"0.44\"}], \"timestamp\":\"1785211428117\", \"event_type\":\"price_change\"}","received_at":"2026-07-28T04:03:49.747269Z","schema_version":"clob-market-ws.price_change.v1","sequence":null,"server_hash":null,"server_timestamp":"1785211428117","session_id":"2d607381e3054cee91998cdf45a4231c","source":"clob_market_ws"},"received_at":"2026-07-28T04:03:49.747269Z","record_id":"d99b40a2d143b9e33e59c3871dc574f9ee228dbb1dc2e21224952d5604ec2909","schema_fingerprint":"4aa3821a28b0b7c2400bc59aba4bcc0a76e971dadd19610d3ad38c768e124dc7","schema_version":"edge-lab-recorder.raw.v1","sequence":null,"source":"clob_market_ws"}
{"event_at":"2026-07-28T04:03:48.124000Z","event_fingerprint":"a12955083c741f117f3692f6f70af7b09169bb53972774976710355278138488","payload":{"connection_id":"f6725804f86a4c4eb588e4d5ed7db029","event_at":"2026-07-28T04:03:48.124000Z","event_type":"price_change","frame_hash":"a8ad8e5a8ee70fc292faf90264d6a0fdcac2ff7d9a084c60234962afee9c88cf","frame_index":0,"kind":"data","monotonic_ns":313412798357375,"payload":{"event_type":"price_change","market":"0xd412ce774cfcf8dc9f71164aac78783978aac7b03871702a3b8a481bd9dc9688","price_changes":[{"asset_id":"107603864457683460275633293642179940881969192120168665300712204232021063124301","best_ask":"0.57","best_bid":"0.56","hash":"80ec8559bb50cd4fca2553f136fb481fc27857b3","price":"0.43","side":"BUY","size":"199.2"},{"asset_id":"96600821790790307414914106093858868634329285205417149685270682748367152458577","best_ask":"0.44","best_bid":"0.43","hash":"30652b63a212f765ff68e4002392ac9b791fe80c","price":"0.57","side":"SELL","size":"199.2"}],"timestamp":"1785211428124"},"payload_hash":"863fae74c424e22f79d41958341b26c5ebdbd29d02e96582a1b7f48eafd8efea","raw_frame":"{\"market\":\"0xd412ce774cfcf8dc9f71164aac78783978aac7b03871702a3b8a481bd9dc9688\", \"price_changes\":[{\"asset_id\":\"107603864457683460275633293642179940881969192120168665300712204232021063124301\", \"price\":\"0.43\", \"size\":\"199.2\", \"side\":\"BUY\", \"hash\":\"80ec8559bb50cd4fca2553f136fb481fc27857b3\", \"best_bid\":\"0.56\", \"best_ask\":\"0.57\"}, {\"asset_id\":\"96600821790790307414914106093858868634329285205417149685270682748367152458577\", \"price\":\"0.57\", \"size\":\"199.2\", \"side\":\"SELL\", \"hash\":\"30652b63a212f765ff68e4002392ac9b791fe80c\", \"best_bid\":\"0.43\", \"best_ask\":\"0.44\"}], \"timestamp\":\"1785211428124\", \"event_type\":\"price_change\"}","received_at":"2026-07-28T04:03:49.748742Z","schema_version":"clob-market-ws.price_change.v1","sequence":null,"server_hash":null,"server_timestamp":"1785211428124","session_id":"2d607381e3054cee91998cdf45a4231c","source":"clob_market_ws"},"received_at":"2026-07-28T04:03:49.748742Z","record_id":"2c4cf5ed27e64f5cbf09a952a03859df393e2ab66c3c91f0543741e1871ea58e","schema_fingerprint":"4aa3821a28b0b7c2400bc59aba4bcc0a76e971dadd19610d3ad38c768e124dc7","schema_version":"edge-lab-recorder.raw.v1","sequence":null,"source":"clob_market_ws"}
{"event_at":"2026-07-28T04:03:48.128000Z","event_fingerprint":"f91aae24d883cc9319f7d928cc4c0865c2ceec49ab1b06e63b49b1827f70ed6c","payload":{"connection_id":"f6725804f86a4c4eb588e4d5ed7db029","event_at":"2026-07-28T04:03:48.128000Z","event_type":"price_change","frame_hash":"d45fbb74031ac7da3bbb837fa9ba8d2bceaa3b33b1ba121e31ba31857920ae3d","frame_index":0,"kind":"data","monotonic_ns":313412799835333,"payload":{"event_type":"price_change","market":"0xd412ce774cfcf8dc9f71164aac78783978aac7b03871702a3b8a481bd9dc9688","price_changes":[{"asset_id":"96600821790790307414914106093858868634329285205417149685270682748367152458577","best_ask":"0.44","best_bid":"0.43","hash":"7495422b62af472b14a71e42f0be40ea42e23565","price":"0.01","side":"BUY","size":"7853.02"},{"asset_id":"107603864457683460275633293642179940881969192120168665300712204232021063124301","best_ask":"0.57","best_bid":"0.56","hash":"7519d6ac0477ab4e445b3cff4f94a5d2e099b95f","price":"0.99","side":"SELL","size":"7853.02"}],"timestamp":"1785211428128"},"payload_hash":"121d283519e803baf5c64cd334d92e43c804b6f8177b32ef3e4dbfef0a40e8da","raw_frame":"{\"market\":\"0xd412ce774cfcf8dc9f71164aac78783978aac7b03871702a3b8a481bd9dc9688\", \"price_changes\":[{\"asset_id\":\"96600821790790307414914106093858868634329285205417149685270682748367152458577\", \"price\":\"0.01\", \"size\":\"7853.02\", \"side\":\"BUY\", \"hash\":\"7495422b62af472b14a71e42f0be40ea42e23565\", \"best_bid\":\"0.43\", \"best_ask\":\"0.44\"}, {\"asset_id\":\"107603864457683460275633293642179940881969192120168665300712204232021063124301\", \"price\":\"0.99\", \"size\":\"7853.02\", \"side\":\"SELL\", \"hash\":\"7519d6ac0477ab4e445b3cff4f94a5d2e099b95f\", \"best_bid\":\"0.56\", \"best_ask\":\"0.57\"}], \"timestamp\":\"1785211428128\", \"event_type\":\"price_change\"}","received_at":"2026-07-28T04:03:49.750222Z","schema_version":"clob-market-ws.price_change.v1","sequence":null,"server_hash":null,"server_timestamp":"1785211428128","session_id":"2d607381e3054cee91998cdf45a4231c","source":"clob_market_ws"},"received_at":"2026-07-28T04:03:49.750222Z","record_id":"7fb6af4fd8d9af3a670ce4971d9d8a05dee32806f131c4cff215a3e88add4c44","schema_fingerprint":"4aa3821a28b0b7c2400bc59aba4bcc0a76e971dadd19610d3ad38c768e124dc7","schema_version":"edge-lab-recorder.raw.v1","sequence":null,"source":"clob_market_ws"}
{"event_at":"2026-07-28T04:03:48.130000Z","event_fingerprint":"80e29cf85208d4ba56e128e8acaa327f20badb9db94178f8c4ed3be5d22d5620","payload":{"connection_id":"f6725804f86a4c4eb588e4d5ed7db029","event_at":"2026-07-28T04:03:48.130000Z","event_type":"price_change","frame_hash":"31c0083e1b2f6cefd6ef3f51bd188a6b206c939e576228d6b7a3040656c11ae8","frame_index":0,"kind":"data","monotonic_ns":313412801334458,"payload":{"event_type":"price_change","market":"0xd412ce774cfcf8dc9f71164aac78783978aac7b03871702a3b8a481bd9dc9688","price_changes":[{"asset_id":"107603864457683460275633293642179940881969192120168665300712204232021063124301","best_ask":"0.57","best_bid":"0.56","hash":"bd8640c6e41359a29c67007ffe12d75dc4b84e5b","price":"0.03","side":"BUY","size":"613.1"},{"asset_id":"96600821790790307414914106093858868634329285205417149685270682748367152458577","best_ask":"0.44","best_bid":"0.43","hash":"119a8fb1c3d822e61866b625caf2604ba03b2fb1","price":"0.97","side":"SELL","size":"613.1"}],"timestamp":"1785211428130"},"payload_hash":"fd76e4fe6040acfe5dd0d41657950fb49a02609e366dd0401de6660dbc33e61c","raw_frame":"{\"market\":\"0xd412ce774cfcf8dc9f71164aac78783978aac7b03871702a3b8a481bd9dc9688\", \"price_changes\":[{\"asset_id\":\"107603864457683460275633293642179940881969192120168665300712204232021063124301\", \"price\":\"0.03\", \"size\":\"613.1\", \"side\":\"BUY\", \"hash\":\"bd8640c6e41359a29c67007ffe12d75dc4b84e5b\", \"best_bid\":\"0.56\", \"best_ask\":\"0.57\"}, {\"asset_id\":\"96600821790790307414914106093858868634329285205417149685270682748367152458577\", \"price\":\"0.97\", \"size\":\"613.1\", \"side\":\"SELL\", \"hash\":\"119a8fb1c3d822e61866b625caf2604ba03b2fb1\", \"best_bid\":\"0.43\", \"best_ask\":\"0.44\"}], \"timestamp\":\"1785211428130\", \"event_type\":\"price_change\"}","received_at":"2026-07-28T04:03:49.751719Z","schema_version":"clob-market-ws.price_change.v1","sequence":null,"server_hash":null,"server_timestamp":"1785211428130","session_id":"2d607381e3054cee91998cdf45a4231c","source":"clob_market_ws"},"received_at":"2026-07-28T04:03:49.751719Z","record_id":"30be47420edf3e589201deaf9ba725d6e259145927103edd00e4da6c2d9684d8","schema_fingerprint":"4aa3821a28b0b7c2400bc59aba4bcc0a76e971dadd19610d3ad38c768e124dc7","schema_version":"edge-lab-recorder.raw.v1","sequence":null,"source":"clob_market_ws"}
{"event_at":"2026-07-28T04:03:48.135000Z","event_fingerprint":"adb9f482d558957e53a4d2363ef846f762c6228d3678b46de6f27b054836ad58","payload":{"connection_id":"f6725804f86a4c4eb588e4d5ed7db029","event_at":"2026-07-28T04:03:48.135000Z","event_type":"price_change","frame_hash":"69244969009ffeeeca3e38e1318ed3fe2fc38854047289728be6e73818b81f6c","frame_index":0,"kind":"data","monotonic_ns":313412802917875,"payload":{"event_type":"price_change","market":"0xd412ce774cfcf8dc9f71164aac78783978aac7b03871702a3b8a481bd9dc9688","price_changes":[{"asset_id":"107603864457683460275633293642179940881969192120168665300712204232021063124301","best_ask":"0.57","best_bid":"0.56","hash":"812bfb6552a3ea29e1bbca48be2e52edd63f8b46","price":"0.01","side":"BUY","size":"7893.02"},{"asset_id":"96600821790790307414914106093858868634329285205417149685270682748367152458577","best_ask":"0.44","best_bid":"0.43","hash":"85a3d6d7133a1d891c4e14ec9af88d71e9b7d84b","price":"0.99","side":"SELL","size":"7893.02"}],"timestamp":"1785211428135"},"payload_hash":"bbe131ba201a19ceef63690dff7ba5bc8f8abecaae238a6c665ed1043332a043","raw_frame":"{\"market\":\"0xd412ce774cfcf8dc9f71164aac78783978aac7b03871702a3b8a481bd9dc9688\", \"price_changes\":[{\"asset_id\":\"107603864457683460275633293642179940881969192120168665300712204232021063124301\", \"price\":\"0.01\", \"size\":\"7893.02\", \"side\":\"BUY\", \"hash\":\"812bfb6552a3ea29e1bbca48be2e52edd63f8b46\", \"best_bid\":\"0.56\", \"best_ask\":\"0.57\"}, {\"asset_id\":\"96600821790790307414914106093858868634329285205417149685270682748367152458577\", \"price\":\"0.99\", \"size\":\"7893.02\", \"side\":\"SELL\", \"hash\":\"85a3d6d7133a1d891c4e14ec9af88d71e9b7d84b\", \"best_bid\":\"0.43\", \"best_ask\":\"0.44\"}], \"timestamp\":\"1785211428135\", \"event_type\":\"price_change\"}","received_at":"2026-07-28T04:03:49.753305Z","schema_version":"clob-market-ws.price_change.v1","sequence":null,"server_hash":null,"server_timestamp":"1785211428135","session_id":"2d607381e3054cee91998cdf45a4231c","source":"clob_market_ws"},"received_at":"2026-07-28T04:03:49.753305Z","record_id":"d1299bc31463b26b2774a70487dfe9c94bebe43940b81998efe3b63e425be02e","schema_fingerprint":"4aa3821a28b0b7c2400bc59aba4bcc0a76e971dadd19610d3ad38c768e124dc7","schema_version":"edge-lab-recorder.raw.v1","sequence":null,"source":"clob_market_ws"}
{"event_at":"2026-07-28T04:03:48.139000Z","event_fingerprint":"2a8257c9992d0387b503b28b0850bae1b5c7c709bf05d68a7121160eecf9c740","payload":{"connection_id":"f6725804f86a4c4eb588e4d5ed7db029","event_at":"2026-07-28T04:03:48.139000Z","event_type":"price_change","frame_hash":"597fca4adfb69319071fc7cd5a50ed608a3ac3781686c4893bc599824ef8f1b1","frame_index":0,"kind":"data","monotonic_ns":313412804368083,"payload":{"event_type":"price_change","market":"0xd412ce774cfcf8dc9f71164aac78783978aac7b03871702a3b8a481bd9dc9688","price_changes":[{"asset_id":"107603864457683460275633293642179940881969192120168665300712204232021063124301","best_ask":"0.57","best_bid":"0.56","hash":"f5eb6b6e56fbc136d9df18311e7d3c954d72bc58","price":"0.01","side":"BUY","size":"7888.02"},{"asset_id":"96600821790790307414914106093858868634329285205417149685270682748367152458577","best_ask":"0.44","best_bid":"0.43","hash":"25528e98311a01d3cda515921f25d98be62e2d78","price":"0.99","side":"SELL","size":"7888.02"}],"timestamp":"1785211428139"},"payload_hash":"525941f7ab31527b87e8ec7da265f5846179ee0d2586a758e6be8f9cfac86530","raw_frame":"{\"market\":\"0xd412ce774cfcf8dc9f71164aac78783978aac7b03871702a3b8a481bd9dc9688\", \"price_changes\":[{\"asset_id\":\"107603864457683460275633293642179940881969192120168665300712204232021063124301\", \"price\":\"0.01\", \"size\":\"7888.02\", \"side\":\"BUY\", \"hash\":\"f5eb6b6e56fbc136d9df18311e7d3c954d72bc58\", \"best_bid\":\"0.56\", \"best_ask\":\"0.57\"}, {\"asset_id\":\"96600821790790307414914106093858868634329285205417149685270682748367152458577\", \"price\":\"0.99\", \"size\":\"7888.02\", \"side\":\"SELL\", \"hash\":\"25528e98311a01d3cda515921f25d98be62e2d78\", \"best_bid\":\"0.43\", \"best_ask\":\"0.44\"}], \"timestamp\":\"1785211428139\", \"event_type\":\"price_change\"}","received_at":"2026-07-28T04:03:49.754755Z","schema_version":"clob-market-ws.price_change.v1","sequence":null,"server_hash":null,"server_timestamp":"1785211428139","session_id":"2d607381e3054cee91998cdf45a4231c","source":"clob_market_ws"},"received_at":"2026-07-28T04:03:49.754755Z","record_id":"b6fffff1d8a35f26ae81493e4a0d38a557e5b29ddc16cb70924663385f8e5989","schema_fingerprint":"4aa3821a28b0b7c2400bc59aba4bcc0a76e971dadd19610d3ad38c768e124dc7","schema_version":"edge-lab-recorder.raw.v1","sequence":null,"source":"clob_market_ws"}
{"event_at":"2026-07-28T04:03:48.157000Z","event_fingerprint":"98dd1f83b6931f70c64d7b39fbe09d1758f41bca451644a62689734cf836378f","payload":{"connection_id":"f6725804f86a4c4eb588e4d5ed7db029","event_at":"2026-07-28T04:03:48.157000Z","event_type":"price_change","frame_hash":"97fc5807148c68b4fa9d676015dd6e1a349e04b696f46a9d742781d0670cb0c4","frame_index":0,"kind":"data","monotonic_ns":313412805843958,"payload":{"event_type":"price_change","market":"0xd412ce774cfcf8dc9f71164aac78783978aac7b03871702a3b8a481bd9dc9688","price_changes":[{"asset_id":"107603864457683460275633293642179940881969192120168665300712204232021063124301","best_ask":"0.57","best_bid":"0.56","hash":"999d2a03a6a4521009e2090bf606bdd2021452fe","price":"0.01","side":"BUY","size":"7883.02"},{"asset_id":"96600821790790307414914106093858868634329285205417149685270682748367152458577","best_ask":"0.44","best_bid":"0.43","hash":"f4c331e98d32c7623dc3123c90dcd9052c604b5a","price":"0.99","side":"SELL","size":"7883.02"}],"timestamp":"1785211428157"},"payload_hash":"9ea2ee68f4412c3cfa77ab68f0907340106168f76de236b4ffec0dcc9a370667","raw_frame":"{\"market\":\"0xd412ce774cfcf8dc9f71164aac78783978aac7b03871702a3b8a481bd9dc9688\", \"price_changes\":[{\"asset_id\":\"107603864457683460275633293642179940881969192120168665300712204232021063124301\", \"price\":\"0.01\", \"size\":\"7883.02\", \"side\":\"BUY\", \"hash\":\"999d2a03a6a4521009e2090bf606bdd2021452fe\", \"best_bid\":\"0.56\", \"best_ask\":\"0.57\"}, {\"asset_id\":\"96600821790790307414914106093858868634329285205417149685270682748367152458577\", \"price\":\"0.99\", \"size\":\"7883.02\", \"side\":\"SELL\", \"hash\":\"f4c331e98d32c7623dc3123c90dcd9052c604b5a\", \"best_bid\":\"0.43\", \"best_ask\":\"0.44\"}], \"timestamp\":\"1785211428157\", \"event_type\":\"price_change\"}","received_at":"2026-07-28T04:03:49.756231Z","schema_version":"clob-market-ws.price_change.v1","sequence":null,"server_hash":null,"server_timestamp":"1785211428157","session_id":"2d607381e3054cee91998cdf45a4231c","source":"clob_market_ws"},"received_at":"2026-07-28T04:03:49.756231Z","record_id":"c64e8034925cc7d4d8d930a7a5b196e8dbf506c2ff0c156ae3e39a63319ee33f","schema_fingerprint":"4aa3821a28b0b7c2400bc59aba4bcc0a76e971dadd19610d3ad38c768e124dc7","schema_version":"edge-lab-recorder.raw.v1","sequence":null,"source":"clob_market_ws"}
{"event_at":"2026-07-28T04:03:48.241000Z","event_fingerprint":"706fbe23e6d96b45ee6d2d4045b323164065246f5cff778cd9d93c16dd93e90c","payload":{"connection_id":"f6725804f86a4c4eb588e4d5ed7db029","event_at":"2026-07-28T04:03:48.241000Z","event_type":"price_change","frame_hash":"0c48d20047a400f378ff09cabdf231edc01174d8d5364ba286170a66df27c340","frame_index":0,"kind":"data","monotonic_ns":313412807340875,"payload":{"event_type":"price_change","market":"0xd412ce774cfcf8dc9f71164aac78783978aac7b03871702a3b8a481bd9dc9688","price_changes":[{"asset_id":"107603864457683460275633293642179940881969192120168665300712204232021063124301","best_ask":"0.57","best_bid":"0.56","hash":"8cefe4c8bc0d260d1892e8732d4fc9064177a395","price":"0.53","side":"BUY","size":"106.62"},{"asset_id":"96600821790790307414914106093858868634329285205417149685270682748367152458577","best_ask":"0.44","best_bid":"0.43","hash":"59d15b8f8c6b342b18f44ef0eb1bcbfe44bfe2c1","price":"0.47","side":"SELL","size":"106.62"}],"timestamp":"1785211428241"},"payload_hash":"30b6aa8e174b985e5e277f54e509ceb96348012d8431a2b545631a1bea678a8b","raw_frame":"{\"market\":\"0xd412ce774cfcf8dc9f71164aac78783978aac7b03871702a3b8a481bd9dc9688\", \"price_changes\":[{\"asset_id\":\"107603864457683460275633293642179940881969192120168665300712204232021063124301\", \"price\":\"0.53\", \"size\":\"106.62\", \"side\":\"BUY\", \"hash\":\"8cefe4c8bc0d260d1892e8732d4fc9064177a395\", \"best_bid\":\"0.56\", \"best_ask\":\"0.57\"}, {\"asset_id\":\"96600821790790307414914106093858868634329285205417149685270682748367152458577\", \"price\":\"0.47\", \"size\":\"106.62\", \"side\":\"SELL\", \"hash\":\"59d15b8f8c6b342b18f44ef0eb1bcbfe44bfe2c1\", \"best_bid\":\"0.43\", \"best_ask\":\"0.44\"}], \"timestamp\":\"1785211428241\", \"event_type\":\"price_change\"}","received_at":"2026-07-28T04:03:49.757725Z","schema_version":"clob-market-ws.price_change.v1","sequence":null,"server_hash":null,"server_timestamp":"1785211428241","session_id":"2d607381e3054cee91998cdf45a4231c","source":"clob_market_ws"},"received_at":"2026-07-28T04:03:49.757725Z","record_id":"0da45addd07f000e04e2bdd9acca7bf2a6a87d78392087df4f7796a86e65c95e","schema_fingerprint":"4aa3821a28b0b7c2400bc59aba4bcc0a76e971dadd19610d3ad38c768e124dc7","schema_version":"edge-lab-recorder.raw.v1","sequence":null,"source":"clob_market_ws"}
{"event_at":"2026-07-28T04:03:48.265000Z","event_fingerprint":"f0a7d8354c2193e20d715c5265d381d276088f924b7c483533cd6d6cf8a1c652","payload":{"connection_id":"f6725804f86a4c4eb588e4d5ed7db029","event_at":"2026-07-28T04:03:48.265000Z","event_type":"price_change","frame_hash":"fd040cbe7618f04aa5d1214267d07a62ccd52b0a976d33acff9d772764275c53","frame_index":0,"kind":"data","monotonic_ns":313412808987583,"payload":{"event_type":"price_change","market":"0xd412ce774cfcf8dc9f71164aac78783978aac7b03871702a3b8a481bd9dc9688","price_changes":[{"asset_id":"107603864457683460275633293642179940881969192120168665300712204232021063124301","best_ask":"0.57","best_bid":"0.56","hash":"4632cf81732e9e4a39dfb5af59306638cb5987ad","price":"0.04","side":"BUY","size":"673.09"},{"asset_id":"96600821790790307414914106093858868634329285205417149685270682748367152458577","best_ask":"0.44","best_bid":"0.43","hash":"32a3e5117849922025128bbd2e3ce36acef69672","price":"0.96","side":"SELL","size":"673.09"}],"timestamp":"1785211428265"},"payload_hash":"74984875580af8d96aafd823fb0b06502b70c8303cec31b140b4f3786da232e7","raw_frame":"{\"market\":\"0xd412ce774cfcf8dc9f71164aac78783978aac7b03871702a3b8a481bd9dc9688\", \"price_changes\":[{\"asset_id\":\"107603864457683460275633293642179940881969192120168665300712204232021063124301\", \"price\":\"0.04\", \"size\":\"673.09\", \"side\":\"BUY\", \"hash\":\"4632cf81732e9e4a39dfb5af59306638cb5987ad\", \"best_bid\":\"0.56\", \"best_ask\":\"0.57\"}, {\"asset_id\":\"96600821790790307414914106093858868634329285205417149685270682748367152458577\", \"price\":\"0.96\", \"size\":\"673.09\", \"side\":\"SELL\", \"hash\":\"32a3e5117849922025128bbd2e3ce36acef69672\", \"best_bid\":\"0.43\", \"best_ask\":\"0.44\"}], \"timestamp\":\"1785211428265\", \"event_type\":\"price_change\"}","received_at":"2026-07-28T04:03:49.759373Z","schema_version":"clob-market-ws.price_change.v1","sequence":null,"server_hash":null,"server_timestamp":"1785211428265","session_id":"2d607381e3054cee91998cdf45a4231c","source":"clob_market_ws"},"received_at":"2026-07-28T04:03:49.759373Z","record_id":"47313b07bfe8eb25fb65dafcea017843ad8628b3022715f15e6f8997378a1b00","schema_fingerprint":"4aa3821a28b0b7c2400bc59aba4bcc0a76e971dadd19610d3ad38c768e124dc7","schema_version":"edge-lab-recorder.raw.v1","sequence":null,"source":"clob_market_ws"}
{"event_at":"2026-07-28T04:03:48.397000Z","event_fingerprint":"3edf08d0b6c094b4f22d53f73773b6307191b76d6eaa145ed0b9ea73bec1a265","payload":{"connection_id":"f6725804f86a4c4eb588e4d5ed7db029","event_at":"2026-07-28T04:03:48.397000Z","event_type":"price_change","frame_hash":"e4cee341878184d09d59f44e4cdf44afd15387236348cefecd7a6efa1ecdf9ff","frame_index":0,"kind":"data","monotonic_ns":313412810443416,"payload":{"event_type":"price_change","market":"0xd412ce774cfcf8dc9f71164aac78783978aac7b03871702a3b8a481bd9dc9688","price_changes":[{"asset_id":"107603864457683460275633293642179940881969192120168665300712204232021063124301","best_ask":"0.57","best_bid":"0.56","hash":"92cf8c32f5476be8dec037f59b477fe007bd4f08","price":"0.04","side":"BUY","size":"668.09"},{"asset_id":"96600821790790307414914106093858868634329285205417149685270682748367152458577","best_ask":"0.44","best_bid":"0.43","hash":"7595fb69572c254566b91192dc670a86b9d6cd88","price":"0.96","side":"SELL","size":"668.09"}],"timestamp":"1785211428397"},"payload_hash":"6066e51d35ee6a625165a81897fe7f61d1612fa80a8b41299bd819a3bcb3651a","raw_frame":"{\"market\":\"0xd412ce774cfcf8dc9f71164aac78783978aac7b03871702a3b8a481bd9dc9688\", \"price_changes\":[{\"asset_id\":\"107603864457683460275633293642179940881969192120168665300712204232021063124301\", \"price\":\"0.04\", \"size\":\"668.09\", \"side\":\"BUY\", \"hash\":\"92cf8c32f5476be8dec037f59b477fe007bd4f08\", \"best_bid\":\"0.56\", \"best_ask\":\"0.57\"}, {\"asset_id\":\"96600821790790307414914106093858868634329285205417149685270682748367152458577\", \"price\":\"0.96\", \"size\":\"668.09\", \"side\":\"SELL\", \"hash\":\"7595fb69572c254566b91192dc670a86b9d6cd88\", \"best_bid\":\"0.43\", \"best_ask\":\"0.44\"}], \"timestamp\":\"1785211428397\", \"event_type\":\"price_change\"}","received_at":"2026-07-28T04:03:49.760831Z","schema_version":"clob-market-ws.price_change.v1","sequence":null,"server_hash":null,"server_timestamp":"1785211428397","session_id":"2d607381e3054cee91998cdf45a4231c","source":"clob_market_ws"},"received_at":"2026-07-28T04:03:49.760831Z","record_id":"7359004be40d95d2454c6f0c7c83c435a1972459ad0d72a659b483975fab5c96","schema_fingerprint":"4aa3821a28b0b7c2400bc59aba4bcc0a76e971dadd19610d3ad38c768e124dc7","schema_version":"edge-lab-recorder.raw.v1","sequence":null,"source":"clob_market_ws"}
{"event_at":"2026-07-28T04:03:48.467000Z","event_fingerprint":"1191c270977748dd58f63b77d0f8430de5671ad50da03100c4753f12ab4db7a4","payload":{"connection_id":"f6725804f86a4c4eb588e4d5ed7db029","event_at":"2026-07-28T04:03:48.467000Z","event_type":"price_change","frame_hash":"bf657a6215d4e8af69d71caf588781e131a2155db4d91c3ae39c4d488871d7f1","frame_index":0,"kind":"data","monotonic_ns":313412843608541,"payload":{"event_type":"price_change","market":"0xd412ce774cfcf8dc9f71164aac78783978aac7b03871702a3b8a481bd9dc9688","price_changes":[{"asset_id":"107603864457683460275633293642179940881969192120168665300712204232021063124301","best_ask":"0.57","best_bid":"0.56","hash":"7c58f52a4867860b4e1ca39dd5b696bb95daa31b","price":"0.42","side":"BUY","size":"132.3"},{"asset_id":"96600821790790307414914106093858868634329285205417149685270682748367152458577","best_ask":"0.44","best_bid":"0.43","hash":"63262a9727161d04b0430f171d3d3f74d833981f","price":"0.58","side":"SELL","size":"132.3"}],"timestamp":"1785211428467"},"payload_hash":"7a580455656c9ecf569722fcc4f77e24033188983f5592153230b854cf29357a","raw_frame":"{\"market\":\"0xd412ce774cfcf8dc9f71164aac78783978aac7b03871702a3b8a481bd9dc9688\", \"price_changes\":[{\"asset_id\":\"107603864457683460275633293642179940881969192120168665300712204232021063124301\", \"price\":\"0.42\", \"size\":\"132.3\", \"side\":\"BUY\", \"hash\":\"7c58f52a4867860b4e1ca39dd5b696bb95daa31b\", \"best_bid\":\"0.56\", \"best_ask\":\"0.57\"}, {\"asset_id\":\"96600821790790307414914106093858868634329285205417149685270682748367152458577\", \"price\":\"0.58\", \"size\":\"132.3\", \"side\":\"SELL\", \"hash\":\"63262a9727161d04b0430f171d3d3f74d833981f\", \"best_bid\":\"0.43\", \"best_ask\":\"0.44\"}], \"timestamp\":\"1785211428467\", \"event_type\":\"price_change\"}","received_at":"2026-07-28T04:03:49.793992Z","schema_version":"clob-market-ws.price_change.v1","sequence":null,"server_hash":null,"server_timestamp":"1785211428467","session_id":"2d607381e3054cee91998cdf45a4231c","source":"clob_market_ws"},"received_at":"2026-07-28T04:03:49.793992Z","record_id":"cc300fad58b2693a0431b611cb0a8f59f8e85361bbb12ec0cb75f4c50103f80c","schema_fingerprint":"4aa3821a28b0b7c2400bc59aba4bcc0a76e971dadd19610d3ad38c768e124dc7","schema_version":"edge-lab-recorder.raw.v1","sequence":null,"source":"clob_market_ws"}
{"event_at":"2026-07-28T04:03:48.468000Z","event_fingerprint":"17a12e24b7a2483adada62292d6a92477fa44f6983428c3bfb1459819a5912c5","payload":{"connection_id":"f6725804f86a4c4eb588e4d5ed7db029","event_at":"2026-07-28T04:03:48.468000Z","event_type":"price_change","frame_hash":"979773be740ccd5382ad6df4eca1d3a0dc520047df649138e1613992d93ce5a6","frame_index":0,"kind":"data","monotonic_ns":313412852259000,"payload":{"event_type":"price_change","market":"0xd412ce774cfcf8dc9f71164aac78783978aac7b03871702a3b8a481bd9dc9688","price_changes":[{"asset_id":"107603864457683460275633293642179940881969192120168665300712204232021063124301","best_ask":"0.57","best_bid":"0.56","hash":"bed1ec33e7d991415479d9dcf7ac8302a7b33e95","price":"0.44","side":"BUY","size":"120"},{"asset_id":"96600821790790307414914106093858868634329285205417149685270682748367152458577","best_ask":"0.44","best_bid":"0.43","hash":"32086b90857177e2e689c93b33107f41ddb9e2a3","price":"0.56","side":"SELL","size":"120"}],"timestamp":"1785211428468"},"payload_hash":"a9297c3603c1e7afb895801dea32be90356088acaaac2e4fd043456c220b1c89","raw_frame":"{\"market\":\"0xd412ce774cfcf8dc9f71164aac78783978aac7b03871702a3b8a481bd9dc9688\", \"price_changes\":[{\"asset_id\":\"107603864457683460275633293642179940881969192120168665300712204232021063124301\", \"price\":\"0.44\", \"size\":\"120\", \"side\":\"BUY\", \"hash\":\"bed1ec33e7d991415479d9dcf7ac8302a7b33e95\", \"best_bid\":\"0.56\", \"best_ask\":\"0.57\"}, {\"asset_id\":\"96600821790790307414914106093858868634329285205417149685270682748367152458577\", \"price\":\"0.56\", \"size\":\"120\", \"side\":\"SELL\", \"hash\":\"32086b90857177e2e689c93b33107f41ddb9e2a3\", \"best_bid\":\"0.43\", \"best_ask\":\"0.44\"}], \"timestamp\":\"1785211428468\", \"event_type\":\"price_change\"}","received_at":"2026-07-28T04:03:49.802643Z","schema_version":"clob-market-ws.price_change.v1","sequence":null,"server_hash":null,"server_timestamp":"1785211428468","session_id":"2d607381e3054cee91998cdf45a4231c","source":"clob_market_ws"},"received_at":"2026-07-28T04:03:49.802643Z","record_id":"7714c9134e34b6c5e6e526d74f7e6aeef44648925b804673a12523a196143d23","schema_fingerprint":"4aa3821a28b0b7c2400bc59aba4bcc0a76e971dadd19610d3ad38c768e124dc7","schema_version":"edge-lab-recorder.raw.v1","sequence":null,"source":"clob_market_ws"}
{"event_at":"2026-07-28T04:03:48.468000Z","event_fingerprint":"2482a995ed96a82b4f7be06625f715f510e4a81f1ae8a64bac0378ce3c61ad1b","payload":{"connection_id":"f6725804f86a4c4eb588e4d5ed7db029","event_at":"2026-07-28T04:03:48.468000Z","event_type":"price_change","frame_hash":"d468a8356770dd1a32765cde1bdaa1ec395dca8711004ae926ae76e922f0603b","frame_index":0,"kind":"data","monotonic_ns":313412854234791,"payload":{"event_type":"price_change","market":"0xd412ce774cfcf8dc9f71164aac78783978aac7b03871702a3b8a481bd9dc9688","price_changes":[{"asset_id":"107603864457683460275633293642179940881969192120168665300712204232021063124301","best_ask":"0.57","best_bid":"0.56","hash":"580d3b3bce56f0800540e66dbe11ecdebd0de102","price":"0.53","side":"BUY","size":"68.62"},{"asset_id":"96600821790790307414914106093858868634329285205417149685270682748367152458577","best_ask":"0.44","best_bid":"0.43","hash":"380fedebd5d8c55c44962c77fc015976bfe927d9","price":"0.47","side":"SELL","size":"68.62"}],"timestamp":"1785211428468"},"payload_hash":"7f63bf6295713daa7242f9ebff7eb9a0beeb3c431313b1a5d1f8962bb50a84f5","raw_frame":"{\"market\":\"0xd412ce774cfcf8dc9f71164aac78783978aac7b03871702a3b8a481bd9dc9688\", \"price_changes\":[{\"asset_id\":\"107603864457683460275633293642179940881969192120168665300712204232021063124301\", \"price\":\"0.53\", \"size\":\"68.62\", \"side\":\"BUY\", \"hash\":\"580d3b3bce56f0800540e66dbe11ecdebd0de102\", \"best_bid\":\"0.56\", \"best_ask\":\"0.57\"}, {\"asset_id\":\"96600821790790307414914106093858868634329285205417149685270682748367152458577\", \"price\":\"0.47\", \"size\":\"68.62\", \"side\":\"SELL\", \"hash\":\"380fedebd5d8c55c44962c77fc015976bfe927d9\", \"best_bid\":\"0.43\", \"best_ask\":\"0.44\"}], \"timestamp\":\"1785211428468\", \"event_type\":\"price_change\"}","received_at":"2026-07-28T04:03:49.804619Z","schema_version":"clob-market-ws.price_change.v1","sequence":null,"server_hash":null,"server_timestamp":"1785211428468","session_id":"2d607381e3054cee91998cdf45a4231c","source":"clob_market_ws"},"received_at":"2026-07-28T04:03:49.804619Z","record_id":"32d0b9f293c63ff53c108507b276770bd4d4ef45435ef77705301ba2caf2ec5a","schema_fingerprint":"4aa3821a28b0b7c2400bc59aba4bcc0a76e971dadd19610d3ad38c768e124dc7","schema_version":"edge-lab-recorder.raw.v1","sequence":null,"source":"clob_market_ws"}
{"event_at":"2026-07-28T04:03:48.469000Z","event_fingerprint":"5d261cd476cd256c2b91317a277de2ff5725aa64ac48be562bdac94d1abfa1f5","payload":{"connection_id":"f6725804f86a4c4eb588e4d5ed7db029","event_at":"2026-07-28T04:03:48.469000Z","event_type":"price_change","frame_hash":"7337a7c45127e0529028c1c887546d109c43b1635f1d0d338ba2f0c3ceaff45e","frame_index":0,"kind":"data","monotonic_ns":313412855831125,"payload":{"event_type":"price_change","market":"0xd412ce774cfcf8dc9f71164aac78783978aac7b03871702a3b8a481bd9dc9688","price_changes":[{"asset_id":"107603864457683460275633293642179940881969192120168665300712204232021063124301","best_ask":"0.57","best_bid":"0.56","hash":"7d2e76b9a27ae5f2bbd330e6769fd6983be25dd7","price":"0.55","side":"BUY","size":"79.28"},{"asset_id":"96600821790790307414914106093858868634329285205417149685270682748367152458577","best_ask":"0.44","best_bid":"0.43","hash":"072347bcd2a5cebde71438584b01667564398a3d","price":"0.45","side":"SELL","size":"79.28"}],"timestamp":"1785211428469"},"payload_hash":"9209d2e5af8ac5f28ed0f27213ed4c50fbb0a22332b3afafc8e93a7a19dc2f68","raw_frame":"{\"market\":\"0xd412ce774cfcf8dc9f71164aac78783978aac7b03871702a3b8a481bd9dc9688\", \"price_changes\":[{\"asset_id\":\"107603864457683460275633293642179940881969192120168665300712204232021063124301\", \"price\":\"0.55\", \"size\":\"79.28\", \"side\":\"BUY\", \"hash\":\"7d2e76b9a27ae5f2bbd330e6769fd6983be25dd7\", \"best_bid\":\"0.56\", \"best_ask\":\"0.57\"}, {\"asset_id\":\"96600821790790307414914106093858868634329285205417149685270682748367152458577\", \"price\":\"0.45\", \"size\":\"79.28\", \"side\":\"SELL\", \"hash\":\"072347bcd2a5cebde71438584b01667564398a3d\", \"best_bid\":\"0.43\", \"best_ask\":\"0.44\"}], \"timestamp\":\"1785211428469\", \"event_type\":\"price_change\"}","received_at":"2026-07-28T04:03:49.806216Z","schema_version":"clob-market-ws.price_change.v1","sequence":null,"server_hash":null,"server_timestamp":"1785211428469","session_id":"2d607381e3054cee91998cdf45a4231c","source":"clob_market_ws"},"received_at":"2026-07-28T04:03:49.806216Z","record_id":"156102ef585a67fb3ca3dce5a2b9953c5babcc5d5e1bb690589ca32741d33e73","schema_fingerprint":"4aa3821a28b0b7c2400bc59aba4bcc0a76e971dadd19610d3ad38c768e124dc7","schema_version":"edge-lab-recorder.raw.v1","sequence":null,"source":"clob_market_ws"}
{"event_at":"2026-07-28T04:03:48.470000Z","event_fingerprint":"86b66046ee1d54a1042fd258befa9ca152f9eacabbf492b2955f46e01b37f5af","payload":{"connection_id":"f6725804f86a4c4eb588e4d5ed7db029","event_at":"2026-07-28T04:03:48.470000Z","event_type":"price_change","frame_hash":"51763f9f1211c0b270555f514105ab7197074060526c7b24cf62a66186a6e3a1","frame_index":0,"kind":"data","monotonic_ns":313412857392916,"payload":{"event_type":"price_change","market":"0xd412ce774cfcf8dc9f71164aac78783978aac7b03871702a3b8a481bd9dc9688","price_changes":[{"asset_id":"107603864457683460275633293642179940881969192120168665300712204232021063124301","best_ask":"0.57","best_bid":"0.56","hash":"4d410d578494447c2585412641e302da6b214f6b","price":"0.46","side":"BUY","size":"135"},{"asset_id":"96600821790790307414914106093858868634329285205417149685270682748367152458577","best_ask":"0.44","best_bid":"0.43","hash":"38f52e24181531d86763b6cd92d7eb1f3886caa2","price":"0.54","side":"SELL","size":"135"}],"timestamp":"1785211428470"},"payload_hash":"33f8f4ccaf4083f7546f2026d73cf8342fc00daa54ff8ae3bc47916c4ee29629","raw_frame":"{\"market\":\"0xd412ce774cfcf8dc9f71164aac78783978aac7b03871702a3b8a481bd9dc9688\", \"price_changes\":[{\"asset_id\":\"107603864457683460275633293642179940881969192120168665300712204232021063124301\", \"price\":\"0.46\", \"size\":\"135\", \"side\":\"BUY\", \"hash\":\"4d410d578494447c2585412641e302da6b214f6b\", \"best_bid\":\"0.56\", \"best_ask\":\"0.57\"}, {\"asset_id\":\"96600821790790307414914106093858868634329285205417149685270682748367152458577\", \"price\":\"0.54\", \"size\":\"135\", \"side\":\"SELL\", \"hash\":\"38f52e24181531d86763b6cd92d7eb1f3886caa2\", \"best_bid\":\"0.43\", \"best_ask\":\"0.44\"}], \"timestamp\":\"1785211428470\", \"event_type\":\"price_change\"}","received_at":"2026-07-28T04:03:49.807779Z","schema_version":"clob-market-ws.price_change.v1","sequence":null,"server_hash":null,"server_timestamp":"1785211428470","session_id":"2d607381e3054cee91998cdf45a4231c","source":"clob_market_ws"},"received_at":"2026-07-28T04:03:49.807779Z","record_id":"ba4fc9081814997d4f2174e68d449ac9689b20fbf8d5b56bba82b922349be3b4","schema_fingerprint":"4aa3821a28b0b7c2400bc59aba4bcc0a76e971dadd19610d3ad38c768e124dc7","schema_version":"edge-lab-recorder.raw.v1","sequence":null,"source":"clob_market_ws"}
{"event_at":"2026-07-28T04:03:48.470000Z","event_fingerprint":"c8e714d4e3347f50fb475ed0835453ab6c04d093a8ea587216cca97621713abc","payload":{"connection_id":"f6725804f86a4c4eb588e4d5ed7db029","event_at":"2026-07-28T04:03:48.470000Z","event_type":"price_change","frame_hash":"3d5619548704d435bf67b67a783fced0060f247fb3a4a0469cb600b7669f2b0d","frame_index":0,"kind":"data","monotonic_ns":313412858991500,"payload":{"event_type":"price_change","market":"0xd412ce774cfcf8dc9f71164aac78783978aac7b03871702a3b8a481bd9dc9688","price_changes":[{"asset_id":"107603864457683460275633293642179940881969192120168665300712204232021063124301","best_ask":"0.57","best_bid":"0.56","hash":"e86ed336f072efbdb563207ce146be683ed14842","price":"0.47","side":"BUY","size":"206.38"},{"asset_id":"96600821790790307414914106093858868634329285205417149685270682748367152458577","best_ask":"0.44","best_bid":"0.43","hash":"5ece600eeacd3c4e553a068f9054ac39d8ec2d74","price":"0.53","side":"SELL","size":"206.38"}],"timestamp":"1785211428470"},"payload_hash":"d075657f64167857856a8f6913efb6ba81b6455f0a372fdffc001a146cee22b9","raw_frame":"{\"market\":\"0xd412ce774cfcf8dc9f71164aac78783978aac7b03871702a3b8a481bd9dc9688\", \"price_changes\":[{\"asset_id\":\"107603864457683460275633293642179940881969192120168665300712204232021063124301\", \"price\":\"0.47\", \"size\":\"206.38\", \"side\":\"BUY\", \"hash\":\"e86ed336f072efbdb563207ce146be683ed14842\", \"best_bid\":\"0.56\", \"best_ask\":\"0.57\"}, {\"asset_id\":\"96600821790790307414914106093858868634329285205417149685270682748367152458577\", \"price\":\"0.53\", \"size\":\"206.38\", \"side\":\"SELL\", \"hash\":\"5ece600eeacd3c4e553a068f9054ac39d8ec2d74\", \"best_bid\":\"0.43\", \"best_ask\":\"0.44\"}], \"timestamp\":\"1785211428470\", \"event_type\":\"price_change\"}","received_at":"2026-07-28T04:03:49.809372Z","schema_version":"clob-market-ws.price_change.v1","sequence":null,"server_hash":null,"server_timestamp":"1785211428470","session_id":"2d607381e3054cee91998cdf45a4231c","source":"clob_market_ws"},"received_at":"2026-07-28T04:03:49.809372Z","record_id":"3bf1f1442091cba0f0dd90ce4a498dc1996cf1d48ea7a1dedfb34a21bb02ebd1","schema_fingerprint":"4aa3821a28b0b7c2400bc59aba4bcc0a76e971dadd19610d3ad38c768e124dc7","schema_version":"edge-lab-recorder.raw.v1","sequence":null,"source":"clob_market_ws"}
{"event_at":"2026-07-28T04:03:48.470000Z","event_fingerprint":"5f20473f70091838becf3ef2bc626cbfa6032d39baf1746a3f15de58920febac","payload":{"connection_id":"f6725804f86a4c4eb588e4d5ed7db029","event_at":"2026-07-28T04:03:48.470000Z","event_type":"price_change","frame_hash":"60bf7a2e4bc132252a3ac6aa6692000e2f7cd755ac4bc54511e24ccad01d4dcb","frame_index":0,"kind":"data","monotonic_ns":313412862241750,"payload":{"event_type":"price_change","market":"0xd412ce774cfcf8dc9f71164aac78783978aac7b03871702a3b8a481bd9dc9688","price_changes":[{"asset_id":"107603864457683460275633293642179940881969192120168665300712204232021063124301","best_ask":"0.57","best_bid":"0.56","hash":"119a0fda8e6d95adb33720de7cb1f350f247fc46","price":"0.5","side":"BUY","size":"32.6"},{"asset_id":"96600821790790307414914106093858868634329285205417149685270682748367152458577","best_ask":"0.44","best_bid":"0.43","hash":"bc639b4403cb51bd769b748d7b213b31797f3f0a","price":"0.5","side":"SELL","size":"32.6"}],"timestamp":"1785211428470"},"payload_hash":"2114fede61c829f67533633855c3e6d33d7e7f39ccc4d18e47f21d84eb33ff7f","raw_frame":"{\"market\":\"0xd412ce774cfcf8dc9f71164aac78783978aac7b03871702a3b8a481bd9dc9688\", \"price_changes\":[{\"asset_id\":\"107603864457683460275633293642179940881969192120168665300712204232021063124301\", \"price\":\"0.5\", \"size\":\"32.6\", \"side\":\"BUY\", \"hash\":\"119a0fda8e6d95adb33720de7cb1f350f247fc46\", \"best_bid\":\"0.56\", \"best_ask\":\"0.57\"}, {\"asset_id\":\"96600821790790307414914106093858868634329285205417149685270682748367152458577\", \"price\":\"0.5\", \"size\":\"32.6\", \"side\":\"SELL\", \"hash\":\"bc639b4403cb51bd769b748d7b213b31797f3f0a\", \"best_bid\":\"0.43\", \"best_ask\":\"0.44\"}], \"timestamp\":\"1785211428470\", \"event_type\":\"price_change\"}","received_at":"2026-07-28T04:03:49.812628Z","schema_version":"clob-market-ws.price_change.v1","sequence":null,"server_hash":null,"server_timestamp":"1785211428470","session_id":"2d607381e3054cee91998cdf45a4231c","source":"clob_market_ws"},"received_at":"2026-07-28T04:03:49.812628Z","record_id":"d9e95e818dcf8c9221fb9363358fa5411fff3731102f4dfd18c3112140de5893","schema_fingerprint":"4aa3821a28b0b7c2400bc59aba4bcc0a76e971dadd19610d3ad38c768e124dc7","schema_version":"edge-lab-recorder.raw.v1","sequence":null,"source":"clob_market_ws"}
{"event_at":"2026-07-28T04:03:48.470000Z","event_fingerprint":"c4e21ba6e03ef280ccab1a9964bf760b9d0a850c4d4381dfb30d66011e86a9ff","payload":{"connection_id":"f6725804f86a4c4eb588e4d5ed7db029","event_at":"2026-07-28T04:03:48.470000Z","event_type":"price_change","frame_hash":"faee75c39ba11f383e7b605519e9860ae59b2a581c49dd8156fc863096b61c65","frame_index":0,"kind":"data","monotonic_ns":313412864597750,"payload":{"event_type":"price_change","market":"0xd412ce774cfcf8dc9f71164aac78783978aac7b03871702a3b8a481bd9dc9688","price_changes":[{"asset_id":"107603864457683460275633293642179940881969192120168665300712204232021063124301","best_ask":"0.57","best_bid":"0.56","hash":"2967f76cc50f62ceea8ba8673a6ce7c5f449948f","price":"0.45","side":"BUY","size":"113"},{"asset_id":"96600821790790307414914106093858868634329285205417149685270682748367152458577","best_ask":"0.44","best_bid":"0.43","hash":"cef84b4cb7235109684fa17e3e47bf65fee6bcd3","price":"0.55","side":"SELL","size":"113"}],"timestamp":"1785211428470"},"payload_hash":"8e5583e865b7d69dd83a209b463489ffeddfcf040335d0a28ef7aa5d44d7fa84","raw_frame":"{\"market\":\"0xd412ce774cfcf8dc9f71164aac78783978aac7b03871702a3b8a481bd9dc9688\", \"price_changes\":[{\"asset_id\":\"107603864457683460275633293642179940881969192120168665300712204232021063124301\", \"price\":\"0.45\", \"size\":\"113\", \"side\":\"BUY\", \"hash\":\"2967f76cc50f62ceea8ba8673a6ce7c5f449948f\", \"best_bid\":\"0.56\", \"best_ask\":\"0.57\"}, {\"asset_id\":\"96600821790790307414914106093858868634329285205417149685270682748367152458577\", \"price\":\"0.55\", \"size\":\"113\", \"side\":\"SELL\", \"hash\":\"cef84b4cb7235109684fa17e3e47bf65fee6bcd3\", \"best_bid\":\"0.43\", \"best_ask\":\"0.44\"}], \"timestamp\":\"1785211428470\", \"event_type\":\"price_change\"}","received_at":"2026-07-28T04:03:49.814983Z","schema_version":"clob-market-ws.price_change.v1","sequence":null,"server_hash":null,"server_timestamp":"1785211428470","session_id":"2d607381e3054cee91998cdf45a4231c","source":"clob_market_ws"},"received_at":"2026-07-28T04:03:49.814983Z","record_id":"169cf73651b230c9fdd8a141435f342aacf6b1e20bc2697f1eeeb9815fefe21e","schema_fingerprint":"4aa3821a28b0b7c2400bc59aba4bcc0a76e971dadd19610d3ad38c768e124dc7","schema_version":"edge-lab-recorder.raw.v1","sequence":null,"source":"clob_market_ws"}
{"event_at":"2026-07-28T04:03:48.471000Z","event_fingerprint":"cd1a9970dd75cde24af47a3900e78bb289c6045a61c164b2bd5b7288ee6d36b4","payload":{"connection_id":"f6725804f86a4c4eb588e4d5ed7db029","event_at":"2026-07-28T04:03:48.471000Z","event_type":"price_change","frame_hash":"9208098987767a3d2f412657e7b19a83112abe2d6a6a7497c09073297af9828d","frame_index":0,"kind":"data","monotonic_ns":313412867486625,"payload":{"event_type":"price_change","market":"0xd412ce774cfcf8dc9f71164aac78783978aac7b03871702a3b8a481bd9dc9688","price_changes":[{"asset_id":"107603864457683460275633293642179940881969192120168665300712204232021063124301","best_ask":"0.57","best_bid":"0.56","hash":"8e1a7d96f01ec20d001682754b2996006dd50ae3","price":"0.52","side":"BUY","size":"81.6"},{"asset_id":"96600821790790307414914106093858868634329285205417149685270682748367152458577","best_ask":"0.44","best_bid":"0.43","hash":"62e2e3b288b25bae1ae07c396cc859e9713bcaca","price":"0.48","side":"SELL","size":"81.6"}],"timestamp":"1785211428471"},"payload_hash":"7c493995353cded99171358f7ca94f7f460af8219704eee6cd17489dc61c1819","raw_frame":"{\"market\":\"0xd412ce774cfcf8dc9f71164aac78783978aac7b03871702a3b8a481bd9dc9688\", \"price_changes\":[{\"asset_id\":\"107603864457683460275633293642179940881969192120168665300712204232021063124301\", \"price\":\"0.52\", \"size\":\"81.6\", \"side\":\"BUY\", \"hash\":\"8e1a7d96f01ec20d001682754b2996006dd50ae3\", \"best_bid\":\"0.56\", \"best_ask\":\"0.57\"}, {\"asset_id\":\"96600821790790307414914106093858868634329285205417149685270682748367152458577\", \"price\":\"0.48\", \"size\":\"81.6\", \"side\":\"SELL\", \"hash\":\"62e2e3b288b25bae1ae07c396cc859e9713bcaca\", \"best_bid\":\"0.43\", \"best_ask\":\"0.44\"}], \"timestamp\":\"1785211428471\", \"event_type\":\"price_change\"}","received_at":"2026-07-28T04:03:49.817873Z","schema_version":"clob-market-ws.price_change.v1","sequence":null,"server_hash":null,"server_timestamp":"1785211428471","session_id":"2d607381e3054cee91998cdf45a4231c","source":"clob_market_ws"},"received_at":"2026-07-28T04:03:49.817873Z","record_id":"7f6533c78c90308dbcb4eaf50029611327ba4d52542a5b53b594056856ad9971","schema_fingerprint":"4aa3821a28b0b7c2400bc59aba4bcc0a76e971dadd19610d3ad38c768e124dc7","schema_version":"edge-lab-recorder.raw.v1","sequence":null,"source":"clob_market_ws"}
{"event_at":"2026-07-28T04:03:48.471000Z","event_fingerprint":"27887fbf5407e1bc30e610469c4e4bf452f5bc775ee78f47af316f478fd5e64d","payload":{"connection_id":"f6725804f86a4c4eb588e4d5ed7db029","event_at":"2026-07-28T04:03:48.471000Z","event_type":"price_change","frame_hash":"dcda51a8beb362c77fe8459aa3b673d2baf525ff4ff4a030c7387bd51bbbd278","frame_index":0,"kind":"data","monotonic_ns":313412869738166,"payload":{"event_type":"price_change","market":"0xd412ce774cfcf8dc9f71164aac78783978aac7b03871702a3b8a481bd9dc9688","price_changes":[{"asset_id":"107603864457683460275633293642179940881969192120168665300712204232021063124301","best_ask":"0.57","best_bid":"0.56","hash":"d4d00ab869a0e2fa1fbe1b35939669a3ddd1ba93","price":"0.48","side":"BUY","size":"140"},{"asset_id":"96600821790790307414914106093858868634329285205417149685270682748367152458577","best_ask":"0.44","best_bid":"0.43","hash":"1eec3a65e1e5bb8c4a35a26bcf1eb75469dedd32","price":"0.52","side":"SELL","size":"140"}],"timestamp":"1785211428471"},"payload_hash":"4c63504a4026dd7b7b1cb85cee703f628b539856a9304e4ad9b9e6cebc004083","raw_frame":"{\"market\":\"0xd412ce774cfcf8dc9f71164aac78783978aac7b03871702a3b8a481bd9dc9688\", \"price_changes\":[{\"asset_id\":\"107603864457683460275633293642179940881969192120168665300712204232021063124301\", \"price\":\"0.48\", \"size\":\"140\", \"side\":\"BUY\", \"hash\":\"d4d00ab869a0e2fa1fbe1b35939669a3ddd1ba93\", \"best_bid\":\"0.56\", \"best_ask\":\"0.57\"}, {\"asset_id\":\"96600821790790307414914106093858868634329285205417149685270682748367152458577\", \"price\":\"0.52\", \"size\":\"140\", \"side\":\"SELL\", \"hash\":\"1eec3a65e1e5bb8c4a35a26bcf1eb75469dedd32\", \"best_bid\":\"0.43\", \"best_ask\":\"0.44\"}], \"timestamp\":\"1785211428471\", \"event_type\":\"price_change\"}","received_at":"2026-07-28T04:03:49.820123Z","schema_version":"clob-market-ws.price_change.v1","sequence":null,"server_hash":null,"server_timestamp":"1785211428471","session_id":"2d607381e3054cee91998cdf45a4231c","source":"clob_market_ws"},"received_at":"2026-07-28T04:03:49.820123Z","record_id":"d8224f2833c79b01fb3e00027c3a4ef480abe6bb235c805160acc5bdbc43bc80","schema_fingerprint":"4aa3821a28b0b7c2400bc59aba4bcc0a76e971dadd19610d3ad38c768e124dc7","schema_version":"edge-lab-recorder.raw.v1","sequence":null,"source":"clob_market_ws"}
{"event_at":"2026-07-28T04:03:48.471000Z","event_fingerprint":"57e8a9a7d2e17760cabf704a4bcf6cb47d5eddedf0c9497247d8d43cca09164e","payload":{"connection_id":"f6725804f86a4c4eb588e4d5ed7db029","event_at":"2026-07-28T04:03:48.471000Z","event_type":"price_change","frame_hash":"c38a86f15d53a0440fa672f2aff3792145feb6d15b9ebe74c23f79e723a38ba1","frame_index":0,"kind":"data","monotonic_ns":313412892150875,"payload":{"event_type":"price_change","market":"0xd412ce774cfcf8dc9f71164aac78783978aac7b03871702a3b8a481bd9dc9688","price_changes":[{"asset_id":"107603864457683460275633293642179940881969192120168665300712204232021063124301","best_ask":"0.57","best_bid":"0.56","hash":"df9938e520ccbe41a5fea0528cbfa09b259d7c40","price":"0.54","side":"BUY","size":"130.25"},{"asset_id":"96600821790790307414914106093858868634329285205417149685270682748367152458577","best_ask":"0.44","best_bid":"0.43","hash":"f0cf6d34350548682c0af57aa013d483e5c0920b","price":"0.46","side":"SELL","size":"130.25"}],"timestamp":"1785211428471"},"payload_hash":"aa1f7a87c5847e14964f6c9004f990adc7139e0687ca9c3f49da1d93bbca4301","raw_frame":"{\"market\":\"0xd412ce774cfcf8dc9f71164aac78783978aac7b03871702a3b8a481bd9dc9688\", \"price_changes\":[{\"asset_id\":\"107603864457683460275633293642179940881969192120168665300712204232021063124301\", \"price\":\"0.54\", \"size\":\"130.25\", \"side\":\"BUY\", \"hash\":\"df9938e520ccbe41a5fea0528cbfa09b259d7c40\", \"best_bid\":\"0.56\", \"best_ask\":\"0.57\"}, {\"asset_id\":\"96600821790790307414914106093858868634329285205417149685270682748367152458577\", \"price\":\"0.46\", \"size\":\"130.25\", \"side\":\"SELL\", \"hash\":\"f0cf6d34350548682c0af57aa013d483e5c0920b\", \"best_bid\":\"0.43\", \"best_ask\":\"0.44\"}], \"timestamp\":\"1785211428471\", \"event_type\":\"price_change\"}","received_at":"2026-07-28T04:03:49.842534Z","schema_version":"clob-market-ws.price_change.v1","sequence":null,"server_hash":null,"server_timestamp":"1785211428471","session_id":"2d607381e3054cee91998cdf45a4231c","source":"clob_market_ws"},"received_at":"2026-07-28T04:03:49.842534Z","record_id":"09b4d4f85ca62680be2fbe43d868dafdedccadf828cf58dcad6e8837090becc9","schema_fingerprint":"4aa3821a28b0b7c2400bc59aba4bcc0a76e971dadd19610d3ad38c768e124dc7","schema_version":"edge-lab-recorder.raw.v1","sequence":null,"source":"clob_market_ws"}
{"event_at":"2026-07-28T04:03:48.471000Z","event_fingerprint":"046c68c160ba0b0c54d5c874823516fe1cda53a4e0d7eb5312eaa37a19375cb8","payload":{"connection_id":"f6725804f86a4c4eb588e4d5ed7db029","event_at":"2026-07-28T04:03:48.471000Z","event_type":"price_change","frame_hash":"cc571e5f83b5d09b65fc59368ffee5713e70925beff3fabea3f8e741aeccfbe6","frame_index":0,"kind":"data","monotonic_ns":313412893747291,"payload":{"event_type":"price_change","market":"0xd412ce774cfcf8dc9f71164aac78783978aac7b03871702a3b8a481bd9dc9688","price_changes":[{"asset_id":"107603864457683460275633293642179940881969192120168665300712204232021063124301","best_ask":"0.57","best_bid":"0.56","hash":"b8ee7162480a3bae77ed7fae66859c5dd063aea4","price":"0.51","side":"BUY","size":"95.8"},{"asset_id":"96600821790790307414914106093858868634329285205417149685270682748367152458577","best_ask":"0.44","best_bid":"0.43","hash":"9532a8e0d09498305926dccce26fce427f0970f8","price":"0.49","side":"SELL","size":"95.8"}],"timestamp":"1785211428471"},"payload_hash":"b06f37b459e2c1fcfaee12fc471e55d0044d4ad6331129aa33f5402f63e9877d","raw_frame":"{\"market\":\"0xd412ce774cfcf8dc9f71164aac78783978aac7b03871702a3b8a481bd9dc9688\", \"price_changes\":[{\"asset_id\":\"107603864457683460275633293642179940881969192120168665300712204232021063124301\", \"price\":\"0.51\", \"size\":\"95.8\", \"side\":\"BUY\", \"hash\":\"b8ee7162480a3bae77ed7fae66859c5dd063aea4\", \"best_bid\":\"0.56\", \"best_ask\":\"0.57\"}, {\"asset_id\":\"96600821790790307414914106093858868634329285205417149685270682748367152458577\", \"price\":\"0.49\", \"size\":\"95.8\", \"side\":\"SELL\", \"hash\":\"9532a8e0d09498305926dccce26fce427f0970f8\", \"best_bid\":\"0.43\", \"best_ask\":\"0.44\"}], \"timestamp\":\"1785211428471\", \"event_type\":\"price_change\"}","received_at":"2026-07-28T04:03:49.844131Z","schema_version":"clob-market-ws.price_change.v1","sequence":null,"server_hash":null,"server_timestamp":"1785211428471","session_id":"2d607381e3054cee91998cdf45a4231c","source":"clob_market_ws"},"received_at":"2026-07-28T04:03:49.844131Z","record_id":"787c7bd4304eb86f79641ab512e25f86c73c3a641bd8e9253dbc0db46764d60b","schema_fingerprint":"4aa3821a28b0b7c2400bc59aba4bcc0a76e971dadd19610d3ad38c768e124dc7","schema_version":"edge-lab-recorder.raw.v1","sequence":null,"source":"clob_market_ws"}
{"event_at":"2026-07-28T04:03:48.473000Z","event_fingerprint":"91c49d9fc2317475df1e38c98d5cdf84d2fa392be3b30ce18c6d651f6516c6d1","payload":{"connection_id":"f6725804f86a4c4eb588e4d5ed7db029","event_at":"2026-07-28T04:03:48.473000Z","event_type":"price_change","frame_hash":"e268a165d1e5e8e5b58abf1c75a2dcfc31e2eace39795ad8cef080d0452eee2d","frame_index":0,"kind":"data","monotonic_ns":313412918721833,"payload":{"event_type":"price_change","market":"0xd412ce774cfcf8dc9f71164aac78783978aac7b03871702a3b8a481bd9dc9688","price_changes":[{"asset_id":"107603864457683460275633293642179940881969192120168665300712204232021063124301","best_ask":"0.57","best_bid":"0.56","hash":"16fdd03f1101518a2673246e3cab1c71629f896b","price":"0.43","side":"BUY","size":"152.2"},{"asset_id":"96600821790790307414914106093858868634329285205417149685270682748367152458577","best_ask":"0.44","best_bid":"0.43","hash":"13be3d93464ece13766cb3e5cfae6a1eb0c63254","price":"0.57","side":"SELL","size":"152.2"}],"timestamp":"1785211428473"},"payload_hash":"22f0d4d3eb9d0636414656f2eafc288926ca7afd8f9583a02c10424e14b2d703","raw_frame":"{\"market\":\"0xd412ce774cfcf8dc9f71164aac78783978aac7b03871702a3b8a481bd9dc9688\", \"price_changes\":[{\"asset_id\":\"107603864457683460275633293642179940881969192120168665300712204232021063124301\", \"price\":\"0.43\", \"size\":\"152.2\", \"side\":\"BUY\", \"hash\":\"16fdd03f1101518a2673246e3cab1c71629f896b\", \"best_bid\":\"0.56\", \"best_ask\":\"0.57\"}, {\"asset_id\":\"96600821790790307414914106093858868634329285205417149685270682748367152458577\", \"price\":\"0.57\", \"size\":\"152.2\", \"side\":\"SELL\", \"hash\":\"13be3d93464ece13766cb3e5cfae6a1eb0c63254\", \"best_bid\":\"0.43\", \"best_ask\":\"0.44\"}], \"timestamp\":\"1785211428473\", \"event_type\":\"price_change\"}","received_at":"2026-07-28T04:03:49.869104Z","schema_version":"clob-market-ws.price_change.v1","sequence":null,"server_hash":null,"server_timestamp":"1785211428473","session_id":"2d607381e3054cee91998cdf45a4231c","source":"clob_market_ws"},"received_at":"2026-07-28T04:03:49.869104Z","record_id":"563c5575420fb23f23f647f7e57c85e8e9a3c7016134d5d608ac35f8d0d623bc","schema_fingerprint":"4aa3821a28b0b7c2400bc59aba4bcc0a76e971dadd19610d3ad38c768e124dc7","schema_version":"edge-lab-recorder.raw.v1","sequence":null,"source":"clob_market_ws"}
{"event_at":"2026-07-28T04:03:48.473000Z","event_fingerprint":"02fff4e23268fc8f391ab0d04434df89df54ec95dc509cf1b5988f6121d739ce","payload":{"connection_id":"f6725804f86a4c4eb588e4d5ed7db029","event_at":"2026-07-28T04:03:48.473000Z","event_type":"price_change","frame_hash":"9b24d010e235254a2f69ada5d3f5271b348fe6ed938c4ea5735268170f2de602","frame_index":0,"kind":"data","monotonic_ns":313412920413250,"payload":{"event_type":"price_change","market":"0xd412ce774cfcf8dc9f71164aac78783978aac7b03871702a3b8a481bd9dc9688","price_changes":[{"asset_id":"107603864457683460275633293642179940881969192120168665300712204232021063124301","best_ask":"0.57","best_bid":"0.56","hash":"a5abea02801e7b1feb48b6e2c36658303551b8c5","price":"0.49","side":"BUY","size":"60"},{"asset_id":"96600821790790307414914106093858868634329285205417149685270682748367152458577","best_ask":"0.44","best_bid":"0.43","hash":"a54098f63f4cd279d2658aa639fb123c5f279550","price":"0.51","side":"SELL","size":"60"}],"timestamp":"1785211428473"},"payload_hash":"3471fe5464b7d3302bbd7326d73b74f5eec872099d6d6c1222282f1730ef00ba","raw_frame":"{\"market\":\"0xd412ce774cfcf8dc9f71164aac78783978aac7b03871702a3b8a481bd9dc9688\", \"price_changes\":[{\"asset_id\":\"107603864457683460275633293642179940881969192120168665300712204232021063124301\", \"price\":\"0.49\", \"size\":\"60\", \"side\":\"BUY\", \"hash\":\"a5abea02801e7b1feb48b6e2c36658303551b8c5\", \"best_bid\":\"0.56\", \"best_ask\":\"0.57\"}, {\"asset_id\":\"96600821790790307414914106093858868634329285205417149685270682748367152458577\", \"price\":\"0.51\", \"size\":\"60\", \"side\":\"SELL\", \"hash\":\"a54098f63f4cd279d2658aa639fb123c5f279550\", \"best_bid\":\"0.43\", \"best_ask\":\"0.44\"}], \"timestamp\":\"1785211428473\", \"event_type\":\"price_change\"}","received_at":"2026-07-28T04:03:49.870798Z","schema_version":"clob-market-ws.price_change.v1","sequence":null,"server_hash":null,"server_timestamp":"1785211428473","session_id":"2d607381e3054cee91998cdf45a4231c","source":"clob_market_ws"},"received_at":"2026-07-28T04:03:49.870798Z","record_id":"51194f6708aed7048c76ad30607dfcd91792e74efe376daf93f0984e6423e902","schema_fingerprint":"4aa3821a28b0b7c2400bc59aba4bcc0a76e971dadd19610d3ad38c768e124dc7","schema_version":"edge-lab-recorder.raw.v1","sequence":null,"source":"clob_market_ws"}
{"event_at":"2026-07-28T04:03:48.491000Z","event_fingerprint":"d2e9bba42f17e7e4cde6fd896b665ae8af0716ac2a9c42577b19e9b2eed97573","payload":{"connection_id":"f6725804f86a4c4eb588e4d5ed7db029","event_at":"2026-07-28T04:03:48.491000Z","event_type":"price_change","frame_hash":"1f29decb4b623e220c760c65e41db6c21a0a424cf4a6de7e951ff9ecf9aa9ffa","frame_index":0,"kind":"data","monotonic_ns":313412923433583,"payload":{"event_type":"price_change","market":"0xd412ce774cfcf8dc9f71164aac78783978aac7b03871702a3b8a481bd9dc9688","price_changes":[{"asset_id":"107603864457683460275633293642179940881969192120168665300712204232021063124301","best_ask":"0.57","best_bid":"0.56","hash":"fa50e2eebf66080e6c8d13ae1b4c736fd29a8bc4","price":"0.04","side":"BUY","size":"673.09"},{"asset_id":"96600821790790307414914106093858868634329285205417149685270682748367152458577","best_ask":"0.44","best_bid":"0.43","hash":"1aba53d3b8c327f989d06d2a4dac6c99126f0b1a","price":"0.96","side":"SELL","size":"673.09"}],"timestamp":"1785211428491"},"payload_hash":"93e64e71209001d3ae49a41eae92b4bbb3d4d9dadf625d57bce0f921c3fbdf59","raw_frame":"{\"market\":\"0xd412ce774cfcf8dc9f71164aac78783978aac7b03871702a3b8a481bd9dc9688\", \"price_changes\":[{\"asset_id\":\"107603864457683460275633293642179940881969192120168665300712204232021063124301\", \"price\":\"0.04\", \"size\":\"673.09\", \"side\":\"BUY\", \"hash\":\"fa50e2eebf66080e6c8d13ae1b4c736fd29a8bc4\", \"best_bid\":\"0.56\", \"best_ask\":\"0.57\"}, {\"asset_id\":\"96600821790790307414914106093858868634329285205417149685270682748367152458577\", \"price\":\"0.96\", \"size\":\"673.09\", \"side\":\"SELL\", \"hash\":\"1aba53d3b8c327f989d06d2a4dac6c99126f0b1a\", \"best_bid\":\"0.43\", \"best_ask\":\"0.44\"}], \"timestamp\":\"1785211428491\", \"event_type\":\"price_change\"}","received_at":"2026-07-28T04:03:49.873818Z","schema_version":"clob-market-ws.price_change.v1","sequence":null,"server_hash":null,"server_timestamp":"1785211428491","session_id":"2d607381e3054cee91998cdf45a4231c","source":"clob_market_ws"},"received_at":"2026-07-28T04:03:49.873818Z","record_id":"9acf5976d8564f8e14087950dcf09cbc2881e9d4576c5875abf569aa1515ec72","schema_fingerprint":"4aa3821a28b0b7c2400bc59aba4bcc0a76e971dadd19610d3ad38c768e124dc7","schema_version":"edge-lab-recorder.raw.v1","sequence":null,"source":"clob_market_ws"}
{"event_at":"2026-07-28T04:03:48.518000Z","event_fingerprint":"9eb8c9944f883c7e7f4a3467fa2c7b3a345fe62f2da24f1e7b24904e346f389b","payload":{"connection_id":"f6725804f86a4c4eb588e4d5ed7db029","event_at":"2026-07-28T04:03:48.518000Z","event_type":"price_change","frame_hash":"068298606adbf8cd49ed855aca032dd70c7964a37b5d72dc3d26289c5920060b","frame_index":0,"kind":"data","monotonic_ns":313412925733458,"payload":{"event_type":"price_change","market":"0xd412ce774cfcf8dc9f71164aac78783978aac7b03871702a3b8a481bd9dc9688","price_changes":[{"asset_id":"107603864457683460275633293642179940881969192120168665300712204232021063124301","best_ask":"0.57","best_bid":"0.56","hash":"74ed366596cc066ebc1832a20581bb222333998a","price":"0.01","side":"BUY","size":"7888.02"},{"asset_id":"96600821790790307414914106093858868634329285205417149685270682748367152458577","best_ask":"0.44","best_bid":"0.43","hash":"599fed5e8939700414d2437604de967479cca61b","price":"0.99","side":"SELL","size":"7888.02"}],"timestamp":"1785211428518"},"payload_hash":"4eaf5375735f0a0d65179ff1bcc7f511a8df9661e8afefd01ccaccf4d282bda9","raw_frame":"{\"market\":\"0xd412ce774cfcf8dc9f71164aac78783978aac7b03871702a3b8a481bd9dc9688\", \"price_changes\":[{\"asset_id\":\"107603864457683460275633293642179940881969192120168665300712204232021063124301\", \"price\":\"0.01\", \"size\":\"7888.02\", \"side\":\"BUY\", \"hash\":\"74ed366596cc066ebc1832a20581bb222333998a\", \"best_bid\":\"0.56\", \"best_ask\":\"0.57\"}, {\"asset_id\":\"96600821790790307414914106093858868634329285205417149685270682748367152458577\", \"price\":\"0.99\", \"size\":\"7888.02\", \"side\":\"SELL\", \"hash\":\"599fed5e8939700414d2437604de967479cca61b\", \"best_bid\":\"0.43\", \"best_ask\":\"0.44\"}], \"timestamp\":\"1785211428518\", \"event_type\":\"price_change\"}","received_at":"2026-07-28T04:03:49.876118Z","schema_version":"clob-market-ws.price_change.v1","sequence":null,"server_hash":null,"server_timestamp":"1785211428518","session_id":"2d607381e3054cee91998cdf45a4231c","source":"clob_market_ws"},"received_at":"2026-07-28T04:03:49.876118Z","record_id":"71301a17001c5bbf4c906bb9c2eef1060753cf0a151348f116e4ae0a479aab95","schema_fingerprint":"4aa3821a28b0b7c2400bc59aba4bcc0a76e971dadd19610d3ad38c768e124dc7","schema_version":"edge-lab-recorder.raw.v1","sequence":null,"source":"clob_market_ws"}
{"event_at":"2026-07-28T04:03:48.538000Z","event_fingerprint":"25df365bd32727aad43c11eaac19c39ba70b0ed6498d57393c15a3b41541bcae","payload":{"connection_id":"f6725804f86a4c4eb588e4d5ed7db029","event_at":"2026-07-28T04:03:48.538000Z","event_type":"price_change","frame_hash":"2c7c0853e6ddfc6d914f01f89379db676dd199e8be02a3b7f49c66f11dcba740","frame_index":0,"kind":"data","monotonic_ns":313412927314416,"payload":{"event_type":"price_change","market":"0xd412ce774cfcf8dc9f71164aac78783978aac7b03871702a3b8a481bd9dc9688","price_changes":[{"asset_id":"107603864457683460275633293642179940881969192120168665300712204232021063124301","best_ask":"0.57","best_bid":"0.56","hash":"0928c88e9fa5bcc5aceb7b2b07a56c40d76352e5","price":"0.01","side":"BUY","size":"7883.02"},{"asset_id":"96600821790790307414914106093858868634329285205417149685270682748367152458577","best_ask":"0.44","best_bid":"0.43","hash":"6b6c44c6e8be34608fef63603763abf1617a2aa4","price":"0.99","side":"SELL","size":"7883.02"}],"timestamp":"1785211428538"},"payload_hash":"6d665a8ff1660346751a93a0d6fa90cb2da604eb97f545b653176289a0e6d807","raw_frame":"{\"market\":\"0xd412ce774cfcf8dc9f71164aac78783978aac7b03871702a3b8a481bd9dc9688\", \"price_changes\":[{\"asset_id\":\"107603864457683460275633293642179940881969192120168665300712204232021063124301\", \"price\":\"0.01\", \"size\":\"7883.02\", \"side\":\"BUY\", \"hash\":\"0928c88e9fa5bcc5aceb7b2b07a56c40d76352e5\", \"best_bid\":\"0.56\", \"best_ask\":\"0.57\"}, {\"asset_id\":\"96600821790790307414914106093858868634329285205417149685270682748367152458577\", \"price\":\"0.99\", \"size\":\"7883.02\", \"side\":\"SELL\", \"hash\":\"6b6c44c6e8be34608fef63603763abf1617a2aa4\", \"best_bid\":\"0.43\", \"best_ask\":\"0.44\"}], \"timestamp\":\"1785211428538\", \"event_type\":\"price_change\"}","received_at":"2026-07-28T04:03:49.877700Z","schema_version":"clob-market-ws.price_change.v1","sequence":null,"server_hash":null,"server_timestamp":"1785211428538","session_id":"2d607381e3054cee91998cdf45a4231c","source":"clob_market_ws"},"received_at":"2026-07-28T04:03:49.877700Z","record_id":"5f78f67b1ff281c5618532d45e64224852e326f48e06947e168bff543edcaf6e","schema_fingerprint":"4aa3821a28b0b7c2400bc59aba4bcc0a76e971dadd19610d3ad38c768e124dc7","schema_version":"edge-lab-recorder.raw.v1","sequence":null,"source":"clob_market_ws"}
{"event_at":"2026-07-28T04:03:48.541000Z","event_fingerprint":"f665d38bc1be213b4e0fafa8d0983075ee2e0631cc109e473724bdadf43c25da","payload":{"connection_id":"f6725804f86a4c4eb588e4d5ed7db029","event_at":"2026-07-28T04:03:48.541000Z","event_type":"price_change","frame_hash":"f51a4e0e65613d56ae963d3cbea26adf4783350226c65604fe48d7dfb4c658cd","frame_index":0,"kind":"data","monotonic_ns":313412928889000,"payload":{"event_type":"price_change","market":"0xd412ce774cfcf8dc9f71164aac78783978aac7b03871702a3b8a481bd9dc9688","price_changes":[{"asset_id":"107603864457683460275633293642179940881969192120168665300712204232021063124301","best_ask":"0.57","best_bid":"0.56","hash":"68c3134dbac67925f26bfc92e3a52de16a4f45fd","price":"0.51","side":"BUY","size":"75.8"},{"asset_id":"96600821790790307414914106093858868634329285205417149685270682748367152458577","best_ask":"0.44","best_bid":"0.43","hash":"01611f5fd7f7f6da9c09b2026393fb8132e4b27d","price":"0.49","side":"SELL","size":"75.8"}],"timestamp":"1785211428541"},"payload_hash":"9747d9a272176185602bfb2d846f9a6983db4939b224a9eba5f0adeb587e5cca","raw_frame":"{\"market\":\"0xd412ce774cfcf8dc9f71164aac78783978aac7b03871702a3b8a481bd9dc9688\", \"price_changes\":[{\"asset_id\":\"107603864457683460275633293642179940881969192120168665300712204232021063124301\", \"price\":\"0.51\", \"size\":\"75.8\", \"side\":\"BUY\", \"hash\":\"68c3134dbac67925f26bfc92e3a52de16a4f45fd\", \"best_bid\":\"0.56\", \"best_ask\":\"0.57\"}, {\"asset_id\":\"96600821790790307414914106093858868634329285205417149685270682748367152458577\", \"price\":\"0.49\", \"size\":\"75.8\", \"side\":\"SELL\", \"hash\":\"01611f5fd7f7f6da9c09b2026393fb8132e4b27d\", \"best_bid\":\"0.43\", \"best_ask\":\"0.44\"}], \"timestamp\":\"1785211428541\", \"event_type\":\"price_change\"}","received_at":"2026-07-28T04:03:49.879273Z","schema_version":"clob-market-ws.price_change.v1","sequence":null,"server_hash":null,"server_timestamp":"1785211428541","session_id":"2d607381e3054cee91998cdf45a4231c","source":"clob_market_ws"},"received_at":"2026-07-28T04:03:49.879273Z","record_id":"f7f16706a8428545c6ecabe0015362e2b1cf317020bdcb375e6c5e60475be354","schema_fingerprint":"4aa3821a28b0b7c2400bc59aba4bcc0a76e971dadd19610d3ad38c768e124dc7","schema_version":"edge-lab-recorder.raw.v1","sequence":null,"source":"clob_market_ws"}
{"event_at":"2026-07-28T04:03:48.541000Z","event_fingerprint":"d961c31e29e2a9728038b445ce2c2f3cc8030059e3fc833adb97c1573d4254fa","payload":{"connection_id":"f6725804f86a4c4eb588e4d5ed7db029","event_at":"2026-07-28T04:03:48.541000Z","event_type":"price_change","frame_hash":"b8b07c8ac8e1d13385efa40a57202b04e0c051ed6ba3475ec7befe8f6acbae22","frame_index":0,"kind":"data","monotonic_ns":313412930426583,"payload":{"event_type":"price_change","market":"0xd412ce774cfcf8dc9f71164aac78783978aac7b03871702a3b8a481bd9dc9688","price_changes":[{"asset_id":"96600821790790307414914106093858868634329285205417149685270682748367152458577","best_ask":"0.44","best_bid":"0.43","hash":"01611f5fd7f7f6da9c09b2026393fb8132e4b27d","price":"0.39","side":"BUY","size":"169"},{"asset_id":"107603864457683460275633293642179940881969192120168665300712204232021063124301","best_ask":"0.57","best_bid":"0.56","hash":"68c3134dbac67925f26bfc92e3a52de16a4f45fd","price":"0.61","side":"SELL","size":"169"}],"timestamp":"1785211428541"},"payload_hash":"9e4bfbcddb93592028565024eadaf77075275ad62b7fdde475dfc8ad9c718bda","raw_frame":"{\"market\":\"0xd412ce774cfcf8dc9f71164aac78783978aac7b03871702a3b8a481bd9dc9688\", \"price_changes\":[{\"asset_id\":\"96600821790790307414914106093858868634329285205417149685270682748367152458577\", \"price\":\"0.39\", \"size\":\"169\", \"side\":\"BUY\", \"hash\":\"01611f5fd7f7f6da9c09b2026393fb8132e4b27d\", \"best_bid\":\"0.43\", \"best_ask\":\"0.44\"}, {\"asset_id\":\"107603864457683460275633293642179940881969192120168665300712204232021063124301\", \"price\":\"0.61\", \"size\":\"169\", \"side\":\"SELL\", \"hash\":\"68c3134dbac67925f26bfc92e3a52de16a4f45fd\", \"best_bid\":\"0.56\", \"best_ask\":\"0.57\"}], \"timestamp\":\"1785211428541\", \"event_type\":\"price_change\"}","received_at":"2026-07-28T04:03:49.880812Z","schema_version":"clob-market-ws.price_change.v1","sequence":null,"server_hash":null,"server_timestamp":"1785211428541","session_id":"2d607381e3054cee91998cdf45a4231c","source":"clob_market_ws"},"received_at":"2026-07-28T04:03:49.880812Z","record_id":"9717505847b6f8cd586e54eb008b76727eaf225794d765f5bd530b2bfc80fef0","schema_fingerprint":"4aa3821a28b0b7c2400bc59aba4bcc0a76e971dadd19610d3ad38c768e124dc7","schema_version":"edge-lab-recorder.raw.v1","sequence":null,"source":"clob_market_ws"}
{"event_at":"2026-07-28T04:03:48.544000Z","event_fingerprint":"c30e6fbed866e093b6be897be8fbfc015f6f0002884e008593d3c91f92951888","payload":{"connection_id":"f6725804f86a4c4eb588e4d5ed7db029","event_at":"2026-07-28T04:03:48.544000Z","event_type":"price_change","frame_hash":"b6a5dc25f7f06298fc54cfec5facd1136df7c55317c9c055c17143707d4be355","frame_index":0,"kind":"data","monotonic_ns":313412981117291,"payload":{"event_type":"price_change","market":"0xd412ce774cfcf8dc9f71164aac78783978aac7b03871702a3b8a481bd9dc9688","price_changes":[{"asset_id":"107603864457683460275633293642179940881969192120168665300712204232021063124301","best_ask":"0.57","best_bid":"0.56","hash":"5c2a9eaa8d79bdb78e9dacc7e61345d27d9139c2","price":"0.04","side":"BUY","size":"668.09"},{"asset_id":"96600821790790307414914106093858868634329285205417149685270682748367152458577","best_ask":"0.44","best_bid":"0.43","hash":"09207f9be25688fd3c873e19ad96c5facd0af997","price":"0.96","side":"SELL","size":"668.09"}],"timestamp":"1785211428544"},"payload_hash":"74c46c9930d52a54eb8517033f735b2cec9d94d0f35bd003ce1b731941754674","raw_frame":"{\"market\":\"0xd412ce774cfcf8dc9f71164aac78783978aac7b03871702a3b8a481bd9dc9688\", \"price_changes\":[{\"asset_id\":\"107603864457683460275633293642179940881969192120168665300712204232021063124301\", \"price\":\"0.04\", \"size\":\"668.09\", \"side\":\"BUY\", \"hash\":\"5c2a9eaa8d79bdb78e9dacc7e61345d27d9139c2\", \"best_bid\":\"0.56\", \"best_ask\":\"0.57\"}, {\"asset_id\":\"96600821790790307414914106093858868634329285205417149685270682748367152458577\", \"price\":\"0.96\", \"size\":\"668.09\", \"side\":\"SELL\", \"hash\":\"09207f9be25688fd3c873e19ad96c5facd0af997\", \"best_bid\":\"0.43\", \"best_ask\":\"0.44\"}], \"timestamp\":\"1785211428544\", \"event_type\":\"price_change\"}","received_at":"2026-07-28T04:03:49.931499Z","schema_version":"clob-market-ws.price_change.v1","sequence":null,"server_hash":null,"server_timestamp":"1785211428544","session_id":"2d607381e3054cee91998cdf45a4231c","source":"clob_market_ws"},"received_at":"2026-07-28T04:03:49.931499Z","record_id":"32abb8c523df872f8524b0f2f730b4f3037d3b1bddefdfddd5071f28df92e7c2","schema_fingerprint":"4aa3821a28b0b7c2400bc59aba4bcc0a76e971dadd19610d3ad38c768e124dc7","schema_version":"edge-lab-recorder.raw.v1","sequence":null,"source":"clob_market_ws"}
{"event_at":"2026-07-28T04:03:48.547000Z","event_fingerprint":"c69c6ef47abbc02f2738a9a8846207752be142f03014e78ad1d4e1c34376520f","payload":{"connection_id":"f6725804f86a4c4eb588e4d5ed7db029","event_at":"2026-07-28T04:03:48.547000Z","event_type":"price_change","frame_hash":"eec49ef24c550f4fa3ac1c988a4412502ff0c24cdec2d4f3176e271cc2ad23a7","frame_index":0,"kind":"data","monotonic_ns":313412982750000,"payload":{"event_type":"price_change","market":"0xd412ce774cfcf8dc9f71164aac78783978aac7b03871702a3b8a481bd9dc9688","price_changes":[{"asset_id":"107603864457683460275633293642179940881969192120168665300712204232021063124301","best_ask":"0.57","best_bid":"0.56","hash":"9069818ab80da91fea2069a3658bcbc447e59557","price":"0.51","side":"BUY","size":"55.8"},{"asset_id":"96600821790790307414914106093858868634329285205417149685270682748367152458577","best_ask":"0.44","best_bid":"0.43","hash":"7eb953cde93a636d1c37522b096c3933c1f97406","price":"0.49","side":"SELL","size":"55.8"}],"timestamp":"1785211428547"},"payload_hash":"3b0c5ee13f1ec25a10a03246dee220249ea14d27128549d094bcdf9b413fe51e","raw_frame":"{\"market\":\"0xd412ce774cfcf8dc9f71164aac78783978aac7b03871702a3b8a481bd9dc9688\", \"price_changes\":[{\"asset_id\":\"107603864457683460275633293642179940881969192120168665300712204232021063124301\", \"price\":\"0.51\", \"size\":\"55.8\", \"side\":\"BUY\", \"hash\":\"9069818ab80da91fea2069a3658bcbc447e59557\", \"best_bid\":\"0.56\", \"best_ask\":\"0.57\"}, {\"asset_id\":\"96600821790790307414914106093858868634329285205417149685270682748367152458577\", \"price\":\"0.49\", \"size\":\"55.8\", \"side\":\"SELL\", \"hash\":\"7eb953cde93a636d1c37522b096c3933c1f97406\", \"best_bid\":\"0.43\", \"best_ask\":\"0.44\"}], \"timestamp\":\"1785211428547\", \"event_type\":\"price_change\"}","received_at":"2026-07-28T04:03:49.933134Z","schema_version":"clob-market-ws.price_change.v1","sequence":null,"server_hash":null,"server_timestamp":"1785211428547","session_id":"2d607381e3054cee91998cdf45a4231c","source":"clob_market_ws"},"received_at":"2026-07-28T04:03:49.933134Z","record_id":"210fc6c5cafb0bb13b2a15b2c88a171704ad623ca004d96dc180c3cd63979c12","schema_fingerprint":"4aa3821a28b0b7c2400bc59aba4bcc0a76e971dadd19610d3ad38c768e124dc7","schema_version":"edge-lab-recorder.raw.v1","sequence":null,"source":"clob_market_ws"}
{"event_at":"2026-07-28T04:03:48.547000Z","event_fingerprint":"55bc89b916bb5c19b8173dcb111f490555e673269064c3dcf7c89108d330c230","payload":{"connection_id":"f6725804f86a4c4eb588e4d5ed7db029","event_at":"2026-07-28T04:03:48.547000Z","event_type":"price_change","frame_hash":"38e8efbcacd4240a22a1c36e68851230ba45c8be64517d9e4e708549c47c2e2e","frame_index":0,"kind":"data","monotonic_ns":313412984264541,"payload":{"event_type":"price_change","market":"0xd412ce774cfcf8dc9f71164aac78783978aac7b03871702a3b8a481bd9dc9688","price_changes":[{"asset_id":"96600821790790307414914106093858868634329285205417149685270682748367152458577","best_ask":"0.44","best_bid":"0.43","hash":"7eb953cde93a636d1c37522b096c3933c1f97406","price":"0.39","side":"BUY","size":"149"},{"asset_id":"107603864457683460275633293642179940881969192120168665300712204232021063124301","best_ask":"0.57","best_bid":"0.56","hash":"9069818ab80da91fea2069a3658bcbc447e59557","price":"0.61","side":"SELL","size":"149"}],"timestamp":"1785211428547"},"payload_hash":"ba79c1bbd02b861f51507e117b6768782c44673df77fc834f5894eb3d8dd5e0d","raw_frame":"{\"market\":\"0xd412ce774cfcf8dc9f71164aac78783978aac7b03871702a3b8a481bd9dc9688\", \"price_changes\":[{\"asset_id\":\"96600821790790307414914106093858868634329285205417149685270682748367152458577\", \"price\":\"0.39\", \"size\":\"149\", \"side\":\"BUY\", \"hash\":\"7eb953cde93a636d1c37522b096c3933c1f97406\", \"best_bid\":\"0.43\", \"best_ask\":\"0.44\"}, {\"asset_id\":\"107603864457683460275633293642179940881969192120168665300712204232021063124301\", \"price\":\"0.61\", \"size\":\"149\", \"side\":\"SELL\", \"hash\":\"9069818ab80da91fea2069a3658bcbc447e59557\", \"best_bid\":\"0.56\", \"best_ask\":\"0.57\"}], \"timestamp\":\"1785211428547\", \"event_type\":\"price_change\"}","received_at":"2026-07-28T04:03:49.934649Z","schema_version":"clob-market-ws.price_change.v1","sequence":null,"server_hash":null,"server_timestamp":"1785211428547","session_id":"2d607381e3054cee91998cdf45a4231c","source":"clob_market_ws"},"received_at":"2026-07-28T04:03:49.934649Z","record_id":"3360ac7325c3559e4f1c51bf410fcd1556e1f929216bc32042bd1767049ccb63","schema_fingerprint":"4aa3821a28b0b7c2400bc59aba4bcc0a76e971dadd19610d3ad38c768e124dc7","schema_version":"edge-lab-recorder.raw.v1","sequence":null,"source":"clob_market_ws"}
{"event_at":"2026-07-28T04:03:48.565000Z","event_fingerprint":"cfe117c16c3462e64b881f71845dbc984214ba084184b1562fe296c58772381b","payload":{"connection_id":"f6725804f86a4c4eb588e4d5ed7db029","event_at":"2026-07-28T04:03:48.565000Z","event_type":"price_change","frame_hash":"2f8a6c7f6e423965143048b253f6c7a24bdcbfba3996873636c14332d999523b","frame_index":0,"kind":"data","monotonic_ns":313412985769875,"payload":{"event_type":"price_change","market":"0xd412ce774cfcf8dc9f71164aac78783978aac7b03871702a3b8a481bd9dc9688","price_changes":[{"asset_id":"107603864457683460275633293642179940881969192120168665300712204232021063124301","best_ask":"0.57","best_bid":"0.56","hash":"cefc1de57b8a1b8fe07207a9eb5e0258489c88f0","price":"0.39","side":"BUY","size":"117.6"},{"asset_id":"96600821790790307414914106093858868634329285205417149685270682748367152458577","best_ask":"0.44","best_bid":"0.43","hash":"7e6115cd7e84a2151e8306f72c110b68c941ad86","price":"0.61","side":"SELL","size":"117.6"}],"timestamp":"1785211428565"},"payload_hash":"b9fa1f8697d3e9bae7ac907058717c9193b3a958853fec30dc7c916473cde56d","raw_frame":"{\"market\":\"0xd412ce774cfcf8dc9f71164aac78783978aac7b03871702a3b8a481bd9dc9688\", \"price_changes\":[{\"asset_id\":\"107603864457683460275633293642179940881969192120168665300712204232021063124301\", \"price\":\"0.39\", \"size\":\"117.6\", \"side\":\"BUY\", \"hash\":\"cefc1de57b8a1b8fe07207a9eb5e0258489c88f0\", \"best_bid\":\"0.56\", \"best_ask\":\"0.57\"}, {\"asset_id\":\"96600821790790307414914106093858868634329285205417149685270682748367152458577\", \"price\":\"0.61\", \"size\":\"117.6\", \"side\":\"SELL\", \"hash\":\"7e6115cd7e84a2151e8306f72c110b68c941ad86\", \"best_bid\":\"0.43\", \"best_ask\":\"0.44\"}], \"timestamp\":\"1785211428565\", \"event_type\":\"price_change\"}","received_at":"2026-07-28T04:03:49.936155Z","schema_version":"clob-market-ws.price_change.v1","sequence":null,"server_hash":null,"server_timestamp":"1785211428565","session_id":"2d607381e3054cee91998cdf45a4231c","source":"clob_market_ws"},"received_at":"2026-07-28T04:03:49.936155Z","record_id":"c4e428afddc7dbb1d4d619879e96ee6b2a7281aa993f8fd6897125f82bd5bff1","schema_fingerprint":"4aa3821a28b0b7c2400bc59aba4bcc0a76e971dadd19610d3ad38c768e124dc7","schema_version":"edge-lab-recorder.raw.v1","sequence":null,"source":"clob_market_ws"}
{"event_at":"2026-07-28T04:03:48.586000Z","event_fingerprint":"702ef46b7f2f35f108d0992b34b3340d89e496ecc42f3d83f0d88c22eb3cba56","payload":{"connection_id":"f6725804f86a4c4eb588e4d5ed7db029","event_at":"2026-07-28T04:03:48.586000Z","event_type":"new_market","frame_hash":"65abe9952125edcc9462f46eb44279010f3f19266b0a0f2657473afe2f57081e","frame_index":0,"kind":"data","monotonic_ns":313413029448166,"payload":{"active":true,"assets_ids":["53004329079419003375328803199780088700867781609538615320117739032143114855809","108972912427823192367080822822148104094501687140817368671495473663472177681473"],"clob_token_ids":["53004329079419003375328803199780088700867781609538615320117739032143114855809","108972912427823192367080822822148104094501687140817368671495473663472177681473"],"condition_id":"0xcdfc8c38ac7d9f06db57ea8aa464323f3f3c6ec2945cd5a9850701c7d4ea1683","description":"In the upcoming EFL Cup (Carabao Cup) game between Rotherham United FC and West Bromwich Albion FC, scheduled for August 8, 2026 at 12:30 PM ET: This market will resolve based on the final score of the Rotherham United FC vs. West Bromwich Albion FC match originally scheduled for August 8, 2026 at 12:30 PM ET, considering only the result at the end of 90 minutes of regulation plus stoppage time; extra time and penalty shoot-outs are excluded. If the actual score is not one of the explicitly listed outcomes, the market resolves to \"Any Other Score.\" If the match is postponed, the market will remain open until it is completed; if it is canceled with no make-up game, the market resolves to \"0-0.\" The primary resolution source for this market is the official statistics of the event as recognized by the governing body or event organizers. However, if the governing body or event organizers have not published final match statistics within 2 hours after the event's conclusion, a consensus of credible reporting may be used instead. All markets will settle based on the official final result as recognized by the governing body or event organizers. Revisions to officially declared final scores made after market resolution will not be accounted for in determining the outcome.","event_message":{"description":"In the upcoming EFL Cup (Carabao Cup) game between Rotherham United FC and West Bromwich Albion FC, scheduled for August 8, 2026 at 12:30 PM ET: This market will resolve based on the final score of the Rotherham United FC vs. West Bromwich Albion FC match originally scheduled for August 8, 2026 at 12:30 PM ET, considering only the result at the end of 90 minutes of regulation plus stoppage time; extra time and penalty shoot-outs are excluded. If the actual score is not one of the explicitly listed outcomes, the market resolves to \"Any Other Score.\" If the match is postponed, the market will remain open until it is completed; if it is canceled with no make-up game, the market resolves to \"0-0.\" The primary resolution source for this market is the official statistics of the event as recognized by the governing body or event organizers. However, if the governing body or event organizers have not published final match statistics within 2 hours after the event's conclusion, a consensus of credible reporting may be used instead. All markets will settle based on the official final result as recognized by the governing body or event organizers. Revisions to officially declared final scores made after market resolution will not be accounted for in determining the outcome.","id":"759599","slug":"efl-rot-wba-2026-08-08-exact-score","ticker":"efl-rot-wba-2026-08-08-exact-score","title":"Rotherham United FC vs. West Bromwich Albion FC - Exact Score"},"event_type":"new_market","fee_schedule":{"exponent":"1","rate":"0.05","rebate_rate":"0.15","taker_only":true},"fees_enabled":true,"game_start_time":"2026-08-08 16:30:00+00","group_item_title":"Rotherham United FC 3 - 2 West Bromwich Albion FC","id":"3147102","line":"","market":"0xcdfc8c38ac7d9f06db57ea8aa464323f3f3c6ec2945cd5a9850701c7d4ea1683","order_price_min_tick_size":"0.01","outcomes":["Yes","No"],"question":"Exact Score: Rotherham United FC 3 - 2 West Bromwich Albion FC?","slug":"efl-rot-wba-2026-08-08-exact-score-3-2","sports_market_type":"soccer_exact_score","tags":[],"taker_base_fee":"1000","timestamp":"1785211428586"},"payload_hash":"adb4826e5929dc89d0ab2fb70b736df51fc08eccd74570864eba3df2fa91496c","raw_frame":"{\"id\":\"3147102\", \"question\":\"Exact Score: Rotherham United FC 3 - 2 West Bromwich Albion FC?\", \"market\":\"0xcdfc8c38ac7d9f06db57ea8aa464323f3f3c6ec2945cd5a9850701c7d4ea1683\", \"slug\":\"efl-rot-wba-2026-08-08-exact-score-3-2\", \"description\":\"In the upcoming EFL Cup (Carabao Cup) game between Rotherham United FC and West Bromwich Albion FC, scheduled for August 8, 2026 at 12:30 PM ET: This market will resolve based on the final score of the Rotherham United FC vs. West Bromwich Albion FC match originally scheduled for August 8, 2026 at 12:30 PM ET, considering only the result at the end of 90 minutes of regulation plus stoppage time; extra time and penalty shoot-outs are excluded. If the actual score is not one of the explicitly listed outcomes, the market resolves to \\\"Any Other Score.\\\" If the match is postponed, the market will remain open until it is completed; if it is canceled with no make-up game, the market resolves to \\\"0-0.\\\" The primary resolution source for this market is the official statistics of the event as recognized by the governing body or event organizers. However, if the governing body or event organizers have not published final match statistics within 2 hours after the event's conclusion, a consensus of credible reporting may be used instead. All markets will settle based on the official final result as recognized by the governing body or event organizers. Revisions to officially declared final scores made after market resolution will not be accounted for in determining the outcome.\", \"assets_ids\":[\"53004329079419003375328803199780088700867781609538615320117739032143114855809\", \"108972912427823192367080822822148104094501687140817368671495473663472177681473\"], \"outcomes\":[\"Yes\", \"No\"], \"event_message\":{\"id\":\"759599\", \"ticker\":\"efl-rot-wba-2026-08-08-exact-score\", \"slug\":\"efl-rot-wba-2026-08-08-exact-score\", \"title\":\"Rotherham United FC vs. West Bromwich Albion FC - Exact Score\", \"description\":\"In the upcoming EFL Cup (Carabao Cup) game between Rotherham United FC and West Bromwich Albion FC, scheduled for August 8, 2026 at 12:30 PM ET: This market will resolve based on the final score of the Rotherham United FC vs. West Bromwich Albion FC match originally scheduled for August 8, 2026 at 12:30 PM ET, considering only the result at the end of 90 minutes of regulation plus stoppage time; extra time and penalty shoot-outs are excluded. If the actual score is not one of the explicitly listed outcomes, the market resolves to \\\"Any Other Score.\\\" If the match is postponed, the market will remain open until it is completed; if it is canceled with no make-up game, the market resolves to \\\"0-0.\\\" The primary resolution source for this market is the official statistics of the event as recognized by the governing body or event organizers. However, if the governing body or event organizers have not published final match statistics within 2 hours after the event's conclusion, a consensus of credible reporting may be used instead. All markets will settle based on the official final result as recognized by the governing body or event organizers. Revisions to officially declared final scores made after market resolution will not be accounted for in determining the outcome.\"}, \"timestamp\":\"1785211428586\", \"event_type\":\"new_market\", \"tags\":[], \"condition_id\":\"0xcdfc8c38ac7d9f06db57ea8aa464323f3f3c6ec2945cd5a9850701c7d4ea1683\", \"active\":true, \"clob_token_ids\":[\"53004329079419003375328803199780088700867781609538615320117739032143114855809\", \"108972912427823192367080822822148104094501687140817368671495473663472177681473\"], \"sports_market_type\":\"soccer_exact_score\", \"line\":\"\", \"game_start_time\":\"2026-08-08 16:30:00+00\", \"order_price_min_tick_size\":\"0.01\", \"group_item_title\":\"Rotherham United FC 3 - 2 West Bromwich Albion FC\", \"taker_base_fee\":\"1000\", \"fees_enabled\":true, \"fee_schedule\":{\"exponent\":\"1\", \"rate\":\"0.05\", \"taker_only\":true, \"rebate_rate\":\"0.15\"}}","received_at":"2026-07-28T04:03:49.979832Z","schema_version":"clob-market-ws.new_market.v1","sequence":null,"server_hash":null,"server_timestamp":"1785211428586","session_id":"2d607381e3054cee91998cdf45a4231c","source":"clob_market_ws"},"received_at":"2026-07-28T04:03:49.979832Z","record_id":"b32733a2a63c3627af32db2134cb6fc834ae5799b27e4ee358399ecf1ee7d4f2","schema_fingerprint":"6639a822a7b79cfa4c3fc0044066e4f66ba8611f5bf361772bd6902a2319b82d","schema_version":"edge-lab-recorder.raw.v1","sequence":null,"source":"clob_market_ws"}
{"event_at":"2026-07-28T04:03:48.591000Z","event_fingerprint":"a4366216df1dfc9f9fee40023575326ccef43635e9aa565868ec66173976b2e0","payload":{"connection_id":"f6725804f86a4c4eb588e4d5ed7db029","event_at":"2026-07-28T04:03:48.591000Z","event_type":"new_market","frame_hash":"223fee38b9751d63c6f5ca480e838dd54bf97d373fcec2a574b62809038ee426","frame_index":0,"kind":"data","monotonic_ns":313413032186500,"payload":{"active":true,"assets_ids":["35241583862777818657622241161748082434086695599775243462821592824010736497193","95694728915590065333971268876467437105913039866752661912155284472112627779231"],"clob_token_ids":["35241583862777818657622241161748082434086695599775243462821592824010736497193","95694728915590065333971268876467437105913039866752661912155284472112627779231"],"condition_id":"0x31b5ff67dbfdc3d937df3d3191d677fd5597a3251d2e5007a140417492c79101","description":"In the upcoming game, scheduled for August 9, 2026 If Sheffield United FC wins within the first 45 minutes of regular play plus stoppage time, this market will resolve to \"Yes\". Otherwise, this market will resolve to \"No\". If the game is postponed, this market will remain open until the game has been completed. If the game is canceled entirely, with no make-up game, this market will resolve \"No\". This market refers only to the outcome within the first 45 minutes of regular play plus stoppage time.The primary resolution source for this market is the official statistics of the event as recognized by the governing body or event organizers. However, if the governing body or event organizers have not published final match statistics within 24 hours after the event's conclusion, a consensus of credible reporting may be used instead. All markets will settle based on the official final result as recognized by the governing body or event organizers. Revisions to officially declared final scores made after market resolution will not be accounted for in determining the outcome.","event_message":{"description":"In the upcoming EFL Cup (Carabao Cup) game between Mansfield Town FC and Sheffield United FC, scheduled for August 9, 2026 at 11:00 AM ET: This event contains halftime result markets for home, draw, and away outcomes within the first 45 minutes of regular play plus stoppage time.","id":"759605","slug":"efl-man-she-2026-08-09-halftime-result","ticker":"efl-man-she-2026-08-09-halftime-result","title":"Mansfield Town FC vs. Sheffield United FC - Halftime Result"},"event_type":"new_market","fee_schedule":{"exponent":"1","rate":"0.05","rebate_rate":"0.15","taker_only":true},"fees_enabled":true,"game_start_time":"2026-08-09 15:00:00+00","group_item_title":"Sheffield United FC","id":"3147136","line":"","market":"0x31b5ff67dbfdc3d937df3d3191d677fd5597a3251d2e5007a140417492c79101","order_price_min_tick_size":"0.01","outcomes":["Yes","No"],"question":"Sheffield United FC leading at halftime?","slug":"efl-man-she-2026-08-09-halftime-result-away","sports_market_type":"soccer_halftime_result","tags":[],"taker_base_fee":"1000","timestamp":"1785211428591"},"payload_hash":"6b38fc7633f6205c8f4e1bf1e769f9498a4ad38ac5644d0518c7d1ff02e95351","raw_frame":"{\"id\":\"3147136\", \"question\":\"Sheffield United FC leading at halftime?\", \"market\":\"0x31b5ff67dbfdc3d937df3d3191d677fd5597a3251d2e5007a140417492c79101\", \"slug\":\"efl-man-she-2026-08-09-halftime-result-away\", \"description\":\"In the upcoming game, scheduled for August 9, 2026 If Sheffield United FC wins within the first 45 minutes of regular play plus stoppage time, this market will resolve to \\\"Yes\\\". Otherwise, this market will resolve to \\\"No\\\". If the game is postponed, this market will remain open until the game has been completed. If the game is canceled entirely, with no make-up game, this market will resolve \\\"No\\\". This market refers only to the outcome within the first 45 minutes of regular play plus stoppage time.The primary resolution source for this market is the official statistics of the event as recognized by the governing body or event organizers. However, if the governing body or event organizers have not published final match statistics within 24 hours after the event's conclusion, a consensus of credible reporting may be used instead. All markets will settle based on the official final result as recognized by the governing body or event organizers. Revisions to officially declared final scores made after market resolution will not be accounted for in determining the outcome.\", \"assets_ids\":[\"35241583862777818657622241161748082434086695599775243462821592824010736497193\", \"95694728915590065333971268876467437105913039866752661912155284472112627779231\"], \"outcomes\":[\"Yes\", \"No\"], \"event_message\":{\"id\":\"759605\", \"ticker\":\"efl-man-she-2026-08-09-halftime-result\", \"slug\":\"efl-man-she-2026-08-09-halftime-result\", \"title\":\"Mansfield Town FC vs. Sheffield United FC - Halftime Result\", \"description\":\"In the upcoming EFL Cup (Carabao Cup) game between Mansfield Town FC and Sheffield United FC, scheduled for August 9, 2026 at 11:00 AM ET: This event contains halftime result markets for home, draw, and away outcomes within the first 45 minutes of regular play plus stoppage time.\"}, \"timestamp\":\"1785211428591\", \"event_type\":\"new_market\", \"tags\":[], \"condition_id\":\"0x31b5ff67dbfdc3d937df3d3191d677fd5597a3251d2e5007a140417492c79101\", \"active\":true, \"clob_token_ids\":[\"35241583862777818657622241161748082434086695599775243462821592824010736497193\", \"95694728915590065333971268876467437105913039866752661912155284472112627779231\"], \"sports_market_type\":\"soccer_halftime_result\", \"line\":\"\", \"game_start_time\":\"2026-08-09 15:00:00+00\", \"order_price_min_tick_size\":\"0.01\", \"group_item_title\":\"Sheffield United FC\", \"taker_base_fee\":\"1000\", \"fees_enabled\":true, \"fee_schedule\":{\"exponent\":\"1\", \"rate\":\"0.05\", \"taker_only\":true, \"rebate_rate\":\"0.15\"}}","received_at":"2026-07-28T04:03:49.982569Z","schema_version":"clob-market-ws.new_market.v1","sequence":null,"server_hash":null,"server_timestamp":"1785211428591","session_id":"2d607381e3054cee91998cdf45a4231c","source":"clob_market_ws"},"received_at":"2026-07-28T04:03:49.982569Z","record_id":"7f07810c0ff614ecffde14ad9de99f38a3d4ddbd62d12d70658e5a29a6e19202","schema_fingerprint":"6639a822a7b79cfa4c3fc0044066e4f66ba8611f5bf361772bd6902a2319b82d","schema_version":"edge-lab-recorder.raw.v1","sequence":null,"source":"clob_market_ws"}
{"event_at":"2026-07-28T04:03:48.589000Z","event_fingerprint":"f18ab4e7bb4d239832e90cecbad8ff140bccdcd0710656a5613f5c3e5b13bb1b","payload":{"connection_id":"f6725804f86a4c4eb588e4d5ed7db029","event_at":"2026-07-28T04:03:48.589000Z","event_type":"new_market","frame_hash":"bf174c0082aa1127de0129198d74990c7c097b1c2843f298ad93ddbb481ce205","frame_index":0,"kind":"data","monotonic_ns":313413082012333,"payload":{"active":true,"assets_ids":["62749665985312216742895444033653986119844754352898358211821672617886867347954","81714469218829113867214398108138159866051765343904364570872860917084296677324"],"clob_token_ids":["62749665985312216742895444033653986119844754352898358211821672617886867347954","81714469218829113867214398108138159866051765343904364570872860917084296677324"],"condition_id":"0xb9059c844e2b84bded209811c76368390731d42d4c677ede2863d73a5740cb9d","description":"In the upcoming EFL Cup (Carabao Cup) game between Rotherham United FC and West Bromwich Albion FC, scheduled for August 8, 2026 at 12:30 PM ET: This market will resolve based on the final score of the Rotherham United FC vs. West Bromwich Albion FC match originally scheduled for August 8, 2026 at 12:30 PM ET, considering only the result at the end of 90 minutes of regulation plus stoppage time; extra time and penalty shoot-outs are excluded. If the actual score is not one of the explicitly listed outcomes, the market resolves to \"Any Other Score.\" If the match is postponed, the market will remain open until it is completed; if it is canceled with no make-up game, the market resolves to \"0-0.\" The primary resolution source for this market is the official statistics of the event as recognized by the governing body or event organizers. However, if the governing body or event organizers have not published final match statistics within 2 hours after the event's conclusion, a consensus of credible reporting may be used instead. All markets will settle based on the official final result as recognized by the governing body or event organizers. Revisions to officially declared final scores made after market resolution will not be accounted for in determining the outcome.","event_message":{"description":"In the upcoming EFL Cup (Carabao Cup) game between Rotherham United FC and West Bromwich Albion FC, scheduled for August 8, 2026 at 12:30 PM ET: This market will resolve based on the final score of the Rotherham United FC vs. West Bromwich Albion FC match originally scheduled for August 8, 2026 at 12:30 PM ET, considering only the result at the end of 90 minutes of regulation plus stoppage time; extra time and penalty shoot-outs are excluded. If the actual score is not one of the explicitly listed outcomes, the market resolves to \"Any Other Score.\" If the match is postponed, the market will remain open until it is completed; if it is canceled with no make-up game, the market resolves to \"0-0.\" The primary resolution source for this market is the official statistics of the event as recognized by the governing body or event organizers. However, if the governing body or event organizers have not published final match statistics within 2 hours after the event's conclusion, a consensus of credible reporting may be used instead. All markets will settle based on the official final result as recognized by the governing body or event organizers. Revisions to officially declared final scores made after market resolution will not be accounted for in determining the outcome.","id":"759599","slug":"efl-rot-wba-2026-08-08-exact-score","ticker":"efl-rot-wba-2026-08-08-exact-score","title":"Rotherham United FC vs. West Bromwich Albion FC - Exact Score"},"event_type":"new_market","fee_schedule":{"exponent":"1","rate":"0.05","rebate_rate":"0.15","taker_only":true},"fees_enabled":true,"game_start_time":"2026-08-08 16:30:00+00","group_item_title":"Rotherham United FC 0 - 1 West Bromwich Albion FC","id":"3147089","line":"","market":"0xb9059c844e2b84bded209811c76368390731d42d4c677ede2863d73a5740cb9d","order_price_min_tick_size":"0.01","outcomes":["Yes","No"],"question":"Exact Score: Rotherham United FC 0 - 1 West Bromwich Albion FC?","slug":"efl-rot-wba-2026-08-08-exact-score-0-1","sports_market_type":"soccer_exact_score","tags":[],"taker_base_fee":"1000","timestamp":"1785211428589"},"payload_hash":"a308fc0f52789fb707644b9b2288ed8c7e21dc25331f07c98a7a0caf795b2ce7","raw_frame":"{\"id\":\"3147089\", \"question\":\"Exact Score: Rotherham United FC 0 - 1 West Bromwich Albion FC?\", \"market\":\"0xb9059c844e2b84bded209811c76368390731d42d4c677ede2863d73a5740cb9d\", \"slug\":\"efl-rot-wba-2026-08-08-exact-score-0-1\", \"description\":\"In the upcoming EFL Cup (Carabao Cup) game between Rotherham United FC and West Bromwich Albion FC, scheduled for August 8, 2026 at 12:30 PM ET: This market will resolve based on the final score of the Rotherham United FC vs. West Bromwich Albion FC match originally scheduled for August 8, 2026 at 12:30 PM ET, considering only the result at the end of 90 minutes of regulation plus stoppage time; extra time and penalty shoot-outs are excluded. If the actual score is not one of the explicitly listed outcomes, the market resolves to \\\"Any Other Score.\\\" If the match is postponed, the market will remain open until it is completed; if it is canceled with no make-up game, the market resolves to \\\"0-0.\\\" The primary resolution source for this market is the official statistics of the event as recognized by the governing body or event organizers. However, if the governing body or event organizers have not published final match statistics within 2 hours after the event's conclusion, a consensus of credible reporting may be used instead. All markets will settle based on the official final result as recognized by the governing body or event organizers. Revisions to officially declared final scores made after market resolution will not be accounted for in determining the outcome.\", \"assets_ids\":[\"62749665985312216742895444033653986119844754352898358211821672617886867347954\", \"81714469218829113867214398108138159866051765343904364570872860917084296677324\"], \"outcomes\":[\"Yes\", \"No\"], \"event_message\":{\"id\":\"759599\", \"ticker\":\"efl-rot-wba-2026-08-08-exact-score\", \"slug\":\"efl-rot-wba-2026-08-08-exact-score\", \"title\":\"Rotherham United FC vs. West Bromwich Albion FC - Exact Score\", \"description\":\"In the upcoming EFL Cup (Carabao Cup) game between Rotherham United FC and West Bromwich Albion FC, scheduled for August 8, 2026 at 12:30 PM ET: This market will resolve based on the final score of the Rotherham United FC vs. West Bromwich Albion FC match originally scheduled for August 8, 2026 at 12:30 PM ET, considering only the result at the end of 90 minutes of regulation plus stoppage time; extra time and penalty shoot-outs are excluded. If the actual score is not one of the explicitly listed outcomes, the market resolves to \\\"Any Other Score.\\\" If the match is postponed, the market will remain open until it is completed; if it is canceled with no make-up game, the market resolves to \\\"0-0.\\\" The primary resolution source for this market is the official statistics of the event as recognized by the governing body or event organizers. However, if the governing body or event organizers have not published final match statistics within 2 hours after the event's conclusion, a consensus of credible reporting may be used instead. All markets will settle based on the official final result as recognized by the governing body or event organizers. Revisions to officially declared final scores made after market resolution will not be accounted for in determining the outcome.\"}, \"timestamp\":\"1785211428589\", \"event_type\":\"new_market\", \"tags\":[], \"condition_id\":\"0xb9059c844e2b84bded209811c76368390731d42d4c677ede2863d73a5740cb9d\", \"active\":true, \"clob_token_ids\":[\"62749665985312216742895444033653986119844754352898358211821672617886867347954\", \"81714469218829113867214398108138159866051765343904364570872860917084296677324\"], \"sports_market_type\":\"soccer_exact_score\", \"line\":\"\", \"game_start_time\":\"2026-08-08 16:30:00+00\", \"order_price_min_tick_size\":\"0.01\", \"group_item_title\":\"Rotherham United FC 0 - 1 West Bromwich Albion FC\", \"taker_base_fee\":\"1000\", \"fees_enabled\":true, \"fee_schedule\":{\"exponent\":\"1\", \"rate\":\"0.05\", \"taker_only\":true, \"rebate_rate\":\"0.15\"}}","received_at":"2026-07-28T04:03:50.032393Z","schema_version":"clob-market-ws.new_market.v1","sequence":null,"server_hash":null,"server_timestamp":"1785211428589","session_id":"2d607381e3054cee91998cdf45a4231c","source":"clob_market_ws"},"received_at":"2026-07-28T04:03:50.032393Z","record_id":"20f22dc38669bb8385b91ac866556ab9ceb5b30f5ecd2f9917f0c3457b234f74","schema_fingerprint":"6639a822a7b79cfa4c3fc0044066e4f66ba8611f5bf361772bd6902a2319b82d","schema_version":"edge-lab-recorder.raw.v1","sequence":null,"source":"clob_market_ws"}
{"event_at":"2026-07-28T04:03:48.593000Z","event_fingerprint":"cf5e6dd951b47da809bb173ed176e64b926e3fd1a0014dff0c14d2220e177007","payload":{"connection_id":"f6725804f86a4c4eb588e4d5ed7db029","event_at":"2026-07-28T04:03:48.593000Z","event_type":"new_market","frame_hash":"5367459b45301fe05edf7f331cd505a443f4a8a574f02f59d51a9f8f9ee120bc","frame_index":0,"kind":"data","monotonic_ns":313413104506750,"payload":{"active":true,"assets_ids":["28022583307818095099733769192476074130386191845006698433640515135835751514525","2286417164681021563642105271252594139953251956186952489155478710341852006797"],"clob_token_ids":["28022583307818095099733769192476074130386191845006698433640515135835751514525","2286417164681021563642105271252594139953251956186952489155478710341852006797"],"condition_id":"0x7711560dd85141cc5504087c9333b8a816163335db0b3f156ef372767effadd3","description":"In the upcoming game, scheduled for August 9, 2026 If Mansfield Town FC wins within the first 45 minutes of regular play plus stoppage time, this market will resolve to \"Yes\". Otherwise, this market will resolve to \"No\". If the game is postponed, this market will remain open until the game has been completed. If the game is canceled entirely, with no make-up game, this market will resolve \"No\". This market refers only to the outcome within the first 45 minutes of regular play plus stoppage time.The primary resolution source for this market is the official statistics of the event as recognized by the governing body or event organizers. However, if the governing body or event organizers have not published final match statistics within 24 hours after the event's conclusion, a consensus of credible reporting may be used instead. All markets will settle based on the official final result as recognized by the governing body or event organizers. Revisions to officially declared final scores made after market resolution will not be accounted for in determining the outcome.","event_message":{"description":"In the upcoming EFL Cup (Carabao Cup) game between Mansfield Town FC and Sheffield United FC, scheduled for August 9, 2026 at 11:00 AM ET: This event contains halftime result markets for home, draw, and away outcomes within the first 45 minutes of regular play plus stoppage time.","id":"759605","slug":"efl-man-she-2026-08-09-halftime-result","ticker":"efl-man-she-2026-08-09-halftime-result","title":"Mansfield Town FC vs. Sheffield United FC - Halftime Result"},"event_type":"new_market","fee_schedule":{"exponent":"1","rate":"0.05","rebate_rate":"0.15","taker_only":true},"fees_enabled":true,"game_start_time":"2026-08-09 15:00:00+00","group_item_title":"Mansfield Town FC","id":"3147134","line":"","market":"0x7711560dd85141cc5504087c9333b8a816163335db0b3f156ef372767effadd3","order_price_min_tick_size":"0.01","outcomes":["Yes","No"],"question":"Mansfield Town FC leading at halftime?","slug":"efl-man-she-2026-08-09-halftime-result-home","sports_market_type":"soccer_halftime_result","tags":[],"taker_base_fee":"1000","timestamp":"1785211428593"},"payload_hash":"b52e61d33be40c929f4f8f6d70233e0b2de54653096b8a5a235e914e143271e2","raw_frame":"{\"id\":\"3147134\", \"question\":\"Mansfield Town FC leading at halftime?\", \"market\":\"0x7711560dd85141cc5504087c9333b8a816163335db0b3f156ef372767effadd3\", \"slug\":\"efl-man-she-2026-08-09-halftime-result-home\", \"description\":\"In the upcoming game, scheduled for August 9, 2026 If Mansfield Town FC wins within the first 45 minutes of regular play plus stoppage time, this market will resolve to \\\"Yes\\\". Otherwise, this market will resolve to \\\"No\\\". If the game is postponed, this market will remain open until the game has been completed. If the game is canceled entirely, with no make-up game, this market will resolve \\\"No\\\". This market refers only to the outcome within the first 45 minutes of regular play plus stoppage time.The primary resolution source for this market is the official statistics of the event as recognized by the governing body or event organizers. However, if the governing body or event organizers have not published final match statistics within 24 hours after the event's conclusion, a consensus of credible reporting may be used instead. All markets will settle based on the official final result as recognized by the governing body or event organizers. Revisions to officially declared final scores made after market resolution will not be accounted for in determining the outcome.\", \"assets_ids\":[\"28022583307818095099733769192476074130386191845006698433640515135835751514525\", \"2286417164681021563642105271252594139953251956186952489155478710341852006797\"], \"outcomes\":[\"Yes\", \"No\"], \"event_message\":{\"id\":\"759605\", \"ticker\":\"efl-man-she-2026-08-09-halftime-result\", \"slug\":\"efl-man-she-2026-08-09-halftime-result\", \"title\":\"Mansfield Town FC vs. Sheffield United FC - Halftime Result\", \"description\":\"In the upcoming EFL Cup (Carabao Cup) game between Mansfield Town FC and Sheffield United FC, scheduled for August 9, 2026 at 11:00 AM ET: This event contains halftime result markets for home, draw, and away outcomes within the first 45 minutes of regular play plus stoppage time.\"}, \"timestamp\":\"1785211428593\", \"event_type\":\"new_market\", \"tags\":[], \"condition_id\":\"0x7711560dd85141cc5504087c9333b8a816163335db0b3f156ef372767effadd3\", \"active\":true, \"clob_token_ids\":[\"28022583307818095099733769192476074130386191845006698433640515135835751514525\", \"2286417164681021563642105271252594139953251956186952489155478710341852006797\"], \"sports_market_type\":\"soccer_halftime_result\", \"line\":\"\", \"game_start_time\":\"2026-08-09 15:00:00+00\", \"order_price_min_tick_size\":\"0.01\", \"group_item_title\":\"Mansfield Town FC\", \"taker_base_fee\":\"1000\", \"fees_enabled\":true, \"fee_schedule\":{\"exponent\":\"1\", \"rate\":\"0.05\", \"taker_only\":true, \"rebate_rate\":\"0.15\"}}","received_at":"2026-07-28T04:03:50.054888Z","schema_version":"clob-market-ws.new_market.v1","sequence":null,"server_hash":null,"server_timestamp":"1785211428593","session_id":"2d607381e3054cee91998cdf45a4231c","source":"clob_market_ws"},"received_at":"2026-07-28T04:03:50.054888Z","record_id":"df639f8d5f7fba45a24dd4d15aafe8dfdfecdfb0778084a953fa818aef1905b7","schema_fingerprint":"6639a822a7b79cfa4c3fc0044066e4f66ba8611f5bf361772bd6902a2319b82d","schema_version":"edge-lab-recorder.raw.v1","sequence":null,"source":"clob_market_ws"}
{"event_at":"2026-07-28T04:03:48.603000Z","event_fingerprint":"89e961bef9c5d1b4e5fb8c9e8bc34a47ebd6e43fbb52933d3cfb8572128f6671","payload":{"connection_id":"f6725804f86a4c4eb588e4d5ed7db029","event_at":"2026-07-28T04:03:48.603000Z","event_type":"new_market","frame_hash":"808b64fe71b3396e1514867bd5df80cdf404f038de6357681219a26891debad3","frame_index":0,"kind":"data","monotonic_ns":313413170637875,"payload":{"active":true,"assets_ids":["23962362498861493850060198014056885464453954107435714255762712805010678708990","17536202167826615398114428633116992937232495171326410024923621850357849915605"],"clob_token_ids":["23962362498861493850060198014056885464453954107435714255762712805010678708990","17536202167826615398114428633116992937232495171326410024923621850357849915605"],"condition_id":"0x26f9597a391b409f260e866733d9d4c809eccbcd40cf79cf02de301979263b19","description":"In the upcoming EFL Cup (Carabao Cup) game between Rotherham United FC and West Bromwich Albion FC, scheduled for August 8, 2026 at 12:30 PM ET: This market will resolve based on the final score of the Rotherham United FC vs. West Bromwich Albion FC match originally scheduled for August 8, 2026 at 12:30 PM ET, considering only the result at the end of 90 minutes of regulation plus stoppage time; extra time and penalty shoot-outs are excluded. If the actual score is not one of the explicitly listed outcomes, the market resolves to \"Any Other Score.\" If the match is postponed, the market will remain open until it is completed; if it is canceled with no make-up game, the market resolves to \"0-0.\" The primary resolution source for this market is the official statistics of the event as recognized by the governing body or event organizers. However, if the governing body or event organizers have not published final match statistics within 2 hours after the event's conclusion, a consensus of credible reporting may be used instead. All markets will settle based on the official final result as recognized by the governing body or event organizers. Revisions to officially declared final scores made after market resolution will not be accounted for in determining the outcome.","event_message":{"description":"In the upcoming EFL Cup (Carabao Cup) game between Rotherham United FC and West Bromwich Albion FC, scheduled for August 8, 2026 at 12:30 PM ET: This market will resolve based on the final score of the Rotherham United FC vs. West Bromwich Albion FC match originally scheduled for August 8, 2026 at 12:30 PM ET, considering only the result at the end of 90 minutes of regulation plus stoppage time; extra time and penalty shoot-outs are excluded. If the actual score is not one of the explicitly listed outcomes, the market resolves to \"Any Other Score.\" If the match is postponed, the market will remain open until it is completed; if it is canceled with no make-up game, the market resolves to \"0-0.\" The primary resolution source for this market is the official statistics of the event as recognized by the governing body or event organizers. However, if the governing body or event organizers have not published final match statistics within 2 hours after the event's conclusion, a consensus of credible reporting may be used instead. All markets will settle based on the official final result as recognized by the governing body or event organizers. Revisions to officially declared final scores made after market resolution will not be accounted for in determining the outcome.","id":"759599","slug":"efl-rot-wba-2026-08-08-exact-score","ticker":"efl-rot-wba-2026-08-08-exact-score","title":"Rotherham United FC vs. West Bromwich Albion FC - Exact Score"},"event_type":"new_market","fee_schedule":{"exponent":"1","rate":"0.05","rebate_rate":"0.15","taker_only":true},"fees_enabled":true,"game_start_time":"2026-08-08 16:30:00+00","group_item_title":"Any Other Score","id":"3147104","line":"","market":"0x26f9597a391b409f260e866733d9d4c809eccbcd40cf79cf02de301979263b19","order_price_min_tick_size":"0.01","outcomes":["Yes","No"],"question":"Exact Score: Any Other Score?","slug":"efl-rot-wba-2026-08-08-exact-score-any-other","sports_market_type":"soccer_exact_score","tags":[],"taker_base_fee":"1000","timestamp":"1785211428603"},"payload_hash":"50bab4201718b7cd0cee7c2931cf16bb5d97764fc04ab22244198072b42395c7","raw_frame":"{\"id\":\"3147104\", \"question\":\"Exact Score: Any Other Score?\", \"market\":\"0x26f9597a391b409f260e866733d9d4c809eccbcd40cf79cf02de301979263b19\", \"slug\":\"efl-rot-wba-2026-08-08-exact-score-any-other\", \"description\":\"In the upcoming EFL Cup (Carabao Cup) game between Rotherham United FC and West Bromwich Albion FC, scheduled for August 8, 2026 at 12:30 PM ET: This market will resolve based on the final score of the Rotherham United FC vs. West Bromwich Albion FC match originally scheduled for August 8, 2026 at 12:30 PM ET, considering only the result at the end of 90 minutes of regulation plus stoppage time; extra time and penalty shoot-outs are excluded. If the actual score is not one of the explicitly listed outcomes, the market resolves to \\\"Any Other Score.\\\" If the match is postponed, the market will remain open until it is completed; if it is canceled with no make-up game, the market resolves to \\\"0-0.\\\" The primary resolution source for this market is the official statistics of the event as recognized by the governing body or event organizers. However, if the governing body or event organizers have not published final match statistics within 2 hours after the event's conclusion, a consensus of credible reporting may be used instead. All markets will settle based on the official final result as recognized by the governing body or event organizers. Revisions to officially declared final scores made after market resolution will not be accounted for in determining the outcome.\", \"assets_ids\":[\"23962362498861493850060198014056885464453954107435714255762712805010678708990\", \"17536202167826615398114428633116992937232495171326410024923621850357849915605\"], \"outcomes\":[\"Yes\", \"No\"], \"event_message\":{\"id\":\"759599\", \"ticker\":\"efl-rot-wba-2026-08-08-exact-score\", \"slug\":\"efl-rot-wba-2026-08-08-exact-score\", \"title\":\"Rotherham United FC vs. West Bromwich Albion FC - Exact Score\", \"description\":\"In the upcoming EFL Cup (Carabao Cup) game between Rotherham United FC and West Bromwich Albion FC, scheduled for August 8, 2026 at 12:30 PM ET: This market will resolve based on the final score of the Rotherham United FC vs. West Bromwich Albion FC match originally scheduled for August 8, 2026 at 12:30 PM ET, considering only the result at the end of 90 minutes of regulation plus stoppage time; extra time and penalty shoot-outs are excluded. If the actual score is not one of the explicitly listed outcomes, the market resolves to \\\"Any Other Score.\\\" If the match is postponed, the market will remain open until it is completed; if it is canceled with no make-up game, the market resolves to \\\"0-0.\\\" The primary resolution source for this market is the official statistics of the event as recognized by the governing body or event organizers. However, if the governing body or event organizers have not published final match statistics within 2 hours after the event's conclusion, a consensus of credible reporting may be used instead. All markets will settle based on the official final result as recognized by the governing body or event organizers. Revisions to officially declared final scores made after market resolution will not be accounted for in determining the outcome.\"}, \"timestamp\":\"1785211428603\", \"event_type\":\"new_market\", \"tags\":[], \"condition_id\":\"0x26f9597a391b409f260e866733d9d4c809eccbcd40cf79cf02de301979263b19\", \"active\":true, \"clob_token_ids\":[\"23962362498861493850060198014056885464453954107435714255762712805010678708990\", \"17536202167826615398114428633116992937232495171326410024923621850357849915605\"], \"sports_market_type\":\"soccer_exact_score\", \"line\":\"\", \"game_start_time\":\"2026-08-08 16:30:00+00\", \"order_price_min_tick_size\":\"0.01\", \"group_item_title\":\"Any Other Score\", \"taker_base_fee\":\"1000\", \"fees_enabled\":true, \"fee_schedule\":{\"exponent\":\"1\", \"rate\":\"0.05\", \"taker_only\":true, \"rebate_rate\":\"0.15\"}}","received_at":"2026-07-28T04:03:50.121020Z","schema_version":"clob-market-ws.new_market.v1","sequence":null,"server_hash":null,"server_timestamp":"1785211428603","session_id":"2d607381e3054cee91998cdf45a4231c","source":"clob_market_ws"},"received_at":"2026-07-28T04:03:50.121020Z","record_id":"9811a8fad3368d84f223709e14dce918741ba3924d2d2381450a92fa4d6d9885","schema_fingerprint":"6639a822a7b79cfa4c3fc0044066e4f66ba8611f5bf361772bd6902a2319b82d","schema_version":"edge-lab-recorder.raw.v1","sequence":null,"source":"clob_market_ws"}
{"event_at":"2026-07-28T04:03:48.596000Z","event_fingerprint":"36979ab497e606998b1a92ce425e551a5491993ab4638b2eebf92a3df2caeeab","payload":{"connection_id":"f6725804f86a4c4eb588e4d5ed7db029","event_at":"2026-07-28T04:03:48.596000Z","event_type":"new_market","frame_hash":"1318706e90c1791ac40ba18a1d1e29c6e37da8264962639eef339ac2c5c2ebff","frame_index":0,"kind":"data","monotonic_ns":313413216849333,"payload":{"active":true,"assets_ids":["27505442371641230600130506553476820363354936248778638510930947702687234892304","42899825713608320406160932368200057745313841560649935843688713713077838473897"],"clob_token_ids":["27505442371641230600130506553476820363354936248778638510930947702687234892304","42899825713608320406160932368200057745313841560649935843688713713077838473897"],"condition_id":"0x4b45c9732b0e8f60adebf1f01d8f1da1bed28cd6e06a7eebb1e554cb26a7e2bd","description":"In the upcoming game, scheduled for August 9, 2026 If the game ends in a draw within the first 45 minutes of regular play plus stoppage time, this market will resolve to \"Yes\". Otherwise, this market will resolve to \"No\". If the game is postponed, this market will remain open until the game has been completed. If the game is canceled entirely, with no make-up game, this market will resolve to \"Yes\". This market refers only to the outcome within the first 45 minutes of regular play plus stoppage time.The primary resolution source for this market is the official statistics of the event as recognized by the governing body or event organizers. However, if the governing body or event organizers have not published final match statistics within 24 hours after the event's conclusion, a consensus of credible reporting may be used instead. All markets will settle based on the official final result as recognized by the governing body or event organizers. Revisions to officially declared final scores made after market resolution will not be accounted for in determining the outcome.","event_message":{"description":"In the upcoming EFL Cup (Carabao Cup) game between Mansfield Town FC and Sheffield United FC, scheduled for August 9, 2026 at 11:00 AM ET: This event contains halftime result markets for home, draw, and away outcomes within the first 45 minutes of regular play plus stoppage time.","id":"759605","slug":"efl-man-she-2026-08-09-halftime-result","ticker":"efl-man-she-2026-08-09-halftime-result","title":"Mansfield Town FC vs. Sheffield United FC - Halftime Result"},"event_type":"new_market","fee_schedule":{"exponent":"1","rate":"0.05","rebate_rate":"0.15","taker_only":true},"fees_enabled":true,"game_start_time":"2026-08-09 15:00:00+00","group_item_title":"Draw","id":"3147135","line":"","market":"0x4b45c9732b0e8f60adebf1f01d8f1da1bed28cd6e06a7eebb1e554cb26a7e2bd","order_price_min_tick_size":"0.01","outcomes":["Yes","No"],"question":"Mansfield Town FC vs. Sheffield United FC: Draw at halftime?","slug":"efl-man-she-2026-08-09-halftime-result-draw","sports_market_type":"soccer_halftime_result","tags":[],"taker_base_fee":"1000","timestamp":"1785211428596"},"payload_hash":"7d05d21984441a8ff5bbd0e0917b72e353fd97f3e64d04dfe62e48f18ffc3b0a","raw_frame":"{\"id\":\"3147135\", \"question\":\"Mansfield Town FC vs. Sheffield United FC: Draw at halftime?\", \"market\":\"0x4b45c9732b0e8f60adebf1f01d8f1da1bed28cd6e06a7eebb1e554cb26a7e2bd\", \"slug\":\"efl-man-she-2026-08-09-halftime-result-draw\", \"description\":\"In the upcoming game, scheduled for August 9, 2026 If the game ends in a draw within the first 45 minutes of regular play plus stoppage time, this market will resolve to \\\"Yes\\\". Otherwise, this market will resolve to \\\"No\\\". If the game is postponed, this market will remain open until the game has been completed. If the game is canceled entirely, with no make-up game, this market will resolve to \\\"Yes\\\". This market refers only to the outcome within the first 45 minutes of regular play plus stoppage time.The primary resolution source for this market is the official statistics of the event as recognized by the governing body or event organizers. However, if the governing body or event organizers have not published final match statistics within 24 hours after the event's conclusion, a consensus of credible reporting may be used instead. All markets will settle based on the official final result as recognized by the governing body or event organizers. Revisions to officially declared final scores made after market resolution will not be accounted for in determining the outcome.\", \"assets_ids\":[\"27505442371641230600130506553476820363354936248778638510930947702687234892304\", \"42899825713608320406160932368200057745313841560649935843688713713077838473897\"], \"outcomes\":[\"Yes\", \"No\"], \"event_message\":{\"id\":\"759605\", \"ticker\":\"efl-man-she-2026-08-09-halftime-result\", \"slug\":\"efl-man-she-2026-08-09-halftime-result\", \"title\":\"Mansfield Town FC vs. Sheffield United FC - Halftime Result\", \"description\":\"In the upcoming EFL Cup (Carabao Cup) game between Mansfield Town FC and Sheffield United FC, scheduled for August 9, 2026 at 11:00 AM ET: This event contains halftime result markets for home, draw, and away outcomes within the first 45 minutes of regular play plus stoppage time.\"}, \"timestamp\":\"1785211428596\", \"event_type\":\"new_market\", \"tags\":[], \"condition_id\":\"0x4b45c9732b0e8f60adebf1f01d8f1da1bed28cd6e06a7eebb1e554cb26a7e2bd\", \"active\":true, \"clob_token_ids\":[\"27505442371641230600130506553476820363354936248778638510930947702687234892304\", \"42899825713608320406160932368200057745313841560649935843688713713077838473897\"], \"sports_market_type\":\"soccer_halftime_result\", \"line\":\"\", \"game_start_time\":\"2026-08-09 15:00:00+00\", \"order_price_min_tick_size\":\"0.01\", \"group_item_title\":\"Draw\", \"taker_base_fee\":\"1000\", \"fees_enabled\":true, \"fee_schedule\":{\"exponent\":\"1\", \"rate\":\"0.05\", \"taker_only\":true, \"rebate_rate\":\"0.15\"}}","received_at":"2026-07-28T04:03:50.167231Z","schema_version":"clob-market-ws.new_market.v1","sequence":null,"server_hash":null,"server_timestamp":"1785211428596","session_id":"2d607381e3054cee91998cdf45a4231c","source":"clob_market_ws"},"received_at":"2026-07-28T04:03:50.167231Z","record_id":"8882d70cf76935cb355c51110f9237fd7845603c60112f06aa8249941a62a1eb","schema_fingerprint":"6639a822a7b79cfa4c3fc0044066e4f66ba8611f5bf361772bd6902a2319b82d","schema_version":"edge-lab-recorder.raw.v1","sequence":null,"source":"clob_market_ws"}
{"event_at":"2026-07-28T04:03:48.606000Z","event_fingerprint":"5a5f9661652405236929aee75fde09a825e973de959a04d8a3e2514c310cbe2a","payload":{"connection_id":"f6725804f86a4c4eb588e4d5ed7db029","event_at":"2026-07-28T04:03:48.606000Z","event_type":"new_market","frame_hash":"1649d3dc584d12ef51b1097cd28c824361db67ae612bc6e09889973e4c355e96","frame_index":0,"kind":"data","monotonic_ns":313413219175000,"payload":{"active":true,"assets_ids":["14373956789021944776089821252671073483692826421256997598797011617708656035785","115062469793525941380364655579183588695318226172912142473872985479807892139624"],"clob_token_ids":["14373956789021944776089821252671073483692826421256997598797011617708656035785","115062469793525941380364655579183588695318226172912142473872985479807892139624"],"condition_id":"0xee167d2633e2ff2c1dd1fda8c827d448296c3b0dd022006fb672ba146b404702","description":"In the upcoming EFL Cup (Carabao Cup) game between Mansfield Town FC and Sheffield United FC, scheduled for August 9, 2026 at 11:00 AM ET: This market will resolve to \"Mansfield Town FC\" if Mansfield Town FC score more goals than Sheffield United FC in the second half of regular play plus second-half stoppage time. This market will resolve to \"Draw\" if Mansfield Town FC and Sheffield United FC score the same number of goals in the second half of regular play plus second-half stoppage time. This market will resolve to \"Sheffield United FC\" if Sheffield United FC score more goals than Mansfield Town FC in the second half of regular play plus second-half stoppage time. If the game is postponed, this market will remain open until the game has been completed. If the game is canceled entirely, with no make-up game, this market will resolve to \"Draw\". This market refers only to the outcome within the second half of regular play plus second-half stoppage time. First-half goals, extra time, and penalty shoot-outs are excluded. The primary resolution source for this market is the official statistics of the event as recognized by the governing body or event organizers. However, if the governing body or event organizers have not published final match statistics within 24 hours after the event's conclusion, a consensus of credible reporting may be used instead. All markets will settle based on the official final result as recognized by the governing body or event organizers. Revisions to officially declared final scores made after market resolution will not be accounted for in determining the outcome.","event_message":{"description":"In the upcoming EFL Cup (Carabao Cup) game between Mansfield Town FC and Sheffield United FC, scheduled for August 9, 2026 at 11:00 AM ET: This market will resolve to \"Mansfield Town FC\" if Mansfield Town FC score more goals than Sheffield United FC in the second half of regular play plus second-half stoppage time. This market will resolve to \"Draw\" if Mansfield Town FC and Sheffield United FC score the same number of goals in the second half of regular play plus second-half stoppage time. This market will resolve to \"Sheffield United FC\" if Sheffield United FC score more goals than Mansfield Town FC in the second half of regular play plus second-half stoppage time. If the game is postponed, this market will remain open until the game has been completed. If the game is canceled entirely, with no make-up game, this market will resolve to \"Draw\". This market refers only to the outcome within the second half of regular play plus second-half stoppage time. First-half goals, extra time, and penalty shoot-outs are excluded. The primary resolution source for this market is the official statistics of the event as recognized by the governing body or event organizers. However, if the governing body or event organizers have not published final match statistics within 24 hours after the event's conclusion, a consensus of credible reporting may be used instead. All markets will settle based on the official final result as recognized by the governing body or event organizers. Revisions to officially declared final scores made after market resolution will not be accounted for in determining the outcome.","id":"759606","slug":"efl-man-she-2026-08-09-second-half-result","ticker":"efl-man-she-2026-08-09-second-half-result","title":"Mansfield Town FC vs. Sheffield United FC - Second Half Result"},"event_type":"new_market","fee_schedule":{"exponent":"1","rate":"0.05","rebate_rate":"0.15","taker_only":true},"fees_enabled":true,"game_start_time":"2026-08-09 15:00:00+00","group_item_title":"Sheffield United FC","id":"3147139","line":"","market":"0xee167d2633e2ff2c1dd1fda8c827d448296c3b0dd022006fb672ba146b404702","order_price_min_tick_size":"0.01","outcomes":["Yes","No"],"question":"Sheffield United FC to win the second half?","slug":"efl-man-she-2026-08-09-second-half-result-away","sports_market_type":"soccer_second_half_result","tags":[],"taker_base_fee":"1000","timestamp":"1785211428606"},"payload_hash":"45a42291f2f27a7b4de1cc5a4a656e1e98962182a25325fbc5299e866d7aba06","raw_frame":"{\"id\":\"3147139\", \"question\":\"Sheffield United FC to win the second half?\", \"market\":\"0xee167d2633e2ff2c1dd1fda8c827d448296c3b0dd022006fb672ba146b404702\", \"slug\":\"efl-man-she-2026-08-09-second-half-result-away\", \"description\":\"In the upcoming EFL Cup (Carabao Cup) game between Mansfield Town FC and Sheffield United FC, scheduled for August 9, 2026 at 11:00 AM ET: This market will resolve to \\\"Mansfield Town FC\\\" if Mansfield Town FC score more goals than Sheffield United FC in the second half of regular play plus second-half stoppage time. This market will resolve to \\\"Draw\\\" if Mansfield Town FC and Sheffield United FC score the same number of goals in the second half of regular play plus second-half stoppage time. This market will resolve to \\\"Sheffield United FC\\\" if Sheffield United FC score more goals than Mansfield Town FC in the second half of regular play plus second-half stoppage time. If the game is postponed, this market will remain open until the game has been completed. If the game is canceled entirely, with no make-up game, this market will resolve to \\\"Draw\\\". This market refers only to the outcome within the second half of regular play plus second-half stoppage time. First-half goals, extra time, and penalty shoot-outs are excluded. The primary resolution source for this market is the official statistics of the event as recognized by the governing body or event organizers. However, if the governing body or event organizers have not published final match statistics within 24 hours after the event's conclusion, a consensus of credible reporting may be used instead. All markets will settle based on the official final result as recognized by the governing body or event organizers. Revisions to officially declared final scores made after market resolution will not be accounted for in determining the outcome.\", \"assets_ids\":[\"14373956789021944776089821252671073483692826421256997598797011617708656035785\", \"115062469793525941380364655579183588695318226172912142473872985479807892139624\"], \"outcomes\":[\"Yes\", \"No\"], \"event_message\":{\"id\":\"759606\", \"ticker\":\"efl-man-she-2026-08-09-second-half-result\", \"slug\":\"efl-man-she-2026-08-09-second-half-result\", \"title\":\"Mansfield Town FC vs. Sheffield United FC - Second Half Result\", \"description\":\"In the upcoming EFL Cup (Carabao Cup) game between Mansfield Town FC and Sheffield United FC, scheduled for August 9, 2026 at 11:00 AM ET: This market will resolve to \\\"Mansfield Town FC\\\" if Mansfield Town FC score more goals than Sheffield United FC in the second half of regular play plus second-half stoppage time. This market will resolve to \\\"Draw\\\" if Mansfield Town FC and Sheffield United FC score the same number of goals in the second half of regular play plus second-half stoppage time. This market will resolve to \\\"Sheffield United FC\\\" if Sheffield United FC score more goals than Mansfield Town FC in the second half of regular play plus second-half stoppage time. If the game is postponed, this market will remain open until the game has been completed. If the game is canceled entirely, with no make-up game, this market will resolve to \\\"Draw\\\". This market refers only to the outcome within the second half of regular play plus second-half stoppage time. First-half goals, extra time, and penalty shoot-outs are excluded. The primary resolution source for this market is the official statistics of the event as recognized by the governing body or event organizers. However, if the governing body or event organizers have not published final match statistics within 24 hours after the event's conclusion, a consensus of credible reporting may be used instead. All markets will settle based on the official final result as recognized by the governing body or event organizers. Revisions to officially declared final scores made after market resolution will not be accounted for in determining the outcome.\"}, \"timestamp\":\"1785211428606\", \"event_type\":\"new_market\", \"tags\":[], \"condition_id\":\"0xee167d2633e2ff2c1dd1fda8c827d448296c3b0dd022006fb672ba146b404702\", \"active\":true, \"clob_token_ids\":[\"14373956789021944776089821252671073483692826421256997598797011617708656035785\", \"115062469793525941380364655579183588695318226172912142473872985479807892139624\"], \"sports_market_type\":\"soccer_second_half_result\", \"line\":\"\", \"game_start_time\":\"2026-08-09 15:00:00+00\", \"order_price_min_tick_size\":\"0.01\", \"group_item_title\":\"Sheffield United FC\", \"taker_base_fee\":\"1000\", \"fees_enabled\":true, \"fee_schedule\":{\"exponent\":\"1\", \"rate\":\"0.05\", \"taker_only\":true, \"rebate_rate\":\"0.15\"}}","received_at":"2026-07-28T04:03:50.169556Z","schema_version":"clob-market-ws.new_market.v1","sequence":null,"server_hash":null,"server_timestamp":"1785211428606","session_id":"2d607381e3054cee91998cdf45a4231c","source":"clob_market_ws"},"received_at":"2026-07-28T04:03:50.169556Z","record_id":"a0e415c9b4a78c2a098591d8ee35f7f301628ab25e34132e9b40b95da55c6661","schema_fingerprint":"6639a822a7b79cfa4c3fc0044066e4f66ba8611f5bf361772bd6902a2319b82d","schema_version":"edge-lab-recorder.raw.v1","sequence":null,"source":"clob_market_ws"}
{"event_at":"2026-07-28T04:03:48.596000Z","event_fingerprint":"9a091e5415a0b79b95b2a09ef42ba47d236daaa628d134f033298533ca7017b0","payload":{"connection_id":"f6725804f86a4c4eb588e4d5ed7db029","event_at":"2026-07-28T04:03:48.596000Z","event_type":"price_change","frame_hash":"cd26710634bd0485abee6269a6b84c9ce0e419ba052b1e40c1493bf4f5df37e0","frame_index":0,"kind":"data","monotonic_ns":313413221165041,"payload":{"event_type":"price_change","market":"0xd412ce774cfcf8dc9f71164aac78783978aac7b03871702a3b8a481bd9dc9688","price_changes":[{"asset_id":"107603864457683460275633293642179940881969192120168665300712204232021063124301","best_ask":"0.57","best_bid":"0.56","hash":"43715b2014e4fe3d326f39af07653c7eb93a682d","price":"0.4","side":"BUY","size":"176.91"},{"asset_id":"96600821790790307414914106093858868634329285205417149685270682748367152458577","best_ask":"0.44","best_bid":"0.43","hash":"eb38604fd4fe5e85969d500d3c7b6a2417cbdec6","price":"0.6","side":"SELL","size":"176.91"}],"timestamp":"1785211428596"},"payload_hash":"ae62bd49b24edd9d09eeadffa895c4116e147622def3fa8e89fd7bd9fc7ddc9e","raw_frame":"{\"market\":\"0xd412ce774cfcf8dc9f71164aac78783978aac7b03871702a3b8a481bd9dc9688\", \"price_changes\":[{\"asset_id\":\"107603864457683460275633293642179940881969192120168665300712204232021063124301\", \"price\":\"0.4\", \"size\":\"176.91\", \"side\":\"BUY\", \"hash\":\"43715b2014e4fe3d326f39af07653c7eb93a682d\", \"best_bid\":\"0.56\", \"best_ask\":\"0.57\"}, {\"asset_id\":\"96600821790790307414914106093858868634329285205417149685270682748367152458577\", \"price\":\"0.6\", \"size\":\"176.91\", \"side\":\"SELL\", \"hash\":\"eb38604fd4fe5e85969d500d3c7b6a2417cbdec6\", \"best_bid\":\"0.43\", \"best_ask\":\"0.44\"}], \"timestamp\":\"1785211428596\", \"event_type\":\"price_change\"}","received_at":"2026-07-28T04:03:50.171546Z","schema_version":"clob-market-ws.price_change.v1","sequence":null,"server_hash":null,"server_timestamp":"1785211428596","session_id":"2d607381e3054cee91998cdf45a4231c","source":"clob_market_ws"},"received_at":"2026-07-28T04:03:50.171546Z","record_id":"04e33ad8ace79a1e5eac61b21cc99deb7cbe06905810ddec3724d9a818a06b3c","schema_fingerprint":"4aa3821a28b0b7c2400bc59aba4bcc0a76e971dadd19610d3ad38c768e124dc7","schema_version":"edge-lab-recorder.raw.v1","sequence":null,"source":"clob_market_ws"}
{"event_at":"2026-07-28T04:03:48.598000Z","event_fingerprint":"b1a987bd8a6817254eb5ff3b2a0a5406305711137784160daa5007cf1a322d47","payload":{"connection_id":"f6725804f86a4c4eb588e4d5ed7db029","event_at":"2026-07-28T04:03:48.598000Z","event_type":"new_market","frame_hash":"0f0085598dbb9ca0cfeab1a0ac310643db948832dfec99f0d04db08c9af21182","frame_index":0,"kind":"data","monotonic_ns":313413270969000,"payload":{"active":true,"assets_ids":["114956620324666124943984668302212854955910589301538227306970159095505577333331","30978804988245623901316404305159626400343342738881175023443885520743528260484"],"clob_token_ids":["114956620324666124943984668302212854955910589301538227306970159095505577333331","30978804988245623901316404305159626400343342738881175023443885520743528260484"],"condition_id":"0xbdeacb3b6ee8503451577f3d58002d43ba1b63a42bac2d3e1eb4392b7f25d241","description":"In the upcoming EFL Cup (Carabao Cup) game between Rotherham United FC and West Bromwich Albion FC, scheduled for August 8, 2026 at 12:30 PM ET: This market will resolve based on the final score of the Rotherham United FC vs. West Bromwich Albion FC match originally scheduled for August 8, 2026 at 12:30 PM ET, considering only the result at the end of 90 minutes of regulation plus stoppage time; extra time and penalty shoot-outs are excluded. If the actual score is not one of the explicitly listed outcomes, the market resolves to \"Any Other Score.\" If the match is postponed, the market will remain open until it is completed; if it is canceled with no make-up game, the market resolves to \"0-0.\" The primary resolution source for this market is the official statistics of the event as recognized by the governing body or event organizers. However, if the governing body or event organizers have not published final match statistics within 2 hours after the event's conclusion, a consensus of credible reporting may be used instead. All markets will settle based on the official final result as recognized by the governing body or event organizers. Revisions to officially declared final scores made after market resolution will not be accounted for in determining the outcome.","event_message":{"description":"In the upcoming EFL Cup (Carabao Cup) game between Rotherham United FC and West Bromwich Albion FC, scheduled for August 8, 2026 at 12:30 PM ET: This market will resolve based on the final score of the Rotherham United FC vs. West Bromwich Albion FC match originally scheduled for August 8, 2026 at 12:30 PM ET, considering only the result at the end of 90 minutes of regulation plus stoppage time; extra time and penalty shoot-outs are excluded. If the actual score is not one of the explicitly listed outcomes, the market resolves to \"Any Other Score.\" If the match is postponed, the market will remain open until it is completed; if it is canceled with no make-up game, the market resolves to \"0-0.\" The primary resolution source for this market is the official statistics of the event as recognized by the governing body or event organizers. However, if the governing body or event organizers have not published final match statistics within 2 hours after the event's conclusion, a consensus of credible reporting may be used instead. All markets will settle based on the official final result as recognized by the governing body or event organizers. Revisions to officially declared final scores made after market resolution will not be accounted for in determining the outcome.","id":"759599","slug":"efl-rot-wba-2026-08-08-exact-score","ticker":"efl-rot-wba-2026-08-08-exact-score","title":"Rotherham United FC vs. West Bromwich Albion FC - Exact Score"},"event_type":"new_market","fee_schedule":{"exponent":"1","rate":"0.05","rebate_rate":"0.15","taker_only":true},"fees_enabled":true,"game_start_time":"2026-08-08 16:30:00+00","group_item_title":"Rotherham United FC 2 - 0 West Bromwich Albion FC","id":"3147093","line":"","market":"0xbdeacb3b6ee8503451577f3d58002d43ba1b63a42bac2d3e1eb4392b7f25d241","order_price_min_tick_size":"0.01","outcomes":["Yes","No"],"question":"Exact Score: Rotherham United FC 2 - 0 West Bromwich Albion FC?","slug":"efl-rot-wba-2026-08-08-exact-score-2-0","sports_market_type":"soccer_exact_score","tags":[],"taker_base_fee":"1000","timestamp":"1785211428598"},"payload_hash":"ac877203df116e2f3d07605d28da93046e37428a19a21d87cce274300ebae5c2","raw_frame":"{\"id\":\"3147093\", \"question\":\"Exact Score: Rotherham United FC 2 - 0 West Bromwich Albion FC?\", \"market\":\"0xbdeacb3b6ee8503451577f3d58002d43ba1b63a42bac2d3e1eb4392b7f25d241\", \"slug\":\"efl-rot-wba-2026-08-08-exact-score-2-0\", \"description\":\"In the upcoming EFL Cup (Carabao Cup) game between Rotherham United FC and West Bromwich Albion FC, scheduled for August 8, 2026 at 12:30 PM ET: This market will resolve based on the final score of the Rotherham United FC vs. West Bromwich Albion FC match originally scheduled for August 8, 2026 at 12:30 PM ET, considering only the result at the end of 90 minutes of regulation plus stoppage time; extra time and penalty shoot-outs are excluded. If the actual score is not one of the explicitly listed outcomes, the market resolves to \\\"Any Other Score.\\\" If the match is postponed, the market will remain open until it is completed; if it is canceled with no make-up game, the market resolves to \\\"0-0.\\\" The primary resolution source for this market is the official statistics of the event as recognized by the governing body or event organizers. However, if the governing body or event organizers have not published final match statistics within 2 hours after the event's conclusion, a consensus of credible reporting may be used instead. All markets will settle based on the official final result as recognized by the governing body or event organizers. Revisions to officially declared final scores made after market resolution will not be accounted for in determining the outcome.\", \"assets_ids\":[\"114956620324666124943984668302212854955910589301538227306970159095505577333331\", \"30978804988245623901316404305159626400343342738881175023443885520743528260484\"], \"outcomes\":[\"Yes\", \"No\"], \"event_message\":{\"id\":\"759599\", \"ticker\":\"efl-rot-wba-2026-08-08-exact-score\", \"slug\":\"efl-rot-wba-2026-08-08-exact-score\", \"title\":\"Rotherham United FC vs. West Bromwich Albion FC - Exact Score\", \"description\":\"In the upcoming EFL Cup (Carabao Cup) game between Rotherham United FC and West Bromwich Albion FC, scheduled for August 8, 2026 at 12:30 PM ET: This market will resolve based on the final score of the Rotherham United FC vs. West Bromwich Albion FC match originally scheduled for August 8, 2026 at 12:30 PM ET, considering only the result at the end of 90 minutes of regulation plus stoppage time; extra time and penalty shoot-outs are excluded. If the actual score is not one of the explicitly listed outcomes, the market resolves to \\\"Any Other Score.\\\" If the match is postponed, the market will remain open until it is completed; if it is canceled with no make-up game, the market resolves to \\\"0-0.\\\" The primary resolution source for this market is the official statistics of the event as recognized by the governing body or event organizers. However, if the governing body or event organizers have not published final match statistics within 2 hours after the event's conclusion, a consensus of credible reporting may be used instead. All markets will settle based on the official final result as recognized by the governing body or event organizers. Revisions to officially declared final scores made after market resolution will not be accounted for in determining the outcome.\"}, \"timestamp\":\"1785211428598\", \"event_type\":\"new_market\", \"tags\":[], \"condition_id\":\"0xbdeacb3b6ee8503451577f3d58002d43ba1b63a42bac2d3e1eb4392b7f25d241\", \"active\":true, \"clob_token_ids\":[\"114956620324666124943984668302212854955910589301538227306970159095505577333331\", \"30978804988245623901316404305159626400343342738881175023443885520743528260484\"], \"sports_market_type\":\"soccer_exact_score\", \"line\":\"\", \"game_start_time\":\"2026-08-08 16:30:00+00\", \"order_price_min_tick_size\":\"0.01\", \"group_item_title\":\"Rotherham United FC 2 - 0 West Bromwich Albion FC\", \"taker_base_fee\":\"1000\", \"fees_enabled\":true, \"fee_schedule\":{\"exponent\":\"1\", \"rate\":\"0.05\", \"taker_only\":true, \"rebate_rate\":\"0.15\"}}","received_at":"2026-07-28T04:03:50.221349Z","schema_version":"clob-market-ws.new_market.v1","sequence":null,"server_hash":null,"server_timestamp":"1785211428598","session_id":"2d607381e3054cee91998cdf45a4231c","source":"clob_market_ws"},"received_at":"2026-07-28T04:03:50.221349Z","record_id":"a618ac860d1fd8be6ba5005f0938494067adfd29bd7562dfff362367747e28a1","schema_fingerprint":"6639a822a7b79cfa4c3fc0044066e4f66ba8611f5bf361772bd6902a2319b82d","schema_version":"edge-lab-recorder.raw.v1","sequence":null,"source":"clob_market_ws"}
{"event_at":null,"event_fingerprint":"affd8eeb0b5549f650ee33eb1cb3c708758fbcde0c9fc2991713f96cbc361c7a","payload":{"connection_id":"f6725804f86a4c4eb588e4d5ed7db029","detail":{"interval_seconds":10.0,"message":"PING"},"event_type":"heartbeat","kind":"lifecycle","monotonic_ns":313413333378833,"received_at":"2026-07-28T04:03:50.283760Z","schema_version":"edge-lab-recorder.lifecycle.v1","session_id":"2d607381e3054cee91998cdf45a4231c","source":"clob_market_ws"},"received_at":"2026-07-28T04:03:50.283760Z","record_id":"3de11452da7ba7a0f7868e64ae5aec64ef40b9ff44bfcc48434c2958c3f8db39","schema_fingerprint":"cb8aa3aa4cb168a4b724fd9077bee6ecfb9bc586c57cfdf0ab89f00d82045e3c","schema_version":"edge-lab-recorder.raw.v1","sequence":null,"source":"clob_market_ws"}
{"event_at":"2026-07-28T04:03:48.601000Z","event_fingerprint":"23c66612034d368e54d01c2d8cc6e86eaf04ebf3e14a5e7f382c2f4b236b6370","payload":{"connection_id":"f6725804f86a4c4eb588e4d5ed7db029","event_at":"2026-07-28T04:03:48.601000Z","event_type":"new_market","frame_hash":"f58e69399850ea28a4fcde343b9346e965cc8418d6ff3028eda4c02e297be8eb","frame_index":0,"kind":"data","monotonic_ns":313413335273708,"payload":{"active":true,"assets_ids":["59943262071847607302137079654556169502292670896581034092567739003076893824165","66494971318783545531184891821461352067236183954078690387176488218023043466368"],"clob_token_ids":["59943262071847607302137079654556169502292670896581034092567739003076893824165","66494971318783545531184891821461352067236183954078690387176488218023043466368"],"condition_id":"0x758fb793f23c134e2ecf830d716a5b376f52311266b740a0187ef4202b8f3429","description":"In the upcoming EFL Cup (Carabao Cup) game between Mansfield Town FC and Sheffield United FC, scheduled for August 9, 2026 at 11:00 AM ET: This market will resolve to \"Mansfield Town FC\" if Mansfield Town FC score more goals than Sheffield United FC in the second half of regular play plus second-half stoppage time. This market will resolve to \"Draw\" if Mansfield Town FC and Sheffield United FC score the same number of goals in the second half of regular play plus second-half stoppage time. This market will resolve to \"Sheffield United FC\" if Sheffield United FC score more goals than Mansfield Town FC in the second half of regular play plus second-half stoppage time. If the game is postponed, this market will remain open until the game has been completed. If the game is canceled entirely, with no make-up game, this market will resolve to \"Draw\". This market refers only to the outcome within the second half of regular play plus second-half stoppage time. First-half goals, extra time, and penalty shoot-outs are excluded. The primary resolution source for this market is the official statistics of the event as recognized by the governing body or event organizers. However, if the governing body or event organizers have not published final match statistics within 24 hours after the event's conclusion, a consensus of credible reporting may be used instead. All markets will settle based on the official final result as recognized by the governing body or event organizers. Revisions to officially declared final scores made after market resolution will not be accounted for in determining the outcome.","event_message":{"description":"In the upcoming EFL Cup (Carabao Cup) game between Mansfield Town FC and Sheffield United FC, scheduled for August 9, 2026 at 11:00 AM ET: This market will resolve to \"Mansfield Town FC\" if Mansfield Town FC score more goals than Sheffield United FC in the second half of regular play plus second-half stoppage time. This market will resolve to \"Draw\" if Mansfield Town FC and Sheffield United FC score the same number of goals in the second half of regular play plus second-half stoppage time. This market will resolve to \"Sheffield United FC\" if Sheffield United FC score more goals than Mansfield Town FC in the second half of regular play plus second-half stoppage time. If the game is postponed, this market will remain open until the game has been completed. If the game is canceled entirely, with no make-up game, this market will resolve to \"Draw\". This market refers only to the outcome within the second half of regular play plus second-half stoppage time. First-half goals, extra time, and penalty shoot-outs are excluded. The primary resolution source for this market is the official statistics of the event as recognized by the governing body or event organizers. However, if the governing body or event organizers have not published final match statistics within 24 hours after the event's conclusion, a consensus of credible reporting may be used instead. All markets will settle based on the official final result as recognized by the governing body or event organizers. Revisions to officially declared final scores made after market resolution will not be accounted for in determining the outcome.","id":"759606","slug":"efl-man-she-2026-08-09-second-half-result","ticker":"efl-man-she-2026-08-09-second-half-result","title":"Mansfield Town FC vs. Sheffield United FC - Second Half Result"},"event_type":"new_market","fee_schedule":{"exponent":"1","rate":"0.05","rebate_rate":"0.15","taker_only":true},"fees_enabled":true,"game_start_time":"2026-08-09 15:00:00+00","group_item_title":"Mansfield Town FC","id":"3147137","line":"","market":"0x758fb793f23c134e2ecf830d716a5b376f52311266b740a0187ef4202b8f3429","order_price_min_tick_size":"0.01","outcomes":["Yes","No"],"question":"Mansfield Town FC to win the second half?","slug":"efl-man-she-2026-08-09-second-half-result-home","sports_market_type":"soccer_second_half_result","tags":[],"taker_base_fee":"1000","timestamp":"1785211428601"},"payload_hash":"3143728ff48f51e136d335b0bbd9c39c537c58e86a2acb711505e23b68984fa3","raw_frame":"{\"id\":\"3147137\", \"question\":\"Mansfield Town FC to win the second half?\", \"market\":\"0x758fb793f23c134e2ecf830d716a5b376f52311266b740a0187ef4202b8f3429\", \"slug\":\"efl-man-she-2026-08-09-second-half-result-home\", \"description\":\"In the upcoming EFL Cup (Carabao Cup) game between Mansfield Town FC and Sheffield United FC, scheduled for August 9, 2026 at 11:00 AM ET: This market will resolve to \\\"Mansfield Town FC\\\" if Mansfield Town FC score more goals than Sheffield United FC in the second half of regular play plus second-half stoppage time. This market will resolve to \\\"Draw\\\" if Mansfield Town FC and Sheffield United FC score the same number of goals in the second half of regular play plus second-half stoppage time. This market will resolve to \\\"Sheffield United FC\\\" if Sheffield United FC score more goals than Mansfield Town FC in the second half of regular play plus second-half stoppage time. If the game is postponed, this market will remain open until the game has been completed. If the game is canceled entirely, with no make-up game, this market will resolve to \\\"Draw\\\". This market refers only to the outcome within the second half of regular play plus second-half stoppage time. First-half goals, extra time, and penalty shoot-outs are excluded. The primary resolution source for this market is the official statistics of the event as recognized by the governing body or event organizers. However, if the governing body or event organizers have not published final match statistics within 24 hours after the event's conclusion, a consensus of credible reporting may be used instead. All markets will settle based on the official final result as recognized by the governing body or event organizers. Revisions to officially declared final scores made after market resolution will not be accounted for in determining the outcome.\", \"assets_ids\":[\"59943262071847607302137079654556169502292670896581034092567739003076893824165\", \"66494971318783545531184891821461352067236183954078690387176488218023043466368\"], \"outcomes\":[\"Yes\", \"No\"], \"event_message\":{\"id\":\"759606\", \"ticker\":\"efl-man-she-2026-08-09-second-half-result\", \"slug\":\"efl-man-she-2026-08-09-second-half-result\", \"title\":\"Mansfield Town FC vs. Sheffield United FC - Second Half Result\", \"description\":\"In the upcoming EFL Cup (Carabao Cup) game between Mansfield Town FC and Sheffield United FC, scheduled for August 9, 2026 at 11:00 AM ET: This market will resolve to \\\"Mansfield Town FC\\\" if Mansfield Town FC score more goals than Sheffield United FC in the second half of regular play plus second-half stoppage time. This market will resolve to \\\"Draw\\\" if Mansfield Town FC and Sheffield United FC score the same number of goals in the second half of regular play plus second-half stoppage time. This market will resolve to \\\"Sheffield United FC\\\" if Sheffield United FC score more goals than Mansfield Town FC in the second half of regular play plus second-half stoppage time. If the game is postponed, this market will remain open until the game has been completed. If the game is canceled entirely, with no make-up game, this market will resolve to \\\"Draw\\\". This market refers only to the outcome within the second half of regular play plus second-half stoppage time. First-half goals, extra time, and penalty shoot-outs are excluded. The primary resolution source for this market is the official statistics of the event as recognized by the governing body or event organizers. However, if the governing body or event organizers have not published final match statistics within 24 hours after the event's conclusion, a consensus of credible reporting may be used instead. All markets will settle based on the official final result as recognized by the governing body or event organizers. Revisions to officially declared final scores made after market resolution will not be accounted for in determining the outcome.\"}, \"timestamp\":\"1785211428601\", \"event_type\":\"new_market\", \"tags\":[], \"condition_id\":\"0x758fb793f23c134e2ecf830d716a5b376f52311266b740a0187ef4202b8f3429\", \"active\":true, \"clob_token_ids\":[\"59943262071847607302137079654556169502292670896581034092567739003076893824165\", \"66494971318783545531184891821461352067236183954078690387176488218023043466368\"], \"sports_market_type\":\"soccer_second_half_result\", \"line\":\"\", \"game_start_time\":\"2026-08-09 15:00:00+00\", \"order_price_min_tick_size\":\"0.01\", \"group_item_title\":\"Mansfield Town FC\", \"taker_base_fee\":\"1000\", \"fees_enabled\":true, \"fee_schedule\":{\"exponent\":\"1\", \"rate\":\"0.05\", \"taker_only\":true, \"rebate_rate\":\"0.15\"}}","received_at":"2026-07-28T04:03:50.285655Z","schema_version":"clob-market-ws.new_market.v1","sequence":null,"server_hash":null,"server_timestamp":"1785211428601","session_id":"2d607381e3054cee91998cdf45a4231c","source":"clob_market_ws"},"received_at":"2026-07-28T04:03:50.285655Z","record_id":"749dc54be1ec6d8f6dba2175e84860991e673b49554a8ca930a77bf48e81ccf4","schema_fingerprint":"6639a822a7b79cfa4c3fc0044066e4f66ba8611f5bf361772bd6902a2319b82d","schema_version":"edge-lab-recorder.raw.v1","sequence":null,"source":"clob_market_ws"}
{"event_at":"2026-07-28T04:03:48.608000Z","event_fingerprint":"1070d143c9cece736f832d60fea859015f15b9d99ca8624a1affc7a1e8fcf7cd","payload":{"connection_id":"f6725804f86a4c4eb588e4d5ed7db029","event_at":"2026-07-28T04:03:48.608000Z","event_type":"new_market","frame_hash":"1525f5c0d6cca56cf3adab80e9b9328198400f6307aa36670a54169ee0d54f76","frame_index":0,"kind":"data","monotonic_ns":313413406998000,"payload":{"active":true,"assets_ids":["47342483133937700556912750798223508103472171666294992965975419564468238348194","102024796627032285399438520577922718115059392139978783889739781410902868884161"],"clob_token_ids":["47342483133937700556912750798223508103472171666294992965975419564468238348194","102024796627032285399438520577922718115059392139978783889739781410902868884161"],"condition_id":"0xeecb88a255f37fab4a9fa8adf225310475c2152510578b0fc4a016501c79f22c","description":"In the upcoming EFL Cup (Carabao Cup) game between Rotherham United FC and West Bromwich Albion FC, scheduled for August 8, 2026 at 12:30 PM ET: This market will resolve based on the final score of the Rotherham United FC vs. West Bromwich Albion FC match originally scheduled for August 8, 2026 at 12:30 PM ET, considering only the result at the end of 90 minutes of regulation plus stoppage time; extra time and penalty shoot-outs are excluded. If the actual score is not one of the explicitly listed outcomes, the market resolves to \"Any Other Score.\" If the match is postponed, the market will remain open until it is completed; if it is canceled with no make-up game, the market resolves to \"0-0.\" The primary resolution source for this market is the official statistics of the event as recognized by the governing body or event organizers. However, if the governing body or event organizers have not published final match statistics within 2 hours after the event's conclusion, a consensus of credible reporting may be used instead. All markets will settle based on the official final result as recognized by the governing body or event organizers. Revisions to officially declared final scores made after market resolution will not be accounted for in determining the outcome.","event_message":{"description":"In the upcoming EFL Cup (Carabao Cup) game between Rotherham United FC and West Bromwich Albion FC, scheduled for August 8, 2026 at 12:30 PM ET: This market will resolve based on the final score of the Rotherham United FC vs. West Bromwich Albion FC match originally scheduled for August 8, 2026 at 12:30 PM ET, considering only the result at the end of 90 minutes of regulation plus stoppage time; extra time and penalty shoot-outs are excluded. If the actual score is not one of the explicitly listed outcomes, the market resolves to \"Any Other Score.\" If the match is postponed, the market will remain open until it is completed; if it is canceled with no make-up game, the market resolves to \"0-0.\" The primary resolution source for this market is the official statistics of the event as recognized by the governing body or event organizers. However, if the governing body or event organizers have not published final match statistics within 2 hours after the event's conclusion, a consensus of credible reporting may be used instead. All markets will settle based on the official final result as recognized by the governing body or event organizers. Revisions to officially declared final scores made after market resolution will not be accounted for in determining the outcome.","id":"759599","slug":"efl-rot-wba-2026-08-08-exact-score","ticker":"efl-rot-wba-2026-08-08-exact-score","title":"Rotherham United FC vs. West Bromwich Albion FC - Exact Score"},"event_type":"new_market","fee_schedule":{"exponent":"1","rate":"0.05","rebate_rate":"0.15","taker_only":true},"fees_enabled":true,"game_start_time":"2026-08-08 16:30:00+00","group_item_title":"Rotherham United FC 3 - 0 West Bromwich Albion FC","id":"3147097","line":"","market":"0xeecb88a255f37fab4a9fa8adf225310475c2152510578b0fc4a016501c79f22c","order_price_min_tick_size":"0.01","outcomes":["Yes","No"],"question":"Exact Score: Rotherham United FC 3 - 0 West Bromwich Albion FC?","slug":"efl-rot-wba-2026-08-08-exact-score-3-0","sports_market_type":"soccer_exact_score","tags":[],"taker_base_fee":"1000","timestamp":"1785211428608"},"payload_hash":"533b289955fb5e649621d1a685793771c37f9f8e88c979e72e575e482b60c2f1","raw_frame":"{\"id\":\"3147097\", \"question\":\"Exact Score: Rotherham United FC 3 - 0 West Bromwich Albion FC?\", \"market\":\"0xeecb88a255f37fab4a9fa8adf225310475c2152510578b0fc4a016501c79f22c\", \"slug\":\"efl-rot-wba-2026-08-08-exact-score-3-0\", \"description\":\"In the upcoming EFL Cup (Carabao Cup) game between Rotherham United FC and West Bromwich Albion FC, scheduled for August 8, 2026 at 12:30 PM ET: This market will resolve based on the final score of the Rotherham United FC vs. West Bromwich Albion FC match originally scheduled for August 8, 2026 at 12:30 PM ET, considering only the result at the end of 90 minutes of regulation plus stoppage time; extra time and penalty shoot-outs are excluded. If the actual score is not one of the explicitly listed outcomes, the market resolves to \\\"Any Other Score.\\\" If the match is postponed, the market will remain open until it is completed; if it is canceled with no make-up game, the market resolves to \\\"0-0.\\\" The primary resolution source for this market is the official statistics of the event as recognized by the governing body or event organizers. However, if the governing body or event organizers have not published final match statistics within 2 hours after the event's conclusion, a consensus of credible reporting may be used instead. All markets will settle based on the official final result as recognized by the governing body or event organizers. Revisions to officially declared final scores made after market resolution will not be accounted for in determining the outcome.\", \"assets_ids\":[\"47342483133937700556912750798223508103472171666294992965975419564468238348194\", \"102024796627032285399438520577922718115059392139978783889739781410902868884161\"], \"outcomes\":[\"Yes\", \"No\"], \"event_message\":{\"id\":\"759599\", \"ticker\":\"efl-rot-wba-2026-08-08-exact-score\", \"slug\":\"efl-rot-wba-2026-08-08-exact-score\", \"title\":\"Rotherham United FC vs. West Bromwich Albion FC - Exact Score\", \"description\":\"In the upcoming EFL Cup (Carabao Cup) game between Rotherham United FC and West Bromwich Albion FC, scheduled for August 8, 2026 at 12:30 PM ET: This market will resolve based on the final score of the Rotherham United FC vs. West Bromwich Albion FC match originally scheduled for August 8, 2026 at 12:30 PM ET, considering only the result at the end of 90 minutes of regulation plus stoppage time; extra time and penalty shoot-outs are excluded. If the actual score is not one of the explicitly listed outcomes, the market resolves to \\\"Any Other Score.\\\" If the match is postponed, the market will remain open until it is completed; if it is canceled with no make-up game, the market resolves to \\\"0-0.\\\" The primary resolution source for this market is the official statistics of the event as recognized by the governing body or event organizers. However, if the governing body or event organizers have not published final match statistics within 2 hours after the event's conclusion, a consensus of credible reporting may be used instead. All markets will settle based on the official final result as recognized by the governing body or event organizers. Revisions to officially declared final scores made after market resolution will not be accounted for in determining the outcome.\"}, \"timestamp\":\"1785211428608\", \"event_type\":\"new_market\", \"tags\":[], \"condition_id\":\"0xeecb88a255f37fab4a9fa8adf225310475c2152510578b0fc4a016501c79f22c\", \"active\":true, \"clob_token_ids\":[\"47342483133937700556912750798223508103472171666294992965975419564468238348194\", \"102024796627032285399438520577922718115059392139978783889739781410902868884161\"], \"sports_market_type\":\"soccer_exact_score\", \"line\":\"\", \"game_start_time\":\"2026-08-08 16:30:00+00\", \"order_price_min_tick_size\":\"0.01\", \"group_item_title\":\"Rotherham United FC 3 - 0 West Bromwich Albion FC\", \"taker_base_fee\":\"1000\", \"fees_enabled\":true, \"fee_schedule\":{\"exponent\":\"1\", \"rate\":\"0.05\", \"taker_only\":true, \"rebate_rate\":\"0.15\"}}","received_at":"2026-07-28T04:03:50.357375Z","schema_version":"clob-market-ws.new_market.v1","sequence":null,"server_hash":null,"server_timestamp":"1785211428608","session_id":"2d607381e3054cee91998cdf45a4231c","source":"clob_market_ws"},"received_at":"2026-07-28T04:03:50.357375Z","record_id":"1e891e3813480f9ca8fc7245fd0540ef4afe55e64e5ce55d2f06cb97230c3c3d","schema_fingerprint":"6639a822a7b79cfa4c3fc0044066e4f66ba8611f5bf361772bd6902a2319b82d","schema_version":"edge-lab-recorder.raw.v1","sequence":null,"source":"clob_market_ws"}
{"event_at":"2026-07-28T04:03:48.630000Z","event_fingerprint":"87f9ceedce4c2f8c93771bfabec79317aa7e20b1ff4e23f87adc1fe5cb61c6bf","payload":{"connection_id":"f6725804f86a4c4eb588e4d5ed7db029","event_at":"2026-07-28T04:03:48.630000Z","event_type":"price_change","frame_hash":"c926abde14adff999cf7cbcd11fca9943c4eee358451803d292fd8d9581ef16f","frame_index":0,"kind":"data","monotonic_ns":313413409282750,"payload":{"event_type":"price_change","market":"0xd412ce774cfcf8dc9f71164aac78783978aac7b03871702a3b8a481bd9dc9688","price_changes":[{"asset_id":"96600821790790307414914106093858868634329285205417149685270682748367152458577","best_ask":"0.44","best_bid":"0.43","hash":"2f99726596abaac466e04b0404662efb4a9be3bb","price":"0.35","side":"BUY","size":"233.03"},{"asset_id":"107603864457683460275633293642179940881969192120168665300712204232021063124301","best_ask":"0.57","best_bid":"0.56","hash":"3f7662308ea066922caf4e2c03589db1904f6419","price":"0.65","side":"SELL","size":"233.03"}],"timestamp":"1785211428630"},"payload_hash":"9ef8dee919d2630c847775cf1070b0050a1c55d790aa0b7ab1a2c82d24bd664a","raw_frame":"{\"market\":\"0xd412ce774cfcf8dc9f71164aac78783978aac7b03871702a3b8a481bd9dc9688\", \"price_changes\":[{\"asset_id\":\"96600821790790307414914106093858868634329285205417149685270682748367152458577\", \"price\":\"0.35\", \"size\":\"233.03\", \"side\":\"BUY\", \"hash\":\"2f99726596abaac466e04b0404662efb4a9be3bb\", \"best_bid\":\"0.43\", \"best_ask\":\"0.44\"}, {\"asset_id\":\"107603864457683460275633293642179940881969192120168665300712204232021063124301\", \"price\":\"0.65\", \"size\":\"233.03\", \"side\":\"SELL\", \"hash\":\"3f7662308ea066922caf4e2c03589db1904f6419\", \"best_bid\":\"0.56\", \"best_ask\":\"0.57\"}], \"timestamp\":\"1785211428630\", \"event_type\":\"price_change\"}","received_at":"2026-07-28T04:03:50.359663Z","schema_version":"clob-market-ws.price_change.v1","sequence":null,"server_hash":null,"server_timestamp":"1785211428630","session_id":"2d607381e3054cee91998cdf45a4231c","source":"clob_market_ws"},"received_at":"2026-07-28T04:03:50.359663Z","record_id":"61d9bb44d3ce23accafe77b413397c1f72025c8510a5717ec2f4841ee50bf74f","schema_fingerprint":"4aa3821a28b0b7c2400bc59aba4bcc0a76e971dadd19610d3ad38c768e124dc7","schema_version":"edge-lab-recorder.raw.v1","sequence":null,"source":"clob_market_ws"}
