{"event_at":"2026-07-28T04:09:50.739000Z","event_fingerprint":"53224189bafe94f141cc7200fa34c6c920fb9a1a821c62e053de608f6aff92e0","payload":{"connection_id":"f6725804f86a4c4eb588e4d5ed7db029","event_at":"2026-07-28T04:09:50.739000Z","event_type":"price_change","frame_hash":"b99912e64784e9ad04079215beee8538e0cb507edd642b8b5c9ca57c0ff72834","frame_index":0,"kind":"data","monotonic_ns":313773746577541,"payload":{"event_type":"price_change","market":"0xd412ce774cfcf8dc9f71164aac78783978aac7b03871702a3b8a481bd9dc9688","price_changes":[{"asset_id":"107603864457683460275633293642179940881969192120168665300712204232021063124301","best_ask":"0.61","best_bid":"0.6","hash":"580139e4c6a4f47b07c8b1a56433f199960f9617","price":"0.29","side":"BUY","size":"20.6"},{"asset_id":"96600821790790307414914106093858868634329285205417149685270682748367152458577","best_ask":"0.4","best_bid":"0.39","hash":"c5e4bcb04d25e0c0a0c08799d579a37af03f1a5b","price":"0.71","side":"SELL","size":"20.6"}],"timestamp":"1785211790739"},"payload_hash":"58b17a32829aa496453f716514d5777edea11fb6598bed5a52fc082108a5e68f","raw_frame":"{\"market\":\"0xd412ce774cfcf8dc9f71164aac78783978aac7b03871702a3b8a481bd9dc9688\", \"price_changes\":[{\"asset_id\":\"107603864457683460275633293642179940881969192120168665300712204232021063124301\", \"price\":\"0.29\", \"size\":\"20.6\", \"side\":\"BUY\", \"hash\":\"580139e4c6a4f47b07c8b1a56433f199960f9617\", \"best_bid\":\"0.6\", \"best_ask\":\"0.61\"}, {\"asset_id\":\"96600821790790307414914106093858868634329285205417149685270682748367152458577\", \"price\":\"0.71\", \"size\":\"20.6\", \"side\":\"SELL\", \"hash\":\"c5e4bcb04d25e0c0a0c08799d579a37af03f1a5b\", \"best_bid\":\"0.39\", \"best_ask\":\"0.4\"}], \"timestamp\":\"1785211790739\", \"event_type\":\"price_change\"}","received_at":"2026-07-28T04:09:50.670837Z","schema_version":"clob-market-ws.price_change.v1","sequence":null,"server_hash":null,"server_timestamp":"1785211790739","session_id":"2d607381e3054cee91998cdf45a4231c","source":"clob_market_ws"},"received_at":"2026-07-28T04:09:50.670837Z","record_id":"9d7538a4997e58cc99a3120f71afc50cac4913c7c2b7276dde8fdfdfdc2c2bfb","schema_fingerprint":"4aa3821a28b0b7c2400bc59aba4bcc0a76e971dadd19610d3ad38c768e124dc7","schema_version":"edge-lab-recorder.raw.v1","sequence":null,"source":"clob_market_ws"}
{"event_at":"2026-07-28T04:09:50.756000Z","event_fingerprint":"40b4c752901fda540d07b90433992e1666bbb56d1033233ac00ade0c0f377f57","payload":{"connection_id":"f6725804f86a4c4eb588e4d5ed7db029","event_at":"2026-07-28T04:09:50.756000Z","event_type":"price_change","frame_hash":"9adf323521eb13b761470f3b836c3e7d6b946579e9397bd63c7b04df379d8ec4","frame_index":0,"kind":"data","monotonic_ns":313773751051375,"payload":{"event_type":"price_change","market":"0xd412ce774cfcf8dc9f71164aac78783978aac7b03871702a3b8a481bd9dc9688","price_changes":[{"asset_id":"107603864457683460275633293642179940881969192120168665300712204232021063124301","best_ask":"0.61","best_bid":"0.6","hash":"19cfe7781fb64217e017c2095d4fbb06c40e108a","price":"0.6","side":"BUY","size":"18"},{"asset_id":"96600821790790307414914106093858868634329285205417149685270682748367152458577","best_ask":"0.4","best_bid":"0.39","hash":"1042aafaa62c626f0e6b6b1d11078fe2f01ad22b","price":"0.4","side":"SELL","size":"18"}],"timestamp":"1785211790756"},"payload_hash":"88be2d4d1810f27c3e636645cfb5853c5c4562206656b39d0142b6cada413416","raw_frame":"{\"market\":\"0xd412ce774cfcf8dc9f71164aac78783978aac7b03871702a3b8a481bd9dc9688\", \"price_changes\":[{\"asset_id\":\"107603864457683460275633293642179940881969192120168665300712204232021063124301\", \"price\":\"0.6\", \"size\":\"18\", \"side\":\"BUY\", \"hash\":\"19cfe7781fb64217e017c2095d4fbb06c40e108a\", \"best_bid\":\"0.6\", \"best_ask\":\"0.61\"}, {\"asset_id\":\"96600821790790307414914106093858868634329285205417149685270682748367152458577\", \"price\":\"0.4\", \"size\":\"18\", \"side\":\"SELL\", \"hash\":\"1042aafaa62c626f0e6b6b1d11078fe2f01ad22b\", \"best_bid\":\"0.39\", \"best_ask\":\"0.4\"}], \"timestamp\":\"1785211790756\", \"event_type\":\"price_change\"}","received_at":"2026-07-28T04:09:50.675311Z","schema_version":"clob-market-ws.price_change.v1","sequence":null,"server_hash":null,"server_timestamp":"1785211790756","session_id":"2d607381e3054cee91998cdf45a4231c","source":"clob_market_ws"},"received_at":"2026-07-28T04:09:50.675311Z","record_id":"a4738a0eead2e2efe028ff3599d5e97816d3eb3ff22fbf9c3894134ece697c28","schema_fingerprint":"4aa3821a28b0b7c2400bc59aba4bcc0a76e971dadd19610d3ad38c768e124dc7","schema_version":"edge-lab-recorder.raw.v1","sequence":null,"source":"clob_market_ws"}
{"event_at":"2026-07-28T04:09:50.758000Z","event_fingerprint":"ce73d250cc980c7822bef6f3651b4f2a477789aea5d0860390a555a7a83f2f30","payload":{"connection_id":"f6725804f86a4c4eb588e4d5ed7db029","event_at":"2026-07-28T04:09:50.758000Z","event_type":"price_change","frame_hash":"87d195ec078689bd5c727e6e30f1eb809a4af38077ff25f685deab7ee8f59a35","frame_index":0,"kind":"data","monotonic_ns":313773753967291,"payload":{"event_type":"price_change","market":"0xd412ce774cfcf8dc9f71164aac78783978aac7b03871702a3b8a481bd9dc9688","price_changes":[{"asset_id":"96600821790790307414914106093858868634329285205417149685270682748367152458577","best_ask":"0.4","best_bid":"0.39","hash":"177353431d6349cc4d356b6dbdc6366d57882d7a","price":"0.38","side":"BUY","size":"86.6"},{"asset_id":"107603864457683460275633293642179940881969192120168665300712204232021063124301","best_ask":"0.61","best_bid":"0.6","hash":"5654207af9f8297554776d2c6a47a509ef2e1bff","price":"0.62","side":"SELL","size":"86.6"}],"timestamp":"1785211790758"},"payload_hash":"cf74e34f897e91f6f7b3cc24f715b4a22214f0c310c5125f5056b790b7e1317f","raw_frame":"{\"market\":\"0xd412ce774cfcf8dc9f71164aac78783978aac7b03871702a3b8a481bd9dc9688\", \"price_changes\":[{\"asset_id\":\"96600821790790307414914106093858868634329285205417149685270682748367152458577\", \"price\":\"0.38\", \"size\":\"86.6\", \"side\":\"BUY\", \"hash\":\"177353431d6349cc4d356b6dbdc6366d57882d7a\", \"best_bid\":\"0.39\", \"best_ask\":\"0.4\"}, {\"asset_id\":\"107603864457683460275633293642179940881969192120168665300712204232021063124301\", \"price\":\"0.62\", \"size\":\"86.6\", \"side\":\"SELL\", \"hash\":\"5654207af9f8297554776d2c6a47a509ef2e1bff\", \"best_bid\":\"0.6\", \"best_ask\":\"0.61\"}], \"timestamp\":\"1785211790758\", \"event_type\":\"price_change\"}","received_at":"2026-07-28T04:09:50.678228Z","schema_version":"clob-market-ws.price_change.v1","sequence":null,"server_hash":null,"server_timestamp":"1785211790758","session_id":"2d607381e3054cee91998cdf45a4231c","source":"clob_market_ws"},"received_at":"2026-07-28T04:09:50.678228Z","record_id":"14471af231ebd8ff12fc301b139f904b6057f3271e7c273779d0fc80cc704172","schema_fingerprint":"4aa3821a28b0b7c2400bc59aba4bcc0a76e971dadd19610d3ad38c768e124dc7","schema_version":"edge-lab-recorder.raw.v1","sequence":null,"source":"clob_market_ws"}
{"event_at":"2026-07-28T04:09:50.760000Z","event_fingerprint":"e993d231966ed051ab3c156ad5448fee86a051ad3281ab29a07fdc064284bbe5","payload":{"connection_id":"f6725804f86a4c4eb588e4d5ed7db029","event_at":"2026-07-28T04:09:50.760000Z","event_type":"price_change","frame_hash":"bdc6ca89eb888c1b1de243108147f2e03598266f6f09e887d6b96e8bddcb01b5","frame_index":0,"kind":"data","monotonic_ns":313773756521625,"payload":{"event_type":"price_change","market":"0xd412ce774cfcf8dc9f71164aac78783978aac7b03871702a3b8a481bd9dc9688","price_changes":[{"asset_id":"107603864457683460275633293642179940881969192120168665300712204232021063124301","best_ask":"0.61","best_bid":"0.6","hash":"ac52204eb690c8845b6c2310d15d9db8da905c1a","price":"0.6","side":"BUY","size":"23"},{"asset_id":"96600821790790307414914106093858868634329285205417149685270682748367152458577","best_ask":"0.4","best_bid":"0.39","hash":"7b43614b844df97ea35331112fc9d75cd7ba56c8","price":"0.4","side":"SELL","size":"23"}],"timestamp":"1785211790760"},"payload_hash":"bc57925391dfbf1b7e7dbecd6918b7e156c97ef6af7748f0df911c94ce82924d","raw_frame":"{\"market\":\"0xd412ce774cfcf8dc9f71164aac78783978aac7b03871702a3b8a481bd9dc9688\", \"price_changes\":[{\"asset_id\":\"107603864457683460275633293642179940881969192120168665300712204232021063124301\", \"price\":\"0.6\", \"size\":\"23\", \"side\":\"BUY\", \"hash\":\"ac52204eb690c8845b6c2310d15d9db8da905c1a\", \"best_bid\":\"0.6\", \"best_ask\":\"0.61\"}, {\"asset_id\":\"96600821790790307414914106093858868634329285205417149685270682748367152458577\", \"price\":\"0.4\", \"size\":\"23\", \"side\":\"SELL\", \"hash\":\"7b43614b844df97ea35331112fc9d75cd7ba56c8\", \"best_bid\":\"0.39\", \"best_ask\":\"0.4\"}], \"timestamp\":\"1785211790760\", \"event_type\":\"price_change\"}","received_at":"2026-07-28T04:09:50.680776Z","schema_version":"clob-market-ws.price_change.v1","sequence":null,"server_hash":null,"server_timestamp":"1785211790760","session_id":"2d607381e3054cee91998cdf45a4231c","source":"clob_market_ws"},"received_at":"2026-07-28T04:09:50.680776Z","record_id":"0a6e6bf91181062faab8ab52e2511eafaeb2a8691e1776056950235aed6e6921","schema_fingerprint":"4aa3821a28b0b7c2400bc59aba4bcc0a76e971dadd19610d3ad38c768e124dc7","schema_version":"edge-lab-recorder.raw.v1","sequence":null,"source":"clob_market_ws"}
{"event_at":"2026-07-28T04:09:50.761000Z","event_fingerprint":"8b5902b1aad859d1e616eeb24450953e3a7191842f96860bb7eda1a8b284d2a6","payload":{"connection_id":"f6725804f86a4c4eb588e4d5ed7db029","event_at":"2026-07-28T04:09:50.761000Z","event_type":"price_change","frame_hash":"c46cb1a461e92f3a8b8bcf2fc34c2b3e6b10e0dd3f05f808d24754f376c5daf2","frame_index":0,"kind":"data","monotonic_ns":313773759062708,"payload":{"event_type":"price_change","market":"0xd412ce774cfcf8dc9f71164aac78783978aac7b03871702a3b8a481bd9dc9688","price_changes":[{"asset_id":"107603864457683460275633293642179940881969192120168665300712204232021063124301","best_ask":"0.61","best_bid":"0.6","hash":"58e5ad7ab813a61838a7f20eea624661dbf7636a","price":"0.3","side":"BUY","size":"102.3"},{"asset_id":"96600821790790307414914106093858868634329285205417149685270682748367152458577","best_ask":"0.4","best_bid":"0.39","hash":"0afad34bc14a511e11d2978b5773ca5729a98993","price":"0.7","side":"SELL","size":"102.3"}],"timestamp":"1785211790761"},"payload_hash":"781df9c2a85533214211ac8feac0902c6ff8cb1660a4ebf4b374005c7d16584f","raw_frame":"{\"market\":\"0xd412ce774cfcf8dc9f71164aac78783978aac7b03871702a3b8a481bd9dc9688\", \"price_changes\":[{\"asset_id\":\"107603864457683460275633293642179940881969192120168665300712204232021063124301\", \"price\":\"0.3\", \"size\":\"102.3\", \"side\":\"BUY\", \"hash\":\"58e5ad7ab813a61838a7f20eea624661dbf7636a\", \"best_bid\":\"0.6\", \"best_ask\":\"0.61\"}, {\"asset_id\":\"96600821790790307414914106093858868634329285205417149685270682748367152458577\", \"price\":\"0.7\", \"size\":\"102.3\", \"side\":\"SELL\", \"hash\":\"0afad34bc14a511e11d2978b5773ca5729a98993\", \"best_bid\":\"0.39\", \"best_ask\":\"0.4\"}], \"timestamp\":\"1785211790761\", \"event_type\":\"price_change\"}","received_at":"2026-07-28T04:09:50.683323Z","schema_version":"clob-market-ws.price_change.v1","sequence":null,"server_hash":null,"server_timestamp":"1785211790761","session_id":"2d607381e3054cee91998cdf45a4231c","source":"clob_market_ws"},"received_at":"2026-07-28T04:09:50.683323Z","record_id":"0e7c6ffa4367a07d40f226f6e260630fbea6219bdaf24ca773d189e3b0e73396","schema_fingerprint":"4aa3821a28b0b7c2400bc59aba4bcc0a76e971dadd19610d3ad38c768e124dc7","schema_version":"edge-lab-recorder.raw.v1","sequence":null,"source":"clob_market_ws"}
{"event_at":"2026-07-28T04:09:50.764000Z","event_fingerprint":"fdf0a9cbe505b4785b89e158cf735f19c0322e03cc95027e8e681087f0fd4b9f","payload":{"connection_id":"f6725804f86a4c4eb588e4d5ed7db029","event_at":"2026-07-28T04:09:50.764000Z","event_type":"price_change","frame_hash":"a392bab63a03c03c77c634335ee049705be3ceffc08b051e1b16063138efec21","frame_index":0,"kind":"data","monotonic_ns":313773762227958,"payload":{"event_type":"price_change","market":"0xd412ce774cfcf8dc9f71164aac78783978aac7b03871702a3b8a481bd9dc9688","price_changes":[{"asset_id":"96600821790790307414914106093858868634329285205417149685270682748367152458577","best_ask":"0.4","best_bid":"0.39","hash":"b01658f808b7a926262874acf99d9ba643027884","price":"0.39","side":"BUY","size":"81.2"},{"asset_id":"107603864457683460275633293642179940881969192120168665300712204232021063124301","best_ask":"0.61","best_bid":"0.6","hash":"862069f78b144662aac4a487f6a6b5586bd84478","price":"0.61","side":"SELL","size":"81.2"}],"timestamp":"1785211790764"},"payload_hash":"74307318f90a7533e02165211fe6ed0f8b6874bcfcbe89bb830f7cefd9080e8f","raw_frame":"{\"market\":\"0xd412ce774cfcf8dc9f71164aac78783978aac7b03871702a3b8a481bd9dc9688\", \"price_changes\":[{\"asset_id\":\"96600821790790307414914106093858868634329285205417149685270682748367152458577\", \"price\":\"0.39\", \"size\":\"81.2\", \"side\":\"BUY\", \"hash\":\"b01658f808b7a926262874acf99d9ba643027884\", \"best_bid\":\"0.39\", \"best_ask\":\"0.4\"}, {\"asset_id\":\"107603864457683460275633293642179940881969192120168665300712204232021063124301\", \"price\":\"0.61\", \"size\":\"81.2\", \"side\":\"SELL\", \"hash\":\"862069f78b144662aac4a487f6a6b5586bd84478\", \"best_bid\":\"0.6\", \"best_ask\":\"0.61\"}], \"timestamp\":\"1785211790764\", \"event_type\":\"price_change\"}","received_at":"2026-07-28T04:09:50.686487Z","schema_version":"clob-market-ws.price_change.v1","sequence":null,"server_hash":null,"server_timestamp":"1785211790764","session_id":"2d607381e3054cee91998cdf45a4231c","source":"clob_market_ws"},"received_at":"2026-07-28T04:09:50.686487Z","record_id":"7c78333bcc1adb8dd03ff2a80303b374bf55c349f252f347ebee3ed8aff8a9cb","schema_fingerprint":"4aa3821a28b0b7c2400bc59aba4bcc0a76e971dadd19610d3ad38c768e124dc7","schema_version":"edge-lab-recorder.raw.v1","sequence":null,"source":"clob_market_ws"}
{"event_at":"2026-07-28T04:09:50.765000Z","event_fingerprint":"7d9277910808608f50bbaa4b6f39cc9b9610483756f2138822305617f9a46b56","payload":{"connection_id":"f6725804f86a4c4eb588e4d5ed7db029","event_at":"2026-07-28T04:09:50.765000Z","event_type":"price_change","frame_hash":"744756f83978a4ea3b928a32349dc9091c8dfd5e9ef5212caf911e3527260a0c","frame_index":0,"kind":"data","monotonic_ns":313773765328708,"payload":{"event_type":"price_change","market":"0xd412ce774cfcf8dc9f71164aac78783978aac7b03871702a3b8a481bd9dc9688","price_changes":[{"asset_id":"107603864457683460275633293642179940881969192120168665300712204232021063124301","best_ask":"0.61","best_bid":"0.6","hash":"a4bb5e2ec4df64ae4f99bb154a4b00bcf99b28e0","price":"0.6","side":"BUY","size":"28"},{"asset_id":"96600821790790307414914106093858868634329285205417149685270682748367152458577","best_ask":"0.4","best_bid":"0.39","hash":"6b232848b0c99c741ae3f5d28408413083e49c54","price":"0.4","side":"SELL","size":"28"}],"timestamp":"1785211790765"},"payload_hash":"0db0daf1fe0fc0590595e3470d964250babcafe5c62b62c0d8112232f8e31e48","raw_frame":"{\"market\":\"0xd412ce774cfcf8dc9f71164aac78783978aac7b03871702a3b8a481bd9dc9688\", \"price_changes\":[{\"asset_id\":\"107603864457683460275633293642179940881969192120168665300712204232021063124301\", \"price\":\"0.6\", \"size\":\"28\", \"side\":\"BUY\", \"hash\":\"a4bb5e2ec4df64ae4f99bb154a4b00bcf99b28e0\", \"best_bid\":\"0.6\", \"best_ask\":\"0.61\"}, {\"asset_id\":\"96600821790790307414914106093858868634329285205417149685270682748367152458577\", \"price\":\"0.4\", \"size\":\"28\", \"side\":\"SELL\", \"hash\":\"6b232848b0c99c741ae3f5d28408413083e49c54\", \"best_bid\":\"0.39\", \"best_ask\":\"0.4\"}], \"timestamp\":\"1785211790765\", \"event_type\":\"price_change\"}","received_at":"2026-07-28T04:09:50.689589Z","schema_version":"clob-market-ws.price_change.v1","sequence":null,"server_hash":null,"server_timestamp":"1785211790765","session_id":"2d607381e3054cee91998cdf45a4231c","source":"clob_market_ws"},"received_at":"2026-07-28T04:09:50.689589Z","record_id":"4473d1e612e589720955a5664442498848dbbb8dcbc5ca8cebe16bdb3ea3a1e9","schema_fingerprint":"4aa3821a28b0b7c2400bc59aba4bcc0a76e971dadd19610d3ad38c768e124dc7","schema_version":"edge-lab-recorder.raw.v1","sequence":null,"source":"clob_market_ws"}
{"event_at":"2026-07-28T04:09:50.765000Z","event_fingerprint":"88f750dfc8f66ed7a9add5b0a89f5866ac5a867de87ff87c87a180f5804fb35a","payload":{"connection_id":"f6725804f86a4c4eb588e4d5ed7db029","event_at":"2026-07-28T04:09:50.765000Z","event_type":"price_change","frame_hash":"8a29cde820819af3cedee14ddac7595bb64adc6461c8a023e39b9de2fc52d309","frame_index":0,"kind":"data","monotonic_ns":313773767852541,"payload":{"event_type":"price_change","market":"0xd412ce774cfcf8dc9f71164aac78783978aac7b03871702a3b8a481bd9dc9688","price_changes":[{"asset_id":"107603864457683460275633293642179940881969192120168665300712204232021063124301","best_ask":"0.61","best_bid":"0.6","hash":"9758bff8edb66cf5e3482207792677fd830b0ec6","price":"0.81","side":"SELL","size":"35"},{"asset_id":"96600821790790307414914106093858868634329285205417149685270682748367152458577","best_ask":"0.4","best_bid":"0.39","hash":"0cc4daf62acca9809e5657c29fb683c14021c280","price":"0.19","side":"BUY","size":"35"}],"timestamp":"1785211790765"},"payload_hash":"b9edd2eeca7e189a980215d677c2ef87837d8ad2c139aaa0fc841aaf5f201b82","raw_frame":"{\"market\":\"0xd412ce774cfcf8dc9f71164aac78783978aac7b03871702a3b8a481bd9dc9688\", \"price_changes\":[{\"asset_id\":\"107603864457683460275633293642179940881969192120168665300712204232021063124301\", \"price\":\"0.81\", \"size\":\"35\", \"side\":\"SELL\", \"hash\":\"9758bff8edb66cf5e3482207792677fd830b0ec6\", \"best_bid\":\"0.6\", \"best_ask\":\"0.61\"}, {\"asset_id\":\"96600821790790307414914106093858868634329285205417149685270682748367152458577\", \"price\":\"0.19\", \"size\":\"35\", \"side\":\"BUY\", \"hash\":\"0cc4daf62acca9809e5657c29fb683c14021c280\", \"best_bid\":\"0.39\", \"best_ask\":\"0.4\"}], \"timestamp\":\"1785211790765\", \"event_type\":\"price_change\"}","received_at":"2026-07-28T04:09:50.692112Z","schema_version":"clob-market-ws.price_change.v1","sequence":null,"server_hash":null,"server_timestamp":"1785211790765","session_id":"2d607381e3054cee91998cdf45a4231c","source":"clob_market_ws"},"received_at":"2026-07-28T04:09:50.692112Z","record_id":"00e90045cdd68d0c255e1dacf7f22a0b0d7298e5853d48b79c52bc614ad1310a","schema_fingerprint":"4aa3821a28b0b7c2400bc59aba4bcc0a76e971dadd19610d3ad38c768e124dc7","schema_version":"edge-lab-recorder.raw.v1","sequence":null,"source":"clob_market_ws"}
{"event_at":"2026-07-28T04:09:50.766000Z","event_fingerprint":"f4de7bd6010267089e6ecba8629999352df3b8a300c5a588c67ecef819ea881f","payload":{"connection_id":"f6725804f86a4c4eb588e4d5ed7db029","event_at":"2026-07-28T04:09:50.766000Z","event_type":"price_change","frame_hash":"42351b897f652c225510ef5d535260f1b1c6727e28ff7c98d16bce4f6bc255d8","frame_index":0,"kind":"data","monotonic_ns":313773770056208,"payload":{"event_type":"price_change","market":"0xd412ce774cfcf8dc9f71164aac78783978aac7b03871702a3b8a481bd9dc9688","price_changes":[{"asset_id":"107603864457683460275633293642179940881969192120168665300712204232021063124301","best_ask":"0.61","best_bid":"0.6","hash":"7c603e05b16be3349d275d8bd56897e4913155f6","price":"0.6","side":"BUY","size":"33"},{"asset_id":"96600821790790307414914106093858868634329285205417149685270682748367152458577","best_ask":"0.4","best_bid":"0.39","hash":"f2258384fc4f1702efee9c449630f5093edfcc66","price":"0.4","side":"SELL","size":"33"}],"timestamp":"1785211790766"},"payload_hash":"b66e5b97f0ced66b2711ca05b96f29c335f7fbfce8dceb1d9622d70a0e1c8da9","raw_frame":"{\"market\":\"0xd412ce774cfcf8dc9f71164aac78783978aac7b03871702a3b8a481bd9dc9688\", \"price_changes\":[{\"asset_id\":\"107603864457683460275633293642179940881969192120168665300712204232021063124301\", \"price\":\"0.6\", \"size\":\"33\", \"side\":\"BUY\", \"hash\":\"7c603e05b16be3349d275d8bd56897e4913155f6\", \"best_bid\":\"0.6\", \"best_ask\":\"0.61\"}, {\"asset_id\":\"96600821790790307414914106093858868634329285205417149685270682748367152458577\", \"price\":\"0.4\", \"size\":\"33\", \"side\":\"SELL\", \"hash\":\"f2258384fc4f1702efee9c449630f5093edfcc66\", \"best_bid\":\"0.39\", \"best_ask\":\"0.4\"}], \"timestamp\":\"1785211790766\", \"event_type\":\"price_change\"}","received_at":"2026-07-28T04:09:50.694316Z","schema_version":"clob-market-ws.price_change.v1","sequence":null,"server_hash":null,"server_timestamp":"1785211790766","session_id":"2d607381e3054cee91998cdf45a4231c","source":"clob_market_ws"},"received_at":"2026-07-28T04:09:50.694316Z","record_id":"5079c202a17ed648523f83a936abf5c44f9ce1a18e2ae20f12a69be6a8fde9b4","schema_fingerprint":"4aa3821a28b0b7c2400bc59aba4bcc0a76e971dadd19610d3ad38c768e124dc7","schema_version":"edge-lab-recorder.raw.v1","sequence":null,"source":"clob_market_ws"}
{"event_at":"2026-07-28T04:09:50.777000Z","event_fingerprint":"ee5cb6dc867498826c4713607cc0d179e4ffc9f7945f85131807850b2441ca48","payload":{"connection_id":"f6725804f86a4c4eb588e4d5ed7db029","event_at":"2026-07-28T04:09:50.777000Z","event_type":"price_change","frame_hash":"200f5b7e1e671cfde5bbcb91adf294462bea891468c388e82eba1476a07457c0","frame_index":0,"kind":"data","monotonic_ns":313773772767375,"payload":{"event_type":"price_change","market":"0xd412ce774cfcf8dc9f71164aac78783978aac7b03871702a3b8a481bd9dc9688","price_changes":[{"asset_id":"107603864457683460275633293642179940881969192120168665300712204232021063124301","best_ask":"0.61","best_bid":"0.6","hash":"b9ddd4240a52d839188c43d81e51506a33d464ad","price":"0.01","side":"BUY","size":"5638.02"},{"asset_id":"96600821790790307414914106093858868634329285205417149685270682748367152458577","best_ask":"0.4","best_bid":"0.39","hash":"eeee809251f6bc86767ec44bfecd4f720022f2be","price":"0.99","side":"SELL","size":"5638.02"}],"timestamp":"1785211790777"},"payload_hash":"e9efd822a792058fb13ddce156c543e135b3a227c097d83334a80a2dfcbd3f62","raw_frame":"{\"market\":\"0xd412ce774cfcf8dc9f71164aac78783978aac7b03871702a3b8a481bd9dc9688\", \"price_changes\":[{\"asset_id\":\"107603864457683460275633293642179940881969192120168665300712204232021063124301\", \"price\":\"0.01\", \"size\":\"5638.02\", \"side\":\"BUY\", \"hash\":\"b9ddd4240a52d839188c43d81e51506a33d464ad\", \"best_bid\":\"0.6\", \"best_ask\":\"0.61\"}, {\"asset_id\":\"96600821790790307414914106093858868634329285205417149685270682748367152458577\", \"price\":\"0.99\", \"size\":\"5638.02\", \"side\":\"SELL\", \"hash\":\"eeee809251f6bc86767ec44bfecd4f720022f2be\", \"best_bid\":\"0.39\", \"best_ask\":\"0.4\"}], \"timestamp\":\"1785211790777\", \"event_type\":\"price_change\"}","received_at":"2026-07-28T04:09:50.697026Z","schema_version":"clob-market-ws.price_change.v1","sequence":null,"server_hash":null,"server_timestamp":"1785211790777","session_id":"2d607381e3054cee91998cdf45a4231c","source":"clob_market_ws"},"received_at":"2026-07-28T04:09:50.697026Z","record_id":"7ccf520476e0c5447c27130eca6c9c0fd19c11ead33c5ceace7480aeb0ca5fd4","schema_fingerprint":"4aa3821a28b0b7c2400bc59aba4bcc0a76e971dadd19610d3ad38c768e124dc7","schema_version":"edge-lab-recorder.raw.v1","sequence":null,"source":"clob_market_ws"}
{"event_at":"2026-07-28T04:09:50.790000Z","event_fingerprint":"7b2864ee8cb2853735dd685491934e2a2052995cd9cdc810b76a5ecb1b627863","payload":{"connection_id":"f6725804f86a4c4eb588e4d5ed7db029","event_at":"2026-07-28T04:09:50.790000Z","event_type":"price_change","frame_hash":"e749b9e330bac8d02145048a3a6597235ff1ffd70f6f50e12b756386f64f7aba","frame_index":0,"kind":"data","monotonic_ns":313773783181083,"payload":{"event_type":"price_change","market":"0xd412ce774cfcf8dc9f71164aac78783978aac7b03871702a3b8a481bd9dc9688","price_changes":[{"asset_id":"107603864457683460275633293642179940881969192120168665300712204232021063124301","best_ask":"0.61","best_bid":"0.6","hash":"2eb3d69eba4ccfc704f083617ad3ac7c1cbbdf75","price":"0.02","side":"BUY","size":"688.1"},{"asset_id":"96600821790790307414914106093858868634329285205417149685270682748367152458577","best_ask":"0.4","best_bid":"0.39","hash":"720f48cc0dc85ed9fb8eb33f94ba629a432d7025","price":"0.98","side":"SELL","size":"688.1"}],"timestamp":"1785211790790"},"payload_hash":"e5c48380173c94a2cc4e8af5306e605c358573f0c8dd7b1af18563a25eb561e6","raw_frame":"{\"market\":\"0xd412ce774cfcf8dc9f71164aac78783978aac7b03871702a3b8a481bd9dc9688\", \"price_changes\":[{\"asset_id\":\"107603864457683460275633293642179940881969192120168665300712204232021063124301\", \"price\":\"0.02\", \"size\":\"688.1\", \"side\":\"BUY\", \"hash\":\"2eb3d69eba4ccfc704f083617ad3ac7c1cbbdf75\", \"best_bid\":\"0.6\", \"best_ask\":\"0.61\"}, {\"asset_id\":\"96600821790790307414914106093858868634329285205417149685270682748367152458577\", \"price\":\"0.98\", \"size\":\"688.1\", \"side\":\"SELL\", \"hash\":\"720f48cc0dc85ed9fb8eb33f94ba629a432d7025\", \"best_bid\":\"0.39\", \"best_ask\":\"0.4\"}], \"timestamp\":\"1785211790790\", \"event_type\":\"price_change\"}","received_at":"2026-07-28T04:09:50.707441Z","schema_version":"clob-market-ws.price_change.v1","sequence":null,"server_hash":null,"server_timestamp":"1785211790790","session_id":"2d607381e3054cee91998cdf45a4231c","source":"clob_market_ws"},"received_at":"2026-07-28T04:09:50.707441Z","record_id":"d2d803a25a8899995eddd7307f1e4235f92bd102b8b14219c2e2a4046ae11cd1","schema_fingerprint":"4aa3821a28b0b7c2400bc59aba4bcc0a76e971dadd19610d3ad38c768e124dc7","schema_version":"edge-lab-recorder.raw.v1","sequence":null,"source":"clob_market_ws"}
{"event_at":"2026-07-28T04:09:50.798000Z","event_fingerprint":"37b5ad245bb237363ac34f601c62d4792606f3c937c8e519d29e1f9f83414a67","payload":{"connection_id":"f6725804f86a4c4eb588e4d5ed7db029","event_at":"2026-07-28T04:09:50.798000Z","event_type":"price_change","frame_hash":"9e0613218f653d417191c1f420a882ae8ad9bff8a3f09bcf4e373a4fadb84ff2","frame_index":0,"kind":"data","monotonic_ns":313773786493708,"payload":{"event_type":"price_change","market":"0xd412ce774cfcf8dc9f71164aac78783978aac7b03871702a3b8a481bd9dc9688","price_changes":[{"asset_id":"107603864457683460275633293642179940881969192120168665300712204232021063124301","best_ask":"0.61","best_bid":"0.6","hash":"8c58c0d093e47520086f95011aae24c358210475","price":"0.01","side":"BUY","size":"5633.02"},{"asset_id":"96600821790790307414914106093858868634329285205417149685270682748367152458577","best_ask":"0.4","best_bid":"0.39","hash":"c7563d8c9d6b0c17cc4bade23ac384612d8bde91","price":"0.99","side":"SELL","size":"5633.02"}],"timestamp":"1785211790798"},"payload_hash":"d8031cec84cf339c4d840b9223636ca096b0b0999f7d142b6a06aa3272eb9071","raw_frame":"{\"market\":\"0xd412ce774cfcf8dc9f71164aac78783978aac7b03871702a3b8a481bd9dc9688\", \"price_changes\":[{\"asset_id\":\"107603864457683460275633293642179940881969192120168665300712204232021063124301\", \"price\":\"0.01\", \"size\":\"5633.02\", \"side\":\"BUY\", \"hash\":\"8c58c0d093e47520086f95011aae24c358210475\", \"best_bid\":\"0.6\", \"best_ask\":\"0.61\"}, {\"asset_id\":\"96600821790790307414914106093858868634329285205417149685270682748367152458577\", \"price\":\"0.99\", \"size\":\"5633.02\", \"side\":\"SELL\", \"hash\":\"c7563d8c9d6b0c17cc4bade23ac384612d8bde91\", \"best_bid\":\"0.39\", \"best_ask\":\"0.4\"}], \"timestamp\":\"1785211790798\", \"event_type\":\"price_change\"}","received_at":"2026-07-28T04:09:50.710754Z","schema_version":"clob-market-ws.price_change.v1","sequence":null,"server_hash":null,"server_timestamp":"1785211790798","session_id":"2d607381e3054cee91998cdf45a4231c","source":"clob_market_ws"},"received_at":"2026-07-28T04:09:50.710754Z","record_id":"5293d8c35702cdad32eba315996405b9bd6f2341a758e4cd7ff091d00e74b256","schema_fingerprint":"4aa3821a28b0b7c2400bc59aba4bcc0a76e971dadd19610d3ad38c768e124dc7","schema_version":"edge-lab-recorder.raw.v1","sequence":null,"source":"clob_market_ws"}
{"event_at":"2026-07-28T04:09:50.832000Z","event_fingerprint":"35d4c771f86b03d4a7c623f0984c49af6be29946f3953a9c914737c463901346","payload":{"connection_id":"f6725804f86a4c4eb588e4d5ed7db029","event_at":"2026-07-28T04:09:50.832000Z","event_type":"price_change","frame_hash":"0b16b1bb146f0e684771d65c05429928df55a007d0a980ed3f7d6d95372cb850","frame_index":0,"kind":"data","monotonic_ns":313773789412750,"payload":{"event_type":"price_change","market":"0xd412ce774cfcf8dc9f71164aac78783978aac7b03871702a3b8a481bd9dc9688","price_changes":[{"asset_id":"107603864457683460275633293642179940881969192120168665300712204232021063124301","best_ask":"0.61","best_bid":"0.6","hash":"3c0c5b249490b7e3564aa8d3ee335e82404e755e","price":"0.39","side":"BUY","size":"32.6"},{"asset_id":"96600821790790307414914106093858868634329285205417149685270682748367152458577","best_ask":"0.4","best_bid":"0.39","hash":"debb137c5061058e91f497a50b575a4a9f5273f5","price":"0.61","side":"SELL","size":"32.6"}],"timestamp":"1785211790832"},"payload_hash":"44cc9db8dd96a384b9136d28479a5a2dd6a23bd1a567f55dccb6ad0e9ee707c1","raw_frame":"{\"market\":\"0xd412ce774cfcf8dc9f71164aac78783978aac7b03871702a3b8a481bd9dc9688\", \"price_changes\":[{\"asset_id\":\"107603864457683460275633293642179940881969192120168665300712204232021063124301\", \"price\":\"0.39\", \"size\":\"32.6\", \"side\":\"BUY\", \"hash\":\"3c0c5b249490b7e3564aa8d3ee335e82404e755e\", \"best_bid\":\"0.6\", \"best_ask\":\"0.61\"}, {\"asset_id\":\"96600821790790307414914106093858868634329285205417149685270682748367152458577\", \"price\":\"0.61\", \"size\":\"32.6\", \"side\":\"SELL\", \"hash\":\"debb137c5061058e91f497a50b575a4a9f5273f5\", \"best_bid\":\"0.39\", \"best_ask\":\"0.4\"}], \"timestamp\":\"1785211790832\", \"event_type\":\"price_change\"}","received_at":"2026-07-28T04:09:50.713672Z","schema_version":"clob-market-ws.price_change.v1","sequence":null,"server_hash":null,"server_timestamp":"1785211790832","session_id":"2d607381e3054cee91998cdf45a4231c","source":"clob_market_ws"},"received_at":"2026-07-28T04:09:50.713672Z","record_id":"c9dc979e15d46650ac95e94ae974062e06956ff6b66c26aab05a84ede285d435","schema_fingerprint":"4aa3821a28b0b7c2400bc59aba4bcc0a76e971dadd19610d3ad38c768e124dc7","schema_version":"edge-lab-recorder.raw.v1","sequence":null,"source":"clob_market_ws"}
{"event_at":"2026-07-28T04:09:50.840000Z","event_fingerprint":"d888e871bf4010ad6083dd8d0059890c7215101db845219aba2f153053c4b23c","payload":{"connection_id":"f6725804f86a4c4eb588e4d5ed7db029","event_at":"2026-07-28T04:09:50.840000Z","event_type":"last_trade_price","frame_hash":"9a4722b9fd9562426288dae2de79d3560e1ef445ebb4acf3de63c50304d87717","frame_index":0,"kind":"data","monotonic_ns":313773791607750,"payload":{"asset_id":"107603864457683460275633293642179940881969192120168665300712204232021063124301","event_type":"last_trade_price","fee_rate_bps":"0","market":"0xd412ce774cfcf8dc9f71164aac78783978aac7b03871702a3b8a481bd9dc9688","price":"0.6","side":"BUY","size":"50","timestamp":"1785211790840","transaction_hash":"0x90abd27543effdc1b9c5facd98fc83f98d405cc1350726315e436564d9736ae3"},"payload_hash":"69d012ec86098c545cc7f8bec3cea8f1295e2da7bf989ba8abb094b00c4d989a","raw_frame":"{\"market\":\"0xd412ce774cfcf8dc9f71164aac78783978aac7b03871702a3b8a481bd9dc9688\", \"asset_id\":\"107603864457683460275633293642179940881969192120168665300712204232021063124301\", \"price\":\"0.6\", \"size\":\"50\", \"fee_rate_bps\":\"0\", \"side\":\"BUY\", \"timestamp\":\"1785211790840\", \"event_type\":\"last_trade_price\", \"transaction_hash\":\"0x90abd27543effdc1b9c5facd98fc83f98d405cc1350726315e436564d9736ae3\"}","received_at":"2026-07-28T04:09:50.715867Z","schema_version":"clob-market-ws.last_trade_price.v1","sequence":null,"server_hash":null,"server_timestamp":"1785211790840","session_id":"2d607381e3054cee91998cdf45a4231c","source":"clob_market_ws"},"received_at":"2026-07-28T04:09:50.715867Z","record_id":"dfad62486fae072ff5b17cb3f1ea5895bc0d0ac934c8d5faa5fcd28a26877515","schema_fingerprint":"95ad9be75a4b695cd99991e12b2592bc7346f3f5388a82d0000ba65bc0d9fd0a","schema_version":"edge-lab-recorder.raw.v1","sequence":null,"source":"clob_market_ws"}
