{"event_at":"2026-07-28T04:13:18.858000Z","event_fingerprint":"40ca9b326ae4947fafbc344e322f1397473e2fe0232ffef2b7760630b9a88a5a","payload":{"connection_id":"f6725804f86a4c4eb588e4d5ed7db029","event_at":"2026-07-28T04:13:18.858000Z","event_type":"price_change","frame_hash":"6101a9f7e724944c210129f4d89b5ea77d38e5abc009a1515278ed5dc8fdcdf2","frame_index":0,"kind":"data","monotonic_ns":313993055232666,"payload":{"event_type":"price_change","market":"0xd412ce774cfcf8dc9f71164aac78783978aac7b03871702a3b8a481bd9dc9688","price_changes":[{"asset_id":"107603864457683460275633293642179940881969192120168665300712204232021063124301","best_ask":"0.45","best_bid":"0.4","hash":"9b15cbeebb492cd6ba1856b3cd87d9ed54f750fe","price":"0.44","side":"SELL","size":"0"},{"asset_id":"96600821790790307414914106093858868634329285205417149685270682748367152458577","best_ask":"0.6","best_bid":"0.55","hash":"50590bbf0521bc8369419af0b2a0d9ee42ee0a9f","price":"0.56","side":"BUY","size":"0"}],"timestamp":"1785211998858"},"payload_hash":"bee4d4e20cf673ff6313de7bbc83b819791f0a6a27c9ffc20d650cbd2f38cda9","raw_frame":"{\"market\":\"0xd412ce774cfcf8dc9f71164aac78783978aac7b03871702a3b8a481bd9dc9688\", \"price_changes\":[{\"asset_id\":\"107603864457683460275633293642179940881969192120168665300712204232021063124301\", \"price\":\"0.44\", \"size\":\"0\", \"side\":\"SELL\", \"hash\":\"9b15cbeebb492cd6ba1856b3cd87d9ed54f750fe\", \"best_bid\":\"0.4\", \"best_ask\":\"0.45\"}, {\"asset_id\":\"96600821790790307414914106093858868634329285205417149685270682748367152458577\", \"price\":\"0.56\", \"size\":\"0\", \"side\":\"BUY\", \"hash\":\"50590bbf0521bc8369419af0b2a0d9ee42ee0a9f\", \"best_bid\":\"0.55\", \"best_ask\":\"0.6\"}], \"timestamp\":\"1785211998858\", \"event_type\":\"price_change\"}","received_at":"2026-07-28T04:13:29.977210Z","schema_version":"clob-market-ws.price_change.v1","sequence":null,"server_hash":null,"server_timestamp":"1785211998858","session_id":"2d607381e3054cee91998cdf45a4231c","source":"clob_market_ws"},"received_at":"2026-07-28T04:13:29.977210Z","record_id":"f1b106ad5ce5e042f5bbccd0b3061459f6074a6c1dd222feee3e0d4ec338e956","schema_fingerprint":"4aa3821a28b0b7c2400bc59aba4bcc0a76e971dadd19610d3ad38c768e124dc7","schema_version":"edge-lab-recorder.raw.v1","sequence":null,"source":"clob_market_ws"}
{"event_at":"2026-07-28T04:13:18.859000Z","event_fingerprint":"0574a53f5ccd8e02be6c84d0f09a6324fbc855e1df14b6b7b945b2b2f40dd5ca","payload":{"connection_id":"f6725804f86a4c4eb588e4d5ed7db029","event_at":"2026-07-28T04:13:18.859000Z","event_type":"best_bid_ask","frame_hash":"d572b5f946df302c71eda76526fbc580bc32bce27dd679c384f2df0e675f1dba","frame_index":0,"kind":"data","monotonic_ns":313993060261458,"payload":{"asset_id":"107603864457683460275633293642179940881969192120168665300712204232021063124301","best_ask":"0.43","best_bid":"0.4","event_type":"best_bid_ask","market":"0xd412ce774cfcf8dc9f71164aac78783978aac7b03871702a3b8a481bd9dc9688","spread":"0.03","timestamp":"1785211998859"},"payload_hash":"0a23e57f89dbf3fce2058cc67b75baaf93dc305cf8a617986eb8b82029ae5209","raw_frame":"{\"market\":\"0xd412ce774cfcf8dc9f71164aac78783978aac7b03871702a3b8a481bd9dc9688\", \"asset_id\":\"107603864457683460275633293642179940881969192120168665300712204232021063124301\", \"best_bid\":\"0.4\", \"best_ask\":\"0.43\", \"spread\":\"0.03\", \"timestamp\":\"1785211998859\", \"event_type\":\"best_bid_ask\"}","received_at":"2026-07-28T04:13:29.982250Z","schema_version":"clob-market-ws.best_bid_ask.v1","sequence":null,"server_hash":null,"server_timestamp":"1785211998859","session_id":"2d607381e3054cee91998cdf45a4231c","source":"clob_market_ws"},"received_at":"2026-07-28T04:13:29.982250Z","record_id":"5b97300871c7e6b1f83d33c399cc85e822e25044c4839e651e15d39c4dadca57","schema_fingerprint":"8488399f31b0337811b13b266be932db7062827c2470b78bd8e9e99bab51d17d","schema_version":"edge-lab-recorder.raw.v1","sequence":null,"source":"clob_market_ws"}
{"event_at":"2026-07-28T04:13:18.859000Z","event_fingerprint":"95c441fd0bb3a6832eb499db2304acb4bc2c0fbe536bee504ca46b793f23df9a","payload":{"connection_id":"f6725804f86a4c4eb588e4d5ed7db029","event_at":"2026-07-28T04:13:18.859000Z","event_type":"best_bid_ask","frame_hash":"e443509f294c9b34a94df95ce1a426f9c3e6ed93130e5fc1b4a7991aad8f4039","frame_index":0,"kind":"data","monotonic_ns":313993061967875,"payload":{"asset_id":"96600821790790307414914106093858868634329285205417149685270682748367152458577","best_ask":"0.6","best_bid":"0.57","event_type":"best_bid_ask","market":"0xd412ce774cfcf8dc9f71164aac78783978aac7b03871702a3b8a481bd9dc9688","spread":"0.03","timestamp":"1785211998859"},"payload_hash":"3f141d5bca3b88bd0c47152f5e45fde0c5e285f7aaaf79da4811367ca7c053a8","raw_frame":"{\"market\":\"0xd412ce774cfcf8dc9f71164aac78783978aac7b03871702a3b8a481bd9dc9688\", \"asset_id\":\"96600821790790307414914106093858868634329285205417149685270682748367152458577\", \"best_bid\":\"0.57\", \"best_ask\":\"0.6\", \"spread\":\"0.03\", \"timestamp\":\"1785211998859\", \"event_type\":\"best_bid_ask\"}","received_at":"2026-07-28T04:13:29.983950Z","schema_version":"clob-market-ws.best_bid_ask.v1","sequence":null,"server_hash":null,"server_timestamp":"1785211998859","session_id":"2d607381e3054cee91998cdf45a4231c","source":"clob_market_ws"},"received_at":"2026-07-28T04:13:29.983950Z","record_id":"470015c4291de9e52791f3457d0b301757279ac32b2b1565eb2f0a4043a44de3","schema_fingerprint":"8488399f31b0337811b13b266be932db7062827c2470b78bd8e9e99bab51d17d","schema_version":"edge-lab-recorder.raw.v1","sequence":null,"source":"clob_market_ws"}
{"event_at":"2026-07-28T04:13:18.859000Z","event_fingerprint":"e80579fe6bd8726d7c688f2fa877bfda253e06b3f9cf94bde1b257493a8b052e","payload":{"connection_id":"f6725804f86a4c4eb588e4d5ed7db029","event_at":"2026-07-28T04:13:18.859000Z","event_type":"price_change","frame_hash":"d3523046c389a89515d013b182ae17d1dd8a312841cb205f689fac9113691711","frame_index":0,"kind":"data","monotonic_ns":313993063237416,"payload":{"event_type":"price_change","market":"0xd412ce774cfcf8dc9f71164aac78783978aac7b03871702a3b8a481bd9dc9688","price_changes":[{"asset_id":"96600821790790307414914106093858868634329285205417149685270682748367152458577","best_ask":"0.6","best_bid":"0.57","hash":"39b200fa95ea275680ede8b45596122b594082cb","price":"0.57","side":"BUY","size":"5"},{"asset_id":"107603864457683460275633293642179940881969192120168665300712204232021063124301","best_ask":"0.43","best_bid":"0.4","hash":"ca51b9fd74ee3cbca7257eebc7151e29fa625ecb","price":"0.43","side":"SELL","size":"5"}],"timestamp":"1785211998859"},"payload_hash":"797ca8bcfe5604259d11d450f8a4743b24a65c2522dc871701d6405a9412412c","raw_frame":"{\"market\":\"0xd412ce774cfcf8dc9f71164aac78783978aac7b03871702a3b8a481bd9dc9688\", \"price_changes\":[{\"asset_id\":\"96600821790790307414914106093858868634329285205417149685270682748367152458577\", \"price\":\"0.57\", \"size\":\"5\", \"side\":\"BUY\", \"hash\":\"39b200fa95ea275680ede8b45596122b594082cb\", \"best_bid\":\"0.57\", \"best_ask\":\"0.6\"}, {\"asset_id\":\"107603864457683460275633293642179940881969192120168665300712204232021063124301\", \"price\":\"0.43\", \"size\":\"5\", \"side\":\"SELL\", \"hash\":\"ca51b9fd74ee3cbca7257eebc7151e29fa625ecb\", \"best_bid\":\"0.4\", \"best_ask\":\"0.43\"}], \"timestamp\":\"1785211998859\", \"event_type\":\"price_change\"}","received_at":"2026-07-28T04:13:29.985220Z","schema_version":"clob-market-ws.price_change.v1","sequence":null,"server_hash":null,"server_timestamp":"1785211998859","session_id":"2d607381e3054cee91998cdf45a4231c","source":"clob_market_ws"},"received_at":"2026-07-28T04:13:29.985220Z","record_id":"34a7e2aa113059ccceb39292fc31c575edb8b665459790e79c237bf5799675a4","schema_fingerprint":"4aa3821a28b0b7c2400bc59aba4bcc0a76e971dadd19610d3ad38c768e124dc7","schema_version":"edge-lab-recorder.raw.v1","sequence":null,"source":"clob_market_ws"}
{"event_at":"2026-07-28T04:13:18.861000Z","event_fingerprint":"6cba089c084a7ed75ea015296f443d6e8e45de9a3a64c9d2f8091b7b8e7be955","payload":{"connection_id":"f6725804f86a4c4eb588e4d5ed7db029","event_at":"2026-07-28T04:13:18.861000Z","event_type":"price_change","frame_hash":"5856fc0647970627feccd7e7f1bb83d587471f662ca6d5e44067e2cfc8e403c2","frame_index":0,"kind":"data","monotonic_ns":313993066462541,"payload":{"event_type":"price_change","market":"0xd412ce774cfcf8dc9f71164aac78783978aac7b03871702a3b8a481bd9dc9688","price_changes":[{"asset_id":"107603864457683460275633293642179940881969192120168665300712204232021063124301","best_ask":"0.43","best_bid":"0.4","hash":"c409609f897b3967a3b15e8248089f4b68a1bc72","price":"0.55","side":"SELL","size":"107"},{"asset_id":"96600821790790307414914106093858868634329285205417149685270682748367152458577","best_ask":"0.6","best_bid":"0.57","hash":"78b20fdf45480deda607b16372508339da6229ef","price":"0.45","side":"BUY","size":"107"}],"timestamp":"1785211998861"},"payload_hash":"87a7e7d408e15c4b818bcfc859113cf9911830b40e3c6b2776adc5ba308f3acf","raw_frame":"{\"market\":\"0xd412ce774cfcf8dc9f71164aac78783978aac7b03871702a3b8a481bd9dc9688\", \"price_changes\":[{\"asset_id\":\"107603864457683460275633293642179940881969192120168665300712204232021063124301\", \"price\":\"0.55\", \"size\":\"107\", \"side\":\"SELL\", \"hash\":\"c409609f897b3967a3b15e8248089f4b68a1bc72\", \"best_bid\":\"0.4\", \"best_ask\":\"0.43\"}, {\"asset_id\":\"96600821790790307414914106093858868634329285205417149685270682748367152458577\", \"price\":\"0.45\", \"size\":\"107\", \"side\":\"BUY\", \"hash\":\"78b20fdf45480deda607b16372508339da6229ef\", \"best_bid\":\"0.57\", \"best_ask\":\"0.6\"}], \"timestamp\":\"1785211998861\", \"event_type\":\"price_change\"}","received_at":"2026-07-28T04:13:29.988445Z","schema_version":"clob-market-ws.price_change.v1","sequence":null,"server_hash":null,"server_timestamp":"1785211998861","session_id":"2d607381e3054cee91998cdf45a4231c","source":"clob_market_ws"},"received_at":"2026-07-28T04:13:29.988445Z","record_id":"ce34363f59bb593f9defab61adcad9f27b8a230febb9af017266c5331f5d4383","schema_fingerprint":"4aa3821a28b0b7c2400bc59aba4bcc0a76e971dadd19610d3ad38c768e124dc7","schema_version":"edge-lab-recorder.raw.v1","sequence":null,"source":"clob_market_ws"}
{"event_at":"2026-07-28T04:13:18.863000Z","event_fingerprint":"a723af4b849c5a2971819ea2cdba53eefab28348954b44f3c61ca219b21afd9e","payload":{"connection_id":"f6725804f86a4c4eb588e4d5ed7db029","event_at":"2026-07-28T04:13:18.863000Z","event_type":"price_change","frame_hash":"991198a8c545da1543300670bbcb7382a488b90c85b5cb59e94f849c4840bacc","frame_index":0,"kind":"data","monotonic_ns":313993069443291,"payload":{"event_type":"price_change","market":"0xd412ce774cfcf8dc9f71164aac78783978aac7b03871702a3b8a481bd9dc9688","price_changes":[{"asset_id":"107603864457683460275633293642179940881969192120168665300712204232021063124301","best_ask":"0.43","best_bid":"0.4","hash":"e84f9b19f6b207938353fae9ecad1260a8898ab3","price":"0.4","side":"BUY","size":"57.78"},{"asset_id":"96600821790790307414914106093858868634329285205417149685270682748367152458577","best_ask":"0.6","best_bid":"0.57","hash":"15d1f407272709a4962e4a9a79358e427d34d75a","price":"0.6","side":"SELL","size":"57.78"}],"timestamp":"1785211998863"},"payload_hash":"a22ec7d2dcc8628fa408d8518a8859d56af50b526838c3a6ac7e11f9e8d696b8","raw_frame":"{\"market\":\"0xd412ce774cfcf8dc9f71164aac78783978aac7b03871702a3b8a481bd9dc9688\", \"price_changes\":[{\"asset_id\":\"107603864457683460275633293642179940881969192120168665300712204232021063124301\", \"price\":\"0.4\", \"size\":\"57.78\", \"side\":\"BUY\", \"hash\":\"e84f9b19f6b207938353fae9ecad1260a8898ab3\", \"best_bid\":\"0.4\", \"best_ask\":\"0.43\"}, {\"asset_id\":\"96600821790790307414914106093858868634329285205417149685270682748367152458577\", \"price\":\"0.6\", \"size\":\"57.78\", \"side\":\"SELL\", \"hash\":\"15d1f407272709a4962e4a9a79358e427d34d75a\", \"best_bid\":\"0.57\", \"best_ask\":\"0.6\"}], \"timestamp\":\"1785211998863\", \"event_type\":\"price_change\"}","received_at":"2026-07-28T04:13:29.991426Z","schema_version":"clob-market-ws.price_change.v1","sequence":null,"server_hash":null,"server_timestamp":"1785211998863","session_id":"2d607381e3054cee91998cdf45a4231c","source":"clob_market_ws"},"received_at":"2026-07-28T04:13:29.991426Z","record_id":"8d451b0032beb24777dd1a4b5d8ffad30871dcea4139a5983e9494b022e7b385","schema_fingerprint":"4aa3821a28b0b7c2400bc59aba4bcc0a76e971dadd19610d3ad38c768e124dc7","schema_version":"edge-lab-recorder.raw.v1","sequence":null,"source":"clob_market_ws"}
{"event_at":"2026-07-28T04:13:18.865000Z","event_fingerprint":"b12755b018c64684e10925d2c8f097d663a53cb5787fe9953215b032ead05aee","payload":{"connection_id":"f6725804f86a4c4eb588e4d5ed7db029","event_at":"2026-07-28T04:13:18.865000Z","event_type":"price_change","frame_hash":"c3d1c21ac2c4c009cfdcd7d6744d61d13bc34bfddb4eff8ad7c87218a004d0ea","frame_index":0,"kind":"data","monotonic_ns":313993072427291,"payload":{"event_type":"price_change","market":"0xd412ce774cfcf8dc9f71164aac78783978aac7b03871702a3b8a481bd9dc9688","price_changes":[{"asset_id":"96600821790790307414914106093858868634329285205417149685270682748367152458577","best_ask":"0.6","best_bid":"0.57","hash":"04c9c70efaab3101ec86dfa45c789f07a970967c","price":"0.6","side":"SELL","size":"81.91"},{"asset_id":"107603864457683460275633293642179940881969192120168665300712204232021063124301","best_ask":"0.43","best_bid":"0.4","hash":"9d5ba9c707043e80258f0c57d7d3d58c93ac4d30","price":"0.4","side":"BUY","size":"81.91"}],"timestamp":"1785211998865"},"payload_hash":"c62f1d2e65bced1b045de1f916e0d422a2b06bbf731d524dd3c52693865c2f7b","raw_frame":"{\"market\":\"0xd412ce774cfcf8dc9f71164aac78783978aac7b03871702a3b8a481bd9dc9688\", \"price_changes\":[{\"asset_id\":\"96600821790790307414914106093858868634329285205417149685270682748367152458577\", \"price\":\"0.6\", \"size\":\"81.91\", \"side\":\"SELL\", \"hash\":\"04c9c70efaab3101ec86dfa45c789f07a970967c\", \"best_bid\":\"0.57\", \"best_ask\":\"0.6\"}, {\"asset_id\":\"107603864457683460275633293642179940881969192120168665300712204232021063124301\", \"price\":\"0.4\", \"size\":\"81.91\", \"side\":\"BUY\", \"hash\":\"9d5ba9c707043e80258f0c57d7d3d58c93ac4d30\", \"best_bid\":\"0.4\", \"best_ask\":\"0.43\"}], \"timestamp\":\"1785211998865\", \"event_type\":\"price_change\"}","received_at":"2026-07-28T04:13:29.994410Z","schema_version":"clob-market-ws.price_change.v1","sequence":null,"server_hash":null,"server_timestamp":"1785211998865","session_id":"2d607381e3054cee91998cdf45a4231c","source":"clob_market_ws"},"received_at":"2026-07-28T04:13:29.994410Z","record_id":"b3dda973168919415a53f45e8cd3d31675e97caad93594e4f8d71186b1fbd0dc","schema_fingerprint":"4aa3821a28b0b7c2400bc59aba4bcc0a76e971dadd19610d3ad38c768e124dc7","schema_version":"edge-lab-recorder.raw.v1","sequence":null,"source":"clob_market_ws"}
{"event_at":"2026-07-28T04:13:18.869000Z","event_fingerprint":"27fa8de9a37711502eba425722a390a916a9605a538617036cd33b7548e36096","payload":{"connection_id":"f6725804f86a4c4eb588e4d5ed7db029","event_at":"2026-07-28T04:13:18.869000Z","event_type":"price_change","frame_hash":"4ad888695141926680af2396743a4f285f2b8c20ec6ca54b5519b35f45b9ed6a","frame_index":0,"kind":"data","monotonic_ns":313993075317083,"payload":{"event_type":"price_change","market":"0xd412ce774cfcf8dc9f71164aac78783978aac7b03871702a3b8a481bd9dc9688","price_changes":[{"asset_id":"96600821790790307414914106093858868634329285205417149685270682748367152458577","best_ask":"0.6","best_bid":"0.57","hash":"cb198d9681c4c0f2f638686c31195afb1a7d2b56","price":"0.03","side":"BUY","size":"540"},{"asset_id":"107603864457683460275633293642179940881969192120168665300712204232021063124301","best_ask":"0.43","best_bid":"0.4","hash":"91757dd12270f047c2d71519787944e6bfbbaee9","price":"0.97","side":"SELL","size":"540"}],"timestamp":"1785211998869"},"payload_hash":"572df254e93c50ed5be388661ebbf11f631734823952e2869eb8eb798a0ad721","raw_frame":"{\"market\":\"0xd412ce774cfcf8dc9f71164aac78783978aac7b03871702a3b8a481bd9dc9688\", \"price_changes\":[{\"asset_id\":\"96600821790790307414914106093858868634329285205417149685270682748367152458577\", \"price\":\"0.03\", \"size\":\"540\", \"side\":\"BUY\", \"hash\":\"cb198d9681c4c0f2f638686c31195afb1a7d2b56\", \"best_bid\":\"0.57\", \"best_ask\":\"0.6\"}, {\"asset_id\":\"107603864457683460275633293642179940881969192120168665300712204232021063124301\", \"price\":\"0.97\", \"size\":\"540\", \"side\":\"SELL\", \"hash\":\"91757dd12270f047c2d71519787944e6bfbbaee9\", \"best_bid\":\"0.4\", \"best_ask\":\"0.43\"}], \"timestamp\":\"1785211998869\", \"event_type\":\"price_change\"}","received_at":"2026-07-28T04:13:29.997300Z","schema_version":"clob-market-ws.price_change.v1","sequence":null,"server_hash":null,"server_timestamp":"1785211998869","session_id":"2d607381e3054cee91998cdf45a4231c","source":"clob_market_ws"},"received_at":"2026-07-28T04:13:29.997300Z","record_id":"ba5441e8d75c7d34fa285cbafe1711c04e9abb4eb132d99f0a4a822269a7b34a","schema_fingerprint":"4aa3821a28b0b7c2400bc59aba4bcc0a76e971dadd19610d3ad38c768e124dc7","schema_version":"edge-lab-recorder.raw.v1","sequence":null,"source":"clob_market_ws"}
{"event_at":"2026-07-28T04:13:18.875000Z","event_fingerprint":"135c1691ffe84373b8e4a0d4b4180cc079fa5d738ea85b8e789d05b58f27ff4e","payload":{"connection_id":"f6725804f86a4c4eb588e4d5ed7db029","event_at":"2026-07-28T04:13:18.875000Z","event_type":"price_change","frame_hash":"cd974325a8aa8f3a6205987fdd53c5d62e84d150f5c39aa88811972ea4f1b9ed","frame_index":0,"kind":"data","monotonic_ns":313993078220041,"payload":{"event_type":"price_change","market":"0xd412ce774cfcf8dc9f71164aac78783978aac7b03871702a3b8a481bd9dc9688","price_changes":[{"asset_id":"96600821790790307414914106093858868634329285205417149685270682748367152458577","best_ask":"0.6","best_bid":"0.57","hash":"f16bb6ac4577adde9f9894f2195153a615c5d94f","price":"0.01","side":"BUY","size":"6045.02"},{"asset_id":"107603864457683460275633293642179940881969192120168665300712204232021063124301","best_ask":"0.43","best_bid":"0.4","hash":"2a8c0885130f3573752ba458bc30c0d333c27d70","price":"0.99","side":"SELL","size":"6045.02"}],"timestamp":"1785211998875"},"payload_hash":"b96a70d138151eed9ce63f54e2e2ff319c5e47f8705dbb4688405cc5c584d690","raw_frame":"{\"market\":\"0xd412ce774cfcf8dc9f71164aac78783978aac7b03871702a3b8a481bd9dc9688\", \"price_changes\":[{\"asset_id\":\"96600821790790307414914106093858868634329285205417149685270682748367152458577\", \"price\":\"0.01\", \"size\":\"6045.02\", \"side\":\"BUY\", \"hash\":\"f16bb6ac4577adde9f9894f2195153a615c5d94f\", \"best_bid\":\"0.57\", \"best_ask\":\"0.6\"}, {\"asset_id\":\"107603864457683460275633293642179940881969192120168665300712204232021063124301\", \"price\":\"0.99\", \"size\":\"6045.02\", \"side\":\"SELL\", \"hash\":\"2a8c0885130f3573752ba458bc30c0d333c27d70\", \"best_bid\":\"0.4\", \"best_ask\":\"0.43\"}], \"timestamp\":\"1785211998875\", \"event_type\":\"price_change\"}","received_at":"2026-07-28T04:13:30.000202Z","schema_version":"clob-market-ws.price_change.v1","sequence":null,"server_hash":null,"server_timestamp":"1785211998875","session_id":"2d607381e3054cee91998cdf45a4231c","source":"clob_market_ws"},"received_at":"2026-07-28T04:13:30.000202Z","record_id":"571d40eaa3401a0789093622102247c3797dd42c91e5663488200f087af0600b","schema_fingerprint":"4aa3821a28b0b7c2400bc59aba4bcc0a76e971dadd19610d3ad38c768e124dc7","schema_version":"edge-lab-recorder.raw.v1","sequence":null,"source":"clob_market_ws"}
{"event_at":"2026-07-28T04:13:18.878000Z","event_fingerprint":"bcffc7504d339221eba2988f868e39f4ca81e18da260916469eed53abedf52da","payload":{"connection_id":"f6725804f86a4c4eb588e4d5ed7db029","event_at":"2026-07-28T04:13:18.878000Z","event_type":"best_bid_ask","frame_hash":"3d28005a5019f56f91fb6ec7740585c93b9b678e28da5bd0c06a3215fa6f2c4d","frame_index":0,"kind":"data","monotonic_ns":313993079935208,"payload":{"asset_id":"107603864457683460275633293642179940881969192120168665300712204232021063124301","best_ask":"0.45","best_bid":"0.4","event_type":"best_bid_ask","market":"0xd412ce774cfcf8dc9f71164aac78783978aac7b03871702a3b8a481bd9dc9688","spread":"0.05","timestamp":"1785211998878"},"payload_hash":"beee09d898e18a7f93a01c21b1a242bcab35f1e158f88610d8facd2fa72c27a8","raw_frame":"{\"market\":\"0xd412ce774cfcf8dc9f71164aac78783978aac7b03871702a3b8a481bd9dc9688\", \"asset_id\":\"107603864457683460275633293642179940881969192120168665300712204232021063124301\", \"best_bid\":\"0.4\", \"best_ask\":\"0.45\", \"spread\":\"0.05\", \"timestamp\":\"1785211998878\", \"event_type\":\"best_bid_ask\"}","received_at":"2026-07-28T04:13:30.001917Z","schema_version":"clob-market-ws.best_bid_ask.v1","sequence":null,"server_hash":null,"server_timestamp":"1785211998878","session_id":"2d607381e3054cee91998cdf45a4231c","source":"clob_market_ws"},"received_at":"2026-07-28T04:13:30.001917Z","record_id":"57dd0d84c715b41188aab52632126ade45aefc887231e9854db72e4988801ca6","schema_fingerprint":"8488399f31b0337811b13b266be932db7062827c2470b78bd8e9e99bab51d17d","schema_version":"edge-lab-recorder.raw.v1","sequence":null,"source":"clob_market_ws"}
{"event_at":"2026-07-28T04:13:18.878000Z","event_fingerprint":"82f0eb6b85767f24a0c700875e53723408215d9311243cfe44158c0dd7d4d435","payload":{"connection_id":"f6725804f86a4c4eb588e4d5ed7db029","event_at":"2026-07-28T04:13:18.878000Z","event_type":"best_bid_ask","frame_hash":"7dcb85e71cdac10fa16e8fcbdee8c16b9deac4ab5b8b9a74b37292721216080b","frame_index":0,"kind":"data","monotonic_ns":313993081054833,"payload":{"asset_id":"96600821790790307414914106093858868634329285205417149685270682748367152458577","best_ask":"0.6","best_bid":"0.55","event_type":"best_bid_ask","market":"0xd412ce774cfcf8dc9f71164aac78783978aac7b03871702a3b8a481bd9dc9688","spread":"0.05","timestamp":"1785211998878"},"payload_hash":"25c8037ce07f2cd3690e449b732df3331aec2ccb49de98b43eb8fce94f2a8904","raw_frame":"{\"market\":\"0xd412ce774cfcf8dc9f71164aac78783978aac7b03871702a3b8a481bd9dc9688\", \"asset_id\":\"96600821790790307414914106093858868634329285205417149685270682748367152458577\", \"best_bid\":\"0.55\", \"best_ask\":\"0.6\", \"spread\":\"0.05\", \"timestamp\":\"1785211998878\", \"event_type\":\"best_bid_ask\"}","received_at":"2026-07-28T04:13:30.003036Z","schema_version":"clob-market-ws.best_bid_ask.v1","sequence":null,"server_hash":null,"server_timestamp":"1785211998878","session_id":"2d607381e3054cee91998cdf45a4231c","source":"clob_market_ws"},"received_at":"2026-07-28T04:13:30.003036Z","record_id":"47ff07de6591743e37c8f6d8b82a79644fdbd55050b360c2975566bbe82cc650","schema_fingerprint":"8488399f31b0337811b13b266be932db7062827c2470b78bd8e9e99bab51d17d","schema_version":"edge-lab-recorder.raw.v1","sequence":null,"source":"clob_market_ws"}
{"event_at":"2026-07-28T04:13:18.878000Z","event_fingerprint":"8ee02d311a60afaee9f756a9eeb3dece6e03a84bad0a21450a1a52766f968808","payload":{"connection_id":"f6725804f86a4c4eb588e4d5ed7db029","event_at":"2026-07-28T04:13:18.878000Z","event_type":"price_change","frame_hash":"398d2e3f6befd74a18bcaf9e5662dec10b0d545754047aeb758c7553ea9210f9","frame_index":0,"kind":"data","monotonic_ns":313993083564041,"payload":{"event_type":"price_change","market":"0xd412ce774cfcf8dc9f71164aac78783978aac7b03871702a3b8a481bd9dc9688","price_changes":[{"asset_id":"96600821790790307414914106093858868634329285205417149685270682748367152458577","best_ask":"0.6","best_bid":"0.55","hash":"fac24050089bf25a9bc80a121b6e131f8a3a003c","price":"0.57","side":"BUY","size":"0"},{"asset_id":"107603864457683460275633293642179940881969192120168665300712204232021063124301","best_ask":"0.45","best_bid":"0.4","hash":"27faaff9773b196120be95861a07473188b68ef8","price":"0.43","side":"SELL","size":"0"}],"timestamp":"1785211998878"},"payload_hash":"68927d942df7c5138ea9ee5fdba6baa3e78f8638898f4e3b646e6a83a4e92166","raw_frame":"{\"market\":\"0xd412ce774cfcf8dc9f71164aac78783978aac7b03871702a3b8a481bd9dc9688\", \"price_changes\":[{\"asset_id\":\"96600821790790307414914106093858868634329285205417149685270682748367152458577\", \"price\":\"0.57\", \"size\":\"0\", \"side\":\"BUY\", \"hash\":\"fac24050089bf25a9bc80a121b6e131f8a3a003c\", \"best_bid\":\"0.55\", \"best_ask\":\"0.6\"}, {\"asset_id\":\"107603864457683460275633293642179940881969192120168665300712204232021063124301\", \"price\":\"0.43\", \"size\":\"0\", \"side\":\"SELL\", \"hash\":\"27faaff9773b196120be95861a07473188b68ef8\", \"best_bid\":\"0.4\", \"best_ask\":\"0.45\"}], \"timestamp\":\"1785211998878\", \"event_type\":\"price_change\"}","received_at":"2026-07-28T04:13:30.005546Z","schema_version":"clob-market-ws.price_change.v1","sequence":null,"server_hash":null,"server_timestamp":"1785211998878","session_id":"2d607381e3054cee91998cdf45a4231c","source":"clob_market_ws"},"received_at":"2026-07-28T04:13:30.005546Z","record_id":"b91c975aa788c2e1d9fe0c0066fbd599f934ad77a3864066c1d43e5baca42bbe","schema_fingerprint":"4aa3821a28b0b7c2400bc59aba4bcc0a76e971dadd19610d3ad38c768e124dc7","schema_version":"edge-lab-recorder.raw.v1","sequence":null,"source":"clob_market_ws"}
{"event_at":"2026-07-28T04:13:18.892000Z","event_fingerprint":"d436c24f81bb1d654b5026df819f868b3f977b3d33998103845b6e922f547f04","payload":{"connection_id":"f6725804f86a4c4eb588e4d5ed7db029","event_at":"2026-07-28T04:13:18.892000Z","event_type":"best_bid_ask","frame_hash":"acb72e78e9d5a26439a3ddf8fddbb3742ba92732656f4ffe0acde72e98998712","frame_index":0,"kind":"data","monotonic_ns":313993085916541,"payload":{"asset_id":"107603864457683460275633293642179940881969192120168665300712204232021063124301","best_ask":"0.45","best_bid":"0.41","event_type":"best_bid_ask","market":"0xd412ce774cfcf8dc9f71164aac78783978aac7b03871702a3b8a481bd9dc9688","spread":"0.04","timestamp":"1785211998892"},"payload_hash":"82f9eb9636bd708d7c43998e4a9a0d6bcb6a6f6ee3dcff73e2a9831832fd2c17","raw_frame":"{\"market\":\"0xd412ce774cfcf8dc9f71164aac78783978aac7b03871702a3b8a481bd9dc9688\", \"asset_id\":\"107603864457683460275633293642179940881969192120168665300712204232021063124301\", \"best_bid\":\"0.41\", \"best_ask\":\"0.45\", \"spread\":\"0.04\", \"timestamp\":\"1785211998892\", \"event_type\":\"best_bid_ask\"}","received_at":"2026-07-28T04:13:30.007900Z","schema_version":"clob-market-ws.best_bid_ask.v1","sequence":null,"server_hash":null,"server_timestamp":"1785211998892","session_id":"2d607381e3054cee91998cdf45a4231c","source":"clob_market_ws"},"received_at":"2026-07-28T04:13:30.007900Z","record_id":"186d0053dee81f8e505600bd4da550eeb5ef827f12cb777d5aa0b8de555a74c0","schema_fingerprint":"8488399f31b0337811b13b266be932db7062827c2470b78bd8e9e99bab51d17d","schema_version":"edge-lab-recorder.raw.v1","sequence":null,"source":"clob_market_ws"}
{"event_at":"2026-07-28T04:13:18.892000Z","event_fingerprint":"7d711dd914c0634845366e119ca5adbf2d636c6036fd8565e8db9a2672713333","payload":{"connection_id":"f6725804f86a4c4eb588e4d5ed7db029","event_at":"2026-07-28T04:13:18.892000Z","event_type":"best_bid_ask","frame_hash":"00f3a00a723fb286aa34697bbf1b80913e529e88fa1a6c441adb914dbcea87e3","frame_index":0,"kind":"data","monotonic_ns":313993087812166,"payload":{"asset_id":"96600821790790307414914106093858868634329285205417149685270682748367152458577","best_ask":"0.59","best_bid":"0.55","event_type":"best_bid_ask","market":"0xd412ce774cfcf8dc9f71164aac78783978aac7b03871702a3b8a481bd9dc9688","spread":"0.04","timestamp":"1785211998892"},"payload_hash":"b8e6c83be8423f4a559660a0fdbd943d60e2f4bb8ad65e116d9800d95c2896f9","raw_frame":"{\"market\":\"0xd412ce774cfcf8dc9f71164aac78783978aac7b03871702a3b8a481bd9dc9688\", \"asset_id\":\"96600821790790307414914106093858868634329285205417149685270682748367152458577\", \"best_bid\":\"0.55\", \"best_ask\":\"0.59\", \"spread\":\"0.04\", \"timestamp\":\"1785211998892\", \"event_type\":\"best_bid_ask\"}","received_at":"2026-07-28T04:13:30.009794Z","schema_version":"clob-market-ws.best_bid_ask.v1","sequence":null,"server_hash":null,"server_timestamp":"1785211998892","session_id":"2d607381e3054cee91998cdf45a4231c","source":"clob_market_ws"},"received_at":"2026-07-28T04:13:30.009794Z","record_id":"6ebd729c54988c3150ef5681dac00fcdbcad00623113e868566b18c270687e2d","schema_fingerprint":"8488399f31b0337811b13b266be932db7062827c2470b78bd8e9e99bab51d17d","schema_version":"edge-lab-recorder.raw.v1","sequence":null,"source":"clob_market_ws"}
{"event_at":"2026-07-28T04:13:18.891000Z","event_fingerprint":"88862dfc44c9cb22036091dd35e3acc15b27a4f7923e68f592fe6bf1d14379a7","payload":{"connection_id":"f6725804f86a4c4eb588e4d5ed7db029","event_at":"2026-07-28T04:13:18.891000Z","event_type":"price_change","frame_hash":"5235b4d38045eccdb96f8e8d904edeed778f87c12f226e3ff97c64f58212ac8a","frame_index":0,"kind":"data","monotonic_ns":313993090369416,"payload":{"event_type":"price_change","market":"0xd412ce774cfcf8dc9f71164aac78783978aac7b03871702a3b8a481bd9dc9688","price_changes":[{"asset_id":"107603864457683460275633293642179940881969192120168665300712204232021063124301","best_ask":"0.45","best_bid":"0.41","hash":"6e6be6f313d56601cbe2c4e95f4e3826b0f88af5","price":"0.41","side":"BUY","size":"6"},{"asset_id":"96600821790790307414914106093858868634329285205417149685270682748367152458577","best_ask":"0.59","best_bid":"0.55","hash":"64175a0b1789c4bdd49a06f6fa7f5dd3c3ada952","price":"0.59","side":"SELL","size":"6"}],"timestamp":"1785211998891"},"payload_hash":"b524584df6cb5b76700447e62b123570c8a6e5a590ba3a27fa1bbf1b8501e7b0","raw_frame":"{\"market\":\"0xd412ce774cfcf8dc9f71164aac78783978aac7b03871702a3b8a481bd9dc9688\", \"price_changes\":[{\"asset_id\":\"107603864457683460275633293642179940881969192120168665300712204232021063124301\", \"price\":\"0.41\", \"size\":\"6\", \"side\":\"BUY\", \"hash\":\"6e6be6f313d56601cbe2c4e95f4e3826b0f88af5\", \"best_bid\":\"0.41\", \"best_ask\":\"0.45\"}, {\"asset_id\":\"96600821790790307414914106093858868634329285205417149685270682748367152458577\", \"price\":\"0.59\", \"size\":\"6\", \"side\":\"SELL\", \"hash\":\"64175a0b1789c4bdd49a06f6fa7f5dd3c3ada952\", \"best_bid\":\"0.55\", \"best_ask\":\"0.59\"}], \"timestamp\":\"1785211998891\", \"event_type\":\"price_change\"}","received_at":"2026-07-28T04:13:30.012352Z","schema_version":"clob-market-ws.price_change.v1","sequence":null,"server_hash":null,"server_timestamp":"1785211998891","session_id":"2d607381e3054cee91998cdf45a4231c","source":"clob_market_ws"},"received_at":"2026-07-28T04:13:30.012352Z","record_id":"fc9a929019e18cd629c93f23d220d1116c29b6fb8f8b68d1330d7c7c8c25fc5d","schema_fingerprint":"4aa3821a28b0b7c2400bc59aba4bcc0a76e971dadd19610d3ad38c768e124dc7","schema_version":"edge-lab-recorder.raw.v1","sequence":null,"source":"clob_market_ws"}
{"event_at":"2026-07-28T04:13:18.895000Z","event_fingerprint":"726389a75e36beb5f2a5b2aab3e73ca0915f971b41b2e56c4444bbbbde9bde18","payload":{"connection_id":"f6725804f86a4c4eb588e4d5ed7db029","event_at":"2026-07-28T04:13:18.895000Z","event_type":"best_bid_ask","frame_hash":"df258521956813df9f9937d4c8f20d6325485ed3ddab4ed7bf5bfb3c9f939494","frame_index":0,"kind":"data","monotonic_ns":313993093334166,"payload":{"asset_id":"107603864457683460275633293642179940881969192120168665300712204232021063124301","best_ask":"0.45","best_bid":"0.4","event_type":"best_bid_ask","market":"0xd412ce774cfcf8dc9f71164aac78783978aac7b03871702a3b8a481bd9dc9688","spread":"0.05","timestamp":"1785211998895"},"payload_hash":"83b3ceb6159dcfdd977bb2d6e7bbbf9931c9ef368633faee6c552ed52f1bad3f","raw_frame":"{\"market\":\"0xd412ce774cfcf8dc9f71164aac78783978aac7b03871702a3b8a481bd9dc9688\", \"asset_id\":\"107603864457683460275633293642179940881969192120168665300712204232021063124301\", \"best_bid\":\"0.4\", \"best_ask\":\"0.45\", \"spread\":\"0.05\", \"timestamp\":\"1785211998895\", \"event_type\":\"best_bid_ask\"}","received_at":"2026-07-28T04:13:30.015318Z","schema_version":"clob-market-ws.best_bid_ask.v1","sequence":null,"server_hash":null,"server_timestamp":"1785211998895","session_id":"2d607381e3054cee91998cdf45a4231c","source":"clob_market_ws"},"received_at":"2026-07-28T04:13:30.015318Z","record_id":"02d9fa195783abfd47e20ce34b3c634a647d50656098f3f68e0bd3cfe02dbb5e","schema_fingerprint":"8488399f31b0337811b13b266be932db7062827c2470b78bd8e9e99bab51d17d","schema_version":"edge-lab-recorder.raw.v1","sequence":null,"source":"clob_market_ws"}
{"event_at":"2026-07-28T04:13:18.895000Z","event_fingerprint":"4e12d1852957d7c17ef5360a083a8a406b57b49055bfef62dbd31fb66ca0a8b3","payload":{"connection_id":"f6725804f86a4c4eb588e4d5ed7db029","event_at":"2026-07-28T04:13:18.895000Z","event_type":"best_bid_ask","frame_hash":"e5d34383fd7a6eee2e321fc182c3e31a7aa947a146c3146d008d2f1d86d7ef0a","frame_index":0,"kind":"data","monotonic_ns":313993095389458,"payload":{"asset_id":"96600821790790307414914106093858868634329285205417149685270682748367152458577","best_ask":"0.6","best_bid":"0.55","event_type":"best_bid_ask","market":"0xd412ce774cfcf8dc9f71164aac78783978aac7b03871702a3b8a481bd9dc9688","spread":"0.05","timestamp":"1785211998895"},"payload_hash":"94e2eafe6e18926c4098590d0b8b8f530e25cbdf087f8be6689b07ec3ca1b421","raw_frame":"{\"market\":\"0xd412ce774cfcf8dc9f71164aac78783978aac7b03871702a3b8a481bd9dc9688\", \"asset_id\":\"96600821790790307414914106093858868634329285205417149685270682748367152458577\", \"best_bid\":\"0.55\", \"best_ask\":\"0.6\", \"spread\":\"0.05\", \"timestamp\":\"1785211998895\", \"event_type\":\"best_bid_ask\"}","received_at":"2026-07-28T04:13:30.017373Z","schema_version":"clob-market-ws.best_bid_ask.v1","sequence":null,"server_hash":null,"server_timestamp":"1785211998895","session_id":"2d607381e3054cee91998cdf45a4231c","source":"clob_market_ws"},"received_at":"2026-07-28T04:13:30.017373Z","record_id":"711fe66614c3af195b689302696def2a67d776713513461a4b6ab7a6bb37bf4c","schema_fingerprint":"8488399f31b0337811b13b266be932db7062827c2470b78bd8e9e99bab51d17d","schema_version":"edge-lab-recorder.raw.v1","sequence":null,"source":"clob_market_ws"}
{"event_at":"2026-07-28T04:13:18.895000Z","event_fingerprint":"b61b17b25c33d1affce802009424f81bb51d3d915a6521c26d2876fe15630fa6","payload":{"connection_id":"f6725804f86a4c4eb588e4d5ed7db029","event_at":"2026-07-28T04:13:18.895000Z","event_type":"price_change","frame_hash":"6d401944640e5c63d5802c232b5d3f7c6916bbdb6c63bcea687c464927987215","frame_index":0,"kind":"data","monotonic_ns":313993097589500,"payload":{"event_type":"price_change","market":"0xd412ce774cfcf8dc9f71164aac78783978aac7b03871702a3b8a481bd9dc9688","price_changes":[{"asset_id":"107603864457683460275633293642179940881969192120168665300712204232021063124301","best_ask":"0.45","best_bid":"0.4","hash":"96637371d27cb8dd1ca1c51082cf8d1c90c02a13","price":"0.41","side":"BUY","size":"0"},{"asset_id":"96600821790790307414914106093858868634329285205417149685270682748367152458577","best_ask":"0.6","best_bid":"0.55","hash":"1dd4c4736dbfe10ef54c8e3f0efbd9593687097a","price":"0.59","side":"SELL","size":"0"}],"timestamp":"1785211998895"},"payload_hash":"89ec60295c8c12111ccafca2125a577f26fee291aa1aa19cd0676ad7df0dc989","raw_frame":"{\"market\":\"0xd412ce774cfcf8dc9f71164aac78783978aac7b03871702a3b8a481bd9dc9688\", \"price_changes\":[{\"asset_id\":\"107603864457683460275633293642179940881969192120168665300712204232021063124301\", \"price\":\"0.41\", \"size\":\"0\", \"side\":\"BUY\", \"hash\":\"96637371d27cb8dd1ca1c51082cf8d1c90c02a13\", \"best_bid\":\"0.4\", \"best_ask\":\"0.45\"}, {\"asset_id\":\"96600821790790307414914106093858868634329285205417149685270682748367152458577\", \"price\":\"0.59\", \"size\":\"0\", \"side\":\"SELL\", \"hash\":\"1dd4c4736dbfe10ef54c8e3f0efbd9593687097a\", \"best_bid\":\"0.55\", \"best_ask\":\"0.6\"}], \"timestamp\":\"1785211998895\", \"event_type\":\"price_change\"}","received_at":"2026-07-28T04:13:30.019572Z","schema_version":"clob-market-ws.price_change.v1","sequence":null,"server_hash":null,"server_timestamp":"1785211998895","session_id":"2d607381e3054cee91998cdf45a4231c","source":"clob_market_ws"},"received_at":"2026-07-28T04:13:30.019572Z","record_id":"16afa58011454b3aea91e4063505a13eb94475c660f37ccb18fb35e658563c95","schema_fingerprint":"4aa3821a28b0b7c2400bc59aba4bcc0a76e971dadd19610d3ad38c768e124dc7","schema_version":"edge-lab-recorder.raw.v1","sequence":null,"source":"clob_market_ws"}
{"event_at":"2026-07-28T04:13:18.900000Z","event_fingerprint":"bedf228fbf2ecb914252d23765d9f52e5681ed1224969039ba74f1baa8d79ca1","payload":{"connection_id":"f6725804f86a4c4eb588e4d5ed7db029","event_at":"2026-07-28T04:13:18.900000Z","event_type":"best_bid_ask","frame_hash":"18118440a9453fffe500cc854f1e0900cf04ca5c1b8131a1c3389a40a9696f43","frame_index":0,"kind":"data","monotonic_ns":313993099189833,"payload":{"asset_id":"107603864457683460275633293642179940881969192120168665300712204232021063124301","best_ask":"0.45","best_bid":"0.41","event_type":"best_bid_ask","market":"0xd412ce774cfcf8dc9f71164aac78783978aac7b03871702a3b8a481bd9dc9688","spread":"0.04","timestamp":"1785211998900"},"payload_hash":"bd48b448397d449425c3e33af391ebc8e9f57fb7e208bb319cb5835366e3b240","raw_frame":"{\"market\":\"0xd412ce774cfcf8dc9f71164aac78783978aac7b03871702a3b8a481bd9dc9688\", \"asset_id\":\"107603864457683460275633293642179940881969192120168665300712204232021063124301\", \"best_bid\":\"0.41\", \"best_ask\":\"0.45\", \"spread\":\"0.04\", \"timestamp\":\"1785211998900\", \"event_type\":\"best_bid_ask\"}","received_at":"2026-07-28T04:13:30.021171Z","schema_version":"clob-market-ws.best_bid_ask.v1","sequence":null,"server_hash":null,"server_timestamp":"1785211998900","session_id":"2d607381e3054cee91998cdf45a4231c","source":"clob_market_ws"},"received_at":"2026-07-28T04:13:30.021171Z","record_id":"1723725d79191452fe6bc8907752f04ad4d9da2c59ab596f2608210073de61fa","schema_fingerprint":"8488399f31b0337811b13b266be932db7062827c2470b78bd8e9e99bab51d17d","schema_version":"edge-lab-recorder.raw.v1","sequence":null,"source":"clob_market_ws"}
{"event_at":"2026-07-28T04:13:18.900000Z","event_fingerprint":"9fda76dcfb62b655d848071c6c2a0a8483b14d325cde466e03b9b314578449b5","payload":{"connection_id":"f6725804f86a4c4eb588e4d5ed7db029","event_at":"2026-07-28T04:13:18.900000Z","event_type":"best_bid_ask","frame_hash":"b2052c6275e14ffc521cd29433723de58c9208bcb8b375327e97d672f2700d66","frame_index":0,"kind":"data","monotonic_ns":313993100283500,"payload":{"asset_id":"96600821790790307414914106093858868634329285205417149685270682748367152458577","best_ask":"0.59","best_bid":"0.55","event_type":"best_bid_ask","market":"0xd412ce774cfcf8dc9f71164aac78783978aac7b03871702a3b8a481bd9dc9688","spread":"0.04","timestamp":"1785211998900"},"payload_hash":"bc00fc8c50437e17da355d5957c445807d079f4c6a361ada3a89d158bd8068a5","raw_frame":"{\"market\":\"0xd412ce774cfcf8dc9f71164aac78783978aac7b03871702a3b8a481bd9dc9688\", \"asset_id\":\"96600821790790307414914106093858868634329285205417149685270682748367152458577\", \"best_bid\":\"0.55\", \"best_ask\":\"0.59\", \"spread\":\"0.04\", \"timestamp\":\"1785211998900\", \"event_type\":\"best_bid_ask\"}","received_at":"2026-07-28T04:13:30.022265Z","schema_version":"clob-market-ws.best_bid_ask.v1","sequence":null,"server_hash":null,"server_timestamp":"1785211998900","session_id":"2d607381e3054cee91998cdf45a4231c","source":"clob_market_ws"},"received_at":"2026-07-28T04:13:30.022265Z","record_id":"7cf2b3574750704be24d467a046a987d314acb4fba3030d3122a641e8ce0ddc2","schema_fingerprint":"8488399f31b0337811b13b266be932db7062827c2470b78bd8e9e99bab51d17d","schema_version":"edge-lab-recorder.raw.v1","sequence":null,"source":"clob_market_ws"}
{"event_at":"2026-07-28T04:13:18.900000Z","event_fingerprint":"e752f62d07453e0304f995e3fb6e3cdbd9fca93ff3368667517b7d3dae4be511","payload":{"connection_id":"f6725804f86a4c4eb588e4d5ed7db029","event_at":"2026-07-28T04:13:18.900000Z","event_type":"price_change","frame_hash":"8c47d44ba15db5dc40aab2e297d82531fc50b9eec8f9257cad721ecc0e39e2d1","frame_index":0,"kind":"data","monotonic_ns":313993101360041,"payload":{"event_type":"price_change","market":"0xd412ce774cfcf8dc9f71164aac78783978aac7b03871702a3b8a481bd9dc9688","price_changes":[{"asset_id":"107603864457683460275633293642179940881969192120168665300712204232021063124301","best_ask":"0.45","best_bid":"0.41","hash":"97cd4309438681b5ef33e2bdee603b33a564577b","price":"0.41","side":"BUY","size":"6"},{"asset_id":"96600821790790307414914106093858868634329285205417149685270682748367152458577","best_ask":"0.59","best_bid":"0.55","hash":"6f9f72cdf2f6e2dae6526a4d0c1fdf886d9e02ca","price":"0.59","side":"SELL","size":"6"}],"timestamp":"1785211998900"},"payload_hash":"1fa8361311d818995a86161993a55dc47c205ad9afab224be63745654952c24b","raw_frame":"{\"market\":\"0xd412ce774cfcf8dc9f71164aac78783978aac7b03871702a3b8a481bd9dc9688\", \"price_changes\":[{\"asset_id\":\"107603864457683460275633293642179940881969192120168665300712204232021063124301\", \"price\":\"0.41\", \"size\":\"6\", \"side\":\"BUY\", \"hash\":\"97cd4309438681b5ef33e2bdee603b33a564577b\", \"best_bid\":\"0.41\", \"best_ask\":\"0.45\"}, {\"asset_id\":\"96600821790790307414914106093858868634329285205417149685270682748367152458577\", \"price\":\"0.59\", \"size\":\"6\", \"side\":\"SELL\", \"hash\":\"6f9f72cdf2f6e2dae6526a4d0c1fdf886d9e02ca\", \"best_bid\":\"0.55\", \"best_ask\":\"0.59\"}], \"timestamp\":\"1785211998900\", \"event_type\":\"price_change\"}","received_at":"2026-07-28T04:13:30.023342Z","schema_version":"clob-market-ws.price_change.v1","sequence":null,"server_hash":null,"server_timestamp":"1785211998900","session_id":"2d607381e3054cee91998cdf45a4231c","source":"clob_market_ws"},"received_at":"2026-07-28T04:13:30.023342Z","record_id":"cff88b9042a29efaf78ce578d02225c5f414ecae0e45de5cb8302c96da31cb2a","schema_fingerprint":"4aa3821a28b0b7c2400bc59aba4bcc0a76e971dadd19610d3ad38c768e124dc7","schema_version":"edge-lab-recorder.raw.v1","sequence":null,"source":"clob_market_ws"}
{"event_at":"2026-07-28T04:13:18.909000Z","event_fingerprint":"859c755b7691344b07fb03b53c235ef1101a2dadae425e8b1c833facecd2d5d3","payload":{"connection_id":"f6725804f86a4c4eb588e4d5ed7db029","event_at":"2026-07-28T04:13:18.909000Z","event_type":"best_bid_ask","frame_hash":"d8fc842c8966a2583e8abd489a5bff6b58db5d55d50262b3e29dbe39b33cfbd6","frame_index":0,"kind":"data","monotonic_ns":313993102888750,"payload":{"asset_id":"107603864457683460275633293642179940881969192120168665300712204232021063124301","best_ask":"0.45","best_bid":"0.4","event_type":"best_bid_ask","market":"0xd412ce774cfcf8dc9f71164aac78783978aac7b03871702a3b8a481bd9dc9688","spread":"0.05","timestamp":"1785211998909"},"payload_hash":"152ec5d81604f5a867c45eb3dc5ffe4010daafa4494f7a0e6e3fd0029b2b864b","raw_frame":"{\"market\":\"0xd412ce774cfcf8dc9f71164aac78783978aac7b03871702a3b8a481bd9dc9688\", \"asset_id\":\"107603864457683460275633293642179940881969192120168665300712204232021063124301\", \"best_bid\":\"0.4\", \"best_ask\":\"0.45\", \"spread\":\"0.05\", \"timestamp\":\"1785211998909\", \"event_type\":\"best_bid_ask\"}","received_at":"2026-07-28T04:13:30.024871Z","schema_version":"clob-market-ws.best_bid_ask.v1","sequence":null,"server_hash":null,"server_timestamp":"1785211998909","session_id":"2d607381e3054cee91998cdf45a4231c","source":"clob_market_ws"},"received_at":"2026-07-28T04:13:30.024871Z","record_id":"ad4536c016295a0558bcd33f5c11630eeba5f5624a2643ded8c4bc4a9614c425","schema_fingerprint":"8488399f31b0337811b13b266be932db7062827c2470b78bd8e9e99bab51d17d","schema_version":"edge-lab-recorder.raw.v1","sequence":null,"source":"clob_market_ws"}
{"event_at":"2026-07-28T04:13:18.909000Z","event_fingerprint":"e3801ef7458f2523e7bb2362dc08db8c45a5d83caee2c8e27faa45303c242df3","payload":{"connection_id":"f6725804f86a4c4eb588e4d5ed7db029","event_at":"2026-07-28T04:13:18.909000Z","event_type":"best_bid_ask","frame_hash":"49a59f566058f147eb0812e274cab5fe473c5c6419a8245cb3e3a5533105fd92","frame_index":0,"kind":"data","monotonic_ns":313993103951958,"payload":{"asset_id":"96600821790790307414914106093858868634329285205417149685270682748367152458577","best_ask":"0.6","best_bid":"0.55","event_type":"best_bid_ask","market":"0xd412ce774cfcf8dc9f71164aac78783978aac7b03871702a3b8a481bd9dc9688","spread":"0.05","timestamp":"1785211998909"},"payload_hash":"e233e1452976c1142edfcffeb54d720a047c80dd24bbc808faa71befa638c242","raw_frame":"{\"market\":\"0xd412ce774cfcf8dc9f71164aac78783978aac7b03871702a3b8a481bd9dc9688\", \"asset_id\":\"96600821790790307414914106093858868634329285205417149685270682748367152458577\", \"best_bid\":\"0.55\", \"best_ask\":\"0.6\", \"spread\":\"0.05\", \"timestamp\":\"1785211998909\", \"event_type\":\"best_bid_ask\"}","received_at":"2026-07-28T04:13:30.025934Z","schema_version":"clob-market-ws.best_bid_ask.v1","sequence":null,"server_hash":null,"server_timestamp":"1785211998909","session_id":"2d607381e3054cee91998cdf45a4231c","source":"clob_market_ws"},"received_at":"2026-07-28T04:13:30.025934Z","record_id":"44b34ac65c4ec97f4d1835f17c5968887b9f395b806f7e6a489781958b926c3b","schema_fingerprint":"8488399f31b0337811b13b266be932db7062827c2470b78bd8e9e99bab51d17d","schema_version":"edge-lab-recorder.raw.v1","sequence":null,"source":"clob_market_ws"}
