{"event_at":"2026-07-28T04:02:08.347000Z","event_fingerprint":"3081c48023fc8432ee9f758aec3ea9fd678912e0f437e034aba2882296aa51e7","payload":{"connection_id":"f6725804f86a4c4eb588e4d5ed7db029","event_at":"2026-07-28T04:02:08.347000Z","event_type":"best_bid_ask","frame_hash":"c76d936e372557c766e506eb3f38585c9809a9e65fc9220472b5fe4a269f95ae","frame_index":0,"kind":"data","monotonic_ns":313312224720791,"payload":{"asset_id":"107603864457683460275633293642179940881969192120168665300712204232021063124301","best_ask":"0.43","best_bid":"0.4","event_type":"best_bid_ask","market":"0xd412ce774cfcf8dc9f71164aac78783978aac7b03871702a3b8a481bd9dc9688","spread":"0.03","timestamp":"1785211328347"},"payload_hash":"ac874f657c1aa7773f7ab8290898d04e08cfc448e96f65d7d5bbdd2cb6991318","raw_frame":"{\"market\":\"0xd412ce774cfcf8dc9f71164aac78783978aac7b03871702a3b8a481bd9dc9688\", \"asset_id\":\"107603864457683460275633293642179940881969192120168665300712204232021063124301\", \"best_bid\":\"0.4\", \"best_ask\":\"0.43\", \"spread\":\"0.03\", \"timestamp\":\"1785211328347\", \"event_type\":\"best_bid_ask\"}","received_at":"2026-07-28T04:02:09.175850Z","schema_version":"clob-market-ws.best_bid_ask.v1","sequence":null,"server_hash":null,"server_timestamp":"1785211328347","session_id":"2d607381e3054cee91998cdf45a4231c","source":"clob_market_ws"},"received_at":"2026-07-28T04:02:09.175850Z","record_id":"a3b39a72866d857c0a6e224eca82dd0c1fab08fe510eb12391858588b1e45d21","schema_fingerprint":"8488399f31b0337811b13b266be932db7062827c2470b78bd8e9e99bab51d17d","schema_version":"edge-lab-recorder.raw.v1","sequence":null,"source":"clob_market_ws"}
{"event_at":"2026-07-28T04:02:08.347000Z","event_fingerprint":"cc85a6647c130c6c4d8f442a488c6d0b52bd6646ffd0645ec74e5217b9e58648","payload":{"connection_id":"f6725804f86a4c4eb588e4d5ed7db029","event_at":"2026-07-28T04:02:08.347000Z","event_type":"best_bid_ask","frame_hash":"7892686ad961f1e35f076e1e64e58a6d4b83f7bb6acd127db08c635af5f1298f","frame_index":0,"kind":"data","monotonic_ns":313312226570083,"payload":{"asset_id":"96600821790790307414914106093858868634329285205417149685270682748367152458577","best_ask":"0.6","best_bid":"0.57","event_type":"best_bid_ask","market":"0xd412ce774cfcf8dc9f71164aac78783978aac7b03871702a3b8a481bd9dc9688","spread":"0.03","timestamp":"1785211328347"},"payload_hash":"f0f7a669a3605a25e50424a7747243fab1c1aeb0633dee668ed6b5d610e3fa80","raw_frame":"{\"market\":\"0xd412ce774cfcf8dc9f71164aac78783978aac7b03871702a3b8a481bd9dc9688\", \"asset_id\":\"96600821790790307414914106093858868634329285205417149685270682748367152458577\", \"best_bid\":\"0.57\", \"best_ask\":\"0.6\", \"spread\":\"0.03\", \"timestamp\":\"1785211328347\", \"event_type\":\"best_bid_ask\"}","received_at":"2026-07-28T04:02:09.177702Z","schema_version":"clob-market-ws.best_bid_ask.v1","sequence":null,"server_hash":null,"server_timestamp":"1785211328347","session_id":"2d607381e3054cee91998cdf45a4231c","source":"clob_market_ws"},"received_at":"2026-07-28T04:02:09.177702Z","record_id":"ef316e5a43bae2a0ee76e68ddb0c10b29bdaf84dd426b154619da113b2f268fd","schema_fingerprint":"8488399f31b0337811b13b266be932db7062827c2470b78bd8e9e99bab51d17d","schema_version":"edge-lab-recorder.raw.v1","sequence":null,"source":"clob_market_ws"}
{"event_at":"2026-07-28T04:02:08.347000Z","event_fingerprint":"79eeeff2a54e688ca12f8f12efff7d01453f9e0188defab730a935d4f6088acb","payload":{"connection_id":"f6725804f86a4c4eb588e4d5ed7db029","event_at":"2026-07-28T04:02:08.347000Z","event_type":"price_change","frame_hash":"1c31ed55336cd879b5fde290f453ffc0911adeca9e02cc7f8b213fe13b6b09d3","frame_index":0,"kind":"data","monotonic_ns":313312227653625,"payload":{"event_type":"price_change","market":"0xd412ce774cfcf8dc9f71164aac78783978aac7b03871702a3b8a481bd9dc9688","price_changes":[{"asset_id":"107603864457683460275633293642179940881969192120168665300712204232021063124301","best_ask":"0.43","best_bid":"0.4","hash":"b8bc962b6304fb0250af8e9f9b1be5f201bfbf02","price":"0.42","side":"SELL","size":"0"},{"asset_id":"96600821790790307414914106093858868634329285205417149685270682748367152458577","best_ask":"0.6","best_bid":"0.57","hash":"15ddf517f62a5046eaa7e4e88f353f6a75af942d","price":"0.58","side":"BUY","size":"0"}],"timestamp":"1785211328347"},"payload_hash":"48270773b565260988e681a84ba56c39e488f083f6ef9b4bccb6b571871ac9b6","raw_frame":"{\"market\":\"0xd412ce774cfcf8dc9f71164aac78783978aac7b03871702a3b8a481bd9dc9688\", \"price_changes\":[{\"asset_id\":\"107603864457683460275633293642179940881969192120168665300712204232021063124301\", \"price\":\"0.42\", \"size\":\"0\", \"side\":\"SELL\", \"hash\":\"b8bc962b6304fb0250af8e9f9b1be5f201bfbf02\", \"best_bid\":\"0.4\", \"best_ask\":\"0.43\"}, {\"asset_id\":\"96600821790790307414914106093858868634329285205417149685270682748367152458577\", \"price\":\"0.58\", \"size\":\"0\", \"side\":\"BUY\", \"hash\":\"15ddf517f62a5046eaa7e4e88f353f6a75af942d\", \"best_bid\":\"0.57\", \"best_ask\":\"0.6\"}], \"timestamp\":\"1785211328347\", \"event_type\":\"price_change\"}","received_at":"2026-07-28T04:02:09.178784Z","schema_version":"clob-market-ws.price_change.v1","sequence":null,"server_hash":null,"server_timestamp":"1785211328347","session_id":"2d607381e3054cee91998cdf45a4231c","source":"clob_market_ws"},"received_at":"2026-07-28T04:02:09.178784Z","record_id":"4b8e8542b04d5886d974ace8e66b0a0cc71c50169636b5ee72753e54203fb012","schema_fingerprint":"4aa3821a28b0b7c2400bc59aba4bcc0a76e971dadd19610d3ad38c768e124dc7","schema_version":"edge-lab-recorder.raw.v1","sequence":null,"source":"clob_market_ws"}
{"event_at":"2026-07-28T04:02:08.352000Z","event_fingerprint":"50950cae103f8dc2a76bd029392b839f6ea9ec01a0b3acb30e41553b6be09589","payload":{"connection_id":"f6725804f86a4c4eb588e4d5ed7db029","event_at":"2026-07-28T04:02:08.352000Z","event_type":"best_bid_ask","frame_hash":"5fd8e6e88e33526bdab6952cbb72a845a19ed3ea2a73522f1a7a38846d6ad54a","frame_index":0,"kind":"data","monotonic_ns":313312229248625,"payload":{"asset_id":"107603864457683460275633293642179940881969192120168665300712204232021063124301","best_ask":"0.43","best_bid":"0.41","event_type":"best_bid_ask","market":"0xd412ce774cfcf8dc9f71164aac78783978aac7b03871702a3b8a481bd9dc9688","spread":"0.02","timestamp":"1785211328352"},"payload_hash":"c318344812791d7f906d26550bfbe0f7105f17ed6b59bc614f7922855231eb6c","raw_frame":"{\"market\":\"0xd412ce774cfcf8dc9f71164aac78783978aac7b03871702a3b8a481bd9dc9688\", \"asset_id\":\"107603864457683460275633293642179940881969192120168665300712204232021063124301\", \"best_bid\":\"0.41\", \"best_ask\":\"0.43\", \"spread\":\"0.02\", \"timestamp\":\"1785211328352\", \"event_type\":\"best_bid_ask\"}","received_at":"2026-07-28T04:02:09.180379Z","schema_version":"clob-market-ws.best_bid_ask.v1","sequence":null,"server_hash":null,"server_timestamp":"1785211328352","session_id":"2d607381e3054cee91998cdf45a4231c","source":"clob_market_ws"},"received_at":"2026-07-28T04:02:09.180379Z","record_id":"e492f0698730639519fc93f91c2c48cab90b88d42dc8029faef7498dbe9b57f1","schema_fingerprint":"8488399f31b0337811b13b266be932db7062827c2470b78bd8e9e99bab51d17d","schema_version":"edge-lab-recorder.raw.v1","sequence":null,"source":"clob_market_ws"}
{"event_at":"2026-07-28T04:02:08.352000Z","event_fingerprint":"c23534e03785e91dd7a132943102ca935aa5ee2713ea09180019cb86ba6b26cb","payload":{"connection_id":"f6725804f86a4c4eb588e4d5ed7db029","event_at":"2026-07-28T04:02:08.352000Z","event_type":"best_bid_ask","frame_hash":"ec0a3c4dc7edeea318f99bd92c5b9c5ff7f7bab7714a6780a763d60d8d1f8ebf","frame_index":0,"kind":"data","monotonic_ns":313312230309666,"payload":{"asset_id":"96600821790790307414914106093858868634329285205417149685270682748367152458577","best_ask":"0.59","best_bid":"0.57","event_type":"best_bid_ask","market":"0xd412ce774cfcf8dc9f71164aac78783978aac7b03871702a3b8a481bd9dc9688","spread":"0.02","timestamp":"1785211328352"},"payload_hash":"f3cb0bb687a07e60ce662f2cbb0aee266cfa5e46c29234491880ea3c768a93f3","raw_frame":"{\"market\":\"0xd412ce774cfcf8dc9f71164aac78783978aac7b03871702a3b8a481bd9dc9688\", \"asset_id\":\"96600821790790307414914106093858868634329285205417149685270682748367152458577\", \"best_bid\":\"0.57\", \"best_ask\":\"0.59\", \"spread\":\"0.02\", \"timestamp\":\"1785211328352\", \"event_type\":\"best_bid_ask\"}","received_at":"2026-07-28T04:02:09.181443Z","schema_version":"clob-market-ws.best_bid_ask.v1","sequence":null,"server_hash":null,"server_timestamp":"1785211328352","session_id":"2d607381e3054cee91998cdf45a4231c","source":"clob_market_ws"},"received_at":"2026-07-28T04:02:09.181443Z","record_id":"28b11f92b3b1fb5315abace83fc74781722901ea66252b234c3deb92cf7b5886","schema_fingerprint":"8488399f31b0337811b13b266be932db7062827c2470b78bd8e9e99bab51d17d","schema_version":"edge-lab-recorder.raw.v1","sequence":null,"source":"clob_market_ws"}
{"event_at":"2026-07-28T04:02:08.352000Z","event_fingerprint":"f470ae850792b838833c43d9347fe2c69eda4ff55abf6e96cc2a8e3d03d937ef","payload":{"connection_id":"f6725804f86a4c4eb588e4d5ed7db029","event_at":"2026-07-28T04:02:08.352000Z","event_type":"price_change","frame_hash":"ded7d8ecc9c7c0888ccf86ea9d0e8b7cc85fdc34b6b889a371f0e55e603894ac","frame_index":0,"kind":"data","monotonic_ns":313312231357000,"payload":{"event_type":"price_change","market":"0xd412ce774cfcf8dc9f71164aac78783978aac7b03871702a3b8a481bd9dc9688","price_changes":[{"asset_id":"107603864457683460275633293642179940881969192120168665300712204232021063124301","best_ask":"0.43","best_bid":"0.41","hash":"ecde93756a8bb633ac5792270d74ef39feffc1d3","price":"0.41","side":"BUY","size":"6"},{"asset_id":"96600821790790307414914106093858868634329285205417149685270682748367152458577","best_ask":"0.59","best_bid":"0.57","hash":"2c6071688a8af200aac4d5ffd2388e01ca5f153e","price":"0.59","side":"SELL","size":"6"}],"timestamp":"1785211328352"},"payload_hash":"7b562ae8f1d379dfc9c8d501a5291fd595845dc211b18f7c2c0591ae15f43efd","raw_frame":"{\"market\":\"0xd412ce774cfcf8dc9f71164aac78783978aac7b03871702a3b8a481bd9dc9688\", \"price_changes\":[{\"asset_id\":\"107603864457683460275633293642179940881969192120168665300712204232021063124301\", \"price\":\"0.41\", \"size\":\"6\", \"side\":\"BUY\", \"hash\":\"ecde93756a8bb633ac5792270d74ef39feffc1d3\", \"best_bid\":\"0.41\", \"best_ask\":\"0.43\"}, {\"asset_id\":\"96600821790790307414914106093858868634329285205417149685270682748367152458577\", \"price\":\"0.59\", \"size\":\"6\", \"side\":\"SELL\", \"hash\":\"2c6071688a8af200aac4d5ffd2388e01ca5f153e\", \"best_bid\":\"0.57\", \"best_ask\":\"0.59\"}], \"timestamp\":\"1785211328352\", \"event_type\":\"price_change\"}","received_at":"2026-07-28T04:02:09.182490Z","schema_version":"clob-market-ws.price_change.v1","sequence":null,"server_hash":null,"server_timestamp":"1785211328352","session_id":"2d607381e3054cee91998cdf45a4231c","source":"clob_market_ws"},"received_at":"2026-07-28T04:02:09.182490Z","record_id":"193a67818df6f16ee6c5fecab71205a288f0937549f12ea68c9d972e08ce9eda","schema_fingerprint":"4aa3821a28b0b7c2400bc59aba4bcc0a76e971dadd19610d3ad38c768e124dc7","schema_version":"edge-lab-recorder.raw.v1","sequence":null,"source":"clob_market_ws"}
{"event_at":"2026-07-28T04:02:08.360000Z","event_fingerprint":"af2a3f31783a20d21fcd24ef37e31fc9090a9c074681d27e676341cf5b3f8ca3","payload":{"connection_id":"f6725804f86a4c4eb588e4d5ed7db029","event_at":"2026-07-28T04:02:08.360000Z","event_type":"price_change","frame_hash":"ad8ae0e9314b2e0e90034d691d89503a8daeacfd6270a49725e29f29c9942fee","frame_index":0,"kind":"data","monotonic_ns":313312232837541,"payload":{"event_type":"price_change","market":"0xd412ce774cfcf8dc9f71164aac78783978aac7b03871702a3b8a481bd9dc9688","price_changes":[{"asset_id":"107603864457683460275633293642179940881969192120168665300712204232021063124301","best_ask":"0.43","best_bid":"0.41","hash":"4967b22124caae731c536f7ba2e4bfff1ba8bb58","price":"0.36","side":"BUY","size":"104.87"},{"asset_id":"96600821790790307414914106093858868634329285205417149685270682748367152458577","best_ask":"0.59","best_bid":"0.57","hash":"0e077146c9bfed47f3a213d260e6ffaf5b03cf40","price":"0.64","side":"SELL","size":"104.87"}],"timestamp":"1785211328360"},"payload_hash":"fc23a66e5d6d9216d0f69af06a7b05f2235da14b84417dee13a3b224f84cebd5","raw_frame":"{\"market\":\"0xd412ce774cfcf8dc9f71164aac78783978aac7b03871702a3b8a481bd9dc9688\", \"price_changes\":[{\"asset_id\":\"107603864457683460275633293642179940881969192120168665300712204232021063124301\", \"price\":\"0.36\", \"size\":\"104.87\", \"side\":\"BUY\", \"hash\":\"4967b22124caae731c536f7ba2e4bfff1ba8bb58\", \"best_bid\":\"0.41\", \"best_ask\":\"0.43\"}, {\"asset_id\":\"96600821790790307414914106093858868634329285205417149685270682748367152458577\", \"price\":\"0.64\", \"size\":\"104.87\", \"side\":\"SELL\", \"hash\":\"0e077146c9bfed47f3a213d260e6ffaf5b03cf40\", \"best_bid\":\"0.57\", \"best_ask\":\"0.59\"}], \"timestamp\":\"1785211328360\", \"event_type\":\"price_change\"}","received_at":"2026-07-28T04:02:09.183970Z","schema_version":"clob-market-ws.price_change.v1","sequence":null,"server_hash":null,"server_timestamp":"1785211328360","session_id":"2d607381e3054cee91998cdf45a4231c","source":"clob_market_ws"},"received_at":"2026-07-28T04:02:09.183970Z","record_id":"e6f64bbc6ac0c30cb87d60fc52cd40ab35b5e337f859b7bed981e3f20659cdfd","schema_fingerprint":"4aa3821a28b0b7c2400bc59aba4bcc0a76e971dadd19610d3ad38c768e124dc7","schema_version":"edge-lab-recorder.raw.v1","sequence":null,"source":"clob_market_ws"}
{"event_at":"2026-07-28T04:02:08.369000Z","event_fingerprint":"3bc7f14d90346926f7abee475ea28a6f2ebe7f4e5eda62131e8c1b88d1c82c28","payload":{"connection_id":"f6725804f86a4c4eb588e4d5ed7db029","event_at":"2026-07-28T04:02:08.369000Z","event_type":"price_change","frame_hash":"ad3009e16b9f57858919b13e098776e18dec753902ec2298828d6bb259a0f4d4","frame_index":0,"kind":"data","monotonic_ns":313312234329000,"payload":{"event_type":"price_change","market":"0xd412ce774cfcf8dc9f71164aac78783978aac7b03871702a3b8a481bd9dc9688","price_changes":[{"asset_id":"107603864457683460275633293642179940881969192120168665300712204232021063124301","best_ask":"0.43","best_bid":"0.41","hash":"31928a5addbad3a4a9133f1f42290df25742a882","price":"0.39","side":"BUY","size":"49.6"},{"asset_id":"96600821790790307414914106093858868634329285205417149685270682748367152458577","best_ask":"0.59","best_bid":"0.57","hash":"57eed0b3a591f31c97673e7c95b695c660f90af2","price":"0.61","side":"SELL","size":"49.6"}],"timestamp":"1785211328369"},"payload_hash":"1a9d85c817d1f3a8b3d4fdc247ffd7b7ba386f4e574dd44e2d0f94d0e226b204","raw_frame":"{\"market\":\"0xd412ce774cfcf8dc9f71164aac78783978aac7b03871702a3b8a481bd9dc9688\", \"price_changes\":[{\"asset_id\":\"107603864457683460275633293642179940881969192120168665300712204232021063124301\", \"price\":\"0.39\", \"size\":\"49.6\", \"side\":\"BUY\", \"hash\":\"31928a5addbad3a4a9133f1f42290df25742a882\", \"best_bid\":\"0.41\", \"best_ask\":\"0.43\"}, {\"asset_id\":\"96600821790790307414914106093858868634329285205417149685270682748367152458577\", \"price\":\"0.61\", \"size\":\"49.6\", \"side\":\"SELL\", \"hash\":\"57eed0b3a591f31c97673e7c95b695c660f90af2\", \"best_bid\":\"0.57\", \"best_ask\":\"0.59\"}], \"timestamp\":\"1785211328369\", \"event_type\":\"price_change\"}","received_at":"2026-07-28T04:02:09.185463Z","schema_version":"clob-market-ws.price_change.v1","sequence":null,"server_hash":null,"server_timestamp":"1785211328369","session_id":"2d607381e3054cee91998cdf45a4231c","source":"clob_market_ws"},"received_at":"2026-07-28T04:02:09.185463Z","record_id":"391057dc46efafe0b57d9a47555c6337691c95c50b34328e32e57869aaa0c3cc","schema_fingerprint":"4aa3821a28b0b7c2400bc59aba4bcc0a76e971dadd19610d3ad38c768e124dc7","schema_version":"edge-lab-recorder.raw.v1","sequence":null,"source":"clob_market_ws"}
{"event_at":"2026-07-28T04:02:08.370000Z","event_fingerprint":"78d2c1f02992ae08eec6d7c24709277ce035d890d2858e70ba7f8ac64a48fff6","payload":{"connection_id":"f6725804f86a4c4eb588e4d5ed7db029","event_at":"2026-07-28T04:02:08.370000Z","event_type":"best_bid_ask","frame_hash":"5ac22483f2bf42769ed6134c07d25d1205cea165d28e79a08e0c5d0e222b01e9","frame_index":0,"kind":"data","monotonic_ns":313312374772541,"payload":{"asset_id":"107603864457683460275633293642179940881969192120168665300712204232021063124301","best_ask":"0.42","best_bid":"0.41","event_type":"best_bid_ask","market":"0xd412ce774cfcf8dc9f71164aac78783978aac7b03871702a3b8a481bd9dc9688","spread":"0.01","timestamp":"1785211328370"},"payload_hash":"4ec70e5e88d75c07ba593544a0fc627dc56d77c9fa82fed5725dbdec0e115db5","raw_frame":"{\"market\":\"0xd412ce774cfcf8dc9f71164aac78783978aac7b03871702a3b8a481bd9dc9688\", \"asset_id\":\"107603864457683460275633293642179940881969192120168665300712204232021063124301\", \"best_bid\":\"0.41\", \"best_ask\":\"0.42\", \"spread\":\"0.01\", \"timestamp\":\"1785211328370\", \"event_type\":\"best_bid_ask\"}","received_at":"2026-07-28T04:02:09.325904Z","schema_version":"clob-market-ws.best_bid_ask.v1","sequence":null,"server_hash":null,"server_timestamp":"1785211328370","session_id":"2d607381e3054cee91998cdf45a4231c","source":"clob_market_ws"},"received_at":"2026-07-28T04:02:09.325904Z","record_id":"08b3b7925accb7afa6a6d7fb76d1d98672adfddf6fa46d0a896efd4824f840be","schema_fingerprint":"8488399f31b0337811b13b266be932db7062827c2470b78bd8e9e99bab51d17d","schema_version":"edge-lab-recorder.raw.v1","sequence":null,"source":"clob_market_ws"}
{"event_at":"2026-07-28T04:02:08.370000Z","event_fingerprint":"0a6d1b3200d9335f02c32e40bfa75fe581a8c325e9efb956153fd3b24b679859","payload":{"connection_id":"f6725804f86a4c4eb588e4d5ed7db029","event_at":"2026-07-28T04:02:08.370000Z","event_type":"best_bid_ask","frame_hash":"bdcf7aa7a08c61a81d82e2d333d5e09cd53131a144a3c973b5f748390d43566c","frame_index":0,"kind":"data","monotonic_ns":313312377227166,"payload":{"asset_id":"96600821790790307414914106093858868634329285205417149685270682748367152458577","best_ask":"0.59","best_bid":"0.58","event_type":"best_bid_ask","market":"0xd412ce774cfcf8dc9f71164aac78783978aac7b03871702a3b8a481bd9dc9688","spread":"0.01","timestamp":"1785211328370"},"payload_hash":"aa852240656c86dcb67c29a3d280f4f969e420671f300a8cc31155d5bee97067","raw_frame":"{\"market\":\"0xd412ce774cfcf8dc9f71164aac78783978aac7b03871702a3b8a481bd9dc9688\", \"asset_id\":\"96600821790790307414914106093858868634329285205417149685270682748367152458577\", \"best_bid\":\"0.58\", \"best_ask\":\"0.59\", \"spread\":\"0.01\", \"timestamp\":\"1785211328370\", \"event_type\":\"best_bid_ask\"}","received_at":"2026-07-28T04:02:09.328357Z","schema_version":"clob-market-ws.best_bid_ask.v1","sequence":null,"server_hash":null,"server_timestamp":"1785211328370","session_id":"2d607381e3054cee91998cdf45a4231c","source":"clob_market_ws"},"received_at":"2026-07-28T04:02:09.328357Z","record_id":"5b8d933bfa2c554b40e12ab0c468fe0b0c3a7aeb0a1ab42ba7da41bad381e804","schema_fingerprint":"8488399f31b0337811b13b266be932db7062827c2470b78bd8e9e99bab51d17d","schema_version":"edge-lab-recorder.raw.v1","sequence":null,"source":"clob_market_ws"}
{"event_at":"2026-07-28T04:02:08.370000Z","event_fingerprint":"1827f7ca35e34908e11566b58de214117c9ccb408e321ca157ce3b7f113896af","payload":{"connection_id":"f6725804f86a4c4eb588e4d5ed7db029","event_at":"2026-07-28T04:02:08.370000Z","event_type":"price_change","frame_hash":"5bd8cd60fc631a45cdd9e406a1b89cea9d1203c4cb97e83e30d5aff73a355532","frame_index":0,"kind":"data","monotonic_ns":313312379667166,"payload":{"event_type":"price_change","market":"0xd412ce774cfcf8dc9f71164aac78783978aac7b03871702a3b8a481bd9dc9688","price_changes":[{"asset_id":"96600821790790307414914106093858868634329285205417149685270682748367152458577","best_ask":"0.59","best_bid":"0.58","hash":"f5a38dcf1688ab8e90598502f9a25e0080532e52","price":"0.58","side":"BUY","size":"5"},{"asset_id":"107603864457683460275633293642179940881969192120168665300712204232021063124301","best_ask":"0.42","best_bid":"0.41","hash":"40053ae3eaa29dda98190177da3cbe0d07aa6316","price":"0.42","side":"SELL","size":"5"}],"timestamp":"1785211328370"},"payload_hash":"035d22898cfecc0b14db3748e0c9fd3df0984d8a75d9ff38de7ba254b5c902e6","raw_frame":"{\"market\":\"0xd412ce774cfcf8dc9f71164aac78783978aac7b03871702a3b8a481bd9dc9688\", \"price_changes\":[{\"asset_id\":\"96600821790790307414914106093858868634329285205417149685270682748367152458577\", \"price\":\"0.58\", \"size\":\"5\", \"side\":\"BUY\", \"hash\":\"f5a38dcf1688ab8e90598502f9a25e0080532e52\", \"best_bid\":\"0.58\", \"best_ask\":\"0.59\"}, {\"asset_id\":\"107603864457683460275633293642179940881969192120168665300712204232021063124301\", \"price\":\"0.42\", \"size\":\"5\", \"side\":\"SELL\", \"hash\":\"40053ae3eaa29dda98190177da3cbe0d07aa6316\", \"best_bid\":\"0.41\", \"best_ask\":\"0.42\"}], \"timestamp\":\"1785211328370\", \"event_type\":\"price_change\"}","received_at":"2026-07-28T04:02:09.330798Z","schema_version":"clob-market-ws.price_change.v1","sequence":null,"server_hash":null,"server_timestamp":"1785211328370","session_id":"2d607381e3054cee91998cdf45a4231c","source":"clob_market_ws"},"received_at":"2026-07-28T04:02:09.330798Z","record_id":"64507218a50d6d10bd05d9aff91a21ab42b5a10648a164e3f1b2a50b275c3644","schema_fingerprint":"4aa3821a28b0b7c2400bc59aba4bcc0a76e971dadd19610d3ad38c768e124dc7","schema_version":"edge-lab-recorder.raw.v1","sequence":null,"source":"clob_market_ws"}
{"event_at":"2026-07-28T04:02:08.371000Z","event_fingerprint":"a1a620f7f8bf58e85bd65dca3c68fa8a244e83189e34d1f12dc420dccc78a76a","payload":{"connection_id":"f6725804f86a4c4eb588e4d5ed7db029","event_at":"2026-07-28T04:02:08.371000Z","event_type":"price_change","frame_hash":"f90350d04210d90ac6e6ab55e1a9024fe3515ccb430354ed25bbf432870ab3ac","frame_index":0,"kind":"data","monotonic_ns":313312666347625,"payload":{"event_type":"price_change","market":"0xd412ce774cfcf8dc9f71164aac78783978aac7b03871702a3b8a481bd9dc9688","price_changes":[{"asset_id":"107603864457683460275633293642179940881969192120168665300712204232021063124301","best_ask":"0.42","best_bid":"0.41","hash":"80d1110d53e7d28f9d1bb9d3736f17a38d5d8bc9","price":"0.42","side":"SELL","size":"10"},{"asset_id":"96600821790790307414914106093858868634329285205417149685270682748367152458577","best_ask":"0.59","best_bid":"0.58","hash":"563a86eac24032c380ebfb7dbdfc95bfbfafb71a","price":"0.58","side":"BUY","size":"10"}],"timestamp":"1785211328371"},"payload_hash":"83a711aa2ae7ff3b9be0af1fac7e2989f4fab705666653e5c94863bff8708eb1","raw_frame":"{\"market\":\"0xd412ce774cfcf8dc9f71164aac78783978aac7b03871702a3b8a481bd9dc9688\", \"price_changes\":[{\"asset_id\":\"107603864457683460275633293642179940881969192120168665300712204232021063124301\", \"price\":\"0.42\", \"size\":\"10\", \"side\":\"SELL\", \"hash\":\"80d1110d53e7d28f9d1bb9d3736f17a38d5d8bc9\", \"best_bid\":\"0.41\", \"best_ask\":\"0.42\"}, {\"asset_id\":\"96600821790790307414914106093858868634329285205417149685270682748367152458577\", \"price\":\"0.58\", \"size\":\"10\", \"side\":\"BUY\", \"hash\":\"563a86eac24032c380ebfb7dbdfc95bfbfafb71a\", \"best_bid\":\"0.58\", \"best_ask\":\"0.59\"}], \"timestamp\":\"1785211328371\", \"event_type\":\"price_change\"}","received_at":"2026-07-28T04:02:09.617474Z","schema_version":"clob-market-ws.price_change.v1","sequence":null,"server_hash":null,"server_timestamp":"1785211328371","session_id":"2d607381e3054cee91998cdf45a4231c","source":"clob_market_ws"},"received_at":"2026-07-28T04:02:09.617474Z","record_id":"fbc484fa336a9f67e747e3194f17e3940e72e2392f019b31b34d7dc16ab09baa","schema_fingerprint":"4aa3821a28b0b7c2400bc59aba4bcc0a76e971dadd19610d3ad38c768e124dc7","schema_version":"edge-lab-recorder.raw.v1","sequence":null,"source":"clob_market_ws"}
{"event_at":"2026-07-28T04:02:08.387000Z","event_fingerprint":"ac60ee0470f6ff95aba0eb19f96b3debf2f82882c674b0bd9f019d2078b8b3fc","payload":{"connection_id":"f6725804f86a4c4eb588e4d5ed7db029","event_at":"2026-07-28T04:02:08.387000Z","event_type":"best_bid_ask","frame_hash":"da066fc679fa06168560b20d01fbbb99658961d7110e965f727787cb1a293936","frame_index":0,"kind":"data","monotonic_ns":313312668073416,"payload":{"asset_id":"107603864457683460275633293642179940881969192120168665300712204232021063124301","best_ask":"0.42","best_bid":"0.4","event_type":"best_bid_ask","market":"0xd412ce774cfcf8dc9f71164aac78783978aac7b03871702a3b8a481bd9dc9688","spread":"0.02","timestamp":"1785211328387"},"payload_hash":"6894ccf3eb3989cb0f9f1687606ce317012e59a2b93d14595d47e05d0761ff90","raw_frame":"{\"market\":\"0xd412ce774cfcf8dc9f71164aac78783978aac7b03871702a3b8a481bd9dc9688\", \"asset_id\":\"107603864457683460275633293642179940881969192120168665300712204232021063124301\", \"best_bid\":\"0.4\", \"best_ask\":\"0.42\", \"spread\":\"0.02\", \"timestamp\":\"1785211328387\", \"event_type\":\"best_bid_ask\"}","received_at":"2026-07-28T04:02:09.619201Z","schema_version":"clob-market-ws.best_bid_ask.v1","sequence":null,"server_hash":null,"server_timestamp":"1785211328387","session_id":"2d607381e3054cee91998cdf45a4231c","source":"clob_market_ws"},"received_at":"2026-07-28T04:02:09.619201Z","record_id":"af515486c2b77cea7ee5bbbea389e9545d4fe467e3c6d0ef1b278a6041386317","schema_fingerprint":"8488399f31b0337811b13b266be932db7062827c2470b78bd8e9e99bab51d17d","schema_version":"edge-lab-recorder.raw.v1","sequence":null,"source":"clob_market_ws"}
{"event_at":"2026-07-28T04:02:08.387000Z","event_fingerprint":"76edc0378c11179604b8f17e14c0ebd894f89f3c1f4c5b7f080fa32c82de6947","payload":{"connection_id":"f6725804f86a4c4eb588e4d5ed7db029","event_at":"2026-07-28T04:02:08.387000Z","event_type":"best_bid_ask","frame_hash":"194e108cb5557b433a43dc0167cb5a188c9d445991477c2e0bb508b7e6a9a30d","frame_index":0,"kind":"data","monotonic_ns":313312669198958,"payload":{"asset_id":"96600821790790307414914106093858868634329285205417149685270682748367152458577","best_ask":"0.6","best_bid":"0.58","event_type":"best_bid_ask","market":"0xd412ce774cfcf8dc9f71164aac78783978aac7b03871702a3b8a481bd9dc9688","spread":"0.02","timestamp":"1785211328387"},"payload_hash":"bd6a651398f6fa465704e5817c90c15c8b596392105f7eed5c66962388017b7d","raw_frame":"{\"market\":\"0xd412ce774cfcf8dc9f71164aac78783978aac7b03871702a3b8a481bd9dc9688\", \"asset_id\":\"96600821790790307414914106093858868634329285205417149685270682748367152458577\", \"best_bid\":\"0.58\", \"best_ask\":\"0.6\", \"spread\":\"0.02\", \"timestamp\":\"1785211328387\", \"event_type\":\"best_bid_ask\"}","received_at":"2026-07-28T04:02:09.620327Z","schema_version":"clob-market-ws.best_bid_ask.v1","sequence":null,"server_hash":null,"server_timestamp":"1785211328387","session_id":"2d607381e3054cee91998cdf45a4231c","source":"clob_market_ws"},"received_at":"2026-07-28T04:02:09.620327Z","record_id":"3ed49960591fd50a7f05b4f92362ea82ea64fdab6bb4fcc11c249771d06a0fbb","schema_fingerprint":"8488399f31b0337811b13b266be932db7062827c2470b78bd8e9e99bab51d17d","schema_version":"edge-lab-recorder.raw.v1","sequence":null,"source":"clob_market_ws"}
{"event_at":"2026-07-28T04:02:08.387000Z","event_fingerprint":"e334c732fad540527212d3362d3f101bd1fd440476374ed463f4e87674564203","payload":{"connection_id":"f6725804f86a4c4eb588e4d5ed7db029","event_at":"2026-07-28T04:02:08.387000Z","event_type":"price_change","frame_hash":"eddfbc06aaee1957cf446ef9a358971650120827d7edae4c2bd0f91cbc833cd1","frame_index":0,"kind":"data","monotonic_ns":313312670270916,"payload":{"event_type":"price_change","market":"0xd412ce774cfcf8dc9f71164aac78783978aac7b03871702a3b8a481bd9dc9688","price_changes":[{"asset_id":"107603864457683460275633293642179940881969192120168665300712204232021063124301","best_ask":"0.42","best_bid":"0.4","hash":"4f9969baebb65b6139b1b4e09e441bdc3f1086aa","price":"0.41","side":"BUY","size":"0"},{"asset_id":"96600821790790307414914106093858868634329285205417149685270682748367152458577","best_ask":"0.6","best_bid":"0.58","hash":"1248833ae2d4478e129c6b91fc0f2d00eea29d08","price":"0.59","side":"SELL","size":"0"}],"timestamp":"1785211328387"},"payload_hash":"34daafe88cc73e6acf2173658595bbd17238d64f78ee917d7740d1c8c39a72e1","raw_frame":"{\"market\":\"0xd412ce774cfcf8dc9f71164aac78783978aac7b03871702a3b8a481bd9dc9688\", \"price_changes\":[{\"asset_id\":\"107603864457683460275633293642179940881969192120168665300712204232021063124301\", \"price\":\"0.41\", \"size\":\"0\", \"side\":\"BUY\", \"hash\":\"4f9969baebb65b6139b1b4e09e441bdc3f1086aa\", \"best_bid\":\"0.4\", \"best_ask\":\"0.42\"}, {\"asset_id\":\"96600821790790307414914106093858868634329285205417149685270682748367152458577\", \"price\":\"0.59\", \"size\":\"0\", \"side\":\"SELL\", \"hash\":\"1248833ae2d4478e129c6b91fc0f2d00eea29d08\", \"best_bid\":\"0.58\", \"best_ask\":\"0.6\"}], \"timestamp\":\"1785211328387\", \"event_type\":\"price_change\"}","received_at":"2026-07-28T04:02:09.621400Z","schema_version":"clob-market-ws.price_change.v1","sequence":null,"server_hash":null,"server_timestamp":"1785211328387","session_id":"2d607381e3054cee91998cdf45a4231c","source":"clob_market_ws"},"received_at":"2026-07-28T04:02:09.621400Z","record_id":"a5097be2494aaaea66cfa85bd58bbe6ec17106df45cc5a386d26cf1e83b5cf54","schema_fingerprint":"4aa3821a28b0b7c2400bc59aba4bcc0a76e971dadd19610d3ad38c768e124dc7","schema_version":"edge-lab-recorder.raw.v1","sequence":null,"source":"clob_market_ws"}
{"event_at":"2026-07-28T04:02:08.390000Z","event_fingerprint":"c0cc0c519b4fb989ea5bd5f940ce1c7999dd20d9d85f0803051d385594ce08c0","payload":{"connection_id":"f6725804f86a4c4eb588e4d5ed7db029","event_at":"2026-07-28T04:02:08.390000Z","event_type":"price_change","frame_hash":"f166fa268c41eaca40c31e247ea61dac8ce13e47cd41243b35090301aa49a86f","frame_index":0,"kind":"data","monotonic_ns":313312671803875,"payload":{"event_type":"price_change","market":"0xd412ce774cfcf8dc9f71164aac78783978aac7b03871702a3b8a481bd9dc9688","price_changes":[{"asset_id":"107603864457683460275633293642179940881969192120168665300712204232021063124301","best_ask":"0.42","best_bid":"0.4","hash":"e5ae1387d30aec8afd0a7caf40af1e7d619dff4c","price":"0.36","side":"BUY","size":"99.87"},{"asset_id":"96600821790790307414914106093858868634329285205417149685270682748367152458577","best_ask":"0.6","best_bid":"0.58","hash":"bfc481b7fc2860d96cc31b0b8918474e8c9b625c","price":"0.64","side":"SELL","size":"99.87"}],"timestamp":"1785211328390"},"payload_hash":"3d2c901928d13c4f89b1c57dd690ff6e4c90763a4298bce54b3b74cfc8883363","raw_frame":"{\"market\":\"0xd412ce774cfcf8dc9f71164aac78783978aac7b03871702a3b8a481bd9dc9688\", \"price_changes\":[{\"asset_id\":\"107603864457683460275633293642179940881969192120168665300712204232021063124301\", \"price\":\"0.36\", \"size\":\"99.87\", \"side\":\"BUY\", \"hash\":\"e5ae1387d30aec8afd0a7caf40af1e7d619dff4c\", \"best_bid\":\"0.4\", \"best_ask\":\"0.42\"}, {\"asset_id\":\"96600821790790307414914106093858868634329285205417149685270682748367152458577\", \"price\":\"0.64\", \"size\":\"99.87\", \"side\":\"SELL\", \"hash\":\"bfc481b7fc2860d96cc31b0b8918474e8c9b625c\", \"best_bid\":\"0.58\", \"best_ask\":\"0.6\"}], \"timestamp\":\"1785211328390\", \"event_type\":\"price_change\"}","received_at":"2026-07-28T04:02:09.622932Z","schema_version":"clob-market-ws.price_change.v1","sequence":null,"server_hash":null,"server_timestamp":"1785211328390","session_id":"2d607381e3054cee91998cdf45a4231c","source":"clob_market_ws"},"received_at":"2026-07-28T04:02:09.622932Z","record_id":"58f43a237ea1fdf084c4435c0e133e6fc76f4e550e4745a7b16fa07567f89a13","schema_fingerprint":"4aa3821a28b0b7c2400bc59aba4bcc0a76e971dadd19610d3ad38c768e124dc7","schema_version":"edge-lab-recorder.raw.v1","sequence":null,"source":"clob_market_ws"}
{"event_at":"2026-07-28T04:02:08.402000Z","event_fingerprint":"cf1c73485e6bdb69ed5eb8c949c0a2b4b51dd942f142cd930148ac0e04e4c936","payload":{"connection_id":"f6725804f86a4c4eb588e4d5ed7db029","event_at":"2026-07-28T04:02:08.402000Z","event_type":"price_change","frame_hash":"305b1c6bd8bb41b0bf4a2a5738d4eaa8e77e813a0a7e04dbb1e013bde0fc43d6","frame_index":0,"kind":"data","monotonic_ns":313312673300583,"payload":{"event_type":"price_change","market":"0xd412ce774cfcf8dc9f71164aac78783978aac7b03871702a3b8a481bd9dc9688","price_changes":[{"asset_id":"96600821790790307414914106093858868634329285205417149685270682748367152458577","best_ask":"0.6","best_bid":"0.58","hash":"de08f9eac1ec8757817272e3d8019af1e5fdec83","price":"0.58","side":"BUY","size":"5"},{"asset_id":"107603864457683460275633293642179940881969192120168665300712204232021063124301","best_ask":"0.42","best_bid":"0.4","hash":"8d5c669ab0dd05883bb6c809657af025475fe2a8","price":"0.42","side":"SELL","size":"5"}],"timestamp":"1785211328402"},"payload_hash":"32430e07568f796fadc727dbedf1c6768c65be971b9c684462181cdc5793ddb9","raw_frame":"{\"market\":\"0xd412ce774cfcf8dc9f71164aac78783978aac7b03871702a3b8a481bd9dc9688\", \"price_changes\":[{\"asset_id\":\"96600821790790307414914106093858868634329285205417149685270682748367152458577\", \"price\":\"0.58\", \"size\":\"5\", \"side\":\"BUY\", \"hash\":\"de08f9eac1ec8757817272e3d8019af1e5fdec83\", \"best_bid\":\"0.58\", \"best_ask\":\"0.6\"}, {\"asset_id\":\"107603864457683460275633293642179940881969192120168665300712204232021063124301\", \"price\":\"0.42\", \"size\":\"5\", \"side\":\"SELL\", \"hash\":\"8d5c669ab0dd05883bb6c809657af025475fe2a8\", \"best_bid\":\"0.4\", \"best_ask\":\"0.42\"}], \"timestamp\":\"1785211328402\", \"event_type\":\"price_change\"}","received_at":"2026-07-28T04:02:09.624430Z","schema_version":"clob-market-ws.price_change.v1","sequence":null,"server_hash":null,"server_timestamp":"1785211328402","session_id":"2d607381e3054cee91998cdf45a4231c","source":"clob_market_ws"},"received_at":"2026-07-28T04:02:09.624430Z","record_id":"83db7384cb99c3bb474cd605b1739c390b9a4ab02d8a07b714b894c15733dc23","schema_fingerprint":"4aa3821a28b0b7c2400bc59aba4bcc0a76e971dadd19610d3ad38c768e124dc7","schema_version":"edge-lab-recorder.raw.v1","sequence":null,"source":"clob_market_ws"}
{"event_at":"2026-07-28T04:02:08.403000Z","event_fingerprint":"e4a2b8eb0257a5518938047194bf31f363c09d0cd562dfb397cffc5b9bd773dc","payload":{"connection_id":"f6725804f86a4c4eb588e4d5ed7db029","event_at":"2026-07-28T04:02:08.403000Z","event_type":"best_bid_ask","frame_hash":"c8d9362c39353aa88ab54b69337dcd603d49331524b33abe607e0b7dc34d7908","frame_index":0,"kind":"data","monotonic_ns":313312674846000,"payload":{"asset_id":"107603864457683460275633293642179940881969192120168665300712204232021063124301","best_ask":"0.43","best_bid":"0.4","event_type":"best_bid_ask","market":"0xd412ce774cfcf8dc9f71164aac78783978aac7b03871702a3b8a481bd9dc9688","spread":"0.03","timestamp":"1785211328403"},"payload_hash":"fcc079df2ca4860ed76bb634359d07b6e21b598d56907d132b379a928d8a2e45","raw_frame":"{\"market\":\"0xd412ce774cfcf8dc9f71164aac78783978aac7b03871702a3b8a481bd9dc9688\", \"asset_id\":\"107603864457683460275633293642179940881969192120168665300712204232021063124301\", \"best_bid\":\"0.4\", \"best_ask\":\"0.43\", \"spread\":\"0.03\", \"timestamp\":\"1785211328403\", \"event_type\":\"best_bid_ask\"}","received_at":"2026-07-28T04:02:09.625973Z","schema_version":"clob-market-ws.best_bid_ask.v1","sequence":null,"server_hash":null,"server_timestamp":"1785211328403","session_id":"2d607381e3054cee91998cdf45a4231c","source":"clob_market_ws"},"received_at":"2026-07-28T04:02:09.625973Z","record_id":"cd9473ff4a6b8b7e96cc94b7854475a6c8684d956b5d6839f9fcde52c89c64dc","schema_fingerprint":"8488399f31b0337811b13b266be932db7062827c2470b78bd8e9e99bab51d17d","schema_version":"edge-lab-recorder.raw.v1","sequence":null,"source":"clob_market_ws"}
{"event_at":"2026-07-28T04:02:08.403000Z","event_fingerprint":"d425b07f5d4c0c942325dfab3417f2324d3f04500dabdd457fb377f76bd4e714","payload":{"connection_id":"f6725804f86a4c4eb588e4d5ed7db029","event_at":"2026-07-28T04:02:08.403000Z","event_type":"best_bid_ask","frame_hash":"1d828b736d1ba66410531d9b07b8f3ed2bfc9c62d2e596447ee4ed5817aa85cd","frame_index":0,"kind":"data","monotonic_ns":313312675950041,"payload":{"asset_id":"96600821790790307414914106093858868634329285205417149685270682748367152458577","best_ask":"0.6","best_bid":"0.57","event_type":"best_bid_ask","market":"0xd412ce774cfcf8dc9f71164aac78783978aac7b03871702a3b8a481bd9dc9688","spread":"0.03","timestamp":"1785211328403"},"payload_hash":"ccaf73e875c8db1afd46f6dc4c0599b904371f2ac5be3436acbcd85a8c812030","raw_frame":"{\"market\":\"0xd412ce774cfcf8dc9f71164aac78783978aac7b03871702a3b8a481bd9dc9688\", \"asset_id\":\"96600821790790307414914106093858868634329285205417149685270682748367152458577\", \"best_bid\":\"0.57\", \"best_ask\":\"0.6\", \"spread\":\"0.03\", \"timestamp\":\"1785211328403\", \"event_type\":\"best_bid_ask\"}","received_at":"2026-07-28T04:02:09.627079Z","schema_version":"clob-market-ws.best_bid_ask.v1","sequence":null,"server_hash":null,"server_timestamp":"1785211328403","session_id":"2d607381e3054cee91998cdf45a4231c","source":"clob_market_ws"},"received_at":"2026-07-28T04:02:09.627079Z","record_id":"a5ab0a2b3ae100bb055f735abc0b2c4a878c12d2fa558484feff85ab3fbf67fa","schema_fingerprint":"8488399f31b0337811b13b266be932db7062827c2470b78bd8e9e99bab51d17d","schema_version":"edge-lab-recorder.raw.v1","sequence":null,"source":"clob_market_ws"}
{"event_at":"2026-07-28T04:02:08.403000Z","event_fingerprint":"e682c455df5f6f5d1fd173babc0edb4f208acd25866da97e4b4478dc7b88028c","payload":{"connection_id":"f6725804f86a4c4eb588e4d5ed7db029","event_at":"2026-07-28T04:02:08.403000Z","event_type":"price_change","frame_hash":"8a4b0128e394394bf4c7f185e5abc9753f08528fa601e8ccd8703e22641a2f62","frame_index":0,"kind":"data","monotonic_ns":313312676992541,"payload":{"event_type":"price_change","market":"0xd412ce774cfcf8dc9f71164aac78783978aac7b03871702a3b8a481bd9dc9688","price_changes":[{"asset_id":"107603864457683460275633293642179940881969192120168665300712204232021063124301","best_ask":"0.43","best_bid":"0.4","hash":"15865799bbf07a30b0bba23b6c204effe10e216c","price":"0.42","side":"SELL","size":"0"},{"asset_id":"96600821790790307414914106093858868634329285205417149685270682748367152458577","best_ask":"0.6","best_bid":"0.57","hash":"d197006fe092cf5ddfcd23f2d5a21e49f7d4a554","price":"0.58","side":"BUY","size":"0"}],"timestamp":"1785211328403"},"payload_hash":"b3493ded2a2aecf9d0ea0271aee1fa4a0909eb00338f642e8e1076007a8a9d08","raw_frame":"{\"market\":\"0xd412ce774cfcf8dc9f71164aac78783978aac7b03871702a3b8a481bd9dc9688\", \"price_changes\":[{\"asset_id\":\"107603864457683460275633293642179940881969192120168665300712204232021063124301\", \"price\":\"0.42\", \"size\":\"0\", \"side\":\"SELL\", \"hash\":\"15865799bbf07a30b0bba23b6c204effe10e216c\", \"best_bid\":\"0.4\", \"best_ask\":\"0.43\"}, {\"asset_id\":\"96600821790790307414914106093858868634329285205417149685270682748367152458577\", \"price\":\"0.58\", \"size\":\"0\", \"side\":\"BUY\", \"hash\":\"d197006fe092cf5ddfcd23f2d5a21e49f7d4a554\", \"best_bid\":\"0.57\", \"best_ask\":\"0.6\"}], \"timestamp\":\"1785211328403\", \"event_type\":\"price_change\"}","received_at":"2026-07-28T04:02:09.628122Z","schema_version":"clob-market-ws.price_change.v1","sequence":null,"server_hash":null,"server_timestamp":"1785211328403","session_id":"2d607381e3054cee91998cdf45a4231c","source":"clob_market_ws"},"received_at":"2026-07-28T04:02:09.628122Z","record_id":"3f89a3411ac40f7a17e8109261818d0668e16fcacae38f8f44e28d0406dec6c9","schema_fingerprint":"4aa3821a28b0b7c2400bc59aba4bcc0a76e971dadd19610d3ad38c768e124dc7","schema_version":"edge-lab-recorder.raw.v1","sequence":null,"source":"clob_market_ws"}
{"event_at":"2026-07-28T04:02:08.407000Z","event_fingerprint":"cf9d1852caa4ecc32c09b5d99be7fbb9e702155627423e627dfdc8ac17632e17","payload":{"connection_id":"f6725804f86a4c4eb588e4d5ed7db029","event_at":"2026-07-28T04:02:08.407000Z","event_type":"price_change","frame_hash":"eefd3ec1cb8b29e9f29a6ff23ab65be6ddc923be79217a7286a1a902f56751b9","frame_index":0,"kind":"data","monotonic_ns":313312678478541,"payload":{"event_type":"price_change","market":"0xd412ce774cfcf8dc9f71164aac78783978aac7b03871702a3b8a481bd9dc9688","price_changes":[{"asset_id":"96600821790790307414914106093858868634329285205417149685270682748367152458577","best_ask":"0.6","best_bid":"0.57","hash":"8e8f04c6f0ddfbe54a6aef41380e07ca88dd7d1f","price":"0.52","side":"BUY","size":"134.01"},{"asset_id":"107603864457683460275633293642179940881969192120168665300712204232021063124301","best_ask":"0.43","best_bid":"0.4","hash":"976e1ef394fd4bdab812bc8f1ac9ee4bed9f2ea9","price":"0.48","side":"SELL","size":"134.01"}],"timestamp":"1785211328407"},"payload_hash":"2903706616dceceaf190f75bf1ab97f543717b178d21748f649c6d785622db63","raw_frame":"{\"market\":\"0xd412ce774cfcf8dc9f71164aac78783978aac7b03871702a3b8a481bd9dc9688\", \"price_changes\":[{\"asset_id\":\"96600821790790307414914106093858868634329285205417149685270682748367152458577\", \"price\":\"0.52\", \"size\":\"134.01\", \"side\":\"BUY\", \"hash\":\"8e8f04c6f0ddfbe54a6aef41380e07ca88dd7d1f\", \"best_bid\":\"0.57\", \"best_ask\":\"0.6\"}, {\"asset_id\":\"107603864457683460275633293642179940881969192120168665300712204232021063124301\", \"price\":\"0.48\", \"size\":\"134.01\", \"side\":\"SELL\", \"hash\":\"976e1ef394fd4bdab812bc8f1ac9ee4bed9f2ea9\", \"best_bid\":\"0.4\", \"best_ask\":\"0.43\"}], \"timestamp\":\"1785211328407\", \"event_type\":\"price_change\"}","received_at":"2026-07-28T04:02:09.629608Z","schema_version":"clob-market-ws.price_change.v1","sequence":null,"server_hash":null,"server_timestamp":"1785211328407","session_id":"2d607381e3054cee91998cdf45a4231c","source":"clob_market_ws"},"received_at":"2026-07-28T04:02:09.629608Z","record_id":"b8116aaf93c837843316da5db6158f38eec1aac0adcfecaa52057430d25e121c","schema_fingerprint":"4aa3821a28b0b7c2400bc59aba4bcc0a76e971dadd19610d3ad38c768e124dc7","schema_version":"edge-lab-recorder.raw.v1","sequence":null,"source":"clob_market_ws"}
{"event_at":"2026-07-28T04:02:08.408000Z","event_fingerprint":"23ba01d4cb1758de955b01f71422b2973cebd09263c9e1e19dca9eb0569e6dc8","payload":{"connection_id":"f6725804f86a4c4eb588e4d5ed7db029","event_at":"2026-07-28T04:02:08.408000Z","event_type":"best_bid_ask","frame_hash":"d5b91ab18409edee2c7622c97d15e6518bfe11280441db36f1c4c060375f399f","frame_index":0,"kind":"data","monotonic_ns":313312679999708,"payload":{"asset_id":"107603864457683460275633293642179940881969192120168665300712204232021063124301","best_ask":"0.43","best_bid":"0.42","event_type":"best_bid_ask","market":"0xd412ce774cfcf8dc9f71164aac78783978aac7b03871702a3b8a481bd9dc9688","spread":"0.01","timestamp":"1785211328408"},"payload_hash":"4d48525f236c79703e5d7da2ad9d99064661dccc995c451ca92791873061d930","raw_frame":"{\"market\":\"0xd412ce774cfcf8dc9f71164aac78783978aac7b03871702a3b8a481bd9dc9688\", \"asset_id\":\"107603864457683460275633293642179940881969192120168665300712204232021063124301\", \"best_bid\":\"0.42\", \"best_ask\":\"0.43\", \"spread\":\"0.01\", \"timestamp\":\"1785211328408\", \"event_type\":\"best_bid_ask\"}","received_at":"2026-07-28T04:02:09.631129Z","schema_version":"clob-market-ws.best_bid_ask.v1","sequence":null,"server_hash":null,"server_timestamp":"1785211328408","session_id":"2d607381e3054cee91998cdf45a4231c","source":"clob_market_ws"},"received_at":"2026-07-28T04:02:09.631129Z","record_id":"bc2a4271c4de16e01cb884b6745f176740920fde7ba87125c38671a0b340b866","schema_fingerprint":"8488399f31b0337811b13b266be932db7062827c2470b78bd8e9e99bab51d17d","schema_version":"edge-lab-recorder.raw.v1","sequence":null,"source":"clob_market_ws"}
{"event_at":"2026-07-28T04:02:08.408000Z","event_fingerprint":"569519c2c023f221e859ffe9a3dc5fe88d3ac37d1bf8c94fc6217f4c63b30f04","payload":{"connection_id":"f6725804f86a4c4eb588e4d5ed7db029","event_at":"2026-07-28T04:02:08.408000Z","event_type":"best_bid_ask","frame_hash":"1d9dbb609650400ed50c0cae34a73bc252f34c0feacf1c67110cb2a879939f73","frame_index":0,"kind":"data","monotonic_ns":313312681017250,"payload":{"asset_id":"96600821790790307414914106093858868634329285205417149685270682748367152458577","best_ask":"0.58","best_bid":"0.57","event_type":"best_bid_ask","market":"0xd412ce774cfcf8dc9f71164aac78783978aac7b03871702a3b8a481bd9dc9688","spread":"0.01","timestamp":"1785211328408"},"payload_hash":"9707698726dba4987b098fbfefbb5d650057eafcd1bd4fd0cdebc9cec3264ffa","raw_frame":"{\"market\":\"0xd412ce774cfcf8dc9f71164aac78783978aac7b03871702a3b8a481bd9dc9688\", \"asset_id\":\"96600821790790307414914106093858868634329285205417149685270682748367152458577\", \"best_bid\":\"0.57\", \"best_ask\":\"0.58\", \"spread\":\"0.01\", \"timestamp\":\"1785211328408\", \"event_type\":\"best_bid_ask\"}","received_at":"2026-07-28T04:02:09.632147Z","schema_version":"clob-market-ws.best_bid_ask.v1","sequence":null,"server_hash":null,"server_timestamp":"1785211328408","session_id":"2d607381e3054cee91998cdf45a4231c","source":"clob_market_ws"},"received_at":"2026-07-28T04:02:09.632147Z","record_id":"7d63541d260718f2f8a3a867577bc341e0e77e45d9cf39d79c6eb647f5240737","schema_fingerprint":"8488399f31b0337811b13b266be932db7062827c2470b78bd8e9e99bab51d17d","schema_version":"edge-lab-recorder.raw.v1","sequence":null,"source":"clob_market_ws"}
{"event_at":"2026-07-28T04:02:08.408000Z","event_fingerprint":"6b0ace2019d86068f031b4b940889ec225c113198b698400ae11b684ab552f6d","payload":{"connection_id":"f6725804f86a4c4eb588e4d5ed7db029","event_at":"2026-07-28T04:02:08.408000Z","event_type":"price_change","frame_hash":"97778c3b743f01e7fea8f1e0c1b405aa93ff40b3c5f3f86a59a188875d1440bf","frame_index":0,"kind":"data","monotonic_ns":313312682051125,"payload":{"event_type":"price_change","market":"0xd412ce774cfcf8dc9f71164aac78783978aac7b03871702a3b8a481bd9dc9688","price_changes":[{"asset_id":"107603864457683460275633293642179940881969192120168665300712204232021063124301","best_ask":"0.43","best_bid":"0.42","hash":"c2a0bcec83cf8da6b429424ecf2e7312d43f3e34","price":"0.42","side":"BUY","size":"40"},{"asset_id":"96600821790790307414914106093858868634329285205417149685270682748367152458577","best_ask":"0.58","best_bid":"0.57","hash":"da2750a1725e6d2d10f2a58a84fe03940b104ed0","price":"0.58","side":"SELL","size":"40"}],"timestamp":"1785211328408"},"payload_hash":"615dbfe2dd9b4dfde8dbee88ec0be5ca11aeb4267c8ecf4192b4389eb02ff478","raw_frame":"{\"market\":\"0xd412ce774cfcf8dc9f71164aac78783978aac7b03871702a3b8a481bd9dc9688\", \"price_changes\":[{\"asset_id\":\"107603864457683460275633293642179940881969192120168665300712204232021063124301\", \"price\":\"0.42\", \"size\":\"40\", \"side\":\"BUY\", \"hash\":\"c2a0bcec83cf8da6b429424ecf2e7312d43f3e34\", \"best_bid\":\"0.42\", \"best_ask\":\"0.43\"}, {\"asset_id\":\"96600821790790307414914106093858868634329285205417149685270682748367152458577\", \"price\":\"0.58\", \"size\":\"40\", \"side\":\"SELL\", \"hash\":\"da2750a1725e6d2d10f2a58a84fe03940b104ed0\", \"best_bid\":\"0.57\", \"best_ask\":\"0.58\"}], \"timestamp\":\"1785211328408\", \"event_type\":\"price_change\"}","received_at":"2026-07-28T04:02:09.633181Z","schema_version":"clob-market-ws.price_change.v1","sequence":null,"server_hash":null,"server_timestamp":"1785211328408","session_id":"2d607381e3054cee91998cdf45a4231c","source":"clob_market_ws"},"received_at":"2026-07-28T04:02:09.633181Z","record_id":"1cc07c1aa437bc9734da5969367c490a2901aabc28bb32d73a4d9682d8bbf26b","schema_fingerprint":"4aa3821a28b0b7c2400bc59aba4bcc0a76e971dadd19610d3ad38c768e124dc7","schema_version":"edge-lab-recorder.raw.v1","sequence":null,"source":"clob_market_ws"}
{"event_at":"2026-07-28T04:02:08.409000Z","event_fingerprint":"377300570cd79641d15fefd8792f31a0e20290499ae119d3ab7b4a20980eca36","payload":{"connection_id":"f6725804f86a4c4eb588e4d5ed7db029","event_at":"2026-07-28T04:02:08.409000Z","event_type":"price_change","frame_hash":"fc898882fcb804eb7e90475f168dbea350aa6fb281946e96be8e633635a9eb63","frame_index":0,"kind":"data","monotonic_ns":313312683520666,"payload":{"event_type":"price_change","market":"0xd412ce774cfcf8dc9f71164aac78783978aac7b03871702a3b8a481bd9dc9688","price_changes":[{"asset_id":"107603864457683460275633293642179940881969192120168665300712204232021063124301","best_ask":"0.43","best_bid":"0.42","hash":"3cf05ed9f1ff46866942c170356541381810e605","price":"0.41","side":"BUY","size":"6"},{"asset_id":"96600821790790307414914106093858868634329285205417149685270682748367152458577","best_ask":"0.58","best_bid":"0.57","hash":"d2a4b4af39bf57a66fd7b4d15d98f65145e0a318","price":"0.59","side":"SELL","size":"6"}],"timestamp":"1785211328409"},"payload_hash":"85ff5b676de99516b170f4c0058cc4de94d263e169042c59ce5196f913912165","raw_frame":"{\"market\":\"0xd412ce774cfcf8dc9f71164aac78783978aac7b03871702a3b8a481bd9dc9688\", \"price_changes\":[{\"asset_id\":\"107603864457683460275633293642179940881969192120168665300712204232021063124301\", \"price\":\"0.41\", \"size\":\"6\", \"side\":\"BUY\", \"hash\":\"3cf05ed9f1ff46866942c170356541381810e605\", \"best_bid\":\"0.42\", \"best_ask\":\"0.43\"}, {\"asset_id\":\"96600821790790307414914106093858868634329285205417149685270682748367152458577\", \"price\":\"0.59\", \"size\":\"6\", \"side\":\"SELL\", \"hash\":\"d2a4b4af39bf57a66fd7b4d15d98f65145e0a318\", \"best_bid\":\"0.57\", \"best_ask\":\"0.58\"}], \"timestamp\":\"1785211328409\", \"event_type\":\"price_change\"}","received_at":"2026-07-28T04:02:09.634651Z","schema_version":"clob-market-ws.price_change.v1","sequence":null,"server_hash":null,"server_timestamp":"1785211328409","session_id":"2d607381e3054cee91998cdf45a4231c","source":"clob_market_ws"},"received_at":"2026-07-28T04:02:09.634651Z","record_id":"a930a4caa947640c80351b35e17a1b4231ede0d77f497d5dcdb8503ac508a53c","schema_fingerprint":"4aa3821a28b0b7c2400bc59aba4bcc0a76e971dadd19610d3ad38c768e124dc7","schema_version":"edge-lab-recorder.raw.v1","sequence":null,"source":"clob_market_ws"}
{"event_at":"2026-07-28T04:02:08.412000Z","event_fingerprint":"b4407321c629ac2ed435e3e36f09217fecfe558fedb496c74026fb8f008ecd29","payload":{"connection_id":"f6725804f86a4c4eb588e4d5ed7db029","event_at":"2026-07-28T04:02:08.412000Z","event_type":"price_change","frame_hash":"0a0c4968b50e2b0f47f814a4aa4dafce90f9928773da98336c5bae49fdf934d4","frame_index":0,"kind":"data","monotonic_ns":313312684997833,"payload":{"event_type":"price_change","market":"0xd412ce774cfcf8dc9f71164aac78783978aac7b03871702a3b8a481bd9dc9688","price_changes":[{"asset_id":"96600821790790307414914106093858868634329285205417149685270682748367152458577","best_ask":"0.58","best_bid":"0.57","hash":"8418fcd7234c0d58cc27dc0dd24a9087656ceadd","price":"0.04","side":"BUY","size":"643.09"},{"asset_id":"107603864457683460275633293642179940881969192120168665300712204232021063124301","best_ask":"0.43","best_bid":"0.42","hash":"2fb8d35181ba2732613051fc00ffc3247f1d976e","price":"0.96","side":"SELL","size":"643.09"}],"timestamp":"1785211328412"},"payload_hash":"43b316f7091b323ec9d5a47715e0aa5d83176dd09162339bd93311e4e52a085b","raw_frame":"{\"market\":\"0xd412ce774cfcf8dc9f71164aac78783978aac7b03871702a3b8a481bd9dc9688\", \"price_changes\":[{\"asset_id\":\"96600821790790307414914106093858868634329285205417149685270682748367152458577\", \"price\":\"0.04\", \"size\":\"643.09\", \"side\":\"BUY\", \"hash\":\"8418fcd7234c0d58cc27dc0dd24a9087656ceadd\", \"best_bid\":\"0.57\", \"best_ask\":\"0.58\"}, {\"asset_id\":\"107603864457683460275633293642179940881969192120168665300712204232021063124301\", \"price\":\"0.96\", \"size\":\"643.09\", \"side\":\"SELL\", \"hash\":\"2fb8d35181ba2732613051fc00ffc3247f1d976e\", \"best_bid\":\"0.42\", \"best_ask\":\"0.43\"}], \"timestamp\":\"1785211328412\", \"event_type\":\"price_change\"}","received_at":"2026-07-28T04:02:09.636128Z","schema_version":"clob-market-ws.price_change.v1","sequence":null,"server_hash":null,"server_timestamp":"1785211328412","session_id":"2d607381e3054cee91998cdf45a4231c","source":"clob_market_ws"},"received_at":"2026-07-28T04:02:09.636128Z","record_id":"06bcf6a504cedb1769cc7b4812d5d592a1e9adcf4c0fa66e682017aa235051bd","schema_fingerprint":"4aa3821a28b0b7c2400bc59aba4bcc0a76e971dadd19610d3ad38c768e124dc7","schema_version":"edge-lab-recorder.raw.v1","sequence":null,"source":"clob_market_ws"}
{"event_at":"2026-07-28T04:02:08.413000Z","event_fingerprint":"74a99f76cc400f23d0397fbb5897101f10b4e79c0c8e8e0348a3f664ed20b115","payload":{"connection_id":"f6725804f86a4c4eb588e4d5ed7db029","event_at":"2026-07-28T04:02:08.413000Z","event_type":"price_change","frame_hash":"b8fae387d7f760b3d5fa64fc4d05db67a06bfabdb9b290638ce27ff999e3f6e8","frame_index":0,"kind":"data","monotonic_ns":313312686447291,"payload":{"event_type":"price_change","market":"0xd412ce774cfcf8dc9f71164aac78783978aac7b03871702a3b8a481bd9dc9688","price_changes":[{"asset_id":"96600821790790307414914106093858868634329285205417149685270682748367152458577","best_ask":"0.58","best_bid":"0.57","hash":"f137b6fe5a98f4caa3227327a07edf31c76409cb","price":"0.54","side":"BUY","size":"62.63"},{"asset_id":"107603864457683460275633293642179940881969192120168665300712204232021063124301","best_ask":"0.43","best_bid":"0.42","hash":"d1d658c311b02d6a4fd1855447014a31e4eb1702","price":"0.46","side":"SELL","size":"62.63"}],"timestamp":"1785211328413"},"payload_hash":"1cdbaba98f59eabf64e7ab9a23c742d72ec23cadbe52c67f50a3950788845208","raw_frame":"{\"market\":\"0xd412ce774cfcf8dc9f71164aac78783978aac7b03871702a3b8a481bd9dc9688\", \"price_changes\":[{\"asset_id\":\"96600821790790307414914106093858868634329285205417149685270682748367152458577\", \"price\":\"0.54\", \"size\":\"62.63\", \"side\":\"BUY\", \"hash\":\"f137b6fe5a98f4caa3227327a07edf31c76409cb\", \"best_bid\":\"0.57\", \"best_ask\":\"0.58\"}, {\"asset_id\":\"107603864457683460275633293642179940881969192120168665300712204232021063124301\", \"price\":\"0.46\", \"size\":\"62.63\", \"side\":\"SELL\", \"hash\":\"d1d658c311b02d6a4fd1855447014a31e4eb1702\", \"best_bid\":\"0.42\", \"best_ask\":\"0.43\"}], \"timestamp\":\"1785211328413\", \"event_type\":\"price_change\"}","received_at":"2026-07-28T04:02:09.637577Z","schema_version":"clob-market-ws.price_change.v1","sequence":null,"server_hash":null,"server_timestamp":"1785211328413","session_id":"2d607381e3054cee91998cdf45a4231c","source":"clob_market_ws"},"received_at":"2026-07-28T04:02:09.637577Z","record_id":"9aaab3951642537742206921c269f1053a9dc4664f31da8b4145032aac5b9bdb","schema_fingerprint":"4aa3821a28b0b7c2400bc59aba4bcc0a76e971dadd19610d3ad38c768e124dc7","schema_version":"edge-lab-recorder.raw.v1","sequence":null,"source":"clob_market_ws"}
{"event_at":"2026-07-28T04:02:08.413000Z","event_fingerprint":"a0365f36f83a5d1dbc0578141321ac6799023ee8c523089aec8a5bb02df0a67d","payload":{"connection_id":"f6725804f86a4c4eb588e4d5ed7db029","event_at":"2026-07-28T04:02:08.413000Z","event_type":"price_change","frame_hash":"6cad176a1adbd0891f1ca39ca3ed5b1c09096882d99239555ec967f9ee1fc8d4","frame_index":0,"kind":"data","monotonic_ns":313312687912833,"payload":{"event_type":"price_change","market":"0xd412ce774cfcf8dc9f71164aac78783978aac7b03871702a3b8a481bd9dc9688","price_changes":[{"asset_id":"107603864457683460275633293642179940881969192120168665300712204232021063124301","best_ask":"0.43","best_bid":"0.42","hash":"2a3fe5cfc691d57eb8334a81693845c881a469c4","price":"0.4","side":"BUY","size":"151.21"},{"asset_id":"96600821790790307414914106093858868634329285205417149685270682748367152458577","best_ask":"0.58","best_bid":"0.57","hash":"1e29c12f7279f12eef6329375d480f1a7c22f9cd","price":"0.6","side":"SELL","size":"151.21"}],"timestamp":"1785211328413"},"payload_hash":"da09c5d6e46f242872b27a647d12abf2004898f0afe46a27b7a43054f8c92b72","raw_frame":"{\"market\":\"0xd412ce774cfcf8dc9f71164aac78783978aac7b03871702a3b8a481bd9dc9688\", \"price_changes\":[{\"asset_id\":\"107603864457683460275633293642179940881969192120168665300712204232021063124301\", \"price\":\"0.4\", \"size\":\"151.21\", \"side\":\"BUY\", \"hash\":\"2a3fe5cfc691d57eb8334a81693845c881a469c4\", \"best_bid\":\"0.42\", \"best_ask\":\"0.43\"}, {\"asset_id\":\"96600821790790307414914106093858868634329285205417149685270682748367152458577\", \"price\":\"0.6\", \"size\":\"151.21\", \"side\":\"SELL\", \"hash\":\"1e29c12f7279f12eef6329375d480f1a7c22f9cd\", \"best_bid\":\"0.57\", \"best_ask\":\"0.58\"}], \"timestamp\":\"1785211328413\", \"event_type\":\"price_change\"}","received_at":"2026-07-28T04:02:09.639042Z","schema_version":"clob-market-ws.price_change.v1","sequence":null,"server_hash":null,"server_timestamp":"1785211328413","session_id":"2d607381e3054cee91998cdf45a4231c","source":"clob_market_ws"},"received_at":"2026-07-28T04:02:09.639042Z","record_id":"57d9ef412089df09a2a85508f5e7fe3ddc4abee689ffee5551c50e1b0c2c87e2","schema_fingerprint":"4aa3821a28b0b7c2400bc59aba4bcc0a76e971dadd19610d3ad38c768e124dc7","schema_version":"edge-lab-recorder.raw.v1","sequence":null,"source":"clob_market_ws"}
{"event_at":"2026-07-28T04:02:08.414000Z","event_fingerprint":"8584103027556ea49adad29920d95a2b6a51e3adaea89b3968d2859d1871044e","payload":{"connection_id":"f6725804f86a4c4eb588e4d5ed7db029","event_at":"2026-07-28T04:02:08.414000Z","event_type":"price_change","frame_hash":"4f43fa5e2f69fd59a06dd7c5ff6f1e120ae19b453f0e646c481dbfbacaea45c9","frame_index":0,"kind":"data","monotonic_ns":313312689346541,"payload":{"event_type":"price_change","market":"0xd412ce774cfcf8dc9f71164aac78783978aac7b03871702a3b8a481bd9dc9688","price_changes":[{"asset_id":"107603864457683460275633293642179940881969192120168665300712204232021063124301","best_ask":"0.43","best_bid":"0.42","hash":"ee0736bc50351cad98201b2c03526f0e2975cc1d","price":"0.41","side":"BUY","size":"18.6"},{"asset_id":"96600821790790307414914106093858868634329285205417149685270682748367152458577","best_ask":"0.58","best_bid":"0.57","hash":"96dc6c1f4d21ce4fd5ff869acba31c1d06f79c87","price":"0.59","side":"SELL","size":"18.6"}],"timestamp":"1785211328414"},"payload_hash":"12daa3f0af134604c4937c9f49bd9ad1ff5653d2c02126c91aae0a4474cca70d","raw_frame":"{\"market\":\"0xd412ce774cfcf8dc9f71164aac78783978aac7b03871702a3b8a481bd9dc9688\", \"price_changes\":[{\"asset_id\":\"107603864457683460275633293642179940881969192120168665300712204232021063124301\", \"price\":\"0.41\", \"size\":\"18.6\", \"side\":\"BUY\", \"hash\":\"ee0736bc50351cad98201b2c03526f0e2975cc1d\", \"best_bid\":\"0.42\", \"best_ask\":\"0.43\"}, {\"asset_id\":\"96600821790790307414914106093858868634329285205417149685270682748367152458577\", \"price\":\"0.59\", \"size\":\"18.6\", \"side\":\"SELL\", \"hash\":\"96dc6c1f4d21ce4fd5ff869acba31c1d06f79c87\", \"best_bid\":\"0.57\", \"best_ask\":\"0.58\"}], \"timestamp\":\"1785211328414\", \"event_type\":\"price_change\"}","received_at":"2026-07-28T04:02:09.640476Z","schema_version":"clob-market-ws.price_change.v1","sequence":null,"server_hash":null,"server_timestamp":"1785211328414","session_id":"2d607381e3054cee91998cdf45a4231c","source":"clob_market_ws"},"received_at":"2026-07-28T04:02:09.640476Z","record_id":"34c2c79ad49ab5f4e10ea515877c603414682917d2cb182692cc8c0a2e9863bf","schema_fingerprint":"4aa3821a28b0b7c2400bc59aba4bcc0a76e971dadd19610d3ad38c768e124dc7","schema_version":"edge-lab-recorder.raw.v1","sequence":null,"source":"clob_market_ws"}
{"event_at":"2026-07-28T04:02:08.415000Z","event_fingerprint":"d762be48686f00b99bc81ce74a9ed10344d3623d20b978f96eda10b495cd80bc","payload":{"connection_id":"f6725804f86a4c4eb588e4d5ed7db029","event_at":"2026-07-28T04:02:08.415000Z","event_type":"price_change","frame_hash":"925188080f42874ba03f494dd6207483dc8a687e75fb5fa7c721823eec39677b","frame_index":0,"kind":"data","monotonic_ns":313312690788666,"payload":{"event_type":"price_change","market":"0xd412ce774cfcf8dc9f71164aac78783978aac7b03871702a3b8a481bd9dc9688","price_changes":[{"asset_id":"96600821790790307414914106093858868634329285205417149685270682748367152458577","best_ask":"0.58","best_bid":"0.57","hash":"0d0e7f29b64c9194d865114b949fe98bce448c3a","price":"0.53","side":"BUY","size":"176.02"},{"asset_id":"107603864457683460275633293642179940881969192120168665300712204232021063124301","best_ask":"0.43","best_bid":"0.42","hash":"c55b6f56795cb662e33c0c54242c270f7db94cd7","price":"0.47","side":"SELL","size":"176.02"}],"timestamp":"1785211328415"},"payload_hash":"9d250403358b1e0b6d40dcafb0af163cf31df6a0c3c028c16e5e0a9c270bd32e","raw_frame":"{\"market\":\"0xd412ce774cfcf8dc9f71164aac78783978aac7b03871702a3b8a481bd9dc9688\", \"price_changes\":[{\"asset_id\":\"96600821790790307414914106093858868634329285205417149685270682748367152458577\", \"price\":\"0.53\", \"size\":\"176.02\", \"side\":\"BUY\", \"hash\":\"0d0e7f29b64c9194d865114b949fe98bce448c3a\", \"best_bid\":\"0.57\", \"best_ask\":\"0.58\"}, {\"asset_id\":\"107603864457683460275633293642179940881969192120168665300712204232021063124301\", \"price\":\"0.47\", \"size\":\"176.02\", \"side\":\"SELL\", \"hash\":\"c55b6f56795cb662e33c0c54242c270f7db94cd7\", \"best_bid\":\"0.42\", \"best_ask\":\"0.43\"}], \"timestamp\":\"1785211328415\", \"event_type\":\"price_change\"}","received_at":"2026-07-28T04:02:09.641918Z","schema_version":"clob-market-ws.price_change.v1","sequence":null,"server_hash":null,"server_timestamp":"1785211328415","session_id":"2d607381e3054cee91998cdf45a4231c","source":"clob_market_ws"},"received_at":"2026-07-28T04:02:09.641918Z","record_id":"b02b082ca046fa1aeb871b082560eacfec7f374a34ecda314dce7310bc75678c","schema_fingerprint":"4aa3821a28b0b7c2400bc59aba4bcc0a76e971dadd19610d3ad38c768e124dc7","schema_version":"edge-lab-recorder.raw.v1","sequence":null,"source":"clob_market_ws"}
{"event_at":"2026-07-28T04:02:08.416000Z","event_fingerprint":"231d205399da591cc949a5acf820bab5ef2838a98865bc41219405d2cb6e8228","payload":{"connection_id":"f6725804f86a4c4eb588e4d5ed7db029","event_at":"2026-07-28T04:02:08.416000Z","event_type":"price_change","frame_hash":"cf76c2e8977d54a05b53083804aa993d5570993eb720bb7ec29f9536ff93af0d","frame_index":0,"kind":"data","monotonic_ns":313312692243791,"payload":{"event_type":"price_change","market":"0xd412ce774cfcf8dc9f71164aac78783978aac7b03871702a3b8a481bd9dc9688","price_changes":[{"asset_id":"96600821790790307414914106093858868634329285205417149685270682748367152458577","best_ask":"0.58","best_bid":"0.57","hash":"21b251a625efab27e037b986decc6888a32e32d4","price":"0.56","side":"BUY","size":"28"},{"asset_id":"107603864457683460275633293642179940881969192120168665300712204232021063124301","best_ask":"0.43","best_bid":"0.42","hash":"ef7f058dab02569b54f352e4b6e636041c9c2018","price":"0.44","side":"SELL","size":"28"}],"timestamp":"1785211328416"},"payload_hash":"c73345b0b3015a19a403adc8f0c00e71b5368f43caae442e9830f8089b434aa3","raw_frame":"{\"market\":\"0xd412ce774cfcf8dc9f71164aac78783978aac7b03871702a3b8a481bd9dc9688\", \"price_changes\":[{\"asset_id\":\"96600821790790307414914106093858868634329285205417149685270682748367152458577\", \"price\":\"0.56\", \"size\":\"28\", \"side\":\"BUY\", \"hash\":\"21b251a625efab27e037b986decc6888a32e32d4\", \"best_bid\":\"0.57\", \"best_ask\":\"0.58\"}, {\"asset_id\":\"107603864457683460275633293642179940881969192120168665300712204232021063124301\", \"price\":\"0.44\", \"size\":\"28\", \"side\":\"SELL\", \"hash\":\"ef7f058dab02569b54f352e4b6e636041c9c2018\", \"best_bid\":\"0.42\", \"best_ask\":\"0.43\"}], \"timestamp\":\"1785211328416\", \"event_type\":\"price_change\"}","received_at":"2026-07-28T04:02:09.643372Z","schema_version":"clob-market-ws.price_change.v1","sequence":null,"server_hash":null,"server_timestamp":"1785211328416","session_id":"2d607381e3054cee91998cdf45a4231c","source":"clob_market_ws"},"received_at":"2026-07-28T04:02:09.643372Z","record_id":"9351eb7c130058abf65e23b0e075ab060e92ed36691400176b953b8dfd37c41f","schema_fingerprint":"4aa3821a28b0b7c2400bc59aba4bcc0a76e971dadd19610d3ad38c768e124dc7","schema_version":"edge-lab-recorder.raw.v1","sequence":null,"source":"clob_market_ws"}
{"event_at":"2026-07-28T04:02:08.418000Z","event_fingerprint":"eed8b14b3bbed8f5357683e198e79b9026aaf6e581f6b7bc3fe0ab1b6446ed04","payload":{"connection_id":"f6725804f86a4c4eb588e4d5ed7db029","event_at":"2026-07-28T04:02:08.418000Z","event_type":"price_change","frame_hash":"137d65db56fd18b085dc4936053610d7a18c0d8b03df77ca6c93ed31c61776fd","frame_index":0,"kind":"data","monotonic_ns":313312693769375,"payload":{"event_type":"price_change","market":"0xd412ce774cfcf8dc9f71164aac78783978aac7b03871702a3b8a481bd9dc9688","price_changes":[{"asset_id":"107603864457683460275633293642179940881969192120168665300712204232021063124301","best_ask":"0.43","best_bid":"0.42","hash":"6bff3e83ba4bd8107a963a85788428ed17b80722","price":"0.41","side":"BUY","size":"31.2"},{"asset_id":"96600821790790307414914106093858868634329285205417149685270682748367152458577","best_ask":"0.58","best_bid":"0.57","hash":"1da553965d20fda87e585ace205715de66d747b5","price":"0.59","side":"SELL","size":"31.2"}],"timestamp":"1785211328418"},"payload_hash":"00d732cd5d4f2eff76d68e3b067af106e8f3f567c084e5445de9ef45ffc139c4","raw_frame":"{\"market\":\"0xd412ce774cfcf8dc9f71164aac78783978aac7b03871702a3b8a481bd9dc9688\", \"price_changes\":[{\"asset_id\":\"107603864457683460275633293642179940881969192120168665300712204232021063124301\", \"price\":\"0.41\", \"size\":\"31.2\", \"side\":\"BUY\", \"hash\":\"6bff3e83ba4bd8107a963a85788428ed17b80722\", \"best_bid\":\"0.42\", \"best_ask\":\"0.43\"}, {\"asset_id\":\"96600821790790307414914106093858868634329285205417149685270682748367152458577\", \"price\":\"0.59\", \"size\":\"31.2\", \"side\":\"SELL\", \"hash\":\"1da553965d20fda87e585ace205715de66d747b5\", \"best_bid\":\"0.57\", \"best_ask\":\"0.58\"}], \"timestamp\":\"1785211328418\", \"event_type\":\"price_change\"}","received_at":"2026-07-28T04:02:09.644896Z","schema_version":"clob-market-ws.price_change.v1","sequence":null,"server_hash":null,"server_timestamp":"1785211328418","session_id":"2d607381e3054cee91998cdf45a4231c","source":"clob_market_ws"},"received_at":"2026-07-28T04:02:09.644896Z","record_id":"fa69208eb54283a62ef760d1bddbd5e1d8fd6ff3b7b92efdabe4079225b75965","schema_fingerprint":"4aa3821a28b0b7c2400bc59aba4bcc0a76e971dadd19610d3ad38c768e124dc7","schema_version":"edge-lab-recorder.raw.v1","sequence":null,"source":"clob_market_ws"}
{"event_at":"2026-07-28T04:02:08.419000Z","event_fingerprint":"d79f7ca9a02a7f1f94ec878179fc584084f1e1276f59fdfeeeee08a0e7920a22","payload":{"connection_id":"f6725804f86a4c4eb588e4d5ed7db029","event_at":"2026-07-28T04:02:08.419000Z","event_type":"price_change","frame_hash":"00e67440241ea14a4ea8a75fae995453af60bd7c02f56eabc4dc8562145156ef","frame_index":0,"kind":"data","monotonic_ns":313312695367583,"payload":{"event_type":"price_change","market":"0xd412ce774cfcf8dc9f71164aac78783978aac7b03871702a3b8a481bd9dc9688","price_changes":[{"asset_id":"96600821790790307414914106093858868634329285205417149685270682748367152458577","best_ask":"0.58","best_bid":"0.57","hash":"8879d4bf3aecd2f7aa9ef0a2af2124470bea1ab2","price":"0.55","side":"BUY","size":"13"},{"asset_id":"107603864457683460275633293642179940881969192120168665300712204232021063124301","best_ask":"0.43","best_bid":"0.42","hash":"284495baf63b16404ec1d9c548a9db542af29a3d","price":"0.45","side":"SELL","size":"13"}],"timestamp":"1785211328419"},"payload_hash":"315601e2992d79e179a388fa853c8b27e1f44fcc264c01cd3a5bdc9b73617e3a","raw_frame":"{\"market\":\"0xd412ce774cfcf8dc9f71164aac78783978aac7b03871702a3b8a481bd9dc9688\", \"price_changes\":[{\"asset_id\":\"96600821790790307414914106093858868634329285205417149685270682748367152458577\", \"price\":\"0.55\", \"size\":\"13\", \"side\":\"BUY\", \"hash\":\"8879d4bf3aecd2f7aa9ef0a2af2124470bea1ab2\", \"best_bid\":\"0.57\", \"best_ask\":\"0.58\"}, {\"asset_id\":\"107603864457683460275633293642179940881969192120168665300712204232021063124301\", \"price\":\"0.45\", \"size\":\"13\", \"side\":\"SELL\", \"hash\":\"284495baf63b16404ec1d9c548a9db542af29a3d\", \"best_bid\":\"0.42\", \"best_ask\":\"0.43\"}], \"timestamp\":\"1785211328419\", \"event_type\":\"price_change\"}","received_at":"2026-07-28T04:02:09.646496Z","schema_version":"clob-market-ws.price_change.v1","sequence":null,"server_hash":null,"server_timestamp":"1785211328419","session_id":"2d607381e3054cee91998cdf45a4231c","source":"clob_market_ws"},"received_at":"2026-07-28T04:02:09.646496Z","record_id":"9d5e3359681c19afeb313bdbbb3ce553315bd42c03a9b8b7d144a6718f40f27c","schema_fingerprint":"4aa3821a28b0b7c2400bc59aba4bcc0a76e971dadd19610d3ad38c768e124dc7","schema_version":"edge-lab-recorder.raw.v1","sequence":null,"source":"clob_market_ws"}
{"event_at":"2026-07-28T04:02:08.420000Z","event_fingerprint":"2a42f9cbdcd0403c9bc1dae222b107cb67e5e69e0c535232769a1359023d2b9c","payload":{"connection_id":"f6725804f86a4c4eb588e4d5ed7db029","event_at":"2026-07-28T04:02:08.420000Z","event_type":"price_change","frame_hash":"cda90059207798813b840a7740bbaded7d96c1ed0e12127cabbf55ea41419ebf","frame_index":0,"kind":"data","monotonic_ns":313312696811125,"payload":{"event_type":"price_change","market":"0xd412ce774cfcf8dc9f71164aac78783978aac7b03871702a3b8a481bd9dc9688","price_changes":[{"asset_id":"107603864457683460275633293642179940881969192120168665300712204232021063124301","best_ask":"0.43","best_bid":"0.42","hash":"2637b654df24acf8b6ec0f17d8ad56a145eee8d6","price":"0.32","side":"BUY","size":"175"},{"asset_id":"96600821790790307414914106093858868634329285205417149685270682748367152458577","best_ask":"0.58","best_bid":"0.57","hash":"f17a73bf14cde84cadf58d1898f33c956de2cbcc","price":"0.68","side":"SELL","size":"175"}],"timestamp":"1785211328420"},"payload_hash":"28fe04730db4b0fc3a68e7bc459ca572dd420ff98d83b9faa6e8464f19d00a39","raw_frame":"{\"market\":\"0xd412ce774cfcf8dc9f71164aac78783978aac7b03871702a3b8a481bd9dc9688\", \"price_changes\":[{\"asset_id\":\"107603864457683460275633293642179940881969192120168665300712204232021063124301\", \"price\":\"0.32\", \"size\":\"175\", \"side\":\"BUY\", \"hash\":\"2637b654df24acf8b6ec0f17d8ad56a145eee8d6\", \"best_bid\":\"0.42\", \"best_ask\":\"0.43\"}, {\"asset_id\":\"96600821790790307414914106093858868634329285205417149685270682748367152458577\", \"price\":\"0.68\", \"size\":\"175\", \"side\":\"SELL\", \"hash\":\"f17a73bf14cde84cadf58d1898f33c956de2cbcc\", \"best_bid\":\"0.57\", \"best_ask\":\"0.58\"}], \"timestamp\":\"1785211328420\", \"event_type\":\"price_change\"}","received_at":"2026-07-28T04:02:09.647940Z","schema_version":"clob-market-ws.price_change.v1","sequence":null,"server_hash":null,"server_timestamp":"1785211328420","session_id":"2d607381e3054cee91998cdf45a4231c","source":"clob_market_ws"},"received_at":"2026-07-28T04:02:09.647940Z","record_id":"d442c3c9570f7b51df1a435320a86a67dded71993a5c4440d8c6bba7fc2f6582","schema_fingerprint":"4aa3821a28b0b7c2400bc59aba4bcc0a76e971dadd19610d3ad38c768e124dc7","schema_version":"edge-lab-recorder.raw.v1","sequence":null,"source":"clob_market_ws"}
{"event_at":"2026-07-28T04:02:08.424000Z","event_fingerprint":"cf84fa1d007d4062242ea98ee855468f429de7fdb32b61f5b120f9bbf2359a7d","payload":{"connection_id":"f6725804f86a4c4eb588e4d5ed7db029","event_at":"2026-07-28T04:02:08.424000Z","event_type":"price_change","frame_hash":"73bc8891f4a194678be3cd978cf50e7302c3eb49db028df12df6555af860e26a","frame_index":0,"kind":"data","monotonic_ns":313312698285250,"payload":{"event_type":"price_change","market":"0xd412ce774cfcf8dc9f71164aac78783978aac7b03871702a3b8a481bd9dc9688","price_changes":[{"asset_id":"107603864457683460275633293642179940881969192120168665300712204232021063124301","best_ask":"0.43","best_bid":"0.42","hash":"4cc5782808e125bfa3a40e81810a0d38f302fb90","price":"0.41","side":"BUY","size":"18.6"},{"asset_id":"96600821790790307414914106093858868634329285205417149685270682748367152458577","best_ask":"0.58","best_bid":"0.57","hash":"2783bfb9cc3b8f408b0104a2f523506461e12b81","price":"0.59","side":"SELL","size":"18.6"}],"timestamp":"1785211328424"},"payload_hash":"5809a8033947fd8dce2103f69ae2e3a2db60f423011ad8776ad0a6689131544e","raw_frame":"{\"market\":\"0xd412ce774cfcf8dc9f71164aac78783978aac7b03871702a3b8a481bd9dc9688\", \"price_changes\":[{\"asset_id\":\"107603864457683460275633293642179940881969192120168665300712204232021063124301\", \"price\":\"0.41\", \"size\":\"18.6\", \"side\":\"BUY\", \"hash\":\"4cc5782808e125bfa3a40e81810a0d38f302fb90\", \"best_bid\":\"0.42\", \"best_ask\":\"0.43\"}, {\"asset_id\":\"96600821790790307414914106093858868634329285205417149685270682748367152458577\", \"price\":\"0.59\", \"size\":\"18.6\", \"side\":\"SELL\", \"hash\":\"2783bfb9cc3b8f408b0104a2f523506461e12b81\", \"best_bid\":\"0.57\", \"best_ask\":\"0.58\"}], \"timestamp\":\"1785211328424\", \"event_type\":\"price_change\"}","received_at":"2026-07-28T04:02:09.649415Z","schema_version":"clob-market-ws.price_change.v1","sequence":null,"server_hash":null,"server_timestamp":"1785211328424","session_id":"2d607381e3054cee91998cdf45a4231c","source":"clob_market_ws"},"received_at":"2026-07-28T04:02:09.649415Z","record_id":"a45c3b8d62144ae889c12a8af77018a857f98c5a77e33b9a422dd4da57786741","schema_fingerprint":"4aa3821a28b0b7c2400bc59aba4bcc0a76e971dadd19610d3ad38c768e124dc7","schema_version":"edge-lab-recorder.raw.v1","sequence":null,"source":"clob_market_ws"}
{"event_at":"2026-07-28T04:02:08.426000Z","event_fingerprint":"6540dc6716ec46ab36c67344f81c5c1e38adb8aeb18b6a7cb4f1e7e25c1fbe09","payload":{"connection_id":"f6725804f86a4c4eb588e4d5ed7db029","event_at":"2026-07-28T04:02:08.426000Z","event_type":"price_change","frame_hash":"0a6961d0229abdb0c2fe09ed20f4887efa3847fcc776564ac94cb6a17c8a2210","frame_index":0,"kind":"data","monotonic_ns":313312699732291,"payload":{"event_type":"price_change","market":"0xd412ce774cfcf8dc9f71164aac78783978aac7b03871702a3b8a481bd9dc9688","price_changes":[{"asset_id":"107603864457683460275633293642179940881969192120168665300712204232021063124301","best_ask":"0.43","best_bid":"0.42","hash":"3e193c7338c9d151acfd64f05665b23061084085","price":"0.41","side":"BUY","size":"23.6"},{"asset_id":"96600821790790307414914106093858868634329285205417149685270682748367152458577","best_ask":"0.58","best_bid":"0.57","hash":"136617487d0ec30023615fd42f262716e3b06be4","price":"0.59","side":"SELL","size":"23.6"}],"timestamp":"1785211328426"},"payload_hash":"edf3a0c0ab77499a43e048972a21f79211add25167aa3b6bd659216a1623fcc3","raw_frame":"{\"market\":\"0xd412ce774cfcf8dc9f71164aac78783978aac7b03871702a3b8a481bd9dc9688\", \"price_changes\":[{\"asset_id\":\"107603864457683460275633293642179940881969192120168665300712204232021063124301\", \"price\":\"0.41\", \"size\":\"23.6\", \"side\":\"BUY\", \"hash\":\"3e193c7338c9d151acfd64f05665b23061084085\", \"best_bid\":\"0.42\", \"best_ask\":\"0.43\"}, {\"asset_id\":\"96600821790790307414914106093858868634329285205417149685270682748367152458577\", \"price\":\"0.59\", \"size\":\"23.6\", \"side\":\"SELL\", \"hash\":\"136617487d0ec30023615fd42f262716e3b06be4\", \"best_bid\":\"0.57\", \"best_ask\":\"0.58\"}], \"timestamp\":\"1785211328426\", \"event_type\":\"price_change\"}","received_at":"2026-07-28T04:02:09.650862Z","schema_version":"clob-market-ws.price_change.v1","sequence":null,"server_hash":null,"server_timestamp":"1785211328426","session_id":"2d607381e3054cee91998cdf45a4231c","source":"clob_market_ws"},"received_at":"2026-07-28T04:02:09.650862Z","record_id":"e493e06e09b429470eb029e8deafbe4d25dd00cae56057fecf7444aa1b8155f6","schema_fingerprint":"4aa3821a28b0b7c2400bc59aba4bcc0a76e971dadd19610d3ad38c768e124dc7","schema_version":"edge-lab-recorder.raw.v1","sequence":null,"source":"clob_market_ws"}
{"event_at":"2026-07-28T04:02:08.427000Z","event_fingerprint":"9adeabed45fe3731eb9e3c634f27c6a114dbb6746281a6085c9c5700f3432ef0","payload":{"connection_id":"f6725804f86a4c4eb588e4d5ed7db029","event_at":"2026-07-28T04:02:08.427000Z","event_type":"price_change","frame_hash":"d50e0488a9d68469403c17a08f61bab8f72a04b32c4d85b70f07a345ece8751d","frame_index":0,"kind":"data","monotonic_ns":313312701184750,"payload":{"event_type":"price_change","market":"0xd412ce774cfcf8dc9f71164aac78783978aac7b03871702a3b8a481bd9dc9688","price_changes":[{"asset_id":"107603864457683460275633293642179940881969192120168665300712204232021063124301","best_ask":"0.43","best_bid":"0.42","hash":"8506f1db308acf8dba13e0000e264b4c08ad4511","price":"0.41","side":"BUY","size":"18.6"},{"asset_id":"96600821790790307414914106093858868634329285205417149685270682748367152458577","best_ask":"0.58","best_bid":"0.57","hash":"8e2eebedcdbecf8889fff23662d4750800ef0527","price":"0.59","side":"SELL","size":"18.6"}],"timestamp":"1785211328427"},"payload_hash":"42355177a5affd3b7b6d489f27c91f0171b173673cb64241ac7b9bb555f6fa81","raw_frame":"{\"market\":\"0xd412ce774cfcf8dc9f71164aac78783978aac7b03871702a3b8a481bd9dc9688\", \"price_changes\":[{\"asset_id\":\"107603864457683460275633293642179940881969192120168665300712204232021063124301\", \"price\":\"0.41\", \"size\":\"18.6\", \"side\":\"BUY\", \"hash\":\"8506f1db308acf8dba13e0000e264b4c08ad4511\", \"best_bid\":\"0.42\", \"best_ask\":\"0.43\"}, {\"asset_id\":\"96600821790790307414914106093858868634329285205417149685270682748367152458577\", \"price\":\"0.59\", \"size\":\"18.6\", \"side\":\"SELL\", \"hash\":\"8e2eebedcdbecf8889fff23662d4750800ef0527\", \"best_bid\":\"0.57\", \"best_ask\":\"0.58\"}], \"timestamp\":\"1785211328427\", \"event_type\":\"price_change\"}","received_at":"2026-07-28T04:02:09.652314Z","schema_version":"clob-market-ws.price_change.v1","sequence":null,"server_hash":null,"server_timestamp":"1785211328427","session_id":"2d607381e3054cee91998cdf45a4231c","source":"clob_market_ws"},"received_at":"2026-07-28T04:02:09.652314Z","record_id":"0410fe83b33895a88097eb8688a5885182ab897d3dc49f1c014c94e71cb99691","schema_fingerprint":"4aa3821a28b0b7c2400bc59aba4bcc0a76e971dadd19610d3ad38c768e124dc7","schema_version":"edge-lab-recorder.raw.v1","sequence":null,"source":"clob_market_ws"}
{"event_at":"2026-07-28T04:02:08.427000Z","event_fingerprint":"770b975b77bb250f5b2d04d6175bac8bcfe31847fa0f7cd8feca2e171d96be91","payload":{"connection_id":"f6725804f86a4c4eb588e4d5ed7db029","event_at":"2026-07-28T04:02:08.427000Z","event_type":"price_change","frame_hash":"41defe2c837dff3c11484c5779e96ebaf1b53db7ea5e1182969c25d87c844f83","frame_index":0,"kind":"data","monotonic_ns":313312703590041,"payload":{"event_type":"price_change","market":"0xd412ce774cfcf8dc9f71164aac78783978aac7b03871702a3b8a481bd9dc9688","price_changes":[{"asset_id":"107603864457683460275633293642179940881969192120168665300712204232021063124301","best_ask":"0.43","best_bid":"0.42","hash":"64a6f874690ff1416f796f2019580c536f615793","price":"0.4","side":"BUY","size":"145.21"},{"asset_id":"96600821790790307414914106093858868634329285205417149685270682748367152458577","best_ask":"0.58","best_bid":"0.57","hash":"bdfd0b6fa964e9c681e7b840dec06120de8e1194","price":"0.6","side":"SELL","size":"145.21"}],"timestamp":"1785211328427"},"payload_hash":"81bdda402666f6e6dfd4ae86c35be90242511cf06fb41b9ad04f1fb37cc2d4ac","raw_frame":"{\"market\":\"0xd412ce774cfcf8dc9f71164aac78783978aac7b03871702a3b8a481bd9dc9688\", \"price_changes\":[{\"asset_id\":\"107603864457683460275633293642179940881969192120168665300712204232021063124301\", \"price\":\"0.4\", \"size\":\"145.21\", \"side\":\"BUY\", \"hash\":\"64a6f874690ff1416f796f2019580c536f615793\", \"best_bid\":\"0.42\", \"best_ask\":\"0.43\"}, {\"asset_id\":\"96600821790790307414914106093858868634329285205417149685270682748367152458577\", \"price\":\"0.6\", \"size\":\"145.21\", \"side\":\"SELL\", \"hash\":\"bdfd0b6fa964e9c681e7b840dec06120de8e1194\", \"best_bid\":\"0.57\", \"best_ask\":\"0.58\"}], \"timestamp\":\"1785211328427\", \"event_type\":\"price_change\"}","received_at":"2026-07-28T04:02:09.654720Z","schema_version":"clob-market-ws.price_change.v1","sequence":null,"server_hash":null,"server_timestamp":"1785211328427","session_id":"2d607381e3054cee91998cdf45a4231c","source":"clob_market_ws"},"received_at":"2026-07-28T04:02:09.654720Z","record_id":"15263d6d9fa158df9a7017c5d48c5e2ad7c6bbfd878dffc2f02e2e75f6be6673","schema_fingerprint":"4aa3821a28b0b7c2400bc59aba4bcc0a76e971dadd19610d3ad38c768e124dc7","schema_version":"edge-lab-recorder.raw.v1","sequence":null,"source":"clob_market_ws"}
{"event_at":"2026-07-28T04:02:08.427000Z","event_fingerprint":"ac50d07680cd09dbcf5b2f35404ffdde0b4d62a15540058e3abc281c2e96d5c2","payload":{"connection_id":"f6725804f86a4c4eb588e4d5ed7db029","event_at":"2026-07-28T04:02:08.427000Z","event_type":"price_change","frame_hash":"17f0e35e8bb4fb4cbb7c23f46f8327b91eefb1956e255a61dbaa95c3d966c5fa","frame_index":0,"kind":"data","monotonic_ns":313312705054291,"payload":{"event_type":"price_change","market":"0xd412ce774cfcf8dc9f71164aac78783978aac7b03871702a3b8a481bd9dc9688","price_changes":[{"asset_id":"96600821790790307414914106093858868634329285205417149685270682748367152458577","best_ask":"0.58","best_bid":"0.57","hash":"2acc9ce7e8f9d60aad3f98389f344a3e8552dbf0","price":"0.56","side":"BUY","size":"34"},{"asset_id":"107603864457683460275633293642179940881969192120168665300712204232021063124301","best_ask":"0.43","best_bid":"0.42","hash":"f0fd7a0af82f8e1aac73532dc98d95a384185b48","price":"0.44","side":"SELL","size":"34"}],"timestamp":"1785211328427"},"payload_hash":"e8e220a621b1859785f10e854914107da2e8877c582f437ce97e5b63a412d94f","raw_frame":"{\"market\":\"0xd412ce774cfcf8dc9f71164aac78783978aac7b03871702a3b8a481bd9dc9688\", \"price_changes\":[{\"asset_id\":\"96600821790790307414914106093858868634329285205417149685270682748367152458577\", \"price\":\"0.56\", \"size\":\"34\", \"side\":\"BUY\", \"hash\":\"2acc9ce7e8f9d60aad3f98389f344a3e8552dbf0\", \"best_bid\":\"0.57\", \"best_ask\":\"0.58\"}, {\"asset_id\":\"107603864457683460275633293642179940881969192120168665300712204232021063124301\", \"price\":\"0.44\", \"size\":\"34\", \"side\":\"SELL\", \"hash\":\"f0fd7a0af82f8e1aac73532dc98d95a384185b48\", \"best_bid\":\"0.42\", \"best_ask\":\"0.43\"}], \"timestamp\":\"1785211328427\", \"event_type\":\"price_change\"}","received_at":"2026-07-28T04:02:09.656184Z","schema_version":"clob-market-ws.price_change.v1","sequence":null,"server_hash":null,"server_timestamp":"1785211328427","session_id":"2d607381e3054cee91998cdf45a4231c","source":"clob_market_ws"},"received_at":"2026-07-28T04:02:09.656184Z","record_id":"c70cf24d3fb86442145d492ebb22ccbbb25e5f784eca6e8a155d6ce98efebd2c","schema_fingerprint":"4aa3821a28b0b7c2400bc59aba4bcc0a76e971dadd19610d3ad38c768e124dc7","schema_version":"edge-lab-recorder.raw.v1","sequence":null,"source":"clob_market_ws"}
{"event_at":"2026-07-28T04:02:08.428000Z","event_fingerprint":"29fea723f4e9a86569274a7a455ed196780c53ebc8ccff79d433937132240b09","payload":{"connection_id":"f6725804f86a4c4eb588e4d5ed7db029","event_at":"2026-07-28T04:02:08.428000Z","event_type":"price_change","frame_hash":"40091fbc83b2e1f0c68c166dcd45b9770485bdb536124a496db4ff4fde76006a","frame_index":0,"kind":"data","monotonic_ns":313312706574041,"payload":{"event_type":"price_change","market":"0xd412ce774cfcf8dc9f71164aac78783978aac7b03871702a3b8a481bd9dc9688","price_changes":[{"asset_id":"107603864457683460275633293642179940881969192120168665300712204232021063124301","best_ask":"0.43","best_bid":"0.42","hash":"8abda80bcb6e104666a387973b67d9f8d1a47e68","price":"0.41","side":"BUY","size":"31.6"},{"asset_id":"96600821790790307414914106093858868634329285205417149685270682748367152458577","best_ask":"0.58","best_bid":"0.57","hash":"481c1e478bb8bf2f68b7fda9dc6427557a8b10b6","price":"0.59","side":"SELL","size":"31.6"}],"timestamp":"1785211328428"},"payload_hash":"fcb2c6d5406b58b560f7cb0af67e0888d0c8c8694d742c5dee659723fed7e90c","raw_frame":"{\"market\":\"0xd412ce774cfcf8dc9f71164aac78783978aac7b03871702a3b8a481bd9dc9688\", \"price_changes\":[{\"asset_id\":\"107603864457683460275633293642179940881969192120168665300712204232021063124301\", \"price\":\"0.41\", \"size\":\"31.6\", \"side\":\"BUY\", \"hash\":\"8abda80bcb6e104666a387973b67d9f8d1a47e68\", \"best_bid\":\"0.42\", \"best_ask\":\"0.43\"}, {\"asset_id\":\"96600821790790307414914106093858868634329285205417149685270682748367152458577\", \"price\":\"0.59\", \"size\":\"31.6\", \"side\":\"SELL\", \"hash\":\"481c1e478bb8bf2f68b7fda9dc6427557a8b10b6\", \"best_bid\":\"0.57\", \"best_ask\":\"0.58\"}], \"timestamp\":\"1785211328428\", \"event_type\":\"price_change\"}","received_at":"2026-07-28T04:02:09.657704Z","schema_version":"clob-market-ws.price_change.v1","sequence":null,"server_hash":null,"server_timestamp":"1785211328428","session_id":"2d607381e3054cee91998cdf45a4231c","source":"clob_market_ws"},"received_at":"2026-07-28T04:02:09.657704Z","record_id":"d28f6bd51187b4d42e4ed87fca22a7ed086648ce6d4fab054be8cc18280c56bf","schema_fingerprint":"4aa3821a28b0b7c2400bc59aba4bcc0a76e971dadd19610d3ad38c768e124dc7","schema_version":"edge-lab-recorder.raw.v1","sequence":null,"source":"clob_market_ws"}
{"event_at":"2026-07-28T04:02:08.431000Z","event_fingerprint":"ea5626e34d2c5f29f043cb37885019646df4f2e402f84c15186e183f7ffabc06","payload":{"connection_id":"f6725804f86a4c4eb588e4d5ed7db029","event_at":"2026-07-28T04:02:08.431000Z","event_type":"price_change","frame_hash":"ccf0ed0fd6d1601dd43e22b3b8cb19870932e8af01410db9800bf6e24682ab85","frame_index":0,"kind":"data","monotonic_ns":313312708018750,"payload":{"event_type":"price_change","market":"0xd412ce774cfcf8dc9f71164aac78783978aac7b03871702a3b8a481bd9dc9688","price_changes":[{"asset_id":"107603864457683460275633293642179940881969192120168665300712204232021063124301","best_ask":"0.43","best_bid":"0.42","hash":"0f02a4808a3d68d6ef79da5fb42ef415c55a9c44","price":"0.4","side":"BUY","size":"150.21"},{"asset_id":"96600821790790307414914106093858868634329285205417149685270682748367152458577","best_ask":"0.58","best_bid":"0.57","hash":"62ab3f31232a958ad4b0ed6225ed4a1680596db7","price":"0.6","side":"SELL","size":"150.21"}],"timestamp":"1785211328431"},"payload_hash":"56be53e36a046872e396f284bb2a538c6622326dd34b530efd24b349924a1df4","raw_frame":"{\"market\":\"0xd412ce774cfcf8dc9f71164aac78783978aac7b03871702a3b8a481bd9dc9688\", \"price_changes\":[{\"asset_id\":\"107603864457683460275633293642179940881969192120168665300712204232021063124301\", \"price\":\"0.4\", \"size\":\"150.21\", \"side\":\"BUY\", \"hash\":\"0f02a4808a3d68d6ef79da5fb42ef415c55a9c44\", \"best_bid\":\"0.42\", \"best_ask\":\"0.43\"}, {\"asset_id\":\"96600821790790307414914106093858868634329285205417149685270682748367152458577\", \"price\":\"0.6\", \"size\":\"150.21\", \"side\":\"SELL\", \"hash\":\"62ab3f31232a958ad4b0ed6225ed4a1680596db7\", \"best_bid\":\"0.57\", \"best_ask\":\"0.58\"}], \"timestamp\":\"1785211328431\", \"event_type\":\"price_change\"}","received_at":"2026-07-28T04:02:09.659148Z","schema_version":"clob-market-ws.price_change.v1","sequence":null,"server_hash":null,"server_timestamp":"1785211328431","session_id":"2d607381e3054cee91998cdf45a4231c","source":"clob_market_ws"},"received_at":"2026-07-28T04:02:09.659148Z","record_id":"dde4c28fa7d21b08094d0b442f07e140d3d3482c0fb86aa771c3d75aa01b90ee","schema_fingerprint":"4aa3821a28b0b7c2400bc59aba4bcc0a76e971dadd19610d3ad38c768e124dc7","schema_version":"edge-lab-recorder.raw.v1","sequence":null,"source":"clob_market_ws"}
{"event_at":"2026-07-28T04:02:08.432000Z","event_fingerprint":"02fb68164ff7111250aa97f42ffc83364ccef0a9f9affb09e47598053b14b3b4","payload":{"connection_id":"f6725804f86a4c4eb588e4d5ed7db029","event_at":"2026-07-28T04:02:08.432000Z","event_type":"price_change","frame_hash":"6dba98ac10f4d809a79f876878fa38689ff41273fab0d902ac09a81db7ec08fa","frame_index":0,"kind":"data","monotonic_ns":313312709471083,"payload":{"event_type":"price_change","market":"0xd412ce774cfcf8dc9f71164aac78783978aac7b03871702a3b8a481bd9dc9688","price_changes":[{"asset_id":"107603864457683460275633293642179940881969192120168665300712204232021063124301","best_ask":"0.43","best_bid":"0.42","hash":"71f9972e022d979c0ab3c4d0baaf268190be8bc1","price":"0.36","side":"BUY","size":"104.87"},{"asset_id":"96600821790790307414914106093858868634329285205417149685270682748367152458577","best_ask":"0.58","best_bid":"0.57","hash":"f45adb430d30bf50aaf09f5b5ac6bbe4701164d5","price":"0.64","side":"SELL","size":"104.87"}],"timestamp":"1785211328432"},"payload_hash":"6d63e812c7717afc228dc5f8e860be8c8ac74689a055f432516baacd03336ee4","raw_frame":"{\"market\":\"0xd412ce774cfcf8dc9f71164aac78783978aac7b03871702a3b8a481bd9dc9688\", \"price_changes\":[{\"asset_id\":\"107603864457683460275633293642179940881969192120168665300712204232021063124301\", \"price\":\"0.36\", \"size\":\"104.87\", \"side\":\"BUY\", \"hash\":\"71f9972e022d979c0ab3c4d0baaf268190be8bc1\", \"best_bid\":\"0.42\", \"best_ask\":\"0.43\"}, {\"asset_id\":\"96600821790790307414914106093858868634329285205417149685270682748367152458577\", \"price\":\"0.64\", \"size\":\"104.87\", \"side\":\"SELL\", \"hash\":\"f45adb430d30bf50aaf09f5b5ac6bbe4701164d5\", \"best_bid\":\"0.57\", \"best_ask\":\"0.58\"}], \"timestamp\":\"1785211328432\", \"event_type\":\"price_change\"}","received_at":"2026-07-28T04:02:09.660601Z","schema_version":"clob-market-ws.price_change.v1","sequence":null,"server_hash":null,"server_timestamp":"1785211328432","session_id":"2d607381e3054cee91998cdf45a4231c","source":"clob_market_ws"},"received_at":"2026-07-28T04:02:09.660601Z","record_id":"7de815ce55f23c805578d5ea8a69d7a06b5d6d6517b0147acd9ac8df59132248","schema_fingerprint":"4aa3821a28b0b7c2400bc59aba4bcc0a76e971dadd19610d3ad38c768e124dc7","schema_version":"edge-lab-recorder.raw.v1","sequence":null,"source":"clob_market_ws"}
{"event_at":"2026-07-28T04:02:08.434000Z","event_fingerprint":"1263ae9fd4ec5ffa3f7dbfb4e1f02f6b45beea99beec54d81eaeeeb1703a7302","payload":{"connection_id":"f6725804f86a4c4eb588e4d5ed7db029","event_at":"2026-07-28T04:02:08.434000Z","event_type":"price_change","frame_hash":"720515e78fad71b05c5ca59f798bc4791de592df098838da08339f426d2732f6","frame_index":0,"kind":"data","monotonic_ns":313312710932833,"payload":{"event_type":"price_change","market":"0xd412ce774cfcf8dc9f71164aac78783978aac7b03871702a3b8a481bd9dc9688","price_changes":[{"asset_id":"96600821790790307414914106093858868634329285205417149685270682748367152458577","best_ask":"0.58","best_bid":"0.57","hash":"09fada3b968ec222beeb0e29b6720cd6e69f1d13","price":"0.55","side":"BUY","size":"19"},{"asset_id":"107603864457683460275633293642179940881969192120168665300712204232021063124301","best_ask":"0.43","best_bid":"0.42","hash":"db9cad56b5f92ebe18f93d2e363892dc35815c4a","price":"0.45","side":"SELL","size":"19"}],"timestamp":"1785211328434"},"payload_hash":"ff0219c5f6dcd10264058e1f2444ffeec6001ae759278e314ef70f691d567c0d","raw_frame":"{\"market\":\"0xd412ce774cfcf8dc9f71164aac78783978aac7b03871702a3b8a481bd9dc9688\", \"price_changes\":[{\"asset_id\":\"96600821790790307414914106093858868634329285205417149685270682748367152458577\", \"price\":\"0.55\", \"size\":\"19\", \"side\":\"BUY\", \"hash\":\"09fada3b968ec222beeb0e29b6720cd6e69f1d13\", \"best_bid\":\"0.57\", \"best_ask\":\"0.58\"}, {\"asset_id\":\"107603864457683460275633293642179940881969192120168665300712204232021063124301\", \"price\":\"0.45\", \"size\":\"19\", \"side\":\"SELL\", \"hash\":\"db9cad56b5f92ebe18f93d2e363892dc35815c4a\", \"best_bid\":\"0.42\", \"best_ask\":\"0.43\"}], \"timestamp\":\"1785211328434\", \"event_type\":\"price_change\"}","received_at":"2026-07-28T04:02:09.662061Z","schema_version":"clob-market-ws.price_change.v1","sequence":null,"server_hash":null,"server_timestamp":"1785211328434","session_id":"2d607381e3054cee91998cdf45a4231c","source":"clob_market_ws"},"received_at":"2026-07-28T04:02:09.662061Z","record_id":"a2510805815d295bf66680bde67f2396e42e4d610eb4ed192521c090e5a7d8b4","schema_fingerprint":"4aa3821a28b0b7c2400bc59aba4bcc0a76e971dadd19610d3ad38c768e124dc7","schema_version":"edge-lab-recorder.raw.v1","sequence":null,"source":"clob_market_ws"}
{"event_at":"2026-07-28T04:02:08.434000Z","event_fingerprint":"28e9344e5a4c51d13b7e14f8f0bcb2df76e023c0f07476456c6d20455fd3bd74","payload":{"connection_id":"f6725804f86a4c4eb588e4d5ed7db029","event_at":"2026-07-28T04:02:08.434000Z","event_type":"price_change","frame_hash":"859347de9085310c447588c3de1187f8b7f0d63f297a24a55bdd015c9b72274c","frame_index":0,"kind":"data","monotonic_ns":313312712398291,"payload":{"event_type":"price_change","market":"0xd412ce774cfcf8dc9f71164aac78783978aac7b03871702a3b8a481bd9dc9688","price_changes":[{"asset_id":"96600821790790307414914106093858868634329285205417149685270682748367152458577","best_ask":"0.58","best_bid":"0.57","hash":"85b2977ad21e2e25d677efa39d4014234d5acb90","price":"0.56","side":"BUY","size":"21"},{"asset_id":"107603864457683460275633293642179940881969192120168665300712204232021063124301","best_ask":"0.43","best_bid":"0.42","hash":"c40b5d0281f2579429bc6863a60a8ebcf398c25d","price":"0.44","side":"SELL","size":"21"}],"timestamp":"1785211328434"},"payload_hash":"2bacdd9d444e34e18534f1388ca20ef6cee8be32dc731df8d6c14b3a8c01cdba","raw_frame":"{\"market\":\"0xd412ce774cfcf8dc9f71164aac78783978aac7b03871702a3b8a481bd9dc9688\", \"price_changes\":[{\"asset_id\":\"96600821790790307414914106093858868634329285205417149685270682748367152458577\", \"price\":\"0.56\", \"size\":\"21\", \"side\":\"BUY\", \"hash\":\"85b2977ad21e2e25d677efa39d4014234d5acb90\", \"best_bid\":\"0.57\", \"best_ask\":\"0.58\"}, {\"asset_id\":\"107603864457683460275633293642179940881969192120168665300712204232021063124301\", \"price\":\"0.44\", \"size\":\"21\", \"side\":\"SELL\", \"hash\":\"c40b5d0281f2579429bc6863a60a8ebcf398c25d\", \"best_bid\":\"0.42\", \"best_ask\":\"0.43\"}], \"timestamp\":\"1785211328434\", \"event_type\":\"price_change\"}","received_at":"2026-07-28T04:02:09.663527Z","schema_version":"clob-market-ws.price_change.v1","sequence":null,"server_hash":null,"server_timestamp":"1785211328434","session_id":"2d607381e3054cee91998cdf45a4231c","source":"clob_market_ws"},"received_at":"2026-07-28T04:02:09.663527Z","record_id":"bfdc3ada95bf95ec50fcb68dd2e084fc39e0c3ce5f9ec36685c5b86ff42ff56c","schema_fingerprint":"4aa3821a28b0b7c2400bc59aba4bcc0a76e971dadd19610d3ad38c768e124dc7","schema_version":"edge-lab-recorder.raw.v1","sequence":null,"source":"clob_market_ws"}
{"event_at":"2026-07-28T04:02:08.434000Z","event_fingerprint":"e1d1d4ef3ef406843c026cb447866538be0549956979b15f7294be0bf0b48a82","payload":{"connection_id":"f6725804f86a4c4eb588e4d5ed7db029","event_at":"2026-07-28T04:02:08.434000Z","event_type":"price_change","frame_hash":"3d803dae7c123b2cce34f94a341e06746daccff8fc0c986d4930323c988d9764","frame_index":0,"kind":"data","monotonic_ns":313312713862958,"payload":{"event_type":"price_change","market":"0xd412ce774cfcf8dc9f71164aac78783978aac7b03871702a3b8a481bd9dc9688","price_changes":[{"asset_id":"107603864457683460275633293642179940881969192120168665300712204232021063124301","best_ask":"0.43","best_bid":"0.42","hash":"873c34ee9f482850ec3b1c7a4add0d69f82fa6f1","price":"0.42","side":"BUY","size":"45"},{"asset_id":"96600821790790307414914106093858868634329285205417149685270682748367152458577","best_ask":"0.58","best_bid":"0.57","hash":"53aaa881ae8c41391c3df4942db30235bcd679aa","price":"0.58","side":"SELL","size":"45"}],"timestamp":"1785211328434"},"payload_hash":"000535b93114355e7845e820b383e799519551d41409d286e5e4e2b4c940101b","raw_frame":"{\"market\":\"0xd412ce774cfcf8dc9f71164aac78783978aac7b03871702a3b8a481bd9dc9688\", \"price_changes\":[{\"asset_id\":\"107603864457683460275633293642179940881969192120168665300712204232021063124301\", \"price\":\"0.42\", \"size\":\"45\", \"side\":\"BUY\", \"hash\":\"873c34ee9f482850ec3b1c7a4add0d69f82fa6f1\", \"best_bid\":\"0.42\", \"best_ask\":\"0.43\"}, {\"asset_id\":\"96600821790790307414914106093858868634329285205417149685270682748367152458577\", \"price\":\"0.58\", \"size\":\"45\", \"side\":\"SELL\", \"hash\":\"53aaa881ae8c41391c3df4942db30235bcd679aa\", \"best_bid\":\"0.57\", \"best_ask\":\"0.58\"}], \"timestamp\":\"1785211328434\", \"event_type\":\"price_change\"}","received_at":"2026-07-28T04:02:09.664992Z","schema_version":"clob-market-ws.price_change.v1","sequence":null,"server_hash":null,"server_timestamp":"1785211328434","session_id":"2d607381e3054cee91998cdf45a4231c","source":"clob_market_ws"},"received_at":"2026-07-28T04:02:09.664992Z","record_id":"615329aab472aab9eca4fd7c5f55ada9da1609299f4beb8d93d5d18a6597ad61","schema_fingerprint":"4aa3821a28b0b7c2400bc59aba4bcc0a76e971dadd19610d3ad38c768e124dc7","schema_version":"edge-lab-recorder.raw.v1","sequence":null,"source":"clob_market_ws"}
{"event_at":"2026-07-28T04:02:08.435000Z","event_fingerprint":"f21d060362fb67278627ea5337a41e3f55d89f3735c30b5db23bfc701efb24da","payload":{"connection_id":"f6725804f86a4c4eb588e4d5ed7db029","event_at":"2026-07-28T04:02:08.435000Z","event_type":"price_change","frame_hash":"45636fe62dbecc1730be18d67d826fa4743debadf94a540463a2a74e50b5b28a","frame_index":0,"kind":"data","monotonic_ns":313312715330666,"payload":{"event_type":"price_change","market":"0xd412ce774cfcf8dc9f71164aac78783978aac7b03871702a3b8a481bd9dc9688","price_changes":[{"asset_id":"107603864457683460275633293642179940881969192120168665300712204232021063124301","best_ask":"0.43","best_bid":"0.42","hash":"71498155c798ff4d10520dc35e5888b193c00883","price":"0.37","side":"BUY","size":"138.35"},{"asset_id":"96600821790790307414914106093858868634329285205417149685270682748367152458577","best_ask":"0.58","best_bid":"0.57","hash":"67624f0d75f00f8d4b61f54aed288fed14b4a1eb","price":"0.63","side":"SELL","size":"138.35"}],"timestamp":"1785211328435"},"payload_hash":"8da2404d47115eff525319d2b531d917933dc50a81e0b74872c8e949e53438fb","raw_frame":"{\"market\":\"0xd412ce774cfcf8dc9f71164aac78783978aac7b03871702a3b8a481bd9dc9688\", \"price_changes\":[{\"asset_id\":\"107603864457683460275633293642179940881969192120168665300712204232021063124301\", \"price\":\"0.37\", \"size\":\"138.35\", \"side\":\"BUY\", \"hash\":\"71498155c798ff4d10520dc35e5888b193c00883\", \"best_bid\":\"0.42\", \"best_ask\":\"0.43\"}, {\"asset_id\":\"96600821790790307414914106093858868634329285205417149685270682748367152458577\", \"price\":\"0.63\", \"size\":\"138.35\", \"side\":\"SELL\", \"hash\":\"67624f0d75f00f8d4b61f54aed288fed14b4a1eb\", \"best_bid\":\"0.57\", \"best_ask\":\"0.58\"}], \"timestamp\":\"1785211328435\", \"event_type\":\"price_change\"}","received_at":"2026-07-28T04:02:09.666460Z","schema_version":"clob-market-ws.price_change.v1","sequence":null,"server_hash":null,"server_timestamp":"1785211328435","session_id":"2d607381e3054cee91998cdf45a4231c","source":"clob_market_ws"},"received_at":"2026-07-28T04:02:09.666460Z","record_id":"2f688f645fc8c81336999175f96a341f2e8b22ba203f01c5e5d66040a08318a0","schema_fingerprint":"4aa3821a28b0b7c2400bc59aba4bcc0a76e971dadd19610d3ad38c768e124dc7","schema_version":"edge-lab-recorder.raw.v1","sequence":null,"source":"clob_market_ws"}
{"event_at":"2026-07-28T04:02:08.435000Z","event_fingerprint":"b57873115a8412182c7e89b104a106e4ff159d023de5244b6177eeef40259bae","payload":{"connection_id":"f6725804f86a4c4eb588e4d5ed7db029","event_at":"2026-07-28T04:02:08.435000Z","event_type":"price_change","frame_hash":"45d74d7535e15dedfecde656875ed488acaaacec70f6778e421ee90c96237005","frame_index":0,"kind":"data","monotonic_ns":313312716891333,"payload":{"event_type":"price_change","market":"0xd412ce774cfcf8dc9f71164aac78783978aac7b03871702a3b8a481bd9dc9688","price_changes":[{"asset_id":"107603864457683460275633293642179940881969192120168665300712204232021063124301","best_ask":"0.43","best_bid":"0.42","hash":"c994bccddc30caa26246f2ec4e0730469e4b6671","price":"0.42","side":"BUY","size":"50"},{"asset_id":"96600821790790307414914106093858868634329285205417149685270682748367152458577","best_ask":"0.58","best_bid":"0.57","hash":"b5652b24ba057e68d31c84cce50341769fff52cd","price":"0.58","side":"SELL","size":"50"}],"timestamp":"1785211328435"},"payload_hash":"8f5c33bc17ab3318455ad50fd0df20d478cbeea56944369273f6c5600f64a93c","raw_frame":"{\"market\":\"0xd412ce774cfcf8dc9f71164aac78783978aac7b03871702a3b8a481bd9dc9688\", \"price_changes\":[{\"asset_id\":\"107603864457683460275633293642179940881969192120168665300712204232021063124301\", \"price\":\"0.42\", \"size\":\"50\", \"side\":\"BUY\", \"hash\":\"c994bccddc30caa26246f2ec4e0730469e4b6671\", \"best_bid\":\"0.42\", \"best_ask\":\"0.43\"}, {\"asset_id\":\"96600821790790307414914106093858868634329285205417149685270682748367152458577\", \"price\":\"0.58\", \"size\":\"50\", \"side\":\"SELL\", \"hash\":\"b5652b24ba057e68d31c84cce50341769fff52cd\", \"best_bid\":\"0.57\", \"best_ask\":\"0.58\"}], \"timestamp\":\"1785211328435\", \"event_type\":\"price_change\"}","received_at":"2026-07-28T04:02:09.668020Z","schema_version":"clob-market-ws.price_change.v1","sequence":null,"server_hash":null,"server_timestamp":"1785211328435","session_id":"2d607381e3054cee91998cdf45a4231c","source":"clob_market_ws"},"received_at":"2026-07-28T04:02:09.668020Z","record_id":"88f87d26306ec35473cb059de4ef8bb75e8dc75e1649ea54bce027984345f70b","schema_fingerprint":"4aa3821a28b0b7c2400bc59aba4bcc0a76e971dadd19610d3ad38c768e124dc7","schema_version":"edge-lab-recorder.raw.v1","sequence":null,"source":"clob_market_ws"}
{"event_at":"2026-07-28T04:02:08.436000Z","event_fingerprint":"4035995a7486db3b891becdeb1e034f49bb8400522d4398f7041eb4d5eb4521a","payload":{"connection_id":"f6725804f86a4c4eb588e4d5ed7db029","event_at":"2026-07-28T04:02:08.436000Z","event_type":"price_change","frame_hash":"8c29a937df6edf4376335b7ec41ef25f2b1bebee82dd8324e1e90ced1950fca3","frame_index":0,"kind":"data","monotonic_ns":313312718503500,"payload":{"event_type":"price_change","market":"0xd412ce774cfcf8dc9f71164aac78783978aac7b03871702a3b8a481bd9dc9688","price_changes":[{"asset_id":"107603864457683460275633293642179940881969192120168665300712204232021063124301","best_ask":"0.43","best_bid":"0.42","hash":"200f71ed567e6dfb36156a5fbda3694ad5f404fe","price":"0.41","side":"BUY","size":"37.6"},{"asset_id":"96600821790790307414914106093858868634329285205417149685270682748367152458577","best_ask":"0.58","best_bid":"0.57","hash":"9218c9a9526f4208e4a5a533e93272fe34846243","price":"0.59","side":"SELL","size":"37.6"}],"timestamp":"1785211328436"},"payload_hash":"e4db25303c06aeb96afb20663474e28f6d5d62e879eb2d255f9f9c0036dd76bc","raw_frame":"{\"market\":\"0xd412ce774cfcf8dc9f71164aac78783978aac7b03871702a3b8a481bd9dc9688\", \"price_changes\":[{\"asset_id\":\"107603864457683460275633293642179940881969192120168665300712204232021063124301\", \"price\":\"0.41\", \"size\":\"37.6\", \"side\":\"BUY\", \"hash\":\"200f71ed567e6dfb36156a5fbda3694ad5f404fe\", \"best_bid\":\"0.42\", \"best_ask\":\"0.43\"}, {\"asset_id\":\"96600821790790307414914106093858868634329285205417149685270682748367152458577\", \"price\":\"0.59\", \"size\":\"37.6\", \"side\":\"SELL\", \"hash\":\"9218c9a9526f4208e4a5a533e93272fe34846243\", \"best_bid\":\"0.57\", \"best_ask\":\"0.58\"}], \"timestamp\":\"1785211328436\", \"event_type\":\"price_change\"}","received_at":"2026-07-28T04:02:09.669633Z","schema_version":"clob-market-ws.price_change.v1","sequence":null,"server_hash":null,"server_timestamp":"1785211328436","session_id":"2d607381e3054cee91998cdf45a4231c","source":"clob_market_ws"},"received_at":"2026-07-28T04:02:09.669633Z","record_id":"0d36b29c1fee82cb86bf29108a222a1727984fd6abb29baba2e4123e133b4584","schema_fingerprint":"4aa3821a28b0b7c2400bc59aba4bcc0a76e971dadd19610d3ad38c768e124dc7","schema_version":"edge-lab-recorder.raw.v1","sequence":null,"source":"clob_market_ws"}
{"event_at":"2026-07-28T04:02:08.437000Z","event_fingerprint":"8385ab05d6c512c69749d71f9b3b460206c34c4ca44c86c4b33ff77b32db51a2","payload":{"connection_id":"f6725804f86a4c4eb588e4d5ed7db029","event_at":"2026-07-28T04:02:08.437000Z","event_type":"price_change","frame_hash":"928b097d0069150fe881344ef2f43525217be9dae348abbdf6a168429f35dc17","frame_index":0,"kind":"data","monotonic_ns":313312720001333,"payload":{"event_type":"price_change","market":"0xd412ce774cfcf8dc9f71164aac78783978aac7b03871702a3b8a481bd9dc9688","price_changes":[{"asset_id":"107603864457683460275633293642179940881969192120168665300712204232021063124301","best_ask":"0.43","best_bid":"0.42","hash":"a801d8d5d5d5332ad358a00e4274f27a781b4e35","price":"0.43","side":"SELL","size":"31"},{"asset_id":"96600821790790307414914106093858868634329285205417149685270682748367152458577","best_ask":"0.58","best_bid":"0.57","hash":"a682ead52d7ef5778e9dd98770f51ac2bcca1bc7","price":"0.57","side":"BUY","size":"31"}],"timestamp":"1785211328437"},"payload_hash":"be3a206aea6a89122000c58466f23d61f8a25d9605d57956fa832a095c160905","raw_frame":"{\"market\":\"0xd412ce774cfcf8dc9f71164aac78783978aac7b03871702a3b8a481bd9dc9688\", \"price_changes\":[{\"asset_id\":\"107603864457683460275633293642179940881969192120168665300712204232021063124301\", \"price\":\"0.43\", \"size\":\"31\", \"side\":\"SELL\", \"hash\":\"a801d8d5d5d5332ad358a00e4274f27a781b4e35\", \"best_bid\":\"0.42\", \"best_ask\":\"0.43\"}, {\"asset_id\":\"96600821790790307414914106093858868634329285205417149685270682748367152458577\", \"price\":\"0.57\", \"size\":\"31\", \"side\":\"BUY\", \"hash\":\"a682ead52d7ef5778e9dd98770f51ac2bcca1bc7\", \"best_bid\":\"0.57\", \"best_ask\":\"0.58\"}], \"timestamp\":\"1785211328437\", \"event_type\":\"price_change\"}","received_at":"2026-07-28T04:02:09.671130Z","schema_version":"clob-market-ws.price_change.v1","sequence":null,"server_hash":null,"server_timestamp":"1785211328437","session_id":"2d607381e3054cee91998cdf45a4231c","source":"clob_market_ws"},"received_at":"2026-07-28T04:02:09.671130Z","record_id":"6f8693758ecfce7320cd658b3e9901f213954209a2b2f47903890ae56e0ac386","schema_fingerprint":"4aa3821a28b0b7c2400bc59aba4bcc0a76e971dadd19610d3ad38c768e124dc7","schema_version":"edge-lab-recorder.raw.v1","sequence":null,"source":"clob_market_ws"}
{"event_at":"2026-07-28T04:02:08.438000Z","event_fingerprint":"069efbef431f50d74ec8f638e86d90ef0914b5e7d5c73f91c6077e1224154364","payload":{"connection_id":"f6725804f86a4c4eb588e4d5ed7db029","event_at":"2026-07-28T04:02:08.438000Z","event_type":"price_change","frame_hash":"a3c105dc03e6aa47193bbf2b1fc0f11fe55d88566dfd94ca95adb65e9036e5f9","frame_index":0,"kind":"data","monotonic_ns":313312721455250,"payload":{"event_type":"price_change","market":"0xd412ce774cfcf8dc9f71164aac78783978aac7b03871702a3b8a481bd9dc9688","price_changes":[{"asset_id":"107603864457683460275633293642179940881969192120168665300712204232021063124301","best_ask":"0.43","best_bid":"0.42","hash":"594f5343aadfb78a20646ee76ef085da3e8f71de","price":"0.42","side":"BUY","size":"10"},{"asset_id":"96600821790790307414914106093858868634329285205417149685270682748367152458577","best_ask":"0.58","best_bid":"0.57","hash":"abe5aea44188518d9b885b1a555cf252090a1d2d","price":"0.58","side":"SELL","size":"10"}],"timestamp":"1785211328438"},"payload_hash":"a6d4bcf66be7f4c9e761593c30cb453448e17a3bce1a8158c40533c072951e27","raw_frame":"{\"market\":\"0xd412ce774cfcf8dc9f71164aac78783978aac7b03871702a3b8a481bd9dc9688\", \"price_changes\":[{\"asset_id\":\"107603864457683460275633293642179940881969192120168665300712204232021063124301\", \"price\":\"0.42\", \"size\":\"10\", \"side\":\"BUY\", \"hash\":\"594f5343aadfb78a20646ee76ef085da3e8f71de\", \"best_bid\":\"0.42\", \"best_ask\":\"0.43\"}, {\"asset_id\":\"96600821790790307414914106093858868634329285205417149685270682748367152458577\", \"price\":\"0.58\", \"size\":\"10\", \"side\":\"SELL\", \"hash\":\"abe5aea44188518d9b885b1a555cf252090a1d2d\", \"best_bid\":\"0.57\", \"best_ask\":\"0.58\"}], \"timestamp\":\"1785211328438\", \"event_type\":\"price_change\"}","received_at":"2026-07-28T04:02:09.672584Z","schema_version":"clob-market-ws.price_change.v1","sequence":null,"server_hash":null,"server_timestamp":"1785211328438","session_id":"2d607381e3054cee91998cdf45a4231c","source":"clob_market_ws"},"received_at":"2026-07-28T04:02:09.672584Z","record_id":"9c158346c8c8788ebfd9eb8b2ccc8672c15335b87c37892fe10406d9af3016fb","schema_fingerprint":"4aa3821a28b0b7c2400bc59aba4bcc0a76e971dadd19610d3ad38c768e124dc7","schema_version":"edge-lab-recorder.raw.v1","sequence":null,"source":"clob_market_ws"}
{"event_at":"2026-07-28T04:02:08.439000Z","event_fingerprint":"ba1bc87eff84aee419ccb9136d85cd7f0f4f3aa16c0baada8f32837042f625f5","payload":{"connection_id":"f6725804f86a4c4eb588e4d5ed7db029","event_at":"2026-07-28T04:02:08.439000Z","event_type":"price_change","frame_hash":"a7e19626d823f6dc82d9ce19e680fa309ee03fa6ad4ba972c0ba7242eae39e97","frame_index":0,"kind":"data","monotonic_ns":313312722906083,"payload":{"event_type":"price_change","market":"0xd412ce774cfcf8dc9f71164aac78783978aac7b03871702a3b8a481bd9dc9688","price_changes":[{"asset_id":"96600821790790307414914106093858868634329285205417149685270682748367152458577","best_ask":"0.58","best_bid":"0.57","hash":"1e825222bdfa7890db6793d97e2255d04a5bbed7","price":"0.6","side":"SELL","size":"130.2"},{"asset_id":"107603864457683460275633293642179940881969192120168665300712204232021063124301","best_ask":"0.43","best_bid":"0.42","hash":"fdd14a1df2576ef3e68ded1fefd680e7d014a8f3","price":"0.4","side":"BUY","size":"130.2"}],"timestamp":"1785211328439"},"payload_hash":"47b2ed2c2a5e43f3193a2547555f56b458f6d086f6355b78d4f677a052a96c3e","raw_frame":"{\"market\":\"0xd412ce774cfcf8dc9f71164aac78783978aac7b03871702a3b8a481bd9dc9688\", \"price_changes\":[{\"asset_id\":\"96600821790790307414914106093858868634329285205417149685270682748367152458577\", \"price\":\"0.6\", \"size\":\"130.2\", \"side\":\"SELL\", \"hash\":\"1e825222bdfa7890db6793d97e2255d04a5bbed7\", \"best_bid\":\"0.57\", \"best_ask\":\"0.58\"}, {\"asset_id\":\"107603864457683460275633293642179940881969192120168665300712204232021063124301\", \"price\":\"0.4\", \"size\":\"130.2\", \"side\":\"BUY\", \"hash\":\"fdd14a1df2576ef3e68ded1fefd680e7d014a8f3\", \"best_bid\":\"0.42\", \"best_ask\":\"0.43\"}], \"timestamp\":\"1785211328439\", \"event_type\":\"price_change\"}","received_at":"2026-07-28T04:02:09.674036Z","schema_version":"clob-market-ws.price_change.v1","sequence":null,"server_hash":null,"server_timestamp":"1785211328439","session_id":"2d607381e3054cee91998cdf45a4231c","source":"clob_market_ws"},"received_at":"2026-07-28T04:02:09.674036Z","record_id":"47273fa4c46eb5fb5ea2a27c37083eb43189aafded5288655b240a72a315c419","schema_fingerprint":"4aa3821a28b0b7c2400bc59aba4bcc0a76e971dadd19610d3ad38c768e124dc7","schema_version":"edge-lab-recorder.raw.v1","sequence":null,"source":"clob_market_ws"}
{"event_at":"2026-07-28T04:02:08.439000Z","event_fingerprint":"52f53251695482407b674342e26cdc80be83d76156209e99f6296f80b7608c62","payload":{"connection_id":"f6725804f86a4c4eb588e4d5ed7db029","event_at":"2026-07-28T04:02:08.439000Z","event_type":"price_change","frame_hash":"7ef2186ccce3943d4364404e3c915f6bb029e91116194438df8d1966b10d504a","frame_index":0,"kind":"data","monotonic_ns":313312724345791,"payload":{"event_type":"price_change","market":"0xd412ce774cfcf8dc9f71164aac78783978aac7b03871702a3b8a481bd9dc9688","price_changes":[{"asset_id":"96600821790790307414914106093858868634329285205417149685270682748367152458577","best_ask":"0.58","best_bid":"0.57","hash":"a28c9b6c0da3615eb521a79bd0bc1bfb6adc21e4","price":"0.57","side":"BUY","size":"37"},{"asset_id":"107603864457683460275633293642179940881969192120168665300712204232021063124301","best_ask":"0.43","best_bid":"0.42","hash":"66d0b592856e0fb08331b53aab6ee3584a40a451","price":"0.43","side":"SELL","size":"37"}],"timestamp":"1785211328439"},"payload_hash":"2da99b612bc7464bfe85e09b93b265acf46b73c794dd154d070543951c23d3a2","raw_frame":"{\"market\":\"0xd412ce774cfcf8dc9f71164aac78783978aac7b03871702a3b8a481bd9dc9688\", \"price_changes\":[{\"asset_id\":\"96600821790790307414914106093858868634329285205417149685270682748367152458577\", \"price\":\"0.57\", \"size\":\"37\", \"side\":\"BUY\", \"hash\":\"a28c9b6c0da3615eb521a79bd0bc1bfb6adc21e4\", \"best_bid\":\"0.57\", \"best_ask\":\"0.58\"}, {\"asset_id\":\"107603864457683460275633293642179940881969192120168665300712204232021063124301\", \"price\":\"0.43\", \"size\":\"37\", \"side\":\"SELL\", \"hash\":\"66d0b592856e0fb08331b53aab6ee3584a40a451\", \"best_bid\":\"0.42\", \"best_ask\":\"0.43\"}], \"timestamp\":\"1785211328439\", \"event_type\":\"price_change\"}","received_at":"2026-07-28T04:02:09.675474Z","schema_version":"clob-market-ws.price_change.v1","sequence":null,"server_hash":null,"server_timestamp":"1785211328439","session_id":"2d607381e3054cee91998cdf45a4231c","source":"clob_market_ws"},"received_at":"2026-07-28T04:02:09.675474Z","record_id":"2173b30e02bc6fd4e975f7ad746d9502f1240fdf85a43ba23e6b5760c7161129","schema_fingerprint":"4aa3821a28b0b7c2400bc59aba4bcc0a76e971dadd19610d3ad38c768e124dc7","schema_version":"edge-lab-recorder.raw.v1","sequence":null,"source":"clob_market_ws"}
{"event_at":"2026-07-28T04:02:08.440000Z","event_fingerprint":"8edfa23a22f52e9f80a23ed63ed27783c1d8d2d66f6156d25094a4dab32711b2","payload":{"connection_id":"f6725804f86a4c4eb588e4d5ed7db029","event_at":"2026-07-28T04:02:08.440000Z","event_type":"price_change","frame_hash":"cfec3ab08654582015de941f082ffbf2377f9645035d4aad20682951ec7c453a","frame_index":0,"kind":"data","monotonic_ns":313312725796708,"payload":{"event_type":"price_change","market":"0xd412ce774cfcf8dc9f71164aac78783978aac7b03871702a3b8a481bd9dc9688","price_changes":[{"asset_id":"96600821790790307414914106093858868634329285205417149685270682748367152458577","best_ask":"0.58","best_bid":"0.57","hash":"c8f7db072251477e6d05c3ad76ce4df284703caf","price":"0.54","side":"BUY","size":"68.63"},{"asset_id":"107603864457683460275633293642179940881969192120168665300712204232021063124301","best_ask":"0.43","best_bid":"0.42","hash":"c074a050d89590659d0d608a8cf15b82527bf078","price":"0.46","side":"SELL","size":"68.63"}],"timestamp":"1785211328440"},"payload_hash":"2c2148b610f29695cf995265930f206f4d85e8f43a1ca35bd7372845f94fa57e","raw_frame":"{\"market\":\"0xd412ce774cfcf8dc9f71164aac78783978aac7b03871702a3b8a481bd9dc9688\", \"price_changes\":[{\"asset_id\":\"96600821790790307414914106093858868634329285205417149685270682748367152458577\", \"price\":\"0.54\", \"size\":\"68.63\", \"side\":\"BUY\", \"hash\":\"c8f7db072251477e6d05c3ad76ce4df284703caf\", \"best_bid\":\"0.57\", \"best_ask\":\"0.58\"}, {\"asset_id\":\"107603864457683460275633293642179940881969192120168665300712204232021063124301\", \"price\":\"0.46\", \"size\":\"68.63\", \"side\":\"SELL\", \"hash\":\"c074a050d89590659d0d608a8cf15b82527bf078\", \"best_bid\":\"0.42\", \"best_ask\":\"0.43\"}], \"timestamp\":\"1785211328440\", \"event_type\":\"price_change\"}","received_at":"2026-07-28T04:02:09.676926Z","schema_version":"clob-market-ws.price_change.v1","sequence":null,"server_hash":null,"server_timestamp":"1785211328440","session_id":"2d607381e3054cee91998cdf45a4231c","source":"clob_market_ws"},"received_at":"2026-07-28T04:02:09.676926Z","record_id":"18bf4ab05dc259764ce435ed8d4d2ec9d5af1031dfb0b11ae4166841c61fdf77","schema_fingerprint":"4aa3821a28b0b7c2400bc59aba4bcc0a76e971dadd19610d3ad38c768e124dc7","schema_version":"edge-lab-recorder.raw.v1","sequence":null,"source":"clob_market_ws"}
{"event_at":"2026-07-28T04:02:08.444000Z","event_fingerprint":"df405628175e5a50be909dfab9b71fe2aee9724002466a5d51f73a1fe0ec5600","payload":{"connection_id":"f6725804f86a4c4eb588e4d5ed7db029","event_at":"2026-07-28T04:02:08.444000Z","event_type":"price_change","frame_hash":"9880a9c38198f99686443a0e5fdbcb5a1509f03521095c670ba1142a97135a1c","frame_index":0,"kind":"data","monotonic_ns":313312727244416,"payload":{"event_type":"price_change","market":"0xd412ce774cfcf8dc9f71164aac78783978aac7b03871702a3b8a481bd9dc9688","price_changes":[{"asset_id":"96600821790790307414914106093858868634329285205417149685270682748367152458577","best_ask":"0.58","best_bid":"0.57","hash":"4b46d84794907651e2c147815f65556413d53cc8","price":"0.53","side":"BUY","size":"182.02"},{"asset_id":"107603864457683460275633293642179940881969192120168665300712204232021063124301","best_ask":"0.43","best_bid":"0.42","hash":"6b9eda7745a1f7f8bc60da15735a53f19093f8c8","price":"0.47","side":"SELL","size":"182.02"}],"timestamp":"1785211328444"},"payload_hash":"784868f5932de85fcbb808aac803b81c12ba052c5364ee61475547cbfd0d6490","raw_frame":"{\"market\":\"0xd412ce774cfcf8dc9f71164aac78783978aac7b03871702a3b8a481bd9dc9688\", \"price_changes\":[{\"asset_id\":\"96600821790790307414914106093858868634329285205417149685270682748367152458577\", \"price\":\"0.53\", \"size\":\"182.02\", \"side\":\"BUY\", \"hash\":\"4b46d84794907651e2c147815f65556413d53cc8\", \"best_bid\":\"0.57\", \"best_ask\":\"0.58\"}, {\"asset_id\":\"107603864457683460275633293642179940881969192120168665300712204232021063124301\", \"price\":\"0.47\", \"size\":\"182.02\", \"side\":\"SELL\", \"hash\":\"6b9eda7745a1f7f8bc60da15735a53f19093f8c8\", \"best_bid\":\"0.42\", \"best_ask\":\"0.43\"}], \"timestamp\":\"1785211328444\", \"event_type\":\"price_change\"}","received_at":"2026-07-28T04:02:09.678374Z","schema_version":"clob-market-ws.price_change.v1","sequence":null,"server_hash":null,"server_timestamp":"1785211328444","session_id":"2d607381e3054cee91998cdf45a4231c","source":"clob_market_ws"},"received_at":"2026-07-28T04:02:09.678374Z","record_id":"86436932e27cd733ecd800fd5a81db50fd0c236c6a5c9d7ba1a9be8b68e4ecc8","schema_fingerprint":"4aa3821a28b0b7c2400bc59aba4bcc0a76e971dadd19610d3ad38c768e124dc7","schema_version":"edge-lab-recorder.raw.v1","sequence":null,"source":"clob_market_ws"}
{"event_at":"2026-07-28T04:02:08.446000Z","event_fingerprint":"d4e79bc0f9bcefed663e160930f0be3b8e9c4cc2c170ed2e72068309f4094364","payload":{"connection_id":"f6725804f86a4c4eb588e4d5ed7db029","event_at":"2026-07-28T04:02:08.446000Z","event_type":"price_change","frame_hash":"fdd1155aef8e5afa33fc8f0bc92cfa6e4df9648499040b3f9bd6188059da8b8f","frame_index":0,"kind":"data","monotonic_ns":313312728689125,"payload":{"event_type":"price_change","market":"0xd412ce774cfcf8dc9f71164aac78783978aac7b03871702a3b8a481bd9dc9688","price_changes":[{"asset_id":"107603864457683460275633293642179940881969192120168665300712204232021063124301","best_ask":"0.43","best_bid":"0.42","hash":"c64f8cca4b455e0593ad663d804c717207a20e95","price":"0.4","side":"BUY","size":"135.2"},{"asset_id":"96600821790790307414914106093858868634329285205417149685270682748367152458577","best_ask":"0.58","best_bid":"0.57","hash":"8e1ae7cddd48186bf58c312726e2568e1d8e2e0f","price":"0.6","side":"SELL","size":"135.2"}],"timestamp":"1785211328446"},"payload_hash":"59e400e510dec9492c8948a54a910de1e9f54f86cb4d8e004454d3e7d98c0c44","raw_frame":"{\"market\":\"0xd412ce774cfcf8dc9f71164aac78783978aac7b03871702a3b8a481bd9dc9688\", \"price_changes\":[{\"asset_id\":\"107603864457683460275633293642179940881969192120168665300712204232021063124301\", \"price\":\"0.4\", \"size\":\"135.2\", \"side\":\"BUY\", \"hash\":\"c64f8cca4b455e0593ad663d804c717207a20e95\", \"best_bid\":\"0.42\", \"best_ask\":\"0.43\"}, {\"asset_id\":\"96600821790790307414914106093858868634329285205417149685270682748367152458577\", \"price\":\"0.6\", \"size\":\"135.2\", \"side\":\"SELL\", \"hash\":\"8e1ae7cddd48186bf58c312726e2568e1d8e2e0f\", \"best_bid\":\"0.57\", \"best_ask\":\"0.58\"}], \"timestamp\":\"1785211328446\", \"event_type\":\"price_change\"}","received_at":"2026-07-28T04:02:09.679818Z","schema_version":"clob-market-ws.price_change.v1","sequence":null,"server_hash":null,"server_timestamp":"1785211328446","session_id":"2d607381e3054cee91998cdf45a4231c","source":"clob_market_ws"},"received_at":"2026-07-28T04:02:09.679818Z","record_id":"cb03038abef1ab41926c45a27a952bd30bfb112cccdc66ff75ade8e0c16f3f78","schema_fingerprint":"4aa3821a28b0b7c2400bc59aba4bcc0a76e971dadd19610d3ad38c768e124dc7","schema_version":"edge-lab-recorder.raw.v1","sequence":null,"source":"clob_market_ws"}
{"event_at":"2026-07-28T04:02:08.448000Z","event_fingerprint":"708691b4fdc97c81d9d5bd4a75a4387679110412fc0551be3ba9300ca14b0768","payload":{"connection_id":"f6725804f86a4c4eb588e4d5ed7db029","event_at":"2026-07-28T04:02:08.448000Z","event_type":"price_change","frame_hash":"c881fae9f10b3d827ea127011428c2b4173cea224b178fb416238725fa36c995","frame_index":0,"kind":"data","monotonic_ns":313312730156083,"payload":{"event_type":"price_change","market":"0xd412ce774cfcf8dc9f71164aac78783978aac7b03871702a3b8a481bd9dc9688","price_changes":[{"asset_id":"96600821790790307414914106093858868634329285205417149685270682748367152458577","best_ask":"0.58","best_bid":"0.57","hash":"ecf48b71763c5a56b8cb0b4a9a7a2428036f1fc4","price":"0.56","side":"BUY","size":"15"},{"asset_id":"107603864457683460275633293642179940881969192120168665300712204232021063124301","best_ask":"0.43","best_bid":"0.42","hash":"f92b6e8e852b1c76b1bc185af8eccd7ea1a0399c","price":"0.44","side":"SELL","size":"15"}],"timestamp":"1785211328448"},"payload_hash":"bc99c7f80bb4b16e44dcf473ea37b324c07307d5765d199f9fec1db8c6a69b27","raw_frame":"{\"market\":\"0xd412ce774cfcf8dc9f71164aac78783978aac7b03871702a3b8a481bd9dc9688\", \"price_changes\":[{\"asset_id\":\"96600821790790307414914106093858868634329285205417149685270682748367152458577\", \"price\":\"0.56\", \"size\":\"15\", \"side\":\"BUY\", \"hash\":\"ecf48b71763c5a56b8cb0b4a9a7a2428036f1fc4\", \"best_bid\":\"0.57\", \"best_ask\":\"0.58\"}, {\"asset_id\":\"107603864457683460275633293642179940881969192120168665300712204232021063124301\", \"price\":\"0.44\", \"size\":\"15\", \"side\":\"SELL\", \"hash\":\"f92b6e8e852b1c76b1bc185af8eccd7ea1a0399c\", \"best_bid\":\"0.42\", \"best_ask\":\"0.43\"}], \"timestamp\":\"1785211328448\", \"event_type\":\"price_change\"}","received_at":"2026-07-28T04:02:09.681285Z","schema_version":"clob-market-ws.price_change.v1","sequence":null,"server_hash":null,"server_timestamp":"1785211328448","session_id":"2d607381e3054cee91998cdf45a4231c","source":"clob_market_ws"},"received_at":"2026-07-28T04:02:09.681285Z","record_id":"71c06320827aa911d4944722bc2224009e32b1e4477ef660adfd91ac8b2c8fbf","schema_fingerprint":"4aa3821a28b0b7c2400bc59aba4bcc0a76e971dadd19610d3ad38c768e124dc7","schema_version":"edge-lab-recorder.raw.v1","sequence":null,"source":"clob_market_ws"}
{"event_at":"2026-07-28T04:02:08.448000Z","event_fingerprint":"38dcd214d0eaa566d4c24ee1da89b66c52876fbe266838ba3f1795be2b5793ae","payload":{"connection_id":"f6725804f86a4c4eb588e4d5ed7db029","event_at":"2026-07-28T04:02:08.448000Z","event_type":"price_change","frame_hash":"93ae554dfbf86b5cdc06b7f4aac34dbf218b88f4f89b86336a50568ac38e3217","frame_index":0,"kind":"data","monotonic_ns":313312731599375,"payload":{"event_type":"price_change","market":"0xd412ce774cfcf8dc9f71164aac78783978aac7b03871702a3b8a481bd9dc9688","price_changes":[{"asset_id":"107603864457683460275633293642179940881969192120168665300712204232021063124301","best_ask":"0.43","best_bid":"0.42","hash":"d5466489f2744db2ae186dc6f2859148391329c8","price":"0.4","side":"BUY","size":"161.2"},{"asset_id":"96600821790790307414914106093858868634329285205417149685270682748367152458577","best_ask":"0.58","best_bid":"0.57","hash":"d5e469ad99c356552614618283a81e162cef7216","price":"0.6","side":"SELL","size":"161.2"}],"timestamp":"1785211328448"},"payload_hash":"c88b117755badac259524c6a204c3eafae77a90a8133726930461a57bab52f19","raw_frame":"{\"market\":\"0xd412ce774cfcf8dc9f71164aac78783978aac7b03871702a3b8a481bd9dc9688\", \"price_changes\":[{\"asset_id\":\"107603864457683460275633293642179940881969192120168665300712204232021063124301\", \"price\":\"0.4\", \"size\":\"161.2\", \"side\":\"BUY\", \"hash\":\"d5466489f2744db2ae186dc6f2859148391329c8\", \"best_bid\":\"0.42\", \"best_ask\":\"0.43\"}, {\"asset_id\":\"96600821790790307414914106093858868634329285205417149685270682748367152458577\", \"price\":\"0.6\", \"size\":\"161.2\", \"side\":\"SELL\", \"hash\":\"d5e469ad99c356552614618283a81e162cef7216\", \"best_bid\":\"0.57\", \"best_ask\":\"0.58\"}], \"timestamp\":\"1785211328448\", \"event_type\":\"price_change\"}","received_at":"2026-07-28T04:02:09.682729Z","schema_version":"clob-market-ws.price_change.v1","sequence":null,"server_hash":null,"server_timestamp":"1785211328448","session_id":"2d607381e3054cee91998cdf45a4231c","source":"clob_market_ws"},"received_at":"2026-07-28T04:02:09.682729Z","record_id":"2be2d908dd6be446e566cda2578d9082f4345db7c756362e7239cd9d077835bd","schema_fingerprint":"4aa3821a28b0b7c2400bc59aba4bcc0a76e971dadd19610d3ad38c768e124dc7","schema_version":"edge-lab-recorder.raw.v1","sequence":null,"source":"clob_market_ws"}
{"event_at":"2026-07-28T04:02:08.451000Z","event_fingerprint":"dab0208f9004e98d6df099d642f1068b473e47857b03b98e4b5b45dc0567b07f","payload":{"connection_id":"f6725804f86a4c4eb588e4d5ed7db029","event_at":"2026-07-28T04:02:08.451000Z","event_type":"price_change","frame_hash":"0babf2b3cb96ee31affeedfb1e9883ac13f1fd264c414e09302bdc619ec65568","frame_index":0,"kind":"data","monotonic_ns":313312733055500,"payload":{"event_type":"price_change","market":"0xd412ce774cfcf8dc9f71164aac78783978aac7b03871702a3b8a481bd9dc9688","price_changes":[{"asset_id":"96600821790790307414914106093858868634329285205417149685270682748367152458577","best_ask":"0.58","best_bid":"0.57","hash":"cb34c357aac64ab3a718bf43058e1ebde6af2794","price":"0.4","side":"BUY","size":"151.5"},{"asset_id":"107603864457683460275633293642179940881969192120168665300712204232021063124301","best_ask":"0.43","best_bid":"0.42","hash":"ee81e184dda34642bc581470b4fefda5b6d1e1aa","price":"0.6","side":"SELL","size":"151.5"}],"timestamp":"1785211328451"},"payload_hash":"90af524834a959a1662d4967e21d24b950b3a6d3610209b9fd888576394bcbec","raw_frame":"{\"market\":\"0xd412ce774cfcf8dc9f71164aac78783978aac7b03871702a3b8a481bd9dc9688\", \"price_changes\":[{\"asset_id\":\"96600821790790307414914106093858868634329285205417149685270682748367152458577\", \"price\":\"0.4\", \"size\":\"151.5\", \"side\":\"BUY\", \"hash\":\"cb34c357aac64ab3a718bf43058e1ebde6af2794\", \"best_bid\":\"0.57\", \"best_ask\":\"0.58\"}, {\"asset_id\":\"107603864457683460275633293642179940881969192120168665300712204232021063124301\", \"price\":\"0.6\", \"size\":\"151.5\", \"side\":\"SELL\", \"hash\":\"ee81e184dda34642bc581470b4fefda5b6d1e1aa\", \"best_bid\":\"0.42\", \"best_ask\":\"0.43\"}], \"timestamp\":\"1785211328451\", \"event_type\":\"price_change\"}","received_at":"2026-07-28T04:02:09.684184Z","schema_version":"clob-market-ws.price_change.v1","sequence":null,"server_hash":null,"server_timestamp":"1785211328451","session_id":"2d607381e3054cee91998cdf45a4231c","source":"clob_market_ws"},"received_at":"2026-07-28T04:02:09.684184Z","record_id":"9efac6bb740d87e22be06f9f3a3d01291adc4704ed7be42dac0393ff8e6f4730","schema_fingerprint":"4aa3821a28b0b7c2400bc59aba4bcc0a76e971dadd19610d3ad38c768e124dc7","schema_version":"edge-lab-recorder.raw.v1","sequence":null,"source":"clob_market_ws"}
{"event_at":"2026-07-28T04:02:08.460000Z","event_fingerprint":"737956faecb334215f611c8b740bd7ea83d37d0dd919e8058103617bb7302ae4","payload":{"connection_id":"f6725804f86a4c4eb588e4d5ed7db029","event_at":"2026-07-28T04:02:08.460000Z","event_type":"price_change","frame_hash":"1b90d0c894b3fc3165fbd9bafa91f914061d5c92d40c3af8b37bca9314574da5","frame_index":0,"kind":"data","monotonic_ns":313312734670125,"payload":{"event_type":"price_change","market":"0xd412ce774cfcf8dc9f71164aac78783978aac7b03871702a3b8a481bd9dc9688","price_changes":[{"asset_id":"96600821790790307414914106093858868634329285205417149685270682748367152458577","best_ask":"0.58","best_bid":"0.57","hash":"2be041e7a0a8bd7231dd5addc41ebab91cac2b69","price":"0.57","side":"BUY","size":"12"},{"asset_id":"107603864457683460275633293642179940881969192120168665300712204232021063124301","best_ask":"0.43","best_bid":"0.42","hash":"1003e2fe77682e753783458828831cccf62b55f3","price":"0.43","side":"SELL","size":"12"}],"timestamp":"1785211328460"},"payload_hash":"ad9e23dd73a3e4624e2dd464cb5fd020963d96778f80d324ce2ad7317fd03a15","raw_frame":"{\"market\":\"0xd412ce774cfcf8dc9f71164aac78783978aac7b03871702a3b8a481bd9dc9688\", \"price_changes\":[{\"asset_id\":\"96600821790790307414914106093858868634329285205417149685270682748367152458577\", \"price\":\"0.57\", \"size\":\"12\", \"side\":\"BUY\", \"hash\":\"2be041e7a0a8bd7231dd5addc41ebab91cac2b69\", \"best_bid\":\"0.57\", \"best_ask\":\"0.58\"}, {\"asset_id\":\"107603864457683460275633293642179940881969192120168665300712204232021063124301\", \"price\":\"0.43\", \"size\":\"12\", \"side\":\"SELL\", \"hash\":\"1003e2fe77682e753783458828831cccf62b55f3\", \"best_bid\":\"0.42\", \"best_ask\":\"0.43\"}], \"timestamp\":\"1785211328460\", \"event_type\":\"price_change\"}","received_at":"2026-07-28T04:02:09.685798Z","schema_version":"clob-market-ws.price_change.v1","sequence":null,"server_hash":null,"server_timestamp":"1785211328460","session_id":"2d607381e3054cee91998cdf45a4231c","source":"clob_market_ws"},"received_at":"2026-07-28T04:02:09.685798Z","record_id":"114733b16044235fb7e9ec625d3ff208f17128a535f17d187fa0da779a0bc0b0","schema_fingerprint":"4aa3821a28b0b7c2400bc59aba4bcc0a76e971dadd19610d3ad38c768e124dc7","schema_version":"edge-lab-recorder.raw.v1","sequence":null,"source":"clob_market_ws"}
{"event_at":"2026-07-28T04:02:08.462000Z","event_fingerprint":"bc21d77873b16c5d0ac1cb707fec02bac2d004312f73f7a798df9ec17a8de332","payload":{"connection_id":"f6725804f86a4c4eb588e4d5ed7db029","event_at":"2026-07-28T04:02:08.462000Z","event_type":"price_change","frame_hash":"c896ab496f61b2de4f4db94c1744594fe7bc28fef851934f1caac1477576706e","frame_index":0,"kind":"data","monotonic_ns":313312736161833,"payload":{"event_type":"price_change","market":"0xd412ce774cfcf8dc9f71164aac78783978aac7b03871702a3b8a481bd9dc9688","price_changes":[{"asset_id":"96600821790790307414914106093858868634329285205417149685270682748367152458577","best_ask":"0.58","best_bid":"0.57","hash":"c792795d7fb1dfcf4da61ae819b849699436bb6f","price":"0.04","side":"BUY","size":"638.09"},{"asset_id":"107603864457683460275633293642179940881969192120168665300712204232021063124301","best_ask":"0.43","best_bid":"0.42","hash":"d69c6f624b998ec5d6ccbc2a9b91fa1fb5a4d2c2","price":"0.96","side":"SELL","size":"638.09"}],"timestamp":"1785211328462"},"payload_hash":"7afd21d661c9a58d8de4fd2aa5856a07ed58ee0711e982969f0a105b47f10589","raw_frame":"{\"market\":\"0xd412ce774cfcf8dc9f71164aac78783978aac7b03871702a3b8a481bd9dc9688\", \"price_changes\":[{\"asset_id\":\"96600821790790307414914106093858868634329285205417149685270682748367152458577\", \"price\":\"0.04\", \"size\":\"638.09\", \"side\":\"BUY\", \"hash\":\"c792795d7fb1dfcf4da61ae819b849699436bb6f\", \"best_bid\":\"0.57\", \"best_ask\":\"0.58\"}, {\"asset_id\":\"107603864457683460275633293642179940881969192120168665300712204232021063124301\", \"price\":\"0.96\", \"size\":\"638.09\", \"side\":\"SELL\", \"hash\":\"d69c6f624b998ec5d6ccbc2a9b91fa1fb5a4d2c2\", \"best_bid\":\"0.42\", \"best_ask\":\"0.43\"}], \"timestamp\":\"1785211328462\", \"event_type\":\"price_change\"}","received_at":"2026-07-28T04:02:09.687291Z","schema_version":"clob-market-ws.price_change.v1","sequence":null,"server_hash":null,"server_timestamp":"1785211328462","session_id":"2d607381e3054cee91998cdf45a4231c","source":"clob_market_ws"},"received_at":"2026-07-28T04:02:09.687291Z","record_id":"c3496326e1aa3c2b2ec7fa383a106af2188bc0d9ea16a348c9628124ecd76192","schema_fingerprint":"4aa3821a28b0b7c2400bc59aba4bcc0a76e971dadd19610d3ad38c768e124dc7","schema_version":"edge-lab-recorder.raw.v1","sequence":null,"source":"clob_market_ws"}
{"event_at":"2026-07-28T04:02:08.467000Z","event_fingerprint":"96299093d658fab80ec324e8208ffed96553111dacbd975156977500761268eb","payload":{"connection_id":"f6725804f86a4c4eb588e4d5ed7db029","event_at":"2026-07-28T04:02:08.467000Z","event_type":"price_change","frame_hash":"0310b33da544c741d7b7ff14e32eeaf3ad21c2ff3809f110290b84e88da1f333","frame_index":0,"kind":"data","monotonic_ns":313312737624083,"payload":{"event_type":"price_change","market":"0xd412ce774cfcf8dc9f71164aac78783978aac7b03871702a3b8a481bd9dc9688","price_changes":[{"asset_id":"107603864457683460275633293642179940881969192120168665300712204232021063124301","best_ask":"0.43","best_bid":"0.42","hash":"a8f01aa11faa7c2385ffb002c791247c19c2b5e2","price":"0.39","side":"BUY","size":"54.6"},{"asset_id":"96600821790790307414914106093858868634329285205417149685270682748367152458577","best_ask":"0.58","best_bid":"0.57","hash":"46cd378516dbe1e8dcae32ea1e775ad46d82fdd5","price":"0.61","side":"SELL","size":"54.6"}],"timestamp":"1785211328467"},"payload_hash":"586c1f3b98a4408b7a5b5c15969f3ba9fc70d052d7b65bf85cd55e8d09dd28b4","raw_frame":"{\"market\":\"0xd412ce774cfcf8dc9f71164aac78783978aac7b03871702a3b8a481bd9dc9688\", \"price_changes\":[{\"asset_id\":\"107603864457683460275633293642179940881969192120168665300712204232021063124301\", \"price\":\"0.39\", \"size\":\"54.6\", \"side\":\"BUY\", \"hash\":\"a8f01aa11faa7c2385ffb002c791247c19c2b5e2\", \"best_bid\":\"0.42\", \"best_ask\":\"0.43\"}, {\"asset_id\":\"96600821790790307414914106093858868634329285205417149685270682748367152458577\", \"price\":\"0.61\", \"size\":\"54.6\", \"side\":\"SELL\", \"hash\":\"46cd378516dbe1e8dcae32ea1e775ad46d82fdd5\", \"best_bid\":\"0.57\", \"best_ask\":\"0.58\"}], \"timestamp\":\"1785211328467\", \"event_type\":\"price_change\"}","received_at":"2026-07-28T04:02:09.688753Z","schema_version":"clob-market-ws.price_change.v1","sequence":null,"server_hash":null,"server_timestamp":"1785211328467","session_id":"2d607381e3054cee91998cdf45a4231c","source":"clob_market_ws"},"received_at":"2026-07-28T04:02:09.688753Z","record_id":"74221f6a81f33a97ec7d84fbe86840685a307bf324d2e7c2705590b89fb73175","schema_fingerprint":"4aa3821a28b0b7c2400bc59aba4bcc0a76e971dadd19610d3ad38c768e124dc7","schema_version":"edge-lab-recorder.raw.v1","sequence":null,"source":"clob_market_ws"}
{"event_at":"2026-07-28T04:02:08.468000Z","event_fingerprint":"187f048c0f2042ab1c663ce42d6c80343d20c745b65ddfac3374e2665a850569","payload":{"connection_id":"f6725804f86a4c4eb588e4d5ed7db029","event_at":"2026-07-28T04:02:08.468000Z","event_type":"price_change","frame_hash":"f4bc9d61ae59348f2cc36fcfa000b34ce1259fefcfd7734053b1d00473b2ac48","frame_index":0,"kind":"data","monotonic_ns":313312739073333,"payload":{"event_type":"price_change","market":"0xd412ce774cfcf8dc9f71164aac78783978aac7b03871702a3b8a481bd9dc9688","price_changes":[{"asset_id":"107603864457683460275633293642179940881969192120168665300712204232021063124301","best_ask":"0.43","best_bid":"0.42","hash":"32e55d8a0617bcae592beb81e1fc69612181eaeb","price":"0.4","side":"BUY","size":"166.2"},{"asset_id":"96600821790790307414914106093858868634329285205417149685270682748367152458577","best_ask":"0.58","best_bid":"0.57","hash":"1491db0931013da381d2f55ad42deaae4f5dec80","price":"0.6","side":"SELL","size":"166.2"}],"timestamp":"1785211328468"},"payload_hash":"9f39aa215522aedd87e31c837b5d8df8dd738477c40d6bc44eb10cf4d74b5d4c","raw_frame":"{\"market\":\"0xd412ce774cfcf8dc9f71164aac78783978aac7b03871702a3b8a481bd9dc9688\", \"price_changes\":[{\"asset_id\":\"107603864457683460275633293642179940881969192120168665300712204232021063124301\", \"price\":\"0.4\", \"size\":\"166.2\", \"side\":\"BUY\", \"hash\":\"32e55d8a0617bcae592beb81e1fc69612181eaeb\", \"best_bid\":\"0.42\", \"best_ask\":\"0.43\"}, {\"asset_id\":\"96600821790790307414914106093858868634329285205417149685270682748367152458577\", \"price\":\"0.6\", \"size\":\"166.2\", \"side\":\"SELL\", \"hash\":\"1491db0931013da381d2f55ad42deaae4f5dec80\", \"best_bid\":\"0.57\", \"best_ask\":\"0.58\"}], \"timestamp\":\"1785211328468\", \"event_type\":\"price_change\"}","received_at":"2026-07-28T04:02:09.690203Z","schema_version":"clob-market-ws.price_change.v1","sequence":null,"server_hash":null,"server_timestamp":"1785211328468","session_id":"2d607381e3054cee91998cdf45a4231c","source":"clob_market_ws"},"received_at":"2026-07-28T04:02:09.690203Z","record_id":"7888cbb1f45fdfc5b5a42ad2a2e3679ae44fa23964951b3e8abc2e3a7d41c924","schema_fingerprint":"4aa3821a28b0b7c2400bc59aba4bcc0a76e971dadd19610d3ad38c768e124dc7","schema_version":"edge-lab-recorder.raw.v1","sequence":null,"source":"clob_market_ws"}
{"event_at":"2026-07-28T04:02:08.475000Z","event_fingerprint":"bb15277681f868664684a3748f41202c0144ff818cbbf3ca093d31e7ff977e3b","payload":{"connection_id":"f6725804f86a4c4eb588e4d5ed7db029","event_at":"2026-07-28T04:02:08.475000Z","event_type":"price_change","frame_hash":"d9bcd24f68809e1d2065412447be4a8745f816396bb135ef1c78998526b052ac","frame_index":0,"kind":"data","monotonic_ns":313312740573791,"payload":{"event_type":"price_change","market":"0xd412ce774cfcf8dc9f71164aac78783978aac7b03871702a3b8a481bd9dc9688","price_changes":[{"asset_id":"107603864457683460275633293642179940881969192120168665300712204232021063124301","best_ask":"0.43","best_bid":"0.42","hash":"f582ec38d29ea33f4d04bb8c234929f76ed229bc","price":"0.36","side":"BUY","size":"99.87"},{"asset_id":"96600821790790307414914106093858868634329285205417149685270682748367152458577","best_ask":"0.58","best_bid":"0.57","hash":"d7d26fb503613af403b0fe91dc815168eb0c942c","price":"0.64","side":"SELL","size":"99.87"}],"timestamp":"1785211328475"},"payload_hash":"124ef1f2d8bfc2d028741279333dd86369a4c3c1155240055c7caee6121b5de5","raw_frame":"{\"market\":\"0xd412ce774cfcf8dc9f71164aac78783978aac7b03871702a3b8a481bd9dc9688\", \"price_changes\":[{\"asset_id\":\"107603864457683460275633293642179940881969192120168665300712204232021063124301\", \"price\":\"0.36\", \"size\":\"99.87\", \"side\":\"BUY\", \"hash\":\"f582ec38d29ea33f4d04bb8c234929f76ed229bc\", \"best_bid\":\"0.42\", \"best_ask\":\"0.43\"}, {\"asset_id\":\"96600821790790307414914106093858868634329285205417149685270682748367152458577\", \"price\":\"0.64\", \"size\":\"99.87\", \"side\":\"SELL\", \"hash\":\"d7d26fb503613af403b0fe91dc815168eb0c942c\", \"best_bid\":\"0.57\", \"best_ask\":\"0.58\"}], \"timestamp\":\"1785211328475\", \"event_type\":\"price_change\"}","received_at":"2026-07-28T04:02:09.691702Z","schema_version":"clob-market-ws.price_change.v1","sequence":null,"server_hash":null,"server_timestamp":"1785211328475","session_id":"2d607381e3054cee91998cdf45a4231c","source":"clob_market_ws"},"received_at":"2026-07-28T04:02:09.691702Z","record_id":"1236e09c595e041f2414591fd350e2f74fe501f9cec5f2bc9f33d2c69456dab7","schema_fingerprint":"4aa3821a28b0b7c2400bc59aba4bcc0a76e971dadd19610d3ad38c768e124dc7","schema_version":"edge-lab-recorder.raw.v1","sequence":null,"source":"clob_market_ws"}
{"event_at":"2026-07-28T04:02:08.483000Z","event_fingerprint":"b95c2f37dbd04da003d455870d069714082b1847ce3ee9c72b5a5cdd8312c45d","payload":{"connection_id":"f6725804f86a4c4eb588e4d5ed7db029","event_at":"2026-07-28T04:02:08.483000Z","event_type":"price_change","frame_hash":"b237ab8bb102222706d3be8caa902a46646687866321091731de253857038321","frame_index":0,"kind":"data","monotonic_ns":313312742109000,"payload":{"event_type":"price_change","market":"0xd412ce774cfcf8dc9f71164aac78783978aac7b03871702a3b8a481bd9dc9688","price_changes":[{"asset_id":"96600821790790307414914106093858868634329285205417149685270682748367152458577","best_ask":"0.58","best_bid":"0.57","hash":"595cd37ae0bd50c196b2877a6e9b414eb668fc63","price":"0.4","side":"BUY","size":"159"},{"asset_id":"107603864457683460275633293642179940881969192120168665300712204232021063124301","best_ask":"0.43","best_bid":"0.42","hash":"82ae8de819a36682b5f0f5d98eac00db5503c69b","price":"0.6","side":"SELL","size":"159"}],"timestamp":"1785211328483"},"payload_hash":"53bf2d60db2855d098814a45d6a09ff6fc8541bb3ed09c3cb5822bda8e25843a","raw_frame":"{\"market\":\"0xd412ce774cfcf8dc9f71164aac78783978aac7b03871702a3b8a481bd9dc9688\", \"price_changes\":[{\"asset_id\":\"96600821790790307414914106093858868634329285205417149685270682748367152458577\", \"price\":\"0.4\", \"size\":\"159\", \"side\":\"BUY\", \"hash\":\"595cd37ae0bd50c196b2877a6e9b414eb668fc63\", \"best_bid\":\"0.57\", \"best_ask\":\"0.58\"}, {\"asset_id\":\"107603864457683460275633293642179940881969192120168665300712204232021063124301\", \"price\":\"0.6\", \"size\":\"159\", \"side\":\"SELL\", \"hash\":\"82ae8de819a36682b5f0f5d98eac00db5503c69b\", \"best_bid\":\"0.42\", \"best_ask\":\"0.43\"}], \"timestamp\":\"1785211328483\", \"event_type\":\"price_change\"}","received_at":"2026-07-28T04:02:09.693237Z","schema_version":"clob-market-ws.price_change.v1","sequence":null,"server_hash":null,"server_timestamp":"1785211328483","session_id":"2d607381e3054cee91998cdf45a4231c","source":"clob_market_ws"},"received_at":"2026-07-28T04:02:09.693237Z","record_id":"ef4981ad54d648354fc9e055190138dbbb83d2b74b72e4cec0cef318d55c6175","schema_fingerprint":"4aa3821a28b0b7c2400bc59aba4bcc0a76e971dadd19610d3ad38c768e124dc7","schema_version":"edge-lab-recorder.raw.v1","sequence":null,"source":"clob_market_ws"}
{"event_at":"2026-07-28T04:02:08.498000Z","event_fingerprint":"b4140aadf3643971af8dc4b9e397476610e0167e8259c73b4477141b4acbe9b8","payload":{"connection_id":"f6725804f86a4c4eb588e4d5ed7db029","event_at":"2026-07-28T04:02:08.498000Z","event_type":"price_change","frame_hash":"4482d3535586b56875d0811831f34fa37ed9490c9defc11ae1258d7195748ee3","frame_index":0,"kind":"data","monotonic_ns":313312744976583,"payload":{"event_type":"price_change","market":"0xd412ce774cfcf8dc9f71164aac78783978aac7b03871702a3b8a481bd9dc9688","price_changes":[{"asset_id":"96600821790790307414914106093858868634329285205417149685270682748367152458577","best_ask":"0.58","best_bid":"0.57","hash":"bdef83faad39ade886724f8a17f79a43a13a0005","price":"0.54","side":"BUY","size":"56.6"},{"asset_id":"107603864457683460275633293642179940881969192120168665300712204232021063124301","best_ask":"0.43","best_bid":"0.42","hash":"0cabf6935a92190447a4f255d021b8b013e8f795","price":"0.46","side":"SELL","size":"56.6"}],"timestamp":"1785211328498"},"payload_hash":"1e2f0eb17967a360f73129de29638a2befaa6ee89e97db5611736f095da0e562","raw_frame":"{\"market\":\"0xd412ce774cfcf8dc9f71164aac78783978aac7b03871702a3b8a481bd9dc9688\", \"price_changes\":[{\"asset_id\":\"96600821790790307414914106093858868634329285205417149685270682748367152458577\", \"price\":\"0.54\", \"size\":\"56.6\", \"side\":\"BUY\", \"hash\":\"bdef83faad39ade886724f8a17f79a43a13a0005\", \"best_bid\":\"0.57\", \"best_ask\":\"0.58\"}, {\"asset_id\":\"107603864457683460275633293642179940881969192120168665300712204232021063124301\", \"price\":\"0.46\", \"size\":\"56.6\", \"side\":\"SELL\", \"hash\":\"0cabf6935a92190447a4f255d021b8b013e8f795\", \"best_bid\":\"0.42\", \"best_ask\":\"0.43\"}], \"timestamp\":\"1785211328498\", \"event_type\":\"price_change\"}","received_at":"2026-07-28T04:02:09.696105Z","schema_version":"clob-market-ws.price_change.v1","sequence":null,"server_hash":null,"server_timestamp":"1785211328498","session_id":"2d607381e3054cee91998cdf45a4231c","source":"clob_market_ws"},"received_at":"2026-07-28T04:02:09.696105Z","record_id":"d07ec19278c26a22ac64a73033aed754db91cc44ee920372cfd38b98ca9fd555","schema_fingerprint":"4aa3821a28b0b7c2400bc59aba4bcc0a76e971dadd19610d3ad38c768e124dc7","schema_version":"edge-lab-recorder.raw.v1","sequence":null,"source":"clob_market_ws"}
{"event_at":"2026-07-28T04:02:08.508000Z","event_fingerprint":"dbf8ec5173e9d6ff6db3b4820fe9e160d8c63e4d2433e6885591946490128fe1","payload":{"connection_id":"f6725804f86a4c4eb588e4d5ed7db029","event_at":"2026-07-28T04:02:08.508000Z","event_type":"price_change","frame_hash":"b552a93c110f9e9cabd7ba2ccd302e7afbdec5c265291deef42da4a1e8130213","frame_index":0,"kind":"data","monotonic_ns":313312747203583,"payload":{"event_type":"price_change","market":"0xd412ce774cfcf8dc9f71164aac78783978aac7b03871702a3b8a481bd9dc9688","price_changes":[{"asset_id":"96600821790790307414914106093858868634329285205417149685270682748367152458577","best_ask":"0.58","best_bid":"0.57","hash":"b6c8f8b19d0b08d0163c98840668a4ef4f85e84f","price":"0.5","side":"BUY","size":"129"},{"asset_id":"107603864457683460275633293642179940881969192120168665300712204232021063124301","best_ask":"0.43","best_bid":"0.42","hash":"2c44a15717920f44ca480aa77a35325d2e71ca37","price":"0.5","side":"SELL","size":"129"}],"timestamp":"1785211328508"},"payload_hash":"9d9f6fcdf55d59b2d06a0b816312c60473c9105ae87fc4a19cbfe1d3b4447854","raw_frame":"{\"market\":\"0xd412ce774cfcf8dc9f71164aac78783978aac7b03871702a3b8a481bd9dc9688\", \"price_changes\":[{\"asset_id\":\"96600821790790307414914106093858868634329285205417149685270682748367152458577\", \"price\":\"0.5\", \"size\":\"129\", \"side\":\"BUY\", \"hash\":\"b6c8f8b19d0b08d0163c98840668a4ef4f85e84f\", \"best_bid\":\"0.57\", \"best_ask\":\"0.58\"}, {\"asset_id\":\"107603864457683460275633293642179940881969192120168665300712204232021063124301\", \"price\":\"0.5\", \"size\":\"129\", \"side\":\"SELL\", \"hash\":\"2c44a15717920f44ca480aa77a35325d2e71ca37\", \"best_bid\":\"0.42\", \"best_ask\":\"0.43\"}], \"timestamp\":\"1785211328508\", \"event_type\":\"price_change\"}","received_at":"2026-07-28T04:02:09.698332Z","schema_version":"clob-market-ws.price_change.v1","sequence":null,"server_hash":null,"server_timestamp":"1785211328508","session_id":"2d607381e3054cee91998cdf45a4231c","source":"clob_market_ws"},"received_at":"2026-07-28T04:02:09.698332Z","record_id":"4a9a17cd54d1dd8cf7f6a3ecf009833bb07711509af91c9aa35d1fed1af69bac","schema_fingerprint":"4aa3821a28b0b7c2400bc59aba4bcc0a76e971dadd19610d3ad38c768e124dc7","schema_version":"edge-lab-recorder.raw.v1","sequence":null,"source":"clob_market_ws"}
{"event_at":"2026-07-28T04:02:08.518000Z","event_fingerprint":"1ca08d4fb5407462fd1c98599c8a4011095f4b266bb6d08f7d0014b90ae6a14e","payload":{"connection_id":"f6725804f86a4c4eb588e4d5ed7db029","event_at":"2026-07-28T04:02:08.518000Z","event_type":"price_change","frame_hash":"6182951b0d23500603eb18bc0381db56a03e380179f1568530f389dc0a1f667a","frame_index":0,"kind":"data","monotonic_ns":313312748819916,"payload":{"event_type":"price_change","market":"0xd412ce774cfcf8dc9f71164aac78783978aac7b03871702a3b8a481bd9dc9688","price_changes":[{"asset_id":"96600821790790307414914106093858868634329285205417149685270682748367152458577","best_ask":"0.58","best_bid":"0.57","hash":"844c37a4483a55db9eeb8b6a6c2ba1fb25e67130","price":"0.01","side":"BUY","size":"7858.02"},{"asset_id":"107603864457683460275633293642179940881969192120168665300712204232021063124301","best_ask":"0.43","best_bid":"0.42","hash":"a0e8d1869708994836858ca2ab26f3676c22b4ce","price":"0.99","side":"SELL","size":"7858.02"}],"timestamp":"1785211328518"},"payload_hash":"f3d20711ed917d529f710953f22cf43be6c33c5b04e127f90425df68d79c1e29","raw_frame":"{\"market\":\"0xd412ce774cfcf8dc9f71164aac78783978aac7b03871702a3b8a481bd9dc9688\", \"price_changes\":[{\"asset_id\":\"96600821790790307414914106093858868634329285205417149685270682748367152458577\", \"price\":\"0.01\", \"size\":\"7858.02\", \"side\":\"BUY\", \"hash\":\"844c37a4483a55db9eeb8b6a6c2ba1fb25e67130\", \"best_bid\":\"0.57\", \"best_ask\":\"0.58\"}, {\"asset_id\":\"107603864457683460275633293642179940881969192120168665300712204232021063124301\", \"price\":\"0.99\", \"size\":\"7858.02\", \"side\":\"SELL\", \"hash\":\"a0e8d1869708994836858ca2ab26f3676c22b4ce\", \"best_bid\":\"0.42\", \"best_ask\":\"0.43\"}], \"timestamp\":\"1785211328518\", \"event_type\":\"price_change\"}","received_at":"2026-07-28T04:02:09.699948Z","schema_version":"clob-market-ws.price_change.v1","sequence":null,"server_hash":null,"server_timestamp":"1785211328518","session_id":"2d607381e3054cee91998cdf45a4231c","source":"clob_market_ws"},"received_at":"2026-07-28T04:02:09.699948Z","record_id":"1917a3a51ab19c16b9151871133c4940a35a922f0da67aef55a9bd4fea717709","schema_fingerprint":"4aa3821a28b0b7c2400bc59aba4bcc0a76e971dadd19610d3ad38c768e124dc7","schema_version":"edge-lab-recorder.raw.v1","sequence":null,"source":"clob_market_ws"}
{"event_at":"2026-07-28T04:02:08.542000Z","event_fingerprint":"7cee1dd2484deb52c7babca0c0a8098bf2a68a78310df84e18e82fafb6429230","payload":{"connection_id":"f6725804f86a4c4eb588e4d5ed7db029","event_at":"2026-07-28T04:02:08.542000Z","event_type":"price_change","frame_hash":"a423bd16a2c365b5ae4beb446ac7a2c45bb9d433eb45f012c499d1d12878b400","frame_index":0,"kind":"data","monotonic_ns":313312751651500,"payload":{"event_type":"price_change","market":"0xd412ce774cfcf8dc9f71164aac78783978aac7b03871702a3b8a481bd9dc9688","price_changes":[{"asset_id":"96600821790790307414914106093858868634329285205417149685270682748367152458577","best_ask":"0.58","best_bid":"0.57","hash":"de25b69ba7396f92898c205a14f92bf4eb89549f","price":"0.01","side":"BUY","size":"7853.02"},{"asset_id":"107603864457683460275633293642179940881969192120168665300712204232021063124301","best_ask":"0.43","best_bid":"0.42","hash":"8851d3b65a5af0091b8d7fd2524d0464d37f0898","price":"0.99","side":"SELL","size":"7853.02"}],"timestamp":"1785211328542"},"payload_hash":"ba88f3cd6cea1e61217b5490927911e53901dd589190a3c10a55acb83ea113ed","raw_frame":"{\"market\":\"0xd412ce774cfcf8dc9f71164aac78783978aac7b03871702a3b8a481bd9dc9688\", \"price_changes\":[{\"asset_id\":\"96600821790790307414914106093858868634329285205417149685270682748367152458577\", \"price\":\"0.01\", \"size\":\"7853.02\", \"side\":\"BUY\", \"hash\":\"de25b69ba7396f92898c205a14f92bf4eb89549f\", \"best_bid\":\"0.57\", \"best_ask\":\"0.58\"}, {\"asset_id\":\"107603864457683460275633293642179940881969192120168665300712204232021063124301\", \"price\":\"0.99\", \"size\":\"7853.02\", \"side\":\"SELL\", \"hash\":\"8851d3b65a5af0091b8d7fd2524d0464d37f0898\", \"best_bid\":\"0.42\", \"best_ask\":\"0.43\"}], \"timestamp\":\"1785211328542\", \"event_type\":\"price_change\"}","received_at":"2026-07-28T04:02:09.702780Z","schema_version":"clob-market-ws.price_change.v1","sequence":null,"server_hash":null,"server_timestamp":"1785211328542","session_id":"2d607381e3054cee91998cdf45a4231c","source":"clob_market_ws"},"received_at":"2026-07-28T04:02:09.702780Z","record_id":"257f04b167fc45cbb7ceae490bf9af65b52f459d484ec5743337a747bbd76d58","schema_fingerprint":"4aa3821a28b0b7c2400bc59aba4bcc0a76e971dadd19610d3ad38c768e124dc7","schema_version":"edge-lab-recorder.raw.v1","sequence":null,"source":"clob_market_ws"}
{"event_at":"2026-07-28T04:02:08.543000Z","event_fingerprint":"9a3e689239a3cdcdfc3fb6f637443d1cf966b479bf6118a0716daf45723cf215","payload":{"connection_id":"f6725804f86a4c4eb588e4d5ed7db029","event_at":"2026-07-28T04:02:08.543000Z","event_type":"price_change","frame_hash":"9acf2697a090e435c38675ded9e04e864021d63d28b92ad135954870372d10cf","frame_index":0,"kind":"data","monotonic_ns":313312755632625,"payload":{"event_type":"price_change","market":"0xd412ce774cfcf8dc9f71164aac78783978aac7b03871702a3b8a481bd9dc9688","price_changes":[{"asset_id":"96600821790790307414914106093858868634329285205417149685270682748367152458577","best_ask":"0.58","best_bid":"0.57","hash":"61e10716bf5c0e343d4dedb321a2077c2a8d438d","price":"0.03","side":"BUY","size":"648.1"},{"asset_id":"107603864457683460275633293642179940881969192120168665300712204232021063124301","best_ask":"0.43","best_bid":"0.42","hash":"48dd2431d01f0bfe206ac71973655216fde363d5","price":"0.97","side":"SELL","size":"648.1"}],"timestamp":"1785211328543"},"payload_hash":"8b725d5b4b9097f2ac6685a7c3bb3acf1f01ab7a7cc100edbecc93d97a15de0d","raw_frame":"{\"market\":\"0xd412ce774cfcf8dc9f71164aac78783978aac7b03871702a3b8a481bd9dc9688\", \"price_changes\":[{\"asset_id\":\"96600821790790307414914106093858868634329285205417149685270682748367152458577\", \"price\":\"0.03\", \"size\":\"648.1\", \"side\":\"BUY\", \"hash\":\"61e10716bf5c0e343d4dedb321a2077c2a8d438d\", \"best_bid\":\"0.57\", \"best_ask\":\"0.58\"}, {\"asset_id\":\"107603864457683460275633293642179940881969192120168665300712204232021063124301\", \"price\":\"0.97\", \"size\":\"648.1\", \"side\":\"SELL\", \"hash\":\"48dd2431d01f0bfe206ac71973655216fde363d5\", \"best_bid\":\"0.42\", \"best_ask\":\"0.43\"}], \"timestamp\":\"1785211328543\", \"event_type\":\"price_change\"}","received_at":"2026-07-28T04:02:09.706761Z","schema_version":"clob-market-ws.price_change.v1","sequence":null,"server_hash":null,"server_timestamp":"1785211328543","session_id":"2d607381e3054cee91998cdf45a4231c","source":"clob_market_ws"},"received_at":"2026-07-28T04:02:09.706761Z","record_id":"0e95cca578e5a44cf5808fb7b88fe9cd802a33ee47cd9e9ac4e83479beadcac5","schema_fingerprint":"4aa3821a28b0b7c2400bc59aba4bcc0a76e971dadd19610d3ad38c768e124dc7","schema_version":"edge-lab-recorder.raw.v1","sequence":null,"source":"clob_market_ws"}
{"event_at":"2026-07-28T04:02:08.543000Z","event_fingerprint":"b22bf91b7b17f5c61fdff2c809f2b3aa33c7898f57662479910109a23a9f4d23","payload":{"connection_id":"f6725804f86a4c4eb588e4d5ed7db029","event_at":"2026-07-28T04:02:08.543000Z","event_type":"price_change","frame_hash":"ddef4f6e9d3474d26b28248996d2dcca4dcd33090bcb6206e19478038c775528","frame_index":0,"kind":"data","monotonic_ns":313312761289250,"payload":{"event_type":"price_change","market":"0xd412ce774cfcf8dc9f71164aac78783978aac7b03871702a3b8a481bd9dc9688","price_changes":[{"asset_id":"107603864457683460275633293642179940881969192120168665300712204232021063124301","best_ask":"0.43","best_bid":"0.42","hash":"9d4ac0df249ad2ca82efe27f296e8235c641113a","price":"0.39","side":"BUY","size":"48.6"},{"asset_id":"96600821790790307414914106093858868634329285205417149685270682748367152458577","best_ask":"0.58","best_bid":"0.57","hash":"a9523c10e2487302dcde6f9bfd6d7942b91d9fe1","price":"0.61","side":"SELL","size":"48.6"}],"timestamp":"1785211328543"},"payload_hash":"4dea0571a2d004f5ec717dda25501a8c1fe6a9e92c294b665d40988b0334473c","raw_frame":"{\"market\":\"0xd412ce774cfcf8dc9f71164aac78783978aac7b03871702a3b8a481bd9dc9688\", \"price_changes\":[{\"asset_id\":\"107603864457683460275633293642179940881969192120168665300712204232021063124301\", \"price\":\"0.39\", \"size\":\"48.6\", \"side\":\"BUY\", \"hash\":\"9d4ac0df249ad2ca82efe27f296e8235c641113a\", \"best_bid\":\"0.42\", \"best_ask\":\"0.43\"}, {\"asset_id\":\"96600821790790307414914106093858868634329285205417149685270682748367152458577\", \"price\":\"0.61\", \"size\":\"48.6\", \"side\":\"SELL\", \"hash\":\"a9523c10e2487302dcde6f9bfd6d7942b91d9fe1\", \"best_bid\":\"0.57\", \"best_ask\":\"0.58\"}], \"timestamp\":\"1785211328543\", \"event_type\":\"price_change\"}","received_at":"2026-07-28T04:02:09.712418Z","schema_version":"clob-market-ws.price_change.v1","sequence":null,"server_hash":null,"server_timestamp":"1785211328543","session_id":"2d607381e3054cee91998cdf45a4231c","source":"clob_market_ws"},"received_at":"2026-07-28T04:02:09.712418Z","record_id":"b7de0b6ed31b73ce6d0c9ecf725dfca2038ec58a4909d55b603041b30364024f","schema_fingerprint":"4aa3821a28b0b7c2400bc59aba4bcc0a76e971dadd19610d3ad38c768e124dc7","schema_version":"edge-lab-recorder.raw.v1","sequence":null,"source":"clob_market_ws"}
{"event_at":"2026-07-28T04:02:08.544000Z","event_fingerprint":"ee790da5f6e549ecca0651faf9f0ddb4d795391599493f654cf19ebac5415111","payload":{"connection_id":"f6725804f86a4c4eb588e4d5ed7db029","event_at":"2026-07-28T04:02:08.544000Z","event_type":"price_change","frame_hash":"1ab5c378680f9e9b5b2a1d6eab69ee0dd3c81e631715474540df3661d774f534","frame_index":0,"kind":"data","monotonic_ns":313312764941000,"payload":{"event_type":"price_change","market":"0xd412ce774cfcf8dc9f71164aac78783978aac7b03871702a3b8a481bd9dc9688","price_changes":[{"asset_id":"107603864457683460275633293642179940881969192120168665300712204232021063124301","best_ask":"0.43","best_bid":"0.42","hash":"25f25a58e905320836e607aad3cb474283b5bc2b","price":"0.4","side":"BUY","size":"140.2"},{"asset_id":"96600821790790307414914106093858868634329285205417149685270682748367152458577","best_ask":"0.58","best_bid":"0.57","hash":"329ba4be9dd6ba641c8c2aaca70cb0da6880c36b","price":"0.6","side":"SELL","size":"140.2"}],"timestamp":"1785211328544"},"payload_hash":"96a47a155a0d0c707fd5bf24b15616665540f29c10d6173ab4deec370920b0cd","raw_frame":"{\"market\":\"0xd412ce774cfcf8dc9f71164aac78783978aac7b03871702a3b8a481bd9dc9688\", \"price_changes\":[{\"asset_id\":\"107603864457683460275633293642179940881969192120168665300712204232021063124301\", \"price\":\"0.4\", \"size\":\"140.2\", \"side\":\"BUY\", \"hash\":\"25f25a58e905320836e607aad3cb474283b5bc2b\", \"best_bid\":\"0.42\", \"best_ask\":\"0.43\"}, {\"asset_id\":\"96600821790790307414914106093858868634329285205417149685270682748367152458577\", \"price\":\"0.6\", \"size\":\"140.2\", \"side\":\"SELL\", \"hash\":\"329ba4be9dd6ba641c8c2aaca70cb0da6880c36b\", \"best_bid\":\"0.57\", \"best_ask\":\"0.58\"}], \"timestamp\":\"1785211328544\", \"event_type\":\"price_change\"}","received_at":"2026-07-28T04:02:09.716070Z","schema_version":"clob-market-ws.price_change.v1","sequence":null,"server_hash":null,"server_timestamp":"1785211328544","session_id":"2d607381e3054cee91998cdf45a4231c","source":"clob_market_ws"},"received_at":"2026-07-28T04:02:09.716070Z","record_id":"46c983600c628fda96f48028c2836d322d62d2c7a0305e88284f7f40c9ac04a0","schema_fingerprint":"4aa3821a28b0b7c2400bc59aba4bcc0a76e971dadd19610d3ad38c768e124dc7","schema_version":"edge-lab-recorder.raw.v1","sequence":null,"source":"clob_market_ws"}
{"event_at":"2026-07-28T04:02:08.545000Z","event_fingerprint":"133444959ca629c2336293bbba57bf903dff8baffe8d4d8e5122c9878bad73f5","payload":{"connection_id":"f6725804f86a4c4eb588e4d5ed7db029","event_at":"2026-07-28T04:02:08.545000Z","event_type":"price_change","frame_hash":"10f5fb0f2939ca7ae0fc2e619da199b7e39fd93572886126271bbeaad493cb47","frame_index":0,"kind":"data","monotonic_ns":313312766916958,"payload":{"event_type":"price_change","market":"0xd412ce774cfcf8dc9f71164aac78783978aac7b03871702a3b8a481bd9dc9688","price_changes":[{"asset_id":"107603864457683460275633293642179940881969192120168665300712204232021063124301","best_ask":"0.43","best_bid":"0.42","hash":"a7984ee8e09a7c39cfab8907e03e7621758d2cc8","price":"0.4","side":"BUY","size":"129.2"},{"asset_id":"96600821790790307414914106093858868634329285205417149685270682748367152458577","best_ask":"0.58","best_bid":"0.57","hash":"d8cab89ff683a1571c0f070863cb7cce354319e4","price":"0.6","side":"SELL","size":"129.2"}],"timestamp":"1785211328545"},"payload_hash":"ae00b57b02daa2518440690644a9a4dc23727b62f35bac6e431646c11d953c4a","raw_frame":"{\"market\":\"0xd412ce774cfcf8dc9f71164aac78783978aac7b03871702a3b8a481bd9dc9688\", \"price_changes\":[{\"asset_id\":\"107603864457683460275633293642179940881969192120168665300712204232021063124301\", \"price\":\"0.4\", \"size\":\"129.2\", \"side\":\"BUY\", \"hash\":\"a7984ee8e09a7c39cfab8907e03e7621758d2cc8\", \"best_bid\":\"0.42\", \"best_ask\":\"0.43\"}, {\"asset_id\":\"96600821790790307414914106093858868634329285205417149685270682748367152458577\", \"price\":\"0.6\", \"size\":\"129.2\", \"side\":\"SELL\", \"hash\":\"d8cab89ff683a1571c0f070863cb7cce354319e4\", \"best_bid\":\"0.57\", \"best_ask\":\"0.58\"}], \"timestamp\":\"1785211328545\", \"event_type\":\"price_change\"}","received_at":"2026-07-28T04:02:09.718046Z","schema_version":"clob-market-ws.price_change.v1","sequence":null,"server_hash":null,"server_timestamp":"1785211328545","session_id":"2d607381e3054cee91998cdf45a4231c","source":"clob_market_ws"},"received_at":"2026-07-28T04:02:09.718046Z","record_id":"11f85ec45396883985596e8cd6cee28e0529dd98d565d4f16e05272f040933a2","schema_fingerprint":"4aa3821a28b0b7c2400bc59aba4bcc0a76e971dadd19610d3ad38c768e124dc7","schema_version":"edge-lab-recorder.raw.v1","sequence":null,"source":"clob_market_ws"}
{"event_at":"2026-07-28T04:02:08.545000Z","event_fingerprint":"7269f8e1bb46df4640b0477073a5d5fc6a774d429eb1c3ba280f8fc34c6d2999","payload":{"connection_id":"f6725804f86a4c4eb588e4d5ed7db029","event_at":"2026-07-28T04:02:08.545000Z","event_type":"price_change","frame_hash":"2afacf059a4bd67940d669eb9e45579dd923d624d3a7ca6921a47562edd648bd","frame_index":0,"kind":"data","monotonic_ns":313312768555125,"payload":{"event_type":"price_change","market":"0xd412ce774cfcf8dc9f71164aac78783978aac7b03871702a3b8a481bd9dc9688","price_changes":[{"asset_id":"107603864457683460275633293642179940881969192120168665300712204232021063124301","best_ask":"0.43","best_bid":"0.42","hash":"d7e51342e2e8a3c89f16ff7f5b1758fa046d3e91","price":"0.43","side":"SELL","size":"23"},{"asset_id":"96600821790790307414914106093858868634329285205417149685270682748367152458577","best_ask":"0.58","best_bid":"0.57","hash":"2425be2d77fde92260d419d202bcd4056b72c103","price":"0.57","side":"BUY","size":"23"}],"timestamp":"1785211328545"},"payload_hash":"937f6b2e2bcac4729a96ba45f669b1e84583191ea6345e7b26baa343ad4b4405","raw_frame":"{\"market\":\"0xd412ce774cfcf8dc9f71164aac78783978aac7b03871702a3b8a481bd9dc9688\", \"price_changes\":[{\"asset_id\":\"107603864457683460275633293642179940881969192120168665300712204232021063124301\", \"price\":\"0.43\", \"size\":\"23\", \"side\":\"SELL\", \"hash\":\"d7e51342e2e8a3c89f16ff7f5b1758fa046d3e91\", \"best_bid\":\"0.42\", \"best_ask\":\"0.43\"}, {\"asset_id\":\"96600821790790307414914106093858868634329285205417149685270682748367152458577\", \"price\":\"0.57\", \"size\":\"23\", \"side\":\"BUY\", \"hash\":\"2425be2d77fde92260d419d202bcd4056b72c103\", \"best_bid\":\"0.57\", \"best_ask\":\"0.58\"}], \"timestamp\":\"1785211328545\", \"event_type\":\"price_change\"}","received_at":"2026-07-28T04:02:09.719684Z","schema_version":"clob-market-ws.price_change.v1","sequence":null,"server_hash":null,"server_timestamp":"1785211328545","session_id":"2d607381e3054cee91998cdf45a4231c","source":"clob_market_ws"},"received_at":"2026-07-28T04:02:09.719684Z","record_id":"52cafe586bad7e820bdde1848298624a3df8f01627406193e0a824e0b738fee3","schema_fingerprint":"4aa3821a28b0b7c2400bc59aba4bcc0a76e971dadd19610d3ad38c768e124dc7","schema_version":"edge-lab-recorder.raw.v1","sequence":null,"source":"clob_market_ws"}
{"event_at":"2026-07-28T04:02:08.546000Z","event_fingerprint":"eddbaec9bda7e662af111ecc252f251b0de4f5d22b014ebdb193291b78217f7d","payload":{"connection_id":"f6725804f86a4c4eb588e4d5ed7db029","event_at":"2026-07-28T04:02:08.546000Z","event_type":"price_change","frame_hash":"66ce8db60596c1f1d37eb55cf6769674004db2c0b96ae8525784676adc05d6f5","frame_index":0,"kind":"data","monotonic_ns":313312770078791,"payload":{"event_type":"price_change","market":"0xd412ce774cfcf8dc9f71164aac78783978aac7b03871702a3b8a481bd9dc9688","price_changes":[{"asset_id":"96600821790790307414914106093858868634329285205417149685270682748367152458577","best_ask":"0.58","best_bid":"0.57","hash":"16c5df4f920882e0d5dd477bff915932eceda140","price":"0.56","side":"BUY","size":"22.38"},{"asset_id":"107603864457683460275633293642179940881969192120168665300712204232021063124301","best_ask":"0.43","best_bid":"0.42","hash":"904833e0ec9f37489886b6de8be919a60a8fa72b","price":"0.44","side":"SELL","size":"22.38"}],"timestamp":"1785211328546"},"payload_hash":"3759b2cfa13531873aeb4103337a28f7c3c63eb7781afb29bb7565821e87be50","raw_frame":"{\"market\":\"0xd412ce774cfcf8dc9f71164aac78783978aac7b03871702a3b8a481bd9dc9688\", \"price_changes\":[{\"asset_id\":\"96600821790790307414914106093858868634329285205417149685270682748367152458577\", \"price\":\"0.56\", \"size\":\"22.38\", \"side\":\"BUY\", \"hash\":\"16c5df4f920882e0d5dd477bff915932eceda140\", \"best_bid\":\"0.57\", \"best_ask\":\"0.58\"}, {\"asset_id\":\"107603864457683460275633293642179940881969192120168665300712204232021063124301\", \"price\":\"0.44\", \"size\":\"22.38\", \"side\":\"SELL\", \"hash\":\"904833e0ec9f37489886b6de8be919a60a8fa72b\", \"best_bid\":\"0.42\", \"best_ask\":\"0.43\"}], \"timestamp\":\"1785211328546\", \"event_type\":\"price_change\"}","received_at":"2026-07-28T04:02:09.721207Z","schema_version":"clob-market-ws.price_change.v1","sequence":null,"server_hash":null,"server_timestamp":"1785211328546","session_id":"2d607381e3054cee91998cdf45a4231c","source":"clob_market_ws"},"received_at":"2026-07-28T04:02:09.721207Z","record_id":"83d5e6525d8000bf6c09763a8122326d1cbcfd71bcdcd55963e2d4c61062f972","schema_fingerprint":"4aa3821a28b0b7c2400bc59aba4bcc0a76e971dadd19610d3ad38c768e124dc7","schema_version":"edge-lab-recorder.raw.v1","sequence":null,"source":"clob_market_ws"}
{"event_at":"2026-07-28T04:02:08.546000Z","event_fingerprint":"a55951312aa9564db218009bcdf451f0f9d7a4b3bce03423b74464e339273ca0","payload":{"connection_id":"f6725804f86a4c4eb588e4d5ed7db029","event_at":"2026-07-28T04:02:08.546000Z","event_type":"price_change","frame_hash":"8c79d34a2bad0cbf00499d989e9d9ca9b1ea8aad9467ac02ddd1b481f4f63bcc","frame_index":0,"kind":"data","monotonic_ns":313312771606625,"payload":{"event_type":"price_change","market":"0xd412ce774cfcf8dc9f71164aac78783978aac7b03871702a3b8a481bd9dc9688","price_changes":[{"asset_id":"96600821790790307414914106093858868634329285205417149685270682748367152458577","best_ask":"0.58","best_bid":"0.57","hash":"90ca65b8c2db094278702a2af52fbb5a38916a73","price":"0.6","side":"SELL","size":"137.2"},{"asset_id":"107603864457683460275633293642179940881969192120168665300712204232021063124301","best_ask":"0.43","best_bid":"0.42","hash":"a9169df2edea92ccffc431ce2bbe975cb48878a6","price":"0.4","side":"BUY","size":"137.2"}],"timestamp":"1785211328546"},"payload_hash":"af7843941c4ab51bf8925265e58495306d8121db091bb2a5b5df5a66a51e856c","raw_frame":"{\"market\":\"0xd412ce774cfcf8dc9f71164aac78783978aac7b03871702a3b8a481bd9dc9688\", \"price_changes\":[{\"asset_id\":\"96600821790790307414914106093858868634329285205417149685270682748367152458577\", \"price\":\"0.6\", \"size\":\"137.2\", \"side\":\"SELL\", \"hash\":\"90ca65b8c2db094278702a2af52fbb5a38916a73\", \"best_bid\":\"0.57\", \"best_ask\":\"0.58\"}, {\"asset_id\":\"107603864457683460275633293642179940881969192120168665300712204232021063124301\", \"price\":\"0.4\", \"size\":\"137.2\", \"side\":\"BUY\", \"hash\":\"a9169df2edea92ccffc431ce2bbe975cb48878a6\", \"best_bid\":\"0.42\", \"best_ask\":\"0.43\"}], \"timestamp\":\"1785211328546\", \"event_type\":\"price_change\"}","received_at":"2026-07-28T04:02:09.722734Z","schema_version":"clob-market-ws.price_change.v1","sequence":null,"server_hash":null,"server_timestamp":"1785211328546","session_id":"2d607381e3054cee91998cdf45a4231c","source":"clob_market_ws"},"received_at":"2026-07-28T04:02:09.722734Z","record_id":"e7dd535a01f9a132c34526d269159f6fe5ad5e9aea809161810fe424f1566fe5","schema_fingerprint":"4aa3821a28b0b7c2400bc59aba4bcc0a76e971dadd19610d3ad38c768e124dc7","schema_version":"edge-lab-recorder.raw.v1","sequence":null,"source":"clob_market_ws"}
{"event_at":"2026-07-28T04:02:08.547000Z","event_fingerprint":"0fb5b57ccf4fe26277e4a65bcf2e6b31b667b7045937463aae1e34e09bbcfcda","payload":{"connection_id":"f6725804f86a4c4eb588e4d5ed7db029","event_at":"2026-07-28T04:02:08.547000Z","event_type":"price_change","frame_hash":"e837446bff3f749102307710eaf142961e965d1f26667de9326835e7f196bc0f","frame_index":0,"kind":"data","monotonic_ns":313312773130708,"payload":{"event_type":"price_change","market":"0xd412ce774cfcf8dc9f71164aac78783978aac7b03871702a3b8a481bd9dc9688","price_changes":[{"asset_id":"107603864457683460275633293642179940881969192120168665300712204232021063124301","best_ask":"0.43","best_bid":"0.42","hash":"25c55993ad7a4092354040314b1a9500bca049ed","price":"0.33","side":"BUY","size":"290"},{"asset_id":"96600821790790307414914106093858868634329285205417149685270682748367152458577","best_ask":"0.58","best_bid":"0.57","hash":"2b34bccc28b96ba7e6fc6daab8551e6d17b70368","price":"0.67","side":"SELL","size":"290"}],"timestamp":"1785211328547"},"payload_hash":"44caa4c9c4e29d311dd1e9532a5bfc7d7bcbfbca6706210230395d133d3b25ba","raw_frame":"{\"market\":\"0xd412ce774cfcf8dc9f71164aac78783978aac7b03871702a3b8a481bd9dc9688\", \"price_changes\":[{\"asset_id\":\"107603864457683460275633293642179940881969192120168665300712204232021063124301\", \"price\":\"0.33\", \"size\":\"290\", \"side\":\"BUY\", \"hash\":\"25c55993ad7a4092354040314b1a9500bca049ed\", \"best_bid\":\"0.42\", \"best_ask\":\"0.43\"}, {\"asset_id\":\"96600821790790307414914106093858868634329285205417149685270682748367152458577\", \"price\":\"0.67\", \"size\":\"290\", \"side\":\"SELL\", \"hash\":\"2b34bccc28b96ba7e6fc6daab8551e6d17b70368\", \"best_bid\":\"0.57\", \"best_ask\":\"0.58\"}], \"timestamp\":\"1785211328547\", \"event_type\":\"price_change\"}","received_at":"2026-07-28T04:02:09.724258Z","schema_version":"clob-market-ws.price_change.v1","sequence":null,"server_hash":null,"server_timestamp":"1785211328547","session_id":"2d607381e3054cee91998cdf45a4231c","source":"clob_market_ws"},"received_at":"2026-07-28T04:02:09.724258Z","record_id":"a24e097c5353f9d80ebc0009af33d07f8fb307a95e3011bb2b79d65547893661","schema_fingerprint":"4aa3821a28b0b7c2400bc59aba4bcc0a76e971dadd19610d3ad38c768e124dc7","schema_version":"edge-lab-recorder.raw.v1","sequence":null,"source":"clob_market_ws"}
{"event_at":"2026-07-28T04:02:08.547000Z","event_fingerprint":"987bc77dd48843383f36b3210b9c6d04d1acab2a371d9ababda0e08c2056c068","payload":{"connection_id":"f6725804f86a4c4eb588e4d5ed7db029","event_at":"2026-07-28T04:02:08.547000Z","event_type":"price_change","frame_hash":"9520f5ab085b9701f751d9755974c33f448d831eab0495c72fe90e53f2b6484b","frame_index":0,"kind":"data","monotonic_ns":313312774647000,"payload":{"event_type":"price_change","market":"0xd412ce774cfcf8dc9f71164aac78783978aac7b03871702a3b8a481bd9dc9688","price_changes":[{"asset_id":"96600821790790307414914106093858868634329285205417149685270682748367152458577","best_ask":"0.58","best_bid":"0.57","hash":"6a000583019978ac105a51ce2e489218cc1e5256","price":"0.55","side":"BUY","size":"28"},{"asset_id":"107603864457683460275633293642179940881969192120168665300712204232021063124301","best_ask":"0.43","best_bid":"0.42","hash":"8cf863c8676f22fd0e39a96f5a4c7bbcdd58a141","price":"0.45","side":"SELL","size":"28"}],"timestamp":"1785211328547"},"payload_hash":"dc13f8123099169c99d606e56219e3469af28dd9a6ced2f9d48654d4fa373e51","raw_frame":"{\"market\":\"0xd412ce774cfcf8dc9f71164aac78783978aac7b03871702a3b8a481bd9dc9688\", \"price_changes\":[{\"asset_id\":\"96600821790790307414914106093858868634329285205417149685270682748367152458577\", \"price\":\"0.55\", \"size\":\"28\", \"side\":\"BUY\", \"hash\":\"6a000583019978ac105a51ce2e489218cc1e5256\", \"best_bid\":\"0.57\", \"best_ask\":\"0.58\"}, {\"asset_id\":\"107603864457683460275633293642179940881969192120168665300712204232021063124301\", \"price\":\"0.45\", \"size\":\"28\", \"side\":\"SELL\", \"hash\":\"8cf863c8676f22fd0e39a96f5a4c7bbcdd58a141\", \"best_bid\":\"0.42\", \"best_ask\":\"0.43\"}], \"timestamp\":\"1785211328547\", \"event_type\":\"price_change\"}","received_at":"2026-07-28T04:02:09.725776Z","schema_version":"clob-market-ws.price_change.v1","sequence":null,"server_hash":null,"server_timestamp":"1785211328547","session_id":"2d607381e3054cee91998cdf45a4231c","source":"clob_market_ws"},"received_at":"2026-07-28T04:02:09.725776Z","record_id":"01d661f2600a46d3567641dfae46b09082e9721f2c8e266c533c50f01229c59e","schema_fingerprint":"4aa3821a28b0b7c2400bc59aba4bcc0a76e971dadd19610d3ad38c768e124dc7","schema_version":"edge-lab-recorder.raw.v1","sequence":null,"source":"clob_market_ws"}
{"event_at":"2026-07-28T04:02:08.548000Z","event_fingerprint":"1dedd88d4d4bf39c624bed5c9f44726bc5ad1c660e2fca96866bcb071dd0dc85","payload":{"connection_id":"f6725804f86a4c4eb588e4d5ed7db029","event_at":"2026-07-28T04:02:08.548000Z","event_type":"price_change","frame_hash":"86df219cbd44a4bfbd67ae3e03011ef3aa3572b7fa28276da3148aa50dc8a816","frame_index":0,"kind":"data","monotonic_ns":313312776124125,"payload":{"event_type":"price_change","market":"0xd412ce774cfcf8dc9f71164aac78783978aac7b03871702a3b8a481bd9dc9688","price_changes":[{"asset_id":"96600821790790307414914106093858868634329285205417149685270682748367152458577","best_ask":"0.58","best_bid":"0.57","hash":"6e96f88b89dfdbabf9e2f9005e46e6e916b7e406","price":"0.61","side":"SELL","size":"57.6"},{"asset_id":"107603864457683460275633293642179940881969192120168665300712204232021063124301","best_ask":"0.43","best_bid":"0.42","hash":"c5b2d1d1ccb76eadaea926b115508d23656901a6","price":"0.39","side":"BUY","size":"57.6"}],"timestamp":"1785211328548"},"payload_hash":"901285ef41e3bfe2ae9638ce7946028b860749f1c3e1a46cf981e8f7cbc568d3","raw_frame":"{\"market\":\"0xd412ce774cfcf8dc9f71164aac78783978aac7b03871702a3b8a481bd9dc9688\", \"price_changes\":[{\"asset_id\":\"96600821790790307414914106093858868634329285205417149685270682748367152458577\", \"price\":\"0.61\", \"size\":\"57.6\", \"side\":\"SELL\", \"hash\":\"6e96f88b89dfdbabf9e2f9005e46e6e916b7e406\", \"best_bid\":\"0.57\", \"best_ask\":\"0.58\"}, {\"asset_id\":\"107603864457683460275633293642179940881969192120168665300712204232021063124301\", \"price\":\"0.39\", \"size\":\"57.6\", \"side\":\"BUY\", \"hash\":\"c5b2d1d1ccb76eadaea926b115508d23656901a6\", \"best_bid\":\"0.42\", \"best_ask\":\"0.43\"}], \"timestamp\":\"1785211328548\", \"event_type\":\"price_change\"}","received_at":"2026-07-28T04:02:09.727253Z","schema_version":"clob-market-ws.price_change.v1","sequence":null,"server_hash":null,"server_timestamp":"1785211328548","session_id":"2d607381e3054cee91998cdf45a4231c","source":"clob_market_ws"},"received_at":"2026-07-28T04:02:09.727253Z","record_id":"dbc2323546c28852566c8383833f77f429061a12443f9cb066c639dcc7f5d706","schema_fingerprint":"4aa3821a28b0b7c2400bc59aba4bcc0a76e971dadd19610d3ad38c768e124dc7","schema_version":"edge-lab-recorder.raw.v1","sequence":null,"source":"clob_market_ws"}
{"event_at":"2026-07-28T04:02:08.555000Z","event_fingerprint":"a7a230a432e43c8170b9a3ff396f514dded5657363744c2cf45f6228a1c6ca19","payload":{"connection_id":"f6725804f86a4c4eb588e4d5ed7db029","event_at":"2026-07-28T04:02:08.555000Z","event_type":"price_change","frame_hash":"efcda31dfc0a01c52c16cb90b374a6a2916b945c9daa80f22d3418e968f3fcf4","frame_index":0,"kind":"data","monotonic_ns":313312777615583,"payload":{"event_type":"price_change","market":"0xd412ce774cfcf8dc9f71164aac78783978aac7b03871702a3b8a481bd9dc9688","price_changes":[{"asset_id":"107603864457683460275633293642179940881969192120168665300712204232021063124301","best_ask":"0.43","best_bid":"0.42","hash":"ea49f545b3624b092c62a6098a63b0ae23690bc5","price":"0.33","side":"BUY","size":"284"},{"asset_id":"96600821790790307414914106093858868634329285205417149685270682748367152458577","best_ask":"0.58","best_bid":"0.57","hash":"94042e9984851f65a7b046b3c4e93cb150b91195","price":"0.67","side":"SELL","size":"284"}],"timestamp":"1785211328555"},"payload_hash":"6dc9b9d1f63804764e642615c2daffcf6a44ae8d83d2c30acda77227a736071d","raw_frame":"{\"market\":\"0xd412ce774cfcf8dc9f71164aac78783978aac7b03871702a3b8a481bd9dc9688\", \"price_changes\":[{\"asset_id\":\"107603864457683460275633293642179940881969192120168665300712204232021063124301\", \"price\":\"0.33\", \"size\":\"284\", \"side\":\"BUY\", \"hash\":\"ea49f545b3624b092c62a6098a63b0ae23690bc5\", \"best_bid\":\"0.42\", \"best_ask\":\"0.43\"}, {\"asset_id\":\"96600821790790307414914106093858868634329285205417149685270682748367152458577\", \"price\":\"0.67\", \"size\":\"284\", \"side\":\"SELL\", \"hash\":\"94042e9984851f65a7b046b3c4e93cb150b91195\", \"best_bid\":\"0.57\", \"best_ask\":\"0.58\"}], \"timestamp\":\"1785211328555\", \"event_type\":\"price_change\"}","received_at":"2026-07-28T04:02:09.728744Z","schema_version":"clob-market-ws.price_change.v1","sequence":null,"server_hash":null,"server_timestamp":"1785211328555","session_id":"2d607381e3054cee91998cdf45a4231c","source":"clob_market_ws"},"received_at":"2026-07-28T04:02:09.728744Z","record_id":"e8634608075a7e68b7e6efbfbf25d6e7bd9b24aab955a2d903e2c451898ed3a6","schema_fingerprint":"4aa3821a28b0b7c2400bc59aba4bcc0a76e971dadd19610d3ad38c768e124dc7","schema_version":"edge-lab-recorder.raw.v1","sequence":null,"source":"clob_market_ws"}
{"event_at":"2026-07-28T04:02:08.597000Z","event_fingerprint":"1922211575bf6e43bb255783fac9af6726b8c5c216e21d2266a596fd017841ec","payload":{"connection_id":"f6725804f86a4c4eb588e4d5ed7db029","event_at":"2026-07-28T04:02:08.597000Z","event_type":"price_change","frame_hash":"c692a897c88c9f6cba08c2f77cdc64010e47b043104053094466748f2d107a0f","frame_index":0,"kind":"data","monotonic_ns":313312779063458,"payload":{"event_type":"price_change","market":"0xd412ce774cfcf8dc9f71164aac78783978aac7b03871702a3b8a481bd9dc9688","price_changes":[{"asset_id":"96600821790790307414914106093858868634329285205417149685270682748367152458577","best_ask":"0.58","best_bid":"0.57","hash":"f1cf2bdb018c53002f2a36e5818d4a765ff0028b","price":"0.03","side":"BUY","size":"643.1"},{"asset_id":"107603864457683460275633293642179940881969192120168665300712204232021063124301","best_ask":"0.43","best_bid":"0.42","hash":"c76725a4ee5b2eb9ca43494c57e7747b651ebc7c","price":"0.97","side":"SELL","size":"643.1"}],"timestamp":"1785211328597"},"payload_hash":"c69099f2314fa4551011782b82f5015321f16bb5ebb60a415c419f2b121c3962","raw_frame":"{\"market\":\"0xd412ce774cfcf8dc9f71164aac78783978aac7b03871702a3b8a481bd9dc9688\", \"price_changes\":[{\"asset_id\":\"96600821790790307414914106093858868634329285205417149685270682748367152458577\", \"price\":\"0.03\", \"size\":\"643.1\", \"side\":\"BUY\", \"hash\":\"f1cf2bdb018c53002f2a36e5818d4a765ff0028b\", \"best_bid\":\"0.57\", \"best_ask\":\"0.58\"}, {\"asset_id\":\"107603864457683460275633293642179940881969192120168665300712204232021063124301\", \"price\":\"0.97\", \"size\":\"643.1\", \"side\":\"SELL\", \"hash\":\"c76725a4ee5b2eb9ca43494c57e7747b651ebc7c\", \"best_bid\":\"0.42\", \"best_ask\":\"0.43\"}], \"timestamp\":\"1785211328597\", \"event_type\":\"price_change\"}","received_at":"2026-07-28T04:02:09.730192Z","schema_version":"clob-market-ws.price_change.v1","sequence":null,"server_hash":null,"server_timestamp":"1785211328597","session_id":"2d607381e3054cee91998cdf45a4231c","source":"clob_market_ws"},"received_at":"2026-07-28T04:02:09.730192Z","record_id":"b9ce0cc188f6c59660dfb205553432d827090288b5b03ea5aa6fdddb7f0097b7","schema_fingerprint":"4aa3821a28b0b7c2400bc59aba4bcc0a76e971dadd19610d3ad38c768e124dc7","schema_version":"edge-lab-recorder.raw.v1","sequence":null,"source":"clob_market_ws"}
{"event_at":"2026-07-28T04:02:08.599000Z","event_fingerprint":"370968a019870a1ed392079a75b5a1ac4a3e95ae1016736a88cb1b37403025b1","payload":{"connection_id":"f6725804f86a4c4eb588e4d5ed7db029","event_at":"2026-07-28T04:02:08.599000Z","event_type":"price_change","frame_hash":"0b0751ab4614b22139e82aedca8a94bd64513c7e44ef34c649f4b9c01e9bf0f8","frame_index":0,"kind":"data","monotonic_ns":313312780537375,"payload":{"event_type":"price_change","market":"0xd412ce774cfcf8dc9f71164aac78783978aac7b03871702a3b8a481bd9dc9688","price_changes":[{"asset_id":"96600821790790307414914106093858868634329285205417149685270682748367152458577","best_ask":"0.58","best_bid":"0.57","hash":"272a95f2cb691f8424ae565aa2a7d2819af5c66b","price":"0.01","side":"BUY","size":"7858.02"},{"asset_id":"107603864457683460275633293642179940881969192120168665300712204232021063124301","best_ask":"0.43","best_bid":"0.42","hash":"7774e1a300fa245285062bfa3a23fd3d9ff5f4d0","price":"0.99","side":"SELL","size":"7858.02"}],"timestamp":"1785211328599"},"payload_hash":"46f4b30490fadeff07d75a35d8d8ec4d47f807ac559deae34a457ac7d3ef7302","raw_frame":"{\"market\":\"0xd412ce774cfcf8dc9f71164aac78783978aac7b03871702a3b8a481bd9dc9688\", \"price_changes\":[{\"asset_id\":\"96600821790790307414914106093858868634329285205417149685270682748367152458577\", \"price\":\"0.01\", \"size\":\"7858.02\", \"side\":\"BUY\", \"hash\":\"272a95f2cb691f8424ae565aa2a7d2819af5c66b\", \"best_bid\":\"0.57\", \"best_ask\":\"0.58\"}, {\"asset_id\":\"107603864457683460275633293642179940881969192120168665300712204232021063124301\", \"price\":\"0.99\", \"size\":\"7858.02\", \"side\":\"SELL\", \"hash\":\"7774e1a300fa245285062bfa3a23fd3d9ff5f4d0\", \"best_bid\":\"0.42\", \"best_ask\":\"0.43\"}], \"timestamp\":\"1785211328599\", \"event_type\":\"price_change\"}","received_at":"2026-07-28T04:02:09.731667Z","schema_version":"clob-market-ws.price_change.v1","sequence":null,"server_hash":null,"server_timestamp":"1785211328599","session_id":"2d607381e3054cee91998cdf45a4231c","source":"clob_market_ws"},"received_at":"2026-07-28T04:02:09.731667Z","record_id":"266ae8650f4004783477b2e59f58406984d3fd474fe1ebac5701fb2a09928741","schema_fingerprint":"4aa3821a28b0b7c2400bc59aba4bcc0a76e971dadd19610d3ad38c768e124dc7","schema_version":"edge-lab-recorder.raw.v1","sequence":null,"source":"clob_market_ws"}
{"event_at":"2026-07-28T04:02:08.621000Z","event_fingerprint":"ddbf34cd9db3f7c0d24cfc38557527fca49c7e535a19d774fb4a07ca2aafd761","payload":{"connection_id":"f6725804f86a4c4eb588e4d5ed7db029","event_at":"2026-07-28T04:02:08.621000Z","event_type":"price_change","frame_hash":"d5e3adfa1c66e20aedde84fe62c27cb62a5c954ab191c416f642d47edfe36ba2","frame_index":0,"kind":"data","monotonic_ns":313312781981583,"payload":{"event_type":"price_change","market":"0xd412ce774cfcf8dc9f71164aac78783978aac7b03871702a3b8a481bd9dc9688","price_changes":[{"asset_id":"96600821790790307414914106093858868634329285205417149685270682748367152458577","best_ask":"0.58","best_bid":"0.57","hash":"b01d21d3e40c11e80bb3814ddf79d3a3f652dbaa","price":"0.01","side":"BUY","size":"7853.02"},{"asset_id":"107603864457683460275633293642179940881969192120168665300712204232021063124301","best_ask":"0.43","best_bid":"0.42","hash":"e49eb4c1c19ae534a1ae4120a253941cf2aa5ac0","price":"0.99","side":"SELL","size":"7853.02"}],"timestamp":"1785211328621"},"payload_hash":"4fff09211331cfa000bd3e18ea3be88bcd2d4a9f7671d7c544d92d3439a11a6f","raw_frame":"{\"market\":\"0xd412ce774cfcf8dc9f71164aac78783978aac7b03871702a3b8a481bd9dc9688\", \"price_changes\":[{\"asset_id\":\"96600821790790307414914106093858868634329285205417149685270682748367152458577\", \"price\":\"0.01\", \"size\":\"7853.02\", \"side\":\"BUY\", \"hash\":\"b01d21d3e40c11e80bb3814ddf79d3a3f652dbaa\", \"best_bid\":\"0.57\", \"best_ask\":\"0.58\"}, {\"asset_id\":\"107603864457683460275633293642179940881969192120168665300712204232021063124301\", \"price\":\"0.99\", \"size\":\"7853.02\", \"side\":\"SELL\", \"hash\":\"e49eb4c1c19ae534a1ae4120a253941cf2aa5ac0\", \"best_bid\":\"0.42\", \"best_ask\":\"0.43\"}], \"timestamp\":\"1785211328621\", \"event_type\":\"price_change\"}","received_at":"2026-07-28T04:02:09.733111Z","schema_version":"clob-market-ws.price_change.v1","sequence":null,"server_hash":null,"server_timestamp":"1785211328621","session_id":"2d607381e3054cee91998cdf45a4231c","source":"clob_market_ws"},"received_at":"2026-07-28T04:02:09.733111Z","record_id":"eef9d97c284a1dcea8797edd87c234236c6be23c26e567289f7ec610b084ea35","schema_fingerprint":"4aa3821a28b0b7c2400bc59aba4bcc0a76e971dadd19610d3ad38c768e124dc7","schema_version":"edge-lab-recorder.raw.v1","sequence":null,"source":"clob_market_ws"}
{"event_at":"2026-07-28T04:02:08.653000Z","event_fingerprint":"4bbbbd676ee28a63e31000c89f9b3ac93290ee5b84305072c5dec8d2ba0bc138","payload":{"connection_id":"f6725804f86a4c4eb588e4d5ed7db029","event_at":"2026-07-28T04:02:08.653000Z","event_type":"price_change","frame_hash":"c60ee0b70fba7b35e514477176f0110c16ec7ba8974f05e7d1230bdfcffa48e4","frame_index":0,"kind":"data","monotonic_ns":313312783445416,"payload":{"event_type":"price_change","market":"0xd412ce774cfcf8dc9f71164aac78783978aac7b03871702a3b8a481bd9dc9688","price_changes":[{"asset_id":"107603864457683460275633293642179940881969192120168665300712204232021063124301","best_ask":"0.43","best_bid":"0.42","hash":"436fd89cac7b9b884b4f14e85de2a1592732536a","price":"0.4","side":"BUY","size":"112.2"},{"asset_id":"96600821790790307414914106093858868634329285205417149685270682748367152458577","best_ask":"0.58","best_bid":"0.57","hash":"130d2e54d5c6b4d93af7504577411f38e167daf9","price":"0.6","side":"SELL","size":"112.2"}],"timestamp":"1785211328653"},"payload_hash":"d02a83d11e304d1717dd866e4ba66fdc09656910dfe0cc6f1b268ce64ed0f36f","raw_frame":"{\"market\":\"0xd412ce774cfcf8dc9f71164aac78783978aac7b03871702a3b8a481bd9dc9688\", \"price_changes\":[{\"asset_id\":\"107603864457683460275633293642179940881969192120168665300712204232021063124301\", \"price\":\"0.4\", \"size\":\"112.2\", \"side\":\"BUY\", \"hash\":\"436fd89cac7b9b884b4f14e85de2a1592732536a\", \"best_bid\":\"0.42\", \"best_ask\":\"0.43\"}, {\"asset_id\":\"96600821790790307414914106093858868634329285205417149685270682748367152458577\", \"price\":\"0.6\", \"size\":\"112.2\", \"side\":\"SELL\", \"hash\":\"130d2e54d5c6b4d93af7504577411f38e167daf9\", \"best_bid\":\"0.57\", \"best_ask\":\"0.58\"}], \"timestamp\":\"1785211328653\", \"event_type\":\"price_change\"}","received_at":"2026-07-28T04:02:09.734574Z","schema_version":"clob-market-ws.price_change.v1","sequence":null,"server_hash":null,"server_timestamp":"1785211328653","session_id":"2d607381e3054cee91998cdf45a4231c","source":"clob_market_ws"},"received_at":"2026-07-28T04:02:09.734574Z","record_id":"dff5a036afe0650da114cdec3aa5244540d529d14874840f5f6a5bd2450e9934","schema_fingerprint":"4aa3821a28b0b7c2400bc59aba4bcc0a76e971dadd19610d3ad38c768e124dc7","schema_version":"edge-lab-recorder.raw.v1","sequence":null,"source":"clob_market_ws"}
{"event_at":"2026-07-28T04:02:08.658000Z","event_fingerprint":"5c29d20a65cbe7dbbf9ea27c4f7847f091504a1cef7157cf1e5cd9c911810bd2","payload":{"connection_id":"f6725804f86a4c4eb588e4d5ed7db029","event_at":"2026-07-28T04:02:08.658000Z","event_type":"price_change","frame_hash":"0f1e23008c2c96c65a35e2456506505c3b408d0b5c4c73edbdd74194d5b1c81c","frame_index":0,"kind":"data","monotonic_ns":313312784900166,"payload":{"event_type":"price_change","market":"0xd412ce774cfcf8dc9f71164aac78783978aac7b03871702a3b8a481bd9dc9688","price_changes":[{"asset_id":"96600821790790307414914106093858868634329285205417149685270682748367152458577","best_ask":"0.58","best_bid":"0.57","hash":"528a55f2aa4fa6621ba6039657ed2fba46ebfc6f","price":"0.6","side":"SELL","size":"87.2"},{"asset_id":"107603864457683460275633293642179940881969192120168665300712204232021063124301","best_ask":"0.43","best_bid":"0.42","hash":"7836497ab5a47ea3678ae54c923eec75623b170e","price":"0.4","side":"BUY","size":"87.2"}],"timestamp":"1785211328658"},"payload_hash":"e8ca02c156700fab09c81a27c89c00e0ec7d15984e19142fd3f03630f23ed0df","raw_frame":"{\"market\":\"0xd412ce774cfcf8dc9f71164aac78783978aac7b03871702a3b8a481bd9dc9688\", \"price_changes\":[{\"asset_id\":\"96600821790790307414914106093858868634329285205417149685270682748367152458577\", \"price\":\"0.6\", \"size\":\"87.2\", \"side\":\"SELL\", \"hash\":\"528a55f2aa4fa6621ba6039657ed2fba46ebfc6f\", \"best_bid\":\"0.57\", \"best_ask\":\"0.58\"}, {\"asset_id\":\"107603864457683460275633293642179940881969192120168665300712204232021063124301\", \"price\":\"0.4\", \"size\":\"87.2\", \"side\":\"BUY\", \"hash\":\"7836497ab5a47ea3678ae54c923eec75623b170e\", \"best_bid\":\"0.42\", \"best_ask\":\"0.43\"}], \"timestamp\":\"1785211328658\", \"event_type\":\"price_change\"}","received_at":"2026-07-28T04:02:09.736029Z","schema_version":"clob-market-ws.price_change.v1","sequence":null,"server_hash":null,"server_timestamp":"1785211328658","session_id":"2d607381e3054cee91998cdf45a4231c","source":"clob_market_ws"},"received_at":"2026-07-28T04:02:09.736029Z","record_id":"7bb96b8a3c38a2224683f46d11d20b204e85807abded5b155ad0ed5e5fdb6b40","schema_fingerprint":"4aa3821a28b0b7c2400bc59aba4bcc0a76e971dadd19610d3ad38c768e124dc7","schema_version":"edge-lab-recorder.raw.v1","sequence":null,"source":"clob_market_ws"}
{"event_at":"2026-07-28T04:02:08.668000Z","event_fingerprint":"302cee5610a73038dad104df64f0fb312bf412ed07cbdf3ce0ddb93f33baa380","payload":{"connection_id":"f6725804f86a4c4eb588e4d5ed7db029","event_at":"2026-07-28T04:02:08.668000Z","event_type":"price_change","frame_hash":"6c48c4a5909a11c5dac25d2ff49da949df67ba11adef428b0215723adc525c0b","frame_index":0,"kind":"data","monotonic_ns":313312786351125,"payload":{"event_type":"price_change","market":"0xd412ce774cfcf8dc9f71164aac78783978aac7b03871702a3b8a481bd9dc9688","price_changes":[{"asset_id":"96600821790790307414914106093858868634329285205417149685270682748367152458577","best_ask":"0.58","best_bid":"0.57","hash":"661d51b729ece2680c5c03ef2e1af79a31d6c131","price":"0.61","side":"SELL","size":"48.6"},{"asset_id":"107603864457683460275633293642179940881969192120168665300712204232021063124301","best_ask":"0.43","best_bid":"0.42","hash":"7c7bb2ea51bcdbe7b9ac6b1cb521d65c0df8e6ec","price":"0.39","side":"BUY","size":"48.6"}],"timestamp":"1785211328668"},"payload_hash":"14f2db4aabaf1efe38528459eb989028a1634e17f60e530ca69b744103d992a4","raw_frame":"{\"market\":\"0xd412ce774cfcf8dc9f71164aac78783978aac7b03871702a3b8a481bd9dc9688\", \"price_changes\":[{\"asset_id\":\"96600821790790307414914106093858868634329285205417149685270682748367152458577\", \"price\":\"0.61\", \"size\":\"48.6\", \"side\":\"SELL\", \"hash\":\"661d51b729ece2680c5c03ef2e1af79a31d6c131\", \"best_bid\":\"0.57\", \"best_ask\":\"0.58\"}, {\"asset_id\":\"107603864457683460275633293642179940881969192120168665300712204232021063124301\", \"price\":\"0.39\", \"size\":\"48.6\", \"side\":\"BUY\", \"hash\":\"7c7bb2ea51bcdbe7b9ac6b1cb521d65c0df8e6ec\", \"best_bid\":\"0.42\", \"best_ask\":\"0.43\"}], \"timestamp\":\"1785211328668\", \"event_type\":\"price_change\"}","received_at":"2026-07-28T04:02:09.737480Z","schema_version":"clob-market-ws.price_change.v1","sequence":null,"server_hash":null,"server_timestamp":"1785211328668","session_id":"2d607381e3054cee91998cdf45a4231c","source":"clob_market_ws"},"received_at":"2026-07-28T04:02:09.737480Z","record_id":"29c83a7d118f4aa35434ff6289ae005858d96447b608d3b0c61f53c45d963c1e","schema_fingerprint":"4aa3821a28b0b7c2400bc59aba4bcc0a76e971dadd19610d3ad38c768e124dc7","schema_version":"edge-lab-recorder.raw.v1","sequence":null,"source":"clob_market_ws"}
{"event_at":"2026-07-28T04:02:08.673000Z","event_fingerprint":"d7c19abe6967849d5bdc44c49b985b785a5f0f7bec47dffa8733d9110608676f","payload":{"connection_id":"f6725804f86a4c4eb588e4d5ed7db029","event_at":"2026-07-28T04:02:08.673000Z","event_type":"price_change","frame_hash":"18cd21a30d10f4c3fc0d70e5077a186865b673967ef4a32fc81030810e3686a9","frame_index":0,"kind":"data","monotonic_ns":313312787810750,"payload":{"event_type":"price_change","market":"0xd412ce774cfcf8dc9f71164aac78783978aac7b03871702a3b8a481bd9dc9688","price_changes":[{"asset_id":"96600821790790307414914106093858868634329285205417149685270682748367152458577","best_ask":"0.58","best_bid":"0.57","hash":"3db0d7cd20a9df15956d5ec407974cc242b01a24","price":"0.57","side":"BUY","size":"32.38"},{"asset_id":"107603864457683460275633293642179940881969192120168665300712204232021063124301","best_ask":"0.43","best_bid":"0.42","hash":"0356c7ed6699de57e9cb9b561a363607268a2717","price":"0.43","side":"SELL","size":"32.38"}],"timestamp":"1785211328673"},"payload_hash":"a22ac365b500d9b83b43883754214cbbcb62cbecc6a9ca90056fb9f3ecb4b2aa","raw_frame":"{\"market\":\"0xd412ce774cfcf8dc9f71164aac78783978aac7b03871702a3b8a481bd9dc9688\", \"price_changes\":[{\"asset_id\":\"96600821790790307414914106093858868634329285205417149685270682748367152458577\", \"price\":\"0.57\", \"size\":\"32.38\", \"side\":\"BUY\", \"hash\":\"3db0d7cd20a9df15956d5ec407974cc242b01a24\", \"best_bid\":\"0.57\", \"best_ask\":\"0.58\"}, {\"asset_id\":\"107603864457683460275633293642179940881969192120168665300712204232021063124301\", \"price\":\"0.43\", \"size\":\"32.38\", \"side\":\"SELL\", \"hash\":\"0356c7ed6699de57e9cb9b561a363607268a2717\", \"best_bid\":\"0.42\", \"best_ask\":\"0.43\"}], \"timestamp\":\"1785211328673\", \"event_type\":\"price_change\"}","received_at":"2026-07-28T04:02:09.738940Z","schema_version":"clob-market-ws.price_change.v1","sequence":null,"server_hash":null,"server_timestamp":"1785211328673","session_id":"2d607381e3054cee91998cdf45a4231c","source":"clob_market_ws"},"received_at":"2026-07-28T04:02:09.738940Z","record_id":"4176604a177a12bcdd68e7e8ed34a729f2bf9a959c97e69855a08ccce61bfcbb","schema_fingerprint":"4aa3821a28b0b7c2400bc59aba4bcc0a76e971dadd19610d3ad38c768e124dc7","schema_version":"edge-lab-recorder.raw.v1","sequence":null,"source":"clob_market_ws"}
{"event_at":"2026-07-28T04:02:08.674000Z","event_fingerprint":"6302256530066d29fb3f098878042f02e3a2867aaf8f6bf54d6e41d050b2298a","payload":{"connection_id":"f6725804f86a4c4eb588e4d5ed7db029","event_at":"2026-07-28T04:02:08.674000Z","event_type":"price_change","frame_hash":"4aa147cd5c5a94ed6bd8638e3fbdf875ce30e8f772d6ec035f060548f83ed8b3","frame_index":0,"kind":"data","monotonic_ns":313312789260125,"payload":{"event_type":"price_change","market":"0xd412ce774cfcf8dc9f71164aac78783978aac7b03871702a3b8a481bd9dc9688","price_changes":[{"asset_id":"107603864457683460275633293642179940881969192120168665300712204232021063124301","best_ask":"0.43","best_bid":"0.42","hash":"990ca3598fdcf58b3bc968bded7ba922765682dd","price":"0.41","side":"BUY","size":"62.6"},{"asset_id":"96600821790790307414914106093858868634329285205417149685270682748367152458577","best_ask":"0.58","best_bid":"0.57","hash":"a5e72b4d030522a2ded536410d71cfe9e89ccf1e","price":"0.59","side":"SELL","size":"62.6"}],"timestamp":"1785211328674"},"payload_hash":"852736ae1ceeccc67db282c70fe60519453671f8dafa1a1ae83d047d90e02a08","raw_frame":"{\"market\":\"0xd412ce774cfcf8dc9f71164aac78783978aac7b03871702a3b8a481bd9dc9688\", \"price_changes\":[{\"asset_id\":\"107603864457683460275633293642179940881969192120168665300712204232021063124301\", \"price\":\"0.41\", \"size\":\"62.6\", \"side\":\"BUY\", \"hash\":\"990ca3598fdcf58b3bc968bded7ba922765682dd\", \"best_bid\":\"0.42\", \"best_ask\":\"0.43\"}, {\"asset_id\":\"96600821790790307414914106093858868634329285205417149685270682748367152458577\", \"price\":\"0.59\", \"size\":\"62.6\", \"side\":\"SELL\", \"hash\":\"a5e72b4d030522a2ded536410d71cfe9e89ccf1e\", \"best_bid\":\"0.57\", \"best_ask\":\"0.58\"}], \"timestamp\":\"1785211328674\", \"event_type\":\"price_change\"}","received_at":"2026-07-28T04:02:09.740389Z","schema_version":"clob-market-ws.price_change.v1","sequence":null,"server_hash":null,"server_timestamp":"1785211328674","session_id":"2d607381e3054cee91998cdf45a4231c","source":"clob_market_ws"},"received_at":"2026-07-28T04:02:09.740389Z","record_id":"13e35c1852bc6a78d9c2e49763ee7a38c34722e1df65e4d18c982c0512439761","schema_fingerprint":"4aa3821a28b0b7c2400bc59aba4bcc0a76e971dadd19610d3ad38c768e124dc7","schema_version":"edge-lab-recorder.raw.v1","sequence":null,"source":"clob_market_ws"}
{"event_at":"2026-07-28T04:02:08.674000Z","event_fingerprint":"361c737bcfbb4dbf20a67946315a1b55251888bffd990b4713eb3178ba4f05e3","payload":{"connection_id":"f6725804f86a4c4eb588e4d5ed7db029","event_at":"2026-07-28T04:02:08.674000Z","event_type":"price_change","frame_hash":"0698185b2531872b70349ba687fee8e1da71432642119e0d88b98c5c92cf2ab7","frame_index":0,"kind":"data","monotonic_ns":313312790724583,"payload":{"event_type":"price_change","market":"0xd412ce774cfcf8dc9f71164aac78783978aac7b03871702a3b8a481bd9dc9688","price_changes":[{"asset_id":"107603864457683460275633293642179940881969192120168665300712204232021063124301","best_ask":"0.43","best_bid":"0.42","hash":"83c0e48683ca08d74f1d43390c8c2594ed7dbfdb","price":"0.39","side":"BUY","size":"58.6"},{"asset_id":"96600821790790307414914106093858868634329285205417149685270682748367152458577","best_ask":"0.58","best_bid":"0.57","hash":"3cdc3a425f73d28769992a6250416e3814d9fea8","price":"0.61","side":"SELL","size":"58.6"}],"timestamp":"1785211328674"},"payload_hash":"2865d5b0841cd228d9743a4870cf93e4f5976b61cb2646d3af7ec4135bb6f68e","raw_frame":"{\"market\":\"0xd412ce774cfcf8dc9f71164aac78783978aac7b03871702a3b8a481bd9dc9688\", \"price_changes\":[{\"asset_id\":\"107603864457683460275633293642179940881969192120168665300712204232021063124301\", \"price\":\"0.39\", \"size\":\"58.6\", \"side\":\"BUY\", \"hash\":\"83c0e48683ca08d74f1d43390c8c2594ed7dbfdb\", \"best_bid\":\"0.42\", \"best_ask\":\"0.43\"}, {\"asset_id\":\"96600821790790307414914106093858868634329285205417149685270682748367152458577\", \"price\":\"0.61\", \"size\":\"58.6\", \"side\":\"SELL\", \"hash\":\"3cdc3a425f73d28769992a6250416e3814d9fea8\", \"best_bid\":\"0.57\", \"best_ask\":\"0.58\"}], \"timestamp\":\"1785211328674\", \"event_type\":\"price_change\"}","received_at":"2026-07-28T04:02:09.741854Z","schema_version":"clob-market-ws.price_change.v1","sequence":null,"server_hash":null,"server_timestamp":"1785211328674","session_id":"2d607381e3054cee91998cdf45a4231c","source":"clob_market_ws"},"received_at":"2026-07-28T04:02:09.741854Z","record_id":"b55d240c3d41ac5fc0ef1a647a23ed272745ba7c399ce4e539f1b588b5d06eef","schema_fingerprint":"4aa3821a28b0b7c2400bc59aba4bcc0a76e971dadd19610d3ad38c768e124dc7","schema_version":"edge-lab-recorder.raw.v1","sequence":null,"source":"clob_market_ws"}
{"event_at":"2026-07-28T04:02:08.681000Z","event_fingerprint":"9f1cf90f8bd3c31c4c6a95d55551fcbdf7f9103e3b89d0a4bbd4a2c98eeebccf","payload":{"connection_id":"f6725804f86a4c4eb588e4d5ed7db029","event_at":"2026-07-28T04:02:08.681000Z","event_type":"price_change","frame_hash":"70f5e64c78c880503721d264d3ffae17c5c39c701fd3faa254d71cad422d2764","frame_index":0,"kind":"data","monotonic_ns":313312792178333,"payload":{"event_type":"price_change","market":"0xd412ce774cfcf8dc9f71164aac78783978aac7b03871702a3b8a481bd9dc9688","price_changes":[{"asset_id":"96600821790790307414914106093858868634329285205417149685270682748367152458577","best_ask":"0.58","best_bid":"0.57","hash":"a83ff52a5cf2d63fa9b78bfc8146d37b1bb0bef1","price":"0.59","side":"SELL","size":"87.6"},{"asset_id":"107603864457683460275633293642179940881969192120168665300712204232021063124301","best_ask":"0.43","best_bid":"0.42","hash":"7c2734b39843488eddccc7cd55a60864195ddeaa","price":"0.41","side":"BUY","size":"87.6"}],"timestamp":"1785211328681"},"payload_hash":"608ac40e1f2fd4011b33a33563541f77b7f4b25f48c19925a9e7ba9d7f1edda8","raw_frame":"{\"market\":\"0xd412ce774cfcf8dc9f71164aac78783978aac7b03871702a3b8a481bd9dc9688\", \"price_changes\":[{\"asset_id\":\"96600821790790307414914106093858868634329285205417149685270682748367152458577\", \"price\":\"0.59\", \"size\":\"87.6\", \"side\":\"SELL\", \"hash\":\"a83ff52a5cf2d63fa9b78bfc8146d37b1bb0bef1\", \"best_bid\":\"0.57\", \"best_ask\":\"0.58\"}, {\"asset_id\":\"107603864457683460275633293642179940881969192120168665300712204232021063124301\", \"price\":\"0.41\", \"size\":\"87.6\", \"side\":\"BUY\", \"hash\":\"7c2734b39843488eddccc7cd55a60864195ddeaa\", \"best_bid\":\"0.42\", \"best_ask\":\"0.43\"}], \"timestamp\":\"1785211328681\", \"event_type\":\"price_change\"}","received_at":"2026-07-28T04:02:09.743308Z","schema_version":"clob-market-ws.price_change.v1","sequence":null,"server_hash":null,"server_timestamp":"1785211328681","session_id":"2d607381e3054cee91998cdf45a4231c","source":"clob_market_ws"},"received_at":"2026-07-28T04:02:09.743308Z","record_id":"a441dd5550821e3211f9048fefd7cda89e35b9864a11aabd7a2abfbaa8ab3469","schema_fingerprint":"4aa3821a28b0b7c2400bc59aba4bcc0a76e971dadd19610d3ad38c768e124dc7","schema_version":"edge-lab-recorder.raw.v1","sequence":null,"source":"clob_market_ws"}
