{"event_at":"2026-07-28T04:12:41.011000Z","event_fingerprint":"9afdedfef13436f429339f215ea7aecdb2005a7255d0ea4aa4fa6270f43a81d5","payload":{"connection_id":"f6725804f86a4c4eb588e4d5ed7db029","event_at":"2026-07-28T04:12:41.011000Z","event_type":"price_change","frame_hash":"ad17ab85699b2b1a9e61ddd3f91ef344a08eb7009d9db6fdbeb5b42d69a2624d","frame_index":0,"kind":"data","monotonic_ns":313944314169791,"payload":{"event_type":"price_change","market":"0xd412ce774cfcf8dc9f71164aac78783978aac7b03871702a3b8a481bd9dc9688","price_changes":[{"asset_id":"107603864457683460275633293642179940881969192120168665300712204232021063124301","best_ask":"0.62","best_bid":"0.6","hash":"a68a4ee9287d008df786faf637410819d0931584","price":"0.59","side":"BUY","size":"45"},{"asset_id":"96600821790790307414914106093858868634329285205417149685270682748367152458577","best_ask":"0.4","best_bid":"0.38","hash":"fefc0d5d51a3664f0f254bb4d566cf894b2eeb73","price":"0.41","side":"SELL","size":"45"}],"timestamp":"1785211961011"},"payload_hash":"acc771192780d4530d1753d20aaee36fa9418b2307fb20726cb194a4bab0962e","raw_frame":"{\"market\":\"0xd412ce774cfcf8dc9f71164aac78783978aac7b03871702a3b8a481bd9dc9688\", \"price_changes\":[{\"asset_id\":\"107603864457683460275633293642179940881969192120168665300712204232021063124301\", \"price\":\"0.59\", \"size\":\"45\", \"side\":\"BUY\", \"hash\":\"a68a4ee9287d008df786faf637410819d0931584\", \"best_bid\":\"0.6\", \"best_ask\":\"0.62\"}, {\"asset_id\":\"96600821790790307414914106093858868634329285205417149685270682748367152458577\", \"price\":\"0.41\", \"size\":\"45\", \"side\":\"SELL\", \"hash\":\"fefc0d5d51a3664f0f254bb4d566cf894b2eeb73\", \"best_bid\":\"0.38\", \"best_ask\":\"0.4\"}], \"timestamp\":\"1785211961011\", \"event_type\":\"price_change\"}","received_at":"2026-07-28T04:12:41.236649Z","schema_version":"clob-market-ws.price_change.v1","sequence":null,"server_hash":null,"server_timestamp":"1785211961011","session_id":"2d607381e3054cee91998cdf45a4231c","source":"clob_market_ws"},"received_at":"2026-07-28T04:12:41.236649Z","record_id":"ee09039126e343faeb2011f5b18b999d283eaf2ff8b937cbe695ab96daf0f4d3","schema_fingerprint":"4aa3821a28b0b7c2400bc59aba4bcc0a76e971dadd19610d3ad38c768e124dc7","schema_version":"edge-lab-recorder.raw.v1","sequence":null,"source":"clob_market_ws"}
{"event_at":"2026-07-28T04:12:41.011000Z","event_fingerprint":"e50e0dc6ba8a04f0679964e140ddd65c5d41bfa4a6e2d423b37f1d7c6e4bc97f","payload":{"connection_id":"f6725804f86a4c4eb588e4d5ed7db029","event_at":"2026-07-28T04:12:41.011000Z","event_type":"price_change","frame_hash":"f68b34f6a26a51b99db89e6b438f3060e17ddeee6e0b4e6239835b3b173aeda6","frame_index":0,"kind":"data","monotonic_ns":313944331854666,"payload":{"event_type":"price_change","market":"0xd412ce774cfcf8dc9f71164aac78783978aac7b03871702a3b8a481bd9dc9688","price_changes":[{"asset_id":"107603864457683460275633293642179940881969192120168665300712204232021063124301","best_ask":"0.62","best_bid":"0.6","hash":"0a114d8f6251328a996899c8f3b917e21d56ca8d","price":"0.6","side":"BUY","size":"69.12"},{"asset_id":"96600821790790307414914106093858868634329285205417149685270682748367152458577","best_ask":"0.4","best_bid":"0.38","hash":"05bda5d5722e048ea0b755128fa62fdedfabc806","price":"0.4","side":"SELL","size":"69.12"}],"timestamp":"1785211961011"},"payload_hash":"960f70b914d5d524389b447f26fd8dbb977177c9aabd2353ba4cef4c2b7dc6e5","raw_frame":"{\"market\":\"0xd412ce774cfcf8dc9f71164aac78783978aac7b03871702a3b8a481bd9dc9688\", \"price_changes\":[{\"asset_id\":\"107603864457683460275633293642179940881969192120168665300712204232021063124301\", \"price\":\"0.6\", \"size\":\"69.12\", \"side\":\"BUY\", \"hash\":\"0a114d8f6251328a996899c8f3b917e21d56ca8d\", \"best_bid\":\"0.6\", \"best_ask\":\"0.62\"}, {\"asset_id\":\"96600821790790307414914106093858868634329285205417149685270682748367152458577\", \"price\":\"0.4\", \"size\":\"69.12\", \"side\":\"SELL\", \"hash\":\"05bda5d5722e048ea0b755128fa62fdedfabc806\", \"best_bid\":\"0.38\", \"best_ask\":\"0.4\"}], \"timestamp\":\"1785211961011\", \"event_type\":\"price_change\"}","received_at":"2026-07-28T04:12:41.254334Z","schema_version":"clob-market-ws.price_change.v1","sequence":null,"server_hash":null,"server_timestamp":"1785211961011","session_id":"2d607381e3054cee91998cdf45a4231c","source":"clob_market_ws"},"received_at":"2026-07-28T04:12:41.254334Z","record_id":"6dfc8a301a3e32c51482d2f7ed4ad161b803a164acb2c23d7de010f0ec3c4624","schema_fingerprint":"4aa3821a28b0b7c2400bc59aba4bcc0a76e971dadd19610d3ad38c768e124dc7","schema_version":"edge-lab-recorder.raw.v1","sequence":null,"source":"clob_market_ws"}
{"event_at":"2026-07-28T04:12:41.012000Z","event_fingerprint":"f63b56f66936a4fcc47645fc5dc87b002f24f22b3f1df21fec8237c86d624a66","payload":{"connection_id":"f6725804f86a4c4eb588e4d5ed7db029","event_at":"2026-07-28T04:12:41.012000Z","event_type":"price_change","frame_hash":"d569e30391470ab6658260feae0508c7e750fea8a875cee8539d0dc14824ca06","frame_index":0,"kind":"data","monotonic_ns":313944339319750,"payload":{"event_type":"price_change","market":"0xd412ce774cfcf8dc9f71164aac78783978aac7b03871702a3b8a481bd9dc9688","price_changes":[{"asset_id":"96600821790790307414914106093858868634329285205417149685270682748367152458577","best_ask":"0.4","best_bid":"0.38","hash":"144025fd360c2caeeb90ba79068a5e1040cbf89f","price":"0.38","side":"BUY","size":"100"},{"asset_id":"107603864457683460275633293642179940881969192120168665300712204232021063124301","best_ask":"0.62","best_bid":"0.6","hash":"1fd152eddf370516312961817df10c74fc1e5c93","price":"0.62","side":"SELL","size":"100"}],"timestamp":"1785211961012"},"payload_hash":"cfb3f6459e214c4343a8ac62d61a39ee02fea017a44f7cbb5cf08cae6cd1fc5a","raw_frame":"{\"market\":\"0xd412ce774cfcf8dc9f71164aac78783978aac7b03871702a3b8a481bd9dc9688\", \"price_changes\":[{\"asset_id\":\"96600821790790307414914106093858868634329285205417149685270682748367152458577\", \"price\":\"0.38\", \"size\":\"100\", \"side\":\"BUY\", \"hash\":\"144025fd360c2caeeb90ba79068a5e1040cbf89f\", \"best_bid\":\"0.38\", \"best_ask\":\"0.4\"}, {\"asset_id\":\"107603864457683460275633293642179940881969192120168665300712204232021063124301\", \"price\":\"0.62\", \"size\":\"100\", \"side\":\"SELL\", \"hash\":\"1fd152eddf370516312961817df10c74fc1e5c93\", \"best_bid\":\"0.6\", \"best_ask\":\"0.62\"}], \"timestamp\":\"1785211961012\", \"event_type\":\"price_change\"}","received_at":"2026-07-28T04:12:41.261800Z","schema_version":"clob-market-ws.price_change.v1","sequence":null,"server_hash":null,"server_timestamp":"1785211961012","session_id":"2d607381e3054cee91998cdf45a4231c","source":"clob_market_ws"},"received_at":"2026-07-28T04:12:41.261800Z","record_id":"eb6307f3ae7ea87a29688b9a3177008c705e92fc30dec3bb03fe9db530b33a74","schema_fingerprint":"4aa3821a28b0b7c2400bc59aba4bcc0a76e971dadd19610d3ad38c768e124dc7","schema_version":"edge-lab-recorder.raw.v1","sequence":null,"source":"clob_market_ws"}
{"event_at":"2026-07-28T04:12:41.018000Z","event_fingerprint":"1a6a78c489684311e613096a2f5c5d9627ae3e8b8726873f03c62ed8ae37b39c","payload":{"connection_id":"f6725804f86a4c4eb588e4d5ed7db029","event_at":"2026-07-28T04:12:41.018000Z","event_type":"price_change","frame_hash":"89efcae020a50658c0afc5eadf9f518883879088a05ed8aee5dce181634c5f9f","frame_index":0,"kind":"data","monotonic_ns":313944343636666,"payload":{"event_type":"price_change","market":"0xd412ce774cfcf8dc9f71164aac78783978aac7b03871702a3b8a481bd9dc9688","price_changes":[{"asset_id":"96600821790790307414914106093858868634329285205417149685270682748367152458577","best_ask":"0.4","best_bid":"0.38","hash":"54730b1a7a15c5ea29b727f7c8ef1a8cde616da0","price":"0.37","side":"BUY","size":"91.41"},{"asset_id":"107603864457683460275633293642179940881969192120168665300712204232021063124301","best_ask":"0.62","best_bid":"0.6","hash":"cdb19ff868468ac8f02598f8aa9161a2725ec43a","price":"0.63","side":"SELL","size":"91.41"}],"timestamp":"1785211961018"},"payload_hash":"a657bce28061a312479a78c0c5700fda11a1a428adec2fce59012ab6b633fcb5","raw_frame":"{\"market\":\"0xd412ce774cfcf8dc9f71164aac78783978aac7b03871702a3b8a481bd9dc9688\", \"price_changes\":[{\"asset_id\":\"96600821790790307414914106093858868634329285205417149685270682748367152458577\", \"price\":\"0.37\", \"size\":\"91.41\", \"side\":\"BUY\", \"hash\":\"54730b1a7a15c5ea29b727f7c8ef1a8cde616da0\", \"best_bid\":\"0.38\", \"best_ask\":\"0.4\"}, {\"asset_id\":\"107603864457683460275633293642179940881969192120168665300712204232021063124301\", \"price\":\"0.63\", \"size\":\"91.41\", \"side\":\"SELL\", \"hash\":\"cdb19ff868468ac8f02598f8aa9161a2725ec43a\", \"best_bid\":\"0.6\", \"best_ask\":\"0.62\"}], \"timestamp\":\"1785211961018\", \"event_type\":\"price_change\"}","received_at":"2026-07-28T04:12:41.266115Z","schema_version":"clob-market-ws.price_change.v1","sequence":null,"server_hash":null,"server_timestamp":"1785211961018","session_id":"2d607381e3054cee91998cdf45a4231c","source":"clob_market_ws"},"received_at":"2026-07-28T04:12:41.266115Z","record_id":"c701c80624b75a4a348adde990933363777fafda07cb8f8d9555b5b0dacd1160","schema_fingerprint":"4aa3821a28b0b7c2400bc59aba4bcc0a76e971dadd19610d3ad38c768e124dc7","schema_version":"edge-lab-recorder.raw.v1","sequence":null,"source":"clob_market_ws"}
{"event_at":"2026-07-28T04:12:41.028000Z","event_fingerprint":"fdbb25ccd8f390977d3e313c0313636bddd7beffb7ef680d47e2eff97b361f76","payload":{"connection_id":"f6725804f86a4c4eb588e4d5ed7db029","event_at":"2026-07-28T04:12:41.028000Z","event_type":"price_change","frame_hash":"bc0161d85d40769f4eaa7af68c0dbcfbad14a4b28196ea869010fc351cf33cc6","frame_index":0,"kind":"data","monotonic_ns":313944348182791,"payload":{"event_type":"price_change","market":"0xd412ce774cfcf8dc9f71164aac78783978aac7b03871702a3b8a481bd9dc9688","price_changes":[{"asset_id":"96600821790790307414914106093858868634329285205417149685270682748367152458577","best_ask":"0.4","best_bid":"0.38","hash":"2093ed991edbfac1bc250bfdcec542d4fbe5677e","price":"0.01","side":"BUY","size":"5305.02"},{"asset_id":"107603864457683460275633293642179940881969192120168665300712204232021063124301","best_ask":"0.62","best_bid":"0.6","hash":"d8a537c9a1eeee8ea1936fa2b86a7e58c3b011ba","price":"0.99","side":"SELL","size":"5305.02"}],"timestamp":"1785211961028"},"payload_hash":"dddc2674ba43b89abc88ac12b2a620892a24f36c399b0f292bee31a0950353f2","raw_frame":"{\"market\":\"0xd412ce774cfcf8dc9f71164aac78783978aac7b03871702a3b8a481bd9dc9688\", \"price_changes\":[{\"asset_id\":\"96600821790790307414914106093858868634329285205417149685270682748367152458577\", \"price\":\"0.01\", \"size\":\"5305.02\", \"side\":\"BUY\", \"hash\":\"2093ed991edbfac1bc250bfdcec542d4fbe5677e\", \"best_bid\":\"0.38\", \"best_ask\":\"0.4\"}, {\"asset_id\":\"107603864457683460275633293642179940881969192120168665300712204232021063124301\", \"price\":\"0.99\", \"size\":\"5305.02\", \"side\":\"SELL\", \"hash\":\"d8a537c9a1eeee8ea1936fa2b86a7e58c3b011ba\", \"best_bid\":\"0.6\", \"best_ask\":\"0.62\"}], \"timestamp\":\"1785211961028\", \"event_type\":\"price_change\"}","received_at":"2026-07-28T04:12:41.270662Z","schema_version":"clob-market-ws.price_change.v1","sequence":null,"server_hash":null,"server_timestamp":"1785211961028","session_id":"2d607381e3054cee91998cdf45a4231c","source":"clob_market_ws"},"received_at":"2026-07-28T04:12:41.270662Z","record_id":"1bcb4e7affafe111f41b2e69a0da434691d7283f1d076f89bb2864c9b58e046c","schema_fingerprint":"4aa3821a28b0b7c2400bc59aba4bcc0a76e971dadd19610d3ad38c768e124dc7","schema_version":"edge-lab-recorder.raw.v1","sequence":null,"source":"clob_market_ws"}
{"event_at":"2026-07-28T04:12:41.030000Z","event_fingerprint":"5e4d24a1697e6bdfc662bb83c3bf458d93cfce446ae0255910229b110a5dda0c","payload":{"connection_id":"f6725804f86a4c4eb588e4d5ed7db029","event_at":"2026-07-28T04:12:41.030000Z","event_type":"price_change","frame_hash":"c0acb623416f3062e85b6f59c81a5b206027f2180c24cd53fbd27b2130218f74","frame_index":0,"kind":"data","monotonic_ns":313944354888500,"payload":{"event_type":"price_change","market":"0xd412ce774cfcf8dc9f71164aac78783978aac7b03871702a3b8a481bd9dc9688","price_changes":[{"asset_id":"107603864457683460275633293642179940881969192120168665300712204232021063124301","best_ask":"0.62","best_bid":"0.6","hash":"99247a038ed4720997140375ec1e159602461f12","price":"0.6","side":"BUY","size":"36.12"},{"asset_id":"96600821790790307414914106093858868634329285205417149685270682748367152458577","best_ask":"0.4","best_bid":"0.38","hash":"cd2b359542b2090ce16cb64b0c2bca880056fcad","price":"0.4","side":"SELL","size":"36.12"}],"timestamp":"1785211961030"},"payload_hash":"1336730208c73be9caabba02f60f7219f898123fcf7d9fee5c4b3fd69f2db8d4","raw_frame":"{\"market\":\"0xd412ce774cfcf8dc9f71164aac78783978aac7b03871702a3b8a481bd9dc9688\", \"price_changes\":[{\"asset_id\":\"107603864457683460275633293642179940881969192120168665300712204232021063124301\", \"price\":\"0.6\", \"size\":\"36.12\", \"side\":\"BUY\", \"hash\":\"99247a038ed4720997140375ec1e159602461f12\", \"best_bid\":\"0.6\", \"best_ask\":\"0.62\"}, {\"asset_id\":\"96600821790790307414914106093858868634329285205417149685270682748367152458577\", \"price\":\"0.4\", \"size\":\"36.12\", \"side\":\"SELL\", \"hash\":\"cd2b359542b2090ce16cb64b0c2bca880056fcad\", \"best_bid\":\"0.38\", \"best_ask\":\"0.4\"}], \"timestamp\":\"1785211961030\", \"event_type\":\"price_change\"}","received_at":"2026-07-28T04:12:41.277368Z","schema_version":"clob-market-ws.price_change.v1","sequence":null,"server_hash":null,"server_timestamp":"1785211961030","session_id":"2d607381e3054cee91998cdf45a4231c","source":"clob_market_ws"},"received_at":"2026-07-28T04:12:41.277368Z","record_id":"005179ddd63bcff3d1030fb583e39dc72c25b8fea545f1f22555a6814543452f","schema_fingerprint":"4aa3821a28b0b7c2400bc59aba4bcc0a76e971dadd19610d3ad38c768e124dc7","schema_version":"edge-lab-recorder.raw.v1","sequence":null,"source":"clob_market_ws"}
{"event_at":"2026-07-28T04:12:41.031000Z","event_fingerprint":"c90761668b6b8dbc594d45c210a292cafef31d5c3fa311a5238693bb101b38e0","payload":{"connection_id":"f6725804f86a4c4eb588e4d5ed7db029","event_at":"2026-07-28T04:12:41.031000Z","event_type":"price_change","frame_hash":"e38f2f1bcda4e7ebba8feef8a17fdd7ab7e9e00dc07ebd7a980967616ccf649b","frame_index":0,"kind":"data","monotonic_ns":313944361436000,"payload":{"event_type":"price_change","market":"0xd412ce774cfcf8dc9f71164aac78783978aac7b03871702a3b8a481bd9dc9688","price_changes":[{"asset_id":"96600821790790307414914106093858868634329285205417149685270682748367152458577","best_ask":"0.4","best_bid":"0.38","hash":"95ace1f4ddff6bde6126e7c11332ae33993199d6","price":"0.01","side":"BUY","size":"5310.02"},{"asset_id":"107603864457683460275633293642179940881969192120168665300712204232021063124301","best_ask":"0.62","best_bid":"0.6","hash":"f4e468df67b6a354947b672edf60525d9fe67fb8","price":"0.99","side":"SELL","size":"5310.02"}],"timestamp":"1785211961031"},"payload_hash":"4199fb97a14d6d0f115637feebec177f19973db784361df27e048939077c404f","raw_frame":"{\"market\":\"0xd412ce774cfcf8dc9f71164aac78783978aac7b03871702a3b8a481bd9dc9688\", \"price_changes\":[{\"asset_id\":\"96600821790790307414914106093858868634329285205417149685270682748367152458577\", \"price\":\"0.01\", \"size\":\"5310.02\", \"side\":\"BUY\", \"hash\":\"95ace1f4ddff6bde6126e7c11332ae33993199d6\", \"best_bid\":\"0.38\", \"best_ask\":\"0.4\"}, {\"asset_id\":\"107603864457683460275633293642179940881969192120168665300712204232021063124301\", \"price\":\"0.99\", \"size\":\"5310.02\", \"side\":\"SELL\", \"hash\":\"f4e468df67b6a354947b672edf60525d9fe67fb8\", \"best_bid\":\"0.6\", \"best_ask\":\"0.62\"}], \"timestamp\":\"1785211961031\", \"event_type\":\"price_change\"}","received_at":"2026-07-28T04:12:41.283916Z","schema_version":"clob-market-ws.price_change.v1","sequence":null,"server_hash":null,"server_timestamp":"1785211961031","session_id":"2d607381e3054cee91998cdf45a4231c","source":"clob_market_ws"},"received_at":"2026-07-28T04:12:41.283916Z","record_id":"9ea5622dd614cd37e1db0f6a3c0bc3b8474298c01e8514a57d057941f3d91e2a","schema_fingerprint":"4aa3821a28b0b7c2400bc59aba4bcc0a76e971dadd19610d3ad38c768e124dc7","schema_version":"edge-lab-recorder.raw.v1","sequence":null,"source":"clob_market_ws"}
{"event_at":"2026-07-28T04:12:41.032000Z","event_fingerprint":"67666b2fa6c2417d213ac360b5588d6a6384074d9605cf575f9213ce219f169f","payload":{"connection_id":"f6725804f86a4c4eb588e4d5ed7db029","event_at":"2026-07-28T04:12:41.032000Z","event_type":"price_change","frame_hash":"acad8b4a9687bca99f00a77e6674a598011003006d067e1a8fd3ab818f84c0fe","frame_index":0,"kind":"data","monotonic_ns":313944365401125,"payload":{"event_type":"price_change","market":"0xd412ce774cfcf8dc9f71164aac78783978aac7b03871702a3b8a481bd9dc9688","price_changes":[{"asset_id":"107603864457683460275633293642179940881969192120168665300712204232021063124301","best_ask":"0.62","best_bid":"0.6","hash":"43ac203f6ae2d1bd2fb2ff931a454afbdf234bbb","price":"0.59","side":"BUY","size":"11"},{"asset_id":"96600821790790307414914106093858868634329285205417149685270682748367152458577","best_ask":"0.4","best_bid":"0.38","hash":"578715bb190b4730d842fdf492efd00ea7b46951","price":"0.41","side":"SELL","size":"11"}],"timestamp":"1785211961032"},"payload_hash":"bdc7dfbf6926537b32872e07c484c6c03a2c627a6ffddf56e077297dedec43cc","raw_frame":"{\"market\":\"0xd412ce774cfcf8dc9f71164aac78783978aac7b03871702a3b8a481bd9dc9688\", \"price_changes\":[{\"asset_id\":\"107603864457683460275633293642179940881969192120168665300712204232021063124301\", \"price\":\"0.59\", \"size\":\"11\", \"side\":\"BUY\", \"hash\":\"43ac203f6ae2d1bd2fb2ff931a454afbdf234bbb\", \"best_bid\":\"0.6\", \"best_ask\":\"0.62\"}, {\"asset_id\":\"96600821790790307414914106093858868634329285205417149685270682748367152458577\", \"price\":\"0.41\", \"size\":\"11\", \"side\":\"SELL\", \"hash\":\"578715bb190b4730d842fdf492efd00ea7b46951\", \"best_bid\":\"0.38\", \"best_ask\":\"0.4\"}], \"timestamp\":\"1785211961032\", \"event_type\":\"price_change\"}","received_at":"2026-07-28T04:12:41.287881Z","schema_version":"clob-market-ws.price_change.v1","sequence":null,"server_hash":null,"server_timestamp":"1785211961032","session_id":"2d607381e3054cee91998cdf45a4231c","source":"clob_market_ws"},"received_at":"2026-07-28T04:12:41.287881Z","record_id":"c5e6e0ab1ffd5985a8abadd77b5367ec2eb2c4565c98974fe286306f1b0d0e07","schema_fingerprint":"4aa3821a28b0b7c2400bc59aba4bcc0a76e971dadd19610d3ad38c768e124dc7","schema_version":"edge-lab-recorder.raw.v1","sequence":null,"source":"clob_market_ws"}
{"event_at":"2026-07-28T04:12:41.047000Z","event_fingerprint":"099efbda372758232ea0d258bd669c7d46edb350c02ed5d381baa71a01a1ba16","payload":{"connection_id":"f6725804f86a4c4eb588e4d5ed7db029","event_at":"2026-07-28T04:12:41.047000Z","event_type":"price_change","frame_hash":"f57831aede0b45b3b6d2228ad1338fdfdfdbff88257a3db838b223a4b4692611","frame_index":0,"kind":"data","monotonic_ns":313944369815708,"payload":{"event_type":"price_change","market":"0xd412ce774cfcf8dc9f71164aac78783978aac7b03871702a3b8a481bd9dc9688","price_changes":[{"asset_id":"96600821790790307414914106093858868634329285205417149685270682748367152458577","best_ask":"0.4","best_bid":"0.38","hash":"06af6f55f6b33bab85e04f4b83abd8efdbfce3d9","price":"0.01","side":"BUY","size":"5305.02"},{"asset_id":"107603864457683460275633293642179940881969192120168665300712204232021063124301","best_ask":"0.62","best_bid":"0.6","hash":"75c039bd90436478579dac82418d82aae8752bf0","price":"0.99","side":"SELL","size":"5305.02"}],"timestamp":"1785211961047"},"payload_hash":"cc3d213a30da6d0a1510689f6ca35f61bf13eb5bca13183e9206d574574892e6","raw_frame":"{\"market\":\"0xd412ce774cfcf8dc9f71164aac78783978aac7b03871702a3b8a481bd9dc9688\", \"price_changes\":[{\"asset_id\":\"96600821790790307414914106093858868634329285205417149685270682748367152458577\", \"price\":\"0.01\", \"size\":\"5305.02\", \"side\":\"BUY\", \"hash\":\"06af6f55f6b33bab85e04f4b83abd8efdbfce3d9\", \"best_bid\":\"0.38\", \"best_ask\":\"0.4\"}, {\"asset_id\":\"107603864457683460275633293642179940881969192120168665300712204232021063124301\", \"price\":\"0.99\", \"size\":\"5305.02\", \"side\":\"SELL\", \"hash\":\"75c039bd90436478579dac82418d82aae8752bf0\", \"best_bid\":\"0.6\", \"best_ask\":\"0.62\"}], \"timestamp\":\"1785211961047\", \"event_type\":\"price_change\"}","received_at":"2026-07-28T04:12:41.292296Z","schema_version":"clob-market-ws.price_change.v1","sequence":null,"server_hash":null,"server_timestamp":"1785211961047","session_id":"2d607381e3054cee91998cdf45a4231c","source":"clob_market_ws"},"received_at":"2026-07-28T04:12:41.292296Z","record_id":"db25eb856cc5fe91effeaaa0d49bf2a0dd21927d5902e9dc99a3be09c15367dc","schema_fingerprint":"4aa3821a28b0b7c2400bc59aba4bcc0a76e971dadd19610d3ad38c768e124dc7","schema_version":"edge-lab-recorder.raw.v1","sequence":null,"source":"clob_market_ws"}
{"event_at":"2026-07-28T04:12:41.057000Z","event_fingerprint":"e74a8699642c77136507e414d9d242483869d6d8dc5b02cb3cfc0088a2248602","payload":{"connection_id":"f6725804f86a4c4eb588e4d5ed7db029","event_at":"2026-07-28T04:12:41.057000Z","event_type":"price_change","frame_hash":"a3d917a73f41415075b928afcb6608dbf847b14c61199180261940d6f93c0705","frame_index":0,"kind":"data","monotonic_ns":313944374754250,"payload":{"event_type":"price_change","market":"0xd412ce774cfcf8dc9f71164aac78783978aac7b03871702a3b8a481bd9dc9688","price_changes":[{"asset_id":"107603864457683460275633293642179940881969192120168665300712204232021063124301","best_ask":"0.62","best_bid":"0.6","hash":"1cdad3fcc50bc51b62ba77f60cd49beea3496a97","price":"0.58","side":"BUY","size":"19"},{"asset_id":"96600821790790307414914106093858868634329285205417149685270682748367152458577","best_ask":"0.4","best_bid":"0.38","hash":"e9b58950b7694e980c7d7fdc42f8f5e2bddbece2","price":"0.42","side":"SELL","size":"19"}],"timestamp":"1785211961057"},"payload_hash":"a1498a426f3c92f206bc7f7b369353d89857e8e3a03f872c365971677ecedb12","raw_frame":"{\"market\":\"0xd412ce774cfcf8dc9f71164aac78783978aac7b03871702a3b8a481bd9dc9688\", \"price_changes\":[{\"asset_id\":\"107603864457683460275633293642179940881969192120168665300712204232021063124301\", \"price\":\"0.58\", \"size\":\"19\", \"side\":\"BUY\", \"hash\":\"1cdad3fcc50bc51b62ba77f60cd49beea3496a97\", \"best_bid\":\"0.6\", \"best_ask\":\"0.62\"}, {\"asset_id\":\"96600821790790307414914106093858868634329285205417149685270682748367152458577\", \"price\":\"0.42\", \"size\":\"19\", \"side\":\"SELL\", \"hash\":\"e9b58950b7694e980c7d7fdc42f8f5e2bddbece2\", \"best_bid\":\"0.38\", \"best_ask\":\"0.4\"}], \"timestamp\":\"1785211961057\", \"event_type\":\"price_change\"}","received_at":"2026-07-28T04:12:41.297234Z","schema_version":"clob-market-ws.price_change.v1","sequence":null,"server_hash":null,"server_timestamp":"1785211961057","session_id":"2d607381e3054cee91998cdf45a4231c","source":"clob_market_ws"},"received_at":"2026-07-28T04:12:41.297234Z","record_id":"b7f799abd35ab23b2723693ff2ee048e86231278f683db6912780d131e31f22a","schema_fingerprint":"4aa3821a28b0b7c2400bc59aba4bcc0a76e971dadd19610d3ad38c768e124dc7","schema_version":"edge-lab-recorder.raw.v1","sequence":null,"source":"clob_market_ws"}
{"event_at":"2026-07-28T04:12:41.086000Z","event_fingerprint":"692b37eea6fddd81471e46d1bb1a96515541184df8470cc67080917be4b016eb","payload":{"connection_id":"f6725804f86a4c4eb588e4d5ed7db029","event_at":"2026-07-28T04:12:41.086000Z","event_type":"price_change","frame_hash":"904a3121576b0e8fd78603b223c1619219d1137c748da85ac09190c626dc4025","frame_index":0,"kind":"data","monotonic_ns":313944377539916,"payload":{"event_type":"price_change","market":"0xd412ce774cfcf8dc9f71164aac78783978aac7b03871702a3b8a481bd9dc9688","price_changes":[{"asset_id":"107603864457683460275633293642179940881969192120168665300712204232021063124301","best_ask":"0.62","best_bid":"0.6","hash":"3227e73a32d21924216a0d9845318bfbb6a9be6e","price":"0.01","side":"BUY","size":"5335.02"},{"asset_id":"96600821790790307414914106093858868634329285205417149685270682748367152458577","best_ask":"0.4","best_bid":"0.38","hash":"9f0ac224f252eba228a52cbb96161220fa583c46","price":"0.99","side":"SELL","size":"5335.02"}],"timestamp":"1785211961086"},"payload_hash":"6f655f3d4d9440cdfd33bc1615fa0d4035963a05f542559497f269c7f441a750","raw_frame":"{\"market\":\"0xd412ce774cfcf8dc9f71164aac78783978aac7b03871702a3b8a481bd9dc9688\", \"price_changes\":[{\"asset_id\":\"107603864457683460275633293642179940881969192120168665300712204232021063124301\", \"price\":\"0.01\", \"size\":\"5335.02\", \"side\":\"BUY\", \"hash\":\"3227e73a32d21924216a0d9845318bfbb6a9be6e\", \"best_bid\":\"0.6\", \"best_ask\":\"0.62\"}, {\"asset_id\":\"96600821790790307414914106093858868634329285205417149685270682748367152458577\", \"price\":\"0.99\", \"size\":\"5335.02\", \"side\":\"SELL\", \"hash\":\"9f0ac224f252eba228a52cbb96161220fa583c46\", \"best_bid\":\"0.38\", \"best_ask\":\"0.4\"}], \"timestamp\":\"1785211961086\", \"event_type\":\"price_change\"}","received_at":"2026-07-28T04:12:41.300020Z","schema_version":"clob-market-ws.price_change.v1","sequence":null,"server_hash":null,"server_timestamp":"1785211961086","session_id":"2d607381e3054cee91998cdf45a4231c","source":"clob_market_ws"},"received_at":"2026-07-28T04:12:41.300020Z","record_id":"ddcb1ea7cd8a74d51cf7eaaceafec3bc842f17c63bc002b9e8f1252d67bd2709","schema_fingerprint":"4aa3821a28b0b7c2400bc59aba4bcc0a76e971dadd19610d3ad38c768e124dc7","schema_version":"edge-lab-recorder.raw.v1","sequence":null,"source":"clob_market_ws"}
{"event_at":"2026-07-28T04:12:41.098000Z","event_fingerprint":"b138360a3fb14d1a480b363ab906a8f253892f0ebe90bcba78a59bedc5b53bb9","payload":{"connection_id":"f6725804f86a4c4eb588e4d5ed7db029","event_at":"2026-07-28T04:12:41.098000Z","event_type":"price_change","frame_hash":"41934b0d0b05fb626c66abd3ddbe9c0f0305634db0661590f0f021c1ee19ac82","frame_index":0,"kind":"data","monotonic_ns":313944382428833,"payload":{"event_type":"price_change","market":"0xd412ce774cfcf8dc9f71164aac78783978aac7b03871702a3b8a481bd9dc9688","price_changes":[{"asset_id":"107603864457683460275633293642179940881969192120168665300712204232021063124301","best_ask":"0.62","best_bid":"0.6","hash":"2ca24760253a3aede8160ab6430e0690a0006a80","price":"0.39","side":"BUY","size":"20"},{"asset_id":"96600821790790307414914106093858868634329285205417149685270682748367152458577","best_ask":"0.4","best_bid":"0.38","hash":"324b082e284dd7e57831871963010040c1564627","price":"0.61","side":"SELL","size":"20"}],"timestamp":"1785211961098"},"payload_hash":"c38b6775f3468e2b750115fcf0cb0c9a44b12266b55890cd1769bfdaebc0fa86","raw_frame":"{\"market\":\"0xd412ce774cfcf8dc9f71164aac78783978aac7b03871702a3b8a481bd9dc9688\", \"price_changes\":[{\"asset_id\":\"107603864457683460275633293642179940881969192120168665300712204232021063124301\", \"price\":\"0.39\", \"size\":\"20\", \"side\":\"BUY\", \"hash\":\"2ca24760253a3aede8160ab6430e0690a0006a80\", \"best_bid\":\"0.6\", \"best_ask\":\"0.62\"}, {\"asset_id\":\"96600821790790307414914106093858868634329285205417149685270682748367152458577\", \"price\":\"0.61\", \"size\":\"20\", \"side\":\"SELL\", \"hash\":\"324b082e284dd7e57831871963010040c1564627\", \"best_bid\":\"0.38\", \"best_ask\":\"0.4\"}], \"timestamp\":\"1785211961098\", \"event_type\":\"price_change\"}","received_at":"2026-07-28T04:12:41.304907Z","schema_version":"clob-market-ws.price_change.v1","sequence":null,"server_hash":null,"server_timestamp":"1785211961098","session_id":"2d607381e3054cee91998cdf45a4231c","source":"clob_market_ws"},"received_at":"2026-07-28T04:12:41.304907Z","record_id":"a3720948c0998e7072c559cbb97402de79995339aa64987a79c55ef64d51a87e","schema_fingerprint":"4aa3821a28b0b7c2400bc59aba4bcc0a76e971dadd19610d3ad38c768e124dc7","schema_version":"edge-lab-recorder.raw.v1","sequence":null,"source":"clob_market_ws"}
{"event_at":"2026-07-28T04:12:41.098000Z","event_fingerprint":"ad2445778eff7e7fafb03a048173cc93c07e978b496ef5a299912c2e0f133b3f","payload":{"connection_id":"f6725804f86a4c4eb588e4d5ed7db029","event_at":"2026-07-28T04:12:41.098000Z","event_type":"price_change","frame_hash":"20a03d22eae7af9b6676d22039bf4567dbd7f08343509106db7e763538841478","frame_index":0,"kind":"data","monotonic_ns":313944387641166,"payload":{"event_type":"price_change","market":"0xd412ce774cfcf8dc9f71164aac78783978aac7b03871702a3b8a481bd9dc9688","price_changes":[{"asset_id":"96600821790790307414914106093858868634329285205417149685270682748367152458577","best_ask":"0.4","best_bid":"0.38","hash":"324b082e284dd7e57831871963010040c1564627","price":"0.31","side":"BUY","size":"144"},{"asset_id":"107603864457683460275633293642179940881969192120168665300712204232021063124301","best_ask":"0.62","best_bid":"0.6","hash":"2ca24760253a3aede8160ab6430e0690a0006a80","price":"0.69","side":"SELL","size":"144"}],"timestamp":"1785211961098"},"payload_hash":"e79bbd0a9775e93deb8f876e60f491e7250ca19c5f9b982a920d8cc8fd540454","raw_frame":"{\"market\":\"0xd412ce774cfcf8dc9f71164aac78783978aac7b03871702a3b8a481bd9dc9688\", \"price_changes\":[{\"asset_id\":\"96600821790790307414914106093858868634329285205417149685270682748367152458577\", \"price\":\"0.31\", \"size\":\"144\", \"side\":\"BUY\", \"hash\":\"324b082e284dd7e57831871963010040c1564627\", \"best_bid\":\"0.38\", \"best_ask\":\"0.4\"}, {\"asset_id\":\"107603864457683460275633293642179940881969192120168665300712204232021063124301\", \"price\":\"0.69\", \"size\":\"144\", \"side\":\"SELL\", \"hash\":\"2ca24760253a3aede8160ab6430e0690a0006a80\", \"best_bid\":\"0.6\", \"best_ask\":\"0.62\"}], \"timestamp\":\"1785211961098\", \"event_type\":\"price_change\"}","received_at":"2026-07-28T04:12:41.310121Z","schema_version":"clob-market-ws.price_change.v1","sequence":null,"server_hash":null,"server_timestamp":"1785211961098","session_id":"2d607381e3054cee91998cdf45a4231c","source":"clob_market_ws"},"received_at":"2026-07-28T04:12:41.310121Z","record_id":"a58c4be2f8177af0521a17b7ba23490b4cb83ef8aff55d3545d719ee2e813d02","schema_fingerprint":"4aa3821a28b0b7c2400bc59aba4bcc0a76e971dadd19610d3ad38c768e124dc7","schema_version":"edge-lab-recorder.raw.v1","sequence":null,"source":"clob_market_ws"}
{"event_at":"2026-07-28T04:12:41.119000Z","event_fingerprint":"d435eb80a4c5c7e113b3edfec10efcf9ecaa3b3ee0204f84994b2247689f0df2","payload":{"connection_id":"f6725804f86a4c4eb588e4d5ed7db029","event_at":"2026-07-28T04:12:41.119000Z","event_type":"price_change","frame_hash":"2f70ed8d1bc99528ab3b274029906c30ba3dbe2ca122aa8abdb45a706be892ef","frame_index":0,"kind":"data","monotonic_ns":313944392025333,"payload":{"event_type":"price_change","market":"0xd412ce774cfcf8dc9f71164aac78783978aac7b03871702a3b8a481bd9dc9688","price_changes":[{"asset_id":"107603864457683460275633293642179940881969192120168665300712204232021063124301","best_ask":"0.62","best_bid":"0.6","hash":"107e6f5ed74500d42d701ed09d550aeae00b414f","price":"0.01","side":"BUY","size":"5340.02"},{"asset_id":"96600821790790307414914106093858868634329285205417149685270682748367152458577","best_ask":"0.4","best_bid":"0.38","hash":"1aab2d778c44856f118b5593358e6ecaf0ccfdcb","price":"0.99","side":"SELL","size":"5340.02"}],"timestamp":"1785211961119"},"payload_hash":"344ec3dddc99916dd95c0d06f307d203b1312dc28108aba02b41b6bd37e8d33e","raw_frame":"{\"market\":\"0xd412ce774cfcf8dc9f71164aac78783978aac7b03871702a3b8a481bd9dc9688\", \"price_changes\":[{\"asset_id\":\"107603864457683460275633293642179940881969192120168665300712204232021063124301\", \"price\":\"0.01\", \"size\":\"5340.02\", \"side\":\"BUY\", \"hash\":\"107e6f5ed74500d42d701ed09d550aeae00b414f\", \"best_bid\":\"0.6\", \"best_ask\":\"0.62\"}, {\"asset_id\":\"96600821790790307414914106093858868634329285205417149685270682748367152458577\", \"price\":\"0.99\", \"size\":\"5340.02\", \"side\":\"SELL\", \"hash\":\"1aab2d778c44856f118b5593358e6ecaf0ccfdcb\", \"best_bid\":\"0.38\", \"best_ask\":\"0.4\"}], \"timestamp\":\"1785211961119\", \"event_type\":\"price_change\"}","received_at":"2026-07-28T04:12:41.314505Z","schema_version":"clob-market-ws.price_change.v1","sequence":null,"server_hash":null,"server_timestamp":"1785211961119","session_id":"2d607381e3054cee91998cdf45a4231c","source":"clob_market_ws"},"received_at":"2026-07-28T04:12:41.314505Z","record_id":"8d8ebcf75f3989b25bd804b84ff0c10fcdf7d0006528eeb704b5b5b99bae07d4","schema_fingerprint":"4aa3821a28b0b7c2400bc59aba4bcc0a76e971dadd19610d3ad38c768e124dc7","schema_version":"edge-lab-recorder.raw.v1","sequence":null,"source":"clob_market_ws"}
{"event_at":"2026-07-28T04:12:41.120000Z","event_fingerprint":"5bc6ac622d6bd3a5ec944a6d8aca06d6f94d8b0c961ba1ba32c9403ee42b158f","payload":{"connection_id":"f6725804f86a4c4eb588e4d5ed7db029","event_at":"2026-07-28T04:12:41.120000Z","event_type":"price_change","frame_hash":"297bee7f5eb05b5c80f003d433bdc1d20392c66ca2453f29d27a5e41f12c0f72","frame_index":0,"kind":"data","monotonic_ns":313944396471083,"payload":{"event_type":"price_change","market":"0xd412ce774cfcf8dc9f71164aac78783978aac7b03871702a3b8a481bd9dc9688","price_changes":[{"asset_id":"96600821790790307414914106093858868634329285205417149685270682748367152458577","best_ask":"0.4","best_bid":"0.38","hash":"1190af0a66bf0e44da532e6bb0c1178abbabce39","price":"0.38","side":"BUY","size":"47"},{"asset_id":"107603864457683460275633293642179940881969192120168665300712204232021063124301","best_ask":"0.62","best_bid":"0.6","hash":"49c349ae86d676164109fb54a37f7e5c5a5ecf7b","price":"0.62","side":"SELL","size":"47"}],"timestamp":"1785211961120"},"payload_hash":"dc75d2a80c8dc6e7f92f549b4ea6ed904e143872ee0c182703d7e94a7375745d","raw_frame":"{\"market\":\"0xd412ce774cfcf8dc9f71164aac78783978aac7b03871702a3b8a481bd9dc9688\", \"price_changes\":[{\"asset_id\":\"96600821790790307414914106093858868634329285205417149685270682748367152458577\", \"price\":\"0.38\", \"size\":\"47\", \"side\":\"BUY\", \"hash\":\"1190af0a66bf0e44da532e6bb0c1178abbabce39\", \"best_bid\":\"0.38\", \"best_ask\":\"0.4\"}, {\"asset_id\":\"107603864457683460275633293642179940881969192120168665300712204232021063124301\", \"price\":\"0.62\", \"size\":\"47\", \"side\":\"SELL\", \"hash\":\"49c349ae86d676164109fb54a37f7e5c5a5ecf7b\", \"best_bid\":\"0.6\", \"best_ask\":\"0.62\"}], \"timestamp\":\"1785211961120\", \"event_type\":\"price_change\"}","received_at":"2026-07-28T04:12:41.318951Z","schema_version":"clob-market-ws.price_change.v1","sequence":null,"server_hash":null,"server_timestamp":"1785211961120","session_id":"2d607381e3054cee91998cdf45a4231c","source":"clob_market_ws"},"received_at":"2026-07-28T04:12:41.318951Z","record_id":"f03bcf15f9c751988fd142e2fbbef822b0b95c1f0c88f933ee4f18d1056febe0","schema_fingerprint":"4aa3821a28b0b7c2400bc59aba4bcc0a76e971dadd19610d3ad38c768e124dc7","schema_version":"edge-lab-recorder.raw.v1","sequence":null,"source":"clob_market_ws"}
{"event_at":"2026-07-28T04:12:41.122000Z","event_fingerprint":"b8d0fbf640fee2151fd545422c1ad12761fa0b07bac926bc30ebfcc4ca4054da","payload":{"connection_id":"f6725804f86a4c4eb588e4d5ed7db029","event_at":"2026-07-28T04:12:41.122000Z","event_type":"price_change","frame_hash":"ff79af6917943b2f1312a3b2c3d5d42db52665b022e5e0985dc028a1a6188ef5","frame_index":0,"kind":"data","monotonic_ns":313944401725166,"payload":{"event_type":"price_change","market":"0xd412ce774cfcf8dc9f71164aac78783978aac7b03871702a3b8a481bd9dc9688","price_changes":[{"asset_id":"96600821790790307414914106093858868634329285205417149685270682748367152458577","best_ask":"0.4","best_bid":"0.38","hash":"3824515323f3784c5a0488302615af9904285f38","price":"0.37","side":"BUY","size":"37.41"},{"asset_id":"107603864457683460275633293642179940881969192120168665300712204232021063124301","best_ask":"0.62","best_bid":"0.6","hash":"e2867b6ba8330a22734fb487d9d184e3a367b00f","price":"0.63","side":"SELL","size":"37.41"}],"timestamp":"1785211961122"},"payload_hash":"ad22a0dcb8bece64a1b16b396f5773b60f9be842382f417480248103c8051f89","raw_frame":"{\"market\":\"0xd412ce774cfcf8dc9f71164aac78783978aac7b03871702a3b8a481bd9dc9688\", \"price_changes\":[{\"asset_id\":\"96600821790790307414914106093858868634329285205417149685270682748367152458577\", \"price\":\"0.37\", \"size\":\"37.41\", \"side\":\"BUY\", \"hash\":\"3824515323f3784c5a0488302615af9904285f38\", \"best_bid\":\"0.38\", \"best_ask\":\"0.4\"}, {\"asset_id\":\"107603864457683460275633293642179940881969192120168665300712204232021063124301\", \"price\":\"0.63\", \"size\":\"37.41\", \"side\":\"SELL\", \"hash\":\"e2867b6ba8330a22734fb487d9d184e3a367b00f\", \"best_bid\":\"0.6\", \"best_ask\":\"0.62\"}], \"timestamp\":\"1785211961122\", \"event_type\":\"price_change\"}","received_at":"2026-07-28T04:12:41.324205Z","schema_version":"clob-market-ws.price_change.v1","sequence":null,"server_hash":null,"server_timestamp":"1785211961122","session_id":"2d607381e3054cee91998cdf45a4231c","source":"clob_market_ws"},"received_at":"2026-07-28T04:12:41.324205Z","record_id":"93925f84edf2ab3dbc5c80fcb4174124ca3995264cf9dfc7a8fe4086c181a14e","schema_fingerprint":"4aa3821a28b0b7c2400bc59aba4bcc0a76e971dadd19610d3ad38c768e124dc7","schema_version":"edge-lab-recorder.raw.v1","sequence":null,"source":"clob_market_ws"}
{"event_at":"2026-07-28T04:12:41.124000Z","event_fingerprint":"31f9f779cd1cfffc90347e723d0987335fee6b45dafd508dfddf1e50d1588c25","payload":{"connection_id":"f6725804f86a4c4eb588e4d5ed7db029","event_at":"2026-07-28T04:12:41.124000Z","event_type":"price_change","frame_hash":"06d28b31d05b32603a604a88de7297d83d3c688b08e09abf3461599920c4358d","frame_index":0,"kind":"data","monotonic_ns":313944405993541,"payload":{"event_type":"price_change","market":"0xd412ce774cfcf8dc9f71164aac78783978aac7b03871702a3b8a481bd9dc9688","price_changes":[{"asset_id":"107603864457683460275633293642179940881969192120168665300712204232021063124301","best_ask":"0.62","best_bid":"0.6","hash":"f72ac72c71287704912d61db1324486e762f3b5a","price":"0.58","side":"BUY","size":"53"},{"asset_id":"96600821790790307414914106093858868634329285205417149685270682748367152458577","best_ask":"0.4","best_bid":"0.38","hash":"39421f7855b7e2ca999a50a0147fbbab7415ec2b","price":"0.42","side":"SELL","size":"53"}],"timestamp":"1785211961124"},"payload_hash":"79e58fb724e3f2a29768f8649021a9f9133eaa8eb82a6203eb8564c64ca4f460","raw_frame":"{\"market\":\"0xd412ce774cfcf8dc9f71164aac78783978aac7b03871702a3b8a481bd9dc9688\", \"price_changes\":[{\"asset_id\":\"107603864457683460275633293642179940881969192120168665300712204232021063124301\", \"price\":\"0.58\", \"size\":\"53\", \"side\":\"BUY\", \"hash\":\"f72ac72c71287704912d61db1324486e762f3b5a\", \"best_bid\":\"0.6\", \"best_ask\":\"0.62\"}, {\"asset_id\":\"96600821790790307414914106093858868634329285205417149685270682748367152458577\", \"price\":\"0.42\", \"size\":\"53\", \"side\":\"SELL\", \"hash\":\"39421f7855b7e2ca999a50a0147fbbab7415ec2b\", \"best_bid\":\"0.38\", \"best_ask\":\"0.4\"}], \"timestamp\":\"1785211961124\", \"event_type\":\"price_change\"}","received_at":"2026-07-28T04:12:41.328472Z","schema_version":"clob-market-ws.price_change.v1","sequence":null,"server_hash":null,"server_timestamp":"1785211961124","session_id":"2d607381e3054cee91998cdf45a4231c","source":"clob_market_ws"},"received_at":"2026-07-28T04:12:41.328472Z","record_id":"14ed519ab1ee200d21ceab58f0f8824f3082785bc0714fe79646100592d06a38","schema_fingerprint":"4aa3821a28b0b7c2400bc59aba4bcc0a76e971dadd19610d3ad38c768e124dc7","schema_version":"edge-lab-recorder.raw.v1","sequence":null,"source":"clob_market_ws"}
{"event_at":"2026-07-28T04:12:41.124000Z","event_fingerprint":"efd5eacb15f92feaf7c5b7d5ae45d3b9cb1b7dfd696de973d8ca8c15c67b99b2","payload":{"connection_id":"f6725804f86a4c4eb588e4d5ed7db029","event_at":"2026-07-28T04:12:41.124000Z","event_type":"price_change","frame_hash":"f5672f202f904f973885703e4f0262e21546c39f4db41460ce22e9a901592413","frame_index":0,"kind":"data","monotonic_ns":313944410374916,"payload":{"event_type":"price_change","market":"0xd412ce774cfcf8dc9f71164aac78783978aac7b03871702a3b8a481bd9dc9688","price_changes":[{"asset_id":"107603864457683460275633293642179940881969192120168665300712204232021063124301","best_ask":"0.62","best_bid":"0.6","hash":"32773189e7cabfd916ea9cbfde0d70e0d94deefb","price":"0.6","side":"BUY","size":"69.12"},{"asset_id":"96600821790790307414914106093858868634329285205417149685270682748367152458577","best_ask":"0.4","best_bid":"0.38","hash":"481cb15b2ed76f18587918a599270a8b8b8832e8","price":"0.4","side":"SELL","size":"69.12"}],"timestamp":"1785211961124"},"payload_hash":"55daec71f855d539e8261f633c2f517683e12a8ce6e91447012026e6043e5958","raw_frame":"{\"market\":\"0xd412ce774cfcf8dc9f71164aac78783978aac7b03871702a3b8a481bd9dc9688\", \"price_changes\":[{\"asset_id\":\"107603864457683460275633293642179940881969192120168665300712204232021063124301\", \"price\":\"0.6\", \"size\":\"69.12\", \"side\":\"BUY\", \"hash\":\"32773189e7cabfd916ea9cbfde0d70e0d94deefb\", \"best_bid\":\"0.6\", \"best_ask\":\"0.62\"}, {\"asset_id\":\"96600821790790307414914106093858868634329285205417149685270682748367152458577\", \"price\":\"0.4\", \"size\":\"69.12\", \"side\":\"SELL\", \"hash\":\"481cb15b2ed76f18587918a599270a8b8b8832e8\", \"best_bid\":\"0.38\", \"best_ask\":\"0.4\"}], \"timestamp\":\"1785211961124\", \"event_type\":\"price_change\"}","received_at":"2026-07-28T04:12:41.332854Z","schema_version":"clob-market-ws.price_change.v1","sequence":null,"server_hash":null,"server_timestamp":"1785211961124","session_id":"2d607381e3054cee91998cdf45a4231c","source":"clob_market_ws"},"received_at":"2026-07-28T04:12:41.332854Z","record_id":"09da7761ca4a3f9a31061d5babc2df923343622c04e1ef3ec1f4cecdd3998605","schema_fingerprint":"4aa3821a28b0b7c2400bc59aba4bcc0a76e971dadd19610d3ad38c768e124dc7","schema_version":"edge-lab-recorder.raw.v1","sequence":null,"source":"clob_market_ws"}
{"event_at":"2026-07-28T04:12:41.125000Z","event_fingerprint":"0c75a34afe125af424566c43227c605f16c97948919d20a11c1d808a8517ccd0","payload":{"connection_id":"f6725804f86a4c4eb588e4d5ed7db029","event_at":"2026-07-28T04:12:41.125000Z","event_type":"price_change","frame_hash":"3322b1e60eb11a8c2e62b60f31d04d221fd7461ff02730980634575ba103594e","frame_index":0,"kind":"data","monotonic_ns":313944414692500,"payload":{"event_type":"price_change","market":"0xd412ce774cfcf8dc9f71164aac78783978aac7b03871702a3b8a481bd9dc9688","price_changes":[{"asset_id":"96600821790790307414914106093858868634329285205417149685270682748367152458577","best_ask":"0.4","best_bid":"0.38","hash":"35d3e203df7b16873afaf236184325957baab8ba","price":"0.38","side":"BUY","size":"100"},{"asset_id":"107603864457683460275633293642179940881969192120168665300712204232021063124301","best_ask":"0.62","best_bid":"0.6","hash":"66d5926d70c986f58de1252a4e25dc4064881101","price":"0.62","side":"SELL","size":"100"}],"timestamp":"1785211961125"},"payload_hash":"f810a25634edbf27f3abb8c095958c2d9e1349a5024fbe79900330aecc7543b6","raw_frame":"{\"market\":\"0xd412ce774cfcf8dc9f71164aac78783978aac7b03871702a3b8a481bd9dc9688\", \"price_changes\":[{\"asset_id\":\"96600821790790307414914106093858868634329285205417149685270682748367152458577\", \"price\":\"0.38\", \"size\":\"100\", \"side\":\"BUY\", \"hash\":\"35d3e203df7b16873afaf236184325957baab8ba\", \"best_bid\":\"0.38\", \"best_ask\":\"0.4\"}, {\"asset_id\":\"107603864457683460275633293642179940881969192120168665300712204232021063124301\", \"price\":\"0.62\", \"size\":\"100\", \"side\":\"SELL\", \"hash\":\"66d5926d70c986f58de1252a4e25dc4064881101\", \"best_bid\":\"0.6\", \"best_ask\":\"0.62\"}], \"timestamp\":\"1785211961125\", \"event_type\":\"price_change\"}","received_at":"2026-07-28T04:12:41.337172Z","schema_version":"clob-market-ws.price_change.v1","sequence":null,"server_hash":null,"server_timestamp":"1785211961125","session_id":"2d607381e3054cee91998cdf45a4231c","source":"clob_market_ws"},"received_at":"2026-07-28T04:12:41.337172Z","record_id":"0891614fc3b6cba56d27f0d2f721649f4896d2e1892db982b720c7104f14b9f6","schema_fingerprint":"4aa3821a28b0b7c2400bc59aba4bcc0a76e971dadd19610d3ad38c768e124dc7","schema_version":"edge-lab-recorder.raw.v1","sequence":null,"source":"clob_market_ws"}
{"event_at":"2026-07-28T04:12:41.126000Z","event_fingerprint":"e4c7014a4d33412594d835ebb836165c03994a690dab53a8c90975725969a470","payload":{"connection_id":"f6725804f86a4c4eb588e4d5ed7db029","event_at":"2026-07-28T04:12:41.126000Z","event_type":"price_change","frame_hash":"4b0c36417e394b4efb1596d11c6e0c8cb10c2e770cb305718193955da815db0c","frame_index":0,"kind":"data","monotonic_ns":313944419068333,"payload":{"event_type":"price_change","market":"0xd412ce774cfcf8dc9f71164aac78783978aac7b03871702a3b8a481bd9dc9688","price_changes":[{"asset_id":"107603864457683460275633293642179940881969192120168665300712204232021063124301","best_ask":"0.62","best_bid":"0.6","hash":"f5ff9b762d6d7f8a0ab2777c36a9ea241e9331bb","price":"0.59","side":"BUY","size":"45"},{"asset_id":"96600821790790307414914106093858868634329285205417149685270682748367152458577","best_ask":"0.4","best_bid":"0.38","hash":"ff0596b928b79bdd3fa599aaf2c10c851f360573","price":"0.41","side":"SELL","size":"45"}],"timestamp":"1785211961126"},"payload_hash":"88f581a0542fb8c4fe642dea8d93bf8914a9a29fc037775956458ffd5148fcb9","raw_frame":"{\"market\":\"0xd412ce774cfcf8dc9f71164aac78783978aac7b03871702a3b8a481bd9dc9688\", \"price_changes\":[{\"asset_id\":\"107603864457683460275633293642179940881969192120168665300712204232021063124301\", \"price\":\"0.59\", \"size\":\"45\", \"side\":\"BUY\", \"hash\":\"f5ff9b762d6d7f8a0ab2777c36a9ea241e9331bb\", \"best_bid\":\"0.6\", \"best_ask\":\"0.62\"}, {\"asset_id\":\"96600821790790307414914106093858868634329285205417149685270682748367152458577\", \"price\":\"0.41\", \"size\":\"45\", \"side\":\"SELL\", \"hash\":\"ff0596b928b79bdd3fa599aaf2c10c851f360573\", \"best_bid\":\"0.38\", \"best_ask\":\"0.4\"}], \"timestamp\":\"1785211961126\", \"event_type\":\"price_change\"}","received_at":"2026-07-28T04:12:41.341533Z","schema_version":"clob-market-ws.price_change.v1","sequence":null,"server_hash":null,"server_timestamp":"1785211961126","session_id":"2d607381e3054cee91998cdf45a4231c","source":"clob_market_ws"},"received_at":"2026-07-28T04:12:41.341533Z","record_id":"baa1fc3ea1f8f82329872af2d9806fe12a600c79306ea9d677d672af5506bf8b","schema_fingerprint":"4aa3821a28b0b7c2400bc59aba4bcc0a76e971dadd19610d3ad38c768e124dc7","schema_version":"edge-lab-recorder.raw.v1","sequence":null,"source":"clob_market_ws"}
{"event_at":"2026-07-28T04:12:41.130000Z","event_fingerprint":"f6e2b456e7f8cc7bade1a7d34d6f50d0307dbf45f2aa6b1c9da7ec2c665964d7","payload":{"connection_id":"f6725804f86a4c4eb588e4d5ed7db029","event_at":"2026-07-28T04:12:41.130000Z","event_type":"price_change","frame_hash":"b0da8dcaa3eac0a844d54c96bb0f84966ae12a4b8b12e1ea3cb1b43c45501d69","frame_index":0,"kind":"data","monotonic_ns":313944423402500,"payload":{"event_type":"price_change","market":"0xd412ce774cfcf8dc9f71164aac78783978aac7b03871702a3b8a481bd9dc9688","price_changes":[{"asset_id":"96600821790790307414914106093858868634329285205417149685270682748367152458577","best_ask":"0.4","best_bid":"0.38","hash":"fb678f6cdb5fb3d91c8c98b81c5ed1072083f95d","price":"0.37","side":"BUY","size":"91.41"},{"asset_id":"107603864457683460275633293642179940881969192120168665300712204232021063124301","best_ask":"0.62","best_bid":"0.6","hash":"dd3b832c8171f545ba009e8ca83d251c948a161b","price":"0.63","side":"SELL","size":"91.41"}],"timestamp":"1785211961130"},"payload_hash":"06ae43c3b2e18c7934b6292ade34a7d3347e5d8ec952dbbb96d3c1dcc5fb7d26","raw_frame":"{\"market\":\"0xd412ce774cfcf8dc9f71164aac78783978aac7b03871702a3b8a481bd9dc9688\", \"price_changes\":[{\"asset_id\":\"96600821790790307414914106093858868634329285205417149685270682748367152458577\", \"price\":\"0.37\", \"size\":\"91.41\", \"side\":\"BUY\", \"hash\":\"fb678f6cdb5fb3d91c8c98b81c5ed1072083f95d\", \"best_bid\":\"0.38\", \"best_ask\":\"0.4\"}, {\"asset_id\":\"107603864457683460275633293642179940881969192120168665300712204232021063124301\", \"price\":\"0.63\", \"size\":\"91.41\", \"side\":\"SELL\", \"hash\":\"dd3b832c8171f545ba009e8ca83d251c948a161b\", \"best_bid\":\"0.6\", \"best_ask\":\"0.62\"}], \"timestamp\":\"1785211961130\", \"event_type\":\"price_change\"}","received_at":"2026-07-28T04:12:41.345881Z","schema_version":"clob-market-ws.price_change.v1","sequence":null,"server_hash":null,"server_timestamp":"1785211961130","session_id":"2d607381e3054cee91998cdf45a4231c","source":"clob_market_ws"},"received_at":"2026-07-28T04:12:41.345881Z","record_id":"d3ac469c98f01964ec2b14176d4b810cf256cdb4e28c71688793cc372f23a5f1","schema_fingerprint":"4aa3821a28b0b7c2400bc59aba4bcc0a76e971dadd19610d3ad38c768e124dc7","schema_version":"edge-lab-recorder.raw.v1","sequence":null,"source":"clob_market_ws"}
{"event_at":"2026-07-28T04:12:41.137000Z","event_fingerprint":"2635177498be30b54da95425029228ef2b2d403139344bf4afcf76cec46ac9fc","payload":{"connection_id":"f6725804f86a4c4eb588e4d5ed7db029","event_at":"2026-07-28T04:12:41.137000Z","event_type":"price_change","frame_hash":"e4526e215b69e9a2f7f9030c4792790b798e6da95452736fdcee7622a32c750a","frame_index":0,"kind":"data","monotonic_ns":313944427683125,"payload":{"event_type":"price_change","market":"0xd412ce774cfcf8dc9f71164aac78783978aac7b03871702a3b8a481bd9dc9688","price_changes":[{"asset_id":"96600821790790307414914106093858868634329285205417149685270682748367152458577","best_ask":"0.4","best_bid":"0.38","hash":"4e2b79c3d8b7f8cf1a8e51f3cf2c96e8531720bb","price":"0.38","side":"BUY","size":"94"},{"asset_id":"107603864457683460275633293642179940881969192120168665300712204232021063124301","best_ask":"0.62","best_bid":"0.6","hash":"c606b852991c7921084cf1b720ce105ef09b0634","price":"0.62","side":"SELL","size":"94"}],"timestamp":"1785211961137"},"payload_hash":"4c68d84cd68fb1fd6eb115f4ffea0c20253a6f762b5cbee080b62cb75cd41b3a","raw_frame":"{\"market\":\"0xd412ce774cfcf8dc9f71164aac78783978aac7b03871702a3b8a481bd9dc9688\", \"price_changes\":[{\"asset_id\":\"96600821790790307414914106093858868634329285205417149685270682748367152458577\", \"price\":\"0.38\", \"size\":\"94\", \"side\":\"BUY\", \"hash\":\"4e2b79c3d8b7f8cf1a8e51f3cf2c96e8531720bb\", \"best_bid\":\"0.38\", \"best_ask\":\"0.4\"}, {\"asset_id\":\"107603864457683460275633293642179940881969192120168665300712204232021063124301\", \"price\":\"0.62\", \"size\":\"94\", \"side\":\"SELL\", \"hash\":\"c606b852991c7921084cf1b720ce105ef09b0634\", \"best_bid\":\"0.6\", \"best_ask\":\"0.62\"}], \"timestamp\":\"1785211961137\", \"event_type\":\"price_change\"}","received_at":"2026-07-28T04:12:41.350163Z","schema_version":"clob-market-ws.price_change.v1","sequence":null,"server_hash":null,"server_timestamp":"1785211961137","session_id":"2d607381e3054cee91998cdf45a4231c","source":"clob_market_ws"},"received_at":"2026-07-28T04:12:41.350163Z","record_id":"7195a757d5f17c815aa01417b718b895817ac352eb77a18216de1cf8f15525e9","schema_fingerprint":"4aa3821a28b0b7c2400bc59aba4bcc0a76e971dadd19610d3ad38c768e124dc7","schema_version":"edge-lab-recorder.raw.v1","sequence":null,"source":"clob_market_ws"}
{"event_at":"2026-07-28T04:12:41.140000Z","event_fingerprint":"4a74eb9dc612e459a22743826bf932c2fadca6d8dadfdb91053b8f97574aa69d","payload":{"connection_id":"f6725804f86a4c4eb588e4d5ed7db029","event_at":"2026-07-28T04:12:41.140000Z","event_type":"price_change","frame_hash":"4bf951d7765a7c18810e8fb6cd8733b7cbdfc1ba25fe6dae090839fed80bb032","frame_index":0,"kind":"data","monotonic_ns":313944432103916,"payload":{"event_type":"price_change","market":"0xd412ce774cfcf8dc9f71164aac78783978aac7b03871702a3b8a481bd9dc9688","price_changes":[{"asset_id":"107603864457683460275633293642179940881969192120168665300712204232021063124301","best_ask":"0.62","best_bid":"0.6","hash":"fe04bf47174e9e41783c1bd4171749fc499a57a7","price":"0.01","side":"BUY","size":"5335.02"},{"asset_id":"96600821790790307414914106093858868634329285205417149685270682748367152458577","best_ask":"0.4","best_bid":"0.38","hash":"25d807881180f5ef14bd911d8bb3ba795226723b","price":"0.99","side":"SELL","size":"5335.02"}],"timestamp":"1785211961140"},"payload_hash":"1606f0ea8e576a8aa1e62e5f98254de34a8f3d0105fe57458a603f9bc8068353","raw_frame":"{\"market\":\"0xd412ce774cfcf8dc9f71164aac78783978aac7b03871702a3b8a481bd9dc9688\", \"price_changes\":[{\"asset_id\":\"107603864457683460275633293642179940881969192120168665300712204232021063124301\", \"price\":\"0.01\", \"size\":\"5335.02\", \"side\":\"BUY\", \"hash\":\"fe04bf47174e9e41783c1bd4171749fc499a57a7\", \"best_bid\":\"0.6\", \"best_ask\":\"0.62\"}, {\"asset_id\":\"96600821790790307414914106093858868634329285205417149685270682748367152458577\", \"price\":\"0.99\", \"size\":\"5335.02\", \"side\":\"SELL\", \"hash\":\"25d807881180f5ef14bd911d8bb3ba795226723b\", \"best_bid\":\"0.38\", \"best_ask\":\"0.4\"}], \"timestamp\":\"1785211961140\", \"event_type\":\"price_change\"}","received_at":"2026-07-28T04:12:41.354583Z","schema_version":"clob-market-ws.price_change.v1","sequence":null,"server_hash":null,"server_timestamp":"1785211961140","session_id":"2d607381e3054cee91998cdf45a4231c","source":"clob_market_ws"},"received_at":"2026-07-28T04:12:41.354583Z","record_id":"067093909758c7f099af2df8b6cf69ff9141789dadf471d8530fef6c89b9a51b","schema_fingerprint":"4aa3821a28b0b7c2400bc59aba4bcc0a76e971dadd19610d3ad38c768e124dc7","schema_version":"edge-lab-recorder.raw.v1","sequence":null,"source":"clob_market_ws"}
{"event_at":"2026-07-28T04:12:41.141000Z","event_fingerprint":"4c4e48c96bb2f5f083ffe6b211292bb4654dd2a1e65c31aa772fa89c90b553bd","payload":{"connection_id":"f6725804f86a4c4eb588e4d5ed7db029","event_at":"2026-07-28T04:12:41.141000Z","event_type":"price_change","frame_hash":"4555d7967362faaec78429edcb2c5e0474a2766e36385b42062de701e087ae10","frame_index":0,"kind":"data","monotonic_ns":313944436518458,"payload":{"event_type":"price_change","market":"0xd412ce774cfcf8dc9f71164aac78783978aac7b03871702a3b8a481bd9dc9688","price_changes":[{"asset_id":"107603864457683460275633293642179940881969192120168665300712204232021063124301","best_ask":"0.62","best_bid":"0.6","hash":"c7827e2a2f3de30c4424a0073ce9eb62394aafe5","price":"0.4","side":"BUY","size":"45.41"},{"asset_id":"96600821790790307414914106093858868634329285205417149685270682748367152458577","best_ask":"0.4","best_bid":"0.38","hash":"8d433b0bf4afea14eb792cba6bdf4569e66d6fc4","price":"0.6","side":"SELL","size":"45.41"}],"timestamp":"1785211961141"},"payload_hash":"df79722185749f53ff8a960cb46b86ae1a2725f4187ae350c16a7866ca950649","raw_frame":"{\"market\":\"0xd412ce774cfcf8dc9f71164aac78783978aac7b03871702a3b8a481bd9dc9688\", \"price_changes\":[{\"asset_id\":\"107603864457683460275633293642179940881969192120168665300712204232021063124301\", \"price\":\"0.4\", \"size\":\"45.41\", \"side\":\"BUY\", \"hash\":\"c7827e2a2f3de30c4424a0073ce9eb62394aafe5\", \"best_bid\":\"0.6\", \"best_ask\":\"0.62\"}, {\"asset_id\":\"96600821790790307414914106093858868634329285205417149685270682748367152458577\", \"price\":\"0.6\", \"size\":\"45.41\", \"side\":\"SELL\", \"hash\":\"8d433b0bf4afea14eb792cba6bdf4569e66d6fc4\", \"best_bid\":\"0.38\", \"best_ask\":\"0.4\"}], \"timestamp\":\"1785211961141\", \"event_type\":\"price_change\"}","received_at":"2026-07-28T04:12:41.358998Z","schema_version":"clob-market-ws.price_change.v1","sequence":null,"server_hash":null,"server_timestamp":"1785211961141","session_id":"2d607381e3054cee91998cdf45a4231c","source":"clob_market_ws"},"received_at":"2026-07-28T04:12:41.358998Z","record_id":"88b6f2f04ef3015e80a2cc153585d26e95ecd3918efb547c1c5899f95258a53f","schema_fingerprint":"4aa3821a28b0b7c2400bc59aba4bcc0a76e971dadd19610d3ad38c768e124dc7","schema_version":"edge-lab-recorder.raw.v1","sequence":null,"source":"clob_market_ws"}
{"event_at":"2026-07-28T04:12:41.143000Z","event_fingerprint":"1969f99643189f986252ceaae5262cef33ad48d3bd1eb8afdcbaf24ebe423b1f","payload":{"connection_id":"f6725804f86a4c4eb588e4d5ed7db029","event_at":"2026-07-28T04:12:41.143000Z","event_type":"price_change","frame_hash":"f84c28a22f4574d8b2c61dc12e632872366ae94c8196a6a518784087c6f1556b","frame_index":0,"kind":"data","monotonic_ns":313944439833791,"payload":{"event_type":"price_change","market":"0xd412ce774cfcf8dc9f71164aac78783978aac7b03871702a3b8a481bd9dc9688","price_changes":[{"asset_id":"96600821790790307414914106093858868634329285205417149685270682748367152458577","best_ask":"0.4","best_bid":"0.38","hash":"7553688b3adfde38d3f82c5623372440f917f8e4","price":"0.3","side":"BUY","size":"134.19"},{"asset_id":"107603864457683460275633293642179940881969192120168665300712204232021063124301","best_ask":"0.62","best_bid":"0.6","hash":"0d39a165dac15918d2334ac060095b5e54d85184","price":"0.7","side":"SELL","size":"134.19"}],"timestamp":"1785211961143"},"payload_hash":"98a49f0038c1b9e9c59e622780200c87eb396a0bd1c4679f1a3765e6f793fe38","raw_frame":"{\"market\":\"0xd412ce774cfcf8dc9f71164aac78783978aac7b03871702a3b8a481bd9dc9688\", \"price_changes\":[{\"asset_id\":\"96600821790790307414914106093858868634329285205417149685270682748367152458577\", \"price\":\"0.3\", \"size\":\"134.19\", \"side\":\"BUY\", \"hash\":\"7553688b3adfde38d3f82c5623372440f917f8e4\", \"best_bid\":\"0.38\", \"best_ask\":\"0.4\"}, {\"asset_id\":\"107603864457683460275633293642179940881969192120168665300712204232021063124301\", \"price\":\"0.7\", \"size\":\"134.19\", \"side\":\"SELL\", \"hash\":\"0d39a165dac15918d2334ac060095b5e54d85184\", \"best_bid\":\"0.6\", \"best_ask\":\"0.62\"}], \"timestamp\":\"1785211961143\", \"event_type\":\"price_change\"}","received_at":"2026-07-28T04:12:41.362312Z","schema_version":"clob-market-ws.price_change.v1","sequence":null,"server_hash":null,"server_timestamp":"1785211961143","session_id":"2d607381e3054cee91998cdf45a4231c","source":"clob_market_ws"},"received_at":"2026-07-28T04:12:41.362312Z","record_id":"4075ebe6e5a3efecd4ecb43aca8fd07728954e987dca55236969ae0de3f2931f","schema_fingerprint":"4aa3821a28b0b7c2400bc59aba4bcc0a76e971dadd19610d3ad38c768e124dc7","schema_version":"edge-lab-recorder.raw.v1","sequence":null,"source":"clob_market_ws"}
{"event_at":"2026-07-28T04:12:41.145000Z","event_fingerprint":"57c28f6e1da47627ee50e2c6f861562cc2355937bfe958287c2a38e8959d18d5","payload":{"connection_id":"f6725804f86a4c4eb588e4d5ed7db029","event_at":"2026-07-28T04:12:41.145000Z","event_type":"price_change","frame_hash":"b3b8aa1a7178f04c1b03eda0ead5b7968b4407cf0b8a2551632f62b288d006fc","frame_index":0,"kind":"data","monotonic_ns":313944444284333,"payload":{"event_type":"price_change","market":"0xd412ce774cfcf8dc9f71164aac78783978aac7b03871702a3b8a481bd9dc9688","price_changes":[{"asset_id":"107603864457683460275633293642179940881969192120168665300712204232021063124301","best_ask":"0.62","best_bid":"0.6","hash":"ee508ecd4532cebaaa4433324c48205282b3aa8d","price":"0.58","side":"BUY","size":"19"},{"asset_id":"96600821790790307414914106093858868634329285205417149685270682748367152458577","best_ask":"0.4","best_bid":"0.38","hash":"5c4fc0ecef37e6b8527520f12a104f80469ead16","price":"0.42","side":"SELL","size":"19"}],"timestamp":"1785211961145"},"payload_hash":"1c524d83e1b70a5b0cf800aaede2769ea667e8e007c00712aae7ec2d48ece868","raw_frame":"{\"market\":\"0xd412ce774cfcf8dc9f71164aac78783978aac7b03871702a3b8a481bd9dc9688\", \"price_changes\":[{\"asset_id\":\"107603864457683460275633293642179940881969192120168665300712204232021063124301\", \"price\":\"0.58\", \"size\":\"19\", \"side\":\"BUY\", \"hash\":\"ee508ecd4532cebaaa4433324c48205282b3aa8d\", \"best_bid\":\"0.6\", \"best_ask\":\"0.62\"}, {\"asset_id\":\"96600821790790307414914106093858868634329285205417149685270682748367152458577\", \"price\":\"0.42\", \"size\":\"19\", \"side\":\"SELL\", \"hash\":\"5c4fc0ecef37e6b8527520f12a104f80469ead16\", \"best_bid\":\"0.38\", \"best_ask\":\"0.4\"}], \"timestamp\":\"1785211961145\", \"event_type\":\"price_change\"}","received_at":"2026-07-28T04:12:41.366761Z","schema_version":"clob-market-ws.price_change.v1","sequence":null,"server_hash":null,"server_timestamp":"1785211961145","session_id":"2d607381e3054cee91998cdf45a4231c","source":"clob_market_ws"},"received_at":"2026-07-28T04:12:41.366761Z","record_id":"02b6b624930726c4fb7569d1b9c44fbbc7bdd4e6d34602921b39276362a59a3e","schema_fingerprint":"4aa3821a28b0b7c2400bc59aba4bcc0a76e971dadd19610d3ad38c768e124dc7","schema_version":"edge-lab-recorder.raw.v1","sequence":null,"source":"clob_market_ws"}
{"event_at":"2026-07-28T04:12:41.145000Z","event_fingerprint":"7a50d9181cdfe4e992cade6baa712dd8428ba180d0569ef3565e05c2155aa035","payload":{"connection_id":"f6725804f86a4c4eb588e4d5ed7db029","event_at":"2026-07-28T04:12:41.145000Z","event_type":"price_change","frame_hash":"e1bfca66f4e51e590a8ddd521c5baf7ed0080ba3225c4f82f381ff5d5db9f4a1","frame_index":0,"kind":"data","monotonic_ns":313944448932416,"payload":{"event_type":"price_change","market":"0xd412ce774cfcf8dc9f71164aac78783978aac7b03871702a3b8a481bd9dc9688","price_changes":[{"asset_id":"107603864457683460275633293642179940881969192120168665300712204232021063124301","best_ask":"0.62","best_bid":"0.6","hash":"47d61fa3a7f4a6f3c040f271b2874f948c5f06da","price":"0.59","side":"BUY","size":"11"},{"asset_id":"96600821790790307414914106093858868634329285205417149685270682748367152458577","best_ask":"0.4","best_bid":"0.38","hash":"653a932c8f00a1f7e1d85991e85c35965651af5f","price":"0.41","side":"SELL","size":"11"}],"timestamp":"1785211961145"},"payload_hash":"bd22c9f81f9179d7e45254473aa76c1ec6a74e5ee4a9d34c06ac804f8e9c1c42","raw_frame":"{\"market\":\"0xd412ce774cfcf8dc9f71164aac78783978aac7b03871702a3b8a481bd9dc9688\", \"price_changes\":[{\"asset_id\":\"107603864457683460275633293642179940881969192120168665300712204232021063124301\", \"price\":\"0.59\", \"size\":\"11\", \"side\":\"BUY\", \"hash\":\"47d61fa3a7f4a6f3c040f271b2874f948c5f06da\", \"best_bid\":\"0.6\", \"best_ask\":\"0.62\"}, {\"asset_id\":\"96600821790790307414914106093858868634329285205417149685270682748367152458577\", \"price\":\"0.41\", \"size\":\"11\", \"side\":\"SELL\", \"hash\":\"653a932c8f00a1f7e1d85991e85c35965651af5f\", \"best_bid\":\"0.38\", \"best_ask\":\"0.4\"}], \"timestamp\":\"1785211961145\", \"event_type\":\"price_change\"}","received_at":"2026-07-28T04:12:41.371409Z","schema_version":"clob-market-ws.price_change.v1","sequence":null,"server_hash":null,"server_timestamp":"1785211961145","session_id":"2d607381e3054cee91998cdf45a4231c","source":"clob_market_ws"},"received_at":"2026-07-28T04:12:41.371409Z","record_id":"f994eaf7be803ecdcd427ff175e2fa13f9a20e38a0a7826abc6b817aed672b62","schema_fingerprint":"4aa3821a28b0b7c2400bc59aba4bcc0a76e971dadd19610d3ad38c768e124dc7","schema_version":"edge-lab-recorder.raw.v1","sequence":null,"source":"clob_market_ws"}
{"event_at":"2026-07-28T04:12:41.147000Z","event_fingerprint":"49744cde66665f9128bebff21e2c337b65dbc99ba80dee4a7a8f6f2f1c0e3a55","payload":{"connection_id":"f6725804f86a4c4eb588e4d5ed7db029","event_at":"2026-07-28T04:12:41.147000Z","event_type":"price_change","frame_hash":"7e4fbe84e17a967a65c6858df1eae2d3b8a4cd4fe2b957c2025efe42a33bdc3f","frame_index":0,"kind":"data","monotonic_ns":313944453351916,"payload":{"event_type":"price_change","market":"0xd412ce774cfcf8dc9f71164aac78783978aac7b03871702a3b8a481bd9dc9688","price_changes":[{"asset_id":"107603864457683460275633293642179940881969192120168665300712204232021063124301","best_ask":"0.62","best_bid":"0.6","hash":"ee369a91d76dc5ada8bc6e737df58cb1dcccac23","price":"0.01","side":"BUY","size":"5330.02"},{"asset_id":"96600821790790307414914106093858868634329285205417149685270682748367152458577","best_ask":"0.4","best_bid":"0.38","hash":"2e8177203555e6579fae33ae17f3e423607b5f70","price":"0.99","side":"SELL","size":"5330.02"}],"timestamp":"1785211961147"},"payload_hash":"57adcef7d8b7c05e2ef1f308ecac5d680a04c4abc3c094558b0b4eb846192bc2","raw_frame":"{\"market\":\"0xd412ce774cfcf8dc9f71164aac78783978aac7b03871702a3b8a481bd9dc9688\", \"price_changes\":[{\"asset_id\":\"107603864457683460275633293642179940881969192120168665300712204232021063124301\", \"price\":\"0.01\", \"size\":\"5330.02\", \"side\":\"BUY\", \"hash\":\"ee369a91d76dc5ada8bc6e737df58cb1dcccac23\", \"best_bid\":\"0.6\", \"best_ask\":\"0.62\"}, {\"asset_id\":\"96600821790790307414914106093858868634329285205417149685270682748367152458577\", \"price\":\"0.99\", \"size\":\"5330.02\", \"side\":\"SELL\", \"hash\":\"2e8177203555e6579fae33ae17f3e423607b5f70\", \"best_bid\":\"0.38\", \"best_ask\":\"0.4\"}], \"timestamp\":\"1785211961147\", \"event_type\":\"price_change\"}","received_at":"2026-07-28T04:12:41.375830Z","schema_version":"clob-market-ws.price_change.v1","sequence":null,"server_hash":null,"server_timestamp":"1785211961147","session_id":"2d607381e3054cee91998cdf45a4231c","source":"clob_market_ws"},"received_at":"2026-07-28T04:12:41.375830Z","record_id":"234a8618866e71283e7c4cbc295af44b2e4c5f66b807f7d94c4a569f84a76b62","schema_fingerprint":"4aa3821a28b0b7c2400bc59aba4bcc0a76e971dadd19610d3ad38c768e124dc7","schema_version":"edge-lab-recorder.raw.v1","sequence":null,"source":"clob_market_ws"}
{"event_at":"2026-07-28T04:12:41.151000Z","event_fingerprint":"a037bc89be6ae76558626a4abdf32bf1bbe5bc0e652ab833f3e99be607266ba1","payload":{"connection_id":"f6725804f86a4c4eb588e4d5ed7db029","event_at":"2026-07-28T04:12:41.151000Z","event_type":"price_change","frame_hash":"5fe5576cb56ce4e03c7815dd2c50e62536228752ea7a47252cd6e3cd9f672cb6","frame_index":0,"kind":"data","monotonic_ns":313944457786875,"payload":{"event_type":"price_change","market":"0xd412ce774cfcf8dc9f71164aac78783978aac7b03871702a3b8a481bd9dc9688","price_changes":[{"asset_id":"107603864457683460275633293642179940881969192120168665300712204232021063124301","best_ask":"0.62","best_bid":"0.6","hash":"0e977f378729f99316fa78551c47fc82e63ca96f","price":"0.6","side":"BUY","size":"36.12"},{"asset_id":"96600821790790307414914106093858868634329285205417149685270682748367152458577","best_ask":"0.4","best_bid":"0.38","hash":"b85b3a91792dab5736f41e30e203025b1f948740","price":"0.4","side":"SELL","size":"36.12"}],"timestamp":"1785211961151"},"payload_hash":"e9101add2418b11243e664e5b8d56138e56ca462d958b515600099a15cea251c","raw_frame":"{\"market\":\"0xd412ce774cfcf8dc9f71164aac78783978aac7b03871702a3b8a481bd9dc9688\", \"price_changes\":[{\"asset_id\":\"107603864457683460275633293642179940881969192120168665300712204232021063124301\", \"price\":\"0.6\", \"size\":\"36.12\", \"side\":\"BUY\", \"hash\":\"0e977f378729f99316fa78551c47fc82e63ca96f\", \"best_bid\":\"0.6\", \"best_ask\":\"0.62\"}, {\"asset_id\":\"96600821790790307414914106093858868634329285205417149685270682748367152458577\", \"price\":\"0.4\", \"size\":\"36.12\", \"side\":\"SELL\", \"hash\":\"b85b3a91792dab5736f41e30e203025b1f948740\", \"best_bid\":\"0.38\", \"best_ask\":\"0.4\"}], \"timestamp\":\"1785211961151\", \"event_type\":\"price_change\"}","received_at":"2026-07-28T04:12:41.380265Z","schema_version":"clob-market-ws.price_change.v1","sequence":null,"server_hash":null,"server_timestamp":"1785211961151","session_id":"2d607381e3054cee91998cdf45a4231c","source":"clob_market_ws"},"received_at":"2026-07-28T04:12:41.380265Z","record_id":"0d2501890ef38e0981a53f55c913a06094547463cf03a94c6bd080aa8855b705","schema_fingerprint":"4aa3821a28b0b7c2400bc59aba4bcc0a76e971dadd19610d3ad38c768e124dc7","schema_version":"edge-lab-recorder.raw.v1","sequence":null,"source":"clob_market_ws"}
{"event_at":"2026-07-28T04:12:41.162000Z","event_fingerprint":"758a8dcf30951664c4c1a4a4837c489ab6b3c721468b8d63df276611b96df301","payload":{"connection_id":"f6725804f86a4c4eb588e4d5ed7db029","event_at":"2026-07-28T04:12:41.162000Z","event_type":"price_change","frame_hash":"c16f9c7f052c345a9885058adee5080dcbb0e8489c3f90b9303814a10e917127","frame_index":0,"kind":"data","monotonic_ns":313944461797875,"payload":{"event_type":"price_change","market":"0xd412ce774cfcf8dc9f71164aac78783978aac7b03871702a3b8a481bd9dc9688","price_changes":[{"asset_id":"107603864457683460275633293642179940881969192120168665300712204232021063124301","best_ask":"0.62","best_bid":"0.6","hash":"f18793ebaf0870eb3b621118d5b51e8484c126fe","price":"0.58","side":"BUY","size":"53"},{"asset_id":"96600821790790307414914106093858868634329285205417149685270682748367152458577","best_ask":"0.4","best_bid":"0.38","hash":"da799496fe0bd5ce21ab007a13abb45961c43907","price":"0.42","side":"SELL","size":"53"}],"timestamp":"1785211961162"},"payload_hash":"4aa1ecaa227833ec866c0ccc8d863b4e16a3ebba400ea33754d28927d13dc67f","raw_frame":"{\"market\":\"0xd412ce774cfcf8dc9f71164aac78783978aac7b03871702a3b8a481bd9dc9688\", \"price_changes\":[{\"asset_id\":\"107603864457683460275633293642179940881969192120168665300712204232021063124301\", \"price\":\"0.58\", \"size\":\"53\", \"side\":\"BUY\", \"hash\":\"f18793ebaf0870eb3b621118d5b51e8484c126fe\", \"best_bid\":\"0.6\", \"best_ask\":\"0.62\"}, {\"asset_id\":\"96600821790790307414914106093858868634329285205417149685270682748367152458577\", \"price\":\"0.42\", \"size\":\"53\", \"side\":\"SELL\", \"hash\":\"da799496fe0bd5ce21ab007a13abb45961c43907\", \"best_bid\":\"0.38\", \"best_ask\":\"0.4\"}], \"timestamp\":\"1785211961162\", \"event_type\":\"price_change\"}","received_at":"2026-07-28T04:12:41.384277Z","schema_version":"clob-market-ws.price_change.v1","sequence":null,"server_hash":null,"server_timestamp":"1785211961162","session_id":"2d607381e3054cee91998cdf45a4231c","source":"clob_market_ws"},"received_at":"2026-07-28T04:12:41.384277Z","record_id":"00d32f41f4f636e657ea2ffa98c7b8cc0bfcb4b671e01a655de4cb034feedd5a","schema_fingerprint":"4aa3821a28b0b7c2400bc59aba4bcc0a76e971dadd19610d3ad38c768e124dc7","schema_version":"edge-lab-recorder.raw.v1","sequence":null,"source":"clob_market_ws"}
{"event_at":"2026-07-28T04:12:41.184000Z","event_fingerprint":"26f8dd43beae0bee0baa2837c76aa56e16a9ee07f6afcd5e1156ee66f0883796","payload":{"connection_id":"f6725804f86a4c4eb588e4d5ed7db029","event_at":"2026-07-28T04:12:41.184000Z","event_type":"price_change","frame_hash":"070c15e57a6981a12de25478c19844dba72a546ac58fa03df69307c59f2dbd1e","frame_index":0,"kind":"data","monotonic_ns":313944465805875,"payload":{"event_type":"price_change","market":"0xd412ce774cfcf8dc9f71164aac78783978aac7b03871702a3b8a481bd9dc9688","price_changes":[{"asset_id":"96600821790790307414914106093858868634329285205417149685270682748367152458577","best_ask":"0.4","best_bid":"0.38","hash":"d884cea380b6c4b613ab0a435a5752dba86b10e5","price":"0.01","side":"BUY","size":"5300.02"},{"asset_id":"107603864457683460275633293642179940881969192120168665300712204232021063124301","best_ask":"0.62","best_bid":"0.6","hash":"f34cbb459cdfef688c64b726c7770d7d7414690e","price":"0.99","side":"SELL","size":"5300.02"}],"timestamp":"1785211961184"},"payload_hash":"b30d375c71eb45d4c2704f3398fe8216328cbc66515dd7c6d5ea35f8454e7eb4","raw_frame":"{\"market\":\"0xd412ce774cfcf8dc9f71164aac78783978aac7b03871702a3b8a481bd9dc9688\", \"price_changes\":[{\"asset_id\":\"96600821790790307414914106093858868634329285205417149685270682748367152458577\", \"price\":\"0.01\", \"size\":\"5300.02\", \"side\":\"BUY\", \"hash\":\"d884cea380b6c4b613ab0a435a5752dba86b10e5\", \"best_bid\":\"0.38\", \"best_ask\":\"0.4\"}, {\"asset_id\":\"107603864457683460275633293642179940881969192120168665300712204232021063124301\", \"price\":\"0.99\", \"size\":\"5300.02\", \"side\":\"SELL\", \"hash\":\"f34cbb459cdfef688c64b726c7770d7d7414690e\", \"best_bid\":\"0.6\", \"best_ask\":\"0.62\"}], \"timestamp\":\"1785211961184\", \"event_type\":\"price_change\"}","received_at":"2026-07-28T04:12:41.388285Z","schema_version":"clob-market-ws.price_change.v1","sequence":null,"server_hash":null,"server_timestamp":"1785211961184","session_id":"2d607381e3054cee91998cdf45a4231c","source":"clob_market_ws"},"received_at":"2026-07-28T04:12:41.388285Z","record_id":"84c9f5c8d6236478122679a132e69f012578dd90cc6bf2fbfeb8c1f5074fa3b6","schema_fingerprint":"4aa3821a28b0b7c2400bc59aba4bcc0a76e971dadd19610d3ad38c768e124dc7","schema_version":"edge-lab-recorder.raw.v1","sequence":null,"source":"clob_market_ws"}
{"event_at":"2026-07-28T04:12:41.190000Z","event_fingerprint":"ae49ace827032afa35e208398543a50fc5a9a079ec0c3276fd78527367a67a6c","payload":{"connection_id":"f6725804f86a4c4eb588e4d5ed7db029","event_at":"2026-07-28T04:12:41.190000Z","event_type":"price_change","frame_hash":"882d9e3efb65996cae9820a9d6d02e41170f446e1496dd4b9e752180d63bae32","frame_index":0,"kind":"data","monotonic_ns":313944469559833,"payload":{"event_type":"price_change","market":"0xd412ce774cfcf8dc9f71164aac78783978aac7b03871702a3b8a481bd9dc9688","price_changes":[{"asset_id":"96600821790790307414914106093858868634329285205417149685270682748367152458577","best_ask":"0.4","best_bid":"0.38","hash":"868f75bc507c5e07f79c50037764a58e42278dce","price":"0.36","side":"BUY","size":"79"},{"asset_id":"107603864457683460275633293642179940881969192120168665300712204232021063124301","best_ask":"0.62","best_bid":"0.6","hash":"0e9664f3cb7b913deae4996c057006a99bcc0a81","price":"0.64","side":"SELL","size":"79"}],"timestamp":"1785211961190"},"payload_hash":"fb794554914ecd67619ffbe77d60f0f77b0f33c6bca0f5632b668a953f9f2d2b","raw_frame":"{\"market\":\"0xd412ce774cfcf8dc9f71164aac78783978aac7b03871702a3b8a481bd9dc9688\", \"price_changes\":[{\"asset_id\":\"96600821790790307414914106093858868634329285205417149685270682748367152458577\", \"price\":\"0.36\", \"size\":\"79\", \"side\":\"BUY\", \"hash\":\"868f75bc507c5e07f79c50037764a58e42278dce\", \"best_bid\":\"0.38\", \"best_ask\":\"0.4\"}, {\"asset_id\":\"107603864457683460275633293642179940881969192120168665300712204232021063124301\", \"price\":\"0.64\", \"size\":\"79\", \"side\":\"SELL\", \"hash\":\"0e9664f3cb7b913deae4996c057006a99bcc0a81\", \"best_bid\":\"0.6\", \"best_ask\":\"0.62\"}], \"timestamp\":\"1785211961190\", \"event_type\":\"price_change\"}","received_at":"2026-07-28T04:12:41.392038Z","schema_version":"clob-market-ws.price_change.v1","sequence":null,"server_hash":null,"server_timestamp":"1785211961190","session_id":"2d607381e3054cee91998cdf45a4231c","source":"clob_market_ws"},"received_at":"2026-07-28T04:12:41.392038Z","record_id":"8f569638a6f442a68e72115c16a82d396270c8bffe48baf4e2bde463ab15499b","schema_fingerprint":"4aa3821a28b0b7c2400bc59aba4bcc0a76e971dadd19610d3ad38c768e124dc7","schema_version":"edge-lab-recorder.raw.v1","sequence":null,"source":"clob_market_ws"}
{"event_at":"2026-07-28T04:12:41.220000Z","event_fingerprint":"696c9d62a34fd3c5de9ac797a9d2a172ddb2e49a0572f0601c831bd12fb38451","payload":{"connection_id":"f6725804f86a4c4eb588e4d5ed7db029","event_at":"2026-07-28T04:12:41.220000Z","event_type":"price_change","frame_hash":"c9850d0d478480e21b4fcf68c560e4d7671f06a53421860a5abace0767979984","frame_index":0,"kind":"data","monotonic_ns":313944476360250,"payload":{"event_type":"price_change","market":"0xd412ce774cfcf8dc9f71164aac78783978aac7b03871702a3b8a481bd9dc9688","price_changes":[{"asset_id":"107603864457683460275633293642179940881969192120168665300712204232021063124301","best_ask":"0.62","best_bid":"0.6","hash":"b246ed1813ecac19193dcd074247451f449f247d","price":"0.4","side":"BUY","size":"60.41"},{"asset_id":"96600821790790307414914106093858868634329285205417149685270682748367152458577","best_ask":"0.4","best_bid":"0.38","hash":"cf867a5f03eeca9ecb9a10a8fdc4bfd78b90a6c3","price":"0.6","side":"SELL","size":"60.41"}],"timestamp":"1785211961220"},"payload_hash":"3e417959bd12d8a3fa3d8e1ee5c72943ad1645cfafb7eeff78149526d5b237eb","raw_frame":"{\"market\":\"0xd412ce774cfcf8dc9f71164aac78783978aac7b03871702a3b8a481bd9dc9688\", \"price_changes\":[{\"asset_id\":\"107603864457683460275633293642179940881969192120168665300712204232021063124301\", \"price\":\"0.4\", \"size\":\"60.41\", \"side\":\"BUY\", \"hash\":\"b246ed1813ecac19193dcd074247451f449f247d\", \"best_bid\":\"0.6\", \"best_ask\":\"0.62\"}, {\"asset_id\":\"96600821790790307414914106093858868634329285205417149685270682748367152458577\", \"price\":\"0.6\", \"size\":\"60.41\", \"side\":\"SELL\", \"hash\":\"cf867a5f03eeca9ecb9a10a8fdc4bfd78b90a6c3\", \"best_bid\":\"0.38\", \"best_ask\":\"0.4\"}], \"timestamp\":\"1785211961220\", \"event_type\":\"price_change\"}","received_at":"2026-07-28T04:12:41.398839Z","schema_version":"clob-market-ws.price_change.v1","sequence":null,"server_hash":null,"server_timestamp":"1785211961220","session_id":"2d607381e3054cee91998cdf45a4231c","source":"clob_market_ws"},"received_at":"2026-07-28T04:12:41.398839Z","record_id":"8ac9ec9510405ef867f6d174b47834a3b24d84a46cedbfb0982f69a0b9fa736b","schema_fingerprint":"4aa3821a28b0b7c2400bc59aba4bcc0a76e971dadd19610d3ad38c768e124dc7","schema_version":"edge-lab-recorder.raw.v1","sequence":null,"source":"clob_market_ws"}
{"event_at":"2026-07-28T04:12:41.221000Z","event_fingerprint":"182217a664e988a14e0419006fcddd820c2981f0e2871684baebd7149d8b7514","payload":{"connection_id":"f6725804f86a4c4eb588e4d5ed7db029","event_at":"2026-07-28T04:12:41.221000Z","event_type":"price_change","frame_hash":"0e05476f59195c26ac326148f746e92667d1c3ba8f0d3fc43a3dfda960254b71","frame_index":0,"kind":"data","monotonic_ns":313944482182083,"payload":{"event_type":"price_change","market":"0xd412ce774cfcf8dc9f71164aac78783978aac7b03871702a3b8a481bd9dc9688","price_changes":[{"asset_id":"96600821790790307414914106093858868634329285205417149685270682748367152458577","best_ask":"0.4","best_bid":"0.38","hash":"c5702f9ed4faf6e5bd2f4f3c5eb62e2b35bd5bce","price":"0.38","side":"BUY","size":"109"},{"asset_id":"107603864457683460275633293642179940881969192120168665300712204232021063124301","best_ask":"0.62","best_bid":"0.6","hash":"5535064d55a08cfa444e8471468885de4ee5dfcd","price":"0.62","side":"SELL","size":"109"}],"timestamp":"1785211961221"},"payload_hash":"bb0dcda6b3fc834f78f78b8682f80911c816d29ba366da391b3630c0f309dd3f","raw_frame":"{\"market\":\"0xd412ce774cfcf8dc9f71164aac78783978aac7b03871702a3b8a481bd9dc9688\", \"price_changes\":[{\"asset_id\":\"96600821790790307414914106093858868634329285205417149685270682748367152458577\", \"price\":\"0.38\", \"size\":\"109\", \"side\":\"BUY\", \"hash\":\"c5702f9ed4faf6e5bd2f4f3c5eb62e2b35bd5bce\", \"best_bid\":\"0.38\", \"best_ask\":\"0.4\"}, {\"asset_id\":\"107603864457683460275633293642179940881969192120168665300712204232021063124301\", \"price\":\"0.62\", \"size\":\"109\", \"side\":\"SELL\", \"hash\":\"5535064d55a08cfa444e8471468885de4ee5dfcd\", \"best_bid\":\"0.6\", \"best_ask\":\"0.62\"}], \"timestamp\":\"1785211961221\", \"event_type\":\"price_change\"}","received_at":"2026-07-28T04:12:41.404661Z","schema_version":"clob-market-ws.price_change.v1","sequence":null,"server_hash":null,"server_timestamp":"1785211961221","session_id":"2d607381e3054cee91998cdf45a4231c","source":"clob_market_ws"},"received_at":"2026-07-28T04:12:41.404661Z","record_id":"4b97371ab2d6341f3d553d77125318318b4285e57636a5185bce8f6e35641ab9","schema_fingerprint":"4aa3821a28b0b7c2400bc59aba4bcc0a76e971dadd19610d3ad38c768e124dc7","schema_version":"edge-lab-recorder.raw.v1","sequence":null,"source":"clob_market_ws"}
{"event_at":"2026-07-28T04:12:41.246000Z","event_fingerprint":"8133da2063909707d42d04d5056dd8d4208f29450c739893d9064f138770cdbf","payload":{"connection_id":"f6725804f86a4c4eb588e4d5ed7db029","event_at":"2026-07-28T04:12:41.246000Z","event_type":"price_change","frame_hash":"cf83d72e6adf65eaa8455fa0fa73084123929fb4895f5e2e147b04dc3212edfc","frame_index":0,"kind":"data","monotonic_ns":313944495214916,"payload":{"event_type":"price_change","market":"0xd412ce774cfcf8dc9f71164aac78783978aac7b03871702a3b8a481bd9dc9688","price_changes":[{"asset_id":"107603864457683460275633293642179940881969192120168665300712204232021063124301","best_ask":"0.62","best_bid":"0.6","hash":"3afbc40f6bc35a4a8fafbb2cdba32a788bbf9a69","price":"0.01","side":"BUY","size":"5335.02"},{"asset_id":"96600821790790307414914106093858868634329285205417149685270682748367152458577","best_ask":"0.4","best_bid":"0.38","hash":"bca8aa6df0c4757e13ed8d53b54230ae07f4c2ed","price":"0.99","side":"SELL","size":"5335.02"}],"timestamp":"1785211961246"},"payload_hash":"cd8d44f047ae0868cb60187f6a823aa644f0bc9ae07809062ac0cadfc9ccccb3","raw_frame":"{\"market\":\"0xd412ce774cfcf8dc9f71164aac78783978aac7b03871702a3b8a481bd9dc9688\", \"price_changes\":[{\"asset_id\":\"107603864457683460275633293642179940881969192120168665300712204232021063124301\", \"price\":\"0.01\", \"size\":\"5335.02\", \"side\":\"BUY\", \"hash\":\"3afbc40f6bc35a4a8fafbb2cdba32a788bbf9a69\", \"best_bid\":\"0.6\", \"best_ask\":\"0.62\"}, {\"asset_id\":\"96600821790790307414914106093858868634329285205417149685270682748367152458577\", \"price\":\"0.99\", \"size\":\"5335.02\", \"side\":\"SELL\", \"hash\":\"bca8aa6df0c4757e13ed8d53b54230ae07f4c2ed\", \"best_bid\":\"0.38\", \"best_ask\":\"0.4\"}], \"timestamp\":\"1785211961246\", \"event_type\":\"price_change\"}","received_at":"2026-07-28T04:12:41.417691Z","schema_version":"clob-market-ws.price_change.v1","sequence":null,"server_hash":null,"server_timestamp":"1785211961246","session_id":"2d607381e3054cee91998cdf45a4231c","source":"clob_market_ws"},"received_at":"2026-07-28T04:12:41.417691Z","record_id":"8058c605aa7ed317fc65322f90f0f278dbf9485c80647bb01fcb158003fe0e97","schema_fingerprint":"4aa3821a28b0b7c2400bc59aba4bcc0a76e971dadd19610d3ad38c768e124dc7","schema_version":"edge-lab-recorder.raw.v1","sequence":null,"source":"clob_market_ws"}
{"event_at":"2026-07-28T04:12:41.246000Z","event_fingerprint":"0f8a472bcd8a62d89c280d424907979327b53e4165a9b0f5b3388f3b89ff025b","payload":{"connection_id":"f6725804f86a4c4eb588e4d5ed7db029","event_at":"2026-07-28T04:12:41.246000Z","event_type":"price_change","frame_hash":"53b60a4e7219ca0267eea6b5d1871e74a629ead120db1ec8500931ab34aeafda","frame_index":0,"kind":"data","monotonic_ns":313944499133166,"payload":{"event_type":"price_change","market":"0xd412ce774cfcf8dc9f71164aac78783978aac7b03871702a3b8a481bd9dc9688","price_changes":[{"asset_id":"96600821790790307414914106093858868634329285205417149685270682748367152458577","best_ask":"0.4","best_bid":"0.38","hash":"e36e5371aa0dbabd9b693f98b6e1ddd9da3101c9","price":"0.37","side":"BUY","size":"76.41"},{"asset_id":"107603864457683460275633293642179940881969192120168665300712204232021063124301","best_ask":"0.62","best_bid":"0.6","hash":"2de12452f5a3bb4810eb6a2389d2c9c8ef25db2d","price":"0.63","side":"SELL","size":"76.41"}],"timestamp":"1785211961246"},"payload_hash":"36c6997d924874ce95becfabfa360d41e23d44c86d49ab64a77d2490e02cc72d","raw_frame":"{\"market\":\"0xd412ce774cfcf8dc9f71164aac78783978aac7b03871702a3b8a481bd9dc9688\", \"price_changes\":[{\"asset_id\":\"96600821790790307414914106093858868634329285205417149685270682748367152458577\", \"price\":\"0.37\", \"size\":\"76.41\", \"side\":\"BUY\", \"hash\":\"e36e5371aa0dbabd9b693f98b6e1ddd9da3101c9\", \"best_bid\":\"0.38\", \"best_ask\":\"0.4\"}, {\"asset_id\":\"107603864457683460275633293642179940881969192120168665300712204232021063124301\", \"price\":\"0.63\", \"size\":\"76.41\", \"side\":\"SELL\", \"hash\":\"2de12452f5a3bb4810eb6a2389d2c9c8ef25db2d\", \"best_bid\":\"0.6\", \"best_ask\":\"0.62\"}], \"timestamp\":\"1785211961246\", \"event_type\":\"price_change\"}","received_at":"2026-07-28T04:12:41.421610Z","schema_version":"clob-market-ws.price_change.v1","sequence":null,"server_hash":null,"server_timestamp":"1785211961246","session_id":"2d607381e3054cee91998cdf45a4231c","source":"clob_market_ws"},"received_at":"2026-07-28T04:12:41.421610Z","record_id":"2c42f83aded257ba6394d46fe48c04ce03b9632d4302c1bb489fdcb74deca876","schema_fingerprint":"4aa3821a28b0b7c2400bc59aba4bcc0a76e971dadd19610d3ad38c768e124dc7","schema_version":"edge-lab-recorder.raw.v1","sequence":null,"source":"clob_market_ws"}
{"event_at":"2026-07-28T04:12:41.279000Z","event_fingerprint":"a5d2f4d8ad6dd60a67036e7c437901bd9a369437733c4614a63bb372bc8fbbcb","payload":{"connection_id":"f6725804f86a4c4eb588e4d5ed7db029","event_at":"2026-07-28T04:12:41.279000Z","event_type":"price_change","frame_hash":"a6d0520c19e4f98022fd28619da941b0f457d64424a14cb235abe9779ca9e98e","frame_index":0,"kind":"data","monotonic_ns":313944505618375,"payload":{"event_type":"price_change","market":"0xd412ce774cfcf8dc9f71164aac78783978aac7b03871702a3b8a481bd9dc9688","price_changes":[{"asset_id":"96600821790790307414914106093858868634329285205417149685270682748367152458577","best_ask":"0.4","best_bid":"0.38","hash":"d5b2f836030a349ec6c36edeaf6ad25dd6bf66ec","price":"0.36","side":"BUY","size":"94"},{"asset_id":"107603864457683460275633293642179940881969192120168665300712204232021063124301","best_ask":"0.62","best_bid":"0.6","hash":"106acfebdd286546e96c5020126ea20f30d818a2","price":"0.64","side":"SELL","size":"94"}],"timestamp":"1785211961279"},"payload_hash":"c586e39b4d50d7e295cf094657cab75a50ff8baa08d1a41d03e16f89b9b2e9f5","raw_frame":"{\"market\":\"0xd412ce774cfcf8dc9f71164aac78783978aac7b03871702a3b8a481bd9dc9688\", \"price_changes\":[{\"asset_id\":\"96600821790790307414914106093858868634329285205417149685270682748367152458577\", \"price\":\"0.36\", \"size\":\"94\", \"side\":\"BUY\", \"hash\":\"d5b2f836030a349ec6c36edeaf6ad25dd6bf66ec\", \"best_bid\":\"0.38\", \"best_ask\":\"0.4\"}, {\"asset_id\":\"107603864457683460275633293642179940881969192120168665300712204232021063124301\", \"price\":\"0.64\", \"size\":\"94\", \"side\":\"SELL\", \"hash\":\"106acfebdd286546e96c5020126ea20f30d818a2\", \"best_bid\":\"0.6\", \"best_ask\":\"0.62\"}], \"timestamp\":\"1785211961279\", \"event_type\":\"price_change\"}","received_at":"2026-07-28T04:12:41.428096Z","schema_version":"clob-market-ws.price_change.v1","sequence":null,"server_hash":null,"server_timestamp":"1785211961279","session_id":"2d607381e3054cee91998cdf45a4231c","source":"clob_market_ws"},"received_at":"2026-07-28T04:12:41.428096Z","record_id":"dad710b83b14fea85139705e4f95b8e4049ddf652cae8b7b32bbb67078604c59","schema_fingerprint":"4aa3821a28b0b7c2400bc59aba4bcc0a76e971dadd19610d3ad38c768e124dc7","schema_version":"edge-lab-recorder.raw.v1","sequence":null,"source":"clob_market_ws"}
{"event_at":"2026-07-28T04:12:41.288000Z","event_fingerprint":"1de6c1a335fa42744e47a55d4bd0ce0185e3802ef96739437caf90cdf553427e","payload":{"connection_id":"f6725804f86a4c4eb588e4d5ed7db029","event_at":"2026-07-28T04:12:41.288000Z","event_type":"price_change","frame_hash":"4f044c4eab7eb2845710a14430bf221bc8b88b359e7c921369639931c0001e7f","frame_index":0,"kind":"data","monotonic_ns":313944510071458,"payload":{"event_type":"price_change","market":"0xd412ce774cfcf8dc9f71164aac78783978aac7b03871702a3b8a481bd9dc9688","price_changes":[{"asset_id":"96600821790790307414914106093858868634329285205417149685270682748367152458577","best_ask":"0.4","best_bid":"0.38","hash":"0dab22068afe656de7673fccf22f166365d2608b","price":"0.37","side":"BUY","size":"22.41"},{"asset_id":"107603864457683460275633293642179940881969192120168665300712204232021063124301","best_ask":"0.62","best_bid":"0.6","hash":"62edd5287c63d365a3c3afe83078f46fac4391fe","price":"0.63","side":"SELL","size":"22.41"}],"timestamp":"1785211961288"},"payload_hash":"e1751eefd414262806652e2acb371774f775840a7da19a78286e4c70b0046498","raw_frame":"{\"market\":\"0xd412ce774cfcf8dc9f71164aac78783978aac7b03871702a3b8a481bd9dc9688\", \"price_changes\":[{\"asset_id\":\"96600821790790307414914106093858868634329285205417149685270682748367152458577\", \"price\":\"0.37\", \"size\":\"22.41\", \"side\":\"BUY\", \"hash\":\"0dab22068afe656de7673fccf22f166365d2608b\", \"best_bid\":\"0.38\", \"best_ask\":\"0.4\"}, {\"asset_id\":\"107603864457683460275633293642179940881969192120168665300712204232021063124301\", \"price\":\"0.63\", \"size\":\"22.41\", \"side\":\"SELL\", \"hash\":\"62edd5287c63d365a3c3afe83078f46fac4391fe\", \"best_bid\":\"0.6\", \"best_ask\":\"0.62\"}], \"timestamp\":\"1785211961288\", \"event_type\":\"price_change\"}","received_at":"2026-07-28T04:12:41.432549Z","schema_version":"clob-market-ws.price_change.v1","sequence":null,"server_hash":null,"server_timestamp":"1785211961288","session_id":"2d607381e3054cee91998cdf45a4231c","source":"clob_market_ws"},"received_at":"2026-07-28T04:12:41.432549Z","record_id":"fb7bb296e61f5b77d667134f5c8d4f06588f4c1569611ffc42cc088bebdd095c","schema_fingerprint":"4aa3821a28b0b7c2400bc59aba4bcc0a76e971dadd19610d3ad38c768e124dc7","schema_version":"edge-lab-recorder.raw.v1","sequence":null,"source":"clob_market_ws"}
{"event_at":"2026-07-28T04:12:41.288000Z","event_fingerprint":"92465295842ed47243a6ea6ecfa8564d2bba52ea5c97508d1d3425e6be35da9e","payload":{"connection_id":"f6725804f86a4c4eb588e4d5ed7db029","event_at":"2026-07-28T04:12:41.288000Z","event_type":"price_change","frame_hash":"2a064d5c0a77e2df6eb5d332148281d75ec517a4a67bc6c5faa54e2fb7335d04","frame_index":0,"kind":"data","monotonic_ns":313944514417750,"payload":{"event_type":"price_change","market":"0xd412ce774cfcf8dc9f71164aac78783978aac7b03871702a3b8a481bd9dc9688","price_changes":[{"asset_id":"96600821790790307414914106093858868634329285205417149685270682748367152458577","best_ask":"0.4","best_bid":"0.38","hash":"f362fd752b0f67dc6090be787e94bd22ffc36813","price":"0.36","side":"BUY","size":"38"},{"asset_id":"107603864457683460275633293642179940881969192120168665300712204232021063124301","best_ask":"0.62","best_bid":"0.6","hash":"2d7f6dfed3629766c6d6051dce874e04bd734d67","price":"0.64","side":"SELL","size":"38"}],"timestamp":"1785211961288"},"payload_hash":"c3e6b2a74b045eccd464be47977b9481bc4166b576f7a0acd7d710738383d3b9","raw_frame":"{\"market\":\"0xd412ce774cfcf8dc9f71164aac78783978aac7b03871702a3b8a481bd9dc9688\", \"price_changes\":[{\"asset_id\":\"96600821790790307414914106093858868634329285205417149685270682748367152458577\", \"price\":\"0.36\", \"size\":\"38\", \"side\":\"BUY\", \"hash\":\"f362fd752b0f67dc6090be787e94bd22ffc36813\", \"best_bid\":\"0.38\", \"best_ask\":\"0.4\"}, {\"asset_id\":\"107603864457683460275633293642179940881969192120168665300712204232021063124301\", \"price\":\"0.64\", \"size\":\"38\", \"side\":\"SELL\", \"hash\":\"2d7f6dfed3629766c6d6051dce874e04bd734d67\", \"best_bid\":\"0.6\", \"best_ask\":\"0.62\"}], \"timestamp\":\"1785211961288\", \"event_type\":\"price_change\"}","received_at":"2026-07-28T04:12:41.436896Z","schema_version":"clob-market-ws.price_change.v1","sequence":null,"server_hash":null,"server_timestamp":"1785211961288","session_id":"2d607381e3054cee91998cdf45a4231c","source":"clob_market_ws"},"received_at":"2026-07-28T04:12:41.436896Z","record_id":"6cc04197bd20afb3c1c6b423b978b1eb09a71fe425649d77150fa47fee47ca5a","schema_fingerprint":"4aa3821a28b0b7c2400bc59aba4bcc0a76e971dadd19610d3ad38c768e124dc7","schema_version":"edge-lab-recorder.raw.v1","sequence":null,"source":"clob_market_ws"}
{"event_at":"2026-07-28T04:12:41.289000Z","event_fingerprint":"20afa134b2a6c9830044b0d77ecd235e623ced6f41c925a2280ed856a24a4d68","payload":{"connection_id":"f6725804f86a4c4eb588e4d5ed7db029","event_at":"2026-07-28T04:12:41.289000Z","event_type":"price_change","frame_hash":"c376f5beb21a195d33f1202999dd5fd1b992c3c156092867ad5f26b62d4cae26","frame_index":0,"kind":"data","monotonic_ns":313944518750416,"payload":{"event_type":"price_change","market":"0xd412ce774cfcf8dc9f71164aac78783978aac7b03871702a3b8a481bd9dc9688","price_changes":[{"asset_id":"96600821790790307414914106093858868634329285205417149685270682748367152458577","best_ask":"0.4","best_bid":"0.38","hash":"533dafdd82b88d79ef1a7bc3242e1da431fd3f56","price":"0.38","side":"BUY","size":"56"},{"asset_id":"107603864457683460275633293642179940881969192120168665300712204232021063124301","best_ask":"0.62","best_bid":"0.6","hash":"8e448cd0d1506e5b4079ef9bf2cca6f4f556e14a","price":"0.62","side":"SELL","size":"56"}],"timestamp":"1785211961289"},"payload_hash":"809f828f21842092e20f38d962c7293e8fd6227a7652350cb1c40cf0165236fc","raw_frame":"{\"market\":\"0xd412ce774cfcf8dc9f71164aac78783978aac7b03871702a3b8a481bd9dc9688\", \"price_changes\":[{\"asset_id\":\"96600821790790307414914106093858868634329285205417149685270682748367152458577\", \"price\":\"0.38\", \"size\":\"56\", \"side\":\"BUY\", \"hash\":\"533dafdd82b88d79ef1a7bc3242e1da431fd3f56\", \"best_bid\":\"0.38\", \"best_ask\":\"0.4\"}, {\"asset_id\":\"107603864457683460275633293642179940881969192120168665300712204232021063124301\", \"price\":\"0.62\", \"size\":\"56\", \"side\":\"SELL\", \"hash\":\"8e448cd0d1506e5b4079ef9bf2cca6f4f556e14a\", \"best_bid\":\"0.6\", \"best_ask\":\"0.62\"}], \"timestamp\":\"1785211961289\", \"event_type\":\"price_change\"}","received_at":"2026-07-28T04:12:41.441228Z","schema_version":"clob-market-ws.price_change.v1","sequence":null,"server_hash":null,"server_timestamp":"1785211961289","session_id":"2d607381e3054cee91998cdf45a4231c","source":"clob_market_ws"},"received_at":"2026-07-28T04:12:41.441228Z","record_id":"622e3412a30e434d5bd70c45ef845c4e1220177949f58c63f0cea9412d42786d","schema_fingerprint":"4aa3821a28b0b7c2400bc59aba4bcc0a76e971dadd19610d3ad38c768e124dc7","schema_version":"edge-lab-recorder.raw.v1","sequence":null,"source":"clob_market_ws"}
{"event_at":"2026-07-28T04:12:41.291000Z","event_fingerprint":"80d58cdf9d28e02a9a9f1cb59cdc01f0dd1a2cc919b253dc703d5b4b128a996e","payload":{"connection_id":"f6725804f86a4c4eb588e4d5ed7db029","event_at":"2026-07-28T04:12:41.291000Z","event_type":"price_change","frame_hash":"3f61c2b3149f4887b47992b5af7836f25eaaa039586d9d694ef7206c91efc4c7","frame_index":0,"kind":"data","monotonic_ns":313944522748166,"payload":{"event_type":"price_change","market":"0xd412ce774cfcf8dc9f71164aac78783978aac7b03871702a3b8a481bd9dc9688","price_changes":[{"asset_id":"96600821790790307414914106093858868634329285205417149685270682748367152458577","best_ask":"0.4","best_bid":"0.38","hash":"79e1d56ecc483977593eb82289f2c844cd87fc37","price":"0.32","side":"BUY","size":"113.02"},{"asset_id":"107603864457683460275633293642179940881969192120168665300712204232021063124301","best_ask":"0.62","best_bid":"0.6","hash":"d640274eeb8f5d18b3885a9ab22d8ab79d778bd0","price":"0.68","side":"SELL","size":"113.02"}],"timestamp":"1785211961291"},"payload_hash":"790a81075c935e522fa6f10fb7b42dffe7424fa88c73a495a070a31f573774b4","raw_frame":"{\"market\":\"0xd412ce774cfcf8dc9f71164aac78783978aac7b03871702a3b8a481bd9dc9688\", \"price_changes\":[{\"asset_id\":\"96600821790790307414914106093858868634329285205417149685270682748367152458577\", \"price\":\"0.32\", \"size\":\"113.02\", \"side\":\"BUY\", \"hash\":\"79e1d56ecc483977593eb82289f2c844cd87fc37\", \"best_bid\":\"0.38\", \"best_ask\":\"0.4\"}, {\"asset_id\":\"107603864457683460275633293642179940881969192120168665300712204232021063124301\", \"price\":\"0.68\", \"size\":\"113.02\", \"side\":\"SELL\", \"hash\":\"d640274eeb8f5d18b3885a9ab22d8ab79d778bd0\", \"best_bid\":\"0.6\", \"best_ask\":\"0.62\"}], \"timestamp\":\"1785211961291\", \"event_type\":\"price_change\"}","received_at":"2026-07-28T04:12:41.445226Z","schema_version":"clob-market-ws.price_change.v1","sequence":null,"server_hash":null,"server_timestamp":"1785211961291","session_id":"2d607381e3054cee91998cdf45a4231c","source":"clob_market_ws"},"received_at":"2026-07-28T04:12:41.445226Z","record_id":"523c0daa8c2c085d45ffd2e1fc57c9acb683d45646b49b2bde2c42b3f604d3c0","schema_fingerprint":"4aa3821a28b0b7c2400bc59aba4bcc0a76e971dadd19610d3ad38c768e124dc7","schema_version":"edge-lab-recorder.raw.v1","sequence":null,"source":"clob_market_ws"}
{"event_at":"2026-07-28T04:12:41.291000Z","event_fingerprint":"5cd6f38be67c5255ceae621b5188103519b039837f7d6ce78a0f935c7c336934","payload":{"connection_id":"f6725804f86a4c4eb588e4d5ed7db029","event_at":"2026-07-28T04:12:41.291000Z","event_type":"price_change","frame_hash":"0e8d1b79de5ccf796de01b6453be9cd271d79bd82be1ec5b5e4e0a58b5ef47a2","frame_index":0,"kind":"data","monotonic_ns":313944527038833,"payload":{"event_type":"price_change","market":"0xd412ce774cfcf8dc9f71164aac78783978aac7b03871702a3b8a481bd9dc9688","price_changes":[{"asset_id":"107603864457683460275633293642179940881969192120168665300712204232021063124301","best_ask":"0.62","best_bid":"0.6","hash":"1f7fa6c506788538444c1d2eede1264a3eb2dd46","price":"0.58","side":"BUY","size":"19"},{"asset_id":"96600821790790307414914106093858868634329285205417149685270682748367152458577","best_ask":"0.4","best_bid":"0.38","hash":"d0e53c84b50be34f64df9aa3679f11be01c4085f","price":"0.42","side":"SELL","size":"19"}],"timestamp":"1785211961291"},"payload_hash":"7149ffbae5a4bedf50202f4411b0c1b7d95e478304551d64fd4059270d1573ff","raw_frame":"{\"market\":\"0xd412ce774cfcf8dc9f71164aac78783978aac7b03871702a3b8a481bd9dc9688\", \"price_changes\":[{\"asset_id\":\"107603864457683460275633293642179940881969192120168665300712204232021063124301\", \"price\":\"0.58\", \"size\":\"19\", \"side\":\"BUY\", \"hash\":\"1f7fa6c506788538444c1d2eede1264a3eb2dd46\", \"best_bid\":\"0.6\", \"best_ask\":\"0.62\"}, {\"asset_id\":\"96600821790790307414914106093858868634329285205417149685270682748367152458577\", \"price\":\"0.42\", \"size\":\"19\", \"side\":\"SELL\", \"hash\":\"d0e53c84b50be34f64df9aa3679f11be01c4085f\", \"best_bid\":\"0.38\", \"best_ask\":\"0.4\"}], \"timestamp\":\"1785211961291\", \"event_type\":\"price_change\"}","received_at":"2026-07-28T04:12:41.449517Z","schema_version":"clob-market-ws.price_change.v1","sequence":null,"server_hash":null,"server_timestamp":"1785211961291","session_id":"2d607381e3054cee91998cdf45a4231c","source":"clob_market_ws"},"received_at":"2026-07-28T04:12:41.449517Z","record_id":"144e678937d03f828e1641e45e4dc3b8b55670eb3ed839cb5cee1e3a459a8fee","schema_fingerprint":"4aa3821a28b0b7c2400bc59aba4bcc0a76e971dadd19610d3ad38c768e124dc7","schema_version":"edge-lab-recorder.raw.v1","sequence":null,"source":"clob_market_ws"}
{"event_at":"2026-07-28T04:12:41.293000Z","event_fingerprint":"379f54ce8b9d369952cfd3a2b080c3a7f58c98b516bff3bb12c63c335db673fc","payload":{"connection_id":"f6725804f86a4c4eb588e4d5ed7db029","event_at":"2026-07-28T04:12:41.293000Z","event_type":"price_change","frame_hash":"73b1e8d10a130c8407a8a9cad6b4b22d963de5e2118b434d48271d302c14b4b3","frame_index":0,"kind":"data","monotonic_ns":313944531399750,"payload":{"event_type":"price_change","market":"0xd412ce774cfcf8dc9f71164aac78783978aac7b03871702a3b8a481bd9dc9688","price_changes":[{"asset_id":"107603864457683460275633293642179940881969192120168665300712204232021063124301","best_ask":"0.62","best_bid":"0.6","hash":"218bbf78f62d8bb24b7ae275bbb3c11e16b4fe1d","price":"0.59","side":"BUY","size":"45"},{"asset_id":"96600821790790307414914106093858868634329285205417149685270682748367152458577","best_ask":"0.4","best_bid":"0.38","hash":"7ffca8e1babeabafe9bddcb5f3d0344bf886a7da","price":"0.41","side":"SELL","size":"45"}],"timestamp":"1785211961293"},"payload_hash":"c189c969507c4fbc2b4129fdb21a273ab5a260caedfad65e1c8fc7bfda3eca92","raw_frame":"{\"market\":\"0xd412ce774cfcf8dc9f71164aac78783978aac7b03871702a3b8a481bd9dc9688\", \"price_changes\":[{\"asset_id\":\"107603864457683460275633293642179940881969192120168665300712204232021063124301\", \"price\":\"0.59\", \"size\":\"45\", \"side\":\"BUY\", \"hash\":\"218bbf78f62d8bb24b7ae275bbb3c11e16b4fe1d\", \"best_bid\":\"0.6\", \"best_ask\":\"0.62\"}, {\"asset_id\":\"96600821790790307414914106093858868634329285205417149685270682748367152458577\", \"price\":\"0.41\", \"size\":\"45\", \"side\":\"SELL\", \"hash\":\"7ffca8e1babeabafe9bddcb5f3d0344bf886a7da\", \"best_bid\":\"0.38\", \"best_ask\":\"0.4\"}], \"timestamp\":\"1785211961293\", \"event_type\":\"price_change\"}","received_at":"2026-07-28T04:12:41.453878Z","schema_version":"clob-market-ws.price_change.v1","sequence":null,"server_hash":null,"server_timestamp":"1785211961293","session_id":"2d607381e3054cee91998cdf45a4231c","source":"clob_market_ws"},"received_at":"2026-07-28T04:12:41.453878Z","record_id":"a4431c0049f981facbbe545a57b87de3dfb2f9ff5cc1b1f6a2c26c096e8df1b3","schema_fingerprint":"4aa3821a28b0b7c2400bc59aba4bcc0a76e971dadd19610d3ad38c768e124dc7","schema_version":"edge-lab-recorder.raw.v1","sequence":null,"source":"clob_market_ws"}
{"event_at":"2026-07-28T04:12:41.295000Z","event_fingerprint":"3c8bd192d48a34c82239092b78db875d26658db2e95bbeda2da2d87bf53ef6cb","payload":{"connection_id":"f6725804f86a4c4eb588e4d5ed7db029","event_at":"2026-07-28T04:12:41.295000Z","event_type":"price_change","frame_hash":"6f53a12db3b92073f8975c2ea454f05e9686e346f37ab3d32b1d83c2d58572b2","frame_index":0,"kind":"data","monotonic_ns":313944535740333,"payload":{"event_type":"price_change","market":"0xd412ce774cfcf8dc9f71164aac78783978aac7b03871702a3b8a481bd9dc9688","price_changes":[{"asset_id":"96600821790790307414914106093858868634329285205417149685270682748367152458577","best_ask":"0.4","best_bid":"0.38","hash":"43bc3ed945f3c5e256c6cfbd17405f58cdb6701a","price":"0.38","side":"BUY","size":"109"},{"asset_id":"107603864457683460275633293642179940881969192120168665300712204232021063124301","best_ask":"0.62","best_bid":"0.6","hash":"7792eb6e8ac959b4bf967a088cae65d8236d8f1d","price":"0.62","side":"SELL","size":"109"}],"timestamp":"1785211961295"},"payload_hash":"356075dfb8c7c1bd5e2f504d1f3710441059ea274243bce903f56e3765530e15","raw_frame":"{\"market\":\"0xd412ce774cfcf8dc9f71164aac78783978aac7b03871702a3b8a481bd9dc9688\", \"price_changes\":[{\"asset_id\":\"96600821790790307414914106093858868634329285205417149685270682748367152458577\", \"price\":\"0.38\", \"size\":\"109\", \"side\":\"BUY\", \"hash\":\"43bc3ed945f3c5e256c6cfbd17405f58cdb6701a\", \"best_bid\":\"0.38\", \"best_ask\":\"0.4\"}, {\"asset_id\":\"107603864457683460275633293642179940881969192120168665300712204232021063124301\", \"price\":\"0.62\", \"size\":\"109\", \"side\":\"SELL\", \"hash\":\"7792eb6e8ac959b4bf967a088cae65d8236d8f1d\", \"best_bid\":\"0.6\", \"best_ask\":\"0.62\"}], \"timestamp\":\"1785211961295\", \"event_type\":\"price_change\"}","received_at":"2026-07-28T04:12:41.458218Z","schema_version":"clob-market-ws.price_change.v1","sequence":null,"server_hash":null,"server_timestamp":"1785211961295","session_id":"2d607381e3054cee91998cdf45a4231c","source":"clob_market_ws"},"received_at":"2026-07-28T04:12:41.458218Z","record_id":"e21994ce68ca4e287499bb828331c7c95b63738e7a4ed5ecb105e7aa719d576a","schema_fingerprint":"4aa3821a28b0b7c2400bc59aba4bcc0a76e971dadd19610d3ad38c768e124dc7","schema_version":"edge-lab-recorder.raw.v1","sequence":null,"source":"clob_market_ws"}
{"event_at":"2026-07-28T04:12:41.299000Z","event_fingerprint":"f3bfb759a76e4019b5beef0bf4eb5c7e4c34c99a0f3521a060da670a9af494d8","payload":{"connection_id":"f6725804f86a4c4eb588e4d5ed7db029","event_at":"2026-07-28T04:12:41.299000Z","event_type":"price_change","frame_hash":"749eca77fa66f50da10f548716a89508d848b2257e767cddc835d49600406098","frame_index":0,"kind":"data","monotonic_ns":313944540036416,"payload":{"event_type":"price_change","market":"0xd412ce774cfcf8dc9f71164aac78783978aac7b03871702a3b8a481bd9dc9688","price_changes":[{"asset_id":"96600821790790307414914106093858868634329285205417149685270682748367152458577","best_ask":"0.4","best_bid":"0.38","hash":"20b4aac01ea3e47487d307a161fd5c5580c3ea0f","price":"0.37","side":"BUY","size":"76.41"},{"asset_id":"107603864457683460275633293642179940881969192120168665300712204232021063124301","best_ask":"0.62","best_bid":"0.6","hash":"48d7ef4bb22506b75e85b81443fc3b575c49dc8e","price":"0.63","side":"SELL","size":"76.41"}],"timestamp":"1785211961299"},"payload_hash":"cd2d5274c39df225348e0b3398dc9505d28bd609df01f6d0dc2a739f30900170","raw_frame":"{\"market\":\"0xd412ce774cfcf8dc9f71164aac78783978aac7b03871702a3b8a481bd9dc9688\", \"price_changes\":[{\"asset_id\":\"96600821790790307414914106093858868634329285205417149685270682748367152458577\", \"price\":\"0.37\", \"size\":\"76.41\", \"side\":\"BUY\", \"hash\":\"20b4aac01ea3e47487d307a161fd5c5580c3ea0f\", \"best_bid\":\"0.38\", \"best_ask\":\"0.4\"}, {\"asset_id\":\"107603864457683460275633293642179940881969192120168665300712204232021063124301\", \"price\":\"0.63\", \"size\":\"76.41\", \"side\":\"SELL\", \"hash\":\"48d7ef4bb22506b75e85b81443fc3b575c49dc8e\", \"best_bid\":\"0.6\", \"best_ask\":\"0.62\"}], \"timestamp\":\"1785211961299\", \"event_type\":\"price_change\"}","received_at":"2026-07-28T04:12:41.462514Z","schema_version":"clob-market-ws.price_change.v1","sequence":null,"server_hash":null,"server_timestamp":"1785211961299","session_id":"2d607381e3054cee91998cdf45a4231c","source":"clob_market_ws"},"received_at":"2026-07-28T04:12:41.462514Z","record_id":"8d509cfa87636fcb6596c321f2f0a1a8d8145ef4033fd0c4b767a5726f8680dd","schema_fingerprint":"4aa3821a28b0b7c2400bc59aba4bcc0a76e971dadd19610d3ad38c768e124dc7","schema_version":"edge-lab-recorder.raw.v1","sequence":null,"source":"clob_market_ws"}
{"event_at":"2026-07-28T04:12:41.299000Z","event_fingerprint":"b98eb9736262ddc6a89b488b5cba4d0a330ace92727b5880dfe176bce015a794","payload":{"connection_id":"f6725804f86a4c4eb588e4d5ed7db029","event_at":"2026-07-28T04:12:41.299000Z","event_type":"price_change","frame_hash":"52f0caad4e47814dd54cba77009b804bffa4b611c341de6f3adb67451b0bff3c","frame_index":0,"kind":"data","monotonic_ns":313944544348083,"payload":{"event_type":"price_change","market":"0xd412ce774cfcf8dc9f71164aac78783978aac7b03871702a3b8a481bd9dc9688","price_changes":[{"asset_id":"107603864457683460275633293642179940881969192120168665300712204232021063124301","best_ask":"0.62","best_bid":"0.6","hash":"7565073bc07c3f2712832a0d1e6c27481968ff93","price":"0.58","side":"BUY","size":"53"},{"asset_id":"96600821790790307414914106093858868634329285205417149685270682748367152458577","best_ask":"0.4","best_bid":"0.38","hash":"ce76c33389c44330ad261300535f93317ca5044d","price":"0.42","side":"SELL","size":"53"}],"timestamp":"1785211961299"},"payload_hash":"627a48169ccedbd97b958d0f99350be7da08715375e9561057743b3e376a965c","raw_frame":"{\"market\":\"0xd412ce774cfcf8dc9f71164aac78783978aac7b03871702a3b8a481bd9dc9688\", \"price_changes\":[{\"asset_id\":\"107603864457683460275633293642179940881969192120168665300712204232021063124301\", \"price\":\"0.58\", \"size\":\"53\", \"side\":\"BUY\", \"hash\":\"7565073bc07c3f2712832a0d1e6c27481968ff93\", \"best_bid\":\"0.6\", \"best_ask\":\"0.62\"}, {\"asset_id\":\"96600821790790307414914106093858868634329285205417149685270682748367152458577\", \"price\":\"0.42\", \"size\":\"53\", \"side\":\"SELL\", \"hash\":\"ce76c33389c44330ad261300535f93317ca5044d\", \"best_bid\":\"0.38\", \"best_ask\":\"0.4\"}], \"timestamp\":\"1785211961299\", \"event_type\":\"price_change\"}","received_at":"2026-07-28T04:12:41.466825Z","schema_version":"clob-market-ws.price_change.v1","sequence":null,"server_hash":null,"server_timestamp":"1785211961299","session_id":"2d607381e3054cee91998cdf45a4231c","source":"clob_market_ws"},"received_at":"2026-07-28T04:12:41.466825Z","record_id":"94f9bad70c7f9b1cc43bf0dc5b413109908c55920e187d172b6a96cc88ade530","schema_fingerprint":"4aa3821a28b0b7c2400bc59aba4bcc0a76e971dadd19610d3ad38c768e124dc7","schema_version":"edge-lab-recorder.raw.v1","sequence":null,"source":"clob_market_ws"}
{"event_at":"2026-07-28T04:12:41.302000Z","event_fingerprint":"25072be0bebde7faec64dc716f27419ef518faffd68c22b2f7791890e4696e3a","payload":{"connection_id":"f6725804f86a4c4eb588e4d5ed7db029","event_at":"2026-07-28T04:12:41.302000Z","event_type":"price_change","frame_hash":"50422c66ec6ae04884d1df88b8345808260520dbfcb19a841b23ee1549f96526","frame_index":0,"kind":"data","monotonic_ns":313944548072666,"payload":{"event_type":"price_change","market":"0xd412ce774cfcf8dc9f71164aac78783978aac7b03871702a3b8a481bd9dc9688","price_changes":[{"asset_id":"96600821790790307414914106093858868634329285205417149685270682748367152458577","best_ask":"0.4","best_bid":"0.38","hash":"80e4308b7396c261c80287cd9668a0587a0e6000","price":"0.36","side":"BUY","size":"94"},{"asset_id":"107603864457683460275633293642179940881969192120168665300712204232021063124301","best_ask":"0.62","best_bid":"0.6","hash":"197f44e8f7a3e0271d6daa5a15cb1a179662c2b8","price":"0.64","side":"SELL","size":"94"}],"timestamp":"1785211961302"},"payload_hash":"31ff7c20ef9fa60fd4158bd21521274c127b53c6d43bec02ff2920799ac2cc34","raw_frame":"{\"market\":\"0xd412ce774cfcf8dc9f71164aac78783978aac7b03871702a3b8a481bd9dc9688\", \"price_changes\":[{\"asset_id\":\"96600821790790307414914106093858868634329285205417149685270682748367152458577\", \"price\":\"0.36\", \"size\":\"94\", \"side\":\"BUY\", \"hash\":\"80e4308b7396c261c80287cd9668a0587a0e6000\", \"best_bid\":\"0.38\", \"best_ask\":\"0.4\"}, {\"asset_id\":\"107603864457683460275633293642179940881969192120168665300712204232021063124301\", \"price\":\"0.64\", \"size\":\"94\", \"side\":\"SELL\", \"hash\":\"197f44e8f7a3e0271d6daa5a15cb1a179662c2b8\", \"best_bid\":\"0.6\", \"best_ask\":\"0.62\"}], \"timestamp\":\"1785211961302\", \"event_type\":\"price_change\"}","received_at":"2026-07-28T04:12:41.470551Z","schema_version":"clob-market-ws.price_change.v1","sequence":null,"server_hash":null,"server_timestamp":"1785211961302","session_id":"2d607381e3054cee91998cdf45a4231c","source":"clob_market_ws"},"received_at":"2026-07-28T04:12:41.470551Z","record_id":"ecb3cf60a6981b41bc4e26f59aa4c9f47bc9eb1d41167436d9476762156ea042","schema_fingerprint":"4aa3821a28b0b7c2400bc59aba4bcc0a76e971dadd19610d3ad38c768e124dc7","schema_version":"edge-lab-recorder.raw.v1","sequence":null,"source":"clob_market_ws"}
{"event_at":"2026-07-28T04:12:41.308000Z","event_fingerprint":"9c04656628375923ead20692f2dc6d6372cbafd7b8c840d6082b1d4acadfdbeb","payload":{"connection_id":"f6725804f86a4c4eb588e4d5ed7db029","event_at":"2026-07-28T04:12:41.308000Z","event_type":"price_change","frame_hash":"4500cae32413bb7690d863e7ec529db2249903606104a691ae30e91a7c830f86","frame_index":0,"kind":"data","monotonic_ns":313944554783583,"payload":{"event_type":"price_change","market":"0xd412ce774cfcf8dc9f71164aac78783978aac7b03871702a3b8a481bd9dc9688","price_changes":[{"asset_id":"107603864457683460275633293642179940881969192120168665300712204232021063124301","best_ask":"0.62","best_bid":"0.6","hash":"0edd6a2aa2e354ecf31724672dbe51ac706b4183","price":"0.01","side":"BUY","size":"5330.02"},{"asset_id":"96600821790790307414914106093858868634329285205417149685270682748367152458577","best_ask":"0.4","best_bid":"0.38","hash":"fee6d478158778ec020b969fc9ab447cba3a9e70","price":"0.99","side":"SELL","size":"5330.02"}],"timestamp":"1785211961308"},"payload_hash":"e7c7cfa5429496c7b044b653d1bf10ef66c4f155702a4aeff7060e646abe5fd0","raw_frame":"{\"market\":\"0xd412ce774cfcf8dc9f71164aac78783978aac7b03871702a3b8a481bd9dc9688\", \"price_changes\":[{\"asset_id\":\"107603864457683460275633293642179940881969192120168665300712204232021063124301\", \"price\":\"0.01\", \"size\":\"5330.02\", \"side\":\"BUY\", \"hash\":\"0edd6a2aa2e354ecf31724672dbe51ac706b4183\", \"best_bid\":\"0.6\", \"best_ask\":\"0.62\"}, {\"asset_id\":\"96600821790790307414914106093858868634329285205417149685270682748367152458577\", \"price\":\"0.99\", \"size\":\"5330.02\", \"side\":\"SELL\", \"hash\":\"fee6d478158778ec020b969fc9ab447cba3a9e70\", \"best_bid\":\"0.38\", \"best_ask\":\"0.4\"}], \"timestamp\":\"1785211961308\", \"event_type\":\"price_change\"}","received_at":"2026-07-28T04:12:41.477262Z","schema_version":"clob-market-ws.price_change.v1","sequence":null,"server_hash":null,"server_timestamp":"1785211961308","session_id":"2d607381e3054cee91998cdf45a4231c","source":"clob_market_ws"},"received_at":"2026-07-28T04:12:41.477262Z","record_id":"8bf9848a0a0a38426622e9f27397b313da8e1acaf1a26d329a9f5ad3bf81cb67","schema_fingerprint":"4aa3821a28b0b7c2400bc59aba4bcc0a76e971dadd19610d3ad38c768e124dc7","schema_version":"edge-lab-recorder.raw.v1","sequence":null,"source":"clob_market_ws"}
{"event_at":"2026-07-28T04:12:41.313000Z","event_fingerprint":"c04a367dcea9970f4ce7b5b31450e28866eb321671a179c26c51ee5364b7397f","payload":{"connection_id":"f6725804f86a4c4eb588e4d5ed7db029","event_at":"2026-07-28T04:12:41.313000Z","event_type":"price_change","frame_hash":"29b7f2245b6ee8b0269119d2a812dab69d830d3335085118043c4b595434f53a","frame_index":0,"kind":"data","monotonic_ns":313944559200875,"payload":{"event_type":"price_change","market":"0xd412ce774cfcf8dc9f71164aac78783978aac7b03871702a3b8a481bd9dc9688","price_changes":[{"asset_id":"107603864457683460275633293642179940881969192120168665300712204232021063124301","best_ask":"0.62","best_bid":"0.6","hash":"beb6f43c20a053e77c86b9ede6a665e1cb6f59b6","price":"0.6","side":"BUY","size":"69.12"},{"asset_id":"96600821790790307414914106093858868634329285205417149685270682748367152458577","best_ask":"0.4","best_bid":"0.38","hash":"dbc30936e84645c04df854c405ed959eaa154403","price":"0.4","side":"SELL","size":"69.12"}],"timestamp":"1785211961313"},"payload_hash":"ca27b95a5f5d0925a81b0000896e5523f954c058ce5ed53543ce4644590d9a33","raw_frame":"{\"market\":\"0xd412ce774cfcf8dc9f71164aac78783978aac7b03871702a3b8a481bd9dc9688\", \"price_changes\":[{\"asset_id\":\"107603864457683460275633293642179940881969192120168665300712204232021063124301\", \"price\":\"0.6\", \"size\":\"69.12\", \"side\":\"BUY\", \"hash\":\"beb6f43c20a053e77c86b9ede6a665e1cb6f59b6\", \"best_bid\":\"0.6\", \"best_ask\":\"0.62\"}, {\"asset_id\":\"96600821790790307414914106093858868634329285205417149685270682748367152458577\", \"price\":\"0.4\", \"size\":\"69.12\", \"side\":\"SELL\", \"hash\":\"dbc30936e84645c04df854c405ed959eaa154403\", \"best_bid\":\"0.38\", \"best_ask\":\"0.4\"}], \"timestamp\":\"1785211961313\", \"event_type\":\"price_change\"}","received_at":"2026-07-28T04:12:41.481678Z","schema_version":"clob-market-ws.price_change.v1","sequence":null,"server_hash":null,"server_timestamp":"1785211961313","session_id":"2d607381e3054cee91998cdf45a4231c","source":"clob_market_ws"},"received_at":"2026-07-28T04:12:41.481678Z","record_id":"03a3941fa988a917d8bb9381b63d317b557ffd280835db0c275f6508e0f9dafc","schema_fingerprint":"4aa3821a28b0b7c2400bc59aba4bcc0a76e971dadd19610d3ad38c768e124dc7","schema_version":"edge-lab-recorder.raw.v1","sequence":null,"source":"clob_market_ws"}
{"event_at":"2026-07-28T04:12:41.318000Z","event_fingerprint":"ba6d2fa0ee2f9ab74ed3dbae06cf13ca2dabeea6ee7b99776ca89445d4acfaa5","payload":{"connection_id":"f6725804f86a4c4eb588e4d5ed7db029","event_at":"2026-07-28T04:12:41.318000Z","event_type":"price_change","frame_hash":"3e682d057c853317038d3ece5cde44bdfa99e81282aa9b190f4c69593ae308ad","frame_index":0,"kind":"data","monotonic_ns":313944564015958,"payload":{"event_type":"price_change","market":"0xd412ce774cfcf8dc9f71164aac78783978aac7b03871702a3b8a481bd9dc9688","price_changes":[{"asset_id":"107603864457683460275633293642179940881969192120168665300712204232021063124301","best_ask":"0.62","best_bid":"0.6","hash":"14b6a56a1b022431717fc7b3e91bd62a9ede6c88","price":"0.59","side":"BUY","size":"11"},{"asset_id":"96600821790790307414914106093858868634329285205417149685270682748367152458577","best_ask":"0.4","best_bid":"0.38","hash":"c7a39f09e4b6e7dac941ca2b874a63c96f18563b","price":"0.41","side":"SELL","size":"11"}],"timestamp":"1785211961318"},"payload_hash":"177be0df864e04467be77cb81430bca4454d1c01ae9a078fe8e3dba6dbd8a73f","raw_frame":"{\"market\":\"0xd412ce774cfcf8dc9f71164aac78783978aac7b03871702a3b8a481bd9dc9688\", \"price_changes\":[{\"asset_id\":\"107603864457683460275633293642179940881969192120168665300712204232021063124301\", \"price\":\"0.59\", \"size\":\"11\", \"side\":\"BUY\", \"hash\":\"14b6a56a1b022431717fc7b3e91bd62a9ede6c88\", \"best_bid\":\"0.6\", \"best_ask\":\"0.62\"}, {\"asset_id\":\"96600821790790307414914106093858868634329285205417149685270682748367152458577\", \"price\":\"0.41\", \"size\":\"11\", \"side\":\"SELL\", \"hash\":\"c7a39f09e4b6e7dac941ca2b874a63c96f18563b\", \"best_bid\":\"0.38\", \"best_ask\":\"0.4\"}], \"timestamp\":\"1785211961318\", \"event_type\":\"price_change\"}","received_at":"2026-07-28T04:12:41.486494Z","schema_version":"clob-market-ws.price_change.v1","sequence":null,"server_hash":null,"server_timestamp":"1785211961318","session_id":"2d607381e3054cee91998cdf45a4231c","source":"clob_market_ws"},"received_at":"2026-07-28T04:12:41.486494Z","record_id":"aa9f16383b855085047a2b26f32224f67d6b3e29ccc3420103637d5045cc3a7b","schema_fingerprint":"4aa3821a28b0b7c2400bc59aba4bcc0a76e971dadd19610d3ad38c768e124dc7","schema_version":"edge-lab-recorder.raw.v1","sequence":null,"source":"clob_market_ws"}
{"event_at":"2026-07-28T04:12:41.326000Z","event_fingerprint":"68db4271c4472e9eb1d2b8eb217e9be72eaa2e7adb13916f493ad350aff16fa8","payload":{"connection_id":"f6725804f86a4c4eb588e4d5ed7db029","event_at":"2026-07-28T04:12:41.326000Z","event_type":"price_change","frame_hash":"fa280526d0345735f6bd54a12eed08be6724c2bf31d2b63bbcc28ee534537425","frame_index":0,"kind":"data","monotonic_ns":313944568354833,"payload":{"event_type":"price_change","market":"0xd412ce774cfcf8dc9f71164aac78783978aac7b03871702a3b8a481bd9dc9688","price_changes":[{"asset_id":"107603864457683460275633293642179940881969192120168665300712204232021063124301","best_ask":"0.62","best_bid":"0.6","hash":"6a18caa3cba737472f827f4182e532797b532cba","price":"0.01","side":"BUY","size":"5335.02"},{"asset_id":"96600821790790307414914106093858868634329285205417149685270682748367152458577","best_ask":"0.4","best_bid":"0.38","hash":"c56b958a10d03244f06baabc6e37708d55ef7f61","price":"0.99","side":"SELL","size":"5335.02"}],"timestamp":"1785211961326"},"payload_hash":"481cef519ef99d41942978362050ce1540f3118ea1f43669587254c6b98a2ac5","raw_frame":"{\"market\":\"0xd412ce774cfcf8dc9f71164aac78783978aac7b03871702a3b8a481bd9dc9688\", \"price_changes\":[{\"asset_id\":\"107603864457683460275633293642179940881969192120168665300712204232021063124301\", \"price\":\"0.01\", \"size\":\"5335.02\", \"side\":\"BUY\", \"hash\":\"6a18caa3cba737472f827f4182e532797b532cba\", \"best_bid\":\"0.6\", \"best_ask\":\"0.62\"}, {\"asset_id\":\"96600821790790307414914106093858868634329285205417149685270682748367152458577\", \"price\":\"0.99\", \"size\":\"5335.02\", \"side\":\"SELL\", \"hash\":\"c56b958a10d03244f06baabc6e37708d55ef7f61\", \"best_bid\":\"0.38\", \"best_ask\":\"0.4\"}], \"timestamp\":\"1785211961326\", \"event_type\":\"price_change\"}","received_at":"2026-07-28T04:12:41.490833Z","schema_version":"clob-market-ws.price_change.v1","sequence":null,"server_hash":null,"server_timestamp":"1785211961326","session_id":"2d607381e3054cee91998cdf45a4231c","source":"clob_market_ws"},"received_at":"2026-07-28T04:12:41.490833Z","record_id":"c34088f14f095e3cfe871b4f76f3680665c7209e26e27a2a9338b4dc89e3be49","schema_fingerprint":"4aa3821a28b0b7c2400bc59aba4bcc0a76e971dadd19610d3ad38c768e124dc7","schema_version":"edge-lab-recorder.raw.v1","sequence":null,"source":"clob_market_ws"}
{"event_at":"2026-07-28T04:12:41.331000Z","event_fingerprint":"8328d070f0db6b25cfb30eb96d97668fc39ced6b28d63f67cb04be2c5650d871","payload":{"connection_id":"f6725804f86a4c4eb588e4d5ed7db029","event_at":"2026-07-28T04:12:41.331000Z","event_type":"price_change","frame_hash":"2303cd3bc5b8d6d14df4c300b76eb167732e2244753dfc31e38270b7db0edf1c","frame_index":0,"kind":"data","monotonic_ns":313944572831125,"payload":{"event_type":"price_change","market":"0xd412ce774cfcf8dc9f71164aac78783978aac7b03871702a3b8a481bd9dc9688","price_changes":[{"asset_id":"107603864457683460275633293642179940881969192120168665300712204232021063124301","best_ask":"0.62","best_bid":"0.6","hash":"41db02615ba1c11acf7f35c1c9b2708e3648dfec","price":"0.6","side":"BUY","size":"36.12"},{"asset_id":"96600821790790307414914106093858868634329285205417149685270682748367152458577","best_ask":"0.4","best_bid":"0.38","hash":"fc54afb1b8748cb933c7f7f3e6a7b735302bdaa8","price":"0.4","side":"SELL","size":"36.12"}],"timestamp":"1785211961331"},"payload_hash":"5d3f8ce8958bd73c5bb42c0a229533a2479125d7022bebdad869be47d3524e83","raw_frame":"{\"market\":\"0xd412ce774cfcf8dc9f71164aac78783978aac7b03871702a3b8a481bd9dc9688\", \"price_changes\":[{\"asset_id\":\"107603864457683460275633293642179940881969192120168665300712204232021063124301\", \"price\":\"0.6\", \"size\":\"36.12\", \"side\":\"BUY\", \"hash\":\"41db02615ba1c11acf7f35c1c9b2708e3648dfec\", \"best_bid\":\"0.6\", \"best_ask\":\"0.62\"}, {\"asset_id\":\"96600821790790307414914106093858868634329285205417149685270682748367152458577\", \"price\":\"0.4\", \"size\":\"36.12\", \"side\":\"SELL\", \"hash\":\"fc54afb1b8748cb933c7f7f3e6a7b735302bdaa8\", \"best_bid\":\"0.38\", \"best_ask\":\"0.4\"}], \"timestamp\":\"1785211961331\", \"event_type\":\"price_change\"}","received_at":"2026-07-28T04:12:41.495309Z","schema_version":"clob-market-ws.price_change.v1","sequence":null,"server_hash":null,"server_timestamp":"1785211961331","session_id":"2d607381e3054cee91998cdf45a4231c","source":"clob_market_ws"},"received_at":"2026-07-28T04:12:41.495309Z","record_id":"b9d6fc822afda1dec534c0ea215bfa8e02180f6db6fede3e3bd195963015ae66","schema_fingerprint":"4aa3821a28b0b7c2400bc59aba4bcc0a76e971dadd19610d3ad38c768e124dc7","schema_version":"edge-lab-recorder.raw.v1","sequence":null,"source":"clob_market_ws"}
{"event_at":"2026-07-28T04:12:41.342000Z","event_fingerprint":"490022c5f8ba909a9f4b69b665feae1ff2c6a8350649446b323373d682db022d","payload":{"connection_id":"f6725804f86a4c4eb588e4d5ed7db029","event_at":"2026-07-28T04:12:41.342000Z","event_type":"price_change","frame_hash":"d3c0730ad86961afba3779b310800afc0685940cebdb70b3cb07478fbafa258f","frame_index":0,"kind":"data","monotonic_ns":313944577190208,"payload":{"event_type":"price_change","market":"0xd412ce774cfcf8dc9f71164aac78783978aac7b03871702a3b8a481bd9dc9688","price_changes":[{"asset_id":"107603864457683460275633293642179940881969192120168665300712204232021063124301","best_ask":"0.62","best_bid":"0.6","hash":"a99831d9c8500e96050e5dc9c73817c3e896af2e","price":"0.55","side":"BUY","size":"101"},{"asset_id":"96600821790790307414914106093858868634329285205417149685270682748367152458577","best_ask":"0.4","best_bid":"0.38","hash":"ad27056d797881b8dfc538b49c7967bbeee73538","price":"0.45","side":"SELL","size":"101"}],"timestamp":"1785211961342"},"payload_hash":"4009e1d67ed162d6652fbde2d39c0f52c0dfbc0fc1a480a009f7d50203ea8015","raw_frame":"{\"market\":\"0xd412ce774cfcf8dc9f71164aac78783978aac7b03871702a3b8a481bd9dc9688\", \"price_changes\":[{\"asset_id\":\"107603864457683460275633293642179940881969192120168665300712204232021063124301\", \"price\":\"0.55\", \"size\":\"101\", \"side\":\"BUY\", \"hash\":\"a99831d9c8500e96050e5dc9c73817c3e896af2e\", \"best_bid\":\"0.6\", \"best_ask\":\"0.62\"}, {\"asset_id\":\"96600821790790307414914106093858868634329285205417149685270682748367152458577\", \"price\":\"0.45\", \"size\":\"101\", \"side\":\"SELL\", \"hash\":\"ad27056d797881b8dfc538b49c7967bbeee73538\", \"best_bid\":\"0.38\", \"best_ask\":\"0.4\"}], \"timestamp\":\"1785211961342\", \"event_type\":\"price_change\"}","received_at":"2026-07-28T04:12:41.499667Z","schema_version":"clob-market-ws.price_change.v1","sequence":null,"server_hash":null,"server_timestamp":"1785211961342","session_id":"2d607381e3054cee91998cdf45a4231c","source":"clob_market_ws"},"received_at":"2026-07-28T04:12:41.499667Z","record_id":"94edf539b9e44fe7ff033e3ebde6b90bc10fe270e2ff5c57c145f7271eb1b5bb","schema_fingerprint":"4aa3821a28b0b7c2400bc59aba4bcc0a76e971dadd19610d3ad38c768e124dc7","schema_version":"edge-lab-recorder.raw.v1","sequence":null,"source":"clob_market_ws"}
{"event_at":"2026-07-28T04:12:41.350000Z","event_fingerprint":"0aa18ff00e51fc206f6fb71c9390755be0ee89b094f90b716f2ffafcd085ba40","payload":{"connection_id":"f6725804f86a4c4eb588e4d5ed7db029","event_at":"2026-07-28T04:12:41.350000Z","event_type":"price_change","frame_hash":"e8ebca308da881a913c3bd4b181e09dfd82c54694e13afb2d27fd585ab95dce1","frame_index":0,"kind":"data","monotonic_ns":313944581498666,"payload":{"event_type":"price_change","market":"0xd412ce774cfcf8dc9f71164aac78783978aac7b03871702a3b8a481bd9dc9688","price_changes":[{"asset_id":"107603864457683460275633293642179940881969192120168665300712204232021063124301","best_ask":"0.62","best_bid":"0.6","hash":"cfe2d77bc0e20f3c0329091289b2c4753c2597ef","price":"0.01","side":"BUY","size":"5330.02"},{"asset_id":"96600821790790307414914106093858868634329285205417149685270682748367152458577","best_ask":"0.4","best_bid":"0.38","hash":"5e51003c9dd3c72b218c950978530139ce0e6f91","price":"0.99","side":"SELL","size":"5330.02"}],"timestamp":"1785211961350"},"payload_hash":"350610b15c846383518f9c1f60927f22beaa2bf2dc16c920533dcbe38b17cae2","raw_frame":"{\"market\":\"0xd412ce774cfcf8dc9f71164aac78783978aac7b03871702a3b8a481bd9dc9688\", \"price_changes\":[{\"asset_id\":\"107603864457683460275633293642179940881969192120168665300712204232021063124301\", \"price\":\"0.01\", \"size\":\"5330.02\", \"side\":\"BUY\", \"hash\":\"cfe2d77bc0e20f3c0329091289b2c4753c2597ef\", \"best_bid\":\"0.6\", \"best_ask\":\"0.62\"}, {\"asset_id\":\"96600821790790307414914106093858868634329285205417149685270682748367152458577\", \"price\":\"0.99\", \"size\":\"5330.02\", \"side\":\"SELL\", \"hash\":\"5e51003c9dd3c72b218c950978530139ce0e6f91\", \"best_bid\":\"0.38\", \"best_ask\":\"0.4\"}], \"timestamp\":\"1785211961350\", \"event_type\":\"price_change\"}","received_at":"2026-07-28T04:12:41.503976Z","schema_version":"clob-market-ws.price_change.v1","sequence":null,"server_hash":null,"server_timestamp":"1785211961350","session_id":"2d607381e3054cee91998cdf45a4231c","source":"clob_market_ws"},"received_at":"2026-07-28T04:12:41.503976Z","record_id":"69caf71100162f82c507e093377d6767e340d3ce8ed9a564655540ba0b296d52","schema_fingerprint":"4aa3821a28b0b7c2400bc59aba4bcc0a76e971dadd19610d3ad38c768e124dc7","schema_version":"edge-lab-recorder.raw.v1","sequence":null,"source":"clob_market_ws"}
{"event_at":"2026-07-28T04:12:41.393000Z","event_fingerprint":"71ad34e15cac0937c160913787dc9c5dc36c67afe82aab1dfc7d53e5870d8da7","payload":{"connection_id":"f6725804f86a4c4eb588e4d5ed7db029","event_at":"2026-07-28T04:12:41.393000Z","event_type":"price_change","frame_hash":"a10bf42cae63d13bf6c382aff73b8b0af1cb9457a0dba41468ce22b1dd86b929","frame_index":0,"kind":"data","monotonic_ns":313944585874333,"payload":{"event_type":"price_change","market":"0xd412ce774cfcf8dc9f71164aac78783978aac7b03871702a3b8a481bd9dc9688","price_changes":[{"asset_id":"107603864457683460275633293642179940881969192120168665300712204232021063124301","best_ask":"0.62","best_bid":"0.6","hash":"639f49190ea45f1bc7f6b569ed8a4c6fc65a62b6","price":"0.45","side":"BUY","size":"165"},{"asset_id":"96600821790790307414914106093858868634329285205417149685270682748367152458577","best_ask":"0.4","best_bid":"0.38","hash":"e39425291a023fff34181d3405096c349b8729e0","price":"0.55","side":"SELL","size":"165"}],"timestamp":"1785211961393"},"payload_hash":"028a4cca2072c948e47b70f376380aa686b45d91be5bc9b33bc2947e1efc4e4e","raw_frame":"{\"market\":\"0xd412ce774cfcf8dc9f71164aac78783978aac7b03871702a3b8a481bd9dc9688\", \"price_changes\":[{\"asset_id\":\"107603864457683460275633293642179940881969192120168665300712204232021063124301\", \"price\":\"0.45\", \"size\":\"165\", \"side\":\"BUY\", \"hash\":\"639f49190ea45f1bc7f6b569ed8a4c6fc65a62b6\", \"best_bid\":\"0.6\", \"best_ask\":\"0.62\"}, {\"asset_id\":\"96600821790790307414914106093858868634329285205417149685270682748367152458577\", \"price\":\"0.55\", \"size\":\"165\", \"side\":\"SELL\", \"hash\":\"e39425291a023fff34181d3405096c349b8729e0\", \"best_bid\":\"0.38\", \"best_ask\":\"0.4\"}], \"timestamp\":\"1785211961393\", \"event_type\":\"price_change\"}","received_at":"2026-07-28T04:12:41.508352Z","schema_version":"clob-market-ws.price_change.v1","sequence":null,"server_hash":null,"server_timestamp":"1785211961393","session_id":"2d607381e3054cee91998cdf45a4231c","source":"clob_market_ws"},"received_at":"2026-07-28T04:12:41.508352Z","record_id":"cc89fe5c0d0787b3532cb1c0a3a0b60ea46e99aa8489be3ba572def9ebc559c9","schema_fingerprint":"4aa3821a28b0b7c2400bc59aba4bcc0a76e971dadd19610d3ad38c768e124dc7","schema_version":"edge-lab-recorder.raw.v1","sequence":null,"source":"clob_market_ws"}
{"event_at":"2026-07-28T04:12:41.394000Z","event_fingerprint":"c2433c5334b84c537a6b6564525aaeb78de71409d12bea90e4659024b9138f0e","payload":{"connection_id":"f6725804f86a4c4eb588e4d5ed7db029","event_at":"2026-07-28T04:12:41.394000Z","event_type":"price_change","frame_hash":"bfffbb27f995f8714788ef5bbb32686d0758a0aca5c51ff62d124923849afa32","frame_index":0,"kind":"data","monotonic_ns":313944588709416,"payload":{"event_type":"price_change","market":"0xd412ce774cfcf8dc9f71164aac78783978aac7b03871702a3b8a481bd9dc9688","price_changes":[{"asset_id":"107603864457683460275633293642179940881969192120168665300712204232021063124301","best_ask":"0.62","best_bid":"0.6","hash":"04f3e08108ff7339b2df069b7e4d1811e6dd7781","price":"0.45","side":"BUY","size":"135"},{"asset_id":"96600821790790307414914106093858868634329285205417149685270682748367152458577","best_ask":"0.4","best_bid":"0.38","hash":"93753d3a3412d1990261cfb249afed60263ba3d9","price":"0.55","side":"SELL","size":"135"}],"timestamp":"1785211961394"},"payload_hash":"c9417b05d30d7603eb4ba246cb3774c8dc47665d603cce5fd5b79aa1aceca033","raw_frame":"{\"market\":\"0xd412ce774cfcf8dc9f71164aac78783978aac7b03871702a3b8a481bd9dc9688\", \"price_changes\":[{\"asset_id\":\"107603864457683460275633293642179940881969192120168665300712204232021063124301\", \"price\":\"0.45\", \"size\":\"135\", \"side\":\"BUY\", \"hash\":\"04f3e08108ff7339b2df069b7e4d1811e6dd7781\", \"best_bid\":\"0.6\", \"best_ask\":\"0.62\"}, {\"asset_id\":\"96600821790790307414914106093858868634329285205417149685270682748367152458577\", \"price\":\"0.55\", \"size\":\"135\", \"side\":\"SELL\", \"hash\":\"93753d3a3412d1990261cfb249afed60263ba3d9\", \"best_bid\":\"0.38\", \"best_ask\":\"0.4\"}], \"timestamp\":\"1785211961394\", \"event_type\":\"price_change\"}","received_at":"2026-07-28T04:12:41.511187Z","schema_version":"clob-market-ws.price_change.v1","sequence":null,"server_hash":null,"server_timestamp":"1785211961394","session_id":"2d607381e3054cee91998cdf45a4231c","source":"clob_market_ws"},"received_at":"2026-07-28T04:12:41.511187Z","record_id":"549cc23cf882d5d82caf61ec0639b18540ff28fee95f5eb0245f3e6a8faa6358","schema_fingerprint":"4aa3821a28b0b7c2400bc59aba4bcc0a76e971dadd19610d3ad38c768e124dc7","schema_version":"edge-lab-recorder.raw.v1","sequence":null,"source":"clob_market_ws"}
{"event_at":"2026-07-28T04:12:41.397000Z","event_fingerprint":"244691b50864777fc74f826b5ab0e2d7e8136b8ba96de977080b38ee3601465b","payload":{"connection_id":"f6725804f86a4c4eb588e4d5ed7db029","event_at":"2026-07-28T04:12:41.397000Z","event_type":"price_change","frame_hash":"88eedbbdb7d57536f0a519e57eb483051229f77e8bf72f080b72133db5ac403c","frame_index":0,"kind":"data","monotonic_ns":313944593047791,"payload":{"event_type":"price_change","market":"0xd412ce774cfcf8dc9f71164aac78783978aac7b03871702a3b8a481bd9dc9688","price_changes":[{"asset_id":"107603864457683460275633293642179940881969192120168665300712204232021063124301","best_ask":"0.62","best_bid":"0.6","hash":"00659aa6bd6578c518ac5c28fb49efc0bf5f6ea4","price":"0.45","side":"BUY","size":"105"},{"asset_id":"96600821790790307414914106093858868634329285205417149685270682748367152458577","best_ask":"0.4","best_bid":"0.38","hash":"b84372cf952f71bee705a150cb5c0333f2ca7bf3","price":"0.55","side":"SELL","size":"105"}],"timestamp":"1785211961397"},"payload_hash":"4deea966e854b0c7821a050660db325b29dbddf7349099111d57d66342f1d191","raw_frame":"{\"market\":\"0xd412ce774cfcf8dc9f71164aac78783978aac7b03871702a3b8a481bd9dc9688\", \"price_changes\":[{\"asset_id\":\"107603864457683460275633293642179940881969192120168665300712204232021063124301\", \"price\":\"0.45\", \"size\":\"105\", \"side\":\"BUY\", \"hash\":\"00659aa6bd6578c518ac5c28fb49efc0bf5f6ea4\", \"best_bid\":\"0.6\", \"best_ask\":\"0.62\"}, {\"asset_id\":\"96600821790790307414914106093858868634329285205417149685270682748367152458577\", \"price\":\"0.55\", \"size\":\"105\", \"side\":\"SELL\", \"hash\":\"b84372cf952f71bee705a150cb5c0333f2ca7bf3\", \"best_bid\":\"0.38\", \"best_ask\":\"0.4\"}], \"timestamp\":\"1785211961397\", \"event_type\":\"price_change\"}","received_at":"2026-07-28T04:12:41.515525Z","schema_version":"clob-market-ws.price_change.v1","sequence":null,"server_hash":null,"server_timestamp":"1785211961397","session_id":"2d607381e3054cee91998cdf45a4231c","source":"clob_market_ws"},"received_at":"2026-07-28T04:12:41.515525Z","record_id":"e289d78f3869d60d7b1d26aad6f04ae5ed91d8837dcd18139e5d503f23c0d3cd","schema_fingerprint":"4aa3821a28b0b7c2400bc59aba4bcc0a76e971dadd19610d3ad38c768e124dc7","schema_version":"edge-lab-recorder.raw.v1","sequence":null,"source":"clob_market_ws"}
{"event_at":"2026-07-28T04:12:41.397000Z","event_fingerprint":"6ced5277a7f248ea7665d484952080412f00cb67c9cd9abddeb416477cff8479","payload":{"connection_id":"f6725804f86a4c4eb588e4d5ed7db029","event_at":"2026-07-28T04:12:41.397000Z","event_type":"price_change","frame_hash":"7c0f9c18df6a009885dccd371565890c7a1b1225e85f484458549ee9fd2d99fb","frame_index":0,"kind":"data","monotonic_ns":313944597405958,"payload":{"event_type":"price_change","market":"0xd412ce774cfcf8dc9f71164aac78783978aac7b03871702a3b8a481bd9dc9688","price_changes":[{"asset_id":"107603864457683460275633293642179940881969192120168665300712204232021063124301","best_ask":"0.62","best_bid":"0.6","hash":"085e19f3e10ea48d9ed8df3d91452b34fe4364a7","price":"0.02","side":"BUY","size":"535"},{"asset_id":"96600821790790307414914106093858868634329285205417149685270682748367152458577","best_ask":"0.4","best_bid":"0.38","hash":"8999857d273cda8b814ef0c7f81843d75fb701fc","price":"0.98","side":"SELL","size":"535"}],"timestamp":"1785211961397"},"payload_hash":"40bf88d18006b04fc67ce525920a7ba52e970c441d61c8337a7dbbb399418aed","raw_frame":"{\"market\":\"0xd412ce774cfcf8dc9f71164aac78783978aac7b03871702a3b8a481bd9dc9688\", \"price_changes\":[{\"asset_id\":\"107603864457683460275633293642179940881969192120168665300712204232021063124301\", \"price\":\"0.02\", \"size\":\"535\", \"side\":\"BUY\", \"hash\":\"085e19f3e10ea48d9ed8df3d91452b34fe4364a7\", \"best_bid\":\"0.6\", \"best_ask\":\"0.62\"}, {\"asset_id\":\"96600821790790307414914106093858868634329285205417149685270682748367152458577\", \"price\":\"0.98\", \"size\":\"535\", \"side\":\"SELL\", \"hash\":\"8999857d273cda8b814ef0c7f81843d75fb701fc\", \"best_bid\":\"0.38\", \"best_ask\":\"0.4\"}], \"timestamp\":\"1785211961397\", \"event_type\":\"price_change\"}","received_at":"2026-07-28T04:12:41.519883Z","schema_version":"clob-market-ws.price_change.v1","sequence":null,"server_hash":null,"server_timestamp":"1785211961397","session_id":"2d607381e3054cee91998cdf45a4231c","source":"clob_market_ws"},"received_at":"2026-07-28T04:12:41.519883Z","record_id":"dbed15e772efa8fe98816ca977d2ae82f6473898ed0bf7d148902e27591dbeb3","schema_fingerprint":"4aa3821a28b0b7c2400bc59aba4bcc0a76e971dadd19610d3ad38c768e124dc7","schema_version":"edge-lab-recorder.raw.v1","sequence":null,"source":"clob_market_ws"}
{"event_at":"2026-07-28T04:12:41.403000Z","event_fingerprint":"bd75b8da114e8f1f4f6fcc48bb9eef4d0120e173a5e20d856db0509a3ac08c24","payload":{"connection_id":"f6725804f86a4c4eb588e4d5ed7db029","event_at":"2026-07-28T04:12:41.403000Z","event_type":"price_change","frame_hash":"4d3f04919cd1d29d1f8ee5f6c8a685834009576ab1e05b6966e59492a33879f1","frame_index":0,"kind":"data","monotonic_ns":313944601811708,"payload":{"event_type":"price_change","market":"0xd412ce774cfcf8dc9f71164aac78783978aac7b03871702a3b8a481bd9dc9688","price_changes":[{"asset_id":"96600821790790307414914106093858868634329285205417149685270682748367152458577","best_ask":"0.4","best_bid":"0.38","hash":"08524e5746c462a57e478379d73db1993ffa751c","price":"0.38","side":"BUY","size":"56"},{"asset_id":"107603864457683460275633293642179940881969192120168665300712204232021063124301","best_ask":"0.62","best_bid":"0.6","hash":"b9e181ce08bda29fa13f4a8d8c330183fae89597","price":"0.62","side":"SELL","size":"56"}],"timestamp":"1785211961403"},"payload_hash":"51dbfd70db1456bf1881925dd6a4d640085774e24090ad890a38ce1ab3013aba","raw_frame":"{\"market\":\"0xd412ce774cfcf8dc9f71164aac78783978aac7b03871702a3b8a481bd9dc9688\", \"price_changes\":[{\"asset_id\":\"96600821790790307414914106093858868634329285205417149685270682748367152458577\", \"price\":\"0.38\", \"size\":\"56\", \"side\":\"BUY\", \"hash\":\"08524e5746c462a57e478379d73db1993ffa751c\", \"best_bid\":\"0.38\", \"best_ask\":\"0.4\"}, {\"asset_id\":\"107603864457683460275633293642179940881969192120168665300712204232021063124301\", \"price\":\"0.62\", \"size\":\"56\", \"side\":\"SELL\", \"hash\":\"b9e181ce08bda29fa13f4a8d8c330183fae89597\", \"best_bid\":\"0.6\", \"best_ask\":\"0.62\"}], \"timestamp\":\"1785211961403\", \"event_type\":\"price_change\"}","received_at":"2026-07-28T04:12:41.524289Z","schema_version":"clob-market-ws.price_change.v1","sequence":null,"server_hash":null,"server_timestamp":"1785211961403","session_id":"2d607381e3054cee91998cdf45a4231c","source":"clob_market_ws"},"received_at":"2026-07-28T04:12:41.524289Z","record_id":"144a17af6fc53a72b8d82422fef5e2f3cbf28783a48853583e77f94be2f9a50b","schema_fingerprint":"4aa3821a28b0b7c2400bc59aba4bcc0a76e971dadd19610d3ad38c768e124dc7","schema_version":"edge-lab-recorder.raw.v1","sequence":null,"source":"clob_market_ws"}
{"event_at":"2026-07-28T04:12:41.408000Z","event_fingerprint":"fed9ccfd64231458ed8cad53d1cd22430991a566dc64e24f1a0caa21723effab","payload":{"connection_id":"f6725804f86a4c4eb588e4d5ed7db029","event_at":"2026-07-28T04:12:41.408000Z","event_type":"price_change","frame_hash":"964fb4fe170994d3109b3925ac1336dcaa61d06729f1bbb659d7a4defe387d60","frame_index":0,"kind":"data","monotonic_ns":313944606048041,"payload":{"event_type":"price_change","market":"0xd412ce774cfcf8dc9f71164aac78783978aac7b03871702a3b8a481bd9dc9688","price_changes":[{"asset_id":"96600821790790307414914106093858868634329285205417149685270682748367152458577","best_ask":"0.4","best_bid":"0.38","hash":"01d5eba67a6421619252edd50fb609b533d68513","price":"0.37","side":"BUY","size":"22.41"},{"asset_id":"107603864457683460275633293642179940881969192120168665300712204232021063124301","best_ask":"0.62","best_bid":"0.6","hash":"f352a04367492b86a48d0249196aec7af49d3dde","price":"0.63","side":"SELL","size":"22.41"}],"timestamp":"1785211961408"},"payload_hash":"7095bfb47d9e5942aa27c17a53d3b9dbcbd441fb0631d5fcad4fe845fb6f6fac","raw_frame":"{\"market\":\"0xd412ce774cfcf8dc9f71164aac78783978aac7b03871702a3b8a481bd9dc9688\", \"price_changes\":[{\"asset_id\":\"96600821790790307414914106093858868634329285205417149685270682748367152458577\", \"price\":\"0.37\", \"size\":\"22.41\", \"side\":\"BUY\", \"hash\":\"01d5eba67a6421619252edd50fb609b533d68513\", \"best_bid\":\"0.38\", \"best_ask\":\"0.4\"}, {\"asset_id\":\"107603864457683460275633293642179940881969192120168665300712204232021063124301\", \"price\":\"0.63\", \"size\":\"22.41\", \"side\":\"SELL\", \"hash\":\"f352a04367492b86a48d0249196aec7af49d3dde\", \"best_bid\":\"0.6\", \"best_ask\":\"0.62\"}], \"timestamp\":\"1785211961408\", \"event_type\":\"price_change\"}","received_at":"2026-07-28T04:12:41.528526Z","schema_version":"clob-market-ws.price_change.v1","sequence":null,"server_hash":null,"server_timestamp":"1785211961408","session_id":"2d607381e3054cee91998cdf45a4231c","source":"clob_market_ws"},"received_at":"2026-07-28T04:12:41.528526Z","record_id":"0a73a8fa831da4bfd3bb13ea0363b0bef166fbbb493837381c1c498808e90f14","schema_fingerprint":"4aa3821a28b0b7c2400bc59aba4bcc0a76e971dadd19610d3ad38c768e124dc7","schema_version":"edge-lab-recorder.raw.v1","sequence":null,"source":"clob_market_ws"}
{"event_at":"2026-07-28T04:12:41.413000Z","event_fingerprint":"886b58cdc0d4c73b0baf12be8e6b4258ea66f22a12b40fca17082e5072718b5b","payload":{"connection_id":"f6725804f86a4c4eb588e4d5ed7db029","event_at":"2026-07-28T04:12:41.413000Z","event_type":"price_change","frame_hash":"6d8c76a1ead643bacd2652bf2eb671513cf3e3c6ec7f4a2aa522ccef9b5da5e6","frame_index":0,"kind":"data","monotonic_ns":313944610627708,"payload":{"event_type":"price_change","market":"0xd412ce774cfcf8dc9f71164aac78783978aac7b03871702a3b8a481bd9dc9688","price_changes":[{"asset_id":"96600821790790307414914106093858868634329285205417149685270682748367152458577","best_ask":"0.4","best_bid":"0.38","hash":"ce94351c33c2e59b17c9b404e845a3826be25c32","price":"0.37","side":"BUY","size":"76.41"},{"asset_id":"107603864457683460275633293642179940881969192120168665300712204232021063124301","best_ask":"0.62","best_bid":"0.6","hash":"59019c4c3760a1e25404ae40ea829394be763f8f","price":"0.63","side":"SELL","size":"76.41"}],"timestamp":"1785211961413"},"payload_hash":"b5e3f7777424d108f8e4df138570ff93685a2e0c1316f3aff3bd25902f565f5a","raw_frame":"{\"market\":\"0xd412ce774cfcf8dc9f71164aac78783978aac7b03871702a3b8a481bd9dc9688\", \"price_changes\":[{\"asset_id\":\"96600821790790307414914106093858868634329285205417149685270682748367152458577\", \"price\":\"0.37\", \"size\":\"76.41\", \"side\":\"BUY\", \"hash\":\"ce94351c33c2e59b17c9b404e845a3826be25c32\", \"best_bid\":\"0.38\", \"best_ask\":\"0.4\"}, {\"asset_id\":\"107603864457683460275633293642179940881969192120168665300712204232021063124301\", \"price\":\"0.63\", \"size\":\"76.41\", \"side\":\"SELL\", \"hash\":\"59019c4c3760a1e25404ae40ea829394be763f8f\", \"best_bid\":\"0.6\", \"best_ask\":\"0.62\"}], \"timestamp\":\"1785211961413\", \"event_type\":\"price_change\"}","received_at":"2026-07-28T04:12:41.533105Z","schema_version":"clob-market-ws.price_change.v1","sequence":null,"server_hash":null,"server_timestamp":"1785211961413","session_id":"2d607381e3054cee91998cdf45a4231c","source":"clob_market_ws"},"received_at":"2026-07-28T04:12:41.533105Z","record_id":"053bd12c5de921e0a8ec6ac485b34d27134c5df181a42473af4f73253a9a124e","schema_fingerprint":"4aa3821a28b0b7c2400bc59aba4bcc0a76e971dadd19610d3ad38c768e124dc7","schema_version":"edge-lab-recorder.raw.v1","sequence":null,"source":"clob_market_ws"}
{"event_at":"2026-07-28T04:12:41.414000Z","event_fingerprint":"ed5d0cd178f437c22afa1f4be8f6856075839574fe792d494aa7435cfd4e623f","payload":{"connection_id":"f6725804f86a4c4eb588e4d5ed7db029","event_at":"2026-07-28T04:12:41.414000Z","event_type":"price_change","frame_hash":"407ed580cae760cfbb82b6707d345104c87491202d2f5c6d8dc65120037a239d","frame_index":0,"kind":"data","monotonic_ns":313944615102000,"payload":{"event_type":"price_change","market":"0xd412ce774cfcf8dc9f71164aac78783978aac7b03871702a3b8a481bd9dc9688","price_changes":[{"asset_id":"96600821790790307414914106093858868634329285205417149685270682748367152458577","best_ask":"0.4","best_bid":"0.38","hash":"d5997378cec6aba0cddf2fc49b12fde466e1ad8a","price":"0.38","side":"BUY","size":"109"},{"asset_id":"107603864457683460275633293642179940881969192120168665300712204232021063124301","best_ask":"0.62","best_bid":"0.6","hash":"1aa553f36d95329eb7956ab61b816c49036cd21b","price":"0.62","side":"SELL","size":"109"}],"timestamp":"1785211961414"},"payload_hash":"32c0679f7b074a6bf4fcdbdd9858af030b9b8e4e3042bf0644d88b10aa127d0e","raw_frame":"{\"market\":\"0xd412ce774cfcf8dc9f71164aac78783978aac7b03871702a3b8a481bd9dc9688\", \"price_changes\":[{\"asset_id\":\"96600821790790307414914106093858868634329285205417149685270682748367152458577\", \"price\":\"0.38\", \"size\":\"109\", \"side\":\"BUY\", \"hash\":\"d5997378cec6aba0cddf2fc49b12fde466e1ad8a\", \"best_bid\":\"0.38\", \"best_ask\":\"0.4\"}, {\"asset_id\":\"107603864457683460275633293642179940881969192120168665300712204232021063124301\", \"price\":\"0.62\", \"size\":\"109\", \"side\":\"SELL\", \"hash\":\"1aa553f36d95329eb7956ab61b816c49036cd21b\", \"best_bid\":\"0.6\", \"best_ask\":\"0.62\"}], \"timestamp\":\"1785211961414\", \"event_type\":\"price_change\"}","received_at":"2026-07-28T04:12:41.537574Z","schema_version":"clob-market-ws.price_change.v1","sequence":null,"server_hash":null,"server_timestamp":"1785211961414","session_id":"2d607381e3054cee91998cdf45a4231c","source":"clob_market_ws"},"received_at":"2026-07-28T04:12:41.537574Z","record_id":"8da38593ee937acb1e0d7e924299c58d7e775aed4a2d64fb6fb097b3400e1054","schema_fingerprint":"4aa3821a28b0b7c2400bc59aba4bcc0a76e971dadd19610d3ad38c768e124dc7","schema_version":"edge-lab-recorder.raw.v1","sequence":null,"source":"clob_market_ws"}
{"event_at":"2026-07-28T04:12:41.415000Z","event_fingerprint":"c1de86a7b9f85fb8781052c5de51f53b1ba0c04fee4008940f8a0fc55a4c8fc8","payload":{"connection_id":"f6725804f86a4c4eb588e4d5ed7db029","event_at":"2026-07-28T04:12:41.415000Z","event_type":"price_change","frame_hash":"e1ee697170d5b21d01cb043cede6d129a28981abb3c78c5f567ac691c0ecdc46","frame_index":0,"kind":"data","monotonic_ns":313944619445291,"payload":{"event_type":"price_change","market":"0xd412ce774cfcf8dc9f71164aac78783978aac7b03871702a3b8a481bd9dc9688","price_changes":[{"asset_id":"107603864457683460275633293642179940881969192120168665300712204232021063124301","best_ask":"0.62","best_bid":"0.6","hash":"57ff2c280dc201ca72c92a5a7647681d1aa7f142","price":"0.59","side":"BUY","size":"45"},{"asset_id":"96600821790790307414914106093858868634329285205417149685270682748367152458577","best_ask":"0.4","best_bid":"0.38","hash":"510edec653b5e52ed4e8564647a4fcf743f983e8","price":"0.41","side":"SELL","size":"45"}],"timestamp":"1785211961415"},"payload_hash":"1cc3f7c6a73810757a9634d19a60d09596b7aaea1a9fd4860018f33d67c234b8","raw_frame":"{\"market\":\"0xd412ce774cfcf8dc9f71164aac78783978aac7b03871702a3b8a481bd9dc9688\", \"price_changes\":[{\"asset_id\":\"107603864457683460275633293642179940881969192120168665300712204232021063124301\", \"price\":\"0.59\", \"size\":\"45\", \"side\":\"BUY\", \"hash\":\"57ff2c280dc201ca72c92a5a7647681d1aa7f142\", \"best_bid\":\"0.6\", \"best_ask\":\"0.62\"}, {\"asset_id\":\"96600821790790307414914106093858868634329285205417149685270682748367152458577\", \"price\":\"0.41\", \"size\":\"45\", \"side\":\"SELL\", \"hash\":\"510edec653b5e52ed4e8564647a4fcf743f983e8\", \"best_bid\":\"0.38\", \"best_ask\":\"0.4\"}], \"timestamp\":\"1785211961415\", \"event_type\":\"price_change\"}","received_at":"2026-07-28T04:12:41.541922Z","schema_version":"clob-market-ws.price_change.v1","sequence":null,"server_hash":null,"server_timestamp":"1785211961415","session_id":"2d607381e3054cee91998cdf45a4231c","source":"clob_market_ws"},"received_at":"2026-07-28T04:12:41.541922Z","record_id":"c366783eb151222d9f17ec3ab17f7e991c9be9684c60a7dc25eb3a771b0acb16","schema_fingerprint":"4aa3821a28b0b7c2400bc59aba4bcc0a76e971dadd19610d3ad38c768e124dc7","schema_version":"edge-lab-recorder.raw.v1","sequence":null,"source":"clob_market_ws"}
{"event_at":"2026-07-28T04:12:41.416000Z","event_fingerprint":"9b32cbf3acb65ad9c3d055fc988b048f2138dd1f580c2b1782932346f688b645","payload":{"connection_id":"f6725804f86a4c4eb588e4d5ed7db029","event_at":"2026-07-28T04:12:41.416000Z","event_type":"price_change","frame_hash":"1c74aec7ff01da0be1cf98474eb6f1b0081e50c80d2c4089a024952f2654f92d","frame_index":0,"kind":"data","monotonic_ns":313944623712791,"payload":{"event_type":"price_change","market":"0xd412ce774cfcf8dc9f71164aac78783978aac7b03871702a3b8a481bd9dc9688","price_changes":[{"asset_id":"107603864457683460275633293642179940881969192120168665300712204232021063124301","best_ask":"0.62","best_bid":"0.6","hash":"34c0d3dde9baf309e09444c4bf396609a6f08a15","price":"0.46","side":"BUY","size":"108"},{"asset_id":"96600821790790307414914106093858868634329285205417149685270682748367152458577","best_ask":"0.4","best_bid":"0.38","hash":"789eeec7530c46d981efa4742869246ecf5b31d3","price":"0.54","side":"SELL","size":"108"}],"timestamp":"1785211961416"},"payload_hash":"e3e8f4f92e2aecb926bfc5e7629a9dea21e5c0de3214649922f4f338c1ad07a4","raw_frame":"{\"market\":\"0xd412ce774cfcf8dc9f71164aac78783978aac7b03871702a3b8a481bd9dc9688\", \"price_changes\":[{\"asset_id\":\"107603864457683460275633293642179940881969192120168665300712204232021063124301\", \"price\":\"0.46\", \"size\":\"108\", \"side\":\"BUY\", \"hash\":\"34c0d3dde9baf309e09444c4bf396609a6f08a15\", \"best_bid\":\"0.6\", \"best_ask\":\"0.62\"}, {\"asset_id\":\"96600821790790307414914106093858868634329285205417149685270682748367152458577\", \"price\":\"0.54\", \"size\":\"108\", \"side\":\"SELL\", \"hash\":\"789eeec7530c46d981efa4742869246ecf5b31d3\", \"best_bid\":\"0.38\", \"best_ask\":\"0.4\"}], \"timestamp\":\"1785211961416\", \"event_type\":\"price_change\"}","received_at":"2026-07-28T04:12:41.546190Z","schema_version":"clob-market-ws.price_change.v1","sequence":null,"server_hash":null,"server_timestamp":"1785211961416","session_id":"2d607381e3054cee91998cdf45a4231c","source":"clob_market_ws"},"received_at":"2026-07-28T04:12:41.546190Z","record_id":"4222e79e84c7d48f86b548eeff82caf1c9c1b86760c697f5ecf2e8c2574841ae","schema_fingerprint":"4aa3821a28b0b7c2400bc59aba4bcc0a76e971dadd19610d3ad38c768e124dc7","schema_version":"edge-lab-recorder.raw.v1","sequence":null,"source":"clob_market_ws"}
{"event_at":"2026-07-28T04:12:41.418000Z","event_fingerprint":"29da2b6b836cda4e783a18b797662ad691bc4a595d7240f038d0db722d8876f1","payload":{"connection_id":"f6725804f86a4c4eb588e4d5ed7db029","event_at":"2026-07-28T04:12:41.418000Z","event_type":"price_change","frame_hash":"d7f00650794e9b883e39c99773c5d6d99d4412c3ced38c3fd6f419d06ef51d52","frame_index":0,"kind":"data","monotonic_ns":313944627999625,"payload":{"event_type":"price_change","market":"0xd412ce774cfcf8dc9f71164aac78783978aac7b03871702a3b8a481bd9dc9688","price_changes":[{"asset_id":"107603864457683460275633293642179940881969192120168665300712204232021063124301","best_ask":"0.62","best_bid":"0.6","hash":"674f0af25334256f63ed3fa467ca86e306ea92b4","price":"0.6","side":"BUY","size":"69.12"},{"asset_id":"96600821790790307414914106093858868634329285205417149685270682748367152458577","best_ask":"0.4","best_bid":"0.38","hash":"8fff7dd60d99de9d92685099fe5032b346cd33e4","price":"0.4","side":"SELL","size":"69.12"}],"timestamp":"1785211961418"},"payload_hash":"2e42d0771e8939ce87a23e052414ca2405ea26a7568476632c6410672aec35e4","raw_frame":"{\"market\":\"0xd412ce774cfcf8dc9f71164aac78783978aac7b03871702a3b8a481bd9dc9688\", \"price_changes\":[{\"asset_id\":\"107603864457683460275633293642179940881969192120168665300712204232021063124301\", \"price\":\"0.6\", \"size\":\"69.12\", \"side\":\"BUY\", \"hash\":\"674f0af25334256f63ed3fa467ca86e306ea92b4\", \"best_bid\":\"0.6\", \"best_ask\":\"0.62\"}, {\"asset_id\":\"96600821790790307414914106093858868634329285205417149685270682748367152458577\", \"price\":\"0.4\", \"size\":\"69.12\", \"side\":\"SELL\", \"hash\":\"8fff7dd60d99de9d92685099fe5032b346cd33e4\", \"best_bid\":\"0.38\", \"best_ask\":\"0.4\"}], \"timestamp\":\"1785211961418\", \"event_type\":\"price_change\"}","received_at":"2026-07-28T04:12:41.550476Z","schema_version":"clob-market-ws.price_change.v1","sequence":null,"server_hash":null,"server_timestamp":"1785211961418","session_id":"2d607381e3054cee91998cdf45a4231c","source":"clob_market_ws"},"received_at":"2026-07-28T04:12:41.550476Z","record_id":"196821669a266c3921881027781a4988d0ecc17babf9f2a00e9c099345b7d693","schema_fingerprint":"4aa3821a28b0b7c2400bc59aba4bcc0a76e971dadd19610d3ad38c768e124dc7","schema_version":"edge-lab-recorder.raw.v1","sequence":null,"source":"clob_market_ws"}
{"event_at":"2026-07-28T04:12:41.421000Z","event_fingerprint":"e3c690e6240005f929da3b7c26eb790905560f1142de657016802e1853e440aa","payload":{"connection_id":"f6725804f86a4c4eb588e4d5ed7db029","event_at":"2026-07-28T04:12:41.421000Z","event_type":"price_change","frame_hash":"bac68879b77741dd824a2d22515cbac1e00ac472c758cd9828c9a1933bd81ce5","frame_index":0,"kind":"data","monotonic_ns":313944632409708,"payload":{"event_type":"price_change","market":"0xd412ce774cfcf8dc9f71164aac78783978aac7b03871702a3b8a481bd9dc9688","price_changes":[{"asset_id":"107603864457683460275633293642179940881969192120168665300712204232021063124301","best_ask":"0.62","best_bid":"0.6","hash":"4b93dc02d257bc9c7e3290046efcc984bf30b0ca","price":"0.46","side":"BUY","size":"138"},{"asset_id":"96600821790790307414914106093858868634329285205417149685270682748367152458577","best_ask":"0.4","best_bid":"0.38","hash":"1a2530cb56abe2b11e7bbcb6e8cd50b27f683422","price":"0.54","side":"SELL","size":"138"}],"timestamp":"1785211961421"},"payload_hash":"fab499ad32309ddfaadddf2705c86634505977f354d520a91858d9111a792df2","raw_frame":"{\"market\":\"0xd412ce774cfcf8dc9f71164aac78783978aac7b03871702a3b8a481bd9dc9688\", \"price_changes\":[{\"asset_id\":\"107603864457683460275633293642179940881969192120168665300712204232021063124301\", \"price\":\"0.46\", \"size\":\"138\", \"side\":\"BUY\", \"hash\":\"4b93dc02d257bc9c7e3290046efcc984bf30b0ca\", \"best_bid\":\"0.6\", \"best_ask\":\"0.62\"}, {\"asset_id\":\"96600821790790307414914106093858868634329285205417149685270682748367152458577\", \"price\":\"0.54\", \"size\":\"138\", \"side\":\"SELL\", \"hash\":\"1a2530cb56abe2b11e7bbcb6e8cd50b27f683422\", \"best_bid\":\"0.38\", \"best_ask\":\"0.4\"}], \"timestamp\":\"1785211961421\", \"event_type\":\"price_change\"}","received_at":"2026-07-28T04:12:41.554885Z","schema_version":"clob-market-ws.price_change.v1","sequence":null,"server_hash":null,"server_timestamp":"1785211961421","session_id":"2d607381e3054cee91998cdf45a4231c","source":"clob_market_ws"},"received_at":"2026-07-28T04:12:41.554885Z","record_id":"970f7e035bb41b0db72793c8ea445f3ac9cfdc736d4e7ca2a17f2795616a12fb","schema_fingerprint":"4aa3821a28b0b7c2400bc59aba4bcc0a76e971dadd19610d3ad38c768e124dc7","schema_version":"edge-lab-recorder.raw.v1","sequence":null,"source":"clob_market_ws"}
{"event_at":"2026-07-28T04:12:41.426000Z","event_fingerprint":"acd67e7bab0dfe45d9a4efcc392b91b2b0fb7d32dda8946d4e08e73be5316fa5","payload":{"connection_id":"f6725804f86a4c4eb588e4d5ed7db029","event_at":"2026-07-28T04:12:41.426000Z","event_type":"price_change","frame_hash":"ceb90cccf08d91291761d4de2d5a710e6ab94c3fc2a7d7d25591c7b3cb123411","frame_index":0,"kind":"data","monotonic_ns":313944636817791,"payload":{"event_type":"price_change","market":"0xd412ce774cfcf8dc9f71164aac78783978aac7b03871702a3b8a481bd9dc9688","price_changes":[{"asset_id":"107603864457683460275633293642179940881969192120168665300712204232021063124301","best_ask":"0.62","best_bid":"0.6","hash":"35a97ff13eb02d5a54f7b8a135289a14b8845fbc","price":"0.46","side":"BUY","size":"168"},{"asset_id":"96600821790790307414914106093858868634329285205417149685270682748367152458577","best_ask":"0.4","best_bid":"0.38","hash":"031cc8fa90190b6fd5c7d89f5c5194f73a64dfe5","price":"0.54","side":"SELL","size":"168"}],"timestamp":"1785211961426"},"payload_hash":"f4dc6dcfeae0efd94eac6dbf94bdbc7e9937e313cdd6ac062f4b7377680ba4c7","raw_frame":"{\"market\":\"0xd412ce774cfcf8dc9f71164aac78783978aac7b03871702a3b8a481bd9dc9688\", \"price_changes\":[{\"asset_id\":\"107603864457683460275633293642179940881969192120168665300712204232021063124301\", \"price\":\"0.46\", \"size\":\"168\", \"side\":\"BUY\", \"hash\":\"35a97ff13eb02d5a54f7b8a135289a14b8845fbc\", \"best_bid\":\"0.6\", \"best_ask\":\"0.62\"}, {\"asset_id\":\"96600821790790307414914106093858868634329285205417149685270682748367152458577\", \"price\":\"0.54\", \"size\":\"168\", \"side\":\"SELL\", \"hash\":\"031cc8fa90190b6fd5c7d89f5c5194f73a64dfe5\", \"best_bid\":\"0.38\", \"best_ask\":\"0.4\"}], \"timestamp\":\"1785211961426\", \"event_type\":\"price_change\"}","received_at":"2026-07-28T04:12:41.559295Z","schema_version":"clob-market-ws.price_change.v1","sequence":null,"server_hash":null,"server_timestamp":"1785211961426","session_id":"2d607381e3054cee91998cdf45a4231c","source":"clob_market_ws"},"received_at":"2026-07-28T04:12:41.559295Z","record_id":"c30c257a44dd7c7d7ceb783d2f181645d095333d3ff7c2844fd7d0353b24c81f","schema_fingerprint":"4aa3821a28b0b7c2400bc59aba4bcc0a76e971dadd19610d3ad38c768e124dc7","schema_version":"edge-lab-recorder.raw.v1","sequence":null,"source":"clob_market_ws"}
{"event_at":"2026-07-28T04:12:41.438000Z","event_fingerprint":"159ae5d4713832ea9e899cc0cfdd6bc175fee739ef16a39a4a76264b01803d85","payload":{"connection_id":"f6725804f86a4c4eb588e4d5ed7db029","event_at":"2026-07-28T04:12:41.438000Z","event_type":"price_change","frame_hash":"13f7f0edb173d7a2e6288c4023953b0221ee0d56c8763617f2dbf8e40c590ea4","frame_index":0,"kind":"data","monotonic_ns":313944641147041,"payload":{"event_type":"price_change","market":"0xd412ce774cfcf8dc9f71164aac78783978aac7b03871702a3b8a481bd9dc9688","price_changes":[{"asset_id":"107603864457683460275633293642179940881969192120168665300712204232021063124301","best_ask":"0.62","best_bid":"0.6","hash":"8f676a5cbbc673ca61b54f7433185a1e705be712","price":"0.59","side":"BUY","size":"11"},{"asset_id":"96600821790790307414914106093858868634329285205417149685270682748367152458577","best_ask":"0.4","best_bid":"0.38","hash":"4b002c9344f86dd386a3e357d480b102123489d6","price":"0.41","side":"SELL","size":"11"}],"timestamp":"1785211961438"},"payload_hash":"59c4dab3f4a84c59de61f29a2d82121af5456360974f0fc4da769e7618383c40","raw_frame":"{\"market\":\"0xd412ce774cfcf8dc9f71164aac78783978aac7b03871702a3b8a481bd9dc9688\", \"price_changes\":[{\"asset_id\":\"107603864457683460275633293642179940881969192120168665300712204232021063124301\", \"price\":\"0.59\", \"size\":\"11\", \"side\":\"BUY\", \"hash\":\"8f676a5cbbc673ca61b54f7433185a1e705be712\", \"best_bid\":\"0.6\", \"best_ask\":\"0.62\"}, {\"asset_id\":\"96600821790790307414914106093858868634329285205417149685270682748367152458577\", \"price\":\"0.41\", \"size\":\"11\", \"side\":\"SELL\", \"hash\":\"4b002c9344f86dd386a3e357d480b102123489d6\", \"best_bid\":\"0.38\", \"best_ask\":\"0.4\"}], \"timestamp\":\"1785211961438\", \"event_type\":\"price_change\"}","received_at":"2026-07-28T04:12:41.563624Z","schema_version":"clob-market-ws.price_change.v1","sequence":null,"server_hash":null,"server_timestamp":"1785211961438","session_id":"2d607381e3054cee91998cdf45a4231c","source":"clob_market_ws"},"received_at":"2026-07-28T04:12:41.563624Z","record_id":"f70c1e3cd45bffa5ce5308175a9bc7f7a8ad654a16f7188c5455caaa740c00ca","schema_fingerprint":"4aa3821a28b0b7c2400bc59aba4bcc0a76e971dadd19610d3ad38c768e124dc7","schema_version":"edge-lab-recorder.raw.v1","sequence":null,"source":"clob_market_ws"}
{"event_at":"2026-07-28T04:12:41.440000Z","event_fingerprint":"594e98ebbf769ddb042aa133fc0dccb2e4d861b510ad66066cdb864854f688dc","payload":{"connection_id":"f6725804f86a4c4eb588e4d5ed7db029","event_at":"2026-07-28T04:12:41.440000Z","event_type":"price_change","frame_hash":"f510faf280bf890ee945a3f5cf10890db48337370f7ceb7595355a28a9000c25","frame_index":0,"kind":"data","monotonic_ns":313944645491083,"payload":{"event_type":"price_change","market":"0xd412ce774cfcf8dc9f71164aac78783978aac7b03871702a3b8a481bd9dc9688","price_changes":[{"asset_id":"107603864457683460275633293642179940881969192120168665300712204232021063124301","best_ask":"0.62","best_bid":"0.6","hash":"ef872a0582a551d2368a1a4af43bc3dd0b4948df","price":"0.6","side":"BUY","size":"36.12"},{"asset_id":"96600821790790307414914106093858868634329285205417149685270682748367152458577","best_ask":"0.4","best_bid":"0.38","hash":"5c880162662f31dad861f818e003a79c4cd9eb05","price":"0.4","side":"SELL","size":"36.12"}],"timestamp":"1785211961440"},"payload_hash":"04a4a83415f93f4e0266d05ad640a151767d1950c74b56ed5d69b82507d8e588","raw_frame":"{\"market\":\"0xd412ce774cfcf8dc9f71164aac78783978aac7b03871702a3b8a481bd9dc9688\", \"price_changes\":[{\"asset_id\":\"107603864457683460275633293642179940881969192120168665300712204232021063124301\", \"price\":\"0.6\", \"size\":\"36.12\", \"side\":\"BUY\", \"hash\":\"ef872a0582a551d2368a1a4af43bc3dd0b4948df\", \"best_bid\":\"0.6\", \"best_ask\":\"0.62\"}, {\"asset_id\":\"96600821790790307414914106093858868634329285205417149685270682748367152458577\", \"price\":\"0.4\", \"size\":\"36.12\", \"side\":\"SELL\", \"hash\":\"5c880162662f31dad861f818e003a79c4cd9eb05\", \"best_bid\":\"0.38\", \"best_ask\":\"0.4\"}], \"timestamp\":\"1785211961440\", \"event_type\":\"price_change\"}","received_at":"2026-07-28T04:12:41.567963Z","schema_version":"clob-market-ws.price_change.v1","sequence":null,"server_hash":null,"server_timestamp":"1785211961440","session_id":"2d607381e3054cee91998cdf45a4231c","source":"clob_market_ws"},"received_at":"2026-07-28T04:12:41.567963Z","record_id":"ce61b8a3d856f73fac9f61cbd75763e0e5fb78aff20ae7c4dd1007a5a9ade2bf","schema_fingerprint":"4aa3821a28b0b7c2400bc59aba4bcc0a76e971dadd19610d3ad38c768e124dc7","schema_version":"edge-lab-recorder.raw.v1","sequence":null,"source":"clob_market_ws"}
{"event_at":"2026-07-28T04:12:41.446000Z","event_fingerprint":"651dfe2851a70ddee9591ef63dcff3945ec20ce32e22a5e8edc27a14037e79fa","payload":{"connection_id":"f6725804f86a4c4eb588e4d5ed7db029","event_at":"2026-07-28T04:12:41.446000Z","event_type":"price_change","frame_hash":"b25b0761dea378f1daf5e4150084b926cd252a1ad6aea8114891e4bcde9664f1","frame_index":0,"kind":"data","monotonic_ns":313944649789041,"payload":{"event_type":"price_change","market":"0xd412ce774cfcf8dc9f71164aac78783978aac7b03871702a3b8a481bd9dc9688","price_changes":[{"asset_id":"107603864457683460275633293642179940881969192120168665300712204232021063124301","best_ask":"0.62","best_bid":"0.6","hash":"37de08faef91d9011ded4e7eb185c197a8777cf7","price":"0.02","side":"BUY","size":"530"},{"asset_id":"96600821790790307414914106093858868634329285205417149685270682748367152458577","best_ask":"0.4","best_bid":"0.38","hash":"2d9fbfb27483bfeb3cb230c8efa6c1ecec6e719f","price":"0.98","side":"SELL","size":"530"}],"timestamp":"1785211961446"},"payload_hash":"e46974fcba1439f8bd7f228bf612a8e37685875b27f3551a1f715de888f6ec6f","raw_frame":"{\"market\":\"0xd412ce774cfcf8dc9f71164aac78783978aac7b03871702a3b8a481bd9dc9688\", \"price_changes\":[{\"asset_id\":\"107603864457683460275633293642179940881969192120168665300712204232021063124301\", \"price\":\"0.02\", \"size\":\"530\", \"side\":\"BUY\", \"hash\":\"37de08faef91d9011ded4e7eb185c197a8777cf7\", \"best_bid\":\"0.6\", \"best_ask\":\"0.62\"}, {\"asset_id\":\"96600821790790307414914106093858868634329285205417149685270682748367152458577\", \"price\":\"0.98\", \"size\":\"530\", \"side\":\"SELL\", \"hash\":\"2d9fbfb27483bfeb3cb230c8efa6c1ecec6e719f\", \"best_bid\":\"0.38\", \"best_ask\":\"0.4\"}], \"timestamp\":\"1785211961446\", \"event_type\":\"price_change\"}","received_at":"2026-07-28T04:12:41.572266Z","schema_version":"clob-market-ws.price_change.v1","sequence":null,"server_hash":null,"server_timestamp":"1785211961446","session_id":"2d607381e3054cee91998cdf45a4231c","source":"clob_market_ws"},"received_at":"2026-07-28T04:12:41.572266Z","record_id":"20af2de3ed8ae03a4de76455a8d7da3cd55361b593ff39bab47de18a5c89fc0e","schema_fingerprint":"4aa3821a28b0b7c2400bc59aba4bcc0a76e971dadd19610d3ad38c768e124dc7","schema_version":"edge-lab-recorder.raw.v1","sequence":null,"source":"clob_market_ws"}
{"event_at":"2026-07-28T04:12:41.494000Z","event_fingerprint":"8de16b73da5ddf412d396bdd8da2ffb11ae3007caac219625030b4af9fcdf65e","payload":{"connection_id":"f6725804f86a4c4eb588e4d5ed7db029","event_at":"2026-07-28T04:12:41.494000Z","event_type":"price_change","frame_hash":"e3ee0477c51f503780c746f8b3f6030efdb2ffac780921fbdd97cb482bf0ad26","frame_index":0,"kind":"data","monotonic_ns":313944654077916,"payload":{"event_type":"price_change","market":"0xd412ce774cfcf8dc9f71164aac78783978aac7b03871702a3b8a481bd9dc9688","price_changes":[{"asset_id":"96600821790790307414914106093858868634329285205417149685270682748367152458577","best_ask":"0.4","best_bid":"0.38","hash":"b9a7659ade920367c561637bc84327e580dae453","price":"0.38","side":"BUY","size":"94"},{"asset_id":"107603864457683460275633293642179940881969192120168665300712204232021063124301","best_ask":"0.62","best_bid":"0.6","hash":"230a4ee5317b0dee7b319f68d8e254af10aa080c","price":"0.62","side":"SELL","size":"94"}],"timestamp":"1785211961494"},"payload_hash":"fefe2c059601db737b2f2a5808115c08a666f380aa2a51eb2a0116a0c5d74b24","raw_frame":"{\"market\":\"0xd412ce774cfcf8dc9f71164aac78783978aac7b03871702a3b8a481bd9dc9688\", \"price_changes\":[{\"asset_id\":\"96600821790790307414914106093858868634329285205417149685270682748367152458577\", \"price\":\"0.38\", \"size\":\"94\", \"side\":\"BUY\", \"hash\":\"b9a7659ade920367c561637bc84327e580dae453\", \"best_bid\":\"0.38\", \"best_ask\":\"0.4\"}, {\"asset_id\":\"107603864457683460275633293642179940881969192120168665300712204232021063124301\", \"price\":\"0.62\", \"size\":\"94\", \"side\":\"SELL\", \"hash\":\"230a4ee5317b0dee7b319f68d8e254af10aa080c\", \"best_bid\":\"0.6\", \"best_ask\":\"0.62\"}], \"timestamp\":\"1785211961494\", \"event_type\":\"price_change\"}","received_at":"2026-07-28T04:12:41.576554Z","schema_version":"clob-market-ws.price_change.v1","sequence":null,"server_hash":null,"server_timestamp":"1785211961494","session_id":"2d607381e3054cee91998cdf45a4231c","source":"clob_market_ws"},"received_at":"2026-07-28T04:12:41.576554Z","record_id":"f78ea1b068ea71b8dda511d717363b29f964a39e92e8cb6571a650508b9d5acd","schema_fingerprint":"4aa3821a28b0b7c2400bc59aba4bcc0a76e971dadd19610d3ad38c768e124dc7","schema_version":"edge-lab-recorder.raw.v1","sequence":null,"source":"clob_market_ws"}
{"event_at":"2026-07-28T04:12:41.519000Z","event_fingerprint":"4a5abc0a7535deb50ae134a7fbff8e12297e5a875cdb29c2b07e57d08e381151","payload":{"connection_id":"f6725804f86a4c4eb588e4d5ed7db029","event_at":"2026-07-28T04:12:41.519000Z","event_type":"price_change","frame_hash":"0524fd0c5e436660fea1f95ccee7dea0325fa3e55864966f7bdb4940d328fccf","frame_index":0,"kind":"data","monotonic_ns":313944658535416,"payload":{"event_type":"price_change","market":"0xd412ce774cfcf8dc9f71164aac78783978aac7b03871702a3b8a481bd9dc9688","price_changes":[{"asset_id":"107603864457683460275633293642179940881969192120168665300712204232021063124301","best_ask":"0.62","best_bid":"0.6","hash":"155693c075c8f4dc90410013ebbc452af115b5ea","price":"0.01","side":"BUY","size":"5335.02"},{"asset_id":"96600821790790307414914106093858868634329285205417149685270682748367152458577","best_ask":"0.4","best_bid":"0.38","hash":"2ec15a47cf5639d4986dedae0feebb0815646e83","price":"0.99","side":"SELL","size":"5335.02"}],"timestamp":"1785211961519"},"payload_hash":"b6d4baa5268a4e24070570fb998c007ec65dfe9689891aa0a648393f341e4a1d","raw_frame":"{\"market\":\"0xd412ce774cfcf8dc9f71164aac78783978aac7b03871702a3b8a481bd9dc9688\", \"price_changes\":[{\"asset_id\":\"107603864457683460275633293642179940881969192120168665300712204232021063124301\", \"price\":\"0.01\", \"size\":\"5335.02\", \"side\":\"BUY\", \"hash\":\"155693c075c8f4dc90410013ebbc452af115b5ea\", \"best_bid\":\"0.6\", \"best_ask\":\"0.62\"}, {\"asset_id\":\"96600821790790307414914106093858868634329285205417149685270682748367152458577\", \"price\":\"0.99\", \"size\":\"5335.02\", \"side\":\"SELL\", \"hash\":\"2ec15a47cf5639d4986dedae0feebb0815646e83\", \"best_bid\":\"0.38\", \"best_ask\":\"0.4\"}], \"timestamp\":\"1785211961519\", \"event_type\":\"price_change\"}","received_at":"2026-07-28T04:12:41.581012Z","schema_version":"clob-market-ws.price_change.v1","sequence":null,"server_hash":null,"server_timestamp":"1785211961519","session_id":"2d607381e3054cee91998cdf45a4231c","source":"clob_market_ws"},"received_at":"2026-07-28T04:12:41.581012Z","record_id":"ce75473ae2e6789d908baf360c4dc7dfa15e8a748212bc44e99c0e9a7428c7fe","schema_fingerprint":"4aa3821a28b0b7c2400bc59aba4bcc0a76e971dadd19610d3ad38c768e124dc7","schema_version":"edge-lab-recorder.raw.v1","sequence":null,"source":"clob_market_ws"}
{"event_at":"2026-07-28T04:12:41.520000Z","event_fingerprint":"fb31bfd88573a326a19c0eec6e8f03fb900ba974aee8cfcfbcf31fc32cadf194","payload":{"connection_id":"f6725804f86a4c4eb588e4d5ed7db029","event_at":"2026-07-28T04:12:41.520000Z","event_type":"price_change","frame_hash":"a375a6e8a20514191de5db369981988d34800701ca5981501a0654ffbf79b831","frame_index":0,"kind":"data","monotonic_ns":313944662885791,"payload":{"event_type":"price_change","market":"0xd412ce774cfcf8dc9f71164aac78783978aac7b03871702a3b8a481bd9dc9688","price_changes":[{"asset_id":"96600821790790307414914106093858868634329285205417149685270682748367152458577","best_ask":"0.4","best_bid":"0.38","hash":"0ed9ba76d952492ef7718f756eab9110b4af3023","price":"0.37","side":"BUY","size":"91.41"},{"asset_id":"107603864457683460275633293642179940881969192120168665300712204232021063124301","best_ask":"0.62","best_bid":"0.6","hash":"18725500030f1898e76a3d515a1f14accedb0c33","price":"0.63","side":"SELL","size":"91.41"}],"timestamp":"1785211961520"},"payload_hash":"519eda4648b9a78a2b11280ecfc18f18c3333711adcf4946bc372731a0b7b691","raw_frame":"{\"market\":\"0xd412ce774cfcf8dc9f71164aac78783978aac7b03871702a3b8a481bd9dc9688\", \"price_changes\":[{\"asset_id\":\"96600821790790307414914106093858868634329285205417149685270682748367152458577\", \"price\":\"0.37\", \"size\":\"91.41\", \"side\":\"BUY\", \"hash\":\"0ed9ba76d952492ef7718f756eab9110b4af3023\", \"best_bid\":\"0.38\", \"best_ask\":\"0.4\"}, {\"asset_id\":\"107603864457683460275633293642179940881969192120168665300712204232021063124301\", \"price\":\"0.63\", \"size\":\"91.41\", \"side\":\"SELL\", \"hash\":\"18725500030f1898e76a3d515a1f14accedb0c33\", \"best_bid\":\"0.6\", \"best_ask\":\"0.62\"}], \"timestamp\":\"1785211961520\", \"event_type\":\"price_change\"}","received_at":"2026-07-28T04:12:41.585361Z","schema_version":"clob-market-ws.price_change.v1","sequence":null,"server_hash":null,"server_timestamp":"1785211961520","session_id":"2d607381e3054cee91998cdf45a4231c","source":"clob_market_ws"},"received_at":"2026-07-28T04:12:41.585361Z","record_id":"618c2071ebea6ba987ac89946b5c2f00106fa316b47bbee2b3da82463aeadd68","schema_fingerprint":"4aa3821a28b0b7c2400bc59aba4bcc0a76e971dadd19610d3ad38c768e124dc7","schema_version":"edge-lab-recorder.raw.v1","sequence":null,"source":"clob_market_ws"}
{"event_at":"2026-07-28T04:12:41.542000Z","event_fingerprint":"ce4356a2f842e672ff0cf505ed9d4bfae6991a43c0cbc270652d1146a17c0abe","payload":{"connection_id":"f6725804f86a4c4eb588e4d5ed7db029","event_at":"2026-07-28T04:12:41.542000Z","event_type":"price_change","frame_hash":"bf963535843be4fb34e79df8c70a43aeb23f02c9184248bd0e1a68a36c7e34e1","frame_index":0,"kind":"data","monotonic_ns":313944665830750,"payload":{"event_type":"price_change","market":"0xd412ce774cfcf8dc9f71164aac78783978aac7b03871702a3b8a481bd9dc9688","price_changes":[{"asset_id":"107603864457683460275633293642179940881969192120168665300712204232021063124301","best_ask":"0.62","best_bid":"0.6","hash":"a5b0bc3af8e1bbc03ea6af2e57c13c814db89da2","price":"0.01","side":"BUY","size":"5330.02"},{"asset_id":"96600821790790307414914106093858868634329285205417149685270682748367152458577","best_ask":"0.4","best_bid":"0.38","hash":"424a483687c28a23f47a037362340a976d005453","price":"0.99","side":"SELL","size":"5330.02"}],"timestamp":"1785211961542"},"payload_hash":"c469bf66f6c346a59d1da7714a57fe95f332572eed4c015f97bc99f7e0528faa","raw_frame":"{\"market\":\"0xd412ce774cfcf8dc9f71164aac78783978aac7b03871702a3b8a481bd9dc9688\", \"price_changes\":[{\"asset_id\":\"107603864457683460275633293642179940881969192120168665300712204232021063124301\", \"price\":\"0.01\", \"size\":\"5330.02\", \"side\":\"BUY\", \"hash\":\"a5b0bc3af8e1bbc03ea6af2e57c13c814db89da2\", \"best_bid\":\"0.6\", \"best_ask\":\"0.62\"}, {\"asset_id\":\"96600821790790307414914106093858868634329285205417149685270682748367152458577\", \"price\":\"0.99\", \"size\":\"5330.02\", \"side\":\"SELL\", \"hash\":\"424a483687c28a23f47a037362340a976d005453\", \"best_bid\":\"0.38\", \"best_ask\":\"0.4\"}], \"timestamp\":\"1785211961542\", \"event_type\":\"price_change\"}","received_at":"2026-07-28T04:12:41.588308Z","schema_version":"clob-market-ws.price_change.v1","sequence":null,"server_hash":null,"server_timestamp":"1785211961542","session_id":"2d607381e3054cee91998cdf45a4231c","source":"clob_market_ws"},"received_at":"2026-07-28T04:12:41.588308Z","record_id":"278ffa0a77c10aaf859902f965d852a3453dd5b4dca1aaa99a93d07ab50fe66f","schema_fingerprint":"4aa3821a28b0b7c2400bc59aba4bcc0a76e971dadd19610d3ad38c768e124dc7","schema_version":"edge-lab-recorder.raw.v1","sequence":null,"source":"clob_market_ws"}
{"event_at":"2026-07-28T04:12:41.547000Z","event_fingerprint":"47e1411dd9b060bf84c7e32d1a09b7fee2027ee5dd5068dd36085cd54fc8af96","payload":{"connection_id":"f6725804f86a4c4eb588e4d5ed7db029","event_at":"2026-07-28T04:12:41.547000Z","event_type":"price_change","frame_hash":"bf3131d62e89a62c0d040fd3bcce9881483c0a9c6641a3dc42463acd0fd478db","frame_index":0,"kind":"data","monotonic_ns":313944670242458,"payload":{"event_type":"price_change","market":"0xd412ce774cfcf8dc9f71164aac78783978aac7b03871702a3b8a481bd9dc9688","price_changes":[{"asset_id":"107603864457683460275633293642179940881969192120168665300712204232021063124301","best_ask":"0.62","best_bid":"0.6","hash":"332b926adbcaf6f906d065c37e33e57f2ffd57ba","price":"0.04","side":"BUY","size":"545"},{"asset_id":"96600821790790307414914106093858868634329285205417149685270682748367152458577","best_ask":"0.4","best_bid":"0.38","hash":"3957d946512bf9ec80e8c0a48a22a0bd73fae261","price":"0.96","side":"SELL","size":"545"}],"timestamp":"1785211961547"},"payload_hash":"c02812063bef781d320eeace636a344f27b43d812d39e1c5a7951cc6d2fd59c9","raw_frame":"{\"market\":\"0xd412ce774cfcf8dc9f71164aac78783978aac7b03871702a3b8a481bd9dc9688\", \"price_changes\":[{\"asset_id\":\"107603864457683460275633293642179940881969192120168665300712204232021063124301\", \"price\":\"0.04\", \"size\":\"545\", \"side\":\"BUY\", \"hash\":\"332b926adbcaf6f906d065c37e33e57f2ffd57ba\", \"best_bid\":\"0.6\", \"best_ask\":\"0.62\"}, {\"asset_id\":\"96600821790790307414914106093858868634329285205417149685270682748367152458577\", \"price\":\"0.96\", \"size\":\"545\", \"side\":\"SELL\", \"hash\":\"3957d946512bf9ec80e8c0a48a22a0bd73fae261\", \"best_bid\":\"0.38\", \"best_ask\":\"0.4\"}], \"timestamp\":\"1785211961547\", \"event_type\":\"price_change\"}","received_at":"2026-07-28T04:12:41.592719Z","schema_version":"clob-market-ws.price_change.v1","sequence":null,"server_hash":null,"server_timestamp":"1785211961547","session_id":"2d607381e3054cee91998cdf45a4231c","source":"clob_market_ws"},"received_at":"2026-07-28T04:12:41.592719Z","record_id":"f7612f11a1d9b563abfae54b2ae3053f16dab2da6c2f4210912c5353d6ae8f12","schema_fingerprint":"4aa3821a28b0b7c2400bc59aba4bcc0a76e971dadd19610d3ad38c768e124dc7","schema_version":"edge-lab-recorder.raw.v1","sequence":null,"source":"clob_market_ws"}
{"event_at":"2026-07-28T04:12:41.594000Z","event_fingerprint":"b66387f157a994abeddf4b0b05edcde5ede75e922bd681d3aa8664fe024f395c","payload":{"connection_id":"f6725804f86a4c4eb588e4d5ed7db029","event_at":"2026-07-28T04:12:41.594000Z","event_type":"price_change","frame_hash":"a70d85a7e4be9cad39077d1b7281135dfe5d993d23885d336f2a7b22a651caa0","frame_index":0,"kind":"data","monotonic_ns":313944673155791,"payload":{"event_type":"price_change","market":"0xd412ce774cfcf8dc9f71164aac78783978aac7b03871702a3b8a481bd9dc9688","price_changes":[{"asset_id":"107603864457683460275633293642179940881969192120168665300712204232021063124301","best_ask":"0.62","best_bid":"0.6","hash":"4248ae8a222eeabb957960e9137e8a219c6f38ec","price":"0.04","side":"BUY","size":"540"},{"asset_id":"96600821790790307414914106093858868634329285205417149685270682748367152458577","best_ask":"0.4","best_bid":"0.38","hash":"bedf17ea2461b4de5a88f3bfa0fd34e10a4d355b","price":"0.96","side":"SELL","size":"540"}],"timestamp":"1785211961594"},"payload_hash":"35a29e5e70db929db48586a505c6d6c6c20aa61183688183a8c418f98bdeb38f","raw_frame":"{\"market\":\"0xd412ce774cfcf8dc9f71164aac78783978aac7b03871702a3b8a481bd9dc9688\", \"price_changes\":[{\"asset_id\":\"107603864457683460275633293642179940881969192120168665300712204232021063124301\", \"price\":\"0.04\", \"size\":\"540\", \"side\":\"BUY\", \"hash\":\"4248ae8a222eeabb957960e9137e8a219c6f38ec\", \"best_bid\":\"0.6\", \"best_ask\":\"0.62\"}, {\"asset_id\":\"96600821790790307414914106093858868634329285205417149685270682748367152458577\", \"price\":\"0.96\", \"size\":\"540\", \"side\":\"SELL\", \"hash\":\"bedf17ea2461b4de5a88f3bfa0fd34e10a4d355b\", \"best_bid\":\"0.38\", \"best_ask\":\"0.4\"}], \"timestamp\":\"1785211961594\", \"event_type\":\"price_change\"}","received_at":"2026-07-28T04:12:41.595633Z","schema_version":"clob-market-ws.price_change.v1","sequence":null,"server_hash":null,"server_timestamp":"1785211961594","session_id":"2d607381e3054cee91998cdf45a4231c","source":"clob_market_ws"},"received_at":"2026-07-28T04:12:41.595633Z","record_id":"19825ad1126c9d6afecfe8496aff426e8a746523d33ad9af7297ebe459e77c66","schema_fingerprint":"4aa3821a28b0b7c2400bc59aba4bcc0a76e971dadd19610d3ad38c768e124dc7","schema_version":"edge-lab-recorder.raw.v1","sequence":null,"source":"clob_market_ws"}
{"event_at":"2026-07-28T04:12:41.699000Z","event_fingerprint":"061ab534cd5f5aeb375faeb15349d849930af83f3d3b9939d43111789655fd8f","payload":{"connection_id":"f6725804f86a4c4eb588e4d5ed7db029","event_at":"2026-07-28T04:12:41.699000Z","event_type":"price_change","frame_hash":"8455419ae366c17d8580fb7c36b845bd7bb6e0b2e24bcbb48b029a03c2148c7c","frame_index":0,"kind":"data","monotonic_ns":313944676761291,"payload":{"event_type":"price_change","market":"0xd412ce774cfcf8dc9f71164aac78783978aac7b03871702a3b8a481bd9dc9688","price_changes":[{"asset_id":"107603864457683460275633293642179940881969192120168665300712204232021063124301","best_ask":"0.62","best_bid":"0.6","hash":"cb43717fbb7000726557eab633a5cd04b69ad0a9","price":"0.02","side":"BUY","size":"535"},{"asset_id":"96600821790790307414914106093858868634329285205417149685270682748367152458577","best_ask":"0.4","best_bid":"0.38","hash":"8ac85359dbf0485b9ceb153153274e2e34d2d6af","price":"0.98","side":"SELL","size":"535"}],"timestamp":"1785211961699"},"payload_hash":"7bc10f3d50da71862a474b55d75f639bfb5c4671c23ebccc1065f38430e61188","raw_frame":"{\"market\":\"0xd412ce774cfcf8dc9f71164aac78783978aac7b03871702a3b8a481bd9dc9688\", \"price_changes\":[{\"asset_id\":\"107603864457683460275633293642179940881969192120168665300712204232021063124301\", \"price\":\"0.02\", \"size\":\"535\", \"side\":\"BUY\", \"hash\":\"cb43717fbb7000726557eab633a5cd04b69ad0a9\", \"best_bid\":\"0.6\", \"best_ask\":\"0.62\"}, {\"asset_id\":\"96600821790790307414914106093858868634329285205417149685270682748367152458577\", \"price\":\"0.98\", \"size\":\"535\", \"side\":\"SELL\", \"hash\":\"8ac85359dbf0485b9ceb153153274e2e34d2d6af\", \"best_bid\":\"0.38\", \"best_ask\":\"0.4\"}], \"timestamp\":\"1785211961699\", \"event_type\":\"price_change\"}","received_at":"2026-07-28T04:12:41.599238Z","schema_version":"clob-market-ws.price_change.v1","sequence":null,"server_hash":null,"server_timestamp":"1785211961699","session_id":"2d607381e3054cee91998cdf45a4231c","source":"clob_market_ws"},"received_at":"2026-07-28T04:12:41.599238Z","record_id":"7e96b274ae24c6f2c9c14aab98e3a2681e1726e4b032bf2d3d50519f39135ec9","schema_fingerprint":"4aa3821a28b0b7c2400bc59aba4bcc0a76e971dadd19610d3ad38c768e124dc7","schema_version":"edge-lab-recorder.raw.v1","sequence":null,"source":"clob_market_ws"}
{"event_at":"2026-07-28T04:12:41.749000Z","event_fingerprint":"95821e5629a60fa9ce73466ca5f92ee5aae6b88a533a5cde8941106381a93ae1","payload":{"connection_id":"f6725804f86a4c4eb588e4d5ed7db029","event_at":"2026-07-28T04:12:41.749000Z","event_type":"price_change","frame_hash":"5e45ac011086bb6c0267439eeaa07519f3da3795d4aa11e21a9fcfcce1107c8f","frame_index":0,"kind":"data","monotonic_ns":313944681197583,"payload":{"event_type":"price_change","market":"0xd412ce774cfcf8dc9f71164aac78783978aac7b03871702a3b8a481bd9dc9688","price_changes":[{"asset_id":"96600821790790307414914106093858868634329285205417149685270682748367152458577","best_ask":"0.4","best_bid":"0.38","hash":"f4a1b4337c0515ee3ad8f9ad71d0ac394e1cdf1f","price":"0.28","side":"BUY","size":"111"},{"asset_id":"107603864457683460275633293642179940881969192120168665300712204232021063124301","best_ask":"0.62","best_bid":"0.6","hash":"de3cc8f0f449c18681c11640d437dce3e4d42fed","price":"0.72","side":"SELL","size":"111"}],"timestamp":"1785211961749"},"payload_hash":"697e893f89fb9ea3f34cf38f008263d5b6e9fc625ea6e08894f98da4538c9a28","raw_frame":"{\"market\":\"0xd412ce774cfcf8dc9f71164aac78783978aac7b03871702a3b8a481bd9dc9688\", \"price_changes\":[{\"asset_id\":\"96600821790790307414914106093858868634329285205417149685270682748367152458577\", \"price\":\"0.28\", \"size\":\"111\", \"side\":\"BUY\", \"hash\":\"f4a1b4337c0515ee3ad8f9ad71d0ac394e1cdf1f\", \"best_bid\":\"0.38\", \"best_ask\":\"0.4\"}, {\"asset_id\":\"107603864457683460275633293642179940881969192120168665300712204232021063124301\", \"price\":\"0.72\", \"size\":\"111\", \"side\":\"SELL\", \"hash\":\"de3cc8f0f449c18681c11640d437dce3e4d42fed\", \"best_bid\":\"0.6\", \"best_ask\":\"0.62\"}], \"timestamp\":\"1785211961749\", \"event_type\":\"price_change\"}","received_at":"2026-07-28T04:12:41.603675Z","schema_version":"clob-market-ws.price_change.v1","sequence":null,"server_hash":null,"server_timestamp":"1785211961749","session_id":"2d607381e3054cee91998cdf45a4231c","source":"clob_market_ws"},"received_at":"2026-07-28T04:12:41.603675Z","record_id":"b1011bbcbdee2c1aca39687647e68c47f601cdb7830c8411f8dee730681533b8","schema_fingerprint":"4aa3821a28b0b7c2400bc59aba4bcc0a76e971dadd19610d3ad38c768e124dc7","schema_version":"edge-lab-recorder.raw.v1","sequence":null,"source":"clob_market_ws"}
{"event_at":"2026-07-28T04:12:41.777000Z","event_fingerprint":"1f2f26c1c1f8981dcf57ffb50878fa325c5d7644394bdcfd2e597ff7bb3c119c","payload":{"connection_id":"f6725804f86a4c4eb588e4d5ed7db029","event_at":"2026-07-28T04:12:41.777000Z","event_type":"price_change","frame_hash":"c78f17b97d50037480c43cd3ee7dc8071db0cde88ede42e12329414a22c170ce","frame_index":0,"kind":"data","monotonic_ns":313944686403833,"payload":{"event_type":"price_change","market":"0xd412ce774cfcf8dc9f71164aac78783978aac7b03871702a3b8a481bd9dc9688","price_changes":[{"asset_id":"107603864457683460275633293642179940881969192120168665300712204232021063124301","best_ask":"0.62","best_bid":"0.6","hash":"4da4bf942a5f63e9c6d97ee5b2e5ac0b6d6c7e07","price":"0.02","side":"BUY","size":"530"},{"asset_id":"96600821790790307414914106093858868634329285205417149685270682748367152458577","best_ask":"0.4","best_bid":"0.38","hash":"a12a17afc23fd998be814912f12d260504270477","price":"0.98","side":"SELL","size":"530"}],"timestamp":"1785211961777"},"payload_hash":"9ff5858560e983989a6c790deeb797529d269d21c74dd3f70f7a915b71cb56dd","raw_frame":"{\"market\":\"0xd412ce774cfcf8dc9f71164aac78783978aac7b03871702a3b8a481bd9dc9688\", \"price_changes\":[{\"asset_id\":\"107603864457683460275633293642179940881969192120168665300712204232021063124301\", \"price\":\"0.02\", \"size\":\"530\", \"side\":\"BUY\", \"hash\":\"4da4bf942a5f63e9c6d97ee5b2e5ac0b6d6c7e07\", \"best_bid\":\"0.6\", \"best_ask\":\"0.62\"}, {\"asset_id\":\"96600821790790307414914106093858868634329285205417149685270682748367152458577\", \"price\":\"0.98\", \"size\":\"530\", \"side\":\"SELL\", \"hash\":\"a12a17afc23fd998be814912f12d260504270477\", \"best_bid\":\"0.38\", \"best_ask\":\"0.4\"}], \"timestamp\":\"1785211961777\", \"event_type\":\"price_change\"}","received_at":"2026-07-28T04:12:41.608879Z","schema_version":"clob-market-ws.price_change.v1","sequence":null,"server_hash":null,"server_timestamp":"1785211961777","session_id":"2d607381e3054cee91998cdf45a4231c","source":"clob_market_ws"},"received_at":"2026-07-28T04:12:41.608879Z","record_id":"1accf8c9362d788742381a7ef7c38097aafdd12b82481f8310ad5f8df32fc3bd","schema_fingerprint":"4aa3821a28b0b7c2400bc59aba4bcc0a76e971dadd19610d3ad38c768e124dc7","schema_version":"edge-lab-recorder.raw.v1","sequence":null,"source":"clob_market_ws"}
{"event_at":"2026-07-28T04:12:41.841000Z","event_fingerprint":"7937b4339b0880ac328bce81d915a7049478e6d74d3909f9462c642719b7ed6e","payload":{"connection_id":"f6725804f86a4c4eb588e4d5ed7db029","event_at":"2026-07-28T04:12:41.841000Z","event_type":"price_change","frame_hash":"d2b814b81e48196613d34f0f71c8beeeb61410afde83e46e1899730c76c587f2","frame_index":0,"kind":"data","monotonic_ns":313944695873791,"payload":{"event_type":"price_change","market":"0xd412ce774cfcf8dc9f71164aac78783978aac7b03871702a3b8a481bd9dc9688","price_changes":[{"asset_id":"107603864457683460275633293642179940881969192120168665300712204232021063124301","best_ask":"0.62","best_bid":"0.6","hash":"6468b52c206f5a47748c437801253d98ba5a3dfc","price":"0.01","side":"BUY","size":"5335.02"},{"asset_id":"96600821790790307414914106093858868634329285205417149685270682748367152458577","best_ask":"0.4","best_bid":"0.38","hash":"eb08e0bab984fc0563cb8ad5ae30d7497655053e","price":"0.99","side":"SELL","size":"5335.02"}],"timestamp":"1785211961841"},"payload_hash":"33eb04186039217991f16b853a39923b38e81d2c0e61930eecc897836078d71c","raw_frame":"{\"market\":\"0xd412ce774cfcf8dc9f71164aac78783978aac7b03871702a3b8a481bd9dc9688\", \"price_changes\":[{\"asset_id\":\"107603864457683460275633293642179940881969192120168665300712204232021063124301\", \"price\":\"0.01\", \"size\":\"5335.02\", \"side\":\"BUY\", \"hash\":\"6468b52c206f5a47748c437801253d98ba5a3dfc\", \"best_bid\":\"0.6\", \"best_ask\":\"0.62\"}, {\"asset_id\":\"96600821790790307414914106093858868634329285205417149685270682748367152458577\", \"price\":\"0.99\", \"size\":\"5335.02\", \"side\":\"SELL\", \"hash\":\"eb08e0bab984fc0563cb8ad5ae30d7497655053e\", \"best_bid\":\"0.38\", \"best_ask\":\"0.4\"}], \"timestamp\":\"1785211961841\", \"event_type\":\"price_change\"}","received_at":"2026-07-28T04:12:41.618351Z","schema_version":"clob-market-ws.price_change.v1","sequence":null,"server_hash":null,"server_timestamp":"1785211961841","session_id":"2d607381e3054cee91998cdf45a4231c","source":"clob_market_ws"},"received_at":"2026-07-28T04:12:41.618351Z","record_id":"6095fd49e31caf45737cded3eb1f13a81371bc5c044dcfcf7e3a7ec21887d2c4","schema_fingerprint":"4aa3821a28b0b7c2400bc59aba4bcc0a76e971dadd19610d3ad38c768e124dc7","schema_version":"edge-lab-recorder.raw.v1","sequence":null,"source":"clob_market_ws"}
{"event_at":"2026-07-28T04:12:41.864000Z","event_fingerprint":"15752b42a253dc161c95ffeaa27661bf4cea845c1087a4c51d500d86d98e7d11","payload":{"connection_id":"f6725804f86a4c4eb588e4d5ed7db029","event_at":"2026-07-28T04:12:41.864000Z","event_type":"price_change","frame_hash":"3841b123282e4eb9720c70ed14a74bdbd3bd39dcdc319de05c36aa39fb83cd05","frame_index":0,"kind":"data","monotonic_ns":313944716987500,"payload":{"event_type":"price_change","market":"0xd412ce774cfcf8dc9f71164aac78783978aac7b03871702a3b8a481bd9dc9688","price_changes":[{"asset_id":"107603864457683460275633293642179940881969192120168665300712204232021063124301","best_ask":"0.62","best_bid":"0.6","hash":"8013d6d1838343c9848d7a0d65f0488271acb7f1","price":"0.04","side":"BUY","size":"545"},{"asset_id":"96600821790790307414914106093858868634329285205417149685270682748367152458577","best_ask":"0.4","best_bid":"0.38","hash":"702314f8e97ca5ffa033f07eb8e9a6aac6addc1b","price":"0.96","side":"SELL","size":"545"}],"timestamp":"1785211961864"},"payload_hash":"73da493c92e109b398c9e214425d23b5d9bd52b8ff5fa95679a2df0215cf2e0a","raw_frame":"{\"market\":\"0xd412ce774cfcf8dc9f71164aac78783978aac7b03871702a3b8a481bd9dc9688\", \"price_changes\":[{\"asset_id\":\"107603864457683460275633293642179940881969192120168665300712204232021063124301\", \"price\":\"0.04\", \"size\":\"545\", \"side\":\"BUY\", \"hash\":\"8013d6d1838343c9848d7a0d65f0488271acb7f1\", \"best_bid\":\"0.6\", \"best_ask\":\"0.62\"}, {\"asset_id\":\"96600821790790307414914106093858868634329285205417149685270682748367152458577\", \"price\":\"0.96\", \"size\":\"545\", \"side\":\"SELL\", \"hash\":\"702314f8e97ca5ffa033f07eb8e9a6aac6addc1b\", \"best_bid\":\"0.38\", \"best_ask\":\"0.4\"}], \"timestamp\":\"1785211961864\", \"event_type\":\"price_change\"}","received_at":"2026-07-28T04:12:41.639463Z","schema_version":"clob-market-ws.price_change.v1","sequence":null,"server_hash":null,"server_timestamp":"1785211961864","session_id":"2d607381e3054cee91998cdf45a4231c","source":"clob_market_ws"},"received_at":"2026-07-28T04:12:41.639463Z","record_id":"fc1e56d13862c0cfa732420ba928833a23fe841fef401acc208c228665b09674","schema_fingerprint":"4aa3821a28b0b7c2400bc59aba4bcc0a76e971dadd19610d3ad38c768e124dc7","schema_version":"edge-lab-recorder.raw.v1","sequence":null,"source":"clob_market_ws"}
{"event_at":"2026-07-28T04:12:41.867000Z","event_fingerprint":"8bb8fbeb19521d4bf0568f819627bf4b265b33a35e640ebd5c02b9032c2a5c7f","payload":{"connection_id":"f6725804f86a4c4eb588e4d5ed7db029","event_at":"2026-07-28T04:12:41.867000Z","event_type":"price_change","frame_hash":"d27fe989d8cedc55c12a214c44eed670d647ff44a836a52f4cf4d5ed944dce10","frame_index":0,"kind":"data","monotonic_ns":313944720658750,"payload":{"event_type":"price_change","market":"0xd412ce774cfcf8dc9f71164aac78783978aac7b03871702a3b8a481bd9dc9688","price_changes":[{"asset_id":"107603864457683460275633293642179940881969192120168665300712204232021063124301","best_ask":"0.62","best_bid":"0.6","hash":"e5689c892080a825770e24458a283470ff9d7991","price":"0.01","side":"BUY","size":"5330.02"},{"asset_id":"96600821790790307414914106093858868634329285205417149685270682748367152458577","best_ask":"0.4","best_bid":"0.38","hash":"20ab066a6b9488f5be69895a1a068efe42da9d40","price":"0.99","side":"SELL","size":"5330.02"}],"timestamp":"1785211961867"},"payload_hash":"5d79316a0283ccdbf8ba1f804d5b7fe1804c8a528fbddb7f6730f1f28db460c0","raw_frame":"{\"market\":\"0xd412ce774cfcf8dc9f71164aac78783978aac7b03871702a3b8a481bd9dc9688\", \"price_changes\":[{\"asset_id\":\"107603864457683460275633293642179940881969192120168665300712204232021063124301\", \"price\":\"0.01\", \"size\":\"5330.02\", \"side\":\"BUY\", \"hash\":\"e5689c892080a825770e24458a283470ff9d7991\", \"best_bid\":\"0.6\", \"best_ask\":\"0.62\"}, {\"asset_id\":\"96600821790790307414914106093858868634329285205417149685270682748367152458577\", \"price\":\"0.99\", \"size\":\"5330.02\", \"side\":\"SELL\", \"hash\":\"20ab066a6b9488f5be69895a1a068efe42da9d40\", \"best_bid\":\"0.38\", \"best_ask\":\"0.4\"}], \"timestamp\":\"1785211961867\", \"event_type\":\"price_change\"}","received_at":"2026-07-28T04:12:41.643134Z","schema_version":"clob-market-ws.price_change.v1","sequence":null,"server_hash":null,"server_timestamp":"1785211961867","session_id":"2d607381e3054cee91998cdf45a4231c","source":"clob_market_ws"},"received_at":"2026-07-28T04:12:41.643134Z","record_id":"eacfdd68cd2ef06299161cd32edbea9b4000ce3956ed3feaa7ef47576cfcf247","schema_fingerprint":"4aa3821a28b0b7c2400bc59aba4bcc0a76e971dadd19610d3ad38c768e124dc7","schema_version":"edge-lab-recorder.raw.v1","sequence":null,"source":"clob_market_ws"}
{"event_at":"2026-07-28T04:12:41.887000Z","event_fingerprint":"a41da9d01ee0ccee6d6645d5c47e9fcf837fb1c9a1a48625a2a128eaa4772d5c","payload":{"connection_id":"f6725804f86a4c4eb588e4d5ed7db029","event_at":"2026-07-28T04:12:41.887000Z","event_type":"price_change","frame_hash":"c38dfca667422769048136f29466d6e5162b4c74229773e95de6d5d0d1586668","frame_index":0,"kind":"data","monotonic_ns":313944737086125,"payload":{"event_type":"price_change","market":"0xd412ce774cfcf8dc9f71164aac78783978aac7b03871702a3b8a481bd9dc9688","price_changes":[{"asset_id":"107603864457683460275633293642179940881969192120168665300712204232021063124301","best_ask":"0.62","best_bid":"0.6","hash":"6a2b18989cc0e38e58f5ffc3f489d98ae7624295","price":"0.6","side":"BUY","size":"11"},{"asset_id":"96600821790790307414914106093858868634329285205417149685270682748367152458577","best_ask":"0.4","best_bid":"0.38","hash":"0249278d9c071315fa4ae01df919001705300f24","price":"0.4","side":"SELL","size":"11"}],"timestamp":"1785211961887"},"payload_hash":"fffc0cd9dc9819a5cdf22bcf2d324925af9fe2936055f8f3b77d1bedc06e2b14","raw_frame":"{\"market\":\"0xd412ce774cfcf8dc9f71164aac78783978aac7b03871702a3b8a481bd9dc9688\", \"price_changes\":[{\"asset_id\":\"107603864457683460275633293642179940881969192120168665300712204232021063124301\", \"price\":\"0.6\", \"size\":\"11\", \"side\":\"BUY\", \"hash\":\"6a2b18989cc0e38e58f5ffc3f489d98ae7624295\", \"best_bid\":\"0.6\", \"best_ask\":\"0.62\"}, {\"asset_id\":\"96600821790790307414914106093858868634329285205417149685270682748367152458577\", \"price\":\"0.4\", \"size\":\"11\", \"side\":\"SELL\", \"hash\":\"0249278d9c071315fa4ae01df919001705300f24\", \"best_bid\":\"0.38\", \"best_ask\":\"0.4\"}], \"timestamp\":\"1785211961887\", \"event_type\":\"price_change\"}","received_at":"2026-07-28T04:12:41.659562Z","schema_version":"clob-market-ws.price_change.v1","sequence":null,"server_hash":null,"server_timestamp":"1785211961887","session_id":"2d607381e3054cee91998cdf45a4231c","source":"clob_market_ws"},"received_at":"2026-07-28T04:12:41.659562Z","record_id":"67608bb361d2b8beff5b7f9f2eb1cbc8795ff45ecb5802d4529b32fa81c2473e","schema_fingerprint":"4aa3821a28b0b7c2400bc59aba4bcc0a76e971dadd19610d3ad38c768e124dc7","schema_version":"edge-lab-recorder.raw.v1","sequence":null,"source":"clob_market_ws"}
{"event_at":"2026-07-28T04:12:41.888000Z","event_fingerprint":"badebcb8b1720e76431beedeb07900c9036cabeee669d3ee1b12f288a51fd5d4","payload":{"connection_id":"f6725804f86a4c4eb588e4d5ed7db029","event_at":"2026-07-28T04:12:41.888000Z","event_type":"best_bid_ask","frame_hash":"fcf0fbd6ab8b0096cef463f53188bad655735427fba713bba25f56eaf3c57965","frame_index":0,"kind":"data","monotonic_ns":313944742914416,"payload":{"asset_id":"107603864457683460275633293642179940881969192120168665300712204232021063124301","best_ask":"0.62","best_bid":"0.59","event_type":"best_bid_ask","market":"0xd412ce774cfcf8dc9f71164aac78783978aac7b03871702a3b8a481bd9dc9688","spread":"0.03","timestamp":"1785211961888"},"payload_hash":"7f0441e964e2a17eeff9282276cd6d98f09b16c1fabc0bf57d96540e3a4ec138","raw_frame":"{\"market\":\"0xd412ce774cfcf8dc9f71164aac78783978aac7b03871702a3b8a481bd9dc9688\", \"asset_id\":\"107603864457683460275633293642179940881969192120168665300712204232021063124301\", \"best_bid\":\"0.59\", \"best_ask\":\"0.62\", \"spread\":\"0.03\", \"timestamp\":\"1785211961888\", \"event_type\":\"best_bid_ask\"}","received_at":"2026-07-28T04:12:41.665389Z","schema_version":"clob-market-ws.best_bid_ask.v1","sequence":null,"server_hash":null,"server_timestamp":"1785211961888","session_id":"2d607381e3054cee91998cdf45a4231c","source":"clob_market_ws"},"received_at":"2026-07-28T04:12:41.665389Z","record_id":"a0656b48ec61418a8a00f232b8443a0d4ef947ef364bdc25f5482eebdd57de32","schema_fingerprint":"8488399f31b0337811b13b266be932db7062827c2470b78bd8e9e99bab51d17d","schema_version":"edge-lab-recorder.raw.v1","sequence":null,"source":"clob_market_ws"}
{"event_at":"2026-07-28T04:12:41.888000Z","event_fingerprint":"10dbde1442e3a6dc7f4fa54749b49243777080780d1ab0eaa2efc7bbea97bbff","payload":{"connection_id":"f6725804f86a4c4eb588e4d5ed7db029","event_at":"2026-07-28T04:12:41.888000Z","event_type":"best_bid_ask","frame_hash":"9d2be5dc34eee70d067928b802ec04d513950987b165c5fb11ff4f75030dab28","frame_index":0,"kind":"data","monotonic_ns":313944747399833,"payload":{"asset_id":"96600821790790307414914106093858868634329285205417149685270682748367152458577","best_ask":"0.41","best_bid":"0.38","event_type":"best_bid_ask","market":"0xd412ce774cfcf8dc9f71164aac78783978aac7b03871702a3b8a481bd9dc9688","spread":"0.03","timestamp":"1785211961888"},"payload_hash":"13d02b46455f4513e754a3728192df1a201e8f06b33cf5a9d578c42eb82fd798","raw_frame":"{\"market\":\"0xd412ce774cfcf8dc9f71164aac78783978aac7b03871702a3b8a481bd9dc9688\", \"asset_id\":\"96600821790790307414914106093858868634329285205417149685270682748367152458577\", \"best_bid\":\"0.38\", \"best_ask\":\"0.41\", \"spread\":\"0.03\", \"timestamp\":\"1785211961888\", \"event_type\":\"best_bid_ask\"}","received_at":"2026-07-28T04:12:41.669876Z","schema_version":"clob-market-ws.best_bid_ask.v1","sequence":null,"server_hash":null,"server_timestamp":"1785211961888","session_id":"2d607381e3054cee91998cdf45a4231c","source":"clob_market_ws"},"received_at":"2026-07-28T04:12:41.669876Z","record_id":"7389791a32237d612ca88162c57a8520e358329fcf508efe1daeb146c8fbe4ee","schema_fingerprint":"8488399f31b0337811b13b266be932db7062827c2470b78bd8e9e99bab51d17d","schema_version":"edge-lab-recorder.raw.v1","sequence":null,"source":"clob_market_ws"}
{"event_at":"2026-07-28T04:12:41.888000Z","event_fingerprint":"46851a8eaabeb5ed0002c7f85b91f1e3b2584807280a353c1746ed5e1b1cbfb2","payload":{"connection_id":"f6725804f86a4c4eb588e4d5ed7db029","event_at":"2026-07-28T04:12:41.888000Z","event_type":"price_change","frame_hash":"21c5161254f4fd790ae353632a54e03a6cb50c21c4f1edc6c4fe94854a738b41","frame_index":0,"kind":"data","monotonic_ns":313944752768541,"payload":{"event_type":"price_change","market":"0xd412ce774cfcf8dc9f71164aac78783978aac7b03871702a3b8a481bd9dc9688","price_changes":[{"asset_id":"107603864457683460275633293642179940881969192120168665300712204232021063124301","best_ask":"0.62","best_bid":"0.59","hash":"80fb1c5ae2e21d7c016976a184516e8929ff3828","price":"0.6","side":"BUY","size":"0"},{"asset_id":"96600821790790307414914106093858868634329285205417149685270682748367152458577","best_ask":"0.41","best_bid":"0.38","hash":"136a912b2fdd2a433c921f82df06eef4c3a1deac","price":"0.4","side":"SELL","size":"0"}],"timestamp":"1785211961888"},"payload_hash":"3354c58e1e088b684c350a4a048f6f9f30e64b48bb327a42aa03dba702b900df","raw_frame":"{\"market\":\"0xd412ce774cfcf8dc9f71164aac78783978aac7b03871702a3b8a481bd9dc9688\", \"price_changes\":[{\"asset_id\":\"107603864457683460275633293642179940881969192120168665300712204232021063124301\", \"price\":\"0.6\", \"size\":\"0\", \"side\":\"BUY\", \"hash\":\"80fb1c5ae2e21d7c016976a184516e8929ff3828\", \"best_bid\":\"0.59\", \"best_ask\":\"0.62\"}, {\"asset_id\":\"96600821790790307414914106093858868634329285205417149685270682748367152458577\", \"price\":\"0.4\", \"size\":\"0\", \"side\":\"SELL\", \"hash\":\"136a912b2fdd2a433c921f82df06eef4c3a1deac\", \"best_bid\":\"0.38\", \"best_ask\":\"0.41\"}], \"timestamp\":\"1785211961888\", \"event_type\":\"price_change\"}","received_at":"2026-07-28T04:12:41.675245Z","schema_version":"clob-market-ws.price_change.v1","sequence":null,"server_hash":null,"server_timestamp":"1785211961888","session_id":"2d607381e3054cee91998cdf45a4231c","source":"clob_market_ws"},"received_at":"2026-07-28T04:12:41.675245Z","record_id":"e7c065020b44932a9e9b69ebfb6a140aeedf7c4e9d660101427febf346c10d25","schema_fingerprint":"4aa3821a28b0b7c2400bc59aba4bcc0a76e971dadd19610d3ad38c768e124dc7","schema_version":"edge-lab-recorder.raw.v1","sequence":null,"source":"clob_market_ws"}
