{"event_at":"2026-07-28T04:06:30.020000Z","event_fingerprint":"700d3b866aa177a204169f9492f61957eb0b05573bf6ea6668aa0e03ce6f4fd4","payload":{"connection_id":"f6725804f86a4c4eb588e4d5ed7db029","event_at":"2026-07-28T04:06:30.020000Z","event_type":"price_change","frame_hash":"7d6e67eefe4611483c9b09e2e4137b24fbc8ecaad7cfbd19e6130177cbade8d1","frame_index":0,"kind":"data","monotonic_ns":313572933317000,"payload":{"event_type":"price_change","market":"0xd412ce774cfcf8dc9f71164aac78783978aac7b03871702a3b8a481bd9dc9688","price_changes":[{"asset_id":"96600821790790307414914106093858868634329285205417149685270682748367152458577","best_ask":"0.39","best_bid":"0.38","hash":"c44e53441ec7e4131b9567d9473f302103d60b61","price":"0.01","side":"BUY","size":"5613.02"},{"asset_id":"107603864457683460275633293642179940881969192120168665300712204232021063124301","best_ask":"0.62","best_bid":"0.61","hash":"c96f8646f3df635dc0356a358111b5866f6680c4","price":"0.99","side":"SELL","size":"5613.02"}],"timestamp":"1785211590020"},"payload_hash":"aef5042ba1080c388486c26d47ce304d68737c55a55a8497311a90f4d740cbd9","raw_frame":"{\"market\":\"0xd412ce774cfcf8dc9f71164aac78783978aac7b03871702a3b8a481bd9dc9688\", \"price_changes\":[{\"asset_id\":\"96600821790790307414914106093858868634329285205417149685270682748367152458577\", \"price\":\"0.01\", \"size\":\"5613.02\", \"side\":\"BUY\", \"hash\":\"c44e53441ec7e4131b9567d9473f302103d60b61\", \"best_bid\":\"0.38\", \"best_ask\":\"0.39\"}, {\"asset_id\":\"107603864457683460275633293642179940881969192120168665300712204232021063124301\", \"price\":\"0.99\", \"size\":\"5613.02\", \"side\":\"SELL\", \"hash\":\"c96f8646f3df635dc0356a358111b5866f6680c4\", \"best_bid\":\"0.61\", \"best_ask\":\"0.62\"}], \"timestamp\":\"1785211590020\", \"event_type\":\"price_change\"}","received_at":"2026-07-28T04:06:29.882513Z","schema_version":"clob-market-ws.price_change.v1","sequence":null,"server_hash":null,"server_timestamp":"1785211590020","session_id":"2d607381e3054cee91998cdf45a4231c","source":"clob_market_ws"},"received_at":"2026-07-28T04:06:29.882513Z","record_id":"2a1c894b3f75c7ca6744c139295d52c07b61e60a1c495679b31f89efaa01de6d","schema_fingerprint":"4aa3821a28b0b7c2400bc59aba4bcc0a76e971dadd19610d3ad38c768e124dc7","schema_version":"edge-lab-recorder.raw.v1","sequence":null,"source":"clob_market_ws"}
{"event_at":"2026-07-28T04:06:30.024000Z","event_fingerprint":"b489b20e4e1e6f696b5bce8393359542a58745f15c38fba97eb6a1b873586d73","payload":{"connection_id":"f6725804f86a4c4eb588e4d5ed7db029","event_at":"2026-07-28T04:06:30.024000Z","event_type":"price_change","frame_hash":"1f51414c73f3eee72352147c219122401ca57524d982e5934b7cc20f4046af12","frame_index":0,"kind":"data","monotonic_ns":313572950460375,"payload":{"event_type":"price_change","market":"0xd412ce774cfcf8dc9f71164aac78783978aac7b03871702a3b8a481bd9dc9688","price_changes":[{"asset_id":"96600821790790307414914106093858868634329285205417149685270682748367152458577","best_ask":"0.39","best_bid":"0.38","hash":"5e358862534b9a342f7144697e923c5963351f11","price":"0.01","side":"BUY","size":"5618.02"},{"asset_id":"107603864457683460275633293642179940881969192120168665300712204232021063124301","best_ask":"0.62","best_bid":"0.61","hash":"aab2bbfcf86893cb09e159c0174fae0806b84b0f","price":"0.99","side":"SELL","size":"5618.02"}],"timestamp":"1785211590024"},"payload_hash":"a70395c8dd8a858a74336e6f5424d78ba0fbb0351989b3c59b7c730b6cbc41aa","raw_frame":"{\"market\":\"0xd412ce774cfcf8dc9f71164aac78783978aac7b03871702a3b8a481bd9dc9688\", \"price_changes\":[{\"asset_id\":\"96600821790790307414914106093858868634329285205417149685270682748367152458577\", \"price\":\"0.01\", \"size\":\"5618.02\", \"side\":\"BUY\", \"hash\":\"5e358862534b9a342f7144697e923c5963351f11\", \"best_bid\":\"0.38\", \"best_ask\":\"0.39\"}, {\"asset_id\":\"107603864457683460275633293642179940881969192120168665300712204232021063124301\", \"price\":\"0.99\", \"size\":\"5618.02\", \"side\":\"SELL\", \"hash\":\"aab2bbfcf86893cb09e159c0174fae0806b84b0f\", \"best_bid\":\"0.61\", \"best_ask\":\"0.62\"}], \"timestamp\":\"1785211590024\", \"event_type\":\"price_change\"}","received_at":"2026-07-28T04:06:29.899657Z","schema_version":"clob-market-ws.price_change.v1","sequence":null,"server_hash":null,"server_timestamp":"1785211590024","session_id":"2d607381e3054cee91998cdf45a4231c","source":"clob_market_ws"},"received_at":"2026-07-28T04:06:29.899657Z","record_id":"a00a7214d4ec809ebe5651e2ed9452e48e7e3a9aaef27a1f66fb89e518203634","schema_fingerprint":"4aa3821a28b0b7c2400bc59aba4bcc0a76e971dadd19610d3ad38c768e124dc7","schema_version":"edge-lab-recorder.raw.v1","sequence":null,"source":"clob_market_ws"}
{"event_at":"2026-07-28T04:06:30.027000Z","event_fingerprint":"ce0c08d1de9de66c5f04799e00fc0c77b27f13171357f318e553f6b6b7ab2431","payload":{"connection_id":"f6725804f86a4c4eb588e4d5ed7db029","event_at":"2026-07-28T04:06:30.027000Z","event_type":"price_change","frame_hash":"bab21423bb54680110e6bcdc999913beeec128294c1a5e9c887ba7361866783f","frame_index":0,"kind":"data","monotonic_ns":313572955336333,"payload":{"event_type":"price_change","market":"0xd412ce774cfcf8dc9f71164aac78783978aac7b03871702a3b8a481bd9dc9688","price_changes":[{"asset_id":"107603864457683460275633293642179940881969192120168665300712204232021063124301","best_ask":"0.62","best_bid":"0.61","hash":"72b234de26d315443e29e1db996ede3d88a25fd8","price":"0.49","side":"BUY","size":"150"},{"asset_id":"96600821790790307414914106093858868634329285205417149685270682748367152458577","best_ask":"0.39","best_bid":"0.38","hash":"593f30ee6805d9ebb9bdef2083ba82bfa3a79fb0","price":"0.51","side":"SELL","size":"150"}],"timestamp":"1785211590027"},"payload_hash":"254765f674b93e0d355d9ac3e39137dc4ed9fb2de128a08938c678f9fb39d1da","raw_frame":"{\"market\":\"0xd412ce774cfcf8dc9f71164aac78783978aac7b03871702a3b8a481bd9dc9688\", \"price_changes\":[{\"asset_id\":\"107603864457683460275633293642179940881969192120168665300712204232021063124301\", \"price\":\"0.49\", \"size\":\"150\", \"side\":\"BUY\", \"hash\":\"72b234de26d315443e29e1db996ede3d88a25fd8\", \"best_bid\":\"0.61\", \"best_ask\":\"0.62\"}, {\"asset_id\":\"96600821790790307414914106093858868634329285205417149685270682748367152458577\", \"price\":\"0.51\", \"size\":\"150\", \"side\":\"SELL\", \"hash\":\"593f30ee6805d9ebb9bdef2083ba82bfa3a79fb0\", \"best_bid\":\"0.38\", \"best_ask\":\"0.39\"}], \"timestamp\":\"1785211590027\", \"event_type\":\"price_change\"}","received_at":"2026-07-28T04:06:29.904534Z","schema_version":"clob-market-ws.price_change.v1","sequence":null,"server_hash":null,"server_timestamp":"1785211590027","session_id":"2d607381e3054cee91998cdf45a4231c","source":"clob_market_ws"},"received_at":"2026-07-28T04:06:29.904534Z","record_id":"6039fb5dd512783ad1c5d2b5e88581643f105e69760ac5912ebe8cb562938c0c","schema_fingerprint":"4aa3821a28b0b7c2400bc59aba4bcc0a76e971dadd19610d3ad38c768e124dc7","schema_version":"edge-lab-recorder.raw.v1","sequence":null,"source":"clob_market_ws"}
{"event_at":"2026-07-28T04:06:30.029000Z","event_fingerprint":"b98c6736b302e3576d6b96715d40c70036ef6349e231c0598f115029cddd146e","payload":{"connection_id":"f6725804f86a4c4eb588e4d5ed7db029","event_at":"2026-07-28T04:06:30.029000Z","event_type":"price_change","frame_hash":"a4ef67a0e037d58c78c4200ef8ffdacb2dfeb29ea8a7bbabbc67cbbf81b58cb3","frame_index":0,"kind":"data","monotonic_ns":313572958554166,"payload":{"event_type":"price_change","market":"0xd412ce774cfcf8dc9f71164aac78783978aac7b03871702a3b8a481bd9dc9688","price_changes":[{"asset_id":"107603864457683460275633293642179940881969192120168665300712204232021063124301","best_ask":"0.62","best_bid":"0.61","hash":"9632c49c007d67ee6d374a9ef2d179213644e8b5","price":"0.6","side":"BUY","size":"81"},{"asset_id":"96600821790790307414914106093858868634329285205417149685270682748367152458577","best_ask":"0.39","best_bid":"0.38","hash":"fef26f591dfb5055d46dab4f3242bf12d8d80bf7","price":"0.4","side":"SELL","size":"81"}],"timestamp":"1785211590029"},"payload_hash":"66d9beebef4099fe089fbb0082098b9c70fa137cb9db29327dcf5d579770a620","raw_frame":"{\"market\":\"0xd412ce774cfcf8dc9f71164aac78783978aac7b03871702a3b8a481bd9dc9688\", \"price_changes\":[{\"asset_id\":\"107603864457683460275633293642179940881969192120168665300712204232021063124301\", \"price\":\"0.6\", \"size\":\"81\", \"side\":\"BUY\", \"hash\":\"9632c49c007d67ee6d374a9ef2d179213644e8b5\", \"best_bid\":\"0.61\", \"best_ask\":\"0.62\"}, {\"asset_id\":\"96600821790790307414914106093858868634329285205417149685270682748367152458577\", \"price\":\"0.4\", \"size\":\"81\", \"side\":\"SELL\", \"hash\":\"fef26f591dfb5055d46dab4f3242bf12d8d80bf7\", \"best_bid\":\"0.38\", \"best_ask\":\"0.39\"}], \"timestamp\":\"1785211590029\", \"event_type\":\"price_change\"}","received_at":"2026-07-28T04:06:29.907753Z","schema_version":"clob-market-ws.price_change.v1","sequence":null,"server_hash":null,"server_timestamp":"1785211590029","session_id":"2d607381e3054cee91998cdf45a4231c","source":"clob_market_ws"},"received_at":"2026-07-28T04:06:29.907753Z","record_id":"78b85147b9417530025bca2cea7b10de760a65ad0ba95a7c594b803ac7374931","schema_fingerprint":"4aa3821a28b0b7c2400bc59aba4bcc0a76e971dadd19610d3ad38c768e124dc7","schema_version":"edge-lab-recorder.raw.v1","sequence":null,"source":"clob_market_ws"}
{"event_at":"2026-07-28T04:06:30.029000Z","event_fingerprint":"823a8a1a897ecbd73e4d1869c21d4281e04414c7f6af43693c7997f7d0572364","payload":{"connection_id":"f6725804f86a4c4eb588e4d5ed7db029","event_at":"2026-07-28T04:06:30.029000Z","event_type":"price_change","frame_hash":"10a9dad19508d2a6aa8f065a13ebf7de7b7e72c4e1b1b3d3e56c6a8469fea6a5","frame_index":0,"kind":"data","monotonic_ns":313572961497916,"payload":{"event_type":"price_change","market":"0xd412ce774cfcf8dc9f71164aac78783978aac7b03871702a3b8a481bd9dc9688","price_changes":[{"asset_id":"96600821790790307414914106093858868634329285205417149685270682748367152458577","best_ask":"0.39","best_bid":"0.38","hash":"fef26f591dfb5055d46dab4f3242bf12d8d80bf7","price":"0.3","side":"BUY","size":"177"},{"asset_id":"107603864457683460275633293642179940881969192120168665300712204232021063124301","best_ask":"0.62","best_bid":"0.61","hash":"9632c49c007d67ee6d374a9ef2d179213644e8b5","price":"0.7","side":"SELL","size":"177"}],"timestamp":"1785211590029"},"payload_hash":"c021a84b447bd96821b86c00cb959c0604369a86c3a576e9a996ce38d2b78d80","raw_frame":"{\"market\":\"0xd412ce774cfcf8dc9f71164aac78783978aac7b03871702a3b8a481bd9dc9688\", \"price_changes\":[{\"asset_id\":\"96600821790790307414914106093858868634329285205417149685270682748367152458577\", \"price\":\"0.3\", \"size\":\"177\", \"side\":\"BUY\", \"hash\":\"fef26f591dfb5055d46dab4f3242bf12d8d80bf7\", \"best_bid\":\"0.38\", \"best_ask\":\"0.39\"}, {\"asset_id\":\"107603864457683460275633293642179940881969192120168665300712204232021063124301\", \"price\":\"0.7\", \"size\":\"177\", \"side\":\"SELL\", \"hash\":\"9632c49c007d67ee6d374a9ef2d179213644e8b5\", \"best_bid\":\"0.61\", \"best_ask\":\"0.62\"}], \"timestamp\":\"1785211590029\", \"event_type\":\"price_change\"}","received_at":"2026-07-28T04:06:29.910696Z","schema_version":"clob-market-ws.price_change.v1","sequence":null,"server_hash":null,"server_timestamp":"1785211590029","session_id":"2d607381e3054cee91998cdf45a4231c","source":"clob_market_ws"},"received_at":"2026-07-28T04:06:29.910696Z","record_id":"1686bb1ec417b64e7c296ca55548166cb3b863ec67e06d4373851f3a0ed96c73","schema_fingerprint":"4aa3821a28b0b7c2400bc59aba4bcc0a76e971dadd19610d3ad38c768e124dc7","schema_version":"edge-lab-recorder.raw.v1","sequence":null,"source":"clob_market_ws"}
{"event_at":"2026-07-28T04:06:30.040000Z","event_fingerprint":"b08d679f1abbdcf5918db15c85738357b9d157b73eefc190b6e255f5776d3c32","payload":{"connection_id":"f6725804f86a4c4eb588e4d5ed7db029","event_at":"2026-07-28T04:06:30.040000Z","event_type":"price_change","frame_hash":"a1808da9988fe4b7a228ec0142a4e656c8592bf4d656db2a485739d096fa0381","frame_index":0,"kind":"data","monotonic_ns":313572964609250,"payload":{"event_type":"price_change","market":"0xd412ce774cfcf8dc9f71164aac78783978aac7b03871702a3b8a481bd9dc9688","price_changes":[{"asset_id":"96600821790790307414914106093858868634329285205417149685270682748367152458577","best_ask":"0.39","best_bid":"0.38","hash":"38af32330032dba801bad355672336eaeac7c826","price":"0.01","side":"BUY","size":"5613.02"},{"asset_id":"107603864457683460275633293642179940881969192120168665300712204232021063124301","best_ask":"0.62","best_bid":"0.61","hash":"7dfe356d21bdbc26d8cba853eb4f2454eb8c5d7a","price":"0.99","side":"SELL","size":"5613.02"}],"timestamp":"1785211590040"},"payload_hash":"14605a37904168f2d4520708a4365129e1aedff5c977b622ec970a44725caf79","raw_frame":"{\"market\":\"0xd412ce774cfcf8dc9f71164aac78783978aac7b03871702a3b8a481bd9dc9688\", \"price_changes\":[{\"asset_id\":\"96600821790790307414914106093858868634329285205417149685270682748367152458577\", \"price\":\"0.01\", \"size\":\"5613.02\", \"side\":\"BUY\", \"hash\":\"38af32330032dba801bad355672336eaeac7c826\", \"best_bid\":\"0.38\", \"best_ask\":\"0.39\"}, {\"asset_id\":\"107603864457683460275633293642179940881969192120168665300712204232021063124301\", \"price\":\"0.99\", \"size\":\"5613.02\", \"side\":\"SELL\", \"hash\":\"7dfe356d21bdbc26d8cba853eb4f2454eb8c5d7a\", \"best_bid\":\"0.61\", \"best_ask\":\"0.62\"}], \"timestamp\":\"1785211590040\", \"event_type\":\"price_change\"}","received_at":"2026-07-28T04:06:29.913808Z","schema_version":"clob-market-ws.price_change.v1","sequence":null,"server_hash":null,"server_timestamp":"1785211590040","session_id":"2d607381e3054cee91998cdf45a4231c","source":"clob_market_ws"},"received_at":"2026-07-28T04:06:29.913808Z","record_id":"2955ca61d3ff700138fb0bce42f25ea1dca23d39bafa0f46b9b670c10259ca51","schema_fingerprint":"4aa3821a28b0b7c2400bc59aba4bcc0a76e971dadd19610d3ad38c768e124dc7","schema_version":"edge-lab-recorder.raw.v1","sequence":null,"source":"clob_market_ws"}
{"event_at":"2026-07-28T04:06:30.042000Z","event_fingerprint":"f48b7f91c58d237679809eb4ea5e547c7c0948e15ca964e622d2d2a7965c1b28","payload":{"connection_id":"f6725804f86a4c4eb588e4d5ed7db029","event_at":"2026-07-28T04:06:30.042000Z","event_type":"price_change","frame_hash":"bfda1c3b52708153b07dd76d1cb4be0b101c082b7b391aeb2ecc0113a91fd935","frame_index":0,"kind":"data","monotonic_ns":313572967874625,"payload":{"event_type":"price_change","market":"0xd412ce774cfcf8dc9f71164aac78783978aac7b03871702a3b8a481bd9dc9688","price_changes":[{"asset_id":"107603864457683460275633293642179940881969192120168665300712204232021063124301","best_ask":"0.62","best_bid":"0.61","hash":"3eae02c281da0e6db0814f3a279032b1633b0161","price":"0.6","side":"BUY","size":"61"},{"asset_id":"96600821790790307414914106093858868634329285205417149685270682748367152458577","best_ask":"0.39","best_bid":"0.38","hash":"44587ddaaccfdcd291f8a7d1dd8ab30f90603639","price":"0.4","side":"SELL","size":"61"}],"timestamp":"1785211590042"},"payload_hash":"347e97f857d0a3ed875d94bc76f82c92f9028b147ada668a0f93fa4453814c87","raw_frame":"{\"market\":\"0xd412ce774cfcf8dc9f71164aac78783978aac7b03871702a3b8a481bd9dc9688\", \"price_changes\":[{\"asset_id\":\"107603864457683460275633293642179940881969192120168665300712204232021063124301\", \"price\":\"0.6\", \"size\":\"61\", \"side\":\"BUY\", \"hash\":\"3eae02c281da0e6db0814f3a279032b1633b0161\", \"best_bid\":\"0.61\", \"best_ask\":\"0.62\"}, {\"asset_id\":\"96600821790790307414914106093858868634329285205417149685270682748367152458577\", \"price\":\"0.4\", \"size\":\"61\", \"side\":\"SELL\", \"hash\":\"44587ddaaccfdcd291f8a7d1dd8ab30f90603639\", \"best_bid\":\"0.38\", \"best_ask\":\"0.39\"}], \"timestamp\":\"1785211590042\", \"event_type\":\"price_change\"}","received_at":"2026-07-28T04:06:29.917072Z","schema_version":"clob-market-ws.price_change.v1","sequence":null,"server_hash":null,"server_timestamp":"1785211590042","session_id":"2d607381e3054cee91998cdf45a4231c","source":"clob_market_ws"},"received_at":"2026-07-28T04:06:29.917072Z","record_id":"fdd9fe00c6b758c3bb55fd650a010f329b143c307b5eb307881536085a5e3746","schema_fingerprint":"4aa3821a28b0b7c2400bc59aba4bcc0a76e971dadd19610d3ad38c768e124dc7","schema_version":"edge-lab-recorder.raw.v1","sequence":null,"source":"clob_market_ws"}
{"event_at":"2026-07-28T04:06:30.042000Z","event_fingerprint":"0226bfdd3d2e213486eb8f9f14a3979085c90755a531d8d3f92f4d96dff3b013","payload":{"connection_id":"f6725804f86a4c4eb588e4d5ed7db029","event_at":"2026-07-28T04:06:30.042000Z","event_type":"price_change","frame_hash":"333f808ba76d8dc7410ff42cb08100752c3dbf0151ced56d964aa01b58dd5cb3","frame_index":0,"kind":"data","monotonic_ns":313572970920166,"payload":{"event_type":"price_change","market":"0xd412ce774cfcf8dc9f71164aac78783978aac7b03871702a3b8a481bd9dc9688","price_changes":[{"asset_id":"96600821790790307414914106093858868634329285205417149685270682748367152458577","best_ask":"0.39","best_bid":"0.38","hash":"44587ddaaccfdcd291f8a7d1dd8ab30f90603639","price":"0.3","side":"BUY","size":"157"},{"asset_id":"107603864457683460275633293642179940881969192120168665300712204232021063124301","best_ask":"0.62","best_bid":"0.61","hash":"3eae02c281da0e6db0814f3a279032b1633b0161","price":"0.7","side":"SELL","size":"157"}],"timestamp":"1785211590042"},"payload_hash":"981e9cd39b87dcaf8e6a6e144146243d622f4644fe2638fa1ff3a5488a25df62","raw_frame":"{\"market\":\"0xd412ce774cfcf8dc9f71164aac78783978aac7b03871702a3b8a481bd9dc9688\", \"price_changes\":[{\"asset_id\":\"96600821790790307414914106093858868634329285205417149685270682748367152458577\", \"price\":\"0.3\", \"size\":\"157\", \"side\":\"BUY\", \"hash\":\"44587ddaaccfdcd291f8a7d1dd8ab30f90603639\", \"best_bid\":\"0.38\", \"best_ask\":\"0.39\"}, {\"asset_id\":\"107603864457683460275633293642179940881969192120168665300712204232021063124301\", \"price\":\"0.7\", \"size\":\"157\", \"side\":\"SELL\", \"hash\":\"3eae02c281da0e6db0814f3a279032b1633b0161\", \"best_bid\":\"0.61\", \"best_ask\":\"0.62\"}], \"timestamp\":\"1785211590042\", \"event_type\":\"price_change\"}","received_at":"2026-07-28T04:06:29.920118Z","schema_version":"clob-market-ws.price_change.v1","sequence":null,"server_hash":null,"server_timestamp":"1785211590042","session_id":"2d607381e3054cee91998cdf45a4231c","source":"clob_market_ws"},"received_at":"2026-07-28T04:06:29.920118Z","record_id":"ec18592ca659a66a4bb35f5fa4d42d781eb4a1e2da8b797119b672049285d49f","schema_fingerprint":"4aa3821a28b0b7c2400bc59aba4bcc0a76e971dadd19610d3ad38c768e124dc7","schema_version":"edge-lab-recorder.raw.v1","sequence":null,"source":"clob_market_ws"}
{"event_at":"2026-07-28T04:06:30.048000Z","event_fingerprint":"a5157e164863019b75c5a841efc6d5f51fd02063644d4be38b2d326448c68032","payload":{"connection_id":"f6725804f86a4c4eb588e4d5ed7db029","event_at":"2026-07-28T04:06:30.048000Z","event_type":"price_change","frame_hash":"fff986701ed3fc6f6af3172338087c1dbf2bd6233200baf47b3d9665f89ba266","frame_index":0,"kind":"data","monotonic_ns":313572975450458,"payload":{"event_type":"price_change","market":"0xd412ce774cfcf8dc9f71164aac78783978aac7b03871702a3b8a481bd9dc9688","price_changes":[{"asset_id":"107603864457683460275633293642179940881969192120168665300712204232021063124301","best_ask":"0.62","best_bid":"0.61","hash":"c8599645e087449b1f24d23e45a586e591aeeed3","price":"0.04","side":"BUY","size":"618.09"},{"asset_id":"96600821790790307414914106093858868634329285205417149685270682748367152458577","best_ask":"0.39","best_bid":"0.38","hash":"6464c986470b1697511f64d2a03becbd3c487d9b","price":"0.96","side":"SELL","size":"618.09"}],"timestamp":"1785211590048"},"payload_hash":"c94abb83dcf7ae0ca8543ce06c251c8a95c4f713908a994ab39c6c270b0c0610","raw_frame":"{\"market\":\"0xd412ce774cfcf8dc9f71164aac78783978aac7b03871702a3b8a481bd9dc9688\", \"price_changes\":[{\"asset_id\":\"107603864457683460275633293642179940881969192120168665300712204232021063124301\", \"price\":\"0.04\", \"size\":\"618.09\", \"side\":\"BUY\", \"hash\":\"c8599645e087449b1f24d23e45a586e591aeeed3\", \"best_bid\":\"0.61\", \"best_ask\":\"0.62\"}, {\"asset_id\":\"96600821790790307414914106093858868634329285205417149685270682748367152458577\", \"price\":\"0.96\", \"size\":\"618.09\", \"side\":\"SELL\", \"hash\":\"6464c986470b1697511f64d2a03becbd3c487d9b\", \"best_bid\":\"0.38\", \"best_ask\":\"0.39\"}], \"timestamp\":\"1785211590048\", \"event_type\":\"price_change\"}","received_at":"2026-07-28T04:06:29.924649Z","schema_version":"clob-market-ws.price_change.v1","sequence":null,"server_hash":null,"server_timestamp":"1785211590048","session_id":"2d607381e3054cee91998cdf45a4231c","source":"clob_market_ws"},"received_at":"2026-07-28T04:06:29.924649Z","record_id":"143e2c2f6fbd41c453e2dfb534f9c686f0b1d6685214604b1a772979136ed4e4","schema_fingerprint":"4aa3821a28b0b7c2400bc59aba4bcc0a76e971dadd19610d3ad38c768e124dc7","schema_version":"edge-lab-recorder.raw.v1","sequence":null,"source":"clob_market_ws"}
{"event_at":"2026-07-28T04:06:30.103000Z","event_fingerprint":"9d6f06f30de77fe159c8aa88fba5dfb2dffbd8893d21c6dd638b6171f6b78137","payload":{"connection_id":"f6725804f86a4c4eb588e4d5ed7db029","event_at":"2026-07-28T04:06:30.103000Z","event_type":"price_change","frame_hash":"ea79059a3f8cdacc0b41f23a9b5200864a7aebb5a3bfe70c091034078c1adbcf","frame_index":0,"kind":"data","monotonic_ns":313572979973166,"payload":{"event_type":"price_change","market":"0xd412ce774cfcf8dc9f71164aac78783978aac7b03871702a3b8a481bd9dc9688","price_changes":[{"asset_id":"107603864457683460275633293642179940881969192120168665300712204232021063124301","best_ask":"0.62","best_bid":"0.61","hash":"f0d8571b461635fece5235544ec71132a49c982c","price":"0.65","side":"SELL","size":"65.98"},{"asset_id":"96600821790790307414914106093858868634329285205417149685270682748367152458577","best_ask":"0.39","best_bid":"0.38","hash":"4623b01cb728c5e4cf2640002b638312cc305848","price":"0.35","side":"BUY","size":"65.98"}],"timestamp":"1785211590103"},"payload_hash":"f1f6140c4e18d83d92bc748ab1389d49e6bb9c361f8763b5d7c471ea033f8341","raw_frame":"{\"market\":\"0xd412ce774cfcf8dc9f71164aac78783978aac7b03871702a3b8a481bd9dc9688\", \"price_changes\":[{\"asset_id\":\"107603864457683460275633293642179940881969192120168665300712204232021063124301\", \"price\":\"0.65\", \"size\":\"65.98\", \"side\":\"SELL\", \"hash\":\"f0d8571b461635fece5235544ec71132a49c982c\", \"best_bid\":\"0.61\", \"best_ask\":\"0.62\"}, {\"asset_id\":\"96600821790790307414914106093858868634329285205417149685270682748367152458577\", \"price\":\"0.35\", \"size\":\"65.98\", \"side\":\"BUY\", \"hash\":\"4623b01cb728c5e4cf2640002b638312cc305848\", \"best_bid\":\"0.38\", \"best_ask\":\"0.39\"}], \"timestamp\":\"1785211590103\", \"event_type\":\"price_change\"}","received_at":"2026-07-28T04:06:29.929172Z","schema_version":"clob-market-ws.price_change.v1","sequence":null,"server_hash":null,"server_timestamp":"1785211590103","session_id":"2d607381e3054cee91998cdf45a4231c","source":"clob_market_ws"},"received_at":"2026-07-28T04:06:29.929172Z","record_id":"a40347b8615d5fd567d7a6b8cef6e87dcf274891be68b52183ac5d276ea2ab89","schema_fingerprint":"4aa3821a28b0b7c2400bc59aba4bcc0a76e971dadd19610d3ad38c768e124dc7","schema_version":"edge-lab-recorder.raw.v1","sequence":null,"source":"clob_market_ws"}
{"event_at":"2026-07-28T04:06:30.120000Z","event_fingerprint":"5e471bdec6d4254366633e92a555299ce59c5b108dce05b909123f4df72e8123","payload":{"connection_id":"f6725804f86a4c4eb588e4d5ed7db029","event_at":"2026-07-28T04:06:30.120000Z","event_type":"price_change","frame_hash":"b32a59ff5aca7f356a7cd2c91dbc2f45561848ef7fee429a0430e98d750366c1","frame_index":0,"kind":"data","monotonic_ns":313572983749416,"payload":{"event_type":"price_change","market":"0xd412ce774cfcf8dc9f71164aac78783978aac7b03871702a3b8a481bd9dc9688","price_changes":[{"asset_id":"107603864457683460275633293642179940881969192120168665300712204232021063124301","best_ask":"0.62","best_bid":"0.61","hash":"58c414b0cbe787a93ed78e0af2632df95b20e950","price":"0.01","side":"BUY","size":"5643.02"},{"asset_id":"96600821790790307414914106093858868634329285205417149685270682748367152458577","best_ask":"0.39","best_bid":"0.38","hash":"510f82a94f8c3fb499491ac4c0cb2823de452691","price":"0.99","side":"SELL","size":"5643.02"}],"timestamp":"1785211590120"},"payload_hash":"1c3dfa06c5ca1b5d0d61b04d9b3c0565220fa5b43580a7938ea156ad5adddead","raw_frame":"{\"market\":\"0xd412ce774cfcf8dc9f71164aac78783978aac7b03871702a3b8a481bd9dc9688\", \"price_changes\":[{\"asset_id\":\"107603864457683460275633293642179940881969192120168665300712204232021063124301\", \"price\":\"0.01\", \"size\":\"5643.02\", \"side\":\"BUY\", \"hash\":\"58c414b0cbe787a93ed78e0af2632df95b20e950\", \"best_bid\":\"0.61\", \"best_ask\":\"0.62\"}, {\"asset_id\":\"96600821790790307414914106093858868634329285205417149685270682748367152458577\", \"price\":\"0.99\", \"size\":\"5643.02\", \"side\":\"SELL\", \"hash\":\"510f82a94f8c3fb499491ac4c0cb2823de452691\", \"best_bid\":\"0.38\", \"best_ask\":\"0.39\"}], \"timestamp\":\"1785211590120\", \"event_type\":\"price_change\"}","received_at":"2026-07-28T04:06:29.932949Z","schema_version":"clob-market-ws.price_change.v1","sequence":null,"server_hash":null,"server_timestamp":"1785211590120","session_id":"2d607381e3054cee91998cdf45a4231c","source":"clob_market_ws"},"received_at":"2026-07-28T04:06:29.932949Z","record_id":"b6da4f3108e2f4d05e1d97463006ffa61be560ea31eeb121c5885b32eb1fa97e","schema_fingerprint":"4aa3821a28b0b7c2400bc59aba4bcc0a76e971dadd19610d3ad38c768e124dc7","schema_version":"edge-lab-recorder.raw.v1","sequence":null,"source":"clob_market_ws"}
{"event_at":"2026-07-28T04:06:30.128000Z","event_fingerprint":"33883bfbcdd0a4eceee439a945ef356b6df7878884244f2e43d1220d06044759","payload":{"connection_id":"f6725804f86a4c4eb588e4d5ed7db029","event_at":"2026-07-28T04:06:30.128000Z","event_type":"price_change","frame_hash":"cf105df5e77f338371b648671fe6a520aa977074dd181555d24546bfeda9f95e","frame_index":0,"kind":"data","monotonic_ns":313572986127708,"payload":{"event_type":"price_change","market":"0xd412ce774cfcf8dc9f71164aac78783978aac7b03871702a3b8a481bd9dc9688","price_changes":[{"asset_id":"107603864457683460275633293642179940881969192120168665300712204232021063124301","best_ask":"0.62","best_bid":"0.61","hash":"069b70cffa7f03551d792697a3cada4f324f4f93","price":"0.04","side":"BUY","size":"623.09"},{"asset_id":"96600821790790307414914106093858868634329285205417149685270682748367152458577","best_ask":"0.39","best_bid":"0.38","hash":"46c3391220b5ef48b639b0841af444a43b116bf9","price":"0.96","side":"SELL","size":"623.09"}],"timestamp":"1785211590128"},"payload_hash":"7667edc93441d335a11e939923a972af6f0a4f22ad990c12db8d6a1114f2afa2","raw_frame":"{\"market\":\"0xd412ce774cfcf8dc9f71164aac78783978aac7b03871702a3b8a481bd9dc9688\", \"price_changes\":[{\"asset_id\":\"107603864457683460275633293642179940881969192120168665300712204232021063124301\", \"price\":\"0.04\", \"size\":\"623.09\", \"side\":\"BUY\", \"hash\":\"069b70cffa7f03551d792697a3cada4f324f4f93\", \"best_bid\":\"0.61\", \"best_ask\":\"0.62\"}, {\"asset_id\":\"96600821790790307414914106093858868634329285205417149685270682748367152458577\", \"price\":\"0.96\", \"size\":\"623.09\", \"side\":\"SELL\", \"hash\":\"46c3391220b5ef48b639b0841af444a43b116bf9\", \"best_bid\":\"0.38\", \"best_ask\":\"0.39\"}], \"timestamp\":\"1785211590128\", \"event_type\":\"price_change\"}","received_at":"2026-07-28T04:06:29.935327Z","schema_version":"clob-market-ws.price_change.v1","sequence":null,"server_hash":null,"server_timestamp":"1785211590128","session_id":"2d607381e3054cee91998cdf45a4231c","source":"clob_market_ws"},"received_at":"2026-07-28T04:06:29.935327Z","record_id":"3dec4f9879199c31a4be857afccf6bf7b71a9fdf572e22016ddba9ea6bd0edc9","schema_fingerprint":"4aa3821a28b0b7c2400bc59aba4bcc0a76e971dadd19610d3ad38c768e124dc7","schema_version":"edge-lab-recorder.raw.v1","sequence":null,"source":"clob_market_ws"}
{"event_at":"2026-07-28T04:06:30.137000Z","event_fingerprint":"9db04d37fc2bbda16a12cfd03716770717922d1bb3fcfc7ea07861a94ff2590b","payload":{"connection_id":"f6725804f86a4c4eb588e4d5ed7db029","event_at":"2026-07-28T04:06:30.137000Z","event_type":"price_change","frame_hash":"81cad67c51d8c542a3577181c8b122cf08ef3cca6d46f66673169ae0bee25ad9","frame_index":0,"kind":"data","monotonic_ns":313572989940666,"payload":{"event_type":"price_change","market":"0xd412ce774cfcf8dc9f71164aac78783978aac7b03871702a3b8a481bd9dc9688","price_changes":[{"asset_id":"96600821790790307414914106093858868634329285205417149685270682748367152458577","best_ask":"0.39","best_bid":"0.38","hash":"e98a71c889496ed2d5a59641481aa39c6cc5b0e8","price":"0.01","side":"BUY","size":"5608.02"},{"asset_id":"107603864457683460275633293642179940881969192120168665300712204232021063124301","best_ask":"0.62","best_bid":"0.61","hash":"ae9f700a89f442fc22c445963f9ce0f818c9992a","price":"0.99","side":"SELL","size":"5608.02"}],"timestamp":"1785211590137"},"payload_hash":"6ca9b748e6137edb668d8e66095a0eb4952725e6758e5fa2ac3119bfba149ef8","raw_frame":"{\"market\":\"0xd412ce774cfcf8dc9f71164aac78783978aac7b03871702a3b8a481bd9dc9688\", \"price_changes\":[{\"asset_id\":\"96600821790790307414914106093858868634329285205417149685270682748367152458577\", \"price\":\"0.01\", \"size\":\"5608.02\", \"side\":\"BUY\", \"hash\":\"e98a71c889496ed2d5a59641481aa39c6cc5b0e8\", \"best_bid\":\"0.38\", \"best_ask\":\"0.39\"}, {\"asset_id\":\"107603864457683460275633293642179940881969192120168665300712204232021063124301\", \"price\":\"0.99\", \"size\":\"5608.02\", \"side\":\"SELL\", \"hash\":\"ae9f700a89f442fc22c445963f9ce0f818c9992a\", \"best_bid\":\"0.61\", \"best_ask\":\"0.62\"}], \"timestamp\":\"1785211590137\", \"event_type\":\"price_change\"}","received_at":"2026-07-28T04:06:29.939140Z","schema_version":"clob-market-ws.price_change.v1","sequence":null,"server_hash":null,"server_timestamp":"1785211590137","session_id":"2d607381e3054cee91998cdf45a4231c","source":"clob_market_ws"},"received_at":"2026-07-28T04:06:29.939140Z","record_id":"d72e3b0ef9369b6414888b9b223c8648382da93048ae28d2846ea0389285a24f","schema_fingerprint":"4aa3821a28b0b7c2400bc59aba4bcc0a76e971dadd19610d3ad38c768e124dc7","schema_version":"edge-lab-recorder.raw.v1","sequence":null,"source":"clob_market_ws"}
{"event_at":"2026-07-28T04:06:30.144000Z","event_fingerprint":"dd9936affdb8a7f61df11f755751690570390b57d7992d83f1ebdc17914c34c8","payload":{"connection_id":"f6725804f86a4c4eb588e4d5ed7db029","event_at":"2026-07-28T04:06:30.144000Z","event_type":"price_change","frame_hash":"84b0533d7b069a955f095f8a77782823adffe1e24eba8df73cdbe1f84b486776","frame_index":0,"kind":"data","monotonic_ns":313572993841958,"payload":{"event_type":"price_change","market":"0xd412ce774cfcf8dc9f71164aac78783978aac7b03871702a3b8a481bd9dc9688","price_changes":[{"asset_id":"107603864457683460275633293642179940881969192120168665300712204232021063124301","best_ask":"0.62","best_bid":"0.61","hash":"72e6f6044dee5b110e8e51d20049540ba03d2ba6","price":"0.01","side":"BUY","size":"5638.02"},{"asset_id":"96600821790790307414914106093858868634329285205417149685270682748367152458577","best_ask":"0.39","best_bid":"0.38","hash":"e0663c6c9a112b4c8b8b70dfa92894ea1164a514","price":"0.99","side":"SELL","size":"5638.02"}],"timestamp":"1785211590144"},"payload_hash":"d21c039f936219d48099932a58d4be900eda92e70e2421adb6b17cc4e2e7d597","raw_frame":"{\"market\":\"0xd412ce774cfcf8dc9f71164aac78783978aac7b03871702a3b8a481bd9dc9688\", \"price_changes\":[{\"asset_id\":\"107603864457683460275633293642179940881969192120168665300712204232021063124301\", \"price\":\"0.01\", \"size\":\"5638.02\", \"side\":\"BUY\", \"hash\":\"72e6f6044dee5b110e8e51d20049540ba03d2ba6\", \"best_bid\":\"0.61\", \"best_ask\":\"0.62\"}, {\"asset_id\":\"96600821790790307414914106093858868634329285205417149685270682748367152458577\", \"price\":\"0.99\", \"size\":\"5638.02\", \"side\":\"SELL\", \"hash\":\"e0663c6c9a112b4c8b8b70dfa92894ea1164a514\", \"best_bid\":\"0.38\", \"best_ask\":\"0.39\"}], \"timestamp\":\"1785211590144\", \"event_type\":\"price_change\"}","received_at":"2026-07-28T04:06:29.943039Z","schema_version":"clob-market-ws.price_change.v1","sequence":null,"server_hash":null,"server_timestamp":"1785211590144","session_id":"2d607381e3054cee91998cdf45a4231c","source":"clob_market_ws"},"received_at":"2026-07-28T04:06:29.943039Z","record_id":"dcced8cd320b9b10ce94cf7582ab81e408a748a21f1fc9ec0346b5551875b303","schema_fingerprint":"4aa3821a28b0b7c2400bc59aba4bcc0a76e971dadd19610d3ad38c768e124dc7","schema_version":"edge-lab-recorder.raw.v1","sequence":null,"source":"clob_market_ws"}
{"event_at":"2026-07-28T04:06:30.197000Z","event_fingerprint":"de8f83693c1fbc4a61613670407262b52ef31be89b2b6d18ffda062854e3e1ab","payload":{"connection_id":"f6725804f86a4c4eb588e4d5ed7db029","event_at":"2026-07-28T04:06:30.197000Z","event_type":"price_change","frame_hash":"04d09e5b15bc347235a64bb1b6b35f64ea90731b2f1ab6e447d45ee3899afaf2","frame_index":0,"kind":"data","monotonic_ns":313573049261500,"payload":{"event_type":"price_change","market":"0xd412ce774cfcf8dc9f71164aac78783978aac7b03871702a3b8a481bd9dc9688","price_changes":[{"asset_id":"107603864457683460275633293642179940881969192120168665300712204232021063124301","best_ask":"0.62","best_bid":"0.61","hash":"f1dc2fa390232958dc7b332a0e3a36a55e750b64","price":"0.04","side":"BUY","size":"618.09"},{"asset_id":"96600821790790307414914106093858868634329285205417149685270682748367152458577","best_ask":"0.39","best_bid":"0.38","hash":"7fd07522d202a8e790b573f8af4b6b91c538e8fc","price":"0.96","side":"SELL","size":"618.09"}],"timestamp":"1785211590197"},"payload_hash":"ef23848c2b456e4fe11613f8ea9d7143260532ed621217d30d0146ff5b9ec934","raw_frame":"{\"market\":\"0xd412ce774cfcf8dc9f71164aac78783978aac7b03871702a3b8a481bd9dc9688\", \"price_changes\":[{\"asset_id\":\"107603864457683460275633293642179940881969192120168665300712204232021063124301\", \"price\":\"0.04\", \"size\":\"618.09\", \"side\":\"BUY\", \"hash\":\"f1dc2fa390232958dc7b332a0e3a36a55e750b64\", \"best_bid\":\"0.61\", \"best_ask\":\"0.62\"}, {\"asset_id\":\"96600821790790307414914106093858868634329285205417149685270682748367152458577\", \"price\":\"0.96\", \"size\":\"618.09\", \"side\":\"SELL\", \"hash\":\"7fd07522d202a8e790b573f8af4b6b91c538e8fc\", \"best_bid\":\"0.38\", \"best_ask\":\"0.39\"}], \"timestamp\":\"1785211590197\", \"event_type\":\"price_change\"}","received_at":"2026-07-28T04:06:29.998460Z","schema_version":"clob-market-ws.price_change.v1","sequence":null,"server_hash":null,"server_timestamp":"1785211590197","session_id":"2d607381e3054cee91998cdf45a4231c","source":"clob_market_ws"},"received_at":"2026-07-28T04:06:29.998460Z","record_id":"b4153430949590ddaeb296479956cb7517e4d415c138ec287358160f7179d997","schema_fingerprint":"4aa3821a28b0b7c2400bc59aba4bcc0a76e971dadd19610d3ad38c768e124dc7","schema_version":"edge-lab-recorder.raw.v1","sequence":null,"source":"clob_market_ws"}
{"event_at":"2026-07-28T04:06:30.209000Z","event_fingerprint":"3b584a120b70704b2169d284065221dcc880633007e84bfbe18879716512b70f","payload":{"connection_id":"f6725804f86a4c4eb588e4d5ed7db029","event_at":"2026-07-28T04:06:30.209000Z","event_type":"price_change","frame_hash":"46e09f2dd608c1d493e744d9a79e82f8c7f7004e839a900351c7eba69793c924","frame_index":0,"kind":"data","monotonic_ns":313573061712208,"payload":{"event_type":"price_change","market":"0xd412ce774cfcf8dc9f71164aac78783978aac7b03871702a3b8a481bd9dc9688","price_changes":[{"asset_id":"107603864457683460275633293642179940881969192120168665300712204232021063124301","best_ask":"0.62","best_bid":"0.61","hash":"cecc701a51edc021fe2bcdeaa44b712afbb4e1c7","price":"0.65","side":"SELL","size":"76.59"},{"asset_id":"96600821790790307414914106093858868634329285205417149685270682748367152458577","best_ask":"0.39","best_bid":"0.38","hash":"4e3d289e8d2e06c19978c0d33cc84b9b455464fc","price":"0.35","side":"BUY","size":"76.59"}],"timestamp":"1785211590209"},"payload_hash":"d21a8fcfab7b762becae7a7a169bdc30375d9849c29fe4091962c42ddabd7c19","raw_frame":"{\"market\":\"0xd412ce774cfcf8dc9f71164aac78783978aac7b03871702a3b8a481bd9dc9688\", \"price_changes\":[{\"asset_id\":\"107603864457683460275633293642179940881969192120168665300712204232021063124301\", \"price\":\"0.65\", \"size\":\"76.59\", \"side\":\"SELL\", \"hash\":\"cecc701a51edc021fe2bcdeaa44b712afbb4e1c7\", \"best_bid\":\"0.61\", \"best_ask\":\"0.62\"}, {\"asset_id\":\"96600821790790307414914106093858868634329285205417149685270682748367152458577\", \"price\":\"0.35\", \"size\":\"76.59\", \"side\":\"BUY\", \"hash\":\"4e3d289e8d2e06c19978c0d33cc84b9b455464fc\", \"best_bid\":\"0.38\", \"best_ask\":\"0.39\"}], \"timestamp\":\"1785211590209\", \"event_type\":\"price_change\"}","received_at":"2026-07-28T04:06:30.010909Z","schema_version":"clob-market-ws.price_change.v1","sequence":null,"server_hash":null,"server_timestamp":"1785211590209","session_id":"2d607381e3054cee91998cdf45a4231c","source":"clob_market_ws"},"received_at":"2026-07-28T04:06:30.010909Z","record_id":"5df3d8b2faea200f3d1a3d5af3ddc65b15334fe70d6f96a22c0f46a059e62fa8","schema_fingerprint":"4aa3821a28b0b7c2400bc59aba4bcc0a76e971dadd19610d3ad38c768e124dc7","schema_version":"edge-lab-recorder.raw.v1","sequence":null,"source":"clob_market_ws"}
{"event_at":"2026-07-28T04:06:30.210000Z","event_fingerprint":"91f5c76750f4a105d665c6b4125f37d82f6dc6c74c7037f09933324df93d91ca","payload":{"connection_id":"f6725804f86a4c4eb588e4d5ed7db029","event_at":"2026-07-28T04:06:30.210000Z","event_type":"price_change","frame_hash":"c2ede97d8346237f37d021163c2f6f96b5f67d8c3e646f9dbb2fd3259ff9d9fa","frame_index":0,"kind":"data","monotonic_ns":313573066232583,"payload":{"event_type":"price_change","market":"0xd412ce774cfcf8dc9f71164aac78783978aac7b03871702a3b8a481bd9dc9688","price_changes":[{"asset_id":"96600821790790307414914106093858868634329285205417149685270682748367152458577","best_ask":"0.39","best_bid":"0.38","hash":"374df62b2d0d2697b855fddd8dba456f7623a80b","price":"0.4","side":"SELL","size":"66"},{"asset_id":"107603864457683460275633293642179940881969192120168665300712204232021063124301","best_ask":"0.62","best_bid":"0.61","hash":"9e83e7b9ae7ae4b4214a7029e4e99bbd51b8a529","price":"0.6","side":"BUY","size":"66"}],"timestamp":"1785211590210"},"payload_hash":"0dc7c29438fb3418c2bbb7cb5e37ada70ba523ffbf705545cc386f7bc170739b","raw_frame":"{\"market\":\"0xd412ce774cfcf8dc9f71164aac78783978aac7b03871702a3b8a481bd9dc9688\", \"price_changes\":[{\"asset_id\":\"96600821790790307414914106093858868634329285205417149685270682748367152458577\", \"price\":\"0.4\", \"size\":\"66\", \"side\":\"SELL\", \"hash\":\"374df62b2d0d2697b855fddd8dba456f7623a80b\", \"best_bid\":\"0.38\", \"best_ask\":\"0.39\"}, {\"asset_id\":\"107603864457683460275633293642179940881969192120168665300712204232021063124301\", \"price\":\"0.6\", \"size\":\"66\", \"side\":\"BUY\", \"hash\":\"9e83e7b9ae7ae4b4214a7029e4e99bbd51b8a529\", \"best_bid\":\"0.61\", \"best_ask\":\"0.62\"}], \"timestamp\":\"1785211590210\", \"event_type\":\"price_change\"}","received_at":"2026-07-28T04:06:30.015429Z","schema_version":"clob-market-ws.price_change.v1","sequence":null,"server_hash":null,"server_timestamp":"1785211590210","session_id":"2d607381e3054cee91998cdf45a4231c","source":"clob_market_ws"},"received_at":"2026-07-28T04:06:30.015429Z","record_id":"71aa6ec0d66be3ce198dc2bdab629f37bab74ddc52c163cfcf5b4f8331ab254e","schema_fingerprint":"4aa3821a28b0b7c2400bc59aba4bcc0a76e971dadd19610d3ad38c768e124dc7","schema_version":"edge-lab-recorder.raw.v1","sequence":null,"source":"clob_market_ws"}
{"event_at":"2026-07-28T04:06:30.214000Z","event_fingerprint":"e5dcb4fc3f2701f5357b14a3f45b3faf6bc48273865aa8d9fcb4166167d46252","payload":{"connection_id":"f6725804f86a4c4eb588e4d5ed7db029","event_at":"2026-07-28T04:06:30.214000Z","event_type":"price_change","frame_hash":"e54f31e7886dca41a4c777d525197bf9b0cd68ca02c3e509df3e8fb74896b7ac","frame_index":0,"kind":"data","monotonic_ns":313573069281458,"payload":{"event_type":"price_change","market":"0xd412ce774cfcf8dc9f71164aac78783978aac7b03871702a3b8a481bd9dc9688","price_changes":[{"asset_id":"107603864457683460275633293642179940881969192120168665300712204232021063124301","best_ask":"0.62","best_bid":"0.61","hash":"b507e71af5b53624f7bce123ed24b4a0a03fed80","price":"0.01","side":"BUY","size":"5643.02"},{"asset_id":"96600821790790307414914106093858868634329285205417149685270682748367152458577","best_ask":"0.39","best_bid":"0.38","hash":"5fac8b8239d7afe521cdafb3ea18d1ee2bd7a659","price":"0.99","side":"SELL","size":"5643.02"}],"timestamp":"1785211590214"},"payload_hash":"1bc95b6f633e63743678ce45e73a607bae9b5bfacfc927d7579784e3b81d528b","raw_frame":"{\"market\":\"0xd412ce774cfcf8dc9f71164aac78783978aac7b03871702a3b8a481bd9dc9688\", \"price_changes\":[{\"asset_id\":\"107603864457683460275633293642179940881969192120168665300712204232021063124301\", \"price\":\"0.01\", \"size\":\"5643.02\", \"side\":\"BUY\", \"hash\":\"b507e71af5b53624f7bce123ed24b4a0a03fed80\", \"best_bid\":\"0.61\", \"best_ask\":\"0.62\"}, {\"asset_id\":\"96600821790790307414914106093858868634329285205417149685270682748367152458577\", \"price\":\"0.99\", \"size\":\"5643.02\", \"side\":\"SELL\", \"hash\":\"5fac8b8239d7afe521cdafb3ea18d1ee2bd7a659\", \"best_bid\":\"0.38\", \"best_ask\":\"0.39\"}], \"timestamp\":\"1785211590214\", \"event_type\":\"price_change\"}","received_at":"2026-07-28T04:06:30.018481Z","schema_version":"clob-market-ws.price_change.v1","sequence":null,"server_hash":null,"server_timestamp":"1785211590214","session_id":"2d607381e3054cee91998cdf45a4231c","source":"clob_market_ws"},"received_at":"2026-07-28T04:06:30.018481Z","record_id":"ea45fbc87b12790d3a120ec90d4c88fc1dd6e41415c2cad61073f3a7f277a271","schema_fingerprint":"4aa3821a28b0b7c2400bc59aba4bcc0a76e971dadd19610d3ad38c768e124dc7","schema_version":"edge-lab-recorder.raw.v1","sequence":null,"source":"clob_market_ws"}
{"event_at":"2026-07-28T04:06:30.221000Z","event_fingerprint":"8a322e420a39c76590153d7711ea980368786eabd1d6f6ca0d71d94c13ba4e6d","payload":{"connection_id":"f6725804f86a4c4eb588e4d5ed7db029","event_at":"2026-07-28T04:06:30.221000Z","event_type":"price_change","frame_hash":"b5a372ced39e15df40d87c0a27fb7a102605a8ed4a8ca928c24ac69d9cd51025","frame_index":0,"kind":"data","monotonic_ns":313573074564416,"payload":{"event_type":"price_change","market":"0xd412ce774cfcf8dc9f71164aac78783978aac7b03871702a3b8a481bd9dc9688","price_changes":[{"asset_id":"96600821790790307414914106093858868634329285205417149685270682748367152458577","best_ask":"0.39","best_bid":"0.38","hash":"ca240971adbfb508697cdc25d553f23ec6285cdd","price":"0.39","side":"SELL","size":"63.2"},{"asset_id":"107603864457683460275633293642179940881969192120168665300712204232021063124301","best_ask":"0.62","best_bid":"0.61","hash":"77777e9892ae9aa1235a57b165d7e0d182a55d62","price":"0.61","side":"BUY","size":"63.2"}],"timestamp":"1785211590221"},"payload_hash":"e751bd0aa68b9d71035d93b0b6c7c6dbc95a50e21ebf657b4a1a690cfa0e5444","raw_frame":"{\"market\":\"0xd412ce774cfcf8dc9f71164aac78783978aac7b03871702a3b8a481bd9dc9688\", \"price_changes\":[{\"asset_id\":\"96600821790790307414914106093858868634329285205417149685270682748367152458577\", \"price\":\"0.39\", \"size\":\"63.2\", \"side\":\"SELL\", \"hash\":\"ca240971adbfb508697cdc25d553f23ec6285cdd\", \"best_bid\":\"0.38\", \"best_ask\":\"0.39\"}, {\"asset_id\":\"107603864457683460275633293642179940881969192120168665300712204232021063124301\", \"price\":\"0.61\", \"size\":\"63.2\", \"side\":\"BUY\", \"hash\":\"77777e9892ae9aa1235a57b165d7e0d182a55d62\", \"best_bid\":\"0.61\", \"best_ask\":\"0.62\"}], \"timestamp\":\"1785211590221\", \"event_type\":\"price_change\"}","received_at":"2026-07-28T04:06:30.023762Z","schema_version":"clob-market-ws.price_change.v1","sequence":null,"server_hash":null,"server_timestamp":"1785211590221","session_id":"2d607381e3054cee91998cdf45a4231c","source":"clob_market_ws"},"received_at":"2026-07-28T04:06:30.023762Z","record_id":"3c3622d999738377310f8aa797826490021243618ec12d3db85818a648ab1f98","schema_fingerprint":"4aa3821a28b0b7c2400bc59aba4bcc0a76e971dadd19610d3ad38c768e124dc7","schema_version":"edge-lab-recorder.raw.v1","sequence":null,"source":"clob_market_ws"}
{"event_at":"2026-07-28T04:06:30.230000Z","event_fingerprint":"fdca988afde2a4552b99845b6c343d7e32068501760ec9d1ffc9d6dbd8bf36fa","payload":{"connection_id":"f6725804f86a4c4eb588e4d5ed7db029","event_at":"2026-07-28T04:06:30.230000Z","event_type":"price_change","frame_hash":"1a9d6d3e214092debd74fea45788ecfea83fd613662dd87ffc45060d35aff962","frame_index":0,"kind":"data","monotonic_ns":313573083644250,"payload":{"event_type":"price_change","market":"0xd412ce774cfcf8dc9f71164aac78783978aac7b03871702a3b8a481bd9dc9688","price_changes":[{"asset_id":"107603864457683460275633293642179940881969192120168665300712204232021063124301","best_ask":"0.62","best_bid":"0.61","hash":"fc3a354184cd9ff5f4363c7ce93911d3e3fa0107","price":"0.76","side":"SELL","size":"153.39"},{"asset_id":"96600821790790307414914106093858868634329285205417149685270682748367152458577","best_ask":"0.39","best_bid":"0.38","hash":"85b1d0ae664caff11ff6f072ca3d6e0ed3af29ec","price":"0.24","side":"BUY","size":"153.39"}],"timestamp":"1785211590230"},"payload_hash":"54e7e9b83132f30b3c3509007fdd412539a52f0d31959a0c7d2687f7432a4760","raw_frame":"{\"market\":\"0xd412ce774cfcf8dc9f71164aac78783978aac7b03871702a3b8a481bd9dc9688\", \"price_changes\":[{\"asset_id\":\"107603864457683460275633293642179940881969192120168665300712204232021063124301\", \"price\":\"0.76\", \"size\":\"153.39\", \"side\":\"SELL\", \"hash\":\"fc3a354184cd9ff5f4363c7ce93911d3e3fa0107\", \"best_bid\":\"0.61\", \"best_ask\":\"0.62\"}, {\"asset_id\":\"96600821790790307414914106093858868634329285205417149685270682748367152458577\", \"price\":\"0.24\", \"size\":\"153.39\", \"side\":\"BUY\", \"hash\":\"85b1d0ae664caff11ff6f072ca3d6e0ed3af29ec\", \"best_bid\":\"0.38\", \"best_ask\":\"0.39\"}], \"timestamp\":\"1785211590230\", \"event_type\":\"price_change\"}","received_at":"2026-07-28T04:06:30.032842Z","schema_version":"clob-market-ws.price_change.v1","sequence":null,"server_hash":null,"server_timestamp":"1785211590230","session_id":"2d607381e3054cee91998cdf45a4231c","source":"clob_market_ws"},"received_at":"2026-07-28T04:06:30.032842Z","record_id":"abc7caea6591a16f94cdfa133ae03f713fedc92a19333b4596ee74652ac04fbc","schema_fingerprint":"4aa3821a28b0b7c2400bc59aba4bcc0a76e971dadd19610d3ad38c768e124dc7","schema_version":"edge-lab-recorder.raw.v1","sequence":null,"source":"clob_market_ws"}
{"event_at":"2026-07-28T04:06:30.243000Z","event_fingerprint":"263e441602a508873a6531f4083455d08e204a3da9f440e82063eb7cbc1b2dd9","payload":{"connection_id":"f6725804f86a4c4eb588e4d5ed7db029","event_at":"2026-07-28T04:06:30.243000Z","event_type":"price_change","frame_hash":"1d661ba94a5a456a864b5942b33e09c101bb06e952f875e2bc507e31e585d7e0","frame_index":0,"kind":"data","monotonic_ns":313573094872958,"payload":{"event_type":"price_change","market":"0xd412ce774cfcf8dc9f71164aac78783978aac7b03871702a3b8a481bd9dc9688","price_changes":[{"asset_id":"107603864457683460275633293642179940881969192120168665300712204232021063124301","best_ask":"0.62","best_bid":"0.61","hash":"0ff7af2c0cbde77af6a230b0ea38fe216e6e7e1b","price":"0.01","side":"BUY","size":"5638.02"},{"asset_id":"96600821790790307414914106093858868634329285205417149685270682748367152458577","best_ask":"0.39","best_bid":"0.38","hash":"90224e4812d311c65f017e5ab926bf00a31d44d9","price":"0.99","side":"SELL","size":"5638.02"}],"timestamp":"1785211590243"},"payload_hash":"05dbf834af51b9634505ab4345ac8a39c0dc2ff4e1797c85f952231ed149d672","raw_frame":"{\"market\":\"0xd412ce774cfcf8dc9f71164aac78783978aac7b03871702a3b8a481bd9dc9688\", \"price_changes\":[{\"asset_id\":\"107603864457683460275633293642179940881969192120168665300712204232021063124301\", \"price\":\"0.01\", \"size\":\"5638.02\", \"side\":\"BUY\", \"hash\":\"0ff7af2c0cbde77af6a230b0ea38fe216e6e7e1b\", \"best_bid\":\"0.61\", \"best_ask\":\"0.62\"}, {\"asset_id\":\"96600821790790307414914106093858868634329285205417149685270682748367152458577\", \"price\":\"0.99\", \"size\":\"5638.02\", \"side\":\"SELL\", \"hash\":\"90224e4812d311c65f017e5ab926bf00a31d44d9\", \"best_bid\":\"0.38\", \"best_ask\":\"0.39\"}], \"timestamp\":\"1785211590243\", \"event_type\":\"price_change\"}","received_at":"2026-07-28T04:06:30.044070Z","schema_version":"clob-market-ws.price_change.v1","sequence":null,"server_hash":null,"server_timestamp":"1785211590243","session_id":"2d607381e3054cee91998cdf45a4231c","source":"clob_market_ws"},"received_at":"2026-07-28T04:06:30.044070Z","record_id":"1c301a2a4b5e67fc19a7141ea20936f6ca6204c2355bc812f311a327e4da41ac","schema_fingerprint":"4aa3821a28b0b7c2400bc59aba4bcc0a76e971dadd19610d3ad38c768e124dc7","schema_version":"edge-lab-recorder.raw.v1","sequence":null,"source":"clob_market_ws"}
{"event_at":"2026-07-28T04:06:30.270000Z","event_fingerprint":"ab59bfe2f88be04199041061c14e8feb180c8046b61ac396b08175da979d540b","payload":{"connection_id":"f6725804f86a4c4eb588e4d5ed7db029","event_at":"2026-07-28T04:06:30.270000Z","event_type":"price_change","frame_hash":"4851e1e0a8f4835689975a4c2ee02f25cf732f0ad3fc264230fe5ddda3ece824","frame_index":0,"kind":"data","monotonic_ns":313573121387083,"payload":{"event_type":"price_change","market":"0xd412ce774cfcf8dc9f71164aac78783978aac7b03871702a3b8a481bd9dc9688","price_changes":[{"asset_id":"107603864457683460275633293642179940881969192120168665300712204232021063124301","best_ask":"0.62","best_bid":"0.61","hash":"27472904e517d31c7b0392381c0febadc4620964","price":"0.76","side":"SELL","size":"160.89"},{"asset_id":"96600821790790307414914106093858868634329285205417149685270682748367152458577","best_ask":"0.39","best_bid":"0.38","hash":"bbc57d480cb7502515c92dc0ccbdc49317c8f7c6","price":"0.24","side":"BUY","size":"160.89"}],"timestamp":"1785211590270"},"payload_hash":"6e4737b22099e160ff69ba106034977f185e2159d2bde0862dfb29925d7155a4","raw_frame":"{\"market\":\"0xd412ce774cfcf8dc9f71164aac78783978aac7b03871702a3b8a481bd9dc9688\", \"price_changes\":[{\"asset_id\":\"107603864457683460275633293642179940881969192120168665300712204232021063124301\", \"price\":\"0.76\", \"size\":\"160.89\", \"side\":\"SELL\", \"hash\":\"27472904e517d31c7b0392381c0febadc4620964\", \"best_bid\":\"0.61\", \"best_ask\":\"0.62\"}, {\"asset_id\":\"96600821790790307414914106093858868634329285205417149685270682748367152458577\", \"price\":\"0.24\", \"size\":\"160.89\", \"side\":\"BUY\", \"hash\":\"bbc57d480cb7502515c92dc0ccbdc49317c8f7c6\", \"best_bid\":\"0.38\", \"best_ask\":\"0.39\"}], \"timestamp\":\"1785211590270\", \"event_type\":\"price_change\"}","received_at":"2026-07-28T04:06:30.070584Z","schema_version":"clob-market-ws.price_change.v1","sequence":null,"server_hash":null,"server_timestamp":"1785211590270","session_id":"2d607381e3054cee91998cdf45a4231c","source":"clob_market_ws"},"received_at":"2026-07-28T04:06:30.070584Z","record_id":"cc50068dde1a2427166c7aa94675478c72de24518c9b007715f8cd7669a2e3fd","schema_fingerprint":"4aa3821a28b0b7c2400bc59aba4bcc0a76e971dadd19610d3ad38c768e124dc7","schema_version":"edge-lab-recorder.raw.v1","sequence":null,"source":"clob_market_ws"}
{"event_at":"2026-07-28T04:06:30.292000Z","event_fingerprint":"1f0acff607b14a8e66caff2b82f8b2f927a6f0c0201cfc0e3d741099bb78403d","payload":{"connection_id":"f6725804f86a4c4eb588e4d5ed7db029","event_at":"2026-07-28T04:06:30.292000Z","event_type":"price_change","frame_hash":"c713b97906e4f826100515c2f19eccf924041308b5210ce88bc77af95351c56c","frame_index":0,"kind":"data","monotonic_ns":313573143269083,"payload":{"event_type":"price_change","market":"0xd412ce774cfcf8dc9f71164aac78783978aac7b03871702a3b8a481bd9dc9688","price_changes":[{"asset_id":"107603864457683460275633293642179940881969192120168665300712204232021063124301","best_ask":"0.62","best_bid":"0.61","hash":"21d28387d37ce7f8398460b75e9d56ca401f6ee1","price":"0.04","side":"BUY","size":"623.09"},{"asset_id":"96600821790790307414914106093858868634329285205417149685270682748367152458577","best_ask":"0.39","best_bid":"0.38","hash":"ce6bebe34f0a0140c657f3a549cd139abc081a14","price":"0.96","side":"SELL","size":"623.09"}],"timestamp":"1785211590292"},"payload_hash":"0a024f305a8922423424962a97f9a41241f80c19df6a47c249709454b29648e1","raw_frame":"{\"market\":\"0xd412ce774cfcf8dc9f71164aac78783978aac7b03871702a3b8a481bd9dc9688\", \"price_changes\":[{\"asset_id\":\"107603864457683460275633293642179940881969192120168665300712204232021063124301\", \"price\":\"0.04\", \"size\":\"623.09\", \"side\":\"BUY\", \"hash\":\"21d28387d37ce7f8398460b75e9d56ca401f6ee1\", \"best_bid\":\"0.61\", \"best_ask\":\"0.62\"}, {\"asset_id\":\"96600821790790307414914106093858868634329285205417149685270682748367152458577\", \"price\":\"0.96\", \"size\":\"623.09\", \"side\":\"SELL\", \"hash\":\"ce6bebe34f0a0140c657f3a549cd139abc081a14\", \"best_bid\":\"0.38\", \"best_ask\":\"0.39\"}], \"timestamp\":\"1785211590292\", \"event_type\":\"price_change\"}","received_at":"2026-07-28T04:06:30.092467Z","schema_version":"clob-market-ws.price_change.v1","sequence":null,"server_hash":null,"server_timestamp":"1785211590292","session_id":"2d607381e3054cee91998cdf45a4231c","source":"clob_market_ws"},"received_at":"2026-07-28T04:06:30.092467Z","record_id":"669d9500bafd670a1e08e4667998ffd44ab7e6117fa8d70fd11feb85e1c04854","schema_fingerprint":"4aa3821a28b0b7c2400bc59aba4bcc0a76e971dadd19610d3ad38c768e124dc7","schema_version":"edge-lab-recorder.raw.v1","sequence":null,"source":"clob_market_ws"}
{"event_at":"2026-07-28T04:06:30.306000Z","event_fingerprint":"d47a9eede21c4404c9c0de99a6b95bf87d14ecfcc7b195fbceda8fc5fa473d6d","payload":{"connection_id":"f6725804f86a4c4eb588e4d5ed7db029","event_at":"2026-07-28T04:06:30.306000Z","event_type":"price_change","frame_hash":"3f8bce9dbe8a4fe6a865e0dade5b6c79dc1a52eb77ea082f3be9d151ffd4f65c","frame_index":0,"kind":"data","monotonic_ns":313573172729000,"payload":{"event_type":"price_change","market":"0xd412ce774cfcf8dc9f71164aac78783978aac7b03871702a3b8a481bd9dc9688","price_changes":[{"asset_id":"107603864457683460275633293642179940881969192120168665300712204232021063124301","best_ask":"0.62","best_bid":"0.61","hash":"131e19bfd51fa38126091f0967d3ef71930692f9","price":"0.65","side":"SELL","size":"65.98"},{"asset_id":"96600821790790307414914106093858868634329285205417149685270682748367152458577","best_ask":"0.39","best_bid":"0.38","hash":"3817b25da92e901fbaaf23d08c6d777b08f6011d","price":"0.35","side":"BUY","size":"65.98"}],"timestamp":"1785211590306"},"payload_hash":"a7163d0db19498a75ff3d06452dc5eb1d4af99533ddff808cb8157f3377dd69f","raw_frame":"{\"market\":\"0xd412ce774cfcf8dc9f71164aac78783978aac7b03871702a3b8a481bd9dc9688\", \"price_changes\":[{\"asset_id\":\"107603864457683460275633293642179940881969192120168665300712204232021063124301\", \"price\":\"0.65\", \"size\":\"65.98\", \"side\":\"SELL\", \"hash\":\"131e19bfd51fa38126091f0967d3ef71930692f9\", \"best_bid\":\"0.61\", \"best_ask\":\"0.62\"}, {\"asset_id\":\"96600821790790307414914106093858868634329285205417149685270682748367152458577\", \"price\":\"0.35\", \"size\":\"65.98\", \"side\":\"BUY\", \"hash\":\"3817b25da92e901fbaaf23d08c6d777b08f6011d\", \"best_bid\":\"0.38\", \"best_ask\":\"0.39\"}], \"timestamp\":\"1785211590306\", \"event_type\":\"price_change\"}","received_at":"2026-07-28T04:06:30.121927Z","schema_version":"clob-market-ws.price_change.v1","sequence":null,"server_hash":null,"server_timestamp":"1785211590306","session_id":"2d607381e3054cee91998cdf45a4231c","source":"clob_market_ws"},"received_at":"2026-07-28T04:06:30.121927Z","record_id":"ce4bf6c189800eb9daf831074c0c9cdacbfd6f59a2c993087000f46c32382ded","schema_fingerprint":"4aa3821a28b0b7c2400bc59aba4bcc0a76e971dadd19610d3ad38c768e124dc7","schema_version":"edge-lab-recorder.raw.v1","sequence":null,"source":"clob_market_ws"}
{"event_at":"2026-07-28T04:06:30.306000Z","event_fingerprint":"3b43092ed3fa73d7791d127868d444a49a112d14566586488394e91b6d5dd7b6","payload":{"connection_id":"f6725804f86a4c4eb588e4d5ed7db029","event_at":"2026-07-28T04:06:30.306000Z","event_type":"price_change","frame_hash":"c6660f9d80e7e6b00239507306ca0f66939ac69e2b0a8bacca156ba2d92d4b13","frame_index":0,"kind":"data","monotonic_ns":313573176961208,"payload":{"event_type":"price_change","market":"0xd412ce774cfcf8dc9f71164aac78783978aac7b03871702a3b8a481bd9dc9688","price_changes":[{"asset_id":"96600821790790307414914106093858868634329285205417149685270682748367152458577","best_ask":"0.39","best_bid":"0.38","hash":"3817b25da92e901fbaaf23d08c6d777b08f6011d","price":"0.39","side":"SELL","size":"55.2"},{"asset_id":"107603864457683460275633293642179940881969192120168665300712204232021063124301","best_ask":"0.62","best_bid":"0.61","hash":"131e19bfd51fa38126091f0967d3ef71930692f9","price":"0.61","side":"BUY","size":"55.2"}],"timestamp":"1785211590306"},"payload_hash":"0c0de6d335b9c6aff88ab120dcee4ebd21a69274be39321965c301b8f7d3890b","raw_frame":"{\"market\":\"0xd412ce774cfcf8dc9f71164aac78783978aac7b03871702a3b8a481bd9dc9688\", \"price_changes\":[{\"asset_id\":\"96600821790790307414914106093858868634329285205417149685270682748367152458577\", \"price\":\"0.39\", \"size\":\"55.2\", \"side\":\"SELL\", \"hash\":\"3817b25da92e901fbaaf23d08c6d777b08f6011d\", \"best_bid\":\"0.38\", \"best_ask\":\"0.39\"}, {\"asset_id\":\"107603864457683460275633293642179940881969192120168665300712204232021063124301\", \"price\":\"0.61\", \"size\":\"55.2\", \"side\":\"BUY\", \"hash\":\"131e19bfd51fa38126091f0967d3ef71930692f9\", \"best_bid\":\"0.61\", \"best_ask\":\"0.62\"}], \"timestamp\":\"1785211590306\", \"event_type\":\"price_change\"}","received_at":"2026-07-28T04:06:30.126158Z","schema_version":"clob-market-ws.price_change.v1","sequence":null,"server_hash":null,"server_timestamp":"1785211590306","session_id":"2d607381e3054cee91998cdf45a4231c","source":"clob_market_ws"},"received_at":"2026-07-28T04:06:30.126158Z","record_id":"82553b5287f0254eb3356d1438d45db5725fe98be0f02aaa7b197768840a3c07","schema_fingerprint":"4aa3821a28b0b7c2400bc59aba4bcc0a76e971dadd19610d3ad38c768e124dc7","schema_version":"edge-lab-recorder.raw.v1","sequence":null,"source":"clob_market_ws"}
{"event_at":"2026-07-28T04:06:30.398000Z","event_fingerprint":"db86987797816f3d8cef7173492f89561e6cf7508e4b058d51e6ab67f2819ae7","payload":{"connection_id":"f6725804f86a4c4eb588e4d5ed7db029","event_at":"2026-07-28T04:06:30.398000Z","event_type":"price_change","frame_hash":"87df6b84136dc676e3d474721286e91287414443e14bacd4f819888aaed02fe0","frame_index":0,"kind":"data","monotonic_ns":313573252017166,"payload":{"event_type":"price_change","market":"0xd412ce774cfcf8dc9f71164aac78783978aac7b03871702a3b8a481bd9dc9688","price_changes":[{"asset_id":"107603864457683460275633293642179940881969192120168665300712204232021063124301","best_ask":"0.62","best_bid":"0.61","hash":"ad4ad816ed406d26167323fc085009393dcd5abf","price":"0.04","side":"BUY","size":"618.09"},{"asset_id":"96600821790790307414914106093858868634329285205417149685270682748367152458577","best_ask":"0.39","best_bid":"0.38","hash":"13cb50f7d3481b1d6c23853e14d3856af2e67592","price":"0.96","side":"SELL","size":"618.09"}],"timestamp":"1785211590398"},"payload_hash":"b46db0f392acffe0adf4cd65cc6b332cb28b73e625081f0dbf34e9a7ecfcb140","raw_frame":"{\"market\":\"0xd412ce774cfcf8dc9f71164aac78783978aac7b03871702a3b8a481bd9dc9688\", \"price_changes\":[{\"asset_id\":\"107603864457683460275633293642179940881969192120168665300712204232021063124301\", \"price\":\"0.04\", \"size\":\"618.09\", \"side\":\"BUY\", \"hash\":\"ad4ad816ed406d26167323fc085009393dcd5abf\", \"best_bid\":\"0.61\", \"best_ask\":\"0.62\"}, {\"asset_id\":\"96600821790790307414914106093858868634329285205417149685270682748367152458577\", \"price\":\"0.96\", \"size\":\"618.09\", \"side\":\"SELL\", \"hash\":\"13cb50f7d3481b1d6c23853e14d3856af2e67592\", \"best_bid\":\"0.38\", \"best_ask\":\"0.39\"}], \"timestamp\":\"1785211590398\", \"event_type\":\"price_change\"}","received_at":"2026-07-28T04:06:30.201210Z","schema_version":"clob-market-ws.price_change.v1","sequence":null,"server_hash":null,"server_timestamp":"1785211590398","session_id":"2d607381e3054cee91998cdf45a4231c","source":"clob_market_ws"},"received_at":"2026-07-28T04:06:30.201210Z","record_id":"7fe55fd17e99cc5d73b8cd3e3801ce5ad00d7ba85372e4d64e4cad717c1ac535","schema_fingerprint":"4aa3821a28b0b7c2400bc59aba4bcc0a76e971dadd19610d3ad38c768e124dc7","schema_version":"edge-lab-recorder.raw.v1","sequence":null,"source":"clob_market_ws"}
{"event_at":"2026-07-28T04:06:30.424000Z","event_fingerprint":"e22d91a7e363826c3a42b1dd23aa35cfea3f2cb95fb07ada17016d3434369d4c","payload":{"connection_id":"f6725804f86a4c4eb588e4d5ed7db029","event_at":"2026-07-28T04:06:30.424000Z","event_type":"price_change","frame_hash":"ee1b2d0ef63d3e6cc42fbb6f28be59f97c321190dca5c63080322d282dbba480","frame_index":0,"kind":"data","monotonic_ns":313573278223750,"payload":{"event_type":"price_change","market":"0xd412ce774cfcf8dc9f71164aac78783978aac7b03871702a3b8a481bd9dc9688","price_changes":[{"asset_id":"107603864457683460275633293642179940881969192120168665300712204232021063124301","best_ask":"0.62","best_bid":"0.61","hash":"94c6b4cfe50ea3b529775086a7b59f5155efb177","price":"0.6","side":"BUY","size":"61"},{"asset_id":"96600821790790307414914106093858868634329285205417149685270682748367152458577","best_ask":"0.39","best_bid":"0.38","hash":"2c5e01a1ca5a7fd6afd613ce8f00098e97a739ba","price":"0.4","side":"SELL","size":"61"}],"timestamp":"1785211590424"},"payload_hash":"2c9a631d34ecfdc302dfe3db7f088f6df88ff34b5aa16f91395912789c8feb1e","raw_frame":"{\"market\":\"0xd412ce774cfcf8dc9f71164aac78783978aac7b03871702a3b8a481bd9dc9688\", \"price_changes\":[{\"asset_id\":\"107603864457683460275633293642179940881969192120168665300712204232021063124301\", \"price\":\"0.6\", \"size\":\"61\", \"side\":\"BUY\", \"hash\":\"94c6b4cfe50ea3b529775086a7b59f5155efb177\", \"best_bid\":\"0.61\", \"best_ask\":\"0.62\"}, {\"asset_id\":\"96600821790790307414914106093858868634329285205417149685270682748367152458577\", \"price\":\"0.4\", \"size\":\"61\", \"side\":\"SELL\", \"hash\":\"2c5e01a1ca5a7fd6afd613ce8f00098e97a739ba\", \"best_bid\":\"0.38\", \"best_ask\":\"0.39\"}], \"timestamp\":\"1785211590424\", \"event_type\":\"price_change\"}","received_at":"2026-07-28T04:06:30.227420Z","schema_version":"clob-market-ws.price_change.v1","sequence":null,"server_hash":null,"server_timestamp":"1785211590424","session_id":"2d607381e3054cee91998cdf45a4231c","source":"clob_market_ws"},"received_at":"2026-07-28T04:06:30.227420Z","record_id":"ded3703de69e7760a512b25aaea074147f1d94d3d71b77e048e8ddcb9c923998","schema_fingerprint":"4aa3821a28b0b7c2400bc59aba4bcc0a76e971dadd19610d3ad38c768e124dc7","schema_version":"edge-lab-recorder.raw.v1","sequence":null,"source":"clob_market_ws"}
{"event_at":"2026-07-28T04:06:30.432000Z","event_fingerprint":"5d043f8c7c5990fa963c9805d2e2a4bc0a07e97242f0e27deda06740ba83e8ea","payload":{"connection_id":"f6725804f86a4c4eb588e4d5ed7db029","event_at":"2026-07-28T04:06:30.432000Z","event_type":"price_change","frame_hash":"ab9ca150b5439cb116fef594425893f8e94acb376b61119798c66bef965d0548","frame_index":0,"kind":"data","monotonic_ns":313573285178250,"payload":{"event_type":"price_change","market":"0xd412ce774cfcf8dc9f71164aac78783978aac7b03871702a3b8a481bd9dc9688","price_changes":[{"asset_id":"96600821790790307414914106093858868634329285205417149685270682748367152458577","best_ask":"0.39","best_bid":"0.38","hash":"0f857d41ab4b6a4c5afd367734c9dc6c56d00e1f","price":"0.39","side":"SELL","size":"60.2"},{"asset_id":"107603864457683460275633293642179940881969192120168665300712204232021063124301","best_ask":"0.62","best_bid":"0.61","hash":"f9237d7135077d0b1fde386358378ae9f83f67e4","price":"0.61","side":"BUY","size":"60.2"}],"timestamp":"1785211590432"},"payload_hash":"5c3cdc5ad0aef8c3b7109d6c9631b26d40f6c57f44e5a0152410c42b280a0dd7","raw_frame":"{\"market\":\"0xd412ce774cfcf8dc9f71164aac78783978aac7b03871702a3b8a481bd9dc9688\", \"price_changes\":[{\"asset_id\":\"96600821790790307414914106093858868634329285205417149685270682748367152458577\", \"price\":\"0.39\", \"size\":\"60.2\", \"side\":\"SELL\", \"hash\":\"0f857d41ab4b6a4c5afd367734c9dc6c56d00e1f\", \"best_bid\":\"0.38\", \"best_ask\":\"0.39\"}, {\"asset_id\":\"107603864457683460275633293642179940881969192120168665300712204232021063124301\", \"price\":\"0.61\", \"size\":\"60.2\", \"side\":\"BUY\", \"hash\":\"f9237d7135077d0b1fde386358378ae9f83f67e4\", \"best_bid\":\"0.61\", \"best_ask\":\"0.62\"}], \"timestamp\":\"1785211590432\", \"event_type\":\"price_change\"}","received_at":"2026-07-28T04:06:30.234372Z","schema_version":"clob-market-ws.price_change.v1","sequence":null,"server_hash":null,"server_timestamp":"1785211590432","session_id":"2d607381e3054cee91998cdf45a4231c","source":"clob_market_ws"},"received_at":"2026-07-28T04:06:30.234372Z","record_id":"6d8ed9bfc6c118179fca3a2184215286b43b62e40dd57b391bc93078a958a121","schema_fingerprint":"4aa3821a28b0b7c2400bc59aba4bcc0a76e971dadd19610d3ad38c768e124dc7","schema_version":"edge-lab-recorder.raw.v1","sequence":null,"source":"clob_market_ws"}
{"event_at":"2026-07-28T04:06:30.433000Z","event_fingerprint":"13b0dc2cd89f281b93128879531570b910a3ae3032c6fcfa2c7daccdc242f444","payload":{"connection_id":"f6725804f86a4c4eb588e4d5ed7db029","event_at":"2026-07-28T04:06:30.433000Z","event_type":"price_change","frame_hash":"2df47d6eff4a8c4746fa1fbb06d394a1f55c98aa06fbdf1a3ea3cc2db08b1ca7","frame_index":0,"kind":"data","monotonic_ns":313573291459291,"payload":{"event_type":"price_change","market":"0xd412ce774cfcf8dc9f71164aac78783978aac7b03871702a3b8a481bd9dc9688","price_changes":[{"asset_id":"107603864457683460275633293642179940881969192120168665300712204232021063124301","best_ask":"0.62","best_bid":"0.61","hash":"a85f9afa115db9825a4b312c03bd22dfa0fbfa92","price":"0.64","side":"SELL","size":"31.61"},{"asset_id":"96600821790790307414914106093858868634329285205417149685270682748367152458577","best_ask":"0.39","best_bid":"0.38","hash":"6aefdcfe567ec76b2ddd792c6890467c7641d694","price":"0.36","side":"BUY","size":"31.61"}],"timestamp":"1785211590433"},"payload_hash":"4816174056528ed78193bfe64be9ab898aacb87a8be5c180ec081dd33c61e6d7","raw_frame":"{\"market\":\"0xd412ce774cfcf8dc9f71164aac78783978aac7b03871702a3b8a481bd9dc9688\", \"price_changes\":[{\"asset_id\":\"107603864457683460275633293642179940881969192120168665300712204232021063124301\", \"price\":\"0.64\", \"size\":\"31.61\", \"side\":\"SELL\", \"hash\":\"a85f9afa115db9825a4b312c03bd22dfa0fbfa92\", \"best_bid\":\"0.61\", \"best_ask\":\"0.62\"}, {\"asset_id\":\"96600821790790307414914106093858868634329285205417149685270682748367152458577\", \"price\":\"0.36\", \"size\":\"31.61\", \"side\":\"BUY\", \"hash\":\"6aefdcfe567ec76b2ddd792c6890467c7641d694\", \"best_bid\":\"0.38\", \"best_ask\":\"0.39\"}], \"timestamp\":\"1785211590433\", \"event_type\":\"price_change\"}","received_at":"2026-07-28T04:06:30.240655Z","schema_version":"clob-market-ws.price_change.v1","sequence":null,"server_hash":null,"server_timestamp":"1785211590433","session_id":"2d607381e3054cee91998cdf45a4231c","source":"clob_market_ws"},"received_at":"2026-07-28T04:06:30.240655Z","record_id":"ed1caf38c9c122c315a3dad93b1d9d15a958798e7e13ebd03568e77d2b0ac6b9","schema_fingerprint":"4aa3821a28b0b7c2400bc59aba4bcc0a76e971dadd19610d3ad38c768e124dc7","schema_version":"edge-lab-recorder.raw.v1","sequence":null,"source":"clob_market_ws"}
{"event_at":"2026-07-28T04:06:30.485000Z","event_fingerprint":"ef4ec8ba91ac2cc99ac41ebe9b7717f2fd7c5d49eb4e84c3d9f6ee06ffa413cd","payload":{"connection_id":"f6725804f86a4c4eb588e4d5ed7db029","event_at":"2026-07-28T04:06:30.485000Z","event_type":"price_change","frame_hash":"999568a5a61bfe76c8a130e61c47dae3590b1c3945c06e9d8161be1685188be5","frame_index":0,"kind":"data","monotonic_ns":313573339014250,"payload":{"event_type":"price_change","market":"0xd412ce774cfcf8dc9f71164aac78783978aac7b03871702a3b8a481bd9dc9688","price_changes":[{"asset_id":"96600821790790307414914106093858868634329285205417149685270682748367152458577","best_ask":"0.39","best_bid":"0.38","hash":"26d5c68de9f54adfdae8a9d924bb8d44bac6d125","price":"0.39","side":"SELL","size":"65.2"},{"asset_id":"107603864457683460275633293642179940881969192120168665300712204232021063124301","best_ask":"0.62","best_bid":"0.61","hash":"5898d82bce70a92a0d78bcbdf562170d80befdfe","price":"0.61","side":"BUY","size":"65.2"}],"timestamp":"1785211590485"},"payload_hash":"4d82eb8a5d0d0f277dc87635e0766a34a95f3e1cc21876213d6aaa4e7c70c3d1","raw_frame":"{\"market\":\"0xd412ce774cfcf8dc9f71164aac78783978aac7b03871702a3b8a481bd9dc9688\", \"price_changes\":[{\"asset_id\":\"96600821790790307414914106093858868634329285205417149685270682748367152458577\", \"price\":\"0.39\", \"size\":\"65.2\", \"side\":\"SELL\", \"hash\":\"26d5c68de9f54adfdae8a9d924bb8d44bac6d125\", \"best_bid\":\"0.38\", \"best_ask\":\"0.39\"}, {\"asset_id\":\"107603864457683460275633293642179940881969192120168665300712204232021063124301\", \"price\":\"0.61\", \"size\":\"65.2\", \"side\":\"BUY\", \"hash\":\"5898d82bce70a92a0d78bcbdf562170d80befdfe\", \"best_bid\":\"0.61\", \"best_ask\":\"0.62\"}], \"timestamp\":\"1785211590485\", \"event_type\":\"price_change\"}","received_at":"2026-07-28T04:06:30.288210Z","schema_version":"clob-market-ws.price_change.v1","sequence":null,"server_hash":null,"server_timestamp":"1785211590485","session_id":"2d607381e3054cee91998cdf45a4231c","source":"clob_market_ws"},"received_at":"2026-07-28T04:06:30.288210Z","record_id":"5913dbc8a2c0f17dcfff2d17d291c45cdbe192591056fc2b6a02dded4e76f44b","schema_fingerprint":"4aa3821a28b0b7c2400bc59aba4bcc0a76e971dadd19610d3ad38c768e124dc7","schema_version":"edge-lab-recorder.raw.v1","sequence":null,"source":"clob_market_ws"}
{"event_at":"2026-07-28T04:06:30.497000Z","event_fingerprint":"4d00bd795864a56a493af9f05d55c551d5f30d577748a7ff31ee011dbebbaf64","payload":{"connection_id":"f6725804f86a4c4eb588e4d5ed7db029","event_at":"2026-07-28T04:06:30.497000Z","event_type":"price_change","frame_hash":"2440c4442a2d9c482dcdc315298f253ebff030c3a25a9da2c40acba4779094a1","frame_index":0,"kind":"data","monotonic_ns":313573351975875,"payload":{"event_type":"price_change","market":"0xd412ce774cfcf8dc9f71164aac78783978aac7b03871702a3b8a481bd9dc9688","price_changes":[{"asset_id":"107603864457683460275633293642179940881969192120168665300712204232021063124301","best_ask":"0.62","best_bid":"0.61","hash":"8899b5f1507e602f1bba507c0ace1a1b608b0a76","price":"0.02","side":"BUY","size":"693.1"},{"asset_id":"96600821790790307414914106093858868634329285205417149685270682748367152458577","best_ask":"0.39","best_bid":"0.38","hash":"2a703fbb7b073825bf808ce9ee4761bb884affc9","price":"0.98","side":"SELL","size":"693.1"}],"timestamp":"1785211590497"},"payload_hash":"c066abfca6e919a86bfd04595cb048996d164426bf8db2edf812368497b52384","raw_frame":"{\"market\":\"0xd412ce774cfcf8dc9f71164aac78783978aac7b03871702a3b8a481bd9dc9688\", \"price_changes\":[{\"asset_id\":\"107603864457683460275633293642179940881969192120168665300712204232021063124301\", \"price\":\"0.02\", \"size\":\"693.1\", \"side\":\"BUY\", \"hash\":\"8899b5f1507e602f1bba507c0ace1a1b608b0a76\", \"best_bid\":\"0.61\", \"best_ask\":\"0.62\"}, {\"asset_id\":\"96600821790790307414914106093858868634329285205417149685270682748367152458577\", \"price\":\"0.98\", \"size\":\"693.1\", \"side\":\"SELL\", \"hash\":\"2a703fbb7b073825bf808ce9ee4761bb884affc9\", \"best_bid\":\"0.38\", \"best_ask\":\"0.39\"}], \"timestamp\":\"1785211590497\", \"event_type\":\"price_change\"}","received_at":"2026-07-28T04:06:30.301171Z","schema_version":"clob-market-ws.price_change.v1","sequence":null,"server_hash":null,"server_timestamp":"1785211590497","session_id":"2d607381e3054cee91998cdf45a4231c","source":"clob_market_ws"},"received_at":"2026-07-28T04:06:30.301171Z","record_id":"1e6e86160bcbd95436acfbbeaed01014f9934abcb7f15d04bd9270a2e7ffa68c","schema_fingerprint":"4aa3821a28b0b7c2400bc59aba4bcc0a76e971dadd19610d3ad38c768e124dc7","schema_version":"edge-lab-recorder.raw.v1","sequence":null,"source":"clob_market_ws"}
{"event_at":"2026-07-28T04:06:30.518000Z","event_fingerprint":"d1a9fa234b26f98c88df6aaf24075a20aec6440a3834ebdc75fb35080edf2c6f","payload":{"connection_id":"f6725804f86a4c4eb588e4d5ed7db029","event_at":"2026-07-28T04:06:30.518000Z","event_type":"price_change","frame_hash":"a697eba1f4d03c67ad2d2510eb30eed7e53eeb7e41e9da7cf1fbbd72a3f7d0a5","frame_index":0,"kind":"data","monotonic_ns":313573371192000,"payload":{"event_type":"price_change","market":"0xd412ce774cfcf8dc9f71164aac78783978aac7b03871702a3b8a481bd9dc9688","price_changes":[{"asset_id":"107603864457683460275633293642179940881969192120168665300712204232021063124301","best_ask":"0.62","best_bid":"0.61","hash":"2a2785e8d365566328f11d7c03a9e23707c97295","price":"0.01","side":"BUY","size":"5643.02"},{"asset_id":"96600821790790307414914106093858868634329285205417149685270682748367152458577","best_ask":"0.39","best_bid":"0.38","hash":"13331966edc5388a6c209771080adc2af0e005ff","price":"0.99","side":"SELL","size":"5643.02"}],"timestamp":"1785211590518"},"payload_hash":"9fd0d0304eca6102112036f1f568fd45ee80a3a845bf04b253c7d5848580de0f","raw_frame":"{\"market\":\"0xd412ce774cfcf8dc9f71164aac78783978aac7b03871702a3b8a481bd9dc9688\", \"price_changes\":[{\"asset_id\":\"107603864457683460275633293642179940881969192120168665300712204232021063124301\", \"price\":\"0.01\", \"size\":\"5643.02\", \"side\":\"BUY\", \"hash\":\"2a2785e8d365566328f11d7c03a9e23707c97295\", \"best_bid\":\"0.61\", \"best_ask\":\"0.62\"}, {\"asset_id\":\"96600821790790307414914106093858868634329285205417149685270682748367152458577\", \"price\":\"0.99\", \"size\":\"5643.02\", \"side\":\"SELL\", \"hash\":\"13331966edc5388a6c209771080adc2af0e005ff\", \"best_bid\":\"0.38\", \"best_ask\":\"0.39\"}], \"timestamp\":\"1785211590518\", \"event_type\":\"price_change\"}","received_at":"2026-07-28T04:06:30.320388Z","schema_version":"clob-market-ws.price_change.v1","sequence":null,"server_hash":null,"server_timestamp":"1785211590518","session_id":"2d607381e3054cee91998cdf45a4231c","source":"clob_market_ws"},"received_at":"2026-07-28T04:06:30.320388Z","record_id":"85df6e59f6f137856a4988ebed2e4dadf3860d49d0d26706bde93b26f5837d6d","schema_fingerprint":"4aa3821a28b0b7c2400bc59aba4bcc0a76e971dadd19610d3ad38c768e124dc7","schema_version":"edge-lab-recorder.raw.v1","sequence":null,"source":"clob_market_ws"}
{"event_at":"2026-07-28T04:06:30.525000Z","event_fingerprint":"a36c3fb459e93bfd90c5ac14b97e38e40b68dafaf62c2f2b1099716d54cf902b","payload":{"connection_id":"f6725804f86a4c4eb588e4d5ed7db029","event_at":"2026-07-28T04:06:30.525000Z","event_type":"price_change","frame_hash":"19c5843f67bab7ee645b23e3e6387a39137483526a664f58024ea630e5317874","frame_index":0,"kind":"data","monotonic_ns":313573376933916,"payload":{"event_type":"price_change","market":"0xd412ce774cfcf8dc9f71164aac78783978aac7b03871702a3b8a481bd9dc9688","price_changes":[{"asset_id":"107603864457683460275633293642179940881969192120168665300712204232021063124301","best_ask":"0.62","best_bid":"0.61","hash":"ca9d249bdfe1ba9ad0dfae15088f89957f252dde","price":"0.64","side":"SELL","size":"21"},{"asset_id":"96600821790790307414914106093858868634329285205417149685270682748367152458577","best_ask":"0.39","best_bid":"0.38","hash":"efeb52bfefe2877e0289d0455c49c5c70814c2c6","price":"0.36","side":"BUY","size":"21"}],"timestamp":"1785211590525"},"payload_hash":"5d36890be46f2603b9a4adb79d1c025b26ce69f15fd481e0ff6bdeab796c483c","raw_frame":"{\"market\":\"0xd412ce774cfcf8dc9f71164aac78783978aac7b03871702a3b8a481bd9dc9688\", \"price_changes\":[{\"asset_id\":\"107603864457683460275633293642179940881969192120168665300712204232021063124301\", \"price\":\"0.64\", \"size\":\"21\", \"side\":\"SELL\", \"hash\":\"ca9d249bdfe1ba9ad0dfae15088f89957f252dde\", \"best_bid\":\"0.61\", \"best_ask\":\"0.62\"}, {\"asset_id\":\"96600821790790307414914106093858868634329285205417149685270682748367152458577\", \"price\":\"0.36\", \"size\":\"21\", \"side\":\"BUY\", \"hash\":\"efeb52bfefe2877e0289d0455c49c5c70814c2c6\", \"best_bid\":\"0.38\", \"best_ask\":\"0.39\"}], \"timestamp\":\"1785211590525\", \"event_type\":\"price_change\"}","received_at":"2026-07-28T04:06:30.326129Z","schema_version":"clob-market-ws.price_change.v1","sequence":null,"server_hash":null,"server_timestamp":"1785211590525","session_id":"2d607381e3054cee91998cdf45a4231c","source":"clob_market_ws"},"received_at":"2026-07-28T04:06:30.326129Z","record_id":"0ddaa724288bf20e8d63b39c76a02e02b035482b55a3fbac4cb8d82d6bee50bb","schema_fingerprint":"4aa3821a28b0b7c2400bc59aba4bcc0a76e971dadd19610d3ad38c768e124dc7","schema_version":"edge-lab-recorder.raw.v1","sequence":null,"source":"clob_market_ws"}
{"event_at":"2026-07-28T04:06:30.531000Z","event_fingerprint":"c827615e324c31302a87851fff28e34c85d929c65c038d7eb8b552545d4e7727","payload":{"connection_id":"f6725804f86a4c4eb588e4d5ed7db029","event_at":"2026-07-28T04:06:30.531000Z","event_type":"price_change","frame_hash":"469f9c3fec78019c82ceaf431c8c26b176ea9e766693fbdc84c3d8e11164c5a6","frame_index":0,"kind":"data","monotonic_ns":313573383851833,"payload":{"event_type":"price_change","market":"0xd412ce774cfcf8dc9f71164aac78783978aac7b03871702a3b8a481bd9dc9688","price_changes":[{"asset_id":"96600821790790307414914106093858868634329285205417149685270682748367152458577","best_ask":"0.39","best_bid":"0.38","hash":"b9d26fa6dfee1df38e60bee4e9928738b8c101bf","price":"0.36","side":"BUY","size":"32"},{"asset_id":"107603864457683460275633293642179940881969192120168665300712204232021063124301","best_ask":"0.62","best_bid":"0.61","hash":"9f38e6add7655aad06702f4a20c96dd7225c4bcb","price":"0.64","side":"SELL","size":"32"}],"timestamp":"1785211590531"},"payload_hash":"dcb1c57b33cfe326a968b59dded62e9b983caf839dc6f2becc163f169613512a","raw_frame":"{\"market\":\"0xd412ce774cfcf8dc9f71164aac78783978aac7b03871702a3b8a481bd9dc9688\", \"price_changes\":[{\"asset_id\":\"96600821790790307414914106093858868634329285205417149685270682748367152458577\", \"price\":\"0.36\", \"size\":\"32\", \"side\":\"BUY\", \"hash\":\"b9d26fa6dfee1df38e60bee4e9928738b8c101bf\", \"best_bid\":\"0.38\", \"best_ask\":\"0.39\"}, {\"asset_id\":\"107603864457683460275633293642179940881969192120168665300712204232021063124301\", \"price\":\"0.64\", \"size\":\"32\", \"side\":\"SELL\", \"hash\":\"9f38e6add7655aad06702f4a20c96dd7225c4bcb\", \"best_bid\":\"0.61\", \"best_ask\":\"0.62\"}], \"timestamp\":\"1785211590531\", \"event_type\":\"price_change\"}","received_at":"2026-07-28T04:06:30.333047Z","schema_version":"clob-market-ws.price_change.v1","sequence":null,"server_hash":null,"server_timestamp":"1785211590531","session_id":"2d607381e3054cee91998cdf45a4231c","source":"clob_market_ws"},"received_at":"2026-07-28T04:06:30.333047Z","record_id":"c2fc7fcfaa669fedec1033f77f6be5639fbd1265081f779c99454c61bfcee0f0","schema_fingerprint":"4aa3821a28b0b7c2400bc59aba4bcc0a76e971dadd19610d3ad38c768e124dc7","schema_version":"edge-lab-recorder.raw.v1","sequence":null,"source":"clob_market_ws"}
{"event_at":"2026-07-28T04:06:30.538000Z","event_fingerprint":"a14d44013d5504165f4e901730962aa0db46a09400a52e1d6f7bc5d498e217dc","payload":{"connection_id":"f6725804f86a4c4eb588e4d5ed7db029","event_at":"2026-07-28T04:06:30.538000Z","event_type":"price_change","frame_hash":"e4be7746c7ef0a2d0cce2690ceb9369b70923af7f7a95abfda7ee398238ba574","frame_index":0,"kind":"data","monotonic_ns":313573389926833,"payload":{"event_type":"price_change","market":"0xd412ce774cfcf8dc9f71164aac78783978aac7b03871702a3b8a481bd9dc9688","price_changes":[{"asset_id":"107603864457683460275633293642179940881969192120168665300712204232021063124301","best_ask":"0.62","best_bid":"0.61","hash":"6b915e1e9f560034a434ebb821ad0eb0f8e73585","price":"0.01","side":"BUY","size":"5638.02"},{"asset_id":"96600821790790307414914106093858868634329285205417149685270682748367152458577","best_ask":"0.39","best_bid":"0.38","hash":"cd549c1f076dd8d91a33349b905478ebc6f4e392","price":"0.99","side":"SELL","size":"5638.02"}],"timestamp":"1785211590538"},"payload_hash":"ea7f4913f09af1f863a70133d3ddd8dffcc761d3207bb879a7cc4c90833defe2","raw_frame":"{\"market\":\"0xd412ce774cfcf8dc9f71164aac78783978aac7b03871702a3b8a481bd9dc9688\", \"price_changes\":[{\"asset_id\":\"107603864457683460275633293642179940881969192120168665300712204232021063124301\", \"price\":\"0.01\", \"size\":\"5638.02\", \"side\":\"BUY\", \"hash\":\"6b915e1e9f560034a434ebb821ad0eb0f8e73585\", \"best_bid\":\"0.61\", \"best_ask\":\"0.62\"}, {\"asset_id\":\"96600821790790307414914106093858868634329285205417149685270682748367152458577\", \"price\":\"0.99\", \"size\":\"5638.02\", \"side\":\"SELL\", \"hash\":\"cd549c1f076dd8d91a33349b905478ebc6f4e392\", \"best_bid\":\"0.38\", \"best_ask\":\"0.39\"}], \"timestamp\":\"1785211590538\", \"event_type\":\"price_change\"}","received_at":"2026-07-28T04:06:30.339123Z","schema_version":"clob-market-ws.price_change.v1","sequence":null,"server_hash":null,"server_timestamp":"1785211590538","session_id":"2d607381e3054cee91998cdf45a4231c","source":"clob_market_ws"},"received_at":"2026-07-28T04:06:30.339123Z","record_id":"21794460e511355248f4c7328d910e44fcf653d654da28663021fa31838e7fb1","schema_fingerprint":"4aa3821a28b0b7c2400bc59aba4bcc0a76e971dadd19610d3ad38c768e124dc7","schema_version":"edge-lab-recorder.raw.v1","sequence":null,"source":"clob_market_ws"}
{"event_at":"2026-07-28T04:06:30.552000Z","event_fingerprint":"a32d586e2324883774dcebbf8b3035ed472803c5893f9aa10e5160773418b222","payload":{"connection_id":"f6725804f86a4c4eb588e4d5ed7db029","event_at":"2026-07-28T04:06:30.552000Z","event_type":"price_change","frame_hash":"8cff37b78b3ddf6b94f10c01ae9c9d1cc0c0b868e10f8c8713eb251069c58db8","frame_index":0,"kind":"data","monotonic_ns":313573403681958,"payload":{"event_type":"price_change","market":"0xd412ce774cfcf8dc9f71164aac78783978aac7b03871702a3b8a481bd9dc9688","price_changes":[{"asset_id":"107603864457683460275633293642179940881969192120168665300712204232021063124301","best_ask":"0.62","best_bid":"0.61","hash":"c0bc4763e1a8a097016ce90c05b1bd58ef1012d2","price":"0.02","side":"BUY","size":"688.1"},{"asset_id":"96600821790790307414914106093858868634329285205417149685270682748367152458577","best_ask":"0.39","best_bid":"0.38","hash":"4a1dd5fd27f9f230450b2f22ff1324308cf1a21b","price":"0.98","side":"SELL","size":"688.1"}],"timestamp":"1785211590552"},"payload_hash":"2dfe5425c8b50c47fdd703d9097e55e714b141049ba7760566ecc668f4aaa299","raw_frame":"{\"market\":\"0xd412ce774cfcf8dc9f71164aac78783978aac7b03871702a3b8a481bd9dc9688\", \"price_changes\":[{\"asset_id\":\"107603864457683460275633293642179940881969192120168665300712204232021063124301\", \"price\":\"0.02\", \"size\":\"688.1\", \"side\":\"BUY\", \"hash\":\"c0bc4763e1a8a097016ce90c05b1bd58ef1012d2\", \"best_bid\":\"0.61\", \"best_ask\":\"0.62\"}, {\"asset_id\":\"96600821790790307414914106093858868634329285205417149685270682748367152458577\", \"price\":\"0.98\", \"size\":\"688.1\", \"side\":\"SELL\", \"hash\":\"4a1dd5fd27f9f230450b2f22ff1324308cf1a21b\", \"best_bid\":\"0.38\", \"best_ask\":\"0.39\"}], \"timestamp\":\"1785211590552\", \"event_type\":\"price_change\"}","received_at":"2026-07-28T04:06:30.352877Z","schema_version":"clob-market-ws.price_change.v1","sequence":null,"server_hash":null,"server_timestamp":"1785211590552","session_id":"2d607381e3054cee91998cdf45a4231c","source":"clob_market_ws"},"received_at":"2026-07-28T04:06:30.352877Z","record_id":"acc6763ef8119bc0acc32f1de85ce8c8c7f6c8f2977b6b1f1a7728730c13ce2f","schema_fingerprint":"4aa3821a28b0b7c2400bc59aba4bcc0a76e971dadd19610d3ad38c768e124dc7","schema_version":"edge-lab-recorder.raw.v1","sequence":null,"source":"clob_market_ws"}
{"event_at":null,"event_fingerprint":"80b861ba535c0fc9c88d5c4983ad14a9e9e67ffde2f2e1618b2f06844dac673c","payload":{"connection_id":"f6725804f86a4c4eb588e4d5ed7db029","detail":{"interval_seconds":10.0,"message":"PING"},"event_type":"heartbeat","kind":"lifecycle","monotonic_ns":313573462713333,"received_at":"2026-07-28T04:06:30.411908Z","schema_version":"edge-lab-recorder.lifecycle.v1","session_id":"2d607381e3054cee91998cdf45a4231c","source":"clob_market_ws"},"received_at":"2026-07-28T04:06:30.411908Z","record_id":"083c6528473d8c6049b36ed67cb4be8e54c2f538b91ce297d02c7fa55f8d0bd8","schema_fingerprint":"cb8aa3aa4cb168a4b724fd9077bee6ecfb9bc586c57cfdf0ab89f00d82045e3c","schema_version":"edge-lab-recorder.raw.v1","sequence":null,"source":"clob_market_ws"}
{"event_at":"2026-07-28T04:06:30.681000Z","event_fingerprint":"fb93d44a1c5f3600f2c5fa4ad042e4e5f28f43c3d17a0575762af259183994bf","payload":{"connection_id":"f6725804f86a4c4eb588e4d5ed7db029","event_at":"2026-07-28T04:06:30.681000Z","event_type":"price_change","frame_hash":"4818f1323135eaeb56dbed62026df5fc9dfefda9150f155765d85eda26b240fb","frame_index":0,"kind":"data","monotonic_ns":313573535211875,"payload":{"event_type":"price_change","market":"0xd412ce774cfcf8dc9f71164aac78783978aac7b03871702a3b8a481bd9dc9688","price_changes":[{"asset_id":"96600821790790307414914106093858868634329285205417149685270682748367152458577","best_ask":"0.39","best_bid":"0.38","hash":"0be723e731cb0a5a6b3f007e374df799651fc33e","price":"0.36","side":"BUY","size":"21"},{"asset_id":"107603864457683460275633293642179940881969192120168665300712204232021063124301","best_ask":"0.62","best_bid":"0.61","hash":"d860ef98469bf3ef9861a50fb784412f6638148f","price":"0.64","side":"SELL","size":"21"}],"timestamp":"1785211590681"},"payload_hash":"e54b83a2a5705fbdb3f8df7af25999ae567f01b88f15407323b90daa80e92556","raw_frame":"{\"market\":\"0xd412ce774cfcf8dc9f71164aac78783978aac7b03871702a3b8a481bd9dc9688\", \"price_changes\":[{\"asset_id\":\"96600821790790307414914106093858868634329285205417149685270682748367152458577\", \"price\":\"0.36\", \"size\":\"21\", \"side\":\"BUY\", \"hash\":\"0be723e731cb0a5a6b3f007e374df799651fc33e\", \"best_bid\":\"0.38\", \"best_ask\":\"0.39\"}, {\"asset_id\":\"107603864457683460275633293642179940881969192120168665300712204232021063124301\", \"price\":\"0.64\", \"size\":\"21\", \"side\":\"SELL\", \"hash\":\"d860ef98469bf3ef9861a50fb784412f6638148f\", \"best_bid\":\"0.61\", \"best_ask\":\"0.62\"}], \"timestamp\":\"1785211590681\", \"event_type\":\"price_change\"}","received_at":"2026-07-28T04:06:30.484407Z","schema_version":"clob-market-ws.price_change.v1","sequence":null,"server_hash":null,"server_timestamp":"1785211590681","session_id":"2d607381e3054cee91998cdf45a4231c","source":"clob_market_ws"},"received_at":"2026-07-28T04:06:30.484407Z","record_id":"b333b03f317d30222935010194e74c11085a935a5d68dc72f7b2092d7322fe7d","schema_fingerprint":"4aa3821a28b0b7c2400bc59aba4bcc0a76e971dadd19610d3ad38c768e124dc7","schema_version":"edge-lab-recorder.raw.v1","sequence":null,"source":"clob_market_ws"}
{"event_at":"2026-07-28T04:06:30.683000Z","event_fingerprint":"519e0bba0a8da044795078111aaea9d64b9e8457be31c98b6c6b80177a02cd3c","payload":{"connection_id":"f6725804f86a4c4eb588e4d5ed7db029","event_at":"2026-07-28T04:06:30.683000Z","event_type":"price_change","frame_hash":"6936d0938820528a7d702886614b8922ffc3d0cc0a33a946b96322908e6e6e78","frame_index":0,"kind":"data","monotonic_ns":313573538930041,"payload":{"event_type":"price_change","market":"0xd412ce774cfcf8dc9f71164aac78783978aac7b03871702a3b8a481bd9dc9688","price_changes":[{"asset_id":"107603864457683460275633293642179940881969192120168665300712204232021063124301","best_ask":"0.62","best_bid":"0.61","hash":"ca03330693851b3f21663eabf924a4bd6656a266","price":"0.64","side":"SELL","size":"31.61"},{"asset_id":"96600821790790307414914106093858868634329285205417149685270682748367152458577","best_ask":"0.39","best_bid":"0.38","hash":"e133ae0abf4e1de42994465ded8f5e4e96e39fd1","price":"0.36","side":"BUY","size":"31.61"}],"timestamp":"1785211590683"},"payload_hash":"ff04a5654ec3c31a2f5120517d4050a6e14481dc28d23ea627a2dad74e2898a6","raw_frame":"{\"market\":\"0xd412ce774cfcf8dc9f71164aac78783978aac7b03871702a3b8a481bd9dc9688\", \"price_changes\":[{\"asset_id\":\"107603864457683460275633293642179940881969192120168665300712204232021063124301\", \"price\":\"0.64\", \"size\":\"31.61\", \"side\":\"SELL\", \"hash\":\"ca03330693851b3f21663eabf924a4bd6656a266\", \"best_bid\":\"0.61\", \"best_ask\":\"0.62\"}, {\"asset_id\":\"96600821790790307414914106093858868634329285205417149685270682748367152458577\", \"price\":\"0.36\", \"size\":\"31.61\", \"side\":\"BUY\", \"hash\":\"e133ae0abf4e1de42994465ded8f5e4e96e39fd1\", \"best_bid\":\"0.38\", \"best_ask\":\"0.39\"}], \"timestamp\":\"1785211590683\", \"event_type\":\"price_change\"}","received_at":"2026-07-28T04:06:30.488124Z","schema_version":"clob-market-ws.price_change.v1","sequence":null,"server_hash":null,"server_timestamp":"1785211590683","session_id":"2d607381e3054cee91998cdf45a4231c","source":"clob_market_ws"},"received_at":"2026-07-28T04:06:30.488124Z","record_id":"2680f04cfe7eb5005b4b9f967ac41d8a47ec464b25d5acecd067b7b6d25f7a1d","schema_fingerprint":"4aa3821a28b0b7c2400bc59aba4bcc0a76e971dadd19610d3ad38c768e124dc7","schema_version":"edge-lab-recorder.raw.v1","sequence":null,"source":"clob_market_ws"}
{"event_at":"2026-07-28T04:06:30.696000Z","event_fingerprint":"dbaebc1ae42e73c23ef1c8b481e45423ab2c6aa7daeae24b8deda62f86f88c55","payload":{"connection_id":"f6725804f86a4c4eb588e4d5ed7db029","event_at":"2026-07-28T04:06:30.696000Z","event_type":"price_change","frame_hash":"32f56824398c0e7c5dd6960e3a322c68e7dfcacbc6a57d59df16e96c7a02ddeb","frame_index":0,"kind":"data","monotonic_ns":313573549209791,"payload":{"event_type":"price_change","market":"0xd412ce774cfcf8dc9f71164aac78783978aac7b03871702a3b8a481bd9dc9688","price_changes":[{"asset_id":"107603864457683460275633293642179940881969192120168665300712204232021063124301","best_ask":"0.62","best_bid":"0.61","hash":"fada4a776eafb826182489a9df7dfe4d1168d0c4","price":"0.04","side":"BUY","size":"623.09"},{"asset_id":"96600821790790307414914106093858868634329285205417149685270682748367152458577","best_ask":"0.39","best_bid":"0.38","hash":"e7e6081948bc58a3b64ef5180d3418719a85ed87","price":"0.96","side":"SELL","size":"623.09"}],"timestamp":"1785211590696"},"payload_hash":"41e3289c5f298c59489d42acec600d1cb8c0e1a127508c695dd228f7d8ad2583","raw_frame":"{\"market\":\"0xd412ce774cfcf8dc9f71164aac78783978aac7b03871702a3b8a481bd9dc9688\", \"price_changes\":[{\"asset_id\":\"107603864457683460275633293642179940881969192120168665300712204232021063124301\", \"price\":\"0.04\", \"size\":\"623.09\", \"side\":\"BUY\", \"hash\":\"fada4a776eafb826182489a9df7dfe4d1168d0c4\", \"best_bid\":\"0.61\", \"best_ask\":\"0.62\"}, {\"asset_id\":\"96600821790790307414914106093858868634329285205417149685270682748367152458577\", \"price\":\"0.96\", \"size\":\"623.09\", \"side\":\"SELL\", \"hash\":\"e7e6081948bc58a3b64ef5180d3418719a85ed87\", \"best_bid\":\"0.38\", \"best_ask\":\"0.39\"}], \"timestamp\":\"1785211590696\", \"event_type\":\"price_change\"}","received_at":"2026-07-28T04:06:30.498403Z","schema_version":"clob-market-ws.price_change.v1","sequence":null,"server_hash":null,"server_timestamp":"1785211590696","session_id":"2d607381e3054cee91998cdf45a4231c","source":"clob_market_ws"},"received_at":"2026-07-28T04:06:30.498403Z","record_id":"32ea4919ef78cbc3b80f2b0f199a73e23caaf547f7d7ec73e6f6f354be3eb6aa","schema_fingerprint":"4aa3821a28b0b7c2400bc59aba4bcc0a76e971dadd19610d3ad38c768e124dc7","schema_version":"edge-lab-recorder.raw.v1","sequence":null,"source":"clob_market_ws"}
{"event_at":"2026-07-28T04:06:30.712000Z","event_fingerprint":"db35428488cb4cab0d17fb4642d3f86af1d0c4b57ba15f1a2e94e9c2c160978c","payload":{"connection_id":"f6725804f86a4c4eb588e4d5ed7db029","event_at":"2026-07-28T04:06:30.712000Z","event_type":"price_change","frame_hash":"97c0147fb630200f192459402fc906570d5e2d8e39cef19ce8e628ca54f7bb5a","frame_index":0,"kind":"data","monotonic_ns":313573564902500,"payload":{"event_type":"price_change","market":"0xd412ce774cfcf8dc9f71164aac78783978aac7b03871702a3b8a481bd9dc9688","price_changes":[{"asset_id":"107603864457683460275633293642179940881969192120168665300712204232021063124301","best_ask":"0.62","best_bid":"0.61","hash":"e1e32767288f76435be97be1a8fefd67db0c6299","price":"0.01","side":"BUY","size":"5643.02"},{"asset_id":"96600821790790307414914106093858868634329285205417149685270682748367152458577","best_ask":"0.39","best_bid":"0.38","hash":"c08a8eb2b97ae3bb0946eb10a96128200ed7bac6","price":"0.99","side":"SELL","size":"5643.02"}],"timestamp":"1785211590712"},"payload_hash":"60b4d5882567353df82aa0e59fa373e5eb19bc8ba9e158bf038e48bf74b95ee6","raw_frame":"{\"market\":\"0xd412ce774cfcf8dc9f71164aac78783978aac7b03871702a3b8a481bd9dc9688\", \"price_changes\":[{\"asset_id\":\"107603864457683460275633293642179940881969192120168665300712204232021063124301\", \"price\":\"0.01\", \"size\":\"5643.02\", \"side\":\"BUY\", \"hash\":\"e1e32767288f76435be97be1a8fefd67db0c6299\", \"best_bid\":\"0.61\", \"best_ask\":\"0.62\"}, {\"asset_id\":\"96600821790790307414914106093858868634329285205417149685270682748367152458577\", \"price\":\"0.99\", \"size\":\"5643.02\", \"side\":\"SELL\", \"hash\":\"c08a8eb2b97ae3bb0946eb10a96128200ed7bac6\", \"best_bid\":\"0.38\", \"best_ask\":\"0.39\"}], \"timestamp\":\"1785211590712\", \"event_type\":\"price_change\"}","received_at":"2026-07-28T04:06:30.514096Z","schema_version":"clob-market-ws.price_change.v1","sequence":null,"server_hash":null,"server_timestamp":"1785211590712","session_id":"2d607381e3054cee91998cdf45a4231c","source":"clob_market_ws"},"received_at":"2026-07-28T04:06:30.514096Z","record_id":"fdbbc951f08419881894a2f55cd8f11da40e512cf65e260cbd03f8b24cb12a3d","schema_fingerprint":"4aa3821a28b0b7c2400bc59aba4bcc0a76e971dadd19610d3ad38c768e124dc7","schema_version":"edge-lab-recorder.raw.v1","sequence":null,"source":"clob_market_ws"}
{"event_at":"2026-07-28T04:06:30.740000Z","event_fingerprint":"3d747b8fac958e2e925d44cee0a96ec5d764dd6d15b8402f6410525025900652","payload":{"connection_id":"f6725804f86a4c4eb588e4d5ed7db029","event_at":"2026-07-28T04:06:30.740000Z","event_type":"price_change","frame_hash":"0d59f34eb2c70e5e2d852e9ddcf84bdd4a643a0277931891c72e3c5f0f894658","frame_index":0,"kind":"data","monotonic_ns":313573591683291,"payload":{"event_type":"price_change","market":"0xd412ce774cfcf8dc9f71164aac78783978aac7b03871702a3b8a481bd9dc9688","price_changes":[{"asset_id":"107603864457683460275633293642179940881969192120168665300712204232021063124301","best_ask":"0.62","best_bid":"0.61","hash":"b4f18f8e7bc93f536044ac5c112cd79422eab9bf","price":"0.01","side":"BUY","size":"5638.02"},{"asset_id":"96600821790790307414914106093858868634329285205417149685270682748367152458577","best_ask":"0.39","best_bid":"0.38","hash":"eec7503b2f80df5eff3e4be6897b252515d12f61","price":"0.99","side":"SELL","size":"5638.02"}],"timestamp":"1785211590740"},"payload_hash":"ebbc3afec6950404982990db95fc5537bb43ddb92565a5918b7196a4f76ad3fa","raw_frame":"{\"market\":\"0xd412ce774cfcf8dc9f71164aac78783978aac7b03871702a3b8a481bd9dc9688\", \"price_changes\":[{\"asset_id\":\"107603864457683460275633293642179940881969192120168665300712204232021063124301\", \"price\":\"0.01\", \"size\":\"5638.02\", \"side\":\"BUY\", \"hash\":\"b4f18f8e7bc93f536044ac5c112cd79422eab9bf\", \"best_bid\":\"0.61\", \"best_ask\":\"0.62\"}, {\"asset_id\":\"96600821790790307414914106093858868634329285205417149685270682748367152458577\", \"price\":\"0.99\", \"size\":\"5638.02\", \"side\":\"SELL\", \"hash\":\"eec7503b2f80df5eff3e4be6897b252515d12f61\", \"best_bid\":\"0.38\", \"best_ask\":\"0.39\"}], \"timestamp\":\"1785211590740\", \"event_type\":\"price_change\"}","received_at":"2026-07-28T04:06:30.540876Z","schema_version":"clob-market-ws.price_change.v1","sequence":null,"server_hash":null,"server_timestamp":"1785211590740","session_id":"2d607381e3054cee91998cdf45a4231c","source":"clob_market_ws"},"received_at":"2026-07-28T04:06:30.540876Z","record_id":"be8bff28306abc2ec479262381e46d79b32a9e68d11c868ca73ffa96e08d174d","schema_fingerprint":"4aa3821a28b0b7c2400bc59aba4bcc0a76e971dadd19610d3ad38c768e124dc7","schema_version":"edge-lab-recorder.raw.v1","sequence":null,"source":"clob_market_ws"}
{"event_at":"2026-07-28T04:06:30.765000Z","event_fingerprint":"399b22b7f226b1f4b2c131f7d8c7a871384330876c6619fb3a037f5df30726e0","payload":{"connection_id":"f6725804f86a4c4eb588e4d5ed7db029","event_at":"2026-07-28T04:06:30.765000Z","event_type":"price_change","frame_hash":"f6cad3a9d29cadf28f15dca49f7a99fa8cc0beda9646fb74b45d62b0c157916a","frame_index":0,"kind":"data","monotonic_ns":313573625140833,"payload":{"event_type":"price_change","market":"0xd412ce774cfcf8dc9f71164aac78783978aac7b03871702a3b8a481bd9dc9688","price_changes":[{"asset_id":"107603864457683460275633293642179940881969192120168665300712204232021063124301","best_ask":"0.62","best_bid":"0.61","hash":"f4da63d0a3ad5c295d79aa62aeabdc8e2914936e","price":"0.04","side":"BUY","size":"618.09"},{"asset_id":"96600821790790307414914106093858868634329285205417149685270682748367152458577","best_ask":"0.39","best_bid":"0.38","hash":"93804fb9e82acb86539f9d8b2c1aec5986ac669e","price":"0.96","side":"SELL","size":"618.09"}],"timestamp":"1785211590765"},"payload_hash":"772791c7f9d76019e86b0903bac3d5bdef021ffb72658962cd00a6119069f5b3","raw_frame":"{\"market\":\"0xd412ce774cfcf8dc9f71164aac78783978aac7b03871702a3b8a481bd9dc9688\", \"price_changes\":[{\"asset_id\":\"107603864457683460275633293642179940881969192120168665300712204232021063124301\", \"price\":\"0.04\", \"size\":\"618.09\", \"side\":\"BUY\", \"hash\":\"f4da63d0a3ad5c295d79aa62aeabdc8e2914936e\", \"best_bid\":\"0.61\", \"best_ask\":\"0.62\"}, {\"asset_id\":\"96600821790790307414914106093858868634329285205417149685270682748367152458577\", \"price\":\"0.96\", \"size\":\"618.09\", \"side\":\"SELL\", \"hash\":\"93804fb9e82acb86539f9d8b2c1aec5986ac669e\", \"best_bid\":\"0.38\", \"best_ask\":\"0.39\"}], \"timestamp\":\"1785211590765\", \"event_type\":\"price_change\"}","received_at":"2026-07-28T04:06:30.574334Z","schema_version":"clob-market-ws.price_change.v1","sequence":null,"server_hash":null,"server_timestamp":"1785211590765","session_id":"2d607381e3054cee91998cdf45a4231c","source":"clob_market_ws"},"received_at":"2026-07-28T04:06:30.574334Z","record_id":"04da8357a3a604aa33dff2ed92dd0dd88c77e55795ae4d2ae982fc127ebdbfae","schema_fingerprint":"4aa3821a28b0b7c2400bc59aba4bcc0a76e971dadd19610d3ad38c768e124dc7","schema_version":"edge-lab-recorder.raw.v1","sequence":null,"source":"clob_market_ws"}
{"event_at":"2026-07-28T04:06:30.806000Z","event_fingerprint":"da464afbbb8e423b039fb34b4bfabbcb88dad9a2ffc9a2f8fc4c8df259c0efdd","payload":{"connection_id":"f6725804f86a4c4eb588e4d5ed7db029","event_at":"2026-07-28T04:06:30.806000Z","event_type":"price_change","frame_hash":"ed44ae7df3432c33c59c539131a951ebca645e4bc6dbe58a76e9e1bf401f52a9","frame_index":0,"kind":"data","monotonic_ns":313573658296500,"payload":{"event_type":"price_change","market":"0xd412ce774cfcf8dc9f71164aac78783978aac7b03871702a3b8a481bd9dc9688","price_changes":[{"asset_id":"96600821790790307414914106093858868634329285205417149685270682748367152458577","best_ask":"0.39","best_bid":"0.38","hash":"67c87fe852cca0759bcca03fba6e396c19c8f135","price":"0.38","side":"BUY","size":"15"},{"asset_id":"107603864457683460275633293642179940881969192120168665300712204232021063124301","best_ask":"0.62","best_bid":"0.61","hash":"b4286787fbff58a48808ea796c7c8ed3c9020da7","price":"0.62","side":"SELL","size":"15"}],"timestamp":"1785211590806"},"payload_hash":"3215751ff71d98eb248d248c6821b3f809c0ee917379520d4e18aa24af52f89c","raw_frame":"{\"market\":\"0xd412ce774cfcf8dc9f71164aac78783978aac7b03871702a3b8a481bd9dc9688\", \"price_changes\":[{\"asset_id\":\"96600821790790307414914106093858868634329285205417149685270682748367152458577\", \"price\":\"0.38\", \"size\":\"15\", \"side\":\"BUY\", \"hash\":\"67c87fe852cca0759bcca03fba6e396c19c8f135\", \"best_bid\":\"0.38\", \"best_ask\":\"0.39\"}, {\"asset_id\":\"107603864457683460275633293642179940881969192120168665300712204232021063124301\", \"price\":\"0.62\", \"size\":\"15\", \"side\":\"SELL\", \"hash\":\"b4286787fbff58a48808ea796c7c8ed3c9020da7\", \"best_bid\":\"0.61\", \"best_ask\":\"0.62\"}], \"timestamp\":\"1785211590806\", \"event_type\":\"price_change\"}","received_at":"2026-07-28T04:06:30.607490Z","schema_version":"clob-market-ws.price_change.v1","sequence":null,"server_hash":null,"server_timestamp":"1785211590806","session_id":"2d607381e3054cee91998cdf45a4231c","source":"clob_market_ws"},"received_at":"2026-07-28T04:06:30.607490Z","record_id":"14a62c6a5da76f11f1c4350c3032b720a6e4735532a5839b4d8890470458115a","schema_fingerprint":"4aa3821a28b0b7c2400bc59aba4bcc0a76e971dadd19610d3ad38c768e124dc7","schema_version":"edge-lab-recorder.raw.v1","sequence":null,"source":"clob_market_ws"}
{"event_at":"2026-07-28T04:06:30.809000Z","event_fingerprint":"465ab944f8a245484ff3d3b0a4f14f19783f07b4e11d70f71c820ec7441d8601","payload":{"connection_id":"f6725804f86a4c4eb588e4d5ed7db029","event_at":"2026-07-28T04:06:30.809000Z","event_type":"price_change","frame_hash":"d49a7b5a32f7bf9c62d2ab35053f2cbe1c9f5376bde71d2a3332118238735a4e","frame_index":0,"kind":"data","monotonic_ns":313573663544166,"payload":{"event_type":"price_change","market":"0xd412ce774cfcf8dc9f71164aac78783978aac7b03871702a3b8a481bd9dc9688","price_changes":[{"asset_id":"96600821790790307414914106093858868634329285205417149685270682748367152458577","best_ask":"0.39","best_bid":"0.38","hash":"7ece65e73a21c7964d177ef1334b02f4fa192683","price":"0.36","side":"BUY","size":"42.61"},{"asset_id":"107603864457683460275633293642179940881969192120168665300712204232021063124301","best_ask":"0.62","best_bid":"0.61","hash":"d81657e535863eefc12c0f69cfdcd7ad6ae56ae5","price":"0.64","side":"SELL","size":"42.61"}],"timestamp":"1785211590809"},"payload_hash":"0f7a2189b29cb454bcdecb511d55d4deafc423e29baa666356d6949aa0ac54cb","raw_frame":"{\"market\":\"0xd412ce774cfcf8dc9f71164aac78783978aac7b03871702a3b8a481bd9dc9688\", \"price_changes\":[{\"asset_id\":\"96600821790790307414914106093858868634329285205417149685270682748367152458577\", \"price\":\"0.36\", \"size\":\"42.61\", \"side\":\"BUY\", \"hash\":\"7ece65e73a21c7964d177ef1334b02f4fa192683\", \"best_bid\":\"0.38\", \"best_ask\":\"0.39\"}, {\"asset_id\":\"107603864457683460275633293642179940881969192120168665300712204232021063124301\", \"price\":\"0.64\", \"size\":\"42.61\", \"side\":\"SELL\", \"hash\":\"d81657e535863eefc12c0f69cfdcd7ad6ae56ae5\", \"best_bid\":\"0.61\", \"best_ask\":\"0.62\"}], \"timestamp\":\"1785211590809\", \"event_type\":\"price_change\"}","received_at":"2026-07-28T04:06:30.612739Z","schema_version":"clob-market-ws.price_change.v1","sequence":null,"server_hash":null,"server_timestamp":"1785211590809","session_id":"2d607381e3054cee91998cdf45a4231c","source":"clob_market_ws"},"received_at":"2026-07-28T04:06:30.612739Z","record_id":"23eb9e84b74701b3e53c003044d9b424ebfc3f9071da45880468ce6dd6d3b44b","schema_fingerprint":"4aa3821a28b0b7c2400bc59aba4bcc0a76e971dadd19610d3ad38c768e124dc7","schema_version":"edge-lab-recorder.raw.v1","sequence":null,"source":"clob_market_ws"}
{"event_at":"2026-07-28T04:06:30.810000Z","event_fingerprint":"47a7a905d0d854063ed4aa07b8acb8e450baae8b33d28784153536a2b7f579c1","payload":{"connection_id":"f6725804f86a4c4eb588e4d5ed7db029","event_at":"2026-07-28T04:06:30.810000Z","event_type":"price_change","frame_hash":"a4a81899ee35834d692b80d5b7ed6626adba013900ae4bced8e9b2961eaba126","frame_index":0,"kind":"data","monotonic_ns":313573668160958,"payload":{"event_type":"price_change","market":"0xd412ce774cfcf8dc9f71164aac78783978aac7b03871702a3b8a481bd9dc9688","price_changes":[{"asset_id":"107603864457683460275633293642179940881969192120168665300712204232021063124301","best_ask":"0.62","best_bid":"0.61","hash":"981c6bc93fcc05128ce7c29414810eef4c702e86","price":"0.64","side":"SELL","size":"32"},{"asset_id":"96600821790790307414914106093858868634329285205417149685270682748367152458577","best_ask":"0.39","best_bid":"0.38","hash":"beed587acefa0b78c435fc90295ca39e77d0dbce","price":"0.36","side":"BUY","size":"32"}],"timestamp":"1785211590810"},"payload_hash":"9c281ad3790ddaa2aab0235f8940d3e7e0289d5d48ddcd8dc3b4a095b2371690","raw_frame":"{\"market\":\"0xd412ce774cfcf8dc9f71164aac78783978aac7b03871702a3b8a481bd9dc9688\", \"price_changes\":[{\"asset_id\":\"107603864457683460275633293642179940881969192120168665300712204232021063124301\", \"price\":\"0.64\", \"size\":\"32\", \"side\":\"SELL\", \"hash\":\"981c6bc93fcc05128ce7c29414810eef4c702e86\", \"best_bid\":\"0.61\", \"best_ask\":\"0.62\"}, {\"asset_id\":\"96600821790790307414914106093858868634329285205417149685270682748367152458577\", \"price\":\"0.36\", \"size\":\"32\", \"side\":\"BUY\", \"hash\":\"beed587acefa0b78c435fc90295ca39e77d0dbce\", \"best_bid\":\"0.38\", \"best_ask\":\"0.39\"}], \"timestamp\":\"1785211590810\", \"event_type\":\"price_change\"}","received_at":"2026-07-28T04:06:30.617355Z","schema_version":"clob-market-ws.price_change.v1","sequence":null,"server_hash":null,"server_timestamp":"1785211590810","session_id":"2d607381e3054cee91998cdf45a4231c","source":"clob_market_ws"},"received_at":"2026-07-28T04:06:30.617355Z","record_id":"c2bd94bb4dce11e1c4a49b9e48785390c3784f3c8b7361cf85206f556d44215a","schema_fingerprint":"4aa3821a28b0b7c2400bc59aba4bcc0a76e971dadd19610d3ad38c768e124dc7","schema_version":"edge-lab-recorder.raw.v1","sequence":null,"source":"clob_market_ws"}
{"event_at":null,"event_fingerprint":"fe3dcb260b90ac05acad1835b2be6431432805f9e259c6609d9325361f9b5c7c","payload":{"connection_id":"f6725804f86a4c4eb588e4d5ed7db029","event_type":"heartbeat_ack","frame_hash":"95784973cc639977bff93619700168505cb8f7855e44fa643d34622a43706c87","kind":"lifecycle","monotonic_ns":313573673087625,"raw_frame":"PONG","received_at":"2026-07-28T04:06:30.622282Z","schema_version":"edge-lab-recorder.heartbeat-ack.v1","session_id":"2d607381e3054cee91998cdf45a4231c","source":"clob_market_ws"},"received_at":"2026-07-28T04:06:30.622282Z","record_id":"319f1b65b19a3339f668b0e16d517c8771dc8cad7d8110b4e1fe06fcdd9834ba","schema_fingerprint":"c14ee1aab3ca674ee738e5268877b544d74c41ad3c427cedc09236467dc68ba1","schema_version":"edge-lab-recorder.raw.v1","sequence":null,"source":"clob_market_ws"}
{"event_at":"2026-07-28T04:06:30.827000Z","event_fingerprint":"7e1495a6923080ea642d9636cef614aac7e9dd03964b9ad5ebbdaa28d8afc4fb","payload":{"connection_id":"f6725804f86a4c4eb588e4d5ed7db029","event_at":"2026-07-28T04:06:30.827000Z","event_type":"price_change","frame_hash":"88d29d8440c4db4e24ed225df2de48013fb1d83b370484cca17083535e2a6c7f","frame_index":0,"kind":"data","monotonic_ns":313573679981291,"payload":{"event_type":"price_change","market":"0xd412ce774cfcf8dc9f71164aac78783978aac7b03871702a3b8a481bd9dc9688","price_changes":[{"asset_id":"96600821790790307414914106093858868634329285205417149685270682748367152458577","best_ask":"0.39","best_bid":"0.38","hash":"33be993dd7c996d4fbfa678f1c901089f74ebee0","price":"0.37","side":"BUY","size":"40"},{"asset_id":"107603864457683460275633293642179940881969192120168665300712204232021063124301","best_ask":"0.62","best_bid":"0.61","hash":"1ccdb2b1600e105ac94e6496471fd25372975156","price":"0.63","side":"SELL","size":"40"}],"timestamp":"1785211590827"},"payload_hash":"ff1785b849699db0d7ccb1a2c8870b4b80948ba0993d0dd953f7ba09f2b2401b","raw_frame":"{\"market\":\"0xd412ce774cfcf8dc9f71164aac78783978aac7b03871702a3b8a481bd9dc9688\", \"price_changes\":[{\"asset_id\":\"96600821790790307414914106093858868634329285205417149685270682748367152458577\", \"price\":\"0.37\", \"size\":\"40\", \"side\":\"BUY\", \"hash\":\"33be993dd7c996d4fbfa678f1c901089f74ebee0\", \"best_bid\":\"0.38\", \"best_ask\":\"0.39\"}, {\"asset_id\":\"107603864457683460275633293642179940881969192120168665300712204232021063124301\", \"price\":\"0.63\", \"size\":\"40\", \"side\":\"SELL\", \"hash\":\"1ccdb2b1600e105ac94e6496471fd25372975156\", \"best_bid\":\"0.61\", \"best_ask\":\"0.62\"}], \"timestamp\":\"1785211590827\", \"event_type\":\"price_change\"}","received_at":"2026-07-28T04:06:30.629175Z","schema_version":"clob-market-ws.price_change.v1","sequence":null,"server_hash":null,"server_timestamp":"1785211590827","session_id":"2d607381e3054cee91998cdf45a4231c","source":"clob_market_ws"},"received_at":"2026-07-28T04:06:30.629175Z","record_id":"89a08dc25b05147e77d7af064d8b0990ce116f09b04b30283af3f35e5ecffd5d","schema_fingerprint":"4aa3821a28b0b7c2400bc59aba4bcc0a76e971dadd19610d3ad38c768e124dc7","schema_version":"edge-lab-recorder.raw.v1","sequence":null,"source":"clob_market_ws"}
{"event_at":"2026-07-28T04:06:30.850000Z","event_fingerprint":"c77082bfee1013e3ba470ed8e072f6d2e77ebee78814fce65d7529b7c7e955d3","payload":{"connection_id":"f6725804f86a4c4eb588e4d5ed7db029","event_at":"2026-07-28T04:06:30.850000Z","event_type":"price_change","frame_hash":"f0508a48216731df0a8af1a83e34a358ac62694eb9e962522cce537de9b7ec2e","frame_index":0,"kind":"data","monotonic_ns":313573701278458,"payload":{"event_type":"price_change","market":"0xd412ce774cfcf8dc9f71164aac78783978aac7b03871702a3b8a481bd9dc9688","price_changes":[{"asset_id":"107603864457683460275633293642179940881969192120168665300712204232021063124301","best_ask":"0.62","best_bid":"0.61","hash":"aba9f8bbdffb20ccb5a6dba530191b351327dac1","price":"0.03","side":"BUY","size":"623.1"},{"asset_id":"96600821790790307414914106093858868634329285205417149685270682748367152458577","best_ask":"0.39","best_bid":"0.38","hash":"0f141fb442857605bca46d2954649cf002921b54","price":"0.97","side":"SELL","size":"623.1"}],"timestamp":"1785211590850"},"payload_hash":"013f0662b1f9a07fc25e61d900b7c07d9cd7b442297a46109603d6570cb98ced","raw_frame":"{\"market\":\"0xd412ce774cfcf8dc9f71164aac78783978aac7b03871702a3b8a481bd9dc9688\", \"price_changes\":[{\"asset_id\":\"107603864457683460275633293642179940881969192120168665300712204232021063124301\", \"price\":\"0.03\", \"size\":\"623.1\", \"side\":\"BUY\", \"hash\":\"aba9f8bbdffb20ccb5a6dba530191b351327dac1\", \"best_bid\":\"0.61\", \"best_ask\":\"0.62\"}, {\"asset_id\":\"96600821790790307414914106093858868634329285205417149685270682748367152458577\", \"price\":\"0.97\", \"size\":\"623.1\", \"side\":\"SELL\", \"hash\":\"0f141fb442857605bca46d2954649cf002921b54\", \"best_bid\":\"0.38\", \"best_ask\":\"0.39\"}], \"timestamp\":\"1785211590850\", \"event_type\":\"price_change\"}","received_at":"2026-07-28T04:06:30.650471Z","schema_version":"clob-market-ws.price_change.v1","sequence":null,"server_hash":null,"server_timestamp":"1785211590850","session_id":"2d607381e3054cee91998cdf45a4231c","source":"clob_market_ws"},"received_at":"2026-07-28T04:06:30.650471Z","record_id":"4d6b519ac51b9e33d52c9d8266968a8b70c5e2a70f29e373d155a32807c1c929","schema_fingerprint":"4aa3821a28b0b7c2400bc59aba4bcc0a76e971dadd19610d3ad38c768e124dc7","schema_version":"edge-lab-recorder.raw.v1","sequence":null,"source":"clob_market_ws"}
{"event_at":"2026-07-28T04:06:30.922000Z","event_fingerprint":"7a497b17012d52072bfe1b3df74e495eb64393bfc9bb5e785c4e38ae2d298a6f","payload":{"connection_id":"f6725804f86a4c4eb588e4d5ed7db029","event_at":"2026-07-28T04:06:30.922000Z","event_type":"price_change","frame_hash":"d83553426df0c90819b865accc2825c417fedff933e264d8bbc4dc1a21d938af","frame_index":0,"kind":"data","monotonic_ns":313573777355791,"payload":{"event_type":"price_change","market":"0xd412ce774cfcf8dc9f71164aac78783978aac7b03871702a3b8a481bd9dc9688","price_changes":[{"asset_id":"107603864457683460275633293642179940881969192120168665300712204232021063124301","best_ask":"0.62","best_bid":"0.61","hash":"391b202f83eb2831c8cb8a67508e084aa01489a0","price":"0.01","side":"BUY","size":"5643.02"},{"asset_id":"96600821790790307414914106093858868634329285205417149685270682748367152458577","best_ask":"0.39","best_bid":"0.38","hash":"4b6100f7ecc480666274ad32ed09079b86beadc2","price":"0.99","side":"SELL","size":"5643.02"}],"timestamp":"1785211590922"},"payload_hash":"47c6e0d2a324c69718eb0a3ccb28c3406436245a99232cbbd9156874dc121140","raw_frame":"{\"market\":\"0xd412ce774cfcf8dc9f71164aac78783978aac7b03871702a3b8a481bd9dc9688\", \"price_changes\":[{\"asset_id\":\"107603864457683460275633293642179940881969192120168665300712204232021063124301\", \"price\":\"0.01\", \"size\":\"5643.02\", \"side\":\"BUY\", \"hash\":\"391b202f83eb2831c8cb8a67508e084aa01489a0\", \"best_bid\":\"0.61\", \"best_ask\":\"0.62\"}, {\"asset_id\":\"96600821790790307414914106093858868634329285205417149685270682748367152458577\", \"price\":\"0.99\", \"size\":\"5643.02\", \"side\":\"SELL\", \"hash\":\"4b6100f7ecc480666274ad32ed09079b86beadc2\", \"best_bid\":\"0.38\", \"best_ask\":\"0.39\"}], \"timestamp\":\"1785211590922\", \"event_type\":\"price_change\"}","received_at":"2026-07-28T04:06:30.726547Z","schema_version":"clob-market-ws.price_change.v1","sequence":null,"server_hash":null,"server_timestamp":"1785211590922","session_id":"2d607381e3054cee91998cdf45a4231c","source":"clob_market_ws"},"received_at":"2026-07-28T04:06:30.726547Z","record_id":"9e73c10631ef7c21ec4405d8437bbf265bf17159e55bc5e17c3628b79add9571","schema_fingerprint":"4aa3821a28b0b7c2400bc59aba4bcc0a76e971dadd19610d3ad38c768e124dc7","schema_version":"edge-lab-recorder.raw.v1","sequence":null,"source":"clob_market_ws"}
{"event_at":"2026-07-28T04:06:30.937000Z","event_fingerprint":"fdb843ace1ac599f606c42861843fb5db712aa0367ed0d0d8e424b3dc02c7f42","payload":{"connection_id":"f6725804f86a4c4eb588e4d5ed7db029","event_at":"2026-07-28T04:06:30.937000Z","event_type":"price_change","frame_hash":"76e94f0f0b5649dd5676846f1815d04a85fc2c1cc952d0782c5fec1d1cb4cecb","frame_index":0,"kind":"data","monotonic_ns":313573795484458,"payload":{"event_type":"price_change","market":"0xd412ce774cfcf8dc9f71164aac78783978aac7b03871702a3b8a481bd9dc9688","price_changes":[{"asset_id":"96600821790790307414914106093858868634329285205417149685270682748367152458577","best_ask":"0.39","best_bid":"0.38","hash":"59419b917c6b23b976dc7fe6b139486938fb164b","price":"0.36","side":"BUY","size":"21"},{"asset_id":"107603864457683460275633293642179940881969192120168665300712204232021063124301","best_ask":"0.62","best_bid":"0.61","hash":"f0430ab55a7b69218c9bfaac8669354a33df2f24","price":"0.64","side":"SELL","size":"21"}],"timestamp":"1785211590937"},"payload_hash":"a77452144dd7ea09b2abcd6081f88e6920452988ae5087b3dcb94cabfe0188eb","raw_frame":"{\"market\":\"0xd412ce774cfcf8dc9f71164aac78783978aac7b03871702a3b8a481bd9dc9688\", \"price_changes\":[{\"asset_id\":\"96600821790790307414914106093858868634329285205417149685270682748367152458577\", \"price\":\"0.36\", \"size\":\"21\", \"side\":\"BUY\", \"hash\":\"59419b917c6b23b976dc7fe6b139486938fb164b\", \"best_bid\":\"0.38\", \"best_ask\":\"0.39\"}, {\"asset_id\":\"107603864457683460275633293642179940881969192120168665300712204232021063124301\", \"price\":\"0.64\", \"size\":\"21\", \"side\":\"SELL\", \"hash\":\"f0430ab55a7b69218c9bfaac8669354a33df2f24\", \"best_bid\":\"0.61\", \"best_ask\":\"0.62\"}], \"timestamp\":\"1785211590937\", \"event_type\":\"price_change\"}","received_at":"2026-07-28T04:06:30.744676Z","schema_version":"clob-market-ws.price_change.v1","sequence":null,"server_hash":null,"server_timestamp":"1785211590937","session_id":"2d607381e3054cee91998cdf45a4231c","source":"clob_market_ws"},"received_at":"2026-07-28T04:06:30.744676Z","record_id":"eb787c0a830e00964b5743c0253a20b9bc23188ecc623729f5596597b9874548","schema_fingerprint":"4aa3821a28b0b7c2400bc59aba4bcc0a76e971dadd19610d3ad38c768e124dc7","schema_version":"edge-lab-recorder.raw.v1","sequence":null,"source":"clob_market_ws"}
{"event_at":"2026-07-28T04:06:30.941000Z","event_fingerprint":"1ae54600dded3a5c27c471589cc39b3e32a6bdee503135cbc99a7fb991281c03","payload":{"connection_id":"f6725804f86a4c4eb588e4d5ed7db029","event_at":"2026-07-28T04:06:30.941000Z","event_type":"price_change","frame_hash":"0985249df2736b16a7c8c890bb3ff77ac0e3198f511bde1a242aaef84ad4e556","frame_index":0,"kind":"data","monotonic_ns":313573800862125,"payload":{"event_type":"price_change","market":"0xd412ce774cfcf8dc9f71164aac78783978aac7b03871702a3b8a481bd9dc9688","price_changes":[{"asset_id":"107603864457683460275633293642179940881969192120168665300712204232021063124301","best_ask":"0.62","best_bid":"0.61","hash":"a5f65e96138ac0f0a46bc35b16f085e0917ed01a","price":"0.64","side":"SELL","size":"31"},{"asset_id":"96600821790790307414914106093858868634329285205417149685270682748367152458577","best_ask":"0.39","best_bid":"0.38","hash":"53850e449a32d7e389853fa11a00217f3ada7ab3","price":"0.36","side":"BUY","size":"31"}],"timestamp":"1785211590941"},"payload_hash":"18e4cd50b88fcf1f9c301e469014b1e11906bde2205d793294b90f5df8a632cb","raw_frame":"{\"market\":\"0xd412ce774cfcf8dc9f71164aac78783978aac7b03871702a3b8a481bd9dc9688\", \"price_changes\":[{\"asset_id\":\"107603864457683460275633293642179940881969192120168665300712204232021063124301\", \"price\":\"0.64\", \"size\":\"31\", \"side\":\"SELL\", \"hash\":\"a5f65e96138ac0f0a46bc35b16f085e0917ed01a\", \"best_bid\":\"0.61\", \"best_ask\":\"0.62\"}, {\"asset_id\":\"96600821790790307414914106093858868634329285205417149685270682748367152458577\", \"price\":\"0.36\", \"size\":\"31\", \"side\":\"BUY\", \"hash\":\"53850e449a32d7e389853fa11a00217f3ada7ab3\", \"best_bid\":\"0.38\", \"best_ask\":\"0.39\"}], \"timestamp\":\"1785211590941\", \"event_type\":\"price_change\"}","received_at":"2026-07-28T04:06:30.750054Z","schema_version":"clob-market-ws.price_change.v1","sequence":null,"server_hash":null,"server_timestamp":"1785211590941","session_id":"2d607381e3054cee91998cdf45a4231c","source":"clob_market_ws"},"received_at":"2026-07-28T04:06:30.750054Z","record_id":"d897010bc36b3f3fc6e3e437a12d63803cc259342961fb1c75e8c1ea584137be","schema_fingerprint":"4aa3821a28b0b7c2400bc59aba4bcc0a76e971dadd19610d3ad38c768e124dc7","schema_version":"edge-lab-recorder.raw.v1","sequence":null,"source":"clob_market_ws"}
{"event_at":"2026-07-28T04:06:30.947000Z","event_fingerprint":"5ef0c2a9702d13096675abaf98296a2e3836d159a8551a6becccd14181d2b45f","payload":{"connection_id":"f6725804f86a4c4eb588e4d5ed7db029","event_at":"2026-07-28T04:06:30.947000Z","event_type":"price_change","frame_hash":"29e8b3b7e4a2075d0958751481f9b9db1b63d91c0172f62bfd5824a7932d4955","frame_index":0,"kind":"data","monotonic_ns":313573806260583,"payload":{"event_type":"price_change","market":"0xd412ce774cfcf8dc9f71164aac78783978aac7b03871702a3b8a481bd9dc9688","price_changes":[{"asset_id":"107603864457683460275633293642179940881969192120168665300712204232021063124301","best_ask":"0.62","best_bid":"0.61","hash":"31167d0702fca543546db78e4278524c4990b28c","price":"0.01","side":"BUY","size":"5638.02"},{"asset_id":"96600821790790307414914106093858868634329285205417149685270682748367152458577","best_ask":"0.39","best_bid":"0.38","hash":"2ee9e886b4ce7f3cb081b3b202640181ee0bbc05","price":"0.99","side":"SELL","size":"5638.02"}],"timestamp":"1785211590947"},"payload_hash":"7d6491d03a8fb5a5ea1adf5ed5323a643f3b7c7ca21c6308f7e3dd314d8ccb03","raw_frame":"{\"market\":\"0xd412ce774cfcf8dc9f71164aac78783978aac7b03871702a3b8a481bd9dc9688\", \"price_changes\":[{\"asset_id\":\"107603864457683460275633293642179940881969192120168665300712204232021063124301\", \"price\":\"0.01\", \"size\":\"5638.02\", \"side\":\"BUY\", \"hash\":\"31167d0702fca543546db78e4278524c4990b28c\", \"best_bid\":\"0.61\", \"best_ask\":\"0.62\"}, {\"asset_id\":\"96600821790790307414914106093858868634329285205417149685270682748367152458577\", \"price\":\"0.99\", \"size\":\"5638.02\", \"side\":\"SELL\", \"hash\":\"2ee9e886b4ce7f3cb081b3b202640181ee0bbc05\", \"best_bid\":\"0.38\", \"best_ask\":\"0.39\"}], \"timestamp\":\"1785211590947\", \"event_type\":\"price_change\"}","received_at":"2026-07-28T04:06:30.755452Z","schema_version":"clob-market-ws.price_change.v1","sequence":null,"server_hash":null,"server_timestamp":"1785211590947","session_id":"2d607381e3054cee91998cdf45a4231c","source":"clob_market_ws"},"received_at":"2026-07-28T04:06:30.755452Z","record_id":"4097ae4317871bf2c3bb82035815c8e72bab98adaa30e980cec01193bbde434e","schema_fingerprint":"4aa3821a28b0b7c2400bc59aba4bcc0a76e971dadd19610d3ad38c768e124dc7","schema_version":"edge-lab-recorder.raw.v1","sequence":null,"source":"clob_market_ws"}
{"event_at":"2026-07-28T04:06:30.947000Z","event_fingerprint":"a848338f84075258acf9281ee08f7c3d4e12b6be957051515a851512872d98b5","payload":{"connection_id":"f6725804f86a4c4eb588e4d5ed7db029","event_at":"2026-07-28T04:06:30.947000Z","event_type":"price_change","frame_hash":"279c7c66e93e43a51d9a11314c71137f6bcbb88caa3cdbd6142a366469fd6730","frame_index":0,"kind":"data","monotonic_ns":313573809493291,"payload":{"event_type":"price_change","market":"0xd412ce774cfcf8dc9f71164aac78783978aac7b03871702a3b8a481bd9dc9688","price_changes":[{"asset_id":"107603864457683460275633293642179940881969192120168665300712204232021063124301","best_ask":"0.62","best_bid":"0.61","hash":"f359250d2d7a9353def01d7ebbbb6e4650a615b6","price":"0.03","side":"BUY","size":"618.1"},{"asset_id":"96600821790790307414914106093858868634329285205417149685270682748367152458577","best_ask":"0.39","best_bid":"0.38","hash":"714ab0a05d974ebaafce7a5f1e3439fbdb5fb8f8","price":"0.97","side":"SELL","size":"618.1"}],"timestamp":"1785211590947"},"payload_hash":"59539ed18a49d52b7e685d9254e8a0b5db92b8c827ccdb2b32d816a170776b57","raw_frame":"{\"market\":\"0xd412ce774cfcf8dc9f71164aac78783978aac7b03871702a3b8a481bd9dc9688\", \"price_changes\":[{\"asset_id\":\"107603864457683460275633293642179940881969192120168665300712204232021063124301\", \"price\":\"0.03\", \"size\":\"618.1\", \"side\":\"BUY\", \"hash\":\"f359250d2d7a9353def01d7ebbbb6e4650a615b6\", \"best_bid\":\"0.61\", \"best_ask\":\"0.62\"}, {\"asset_id\":\"96600821790790307414914106093858868634329285205417149685270682748367152458577\", \"price\":\"0.97\", \"size\":\"618.1\", \"side\":\"SELL\", \"hash\":\"714ab0a05d974ebaafce7a5f1e3439fbdb5fb8f8\", \"best_bid\":\"0.38\", \"best_ask\":\"0.39\"}], \"timestamp\":\"1785211590947\", \"event_type\":\"price_change\"}","received_at":"2026-07-28T04:06:30.758686Z","schema_version":"clob-market-ws.price_change.v1","sequence":null,"server_hash":null,"server_timestamp":"1785211590947","session_id":"2d607381e3054cee91998cdf45a4231c","source":"clob_market_ws"},"received_at":"2026-07-28T04:06:30.758686Z","record_id":"6a62dba5ed442db2d4c8f5201586c23af10d646d4a023dddc55e71ccf25e1052","schema_fingerprint":"4aa3821a28b0b7c2400bc59aba4bcc0a76e971dadd19610d3ad38c768e124dc7","schema_version":"edge-lab-recorder.raw.v1","sequence":null,"source":"clob_market_ws"}
{"event_at":"2026-07-28T04:06:30.974000Z","event_fingerprint":"498cebc48747e5ee9f658abae7cea416c6750ea623a9e42b50122b3e293f5f0c","payload":{"connection_id":"f6725804f86a4c4eb588e4d5ed7db029","event_at":"2026-07-28T04:06:30.974000Z","event_type":"price_change","frame_hash":"116da909ba51ae6559e017ca8b614391ba350aef653bdd8c928f92b7369b2f51","frame_index":0,"kind":"data","monotonic_ns":313573825598041,"payload":{"event_type":"price_change","market":"0xd412ce774cfcf8dc9f71164aac78783978aac7b03871702a3b8a481bd9dc9688","price_changes":[{"asset_id":"96600821790790307414914106093858868634329285205417149685270682748367152458577","best_ask":"0.39","best_bid":"0.38","hash":"47a0db817bf095e282c4ead357c87a0330f7a0bb","price":"0.29","side":"BUY","size":"159"},{"asset_id":"107603864457683460275633293642179940881969192120168665300712204232021063124301","best_ask":"0.62","best_bid":"0.61","hash":"4fce31e25252ad0d5ef5a8ca678cf87290f9060e","price":"0.71","side":"SELL","size":"159"}],"timestamp":"1785211590974"},"payload_hash":"38beb0d7e47627f0b0ba1978d2180fe3d177683548e7031bc4daf2681b58b921","raw_frame":"{\"market\":\"0xd412ce774cfcf8dc9f71164aac78783978aac7b03871702a3b8a481bd9dc9688\", \"price_changes\":[{\"asset_id\":\"96600821790790307414914106093858868634329285205417149685270682748367152458577\", \"price\":\"0.29\", \"size\":\"159\", \"side\":\"BUY\", \"hash\":\"47a0db817bf095e282c4ead357c87a0330f7a0bb\", \"best_bid\":\"0.38\", \"best_ask\":\"0.39\"}, {\"asset_id\":\"107603864457683460275633293642179940881969192120168665300712204232021063124301\", \"price\":\"0.71\", \"size\":\"159\", \"side\":\"SELL\", \"hash\":\"4fce31e25252ad0d5ef5a8ca678cf87290f9060e\", \"best_bid\":\"0.61\", \"best_ask\":\"0.62\"}], \"timestamp\":\"1785211590974\", \"event_type\":\"price_change\"}","received_at":"2026-07-28T04:06:30.774789Z","schema_version":"clob-market-ws.price_change.v1","sequence":null,"server_hash":null,"server_timestamp":"1785211590974","session_id":"2d607381e3054cee91998cdf45a4231c","source":"clob_market_ws"},"received_at":"2026-07-28T04:06:30.774789Z","record_id":"3e80bfc63f43f2583f8d447613fd47642aeb65ea9755a6baf293991c1bfcbbb6","schema_fingerprint":"4aa3821a28b0b7c2400bc59aba4bcc0a76e971dadd19610d3ad38c768e124dc7","schema_version":"edge-lab-recorder.raw.v1","sequence":null,"source":"clob_market_ws"}
{"event_at":"2026-07-28T04:06:30.983000Z","event_fingerprint":"d18ed428944f058f5c436139bd741aee146481b7a52561dee1ebd77d75fc335b","payload":{"connection_id":"f6725804f86a4c4eb588e4d5ed7db029","event_at":"2026-07-28T04:06:30.983000Z","event_type":"price_change","frame_hash":"7cbea651fe0b5bcca3fb06c51af081682bf82f83bcbf163bd673cc0bbb746086","frame_index":0,"kind":"data","monotonic_ns":313573838106375,"payload":{"event_type":"price_change","market":"0xd412ce774cfcf8dc9f71164aac78783978aac7b03871702a3b8a481bd9dc9688","price_changes":[{"asset_id":"96600821790790307414914106093858868634329285205417149685270682748367152458577","best_ask":"0.39","best_bid":"0.38","hash":"a5813e916c3dc5526f125507f9edc1dcedf16618","price":"0.25","side":"BUY","size":"273.17"},{"asset_id":"107603864457683460275633293642179940881969192120168665300712204232021063124301","best_ask":"0.62","best_bid":"0.61","hash":"450b8e308c56442c4df1125320faca531fbc1043","price":"0.75","side":"SELL","size":"273.17"}],"timestamp":"1785211590983"},"payload_hash":"aa1374eded3dfe6b6f2ac100e8798a42db6e11a64f7149fa14ec18782a39575e","raw_frame":"{\"market\":\"0xd412ce774cfcf8dc9f71164aac78783978aac7b03871702a3b8a481bd9dc9688\", \"price_changes\":[{\"asset_id\":\"96600821790790307414914106093858868634329285205417149685270682748367152458577\", \"price\":\"0.25\", \"size\":\"273.17\", \"side\":\"BUY\", \"hash\":\"a5813e916c3dc5526f125507f9edc1dcedf16618\", \"best_bid\":\"0.38\", \"best_ask\":\"0.39\"}, {\"asset_id\":\"107603864457683460275633293642179940881969192120168665300712204232021063124301\", \"price\":\"0.75\", \"size\":\"273.17\", \"side\":\"SELL\", \"hash\":\"450b8e308c56442c4df1125320faca531fbc1043\", \"best_bid\":\"0.61\", \"best_ask\":\"0.62\"}], \"timestamp\":\"1785211590983\", \"event_type\":\"price_change\"}","received_at":"2026-07-28T04:06:30.787298Z","schema_version":"clob-market-ws.price_change.v1","sequence":null,"server_hash":null,"server_timestamp":"1785211590983","session_id":"2d607381e3054cee91998cdf45a4231c","source":"clob_market_ws"},"received_at":"2026-07-28T04:06:30.787298Z","record_id":"e4485151cb006259118f1b2933d657b7532c18e06e2c97d0eed146395b91b64c","schema_fingerprint":"4aa3821a28b0b7c2400bc59aba4bcc0a76e971dadd19610d3ad38c768e124dc7","schema_version":"edge-lab-recorder.raw.v1","sequence":null,"source":"clob_market_ws"}
{"event_at":"2026-07-28T04:06:31.018000Z","event_fingerprint":"773f340083e3712c0e84cbc0d103854b20908889bf3080dc98abe30870bbb700","payload":{"connection_id":"f6725804f86a4c4eb588e4d5ed7db029","event_at":"2026-07-28T04:06:31.018000Z","event_type":"price_change","frame_hash":"a943f5d87691b78d29f981cb9372dc7e26ea2cc40ea45c4aa141296d3139952d","frame_index":0,"kind":"data","monotonic_ns":313573872463625,"payload":{"event_type":"price_change","market":"0xd412ce774cfcf8dc9f71164aac78783978aac7b03871702a3b8a481bd9dc9688","price_changes":[{"asset_id":"96600821790790307414914106093858868634329285205417149685270682748367152458577","best_ask":"0.39","best_bid":"0.38","hash":"748ece222637f36066285bdceb0e921498d7fff0","price":"0.01","side":"BUY","size":"5613.02"},{"asset_id":"107603864457683460275633293642179940881969192120168665300712204232021063124301","best_ask":"0.62","best_bid":"0.61","hash":"c95eb867bc920859a8c62bf1272a530abd1443e0","price":"0.99","side":"SELL","size":"5613.02"}],"timestamp":"1785211591018"},"payload_hash":"429c277adfdd1469a5a7684fa10527ad550259d2c00f62304f0961f3235fe2b1","raw_frame":"{\"market\":\"0xd412ce774cfcf8dc9f71164aac78783978aac7b03871702a3b8a481bd9dc9688\", \"price_changes\":[{\"asset_id\":\"96600821790790307414914106093858868634329285205417149685270682748367152458577\", \"price\":\"0.01\", \"size\":\"5613.02\", \"side\":\"BUY\", \"hash\":\"748ece222637f36066285bdceb0e921498d7fff0\", \"best_bid\":\"0.38\", \"best_ask\":\"0.39\"}, {\"asset_id\":\"107603864457683460275633293642179940881969192120168665300712204232021063124301\", \"price\":\"0.99\", \"size\":\"5613.02\", \"side\":\"SELL\", \"hash\":\"c95eb867bc920859a8c62bf1272a530abd1443e0\", \"best_bid\":\"0.61\", \"best_ask\":\"0.62\"}], \"timestamp\":\"1785211591018\", \"event_type\":\"price_change\"}","received_at":"2026-07-28T04:06:30.821655Z","schema_version":"clob-market-ws.price_change.v1","sequence":null,"server_hash":null,"server_timestamp":"1785211591018","session_id":"2d607381e3054cee91998cdf45a4231c","source":"clob_market_ws"},"received_at":"2026-07-28T04:06:30.821655Z","record_id":"28a1004fe8e71f4acf7b939a971c766cb96ed581c4e40850a14ee9d1caa8659f","schema_fingerprint":"4aa3821a28b0b7c2400bc59aba4bcc0a76e971dadd19610d3ad38c768e124dc7","schema_version":"edge-lab-recorder.raw.v1","sequence":null,"source":"clob_market_ws"}
{"event_at":"2026-07-28T04:06:31.026000Z","event_fingerprint":"164dc889a3cccc8e7c4ca5d861d13ff1e0984d0d6408824fa5398f89c5c95048","payload":{"connection_id":"f6725804f86a4c4eb588e4d5ed7db029","event_at":"2026-07-28T04:06:31.026000Z","event_type":"price_change","frame_hash":"e76ae5f9df4d0410aa1ab451757456187e5dc21f9c818e676c2983091415f166","frame_index":0,"kind":"data","monotonic_ns":313573878855708,"payload":{"event_type":"price_change","market":"0xd412ce774cfcf8dc9f71164aac78783978aac7b03871702a3b8a481bd9dc9688","price_changes":[{"asset_id":"96600821790790307414914106093858868634329285205417149685270682748367152458577","best_ask":"0.39","best_bid":"0.38","hash":"a4788b063159c99c94f62bbc3f5ac43e718b394e","price":"0.01","side":"BUY","size":"5618.02"},{"asset_id":"107603864457683460275633293642179940881969192120168665300712204232021063124301","best_ask":"0.62","best_bid":"0.61","hash":"fce5688d6550dff5bad703d23a73a15d79f2078e","price":"0.99","side":"SELL","size":"5618.02"}],"timestamp":"1785211591026"},"payload_hash":"b8fd9d9ac07474ba8b166c979bc7e0cc41de4f8e964aa1a53fe59e03a16e9af3","raw_frame":"{\"market\":\"0xd412ce774cfcf8dc9f71164aac78783978aac7b03871702a3b8a481bd9dc9688\", \"price_changes\":[{\"asset_id\":\"96600821790790307414914106093858868634329285205417149685270682748367152458577\", \"price\":\"0.01\", \"size\":\"5618.02\", \"side\":\"BUY\", \"hash\":\"a4788b063159c99c94f62bbc3f5ac43e718b394e\", \"best_bid\":\"0.38\", \"best_ask\":\"0.39\"}, {\"asset_id\":\"107603864457683460275633293642179940881969192120168665300712204232021063124301\", \"price\":\"0.99\", \"size\":\"5618.02\", \"side\":\"SELL\", \"hash\":\"fce5688d6550dff5bad703d23a73a15d79f2078e\", \"best_bid\":\"0.61\", \"best_ask\":\"0.62\"}], \"timestamp\":\"1785211591026\", \"event_type\":\"price_change\"}","received_at":"2026-07-28T04:06:30.828048Z","schema_version":"clob-market-ws.price_change.v1","sequence":null,"server_hash":null,"server_timestamp":"1785211591026","session_id":"2d607381e3054cee91998cdf45a4231c","source":"clob_market_ws"},"received_at":"2026-07-28T04:06:30.828048Z","record_id":"b616297b0f214ebcc4200df88e0ded9e55b3325f93cfd8302b5e0d20939a0853","schema_fingerprint":"4aa3821a28b0b7c2400bc59aba4bcc0a76e971dadd19610d3ad38c768e124dc7","schema_version":"edge-lab-recorder.raw.v1","sequence":null,"source":"clob_market_ws"}
{"event_at":"2026-07-28T04:06:31.029000Z","event_fingerprint":"8ecb8207f91d07f9e1f054c3dcfe65f976884a750e2cb7318abbcde38792f7a0","payload":{"connection_id":"f6725804f86a4c4eb588e4d5ed7db029","event_at":"2026-07-28T04:06:31.029000Z","event_type":"price_change","frame_hash":"285dce8d5098914b94c495e13a6e432ba52f69db39d0f890c383efdba16538ea","frame_index":0,"kind":"data","monotonic_ns":313573892352625,"payload":{"event_type":"price_change","market":"0xd412ce774cfcf8dc9f71164aac78783978aac7b03871702a3b8a481bd9dc9688","price_changes":[{"asset_id":"107603864457683460275633293642179940881969192120168665300712204232021063124301","best_ask":"0.62","best_bid":"0.61","hash":"3ae5c4be22b5e452cc00ce361064dbe944299d2e","price":"0.37","side":"BUY","size":"228.08"},{"asset_id":"96600821790790307414914106093858868634329285205417149685270682748367152458577","best_ask":"0.39","best_bid":"0.38","hash":"69ab9a9867a21f13be9eb654d93a8c15f3b9deda","price":"0.63","side":"SELL","size":"228.08"}],"timestamp":"1785211591029"},"payload_hash":"9591006047b459a6fb4a04859a340388f8cc922562a94b3127ab0e273361f078","raw_frame":"{\"market\":\"0xd412ce774cfcf8dc9f71164aac78783978aac7b03871702a3b8a481bd9dc9688\", \"price_changes\":[{\"asset_id\":\"107603864457683460275633293642179940881969192120168665300712204232021063124301\", \"price\":\"0.37\", \"size\":\"228.08\", \"side\":\"BUY\", \"hash\":\"3ae5c4be22b5e452cc00ce361064dbe944299d2e\", \"best_bid\":\"0.61\", \"best_ask\":\"0.62\"}, {\"asset_id\":\"96600821790790307414914106093858868634329285205417149685270682748367152458577\", \"price\":\"0.63\", \"size\":\"228.08\", \"side\":\"SELL\", \"hash\":\"69ab9a9867a21f13be9eb654d93a8c15f3b9deda\", \"best_bid\":\"0.38\", \"best_ask\":\"0.39\"}], \"timestamp\":\"1785211591029\", \"event_type\":\"price_change\"}","received_at":"2026-07-28T04:06:30.841543Z","schema_version":"clob-market-ws.price_change.v1","sequence":null,"server_hash":null,"server_timestamp":"1785211591029","session_id":"2d607381e3054cee91998cdf45a4231c","source":"clob_market_ws"},"received_at":"2026-07-28T04:06:30.841543Z","record_id":"a89dff823360e99e88e4837b05cd36267522203ee0d7eb58f6cb0d08dde781ff","schema_fingerprint":"4aa3821a28b0b7c2400bc59aba4bcc0a76e971dadd19610d3ad38c768e124dc7","schema_version":"edge-lab-recorder.raw.v1","sequence":null,"source":"clob_market_ws"}
{"event_at":"2026-07-28T04:06:31.031000Z","event_fingerprint":"e7190071597657045f3adfe0037811c2dd846164dedd11adc9fe0d96c8f459be","payload":{"connection_id":"f6725804f86a4c4eb588e4d5ed7db029","event_at":"2026-07-28T04:06:31.031000Z","event_type":"price_change","frame_hash":"c03e5a74db6d7a6f88dacfbaa16fa5f2caf9609a522042c1526553160130bcec","frame_index":0,"kind":"data","monotonic_ns":313573899076416,"payload":{"event_type":"price_change","market":"0xd412ce774cfcf8dc9f71164aac78783978aac7b03871702a3b8a481bd9dc9688","price_changes":[{"asset_id":"107603864457683460275633293642179940881969192120168665300712204232021063124301","best_ask":"0.62","best_bid":"0.61","hash":"6710570403d2565f6d12bededd30a82ac20dd241","price":"0.37","side":"BUY","size":"137.99"},{"asset_id":"96600821790790307414914106093858868634329285205417149685270682748367152458577","best_ask":"0.39","best_bid":"0.38","hash":"454cba035dd6e5273065b6775695f44b7bbbb805","price":"0.63","side":"SELL","size":"137.99"}],"timestamp":"1785211591031"},"payload_hash":"a2415e4523382afffa021f40dd6c39ae04f5d49e9a1e64a9e44b878b373398ed","raw_frame":"{\"market\":\"0xd412ce774cfcf8dc9f71164aac78783978aac7b03871702a3b8a481bd9dc9688\", \"price_changes\":[{\"asset_id\":\"107603864457683460275633293642179940881969192120168665300712204232021063124301\", \"price\":\"0.37\", \"size\":\"137.99\", \"side\":\"BUY\", \"hash\":\"6710570403d2565f6d12bededd30a82ac20dd241\", \"best_bid\":\"0.61\", \"best_ask\":\"0.62\"}, {\"asset_id\":\"96600821790790307414914106093858868634329285205417149685270682748367152458577\", \"price\":\"0.63\", \"size\":\"137.99\", \"side\":\"SELL\", \"hash\":\"454cba035dd6e5273065b6775695f44b7bbbb805\", \"best_bid\":\"0.38\", \"best_ask\":\"0.39\"}], \"timestamp\":\"1785211591031\", \"event_type\":\"price_change\"}","received_at":"2026-07-28T04:06:30.848269Z","schema_version":"clob-market-ws.price_change.v1","sequence":null,"server_hash":null,"server_timestamp":"1785211591031","session_id":"2d607381e3054cee91998cdf45a4231c","source":"clob_market_ws"},"received_at":"2026-07-28T04:06:30.848269Z","record_id":"a12e411b02bd82e411f709499cefd5bc67181affc2695ed271d1f6c53506d9a7","schema_fingerprint":"4aa3821a28b0b7c2400bc59aba4bcc0a76e971dadd19610d3ad38c768e124dc7","schema_version":"edge-lab-recorder.raw.v1","sequence":null,"source":"clob_market_ws"}
{"event_at":"2026-07-28T04:06:31.033000Z","event_fingerprint":"ea21748817a5ee51793ae878c723fecad635bc20eb8c2968a110d61632533f16","payload":{"connection_id":"f6725804f86a4c4eb588e4d5ed7db029","event_at":"2026-07-28T04:06:31.033000Z","event_type":"price_change","frame_hash":"602f92da0a94f0c60f6aad15799b319cea2c6854f85917591b357c708c114e20","frame_index":0,"kind":"data","monotonic_ns":313573904420500,"payload":{"event_type":"price_change","market":"0xd412ce774cfcf8dc9f71164aac78783978aac7b03871702a3b8a481bd9dc9688","price_changes":[{"asset_id":"96600821790790307414914106093858868634329285205417149685270682748367152458577","best_ask":"0.39","best_bid":"0.38","hash":"dfb5f8e3e35d85a1047509b39f990b04ed89231d","price":"0.18","side":"BUY","size":"428.66"},{"asset_id":"107603864457683460275633293642179940881969192120168665300712204232021063124301","best_ask":"0.62","best_bid":"0.61","hash":"31161e92f16a736e2125ce86f1830494719f04b2","price":"0.82","side":"SELL","size":"428.66"}],"timestamp":"1785211591033"},"payload_hash":"636aaa7ad78201b064fae726262da5a7cce9923102f1da9e398afe44d723c988","raw_frame":"{\"market\":\"0xd412ce774cfcf8dc9f71164aac78783978aac7b03871702a3b8a481bd9dc9688\", \"price_changes\":[{\"asset_id\":\"96600821790790307414914106093858868634329285205417149685270682748367152458577\", \"price\":\"0.18\", \"size\":\"428.66\", \"side\":\"BUY\", \"hash\":\"dfb5f8e3e35d85a1047509b39f990b04ed89231d\", \"best_bid\":\"0.38\", \"best_ask\":\"0.39\"}, {\"asset_id\":\"107603864457683460275633293642179940881969192120168665300712204232021063124301\", \"price\":\"0.82\", \"size\":\"428.66\", \"side\":\"SELL\", \"hash\":\"31161e92f16a736e2125ce86f1830494719f04b2\", \"best_bid\":\"0.61\", \"best_ask\":\"0.62\"}], \"timestamp\":\"1785211591033\", \"event_type\":\"price_change\"}","received_at":"2026-07-28T04:06:30.853612Z","schema_version":"clob-market-ws.price_change.v1","sequence":null,"server_hash":null,"server_timestamp":"1785211591033","session_id":"2d607381e3054cee91998cdf45a4231c","source":"clob_market_ws"},"received_at":"2026-07-28T04:06:30.853612Z","record_id":"bb97154a29a2f9455514c9c30b0e7389181d2ecaaca4869205bec3c8fdf11677","schema_fingerprint":"4aa3821a28b0b7c2400bc59aba4bcc0a76e971dadd19610d3ad38c768e124dc7","schema_version":"edge-lab-recorder.raw.v1","sequence":null,"source":"clob_market_ws"}
{"event_at":"2026-07-28T04:06:31.034000Z","event_fingerprint":"6c4f6f75c8b9e91e5b5d020f04a6b437eb494675afffa7a8e0593e8d6bd81a41","payload":{"connection_id":"f6725804f86a4c4eb588e4d5ed7db029","event_at":"2026-07-28T04:06:31.034000Z","event_type":"price_change","frame_hash":"b2ccab1c1e674ec11d0ae65060933964dd10ae1cd09e1215a192dd0ecade76ec","frame_index":0,"kind":"data","monotonic_ns":313573908263833,"payload":{"event_type":"price_change","market":"0xd412ce774cfcf8dc9f71164aac78783978aac7b03871702a3b8a481bd9dc9688","price_changes":[{"asset_id":"96600821790790307414914106093858868634329285205417149685270682748367152458577","best_ask":"0.39","best_bid":"0.38","hash":"f7f6b4b75331686df9c4f6ea0fa47e4fd1dca892","price":"0.18","side":"BUY","size":"243.48"},{"asset_id":"107603864457683460275633293642179940881969192120168665300712204232021063124301","best_ask":"0.62","best_bid":"0.61","hash":"86e66cb737ac21fc5836c000a664812d6190ec65","price":"0.82","side":"SELL","size":"243.48"}],"timestamp":"1785211591034"},"payload_hash":"7ab4f0bbc2f7a2b90b8fe1f6fb71eb07dda75628e76e09c1a627660f6521ee12","raw_frame":"{\"market\":\"0xd412ce774cfcf8dc9f71164aac78783978aac7b03871702a3b8a481bd9dc9688\", \"price_changes\":[{\"asset_id\":\"96600821790790307414914106093858868634329285205417149685270682748367152458577\", \"price\":\"0.18\", \"size\":\"243.48\", \"side\":\"BUY\", \"hash\":\"f7f6b4b75331686df9c4f6ea0fa47e4fd1dca892\", \"best_bid\":\"0.38\", \"best_ask\":\"0.39\"}, {\"asset_id\":\"107603864457683460275633293642179940881969192120168665300712204232021063124301\", \"price\":\"0.82\", \"size\":\"243.48\", \"side\":\"SELL\", \"hash\":\"86e66cb737ac21fc5836c000a664812d6190ec65\", \"best_bid\":\"0.61\", \"best_ask\":\"0.62\"}], \"timestamp\":\"1785211591034\", \"event_type\":\"price_change\"}","received_at":"2026-07-28T04:06:30.857457Z","schema_version":"clob-market-ws.price_change.v1","sequence":null,"server_hash":null,"server_timestamp":"1785211591034","session_id":"2d607381e3054cee91998cdf45a4231c","source":"clob_market_ws"},"received_at":"2026-07-28T04:06:30.857457Z","record_id":"60ba70beadd3d47ec16983b2e213bbc973ef529ac0e49e541fcce051ac457016","schema_fingerprint":"4aa3821a28b0b7c2400bc59aba4bcc0a76e971dadd19610d3ad38c768e124dc7","schema_version":"edge-lab-recorder.raw.v1","sequence":null,"source":"clob_market_ws"}
{"event_at":"2026-07-28T04:06:31.036000Z","event_fingerprint":"0c277f6afcdbd7459a124c3a39d0fc6e28f1a8c4822bb1e0feab3079b7dcbe99","payload":{"connection_id":"f6725804f86a4c4eb588e4d5ed7db029","event_at":"2026-07-28T04:06:31.036000Z","event_type":"price_change","frame_hash":"8b9aee6f871b92d2112b3f7e8bf0bddb1f4069b9bcdd0eed74530b154efef994","frame_index":0,"kind":"data","monotonic_ns":313573912327708,"payload":{"event_type":"price_change","market":"0xd412ce774cfcf8dc9f71164aac78783978aac7b03871702a3b8a481bd9dc9688","price_changes":[{"asset_id":"107603864457683460275633293642179940881969192120168665300712204232021063124301","best_ask":"0.62","best_bid":"0.61","hash":"610cc64e9c9cbe30cfb4a80c46ebf0fdcdc9a4c3","price":"0.37","side":"BUY","size":"47.9"},{"asset_id":"96600821790790307414914106093858868634329285205417149685270682748367152458577","best_ask":"0.39","best_bid":"0.38","hash":"e4c97f594b1addf55fae5cadf42bced17cf76cd5","price":"0.63","side":"SELL","size":"47.9"}],"timestamp":"1785211591036"},"payload_hash":"7fa65c3e9ac25a41306dcd60ced3e4c8dd74b7ea10ada343956711e0390f89cc","raw_frame":"{\"market\":\"0xd412ce774cfcf8dc9f71164aac78783978aac7b03871702a3b8a481bd9dc9688\", \"price_changes\":[{\"asset_id\":\"107603864457683460275633293642179940881969192120168665300712204232021063124301\", \"price\":\"0.37\", \"size\":\"47.9\", \"side\":\"BUY\", \"hash\":\"610cc64e9c9cbe30cfb4a80c46ebf0fdcdc9a4c3\", \"best_bid\":\"0.61\", \"best_ask\":\"0.62\"}, {\"asset_id\":\"96600821790790307414914106093858868634329285205417149685270682748367152458577\", \"price\":\"0.63\", \"size\":\"47.9\", \"side\":\"SELL\", \"hash\":\"e4c97f594b1addf55fae5cadf42bced17cf76cd5\", \"best_bid\":\"0.38\", \"best_ask\":\"0.39\"}], \"timestamp\":\"1785211591036\", \"event_type\":\"price_change\"}","received_at":"2026-07-28T04:06:30.861520Z","schema_version":"clob-market-ws.price_change.v1","sequence":null,"server_hash":null,"server_timestamp":"1785211591036","session_id":"2d607381e3054cee91998cdf45a4231c","source":"clob_market_ws"},"received_at":"2026-07-28T04:06:30.861520Z","record_id":"70f3f5e0abcf57e231428ef9c1029d0550b1f0714030aa0a0d5a2bd2f315c502","schema_fingerprint":"4aa3821a28b0b7c2400bc59aba4bcc0a76e971dadd19610d3ad38c768e124dc7","schema_version":"edge-lab-recorder.raw.v1","sequence":null,"source":"clob_market_ws"}
{"event_at":"2026-07-28T04:06:31.037000Z","event_fingerprint":"82deb7768a30c589d2271f4333899c9ce6cd1050d53a4904a9ce4322f6c4e562","payload":{"connection_id":"f6725804f86a4c4eb588e4d5ed7db029","event_at":"2026-07-28T04:06:31.037000Z","event_type":"price_change","frame_hash":"1c987b7a43ee148a585103b8613da571c344c49da006bd00360519f9abfd422d","frame_index":0,"kind":"data","monotonic_ns":313573919070958,"payload":{"event_type":"price_change","market":"0xd412ce774cfcf8dc9f71164aac78783978aac7b03871702a3b8a481bd9dc9688","price_changes":[{"asset_id":"96600821790790307414914106093858868634329285205417149685270682748367152458577","best_ask":"0.39","best_bid":"0.38","hash":"cd0433d76df4b50742af98c7dbf2e97b3515a22a","price":"0.18","side":"BUY","size":"58.3"},{"asset_id":"107603864457683460275633293642179940881969192120168665300712204232021063124301","best_ask":"0.62","best_bid":"0.61","hash":"95d228576d8557d1e8fb0bc516ff092d35577e81","price":"0.82","side":"SELL","size":"58.3"}],"timestamp":"1785211591037"},"payload_hash":"62daa8f340602007efd7ac7406e35a9c1b24496dc9d70e0771e4c62b5e113f47","raw_frame":"{\"market\":\"0xd412ce774cfcf8dc9f71164aac78783978aac7b03871702a3b8a481bd9dc9688\", \"price_changes\":[{\"asset_id\":\"96600821790790307414914106093858868634329285205417149685270682748367152458577\", \"price\":\"0.18\", \"size\":\"58.3\", \"side\":\"BUY\", \"hash\":\"cd0433d76df4b50742af98c7dbf2e97b3515a22a\", \"best_bid\":\"0.38\", \"best_ask\":\"0.39\"}, {\"asset_id\":\"107603864457683460275633293642179940881969192120168665300712204232021063124301\", \"price\":\"0.82\", \"size\":\"58.3\", \"side\":\"SELL\", \"hash\":\"95d228576d8557d1e8fb0bc516ff092d35577e81\", \"best_bid\":\"0.61\", \"best_ask\":\"0.62\"}], \"timestamp\":\"1785211591037\", \"event_type\":\"price_change\"}","received_at":"2026-07-28T04:06:30.868261Z","schema_version":"clob-market-ws.price_change.v1","sequence":null,"server_hash":null,"server_timestamp":"1785211591037","session_id":"2d607381e3054cee91998cdf45a4231c","source":"clob_market_ws"},"received_at":"2026-07-28T04:06:30.868261Z","record_id":"508e531c5cdc2a78be4789bf6006e8fc4d6a9a5bb459f8928d24ac12fe58eaf1","schema_fingerprint":"4aa3821a28b0b7c2400bc59aba4bcc0a76e971dadd19610d3ad38c768e124dc7","schema_version":"edge-lab-recorder.raw.v1","sequence":null,"source":"clob_market_ws"}
{"event_at":"2026-07-28T04:06:31.047000Z","event_fingerprint":"9da6e3959e423f21776bdbcd3ba40c04a45262788d9e7b717575280a7dddd9ec","payload":{"connection_id":"f6725804f86a4c4eb588e4d5ed7db029","event_at":"2026-07-28T04:06:31.047000Z","event_type":"price_change","frame_hash":"83210d55f8c98f7f910309b57cd59fe8c037eb24cb1526d0d84fb458914ebd8d","frame_index":0,"kind":"data","monotonic_ns":313573922785041,"payload":{"event_type":"price_change","market":"0xd412ce774cfcf8dc9f71164aac78783978aac7b03871702a3b8a481bd9dc9688","price_changes":[{"asset_id":"96600821790790307414914106093858868634329285205417149685270682748367152458577","best_ask":"0.39","best_bid":"0.38","hash":"0320daa122f69238ecb409dd982775b648aa2449","price":"0.01","side":"BUY","size":"5613.02"},{"asset_id":"107603864457683460275633293642179940881969192120168665300712204232021063124301","best_ask":"0.62","best_bid":"0.61","hash":"805e0a9590690c9d67b403e44a0a81b8bfc3689d","price":"0.99","side":"SELL","size":"5613.02"}],"timestamp":"1785211591047"},"payload_hash":"c1f9a5fcc36baf0cfb1c5fb37c15dae1e62517d4259e5333d9efec39983c5097","raw_frame":"{\"market\":\"0xd412ce774cfcf8dc9f71164aac78783978aac7b03871702a3b8a481bd9dc9688\", \"price_changes\":[{\"asset_id\":\"96600821790790307414914106093858868634329285205417149685270682748367152458577\", \"price\":\"0.01\", \"size\":\"5613.02\", \"side\":\"BUY\", \"hash\":\"0320daa122f69238ecb409dd982775b648aa2449\", \"best_bid\":\"0.38\", \"best_ask\":\"0.39\"}, {\"asset_id\":\"107603864457683460275633293642179940881969192120168665300712204232021063124301\", \"price\":\"0.99\", \"size\":\"5613.02\", \"side\":\"SELL\", \"hash\":\"805e0a9590690c9d67b403e44a0a81b8bfc3689d\", \"best_bid\":\"0.61\", \"best_ask\":\"0.62\"}], \"timestamp\":\"1785211591047\", \"event_type\":\"price_change\"}","received_at":"2026-07-28T04:06:30.871978Z","schema_version":"clob-market-ws.price_change.v1","sequence":null,"server_hash":null,"server_timestamp":"1785211591047","session_id":"2d607381e3054cee91998cdf45a4231c","source":"clob_market_ws"},"received_at":"2026-07-28T04:06:30.871978Z","record_id":"86119ac1b0359c5adfeed565b640e9e4630615a58f3de33f6042c77255ff333c","schema_fingerprint":"4aa3821a28b0b7c2400bc59aba4bcc0a76e971dadd19610d3ad38c768e124dc7","schema_version":"edge-lab-recorder.raw.v1","sequence":null,"source":"clob_market_ws"}
{"event_at":"2026-07-28T04:06:31.048000Z","event_fingerprint":"f39faa3572719d6c5f27a596eae78872cdd33366087a3f5ba030984dd0e20013","payload":{"connection_id":"f6725804f86a4c4eb588e4d5ed7db029","event_at":"2026-07-28T04:06:31.048000Z","event_type":"price_change","frame_hash":"4e3c4a175f1069b1ddf11004bc5eb4eb4e430b63c77b7045306f1a89132b7d2c","frame_index":0,"kind":"data","monotonic_ns":313573927851708,"payload":{"event_type":"price_change","market":"0xd412ce774cfcf8dc9f71164aac78783978aac7b03871702a3b8a481bd9dc9688","price_changes":[{"asset_id":"107603864457683460275633293642179940881969192120168665300712204232021063124301","best_ask":"0.62","best_bid":"0.61","hash":"e56d1949cbba74f6dabb40be48912a8e4dea7626","price":"0.03","side":"BUY","size":"623.1"},{"asset_id":"96600821790790307414914106093858868634329285205417149685270682748367152458577","best_ask":"0.39","best_bid":"0.38","hash":"6a570c425b450f8c7819bcbc8b9252ad105a910c","price":"0.97","side":"SELL","size":"623.1"}],"timestamp":"1785211591048"},"payload_hash":"b3a9d7e538061007934f6fd5bae03a3311580677fd8d9f4580cc4bdb1cfd6a66","raw_frame":"{\"market\":\"0xd412ce774cfcf8dc9f71164aac78783978aac7b03871702a3b8a481bd9dc9688\", \"price_changes\":[{\"asset_id\":\"107603864457683460275633293642179940881969192120168665300712204232021063124301\", \"price\":\"0.03\", \"size\":\"623.1\", \"side\":\"BUY\", \"hash\":\"e56d1949cbba74f6dabb40be48912a8e4dea7626\", \"best_bid\":\"0.61\", \"best_ask\":\"0.62\"}, {\"asset_id\":\"96600821790790307414914106093858868634329285205417149685270682748367152458577\", \"price\":\"0.97\", \"size\":\"623.1\", \"side\":\"SELL\", \"hash\":\"6a570c425b450f8c7819bcbc8b9252ad105a910c\", \"best_bid\":\"0.38\", \"best_ask\":\"0.39\"}], \"timestamp\":\"1785211591048\", \"event_type\":\"price_change\"}","received_at":"2026-07-28T04:06:30.877044Z","schema_version":"clob-market-ws.price_change.v1","sequence":null,"server_hash":null,"server_timestamp":"1785211591048","session_id":"2d607381e3054cee91998cdf45a4231c","source":"clob_market_ws"},"received_at":"2026-07-28T04:06:30.877044Z","record_id":"9ab1a552601884161eabdc36a6c0e8a6acd4ab69fac08b591302799f1fcb9298","schema_fingerprint":"4aa3821a28b0b7c2400bc59aba4bcc0a76e971dadd19610d3ad38c768e124dc7","schema_version":"edge-lab-recorder.raw.v1","sequence":null,"source":"clob_market_ws"}
{"event_at":"2026-07-28T04:06:31.052000Z","event_fingerprint":"e6f62412ac64a3a6e86c4250bdf2e82717d196bdc29d3b328aecb0a00ab71124","payload":{"connection_id":"f6725804f86a4c4eb588e4d5ed7db029","event_at":"2026-07-28T04:06:31.052000Z","event_type":"price_change","frame_hash":"5fa4422daffab49497f26e4a987cca29820829a7deb47e30f16a331956215555","frame_index":0,"kind":"data","monotonic_ns":313573931504208,"payload":{"event_type":"price_change","market":"0xd412ce774cfcf8dc9f71164aac78783978aac7b03871702a3b8a481bd9dc9688","price_changes":[{"asset_id":"107603864457683460275633293642179940881969192120168665300712204232021063124301","best_ask":"0.62","best_bid":"0.61","hash":"7597c3ad29a4f19f0cc62d7579d8308ad08fe494","price":"0.64","side":"SELL","size":"21"},{"asset_id":"96600821790790307414914106093858868634329285205417149685270682748367152458577","best_ask":"0.39","best_bid":"0.38","hash":"c8e1ac732dc9c7f9f535277f2f0bf53bd32a41de","price":"0.36","side":"BUY","size":"21"}],"timestamp":"1785211591052"},"payload_hash":"028d9e89279333ed39b00b833ff3a05f326e86c0b57eb83de3077f6464f63134","raw_frame":"{\"market\":\"0xd412ce774cfcf8dc9f71164aac78783978aac7b03871702a3b8a481bd9dc9688\", \"price_changes\":[{\"asset_id\":\"107603864457683460275633293642179940881969192120168665300712204232021063124301\", \"price\":\"0.64\", \"size\":\"21\", \"side\":\"SELL\", \"hash\":\"7597c3ad29a4f19f0cc62d7579d8308ad08fe494\", \"best_bid\":\"0.61\", \"best_ask\":\"0.62\"}, {\"asset_id\":\"96600821790790307414914106093858868634329285205417149685270682748367152458577\", \"price\":\"0.36\", \"size\":\"21\", \"side\":\"BUY\", \"hash\":\"c8e1ac732dc9c7f9f535277f2f0bf53bd32a41de\", \"best_bid\":\"0.38\", \"best_ask\":\"0.39\"}], \"timestamp\":\"1785211591052\", \"event_type\":\"price_change\"}","received_at":"2026-07-28T04:06:30.880697Z","schema_version":"clob-market-ws.price_change.v1","sequence":null,"server_hash":null,"server_timestamp":"1785211591052","session_id":"2d607381e3054cee91998cdf45a4231c","source":"clob_market_ws"},"received_at":"2026-07-28T04:06:30.880697Z","record_id":"3ba99364e063a4ddfbc553b7d1549a9fb6152711d9b333974a45c7748008dec5","schema_fingerprint":"4aa3821a28b0b7c2400bc59aba4bcc0a76e971dadd19610d3ad38c768e124dc7","schema_version":"edge-lab-recorder.raw.v1","sequence":null,"source":"clob_market_ws"}
{"event_at":"2026-07-28T04:06:31.058000Z","event_fingerprint":"c7afabe17da0e6354ab9a989db333b1c4f48f1e0c6020815b9de15e845306cd8","payload":{"connection_id":"f6725804f86a4c4eb588e4d5ed7db029","event_at":"2026-07-28T04:06:31.058000Z","event_type":"price_change","frame_hash":"6f7b317aa9f36b1d28d98001cddfa0f9b9978de6bc9be4b8ee1de5b61f51e3b8","frame_index":0,"kind":"data","monotonic_ns":313573936574083,"payload":{"event_type":"price_change","market":"0xd412ce774cfcf8dc9f71164aac78783978aac7b03871702a3b8a481bd9dc9688","price_changes":[{"asset_id":"96600821790790307414914106093858868634329285205417149685270682748367152458577","best_ask":"0.39","best_bid":"0.38","hash":"e270fd17647c5877887f13a01d9451ff2485bd98","price":"0.01","side":"BUY","size":"5608.02"},{"asset_id":"107603864457683460275633293642179940881969192120168665300712204232021063124301","best_ask":"0.62","best_bid":"0.61","hash":"0bb23a2e5ec439e80961af45276e25df855ee5f0","price":"0.99","side":"SELL","size":"5608.02"}],"timestamp":"1785211591058"},"payload_hash":"78547a48acfbd77b34ad6e009c9fabf0f5e3c22accaea7b0e9de0a225bcd055e","raw_frame":"{\"market\":\"0xd412ce774cfcf8dc9f71164aac78783978aac7b03871702a3b8a481bd9dc9688\", \"price_changes\":[{\"asset_id\":\"96600821790790307414914106093858868634329285205417149685270682748367152458577\", \"price\":\"0.01\", \"size\":\"5608.02\", \"side\":\"BUY\", \"hash\":\"e270fd17647c5877887f13a01d9451ff2485bd98\", \"best_bid\":\"0.38\", \"best_ask\":\"0.39\"}, {\"asset_id\":\"107603864457683460275633293642179940881969192120168665300712204232021063124301\", \"price\":\"0.99\", \"size\":\"5608.02\", \"side\":\"SELL\", \"hash\":\"0bb23a2e5ec439e80961af45276e25df855ee5f0\", \"best_bid\":\"0.61\", \"best_ask\":\"0.62\"}], \"timestamp\":\"1785211591058\", \"event_type\":\"price_change\"}","received_at":"2026-07-28T04:06:30.885767Z","schema_version":"clob-market-ws.price_change.v1","sequence":null,"server_hash":null,"server_timestamp":"1785211591058","session_id":"2d607381e3054cee91998cdf45a4231c","source":"clob_market_ws"},"received_at":"2026-07-28T04:06:30.885767Z","record_id":"4a8c9c855172757377ce3e1ed26679c16ed34b7d2cb580e3ed31597c17a6c39a","schema_fingerprint":"4aa3821a28b0b7c2400bc59aba4bcc0a76e971dadd19610d3ad38c768e124dc7","schema_version":"edge-lab-recorder.raw.v1","sequence":null,"source":"clob_market_ws"}
{"event_at":"2026-07-28T04:06:31.099000Z","event_fingerprint":"f485a0bb0630d9cfe4f1b154869a3a3949dd2c1e27cafdd475ce4a518b9723c5","payload":{"connection_id":"f6725804f86a4c4eb588e4d5ed7db029","event_at":"2026-07-28T04:06:31.099000Z","event_type":"price_change","frame_hash":"99b2dd16691f08b70f0fc72a80ece0280f4064aaac3c2bc1a1835136d3aa2354","frame_index":0,"kind":"data","monotonic_ns":313573952213041,"payload":{"event_type":"price_change","market":"0xd412ce774cfcf8dc9f71164aac78783978aac7b03871702a3b8a481bd9dc9688","price_changes":[{"asset_id":"107603864457683460275633293642179940881969192120168665300712204232021063124301","best_ask":"0.62","best_bid":"0.61","hash":"98341b2738589e4b1aba5d7a7c4d6eb6dff66bcf","price":"0.03","side":"BUY","size":"618.1"},{"asset_id":"96600821790790307414914106093858868634329285205417149685270682748367152458577","best_ask":"0.39","best_bid":"0.38","hash":"380f578c699379841473df0cba3bfcd5755739e2","price":"0.97","side":"SELL","size":"618.1"}],"timestamp":"1785211591099"},"payload_hash":"4e989b11278d8f8b7d436cd60a0bcc37f6200d88cac1cebd79153ea528ae31ca","raw_frame":"{\"market\":\"0xd412ce774cfcf8dc9f71164aac78783978aac7b03871702a3b8a481bd9dc9688\", \"price_changes\":[{\"asset_id\":\"107603864457683460275633293642179940881969192120168665300712204232021063124301\", \"price\":\"0.03\", \"size\":\"618.1\", \"side\":\"BUY\", \"hash\":\"98341b2738589e4b1aba5d7a7c4d6eb6dff66bcf\", \"best_bid\":\"0.61\", \"best_ask\":\"0.62\"}, {\"asset_id\":\"96600821790790307414914106093858868634329285205417149685270682748367152458577\", \"price\":\"0.97\", \"size\":\"618.1\", \"side\":\"SELL\", \"hash\":\"380f578c699379841473df0cba3bfcd5755739e2\", \"best_bid\":\"0.38\", \"best_ask\":\"0.39\"}], \"timestamp\":\"1785211591099\", \"event_type\":\"price_change\"}","received_at":"2026-07-28T04:06:30.901405Z","schema_version":"clob-market-ws.price_change.v1","sequence":null,"server_hash":null,"server_timestamp":"1785211591099","session_id":"2d607381e3054cee91998cdf45a4231c","source":"clob_market_ws"},"received_at":"2026-07-28T04:06:30.901405Z","record_id":"5e0bbcc2063eb7954b3315fa573518d9e0d6a1ed02b9786078e95388d49cb5f7","schema_fingerprint":"4aa3821a28b0b7c2400bc59aba4bcc0a76e971dadd19610d3ad38c768e124dc7","schema_version":"edge-lab-recorder.raw.v1","sequence":null,"source":"clob_market_ws"}
{"event_at":"2026-07-28T04:06:31.181000Z","event_fingerprint":"a172bd8b82ce522b44652cd1e43bd37e5ac9713b9e1178f896d286a31b971477","payload":{"connection_id":"f6725804f86a4c4eb588e4d5ed7db029","event_at":"2026-07-28T04:06:31.181000Z","event_type":"price_change","frame_hash":"6edb652b8e1e0882bdce590221e61d2f2c4f2e58ae334a7e7b6551309976f12a","frame_index":0,"kind":"data","monotonic_ns":313574035753666,"payload":{"event_type":"price_change","market":"0xd412ce774cfcf8dc9f71164aac78783978aac7b03871702a3b8a481bd9dc9688","price_changes":[{"asset_id":"107603864457683460275633293642179940881969192120168665300712204232021063124301","best_ask":"0.62","best_bid":"0.61","hash":"2f714044daec398b9feea29ffb840a5bac4e04dc","price":"0.65","side":"SELL","size":"76.59"},{"asset_id":"96600821790790307414914106093858868634329285205417149685270682748367152458577","best_ask":"0.39","best_bid":"0.38","hash":"be1909566f53cfc36a2740617d94cff8f38575d4","price":"0.35","side":"BUY","size":"76.59"}],"timestamp":"1785211591181"},"payload_hash":"634caf5f434c4df803d4f9245f1383cc8755f146b1c06627894e84f6efc1a03b","raw_frame":"{\"market\":\"0xd412ce774cfcf8dc9f71164aac78783978aac7b03871702a3b8a481bd9dc9688\", \"price_changes\":[{\"asset_id\":\"107603864457683460275633293642179940881969192120168665300712204232021063124301\", \"price\":\"0.65\", \"size\":\"76.59\", \"side\":\"SELL\", \"hash\":\"2f714044daec398b9feea29ffb840a5bac4e04dc\", \"best_bid\":\"0.61\", \"best_ask\":\"0.62\"}, {\"asset_id\":\"96600821790790307414914106093858868634329285205417149685270682748367152458577\", \"price\":\"0.35\", \"size\":\"76.59\", \"side\":\"BUY\", \"hash\":\"be1909566f53cfc36a2740617d94cff8f38575d4\", \"best_bid\":\"0.38\", \"best_ask\":\"0.39\"}], \"timestamp\":\"1785211591181\", \"event_type\":\"price_change\"}","received_at":"2026-07-28T04:06:30.984945Z","schema_version":"clob-market-ws.price_change.v1","sequence":null,"server_hash":null,"server_timestamp":"1785211591181","session_id":"2d607381e3054cee91998cdf45a4231c","source":"clob_market_ws"},"received_at":"2026-07-28T04:06:30.984945Z","record_id":"877e33523cc7086318461a78b5df32de53254e50415634f2cbd6196f0af80e46","schema_fingerprint":"4aa3821a28b0b7c2400bc59aba4bcc0a76e971dadd19610d3ad38c768e124dc7","schema_version":"edge-lab-recorder.raw.v1","sequence":null,"source":"clob_market_ws"}
{"event_at":"2026-07-28T04:06:31.189000Z","event_fingerprint":"28e631efaec63eae524dff3885aabb272327dc69229dcee5ab0246bcb48d9d18","payload":{"connection_id":"f6725804f86a4c4eb588e4d5ed7db029","event_at":"2026-07-28T04:06:31.189000Z","event_type":"price_change","frame_hash":"8cb7204718837430fdafc2553aaa9272d73cbd3f179ccd4cd676c9a76d55cfa2","frame_index":0,"kind":"data","monotonic_ns":313574047684125,"payload":{"event_type":"price_change","market":"0xd412ce774cfcf8dc9f71164aac78783978aac7b03871702a3b8a481bd9dc9688","price_changes":[{"asset_id":"107603864457683460275633293642179940881969192120168665300712204232021063124301","best_ask":"0.62","best_bid":"0.61","hash":"6c505238da604f8fc14783434cf0276b93e43dbe","price":"0.36","side":"BUY","size":"110.59"},{"asset_id":"96600821790790307414914106093858868634329285205417149685270682748367152458577","best_ask":"0.39","best_bid":"0.38","hash":"68b9c3b0f71d64e3c21c2e9aeca3628e5de0e3bb","price":"0.64","side":"SELL","size":"110.59"}],"timestamp":"1785211591189"},"payload_hash":"1e698f7ced761244d09f7fbb60362406e57b293d155b142e221cb25492df41be","raw_frame":"{\"market\":\"0xd412ce774cfcf8dc9f71164aac78783978aac7b03871702a3b8a481bd9dc9688\", \"price_changes\":[{\"asset_id\":\"107603864457683460275633293642179940881969192120168665300712204232021063124301\", \"price\":\"0.36\", \"size\":\"110.59\", \"side\":\"BUY\", \"hash\":\"6c505238da604f8fc14783434cf0276b93e43dbe\", \"best_bid\":\"0.61\", \"best_ask\":\"0.62\"}, {\"asset_id\":\"96600821790790307414914106093858868634329285205417149685270682748367152458577\", \"price\":\"0.64\", \"size\":\"110.59\", \"side\":\"SELL\", \"hash\":\"68b9c3b0f71d64e3c21c2e9aeca3628e5de0e3bb\", \"best_bid\":\"0.38\", \"best_ask\":\"0.39\"}], \"timestamp\":\"1785211591189\", \"event_type\":\"price_change\"}","received_at":"2026-07-28T04:06:30.996876Z","schema_version":"clob-market-ws.price_change.v1","sequence":null,"server_hash":null,"server_timestamp":"1785211591189","session_id":"2d607381e3054cee91998cdf45a4231c","source":"clob_market_ws"},"received_at":"2026-07-28T04:06:30.996876Z","record_id":"f5253b525935739616b74aded0a676bbd4e2bdc9138cb72b9bf70b88ac4a5b9f","schema_fingerprint":"4aa3821a28b0b7c2400bc59aba4bcc0a76e971dadd19610d3ad38c768e124dc7","schema_version":"edge-lab-recorder.raw.v1","sequence":null,"source":"clob_market_ws"}
{"event_at":"2026-07-28T04:06:31.191000Z","event_fingerprint":"de92f05119789e4a756f6572c3a0e898c5574923b5c8995963c2b59fef34b6fb","payload":{"connection_id":"f6725804f86a4c4eb588e4d5ed7db029","event_at":"2026-07-28T04:06:31.191000Z","event_type":"price_change","frame_hash":"7133671428a76c3e66d2753b6e8ad7769e1ced277f2ad57888a4b5e7b1b2c029","frame_index":0,"kind":"data","monotonic_ns":313574052473208,"payload":{"event_type":"price_change","market":"0xd412ce774cfcf8dc9f71164aac78783978aac7b03871702a3b8a481bd9dc9688","price_changes":[{"asset_id":"96600821790790307414914106093858868634329285205417149685270682748367152458577","best_ask":"0.39","best_bid":"0.38","hash":"df75c20248f3c8d2a4df606e599cbfdf4b0c4d4b","price":"0.16","side":"BUY","size":"332.42"},{"asset_id":"107603864457683460275633293642179940881969192120168665300712204232021063124301","best_ask":"0.62","best_bid":"0.61","hash":"135a817b871f5631f4ef71f8370456d1e7c8eec9","price":"0.84","side":"SELL","size":"332.42"}],"timestamp":"1785211591191"},"payload_hash":"0df3055b5d24fb6193e76ee91505baea59b1b0eca9bb8e9269c75e1504184fde","raw_frame":"{\"market\":\"0xd412ce774cfcf8dc9f71164aac78783978aac7b03871702a3b8a481bd9dc9688\", \"price_changes\":[{\"asset_id\":\"96600821790790307414914106093858868634329285205417149685270682748367152458577\", \"price\":\"0.16\", \"size\":\"332.42\", \"side\":\"BUY\", \"hash\":\"df75c20248f3c8d2a4df606e599cbfdf4b0c4d4b\", \"best_bid\":\"0.38\", \"best_ask\":\"0.39\"}, {\"asset_id\":\"107603864457683460275633293642179940881969192120168665300712204232021063124301\", \"price\":\"0.84\", \"size\":\"332.42\", \"side\":\"SELL\", \"hash\":\"135a817b871f5631f4ef71f8370456d1e7c8eec9\", \"best_bid\":\"0.61\", \"best_ask\":\"0.62\"}], \"timestamp\":\"1785211591191\", \"event_type\":\"price_change\"}","received_at":"2026-07-28T04:06:31.001664Z","schema_version":"clob-market-ws.price_change.v1","sequence":null,"server_hash":null,"server_timestamp":"1785211591191","session_id":"2d607381e3054cee91998cdf45a4231c","source":"clob_market_ws"},"received_at":"2026-07-28T04:06:31.001664Z","record_id":"65228a709c07ac8cc76157f924dfe7098c31853249c6488f48f32d9285863613","schema_fingerprint":"4aa3821a28b0b7c2400bc59aba4bcc0a76e971dadd19610d3ad38c768e124dc7","schema_version":"edge-lab-recorder.raw.v1","sequence":null,"source":"clob_market_ws"}
{"event_at":"2026-07-28T04:06:31.195000Z","event_fingerprint":"77f580182b4a81734c78c8f8a5af153f0dfc5424523a9d16dd2aafdeb48c96a2","payload":{"connection_id":"f6725804f86a4c4eb588e4d5ed7db029","event_at":"2026-07-28T04:06:31.195000Z","event_type":"price_change","frame_hash":"a14669e07676531227bea20463050f140e740a880619e198a1235fd098194be7","frame_index":0,"kind":"data","monotonic_ns":313574056306333,"payload":{"event_type":"price_change","market":"0xd412ce774cfcf8dc9f71164aac78783978aac7b03871702a3b8a481bd9dc9688","price_changes":[{"asset_id":"107603864457683460275633293642179940881969192120168665300712204232021063124301","best_ask":"0.62","best_bid":"0.61","hash":"0b567dbc754b7545a51f6710dab91748666f8d36","price":"0.76","side":"SELL","size":"153.39"},{"asset_id":"96600821790790307414914106093858868634329285205417149685270682748367152458577","best_ask":"0.39","best_bid":"0.38","hash":"4e6f5a171b9370cc84d3ea8acb6bc24d301f2c12","price":"0.24","side":"BUY","size":"153.39"}],"timestamp":"1785211591195"},"payload_hash":"eba882f1c2a6cbebb727d5f9818a6cdefc938aaa1d5f915119e734f8394e8484","raw_frame":"{\"market\":\"0xd412ce774cfcf8dc9f71164aac78783978aac7b03871702a3b8a481bd9dc9688\", \"price_changes\":[{\"asset_id\":\"107603864457683460275633293642179940881969192120168665300712204232021063124301\", \"price\":\"0.76\", \"size\":\"153.39\", \"side\":\"SELL\", \"hash\":\"0b567dbc754b7545a51f6710dab91748666f8d36\", \"best_bid\":\"0.61\", \"best_ask\":\"0.62\"}, {\"asset_id\":\"96600821790790307414914106093858868634329285205417149685270682748367152458577\", \"price\":\"0.24\", \"size\":\"153.39\", \"side\":\"BUY\", \"hash\":\"4e6f5a171b9370cc84d3ea8acb6bc24d301f2c12\", \"best_bid\":\"0.38\", \"best_ask\":\"0.39\"}], \"timestamp\":\"1785211591195\", \"event_type\":\"price_change\"}","received_at":"2026-07-28T04:06:31.005491Z","schema_version":"clob-market-ws.price_change.v1","sequence":null,"server_hash":null,"server_timestamp":"1785211591195","session_id":"2d607381e3054cee91998cdf45a4231c","source":"clob_market_ws"},"received_at":"2026-07-28T04:06:31.005491Z","record_id":"06b7d58e98b2d29a8e0f05bd7d53aae0378ecabdf304a6ef0c80b9eb2ddf1552","schema_fingerprint":"4aa3821a28b0b7c2400bc59aba4bcc0a76e971dadd19610d3ad38c768e124dc7","schema_version":"edge-lab-recorder.raw.v1","sequence":null,"source":"clob_market_ws"}
{"event_at":"2026-07-28T04:06:31.196000Z","event_fingerprint":"a268b06263e9f23344907131847a31fa01f37b3e41004c4ff348e6d51dead308","payload":{"connection_id":"f6725804f86a4c4eb588e4d5ed7db029","event_at":"2026-07-28T04:06:31.196000Z","event_type":"price_change","frame_hash":"d406d62627b41b572da056c2c33069e3f5bb3b48350dab3ac44ed5f0e2db723c","frame_index":0,"kind":"data","monotonic_ns":313574061764666,"payload":{"event_type":"price_change","market":"0xd412ce774cfcf8dc9f71164aac78783978aac7b03871702a3b8a481bd9dc9688","price_changes":[{"asset_id":"107603864457683460275633293642179940881969192120168665300712204232021063124301","best_ask":"0.62","best_bid":"0.61","hash":"5f364ce92db6733c928c3340b8fc9fcc9a831272","price":"0.03","side":"BUY","size":"623.1"},{"asset_id":"96600821790790307414914106093858868634329285205417149685270682748367152458577","best_ask":"0.39","best_bid":"0.38","hash":"f3c5534f3dece1439d5cf232843251c503017042","price":"0.97","side":"SELL","size":"623.1"}],"timestamp":"1785211591196"},"payload_hash":"65c40c3d3d3ff8517341c52e311de5d4169b2f30f0e9a6cd1eb8475f19beebe0","raw_frame":"{\"market\":\"0xd412ce774cfcf8dc9f71164aac78783978aac7b03871702a3b8a481bd9dc9688\", \"price_changes\":[{\"asset_id\":\"107603864457683460275633293642179940881969192120168665300712204232021063124301\", \"price\":\"0.03\", \"size\":\"623.1\", \"side\":\"BUY\", \"hash\":\"5f364ce92db6733c928c3340b8fc9fcc9a831272\", \"best_bid\":\"0.61\", \"best_ask\":\"0.62\"}, {\"asset_id\":\"96600821790790307414914106093858868634329285205417149685270682748367152458577\", \"price\":\"0.97\", \"size\":\"623.1\", \"side\":\"SELL\", \"hash\":\"f3c5534f3dece1439d5cf232843251c503017042\", \"best_bid\":\"0.38\", \"best_ask\":\"0.39\"}], \"timestamp\":\"1785211591196\", \"event_type\":\"price_change\"}","received_at":"2026-07-28T04:06:31.010956Z","schema_version":"clob-market-ws.price_change.v1","sequence":null,"server_hash":null,"server_timestamp":"1785211591196","session_id":"2d607381e3054cee91998cdf45a4231c","source":"clob_market_ws"},"received_at":"2026-07-28T04:06:31.010956Z","record_id":"fdf83bd63feea378d8019baeca43a66a9958a35dd8d8831e23d491f9ec5ef933","schema_fingerprint":"4aa3821a28b0b7c2400bc59aba4bcc0a76e971dadd19610d3ad38c768e124dc7","schema_version":"edge-lab-recorder.raw.v1","sequence":null,"source":"clob_market_ws"}
{"event_at":"2026-07-28T04:06:31.198000Z","event_fingerprint":"61bf506c3864633db04a861696e306a6ed4c12f19e9fae7cc8d9e14b0e6eb552","payload":{"connection_id":"f6725804f86a4c4eb588e4d5ed7db029","event_at":"2026-07-28T04:06:31.198000Z","event_type":"price_change","frame_hash":"98188d4ef9d0ebff84b175a82fba3bb54848806a2e9dafc33ba821716dbf49b9","frame_index":0,"kind":"data","monotonic_ns":313574066171708,"payload":{"event_type":"price_change","market":"0xd412ce774cfcf8dc9f71164aac78783978aac7b03871702a3b8a481bd9dc9688","price_changes":[{"asset_id":"96600821790790307414914106093858868634329285205417149685270682748367152458577","best_ask":"0.39","best_bid":"0.38","hash":"aea9d10b1c7daf58c54c883a90c3b04e26d7afd7","price":"0.2","side":"BUY","size":"161.8"},{"asset_id":"107603864457683460275633293642179940881969192120168665300712204232021063124301","best_ask":"0.62","best_bid":"0.61","hash":"d1791a1a4d8d1f7c0900dd0f5548da17d85ccce4","price":"0.8","side":"SELL","size":"161.8"}],"timestamp":"1785211591198"},"payload_hash":"cdec1386141bdd5c12e1d3fc10f587887a7d4efd2bce907088a4e76fa2728f7a","raw_frame":"{\"market\":\"0xd412ce774cfcf8dc9f71164aac78783978aac7b03871702a3b8a481bd9dc9688\", \"price_changes\":[{\"asset_id\":\"96600821790790307414914106093858868634329285205417149685270682748367152458577\", \"price\":\"0.2\", \"size\":\"161.8\", \"side\":\"BUY\", \"hash\":\"aea9d10b1c7daf58c54c883a90c3b04e26d7afd7\", \"best_bid\":\"0.38\", \"best_ask\":\"0.39\"}, {\"asset_id\":\"107603864457683460275633293642179940881969192120168665300712204232021063124301\", \"price\":\"0.8\", \"size\":\"161.8\", \"side\":\"SELL\", \"hash\":\"d1791a1a4d8d1f7c0900dd0f5548da17d85ccce4\", \"best_bid\":\"0.61\", \"best_ask\":\"0.62\"}], \"timestamp\":\"1785211591198\", \"event_type\":\"price_change\"}","received_at":"2026-07-28T04:06:31.015363Z","schema_version":"clob-market-ws.price_change.v1","sequence":null,"server_hash":null,"server_timestamp":"1785211591198","session_id":"2d607381e3054cee91998cdf45a4231c","source":"clob_market_ws"},"received_at":"2026-07-28T04:06:31.015363Z","record_id":"16c785232fafdcd26e6d66635a9c787aae04fe47333c1490f2bcd278c79b06d5","schema_fingerprint":"4aa3821a28b0b7c2400bc59aba4bcc0a76e971dadd19610d3ad38c768e124dc7","schema_version":"edge-lab-recorder.raw.v1","sequence":null,"source":"clob_market_ws"}
{"event_at":"2026-07-28T04:06:31.199000Z","event_fingerprint":"6107765eb60d078c0e411473d1db6a4f3db9f81e3b57f71de0e8a1cec0d23ee9","payload":{"connection_id":"f6725804f86a4c4eb588e4d5ed7db029","event_at":"2026-07-28T04:06:31.199000Z","event_type":"price_change","frame_hash":"352919237858470b5de663ad6a1ede2200d16df859a28ccc6887861b0b2a85cc","frame_index":0,"kind":"data","monotonic_ns":313574070645791,"payload":{"event_type":"price_change","market":"0xd412ce774cfcf8dc9f71164aac78783978aac7b03871702a3b8a481bd9dc9688","price_changes":[{"asset_id":"96600821790790307414914106093858868634329285205417149685270682748367152458577","best_ask":"0.39","best_bid":"0.38","hash":"c72b4732f80dd2c624ae65edc27d73fa96518c0a","price":"0.23","side":"BUY","size":"123.89"},{"asset_id":"107603864457683460275633293642179940881969192120168665300712204232021063124301","best_ask":"0.62","best_bid":"0.61","hash":"d5db4dd44a5430aa6a0ca429ae4aaf40a060dd8c","price":"0.77","side":"SELL","size":"123.89"}],"timestamp":"1785211591199"},"payload_hash":"1c555b1f8073a3562f41f29d89b91012787514665d63a8991395a7bdced00a4b","raw_frame":"{\"market\":\"0xd412ce774cfcf8dc9f71164aac78783978aac7b03871702a3b8a481bd9dc9688\", \"price_changes\":[{\"asset_id\":\"96600821790790307414914106093858868634329285205417149685270682748367152458577\", \"price\":\"0.23\", \"size\":\"123.89\", \"side\":\"BUY\", \"hash\":\"c72b4732f80dd2c624ae65edc27d73fa96518c0a\", \"best_bid\":\"0.38\", \"best_ask\":\"0.39\"}, {\"asset_id\":\"107603864457683460275633293642179940881969192120168665300712204232021063124301\", \"price\":\"0.77\", \"size\":\"123.89\", \"side\":\"SELL\", \"hash\":\"d5db4dd44a5430aa6a0ca429ae4aaf40a060dd8c\", \"best_bid\":\"0.61\", \"best_ask\":\"0.62\"}], \"timestamp\":\"1785211591199\", \"event_type\":\"price_change\"}","received_at":"2026-07-28T04:06:31.019837Z","schema_version":"clob-market-ws.price_change.v1","sequence":null,"server_hash":null,"server_timestamp":"1785211591199","session_id":"2d607381e3054cee91998cdf45a4231c","source":"clob_market_ws"},"received_at":"2026-07-28T04:06:31.019837Z","record_id":"d4a30ffc0a3ca1784d7a51d1d105cb9a64ea0fd05b9225f78a417887660718ce","schema_fingerprint":"4aa3821a28b0b7c2400bc59aba4bcc0a76e971dadd19610d3ad38c768e124dc7","schema_version":"edge-lab-recorder.raw.v1","sequence":null,"source":"clob_market_ws"}
{"event_at":"2026-07-28T04:06:31.203000Z","event_fingerprint":"773096307feed4651e58416c4f1b75ea511ef5ebc6d4ee0fc0e2e9a7e326f026","payload":{"connection_id":"f6725804f86a4c4eb588e4d5ed7db029","event_at":"2026-07-28T04:06:31.203000Z","event_type":"price_change","frame_hash":"a19d618fa623dc513290185ca37913d5fd4cd750269ee19cb68fbe3237936555","frame_index":0,"kind":"data","monotonic_ns":313574075745958,"payload":{"event_type":"price_change","market":"0xd412ce774cfcf8dc9f71164aac78783978aac7b03871702a3b8a481bd9dc9688","price_changes":[{"asset_id":"107603864457683460275633293642179940881969192120168665300712204232021063124301","best_ask":"0.62","best_bid":"0.61","hash":"0236621d59ed47de4b5ce4626f3df5b1908c5ddc","price":"0.01","side":"BUY","size":"5643.02"},{"asset_id":"96600821790790307414914106093858868634329285205417149685270682748367152458577","best_ask":"0.39","best_bid":"0.38","hash":"17cdd66629f7d18d4edc150253c12cdbb659a750","price":"0.99","side":"SELL","size":"5643.02"}],"timestamp":"1785211591203"},"payload_hash":"3718084b5b3a651d8fceae589e36b856c054e4a92d18a2fcd4821d64e83a6738","raw_frame":"{\"market\":\"0xd412ce774cfcf8dc9f71164aac78783978aac7b03871702a3b8a481bd9dc9688\", \"price_changes\":[{\"asset_id\":\"107603864457683460275633293642179940881969192120168665300712204232021063124301\", \"price\":\"0.01\", \"size\":\"5643.02\", \"side\":\"BUY\", \"hash\":\"0236621d59ed47de4b5ce4626f3df5b1908c5ddc\", \"best_bid\":\"0.61\", \"best_ask\":\"0.62\"}, {\"asset_id\":\"96600821790790307414914106093858868634329285205417149685270682748367152458577\", \"price\":\"0.99\", \"size\":\"5643.02\", \"side\":\"SELL\", \"hash\":\"17cdd66629f7d18d4edc150253c12cdbb659a750\", \"best_bid\":\"0.38\", \"best_ask\":\"0.39\"}], \"timestamp\":\"1785211591203\", \"event_type\":\"price_change\"}","received_at":"2026-07-28T04:06:31.024937Z","schema_version":"clob-market-ws.price_change.v1","sequence":null,"server_hash":null,"server_timestamp":"1785211591203","session_id":"2d607381e3054cee91998cdf45a4231c","source":"clob_market_ws"},"received_at":"2026-07-28T04:06:31.024937Z","record_id":"cf605db548af0d27381312e80187b82118ce7d5e7b72495e7535a68d2d44d693","schema_fingerprint":"4aa3821a28b0b7c2400bc59aba4bcc0a76e971dadd19610d3ad38c768e124dc7","schema_version":"edge-lab-recorder.raw.v1","sequence":null,"source":"clob_market_ws"}
{"event_at":"2026-07-28T04:06:31.222000Z","event_fingerprint":"307670bcb63cdd8873aed020e0b48538e2b910da24792ec90738d7913650772b","payload":{"connection_id":"f6725804f86a4c4eb588e4d5ed7db029","event_at":"2026-07-28T04:06:31.222000Z","event_type":"price_change","frame_hash":"7371b3c9a7ae5771ea72097138d601fa9a0fd09522aff16d62820f7a3e0ee2e3","frame_index":0,"kind":"data","monotonic_ns":313574081423208,"payload":{"event_type":"price_change","market":"0xd412ce774cfcf8dc9f71164aac78783978aac7b03871702a3b8a481bd9dc9688","price_changes":[{"asset_id":"96600821790790307414914106093858868634329285205417149685270682748367152458577","best_ask":"0.39","best_bid":"0.38","hash":"d993ed81d7bceecc428de5c14656ee8fed07e635","price":"0.36","side":"BUY","size":"33.6"},{"asset_id":"107603864457683460275633293642179940881969192120168665300712204232021063124301","best_ask":"0.62","best_bid":"0.61","hash":"bea52414529928ef52474291f9ef07161ec2156e","price":"0.64","side":"SELL","size":"33.6"}],"timestamp":"1785211591222"},"payload_hash":"cbec6d3449db19e4002f20e568c246e2dd726e6e1668d570a47404ee654d16a4","raw_frame":"{\"market\":\"0xd412ce774cfcf8dc9f71164aac78783978aac7b03871702a3b8a481bd9dc9688\", \"price_changes\":[{\"asset_id\":\"96600821790790307414914106093858868634329285205417149685270682748367152458577\", \"price\":\"0.36\", \"size\":\"33.6\", \"side\":\"BUY\", \"hash\":\"d993ed81d7bceecc428de5c14656ee8fed07e635\", \"best_bid\":\"0.38\", \"best_ask\":\"0.39\"}, {\"asset_id\":\"107603864457683460275633293642179940881969192120168665300712204232021063124301\", \"price\":\"0.64\", \"size\":\"33.6\", \"side\":\"SELL\", \"hash\":\"bea52414529928ef52474291f9ef07161ec2156e\", \"best_bid\":\"0.61\", \"best_ask\":\"0.62\"}], \"timestamp\":\"1785211591222\", \"event_type\":\"price_change\"}","received_at":"2026-07-28T04:06:31.030613Z","schema_version":"clob-market-ws.price_change.v1","sequence":null,"server_hash":null,"server_timestamp":"1785211591222","session_id":"2d607381e3054cee91998cdf45a4231c","source":"clob_market_ws"},"received_at":"2026-07-28T04:06:31.030613Z","record_id":"df64eb439edfd064f4d40b549353b36e9a6afad12ae84e53740678560362660c","schema_fingerprint":"4aa3821a28b0b7c2400bc59aba4bcc0a76e971dadd19610d3ad38c768e124dc7","schema_version":"edge-lab-recorder.raw.v1","sequence":null,"source":"clob_market_ws"}
{"event_at":"2026-07-28T04:06:31.227000Z","event_fingerprint":"fd95b7e90cee6693e36f5e0e786661ef8318c5416a0fe77f582de7210ea272c0","payload":{"connection_id":"f6725804f86a4c4eb588e4d5ed7db029","event_at":"2026-07-28T04:06:31.227000Z","event_type":"price_change","frame_hash":"09219b1dfc99358d4b28fe6c4a7d4f96e3e100f2200c82b6d7bfb2b8c22ce1e8","frame_index":0,"kind":"data","monotonic_ns":313574084487875,"payload":{"event_type":"price_change","market":"0xd412ce774cfcf8dc9f71164aac78783978aac7b03871702a3b8a481bd9dc9688","price_changes":[{"asset_id":"107603864457683460275633293642179940881969192120168665300712204232021063124301","best_ask":"0.62","best_bid":"0.61","hash":"f70cd478f17bc176c617f2f3a8a1e099ad1171ab","price":"0.77","side":"SELL","size":"131.39"},{"asset_id":"96600821790790307414914106093858868634329285205417149685270682748367152458577","best_ask":"0.39","best_bid":"0.38","hash":"f35d2354ea14b8a1e5262df6fd831f60923fb161","price":"0.23","side":"BUY","size":"131.39"}],"timestamp":"1785211591227"},"payload_hash":"a4529e331b541156e87c7fb9eb6099d5d005d4bca25c891364e7f2f78a763b85","raw_frame":"{\"market\":\"0xd412ce774cfcf8dc9f71164aac78783978aac7b03871702a3b8a481bd9dc9688\", \"price_changes\":[{\"asset_id\":\"107603864457683460275633293642179940881969192120168665300712204232021063124301\", \"price\":\"0.77\", \"size\":\"131.39\", \"side\":\"SELL\", \"hash\":\"f70cd478f17bc176c617f2f3a8a1e099ad1171ab\", \"best_bid\":\"0.61\", \"best_ask\":\"0.62\"}, {\"asset_id\":\"96600821790790307414914106093858868634329285205417149685270682748367152458577\", \"price\":\"0.23\", \"size\":\"131.39\", \"side\":\"BUY\", \"hash\":\"f35d2354ea14b8a1e5262df6fd831f60923fb161\", \"best_bid\":\"0.38\", \"best_ask\":\"0.39\"}], \"timestamp\":\"1785211591227\", \"event_type\":\"price_change\"}","received_at":"2026-07-28T04:06:31.033680Z","schema_version":"clob-market-ws.price_change.v1","sequence":null,"server_hash":null,"server_timestamp":"1785211591227","session_id":"2d607381e3054cee91998cdf45a4231c","source":"clob_market_ws"},"received_at":"2026-07-28T04:06:31.033680Z","record_id":"b64acc066de15d6d5dc8a8316d8e23be97766141a76d0bd6d11accdea35e5a1e","schema_fingerprint":"4aa3821a28b0b7c2400bc59aba4bcc0a76e971dadd19610d3ad38c768e124dc7","schema_version":"edge-lab-recorder.raw.v1","sequence":null,"source":"clob_market_ws"}
{"event_at":"2026-07-28T04:06:31.228000Z","event_fingerprint":"5bf65d57634a4be90a0769356780438655cd9b6a7ad566eafe93d4a39811fbea","payload":{"connection_id":"f6725804f86a4c4eb588e4d5ed7db029","event_at":"2026-07-28T04:06:31.228000Z","event_type":"price_change","frame_hash":"de93571e2461d9b24fc12562eb90542c4504d8d17c94771a3cd0824c5874eb09","frame_index":0,"kind":"data","monotonic_ns":313574087219916,"payload":{"event_type":"price_change","market":"0xd412ce774cfcf8dc9f71164aac78783978aac7b03871702a3b8a481bd9dc9688","price_changes":[{"asset_id":"107603864457683460275633293642179940881969192120168665300712204232021063124301","best_ask":"0.62","best_bid":"0.61","hash":"5142bcf2f58a8dc6620b41451e5b1980405db8ed","price":"0.01","side":"BUY","size":"5638.02"},{"asset_id":"96600821790790307414914106093858868634329285205417149685270682748367152458577","best_ask":"0.39","best_bid":"0.38","hash":"f233eb3469c36fa247a58eec455b2f3c003adbda","price":"0.99","side":"SELL","size":"5638.02"}],"timestamp":"1785211591228"},"payload_hash":"3893df0c4c02564b4f282426da017ac1595de4d670d9129fb8dc853304978d2d","raw_frame":"{\"market\":\"0xd412ce774cfcf8dc9f71164aac78783978aac7b03871702a3b8a481bd9dc9688\", \"price_changes\":[{\"asset_id\":\"107603864457683460275633293642179940881969192120168665300712204232021063124301\", \"price\":\"0.01\", \"size\":\"5638.02\", \"side\":\"BUY\", \"hash\":\"5142bcf2f58a8dc6620b41451e5b1980405db8ed\", \"best_bid\":\"0.61\", \"best_ask\":\"0.62\"}, {\"asset_id\":\"96600821790790307414914106093858868634329285205417149685270682748367152458577\", \"price\":\"0.99\", \"size\":\"5638.02\", \"side\":\"SELL\", \"hash\":\"f233eb3469c36fa247a58eec455b2f3c003adbda\", \"best_bid\":\"0.38\", \"best_ask\":\"0.39\"}], \"timestamp\":\"1785211591228\", \"event_type\":\"price_change\"}","received_at":"2026-07-28T04:06:31.036412Z","schema_version":"clob-market-ws.price_change.v1","sequence":null,"server_hash":null,"server_timestamp":"1785211591228","session_id":"2d607381e3054cee91998cdf45a4231c","source":"clob_market_ws"},"received_at":"2026-07-28T04:06:31.036412Z","record_id":"39e005f1f5be737ffa8a429a3e7ea67d9c85a58b1c1d708683fbdc0fc8929b41","schema_fingerprint":"4aa3821a28b0b7c2400bc59aba4bcc0a76e971dadd19610d3ad38c768e124dc7","schema_version":"edge-lab-recorder.raw.v1","sequence":null,"source":"clob_market_ws"}
{"event_at":"2026-07-28T04:06:31.245000Z","event_fingerprint":"b2e861e48f5b6cd68f9643f9e722fc238baee2f9cbc7d084a3476af282e1cb5a","payload":{"connection_id":"f6725804f86a4c4eb588e4d5ed7db029","event_at":"2026-07-28T04:06:31.245000Z","event_type":"price_change","frame_hash":"f6c4080ccc24c9a6e873c825839ca74afc279244011d5ae59aec942de268fe13","frame_index":0,"kind":"data","monotonic_ns":313574096413666,"payload":{"event_type":"price_change","market":"0xd412ce774cfcf8dc9f71164aac78783978aac7b03871702a3b8a481bd9dc9688","price_changes":[{"asset_id":"107603864457683460275633293642179940881969192120168665300712204232021063124301","best_ask":"0.62","best_bid":"0.61","hash":"76c98c24e6df36cf1727f3df64bf8a8ec966aa91","price":"0.55","side":"BUY","size":"233"},{"asset_id":"96600821790790307414914106093858868634329285205417149685270682748367152458577","best_ask":"0.39","best_bid":"0.38","hash":"a267aee2012cc2c19653282f77ddf3d1de30030c","price":"0.45","side":"SELL","size":"233"}],"timestamp":"1785211591245"},"payload_hash":"f461fe3359f018a95e9b1ab25ebc5970b8da3da2a5ffcfb32f492baaed796ee2","raw_frame":"{\"market\":\"0xd412ce774cfcf8dc9f71164aac78783978aac7b03871702a3b8a481bd9dc9688\", \"price_changes\":[{\"asset_id\":\"107603864457683460275633293642179940881969192120168665300712204232021063124301\", \"price\":\"0.55\", \"size\":\"233\", \"side\":\"BUY\", \"hash\":\"76c98c24e6df36cf1727f3df64bf8a8ec966aa91\", \"best_bid\":\"0.61\", \"best_ask\":\"0.62\"}, {\"asset_id\":\"96600821790790307414914106093858868634329285205417149685270682748367152458577\", \"price\":\"0.45\", \"size\":\"233\", \"side\":\"SELL\", \"hash\":\"a267aee2012cc2c19653282f77ddf3d1de30030c\", \"best_bid\":\"0.38\", \"best_ask\":\"0.39\"}], \"timestamp\":\"1785211591245\", \"event_type\":\"price_change\"}","received_at":"2026-07-28T04:06:31.045603Z","schema_version":"clob-market-ws.price_change.v1","sequence":null,"server_hash":null,"server_timestamp":"1785211591245","session_id":"2d607381e3054cee91998cdf45a4231c","source":"clob_market_ws"},"received_at":"2026-07-28T04:06:31.045603Z","record_id":"4ca359bdc2cf5348e57e6762a4c2d4268b82766e516b24331149383e6d0b88ea","schema_fingerprint":"4aa3821a28b0b7c2400bc59aba4bcc0a76e971dadd19610d3ad38c768e124dc7","schema_version":"edge-lab-recorder.raw.v1","sequence":null,"source":"clob_market_ws"}
{"event_at":"2026-07-28T04:06:31.247000Z","event_fingerprint":"5b0f78a16fe4711f4e2bab14976bde5879e45f838ff5a3e3c2252643ccc8ab0f","payload":{"connection_id":"f6725804f86a4c4eb588e4d5ed7db029","event_at":"2026-07-28T04:06:31.247000Z","event_type":"price_change","frame_hash":"49601f08f0d7ea373c0d9dd597b3dd6ed65a0c989765ed5f1eae2fe88cb843e5","frame_index":0,"kind":"data","monotonic_ns":313574099594583,"payload":{"event_type":"price_change","market":"0xd412ce774cfcf8dc9f71164aac78783978aac7b03871702a3b8a481bd9dc9688","price_changes":[{"asset_id":"107603864457683460275633293642179940881969192120168665300712204232021063124301","best_ask":"0.62","best_bid":"0.61","hash":"5ada79f2034e5ffd775ec7f325f6a3a3ffb9177c","price":"0.03","side":"BUY","size":"618.1"},{"asset_id":"96600821790790307414914106093858868634329285205417149685270682748367152458577","best_ask":"0.39","best_bid":"0.38","hash":"623ff7d10d0ed07d652380a09591caf38a0ea0b6","price":"0.97","side":"SELL","size":"618.1"}],"timestamp":"1785211591247"},"payload_hash":"2ee7453b62e4dffe76a010079514858e15ec12390d63a7838fea79cc79ed8f11","raw_frame":"{\"market\":\"0xd412ce774cfcf8dc9f71164aac78783978aac7b03871702a3b8a481bd9dc9688\", \"price_changes\":[{\"asset_id\":\"107603864457683460275633293642179940881969192120168665300712204232021063124301\", \"price\":\"0.03\", \"size\":\"618.1\", \"side\":\"BUY\", \"hash\":\"5ada79f2034e5ffd775ec7f325f6a3a3ffb9177c\", \"best_bid\":\"0.61\", \"best_ask\":\"0.62\"}, {\"asset_id\":\"96600821790790307414914106093858868634329285205417149685270682748367152458577\", \"price\":\"0.97\", \"size\":\"618.1\", \"side\":\"SELL\", \"hash\":\"623ff7d10d0ed07d652380a09591caf38a0ea0b6\", \"best_bid\":\"0.38\", \"best_ask\":\"0.39\"}], \"timestamp\":\"1785211591247\", \"event_type\":\"price_change\"}","received_at":"2026-07-28T04:06:31.048786Z","schema_version":"clob-market-ws.price_change.v1","sequence":null,"server_hash":null,"server_timestamp":"1785211591247","session_id":"2d607381e3054cee91998cdf45a4231c","source":"clob_market_ws"},"received_at":"2026-07-28T04:06:31.048786Z","record_id":"3cffc703325248f0240061dd23acf27b08edf96ca50b3dbee59c2d9b3cf16869","schema_fingerprint":"4aa3821a28b0b7c2400bc59aba4bcc0a76e971dadd19610d3ad38c768e124dc7","schema_version":"edge-lab-recorder.raw.v1","sequence":null,"source":"clob_market_ws"}
{"event_at":"2026-07-28T04:06:31.277000Z","event_fingerprint":"f9570a977991760ef214ab9183b4bd3a04a8a31bd4d603288e3cf78e179150dd","payload":{"connection_id":"f6725804f86a4c4eb588e4d5ed7db029","event_at":"2026-07-28T04:06:31.277000Z","event_type":"price_change","frame_hash":"22b246be3a6dc9b4f1e5dc5f07c7ea57fc70d1604a9b47c6db57269ab0b849e1","frame_index":0,"kind":"data","monotonic_ns":313574129700916,"payload":{"event_type":"price_change","market":"0xd412ce774cfcf8dc9f71164aac78783978aac7b03871702a3b8a481bd9dc9688","price_changes":[{"asset_id":"107603864457683460275633293642179940881969192120168665300712204232021063124301","best_ask":"0.62","best_bid":"0.61","hash":"d37ab4634833ee2f436d1b84f3a6aaf3818030f3","price":"0.65","side":"SELL","size":"65.98"},{"asset_id":"96600821790790307414914106093858868634329285205417149685270682748367152458577","best_ask":"0.39","best_bid":"0.38","hash":"089ec46330cb6ec13d325737f5153fa29e592b9a","price":"0.35","side":"BUY","size":"65.98"}],"timestamp":"1785211591277"},"payload_hash":"caa78f6af207e01773f81d3a1771dede0fb03f89f0bb2260773dd5ab403a78f9","raw_frame":"{\"market\":\"0xd412ce774cfcf8dc9f71164aac78783978aac7b03871702a3b8a481bd9dc9688\", \"price_changes\":[{\"asset_id\":\"107603864457683460275633293642179940881969192120168665300712204232021063124301\", \"price\":\"0.65\", \"size\":\"65.98\", \"side\":\"SELL\", \"hash\":\"d37ab4634833ee2f436d1b84f3a6aaf3818030f3\", \"best_bid\":\"0.61\", \"best_ask\":\"0.62\"}, {\"asset_id\":\"96600821790790307414914106093858868634329285205417149685270682748367152458577\", \"price\":\"0.35\", \"size\":\"65.98\", \"side\":\"BUY\", \"hash\":\"089ec46330cb6ec13d325737f5153fa29e592b9a\", \"best_bid\":\"0.38\", \"best_ask\":\"0.39\"}], \"timestamp\":\"1785211591277\", \"event_type\":\"price_change\"}","received_at":"2026-07-28T04:06:31.078890Z","schema_version":"clob-market-ws.price_change.v1","sequence":null,"server_hash":null,"server_timestamp":"1785211591277","session_id":"2d607381e3054cee91998cdf45a4231c","source":"clob_market_ws"},"received_at":"2026-07-28T04:06:31.078890Z","record_id":"2fdca3359a1dc9a3d1fbbf59a347084c011b5d2f79a440c2988e15aab9f851a7","schema_fingerprint":"4aa3821a28b0b7c2400bc59aba4bcc0a76e971dadd19610d3ad38c768e124dc7","schema_version":"edge-lab-recorder.raw.v1","sequence":null,"source":"clob_market_ws"}
{"event_at":"2026-07-28T04:06:31.314000Z","event_fingerprint":"1ca094175305a7459f3caba01934fd0de59afd5a20a0c835365f3792c311c929","payload":{"connection_id":"f6725804f86a4c4eb588e4d5ed7db029","event_at":"2026-07-28T04:06:31.314000Z","event_type":"price_change","frame_hash":"dccf4e7d3add30d4ef8e12c570d4259ecf42ce66224d74700c6b9165149e9d4f","frame_index":0,"kind":"data","monotonic_ns":313574166262875,"payload":{"event_type":"price_change","market":"0xd412ce774cfcf8dc9f71164aac78783978aac7b03871702a3b8a481bd9dc9688","price_changes":[{"asset_id":"107603864457683460275633293642179940881969192120168665300712204232021063124301","best_ask":"0.62","best_bid":"0.61","hash":"e992f8d118c2104465b0566131dad57e3170198a","price":"0.36","side":"BUY","size":"203.18"},{"asset_id":"96600821790790307414914106093858868634329285205417149685270682748367152458577","best_ask":"0.39","best_bid":"0.38","hash":"a47b7be2f6dd66d0a2c75b47be3322bbf38ad5a2","price":"0.64","side":"SELL","size":"203.18"}],"timestamp":"1785211591314"},"payload_hash":"5ced9806ab6da6e4636c06bbe87d28d6f38a8e81c0108397d6e1e82ce2db119d","raw_frame":"{\"market\":\"0xd412ce774cfcf8dc9f71164aac78783978aac7b03871702a3b8a481bd9dc9688\", \"price_changes\":[{\"asset_id\":\"107603864457683460275633293642179940881969192120168665300712204232021063124301\", \"price\":\"0.36\", \"size\":\"203.18\", \"side\":\"BUY\", \"hash\":\"e992f8d118c2104465b0566131dad57e3170198a\", \"best_bid\":\"0.61\", \"best_ask\":\"0.62\"}, {\"asset_id\":\"96600821790790307414914106093858868634329285205417149685270682748367152458577\", \"price\":\"0.64\", \"size\":\"203.18\", \"side\":\"SELL\", \"hash\":\"a47b7be2f6dd66d0a2c75b47be3322bbf38ad5a2\", \"best_bid\":\"0.38\", \"best_ask\":\"0.39\"}], \"timestamp\":\"1785211591314\", \"event_type\":\"price_change\"}","received_at":"2026-07-28T04:06:31.115452Z","schema_version":"clob-market-ws.price_change.v1","sequence":null,"server_hash":null,"server_timestamp":"1785211591314","session_id":"2d607381e3054cee91998cdf45a4231c","source":"clob_market_ws"},"received_at":"2026-07-28T04:06:31.115452Z","record_id":"57cd26aeceac7d8769b60a74d8a527d721f2a07627463c58ab081a42d81ed5f1","schema_fingerprint":"4aa3821a28b0b7c2400bc59aba4bcc0a76e971dadd19610d3ad38c768e124dc7","schema_version":"edge-lab-recorder.raw.v1","sequence":null,"source":"clob_market_ws"}
{"event_at":"2026-07-28T04:06:31.320000Z","event_fingerprint":"5a41a74adfa8619ff9c6a7b4a68802c7064abe06bb4c13ee3fd06b63cbf2ba69","payload":{"connection_id":"f6725804f86a4c4eb588e4d5ed7db029","event_at":"2026-07-28T04:06:31.320000Z","event_type":"price_change","frame_hash":"76ddf72f70ce92adef095a9a66b0422267456b17a4c54212b8dd69fc3b6891e1","frame_index":0,"kind":"data","monotonic_ns":313574179073875,"payload":{"event_type":"price_change","market":"0xd412ce774cfcf8dc9f71164aac78783978aac7b03871702a3b8a481bd9dc9688","price_changes":[{"asset_id":"96600821790790307414914106093858868634329285205417149685270682748367152458577","best_ask":"0.39","best_bid":"0.38","hash":"2d2579c9dd7fa0dc80a4aeee33b89f9a9a1cf5fd","price":"0.16","side":"BUY","size":"527.42"},{"asset_id":"107603864457683460275633293642179940881969192120168665300712204232021063124301","best_ask":"0.62","best_bid":"0.61","hash":"0190077702b2240523b79d17556804ffb02555b0","price":"0.84","side":"SELL","size":"527.42"}],"timestamp":"1785211591320"},"payload_hash":"c9a40dc3b5a34ddf4174c0a0c92aad70ce8aa7830a952dd49713d61431c0a9a8","raw_frame":"{\"market\":\"0xd412ce774cfcf8dc9f71164aac78783978aac7b03871702a3b8a481bd9dc9688\", \"price_changes\":[{\"asset_id\":\"96600821790790307414914106093858868634329285205417149685270682748367152458577\", \"price\":\"0.16\", \"size\":\"527.42\", \"side\":\"BUY\", \"hash\":\"2d2579c9dd7fa0dc80a4aeee33b89f9a9a1cf5fd\", \"best_bid\":\"0.38\", \"best_ask\":\"0.39\"}, {\"asset_id\":\"107603864457683460275633293642179940881969192120168665300712204232021063124301\", \"price\":\"0.84\", \"size\":\"527.42\", \"side\":\"SELL\", \"hash\":\"0190077702b2240523b79d17556804ffb02555b0\", \"best_bid\":\"0.61\", \"best_ask\":\"0.62\"}], \"timestamp\":\"1785211591320\", \"event_type\":\"price_change\"}","received_at":"2026-07-28T04:06:31.128263Z","schema_version":"clob-market-ws.price_change.v1","sequence":null,"server_hash":null,"server_timestamp":"1785211591320","session_id":"2d607381e3054cee91998cdf45a4231c","source":"clob_market_ws"},"received_at":"2026-07-28T04:06:31.128263Z","record_id":"af7eb3613f6d47adcc4fead878dc68457903f64853ed70851b0079b7b47b71a3","schema_fingerprint":"4aa3821a28b0b7c2400bc59aba4bcc0a76e971dadd19610d3ad38c768e124dc7","schema_version":"edge-lab-recorder.raw.v1","sequence":null,"source":"clob_market_ws"}
{"event_at":"2026-07-28T04:06:31.321000Z","event_fingerprint":"796d927e12ef5e500f1ef4d8147bf306ebcd63d4d706490b6df75921a7ed2863","payload":{"connection_id":"f6725804f86a4c4eb588e4d5ed7db029","event_at":"2026-07-28T04:06:31.321000Z","event_type":"price_change","frame_hash":"ab640d99f51acede57569fcf19105febb3238f6161a995343375a448d9fa6f80","frame_index":0,"kind":"data","monotonic_ns":313574192561583,"payload":{"event_type":"price_change","market":"0xd412ce774cfcf8dc9f71164aac78783978aac7b03871702a3b8a481bd9dc9688","price_changes":[{"asset_id":"107603864457683460275633293642179940881969192120168665300712204232021063124301","best_ask":"0.62","best_bid":"0.61","hash":"eee65f16f6d34da839613d3fce92377c17045869","price":"0.01","side":"BUY","size":"5643.02"},{"asset_id":"96600821790790307414914106093858868634329285205417149685270682748367152458577","best_ask":"0.39","best_bid":"0.38","hash":"9fd2d79e42406bd8fd5035e302c9cb6b8948437d","price":"0.99","side":"SELL","size":"5643.02"}],"timestamp":"1785211591321"},"payload_hash":"bd7911b012d2fe8e427fa48c2b20cd9232f96ec041388e0d03a382449548bbe6","raw_frame":"{\"market\":\"0xd412ce774cfcf8dc9f71164aac78783978aac7b03871702a3b8a481bd9dc9688\", \"price_changes\":[{\"asset_id\":\"107603864457683460275633293642179940881969192120168665300712204232021063124301\", \"price\":\"0.01\", \"size\":\"5643.02\", \"side\":\"BUY\", \"hash\":\"eee65f16f6d34da839613d3fce92377c17045869\", \"best_bid\":\"0.61\", \"best_ask\":\"0.62\"}, {\"asset_id\":\"96600821790790307414914106093858868634329285205417149685270682748367152458577\", \"price\":\"0.99\", \"size\":\"5643.02\", \"side\":\"SELL\", \"hash\":\"9fd2d79e42406bd8fd5035e302c9cb6b8948437d\", \"best_bid\":\"0.38\", \"best_ask\":\"0.39\"}], \"timestamp\":\"1785211591321\", \"event_type\":\"price_change\"}","received_at":"2026-07-28T04:06:31.141751Z","schema_version":"clob-market-ws.price_change.v1","sequence":null,"server_hash":null,"server_timestamp":"1785211591321","session_id":"2d607381e3054cee91998cdf45a4231c","source":"clob_market_ws"},"received_at":"2026-07-28T04:06:31.141751Z","record_id":"6737890b2b14f131cc4dd3029327c2fe890deaec103246e2912aea7de07247f2","schema_fingerprint":"4aa3821a28b0b7c2400bc59aba4bcc0a76e971dadd19610d3ad38c768e124dc7","schema_version":"edge-lab-recorder.raw.v1","sequence":null,"source":"clob_market_ws"}
{"event_at":"2026-07-28T04:06:31.338000Z","event_fingerprint":"079a2c68c980d681442e62297b5506191434f1fa26971c441fecf3a231313d18","payload":{"connection_id":"f6725804f86a4c4eb588e4d5ed7db029","event_at":"2026-07-28T04:06:31.338000Z","event_type":"price_change","frame_hash":"edf480d10b30b07de91c1b65991dac4a40a6057e92cdf84b997d4c29c7c694ec","frame_index":0,"kind":"data","monotonic_ns":313574197574541,"payload":{"event_type":"price_change","market":"0xd412ce774cfcf8dc9f71164aac78783978aac7b03871702a3b8a481bd9dc9688","price_changes":[{"asset_id":"107603864457683460275633293642179940881969192120168665300712204232021063124301","best_ask":"0.62","best_bid":"0.61","hash":"85f18ac897baa32ae48c500cdcb983cf0c573b53","price":"0.03","side":"BUY","size":"623.1"},{"asset_id":"96600821790790307414914106093858868634329285205417149685270682748367152458577","best_ask":"0.39","best_bid":"0.38","hash":"b2432912badd9d0922ccb9e833f45c448dd3e297","price":"0.97","side":"SELL","size":"623.1"}],"timestamp":"1785211591338"},"payload_hash":"04be43f38f15e3d0a8b79b221f243ae541d788aa989e127de4357e7e40f6d7bd","raw_frame":"{\"market\":\"0xd412ce774cfcf8dc9f71164aac78783978aac7b03871702a3b8a481bd9dc9688\", \"price_changes\":[{\"asset_id\":\"107603864457683460275633293642179940881969192120168665300712204232021063124301\", \"price\":\"0.03\", \"size\":\"623.1\", \"side\":\"BUY\", \"hash\":\"85f18ac897baa32ae48c500cdcb983cf0c573b53\", \"best_bid\":\"0.61\", \"best_ask\":\"0.62\"}, {\"asset_id\":\"96600821790790307414914106093858868634329285205417149685270682748367152458577\", \"price\":\"0.97\", \"size\":\"623.1\", \"side\":\"SELL\", \"hash\":\"b2432912badd9d0922ccb9e833f45c448dd3e297\", \"best_bid\":\"0.38\", \"best_ask\":\"0.39\"}], \"timestamp\":\"1785211591338\", \"event_type\":\"price_change\"}","received_at":"2026-07-28T04:06:31.146764Z","schema_version":"clob-market-ws.price_change.v1","sequence":null,"server_hash":null,"server_timestamp":"1785211591338","session_id":"2d607381e3054cee91998cdf45a4231c","source":"clob_market_ws"},"received_at":"2026-07-28T04:06:31.146764Z","record_id":"43f42c3bbfa4bbbfb357e1df9c646efed742df77493442f9ced954827ea0911d","schema_fingerprint":"4aa3821a28b0b7c2400bc59aba4bcc0a76e971dadd19610d3ad38c768e124dc7","schema_version":"edge-lab-recorder.raw.v1","sequence":null,"source":"clob_market_ws"}
