{"event_at":"2026-07-28T04:04:39.293000Z","event_fingerprint":"78203b530394488fc3c4b2075bedd8f6a219e34d7d4ce4d015f1531821ba6f8e","payload":{"connection_id":"f6725804f86a4c4eb588e4d5ed7db029","event_at":"2026-07-28T04:04:39.293000Z","event_type":"price_change","frame_hash":"bcffefbcf317cca0ddbb985ffed5f9340e14f8a1c293a2dd90bc55892f55cbb1","frame_index":0,"kind":"data","monotonic_ns":313462268745958,"payload":{"event_type":"price_change","market":"0xd412ce774cfcf8dc9f71164aac78783978aac7b03871702a3b8a481bd9dc9688","price_changes":[{"asset_id":"107603864457683460275633293642179940881969192120168665300712204232021063124301","best_ask":"0.59","best_bid":"0.58","hash":"4f5d7207a1ba9b8282ed1cbd5db3d137ba414233","price":"0.58","side":"BUY","size":"56"},{"asset_id":"96600821790790307414914106093858868634329285205417149685270682748367152458577","best_ask":"0.42","best_bid":"0.41","hash":"30e7617102b981682b0834fe375b21b488795d52","price":"0.42","side":"SELL","size":"56"}],"timestamp":"1785211479293"},"payload_hash":"49d8cac02c5341c9579d09c9251048599f073450ea270da117e12ef2c2ad619c","raw_frame":"{\"market\":\"0xd412ce774cfcf8dc9f71164aac78783978aac7b03871702a3b8a481bd9dc9688\", \"price_changes\":[{\"asset_id\":\"107603864457683460275633293642179940881969192120168665300712204232021063124301\", \"price\":\"0.58\", \"size\":\"56\", \"side\":\"BUY\", \"hash\":\"4f5d7207a1ba9b8282ed1cbd5db3d137ba414233\", \"best_bid\":\"0.58\", \"best_ask\":\"0.59\"}, {\"asset_id\":\"96600821790790307414914106093858868634329285205417149685270682748367152458577\", \"price\":\"0.42\", \"size\":\"56\", \"side\":\"SELL\", \"hash\":\"30e7617102b981682b0834fe375b21b488795d52\", \"best_bid\":\"0.41\", \"best_ask\":\"0.42\"}], \"timestamp\":\"1785211479293\", \"event_type\":\"price_change\"}","received_at":"2026-07-28T04:04:39.218764Z","schema_version":"clob-market-ws.price_change.v1","sequence":null,"server_hash":null,"server_timestamp":"1785211479293","session_id":"2d607381e3054cee91998cdf45a4231c","source":"clob_market_ws"},"received_at":"2026-07-28T04:04:39.218764Z","record_id":"a35b60637e43effff369796163826449ab324ce9e4003a567a3a272cf7ee92c5","schema_fingerprint":"4aa3821a28b0b7c2400bc59aba4bcc0a76e971dadd19610d3ad38c768e124dc7","schema_version":"edge-lab-recorder.raw.v1","sequence":null,"source":"clob_market_ws"}
{"event_at":"2026-07-28T04:04:39.294000Z","event_fingerprint":"e4ae4b54706ce7d7916a8201f3365f9d3f8acccbb492fa515310caeab377745b","payload":{"connection_id":"f6725804f86a4c4eb588e4d5ed7db029","event_at":"2026-07-28T04:04:39.294000Z","event_type":"price_change","frame_hash":"f08c8e74336e0ec1908f4369c93d6515d6883e9df520a1d51bf2463c7bd792de","frame_index":0,"kind":"data","monotonic_ns":313462280600875,"payload":{"event_type":"price_change","market":"0xd412ce774cfcf8dc9f71164aac78783978aac7b03871702a3b8a481bd9dc9688","price_changes":[{"asset_id":"96600821790790307414914106093858868634329285205417149685270682748367152458577","best_ask":"0.42","best_bid":"0.41","hash":"6664d04f6e3a904b62855b43af1db58b4fb177be","price":"0.43","side":"SELL","size":"100.2"},{"asset_id":"107603864457683460275633293642179940881969192120168665300712204232021063124301","best_ask":"0.59","best_bid":"0.58","hash":"48d1cafceb5f551a59baacbf3e7164321192d9b0","price":"0.57","side":"BUY","size":"100.2"}],"timestamp":"1785211479294"},"payload_hash":"cb90f6b41ac5a65745df9111c7c8172141e9aabef475a4680a37c70459020f59","raw_frame":"{\"market\":\"0xd412ce774cfcf8dc9f71164aac78783978aac7b03871702a3b8a481bd9dc9688\", \"price_changes\":[{\"asset_id\":\"96600821790790307414914106093858868634329285205417149685270682748367152458577\", \"price\":\"0.43\", \"size\":\"100.2\", \"side\":\"SELL\", \"hash\":\"6664d04f6e3a904b62855b43af1db58b4fb177be\", \"best_bid\":\"0.41\", \"best_ask\":\"0.42\"}, {\"asset_id\":\"107603864457683460275633293642179940881969192120168665300712204232021063124301\", \"price\":\"0.57\", \"size\":\"100.2\", \"side\":\"BUY\", \"hash\":\"48d1cafceb5f551a59baacbf3e7164321192d9b0\", \"best_bid\":\"0.58\", \"best_ask\":\"0.59\"}], \"timestamp\":\"1785211479294\", \"event_type\":\"price_change\"}","received_at":"2026-07-28T04:04:39.230617Z","schema_version":"clob-market-ws.price_change.v1","sequence":null,"server_hash":null,"server_timestamp":"1785211479294","session_id":"2d607381e3054cee91998cdf45a4231c","source":"clob_market_ws"},"received_at":"2026-07-28T04:04:39.230617Z","record_id":"a3dcc5ecaa435abc49e1962371707f8ee5a3f4445bae9b7657fec581e0ca00d1","schema_fingerprint":"4aa3821a28b0b7c2400bc59aba4bcc0a76e971dadd19610d3ad38c768e124dc7","schema_version":"edge-lab-recorder.raw.v1","sequence":null,"source":"clob_market_ws"}
{"event_at":"2026-07-28T04:04:39.295000Z","event_fingerprint":"7203f7ce682b3d928b58b04e0a30f569fe5e8ae3052467fc707c6546fddf2c61","payload":{"connection_id":"f6725804f86a4c4eb588e4d5ed7db029","event_at":"2026-07-28T04:04:39.295000Z","event_type":"price_change","frame_hash":"197b2a1a5facde7f6e2468ba330192fe51f69ab9f2333ba406af5fba52386085","frame_index":0,"kind":"data","monotonic_ns":313462282298416,"payload":{"event_type":"price_change","market":"0xd412ce774cfcf8dc9f71164aac78783978aac7b03871702a3b8a481bd9dc9688","price_changes":[{"asset_id":"107603864457683460275633293642179940881969192120168665300712204232021063124301","best_ask":"0.59","best_bid":"0.58","hash":"48c2ea737908dcd0bccd223e548955ae8c68f0a5","price":"0.58","side":"BUY","size":"84"},{"asset_id":"96600821790790307414914106093858868634329285205417149685270682748367152458577","best_ask":"0.42","best_bid":"0.41","hash":"6701e202d372398e540757f965f2cf571291e5f8","price":"0.42","side":"SELL","size":"84"}],"timestamp":"1785211479295"},"payload_hash":"79b0ae90fa15bc0d47c1384aec6565bf1e479287c36bc377a95e21b8df975216","raw_frame":"{\"market\":\"0xd412ce774cfcf8dc9f71164aac78783978aac7b03871702a3b8a481bd9dc9688\", \"price_changes\":[{\"asset_id\":\"107603864457683460275633293642179940881969192120168665300712204232021063124301\", \"price\":\"0.58\", \"size\":\"84\", \"side\":\"BUY\", \"hash\":\"48c2ea737908dcd0bccd223e548955ae8c68f0a5\", \"best_bid\":\"0.58\", \"best_ask\":\"0.59\"}, {\"asset_id\":\"96600821790790307414914106093858868634329285205417149685270682748367152458577\", \"price\":\"0.42\", \"size\":\"84\", \"side\":\"SELL\", \"hash\":\"6701e202d372398e540757f965f2cf571291e5f8\", \"best_bid\":\"0.41\", \"best_ask\":\"0.42\"}], \"timestamp\":\"1785211479295\", \"event_type\":\"price_change\"}","received_at":"2026-07-28T04:04:39.232315Z","schema_version":"clob-market-ws.price_change.v1","sequence":null,"server_hash":null,"server_timestamp":"1785211479295","session_id":"2d607381e3054cee91998cdf45a4231c","source":"clob_market_ws"},"received_at":"2026-07-28T04:04:39.232315Z","record_id":"b1b9fd05454bd29cae7002545c90fb6eb01297972154a9cff0bf3aa87df3287b","schema_fingerprint":"4aa3821a28b0b7c2400bc59aba4bcc0a76e971dadd19610d3ad38c768e124dc7","schema_version":"edge-lab-recorder.raw.v1","sequence":null,"source":"clob_market_ws"}
{"event_at":"2026-07-28T04:04:39.297000Z","event_fingerprint":"fe10372bfc0bbaf1da6436cdf2db8cba402ac691ec2514581cfb86293dba56d9","payload":{"connection_id":"f6725804f86a4c4eb588e4d5ed7db029","event_at":"2026-07-28T04:04:39.297000Z","event_type":"price_change","frame_hash":"45cc089ad06586e689489120755b0fa9fff4367fee59b70626a697eaafbcfbfb","frame_index":0,"kind":"data","monotonic_ns":313462285156208,"payload":{"event_type":"price_change","market":"0xd412ce774cfcf8dc9f71164aac78783978aac7b03871702a3b8a481bd9dc9688","price_changes":[{"asset_id":"107603864457683460275633293642179940881969192120168665300712204232021063124301","best_ask":"0.59","best_bid":"0.58","hash":"2329a233a531c386de848916b85c6da934689862","price":"0.51","side":"BUY","size":"88.6"},{"asset_id":"96600821790790307414914106093858868634329285205417149685270682748367152458577","best_ask":"0.42","best_bid":"0.41","hash":"663f85a12cdcea4a1be37923450135d4dcc4aded","price":"0.49","side":"SELL","size":"88.6"}],"timestamp":"1785211479297"},"payload_hash":"9d2bd607a47ef4da38b815f2122a839a57a204c10d7feb08850cff23c70d760a","raw_frame":"{\"market\":\"0xd412ce774cfcf8dc9f71164aac78783978aac7b03871702a3b8a481bd9dc9688\", \"price_changes\":[{\"asset_id\":\"107603864457683460275633293642179940881969192120168665300712204232021063124301\", \"price\":\"0.51\", \"size\":\"88.6\", \"side\":\"BUY\", \"hash\":\"2329a233a531c386de848916b85c6da934689862\", \"best_bid\":\"0.58\", \"best_ask\":\"0.59\"}, {\"asset_id\":\"96600821790790307414914106093858868634329285205417149685270682748367152458577\", \"price\":\"0.49\", \"size\":\"88.6\", \"side\":\"SELL\", \"hash\":\"663f85a12cdcea4a1be37923450135d4dcc4aded\", \"best_bid\":\"0.41\", \"best_ask\":\"0.42\"}], \"timestamp\":\"1785211479297\", \"event_type\":\"price_change\"}","received_at":"2026-07-28T04:04:39.235175Z","schema_version":"clob-market-ws.price_change.v1","sequence":null,"server_hash":null,"server_timestamp":"1785211479297","session_id":"2d607381e3054cee91998cdf45a4231c","source":"clob_market_ws"},"received_at":"2026-07-28T04:04:39.235175Z","record_id":"d7ea3a1ba43a1e04a3238d457621855c90814d3d6dc9bd1e2ea3b6f39f2dcdf3","schema_fingerprint":"4aa3821a28b0b7c2400bc59aba4bcc0a76e971dadd19610d3ad38c768e124dc7","schema_version":"edge-lab-recorder.raw.v1","sequence":null,"source":"clob_market_ws"}
{"event_at":"2026-07-28T04:04:39.298000Z","event_fingerprint":"781136cdca69eb0cfd2334068adb8c8430a11bf86e1dd6c72603ac7dc618ac50","payload":{"connection_id":"f6725804f86a4c4eb588e4d5ed7db029","event_at":"2026-07-28T04:04:39.298000Z","event_type":"price_change","frame_hash":"d5ac3d6d65caa780ad4c01e64b4465219b68ac534a269e2b939869f790811079","frame_index":0,"kind":"data","monotonic_ns":313462286719250,"payload":{"event_type":"price_change","market":"0xd412ce774cfcf8dc9f71164aac78783978aac7b03871702a3b8a481bd9dc9688","price_changes":[{"asset_id":"107603864457683460275633293642179940881969192120168665300712204232021063124301","best_ask":"0.59","best_bid":"0.58","hash":"e736fce27b3f5ef273dede5b241612f880b4ff06","price":"0.58","side":"BUY","size":"89"},{"asset_id":"96600821790790307414914106093858868634329285205417149685270682748367152458577","best_ask":"0.42","best_bid":"0.41","hash":"75fefd073f6882776a587da4563f9a343080009d","price":"0.42","side":"SELL","size":"89"}],"timestamp":"1785211479298"},"payload_hash":"6aaba45752d620e543dc05066b823c1e2fe6c81a842d95d78d2f0bb826cfd908","raw_frame":"{\"market\":\"0xd412ce774cfcf8dc9f71164aac78783978aac7b03871702a3b8a481bd9dc9688\", \"price_changes\":[{\"asset_id\":\"107603864457683460275633293642179940881969192120168665300712204232021063124301\", \"price\":\"0.58\", \"size\":\"89\", \"side\":\"BUY\", \"hash\":\"e736fce27b3f5ef273dede5b241612f880b4ff06\", \"best_bid\":\"0.58\", \"best_ask\":\"0.59\"}, {\"asset_id\":\"96600821790790307414914106093858868634329285205417149685270682748367152458577\", \"price\":\"0.42\", \"size\":\"89\", \"side\":\"SELL\", \"hash\":\"75fefd073f6882776a587da4563f9a343080009d\", \"best_bid\":\"0.41\", \"best_ask\":\"0.42\"}], \"timestamp\":\"1785211479298\", \"event_type\":\"price_change\"}","received_at":"2026-07-28T04:04:39.236737Z","schema_version":"clob-market-ws.price_change.v1","sequence":null,"server_hash":null,"server_timestamp":"1785211479298","session_id":"2d607381e3054cee91998cdf45a4231c","source":"clob_market_ws"},"received_at":"2026-07-28T04:04:39.236737Z","record_id":"a30cc9a8dfaf871e3ce6bb7577a722b76f31d536cb4de540cec04cea2907af9e","schema_fingerprint":"4aa3821a28b0b7c2400bc59aba4bcc0a76e971dadd19610d3ad38c768e124dc7","schema_version":"edge-lab-recorder.raw.v1","sequence":null,"source":"clob_market_ws"}
{"event_at":"2026-07-28T04:04:39.298000Z","event_fingerprint":"5f65b839341fc0672ca05189be94397ca8f89e510a93cdbb754823e7a755951c","payload":{"connection_id":"f6725804f86a4c4eb588e4d5ed7db029","event_at":"2026-07-28T04:04:39.298000Z","event_type":"price_change","frame_hash":"436c0c69ecfa21d7daddb2d47d1a983ce410563bca289ac8c84a8a485df839e0","frame_index":0,"kind":"data","monotonic_ns":313462288265791,"payload":{"event_type":"price_change","market":"0xd412ce774cfcf8dc9f71164aac78783978aac7b03871702a3b8a481bd9dc9688","price_changes":[{"asset_id":"107603864457683460275633293642179940881969192120168665300712204232021063124301","best_ask":"0.59","best_bid":"0.58","hash":"07c26408bcaccfd3916c09c2780feacd4a9a021e","price":"0.5","side":"BUY","size":"134"},{"asset_id":"96600821790790307414914106093858868634329285205417149685270682748367152458577","best_ask":"0.42","best_bid":"0.41","hash":"bcb9055d94d98eb16b5d58e8c4c913c4fc621275","price":"0.5","side":"SELL","size":"134"}],"timestamp":"1785211479298"},"payload_hash":"6714cdf900c0825016ed40677c46912b66465761d138edf87601e509f8bfd7da","raw_frame":"{\"market\":\"0xd412ce774cfcf8dc9f71164aac78783978aac7b03871702a3b8a481bd9dc9688\", \"price_changes\":[{\"asset_id\":\"107603864457683460275633293642179940881969192120168665300712204232021063124301\", \"price\":\"0.5\", \"size\":\"134\", \"side\":\"BUY\", \"hash\":\"07c26408bcaccfd3916c09c2780feacd4a9a021e\", \"best_bid\":\"0.58\", \"best_ask\":\"0.59\"}, {\"asset_id\":\"96600821790790307414914106093858868634329285205417149685270682748367152458577\", \"price\":\"0.5\", \"size\":\"134\", \"side\":\"SELL\", \"hash\":\"bcb9055d94d98eb16b5d58e8c4c913c4fc621275\", \"best_bid\":\"0.41\", \"best_ask\":\"0.42\"}], \"timestamp\":\"1785211479298\", \"event_type\":\"price_change\"}","received_at":"2026-07-28T04:04:39.238284Z","schema_version":"clob-market-ws.price_change.v1","sequence":null,"server_hash":null,"server_timestamp":"1785211479298","session_id":"2d607381e3054cee91998cdf45a4231c","source":"clob_market_ws"},"received_at":"2026-07-28T04:04:39.238284Z","record_id":"8758fb4af5fe917d607caf027e7043ba09aa7c942c820e2367d26253f3d012c6","schema_fingerprint":"4aa3821a28b0b7c2400bc59aba4bcc0a76e971dadd19610d3ad38c768e124dc7","schema_version":"edge-lab-recorder.raw.v1","sequence":null,"source":"clob_market_ws"}
{"event_at":"2026-07-28T04:04:39.298000Z","event_fingerprint":"ce75f07728d889cbc1f393106862e454a5fd9df3fc88d30ef09493f10ac5f5e1","payload":{"connection_id":"f6725804f86a4c4eb588e4d5ed7db029","event_at":"2026-07-28T04:04:39.298000Z","event_type":"price_change","frame_hash":"2b0705ae14b057cac9d7ec8a2303a23be918e7d89f1da40bdbe90ae963ddbc3b","frame_index":0,"kind":"data","monotonic_ns":313462289809291,"payload":{"event_type":"price_change","market":"0xd412ce774cfcf8dc9f71164aac78783978aac7b03871702a3b8a481bd9dc9688","price_changes":[{"asset_id":"107603864457683460275633293642179940881969192120168665300712204232021063124301","best_ask":"0.59","best_bid":"0.58","hash":"8432aade5d6c77795763c1c939a1571406a2a0c7","price":"0.58","side":"BUY","size":"113"},{"asset_id":"96600821790790307414914106093858868634329285205417149685270682748367152458577","best_ask":"0.42","best_bid":"0.41","hash":"f474a01d5eba60606f7e4ff615d72761806aa0b3","price":"0.42","side":"SELL","size":"113"}],"timestamp":"1785211479298"},"payload_hash":"c94624971385216396dc80d6f1d4db86e465d134b7534e9d0fe1d20d3cd863c9","raw_frame":"{\"market\":\"0xd412ce774cfcf8dc9f71164aac78783978aac7b03871702a3b8a481bd9dc9688\", \"price_changes\":[{\"asset_id\":\"107603864457683460275633293642179940881969192120168665300712204232021063124301\", \"price\":\"0.58\", \"size\":\"113\", \"side\":\"BUY\", \"hash\":\"8432aade5d6c77795763c1c939a1571406a2a0c7\", \"best_bid\":\"0.58\", \"best_ask\":\"0.59\"}, {\"asset_id\":\"96600821790790307414914106093858868634329285205417149685270682748367152458577\", \"price\":\"0.42\", \"size\":\"113\", \"side\":\"SELL\", \"hash\":\"f474a01d5eba60606f7e4ff615d72761806aa0b3\", \"best_bid\":\"0.41\", \"best_ask\":\"0.42\"}], \"timestamp\":\"1785211479298\", \"event_type\":\"price_change\"}","received_at":"2026-07-28T04:04:39.239829Z","schema_version":"clob-market-ws.price_change.v1","sequence":null,"server_hash":null,"server_timestamp":"1785211479298","session_id":"2d607381e3054cee91998cdf45a4231c","source":"clob_market_ws"},"received_at":"2026-07-28T04:04:39.239829Z","record_id":"78e3182ba36156c1ed1d8e18ec3f0c202abd1b259cacf397dd40d1cb695b9ec3","schema_fingerprint":"4aa3821a28b0b7c2400bc59aba4bcc0a76e971dadd19610d3ad38c768e124dc7","schema_version":"edge-lab-recorder.raw.v1","sequence":null,"source":"clob_market_ws"}
{"event_at":"2026-07-28T04:04:39.299000Z","event_fingerprint":"65e0b59c2ff3f97e17e3ef0bd485d636790ee4520079fe8d1604c98eea4b51c0","payload":{"connection_id":"f6725804f86a4c4eb588e4d5ed7db029","event_at":"2026-07-28T04:04:39.299000Z","event_type":"price_change","frame_hash":"33a3eeb3d412e534d99b2fe693adf04d4f93afc997360c500a746b6d70018ac1","frame_index":0,"kind":"data","monotonic_ns":313462291285250,"payload":{"event_type":"price_change","market":"0xd412ce774cfcf8dc9f71164aac78783978aac7b03871702a3b8a481bd9dc9688","price_changes":[{"asset_id":"96600821790790307414914106093858868634329285205417149685270682748367152458577","best_ask":"0.42","best_bid":"0.41","hash":"bc8b1c1ac19e59483db3dbeb2d91f8a46ce9acdc","price":"0.37","side":"BUY","size":"160.38"},{"asset_id":"107603864457683460275633293642179940881969192120168665300712204232021063124301","best_ask":"0.59","best_bid":"0.58","hash":"f795e7ddd02275b16acfbdeb51ed5d118b4b4d5d","price":"0.63","side":"SELL","size":"160.38"}],"timestamp":"1785211479299"},"payload_hash":"c28ca559a851e6adf4e52636993b827f97ad11644421a5d51a2085f65410d34d","raw_frame":"{\"market\":\"0xd412ce774cfcf8dc9f71164aac78783978aac7b03871702a3b8a481bd9dc9688\", \"price_changes\":[{\"asset_id\":\"96600821790790307414914106093858868634329285205417149685270682748367152458577\", \"price\":\"0.37\", \"size\":\"160.38\", \"side\":\"BUY\", \"hash\":\"bc8b1c1ac19e59483db3dbeb2d91f8a46ce9acdc\", \"best_bid\":\"0.41\", \"best_ask\":\"0.42\"}, {\"asset_id\":\"107603864457683460275633293642179940881969192120168665300712204232021063124301\", \"price\":\"0.63\", \"size\":\"160.38\", \"side\":\"SELL\", \"hash\":\"f795e7ddd02275b16acfbdeb51ed5d118b4b4d5d\", \"best_bid\":\"0.58\", \"best_ask\":\"0.59\"}], \"timestamp\":\"1785211479299\", \"event_type\":\"price_change\"}","received_at":"2026-07-28T04:04:39.241304Z","schema_version":"clob-market-ws.price_change.v1","sequence":null,"server_hash":null,"server_timestamp":"1785211479299","session_id":"2d607381e3054cee91998cdf45a4231c","source":"clob_market_ws"},"received_at":"2026-07-28T04:04:39.241304Z","record_id":"1118c13588cf4f2d4bd0f85399ade22b2613ef00c392b45a264f81761f128587","schema_fingerprint":"4aa3821a28b0b7c2400bc59aba4bcc0a76e971dadd19610d3ad38c768e124dc7","schema_version":"edge-lab-recorder.raw.v1","sequence":null,"source":"clob_market_ws"}
{"event_at":"2026-07-28T04:04:39.300000Z","event_fingerprint":"7008d20b2457a2af983cdd0a8d3a168f31a7344e30e0491bc6994d84c7a1b490","payload":{"connection_id":"f6725804f86a4c4eb588e4d5ed7db029","event_at":"2026-07-28T04:04:39.300000Z","event_type":"price_change","frame_hash":"5452125c51b6d6ba8d4fd065db94de4b75421a03e76cfd1c35a1a3de8ea57ef0","frame_index":0,"kind":"data","monotonic_ns":313462292843416,"payload":{"event_type":"price_change","market":"0xd412ce774cfcf8dc9f71164aac78783978aac7b03871702a3b8a481bd9dc9688","price_changes":[{"asset_id":"96600821790790307414914106093858868634329285205417149685270682748367152458577","best_ask":"0.42","best_bid":"0.41","hash":"c18cf7975d6295c9e009ea0c0cca98b0651173b6","price":"0.37","side":"BUY","size":"170.38"},{"asset_id":"107603864457683460275633293642179940881969192120168665300712204232021063124301","best_ask":"0.59","best_bid":"0.58","hash":"1ffddeb9034185efc65f60139b0872168e1ff89d","price":"0.63","side":"SELL","size":"170.38"}],"timestamp":"1785211479300"},"payload_hash":"9e84d63b3969d0742c799f926cc9cf62c326b1d763fe4471e227639b301f7725","raw_frame":"{\"market\":\"0xd412ce774cfcf8dc9f71164aac78783978aac7b03871702a3b8a481bd9dc9688\", \"price_changes\":[{\"asset_id\":\"96600821790790307414914106093858868634329285205417149685270682748367152458577\", \"price\":\"0.37\", \"size\":\"170.38\", \"side\":\"BUY\", \"hash\":\"c18cf7975d6295c9e009ea0c0cca98b0651173b6\", \"best_bid\":\"0.41\", \"best_ask\":\"0.42\"}, {\"asset_id\":\"107603864457683460275633293642179940881969192120168665300712204232021063124301\", \"price\":\"0.63\", \"size\":\"170.38\", \"side\":\"SELL\", \"hash\":\"1ffddeb9034185efc65f60139b0872168e1ff89d\", \"best_bid\":\"0.58\", \"best_ask\":\"0.59\"}], \"timestamp\":\"1785211479300\", \"event_type\":\"price_change\"}","received_at":"2026-07-28T04:04:39.242862Z","schema_version":"clob-market-ws.price_change.v1","sequence":null,"server_hash":null,"server_timestamp":"1785211479300","session_id":"2d607381e3054cee91998cdf45a4231c","source":"clob_market_ws"},"received_at":"2026-07-28T04:04:39.242862Z","record_id":"f4a0c1e49b929df9b76abee41270c34ee2aa673c29de12b10cafd0eef33fdefc","schema_fingerprint":"4aa3821a28b0b7c2400bc59aba4bcc0a76e971dadd19610d3ad38c768e124dc7","schema_version":"edge-lab-recorder.raw.v1","sequence":null,"source":"clob_market_ws"}
{"event_at":"2026-07-28T04:04:39.301000Z","event_fingerprint":"d37ef173d7fb84c6e48ba7f37c9c487537ddd2a2ee1a6b6d817b3872ae026353","payload":{"connection_id":"f6725804f86a4c4eb588e4d5ed7db029","event_at":"2026-07-28T04:04:39.301000Z","event_type":"price_change","frame_hash":"fa090fb082352248855f27d06af4f57ca43903fb3a0d49dcdbac13042beb318f","frame_index":0,"kind":"data","monotonic_ns":313462294370458,"payload":{"event_type":"price_change","market":"0xd412ce774cfcf8dc9f71164aac78783978aac7b03871702a3b8a481bd9dc9688","price_changes":[{"asset_id":"107603864457683460275633293642179940881969192120168665300712204232021063124301","best_ask":"0.59","best_bid":"0.58","hash":"c683434e50a5ba0ff1ea0d6e331128d34f82eae0","price":"0.48","side":"BUY","size":"60"},{"asset_id":"96600821790790307414914106093858868634329285205417149685270682748367152458577","best_ask":"0.42","best_bid":"0.41","hash":"9900ff0f2d8e1dd5b79a59eaf6cb1dea2b2000da","price":"0.52","side":"SELL","size":"60"}],"timestamp":"1785211479301"},"payload_hash":"dffe7f30f387c86bd71dc093dd876760e93feafb554347a2fafe92762f62b915","raw_frame":"{\"market\":\"0xd412ce774cfcf8dc9f71164aac78783978aac7b03871702a3b8a481bd9dc9688\", \"price_changes\":[{\"asset_id\":\"107603864457683460275633293642179940881969192120168665300712204232021063124301\", \"price\":\"0.48\", \"size\":\"60\", \"side\":\"BUY\", \"hash\":\"c683434e50a5ba0ff1ea0d6e331128d34f82eae0\", \"best_bid\":\"0.58\", \"best_ask\":\"0.59\"}, {\"asset_id\":\"96600821790790307414914106093858868634329285205417149685270682748367152458577\", \"price\":\"0.52\", \"size\":\"60\", \"side\":\"SELL\", \"hash\":\"9900ff0f2d8e1dd5b79a59eaf6cb1dea2b2000da\", \"best_bid\":\"0.41\", \"best_ask\":\"0.42\"}], \"timestamp\":\"1785211479301\", \"event_type\":\"price_change\"}","received_at":"2026-07-28T04:04:39.244390Z","schema_version":"clob-market-ws.price_change.v1","sequence":null,"server_hash":null,"server_timestamp":"1785211479301","session_id":"2d607381e3054cee91998cdf45a4231c","source":"clob_market_ws"},"received_at":"2026-07-28T04:04:39.244390Z","record_id":"371057470443e173be7caa28c0802332484d49a4042012fa9e42ec9092e7b58f","schema_fingerprint":"4aa3821a28b0b7c2400bc59aba4bcc0a76e971dadd19610d3ad38c768e124dc7","schema_version":"edge-lab-recorder.raw.v1","sequence":null,"source":"clob_market_ws"}
{"event_at":"2026-07-28T04:04:39.301000Z","event_fingerprint":"2afbe02a1e0a0774a1da45d166325558c6a73db4b0a47e2ff8fb80f9d5f38273","payload":{"connection_id":"f6725804f86a4c4eb588e4d5ed7db029","event_at":"2026-07-28T04:04:39.301000Z","event_type":"price_change","frame_hash":"7eac96a528cca3e321623e6ca2ef88cf15c13083c981df051e186c35e8f8577d","frame_index":0,"kind":"data","monotonic_ns":313462295842750,"payload":{"event_type":"price_change","market":"0xd412ce774cfcf8dc9f71164aac78783978aac7b03871702a3b8a481bd9dc9688","price_changes":[{"asset_id":"107603864457683460275633293642179940881969192120168665300712204232021063124301","best_ask":"0.59","best_bid":"0.58","hash":"90dcf560fe1ac1192ef8a9ee50274a1a7e90c918","price":"0.58","side":"BUY","size":"118"},{"asset_id":"96600821790790307414914106093858868634329285205417149685270682748367152458577","best_ask":"0.42","best_bid":"0.41","hash":"235028dd7d769a7b0c71583a905c5f6dc6a41ea8","price":"0.42","side":"SELL","size":"118"}],"timestamp":"1785211479301"},"payload_hash":"2e53c37217e42e0f7b382296fb5df62ba582d9c41a27edc5f844cb2c25f567d1","raw_frame":"{\"market\":\"0xd412ce774cfcf8dc9f71164aac78783978aac7b03871702a3b8a481bd9dc9688\", \"price_changes\":[{\"asset_id\":\"107603864457683460275633293642179940881969192120168665300712204232021063124301\", \"price\":\"0.58\", \"size\":\"118\", \"side\":\"BUY\", \"hash\":\"90dcf560fe1ac1192ef8a9ee50274a1a7e90c918\", \"best_bid\":\"0.58\", \"best_ask\":\"0.59\"}, {\"asset_id\":\"96600821790790307414914106093858868634329285205417149685270682748367152458577\", \"price\":\"0.42\", \"size\":\"118\", \"side\":\"SELL\", \"hash\":\"235028dd7d769a7b0c71583a905c5f6dc6a41ea8\", \"best_bid\":\"0.41\", \"best_ask\":\"0.42\"}], \"timestamp\":\"1785211479301\", \"event_type\":\"price_change\"}","received_at":"2026-07-28T04:04:39.245862Z","schema_version":"clob-market-ws.price_change.v1","sequence":null,"server_hash":null,"server_timestamp":"1785211479301","session_id":"2d607381e3054cee91998cdf45a4231c","source":"clob_market_ws"},"received_at":"2026-07-28T04:04:39.245862Z","record_id":"58e312810c9d49194296a8afe74174b76e6255b2b30070ec9fbd8d8bd7759d59","schema_fingerprint":"4aa3821a28b0b7c2400bc59aba4bcc0a76e971dadd19610d3ad38c768e124dc7","schema_version":"edge-lab-recorder.raw.v1","sequence":null,"source":"clob_market_ws"}
{"event_at":"2026-07-28T04:04:39.303000Z","event_fingerprint":"b39d629b534cd589b607f3be879e635099c695508f672e5dcc9653fc6b1a1a6a","payload":{"connection_id":"f6725804f86a4c4eb588e4d5ed7db029","event_at":"2026-07-28T04:04:39.303000Z","event_type":"price_change","frame_hash":"9fbf3f2aa0bd26b752f3654a4bcebf75546fcf37eec3007337e5da4ae8d4783f","frame_index":0,"kind":"data","monotonic_ns":313462297334833,"payload":{"event_type":"price_change","market":"0xd412ce774cfcf8dc9f71164aac78783978aac7b03871702a3b8a481bd9dc9688","price_changes":[{"asset_id":"96600821790790307414914106093858868634329285205417149685270682748367152458577","best_ask":"0.42","best_bid":"0.41","hash":"14f8f45a6b5e2e2b07e1dabb20becdbfe37af375","price":"0.35","side":"BUY","size":"205"},{"asset_id":"107603864457683460275633293642179940881969192120168665300712204232021063124301","best_ask":"0.59","best_bid":"0.58","hash":"55fb8b75fd20265777f476ddb0af1e86bd240a99","price":"0.65","side":"SELL","size":"205"}],"timestamp":"1785211479303"},"payload_hash":"9eeda59118639283ade3b3c6fe40013deafe57ce7b03632921175b18c4626a18","raw_frame":"{\"market\":\"0xd412ce774cfcf8dc9f71164aac78783978aac7b03871702a3b8a481bd9dc9688\", \"price_changes\":[{\"asset_id\":\"96600821790790307414914106093858868634329285205417149685270682748367152458577\", \"price\":\"0.35\", \"size\":\"205\", \"side\":\"BUY\", \"hash\":\"14f8f45a6b5e2e2b07e1dabb20becdbfe37af375\", \"best_bid\":\"0.41\", \"best_ask\":\"0.42\"}, {\"asset_id\":\"107603864457683460275633293642179940881969192120168665300712204232021063124301\", \"price\":\"0.65\", \"size\":\"205\", \"side\":\"SELL\", \"hash\":\"55fb8b75fd20265777f476ddb0af1e86bd240a99\", \"best_bid\":\"0.58\", \"best_ask\":\"0.59\"}], \"timestamp\":\"1785211479303\", \"event_type\":\"price_change\"}","received_at":"2026-07-28T04:04:39.247355Z","schema_version":"clob-market-ws.price_change.v1","sequence":null,"server_hash":null,"server_timestamp":"1785211479303","session_id":"2d607381e3054cee91998cdf45a4231c","source":"clob_market_ws"},"received_at":"2026-07-28T04:04:39.247355Z","record_id":"b220bc88ae58786572f3637fe4ec264084fcc9eb8fd7281b3816da4a8b6917d0","schema_fingerprint":"4aa3821a28b0b7c2400bc59aba4bcc0a76e971dadd19610d3ad38c768e124dc7","schema_version":"edge-lab-recorder.raw.v1","sequence":null,"source":"clob_market_ws"}
{"event_at":"2026-07-28T04:04:39.303000Z","event_fingerprint":"4f27c6978b9bd7f8d77d5dfe0135fd9b6385f7bc9fe22d2487af169eaf3d27d7","payload":{"connection_id":"f6725804f86a4c4eb588e4d5ed7db029","event_at":"2026-07-28T04:04:39.303000Z","event_type":"price_change","frame_hash":"f8f552a869729e9462cfe721afccf9bc087d34e8b46b8d78c3551a29d1713732","frame_index":0,"kind":"data","monotonic_ns":313462298785458,"payload":{"event_type":"price_change","market":"0xd412ce774cfcf8dc9f71164aac78783978aac7b03871702a3b8a481bd9dc9688","price_changes":[{"asset_id":"96600821790790307414914106093858868634329285205417149685270682748367152458577","best_ask":"0.42","best_bid":"0.41","hash":"2b43ef3049241af6634f04aef1e9d44a9d15f377","price":"0.41","side":"BUY","size":"40.38"},{"asset_id":"107603864457683460275633293642179940881969192120168665300712204232021063124301","best_ask":"0.59","best_bid":"0.58","hash":"69c44cd3bc8a969bb8da4a58440699f5c8110aba","price":"0.59","side":"SELL","size":"40.38"}],"timestamp":"1785211479303"},"payload_hash":"b79aab74a0b9d170906ff05b8a28205a094333f48b6a7bbd72ea172d9716d80c","raw_frame":"{\"market\":\"0xd412ce774cfcf8dc9f71164aac78783978aac7b03871702a3b8a481bd9dc9688\", \"price_changes\":[{\"asset_id\":\"96600821790790307414914106093858868634329285205417149685270682748367152458577\", \"price\":\"0.41\", \"size\":\"40.38\", \"side\":\"BUY\", \"hash\":\"2b43ef3049241af6634f04aef1e9d44a9d15f377\", \"best_bid\":\"0.41\", \"best_ask\":\"0.42\"}, {\"asset_id\":\"107603864457683460275633293642179940881969192120168665300712204232021063124301\", \"price\":\"0.59\", \"size\":\"40.38\", \"side\":\"SELL\", \"hash\":\"69c44cd3bc8a969bb8da4a58440699f5c8110aba\", \"best_bid\":\"0.58\", \"best_ask\":\"0.59\"}], \"timestamp\":\"1785211479303\", \"event_type\":\"price_change\"}","received_at":"2026-07-28T04:04:39.248805Z","schema_version":"clob-market-ws.price_change.v1","sequence":null,"server_hash":null,"server_timestamp":"1785211479303","session_id":"2d607381e3054cee91998cdf45a4231c","source":"clob_market_ws"},"received_at":"2026-07-28T04:04:39.248805Z","record_id":"9c8326a4b24f6fd89e50e1c1b0ab66520746084b09e3fef59398a71032770fe6","schema_fingerprint":"4aa3821a28b0b7c2400bc59aba4bcc0a76e971dadd19610d3ad38c768e124dc7","schema_version":"edge-lab-recorder.raw.v1","sequence":null,"source":"clob_market_ws"}
{"event_at":"2026-07-28T04:04:39.303000Z","event_fingerprint":"b16f0e134a13c40fc40b82613d2e6bfb0ef6e3cb940c09dafb3744a9c5824dd8","payload":{"connection_id":"f6725804f86a4c4eb588e4d5ed7db029","event_at":"2026-07-28T04:04:39.303000Z","event_type":"price_change","frame_hash":"349ce4efc691de275b1717d21d7c2cb4a4b6bec7d435b56da238b6d5812b0d5f","frame_index":0,"kind":"data","monotonic_ns":313462300256625,"payload":{"event_type":"price_change","market":"0xd412ce774cfcf8dc9f71164aac78783978aac7b03871702a3b8a481bd9dc9688","price_changes":[{"asset_id":"96600821790790307414914106093858868634329285205417149685270682748367152458577","best_ask":"0.42","best_bid":"0.41","hash":"8a510701f3dcb1d48a73b7430a6e3763077f6510","price":"0.35","side":"BUY","size":"175"},{"asset_id":"107603864457683460275633293642179940881969192120168665300712204232021063124301","best_ask":"0.59","best_bid":"0.58","hash":"1be0b9a964b692a6d238935e0f0e959f2e707131","price":"0.65","side":"SELL","size":"175"}],"timestamp":"1785211479303"},"payload_hash":"5e41ebc89b6c090217aa70c4f9f92a3e6fe909fe722d2234acfc361692fe0176","raw_frame":"{\"market\":\"0xd412ce774cfcf8dc9f71164aac78783978aac7b03871702a3b8a481bd9dc9688\", \"price_changes\":[{\"asset_id\":\"96600821790790307414914106093858868634329285205417149685270682748367152458577\", \"price\":\"0.35\", \"size\":\"175\", \"side\":\"BUY\", \"hash\":\"8a510701f3dcb1d48a73b7430a6e3763077f6510\", \"best_bid\":\"0.41\", \"best_ask\":\"0.42\"}, {\"asset_id\":\"107603864457683460275633293642179940881969192120168665300712204232021063124301\", \"price\":\"0.65\", \"size\":\"175\", \"side\":\"SELL\", \"hash\":\"1be0b9a964b692a6d238935e0f0e959f2e707131\", \"best_bid\":\"0.58\", \"best_ask\":\"0.59\"}], \"timestamp\":\"1785211479303\", \"event_type\":\"price_change\"}","received_at":"2026-07-28T04:04:39.250277Z","schema_version":"clob-market-ws.price_change.v1","sequence":null,"server_hash":null,"server_timestamp":"1785211479303","session_id":"2d607381e3054cee91998cdf45a4231c","source":"clob_market_ws"},"received_at":"2026-07-28T04:04:39.250277Z","record_id":"6fa7e071a04e05b7225e455f4da10a420a28479223baac7f263e7068939af51d","schema_fingerprint":"4aa3821a28b0b7c2400bc59aba4bcc0a76e971dadd19610d3ad38c768e124dc7","schema_version":"edge-lab-recorder.raw.v1","sequence":null,"source":"clob_market_ws"}
{"event_at":"2026-07-28T04:04:39.304000Z","event_fingerprint":"9f4985a6012ba11c1e6567e2e0c71e0793df229e9d752e3c43153d8b65195329","payload":{"connection_id":"f6725804f86a4c4eb588e4d5ed7db029","event_at":"2026-07-28T04:04:39.304000Z","event_type":"price_change","frame_hash":"9e6da678f43aced68eeffff10bd2c9724ddf82b717cc7fd3ed301a63eddff6ac","frame_index":0,"kind":"data","monotonic_ns":313462301727166,"payload":{"event_type":"price_change","market":"0xd412ce774cfcf8dc9f71164aac78783978aac7b03871702a3b8a481bd9dc9688","price_changes":[{"asset_id":"107603864457683460275633293642179940881969192120168665300712204232021063124301","best_ask":"0.59","best_bid":"0.58","hash":"605c49eedec6d606723cbd5d7c354efba4de6e38","price":"0.49","side":"BUY","size":"99.63"},{"asset_id":"96600821790790307414914106093858868634329285205417149685270682748367152458577","best_ask":"0.42","best_bid":"0.41","hash":"4fef3c212ce6ca47a193815bbd28e037b75ee637","price":"0.51","side":"SELL","size":"99.63"}],"timestamp":"1785211479304"},"payload_hash":"93bfa320694db5d9e2feb9f24c71817021893d0d834dd237c6712944f280234b","raw_frame":"{\"market\":\"0xd412ce774cfcf8dc9f71164aac78783978aac7b03871702a3b8a481bd9dc9688\", \"price_changes\":[{\"asset_id\":\"107603864457683460275633293642179940881969192120168665300712204232021063124301\", \"price\":\"0.49\", \"size\":\"99.63\", \"side\":\"BUY\", \"hash\":\"605c49eedec6d606723cbd5d7c354efba4de6e38\", \"best_bid\":\"0.58\", \"best_ask\":\"0.59\"}, {\"asset_id\":\"96600821790790307414914106093858868634329285205417149685270682748367152458577\", \"price\":\"0.51\", \"size\":\"99.63\", \"side\":\"SELL\", \"hash\":\"4fef3c212ce6ca47a193815bbd28e037b75ee637\", \"best_bid\":\"0.41\", \"best_ask\":\"0.42\"}], \"timestamp\":\"1785211479304\", \"event_type\":\"price_change\"}","received_at":"2026-07-28T04:04:39.251747Z","schema_version":"clob-market-ws.price_change.v1","sequence":null,"server_hash":null,"server_timestamp":"1785211479304","session_id":"2d607381e3054cee91998cdf45a4231c","source":"clob_market_ws"},"received_at":"2026-07-28T04:04:39.251747Z","record_id":"c18f7552b2f37aa3ac2e112984265de281105cad51622c88a0784e28e8b1d4db","schema_fingerprint":"4aa3821a28b0b7c2400bc59aba4bcc0a76e971dadd19610d3ad38c768e124dc7","schema_version":"edge-lab-recorder.raw.v1","sequence":null,"source":"clob_market_ws"}
{"event_at":"2026-07-28T04:04:39.304000Z","event_fingerprint":"bf268262eede66c4552f293d216ba06801cb917a0b9c6b8d2e0c793555d24704","payload":{"connection_id":"f6725804f86a4c4eb588e4d5ed7db029","event_at":"2026-07-28T04:04:39.304000Z","event_type":"price_change","frame_hash":"221003212a21a9de669d59e66d752dada9e77ea633d921fab091c270d91c8081","frame_index":0,"kind":"data","monotonic_ns":313462303195833,"payload":{"event_type":"price_change","market":"0xd412ce774cfcf8dc9f71164aac78783978aac7b03871702a3b8a481bd9dc9688","price_changes":[{"asset_id":"107603864457683460275633293642179940881969192120168665300712204232021063124301","best_ask":"0.59","best_bid":"0.58","hash":"aca7a2b69ce3430aeeee45ff2c59a68d94023482","price":"0.5","side":"BUY","size":"149"},{"asset_id":"96600821790790307414914106093858868634329285205417149685270682748367152458577","best_ask":"0.42","best_bid":"0.41","hash":"00c17774d7486d81874f699052e5015b09780cd2","price":"0.5","side":"SELL","size":"149"}],"timestamp":"1785211479304"},"payload_hash":"4fc61b0a05d3bb29c6c88736fec48baf254871569af243ebfc50e35fe130df6b","raw_frame":"{\"market\":\"0xd412ce774cfcf8dc9f71164aac78783978aac7b03871702a3b8a481bd9dc9688\", \"price_changes\":[{\"asset_id\":\"107603864457683460275633293642179940881969192120168665300712204232021063124301\", \"price\":\"0.5\", \"size\":\"149\", \"side\":\"BUY\", \"hash\":\"aca7a2b69ce3430aeeee45ff2c59a68d94023482\", \"best_bid\":\"0.58\", \"best_ask\":\"0.59\"}, {\"asset_id\":\"96600821790790307414914106093858868634329285205417149685270682748367152458577\", \"price\":\"0.5\", \"size\":\"149\", \"side\":\"SELL\", \"hash\":\"00c17774d7486d81874f699052e5015b09780cd2\", \"best_bid\":\"0.41\", \"best_ask\":\"0.42\"}], \"timestamp\":\"1785211479304\", \"event_type\":\"price_change\"}","received_at":"2026-07-28T04:04:39.253216Z","schema_version":"clob-market-ws.price_change.v1","sequence":null,"server_hash":null,"server_timestamp":"1785211479304","session_id":"2d607381e3054cee91998cdf45a4231c","source":"clob_market_ws"},"received_at":"2026-07-28T04:04:39.253216Z","record_id":"c9f0fc53af7a3b8409479bc748ac49c5a1580fe7217839dc1b86e0c59b9bbf8d","schema_fingerprint":"4aa3821a28b0b7c2400bc59aba4bcc0a76e971dadd19610d3ad38c768e124dc7","schema_version":"edge-lab-recorder.raw.v1","sequence":null,"source":"clob_market_ws"}
{"event_at":"2026-07-28T04:04:39.305000Z","event_fingerprint":"d53b61f0603c6ea290a9faf714700bf15769c207d0a60754f1702cec3c244a69","payload":{"connection_id":"f6725804f86a4c4eb588e4d5ed7db029","event_at":"2026-07-28T04:04:39.305000Z","event_type":"price_change","frame_hash":"4982965b86d90ae093427e89739c65e1f8d65c9b781b8dae10c41314e0c6eef9","frame_index":0,"kind":"data","monotonic_ns":313462304675291,"payload":{"event_type":"price_change","market":"0xd412ce774cfcf8dc9f71164aac78783978aac7b03871702a3b8a481bd9dc9688","price_changes":[{"asset_id":"107603864457683460275633293642179940881969192120168665300712204232021063124301","best_ask":"0.59","best_bid":"0.58","hash":"3b813aedd8d679beec18382d68c6ac2f2efd99db","price":"0.51","side":"BUY","size":"75.6"},{"asset_id":"96600821790790307414914106093858868634329285205417149685270682748367152458577","best_ask":"0.42","best_bid":"0.41","hash":"0b86f3b1b4fca3982c8934c42005bf4e5e400936","price":"0.49","side":"SELL","size":"75.6"}],"timestamp":"1785211479305"},"payload_hash":"320f007392a54a608f5399874270c70d70ecf15187ce802b6fa217219f18ac28","raw_frame":"{\"market\":\"0xd412ce774cfcf8dc9f71164aac78783978aac7b03871702a3b8a481bd9dc9688\", \"price_changes\":[{\"asset_id\":\"107603864457683460275633293642179940881969192120168665300712204232021063124301\", \"price\":\"0.51\", \"size\":\"75.6\", \"side\":\"BUY\", \"hash\":\"3b813aedd8d679beec18382d68c6ac2f2efd99db\", \"best_bid\":\"0.58\", \"best_ask\":\"0.59\"}, {\"asset_id\":\"96600821790790307414914106093858868634329285205417149685270682748367152458577\", \"price\":\"0.49\", \"size\":\"75.6\", \"side\":\"SELL\", \"hash\":\"0b86f3b1b4fca3982c8934c42005bf4e5e400936\", \"best_bid\":\"0.41\", \"best_ask\":\"0.42\"}], \"timestamp\":\"1785211479305\", \"event_type\":\"price_change\"}","received_at":"2026-07-28T04:04:39.254696Z","schema_version":"clob-market-ws.price_change.v1","sequence":null,"server_hash":null,"server_timestamp":"1785211479305","session_id":"2d607381e3054cee91998cdf45a4231c","source":"clob_market_ws"},"received_at":"2026-07-28T04:04:39.254696Z","record_id":"7471aa69b39512668e152ce6f97ea528b28f5e35725cc1d6b05efda21dc4db08","schema_fingerprint":"4aa3821a28b0b7c2400bc59aba4bcc0a76e971dadd19610d3ad38c768e124dc7","schema_version":"edge-lab-recorder.raw.v1","sequence":null,"source":"clob_market_ws"}
{"event_at":"2026-07-28T04:04:39.305000Z","event_fingerprint":"3b86271eaeca2b7749e7f2007cd791e3a38f40a74f02d42201bd5abb16caa96e","payload":{"connection_id":"f6725804f86a4c4eb588e4d5ed7db029","event_at":"2026-07-28T04:04:39.305000Z","event_type":"price_change","frame_hash":"0019584b3c8080b50004aa004c60bf7f1fc930fe6fb29f4ba9ede824a1bda951","frame_index":0,"kind":"data","monotonic_ns":313462306118750,"payload":{"event_type":"price_change","market":"0xd412ce774cfcf8dc9f71164aac78783978aac7b03871702a3b8a481bd9dc9688","price_changes":[{"asset_id":"96600821790790307414914106093858868634329285205417149685270682748367152458577","best_ask":"0.42","best_bid":"0.41","hash":"8b235ba45ae36f6368feeb08e0fc5e85d014eeae","price":"0.38","side":"BUY","size":"42.98"},{"asset_id":"107603864457683460275633293642179940881969192120168665300712204232021063124301","best_ask":"0.59","best_bid":"0.58","hash":"3b2ce20c925ff9027fe42963db09c6550dbfe15f","price":"0.62","side":"SELL","size":"42.98"}],"timestamp":"1785211479305"},"payload_hash":"320f828f60c74b827c41cf7447d267b565ee977a2fffbe4ba9c79b2d429de5f5","raw_frame":"{\"market\":\"0xd412ce774cfcf8dc9f71164aac78783978aac7b03871702a3b8a481bd9dc9688\", \"price_changes\":[{\"asset_id\":\"96600821790790307414914106093858868634329285205417149685270682748367152458577\", \"price\":\"0.38\", \"size\":\"42.98\", \"side\":\"BUY\", \"hash\":\"8b235ba45ae36f6368feeb08e0fc5e85d014eeae\", \"best_bid\":\"0.41\", \"best_ask\":\"0.42\"}, {\"asset_id\":\"107603864457683460275633293642179940881969192120168665300712204232021063124301\", \"price\":\"0.62\", \"size\":\"42.98\", \"side\":\"SELL\", \"hash\":\"3b2ce20c925ff9027fe42963db09c6550dbfe15f\", \"best_bid\":\"0.58\", \"best_ask\":\"0.59\"}], \"timestamp\":\"1785211479305\", \"event_type\":\"price_change\"}","received_at":"2026-07-28T04:04:39.256139Z","schema_version":"clob-market-ws.price_change.v1","sequence":null,"server_hash":null,"server_timestamp":"1785211479305","session_id":"2d607381e3054cee91998cdf45a4231c","source":"clob_market_ws"},"received_at":"2026-07-28T04:04:39.256139Z","record_id":"8bd7e72984411c9b77de537d4e4696c10a9f9886ce0c6c666175b0fbca252d1f","schema_fingerprint":"4aa3821a28b0b7c2400bc59aba4bcc0a76e971dadd19610d3ad38c768e124dc7","schema_version":"edge-lab-recorder.raw.v1","sequence":null,"source":"clob_market_ws"}
{"event_at":"2026-07-28T04:04:39.306000Z","event_fingerprint":"e5a086f267cb2776de8db919077a2aa14320bfac63fb325f4a955b3319e0b020","payload":{"connection_id":"f6725804f86a4c4eb588e4d5ed7db029","event_at":"2026-07-28T04:04:39.306000Z","event_type":"price_change","frame_hash":"fae3109ba04ba21e0882926c6431d64e536e9b59919d22a64ee78430530cc7b9","frame_index":0,"kind":"data","monotonic_ns":313462307592125,"payload":{"event_type":"price_change","market":"0xd412ce774cfcf8dc9f71164aac78783978aac7b03871702a3b8a481bd9dc9688","price_changes":[{"asset_id":"107603864457683460275633293642179940881969192120168665300712204232021063124301","best_ask":"0.59","best_bid":"0.58","hash":"71e74753c0e720b7d5b388a23639e1413f3d2342","price":"0.51","side":"BUY","size":"69.6"},{"asset_id":"96600821790790307414914106093858868634329285205417149685270682748367152458577","best_ask":"0.42","best_bid":"0.41","hash":"39e65c556d9a8ff8fa2f135cdf242fea53e59bd3","price":"0.49","side":"SELL","size":"69.6"}],"timestamp":"1785211479306"},"payload_hash":"169ac921bcbb9ec3d545b1d970753c05b41ba594cdf434ca9039b4f083e95fb5","raw_frame":"{\"market\":\"0xd412ce774cfcf8dc9f71164aac78783978aac7b03871702a3b8a481bd9dc9688\", \"price_changes\":[{\"asset_id\":\"107603864457683460275633293642179940881969192120168665300712204232021063124301\", \"price\":\"0.51\", \"size\":\"69.6\", \"side\":\"BUY\", \"hash\":\"71e74753c0e720b7d5b388a23639e1413f3d2342\", \"best_bid\":\"0.58\", \"best_ask\":\"0.59\"}, {\"asset_id\":\"96600821790790307414914106093858868634329285205417149685270682748367152458577\", \"price\":\"0.49\", \"size\":\"69.6\", \"side\":\"SELL\", \"hash\":\"39e65c556d9a8ff8fa2f135cdf242fea53e59bd3\", \"best_bid\":\"0.41\", \"best_ask\":\"0.42\"}], \"timestamp\":\"1785211479306\", \"event_type\":\"price_change\"}","received_at":"2026-07-28T04:04:39.257612Z","schema_version":"clob-market-ws.price_change.v1","sequence":null,"server_hash":null,"server_timestamp":"1785211479306","session_id":"2d607381e3054cee91998cdf45a4231c","source":"clob_market_ws"},"received_at":"2026-07-28T04:04:39.257612Z","record_id":"586f9e6408e6fc298fcccb9dd2b5c6322785c7d065cd644f6cbb019c4e9eb4e2","schema_fingerprint":"4aa3821a28b0b7c2400bc59aba4bcc0a76e971dadd19610d3ad38c768e124dc7","schema_version":"edge-lab-recorder.raw.v1","sequence":null,"source":"clob_market_ws"}
{"event_at":"2026-07-28T04:04:39.306000Z","event_fingerprint":"3a51799852d96e546f1b6290f250ae72c0a72e3561eef6e50c5da098ebcaf2d9","payload":{"connection_id":"f6725804f86a4c4eb588e4d5ed7db029","event_at":"2026-07-28T04:04:39.306000Z","event_type":"price_change","frame_hash":"c07fc99c67a0d7d053acee3c784b22ca663da44927a48b58dfd52cff9bc1928f","frame_index":0,"kind":"data","monotonic_ns":313462309060041,"payload":{"event_type":"price_change","market":"0xd412ce774cfcf8dc9f71164aac78783978aac7b03871702a3b8a481bd9dc9688","price_changes":[{"asset_id":"107603864457683460275633293642179940881969192120168665300712204232021063124301","best_ask":"0.59","best_bid":"0.58","hash":"731bdb6e31a65093cd81b66298d315ce87c4ccb4","price":"0.46","side":"BUY","size":"96"},{"asset_id":"96600821790790307414914106093858868634329285205417149685270682748367152458577","best_ask":"0.42","best_bid":"0.41","hash":"a51cf5e7ab7e9b17ed227fa2c3b12a0d210e2c27","price":"0.54","side":"SELL","size":"96"}],"timestamp":"1785211479306"},"payload_hash":"956d78799748853b7a6783119a2de9ff006fefb21545c76bfd109884adf0b82f","raw_frame":"{\"market\":\"0xd412ce774cfcf8dc9f71164aac78783978aac7b03871702a3b8a481bd9dc9688\", \"price_changes\":[{\"asset_id\":\"107603864457683460275633293642179940881969192120168665300712204232021063124301\", \"price\":\"0.46\", \"size\":\"96\", \"side\":\"BUY\", \"hash\":\"731bdb6e31a65093cd81b66298d315ce87c4ccb4\", \"best_bid\":\"0.58\", \"best_ask\":\"0.59\"}, {\"asset_id\":\"96600821790790307414914106093858868634329285205417149685270682748367152458577\", \"price\":\"0.54\", \"size\":\"96\", \"side\":\"SELL\", \"hash\":\"a51cf5e7ab7e9b17ed227fa2c3b12a0d210e2c27\", \"best_bid\":\"0.41\", \"best_ask\":\"0.42\"}], \"timestamp\":\"1785211479306\", \"event_type\":\"price_change\"}","received_at":"2026-07-28T04:04:39.259080Z","schema_version":"clob-market-ws.price_change.v1","sequence":null,"server_hash":null,"server_timestamp":"1785211479306","session_id":"2d607381e3054cee91998cdf45a4231c","source":"clob_market_ws"},"received_at":"2026-07-28T04:04:39.259080Z","record_id":"29ddc320fba3cd98c2d901819206d4b67285ecfddaed1b45ee70a7455da65b9d","schema_fingerprint":"4aa3821a28b0b7c2400bc59aba4bcc0a76e971dadd19610d3ad38c768e124dc7","schema_version":"edge-lab-recorder.raw.v1","sequence":null,"source":"clob_market_ws"}
{"event_at":"2026-07-28T04:04:39.307000Z","event_fingerprint":"443d24e09ab0c290031e7e7d45a2048b2bc66abccb57b606794937a89101db70","payload":{"connection_id":"f6725804f86a4c4eb588e4d5ed7db029","event_at":"2026-07-28T04:04:39.307000Z","event_type":"price_change","frame_hash":"6c7b8a4751aea08a3b7ba4f8f56ac893dc1caca742e5af1a0e5e95d95b3d48d4","frame_index":0,"kind":"data","monotonic_ns":313462310529541,"payload":{"event_type":"price_change","market":"0xd412ce774cfcf8dc9f71164aac78783978aac7b03871702a3b8a481bd9dc9688","price_changes":[{"asset_id":"107603864457683460275633293642179940881969192120168665300712204232021063124301","best_ask":"0.59","best_bid":"0.58","hash":"6e314b8c6206ae553bfa7225d5e6c4892e632a78","price":"0.46","side":"BUY","size":"111"},{"asset_id":"96600821790790307414914106093858868634329285205417149685270682748367152458577","best_ask":"0.42","best_bid":"0.41","hash":"d9c88be3ec05a9dbce48a1f8f49ff2570a33a524","price":"0.54","side":"SELL","size":"111"}],"timestamp":"1785211479307"},"payload_hash":"d16dca977a2e48f4307528cb303662bc0358ba3d65c897c73eefcb82a4cd16db","raw_frame":"{\"market\":\"0xd412ce774cfcf8dc9f71164aac78783978aac7b03871702a3b8a481bd9dc9688\", \"price_changes\":[{\"asset_id\":\"107603864457683460275633293642179940881969192120168665300712204232021063124301\", \"price\":\"0.46\", \"size\":\"111\", \"side\":\"BUY\", \"hash\":\"6e314b8c6206ae553bfa7225d5e6c4892e632a78\", \"best_bid\":\"0.58\", \"best_ask\":\"0.59\"}, {\"asset_id\":\"96600821790790307414914106093858868634329285205417149685270682748367152458577\", \"price\":\"0.54\", \"size\":\"111\", \"side\":\"SELL\", \"hash\":\"d9c88be3ec05a9dbce48a1f8f49ff2570a33a524\", \"best_bid\":\"0.41\", \"best_ask\":\"0.42\"}], \"timestamp\":\"1785211479307\", \"event_type\":\"price_change\"}","received_at":"2026-07-28T04:04:39.260549Z","schema_version":"clob-market-ws.price_change.v1","sequence":null,"server_hash":null,"server_timestamp":"1785211479307","session_id":"2d607381e3054cee91998cdf45a4231c","source":"clob_market_ws"},"received_at":"2026-07-28T04:04:39.260549Z","record_id":"327ea25982910cedb50df76910ce98a49cd194297a8ed65e9935fd7677e6654d","schema_fingerprint":"4aa3821a28b0b7c2400bc59aba4bcc0a76e971dadd19610d3ad38c768e124dc7","schema_version":"edge-lab-recorder.raw.v1","sequence":null,"source":"clob_market_ws"}
{"event_at":"2026-07-28T04:04:39.308000Z","event_fingerprint":"cb18189ea384a980ad210fae04e2bf2cb663594d92525533057bb785237b0fb2","payload":{"connection_id":"f6725804f86a4c4eb588e4d5ed7db029","event_at":"2026-07-28T04:04:39.308000Z","event_type":"price_change","frame_hash":"3226323c9cd4901622743be3807ef76bfe2aec1464abcfae4e1a6350a22aaf3a","frame_index":0,"kind":"data","monotonic_ns":313462311983958,"payload":{"event_type":"price_change","market":"0xd412ce774cfcf8dc9f71164aac78783978aac7b03871702a3b8a481bd9dc9688","price_changes":[{"asset_id":"96600821790790307414914106093858868634329285205417149685270682748367152458577","best_ask":"0.42","best_bid":"0.41","hash":"ec808af363f9f3f4cdc582891de9bd88a797fa70","price":"0.35","side":"BUY","size":"145"},{"asset_id":"107603864457683460275633293642179940881969192120168665300712204232021063124301","best_ask":"0.59","best_bid":"0.58","hash":"a440130d820a05eb0d114bc044457b5d2b1d3318","price":"0.65","side":"SELL","size":"145"}],"timestamp":"1785211479308"},"payload_hash":"ab6bbc452c87813dc85faad1738a2a07485344d8c255dc8bf3e011d4b159aa21","raw_frame":"{\"market\":\"0xd412ce774cfcf8dc9f71164aac78783978aac7b03871702a3b8a481bd9dc9688\", \"price_changes\":[{\"asset_id\":\"96600821790790307414914106093858868634329285205417149685270682748367152458577\", \"price\":\"0.35\", \"size\":\"145\", \"side\":\"BUY\", \"hash\":\"ec808af363f9f3f4cdc582891de9bd88a797fa70\", \"best_bid\":\"0.41\", \"best_ask\":\"0.42\"}, {\"asset_id\":\"107603864457683460275633293642179940881969192120168665300712204232021063124301\", \"price\":\"0.65\", \"size\":\"145\", \"side\":\"SELL\", \"hash\":\"a440130d820a05eb0d114bc044457b5d2b1d3318\", \"best_bid\":\"0.58\", \"best_ask\":\"0.59\"}], \"timestamp\":\"1785211479308\", \"event_type\":\"price_change\"}","received_at":"2026-07-28T04:04:39.262004Z","schema_version":"clob-market-ws.price_change.v1","sequence":null,"server_hash":null,"server_timestamp":"1785211479308","session_id":"2d607381e3054cee91998cdf45a4231c","source":"clob_market_ws"},"received_at":"2026-07-28T04:04:39.262004Z","record_id":"9b1671f2d1d48c677a608d5037964d51200bb5a0a04ba597d83512bf26bfe904","schema_fingerprint":"4aa3821a28b0b7c2400bc59aba4bcc0a76e971dadd19610d3ad38c768e124dc7","schema_version":"edge-lab-recorder.raw.v1","sequence":null,"source":"clob_market_ws"}
{"event_at":"2026-07-28T04:04:39.308000Z","event_fingerprint":"9c6693b0121e152e87fbae1a2f5b4efacb9ae9d752215dcec8649d7808017cff","payload":{"connection_id":"f6725804f86a4c4eb588e4d5ed7db029","event_at":"2026-07-28T04:04:39.308000Z","event_type":"price_change","frame_hash":"d086cbb18f01172c53ba41d09447e439b5b331c10bc13b3e365e2eec44149e43","frame_index":0,"kind":"data","monotonic_ns":313462313456000,"payload":{"event_type":"price_change","market":"0xd412ce774cfcf8dc9f71164aac78783978aac7b03871702a3b8a481bd9dc9688","price_changes":[{"asset_id":"107603864457683460275633293642179940881969192120168665300712204232021063124301","best_ask":"0.59","best_bid":"0.58","hash":"fb6af4c22797fc39f044899a9d9742a13c0fdc4f","price":"0.04","side":"BUY","size":"673.09"},{"asset_id":"96600821790790307414914106093858868634329285205417149685270682748367152458577","best_ask":"0.42","best_bid":"0.41","hash":"bffa6bf313712a49a2fe28ee222e3029fa589908","price":"0.96","side":"SELL","size":"673.09"}],"timestamp":"1785211479308"},"payload_hash":"5b6143823c50df7b12937cd4ec9c9744385c54681854e696ac5fec49ebb61244","raw_frame":"{\"market\":\"0xd412ce774cfcf8dc9f71164aac78783978aac7b03871702a3b8a481bd9dc9688\", \"price_changes\":[{\"asset_id\":\"107603864457683460275633293642179940881969192120168665300712204232021063124301\", \"price\":\"0.04\", \"size\":\"673.09\", \"side\":\"BUY\", \"hash\":\"fb6af4c22797fc39f044899a9d9742a13c0fdc4f\", \"best_bid\":\"0.58\", \"best_ask\":\"0.59\"}, {\"asset_id\":\"96600821790790307414914106093858868634329285205417149685270682748367152458577\", \"price\":\"0.96\", \"size\":\"673.09\", \"side\":\"SELL\", \"hash\":\"bffa6bf313712a49a2fe28ee222e3029fa589908\", \"best_bid\":\"0.41\", \"best_ask\":\"0.42\"}], \"timestamp\":\"1785211479308\", \"event_type\":\"price_change\"}","received_at":"2026-07-28T04:04:39.263476Z","schema_version":"clob-market-ws.price_change.v1","sequence":null,"server_hash":null,"server_timestamp":"1785211479308","session_id":"2d607381e3054cee91998cdf45a4231c","source":"clob_market_ws"},"received_at":"2026-07-28T04:04:39.263476Z","record_id":"581a627ff131f78fa71c9a3f1d16d6aad4d05c0e5d5dac2e8a1a033fff1f253b","schema_fingerprint":"4aa3821a28b0b7c2400bc59aba4bcc0a76e971dadd19610d3ad38c768e124dc7","schema_version":"edge-lab-recorder.raw.v1","sequence":null,"source":"clob_market_ws"}
{"event_at":"2026-07-28T04:04:39.309000Z","event_fingerprint":"0a961b73ecb6c8b8634f030898c9268c4d6cae456828450b7b16477a97cf2dc3","payload":{"connection_id":"f6725804f86a4c4eb588e4d5ed7db029","event_at":"2026-07-28T04:04:39.309000Z","event_type":"price_change","frame_hash":"093fc1861717f10ad93037073ba5e1b0b2fb72922d9ab0f6069839b7823c4b26","frame_index":0,"kind":"data","monotonic_ns":313462314897000,"payload":{"event_type":"price_change","market":"0xd412ce774cfcf8dc9f71164aac78783978aac7b03871702a3b8a481bd9dc9688","price_changes":[{"asset_id":"107603864457683460275633293642179940881969192120168665300712204232021063124301","best_ask":"0.59","best_bid":"0.58","hash":"17ac77b6523f27770c98a83f0ec23b1d284a787c","price":"0.47","side":"BUY","size":"156"},{"asset_id":"96600821790790307414914106093858868634329285205417149685270682748367152458577","best_ask":"0.42","best_bid":"0.41","hash":"d6d444fff0f0d4e9e4a65d0bfb8ac336b137bdb9","price":"0.53","side":"SELL","size":"156"}],"timestamp":"1785211479309"},"payload_hash":"e6f5b5fec0a0aab03e7839ea3a740274aa246905a09c3f45f100347555f5a6eb","raw_frame":"{\"market\":\"0xd412ce774cfcf8dc9f71164aac78783978aac7b03871702a3b8a481bd9dc9688\", \"price_changes\":[{\"asset_id\":\"107603864457683460275633293642179940881969192120168665300712204232021063124301\", \"price\":\"0.47\", \"size\":\"156\", \"side\":\"BUY\", \"hash\":\"17ac77b6523f27770c98a83f0ec23b1d284a787c\", \"best_bid\":\"0.58\", \"best_ask\":\"0.59\"}, {\"asset_id\":\"96600821790790307414914106093858868634329285205417149685270682748367152458577\", \"price\":\"0.53\", \"size\":\"156\", \"side\":\"SELL\", \"hash\":\"d6d444fff0f0d4e9e4a65d0bfb8ac336b137bdb9\", \"best_bid\":\"0.41\", \"best_ask\":\"0.42\"}], \"timestamp\":\"1785211479309\", \"event_type\":\"price_change\"}","received_at":"2026-07-28T04:04:39.264917Z","schema_version":"clob-market-ws.price_change.v1","sequence":null,"server_hash":null,"server_timestamp":"1785211479309","session_id":"2d607381e3054cee91998cdf45a4231c","source":"clob_market_ws"},"received_at":"2026-07-28T04:04:39.264917Z","record_id":"27f49c7d5c183e4a69d9ca45519ed9ec7bc1183642a9d71345557020e805900a","schema_fingerprint":"4aa3821a28b0b7c2400bc59aba4bcc0a76e971dadd19610d3ad38c768e124dc7","schema_version":"edge-lab-recorder.raw.v1","sequence":null,"source":"clob_market_ws"}
{"event_at":"2026-07-28T04:04:39.310000Z","event_fingerprint":"8e0ed809cdf2f31033d1ff84f7311d8cccaadc9e9829b99dacebc88f4e5ef326","payload":{"connection_id":"f6725804f86a4c4eb588e4d5ed7db029","event_at":"2026-07-28T04:04:39.310000Z","event_type":"price_change","frame_hash":"14fe4a3e698c4ae47566e3f47fc27c1bc2d41faa7b9893e32e47afb1d09ae8d4","frame_index":0,"kind":"data","monotonic_ns":313462316362208,"payload":{"event_type":"price_change","market":"0xd412ce774cfcf8dc9f71164aac78783978aac7b03871702a3b8a481bd9dc9688","price_changes":[{"asset_id":"107603864457683460275633293642179940881969192120168665300712204232021063124301","best_ask":"0.59","best_bid":"0.58","hash":"d0b85c9fb8e6f605362660d7fbcc411e7f7d413f","price":"0.58","side":"BUY","size":"130.6"},{"asset_id":"96600821790790307414914106093858868634329285205417149685270682748367152458577","best_ask":"0.42","best_bid":"0.41","hash":"c4e6870aa07f104599db3f3d552336537e6dd0e5","price":"0.42","side":"SELL","size":"130.6"}],"timestamp":"1785211479310"},"payload_hash":"a18bf928b89bb23a3c449fd8ff8c93dbd81135e0a74d5797d9aea29da4161027","raw_frame":"{\"market\":\"0xd412ce774cfcf8dc9f71164aac78783978aac7b03871702a3b8a481bd9dc9688\", \"price_changes\":[{\"asset_id\":\"107603864457683460275633293642179940881969192120168665300712204232021063124301\", \"price\":\"0.58\", \"size\":\"130.6\", \"side\":\"BUY\", \"hash\":\"d0b85c9fb8e6f605362660d7fbcc411e7f7d413f\", \"best_bid\":\"0.58\", \"best_ask\":\"0.59\"}, {\"asset_id\":\"96600821790790307414914106093858868634329285205417149685270682748367152458577\", \"price\":\"0.42\", \"size\":\"130.6\", \"side\":\"SELL\", \"hash\":\"c4e6870aa07f104599db3f3d552336537e6dd0e5\", \"best_bid\":\"0.41\", \"best_ask\":\"0.42\"}], \"timestamp\":\"1785211479310\", \"event_type\":\"price_change\"}","received_at":"2026-07-28T04:04:39.266382Z","schema_version":"clob-market-ws.price_change.v1","sequence":null,"server_hash":null,"server_timestamp":"1785211479310","session_id":"2d607381e3054cee91998cdf45a4231c","source":"clob_market_ws"},"received_at":"2026-07-28T04:04:39.266382Z","record_id":"9a2e68f28834fd39e7b46f76c55f12113ecd828b1d8e00ec9b44f98df0b086ca","schema_fingerprint":"4aa3821a28b0b7c2400bc59aba4bcc0a76e971dadd19610d3ad38c768e124dc7","schema_version":"edge-lab-recorder.raw.v1","sequence":null,"source":"clob_market_ws"}
{"event_at":"2026-07-28T04:04:39.311000Z","event_fingerprint":"fb264f516e1399110b2b338767522a585b6c0e36291d363b28124ef8d19fa57d","payload":{"connection_id":"f6725804f86a4c4eb588e4d5ed7db029","event_at":"2026-07-28T04:04:39.311000Z","event_type":"price_change","frame_hash":"5107efc25a7b1cdb3aee691089b4e1cf3d555c33333b0d678d9cb0fe241856f4","frame_index":0,"kind":"data","monotonic_ns":313462317826166,"payload":{"event_type":"price_change","market":"0xd412ce774cfcf8dc9f71164aac78783978aac7b03871702a3b8a481bd9dc9688","price_changes":[{"asset_id":"96600821790790307414914106093858868634329285205417149685270682748367152458577","best_ask":"0.42","best_bid":"0.41","hash":"45b10a1a088c781e4d4ed05798927f4bf9e917e3","price":"0.34","side":"BUY","size":"137.38"},{"asset_id":"107603864457683460275633293642179940881969192120168665300712204232021063124301","best_ask":"0.59","best_bid":"0.58","hash":"a110161d75f31421518a3c7507f00666fe44ecfa","price":"0.66","side":"SELL","size":"137.38"}],"timestamp":"1785211479311"},"payload_hash":"6180a8b1049f9a4ef77af0942ed7348ed9e1ae4fbd071724ac5af356969dc9d0","raw_frame":"{\"market\":\"0xd412ce774cfcf8dc9f71164aac78783978aac7b03871702a3b8a481bd9dc9688\", \"price_changes\":[{\"asset_id\":\"96600821790790307414914106093858868634329285205417149685270682748367152458577\", \"price\":\"0.34\", \"size\":\"137.38\", \"side\":\"BUY\", \"hash\":\"45b10a1a088c781e4d4ed05798927f4bf9e917e3\", \"best_bid\":\"0.41\", \"best_ask\":\"0.42\"}, {\"asset_id\":\"107603864457683460275633293642179940881969192120168665300712204232021063124301\", \"price\":\"0.66\", \"size\":\"137.38\", \"side\":\"SELL\", \"hash\":\"a110161d75f31421518a3c7507f00666fe44ecfa\", \"best_bid\":\"0.58\", \"best_ask\":\"0.59\"}], \"timestamp\":\"1785211479311\", \"event_type\":\"price_change\"}","received_at":"2026-07-28T04:04:39.267846Z","schema_version":"clob-market-ws.price_change.v1","sequence":null,"server_hash":null,"server_timestamp":"1785211479311","session_id":"2d607381e3054cee91998cdf45a4231c","source":"clob_market_ws"},"received_at":"2026-07-28T04:04:39.267846Z","record_id":"2100572f830c1f9eafa7bb3a5969c7f021a8164747ad62082d35c4d9e45d530a","schema_fingerprint":"4aa3821a28b0b7c2400bc59aba4bcc0a76e971dadd19610d3ad38c768e124dc7","schema_version":"edge-lab-recorder.raw.v1","sequence":null,"source":"clob_market_ws"}
{"event_at":"2026-07-28T04:04:39.311000Z","event_fingerprint":"10d3d3d05c390a190c1c4dba2fe5825fe001f3cea9b78cab160c61f0da5e876f","payload":{"connection_id":"f6725804f86a4c4eb588e4d5ed7db029","event_at":"2026-07-28T04:04:39.311000Z","event_type":"price_change","frame_hash":"baf3317fe56b93b767dcd9ae8b93c91f54e5d31b4751e5f482d7a4dbdb1712bd","frame_index":0,"kind":"data","monotonic_ns":313462319251833,"payload":{"event_type":"price_change","market":"0xd412ce774cfcf8dc9f71164aac78783978aac7b03871702a3b8a481bd9dc9688","price_changes":[{"asset_id":"96600821790790307414914106093858868634329285205417149685270682748367152458577","best_ask":"0.42","best_bid":"0.41","hash":"546c17e71d87abd91a5745f93e9c288a543f25fa","price":"0.38","side":"BUY","size":"30.38"},{"asset_id":"107603864457683460275633293642179940881969192120168665300712204232021063124301","best_ask":"0.59","best_bid":"0.58","hash":"c257d13a63d717e5e392a0f742ea52415c61a14d","price":"0.62","side":"SELL","size":"30.38"}],"timestamp":"1785211479311"},"payload_hash":"e0b865bf31d4412407fe6c50af55e24cc87ba5ff28819c25405580d77ad659c5","raw_frame":"{\"market\":\"0xd412ce774cfcf8dc9f71164aac78783978aac7b03871702a3b8a481bd9dc9688\", \"price_changes\":[{\"asset_id\":\"96600821790790307414914106093858868634329285205417149685270682748367152458577\", \"price\":\"0.38\", \"size\":\"30.38\", \"side\":\"BUY\", \"hash\":\"546c17e71d87abd91a5745f93e9c288a543f25fa\", \"best_bid\":\"0.41\", \"best_ask\":\"0.42\"}, {\"asset_id\":\"107603864457683460275633293642179940881969192120168665300712204232021063124301\", \"price\":\"0.62\", \"size\":\"30.38\", \"side\":\"SELL\", \"hash\":\"c257d13a63d717e5e392a0f742ea52415c61a14d\", \"best_bid\":\"0.58\", \"best_ask\":\"0.59\"}], \"timestamp\":\"1785211479311\", \"event_type\":\"price_change\"}","received_at":"2026-07-28T04:04:39.269271Z","schema_version":"clob-market-ws.price_change.v1","sequence":null,"server_hash":null,"server_timestamp":"1785211479311","session_id":"2d607381e3054cee91998cdf45a4231c","source":"clob_market_ws"},"received_at":"2026-07-28T04:04:39.269271Z","record_id":"9c154189f4ce3553d7aead68df5396d12cb645a3d459e980afa7e625ae2b39ae","schema_fingerprint":"4aa3821a28b0b7c2400bc59aba4bcc0a76e971dadd19610d3ad38c768e124dc7","schema_version":"edge-lab-recorder.raw.v1","sequence":null,"source":"clob_market_ws"}
{"event_at":"2026-07-28T04:04:39.312000Z","event_fingerprint":"6934229e4a0be3652f4b70b9cfe3265e017f70336a9a9652226460a52bda0d26","payload":{"connection_id":"f6725804f86a4c4eb588e4d5ed7db029","event_at":"2026-07-28T04:04:39.312000Z","event_type":"price_change","frame_hash":"22702ca50fc12d651965f8c2307627856c293f83ef304d3e64a541694d72f7fc","frame_index":0,"kind":"data","monotonic_ns":313462320713208,"payload":{"event_type":"price_change","market":"0xd412ce774cfcf8dc9f71164aac78783978aac7b03871702a3b8a481bd9dc9688","price_changes":[{"asset_id":"107603864457683460275633293642179940881969192120168665300712204232021063124301","best_ask":"0.59","best_bid":"0.58","hash":"5926820e294ce40b5f11a3029963ca844e8f41f9","price":"0.58","side":"BUY","size":"143.2"},{"asset_id":"96600821790790307414914106093858868634329285205417149685270682748367152458577","best_ask":"0.42","best_bid":"0.41","hash":"598521c765652facd100a7725aff164406e88dac","price":"0.42","side":"SELL","size":"143.2"}],"timestamp":"1785211479312"},"payload_hash":"ccba132d1d60692dd0e4c3047aaa0ec7c01aeaee3a217bb6018995a2cac7a5ad","raw_frame":"{\"market\":\"0xd412ce774cfcf8dc9f71164aac78783978aac7b03871702a3b8a481bd9dc9688\", \"price_changes\":[{\"asset_id\":\"107603864457683460275633293642179940881969192120168665300712204232021063124301\", \"price\":\"0.58\", \"size\":\"143.2\", \"side\":\"BUY\", \"hash\":\"5926820e294ce40b5f11a3029963ca844e8f41f9\", \"best_bid\":\"0.58\", \"best_ask\":\"0.59\"}, {\"asset_id\":\"96600821790790307414914106093858868634329285205417149685270682748367152458577\", \"price\":\"0.42\", \"size\":\"143.2\", \"side\":\"SELL\", \"hash\":\"598521c765652facd100a7725aff164406e88dac\", \"best_bid\":\"0.41\", \"best_ask\":\"0.42\"}], \"timestamp\":\"1785211479312\", \"event_type\":\"price_change\"}","received_at":"2026-07-28T04:04:39.270733Z","schema_version":"clob-market-ws.price_change.v1","sequence":null,"server_hash":null,"server_timestamp":"1785211479312","session_id":"2d607381e3054cee91998cdf45a4231c","source":"clob_market_ws"},"received_at":"2026-07-28T04:04:39.270733Z","record_id":"ba656d460b62c9381c5d87bfb49ca86ae608d6fea2e3c933eb560b6f5676c0ed","schema_fingerprint":"4aa3821a28b0b7c2400bc59aba4bcc0a76e971dadd19610d3ad38c768e124dc7","schema_version":"edge-lab-recorder.raw.v1","sequence":null,"source":"clob_market_ws"}
{"event_at":"2026-07-28T04:04:39.312000Z","event_fingerprint":"715a56c2086d8bb6b6ee1d9ef81fdeed907129806a1d1f1716b746c3f97f02ff","payload":{"connection_id":"f6725804f86a4c4eb588e4d5ed7db029","event_at":"2026-07-28T04:04:39.312000Z","event_type":"price_change","frame_hash":"3cd0c1307da8e5e959b84bfe9a49d6f3edd9d2759455c3e3b4995bb5bc24ec70","frame_index":0,"kind":"data","monotonic_ns":313462322160625,"payload":{"event_type":"price_change","market":"0xd412ce774cfcf8dc9f71164aac78783978aac7b03871702a3b8a481bd9dc9688","price_changes":[{"asset_id":"96600821790790307414914106093858868634329285205417149685270682748367152458577","best_ask":"0.42","best_bid":"0.41","hash":"d75bb87cdc4c9e653fd9f2e3fbd024e37ebb50f5","price":"0.39","side":"BUY","size":"72"},{"asset_id":"107603864457683460275633293642179940881969192120168665300712204232021063124301","best_ask":"0.59","best_bid":"0.58","hash":"f3d7405d8262a5786300d8cb1318907583197fb4","price":"0.61","side":"SELL","size":"72"}],"timestamp":"1785211479312"},"payload_hash":"3a2a9e2650bad53a8bf851a6a65786fcfafaaf834e9d8f65107b21c6ddc882a8","raw_frame":"{\"market\":\"0xd412ce774cfcf8dc9f71164aac78783978aac7b03871702a3b8a481bd9dc9688\", \"price_changes\":[{\"asset_id\":\"96600821790790307414914106093858868634329285205417149685270682748367152458577\", \"price\":\"0.39\", \"size\":\"72\", \"side\":\"BUY\", \"hash\":\"d75bb87cdc4c9e653fd9f2e3fbd024e37ebb50f5\", \"best_bid\":\"0.41\", \"best_ask\":\"0.42\"}, {\"asset_id\":\"107603864457683460275633293642179940881969192120168665300712204232021063124301\", \"price\":\"0.61\", \"size\":\"72\", \"side\":\"SELL\", \"hash\":\"f3d7405d8262a5786300d8cb1318907583197fb4\", \"best_bid\":\"0.58\", \"best_ask\":\"0.59\"}], \"timestamp\":\"1785211479312\", \"event_type\":\"price_change\"}","received_at":"2026-07-28T04:04:39.272181Z","schema_version":"clob-market-ws.price_change.v1","sequence":null,"server_hash":null,"server_timestamp":"1785211479312","session_id":"2d607381e3054cee91998cdf45a4231c","source":"clob_market_ws"},"received_at":"2026-07-28T04:04:39.272181Z","record_id":"8167d199da24e5d66daf6dd71bf649ccb9e5d949e35118bf90d8b157c87a8a25","schema_fingerprint":"4aa3821a28b0b7c2400bc59aba4bcc0a76e971dadd19610d3ad38c768e124dc7","schema_version":"edge-lab-recorder.raw.v1","sequence":null,"source":"clob_market_ws"}
{"event_at":"2026-07-28T04:04:39.313000Z","event_fingerprint":"b8a54a737f90679bde44a1c28806e0f098f6e409393ad7edc86d5ffdbf833146","payload":{"connection_id":"f6725804f86a4c4eb588e4d5ed7db029","event_at":"2026-07-28T04:04:39.313000Z","event_type":"price_change","frame_hash":"22406c64ebb73c437ab6f7a472948e83bccef2f67fed78d4694e27f3560f6d27","frame_index":0,"kind":"data","monotonic_ns":313462323629166,"payload":{"event_type":"price_change","market":"0xd412ce774cfcf8dc9f71164aac78783978aac7b03871702a3b8a481bd9dc9688","price_changes":[{"asset_id":"107603864457683460275633293642179940881969192120168665300712204232021063124301","best_ask":"0.59","best_bid":"0.58","hash":"034ebe051d5b7a07570457206aa98d8fd1c63e65","price":"0.45","side":"BUY","size":"68.62"},{"asset_id":"96600821790790307414914106093858868634329285205417149685270682748367152458577","best_ask":"0.42","best_bid":"0.41","hash":"de1390f8951604b648ddcae5014377a9b79f54f8","price":"0.55","side":"SELL","size":"68.62"}],"timestamp":"1785211479313"},"payload_hash":"c49b26ff29b706b753f9877bb5da83d508008dedf78b88e32993c004f1a8e8fd","raw_frame":"{\"market\":\"0xd412ce774cfcf8dc9f71164aac78783978aac7b03871702a3b8a481bd9dc9688\", \"price_changes\":[{\"asset_id\":\"107603864457683460275633293642179940881969192120168665300712204232021063124301\", \"price\":\"0.45\", \"size\":\"68.62\", \"side\":\"BUY\", \"hash\":\"034ebe051d5b7a07570457206aa98d8fd1c63e65\", \"best_bid\":\"0.58\", \"best_ask\":\"0.59\"}, {\"asset_id\":\"96600821790790307414914106093858868634329285205417149685270682748367152458577\", \"price\":\"0.55\", \"size\":\"68.62\", \"side\":\"SELL\", \"hash\":\"de1390f8951604b648ddcae5014377a9b79f54f8\", \"best_bid\":\"0.41\", \"best_ask\":\"0.42\"}], \"timestamp\":\"1785211479313\", \"event_type\":\"price_change\"}","received_at":"2026-07-28T04:04:39.273649Z","schema_version":"clob-market-ws.price_change.v1","sequence":null,"server_hash":null,"server_timestamp":"1785211479313","session_id":"2d607381e3054cee91998cdf45a4231c","source":"clob_market_ws"},"received_at":"2026-07-28T04:04:39.273649Z","record_id":"1fb1ac9858548ee423504c135f7571bd5fd43eb0c2a74ac0799cd91a65ae6008","schema_fingerprint":"4aa3821a28b0b7c2400bc59aba4bcc0a76e971dadd19610d3ad38c768e124dc7","schema_version":"edge-lab-recorder.raw.v1","sequence":null,"source":"clob_market_ws"}
{"event_at":"2026-07-28T04:04:39.313000Z","event_fingerprint":"d204614d6351367d0ce1ba0ff1e618e7195f2d7d40e90b975c4033a8b51c44bd","payload":{"connection_id":"f6725804f86a4c4eb588e4d5ed7db029","event_at":"2026-07-28T04:04:39.313000Z","event_type":"price_change","frame_hash":"a0a02aff4b625f6988297eeccc53a35252e6354e8b52fbc09650ab4aa1d93878","frame_index":0,"kind":"data","monotonic_ns":313462325088541,"payload":{"event_type":"price_change","market":"0xd412ce774cfcf8dc9f71164aac78783978aac7b03871702a3b8a481bd9dc9688","price_changes":[{"asset_id":"107603864457683460275633293642179940881969192120168665300712204232021063124301","best_ask":"0.59","best_bid":"0.58","hash":"f1363e7baa6fe99a66b60f9b410bcf08635b924c","price":"0.58","side":"BUY","size":"121.2"},{"asset_id":"96600821790790307414914106093858868634329285205417149685270682748367152458577","best_ask":"0.42","best_bid":"0.41","hash":"e13c9342f1c2ff4b1c287c362f939b18936defc4","price":"0.42","side":"SELL","size":"121.2"}],"timestamp":"1785211479313"},"payload_hash":"99d64a5b1312d29dfe2c3ddc6beabf7dd3e13f3f0e8ada4f48f81c186160b09e","raw_frame":"{\"market\":\"0xd412ce774cfcf8dc9f71164aac78783978aac7b03871702a3b8a481bd9dc9688\", \"price_changes\":[{\"asset_id\":\"107603864457683460275633293642179940881969192120168665300712204232021063124301\", \"price\":\"0.58\", \"size\":\"121.2\", \"side\":\"BUY\", \"hash\":\"f1363e7baa6fe99a66b60f9b410bcf08635b924c\", \"best_bid\":\"0.58\", \"best_ask\":\"0.59\"}, {\"asset_id\":\"96600821790790307414914106093858868634329285205417149685270682748367152458577\", \"price\":\"0.42\", \"size\":\"121.2\", \"side\":\"SELL\", \"hash\":\"e13c9342f1c2ff4b1c287c362f939b18936defc4\", \"best_bid\":\"0.41\", \"best_ask\":\"0.42\"}], \"timestamp\":\"1785211479313\", \"event_type\":\"price_change\"}","received_at":"2026-07-28T04:04:39.275109Z","schema_version":"clob-market-ws.price_change.v1","sequence":null,"server_hash":null,"server_timestamp":"1785211479313","session_id":"2d607381e3054cee91998cdf45a4231c","source":"clob_market_ws"},"received_at":"2026-07-28T04:04:39.275109Z","record_id":"baba2465579fe686fa69c0670a70023d9b532401d4411e65d8a723d1589d37ce","schema_fingerprint":"4aa3821a28b0b7c2400bc59aba4bcc0a76e971dadd19610d3ad38c768e124dc7","schema_version":"edge-lab-recorder.raw.v1","sequence":null,"source":"clob_market_ws"}
{"event_at":"2026-07-28T04:04:39.314000Z","event_fingerprint":"4bff76e41cc6d78a2d625f3a84378c3410393888a297d7149d9549716b9bb607","payload":{"connection_id":"f6725804f86a4c4eb588e4d5ed7db029","event_at":"2026-07-28T04:04:39.314000Z","event_type":"price_change","frame_hash":"6efd6da04d60e1d1b7868f397f104384ceaf216885cdea93d64dedc96bc35e19","frame_index":0,"kind":"data","monotonic_ns":313462326531416,"payload":{"event_type":"price_change","market":"0xd412ce774cfcf8dc9f71164aac78783978aac7b03871702a3b8a481bd9dc9688","price_changes":[{"asset_id":"107603864457683460275633293642179940881969192120168665300712204232021063124301","best_ask":"0.59","best_bid":"0.58","hash":"eecad3db7637b3cb1755295e5cf0c0a38112e567","price":"0.57","side":"BUY","size":"107.7"},{"asset_id":"96600821790790307414914106093858868634329285205417149685270682748367152458577","best_ask":"0.42","best_bid":"0.41","hash":"c0f22ac848d35f4f9ab1b27d292c301689bd95e9","price":"0.43","side":"SELL","size":"107.7"}],"timestamp":"1785211479314"},"payload_hash":"dcd013bd3da531228b011d44079b018bc01486f698a297760ce2e0e45256dd89","raw_frame":"{\"market\":\"0xd412ce774cfcf8dc9f71164aac78783978aac7b03871702a3b8a481bd9dc9688\", \"price_changes\":[{\"asset_id\":\"107603864457683460275633293642179940881969192120168665300712204232021063124301\", \"price\":\"0.57\", \"size\":\"107.7\", \"side\":\"BUY\", \"hash\":\"eecad3db7637b3cb1755295e5cf0c0a38112e567\", \"best_bid\":\"0.58\", \"best_ask\":\"0.59\"}, {\"asset_id\":\"96600821790790307414914106093858868634329285205417149685270682748367152458577\", \"price\":\"0.43\", \"size\":\"107.7\", \"side\":\"SELL\", \"hash\":\"c0f22ac848d35f4f9ab1b27d292c301689bd95e9\", \"best_bid\":\"0.41\", \"best_ask\":\"0.42\"}], \"timestamp\":\"1785211479314\", \"event_type\":\"price_change\"}","received_at":"2026-07-28T04:04:39.276552Z","schema_version":"clob-market-ws.price_change.v1","sequence":null,"server_hash":null,"server_timestamp":"1785211479314","session_id":"2d607381e3054cee91998cdf45a4231c","source":"clob_market_ws"},"received_at":"2026-07-28T04:04:39.276552Z","record_id":"cc9651b30c6b519b15014522578722a3834b7f2787e33e5db0270ba2132195d0","schema_fingerprint":"4aa3821a28b0b7c2400bc59aba4bcc0a76e971dadd19610d3ad38c768e124dc7","schema_version":"edge-lab-recorder.raw.v1","sequence":null,"source":"clob_market_ws"}
{"event_at":"2026-07-28T04:04:39.314000Z","event_fingerprint":"2dae2d1ab07fdd9277afdb967184c160a1f00161c0c470435a54ee8ae8ddfc4d","payload":{"connection_id":"f6725804f86a4c4eb588e4d5ed7db029","event_at":"2026-07-28T04:04:39.314000Z","event_type":"price_change","frame_hash":"c1dd4a37e31b795eb907268f640a82ca79be20d8183b007ea67f77593afde0b8","frame_index":0,"kind":"data","monotonic_ns":313462328148291,"payload":{"event_type":"price_change","market":"0xd412ce774cfcf8dc9f71164aac78783978aac7b03871702a3b8a481bd9dc9688","price_changes":[{"asset_id":"107603864457683460275633293642179940881969192120168665300712204232021063124301","best_ask":"0.59","best_bid":"0.58","hash":"9d8547d6c5583ee9113cbedf4af527bd8a82bd5c","price":"0.51","side":"BUY","size":"57"},{"asset_id":"96600821790790307414914106093858868634329285205417149685270682748367152458577","best_ask":"0.42","best_bid":"0.41","hash":"8b933c94f34f5f76b1d4ae535ee9238965ad86a3","price":"0.49","side":"SELL","size":"57"}],"timestamp":"1785211479314"},"payload_hash":"a60c21f0fa80a92650792d3e65c01b21bdcb3c42b52678cbf5d2af341feb294c","raw_frame":"{\"market\":\"0xd412ce774cfcf8dc9f71164aac78783978aac7b03871702a3b8a481bd9dc9688\", \"price_changes\":[{\"asset_id\":\"107603864457683460275633293642179940881969192120168665300712204232021063124301\", \"price\":\"0.51\", \"size\":\"57\", \"side\":\"BUY\", \"hash\":\"9d8547d6c5583ee9113cbedf4af527bd8a82bd5c\", \"best_bid\":\"0.58\", \"best_ask\":\"0.59\"}, {\"asset_id\":\"96600821790790307414914106093858868634329285205417149685270682748367152458577\", \"price\":\"0.49\", \"size\":\"57\", \"side\":\"SELL\", \"hash\":\"8b933c94f34f5f76b1d4ae535ee9238965ad86a3\", \"best_bid\":\"0.41\", \"best_ask\":\"0.42\"}], \"timestamp\":\"1785211479314\", \"event_type\":\"price_change\"}","received_at":"2026-07-28T04:04:39.278165Z","schema_version":"clob-market-ws.price_change.v1","sequence":null,"server_hash":null,"server_timestamp":"1785211479314","session_id":"2d607381e3054cee91998cdf45a4231c","source":"clob_market_ws"},"received_at":"2026-07-28T04:04:39.278165Z","record_id":"9f1c9031faf05fabca92a3bfdb0f88f33993962471286768131a264748c200ba","schema_fingerprint":"4aa3821a28b0b7c2400bc59aba4bcc0a76e971dadd19610d3ad38c768e124dc7","schema_version":"edge-lab-recorder.raw.v1","sequence":null,"source":"clob_market_ws"}
{"event_at":"2026-07-28T04:04:39.315000Z","event_fingerprint":"2df72a8b1dc2ec18e6d32420523c85ffb491429627a0baea652f58c93fb173c5","payload":{"connection_id":"f6725804f86a4c4eb588e4d5ed7db029","event_at":"2026-07-28T04:04:39.315000Z","event_type":"price_change","frame_hash":"cb1c555425e687e5e7df9e943c87819613a0086142bb61b0ecb489c7b2cdec06","frame_index":0,"kind":"data","monotonic_ns":313462329830333,"payload":{"event_type":"price_change","market":"0xd412ce774cfcf8dc9f71164aac78783978aac7b03871702a3b8a481bd9dc9688","price_changes":[{"asset_id":"96600821790790307414914106093858868634329285205417149685270682748367152458577","best_ask":"0.42","best_bid":"0.41","hash":"7b9de9c5daf50e07b0e873e151064a4c584077dc","price":"0.36","side":"BUY","size":"165.27"},{"asset_id":"107603864457683460275633293642179940881969192120168665300712204232021063124301","best_ask":"0.59","best_bid":"0.58","hash":"3d888ddbcdcd9aeb9da77b2df8c5f188716042ad","price":"0.64","side":"SELL","size":"165.27"}],"timestamp":"1785211479315"},"payload_hash":"dff9ed6a541c0b58696216c863d5eb55c0e7823265638eaf6a6bde81956aea5f","raw_frame":"{\"market\":\"0xd412ce774cfcf8dc9f71164aac78783978aac7b03871702a3b8a481bd9dc9688\", \"price_changes\":[{\"asset_id\":\"96600821790790307414914106093858868634329285205417149685270682748367152458577\", \"price\":\"0.36\", \"size\":\"165.27\", \"side\":\"BUY\", \"hash\":\"7b9de9c5daf50e07b0e873e151064a4c584077dc\", \"best_bid\":\"0.41\", \"best_ask\":\"0.42\"}, {\"asset_id\":\"107603864457683460275633293642179940881969192120168665300712204232021063124301\", \"price\":\"0.64\", \"size\":\"165.27\", \"side\":\"SELL\", \"hash\":\"3d888ddbcdcd9aeb9da77b2df8c5f188716042ad\", \"best_bid\":\"0.58\", \"best_ask\":\"0.59\"}], \"timestamp\":\"1785211479315\", \"event_type\":\"price_change\"}","received_at":"2026-07-28T04:04:39.279848Z","schema_version":"clob-market-ws.price_change.v1","sequence":null,"server_hash":null,"server_timestamp":"1785211479315","session_id":"2d607381e3054cee91998cdf45a4231c","source":"clob_market_ws"},"received_at":"2026-07-28T04:04:39.279848Z","record_id":"c5ccdc2a612529871e0e814570ebda1478e1cb74d77fd13efcb67c00f32ced63","schema_fingerprint":"4aa3821a28b0b7c2400bc59aba4bcc0a76e971dadd19610d3ad38c768e124dc7","schema_version":"edge-lab-recorder.raw.v1","sequence":null,"source":"clob_market_ws"}
{"event_at":"2026-07-28T04:04:39.316000Z","event_fingerprint":"e5e86d6e1b98b7ec14c6aac4609d2cc270125fe5f5748e8ed84b65cf84773028","payload":{"connection_id":"f6725804f86a4c4eb588e4d5ed7db029","event_at":"2026-07-28T04:04:39.316000Z","event_type":"price_change","frame_hash":"b7bb0ff74c43916d790f8d4c4dc0560d2974242b0fe18062a3d8706e24c0f8dd","frame_index":0,"kind":"data","monotonic_ns":313462331360000,"payload":{"event_type":"price_change","market":"0xd412ce774cfcf8dc9f71164aac78783978aac7b03871702a3b8a481bd9dc9688","price_changes":[{"asset_id":"107603864457683460275633293642179940881969192120168665300712204232021063124301","best_ask":"0.59","best_bid":"0.58","hash":"7f4126b171ceba61a3b54bdddfacb46023afb711","price":"0.52","side":"BUY","size":"102.6"},{"asset_id":"96600821790790307414914106093858868634329285205417149685270682748367152458577","best_ask":"0.42","best_bid":"0.41","hash":"4f33c4cb837a0a07ca2710a6385dcbfbcbec72ce","price":"0.48","side":"SELL","size":"102.6"}],"timestamp":"1785211479316"},"payload_hash":"427f5ef6ec71f040eb458e2d74917bd120cb7a968ffe65cd4cb7f25170040e0d","raw_frame":"{\"market\":\"0xd412ce774cfcf8dc9f71164aac78783978aac7b03871702a3b8a481bd9dc9688\", \"price_changes\":[{\"asset_id\":\"107603864457683460275633293642179940881969192120168665300712204232021063124301\", \"price\":\"0.52\", \"size\":\"102.6\", \"side\":\"BUY\", \"hash\":\"7f4126b171ceba61a3b54bdddfacb46023afb711\", \"best_bid\":\"0.58\", \"best_ask\":\"0.59\"}, {\"asset_id\":\"96600821790790307414914106093858868634329285205417149685270682748367152458577\", \"price\":\"0.48\", \"size\":\"102.6\", \"side\":\"SELL\", \"hash\":\"4f33c4cb837a0a07ca2710a6385dcbfbcbec72ce\", \"best_bid\":\"0.41\", \"best_ask\":\"0.42\"}], \"timestamp\":\"1785211479316\", \"event_type\":\"price_change\"}","received_at":"2026-07-28T04:04:39.281379Z","schema_version":"clob-market-ws.price_change.v1","sequence":null,"server_hash":null,"server_timestamp":"1785211479316","session_id":"2d607381e3054cee91998cdf45a4231c","source":"clob_market_ws"},"received_at":"2026-07-28T04:04:39.281379Z","record_id":"8e33b2ad972cdf95376186ec8281eeaabffb689170b5ea8e8a4f0ded746a0c6c","schema_fingerprint":"4aa3821a28b0b7c2400bc59aba4bcc0a76e971dadd19610d3ad38c768e124dc7","schema_version":"edge-lab-recorder.raw.v1","sequence":null,"source":"clob_market_ws"}
{"event_at":"2026-07-28T04:04:39.316000Z","event_fingerprint":"68eab2755b8422faa0b235d858cc76ff5a511e19e53858b235c5749be6cd1391","payload":{"connection_id":"f6725804f86a4c4eb588e4d5ed7db029","event_at":"2026-07-28T04:04:39.316000Z","event_type":"price_change","frame_hash":"c8d3368f0d97c9c3602b82a1d0909c9bc8b9e30fc91ece5770cd7e90c3bf6a88","frame_index":0,"kind":"data","monotonic_ns":313462332952541,"payload":{"event_type":"price_change","market":"0xd412ce774cfcf8dc9f71164aac78783978aac7b03871702a3b8a481bd9dc9688","price_changes":[{"asset_id":"96600821790790307414914106093858868634329285205417149685270682748367152458577","best_ask":"0.42","best_bid":"0.41","hash":"ba8ce44cdc3df5010d22c5a52a7a5ee78ad87af2","price":"0.41","side":"BUY","size":"20.38"},{"asset_id":"107603864457683460275633293642179940881969192120168665300712204232021063124301","best_ask":"0.59","best_bid":"0.58","hash":"223268d2c5bcb0eb9d85f51ccadfa181ddb00f51","price":"0.59","side":"SELL","size":"20.38"}],"timestamp":"1785211479316"},"payload_hash":"e2faf7b62d1e5ba08c14305d5bdf3b47d6307f972fafadd4edd6476f2c38ce72","raw_frame":"{\"market\":\"0xd412ce774cfcf8dc9f71164aac78783978aac7b03871702a3b8a481bd9dc9688\", \"price_changes\":[{\"asset_id\":\"96600821790790307414914106093858868634329285205417149685270682748367152458577\", \"price\":\"0.41\", \"size\":\"20.38\", \"side\":\"BUY\", \"hash\":\"ba8ce44cdc3df5010d22c5a52a7a5ee78ad87af2\", \"best_bid\":\"0.41\", \"best_ask\":\"0.42\"}, {\"asset_id\":\"107603864457683460275633293642179940881969192120168665300712204232021063124301\", \"price\":\"0.59\", \"size\":\"20.38\", \"side\":\"SELL\", \"hash\":\"223268d2c5bcb0eb9d85f51ccadfa181ddb00f51\", \"best_bid\":\"0.58\", \"best_ask\":\"0.59\"}], \"timestamp\":\"1785211479316\", \"event_type\":\"price_change\"}","received_at":"2026-07-28T04:04:39.282971Z","schema_version":"clob-market-ws.price_change.v1","sequence":null,"server_hash":null,"server_timestamp":"1785211479316","session_id":"2d607381e3054cee91998cdf45a4231c","source":"clob_market_ws"},"received_at":"2026-07-28T04:04:39.282971Z","record_id":"e3ede46eb7d90ed71e39740a02239f3b5760aa8ef6888fcfcc1ee149fd6e5dd2","schema_fingerprint":"4aa3821a28b0b7c2400bc59aba4bcc0a76e971dadd19610d3ad38c768e124dc7","schema_version":"edge-lab-recorder.raw.v1","sequence":null,"source":"clob_market_ws"}
{"event_at":"2026-07-28T04:04:39.317000Z","event_fingerprint":"d0b5a79642a7e8e7d98b63dd6022b63e83edf3188b3986b1c792a82250f5857d","payload":{"connection_id":"f6725804f86a4c4eb588e4d5ed7db029","event_at":"2026-07-28T04:04:39.317000Z","event_type":"price_change","frame_hash":"87b9da2965c00f062041989bab04e9a7b07a6acd184ea3d11fa4579a876f7c7b","frame_index":0,"kind":"data","monotonic_ns":313462334488041,"payload":{"event_type":"price_change","market":"0xd412ce774cfcf8dc9f71164aac78783978aac7b03871702a3b8a481bd9dc9688","price_changes":[{"asset_id":"107603864457683460275633293642179940881969192120168665300712204232021063124301","best_ask":"0.59","best_bid":"0.58","hash":"d2b34d8b48481a8c49323f3638239acd3da9c88e","price":"0.53","side":"BUY","size":"95.2"},{"asset_id":"96600821790790307414914106093858868634329285205417149685270682748367152458577","best_ask":"0.42","best_bid":"0.41","hash":"ebd453cd53d6fbc213b0d972c43faea0b3c5abb2","price":"0.47","side":"SELL","size":"95.2"}],"timestamp":"1785211479317"},"payload_hash":"a218c1b408029b6f7d926cf3411665af39032f3f3a3b6a1bb5eeb446645a8d3c","raw_frame":"{\"market\":\"0xd412ce774cfcf8dc9f71164aac78783978aac7b03871702a3b8a481bd9dc9688\", \"price_changes\":[{\"asset_id\":\"107603864457683460275633293642179940881969192120168665300712204232021063124301\", \"price\":\"0.53\", \"size\":\"95.2\", \"side\":\"BUY\", \"hash\":\"d2b34d8b48481a8c49323f3638239acd3da9c88e\", \"best_bid\":\"0.58\", \"best_ask\":\"0.59\"}, {\"asset_id\":\"96600821790790307414914106093858868634329285205417149685270682748367152458577\", \"price\":\"0.47\", \"size\":\"95.2\", \"side\":\"SELL\", \"hash\":\"ebd453cd53d6fbc213b0d972c43faea0b3c5abb2\", \"best_bid\":\"0.41\", \"best_ask\":\"0.42\"}], \"timestamp\":\"1785211479317\", \"event_type\":\"price_change\"}","received_at":"2026-07-28T04:04:39.284507Z","schema_version":"clob-market-ws.price_change.v1","sequence":null,"server_hash":null,"server_timestamp":"1785211479317","session_id":"2d607381e3054cee91998cdf45a4231c","source":"clob_market_ws"},"received_at":"2026-07-28T04:04:39.284507Z","record_id":"0471b98bf6593b025c8dbbfa27a1713812b4ee8763671f1e8814d6db1fe2448a","schema_fingerprint":"4aa3821a28b0b7c2400bc59aba4bcc0a76e971dadd19610d3ad38c768e124dc7","schema_version":"edge-lab-recorder.raw.v1","sequence":null,"source":"clob_market_ws"}
{"event_at":"2026-07-28T04:04:39.317000Z","event_fingerprint":"d4933f10c9e5c9520e97d2110f96c33a1739fdac24c898072602d0d58582863b","payload":{"connection_id":"f6725804f86a4c4eb588e4d5ed7db029","event_at":"2026-07-28T04:04:39.317000Z","event_type":"price_change","frame_hash":"177f2a98961a5ce306d07098a02f272b7691d1cff61fdbe506fedd5721fdead9","frame_index":0,"kind":"data","monotonic_ns":313462336071375,"payload":{"event_type":"price_change","market":"0xd412ce774cfcf8dc9f71164aac78783978aac7b03871702a3b8a481bd9dc9688","price_changes":[{"asset_id":"96600821790790307414914106093858868634329285205417149685270682748367152458577","best_ask":"0.42","best_bid":"0.41","hash":"2d827ddc2fe9e5541bd4f810113a421dcd43d9d1","price":"0.42","side":"SELL","size":"134.2"},{"asset_id":"107603864457683460275633293642179940881969192120168665300712204232021063124301","best_ask":"0.59","best_bid":"0.58","hash":"cc7680fd0b95ca8868582e2a3b05be346bd0d7ae","price":"0.58","side":"BUY","size":"134.2"}],"timestamp":"1785211479317"},"payload_hash":"fc6ae017a10b80b0fbccb6d5e534281dcf5c5468e8556cee86f213b416c897c8","raw_frame":"{\"market\":\"0xd412ce774cfcf8dc9f71164aac78783978aac7b03871702a3b8a481bd9dc9688\", \"price_changes\":[{\"asset_id\":\"96600821790790307414914106093858868634329285205417149685270682748367152458577\", \"price\":\"0.42\", \"size\":\"134.2\", \"side\":\"SELL\", \"hash\":\"2d827ddc2fe9e5541bd4f810113a421dcd43d9d1\", \"best_bid\":\"0.41\", \"best_ask\":\"0.42\"}, {\"asset_id\":\"107603864457683460275633293642179940881969192120168665300712204232021063124301\", \"price\":\"0.58\", \"size\":\"134.2\", \"side\":\"BUY\", \"hash\":\"cc7680fd0b95ca8868582e2a3b05be346bd0d7ae\", \"best_bid\":\"0.58\", \"best_ask\":\"0.59\"}], \"timestamp\":\"1785211479317\", \"event_type\":\"price_change\"}","received_at":"2026-07-28T04:04:39.286089Z","schema_version":"clob-market-ws.price_change.v1","sequence":null,"server_hash":null,"server_timestamp":"1785211479317","session_id":"2d607381e3054cee91998cdf45a4231c","source":"clob_market_ws"},"received_at":"2026-07-28T04:04:39.286089Z","record_id":"919c32b67403dfa90cc9326dcb9f46202fd27b3309fa6b5abc073b3ab6617c63","schema_fingerprint":"4aa3821a28b0b7c2400bc59aba4bcc0a76e971dadd19610d3ad38c768e124dc7","schema_version":"edge-lab-recorder.raw.v1","sequence":null,"source":"clob_market_ws"}
{"event_at":"2026-07-28T04:04:39.318000Z","event_fingerprint":"836cd288606495345f0578621c42bfc611b15e9744bcaf177fe42e9856a7aca2","payload":{"connection_id":"f6725804f86a4c4eb588e4d5ed7db029","event_at":"2026-07-28T04:04:39.318000Z","event_type":"price_change","frame_hash":"b0de324dc6e8cf7c1e2eec3804db8dbea3facba54e2b74833f767cdec80edd03","frame_index":0,"kind":"data","monotonic_ns":313462337650708,"payload":{"event_type":"price_change","market":"0xd412ce774cfcf8dc9f71164aac78783978aac7b03871702a3b8a481bd9dc9688","price_changes":[{"asset_id":"107603864457683460275633293642179940881969192120168665300712204232021063124301","best_ask":"0.59","best_bid":"0.58","hash":"3f4932475712d992bc0802b6ff17b80ef5cabd13","price":"0.5","side":"BUY","size":"189"},{"asset_id":"96600821790790307414914106093858868634329285205417149685270682748367152458577","best_ask":"0.42","best_bid":"0.41","hash":"329e2ba9783de3aaeee96ca04a1eb3ee6321de18","price":"0.5","side":"SELL","size":"189"}],"timestamp":"1785211479318"},"payload_hash":"73069454c1463ca9e6c498b0ac3f79eafb9386e14d011f4200dca348068e12fa","raw_frame":"{\"market\":\"0xd412ce774cfcf8dc9f71164aac78783978aac7b03871702a3b8a481bd9dc9688\", \"price_changes\":[{\"asset_id\":\"107603864457683460275633293642179940881969192120168665300712204232021063124301\", \"price\":\"0.5\", \"size\":\"189\", \"side\":\"BUY\", \"hash\":\"3f4932475712d992bc0802b6ff17b80ef5cabd13\", \"best_bid\":\"0.58\", \"best_ask\":\"0.59\"}, {\"asset_id\":\"96600821790790307414914106093858868634329285205417149685270682748367152458577\", \"price\":\"0.5\", \"size\":\"189\", \"side\":\"SELL\", \"hash\":\"329e2ba9783de3aaeee96ca04a1eb3ee6321de18\", \"best_bid\":\"0.41\", \"best_ask\":\"0.42\"}], \"timestamp\":\"1785211479318\", \"event_type\":\"price_change\"}","received_at":"2026-07-28T04:04:39.287666Z","schema_version":"clob-market-ws.price_change.v1","sequence":null,"server_hash":null,"server_timestamp":"1785211479318","session_id":"2d607381e3054cee91998cdf45a4231c","source":"clob_market_ws"},"received_at":"2026-07-28T04:04:39.287666Z","record_id":"a734d9059322ff7c2fa60a5315752e8d631d51b2a60f56f7aa8d4f9f21813ad7","schema_fingerprint":"4aa3821a28b0b7c2400bc59aba4bcc0a76e971dadd19610d3ad38c768e124dc7","schema_version":"edge-lab-recorder.raw.v1","sequence":null,"source":"clob_market_ws"}
{"event_at":"2026-07-28T04:04:39.319000Z","event_fingerprint":"ba35e3862ccb5d84430c51ddfa8e0b72ec7af101c3c6af603d4abe97f2b9db72","payload":{"connection_id":"f6725804f86a4c4eb588e4d5ed7db029","event_at":"2026-07-28T04:04:39.319000Z","event_type":"price_change","frame_hash":"b8f5026ba7fc764cfc82500eb0fdd58ad12d00b4d2e72da0c708ec5259b34ff1","frame_index":0,"kind":"data","monotonic_ns":313462339292166,"payload":{"event_type":"price_change","market":"0xd412ce774cfcf8dc9f71164aac78783978aac7b03871702a3b8a481bd9dc9688","price_changes":[{"asset_id":"107603864457683460275633293642179940881969192120168665300712204232021063124301","best_ask":"0.59","best_bid":"0.58","hash":"683ddf8279d44e21bea20b83b8b795480c91287a","price":"0.54","side":"BUY","size":"94.2"},{"asset_id":"96600821790790307414914106093858868634329285205417149685270682748367152458577","best_ask":"0.42","best_bid":"0.41","hash":"d76f6340a4c1d57b792102569eeaa7c497187df9","price":"0.46","side":"SELL","size":"94.2"}],"timestamp":"1785211479319"},"payload_hash":"479224fd9131116dbf4cde009b2a1b917848139f89684eef1eba2bdbe04cb73b","raw_frame":"{\"market\":\"0xd412ce774cfcf8dc9f71164aac78783978aac7b03871702a3b8a481bd9dc9688\", \"price_changes\":[{\"asset_id\":\"107603864457683460275633293642179940881969192120168665300712204232021063124301\", \"price\":\"0.54\", \"size\":\"94.2\", \"side\":\"BUY\", \"hash\":\"683ddf8279d44e21bea20b83b8b795480c91287a\", \"best_bid\":\"0.58\", \"best_ask\":\"0.59\"}, {\"asset_id\":\"96600821790790307414914106093858868634329285205417149685270682748367152458577\", \"price\":\"0.46\", \"size\":\"94.2\", \"side\":\"SELL\", \"hash\":\"d76f6340a4c1d57b792102569eeaa7c497187df9\", \"best_bid\":\"0.41\", \"best_ask\":\"0.42\"}], \"timestamp\":\"1785211479319\", \"event_type\":\"price_change\"}","received_at":"2026-07-28T04:04:39.289310Z","schema_version":"clob-market-ws.price_change.v1","sequence":null,"server_hash":null,"server_timestamp":"1785211479319","session_id":"2d607381e3054cee91998cdf45a4231c","source":"clob_market_ws"},"received_at":"2026-07-28T04:04:39.289310Z","record_id":"e71e7586401d97c9cef46182f53d1dfaa20e4b2b03e613fd6894e4c28373681a","schema_fingerprint":"4aa3821a28b0b7c2400bc59aba4bcc0a76e971dadd19610d3ad38c768e124dc7","schema_version":"edge-lab-recorder.raw.v1","sequence":null,"source":"clob_market_ws"}
{"event_at":"2026-07-28T04:04:39.320000Z","event_fingerprint":"74958b9407ae3637b4de684e37806c60ed2ec861eda580499cce13a61d0f15e8","payload":{"connection_id":"f6725804f86a4c4eb588e4d5ed7db029","event_at":"2026-07-28T04:04:39.320000Z","event_type":"price_change","frame_hash":"32ad2c51eb7ed538cbce63dbc56b8f382c9c5cffe4c3884b86eedfd11323300e","frame_index":0,"kind":"data","monotonic_ns":313462340820500,"payload":{"event_type":"price_change","market":"0xd412ce774cfcf8dc9f71164aac78783978aac7b03871702a3b8a481bd9dc9688","price_changes":[{"asset_id":"107603864457683460275633293642179940881969192120168665300712204232021063124301","best_ask":"0.59","best_bid":"0.58","hash":"c81f68337ba5d48a2e49fb734b954d855044e955","price":"0.58","side":"BUY","size":"146.2"},{"asset_id":"96600821790790307414914106093858868634329285205417149685270682748367152458577","best_ask":"0.42","best_bid":"0.41","hash":"7ddbf0f07f3c253670d8322df3a47270341b4aa4","price":"0.42","side":"SELL","size":"146.2"}],"timestamp":"1785211479320"},"payload_hash":"bd1595648e4cc350da64628eacf21a4182a8e774d9232679db547574dbd0c5e6","raw_frame":"{\"market\":\"0xd412ce774cfcf8dc9f71164aac78783978aac7b03871702a3b8a481bd9dc9688\", \"price_changes\":[{\"asset_id\":\"107603864457683460275633293642179940881969192120168665300712204232021063124301\", \"price\":\"0.58\", \"size\":\"146.2\", \"side\":\"BUY\", \"hash\":\"c81f68337ba5d48a2e49fb734b954d855044e955\", \"best_bid\":\"0.58\", \"best_ask\":\"0.59\"}, {\"asset_id\":\"96600821790790307414914106093858868634329285205417149685270682748367152458577\", \"price\":\"0.42\", \"size\":\"146.2\", \"side\":\"SELL\", \"hash\":\"7ddbf0f07f3c253670d8322df3a47270341b4aa4\", \"best_bid\":\"0.41\", \"best_ask\":\"0.42\"}], \"timestamp\":\"1785211479320\", \"event_type\":\"price_change\"}","received_at":"2026-07-28T04:04:39.290838Z","schema_version":"clob-market-ws.price_change.v1","sequence":null,"server_hash":null,"server_timestamp":"1785211479320","session_id":"2d607381e3054cee91998cdf45a4231c","source":"clob_market_ws"},"received_at":"2026-07-28T04:04:39.290838Z","record_id":"f9605f0a3f59c246bd55996b455278798cb6056d891827bc38d81ebae1448376","schema_fingerprint":"4aa3821a28b0b7c2400bc59aba4bcc0a76e971dadd19610d3ad38c768e124dc7","schema_version":"edge-lab-recorder.raw.v1","sequence":null,"source":"clob_market_ws"}
{"event_at":"2026-07-28T04:04:39.322000Z","event_fingerprint":"4d1af379e0a7920e042d15313af65b59f8de2b7c8d44cf7523742740974afb34","payload":{"connection_id":"f6725804f86a4c4eb588e4d5ed7db029","event_at":"2026-07-28T04:04:39.322000Z","event_type":"price_change","frame_hash":"faaacfe24ee42bcaa7d47bd6f9ed1f0e6b6b8feccddaf3a98381d9b82d86a103","frame_index":0,"kind":"data","monotonic_ns":313462342379250,"payload":{"event_type":"price_change","market":"0xd412ce774cfcf8dc9f71164aac78783978aac7b03871702a3b8a481bd9dc9688","price_changes":[{"asset_id":"107603864457683460275633293642179940881969192120168665300712204232021063124301","best_ask":"0.59","best_bid":"0.58","hash":"f7c666bf9c131a4c0b6b32a18bded45b973f2248","price":"0.58","side":"BUY","size":"118.2"},{"asset_id":"96600821790790307414914106093858868634329285205417149685270682748367152458577","best_ask":"0.42","best_bid":"0.41","hash":"639560636328d8dfb50861f873533f89c966fddf","price":"0.42","side":"SELL","size":"118.2"}],"timestamp":"1785211479322"},"payload_hash":"1acc875a1946c02acc04da7a600d9bd7272124d4e16eb994df62ce84b784eaa6","raw_frame":"{\"market\":\"0xd412ce774cfcf8dc9f71164aac78783978aac7b03871702a3b8a481bd9dc9688\", \"price_changes\":[{\"asset_id\":\"107603864457683460275633293642179940881969192120168665300712204232021063124301\", \"price\":\"0.58\", \"size\":\"118.2\", \"side\":\"BUY\", \"hash\":\"f7c666bf9c131a4c0b6b32a18bded45b973f2248\", \"best_bid\":\"0.58\", \"best_ask\":\"0.59\"}, {\"asset_id\":\"96600821790790307414914106093858868634329285205417149685270682748367152458577\", \"price\":\"0.42\", \"size\":\"118.2\", \"side\":\"SELL\", \"hash\":\"639560636328d8dfb50861f873533f89c966fddf\", \"best_bid\":\"0.41\", \"best_ask\":\"0.42\"}], \"timestamp\":\"1785211479322\", \"event_type\":\"price_change\"}","received_at":"2026-07-28T04:04:39.292397Z","schema_version":"clob-market-ws.price_change.v1","sequence":null,"server_hash":null,"server_timestamp":"1785211479322","session_id":"2d607381e3054cee91998cdf45a4231c","source":"clob_market_ws"},"received_at":"2026-07-28T04:04:39.292397Z","record_id":"ae00567bfc18b6a607f8d41688f6960a7803a76de9e5cd3845c17104a9a23936","schema_fingerprint":"4aa3821a28b0b7c2400bc59aba4bcc0a76e971dadd19610d3ad38c768e124dc7","schema_version":"edge-lab-recorder.raw.v1","sequence":null,"source":"clob_market_ws"}
{"event_at":"2026-07-28T04:04:39.322000Z","event_fingerprint":"227ff81ce5c354a80443b94dc6540732c2abb7c9036502e9760ef4be36067d6e","payload":{"connection_id":"f6725804f86a4c4eb588e4d5ed7db029","event_at":"2026-07-28T04:04:39.322000Z","event_type":"price_change","frame_hash":"6fb0a62c2d996b1e139a9c22f9f9863a7a39cb19644ac6070f0c82148dcaea4b","frame_index":0,"kind":"data","monotonic_ns":313462344184916,"payload":{"event_type":"price_change","market":"0xd412ce774cfcf8dc9f71164aac78783978aac7b03871702a3b8a481bd9dc9688","price_changes":[{"asset_id":"107603864457683460275633293642179940881969192120168665300712204232021063124301","best_ask":"0.59","best_bid":"0.58","hash":"50aad81ded0ff6b7e91a098b9d12ccf79cf207c5","price":"0.58","side":"BUY","size":"90.2"},{"asset_id":"96600821790790307414914106093858868634329285205417149685270682748367152458577","best_ask":"0.42","best_bid":"0.41","hash":"74a1a8941fc65eff39072525fd3ff2b98c5fd49f","price":"0.42","side":"SELL","size":"90.2"}],"timestamp":"1785211479322"},"payload_hash":"a342c85bbbbb8c8cf10d1899b4db9f3336cd867739e86d297a1a219129ae321b","raw_frame":"{\"market\":\"0xd412ce774cfcf8dc9f71164aac78783978aac7b03871702a3b8a481bd9dc9688\", \"price_changes\":[{\"asset_id\":\"107603864457683460275633293642179940881969192120168665300712204232021063124301\", \"price\":\"0.58\", \"size\":\"90.2\", \"side\":\"BUY\", \"hash\":\"50aad81ded0ff6b7e91a098b9d12ccf79cf207c5\", \"best_bid\":\"0.58\", \"best_ask\":\"0.59\"}, {\"asset_id\":\"96600821790790307414914106093858868634329285205417149685270682748367152458577\", \"price\":\"0.42\", \"size\":\"90.2\", \"side\":\"SELL\", \"hash\":\"74a1a8941fc65eff39072525fd3ff2b98c5fd49f\", \"best_bid\":\"0.41\", \"best_ask\":\"0.42\"}], \"timestamp\":\"1785211479322\", \"event_type\":\"price_change\"}","received_at":"2026-07-28T04:04:39.294200Z","schema_version":"clob-market-ws.price_change.v1","sequence":null,"server_hash":null,"server_timestamp":"1785211479322","session_id":"2d607381e3054cee91998cdf45a4231c","source":"clob_market_ws"},"received_at":"2026-07-28T04:04:39.294200Z","record_id":"d3ade42c3ce76d45e9aec8696b5c29d6af3e62be9da857435cc13d69dd275d79","schema_fingerprint":"4aa3821a28b0b7c2400bc59aba4bcc0a76e971dadd19610d3ad38c768e124dc7","schema_version":"edge-lab-recorder.raw.v1","sequence":null,"source":"clob_market_ws"}
{"event_at":"2026-07-28T04:04:39.323000Z","event_fingerprint":"47ee1be24db02a6c42f4d5e76cc3919ed6cbb901d38ae7c8a5fffe96fa332bce","payload":{"connection_id":"f6725804f86a4c4eb588e4d5ed7db029","event_at":"2026-07-28T04:04:39.323000Z","event_type":"price_change","frame_hash":"9b19eca328947e1a351cbc0a20947873e01bf281efdc6b2215ede03265d2a756","frame_index":0,"kind":"data","monotonic_ns":313462345843125,"payload":{"event_type":"price_change","market":"0xd412ce774cfcf8dc9f71164aac78783978aac7b03871702a3b8a481bd9dc9688","price_changes":[{"asset_id":"107603864457683460275633293642179940881969192120168665300712204232021063124301","best_ask":"0.59","best_bid":"0.58","hash":"4d54023a197b34f24624063733dfce47a507bba1","price":"0.58","side":"BUY","size":"66.2"},{"asset_id":"96600821790790307414914106093858868634329285205417149685270682748367152458577","best_ask":"0.42","best_bid":"0.41","hash":"e26766c5fd18c3f37cd90861499c4125fbf6a76e","price":"0.42","side":"SELL","size":"66.2"}],"timestamp":"1785211479323"},"payload_hash":"8c755ceabb0376d28404aff81d62737c34965c6e238bf102860b087ba02e7a36","raw_frame":"{\"market\":\"0xd412ce774cfcf8dc9f71164aac78783978aac7b03871702a3b8a481bd9dc9688\", \"price_changes\":[{\"asset_id\":\"107603864457683460275633293642179940881969192120168665300712204232021063124301\", \"price\":\"0.58\", \"size\":\"66.2\", \"side\":\"BUY\", \"hash\":\"4d54023a197b34f24624063733dfce47a507bba1\", \"best_bid\":\"0.58\", \"best_ask\":\"0.59\"}, {\"asset_id\":\"96600821790790307414914106093858868634329285205417149685270682748367152458577\", \"price\":\"0.42\", \"size\":\"66.2\", \"side\":\"SELL\", \"hash\":\"e26766c5fd18c3f37cd90861499c4125fbf6a76e\", \"best_bid\":\"0.41\", \"best_ask\":\"0.42\"}], \"timestamp\":\"1785211479323\", \"event_type\":\"price_change\"}","received_at":"2026-07-28T04:04:39.295857Z","schema_version":"clob-market-ws.price_change.v1","sequence":null,"server_hash":null,"server_timestamp":"1785211479323","session_id":"2d607381e3054cee91998cdf45a4231c","source":"clob_market_ws"},"received_at":"2026-07-28T04:04:39.295857Z","record_id":"bab477a052af76677d12846541f3fa61d4957caba79d15137db6a3c4f44b2f9c","schema_fingerprint":"4aa3821a28b0b7c2400bc59aba4bcc0a76e971dadd19610d3ad38c768e124dc7","schema_version":"edge-lab-recorder.raw.v1","sequence":null,"source":"clob_market_ws"}
{"event_at":"2026-07-28T04:04:39.325000Z","event_fingerprint":"346a7dc9e37ca7cb37ba04e9e2fbe04ff373caf307543279f4c588ac1647b858","payload":{"connection_id":"f6725804f86a4c4eb588e4d5ed7db029","event_at":"2026-07-28T04:04:39.325000Z","event_type":"price_change","frame_hash":"1082614911130bc716a88bbd19a3b8a1965a7871211baa52afa924fab1bff359","frame_index":0,"kind":"data","monotonic_ns":313462347564791,"payload":{"event_type":"price_change","market":"0xd412ce774cfcf8dc9f71164aac78783978aac7b03871702a3b8a481bd9dc9688","price_changes":[{"asset_id":"107603864457683460275633293642179940881969192120168665300712204232021063124301","best_ask":"0.59","best_bid":"0.58","hash":"93c45646db119c5172ad565f2dc08dc7f1c76a96","price":"0.5","side":"BUY","size":"174"},{"asset_id":"96600821790790307414914106093858868634329285205417149685270682748367152458577","best_ask":"0.42","best_bid":"0.41","hash":"2cb04d0c485be67b4e7b0c2204fd4c549b9229dc","price":"0.5","side":"SELL","size":"174"}],"timestamp":"1785211479325"},"payload_hash":"5ad6d741cf5415b3a4e42cac25297355c83d4d8dcd1332465b7fd10424a64bea","raw_frame":"{\"market\":\"0xd412ce774cfcf8dc9f71164aac78783978aac7b03871702a3b8a481bd9dc9688\", \"price_changes\":[{\"asset_id\":\"107603864457683460275633293642179940881969192120168665300712204232021063124301\", \"price\":\"0.5\", \"size\":\"174\", \"side\":\"BUY\", \"hash\":\"93c45646db119c5172ad565f2dc08dc7f1c76a96\", \"best_bid\":\"0.58\", \"best_ask\":\"0.59\"}, {\"asset_id\":\"96600821790790307414914106093858868634329285205417149685270682748367152458577\", \"price\":\"0.5\", \"size\":\"174\", \"side\":\"SELL\", \"hash\":\"2cb04d0c485be67b4e7b0c2204fd4c549b9229dc\", \"best_bid\":\"0.41\", \"best_ask\":\"0.42\"}], \"timestamp\":\"1785211479325\", \"event_type\":\"price_change\"}","received_at":"2026-07-28T04:04:39.297583Z","schema_version":"clob-market-ws.price_change.v1","sequence":null,"server_hash":null,"server_timestamp":"1785211479325","session_id":"2d607381e3054cee91998cdf45a4231c","source":"clob_market_ws"},"received_at":"2026-07-28T04:04:39.297583Z","record_id":"78b3bca9d03d8e51f5556ad4f2cc034505872b3be788fe2473e80245c1c7a078","schema_fingerprint":"4aa3821a28b0b7c2400bc59aba4bcc0a76e971dadd19610d3ad38c768e124dc7","schema_version":"edge-lab-recorder.raw.v1","sequence":null,"source":"clob_market_ws"}
{"event_at":"2026-07-28T04:04:39.326000Z","event_fingerprint":"6216c6d1ca4989bd9741ecb9cd90fe7f4f3c740d48342b561c94089077cbc7a0","payload":{"connection_id":"f6725804f86a4c4eb588e4d5ed7db029","event_at":"2026-07-28T04:04:39.326000Z","event_type":"price_change","frame_hash":"2c42eb780bcf50c1b0ef76bcaaa8078c23c185c5bfab92b79674a3266e762a1f","frame_index":0,"kind":"data","monotonic_ns":313462349108625,"payload":{"event_type":"price_change","market":"0xd412ce774cfcf8dc9f71164aac78783978aac7b03871702a3b8a481bd9dc9688","price_changes":[{"asset_id":"96600821790790307414914106093858868634329285205417149685270682748367152458577","best_ask":"0.42","best_bid":"0.41","hash":"b5e372d3bfe9b3011d7eb855ba82548a7eab6b77","price":"0.41","side":"BUY","size":"5.38"},{"asset_id":"107603864457683460275633293642179940881969192120168665300712204232021063124301","best_ask":"0.59","best_bid":"0.58","hash":"6a01e79e61f37e268ecaa4bf5fa4c4a3b839e81f","price":"0.59","side":"SELL","size":"5.38"}],"timestamp":"1785211479326"},"payload_hash":"0faae938787d22a679e483cd9eeb0efc4b861cace2b575a6f6f1a39fc0ed73e8","raw_frame":"{\"market\":\"0xd412ce774cfcf8dc9f71164aac78783978aac7b03871702a3b8a481bd9dc9688\", \"price_changes\":[{\"asset_id\":\"96600821790790307414914106093858868634329285205417149685270682748367152458577\", \"price\":\"0.41\", \"size\":\"5.38\", \"side\":\"BUY\", \"hash\":\"b5e372d3bfe9b3011d7eb855ba82548a7eab6b77\", \"best_bid\":\"0.41\", \"best_ask\":\"0.42\"}, {\"asset_id\":\"107603864457683460275633293642179940881969192120168665300712204232021063124301\", \"price\":\"0.59\", \"size\":\"5.38\", \"side\":\"SELL\", \"hash\":\"6a01e79e61f37e268ecaa4bf5fa4c4a3b839e81f\", \"best_bid\":\"0.58\", \"best_ask\":\"0.59\"}], \"timestamp\":\"1785211479326\", \"event_type\":\"price_change\"}","received_at":"2026-07-28T04:04:39.299127Z","schema_version":"clob-market-ws.price_change.v1","sequence":null,"server_hash":null,"server_timestamp":"1785211479326","session_id":"2d607381e3054cee91998cdf45a4231c","source":"clob_market_ws"},"received_at":"2026-07-28T04:04:39.299127Z","record_id":"6cc4710c67b85918043f6506399308bdbde03aea7db0f62b9ed89a4a9d0170f8","schema_fingerprint":"4aa3821a28b0b7c2400bc59aba4bcc0a76e971dadd19610d3ad38c768e124dc7","schema_version":"edge-lab-recorder.raw.v1","sequence":null,"source":"clob_market_ws"}
{"event_at":"2026-07-28T04:04:39.328000Z","event_fingerprint":"03f58f81aaf0e456e3e329a3ac11cfb9c025912ca8be394db2fe562b0c07ae0e","payload":{"connection_id":"f6725804f86a4c4eb588e4d5ed7db029","event_at":"2026-07-28T04:04:39.328000Z","event_type":"price_change","frame_hash":"2722e4a7a29a22c3d60b189877393cc23d8f1ff9afb601eb8f1df17358550487","frame_index":0,"kind":"data","monotonic_ns":313462350610041,"payload":{"event_type":"price_change","market":"0xd412ce774cfcf8dc9f71164aac78783978aac7b03871702a3b8a481bd9dc9688","price_changes":[{"asset_id":"107603864457683460275633293642179940881969192120168665300712204232021063124301","best_ask":"0.59","best_bid":"0.58","hash":"1001ac0e4bc21edeed42860018921a02b626b648","price":"0.58","side":"BUY","size":"73.2"},{"asset_id":"96600821790790307414914106093858868634329285205417149685270682748367152458577","best_ask":"0.42","best_bid":"0.41","hash":"91200e6459e80bbfa896d5f7cb638cb991014281","price":"0.42","side":"SELL","size":"73.2"}],"timestamp":"1785211479328"},"payload_hash":"35918d37fd9ca9ed87b9bbff003b560eba61ba645e9344ceab41233cfd8b0318","raw_frame":"{\"market\":\"0xd412ce774cfcf8dc9f71164aac78783978aac7b03871702a3b8a481bd9dc9688\", \"price_changes\":[{\"asset_id\":\"107603864457683460275633293642179940881969192120168665300712204232021063124301\", \"price\":\"0.58\", \"size\":\"73.2\", \"side\":\"BUY\", \"hash\":\"1001ac0e4bc21edeed42860018921a02b626b648\", \"best_bid\":\"0.58\", \"best_ask\":\"0.59\"}, {\"asset_id\":\"96600821790790307414914106093858868634329285205417149685270682748367152458577\", \"price\":\"0.42\", \"size\":\"73.2\", \"side\":\"SELL\", \"hash\":\"91200e6459e80bbfa896d5f7cb638cb991014281\", \"best_bid\":\"0.41\", \"best_ask\":\"0.42\"}], \"timestamp\":\"1785211479328\", \"event_type\":\"price_change\"}","received_at":"2026-07-28T04:04:39.300629Z","schema_version":"clob-market-ws.price_change.v1","sequence":null,"server_hash":null,"server_timestamp":"1785211479328","session_id":"2d607381e3054cee91998cdf45a4231c","source":"clob_market_ws"},"received_at":"2026-07-28T04:04:39.300629Z","record_id":"311144208ed0be834b48aba80abad6982d5c19e05b39ca681ae2a2c23f6926ff","schema_fingerprint":"4aa3821a28b0b7c2400bc59aba4bcc0a76e971dadd19610d3ad38c768e124dc7","schema_version":"edge-lab-recorder.raw.v1","sequence":null,"source":"clob_market_ws"}
{"event_at":"2026-07-28T04:04:39.334000Z","event_fingerprint":"d6781eeba699c40cfa7ccdc334b62f7a841a4ff912a16613111f9eac2d54629d","payload":{"connection_id":"f6725804f86a4c4eb588e4d5ed7db029","event_at":"2026-07-28T04:04:39.334000Z","event_type":"price_change","frame_hash":"f7ba5b52b78e3b9334729f0640711b39cb1c6deb8547e4c837c93e23bbc0a7c5","frame_index":0,"kind":"data","monotonic_ns":313462352070625,"payload":{"event_type":"price_change","market":"0xd412ce774cfcf8dc9f71164aac78783978aac7b03871702a3b8a481bd9dc9688","price_changes":[{"asset_id":"96600821790790307414914106093858868634329285205417149685270682748367152458577","best_ask":"0.42","best_bid":"0.41","hash":"37ab251e2e9752343285801ba936cf25b37ab268","price":"0.24","side":"BUY","size":"192.27"},{"asset_id":"107603864457683460275633293642179940881969192120168665300712204232021063124301","best_ask":"0.59","best_bid":"0.58","hash":"76313d8cd44bfbe1788418d016558cf27fe97a32","price":"0.76","side":"SELL","size":"192.27"}],"timestamp":"1785211479334"},"payload_hash":"a52e5b83e1b52dd6c2aaa8e5d92b52c1ba390d3f7b2b30667f147dd22bd78cb1","raw_frame":"{\"market\":\"0xd412ce774cfcf8dc9f71164aac78783978aac7b03871702a3b8a481bd9dc9688\", \"price_changes\":[{\"asset_id\":\"96600821790790307414914106093858868634329285205417149685270682748367152458577\", \"price\":\"0.24\", \"size\":\"192.27\", \"side\":\"BUY\", \"hash\":\"37ab251e2e9752343285801ba936cf25b37ab268\", \"best_bid\":\"0.41\", \"best_ask\":\"0.42\"}, {\"asset_id\":\"107603864457683460275633293642179940881969192120168665300712204232021063124301\", \"price\":\"0.76\", \"size\":\"192.27\", \"side\":\"SELL\", \"hash\":\"76313d8cd44bfbe1788418d016558cf27fe97a32\", \"best_bid\":\"0.58\", \"best_ask\":\"0.59\"}], \"timestamp\":\"1785211479334\", \"event_type\":\"price_change\"}","received_at":"2026-07-28T04:04:39.302090Z","schema_version":"clob-market-ws.price_change.v1","sequence":null,"server_hash":null,"server_timestamp":"1785211479334","session_id":"2d607381e3054cee91998cdf45a4231c","source":"clob_market_ws"},"received_at":"2026-07-28T04:04:39.302090Z","record_id":"e23cfe4f1203e86f64073ae9f2d7a3f63f28ec752290fda3ce543f524a4866c0","schema_fingerprint":"4aa3821a28b0b7c2400bc59aba4bcc0a76e971dadd19610d3ad38c768e124dc7","schema_version":"edge-lab-recorder.raw.v1","sequence":null,"source":"clob_market_ws"}
{"event_at":"2026-07-28T04:04:39.335000Z","event_fingerprint":"3cd0999db7721383bf429059ea891557554a33bd796db5b88c4ce78364392cee","payload":{"connection_id":"f6725804f86a4c4eb588e4d5ed7db029","event_at":"2026-07-28T04:04:39.335000Z","event_type":"price_change","frame_hash":"3dd86498ccfe3d6643bbb431beab65d19d9e3058849e9d54ba5f59cbde8097f9","frame_index":0,"kind":"data","monotonic_ns":313462353546375,"payload":{"event_type":"price_change","market":"0xd412ce774cfcf8dc9f71164aac78783978aac7b03871702a3b8a481bd9dc9688","price_changes":[{"asset_id":"107603864457683460275633293642179940881969192120168665300712204232021063124301","best_ask":"0.59","best_bid":"0.58","hash":"d68816538cadaf2662dc7deb7cb1768a0dee71b5","price":"0.34","side":"BUY","size":"147.43"},{"asset_id":"96600821790790307414914106093858868634329285205417149685270682748367152458577","best_ask":"0.42","best_bid":"0.41","hash":"909fbc6824bb5865dd0f05b88ccf361c6f0bf95c","price":"0.66","side":"SELL","size":"147.43"}],"timestamp":"1785211479335"},"payload_hash":"0728e28a5d0f11b9b424b33899eb918b6659f29570ace38adabd2deaae8f5a9c","raw_frame":"{\"market\":\"0xd412ce774cfcf8dc9f71164aac78783978aac7b03871702a3b8a481bd9dc9688\", \"price_changes\":[{\"asset_id\":\"107603864457683460275633293642179940881969192120168665300712204232021063124301\", \"price\":\"0.34\", \"size\":\"147.43\", \"side\":\"BUY\", \"hash\":\"d68816538cadaf2662dc7deb7cb1768a0dee71b5\", \"best_bid\":\"0.58\", \"best_ask\":\"0.59\"}, {\"asset_id\":\"96600821790790307414914106093858868634329285205417149685270682748367152458577\", \"price\":\"0.66\", \"size\":\"147.43\", \"side\":\"SELL\", \"hash\":\"909fbc6824bb5865dd0f05b88ccf361c6f0bf95c\", \"best_bid\":\"0.41\", \"best_ask\":\"0.42\"}], \"timestamp\":\"1785211479335\", \"event_type\":\"price_change\"}","received_at":"2026-07-28T04:04:39.303566Z","schema_version":"clob-market-ws.price_change.v1","sequence":null,"server_hash":null,"server_timestamp":"1785211479335","session_id":"2d607381e3054cee91998cdf45a4231c","source":"clob_market_ws"},"received_at":"2026-07-28T04:04:39.303566Z","record_id":"da8a1cf0a20c4e5e1172c883ebae4da8502fd6dc24ca8253d3576f5f179731b8","schema_fingerprint":"4aa3821a28b0b7c2400bc59aba4bcc0a76e971dadd19610d3ad38c768e124dc7","schema_version":"edge-lab-recorder.raw.v1","sequence":null,"source":"clob_market_ws"}
{"event_at":"2026-07-28T04:04:39.335000Z","event_fingerprint":"74122b0d2637816a7237e12e627bd1dabd6efe697078259e952b4616e8d804b3","payload":{"connection_id":"f6725804f86a4c4eb588e4d5ed7db029","event_at":"2026-07-28T04:04:39.335000Z","event_type":"price_change","frame_hash":"94a0d6b617e201086b73fe577bf06f92d0670fd4dee99cfce636dcf6b4453eb4","frame_index":0,"kind":"data","monotonic_ns":313462355089958,"payload":{"event_type":"price_change","market":"0xd412ce774cfcf8dc9f71164aac78783978aac7b03871702a3b8a481bd9dc9688","price_changes":[{"asset_id":"96600821790790307414914106093858868634329285205417149685270682748367152458577","best_ask":"0.42","best_bid":"0.41","hash":"2b77dde0752d1bc606b0496a5f9417b46216db5b","price":"0.37","side":"BUY","size":"164.38"},{"asset_id":"107603864457683460275633293642179940881969192120168665300712204232021063124301","best_ask":"0.59","best_bid":"0.58","hash":"b899d3ec9971dfdd29cfbbffadaf5da61dabf089","price":"0.63","side":"SELL","size":"164.38"}],"timestamp":"1785211479335"},"payload_hash":"15d9f8b5703b918ba64e10bee473756fe2eab26c583ff3010ed4f73b6d67062b","raw_frame":"{\"market\":\"0xd412ce774cfcf8dc9f71164aac78783978aac7b03871702a3b8a481bd9dc9688\", \"price_changes\":[{\"asset_id\":\"96600821790790307414914106093858868634329285205417149685270682748367152458577\", \"price\":\"0.37\", \"size\":\"164.38\", \"side\":\"BUY\", \"hash\":\"2b77dde0752d1bc606b0496a5f9417b46216db5b\", \"best_bid\":\"0.41\", \"best_ask\":\"0.42\"}, {\"asset_id\":\"107603864457683460275633293642179940881969192120168665300712204232021063124301\", \"price\":\"0.63\", \"size\":\"164.38\", \"side\":\"SELL\", \"hash\":\"b899d3ec9971dfdd29cfbbffadaf5da61dabf089\", \"best_bid\":\"0.58\", \"best_ask\":\"0.59\"}], \"timestamp\":\"1785211479335\", \"event_type\":\"price_change\"}","received_at":"2026-07-28T04:04:39.305109Z","schema_version":"clob-market-ws.price_change.v1","sequence":null,"server_hash":null,"server_timestamp":"1785211479335","session_id":"2d607381e3054cee91998cdf45a4231c","source":"clob_market_ws"},"received_at":"2026-07-28T04:04:39.305109Z","record_id":"9d00e5d97859041bde70f2f502ffdb626f11818a005e28801b6ebb10752e1943","schema_fingerprint":"4aa3821a28b0b7c2400bc59aba4bcc0a76e971dadd19610d3ad38c768e124dc7","schema_version":"edge-lab-recorder.raw.v1","sequence":null,"source":"clob_market_ws"}
{"event_at":"2026-07-28T04:04:39.337000Z","event_fingerprint":"d239465e1b8ebc2bfd0acfeecd6f394f5aa531c566b6bd06896d1c8369ea1964","payload":{"connection_id":"f6725804f86a4c4eb588e4d5ed7db029","event_at":"2026-07-28T04:04:39.337000Z","event_type":"price_change","frame_hash":"4f7150735a96e36c40810ef4c752f658e3ad32587e0cf2aeff664f5cd20ed432","frame_index":0,"kind":"data","monotonic_ns":313462356647541,"payload":{"event_type":"price_change","market":"0xd412ce774cfcf8dc9f71164aac78783978aac7b03871702a3b8a481bd9dc9688","price_changes":[{"asset_id":"107603864457683460275633293642179940881969192120168665300712204232021063124301","best_ask":"0.59","best_bid":"0.58","hash":"963cfbccf012198cadf728369d5d22023eba2a28","price":"0.33","side":"BUY","size":"31.6"},{"asset_id":"96600821790790307414914106093858868634329285205417149685270682748367152458577","best_ask":"0.42","best_bid":"0.41","hash":"eb63319353339aec10f7673b927451ea53ca9b2c","price":"0.67","side":"SELL","size":"31.6"}],"timestamp":"1785211479337"},"payload_hash":"ee71026f831ab10fc8e7a1cdf150f1c1185c2da6dbd402fbdc3f3e3d0cab1f3f","raw_frame":"{\"market\":\"0xd412ce774cfcf8dc9f71164aac78783978aac7b03871702a3b8a481bd9dc9688\", \"price_changes\":[{\"asset_id\":\"107603864457683460275633293642179940881969192120168665300712204232021063124301\", \"price\":\"0.33\", \"size\":\"31.6\", \"side\":\"BUY\", \"hash\":\"963cfbccf012198cadf728369d5d22023eba2a28\", \"best_bid\":\"0.58\", \"best_ask\":\"0.59\"}, {\"asset_id\":\"96600821790790307414914106093858868634329285205417149685270682748367152458577\", \"price\":\"0.67\", \"size\":\"31.6\", \"side\":\"SELL\", \"hash\":\"eb63319353339aec10f7673b927451ea53ca9b2c\", \"best_bid\":\"0.41\", \"best_ask\":\"0.42\"}], \"timestamp\":\"1785211479337\", \"event_type\":\"price_change\"}","received_at":"2026-07-28T04:04:39.306666Z","schema_version":"clob-market-ws.price_change.v1","sequence":null,"server_hash":null,"server_timestamp":"1785211479337","session_id":"2d607381e3054cee91998cdf45a4231c","source":"clob_market_ws"},"received_at":"2026-07-28T04:04:39.306666Z","record_id":"77cf8023cfd0a5aa0e05c1193dfadf261b42eb009a039bfdaeec0a69a2a4fd73","schema_fingerprint":"4aa3821a28b0b7c2400bc59aba4bcc0a76e971dadd19610d3ad38c768e124dc7","schema_version":"edge-lab-recorder.raw.v1","sequence":null,"source":"clob_market_ws"}
{"event_at":"2026-07-28T04:04:39.339000Z","event_fingerprint":"bc196ab8d4e8fad8897cf3f9c36105303c4a617097b42cb2941ad197efd25d74","payload":{"connection_id":"f6725804f86a4c4eb588e4d5ed7db029","event_at":"2026-07-28T04:04:39.339000Z","event_type":"price_change","frame_hash":"695a9543181ce089b757130cb87a29320ac0cf2d1fbb949ba19bac41526f7d62","frame_index":0,"kind":"data","monotonic_ns":313462358088125,"payload":{"event_type":"price_change","market":"0xd412ce774cfcf8dc9f71164aac78783978aac7b03871702a3b8a481bd9dc9688","price_changes":[{"asset_id":"107603864457683460275633293642179940881969192120168665300712204232021063124301","best_ask":"0.59","best_bid":"0.58","hash":"4058cba6016a15aa5b4f783a6b9fa9ced78a9c4c","price":"0.57","side":"BUY","size":"113.7"},{"asset_id":"96600821790790307414914106093858868634329285205417149685270682748367152458577","best_ask":"0.42","best_bid":"0.41","hash":"41eb825347b9914d9fb10d5e5ed0bebf5a39dfba","price":"0.43","side":"SELL","size":"113.7"}],"timestamp":"1785211479339"},"payload_hash":"885ea7ebdba4313b7f2ca735f50329497d277659dcb2c800ac1d6713c7c8b4f0","raw_frame":"{\"market\":\"0xd412ce774cfcf8dc9f71164aac78783978aac7b03871702a3b8a481bd9dc9688\", \"price_changes\":[{\"asset_id\":\"107603864457683460275633293642179940881969192120168665300712204232021063124301\", \"price\":\"0.57\", \"size\":\"113.7\", \"side\":\"BUY\", \"hash\":\"4058cba6016a15aa5b4f783a6b9fa9ced78a9c4c\", \"best_bid\":\"0.58\", \"best_ask\":\"0.59\"}, {\"asset_id\":\"96600821790790307414914106093858868634329285205417149685270682748367152458577\", \"price\":\"0.43\", \"size\":\"113.7\", \"side\":\"SELL\", \"hash\":\"41eb825347b9914d9fb10d5e5ed0bebf5a39dfba\", \"best_bid\":\"0.41\", \"best_ask\":\"0.42\"}], \"timestamp\":\"1785211479339\", \"event_type\":\"price_change\"}","received_at":"2026-07-28T04:04:39.308107Z","schema_version":"clob-market-ws.price_change.v1","sequence":null,"server_hash":null,"server_timestamp":"1785211479339","session_id":"2d607381e3054cee91998cdf45a4231c","source":"clob_market_ws"},"received_at":"2026-07-28T04:04:39.308107Z","record_id":"c10730b43a400441b299aadd8c0a2c3ae33df5af5c5089ea2931016ed68b9836","schema_fingerprint":"4aa3821a28b0b7c2400bc59aba4bcc0a76e971dadd19610d3ad38c768e124dc7","schema_version":"edge-lab-recorder.raw.v1","sequence":null,"source":"clob_market_ws"}
{"event_at":"2026-07-28T04:04:39.341000Z","event_fingerprint":"12dc875d49a143fd5dc5463f9422e12f8af89d4baa75e3ffe4df2c3fa1cb9d6c","payload":{"connection_id":"f6725804f86a4c4eb588e4d5ed7db029","event_at":"2026-07-28T04:04:39.341000Z","event_type":"price_change","frame_hash":"86f8a2b11f45df183d85f1fbfb20542cb93fb19d2b4e0125729909d65c81d207","frame_index":0,"kind":"data","monotonic_ns":313462359587250,"payload":{"event_type":"price_change","market":"0xd412ce774cfcf8dc9f71164aac78783978aac7b03871702a3b8a481bd9dc9688","price_changes":[{"asset_id":"107603864457683460275633293642179940881969192120168665300712204232021063124301","best_ask":"0.59","best_bid":"0.58","hash":"a5ccda955ee8eb169faf5c32418705869c18f731","price":"0.34","side":"BUY","size":"49.4"},{"asset_id":"96600821790790307414914106093858868634329285205417149685270682748367152458577","best_ask":"0.42","best_bid":"0.41","hash":"b058327940fb9dc192091e1acfa479525dba7dff","price":"0.66","side":"SELL","size":"49.4"}],"timestamp":"1785211479341"},"payload_hash":"4f845cbdfc00325d91640a25980569d3a4497f3a60148a68f6a2c53e4aefe1c0","raw_frame":"{\"market\":\"0xd412ce774cfcf8dc9f71164aac78783978aac7b03871702a3b8a481bd9dc9688\", \"price_changes\":[{\"asset_id\":\"107603864457683460275633293642179940881969192120168665300712204232021063124301\", \"price\":\"0.34\", \"size\":\"49.4\", \"side\":\"BUY\", \"hash\":\"a5ccda955ee8eb169faf5c32418705869c18f731\", \"best_bid\":\"0.58\", \"best_ask\":\"0.59\"}, {\"asset_id\":\"96600821790790307414914106093858868634329285205417149685270682748367152458577\", \"price\":\"0.66\", \"size\":\"49.4\", \"side\":\"SELL\", \"hash\":\"b058327940fb9dc192091e1acfa479525dba7dff\", \"best_bid\":\"0.41\", \"best_ask\":\"0.42\"}], \"timestamp\":\"1785211479341\", \"event_type\":\"price_change\"}","received_at":"2026-07-28T04:04:39.309607Z","schema_version":"clob-market-ws.price_change.v1","sequence":null,"server_hash":null,"server_timestamp":"1785211479341","session_id":"2d607381e3054cee91998cdf45a4231c","source":"clob_market_ws"},"received_at":"2026-07-28T04:04:39.309607Z","record_id":"88f256775f3de59f91531a108d0bad34117ca33b38be4d27b8fd02c04b7ac8c9","schema_fingerprint":"4aa3821a28b0b7c2400bc59aba4bcc0a76e971dadd19610d3ad38c768e124dc7","schema_version":"edge-lab-recorder.raw.v1","sequence":null,"source":"clob_market_ws"}
{"event_at":"2026-07-28T04:04:39.341000Z","event_fingerprint":"ec512e2715d3a53960be4f4a93642efd97af41afdb37b2d2eb1b5e3327bd4f79","payload":{"connection_id":"f6725804f86a4c4eb588e4d5ed7db029","event_at":"2026-07-28T04:04:39.341000Z","event_type":"price_change","frame_hash":"b28448f04a3aa96bc6d53bc5d1b309de8f97f94ac80ce2a1dd8617a950554575","frame_index":0,"kind":"data","monotonic_ns":313462361154875,"payload":{"event_type":"price_change","market":"0xd412ce774cfcf8dc9f71164aac78783978aac7b03871702a3b8a481bd9dc9688","price_changes":[{"asset_id":"96600821790790307414914106093858868634329285205417149685270682748367152458577","best_ask":"0.42","best_bid":"0.41","hash":"0b10913fab04a813c498fc32646a87f1276fcf37","price":"0.3","side":"BUY","size":"68.49"},{"asset_id":"107603864457683460275633293642179940881969192120168665300712204232021063124301","best_ask":"0.59","best_bid":"0.58","hash":"df0f2f75ee5bc0496559fc092d463e195e5b400d","price":"0.7","side":"SELL","size":"68.49"}],"timestamp":"1785211479341"},"payload_hash":"96f1d08f77d50c24033168456cd8cb6823c06409be85fe92f020f8b0b20a9c7a","raw_frame":"{\"market\":\"0xd412ce774cfcf8dc9f71164aac78783978aac7b03871702a3b8a481bd9dc9688\", \"price_changes\":[{\"asset_id\":\"96600821790790307414914106093858868634329285205417149685270682748367152458577\", \"price\":\"0.3\", \"size\":\"68.49\", \"side\":\"BUY\", \"hash\":\"0b10913fab04a813c498fc32646a87f1276fcf37\", \"best_bid\":\"0.41\", \"best_ask\":\"0.42\"}, {\"asset_id\":\"107603864457683460275633293642179940881969192120168665300712204232021063124301\", \"price\":\"0.7\", \"size\":\"68.49\", \"side\":\"SELL\", \"hash\":\"df0f2f75ee5bc0496559fc092d463e195e5b400d\", \"best_bid\":\"0.58\", \"best_ask\":\"0.59\"}], \"timestamp\":\"1785211479341\", \"event_type\":\"price_change\"}","received_at":"2026-07-28T04:04:39.311174Z","schema_version":"clob-market-ws.price_change.v1","sequence":null,"server_hash":null,"server_timestamp":"1785211479341","session_id":"2d607381e3054cee91998cdf45a4231c","source":"clob_market_ws"},"received_at":"2026-07-28T04:04:39.311174Z","record_id":"f2c1c4fea4d32a2089a0f09998546fc818ed0a63a5c7259b118fdcb35dff39a8","schema_fingerprint":"4aa3821a28b0b7c2400bc59aba4bcc0a76e971dadd19610d3ad38c768e124dc7","schema_version":"edge-lab-recorder.raw.v1","sequence":null,"source":"clob_market_ws"}
{"event_at":"2026-07-28T04:04:39.341000Z","event_fingerprint":"8b533060304969b2e118dbd5f5a761913d702d91c4ded44e0a4984982b9b14c7","payload":{"connection_id":"f6725804f86a4c4eb588e4d5ed7db029","event_at":"2026-07-28T04:04:39.341000Z","event_type":"price_change","frame_hash":"dd298f1d1866c8a7a93b0fe8e2dbd79457c07beacdc012c3588952dd9a17b87b","frame_index":0,"kind":"data","monotonic_ns":313462362606458,"payload":{"event_type":"price_change","market":"0xd412ce774cfcf8dc9f71164aac78783978aac7b03871702a3b8a481bd9dc9688","price_changes":[{"asset_id":"96600821790790307414914106093858868634329285205417149685270682748367152458577","best_ask":"0.42","best_bid":"0.41","hash":"a30e6f78d89831feadd5fd983d996f92f017dcef","price":"0.24","side":"BUY","size":"53.39"},{"asset_id":"107603864457683460275633293642179940881969192120168665300712204232021063124301","best_ask":"0.59","best_bid":"0.58","hash":"072f0ab95f89b37a476e9f718f046307ec8b1095","price":"0.76","side":"SELL","size":"53.39"}],"timestamp":"1785211479341"},"payload_hash":"b4d42599e5309303c2327fdef7d5f1b814ae0ca964d223922c1ccddf348fa928","raw_frame":"{\"market\":\"0xd412ce774cfcf8dc9f71164aac78783978aac7b03871702a3b8a481bd9dc9688\", \"price_changes\":[{\"asset_id\":\"96600821790790307414914106093858868634329285205417149685270682748367152458577\", \"price\":\"0.24\", \"size\":\"53.39\", \"side\":\"BUY\", \"hash\":\"a30e6f78d89831feadd5fd983d996f92f017dcef\", \"best_bid\":\"0.41\", \"best_ask\":\"0.42\"}, {\"asset_id\":\"107603864457683460275633293642179940881969192120168665300712204232021063124301\", \"price\":\"0.76\", \"size\":\"53.39\", \"side\":\"SELL\", \"hash\":\"072f0ab95f89b37a476e9f718f046307ec8b1095\", \"best_bid\":\"0.58\", \"best_ask\":\"0.59\"}], \"timestamp\":\"1785211479341\", \"event_type\":\"price_change\"}","received_at":"2026-07-28T04:04:39.312626Z","schema_version":"clob-market-ws.price_change.v1","sequence":null,"server_hash":null,"server_timestamp":"1785211479341","session_id":"2d607381e3054cee91998cdf45a4231c","source":"clob_market_ws"},"received_at":"2026-07-28T04:04:39.312626Z","record_id":"819214c9ef7ef20102a62286be5e1a0294adf2dbefe128da75bba4aa97122cf5","schema_fingerprint":"4aa3821a28b0b7c2400bc59aba4bcc0a76e971dadd19610d3ad38c768e124dc7","schema_version":"edge-lab-recorder.raw.v1","sequence":null,"source":"clob_market_ws"}
{"event_at":"2026-07-28T04:04:39.341000Z","event_fingerprint":"19a8c669c64fb6508be453cd803ed8892292546a5de76dbd0c2961e139856ff2","payload":{"connection_id":"f6725804f86a4c4eb588e4d5ed7db029","event_at":"2026-07-28T04:04:39.341000Z","event_type":"price_change","frame_hash":"aff53b6d1317c95510db153d2e60dcb56ee07c91ccc320cc2a2c32509801e81b","frame_index":0,"kind":"data","monotonic_ns":313462364139583,"payload":{"event_type":"price_change","market":"0xd412ce774cfcf8dc9f71164aac78783978aac7b03871702a3b8a481bd9dc9688","price_changes":[{"asset_id":"107603864457683460275633293642179940881969192120168665300712204232021063124301","best_ask":"0.59","best_bid":"0.58","hash":"adbdf46687913f04bda55befce779c6cb9cd76bc","price":"0.46","side":"BUY","size":"106"},{"asset_id":"96600821790790307414914106093858868634329285205417149685270682748367152458577","best_ask":"0.42","best_bid":"0.41","hash":"8a4893748986a64fbb54f23033a02fbc07dd65eb","price":"0.54","side":"SELL","size":"106"}],"timestamp":"1785211479341"},"payload_hash":"fe5b64018c6798ee9703c30be755e87510266d559cac9b9e4a15b83457d8c79e","raw_frame":"{\"market\":\"0xd412ce774cfcf8dc9f71164aac78783978aac7b03871702a3b8a481bd9dc9688\", \"price_changes\":[{\"asset_id\":\"107603864457683460275633293642179940881969192120168665300712204232021063124301\", \"price\":\"0.46\", \"size\":\"106\", \"side\":\"BUY\", \"hash\":\"adbdf46687913f04bda55befce779c6cb9cd76bc\", \"best_bid\":\"0.58\", \"best_ask\":\"0.59\"}, {\"asset_id\":\"96600821790790307414914106093858868634329285205417149685270682748367152458577\", \"price\":\"0.54\", \"size\":\"106\", \"side\":\"SELL\", \"hash\":\"8a4893748986a64fbb54f23033a02fbc07dd65eb\", \"best_bid\":\"0.41\", \"best_ask\":\"0.42\"}], \"timestamp\":\"1785211479341\", \"event_type\":\"price_change\"}","received_at":"2026-07-28T04:04:39.314157Z","schema_version":"clob-market-ws.price_change.v1","sequence":null,"server_hash":null,"server_timestamp":"1785211479341","session_id":"2d607381e3054cee91998cdf45a4231c","source":"clob_market_ws"},"received_at":"2026-07-28T04:04:39.314157Z","record_id":"7ac9bfa8676e79fef70ba9232af4b20e7fd171ed1213bd62158d7439916eff30","schema_fingerprint":"4aa3821a28b0b7c2400bc59aba4bcc0a76e971dadd19610d3ad38c768e124dc7","schema_version":"edge-lab-recorder.raw.v1","sequence":null,"source":"clob_market_ws"}
{"event_at":"2026-07-28T04:04:39.342000Z","event_fingerprint":"1ace5c69b765d2fe44b0c41ca2a1df35c8aea47ffd77e04e1b20f317e4696363","payload":{"connection_id":"f6725804f86a4c4eb588e4d5ed7db029","event_at":"2026-07-28T04:04:39.342000Z","event_type":"price_change","frame_hash":"35148c8898fbe3013ef2c8c19e7b779091a500e795eba08aa8ec8df7fa696c71","frame_index":0,"kind":"data","monotonic_ns":313462365724750,"payload":{"event_type":"price_change","market":"0xd412ce774cfcf8dc9f71164aac78783978aac7b03871702a3b8a481bd9dc9688","price_changes":[{"asset_id":"107603864457683460275633293642179940881969192120168665300712204232021063124301","best_ask":"0.59","best_bid":"0.58","hash":"f842dbd91bc198ccc3701c71a247eb6ead170f8b","price":"0.56","side":"BUY","size":"76"},{"asset_id":"96600821790790307414914106093858868634329285205417149685270682748367152458577","best_ask":"0.42","best_bid":"0.41","hash":"d2096e157c5b0a232532e011f63fbbf4e39583c2","price":"0.44","side":"SELL","size":"76"}],"timestamp":"1785211479342"},"payload_hash":"1af769679dc0e2e17b4dcaf8a11dec93f2dfe5df3bb057377c25e6b990852026","raw_frame":"{\"market\":\"0xd412ce774cfcf8dc9f71164aac78783978aac7b03871702a3b8a481bd9dc9688\", \"price_changes\":[{\"asset_id\":\"107603864457683460275633293642179940881969192120168665300712204232021063124301\", \"price\":\"0.56\", \"size\":\"76\", \"side\":\"BUY\", \"hash\":\"f842dbd91bc198ccc3701c71a247eb6ead170f8b\", \"best_bid\":\"0.58\", \"best_ask\":\"0.59\"}, {\"asset_id\":\"96600821790790307414914106093858868634329285205417149685270682748367152458577\", \"price\":\"0.44\", \"size\":\"76\", \"side\":\"SELL\", \"hash\":\"d2096e157c5b0a232532e011f63fbbf4e39583c2\", \"best_bid\":\"0.41\", \"best_ask\":\"0.42\"}], \"timestamp\":\"1785211479342\", \"event_type\":\"price_change\"}","received_at":"2026-07-28T04:04:39.315743Z","schema_version":"clob-market-ws.price_change.v1","sequence":null,"server_hash":null,"server_timestamp":"1785211479342","session_id":"2d607381e3054cee91998cdf45a4231c","source":"clob_market_ws"},"received_at":"2026-07-28T04:04:39.315743Z","record_id":"f7b138f38e8130e3fba201dbbb0770fccb3f125bdd955eeec3026a70eb423925","schema_fingerprint":"4aa3821a28b0b7c2400bc59aba4bcc0a76e971dadd19610d3ad38c768e124dc7","schema_version":"edge-lab-recorder.raw.v1","sequence":null,"source":"clob_market_ws"}
{"event_at":"2026-07-28T04:04:39.344000Z","event_fingerprint":"75fbdcb67e4a0ac2e93fd929f36fb787f1d7e097f1cd4dabd8fb23749450bf75","payload":{"connection_id":"f6725804f86a4c4eb588e4d5ed7db029","event_at":"2026-07-28T04:04:39.344000Z","event_type":"price_change","frame_hash":"484bb543cd7acf1462b663938d973ec850bb1ace10bbb1b00f184ae62f422441","frame_index":0,"kind":"data","monotonic_ns":313462367261000,"payload":{"event_type":"price_change","market":"0xd412ce774cfcf8dc9f71164aac78783978aac7b03871702a3b8a481bd9dc9688","price_changes":[{"asset_id":"96600821790790307414914106093858868634329285205417149685270682748367152458577","best_ask":"0.42","best_bid":"0.41","hash":"0996fba1335f367770b2cfbfec36b06bff0d7b2c","price":"0.29","side":"BUY","size":"20.6"},{"asset_id":"107603864457683460275633293642179940881969192120168665300712204232021063124301","best_ask":"0.59","best_bid":"0.58","hash":"80fd0877e430019791d16667e83d06778622a788","price":"0.71","side":"SELL","size":"20.6"}],"timestamp":"1785211479344"},"payload_hash":"703827c1fef847aa6b5a7efb5cafebe25c32773627747f463263b5b43f71a05e","raw_frame":"{\"market\":\"0xd412ce774cfcf8dc9f71164aac78783978aac7b03871702a3b8a481bd9dc9688\", \"price_changes\":[{\"asset_id\":\"96600821790790307414914106093858868634329285205417149685270682748367152458577\", \"price\":\"0.29\", \"size\":\"20.6\", \"side\":\"BUY\", \"hash\":\"0996fba1335f367770b2cfbfec36b06bff0d7b2c\", \"best_bid\":\"0.41\", \"best_ask\":\"0.42\"}, {\"asset_id\":\"107603864457683460275633293642179940881969192120168665300712204232021063124301\", \"price\":\"0.71\", \"size\":\"20.6\", \"side\":\"SELL\", \"hash\":\"80fd0877e430019791d16667e83d06778622a788\", \"best_bid\":\"0.58\", \"best_ask\":\"0.59\"}], \"timestamp\":\"1785211479344\", \"event_type\":\"price_change\"}","received_at":"2026-07-28T04:04:39.317280Z","schema_version":"clob-market-ws.price_change.v1","sequence":null,"server_hash":null,"server_timestamp":"1785211479344","session_id":"2d607381e3054cee91998cdf45a4231c","source":"clob_market_ws"},"received_at":"2026-07-28T04:04:39.317280Z","record_id":"840ab427fb52cd0c93e45018ffb5678b4ee3685bb69649b8f8fff61062f1d714","schema_fingerprint":"4aa3821a28b0b7c2400bc59aba4bcc0a76e971dadd19610d3ad38c768e124dc7","schema_version":"edge-lab-recorder.raw.v1","sequence":null,"source":"clob_market_ws"}
{"event_at":"2026-07-28T04:04:39.344000Z","event_fingerprint":"f8054495a02906fb79383e91ebc62c24279037b1cace383bfb92bf1f51c52d3b","payload":{"connection_id":"f6725804f86a4c4eb588e4d5ed7db029","event_at":"2026-07-28T04:04:39.344000Z","event_type":"price_change","frame_hash":"5ea19424a1086c8598e1ed0ba97831b44572a36b3d57a27ca79654946dfd3b23","frame_index":0,"kind":"data","monotonic_ns":313462368816000,"payload":{"event_type":"price_change","market":"0xd412ce774cfcf8dc9f71164aac78783978aac7b03871702a3b8a481bd9dc9688","price_changes":[{"asset_id":"107603864457683460275633293642179940881969192120168665300712204232021063124301","best_ask":"0.59","best_bid":"0.58","hash":"d44cf9ec11bee2d9f3cdb79bd8665ad0467e33ba","price":"0.55","side":"BUY","size":"93.2"},{"asset_id":"96600821790790307414914106093858868634329285205417149685270682748367152458577","best_ask":"0.42","best_bid":"0.41","hash":"e5dd7a38271bc4cba896940496dc539f888430e9","price":"0.45","side":"SELL","size":"93.2"}],"timestamp":"1785211479344"},"payload_hash":"81f6913e30e7faa46ef9277557f4e73128075a98a7d95e9c44c1356a44f51dc4","raw_frame":"{\"market\":\"0xd412ce774cfcf8dc9f71164aac78783978aac7b03871702a3b8a481bd9dc9688\", \"price_changes\":[{\"asset_id\":\"107603864457683460275633293642179940881969192120168665300712204232021063124301\", \"price\":\"0.55\", \"size\":\"93.2\", \"side\":\"BUY\", \"hash\":\"d44cf9ec11bee2d9f3cdb79bd8665ad0467e33ba\", \"best_bid\":\"0.58\", \"best_ask\":\"0.59\"}, {\"asset_id\":\"96600821790790307414914106093858868634329285205417149685270682748367152458577\", \"price\":\"0.45\", \"size\":\"93.2\", \"side\":\"SELL\", \"hash\":\"e5dd7a38271bc4cba896940496dc539f888430e9\", \"best_bid\":\"0.41\", \"best_ask\":\"0.42\"}], \"timestamp\":\"1785211479344\", \"event_type\":\"price_change\"}","received_at":"2026-07-28T04:04:39.318834Z","schema_version":"clob-market-ws.price_change.v1","sequence":null,"server_hash":null,"server_timestamp":"1785211479344","session_id":"2d607381e3054cee91998cdf45a4231c","source":"clob_market_ws"},"received_at":"2026-07-28T04:04:39.318834Z","record_id":"b6376113f5a4d60612e39712a2cbd1b647b9f77b5d86f21ed1376a88ab7b3bb9","schema_fingerprint":"4aa3821a28b0b7c2400bc59aba4bcc0a76e971dadd19610d3ad38c768e124dc7","schema_version":"edge-lab-recorder.raw.v1","sequence":null,"source":"clob_market_ws"}
{"event_at":"2026-07-28T04:04:39.345000Z","event_fingerprint":"8ad262c8075cc298c4effeea1e98ab98a84ff5b9e78617eb050a609649092ed1","payload":{"connection_id":"f6725804f86a4c4eb588e4d5ed7db029","event_at":"2026-07-28T04:04:39.345000Z","event_type":"price_change","frame_hash":"0c966e7570a32a06f4f44e2802fd256abdea005118dcd5c5a8be7a6457aee9b7","frame_index":0,"kind":"data","monotonic_ns":313462370356041,"payload":{"event_type":"price_change","market":"0xd412ce774cfcf8dc9f71164aac78783978aac7b03871702a3b8a481bd9dc9688","price_changes":[{"asset_id":"107603864457683460275633293642179940881969192120168665300712204232021063124301","best_ask":"0.59","best_bid":"0.58","hash":"ddf15e2c8444b1bc9187942a1bb2e230548b9fae","price":"0.45","side":"BUY","size":"63.62"},{"asset_id":"96600821790790307414914106093858868634329285205417149685270682748367152458577","best_ask":"0.42","best_bid":"0.41","hash":"42ac92369792b1f3c0c3bdd6faeda4b98c3e6fb4","price":"0.55","side":"SELL","size":"63.62"}],"timestamp":"1785211479345"},"payload_hash":"4db5deade56f4d81bda55aac4cc2bcdab94c9e2725b8c8ee6e76aca07a38414d","raw_frame":"{\"market\":\"0xd412ce774cfcf8dc9f71164aac78783978aac7b03871702a3b8a481bd9dc9688\", \"price_changes\":[{\"asset_id\":\"107603864457683460275633293642179940881969192120168665300712204232021063124301\", \"price\":\"0.45\", \"size\":\"63.62\", \"side\":\"BUY\", \"hash\":\"ddf15e2c8444b1bc9187942a1bb2e230548b9fae\", \"best_bid\":\"0.58\", \"best_ask\":\"0.59\"}, {\"asset_id\":\"96600821790790307414914106093858868634329285205417149685270682748367152458577\", \"price\":\"0.55\", \"size\":\"63.62\", \"side\":\"SELL\", \"hash\":\"42ac92369792b1f3c0c3bdd6faeda4b98c3e6fb4\", \"best_bid\":\"0.41\", \"best_ask\":\"0.42\"}], \"timestamp\":\"1785211479345\", \"event_type\":\"price_change\"}","received_at":"2026-07-28T04:04:39.320373Z","schema_version":"clob-market-ws.price_change.v1","sequence":null,"server_hash":null,"server_timestamp":"1785211479345","session_id":"2d607381e3054cee91998cdf45a4231c","source":"clob_market_ws"},"received_at":"2026-07-28T04:04:39.320373Z","record_id":"28f08a1f4fcbcea621c96a825ed6a17cdcb3ac6e5f207f4b7333a757582cf0c6","schema_fingerprint":"4aa3821a28b0b7c2400bc59aba4bcc0a76e971dadd19610d3ad38c768e124dc7","schema_version":"edge-lab-recorder.raw.v1","sequence":null,"source":"clob_market_ws"}
{"event_at":"2026-07-28T04:04:39.346000Z","event_fingerprint":"eb302da211dccb97152bbdb9aecd86d04ea16c55c57ca34ea500309f342baf1f","payload":{"connection_id":"f6725804f86a4c4eb588e4d5ed7db029","event_at":"2026-07-28T04:04:39.346000Z","event_type":"price_change","frame_hash":"fb93c0e14793e6edaac29cb48c423b7dbe59747185cad50870ca70397d4592ea","frame_index":0,"kind":"data","monotonic_ns":313462371854208,"payload":{"event_type":"price_change","market":"0xd412ce774cfcf8dc9f71164aac78783978aac7b03871702a3b8a481bd9dc9688","price_changes":[{"asset_id":"96600821790790307414914106093858868634329285205417149685270682748367152458577","best_ask":"0.42","best_bid":"0.41","hash":"49225adc711a9fc4a505eedff012cb42717767ed","price":"0.36","side":"BUY","size":"152.38"},{"asset_id":"107603864457683460275633293642179940881969192120168665300712204232021063124301","best_ask":"0.59","best_bid":"0.58","hash":"d78c8a05e425129b352faab5b4e44ece86bc6b27","price":"0.64","side":"SELL","size":"152.38"}],"timestamp":"1785211479346"},"payload_hash":"0ecaecb2928693d0cfe11adbd5cc381d51de4056a730c929b4079047d78e8b75","raw_frame":"{\"market\":\"0xd412ce774cfcf8dc9f71164aac78783978aac7b03871702a3b8a481bd9dc9688\", \"price_changes\":[{\"asset_id\":\"96600821790790307414914106093858868634329285205417149685270682748367152458577\", \"price\":\"0.36\", \"size\":\"152.38\", \"side\":\"BUY\", \"hash\":\"49225adc711a9fc4a505eedff012cb42717767ed\", \"best_bid\":\"0.41\", \"best_ask\":\"0.42\"}, {\"asset_id\":\"107603864457683460275633293642179940881969192120168665300712204232021063124301\", \"price\":\"0.64\", \"size\":\"152.38\", \"side\":\"SELL\", \"hash\":\"d78c8a05e425129b352faab5b4e44ece86bc6b27\", \"best_bid\":\"0.58\", \"best_ask\":\"0.59\"}], \"timestamp\":\"1785211479346\", \"event_type\":\"price_change\"}","received_at":"2026-07-28T04:04:39.321873Z","schema_version":"clob-market-ws.price_change.v1","sequence":null,"server_hash":null,"server_timestamp":"1785211479346","session_id":"2d607381e3054cee91998cdf45a4231c","source":"clob_market_ws"},"received_at":"2026-07-28T04:04:39.321873Z","record_id":"3ea5c06f63ea6cf84eee25376522fb35eba5f5e02627a4f1a67683894f73e67b","schema_fingerprint":"4aa3821a28b0b7c2400bc59aba4bcc0a76e971dadd19610d3ad38c768e124dc7","schema_version":"edge-lab-recorder.raw.v1","sequence":null,"source":"clob_market_ws"}
{"event_at":"2026-07-28T04:04:39.347000Z","event_fingerprint":"25a5be0fea458ba82adc87940dcc00a3f9fdeca031df63b6900bd812f242bc65","payload":{"connection_id":"f6725804f86a4c4eb588e4d5ed7db029","event_at":"2026-07-28T04:04:39.347000Z","event_type":"price_change","frame_hash":"baf055d640515567b8da50b05ad2c493889fbe3a2ef9e984fd6c581297cdf8f9","frame_index":0,"kind":"data","monotonic_ns":313462373328875,"payload":{"event_type":"price_change","market":"0xd412ce774cfcf8dc9f71164aac78783978aac7b03871702a3b8a481bd9dc9688","price_changes":[{"asset_id":"107603864457683460275633293642179940881969192120168665300712204232021063124301","best_ask":"0.59","best_bid":"0.58","hash":"fe3351c80483c429efa1988e977c2c7f5787cec2","price":"0.52","side":"BUY","size":"132.6"},{"asset_id":"96600821790790307414914106093858868634329285205417149685270682748367152458577","best_ask":"0.42","best_bid":"0.41","hash":"b3ac213a330f8c6a599ddb71918c517f8a357c58","price":"0.48","side":"SELL","size":"132.6"}],"timestamp":"1785211479347"},"payload_hash":"da66650f6d5db3bd6ff236988b5a7f4ac783522f3f94341eb4c0716b70b37b33","raw_frame":"{\"market\":\"0xd412ce774cfcf8dc9f71164aac78783978aac7b03871702a3b8a481bd9dc9688\", \"price_changes\":[{\"asset_id\":\"107603864457683460275633293642179940881969192120168665300712204232021063124301\", \"price\":\"0.52\", \"size\":\"132.6\", \"side\":\"BUY\", \"hash\":\"fe3351c80483c429efa1988e977c2c7f5787cec2\", \"best_bid\":\"0.58\", \"best_ask\":\"0.59\"}, {\"asset_id\":\"96600821790790307414914106093858868634329285205417149685270682748367152458577\", \"price\":\"0.48\", \"size\":\"132.6\", \"side\":\"SELL\", \"hash\":\"b3ac213a330f8c6a599ddb71918c517f8a357c58\", \"best_bid\":\"0.41\", \"best_ask\":\"0.42\"}], \"timestamp\":\"1785211479347\", \"event_type\":\"price_change\"}","received_at":"2026-07-28T04:04:39.323349Z","schema_version":"clob-market-ws.price_change.v1","sequence":null,"server_hash":null,"server_timestamp":"1785211479347","session_id":"2d607381e3054cee91998cdf45a4231c","source":"clob_market_ws"},"received_at":"2026-07-28T04:04:39.323349Z","record_id":"aedc723284afa262bf6dd4177813987a7a2090a5014cc35e90e72537a7db21df","schema_fingerprint":"4aa3821a28b0b7c2400bc59aba4bcc0a76e971dadd19610d3ad38c768e124dc7","schema_version":"edge-lab-recorder.raw.v1","sequence":null,"source":"clob_market_ws"}
{"event_at":"2026-07-28T04:04:39.347000Z","event_fingerprint":"724508a850d3a595f014736f3a0a7bd8822d9fc072bfd6793d3de32af1e59495","payload":{"connection_id":"f6725804f86a4c4eb588e4d5ed7db029","event_at":"2026-07-28T04:04:39.347000Z","event_type":"price_change","frame_hash":"a47586960942a81a07e78c20c5b2e6521ef1df87dc18db91f2f1d4e01645948b","frame_index":0,"kind":"data","monotonic_ns":313462374830791,"payload":{"event_type":"price_change","market":"0xd412ce774cfcf8dc9f71164aac78783978aac7b03871702a3b8a481bd9dc9688","price_changes":[{"asset_id":"107603864457683460275633293642179940881969192120168665300712204232021063124301","best_ask":"0.59","best_bid":"0.58","hash":"4c31fa435f6b1ade95eb9db75c24c076910dcba1","price":"0.54","side":"BUY","size":"99.84"},{"asset_id":"96600821790790307414914106093858868634329285205417149685270682748367152458577","best_ask":"0.42","best_bid":"0.41","hash":"80ab53a2b90be13c0b8d71d67666e33a95770e15","price":"0.46","side":"SELL","size":"99.84"}],"timestamp":"1785211479347"},"payload_hash":"ce036c81ad12257c9da5302edaad8e8111b9016b872d6bfe292efe0891346d8b","raw_frame":"{\"market\":\"0xd412ce774cfcf8dc9f71164aac78783978aac7b03871702a3b8a481bd9dc9688\", \"price_changes\":[{\"asset_id\":\"107603864457683460275633293642179940881969192120168665300712204232021063124301\", \"price\":\"0.54\", \"size\":\"99.84\", \"side\":\"BUY\", \"hash\":\"4c31fa435f6b1ade95eb9db75c24c076910dcba1\", \"best_bid\":\"0.58\", \"best_ask\":\"0.59\"}, {\"asset_id\":\"96600821790790307414914106093858868634329285205417149685270682748367152458577\", \"price\":\"0.46\", \"size\":\"99.84\", \"side\":\"SELL\", \"hash\":\"80ab53a2b90be13c0b8d71d67666e33a95770e15\", \"best_bid\":\"0.41\", \"best_ask\":\"0.42\"}], \"timestamp\":\"1785211479347\", \"event_type\":\"price_change\"}","received_at":"2026-07-28T04:04:39.324849Z","schema_version":"clob-market-ws.price_change.v1","sequence":null,"server_hash":null,"server_timestamp":"1785211479347","session_id":"2d607381e3054cee91998cdf45a4231c","source":"clob_market_ws"},"received_at":"2026-07-28T04:04:39.324849Z","record_id":"4ea0946e7f2dd1ae61f4d42a7cc159c47a776813e2de65d0c94d3ae4e91d09be","schema_fingerprint":"4aa3821a28b0b7c2400bc59aba4bcc0a76e971dadd19610d3ad38c768e124dc7","schema_version":"edge-lab-recorder.raw.v1","sequence":null,"source":"clob_market_ws"}
{"event_at":"2026-07-28T04:04:39.348000Z","event_fingerprint":"a41442fb085091ca0c3f11fc180adf581389bd3d6ccc390dcd065873f81087c9","payload":{"connection_id":"f6725804f86a4c4eb588e4d5ed7db029","event_at":"2026-07-28T04:04:39.348000Z","event_type":"price_change","frame_hash":"afa2e2b35c9c5f057a02fe782b0bfcee8f047b1a50086d70b6b78457fdb027c0","frame_index":0,"kind":"data","monotonic_ns":313462376328000,"payload":{"event_type":"price_change","market":"0xd412ce774cfcf8dc9f71164aac78783978aac7b03871702a3b8a481bd9dc9688","price_changes":[{"asset_id":"107603864457683460275633293642179940881969192120168665300712204232021063124301","best_ask":"0.59","best_bid":"0.58","hash":"b1bf067907033136fe70ced2efbea24a5257b974","price":"0.4","side":"BUY","size":"161.5"},{"asset_id":"96600821790790307414914106093858868634329285205417149685270682748367152458577","best_ask":"0.42","best_bid":"0.41","hash":"4ccdabd5276acb7e284d5d3de4d42557621fc44f","price":"0.6","side":"SELL","size":"161.5"}],"timestamp":"1785211479348"},"payload_hash":"dc2058d6f3e3e09eaaa3333ad6f1b04ed3ac33713a5301260aa63624da3464f1","raw_frame":"{\"market\":\"0xd412ce774cfcf8dc9f71164aac78783978aac7b03871702a3b8a481bd9dc9688\", \"price_changes\":[{\"asset_id\":\"107603864457683460275633293642179940881969192120168665300712204232021063124301\", \"price\":\"0.4\", \"size\":\"161.5\", \"side\":\"BUY\", \"hash\":\"b1bf067907033136fe70ced2efbea24a5257b974\", \"best_bid\":\"0.58\", \"best_ask\":\"0.59\"}, {\"asset_id\":\"96600821790790307414914106093858868634329285205417149685270682748367152458577\", \"price\":\"0.6\", \"size\":\"161.5\", \"side\":\"SELL\", \"hash\":\"4ccdabd5276acb7e284d5d3de4d42557621fc44f\", \"best_bid\":\"0.41\", \"best_ask\":\"0.42\"}], \"timestamp\":\"1785211479348\", \"event_type\":\"price_change\"}","received_at":"2026-07-28T04:04:39.326347Z","schema_version":"clob-market-ws.price_change.v1","sequence":null,"server_hash":null,"server_timestamp":"1785211479348","session_id":"2d607381e3054cee91998cdf45a4231c","source":"clob_market_ws"},"received_at":"2026-07-28T04:04:39.326347Z","record_id":"acc869586a7a456932fd4ec2aee03834929d4ce731bfc281c0a3c1593ab3a229","schema_fingerprint":"4aa3821a28b0b7c2400bc59aba4bcc0a76e971dadd19610d3ad38c768e124dc7","schema_version":"edge-lab-recorder.raw.v1","sequence":null,"source":"clob_market_ws"}
{"event_at":"2026-07-28T04:04:39.348000Z","event_fingerprint":"e5976cb4a535e2c882114cc7ee0977f7ed1b864258ca9c4d5052b9d308a0e825","payload":{"connection_id":"f6725804f86a4c4eb588e4d5ed7db029","event_at":"2026-07-28T04:04:39.348000Z","event_type":"price_change","frame_hash":"c375d4edc730235ce3d26d30ec81212d5a6e50e6698b8c35feb0d071ddf04510","frame_index":0,"kind":"data","monotonic_ns":313462377818500,"payload":{"event_type":"price_change","market":"0xd412ce774cfcf8dc9f71164aac78783978aac7b03871702a3b8a481bd9dc9688","price_changes":[{"asset_id":"96600821790790307414914106093858868634329285205417149685270682748367152458577","best_ask":"0.42","best_bid":"0.41","hash":"4ccdabd5276acb7e284d5d3de4d42557621fc44f","price":"0.3","side":"BUY","size":"62.3"},{"asset_id":"107603864457683460275633293642179940881969192120168665300712204232021063124301","best_ask":"0.59","best_bid":"0.58","hash":"b1bf067907033136fe70ced2efbea24a5257b974","price":"0.7","side":"SELL","size":"62.3"}],"timestamp":"1785211479348"},"payload_hash":"01d29a6abf50d051d318787d01bbb2109ea17bb5ec8f52b20910f3a9fd8dac75","raw_frame":"{\"market\":\"0xd412ce774cfcf8dc9f71164aac78783978aac7b03871702a3b8a481bd9dc9688\", \"price_changes\":[{\"asset_id\":\"96600821790790307414914106093858868634329285205417149685270682748367152458577\", \"price\":\"0.3\", \"size\":\"62.3\", \"side\":\"BUY\", \"hash\":\"4ccdabd5276acb7e284d5d3de4d42557621fc44f\", \"best_bid\":\"0.41\", \"best_ask\":\"0.42\"}, {\"asset_id\":\"107603864457683460275633293642179940881969192120168665300712204232021063124301\", \"price\":\"0.7\", \"size\":\"62.3\", \"side\":\"SELL\", \"hash\":\"b1bf067907033136fe70ced2efbea24a5257b974\", \"best_bid\":\"0.58\", \"best_ask\":\"0.59\"}], \"timestamp\":\"1785211479348\", \"event_type\":\"price_change\"}","received_at":"2026-07-28T04:04:39.327838Z","schema_version":"clob-market-ws.price_change.v1","sequence":null,"server_hash":null,"server_timestamp":"1785211479348","session_id":"2d607381e3054cee91998cdf45a4231c","source":"clob_market_ws"},"received_at":"2026-07-28T04:04:39.327838Z","record_id":"a18046f6c1de7ae929865826c1f54429b4a29f2f01899a1c6bbda53c4a919f76","schema_fingerprint":"4aa3821a28b0b7c2400bc59aba4bcc0a76e971dadd19610d3ad38c768e124dc7","schema_version":"edge-lab-recorder.raw.v1","sequence":null,"source":"clob_market_ws"}
{"event_at":"2026-07-28T04:04:39.352000Z","event_fingerprint":"605f48e982530a2e7f24aba7f0f579c5fab5913dd503ab88f348e8096ddbd992","payload":{"connection_id":"f6725804f86a4c4eb588e4d5ed7db029","event_at":"2026-07-28T04:04:39.352000Z","event_type":"price_change","frame_hash":"f4fa78cf2c3b9e5600c3e789cfd17cb09dae7bd8b172c315f4a5d835f556121d","frame_index":0,"kind":"data","monotonic_ns":313462379404583,"payload":{"event_type":"price_change","market":"0xd412ce774cfcf8dc9f71164aac78783978aac7b03871702a3b8a481bd9dc9688","price_changes":[{"asset_id":"107603864457683460275633293642179940881969192120168665300712204232021063124301","best_ask":"0.59","best_bid":"0.58","hash":"06072dbe3482b3a3bb6abc28d8432d366009ca6f","price":"0.47","side":"BUY","size":"151"},{"asset_id":"96600821790790307414914106093858868634329285205417149685270682748367152458577","best_ask":"0.42","best_bid":"0.41","hash":"0555af41dfc26b8d8961b52a5bce1bfc3458c5e1","price":"0.53","side":"SELL","size":"151"}],"timestamp":"1785211479352"},"payload_hash":"f579d5c77e6535803ed9c8b8b959694811baafa7433ae5e0a09ccfda3308e261","raw_frame":"{\"market\":\"0xd412ce774cfcf8dc9f71164aac78783978aac7b03871702a3b8a481bd9dc9688\", \"price_changes\":[{\"asset_id\":\"107603864457683460275633293642179940881969192120168665300712204232021063124301\", \"price\":\"0.47\", \"size\":\"151\", \"side\":\"BUY\", \"hash\":\"06072dbe3482b3a3bb6abc28d8432d366009ca6f\", \"best_bid\":\"0.58\", \"best_ask\":\"0.59\"}, {\"asset_id\":\"96600821790790307414914106093858868634329285205417149685270682748367152458577\", \"price\":\"0.53\", \"size\":\"151\", \"side\":\"SELL\", \"hash\":\"0555af41dfc26b8d8961b52a5bce1bfc3458c5e1\", \"best_bid\":\"0.41\", \"best_ask\":\"0.42\"}], \"timestamp\":\"1785211479352\", \"event_type\":\"price_change\"}","received_at":"2026-07-28T04:04:39.329423Z","schema_version":"clob-market-ws.price_change.v1","sequence":null,"server_hash":null,"server_timestamp":"1785211479352","session_id":"2d607381e3054cee91998cdf45a4231c","source":"clob_market_ws"},"received_at":"2026-07-28T04:04:39.329423Z","record_id":"b229104f10b0e7940ac1e1ba253a8552f7f3350cd60d702c6dd823a2a7514026","schema_fingerprint":"4aa3821a28b0b7c2400bc59aba4bcc0a76e971dadd19610d3ad38c768e124dc7","schema_version":"edge-lab-recorder.raw.v1","sequence":null,"source":"clob_market_ws"}
{"event_at":"2026-07-28T04:04:39.352000Z","event_fingerprint":"f0b1eac50fc060af55f91d52b66b501692a77d65991522bf177225f7b0f98aa5","payload":{"connection_id":"f6725804f86a4c4eb588e4d5ed7db029","event_at":"2026-07-28T04:04:39.352000Z","event_type":"price_change","frame_hash":"6f1f0fb1daaf2d4230ac3859fe1de59addeb0bb66955d2302db3becfd81578f0","frame_index":0,"kind":"data","monotonic_ns":313462380937291,"payload":{"event_type":"price_change","market":"0xd412ce774cfcf8dc9f71164aac78783978aac7b03871702a3b8a481bd9dc9688","price_changes":[{"asset_id":"107603864457683460275633293642179940881969192120168665300712204232021063124301","best_ask":"0.59","best_bid":"0.58","hash":"eabbae634e6ce7962db6c29b3672143fc774c25d","price":"0.04","side":"BUY","size":"668.09"},{"asset_id":"96600821790790307414914106093858868634329285205417149685270682748367152458577","best_ask":"0.42","best_bid":"0.41","hash":"dd2f2f41bc974058437850d48bb0f89098e49e6e","price":"0.96","side":"SELL","size":"668.09"}],"timestamp":"1785211479352"},"payload_hash":"fbe245b00190a8d322984e29a3b6c5fd3b43af5fe26367b8c72faf145e0323eb","raw_frame":"{\"market\":\"0xd412ce774cfcf8dc9f71164aac78783978aac7b03871702a3b8a481bd9dc9688\", \"price_changes\":[{\"asset_id\":\"107603864457683460275633293642179940881969192120168665300712204232021063124301\", \"price\":\"0.04\", \"size\":\"668.09\", \"side\":\"BUY\", \"hash\":\"eabbae634e6ce7962db6c29b3672143fc774c25d\", \"best_bid\":\"0.58\", \"best_ask\":\"0.59\"}, {\"asset_id\":\"96600821790790307414914106093858868634329285205417149685270682748367152458577\", \"price\":\"0.96\", \"size\":\"668.09\", \"side\":\"SELL\", \"hash\":\"dd2f2f41bc974058437850d48bb0f89098e49e6e\", \"best_bid\":\"0.41\", \"best_ask\":\"0.42\"}], \"timestamp\":\"1785211479352\", \"event_type\":\"price_change\"}","received_at":"2026-07-28T04:04:39.330956Z","schema_version":"clob-market-ws.price_change.v1","sequence":null,"server_hash":null,"server_timestamp":"1785211479352","session_id":"2d607381e3054cee91998cdf45a4231c","source":"clob_market_ws"},"received_at":"2026-07-28T04:04:39.330956Z","record_id":"3ad99c686d004bc06f5e04da409c488a58a7c281e627f423387a8f59a6581afa","schema_fingerprint":"4aa3821a28b0b7c2400bc59aba4bcc0a76e971dadd19610d3ad38c768e124dc7","schema_version":"edge-lab-recorder.raw.v1","sequence":null,"source":"clob_market_ws"}
{"event_at":"2026-07-28T04:04:39.352000Z","event_fingerprint":"20c0ca69876670ffa48acff3e5c4130a03751c33e29597b1ea27a42ceb01b4e7","payload":{"connection_id":"f6725804f86a4c4eb588e4d5ed7db029","event_at":"2026-07-28T04:04:39.352000Z","event_type":"price_change","frame_hash":"93f08269f882a796cd72baf03704b2fe45ab8512d8c839e1a1bad9da38867f21","frame_index":0,"kind":"data","monotonic_ns":313462382405500,"payload":{"event_type":"price_change","market":"0xd412ce774cfcf8dc9f71164aac78783978aac7b03871702a3b8a481bd9dc9688","price_changes":[{"asset_id":"107603864457683460275633293642179940881969192120168665300712204232021063124301","best_ask":"0.59","best_bid":"0.58","hash":"f3be0d859a180f45998e860d7f9515beb3006fc4","price":"0.47","side":"BUY","size":"146"},{"asset_id":"96600821790790307414914106093858868634329285205417149685270682748367152458577","best_ask":"0.42","best_bid":"0.41","hash":"07db492632d4064f0979905a2cc2c5aa91866f76","price":"0.53","side":"SELL","size":"146"}],"timestamp":"1785211479352"},"payload_hash":"91283e1618b2a392792bf10358f7e47b1b04ba29c098eae9155269fe6a33c3ca","raw_frame":"{\"market\":\"0xd412ce774cfcf8dc9f71164aac78783978aac7b03871702a3b8a481bd9dc9688\", \"price_changes\":[{\"asset_id\":\"107603864457683460275633293642179940881969192120168665300712204232021063124301\", \"price\":\"0.47\", \"size\":\"146\", \"side\":\"BUY\", \"hash\":\"f3be0d859a180f45998e860d7f9515beb3006fc4\", \"best_bid\":\"0.58\", \"best_ask\":\"0.59\"}, {\"asset_id\":\"96600821790790307414914106093858868634329285205417149685270682748367152458577\", \"price\":\"0.53\", \"size\":\"146\", \"side\":\"SELL\", \"hash\":\"07db492632d4064f0979905a2cc2c5aa91866f76\", \"best_bid\":\"0.41\", \"best_ask\":\"0.42\"}], \"timestamp\":\"1785211479352\", \"event_type\":\"price_change\"}","received_at":"2026-07-28T04:04:39.332419Z","schema_version":"clob-market-ws.price_change.v1","sequence":null,"server_hash":null,"server_timestamp":"1785211479352","session_id":"2d607381e3054cee91998cdf45a4231c","source":"clob_market_ws"},"received_at":"2026-07-28T04:04:39.332419Z","record_id":"4113b72c018d9507dd748ab68e4204e2abde322e13edaf2f8a482132cd2e21d7","schema_fingerprint":"4aa3821a28b0b7c2400bc59aba4bcc0a76e971dadd19610d3ad38c768e124dc7","schema_version":"edge-lab-recorder.raw.v1","sequence":null,"source":"clob_market_ws"}
{"event_at":"2026-07-28T04:04:39.353000Z","event_fingerprint":"a49afa0a009d4cfc3da750c1fe910cc79d7330fec2f4e84f4423e435087b4389","payload":{"connection_id":"f6725804f86a4c4eb588e4d5ed7db029","event_at":"2026-07-28T04:04:39.353000Z","event_type":"price_change","frame_hash":"1991ff925b88891333af1a069b12dc0703f12afd67542d383f652bac18eaaeb4","frame_index":0,"kind":"data","monotonic_ns":313462383905125,"payload":{"event_type":"price_change","market":"0xd412ce774cfcf8dc9f71164aac78783978aac7b03871702a3b8a481bd9dc9688","price_changes":[{"asset_id":"96600821790790307414914106093858868634329285205417149685270682748367152458577","best_ask":"0.42","best_bid":"0.41","hash":"a50e98495c2560151119cd46adc79bef1bb04d0b","price":"0.38","side":"BUY","size":"25.38"},{"asset_id":"107603864457683460275633293642179940881969192120168665300712204232021063124301","best_ask":"0.59","best_bid":"0.58","hash":"6785fc8ee661a72360f04e43e8287ffec60a2818","price":"0.62","side":"SELL","size":"25.38"}],"timestamp":"1785211479353"},"payload_hash":"8c617054e4b849e32fe215e6b1f1fa05d6e6de95f1b76cb83a453564789cfece","raw_frame":"{\"market\":\"0xd412ce774cfcf8dc9f71164aac78783978aac7b03871702a3b8a481bd9dc9688\", \"price_changes\":[{\"asset_id\":\"96600821790790307414914106093858868634329285205417149685270682748367152458577\", \"price\":\"0.38\", \"size\":\"25.38\", \"side\":\"BUY\", \"hash\":\"a50e98495c2560151119cd46adc79bef1bb04d0b\", \"best_bid\":\"0.41\", \"best_ask\":\"0.42\"}, {\"asset_id\":\"107603864457683460275633293642179940881969192120168665300712204232021063124301\", \"price\":\"0.62\", \"size\":\"25.38\", \"side\":\"SELL\", \"hash\":\"6785fc8ee661a72360f04e43e8287ffec60a2818\", \"best_bid\":\"0.58\", \"best_ask\":\"0.59\"}], \"timestamp\":\"1785211479353\", \"event_type\":\"price_change\"}","received_at":"2026-07-28T04:04:39.333924Z","schema_version":"clob-market-ws.price_change.v1","sequence":null,"server_hash":null,"server_timestamp":"1785211479353","session_id":"2d607381e3054cee91998cdf45a4231c","source":"clob_market_ws"},"received_at":"2026-07-28T04:04:39.333924Z","record_id":"7450fb92919506b933c0d944db2575966d6ae10ba3cd9e5888cadeae49aa3b02","schema_fingerprint":"4aa3821a28b0b7c2400bc59aba4bcc0a76e971dadd19610d3ad38c768e124dc7","schema_version":"edge-lab-recorder.raw.v1","sequence":null,"source":"clob_market_ws"}
{"event_at":"2026-07-28T04:04:39.355000Z","event_fingerprint":"0794927dc53a8195353924ad6364db89a9da034762e63e7a8ae07e2fdc024369","payload":{"connection_id":"f6725804f86a4c4eb588e4d5ed7db029","event_at":"2026-07-28T04:04:39.355000Z","event_type":"price_change","frame_hash":"c3bdb6ec704cf70b542253b82bf4cb441379248e5f0414a53571e396a735e283","frame_index":0,"kind":"data","monotonic_ns":313462385436916,"payload":{"event_type":"price_change","market":"0xd412ce774cfcf8dc9f71164aac78783978aac7b03871702a3b8a481bd9dc9688","price_changes":[{"asset_id":"96600821790790307414914106093858868634329285205417149685270682748367152458577","best_ask":"0.42","best_bid":"0.41","hash":"beb175a8fee23f0135af519f49c7d026e14d3c8c","price":"0.37","side":"BUY","size":"64.38"},{"asset_id":"107603864457683460275633293642179940881969192120168665300712204232021063124301","best_ask":"0.59","best_bid":"0.58","hash":"47db62230013852555bac579078e8aa85103a950","price":"0.63","side":"SELL","size":"64.38"}],"timestamp":"1785211479355"},"payload_hash":"a5fa109a293611d9b831538234d7f8b66e114753358c73d3b9ea57e90e6bc7f1","raw_frame":"{\"market\":\"0xd412ce774cfcf8dc9f71164aac78783978aac7b03871702a3b8a481bd9dc9688\", \"price_changes\":[{\"asset_id\":\"96600821790790307414914106093858868634329285205417149685270682748367152458577\", \"price\":\"0.37\", \"size\":\"64.38\", \"side\":\"BUY\", \"hash\":\"beb175a8fee23f0135af519f49c7d026e14d3c8c\", \"best_bid\":\"0.41\", \"best_ask\":\"0.42\"}, {\"asset_id\":\"107603864457683460275633293642179940881969192120168665300712204232021063124301\", \"price\":\"0.63\", \"size\":\"64.38\", \"side\":\"SELL\", \"hash\":\"47db62230013852555bac579078e8aa85103a950\", \"best_bid\":\"0.58\", \"best_ask\":\"0.59\"}], \"timestamp\":\"1785211479355\", \"event_type\":\"price_change\"}","received_at":"2026-07-28T04:04:39.335455Z","schema_version":"clob-market-ws.price_change.v1","sequence":null,"server_hash":null,"server_timestamp":"1785211479355","session_id":"2d607381e3054cee91998cdf45a4231c","source":"clob_market_ws"},"received_at":"2026-07-28T04:04:39.335455Z","record_id":"a31de6719bb7bdec311c125d2f7ff2dab41b1835034f74b84da1f27068625129","schema_fingerprint":"4aa3821a28b0b7c2400bc59aba4bcc0a76e971dadd19610d3ad38c768e124dc7","schema_version":"edge-lab-recorder.raw.v1","sequence":null,"source":"clob_market_ws"}
{"event_at":"2026-07-28T04:04:39.355000Z","event_fingerprint":"9e76d5686512eac4c9e54e225f909d375fbf45187617ee880b0046162cd153e7","payload":{"connection_id":"f6725804f86a4c4eb588e4d5ed7db029","event_at":"2026-07-28T04:04:39.355000Z","event_type":"price_change","frame_hash":"4700d9e3a678d7124c32cc93de6c3c6cfbf01471ffcc610c0c552edea5061ffa","frame_index":0,"kind":"data","monotonic_ns":313462386960791,"payload":{"event_type":"price_change","market":"0xd412ce774cfcf8dc9f71164aac78783978aac7b03871702a3b8a481bd9dc9688","price_changes":[{"asset_id":"96600821790790307414914106093858868634329285205417149685270682748367152458577","best_ask":"0.42","best_bid":"0.41","hash":"beb175a8fee23f0135af519f49c7d026e14d3c8c","price":"0.36","side":"BUY","size":"52.38"},{"asset_id":"107603864457683460275633293642179940881969192120168665300712204232021063124301","best_ask":"0.59","best_bid":"0.58","hash":"47db62230013852555bac579078e8aa85103a950","price":"0.64","side":"SELL","size":"52.38"}],"timestamp":"1785211479355"},"payload_hash":"bb3250392041daab68e69c0864e79e14217d7a11cea782642b3a1d7273ef7281","raw_frame":"{\"market\":\"0xd412ce774cfcf8dc9f71164aac78783978aac7b03871702a3b8a481bd9dc9688\", \"price_changes\":[{\"asset_id\":\"96600821790790307414914106093858868634329285205417149685270682748367152458577\", \"price\":\"0.36\", \"size\":\"52.38\", \"side\":\"BUY\", \"hash\":\"beb175a8fee23f0135af519f49c7d026e14d3c8c\", \"best_bid\":\"0.41\", \"best_ask\":\"0.42\"}, {\"asset_id\":\"107603864457683460275633293642179940881969192120168665300712204232021063124301\", \"price\":\"0.64\", \"size\":\"52.38\", \"side\":\"SELL\", \"hash\":\"47db62230013852555bac579078e8aa85103a950\", \"best_bid\":\"0.58\", \"best_ask\":\"0.59\"}], \"timestamp\":\"1785211479355\", \"event_type\":\"price_change\"}","received_at":"2026-07-28T04:04:39.336980Z","schema_version":"clob-market-ws.price_change.v1","sequence":null,"server_hash":null,"server_timestamp":"1785211479355","session_id":"2d607381e3054cee91998cdf45a4231c","source":"clob_market_ws"},"received_at":"2026-07-28T04:04:39.336980Z","record_id":"2aff830556707b419e0cbfcb22511a986cd1f625c0bb1850fbe6a4c8dcda8e77","schema_fingerprint":"4aa3821a28b0b7c2400bc59aba4bcc0a76e971dadd19610d3ad38c768e124dc7","schema_version":"edge-lab-recorder.raw.v1","sequence":null,"source":"clob_market_ws"}
{"event_at":"2026-07-28T04:04:39.356000Z","event_fingerprint":"616f2b41c458041978015f7277051fe1be1c410cdd8112be6b58c0150fcd7251","payload":{"connection_id":"f6725804f86a4c4eb588e4d5ed7db029","event_at":"2026-07-28T04:04:39.356000Z","event_type":"price_change","frame_hash":"4ef007cd2c45b39d3a4bafd97f070687aeebea84e08c15fa82ab2abe657d224a","frame_index":0,"kind":"data","monotonic_ns":313462388494666,"payload":{"event_type":"price_change","market":"0xd412ce774cfcf8dc9f71164aac78783978aac7b03871702a3b8a481bd9dc9688","price_changes":[{"asset_id":"107603864457683460275633293642179940881969192120168665300712204232021063124301","best_ask":"0.59","best_bid":"0.58","hash":"7ae5f0c070ad6a674f1c65740b0c39fe0550e360","price":"0.49","side":"BUY","size":"104.63"},{"asset_id":"96600821790790307414914106093858868634329285205417149685270682748367152458577","best_ask":"0.42","best_bid":"0.41","hash":"3877ea90fbe97718a55da20ea6af216c418bc3e8","price":"0.51","side":"SELL","size":"104.63"}],"timestamp":"1785211479356"},"payload_hash":"b1fad1a0217b9cf03615e127ffad321a716d48567ff8626ce18a4fcd8ccc5763","raw_frame":"{\"market\":\"0xd412ce774cfcf8dc9f71164aac78783978aac7b03871702a3b8a481bd9dc9688\", \"price_changes\":[{\"asset_id\":\"107603864457683460275633293642179940881969192120168665300712204232021063124301\", \"price\":\"0.49\", \"size\":\"104.63\", \"side\":\"BUY\", \"hash\":\"7ae5f0c070ad6a674f1c65740b0c39fe0550e360\", \"best_bid\":\"0.58\", \"best_ask\":\"0.59\"}, {\"asset_id\":\"96600821790790307414914106093858868634329285205417149685270682748367152458577\", \"price\":\"0.51\", \"size\":\"104.63\", \"side\":\"SELL\", \"hash\":\"3877ea90fbe97718a55da20ea6af216c418bc3e8\", \"best_bid\":\"0.41\", \"best_ask\":\"0.42\"}], \"timestamp\":\"1785211479356\", \"event_type\":\"price_change\"}","received_at":"2026-07-28T04:04:39.338512Z","schema_version":"clob-market-ws.price_change.v1","sequence":null,"server_hash":null,"server_timestamp":"1785211479356","session_id":"2d607381e3054cee91998cdf45a4231c","source":"clob_market_ws"},"received_at":"2026-07-28T04:04:39.338512Z","record_id":"9aae5562cc8639571ccb4727cea32c390bc20d9fa833f28639a1515fe6b60697","schema_fingerprint":"4aa3821a28b0b7c2400bc59aba4bcc0a76e971dadd19610d3ad38c768e124dc7","schema_version":"edge-lab-recorder.raw.v1","sequence":null,"source":"clob_market_ws"}
{"event_at":"2026-07-28T04:04:39.357000Z","event_fingerprint":"4e1efe109c0b4b3620f475f595518d3ef13cbfb74808408695337efb6e6c216b","payload":{"connection_id":"f6725804f86a4c4eb588e4d5ed7db029","event_at":"2026-07-28T04:04:39.357000Z","event_type":"price_change","frame_hash":"58544b6ccf551e9335fe1f381958446651c2482e6db60b8a8e224479f9f5351c","frame_index":0,"kind":"data","monotonic_ns":313462389986000,"payload":{"event_type":"price_change","market":"0xd412ce774cfcf8dc9f71164aac78783978aac7b03871702a3b8a481bd9dc9688","price_changes":[{"asset_id":"96600821790790307414914106093858868634329285205417149685270682748367152458577","best_ask":"0.42","best_bid":"0.41","hash":"2504878313f2796275b9cd7d4af9b82e66c31fae","price":"0.35","side":"BUY","size":"135"},{"asset_id":"107603864457683460275633293642179940881969192120168665300712204232021063124301","best_ask":"0.59","best_bid":"0.58","hash":"65e201cd98a91ffaaa8fd1e9c40f41c54195c22e","price":"0.65","side":"SELL","size":"135"}],"timestamp":"1785211479357"},"payload_hash":"71d899360dff5bdf4c0de4c23af87b289d82e3db6e1d83230f39e0a7214b3535","raw_frame":"{\"market\":\"0xd412ce774cfcf8dc9f71164aac78783978aac7b03871702a3b8a481bd9dc9688\", \"price_changes\":[{\"asset_id\":\"96600821790790307414914106093858868634329285205417149685270682748367152458577\", \"price\":\"0.35\", \"size\":\"135\", \"side\":\"BUY\", \"hash\":\"2504878313f2796275b9cd7d4af9b82e66c31fae\", \"best_bid\":\"0.41\", \"best_ask\":\"0.42\"}, {\"asset_id\":\"107603864457683460275633293642179940881969192120168665300712204232021063124301\", \"price\":\"0.65\", \"size\":\"135\", \"side\":\"SELL\", \"hash\":\"65e201cd98a91ffaaa8fd1e9c40f41c54195c22e\", \"best_bid\":\"0.58\", \"best_ask\":\"0.59\"}], \"timestamp\":\"1785211479357\", \"event_type\":\"price_change\"}","received_at":"2026-07-28T04:04:39.340005Z","schema_version":"clob-market-ws.price_change.v1","sequence":null,"server_hash":null,"server_timestamp":"1785211479357","session_id":"2d607381e3054cee91998cdf45a4231c","source":"clob_market_ws"},"received_at":"2026-07-28T04:04:39.340005Z","record_id":"4729f8575d53864325e1a5419f10d8c669bf5cf8066cf92655529a5765bf7436","schema_fingerprint":"4aa3821a28b0b7c2400bc59aba4bcc0a76e971dadd19610d3ad38c768e124dc7","schema_version":"edge-lab-recorder.raw.v1","sequence":null,"source":"clob_market_ws"}
{"event_at":"2026-07-28T04:04:39.357000Z","event_fingerprint":"bea972ad0f4b9eac2ce3a5a36bf0139dcead701cd3a08d674bedcdbb7395f3ff","payload":{"connection_id":"f6725804f86a4c4eb588e4d5ed7db029","event_at":"2026-07-28T04:04:39.357000Z","event_type":"price_change","frame_hash":"94708e3dbd87dfb23e0b4d725734a1b063e8e1528e3e7e74b3b6b7d0d6914a11","frame_index":0,"kind":"data","monotonic_ns":313462391456541,"payload":{"event_type":"price_change","market":"0xd412ce774cfcf8dc9f71164aac78783978aac7b03871702a3b8a481bd9dc9688","price_changes":[{"asset_id":"107603864457683460275633293642179940881969192120168665300712204232021063124301","best_ask":"0.59","best_bid":"0.58","hash":"c0763ab8a89dd1572265546b94b6ccf9c38b1318","price":"0.49","side":"BUY","size":"99.63"},{"asset_id":"96600821790790307414914106093858868634329285205417149685270682748367152458577","best_ask":"0.42","best_bid":"0.41","hash":"87c6674ce722eda18c433527d8283a194c828304","price":"0.51","side":"SELL","size":"99.63"}],"timestamp":"1785211479357"},"payload_hash":"72733b39cb14ab78abcdfcf043efaeb351159f2685682d4760a154ef74b495d1","raw_frame":"{\"market\":\"0xd412ce774cfcf8dc9f71164aac78783978aac7b03871702a3b8a481bd9dc9688\", \"price_changes\":[{\"asset_id\":\"107603864457683460275633293642179940881969192120168665300712204232021063124301\", \"price\":\"0.49\", \"size\":\"99.63\", \"side\":\"BUY\", \"hash\":\"c0763ab8a89dd1572265546b94b6ccf9c38b1318\", \"best_bid\":\"0.58\", \"best_ask\":\"0.59\"}, {\"asset_id\":\"96600821790790307414914106093858868634329285205417149685270682748367152458577\", \"price\":\"0.51\", \"size\":\"99.63\", \"side\":\"SELL\", \"hash\":\"87c6674ce722eda18c433527d8283a194c828304\", \"best_bid\":\"0.41\", \"best_ask\":\"0.42\"}], \"timestamp\":\"1785211479357\", \"event_type\":\"price_change\"}","received_at":"2026-07-28T04:04:39.341475Z","schema_version":"clob-market-ws.price_change.v1","sequence":null,"server_hash":null,"server_timestamp":"1785211479357","session_id":"2d607381e3054cee91998cdf45a4231c","source":"clob_market_ws"},"received_at":"2026-07-28T04:04:39.341475Z","record_id":"60a774032e387ae6b8202984f88940df3e2ec0ab5685444dc2cddb2b4c7b4079","schema_fingerprint":"4aa3821a28b0b7c2400bc59aba4bcc0a76e971dadd19610d3ad38c768e124dc7","schema_version":"edge-lab-recorder.raw.v1","sequence":null,"source":"clob_market_ws"}
{"event_at":"2026-07-28T04:04:39.357000Z","event_fingerprint":"85b46dfc27ede4bac4e75bbfa1a1938d55795712dd8cdbb68da84c759d041964","payload":{"connection_id":"f6725804f86a4c4eb588e4d5ed7db029","event_at":"2026-07-28T04:04:39.357000Z","event_type":"price_change","frame_hash":"cfbf60729c7fa7135dbc649ef087e7595a6fe2c7e26de1ed0b8287d87198a7b0","frame_index":0,"kind":"data","monotonic_ns":313462392951041,"payload":{"event_type":"price_change","market":"0xd412ce774cfcf8dc9f71164aac78783978aac7b03871702a3b8a481bd9dc9688","price_changes":[{"asset_id":"107603864457683460275633293642179940881969192120168665300712204232021063124301","best_ask":"0.59","best_bid":"0.58","hash":"768642ec96ab52d87ca476efc36082012b2a5533","price":"0.38","side":"BUY","size":"127.7"},{"asset_id":"96600821790790307414914106093858868634329285205417149685270682748367152458577","best_ask":"0.42","best_bid":"0.41","hash":"cdf16f2a23bbf98dd2894b8b3fbafc5cf7deea77","price":"0.62","side":"SELL","size":"127.7"}],"timestamp":"1785211479357"},"payload_hash":"2bbdadab871dabca9418bb0cb4b8b36e22b7ee8ec1be8b5713d1969e9c13350a","raw_frame":"{\"market\":\"0xd412ce774cfcf8dc9f71164aac78783978aac7b03871702a3b8a481bd9dc9688\", \"price_changes\":[{\"asset_id\":\"107603864457683460275633293642179940881969192120168665300712204232021063124301\", \"price\":\"0.38\", \"size\":\"127.7\", \"side\":\"BUY\", \"hash\":\"768642ec96ab52d87ca476efc36082012b2a5533\", \"best_bid\":\"0.58\", \"best_ask\":\"0.59\"}, {\"asset_id\":\"96600821790790307414914106093858868634329285205417149685270682748367152458577\", \"price\":\"0.62\", \"size\":\"127.7\", \"side\":\"SELL\", \"hash\":\"cdf16f2a23bbf98dd2894b8b3fbafc5cf7deea77\", \"best_bid\":\"0.41\", \"best_ask\":\"0.42\"}], \"timestamp\":\"1785211479357\", \"event_type\":\"price_change\"}","received_at":"2026-07-28T04:04:39.342969Z","schema_version":"clob-market-ws.price_change.v1","sequence":null,"server_hash":null,"server_timestamp":"1785211479357","session_id":"2d607381e3054cee91998cdf45a4231c","source":"clob_market_ws"},"received_at":"2026-07-28T04:04:39.342969Z","record_id":"7c51ffed6e1bb4b47b11310649e8aa7df3a1af566d58091f26c3dcf99fe4e6fe","schema_fingerprint":"4aa3821a28b0b7c2400bc59aba4bcc0a76e971dadd19610d3ad38c768e124dc7","schema_version":"edge-lab-recorder.raw.v1","sequence":null,"source":"clob_market_ws"}
{"event_at":"2026-07-28T04:04:39.358000Z","event_fingerprint":"79c86b62c41754f8216bf4e7967206069c570e47fe6cd0a8def18df8e3593686","payload":{"connection_id":"f6725804f86a4c4eb588e4d5ed7db029","event_at":"2026-07-28T04:04:39.358000Z","event_type":"price_change","frame_hash":"a1272f8dd14496a2de1b3328dd0181a5c5020345c215976ef02d75f761e0e052","frame_index":0,"kind":"data","monotonic_ns":313462394418666,"payload":{"event_type":"price_change","market":"0xd412ce774cfcf8dc9f71164aac78783978aac7b03871702a3b8a481bd9dc9688","price_changes":[{"asset_id":"107603864457683460275633293642179940881969192120168665300712204232021063124301","best_ask":"0.59","best_bid":"0.58","hash":"eae3be452af1d857f90d49c012df90faddeaa91c","price":"0.48","side":"BUY","size":"65"},{"asset_id":"96600821790790307414914106093858868634329285205417149685270682748367152458577","best_ask":"0.42","best_bid":"0.41","hash":"075ab2a977de0b844420d391063581fdfd2c342d","price":"0.52","side":"SELL","size":"65"}],"timestamp":"1785211479358"},"payload_hash":"03dcc7d1ca2f32f496dcf9ef81936cdfaa385b0d098ee849f0de44fa7d4bcd19","raw_frame":"{\"market\":\"0xd412ce774cfcf8dc9f71164aac78783978aac7b03871702a3b8a481bd9dc9688\", \"price_changes\":[{\"asset_id\":\"107603864457683460275633293642179940881969192120168665300712204232021063124301\", \"price\":\"0.48\", \"size\":\"65\", \"side\":\"BUY\", \"hash\":\"eae3be452af1d857f90d49c012df90faddeaa91c\", \"best_bid\":\"0.58\", \"best_ask\":\"0.59\"}, {\"asset_id\":\"96600821790790307414914106093858868634329285205417149685270682748367152458577\", \"price\":\"0.52\", \"size\":\"65\", \"side\":\"SELL\", \"hash\":\"075ab2a977de0b844420d391063581fdfd2c342d\", \"best_bid\":\"0.41\", \"best_ask\":\"0.42\"}], \"timestamp\":\"1785211479358\", \"event_type\":\"price_change\"}","received_at":"2026-07-28T04:04:39.344437Z","schema_version":"clob-market-ws.price_change.v1","sequence":null,"server_hash":null,"server_timestamp":"1785211479358","session_id":"2d607381e3054cee91998cdf45a4231c","source":"clob_market_ws"},"received_at":"2026-07-28T04:04:39.344437Z","record_id":"176f338797ee55d60062e42b978994d6f4de3aa695dc097d73022db86abd0b8f","schema_fingerprint":"4aa3821a28b0b7c2400bc59aba4bcc0a76e971dadd19610d3ad38c768e124dc7","schema_version":"edge-lab-recorder.raw.v1","sequence":null,"source":"clob_market_ws"}
{"event_at":"2026-07-28T04:04:39.359000Z","event_fingerprint":"4654daa438b43a50f23e8563a39565e65646317494e611dfeafe8d7552e4ccb2","payload":{"connection_id":"f6725804f86a4c4eb588e4d5ed7db029","event_at":"2026-07-28T04:04:39.359000Z","event_type":"price_change","frame_hash":"8aa638807ab519d864d92115bf997a854ad589c9e49d765a32fba1dda982952a","frame_index":0,"kind":"data","monotonic_ns":313462395888083,"payload":{"event_type":"price_change","market":"0xd412ce774cfcf8dc9f71164aac78783978aac7b03871702a3b8a481bd9dc9688","price_changes":[{"asset_id":"96600821790790307414914106093858868634329285205417149685270682748367152458577","best_ask":"0.42","best_bid":"0.41","hash":"bb97ac206dad480b5aedd5d841e1d26953db6a5c","price":"0.31","side":"BUY","size":"6"},{"asset_id":"107603864457683460275633293642179940881969192120168665300712204232021063124301","best_ask":"0.59","best_bid":"0.58","hash":"90c69642b1955edf5a6a3ddf7274ca1e42386913","price":"0.69","side":"SELL","size":"6"}],"timestamp":"1785211479359"},"payload_hash":"cf9025f8ee27344174698a1912433a50073b8e86b8934a41b24dc153f2a6a610","raw_frame":"{\"market\":\"0xd412ce774cfcf8dc9f71164aac78783978aac7b03871702a3b8a481bd9dc9688\", \"price_changes\":[{\"asset_id\":\"96600821790790307414914106093858868634329285205417149685270682748367152458577\", \"price\":\"0.31\", \"size\":\"6\", \"side\":\"BUY\", \"hash\":\"bb97ac206dad480b5aedd5d841e1d26953db6a5c\", \"best_bid\":\"0.41\", \"best_ask\":\"0.42\"}, {\"asset_id\":\"107603864457683460275633293642179940881969192120168665300712204232021063124301\", \"price\":\"0.69\", \"size\":\"6\", \"side\":\"SELL\", \"hash\":\"90c69642b1955edf5a6a3ddf7274ca1e42386913\", \"best_bid\":\"0.58\", \"best_ask\":\"0.59\"}], \"timestamp\":\"1785211479359\", \"event_type\":\"price_change\"}","received_at":"2026-07-28T04:04:39.345907Z","schema_version":"clob-market-ws.price_change.v1","sequence":null,"server_hash":null,"server_timestamp":"1785211479359","session_id":"2d607381e3054cee91998cdf45a4231c","source":"clob_market_ws"},"received_at":"2026-07-28T04:04:39.345907Z","record_id":"30ac512460ad7b908bab15a5213b0f882a0d311359ebdedda874c097a7d39696","schema_fingerprint":"4aa3821a28b0b7c2400bc59aba4bcc0a76e971dadd19610d3ad38c768e124dc7","schema_version":"edge-lab-recorder.raw.v1","sequence":null,"source":"clob_market_ws"}
{"event_at":"2026-07-28T04:04:39.361000Z","event_fingerprint":"eea705ddde51816ed2175a0a5ccf4e6e648ffcda27c921db54e2f619451be91d","payload":{"connection_id":"f6725804f86a4c4eb588e4d5ed7db029","event_at":"2026-07-28T04:04:39.361000Z","event_type":"price_change","frame_hash":"ea4e89d853ee2e574ed62712417b9d1eab061d670fe2a11ff9e1b0f30c2698d3","frame_index":0,"kind":"data","monotonic_ns":313462397429000,"payload":{"event_type":"price_change","market":"0xd412ce774cfcf8dc9f71164aac78783978aac7b03871702a3b8a481bd9dc9688","price_changes":[{"asset_id":"107603864457683460275633293642179940881969192120168665300712204232021063124301","best_ask":"0.59","best_bid":"0.58","hash":"52ff1a813286a3614734d19693e837bcd4a9f2cd","price":"0.36","side":"BUY","size":"110.59"},{"asset_id":"96600821790790307414914106093858868634329285205417149685270682748367152458577","best_ask":"0.42","best_bid":"0.41","hash":"ee373f595a9773537713913785f09e1a08a6a87c","price":"0.64","side":"SELL","size":"110.59"}],"timestamp":"1785211479361"},"payload_hash":"095925ced04e4ad59f0ce8b68c4718f0443ad5e6966b605c21ca655325e69225","raw_frame":"{\"market\":\"0xd412ce774cfcf8dc9f71164aac78783978aac7b03871702a3b8a481bd9dc9688\", \"price_changes\":[{\"asset_id\":\"107603864457683460275633293642179940881969192120168665300712204232021063124301\", \"price\":\"0.36\", \"size\":\"110.59\", \"side\":\"BUY\", \"hash\":\"52ff1a813286a3614734d19693e837bcd4a9f2cd\", \"best_bid\":\"0.58\", \"best_ask\":\"0.59\"}, {\"asset_id\":\"96600821790790307414914106093858868634329285205417149685270682748367152458577\", \"price\":\"0.64\", \"size\":\"110.59\", \"side\":\"SELL\", \"hash\":\"ee373f595a9773537713913785f09e1a08a6a87c\", \"best_bid\":\"0.41\", \"best_ask\":\"0.42\"}], \"timestamp\":\"1785211479361\", \"event_type\":\"price_change\"}","received_at":"2026-07-28T04:04:39.347448Z","schema_version":"clob-market-ws.price_change.v1","sequence":null,"server_hash":null,"server_timestamp":"1785211479361","session_id":"2d607381e3054cee91998cdf45a4231c","source":"clob_market_ws"},"received_at":"2026-07-28T04:04:39.347448Z","record_id":"b86336a4b84faab5fc61c6b0e04edf1e0fbd626cce593f8d78ba336e30d68b4d","schema_fingerprint":"4aa3821a28b0b7c2400bc59aba4bcc0a76e971dadd19610d3ad38c768e124dc7","schema_version":"edge-lab-recorder.raw.v1","sequence":null,"source":"clob_market_ws"}
{"event_at":"2026-07-28T04:04:39.365000Z","event_fingerprint":"0d6b8d5e8694ba3baa15e324a403102c582c728bc7555d773e8035b7c2352ee8","payload":{"connection_id":"f6725804f86a4c4eb588e4d5ed7db029","event_at":"2026-07-28T04:04:39.365000Z","event_type":"price_change","frame_hash":"5de0b147d2c750ff3908bc311109dcac317ad3bfc74cfdea336e849a19b176ce","frame_index":0,"kind":"data","monotonic_ns":313462398911791,"payload":{"event_type":"price_change","market":"0xd412ce774cfcf8dc9f71164aac78783978aac7b03871702a3b8a481bd9dc9688","price_changes":[{"asset_id":"96600821790790307414914106093858868634329285205417149685270682748367152458577","best_ask":"0.42","best_bid":"0.41","hash":"ff65a736566e7c40c5a74e2baef66d40b4cc96b2","price":"0.38","side":"BUY","size":"40.38"},{"asset_id":"107603864457683460275633293642179940881969192120168665300712204232021063124301","best_ask":"0.59","best_bid":"0.58","hash":"0e910cb7b6f92c0b7735040522d0c9d5677b7dac","price":"0.62","side":"SELL","size":"40.38"}],"timestamp":"1785211479365"},"payload_hash":"58ba8251bbc58f90981f0b5ec29b957752a060fbfc9c5e8edd3192d00cc644cb","raw_frame":"{\"market\":\"0xd412ce774cfcf8dc9f71164aac78783978aac7b03871702a3b8a481bd9dc9688\", \"price_changes\":[{\"asset_id\":\"96600821790790307414914106093858868634329285205417149685270682748367152458577\", \"price\":\"0.38\", \"size\":\"40.38\", \"side\":\"BUY\", \"hash\":\"ff65a736566e7c40c5a74e2baef66d40b4cc96b2\", \"best_bid\":\"0.41\", \"best_ask\":\"0.42\"}, {\"asset_id\":\"107603864457683460275633293642179940881969192120168665300712204232021063124301\", \"price\":\"0.62\", \"size\":\"40.38\", \"side\":\"SELL\", \"hash\":\"0e910cb7b6f92c0b7735040522d0c9d5677b7dac\", \"best_bid\":\"0.58\", \"best_ask\":\"0.59\"}], \"timestamp\":\"1785211479365\", \"event_type\":\"price_change\"}","received_at":"2026-07-28T04:04:39.348931Z","schema_version":"clob-market-ws.price_change.v1","sequence":null,"server_hash":null,"server_timestamp":"1785211479365","session_id":"2d607381e3054cee91998cdf45a4231c","source":"clob_market_ws"},"received_at":"2026-07-28T04:04:39.348931Z","record_id":"61c1a8b9b7bafb9cdb02cf52c605e519bc66eb3ccd0856a81e0032988b25ba1e","schema_fingerprint":"4aa3821a28b0b7c2400bc59aba4bcc0a76e971dadd19610d3ad38c768e124dc7","schema_version":"edge-lab-recorder.raw.v1","sequence":null,"source":"clob_market_ws"}
{"event_at":"2026-07-28T04:04:39.366000Z","event_fingerprint":"ef064d1d5740ae0bde80d95198d1a3e56d03ffd775529f63b65e8a9ca5a2b71a","payload":{"connection_id":"f6725804f86a4c4eb588e4d5ed7db029","event_at":"2026-07-28T04:04:39.366000Z","event_type":"best_bid_ask","frame_hash":"7be5f611c180701553a8f06c055275ab57b2eb998ca7867084e462798a56cdbc","frame_index":0,"kind":"data","monotonic_ns":313462400414083,"payload":{"asset_id":"107603864457683460275633293642179940881969192120168665300712204232021063124301","best_ask":"0.6","best_bid":"0.58","event_type":"best_bid_ask","market":"0xd412ce774cfcf8dc9f71164aac78783978aac7b03871702a3b8a481bd9dc9688","spread":"0.02","timestamp":"1785211479366"},"payload_hash":"786ddfe12641a32119c6d35d82a555c16dd1d0a53063618a0cf1f985d5b29a6a","raw_frame":"{\"market\":\"0xd412ce774cfcf8dc9f71164aac78783978aac7b03871702a3b8a481bd9dc9688\", \"asset_id\":\"107603864457683460275633293642179940881969192120168665300712204232021063124301\", \"best_bid\":\"0.58\", \"best_ask\":\"0.6\", \"spread\":\"0.02\", \"timestamp\":\"1785211479366\", \"event_type\":\"best_bid_ask\"}","received_at":"2026-07-28T04:04:39.350433Z","schema_version":"clob-market-ws.best_bid_ask.v1","sequence":null,"server_hash":null,"server_timestamp":"1785211479366","session_id":"2d607381e3054cee91998cdf45a4231c","source":"clob_market_ws"},"received_at":"2026-07-28T04:04:39.350433Z","record_id":"6e2e1c15ce8a0410d33b1b239115545dcf55454026cf38757c2e1ba584b292bd","schema_fingerprint":"8488399f31b0337811b13b266be932db7062827c2470b78bd8e9e99bab51d17d","schema_version":"edge-lab-recorder.raw.v1","sequence":null,"source":"clob_market_ws"}
{"event_at":"2026-07-28T04:04:39.366000Z","event_fingerprint":"fa437fb697b3f52280a37e9ca779514ac2ecbd6019b43cb50901c216619ba256","payload":{"connection_id":"f6725804f86a4c4eb588e4d5ed7db029","event_at":"2026-07-28T04:04:39.366000Z","event_type":"best_bid_ask","frame_hash":"1608cd5e6fdc4d5392b830a43d753d082cb5f738adb2023a67ce2bc597e15ed5","frame_index":0,"kind":"data","monotonic_ns":313462401512916,"payload":{"asset_id":"96600821790790307414914106093858868634329285205417149685270682748367152458577","best_ask":"0.42","best_bid":"0.4","event_type":"best_bid_ask","market":"0xd412ce774cfcf8dc9f71164aac78783978aac7b03871702a3b8a481bd9dc9688","spread":"0.02","timestamp":"1785211479366"},"payload_hash":"906b1e16b936634bff1a2b972d31f02486d00ff6930f26a6b5c66450ea4cc38b","raw_frame":"{\"market\":\"0xd412ce774cfcf8dc9f71164aac78783978aac7b03871702a3b8a481bd9dc9688\", \"asset_id\":\"96600821790790307414914106093858868634329285205417149685270682748367152458577\", \"best_bid\":\"0.4\", \"best_ask\":\"0.42\", \"spread\":\"0.02\", \"timestamp\":\"1785211479366\", \"event_type\":\"best_bid_ask\"}","received_at":"2026-07-28T04:04:39.351532Z","schema_version":"clob-market-ws.best_bid_ask.v1","sequence":null,"server_hash":null,"server_timestamp":"1785211479366","session_id":"2d607381e3054cee91998cdf45a4231c","source":"clob_market_ws"},"received_at":"2026-07-28T04:04:39.351532Z","record_id":"1f95c63b0953d3876e2f89e4c7ae65120fa44d5f395fd8462243eaa557c84280","schema_fingerprint":"8488399f31b0337811b13b266be932db7062827c2470b78bd8e9e99bab51d17d","schema_version":"edge-lab-recorder.raw.v1","sequence":null,"source":"clob_market_ws"}
{"event_at":"2026-07-28T04:04:39.366000Z","event_fingerprint":"d7ea70409e24c350de4e5b07055b8c4355f9331abcedb1d9a05e13c59a39fd4f","payload":{"connection_id":"f6725804f86a4c4eb588e4d5ed7db029","event_at":"2026-07-28T04:04:39.366000Z","event_type":"price_change","frame_hash":"63f38c92f366298509a2d5c897a3c9192de511ec7073be0dd41e65a78257fd6b","frame_index":0,"kind":"data","monotonic_ns":313462402611958,"payload":{"event_type":"price_change","market":"0xd412ce774cfcf8dc9f71164aac78783978aac7b03871702a3b8a481bd9dc9688","price_changes":[{"asset_id":"96600821790790307414914106093858868634329285205417149685270682748367152458577","best_ask":"0.42","best_bid":"0.4","hash":"5b5a312753d8def14772479bd05cd0658febc339","price":"0.4","side":"BUY","size":"39"},{"asset_id":"107603864457683460275633293642179940881969192120168665300712204232021063124301","best_ask":"0.6","best_bid":"0.58","hash":"ea5dab70326d2ff3b785fe7eb8d85e39544b47dc","price":"0.6","side":"SELL","size":"39"}],"timestamp":"1785211479366"},"payload_hash":"2f75ff037c687b8bd5bca918035d95eb872afa12443c71b23a5c68cffa192cae","raw_frame":"{\"market\":\"0xd412ce774cfcf8dc9f71164aac78783978aac7b03871702a3b8a481bd9dc9688\", \"price_changes\":[{\"asset_id\":\"96600821790790307414914106093858868634329285205417149685270682748367152458577\", \"price\":\"0.4\", \"size\":\"39\", \"side\":\"BUY\", \"hash\":\"5b5a312753d8def14772479bd05cd0658febc339\", \"best_bid\":\"0.4\", \"best_ask\":\"0.42\"}, {\"asset_id\":\"107603864457683460275633293642179940881969192120168665300712204232021063124301\", \"price\":\"0.6\", \"size\":\"39\", \"side\":\"SELL\", \"hash\":\"ea5dab70326d2ff3b785fe7eb8d85e39544b47dc\", \"best_bid\":\"0.58\", \"best_ask\":\"0.6\"}], \"timestamp\":\"1785211479366\", \"event_type\":\"price_change\"}","received_at":"2026-07-28T04:04:39.352632Z","schema_version":"clob-market-ws.price_change.v1","sequence":null,"server_hash":null,"server_timestamp":"1785211479366","session_id":"2d607381e3054cee91998cdf45a4231c","source":"clob_market_ws"},"received_at":"2026-07-28T04:04:39.352632Z","record_id":"7261713e79ba9b18d7aeb0cfd659584eca0704622662714eab55aac64cda0ec8","schema_fingerprint":"4aa3821a28b0b7c2400bc59aba4bcc0a76e971dadd19610d3ad38c768e124dc7","schema_version":"edge-lab-recorder.raw.v1","sequence":null,"source":"clob_market_ws"}
{"event_at":"2026-07-28T04:04:39.366000Z","event_fingerprint":"779b4ef30241155d4f8aaa8a3fb2dffa0cc51ea08218b7a6e8ea8d08301b7065","payload":{"connection_id":"f6725804f86a4c4eb588e4d5ed7db029","event_at":"2026-07-28T04:04:39.366000Z","event_type":"price_change","frame_hash":"d8cd4f0cf0bab26bd13ba2340eee4a344a015fec88fb310cf08bc65e3f28dab2","frame_index":0,"kind":"data","monotonic_ns":313462404109791,"payload":{"event_type":"price_change","market":"0xd412ce774cfcf8dc9f71164aac78783978aac7b03871702a3b8a481bd9dc9688","price_changes":[{"asset_id":"96600821790790307414914106093858868634329285205417149685270682748367152458577","best_ask":"0.42","best_bid":"0.4","hash":"5b5a312753d8def14772479bd05cd0658febc339","price":"0.41","side":"BUY","size":"0"},{"asset_id":"107603864457683460275633293642179940881969192120168665300712204232021063124301","best_ask":"0.6","best_bid":"0.58","hash":"ea5dab70326d2ff3b785fe7eb8d85e39544b47dc","price":"0.59","side":"SELL","size":"0"}],"timestamp":"1785211479366"},"payload_hash":"d151e15358b0bc38f2dcd1a115ecfc9e1c58530766c88f514d03b34e8e5de5e9","raw_frame":"{\"market\":\"0xd412ce774cfcf8dc9f71164aac78783978aac7b03871702a3b8a481bd9dc9688\", \"price_changes\":[{\"asset_id\":\"96600821790790307414914106093858868634329285205417149685270682748367152458577\", \"price\":\"0.41\", \"size\":\"0\", \"side\":\"BUY\", \"hash\":\"5b5a312753d8def14772479bd05cd0658febc339\", \"best_bid\":\"0.4\", \"best_ask\":\"0.42\"}, {\"asset_id\":\"107603864457683460275633293642179940881969192120168665300712204232021063124301\", \"price\":\"0.59\", \"size\":\"0\", \"side\":\"SELL\", \"hash\":\"ea5dab70326d2ff3b785fe7eb8d85e39544b47dc\", \"best_bid\":\"0.58\", \"best_ask\":\"0.6\"}], \"timestamp\":\"1785211479366\", \"event_type\":\"price_change\"}","received_at":"2026-07-28T04:04:39.354129Z","schema_version":"clob-market-ws.price_change.v1","sequence":null,"server_hash":null,"server_timestamp":"1785211479366","session_id":"2d607381e3054cee91998cdf45a4231c","source":"clob_market_ws"},"received_at":"2026-07-28T04:04:39.354129Z","record_id":"4694656cdefbf189e76415d293ab01afe04eea944b95beb1ec6f569a34546758","schema_fingerprint":"4aa3821a28b0b7c2400bc59aba4bcc0a76e971dadd19610d3ad38c768e124dc7","schema_version":"edge-lab-recorder.raw.v1","sequence":null,"source":"clob_market_ws"}
{"event_at":"2026-07-28T04:04:39.366000Z","event_fingerprint":"9142ddbab5eb33f25008a44625fc43cf665194dc9d5fa1a2fd1e261715b4ff98","payload":{"connection_id":"f6725804f86a4c4eb588e4d5ed7db029","event_at":"2026-07-28T04:04:39.366000Z","event_type":"price_change","frame_hash":"9286ede2d3e94e773b87460a9f7eea2a7f614f031b54deb5915743328e3fbb1c","frame_index":0,"kind":"data","monotonic_ns":313462405716750,"payload":{"event_type":"price_change","market":"0xd412ce774cfcf8dc9f71164aac78783978aac7b03871702a3b8a481bd9dc9688","price_changes":[{"asset_id":"96600821790790307414914106093858868634329285205417149685270682748367152458577","best_ask":"0.42","best_bid":"0.4","hash":"5b5a312753d8def14772479bd05cd0658febc339","price":"0.46","side":"SELL","size":"92.84"},{"asset_id":"107603864457683460275633293642179940881969192120168665300712204232021063124301","best_ask":"0.6","best_bid":"0.58","hash":"ea5dab70326d2ff3b785fe7eb8d85e39544b47dc","price":"0.54","side":"BUY","size":"92.84"}],"timestamp":"1785211479366"},"payload_hash":"9d2c16a3949cbdd552c90a318dbdc515ca1a278d347d912f92e87f30e7e0798b","raw_frame":"{\"market\":\"0xd412ce774cfcf8dc9f71164aac78783978aac7b03871702a3b8a481bd9dc9688\", \"price_changes\":[{\"asset_id\":\"96600821790790307414914106093858868634329285205417149685270682748367152458577\", \"price\":\"0.46\", \"size\":\"92.84\", \"side\":\"SELL\", \"hash\":\"5b5a312753d8def14772479bd05cd0658febc339\", \"best_bid\":\"0.4\", \"best_ask\":\"0.42\"}, {\"asset_id\":\"107603864457683460275633293642179940881969192120168665300712204232021063124301\", \"price\":\"0.54\", \"size\":\"92.84\", \"side\":\"BUY\", \"hash\":\"ea5dab70326d2ff3b785fe7eb8d85e39544b47dc\", \"best_bid\":\"0.58\", \"best_ask\":\"0.6\"}], \"timestamp\":\"1785211479366\", \"event_type\":\"price_change\"}","received_at":"2026-07-28T04:04:39.355736Z","schema_version":"clob-market-ws.price_change.v1","sequence":null,"server_hash":null,"server_timestamp":"1785211479366","session_id":"2d607381e3054cee91998cdf45a4231c","source":"clob_market_ws"},"received_at":"2026-07-28T04:04:39.355736Z","record_id":"0e391787f185268d2c1384fc3c67cf17282ed8245cae028efcbdf59b8e491d5e","schema_fingerprint":"4aa3821a28b0b7c2400bc59aba4bcc0a76e971dadd19610d3ad38c768e124dc7","schema_version":"edge-lab-recorder.raw.v1","sequence":null,"source":"clob_market_ws"}
{"event_at":"2026-07-28T04:04:39.366000Z","event_fingerprint":"24e9b71e432a1921903353886ff285240a522f690e1a7f2490b91310231b752b","payload":{"connection_id":"f6725804f86a4c4eb588e4d5ed7db029","event_at":"2026-07-28T04:04:39.366000Z","event_type":"price_change","frame_hash":"495cb83b20bc87157d8bba3dbc5d849327c2752a217bdaf0f52ea04cf017052d","frame_index":0,"kind":"data","monotonic_ns":313462407226291,"payload":{"event_type":"price_change","market":"0xd412ce774cfcf8dc9f71164aac78783978aac7b03871702a3b8a481bd9dc9688","price_changes":[{"asset_id":"96600821790790307414914106093858868634329285205417149685270682748367152458577","best_ask":"0.42","best_bid":"0.4","hash":"5b5a312753d8def14772479bd05cd0658febc339","price":"0.47","side":"SELL","size":"88.2"},{"asset_id":"107603864457683460275633293642179940881969192120168665300712204232021063124301","best_ask":"0.6","best_bid":"0.58","hash":"ea5dab70326d2ff3b785fe7eb8d85e39544b47dc","price":"0.53","side":"BUY","size":"88.2"}],"timestamp":"1785211479366"},"payload_hash":"56d9f11ece61387e08c6de8db0231541254de80d7936412b480b630a5296fd7f","raw_frame":"{\"market\":\"0xd412ce774cfcf8dc9f71164aac78783978aac7b03871702a3b8a481bd9dc9688\", \"price_changes\":[{\"asset_id\":\"96600821790790307414914106093858868634329285205417149685270682748367152458577\", \"price\":\"0.47\", \"size\":\"88.2\", \"side\":\"SELL\", \"hash\":\"5b5a312753d8def14772479bd05cd0658febc339\", \"best_bid\":\"0.4\", \"best_ask\":\"0.42\"}, {\"asset_id\":\"107603864457683460275633293642179940881969192120168665300712204232021063124301\", \"price\":\"0.53\", \"size\":\"88.2\", \"side\":\"BUY\", \"hash\":\"ea5dab70326d2ff3b785fe7eb8d85e39544b47dc\", \"best_bid\":\"0.58\", \"best_ask\":\"0.6\"}], \"timestamp\":\"1785211479366\", \"event_type\":\"price_change\"}","received_at":"2026-07-28T04:04:39.357243Z","schema_version":"clob-market-ws.price_change.v1","sequence":null,"server_hash":null,"server_timestamp":"1785211479366","session_id":"2d607381e3054cee91998cdf45a4231c","source":"clob_market_ws"},"received_at":"2026-07-28T04:04:39.357243Z","record_id":"67b3d7b5dd12afdaf654feb3c2752f696804ae099d865838cdf785fb0b791475","schema_fingerprint":"4aa3821a28b0b7c2400bc59aba4bcc0a76e971dadd19610d3ad38c768e124dc7","schema_version":"edge-lab-recorder.raw.v1","sequence":null,"source":"clob_market_ws"}
{"event_at":"2026-07-28T04:04:39.367000Z","event_fingerprint":"9b14705bfee8c9038d58dc68ddecefd1369e820a476cf07ddb9ec97b0c597726","payload":{"connection_id":"f6725804f86a4c4eb588e4d5ed7db029","event_at":"2026-07-28T04:04:39.367000Z","event_type":"price_change","frame_hash":"16989a078f4693b8e93a92cfedf5c0497dffbdd42f6229ae7a6a5669395f312a","frame_index":0,"kind":"data","monotonic_ns":313462408835541,"payload":{"event_type":"price_change","market":"0xd412ce774cfcf8dc9f71164aac78783978aac7b03871702a3b8a481bd9dc9688","price_changes":[{"asset_id":"96600821790790307414914106093858868634329285205417149685270682748367152458577","best_ask":"0.42","best_bid":"0.4","hash":"348c5f6da5640a4d1d88ca6f03349bc91f08ef8e","price":"0.21","side":"BUY","size":"214.82"},{"asset_id":"107603864457683460275633293642179940881969192120168665300712204232021063124301","best_ask":"0.6","best_bid":"0.58","hash":"439f73bab2bb1c366ce250256d972d52e55f1299","price":"0.79","side":"SELL","size":"214.82"}],"timestamp":"1785211479367"},"payload_hash":"51cd14bebbe130c4dd49d28fa17df349a9deb932c3f0a9a22fafb3a7f6ed016d","raw_frame":"{\"market\":\"0xd412ce774cfcf8dc9f71164aac78783978aac7b03871702a3b8a481bd9dc9688\", \"price_changes\":[{\"asset_id\":\"96600821790790307414914106093858868634329285205417149685270682748367152458577\", \"price\":\"0.21\", \"size\":\"214.82\", \"side\":\"BUY\", \"hash\":\"348c5f6da5640a4d1d88ca6f03349bc91f08ef8e\", \"best_bid\":\"0.4\", \"best_ask\":\"0.42\"}, {\"asset_id\":\"107603864457683460275633293642179940881969192120168665300712204232021063124301\", \"price\":\"0.79\", \"size\":\"214.82\", \"side\":\"SELL\", \"hash\":\"439f73bab2bb1c366ce250256d972d52e55f1299\", \"best_bid\":\"0.58\", \"best_ask\":\"0.6\"}], \"timestamp\":\"1785211479367\", \"event_type\":\"price_change\"}","received_at":"2026-07-28T04:04:39.358854Z","schema_version":"clob-market-ws.price_change.v1","sequence":null,"server_hash":null,"server_timestamp":"1785211479367","session_id":"2d607381e3054cee91998cdf45a4231c","source":"clob_market_ws"},"received_at":"2026-07-28T04:04:39.358854Z","record_id":"5662eced299d869121a3d33f80bcb82986348bc68261567c2c8c94461a5dd325","schema_fingerprint":"4aa3821a28b0b7c2400bc59aba4bcc0a76e971dadd19610d3ad38c768e124dc7","schema_version":"edge-lab-recorder.raw.v1","sequence":null,"source":"clob_market_ws"}
