{"event_at":"2026-07-28T04:11:09.362000Z","event_fingerprint":"e4f78797467dde5c3c3fdb61d084655bd68122bd225ee5bd816cc5420cab688e","payload":{"connection_id":"f6725804f86a4c4eb588e4d5ed7db029","event_at":"2026-07-28T04:11:09.362000Z","event_type":"price_change","frame_hash":"d0f38e0e82769e22fbc1b86c5ceaaeb1f5c37556f9ef426c0744ce892633d6fc","frame_index":0,"kind":"data","monotonic_ns":313854594564750,"payload":{"event_type":"price_change","market":"0xd412ce774cfcf8dc9f71164aac78783978aac7b03871702a3b8a481bd9dc9688","price_changes":[{"asset_id":"107603864457683460275633293642179940881969192120168665300712204232021063124301","best_ask":"0.62","best_bid":"0.59","hash":"85aef1c992f5227d88d4829dc7b181fc1234fad1","price":"0.01","side":"BUY","size":"5638.02"},{"asset_id":"96600821790790307414914106093858868634329285205417149685270682748367152458577","best_ask":"0.41","best_bid":"0.38","hash":"3aebad5249680ae6eae261bb611645ccad94ec1c","price":"0.99","side":"SELL","size":"5638.02"}],"timestamp":"1785211869362"},"payload_hash":"cd008ecc4d9d417d7e737c069c8430120e30763a6251416a0a4f0d2b310683bf","raw_frame":"{\"market\":\"0xd412ce774cfcf8dc9f71164aac78783978aac7b03871702a3b8a481bd9dc9688\", \"price_changes\":[{\"asset_id\":\"107603864457683460275633293642179940881969192120168665300712204232021063124301\", \"price\":\"0.01\", \"size\":\"5638.02\", \"side\":\"BUY\", \"hash\":\"85aef1c992f5227d88d4829dc7b181fc1234fad1\", \"best_bid\":\"0.59\", \"best_ask\":\"0.62\"}, {\"asset_id\":\"96600821790790307414914106093858868634329285205417149685270682748367152458577\", \"price\":\"0.99\", \"size\":\"5638.02\", \"side\":\"SELL\", \"hash\":\"3aebad5249680ae6eae261bb611645ccad94ec1c\", \"best_bid\":\"0.38\", \"best_ask\":\"0.41\"}], \"timestamp\":\"1785211869362\", \"event_type\":\"price_change\"}","received_at":"2026-07-28T04:11:11.517959Z","schema_version":"clob-market-ws.price_change.v1","sequence":null,"server_hash":null,"server_timestamp":"1785211869362","session_id":"2d607381e3054cee91998cdf45a4231c","source":"clob_market_ws"},"received_at":"2026-07-28T04:11:11.517959Z","record_id":"47587853009cf24183aa0d61d9865c622e757081594e46837aa39e78e88f0a76","schema_fingerprint":"4aa3821a28b0b7c2400bc59aba4bcc0a76e971dadd19610d3ad38c768e124dc7","schema_version":"edge-lab-recorder.raw.v1","sequence":null,"source":"clob_market_ws"}
{"event_at":"2026-07-28T04:11:09.363000Z","event_fingerprint":"cc6b197199f692eb21f87840bb29619bef8107723d38690c472b3d80d50fb684","payload":{"connection_id":"f6725804f86a4c4eb588e4d5ed7db029","event_at":"2026-07-28T04:11:09.363000Z","event_type":"price_change","frame_hash":"466311525b8ed32e3b4577157a97db138eaf67cad2060c0bcb5e31880030ac8d","frame_index":0,"kind":"data","monotonic_ns":313854610894083,"payload":{"event_type":"price_change","market":"0xd412ce774cfcf8dc9f71164aac78783978aac7b03871702a3b8a481bd9dc9688","price_changes":[{"asset_id":"107603864457683460275633293642179940881969192120168665300712204232021063124301","best_ask":"0.62","best_bid":"0.59","hash":"9ac4066cd8bf9ddaf45f39a234e590de907da740","price":"0.87","side":"SELL","size":"85"},{"asset_id":"96600821790790307414914106093858868634329285205417149685270682748367152458577","best_ask":"0.41","best_bid":"0.38","hash":"7437857cd4222a0ea8563994e4f9de7599b1bf92","price":"0.13","side":"BUY","size":"85"}],"timestamp":"1785211869363"},"payload_hash":"907d1e77b2d9e9bf70a115a66bff85a8c2972fffe7db33371c9712de7ea9f9c3","raw_frame":"{\"market\":\"0xd412ce774cfcf8dc9f71164aac78783978aac7b03871702a3b8a481bd9dc9688\", \"price_changes\":[{\"asset_id\":\"107603864457683460275633293642179940881969192120168665300712204232021063124301\", \"price\":\"0.87\", \"size\":\"85\", \"side\":\"SELL\", \"hash\":\"9ac4066cd8bf9ddaf45f39a234e590de907da740\", \"best_bid\":\"0.59\", \"best_ask\":\"0.62\"}, {\"asset_id\":\"96600821790790307414914106093858868634329285205417149685270682748367152458577\", \"price\":\"0.13\", \"size\":\"85\", \"side\":\"BUY\", \"hash\":\"7437857cd4222a0ea8563994e4f9de7599b1bf92\", \"best_bid\":\"0.38\", \"best_ask\":\"0.41\"}], \"timestamp\":\"1785211869363\", \"event_type\":\"price_change\"}","received_at":"2026-07-28T04:11:11.534287Z","schema_version":"clob-market-ws.price_change.v1","sequence":null,"server_hash":null,"server_timestamp":"1785211869363","session_id":"2d607381e3054cee91998cdf45a4231c","source":"clob_market_ws"},"received_at":"2026-07-28T04:11:11.534287Z","record_id":"962a368486e1d8a7ca6b782988bb12314ced456a7a778de3a72d0083884eab9f","schema_fingerprint":"4aa3821a28b0b7c2400bc59aba4bcc0a76e971dadd19610d3ad38c768e124dc7","schema_version":"edge-lab-recorder.raw.v1","sequence":null,"source":"clob_market_ws"}
{"event_at":"2026-07-28T04:11:09.385000Z","event_fingerprint":"5d3cb115b04f7c55400f48780a201716dc8c5c7683b4c117eae24f3df1c58970","payload":{"connection_id":"f6725804f86a4c4eb588e4d5ed7db029","event_at":"2026-07-28T04:11:09.385000Z","event_type":"best_bid_ask","frame_hash":"0b388cd8966e93799be64c032a14def9e7867af0747202960ee2b7c7410a9fd6","frame_index":0,"kind":"data","monotonic_ns":313854617240416,"payload":{"asset_id":"107603864457683460275633293642179940881969192120168665300712204232021063124301","best_ask":"0.62","best_bid":"0.6","event_type":"best_bid_ask","market":"0xd412ce774cfcf8dc9f71164aac78783978aac7b03871702a3b8a481bd9dc9688","spread":"0.02","timestamp":"1785211869385"},"payload_hash":"9f46e40f43257fd09f576d23ee7a02789833470140cea393a241bc692ee7d819","raw_frame":"{\"market\":\"0xd412ce774cfcf8dc9f71164aac78783978aac7b03871702a3b8a481bd9dc9688\", \"asset_id\":\"107603864457683460275633293642179940881969192120168665300712204232021063124301\", \"best_bid\":\"0.6\", \"best_ask\":\"0.62\", \"spread\":\"0.02\", \"timestamp\":\"1785211869385\", \"event_type\":\"best_bid_ask\"}","received_at":"2026-07-28T04:11:11.540635Z","schema_version":"clob-market-ws.best_bid_ask.v1","sequence":null,"server_hash":null,"server_timestamp":"1785211869385","session_id":"2d607381e3054cee91998cdf45a4231c","source":"clob_market_ws"},"received_at":"2026-07-28T04:11:11.540635Z","record_id":"d747f73e5db801c3f089eb7a61c5f85c7613fc405bc9399cb93ae30535ae8f73","schema_fingerprint":"8488399f31b0337811b13b266be932db7062827c2470b78bd8e9e99bab51d17d","schema_version":"edge-lab-recorder.raw.v1","sequence":null,"source":"clob_market_ws"}
{"event_at":"2026-07-28T04:11:09.385000Z","event_fingerprint":"fdc897bb423e2f16f6fc9db65678e41088c7b0a4c76df7bae146ceefa5364af5","payload":{"connection_id":"f6725804f86a4c4eb588e4d5ed7db029","event_at":"2026-07-28T04:11:09.385000Z","event_type":"best_bid_ask","frame_hash":"381e60e1ae368c8d2461f67130b4e05a38460c2501a8f6df14e665d22da0fcc8","frame_index":0,"kind":"data","monotonic_ns":313854622497041,"payload":{"asset_id":"96600821790790307414914106093858868634329285205417149685270682748367152458577","best_ask":"0.4","best_bid":"0.38","event_type":"best_bid_ask","market":"0xd412ce774cfcf8dc9f71164aac78783978aac7b03871702a3b8a481bd9dc9688","spread":"0.02","timestamp":"1785211869385"},"payload_hash":"f638f1cce1946537169ec42732914da260668d69a2d425b8b503b7723e1bc509","raw_frame":"{\"market\":\"0xd412ce774cfcf8dc9f71164aac78783978aac7b03871702a3b8a481bd9dc9688\", \"asset_id\":\"96600821790790307414914106093858868634329285205417149685270682748367152458577\", \"best_bid\":\"0.38\", \"best_ask\":\"0.4\", \"spread\":\"0.02\", \"timestamp\":\"1785211869385\", \"event_type\":\"best_bid_ask\"}","received_at":"2026-07-28T04:11:11.545890Z","schema_version":"clob-market-ws.best_bid_ask.v1","sequence":null,"server_hash":null,"server_timestamp":"1785211869385","session_id":"2d607381e3054cee91998cdf45a4231c","source":"clob_market_ws"},"received_at":"2026-07-28T04:11:11.545890Z","record_id":"1cc90af0388efccf15e4fc7e47e45ab27af873acd47e57dc7d7595c4da6e33f5","schema_fingerprint":"8488399f31b0337811b13b266be932db7062827c2470b78bd8e9e99bab51d17d","schema_version":"edge-lab-recorder.raw.v1","sequence":null,"source":"clob_market_ws"}
{"event_at":"2026-07-28T04:11:09.385000Z","event_fingerprint":"2e979e2ed78fa3059ce11d1cf373f7df60c8de98a6b4ecc2656022556f50f26d","payload":{"connection_id":"f6725804f86a4c4eb588e4d5ed7db029","event_at":"2026-07-28T04:11:09.385000Z","event_type":"price_change","frame_hash":"b654d36c5ef99949b84f407578721d6dc5ab5de0eb6f336ae24c0fcd4f5df5c1","frame_index":0,"kind":"data","monotonic_ns":313854629370291,"payload":{"event_type":"price_change","market":"0xd412ce774cfcf8dc9f71164aac78783978aac7b03871702a3b8a481bd9dc9688","price_changes":[{"asset_id":"96600821790790307414914106093858868634329285205417149685270682748367152458577","best_ask":"0.4","best_bid":"0.38","hash":"71f002f08a8aa25c2c2a7a6d8ae448be5b09e6df","price":"0.4","side":"SELL","size":"5"},{"asset_id":"107603864457683460275633293642179940881969192120168665300712204232021063124301","best_ask":"0.62","best_bid":"0.6","hash":"e51e6ae0c53272f23423484600b98f50d8958e17","price":"0.6","side":"BUY","size":"5"}],"timestamp":"1785211869385"},"payload_hash":"d6f9fd95e461e102aa9961771b77123b13cf31aa33143db6402d03c1771fa4e6","raw_frame":"{\"market\":\"0xd412ce774cfcf8dc9f71164aac78783978aac7b03871702a3b8a481bd9dc9688\", \"price_changes\":[{\"asset_id\":\"96600821790790307414914106093858868634329285205417149685270682748367152458577\", \"price\":\"0.4\", \"size\":\"5\", \"side\":\"SELL\", \"hash\":\"71f002f08a8aa25c2c2a7a6d8ae448be5b09e6df\", \"best_bid\":\"0.38\", \"best_ask\":\"0.4\"}, {\"asset_id\":\"107603864457683460275633293642179940881969192120168665300712204232021063124301\", \"price\":\"0.6\", \"size\":\"5\", \"side\":\"BUY\", \"hash\":\"e51e6ae0c53272f23423484600b98f50d8958e17\", \"best_bid\":\"0.6\", \"best_ask\":\"0.62\"}], \"timestamp\":\"1785211869385\", \"event_type\":\"price_change\"}","received_at":"2026-07-28T04:11:11.552765Z","schema_version":"clob-market-ws.price_change.v1","sequence":null,"server_hash":null,"server_timestamp":"1785211869385","session_id":"2d607381e3054cee91998cdf45a4231c","source":"clob_market_ws"},"received_at":"2026-07-28T04:11:11.552765Z","record_id":"da1d249c2d753ea829af6ee2bea0f3afa070f87ebf1ae989564f6c35579395f5","schema_fingerprint":"4aa3821a28b0b7c2400bc59aba4bcc0a76e971dadd19610d3ad38c768e124dc7","schema_version":"edge-lab-recorder.raw.v1","sequence":null,"source":"clob_market_ws"}
{"event_at":"2026-07-28T04:11:09.391000Z","event_fingerprint":"7c97a326282791ec3b3c7ebcac23e7cc3ad1d5565650e72a4d0e1130f62485d3","payload":{"connection_id":"f6725804f86a4c4eb588e4d5ed7db029","event_at":"2026-07-28T04:11:09.391000Z","event_type":"price_change","frame_hash":"9034cbef2fa1d8b1062b24700e2c9e47a0e89938dacff44704679e265231e450","frame_index":0,"kind":"data","monotonic_ns":313854634053000,"payload":{"event_type":"price_change","market":"0xd412ce774cfcf8dc9f71164aac78783978aac7b03871702a3b8a481bd9dc9688","price_changes":[{"asset_id":"107603864457683460275633293642179940881969192120168665300712204232021063124301","best_ask":"0.62","best_bid":"0.6","hash":"234b2363e4fb077b63dc926ae455dd7374baea39","price":"0.6","side":"BUY","size":"12"},{"asset_id":"96600821790790307414914106093858868634329285205417149685270682748367152458577","best_ask":"0.4","best_bid":"0.38","hash":"8e344444250b469561dace39c1400087704f7c9e","price":"0.4","side":"SELL","size":"12"}],"timestamp":"1785211869391"},"payload_hash":"3df5f85ff9fce7f008204c3629777a3ce016e70e2948bab1d4a85f440ade7ffa","raw_frame":"{\"market\":\"0xd412ce774cfcf8dc9f71164aac78783978aac7b03871702a3b8a481bd9dc9688\", \"price_changes\":[{\"asset_id\":\"107603864457683460275633293642179940881969192120168665300712204232021063124301\", \"price\":\"0.6\", \"size\":\"12\", \"side\":\"BUY\", \"hash\":\"234b2363e4fb077b63dc926ae455dd7374baea39\", \"best_bid\":\"0.6\", \"best_ask\":\"0.62\"}, {\"asset_id\":\"96600821790790307414914106093858868634329285205417149685270682748367152458577\", \"price\":\"0.4\", \"size\":\"12\", \"side\":\"SELL\", \"hash\":\"8e344444250b469561dace39c1400087704f7c9e\", \"best_bid\":\"0.38\", \"best_ask\":\"0.4\"}], \"timestamp\":\"1785211869391\", \"event_type\":\"price_change\"}","received_at":"2026-07-28T04:11:11.557446Z","schema_version":"clob-market-ws.price_change.v1","sequence":null,"server_hash":null,"server_timestamp":"1785211869391","session_id":"2d607381e3054cee91998cdf45a4231c","source":"clob_market_ws"},"received_at":"2026-07-28T04:11:11.557446Z","record_id":"7c0d322abe8333ab3af9b48bc7169cd367baa42da13b1fcc4290162ae45e4a09","schema_fingerprint":"4aa3821a28b0b7c2400bc59aba4bcc0a76e971dadd19610d3ad38c768e124dc7","schema_version":"edge-lab-recorder.raw.v1","sequence":null,"source":"clob_market_ws"}
{"event_at":"2026-07-28T04:11:09.393000Z","event_fingerprint":"10dfdfa6a9bff42a2e6f5f1d29e50ff6a1584fe23be0ebb0b2396e5b753eae40","payload":{"connection_id":"f6725804f86a4c4eb588e4d5ed7db029","event_at":"2026-07-28T04:11:09.393000Z","event_type":"price_change","frame_hash":"3aaf20eab415421c1887c6cc84c8da9b7a03f69da6381bdf78a1528caee74229","frame_index":0,"kind":"data","monotonic_ns":313854638480625,"payload":{"event_type":"price_change","market":"0xd412ce774cfcf8dc9f71164aac78783978aac7b03871702a3b8a481bd9dc9688","price_changes":[{"asset_id":"107603864457683460275633293642179940881969192120168665300712204232021063124301","best_ask":"0.62","best_bid":"0.6","hash":"c62e71c9a6010053b35f6f5bbd286a004bf85e2b","price":"0.01","side":"BUY","size":"5633.02"},{"asset_id":"96600821790790307414914106093858868634329285205417149685270682748367152458577","best_ask":"0.4","best_bid":"0.38","hash":"f7ae0aca47f529646d9d055555b0f9b123d37fa9","price":"0.99","side":"SELL","size":"5633.02"}],"timestamp":"1785211869393"},"payload_hash":"aa96356acda37a28b054b656e6f5c0427b53e6f503b7e6e4c8819054e31851c5","raw_frame":"{\"market\":\"0xd412ce774cfcf8dc9f71164aac78783978aac7b03871702a3b8a481bd9dc9688\", \"price_changes\":[{\"asset_id\":\"107603864457683460275633293642179940881969192120168665300712204232021063124301\", \"price\":\"0.01\", \"size\":\"5633.02\", \"side\":\"BUY\", \"hash\":\"c62e71c9a6010053b35f6f5bbd286a004bf85e2b\", \"best_bid\":\"0.6\", \"best_ask\":\"0.62\"}, {\"asset_id\":\"96600821790790307414914106093858868634329285205417149685270682748367152458577\", \"price\":\"0.99\", \"size\":\"5633.02\", \"side\":\"SELL\", \"hash\":\"f7ae0aca47f529646d9d055555b0f9b123d37fa9\", \"best_bid\":\"0.38\", \"best_ask\":\"0.4\"}], \"timestamp\":\"1785211869393\", \"event_type\":\"price_change\"}","received_at":"2026-07-28T04:11:11.561876Z","schema_version":"clob-market-ws.price_change.v1","sequence":null,"server_hash":null,"server_timestamp":"1785211869393","session_id":"2d607381e3054cee91998cdf45a4231c","source":"clob_market_ws"},"received_at":"2026-07-28T04:11:11.561876Z","record_id":"7c013b9957f2a757e621eb418d71854d7d5b4de2cfde5d9c0f4cf793746391f8","schema_fingerprint":"4aa3821a28b0b7c2400bc59aba4bcc0a76e971dadd19610d3ad38c768e124dc7","schema_version":"edge-lab-recorder.raw.v1","sequence":null,"source":"clob_market_ws"}
{"event_at":"2026-07-28T04:11:09.395000Z","event_fingerprint":"46b7793fa79af670bf1da1ac44515c22e1cb47f82188bbf53d6f00125e55a82f","payload":{"connection_id":"f6725804f86a4c4eb588e4d5ed7db029","event_at":"2026-07-28T04:11:09.395000Z","event_type":"price_change","frame_hash":"edeacfafdb1c9032b5c45d6ecfbba85b5558a26b0955d9afaffca1243d0f5f46","frame_index":0,"kind":"data","monotonic_ns":313854642432916,"payload":{"event_type":"price_change","market":"0xd412ce774cfcf8dc9f71164aac78783978aac7b03871702a3b8a481bd9dc9688","price_changes":[{"asset_id":"107603864457683460275633293642179940881969192120168665300712204232021063124301","best_ask":"0.62","best_bid":"0.6","hash":"1573ffa27320c591db52df6195c20e8d343a1077","price":"0.02","side":"BUY","size":"688.1"},{"asset_id":"96600821790790307414914106093858868634329285205417149685270682748367152458577","best_ask":"0.4","best_bid":"0.38","hash":"59a2d57504832a0bb24419c5eb7a1c4da92dec69","price":"0.98","side":"SELL","size":"688.1"}],"timestamp":"1785211869395"},"payload_hash":"f49ac67f07525a6f1a19a8ec323022adf83602129544e7cf2c625fa6d6404a4d","raw_frame":"{\"market\":\"0xd412ce774cfcf8dc9f71164aac78783978aac7b03871702a3b8a481bd9dc9688\", \"price_changes\":[{\"asset_id\":\"107603864457683460275633293642179940881969192120168665300712204232021063124301\", \"price\":\"0.02\", \"size\":\"688.1\", \"side\":\"BUY\", \"hash\":\"1573ffa27320c591db52df6195c20e8d343a1077\", \"best_bid\":\"0.6\", \"best_ask\":\"0.62\"}, {\"asset_id\":\"96600821790790307414914106093858868634329285205417149685270682748367152458577\", \"price\":\"0.98\", \"size\":\"688.1\", \"side\":\"SELL\", \"hash\":\"59a2d57504832a0bb24419c5eb7a1c4da92dec69\", \"best_bid\":\"0.38\", \"best_ask\":\"0.4\"}], \"timestamp\":\"1785211869395\", \"event_type\":\"price_change\"}","received_at":"2026-07-28T04:11:11.565828Z","schema_version":"clob-market-ws.price_change.v1","sequence":null,"server_hash":null,"server_timestamp":"1785211869395","session_id":"2d607381e3054cee91998cdf45a4231c","source":"clob_market_ws"},"received_at":"2026-07-28T04:11:11.565828Z","record_id":"0835cc62e6cd03fb5f3d7c4879765bbc928340266a01b968e024215478e809ee","schema_fingerprint":"4aa3821a28b0b7c2400bc59aba4bcc0a76e971dadd19610d3ad38c768e124dc7","schema_version":"edge-lab-recorder.raw.v1","sequence":null,"source":"clob_market_ws"}
{"event_at":"2026-07-28T04:11:09.401000Z","event_fingerprint":"6253cad40b8eb1a2ce93629918fedadc0f4e3c6d66dd9816d2326d4d3d7561b3","payload":{"connection_id":"f6725804f86a4c4eb588e4d5ed7db029","event_at":"2026-07-28T04:11:09.401000Z","event_type":"price_change","frame_hash":"4f2e4ff987bea1c2d1e4ba0aa0d203906b35539a880ef226530b21ccfdff1905","frame_index":0,"kind":"data","monotonic_ns":313854645761833,"payload":{"event_type":"price_change","market":"0xd412ce774cfcf8dc9f71164aac78783978aac7b03871702a3b8a481bd9dc9688","price_changes":[{"asset_id":"107603864457683460275633293642179940881969192120168665300712204232021063124301","best_ask":"0.62","best_bid":"0.6","hash":"b3fa5c8b266a8eb99cc0ad28bc4b0b0d1a8af5fb","price":"0.6","side":"BUY","size":"5"},{"asset_id":"96600821790790307414914106093858868634329285205417149685270682748367152458577","best_ask":"0.4","best_bid":"0.38","hash":"9074332d29b5c36e3c4dccd5a8155167a8389b05","price":"0.4","side":"SELL","size":"5"}],"timestamp":"1785211869401"},"payload_hash":"d7b5ed375d0dc0516eceff3a0976ab43e9b0affa9677dd549df9b1646cbf663c","raw_frame":"{\"market\":\"0xd412ce774cfcf8dc9f71164aac78783978aac7b03871702a3b8a481bd9dc9688\", \"price_changes\":[{\"asset_id\":\"107603864457683460275633293642179940881969192120168665300712204232021063124301\", \"price\":\"0.6\", \"size\":\"5\", \"side\":\"BUY\", \"hash\":\"b3fa5c8b266a8eb99cc0ad28bc4b0b0d1a8af5fb\", \"best_bid\":\"0.6\", \"best_ask\":\"0.62\"}, {\"asset_id\":\"96600821790790307414914106093858868634329285205417149685270682748367152458577\", \"price\":\"0.4\", \"size\":\"5\", \"side\":\"SELL\", \"hash\":\"9074332d29b5c36e3c4dccd5a8155167a8389b05\", \"best_bid\":\"0.38\", \"best_ask\":\"0.4\"}], \"timestamp\":\"1785211869401\", \"event_type\":\"price_change\"}","received_at":"2026-07-28T04:11:11.569157Z","schema_version":"clob-market-ws.price_change.v1","sequence":null,"server_hash":null,"server_timestamp":"1785211869401","session_id":"2d607381e3054cee91998cdf45a4231c","source":"clob_market_ws"},"received_at":"2026-07-28T04:11:11.569157Z","record_id":"8220038fd0a234e47c16c56c94c709315bc66e2f29246aea919916935bf99397","schema_fingerprint":"4aa3821a28b0b7c2400bc59aba4bcc0a76e971dadd19610d3ad38c768e124dc7","schema_version":"edge-lab-recorder.raw.v1","sequence":null,"source":"clob_market_ws"}
{"event_at":"2026-07-28T04:11:09.403000Z","event_fingerprint":"507cd169dfc075ab53aab9673771c05a96a618f2dc227fc393c1e30a26f60c54","payload":{"connection_id":"f6725804f86a4c4eb588e4d5ed7db029","event_at":"2026-07-28T04:11:09.403000Z","event_type":"best_bid_ask","frame_hash":"c6f1d5559780b96546be90bda76f548f5c7fd377b3c6fb22c0884e4d0914f65a","frame_index":0,"kind":"data","monotonic_ns":313854649469666,"payload":{"asset_id":"107603864457683460275633293642179940881969192120168665300712204232021063124301","best_ask":"0.62","best_bid":"0.59","event_type":"best_bid_ask","market":"0xd412ce774cfcf8dc9f71164aac78783978aac7b03871702a3b8a481bd9dc9688","spread":"0.03","timestamp":"1785211869403"},"payload_hash":"2ef53f9a92399848634c6ede5dba87e55f881e85e928477f23c977532948dbdd","raw_frame":"{\"market\":\"0xd412ce774cfcf8dc9f71164aac78783978aac7b03871702a3b8a481bd9dc9688\", \"asset_id\":\"107603864457683460275633293642179940881969192120168665300712204232021063124301\", \"best_bid\":\"0.59\", \"best_ask\":\"0.62\", \"spread\":\"0.03\", \"timestamp\":\"1785211869403\", \"event_type\":\"best_bid_ask\"}","received_at":"2026-07-28T04:11:11.572865Z","schema_version":"clob-market-ws.best_bid_ask.v1","sequence":null,"server_hash":null,"server_timestamp":"1785211869403","session_id":"2d607381e3054cee91998cdf45a4231c","source":"clob_market_ws"},"received_at":"2026-07-28T04:11:11.572865Z","record_id":"07fbc8a91ff85a9250b8e7e062176c97c428199e1a1f1ae13fd6fb6b04c0649a","schema_fingerprint":"8488399f31b0337811b13b266be932db7062827c2470b78bd8e9e99bab51d17d","schema_version":"edge-lab-recorder.raw.v1","sequence":null,"source":"clob_market_ws"}
{"event_at":"2026-07-28T04:11:09.403000Z","event_fingerprint":"382c1a712a993b01c9d6749a5a0ddf50a9de2b61a960da4376abd869ebfee800","payload":{"connection_id":"f6725804f86a4c4eb588e4d5ed7db029","event_at":"2026-07-28T04:11:09.403000Z","event_type":"best_bid_ask","frame_hash":"5cb2f196f3187e01dba2fd3a98713082c499e2af210f20f696061862d42b6ffa","frame_index":0,"kind":"data","monotonic_ns":313854653203333,"payload":{"asset_id":"96600821790790307414914106093858868634329285205417149685270682748367152458577","best_ask":"0.41","best_bid":"0.38","event_type":"best_bid_ask","market":"0xd412ce774cfcf8dc9f71164aac78783978aac7b03871702a3b8a481bd9dc9688","spread":"0.03","timestamp":"1785211869403"},"payload_hash":"38cdd4481f85275b7575ac0efe84063694b04dc5bcc6a371d7205e256626597d","raw_frame":"{\"market\":\"0xd412ce774cfcf8dc9f71164aac78783978aac7b03871702a3b8a481bd9dc9688\", \"asset_id\":\"96600821790790307414914106093858868634329285205417149685270682748367152458577\", \"best_bid\":\"0.38\", \"best_ask\":\"0.41\", \"spread\":\"0.03\", \"timestamp\":\"1785211869403\", \"event_type\":\"best_bid_ask\"}","received_at":"2026-07-28T04:11:11.576599Z","schema_version":"clob-market-ws.best_bid_ask.v1","sequence":null,"server_hash":null,"server_timestamp":"1785211869403","session_id":"2d607381e3054cee91998cdf45a4231c","source":"clob_market_ws"},"received_at":"2026-07-28T04:11:11.576599Z","record_id":"1b124e205615d9d84baeebebd77e956b77297ba70717ffb9d071475e64abf13b","schema_fingerprint":"8488399f31b0337811b13b266be932db7062827c2470b78bd8e9e99bab51d17d","schema_version":"edge-lab-recorder.raw.v1","sequence":null,"source":"clob_market_ws"}
{"event_at":"2026-07-28T04:11:09.403000Z","event_fingerprint":"371d10c063a40f0c0988277cfe8d8c56747791d9f953087a3347ebf96392bfab","payload":{"connection_id":"f6725804f86a4c4eb588e4d5ed7db029","event_at":"2026-07-28T04:11:09.403000Z","event_type":"price_change","frame_hash":"10269fc3a0d4bf9170cd923834dc14f931c5e9adb6371bee9794b56f46bd3ab0","frame_index":0,"kind":"data","monotonic_ns":313854657119166,"payload":{"event_type":"price_change","market":"0xd412ce774cfcf8dc9f71164aac78783978aac7b03871702a3b8a481bd9dc9688","price_changes":[{"asset_id":"96600821790790307414914106093858868634329285205417149685270682748367152458577","best_ask":"0.41","best_bid":"0.38","hash":"7443b9c5148b2a89e420e0a9c544703bd147f977","price":"0.4","side":"SELL","size":"0"},{"asset_id":"107603864457683460275633293642179940881969192120168665300712204232021063124301","best_ask":"0.62","best_bid":"0.59","hash":"c91a5cd517bf224d475888ae3524ab913f6f911b","price":"0.6","side":"BUY","size":"0"}],"timestamp":"1785211869403"},"payload_hash":"86abdf924fe46f6b26cf0afbc0ba769baeb4068ed149e8c84edca571c2ffbf84","raw_frame":"{\"market\":\"0xd412ce774cfcf8dc9f71164aac78783978aac7b03871702a3b8a481bd9dc9688\", \"price_changes\":[{\"asset_id\":\"96600821790790307414914106093858868634329285205417149685270682748367152458577\", \"price\":\"0.4\", \"size\":\"0\", \"side\":\"SELL\", \"hash\":\"7443b9c5148b2a89e420e0a9c544703bd147f977\", \"best_bid\":\"0.38\", \"best_ask\":\"0.41\"}, {\"asset_id\":\"107603864457683460275633293642179940881969192120168665300712204232021063124301\", \"price\":\"0.6\", \"size\":\"0\", \"side\":\"BUY\", \"hash\":\"c91a5cd517bf224d475888ae3524ab913f6f911b\", \"best_bid\":\"0.59\", \"best_ask\":\"0.62\"}], \"timestamp\":\"1785211869403\", \"event_type\":\"price_change\"}","received_at":"2026-07-28T04:11:11.580515Z","schema_version":"clob-market-ws.price_change.v1","sequence":null,"server_hash":null,"server_timestamp":"1785211869403","session_id":"2d607381e3054cee91998cdf45a4231c","source":"clob_market_ws"},"received_at":"2026-07-28T04:11:11.580515Z","record_id":"7aedc1e32bcfd86b8cd534b6f4a04bd51b55b1ba72b581c9b74a98229bff6c44","schema_fingerprint":"4aa3821a28b0b7c2400bc59aba4bcc0a76e971dadd19610d3ad38c768e124dc7","schema_version":"edge-lab-recorder.raw.v1","sequence":null,"source":"clob_market_ws"}
{"event_at":"2026-07-28T04:11:09.407000Z","event_fingerprint":"59608b52d1911e2052a51818c7078dbe1613a390d84387a4d92a92707c3f41cc","payload":{"connection_id":"f6725804f86a4c4eb588e4d5ed7db029","event_at":"2026-07-28T04:11:09.407000Z","event_type":"best_bid_ask","frame_hash":"f6676582475e2a281c1ade72868a3b9c5cd5533e3e99cfb724a36dd0a5c25a33","frame_index":0,"kind":"data","monotonic_ns":313854660644500,"payload":{"asset_id":"107603864457683460275633293642179940881969192120168665300712204232021063124301","best_ask":"0.62","best_bid":"0.61","event_type":"best_bid_ask","market":"0xd412ce774cfcf8dc9f71164aac78783978aac7b03871702a3b8a481bd9dc9688","spread":"0.01","timestamp":"1785211869407"},"payload_hash":"ca8c703d31f24712dcfb98689cdee04c22f94773ad7dca6e0d0535e978a23ef3","raw_frame":"{\"market\":\"0xd412ce774cfcf8dc9f71164aac78783978aac7b03871702a3b8a481bd9dc9688\", \"asset_id\":\"107603864457683460275633293642179940881969192120168665300712204232021063124301\", \"best_bid\":\"0.61\", \"best_ask\":\"0.62\", \"spread\":\"0.01\", \"timestamp\":\"1785211869407\", \"event_type\":\"best_bid_ask\"}","received_at":"2026-07-28T04:11:11.584039Z","schema_version":"clob-market-ws.best_bid_ask.v1","sequence":null,"server_hash":null,"server_timestamp":"1785211869407","session_id":"2d607381e3054cee91998cdf45a4231c","source":"clob_market_ws"},"received_at":"2026-07-28T04:11:11.584039Z","record_id":"362b2070b4b6e1ba696729c1cb6bd842e8834d1b7d5d35397164523e7b39e094","schema_fingerprint":"8488399f31b0337811b13b266be932db7062827c2470b78bd8e9e99bab51d17d","schema_version":"edge-lab-recorder.raw.v1","sequence":null,"source":"clob_market_ws"}
{"event_at":"2026-07-28T04:11:09.407000Z","event_fingerprint":"1ca7d1860df3540a074d27b59e4325c428d0e294fa2ac2094fda72076f7c5eb9","payload":{"connection_id":"f6725804f86a4c4eb588e4d5ed7db029","event_at":"2026-07-28T04:11:09.407000Z","event_type":"best_bid_ask","frame_hash":"91531a380fcc024b53be924986779bc2b1e7be7e5c2f2c42343dfcfa7ea443c9","frame_index":0,"kind":"data","monotonic_ns":313854664482375,"payload":{"asset_id":"96600821790790307414914106093858868634329285205417149685270682748367152458577","best_ask":"0.39","best_bid":"0.38","event_type":"best_bid_ask","market":"0xd412ce774cfcf8dc9f71164aac78783978aac7b03871702a3b8a481bd9dc9688","spread":"0.01","timestamp":"1785211869407"},"payload_hash":"fc9881e35d79e234613e9a767df1ead86931a229c2dccbbef440752b6d1f3ae0","raw_frame":"{\"market\":\"0xd412ce774cfcf8dc9f71164aac78783978aac7b03871702a3b8a481bd9dc9688\", \"asset_id\":\"96600821790790307414914106093858868634329285205417149685270682748367152458577\", \"best_bid\":\"0.38\", \"best_ask\":\"0.39\", \"spread\":\"0.01\", \"timestamp\":\"1785211869407\", \"event_type\":\"best_bid_ask\"}","received_at":"2026-07-28T04:11:11.587877Z","schema_version":"clob-market-ws.best_bid_ask.v1","sequence":null,"server_hash":null,"server_timestamp":"1785211869407","session_id":"2d607381e3054cee91998cdf45a4231c","source":"clob_market_ws"},"received_at":"2026-07-28T04:11:11.587877Z","record_id":"651ba9be4b897455832c466fbf3ce2746b583547c97a969b8b0966c50c167518","schema_fingerprint":"8488399f31b0337811b13b266be932db7062827c2470b78bd8e9e99bab51d17d","schema_version":"edge-lab-recorder.raw.v1","sequence":null,"source":"clob_market_ws"}
{"event_at":"2026-07-28T04:11:09.407000Z","event_fingerprint":"3adb119f549cd1a115af78063680259db88385052d0cdd5fd08c282d10fb0504","payload":{"connection_id":"f6725804f86a4c4eb588e4d5ed7db029","event_at":"2026-07-28T04:11:09.407000Z","event_type":"price_change","frame_hash":"5c4e452e1ab0266ca9296ce20e64f11cb0fbf850f263f0745b61c3ac4e92a939","frame_index":0,"kind":"data","monotonic_ns":313854668414500,"payload":{"event_type":"price_change","market":"0xd412ce774cfcf8dc9f71164aac78783978aac7b03871702a3b8a481bd9dc9688","price_changes":[{"asset_id":"96600821790790307414914106093858868634329285205417149685270682748367152458577","best_ask":"0.39","best_bid":"0.38","hash":"88868ea1ecfaecf2e21e13111f2a5ff5b45633ef","price":"0.39","side":"SELL","size":"7"},{"asset_id":"107603864457683460275633293642179940881969192120168665300712204232021063124301","best_ask":"0.62","best_bid":"0.61","hash":"21ea278b104111fca8e5b598af05039112bb8645","price":"0.61","side":"BUY","size":"7"}],"timestamp":"1785211869407"},"payload_hash":"6afa32c250ffd8bf41bf28d76571daaf405760826f158066959ec460b037073e","raw_frame":"{\"market\":\"0xd412ce774cfcf8dc9f71164aac78783978aac7b03871702a3b8a481bd9dc9688\", \"price_changes\":[{\"asset_id\":\"96600821790790307414914106093858868634329285205417149685270682748367152458577\", \"price\":\"0.39\", \"size\":\"7\", \"side\":\"SELL\", \"hash\":\"88868ea1ecfaecf2e21e13111f2a5ff5b45633ef\", \"best_bid\":\"0.38\", \"best_ask\":\"0.39\"}, {\"asset_id\":\"107603864457683460275633293642179940881969192120168665300712204232021063124301\", \"price\":\"0.61\", \"size\":\"7\", \"side\":\"BUY\", \"hash\":\"21ea278b104111fca8e5b598af05039112bb8645\", \"best_bid\":\"0.61\", \"best_ask\":\"0.62\"}], \"timestamp\":\"1785211869407\", \"event_type\":\"price_change\"}","received_at":"2026-07-28T04:11:11.591807Z","schema_version":"clob-market-ws.price_change.v1","sequence":null,"server_hash":null,"server_timestamp":"1785211869407","session_id":"2d607381e3054cee91998cdf45a4231c","source":"clob_market_ws"},"received_at":"2026-07-28T04:11:11.591807Z","record_id":"f196a3e476500531771dd440d00274c95e203918412e1dc7d9dfb55bded812c5","schema_fingerprint":"4aa3821a28b0b7c2400bc59aba4bcc0a76e971dadd19610d3ad38c768e124dc7","schema_version":"edge-lab-recorder.raw.v1","sequence":null,"source":"clob_market_ws"}
{"event_at":"2026-07-28T04:11:09.419000Z","event_fingerprint":"216b51217a8b06c5b3360fbc866171b43c1dcfda5b4cf3a91f2294cff539dbc6","payload":{"connection_id":"f6725804f86a4c4eb588e4d5ed7db029","event_at":"2026-07-28T04:11:09.419000Z","event_type":"best_bid_ask","frame_hash":"b17a6073fe19cb2147d5955b1e6fb7ddbe1f1973b96a8c96f078f993b1e622d0","frame_index":0,"kind":"data","monotonic_ns":313854672690750,"payload":{"asset_id":"107603864457683460275633293642179940881969192120168665300712204232021063124301","best_ask":"0.62","best_bid":"0.59","event_type":"best_bid_ask","market":"0xd412ce774cfcf8dc9f71164aac78783978aac7b03871702a3b8a481bd9dc9688","spread":"0.03","timestamp":"1785211869419"},"payload_hash":"9e006d536f7e36c287c29a72a2e3ad5bcb85a4cafb025b30904d025e185c79d3","raw_frame":"{\"market\":\"0xd412ce774cfcf8dc9f71164aac78783978aac7b03871702a3b8a481bd9dc9688\", \"asset_id\":\"107603864457683460275633293642179940881969192120168665300712204232021063124301\", \"best_bid\":\"0.59\", \"best_ask\":\"0.62\", \"spread\":\"0.03\", \"timestamp\":\"1785211869419\", \"event_type\":\"best_bid_ask\"}","received_at":"2026-07-28T04:11:11.596085Z","schema_version":"clob-market-ws.best_bid_ask.v1","sequence":null,"server_hash":null,"server_timestamp":"1785211869419","session_id":"2d607381e3054cee91998cdf45a4231c","source":"clob_market_ws"},"received_at":"2026-07-28T04:11:11.596085Z","record_id":"86b30700cf8fbdf546445a34c297f2dd5a3aca845e00166e1c87dc3bb89a9850","schema_fingerprint":"8488399f31b0337811b13b266be932db7062827c2470b78bd8e9e99bab51d17d","schema_version":"edge-lab-recorder.raw.v1","sequence":null,"source":"clob_market_ws"}
{"event_at":"2026-07-28T04:11:09.419000Z","event_fingerprint":"a83513024f3caa004ef9f7773a973f16852ac6afb96d8257cc571d6e17591871","payload":{"connection_id":"f6725804f86a4c4eb588e4d5ed7db029","event_at":"2026-07-28T04:11:09.419000Z","event_type":"best_bid_ask","frame_hash":"0f02a96b74397314c2ad5664bf49e994223ed8e1adc9e525c2d71d01d2f7985a","frame_index":0,"kind":"data","monotonic_ns":313854676514083,"payload":{"asset_id":"96600821790790307414914106093858868634329285205417149685270682748367152458577","best_ask":"0.41","best_bid":"0.38","event_type":"best_bid_ask","market":"0xd412ce774cfcf8dc9f71164aac78783978aac7b03871702a3b8a481bd9dc9688","spread":"0.03","timestamp":"1785211869419"},"payload_hash":"a9c8d0c01480996087a1a287c82705e4022bba3d71b72176b81d84c001db2744","raw_frame":"{\"market\":\"0xd412ce774cfcf8dc9f71164aac78783978aac7b03871702a3b8a481bd9dc9688\", \"asset_id\":\"96600821790790307414914106093858868634329285205417149685270682748367152458577\", \"best_bid\":\"0.38\", \"best_ask\":\"0.41\", \"spread\":\"0.03\", \"timestamp\":\"1785211869419\", \"event_type\":\"best_bid_ask\"}","received_at":"2026-07-28T04:11:11.599909Z","schema_version":"clob-market-ws.best_bid_ask.v1","sequence":null,"server_hash":null,"server_timestamp":"1785211869419","session_id":"2d607381e3054cee91998cdf45a4231c","source":"clob_market_ws"},"received_at":"2026-07-28T04:11:11.599909Z","record_id":"44b3a3cb112294863c168ef0f24ad7eb05086f40dcd9a50e4ab35de5408cdaeb","schema_fingerprint":"8488399f31b0337811b13b266be932db7062827c2470b78bd8e9e99bab51d17d","schema_version":"edge-lab-recorder.raw.v1","sequence":null,"source":"clob_market_ws"}
{"event_at":"2026-07-28T04:11:09.419000Z","event_fingerprint":"6bd674cd4846f64b298379fbf5063c33727150efe33847d34f224cbc47f88fe2","payload":{"connection_id":"f6725804f86a4c4eb588e4d5ed7db029","event_at":"2026-07-28T04:11:09.419000Z","event_type":"price_change","frame_hash":"02d0804533b649cf1c48ab72e19cbc893ce3f24a8ca2434a1ad9706d373f42a6","frame_index":0,"kind":"data","monotonic_ns":313854680259041,"payload":{"event_type":"price_change","market":"0xd412ce774cfcf8dc9f71164aac78783978aac7b03871702a3b8a481bd9dc9688","price_changes":[{"asset_id":"96600821790790307414914106093858868634329285205417149685270682748367152458577","best_ask":"0.41","best_bid":"0.38","hash":"cf3ed4d2e47e305c35a806a6bf91c9e37765fd78","price":"0.39","side":"SELL","size":"0"},{"asset_id":"107603864457683460275633293642179940881969192120168665300712204232021063124301","best_ask":"0.62","best_bid":"0.59","hash":"f1c1642cdbe4e0927810f81f23c454a0324f0533","price":"0.61","side":"BUY","size":"0"}],"timestamp":"1785211869419"},"payload_hash":"81a54264d60448f0c0acafda09d0e2e8f20b963505b255855a911a1f80ab9736","raw_frame":"{\"market\":\"0xd412ce774cfcf8dc9f71164aac78783978aac7b03871702a3b8a481bd9dc9688\", \"price_changes\":[{\"asset_id\":\"96600821790790307414914106093858868634329285205417149685270682748367152458577\", \"price\":\"0.39\", \"size\":\"0\", \"side\":\"SELL\", \"hash\":\"cf3ed4d2e47e305c35a806a6bf91c9e37765fd78\", \"best_bid\":\"0.38\", \"best_ask\":\"0.41\"}, {\"asset_id\":\"107603864457683460275633293642179940881969192120168665300712204232021063124301\", \"price\":\"0.61\", \"size\":\"0\", \"side\":\"BUY\", \"hash\":\"f1c1642cdbe4e0927810f81f23c454a0324f0533\", \"best_bid\":\"0.59\", \"best_ask\":\"0.62\"}], \"timestamp\":\"1785211869419\", \"event_type\":\"price_change\"}","received_at":"2026-07-28T04:11:11.603654Z","schema_version":"clob-market-ws.price_change.v1","sequence":null,"server_hash":null,"server_timestamp":"1785211869419","session_id":"2d607381e3054cee91998cdf45a4231c","source":"clob_market_ws"},"received_at":"2026-07-28T04:11:11.603654Z","record_id":"cdf7b8a16c3e9d1cad2822720e44bebe5efdac77c3d87cbdc0902198dbe79a73","schema_fingerprint":"4aa3821a28b0b7c2400bc59aba4bcc0a76e971dadd19610d3ad38c768e124dc7","schema_version":"edge-lab-recorder.raw.v1","sequence":null,"source":"clob_market_ws"}
{"event_at":"2026-07-28T04:11:09.426000Z","event_fingerprint":"af868c8b9ac072797765cfee563c4887cfe5e18b1d8b7c6daddccd6ba272bbc5","payload":{"connection_id":"f6725804f86a4c4eb588e4d5ed7db029","event_at":"2026-07-28T04:11:09.426000Z","event_type":"price_change","frame_hash":"1a3c37223560caa6674139d9114f38faffce45c9e8183f7462f9aecd5bab5727","frame_index":0,"kind":"data","monotonic_ns":313854684632750,"payload":{"event_type":"price_change","market":"0xd412ce774cfcf8dc9f71164aac78783978aac7b03871702a3b8a481bd9dc9688","price_changes":[{"asset_id":"96600821790790307414914106093858868634329285205417149685270682748367152458577","best_ask":"0.41","best_bid":"0.38","hash":"cf707b071d0de4f30f8685136ec714076766b2ee","price":"0.34","side":"BUY","size":"50.2"},{"asset_id":"107603864457683460275633293642179940881969192120168665300712204232021063124301","best_ask":"0.62","best_bid":"0.59","hash":"595cfce1d06d40b295736ad31b499aa997d2a44f","price":"0.66","side":"SELL","size":"50.2"}],"timestamp":"1785211869426"},"payload_hash":"44865c293a074152c45eb7eba8e8fa0ef50c43862428bc04610909bd32eb65de","raw_frame":"{\"market\":\"0xd412ce774cfcf8dc9f71164aac78783978aac7b03871702a3b8a481bd9dc9688\", \"price_changes\":[{\"asset_id\":\"96600821790790307414914106093858868634329285205417149685270682748367152458577\", \"price\":\"0.34\", \"size\":\"50.2\", \"side\":\"BUY\", \"hash\":\"cf707b071d0de4f30f8685136ec714076766b2ee\", \"best_bid\":\"0.38\", \"best_ask\":\"0.41\"}, {\"asset_id\":\"107603864457683460275633293642179940881969192120168665300712204232021063124301\", \"price\":\"0.66\", \"size\":\"50.2\", \"side\":\"SELL\", \"hash\":\"595cfce1d06d40b295736ad31b499aa997d2a44f\", \"best_bid\":\"0.59\", \"best_ask\":\"0.62\"}], \"timestamp\":\"1785211869426\", \"event_type\":\"price_change\"}","received_at":"2026-07-28T04:11:11.608026Z","schema_version":"clob-market-ws.price_change.v1","sequence":null,"server_hash":null,"server_timestamp":"1785211869426","session_id":"2d607381e3054cee91998cdf45a4231c","source":"clob_market_ws"},"received_at":"2026-07-28T04:11:11.608026Z","record_id":"ce480a7247d14bea868c5bbc3b21bddba5c3a07f6288461df56328b131938364","schema_fingerprint":"4aa3821a28b0b7c2400bc59aba4bcc0a76e971dadd19610d3ad38c768e124dc7","schema_version":"edge-lab-recorder.raw.v1","sequence":null,"source":"clob_market_ws"}
{"event_at":"2026-07-28T04:11:09.430000Z","event_fingerprint":"d864d5077b3dc141d891386298d871733565f673aac77a35a7d67475fa2d6229","payload":{"connection_id":"f6725804f86a4c4eb588e4d5ed7db029","event_at":"2026-07-28T04:11:09.430000Z","event_type":"best_bid_ask","frame_hash":"41a82c26ecca29b6564d9c4d6c625ea1b1d0114e75dd90fb20476e32463aaab3","frame_index":0,"kind":"data","monotonic_ns":313854689613666,"payload":{"asset_id":"107603864457683460275633293642179940881969192120168665300712204232021063124301","best_ask":"0.62","best_bid":"0.61","event_type":"best_bid_ask","market":"0xd412ce774cfcf8dc9f71164aac78783978aac7b03871702a3b8a481bd9dc9688","spread":"0.01","timestamp":"1785211869430"},"payload_hash":"8b863e647820aeb0c944e17ebffedf5e31fce578c7c2e10338a7c221a0a67caf","raw_frame":"{\"market\":\"0xd412ce774cfcf8dc9f71164aac78783978aac7b03871702a3b8a481bd9dc9688\", \"asset_id\":\"107603864457683460275633293642179940881969192120168665300712204232021063124301\", \"best_bid\":\"0.61\", \"best_ask\":\"0.62\", \"spread\":\"0.01\", \"timestamp\":\"1785211869430\", \"event_type\":\"best_bid_ask\"}","received_at":"2026-07-28T04:11:11.613008Z","schema_version":"clob-market-ws.best_bid_ask.v1","sequence":null,"server_hash":null,"server_timestamp":"1785211869430","session_id":"2d607381e3054cee91998cdf45a4231c","source":"clob_market_ws"},"received_at":"2026-07-28T04:11:11.613008Z","record_id":"6096d7ff33fad983ac57fe0312a1fece0f3fcd18853f31d2429ecf8d7b8a0fb2","schema_fingerprint":"8488399f31b0337811b13b266be932db7062827c2470b78bd8e9e99bab51d17d","schema_version":"edge-lab-recorder.raw.v1","sequence":null,"source":"clob_market_ws"}
{"event_at":"2026-07-28T04:11:09.430000Z","event_fingerprint":"dfd073ad10c52b10d75672f53b40dae9387799de3751c36d72198de4faae7229","payload":{"connection_id":"f6725804f86a4c4eb588e4d5ed7db029","event_at":"2026-07-28T04:11:09.430000Z","event_type":"best_bid_ask","frame_hash":"d9018ede23df5a0789aa552d9fa5a8837f49ed6279ea28e6fb4619af812a9b57","frame_index":0,"kind":"data","monotonic_ns":313854693405583,"payload":{"asset_id":"96600821790790307414914106093858868634329285205417149685270682748367152458577","best_ask":"0.39","best_bid":"0.38","event_type":"best_bid_ask","market":"0xd412ce774cfcf8dc9f71164aac78783978aac7b03871702a3b8a481bd9dc9688","spread":"0.01","timestamp":"1785211869430"},"payload_hash":"3c145858f1ae5a1647a5af06c73ad34e300437f4602b478e44e3b069734adc64","raw_frame":"{\"market\":\"0xd412ce774cfcf8dc9f71164aac78783978aac7b03871702a3b8a481bd9dc9688\", \"asset_id\":\"96600821790790307414914106093858868634329285205417149685270682748367152458577\", \"best_bid\":\"0.38\", \"best_ask\":\"0.39\", \"spread\":\"0.01\", \"timestamp\":\"1785211869430\", \"event_type\":\"best_bid_ask\"}","received_at":"2026-07-28T04:11:11.616801Z","schema_version":"clob-market-ws.best_bid_ask.v1","sequence":null,"server_hash":null,"server_timestamp":"1785211869430","session_id":"2d607381e3054cee91998cdf45a4231c","source":"clob_market_ws"},"received_at":"2026-07-28T04:11:11.616801Z","record_id":"60d004ac624793b5e4855f86777bf25fabb9ff4c2441e78fc46eba25e6ba9e7b","schema_fingerprint":"8488399f31b0337811b13b266be932db7062827c2470b78bd8e9e99bab51d17d","schema_version":"edge-lab-recorder.raw.v1","sequence":null,"source":"clob_market_ws"}
{"event_at":"2026-07-28T04:11:09.430000Z","event_fingerprint":"d8dec72404884857fef22bf51582c88d20ca6aeada02fb9f738765bf9ced8745","payload":{"connection_id":"f6725804f86a4c4eb588e4d5ed7db029","event_at":"2026-07-28T04:11:09.430000Z","event_type":"price_change","frame_hash":"231119c212e960cc27e9ef0842378bd958631c8b019164eab5d7872ae3b62ff3","frame_index":0,"kind":"data","monotonic_ns":313854697413791,"payload":{"event_type":"price_change","market":"0xd412ce774cfcf8dc9f71164aac78783978aac7b03871702a3b8a481bd9dc9688","price_changes":[{"asset_id":"107603864457683460275633293642179940881969192120168665300712204232021063124301","best_ask":"0.62","best_bid":"0.61","hash":"45fc75b4ed2c6bf25d92c4119f6d4f59825aa9e7","price":"0.61","side":"BUY","size":"5"},{"asset_id":"96600821790790307414914106093858868634329285205417149685270682748367152458577","best_ask":"0.39","best_bid":"0.38","hash":"061b80b0a8c4a6eb465fa4946b238aa56cff5b8d","price":"0.39","side":"SELL","size":"5"}],"timestamp":"1785211869430"},"payload_hash":"2ccaadc527287867086564763005a4eb72b1546b94272f5740412a0be4a1cfcd","raw_frame":"{\"market\":\"0xd412ce774cfcf8dc9f71164aac78783978aac7b03871702a3b8a481bd9dc9688\", \"price_changes\":[{\"asset_id\":\"107603864457683460275633293642179940881969192120168665300712204232021063124301\", \"price\":\"0.61\", \"size\":\"5\", \"side\":\"BUY\", \"hash\":\"45fc75b4ed2c6bf25d92c4119f6d4f59825aa9e7\", \"best_bid\":\"0.61\", \"best_ask\":\"0.62\"}, {\"asset_id\":\"96600821790790307414914106093858868634329285205417149685270682748367152458577\", \"price\":\"0.39\", \"size\":\"5\", \"side\":\"SELL\", \"hash\":\"061b80b0a8c4a6eb465fa4946b238aa56cff5b8d\", \"best_bid\":\"0.38\", \"best_ask\":\"0.39\"}], \"timestamp\":\"1785211869430\", \"event_type\":\"price_change\"}","received_at":"2026-07-28T04:11:11.620809Z","schema_version":"clob-market-ws.price_change.v1","sequence":null,"server_hash":null,"server_timestamp":"1785211869430","session_id":"2d607381e3054cee91998cdf45a4231c","source":"clob_market_ws"},"received_at":"2026-07-28T04:11:11.620809Z","record_id":"afe630785b38cabb984fc77147f4479f7f80498f6df52635c22a3b22c4c5937c","schema_fingerprint":"4aa3821a28b0b7c2400bc59aba4bcc0a76e971dadd19610d3ad38c768e124dc7","schema_version":"edge-lab-recorder.raw.v1","sequence":null,"source":"clob_market_ws"}
{"event_at":"2026-07-28T04:11:09.435000Z","event_fingerprint":"6594c06905eac72be6a99729b892eacada5796ea7f7203161bfb5c8ef5065208","payload":{"connection_id":"f6725804f86a4c4eb588e4d5ed7db029","event_at":"2026-07-28T04:11:09.435000Z","event_type":"best_bid_ask","frame_hash":"d59fa6463ae6a3ffe0b71fc7d21058261b1d5955d9ac3e4bf08d7bbfa6f70cfb","frame_index":0,"kind":"data","monotonic_ns":313854701765625,"payload":{"asset_id":"107603864457683460275633293642179940881969192120168665300712204232021063124301","best_ask":"0.62","best_bid":"0.59","event_type":"best_bid_ask","market":"0xd412ce774cfcf8dc9f71164aac78783978aac7b03871702a3b8a481bd9dc9688","spread":"0.03","timestamp":"1785211869435"},"payload_hash":"746c49d42e10ade071c244656c2c280057bcfef231fb200af3c8b8e1b1c9afe2","raw_frame":"{\"market\":\"0xd412ce774cfcf8dc9f71164aac78783978aac7b03871702a3b8a481bd9dc9688\", \"asset_id\":\"107603864457683460275633293642179940881969192120168665300712204232021063124301\", \"best_bid\":\"0.59\", \"best_ask\":\"0.62\", \"spread\":\"0.03\", \"timestamp\":\"1785211869435\", \"event_type\":\"best_bid_ask\"}","received_at":"2026-07-28T04:11:11.625160Z","schema_version":"clob-market-ws.best_bid_ask.v1","sequence":null,"server_hash":null,"server_timestamp":"1785211869435","session_id":"2d607381e3054cee91998cdf45a4231c","source":"clob_market_ws"},"received_at":"2026-07-28T04:11:11.625160Z","record_id":"6d35bdcdbacdfe2f12a31fae5844ac6bb0a0a1e255a807de0f7ab65a45951fca","schema_fingerprint":"8488399f31b0337811b13b266be932db7062827c2470b78bd8e9e99bab51d17d","schema_version":"edge-lab-recorder.raw.v1","sequence":null,"source":"clob_market_ws"}
{"event_at":"2026-07-28T04:11:09.435000Z","event_fingerprint":"b394f8f4689f3866f8b3525620b9435a791243aaa6e3de6f5ec37ce72178dc6e","payload":{"connection_id":"f6725804f86a4c4eb588e4d5ed7db029","event_at":"2026-07-28T04:11:09.435000Z","event_type":"best_bid_ask","frame_hash":"170d727578e4e7ac6cfa2ec0b5aedea4f3eefc354d393da2bab1af4377f240f8","frame_index":0,"kind":"data","monotonic_ns":313854704902875,"payload":{"asset_id":"96600821790790307414914106093858868634329285205417149685270682748367152458577","best_ask":"0.41","best_bid":"0.38","event_type":"best_bid_ask","market":"0xd412ce774cfcf8dc9f71164aac78783978aac7b03871702a3b8a481bd9dc9688","spread":"0.03","timestamp":"1785211869435"},"payload_hash":"922cba27010cef04eec16276549e86235f3e2e6ee81953613fdc37d0e9fcf64d","raw_frame":"{\"market\":\"0xd412ce774cfcf8dc9f71164aac78783978aac7b03871702a3b8a481bd9dc9688\", \"asset_id\":\"96600821790790307414914106093858868634329285205417149685270682748367152458577\", \"best_bid\":\"0.38\", \"best_ask\":\"0.41\", \"spread\":\"0.03\", \"timestamp\":\"1785211869435\", \"event_type\":\"best_bid_ask\"}","received_at":"2026-07-28T04:11:11.628297Z","schema_version":"clob-market-ws.best_bid_ask.v1","sequence":null,"server_hash":null,"server_timestamp":"1785211869435","session_id":"2d607381e3054cee91998cdf45a4231c","source":"clob_market_ws"},"received_at":"2026-07-28T04:11:11.628297Z","record_id":"4bc230e1a2228e9f1da7ebefc2a3fa4131334196d71fa20b2ab73852267702ab","schema_fingerprint":"8488399f31b0337811b13b266be932db7062827c2470b78bd8e9e99bab51d17d","schema_version":"edge-lab-recorder.raw.v1","sequence":null,"source":"clob_market_ws"}
{"event_at":"2026-07-28T04:11:09.434000Z","event_fingerprint":"baed32cbb6d5a09c16dd2bfe1571b650d8b1419634d715859f4ce481afc503f8","payload":{"connection_id":"f6725804f86a4c4eb588e4d5ed7db029","event_at":"2026-07-28T04:11:09.434000Z","event_type":"price_change","frame_hash":"dbe39cceb3477c047c51fd2d68061bc6c45c2a8a54f31863314384dac3864bf2","frame_index":0,"kind":"data","monotonic_ns":313854708696875,"payload":{"event_type":"price_change","market":"0xd412ce774cfcf8dc9f71164aac78783978aac7b03871702a3b8a481bd9dc9688","price_changes":[{"asset_id":"107603864457683460275633293642179940881969192120168665300712204232021063124301","best_ask":"0.62","best_bid":"0.59","hash":"ee1c0bc820a157de02cfa7effda99822c9933744","price":"0.61","side":"BUY","size":"0"},{"asset_id":"96600821790790307414914106093858868634329285205417149685270682748367152458577","best_ask":"0.41","best_bid":"0.38","hash":"a953d065fc950cea348af5c9ab834edd06eed52e","price":"0.39","side":"SELL","size":"0"}],"timestamp":"1785211869434"},"payload_hash":"0260dd7e870451bc0782d81940e54e75feb3e440eac0a4708664b05caab190f1","raw_frame":"{\"market\":\"0xd412ce774cfcf8dc9f71164aac78783978aac7b03871702a3b8a481bd9dc9688\", \"price_changes\":[{\"asset_id\":\"107603864457683460275633293642179940881969192120168665300712204232021063124301\", \"price\":\"0.61\", \"size\":\"0\", \"side\":\"BUY\", \"hash\":\"ee1c0bc820a157de02cfa7effda99822c9933744\", \"best_bid\":\"0.59\", \"best_ask\":\"0.62\"}, {\"asset_id\":\"96600821790790307414914106093858868634329285205417149685270682748367152458577\", \"price\":\"0.39\", \"size\":\"0\", \"side\":\"SELL\", \"hash\":\"a953d065fc950cea348af5c9ab834edd06eed52e\", \"best_bid\":\"0.38\", \"best_ask\":\"0.41\"}], \"timestamp\":\"1785211869434\", \"event_type\":\"price_change\"}","received_at":"2026-07-28T04:11:11.632091Z","schema_version":"clob-market-ws.price_change.v1","sequence":null,"server_hash":null,"server_timestamp":"1785211869434","session_id":"2d607381e3054cee91998cdf45a4231c","source":"clob_market_ws"},"received_at":"2026-07-28T04:11:11.632091Z","record_id":"7e052151e5f45cec1b139c4773c3c660022ee337f2addfdf59aae2fe31ec74ff","schema_fingerprint":"4aa3821a28b0b7c2400bc59aba4bcc0a76e971dadd19610d3ad38c768e124dc7","schema_version":"edge-lab-recorder.raw.v1","sequence":null,"source":"clob_market_ws"}
{"event_at":"2026-07-28T04:11:09.438000Z","event_fingerprint":"227c63031dd1f3aa253bb18beea3addba7bccc23ec41fe5203cccb7adb2c717c","payload":{"connection_id":"f6725804f86a4c4eb588e4d5ed7db029","event_at":"2026-07-28T04:11:09.438000Z","event_type":"price_change","frame_hash":"b4d25de1ebf31d144e644f3b2dc8493545e9dc6b0e0878da0158104dc7357f52","frame_index":0,"kind":"data","monotonic_ns":313854712917791,"payload":{"event_type":"price_change","market":"0xd412ce774cfcf8dc9f71164aac78783978aac7b03871702a3b8a481bd9dc9688","price_changes":[{"asset_id":"96600821790790307414914106093858868634329285205417149685270682748367152458577","best_ask":"0.41","best_bid":"0.38","hash":"56e5de8eb048f1fc297fc52e0178addb92c5f276","price":"0.34","side":"BUY","size":"44.2"},{"asset_id":"107603864457683460275633293642179940881969192120168665300712204232021063124301","best_ask":"0.62","best_bid":"0.59","hash":"42631b01952a3aee3a4cf5d7b02e52f01002dc45","price":"0.66","side":"SELL","size":"44.2"}],"timestamp":"1785211869438"},"payload_hash":"9a9c46e405740c68fc4e0b798197e216ccd40f839956c70362f0b7db2b213b79","raw_frame":"{\"market\":\"0xd412ce774cfcf8dc9f71164aac78783978aac7b03871702a3b8a481bd9dc9688\", \"price_changes\":[{\"asset_id\":\"96600821790790307414914106093858868634329285205417149685270682748367152458577\", \"price\":\"0.34\", \"size\":\"44.2\", \"side\":\"BUY\", \"hash\":\"56e5de8eb048f1fc297fc52e0178addb92c5f276\", \"best_bid\":\"0.38\", \"best_ask\":\"0.41\"}, {\"asset_id\":\"107603864457683460275633293642179940881969192120168665300712204232021063124301\", \"price\":\"0.66\", \"size\":\"44.2\", \"side\":\"SELL\", \"hash\":\"42631b01952a3aee3a4cf5d7b02e52f01002dc45\", \"best_bid\":\"0.59\", \"best_ask\":\"0.62\"}], \"timestamp\":\"1785211869438\", \"event_type\":\"price_change\"}","received_at":"2026-07-28T04:11:11.636312Z","schema_version":"clob-market-ws.price_change.v1","sequence":null,"server_hash":null,"server_timestamp":"1785211869438","session_id":"2d607381e3054cee91998cdf45a4231c","source":"clob_market_ws"},"received_at":"2026-07-28T04:11:11.636312Z","record_id":"0cc07d16d725af0935506ca5e2986de90b9199764fdd51fbdfc9385743348566","schema_fingerprint":"4aa3821a28b0b7c2400bc59aba4bcc0a76e971dadd19610d3ad38c768e124dc7","schema_version":"edge-lab-recorder.raw.v1","sequence":null,"source":"clob_market_ws"}
{"event_at":"2026-07-28T04:11:09.442000Z","event_fingerprint":"3222039edf54ad1e2bd629f5a0e122fe8fb07f7fd9bcc1a774858b721519db2a","payload":{"connection_id":"f6725804f86a4c4eb588e4d5ed7db029","event_at":"2026-07-28T04:11:09.442000Z","event_type":"best_bid_ask","frame_hash":"c1dd92f601b89ef7e0140d7f3c1ecb7fad84929e69e6cca2e74a6109e68d02fe","frame_index":0,"kind":"data","monotonic_ns":313854717101625,"payload":{"asset_id":"107603864457683460275633293642179940881969192120168665300712204232021063124301","best_ask":"0.62","best_bid":"0.6","event_type":"best_bid_ask","market":"0xd412ce774cfcf8dc9f71164aac78783978aac7b03871702a3b8a481bd9dc9688","spread":"0.02","timestamp":"1785211869442"},"payload_hash":"963f5d0cfbbb4c3bb991704a67a14dddb9b0ab533fc2ac74b8a9c347b01045ac","raw_frame":"{\"market\":\"0xd412ce774cfcf8dc9f71164aac78783978aac7b03871702a3b8a481bd9dc9688\", \"asset_id\":\"107603864457683460275633293642179940881969192120168665300712204232021063124301\", \"best_bid\":\"0.6\", \"best_ask\":\"0.62\", \"spread\":\"0.02\", \"timestamp\":\"1785211869442\", \"event_type\":\"best_bid_ask\"}","received_at":"2026-07-28T04:11:11.640496Z","schema_version":"clob-market-ws.best_bid_ask.v1","sequence":null,"server_hash":null,"server_timestamp":"1785211869442","session_id":"2d607381e3054cee91998cdf45a4231c","source":"clob_market_ws"},"received_at":"2026-07-28T04:11:11.640496Z","record_id":"3f1f7876a7483f278148653d622e9f8fefd0697f58468f0e35efb65b07258f5b","schema_fingerprint":"8488399f31b0337811b13b266be932db7062827c2470b78bd8e9e99bab51d17d","schema_version":"edge-lab-recorder.raw.v1","sequence":null,"source":"clob_market_ws"}
{"event_at":"2026-07-28T04:11:09.442000Z","event_fingerprint":"0607f815a0b8deb1c875825322c5abf04f8fb857145d8f9c037ab6158803bdee","payload":{"connection_id":"f6725804f86a4c4eb588e4d5ed7db029","event_at":"2026-07-28T04:11:09.442000Z","event_type":"best_bid_ask","frame_hash":"444561d8cdb83c0d973980d6164b7df633875a9203552e14d059ecbee28efc64","frame_index":0,"kind":"data","monotonic_ns":313854719515625,"payload":{"asset_id":"96600821790790307414914106093858868634329285205417149685270682748367152458577","best_ask":"0.4","best_bid":"0.38","event_type":"best_bid_ask","market":"0xd412ce774cfcf8dc9f71164aac78783978aac7b03871702a3b8a481bd9dc9688","spread":"0.02","timestamp":"1785211869442"},"payload_hash":"20852472d8756a034d06586f0324db6ba2a47d616d3c3449779d89bb3a6f6493","raw_frame":"{\"market\":\"0xd412ce774cfcf8dc9f71164aac78783978aac7b03871702a3b8a481bd9dc9688\", \"asset_id\":\"96600821790790307414914106093858868634329285205417149685270682748367152458577\", \"best_bid\":\"0.38\", \"best_ask\":\"0.4\", \"spread\":\"0.02\", \"timestamp\":\"1785211869442\", \"event_type\":\"best_bid_ask\"}","received_at":"2026-07-28T04:11:11.642910Z","schema_version":"clob-market-ws.best_bid_ask.v1","sequence":null,"server_hash":null,"server_timestamp":"1785211869442","session_id":"2d607381e3054cee91998cdf45a4231c","source":"clob_market_ws"},"received_at":"2026-07-28T04:11:11.642910Z","record_id":"f2d088b6c8fc3f1c48881ce8531dd83a2c51e1bd9c8804f901b3a4fb07ced29e","schema_fingerprint":"8488399f31b0337811b13b266be932db7062827c2470b78bd8e9e99bab51d17d","schema_version":"edge-lab-recorder.raw.v1","sequence":null,"source":"clob_market_ws"}
{"event_at":"2026-07-28T04:11:09.441000Z","event_fingerprint":"66b6b9f1d5f0c8ab0c1f85f56465d43a96d812ae451281aefc3c73498d8a9816","payload":{"connection_id":"f6725804f86a4c4eb588e4d5ed7db029","event_at":"2026-07-28T04:11:09.441000Z","event_type":"price_change","frame_hash":"678980a0642d0d1c13653cf136722d46fc1a5db29d2bbaefe62e6a928ca718ea","frame_index":0,"kind":"data","monotonic_ns":313854723322375,"payload":{"event_type":"price_change","market":"0xd412ce774cfcf8dc9f71164aac78783978aac7b03871702a3b8a481bd9dc9688","price_changes":[{"asset_id":"96600821790790307414914106093858868634329285205417149685270682748367152458577","best_ask":"0.4","best_bid":"0.38","hash":"f4e772812b89b3cc684fe29623bb89b5ee9ca94f","price":"0.4","side":"SELL","size":"5"},{"asset_id":"107603864457683460275633293642179940881969192120168665300712204232021063124301","best_ask":"0.62","best_bid":"0.6","hash":"e295231c045c54685e33dd18732feabd2b5e6cdc","price":"0.6","side":"BUY","size":"5"}],"timestamp":"1785211869441"},"payload_hash":"1c1ba10e86fc2e9ae5f69dc9ca9ba146ce7c9b77eb2433a9d2572285d57eb80b","raw_frame":"{\"market\":\"0xd412ce774cfcf8dc9f71164aac78783978aac7b03871702a3b8a481bd9dc9688\", \"price_changes\":[{\"asset_id\":\"96600821790790307414914106093858868634329285205417149685270682748367152458577\", \"price\":\"0.4\", \"size\":\"5\", \"side\":\"SELL\", \"hash\":\"f4e772812b89b3cc684fe29623bb89b5ee9ca94f\", \"best_bid\":\"0.38\", \"best_ask\":\"0.4\"}, {\"asset_id\":\"107603864457683460275633293642179940881969192120168665300712204232021063124301\", \"price\":\"0.6\", \"size\":\"5\", \"side\":\"BUY\", \"hash\":\"e295231c045c54685e33dd18732feabd2b5e6cdc\", \"best_bid\":\"0.6\", \"best_ask\":\"0.62\"}], \"timestamp\":\"1785211869441\", \"event_type\":\"price_change\"}","received_at":"2026-07-28T04:11:11.646717Z","schema_version":"clob-market-ws.price_change.v1","sequence":null,"server_hash":null,"server_timestamp":"1785211869441","session_id":"2d607381e3054cee91998cdf45a4231c","source":"clob_market_ws"},"received_at":"2026-07-28T04:11:11.646717Z","record_id":"1f4079d969dfdb8d00128ebc83cc44b3b7a00c3cf7683333b8ee12655f0a3ed6","schema_fingerprint":"4aa3821a28b0b7c2400bc59aba4bcc0a76e971dadd19610d3ad38c768e124dc7","schema_version":"edge-lab-recorder.raw.v1","sequence":null,"source":"clob_market_ws"}
{"event_at":"2026-07-28T04:11:09.442000Z","event_fingerprint":"ebf8b71aae054dde3a2a3e0093e08dafc71dfa8a48e5ffa57b31b4dc61d40f34","payload":{"connection_id":"f6725804f86a4c4eb588e4d5ed7db029","event_at":"2026-07-28T04:11:09.442000Z","event_type":"price_change","frame_hash":"31a8ebf0cb4f521c034ce842fa097e983083a963f83adc6220c847d598b508d3","frame_index":0,"kind":"data","monotonic_ns":313854726288000,"payload":{"event_type":"price_change","market":"0xd412ce774cfcf8dc9f71164aac78783978aac7b03871702a3b8a481bd9dc9688","price_changes":[{"asset_id":"107603864457683460275633293642179940881969192120168665300712204232021063124301","best_ask":"0.62","best_bid":"0.6","hash":"26f3740f3a20cab71c9c6994946d1c51092bf1b3","price":"0.87","side":"SELL","size":"77.5"},{"asset_id":"96600821790790307414914106093858868634329285205417149685270682748367152458577","best_ask":"0.4","best_bid":"0.38","hash":"3d2c7ac9272eb3642130c0fd1f07286df030f80d","price":"0.13","side":"BUY","size":"77.5"}],"timestamp":"1785211869442"},"payload_hash":"29435d27e61b23d1f5dee861019a2cb18a2021d338d8182b188d758d8e28ad12","raw_frame":"{\"market\":\"0xd412ce774cfcf8dc9f71164aac78783978aac7b03871702a3b8a481bd9dc9688\", \"price_changes\":[{\"asset_id\":\"107603864457683460275633293642179940881969192120168665300712204232021063124301\", \"price\":\"0.87\", \"size\":\"77.5\", \"side\":\"SELL\", \"hash\":\"26f3740f3a20cab71c9c6994946d1c51092bf1b3\", \"best_bid\":\"0.6\", \"best_ask\":\"0.62\"}, {\"asset_id\":\"96600821790790307414914106093858868634329285205417149685270682748367152458577\", \"price\":\"0.13\", \"size\":\"77.5\", \"side\":\"BUY\", \"hash\":\"3d2c7ac9272eb3642130c0fd1f07286df030f80d\", \"best_bid\":\"0.38\", \"best_ask\":\"0.4\"}], \"timestamp\":\"1785211869442\", \"event_type\":\"price_change\"}","received_at":"2026-07-28T04:11:11.649682Z","schema_version":"clob-market-ws.price_change.v1","sequence":null,"server_hash":null,"server_timestamp":"1785211869442","session_id":"2d607381e3054cee91998cdf45a4231c","source":"clob_market_ws"},"received_at":"2026-07-28T04:11:11.649682Z","record_id":"44dab513262170e756b763a7c38e8233b5f7e58907c36173f0cce2597c8c3ed1","schema_fingerprint":"4aa3821a28b0b7c2400bc59aba4bcc0a76e971dadd19610d3ad38c768e124dc7","schema_version":"edge-lab-recorder.raw.v1","sequence":null,"source":"clob_market_ws"}
{"event_at":"2026-07-28T04:11:09.446000Z","event_fingerprint":"0b2c9765bc2b0890612cf90f4936f56b0c281a478db003cb7495938ff19fac58","payload":{"connection_id":"f6725804f86a4c4eb588e4d5ed7db029","event_at":"2026-07-28T04:11:09.446000Z","event_type":"best_bid_ask","frame_hash":"5f3dddb7bd501d8a43a8526e3b0c56d3802a8fe15ea4c9ba292192c2f1e82f7a","frame_index":0,"kind":"data","monotonic_ns":313854730440250,"payload":{"asset_id":"107603864457683460275633293642179940881969192120168665300712204232021063124301","best_ask":"0.62","best_bid":"0.59","event_type":"best_bid_ask","market":"0xd412ce774cfcf8dc9f71164aac78783978aac7b03871702a3b8a481bd9dc9688","spread":"0.03","timestamp":"1785211869446"},"payload_hash":"5be5a73dc84409a59c963d69c13faabb63f5b9d3f126ca196b77392195bb245e","raw_frame":"{\"market\":\"0xd412ce774cfcf8dc9f71164aac78783978aac7b03871702a3b8a481bd9dc9688\", \"asset_id\":\"107603864457683460275633293642179940881969192120168665300712204232021063124301\", \"best_bid\":\"0.59\", \"best_ask\":\"0.62\", \"spread\":\"0.03\", \"timestamp\":\"1785211869446\", \"event_type\":\"best_bid_ask\"}","received_at":"2026-07-28T04:11:11.653835Z","schema_version":"clob-market-ws.best_bid_ask.v1","sequence":null,"server_hash":null,"server_timestamp":"1785211869446","session_id":"2d607381e3054cee91998cdf45a4231c","source":"clob_market_ws"},"received_at":"2026-07-28T04:11:11.653835Z","record_id":"80428fe8fbe287353207d58c341325a205cff4f3903613c9eaf5d8b975b778df","schema_fingerprint":"8488399f31b0337811b13b266be932db7062827c2470b78bd8e9e99bab51d17d","schema_version":"edge-lab-recorder.raw.v1","sequence":null,"source":"clob_market_ws"}
{"event_at":"2026-07-28T04:11:09.446000Z","event_fingerprint":"16bbb5f5ff809c691a930dc3994179829fc197db87bb1648c7a3c687ec7e5605","payload":{"connection_id":"f6725804f86a4c4eb588e4d5ed7db029","event_at":"2026-07-28T04:11:09.446000Z","event_type":"best_bid_ask","frame_hash":"4268f313877acfa6aae5d185ee2a65ab64c12b4474957000d91ddb7541359b0e","frame_index":0,"kind":"data","monotonic_ns":313854733512500,"payload":{"asset_id":"96600821790790307414914106093858868634329285205417149685270682748367152458577","best_ask":"0.41","best_bid":"0.38","event_type":"best_bid_ask","market":"0xd412ce774cfcf8dc9f71164aac78783978aac7b03871702a3b8a481bd9dc9688","spread":"0.03","timestamp":"1785211869446"},"payload_hash":"3bf36fc78d4c094d727d6cb01b50f19e2ee3736d1dddf42387e179ae8743e180","raw_frame":"{\"market\":\"0xd412ce774cfcf8dc9f71164aac78783978aac7b03871702a3b8a481bd9dc9688\", \"asset_id\":\"96600821790790307414914106093858868634329285205417149685270682748367152458577\", \"best_bid\":\"0.38\", \"best_ask\":\"0.41\", \"spread\":\"0.03\", \"timestamp\":\"1785211869446\", \"event_type\":\"best_bid_ask\"}","received_at":"2026-07-28T04:11:11.656907Z","schema_version":"clob-market-ws.best_bid_ask.v1","sequence":null,"server_hash":null,"server_timestamp":"1785211869446","session_id":"2d607381e3054cee91998cdf45a4231c","source":"clob_market_ws"},"received_at":"2026-07-28T04:11:11.656907Z","record_id":"c1fe2dec79843bb4c939dea0c5e4bb779cb6c118a6b8fa3d09d02ababdde0260","schema_fingerprint":"8488399f31b0337811b13b266be932db7062827c2470b78bd8e9e99bab51d17d","schema_version":"edge-lab-recorder.raw.v1","sequence":null,"source":"clob_market_ws"}
{"event_at":"2026-07-28T04:11:09.446000Z","event_fingerprint":"04887cd8201095b84afd50e24ecea0c7a2479daca5804675d7a02cb2fee61717","payload":{"connection_id":"f6725804f86a4c4eb588e4d5ed7db029","event_at":"2026-07-28T04:11:09.446000Z","event_type":"price_change","frame_hash":"ac60d3890d0d40e1f2493d47818c693feab32f1e0a55fc2b186fca134454ce25","frame_index":0,"kind":"data","monotonic_ns":313854736041291,"payload":{"event_type":"price_change","market":"0xd412ce774cfcf8dc9f71164aac78783978aac7b03871702a3b8a481bd9dc9688","price_changes":[{"asset_id":"96600821790790307414914106093858868634329285205417149685270682748367152458577","best_ask":"0.41","best_bid":"0.38","hash":"88e83bf65da8f65e384abe01fab6cfb23b326147","price":"0.4","side":"SELL","size":"0"},{"asset_id":"107603864457683460275633293642179940881969192120168665300712204232021063124301","best_ask":"0.62","best_bid":"0.59","hash":"9a4e56be069415ca7af3d08c8ffb5d2a0b4e38b9","price":"0.6","side":"BUY","size":"0"}],"timestamp":"1785211869446"},"payload_hash":"b34669419581252c9a4fade0246afe4578e98de2bb0fee502fe95a76b3fd9788","raw_frame":"{\"market\":\"0xd412ce774cfcf8dc9f71164aac78783978aac7b03871702a3b8a481bd9dc9688\", \"price_changes\":[{\"asset_id\":\"96600821790790307414914106093858868634329285205417149685270682748367152458577\", \"price\":\"0.4\", \"size\":\"0\", \"side\":\"SELL\", \"hash\":\"88e83bf65da8f65e384abe01fab6cfb23b326147\", \"best_bid\":\"0.38\", \"best_ask\":\"0.41\"}, {\"asset_id\":\"107603864457683460275633293642179940881969192120168665300712204232021063124301\", \"price\":\"0.6\", \"size\":\"0\", \"side\":\"BUY\", \"hash\":\"9a4e56be069415ca7af3d08c8ffb5d2a0b4e38b9\", \"best_bid\":\"0.59\", \"best_ask\":\"0.62\"}], \"timestamp\":\"1785211869446\", \"event_type\":\"price_change\"}","received_at":"2026-07-28T04:11:11.659436Z","schema_version":"clob-market-ws.price_change.v1","sequence":null,"server_hash":null,"server_timestamp":"1785211869446","session_id":"2d607381e3054cee91998cdf45a4231c","source":"clob_market_ws"},"received_at":"2026-07-28T04:11:11.659436Z","record_id":"69c2eb848e49589510e8930eee4776b66c364d8864280a5c3d562546b7c36391","schema_fingerprint":"4aa3821a28b0b7c2400bc59aba4bcc0a76e971dadd19610d3ad38c768e124dc7","schema_version":"edge-lab-recorder.raw.v1","sequence":null,"source":"clob_market_ws"}
{"event_at":"2026-07-28T04:11:09.446000Z","event_fingerprint":"f3e3997744f0057b5f93a537a3c87596bc365d929d94a3831f608e9b519eb291","payload":{"connection_id":"f6725804f86a4c4eb588e4d5ed7db029","event_at":"2026-07-28T04:11:09.446000Z","event_type":"price_change","frame_hash":"e1175ea3f2a5b4dd6568adb12b7168c7ee78752fd6be1051941ee88823c58fdb","frame_index":0,"kind":"data","monotonic_ns":313854740109416,"payload":{"event_type":"price_change","market":"0xd412ce774cfcf8dc9f71164aac78783978aac7b03871702a3b8a481bd9dc9688","price_changes":[{"asset_id":"96600821790790307414914106093858868634329285205417149685270682748367152458577","best_ask":"0.41","best_bid":"0.38","hash":"9fd8c61982ae9f27f42b8abce9d500a4c721bff3","price":"0.34","side":"BUY","size":"50.2"},{"asset_id":"107603864457683460275633293642179940881969192120168665300712204232021063124301","best_ask":"0.62","best_bid":"0.59","hash":"9c3a35ddf8fc818b6645cc9a86ae39e86d6661a7","price":"0.66","side":"SELL","size":"50.2"}],"timestamp":"1785211869446"},"payload_hash":"daa84b63c3789cd3388d2f30a9bbacd58710207a6a7f5fcbced39327dce01360","raw_frame":"{\"market\":\"0xd412ce774cfcf8dc9f71164aac78783978aac7b03871702a3b8a481bd9dc9688\", \"price_changes\":[{\"asset_id\":\"96600821790790307414914106093858868634329285205417149685270682748367152458577\", \"price\":\"0.34\", \"size\":\"50.2\", \"side\":\"BUY\", \"hash\":\"9fd8c61982ae9f27f42b8abce9d500a4c721bff3\", \"best_bid\":\"0.38\", \"best_ask\":\"0.41\"}, {\"asset_id\":\"107603864457683460275633293642179940881969192120168665300712204232021063124301\", \"price\":\"0.66\", \"size\":\"50.2\", \"side\":\"SELL\", \"hash\":\"9c3a35ddf8fc818b6645cc9a86ae39e86d6661a7\", \"best_bid\":\"0.59\", \"best_ask\":\"0.62\"}], \"timestamp\":\"1785211869446\", \"event_type\":\"price_change\"}","received_at":"2026-07-28T04:11:11.663504Z","schema_version":"clob-market-ws.price_change.v1","sequence":null,"server_hash":null,"server_timestamp":"1785211869446","session_id":"2d607381e3054cee91998cdf45a4231c","source":"clob_market_ws"},"received_at":"2026-07-28T04:11:11.663504Z","record_id":"0f55bba2a6368ddefd519133d82a4424cab180e2934dd58130cd387b992f9c38","schema_fingerprint":"4aa3821a28b0b7c2400bc59aba4bcc0a76e971dadd19610d3ad38c768e124dc7","schema_version":"edge-lab-recorder.raw.v1","sequence":null,"source":"clob_market_ws"}
{"event_at":"2026-07-28T04:11:09.451000Z","event_fingerprint":"d5ffb10c0fcc7f00f74c6ebb07fd2265185f6fbf3e705b7a6290a0a91e6c91af","payload":{"connection_id":"f6725804f86a4c4eb588e4d5ed7db029","event_at":"2026-07-28T04:11:09.451000Z","event_type":"price_change","frame_hash":"752502af574ad117db0853012b61cf458ab2d768d5bcd0b585378d88928e932c","frame_index":0,"kind":"data","monotonic_ns":313854744407041,"payload":{"event_type":"price_change","market":"0xd412ce774cfcf8dc9f71164aac78783978aac7b03871702a3b8a481bd9dc9688","price_changes":[{"asset_id":"96600821790790307414914106093858868634329285205417149685270682748367152458577","best_ask":"0.41","best_bid":"0.38","hash":"5b574b094eb80f8b4c0e3cef140da0f286b23ac5","price":"0.34","side":"BUY","size":"44.2"},{"asset_id":"107603864457683460275633293642179940881969192120168665300712204232021063124301","best_ask":"0.62","best_bid":"0.59","hash":"5824653d1342ecf21c9718c5dff090b7b22771fe","price":"0.66","side":"SELL","size":"44.2"}],"timestamp":"1785211869451"},"payload_hash":"b52c33bb7f9545743cf6ed0651e06f19d2dfb6f265ba9e98634ed2e8cb0abbe3","raw_frame":"{\"market\":\"0xd412ce774cfcf8dc9f71164aac78783978aac7b03871702a3b8a481bd9dc9688\", \"price_changes\":[{\"asset_id\":\"96600821790790307414914106093858868634329285205417149685270682748367152458577\", \"price\":\"0.34\", \"size\":\"44.2\", \"side\":\"BUY\", \"hash\":\"5b574b094eb80f8b4c0e3cef140da0f286b23ac5\", \"best_bid\":\"0.38\", \"best_ask\":\"0.41\"}, {\"asset_id\":\"107603864457683460275633293642179940881969192120168665300712204232021063124301\", \"price\":\"0.66\", \"size\":\"44.2\", \"side\":\"SELL\", \"hash\":\"5824653d1342ecf21c9718c5dff090b7b22771fe\", \"best_bid\":\"0.59\", \"best_ask\":\"0.62\"}], \"timestamp\":\"1785211869451\", \"event_type\":\"price_change\"}","received_at":"2026-07-28T04:11:11.667801Z","schema_version":"clob-market-ws.price_change.v1","sequence":null,"server_hash":null,"server_timestamp":"1785211869451","session_id":"2d607381e3054cee91998cdf45a4231c","source":"clob_market_ws"},"received_at":"2026-07-28T04:11:11.667801Z","record_id":"1b28f7986238c53c6f7fc8bb4c0ed4274ffc3488151bdbfac029bc5d8b4fc014","schema_fingerprint":"4aa3821a28b0b7c2400bc59aba4bcc0a76e971dadd19610d3ad38c768e124dc7","schema_version":"edge-lab-recorder.raw.v1","sequence":null,"source":"clob_market_ws"}
{"event_at":"2026-07-28T04:11:09.453000Z","event_fingerprint":"584b4e1810c1489ee33bc7d4a85b37ce7c38094eba8f4bef2743cb8ec7f72c20","payload":{"connection_id":"f6725804f86a4c4eb588e4d5ed7db029","event_at":"2026-07-28T04:11:09.453000Z","event_type":"price_change","frame_hash":"210ff452ef8b528f78a0dc0db137956876071b7f884140535d65502fd2304c21","frame_index":0,"kind":"data","monotonic_ns":313854749447250,"payload":{"event_type":"price_change","market":"0xd412ce774cfcf8dc9f71164aac78783978aac7b03871702a3b8a481bd9dc9688","price_changes":[{"asset_id":"107603864457683460275633293642179940881969192120168665300712204232021063124301","best_ask":"0.62","best_bid":"0.59","hash":"de059bcd30a42eefa031551d4a55323d6013cb38","price":"0.02","side":"BUY","size":"683.1"},{"asset_id":"96600821790790307414914106093858868634329285205417149685270682748367152458577","best_ask":"0.41","best_bid":"0.38","hash":"4f54db3379fbf5d9870e8343e116c6892ea37aae","price":"0.98","side":"SELL","size":"683.1"}],"timestamp":"1785211869453"},"payload_hash":"f175ccc95119cf3a75ebd75fd726bdb4a43575bb1e219f994e3e056d0563e45a","raw_frame":"{\"market\":\"0xd412ce774cfcf8dc9f71164aac78783978aac7b03871702a3b8a481bd9dc9688\", \"price_changes\":[{\"asset_id\":\"107603864457683460275633293642179940881969192120168665300712204232021063124301\", \"price\":\"0.02\", \"size\":\"683.1\", \"side\":\"BUY\", \"hash\":\"de059bcd30a42eefa031551d4a55323d6013cb38\", \"best_bid\":\"0.59\", \"best_ask\":\"0.62\"}, {\"asset_id\":\"96600821790790307414914106093858868634329285205417149685270682748367152458577\", \"price\":\"0.98\", \"size\":\"683.1\", \"side\":\"SELL\", \"hash\":\"4f54db3379fbf5d9870e8343e116c6892ea37aae\", \"best_bid\":\"0.38\", \"best_ask\":\"0.41\"}], \"timestamp\":\"1785211869453\", \"event_type\":\"price_change\"}","received_at":"2026-07-28T04:11:11.672841Z","schema_version":"clob-market-ws.price_change.v1","sequence":null,"server_hash":null,"server_timestamp":"1785211869453","session_id":"2d607381e3054cee91998cdf45a4231c","source":"clob_market_ws"},"received_at":"2026-07-28T04:11:11.672841Z","record_id":"7d8d30db060240c9cd2fdcf31952b47988ff76b3f9bc83857e5e2f7aed9fd8ff","schema_fingerprint":"4aa3821a28b0b7c2400bc59aba4bcc0a76e971dadd19610d3ad38c768e124dc7","schema_version":"edge-lab-recorder.raw.v1","sequence":null,"source":"clob_market_ws"}
{"event_at":"2026-07-28T04:11:09.453000Z","event_fingerprint":"2347f9cf04bcc3a55042ab5db62d6281ba6e480c2bf5e0d749223690df8530e1","payload":{"connection_id":"f6725804f86a4c4eb588e4d5ed7db029","event_at":"2026-07-28T04:11:09.453000Z","event_type":"last_trade_price","frame_hash":"eb1c10b003436f16220b9cb87b92301e12ed9bdb3028354ab254bc7a0cfd7a96","frame_index":0,"kind":"data","monotonic_ns":313854753665958,"payload":{"asset_id":"96600821790790307414914106093858868634329285205417149685270682748367152458577","event_type":"last_trade_price","fee_rate_bps":"0","market":"0xd412ce774cfcf8dc9f71164aac78783978aac7b03871702a3b8a481bd9dc9688","price":"0.4","side":"BUY","size":"62.878047","timestamp":"1785211869453","transaction_hash":"0xdd9f8f2c7b9a5ecb4225995a6194e708a2698d4414fce38573b7ad2a78c96190"},"payload_hash":"6f5027d3faae5061f9b445dfd1fe1cbd0228d51218607292f068d3efe66442be","raw_frame":"{\"market\":\"0xd412ce774cfcf8dc9f71164aac78783978aac7b03871702a3b8a481bd9dc9688\", \"asset_id\":\"96600821790790307414914106093858868634329285205417149685270682748367152458577\", \"price\":\"0.4\", \"size\":\"62.878047\", \"fee_rate_bps\":\"0\", \"side\":\"BUY\", \"timestamp\":\"1785211869453\", \"event_type\":\"last_trade_price\", \"transaction_hash\":\"0xdd9f8f2c7b9a5ecb4225995a6194e708a2698d4414fce38573b7ad2a78c96190\"}","received_at":"2026-07-28T04:11:11.677061Z","schema_version":"clob-market-ws.last_trade_price.v1","sequence":null,"server_hash":null,"server_timestamp":"1785211869453","session_id":"2d607381e3054cee91998cdf45a4231c","source":"clob_market_ws"},"received_at":"2026-07-28T04:11:11.677061Z","record_id":"aef16b53d9432af229973ada1ecd4f086040f8e9e5c552a53e6fb0a528a922c0","schema_fingerprint":"95ad9be75a4b695cd99991e12b2592bc7346f3f5388a82d0000ba65bc0d9fd0a","schema_version":"edge-lab-recorder.raw.v1","sequence":null,"source":"clob_market_ws"}
{"event_at":"2026-07-28T04:11:09.474000Z","event_fingerprint":"337d747c63a375a61fb6ade046d75b46f8064e572570b388a243a2f8952323a8","payload":{"connection_id":"f6725804f86a4c4eb588e4d5ed7db029","event_at":"2026-07-28T04:11:09.474000Z","event_type":"price_change","frame_hash":"a0e27dc882833e7d86e637ae899bdf9c438d5c4cbb5be4c15d5728924ba160dc","frame_index":0,"kind":"data","monotonic_ns":313854756155041,"payload":{"event_type":"price_change","market":"0xd412ce774cfcf8dc9f71164aac78783978aac7b03871702a3b8a481bd9dc9688","price_changes":[{"asset_id":"107603864457683460275633293642179940881969192120168665300712204232021063124301","best_ask":"0.62","best_bid":"0.59","hash":"4705814da99c2c0108e0b52f1c6f7a3996fddb1a","price":"0.85","side":"SELL","size":"95"},{"asset_id":"96600821790790307414914106093858868634329285205417149685270682748367152458577","best_ask":"0.41","best_bid":"0.38","hash":"62d0f592ef223160dd3d6ee0f0565c42f8294dd5","price":"0.15","side":"BUY","size":"95"}],"timestamp":"1785211869474"},"payload_hash":"dbf822669fd415116638ca8e061d84e961fe2a652a6dc6272a1dbf0c5f5513e9","raw_frame":"{\"market\":\"0xd412ce774cfcf8dc9f71164aac78783978aac7b03871702a3b8a481bd9dc9688\", \"price_changes\":[{\"asset_id\":\"107603864457683460275633293642179940881969192120168665300712204232021063124301\", \"price\":\"0.85\", \"size\":\"95\", \"side\":\"SELL\", \"hash\":\"4705814da99c2c0108e0b52f1c6f7a3996fddb1a\", \"best_bid\":\"0.59\", \"best_ask\":\"0.62\"}, {\"asset_id\":\"96600821790790307414914106093858868634329285205417149685270682748367152458577\", \"price\":\"0.15\", \"size\":\"95\", \"side\":\"BUY\", \"hash\":\"62d0f592ef223160dd3d6ee0f0565c42f8294dd5\", \"best_bid\":\"0.38\", \"best_ask\":\"0.41\"}], \"timestamp\":\"1785211869474\", \"event_type\":\"price_change\"}","received_at":"2026-07-28T04:11:11.679549Z","schema_version":"clob-market-ws.price_change.v1","sequence":null,"server_hash":null,"server_timestamp":"1785211869474","session_id":"2d607381e3054cee91998cdf45a4231c","source":"clob_market_ws"},"received_at":"2026-07-28T04:11:11.679549Z","record_id":"edf779e44c2ce066ee1f97542444dedb40243c0b5c1c48bdef361007f82111c1","schema_fingerprint":"4aa3821a28b0b7c2400bc59aba4bcc0a76e971dadd19610d3ad38c768e124dc7","schema_version":"edge-lab-recorder.raw.v1","sequence":null,"source":"clob_market_ws"}
{"event_at":"2026-07-28T04:11:09.476000Z","event_fingerprint":"073e589540d3efcaf8784b9d0c83e7dbdc2a11203bf7890fede90a116d0289b5","payload":{"connection_id":"f6725804f86a4c4eb588e4d5ed7db029","event_at":"2026-07-28T04:11:09.476000Z","event_type":"best_bid_ask","frame_hash":"b7e9de71065150142db9a4bf71664d9cf3738bee032cbc081410764c04324dba","frame_index":0,"kind":"data","monotonic_ns":313854760335666,"payload":{"asset_id":"107603864457683460275633293642179940881969192120168665300712204232021063124301","best_ask":"0.62","best_bid":"0.6","event_type":"best_bid_ask","market":"0xd412ce774cfcf8dc9f71164aac78783978aac7b03871702a3b8a481bd9dc9688","spread":"0.02","timestamp":"1785211869476"},"payload_hash":"208edce762a51ff86b513e6ae6bddcd415a999aba82465eb6b08f46662dc2b0d","raw_frame":"{\"market\":\"0xd412ce774cfcf8dc9f71164aac78783978aac7b03871702a3b8a481bd9dc9688\", \"asset_id\":\"107603864457683460275633293642179940881969192120168665300712204232021063124301\", \"best_bid\":\"0.6\", \"best_ask\":\"0.62\", \"spread\":\"0.02\", \"timestamp\":\"1785211869476\", \"event_type\":\"best_bid_ask\"}","received_at":"2026-07-28T04:11:11.683730Z","schema_version":"clob-market-ws.best_bid_ask.v1","sequence":null,"server_hash":null,"server_timestamp":"1785211869476","session_id":"2d607381e3054cee91998cdf45a4231c","source":"clob_market_ws"},"received_at":"2026-07-28T04:11:11.683730Z","record_id":"b3716bdc10ca5b9ab594e6482370c83a560468e12a2b121b0a12901ed06cb277","schema_fingerprint":"8488399f31b0337811b13b266be932db7062827c2470b78bd8e9e99bab51d17d","schema_version":"edge-lab-recorder.raw.v1","sequence":null,"source":"clob_market_ws"}
{"event_at":"2026-07-28T04:11:09.476000Z","event_fingerprint":"ed2beceee0f84beafe6cec712adbef87940d6d7600c020739e52029ed5e11d62","payload":{"connection_id":"f6725804f86a4c4eb588e4d5ed7db029","event_at":"2026-07-28T04:11:09.476000Z","event_type":"best_bid_ask","frame_hash":"ba04d79b5a0d6c3e16a53714741d45c0ba02dc29db5818d92282a51fd49d32b5","frame_index":0,"kind":"data","monotonic_ns":313854766419541,"payload":{"asset_id":"96600821790790307414914106093858868634329285205417149685270682748367152458577","best_ask":"0.4","best_bid":"0.38","event_type":"best_bid_ask","market":"0xd412ce774cfcf8dc9f71164aac78783978aac7b03871702a3b8a481bd9dc9688","spread":"0.02","timestamp":"1785211869476"},"payload_hash":"c6275768c2b2b85c4027de19b699504457f3dd25f5279ab9a4c4fc8f7d686214","raw_frame":"{\"market\":\"0xd412ce774cfcf8dc9f71164aac78783978aac7b03871702a3b8a481bd9dc9688\", \"asset_id\":\"96600821790790307414914106093858868634329285205417149685270682748367152458577\", \"best_bid\":\"0.38\", \"best_ask\":\"0.4\", \"spread\":\"0.02\", \"timestamp\":\"1785211869476\", \"event_type\":\"best_bid_ask\"}","received_at":"2026-07-28T04:11:11.689813Z","schema_version":"clob-market-ws.best_bid_ask.v1","sequence":null,"server_hash":null,"server_timestamp":"1785211869476","session_id":"2d607381e3054cee91998cdf45a4231c","source":"clob_market_ws"},"received_at":"2026-07-28T04:11:11.689813Z","record_id":"48b83bd1e7cd8f2938c12ae55ca78830068110c36c360ae5d70c384478c98ed5","schema_fingerprint":"8488399f31b0337811b13b266be932db7062827c2470b78bd8e9e99bab51d17d","schema_version":"edge-lab-recorder.raw.v1","sequence":null,"source":"clob_market_ws"}
{"event_at":"2026-07-28T04:11:09.476000Z","event_fingerprint":"493662389a8a94ec9ecfda2cb2dd7989ecbecb995e34bdd57c044e220c025bac","payload":{"connection_id":"f6725804f86a4c4eb588e4d5ed7db029","event_at":"2026-07-28T04:11:09.476000Z","event_type":"price_change","frame_hash":"3d3874aacbbab5b04f1fb0479a0cdcefaed27e6813907ab626be40ec1bdbc5d2","frame_index":0,"kind":"data","monotonic_ns":313854770247666,"payload":{"event_type":"price_change","market":"0xd412ce774cfcf8dc9f71164aac78783978aac7b03871702a3b8a481bd9dc9688","price_changes":[{"asset_id":"96600821790790307414914106093858868634329285205417149685270682748367152458577","best_ask":"0.4","best_bid":"0.38","hash":"e6b8b8d0693df86d54061a31c66cb1831f745bbb","price":"0.4","side":"SELL","size":"5"},{"asset_id":"107603864457683460275633293642179940881969192120168665300712204232021063124301","best_ask":"0.62","best_bid":"0.6","hash":"e73fcaea6368932e5f107ffc69f0ffd66874a98d","price":"0.6","side":"BUY","size":"5"}],"timestamp":"1785211869476"},"payload_hash":"b8b2421c107f9e384dde251ea3ba702c7537a335b3a87f9a4bd2f9ad97819f46","raw_frame":"{\"market\":\"0xd412ce774cfcf8dc9f71164aac78783978aac7b03871702a3b8a481bd9dc9688\", \"price_changes\":[{\"asset_id\":\"96600821790790307414914106093858868634329285205417149685270682748367152458577\", \"price\":\"0.4\", \"size\":\"5\", \"side\":\"SELL\", \"hash\":\"e6b8b8d0693df86d54061a31c66cb1831f745bbb\", \"best_bid\":\"0.38\", \"best_ask\":\"0.4\"}, {\"asset_id\":\"107603864457683460275633293642179940881969192120168665300712204232021063124301\", \"price\":\"0.6\", \"size\":\"5\", \"side\":\"BUY\", \"hash\":\"e73fcaea6368932e5f107ffc69f0ffd66874a98d\", \"best_bid\":\"0.6\", \"best_ask\":\"0.62\"}], \"timestamp\":\"1785211869476\", \"event_type\":\"price_change\"}","received_at":"2026-07-28T04:11:11.693641Z","schema_version":"clob-market-ws.price_change.v1","sequence":null,"server_hash":null,"server_timestamp":"1785211869476","session_id":"2d607381e3054cee91998cdf45a4231c","source":"clob_market_ws"},"received_at":"2026-07-28T04:11:11.693641Z","record_id":"24c4c3a2769a27f2b6ec1e84d97977b1a8a34220aff82906455263bf72de96b7","schema_fingerprint":"4aa3821a28b0b7c2400bc59aba4bcc0a76e971dadd19610d3ad38c768e124dc7","schema_version":"edge-lab-recorder.raw.v1","sequence":null,"source":"clob_market_ws"}
{"event_at":"2026-07-28T04:11:09.478000Z","event_fingerprint":"86e88be86b903c87a148ccf31a9056edcd00cf800bfd14f9a8b1a85179068861","payload":{"connection_id":"f6725804f86a4c4eb588e4d5ed7db029","event_at":"2026-07-28T04:11:09.478000Z","event_type":"price_change","frame_hash":"08bbf0ffbf5a6de6ba341a7b3dd8c0b8d8c6bbdf29c54ba9cf752b93e3ccd65a","frame_index":0,"kind":"data","monotonic_ns":313854774592000,"payload":{"event_type":"price_change","market":"0xd412ce774cfcf8dc9f71164aac78783978aac7b03871702a3b8a481bd9dc9688","price_changes":[{"asset_id":"107603864457683460275633293642179940881969192120168665300712204232021063124301","best_ask":"0.62","best_bid":"0.6","hash":"3cfcda130fb85611c55f9b357ed28673829f2d29","price":"0.59","side":"BUY","size":"0"},{"asset_id":"96600821790790307414914106093858868634329285205417149685270682748367152458577","best_ask":"0.4","best_bid":"0.38","hash":"9b1f9a3173eb8eec6a3e39e5f59841edccb783a2","price":"0.41","side":"SELL","size":"0"}],"timestamp":"1785211869478"},"payload_hash":"52710aaefdd15342cd89a14711d8ff47ff587b2b3af931916c82c98ee758d8c7","raw_frame":"{\"market\":\"0xd412ce774cfcf8dc9f71164aac78783978aac7b03871702a3b8a481bd9dc9688\", \"price_changes\":[{\"asset_id\":\"107603864457683460275633293642179940881969192120168665300712204232021063124301\", \"price\":\"0.59\", \"size\":\"0\", \"side\":\"BUY\", \"hash\":\"3cfcda130fb85611c55f9b357ed28673829f2d29\", \"best_bid\":\"0.6\", \"best_ask\":\"0.62\"}, {\"asset_id\":\"96600821790790307414914106093858868634329285205417149685270682748367152458577\", \"price\":\"0.41\", \"size\":\"0\", \"side\":\"SELL\", \"hash\":\"9b1f9a3173eb8eec6a3e39e5f59841edccb783a2\", \"best_bid\":\"0.38\", \"best_ask\":\"0.4\"}], \"timestamp\":\"1785211869478\", \"event_type\":\"price_change\"}","received_at":"2026-07-28T04:11:11.697986Z","schema_version":"clob-market-ws.price_change.v1","sequence":null,"server_hash":null,"server_timestamp":"1785211869478","session_id":"2d607381e3054cee91998cdf45a4231c","source":"clob_market_ws"},"received_at":"2026-07-28T04:11:11.697986Z","record_id":"9e3ec1145c1964be6fcb5fca70350d83dcd9ce3330fbc65c7464c1886a722d91","schema_fingerprint":"4aa3821a28b0b7c2400bc59aba4bcc0a76e971dadd19610d3ad38c768e124dc7","schema_version":"edge-lab-recorder.raw.v1","sequence":null,"source":"clob_market_ws"}
{"event_at":"2026-07-28T04:11:09.479000Z","event_fingerprint":"ff6fc72837ca393c7513a570d353bd22a6cd3790cccffb2139e5f52380dde50c","payload":{"connection_id":"f6725804f86a4c4eb588e4d5ed7db029","event_at":"2026-07-28T04:11:09.479000Z","event_type":"price_change","frame_hash":"109f829a72bb992d0c561fd13116ebd0be74ac4d5ec4b73da5740c0055c06ef7","frame_index":0,"kind":"data","monotonic_ns":313854778838000,"payload":{"event_type":"price_change","market":"0xd412ce774cfcf8dc9f71164aac78783978aac7b03871702a3b8a481bd9dc9688","price_changes":[{"asset_id":"107603864457683460275633293642179940881969192120168665300712204232021063124301","best_ask":"0.62","best_bid":"0.6","hash":"6936accbab6c96173dae72857fa6ba4a88a53f8d","price":"0.6","side":"BUY","size":"17.6"},{"asset_id":"96600821790790307414914106093858868634329285205417149685270682748367152458577","best_ask":"0.4","best_bid":"0.38","hash":"f9630fcd4f87d903a2eb8c91315ff354c23bbcf6","price":"0.4","side":"SELL","size":"17.6"}],"timestamp":"1785211869479"},"payload_hash":"7b761ae9b91e19ca1a467e4f938ae178530a0fa6dd5eec68a6e3152b78e37548","raw_frame":"{\"market\":\"0xd412ce774cfcf8dc9f71164aac78783978aac7b03871702a3b8a481bd9dc9688\", \"price_changes\":[{\"asset_id\":\"107603864457683460275633293642179940881969192120168665300712204232021063124301\", \"price\":\"0.6\", \"size\":\"17.6\", \"side\":\"BUY\", \"hash\":\"6936accbab6c96173dae72857fa6ba4a88a53f8d\", \"best_bid\":\"0.6\", \"best_ask\":\"0.62\"}, {\"asset_id\":\"96600821790790307414914106093858868634329285205417149685270682748367152458577\", \"price\":\"0.4\", \"size\":\"17.6\", \"side\":\"SELL\", \"hash\":\"f9630fcd4f87d903a2eb8c91315ff354c23bbcf6\", \"best_bid\":\"0.38\", \"best_ask\":\"0.4\"}], \"timestamp\":\"1785211869479\", \"event_type\":\"price_change\"}","received_at":"2026-07-28T04:11:11.702232Z","schema_version":"clob-market-ws.price_change.v1","sequence":null,"server_hash":null,"server_timestamp":"1785211869479","session_id":"2d607381e3054cee91998cdf45a4231c","source":"clob_market_ws"},"received_at":"2026-07-28T04:11:11.702232Z","record_id":"027088c6f11899667c46a9103e9a8fa6c5b8e687c2e4eb7743451fb599faa916","schema_fingerprint":"4aa3821a28b0b7c2400bc59aba4bcc0a76e971dadd19610d3ad38c768e124dc7","schema_version":"edge-lab-recorder.raw.v1","sequence":null,"source":"clob_market_ws"}
{"event_at":"2026-07-28T04:11:09.480000Z","event_fingerprint":"827c2e29814f3116dac2e04a39d2fefb496ee9530b5729297a659041f7404761","payload":{"connection_id":"f6725804f86a4c4eb588e4d5ed7db029","event_at":"2026-07-28T04:11:09.480000Z","event_type":"price_change","frame_hash":"c8e7f8c188005c3f7be88804fc01f1125c33f544de6fb3cb56aad3ee0d0c80ca","frame_index":0,"kind":"data","monotonic_ns":313854781648625,"payload":{"event_type":"price_change","market":"0xd412ce774cfcf8dc9f71164aac78783978aac7b03871702a3b8a481bd9dc9688","price_changes":[{"asset_id":"107603864457683460275633293642179940881969192120168665300712204232021063124301","best_ask":"0.62","best_bid":"0.6","hash":"4d1769b4738903874a146f5a7234885b12b50cf2","price":"0.59","side":"BUY","size":"13"},{"asset_id":"96600821790790307414914106093858868634329285205417149685270682748367152458577","best_ask":"0.4","best_bid":"0.38","hash":"fb75c23b4609c9fe5436c49e1a1d226a0b0107d0","price":"0.41","side":"SELL","size":"13"}],"timestamp":"1785211869480"},"payload_hash":"2aa0e5ca2dcb6bd5c9f26df6ce0e9af61aa512ca394f596f810c612fcd98dce0","raw_frame":"{\"market\":\"0xd412ce774cfcf8dc9f71164aac78783978aac7b03871702a3b8a481bd9dc9688\", \"price_changes\":[{\"asset_id\":\"107603864457683460275633293642179940881969192120168665300712204232021063124301\", \"price\":\"0.59\", \"size\":\"13\", \"side\":\"BUY\", \"hash\":\"4d1769b4738903874a146f5a7234885b12b50cf2\", \"best_bid\":\"0.6\", \"best_ask\":\"0.62\"}, {\"asset_id\":\"96600821790790307414914106093858868634329285205417149685270682748367152458577\", \"price\":\"0.41\", \"size\":\"13\", \"side\":\"SELL\", \"hash\":\"fb75c23b4609c9fe5436c49e1a1d226a0b0107d0\", \"best_bid\":\"0.38\", \"best_ask\":\"0.4\"}], \"timestamp\":\"1785211869480\", \"event_type\":\"price_change\"}","received_at":"2026-07-28T04:11:11.705043Z","schema_version":"clob-market-ws.price_change.v1","sequence":null,"server_hash":null,"server_timestamp":"1785211869480","session_id":"2d607381e3054cee91998cdf45a4231c","source":"clob_market_ws"},"received_at":"2026-07-28T04:11:11.705043Z","record_id":"838093d8293cd830bf80ccd6b8a085f6f1e57e9d5f17dc21ebdc0f7abcfa19b1","schema_fingerprint":"4aa3821a28b0b7c2400bc59aba4bcc0a76e971dadd19610d3ad38c768e124dc7","schema_version":"edge-lab-recorder.raw.v1","sequence":null,"source":"clob_market_ws"}
{"event_at":"2026-07-28T04:11:09.481000Z","event_fingerprint":"5d5780909898bcd268e6d7c4120fc5e276d5e1fa307efd13554aff149acdf151","payload":{"connection_id":"f6725804f86a4c4eb588e4d5ed7db029","event_at":"2026-07-28T04:11:09.481000Z","event_type":"price_change","frame_hash":"6fdb2c1666d0a11eb5a8d9cc72a3274fd00764bcaee9bf961611392582413c81","frame_index":0,"kind":"data","monotonic_ns":313854785925958,"payload":{"event_type":"price_change","market":"0xd412ce774cfcf8dc9f71164aac78783978aac7b03871702a3b8a481bd9dc9688","price_changes":[{"asset_id":"107603864457683460275633293642179940881969192120168665300712204232021063124301","best_ask":"0.62","best_bid":"0.6","hash":"d208a1089ecaa127a2149ec6be423ed4f41f04ae","price":"0.56","side":"BUY","size":"113.97"},{"asset_id":"96600821790790307414914106093858868634329285205417149685270682748367152458577","best_ask":"0.4","best_bid":"0.38","hash":"9f196b6548ecd5683ca92d430688fb210bc60686","price":"0.44","side":"SELL","size":"113.97"}],"timestamp":"1785211869481"},"payload_hash":"adbd8b906e947802a252cf5ed1c48af2993491180391913f99ee231c4f727214","raw_frame":"{\"market\":\"0xd412ce774cfcf8dc9f71164aac78783978aac7b03871702a3b8a481bd9dc9688\", \"price_changes\":[{\"asset_id\":\"107603864457683460275633293642179940881969192120168665300712204232021063124301\", \"price\":\"0.56\", \"size\":\"113.97\", \"side\":\"BUY\", \"hash\":\"d208a1089ecaa127a2149ec6be423ed4f41f04ae\", \"best_bid\":\"0.6\", \"best_ask\":\"0.62\"}, {\"asset_id\":\"96600821790790307414914106093858868634329285205417149685270682748367152458577\", \"price\":\"0.44\", \"size\":\"113.97\", \"side\":\"SELL\", \"hash\":\"9f196b6548ecd5683ca92d430688fb210bc60686\", \"best_bid\":\"0.38\", \"best_ask\":\"0.4\"}], \"timestamp\":\"1785211869481\", \"event_type\":\"price_change\"}","received_at":"2026-07-28T04:11:11.709319Z","schema_version":"clob-market-ws.price_change.v1","sequence":null,"server_hash":null,"server_timestamp":"1785211869481","session_id":"2d607381e3054cee91998cdf45a4231c","source":"clob_market_ws"},"received_at":"2026-07-28T04:11:11.709319Z","record_id":"0252317cb5c2b3e9064f5ab850052518c5a1b97bfa5e2893b80f068e1a5538a0","schema_fingerprint":"4aa3821a28b0b7c2400bc59aba4bcc0a76e971dadd19610d3ad38c768e124dc7","schema_version":"edge-lab-recorder.raw.v1","sequence":null,"source":"clob_market_ws"}
{"event_at":"2026-07-28T04:11:09.482000Z","event_fingerprint":"6859f3a773c6dbf1e8901eef43b3e96da717d81790653767caa6be943ea00373","payload":{"connection_id":"f6725804f86a4c4eb588e4d5ed7db029","event_at":"2026-07-28T04:11:09.482000Z","event_type":"price_change","frame_hash":"d2a4d8ae1a798bc8f3b297bd8bdc9ae9c758ad55aa9f5ca150146a02ac168431","frame_index":0,"kind":"data","monotonic_ns":313854790208916,"payload":{"event_type":"price_change","market":"0xd412ce774cfcf8dc9f71164aac78783978aac7b03871702a3b8a481bd9dc9688","price_changes":[{"asset_id":"96600821790790307414914106093858868634329285205417149685270682748367152458577","best_ask":"0.4","best_bid":"0.38","hash":"ebd7d7c0c137ade44dcc95b5160cebbd447cea7e","price":"0.37","side":"BUY","size":"19"},{"asset_id":"107603864457683460275633293642179940881969192120168665300712204232021063124301","best_ask":"0.62","best_bid":"0.6","hash":"bb9f4c1d2bca8513dbd63a156fac33fd1b67e2b1","price":"0.63","side":"SELL","size":"19"}],"timestamp":"1785211869482"},"payload_hash":"0b740a1bf3fb5efadb51ca427251f1503dfe349651353fc71abb3b7d9bf6af59","raw_frame":"{\"market\":\"0xd412ce774cfcf8dc9f71164aac78783978aac7b03871702a3b8a481bd9dc9688\", \"price_changes\":[{\"asset_id\":\"96600821790790307414914106093858868634329285205417149685270682748367152458577\", \"price\":\"0.37\", \"size\":\"19\", \"side\":\"BUY\", \"hash\":\"ebd7d7c0c137ade44dcc95b5160cebbd447cea7e\", \"best_bid\":\"0.38\", \"best_ask\":\"0.4\"}, {\"asset_id\":\"107603864457683460275633293642179940881969192120168665300712204232021063124301\", \"price\":\"0.63\", \"size\":\"19\", \"side\":\"SELL\", \"hash\":\"bb9f4c1d2bca8513dbd63a156fac33fd1b67e2b1\", \"best_bid\":\"0.6\", \"best_ask\":\"0.62\"}], \"timestamp\":\"1785211869482\", \"event_type\":\"price_change\"}","received_at":"2026-07-28T04:11:11.713602Z","schema_version":"clob-market-ws.price_change.v1","sequence":null,"server_hash":null,"server_timestamp":"1785211869482","session_id":"2d607381e3054cee91998cdf45a4231c","source":"clob_market_ws"},"received_at":"2026-07-28T04:11:11.713602Z","record_id":"dade5554d0b8ccf08d92ba219ef42216814f7ad5c79191dc12eccca26dbfde25","schema_fingerprint":"4aa3821a28b0b7c2400bc59aba4bcc0a76e971dadd19610d3ad38c768e124dc7","schema_version":"edge-lab-recorder.raw.v1","sequence":null,"source":"clob_market_ws"}
{"event_at":"2026-07-28T04:11:09.486000Z","event_fingerprint":"2c4f1f7df988f4f69b32658ab16ae713f0d4c19d809cbb2e8a20437810712dc7","payload":{"connection_id":"f6725804f86a4c4eb588e4d5ed7db029","event_at":"2026-07-28T04:11:09.486000Z","event_type":"price_change","frame_hash":"fbd0f9b440b03d0e3ac25e51452c4ca3360bc89d33913a2fffec1b4d48fd71a2","frame_index":0,"kind":"data","monotonic_ns":313854794440875,"payload":{"event_type":"price_change","market":"0xd412ce774cfcf8dc9f71164aac78783978aac7b03871702a3b8a481bd9dc9688","price_changes":[{"asset_id":"107603864457683460275633293642179940881969192120168665300712204232021063124301","best_ask":"0.62","best_bid":"0.6","hash":"2a02c43ce3ad61b389024e1980ce6b6406781776","price":"0.59","side":"BUY","size":"25.6"},{"asset_id":"96600821790790307414914106093858868634329285205417149685270682748367152458577","best_ask":"0.4","best_bid":"0.38","hash":"0b7344db56b2f61a178e6ba033248770cbfa5acb","price":"0.41","side":"SELL","size":"25.6"}],"timestamp":"1785211869486"},"payload_hash":"f716152b7f088669f0a0c478f1309c8832fe612b48b89dfdd21a3f489bc5b25c","raw_frame":"{\"market\":\"0xd412ce774cfcf8dc9f71164aac78783978aac7b03871702a3b8a481bd9dc9688\", \"price_changes\":[{\"asset_id\":\"107603864457683460275633293642179940881969192120168665300712204232021063124301\", \"price\":\"0.59\", \"size\":\"25.6\", \"side\":\"BUY\", \"hash\":\"2a02c43ce3ad61b389024e1980ce6b6406781776\", \"best_bid\":\"0.6\", \"best_ask\":\"0.62\"}, {\"asset_id\":\"96600821790790307414914106093858868634329285205417149685270682748367152458577\", \"price\":\"0.41\", \"size\":\"25.6\", \"side\":\"SELL\", \"hash\":\"0b7344db56b2f61a178e6ba033248770cbfa5acb\", \"best_bid\":\"0.38\", \"best_ask\":\"0.4\"}], \"timestamp\":\"1785211869486\", \"event_type\":\"price_change\"}","received_at":"2026-07-28T04:11:11.717834Z","schema_version":"clob-market-ws.price_change.v1","sequence":null,"server_hash":null,"server_timestamp":"1785211869486","session_id":"2d607381e3054cee91998cdf45a4231c","source":"clob_market_ws"},"received_at":"2026-07-28T04:11:11.717834Z","record_id":"edbffcdb7583ae4af0ca7302a595198822eea36119195b70dd9d502e0ffd8a9a","schema_fingerprint":"4aa3821a28b0b7c2400bc59aba4bcc0a76e971dadd19610d3ad38c768e124dc7","schema_version":"edge-lab-recorder.raw.v1","sequence":null,"source":"clob_market_ws"}
{"event_at":"2026-07-28T04:11:09.494000Z","event_fingerprint":"786376cf218c9230fdb02269c7dbea836caf52838e0e27624b99092e6ace3954","payload":{"connection_id":"f6725804f86a4c4eb588e4d5ed7db029","event_at":"2026-07-28T04:11:09.494000Z","event_type":"price_change","frame_hash":"e566efd0a967071de9568845bf01296a5346cbf1cc8df1aeb26a274ee8df5822","frame_index":0,"kind":"data","monotonic_ns":313854798655041,"payload":{"event_type":"price_change","market":"0xd412ce774cfcf8dc9f71164aac78783978aac7b03871702a3b8a481bd9dc9688","price_changes":[{"asset_id":"96600821790790307414914106093858868634329285205417149685270682748367152458577","best_ask":"0.4","best_bid":"0.38","hash":"476ae287c8f3cae0b5717602857fcb15fead8cb9","price":"0.4","side":"SELL","size":"12.6"},{"asset_id":"107603864457683460275633293642179940881969192120168665300712204232021063124301","best_ask":"0.62","best_bid":"0.6","hash":"91e6e67c3a28add110f67875f7b1ee31dd89e5d3","price":"0.6","side":"BUY","size":"12.6"}],"timestamp":"1785211869494"},"payload_hash":"053cd8db8a837a65b2c737670aadc6e2983c91036283906714701e6ff007b8db","raw_frame":"{\"market\":\"0xd412ce774cfcf8dc9f71164aac78783978aac7b03871702a3b8a481bd9dc9688\", \"price_changes\":[{\"asset_id\":\"96600821790790307414914106093858868634329285205417149685270682748367152458577\", \"price\":\"0.4\", \"size\":\"12.6\", \"side\":\"SELL\", \"hash\":\"476ae287c8f3cae0b5717602857fcb15fead8cb9\", \"best_bid\":\"0.38\", \"best_ask\":\"0.4\"}, {\"asset_id\":\"107603864457683460275633293642179940881969192120168665300712204232021063124301\", \"price\":\"0.6\", \"size\":\"12.6\", \"side\":\"BUY\", \"hash\":\"91e6e67c3a28add110f67875f7b1ee31dd89e5d3\", \"best_bid\":\"0.6\", \"best_ask\":\"0.62\"}], \"timestamp\":\"1785211869494\", \"event_type\":\"price_change\"}","received_at":"2026-07-28T04:11:11.722049Z","schema_version":"clob-market-ws.price_change.v1","sequence":null,"server_hash":null,"server_timestamp":"1785211869494","session_id":"2d607381e3054cee91998cdf45a4231c","source":"clob_market_ws"},"received_at":"2026-07-28T04:11:11.722049Z","record_id":"d6a8f286ba62180811f8168546966ad35a6c0963e7d90998189a8e211849154f","schema_fingerprint":"4aa3821a28b0b7c2400bc59aba4bcc0a76e971dadd19610d3ad38c768e124dc7","schema_version":"edge-lab-recorder.raw.v1","sequence":null,"source":"clob_market_ws"}
{"event_at":"2026-07-28T04:11:09.497000Z","event_fingerprint":"dcc4694f1a1a52da10578063189d789a4ed74b0e6e34866c6077345f9e29058b","payload":{"connection_id":"f6725804f86a4c4eb588e4d5ed7db029","event_at":"2026-07-28T04:11:09.497000Z","event_type":"price_change","frame_hash":"e5ab3e04fbfc92b7f891195180c1e8aa822e9ed23222f3693207175f56521b85","frame_index":0,"kind":"data","monotonic_ns":313854802824166,"payload":{"event_type":"price_change","market":"0xd412ce774cfcf8dc9f71164aac78783978aac7b03871702a3b8a481bd9dc9688","price_changes":[{"asset_id":"107603864457683460275633293642179940881969192120168665300712204232021063124301","best_ask":"0.62","best_bid":"0.6","hash":"bc48c25a9e971ad9afc59f87e647388edb59c06f","price":"0.59","side":"BUY","size":"31.6"},{"asset_id":"96600821790790307414914106093858868634329285205417149685270682748367152458577","best_ask":"0.4","best_bid":"0.38","hash":"175f086cf0bcc77b69b5d96b5a318c3be4d35aca","price":"0.41","side":"SELL","size":"31.6"}],"timestamp":"1785211869497"},"payload_hash":"2d42f28915b8eef42f913f4f95aa0e641401e8bd0594a507acb7b31de2dc29ff","raw_frame":"{\"market\":\"0xd412ce774cfcf8dc9f71164aac78783978aac7b03871702a3b8a481bd9dc9688\", \"price_changes\":[{\"asset_id\":\"107603864457683460275633293642179940881969192120168665300712204232021063124301\", \"price\":\"0.59\", \"size\":\"31.6\", \"side\":\"BUY\", \"hash\":\"bc48c25a9e971ad9afc59f87e647388edb59c06f\", \"best_bid\":\"0.6\", \"best_ask\":\"0.62\"}, {\"asset_id\":\"96600821790790307414914106093858868634329285205417149685270682748367152458577\", \"price\":\"0.41\", \"size\":\"31.6\", \"side\":\"SELL\", \"hash\":\"175f086cf0bcc77b69b5d96b5a318c3be4d35aca\", \"best_bid\":\"0.38\", \"best_ask\":\"0.4\"}], \"timestamp\":\"1785211869497\", \"event_type\":\"price_change\"}","received_at":"2026-07-28T04:11:11.726218Z","schema_version":"clob-market-ws.price_change.v1","sequence":null,"server_hash":null,"server_timestamp":"1785211869497","session_id":"2d607381e3054cee91998cdf45a4231c","source":"clob_market_ws"},"received_at":"2026-07-28T04:11:11.726218Z","record_id":"b4aa602abd41e5e42a109d2e98023feab2c32ffbb4890fc9bb70dbf6f5d0b549","schema_fingerprint":"4aa3821a28b0b7c2400bc59aba4bcc0a76e971dadd19610d3ad38c768e124dc7","schema_version":"edge-lab-recorder.raw.v1","sequence":null,"source":"clob_market_ws"}
{"event_at":"2026-07-28T04:11:09.498000Z","event_fingerprint":"23248e773ee86f8ea0008f94c4db214244f95ee6bac3fc55314f31255657d2bd","payload":{"connection_id":"f6725804f86a4c4eb588e4d5ed7db029","event_at":"2026-07-28T04:11:09.498000Z","event_type":"price_change","frame_hash":"bdef99925b4e1d23a821e2ce5ad334951f31862048d534a67959598195174948","frame_index":0,"kind":"data","monotonic_ns":313854807120958,"payload":{"event_type":"price_change","market":"0xd412ce774cfcf8dc9f71164aac78783978aac7b03871702a3b8a481bd9dc9688","price_changes":[{"asset_id":"96600821790790307414914106093858868634329285205417149685270682748367152458577","best_ask":"0.4","best_bid":"0.38","hash":"144ab93024b43d65a319db19d07d75231e0ecfae","price":"0.34","side":"BUY","size":"50.2"},{"asset_id":"107603864457683460275633293642179940881969192120168665300712204232021063124301","best_ask":"0.62","best_bid":"0.6","hash":"3f9c69fe3cfa4368ca434c36a8758b24fec6e93d","price":"0.66","side":"SELL","size":"50.2"}],"timestamp":"1785211869498"},"payload_hash":"63751d9df6b5438770d82ec319c481b9a4b82fc594738b0f6f2dce30849ac3b6","raw_frame":"{\"market\":\"0xd412ce774cfcf8dc9f71164aac78783978aac7b03871702a3b8a481bd9dc9688\", \"price_changes\":[{\"asset_id\":\"96600821790790307414914106093858868634329285205417149685270682748367152458577\", \"price\":\"0.34\", \"size\":\"50.2\", \"side\":\"BUY\", \"hash\":\"144ab93024b43d65a319db19d07d75231e0ecfae\", \"best_bid\":\"0.38\", \"best_ask\":\"0.4\"}, {\"asset_id\":\"107603864457683460275633293642179940881969192120168665300712204232021063124301\", \"price\":\"0.66\", \"size\":\"50.2\", \"side\":\"SELL\", \"hash\":\"3f9c69fe3cfa4368ca434c36a8758b24fec6e93d\", \"best_bid\":\"0.6\", \"best_ask\":\"0.62\"}], \"timestamp\":\"1785211869498\", \"event_type\":\"price_change\"}","received_at":"2026-07-28T04:11:11.730514Z","schema_version":"clob-market-ws.price_change.v1","sequence":null,"server_hash":null,"server_timestamp":"1785211869498","session_id":"2d607381e3054cee91998cdf45a4231c","source":"clob_market_ws"},"received_at":"2026-07-28T04:11:11.730514Z","record_id":"ee910a241ae355786469cf774ea5f14ae6a6ebe10b13854548523c5cf6e2bef0","schema_fingerprint":"4aa3821a28b0b7c2400bc59aba4bcc0a76e971dadd19610d3ad38c768e124dc7","schema_version":"edge-lab-recorder.raw.v1","sequence":null,"source":"clob_market_ws"}
{"event_at":"2026-07-28T04:11:09.499000Z","event_fingerprint":"8c1ba845c83097123d8818bebecc64d59fb8b91b2b8b1a1ce5267330338402ea","payload":{"connection_id":"f6725804f86a4c4eb588e4d5ed7db029","event_at":"2026-07-28T04:11:09.499000Z","event_type":"price_change","frame_hash":"3688fea21fd602e8dfca11e92ec7abd5e7b89c221003fbd4ec943fd1e66b2768","frame_index":0,"kind":"data","monotonic_ns":313854810087000,"payload":{"event_type":"price_change","market":"0xd412ce774cfcf8dc9f71164aac78783978aac7b03871702a3b8a481bd9dc9688","price_changes":[{"asset_id":"96600821790790307414914106093858868634329285205417149685270682748367152458577","best_ask":"0.4","best_bid":"0.38","hash":"0f147a1bd38e18fa1f983364d3ca343526ce102e","price":"0.35","side":"BUY","size":"44.2"},{"asset_id":"107603864457683460275633293642179940881969192120168665300712204232021063124301","best_ask":"0.62","best_bid":"0.6","hash":"08e40e8adc041aff93f621a45aa48e8e57edf6db","price":"0.65","side":"SELL","size":"44.2"}],"timestamp":"1785211869499"},"payload_hash":"03668b3327fe982e0b2e6ec961d11044a605c0be0ba61caacc0955810e39329e","raw_frame":"{\"market\":\"0xd412ce774cfcf8dc9f71164aac78783978aac7b03871702a3b8a481bd9dc9688\", \"price_changes\":[{\"asset_id\":\"96600821790790307414914106093858868634329285205417149685270682748367152458577\", \"price\":\"0.35\", \"size\":\"44.2\", \"side\":\"BUY\", \"hash\":\"0f147a1bd38e18fa1f983364d3ca343526ce102e\", \"best_bid\":\"0.38\", \"best_ask\":\"0.4\"}, {\"asset_id\":\"107603864457683460275633293642179940881969192120168665300712204232021063124301\", \"price\":\"0.65\", \"size\":\"44.2\", \"side\":\"SELL\", \"hash\":\"08e40e8adc041aff93f621a45aa48e8e57edf6db\", \"best_bid\":\"0.6\", \"best_ask\":\"0.62\"}], \"timestamp\":\"1785211869499\", \"event_type\":\"price_change\"}","received_at":"2026-07-28T04:11:11.733480Z","schema_version":"clob-market-ws.price_change.v1","sequence":null,"server_hash":null,"server_timestamp":"1785211869499","session_id":"2d607381e3054cee91998cdf45a4231c","source":"clob_market_ws"},"received_at":"2026-07-28T04:11:11.733480Z","record_id":"7e64a43b43e7b664034b77c94111c8bf4eda73ea52fb3ca168dbf39dba126e25","schema_fingerprint":"4aa3821a28b0b7c2400bc59aba4bcc0a76e971dadd19610d3ad38c768e124dc7","schema_version":"edge-lab-recorder.raw.v1","sequence":null,"source":"clob_market_ws"}
{"event_at":"2026-07-28T04:11:09.502000Z","event_fingerprint":"2fd981de1ae5cee0f8cdea2203d44e2db6b585ecf28037c54aa234889a4c1127","payload":{"connection_id":"f6725804f86a4c4eb588e4d5ed7db029","event_at":"2026-07-28T04:11:09.502000Z","event_type":"price_change","frame_hash":"02a8843acfb0b8300b1ac7f4f6c373f8ec590cc2e8cf520786d60b9ddbc94073","frame_index":0,"kind":"data","monotonic_ns":313854814397666,"payload":{"event_type":"price_change","market":"0xd412ce774cfcf8dc9f71164aac78783978aac7b03871702a3b8a481bd9dc9688","price_changes":[{"asset_id":"107603864457683460275633293642179940881969192120168665300712204232021063124301","best_ask":"0.62","best_bid":"0.6","hash":"8801fa059889dd8987546e79fd238ef6b4821fc5","price":"0.58","side":"BUY","size":"65"},{"asset_id":"96600821790790307414914106093858868634329285205417149685270682748367152458577","best_ask":"0.4","best_bid":"0.38","hash":"a1567f5e110b7028f3f2f498ff570ba77baff84b","price":"0.42","side":"SELL","size":"65"}],"timestamp":"1785211869502"},"payload_hash":"206f1fcd13f6539b2760aaf49f9de7aa256d66c58598eb2ecd87b58c46e3ff87","raw_frame":"{\"market\":\"0xd412ce774cfcf8dc9f71164aac78783978aac7b03871702a3b8a481bd9dc9688\", \"price_changes\":[{\"asset_id\":\"107603864457683460275633293642179940881969192120168665300712204232021063124301\", \"price\":\"0.58\", \"size\":\"65\", \"side\":\"BUY\", \"hash\":\"8801fa059889dd8987546e79fd238ef6b4821fc5\", \"best_bid\":\"0.6\", \"best_ask\":\"0.62\"}, {\"asset_id\":\"96600821790790307414914106093858868634329285205417149685270682748367152458577\", \"price\":\"0.42\", \"size\":\"65\", \"side\":\"SELL\", \"hash\":\"a1567f5e110b7028f3f2f498ff570ba77baff84b\", \"best_bid\":\"0.38\", \"best_ask\":\"0.4\"}], \"timestamp\":\"1785211869502\", \"event_type\":\"price_change\"}","received_at":"2026-07-28T04:11:11.737791Z","schema_version":"clob-market-ws.price_change.v1","sequence":null,"server_hash":null,"server_timestamp":"1785211869502","session_id":"2d607381e3054cee91998cdf45a4231c","source":"clob_market_ws"},"received_at":"2026-07-28T04:11:11.737791Z","record_id":"ddfe7adb4e996e2c1f7f19eefe676e98b99f17198eb14b142f06aa6dffb3deac","schema_fingerprint":"4aa3821a28b0b7c2400bc59aba4bcc0a76e971dadd19610d3ad38c768e124dc7","schema_version":"edge-lab-recorder.raw.v1","sequence":null,"source":"clob_market_ws"}
{"event_at":"2026-07-28T04:11:09.510000Z","event_fingerprint":"b3b9a68bc78fced52b42316bd6402df9d4e9355d9ce2e702502acf620078b47d","payload":{"connection_id":"f6725804f86a4c4eb588e4d5ed7db029","event_at":"2026-07-28T04:11:09.510000Z","event_type":"price_change","frame_hash":"9e90537a18662f14a74dee504f7289ae8ed24d7bd6ad734f4e98b1cda180ccb6","frame_index":0,"kind":"data","monotonic_ns":313854818621625,"payload":{"event_type":"price_change","market":"0xd412ce774cfcf8dc9f71164aac78783978aac7b03871702a3b8a481bd9dc9688","price_changes":[{"asset_id":"96600821790790307414914106093858868634329285205417149685270682748367152458577","best_ask":"0.4","best_bid":"0.38","hash":"599997e5a441134e17d06cce1d7e929ccc9a2a42","price":"0.34","side":"BUY","size":"44.2"},{"asset_id":"107603864457683460275633293642179940881969192120168665300712204232021063124301","best_ask":"0.62","best_bid":"0.6","hash":"5efb22a6d38f5202f1b62af7f8e31bfd989e5199","price":"0.66","side":"SELL","size":"44.2"}],"timestamp":"1785211869510"},"payload_hash":"b81a66155ff5c787ffad68db94070a320acc873dff4b4b4fbc25e9c0b17865b5","raw_frame":"{\"market\":\"0xd412ce774cfcf8dc9f71164aac78783978aac7b03871702a3b8a481bd9dc9688\", \"price_changes\":[{\"asset_id\":\"96600821790790307414914106093858868634329285205417149685270682748367152458577\", \"price\":\"0.34\", \"size\":\"44.2\", \"side\":\"BUY\", \"hash\":\"599997e5a441134e17d06cce1d7e929ccc9a2a42\", \"best_bid\":\"0.38\", \"best_ask\":\"0.4\"}, {\"asset_id\":\"107603864457683460275633293642179940881969192120168665300712204232021063124301\", \"price\":\"0.66\", \"size\":\"44.2\", \"side\":\"SELL\", \"hash\":\"5efb22a6d38f5202f1b62af7f8e31bfd989e5199\", \"best_bid\":\"0.6\", \"best_ask\":\"0.62\"}], \"timestamp\":\"1785211869510\", \"event_type\":\"price_change\"}","received_at":"2026-07-28T04:11:11.742015Z","schema_version":"clob-market-ws.price_change.v1","sequence":null,"server_hash":null,"server_timestamp":"1785211869510","session_id":"2d607381e3054cee91998cdf45a4231c","source":"clob_market_ws"},"received_at":"2026-07-28T04:11:11.742015Z","record_id":"34ce32294ccbd0519f51a92fba064083e10518956e0336f9d34a6b684b317a4b","schema_fingerprint":"4aa3821a28b0b7c2400bc59aba4bcc0a76e971dadd19610d3ad38c768e124dc7","schema_version":"edge-lab-recorder.raw.v1","sequence":null,"source":"clob_market_ws"}
{"event_at":"2026-07-28T04:11:09.536000Z","event_fingerprint":"6698acecd24065a5920f477957b5c451af85109aa3c10570073d969e9f050449","payload":{"connection_id":"f6725804f86a4c4eb588e4d5ed7db029","event_at":"2026-07-28T04:11:09.536000Z","event_type":"best_bid_ask","frame_hash":"255e9e61671689cb1b5fb1cdc2a9d69b56c544e975f62bd52bfba7444b876b2b","frame_index":0,"kind":"data","monotonic_ns":313854822294916,"payload":{"asset_id":"107603864457683460275633293642179940881969192120168665300712204232021063124301","best_ask":"0.62","best_bid":"0.61","event_type":"best_bid_ask","market":"0xd412ce774cfcf8dc9f71164aac78783978aac7b03871702a3b8a481bd9dc9688","spread":"0.01","timestamp":"1785211869536"},"payload_hash":"6cc2278b231c25cc64f92bad7e74ad31b434e3d5bfe15236bd6e8034855ed24d","raw_frame":"{\"market\":\"0xd412ce774cfcf8dc9f71164aac78783978aac7b03871702a3b8a481bd9dc9688\", \"asset_id\":\"107603864457683460275633293642179940881969192120168665300712204232021063124301\", \"best_bid\":\"0.61\", \"best_ask\":\"0.62\", \"spread\":\"0.01\", \"timestamp\":\"1785211869536\", \"event_type\":\"best_bid_ask\"}","received_at":"2026-07-28T04:11:11.745689Z","schema_version":"clob-market-ws.best_bid_ask.v1","sequence":null,"server_hash":null,"server_timestamp":"1785211869536","session_id":"2d607381e3054cee91998cdf45a4231c","source":"clob_market_ws"},"received_at":"2026-07-28T04:11:11.745689Z","record_id":"2b2c93cbc8f173ea7d2e0d784b540e294286a9d4c98014750add4515685e8f76","schema_fingerprint":"8488399f31b0337811b13b266be932db7062827c2470b78bd8e9e99bab51d17d","schema_version":"edge-lab-recorder.raw.v1","sequence":null,"source":"clob_market_ws"}
{"event_at":"2026-07-28T04:11:09.536000Z","event_fingerprint":"08b51c6817a2432c1658ecd3394869853233bc92727ec78122fc267174555f49","payload":{"connection_id":"f6725804f86a4c4eb588e4d5ed7db029","event_at":"2026-07-28T04:11:09.536000Z","event_type":"best_bid_ask","frame_hash":"8094b24ee34dc1279e850ddb9aba2c6d3136cf84d8ffaf2738b4fda30293909a","frame_index":0,"kind":"data","monotonic_ns":313854826027708,"payload":{"asset_id":"96600821790790307414914106093858868634329285205417149685270682748367152458577","best_ask":"0.39","best_bid":"0.38","event_type":"best_bid_ask","market":"0xd412ce774cfcf8dc9f71164aac78783978aac7b03871702a3b8a481bd9dc9688","spread":"0.01","timestamp":"1785211869536"},"payload_hash":"a8f6b4a6867a029545a0b0fc276f85f633ad69362d158ff5afe07cde446ccbdc","raw_frame":"{\"market\":\"0xd412ce774cfcf8dc9f71164aac78783978aac7b03871702a3b8a481bd9dc9688\", \"asset_id\":\"96600821790790307414914106093858868634329285205417149685270682748367152458577\", \"best_bid\":\"0.38\", \"best_ask\":\"0.39\", \"spread\":\"0.01\", \"timestamp\":\"1785211869536\", \"event_type\":\"best_bid_ask\"}","received_at":"2026-07-28T04:11:11.749421Z","schema_version":"clob-market-ws.best_bid_ask.v1","sequence":null,"server_hash":null,"server_timestamp":"1785211869536","session_id":"2d607381e3054cee91998cdf45a4231c","source":"clob_market_ws"},"received_at":"2026-07-28T04:11:11.749421Z","record_id":"7abf94b52932ce90031234bd0041abef81731ec5d984be4072aea2c32cec143f","schema_fingerprint":"8488399f31b0337811b13b266be932db7062827c2470b78bd8e9e99bab51d17d","schema_version":"edge-lab-recorder.raw.v1","sequence":null,"source":"clob_market_ws"}
{"event_at":"2026-07-28T04:11:09.536000Z","event_fingerprint":"5b4668786a4904ab2cfbc8bd3f9ca4bcfd459ffebbce6feab2ed7f0393855aa5","payload":{"connection_id":"f6725804f86a4c4eb588e4d5ed7db029","event_at":"2026-07-28T04:11:09.536000Z","event_type":"price_change","frame_hash":"b218eb1c324ab0759fdc0cfc7669d27f11d90ef07357cd1a84ac5cbe132a5b1c","frame_index":0,"kind":"data","monotonic_ns":313854829906500,"payload":{"event_type":"price_change","market":"0xd412ce774cfcf8dc9f71164aac78783978aac7b03871702a3b8a481bd9dc9688","price_changes":[{"asset_id":"107603864457683460275633293642179940881969192120168665300712204232021063124301","best_ask":"0.62","best_bid":"0.61","hash":"6447dc1b28ee231f40de45143a607d0c796829e9","price":"0.61","side":"BUY","size":"6"},{"asset_id":"96600821790790307414914106093858868634329285205417149685270682748367152458577","best_ask":"0.39","best_bid":"0.38","hash":"646a0f00879131ddc38c70c2c5bb84c06beca08e","price":"0.39","side":"SELL","size":"6"}],"timestamp":"1785211869536"},"payload_hash":"cf20aa6e85a54e43cf2a778eee868a4a49367dec29c5c91b1af86198316903ff","raw_frame":"{\"market\":\"0xd412ce774cfcf8dc9f71164aac78783978aac7b03871702a3b8a481bd9dc9688\", \"price_changes\":[{\"asset_id\":\"107603864457683460275633293642179940881969192120168665300712204232021063124301\", \"price\":\"0.61\", \"size\":\"6\", \"side\":\"BUY\", \"hash\":\"6447dc1b28ee231f40de45143a607d0c796829e9\", \"best_bid\":\"0.61\", \"best_ask\":\"0.62\"}, {\"asset_id\":\"96600821790790307414914106093858868634329285205417149685270682748367152458577\", \"price\":\"0.39\", \"size\":\"6\", \"side\":\"SELL\", \"hash\":\"646a0f00879131ddc38c70c2c5bb84c06beca08e\", \"best_bid\":\"0.38\", \"best_ask\":\"0.39\"}], \"timestamp\":\"1785211869536\", \"event_type\":\"price_change\"}","received_at":"2026-07-28T04:11:11.753300Z","schema_version":"clob-market-ws.price_change.v1","sequence":null,"server_hash":null,"server_timestamp":"1785211869536","session_id":"2d607381e3054cee91998cdf45a4231c","source":"clob_market_ws"},"received_at":"2026-07-28T04:11:11.753300Z","record_id":"26a7516450705dcd469fcb20225173fbb6cb534fac9bd808bb882fc840e82562","schema_fingerprint":"4aa3821a28b0b7c2400bc59aba4bcc0a76e971dadd19610d3ad38c768e124dc7","schema_version":"edge-lab-recorder.raw.v1","sequence":null,"source":"clob_market_ws"}
{"event_at":"2026-07-28T04:11:09.537000Z","event_fingerprint":"374b5db48cdc97c33286f60e71e8a2b65f4cb7033084967c97e5f58cb481436f","payload":{"connection_id":"f6725804f86a4c4eb588e4d5ed7db029","event_at":"2026-07-28T04:11:09.537000Z","event_type":"price_change","frame_hash":"2dc2f2d761995dbaf1ca2e4ec71c6160fc013e06cb30fcffec3b63c1404be2bf","frame_index":0,"kind":"data","monotonic_ns":313854834152250,"payload":{"event_type":"price_change","market":"0xd412ce774cfcf8dc9f71164aac78783978aac7b03871702a3b8a481bd9dc9688","price_changes":[{"asset_id":"107603864457683460275633293642179940881969192120168665300712204232021063124301","best_ask":"0.62","best_bid":"0.61","hash":"0ceaf3d5282ec60b12d476d5aef737c202f273c8","price":"0.02","side":"BUY","size":"688.1"},{"asset_id":"96600821790790307414914106093858868634329285205417149685270682748367152458577","best_ask":"0.39","best_bid":"0.38","hash":"2796b6110a46a490d316278c47433405250180c9","price":"0.98","side":"SELL","size":"688.1"}],"timestamp":"1785211869537"},"payload_hash":"53335dd4e5436c4263bbf9553652ebd98fe0b2b43f18f53e9edf89a499c13e1a","raw_frame":"{\"market\":\"0xd412ce774cfcf8dc9f71164aac78783978aac7b03871702a3b8a481bd9dc9688\", \"price_changes\":[{\"asset_id\":\"107603864457683460275633293642179940881969192120168665300712204232021063124301\", \"price\":\"0.02\", \"size\":\"688.1\", \"side\":\"BUY\", \"hash\":\"0ceaf3d5282ec60b12d476d5aef737c202f273c8\", \"best_bid\":\"0.61\", \"best_ask\":\"0.62\"}, {\"asset_id\":\"96600821790790307414914106093858868634329285205417149685270682748367152458577\", \"price\":\"0.98\", \"size\":\"688.1\", \"side\":\"SELL\", \"hash\":\"2796b6110a46a490d316278c47433405250180c9\", \"best_bid\":\"0.38\", \"best_ask\":\"0.39\"}], \"timestamp\":\"1785211869537\", \"event_type\":\"price_change\"}","received_at":"2026-07-28T04:11:11.757546Z","schema_version":"clob-market-ws.price_change.v1","sequence":null,"server_hash":null,"server_timestamp":"1785211869537","session_id":"2d607381e3054cee91998cdf45a4231c","source":"clob_market_ws"},"received_at":"2026-07-28T04:11:11.757546Z","record_id":"904c35defd26b8d44f10812602bc1a59877d12229fff0bb026c583626498c1b6","schema_fingerprint":"4aa3821a28b0b7c2400bc59aba4bcc0a76e971dadd19610d3ad38c768e124dc7","schema_version":"edge-lab-recorder.raw.v1","sequence":null,"source":"clob_market_ws"}
{"event_at":"2026-07-28T04:11:09.548000Z","event_fingerprint":"c6a20115d124ada5ef919645e1efc3f8dd763e43ba3529e42a0ab239d13c0f75","payload":{"connection_id":"f6725804f86a4c4eb588e4d5ed7db029","event_at":"2026-07-28T04:11:09.548000Z","event_type":"price_change","frame_hash":"b55e2e48d5994055111b698e29ef2a5dc536b8e4ba4f33c064b3e86aea09be4e","frame_index":0,"kind":"data","monotonic_ns":313854838369625,"payload":{"event_type":"price_change","market":"0xd412ce774cfcf8dc9f71164aac78783978aac7b03871702a3b8a481bd9dc9688","price_changes":[{"asset_id":"96600821790790307414914106093858868634329285205417149685270682748367152458577","best_ask":"0.39","best_bid":"0.38","hash":"1330e39dc44c3bb0ef306fb4c25f489911295c6c","price":"0.39","side":"SELL","size":"13"},{"asset_id":"107603864457683460275633293642179940881969192120168665300712204232021063124301","best_ask":"0.62","best_bid":"0.61","hash":"0ab4f5b7b7a6550d01e14f622a48f97f326234ee","price":"0.61","side":"BUY","size":"13"}],"timestamp":"1785211869548"},"payload_hash":"de625d568d67ce809f61ffb91706a8335fbaacd88a35d8391d097bcd1a91c417","raw_frame":"{\"market\":\"0xd412ce774cfcf8dc9f71164aac78783978aac7b03871702a3b8a481bd9dc9688\", \"price_changes\":[{\"asset_id\":\"96600821790790307414914106093858868634329285205417149685270682748367152458577\", \"price\":\"0.39\", \"size\":\"13\", \"side\":\"SELL\", \"hash\":\"1330e39dc44c3bb0ef306fb4c25f489911295c6c\", \"best_bid\":\"0.38\", \"best_ask\":\"0.39\"}, {\"asset_id\":\"107603864457683460275633293642179940881969192120168665300712204232021063124301\", \"price\":\"0.61\", \"size\":\"13\", \"side\":\"BUY\", \"hash\":\"0ab4f5b7b7a6550d01e14f622a48f97f326234ee\", \"best_bid\":\"0.61\", \"best_ask\":\"0.62\"}], \"timestamp\":\"1785211869548\", \"event_type\":\"price_change\"}","received_at":"2026-07-28T04:11:11.761763Z","schema_version":"clob-market-ws.price_change.v1","sequence":null,"server_hash":null,"server_timestamp":"1785211869548","session_id":"2d607381e3054cee91998cdf45a4231c","source":"clob_market_ws"},"received_at":"2026-07-28T04:11:11.761763Z","record_id":"f97f38fc8e88193d71fecba4ba01c531c699eccc4e642f5fce2987172e199bd2","schema_fingerprint":"4aa3821a28b0b7c2400bc59aba4bcc0a76e971dadd19610d3ad38c768e124dc7","schema_version":"edge-lab-recorder.raw.v1","sequence":null,"source":"clob_market_ws"}
{"event_at":"2026-07-28T04:11:09.550000Z","event_fingerprint":"41a4fb48df549005753aa5142bf938e333602b6896d71ed58065cf340b08f8c3","payload":{"connection_id":"f6725804f86a4c4eb588e4d5ed7db029","event_at":"2026-07-28T04:11:09.550000Z","event_type":"price_change","frame_hash":"b56894b50d9148f5f58cd47b63f10f95f2e25b15f2c7d3dcb12202254099e5be","frame_index":0,"kind":"data","monotonic_ns":313854842574083,"payload":{"event_type":"price_change","market":"0xd412ce774cfcf8dc9f71164aac78783978aac7b03871702a3b8a481bd9dc9688","price_changes":[{"asset_id":"96600821790790307414914106093858868634329285205417149685270682748367152458577","best_ask":"0.39","best_bid":"0.38","hash":"69923577593fd589ac8ef22b23e39ac55cf5da8c","price":"0.34","side":"BUY","size":"50.2"},{"asset_id":"107603864457683460275633293642179940881969192120168665300712204232021063124301","best_ask":"0.62","best_bid":"0.61","hash":"dd5277c1a3984a02a2d917e28c2ae2eb3af0da8a","price":"0.66","side":"SELL","size":"50.2"}],"timestamp":"1785211869550"},"payload_hash":"cefca389d687b404972a6954de6d72f4002fcf4cff35c47aa068edc9cc88fbd4","raw_frame":"{\"market\":\"0xd412ce774cfcf8dc9f71164aac78783978aac7b03871702a3b8a481bd9dc9688\", \"price_changes\":[{\"asset_id\":\"96600821790790307414914106093858868634329285205417149685270682748367152458577\", \"price\":\"0.34\", \"size\":\"50.2\", \"side\":\"BUY\", \"hash\":\"69923577593fd589ac8ef22b23e39ac55cf5da8c\", \"best_bid\":\"0.38\", \"best_ask\":\"0.39\"}, {\"asset_id\":\"107603864457683460275633293642179940881969192120168665300712204232021063124301\", \"price\":\"0.66\", \"size\":\"50.2\", \"side\":\"SELL\", \"hash\":\"dd5277c1a3984a02a2d917e28c2ae2eb3af0da8a\", \"best_bid\":\"0.61\", \"best_ask\":\"0.62\"}], \"timestamp\":\"1785211869550\", \"event_type\":\"price_change\"}","received_at":"2026-07-28T04:11:11.765968Z","schema_version":"clob-market-ws.price_change.v1","sequence":null,"server_hash":null,"server_timestamp":"1785211869550","session_id":"2d607381e3054cee91998cdf45a4231c","source":"clob_market_ws"},"received_at":"2026-07-28T04:11:11.765968Z","record_id":"794c3f42d74610137f14f0418c7c473ca5132c73305be6fed2ac40dff3acfc14","schema_fingerprint":"4aa3821a28b0b7c2400bc59aba4bcc0a76e971dadd19610d3ad38c768e124dc7","schema_version":"edge-lab-recorder.raw.v1","sequence":null,"source":"clob_market_ws"}
{"event_at":"2026-07-28T04:11:09.589000Z","event_fingerprint":"f65112fe555c7c37415caf05ee46e947ff734633c9d661595748fcb119f22c8f","payload":{"connection_id":"f6725804f86a4c4eb588e4d5ed7db029","event_at":"2026-07-28T04:11:09.589000Z","event_type":"price_change","frame_hash":"5714fc0222ec564130ed1532c804688746854345e14eb819472a8a7748d3ba09","frame_index":0,"kind":"data","monotonic_ns":313854847602291,"payload":{"event_type":"price_change","market":"0xd412ce774cfcf8dc9f71164aac78783978aac7b03871702a3b8a481bd9dc9688","price_changes":[{"asset_id":"107603864457683460275633293642179940881969192120168665300712204232021063124301","best_ask":"0.62","best_bid":"0.61","hash":"0d44e86e49df02b8454cc390641bf3bc4d531226","price":"0.6","side":"BUY","size":"18.6"},{"asset_id":"96600821790790307414914106093858868634329285205417149685270682748367152458577","best_ask":"0.39","best_bid":"0.38","hash":"36774d9e69e4f5763cdd5ee6b4fb672bd22f7586","price":"0.4","side":"SELL","size":"18.6"}],"timestamp":"1785211869589"},"payload_hash":"5af1bef08eb38311c22df7694a6cdbc02dcc75d4eea328ac473acbaa7baff5c4","raw_frame":"{\"market\":\"0xd412ce774cfcf8dc9f71164aac78783978aac7b03871702a3b8a481bd9dc9688\", \"price_changes\":[{\"asset_id\":\"107603864457683460275633293642179940881969192120168665300712204232021063124301\", \"price\":\"0.6\", \"size\":\"18.6\", \"side\":\"BUY\", \"hash\":\"0d44e86e49df02b8454cc390641bf3bc4d531226\", \"best_bid\":\"0.61\", \"best_ask\":\"0.62\"}, {\"asset_id\":\"96600821790790307414914106093858868634329285205417149685270682748367152458577\", \"price\":\"0.4\", \"size\":\"18.6\", \"side\":\"SELL\", \"hash\":\"36774d9e69e4f5763cdd5ee6b4fb672bd22f7586\", \"best_bid\":\"0.38\", \"best_ask\":\"0.39\"}], \"timestamp\":\"1785211869589\", \"event_type\":\"price_change\"}","received_at":"2026-07-28T04:11:11.770996Z","schema_version":"clob-market-ws.price_change.v1","sequence":null,"server_hash":null,"server_timestamp":"1785211869589","session_id":"2d607381e3054cee91998cdf45a4231c","source":"clob_market_ws"},"received_at":"2026-07-28T04:11:11.770996Z","record_id":"fa1cc4bb928bef64ea0cb69685dcbb790b972eab4014e1296ed00e909e858550","schema_fingerprint":"4aa3821a28b0b7c2400bc59aba4bcc0a76e971dadd19610d3ad38c768e124dc7","schema_version":"edge-lab-recorder.raw.v1","sequence":null,"source":"clob_market_ws"}
{"event_at":"2026-07-28T04:11:09.599000Z","event_fingerprint":"d615f777dc8a5dafb8e4a8c16e877310b58fd850f894aa732496e1640da0221a","payload":{"connection_id":"f6725804f86a4c4eb588e4d5ed7db029","event_at":"2026-07-28T04:11:09.599000Z","event_type":"price_change","frame_hash":"7ee44269f22e9a511c0a941e212dfec2357714689272ac72bbf33da23fd61090","frame_index":0,"kind":"data","monotonic_ns":313854850411500,"payload":{"event_type":"price_change","market":"0xd412ce774cfcf8dc9f71164aac78783978aac7b03871702a3b8a481bd9dc9688","price_changes":[{"asset_id":"96600821790790307414914106093858868634329285205417149685270682748367152458577","best_ask":"0.39","best_bid":"0.38","hash":"4e13d97c85764cc3f4811b635885e9af10396b92","price":"0.31","side":"BUY","size":"95"},{"asset_id":"107603864457683460275633293642179940881969192120168665300712204232021063124301","best_ask":"0.62","best_bid":"0.61","hash":"689e12fb37cc3b3060aff4b9dbfc3e15cf58d1d8","price":"0.69","side":"SELL","size":"95"}],"timestamp":"1785211869599"},"payload_hash":"09ab92413c20a958f29b6eaa0d1bee5dcb54902992dd3fac889d8f2292b5b059","raw_frame":"{\"market\":\"0xd412ce774cfcf8dc9f71164aac78783978aac7b03871702a3b8a481bd9dc9688\", \"price_changes\":[{\"asset_id\":\"96600821790790307414914106093858868634329285205417149685270682748367152458577\", \"price\":\"0.31\", \"size\":\"95\", \"side\":\"BUY\", \"hash\":\"4e13d97c85764cc3f4811b635885e9af10396b92\", \"best_bid\":\"0.38\", \"best_ask\":\"0.39\"}, {\"asset_id\":\"107603864457683460275633293642179940881969192120168665300712204232021063124301\", \"price\":\"0.69\", \"size\":\"95\", \"side\":\"SELL\", \"hash\":\"689e12fb37cc3b3060aff4b9dbfc3e15cf58d1d8\", \"best_bid\":\"0.61\", \"best_ask\":\"0.62\"}], \"timestamp\":\"1785211869599\", \"event_type\":\"price_change\"}","received_at":"2026-07-28T04:11:11.773805Z","schema_version":"clob-market-ws.price_change.v1","sequence":null,"server_hash":null,"server_timestamp":"1785211869599","session_id":"2d607381e3054cee91998cdf45a4231c","source":"clob_market_ws"},"received_at":"2026-07-28T04:11:11.773805Z","record_id":"209020603bc6b6603150d252df0b89af5cbc6ecf657aa6caf84b5cb2422b0707","schema_fingerprint":"4aa3821a28b0b7c2400bc59aba4bcc0a76e971dadd19610d3ad38c768e124dc7","schema_version":"edge-lab-recorder.raw.v1","sequence":null,"source":"clob_market_ws"}
{"event_at":"2026-07-28T04:11:09.601000Z","event_fingerprint":"def70e10f279dae3a6fe25b1be8db76ec1aed2f90354b9aaa4254e3e3ef6d859","payload":{"connection_id":"f6725804f86a4c4eb588e4d5ed7db029","event_at":"2026-07-28T04:11:09.601000Z","event_type":"price_change","frame_hash":"0ff880dd92991b0716af56233682a71d9f4a762a00f342ae6b819ffc44dda478","frame_index":0,"kind":"data","monotonic_ns":313854854750416,"payload":{"event_type":"price_change","market":"0xd412ce774cfcf8dc9f71164aac78783978aac7b03871702a3b8a481bd9dc9688","price_changes":[{"asset_id":"107603864457683460275633293642179940881969192120168665300712204232021063124301","best_ask":"0.62","best_bid":"0.61","hash":"67a05b175ecb41bc727aa0dc413695fb274c672a","price":"0.02","side":"BUY","size":"683.1"},{"asset_id":"96600821790790307414914106093858868634329285205417149685270682748367152458577","best_ask":"0.39","best_bid":"0.38","hash":"389dcc88c75b4bc440ac4cc5220def97706ad7bc","price":"0.98","side":"SELL","size":"683.1"}],"timestamp":"1785211869601"},"payload_hash":"e1613cc7fcbdcbb44c7054995a1c0721f7b5603aca487d8d5c48bd1db0f4502f","raw_frame":"{\"market\":\"0xd412ce774cfcf8dc9f71164aac78783978aac7b03871702a3b8a481bd9dc9688\", \"price_changes\":[{\"asset_id\":\"107603864457683460275633293642179940881969192120168665300712204232021063124301\", \"price\":\"0.02\", \"size\":\"683.1\", \"side\":\"BUY\", \"hash\":\"67a05b175ecb41bc727aa0dc413695fb274c672a\", \"best_bid\":\"0.61\", \"best_ask\":\"0.62\"}, {\"asset_id\":\"96600821790790307414914106093858868634329285205417149685270682748367152458577\", \"price\":\"0.98\", \"size\":\"683.1\", \"side\":\"SELL\", \"hash\":\"389dcc88c75b4bc440ac4cc5220def97706ad7bc\", \"best_bid\":\"0.38\", \"best_ask\":\"0.39\"}], \"timestamp\":\"1785211869601\", \"event_type\":\"price_change\"}","received_at":"2026-07-28T04:11:11.778145Z","schema_version":"clob-market-ws.price_change.v1","sequence":null,"server_hash":null,"server_timestamp":"1785211869601","session_id":"2d607381e3054cee91998cdf45a4231c","source":"clob_market_ws"},"received_at":"2026-07-28T04:11:11.778145Z","record_id":"7592111e3163f8a97cb4d5ced8eea64558cda3041f0df287ea187e5cb0273fcd","schema_fingerprint":"4aa3821a28b0b7c2400bc59aba4bcc0a76e971dadd19610d3ad38c768e124dc7","schema_version":"edge-lab-recorder.raw.v1","sequence":null,"source":"clob_market_ws"}
{"event_at":"2026-07-28T04:11:09.695000Z","event_fingerprint":"1f6edeaf07366e33353e081e33ff8ddb52103a8e8455e8ad486095e65e5962b8","payload":{"connection_id":"f6725804f86a4c4eb588e4d5ed7db029","event_at":"2026-07-28T04:11:09.695000Z","event_type":"price_change","frame_hash":"3379cf8f8873848eee6346b13d89ebdf1902cf2abd98c5448d8c876195fd8331","frame_index":0,"kind":"data","monotonic_ns":313854858955458,"payload":{"event_type":"price_change","market":"0xd412ce774cfcf8dc9f71164aac78783978aac7b03871702a3b8a481bd9dc9688","price_changes":[{"asset_id":"107603864457683460275633293642179940881969192120168665300712204232021063124301","best_ask":"0.62","best_bid":"0.61","hash":"d62cbf66dae3920fb5da49bd8a881b765ecdf5cc","price":"0.02","side":"BUY","size":"688.1"},{"asset_id":"96600821790790307414914106093858868634329285205417149685270682748367152458577","best_ask":"0.39","best_bid":"0.38","hash":"edfd99f8a40edf6e22ddeeea88396fe0fafbbb97","price":"0.98","side":"SELL","size":"688.1"}],"timestamp":"1785211869695"},"payload_hash":"82e35f232133b0c39ad59edce91e2cadb20b703f9ea1059b52d761321c302bcf","raw_frame":"{\"market\":\"0xd412ce774cfcf8dc9f71164aac78783978aac7b03871702a3b8a481bd9dc9688\", \"price_changes\":[{\"asset_id\":\"107603864457683460275633293642179940881969192120168665300712204232021063124301\", \"price\":\"0.02\", \"size\":\"688.1\", \"side\":\"BUY\", \"hash\":\"d62cbf66dae3920fb5da49bd8a881b765ecdf5cc\", \"best_bid\":\"0.61\", \"best_ask\":\"0.62\"}, {\"asset_id\":\"96600821790790307414914106093858868634329285205417149685270682748367152458577\", \"price\":\"0.98\", \"size\":\"688.1\", \"side\":\"SELL\", \"hash\":\"edfd99f8a40edf6e22ddeeea88396fe0fafbbb97\", \"best_bid\":\"0.38\", \"best_ask\":\"0.39\"}], \"timestamp\":\"1785211869695\", \"event_type\":\"price_change\"}","received_at":"2026-07-28T04:11:11.782348Z","schema_version":"clob-market-ws.price_change.v1","sequence":null,"server_hash":null,"server_timestamp":"1785211869695","session_id":"2d607381e3054cee91998cdf45a4231c","source":"clob_market_ws"},"received_at":"2026-07-28T04:11:11.782348Z","record_id":"56612fc54330b92d37dcab09ca154329a69f7a32c481ed9802a316861f89bc8c","schema_fingerprint":"4aa3821a28b0b7c2400bc59aba4bcc0a76e971dadd19610d3ad38c768e124dc7","schema_version":"edge-lab-recorder.raw.v1","sequence":null,"source":"clob_market_ws"}
{"event_at":"2026-07-28T04:11:09.717000Z","event_fingerprint":"28f2e2f38a730d3ed19a6ee6b70b4f634acf40257dd2915330ae137f312ec7e1","payload":{"connection_id":"f6725804f86a4c4eb588e4d5ed7db029","event_at":"2026-07-28T04:11:09.717000Z","event_type":"price_change","frame_hash":"2d62b716dc0c80a120d314a289c2896c33b13a290b68895cda78114a09b6ff4f","frame_index":0,"kind":"data","monotonic_ns":313854863291875,"payload":{"event_type":"price_change","market":"0xd412ce774cfcf8dc9f71164aac78783978aac7b03871702a3b8a481bd9dc9688","price_changes":[{"asset_id":"107603864457683460275633293642179940881969192120168665300712204232021063124301","best_ask":"0.62","best_bid":"0.61","hash":"fe6948c898d0873454e309d003e4389ee839316d","price":"0.01","side":"BUY","size":"5638.02"},{"asset_id":"96600821790790307414914106093858868634329285205417149685270682748367152458577","best_ask":"0.39","best_bid":"0.38","hash":"ed387fbc6b71d79ad5721551ce39e5e95d2181e1","price":"0.99","side":"SELL","size":"5638.02"}],"timestamp":"1785211869717"},"payload_hash":"45f8741ed2fc38a5fe033ba17caec8c8d3b0c53f9e556cf8d4730cfbfad55ca4","raw_frame":"{\"market\":\"0xd412ce774cfcf8dc9f71164aac78783978aac7b03871702a3b8a481bd9dc9688\", \"price_changes\":[{\"asset_id\":\"107603864457683460275633293642179940881969192120168665300712204232021063124301\", \"price\":\"0.01\", \"size\":\"5638.02\", \"side\":\"BUY\", \"hash\":\"fe6948c898d0873454e309d003e4389ee839316d\", \"best_bid\":\"0.61\", \"best_ask\":\"0.62\"}, {\"asset_id\":\"96600821790790307414914106093858868634329285205417149685270682748367152458577\", \"price\":\"0.99\", \"size\":\"5638.02\", \"side\":\"SELL\", \"hash\":\"ed387fbc6b71d79ad5721551ce39e5e95d2181e1\", \"best_bid\":\"0.38\", \"best_ask\":\"0.39\"}], \"timestamp\":\"1785211869717\", \"event_type\":\"price_change\"}","received_at":"2026-07-28T04:11:11.786680Z","schema_version":"clob-market-ws.price_change.v1","sequence":null,"server_hash":null,"server_timestamp":"1785211869717","session_id":"2d607381e3054cee91998cdf45a4231c","source":"clob_market_ws"},"received_at":"2026-07-28T04:11:11.786680Z","record_id":"cf232e1c8b9028c1ce9a690ad44f5230eccbf146222e910dc27bb02bf57e0cf7","schema_fingerprint":"4aa3821a28b0b7c2400bc59aba4bcc0a76e971dadd19610d3ad38c768e124dc7","schema_version":"edge-lab-recorder.raw.v1","sequence":null,"source":"clob_market_ws"}
{"event_at":"2026-07-28T04:11:09.724000Z","event_fingerprint":"9fc5a2c259890df0d383a679fa1fc404ebc8299beb9df34960c69d0a0de84d7d","payload":{"connection_id":"f6725804f86a4c4eb588e4d5ed7db029","event_at":"2026-07-28T04:11:09.724000Z","event_type":"price_change","frame_hash":"79f28255b07ce1779420f9a551b94327cfc9aeb035c6685572b5491907f489db","frame_index":0,"kind":"data","monotonic_ns":313854867006416,"payload":{"event_type":"price_change","market":"0xd412ce774cfcf8dc9f71164aac78783978aac7b03871702a3b8a481bd9dc9688","price_changes":[{"asset_id":"96600821790790307414914106093858868634329285205417149685270682748367152458577","best_ask":"0.39","best_bid":"0.38","hash":"03ad9882d58103b6476e3fea7bcaf04ebda3e28d","price":"0.25","side":"BUY","size":"293.49"},{"asset_id":"107603864457683460275633293642179940881969192120168665300712204232021063124301","best_ask":"0.62","best_bid":"0.61","hash":"080763e6bad71ef6da5dba07741dbf3df01efcec","price":"0.75","side":"SELL","size":"293.49"}],"timestamp":"1785211869724"},"payload_hash":"d4e47bfe79db4edc327d1ef4b4a0c947ecbcc0a9f8f4c893b51afbea191d9987","raw_frame":"{\"market\":\"0xd412ce774cfcf8dc9f71164aac78783978aac7b03871702a3b8a481bd9dc9688\", \"price_changes\":[{\"asset_id\":\"96600821790790307414914106093858868634329285205417149685270682748367152458577\", \"price\":\"0.25\", \"size\":\"293.49\", \"side\":\"BUY\", \"hash\":\"03ad9882d58103b6476e3fea7bcaf04ebda3e28d\", \"best_bid\":\"0.38\", \"best_ask\":\"0.39\"}, {\"asset_id\":\"107603864457683460275633293642179940881969192120168665300712204232021063124301\", \"price\":\"0.75\", \"size\":\"293.49\", \"side\":\"SELL\", \"hash\":\"080763e6bad71ef6da5dba07741dbf3df01efcec\", \"best_bid\":\"0.61\", \"best_ask\":\"0.62\"}], \"timestamp\":\"1785211869724\", \"event_type\":\"price_change\"}","received_at":"2026-07-28T04:11:11.790400Z","schema_version":"clob-market-ws.price_change.v1","sequence":null,"server_hash":null,"server_timestamp":"1785211869724","session_id":"2d607381e3054cee91998cdf45a4231c","source":"clob_market_ws"},"received_at":"2026-07-28T04:11:11.790400Z","record_id":"a256a7c1e42e0e3fa075e13d4ebe44ce1aaf4dad60e51d95548d7a400bf61a1e","schema_fingerprint":"4aa3821a28b0b7c2400bc59aba4bcc0a76e971dadd19610d3ad38c768e124dc7","schema_version":"edge-lab-recorder.raw.v1","sequence":null,"source":"clob_market_ws"}
{"event_at":"2026-07-28T04:11:09.742000Z","event_fingerprint":"121c30db3454df150c17f34a0f0102bf8d7677b592a603d346075bdbff44a0c7","payload":{"connection_id":"f6725804f86a4c4eb588e4d5ed7db029","event_at":"2026-07-28T04:11:09.742000Z","event_type":"price_change","frame_hash":"70bf6c70a59ef404d40f21a24118f51256dbd5fbc7d33acff353080175273ae4","frame_index":0,"kind":"data","monotonic_ns":313854871141125,"payload":{"event_type":"price_change","market":"0xd412ce774cfcf8dc9f71164aac78783978aac7b03871702a3b8a481bd9dc9688","price_changes":[{"asset_id":"107603864457683460275633293642179940881969192120168665300712204232021063124301","best_ask":"0.62","best_bid":"0.61","hash":"71f33caadce2e4177ace78dbe4a838ac180cba8f","price":"0.01","side":"BUY","size":"5633.02"},{"asset_id":"96600821790790307414914106093858868634329285205417149685270682748367152458577","best_ask":"0.39","best_bid":"0.38","hash":"2b0be4553d17348ffac763bb4257bb1c246039a8","price":"0.99","side":"SELL","size":"5633.02"}],"timestamp":"1785211869742"},"payload_hash":"3f62a8ba533be849d825f23c4846e2f0571adc918d2abe40f8467754ac975749","raw_frame":"{\"market\":\"0xd412ce774cfcf8dc9f71164aac78783978aac7b03871702a3b8a481bd9dc9688\", \"price_changes\":[{\"asset_id\":\"107603864457683460275633293642179940881969192120168665300712204232021063124301\", \"price\":\"0.01\", \"size\":\"5633.02\", \"side\":\"BUY\", \"hash\":\"71f33caadce2e4177ace78dbe4a838ac180cba8f\", \"best_bid\":\"0.61\", \"best_ask\":\"0.62\"}, {\"asset_id\":\"96600821790790307414914106093858868634329285205417149685270682748367152458577\", \"price\":\"0.99\", \"size\":\"5633.02\", \"side\":\"SELL\", \"hash\":\"2b0be4553d17348ffac763bb4257bb1c246039a8\", \"best_bid\":\"0.38\", \"best_ask\":\"0.39\"}], \"timestamp\":\"1785211869742\", \"event_type\":\"price_change\"}","received_at":"2026-07-28T04:11:11.794534Z","schema_version":"clob-market-ws.price_change.v1","sequence":null,"server_hash":null,"server_timestamp":"1785211869742","session_id":"2d607381e3054cee91998cdf45a4231c","source":"clob_market_ws"},"received_at":"2026-07-28T04:11:11.794534Z","record_id":"2132b3898288718d30b65d7a656ffca1bad56a132e4135d4cecd05764784ce08","schema_fingerprint":"4aa3821a28b0b7c2400bc59aba4bcc0a76e971dadd19610d3ad38c768e124dc7","schema_version":"edge-lab-recorder.raw.v1","sequence":null,"source":"clob_market_ws"}
{"event_at":"2026-07-28T04:11:09.749000Z","event_fingerprint":"74b3d7279ff5c3e57c4a74d84b41c467b14bdcc45b934b86afa691709ba4186f","payload":{"connection_id":"f6725804f86a4c4eb588e4d5ed7db029","event_at":"2026-07-28T04:11:09.749000Z","event_type":"price_change","frame_hash":"9bc6d7dfb35e73d8abdae0233673089784f905d337a7296ec58e2e1e39c3fe6a","frame_index":0,"kind":"data","monotonic_ns":313854876331541,"payload":{"event_type":"price_change","market":"0xd412ce774cfcf8dc9f71164aac78783978aac7b03871702a3b8a481bd9dc9688","price_changes":[{"asset_id":"107603864457683460275633293642179940881969192120168665300712204232021063124301","best_ask":"0.62","best_bid":"0.61","hash":"8829fc1ee5182c7c9b051085b70c890595c36b7f","price":"0.02","side":"BUY","size":"683.1"},{"asset_id":"96600821790790307414914106093858868634329285205417149685270682748367152458577","best_ask":"0.39","best_bid":"0.38","hash":"d9699c2a09191da35b0ba23b5cb546656f864236","price":"0.98","side":"SELL","size":"683.1"}],"timestamp":"1785211869749"},"payload_hash":"973c137536d0171f57581315858d1a4c8652d04f736418223e0c2d29af53aa3b","raw_frame":"{\"market\":\"0xd412ce774cfcf8dc9f71164aac78783978aac7b03871702a3b8a481bd9dc9688\", \"price_changes\":[{\"asset_id\":\"107603864457683460275633293642179940881969192120168665300712204232021063124301\", \"price\":\"0.02\", \"size\":\"683.1\", \"side\":\"BUY\", \"hash\":\"8829fc1ee5182c7c9b051085b70c890595c36b7f\", \"best_bid\":\"0.61\", \"best_ask\":\"0.62\"}, {\"asset_id\":\"96600821790790307414914106093858868634329285205417149685270682748367152458577\", \"price\":\"0.98\", \"size\":\"683.1\", \"side\":\"SELL\", \"hash\":\"d9699c2a09191da35b0ba23b5cb546656f864236\", \"best_bid\":\"0.38\", \"best_ask\":\"0.39\"}], \"timestamp\":\"1785211869749\", \"event_type\":\"price_change\"}","received_at":"2026-07-28T04:11:11.799724Z","schema_version":"clob-market-ws.price_change.v1","sequence":null,"server_hash":null,"server_timestamp":"1785211869749","session_id":"2d607381e3054cee91998cdf45a4231c","source":"clob_market_ws"},"received_at":"2026-07-28T04:11:11.799724Z","record_id":"47ac9147e6bb4eb94e2bb6eaec727eb2dc76732e5bd26d6dbba9bdec9ca00096","schema_fingerprint":"4aa3821a28b0b7c2400bc59aba4bcc0a76e971dadd19610d3ad38c768e124dc7","schema_version":"edge-lab-recorder.raw.v1","sequence":null,"source":"clob_market_ws"}
{"event_at":"2026-07-28T04:11:09.751000Z","event_fingerprint":"e4b7077797fe663adcb4ebd0ba84d1c24005e19acac575d4743520edab5a5348","payload":{"connection_id":"f6725804f86a4c4eb588e4d5ed7db029","event_at":"2026-07-28T04:11:09.751000Z","event_type":"price_change","frame_hash":"85112a95523c6b97baacf1095f1135a84879e0d225db4f531f22900b86442093","frame_index":0,"kind":"data","monotonic_ns":313854881067083,"payload":{"event_type":"price_change","market":"0xd412ce774cfcf8dc9f71164aac78783978aac7b03871702a3b8a481bd9dc9688","price_changes":[{"asset_id":"96600821790790307414914106093858868634329285205417149685270682748367152458577","best_ask":"0.39","best_bid":"0.38","hash":"86bf35e55c9226a657dee08cd991c95c66c91ac9","price":"0.25","side":"BUY","size":"278.49"},{"asset_id":"107603864457683460275633293642179940881969192120168665300712204232021063124301","best_ask":"0.62","best_bid":"0.61","hash":"c23ab139017184dac1679f1f3adb7e7bd7d69168","price":"0.75","side":"SELL","size":"278.49"}],"timestamp":"1785211869751"},"payload_hash":"d6054cc4a459dd04047970935ce26c594e09c4c3a4e22a939d51f8b18a619a00","raw_frame":"{\"market\":\"0xd412ce774cfcf8dc9f71164aac78783978aac7b03871702a3b8a481bd9dc9688\", \"price_changes\":[{\"asset_id\":\"96600821790790307414914106093858868634329285205417149685270682748367152458577\", \"price\":\"0.25\", \"size\":\"278.49\", \"side\":\"BUY\", \"hash\":\"86bf35e55c9226a657dee08cd991c95c66c91ac9\", \"best_bid\":\"0.38\", \"best_ask\":\"0.39\"}, {\"asset_id\":\"107603864457683460275633293642179940881969192120168665300712204232021063124301\", \"price\":\"0.75\", \"size\":\"278.49\", \"side\":\"SELL\", \"hash\":\"c23ab139017184dac1679f1f3adb7e7bd7d69168\", \"best_bid\":\"0.61\", \"best_ask\":\"0.62\"}], \"timestamp\":\"1785211869751\", \"event_type\":\"price_change\"}","received_at":"2026-07-28T04:11:11.804461Z","schema_version":"clob-market-ws.price_change.v1","sequence":null,"server_hash":null,"server_timestamp":"1785211869751","session_id":"2d607381e3054cee91998cdf45a4231c","source":"clob_market_ws"},"received_at":"2026-07-28T04:11:11.804461Z","record_id":"7578bd2f653e7d4fcc0bbb4fed03dbc7eebf4246583c66648ce50469b9959ef4","schema_fingerprint":"4aa3821a28b0b7c2400bc59aba4bcc0a76e971dadd19610d3ad38c768e124dc7","schema_version":"edge-lab-recorder.raw.v1","sequence":null,"source":"clob_market_ws"}
{"event_at":"2026-07-28T04:11:09.781000Z","event_fingerprint":"e885a8439b6bf6c9dcf2a0dae813da4b2e389ad7a2192cf7b21e20b40eb4f0c7","payload":{"connection_id":"f6725804f86a4c4eb588e4d5ed7db029","event_at":"2026-07-28T04:11:09.781000Z","event_type":"price_change","frame_hash":"fa4fdb7e28a54b02954e72c79f9692c7c139ec8fa15e5489b83ff59fb043ee0e","frame_index":0,"kind":"data","monotonic_ns":313854885233250,"payload":{"event_type":"price_change","market":"0xd412ce774cfcf8dc9f71164aac78783978aac7b03871702a3b8a481bd9dc9688","price_changes":[{"asset_id":"96600821790790307414914106093858868634329285205417149685270682748367152458577","best_ask":"0.39","best_bid":"0.38","hash":"7ab4ff19ae304f20f07ed0e1cc4dae0fa1fdc58a","price":"0.35","side":"BUY","size":"59.2"},{"asset_id":"107603864457683460275633293642179940881969192120168665300712204232021063124301","best_ask":"0.62","best_bid":"0.61","hash":"3a823881e4b177d9094ee5062479e40b04427b5d","price":"0.65","side":"SELL","size":"59.2"}],"timestamp":"1785211869781"},"payload_hash":"8b0873ab61451619f6b29fe4c246d16d80129dc196a75054175ffdafcd7d6d4b","raw_frame":"{\"market\":\"0xd412ce774cfcf8dc9f71164aac78783978aac7b03871702a3b8a481bd9dc9688\", \"price_changes\":[{\"asset_id\":\"96600821790790307414914106093858868634329285205417149685270682748367152458577\", \"price\":\"0.35\", \"size\":\"59.2\", \"side\":\"BUY\", \"hash\":\"7ab4ff19ae304f20f07ed0e1cc4dae0fa1fdc58a\", \"best_bid\":\"0.38\", \"best_ask\":\"0.39\"}, {\"asset_id\":\"107603864457683460275633293642179940881969192120168665300712204232021063124301\", \"price\":\"0.65\", \"size\":\"59.2\", \"side\":\"SELL\", \"hash\":\"3a823881e4b177d9094ee5062479e40b04427b5d\", \"best_bid\":\"0.61\", \"best_ask\":\"0.62\"}], \"timestamp\":\"1785211869781\", \"event_type\":\"price_change\"}","received_at":"2026-07-28T04:11:11.808626Z","schema_version":"clob-market-ws.price_change.v1","sequence":null,"server_hash":null,"server_timestamp":"1785211869781","session_id":"2d607381e3054cee91998cdf45a4231c","source":"clob_market_ws"},"received_at":"2026-07-28T04:11:11.808626Z","record_id":"68065ad87be8349aeaeffe2503a834e45f7dea55e5c16c63eb6c8bb437d1a474","schema_fingerprint":"4aa3821a28b0b7c2400bc59aba4bcc0a76e971dadd19610d3ad38c768e124dc7","schema_version":"edge-lab-recorder.raw.v1","sequence":null,"source":"clob_market_ws"}
{"event_at":"2026-07-28T04:11:09.801000Z","event_fingerprint":"53201a89b8407c3e0d2ee184dbe97ca07ce0bc98053a3ea8563857b26d827045","payload":{"connection_id":"f6725804f86a4c4eb588e4d5ed7db029","event_at":"2026-07-28T04:11:09.801000Z","event_type":"price_change","frame_hash":"56e68b9d320a0fdc5e6ed4db53b4dcb5c9ac6bb8f8f26aac757322c2fdb483ee","frame_index":0,"kind":"data","monotonic_ns":313854888788541,"payload":{"event_type":"price_change","market":"0xd412ce774cfcf8dc9f71164aac78783978aac7b03871702a3b8a481bd9dc9688","price_changes":[{"asset_id":"96600821790790307414914106093858868634329285205417149685270682748367152458577","best_ask":"0.39","best_bid":"0.38","hash":"8d10e66c30ffc2b72927bd9a0ace9188c34c7065","price":"0.26","side":"BUY","size":"238.86"},{"asset_id":"107603864457683460275633293642179940881969192120168665300712204232021063124301","best_ask":"0.62","best_bid":"0.61","hash":"0e21f3533a72012b1a700172decd5f5b01680644","price":"0.74","side":"SELL","size":"238.86"}],"timestamp":"1785211869801"},"payload_hash":"0560a55d27ee324d077c22bc9aa4ddaa24830b7e5ef7bb4d55c1de6132ecafcc","raw_frame":"{\"market\":\"0xd412ce774cfcf8dc9f71164aac78783978aac7b03871702a3b8a481bd9dc9688\", \"price_changes\":[{\"asset_id\":\"96600821790790307414914106093858868634329285205417149685270682748367152458577\", \"price\":\"0.26\", \"size\":\"238.86\", \"side\":\"BUY\", \"hash\":\"8d10e66c30ffc2b72927bd9a0ace9188c34c7065\", \"best_bid\":\"0.38\", \"best_ask\":\"0.39\"}, {\"asset_id\":\"107603864457683460275633293642179940881969192120168665300712204232021063124301\", \"price\":\"0.74\", \"size\":\"238.86\", \"side\":\"SELL\", \"hash\":\"0e21f3533a72012b1a700172decd5f5b01680644\", \"best_bid\":\"0.61\", \"best_ask\":\"0.62\"}], \"timestamp\":\"1785211869801\", \"event_type\":\"price_change\"}","received_at":"2026-07-28T04:11:11.812182Z","schema_version":"clob-market-ws.price_change.v1","sequence":null,"server_hash":null,"server_timestamp":"1785211869801","session_id":"2d607381e3054cee91998cdf45a4231c","source":"clob_market_ws"},"received_at":"2026-07-28T04:11:11.812182Z","record_id":"71b1f5b42aab21c5271b2742bbe43c173876c2f5b1907a11e1f3814934c91cfd","schema_fingerprint":"4aa3821a28b0b7c2400bc59aba4bcc0a76e971dadd19610d3ad38c768e124dc7","schema_version":"edge-lab-recorder.raw.v1","sequence":null,"source":"clob_market_ws"}
{"event_at":"2026-07-28T04:11:09.805000Z","event_fingerprint":"b4d790f8d2631ae9118cb8d4f7e776dfb0a9d955d3ec7a4671734d9b865fd4e3","payload":{"connection_id":"f6725804f86a4c4eb588e4d5ed7db029","event_at":"2026-07-28T04:11:09.805000Z","event_type":"price_change","frame_hash":"2e594ba5ee7551e15eae91c8d02b9973f4e00153785153cfae99ba341a32967b","frame_index":0,"kind":"data","monotonic_ns":313854892989666,"payload":{"event_type":"price_change","market":"0xd412ce774cfcf8dc9f71164aac78783978aac7b03871702a3b8a481bd9dc9688","price_changes":[{"asset_id":"96600821790790307414914106093858868634329285205417149685270682748367152458577","best_ask":"0.39","best_bid":"0.38","hash":"dd9626702bec0d517b41a1e00b73086d88112b0f","price":"0.44","side":"SELL","size":"108.97"},{"asset_id":"107603864457683460275633293642179940881969192120168665300712204232021063124301","best_ask":"0.62","best_bid":"0.61","hash":"cd42f113c8bf50ee2e3f7234e8311652c6a887a6","price":"0.56","side":"BUY","size":"108.97"}],"timestamp":"1785211869805"},"payload_hash":"5862260dd7d93e20f377783cc26acc1ac6bb084499228205022cbc84f71193cd","raw_frame":"{\"market\":\"0xd412ce774cfcf8dc9f71164aac78783978aac7b03871702a3b8a481bd9dc9688\", \"price_changes\":[{\"asset_id\":\"96600821790790307414914106093858868634329285205417149685270682748367152458577\", \"price\":\"0.44\", \"size\":\"108.97\", \"side\":\"SELL\", \"hash\":\"dd9626702bec0d517b41a1e00b73086d88112b0f\", \"best_bid\":\"0.38\", \"best_ask\":\"0.39\"}, {\"asset_id\":\"107603864457683460275633293642179940881969192120168665300712204232021063124301\", \"price\":\"0.56\", \"size\":\"108.97\", \"side\":\"BUY\", \"hash\":\"cd42f113c8bf50ee2e3f7234e8311652c6a887a6\", \"best_bid\":\"0.61\", \"best_ask\":\"0.62\"}], \"timestamp\":\"1785211869805\", \"event_type\":\"price_change\"}","received_at":"2026-07-28T04:11:11.816382Z","schema_version":"clob-market-ws.price_change.v1","sequence":null,"server_hash":null,"server_timestamp":"1785211869805","session_id":"2d607381e3054cee91998cdf45a4231c","source":"clob_market_ws"},"received_at":"2026-07-28T04:11:11.816382Z","record_id":"9d8c2f360719ebbf4240a9fe0005e4ce301f6fedabb55b48b77866f025bab8f5","schema_fingerprint":"4aa3821a28b0b7c2400bc59aba4bcc0a76e971dadd19610d3ad38c768e124dc7","schema_version":"edge-lab-recorder.raw.v1","sequence":null,"source":"clob_market_ws"}
{"event_at":"2026-07-28T04:11:09.827000Z","event_fingerprint":"bc5364cce1ba20ac5aa53e4c8722e7aaddc40a029b0d5bbdae5b3cbb99baa8d1","payload":{"connection_id":"f6725804f86a4c4eb588e4d5ed7db029","event_at":"2026-07-28T04:11:09.827000Z","event_type":"price_change","frame_hash":"f878e6620ca68f2cf2ee7541e8899f30f80075a1cef1de9c0201b8fd81c91096","frame_index":0,"kind":"data","monotonic_ns":313854896530708,"payload":{"event_type":"price_change","market":"0xd412ce774cfcf8dc9f71164aac78783978aac7b03871702a3b8a481bd9dc9688","price_changes":[{"asset_id":"107603864457683460275633293642179940881969192120168665300712204232021063124301","best_ask":"0.62","best_bid":"0.61","hash":"12df1916231da7ba3b7f5720da42c3c7d351fba1","price":"0.01","side":"BUY","size":"5638.02"},{"asset_id":"96600821790790307414914106093858868634329285205417149685270682748367152458577","best_ask":"0.39","best_bid":"0.38","hash":"21074dd7e66310763030a1a515a72919d3dc61d6","price":"0.99","side":"SELL","size":"5638.02"}],"timestamp":"1785211869827"},"payload_hash":"e031ec43e48a5946162ff5c0f84641bcaab9069bdd93c20baba45fe707417e42","raw_frame":"{\"market\":\"0xd412ce774cfcf8dc9f71164aac78783978aac7b03871702a3b8a481bd9dc9688\", \"price_changes\":[{\"asset_id\":\"107603864457683460275633293642179940881969192120168665300712204232021063124301\", \"price\":\"0.01\", \"size\":\"5638.02\", \"side\":\"BUY\", \"hash\":\"12df1916231da7ba3b7f5720da42c3c7d351fba1\", \"best_bid\":\"0.61\", \"best_ask\":\"0.62\"}, {\"asset_id\":\"96600821790790307414914106093858868634329285205417149685270682748367152458577\", \"price\":\"0.99\", \"size\":\"5638.02\", \"side\":\"SELL\", \"hash\":\"21074dd7e66310763030a1a515a72919d3dc61d6\", \"best_bid\":\"0.38\", \"best_ask\":\"0.39\"}], \"timestamp\":\"1785211869827\", \"event_type\":\"price_change\"}","received_at":"2026-07-28T04:11:11.819923Z","schema_version":"clob-market-ws.price_change.v1","sequence":null,"server_hash":null,"server_timestamp":"1785211869827","session_id":"2d607381e3054cee91998cdf45a4231c","source":"clob_market_ws"},"received_at":"2026-07-28T04:11:11.819923Z","record_id":"e14956e5df51095885bd3bc4581e6edbd8ee974b501e0feda7635b59841e3d57","schema_fingerprint":"4aa3821a28b0b7c2400bc59aba4bcc0a76e971dadd19610d3ad38c768e124dc7","schema_version":"edge-lab-recorder.raw.v1","sequence":null,"source":"clob_market_ws"}
{"event_at":"2026-07-28T04:11:09.838000Z","event_fingerprint":"ab63265a8a68d48289ac36c9e6c3473e5aba2a6667302fcd20a37af52c1d33fa","payload":{"connection_id":"f6725804f86a4c4eb588e4d5ed7db029","event_at":"2026-07-28T04:11:09.838000Z","event_type":"price_change","frame_hash":"cbeacf61855146ff69e12d68a2cd08e62f6229b6ef6c6e4217dfce58bfc78e6f","frame_index":0,"kind":"data","monotonic_ns":313854899419916,"payload":{"event_type":"price_change","market":"0xd412ce774cfcf8dc9f71164aac78783978aac7b03871702a3b8a481bd9dc9688","price_changes":[{"asset_id":"107603864457683460275633293642179940881969192120168665300712204232021063124301","best_ask":"0.62","best_bid":"0.61","hash":"505a590bd3b48337d31716dd1a04998f6f3dc0e2","price":"0.01","side":"BUY","size":"5643.02"},{"asset_id":"96600821790790307414914106093858868634329285205417149685270682748367152458577","best_ask":"0.39","best_bid":"0.38","hash":"5fc26a0d31f1cc26f023e6dca77c5e758edf46ea","price":"0.99","side":"SELL","size":"5643.02"}],"timestamp":"1785211869838"},"payload_hash":"32d730f5d3f6257d47629edd087129db398f616eb3b7aec11abf703a748b83eb","raw_frame":"{\"market\":\"0xd412ce774cfcf8dc9f71164aac78783978aac7b03871702a3b8a481bd9dc9688\", \"price_changes\":[{\"asset_id\":\"107603864457683460275633293642179940881969192120168665300712204232021063124301\", \"price\":\"0.01\", \"size\":\"5643.02\", \"side\":\"BUY\", \"hash\":\"505a590bd3b48337d31716dd1a04998f6f3dc0e2\", \"best_bid\":\"0.61\", \"best_ask\":\"0.62\"}, {\"asset_id\":\"96600821790790307414914106093858868634329285205417149685270682748367152458577\", \"price\":\"0.99\", \"size\":\"5643.02\", \"side\":\"SELL\", \"hash\":\"5fc26a0d31f1cc26f023e6dca77c5e758edf46ea\", \"best_bid\":\"0.38\", \"best_ask\":\"0.39\"}], \"timestamp\":\"1785211869838\", \"event_type\":\"price_change\"}","received_at":"2026-07-28T04:11:11.822813Z","schema_version":"clob-market-ws.price_change.v1","sequence":null,"server_hash":null,"server_timestamp":"1785211869838","session_id":"2d607381e3054cee91998cdf45a4231c","source":"clob_market_ws"},"received_at":"2026-07-28T04:11:11.822813Z","record_id":"71d16fad7b6067397d098b4f112b3b3d7c51b3543e5d1fef46c402e2bf89fe0b","schema_fingerprint":"4aa3821a28b0b7c2400bc59aba4bcc0a76e971dadd19610d3ad38c768e124dc7","schema_version":"edge-lab-recorder.raw.v1","sequence":null,"source":"clob_market_ws"}
{"event_at":"2026-07-28T04:11:09.860000Z","event_fingerprint":"f97808b812f2401ab76cf5fd86a084be2f365ca6f192246356737a749af2a0e1","payload":{"connection_id":"f6725804f86a4c4eb588e4d5ed7db029","event_at":"2026-07-28T04:11:09.860000Z","event_type":"price_change","frame_hash":"94db47b771547e00caca5d6692fffe21cb894f70552c3b53e8eb593fa39c2d05","frame_index":0,"kind":"data","monotonic_ns":313854903531083,"payload":{"event_type":"price_change","market":"0xd412ce774cfcf8dc9f71164aac78783978aac7b03871702a3b8a481bd9dc9688","price_changes":[{"asset_id":"107603864457683460275633293642179940881969192120168665300712204232021063124301","best_ask":"0.62","best_bid":"0.61","hash":"3575c0c6a6cb6234ea4842e2811459b83f8e3c43","price":"0.85","side":"SELL","size":"87.5"},{"asset_id":"96600821790790307414914106093858868634329285205417149685270682748367152458577","best_ask":"0.39","best_bid":"0.38","hash":"52575ec7056a2b264e5fe44c427d839e1dee0b83","price":"0.15","side":"BUY","size":"87.5"}],"timestamp":"1785211869860"},"payload_hash":"af42501ee3219ad7e77cec62432211c2a9d5813a807ecbd2d8e4427ef092ec55","raw_frame":"{\"market\":\"0xd412ce774cfcf8dc9f71164aac78783978aac7b03871702a3b8a481bd9dc9688\", \"price_changes\":[{\"asset_id\":\"107603864457683460275633293642179940881969192120168665300712204232021063124301\", \"price\":\"0.85\", \"size\":\"87.5\", \"side\":\"SELL\", \"hash\":\"3575c0c6a6cb6234ea4842e2811459b83f8e3c43\", \"best_bid\":\"0.61\", \"best_ask\":\"0.62\"}, {\"asset_id\":\"96600821790790307414914106093858868634329285205417149685270682748367152458577\", \"price\":\"0.15\", \"size\":\"87.5\", \"side\":\"BUY\", \"hash\":\"52575ec7056a2b264e5fe44c427d839e1dee0b83\", \"best_bid\":\"0.38\", \"best_ask\":\"0.39\"}], \"timestamp\":\"1785211869860\", \"event_type\":\"price_change\"}","received_at":"2026-07-28T04:11:11.826924Z","schema_version":"clob-market-ws.price_change.v1","sequence":null,"server_hash":null,"server_timestamp":"1785211869860","session_id":"2d607381e3054cee91998cdf45a4231c","source":"clob_market_ws"},"received_at":"2026-07-28T04:11:11.826924Z","record_id":"01bab637ad0203e269dde86546060bb812cd7bbc56b904dcaeffad1d4c47c59f","schema_fingerprint":"4aa3821a28b0b7c2400bc59aba4bcc0a76e971dadd19610d3ad38c768e124dc7","schema_version":"edge-lab-recorder.raw.v1","sequence":null,"source":"clob_market_ws"}
{"event_at":"2026-07-28T04:11:09.876000Z","event_fingerprint":"a74a34c8b1f7c26020985d4fd8a5dd61c54c511582111e5d0aaf5810220ab2e1","payload":{"connection_id":"f6725804f86a4c4eb588e4d5ed7db029","event_at":"2026-07-28T04:11:09.876000Z","event_type":"price_change","frame_hash":"2f3a340b801434d69d6976e6d2f4b152c46f94201ab6109891d1616356de8bd8","frame_index":0,"kind":"data","monotonic_ns":313854908633375,"payload":{"event_type":"price_change","market":"0xd412ce774cfcf8dc9f71164aac78783978aac7b03871702a3b8a481bd9dc9688","price_changes":[{"asset_id":"107603864457683460275633293642179940881969192120168665300712204232021063124301","best_ask":"0.62","best_bid":"0.61","hash":"638b44b00883a27129443ea65cc0b3a82cc4ba5e","price":"0.01","side":"BUY","size":"5638.02"},{"asset_id":"96600821790790307414914106093858868634329285205417149685270682748367152458577","best_ask":"0.39","best_bid":"0.38","hash":"8404f84eea4c30d723bf0512475da31b8088910f","price":"0.99","side":"SELL","size":"5638.02"}],"timestamp":"1785211869876"},"payload_hash":"afc67889977ed4ef1dc1d0cf1a8e9df8d8ef051cf622e3739c6b45c9935328f6","raw_frame":"{\"market\":\"0xd412ce774cfcf8dc9f71164aac78783978aac7b03871702a3b8a481bd9dc9688\", \"price_changes\":[{\"asset_id\":\"107603864457683460275633293642179940881969192120168665300712204232021063124301\", \"price\":\"0.01\", \"size\":\"5638.02\", \"side\":\"BUY\", \"hash\":\"638b44b00883a27129443ea65cc0b3a82cc4ba5e\", \"best_bid\":\"0.61\", \"best_ask\":\"0.62\"}, {\"asset_id\":\"96600821790790307414914106093858868634329285205417149685270682748367152458577\", \"price\":\"0.99\", \"size\":\"5638.02\", \"side\":\"SELL\", \"hash\":\"8404f84eea4c30d723bf0512475da31b8088910f\", \"best_bid\":\"0.38\", \"best_ask\":\"0.39\"}], \"timestamp\":\"1785211869876\", \"event_type\":\"price_change\"}","received_at":"2026-07-28T04:11:11.832026Z","schema_version":"clob-market-ws.price_change.v1","sequence":null,"server_hash":null,"server_timestamp":"1785211869876","session_id":"2d607381e3054cee91998cdf45a4231c","source":"clob_market_ws"},"received_at":"2026-07-28T04:11:11.832026Z","record_id":"0e28724c48f25e1455c3512dd546ec36ee5f175024504d856349bc9592cf7ff2","schema_fingerprint":"4aa3821a28b0b7c2400bc59aba4bcc0a76e971dadd19610d3ad38c768e124dc7","schema_version":"edge-lab-recorder.raw.v1","sequence":null,"source":"clob_market_ws"}
{"event_at":"2026-07-28T04:11:09.885000Z","event_fingerprint":"630544eaff2743343430ebb99a3b4364590046c176c4f93e1b941185cf63dcac","payload":{"connection_id":"f6725804f86a4c4eb588e4d5ed7db029","event_at":"2026-07-28T04:11:09.885000Z","event_type":"price_change","frame_hash":"2784026372970e4e782b925c4ffcb41fe1c3816dae72f00519c1869b7491a828","frame_index":0,"kind":"data","monotonic_ns":313854913709083,"payload":{"event_type":"price_change","market":"0xd412ce774cfcf8dc9f71164aac78783978aac7b03871702a3b8a481bd9dc9688","price_changes":[{"asset_id":"107603864457683460275633293642179940881969192120168665300712204232021063124301","best_ask":"0.62","best_bid":"0.61","hash":"8aaff0036f8a3bfdf4ba0df2d825cc555bf51c47","price":"0.01","side":"BUY","size":"5633.02"},{"asset_id":"96600821790790307414914106093858868634329285205417149685270682748367152458577","best_ask":"0.39","best_bid":"0.38","hash":"aac34f6a8d7642933fdbee01dd6b6c1a8dff8d38","price":"0.99","side":"SELL","size":"5633.02"}],"timestamp":"1785211869885"},"payload_hash":"667480cfd4c76823c4ed97712447a7c2d87674b3f2efa924cbbec566695e2081","raw_frame":"{\"market\":\"0xd412ce774cfcf8dc9f71164aac78783978aac7b03871702a3b8a481bd9dc9688\", \"price_changes\":[{\"asset_id\":\"107603864457683460275633293642179940881969192120168665300712204232021063124301\", \"price\":\"0.01\", \"size\":\"5633.02\", \"side\":\"BUY\", \"hash\":\"8aaff0036f8a3bfdf4ba0df2d825cc555bf51c47\", \"best_bid\":\"0.61\", \"best_ask\":\"0.62\"}, {\"asset_id\":\"96600821790790307414914106093858868634329285205417149685270682748367152458577\", \"price\":\"0.99\", \"size\":\"5633.02\", \"side\":\"SELL\", \"hash\":\"aac34f6a8d7642933fdbee01dd6b6c1a8dff8d38\", \"best_bid\":\"0.38\", \"best_ask\":\"0.39\"}], \"timestamp\":\"1785211869885\", \"event_type\":\"price_change\"}","received_at":"2026-07-28T04:11:11.837101Z","schema_version":"clob-market-ws.price_change.v1","sequence":null,"server_hash":null,"server_timestamp":"1785211869885","session_id":"2d607381e3054cee91998cdf45a4231c","source":"clob_market_ws"},"received_at":"2026-07-28T04:11:11.837101Z","record_id":"7cf345398e3b80069d5525425eb2e176b4524de13d6c15cd6014161478279ebd","schema_fingerprint":"4aa3821a28b0b7c2400bc59aba4bcc0a76e971dadd19610d3ad38c768e124dc7","schema_version":"edge-lab-recorder.raw.v1","sequence":null,"source":"clob_market_ws"}
{"event_at":"2026-07-28T04:11:09.891000Z","event_fingerprint":"850db1c1931f8bf2294611f37add595bdc5c017cbc5922d8f37a38995a2bd572","payload":{"connection_id":"f6725804f86a4c4eb588e4d5ed7db029","event_at":"2026-07-28T04:11:09.891000Z","event_type":"price_change","frame_hash":"e438a43d8988cdf2fb823a0c3fae6eca76fecf4edc1f33a04778b206d7681142","frame_index":0,"kind":"data","monotonic_ns":313854917995250,"payload":{"event_type":"price_change","market":"0xd412ce774cfcf8dc9f71164aac78783978aac7b03871702a3b8a481bd9dc9688","price_changes":[{"asset_id":"107603864457683460275633293642179940881969192120168665300712204232021063124301","best_ask":"0.62","best_bid":"0.61","hash":"2603f8f1eb76826b411d2d8fb393543a5347bc67","price":"0.87","side":"SELL","size":"85"},{"asset_id":"96600821790790307414914106093858868634329285205417149685270682748367152458577","best_ask":"0.39","best_bid":"0.38","hash":"0b202af5fa14764c79e610abeff34d4f9c914a02","price":"0.13","side":"BUY","size":"85"}],"timestamp":"1785211869891"},"payload_hash":"9219642ddae74f81bfa10766abe88eed1d3c792c03c328e3911a28835e21dbd9","raw_frame":"{\"market\":\"0xd412ce774cfcf8dc9f71164aac78783978aac7b03871702a3b8a481bd9dc9688\", \"price_changes\":[{\"asset_id\":\"107603864457683460275633293642179940881969192120168665300712204232021063124301\", \"price\":\"0.87\", \"size\":\"85\", \"side\":\"SELL\", \"hash\":\"2603f8f1eb76826b411d2d8fb393543a5347bc67\", \"best_bid\":\"0.61\", \"best_ask\":\"0.62\"}, {\"asset_id\":\"96600821790790307414914106093858868634329285205417149685270682748367152458577\", \"price\":\"0.13\", \"size\":\"85\", \"side\":\"BUY\", \"hash\":\"0b202af5fa14764c79e610abeff34d4f9c914a02\", \"best_bid\":\"0.38\", \"best_ask\":\"0.39\"}], \"timestamp\":\"1785211869891\", \"event_type\":\"price_change\"}","received_at":"2026-07-28T04:11:11.841388Z","schema_version":"clob-market-ws.price_change.v1","sequence":null,"server_hash":null,"server_timestamp":"1785211869891","session_id":"2d607381e3054cee91998cdf45a4231c","source":"clob_market_ws"},"received_at":"2026-07-28T04:11:11.841388Z","record_id":"0982b7e27bb9d21ba30ffdb2fe0ad6528a97d4660ee29f191e823b6e32bb9309","schema_fingerprint":"4aa3821a28b0b7c2400bc59aba4bcc0a76e971dadd19610d3ad38c768e124dc7","schema_version":"edge-lab-recorder.raw.v1","sequence":null,"source":"clob_market_ws"}
{"event_at":"2026-07-28T04:11:09.909000Z","event_fingerprint":"616884460fe2e39206e48dee959cc6daeb348df3ff0070443923012840eccc8c","payload":{"connection_id":"f6725804f86a4c4eb588e4d5ed7db029","event_at":"2026-07-28T04:11:09.909000Z","event_type":"best_bid_ask","frame_hash":"ac225b97e6c94e6c94c7fb1ef2be50eca8d1c2bee12900b502b70b535158419c","frame_index":0,"kind":"data","monotonic_ns":313854922198291,"payload":{"asset_id":"107603864457683460275633293642179940881969192120168665300712204232021063124301","best_ask":"0.62","best_bid":"0.59","event_type":"best_bid_ask","market":"0xd412ce774cfcf8dc9f71164aac78783978aac7b03871702a3b8a481bd9dc9688","spread":"0.03","timestamp":"1785211869909"},"payload_hash":"fe81c4351031485dce8b485228490144cb730d595beb7e7f60bd0326054fe36d","raw_frame":"{\"market\":\"0xd412ce774cfcf8dc9f71164aac78783978aac7b03871702a3b8a481bd9dc9688\", \"asset_id\":\"107603864457683460275633293642179940881969192120168665300712204232021063124301\", \"best_bid\":\"0.59\", \"best_ask\":\"0.62\", \"spread\":\"0.03\", \"timestamp\":\"1785211869909\", \"event_type\":\"best_bid_ask\"}","received_at":"2026-07-28T04:11:11.845590Z","schema_version":"clob-market-ws.best_bid_ask.v1","sequence":null,"server_hash":null,"server_timestamp":"1785211869909","session_id":"2d607381e3054cee91998cdf45a4231c","source":"clob_market_ws"},"received_at":"2026-07-28T04:11:11.845590Z","record_id":"f19466b7d60cc92b01d92ce7b4bae73347ba637d5ee584ebf6fdb5a2232cdbca","schema_fingerprint":"8488399f31b0337811b13b266be932db7062827c2470b78bd8e9e99bab51d17d","schema_version":"edge-lab-recorder.raw.v1","sequence":null,"source":"clob_market_ws"}
{"event_at":"2026-07-28T04:11:09.909000Z","event_fingerprint":"2c75a1169182c7e94a5b2d230b294dbca3dbc0a2d1b9e8bc67e9d316e57f5c71","payload":{"connection_id":"f6725804f86a4c4eb588e4d5ed7db029","event_at":"2026-07-28T04:11:09.909000Z","event_type":"best_bid_ask","frame_hash":"b2b1b80c3bfd72d0179737f4430ab8d364de445dd14dd63f538bc5d5a4d0d18b","frame_index":0,"kind":"data","monotonic_ns":313854925927750,"payload":{"asset_id":"96600821790790307414914106093858868634329285205417149685270682748367152458577","best_ask":"0.41","best_bid":"0.38","event_type":"best_bid_ask","market":"0xd412ce774cfcf8dc9f71164aac78783978aac7b03871702a3b8a481bd9dc9688","spread":"0.03","timestamp":"1785211869909"},"payload_hash":"9ae02752f1dd34e1a1126576d4612a437fd0cbf2916893ff69114620e7b77de8","raw_frame":"{\"market\":\"0xd412ce774cfcf8dc9f71164aac78783978aac7b03871702a3b8a481bd9dc9688\", \"asset_id\":\"96600821790790307414914106093858868634329285205417149685270682748367152458577\", \"best_bid\":\"0.38\", \"best_ask\":\"0.41\", \"spread\":\"0.03\", \"timestamp\":\"1785211869909\", \"event_type\":\"best_bid_ask\"}","received_at":"2026-07-28T04:11:11.849320Z","schema_version":"clob-market-ws.best_bid_ask.v1","sequence":null,"server_hash":null,"server_timestamp":"1785211869909","session_id":"2d607381e3054cee91998cdf45a4231c","source":"clob_market_ws"},"received_at":"2026-07-28T04:11:11.849320Z","record_id":"3e6f136a203abd1813531405621c54290bf868258f17433991133702585c30bd","schema_fingerprint":"8488399f31b0337811b13b266be932db7062827c2470b78bd8e9e99bab51d17d","schema_version":"edge-lab-recorder.raw.v1","sequence":null,"source":"clob_market_ws"}
{"event_at":"2026-07-28T04:11:09.909000Z","event_fingerprint":"686696e631095750920221a1ba5dfcd379b69851a98e5474b96a79002844c089","payload":{"connection_id":"f6725804f86a4c4eb588e4d5ed7db029","event_at":"2026-07-28T04:11:09.909000Z","event_type":"price_change","frame_hash":"930e459a19f6d88f8b09e863463a630a7b6b0621530ebd3344b75f13fc90aec5","frame_index":0,"kind":"data","monotonic_ns":313854928327125,"payload":{"event_type":"price_change","market":"0xd412ce774cfcf8dc9f71164aac78783978aac7b03871702a3b8a481bd9dc9688","price_changes":[{"asset_id":"107603864457683460275633293642179940881969192120168665300712204232021063124301","best_ask":"0.62","best_bid":"0.59","hash":"d202d73044eca39e5831f4199d127fc3613167ee","price":"0.59","side":"BUY","size":"1.13"},{"asset_id":"96600821790790307414914106093858868634329285205417149685270682748367152458577","best_ask":"0.41","best_bid":"0.38","hash":"23f7dcfc273cb4e507fcb7353eb591f2769c07af","price":"0.41","side":"SELL","size":"1.13"}],"timestamp":"1785211869909"},"payload_hash":"987aaa88cdbe252bd4247bc59e0632205d00a2814b5983eb177c14ed02429fbc","raw_frame":"{\"market\":\"0xd412ce774cfcf8dc9f71164aac78783978aac7b03871702a3b8a481bd9dc9688\", \"price_changes\":[{\"asset_id\":\"107603864457683460275633293642179940881969192120168665300712204232021063124301\", \"price\":\"0.59\", \"size\":\"1.13\", \"side\":\"BUY\", \"hash\":\"d202d73044eca39e5831f4199d127fc3613167ee\", \"best_bid\":\"0.59\", \"best_ask\":\"0.62\"}, {\"asset_id\":\"96600821790790307414914106093858868634329285205417149685270682748367152458577\", \"price\":\"0.41\", \"size\":\"1.13\", \"side\":\"SELL\", \"hash\":\"23f7dcfc273cb4e507fcb7353eb591f2769c07af\", \"best_bid\":\"0.38\", \"best_ask\":\"0.41\"}], \"timestamp\":\"1785211869909\", \"event_type\":\"price_change\"}","received_at":"2026-07-28T04:11:11.851719Z","schema_version":"clob-market-ws.price_change.v1","sequence":null,"server_hash":null,"server_timestamp":"1785211869909","session_id":"2d607381e3054cee91998cdf45a4231c","source":"clob_market_ws"},"received_at":"2026-07-28T04:11:11.851719Z","record_id":"1228a9f2b4044bbf830ef033c8c362b650b49d353ad00b5d9981ec0b3c70de1e","schema_fingerprint":"4aa3821a28b0b7c2400bc59aba4bcc0a76e971dadd19610d3ad38c768e124dc7","schema_version":"edge-lab-recorder.raw.v1","sequence":null,"source":"clob_market_ws"}
{"event_at":"2026-07-28T04:11:09.909000Z","event_fingerprint":"7c0589fef938320524033aa5ee0f5eb96ec029ee09e6acdefc4a9188812912dc","payload":{"connection_id":"f6725804f86a4c4eb588e4d5ed7db029","event_at":"2026-07-28T04:11:09.909000Z","event_type":"price_change","frame_hash":"eb0ab777caac7fc027a1ea6bfab5014d5abd4d95b252e2f9053e645c1cee59a8","frame_index":0,"kind":"data","monotonic_ns":313854932617000,"payload":{"event_type":"price_change","market":"0xd412ce774cfcf8dc9f71164aac78783978aac7b03871702a3b8a481bd9dc9688","price_changes":[{"asset_id":"107603864457683460275633293642179940881969192120168665300712204232021063124301","best_ask":"0.62","best_bid":"0.59","hash":"d202d73044eca39e5831f4199d127fc3613167ee","price":"0.61","side":"BUY","size":"0"},{"asset_id":"96600821790790307414914106093858868634329285205417149685270682748367152458577","best_ask":"0.41","best_bid":"0.38","hash":"23f7dcfc273cb4e507fcb7353eb591f2769c07af","price":"0.39","side":"SELL","size":"0"}],"timestamp":"1785211869909"},"payload_hash":"b4b140422bb68db8dab120719e3d902471967c2555aa388f4383d99f6a234e33","raw_frame":"{\"market\":\"0xd412ce774cfcf8dc9f71164aac78783978aac7b03871702a3b8a481bd9dc9688\", \"price_changes\":[{\"asset_id\":\"107603864457683460275633293642179940881969192120168665300712204232021063124301\", \"price\":\"0.61\", \"size\":\"0\", \"side\":\"BUY\", \"hash\":\"d202d73044eca39e5831f4199d127fc3613167ee\", \"best_bid\":\"0.59\", \"best_ask\":\"0.62\"}, {\"asset_id\":\"96600821790790307414914106093858868634329285205417149685270682748367152458577\", \"price\":\"0.39\", \"size\":\"0\", \"side\":\"SELL\", \"hash\":\"23f7dcfc273cb4e507fcb7353eb591f2769c07af\", \"best_bid\":\"0.38\", \"best_ask\":\"0.41\"}], \"timestamp\":\"1785211869909\", \"event_type\":\"price_change\"}","received_at":"2026-07-28T04:11:11.856009Z","schema_version":"clob-market-ws.price_change.v1","sequence":null,"server_hash":null,"server_timestamp":"1785211869909","session_id":"2d607381e3054cee91998cdf45a4231c","source":"clob_market_ws"},"received_at":"2026-07-28T04:11:11.856009Z","record_id":"86a4ffadee97c94442b60a095658a66baa39a341e4cc4fbc871f83f3a0313aab","schema_fingerprint":"4aa3821a28b0b7c2400bc59aba4bcc0a76e971dadd19610d3ad38c768e124dc7","schema_version":"edge-lab-recorder.raw.v1","sequence":null,"source":"clob_market_ws"}
{"event_at":"2026-07-28T04:11:09.909000Z","event_fingerprint":"a03a8a43f3d1a000e6f8bf1b3b0227d2e855428198e66180e0b66c0466f19741","payload":{"connection_id":"f6725804f86a4c4eb588e4d5ed7db029","event_at":"2026-07-28T04:11:09.909000Z","event_type":"price_change","frame_hash":"84fd808172d76ad063ec034406be1315f293a37966d2c0f1453d27cec84e7dab","frame_index":0,"kind":"data","monotonic_ns":313854935669458,"payload":{"event_type":"price_change","market":"0xd412ce774cfcf8dc9f71164aac78783978aac7b03871702a3b8a481bd9dc9688","price_changes":[{"asset_id":"96600821790790307414914106093858868634329285205417149685270682748367152458577","best_ask":"0.41","best_bid":"0.38","hash":"23f7dcfc273cb4e507fcb7353eb591f2769c07af","price":"0.39","side":"SELL","size":"0"},{"asset_id":"107603864457683460275633293642179940881969192120168665300712204232021063124301","best_ask":"0.62","best_bid":"0.59","hash":"d202d73044eca39e5831f4199d127fc3613167ee","price":"0.61","side":"BUY","size":"0"}],"timestamp":"1785211869909"},"payload_hash":"5249773d0bed8ed31a67efdc52917831228463b3bf7b997c466de09150efb48a","raw_frame":"{\"market\":\"0xd412ce774cfcf8dc9f71164aac78783978aac7b03871702a3b8a481bd9dc9688\", \"price_changes\":[{\"asset_id\":\"96600821790790307414914106093858868634329285205417149685270682748367152458577\", \"price\":\"0.39\", \"size\":\"0\", \"side\":\"SELL\", \"hash\":\"23f7dcfc273cb4e507fcb7353eb591f2769c07af\", \"best_bid\":\"0.38\", \"best_ask\":\"0.41\"}, {\"asset_id\":\"107603864457683460275633293642179940881969192120168665300712204232021063124301\", \"price\":\"0.61\", \"size\":\"0\", \"side\":\"BUY\", \"hash\":\"d202d73044eca39e5831f4199d127fc3613167ee\", \"best_bid\":\"0.59\", \"best_ask\":\"0.62\"}], \"timestamp\":\"1785211869909\", \"event_type\":\"price_change\"}","received_at":"2026-07-28T04:11:11.859061Z","schema_version":"clob-market-ws.price_change.v1","sequence":null,"server_hash":null,"server_timestamp":"1785211869909","session_id":"2d607381e3054cee91998cdf45a4231c","source":"clob_market_ws"},"received_at":"2026-07-28T04:11:11.859061Z","record_id":"46b9eb7b6109344dc7f8a89e7074511aed7f53208aaf344559a6c0a5698e79ca","schema_fingerprint":"4aa3821a28b0b7c2400bc59aba4bcc0a76e971dadd19610d3ad38c768e124dc7","schema_version":"edge-lab-recorder.raw.v1","sequence":null,"source":"clob_market_ws"}
{"event_at":"2026-07-28T04:11:09.909000Z","event_fingerprint":"7790c1cde6fb22f62fe0fcd2e0551ebf8dfd16e12112dee8421a442caffd559a","payload":{"connection_id":"f6725804f86a4c4eb588e4d5ed7db029","event_at":"2026-07-28T04:11:09.909000Z","event_type":"price_change","frame_hash":"f8aa1f5350e20c242b2d1fdc62ce0c7b2b9b397e0467e08861401e922d79f2e6","frame_index":0,"kind":"data","monotonic_ns":313854939926666,"payload":{"event_type":"price_change","market":"0xd412ce774cfcf8dc9f71164aac78783978aac7b03871702a3b8a481bd9dc9688","price_changes":[{"asset_id":"107603864457683460275633293642179940881969192120168665300712204232021063124301","best_ask":"0.62","best_bid":"0.59","hash":"d202d73044eca39e5831f4199d127fc3613167ee","price":"0.6","side":"BUY","size":"0"},{"asset_id":"96600821790790307414914106093858868634329285205417149685270682748367152458577","best_ask":"0.41","best_bid":"0.38","hash":"23f7dcfc273cb4e507fcb7353eb591f2769c07af","price":"0.4","side":"SELL","size":"0"}],"timestamp":"1785211869909"},"payload_hash":"3f6865becd63ce94591b469db6c6ed885e0cddb0fe839f7953285ef0b69c0da1","raw_frame":"{\"market\":\"0xd412ce774cfcf8dc9f71164aac78783978aac7b03871702a3b8a481bd9dc9688\", \"price_changes\":[{\"asset_id\":\"107603864457683460275633293642179940881969192120168665300712204232021063124301\", \"price\":\"0.6\", \"size\":\"0\", \"side\":\"BUY\", \"hash\":\"d202d73044eca39e5831f4199d127fc3613167ee\", \"best_bid\":\"0.59\", \"best_ask\":\"0.62\"}, {\"asset_id\":\"96600821790790307414914106093858868634329285205417149685270682748367152458577\", \"price\":\"0.4\", \"size\":\"0\", \"side\":\"SELL\", \"hash\":\"23f7dcfc273cb4e507fcb7353eb591f2769c07af\", \"best_bid\":\"0.38\", \"best_ask\":\"0.41\"}], \"timestamp\":\"1785211869909\", \"event_type\":\"price_change\"}","received_at":"2026-07-28T04:11:11.863319Z","schema_version":"clob-market-ws.price_change.v1","sequence":null,"server_hash":null,"server_timestamp":"1785211869909","session_id":"2d607381e3054cee91998cdf45a4231c","source":"clob_market_ws"},"received_at":"2026-07-28T04:11:11.863319Z","record_id":"21e1d7f562f1fe13161b0aa6c195545e419b521700405c859745d2c8c6edcabb","schema_fingerprint":"4aa3821a28b0b7c2400bc59aba4bcc0a76e971dadd19610d3ad38c768e124dc7","schema_version":"edge-lab-recorder.raw.v1","sequence":null,"source":"clob_market_ws"}
