{"event_at":"2026-07-28T04:10:33.926000Z","event_fingerprint":"09904595c75602c9bc17bcdb5416a5b052951ac9821bb2a023034d1a070831f1","payload":{"connection_id":"f6725804f86a4c4eb588e4d5ed7db029","event_at":"2026-07-28T04:10:33.926000Z","event_type":"price_change","frame_hash":"83a8431e593058cad726eaa7485a87f8d6d505311110237720891dc487ff7177","frame_index":0,"kind":"data","monotonic_ns":313817091479083,"payload":{"event_type":"price_change","market":"0xd412ce774cfcf8dc9f71164aac78783978aac7b03871702a3b8a481bd9dc9688","price_changes":[{"asset_id":"107603864457683460275633293642179940881969192120168665300712204232021063124301","best_ask":"0.65","best_bid":"0.63","hash":"21172a4fcf957b6b19cbcd14d7c71e0010c6f29f","price":"0.67","side":"SELL","size":"158"},{"asset_id":"96600821790790307414914106093858868634329285205417149685270682748367152458577","best_ask":"0.37","best_bid":"0.35","hash":"e8215bf45f33733d81a1b3c9643c4ba1b43ca63a","price":"0.33","side":"BUY","size":"158"}],"timestamp":"1785211833926"},"payload_hash":"04c86389f77a7a43cfab0bfc130558a2b5d5c979dd8e2a5eadc76fe56db0ea7a","raw_frame":"{\"market\":\"0xd412ce774cfcf8dc9f71164aac78783978aac7b03871702a3b8a481bd9dc9688\", \"price_changes\":[{\"asset_id\":\"107603864457683460275633293642179940881969192120168665300712204232021063124301\", \"price\":\"0.67\", \"size\":\"158\", \"side\":\"SELL\", \"hash\":\"21172a4fcf957b6b19cbcd14d7c71e0010c6f29f\", \"best_bid\":\"0.63\", \"best_ask\":\"0.65\"}, {\"asset_id\":\"96600821790790307414914106093858868634329285205417149685270682748367152458577\", \"price\":\"0.33\", \"size\":\"158\", \"side\":\"BUY\", \"hash\":\"e8215bf45f33733d81a1b3c9643c4ba1b43ca63a\", \"best_bid\":\"0.35\", \"best_ask\":\"0.37\"}], \"timestamp\":\"1785211833926\", \"event_type\":\"price_change\"}","received_at":"2026-07-28T04:10:34.015256Z","schema_version":"clob-market-ws.price_change.v1","sequence":null,"server_hash":null,"server_timestamp":"1785211833926","session_id":"2d607381e3054cee91998cdf45a4231c","source":"clob_market_ws"},"received_at":"2026-07-28T04:10:34.015256Z","record_id":"88da1be1d9bfcaeb8a4fba1ca0c64c381b141a191473b0f60985df4defe742f6","schema_fingerprint":"4aa3821a28b0b7c2400bc59aba4bcc0a76e971dadd19610d3ad38c768e124dc7","schema_version":"edge-lab-recorder.raw.v1","sequence":null,"source":"clob_market_ws"}
{"event_at":"2026-07-28T04:10:33.927000Z","event_fingerprint":"11244adbaa76631a26f342fbd807c7e8c26c5e9b6239ea9df5f7d9a5e39dff3d","payload":{"connection_id":"f6725804f86a4c4eb588e4d5ed7db029","event_at":"2026-07-28T04:10:33.927000Z","event_type":"price_change","frame_hash":"a694b755e31e2a328d7999db64e73d6190e99c29720297abcabcd7ada02f6552","frame_index":0,"kind":"data","monotonic_ns":313817104315208,"payload":{"event_type":"price_change","market":"0xd412ce774cfcf8dc9f71164aac78783978aac7b03871702a3b8a481bd9dc9688","price_changes":[{"asset_id":"96600821790790307414914106093858868634329285205417149685270682748367152458577","best_ask":"0.37","best_bid":"0.35","hash":"a097842f9a5a84b6850488bdf3134dafffd5925b","price":"0.28","side":"BUY","size":"233.49"},{"asset_id":"107603864457683460275633293642179940881969192120168665300712204232021063124301","best_ask":"0.65","best_bid":"0.63","hash":"e5094ad403a6cf85fb0ac08c12e3e2200f11f20f","price":"0.72","side":"SELL","size":"233.49"}],"timestamp":"1785211833927"},"payload_hash":"d9061a3870a70c47ff4f8fc7196b8e45b78f09aa0579f3bd0a3ed1b50f3bb077","raw_frame":"{\"market\":\"0xd412ce774cfcf8dc9f71164aac78783978aac7b03871702a3b8a481bd9dc9688\", \"price_changes\":[{\"asset_id\":\"96600821790790307414914106093858868634329285205417149685270682748367152458577\", \"price\":\"0.28\", \"size\":\"233.49\", \"side\":\"BUY\", \"hash\":\"a097842f9a5a84b6850488bdf3134dafffd5925b\", \"best_bid\":\"0.35\", \"best_ask\":\"0.37\"}, {\"asset_id\":\"107603864457683460275633293642179940881969192120168665300712204232021063124301\", \"price\":\"0.72\", \"size\":\"233.49\", \"side\":\"SELL\", \"hash\":\"e5094ad403a6cf85fb0ac08c12e3e2200f11f20f\", \"best_bid\":\"0.63\", \"best_ask\":\"0.65\"}], \"timestamp\":\"1785211833927\", \"event_type\":\"price_change\"}","received_at":"2026-07-28T04:10:34.028094Z","schema_version":"clob-market-ws.price_change.v1","sequence":null,"server_hash":null,"server_timestamp":"1785211833927","session_id":"2d607381e3054cee91998cdf45a4231c","source":"clob_market_ws"},"received_at":"2026-07-28T04:10:34.028094Z","record_id":"a18d596d70d6a8c2cc08b94f658fd2e7c87a6cc1b86146b99f32e2a20eef2a0d","schema_fingerprint":"4aa3821a28b0b7c2400bc59aba4bcc0a76e971dadd19610d3ad38c768e124dc7","schema_version":"edge-lab-recorder.raw.v1","sequence":null,"source":"clob_market_ws"}
{"event_at":"2026-07-28T04:10:33.927000Z","event_fingerprint":"159cbf4489a74bbb701a2028da13f220f03581cf49d5438367eac64b944e37a1","payload":{"connection_id":"f6725804f86a4c4eb588e4d5ed7db029","event_at":"2026-07-28T04:10:33.927000Z","event_type":"price_change","frame_hash":"1ade1a1db84c6adc2cfc8b5959a4020aacdd44be4b88e6f9abf675625563ad0a","frame_index":0,"kind":"data","monotonic_ns":313817111776083,"payload":{"event_type":"price_change","market":"0xd412ce774cfcf8dc9f71164aac78783978aac7b03871702a3b8a481bd9dc9688","price_changes":[{"asset_id":"96600821790790307414914106093858868634329285205417149685270682748367152458577","best_ask":"0.37","best_bid":"0.35","hash":"36dd23d57697a949a63fd70ba2ba51fdeada4a22","price":"0.34","side":"BUY","size":"65"},{"asset_id":"107603864457683460275633293642179940881969192120168665300712204232021063124301","best_ask":"0.65","best_bid":"0.63","hash":"d58b38b4fdb08710a83bb0ab36dab6fc1b12530c","price":"0.66","side":"SELL","size":"65"}],"timestamp":"1785211833927"},"payload_hash":"1537ff5378d93469cb5cfd4dfdb4eebfbecbfb1c0e6025eecf0947db904e199e","raw_frame":"{\"market\":\"0xd412ce774cfcf8dc9f71164aac78783978aac7b03871702a3b8a481bd9dc9688\", \"price_changes\":[{\"asset_id\":\"96600821790790307414914106093858868634329285205417149685270682748367152458577\", \"price\":\"0.34\", \"size\":\"65\", \"side\":\"BUY\", \"hash\":\"36dd23d57697a949a63fd70ba2ba51fdeada4a22\", \"best_bid\":\"0.35\", \"best_ask\":\"0.37\"}, {\"asset_id\":\"107603864457683460275633293642179940881969192120168665300712204232021063124301\", \"price\":\"0.66\", \"size\":\"65\", \"side\":\"SELL\", \"hash\":\"d58b38b4fdb08710a83bb0ab36dab6fc1b12530c\", \"best_bid\":\"0.63\", \"best_ask\":\"0.65\"}], \"timestamp\":\"1785211833927\", \"event_type\":\"price_change\"}","received_at":"2026-07-28T04:10:34.035554Z","schema_version":"clob-market-ws.price_change.v1","sequence":null,"server_hash":null,"server_timestamp":"1785211833927","session_id":"2d607381e3054cee91998cdf45a4231c","source":"clob_market_ws"},"received_at":"2026-07-28T04:10:34.035554Z","record_id":"7d796b44f992ee791c8649f2d3ce9cd271bec9463520cbf30f59129be43ec0dc","schema_fingerprint":"4aa3821a28b0b7c2400bc59aba4bcc0a76e971dadd19610d3ad38c768e124dc7","schema_version":"edge-lab-recorder.raw.v1","sequence":null,"source":"clob_market_ws"}
{"event_at":"2026-07-28T04:10:33.928000Z","event_fingerprint":"40a8c8d9e5544c23da410f1012e3fc954fdc3a1d44d86e20f484e829bc88daaa","payload":{"connection_id":"f6725804f86a4c4eb588e4d5ed7db029","event_at":"2026-07-28T04:10:33.928000Z","event_type":"price_change","frame_hash":"058c680f121178f922e351455faba0f89680b0661ec9d01dcf09bef7eb877f4b","frame_index":0,"kind":"data","monotonic_ns":313817117159791,"payload":{"event_type":"price_change","market":"0xd412ce774cfcf8dc9f71164aac78783978aac7b03871702a3b8a481bd9dc9688","price_changes":[{"asset_id":"107603864457683460275633293642179940881969192120168665300712204232021063124301","best_ask":"0.65","best_bid":"0.63","hash":"0c7eadff8a12e9020be6e009c817a97b93d1f6f4","price":"0.6","side":"BUY","size":"70.6"},{"asset_id":"96600821790790307414914106093858868634329285205417149685270682748367152458577","best_ask":"0.37","best_bid":"0.35","hash":"c48e54aaeef2eea6ad65b1b2ff7e05dab0585f45","price":"0.4","side":"SELL","size":"70.6"}],"timestamp":"1785211833928"},"payload_hash":"52a4cf357c0d80a7eb88c04319e098bc691178884f1324448a2c0a3ec62c5d0a","raw_frame":"{\"market\":\"0xd412ce774cfcf8dc9f71164aac78783978aac7b03871702a3b8a481bd9dc9688\", \"price_changes\":[{\"asset_id\":\"107603864457683460275633293642179940881969192120168665300712204232021063124301\", \"price\":\"0.6\", \"size\":\"70.6\", \"side\":\"BUY\", \"hash\":\"0c7eadff8a12e9020be6e009c817a97b93d1f6f4\", \"best_bid\":\"0.63\", \"best_ask\":\"0.65\"}, {\"asset_id\":\"96600821790790307414914106093858868634329285205417149685270682748367152458577\", \"price\":\"0.4\", \"size\":\"70.6\", \"side\":\"SELL\", \"hash\":\"c48e54aaeef2eea6ad65b1b2ff7e05dab0585f45\", \"best_bid\":\"0.35\", \"best_ask\":\"0.37\"}], \"timestamp\":\"1785211833928\", \"event_type\":\"price_change\"}","received_at":"2026-07-28T04:10:34.040940Z","schema_version":"clob-market-ws.price_change.v1","sequence":null,"server_hash":null,"server_timestamp":"1785211833928","session_id":"2d607381e3054cee91998cdf45a4231c","source":"clob_market_ws"},"received_at":"2026-07-28T04:10:34.040940Z","record_id":"1b490b8e758e58139f46d54c6d58d90ff2c18ef25e3ba7d25e5cb3f5f07f2b3f","schema_fingerprint":"4aa3821a28b0b7c2400bc59aba4bcc0a76e971dadd19610d3ad38c768e124dc7","schema_version":"edge-lab-recorder.raw.v1","sequence":null,"source":"clob_market_ws"}
{"event_at":"2026-07-28T04:10:33.930000Z","event_fingerprint":"fa3e2d03dddbeacfd8096118d9dc1e099acc980c273ac684bb9841ea8cc557c9","payload":{"connection_id":"f6725804f86a4c4eb588e4d5ed7db029","event_at":"2026-07-28T04:10:33.930000Z","event_type":"price_change","frame_hash":"32e3d12de68b1a0b3447b4e129acbbe6035442c1991c17d59d368fa521ebd531","frame_index":0,"kind":"data","monotonic_ns":313817122975666,"payload":{"event_type":"price_change","market":"0xd412ce774cfcf8dc9f71164aac78783978aac7b03871702a3b8a481bd9dc9688","price_changes":[{"asset_id":"96600821790790307414914106093858868634329285205417149685270682748367152458577","best_ask":"0.37","best_bid":"0.35","hash":"8e79b8bfd9ef93f3a0a9118090f1bfdcca93914c","price":"0.31","side":"BUY","size":"113"},{"asset_id":"107603864457683460275633293642179940881969192120168665300712204232021063124301","best_ask":"0.65","best_bid":"0.63","hash":"27f80fba901aa7389cd23f9149df1dce7fe8e0ff","price":"0.69","side":"SELL","size":"113"}],"timestamp":"1785211833930"},"payload_hash":"6ed738151f1570180faaeecff99e56490db2bf8bedab1c0d84bb921b973478be","raw_frame":"{\"market\":\"0xd412ce774cfcf8dc9f71164aac78783978aac7b03871702a3b8a481bd9dc9688\", \"price_changes\":[{\"asset_id\":\"96600821790790307414914106093858868634329285205417149685270682748367152458577\", \"price\":\"0.31\", \"size\":\"113\", \"side\":\"BUY\", \"hash\":\"8e79b8bfd9ef93f3a0a9118090f1bfdcca93914c\", \"best_bid\":\"0.35\", \"best_ask\":\"0.37\"}, {\"asset_id\":\"107603864457683460275633293642179940881969192120168665300712204232021063124301\", \"price\":\"0.69\", \"size\":\"113\", \"side\":\"SELL\", \"hash\":\"27f80fba901aa7389cd23f9149df1dce7fe8e0ff\", \"best_bid\":\"0.63\", \"best_ask\":\"0.65\"}], \"timestamp\":\"1785211833930\", \"event_type\":\"price_change\"}","received_at":"2026-07-28T04:10:34.046755Z","schema_version":"clob-market-ws.price_change.v1","sequence":null,"server_hash":null,"server_timestamp":"1785211833930","session_id":"2d607381e3054cee91998cdf45a4231c","source":"clob_market_ws"},"received_at":"2026-07-28T04:10:34.046755Z","record_id":"ffb918affb0f5cb92a039d84b8718aea7450fc1f4930ae71c71706ca5440dcbf","schema_fingerprint":"4aa3821a28b0b7c2400bc59aba4bcc0a76e971dadd19610d3ad38c768e124dc7","schema_version":"edge-lab-recorder.raw.v1","sequence":null,"source":"clob_market_ws"}
{"event_at":"2026-07-28T04:10:33.930000Z","event_fingerprint":"267ada00f4f797c3eae7476c1761bf2028b56c06159d876a3df66621818f1448","payload":{"connection_id":"f6725804f86a4c4eb588e4d5ed7db029","event_at":"2026-07-28T04:10:33.930000Z","event_type":"best_bid_ask","frame_hash":"4e8b96bfae5cb694da586f58dfb66ad22a13ac3fb25b4610fc6ea02171d2b1ec","frame_index":0,"kind":"data","monotonic_ns":313817134611208,"payload":{"asset_id":"107603864457683460275633293642179940881969192120168665300712204232021063124301","best_ask":"0.65","best_bid":"0.64","event_type":"best_bid_ask","market":"0xd412ce774cfcf8dc9f71164aac78783978aac7b03871702a3b8a481bd9dc9688","spread":"0.01","timestamp":"1785211833930"},"payload_hash":"c3d4f8aeea35736bac118b71f4eab7d124c1e86dcc1be92ab49cf013284cf0b5","raw_frame":"{\"market\":\"0xd412ce774cfcf8dc9f71164aac78783978aac7b03871702a3b8a481bd9dc9688\", \"asset_id\":\"107603864457683460275633293642179940881969192120168665300712204232021063124301\", \"best_bid\":\"0.64\", \"best_ask\":\"0.65\", \"spread\":\"0.01\", \"timestamp\":\"1785211833930\", \"event_type\":\"best_bid_ask\"}","received_at":"2026-07-28T04:10:34.058390Z","schema_version":"clob-market-ws.best_bid_ask.v1","sequence":null,"server_hash":null,"server_timestamp":"1785211833930","session_id":"2d607381e3054cee91998cdf45a4231c","source":"clob_market_ws"},"received_at":"2026-07-28T04:10:34.058390Z","record_id":"3517947a699c1aeb89b46f7c6167463e0928de612cc08bfdca2584aa6f78c045","schema_fingerprint":"8488399f31b0337811b13b266be932db7062827c2470b78bd8e9e99bab51d17d","schema_version":"edge-lab-recorder.raw.v1","sequence":null,"source":"clob_market_ws"}
{"event_at":"2026-07-28T04:10:33.930000Z","event_fingerprint":"94fc8c3d5c72190e1454238e60cffad4864cb0d1937e0c708442322d849ebad5","payload":{"connection_id":"f6725804f86a4c4eb588e4d5ed7db029","event_at":"2026-07-28T04:10:33.930000Z","event_type":"best_bid_ask","frame_hash":"5075d420f2669362cda55854aa2bad94f0103dd4abdbe363f7a799f4a536fa2a","frame_index":0,"kind":"data","monotonic_ns":313817138565083,"payload":{"asset_id":"96600821790790307414914106093858868634329285205417149685270682748367152458577","best_ask":"0.36","best_bid":"0.35","event_type":"best_bid_ask","market":"0xd412ce774cfcf8dc9f71164aac78783978aac7b03871702a3b8a481bd9dc9688","spread":"0.01","timestamp":"1785211833930"},"payload_hash":"848c35366a449dbd751fa2fc427c80abe415d3a6aab8d13f639a39c2e3748aa6","raw_frame":"{\"market\":\"0xd412ce774cfcf8dc9f71164aac78783978aac7b03871702a3b8a481bd9dc9688\", \"asset_id\":\"96600821790790307414914106093858868634329285205417149685270682748367152458577\", \"best_bid\":\"0.35\", \"best_ask\":\"0.36\", \"spread\":\"0.01\", \"timestamp\":\"1785211833930\", \"event_type\":\"best_bid_ask\"}","received_at":"2026-07-28T04:10:34.062344Z","schema_version":"clob-market-ws.best_bid_ask.v1","sequence":null,"server_hash":null,"server_timestamp":"1785211833930","session_id":"2d607381e3054cee91998cdf45a4231c","source":"clob_market_ws"},"received_at":"2026-07-28T04:10:34.062344Z","record_id":"a14782e0fa6fe6114cd220b12bdd853402e14b030ec33e863cc13075a376d555","schema_fingerprint":"8488399f31b0337811b13b266be932db7062827c2470b78bd8e9e99bab51d17d","schema_version":"edge-lab-recorder.raw.v1","sequence":null,"source":"clob_market_ws"}
{"event_at":"2026-07-28T04:10:33.930000Z","event_fingerprint":"431b072ef4b2266258727b2b16ba427121ac2c1a8d4f089b143a7ac9bd924c5c","payload":{"connection_id":"f6725804f86a4c4eb588e4d5ed7db029","event_at":"2026-07-28T04:10:33.930000Z","event_type":"price_change","frame_hash":"38f9880820747cdff7a21d574048268eda62f6f6d6d450be2565b22d2c4b6dac","frame_index":0,"kind":"data","monotonic_ns":313817141393833,"payload":{"event_type":"price_change","market":"0xd412ce774cfcf8dc9f71164aac78783978aac7b03871702a3b8a481bd9dc9688","price_changes":[{"asset_id":"107603864457683460275633293642179940881969192120168665300712204232021063124301","best_ask":"0.65","best_bid":"0.64","hash":"3ba651b0c6f33ce69e1f646a75a5c34315f2be15","price":"0.64","side":"BUY","size":"12.6"},{"asset_id":"96600821790790307414914106093858868634329285205417149685270682748367152458577","best_ask":"0.36","best_bid":"0.35","hash":"7c5f1d8dbacd4d180aa9c5f419c6c0c8e76f1db8","price":"0.36","side":"SELL","size":"12.6"}],"timestamp":"1785211833930"},"payload_hash":"1245a340e37c9ef5fb5dd864e5c55232ec76b668965b8889c02a1915a7143198","raw_frame":"{\"market\":\"0xd412ce774cfcf8dc9f71164aac78783978aac7b03871702a3b8a481bd9dc9688\", \"price_changes\":[{\"asset_id\":\"107603864457683460275633293642179940881969192120168665300712204232021063124301\", \"price\":\"0.64\", \"size\":\"12.6\", \"side\":\"BUY\", \"hash\":\"3ba651b0c6f33ce69e1f646a75a5c34315f2be15\", \"best_bid\":\"0.64\", \"best_ask\":\"0.65\"}, {\"asset_id\":\"96600821790790307414914106093858868634329285205417149685270682748367152458577\", \"price\":\"0.36\", \"size\":\"12.6\", \"side\":\"SELL\", \"hash\":\"7c5f1d8dbacd4d180aa9c5f419c6c0c8e76f1db8\", \"best_bid\":\"0.35\", \"best_ask\":\"0.36\"}], \"timestamp\":\"1785211833930\", \"event_type\":\"price_change\"}","received_at":"2026-07-28T04:10:34.065174Z","schema_version":"clob-market-ws.price_change.v1","sequence":null,"server_hash":null,"server_timestamp":"1785211833930","session_id":"2d607381e3054cee91998cdf45a4231c","source":"clob_market_ws"},"received_at":"2026-07-28T04:10:34.065174Z","record_id":"8fb6394788106c9312967a7ed3b1f69792a94761c716f0e959833fcbcfb642be","schema_fingerprint":"4aa3821a28b0b7c2400bc59aba4bcc0a76e971dadd19610d3ad38c768e124dc7","schema_version":"edge-lab-recorder.raw.v1","sequence":null,"source":"clob_market_ws"}
{"event_at":"2026-07-28T04:10:33.931000Z","event_fingerprint":"22ae2865d513a1aa7f6278a966e82ea5aff12c826dd935dd81eef134428e285d","payload":{"connection_id":"f6725804f86a4c4eb588e4d5ed7db029","event_at":"2026-07-28T04:10:33.931000Z","event_type":"price_change","frame_hash":"07d482f5488eadba2e682c539b950a9f09dd3027cffaf9d45ba2828790ee59aa","frame_index":0,"kind":"data","monotonic_ns":313817147721041,"payload":{"event_type":"price_change","market":"0xd412ce774cfcf8dc9f71164aac78783978aac7b03871702a3b8a481bd9dc9688","price_changes":[{"asset_id":"96600821790790307414914106093858868634329285205417149685270682748367152458577","best_ask":"0.36","best_bid":"0.35","hash":"b9710a4e0fae11690aa99f136329761a0c9029f4","price":"0.26","side":"BUY","size":"210.25"},{"asset_id":"107603864457683460275633293642179940881969192120168665300712204232021063124301","best_ask":"0.65","best_bid":"0.64","hash":"20503c58287c901be3d43d3a70f418ebf042e8a6","price":"0.74","side":"SELL","size":"210.25"}],"timestamp":"1785211833931"},"payload_hash":"f18cf3860106e2ab3ba9bb3070a24db774998803da5d544e7328f23051e221f9","raw_frame":"{\"market\":\"0xd412ce774cfcf8dc9f71164aac78783978aac7b03871702a3b8a481bd9dc9688\", \"price_changes\":[{\"asset_id\":\"96600821790790307414914106093858868634329285205417149685270682748367152458577\", \"price\":\"0.26\", \"size\":\"210.25\", \"side\":\"BUY\", \"hash\":\"b9710a4e0fae11690aa99f136329761a0c9029f4\", \"best_bid\":\"0.35\", \"best_ask\":\"0.36\"}, {\"asset_id\":\"107603864457683460275633293642179940881969192120168665300712204232021063124301\", \"price\":\"0.74\", \"size\":\"210.25\", \"side\":\"SELL\", \"hash\":\"20503c58287c901be3d43d3a70f418ebf042e8a6\", \"best_bid\":\"0.64\", \"best_ask\":\"0.65\"}], \"timestamp\":\"1785211833931\", \"event_type\":\"price_change\"}","received_at":"2026-07-28T04:10:34.071500Z","schema_version":"clob-market-ws.price_change.v1","sequence":null,"server_hash":null,"server_timestamp":"1785211833931","session_id":"2d607381e3054cee91998cdf45a4231c","source":"clob_market_ws"},"received_at":"2026-07-28T04:10:34.071500Z","record_id":"d596ce8fde96b29687fb0bb9776acb7b73e95006c25cd3eec9ca1ceabb26a852","schema_fingerprint":"4aa3821a28b0b7c2400bc59aba4bcc0a76e971dadd19610d3ad38c768e124dc7","schema_version":"edge-lab-recorder.raw.v1","sequence":null,"source":"clob_market_ws"}
{"event_at":"2026-07-28T04:10:33.932000Z","event_fingerprint":"de1aca9c50664bb589f6bc004dbb73486dd05f16989d84e9c4bd4ddda1e07807","payload":{"connection_id":"f6725804f86a4c4eb588e4d5ed7db029","event_at":"2026-07-28T04:10:33.932000Z","event_type":"price_change","frame_hash":"12f73bd164386c8d1393cae5b900d4dcff9a6fe376cf790016fd6cacc86c55d6","frame_index":0,"kind":"data","monotonic_ns":313817156456750,"payload":{"event_type":"price_change","market":"0xd412ce774cfcf8dc9f71164aac78783978aac7b03871702a3b8a481bd9dc9688","price_changes":[{"asset_id":"107603864457683460275633293642179940881969192120168665300712204232021063124301","best_ask":"0.65","best_bid":"0.64","hash":"03e19c3d284c6b446531c9b138aac751758ac698","price":"0.64","side":"BUY","size":"76.6"},{"asset_id":"96600821790790307414914106093858868634329285205417149685270682748367152458577","best_ask":"0.36","best_bid":"0.35","hash":"b1056d723ffc33f6fd52cf89f573ba6df9bdf93f","price":"0.36","side":"SELL","size":"76.6"}],"timestamp":"1785211833932"},"payload_hash":"9196651312efc3cd3b09d13dac4b163a73e815ec273257609c4ebdde649fa9e7","raw_frame":"{\"market\":\"0xd412ce774cfcf8dc9f71164aac78783978aac7b03871702a3b8a481bd9dc9688\", \"price_changes\":[{\"asset_id\":\"107603864457683460275633293642179940881969192120168665300712204232021063124301\", \"price\":\"0.64\", \"size\":\"76.6\", \"side\":\"BUY\", \"hash\":\"03e19c3d284c6b446531c9b138aac751758ac698\", \"best_bid\":\"0.64\", \"best_ask\":\"0.65\"}, {\"asset_id\":\"96600821790790307414914106093858868634329285205417149685270682748367152458577\", \"price\":\"0.36\", \"size\":\"76.6\", \"side\":\"SELL\", \"hash\":\"b1056d723ffc33f6fd52cf89f573ba6df9bdf93f\", \"best_bid\":\"0.35\", \"best_ask\":\"0.36\"}], \"timestamp\":\"1785211833932\", \"event_type\":\"price_change\"}","received_at":"2026-07-28T04:10:34.080234Z","schema_version":"clob-market-ws.price_change.v1","sequence":null,"server_hash":null,"server_timestamp":"1785211833932","session_id":"2d607381e3054cee91998cdf45a4231c","source":"clob_market_ws"},"received_at":"2026-07-28T04:10:34.080234Z","record_id":"f400ca929eba7a054ad03107242b601be4270467f6b83cab5df6189032ad87ea","schema_fingerprint":"4aa3821a28b0b7c2400bc59aba4bcc0a76e971dadd19610d3ad38c768e124dc7","schema_version":"edge-lab-recorder.raw.v1","sequence":null,"source":"clob_market_ws"}
{"event_at":"2026-07-28T04:10:33.932000Z","event_fingerprint":"2ffd9e72a722782fa6bd7e5c672e6bfd05eac991c283abbbb4bdbf338da7934f","payload":{"connection_id":"f6725804f86a4c4eb588e4d5ed7db029","event_at":"2026-07-28T04:10:33.932000Z","event_type":"price_change","frame_hash":"ce5dee542f93a3a5aaa0338578fa388cedd78e4cdf10895dab614e9fd5f080d2","frame_index":0,"kind":"data","monotonic_ns":313817162536833,"payload":{"event_type":"price_change","market":"0xd412ce774cfcf8dc9f71164aac78783978aac7b03871702a3b8a481bd9dc9688","price_changes":[{"asset_id":"96600821790790307414914106093858868634329285205417149685270682748367152458577","best_ask":"0.36","best_bid":"0.35","hash":"919c44a2cff3b1504d0a081cdea3377741c76b07","price":"0.26","side":"BUY","size":"223.25"},{"asset_id":"107603864457683460275633293642179940881969192120168665300712204232021063124301","best_ask":"0.65","best_bid":"0.64","hash":"aa1a9a7c81c91230989c6aa052d52982e636a32f","price":"0.74","side":"SELL","size":"223.25"}],"timestamp":"1785211833932"},"payload_hash":"f7dc898f20fae84c51a379d94ff49484d64b49b623d8aa97571185c9e72b91cb","raw_frame":"{\"market\":\"0xd412ce774cfcf8dc9f71164aac78783978aac7b03871702a3b8a481bd9dc9688\", \"price_changes\":[{\"asset_id\":\"96600821790790307414914106093858868634329285205417149685270682748367152458577\", \"price\":\"0.26\", \"size\":\"223.25\", \"side\":\"BUY\", \"hash\":\"919c44a2cff3b1504d0a081cdea3377741c76b07\", \"best_bid\":\"0.35\", \"best_ask\":\"0.36\"}, {\"asset_id\":\"107603864457683460275633293642179940881969192120168665300712204232021063124301\", \"price\":\"0.74\", \"size\":\"223.25\", \"side\":\"SELL\", \"hash\":\"aa1a9a7c81c91230989c6aa052d52982e636a32f\", \"best_bid\":\"0.64\", \"best_ask\":\"0.65\"}], \"timestamp\":\"1785211833932\", \"event_type\":\"price_change\"}","received_at":"2026-07-28T04:10:34.086316Z","schema_version":"clob-market-ws.price_change.v1","sequence":null,"server_hash":null,"server_timestamp":"1785211833932","session_id":"2d607381e3054cee91998cdf45a4231c","source":"clob_market_ws"},"received_at":"2026-07-28T04:10:34.086316Z","record_id":"737362ce4a1b4e1648140951736453ef2a3092d5d1c66e273b375188c396b57c","schema_fingerprint":"4aa3821a28b0b7c2400bc59aba4bcc0a76e971dadd19610d3ad38c768e124dc7","schema_version":"edge-lab-recorder.raw.v1","sequence":null,"source":"clob_market_ws"}
{"event_at":"2026-07-28T04:10:33.933000Z","event_fingerprint":"4f4cde737b2181eb4dfd110035b1bf5a12e8c321cae840f1928d92c78da76aac","payload":{"connection_id":"f6725804f86a4c4eb588e4d5ed7db029","event_at":"2026-07-28T04:10:33.933000Z","event_type":"price_change","frame_hash":"3fa545dee69df9a34438c86431009dc61758c8b4e3040479977adb412146474c","frame_index":0,"kind":"data","monotonic_ns":313817175163000,"payload":{"event_type":"price_change","market":"0xd412ce774cfcf8dc9f71164aac78783978aac7b03871702a3b8a481bd9dc9688","price_changes":[{"asset_id":"96600821790790307414914106093858868634329285205417149685270682748367152458577","best_ask":"0.36","best_bid":"0.35","hash":"95967f2c7cc16deb548e028dd3f7a3d90662bb54","price":"0.27","side":"BUY","size":"229"},{"asset_id":"107603864457683460275633293642179940881969192120168665300712204232021063124301","best_ask":"0.65","best_bid":"0.64","hash":"fdf894e7ab12d40d9246b4a1803487e850cb7b44","price":"0.73","side":"SELL","size":"229"}],"timestamp":"1785211833933"},"payload_hash":"21c354cd78f55e50e9eb20dcd35e188a0f98544b2890379859cd66ca8cf9e149","raw_frame":"{\"market\":\"0xd412ce774cfcf8dc9f71164aac78783978aac7b03871702a3b8a481bd9dc9688\", \"price_changes\":[{\"asset_id\":\"96600821790790307414914106093858868634329285205417149685270682748367152458577\", \"price\":\"0.27\", \"size\":\"229\", \"side\":\"BUY\", \"hash\":\"95967f2c7cc16deb548e028dd3f7a3d90662bb54\", \"best_bid\":\"0.35\", \"best_ask\":\"0.36\"}, {\"asset_id\":\"107603864457683460275633293642179940881969192120168665300712204232021063124301\", \"price\":\"0.73\", \"size\":\"229\", \"side\":\"SELL\", \"hash\":\"fdf894e7ab12d40d9246b4a1803487e850cb7b44\", \"best_bid\":\"0.64\", \"best_ask\":\"0.65\"}], \"timestamp\":\"1785211833933\", \"event_type\":\"price_change\"}","received_at":"2026-07-28T04:10:34.098942Z","schema_version":"clob-market-ws.price_change.v1","sequence":null,"server_hash":null,"server_timestamp":"1785211833933","session_id":"2d607381e3054cee91998cdf45a4231c","source":"clob_market_ws"},"received_at":"2026-07-28T04:10:34.098942Z","record_id":"685c9088066d557106fa001a17cd4d9de1842ae023f37af52b60d1ba9b5b548e","schema_fingerprint":"4aa3821a28b0b7c2400bc59aba4bcc0a76e971dadd19610d3ad38c768e124dc7","schema_version":"edge-lab-recorder.raw.v1","sequence":null,"source":"clob_market_ws"}
{"event_at":"2026-07-28T04:10:33.934000Z","event_fingerprint":"d58f24cbea932bfee58aeb74aae9f4da08e58d8b86f56c6e73f5e0b1254e5b9a","payload":{"connection_id":"f6725804f86a4c4eb588e4d5ed7db029","event_at":"2026-07-28T04:10:33.934000Z","event_type":"price_change","frame_hash":"e1c4183679dc263d0ef6108388ea9419c2d1d82e632a881a5627e8a81ab36e82","frame_index":0,"kind":"data","monotonic_ns":313817181423375,"payload":{"event_type":"price_change","market":"0xd412ce774cfcf8dc9f71164aac78783978aac7b03871702a3b8a481bd9dc9688","price_changes":[{"asset_id":"107603864457683460275633293642179940881969192120168665300712204232021063124301","best_ask":"0.65","best_bid":"0.64","hash":"997174f9e62d2a994ffa7b4878283eb86bf25962","price":"0.57","side":"BUY","size":"47"},{"asset_id":"96600821790790307414914106093858868634329285205417149685270682748367152458577","best_ask":"0.36","best_bid":"0.35","hash":"4631d3844ff82a943fb6400f79fdf5b2d5c461a3","price":"0.43","side":"SELL","size":"47"}],"timestamp":"1785211833934"},"payload_hash":"cfea6a417a02adcaf8a4b880b94d1604172cd13fe182c39a9b1425b0a306d25d","raw_frame":"{\"market\":\"0xd412ce774cfcf8dc9f71164aac78783978aac7b03871702a3b8a481bd9dc9688\", \"price_changes\":[{\"asset_id\":\"107603864457683460275633293642179940881969192120168665300712204232021063124301\", \"price\":\"0.57\", \"size\":\"47\", \"side\":\"BUY\", \"hash\":\"997174f9e62d2a994ffa7b4878283eb86bf25962\", \"best_bid\":\"0.64\", \"best_ask\":\"0.65\"}, {\"asset_id\":\"96600821790790307414914106093858868634329285205417149685270682748367152458577\", \"price\":\"0.43\", \"size\":\"47\", \"side\":\"SELL\", \"hash\":\"4631d3844ff82a943fb6400f79fdf5b2d5c461a3\", \"best_bid\":\"0.35\", \"best_ask\":\"0.36\"}], \"timestamp\":\"1785211833934\", \"event_type\":\"price_change\"}","received_at":"2026-07-28T04:10:34.105201Z","schema_version":"clob-market-ws.price_change.v1","sequence":null,"server_hash":null,"server_timestamp":"1785211833934","session_id":"2d607381e3054cee91998cdf45a4231c","source":"clob_market_ws"},"received_at":"2026-07-28T04:10:34.105201Z","record_id":"dd12dceecfaf93b7a5a0c75e12ad0c9317bd775fcd6ef43e54242e456718d4fb","schema_fingerprint":"4aa3821a28b0b7c2400bc59aba4bcc0a76e971dadd19610d3ad38c768e124dc7","schema_version":"edge-lab-recorder.raw.v1","sequence":null,"source":"clob_market_ws"}
{"event_at":"2026-07-28T04:10:33.934000Z","event_fingerprint":"df41e34f3f57f404eb071c6175b0ed04bd153ae4029f4c1067c80ea3fcaaa6ab","payload":{"connection_id":"f6725804f86a4c4eb588e4d5ed7db029","event_at":"2026-07-28T04:10:33.934000Z","event_type":"price_change","frame_hash":"a5cf7a879b08f8db3312ed528fbf2213d476f4c29e317c9c968316fae4a23cf0","frame_index":0,"kind":"data","monotonic_ns":313817185363166,"payload":{"event_type":"price_change","market":"0xd412ce774cfcf8dc9f71164aac78783978aac7b03871702a3b8a481bd9dc9688","price_changes":[{"asset_id":"96600821790790307414914106093858868634329285205417149685270682748367152458577","best_ask":"0.36","best_bid":"0.35","hash":"1ea20ce57e3e13a11b7e6dd699ee48603ff992c1","price":"0.24","side":"BUY","size":"82.39"},{"asset_id":"107603864457683460275633293642179940881969192120168665300712204232021063124301","best_ask":"0.65","best_bid":"0.64","hash":"267b25114de80d1b2e1fb62c24b06e96df4e12db","price":"0.76","side":"SELL","size":"82.39"}],"timestamp":"1785211833934"},"payload_hash":"676137749f7ab5583ec060a5a98e9111875eb5eeb7f20bf5c93c4490ad0c9275","raw_frame":"{\"market\":\"0xd412ce774cfcf8dc9f71164aac78783978aac7b03871702a3b8a481bd9dc9688\", \"price_changes\":[{\"asset_id\":\"96600821790790307414914106093858868634329285205417149685270682748367152458577\", \"price\":\"0.24\", \"size\":\"82.39\", \"side\":\"BUY\", \"hash\":\"1ea20ce57e3e13a11b7e6dd699ee48603ff992c1\", \"best_bid\":\"0.35\", \"best_ask\":\"0.36\"}, {\"asset_id\":\"107603864457683460275633293642179940881969192120168665300712204232021063124301\", \"price\":\"0.76\", \"size\":\"82.39\", \"side\":\"SELL\", \"hash\":\"267b25114de80d1b2e1fb62c24b06e96df4e12db\", \"best_bid\":\"0.64\", \"best_ask\":\"0.65\"}], \"timestamp\":\"1785211833934\", \"event_type\":\"price_change\"}","received_at":"2026-07-28T04:10:34.109142Z","schema_version":"clob-market-ws.price_change.v1","sequence":null,"server_hash":null,"server_timestamp":"1785211833934","session_id":"2d607381e3054cee91998cdf45a4231c","source":"clob_market_ws"},"received_at":"2026-07-28T04:10:34.109142Z","record_id":"39237407a3937bf6d27000012ab033c0d2e790bd2b28e61b4fa2bfc615c32379","schema_fingerprint":"4aa3821a28b0b7c2400bc59aba4bcc0a76e971dadd19610d3ad38c768e124dc7","schema_version":"edge-lab-recorder.raw.v1","sequence":null,"source":"clob_market_ws"}
{"event_at":"2026-07-28T04:10:33.935000Z","event_fingerprint":"f9c2a1a05d2b7648953d984ec719d6bb8e7de7bc7d9c256d24ec48bb3f74b731","payload":{"connection_id":"f6725804f86a4c4eb588e4d5ed7db029","event_at":"2026-07-28T04:10:33.935000Z","event_type":"price_change","frame_hash":"f40e8fd9b7d37b93725d967029fc3778966b9d6e89960d34bc185e353d8ef1d6","frame_index":0,"kind":"data","monotonic_ns":313817189922000,"payload":{"event_type":"price_change","market":"0xd412ce774cfcf8dc9f71164aac78783978aac7b03871702a3b8a481bd9dc9688","price_changes":[{"asset_id":"107603864457683460275633293642179940881969192120168665300712204232021063124301","best_ask":"0.65","best_bid":"0.64","hash":"f7fbaa5262cdf16b682173a662510486e5ad958f","price":"0.64","side":"BUY","size":"93.03"},{"asset_id":"96600821790790307414914106093858868634329285205417149685270682748367152458577","best_ask":"0.36","best_bid":"0.35","hash":"128775296f092a81e3df45846dadb88259238954","price":"0.36","side":"SELL","size":"93.03"}],"timestamp":"1785211833935"},"payload_hash":"e723b5d66c4a7e8766b05147bee1484fa595a141f082c68d293a20360ba84fa6","raw_frame":"{\"market\":\"0xd412ce774cfcf8dc9f71164aac78783978aac7b03871702a3b8a481bd9dc9688\", \"price_changes\":[{\"asset_id\":\"107603864457683460275633293642179940881969192120168665300712204232021063124301\", \"price\":\"0.64\", \"size\":\"93.03\", \"side\":\"BUY\", \"hash\":\"f7fbaa5262cdf16b682173a662510486e5ad958f\", \"best_bid\":\"0.64\", \"best_ask\":\"0.65\"}, {\"asset_id\":\"96600821790790307414914106093858868634329285205417149685270682748367152458577\", \"price\":\"0.36\", \"size\":\"93.03\", \"side\":\"SELL\", \"hash\":\"128775296f092a81e3df45846dadb88259238954\", \"best_bid\":\"0.35\", \"best_ask\":\"0.36\"}], \"timestamp\":\"1785211833935\", \"event_type\":\"price_change\"}","received_at":"2026-07-28T04:10:34.113701Z","schema_version":"clob-market-ws.price_change.v1","sequence":null,"server_hash":null,"server_timestamp":"1785211833935","session_id":"2d607381e3054cee91998cdf45a4231c","source":"clob_market_ws"},"received_at":"2026-07-28T04:10:34.113701Z","record_id":"b2d93962a9c998df9dd95d6d3b8e6e74554b077db3974c66ff77e415bebc68d8","schema_fingerprint":"4aa3821a28b0b7c2400bc59aba4bcc0a76e971dadd19610d3ad38c768e124dc7","schema_version":"edge-lab-recorder.raw.v1","sequence":null,"source":"clob_market_ws"}
{"event_at":"2026-07-28T04:10:33.936000Z","event_fingerprint":"d8bd9ada59d15c2447daf05f784ecea5cf6ce0b3af42c957d0ce29bcedd9607e","payload":{"connection_id":"f6725804f86a4c4eb588e4d5ed7db029","event_at":"2026-07-28T04:10:33.936000Z","event_type":"price_change","frame_hash":"25631c015454202ede8edf919c31244b9694b5805043492f69db3bfef16acabc","frame_index":0,"kind":"data","monotonic_ns":313817194334958,"payload":{"event_type":"price_change","market":"0xd412ce774cfcf8dc9f71164aac78783978aac7b03871702a3b8a481bd9dc9688","price_changes":[{"asset_id":"107603864457683460275633293642179940881969192120168665300712204232021063124301","best_ask":"0.65","best_bid":"0.64","hash":"8aee6d90a4380f603f6f348e92c6d975d3b71f57","price":"0.62","side":"BUY","size":"31.6"},{"asset_id":"96600821790790307414914106093858868634329285205417149685270682748367152458577","best_ask":"0.36","best_bid":"0.35","hash":"bb221e8396e7859084f3ea6ef6b9cc4c0ae7c496","price":"0.38","side":"SELL","size":"31.6"}],"timestamp":"1785211833936"},"payload_hash":"3264cb26fe3cf220b993d7a0588e00a4e6df86f4d39ca70d43ef3c88aef7e5dd","raw_frame":"{\"market\":\"0xd412ce774cfcf8dc9f71164aac78783978aac7b03871702a3b8a481bd9dc9688\", \"price_changes\":[{\"asset_id\":\"107603864457683460275633293642179940881969192120168665300712204232021063124301\", \"price\":\"0.62\", \"size\":\"31.6\", \"side\":\"BUY\", \"hash\":\"8aee6d90a4380f603f6f348e92c6d975d3b71f57\", \"best_bid\":\"0.64\", \"best_ask\":\"0.65\"}, {\"asset_id\":\"96600821790790307414914106093858868634329285205417149685270682748367152458577\", \"price\":\"0.38\", \"size\":\"31.6\", \"side\":\"SELL\", \"hash\":\"bb221e8396e7859084f3ea6ef6b9cc4c0ae7c496\", \"best_bid\":\"0.35\", \"best_ask\":\"0.36\"}], \"timestamp\":\"1785211833936\", \"event_type\":\"price_change\"}","received_at":"2026-07-28T04:10:34.118120Z","schema_version":"clob-market-ws.price_change.v1","sequence":null,"server_hash":null,"server_timestamp":"1785211833936","session_id":"2d607381e3054cee91998cdf45a4231c","source":"clob_market_ws"},"received_at":"2026-07-28T04:10:34.118120Z","record_id":"eb30557953803495db4c3656d809c7e3bcc0ed4ba8c024fec463942eb4f1fae0","schema_fingerprint":"4aa3821a28b0b7c2400bc59aba4bcc0a76e971dadd19610d3ad38c768e124dc7","schema_version":"edge-lab-recorder.raw.v1","sequence":null,"source":"clob_market_ws"}
{"event_at":"2026-07-28T04:10:33.937000Z","event_fingerprint":"d826fdfa73de0254b9d98806b1fd4916adfecc1305ff94714d459fafa061d49a","payload":{"connection_id":"f6725804f86a4c4eb588e4d5ed7db029","event_at":"2026-07-28T04:10:33.937000Z","event_type":"price_change","frame_hash":"fae00733d4e3e8004c57cd1d188e2ce88a3220eda12fe3feb27d98bcc0d6bf55","frame_index":0,"kind":"data","monotonic_ns":313817199404500,"payload":{"event_type":"price_change","market":"0xd412ce774cfcf8dc9f71164aac78783978aac7b03871702a3b8a481bd9dc9688","price_changes":[{"asset_id":"107603864457683460275633293642179940881969192120168665300712204232021063124301","best_ask":"0.65","best_bid":"0.64","hash":"9f176f99d8625d33e2698aa68803be51d27bf6a5","price":"0.64","side":"BUY","size":"124.03"},{"asset_id":"96600821790790307414914106093858868634329285205417149685270682748367152458577","best_ask":"0.36","best_bid":"0.35","hash":"bbb41f0bd127b3e116ada18c719843f39881c8ae","price":"0.36","side":"SELL","size":"124.03"}],"timestamp":"1785211833937"},"payload_hash":"acafd10421909f16932aa8a37c91dafac3fad014c8e83525726bd785d1fcb537","raw_frame":"{\"market\":\"0xd412ce774cfcf8dc9f71164aac78783978aac7b03871702a3b8a481bd9dc9688\", \"price_changes\":[{\"asset_id\":\"107603864457683460275633293642179940881969192120168665300712204232021063124301\", \"price\":\"0.64\", \"size\":\"124.03\", \"side\":\"BUY\", \"hash\":\"9f176f99d8625d33e2698aa68803be51d27bf6a5\", \"best_bid\":\"0.64\", \"best_ask\":\"0.65\"}, {\"asset_id\":\"96600821790790307414914106093858868634329285205417149685270682748367152458577\", \"price\":\"0.36\", \"size\":\"124.03\", \"side\":\"SELL\", \"hash\":\"bbb41f0bd127b3e116ada18c719843f39881c8ae\", \"best_bid\":\"0.35\", \"best_ask\":\"0.36\"}], \"timestamp\":\"1785211833937\", \"event_type\":\"price_change\"}","received_at":"2026-07-28T04:10:34.123181Z","schema_version":"clob-market-ws.price_change.v1","sequence":null,"server_hash":null,"server_timestamp":"1785211833937","session_id":"2d607381e3054cee91998cdf45a4231c","source":"clob_market_ws"},"received_at":"2026-07-28T04:10:34.123181Z","record_id":"cdad93b8df19b10e189846550d7bf5368b6e3b8c9ba2d230a214fe8ec0f605ee","schema_fingerprint":"4aa3821a28b0b7c2400bc59aba4bcc0a76e971dadd19610d3ad38c768e124dc7","schema_version":"edge-lab-recorder.raw.v1","sequence":null,"source":"clob_market_ws"}
{"event_at":"2026-07-28T04:10:33.938000Z","event_fingerprint":"bcbd160bdd924be91c68cf53e3bf040d28ac71c6cf9dd4d8ce7bb1d673a371fb","payload":{"connection_id":"f6725804f86a4c4eb588e4d5ed7db029","event_at":"2026-07-28T04:10:33.938000Z","event_type":"price_change","frame_hash":"37450dda905cb7d05d75b868d31eb2f81b16d5f71d17b8ae84d7a4edf9df7438","frame_index":0,"kind":"data","monotonic_ns":313817204714458,"payload":{"event_type":"price_change","market":"0xd412ce774cfcf8dc9f71164aac78783978aac7b03871702a3b8a481bd9dc9688","price_changes":[{"asset_id":"96600821790790307414914106093858868634329285205417149685270682748367152458577","best_ask":"0.36","best_bid":"0.35","hash":"f22c7294ada657bc3b83537c6aefd96ddcdef369","price":"0.35","side":"BUY","size":"57"},{"asset_id":"107603864457683460275633293642179940881969192120168665300712204232021063124301","best_ask":"0.65","best_bid":"0.64","hash":"55d8e1095250dde8fb54fb172aea147962c65f77","price":"0.65","side":"SELL","size":"57"}],"timestamp":"1785211833938"},"payload_hash":"8878e704f62a8f85d9145a8c3b5befbb1126e7dc9fad0d2d7f9e431d3d4f2da6","raw_frame":"{\"market\":\"0xd412ce774cfcf8dc9f71164aac78783978aac7b03871702a3b8a481bd9dc9688\", \"price_changes\":[{\"asset_id\":\"96600821790790307414914106093858868634329285205417149685270682748367152458577\", \"price\":\"0.35\", \"size\":\"57\", \"side\":\"BUY\", \"hash\":\"f22c7294ada657bc3b83537c6aefd96ddcdef369\", \"best_bid\":\"0.35\", \"best_ask\":\"0.36\"}, {\"asset_id\":\"107603864457683460275633293642179940881969192120168665300712204232021063124301\", \"price\":\"0.65\", \"size\":\"57\", \"side\":\"SELL\", \"hash\":\"55d8e1095250dde8fb54fb172aea147962c65f77\", \"best_bid\":\"0.64\", \"best_ask\":\"0.65\"}], \"timestamp\":\"1785211833938\", \"event_type\":\"price_change\"}","received_at":"2026-07-28T04:10:34.128484Z","schema_version":"clob-market-ws.price_change.v1","sequence":null,"server_hash":null,"server_timestamp":"1785211833938","session_id":"2d607381e3054cee91998cdf45a4231c","source":"clob_market_ws"},"received_at":"2026-07-28T04:10:34.128484Z","record_id":"a6a0ec5e90dfe6305db6c55a5ad1db0e9fb96087163edc5b5e42fab590eabd3b","schema_fingerprint":"4aa3821a28b0b7c2400bc59aba4bcc0a76e971dadd19610d3ad38c768e124dc7","schema_version":"edge-lab-recorder.raw.v1","sequence":null,"source":"clob_market_ws"}
{"event_at":"2026-07-28T04:10:33.938000Z","event_fingerprint":"29e54d5e5051b731300b77fe6066fbec3c852ef44469c605cb795530149fdf85","payload":{"connection_id":"f6725804f86a4c4eb588e4d5ed7db029","event_at":"2026-07-28T04:10:33.938000Z","event_type":"price_change","frame_hash":"76033030bdd2900478e474336a5d704a1e4287e17d74f6992b1f8fa2a5c00ad0","frame_index":0,"kind":"data","monotonic_ns":313817209491666,"payload":{"event_type":"price_change","market":"0xd412ce774cfcf8dc9f71164aac78783978aac7b03871702a3b8a481bd9dc9688","price_changes":[{"asset_id":"96600821790790307414914106093858868634329285205417149685270682748367152458577","best_ask":"0.36","best_bid":"0.35","hash":"56da3df9de7ab65a4f4d647a1ef557960e1ac50d","price":"0.25","side":"BUY","size":"266.61"},{"asset_id":"107603864457683460275633293642179940881969192120168665300712204232021063124301","best_ask":"0.65","best_bid":"0.64","hash":"53a8c01aef5b9627ce147cafa59edd3ab4894f30","price":"0.75","side":"SELL","size":"266.61"}],"timestamp":"1785211833938"},"payload_hash":"731975d8c17732c748910a8052cb9d60bbdbc53f6f2f3898990f41dbd1d85529","raw_frame":"{\"market\":\"0xd412ce774cfcf8dc9f71164aac78783978aac7b03871702a3b8a481bd9dc9688\", \"price_changes\":[{\"asset_id\":\"96600821790790307414914106093858868634329285205417149685270682748367152458577\", \"price\":\"0.25\", \"size\":\"266.61\", \"side\":\"BUY\", \"hash\":\"56da3df9de7ab65a4f4d647a1ef557960e1ac50d\", \"best_bid\":\"0.35\", \"best_ask\":\"0.36\"}, {\"asset_id\":\"107603864457683460275633293642179940881969192120168665300712204232021063124301\", \"price\":\"0.75\", \"size\":\"266.61\", \"side\":\"SELL\", \"hash\":\"53a8c01aef5b9627ce147cafa59edd3ab4894f30\", \"best_bid\":\"0.64\", \"best_ask\":\"0.65\"}], \"timestamp\":\"1785211833938\", \"event_type\":\"price_change\"}","received_at":"2026-07-28T04:10:34.133269Z","schema_version":"clob-market-ws.price_change.v1","sequence":null,"server_hash":null,"server_timestamp":"1785211833938","session_id":"2d607381e3054cee91998cdf45a4231c","source":"clob_market_ws"},"received_at":"2026-07-28T04:10:34.133269Z","record_id":"fe9eec5f4584c64126c898e999f004e503bebdd2996fb3e12d97c9cc6de06576","schema_fingerprint":"4aa3821a28b0b7c2400bc59aba4bcc0a76e971dadd19610d3ad38c768e124dc7","schema_version":"edge-lab-recorder.raw.v1","sequence":null,"source":"clob_market_ws"}
{"event_at":"2026-07-28T04:10:33.940000Z","event_fingerprint":"0208a6296da67cd1cc2ac2204615e7daee1d6d586926572f0ab9162c5794bd0d","payload":{"connection_id":"f6725804f86a4c4eb588e4d5ed7db029","event_at":"2026-07-28T04:10:33.940000Z","event_type":"price_change","frame_hash":"f81e089b56ad7f0e127bb02ac3a98919e6571d86740d8959aae14ce49acf05c6","frame_index":0,"kind":"data","monotonic_ns":313817214116416,"payload":{"event_type":"price_change","market":"0xd412ce774cfcf8dc9f71164aac78783978aac7b03871702a3b8a481bd9dc9688","price_changes":[{"asset_id":"96600821790790307414914106093858868634329285205417149685270682748367152458577","best_ask":"0.36","best_bid":"0.35","hash":"513b16207844d1d20f34056d934a71b9e454282a","price":"0.23","side":"BUY","size":"129.89"},{"asset_id":"107603864457683460275633293642179940881969192120168665300712204232021063124301","best_ask":"0.65","best_bid":"0.64","hash":"fbeece41b54c8a82b6b892d903f06a30c90476a3","price":"0.77","side":"SELL","size":"129.89"}],"timestamp":"1785211833940"},"payload_hash":"bcfcfa67d4c4022106379c03c1844a455f7160dc2252a978a0e384f8bea5e21f","raw_frame":"{\"market\":\"0xd412ce774cfcf8dc9f71164aac78783978aac7b03871702a3b8a481bd9dc9688\", \"price_changes\":[{\"asset_id\":\"96600821790790307414914106093858868634329285205417149685270682748367152458577\", \"price\":\"0.23\", \"size\":\"129.89\", \"side\":\"BUY\", \"hash\":\"513b16207844d1d20f34056d934a71b9e454282a\", \"best_bid\":\"0.35\", \"best_ask\":\"0.36\"}, {\"asset_id\":\"107603864457683460275633293642179940881969192120168665300712204232021063124301\", \"price\":\"0.77\", \"size\":\"129.89\", \"side\":\"SELL\", \"hash\":\"fbeece41b54c8a82b6b892d903f06a30c90476a3\", \"best_bid\":\"0.64\", \"best_ask\":\"0.65\"}], \"timestamp\":\"1785211833940\", \"event_type\":\"price_change\"}","received_at":"2026-07-28T04:10:34.137895Z","schema_version":"clob-market-ws.price_change.v1","sequence":null,"server_hash":null,"server_timestamp":"1785211833940","session_id":"2d607381e3054cee91998cdf45a4231c","source":"clob_market_ws"},"received_at":"2026-07-28T04:10:34.137895Z","record_id":"708f229151bd6a16cbe0643844ce8215871e1df14412255aa0c4e9b502a0f02d","schema_fingerprint":"4aa3821a28b0b7c2400bc59aba4bcc0a76e971dadd19610d3ad38c768e124dc7","schema_version":"edge-lab-recorder.raw.v1","sequence":null,"source":"clob_market_ws"}
{"event_at":"2026-07-28T04:10:33.941000Z","event_fingerprint":"2ecd884e4304c8a7650ce42b827942d7b6443ff80aa74c8f85a581598b04cb21","payload":{"connection_id":"f6725804f86a4c4eb588e4d5ed7db029","event_at":"2026-07-28T04:10:33.941000Z","event_type":"price_change","frame_hash":"49f5fa2f6bca8729dc0c3876b0855520a97e199061e7861352dc5276928754bb","frame_index":0,"kind":"data","monotonic_ns":313817218591625,"payload":{"event_type":"price_change","market":"0xd412ce774cfcf8dc9f71164aac78783978aac7b03871702a3b8a481bd9dc9688","price_changes":[{"asset_id":"107603864457683460275633293642179940881969192120168665300712204232021063124301","best_ask":"0.65","best_bid":"0.64","hash":"c2da19e96e7d60d4a6ae5e62f37ecad59c107407","price":"0.4","side":"BUY","size":"61.5"},{"asset_id":"96600821790790307414914106093858868634329285205417149685270682748367152458577","best_ask":"0.36","best_bid":"0.35","hash":"e6361110c242d9655674831c1b10c803056eee85","price":"0.6","side":"SELL","size":"61.5"}],"timestamp":"1785211833941"},"payload_hash":"95a0cded9679859ea5115cd9134ef8e73e74120488aa943fc7a917daf76f143c","raw_frame":"{\"market\":\"0xd412ce774cfcf8dc9f71164aac78783978aac7b03871702a3b8a481bd9dc9688\", \"price_changes\":[{\"asset_id\":\"107603864457683460275633293642179940881969192120168665300712204232021063124301\", \"price\":\"0.4\", \"size\":\"61.5\", \"side\":\"BUY\", \"hash\":\"c2da19e96e7d60d4a6ae5e62f37ecad59c107407\", \"best_bid\":\"0.64\", \"best_ask\":\"0.65\"}, {\"asset_id\":\"96600821790790307414914106093858868634329285205417149685270682748367152458577\", \"price\":\"0.6\", \"size\":\"61.5\", \"side\":\"SELL\", \"hash\":\"e6361110c242d9655674831c1b10c803056eee85\", \"best_bid\":\"0.35\", \"best_ask\":\"0.36\"}], \"timestamp\":\"1785211833941\", \"event_type\":\"price_change\"}","received_at":"2026-07-28T04:10:34.142370Z","schema_version":"clob-market-ws.price_change.v1","sequence":null,"server_hash":null,"server_timestamp":"1785211833941","session_id":"2d607381e3054cee91998cdf45a4231c","source":"clob_market_ws"},"received_at":"2026-07-28T04:10:34.142370Z","record_id":"36154db9fe6aae37eb4fa7ccc372a8d104235d69ef2e7c2b907cae723601a28a","schema_fingerprint":"4aa3821a28b0b7c2400bc59aba4bcc0a76e971dadd19610d3ad38c768e124dc7","schema_version":"edge-lab-recorder.raw.v1","sequence":null,"source":"clob_market_ws"}
{"event_at":"2026-07-28T04:10:33.941000Z","event_fingerprint":"46e9067181f833c37054d6b6d2040af136e36e048fa720073906ce1e9f5adc1b","payload":{"connection_id":"f6725804f86a4c4eb588e4d5ed7db029","event_at":"2026-07-28T04:10:33.941000Z","event_type":"price_change","frame_hash":"8df7f12e64b511efc884ccca58b5085268400e2aa92bad2ffc34aa68915ff969","frame_index":0,"kind":"data","monotonic_ns":313817222428625,"payload":{"event_type":"price_change","market":"0xd412ce774cfcf8dc9f71164aac78783978aac7b03871702a3b8a481bd9dc9688","price_changes":[{"asset_id":"96600821790790307414914106093858868634329285205417149685270682748367152458577","best_ask":"0.36","best_bid":"0.35","hash":"501aff4dac2cdfbf455e9807f28f63a1be953d15","price":"0.37","side":"SELL","size":"68.2"},{"asset_id":"107603864457683460275633293642179940881969192120168665300712204232021063124301","best_ask":"0.65","best_bid":"0.64","hash":"3557faa14de28b1cfdae72faa0147675aea64512","price":"0.63","side":"BUY","size":"68.2"}],"timestamp":"1785211833941"},"payload_hash":"3ea00e21a3b6cf23bea7421a6feef5c2416db570ff472d9c1cde66c4f3e35919","raw_frame":"{\"market\":\"0xd412ce774cfcf8dc9f71164aac78783978aac7b03871702a3b8a481bd9dc9688\", \"price_changes\":[{\"asset_id\":\"96600821790790307414914106093858868634329285205417149685270682748367152458577\", \"price\":\"0.37\", \"size\":\"68.2\", \"side\":\"SELL\", \"hash\":\"501aff4dac2cdfbf455e9807f28f63a1be953d15\", \"best_bid\":\"0.35\", \"best_ask\":\"0.36\"}, {\"asset_id\":\"107603864457683460275633293642179940881969192120168665300712204232021063124301\", \"price\":\"0.63\", \"size\":\"68.2\", \"side\":\"BUY\", \"hash\":\"3557faa14de28b1cfdae72faa0147675aea64512\", \"best_bid\":\"0.64\", \"best_ask\":\"0.65\"}], \"timestamp\":\"1785211833941\", \"event_type\":\"price_change\"}","received_at":"2026-07-28T04:10:34.146206Z","schema_version":"clob-market-ws.price_change.v1","sequence":null,"server_hash":null,"server_timestamp":"1785211833941","session_id":"2d607381e3054cee91998cdf45a4231c","source":"clob_market_ws"},"received_at":"2026-07-28T04:10:34.146206Z","record_id":"c3d3114d532f9c35567f07281c5206a0b5f1f1bb5920354ab852d1c865aae745","schema_fingerprint":"4aa3821a28b0b7c2400bc59aba4bcc0a76e971dadd19610d3ad38c768e124dc7","schema_version":"edge-lab-recorder.raw.v1","sequence":null,"source":"clob_market_ws"}
{"event_at":"2026-07-28T04:10:33.942000Z","event_fingerprint":"8082eab68ace7da6372a795c730099b6c69db26eec89462c1ce5211c5a9051b4","payload":{"connection_id":"f6725804f86a4c4eb588e4d5ed7db029","event_at":"2026-07-28T04:10:33.942000Z","event_type":"price_change","frame_hash":"549ae69a271887cfc361d31de296f3248529ebf039edcc1da5bed15639273859","frame_index":0,"kind":"data","monotonic_ns":313817225982416,"payload":{"event_type":"price_change","market":"0xd412ce774cfcf8dc9f71164aac78783978aac7b03871702a3b8a481bd9dc9688","price_changes":[{"asset_id":"96600821790790307414914106093858868634329285205417149685270682748367152458577","best_ask":"0.36","best_bid":"0.35","hash":"6643040840ab5ff6c02e763a4400fc0a3713a6cd","price":"0.22","side":"BUY","size":"130.5"},{"asset_id":"107603864457683460275633293642179940881969192120168665300712204232021063124301","best_ask":"0.65","best_bid":"0.64","hash":"d17cc74d6510a6e65e4c96a3fc359eddf91d5558","price":"0.78","side":"SELL","size":"130.5"}],"timestamp":"1785211833942"},"payload_hash":"b1f54119182fb01a915ac8bb6aa3ef75c5c4db65a3f03ff8e8ec9469168047d7","raw_frame":"{\"market\":\"0xd412ce774cfcf8dc9f71164aac78783978aac7b03871702a3b8a481bd9dc9688\", \"price_changes\":[{\"asset_id\":\"96600821790790307414914106093858868634329285205417149685270682748367152458577\", \"price\":\"0.22\", \"size\":\"130.5\", \"side\":\"BUY\", \"hash\":\"6643040840ab5ff6c02e763a4400fc0a3713a6cd\", \"best_bid\":\"0.35\", \"best_ask\":\"0.36\"}, {\"asset_id\":\"107603864457683460275633293642179940881969192120168665300712204232021063124301\", \"price\":\"0.78\", \"size\":\"130.5\", \"side\":\"SELL\", \"hash\":\"d17cc74d6510a6e65e4c96a3fc359eddf91d5558\", \"best_bid\":\"0.64\", \"best_ask\":\"0.65\"}], \"timestamp\":\"1785211833942\", \"event_type\":\"price_change\"}","received_at":"2026-07-28T04:10:34.149760Z","schema_version":"clob-market-ws.price_change.v1","sequence":null,"server_hash":null,"server_timestamp":"1785211833942","session_id":"2d607381e3054cee91998cdf45a4231c","source":"clob_market_ws"},"received_at":"2026-07-28T04:10:34.149760Z","record_id":"c279ae14bf6f1321119f0d99c68c8ac6960eef7b552812682d07664323a2b804","schema_fingerprint":"4aa3821a28b0b7c2400bc59aba4bcc0a76e971dadd19610d3ad38c768e124dc7","schema_version":"edge-lab-recorder.raw.v1","sequence":null,"source":"clob_market_ws"}
{"event_at":"2026-07-28T04:10:33.942000Z","event_fingerprint":"a9bf4fc341139ec0dbcce3198d6c769af9f3f1548a807eaacf8727399700071d","payload":{"connection_id":"f6725804f86a4c4eb588e4d5ed7db029","event_at":"2026-07-28T04:10:33.942000Z","event_type":"price_change","frame_hash":"ccd3bccba236570aaaf62cf1099e79943b21629f4a1c9e637ee9f5aa64ff20b1","frame_index":0,"kind":"data","monotonic_ns":313817230453000,"payload":{"event_type":"price_change","market":"0xd412ce774cfcf8dc9f71164aac78783978aac7b03871702a3b8a481bd9dc9688","price_changes":[{"asset_id":"96600821790790307414914106093858868634329285205417149685270682748367152458577","best_ask":"0.36","best_bid":"0.35","hash":"cf8e9a3159bcd0142cef59090bdfb7907dbd1bd9","price":"0.22","side":"BUY","size":"143.5"},{"asset_id":"107603864457683460275633293642179940881969192120168665300712204232021063124301","best_ask":"0.65","best_bid":"0.64","hash":"a723926447ecb37fa55c6640f966e1d0c5641eb7","price":"0.78","side":"SELL","size":"143.5"}],"timestamp":"1785211833942"},"payload_hash":"9c2dfbff59e0a81f27dca6f0ac834ed9dff75e502964eb1ac9129df47ac8580c","raw_frame":"{\"market\":\"0xd412ce774cfcf8dc9f71164aac78783978aac7b03871702a3b8a481bd9dc9688\", \"price_changes\":[{\"asset_id\":\"96600821790790307414914106093858868634329285205417149685270682748367152458577\", \"price\":\"0.22\", \"size\":\"143.5\", \"side\":\"BUY\", \"hash\":\"cf8e9a3159bcd0142cef59090bdfb7907dbd1bd9\", \"best_bid\":\"0.35\", \"best_ask\":\"0.36\"}, {\"asset_id\":\"107603864457683460275633293642179940881969192120168665300712204232021063124301\", \"price\":\"0.78\", \"size\":\"143.5\", \"side\":\"SELL\", \"hash\":\"a723926447ecb37fa55c6640f966e1d0c5641eb7\", \"best_bid\":\"0.64\", \"best_ask\":\"0.65\"}], \"timestamp\":\"1785211833942\", \"event_type\":\"price_change\"}","received_at":"2026-07-28T04:10:34.154229Z","schema_version":"clob-market-ws.price_change.v1","sequence":null,"server_hash":null,"server_timestamp":"1785211833942","session_id":"2d607381e3054cee91998cdf45a4231c","source":"clob_market_ws"},"received_at":"2026-07-28T04:10:34.154229Z","record_id":"881a450f73129c742c58b4863329c35294ccfb55d9c77c6dad0ddd132eb9127f","schema_fingerprint":"4aa3821a28b0b7c2400bc59aba4bcc0a76e971dadd19610d3ad38c768e124dc7","schema_version":"edge-lab-recorder.raw.v1","sequence":null,"source":"clob_market_ws"}
{"event_at":"2026-07-28T04:10:33.943000Z","event_fingerprint":"ce44a895857085869005172dcd5da48967828c44d6b25149214c60e117eecea4","payload":{"connection_id":"f6725804f86a4c4eb588e4d5ed7db029","event_at":"2026-07-28T04:10:33.943000Z","event_type":"price_change","frame_hash":"f064566547eb0396e72237b9b021ab41c1c5213f30fe131327a7214dbc524b7c","frame_index":0,"kind":"data","monotonic_ns":313817234624000,"payload":{"event_type":"price_change","market":"0xd412ce774cfcf8dc9f71164aac78783978aac7b03871702a3b8a481bd9dc9688","price_changes":[{"asset_id":"107603864457683460275633293642179940881969192120168665300712204232021063124301","best_ask":"0.65","best_bid":"0.64","hash":"e9b7ce21950090c500fb00cbef82c55aa6d9e0e4","price":"0.28","side":"BUY","size":"50.9"},{"asset_id":"96600821790790307414914106093858868634329285205417149685270682748367152458577","best_ask":"0.36","best_bid":"0.35","hash":"3d7e0aa16fda61ad5b21f2ed5934a27604f4896f","price":"0.72","side":"SELL","size":"50.9"}],"timestamp":"1785211833943"},"payload_hash":"1a08960c3e0da78d9aa9cdf152de36f2bd9900d85e5be124e600f07215a49941","raw_frame":"{\"market\":\"0xd412ce774cfcf8dc9f71164aac78783978aac7b03871702a3b8a481bd9dc9688\", \"price_changes\":[{\"asset_id\":\"107603864457683460275633293642179940881969192120168665300712204232021063124301\", \"price\":\"0.28\", \"size\":\"50.9\", \"side\":\"BUY\", \"hash\":\"e9b7ce21950090c500fb00cbef82c55aa6d9e0e4\", \"best_bid\":\"0.64\", \"best_ask\":\"0.65\"}, {\"asset_id\":\"96600821790790307414914106093858868634329285205417149685270682748367152458577\", \"price\":\"0.72\", \"size\":\"50.9\", \"side\":\"SELL\", \"hash\":\"3d7e0aa16fda61ad5b21f2ed5934a27604f4896f\", \"best_bid\":\"0.35\", \"best_ask\":\"0.36\"}], \"timestamp\":\"1785211833943\", \"event_type\":\"price_change\"}","received_at":"2026-07-28T04:10:34.158396Z","schema_version":"clob-market-ws.price_change.v1","sequence":null,"server_hash":null,"server_timestamp":"1785211833943","session_id":"2d607381e3054cee91998cdf45a4231c","source":"clob_market_ws"},"received_at":"2026-07-28T04:10:34.158396Z","record_id":"c50e23cb2d96a815817ec7e1a3de5e714199c897aa473da54661942c380c5944","schema_fingerprint":"4aa3821a28b0b7c2400bc59aba4bcc0a76e971dadd19610d3ad38c768e124dc7","schema_version":"edge-lab-recorder.raw.v1","sequence":null,"source":"clob_market_ws"}
{"event_at":"2026-07-28T04:10:33.943000Z","event_fingerprint":"a224a9e646c71da97574533cdccf2b49498e9ae02a21765bc420f018fb6cd539","payload":{"connection_id":"f6725804f86a4c4eb588e4d5ed7db029","event_at":"2026-07-28T04:10:33.943000Z","event_type":"price_change","frame_hash":"7081311b934ac34d39b196b16e118835b46c71594b1e0425cd510137de0f4e17","frame_index":0,"kind":"data","monotonic_ns":313817240017458,"payload":{"event_type":"price_change","market":"0xd412ce774cfcf8dc9f71164aac78783978aac7b03871702a3b8a481bd9dc9688","price_changes":[{"asset_id":"96600821790790307414914106093858868634329285205417149685270682748367152458577","best_ask":"0.36","best_bid":"0.35","hash":"37f882af7262ddcc6d40cb9f24cc3528297f525e","price":"0.37","side":"SELL","size":"50.2"},{"asset_id":"107603864457683460275633293642179940881969192120168665300712204232021063124301","best_ask":"0.65","best_bid":"0.64","hash":"34cd477ae55f93ef9fef20021bdb88c7cebb0a2a","price":"0.63","side":"BUY","size":"50.2"}],"timestamp":"1785211833943"},"payload_hash":"5fe278fd07a144200599aedb203be76741719a5a46b6b1e01afdfda2a9661fee","raw_frame":"{\"market\":\"0xd412ce774cfcf8dc9f71164aac78783978aac7b03871702a3b8a481bd9dc9688\", \"price_changes\":[{\"asset_id\":\"96600821790790307414914106093858868634329285205417149685270682748367152458577\", \"price\":\"0.37\", \"size\":\"50.2\", \"side\":\"SELL\", \"hash\":\"37f882af7262ddcc6d40cb9f24cc3528297f525e\", \"best_bid\":\"0.35\", \"best_ask\":\"0.36\"}, {\"asset_id\":\"107603864457683460275633293642179940881969192120168665300712204232021063124301\", \"price\":\"0.63\", \"size\":\"50.2\", \"side\":\"BUY\", \"hash\":\"34cd477ae55f93ef9fef20021bdb88c7cebb0a2a\", \"best_bid\":\"0.64\", \"best_ask\":\"0.65\"}], \"timestamp\":\"1785211833943\", \"event_type\":\"price_change\"}","received_at":"2026-07-28T04:10:34.163796Z","schema_version":"clob-market-ws.price_change.v1","sequence":null,"server_hash":null,"server_timestamp":"1785211833943","session_id":"2d607381e3054cee91998cdf45a4231c","source":"clob_market_ws"},"received_at":"2026-07-28T04:10:34.163796Z","record_id":"6b6b2e55c159d5ad90c87ba8540d103b67cd3bf1e651d192d78f3fd33afc74e9","schema_fingerprint":"4aa3821a28b0b7c2400bc59aba4bcc0a76e971dadd19610d3ad38c768e124dc7","schema_version":"edge-lab-recorder.raw.v1","sequence":null,"source":"clob_market_ws"}
{"event_at":"2026-07-28T04:10:33.943000Z","event_fingerprint":"998e7a3b60a2b03783e9f24d2ebf5cdd9416050ffbccbc286fa128b2e221ba3b","payload":{"connection_id":"f6725804f86a4c4eb588e4d5ed7db029","event_at":"2026-07-28T04:10:33.943000Z","event_type":"price_change","frame_hash":"c2cfb8d7a66ac1e1476a4233f3eb3585e37dcea394bcb5d4276f1532e6ca5f3c","frame_index":0,"kind":"data","monotonic_ns":313817246526000,"payload":{"event_type":"price_change","market":"0xd412ce774cfcf8dc9f71164aac78783978aac7b03871702a3b8a481bd9dc9688","price_changes":[{"asset_id":"107603864457683460275633293642179940881969192120168665300712204232021063124301","best_ask":"0.65","best_bid":"0.64","hash":"e9f6aabf80c2c280fcb16c20f465cc7c5f40c149","price":"0.64","side":"BUY","size":"150.03"},{"asset_id":"96600821790790307414914106093858868634329285205417149685270682748367152458577","best_ask":"0.36","best_bid":"0.35","hash":"3c5eaf88c10cf425518c430f8c48f5f4d24f4d89","price":"0.36","side":"SELL","size":"150.03"}],"timestamp":"1785211833943"},"payload_hash":"a01a75e3cedbcd858a0872574a6a17b71b7be74817954d1258dbf552276a70f5","raw_frame":"{\"market\":\"0xd412ce774cfcf8dc9f71164aac78783978aac7b03871702a3b8a481bd9dc9688\", \"price_changes\":[{\"asset_id\":\"107603864457683460275633293642179940881969192120168665300712204232021063124301\", \"price\":\"0.64\", \"size\":\"150.03\", \"side\":\"BUY\", \"hash\":\"e9f6aabf80c2c280fcb16c20f465cc7c5f40c149\", \"best_bid\":\"0.64\", \"best_ask\":\"0.65\"}, {\"asset_id\":\"96600821790790307414914106093858868634329285205417149685270682748367152458577\", \"price\":\"0.36\", \"size\":\"150.03\", \"side\":\"SELL\", \"hash\":\"3c5eaf88c10cf425518c430f8c48f5f4d24f4d89\", \"best_bid\":\"0.35\", \"best_ask\":\"0.36\"}], \"timestamp\":\"1785211833943\", \"event_type\":\"price_change\"}","received_at":"2026-07-28T04:10:34.170304Z","schema_version":"clob-market-ws.price_change.v1","sequence":null,"server_hash":null,"server_timestamp":"1785211833943","session_id":"2d607381e3054cee91998cdf45a4231c","source":"clob_market_ws"},"received_at":"2026-07-28T04:10:34.170304Z","record_id":"3cb9354f95924d8760eadc4ab247fe7f9deb6021c358f038fad24359e43e1374","schema_fingerprint":"4aa3821a28b0b7c2400bc59aba4bcc0a76e971dadd19610d3ad38c768e124dc7","schema_version":"edge-lab-recorder.raw.v1","sequence":null,"source":"clob_market_ws"}
{"event_at":"2026-07-28T04:10:33.944000Z","event_fingerprint":"24a5d66955e63e15bc002ab496a191c00b464fec62e500f42d438d14f34e0e01","payload":{"connection_id":"f6725804f86a4c4eb588e4d5ed7db029","event_at":"2026-07-28T04:10:33.944000Z","event_type":"price_change","frame_hash":"a667c4594cef5f2bf1fd2b02ecef8bdc9e0f945a383110e7bc5c729a888907ab","frame_index":0,"kind":"data","monotonic_ns":313817252207541,"payload":{"event_type":"price_change","market":"0xd412ce774cfcf8dc9f71164aac78783978aac7b03871702a3b8a481bd9dc9688","price_changes":[{"asset_id":"107603864457683460275633293642179940881969192120168665300712204232021063124301","best_ask":"0.65","best_bid":"0.64","hash":"be3daf199a60d333f49b0de8bab51c919b720f93","price":"0.63","side":"BUY","size":"44.2"},{"asset_id":"96600821790790307414914106093858868634329285205417149685270682748367152458577","best_ask":"0.36","best_bid":"0.35","hash":"bc06a9ffdf171e89ac17234b5d4ba1f7870035ca","price":"0.37","side":"SELL","size":"44.2"}],"timestamp":"1785211833944"},"payload_hash":"02da0ae23d70086c62437e483b5f6e947f0ec87f9731315bc3a8cf0dee2616fa","raw_frame":"{\"market\":\"0xd412ce774cfcf8dc9f71164aac78783978aac7b03871702a3b8a481bd9dc9688\", \"price_changes\":[{\"asset_id\":\"107603864457683460275633293642179940881969192120168665300712204232021063124301\", \"price\":\"0.63\", \"size\":\"44.2\", \"side\":\"BUY\", \"hash\":\"be3daf199a60d333f49b0de8bab51c919b720f93\", \"best_bid\":\"0.64\", \"best_ask\":\"0.65\"}, {\"asset_id\":\"96600821790790307414914106093858868634329285205417149685270682748367152458577\", \"price\":\"0.37\", \"size\":\"44.2\", \"side\":\"SELL\", \"hash\":\"bc06a9ffdf171e89ac17234b5d4ba1f7870035ca\", \"best_bid\":\"0.35\", \"best_ask\":\"0.36\"}], \"timestamp\":\"1785211833944\", \"event_type\":\"price_change\"}","received_at":"2026-07-28T04:10:34.175985Z","schema_version":"clob-market-ws.price_change.v1","sequence":null,"server_hash":null,"server_timestamp":"1785211833944","session_id":"2d607381e3054cee91998cdf45a4231c","source":"clob_market_ws"},"received_at":"2026-07-28T04:10:34.175985Z","record_id":"f8dc96597b4fa95e3fdbc944ef179650dd8f19ba5af72a84b8e116b40c15f29c","schema_fingerprint":"4aa3821a28b0b7c2400bc59aba4bcc0a76e971dadd19610d3ad38c768e124dc7","schema_version":"edge-lab-recorder.raw.v1","sequence":null,"source":"clob_market_ws"}
{"event_at":"2026-07-28T04:10:33.944000Z","event_fingerprint":"b40f0148fcea2d85cfe534b038a547f47fde00a27b7eb39c241678639064e311","payload":{"connection_id":"f6725804f86a4c4eb588e4d5ed7db029","event_at":"2026-07-28T04:10:33.944000Z","event_type":"price_change","frame_hash":"f0270726b3f2f0ea545a100d99fd27448fb6300c7f3ce7a12a21ca6abd405ee3","frame_index":0,"kind":"data","monotonic_ns":313817257610958,"payload":{"event_type":"price_change","market":"0xd412ce774cfcf8dc9f71164aac78783978aac7b03871702a3b8a481bd9dc9688","price_changes":[{"asset_id":"96600821790790307414914106093858868634329285205417149685270682748367152458577","best_ask":"0.36","best_bid":"0.35","hash":"a329cf8c0ee84752e707281d76f7995afee91d7f","price":"0.25","side":"BUY","size":"272.61"},{"asset_id":"107603864457683460275633293642179940881969192120168665300712204232021063124301","best_ask":"0.65","best_bid":"0.64","hash":"eb6f8948d73585a967ed19f427c1ef32642dd689","price":"0.75","side":"SELL","size":"272.61"}],"timestamp":"1785211833944"},"payload_hash":"9a21359ff0c8edd5da6c687f014b57b876f977277b3ee01e1d3b7fc446824c01","raw_frame":"{\"market\":\"0xd412ce774cfcf8dc9f71164aac78783978aac7b03871702a3b8a481bd9dc9688\", \"price_changes\":[{\"asset_id\":\"96600821790790307414914106093858868634329285205417149685270682748367152458577\", \"price\":\"0.25\", \"size\":\"272.61\", \"side\":\"BUY\", \"hash\":\"a329cf8c0ee84752e707281d76f7995afee91d7f\", \"best_bid\":\"0.35\", \"best_ask\":\"0.36\"}, {\"asset_id\":\"107603864457683460275633293642179940881969192120168665300712204232021063124301\", \"price\":\"0.75\", \"size\":\"272.61\", \"side\":\"SELL\", \"hash\":\"eb6f8948d73585a967ed19f427c1ef32642dd689\", \"best_bid\":\"0.64\", \"best_ask\":\"0.65\"}], \"timestamp\":\"1785211833944\", \"event_type\":\"price_change\"}","received_at":"2026-07-28T04:10:34.181386Z","schema_version":"clob-market-ws.price_change.v1","sequence":null,"server_hash":null,"server_timestamp":"1785211833944","session_id":"2d607381e3054cee91998cdf45a4231c","source":"clob_market_ws"},"received_at":"2026-07-28T04:10:34.181386Z","record_id":"7e594ccb257305208896394381183589c6c220ad58e1e2cafd0ec024690d999e","schema_fingerprint":"4aa3821a28b0b7c2400bc59aba4bcc0a76e971dadd19610d3ad38c768e124dc7","schema_version":"edge-lab-recorder.raw.v1","sequence":null,"source":"clob_market_ws"}
{"event_at":"2026-07-28T04:10:33.945000Z","event_fingerprint":"292eee27c6b7fdc7a92bb6018a0072a359197727c0b1855e3e72f1f66f6c0112","payload":{"connection_id":"f6725804f86a4c4eb588e4d5ed7db029","event_at":"2026-07-28T04:10:33.945000Z","event_type":"price_change","frame_hash":"fb63dfc57a8e32184ac53030e3383875fa7333f919d3638e81432a4e09cf3e26","frame_index":0,"kind":"data","monotonic_ns":313817261501833,"payload":{"event_type":"price_change","market":"0xd412ce774cfcf8dc9f71164aac78783978aac7b03871702a3b8a481bd9dc9688","price_changes":[{"asset_id":"96600821790790307414914106093858868634329285205417149685270682748367152458577","best_ask":"0.36","best_bid":"0.35","hash":"a28de78354a44596f567a9adfde85e0b2afa6a73","price":"0.21","side":"BUY","size":"184.1"},{"asset_id":"107603864457683460275633293642179940881969192120168665300712204232021063124301","best_ask":"0.65","best_bid":"0.64","hash":"a79e1a559b3ec7851a892579b340372810494bd6","price":"0.79","side":"SELL","size":"184.1"}],"timestamp":"1785211833945"},"payload_hash":"3eeaebfb770414a6dd2b6da25409f52a81fae253aba06baf7c8a3908992f4c76","raw_frame":"{\"market\":\"0xd412ce774cfcf8dc9f71164aac78783978aac7b03871702a3b8a481bd9dc9688\", \"price_changes\":[{\"asset_id\":\"96600821790790307414914106093858868634329285205417149685270682748367152458577\", \"price\":\"0.21\", \"size\":\"184.1\", \"side\":\"BUY\", \"hash\":\"a28de78354a44596f567a9adfde85e0b2afa6a73\", \"best_bid\":\"0.35\", \"best_ask\":\"0.36\"}, {\"asset_id\":\"107603864457683460275633293642179940881969192120168665300712204232021063124301\", \"price\":\"0.79\", \"size\":\"184.1\", \"side\":\"SELL\", \"hash\":\"a79e1a559b3ec7851a892579b340372810494bd6\", \"best_bid\":\"0.64\", \"best_ask\":\"0.65\"}], \"timestamp\":\"1785211833945\", \"event_type\":\"price_change\"}","received_at":"2026-07-28T04:10:34.185276Z","schema_version":"clob-market-ws.price_change.v1","sequence":null,"server_hash":null,"server_timestamp":"1785211833945","session_id":"2d607381e3054cee91998cdf45a4231c","source":"clob_market_ws"},"received_at":"2026-07-28T04:10:34.185276Z","record_id":"c259506f8431aa916bd5fe4a900037fa427595fd5d43cac9c2895c8ec9c77481","schema_fingerprint":"4aa3821a28b0b7c2400bc59aba4bcc0a76e971dadd19610d3ad38c768e124dc7","schema_version":"edge-lab-recorder.raw.v1","sequence":null,"source":"clob_market_ws"}
{"event_at":"2026-07-28T04:10:33.946000Z","event_fingerprint":"44b15be73e71d29e3c9f49bfdad0ca13d60aafb3d892ad2dba04de7977a8fb08","payload":{"connection_id":"f6725804f86a4c4eb588e4d5ed7db029","event_at":"2026-07-28T04:10:33.946000Z","event_type":"price_change","frame_hash":"5387624ea596c883fc60cd8f34b70d2584380d256f3a53fb2d32567de0c2c320","frame_index":0,"kind":"data","monotonic_ns":313817266825875,"payload":{"event_type":"price_change","market":"0xd412ce774cfcf8dc9f71164aac78783978aac7b03871702a3b8a481bd9dc9688","price_changes":[{"asset_id":"107603864457683460275633293642179940881969192120168665300712204232021063124301","best_ask":"0.65","best_bid":"0.64","hash":"bd9f86148dc1cc8058273ee7230381b5e0ab0337","price":"0.57","side":"BUY","size":"41"},{"asset_id":"96600821790790307414914106093858868634329285205417149685270682748367152458577","best_ask":"0.36","best_bid":"0.35","hash":"04015145fb1314ca213882450605d3e71f0baca1","price":"0.43","side":"SELL","size":"41"}],"timestamp":"1785211833946"},"payload_hash":"8d8a01dd187820f2eeaf509a77d2da3698ad4cfff7a85348b5894ddf8ad2abfa","raw_frame":"{\"market\":\"0xd412ce774cfcf8dc9f71164aac78783978aac7b03871702a3b8a481bd9dc9688\", \"price_changes\":[{\"asset_id\":\"107603864457683460275633293642179940881969192120168665300712204232021063124301\", \"price\":\"0.57\", \"size\":\"41\", \"side\":\"BUY\", \"hash\":\"bd9f86148dc1cc8058273ee7230381b5e0ab0337\", \"best_bid\":\"0.64\", \"best_ask\":\"0.65\"}, {\"asset_id\":\"96600821790790307414914106093858868634329285205417149685270682748367152458577\", \"price\":\"0.43\", \"size\":\"41\", \"side\":\"SELL\", \"hash\":\"04015145fb1314ca213882450605d3e71f0baca1\", \"best_bid\":\"0.35\", \"best_ask\":\"0.36\"}], \"timestamp\":\"1785211833946\", \"event_type\":\"price_change\"}","received_at":"2026-07-28T04:10:34.190601Z","schema_version":"clob-market-ws.price_change.v1","sequence":null,"server_hash":null,"server_timestamp":"1785211833946","session_id":"2d607381e3054cee91998cdf45a4231c","source":"clob_market_ws"},"received_at":"2026-07-28T04:10:34.190601Z","record_id":"941bc8b459a968f81d72b330fdc05fbf055522ef0f6284c43e15b4f07e2b0254","schema_fingerprint":"4aa3821a28b0b7c2400bc59aba4bcc0a76e971dadd19610d3ad38c768e124dc7","schema_version":"edge-lab-recorder.raw.v1","sequence":null,"source":"clob_market_ws"}
{"event_at":"2026-07-28T04:10:33.947000Z","event_fingerprint":"e069662a06cee8e31b029af5e0d96d947bd53962407e29c8dc821d85c4e89155","payload":{"connection_id":"f6725804f86a4c4eb588e4d5ed7db029","event_at":"2026-07-28T04:10:33.947000Z","event_type":"price_change","frame_hash":"e0dc8f3d35cdb234963692f6b8604d3540c50f3287019b197d90f397a655b17b","frame_index":0,"kind":"data","monotonic_ns":313817286868208,"payload":{"event_type":"price_change","market":"0xd412ce774cfcf8dc9f71164aac78783978aac7b03871702a3b8a481bd9dc9688","price_changes":[{"asset_id":"96600821790790307414914106093858868634329285205417149685270682748367152458577","best_ask":"0.36","best_bid":"0.35","hash":"7dba16a8fd63077b3de4c0f6fe61c3a1afa29816","price":"0.32","side":"BUY","size":"96"},{"asset_id":"107603864457683460275633293642179940881969192120168665300712204232021063124301","best_ask":"0.65","best_bid":"0.64","hash":"e200dc173ec314660936a71812e758d00a7c85c9","price":"0.68","side":"SELL","size":"96"}],"timestamp":"1785211833947"},"payload_hash":"6b45488621797bebc166f6784fc945d5bd3cfa56e7f1084cd63f4e3e2e0e2a7b","raw_frame":"{\"market\":\"0xd412ce774cfcf8dc9f71164aac78783978aac7b03871702a3b8a481bd9dc9688\", \"price_changes\":[{\"asset_id\":\"96600821790790307414914106093858868634329285205417149685270682748367152458577\", \"price\":\"0.32\", \"size\":\"96\", \"side\":\"BUY\", \"hash\":\"7dba16a8fd63077b3de4c0f6fe61c3a1afa29816\", \"best_bid\":\"0.35\", \"best_ask\":\"0.36\"}, {\"asset_id\":\"107603864457683460275633293642179940881969192120168665300712204232021063124301\", \"price\":\"0.68\", \"size\":\"96\", \"side\":\"SELL\", \"hash\":\"e200dc173ec314660936a71812e758d00a7c85c9\", \"best_bid\":\"0.64\", \"best_ask\":\"0.65\"}], \"timestamp\":\"1785211833947\", \"event_type\":\"price_change\"}","received_at":"2026-07-28T04:10:34.210643Z","schema_version":"clob-market-ws.price_change.v1","sequence":null,"server_hash":null,"server_timestamp":"1785211833947","session_id":"2d607381e3054cee91998cdf45a4231c","source":"clob_market_ws"},"received_at":"2026-07-28T04:10:34.210643Z","record_id":"bce1521b83d3600e72d0d81717dae8647cd138ebb401f52e2b819ed6e5bf84ec","schema_fingerprint":"4aa3821a28b0b7c2400bc59aba4bcc0a76e971dadd19610d3ad38c768e124dc7","schema_version":"edge-lab-recorder.raw.v1","sequence":null,"source":"clob_market_ws"}
{"event_at":"2026-07-28T04:10:33.947000Z","event_fingerprint":"3bdb841c766d82d50ab8b3c5f94c8d3adc4546d3214c34e79f7798b2e6524e0c","payload":{"connection_id":"f6725804f86a4c4eb588e4d5ed7db029","event_at":"2026-07-28T04:10:33.947000Z","event_type":"price_change","frame_hash":"74d197b1130185e61ffc684e234837a60c2e4991b136695eb529d8287ae1cf7c","frame_index":0,"kind":"data","monotonic_ns":313817291234666,"payload":{"event_type":"price_change","market":"0xd412ce774cfcf8dc9f71164aac78783978aac7b03871702a3b8a481bd9dc9688","price_changes":[{"asset_id":"96600821790790307414914106093858868634329285205417149685270682748367152458577","best_ask":"0.36","best_bid":"0.35","hash":"58ffc8aa09204fa56a52ddd3fc88874ef11b392c","price":"0.31","side":"BUY","size":"107"},{"asset_id":"107603864457683460275633293642179940881969192120168665300712204232021063124301","best_ask":"0.65","best_bid":"0.64","hash":"18cd9239c4bb91a17d88b52940a2368ebfaafac5","price":"0.69","side":"SELL","size":"107"}],"timestamp":"1785211833947"},"payload_hash":"acf81c2608438640aad6f7a9ff3927f08981d6fddf50cfa92b623a15df64a63d","raw_frame":"{\"market\":\"0xd412ce774cfcf8dc9f71164aac78783978aac7b03871702a3b8a481bd9dc9688\", \"price_changes\":[{\"asset_id\":\"96600821790790307414914106093858868634329285205417149685270682748367152458577\", \"price\":\"0.31\", \"size\":\"107\", \"side\":\"BUY\", \"hash\":\"58ffc8aa09204fa56a52ddd3fc88874ef11b392c\", \"best_bid\":\"0.35\", \"best_ask\":\"0.36\"}, {\"asset_id\":\"107603864457683460275633293642179940881969192120168665300712204232021063124301\", \"price\":\"0.69\", \"size\":\"107\", \"side\":\"SELL\", \"hash\":\"18cd9239c4bb91a17d88b52940a2368ebfaafac5\", \"best_bid\":\"0.64\", \"best_ask\":\"0.65\"}], \"timestamp\":\"1785211833947\", \"event_type\":\"price_change\"}","received_at":"2026-07-28T04:10:34.215012Z","schema_version":"clob-market-ws.price_change.v1","sequence":null,"server_hash":null,"server_timestamp":"1785211833947","session_id":"2d607381e3054cee91998cdf45a4231c","source":"clob_market_ws"},"received_at":"2026-07-28T04:10:34.215012Z","record_id":"0e5de7dd2dcfa888846413a9279ef0d16d36bca91babadbd5f0622f29c5305d7","schema_fingerprint":"4aa3821a28b0b7c2400bc59aba4bcc0a76e971dadd19610d3ad38c768e124dc7","schema_version":"edge-lab-recorder.raw.v1","sequence":null,"source":"clob_market_ws"}
{"event_at":"2026-07-28T04:10:33.947000Z","event_fingerprint":"ff9ef3aae010b70e3584c60fdf7d8db8994586127f940cd2405e17330b115a63","payload":{"connection_id":"f6725804f86a4c4eb588e4d5ed7db029","event_at":"2026-07-28T04:10:33.947000Z","event_type":"price_change","frame_hash":"225058005af249349b88756cdcb43f0a6433544f3834156732847327c4948f1d","frame_index":0,"kind":"data","monotonic_ns":313817296205958,"payload":{"event_type":"price_change","market":"0xd412ce774cfcf8dc9f71164aac78783978aac7b03871702a3b8a481bd9dc9688","price_changes":[{"asset_id":"96600821790790307414914106093858868634329285205417149685270682748367152458577","best_ask":"0.36","best_bid":"0.35","hash":"74d469bd1b4be9e826b56a67e2908ddb8477a2c3","price":"0.3","side":"BUY","size":"239"},{"asset_id":"107603864457683460275633293642179940881969192120168665300712204232021063124301","best_ask":"0.65","best_bid":"0.64","hash":"fc27dc7d485df60e0cdd910e17e09d8a212a981c","price":"0.7","side":"SELL","size":"239"}],"timestamp":"1785211833947"},"payload_hash":"0fb5c04f7bd349eed56fcc59a406f662c65598acdcde87d0d4a3ca81ed141c84","raw_frame":"{\"market\":\"0xd412ce774cfcf8dc9f71164aac78783978aac7b03871702a3b8a481bd9dc9688\", \"price_changes\":[{\"asset_id\":\"96600821790790307414914106093858868634329285205417149685270682748367152458577\", \"price\":\"0.3\", \"size\":\"239\", \"side\":\"BUY\", \"hash\":\"74d469bd1b4be9e826b56a67e2908ddb8477a2c3\", \"best_bid\":\"0.35\", \"best_ask\":\"0.36\"}, {\"asset_id\":\"107603864457683460275633293642179940881969192120168665300712204232021063124301\", \"price\":\"0.7\", \"size\":\"239\", \"side\":\"SELL\", \"hash\":\"fc27dc7d485df60e0cdd910e17e09d8a212a981c\", \"best_bid\":\"0.64\", \"best_ask\":\"0.65\"}], \"timestamp\":\"1785211833947\", \"event_type\":\"price_change\"}","received_at":"2026-07-28T04:10:34.219984Z","schema_version":"clob-market-ws.price_change.v1","sequence":null,"server_hash":null,"server_timestamp":"1785211833947","session_id":"2d607381e3054cee91998cdf45a4231c","source":"clob_market_ws"},"received_at":"2026-07-28T04:10:34.219984Z","record_id":"c1a806f0498f5d98726e86ef88765fe9dcaedd21a424235a63062e2f592c635b","schema_fingerprint":"4aa3821a28b0b7c2400bc59aba4bcc0a76e971dadd19610d3ad38c768e124dc7","schema_version":"edge-lab-recorder.raw.v1","sequence":null,"source":"clob_market_ws"}
{"event_at":"2026-07-28T04:10:33.947000Z","event_fingerprint":"8d569aa51c7d285ce8967ac1923c08f0cf163ff72039ba7613bee923b169797f","payload":{"connection_id":"f6725804f86a4c4eb588e4d5ed7db029","event_at":"2026-07-28T04:10:33.947000Z","event_type":"price_change","frame_hash":"8f7a5030bc24f3e6b9acb0a0f304de635967a1880c60208be44ee094bfb550d8","frame_index":0,"kind":"data","monotonic_ns":313817302070916,"payload":{"event_type":"price_change","market":"0xd412ce774cfcf8dc9f71164aac78783978aac7b03871702a3b8a481bd9dc9688","price_changes":[{"asset_id":"96600821790790307414914106093858868634329285205417149685270682748367152458577","best_ask":"0.36","best_bid":"0.35","hash":"ee43b9d56f0b51cf859d8c0baabfb8a0be754acf","price":"0.49","side":"SELL","size":"35.97"},{"asset_id":"107603864457683460275633293642179940881969192120168665300712204232021063124301","best_ask":"0.65","best_bid":"0.64","hash":"52ba6f30ae1e781741f1d08bc6e828214c859d24","price":"0.51","side":"BUY","size":"35.97"}],"timestamp":"1785211833947"},"payload_hash":"60d1f9e0448c352c3d41e1356512330e379bfe130ec9b8bd8aa6701f0ee7460b","raw_frame":"{\"market\":\"0xd412ce774cfcf8dc9f71164aac78783978aac7b03871702a3b8a481bd9dc9688\", \"price_changes\":[{\"asset_id\":\"96600821790790307414914106093858868634329285205417149685270682748367152458577\", \"price\":\"0.49\", \"size\":\"35.97\", \"side\":\"SELL\", \"hash\":\"ee43b9d56f0b51cf859d8c0baabfb8a0be754acf\", \"best_bid\":\"0.35\", \"best_ask\":\"0.36\"}, {\"asset_id\":\"107603864457683460275633293642179940881969192120168665300712204232021063124301\", \"price\":\"0.51\", \"size\":\"35.97\", \"side\":\"BUY\", \"hash\":\"52ba6f30ae1e781741f1d08bc6e828214c859d24\", \"best_bid\":\"0.64\", \"best_ask\":\"0.65\"}], \"timestamp\":\"1785211833947\", \"event_type\":\"price_change\"}","received_at":"2026-07-28T04:10:34.225847Z","schema_version":"clob-market-ws.price_change.v1","sequence":null,"server_hash":null,"server_timestamp":"1785211833947","session_id":"2d607381e3054cee91998cdf45a4231c","source":"clob_market_ws"},"received_at":"2026-07-28T04:10:34.225847Z","record_id":"f43398ac6256a8ce4dd41e8e0d56bfba3f909d7c81fb0fbf4220049288d22cb6","schema_fingerprint":"4aa3821a28b0b7c2400bc59aba4bcc0a76e971dadd19610d3ad38c768e124dc7","schema_version":"edge-lab-recorder.raw.v1","sequence":null,"source":"clob_market_ws"}
{"event_at":"2026-07-28T04:10:33.948000Z","event_fingerprint":"c113583d02a2ca520d1ccd9029ad46453a3876772688a780c1b6226a65ef92a2","payload":{"connection_id":"f6725804f86a4c4eb588e4d5ed7db029","event_at":"2026-07-28T04:10:33.948000Z","event_type":"price_change","frame_hash":"b42defece17bbef4887f5e785f509b7a71555a3cfe8fccc2e8f33022b96e1080","frame_index":0,"kind":"data","monotonic_ns":313817307088541,"payload":{"event_type":"price_change","market":"0xd412ce774cfcf8dc9f71164aac78783978aac7b03871702a3b8a481bd9dc9688","price_changes":[{"asset_id":"107603864457683460275633293642179940881969192120168665300712204232021063124301","best_ask":"0.65","best_bid":"0.64","hash":"0ee01f851338ef1644838ee02b8213c7985aaa14","price":"0.56","side":"BUY","size":"41"},{"asset_id":"96600821790790307414914106093858868634329285205417149685270682748367152458577","best_ask":"0.36","best_bid":"0.35","hash":"947caaf73792a1d861f80f93339983931bcc41eb","price":"0.44","side":"SELL","size":"41"}],"timestamp":"1785211833948"},"payload_hash":"d15e546fa3751c7fec7028b12941364140d910cf5303c3353fcc01c67b7d21f4","raw_frame":"{\"market\":\"0xd412ce774cfcf8dc9f71164aac78783978aac7b03871702a3b8a481bd9dc9688\", \"price_changes\":[{\"asset_id\":\"107603864457683460275633293642179940881969192120168665300712204232021063124301\", \"price\":\"0.56\", \"size\":\"41\", \"side\":\"BUY\", \"hash\":\"0ee01f851338ef1644838ee02b8213c7985aaa14\", \"best_bid\":\"0.64\", \"best_ask\":\"0.65\"}, {\"asset_id\":\"96600821790790307414914106093858868634329285205417149685270682748367152458577\", \"price\":\"0.44\", \"size\":\"41\", \"side\":\"SELL\", \"hash\":\"947caaf73792a1d861f80f93339983931bcc41eb\", \"best_bid\":\"0.35\", \"best_ask\":\"0.36\"}], \"timestamp\":\"1785211833948\", \"event_type\":\"price_change\"}","received_at":"2026-07-28T04:10:34.230862Z","schema_version":"clob-market-ws.price_change.v1","sequence":null,"server_hash":null,"server_timestamp":"1785211833948","session_id":"2d607381e3054cee91998cdf45a4231c","source":"clob_market_ws"},"received_at":"2026-07-28T04:10:34.230862Z","record_id":"f4a0a9d9b30067bc284ef1aa89146a4654679a90251839c37b91e85064a47aa2","schema_fingerprint":"4aa3821a28b0b7c2400bc59aba4bcc0a76e971dadd19610d3ad38c768e124dc7","schema_version":"edge-lab-recorder.raw.v1","sequence":null,"source":"clob_market_ws"}
{"event_at":"2026-07-28T04:10:33.948000Z","event_fingerprint":"65310014614af63e566f0ae019a5c622ff7a7e52b8a53f93589261a22df5cc81","payload":{"connection_id":"f6725804f86a4c4eb588e4d5ed7db029","event_at":"2026-07-28T04:10:33.948000Z","event_type":"price_change","frame_hash":"675df50292145d8e93b4b85c20560c5778f927ea80bae72346f420df10db2765","frame_index":0,"kind":"data","monotonic_ns":313817311171416,"payload":{"event_type":"price_change","market":"0xd412ce774cfcf8dc9f71164aac78783978aac7b03871702a3b8a481bd9dc9688","price_changes":[{"asset_id":"96600821790790307414914106093858868634329285205417149685270682748367152458577","best_ask":"0.36","best_bid":"0.35","hash":"5a6a3aeca3cecc99378d41bd1a65896317261f0a","price":"0.28","side":"BUY","size":"227.49"},{"asset_id":"107603864457683460275633293642179940881969192120168665300712204232021063124301","best_ask":"0.65","best_bid":"0.64","hash":"113ae7962966368a7e127dc22f9bf8bc976f3279","price":"0.72","side":"SELL","size":"227.49"}],"timestamp":"1785211833948"},"payload_hash":"0de175e5b6f0a2df86dc438fcf7c3854bbb161a05c6dd26107318ebb4622d6a5","raw_frame":"{\"market\":\"0xd412ce774cfcf8dc9f71164aac78783978aac7b03871702a3b8a481bd9dc9688\", \"price_changes\":[{\"asset_id\":\"96600821790790307414914106093858868634329285205417149685270682748367152458577\", \"price\":\"0.28\", \"size\":\"227.49\", \"side\":\"BUY\", \"hash\":\"5a6a3aeca3cecc99378d41bd1a65896317261f0a\", \"best_bid\":\"0.35\", \"best_ask\":\"0.36\"}, {\"asset_id\":\"107603864457683460275633293642179940881969192120168665300712204232021063124301\", \"price\":\"0.72\", \"size\":\"227.49\", \"side\":\"SELL\", \"hash\":\"113ae7962966368a7e127dc22f9bf8bc976f3279\", \"best_bid\":\"0.64\", \"best_ask\":\"0.65\"}], \"timestamp\":\"1785211833948\", \"event_type\":\"price_change\"}","received_at":"2026-07-28T04:10:34.234944Z","schema_version":"clob-market-ws.price_change.v1","sequence":null,"server_hash":null,"server_timestamp":"1785211833948","session_id":"2d607381e3054cee91998cdf45a4231c","source":"clob_market_ws"},"received_at":"2026-07-28T04:10:34.234944Z","record_id":"bf7eaae42013d987e427b7f1ef4d84e44888ae209f125b6490fe5faf1a2f831a","schema_fingerprint":"4aa3821a28b0b7c2400bc59aba4bcc0a76e971dadd19610d3ad38c768e124dc7","schema_version":"edge-lab-recorder.raw.v1","sequence":null,"source":"clob_market_ws"}
{"event_at":"2026-07-28T04:10:33.948000Z","event_fingerprint":"a97d444f90c69d118815a1a9071e53216d784e30ded7523a9e83e00da5edfd0b","payload":{"connection_id":"f6725804f86a4c4eb588e4d5ed7db029","event_at":"2026-07-28T04:10:33.948000Z","event_type":"price_change","frame_hash":"344d5d7ab8d3c824bce64810566d5d81a55b0c840efd9cf1c78afdb9333526c8","frame_index":0,"kind":"data","monotonic_ns":313817316845583,"payload":{"event_type":"price_change","market":"0xd412ce774cfcf8dc9f71164aac78783978aac7b03871702a3b8a481bd9dc9688","price_changes":[{"asset_id":"96600821790790307414914106093858868634329285205417149685270682748367152458577","best_ask":"0.36","best_bid":"0.35","hash":"d45ae8147a008f73b1351475910495c72890dd2c","price":"0.15","side":"BUY","size":"95"},{"asset_id":"107603864457683460275633293642179940881969192120168665300712204232021063124301","best_ask":"0.65","best_bid":"0.64","hash":"af3d0ac1b36451f72cdc94fa956a9aeaf68f4386","price":"0.85","side":"SELL","size":"95"}],"timestamp":"1785211833948"},"payload_hash":"c77ff68e12990d1fa5815da4ba5f6f848e673aac7a6d3859ae377404a4108259","raw_frame":"{\"market\":\"0xd412ce774cfcf8dc9f71164aac78783978aac7b03871702a3b8a481bd9dc9688\", \"price_changes\":[{\"asset_id\":\"96600821790790307414914106093858868634329285205417149685270682748367152458577\", \"price\":\"0.15\", \"size\":\"95\", \"side\":\"BUY\", \"hash\":\"d45ae8147a008f73b1351475910495c72890dd2c\", \"best_bid\":\"0.35\", \"best_ask\":\"0.36\"}, {\"asset_id\":\"107603864457683460275633293642179940881969192120168665300712204232021063124301\", \"price\":\"0.85\", \"size\":\"95\", \"side\":\"SELL\", \"hash\":\"af3d0ac1b36451f72cdc94fa956a9aeaf68f4386\", \"best_bid\":\"0.64\", \"best_ask\":\"0.65\"}], \"timestamp\":\"1785211833948\", \"event_type\":\"price_change\"}","received_at":"2026-07-28T04:10:34.240622Z","schema_version":"clob-market-ws.price_change.v1","sequence":null,"server_hash":null,"server_timestamp":"1785211833948","session_id":"2d607381e3054cee91998cdf45a4231c","source":"clob_market_ws"},"received_at":"2026-07-28T04:10:34.240622Z","record_id":"1d7fb4cef8f4a57595ac358e2b4a6f5b86dcaa99255010f62a0d3e0ee5c54418","schema_fingerprint":"4aa3821a28b0b7c2400bc59aba4bcc0a76e971dadd19610d3ad38c768e124dc7","schema_version":"edge-lab-recorder.raw.v1","sequence":null,"source":"clob_market_ws"}
{"event_at":"2026-07-28T04:10:33.948000Z","event_fingerprint":"9cc4ea24a5d8789ed2a3ee97e83aa5c5ef0e3842b14d5426aab01332b520ddeb","payload":{"connection_id":"f6725804f86a4c4eb588e4d5ed7db029","event_at":"2026-07-28T04:10:33.948000Z","event_type":"price_change","frame_hash":"ad9f6e70d7ee8d2b367a16280b9fc681f97457d0cfe83d0d477ae223fe7f632f","frame_index":0,"kind":"data","monotonic_ns":313817321788458,"payload":{"event_type":"price_change","market":"0xd412ce774cfcf8dc9f71164aac78783978aac7b03871702a3b8a481bd9dc9688","price_changes":[{"asset_id":"96600821790790307414914106093858868634329285205417149685270682748367152458577","best_ask":"0.36","best_bid":"0.35","hash":"0f23913bd16e30f0ae4504334a2658cef8021c01","price":"0.32","side":"BUY","size":"90"},{"asset_id":"107603864457683460275633293642179940881969192120168665300712204232021063124301","best_ask":"0.65","best_bid":"0.64","hash":"ca87f80a8e166d3b9230373ab269c53a3ac4a2fc","price":"0.68","side":"SELL","size":"90"}],"timestamp":"1785211833948"},"payload_hash":"2e43597a9fdd4cda696e77c9c6309a1240664f33ce63d9bb60fd6e7ba9fd022c","raw_frame":"{\"market\":\"0xd412ce774cfcf8dc9f71164aac78783978aac7b03871702a3b8a481bd9dc9688\", \"price_changes\":[{\"asset_id\":\"96600821790790307414914106093858868634329285205417149685270682748367152458577\", \"price\":\"0.32\", \"size\":\"90\", \"side\":\"BUY\", \"hash\":\"0f23913bd16e30f0ae4504334a2658cef8021c01\", \"best_bid\":\"0.35\", \"best_ask\":\"0.36\"}, {\"asset_id\":\"107603864457683460275633293642179940881969192120168665300712204232021063124301\", \"price\":\"0.68\", \"size\":\"90\", \"side\":\"SELL\", \"hash\":\"ca87f80a8e166d3b9230373ab269c53a3ac4a2fc\", \"best_bid\":\"0.64\", \"best_ask\":\"0.65\"}], \"timestamp\":\"1785211833948\", \"event_type\":\"price_change\"}","received_at":"2026-07-28T04:10:34.245565Z","schema_version":"clob-market-ws.price_change.v1","sequence":null,"server_hash":null,"server_timestamp":"1785211833948","session_id":"2d607381e3054cee91998cdf45a4231c","source":"clob_market_ws"},"received_at":"2026-07-28T04:10:34.245565Z","record_id":"7c09c58709c7b314b06d7d9eede99c8d72365f37e6336560fad2081407dbdb7a","schema_fingerprint":"4aa3821a28b0b7c2400bc59aba4bcc0a76e971dadd19610d3ad38c768e124dc7","schema_version":"edge-lab-recorder.raw.v1","sequence":null,"source":"clob_market_ws"}
{"event_at":"2026-07-28T04:10:33.949000Z","event_fingerprint":"2d2c160ea6eb519a3f83010fb7a43fdb6523f65b05aea7db2623cd94d6fc687f","payload":{"connection_id":"f6725804f86a4c4eb588e4d5ed7db029","event_at":"2026-07-28T04:10:33.949000Z","event_type":"price_change","frame_hash":"9f8f17788c695a7f2498c168265dad51f055aa3fb595500098deee6a3efbc5b9","frame_index":0,"kind":"data","monotonic_ns":313817326963250,"payload":{"event_type":"price_change","market":"0xd412ce774cfcf8dc9f71164aac78783978aac7b03871702a3b8a481bd9dc9688","price_changes":[{"asset_id":"96600821790790307414914106093858868634329285205417149685270682748367152458577","best_ask":"0.36","best_bid":"0.35","hash":"20d11d2135cd4c3021dc79ce62f3b71090f35bcd","price":"0.17","side":"BUY","size":"55.3"},{"asset_id":"107603864457683460275633293642179940881969192120168665300712204232021063124301","best_ask":"0.65","best_bid":"0.64","hash":"011f0ce3ae1d3c9f657eaefa91e5bc1cd3e677da","price":"0.83","side":"SELL","size":"55.3"}],"timestamp":"1785211833949"},"payload_hash":"3b280627effcb4789ec12a8648cd7040fac42c4764fba1bd09ef8be0e6b4bce7","raw_frame":"{\"market\":\"0xd412ce774cfcf8dc9f71164aac78783978aac7b03871702a3b8a481bd9dc9688\", \"price_changes\":[{\"asset_id\":\"96600821790790307414914106093858868634329285205417149685270682748367152458577\", \"price\":\"0.17\", \"size\":\"55.3\", \"side\":\"BUY\", \"hash\":\"20d11d2135cd4c3021dc79ce62f3b71090f35bcd\", \"best_bid\":\"0.35\", \"best_ask\":\"0.36\"}, {\"asset_id\":\"107603864457683460275633293642179940881969192120168665300712204232021063124301\", \"price\":\"0.83\", \"size\":\"55.3\", \"side\":\"SELL\", \"hash\":\"011f0ce3ae1d3c9f657eaefa91e5bc1cd3e677da\", \"best_bid\":\"0.64\", \"best_ask\":\"0.65\"}], \"timestamp\":\"1785211833949\", \"event_type\":\"price_change\"}","received_at":"2026-07-28T04:10:34.250733Z","schema_version":"clob-market-ws.price_change.v1","sequence":null,"server_hash":null,"server_timestamp":"1785211833949","session_id":"2d607381e3054cee91998cdf45a4231c","source":"clob_market_ws"},"received_at":"2026-07-28T04:10:34.250733Z","record_id":"246f1e8f5e96619185bba629acd10369cee57f1579e04385becf79e7263710e9","schema_fingerprint":"4aa3821a28b0b7c2400bc59aba4bcc0a76e971dadd19610d3ad38c768e124dc7","schema_version":"edge-lab-recorder.raw.v1","sequence":null,"source":"clob_market_ws"}
{"event_at":"2026-07-28T04:10:33.949000Z","event_fingerprint":"db020583e66e121464cf4f15f282760b06cf8d5fef7951ea964285a8370fc0eb","payload":{"connection_id":"f6725804f86a4c4eb588e4d5ed7db029","event_at":"2026-07-28T04:10:33.949000Z","event_type":"price_change","frame_hash":"6f38367399f402f00099479f26b9858dd2636f6d600e7d8e57b56b72fc0eac27","frame_index":0,"kind":"data","monotonic_ns":313817332201458,"payload":{"event_type":"price_change","market":"0xd412ce774cfcf8dc9f71164aac78783978aac7b03871702a3b8a481bd9dc9688","price_changes":[{"asset_id":"107603864457683460275633293642179940881969192120168665300712204232021063124301","best_ask":"0.65","best_bid":"0.64","hash":"e245c816be4a47ce2529d3ae82b1c76e13fc6c54","price":"0.64","side":"BUY","size":"174.03"},{"asset_id":"96600821790790307414914106093858868634329285205417149685270682748367152458577","best_ask":"0.36","best_bid":"0.35","hash":"16e85420b71b97a880ccba4249537fe7f830d87c","price":"0.36","side":"SELL","size":"174.03"}],"timestamp":"1785211833949"},"payload_hash":"d966a4414e48b9adce566c9e031985f0ce37402430403499f07594ccd0742185","raw_frame":"{\"market\":\"0xd412ce774cfcf8dc9f71164aac78783978aac7b03871702a3b8a481bd9dc9688\", \"price_changes\":[{\"asset_id\":\"107603864457683460275633293642179940881969192120168665300712204232021063124301\", \"price\":\"0.64\", \"size\":\"174.03\", \"side\":\"BUY\", \"hash\":\"e245c816be4a47ce2529d3ae82b1c76e13fc6c54\", \"best_bid\":\"0.64\", \"best_ask\":\"0.65\"}, {\"asset_id\":\"96600821790790307414914106093858868634329285205417149685270682748367152458577\", \"price\":\"0.36\", \"size\":\"174.03\", \"side\":\"SELL\", \"hash\":\"16e85420b71b97a880ccba4249537fe7f830d87c\", \"best_bid\":\"0.35\", \"best_ask\":\"0.36\"}], \"timestamp\":\"1785211833949\", \"event_type\":\"price_change\"}","received_at":"2026-07-28T04:10:34.255970Z","schema_version":"clob-market-ws.price_change.v1","sequence":null,"server_hash":null,"server_timestamp":"1785211833949","session_id":"2d607381e3054cee91998cdf45a4231c","source":"clob_market_ws"},"received_at":"2026-07-28T04:10:34.255970Z","record_id":"eac8aa1f2f5a912389ecfa6cf9be5334fcd993aab42e25b811d34db6b288208f","schema_fingerprint":"4aa3821a28b0b7c2400bc59aba4bcc0a76e971dadd19610d3ad38c768e124dc7","schema_version":"edge-lab-recorder.raw.v1","sequence":null,"source":"clob_market_ws"}
{"event_at":"2026-07-28T04:10:33.950000Z","event_fingerprint":"6091cde18bfec39061ceb67fa558aa56730481f536156eb0723b5fd973476684","payload":{"connection_id":"f6725804f86a4c4eb588e4d5ed7db029","event_at":"2026-07-28T04:10:33.950000Z","event_type":"price_change","frame_hash":"099a7829a4d20dbd3f0b7590be76e50c296f3ab3f440ef01e85a76b0945a10f7","frame_index":0,"kind":"data","monotonic_ns":313817338112875,"payload":{"event_type":"price_change","market":"0xd412ce774cfcf8dc9f71164aac78783978aac7b03871702a3b8a481bd9dc9688","price_changes":[{"asset_id":"96600821790790307414914106093858868634329285205417149685270682748367152458577","best_ask":"0.36","best_bid":"0.35","hash":"ad250a5ecb4b8b35bb9e42c74f55b6dac97001c2","price":"0.28","side":"BUY","size":"221.49"},{"asset_id":"107603864457683460275633293642179940881969192120168665300712204232021063124301","best_ask":"0.65","best_bid":"0.64","hash":"ae153b80cb9e0a620f9b547ccfbc0c13de6670f6","price":"0.72","side":"SELL","size":"221.49"}],"timestamp":"1785211833950"},"payload_hash":"3023b0d9f0599f84439f53eed165b1dd2a720f5b641d6c63002e33996be8c510","raw_frame":"{\"market\":\"0xd412ce774cfcf8dc9f71164aac78783978aac7b03871702a3b8a481bd9dc9688\", \"price_changes\":[{\"asset_id\":\"96600821790790307414914106093858868634329285205417149685270682748367152458577\", \"price\":\"0.28\", \"size\":\"221.49\", \"side\":\"BUY\", \"hash\":\"ad250a5ecb4b8b35bb9e42c74f55b6dac97001c2\", \"best_bid\":\"0.35\", \"best_ask\":\"0.36\"}, {\"asset_id\":\"107603864457683460275633293642179940881969192120168665300712204232021063124301\", \"price\":\"0.72\", \"size\":\"221.49\", \"side\":\"SELL\", \"hash\":\"ae153b80cb9e0a620f9b547ccfbc0c13de6670f6\", \"best_bid\":\"0.64\", \"best_ask\":\"0.65\"}], \"timestamp\":\"1785211833950\", \"event_type\":\"price_change\"}","received_at":"2026-07-28T04:10:34.261889Z","schema_version":"clob-market-ws.price_change.v1","sequence":null,"server_hash":null,"server_timestamp":"1785211833950","session_id":"2d607381e3054cee91998cdf45a4231c","source":"clob_market_ws"},"received_at":"2026-07-28T04:10:34.261889Z","record_id":"ace550fae4529e61b623a9f72a4cb132df874b723fd6e8b6f0daf071e705b94d","schema_fingerprint":"4aa3821a28b0b7c2400bc59aba4bcc0a76e971dadd19610d3ad38c768e124dc7","schema_version":"edge-lab-recorder.raw.v1","sequence":null,"source":"clob_market_ws"}
{"event_at":"2026-07-28T04:10:33.950000Z","event_fingerprint":"42c86c453571947ed1da504887300ffef208c13612178f4b2f035e94a275ae10","payload":{"connection_id":"f6725804f86a4c4eb588e4d5ed7db029","event_at":"2026-07-28T04:10:33.950000Z","event_type":"price_change","frame_hash":"22c8253c7feb705f43096cbc93118fcebea3f31421e27e31dc2c89c7a3f97014","frame_index":0,"kind":"data","monotonic_ns":313817344631416,"payload":{"event_type":"price_change","market":"0xd412ce774cfcf8dc9f71164aac78783978aac7b03871702a3b8a481bd9dc9688","price_changes":[{"asset_id":"107603864457683460275633293642179940881969192120168665300712204232021063124301","best_ask":"0.65","best_bid":"0.64","hash":"067813bfadd33294b6831b641ff67e19e082ab40","price":"0.58","side":"BUY","size":"95.6"},{"asset_id":"96600821790790307414914106093858868634329285205417149685270682748367152458577","best_ask":"0.36","best_bid":"0.35","hash":"1c36b1f9de292868a7846641a3eeb9a3ed8b1223","price":"0.42","side":"SELL","size":"95.6"}],"timestamp":"1785211833950"},"payload_hash":"d037e7cad61f4bf849f2ca4688c3593669c60008233c2f504b11a5078daeed8b","raw_frame":"{\"market\":\"0xd412ce774cfcf8dc9f71164aac78783978aac7b03871702a3b8a481bd9dc9688\", \"price_changes\":[{\"asset_id\":\"107603864457683460275633293642179940881969192120168665300712204232021063124301\", \"price\":\"0.58\", \"size\":\"95.6\", \"side\":\"BUY\", \"hash\":\"067813bfadd33294b6831b641ff67e19e082ab40\", \"best_bid\":\"0.64\", \"best_ask\":\"0.65\"}, {\"asset_id\":\"96600821790790307414914106093858868634329285205417149685270682748367152458577\", \"price\":\"0.42\", \"size\":\"95.6\", \"side\":\"SELL\", \"hash\":\"1c36b1f9de292868a7846641a3eeb9a3ed8b1223\", \"best_bid\":\"0.35\", \"best_ask\":\"0.36\"}], \"timestamp\":\"1785211833950\", \"event_type\":\"price_change\"}","received_at":"2026-07-28T04:10:34.268409Z","schema_version":"clob-market-ws.price_change.v1","sequence":null,"server_hash":null,"server_timestamp":"1785211833950","session_id":"2d607381e3054cee91998cdf45a4231c","source":"clob_market_ws"},"received_at":"2026-07-28T04:10:34.268409Z","record_id":"6734199a92ef83c5e0ade0d75a4144f1f5b2b92debce0beefd6edafa71a5633c","schema_fingerprint":"4aa3821a28b0b7c2400bc59aba4bcc0a76e971dadd19610d3ad38c768e124dc7","schema_version":"edge-lab-recorder.raw.v1","sequence":null,"source":"clob_market_ws"}
{"event_at":"2026-07-28T04:10:33.951000Z","event_fingerprint":"5cfbc1b5476ac5c54329e6e5ab7a97f9f67908894cc81947606c7b225db72b09","payload":{"connection_id":"f6725804f86a4c4eb588e4d5ed7db029","event_at":"2026-07-28T04:10:33.951000Z","event_type":"price_change","frame_hash":"f09c4edd48432d74cbcbb82ad694730ced98f4f246d641ed1ddbc697fe53b84e","frame_index":0,"kind":"data","monotonic_ns":313817349549083,"payload":{"event_type":"price_change","market":"0xd412ce774cfcf8dc9f71164aac78783978aac7b03871702a3b8a481bd9dc9688","price_changes":[{"asset_id":"107603864457683460275633293642179940881969192120168665300712204232021063124301","best_ask":"0.65","best_bid":"0.64","hash":"d736009d5e097675007b0684be6674f39cf1f027","price":"0.64","side":"BUY","size":"205.03"},{"asset_id":"96600821790790307414914106093858868634329285205417149685270682748367152458577","best_ask":"0.36","best_bid":"0.35","hash":"876a293539fabf274c5a334256edccbddedf0764","price":"0.36","side":"SELL","size":"205.03"}],"timestamp":"1785211833951"},"payload_hash":"b53d3b1f7b10fe839fb735e0959b0dc50ca5af2e98f82a0d039f301e8167e5d5","raw_frame":"{\"market\":\"0xd412ce774cfcf8dc9f71164aac78783978aac7b03871702a3b8a481bd9dc9688\", \"price_changes\":[{\"asset_id\":\"107603864457683460275633293642179940881969192120168665300712204232021063124301\", \"price\":\"0.64\", \"size\":\"205.03\", \"side\":\"BUY\", \"hash\":\"d736009d5e097675007b0684be6674f39cf1f027\", \"best_bid\":\"0.64\", \"best_ask\":\"0.65\"}, {\"asset_id\":\"96600821790790307414914106093858868634329285205417149685270682748367152458577\", \"price\":\"0.36\", \"size\":\"205.03\", \"side\":\"SELL\", \"hash\":\"876a293539fabf274c5a334256edccbddedf0764\", \"best_bid\":\"0.35\", \"best_ask\":\"0.36\"}], \"timestamp\":\"1785211833951\", \"event_type\":\"price_change\"}","received_at":"2026-07-28T04:10:34.273327Z","schema_version":"clob-market-ws.price_change.v1","sequence":null,"server_hash":null,"server_timestamp":"1785211833951","session_id":"2d607381e3054cee91998cdf45a4231c","source":"clob_market_ws"},"received_at":"2026-07-28T04:10:34.273327Z","record_id":"fd97b06ce432c3d63e92c7f8fa980b4317b83583025b9a38e69c14f04d0e7a3e","schema_fingerprint":"4aa3821a28b0b7c2400bc59aba4bcc0a76e971dadd19610d3ad38c768e124dc7","schema_version":"edge-lab-recorder.raw.v1","sequence":null,"source":"clob_market_ws"}
{"event_at":"2026-07-28T04:10:33.951000Z","event_fingerprint":"3ac7e920da6888e9dbb5c9e583c91211fe5bbbd4bad8ec5a368175193f16ca54","payload":{"connection_id":"f6725804f86a4c4eb588e4d5ed7db029","event_at":"2026-07-28T04:10:33.951000Z","event_type":"price_change","frame_hash":"ac77b1efe4cd01932a48a46cefc004b0288ed29010bda5b7cb1c8a3bb16c4823","frame_index":0,"kind":"data","monotonic_ns":313817354717291,"payload":{"event_type":"price_change","market":"0xd412ce774cfcf8dc9f71164aac78783978aac7b03871702a3b8a481bd9dc9688","price_changes":[{"asset_id":"96600821790790307414914106093858868634329285205417149685270682748367152458577","best_ask":"0.36","best_bid":"0.35","hash":"f03a2a77692b42f48e998a82f9533575511fee76","price":"0.23","side":"BUY","size":"142.89"},{"asset_id":"107603864457683460275633293642179940881969192120168665300712204232021063124301","best_ask":"0.65","best_bid":"0.64","hash":"e866d18254c126e1d5d8f84a4256b59199fb2df4","price":"0.77","side":"SELL","size":"142.89"}],"timestamp":"1785211833951"},"payload_hash":"e92871dff9c4e07c114a8023ad5e05451c15962d0895b42439ad92caa8e8bb47","raw_frame":"{\"market\":\"0xd412ce774cfcf8dc9f71164aac78783978aac7b03871702a3b8a481bd9dc9688\", \"price_changes\":[{\"asset_id\":\"96600821790790307414914106093858868634329285205417149685270682748367152458577\", \"price\":\"0.23\", \"size\":\"142.89\", \"side\":\"BUY\", \"hash\":\"f03a2a77692b42f48e998a82f9533575511fee76\", \"best_bid\":\"0.35\", \"best_ask\":\"0.36\"}, {\"asset_id\":\"107603864457683460275633293642179940881969192120168665300712204232021063124301\", \"price\":\"0.77\", \"size\":\"142.89\", \"side\":\"SELL\", \"hash\":\"e866d18254c126e1d5d8f84a4256b59199fb2df4\", \"best_bid\":\"0.64\", \"best_ask\":\"0.65\"}], \"timestamp\":\"1785211833951\", \"event_type\":\"price_change\"}","received_at":"2026-07-28T04:10:34.278494Z","schema_version":"clob-market-ws.price_change.v1","sequence":null,"server_hash":null,"server_timestamp":"1785211833951","session_id":"2d607381e3054cee91998cdf45a4231c","source":"clob_market_ws"},"received_at":"2026-07-28T04:10:34.278494Z","record_id":"1d272d64d05843c3b590e97e5b920665109afa1c23a24c38a31d99db3ac86322","schema_fingerprint":"4aa3821a28b0b7c2400bc59aba4bcc0a76e971dadd19610d3ad38c768e124dc7","schema_version":"edge-lab-recorder.raw.v1","sequence":null,"source":"clob_market_ws"}
{"event_at":"2026-07-28T04:10:33.952000Z","event_fingerprint":"85bdb586ab9638ce3bfda2b5bbd34cacdd388acfa630ee0e69ceb12065eb5a2b","payload":{"connection_id":"f6725804f86a4c4eb588e4d5ed7db029","event_at":"2026-07-28T04:10:33.952000Z","event_type":"price_change","frame_hash":"8f6f10b5831225d865d06b890c1f5ae85f3d68782581172068a02cf4d0aefad1","frame_index":0,"kind":"data","monotonic_ns":313817369307791,"payload":{"event_type":"price_change","market":"0xd412ce774cfcf8dc9f71164aac78783978aac7b03871702a3b8a481bd9dc9688","price_changes":[{"asset_id":"96600821790790307414914106093858868634329285205417149685270682748367152458577","best_ask":"0.36","best_bid":"0.35","hash":"668b7292b1e0c9491687df06a984e55c6e15b171","price":"0.37","side":"SELL","size":"69.2"},{"asset_id":"107603864457683460275633293642179940881969192120168665300712204232021063124301","best_ask":"0.65","best_bid":"0.64","hash":"4ed8d4766acc061120c742211ee4fc6446f24227","price":"0.63","side":"BUY","size":"69.2"}],"timestamp":"1785211833952"},"payload_hash":"d8fc47d748e5cf6824efe9e2ba072d6e0cdddf6d34dfce5324949dd4f04aca9d","raw_frame":"{\"market\":\"0xd412ce774cfcf8dc9f71164aac78783978aac7b03871702a3b8a481bd9dc9688\", \"price_changes\":[{\"asset_id\":\"96600821790790307414914106093858868634329285205417149685270682748367152458577\", \"price\":\"0.37\", \"size\":\"69.2\", \"side\":\"SELL\", \"hash\":\"668b7292b1e0c9491687df06a984e55c6e15b171\", \"best_bid\":\"0.35\", \"best_ask\":\"0.36\"}, {\"asset_id\":\"107603864457683460275633293642179940881969192120168665300712204232021063124301\", \"price\":\"0.63\", \"size\":\"69.2\", \"side\":\"BUY\", \"hash\":\"4ed8d4766acc061120c742211ee4fc6446f24227\", \"best_bid\":\"0.64\", \"best_ask\":\"0.65\"}], \"timestamp\":\"1785211833952\", \"event_type\":\"price_change\"}","received_at":"2026-07-28T04:10:34.293084Z","schema_version":"clob-market-ws.price_change.v1","sequence":null,"server_hash":null,"server_timestamp":"1785211833952","session_id":"2d607381e3054cee91998cdf45a4231c","source":"clob_market_ws"},"received_at":"2026-07-28T04:10:34.293084Z","record_id":"b00fe70d591d546ad6132c9412b2ecde4f608cbfa2d263e5c7f72c165ae261b4","schema_fingerprint":"4aa3821a28b0b7c2400bc59aba4bcc0a76e971dadd19610d3ad38c768e124dc7","schema_version":"edge-lab-recorder.raw.v1","sequence":null,"source":"clob_market_ws"}
{"event_at":"2026-07-28T04:10:33.953000Z","event_fingerprint":"b23105a3eb8f45151fbd4afa19315447fc88b9c51387b690d6818198381bf380","payload":{"connection_id":"f6725804f86a4c4eb588e4d5ed7db029","event_at":"2026-07-28T04:10:33.953000Z","event_type":"price_change","frame_hash":"1c3b6f053fdd1d95434041c2861788818bbf31a4aca90d9ed85659eb96e878a3","frame_index":0,"kind":"data","monotonic_ns":313817374165333,"payload":{"event_type":"price_change","market":"0xd412ce774cfcf8dc9f71164aac78783978aac7b03871702a3b8a481bd9dc9688","price_changes":[{"asset_id":"96600821790790307414914106093858868634329285205417149685270682748367152458577","best_ask":"0.36","best_bid":"0.35","hash":"70ae37b59222cd9b525bcb347c24c125eb7999c9","price":"0.24","side":"BUY","size":"88.39"},{"asset_id":"107603864457683460275633293642179940881969192120168665300712204232021063124301","best_ask":"0.65","best_bid":"0.64","hash":"79447f44102bc663e4731f9accfe35bf4a2fe60c","price":"0.76","side":"SELL","size":"88.39"}],"timestamp":"1785211833953"},"payload_hash":"bbc615cbd6f03d81baf1dc1c0359ee59b1d0d6eeeafd91ae686f7d13cf99074d","raw_frame":"{\"market\":\"0xd412ce774cfcf8dc9f71164aac78783978aac7b03871702a3b8a481bd9dc9688\", \"price_changes\":[{\"asset_id\":\"96600821790790307414914106093858868634329285205417149685270682748367152458577\", \"price\":\"0.24\", \"size\":\"88.39\", \"side\":\"BUY\", \"hash\":\"70ae37b59222cd9b525bcb347c24c125eb7999c9\", \"best_bid\":\"0.35\", \"best_ask\":\"0.36\"}, {\"asset_id\":\"107603864457683460275633293642179940881969192120168665300712204232021063124301\", \"price\":\"0.76\", \"size\":\"88.39\", \"side\":\"SELL\", \"hash\":\"79447f44102bc663e4731f9accfe35bf4a2fe60c\", \"best_bid\":\"0.64\", \"best_ask\":\"0.65\"}], \"timestamp\":\"1785211833953\", \"event_type\":\"price_change\"}","received_at":"2026-07-28T04:10:34.297942Z","schema_version":"clob-market-ws.price_change.v1","sequence":null,"server_hash":null,"server_timestamp":"1785211833953","session_id":"2d607381e3054cee91998cdf45a4231c","source":"clob_market_ws"},"received_at":"2026-07-28T04:10:34.297942Z","record_id":"90b14b30fb6a5f7944cb6b1120d93a5fb7202ee057745c918bcf733faf0827da","schema_fingerprint":"4aa3821a28b0b7c2400bc59aba4bcc0a76e971dadd19610d3ad38c768e124dc7","schema_version":"edge-lab-recorder.raw.v1","sequence":null,"source":"clob_market_ws"}
{"event_at":"2026-07-28T04:10:33.954000Z","event_fingerprint":"81963399913220ec84c17417b85b178d92df3720c68519b6cfa5b444ba570bf4","payload":{"connection_id":"f6725804f86a4c4eb588e4d5ed7db029","event_at":"2026-07-28T04:10:33.954000Z","event_type":"price_change","frame_hash":"3472cdc21ffb1618db826004a2f8c18ebbb58e234910ae75aff3ca141209f32e","frame_index":0,"kind":"data","monotonic_ns":313817378057000,"payload":{"event_type":"price_change","market":"0xd412ce774cfcf8dc9f71164aac78783978aac7b03871702a3b8a481bd9dc9688","price_changes":[{"asset_id":"96600821790790307414914106093858868634329285205417149685270682748367152458577","best_ask":"0.36","best_bid":"0.35","hash":"890b395e45a783f0a8d5bf215c42a82097a17d55","price":"0.26","side":"BUY","size":"217.25"},{"asset_id":"107603864457683460275633293642179940881969192120168665300712204232021063124301","best_ask":"0.65","best_bid":"0.64","hash":"550d3d0a2e9f485da06d8e7a5f026c8524c2c2dc","price":"0.74","side":"SELL","size":"217.25"}],"timestamp":"1785211833954"},"payload_hash":"caa6c35df43ac73b1a62307d6b8b467bd957938cb09e0df60a8a4e9dfbc851d9","raw_frame":"{\"market\":\"0xd412ce774cfcf8dc9f71164aac78783978aac7b03871702a3b8a481bd9dc9688\", \"price_changes\":[{\"asset_id\":\"96600821790790307414914106093858868634329285205417149685270682748367152458577\", \"price\":\"0.26\", \"size\":\"217.25\", \"side\":\"BUY\", \"hash\":\"890b395e45a783f0a8d5bf215c42a82097a17d55\", \"best_bid\":\"0.35\", \"best_ask\":\"0.36\"}, {\"asset_id\":\"107603864457683460275633293642179940881969192120168665300712204232021063124301\", \"price\":\"0.74\", \"size\":\"217.25\", \"side\":\"SELL\", \"hash\":\"550d3d0a2e9f485da06d8e7a5f026c8524c2c2dc\", \"best_bid\":\"0.64\", \"best_ask\":\"0.65\"}], \"timestamp\":\"1785211833954\", \"event_type\":\"price_change\"}","received_at":"2026-07-28T04:10:34.301836Z","schema_version":"clob-market-ws.price_change.v1","sequence":null,"server_hash":null,"server_timestamp":"1785211833954","session_id":"2d607381e3054cee91998cdf45a4231c","source":"clob_market_ws"},"received_at":"2026-07-28T04:10:34.301836Z","record_id":"99f4de6b5cba7f7c976eb0bdfaa574a75474f43ffcf721d3bd35f063bcd02e67","schema_fingerprint":"4aa3821a28b0b7c2400bc59aba4bcc0a76e971dadd19610d3ad38c768e124dc7","schema_version":"edge-lab-recorder.raw.v1","sequence":null,"source":"clob_market_ws"}
{"event_at":"2026-07-28T04:10:33.954000Z","event_fingerprint":"4d4a3925362b5f75281373bdc109fc1ee5ea329a3de5a939c54e08eabcaab606","payload":{"connection_id":"f6725804f86a4c4eb588e4d5ed7db029","event_at":"2026-07-28T04:10:33.954000Z","event_type":"price_change","frame_hash":"001a8c34f85ef0e18c60ea87d2e7c7897dfbd36fe8c38f60ffdb89752bdfd881","frame_index":0,"kind":"data","monotonic_ns":313817385295583,"payload":{"event_type":"price_change","market":"0xd412ce774cfcf8dc9f71164aac78783978aac7b03871702a3b8a481bd9dc9688","price_changes":[{"asset_id":"107603864457683460275633293642179940881969192120168665300712204232021063124301","best_ask":"0.65","best_bid":"0.64","hash":"0100a4fa078fcce046edb47b73fe778e0c75f554","price":"0.63","side":"BUY","size":"75.2"},{"asset_id":"96600821790790307414914106093858868634329285205417149685270682748367152458577","best_ask":"0.36","best_bid":"0.35","hash":"fc97ae71f0175b4747a196d6aa241a3c004ab3cb","price":"0.37","side":"SELL","size":"75.2"}],"timestamp":"1785211833954"},"payload_hash":"3ef869636821613738106030b0c753088840cd33c27f7ac2a270b0d9e08687e6","raw_frame":"{\"market\":\"0xd412ce774cfcf8dc9f71164aac78783978aac7b03871702a3b8a481bd9dc9688\", \"price_changes\":[{\"asset_id\":\"107603864457683460275633293642179940881969192120168665300712204232021063124301\", \"price\":\"0.63\", \"size\":\"75.2\", \"side\":\"BUY\", \"hash\":\"0100a4fa078fcce046edb47b73fe778e0c75f554\", \"best_bid\":\"0.64\", \"best_ask\":\"0.65\"}, {\"asset_id\":\"96600821790790307414914106093858868634329285205417149685270682748367152458577\", \"price\":\"0.37\", \"size\":\"75.2\", \"side\":\"SELL\", \"hash\":\"fc97ae71f0175b4747a196d6aa241a3c004ab3cb\", \"best_bid\":\"0.35\", \"best_ask\":\"0.36\"}], \"timestamp\":\"1785211833954\", \"event_type\":\"price_change\"}","received_at":"2026-07-28T04:10:34.309072Z","schema_version":"clob-market-ws.price_change.v1","sequence":null,"server_hash":null,"server_timestamp":"1785211833954","session_id":"2d607381e3054cee91998cdf45a4231c","source":"clob_market_ws"},"received_at":"2026-07-28T04:10:34.309072Z","record_id":"d6a3df15ed75380dbd525347a47d35f4ce62bd1ff3566d340791d1a55889baf8","schema_fingerprint":"4aa3821a28b0b7c2400bc59aba4bcc0a76e971dadd19610d3ad38c768e124dc7","schema_version":"edge-lab-recorder.raw.v1","sequence":null,"source":"clob_market_ws"}
{"event_at":"2026-07-28T04:10:33.955000Z","event_fingerprint":"dba1b9e3ce16789342486234d8e566884b356551071390724a46a4316a109d49","payload":{"connection_id":"f6725804f86a4c4eb588e4d5ed7db029","event_at":"2026-07-28T04:10:33.955000Z","event_type":"price_change","frame_hash":"ed5af581cb11ee21597e46a6b584180d75ed9e3f84c7f8d02008fbba8a63e1f3","frame_index":0,"kind":"data","monotonic_ns":313817391690375,"payload":{"event_type":"price_change","market":"0xd412ce774cfcf8dc9f71164aac78783978aac7b03871702a3b8a481bd9dc9688","price_changes":[{"asset_id":"107603864457683460275633293642179940881969192120168665300712204232021063124301","best_ask":"0.65","best_bid":"0.64","hash":"9ddaaee994326fbdb93277c9fffbd9118c441769","price":"0.63","side":"BUY","size":"100.2"},{"asset_id":"96600821790790307414914106093858868634329285205417149685270682748367152458577","best_ask":"0.36","best_bid":"0.35","hash":"1f6b39f35fd1368b0b8b037aad4376548a81041f","price":"0.37","side":"SELL","size":"100.2"}],"timestamp":"1785211833955"},"payload_hash":"80cbb6c05d0f1afe907c5055248aa9b819060a66325805a34124895397902d0b","raw_frame":"{\"market\":\"0xd412ce774cfcf8dc9f71164aac78783978aac7b03871702a3b8a481bd9dc9688\", \"price_changes\":[{\"asset_id\":\"107603864457683460275633293642179940881969192120168665300712204232021063124301\", \"price\":\"0.63\", \"size\":\"100.2\", \"side\":\"BUY\", \"hash\":\"9ddaaee994326fbdb93277c9fffbd9118c441769\", \"best_bid\":\"0.64\", \"best_ask\":\"0.65\"}, {\"asset_id\":\"96600821790790307414914106093858868634329285205417149685270682748367152458577\", \"price\":\"0.37\", \"size\":\"100.2\", \"side\":\"SELL\", \"hash\":\"1f6b39f35fd1368b0b8b037aad4376548a81041f\", \"best_bid\":\"0.35\", \"best_ask\":\"0.36\"}], \"timestamp\":\"1785211833955\", \"event_type\":\"price_change\"}","received_at":"2026-07-28T04:10:34.315459Z","schema_version":"clob-market-ws.price_change.v1","sequence":null,"server_hash":null,"server_timestamp":"1785211833955","session_id":"2d607381e3054cee91998cdf45a4231c","source":"clob_market_ws"},"received_at":"2026-07-28T04:10:34.315459Z","record_id":"d1011adccf03bc2323c2a5506adda3ca8456ebbb82c6e21dbec1fc1b7801fd9c","schema_fingerprint":"4aa3821a28b0b7c2400bc59aba4bcc0a76e971dadd19610d3ad38c768e124dc7","schema_version":"edge-lab-recorder.raw.v1","sequence":null,"source":"clob_market_ws"}
{"event_at":"2026-07-28T04:10:33.956000Z","event_fingerprint":"1c9b2431d6e7b6ca147d8c633c28df50dee314237471aa382b116fed93116905","payload":{"connection_id":"f6725804f86a4c4eb588e4d5ed7db029","event_at":"2026-07-28T04:10:33.956000Z","event_type":"price_change","frame_hash":"1814abbf5674315fef58d51283a2303db601d4e7406c8abd19a2e60dd09ddb76","frame_index":0,"kind":"data","monotonic_ns":313817398302500,"payload":{"event_type":"price_change","market":"0xd412ce774cfcf8dc9f71164aac78783978aac7b03871702a3b8a481bd9dc9688","price_changes":[{"asset_id":"107603864457683460275633293642179940881969192120168665300712204232021063124301","best_ask":"0.65","best_bid":"0.64","hash":"249dec0e943825353859d6ff04b24626983c3fff","price":"0.02","side":"BUY","size":"683.1"},{"asset_id":"96600821790790307414914106093858868634329285205417149685270682748367152458577","best_ask":"0.36","best_bid":"0.35","hash":"0fe2783a683c6ce02a290ea41995dec4707127fd","price":"0.98","side":"SELL","size":"683.1"}],"timestamp":"1785211833956"},"payload_hash":"ede4d5ef1ca4888d2415b111dc2bb3737b57ecfd9ab44d9643396ba3401e38b0","raw_frame":"{\"market\":\"0xd412ce774cfcf8dc9f71164aac78783978aac7b03871702a3b8a481bd9dc9688\", \"price_changes\":[{\"asset_id\":\"107603864457683460275633293642179940881969192120168665300712204232021063124301\", \"price\":\"0.02\", \"size\":\"683.1\", \"side\":\"BUY\", \"hash\":\"249dec0e943825353859d6ff04b24626983c3fff\", \"best_bid\":\"0.64\", \"best_ask\":\"0.65\"}, {\"asset_id\":\"96600821790790307414914106093858868634329285205417149685270682748367152458577\", \"price\":\"0.98\", \"size\":\"683.1\", \"side\":\"SELL\", \"hash\":\"0fe2783a683c6ce02a290ea41995dec4707127fd\", \"best_bid\":\"0.35\", \"best_ask\":\"0.36\"}], \"timestamp\":\"1785211833956\", \"event_type\":\"price_change\"}","received_at":"2026-07-28T04:10:34.322072Z","schema_version":"clob-market-ws.price_change.v1","sequence":null,"server_hash":null,"server_timestamp":"1785211833956","session_id":"2d607381e3054cee91998cdf45a4231c","source":"clob_market_ws"},"received_at":"2026-07-28T04:10:34.322072Z","record_id":"452ae35373096e6d0a16b513ecd30b953740ee7208c768f9b7bac962b7c01c1f","schema_fingerprint":"4aa3821a28b0b7c2400bc59aba4bcc0a76e971dadd19610d3ad38c768e124dc7","schema_version":"edge-lab-recorder.raw.v1","sequence":null,"source":"clob_market_ws"}
{"event_at":"2026-07-28T04:10:33.956000Z","event_fingerprint":"547de8ba90799bee05868ad3ef181134e063c26d6a9eeb4fb66f2a73474b9b33","payload":{"connection_id":"f6725804f86a4c4eb588e4d5ed7db029","event_at":"2026-07-28T04:10:33.956000Z","event_type":"price_change","frame_hash":"65041acfda0256348f27e1840ef5d924860396591cedf944f62eb349802e4198","frame_index":0,"kind":"data","monotonic_ns":313817412268750,"payload":{"event_type":"price_change","market":"0xd412ce774cfcf8dc9f71164aac78783978aac7b03871702a3b8a481bd9dc9688","price_changes":[{"asset_id":"107603864457683460275633293642179940881969192120168665300712204232021063124301","best_ask":"0.65","best_bid":"0.64","hash":"edce219453e2feeeb8ca6aae0fad538e6aea43b4","price":"0.67","side":"SELL","size":"138.38"},{"asset_id":"96600821790790307414914106093858868634329285205417149685270682748367152458577","best_ask":"0.36","best_bid":"0.35","hash":"17fc032b28e6535514ec47df83b161f4124afd54","price":"0.33","side":"BUY","size":"138.38"}],"timestamp":"1785211833956"},"payload_hash":"592451f63f2261e3765300d79f0dede8efb25c869998d205b28d45cb5f0e6921","raw_frame":"{\"market\":\"0xd412ce774cfcf8dc9f71164aac78783978aac7b03871702a3b8a481bd9dc9688\", \"price_changes\":[{\"asset_id\":\"107603864457683460275633293642179940881969192120168665300712204232021063124301\", \"price\":\"0.67\", \"size\":\"138.38\", \"side\":\"SELL\", \"hash\":\"edce219453e2feeeb8ca6aae0fad538e6aea43b4\", \"best_bid\":\"0.64\", \"best_ask\":\"0.65\"}, {\"asset_id\":\"96600821790790307414914106093858868634329285205417149685270682748367152458577\", \"price\":\"0.33\", \"size\":\"138.38\", \"side\":\"BUY\", \"hash\":\"17fc032b28e6535514ec47df83b161f4124afd54\", \"best_bid\":\"0.35\", \"best_ask\":\"0.36\"}], \"timestamp\":\"1785211833956\", \"event_type\":\"price_change\"}","received_at":"2026-07-28T04:10:34.336045Z","schema_version":"clob-market-ws.price_change.v1","sequence":null,"server_hash":null,"server_timestamp":"1785211833956","session_id":"2d607381e3054cee91998cdf45a4231c","source":"clob_market_ws"},"received_at":"2026-07-28T04:10:34.336045Z","record_id":"15ef3078a6983fd5b7776f8681950a8856f0a1bb5bce9ddc528820802f5c1686","schema_fingerprint":"4aa3821a28b0b7c2400bc59aba4bcc0a76e971dadd19610d3ad38c768e124dc7","schema_version":"edge-lab-recorder.raw.v1","sequence":null,"source":"clob_market_ws"}
{"event_at":"2026-07-28T04:10:33.956000Z","event_fingerprint":"85c1b52b900e9c36219a41af99d1d8eb8dbd0fa1f3df32839e18457085de0e8a","payload":{"connection_id":"f6725804f86a4c4eb588e4d5ed7db029","event_at":"2026-07-28T04:10:33.956000Z","event_type":"price_change","frame_hash":"e2c58b777eccf464c95f4dc79eaaad58e58f3ca5723a50c3a19878df1fb00cf5","frame_index":0,"kind":"data","monotonic_ns":313817417147625,"payload":{"event_type":"price_change","market":"0xd412ce774cfcf8dc9f71164aac78783978aac7b03871702a3b8a481bd9dc9688","price_changes":[{"asset_id":"96600821790790307414914106093858868634329285205417149685270682748367152458577","best_ask":"0.36","best_bid":"0.35","hash":"de02924e52bbb746b06d5718b74a435bd05376b7","price":"0.28","side":"BUY","size":"234.49"},{"asset_id":"107603864457683460275633293642179940881969192120168665300712204232021063124301","best_ask":"0.65","best_bid":"0.64","hash":"0de1d642b17184acdc8d5c1948b565ef5c506dd9","price":"0.72","side":"SELL","size":"234.49"}],"timestamp":"1785211833956"},"payload_hash":"b4819bd73e5ef449edd260fe3097d092eb55daac2f70d25d43543caf1c035698","raw_frame":"{\"market\":\"0xd412ce774cfcf8dc9f71164aac78783978aac7b03871702a3b8a481bd9dc9688\", \"price_changes\":[{\"asset_id\":\"96600821790790307414914106093858868634329285205417149685270682748367152458577\", \"price\":\"0.28\", \"size\":\"234.49\", \"side\":\"BUY\", \"hash\":\"de02924e52bbb746b06d5718b74a435bd05376b7\", \"best_bid\":\"0.35\", \"best_ask\":\"0.36\"}, {\"asset_id\":\"107603864457683460275633293642179940881969192120168665300712204232021063124301\", \"price\":\"0.72\", \"size\":\"234.49\", \"side\":\"SELL\", \"hash\":\"0de1d642b17184acdc8d5c1948b565ef5c506dd9\", \"best_bid\":\"0.64\", \"best_ask\":\"0.65\"}], \"timestamp\":\"1785211833956\", \"event_type\":\"price_change\"}","received_at":"2026-07-28T04:10:34.340924Z","schema_version":"clob-market-ws.price_change.v1","sequence":null,"server_hash":null,"server_timestamp":"1785211833956","session_id":"2d607381e3054cee91998cdf45a4231c","source":"clob_market_ws"},"received_at":"2026-07-28T04:10:34.340924Z","record_id":"f06ed353d6b77a47dcb373ccd9d0157baaafb3055923985844547c0da3757414","schema_fingerprint":"4aa3821a28b0b7c2400bc59aba4bcc0a76e971dadd19610d3ad38c768e124dc7","schema_version":"edge-lab-recorder.raw.v1","sequence":null,"source":"clob_market_ws"}
{"event_at":"2026-07-28T04:10:33.957000Z","event_fingerprint":"b4991a1637a808deb28048bda0d923b27d97ab12b6f9c3bc3f5c6c7c868ca855","payload":{"connection_id":"f6725804f86a4c4eb588e4d5ed7db029","event_at":"2026-07-28T04:10:33.957000Z","event_type":"price_change","frame_hash":"2b07aea569c287aad4fdf2e08bd5dd64c6b77ccbc4580f763d08c032b280e5ae","frame_index":0,"kind":"data","monotonic_ns":313817420833916,"payload":{"event_type":"price_change","market":"0xd412ce774cfcf8dc9f71164aac78783978aac7b03871702a3b8a481bd9dc9688","price_changes":[{"asset_id":"96600821790790307414914106093858868634329285205417149685270682748367152458577","best_ask":"0.36","best_bid":"0.35","hash":"21b2a4053431e3f822ed7e05806a1211b2557deb","price":"0.1","side":"BUY","size":"492.29"},{"asset_id":"107603864457683460275633293642179940881969192120168665300712204232021063124301","best_ask":"0.65","best_bid":"0.64","hash":"2ec6f0db433b099c39bfd29017d1cefc830b4ceb","price":"0.9","side":"SELL","size":"492.29"}],"timestamp":"1785211833957"},"payload_hash":"c7597fbbb2236958fdd0dd14488221bb4d0aa42d988ffd32f4f67df649319f88","raw_frame":"{\"market\":\"0xd412ce774cfcf8dc9f71164aac78783978aac7b03871702a3b8a481bd9dc9688\", \"price_changes\":[{\"asset_id\":\"96600821790790307414914106093858868634329285205417149685270682748367152458577\", \"price\":\"0.1\", \"size\":\"492.29\", \"side\":\"BUY\", \"hash\":\"21b2a4053431e3f822ed7e05806a1211b2557deb\", \"best_bid\":\"0.35\", \"best_ask\":\"0.36\"}, {\"asset_id\":\"107603864457683460275633293642179940881969192120168665300712204232021063124301\", \"price\":\"0.9\", \"size\":\"492.29\", \"side\":\"SELL\", \"hash\":\"2ec6f0db433b099c39bfd29017d1cefc830b4ceb\", \"best_bid\":\"0.64\", \"best_ask\":\"0.65\"}], \"timestamp\":\"1785211833957\", \"event_type\":\"price_change\"}","received_at":"2026-07-28T04:10:34.344610Z","schema_version":"clob-market-ws.price_change.v1","sequence":null,"server_hash":null,"server_timestamp":"1785211833957","session_id":"2d607381e3054cee91998cdf45a4231c","source":"clob_market_ws"},"received_at":"2026-07-28T04:10:34.344610Z","record_id":"c0a33ada6fd07024c11fbc3c5b24b2d4f52d76c531c6e697fdcde0ea9c735646","schema_fingerprint":"4aa3821a28b0b7c2400bc59aba4bcc0a76e971dadd19610d3ad38c768e124dc7","schema_version":"edge-lab-recorder.raw.v1","sequence":null,"source":"clob_market_ws"}
{"event_at":"2026-07-28T04:10:33.957000Z","event_fingerprint":"70c8c360f2e2aa1cbbf7ff230b90f6151d5721fafad706f5fe9b814b98e47e3f","payload":{"connection_id":"f6725804f86a4c4eb588e4d5ed7db029","event_at":"2026-07-28T04:10:33.957000Z","event_type":"price_change","frame_hash":"d0c5cfb41a45148d8900b9607fbed8d10b0183f0f9e15388b9098e2ada6ad6bc","frame_index":0,"kind":"data","monotonic_ns":313817423124583,"payload":{"event_type":"price_change","market":"0xd412ce774cfcf8dc9f71164aac78783978aac7b03871702a3b8a481bd9dc9688","price_changes":[{"asset_id":"96600821790790307414914106093858868634329285205417149685270682748367152458577","best_ask":"0.36","best_bid":"0.35","hash":"1f57247c1bad7c0199ba448893455c83578f874a","price":"0.29","side":"BUY","size":"194"},{"asset_id":"107603864457683460275633293642179940881969192120168665300712204232021063124301","best_ask":"0.65","best_bid":"0.64","hash":"b8d6cd99fb22ce270cedd8fbad6d8c30e7199901","price":"0.71","side":"SELL","size":"194"}],"timestamp":"1785211833957"},"payload_hash":"e22a85805f586c3d70bf6a10ddecab49f1af9ba387677f609ed384ea32cc9e33","raw_frame":"{\"market\":\"0xd412ce774cfcf8dc9f71164aac78783978aac7b03871702a3b8a481bd9dc9688\", \"price_changes\":[{\"asset_id\":\"96600821790790307414914106093858868634329285205417149685270682748367152458577\", \"price\":\"0.29\", \"size\":\"194\", \"side\":\"BUY\", \"hash\":\"1f57247c1bad7c0199ba448893455c83578f874a\", \"best_bid\":\"0.35\", \"best_ask\":\"0.36\"}, {\"asset_id\":\"107603864457683460275633293642179940881969192120168665300712204232021063124301\", \"price\":\"0.71\", \"size\":\"194\", \"side\":\"SELL\", \"hash\":\"b8d6cd99fb22ce270cedd8fbad6d8c30e7199901\", \"best_bid\":\"0.64\", \"best_ask\":\"0.65\"}], \"timestamp\":\"1785211833957\", \"event_type\":\"price_change\"}","received_at":"2026-07-28T04:10:34.346900Z","schema_version":"clob-market-ws.price_change.v1","sequence":null,"server_hash":null,"server_timestamp":"1785211833957","session_id":"2d607381e3054cee91998cdf45a4231c","source":"clob_market_ws"},"received_at":"2026-07-28T04:10:34.346900Z","record_id":"d5dd4c4bae5b29cf70c233fc228271e020e974df543e0152a68cdadbc8e51660","schema_fingerprint":"4aa3821a28b0b7c2400bc59aba4bcc0a76e971dadd19610d3ad38c768e124dc7","schema_version":"edge-lab-recorder.raw.v1","sequence":null,"source":"clob_market_ws"}
{"event_at":"2026-07-28T04:10:33.958000Z","event_fingerprint":"fa6d7aa6afe965ff91b3987acde3a4073768be3deaace536bf4c1871f0ecfd20","payload":{"connection_id":"f6725804f86a4c4eb588e4d5ed7db029","event_at":"2026-07-28T04:10:33.958000Z","event_type":"price_change","frame_hash":"0f6c9fe48b369c99a2cbf73f9ed79e2a5262be47659358ccd8953d0f3b5d4e87","frame_index":0,"kind":"data","monotonic_ns":313817427448916,"payload":{"event_type":"price_change","market":"0xd412ce774cfcf8dc9f71164aac78783978aac7b03871702a3b8a481bd9dc9688","price_changes":[{"asset_id":"107603864457683460275633293642179940881969192120168665300712204232021063124301","best_ask":"0.65","best_bid":"0.64","hash":"e3074a998c37ec14b5d8b56e23d36d03d36d80e7","price":"0.59","side":"BUY","size":"101.6"},{"asset_id":"96600821790790307414914106093858868634329285205417149685270682748367152458577","best_ask":"0.36","best_bid":"0.35","hash":"f825589c6860f1425f4ce00873b56d2e055d0f20","price":"0.41","side":"SELL","size":"101.6"}],"timestamp":"1785211833958"},"payload_hash":"7862dfef6a3156c89db0efcdba770fbf3f70ebea283e5a7f76d6906b19ddc39c","raw_frame":"{\"market\":\"0xd412ce774cfcf8dc9f71164aac78783978aac7b03871702a3b8a481bd9dc9688\", \"price_changes\":[{\"asset_id\":\"107603864457683460275633293642179940881969192120168665300712204232021063124301\", \"price\":\"0.59\", \"size\":\"101.6\", \"side\":\"BUY\", \"hash\":\"e3074a998c37ec14b5d8b56e23d36d03d36d80e7\", \"best_bid\":\"0.64\", \"best_ask\":\"0.65\"}, {\"asset_id\":\"96600821790790307414914106093858868634329285205417149685270682748367152458577\", \"price\":\"0.41\", \"size\":\"101.6\", \"side\":\"SELL\", \"hash\":\"f825589c6860f1425f4ce00873b56d2e055d0f20\", \"best_bid\":\"0.35\", \"best_ask\":\"0.36\"}], \"timestamp\":\"1785211833958\", \"event_type\":\"price_change\"}","received_at":"2026-07-28T04:10:34.351226Z","schema_version":"clob-market-ws.price_change.v1","sequence":null,"server_hash":null,"server_timestamp":"1785211833958","session_id":"2d607381e3054cee91998cdf45a4231c","source":"clob_market_ws"},"received_at":"2026-07-28T04:10:34.351226Z","record_id":"adf58934319e4ac1954313b95df4a9619ffab0929f4a0ac57b2ba73609cf5978","schema_fingerprint":"4aa3821a28b0b7c2400bc59aba4bcc0a76e971dadd19610d3ad38c768e124dc7","schema_version":"edge-lab-recorder.raw.v1","sequence":null,"source":"clob_market_ws"}
{"event_at":"2026-07-28T04:10:33.959000Z","event_fingerprint":"dd72aa09f78efea142c4300b645a0c39226e3738c4a0d92899656883d2f93dde","payload":{"connection_id":"f6725804f86a4c4eb588e4d5ed7db029","event_at":"2026-07-28T04:10:33.959000Z","event_type":"price_change","frame_hash":"9c8ea875b33dd3e3adc57f2b44a4ba61589d35322032c216651ae7db33dbf338","frame_index":0,"kind":"data","monotonic_ns":313817431755208,"payload":{"event_type":"price_change","market":"0xd412ce774cfcf8dc9f71164aac78783978aac7b03871702a3b8a481bd9dc9688","price_changes":[{"asset_id":"107603864457683460275633293642179940881969192120168665300712204232021063124301","best_ask":"0.65","best_bid":"0.64","hash":"91b1550e921274a9c0f3b41f11845292f9fd3377","price":"0.58","side":"BUY","size":"83"},{"asset_id":"96600821790790307414914106093858868634329285205417149685270682748367152458577","best_ask":"0.36","best_bid":"0.35","hash":"56e7a3cd38f80ad2654e6be7b3c8142d659d15ff","price":"0.42","side":"SELL","size":"83"}],"timestamp":"1785211833959"},"payload_hash":"f05d76c54f935e60aaf9f07dd93e8cd819ed2f139dd9f53e29dba8a9e45c6e19","raw_frame":"{\"market\":\"0xd412ce774cfcf8dc9f71164aac78783978aac7b03871702a3b8a481bd9dc9688\", \"price_changes\":[{\"asset_id\":\"107603864457683460275633293642179940881969192120168665300712204232021063124301\", \"price\":\"0.58\", \"size\":\"83\", \"side\":\"BUY\", \"hash\":\"91b1550e921274a9c0f3b41f11845292f9fd3377\", \"best_bid\":\"0.64\", \"best_ask\":\"0.65\"}, {\"asset_id\":\"96600821790790307414914106093858868634329285205417149685270682748367152458577\", \"price\":\"0.42\", \"size\":\"83\", \"side\":\"SELL\", \"hash\":\"56e7a3cd38f80ad2654e6be7b3c8142d659d15ff\", \"best_bid\":\"0.35\", \"best_ask\":\"0.36\"}], \"timestamp\":\"1785211833959\", \"event_type\":\"price_change\"}","received_at":"2026-07-28T04:10:34.355532Z","schema_version":"clob-market-ws.price_change.v1","sequence":null,"server_hash":null,"server_timestamp":"1785211833959","session_id":"2d607381e3054cee91998cdf45a4231c","source":"clob_market_ws"},"received_at":"2026-07-28T04:10:34.355532Z","record_id":"8bda7dd131dbbe6d7613596c6a3c27af6f23826af3c661b2151ed6c1604228b5","schema_fingerprint":"4aa3821a28b0b7c2400bc59aba4bcc0a76e971dadd19610d3ad38c768e124dc7","schema_version":"edge-lab-recorder.raw.v1","sequence":null,"source":"clob_market_ws"}
{"event_at":"2026-07-28T04:10:33.959000Z","event_fingerprint":"fa3087ab8e514512147305b5570a159c5834aa8d152b5377813ee5d2a81bf876","payload":{"connection_id":"f6725804f86a4c4eb588e4d5ed7db029","event_at":"2026-07-28T04:10:33.959000Z","event_type":"price_change","frame_hash":"8e926bd91cb9df1ba9abbc70cada714253971a1348ebbeda975914507afc0271","frame_index":0,"kind":"data","monotonic_ns":313817436104333,"payload":{"event_type":"price_change","market":"0xd412ce774cfcf8dc9f71164aac78783978aac7b03871702a3b8a481bd9dc9688","price_changes":[{"asset_id":"107603864457683460275633293642179940881969192120168665300712204232021063124301","best_ask":"0.65","best_bid":"0.64","hash":"084946a962595e5d398dc3b5c72c0cb26054d3d3","price":"0.33","side":"BUY","size":"221.62"},{"asset_id":"96600821790790307414914106093858868634329285205417149685270682748367152458577","best_ask":"0.36","best_bid":"0.35","hash":"5e05befb9fc3885051062aa8abf4662d90e0dab8","price":"0.67","side":"SELL","size":"221.62"}],"timestamp":"1785211833959"},"payload_hash":"11e66aece50e5ad1dc57593836b3e699ad3ffd630a3158534a15d45de81eade0","raw_frame":"{\"market\":\"0xd412ce774cfcf8dc9f71164aac78783978aac7b03871702a3b8a481bd9dc9688\", \"price_changes\":[{\"asset_id\":\"107603864457683460275633293642179940881969192120168665300712204232021063124301\", \"price\":\"0.33\", \"size\":\"221.62\", \"side\":\"BUY\", \"hash\":\"084946a962595e5d398dc3b5c72c0cb26054d3d3\", \"best_bid\":\"0.64\", \"best_ask\":\"0.65\"}, {\"asset_id\":\"96600821790790307414914106093858868634329285205417149685270682748367152458577\", \"price\":\"0.67\", \"size\":\"221.62\", \"side\":\"SELL\", \"hash\":\"5e05befb9fc3885051062aa8abf4662d90e0dab8\", \"best_bid\":\"0.35\", \"best_ask\":\"0.36\"}], \"timestamp\":\"1785211833959\", \"event_type\":\"price_change\"}","received_at":"2026-07-28T04:10:34.359881Z","schema_version":"clob-market-ws.price_change.v1","sequence":null,"server_hash":null,"server_timestamp":"1785211833959","session_id":"2d607381e3054cee91998cdf45a4231c","source":"clob_market_ws"},"received_at":"2026-07-28T04:10:34.359881Z","record_id":"b98bb21ea3900361d70fdaba03df16350a026afae6884e86ada8135bf3e523e9","schema_fingerprint":"4aa3821a28b0b7c2400bc59aba4bcc0a76e971dadd19610d3ad38c768e124dc7","schema_version":"edge-lab-recorder.raw.v1","sequence":null,"source":"clob_market_ws"}
{"event_at":"2026-07-28T04:10:33.960000Z","event_fingerprint":"5211ca6976da0a6543a2f643adf3841eb33ddf6a511c750d42a15fb9ff8fad83","payload":{"connection_id":"f6725804f86a4c4eb588e4d5ed7db029","event_at":"2026-07-28T04:10:33.960000Z","event_type":"best_bid_ask","frame_hash":"2543c61a0d7721b9d7ee50d7ca58f63f42222be83e424a669da91c04d14cd004","frame_index":0,"kind":"data","monotonic_ns":313817439787250,"payload":{"asset_id":"107603864457683460275633293642179940881969192120168665300712204232021063124301","best_ask":"0.66","best_bid":"0.64","event_type":"best_bid_ask","market":"0xd412ce774cfcf8dc9f71164aac78783978aac7b03871702a3b8a481bd9dc9688","spread":"0.02","timestamp":"1785211833960"},"payload_hash":"210c1fd8c4327dc6dc728942d42b19ddacf7cb34072c4ba856dd9b3486002317","raw_frame":"{\"market\":\"0xd412ce774cfcf8dc9f71164aac78783978aac7b03871702a3b8a481bd9dc9688\", \"asset_id\":\"107603864457683460275633293642179940881969192120168665300712204232021063124301\", \"best_bid\":\"0.64\", \"best_ask\":\"0.66\", \"spread\":\"0.02\", \"timestamp\":\"1785211833960\", \"event_type\":\"best_bid_ask\"}","received_at":"2026-07-28T04:10:34.363564Z","schema_version":"clob-market-ws.best_bid_ask.v1","sequence":null,"server_hash":null,"server_timestamp":"1785211833960","session_id":"2d607381e3054cee91998cdf45a4231c","source":"clob_market_ws"},"received_at":"2026-07-28T04:10:34.363564Z","record_id":"f64e63b8dec3b6b264c8570caa3ed7b87cd007692ac3154dafc74588d509511e","schema_fingerprint":"8488399f31b0337811b13b266be932db7062827c2470b78bd8e9e99bab51d17d","schema_version":"edge-lab-recorder.raw.v1","sequence":null,"source":"clob_market_ws"}
{"event_at":"2026-07-28T04:10:33.960000Z","event_fingerprint":"e87a0002b557fa5d8296bbfed1d13e8df9a500f119f64d82eb1b1af8c74863bf","payload":{"connection_id":"f6725804f86a4c4eb588e4d5ed7db029","event_at":"2026-07-28T04:10:33.960000Z","event_type":"best_bid_ask","frame_hash":"1322cc4892473f26534462864f85a3b45359ebc4048815e34d76709b637d256e","frame_index":0,"kind":"data","monotonic_ns":313817443812750,"payload":{"asset_id":"96600821790790307414914106093858868634329285205417149685270682748367152458577","best_ask":"0.36","best_bid":"0.34","event_type":"best_bid_ask","market":"0xd412ce774cfcf8dc9f71164aac78783978aac7b03871702a3b8a481bd9dc9688","spread":"0.02","timestamp":"1785211833960"},"payload_hash":"d7524803bce9318a0cc65f4eb93b76f1a3a5814432ae0d9fe8f8ab58bbf2aab7","raw_frame":"{\"market\":\"0xd412ce774cfcf8dc9f71164aac78783978aac7b03871702a3b8a481bd9dc9688\", \"asset_id\":\"96600821790790307414914106093858868634329285205417149685270682748367152458577\", \"best_bid\":\"0.34\", \"best_ask\":\"0.36\", \"spread\":\"0.02\", \"timestamp\":\"1785211833960\", \"event_type\":\"best_bid_ask\"}","received_at":"2026-07-28T04:10:34.367588Z","schema_version":"clob-market-ws.best_bid_ask.v1","sequence":null,"server_hash":null,"server_timestamp":"1785211833960","session_id":"2d607381e3054cee91998cdf45a4231c","source":"clob_market_ws"},"received_at":"2026-07-28T04:10:34.367588Z","record_id":"1309e1591c08812a0511ef6cdd2041a99510a64cc7fbef6206ed6a42db6aab0c","schema_fingerprint":"8488399f31b0337811b13b266be932db7062827c2470b78bd8e9e99bab51d17d","schema_version":"edge-lab-recorder.raw.v1","sequence":null,"source":"clob_market_ws"}
{"event_at":"2026-07-28T04:10:33.959000Z","event_fingerprint":"4008379ee0b6355c0a71e7e1eb9725a238cd6b3d2520dbc7ceb9e77f3a2b5cb1","payload":{"connection_id":"f6725804f86a4c4eb588e4d5ed7db029","event_at":"2026-07-28T04:10:33.959000Z","event_type":"price_change","frame_hash":"a7af18ff54e5aa49830d34100937ea0db33aeeb93e2b68b9a625846a9aa7fbcd","frame_index":0,"kind":"data","monotonic_ns":313817448147250,"payload":{"event_type":"price_change","market":"0xd412ce774cfcf8dc9f71164aac78783978aac7b03871702a3b8a481bd9dc9688","price_changes":[{"asset_id":"96600821790790307414914106093858868634329285205417149685270682748367152458577","best_ask":"0.36","best_bid":"0.34","hash":"6bd7c68507d20023ca793529f13afaf8ced12fa4","price":"0.35","side":"BUY","size":"0"},{"asset_id":"107603864457683460275633293642179940881969192120168665300712204232021063124301","best_ask":"0.66","best_bid":"0.64","hash":"1bc19afcc8c4deff674aa9f3d89395f7592e373b","price":"0.65","side":"SELL","size":"0"}],"timestamp":"1785211833959"},"payload_hash":"00a6aebebe185043f358051f5d14e57cd3885aa7f4ffa0349f22293e112d8bd6","raw_frame":"{\"market\":\"0xd412ce774cfcf8dc9f71164aac78783978aac7b03871702a3b8a481bd9dc9688\", \"price_changes\":[{\"asset_id\":\"96600821790790307414914106093858868634329285205417149685270682748367152458577\", \"price\":\"0.35\", \"size\":\"0\", \"side\":\"BUY\", \"hash\":\"6bd7c68507d20023ca793529f13afaf8ced12fa4\", \"best_bid\":\"0.34\", \"best_ask\":\"0.36\"}, {\"asset_id\":\"107603864457683460275633293642179940881969192120168665300712204232021063124301\", \"price\":\"0.65\", \"size\":\"0\", \"side\":\"SELL\", \"hash\":\"1bc19afcc8c4deff674aa9f3d89395f7592e373b\", \"best_bid\":\"0.64\", \"best_ask\":\"0.66\"}], \"timestamp\":\"1785211833959\", \"event_type\":\"price_change\"}","received_at":"2026-07-28T04:10:34.371923Z","schema_version":"clob-market-ws.price_change.v1","sequence":null,"server_hash":null,"server_timestamp":"1785211833959","session_id":"2d607381e3054cee91998cdf45a4231c","source":"clob_market_ws"},"received_at":"2026-07-28T04:10:34.371923Z","record_id":"38aa223832cc4c7fc24ad811152545056835f25484be2dea39662da332835814","schema_fingerprint":"4aa3821a28b0b7c2400bc59aba4bcc0a76e971dadd19610d3ad38c768e124dc7","schema_version":"edge-lab-recorder.raw.v1","sequence":null,"source":"clob_market_ws"}
{"event_at":"2026-07-28T04:10:33.960000Z","event_fingerprint":"970bfee26331c17a5e7e1ecc29ac35c199440097a81dd197c0ac920301fb93c3","payload":{"connection_id":"f6725804f86a4c4eb588e4d5ed7db029","event_at":"2026-07-28T04:10:33.960000Z","event_type":"price_change","frame_hash":"d648b8656e022ed62309e5f062f36d985490b73f3d267fbf82dca063ec2ebd4c","frame_index":0,"kind":"data","monotonic_ns":313817452622250,"payload":{"event_type":"price_change","market":"0xd412ce774cfcf8dc9f71164aac78783978aac7b03871702a3b8a481bd9dc9688","price_changes":[{"asset_id":"96600821790790307414914106093858868634329285205417149685270682748367152458577","best_ask":"0.36","best_bid":"0.34","hash":"ff26103467ea7271d0b91bf32e34a4fedc997eb1","price":"0.1","side":"BUY","size":"297.29"},{"asset_id":"107603864457683460275633293642179940881969192120168665300712204232021063124301","best_ask":"0.66","best_bid":"0.64","hash":"841fc23f658fed5ff1810b4297557e66f9198534","price":"0.9","side":"SELL","size":"297.29"}],"timestamp":"1785211833960"},"payload_hash":"c27a04c053e06fee0ee14a814ea2d967e5bb6a9ebc72d96a64303e6ebdb3a32a","raw_frame":"{\"market\":\"0xd412ce774cfcf8dc9f71164aac78783978aac7b03871702a3b8a481bd9dc9688\", \"price_changes\":[{\"asset_id\":\"96600821790790307414914106093858868634329285205417149685270682748367152458577\", \"price\":\"0.1\", \"size\":\"297.29\", \"side\":\"BUY\", \"hash\":\"ff26103467ea7271d0b91bf32e34a4fedc997eb1\", \"best_bid\":\"0.34\", \"best_ask\":\"0.36\"}, {\"asset_id\":\"107603864457683460275633293642179940881969192120168665300712204232021063124301\", \"price\":\"0.9\", \"size\":\"297.29\", \"side\":\"SELL\", \"hash\":\"841fc23f658fed5ff1810b4297557e66f9198534\", \"best_bid\":\"0.64\", \"best_ask\":\"0.66\"}], \"timestamp\":\"1785211833960\", \"event_type\":\"price_change\"}","received_at":"2026-07-28T04:10:34.376398Z","schema_version":"clob-market-ws.price_change.v1","sequence":null,"server_hash":null,"server_timestamp":"1785211833960","session_id":"2d607381e3054cee91998cdf45a4231c","source":"clob_market_ws"},"received_at":"2026-07-28T04:10:34.376398Z","record_id":"b468b67245e123178688bf61d62fecc1426ce9d7d3b57dfd7616393caa2a62a9","schema_fingerprint":"4aa3821a28b0b7c2400bc59aba4bcc0a76e971dadd19610d3ad38c768e124dc7","schema_version":"edge-lab-recorder.raw.v1","sequence":null,"source":"clob_market_ws"}
{"event_at":"2026-07-28T04:10:33.960000Z","event_fingerprint":"4c2a407059a534119e357d463ce28baeebf1bee009b94518ebbecfbbacac56bd","payload":{"connection_id":"f6725804f86a4c4eb588e4d5ed7db029","event_at":"2026-07-28T04:10:33.960000Z","event_type":"price_change","frame_hash":"26990d74fa4d5ec582fe9b4ee04f691fd10a7b4b93cbcaa58a1d14bd8e064ef3","frame_index":0,"kind":"data","monotonic_ns":313817457004791,"payload":{"event_type":"price_change","market":"0xd412ce774cfcf8dc9f71164aac78783978aac7b03871702a3b8a481bd9dc9688","price_changes":[{"asset_id":"96600821790790307414914106093858868634329285205417149685270682748367152458577","best_ask":"0.36","best_bid":"0.34","hash":"e3fcc6c64ed2bc180941eac6c7785ab4509d5473","price":"0.23","side":"BUY","size":"136.89"},{"asset_id":"107603864457683460275633293642179940881969192120168665300712204232021063124301","best_ask":"0.66","best_bid":"0.64","hash":"bbbc15af926f5299250a1c0bd2fca35107cd2fee","price":"0.77","side":"SELL","size":"136.89"}],"timestamp":"1785211833960"},"payload_hash":"c3e3c368b52a54ecbb156778503c08a83fa4778576d9a4dbf00fca2ea86011f0","raw_frame":"{\"market\":\"0xd412ce774cfcf8dc9f71164aac78783978aac7b03871702a3b8a481bd9dc9688\", \"price_changes\":[{\"asset_id\":\"96600821790790307414914106093858868634329285205417149685270682748367152458577\", \"price\":\"0.23\", \"size\":\"136.89\", \"side\":\"BUY\", \"hash\":\"e3fcc6c64ed2bc180941eac6c7785ab4509d5473\", \"best_bid\":\"0.34\", \"best_ask\":\"0.36\"}, {\"asset_id\":\"107603864457683460275633293642179940881969192120168665300712204232021063124301\", \"price\":\"0.77\", \"size\":\"136.89\", \"side\":\"SELL\", \"hash\":\"bbbc15af926f5299250a1c0bd2fca35107cd2fee\", \"best_bid\":\"0.64\", \"best_ask\":\"0.66\"}], \"timestamp\":\"1785211833960\", \"event_type\":\"price_change\"}","received_at":"2026-07-28T04:10:34.380779Z","schema_version":"clob-market-ws.price_change.v1","sequence":null,"server_hash":null,"server_timestamp":"1785211833960","session_id":"2d607381e3054cee91998cdf45a4231c","source":"clob_market_ws"},"received_at":"2026-07-28T04:10:34.380779Z","record_id":"2cacae669cc19c0d1712cc4ef31c1c2fa421adb6b3af863ac4109855179ddbdd","schema_fingerprint":"4aa3821a28b0b7c2400bc59aba4bcc0a76e971dadd19610d3ad38c768e124dc7","schema_version":"edge-lab-recorder.raw.v1","sequence":null,"source":"clob_market_ws"}
{"event_at":"2026-07-28T04:10:33.960000Z","event_fingerprint":"647560cb89e8abf586304d6d02264db76a2040a62a3b4a053dbad7a7671f2635","payload":{"connection_id":"f6725804f86a4c4eb588e4d5ed7db029","event_at":"2026-07-28T04:10:33.960000Z","event_type":"price_change","frame_hash":"4ca3de92244ca2abc76a6ab2b4cb0e43e73fee57b8c62db74cd692d9d0826b1d","frame_index":0,"kind":"data","monotonic_ns":313817467048291,"payload":{"event_type":"price_change","market":"0xd412ce774cfcf8dc9f71164aac78783978aac7b03871702a3b8a481bd9dc9688","price_changes":[{"asset_id":"96600821790790307414914106093858868634329285205417149685270682748367152458577","best_ask":"0.36","best_bid":"0.34","hash":"98b2037bc7c60b7ac9439894f1020d3510fc4374","price":"0.3","side":"BUY","size":"224"},{"asset_id":"107603864457683460275633293642179940881969192120168665300712204232021063124301","best_ask":"0.66","best_bid":"0.64","hash":"d12752a91b0fa7b22c4a1486c03e25a505420c3e","price":"0.7","side":"SELL","size":"224"}],"timestamp":"1785211833960"},"payload_hash":"e5ab7ae52a5ec26d8c3f2c4e95cbe488a62e47076fa99a988cfa12b5546d6297","raw_frame":"{\"market\":\"0xd412ce774cfcf8dc9f71164aac78783978aac7b03871702a3b8a481bd9dc9688\", \"price_changes\":[{\"asset_id\":\"96600821790790307414914106093858868634329285205417149685270682748367152458577\", \"price\":\"0.3\", \"size\":\"224\", \"side\":\"BUY\", \"hash\":\"98b2037bc7c60b7ac9439894f1020d3510fc4374\", \"best_bid\":\"0.34\", \"best_ask\":\"0.36\"}, {\"asset_id\":\"107603864457683460275633293642179940881969192120168665300712204232021063124301\", \"price\":\"0.7\", \"size\":\"224\", \"side\":\"SELL\", \"hash\":\"d12752a91b0fa7b22c4a1486c03e25a505420c3e\", \"best_bid\":\"0.64\", \"best_ask\":\"0.66\"}], \"timestamp\":\"1785211833960\", \"event_type\":\"price_change\"}","received_at":"2026-07-28T04:10:34.390820Z","schema_version":"clob-market-ws.price_change.v1","sequence":null,"server_hash":null,"server_timestamp":"1785211833960","session_id":"2d607381e3054cee91998cdf45a4231c","source":"clob_market_ws"},"received_at":"2026-07-28T04:10:34.390820Z","record_id":"b918647dccaab4f64b64c39f3bc7726b48162f8e40f8ec0845259d792b1daac8","schema_fingerprint":"4aa3821a28b0b7c2400bc59aba4bcc0a76e971dadd19610d3ad38c768e124dc7","schema_version":"edge-lab-recorder.raw.v1","sequence":null,"source":"clob_market_ws"}
{"event_at":"2026-07-28T04:10:33.960000Z","event_fingerprint":"bfb6c98c29493ea6347302839c013705ef507d20f573650b7bea6eeee143f0bd","payload":{"connection_id":"f6725804f86a4c4eb588e4d5ed7db029","event_at":"2026-07-28T04:10:33.960000Z","event_type":"price_change","frame_hash":"2647a3c8b357905b513c121392a97f2af46d130ea7d3bd9efd5e9d28c55a7545","frame_index":0,"kind":"data","monotonic_ns":313817471557000,"payload":{"event_type":"price_change","market":"0xd412ce774cfcf8dc9f71164aac78783978aac7b03871702a3b8a481bd9dc9688","price_changes":[{"asset_id":"107603864457683460275633293642179940881969192120168665300712204232021063124301","best_ask":"0.66","best_bid":"0.64","hash":"d12752a91b0fa7b22c4a1486c03e25a505420c3e","price":"0.43","side":"BUY","size":"160.2"},{"asset_id":"96600821790790307414914106093858868634329285205417149685270682748367152458577","best_ask":"0.36","best_bid":"0.34","hash":"98b2037bc7c60b7ac9439894f1020d3510fc4374","price":"0.57","side":"SELL","size":"160.2"}],"timestamp":"1785211833960"},"payload_hash":"c166e4f9dff1f535bb2af487e419946fc31c9922de1f342b6dab2c6e1da7e037","raw_frame":"{\"market\":\"0xd412ce774cfcf8dc9f71164aac78783978aac7b03871702a3b8a481bd9dc9688\", \"price_changes\":[{\"asset_id\":\"107603864457683460275633293642179940881969192120168665300712204232021063124301\", \"price\":\"0.43\", \"size\":\"160.2\", \"side\":\"BUY\", \"hash\":\"d12752a91b0fa7b22c4a1486c03e25a505420c3e\", \"best_bid\":\"0.64\", \"best_ask\":\"0.66\"}, {\"asset_id\":\"96600821790790307414914106093858868634329285205417149685270682748367152458577\", \"price\":\"0.57\", \"size\":\"160.2\", \"side\":\"SELL\", \"hash\":\"98b2037bc7c60b7ac9439894f1020d3510fc4374\", \"best_bid\":\"0.34\", \"best_ask\":\"0.36\"}], \"timestamp\":\"1785211833960\", \"event_type\":\"price_change\"}","received_at":"2026-07-28T04:10:34.395333Z","schema_version":"clob-market-ws.price_change.v1","sequence":null,"server_hash":null,"server_timestamp":"1785211833960","session_id":"2d607381e3054cee91998cdf45a4231c","source":"clob_market_ws"},"received_at":"2026-07-28T04:10:34.395333Z","record_id":"6d62a965ce20ace6f58832dd319698ca1fb0c54cc7ad58097b9479de2c70795f","schema_fingerprint":"4aa3821a28b0b7c2400bc59aba4bcc0a76e971dadd19610d3ad38c768e124dc7","schema_version":"edge-lab-recorder.raw.v1","sequence":null,"source":"clob_market_ws"}
{"event_at":"2026-07-28T04:10:33.960000Z","event_fingerprint":"3d1fed1033d34c8c94e296191598778bf23389522bc69709482d7c7612eb04a1","payload":{"connection_id":"f6725804f86a4c4eb588e4d5ed7db029","event_at":"2026-07-28T04:10:33.960000Z","event_type":"price_change","frame_hash":"a54014c369f3735b8472a268583881b4cfd69c7bf2256d00123090b7ad1e917b","frame_index":0,"kind":"data","monotonic_ns":313817475445708,"payload":{"event_type":"price_change","market":"0xd412ce774cfcf8dc9f71164aac78783978aac7b03871702a3b8a481bd9dc9688","price_changes":[{"asset_id":"96600821790790307414914106093858868634329285205417149685270682748367152458577","best_ask":"0.36","best_bid":"0.34","hash":"51cb044b9c83b44c1629888c1d228fe18d765781","price":"0.29","side":"BUY","size":"188"},{"asset_id":"107603864457683460275633293642179940881969192120168665300712204232021063124301","best_ask":"0.66","best_bid":"0.64","hash":"fa94b941dc597a431596272a4f9c2a13131becc5","price":"0.71","side":"SELL","size":"188"}],"timestamp":"1785211833960"},"payload_hash":"1417fff840f94e889ad0b67fd445b05a0f3ca8d3f67feae77e3bfe8ab64b3901","raw_frame":"{\"market\":\"0xd412ce774cfcf8dc9f71164aac78783978aac7b03871702a3b8a481bd9dc9688\", \"price_changes\":[{\"asset_id\":\"96600821790790307414914106093858868634329285205417149685270682748367152458577\", \"price\":\"0.29\", \"size\":\"188\", \"side\":\"BUY\", \"hash\":\"51cb044b9c83b44c1629888c1d228fe18d765781\", \"best_bid\":\"0.34\", \"best_ask\":\"0.36\"}, {\"asset_id\":\"107603864457683460275633293642179940881969192120168665300712204232021063124301\", \"price\":\"0.71\", \"size\":\"188\", \"side\":\"SELL\", \"hash\":\"fa94b941dc597a431596272a4f9c2a13131becc5\", \"best_bid\":\"0.64\", \"best_ask\":\"0.66\"}], \"timestamp\":\"1785211833960\", \"event_type\":\"price_change\"}","received_at":"2026-07-28T04:10:34.399220Z","schema_version":"clob-market-ws.price_change.v1","sequence":null,"server_hash":null,"server_timestamp":"1785211833960","session_id":"2d607381e3054cee91998cdf45a4231c","source":"clob_market_ws"},"received_at":"2026-07-28T04:10:34.399220Z","record_id":"c6f888812d2a66259a348ce7f883250aac6fc272e0e2bf9caf363d9b36cc5e8e","schema_fingerprint":"4aa3821a28b0b7c2400bc59aba4bcc0a76e971dadd19610d3ad38c768e124dc7","schema_version":"edge-lab-recorder.raw.v1","sequence":null,"source":"clob_market_ws"}
{"event_at":"2026-07-28T04:10:33.960000Z","event_fingerprint":"6d7c25484424caccd530051424b531e8b73df027014b9caba10841c28b9ec823","payload":{"connection_id":"f6725804f86a4c4eb588e4d5ed7db029","event_at":"2026-07-28T04:10:33.960000Z","event_type":"price_change","frame_hash":"42584af3b0d2594e470e539cf67aba00365c9493ef6359ba77ad71ac9ce59847","frame_index":0,"kind":"data","monotonic_ns":313817479139833,"payload":{"event_type":"price_change","market":"0xd412ce774cfcf8dc9f71164aac78783978aac7b03871702a3b8a481bd9dc9688","price_changes":[{"asset_id":"96600821790790307414914106093858868634329285205417149685270682748367152458577","best_ask":"0.36","best_bid":"0.34","hash":"982432a1f75ae6254d39dd31a2cf4437300c50aa","price":"0.26","side":"BUY","size":"204.25"},{"asset_id":"107603864457683460275633293642179940881969192120168665300712204232021063124301","best_ask":"0.66","best_bid":"0.64","hash":"7225c9a8050b598d0e18d3af577adc43f43201af","price":"0.74","side":"SELL","size":"204.25"}],"timestamp":"1785211833960"},"payload_hash":"da99aeec0bb6fc4933f138d2dec5b5f8408133939e34461877b0e854f87b3b8c","raw_frame":"{\"market\":\"0xd412ce774cfcf8dc9f71164aac78783978aac7b03871702a3b8a481bd9dc9688\", \"price_changes\":[{\"asset_id\":\"96600821790790307414914106093858868634329285205417149685270682748367152458577\", \"price\":\"0.26\", \"size\":\"204.25\", \"side\":\"BUY\", \"hash\":\"982432a1f75ae6254d39dd31a2cf4437300c50aa\", \"best_bid\":\"0.34\", \"best_ask\":\"0.36\"}, {\"asset_id\":\"107603864457683460275633293642179940881969192120168665300712204232021063124301\", \"price\":\"0.74\", \"size\":\"204.25\", \"side\":\"SELL\", \"hash\":\"7225c9a8050b598d0e18d3af577adc43f43201af\", \"best_bid\":\"0.64\", \"best_ask\":\"0.66\"}], \"timestamp\":\"1785211833960\", \"event_type\":\"price_change\"}","received_at":"2026-07-28T04:10:34.402916Z","schema_version":"clob-market-ws.price_change.v1","sequence":null,"server_hash":null,"server_timestamp":"1785211833960","session_id":"2d607381e3054cee91998cdf45a4231c","source":"clob_market_ws"},"received_at":"2026-07-28T04:10:34.402916Z","record_id":"94b3db5a54e67da01d4a66c191e54a84733c3c8e852b4e090f30a2b7c3eed38d","schema_fingerprint":"4aa3821a28b0b7c2400bc59aba4bcc0a76e971dadd19610d3ad38c768e124dc7","schema_version":"edge-lab-recorder.raw.v1","sequence":null,"source":"clob_market_ws"}
{"event_at":"2026-07-28T04:10:33.961000Z","event_fingerprint":"93ae9308c99eb90efae5f341328819a95d0f6c3e86d77dc73aa0a40d0957ad75","payload":{"connection_id":"f6725804f86a4c4eb588e4d5ed7db029","event_at":"2026-07-28T04:10:33.961000Z","event_type":"price_change","frame_hash":"9c2a0782c9071fa642e3a09f18f0cd153d6461f36233e8e5f14b3f5a9903c997","frame_index":0,"kind":"data","monotonic_ns":313817483387500,"payload":{"event_type":"price_change","market":"0xd412ce774cfcf8dc9f71164aac78783978aac7b03871702a3b8a481bd9dc9688","price_changes":[{"asset_id":"107603864457683460275633293642179940881969192120168665300712204232021063124301","best_ask":"0.66","best_bid":"0.64","hash":"659ba573dd3c896b4ae861af993e929d10571396","price":"0.33","side":"BUY","size":"120.61"},{"asset_id":"96600821790790307414914106093858868634329285205417149685270682748367152458577","best_ask":"0.36","best_bid":"0.34","hash":"c6dd93faef1a4b838a6378c6c4257a62d9886706","price":"0.67","side":"SELL","size":"120.61"}],"timestamp":"1785211833961"},"payload_hash":"55bfa147b83de96c800171ea82ff628900edac4df170fb51a157f36c4328bc5b","raw_frame":"{\"market\":\"0xd412ce774cfcf8dc9f71164aac78783978aac7b03871702a3b8a481bd9dc9688\", \"price_changes\":[{\"asset_id\":\"107603864457683460275633293642179940881969192120168665300712204232021063124301\", \"price\":\"0.33\", \"size\":\"120.61\", \"side\":\"BUY\", \"hash\":\"659ba573dd3c896b4ae861af993e929d10571396\", \"best_bid\":\"0.64\", \"best_ask\":\"0.66\"}, {\"asset_id\":\"96600821790790307414914106093858868634329285205417149685270682748367152458577\", \"price\":\"0.67\", \"size\":\"120.61\", \"side\":\"SELL\", \"hash\":\"c6dd93faef1a4b838a6378c6c4257a62d9886706\", \"best_bid\":\"0.34\", \"best_ask\":\"0.36\"}], \"timestamp\":\"1785211833961\", \"event_type\":\"price_change\"}","received_at":"2026-07-28T04:10:34.407163Z","schema_version":"clob-market-ws.price_change.v1","sequence":null,"server_hash":null,"server_timestamp":"1785211833961","session_id":"2d607381e3054cee91998cdf45a4231c","source":"clob_market_ws"},"received_at":"2026-07-28T04:10:34.407163Z","record_id":"3c4a8750677cad0d278fe0ccc716e3ae1510a93fde67215506e1d6755e29b976","schema_fingerprint":"4aa3821a28b0b7c2400bc59aba4bcc0a76e971dadd19610d3ad38c768e124dc7","schema_version":"edge-lab-recorder.raw.v1","sequence":null,"source":"clob_market_ws"}
{"event_at":"2026-07-28T04:10:33.961000Z","event_fingerprint":"624fc408f01d92edfac474ac9048ef495288ca3663de5c269079ec66b7bae3ec","payload":{"connection_id":"f6725804f86a4c4eb588e4d5ed7db029","event_at":"2026-07-28T04:10:33.961000Z","event_type":"price_change","frame_hash":"2418df262e75ac922c5ba4441472d9447aa80fafe51aea029871134bb30683d9","frame_index":0,"kind":"data","monotonic_ns":313817487356250,"payload":{"event_type":"price_change","market":"0xd412ce774cfcf8dc9f71164aac78783978aac7b03871702a3b8a481bd9dc9688","price_changes":[{"asset_id":"96600821790790307414914106093858868634329285205417149685270682748367152458577","best_ask":"0.36","best_bid":"0.34","hash":"f9d7d7f2da504090f10ef717b6489e55180ed7ae","price":"0.34","side":"BUY","size":"6"},{"asset_id":"107603864457683460275633293642179940881969192120168665300712204232021063124301","best_ask":"0.66","best_bid":"0.64","hash":"69a67c056d9bc33d03b35386829f96c6dfb27556","price":"0.66","side":"SELL","size":"6"}],"timestamp":"1785211833961"},"payload_hash":"9a3db330bd67fcc490fd6ed7e949459ed3b4a4896c591d2b4df6d4d0ed058c55","raw_frame":"{\"market\":\"0xd412ce774cfcf8dc9f71164aac78783978aac7b03871702a3b8a481bd9dc9688\", \"price_changes\":[{\"asset_id\":\"96600821790790307414914106093858868634329285205417149685270682748367152458577\", \"price\":\"0.34\", \"size\":\"6\", \"side\":\"BUY\", \"hash\":\"f9d7d7f2da504090f10ef717b6489e55180ed7ae\", \"best_bid\":\"0.34\", \"best_ask\":\"0.36\"}, {\"asset_id\":\"107603864457683460275633293642179940881969192120168665300712204232021063124301\", \"price\":\"0.66\", \"size\":\"6\", \"side\":\"SELL\", \"hash\":\"69a67c056d9bc33d03b35386829f96c6dfb27556\", \"best_bid\":\"0.64\", \"best_ask\":\"0.66\"}], \"timestamp\":\"1785211833961\", \"event_type\":\"price_change\"}","received_at":"2026-07-28T04:10:34.411132Z","schema_version":"clob-market-ws.price_change.v1","sequence":null,"server_hash":null,"server_timestamp":"1785211833961","session_id":"2d607381e3054cee91998cdf45a4231c","source":"clob_market_ws"},"received_at":"2026-07-28T04:10:34.411132Z","record_id":"4f8b3e1cccf31a0d643b6e3bd24817334e5731a3e53428be40e432ee3bee829d","schema_fingerprint":"4aa3821a28b0b7c2400bc59aba4bcc0a76e971dadd19610d3ad38c768e124dc7","schema_version":"edge-lab-recorder.raw.v1","sequence":null,"source":"clob_market_ws"}
{"event_at":"2026-07-28T04:10:33.961000Z","event_fingerprint":"d44c14967e50ab2638332f2b56428f0d66073e877f9ae55bd7e7d50097333ffe","payload":{"connection_id":"f6725804f86a4c4eb588e4d5ed7db029","event_at":"2026-07-28T04:10:33.961000Z","event_type":"price_change","frame_hash":"5323dbe47b25f168db0c6a81302f8b84e147383affe6aa27cbfb213340c9ecd8","frame_index":0,"kind":"data","monotonic_ns":313817491978958,"payload":{"event_type":"price_change","market":"0xd412ce774cfcf8dc9f71164aac78783978aac7b03871702a3b8a481bd9dc9688","price_changes":[{"asset_id":"96600821790790307414914106093858868634329285205417149685270682748367152458577","best_ask":"0.36","best_bid":"0.34","hash":"6dedd8fc86db91761738f98725994e680bb64109","price":"0.27","side":"BUY","size":"216"},{"asset_id":"107603864457683460275633293642179940881969192120168665300712204232021063124301","best_ask":"0.66","best_bid":"0.64","hash":"bf3e776cd520420c604180805541f52a0c23faae","price":"0.73","side":"SELL","size":"216"}],"timestamp":"1785211833961"},"payload_hash":"2ef57489cb56356d2a9306bbda82ac1e31a06c23fba29f34257c0e1a23246f3f","raw_frame":"{\"market\":\"0xd412ce774cfcf8dc9f71164aac78783978aac7b03871702a3b8a481bd9dc9688\", \"price_changes\":[{\"asset_id\":\"96600821790790307414914106093858868634329285205417149685270682748367152458577\", \"price\":\"0.27\", \"size\":\"216\", \"side\":\"BUY\", \"hash\":\"6dedd8fc86db91761738f98725994e680bb64109\", \"best_bid\":\"0.34\", \"best_ask\":\"0.36\"}, {\"asset_id\":\"107603864457683460275633293642179940881969192120168665300712204232021063124301\", \"price\":\"0.73\", \"size\":\"216\", \"side\":\"SELL\", \"hash\":\"bf3e776cd520420c604180805541f52a0c23faae\", \"best_bid\":\"0.64\", \"best_ask\":\"0.66\"}], \"timestamp\":\"1785211833961\", \"event_type\":\"price_change\"}","received_at":"2026-07-28T04:10:34.415755Z","schema_version":"clob-market-ws.price_change.v1","sequence":null,"server_hash":null,"server_timestamp":"1785211833961","session_id":"2d607381e3054cee91998cdf45a4231c","source":"clob_market_ws"},"received_at":"2026-07-28T04:10:34.415755Z","record_id":"c627d2950fbca9b16855e9830cd9c2a0045a2eda784ed441348d5a3f9d19e3c3","schema_fingerprint":"4aa3821a28b0b7c2400bc59aba4bcc0a76e971dadd19610d3ad38c768e124dc7","schema_version":"edge-lab-recorder.raw.v1","sequence":null,"source":"clob_market_ws"}
{"event_at":"2026-07-28T04:10:33.961000Z","event_fingerprint":"54283018ff3a6dd06910b8213bb71187e38f3b77b305accb8b3d6409c0046e16","payload":{"connection_id":"f6725804f86a4c4eb588e4d5ed7db029","event_at":"2026-07-28T04:10:33.961000Z","event_type":"price_change","frame_hash":"9e0cd6efd0a8af153db4e72061743d9b6aabaf61f2e1f4d7045e6aa901551b94","frame_index":0,"kind":"data","monotonic_ns":313817496511333,"payload":{"event_type":"price_change","market":"0xd412ce774cfcf8dc9f71164aac78783978aac7b03871702a3b8a481bd9dc9688","price_changes":[{"asset_id":"107603864457683460275633293642179940881969192120168665300712204232021063124301","best_ask":"0.66","best_bid":"0.64","hash":"080949543ea3110e96de9cc455ee8c2077bf1ac0","price":"0.62","side":"BUY","size":"37.6"},{"asset_id":"96600821790790307414914106093858868634329285205417149685270682748367152458577","best_ask":"0.36","best_bid":"0.34","hash":"427a75bc1d7ab55ef04904e99345aafe3a25f084","price":"0.38","side":"SELL","size":"37.6"}],"timestamp":"1785211833961"},"payload_hash":"76e8015c3c6ee12366d9fa1218c4d1ed63fe736f81c1806220dc543085824b99","raw_frame":"{\"market\":\"0xd412ce774cfcf8dc9f71164aac78783978aac7b03871702a3b8a481bd9dc9688\", \"price_changes\":[{\"asset_id\":\"107603864457683460275633293642179940881969192120168665300712204232021063124301\", \"price\":\"0.62\", \"size\":\"37.6\", \"side\":\"BUY\", \"hash\":\"080949543ea3110e96de9cc455ee8c2077bf1ac0\", \"best_bid\":\"0.64\", \"best_ask\":\"0.66\"}, {\"asset_id\":\"96600821790790307414914106093858868634329285205417149685270682748367152458577\", \"price\":\"0.38\", \"size\":\"37.6\", \"side\":\"SELL\", \"hash\":\"427a75bc1d7ab55ef04904e99345aafe3a25f084\", \"best_bid\":\"0.34\", \"best_ask\":\"0.36\"}], \"timestamp\":\"1785211833961\", \"event_type\":\"price_change\"}","received_at":"2026-07-28T04:10:34.420287Z","schema_version":"clob-market-ws.price_change.v1","sequence":null,"server_hash":null,"server_timestamp":"1785211833961","session_id":"2d607381e3054cee91998cdf45a4231c","source":"clob_market_ws"},"received_at":"2026-07-28T04:10:34.420287Z","record_id":"e0577652bbad67df3692f39558cce7f94cfb8bbe14821852ddbb1433e2f53467","schema_fingerprint":"4aa3821a28b0b7c2400bc59aba4bcc0a76e971dadd19610d3ad38c768e124dc7","schema_version":"edge-lab-recorder.raw.v1","sequence":null,"source":"clob_market_ws"}
{"event_at":"2026-07-28T04:10:33.962000Z","event_fingerprint":"248d367be4935a76f37c7adeff5a1abcbefeb1b8a85cde15a16bb841dadb5cd6","payload":{"connection_id":"f6725804f86a4c4eb588e4d5ed7db029","event_at":"2026-07-28T04:10:33.962000Z","event_type":"price_change","frame_hash":"c2a402bf5b0320510356c25d044875f9aea7078622e74f32395623b768a85fc4","frame_index":0,"kind":"data","monotonic_ns":313817509180208,"payload":{"event_type":"price_change","market":"0xd412ce774cfcf8dc9f71164aac78783978aac7b03871702a3b8a481bd9dc9688","price_changes":[{"asset_id":"96600821790790307414914106093858868634329285205417149685270682748367152458577","best_ask":"0.36","best_bid":"0.34","hash":"b2a8afc0eab9396ca44e6f1c10cf7b3422a1248b","price":"0.22","side":"BUY","size":"137.5"},{"asset_id":"107603864457683460275633293642179940881969192120168665300712204232021063124301","best_ask":"0.66","best_bid":"0.64","hash":"7c24f2bba994a080d5c346d36146be52348be82e","price":"0.78","side":"SELL","size":"137.5"}],"timestamp":"1785211833962"},"payload_hash":"2d2a3c3041fc8ed0905302fc4b186565a6f3390adc4ca0a7a80d3375e3206196","raw_frame":"{\"market\":\"0xd412ce774cfcf8dc9f71164aac78783978aac7b03871702a3b8a481bd9dc9688\", \"price_changes\":[{\"asset_id\":\"96600821790790307414914106093858868634329285205417149685270682748367152458577\", \"price\":\"0.22\", \"size\":\"137.5\", \"side\":\"BUY\", \"hash\":\"b2a8afc0eab9396ca44e6f1c10cf7b3422a1248b\", \"best_bid\":\"0.34\", \"best_ask\":\"0.36\"}, {\"asset_id\":\"107603864457683460275633293642179940881969192120168665300712204232021063124301\", \"price\":\"0.78\", \"size\":\"137.5\", \"side\":\"SELL\", \"hash\":\"7c24f2bba994a080d5c346d36146be52348be82e\", \"best_bid\":\"0.64\", \"best_ask\":\"0.66\"}], \"timestamp\":\"1785211833962\", \"event_type\":\"price_change\"}","received_at":"2026-07-28T04:10:34.432956Z","schema_version":"clob-market-ws.price_change.v1","sequence":null,"server_hash":null,"server_timestamp":"1785211833962","session_id":"2d607381e3054cee91998cdf45a4231c","source":"clob_market_ws"},"received_at":"2026-07-28T04:10:34.432956Z","record_id":"5c32588825d07f21dc3d47c0d4c9871ef3aa2344170cc5f77cdcd506ac52721e","schema_fingerprint":"4aa3821a28b0b7c2400bc59aba4bcc0a76e971dadd19610d3ad38c768e124dc7","schema_version":"edge-lab-recorder.raw.v1","sequence":null,"source":"clob_market_ws"}
{"event_at":"2026-07-28T04:10:33.962000Z","event_fingerprint":"da3f0fb4d7d56f8b1eae875ed71f66e7e4646936b8921e80f17a9d04a39b831f","payload":{"connection_id":"f6725804f86a4c4eb588e4d5ed7db029","event_at":"2026-07-28T04:10:33.962000Z","event_type":"price_change","frame_hash":"15fecb7ccd39e4a82446ee11fcb9c5e20444d320dc896bc9c2613537cdc47858","frame_index":0,"kind":"data","monotonic_ns":313817513292750,"payload":{"event_type":"price_change","market":"0xd412ce774cfcf8dc9f71164aac78783978aac7b03871702a3b8a481bd9dc9688","price_changes":[{"asset_id":"96600821790790307414914106093858868634329285205417149685270682748367152458577","best_ask":"0.36","best_bid":"0.34","hash":"aa0e442dc9fa969f3d222cd900d96b94fc49140d","price":"0.32","side":"BUY","size":"27"},{"asset_id":"107603864457683460275633293642179940881969192120168665300712204232021063124301","best_ask":"0.66","best_bid":"0.64","hash":"c0cf9bb6acdb6384c42acf620b64776ec5a20b28","price":"0.68","side":"SELL","size":"27"}],"timestamp":"1785211833962"},"payload_hash":"4b02c44320d77a11932a699b8ab00300e8db4dcc941ba42fd489a86a27e49396","raw_frame":"{\"market\":\"0xd412ce774cfcf8dc9f71164aac78783978aac7b03871702a3b8a481bd9dc9688\", \"price_changes\":[{\"asset_id\":\"96600821790790307414914106093858868634329285205417149685270682748367152458577\", \"price\":\"0.32\", \"size\":\"27\", \"side\":\"BUY\", \"hash\":\"aa0e442dc9fa969f3d222cd900d96b94fc49140d\", \"best_bid\":\"0.34\", \"best_ask\":\"0.36\"}, {\"asset_id\":\"107603864457683460275633293642179940881969192120168665300712204232021063124301\", \"price\":\"0.68\", \"size\":\"27\", \"side\":\"SELL\", \"hash\":\"c0cf9bb6acdb6384c42acf620b64776ec5a20b28\", \"best_bid\":\"0.64\", \"best_ask\":\"0.66\"}], \"timestamp\":\"1785211833962\", \"event_type\":\"price_change\"}","received_at":"2026-07-28T04:10:34.437068Z","schema_version":"clob-market-ws.price_change.v1","sequence":null,"server_hash":null,"server_timestamp":"1785211833962","session_id":"2d607381e3054cee91998cdf45a4231c","source":"clob_market_ws"},"received_at":"2026-07-28T04:10:34.437068Z","record_id":"96a5c308174097c6140eddfd58831b16de209835343e52729b6b7039ce7daf43","schema_fingerprint":"4aa3821a28b0b7c2400bc59aba4bcc0a76e971dadd19610d3ad38c768e124dc7","schema_version":"edge-lab-recorder.raw.v1","sequence":null,"source":"clob_market_ws"}
{"event_at":"2026-07-28T04:10:33.962000Z","event_fingerprint":"6920985a16e556960b03686d0c6cb32cb26bd3e41b485243429c48bc34514fb2","payload":{"connection_id":"f6725804f86a4c4eb588e4d5ed7db029","event_at":"2026-07-28T04:10:33.962000Z","event_type":"price_change","frame_hash":"f3b4d4994d0e79af37b135561e566f3c7eb3c81773a99ee1846523146de8a74c","frame_index":0,"kind":"data","monotonic_ns":313817522160041,"payload":{"event_type":"price_change","market":"0xd412ce774cfcf8dc9f71164aac78783978aac7b03871702a3b8a481bd9dc9688","price_changes":[{"asset_id":"96600821790790307414914106093858868634329285205417149685270682748367152458577","best_ask":"0.36","best_bid":"0.34","hash":"0de2e9b9a65c68a1a5e44c7287bede16c7c1aee4","price":"0.25","side":"BUY","size":"259.61"},{"asset_id":"107603864457683460275633293642179940881969192120168665300712204232021063124301","best_ask":"0.66","best_bid":"0.64","hash":"ee59112a324bcf8a36bc01becf84f06db30a3202","price":"0.75","side":"SELL","size":"259.61"}],"timestamp":"1785211833962"},"payload_hash":"47a1e0c0a8d00e730ddf51a7af0d517c95e97448876211232ad2a1e619965817","raw_frame":"{\"market\":\"0xd412ce774cfcf8dc9f71164aac78783978aac7b03871702a3b8a481bd9dc9688\", \"price_changes\":[{\"asset_id\":\"96600821790790307414914106093858868634329285205417149685270682748367152458577\", \"price\":\"0.25\", \"size\":\"259.61\", \"side\":\"BUY\", \"hash\":\"0de2e9b9a65c68a1a5e44c7287bede16c7c1aee4\", \"best_bid\":\"0.34\", \"best_ask\":\"0.36\"}, {\"asset_id\":\"107603864457683460275633293642179940881969192120168665300712204232021063124301\", \"price\":\"0.75\", \"size\":\"259.61\", \"side\":\"SELL\", \"hash\":\"ee59112a324bcf8a36bc01becf84f06db30a3202\", \"best_bid\":\"0.64\", \"best_ask\":\"0.66\"}], \"timestamp\":\"1785211833962\", \"event_type\":\"price_change\"}","received_at":"2026-07-28T04:10:34.445936Z","schema_version":"clob-market-ws.price_change.v1","sequence":null,"server_hash":null,"server_timestamp":"1785211833962","session_id":"2d607381e3054cee91998cdf45a4231c","source":"clob_market_ws"},"received_at":"2026-07-28T04:10:34.445936Z","record_id":"dbbb7afd2f4687ffa5a0454c9324aca90f562603a737bfc90da1180d30dd730c","schema_fingerprint":"4aa3821a28b0b7c2400bc59aba4bcc0a76e971dadd19610d3ad38c768e124dc7","schema_version":"edge-lab-recorder.raw.v1","sequence":null,"source":"clob_market_ws"}
{"event_at":"2026-07-28T04:10:33.963000Z","event_fingerprint":"126f6512851de041132f1aaf2c0fa42556524b4550bf82fcc92ee20a746870a1","payload":{"connection_id":"f6725804f86a4c4eb588e4d5ed7db029","event_at":"2026-07-28T04:10:33.963000Z","event_type":"price_change","frame_hash":"88254f7e43b88204173ddaf01d6b36fb7f038e7f383ac4a14470c1f0b5478704","frame_index":0,"kind":"data","monotonic_ns":313817527596291,"payload":{"event_type":"price_change","market":"0xd412ce774cfcf8dc9f71164aac78783978aac7b03871702a3b8a481bd9dc9688","price_changes":[{"asset_id":"96600821790790307414914106093858868634329285205417149685270682748367152458577","best_ask":"0.36","best_bid":"0.34","hash":"3e7adf4fde23ccfb2dc865220dd79b6fa9ce0e23","price":"0.33","side":"BUY","size":"77.38"},{"asset_id":"107603864457683460275633293642179940881969192120168665300712204232021063124301","best_ask":"0.66","best_bid":"0.64","hash":"77dbae01468952364b52e1ae98e81861f4101432","price":"0.67","side":"SELL","size":"77.38"}],"timestamp":"1785211833963"},"payload_hash":"8be1636dd6e936eeea9f015d73c7ea4387180227b84d887241d9879555ca56bf","raw_frame":"{\"market\":\"0xd412ce774cfcf8dc9f71164aac78783978aac7b03871702a3b8a481bd9dc9688\", \"price_changes\":[{\"asset_id\":\"96600821790790307414914106093858868634329285205417149685270682748367152458577\", \"price\":\"0.33\", \"size\":\"77.38\", \"side\":\"BUY\", \"hash\":\"3e7adf4fde23ccfb2dc865220dd79b6fa9ce0e23\", \"best_bid\":\"0.34\", \"best_ask\":\"0.36\"}, {\"asset_id\":\"107603864457683460275633293642179940881969192120168665300712204232021063124301\", \"price\":\"0.67\", \"size\":\"77.38\", \"side\":\"SELL\", \"hash\":\"77dbae01468952364b52e1ae98e81861f4101432\", \"best_bid\":\"0.64\", \"best_ask\":\"0.66\"}], \"timestamp\":\"1785211833963\", \"event_type\":\"price_change\"}","received_at":"2026-07-28T04:10:34.451372Z","schema_version":"clob-market-ws.price_change.v1","sequence":null,"server_hash":null,"server_timestamp":"1785211833963","session_id":"2d607381e3054cee91998cdf45a4231c","source":"clob_market_ws"},"received_at":"2026-07-28T04:10:34.451372Z","record_id":"d0e99d63723c3ce0c608cc8c7ddb31f78ef2da1fc9c1ed740a51503a24a249de","schema_fingerprint":"4aa3821a28b0b7c2400bc59aba4bcc0a76e971dadd19610d3ad38c768e124dc7","schema_version":"edge-lab-recorder.raw.v1","sequence":null,"source":"clob_market_ws"}
{"event_at":"2026-07-28T04:10:33.963000Z","event_fingerprint":"de034d492deaec31f889778ea5ddf78abb0785259ba6baf8d9872cd8e63fc117","payload":{"connection_id":"f6725804f86a4c4eb588e4d5ed7db029","event_at":"2026-07-28T04:10:33.963000Z","event_type":"price_change","frame_hash":"24c563adf913e4b304d2461f644f135e85e501bfa50d32a9167f5b4684e64f68","frame_index":0,"kind":"data","monotonic_ns":313817532047500,"payload":{"event_type":"price_change","market":"0xd412ce774cfcf8dc9f71164aac78783978aac7b03871702a3b8a481bd9dc9688","price_changes":[{"asset_id":"107603864457683460275633293642179940881969192120168665300712204232021063124301","best_ask":"0.66","best_bid":"0.64","hash":"1bc38ace7e94d2c2bf973c2ded276fab339de8a2","price":"0.59","side":"BUY","size":"131.6"},{"asset_id":"96600821790790307414914106093858868634329285205417149685270682748367152458577","best_ask":"0.36","best_bid":"0.34","hash":"5b080b2015d288a365a2af3827b376e180091bb1","price":"0.41","side":"SELL","size":"131.6"}],"timestamp":"1785211833963"},"payload_hash":"f6a02f989856da3a06012c7e1f7d43da5a5729b6802e6cadf25012776c251cbe","raw_frame":"{\"market\":\"0xd412ce774cfcf8dc9f71164aac78783978aac7b03871702a3b8a481bd9dc9688\", \"price_changes\":[{\"asset_id\":\"107603864457683460275633293642179940881969192120168665300712204232021063124301\", \"price\":\"0.59\", \"size\":\"131.6\", \"side\":\"BUY\", \"hash\":\"1bc38ace7e94d2c2bf973c2ded276fab339de8a2\", \"best_bid\":\"0.64\", \"best_ask\":\"0.66\"}, {\"asset_id\":\"96600821790790307414914106093858868634329285205417149685270682748367152458577\", \"price\":\"0.41\", \"size\":\"131.6\", \"side\":\"SELL\", \"hash\":\"5b080b2015d288a365a2af3827b376e180091bb1\", \"best_bid\":\"0.34\", \"best_ask\":\"0.36\"}], \"timestamp\":\"1785211833963\", \"event_type\":\"price_change\"}","received_at":"2026-07-28T04:10:34.455823Z","schema_version":"clob-market-ws.price_change.v1","sequence":null,"server_hash":null,"server_timestamp":"1785211833963","session_id":"2d607381e3054cee91998cdf45a4231c","source":"clob_market_ws"},"received_at":"2026-07-28T04:10:34.455823Z","record_id":"9f793f1bdbdd2d863cf27d99d07e20e427a91107c93822e9b64577ecebc47087","schema_fingerprint":"4aa3821a28b0b7c2400bc59aba4bcc0a76e971dadd19610d3ad38c768e124dc7","schema_version":"edge-lab-recorder.raw.v1","sequence":null,"source":"clob_market_ws"}
{"event_at":"2026-07-28T04:10:33.964000Z","event_fingerprint":"b9500cf6c44515544eb504a2386a2474da28512b8aee1593cbf2daba9ca8cb74","payload":{"connection_id":"f6725804f86a4c4eb588e4d5ed7db029","event_at":"2026-07-28T04:10:33.964000Z","event_type":"price_change","frame_hash":"92224c01d47bbef3619981c0d836210db0d4cfed0c299fceb1feab89fbf90e59","frame_index":0,"kind":"data","monotonic_ns":313817537008833,"payload":{"event_type":"price_change","market":"0xd412ce774cfcf8dc9f71164aac78783978aac7b03871702a3b8a481bd9dc9688","price_changes":[{"asset_id":"96600821790790307414914106093858868634329285205417149685270682748367152458577","best_ask":"0.36","best_bid":"0.34","hash":"2b85ddebb6e069846f755c028a4f28cf1581f68c","price":"0.22","side":"BUY","size":"228.5"},{"asset_id":"107603864457683460275633293642179940881969192120168665300712204232021063124301","best_ask":"0.66","best_bid":"0.64","hash":"df72c65a4033ef07e716aeb99a68107cc7a0f563","price":"0.78","side":"SELL","size":"228.5"}],"timestamp":"1785211833964"},"payload_hash":"ac9067ed11acf295ba8298de0d62a71c63d97c4bbde3dd2ef54f524f596c3f9a","raw_frame":"{\"market\":\"0xd412ce774cfcf8dc9f71164aac78783978aac7b03871702a3b8a481bd9dc9688\", \"price_changes\":[{\"asset_id\":\"96600821790790307414914106093858868634329285205417149685270682748367152458577\", \"price\":\"0.22\", \"size\":\"228.5\", \"side\":\"BUY\", \"hash\":\"2b85ddebb6e069846f755c028a4f28cf1581f68c\", \"best_bid\":\"0.34\", \"best_ask\":\"0.36\"}, {\"asset_id\":\"107603864457683460275633293642179940881969192120168665300712204232021063124301\", \"price\":\"0.78\", \"size\":\"228.5\", \"side\":\"SELL\", \"hash\":\"df72c65a4033ef07e716aeb99a68107cc7a0f563\", \"best_bid\":\"0.64\", \"best_ask\":\"0.66\"}], \"timestamp\":\"1785211833964\", \"event_type\":\"price_change\"}","received_at":"2026-07-28T04:10:34.460785Z","schema_version":"clob-market-ws.price_change.v1","sequence":null,"server_hash":null,"server_timestamp":"1785211833964","session_id":"2d607381e3054cee91998cdf45a4231c","source":"clob_market_ws"},"received_at":"2026-07-28T04:10:34.460785Z","record_id":"1b5fe94f349d4526b73ffd5189db4a69a631575384f9e9f13f516e776c33b662","schema_fingerprint":"4aa3821a28b0b7c2400bc59aba4bcc0a76e971dadd19610d3ad38c768e124dc7","schema_version":"edge-lab-recorder.raw.v1","sequence":null,"source":"clob_market_ws"}
{"event_at":"2026-07-28T04:10:33.964000Z","event_fingerprint":"e0ddce3ddd8d86f5e3ea4b3a95d8dbaa1e7cebf5cc4dbce4a5702c8c6986574e","payload":{"connection_id":"f6725804f86a4c4eb588e4d5ed7db029","event_at":"2026-07-28T04:10:33.964000Z","event_type":"price_change","frame_hash":"593eed539ab827451a44738b926d9670f4449630d1c9305c9a39b434d8e7b384","frame_index":0,"kind":"data","monotonic_ns":313817541342208,"payload":{"event_type":"price_change","market":"0xd412ce774cfcf8dc9f71164aac78783978aac7b03871702a3b8a481bd9dc9688","price_changes":[{"asset_id":"107603864457683460275633293642179940881969192120168665300712204232021063124301","best_ask":"0.66","best_bid":"0.64","hash":"9503c7820a735de41a44bb67e660cf02647d405f","price":"0.59","side":"BUY","size":"125.6"},{"asset_id":"96600821790790307414914106093858868634329285205417149685270682748367152458577","best_ask":"0.36","best_bid":"0.34","hash":"84d98567f946e5dcae417b1582a6aa7b7e73501a","price":"0.41","side":"SELL","size":"125.6"}],"timestamp":"1785211833964"},"payload_hash":"ac8e2bdbcbe91b458e8d4c10eef857d9f7591adb768347f395eb76362401c441","raw_frame":"{\"market\":\"0xd412ce774cfcf8dc9f71164aac78783978aac7b03871702a3b8a481bd9dc9688\", \"price_changes\":[{\"asset_id\":\"107603864457683460275633293642179940881969192120168665300712204232021063124301\", \"price\":\"0.59\", \"size\":\"125.6\", \"side\":\"BUY\", \"hash\":\"9503c7820a735de41a44bb67e660cf02647d405f\", \"best_bid\":\"0.64\", \"best_ask\":\"0.66\"}, {\"asset_id\":\"96600821790790307414914106093858868634329285205417149685270682748367152458577\", \"price\":\"0.41\", \"size\":\"125.6\", \"side\":\"SELL\", \"hash\":\"84d98567f946e5dcae417b1582a6aa7b7e73501a\", \"best_bid\":\"0.34\", \"best_ask\":\"0.36\"}], \"timestamp\":\"1785211833964\", \"event_type\":\"price_change\"}","received_at":"2026-07-28T04:10:34.465118Z","schema_version":"clob-market-ws.price_change.v1","sequence":null,"server_hash":null,"server_timestamp":"1785211833964","session_id":"2d607381e3054cee91998cdf45a4231c","source":"clob_market_ws"},"received_at":"2026-07-28T04:10:34.465118Z","record_id":"4481bf7e0175e28a52c43487e216adbdaccd6889ee40a22d998726d1805330a3","schema_fingerprint":"4aa3821a28b0b7c2400bc59aba4bcc0a76e971dadd19610d3ad38c768e124dc7","schema_version":"edge-lab-recorder.raw.v1","sequence":null,"source":"clob_market_ws"}
{"event_at":"2026-07-28T04:10:33.964000Z","event_fingerprint":"d2a1ac421b0e397e378b19b76c0ad4d5ae96a4714ca9168659999a5f9f3c9cd1","payload":{"connection_id":"f6725804f86a4c4eb588e4d5ed7db029","event_at":"2026-07-28T04:10:33.964000Z","event_type":"price_change","frame_hash":"66c4b5debbd0db69f2f994c0ae770c88b010acbb99fd530dc7daaf9e16d7e87f","frame_index":0,"kind":"data","monotonic_ns":313817546513166,"payload":{"event_type":"price_change","market":"0xd412ce774cfcf8dc9f71164aac78783978aac7b03871702a3b8a481bd9dc9688","price_changes":[{"asset_id":"96600821790790307414914106093858868634329285205417149685270682748367152458577","best_ask":"0.36","best_bid":"0.34","hash":"cb8e4210bc3a1a1ce707a11074b4b25e5798053b","price":"0.25","side":"BUY","size":"253.61"},{"asset_id":"107603864457683460275633293642179940881969192120168665300712204232021063124301","best_ask":"0.66","best_bid":"0.64","hash":"e63ffd52fc60366af8a361a792b6c0e63b739cc2","price":"0.75","side":"SELL","size":"253.61"}],"timestamp":"1785211833964"},"payload_hash":"ce04ceee3633d01158b36d4db72e2fdeb8ac2ffe0d43cdd0d838221f2103c147","raw_frame":"{\"market\":\"0xd412ce774cfcf8dc9f71164aac78783978aac7b03871702a3b8a481bd9dc9688\", \"price_changes\":[{\"asset_id\":\"96600821790790307414914106093858868634329285205417149685270682748367152458577\", \"price\":\"0.25\", \"size\":\"253.61\", \"side\":\"BUY\", \"hash\":\"cb8e4210bc3a1a1ce707a11074b4b25e5798053b\", \"best_bid\":\"0.34\", \"best_ask\":\"0.36\"}, {\"asset_id\":\"107603864457683460275633293642179940881969192120168665300712204232021063124301\", \"price\":\"0.75\", \"size\":\"253.61\", \"side\":\"SELL\", \"hash\":\"e63ffd52fc60366af8a361a792b6c0e63b739cc2\", \"best_bid\":\"0.64\", \"best_ask\":\"0.66\"}], \"timestamp\":\"1785211833964\", \"event_type\":\"price_change\"}","received_at":"2026-07-28T04:10:34.470289Z","schema_version":"clob-market-ws.price_change.v1","sequence":null,"server_hash":null,"server_timestamp":"1785211833964","session_id":"2d607381e3054cee91998cdf45a4231c","source":"clob_market_ws"},"received_at":"2026-07-28T04:10:34.470289Z","record_id":"c3340c4090f94b779e6b62901b061579b21260e3333afb4d3fe4e9c5949ad358","schema_fingerprint":"4aa3821a28b0b7c2400bc59aba4bcc0a76e971dadd19610d3ad38c768e124dc7","schema_version":"edge-lab-recorder.raw.v1","sequence":null,"source":"clob_market_ws"}
{"event_at":"2026-07-28T04:10:33.965000Z","event_fingerprint":"4f9b37f3a0c5f86197eeca06cbb93abb4592b3572f9b09a9b3c10134ec89ea47","payload":{"connection_id":"f6725804f86a4c4eb588e4d5ed7db029","event_at":"2026-07-28T04:10:33.965000Z","event_type":"price_change","frame_hash":"90e2d06c81c5cb21bfe9ec7a4959a4af6bdb190ce8bf35e4bd29d241ec0958bc","frame_index":0,"kind":"data","monotonic_ns":313817550567875,"payload":{"event_type":"price_change","market":"0xd412ce774cfcf8dc9f71164aac78783978aac7b03871702a3b8a481bd9dc9688","price_changes":[{"asset_id":"107603864457683460275633293642179940881969192120168665300712204232021063124301","best_ask":"0.66","best_bid":"0.64","hash":"88c5dd5014e5208085339b7ef7c0888885b23f03","price":"0.64","side":"BUY","size":"174.03"},{"asset_id":"96600821790790307414914106093858868634329285205417149685270682748367152458577","best_ask":"0.36","best_bid":"0.34","hash":"65986dd59f5ee7773af5b014bcbad622fa7fdba4","price":"0.36","side":"SELL","size":"174.03"}],"timestamp":"1785211833965"},"payload_hash":"4c81d632281dabd109dade56cd7b07df76302bf10ed8123ae2804bdbb747dde8","raw_frame":"{\"market\":\"0xd412ce774cfcf8dc9f71164aac78783978aac7b03871702a3b8a481bd9dc9688\", \"price_changes\":[{\"asset_id\":\"107603864457683460275633293642179940881969192120168665300712204232021063124301\", \"price\":\"0.64\", \"size\":\"174.03\", \"side\":\"BUY\", \"hash\":\"88c5dd5014e5208085339b7ef7c0888885b23f03\", \"best_bid\":\"0.64\", \"best_ask\":\"0.66\"}, {\"asset_id\":\"96600821790790307414914106093858868634329285205417149685270682748367152458577\", \"price\":\"0.36\", \"size\":\"174.03\", \"side\":\"SELL\", \"hash\":\"65986dd59f5ee7773af5b014bcbad622fa7fdba4\", \"best_bid\":\"0.34\", \"best_ask\":\"0.36\"}], \"timestamp\":\"1785211833965\", \"event_type\":\"price_change\"}","received_at":"2026-07-28T04:10:34.474344Z","schema_version":"clob-market-ws.price_change.v1","sequence":null,"server_hash":null,"server_timestamp":"1785211833965","session_id":"2d607381e3054cee91998cdf45a4231c","source":"clob_market_ws"},"received_at":"2026-07-28T04:10:34.474344Z","record_id":"fcbb670dd04edb9548508a382b181f91ca4eb1b7d8933e77e84354304bce7f87","schema_fingerprint":"4aa3821a28b0b7c2400bc59aba4bcc0a76e971dadd19610d3ad38c768e124dc7","schema_version":"edge-lab-recorder.raw.v1","sequence":null,"source":"clob_market_ws"}
{"event_at":"2026-07-28T04:10:33.965000Z","event_fingerprint":"94d10dab07fb30a77e12bd533af10a7a6458a7ab47f2bae52db7fb3e4a41891f","payload":{"connection_id":"f6725804f86a4c4eb588e4d5ed7db029","event_at":"2026-07-28T04:10:33.965000Z","event_type":"price_change","frame_hash":"748a5666305fcb82815120b8d0f0bd29f2e0acfc6912c1f07e4798bdaadac9a1","frame_index":0,"kind":"data","monotonic_ns":313817554819125,"payload":{"event_type":"price_change","market":"0xd412ce774cfcf8dc9f71164aac78783978aac7b03871702a3b8a481bd9dc9688","price_changes":[{"asset_id":"96600821790790307414914106093858868634329285205417149685270682748367152458577","best_ask":"0.36","best_bid":"0.34","hash":"3ecff1070f9bc84e9b3b0a7ea6fe57e2cba480ae","price":"0.29","side":"BUY","size":"119"},{"asset_id":"107603864457683460275633293642179940881969192120168665300712204232021063124301","best_ask":"0.66","best_bid":"0.64","hash":"cfa184f53e13a0ce550dbc85dab878dbbb586ab5","price":"0.71","side":"SELL","size":"119"}],"timestamp":"1785211833965"},"payload_hash":"a3a924938eb6e0b70f5b8f520ec28bae848107cfdbadfe7f87e9869b3fbb2dd0","raw_frame":"{\"market\":\"0xd412ce774cfcf8dc9f71164aac78783978aac7b03871702a3b8a481bd9dc9688\", \"price_changes\":[{\"asset_id\":\"96600821790790307414914106093858868634329285205417149685270682748367152458577\", \"price\":\"0.29\", \"size\":\"119\", \"side\":\"BUY\", \"hash\":\"3ecff1070f9bc84e9b3b0a7ea6fe57e2cba480ae\", \"best_bid\":\"0.34\", \"best_ask\":\"0.36\"}, {\"asset_id\":\"107603864457683460275633293642179940881969192120168665300712204232021063124301\", \"price\":\"0.71\", \"size\":\"119\", \"side\":\"SELL\", \"hash\":\"cfa184f53e13a0ce550dbc85dab878dbbb586ab5\", \"best_bid\":\"0.64\", \"best_ask\":\"0.66\"}], \"timestamp\":\"1785211833965\", \"event_type\":\"price_change\"}","received_at":"2026-07-28T04:10:34.478594Z","schema_version":"clob-market-ws.price_change.v1","sequence":null,"server_hash":null,"server_timestamp":"1785211833965","session_id":"2d607381e3054cee91998cdf45a4231c","source":"clob_market_ws"},"received_at":"2026-07-28T04:10:34.478594Z","record_id":"3649c44de7a629cd287433e8ae2a1a4805ffa7bc9f1577dda1b5068020c720b1","schema_fingerprint":"4aa3821a28b0b7c2400bc59aba4bcc0a76e971dadd19610d3ad38c768e124dc7","schema_version":"edge-lab-recorder.raw.v1","sequence":null,"source":"clob_market_ws"}
{"event_at":"2026-07-28T04:10:33.965000Z","event_fingerprint":"44bb77cf3db14cc2d113be364dbaeb1276169abe6610a61c71855db4efcd2f23","payload":{"connection_id":"f6725804f86a4c4eb588e4d5ed7db029","event_at":"2026-07-28T04:10:33.965000Z","event_type":"price_change","frame_hash":"343b812744a45617c8d92ac3a13f3edd0727dbd16eb1ef760eb138df05216608","frame_index":0,"kind":"data","monotonic_ns":313817559134916,"payload":{"event_type":"price_change","market":"0xd412ce774cfcf8dc9f71164aac78783978aac7b03871702a3b8a481bd9dc9688","price_changes":[{"asset_id":"96600821790790307414914106093858868634329285205417149685270682748367152458577","best_ask":"0.36","best_bid":"0.34","hash":"80cfaf6a4dbb11d3c27322ffde88a37a5d21b5c3","price":"0.28","side":"BUY","size":"228.49"},{"asset_id":"107603864457683460275633293642179940881969192120168665300712204232021063124301","best_ask":"0.66","best_bid":"0.64","hash":"5849609924634ce87b375f7e9a818729bf4a9be0","price":"0.72","side":"SELL","size":"228.49"}],"timestamp":"1785211833965"},"payload_hash":"fe7ad5332ace560337edc8350c8da7c1c2226188c795e1187900dd48e8bef79b","raw_frame":"{\"market\":\"0xd412ce774cfcf8dc9f71164aac78783978aac7b03871702a3b8a481bd9dc9688\", \"price_changes\":[{\"asset_id\":\"96600821790790307414914106093858868634329285205417149685270682748367152458577\", \"price\":\"0.28\", \"size\":\"228.49\", \"side\":\"BUY\", \"hash\":\"80cfaf6a4dbb11d3c27322ffde88a37a5d21b5c3\", \"best_bid\":\"0.34\", \"best_ask\":\"0.36\"}, {\"asset_id\":\"107603864457683460275633293642179940881969192120168665300712204232021063124301\", \"price\":\"0.72\", \"size\":\"228.49\", \"side\":\"SELL\", \"hash\":\"5849609924634ce87b375f7e9a818729bf4a9be0\", \"best_bid\":\"0.64\", \"best_ask\":\"0.66\"}], \"timestamp\":\"1785211833965\", \"event_type\":\"price_change\"}","received_at":"2026-07-28T04:10:34.482911Z","schema_version":"clob-market-ws.price_change.v1","sequence":null,"server_hash":null,"server_timestamp":"1785211833965","session_id":"2d607381e3054cee91998cdf45a4231c","source":"clob_market_ws"},"received_at":"2026-07-28T04:10:34.482911Z","record_id":"7ce6dbcab899afbfc1e6254948e0e388f79fbc679710be8472d71c80e85641b8","schema_fingerprint":"4aa3821a28b0b7c2400bc59aba4bcc0a76e971dadd19610d3ad38c768e124dc7","schema_version":"edge-lab-recorder.raw.v1","sequence":null,"source":"clob_market_ws"}
{"event_at":"2026-07-28T04:10:33.965000Z","event_fingerprint":"aee5028905f260fe669274c318c3156d578f0491775558934e7b3cd408b440d2","payload":{"connection_id":"f6725804f86a4c4eb588e4d5ed7db029","event_at":"2026-07-28T04:10:33.965000Z","event_type":"price_change","frame_hash":"a67690c5920a81fb8e89045bafd09a7f3f8638160f0d98956341a0b3727f60f0","frame_index":0,"kind":"data","monotonic_ns":313817563459291,"payload":{"event_type":"price_change","market":"0xd412ce774cfcf8dc9f71164aac78783978aac7b03871702a3b8a481bd9dc9688","price_changes":[{"asset_id":"107603864457683460275633293642179940881969192120168665300712204232021063124301","best_ask":"0.66","best_bid":"0.64","hash":"a7c8613bf61f57a8b6c7c4ec720275dd69ab01c3","price":"0.33","side":"BUY","size":"160.61"},{"asset_id":"96600821790790307414914106093858868634329285205417149685270682748367152458577","best_ask":"0.36","best_bid":"0.34","hash":"839e6a2a374514c41558d4f44e60f60d234af795","price":"0.67","side":"SELL","size":"160.61"}],"timestamp":"1785211833965"},"payload_hash":"d22347a68f36af76228d041972270e781b9ebf7fd90c71a3560cf2b40e135537","raw_frame":"{\"market\":\"0xd412ce774cfcf8dc9f71164aac78783978aac7b03871702a3b8a481bd9dc9688\", \"price_changes\":[{\"asset_id\":\"107603864457683460275633293642179940881969192120168665300712204232021063124301\", \"price\":\"0.33\", \"size\":\"160.61\", \"side\":\"BUY\", \"hash\":\"a7c8613bf61f57a8b6c7c4ec720275dd69ab01c3\", \"best_bid\":\"0.64\", \"best_ask\":\"0.66\"}, {\"asset_id\":\"96600821790790307414914106093858868634329285205417149685270682748367152458577\", \"price\":\"0.67\", \"size\":\"160.61\", \"side\":\"SELL\", \"hash\":\"839e6a2a374514c41558d4f44e60f60d234af795\", \"best_bid\":\"0.34\", \"best_ask\":\"0.36\"}], \"timestamp\":\"1785211833965\", \"event_type\":\"price_change\"}","received_at":"2026-07-28T04:10:34.487234Z","schema_version":"clob-market-ws.price_change.v1","sequence":null,"server_hash":null,"server_timestamp":"1785211833965","session_id":"2d607381e3054cee91998cdf45a4231c","source":"clob_market_ws"},"received_at":"2026-07-28T04:10:34.487234Z","record_id":"3b1d84b5abed2ac8d21430b6871fc91c688d3c4511b07179e6d2c838ea69fc23","schema_fingerprint":"4aa3821a28b0b7c2400bc59aba4bcc0a76e971dadd19610d3ad38c768e124dc7","schema_version":"edge-lab-recorder.raw.v1","sequence":null,"source":"clob_market_ws"}
{"event_at":"2026-07-28T04:10:33.966000Z","event_fingerprint":"33ca46e8c28bf0b5f5ae2dd6ece2e21ba0e699e39daac447f2290c0a3689b3c1","payload":{"connection_id":"f6725804f86a4c4eb588e4d5ed7db029","event_at":"2026-07-28T04:10:33.966000Z","event_type":"price_change","frame_hash":"25e98d692a6e4ca34fdfff1b13d1a58c1db67c83efbf8f88a281461853823495","frame_index":0,"kind":"data","monotonic_ns":313817567054500,"payload":{"event_type":"price_change","market":"0xd412ce774cfcf8dc9f71164aac78783978aac7b03871702a3b8a481bd9dc9688","price_changes":[{"asset_id":"107603864457683460275633293642179940881969192120168665300712204232021063124301","best_ask":"0.66","best_bid":"0.64","hash":"aa4a7d429f939ff55b2a0e4bd2f96544bbb40d42","price":"0.59","side":"BUY","size":"155.6"},{"asset_id":"96600821790790307414914106093858868634329285205417149685270682748367152458577","best_ask":"0.36","best_bid":"0.34","hash":"3e62f3c5be61f2e55651871ccd6d212983c81a7f","price":"0.41","side":"SELL","size":"155.6"}],"timestamp":"1785211833966"},"payload_hash":"b31d158bd44ad2b88cff1e9c8686dd51cbb1e6bfc8d9ad13a7a1100dcc108be9","raw_frame":"{\"market\":\"0xd412ce774cfcf8dc9f71164aac78783978aac7b03871702a3b8a481bd9dc9688\", \"price_changes\":[{\"asset_id\":\"107603864457683460275633293642179940881969192120168665300712204232021063124301\", \"price\":\"0.59\", \"size\":\"155.6\", \"side\":\"BUY\", \"hash\":\"aa4a7d429f939ff55b2a0e4bd2f96544bbb40d42\", \"best_bid\":\"0.64\", \"best_ask\":\"0.66\"}, {\"asset_id\":\"96600821790790307414914106093858868634329285205417149685270682748367152458577\", \"price\":\"0.41\", \"size\":\"155.6\", \"side\":\"SELL\", \"hash\":\"3e62f3c5be61f2e55651871ccd6d212983c81a7f\", \"best_bid\":\"0.34\", \"best_ask\":\"0.36\"}], \"timestamp\":\"1785211833966\", \"event_type\":\"price_change\"}","received_at":"2026-07-28T04:10:34.490830Z","schema_version":"clob-market-ws.price_change.v1","sequence":null,"server_hash":null,"server_timestamp":"1785211833966","session_id":"2d607381e3054cee91998cdf45a4231c","source":"clob_market_ws"},"received_at":"2026-07-28T04:10:34.490830Z","record_id":"32019c35fb8161a42db6a4646e561125281d720ec3229ebc4e6abc7587c47ceb","schema_fingerprint":"4aa3821a28b0b7c2400bc59aba4bcc0a76e971dadd19610d3ad38c768e124dc7","schema_version":"edge-lab-recorder.raw.v1","sequence":null,"source":"clob_market_ws"}
{"event_at":"2026-07-28T04:10:33.967000Z","event_fingerprint":"99384bb6a97bde14794581b48b6a36e87a0f062f448895aa460e16b46835dc1b","payload":{"connection_id":"f6725804f86a4c4eb588e4d5ed7db029","event_at":"2026-07-28T04:10:33.967000Z","event_type":"price_change","frame_hash":"e171d8cc261866f5c2098e427c381ef326e0771ba406ee63914f02191ca012fa","frame_index":0,"kind":"data","monotonic_ns":313817570175916,"payload":{"event_type":"price_change","market":"0xd412ce774cfcf8dc9f71164aac78783978aac7b03871702a3b8a481bd9dc9688","price_changes":[{"asset_id":"96600821790790307414914106093858868634329285205417149685270682748367152458577","best_ask":"0.36","best_bid":"0.34","hash":"6e0e862c3821d8e73f66166ff9cfe2509d69c26c","price":"0.31","side":"BUY","size":"42"},{"asset_id":"107603864457683460275633293642179940881969192120168665300712204232021063124301","best_ask":"0.66","best_bid":"0.64","hash":"d4295d31b87919a608f309884212f3721fb5d9cb","price":"0.69","side":"SELL","size":"42"}],"timestamp":"1785211833967"},"payload_hash":"5d31dba19ccb7cec73411ddf9c666ba2c6f5b47c1fc80731277c621ffd17f9b1","raw_frame":"{\"market\":\"0xd412ce774cfcf8dc9f71164aac78783978aac7b03871702a3b8a481bd9dc9688\", \"price_changes\":[{\"asset_id\":\"96600821790790307414914106093858868634329285205417149685270682748367152458577\", \"price\":\"0.31\", \"size\":\"42\", \"side\":\"BUY\", \"hash\":\"6e0e862c3821d8e73f66166ff9cfe2509d69c26c\", \"best_bid\":\"0.34\", \"best_ask\":\"0.36\"}, {\"asset_id\":\"107603864457683460275633293642179940881969192120168665300712204232021063124301\", \"price\":\"0.69\", \"size\":\"42\", \"side\":\"SELL\", \"hash\":\"d4295d31b87919a608f309884212f3721fb5d9cb\", \"best_bid\":\"0.64\", \"best_ask\":\"0.66\"}], \"timestamp\":\"1785211833967\", \"event_type\":\"price_change\"}","received_at":"2026-07-28T04:10:34.493951Z","schema_version":"clob-market-ws.price_change.v1","sequence":null,"server_hash":null,"server_timestamp":"1785211833967","session_id":"2d607381e3054cee91998cdf45a4231c","source":"clob_market_ws"},"received_at":"2026-07-28T04:10:34.493951Z","record_id":"e9119dfb42655cb76c718bf672a763b3088ceac4ffc54f54f8257ef2cca1e23e","schema_fingerprint":"4aa3821a28b0b7c2400bc59aba4bcc0a76e971dadd19610d3ad38c768e124dc7","schema_version":"edge-lab-recorder.raw.v1","sequence":null,"source":"clob_market_ws"}
{"event_at":"2026-07-28T04:10:33.967000Z","event_fingerprint":"9f5d4b755390db5b429b531fea051d0c4d66fac1bab31acd51fab49a9901ce6b","payload":{"connection_id":"f6725804f86a4c4eb588e4d5ed7db029","event_at":"2026-07-28T04:10:33.967000Z","event_type":"price_change","frame_hash":"1aa9d31eab34d291e9145e7cd0bc2876d29afe2cc434c0f25839f78d4662d6e8","frame_index":0,"kind":"data","monotonic_ns":313817574473416,"payload":{"event_type":"price_change","market":"0xd412ce774cfcf8dc9f71164aac78783978aac7b03871702a3b8a481bd9dc9688","price_changes":[{"asset_id":"96600821790790307414914106093858868634329285205417149685270682748367152458577","best_ask":"0.36","best_bid":"0.34","hash":"41b45f289d4ab7e22a6becd3d996d4935b07be2a","price":"0.24","side":"BUY","size":"75.39"},{"asset_id":"107603864457683460275633293642179940881969192120168665300712204232021063124301","best_ask":"0.66","best_bid":"0.64","hash":"9450f778d8bb33f7517497196a356177f1cafcb4","price":"0.76","side":"SELL","size":"75.39"}],"timestamp":"1785211833967"},"payload_hash":"55b5d8ae71c9f75bd2bceb4a5b4728926453b2a6b20486150ab71b4045e92d52","raw_frame":"{\"market\":\"0xd412ce774cfcf8dc9f71164aac78783978aac7b03871702a3b8a481bd9dc9688\", \"price_changes\":[{\"asset_id\":\"96600821790790307414914106093858868634329285205417149685270682748367152458577\", \"price\":\"0.24\", \"size\":\"75.39\", \"side\":\"BUY\", \"hash\":\"41b45f289d4ab7e22a6becd3d996d4935b07be2a\", \"best_bid\":\"0.34\", \"best_ask\":\"0.36\"}, {\"asset_id\":\"107603864457683460275633293642179940881969192120168665300712204232021063124301\", \"price\":\"0.76\", \"size\":\"75.39\", \"side\":\"SELL\", \"hash\":\"9450f778d8bb33f7517497196a356177f1cafcb4\", \"best_bid\":\"0.64\", \"best_ask\":\"0.66\"}], \"timestamp\":\"1785211833967\", \"event_type\":\"price_change\"}","received_at":"2026-07-28T04:10:34.498249Z","schema_version":"clob-market-ws.price_change.v1","sequence":null,"server_hash":null,"server_timestamp":"1785211833967","session_id":"2d607381e3054cee91998cdf45a4231c","source":"clob_market_ws"},"received_at":"2026-07-28T04:10:34.498249Z","record_id":"9b240f773497a808d14e6c7856fba5aec98d54a20cec11b4b93aef14b9498880","schema_fingerprint":"4aa3821a28b0b7c2400bc59aba4bcc0a76e971dadd19610d3ad38c768e124dc7","schema_version":"edge-lab-recorder.raw.v1","sequence":null,"source":"clob_market_ws"}
{"event_at":"2026-07-28T04:10:33.967000Z","event_fingerprint":"3efa1eb5350a5fe632a75d42d4298907507f9e8b1ae7d45ffda0a761d1a2c7b1","payload":{"connection_id":"f6725804f86a4c4eb588e4d5ed7db029","event_at":"2026-07-28T04:10:33.967000Z","event_type":"price_change","frame_hash":"570e09e16890f757a8c699013b2bd3bf8b0109f54de32f4b87b2a6d86227b977","frame_index":0,"kind":"data","monotonic_ns":313817578662958,"payload":{"event_type":"price_change","market":"0xd412ce774cfcf8dc9f71164aac78783978aac7b03871702a3b8a481bd9dc9688","price_changes":[{"asset_id":"96600821790790307414914106093858868634329285205417149685270682748367152458577","best_ask":"0.36","best_bid":"0.34","hash":"d00c6fd7509ce312c30ff245033ca66253032b63","price":"0.23","side":"BUY","size":"223.89"},{"asset_id":"107603864457683460275633293642179940881969192120168665300712204232021063124301","best_ask":"0.66","best_bid":"0.64","hash":"0b4493bce225a7e960a6c7e6a0bf8442cf75e0f7","price":"0.77","side":"SELL","size":"223.89"}],"timestamp":"1785211833967"},"payload_hash":"9607a0ffb5661f0ef95b732a5a1b14431a0ce091b67b4a0a0eb79184a4b050f1","raw_frame":"{\"market\":\"0xd412ce774cfcf8dc9f71164aac78783978aac7b03871702a3b8a481bd9dc9688\", \"price_changes\":[{\"asset_id\":\"96600821790790307414914106093858868634329285205417149685270682748367152458577\", \"price\":\"0.23\", \"size\":\"223.89\", \"side\":\"BUY\", \"hash\":\"d00c6fd7509ce312c30ff245033ca66253032b63\", \"best_bid\":\"0.34\", \"best_ask\":\"0.36\"}, {\"asset_id\":\"107603864457683460275633293642179940881969192120168665300712204232021063124301\", \"price\":\"0.77\", \"size\":\"223.89\", \"side\":\"SELL\", \"hash\":\"0b4493bce225a7e960a6c7e6a0bf8442cf75e0f7\", \"best_bid\":\"0.64\", \"best_ask\":\"0.66\"}], \"timestamp\":\"1785211833967\", \"event_type\":\"price_change\"}","received_at":"2026-07-28T04:10:34.502439Z","schema_version":"clob-market-ws.price_change.v1","sequence":null,"server_hash":null,"server_timestamp":"1785211833967","session_id":"2d607381e3054cee91998cdf45a4231c","source":"clob_market_ws"},"received_at":"2026-07-28T04:10:34.502439Z","record_id":"89358d5eddc433974268d8f32807068c7441ba6a4a726426956703bd4420b169","schema_fingerprint":"4aa3821a28b0b7c2400bc59aba4bcc0a76e971dadd19610d3ad38c768e124dc7","schema_version":"edge-lab-recorder.raw.v1","sequence":null,"source":"clob_market_ws"}
