{"event_at":"2026-07-28T04:04:39.282000Z","event_fingerprint":"56e7511ac614a574cb42fd705b2ce607e2588c95acbb23c971a5df683d1f851a","payload":{"connection_id":"f6725804f86a4c4eb588e4d5ed7db029","event_at":"2026-07-28T04:04:39.282000Z","event_type":"best_bid_ask","frame_hash":"afa7a6bf8094e1ae6ee2ae8771911f7cb71bbda244f97b3a57340864fe493c72","frame_index":0,"kind":"data","monotonic_ns":313462193558291,"payload":{"asset_id":"96600821790790307414914106093858868634329285205417149685270682748367152458577","best_ask":"0.42","best_bid":"0.41","event_type":"best_bid_ask","market":"0xd412ce774cfcf8dc9f71164aac78783978aac7b03871702a3b8a481bd9dc9688","spread":"0.01","timestamp":"1785211479282"},"payload_hash":"f636d63294c34b60e626b2b4e166a2b09117628e1d87812963093afe9db8f779","raw_frame":"{\"market\":\"0xd412ce774cfcf8dc9f71164aac78783978aac7b03871702a3b8a481bd9dc9688\", \"asset_id\":\"96600821790790307414914106093858868634329285205417149685270682748367152458577\", \"best_bid\":\"0.41\", \"best_ask\":\"0.42\", \"spread\":\"0.01\", \"timestamp\":\"1785211479282\", \"event_type\":\"best_bid_ask\"}","received_at":"2026-07-28T04:04:39.143572Z","schema_version":"clob-market-ws.best_bid_ask.v1","sequence":null,"server_hash":null,"server_timestamp":"1785211479282","session_id":"2d607381e3054cee91998cdf45a4231c","source":"clob_market_ws"},"received_at":"2026-07-28T04:04:39.143572Z","record_id":"2c790e820db7946f678de2af421b56bf9b5bfe2323a80e6d20329f04b6314cfc","schema_fingerprint":"8488399f31b0337811b13b266be932db7062827c2470b78bd8e9e99bab51d17d","schema_version":"edge-lab-recorder.raw.v1","sequence":null,"source":"clob_market_ws"}
{"event_at":"2026-07-28T04:04:39.282000Z","event_fingerprint":"248e6c035ff87a75e6e6963efc9171fdbf44a1337f0fd8d6b34e6e8c2f84877e","payload":{"connection_id":"f6725804f86a4c4eb588e4d5ed7db029","event_at":"2026-07-28T04:04:39.282000Z","event_type":"price_change","frame_hash":"d4434707b685ccdbccfa3c3664f59540cf2cdd4c49ab365a7f694e9eacde2d88","frame_index":0,"kind":"data","monotonic_ns":313462195660375,"payload":{"event_type":"price_change","market":"0xd412ce774cfcf8dc9f71164aac78783978aac7b03871702a3b8a481bd9dc9688","price_changes":[{"asset_id":"107603864457683460275633293642179940881969192120168665300712204232021063124301","best_ask":"0.59","best_bid":"0.58","hash":"f84479a990bfd654f70caa71da5279d1c70bf755","price":"0.58","side":"BUY","size":"22"},{"asset_id":"96600821790790307414914106093858868634329285205417149685270682748367152458577","best_ask":"0.42","best_bid":"0.41","hash":"05a7a628bbc8c0f9f7c1090d93a4355b3e3dd605","price":"0.42","side":"SELL","size":"22"}],"timestamp":"1785211479282"},"payload_hash":"5db3d2119d9e2c721e29e77ec3dbbd98d1da82162fdf1d9d9b8fa4c03d76b536","raw_frame":"{\"market\":\"0xd412ce774cfcf8dc9f71164aac78783978aac7b03871702a3b8a481bd9dc9688\", \"price_changes\":[{\"asset_id\":\"107603864457683460275633293642179940881969192120168665300712204232021063124301\", \"price\":\"0.58\", \"size\":\"22\", \"side\":\"BUY\", \"hash\":\"f84479a990bfd654f70caa71da5279d1c70bf755\", \"best_bid\":\"0.58\", \"best_ask\":\"0.59\"}, {\"asset_id\":\"96600821790790307414914106093858868634329285205417149685270682748367152458577\", \"price\":\"0.42\", \"size\":\"22\", \"side\":\"SELL\", \"hash\":\"05a7a628bbc8c0f9f7c1090d93a4355b3e3dd605\", \"best_bid\":\"0.41\", \"best_ask\":\"0.42\"}], \"timestamp\":\"1785211479282\", \"event_type\":\"price_change\"}","received_at":"2026-07-28T04:04:39.145678Z","schema_version":"clob-market-ws.price_change.v1","sequence":null,"server_hash":null,"server_timestamp":"1785211479282","session_id":"2d607381e3054cee91998cdf45a4231c","source":"clob_market_ws"},"received_at":"2026-07-28T04:04:39.145678Z","record_id":"fcb3701bf7e0457e2fa7ddd7b2bb7ed2b9b6470291b82453a4ccf518b88835b9","schema_fingerprint":"4aa3821a28b0b7c2400bc59aba4bcc0a76e971dadd19610d3ad38c768e124dc7","schema_version":"edge-lab-recorder.raw.v1","sequence":null,"source":"clob_market_ws"}
{"event_at":"2026-07-28T04:04:39.283000Z","event_fingerprint":"604a76eba7de0d4c3caec6a458eea8b0f480514bd22f4e9c85aba3f7eb0d5123","payload":{"connection_id":"f6725804f86a4c4eb588e4d5ed7db029","event_at":"2026-07-28T04:04:39.283000Z","event_type":"price_change","frame_hash":"6700d6e0a53a58e64523abfaf65327a9ffadf99de76134b9b6f47492d546b85a","frame_index":0,"kind":"data","monotonic_ns":313462197296250,"payload":{"event_type":"price_change","market":"0xd412ce774cfcf8dc9f71164aac78783978aac7b03871702a3b8a481bd9dc9688","price_changes":[{"asset_id":"96600821790790307414914106093858868634329285205417149685270682748367152458577","best_ask":"0.42","best_bid":"0.41","hash":"48d3cf2f39cd0b19077cb90ce5bd144a5ab8104d","price":"0.35","side":"BUY","size":"205"},{"asset_id":"107603864457683460275633293642179940881969192120168665300712204232021063124301","best_ask":"0.59","best_bid":"0.58","hash":"f89fa42fbd2d31e49fb669a33a2530d46cc0ddfe","price":"0.65","side":"SELL","size":"205"}],"timestamp":"1785211479283"},"payload_hash":"c8220f45aa24a4914d01cb53f9f33a523b0ce2539b929a8cafef30f52ea3c0d4","raw_frame":"{\"market\":\"0xd412ce774cfcf8dc9f71164aac78783978aac7b03871702a3b8a481bd9dc9688\", \"price_changes\":[{\"asset_id\":\"96600821790790307414914106093858868634329285205417149685270682748367152458577\", \"price\":\"0.35\", \"size\":\"205\", \"side\":\"BUY\", \"hash\":\"48d3cf2f39cd0b19077cb90ce5bd144a5ab8104d\", \"best_bid\":\"0.41\", \"best_ask\":\"0.42\"}, {\"asset_id\":\"107603864457683460275633293642179940881969192120168665300712204232021063124301\", \"price\":\"0.65\", \"size\":\"205\", \"side\":\"SELL\", \"hash\":\"f89fa42fbd2d31e49fb669a33a2530d46cc0ddfe\", \"best_bid\":\"0.58\", \"best_ask\":\"0.59\"}], \"timestamp\":\"1785211479283\", \"event_type\":\"price_change\"}","received_at":"2026-07-28T04:04:39.147317Z","schema_version":"clob-market-ws.price_change.v1","sequence":null,"server_hash":null,"server_timestamp":"1785211479283","session_id":"2d607381e3054cee91998cdf45a4231c","source":"clob_market_ws"},"received_at":"2026-07-28T04:04:39.147317Z","record_id":"b944cc0e513a32486939a7066455cd88235fd81b0570d5342c381c706cddf42f","schema_fingerprint":"4aa3821a28b0b7c2400bc59aba4bcc0a76e971dadd19610d3ad38c768e124dc7","schema_version":"edge-lab-recorder.raw.v1","sequence":null,"source":"clob_market_ws"}
{"event_at":"2026-07-28T04:04:39.285000Z","event_fingerprint":"da3e0e3bf388d51671fcb0b2eec253c6f45e6214d1285fc429b56f0188ac6ab2","payload":{"connection_id":"f6725804f86a4c4eb588e4d5ed7db029","event_at":"2026-07-28T04:04:39.285000Z","event_type":"price_change","frame_hash":"6ed6bd43551b04f71c2dd232ac70f195231778eb8ebee0dd6713a53c8a09ab5b","frame_index":0,"kind":"data","monotonic_ns":313462198976750,"payload":{"event_type":"price_change","market":"0xd412ce774cfcf8dc9f71164aac78783978aac7b03871702a3b8a481bd9dc9688","price_changes":[{"asset_id":"107603864457683460275633293642179940881969192120168665300712204232021063124301","best_ask":"0.59","best_bid":"0.58","hash":"cb6d44329e4af345099be8f4fec0378bf42e5918","price":"0.5","side":"BUY","size":"140"},{"asset_id":"96600821790790307414914106093858868634329285205417149685270682748367152458577","best_ask":"0.42","best_bid":"0.41","hash":"62658aab8b8197ab458682e48aa9cd5c146d4932","price":"0.5","side":"SELL","size":"140"}],"timestamp":"1785211479285"},"payload_hash":"9b28a87d95910ba161f0b272ca28996b87946500bb5459d7878f508e51f51dcb","raw_frame":"{\"market\":\"0xd412ce774cfcf8dc9f71164aac78783978aac7b03871702a3b8a481bd9dc9688\", \"price_changes\":[{\"asset_id\":\"107603864457683460275633293642179940881969192120168665300712204232021063124301\", \"price\":\"0.5\", \"size\":\"140\", \"side\":\"BUY\", \"hash\":\"cb6d44329e4af345099be8f4fec0378bf42e5918\", \"best_bid\":\"0.58\", \"best_ask\":\"0.59\"}, {\"asset_id\":\"96600821790790307414914106093858868634329285205417149685270682748367152458577\", \"price\":\"0.5\", \"size\":\"140\", \"side\":\"SELL\", \"hash\":\"62658aab8b8197ab458682e48aa9cd5c146d4932\", \"best_bid\":\"0.41\", \"best_ask\":\"0.42\"}], \"timestamp\":\"1785211479285\", \"event_type\":\"price_change\"}","received_at":"2026-07-28T04:04:39.148997Z","schema_version":"clob-market-ws.price_change.v1","sequence":null,"server_hash":null,"server_timestamp":"1785211479285","session_id":"2d607381e3054cee91998cdf45a4231c","source":"clob_market_ws"},"received_at":"2026-07-28T04:04:39.148997Z","record_id":"f544eb894c36e08c60ec887c0e39da6fbd2ad3f2f4d9b7579db1c1dec260d2ea","schema_fingerprint":"4aa3821a28b0b7c2400bc59aba4bcc0a76e971dadd19610d3ad38c768e124dc7","schema_version":"edge-lab-recorder.raw.v1","sequence":null,"source":"clob_market_ws"}
{"event_at":"2026-07-28T04:04:39.287000Z","event_fingerprint":"cdeb8f028cc2528572f1400b0372b4fe8bf263aa97fcd6e098ba92820b9b3616","payload":{"connection_id":"f6725804f86a4c4eb588e4d5ed7db029","event_at":"2026-07-28T04:04:39.287000Z","event_type":"price_change","frame_hash":"a7cac5454fa72361bec5323de1c8a3871fef527bf2d80532dd7248272194b0df","frame_index":0,"kind":"data","monotonic_ns":313462200678500,"payload":{"event_type":"price_change","market":"0xd412ce774cfcf8dc9f71164aac78783978aac7b03871702a3b8a481bd9dc9688","price_changes":[{"asset_id":"107603864457683460275633293642179940881969192120168665300712204232021063124301","best_ask":"0.59","best_bid":"0.58","hash":"20bd80bd270a898eb51036b46e65f3fd5707b9e7","price":"0.47","side":"BUY","size":"113"},{"asset_id":"96600821790790307414914106093858868634329285205417149685270682748367152458577","best_ask":"0.42","best_bid":"0.41","hash":"274df66cabcd7509460d1579e725a4fd9ae57c76","price":"0.53","side":"SELL","size":"113"}],"timestamp":"1785211479287"},"payload_hash":"ad5c72e6f69f8b97f925c3ce071dc77407aca0e1210c2cf82b19f6c71025afef","raw_frame":"{\"market\":\"0xd412ce774cfcf8dc9f71164aac78783978aac7b03871702a3b8a481bd9dc9688\", \"price_changes\":[{\"asset_id\":\"107603864457683460275633293642179940881969192120168665300712204232021063124301\", \"price\":\"0.47\", \"size\":\"113\", \"side\":\"BUY\", \"hash\":\"20bd80bd270a898eb51036b46e65f3fd5707b9e7\", \"best_bid\":\"0.58\", \"best_ask\":\"0.59\"}, {\"asset_id\":\"96600821790790307414914106093858868634329285205417149685270682748367152458577\", \"price\":\"0.53\", \"size\":\"113\", \"side\":\"SELL\", \"hash\":\"274df66cabcd7509460d1579e725a4fd9ae57c76\", \"best_bid\":\"0.41\", \"best_ask\":\"0.42\"}], \"timestamp\":\"1785211479287\", \"event_type\":\"price_change\"}","received_at":"2026-07-28T04:04:39.150694Z","schema_version":"clob-market-ws.price_change.v1","sequence":null,"server_hash":null,"server_timestamp":"1785211479287","session_id":"2d607381e3054cee91998cdf45a4231c","source":"clob_market_ws"},"received_at":"2026-07-28T04:04:39.150694Z","record_id":"b495cea0c63c85bbf695868d49ddf87ddf4293ea977f443c683aa78fe9e2047c","schema_fingerprint":"4aa3821a28b0b7c2400bc59aba4bcc0a76e971dadd19610d3ad38c768e124dc7","schema_version":"edge-lab-recorder.raw.v1","sequence":null,"source":"clob_market_ws"}
{"event_at":"2026-07-28T04:04:39.289000Z","event_fingerprint":"58a60318b7fd55eb0023dd7dced6845613a1f5fb9eedadb3ce728004d6302ca9","payload":{"connection_id":"f6725804f86a4c4eb588e4d5ed7db029","event_at":"2026-07-28T04:04:39.289000Z","event_type":"price_change","frame_hash":"05e320ff48d713e1f3da455012adee74015707dab396b8eff42b55f0cf22c94f","frame_index":0,"kind":"data","monotonic_ns":313462202287583,"payload":{"event_type":"price_change","market":"0xd412ce774cfcf8dc9f71164aac78783978aac7b03871702a3b8a481bd9dc9688","price_changes":[{"asset_id":"96600821790790307414914106093858868634329285205417149685270682748367152458577","best_ask":"0.42","best_bid":"0.41","hash":"1be1a4ecd40be3b62c1e7b9b8f855ecee3c871a6","price":"0.43","side":"SELL","size":"118.2"},{"asset_id":"107603864457683460275633293642179940881969192120168665300712204232021063124301","best_ask":"0.59","best_bid":"0.58","hash":"70e5fd40fbb7135f499f8e5ba7b90361d91c1f86","price":"0.57","side":"BUY","size":"118.2"}],"timestamp":"1785211479289"},"payload_hash":"6f4074b665a75327fb7004f13636144c23378b6de60df96c646e465e69e167d6","raw_frame":"{\"market\":\"0xd412ce774cfcf8dc9f71164aac78783978aac7b03871702a3b8a481bd9dc9688\", \"price_changes\":[{\"asset_id\":\"96600821790790307414914106093858868634329285205417149685270682748367152458577\", \"price\":\"0.43\", \"size\":\"118.2\", \"side\":\"SELL\", \"hash\":\"1be1a4ecd40be3b62c1e7b9b8f855ecee3c871a6\", \"best_bid\":\"0.41\", \"best_ask\":\"0.42\"}, {\"asset_id\":\"107603864457683460275633293642179940881969192120168665300712204232021063124301\", \"price\":\"0.57\", \"size\":\"118.2\", \"side\":\"BUY\", \"hash\":\"70e5fd40fbb7135f499f8e5ba7b90361d91c1f86\", \"best_bid\":\"0.58\", \"best_ask\":\"0.59\"}], \"timestamp\":\"1785211479289\", \"event_type\":\"price_change\"}","received_at":"2026-07-28T04:04:39.152308Z","schema_version":"clob-market-ws.price_change.v1","sequence":null,"server_hash":null,"server_timestamp":"1785211479289","session_id":"2d607381e3054cee91998cdf45a4231c","source":"clob_market_ws"},"received_at":"2026-07-28T04:04:39.152308Z","record_id":"2375676c543c18ab07cbbf225b0da8388f3becc395361387f0feeedef8604f5a","schema_fingerprint":"4aa3821a28b0b7c2400bc59aba4bcc0a76e971dadd19610d3ad38c768e124dc7","schema_version":"edge-lab-recorder.raw.v1","sequence":null,"source":"clob_market_ws"}
{"event_at":"2026-07-28T04:04:39.289000Z","event_fingerprint":"f11201b25462014da6633f78d05b491c809b473956bc39cbdb9cf722718c64cf","payload":{"connection_id":"f6725804f86a4c4eb588e4d5ed7db029","event_at":"2026-07-28T04:04:39.289000Z","event_type":"price_change","frame_hash":"c76b76b0468cbe0b9bbfab51591833520d599d3a2958c8d986bba8ac096ed240","frame_index":0,"kind":"data","monotonic_ns":313462203829208,"payload":{"event_type":"price_change","market":"0xd412ce774cfcf8dc9f71164aac78783978aac7b03871702a3b8a481bd9dc9688","price_changes":[{"asset_id":"107603864457683460275633293642179940881969192120168665300712204232021063124301","best_ask":"0.59","best_bid":"0.58","hash":"d517eea85360d70cb6c84b79beae384debd17938","price":"0.49","side":"BUY","size":"58.63"},{"asset_id":"96600821790790307414914106093858868634329285205417149685270682748367152458577","best_ask":"0.42","best_bid":"0.41","hash":"7188d0c1bb33cdb80772c71abca58dcda5a793b5","price":"0.51","side":"SELL","size":"58.63"}],"timestamp":"1785211479289"},"payload_hash":"c9f2833bd6c2e220046d5b2a44c1838a874601a09b0c8d9ee65801d1a16c4f90","raw_frame":"{\"market\":\"0xd412ce774cfcf8dc9f71164aac78783978aac7b03871702a3b8a481bd9dc9688\", \"price_changes\":[{\"asset_id\":\"107603864457683460275633293642179940881969192120168665300712204232021063124301\", \"price\":\"0.49\", \"size\":\"58.63\", \"side\":\"BUY\", \"hash\":\"d517eea85360d70cb6c84b79beae384debd17938\", \"best_bid\":\"0.58\", \"best_ask\":\"0.59\"}, {\"asset_id\":\"96600821790790307414914106093858868634329285205417149685270682748367152458577\", \"price\":\"0.51\", \"size\":\"58.63\", \"side\":\"SELL\", \"hash\":\"7188d0c1bb33cdb80772c71abca58dcda5a793b5\", \"best_bid\":\"0.41\", \"best_ask\":\"0.42\"}], \"timestamp\":\"1785211479289\", \"event_type\":\"price_change\"}","received_at":"2026-07-28T04:04:39.153850Z","schema_version":"clob-market-ws.price_change.v1","sequence":null,"server_hash":null,"server_timestamp":"1785211479289","session_id":"2d607381e3054cee91998cdf45a4231c","source":"clob_market_ws"},"received_at":"2026-07-28T04:04:39.153850Z","record_id":"696279e6280c866f8efc407411e31fda7fe89bfbeb27bd547d04e16845cff809","schema_fingerprint":"4aa3821a28b0b7c2400bc59aba4bcc0a76e971dadd19610d3ad38c768e124dc7","schema_version":"edge-lab-recorder.raw.v1","sequence":null,"source":"clob_market_ws"}
{"event_at":"2026-07-28T04:04:39.290000Z","event_fingerprint":"efaf67fcfb25f13962937a07692f8e46abb2cebd1adb66b4bab403921978d2ee","payload":{"connection_id":"f6725804f86a4c4eb588e4d5ed7db029","event_at":"2026-07-28T04:04:39.290000Z","event_type":"price_change","frame_hash":"ad6cb8d10090ea18fe2e9d5d4d4ef23ab1fc8201c48da90b618b83a319e8a9db","frame_index":0,"kind":"data","monotonic_ns":313462205335875,"payload":{"event_type":"price_change","market":"0xd412ce774cfcf8dc9f71164aac78783978aac7b03871702a3b8a481bd9dc9688","price_changes":[{"asset_id":"107603864457683460275633293642179940881969192120168665300712204232021063124301","best_ask":"0.59","best_bid":"0.58","hash":"ce9a752cd57fe6a4d33485c884803ea1482a9e6c","price":"0.58","side":"BUY","size":"50"},{"asset_id":"96600821790790307414914106093858868634329285205417149685270682748367152458577","best_ask":"0.42","best_bid":"0.41","hash":"88530b27b25240edcc60252dfcf47a522038c33c","price":"0.42","side":"SELL","size":"50"}],"timestamp":"1785211479290"},"payload_hash":"372e21e9d84781e93f5bd27d734c1b625bb6f0264060d38a7f1dd9800d5c853d","raw_frame":"{\"market\":\"0xd412ce774cfcf8dc9f71164aac78783978aac7b03871702a3b8a481bd9dc9688\", \"price_changes\":[{\"asset_id\":\"107603864457683460275633293642179940881969192120168665300712204232021063124301\", \"price\":\"0.58\", \"size\":\"50\", \"side\":\"BUY\", \"hash\":\"ce9a752cd57fe6a4d33485c884803ea1482a9e6c\", \"best_bid\":\"0.58\", \"best_ask\":\"0.59\"}, {\"asset_id\":\"96600821790790307414914106093858868634329285205417149685270682748367152458577\", \"price\":\"0.42\", \"size\":\"50\", \"side\":\"SELL\", \"hash\":\"88530b27b25240edcc60252dfcf47a522038c33c\", \"best_bid\":\"0.41\", \"best_ask\":\"0.42\"}], \"timestamp\":\"1785211479290\", \"event_type\":\"price_change\"}","received_at":"2026-07-28T04:04:39.155354Z","schema_version":"clob-market-ws.price_change.v1","sequence":null,"server_hash":null,"server_timestamp":"1785211479290","session_id":"2d607381e3054cee91998cdf45a4231c","source":"clob_market_ws"},"received_at":"2026-07-28T04:04:39.155354Z","record_id":"b2d74a6d714cf26d1b80c87ba0d1d37a49645815d1cc6e6c2effa347ad53f5e5","schema_fingerprint":"4aa3821a28b0b7c2400bc59aba4bcc0a76e971dadd19610d3ad38c768e124dc7","schema_version":"edge-lab-recorder.raw.v1","sequence":null,"source":"clob_market_ws"}
{"event_at":"2026-07-28T04:04:39.291000Z","event_fingerprint":"fc9f7d49acbaf92b9566d3202f292129c8d18b041fa3a70ebd0c5433c4edfbe3","payload":{"connection_id":"f6725804f86a4c4eb588e4d5ed7db029","event_at":"2026-07-28T04:04:39.291000Z","event_type":"price_change","frame_hash":"068ae9824b7d5b9cede72d6433d61fffc2efffca026a28bb94a3dc44256e9036","frame_index":0,"kind":"data","monotonic_ns":313462206976083,"payload":{"event_type":"price_change","market":"0xd412ce774cfcf8dc9f71164aac78783978aac7b03871702a3b8a481bd9dc9688","price_changes":[{"asset_id":"107603864457683460275633293642179940881969192120168665300712204232021063124301","best_ask":"0.59","best_bid":"0.58","hash":"a8404421deaa8102f89618fcdeefbbe34e32c833","price":"0.56","side":"BUY","size":"40"},{"asset_id":"96600821790790307414914106093858868634329285205417149685270682748367152458577","best_ask":"0.42","best_bid":"0.41","hash":"ea245ead3ac2d5518ce573c300af7ffe3eee7665","price":"0.44","side":"SELL","size":"40"}],"timestamp":"1785211479291"},"payload_hash":"32b11e587a37c2e44198e9e445d7c32b7b842e4610b37840cd4c9f046c48019c","raw_frame":"{\"market\":\"0xd412ce774cfcf8dc9f71164aac78783978aac7b03871702a3b8a481bd9dc9688\", \"price_changes\":[{\"asset_id\":\"107603864457683460275633293642179940881969192120168665300712204232021063124301\", \"price\":\"0.56\", \"size\":\"40\", \"side\":\"BUY\", \"hash\":\"a8404421deaa8102f89618fcdeefbbe34e32c833\", \"best_bid\":\"0.58\", \"best_ask\":\"0.59\"}, {\"asset_id\":\"96600821790790307414914106093858868634329285205417149685270682748367152458577\", \"price\":\"0.44\", \"size\":\"40\", \"side\":\"SELL\", \"hash\":\"ea245ead3ac2d5518ce573c300af7ffe3eee7665\", \"best_bid\":\"0.41\", \"best_ask\":\"0.42\"}], \"timestamp\":\"1785211479291\", \"event_type\":\"price_change\"}","received_at":"2026-07-28T04:04:39.156995Z","schema_version":"clob-market-ws.price_change.v1","sequence":null,"server_hash":null,"server_timestamp":"1785211479291","session_id":"2d607381e3054cee91998cdf45a4231c","source":"clob_market_ws"},"received_at":"2026-07-28T04:04:39.156995Z","record_id":"9a2b6007f231b045293218228928dafe48a721f6f098e6a417234f2c41c2e56e","schema_fingerprint":"4aa3821a28b0b7c2400bc59aba4bcc0a76e971dadd19610d3ad38c768e124dc7","schema_version":"edge-lab-recorder.raw.v1","sequence":null,"source":"clob_market_ws"}
{"event_at":"2026-07-28T04:04:39.291000Z","event_fingerprint":"e6c4297b88209cb271a5d1388fc92a6b08d925c42e3abec0cbb64a26f38d5d40","payload":{"connection_id":"f6725804f86a4c4eb588e4d5ed7db029","event_at":"2026-07-28T04:04:39.291000Z","event_type":"price_change","frame_hash":"d9043347a9772ab8dbe51c11c515071c8fe0f35f2914c6b9d6f8655cba996545","frame_index":0,"kind":"data","monotonic_ns":313462208480833,"payload":{"event_type":"price_change","market":"0xd412ce774cfcf8dc9f71164aac78783978aac7b03871702a3b8a481bd9dc9688","price_changes":[{"asset_id":"107603864457683460275633293642179940881969192120168665300712204232021063124301","best_ask":"0.59","best_bid":"0.58","hash":"68a037d67ed97fa6d2403fd2c3f679316432a13d","price":"0.57","side":"BUY","size":"113.2"},{"asset_id":"96600821790790307414914106093858868634329285205417149685270682748367152458577","best_ask":"0.42","best_bid":"0.41","hash":"85eb4bffc2968844bc3412e6cfa51a4d5e28036f","price":"0.43","side":"SELL","size":"113.2"}],"timestamp":"1785211479291"},"payload_hash":"efaad860c28975a43e19da3f3f67d3ee02048f5eecbbd50e6dc58c01ae5c90d8","raw_frame":"{\"market\":\"0xd412ce774cfcf8dc9f71164aac78783978aac7b03871702a3b8a481bd9dc9688\", \"price_changes\":[{\"asset_id\":\"107603864457683460275633293642179940881969192120168665300712204232021063124301\", \"price\":\"0.57\", \"size\":\"113.2\", \"side\":\"BUY\", \"hash\":\"68a037d67ed97fa6d2403fd2c3f679316432a13d\", \"best_bid\":\"0.58\", \"best_ask\":\"0.59\"}, {\"asset_id\":\"96600821790790307414914106093858868634329285205417149685270682748367152458577\", \"price\":\"0.43\", \"size\":\"113.2\", \"side\":\"SELL\", \"hash\":\"85eb4bffc2968844bc3412e6cfa51a4d5e28036f\", \"best_bid\":\"0.41\", \"best_ask\":\"0.42\"}], \"timestamp\":\"1785211479291\", \"event_type\":\"price_change\"}","received_at":"2026-07-28T04:04:39.158500Z","schema_version":"clob-market-ws.price_change.v1","sequence":null,"server_hash":null,"server_timestamp":"1785211479291","session_id":"2d607381e3054cee91998cdf45a4231c","source":"clob_market_ws"},"received_at":"2026-07-28T04:04:39.158500Z","record_id":"cf911e6698b2d8db1a8b1fd498fb028f4946efa77cbd63ce4fb8a6e768ae4d7f","schema_fingerprint":"4aa3821a28b0b7c2400bc59aba4bcc0a76e971dadd19610d3ad38c768e124dc7","schema_version":"edge-lab-recorder.raw.v1","sequence":null,"source":"clob_market_ws"}
{"event_at":"2026-07-28T04:04:39.291000Z","event_fingerprint":"4d3baaca63f90aed61fbec237b98df14c63eb193cc339b2815d42ba7bd350720","payload":{"connection_id":"f6725804f86a4c4eb588e4d5ed7db029","event_at":"2026-07-28T04:04:39.291000Z","event_type":"price_change","frame_hash":"35ad5883992d58bcecc482fbec27d454d23cbc4afbed64cebd488b311914331f","frame_index":0,"kind":"data","monotonic_ns":313462210039583,"payload":{"event_type":"price_change","market":"0xd412ce774cfcf8dc9f71164aac78783978aac7b03871702a3b8a481bd9dc9688","price_changes":[{"asset_id":"107603864457683460275633293642179940881969192120168665300712204232021063124301","best_ask":"0.59","best_bid":"0.58","hash":"def431234038ab4ccc42fe40918859263d836d11","price":"0.57","side":"BUY","size":"106.2"},{"asset_id":"96600821790790307414914106093858868634329285205417149685270682748367152458577","best_ask":"0.42","best_bid":"0.41","hash":"faceaf59d4a395b560f4c9c7ba3bbf9033d249b2","price":"0.43","side":"SELL","size":"106.2"}],"timestamp":"1785211479291"},"payload_hash":"1003db2982eedd84685f11fa1b482a9e8b17eee2685ccbd029c7803fb89c28cc","raw_frame":"{\"market\":\"0xd412ce774cfcf8dc9f71164aac78783978aac7b03871702a3b8a481bd9dc9688\", \"price_changes\":[{\"asset_id\":\"107603864457683460275633293642179940881969192120168665300712204232021063124301\", \"price\":\"0.57\", \"size\":\"106.2\", \"side\":\"BUY\", \"hash\":\"def431234038ab4ccc42fe40918859263d836d11\", \"best_bid\":\"0.58\", \"best_ask\":\"0.59\"}, {\"asset_id\":\"96600821790790307414914106093858868634329285205417149685270682748367152458577\", \"price\":\"0.43\", \"size\":\"106.2\", \"side\":\"SELL\", \"hash\":\"faceaf59d4a395b560f4c9c7ba3bbf9033d249b2\", \"best_bid\":\"0.41\", \"best_ask\":\"0.42\"}], \"timestamp\":\"1785211479291\", \"event_type\":\"price_change\"}","received_at":"2026-07-28T04:04:39.160059Z","schema_version":"clob-market-ws.price_change.v1","sequence":null,"server_hash":null,"server_timestamp":"1785211479291","session_id":"2d607381e3054cee91998cdf45a4231c","source":"clob_market_ws"},"received_at":"2026-07-28T04:04:39.160059Z","record_id":"b7f75d90630ddac7ccc8f05803d3f9801308f2ffc7af793cc67e8bfae215f909","schema_fingerprint":"4aa3821a28b0b7c2400bc59aba4bcc0a76e971dadd19610d3ad38c768e124dc7","schema_version":"edge-lab-recorder.raw.v1","sequence":null,"source":"clob_market_ws"}
{"event_at":"2026-07-28T04:04:39.291000Z","event_fingerprint":"0fe2ecb33be43c590cda5ce7cde327069f8dbd2470df2f7b7db2b33ae9cfa375","payload":{"connection_id":"f6725804f86a4c4eb588e4d5ed7db029","event_at":"2026-07-28T04:04:39.291000Z","event_type":"price_change","frame_hash":"95b7787c5bf3d5077609329d1a25b1ec61bb518e7c778cda7015a3c317d85a0d","frame_index":0,"kind":"data","monotonic_ns":313462211548500,"payload":{"event_type":"price_change","market":"0xd412ce774cfcf8dc9f71164aac78783978aac7b03871702a3b8a481bd9dc9688","price_changes":[{"asset_id":"107603864457683460275633293642179940881969192120168665300712204232021063124301","best_ask":"0.59","best_bid":"0.58","hash":"e44d3d3589fba8e130e3992e281dab54dc631872","price":"0.38","side":"BUY","size":"167.7"},{"asset_id":"96600821790790307414914106093858868634329285205417149685270682748367152458577","best_ask":"0.42","best_bid":"0.41","hash":"fdb1ec84420f768f69aa6ebf92fa4f7f762c6a81","price":"0.62","side":"SELL","size":"167.7"}],"timestamp":"1785211479291"},"payload_hash":"98efacffed56bdead343115010c665e246eba351d7f714d2f5c43b9cb16e624e","raw_frame":"{\"market\":\"0xd412ce774cfcf8dc9f71164aac78783978aac7b03871702a3b8a481bd9dc9688\", \"price_changes\":[{\"asset_id\":\"107603864457683460275633293642179940881969192120168665300712204232021063124301\", \"price\":\"0.38\", \"size\":\"167.7\", \"side\":\"BUY\", \"hash\":\"e44d3d3589fba8e130e3992e281dab54dc631872\", \"best_bid\":\"0.58\", \"best_ask\":\"0.59\"}, {\"asset_id\":\"96600821790790307414914106093858868634329285205417149685270682748367152458577\", \"price\":\"0.62\", \"size\":\"167.7\", \"side\":\"SELL\", \"hash\":\"fdb1ec84420f768f69aa6ebf92fa4f7f762c6a81\", \"best_bid\":\"0.41\", \"best_ask\":\"0.42\"}], \"timestamp\":\"1785211479291\", \"event_type\":\"price_change\"}","received_at":"2026-07-28T04:04:39.161569Z","schema_version":"clob-market-ws.price_change.v1","sequence":null,"server_hash":null,"server_timestamp":"1785211479291","session_id":"2d607381e3054cee91998cdf45a4231c","source":"clob_market_ws"},"received_at":"2026-07-28T04:04:39.161569Z","record_id":"0246edb5cd1ee8fbd220d682fa2202adcafc4877966a43bed2deada0d78f8795","schema_fingerprint":"4aa3821a28b0b7c2400bc59aba4bcc0a76e971dadd19610d3ad38c768e124dc7","schema_version":"edge-lab-recorder.raw.v1","sequence":null,"source":"clob_market_ws"}
{"event_at":"2026-07-28T04:04:39.292000Z","event_fingerprint":"761c76534064f96cf9242d2ff8ca9dbe94e53b1e4b01de9b163216884f06b9b0","payload":{"connection_id":"f6725804f86a4c4eb588e4d5ed7db029","event_at":"2026-07-28T04:04:39.292000Z","event_type":"price_change","frame_hash":"a4c4715b5ec9a2ddbf207231435ea291b615b4ea7be18ce68cb8ccb20c86004a","frame_index":0,"kind":"data","monotonic_ns":313462213058416,"payload":{"event_type":"price_change","market":"0xd412ce774cfcf8dc9f71164aac78783978aac7b03871702a3b8a481bd9dc9688","price_changes":[{"asset_id":"96600821790790307414914106093858868634329285205417149685270682748367152458577","best_ask":"0.42","best_bid":"0.41","hash":"e49701814d5f4ea76f3f7c2d80190dbf5bb52377","price":"0.35","side":"BUY","size":"235"},{"asset_id":"107603864457683460275633293642179940881969192120168665300712204232021063124301","best_ask":"0.59","best_bid":"0.58","hash":"a003f1500e5ba63fae9ea666b0c09881030f9eef","price":"0.65","side":"SELL","size":"235"}],"timestamp":"1785211479292"},"payload_hash":"32b0c94238cde5f70ff0fc7c8c3dc816fa16b558e1c398ea828cc7fd33d36ae0","raw_frame":"{\"market\":\"0xd412ce774cfcf8dc9f71164aac78783978aac7b03871702a3b8a481bd9dc9688\", \"price_changes\":[{\"asset_id\":\"96600821790790307414914106093858868634329285205417149685270682748367152458577\", \"price\":\"0.35\", \"size\":\"235\", \"side\":\"BUY\", \"hash\":\"e49701814d5f4ea76f3f7c2d80190dbf5bb52377\", \"best_bid\":\"0.41\", \"best_ask\":\"0.42\"}, {\"asset_id\":\"107603864457683460275633293642179940881969192120168665300712204232021063124301\", \"price\":\"0.65\", \"size\":\"235\", \"side\":\"SELL\", \"hash\":\"a003f1500e5ba63fae9ea666b0c09881030f9eef\", \"best_bid\":\"0.58\", \"best_ask\":\"0.59\"}], \"timestamp\":\"1785211479292\", \"event_type\":\"price_change\"}","received_at":"2026-07-28T04:04:39.163079Z","schema_version":"clob-market-ws.price_change.v1","sequence":null,"server_hash":null,"server_timestamp":"1785211479292","session_id":"2d607381e3054cee91998cdf45a4231c","source":"clob_market_ws"},"received_at":"2026-07-28T04:04:39.163079Z","record_id":"70c18890dcc68b09b7d77801a013faf12406bda131c49f45ce2b3304b7595d37","schema_fingerprint":"4aa3821a28b0b7c2400bc59aba4bcc0a76e971dadd19610d3ad38c768e124dc7","schema_version":"edge-lab-recorder.raw.v1","sequence":null,"source":"clob_market_ws"}
