{"event_at":"2026-07-28T04:00:25.750000Z","event_fingerprint":"609cf0d1251924a856efa9530471308d14fb5a42cd29f406e1bbe1b8004f8b2d","payload":{"connection_id":"f6725804f86a4c4eb588e4d5ed7db029","event_at":"2026-07-28T04:00:25.750000Z","event_type":"price_change","frame_hash":"8789ff0aa7ef16c23425716e305a3981e0785ab0c2d76d564013f7073e5265c0","frame_index":0,"kind":"data","monotonic_ns":313211629421625,"payload":{"event_type":"price_change","market":"0xd412ce774cfcf8dc9f71164aac78783978aac7b03871702a3b8a481bd9dc9688","price_changes":[{"asset_id":"96600821790790307414914106093858868634329285205417149685270682748367152458577","best_ask":"0.56","best_bid":"0.55","hash":"dfed9e308acd0e201e1b4879c4a37c13a6405f49","price":"0.52","side":"BUY","size":"54.2"},{"asset_id":"107603864457683460275633293642179940881969192120168665300712204232021063124301","best_ask":"0.45","best_bid":"0.44","hash":"df8c2284ac72daf9e4497cd168bde05eb8aed9c5","price":"0.48","side":"SELL","size":"54.2"}],"timestamp":"1785211225750"},"payload_hash":"3fc679c3dae3201b016df1ef05611148a016c88eae54e875af35b703dbad4843","raw_frame":"{\"market\":\"0xd412ce774cfcf8dc9f71164aac78783978aac7b03871702a3b8a481bd9dc9688\", \"price_changes\":[{\"asset_id\":\"96600821790790307414914106093858868634329285205417149685270682748367152458577\", \"price\":\"0.52\", \"size\":\"54.2\", \"side\":\"BUY\", \"hash\":\"dfed9e308acd0e201e1b4879c4a37c13a6405f49\", \"best_bid\":\"0.55\", \"best_ask\":\"0.56\"}, {\"asset_id\":\"107603864457683460275633293642179940881969192120168665300712204232021063124301\", \"price\":\"0.48\", \"size\":\"54.2\", \"side\":\"SELL\", \"hash\":\"df8c2284ac72daf9e4497cd168bde05eb8aed9c5\", \"best_bid\":\"0.44\", \"best_ask\":\"0.45\"}], \"timestamp\":\"1785211225750\", \"event_type\":\"price_change\"}","received_at":"2026-07-28T04:00:28.581301Z","schema_version":"clob-market-ws.price_change.v1","sequence":null,"server_hash":null,"server_timestamp":"1785211225750","session_id":"2d607381e3054cee91998cdf45a4231c","source":"clob_market_ws"},"received_at":"2026-07-28T04:00:28.581301Z","record_id":"bb50b0a808b1b235cb7ce6f27cc7381b6630939466ed9f4d979dabd7b21ba2e2","schema_fingerprint":"4aa3821a28b0b7c2400bc59aba4bcc0a76e971dadd19610d3ad38c768e124dc7","schema_version":"edge-lab-recorder.raw.v1","sequence":null,"source":"clob_market_ws"}
{"event_at":"2026-07-28T04:00:25.751000Z","event_fingerprint":"1c19e66e157d39f1da13b1290abb4daf00dc00ec7529172c74c41ca203c582b6","payload":{"connection_id":"f6725804f86a4c4eb588e4d5ed7db029","event_at":"2026-07-28T04:00:25.751000Z","event_type":"price_change","frame_hash":"c763942077b2eb3a063c89f66733c8df80c46bd48f3be10254571c4aa2096eca","frame_index":0,"kind":"data","monotonic_ns":313211656480791,"payload":{"event_type":"price_change","market":"0xd412ce774cfcf8dc9f71164aac78783978aac7b03871702a3b8a481bd9dc9688","price_changes":[{"asset_id":"96600821790790307414914106093858868634329285205417149685270682748367152458577","best_ask":"0.56","best_bid":"0.55","hash":"32772d1e76d9467b2dfb1d0eaabc117c75cf8b35","price":"0.51","side":"BUY","size":"64.6"},{"asset_id":"107603864457683460275633293642179940881969192120168665300712204232021063124301","best_ask":"0.45","best_bid":"0.44","hash":"02b08883ee62594a46c816e1df51e0e9d8eaf297","price":"0.49","side":"SELL","size":"64.6"}],"timestamp":"1785211225751"},"payload_hash":"c0754a80aea640230d47490a00a14deab190086b601e447394fd7bd8f6f431a7","raw_frame":"{\"market\":\"0xd412ce774cfcf8dc9f71164aac78783978aac7b03871702a3b8a481bd9dc9688\", \"price_changes\":[{\"asset_id\":\"96600821790790307414914106093858868634329285205417149685270682748367152458577\", \"price\":\"0.51\", \"size\":\"64.6\", \"side\":\"BUY\", \"hash\":\"32772d1e76d9467b2dfb1d0eaabc117c75cf8b35\", \"best_bid\":\"0.55\", \"best_ask\":\"0.56\"}, {\"asset_id\":\"107603864457683460275633293642179940881969192120168665300712204232021063124301\", \"price\":\"0.49\", \"size\":\"64.6\", \"side\":\"SELL\", \"hash\":\"02b08883ee62594a46c816e1df51e0e9d8eaf297\", \"best_bid\":\"0.44\", \"best_ask\":\"0.45\"}], \"timestamp\":\"1785211225751\", \"event_type\":\"price_change\"}","received_at":"2026-07-28T04:00:28.608359Z","schema_version":"clob-market-ws.price_change.v1","sequence":null,"server_hash":null,"server_timestamp":"1785211225751","session_id":"2d607381e3054cee91998cdf45a4231c","source":"clob_market_ws"},"received_at":"2026-07-28T04:00:28.608359Z","record_id":"da9c0859798cd593d3af84d9255d66eb13f87a9661bbc101df7f7f4b6bf32f62","schema_fingerprint":"4aa3821a28b0b7c2400bc59aba4bcc0a76e971dadd19610d3ad38c768e124dc7","schema_version":"edge-lab-recorder.raw.v1","sequence":null,"source":"clob_market_ws"}
{"event_at":"2026-07-28T04:00:25.752000Z","event_fingerprint":"63cfeee5143bc13adc6dc17a307bd906ac4ee99d65bc75950f1f7934247cc381","payload":{"connection_id":"f6725804f86a4c4eb588e4d5ed7db029","event_at":"2026-07-28T04:00:25.752000Z","event_type":"price_change","frame_hash":"a17463edca60741b967cd3ebaa49beb42a6ff33064aa066d9dd9aca974506025","frame_index":0,"kind":"data","monotonic_ns":313211664409458,"payload":{"event_type":"price_change","market":"0xd412ce774cfcf8dc9f71164aac78783978aac7b03871702a3b8a481bd9dc9688","price_changes":[{"asset_id":"107603864457683460275633293642179940881969192120168665300712204232021063124301","best_ask":"0.45","best_bid":"0.44","hash":"a148c21ba276524b121462db99bd899fa8fd0100","price":"0.44","side":"BUY","size":"50.2"},{"asset_id":"96600821790790307414914106093858868634329285205417149685270682748367152458577","best_ask":"0.56","best_bid":"0.55","hash":"4bfbbb7863f680410166c951007efd28fc8f5a4d","price":"0.56","side":"SELL","size":"50.2"}],"timestamp":"1785211225752"},"payload_hash":"1bbf81e94afe5133ae83bc2578ee7c054c1a5e78f23cb9d13f2defd032742d42","raw_frame":"{\"market\":\"0xd412ce774cfcf8dc9f71164aac78783978aac7b03871702a3b8a481bd9dc9688\", \"price_changes\":[{\"asset_id\":\"107603864457683460275633293642179940881969192120168665300712204232021063124301\", \"price\":\"0.44\", \"size\":\"50.2\", \"side\":\"BUY\", \"hash\":\"a148c21ba276524b121462db99bd899fa8fd0100\", \"best_bid\":\"0.44\", \"best_ask\":\"0.45\"}, {\"asset_id\":\"96600821790790307414914106093858868634329285205417149685270682748367152458577\", \"price\":\"0.56\", \"size\":\"50.2\", \"side\":\"SELL\", \"hash\":\"4bfbbb7863f680410166c951007efd28fc8f5a4d\", \"best_bid\":\"0.55\", \"best_ask\":\"0.56\"}], \"timestamp\":\"1785211225752\", \"event_type\":\"price_change\"}","received_at":"2026-07-28T04:00:28.616286Z","schema_version":"clob-market-ws.price_change.v1","sequence":null,"server_hash":null,"server_timestamp":"1785211225752","session_id":"2d607381e3054cee91998cdf45a4231c","source":"clob_market_ws"},"received_at":"2026-07-28T04:00:28.616286Z","record_id":"7d6db519b8a3d1a4903a8cef028ee11015b702200aa4e6cb988a646df911971e","schema_fingerprint":"4aa3821a28b0b7c2400bc59aba4bcc0a76e971dadd19610d3ad38c768e124dc7","schema_version":"edge-lab-recorder.raw.v1","sequence":null,"source":"clob_market_ws"}
{"event_at":"2026-07-28T04:00:25.753000Z","event_fingerprint":"a9cd13345b4ac629837f6084957732264d5ed3a5d1e7c08c5465f414c4a76484","payload":{"connection_id":"f6725804f86a4c4eb588e4d5ed7db029","event_at":"2026-07-28T04:00:25.753000Z","event_type":"price_change","frame_hash":"e4053baf62e035f626d5061ef3355b1c3733fdf2993ff5409f5f41bc1a1cd857","frame_index":0,"kind":"data","monotonic_ns":313211672711958,"payload":{"event_type":"price_change","market":"0xd412ce774cfcf8dc9f71164aac78783978aac7b03871702a3b8a481bd9dc9688","price_changes":[{"asset_id":"107603864457683460275633293642179940881969192120168665300712204232021063124301","best_ask":"0.45","best_bid":"0.44","hash":"1074175e728c994d8494c80c6aa4fa209f22b870","price":"0.42","side":"BUY","size":"91.27"},{"asset_id":"96600821790790307414914106093858868634329285205417149685270682748367152458577","best_ask":"0.56","best_bid":"0.55","hash":"3ae3cb1511540dd36eba724ec4a665293073020c","price":"0.58","side":"SELL","size":"91.27"}],"timestamp":"1785211225753"},"payload_hash":"d007dd39d1c07a3e717034139538061c26f358a050a61151ab1e142166c53ff1","raw_frame":"{\"market\":\"0xd412ce774cfcf8dc9f71164aac78783978aac7b03871702a3b8a481bd9dc9688\", \"price_changes\":[{\"asset_id\":\"107603864457683460275633293642179940881969192120168665300712204232021063124301\", \"price\":\"0.42\", \"size\":\"91.27\", \"side\":\"BUY\", \"hash\":\"1074175e728c994d8494c80c6aa4fa209f22b870\", \"best_bid\":\"0.44\", \"best_ask\":\"0.45\"}, {\"asset_id\":\"96600821790790307414914106093858868634329285205417149685270682748367152458577\", \"price\":\"0.58\", \"size\":\"91.27\", \"side\":\"SELL\", \"hash\":\"3ae3cb1511540dd36eba724ec4a665293073020c\", \"best_bid\":\"0.55\", \"best_ask\":\"0.56\"}], \"timestamp\":\"1785211225753\", \"event_type\":\"price_change\"}","received_at":"2026-07-28T04:00:28.624589Z","schema_version":"clob-market-ws.price_change.v1","sequence":null,"server_hash":null,"server_timestamp":"1785211225753","session_id":"2d607381e3054cee91998cdf45a4231c","source":"clob_market_ws"},"received_at":"2026-07-28T04:00:28.624589Z","record_id":"853ff1a57e4f79719f7839a454233c54d58fbd044f844297ec68a73e8dff8648","schema_fingerprint":"4aa3821a28b0b7c2400bc59aba4bcc0a76e971dadd19610d3ad38c768e124dc7","schema_version":"edge-lab-recorder.raw.v1","sequence":null,"source":"clob_market_ws"}
{"event_at":"2026-07-28T04:00:25.754000Z","event_fingerprint":"d3852fe13c22267b906fef402f3babd0a78de3d81f3bd0abff1cb218d586a0af","payload":{"connection_id":"f6725804f86a4c4eb588e4d5ed7db029","event_at":"2026-07-28T04:00:25.754000Z","event_type":"price_change","frame_hash":"64ebcb7c522108a3aa84d76cf45158fa4c6df2cd9e0ae833d88856cfe018a9e0","frame_index":0,"kind":"data","monotonic_ns":313211680898166,"payload":{"event_type":"price_change","market":"0xd412ce774cfcf8dc9f71164aac78783978aac7b03871702a3b8a481bd9dc9688","price_changes":[{"asset_id":"96600821790790307414914106093858868634329285205417149685270682748367152458577","best_ask":"0.56","best_bid":"0.55","hash":"9d5e93ccfa32111926d49b0354bb5e405ce84474","price":"0.45","side":"BUY","size":"149"},{"asset_id":"107603864457683460275633293642179940881969192120168665300712204232021063124301","best_ask":"0.45","best_bid":"0.44","hash":"7b9ecdff87c3dc2f1b111ca5f6faadf0ace84d87","price":"0.55","side":"SELL","size":"149"}],"timestamp":"1785211225754"},"payload_hash":"32b35a102743204be9f4adfd841f934c847f607026aea0521b697c42f1fb7a30","raw_frame":"{\"market\":\"0xd412ce774cfcf8dc9f71164aac78783978aac7b03871702a3b8a481bd9dc9688\", \"price_changes\":[{\"asset_id\":\"96600821790790307414914106093858868634329285205417149685270682748367152458577\", \"price\":\"0.45\", \"size\":\"149\", \"side\":\"BUY\", \"hash\":\"9d5e93ccfa32111926d49b0354bb5e405ce84474\", \"best_bid\":\"0.55\", \"best_ask\":\"0.56\"}, {\"asset_id\":\"107603864457683460275633293642179940881969192120168665300712204232021063124301\", \"price\":\"0.55\", \"size\":\"149\", \"side\":\"SELL\", \"hash\":\"7b9ecdff87c3dc2f1b111ca5f6faadf0ace84d87\", \"best_bid\":\"0.44\", \"best_ask\":\"0.45\"}], \"timestamp\":\"1785211225754\", \"event_type\":\"price_change\"}","received_at":"2026-07-28T04:00:28.632776Z","schema_version":"clob-market-ws.price_change.v1","sequence":null,"server_hash":null,"server_timestamp":"1785211225754","session_id":"2d607381e3054cee91998cdf45a4231c","source":"clob_market_ws"},"received_at":"2026-07-28T04:00:28.632776Z","record_id":"96e7204eed7acb50d6f9c5809aa8154219cd15de2519253d8c70395c6e6a8022","schema_fingerprint":"4aa3821a28b0b7c2400bc59aba4bcc0a76e971dadd19610d3ad38c768e124dc7","schema_version":"edge-lab-recorder.raw.v1","sequence":null,"source":"clob_market_ws"}
{"event_at":"2026-07-28T04:00:25.755000Z","event_fingerprint":"21d654ea238972489ce871b110316de7b762d91aaea0723b9415c2b8e9cb261f","payload":{"connection_id":"f6725804f86a4c4eb588e4d5ed7db029","event_at":"2026-07-28T04:00:25.755000Z","event_type":"price_change","frame_hash":"492c090726d9a5f5ef739e5853fe8a6e0740e9ed1f4b7447b632b0c35b24772c","frame_index":0,"kind":"data","monotonic_ns":313211692271291,"payload":{"event_type":"price_change","market":"0xd412ce774cfcf8dc9f71164aac78783978aac7b03871702a3b8a481bd9dc9688","price_changes":[{"asset_id":"107603864457683460275633293642179940881969192120168665300712204232021063124301","best_ask":"0.45","best_bid":"0.44","hash":"6cb9da07223b3f0ccb9c174f34ac27987d65e628","price":"0.41","side":"BUY","size":"91.84"},{"asset_id":"96600821790790307414914106093858868634329285205417149685270682748367152458577","best_ask":"0.56","best_bid":"0.55","hash":"be6a38d8ca10909c9a357cc092c541d2a9600594","price":"0.59","side":"SELL","size":"91.84"}],"timestamp":"1785211225755"},"payload_hash":"576e7f6dcc33483fe0bddf9c40e125d7b071041cc62ca6d0778ca18e868a222e","raw_frame":"{\"market\":\"0xd412ce774cfcf8dc9f71164aac78783978aac7b03871702a3b8a481bd9dc9688\", \"price_changes\":[{\"asset_id\":\"107603864457683460275633293642179940881969192120168665300712204232021063124301\", \"price\":\"0.41\", \"size\":\"91.84\", \"side\":\"BUY\", \"hash\":\"6cb9da07223b3f0ccb9c174f34ac27987d65e628\", \"best_bid\":\"0.44\", \"best_ask\":\"0.45\"}, {\"asset_id\":\"96600821790790307414914106093858868634329285205417149685270682748367152458577\", \"price\":\"0.59\", \"size\":\"91.84\", \"side\":\"SELL\", \"hash\":\"be6a38d8ca10909c9a357cc092c541d2a9600594\", \"best_bid\":\"0.55\", \"best_ask\":\"0.56\"}], \"timestamp\":\"1785211225755\", \"event_type\":\"price_change\"}","received_at":"2026-07-28T04:00:28.644147Z","schema_version":"clob-market-ws.price_change.v1","sequence":null,"server_hash":null,"server_timestamp":"1785211225755","session_id":"2d607381e3054cee91998cdf45a4231c","source":"clob_market_ws"},"received_at":"2026-07-28T04:00:28.644147Z","record_id":"f2fccc3eacf06171dee0f7ffa3d2aecaa39940bb80e994e572662c9fbfb9c378","schema_fingerprint":"4aa3821a28b0b7c2400bc59aba4bcc0a76e971dadd19610d3ad38c768e124dc7","schema_version":"edge-lab-recorder.raw.v1","sequence":null,"source":"clob_market_ws"}
{"event_at":"2026-07-28T04:00:25.756000Z","event_fingerprint":"e26417b19e9bd1cf50b85d75300456be77b0bbbd3321c40ac2d143dacd2865fc","payload":{"connection_id":"f6725804f86a4c4eb588e4d5ed7db029","event_at":"2026-07-28T04:00:25.756000Z","event_type":"price_change","frame_hash":"9000129b633934d51a396835891a79ab04dc3c22a3220fdb9cb9c0f063fa0c47","frame_index":0,"kind":"data","monotonic_ns":313211710441666,"payload":{"event_type":"price_change","market":"0xd412ce774cfcf8dc9f71164aac78783978aac7b03871702a3b8a481bd9dc9688","price_changes":[{"asset_id":"96600821790790307414914106093858868634329285205417149685270682748367152458577","best_ask":"0.56","best_bid":"0.55","hash":"4880c4a21dbfb01e2445f948f35e625d42d7af26","price":"0.45","side":"BUY","size":"143"},{"asset_id":"107603864457683460275633293642179940881969192120168665300712204232021063124301","best_ask":"0.45","best_bid":"0.44","hash":"f8025723aa481af72377d649fe967dd82a9e6284","price":"0.55","side":"SELL","size":"143"}],"timestamp":"1785211225756"},"payload_hash":"e20fa70a0b914864566152c4873d5a8d8374c4f6e14bbeb5debeccfc40548bbe","raw_frame":"{\"market\":\"0xd412ce774cfcf8dc9f71164aac78783978aac7b03871702a3b8a481bd9dc9688\", \"price_changes\":[{\"asset_id\":\"96600821790790307414914106093858868634329285205417149685270682748367152458577\", \"price\":\"0.45\", \"size\":\"143\", \"side\":\"BUY\", \"hash\":\"4880c4a21dbfb01e2445f948f35e625d42d7af26\", \"best_bid\":\"0.55\", \"best_ask\":\"0.56\"}, {\"asset_id\":\"107603864457683460275633293642179940881969192120168665300712204232021063124301\", \"price\":\"0.55\", \"size\":\"143\", \"side\":\"SELL\", \"hash\":\"f8025723aa481af72377d649fe967dd82a9e6284\", \"best_bid\":\"0.44\", \"best_ask\":\"0.45\"}], \"timestamp\":\"1785211225756\", \"event_type\":\"price_change\"}","received_at":"2026-07-28T04:00:28.662320Z","schema_version":"clob-market-ws.price_change.v1","sequence":null,"server_hash":null,"server_timestamp":"1785211225756","session_id":"2d607381e3054cee91998cdf45a4231c","source":"clob_market_ws"},"received_at":"2026-07-28T04:00:28.662320Z","record_id":"d9b7575bac4b22d99f025f635996ae2e1a4bcbdf50dc37275ccb350fd66cfd82","schema_fingerprint":"4aa3821a28b0b7c2400bc59aba4bcc0a76e971dadd19610d3ad38c768e124dc7","schema_version":"edge-lab-recorder.raw.v1","sequence":null,"source":"clob_market_ws"}
{"event_at":"2026-07-28T04:00:25.756000Z","event_fingerprint":"2027abbf62ad32fc68f78079517e588909244a2786e35bcaab4d4be174939470","payload":{"connection_id":"f6725804f86a4c4eb588e4d5ed7db029","event_at":"2026-07-28T04:00:25.756000Z","event_type":"price_change","frame_hash":"c30336d88878b23b4b730bacd5645e96e0b6a85364880acff517901d43738cde","frame_index":0,"kind":"data","monotonic_ns":313211722391083,"payload":{"event_type":"price_change","market":"0xd412ce774cfcf8dc9f71164aac78783978aac7b03871702a3b8a481bd9dc9688","price_changes":[{"asset_id":"96600821790790307414914106093858868634329285205417149685270682748367152458577","best_ask":"0.56","best_bid":"0.55","hash":"6e38d7351d50073bc16c1906c195f7800fb43bd0","price":"0.35","side":"BUY","size":"67.32"},{"asset_id":"107603864457683460275633293642179940881969192120168665300712204232021063124301","best_ask":"0.45","best_bid":"0.44","hash":"297094303b26dea6f75e37f39049773fc9cf272d","price":"0.65","side":"SELL","size":"67.32"}],"timestamp":"1785211225756"},"payload_hash":"4ac0392e27559a6e10e88ac21b0f93fbee8545c5558f6ecb3e60e24deb5e9bac","raw_frame":"{\"market\":\"0xd412ce774cfcf8dc9f71164aac78783978aac7b03871702a3b8a481bd9dc9688\", \"price_changes\":[{\"asset_id\":\"96600821790790307414914106093858868634329285205417149685270682748367152458577\", \"price\":\"0.35\", \"size\":\"67.32\", \"side\":\"BUY\", \"hash\":\"6e38d7351d50073bc16c1906c195f7800fb43bd0\", \"best_bid\":\"0.55\", \"best_ask\":\"0.56\"}, {\"asset_id\":\"107603864457683460275633293642179940881969192120168665300712204232021063124301\", \"price\":\"0.65\", \"size\":\"67.32\", \"side\":\"SELL\", \"hash\":\"297094303b26dea6f75e37f39049773fc9cf272d\", \"best_bid\":\"0.44\", \"best_ask\":\"0.45\"}], \"timestamp\":\"1785211225756\", \"event_type\":\"price_change\"}","received_at":"2026-07-28T04:00:28.674270Z","schema_version":"clob-market-ws.price_change.v1","sequence":null,"server_hash":null,"server_timestamp":"1785211225756","session_id":"2d607381e3054cee91998cdf45a4231c","source":"clob_market_ws"},"received_at":"2026-07-28T04:00:28.674270Z","record_id":"09960b8e371558ae9275bc64f883c979c855e46cd85e67f994e6bee6d684e3d9","schema_fingerprint":"4aa3821a28b0b7c2400bc59aba4bcc0a76e971dadd19610d3ad38c768e124dc7","schema_version":"edge-lab-recorder.raw.v1","sequence":null,"source":"clob_market_ws"}
{"event_at":"2026-07-28T04:00:25.756000Z","event_fingerprint":"f7dbf5baaaa60439cb7f2c4697786e462962e87c7a8276a154bafacbcad8bc62","payload":{"connection_id":"f6725804f86a4c4eb588e4d5ed7db029","event_at":"2026-07-28T04:00:25.756000Z","event_type":"price_change","frame_hash":"d77d5ca1d21ee7ed2612764f5168f6a5504276eb970549703699a8dd212f5ea1","frame_index":0,"kind":"data","monotonic_ns":313211730963791,"payload":{"event_type":"price_change","market":"0xd412ce774cfcf8dc9f71164aac78783978aac7b03871702a3b8a481bd9dc9688","price_changes":[{"asset_id":"107603864457683460275633293642179940881969192120168665300712204232021063124301","best_ask":"0.45","best_bid":"0.44","hash":"4b7839e87ae6046ac4c6c7bd0fdc47b3e9796a3a","price":"0.4","side":"BUY","size":"172.92"},{"asset_id":"96600821790790307414914106093858868634329285205417149685270682748367152458577","best_ask":"0.56","best_bid":"0.55","hash":"aac1aa523bfef4db66f2bdb7b46b761f8fc9127c","price":"0.6","side":"SELL","size":"172.92"}],"timestamp":"1785211225756"},"payload_hash":"d4284f2d5e7d009f3671bb3be58792115339affe2c198b022ccb8217a5b49599","raw_frame":"{\"market\":\"0xd412ce774cfcf8dc9f71164aac78783978aac7b03871702a3b8a481bd9dc9688\", \"price_changes\":[{\"asset_id\":\"107603864457683460275633293642179940881969192120168665300712204232021063124301\", \"price\":\"0.4\", \"size\":\"172.92\", \"side\":\"BUY\", \"hash\":\"4b7839e87ae6046ac4c6c7bd0fdc47b3e9796a3a\", \"best_bid\":\"0.44\", \"best_ask\":\"0.45\"}, {\"asset_id\":\"96600821790790307414914106093858868634329285205417149685270682748367152458577\", \"price\":\"0.6\", \"size\":\"172.92\", \"side\":\"SELL\", \"hash\":\"aac1aa523bfef4db66f2bdb7b46b761f8fc9127c\", \"best_bid\":\"0.55\", \"best_ask\":\"0.56\"}], \"timestamp\":\"1785211225756\", \"event_type\":\"price_change\"}","received_at":"2026-07-28T04:00:28.682843Z","schema_version":"clob-market-ws.price_change.v1","sequence":null,"server_hash":null,"server_timestamp":"1785211225756","session_id":"2d607381e3054cee91998cdf45a4231c","source":"clob_market_ws"},"received_at":"2026-07-28T04:00:28.682843Z","record_id":"5d441b29628ee509ffd0057af455cabf44341ff33c125124c00c14bd3ceb81e3","schema_fingerprint":"4aa3821a28b0b7c2400bc59aba4bcc0a76e971dadd19610d3ad38c768e124dc7","schema_version":"edge-lab-recorder.raw.v1","sequence":null,"source":"clob_market_ws"}
{"event_at":"2026-07-28T04:00:25.766000Z","event_fingerprint":"8bb168ad4c41fd7a326f3fb9ce7c727cc3b904336bebe8ea2c7ec92f9e56b8c1","payload":{"connection_id":"f6725804f86a4c4eb588e4d5ed7db029","event_at":"2026-07-28T04:00:25.766000Z","event_type":"price_change","frame_hash":"9fb063b9a6b4e38cf710d8b26b4b01f0ac3f81980f6b0d55e787727f7d27e387","frame_index":0,"kind":"data","monotonic_ns":313211737870291,"payload":{"event_type":"price_change","market":"0xd412ce774cfcf8dc9f71164aac78783978aac7b03871702a3b8a481bd9dc9688","price_changes":[{"asset_id":"107603864457683460275633293642179940881969192120168665300712204232021063124301","best_ask":"0.45","best_bid":"0.44","hash":"9c7caf15522c98b0bdd9e0be63c8aa98de72ff24","price":"0.45","side":"SELL","size":"41.28"},{"asset_id":"96600821790790307414914106093858868634329285205417149685270682748367152458577","best_ask":"0.56","best_bid":"0.55","hash":"bf95d9db2015971ecee005cc0ac18acabff6b35b","price":"0.55","side":"BUY","size":"41.28"}],"timestamp":"1785211225766"},"payload_hash":"feeffd0123780850c7bb3ba11889bca09738995a6d0cff8717b88729ae727e31","raw_frame":"{\"market\":\"0xd412ce774cfcf8dc9f71164aac78783978aac7b03871702a3b8a481bd9dc9688\", \"price_changes\":[{\"asset_id\":\"107603864457683460275633293642179940881969192120168665300712204232021063124301\", \"price\":\"0.45\", \"size\":\"41.28\", \"side\":\"SELL\", \"hash\":\"9c7caf15522c98b0bdd9e0be63c8aa98de72ff24\", \"best_bid\":\"0.44\", \"best_ask\":\"0.45\"}, {\"asset_id\":\"96600821790790307414914106093858868634329285205417149685270682748367152458577\", \"price\":\"0.55\", \"size\":\"41.28\", \"side\":\"BUY\", \"hash\":\"bf95d9db2015971ecee005cc0ac18acabff6b35b\", \"best_bid\":\"0.55\", \"best_ask\":\"0.56\"}], \"timestamp\":\"1785211225766\", \"event_type\":\"price_change\"}","received_at":"2026-07-28T04:00:28.689749Z","schema_version":"clob-market-ws.price_change.v1","sequence":null,"server_hash":null,"server_timestamp":"1785211225766","session_id":"2d607381e3054cee91998cdf45a4231c","source":"clob_market_ws"},"received_at":"2026-07-28T04:00:28.689749Z","record_id":"2fd960a01c0869f86e8f5b56036e99774cbe1e25d725ec1324da8836131c2862","schema_fingerprint":"4aa3821a28b0b7c2400bc59aba4bcc0a76e971dadd19610d3ad38c768e124dc7","schema_version":"edge-lab-recorder.raw.v1","sequence":null,"source":"clob_market_ws"}
{"event_at":"2026-07-28T04:00:25.767000Z","event_fingerprint":"483c8658cb1b8e8702dddf239d754fbd5a553dc7fed53ac4f9e5c915a179662c","payload":{"connection_id":"f6725804f86a4c4eb588e4d5ed7db029","event_at":"2026-07-28T04:00:25.767000Z","event_type":"price_change","frame_hash":"f0796b330afb02d62dc5c2bb17e26666531c4718962ebd24ce27a8b85fd41ed0","frame_index":0,"kind":"data","monotonic_ns":313211742986166,"payload":{"event_type":"price_change","market":"0xd412ce774cfcf8dc9f71164aac78783978aac7b03871702a3b8a481bd9dc9688","price_changes":[{"asset_id":"107603864457683460275633293642179940881969192120168665300712204232021063124301","best_ask":"0.45","best_bid":"0.44","hash":"73b27523a22e74183812d2d1a6ae08dc24e6b996","price":"0.45","side":"SELL","size":"46.28"},{"asset_id":"96600821790790307414914106093858868634329285205417149685270682748367152458577","best_ask":"0.56","best_bid":"0.55","hash":"781f2afcf33d2c8834da2b89afa461a86ef23167","price":"0.55","side":"BUY","size":"46.28"}],"timestamp":"1785211225767"},"payload_hash":"342eec23e4b01b61189762e78967b261319b18037eee79d49dd10ee140ac2344","raw_frame":"{\"market\":\"0xd412ce774cfcf8dc9f71164aac78783978aac7b03871702a3b8a481bd9dc9688\", \"price_changes\":[{\"asset_id\":\"107603864457683460275633293642179940881969192120168665300712204232021063124301\", \"price\":\"0.45\", \"size\":\"46.28\", \"side\":\"SELL\", \"hash\":\"73b27523a22e74183812d2d1a6ae08dc24e6b996\", \"best_bid\":\"0.44\", \"best_ask\":\"0.45\"}, {\"asset_id\":\"96600821790790307414914106093858868634329285205417149685270682748367152458577\", \"price\":\"0.55\", \"size\":\"46.28\", \"side\":\"BUY\", \"hash\":\"781f2afcf33d2c8834da2b89afa461a86ef23167\", \"best_bid\":\"0.55\", \"best_ask\":\"0.56\"}], \"timestamp\":\"1785211225767\", \"event_type\":\"price_change\"}","received_at":"2026-07-28T04:00:28.694865Z","schema_version":"clob-market-ws.price_change.v1","sequence":null,"server_hash":null,"server_timestamp":"1785211225767","session_id":"2d607381e3054cee91998cdf45a4231c","source":"clob_market_ws"},"received_at":"2026-07-28T04:00:28.694865Z","record_id":"0979192ca135d11c1f41afd5acb33d6be0fa621aad0397e0ec041731f2ac73b3","schema_fingerprint":"4aa3821a28b0b7c2400bc59aba4bcc0a76e971dadd19610d3ad38c768e124dc7","schema_version":"edge-lab-recorder.raw.v1","sequence":null,"source":"clob_market_ws"}
{"event_at":"2026-07-28T04:00:25.768000Z","event_fingerprint":"99109f2894223c166de10e3a47027168d186bb9a955112ac7d09f1436465aa82","payload":{"connection_id":"f6725804f86a4c4eb588e4d5ed7db029","event_at":"2026-07-28T04:00:25.768000Z","event_type":"price_change","frame_hash":"24b32b5cedffebdf2d112ab96331288a2b3b1e2834e8c2d31bca8588ae8d388b","frame_index":0,"kind":"data","monotonic_ns":313211748667375,"payload":{"event_type":"price_change","market":"0xd412ce774cfcf8dc9f71164aac78783978aac7b03871702a3b8a481bd9dc9688","price_changes":[{"asset_id":"107603864457683460275633293642179940881969192120168665300712204232021063124301","best_ask":"0.45","best_bid":"0.44","hash":"598d1b2c50e2cd2a8a8ccd0e85ce7d2de6838d4b","price":"0.45","side":"SELL","size":"41.28"},{"asset_id":"96600821790790307414914106093858868634329285205417149685270682748367152458577","best_ask":"0.56","best_bid":"0.55","hash":"fbf83c05ffad077494af7d80d7ec32cfda366103","price":"0.55","side":"BUY","size":"41.28"}],"timestamp":"1785211225768"},"payload_hash":"6deebb2550e02ad658fd80c8a3df4bdb52d40438795c45f76f521bf4a2b88fb9","raw_frame":"{\"market\":\"0xd412ce774cfcf8dc9f71164aac78783978aac7b03871702a3b8a481bd9dc9688\", \"price_changes\":[{\"asset_id\":\"107603864457683460275633293642179940881969192120168665300712204232021063124301\", \"price\":\"0.45\", \"size\":\"41.28\", \"side\":\"SELL\", \"hash\":\"598d1b2c50e2cd2a8a8ccd0e85ce7d2de6838d4b\", \"best_bid\":\"0.44\", \"best_ask\":\"0.45\"}, {\"asset_id\":\"96600821790790307414914106093858868634329285205417149685270682748367152458577\", \"price\":\"0.55\", \"size\":\"41.28\", \"side\":\"BUY\", \"hash\":\"fbf83c05ffad077494af7d80d7ec32cfda366103\", \"best_bid\":\"0.55\", \"best_ask\":\"0.56\"}], \"timestamp\":\"1785211225768\", \"event_type\":\"price_change\"}","received_at":"2026-07-28T04:00:28.700546Z","schema_version":"clob-market-ws.price_change.v1","sequence":null,"server_hash":null,"server_timestamp":"1785211225768","session_id":"2d607381e3054cee91998cdf45a4231c","source":"clob_market_ws"},"received_at":"2026-07-28T04:00:28.700546Z","record_id":"6277c88d9b97054e966d3a564975896c6e5f60c5fa7d41878c1e54825d9956d9","schema_fingerprint":"4aa3821a28b0b7c2400bc59aba4bcc0a76e971dadd19610d3ad38c768e124dc7","schema_version":"edge-lab-recorder.raw.v1","sequence":null,"source":"clob_market_ws"}
{"event_at":"2026-07-28T04:00:25.769000Z","event_fingerprint":"2203549ebba1d8236684c7faccf0a588aea5432f378e9185991a7e032f22de10","payload":{"connection_id":"f6725804f86a4c4eb588e4d5ed7db029","event_at":"2026-07-28T04:00:25.769000Z","event_type":"price_change","frame_hash":"a9a951ab98a79ff9e3df43642f19b9ba91836911d7e769f9f94e5fb2426ef742","frame_index":0,"kind":"data","monotonic_ns":313211755605791,"payload":{"event_type":"price_change","market":"0xd412ce774cfcf8dc9f71164aac78783978aac7b03871702a3b8a481bd9dc9688","price_changes":[{"asset_id":"96600821790790307414914106093858868634329285205417149685270682748367152458577","best_ask":"0.56","best_bid":"0.55","hash":"93e6588ab4b10d410979189f0ecce443073ee895","price":"0.52","side":"BUY","size":"66.2"},{"asset_id":"107603864457683460275633293642179940881969192120168665300712204232021063124301","best_ask":"0.45","best_bid":"0.44","hash":"398f2a8d89887001f074d22bab91a75903f540fd","price":"0.48","side":"SELL","size":"66.2"}],"timestamp":"1785211225769"},"payload_hash":"8d3c0693fcd67fb19ace7fa87a08a113373159cbc57feddd7ac9afbf1eb23593","raw_frame":"{\"market\":\"0xd412ce774cfcf8dc9f71164aac78783978aac7b03871702a3b8a481bd9dc9688\", \"price_changes\":[{\"asset_id\":\"96600821790790307414914106093858868634329285205417149685270682748367152458577\", \"price\":\"0.52\", \"size\":\"66.2\", \"side\":\"BUY\", \"hash\":\"93e6588ab4b10d410979189f0ecce443073ee895\", \"best_bid\":\"0.55\", \"best_ask\":\"0.56\"}, {\"asset_id\":\"107603864457683460275633293642179940881969192120168665300712204232021063124301\", \"price\":\"0.48\", \"size\":\"66.2\", \"side\":\"SELL\", \"hash\":\"398f2a8d89887001f074d22bab91a75903f540fd\", \"best_bid\":\"0.44\", \"best_ask\":\"0.45\"}], \"timestamp\":\"1785211225769\", \"event_type\":\"price_change\"}","received_at":"2026-07-28T04:00:28.707484Z","schema_version":"clob-market-ws.price_change.v1","sequence":null,"server_hash":null,"server_timestamp":"1785211225769","session_id":"2d607381e3054cee91998cdf45a4231c","source":"clob_market_ws"},"received_at":"2026-07-28T04:00:28.707484Z","record_id":"34106d5a12fa394778840c40bdfea71745465c385d796811d241fe376e72dcf2","schema_fingerprint":"4aa3821a28b0b7c2400bc59aba4bcc0a76e971dadd19610d3ad38c768e124dc7","schema_version":"edge-lab-recorder.raw.v1","sequence":null,"source":"clob_market_ws"}
{"event_at":"2026-07-28T04:00:25.769000Z","event_fingerprint":"924b1be90496187467f2e8a086ced7e555a0b60a3489e10ce5e796ecb06f4b05","payload":{"connection_id":"f6725804f86a4c4eb588e4d5ed7db029","event_at":"2026-07-28T04:00:25.769000Z","event_type":"price_change","frame_hash":"3e9ebe5967d17aff229308c94dd6eb3fecf30fd2d0e3f2e8218edde5f0497e4c","frame_index":0,"kind":"data","monotonic_ns":313211763767916,"payload":{"event_type":"price_change","market":"0xd412ce774cfcf8dc9f71164aac78783978aac7b03871702a3b8a481bd9dc9688","price_changes":[{"asset_id":"107603864457683460275633293642179940881969192120168665300712204232021063124301","best_ask":"0.45","best_bid":"0.44","hash":"5d822c2e3d723e159eb3699423869387950a7f5d","price":"0.45","side":"SELL","size":"36.28"},{"asset_id":"96600821790790307414914106093858868634329285205417149685270682748367152458577","best_ask":"0.56","best_bid":"0.55","hash":"f9fc53292eccdff4c0b205088107809410ab81e3","price":"0.55","side":"BUY","size":"36.28"}],"timestamp":"1785211225769"},"payload_hash":"602b88438a8c66f67d045e2cb41d312d117dc64cfd3b9f3271c2837159d269d0","raw_frame":"{\"market\":\"0xd412ce774cfcf8dc9f71164aac78783978aac7b03871702a3b8a481bd9dc9688\", \"price_changes\":[{\"asset_id\":\"107603864457683460275633293642179940881969192120168665300712204232021063124301\", \"price\":\"0.45\", \"size\":\"36.28\", \"side\":\"SELL\", \"hash\":\"5d822c2e3d723e159eb3699423869387950a7f5d\", \"best_bid\":\"0.44\", \"best_ask\":\"0.45\"}, {\"asset_id\":\"96600821790790307414914106093858868634329285205417149685270682748367152458577\", \"price\":\"0.55\", \"size\":\"36.28\", \"side\":\"BUY\", \"hash\":\"f9fc53292eccdff4c0b205088107809410ab81e3\", \"best_bid\":\"0.55\", \"best_ask\":\"0.56\"}], \"timestamp\":\"1785211225769\", \"event_type\":\"price_change\"}","received_at":"2026-07-28T04:00:28.715646Z","schema_version":"clob-market-ws.price_change.v1","sequence":null,"server_hash":null,"server_timestamp":"1785211225769","session_id":"2d607381e3054cee91998cdf45a4231c","source":"clob_market_ws"},"received_at":"2026-07-28T04:00:28.715646Z","record_id":"a062b36caf6786ac793b60cd82d9cac5bbefaf4e8396f853e4be8b0c6926cc83","schema_fingerprint":"4aa3821a28b0b7c2400bc59aba4bcc0a76e971dadd19610d3ad38c768e124dc7","schema_version":"edge-lab-recorder.raw.v1","sequence":null,"source":"clob_market_ws"}
{"event_at":"2026-07-28T04:00:25.770000Z","event_fingerprint":"883492199dc1ecc278e165b2c9a620c73105220582c0c2ce6e13e334ee7526c1","payload":{"connection_id":"f6725804f86a4c4eb588e4d5ed7db029","event_at":"2026-07-28T04:00:25.770000Z","event_type":"price_change","frame_hash":"35322d93c62daf9a2641d2e93e496aa9e3669e1ab37fe5d4ba89436013e99b47","frame_index":0,"kind":"data","monotonic_ns":313211767490458,"payload":{"event_type":"price_change","market":"0xd412ce774cfcf8dc9f71164aac78783978aac7b03871702a3b8a481bd9dc9688","price_changes":[{"asset_id":"107603864457683460275633293642179940881969192120168665300712204232021063124301","best_ask":"0.45","best_bid":"0.44","hash":"8432ec2bb27500c3aadd4e086855d0891af231e4","price":"0.38","side":"BUY","size":"147"},{"asset_id":"96600821790790307414914106093858868634329285205417149685270682748367152458577","best_ask":"0.56","best_bid":"0.55","hash":"a8cbdecf35dfd0ee356d1a3887f391eed928dd8a","price":"0.62","side":"SELL","size":"147"}],"timestamp":"1785211225770"},"payload_hash":"2f67e93fa16f0cf50c5a9f2f4c5e1f6ec2db9300a7f8640941fc613a951296ed","raw_frame":"{\"market\":\"0xd412ce774cfcf8dc9f71164aac78783978aac7b03871702a3b8a481bd9dc9688\", \"price_changes\":[{\"asset_id\":\"107603864457683460275633293642179940881969192120168665300712204232021063124301\", \"price\":\"0.38\", \"size\":\"147\", \"side\":\"BUY\", \"hash\":\"8432ec2bb27500c3aadd4e086855d0891af231e4\", \"best_bid\":\"0.44\", \"best_ask\":\"0.45\"}, {\"asset_id\":\"96600821790790307414914106093858868634329285205417149685270682748367152458577\", \"price\":\"0.62\", \"size\":\"147\", \"side\":\"SELL\", \"hash\":\"a8cbdecf35dfd0ee356d1a3887f391eed928dd8a\", \"best_bid\":\"0.55\", \"best_ask\":\"0.56\"}], \"timestamp\":\"1785211225770\", \"event_type\":\"price_change\"}","received_at":"2026-07-28T04:00:28.719369Z","schema_version":"clob-market-ws.price_change.v1","sequence":null,"server_hash":null,"server_timestamp":"1785211225770","session_id":"2d607381e3054cee91998cdf45a4231c","source":"clob_market_ws"},"received_at":"2026-07-28T04:00:28.719369Z","record_id":"f6d29f20b4ab7cf39427a3d6b1d5cf622ba3239a500b9410ad9a956811f8df14","schema_fingerprint":"4aa3821a28b0b7c2400bc59aba4bcc0a76e971dadd19610d3ad38c768e124dc7","schema_version":"edge-lab-recorder.raw.v1","sequence":null,"source":"clob_market_ws"}
{"event_at":"2026-07-28T04:00:25.771000Z","event_fingerprint":"1362c193e32ffaa794a1c102e6431a826ab6d08533c18e4f7a8c52ede4cbbc7c","payload":{"connection_id":"f6725804f86a4c4eb588e4d5ed7db029","event_at":"2026-07-28T04:00:25.771000Z","event_type":"price_change","frame_hash":"f5822eb1729792c88b35165a4b906cb28ea3a1909a1aff84a078ee26f67aaf52","frame_index":0,"kind":"data","monotonic_ns":313211779972833,"payload":{"event_type":"price_change","market":"0xd412ce774cfcf8dc9f71164aac78783978aac7b03871702a3b8a481bd9dc9688","price_changes":[{"asset_id":"107603864457683460275633293642179940881969192120168665300712204232021063124301","best_ask":"0.45","best_bid":"0.44","hash":"69c3ec833f3ff63a08c6f78bf0bde35c54ae00a9","price":"0.39","side":"BUY","size":"93.52"},{"asset_id":"96600821790790307414914106093858868634329285205417149685270682748367152458577","best_ask":"0.56","best_bid":"0.55","hash":"6058b2c15ea964393cfcdcb1b90ba3021b3c26a0","price":"0.61","side":"SELL","size":"93.52"}],"timestamp":"1785211225771"},"payload_hash":"56fad2aef14e01a1a07eeb33acf6e8b176bbda8e3801b039fa7104ed0248c329","raw_frame":"{\"market\":\"0xd412ce774cfcf8dc9f71164aac78783978aac7b03871702a3b8a481bd9dc9688\", \"price_changes\":[{\"asset_id\":\"107603864457683460275633293642179940881969192120168665300712204232021063124301\", \"price\":\"0.39\", \"size\":\"93.52\", \"side\":\"BUY\", \"hash\":\"69c3ec833f3ff63a08c6f78bf0bde35c54ae00a9\", \"best_bid\":\"0.44\", \"best_ask\":\"0.45\"}, {\"asset_id\":\"96600821790790307414914106093858868634329285205417149685270682748367152458577\", \"price\":\"0.61\", \"size\":\"93.52\", \"side\":\"SELL\", \"hash\":\"6058b2c15ea964393cfcdcb1b90ba3021b3c26a0\", \"best_bid\":\"0.55\", \"best_ask\":\"0.56\"}], \"timestamp\":\"1785211225771\", \"event_type\":\"price_change\"}","received_at":"2026-07-28T04:00:28.731851Z","schema_version":"clob-market-ws.price_change.v1","sequence":null,"server_hash":null,"server_timestamp":"1785211225771","session_id":"2d607381e3054cee91998cdf45a4231c","source":"clob_market_ws"},"received_at":"2026-07-28T04:00:28.731851Z","record_id":"7c5c9d9c560d5611d5a1976d851ee701e2fd0fde73e19df0dcce831ef2d4266b","schema_fingerprint":"4aa3821a28b0b7c2400bc59aba4bcc0a76e971dadd19610d3ad38c768e124dc7","schema_version":"edge-lab-recorder.raw.v1","sequence":null,"source":"clob_market_ws"}
{"event_at":"2026-07-28T04:00:25.772000Z","event_fingerprint":"a645406aa4a68d5c89c0114851b2db9eea6a095c8980404fae27883558aafd32","payload":{"connection_id":"f6725804f86a4c4eb588e4d5ed7db029","event_at":"2026-07-28T04:00:25.772000Z","event_type":"price_change","frame_hash":"e870c620616de06c9da237c67ee833aa87a21ab5962ca794db1fb6eb29c75fe9","frame_index":0,"kind":"data","monotonic_ns":313211784173541,"payload":{"event_type":"price_change","market":"0xd412ce774cfcf8dc9f71164aac78783978aac7b03871702a3b8a481bd9dc9688","price_changes":[{"asset_id":"96600821790790307414914106093858868634329285205417149685270682748367152458577","best_ask":"0.56","best_bid":"0.55","hash":"bb3ec1ba6848ef762f0a3ad549cee5d4c1096672","price":"0.52","side":"BUY","size":"53.6"},{"asset_id":"107603864457683460275633293642179940881969192120168665300712204232021063124301","best_ask":"0.45","best_bid":"0.44","hash":"34a81da1cfb0753844165197bd12ec06e2d3b0aa","price":"0.48","side":"SELL","size":"53.6"}],"timestamp":"1785211225772"},"payload_hash":"fcb56252ff554755c86a742bcecc23bfcc5918355cbbce91022229894f1f3ff7","raw_frame":"{\"market\":\"0xd412ce774cfcf8dc9f71164aac78783978aac7b03871702a3b8a481bd9dc9688\", \"price_changes\":[{\"asset_id\":\"96600821790790307414914106093858868634329285205417149685270682748367152458577\", \"price\":\"0.52\", \"size\":\"53.6\", \"side\":\"BUY\", \"hash\":\"bb3ec1ba6848ef762f0a3ad549cee5d4c1096672\", \"best_bid\":\"0.55\", \"best_ask\":\"0.56\"}, {\"asset_id\":\"107603864457683460275633293642179940881969192120168665300712204232021063124301\", \"price\":\"0.48\", \"size\":\"53.6\", \"side\":\"SELL\", \"hash\":\"34a81da1cfb0753844165197bd12ec06e2d3b0aa\", \"best_bid\":\"0.44\", \"best_ask\":\"0.45\"}], \"timestamp\":\"1785211225772\", \"event_type\":\"price_change\"}","received_at":"2026-07-28T04:00:28.736053Z","schema_version":"clob-market-ws.price_change.v1","sequence":null,"server_hash":null,"server_timestamp":"1785211225772","session_id":"2d607381e3054cee91998cdf45a4231c","source":"clob_market_ws"},"received_at":"2026-07-28T04:00:28.736053Z","record_id":"bd0725d5160dd58ae2a6975699bb2f6ee421e712d8cf2df2520d742de89e5b55","schema_fingerprint":"4aa3821a28b0b7c2400bc59aba4bcc0a76e971dadd19610d3ad38c768e124dc7","schema_version":"edge-lab-recorder.raw.v1","sequence":null,"source":"clob_market_ws"}
{"event_at":"2026-07-28T04:00:25.772000Z","event_fingerprint":"bbaa2ba281e20fa48706e51ce97a8c880dcfb0ca201761355a850e173f46ece8","payload":{"connection_id":"f6725804f86a4c4eb588e4d5ed7db029","event_at":"2026-07-28T04:00:25.772000Z","event_type":"price_change","frame_hash":"f19a324f4d6bf67c7fd12a2a4c0241d103eff6fea06d2df5c2614e8844849ba0","frame_index":0,"kind":"data","monotonic_ns":313211789503083,"payload":{"event_type":"price_change","market":"0xd412ce774cfcf8dc9f71164aac78783978aac7b03871702a3b8a481bd9dc9688","price_changes":[{"asset_id":"96600821790790307414914106093858868634329285205417149685270682748367152458577","best_ask":"0.56","best_bid":"0.55","hash":"e26bef4455c1140b22482fa8c64e5e6eaf940d66","price":"0.53","side":"BUY","size":"52.24"},{"asset_id":"107603864457683460275633293642179940881969192120168665300712204232021063124301","best_ask":"0.45","best_bid":"0.44","hash":"e6e4bc4e5f1f3150562e8bc26d02c06e83a0e4b1","price":"0.47","side":"SELL","size":"52.24"}],"timestamp":"1785211225772"},"payload_hash":"2ebd21d78cfa2296c15a1112dfc13fc868795c1fae2acad28b9bc8c9b9023e67","raw_frame":"{\"market\":\"0xd412ce774cfcf8dc9f71164aac78783978aac7b03871702a3b8a481bd9dc9688\", \"price_changes\":[{\"asset_id\":\"96600821790790307414914106093858868634329285205417149685270682748367152458577\", \"price\":\"0.53\", \"size\":\"52.24\", \"side\":\"BUY\", \"hash\":\"e26bef4455c1140b22482fa8c64e5e6eaf940d66\", \"best_bid\":\"0.55\", \"best_ask\":\"0.56\"}, {\"asset_id\":\"107603864457683460275633293642179940881969192120168665300712204232021063124301\", \"price\":\"0.47\", \"size\":\"52.24\", \"side\":\"SELL\", \"hash\":\"e6e4bc4e5f1f3150562e8bc26d02c06e83a0e4b1\", \"best_bid\":\"0.44\", \"best_ask\":\"0.45\"}], \"timestamp\":\"1785211225772\", \"event_type\":\"price_change\"}","received_at":"2026-07-28T04:00:28.741381Z","schema_version":"clob-market-ws.price_change.v1","sequence":null,"server_hash":null,"server_timestamp":"1785211225772","session_id":"2d607381e3054cee91998cdf45a4231c","source":"clob_market_ws"},"received_at":"2026-07-28T04:00:28.741381Z","record_id":"f765212a21b0d61adbb3a2e44d660f5beea6cb079fc8ed55081da5a67370db78","schema_fingerprint":"4aa3821a28b0b7c2400bc59aba4bcc0a76e971dadd19610d3ad38c768e124dc7","schema_version":"edge-lab-recorder.raw.v1","sequence":null,"source":"clob_market_ws"}
{"event_at":"2026-07-28T04:00:25.772000Z","event_fingerprint":"fdb6978cc6f9a4f7dd5e4c1a0e0fc06d5e0bac2f91a04be3744886d71b313e44","payload":{"connection_id":"f6725804f86a4c4eb588e4d5ed7db029","event_at":"2026-07-28T04:00:25.772000Z","event_type":"price_change","frame_hash":"16c386938123286094ffd56ccf70681b9cab626ae416ed8539d31a3a7d971a03","frame_index":0,"kind":"data","monotonic_ns":313211793758375,"payload":{"event_type":"price_change","market":"0xd412ce774cfcf8dc9f71164aac78783978aac7b03871702a3b8a481bd9dc9688","price_changes":[{"asset_id":"96600821790790307414914106093858868634329285205417149685270682748367152458577","best_ask":"0.56","best_bid":"0.55","hash":"79ddd150b48bd277aef5a5fff5200ab5d2ab30ac","price":"0.53","side":"BUY","size":"46.6"},{"asset_id":"107603864457683460275633293642179940881969192120168665300712204232021063124301","best_ask":"0.45","best_bid":"0.44","hash":"e23f7c31565d0d788e43246326c729b08c11bd67","price":"0.47","side":"SELL","size":"46.6"}],"timestamp":"1785211225772"},"payload_hash":"82b9265ffaa91d4d04337964d770dc206ebf77722e43f39165495d2105154433","raw_frame":"{\"market\":\"0xd412ce774cfcf8dc9f71164aac78783978aac7b03871702a3b8a481bd9dc9688\", \"price_changes\":[{\"asset_id\":\"96600821790790307414914106093858868634329285205417149685270682748367152458577\", \"price\":\"0.53\", \"size\":\"46.6\", \"side\":\"BUY\", \"hash\":\"79ddd150b48bd277aef5a5fff5200ab5d2ab30ac\", \"best_bid\":\"0.55\", \"best_ask\":\"0.56\"}, {\"asset_id\":\"107603864457683460275633293642179940881969192120168665300712204232021063124301\", \"price\":\"0.47\", \"size\":\"46.6\", \"side\":\"SELL\", \"hash\":\"e23f7c31565d0d788e43246326c729b08c11bd67\", \"best_bid\":\"0.44\", \"best_ask\":\"0.45\"}], \"timestamp\":\"1785211225772\", \"event_type\":\"price_change\"}","received_at":"2026-07-28T04:00:28.745637Z","schema_version":"clob-market-ws.price_change.v1","sequence":null,"server_hash":null,"server_timestamp":"1785211225772","session_id":"2d607381e3054cee91998cdf45a4231c","source":"clob_market_ws"},"received_at":"2026-07-28T04:00:28.745637Z","record_id":"40232464d761361b32f2b55f38aed7b4870a8584c080ef5734e7dce3fd5b7bb4","schema_fingerprint":"4aa3821a28b0b7c2400bc59aba4bcc0a76e971dadd19610d3ad38c768e124dc7","schema_version":"edge-lab-recorder.raw.v1","sequence":null,"source":"clob_market_ws"}
{"event_at":"2026-07-28T04:00:25.773000Z","event_fingerprint":"e921b1665a3a1298d2d19b6800c0dfc6979f5f47437a810033150fb23ee8655b","payload":{"connection_id":"f6725804f86a4c4eb588e4d5ed7db029","event_at":"2026-07-28T04:00:25.773000Z","event_type":"price_change","frame_hash":"8cf7745a12f80666bdd819f2fffc0d28666cb174e3b8f1ec431b933fa42f9862","frame_index":0,"kind":"data","monotonic_ns":313211799960958,"payload":{"event_type":"price_change","market":"0xd412ce774cfcf8dc9f71164aac78783978aac7b03871702a3b8a481bd9dc9688","price_changes":[{"asset_id":"96600821790790307414914106093858868634329285205417149685270682748367152458577","best_ask":"0.56","best_bid":"0.55","hash":"47f74e6089f3fd40de2aefe3d0dbaa2d69044298","price":"0.53","side":"BUY","size":"31.6"},{"asset_id":"107603864457683460275633293642179940881969192120168665300712204232021063124301","best_ask":"0.45","best_bid":"0.44","hash":"51d38ebf34a28c53638100d5374f7f3e41434579","price":"0.47","side":"SELL","size":"31.6"}],"timestamp":"1785211225773"},"payload_hash":"3d56f1dc574545e4130912a7949d86e5813dff1c06472189726905f52ffa3004","raw_frame":"{\"market\":\"0xd412ce774cfcf8dc9f71164aac78783978aac7b03871702a3b8a481bd9dc9688\", \"price_changes\":[{\"asset_id\":\"96600821790790307414914106093858868634329285205417149685270682748367152458577\", \"price\":\"0.53\", \"size\":\"31.6\", \"side\":\"BUY\", \"hash\":\"47f74e6089f3fd40de2aefe3d0dbaa2d69044298\", \"best_bid\":\"0.55\", \"best_ask\":\"0.56\"}, {\"asset_id\":\"107603864457683460275633293642179940881969192120168665300712204232021063124301\", \"price\":\"0.47\", \"size\":\"31.6\", \"side\":\"SELL\", \"hash\":\"51d38ebf34a28c53638100d5374f7f3e41434579\", \"best_bid\":\"0.44\", \"best_ask\":\"0.45\"}], \"timestamp\":\"1785211225773\", \"event_type\":\"price_change\"}","received_at":"2026-07-28T04:00:28.751839Z","schema_version":"clob-market-ws.price_change.v1","sequence":null,"server_hash":null,"server_timestamp":"1785211225773","session_id":"2d607381e3054cee91998cdf45a4231c","source":"clob_market_ws"},"received_at":"2026-07-28T04:00:28.751839Z","record_id":"fc3358dc23c92fbdd3b601d2fba77abe9f8ffbdf2487861ac482d0140153cc0e","schema_fingerprint":"4aa3821a28b0b7c2400bc59aba4bcc0a76e971dadd19610d3ad38c768e124dc7","schema_version":"edge-lab-recorder.raw.v1","sequence":null,"source":"clob_market_ws"}
{"event_at":"2026-07-28T04:00:25.774000Z","event_fingerprint":"d24ac87e3b379715d52345272fbea281984fa6783e548b16e3322fab0073317f","payload":{"connection_id":"f6725804f86a4c4eb588e4d5ed7db029","event_at":"2026-07-28T04:00:25.774000Z","event_type":"price_change","frame_hash":"29567309308e80c3fd4f082cc6ca2b8c901908943192f400aa1cb9c624b29b35","frame_index":0,"kind":"data","monotonic_ns":313211805860916,"payload":{"event_type":"price_change","market":"0xd412ce774cfcf8dc9f71164aac78783978aac7b03871702a3b8a481bd9dc9688","price_changes":[{"asset_id":"107603864457683460275633293642179940881969192120168665300712204232021063124301","best_ask":"0.45","best_bid":"0.44","hash":"84a3b281967cc782fa95d2476b9b72fe7f325a1b","price":"0.25","side":"BUY","size":"199.33"},{"asset_id":"96600821790790307414914106093858868634329285205417149685270682748367152458577","best_ask":"0.56","best_bid":"0.55","hash":"b421d46c02cabf6f5b0ac3df4472f42f0cd3861a","price":"0.75","side":"SELL","size":"199.33"}],"timestamp":"1785211225774"},"payload_hash":"497ede2fc3adc130f8bd746aec8bf96bc9542c220610f424e347b1269e353bc9","raw_frame":"{\"market\":\"0xd412ce774cfcf8dc9f71164aac78783978aac7b03871702a3b8a481bd9dc9688\", \"price_changes\":[{\"asset_id\":\"107603864457683460275633293642179940881969192120168665300712204232021063124301\", \"price\":\"0.25\", \"size\":\"199.33\", \"side\":\"BUY\", \"hash\":\"84a3b281967cc782fa95d2476b9b72fe7f325a1b\", \"best_bid\":\"0.44\", \"best_ask\":\"0.45\"}, {\"asset_id\":\"96600821790790307414914106093858868634329285205417149685270682748367152458577\", \"price\":\"0.75\", \"size\":\"199.33\", \"side\":\"SELL\", \"hash\":\"b421d46c02cabf6f5b0ac3df4472f42f0cd3861a\", \"best_bid\":\"0.55\", \"best_ask\":\"0.56\"}], \"timestamp\":\"1785211225774\", \"event_type\":\"price_change\"}","received_at":"2026-07-28T04:00:28.757739Z","schema_version":"clob-market-ws.price_change.v1","sequence":null,"server_hash":null,"server_timestamp":"1785211225774","session_id":"2d607381e3054cee91998cdf45a4231c","source":"clob_market_ws"},"received_at":"2026-07-28T04:00:28.757739Z","record_id":"ba5c6c2296808fb90ba425bf37748bb2f622a4be677c3f63ed36fc3beaa727f2","schema_fingerprint":"4aa3821a28b0b7c2400bc59aba4bcc0a76e971dadd19610d3ad38c768e124dc7","schema_version":"edge-lab-recorder.raw.v1","sequence":null,"source":"clob_market_ws"}
{"event_at":"2026-07-28T04:00:25.776000Z","event_fingerprint":"463bbda8cc4c84430303076b5f2dd0afe226ef962cd006f44373962f76bafae7","payload":{"connection_id":"f6725804f86a4c4eb588e4d5ed7db029","event_at":"2026-07-28T04:00:25.776000Z","event_type":"price_change","frame_hash":"b82b52600bf2e16592ae7c844ab4293ad86acac035b3fed5e1503efa5d2bcd31","frame_index":0,"kind":"data","monotonic_ns":313211810791041,"payload":{"event_type":"price_change","market":"0xd412ce774cfcf8dc9f71164aac78783978aac7b03871702a3b8a481bd9dc9688","price_changes":[{"asset_id":"107603864457683460275633293642179940881969192120168665300712204232021063124301","best_ask":"0.45","best_bid":"0.44","hash":"130e216e9e528e116ac88a47ce27e2ddbe631405","price":"0.38","side":"BUY","size":"177"},{"asset_id":"96600821790790307414914106093858868634329285205417149685270682748367152458577","best_ask":"0.56","best_bid":"0.55","hash":"319d2087b2b3b091ef366e60ef3233a1b92d5262","price":"0.62","side":"SELL","size":"177"}],"timestamp":"1785211225776"},"payload_hash":"d6adba379404a41d563762c1377b56a2679a4124370f8cd2640282841e353d85","raw_frame":"{\"market\":\"0xd412ce774cfcf8dc9f71164aac78783978aac7b03871702a3b8a481bd9dc9688\", \"price_changes\":[{\"asset_id\":\"107603864457683460275633293642179940881969192120168665300712204232021063124301\", \"price\":\"0.38\", \"size\":\"177\", \"side\":\"BUY\", \"hash\":\"130e216e9e528e116ac88a47ce27e2ddbe631405\", \"best_bid\":\"0.44\", \"best_ask\":\"0.45\"}, {\"asset_id\":\"96600821790790307414914106093858868634329285205417149685270682748367152458577\", \"price\":\"0.62\", \"size\":\"177\", \"side\":\"SELL\", \"hash\":\"319d2087b2b3b091ef366e60ef3233a1b92d5262\", \"best_bid\":\"0.55\", \"best_ask\":\"0.56\"}], \"timestamp\":\"1785211225776\", \"event_type\":\"price_change\"}","received_at":"2026-07-28T04:00:28.762669Z","schema_version":"clob-market-ws.price_change.v1","sequence":null,"server_hash":null,"server_timestamp":"1785211225776","session_id":"2d607381e3054cee91998cdf45a4231c","source":"clob_market_ws"},"received_at":"2026-07-28T04:00:28.762669Z","record_id":"65ad23e00595469c5655446be33b3b95ed178878c95cbe452b572159d78b8056","schema_fingerprint":"4aa3821a28b0b7c2400bc59aba4bcc0a76e971dadd19610d3ad38c768e124dc7","schema_version":"edge-lab-recorder.raw.v1","sequence":null,"source":"clob_market_ws"}
{"event_at":"2026-07-28T04:00:25.778000Z","event_fingerprint":"243367eff71d1cc238729ae8c090c20ab45a108628975be9f75d10514724fae2","payload":{"connection_id":"f6725804f86a4c4eb588e4d5ed7db029","event_at":"2026-07-28T04:00:25.778000Z","event_type":"price_change","frame_hash":"954e2c8e5343150a1348ee8e04ac947838831d628fb42d8395a2c817e668d469","frame_index":0,"kind":"data","monotonic_ns":313211823533083,"payload":{"event_type":"price_change","market":"0xd412ce774cfcf8dc9f71164aac78783978aac7b03871702a3b8a481bd9dc9688","price_changes":[{"asset_id":"107603864457683460275633293642179940881969192120168665300712204232021063124301","best_ask":"0.45","best_bid":"0.44","hash":"a1a96cc9f3457535eec022fe83bcabaaf2305f8b","price":"0.38","side":"BUY","size":"207"},{"asset_id":"96600821790790307414914106093858868634329285205417149685270682748367152458577","best_ask":"0.56","best_bid":"0.55","hash":"63399e248256afd0e68b065214b215b87036ad72","price":"0.62","side":"SELL","size":"207"}],"timestamp":"1785211225778"},"payload_hash":"a7bf72b0d79a6b4fca553601dffb35e824808b53cf5364191505da1f39380661","raw_frame":"{\"market\":\"0xd412ce774cfcf8dc9f71164aac78783978aac7b03871702a3b8a481bd9dc9688\", \"price_changes\":[{\"asset_id\":\"107603864457683460275633293642179940881969192120168665300712204232021063124301\", \"price\":\"0.38\", \"size\":\"207\", \"side\":\"BUY\", \"hash\":\"a1a96cc9f3457535eec022fe83bcabaaf2305f8b\", \"best_bid\":\"0.44\", \"best_ask\":\"0.45\"}, {\"asset_id\":\"96600821790790307414914106093858868634329285205417149685270682748367152458577\", \"price\":\"0.62\", \"size\":\"207\", \"side\":\"SELL\", \"hash\":\"63399e248256afd0e68b065214b215b87036ad72\", \"best_bid\":\"0.55\", \"best_ask\":\"0.56\"}], \"timestamp\":\"1785211225778\", \"event_type\":\"price_change\"}","received_at":"2026-07-28T04:00:28.775410Z","schema_version":"clob-market-ws.price_change.v1","sequence":null,"server_hash":null,"server_timestamp":"1785211225778","session_id":"2d607381e3054cee91998cdf45a4231c","source":"clob_market_ws"},"received_at":"2026-07-28T04:00:28.775410Z","record_id":"f451872eb24d06634fe10b8465d9e04b5846ef773d07d01dce787a77bc0fbc45","schema_fingerprint":"4aa3821a28b0b7c2400bc59aba4bcc0a76e971dadd19610d3ad38c768e124dc7","schema_version":"edge-lab-recorder.raw.v1","sequence":null,"source":"clob_market_ws"}
{"event_at":"2026-07-28T04:00:25.781000Z","event_fingerprint":"a6f8539324da1258bcb48312b116ef530cbebd9fed0ef5edd99241d396d786af","payload":{"connection_id":"f6725804f86a4c4eb588e4d5ed7db029","event_at":"2026-07-28T04:00:25.781000Z","event_type":"price_change","frame_hash":"b457286ac23d1bf98bf8cadc976aa7321189696d47ff520a7b662a28161e218f","frame_index":0,"kind":"data","monotonic_ns":313211833817583,"payload":{"event_type":"price_change","market":"0xd412ce774cfcf8dc9f71164aac78783978aac7b03871702a3b8a481bd9dc9688","price_changes":[{"asset_id":"96600821790790307414914106093858868634329285205417149685270682748367152458577","best_ask":"0.56","best_bid":"0.55","hash":"9d8afba7b1b3abfcb8216db1ca46c0c92ca9012e","price":"0.47","side":"BUY","size":"26"},{"asset_id":"107603864457683460275633293642179940881969192120168665300712204232021063124301","best_ask":"0.45","best_bid":"0.44","hash":"470d2400e27751abe2a1b7d88ef92e2556298850","price":"0.53","side":"SELL","size":"26"}],"timestamp":"1785211225781"},"payload_hash":"335ee3a44ba6b6daca95fd8c6fe809cad0dbbdd9571d6cb2db819d11c1cddd21","raw_frame":"{\"market\":\"0xd412ce774cfcf8dc9f71164aac78783978aac7b03871702a3b8a481bd9dc9688\", \"price_changes\":[{\"asset_id\":\"96600821790790307414914106093858868634329285205417149685270682748367152458577\", \"price\":\"0.47\", \"size\":\"26\", \"side\":\"BUY\", \"hash\":\"9d8afba7b1b3abfcb8216db1ca46c0c92ca9012e\", \"best_bid\":\"0.55\", \"best_ask\":\"0.56\"}, {\"asset_id\":\"107603864457683460275633293642179940881969192120168665300712204232021063124301\", \"price\":\"0.53\", \"size\":\"26\", \"side\":\"SELL\", \"hash\":\"470d2400e27751abe2a1b7d88ef92e2556298850\", \"best_bid\":\"0.44\", \"best_ask\":\"0.45\"}], \"timestamp\":\"1785211225781\", \"event_type\":\"price_change\"}","received_at":"2026-07-28T04:00:28.785696Z","schema_version":"clob-market-ws.price_change.v1","sequence":null,"server_hash":null,"server_timestamp":"1785211225781","session_id":"2d607381e3054cee91998cdf45a4231c","source":"clob_market_ws"},"received_at":"2026-07-28T04:00:28.785696Z","record_id":"b947925f0e2784534e7417b3e41bd489672a609707a74cdc055f1e0aba4790a2","schema_fingerprint":"4aa3821a28b0b7c2400bc59aba4bcc0a76e971dadd19610d3ad38c768e124dc7","schema_version":"edge-lab-recorder.raw.v1","sequence":null,"source":"clob_market_ws"}
{"event_at":"2026-07-28T04:00:25.786000Z","event_fingerprint":"dd9e2eecd41d38690ce7b5bea52f3ebaceb67bbb15f1f22c9c4f6ca1f4d40091","payload":{"connection_id":"f6725804f86a4c4eb588e4d5ed7db029","event_at":"2026-07-28T04:00:25.786000Z","event_type":"price_change","frame_hash":"4eae6329e86aac08e52ce425d29e65d91881bedcc692f287ace2f9203a5cfdfc","frame_index":0,"kind":"data","monotonic_ns":313211844144125,"payload":{"event_type":"price_change","market":"0xd412ce774cfcf8dc9f71164aac78783978aac7b03871702a3b8a481bd9dc9688","price_changes":[{"asset_id":"96600821790790307414914106093858868634329285205417149685270682748367152458577","best_ask":"0.56","best_bid":"0.55","hash":"37d3775c0406162cc463eb28c1f83abfd4268507","price":"0.55","side":"BUY","size":"23.28"},{"asset_id":"107603864457683460275633293642179940881969192120168665300712204232021063124301","best_ask":"0.45","best_bid":"0.44","hash":"9ddb5199e701748c2cb5c18f25d3443629701b88","price":"0.45","side":"SELL","size":"23.28"}],"timestamp":"1785211225786"},"payload_hash":"d3e01788a7c2aa4e3693af5bb1f20e6cd4fd9c7eb6251a746d4ed4f1a11f4b65","raw_frame":"{\"market\":\"0xd412ce774cfcf8dc9f71164aac78783978aac7b03871702a3b8a481bd9dc9688\", \"price_changes\":[{\"asset_id\":\"96600821790790307414914106093858868634329285205417149685270682748367152458577\", \"price\":\"0.55\", \"size\":\"23.28\", \"side\":\"BUY\", \"hash\":\"37d3775c0406162cc463eb28c1f83abfd4268507\", \"best_bid\":\"0.55\", \"best_ask\":\"0.56\"}, {\"asset_id\":\"107603864457683460275633293642179940881969192120168665300712204232021063124301\", \"price\":\"0.45\", \"size\":\"23.28\", \"side\":\"SELL\", \"hash\":\"9ddb5199e701748c2cb5c18f25d3443629701b88\", \"best_bid\":\"0.44\", \"best_ask\":\"0.45\"}], \"timestamp\":\"1785211225786\", \"event_type\":\"price_change\"}","received_at":"2026-07-28T04:00:28.796022Z","schema_version":"clob-market-ws.price_change.v1","sequence":null,"server_hash":null,"server_timestamp":"1785211225786","session_id":"2d607381e3054cee91998cdf45a4231c","source":"clob_market_ws"},"received_at":"2026-07-28T04:00:28.796022Z","record_id":"1666dea77dc15a3353d1af46be1f2a95b8d5d2eed12fa470eeea80e98c36c0ce","schema_fingerprint":"4aa3821a28b0b7c2400bc59aba4bcc0a76e971dadd19610d3ad38c768e124dc7","schema_version":"edge-lab-recorder.raw.v1","sequence":null,"source":"clob_market_ws"}
{"event_at":"2026-07-28T04:00:25.786000Z","event_fingerprint":"f710e581f8b774c548c2cbc128ef416f3e350fe6aad1342e435f0a9b1a7db296","payload":{"connection_id":"f6725804f86a4c4eb588e4d5ed7db029","event_at":"2026-07-28T04:00:25.786000Z","event_type":"price_change","frame_hash":"04bd102ceff29b285855ee0b4ef120951a596509d8ea1d7355869747f7247715","frame_index":0,"kind":"data","monotonic_ns":313211849676666,"payload":{"event_type":"price_change","market":"0xd412ce774cfcf8dc9f71164aac78783978aac7b03871702a3b8a481bd9dc9688","price_changes":[{"asset_id":"96600821790790307414914106093858868634329285205417149685270682748367152458577","best_ask":"0.56","best_bid":"0.55","hash":"ef8a82cd1e01a857e26099bbe6666fa13c0d4e01","price":"0.54","side":"BUY","size":"23.28"},{"asset_id":"107603864457683460275633293642179940881969192120168665300712204232021063124301","best_ask":"0.45","best_bid":"0.44","hash":"bedd7dfc4f59b67cd8a97296d368fbaa88b19bfd","price":"0.46","side":"SELL","size":"23.28"}],"timestamp":"1785211225786"},"payload_hash":"0bfa0a2b8251e95492839ec101164a0757d4676294469696c8887a63606fee28","raw_frame":"{\"market\":\"0xd412ce774cfcf8dc9f71164aac78783978aac7b03871702a3b8a481bd9dc9688\", \"price_changes\":[{\"asset_id\":\"96600821790790307414914106093858868634329285205417149685270682748367152458577\", \"price\":\"0.54\", \"size\":\"23.28\", \"side\":\"BUY\", \"hash\":\"ef8a82cd1e01a857e26099bbe6666fa13c0d4e01\", \"best_bid\":\"0.55\", \"best_ask\":\"0.56\"}, {\"asset_id\":\"107603864457683460275633293642179940881969192120168665300712204232021063124301\", \"price\":\"0.46\", \"size\":\"23.28\", \"side\":\"SELL\", \"hash\":\"bedd7dfc4f59b67cd8a97296d368fbaa88b19bfd\", \"best_bid\":\"0.44\", \"best_ask\":\"0.45\"}], \"timestamp\":\"1785211225786\", \"event_type\":\"price_change\"}","received_at":"2026-07-28T04:00:28.801555Z","schema_version":"clob-market-ws.price_change.v1","sequence":null,"server_hash":null,"server_timestamp":"1785211225786","session_id":"2d607381e3054cee91998cdf45a4231c","source":"clob_market_ws"},"received_at":"2026-07-28T04:00:28.801555Z","record_id":"2a6d9b4db4efa52464fa5b026b1b387c70b531edfba9d2b2ab72915154392494","schema_fingerprint":"4aa3821a28b0b7c2400bc59aba4bcc0a76e971dadd19610d3ad38c768e124dc7","schema_version":"edge-lab-recorder.raw.v1","sequence":null,"source":"clob_market_ws"}
{"event_at":"2026-07-28T04:00:25.787000Z","event_fingerprint":"00b50d8c3fb77617fbdeefc3c123907791d5d4805c143b3bac0b1daa25f070ab","payload":{"connection_id":"f6725804f86a4c4eb588e4d5ed7db029","event_at":"2026-07-28T04:00:25.787000Z","event_type":"price_change","frame_hash":"705eff655ab703c89f3253d61e5e567e11c8e5f9d2090f0ba0bf9b5132d1b321","frame_index":0,"kind":"data","monotonic_ns":313211857425125,"payload":{"event_type":"price_change","market":"0xd412ce774cfcf8dc9f71164aac78783978aac7b03871702a3b8a481bd9dc9688","price_changes":[{"asset_id":"96600821790790307414914106093858868634329285205417149685270682748367152458577","best_ask":"0.56","best_bid":"0.55","hash":"455acaa2519dd76bf5879483ddabb7c173b79fc7","price":"0.55","side":"BUY","size":"17.28"},{"asset_id":"107603864457683460275633293642179940881969192120168665300712204232021063124301","best_ask":"0.45","best_bid":"0.44","hash":"c3d31c2e458947de7990780a795043dff11dcafa","price":"0.45","side":"SELL","size":"17.28"}],"timestamp":"1785211225787"},"payload_hash":"031d5fc387d231643a662972b6041a633ff56d4b76dc1505c26f236decf4ef13","raw_frame":"{\"market\":\"0xd412ce774cfcf8dc9f71164aac78783978aac7b03871702a3b8a481bd9dc9688\", \"price_changes\":[{\"asset_id\":\"96600821790790307414914106093858868634329285205417149685270682748367152458577\", \"price\":\"0.55\", \"size\":\"17.28\", \"side\":\"BUY\", \"hash\":\"455acaa2519dd76bf5879483ddabb7c173b79fc7\", \"best_bid\":\"0.55\", \"best_ask\":\"0.56\"}, {\"asset_id\":\"107603864457683460275633293642179940881969192120168665300712204232021063124301\", \"price\":\"0.45\", \"size\":\"17.28\", \"side\":\"SELL\", \"hash\":\"c3d31c2e458947de7990780a795043dff11dcafa\", \"best_bid\":\"0.44\", \"best_ask\":\"0.45\"}], \"timestamp\":\"1785211225787\", \"event_type\":\"price_change\"}","received_at":"2026-07-28T04:00:28.809302Z","schema_version":"clob-market-ws.price_change.v1","sequence":null,"server_hash":null,"server_timestamp":"1785211225787","session_id":"2d607381e3054cee91998cdf45a4231c","source":"clob_market_ws"},"received_at":"2026-07-28T04:00:28.809302Z","record_id":"857b30fce95436fdcbc2a0fe416a044de5dcd708819c4d32e461235b8bf2f659","schema_fingerprint":"4aa3821a28b0b7c2400bc59aba4bcc0a76e971dadd19610d3ad38c768e124dc7","schema_version":"edge-lab-recorder.raw.v1","sequence":null,"source":"clob_market_ws"}
{"event_at":"2026-07-28T04:00:25.788000Z","event_fingerprint":"6cb0ffbcaba1dc24633b6ce193aef18af16d5380e6edded24c63787bee8d84b3","payload":{"connection_id":"f6725804f86a4c4eb588e4d5ed7db029","event_at":"2026-07-28T04:00:25.788000Z","event_type":"price_change","frame_hash":"7351371dc1d63005cc65dde0a0c0581bbd130d0bc1186ce1598c8d40eb920b20","frame_index":0,"kind":"data","monotonic_ns":313211866424791,"payload":{"event_type":"price_change","market":"0xd412ce774cfcf8dc9f71164aac78783978aac7b03871702a3b8a481bd9dc9688","price_changes":[{"asset_id":"96600821790790307414914106093858868634329285205417149685270682748367152458577","best_ask":"0.56","best_bid":"0.55","hash":"c531d24aec0c2090d999e5c4579c6551a1136ff5","price":"0.54","side":"BUY","size":"17.28"},{"asset_id":"107603864457683460275633293642179940881969192120168665300712204232021063124301","best_ask":"0.45","best_bid":"0.44","hash":"6c00893c037627b22cf5847323e3b41091113b3d","price":"0.46","side":"SELL","size":"17.28"}],"timestamp":"1785211225788"},"payload_hash":"0c835af0564641d915f500ae98666d80832b8b3893c106ebcec80928113e6672","raw_frame":"{\"market\":\"0xd412ce774cfcf8dc9f71164aac78783978aac7b03871702a3b8a481bd9dc9688\", \"price_changes\":[{\"asset_id\":\"96600821790790307414914106093858868634329285205417149685270682748367152458577\", \"price\":\"0.54\", \"size\":\"17.28\", \"side\":\"BUY\", \"hash\":\"c531d24aec0c2090d999e5c4579c6551a1136ff5\", \"best_bid\":\"0.55\", \"best_ask\":\"0.56\"}, {\"asset_id\":\"107603864457683460275633293642179940881969192120168665300712204232021063124301\", \"price\":\"0.46\", \"size\":\"17.28\", \"side\":\"SELL\", \"hash\":\"6c00893c037627b22cf5847323e3b41091113b3d\", \"best_bid\":\"0.44\", \"best_ask\":\"0.45\"}], \"timestamp\":\"1785211225788\", \"event_type\":\"price_change\"}","received_at":"2026-07-28T04:00:28.818302Z","schema_version":"clob-market-ws.price_change.v1","sequence":null,"server_hash":null,"server_timestamp":"1785211225788","session_id":"2d607381e3054cee91998cdf45a4231c","source":"clob_market_ws"},"received_at":"2026-07-28T04:00:28.818302Z","record_id":"705926a7c195dcc1c3ddb6cf64e14933725db62f7c6981cfd55e4630b5b0b6e7","schema_fingerprint":"4aa3821a28b0b7c2400bc59aba4bcc0a76e971dadd19610d3ad38c768e124dc7","schema_version":"edge-lab-recorder.raw.v1","sequence":null,"source":"clob_market_ws"}
{"event_at":"2026-07-28T04:00:25.788000Z","event_fingerprint":"1c03ce8a16f9f3604419abb978452bbdbc72771c3ff193784cc562d59a3ce53c","payload":{"connection_id":"f6725804f86a4c4eb588e4d5ed7db029","event_at":"2026-07-28T04:00:25.788000Z","event_type":"price_change","frame_hash":"16b55acf7c4383482de7abb322dcd357a2aaec4129b705b765b12bfc90383547","frame_index":0,"kind":"data","monotonic_ns":313211871348583,"payload":{"event_type":"price_change","market":"0xd412ce774cfcf8dc9f71164aac78783978aac7b03871702a3b8a481bd9dc9688","price_changes":[{"asset_id":"96600821790790307414914106093858868634329285205417149685270682748367152458577","best_ask":"0.56","best_bid":"0.55","hash":"0271306adca37db0fdafa452a6a797e92776cf95","price":"0.55","side":"BUY","size":"22.28"},{"asset_id":"107603864457683460275633293642179940881969192120168665300712204232021063124301","best_ask":"0.45","best_bid":"0.44","hash":"d03cec9a49be4efbee28740f556ef4e30179cc49","price":"0.45","side":"SELL","size":"22.28"}],"timestamp":"1785211225788"},"payload_hash":"6f7287f26eb07c3feb1c853c41ccd3fbc191f4c447782625efd08b8be28c6650","raw_frame":"{\"market\":\"0xd412ce774cfcf8dc9f71164aac78783978aac7b03871702a3b8a481bd9dc9688\", \"price_changes\":[{\"asset_id\":\"96600821790790307414914106093858868634329285205417149685270682748367152458577\", \"price\":\"0.55\", \"size\":\"22.28\", \"side\":\"BUY\", \"hash\":\"0271306adca37db0fdafa452a6a797e92776cf95\", \"best_bid\":\"0.55\", \"best_ask\":\"0.56\"}, {\"asset_id\":\"107603864457683460275633293642179940881969192120168665300712204232021063124301\", \"price\":\"0.45\", \"size\":\"22.28\", \"side\":\"SELL\", \"hash\":\"d03cec9a49be4efbee28740f556ef4e30179cc49\", \"best_bid\":\"0.44\", \"best_ask\":\"0.45\"}], \"timestamp\":\"1785211225788\", \"event_type\":\"price_change\"}","received_at":"2026-07-28T04:00:28.823226Z","schema_version":"clob-market-ws.price_change.v1","sequence":null,"server_hash":null,"server_timestamp":"1785211225788","session_id":"2d607381e3054cee91998cdf45a4231c","source":"clob_market_ws"},"received_at":"2026-07-28T04:00:28.823226Z","record_id":"b2368ea19e71da7748b7b9a27a7938a901c5f15188cd4bdb2e31f3bac5856972","schema_fingerprint":"4aa3821a28b0b7c2400bc59aba4bcc0a76e971dadd19610d3ad38c768e124dc7","schema_version":"edge-lab-recorder.raw.v1","sequence":null,"source":"clob_market_ws"}
{"event_at":"2026-07-28T04:00:25.791000Z","event_fingerprint":"7ed33ed3578ab65bc6e8fdf438de5ce682891a7087dc00fdd61d456d0410ea35","payload":{"connection_id":"f6725804f86a4c4eb588e4d5ed7db029","event_at":"2026-07-28T04:00:25.791000Z","event_type":"price_change","frame_hash":"5da97e734283c63d504c6317abf80078874ff1101c2936b7535ced68f40b743a","frame_index":0,"kind":"data","monotonic_ns":313211875096666,"payload":{"event_type":"price_change","market":"0xd412ce774cfcf8dc9f71164aac78783978aac7b03871702a3b8a481bd9dc9688","price_changes":[{"asset_id":"96600821790790307414914106093858868634329285205417149685270682748367152458577","best_ask":"0.56","best_bid":"0.55","hash":"b2121d73d2d47f90c14689a24a7b0687f8f8aaea","price":"0.53","side":"BUY","size":"19"},{"asset_id":"107603864457683460275633293642179940881969192120168665300712204232021063124301","best_ask":"0.45","best_bid":"0.44","hash":"f4a3710d71537b5c361cba675ebf7ad63046d3f1","price":"0.47","side":"SELL","size":"19"}],"timestamp":"1785211225791"},"payload_hash":"1dfe9437cf07b5d9b336412e5d6049d481bf1638420d6f9587da016ec6f622a3","raw_frame":"{\"market\":\"0xd412ce774cfcf8dc9f71164aac78783978aac7b03871702a3b8a481bd9dc9688\", \"price_changes\":[{\"asset_id\":\"96600821790790307414914106093858868634329285205417149685270682748367152458577\", \"price\":\"0.53\", \"size\":\"19\", \"side\":\"BUY\", \"hash\":\"b2121d73d2d47f90c14689a24a7b0687f8f8aaea\", \"best_bid\":\"0.55\", \"best_ask\":\"0.56\"}, {\"asset_id\":\"107603864457683460275633293642179940881969192120168665300712204232021063124301\", \"price\":\"0.47\", \"size\":\"19\", \"side\":\"SELL\", \"hash\":\"f4a3710d71537b5c361cba675ebf7ad63046d3f1\", \"best_bid\":\"0.44\", \"best_ask\":\"0.45\"}], \"timestamp\":\"1785211225791\", \"event_type\":\"price_change\"}","received_at":"2026-07-28T04:00:28.826974Z","schema_version":"clob-market-ws.price_change.v1","sequence":null,"server_hash":null,"server_timestamp":"1785211225791","session_id":"2d607381e3054cee91998cdf45a4231c","source":"clob_market_ws"},"received_at":"2026-07-28T04:00:28.826974Z","record_id":"91abfb81f657ca9413295f04ed44fbfc3be6c4f4c4575edd2e9d7e55dfcb8f65","schema_fingerprint":"4aa3821a28b0b7c2400bc59aba4bcc0a76e971dadd19610d3ad38c768e124dc7","schema_version":"edge-lab-recorder.raw.v1","sequence":null,"source":"clob_market_ws"}
{"event_at":"2026-07-28T04:00:25.791000Z","event_fingerprint":"80bef496e91d52194aea4eff0c01c3b65ecaee2a0efc662912c7d2868024acf3","payload":{"connection_id":"f6725804f86a4c4eb588e4d5ed7db029","event_at":"2026-07-28T04:00:25.791000Z","event_type":"price_change","frame_hash":"93374c89b785123033119d26406dfbcfa8db6a8e12ceadff0efb79372b6e8389","frame_index":0,"kind":"data","monotonic_ns":313211885919708,"payload":{"event_type":"price_change","market":"0xd412ce774cfcf8dc9f71164aac78783978aac7b03871702a3b8a481bd9dc9688","price_changes":[{"asset_id":"96600821790790307414914106093858868634329285205417149685270682748367152458577","best_ask":"0.56","best_bid":"0.55","hash":"8cd3cda1808a141952815ea2f7274c4dfac7ea0a","price":"0.36","side":"BUY","size":"42.5"},{"asset_id":"107603864457683460275633293642179940881969192120168665300712204232021063124301","best_ask":"0.45","best_bid":"0.44","hash":"390102f4b9f19a66f9f446eb367082af222af821","price":"0.64","side":"SELL","size":"42.5"}],"timestamp":"1785211225791"},"payload_hash":"563fc4ed31381b11170bdf17fd48ffd28cb64ca69b66ed0e73c7caad85606778","raw_frame":"{\"market\":\"0xd412ce774cfcf8dc9f71164aac78783978aac7b03871702a3b8a481bd9dc9688\", \"price_changes\":[{\"asset_id\":\"96600821790790307414914106093858868634329285205417149685270682748367152458577\", \"price\":\"0.36\", \"size\":\"42.5\", \"side\":\"BUY\", \"hash\":\"8cd3cda1808a141952815ea2f7274c4dfac7ea0a\", \"best_bid\":\"0.55\", \"best_ask\":\"0.56\"}, {\"asset_id\":\"107603864457683460275633293642179940881969192120168665300712204232021063124301\", \"price\":\"0.64\", \"size\":\"42.5\", \"side\":\"SELL\", \"hash\":\"390102f4b9f19a66f9f446eb367082af222af821\", \"best_bid\":\"0.44\", \"best_ask\":\"0.45\"}], \"timestamp\":\"1785211225791\", \"event_type\":\"price_change\"}","received_at":"2026-07-28T04:00:28.837797Z","schema_version":"clob-market-ws.price_change.v1","sequence":null,"server_hash":null,"server_timestamp":"1785211225791","session_id":"2d607381e3054cee91998cdf45a4231c","source":"clob_market_ws"},"received_at":"2026-07-28T04:00:28.837797Z","record_id":"a9957eb82a53122f611d6b8b7d288ef46abcc04e5d05859c9962642bfa4977cf","schema_fingerprint":"4aa3821a28b0b7c2400bc59aba4bcc0a76e971dadd19610d3ad38c768e124dc7","schema_version":"edge-lab-recorder.raw.v1","sequence":null,"source":"clob_market_ws"}
{"event_at":"2026-07-28T04:00:25.792000Z","event_fingerprint":"205457a877c2743fca6be2fdc5c5c3016663d0c1666546e091fc2579fc151e1c","payload":{"connection_id":"f6725804f86a4c4eb588e4d5ed7db029","event_at":"2026-07-28T04:00:25.792000Z","event_type":"price_change","frame_hash":"1392ecbab9bf0318d798eef14c85d69751013b90990f7e5f0c72f065e158bdc0","frame_index":0,"kind":"data","monotonic_ns":313211892782083,"payload":{"event_type":"price_change","market":"0xd412ce774cfcf8dc9f71164aac78783978aac7b03871702a3b8a481bd9dc9688","price_changes":[{"asset_id":"107603864457683460275633293642179940881969192120168665300712204232021063124301","best_ask":"0.45","best_bid":"0.44","hash":"9c0be40d97fcb43ecd1d512b798dd604d9f3f755","price":"0.38","side":"BUY","size":"177"},{"asset_id":"96600821790790307414914106093858868634329285205417149685270682748367152458577","best_ask":"0.56","best_bid":"0.55","hash":"23b9c00697609db2079c6eae13f7e77f37772f78","price":"0.62","side":"SELL","size":"177"}],"timestamp":"1785211225792"},"payload_hash":"07557d187018826fbfc6e4d3b3755eccf640a06c805265349c52194726e22780","raw_frame":"{\"market\":\"0xd412ce774cfcf8dc9f71164aac78783978aac7b03871702a3b8a481bd9dc9688\", \"price_changes\":[{\"asset_id\":\"107603864457683460275633293642179940881969192120168665300712204232021063124301\", \"price\":\"0.38\", \"size\":\"177\", \"side\":\"BUY\", \"hash\":\"9c0be40d97fcb43ecd1d512b798dd604d9f3f755\", \"best_bid\":\"0.44\", \"best_ask\":\"0.45\"}, {\"asset_id\":\"96600821790790307414914106093858868634329285205417149685270682748367152458577\", \"price\":\"0.62\", \"size\":\"177\", \"side\":\"SELL\", \"hash\":\"23b9c00697609db2079c6eae13f7e77f37772f78\", \"best_bid\":\"0.55\", \"best_ask\":\"0.56\"}], \"timestamp\":\"1785211225792\", \"event_type\":\"price_change\"}","received_at":"2026-07-28T04:00:28.844659Z","schema_version":"clob-market-ws.price_change.v1","sequence":null,"server_hash":null,"server_timestamp":"1785211225792","session_id":"2d607381e3054cee91998cdf45a4231c","source":"clob_market_ws"},"received_at":"2026-07-28T04:00:28.844659Z","record_id":"aef6f8591b0950165a0a0cb2d872fba7473da4bd08b8af8a66ac8f614640cc70","schema_fingerprint":"4aa3821a28b0b7c2400bc59aba4bcc0a76e971dadd19610d3ad38c768e124dc7","schema_version":"edge-lab-recorder.raw.v1","sequence":null,"source":"clob_market_ws"}
{"event_at":"2026-07-28T04:00:25.793000Z","event_fingerprint":"dec74dd0019ced9778218578233eb5ba5660778070cb4463b46d4d02eb2257b2","payload":{"connection_id":"f6725804f86a4c4eb588e4d5ed7db029","event_at":"2026-07-28T04:00:25.793000Z","event_type":"price_change","frame_hash":"957e1b04c6f549b04d140c16509fe2a11274cdc0b9ac16122b4e35fbecc0dfbe","frame_index":0,"kind":"data","monotonic_ns":313211900604875,"payload":{"event_type":"price_change","market":"0xd412ce774cfcf8dc9f71164aac78783978aac7b03871702a3b8a481bd9dc9688","price_changes":[{"asset_id":"96600821790790307414914106093858868634329285205417149685270682748367152458577","best_ask":"0.56","best_bid":"0.55","hash":"97811a381ed529e720f434aff0df745d456c57fb","price":"0.56","side":"SELL","size":"55.2"},{"asset_id":"107603864457683460275633293642179940881969192120168665300712204232021063124301","best_ask":"0.45","best_bid":"0.44","hash":"9e4fb9a98cc8f1f7dda6037886e4248f585840d7","price":"0.44","side":"BUY","size":"55.2"}],"timestamp":"1785211225793"},"payload_hash":"d092c6b7cf63325757272c0e9c7e0188594edb59c99e298a53c99e18c4596221","raw_frame":"{\"market\":\"0xd412ce774cfcf8dc9f71164aac78783978aac7b03871702a3b8a481bd9dc9688\", \"price_changes\":[{\"asset_id\":\"96600821790790307414914106093858868634329285205417149685270682748367152458577\", \"price\":\"0.56\", \"size\":\"55.2\", \"side\":\"SELL\", \"hash\":\"97811a381ed529e720f434aff0df745d456c57fb\", \"best_bid\":\"0.55\", \"best_ask\":\"0.56\"}, {\"asset_id\":\"107603864457683460275633293642179940881969192120168665300712204232021063124301\", \"price\":\"0.44\", \"size\":\"55.2\", \"side\":\"BUY\", \"hash\":\"9e4fb9a98cc8f1f7dda6037886e4248f585840d7\", \"best_bid\":\"0.44\", \"best_ask\":\"0.45\"}], \"timestamp\":\"1785211225793\", \"event_type\":\"price_change\"}","received_at":"2026-07-28T04:00:28.852482Z","schema_version":"clob-market-ws.price_change.v1","sequence":null,"server_hash":null,"server_timestamp":"1785211225793","session_id":"2d607381e3054cee91998cdf45a4231c","source":"clob_market_ws"},"received_at":"2026-07-28T04:00:28.852482Z","record_id":"819fcd55df057a9fbfd81894d52a3dec6fb8431ee592559c136d700f9bd496a3","schema_fingerprint":"4aa3821a28b0b7c2400bc59aba4bcc0a76e971dadd19610d3ad38c768e124dc7","schema_version":"edge-lab-recorder.raw.v1","sequence":null,"source":"clob_market_ws"}
{"event_at":"2026-07-28T04:00:25.794000Z","event_fingerprint":"94fa718979604e72e621634896f8e43e6b27611f9a26448ef6cd710726e6d85c","payload":{"connection_id":"f6725804f86a4c4eb588e4d5ed7db029","event_at":"2026-07-28T04:00:25.794000Z","event_type":"price_change","frame_hash":"730cc254a6943ab092290609c759a9e3a727ca87f5b4fbd88b99e06d381eda46","frame_index":0,"kind":"data","monotonic_ns":313211906700333,"payload":{"event_type":"price_change","market":"0xd412ce774cfcf8dc9f71164aac78783978aac7b03871702a3b8a481bd9dc9688","price_changes":[{"asset_id":"96600821790790307414914106093858868634329285205417149685270682748367152458577","best_ask":"0.56","best_bid":"0.55","hash":"17e64d05aedc26f02ea9e1c1d192466ae07c1ec3","price":"0.55","side":"BUY","size":"46.28"},{"asset_id":"107603864457683460275633293642179940881969192120168665300712204232021063124301","best_ask":"0.45","best_bid":"0.44","hash":"a1836faff193287b255d11bdc05e4c6606de5691","price":"0.45","side":"SELL","size":"46.28"}],"timestamp":"1785211225794"},"payload_hash":"9f874d3251d0facec0c6801a05259d75108c357bab1771246545ae482408ade8","raw_frame":"{\"market\":\"0xd412ce774cfcf8dc9f71164aac78783978aac7b03871702a3b8a481bd9dc9688\", \"price_changes\":[{\"asset_id\":\"96600821790790307414914106093858868634329285205417149685270682748367152458577\", \"price\":\"0.55\", \"size\":\"46.28\", \"side\":\"BUY\", \"hash\":\"17e64d05aedc26f02ea9e1c1d192466ae07c1ec3\", \"best_bid\":\"0.55\", \"best_ask\":\"0.56\"}, {\"asset_id\":\"107603864457683460275633293642179940881969192120168665300712204232021063124301\", \"price\":\"0.45\", \"size\":\"46.28\", \"side\":\"SELL\", \"hash\":\"a1836faff193287b255d11bdc05e4c6606de5691\", \"best_bid\":\"0.44\", \"best_ask\":\"0.45\"}], \"timestamp\":\"1785211225794\", \"event_type\":\"price_change\"}","received_at":"2026-07-28T04:00:28.858578Z","schema_version":"clob-market-ws.price_change.v1","sequence":null,"server_hash":null,"server_timestamp":"1785211225794","session_id":"2d607381e3054cee91998cdf45a4231c","source":"clob_market_ws"},"received_at":"2026-07-28T04:00:28.858578Z","record_id":"0899e20aea60b29dc59019e1778b6e1a01db8c3be246abd4a5bf7955094eb6c3","schema_fingerprint":"4aa3821a28b0b7c2400bc59aba4bcc0a76e971dadd19610d3ad38c768e124dc7","schema_version":"edge-lab-recorder.raw.v1","sequence":null,"source":"clob_market_ws"}
{"event_at":"2026-07-28T04:00:25.795000Z","event_fingerprint":"34b5b1f890e037fe2d3d0711fc0cde21d727e40071d958388739d6f35a4a9627","payload":{"connection_id":"f6725804f86a4c4eb588e4d5ed7db029","event_at":"2026-07-28T04:00:25.795000Z","event_type":"price_change","frame_hash":"ce2dad7d9ceb78d14f16b943d1eff54efa85f25354c97a290e75096995de3efb","frame_index":0,"kind":"data","monotonic_ns":313211913817125,"payload":{"event_type":"price_change","market":"0xd412ce774cfcf8dc9f71164aac78783978aac7b03871702a3b8a481bd9dc9688","price_changes":[{"asset_id":"107603864457683460275633293642179940881969192120168665300712204232021063124301","best_ask":"0.45","best_bid":"0.44","hash":"221d1c4c7e53d20414b8ef891e26512df09fabf0","price":"0.44","side":"BUY","size":"60.2"},{"asset_id":"96600821790790307414914106093858868634329285205417149685270682748367152458577","best_ask":"0.56","best_bid":"0.55","hash":"62fd6e0c8a843fa619005ca609f7eacbd520c90d","price":"0.56","side":"SELL","size":"60.2"}],"timestamp":"1785211225795"},"payload_hash":"017fd6d322f6e9b3f7b423ac057234f524c245527eeb518c160448e18c61d20b","raw_frame":"{\"market\":\"0xd412ce774cfcf8dc9f71164aac78783978aac7b03871702a3b8a481bd9dc9688\", \"price_changes\":[{\"asset_id\":\"107603864457683460275633293642179940881969192120168665300712204232021063124301\", \"price\":\"0.44\", \"size\":\"60.2\", \"side\":\"BUY\", \"hash\":\"221d1c4c7e53d20414b8ef891e26512df09fabf0\", \"best_bid\":\"0.44\", \"best_ask\":\"0.45\"}, {\"asset_id\":\"96600821790790307414914106093858868634329285205417149685270682748367152458577\", \"price\":\"0.56\", \"size\":\"60.2\", \"side\":\"SELL\", \"hash\":\"62fd6e0c8a843fa619005ca609f7eacbd520c90d\", \"best_bid\":\"0.55\", \"best_ask\":\"0.56\"}], \"timestamp\":\"1785211225795\", \"event_type\":\"price_change\"}","received_at":"2026-07-28T04:00:28.865694Z","schema_version":"clob-market-ws.price_change.v1","sequence":null,"server_hash":null,"server_timestamp":"1785211225795","session_id":"2d607381e3054cee91998cdf45a4231c","source":"clob_market_ws"},"received_at":"2026-07-28T04:00:28.865694Z","record_id":"2675d0f7d6120f9d4b41ef076d1a8ce927961984417587a87655f74c9162fefe","schema_fingerprint":"4aa3821a28b0b7c2400bc59aba4bcc0a76e971dadd19610d3ad38c768e124dc7","schema_version":"edge-lab-recorder.raw.v1","sequence":null,"source":"clob_market_ws"}
{"event_at":"2026-07-28T04:00:25.796000Z","event_fingerprint":"ab5b71b8f3d6e860aa28aae788d8ddfd708b4ba62beb334cf6b180beba2a9262","payload":{"connection_id":"f6725804f86a4c4eb588e4d5ed7db029","event_at":"2026-07-28T04:00:25.796000Z","event_type":"price_change","frame_hash":"e5fea486bf8249efc3cd95a75ccfa30ceec1995e2555d1e0fab395472d65ffd1","frame_index":0,"kind":"data","monotonic_ns":313211917992708,"payload":{"event_type":"price_change","market":"0xd412ce774cfcf8dc9f71164aac78783978aac7b03871702a3b8a481bd9dc9688","price_changes":[{"asset_id":"96600821790790307414914106093858868634329285205417149685270682748367152458577","best_ask":"0.56","best_bid":"0.55","hash":"b3e33b79542d7aac01bff4a84ba48e5d66a3c04f","price":"0.01","side":"BUY","size":"7550.02"},{"asset_id":"107603864457683460275633293642179940881969192120168665300712204232021063124301","best_ask":"0.45","best_bid":"0.44","hash":"68b826a5f108bfb14871873b3b8fbc7308e63060","price":"0.99","side":"SELL","size":"7550.02"}],"timestamp":"1785211225796"},"payload_hash":"a3e38353c1c2d4c5db5828420a2615187d667ca7ea00a471eaf7dec64fbd2c09","raw_frame":"{\"market\":\"0xd412ce774cfcf8dc9f71164aac78783978aac7b03871702a3b8a481bd9dc9688\", \"price_changes\":[{\"asset_id\":\"96600821790790307414914106093858868634329285205417149685270682748367152458577\", \"price\":\"0.01\", \"size\":\"7550.02\", \"side\":\"BUY\", \"hash\":\"b3e33b79542d7aac01bff4a84ba48e5d66a3c04f\", \"best_bid\":\"0.55\", \"best_ask\":\"0.56\"}, {\"asset_id\":\"107603864457683460275633293642179940881969192120168665300712204232021063124301\", \"price\":\"0.99\", \"size\":\"7550.02\", \"side\":\"SELL\", \"hash\":\"68b826a5f108bfb14871873b3b8fbc7308e63060\", \"best_bid\":\"0.44\", \"best_ask\":\"0.45\"}], \"timestamp\":\"1785211225796\", \"event_type\":\"price_change\"}","received_at":"2026-07-28T04:00:28.869870Z","schema_version":"clob-market-ws.price_change.v1","sequence":null,"server_hash":null,"server_timestamp":"1785211225796","session_id":"2d607381e3054cee91998cdf45a4231c","source":"clob_market_ws"},"received_at":"2026-07-28T04:00:28.869870Z","record_id":"4e93b24cae575ada79842f875274e946a678dcb12da41012ac8bdb255e7e3484","schema_fingerprint":"4aa3821a28b0b7c2400bc59aba4bcc0a76e971dadd19610d3ad38c768e124dc7","schema_version":"edge-lab-recorder.raw.v1","sequence":null,"source":"clob_market_ws"}
{"event_at":"2026-07-28T04:00:25.798000Z","event_fingerprint":"995ad5baaf400156a4daab669ab3019170263c33cb75161cbac3338c80bd66cb","payload":{"connection_id":"f6725804f86a4c4eb588e4d5ed7db029","event_at":"2026-07-28T04:00:25.798000Z","event_type":"price_change","frame_hash":"f346029647b0685171ee070f0c2dc4e46229e9304c27409090c99579aa842f4a","frame_index":0,"kind":"data","monotonic_ns":313211923308333,"payload":{"event_type":"price_change","market":"0xd412ce774cfcf8dc9f71164aac78783978aac7b03871702a3b8a481bd9dc9688","price_changes":[{"asset_id":"107603864457683460275633293642179940881969192120168665300712204232021063124301","best_ask":"0.45","best_bid":"0.44","hash":"2cef98681cd8ab28592a8fb09a6d7bb9701e8ebc","price":"0.41","side":"BUY","size":"104.84"},{"asset_id":"96600821790790307414914106093858868634329285205417149685270682748367152458577","best_ask":"0.56","best_bid":"0.55","hash":"a8a7dec3552458cd64dcfab110a6cf8f205578b5","price":"0.59","side":"SELL","size":"104.84"}],"timestamp":"1785211225798"},"payload_hash":"d0f9d9d35ec0b9e269d09c16e8d6a8732545c5cff3d87b13e5d1417b86ead7d8","raw_frame":"{\"market\":\"0xd412ce774cfcf8dc9f71164aac78783978aac7b03871702a3b8a481bd9dc9688\", \"price_changes\":[{\"asset_id\":\"107603864457683460275633293642179940881969192120168665300712204232021063124301\", \"price\":\"0.41\", \"size\":\"104.84\", \"side\":\"BUY\", \"hash\":\"2cef98681cd8ab28592a8fb09a6d7bb9701e8ebc\", \"best_bid\":\"0.44\", \"best_ask\":\"0.45\"}, {\"asset_id\":\"96600821790790307414914106093858868634329285205417149685270682748367152458577\", \"price\":\"0.59\", \"size\":\"104.84\", \"side\":\"SELL\", \"hash\":\"a8a7dec3552458cd64dcfab110a6cf8f205578b5\", \"best_bid\":\"0.55\", \"best_ask\":\"0.56\"}], \"timestamp\":\"1785211225798\", \"event_type\":\"price_change\"}","received_at":"2026-07-28T04:00:28.875184Z","schema_version":"clob-market-ws.price_change.v1","sequence":null,"server_hash":null,"server_timestamp":"1785211225798","session_id":"2d607381e3054cee91998cdf45a4231c","source":"clob_market_ws"},"received_at":"2026-07-28T04:00:28.875184Z","record_id":"17fbd2f9c18d13eaed0e3cd583222bdd6b48e2f8c3405e1e71602857c6b11d68","schema_fingerprint":"4aa3821a28b0b7c2400bc59aba4bcc0a76e971dadd19610d3ad38c768e124dc7","schema_version":"edge-lab-recorder.raw.v1","sequence":null,"source":"clob_market_ws"}
{"event_at":"2026-07-28T04:00:25.798000Z","event_fingerprint":"667c509f0fb4dedf695c7d4d8d28c100ccf0200af808ca3efe30492626eb495c","payload":{"connection_id":"f6725804f86a4c4eb588e4d5ed7db029","event_at":"2026-07-28T04:00:25.798000Z","event_type":"price_change","frame_hash":"be6266ac6eedaef9befcd9e2db55006af9f3e826e357e6c9544e397b1e5d97a8","frame_index":0,"kind":"data","monotonic_ns":313211928098958,"payload":{"event_type":"price_change","market":"0xd412ce774cfcf8dc9f71164aac78783978aac7b03871702a3b8a481bd9dc9688","price_changes":[{"asset_id":"107603864457683460275633293642179940881969192120168665300712204232021063124301","best_ask":"0.45","best_bid":"0.44","hash":"981184b32bb10c97725054f7e7a3d62c959a32ea","price":"0.43","side":"BUY","size":"110.6"},{"asset_id":"96600821790790307414914106093858868634329285205417149685270682748367152458577","best_ask":"0.56","best_bid":"0.55","hash":"f651127bba6a514895bdedc22dc2622dfdf21c99","price":"0.57","side":"SELL","size":"110.6"}],"timestamp":"1785211225798"},"payload_hash":"c35f8acb5539c2e71ec1eb562a3f9b4c5c9e99d5ff052b6729d73034ebce6738","raw_frame":"{\"market\":\"0xd412ce774cfcf8dc9f71164aac78783978aac7b03871702a3b8a481bd9dc9688\", \"price_changes\":[{\"asset_id\":\"107603864457683460275633293642179940881969192120168665300712204232021063124301\", \"price\":\"0.43\", \"size\":\"110.6\", \"side\":\"BUY\", \"hash\":\"981184b32bb10c97725054f7e7a3d62c959a32ea\", \"best_bid\":\"0.44\", \"best_ask\":\"0.45\"}, {\"asset_id\":\"96600821790790307414914106093858868634329285205417149685270682748367152458577\", \"price\":\"0.57\", \"size\":\"110.6\", \"side\":\"SELL\", \"hash\":\"f651127bba6a514895bdedc22dc2622dfdf21c99\", \"best_bid\":\"0.55\", \"best_ask\":\"0.56\"}], \"timestamp\":\"1785211225798\", \"event_type\":\"price_change\"}","received_at":"2026-07-28T04:00:28.879977Z","schema_version":"clob-market-ws.price_change.v1","sequence":null,"server_hash":null,"server_timestamp":"1785211225798","session_id":"2d607381e3054cee91998cdf45a4231c","source":"clob_market_ws"},"received_at":"2026-07-28T04:00:28.879977Z","record_id":"996a4748e3a6754af6e63e1c63527f69ba838b12a5458de89ff1ee2bdff0b471","schema_fingerprint":"4aa3821a28b0b7c2400bc59aba4bcc0a76e971dadd19610d3ad38c768e124dc7","schema_version":"edge-lab-recorder.raw.v1","sequence":null,"source":"clob_market_ws"}
{"event_at":"2026-07-28T04:00:25.800000Z","event_fingerprint":"e9feece80c08b7eea4447102c7d397021c1a1dbae2ef644260ac0b27807042f3","payload":{"connection_id":"f6725804f86a4c4eb588e4d5ed7db029","event_at":"2026-07-28T04:00:25.800000Z","event_type":"price_change","frame_hash":"ae60cb4928f7b1d0d8278f41c1602fb7ef6f68f000b98a8c67fc16b55d7dc94a","frame_index":0,"kind":"data","monotonic_ns":313211932198541,"payload":{"event_type":"price_change","market":"0xd412ce774cfcf8dc9f71164aac78783978aac7b03871702a3b8a481bd9dc9688","price_changes":[{"asset_id":"96600821790790307414914106093858868634329285205417149685270682748367152458577","best_ask":"0.56","best_bid":"0.55","hash":"3a885fa3d5150b7574868e023adcebc20bf97956","price":"0.56","side":"SELL","size":"66.2"},{"asset_id":"107603864457683460275633293642179940881969192120168665300712204232021063124301","best_ask":"0.45","best_bid":"0.44","hash":"d298d7923f1f2a2add1ee95996cf78f868486bdf","price":"0.44","side":"BUY","size":"66.2"}],"timestamp":"1785211225800"},"payload_hash":"58757d96905df9daf52072a41d815a27c2216de59394db1c57afa6907aeae071","raw_frame":"{\"market\":\"0xd412ce774cfcf8dc9f71164aac78783978aac7b03871702a3b8a481bd9dc9688\", \"price_changes\":[{\"asset_id\":\"96600821790790307414914106093858868634329285205417149685270682748367152458577\", \"price\":\"0.56\", \"size\":\"66.2\", \"side\":\"SELL\", \"hash\":\"3a885fa3d5150b7574868e023adcebc20bf97956\", \"best_bid\":\"0.55\", \"best_ask\":\"0.56\"}, {\"asset_id\":\"107603864457683460275633293642179940881969192120168665300712204232021063124301\", \"price\":\"0.44\", \"size\":\"66.2\", \"side\":\"BUY\", \"hash\":\"d298d7923f1f2a2add1ee95996cf78f868486bdf\", \"best_bid\":\"0.44\", \"best_ask\":\"0.45\"}], \"timestamp\":\"1785211225800\", \"event_type\":\"price_change\"}","received_at":"2026-07-28T04:00:28.884075Z","schema_version":"clob-market-ws.price_change.v1","sequence":null,"server_hash":null,"server_timestamp":"1785211225800","session_id":"2d607381e3054cee91998cdf45a4231c","source":"clob_market_ws"},"received_at":"2026-07-28T04:00:28.884075Z","record_id":"d03742a2dfc22cd689f614b945238e98c08bc7ffc04b766252e83c207afe6115","schema_fingerprint":"4aa3821a28b0b7c2400bc59aba4bcc0a76e971dadd19610d3ad38c768e124dc7","schema_version":"edge-lab-recorder.raw.v1","sequence":null,"source":"clob_market_ws"}
{"event_at":"2026-07-28T04:00:25.800000Z","event_fingerprint":"b35f62aff763dfa13676891c5649e2289681fd98f467b1b47257f6b0c266eb53","payload":{"connection_id":"f6725804f86a4c4eb588e4d5ed7db029","event_at":"2026-07-28T04:00:25.800000Z","event_type":"price_change","frame_hash":"04abf9308c9f67536179bb6d98ef25ec3e9c50e64c5adbf954f8a1e32e2ba7bc","frame_index":0,"kind":"data","monotonic_ns":313211937911333,"payload":{"event_type":"price_change","market":"0xd412ce774cfcf8dc9f71164aac78783978aac7b03871702a3b8a481bd9dc9688","price_changes":[{"asset_id":"96600821790790307414914106093858868634329285205417149685270682748367152458577","best_ask":"0.56","best_bid":"0.55","hash":"b66716c4a65bb1d2a7daa9f2d0115686e2b4fa6a","price":"0.55","side":"BUY","size":"86.28"},{"asset_id":"107603864457683460275633293642179940881969192120168665300712204232021063124301","best_ask":"0.45","best_bid":"0.44","hash":"7e549548e20dff643c686be3005eb9e5b21ae388","price":"0.45","side":"SELL","size":"86.28"}],"timestamp":"1785211225800"},"payload_hash":"60a8fb9193ccbc1c583547c21ffea6939bc9d1fcaa1b68f8ad9b960cce149469","raw_frame":"{\"market\":\"0xd412ce774cfcf8dc9f71164aac78783978aac7b03871702a3b8a481bd9dc9688\", \"price_changes\":[{\"asset_id\":\"96600821790790307414914106093858868634329285205417149685270682748367152458577\", \"price\":\"0.55\", \"size\":\"86.28\", \"side\":\"BUY\", \"hash\":\"b66716c4a65bb1d2a7daa9f2d0115686e2b4fa6a\", \"best_bid\":\"0.55\", \"best_ask\":\"0.56\"}, {\"asset_id\":\"107603864457683460275633293642179940881969192120168665300712204232021063124301\", \"price\":\"0.45\", \"size\":\"86.28\", \"side\":\"SELL\", \"hash\":\"7e549548e20dff643c686be3005eb9e5b21ae388\", \"best_bid\":\"0.44\", \"best_ask\":\"0.45\"}], \"timestamp\":\"1785211225800\", \"event_type\":\"price_change\"}","received_at":"2026-07-28T04:00:28.889787Z","schema_version":"clob-market-ws.price_change.v1","sequence":null,"server_hash":null,"server_timestamp":"1785211225800","session_id":"2d607381e3054cee91998cdf45a4231c","source":"clob_market_ws"},"received_at":"2026-07-28T04:00:28.889787Z","record_id":"199fcc59c049719e5fa425d99da93a5c9fac72a88c020dc1fe2e5b3ba66d19a5","schema_fingerprint":"4aa3821a28b0b7c2400bc59aba4bcc0a76e971dadd19610d3ad38c768e124dc7","schema_version":"edge-lab-recorder.raw.v1","sequence":null,"source":"clob_market_ws"}
{"event_at":"2026-07-28T04:00:25.801000Z","event_fingerprint":"bafe7ba612f3703b2e7975a64c22d4289dd4eb596bdb2540ce86771f66c67795","payload":{"connection_id":"f6725804f86a4c4eb588e4d5ed7db029","event_at":"2026-07-28T04:00:25.801000Z","event_type":"price_change","frame_hash":"8dd8c5680ba0869e9a1d8d26d30f518ebdd8dc7eb77f91bfe8ede58d8b0b175b","frame_index":0,"kind":"data","monotonic_ns":313211948084708,"payload":{"event_type":"price_change","market":"0xd412ce774cfcf8dc9f71164aac78783978aac7b03871702a3b8a481bd9dc9688","price_changes":[{"asset_id":"107603864457683460275633293642179940881969192120168665300712204232021063124301","best_ask":"0.45","best_bid":"0.44","hash":"6d7fd1c52c6041c876adb732b9574bac68a1f559","price":"0.44","side":"BUY","size":"72.2"},{"asset_id":"96600821790790307414914106093858868634329285205417149685270682748367152458577","best_ask":"0.56","best_bid":"0.55","hash":"f1d3aabae8a046feea0537785bbc08cbc24472ed","price":"0.56","side":"SELL","size":"72.2"}],"timestamp":"1785211225801"},"payload_hash":"220144dff0114c859466b37ebaea2044e7290b3c7c4c4b02abcb3ab181ea31f9","raw_frame":"{\"market\":\"0xd412ce774cfcf8dc9f71164aac78783978aac7b03871702a3b8a481bd9dc9688\", \"price_changes\":[{\"asset_id\":\"107603864457683460275633293642179940881969192120168665300712204232021063124301\", \"price\":\"0.44\", \"size\":\"72.2\", \"side\":\"BUY\", \"hash\":\"6d7fd1c52c6041c876adb732b9574bac68a1f559\", \"best_bid\":\"0.44\", \"best_ask\":\"0.45\"}, {\"asset_id\":\"96600821790790307414914106093858868634329285205417149685270682748367152458577\", \"price\":\"0.56\", \"size\":\"72.2\", \"side\":\"SELL\", \"hash\":\"f1d3aabae8a046feea0537785bbc08cbc24472ed\", \"best_bid\":\"0.55\", \"best_ask\":\"0.56\"}], \"timestamp\":\"1785211225801\", \"event_type\":\"price_change\"}","received_at":"2026-07-28T04:00:28.899962Z","schema_version":"clob-market-ws.price_change.v1","sequence":null,"server_hash":null,"server_timestamp":"1785211225801","session_id":"2d607381e3054cee91998cdf45a4231c","source":"clob_market_ws"},"received_at":"2026-07-28T04:00:28.899962Z","record_id":"255917d8818288710031eae98b8fba9109554aac87ee25539106309fc3a739eb","schema_fingerprint":"4aa3821a28b0b7c2400bc59aba4bcc0a76e971dadd19610d3ad38c768e124dc7","schema_version":"edge-lab-recorder.raw.v1","sequence":null,"source":"clob_market_ws"}
{"event_at":"2026-07-28T04:00:25.803000Z","event_fingerprint":"47ce5c7170498d612ac44578823b99ea7251bfc2245f55ba71c142a958a66689","payload":{"connection_id":"f6725804f86a4c4eb588e4d5ed7db029","event_at":"2026-07-28T04:00:25.803000Z","event_type":"price_change","frame_hash":"56d36ead515eeca388269b48191566b015021d3333e41ae3ac28e31e5828053e","frame_index":0,"kind":"data","monotonic_ns":313211957643291,"payload":{"event_type":"price_change","market":"0xd412ce774cfcf8dc9f71164aac78783978aac7b03871702a3b8a481bd9dc9688","price_changes":[{"asset_id":"107603864457683460275633293642179940881969192120168665300712204232021063124301","best_ask":"0.45","best_bid":"0.44","hash":"3979bf9fb1da4ca5462c4b6e96a9b55cc7d5253e","price":"0.44","side":"BUY","size":"77.2"},{"asset_id":"96600821790790307414914106093858868634329285205417149685270682748367152458577","best_ask":"0.56","best_bid":"0.55","hash":"0e20debbbe79791f0d4c51ebf2061755d3a2843f","price":"0.56","side":"SELL","size":"77.2"}],"timestamp":"1785211225803"},"payload_hash":"257e16a5625de462eee9b76c65516f28f1967391fd3c65bd6dc9bbdd0f84afe6","raw_frame":"{\"market\":\"0xd412ce774cfcf8dc9f71164aac78783978aac7b03871702a3b8a481bd9dc9688\", \"price_changes\":[{\"asset_id\":\"107603864457683460275633293642179940881969192120168665300712204232021063124301\", \"price\":\"0.44\", \"size\":\"77.2\", \"side\":\"BUY\", \"hash\":\"3979bf9fb1da4ca5462c4b6e96a9b55cc7d5253e\", \"best_bid\":\"0.44\", \"best_ask\":\"0.45\"}, {\"asset_id\":\"96600821790790307414914106093858868634329285205417149685270682748367152458577\", \"price\":\"0.56\", \"size\":\"77.2\", \"side\":\"SELL\", \"hash\":\"0e20debbbe79791f0d4c51ebf2061755d3a2843f\", \"best_bid\":\"0.55\", \"best_ask\":\"0.56\"}], \"timestamp\":\"1785211225803\", \"event_type\":\"price_change\"}","received_at":"2026-07-28T04:00:28.909521Z","schema_version":"clob-market-ws.price_change.v1","sequence":null,"server_hash":null,"server_timestamp":"1785211225803","session_id":"2d607381e3054cee91998cdf45a4231c","source":"clob_market_ws"},"received_at":"2026-07-28T04:00:28.909521Z","record_id":"4289cf0262283058db8fc99402bfc12a7a662704820a27fe087f12bb6dc59ace","schema_fingerprint":"4aa3821a28b0b7c2400bc59aba4bcc0a76e971dadd19610d3ad38c768e124dc7","schema_version":"edge-lab-recorder.raw.v1","sequence":null,"source":"clob_market_ws"}
{"event_at":"2026-07-28T04:00:25.804000Z","event_fingerprint":"6fb0c57b792a94d71d1070b38995660596ae39294b695a3346179b311952cea4","payload":{"connection_id":"f6725804f86a4c4eb588e4d5ed7db029","event_at":"2026-07-28T04:00:25.804000Z","event_type":"price_change","frame_hash":"bc6728cedbacae52b0ac1bfee65a16174e8b7c0b36bc8a4588066e40ab5fb5e6","frame_index":0,"kind":"data","monotonic_ns":313211969227000,"payload":{"event_type":"price_change","market":"0xd412ce774cfcf8dc9f71164aac78783978aac7b03871702a3b8a481bd9dc9688","price_changes":[{"asset_id":"107603864457683460275633293642179940881969192120168665300712204232021063124301","best_ask":"0.45","best_bid":"0.44","hash":"6eccff944e6a1ec41ce64aaaa485535df414d1ba","price":"0.43","side":"BUY","size":"123.6"},{"asset_id":"96600821790790307414914106093858868634329285205417149685270682748367152458577","best_ask":"0.56","best_bid":"0.55","hash":"0cc81a07d2444a8720d1c11891b9661986cf66ee","price":"0.57","side":"SELL","size":"123.6"}],"timestamp":"1785211225804"},"payload_hash":"72b4239869e7dfa929359b9b48e2f01d70430e61c2865399a8c9e2e9be84bf74","raw_frame":"{\"market\":\"0xd412ce774cfcf8dc9f71164aac78783978aac7b03871702a3b8a481bd9dc9688\", \"price_changes\":[{\"asset_id\":\"107603864457683460275633293642179940881969192120168665300712204232021063124301\", \"price\":\"0.43\", \"size\":\"123.6\", \"side\":\"BUY\", \"hash\":\"6eccff944e6a1ec41ce64aaaa485535df414d1ba\", \"best_bid\":\"0.44\", \"best_ask\":\"0.45\"}, {\"asset_id\":\"96600821790790307414914106093858868634329285205417149685270682748367152458577\", \"price\":\"0.57\", \"size\":\"123.6\", \"side\":\"SELL\", \"hash\":\"0cc81a07d2444a8720d1c11891b9661986cf66ee\", \"best_bid\":\"0.55\", \"best_ask\":\"0.56\"}], \"timestamp\":\"1785211225804\", \"event_type\":\"price_change\"}","received_at":"2026-07-28T04:00:28.921103Z","schema_version":"clob-market-ws.price_change.v1","sequence":null,"server_hash":null,"server_timestamp":"1785211225804","session_id":"2d607381e3054cee91998cdf45a4231c","source":"clob_market_ws"},"received_at":"2026-07-28T04:00:28.921103Z","record_id":"f498ae69e3c1b9a0da8fb7bd1e41a2a9bb651aa57fc4b3209406be6ab74e6cc4","schema_fingerprint":"4aa3821a28b0b7c2400bc59aba4bcc0a76e971dadd19610d3ad38c768e124dc7","schema_version":"edge-lab-recorder.raw.v1","sequence":null,"source":"clob_market_ws"}
{"event_at":"2026-07-28T04:00:25.805000Z","event_fingerprint":"d5ef8f021b99a33386e95fe1cf1af0617a0608511899a58afa0145288025a455","payload":{"connection_id":"f6725804f86a4c4eb588e4d5ed7db029","event_at":"2026-07-28T04:00:25.805000Z","event_type":"price_change","frame_hash":"a5134f575513aab7db6c978408122166aa976a47f163ef7540b2307d8f230d44","frame_index":0,"kind":"data","monotonic_ns":313211979926000,"payload":{"event_type":"price_change","market":"0xd412ce774cfcf8dc9f71164aac78783978aac7b03871702a3b8a481bd9dc9688","price_changes":[{"asset_id":"107603864457683460275633293642179940881969192120168665300712204232021063124301","best_ask":"0.45","best_bid":"0.44","hash":"d02ffd0b6579a83cb371e6cd574f9ee4731440b8","price":"0.42","side":"BUY","size":"97.27"},{"asset_id":"96600821790790307414914106093858868634329285205417149685270682748367152458577","best_ask":"0.56","best_bid":"0.55","hash":"1af3a4dffb149b4fedecc0e1f2a4c068b8997039","price":"0.58","side":"SELL","size":"97.27"}],"timestamp":"1785211225805"},"payload_hash":"9f41b449faf80973eb13670f5ec437e34764ae6a424f6249b0e77d7aaf0a5739","raw_frame":"{\"market\":\"0xd412ce774cfcf8dc9f71164aac78783978aac7b03871702a3b8a481bd9dc9688\", \"price_changes\":[{\"asset_id\":\"107603864457683460275633293642179940881969192120168665300712204232021063124301\", \"price\":\"0.42\", \"size\":\"97.27\", \"side\":\"BUY\", \"hash\":\"d02ffd0b6579a83cb371e6cd574f9ee4731440b8\", \"best_bid\":\"0.44\", \"best_ask\":\"0.45\"}, {\"asset_id\":\"96600821790790307414914106093858868634329285205417149685270682748367152458577\", \"price\":\"0.58\", \"size\":\"97.27\", \"side\":\"SELL\", \"hash\":\"1af3a4dffb149b4fedecc0e1f2a4c068b8997039\", \"best_bid\":\"0.55\", \"best_ask\":\"0.56\"}], \"timestamp\":\"1785211225805\", \"event_type\":\"price_change\"}","received_at":"2026-07-28T04:00:28.931802Z","schema_version":"clob-market-ws.price_change.v1","sequence":null,"server_hash":null,"server_timestamp":"1785211225805","session_id":"2d607381e3054cee91998cdf45a4231c","source":"clob_market_ws"},"received_at":"2026-07-28T04:00:28.931802Z","record_id":"ff9537586224aa7c0ceee8598f6e676841b9b98840fe55891cb2786f78c16f09","schema_fingerprint":"4aa3821a28b0b7c2400bc59aba4bcc0a76e971dadd19610d3ad38c768e124dc7","schema_version":"edge-lab-recorder.raw.v1","sequence":null,"source":"clob_market_ws"}
{"event_at":"2026-07-28T04:00:25.806000Z","event_fingerprint":"732fdeb0135160185496e85f4e3f9c5f64927670399c8965d1e1b6508521859f","payload":{"connection_id":"f6725804f86a4c4eb588e4d5ed7db029","event_at":"2026-07-28T04:00:25.806000Z","event_type":"price_change","frame_hash":"75cd7527c49fc92f98aeb6f00817b28174aa91f43a3a837e429aa83df03b120b","frame_index":0,"kind":"data","monotonic_ns":313211984812208,"payload":{"event_type":"price_change","market":"0xd412ce774cfcf8dc9f71164aac78783978aac7b03871702a3b8a481bd9dc9688","price_changes":[{"asset_id":"107603864457683460275633293642179940881969192120168665300712204232021063124301","best_ask":"0.45","best_bid":"0.44","hash":"db3ccda28922594eb5946a601d1764db24621656","price":"0.38","side":"BUY","size":"147"},{"asset_id":"96600821790790307414914106093858868634329285205417149685270682748367152458577","best_ask":"0.56","best_bid":"0.55","hash":"5dc53245edd5b8a379a22d8bcd2beb1d06bdca5e","price":"0.62","side":"SELL","size":"147"}],"timestamp":"1785211225806"},"payload_hash":"79972c00b978982e0d24743c97d215b89ad5cd797497da1297634c48e4c91dde","raw_frame":"{\"market\":\"0xd412ce774cfcf8dc9f71164aac78783978aac7b03871702a3b8a481bd9dc9688\", \"price_changes\":[{\"asset_id\":\"107603864457683460275633293642179940881969192120168665300712204232021063124301\", \"price\":\"0.38\", \"size\":\"147\", \"side\":\"BUY\", \"hash\":\"db3ccda28922594eb5946a601d1764db24621656\", \"best_bid\":\"0.44\", \"best_ask\":\"0.45\"}, {\"asset_id\":\"96600821790790307414914106093858868634329285205417149685270682748367152458577\", \"price\":\"0.62\", \"size\":\"147\", \"side\":\"SELL\", \"hash\":\"5dc53245edd5b8a379a22d8bcd2beb1d06bdca5e\", \"best_bid\":\"0.55\", \"best_ask\":\"0.56\"}], \"timestamp\":\"1785211225806\", \"event_type\":\"price_change\"}","received_at":"2026-07-28T04:00:28.936689Z","schema_version":"clob-market-ws.price_change.v1","sequence":null,"server_hash":null,"server_timestamp":"1785211225806","session_id":"2d607381e3054cee91998cdf45a4231c","source":"clob_market_ws"},"received_at":"2026-07-28T04:00:28.936689Z","record_id":"cc98a26d18f46b8d8b5cfd05cf9aad8d0b2609872ad8e50b815080a42b584ad6","schema_fingerprint":"4aa3821a28b0b7c2400bc59aba4bcc0a76e971dadd19610d3ad38c768e124dc7","schema_version":"edge-lab-recorder.raw.v1","sequence":null,"source":"clob_market_ws"}
{"event_at":"2026-07-28T04:00:25.806000Z","event_fingerprint":"f660c998b1dea7ad972d72d853d56b3a6aa510f4e85254e9d0a68a15a5a2d235","payload":{"connection_id":"f6725804f86a4c4eb588e4d5ed7db029","event_at":"2026-07-28T04:00:25.806000Z","event_type":"price_change","frame_hash":"27d23b8e9fad053f9f9265dbe5300570e592802c8dca701358f4b96a75dbd109","frame_index":0,"kind":"data","monotonic_ns":313211989919750,"payload":{"event_type":"price_change","market":"0xd412ce774cfcf8dc9f71164aac78783978aac7b03871702a3b8a481bd9dc9688","price_changes":[{"asset_id":"107603864457683460275633293642179940881969192120168665300712204232021063124301","best_ask":"0.45","best_bid":"0.44","hash":"8fcb71f91d9af9c9959b4c75519cb661f69b8f8b","price":"0.28","side":"BUY","size":"36"},{"asset_id":"96600821790790307414914106093858868634329285205417149685270682748367152458577","best_ask":"0.56","best_bid":"0.55","hash":"c90f69bfafc294a6b9b37f58a346e8c099b49f8a","price":"0.72","side":"SELL","size":"36"}],"timestamp":"1785211225806"},"payload_hash":"84991aaca8073c7397f18d8f8bf77d44d88b6b7aa4c363dac96a52a99b1d74ce","raw_frame":"{\"market\":\"0xd412ce774cfcf8dc9f71164aac78783978aac7b03871702a3b8a481bd9dc9688\", \"price_changes\":[{\"asset_id\":\"107603864457683460275633293642179940881969192120168665300712204232021063124301\", \"price\":\"0.28\", \"size\":\"36\", \"side\":\"BUY\", \"hash\":\"8fcb71f91d9af9c9959b4c75519cb661f69b8f8b\", \"best_bid\":\"0.44\", \"best_ask\":\"0.45\"}, {\"asset_id\":\"96600821790790307414914106093858868634329285205417149685270682748367152458577\", \"price\":\"0.72\", \"size\":\"36\", \"side\":\"SELL\", \"hash\":\"c90f69bfafc294a6b9b37f58a346e8c099b49f8a\", \"best_bid\":\"0.55\", \"best_ask\":\"0.56\"}], \"timestamp\":\"1785211225806\", \"event_type\":\"price_change\"}","received_at":"2026-07-28T04:00:28.941795Z","schema_version":"clob-market-ws.price_change.v1","sequence":null,"server_hash":null,"server_timestamp":"1785211225806","session_id":"2d607381e3054cee91998cdf45a4231c","source":"clob_market_ws"},"received_at":"2026-07-28T04:00:28.941795Z","record_id":"7dd831add459111678240588f4f36f77992868b4fcf4c19918a1084441b411fe","schema_fingerprint":"4aa3821a28b0b7c2400bc59aba4bcc0a76e971dadd19610d3ad38c768e124dc7","schema_version":"edge-lab-recorder.raw.v1","sequence":null,"source":"clob_market_ws"}
{"event_at":"2026-07-28T04:00:25.808000Z","event_fingerprint":"ae667f9230e5c4ce6afbc9c1192e4ec25a714b6b41d25bb4d1a9e9636dffb747","payload":{"connection_id":"f6725804f86a4c4eb588e4d5ed7db029","event_at":"2026-07-28T04:00:25.808000Z","event_type":"price_change","frame_hash":"6bd713d651d8f6b83d83d4fecb60d552fceceb8ddd965279b609748be586e93e","frame_index":0,"kind":"data","monotonic_ns":313211994916166,"payload":{"event_type":"price_change","market":"0xd412ce774cfcf8dc9f71164aac78783978aac7b03871702a3b8a481bd9dc9688","price_changes":[{"asset_id":"107603864457683460275633293642179940881969192120168665300712204232021063124301","best_ask":"0.45","best_bid":"0.44","hash":"5ca8b05cabc0b559008d21025a63832aeaf6495b","price":"0.38","side":"BUY","size":"117"},{"asset_id":"96600821790790307414914106093858868634329285205417149685270682748367152458577","best_ask":"0.56","best_bid":"0.55","hash":"421161eb7c7c06a179f2b516220797ca11ae36b1","price":"0.62","side":"SELL","size":"117"}],"timestamp":"1785211225808"},"payload_hash":"0bbea94c1252ab13c88fb3ca51dfbee2b2d91a2e21310707df208d9bbbda1af3","raw_frame":"{\"market\":\"0xd412ce774cfcf8dc9f71164aac78783978aac7b03871702a3b8a481bd9dc9688\", \"price_changes\":[{\"asset_id\":\"107603864457683460275633293642179940881969192120168665300712204232021063124301\", \"price\":\"0.38\", \"size\":\"117\", \"side\":\"BUY\", \"hash\":\"5ca8b05cabc0b559008d21025a63832aeaf6495b\", \"best_bid\":\"0.44\", \"best_ask\":\"0.45\"}, {\"asset_id\":\"96600821790790307414914106093858868634329285205417149685270682748367152458577\", \"price\":\"0.62\", \"size\":\"117\", \"side\":\"SELL\", \"hash\":\"421161eb7c7c06a179f2b516220797ca11ae36b1\", \"best_bid\":\"0.55\", \"best_ask\":\"0.56\"}], \"timestamp\":\"1785211225808\", \"event_type\":\"price_change\"}","received_at":"2026-07-28T04:00:28.946793Z","schema_version":"clob-market-ws.price_change.v1","sequence":null,"server_hash":null,"server_timestamp":"1785211225808","session_id":"2d607381e3054cee91998cdf45a4231c","source":"clob_market_ws"},"received_at":"2026-07-28T04:00:28.946793Z","record_id":"2ae6eb812ed5dcfa86508405de9760be3ab2568f31f6bb58eb916a02f0054dab","schema_fingerprint":"4aa3821a28b0b7c2400bc59aba4bcc0a76e971dadd19610d3ad38c768e124dc7","schema_version":"edge-lab-recorder.raw.v1","sequence":null,"source":"clob_market_ws"}
{"event_at":"2026-07-28T04:00:25.809000Z","event_fingerprint":"233246114c1f5ca98827bb384b10a028cd739817e47ae5033482f9733ddde9f0","payload":{"connection_id":"f6725804f86a4c4eb588e4d5ed7db029","event_at":"2026-07-28T04:00:25.809000Z","event_type":"price_change","frame_hash":"46f9bc11e3ae357f40e8e643f38c4d0599f3e1304c28f1cfee84623a86347f7d","frame_index":0,"kind":"data","monotonic_ns":313212000081791,"payload":{"event_type":"price_change","market":"0xd412ce774cfcf8dc9f71164aac78783978aac7b03871702a3b8a481bd9dc9688","price_changes":[{"asset_id":"96600821790790307414914106093858868634329285205417149685270682748367152458577","best_ask":"0.56","best_bid":"0.55","hash":"e297cbf8b7598ce28ab8f0bca774b07b15ad73b2","price":"0.55","side":"BUY","size":"108.28"},{"asset_id":"107603864457683460275633293642179940881969192120168665300712204232021063124301","best_ask":"0.45","best_bid":"0.44","hash":"ddad56d2e8614dd05b55f0580e0536fdc55839d4","price":"0.45","side":"SELL","size":"108.28"}],"timestamp":"1785211225809"},"payload_hash":"0aa53f21657b40904b4c9053181563d3c10ffb46fb10f002d0961acfd8b4d823","raw_frame":"{\"market\":\"0xd412ce774cfcf8dc9f71164aac78783978aac7b03871702a3b8a481bd9dc9688\", \"price_changes\":[{\"asset_id\":\"96600821790790307414914106093858868634329285205417149685270682748367152458577\", \"price\":\"0.55\", \"size\":\"108.28\", \"side\":\"BUY\", \"hash\":\"e297cbf8b7598ce28ab8f0bca774b07b15ad73b2\", \"best_bid\":\"0.55\", \"best_ask\":\"0.56\"}, {\"asset_id\":\"107603864457683460275633293642179940881969192120168665300712204232021063124301\", \"price\":\"0.45\", \"size\":\"108.28\", \"side\":\"SELL\", \"hash\":\"ddad56d2e8614dd05b55f0580e0536fdc55839d4\", \"best_bid\":\"0.44\", \"best_ask\":\"0.45\"}], \"timestamp\":\"1785211225809\", \"event_type\":\"price_change\"}","received_at":"2026-07-28T04:00:28.951957Z","schema_version":"clob-market-ws.price_change.v1","sequence":null,"server_hash":null,"server_timestamp":"1785211225809","session_id":"2d607381e3054cee91998cdf45a4231c","source":"clob_market_ws"},"received_at":"2026-07-28T04:00:28.951957Z","record_id":"927e0f08e985c240eaff9fcd7fed3c3659b7d577376c674a630bf2e1ddd6f9e7","schema_fingerprint":"4aa3821a28b0b7c2400bc59aba4bcc0a76e971dadd19610d3ad38c768e124dc7","schema_version":"edge-lab-recorder.raw.v1","sequence":null,"source":"clob_market_ws"}
{"event_at":"2026-07-28T04:00:25.810000Z","event_fingerprint":"6f70c7665adae57879a22bfd98e87444f8c2c4ed08a5ebc9970ddf66a64fc06c","payload":{"connection_id":"f6725804f86a4c4eb588e4d5ed7db029","event_at":"2026-07-28T04:00:25.810000Z","event_type":"price_change","frame_hash":"862233b538d1555e445ba3598afb477fd1f6737ec109b215c2fe2d2a6d277369","frame_index":0,"kind":"data","monotonic_ns":313212009144166,"payload":{"event_type":"price_change","market":"0xd412ce774cfcf8dc9f71164aac78783978aac7b03871702a3b8a481bd9dc9688","price_changes":[{"asset_id":"107603864457683460275633293642179940881969192120168665300712204232021063124301","best_ask":"0.45","best_bid":"0.44","hash":"e7bc9f55243ea33e42e9fcc3700de44e4aee4681","price":"0.43","side":"BUY","size":"113.6"},{"asset_id":"96600821790790307414914106093858868634329285205417149685270682748367152458577","best_ask":"0.56","best_bid":"0.55","hash":"629330ff7e09b21bc14c712658e94a2ab1226c8d","price":"0.57","side":"SELL","size":"113.6"}],"timestamp":"1785211225810"},"payload_hash":"59e03f0679338d7190c478117f0afd88246ab74b0c42e0e8d44f965614537bb1","raw_frame":"{\"market\":\"0xd412ce774cfcf8dc9f71164aac78783978aac7b03871702a3b8a481bd9dc9688\", \"price_changes\":[{\"asset_id\":\"107603864457683460275633293642179940881969192120168665300712204232021063124301\", \"price\":\"0.43\", \"size\":\"113.6\", \"side\":\"BUY\", \"hash\":\"e7bc9f55243ea33e42e9fcc3700de44e4aee4681\", \"best_bid\":\"0.44\", \"best_ask\":\"0.45\"}, {\"asset_id\":\"96600821790790307414914106093858868634329285205417149685270682748367152458577\", \"price\":\"0.57\", \"size\":\"113.6\", \"side\":\"SELL\", \"hash\":\"629330ff7e09b21bc14c712658e94a2ab1226c8d\", \"best_bid\":\"0.55\", \"best_ask\":\"0.56\"}], \"timestamp\":\"1785211225810\", \"event_type\":\"price_change\"}","received_at":"2026-07-28T04:00:28.961020Z","schema_version":"clob-market-ws.price_change.v1","sequence":null,"server_hash":null,"server_timestamp":"1785211225810","session_id":"2d607381e3054cee91998cdf45a4231c","source":"clob_market_ws"},"received_at":"2026-07-28T04:00:28.961020Z","record_id":"fe6ae1b56fd3346ff7e7486bc13013832b406693c2dfae4fab341e6b65fc5a68","schema_fingerprint":"4aa3821a28b0b7c2400bc59aba4bcc0a76e971dadd19610d3ad38c768e124dc7","schema_version":"edge-lab-recorder.raw.v1","sequence":null,"source":"clob_market_ws"}
{"event_at":"2026-07-28T04:00:25.810000Z","event_fingerprint":"4ecb083c9b63f01842d212415bc8e58bb7a9ba9780416a3db598a385697de228","payload":{"connection_id":"f6725804f86a4c4eb588e4d5ed7db029","event_at":"2026-07-28T04:00:25.810000Z","event_type":"price_change","frame_hash":"ec52d757e742107b7ea93161fc245006954f8a6da548c9103dea5cae6f3a6d5e","frame_index":0,"kind":"data","monotonic_ns":313212021501125,"payload":{"event_type":"price_change","market":"0xd412ce774cfcf8dc9f71164aac78783978aac7b03871702a3b8a481bd9dc9688","price_changes":[{"asset_id":"96600821790790307414914106093858868634329285205417149685270682748367152458577","best_ask":"0.56","best_bid":"0.55","hash":"629330ff7e09b21bc14c712658e94a2ab1226c8d","price":"0.52","side":"BUY","size":"43.6"},{"asset_id":"107603864457683460275633293642179940881969192120168665300712204232021063124301","best_ask":"0.45","best_bid":"0.44","hash":"e7bc9f55243ea33e42e9fcc3700de44e4aee4681","price":"0.48","side":"SELL","size":"43.6"}],"timestamp":"1785211225810"},"payload_hash":"373b2cf000f1da9690174e10e10d759de0e120ddb5b58ccdf402b113f7b0aed3","raw_frame":"{\"market\":\"0xd412ce774cfcf8dc9f71164aac78783978aac7b03871702a3b8a481bd9dc9688\", \"price_changes\":[{\"asset_id\":\"96600821790790307414914106093858868634329285205417149685270682748367152458577\", \"price\":\"0.52\", \"size\":\"43.6\", \"side\":\"BUY\", \"hash\":\"629330ff7e09b21bc14c712658e94a2ab1226c8d\", \"best_bid\":\"0.55\", \"best_ask\":\"0.56\"}, {\"asset_id\":\"107603864457683460275633293642179940881969192120168665300712204232021063124301\", \"price\":\"0.48\", \"size\":\"43.6\", \"side\":\"SELL\", \"hash\":\"e7bc9f55243ea33e42e9fcc3700de44e4aee4681\", \"best_bid\":\"0.44\", \"best_ask\":\"0.45\"}], \"timestamp\":\"1785211225810\", \"event_type\":\"price_change\"}","received_at":"2026-07-28T04:00:28.973377Z","schema_version":"clob-market-ws.price_change.v1","sequence":null,"server_hash":null,"server_timestamp":"1785211225810","session_id":"2d607381e3054cee91998cdf45a4231c","source":"clob_market_ws"},"received_at":"2026-07-28T04:00:28.973377Z","record_id":"eade7b1d27a3c17b98d50e9d77574ad272bac130e5436eed9bef095cc98f32f7","schema_fingerprint":"4aa3821a28b0b7c2400bc59aba4bcc0a76e971dadd19610d3ad38c768e124dc7","schema_version":"edge-lab-recorder.raw.v1","sequence":null,"source":"clob_market_ws"}
{"event_at":"2026-07-28T04:00:25.811000Z","event_fingerprint":"c9e196bc46509156637fa3ccea12d3db6bb83ac822ba4e89247f33e0e376ba27","payload":{"connection_id":"f6725804f86a4c4eb588e4d5ed7db029","event_at":"2026-07-28T04:00:25.811000Z","event_type":"price_change","frame_hash":"1b5e81f6d7f156c8c9d8df83e035436a9dcb8b37a7620e70e8d7d2e64570e97e","frame_index":0,"kind":"data","monotonic_ns":313212026770375,"payload":{"event_type":"price_change","market":"0xd412ce774cfcf8dc9f71164aac78783978aac7b03871702a3b8a481bd9dc9688","price_changes":[{"asset_id":"96600821790790307414914106093858868634329285205417149685270682748367152458577","best_ask":"0.56","best_bid":"0.55","hash":"d8bcb0c6bfd3a2fef04b61bdad34fd161f1f5ac3","price":"0.54","side":"BUY","size":"11.64"},{"asset_id":"107603864457683460275633293642179940881969192120168665300712204232021063124301","best_ask":"0.45","best_bid":"0.44","hash":"911b29412e2ba8422f5f004e3e02abe1d213a799","price":"0.46","side":"SELL","size":"11.64"}],"timestamp":"1785211225811"},"payload_hash":"f5394e6ceddc119a21702a13dc1f582ec9964e253c7161f97108dbda69ffedca","raw_frame":"{\"market\":\"0xd412ce774cfcf8dc9f71164aac78783978aac7b03871702a3b8a481bd9dc9688\", \"price_changes\":[{\"asset_id\":\"96600821790790307414914106093858868634329285205417149685270682748367152458577\", \"price\":\"0.54\", \"size\":\"11.64\", \"side\":\"BUY\", \"hash\":\"d8bcb0c6bfd3a2fef04b61bdad34fd161f1f5ac3\", \"best_bid\":\"0.55\", \"best_ask\":\"0.56\"}, {\"asset_id\":\"107603864457683460275633293642179940881969192120168665300712204232021063124301\", \"price\":\"0.46\", \"size\":\"11.64\", \"side\":\"SELL\", \"hash\":\"911b29412e2ba8422f5f004e3e02abe1d213a799\", \"best_bid\":\"0.44\", \"best_ask\":\"0.45\"}], \"timestamp\":\"1785211225811\", \"event_type\":\"price_change\"}","received_at":"2026-07-28T04:00:28.978647Z","schema_version":"clob-market-ws.price_change.v1","sequence":null,"server_hash":null,"server_timestamp":"1785211225811","session_id":"2d607381e3054cee91998cdf45a4231c","source":"clob_market_ws"},"received_at":"2026-07-28T04:00:28.978647Z","record_id":"22311d14b762053cdc973374914003715965bed4c5c240fc4888efe82d54d691","schema_fingerprint":"4aa3821a28b0b7c2400bc59aba4bcc0a76e971dadd19610d3ad38c768e124dc7","schema_version":"edge-lab-recorder.raw.v1","sequence":null,"source":"clob_market_ws"}
{"event_at":"2026-07-28T04:00:25.811000Z","event_fingerprint":"6fe6ebd3addf84ab0954055216116351982364f85197f4467e77353b1eb76d5d","payload":{"connection_id":"f6725804f86a4c4eb588e4d5ed7db029","event_at":"2026-07-28T04:00:25.811000Z","event_type":"price_change","frame_hash":"7e35c389605b7c4704355880ae51859a24d3ed90fb278e79a59628f71333bcd9","frame_index":0,"kind":"data","monotonic_ns":313212033782041,"payload":{"event_type":"price_change","market":"0xd412ce774cfcf8dc9f71164aac78783978aac7b03871702a3b8a481bd9dc9688","price_changes":[{"asset_id":"96600821790790307414914106093858868634329285205417149685270682748367152458577","best_ask":"0.56","best_bid":"0.55","hash":"d8bcb0c6bfd3a2fef04b61bdad34fd161f1f5ac3","price":"0.55","side":"BUY","size":"102.64"},{"asset_id":"107603864457683460275633293642179940881969192120168665300712204232021063124301","best_ask":"0.45","best_bid":"0.44","hash":"911b29412e2ba8422f5f004e3e02abe1d213a799","price":"0.45","side":"SELL","size":"102.64"}],"timestamp":"1785211225811"},"payload_hash":"464b967dfc8b0648e0fc1979784d5b905b0d3790f469de62286072f522c8991e","raw_frame":"{\"market\":\"0xd412ce774cfcf8dc9f71164aac78783978aac7b03871702a3b8a481bd9dc9688\", \"price_changes\":[{\"asset_id\":\"96600821790790307414914106093858868634329285205417149685270682748367152458577\", \"price\":\"0.55\", \"size\":\"102.64\", \"side\":\"BUY\", \"hash\":\"d8bcb0c6bfd3a2fef04b61bdad34fd161f1f5ac3\", \"best_bid\":\"0.55\", \"best_ask\":\"0.56\"}, {\"asset_id\":\"107603864457683460275633293642179940881969192120168665300712204232021063124301\", \"price\":\"0.45\", \"size\":\"102.64\", \"side\":\"SELL\", \"hash\":\"911b29412e2ba8422f5f004e3e02abe1d213a799\", \"best_bid\":\"0.44\", \"best_ask\":\"0.45\"}], \"timestamp\":\"1785211225811\", \"event_type\":\"price_change\"}","received_at":"2026-07-28T04:00:28.985658Z","schema_version":"clob-market-ws.price_change.v1","sequence":null,"server_hash":null,"server_timestamp":"1785211225811","session_id":"2d607381e3054cee91998cdf45a4231c","source":"clob_market_ws"},"received_at":"2026-07-28T04:00:28.985658Z","record_id":"cc8bc31133b2d9fdcb0301fe5e39e16e5f50de5c09ac985f8ecaf9f0a8f890ad","schema_fingerprint":"4aa3821a28b0b7c2400bc59aba4bcc0a76e971dadd19610d3ad38c768e124dc7","schema_version":"edge-lab-recorder.raw.v1","sequence":null,"source":"clob_market_ws"}
{"event_at":"2026-07-28T04:00:25.812000Z","event_fingerprint":"1a6a1f71f3b0e59f8e2bb7691b8dc8c81a922fb8b3a92e7982dc50ffffdfe58e","payload":{"connection_id":"f6725804f86a4c4eb588e4d5ed7db029","event_at":"2026-07-28T04:00:25.812000Z","event_type":"price_change","frame_hash":"ecdc60a9f8090c736e574b9c5ee71791ba981fd92db59f1a157805f04ac28b77","frame_index":0,"kind":"data","monotonic_ns":313212041429208,"payload":{"event_type":"price_change","market":"0xd412ce774cfcf8dc9f71164aac78783978aac7b03871702a3b8a481bd9dc9688","price_changes":[{"asset_id":"107603864457683460275633293642179940881969192120168665300712204232021063124301","best_ask":"0.45","best_bid":"0.44","hash":"732559d1f1fdfa7283d1e48435c8da4d515ba2e2","price":"0.42","side":"BUY","size":"110.27"},{"asset_id":"96600821790790307414914106093858868634329285205417149685270682748367152458577","best_ask":"0.56","best_bid":"0.55","hash":"5bf37310e4771fa8f04700f8bee633f8c4d76d72","price":"0.58","side":"SELL","size":"110.27"}],"timestamp":"1785211225812"},"payload_hash":"ee9c7fd779cfbe439cb13c263886b5a963817386279731a49d08a20d3b44162a","raw_frame":"{\"market\":\"0xd412ce774cfcf8dc9f71164aac78783978aac7b03871702a3b8a481bd9dc9688\", \"price_changes\":[{\"asset_id\":\"107603864457683460275633293642179940881969192120168665300712204232021063124301\", \"price\":\"0.42\", \"size\":\"110.27\", \"side\":\"BUY\", \"hash\":\"732559d1f1fdfa7283d1e48435c8da4d515ba2e2\", \"best_bid\":\"0.44\", \"best_ask\":\"0.45\"}, {\"asset_id\":\"96600821790790307414914106093858868634329285205417149685270682748367152458577\", \"price\":\"0.58\", \"size\":\"110.27\", \"side\":\"SELL\", \"hash\":\"5bf37310e4771fa8f04700f8bee633f8c4d76d72\", \"best_bid\":\"0.55\", \"best_ask\":\"0.56\"}], \"timestamp\":\"1785211225812\", \"event_type\":\"price_change\"}","received_at":"2026-07-28T04:00:28.993305Z","schema_version":"clob-market-ws.price_change.v1","sequence":null,"server_hash":null,"server_timestamp":"1785211225812","session_id":"2d607381e3054cee91998cdf45a4231c","source":"clob_market_ws"},"received_at":"2026-07-28T04:00:28.993305Z","record_id":"12b5b092e25dcc5a1eaf0d851563578acc0a7880aafc21bf571705d6727c3aac","schema_fingerprint":"4aa3821a28b0b7c2400bc59aba4bcc0a76e971dadd19610d3ad38c768e124dc7","schema_version":"edge-lab-recorder.raw.v1","sequence":null,"source":"clob_market_ws"}
{"event_at":"2026-07-28T04:00:25.813000Z","event_fingerprint":"93c237702e83b7402a60b394df0b7a99ad67df81856070bfd30d3c6dda763d28","payload":{"connection_id":"f6725804f86a4c4eb588e4d5ed7db029","event_at":"2026-07-28T04:00:25.813000Z","event_type":"price_change","frame_hash":"3bd7333b9c3df79ca7561e550f30a2c84f5531c790eaf435f5097e53f506320f","frame_index":0,"kind":"data","monotonic_ns":313212048618916,"payload":{"event_type":"price_change","market":"0xd412ce774cfcf8dc9f71164aac78783978aac7b03871702a3b8a481bd9dc9688","price_changes":[{"asset_id":"96600821790790307414914106093858868634329285205417149685270682748367152458577","best_ask":"0.56","best_bid":"0.55","hash":"49eb89fc462ffc4e1667900d0866836002a97983","price":"0.54","side":"BUY","size":"6"},{"asset_id":"107603864457683460275633293642179940881969192120168665300712204232021063124301","best_ask":"0.45","best_bid":"0.44","hash":"ecafa0fe944bcf51fc01b9b8a68e028e3931c486","price":"0.46","side":"SELL","size":"6"}],"timestamp":"1785211225813"},"payload_hash":"227b111719b8dd2ad9f58bd0e819f5adde1003cce4d8f655dac2f88737e64494","raw_frame":"{\"market\":\"0xd412ce774cfcf8dc9f71164aac78783978aac7b03871702a3b8a481bd9dc9688\", \"price_changes\":[{\"asset_id\":\"96600821790790307414914106093858868634329285205417149685270682748367152458577\", \"price\":\"0.54\", \"size\":\"6\", \"side\":\"BUY\", \"hash\":\"49eb89fc462ffc4e1667900d0866836002a97983\", \"best_bid\":\"0.55\", \"best_ask\":\"0.56\"}, {\"asset_id\":\"107603864457683460275633293642179940881969192120168665300712204232021063124301\", \"price\":\"0.46\", \"size\":\"6\", \"side\":\"SELL\", \"hash\":\"ecafa0fe944bcf51fc01b9b8a68e028e3931c486\", \"best_bid\":\"0.44\", \"best_ask\":\"0.45\"}], \"timestamp\":\"1785211225813\", \"event_type\":\"price_change\"}","received_at":"2026-07-28T04:00:29.000496Z","schema_version":"clob-market-ws.price_change.v1","sequence":null,"server_hash":null,"server_timestamp":"1785211225813","session_id":"2d607381e3054cee91998cdf45a4231c","source":"clob_market_ws"},"received_at":"2026-07-28T04:00:29.000496Z","record_id":"93e104de76e0360e5bc9c2239c46db9a26044dbaf4743d710572731647b850ee","schema_fingerprint":"4aa3821a28b0b7c2400bc59aba4bcc0a76e971dadd19610d3ad38c768e124dc7","schema_version":"edge-lab-recorder.raw.v1","sequence":null,"source":"clob_market_ws"}
{"event_at":"2026-07-28T04:00:25.813000Z","event_fingerprint":"9c158b5082bb80ca915d7b8d1f41197a4fadc815447ec280ca6593604017c7c7","payload":{"connection_id":"f6725804f86a4c4eb588e4d5ed7db029","event_at":"2026-07-28T04:00:25.813000Z","event_type":"price_change","frame_hash":"f45e42ffad857baa8b31ab143869fa93098d40fcf05e2e6c283fecefd7b5eb1e","frame_index":0,"kind":"data","monotonic_ns":313212060401125,"payload":{"event_type":"price_change","market":"0xd412ce774cfcf8dc9f71164aac78783978aac7b03871702a3b8a481bd9dc9688","price_changes":[{"asset_id":"96600821790790307414914106093858868634329285205417149685270682748367152458577","best_ask":"0.56","best_bid":"0.55","hash":"49eb89fc462ffc4e1667900d0866836002a97983","price":"0.55","side":"BUY","size":"97"},{"asset_id":"107603864457683460275633293642179940881969192120168665300712204232021063124301","best_ask":"0.45","best_bid":"0.44","hash":"ecafa0fe944bcf51fc01b9b8a68e028e3931c486","price":"0.45","side":"SELL","size":"97"}],"timestamp":"1785211225813"},"payload_hash":"c966693484c42cb62ec23227f1ab7532fec1ad025f66b8bb9a552d5fa6bdc660","raw_frame":"{\"market\":\"0xd412ce774cfcf8dc9f71164aac78783978aac7b03871702a3b8a481bd9dc9688\", \"price_changes\":[{\"asset_id\":\"96600821790790307414914106093858868634329285205417149685270682748367152458577\", \"price\":\"0.55\", \"size\":\"97\", \"side\":\"BUY\", \"hash\":\"49eb89fc462ffc4e1667900d0866836002a97983\", \"best_bid\":\"0.55\", \"best_ask\":\"0.56\"}, {\"asset_id\":\"107603864457683460275633293642179940881969192120168665300712204232021063124301\", \"price\":\"0.45\", \"size\":\"97\", \"side\":\"SELL\", \"hash\":\"ecafa0fe944bcf51fc01b9b8a68e028e3931c486\", \"best_bid\":\"0.44\", \"best_ask\":\"0.45\"}], \"timestamp\":\"1785211225813\", \"event_type\":\"price_change\"}","received_at":"2026-07-28T04:00:29.012277Z","schema_version":"clob-market-ws.price_change.v1","sequence":null,"server_hash":null,"server_timestamp":"1785211225813","session_id":"2d607381e3054cee91998cdf45a4231c","source":"clob_market_ws"},"received_at":"2026-07-28T04:00:29.012277Z","record_id":"521facf076c1766e210ca5f0b1df5015dd570ae98718dcbb16555b75c9e3fa78","schema_fingerprint":"4aa3821a28b0b7c2400bc59aba4bcc0a76e971dadd19610d3ad38c768e124dc7","schema_version":"edge-lab-recorder.raw.v1","sequence":null,"source":"clob_market_ws"}
{"event_at":"2026-07-28T04:00:25.813000Z","event_fingerprint":"c28b3c89eb32eea2f5ed5daaa310974d458a0c2db77086e112d5c4eb38f4b896","payload":{"connection_id":"f6725804f86a4c4eb588e4d5ed7db029","event_at":"2026-07-28T04:00:25.813000Z","event_type":"price_change","frame_hash":"cd1f1c1556c9d5a9f157878b702f7bd5631d1a3da34b46f833dd7c28282734e6","frame_index":0,"kind":"data","monotonic_ns":313212065848666,"payload":{"event_type":"price_change","market":"0xd412ce774cfcf8dc9f71164aac78783978aac7b03871702a3b8a481bd9dc9688","price_changes":[{"asset_id":"107603864457683460275633293642179940881969192120168665300712204232021063124301","best_ask":"0.45","best_bid":"0.44","hash":"4637d0c947d27efa108f1078ea7339ceba88c18a","price":"0.44","side":"BUY","size":"90.2"},{"asset_id":"96600821790790307414914106093858868634329285205417149685270682748367152458577","best_ask":"0.56","best_bid":"0.55","hash":"b82bb17a571565ab5543ccc1c5a382f6ad1e1e46","price":"0.56","side":"SELL","size":"90.2"}],"timestamp":"1785211225813"},"payload_hash":"75893821ea79727e6c0262c112a3f9641fb6bde6148a25b4cf6b370df293a77d","raw_frame":"{\"market\":\"0xd412ce774cfcf8dc9f71164aac78783978aac7b03871702a3b8a481bd9dc9688\", \"price_changes\":[{\"asset_id\":\"107603864457683460275633293642179940881969192120168665300712204232021063124301\", \"price\":\"0.44\", \"size\":\"90.2\", \"side\":\"BUY\", \"hash\":\"4637d0c947d27efa108f1078ea7339ceba88c18a\", \"best_bid\":\"0.44\", \"best_ask\":\"0.45\"}, {\"asset_id\":\"96600821790790307414914106093858868634329285205417149685270682748367152458577\", \"price\":\"0.56\", \"size\":\"90.2\", \"side\":\"SELL\", \"hash\":\"b82bb17a571565ab5543ccc1c5a382f6ad1e1e46\", \"best_bid\":\"0.55\", \"best_ask\":\"0.56\"}], \"timestamp\":\"1785211225813\", \"event_type\":\"price_change\"}","received_at":"2026-07-28T04:00:29.017720Z","schema_version":"clob-market-ws.price_change.v1","sequence":null,"server_hash":null,"server_timestamp":"1785211225813","session_id":"2d607381e3054cee91998cdf45a4231c","source":"clob_market_ws"},"received_at":"2026-07-28T04:00:29.017720Z","record_id":"078aaab23bf92dafc2acfe41934add354a053ff39a2262e19a2f626ada78a790","schema_fingerprint":"4aa3821a28b0b7c2400bc59aba4bcc0a76e971dadd19610d3ad38c768e124dc7","schema_version":"edge-lab-recorder.raw.v1","sequence":null,"source":"clob_market_ws"}
{"event_at":"2026-07-28T04:00:25.815000Z","event_fingerprint":"d27eaa27a705634ed25217b6bcfcb9863a1ea7d40fbe9bf768f1ed4d2f03d574","payload":{"connection_id":"f6725804f86a4c4eb588e4d5ed7db029","event_at":"2026-07-28T04:00:25.815000Z","event_type":"price_change","frame_hash":"afa743efe1d4d85d516de7e596c879b7f4d299e21b78b89e56fb9a65f6047853","frame_index":0,"kind":"data","monotonic_ns":313212072569583,"payload":{"event_type":"price_change","market":"0xd412ce774cfcf8dc9f71164aac78783978aac7b03871702a3b8a481bd9dc9688","price_changes":[{"asset_id":"107603864457683460275633293642179940881969192120168665300712204232021063124301","best_ask":"0.45","best_bid":"0.44","hash":"96b4167c80ea1afdfb0f82f54665688d0fd3b569","price":"0.39","side":"BUY","size":"123.52"},{"asset_id":"96600821790790307414914106093858868634329285205417149685270682748367152458577","best_ask":"0.56","best_bid":"0.55","hash":"d8295ee7015c8466f5df69c731c0bde7c1ff4f37","price":"0.61","side":"SELL","size":"123.52"}],"timestamp":"1785211225815"},"payload_hash":"ea872f4a475ab00fbace29bef8781fb41f2d77bdb9c587cfebb2b2dcbfa9a307","raw_frame":"{\"market\":\"0xd412ce774cfcf8dc9f71164aac78783978aac7b03871702a3b8a481bd9dc9688\", \"price_changes\":[{\"asset_id\":\"107603864457683460275633293642179940881969192120168665300712204232021063124301\", \"price\":\"0.39\", \"size\":\"123.52\", \"side\":\"BUY\", \"hash\":\"96b4167c80ea1afdfb0f82f54665688d0fd3b569\", \"best_bid\":\"0.44\", \"best_ask\":\"0.45\"}, {\"asset_id\":\"96600821790790307414914106093858868634329285205417149685270682748367152458577\", \"price\":\"0.61\", \"size\":\"123.52\", \"side\":\"SELL\", \"hash\":\"d8295ee7015c8466f5df69c731c0bde7c1ff4f37\", \"best_bid\":\"0.55\", \"best_ask\":\"0.56\"}], \"timestamp\":\"1785211225815\", \"event_type\":\"price_change\"}","received_at":"2026-07-28T04:00:29.024446Z","schema_version":"clob-market-ws.price_change.v1","sequence":null,"server_hash":null,"server_timestamp":"1785211225815","session_id":"2d607381e3054cee91998cdf45a4231c","source":"clob_market_ws"},"received_at":"2026-07-28T04:00:29.024446Z","record_id":"c9eaed2c680068e54e4a513066ec05873c4c003aa9692a34b7f879b83d7b7891","schema_fingerprint":"4aa3821a28b0b7c2400bc59aba4bcc0a76e971dadd19610d3ad38c768e124dc7","schema_version":"edge-lab-recorder.raw.v1","sequence":null,"source":"clob_market_ws"}
{"event_at":"2026-07-28T04:00:25.818000Z","event_fingerprint":"d4fe9f75e1e8d4e6d80033638af50cb25d0c90fedebee1734471d43008dc32db","payload":{"connection_id":"f6725804f86a4c4eb588e4d5ed7db029","event_at":"2026-07-28T04:00:25.818000Z","event_type":"price_change","frame_hash":"f632f24fcf1d781c4cb40f93185eb9809a97e63c5777409aca9e0917f1f06a01","frame_index":0,"kind":"data","monotonic_ns":313212077317291,"payload":{"event_type":"price_change","market":"0xd412ce774cfcf8dc9f71164aac78783978aac7b03871702a3b8a481bd9dc9688","price_changes":[{"asset_id":"96600821790790307414914106093858868634329285205417149685270682748367152458577","best_ask":"0.56","best_bid":"0.55","hash":"af9a70ff79c2f48969b6b59358ba5c429a664e13","price":"0.55","side":"BUY","size":"73"},{"asset_id":"107603864457683460275633293642179940881969192120168665300712204232021063124301","best_ask":"0.45","best_bid":"0.44","hash":"29db26e9fccc5a9ac1556238a7302a157a2fa672","price":"0.45","side":"SELL","size":"73"}],"timestamp":"1785211225818"},"payload_hash":"ebde38aabe6f93a2f50a7b0e251e76f02e5100400d2e6739b56ee48b3cf0f743","raw_frame":"{\"market\":\"0xd412ce774cfcf8dc9f71164aac78783978aac7b03871702a3b8a481bd9dc9688\", \"price_changes\":[{\"asset_id\":\"96600821790790307414914106093858868634329285205417149685270682748367152458577\", \"price\":\"0.55\", \"size\":\"73\", \"side\":\"BUY\", \"hash\":\"af9a70ff79c2f48969b6b59358ba5c429a664e13\", \"best_bid\":\"0.55\", \"best_ask\":\"0.56\"}, {\"asset_id\":\"107603864457683460275633293642179940881969192120168665300712204232021063124301\", \"price\":\"0.45\", \"size\":\"73\", \"side\":\"SELL\", \"hash\":\"29db26e9fccc5a9ac1556238a7302a157a2fa672\", \"best_bid\":\"0.44\", \"best_ask\":\"0.45\"}], \"timestamp\":\"1785211225818\", \"event_type\":\"price_change\"}","received_at":"2026-07-28T04:00:29.029193Z","schema_version":"clob-market-ws.price_change.v1","sequence":null,"server_hash":null,"server_timestamp":"1785211225818","session_id":"2d607381e3054cee91998cdf45a4231c","source":"clob_market_ws"},"received_at":"2026-07-28T04:00:29.029193Z","record_id":"db04c01bb37ce007169fa88e8309cfb4eccfa77eccd6562c9b8ad3c9755be91b","schema_fingerprint":"4aa3821a28b0b7c2400bc59aba4bcc0a76e971dadd19610d3ad38c768e124dc7","schema_version":"edge-lab-recorder.raw.v1","sequence":null,"source":"clob_market_ws"}
{"event_at":"2026-07-28T04:00:25.818000Z","event_fingerprint":"5a4e3232b608fd4efc7417565e8ef9d449895a83de958343899f6fb338ab1c15","payload":{"connection_id":"f6725804f86a4c4eb588e4d5ed7db029","event_at":"2026-07-28T04:00:25.818000Z","event_type":"price_change","frame_hash":"677318f421442bcf0eb4cc7b246ab4d4523e21dd51f0399f4a5d8db75f3eacdc","frame_index":0,"kind":"data","monotonic_ns":313212082767500,"payload":{"event_type":"price_change","market":"0xd412ce774cfcf8dc9f71164aac78783978aac7b03871702a3b8a481bd9dc9688","price_changes":[{"asset_id":"96600821790790307414914106093858868634329285205417149685270682748367152458577","best_ask":"0.56","best_bid":"0.55","hash":"f654a70be03aed082337a2fe1f105213b2993ec7","price":"0.55","side":"BUY","size":"68"},{"asset_id":"107603864457683460275633293642179940881969192120168665300712204232021063124301","best_ask":"0.45","best_bid":"0.44","hash":"cdb1bfd721d9e10a4a51b2a51a1c66278a1c3a60","price":"0.45","side":"SELL","size":"68"}],"timestamp":"1785211225818"},"payload_hash":"c505578f0de048d2d1f2fcfbf9d312e6c4dec9a3938b277492dd8feea470595e","raw_frame":"{\"market\":\"0xd412ce774cfcf8dc9f71164aac78783978aac7b03871702a3b8a481bd9dc9688\", \"price_changes\":[{\"asset_id\":\"96600821790790307414914106093858868634329285205417149685270682748367152458577\", \"price\":\"0.55\", \"size\":\"68\", \"side\":\"BUY\", \"hash\":\"f654a70be03aed082337a2fe1f105213b2993ec7\", \"best_bid\":\"0.55\", \"best_ask\":\"0.56\"}, {\"asset_id\":\"107603864457683460275633293642179940881969192120168665300712204232021063124301\", \"price\":\"0.45\", \"size\":\"68\", \"side\":\"SELL\", \"hash\":\"cdb1bfd721d9e10a4a51b2a51a1c66278a1c3a60\", \"best_bid\":\"0.44\", \"best_ask\":\"0.45\"}], \"timestamp\":\"1785211225818\", \"event_type\":\"price_change\"}","received_at":"2026-07-28T04:00:29.034643Z","schema_version":"clob-market-ws.price_change.v1","sequence":null,"server_hash":null,"server_timestamp":"1785211225818","session_id":"2d607381e3054cee91998cdf45a4231c","source":"clob_market_ws"},"received_at":"2026-07-28T04:00:29.034643Z","record_id":"d0e0cb72c5da42ccd1f871a91982f7faa1f50d4db46854891a3c966570c376ef","schema_fingerprint":"4aa3821a28b0b7c2400bc59aba4bcc0a76e971dadd19610d3ad38c768e124dc7","schema_version":"edge-lab-recorder.raw.v1","sequence":null,"source":"clob_market_ws"}
{"event_at":"2026-07-28T04:00:25.821000Z","event_fingerprint":"a480945c356cb6738d76442969c3dfa95e3cde2b173d053e3c9f69b30fb2f846","payload":{"connection_id":"f6725804f86a4c4eb588e4d5ed7db029","event_at":"2026-07-28T04:00:25.821000Z","event_type":"price_change","frame_hash":"299c0649e16952e57d2216972066aca1462f3f3626e05dd3206598a16ec502e8","frame_index":0,"kind":"data","monotonic_ns":313212088834833,"payload":{"event_type":"price_change","market":"0xd412ce774cfcf8dc9f71164aac78783978aac7b03871702a3b8a481bd9dc9688","price_changes":[{"asset_id":"96600821790790307414914106093858868634329285205417149685270682748367152458577","best_ask":"0.56","best_bid":"0.55","hash":"727acdcf3e2d0a9ebbddbc0aa356a4c8da2bde16","price":"0.53","side":"BUY","size":"13"},{"asset_id":"107603864457683460275633293642179940881969192120168665300712204232021063124301","best_ask":"0.45","best_bid":"0.44","hash":"94038dddb0be032c1dc3f149a9fd43db62a672c2","price":"0.47","side":"SELL","size":"13"}],"timestamp":"1785211225821"},"payload_hash":"a0922ca15d14b631197440a0f3174fb2dca8698078cd9c06702f07896bf1d637","raw_frame":"{\"market\":\"0xd412ce774cfcf8dc9f71164aac78783978aac7b03871702a3b8a481bd9dc9688\", \"price_changes\":[{\"asset_id\":\"96600821790790307414914106093858868634329285205417149685270682748367152458577\", \"price\":\"0.53\", \"size\":\"13\", \"side\":\"BUY\", \"hash\":\"727acdcf3e2d0a9ebbddbc0aa356a4c8da2bde16\", \"best_bid\":\"0.55\", \"best_ask\":\"0.56\"}, {\"asset_id\":\"107603864457683460275633293642179940881969192120168665300712204232021063124301\", \"price\":\"0.47\", \"size\":\"13\", \"side\":\"SELL\", \"hash\":\"94038dddb0be032c1dc3f149a9fd43db62a672c2\", \"best_bid\":\"0.44\", \"best_ask\":\"0.45\"}], \"timestamp\":\"1785211225821\", \"event_type\":\"price_change\"}","received_at":"2026-07-28T04:00:29.040711Z","schema_version":"clob-market-ws.price_change.v1","sequence":null,"server_hash":null,"server_timestamp":"1785211225821","session_id":"2d607381e3054cee91998cdf45a4231c","source":"clob_market_ws"},"received_at":"2026-07-28T04:00:29.040711Z","record_id":"82ce4686d1c0f6b77921059363801644e91683d85e07ee5ed4fc44f7d64e0294","schema_fingerprint":"4aa3821a28b0b7c2400bc59aba4bcc0a76e971dadd19610d3ad38c768e124dc7","schema_version":"edge-lab-recorder.raw.v1","sequence":null,"source":"clob_market_ws"}
{"event_at":"2026-07-28T04:00:25.821000Z","event_fingerprint":"36dbfe6e726677e20a27c6fe6ed190ea5ab3515c3f8ccce24ba2797e4c1a963e","payload":{"connection_id":"f6725804f86a4c4eb588e4d5ed7db029","event_at":"2026-07-28T04:00:25.821000Z","event_type":"price_change","frame_hash":"82f02358805c08c9a8b277298b12b9dd11adef0abe6314255948f4f22ee40cb6","frame_index":0,"kind":"data","monotonic_ns":313212094365875,"payload":{"event_type":"price_change","market":"0xd412ce774cfcf8dc9f71164aac78783978aac7b03871702a3b8a481bd9dc9688","price_changes":[{"asset_id":"96600821790790307414914106093858868634329285205417149685270682748367152458577","best_ask":"0.56","best_bid":"0.55","hash":"21fcb785a1158bef8e5e23b43a9c994bb6410d15","price":"0.55","side":"BUY","size":"46"},{"asset_id":"107603864457683460275633293642179940881969192120168665300712204232021063124301","best_ask":"0.45","best_bid":"0.44","hash":"f33de033582de34005bc6378506800639ad4cf08","price":"0.45","side":"SELL","size":"46"}],"timestamp":"1785211225821"},"payload_hash":"4be0d1305443f1c500a75d677ba74bf6942f072cd90e436f9cb762984465feb5","raw_frame":"{\"market\":\"0xd412ce774cfcf8dc9f71164aac78783978aac7b03871702a3b8a481bd9dc9688\", \"price_changes\":[{\"asset_id\":\"96600821790790307414914106093858868634329285205417149685270682748367152458577\", \"price\":\"0.55\", \"size\":\"46\", \"side\":\"BUY\", \"hash\":\"21fcb785a1158bef8e5e23b43a9c994bb6410d15\", \"best_bid\":\"0.55\", \"best_ask\":\"0.56\"}, {\"asset_id\":\"107603864457683460275633293642179940881969192120168665300712204232021063124301\", \"price\":\"0.45\", \"size\":\"46\", \"side\":\"SELL\", \"hash\":\"f33de033582de34005bc6378506800639ad4cf08\", \"best_bid\":\"0.44\", \"best_ask\":\"0.45\"}], \"timestamp\":\"1785211225821\", \"event_type\":\"price_change\"}","received_at":"2026-07-28T04:00:29.046241Z","schema_version":"clob-market-ws.price_change.v1","sequence":null,"server_hash":null,"server_timestamp":"1785211225821","session_id":"2d607381e3054cee91998cdf45a4231c","source":"clob_market_ws"},"received_at":"2026-07-28T04:00:29.046241Z","record_id":"7475c38eda8486ad227802ca5f0d2bb247997afa8ad1ca1ab2f1c027300c1224","schema_fingerprint":"4aa3821a28b0b7c2400bc59aba4bcc0a76e971dadd19610d3ad38c768e124dc7","schema_version":"edge-lab-recorder.raw.v1","sequence":null,"source":"clob_market_ws"}
{"event_at":"2026-07-28T04:00:25.821000Z","event_fingerprint":"0d69aa22f5f0d4b206681acff7d86893a25bd4552ccf53f7f31a68a9ebdbbe6c","payload":{"connection_id":"f6725804f86a4c4eb588e4d5ed7db029","event_at":"2026-07-28T04:00:25.821000Z","event_type":"price_change","frame_hash":"e505875c2f4376358919e4c794267efa9c334df394ff3886ac23e52ec38a26f4","frame_index":0,"kind":"data","monotonic_ns":313212102109750,"payload":{"event_type":"price_change","market":"0xd412ce774cfcf8dc9f71164aac78783978aac7b03871702a3b8a481bd9dc9688","price_changes":[{"asset_id":"96600821790790307414914106093858868634329285205417149685270682748367152458577","best_ask":"0.56","best_bid":"0.55","hash":"c9a1485d4df37204e3e0bfb230c84717bc329f40","price":"0.55","side":"BUY","size":"6"},{"asset_id":"107603864457683460275633293642179940881969192120168665300712204232021063124301","best_ask":"0.45","best_bid":"0.44","hash":"6ebd15837115c4223d7fb944b6854808b4e9e2fc","price":"0.45","side":"SELL","size":"6"}],"timestamp":"1785211225821"},"payload_hash":"2aca1ebd6bc1b82ed0b219d338b95f3afa0ff229361dd550b5a2dabab3b4e443","raw_frame":"{\"market\":\"0xd412ce774cfcf8dc9f71164aac78783978aac7b03871702a3b8a481bd9dc9688\", \"price_changes\":[{\"asset_id\":\"96600821790790307414914106093858868634329285205417149685270682748367152458577\", \"price\":\"0.55\", \"size\":\"6\", \"side\":\"BUY\", \"hash\":\"c9a1485d4df37204e3e0bfb230c84717bc329f40\", \"best_bid\":\"0.55\", \"best_ask\":\"0.56\"}, {\"asset_id\":\"107603864457683460275633293642179940881969192120168665300712204232021063124301\", \"price\":\"0.45\", \"size\":\"6\", \"side\":\"SELL\", \"hash\":\"6ebd15837115c4223d7fb944b6854808b4e9e2fc\", \"best_bid\":\"0.44\", \"best_ask\":\"0.45\"}], \"timestamp\":\"1785211225821\", \"event_type\":\"price_change\"}","received_at":"2026-07-28T04:00:29.053986Z","schema_version":"clob-market-ws.price_change.v1","sequence":null,"server_hash":null,"server_timestamp":"1785211225821","session_id":"2d607381e3054cee91998cdf45a4231c","source":"clob_market_ws"},"received_at":"2026-07-28T04:00:29.053986Z","record_id":"525504fe71e4d7214b16d2cd2eada5d92f05974355fc954075e0860f1e2c5630","schema_fingerprint":"4aa3821a28b0b7c2400bc59aba4bcc0a76e971dadd19610d3ad38c768e124dc7","schema_version":"edge-lab-recorder.raw.v1","sequence":null,"source":"clob_market_ws"}
{"event_at":"2026-07-28T04:00:25.822000Z","event_fingerprint":"f4e6c0c37c68e11d9e71551e825d6558e7d295e7a41f376fdb5b81300d361b12","payload":{"connection_id":"f6725804f86a4c4eb588e4d5ed7db029","event_at":"2026-07-28T04:00:25.822000Z","event_type":"price_change","frame_hash":"3bcb6ed3ac8f487073c96dded4987fdb2b0a8a10931c764b17a4dea3c466469d","frame_index":0,"kind":"data","monotonic_ns":313212116539791,"payload":{"event_type":"price_change","market":"0xd412ce774cfcf8dc9f71164aac78783978aac7b03871702a3b8a481bd9dc9688","price_changes":[{"asset_id":"96600821790790307414914106093858868634329285205417149685270682748367152458577","best_ask":"0.56","best_bid":"0.55","hash":"8e1721fc23678cc7ea391f3dcf591dfe22d6e847","price":"0.53","side":"BUY","size":"0"},{"asset_id":"107603864457683460275633293642179940881969192120168665300712204232021063124301","best_ask":"0.45","best_bid":"0.44","hash":"0b502f117c8646a6c3a57e40f2e0700039bb0af2","price":"0.47","side":"SELL","size":"0"}],"timestamp":"1785211225822"},"payload_hash":"2cdbe2b65be560f5b2e4b839c98b43fef316fa08f1565d979ada57c54da9345c","raw_frame":"{\"market\":\"0xd412ce774cfcf8dc9f71164aac78783978aac7b03871702a3b8a481bd9dc9688\", \"price_changes\":[{\"asset_id\":\"96600821790790307414914106093858868634329285205417149685270682748367152458577\", \"price\":\"0.53\", \"size\":\"0\", \"side\":\"BUY\", \"hash\":\"8e1721fc23678cc7ea391f3dcf591dfe22d6e847\", \"best_bid\":\"0.55\", \"best_ask\":\"0.56\"}, {\"asset_id\":\"107603864457683460275633293642179940881969192120168665300712204232021063124301\", \"price\":\"0.47\", \"size\":\"0\", \"side\":\"SELL\", \"hash\":\"0b502f117c8646a6c3a57e40f2e0700039bb0af2\", \"best_bid\":\"0.44\", \"best_ask\":\"0.45\"}], \"timestamp\":\"1785211225822\", \"event_type\":\"price_change\"}","received_at":"2026-07-28T04:00:29.068416Z","schema_version":"clob-market-ws.price_change.v1","sequence":null,"server_hash":null,"server_timestamp":"1785211225822","session_id":"2d607381e3054cee91998cdf45a4231c","source":"clob_market_ws"},"received_at":"2026-07-28T04:00:29.068416Z","record_id":"66302ecb1c4d3db44f7f8ab9ffcd18e0295498ea9a64cccae15138dea226f628","schema_fingerprint":"4aa3821a28b0b7c2400bc59aba4bcc0a76e971dadd19610d3ad38c768e124dc7","schema_version":"edge-lab-recorder.raw.v1","sequence":null,"source":"clob_market_ws"}
{"event_at":"2026-07-28T04:00:25.823000Z","event_fingerprint":"273daf1f49c42612b0ae7c0e5fe6e60639151dfaa6241b089d37d4609f9c7cfe","payload":{"connection_id":"f6725804f86a4c4eb588e4d5ed7db029","event_at":"2026-07-28T04:00:25.823000Z","event_type":"new_market","frame_hash":"79e425019aec0552dbea74b37e6dce5c7cf298d0d99b136f3694498ec56e6b16","frame_index":0,"kind":"data","monotonic_ns":313212123754291,"payload":{"active":false,"assets_ids":["79232279783522378407313330804515778669057246269718147160937070845112245315997","80842631769260170119314333692968159467060976703425140894972683091649912060566"],"clob_token_ids":["79232279783522378407313330804515778669057246269718147160937070845112245315997","80842631769260170119314333692968159467060976703425140894972683091649912060566"],"condition_id":"0x97f60aafa260d6f4c477d04fbb87e46a7097bf5a82d9eda8430d6ade6cb7f8a8","description":"This market refers to the tennis match between Eugenia Zozaya Menendez and Mariya Yemshanova in the ITF Women Kursumlijska Banja, originally scheduled for July 28, 2026 at 3:00AM ET.\n\nThis market will resolve to 'Eugenia Zozaya Menendez' if Eugenia Zozaya Menendez advances against Mariya Yemshanova.\n\nThis market will resolve to 'Mariya Yemshanova' if Mariya Yemshanova advances against Eugenia Zozaya Menendez.\n\nIf the match is canceled (not played at all), ends in a tie, or is delayed beyond 7 days from the scheduled date without a winner determined, this market will resolve to 50-50.\n\nIf the match begins but is not completed, and one player advances due to the opponent's retirement, default, or disqualification, this market will resolve to the player who advances.\n\nIf the match ends in a walkover (player withdraws before the start and the other advances automatically), this market will resolve to 50-50.\n\nThe primary resolution source will be official information from the International Tennis Federation (ITF). A consensus of credible reporting may also be used.","event_message":{"description":"This market refers to the tennis match between Eugenia Zozaya Menendez and Mariya Yemshanova in the ITF Women Kursumlijska Banja, originally scheduled for July 28, 2026 at 3:00AM ET.\n\nThis market will resolve to 'Eugenia Zozaya Menendez' if Eugenia Zozaya Menendez advances against Mariya Yemshanova.\n\nThis market will resolve to 'Mariya Yemshanova' if Mariya Yemshanova advances against Eugenia Zozaya Menendez.\n\nIf the match is canceled (not played at all), ends in a tie, or is delayed beyond 7 days from the scheduled date without a winner determined, this market will resolve to 50-50.\n\nIf the match begins but is not completed, and one player advances due to the opponent's retirement, default, or disqualification, this market will resolve to the player who advances.\n\nIf the match ends in a walkover (player withdraws before the start and the other advances automatically), this market will resolve to 50-50.\n\nThe primary resolution source will be official information from the International Tennis Federation (ITF). A consensus of credible reporting may also be used.","id":"759316","slug":"itf-menende-yemshan-2026-07-28","ticker":"itf-menende-yemshan-2026-07-28","title":"ITF Kursumlijska Banja: Eugenia Zozaya Menendez vs Mariya Yemshanova"},"event_type":"new_market","fee_schedule":{"exponent":"1","rate":"0.05","rebate_rate":"0.15","taker_only":true},"fees_enabled":true,"game_start_time":"2026-07-28 07:00:00+00","group_item_title":"","id":"3145718","line":"","market":"0x97f60aafa260d6f4c477d04fbb87e46a7097bf5a82d9eda8430d6ade6cb7f8a8","order_price_min_tick_size":"0.01","outcomes":["Eugenia Zozaya Menendez","Mariya Yemshanova"],"question":"ITF Kursumlijska Banja: Eugenia Zozaya Menendez vs Mariya Yemshanova","slug":"itf-menende-yemshan-2026-07-28","sports_market_type":"moneyline","tags":[],"taker_base_fee":"1000","timestamp":"1785211225823"},"payload_hash":"0f864f08d8eeaa900b00104e392cc7971aa884f82adebac5b361f2d297d49e59","raw_frame":"{\"id\":\"3145718\", \"question\":\"ITF Kursumlijska Banja: Eugenia Zozaya Menendez vs Mariya Yemshanova\", \"market\":\"0x97f60aafa260d6f4c477d04fbb87e46a7097bf5a82d9eda8430d6ade6cb7f8a8\", \"slug\":\"itf-menende-yemshan-2026-07-28\", \"description\":\"This market refers to the tennis match between Eugenia Zozaya Menendez and Mariya Yemshanova in the ITF Women Kursumlijska Banja, originally scheduled for July 28, 2026 at 3:00AM ET.\\n\\nThis market will resolve to 'Eugenia Zozaya Menendez' if Eugenia Zozaya Menendez advances against Mariya Yemshanova.\\n\\nThis market will resolve to 'Mariya Yemshanova' if Mariya Yemshanova advances against Eugenia Zozaya Menendez.\\n\\nIf the match is canceled (not played at all), ends in a tie, or is delayed beyond 7 days from the scheduled date without a winner determined, this market will resolve to 50-50.\\n\\nIf the match begins but is not completed, and one player advances due to the opponent's retirement, default, or disqualification, this market will resolve to the player who advances.\\n\\nIf the match ends in a walkover (player withdraws before the start and the other advances automatically), this market will resolve to 50-50.\\n\\nThe primary resolution source will be official information from the International Tennis Federation (ITF). A consensus of credible reporting may also be used.\", \"assets_ids\":[\"79232279783522378407313330804515778669057246269718147160937070845112245315997\", \"80842631769260170119314333692968159467060976703425140894972683091649912060566\"], \"outcomes\":[\"Eugenia Zozaya Menendez\", \"Mariya Yemshanova\"], \"event_message\":{\"id\":\"759316\", \"ticker\":\"itf-menende-yemshan-2026-07-28\", \"slug\":\"itf-menende-yemshan-2026-07-28\", \"title\":\"ITF Kursumlijska Banja: Eugenia Zozaya Menendez vs Mariya Yemshanova\", \"description\":\"This market refers to the tennis match between Eugenia Zozaya Menendez and Mariya Yemshanova in the ITF Women Kursumlijska Banja, originally scheduled for July 28, 2026 at 3:00AM ET.\\n\\nThis market will resolve to 'Eugenia Zozaya Menendez' if Eugenia Zozaya Menendez advances against Mariya Yemshanova.\\n\\nThis market will resolve to 'Mariya Yemshanova' if Mariya Yemshanova advances against Eugenia Zozaya Menendez.\\n\\nIf the match is canceled (not played at all), ends in a tie, or is delayed beyond 7 days from the scheduled date without a winner determined, this market will resolve to 50-50.\\n\\nIf the match begins but is not completed, and one player advances due to the opponent's retirement, default, or disqualification, this market will resolve to the player who advances.\\n\\nIf the match ends in a walkover (player withdraws before the start and the other advances automatically), this market will resolve to 50-50.\\n\\nThe primary resolution source will be official information from the International Tennis Federation (ITF). A consensus of credible reporting may also be used.\"}, \"timestamp\":\"1785211225823\", \"event_type\":\"new_market\", \"tags\":[], \"condition_id\":\"0x97f60aafa260d6f4c477d04fbb87e46a7097bf5a82d9eda8430d6ade6cb7f8a8\", \"active\":false, \"clob_token_ids\":[\"79232279783522378407313330804515778669057246269718147160937070845112245315997\", \"80842631769260170119314333692968159467060976703425140894972683091649912060566\"], \"sports_market_type\":\"moneyline\", \"line\":\"\", \"game_start_time\":\"2026-07-28 07:00:00+00\", \"order_price_min_tick_size\":\"0.01\", \"group_item_title\":\"\", \"taker_base_fee\":\"1000\", \"fees_enabled\":true, \"fee_schedule\":{\"exponent\":\"1\", \"rate\":\"0.05\", \"taker_only\":true, \"rebate_rate\":\"0.15\"}}","received_at":"2026-07-28T04:00:29.075630Z","schema_version":"clob-market-ws.new_market.v1","sequence":null,"server_hash":null,"server_timestamp":"1785211225823","session_id":"2d607381e3054cee91998cdf45a4231c","source":"clob_market_ws"},"received_at":"2026-07-28T04:00:29.075630Z","record_id":"38360a64cf7674de41336b530a0f1dadcae9fb2fb50cce4049942686919f2780","schema_fingerprint":"6639a822a7b79cfa4c3fc0044066e4f66ba8611f5bf361772bd6902a2319b82d","schema_version":"edge-lab-recorder.raw.v1","sequence":null,"source":"clob_market_ws"}
{"event_at":"2026-07-28T04:00:25.821000Z","event_fingerprint":"132e71a22764eb37f2dcf247356419f3153c10973ba8b3905829bf6a35b9cc69","payload":{"connection_id":"f6725804f86a4c4eb588e4d5ed7db029","event_at":"2026-07-28T04:00:25.821000Z","event_type":"new_market","frame_hash":"64b3db9cd28e7193415d9fe394453a340506fa0c4e55a7afd99bd97db1f553cd","frame_index":0,"kind":"data","monotonic_ns":313212132956458,"payload":{"active":false,"assets_ids":["4754552019209745553197041840201931812000360132776391485795259737620717499352","109521489158971222304676684903082666642135877831201852860397373899979750690107"],"clob_token_ids":["4754552019209745553197041840201931812000360132776391485795259737620717499352","109521489158971222304676684903082666642135877831201852860397373899979750690107"],"condition_id":"0x1ce00c26069f689c69d2af6eda5d617f6208b9a72004c9d1a54413ff0c4af4c4","description":"This market refers to whether the cricket match between Austria and Israel scheduled for 2026-07-27 in T20 European Cup is completed under the competition's official playing conditions.\nThis market resolves according to the finalized match status as published by https://www.espncricinfo.com/.\nAny match where an official result is declared — including results decided by DLS/DRS, over-rate penalties, a Super Over, forfeit/walkover, or any other on-field ruling — will resolve Yes. (Draws count as completed results when recognized by the competition.)\nIf the match is abandoned, ends in No Result, is permanently canceled, or otherwise concludes without an official result, the market will resolve No.\nIf the match is postponed or rescheduled, the market remains open until the listed fixture is completed or permanently canceled, after which it will resolve as described above.\n","event_message":{"description":"This market refers to the cricket match between Austria and Israel scheduled for July 28 2026 in T20 European Cup.\n\nThis market resolves according to the finalized match result as published by https://www.espncricinfo.com/.  \n\nDLS/DRS, over-rate penalties, forfeit/walkover, or any other on-field ruling that leads the competition to declare a winner are treated as ordinary wins.\n\nIf the match ends tied and the playing conditions provide an on-field tiebreak (e.g., Super Over), the winner determined by that tiebreak will be used for resolution. If the match ends tied and no on-field tiebreak is used or available under the playing conditions (e.g., group-stage ODI with no Super Over), the market will resolve 50-50.\n\nIf the match is postponed/rescheduled, the market remains open until the listed fixture is completed. If the match is permanently canceled or abandoned or otherwise is completed without a winner, the market resolves 50-50.\n\nThe primary resolution source for this market is the official statistics of the event as recognized by the governing body or event organizers. However, if the governing body or event organizers have not published final match statistics within 2 hours after the event's conclusion, a consensus of credible reporting may be used instead.\n","id":"759303","slug":"crint-aut-isr-2026-07-28","ticker":"crint-aut-isr-2026-07-28","title":"T20 European Cup: Austria vs Israel"},"event_type":"new_market","fee_schedule":{"exponent":"1","rate":"0.05","rebate_rate":"0.15","taker_only":true},"fees_enabled":true,"game_start_time":"2026-07-28 05:30:00+00","group_item_title":"","id":"3145672","line":"","market":"0x1ce00c26069f689c69d2af6eda5d617f6208b9a72004c9d1a54413ff0c4af4c4","order_price_min_tick_size":"0.01","outcomes":["Yes","No"],"question":"T20 European Cup: Austria vs Israel - Completed match?","slug":"crint-aut-isr-2026-07-28-completed-match","sports_market_type":"cricket_completed_match","tags":[],"taker_base_fee":"1000","timestamp":"1785211225821"},"payload_hash":"b631965c75fd4c73d7c4d9192cfb663b83d0341c04896fb57f7fef1e95aa2466","raw_frame":"{\"id\":\"3145672\", \"question\":\"T20 European Cup: Austria vs Israel - Completed match?\", \"market\":\"0x1ce00c26069f689c69d2af6eda5d617f6208b9a72004c9d1a54413ff0c4af4c4\", \"slug\":\"crint-aut-isr-2026-07-28-completed-match\", \"description\":\"This market refers to whether the cricket match between Austria and Israel scheduled for 2026-07-27 in T20 European Cup is completed under the competition's official playing conditions.\\nThis market resolves according to the finalized match status as published by https://www.espncricinfo.com/.\\nAny match where an official result is declared — including results decided by DLS/DRS, over-rate penalties, a Super Over, forfeit/walkover, or any other on-field ruling — will resolve Yes. (Draws count as completed results when recognized by the competition.)\\nIf the match is abandoned, ends in No Result, is permanently canceled, or otherwise concludes without an official result, the market will resolve No.\\nIf the match is postponed or rescheduled, the market remains open until the listed fixture is completed or permanently canceled, after which it will resolve as described above.\\n\", \"assets_ids\":[\"4754552019209745553197041840201931812000360132776391485795259737620717499352\", \"109521489158971222304676684903082666642135877831201852860397373899979750690107\"], \"outcomes\":[\"Yes\", \"No\"], \"event_message\":{\"id\":\"759303\", \"ticker\":\"crint-aut-isr-2026-07-28\", \"slug\":\"crint-aut-isr-2026-07-28\", \"title\":\"T20 European Cup: Austria vs Israel\", \"description\":\"This market refers to the cricket match between Austria and Israel scheduled for July 28 2026 in T20 European Cup.\\n\\nThis market resolves according to the finalized match result as published by https://www.espncricinfo.com/.  \\n\\nDLS/DRS, over-rate penalties, forfeit/walkover, or any other on-field ruling that leads the competition to declare a winner are treated as ordinary wins.\\n\\nIf the match ends tied and the playing conditions provide an on-field tiebreak (e.g., Super Over), the winner determined by that tiebreak will be used for resolution. If the match ends tied and no on-field tiebreak is used or available under the playing conditions (e.g., group-stage ODI with no Super Over), the market will resolve 50-50.\\n\\nIf the match is postponed/rescheduled, the market remains open until the listed fixture is completed. If the match is permanently canceled or abandoned or otherwise is completed without a winner, the market resolves 50-50.\\n\\nThe primary resolution source for this market is the official statistics of the event as recognized by the governing body or event organizers. However, if the governing body or event organizers have not published final match statistics within 2 hours after the event's conclusion, a consensus of credible reporting may be used instead.\\n\"}, \"timestamp\":\"1785211225821\", \"event_type\":\"new_market\", \"tags\":[], \"condition_id\":\"0x1ce00c26069f689c69d2af6eda5d617f6208b9a72004c9d1a54413ff0c4af4c4\", \"active\":false, \"clob_token_ids\":[\"4754552019209745553197041840201931812000360132776391485795259737620717499352\", \"109521489158971222304676684903082666642135877831201852860397373899979750690107\"], \"sports_market_type\":\"cricket_completed_match\", \"line\":\"\", \"game_start_time\":\"2026-07-28 05:30:00+00\", \"order_price_min_tick_size\":\"0.01\", \"group_item_title\":\"\", \"taker_base_fee\":\"1000\", \"fees_enabled\":true, \"fee_schedule\":{\"exponent\":\"1\", \"rate\":\"0.05\", \"taker_only\":true, \"rebate_rate\":\"0.15\"}}","received_at":"2026-07-28T04:00:29.084832Z","schema_version":"clob-market-ws.new_market.v1","sequence":null,"server_hash":null,"server_timestamp":"1785211225821","session_id":"2d607381e3054cee91998cdf45a4231c","source":"clob_market_ws"},"received_at":"2026-07-28T04:00:29.084832Z","record_id":"7ac13c4b594710e3e1adfdb47ca3b66f10f51a8e585f9186c1d8200128335987","schema_fingerprint":"6639a822a7b79cfa4c3fc0044066e4f66ba8611f5bf361772bd6902a2319b82d","schema_version":"edge-lab-recorder.raw.v1","sequence":null,"source":"clob_market_ws"}
{"event_at":"2026-07-28T04:00:25.825000Z","event_fingerprint":"3f0b904c0e4110ad317bf5dd1fca4d4b9dabd33b1aa6da1dc63450f68ef1e95f","payload":{"connection_id":"f6725804f86a4c4eb588e4d5ed7db029","event_at":"2026-07-28T04:00:25.825000Z","event_type":"price_change","frame_hash":"e8b0c77d970129021745b3c32822e28e2912ebd83ab7be1848e40cba4d8554a7","frame_index":0,"kind":"data","monotonic_ns":313212142322541,"payload":{"event_type":"price_change","market":"0xd412ce774cfcf8dc9f71164aac78783978aac7b03871702a3b8a481bd9dc9688","price_changes":[{"asset_id":"96600821790790307414914106093858868634329285205417149685270682748367152458577","best_ask":"0.56","best_bid":"0.55","hash":"a1a445db2f5b6b2fb9dc55e3f732442a1d5c688f","price":"0.51","side":"BUY","size":"58.6"},{"asset_id":"107603864457683460275633293642179940881969192120168665300712204232021063124301","best_ask":"0.45","best_bid":"0.44","hash":"6f6639851753cf027945130382e9d4be1538f9a7","price":"0.49","side":"SELL","size":"58.6"}],"timestamp":"1785211225825"},"payload_hash":"a0bb67c6c31d8933ae37317e086c038e4467268fd97504e1a65980a74acec79b","raw_frame":"{\"market\":\"0xd412ce774cfcf8dc9f71164aac78783978aac7b03871702a3b8a481bd9dc9688\", \"price_changes\":[{\"asset_id\":\"96600821790790307414914106093858868634329285205417149685270682748367152458577\", \"price\":\"0.51\", \"size\":\"58.6\", \"side\":\"BUY\", \"hash\":\"a1a445db2f5b6b2fb9dc55e3f732442a1d5c688f\", \"best_bid\":\"0.55\", \"best_ask\":\"0.56\"}, {\"asset_id\":\"107603864457683460275633293642179940881969192120168665300712204232021063124301\", \"price\":\"0.49\", \"size\":\"58.6\", \"side\":\"SELL\", \"hash\":\"6f6639851753cf027945130382e9d4be1538f9a7\", \"best_bid\":\"0.44\", \"best_ask\":\"0.45\"}], \"timestamp\":\"1785211225825\", \"event_type\":\"price_change\"}","received_at":"2026-07-28T04:00:29.094197Z","schema_version":"clob-market-ws.price_change.v1","sequence":null,"server_hash":null,"server_timestamp":"1785211225825","session_id":"2d607381e3054cee91998cdf45a4231c","source":"clob_market_ws"},"received_at":"2026-07-28T04:00:29.094197Z","record_id":"6b7bcd5ba40e696db7233eae3e94b612d8364b7e089ee2e3badd66a584860672","schema_fingerprint":"4aa3821a28b0b7c2400bc59aba4bcc0a76e971dadd19610d3ad38c768e124dc7","schema_version":"edge-lab-recorder.raw.v1","sequence":null,"source":"clob_market_ws"}
{"event_at":"2026-07-28T04:00:25.825000Z","event_fingerprint":"199fd4b93060a479d83217296195c4a47a234c18a5c44540a7e05ba67229382a","payload":{"connection_id":"f6725804f86a4c4eb588e4d5ed7db029","event_at":"2026-07-28T04:00:25.825000Z","event_type":"price_change","frame_hash":"858782d46a2c9efcd08a2a94028e996147af7a59f59b9d98fd4ef1473373a074","frame_index":0,"kind":"data","monotonic_ns":313212147394208,"payload":{"event_type":"price_change","market":"0xd412ce774cfcf8dc9f71164aac78783978aac7b03871702a3b8a481bd9dc9688","price_changes":[{"asset_id":"96600821790790307414914106093858868634329285205417149685270682748367152458577","best_ask":"0.56","best_bid":"0.55","hash":"f3f109910271ab6937573ae2882f90cf8752f4e8","price":"0.45","side":"BUY","size":"113"},{"asset_id":"107603864457683460275633293642179940881969192120168665300712204232021063124301","best_ask":"0.45","best_bid":"0.44","hash":"55dc789320f5ce20d0467cd1c97afee9dc73c6fd","price":"0.55","side":"SELL","size":"113"}],"timestamp":"1785211225825"},"payload_hash":"f7878718d7702d5ac25356153fe1eb3f175aa29ae547708917f2b95407ea3895","raw_frame":"{\"market\":\"0xd412ce774cfcf8dc9f71164aac78783978aac7b03871702a3b8a481bd9dc9688\", \"price_changes\":[{\"asset_id\":\"96600821790790307414914106093858868634329285205417149685270682748367152458577\", \"price\":\"0.45\", \"size\":\"113\", \"side\":\"BUY\", \"hash\":\"f3f109910271ab6937573ae2882f90cf8752f4e8\", \"best_bid\":\"0.55\", \"best_ask\":\"0.56\"}, {\"asset_id\":\"107603864457683460275633293642179940881969192120168665300712204232021063124301\", \"price\":\"0.55\", \"size\":\"113\", \"side\":\"SELL\", \"hash\":\"55dc789320f5ce20d0467cd1c97afee9dc73c6fd\", \"best_bid\":\"0.44\", \"best_ask\":\"0.45\"}], \"timestamp\":\"1785211225825\", \"event_type\":\"price_change\"}","received_at":"2026-07-28T04:00:29.099269Z","schema_version":"clob-market-ws.price_change.v1","sequence":null,"server_hash":null,"server_timestamp":"1785211225825","session_id":"2d607381e3054cee91998cdf45a4231c","source":"clob_market_ws"},"received_at":"2026-07-28T04:00:29.099269Z","record_id":"f6799d83d5ee671aaab8f3baf6f2417c37ecf81d4d2a9ed1c78fe0071589794b","schema_fingerprint":"4aa3821a28b0b7c2400bc59aba4bcc0a76e971dadd19610d3ad38c768e124dc7","schema_version":"edge-lab-recorder.raw.v1","sequence":null,"source":"clob_market_ws"}
{"event_at":"2026-07-28T04:00:25.826000Z","event_fingerprint":"e40c35ed492d869f53cee7f5275abdb5e97de1bba2b28697ac903d1bd709c64a","payload":{"connection_id":"f6725804f86a4c4eb588e4d5ed7db029","event_at":"2026-07-28T04:00:25.826000Z","event_type":"price_change","frame_hash":"f8dd0eaa3b57c3fb9515220ccde8440b21279936ad7633b139b149b444c091a1","frame_index":0,"kind":"data","monotonic_ns":313212153296250,"payload":{"event_type":"price_change","market":"0xd412ce774cfcf8dc9f71164aac78783978aac7b03871702a3b8a481bd9dc9688","price_changes":[{"asset_id":"96600821790790307414914106093858868634329285205417149685270682748367152458577","best_ask":"0.56","best_bid":"0.55","hash":"d0c9802611bfae1737f6b4bec0c86d53f0e6a546","price":"0.45","side":"BUY","size":"83"},{"asset_id":"107603864457683460275633293642179940881969192120168665300712204232021063124301","best_ask":"0.45","best_bid":"0.44","hash":"35c5b812dad06c077338524cb625fff21db3a45f","price":"0.55","side":"SELL","size":"83"}],"timestamp":"1785211225826"},"payload_hash":"aa27671aceee5a857605feb4157bce8287f86498936e01ae3584c5ba2e194501","raw_frame":"{\"market\":\"0xd412ce774cfcf8dc9f71164aac78783978aac7b03871702a3b8a481bd9dc9688\", \"price_changes\":[{\"asset_id\":\"96600821790790307414914106093858868634329285205417149685270682748367152458577\", \"price\":\"0.45\", \"size\":\"83\", \"side\":\"BUY\", \"hash\":\"d0c9802611bfae1737f6b4bec0c86d53f0e6a546\", \"best_bid\":\"0.55\", \"best_ask\":\"0.56\"}, {\"asset_id\":\"107603864457683460275633293642179940881969192120168665300712204232021063124301\", \"price\":\"0.55\", \"size\":\"83\", \"side\":\"SELL\", \"hash\":\"35c5b812dad06c077338524cb625fff21db3a45f\", \"best_bid\":\"0.44\", \"best_ask\":\"0.45\"}], \"timestamp\":\"1785211225826\", \"event_type\":\"price_change\"}","received_at":"2026-07-28T04:00:29.105172Z","schema_version":"clob-market-ws.price_change.v1","sequence":null,"server_hash":null,"server_timestamp":"1785211225826","session_id":"2d607381e3054cee91998cdf45a4231c","source":"clob_market_ws"},"received_at":"2026-07-28T04:00:29.105172Z","record_id":"882e219b5f4e6d33bea6ed45a38381969bac907c01864eefcdcd0757439ba23c","schema_fingerprint":"4aa3821a28b0b7c2400bc59aba4bcc0a76e971dadd19610d3ad38c768e124dc7","schema_version":"edge-lab-recorder.raw.v1","sequence":null,"source":"clob_market_ws"}
{"event_at":"2026-07-28T04:00:25.826000Z","event_fingerprint":"c1803a169bcd06f83d72ee0c3c4f721a87dc9cfa31c7abf8d9c02a3e74c71596","payload":{"connection_id":"f6725804f86a4c4eb588e4d5ed7db029","event_at":"2026-07-28T04:00:25.826000Z","event_type":"price_change","frame_hash":"c8406af83d4e8e8e66cbcfa8b08cb652d4f9c4725abf461864ef2aa5088a2707","frame_index":0,"kind":"data","monotonic_ns":313212158905083,"payload":{"event_type":"price_change","market":"0xd412ce774cfcf8dc9f71164aac78783978aac7b03871702a3b8a481bd9dc9688","price_changes":[{"asset_id":"107603864457683460275633293642179940881969192120168665300712204232021063124301","best_ask":"0.45","best_bid":"0.44","hash":"d4173e42ffa30b318e07cdf1f7d65a8131513252","price":"0.38","side":"BUY","size":"111"},{"asset_id":"96600821790790307414914106093858868634329285205417149685270682748367152458577","best_ask":"0.56","best_bid":"0.55","hash":"9cac75cfe3a6f42bec8e2756643d53600bdd0908","price":"0.62","side":"SELL","size":"111"}],"timestamp":"1785211225826"},"payload_hash":"7ea487508fee5577019fbe3e09142525df34d4fc3bf2b4426ac8b9792b919107","raw_frame":"{\"market\":\"0xd412ce774cfcf8dc9f71164aac78783978aac7b03871702a3b8a481bd9dc9688\", \"price_changes\":[{\"asset_id\":\"107603864457683460275633293642179940881969192120168665300712204232021063124301\", \"price\":\"0.38\", \"size\":\"111\", \"side\":\"BUY\", \"hash\":\"d4173e42ffa30b318e07cdf1f7d65a8131513252\", \"best_bid\":\"0.44\", \"best_ask\":\"0.45\"}, {\"asset_id\":\"96600821790790307414914106093858868634329285205417149685270682748367152458577\", \"price\":\"0.62\", \"size\":\"111\", \"side\":\"SELL\", \"hash\":\"9cac75cfe3a6f42bec8e2756643d53600bdd0908\", \"best_bid\":\"0.55\", \"best_ask\":\"0.56\"}], \"timestamp\":\"1785211225826\", \"event_type\":\"price_change\"}","received_at":"2026-07-28T04:00:29.110781Z","schema_version":"clob-market-ws.price_change.v1","sequence":null,"server_hash":null,"server_timestamp":"1785211225826","session_id":"2d607381e3054cee91998cdf45a4231c","source":"clob_market_ws"},"received_at":"2026-07-28T04:00:29.110781Z","record_id":"3f173946bee42a7d927dad75177c6c995fee3591d1525754018c6b5ea212cba6","schema_fingerprint":"4aa3821a28b0b7c2400bc59aba4bcc0a76e971dadd19610d3ad38c768e124dc7","schema_version":"edge-lab-recorder.raw.v1","sequence":null,"source":"clob_market_ws"}
{"event_at":"2026-07-28T04:00:25.827000Z","event_fingerprint":"a47aede623dfff6d49717cbf94ff127af1c2b95ff77247705ac3a82a6bd9cd3f","payload":{"connection_id":"f6725804f86a4c4eb588e4d5ed7db029","event_at":"2026-07-28T04:00:25.827000Z","event_type":"price_change","frame_hash":"d796ba7247c343303d326ad956dd1a55d4e487791386181aa9adaef0d77d5baa","frame_index":0,"kind":"data","monotonic_ns":313212165385750,"payload":{"event_type":"price_change","market":"0xd412ce774cfcf8dc9f71164aac78783978aac7b03871702a3b8a481bd9dc9688","price_changes":[{"asset_id":"107603864457683460275633293642179940881969192120168665300712204232021063124301","best_ask":"0.45","best_bid":"0.44","hash":"7385d7f7998262320d7fa96378b66b8dfd9bd849","price":"0.43","side":"BUY","size":"143.6"},{"asset_id":"96600821790790307414914106093858868634329285205417149685270682748367152458577","best_ask":"0.56","best_bid":"0.55","hash":"5470428ad862eacc32f4f54b5265c8d63a305fdc","price":"0.57","side":"SELL","size":"143.6"}],"timestamp":"1785211225827"},"payload_hash":"864e9506d11a85e030a0ba96f5ad042be7f4e284968cedd13bc69c21704646c3","raw_frame":"{\"market\":\"0xd412ce774cfcf8dc9f71164aac78783978aac7b03871702a3b8a481bd9dc9688\", \"price_changes\":[{\"asset_id\":\"107603864457683460275633293642179940881969192120168665300712204232021063124301\", \"price\":\"0.43\", \"size\":\"143.6\", \"side\":\"BUY\", \"hash\":\"7385d7f7998262320d7fa96378b66b8dfd9bd849\", \"best_bid\":\"0.44\", \"best_ask\":\"0.45\"}, {\"asset_id\":\"96600821790790307414914106093858868634329285205417149685270682748367152458577\", \"price\":\"0.57\", \"size\":\"143.6\", \"side\":\"SELL\", \"hash\":\"5470428ad862eacc32f4f54b5265c8d63a305fdc\", \"best_bid\":\"0.55\", \"best_ask\":\"0.56\"}], \"timestamp\":\"1785211225827\", \"event_type\":\"price_change\"}","received_at":"2026-07-28T04:00:29.117261Z","schema_version":"clob-market-ws.price_change.v1","sequence":null,"server_hash":null,"server_timestamp":"1785211225827","session_id":"2d607381e3054cee91998cdf45a4231c","source":"clob_market_ws"},"received_at":"2026-07-28T04:00:29.117261Z","record_id":"9e51afb877fddabbedce5682a724dacd25a0cde73b98153ff5a526e25cf0e2d5","schema_fingerprint":"4aa3821a28b0b7c2400bc59aba4bcc0a76e971dadd19610d3ad38c768e124dc7","schema_version":"edge-lab-recorder.raw.v1","sequence":null,"source":"clob_market_ws"}
{"event_at":"2026-07-28T04:00:25.833000Z","event_fingerprint":"230be66d1e3e7fb82751056e436f539dc5812aa9a4644b19e10b72567b9b9e03","payload":{"connection_id":"f6725804f86a4c4eb588e4d5ed7db029","event_at":"2026-07-28T04:00:25.833000Z","event_type":"price_change","frame_hash":"31449cecd3b4b3b051a894f3dc8f067a594226e6ce6647ef8c72fb5bfef0d207","frame_index":0,"kind":"data","monotonic_ns":313212170353000,"payload":{"event_type":"price_change","market":"0xd412ce774cfcf8dc9f71164aac78783978aac7b03871702a3b8a481bd9dc9688","price_changes":[{"asset_id":"96600821790790307414914106093858868634329285205417149685270682748367152458577","best_ask":"0.56","best_bid":"0.55","hash":"9cf2b96f3c14b21909ea0d05d7b9db8d087497a6","price":"0.45","side":"BUY","size":"53"},{"asset_id":"107603864457683460275633293642179940881969192120168665300712204232021063124301","best_ask":"0.45","best_bid":"0.44","hash":"5a95f12a0e8c7329a0913a367280f51a9b255def","price":"0.55","side":"SELL","size":"53"}],"timestamp":"1785211225833"},"payload_hash":"108c8504aa731087215641cc593c83ed710e3aae743acb7d5478105706adae0e","raw_frame":"{\"market\":\"0xd412ce774cfcf8dc9f71164aac78783978aac7b03871702a3b8a481bd9dc9688\", \"price_changes\":[{\"asset_id\":\"96600821790790307414914106093858868634329285205417149685270682748367152458577\", \"price\":\"0.45\", \"size\":\"53\", \"side\":\"BUY\", \"hash\":\"9cf2b96f3c14b21909ea0d05d7b9db8d087497a6\", \"best_bid\":\"0.55\", \"best_ask\":\"0.56\"}, {\"asset_id\":\"107603864457683460275633293642179940881969192120168665300712204232021063124301\", \"price\":\"0.55\", \"size\":\"53\", \"side\":\"SELL\", \"hash\":\"5a95f12a0e8c7329a0913a367280f51a9b255def\", \"best_bid\":\"0.44\", \"best_ask\":\"0.45\"}], \"timestamp\":\"1785211225833\", \"event_type\":\"price_change\"}","received_at":"2026-07-28T04:00:29.122229Z","schema_version":"clob-market-ws.price_change.v1","sequence":null,"server_hash":null,"server_timestamp":"1785211225833","session_id":"2d607381e3054cee91998cdf45a4231c","source":"clob_market_ws"},"received_at":"2026-07-28T04:00:29.122229Z","record_id":"a7ed1310d49ecd157e46c627b406dfcaa2bd65464035d798aa95939f4b588b2f","schema_fingerprint":"4aa3821a28b0b7c2400bc59aba4bcc0a76e971dadd19610d3ad38c768e124dc7","schema_version":"edge-lab-recorder.raw.v1","sequence":null,"source":"clob_market_ws"}
{"event_at":"2026-07-28T04:00:25.834000Z","event_fingerprint":"c82db0245920f9eff2c9efc2fd8b831a8bf50f21ba74197d57f3985c351dd38f","payload":{"connection_id":"f6725804f86a4c4eb588e4d5ed7db029","event_at":"2026-07-28T04:00:25.834000Z","event_type":"price_change","frame_hash":"eb653cdf007e160aaa8704254ef1ccf57525b5fe20a9e2653def50923e8fb517","frame_index":0,"kind":"data","monotonic_ns":313212176851000,"payload":{"event_type":"price_change","market":"0xd412ce774cfcf8dc9f71164aac78783978aac7b03871702a3b8a481bd9dc9688","price_changes":[{"asset_id":"107603864457683460275633293642179940881969192120168665300712204232021063124301","best_ask":"0.45","best_bid":"0.44","hash":"f3410494b161b4dfb53ebb78f0220d9059e0bab8","price":"0.38","side":"BUY","size":"98"},{"asset_id":"96600821790790307414914106093858868634329285205417149685270682748367152458577","best_ask":"0.56","best_bid":"0.55","hash":"6df681b0bc70409adf97a323969b4f08ee77962c","price":"0.62","side":"SELL","size":"98"}],"timestamp":"1785211225834"},"payload_hash":"82c4dcb301a9344b10f1ebc510d06ceaebbcd2185f12155f9d7cf840627ddd83","raw_frame":"{\"market\":\"0xd412ce774cfcf8dc9f71164aac78783978aac7b03871702a3b8a481bd9dc9688\", \"price_changes\":[{\"asset_id\":\"107603864457683460275633293642179940881969192120168665300712204232021063124301\", \"price\":\"0.38\", \"size\":\"98\", \"side\":\"BUY\", \"hash\":\"f3410494b161b4dfb53ebb78f0220d9059e0bab8\", \"best_bid\":\"0.44\", \"best_ask\":\"0.45\"}, {\"asset_id\":\"96600821790790307414914106093858868634329285205417149685270682748367152458577\", \"price\":\"0.62\", \"size\":\"98\", \"side\":\"SELL\", \"hash\":\"6df681b0bc70409adf97a323969b4f08ee77962c\", \"best_bid\":\"0.55\", \"best_ask\":\"0.56\"}], \"timestamp\":\"1785211225834\", \"event_type\":\"price_change\"}","received_at":"2026-07-28T04:00:29.128726Z","schema_version":"clob-market-ws.price_change.v1","sequence":null,"server_hash":null,"server_timestamp":"1785211225834","session_id":"2d607381e3054cee91998cdf45a4231c","source":"clob_market_ws"},"received_at":"2026-07-28T04:00:29.128726Z","record_id":"5eb0dd8063c32c3468d0bf1e3e2c4459efd1b0aabed7d7c02a0d0115d3dd7e16","schema_fingerprint":"4aa3821a28b0b7c2400bc59aba4bcc0a76e971dadd19610d3ad38c768e124dc7","schema_version":"edge-lab-recorder.raw.v1","sequence":null,"source":"clob_market_ws"}
{"event_at":"2026-07-28T04:00:25.834000Z","event_fingerprint":"42159c04bfc9540a3a8d1ffa4399ac26af585727d51bf2e9fcf3aa4c98b5e4f0","payload":{"connection_id":"f6725804f86a4c4eb588e4d5ed7db029","event_at":"2026-07-28T04:00:25.834000Z","event_type":"price_change","frame_hash":"5ab888dfcc1db519e287512547a7fe7d4104a4e4c261da8b38cc0349c85e5a4a","frame_index":0,"kind":"data","monotonic_ns":313212183012500,"payload":{"event_type":"price_change","market":"0xd412ce774cfcf8dc9f71164aac78783978aac7b03871702a3b8a481bd9dc9688","price_changes":[{"asset_id":"96600821790790307414914106093858868634329285205417149685270682748367152458577","best_ask":"0.56","best_bid":"0.55","hash":"a3305bbab66225a0712c0a84b74a55c06a872e89","price":"0.51","side":"BUY","size":"43.6"},{"asset_id":"107603864457683460275633293642179940881969192120168665300712204232021063124301","best_ask":"0.45","best_bid":"0.44","hash":"43c9a1df2343daee781a28fd44919f70b15909e9","price":"0.49","side":"SELL","size":"43.6"}],"timestamp":"1785211225834"},"payload_hash":"8cf3c4cf0f70f4c6db76361cb68421c66745af731e753798d3656441379b3067","raw_frame":"{\"market\":\"0xd412ce774cfcf8dc9f71164aac78783978aac7b03871702a3b8a481bd9dc9688\", \"price_changes\":[{\"asset_id\":\"96600821790790307414914106093858868634329285205417149685270682748367152458577\", \"price\":\"0.51\", \"size\":\"43.6\", \"side\":\"BUY\", \"hash\":\"a3305bbab66225a0712c0a84b74a55c06a872e89\", \"best_bid\":\"0.55\", \"best_ask\":\"0.56\"}, {\"asset_id\":\"107603864457683460275633293642179940881969192120168665300712204232021063124301\", \"price\":\"0.49\", \"size\":\"43.6\", \"side\":\"SELL\", \"hash\":\"43c9a1df2343daee781a28fd44919f70b15909e9\", \"best_bid\":\"0.44\", \"best_ask\":\"0.45\"}], \"timestamp\":\"1785211225834\", \"event_type\":\"price_change\"}","received_at":"2026-07-28T04:00:29.134888Z","schema_version":"clob-market-ws.price_change.v1","sequence":null,"server_hash":null,"server_timestamp":"1785211225834","session_id":"2d607381e3054cee91998cdf45a4231c","source":"clob_market_ws"},"received_at":"2026-07-28T04:00:29.134888Z","record_id":"2f871d53eccdadee706e8ba2f19b0f881f7ec0dc6bdbd6abe727d0fb3a18bb2b","schema_fingerprint":"4aa3821a28b0b7c2400bc59aba4bcc0a76e971dadd19610d3ad38c768e124dc7","schema_version":"edge-lab-recorder.raw.v1","sequence":null,"source":"clob_market_ws"}
{"event_at":"2026-07-28T04:00:25.834000Z","event_fingerprint":"5af436054bb7d5ad822a9bd776e05a8cfd569a94e78258c973231d7c2e4c94ae","payload":{"connection_id":"f6725804f86a4c4eb588e4d5ed7db029","event_at":"2026-07-28T04:00:25.834000Z","event_type":"price_change","frame_hash":"7af19402224a4df04e8fc306570aefc0b3a260b29ad5c89de81ac553e2439181","frame_index":0,"kind":"data","monotonic_ns":313212187865041,"payload":{"event_type":"price_change","market":"0xd412ce774cfcf8dc9f71164aac78783978aac7b03871702a3b8a481bd9dc9688","price_changes":[{"asset_id":"96600821790790307414914106093858868634329285205417149685270682748367152458577","best_ask":"0.56","best_bid":"0.55","hash":"36a785c5547cc5176b19ab50185a24fdd4457469","price":"0.52","side":"BUY","size":"31"},{"asset_id":"107603864457683460275633293642179940881969192120168665300712204232021063124301","best_ask":"0.45","best_bid":"0.44","hash":"0b3d8a414e369ee49f93ab88aef5c905aba9303e","price":"0.48","side":"SELL","size":"31"}],"timestamp":"1785211225834"},"payload_hash":"8d49569a106f2c3c08059332689eb35ad0a518464348e5385fe5f8fe717ef0bc","raw_frame":"{\"market\":\"0xd412ce774cfcf8dc9f71164aac78783978aac7b03871702a3b8a481bd9dc9688\", \"price_changes\":[{\"asset_id\":\"96600821790790307414914106093858868634329285205417149685270682748367152458577\", \"price\":\"0.52\", \"size\":\"31\", \"side\":\"BUY\", \"hash\":\"36a785c5547cc5176b19ab50185a24fdd4457469\", \"best_bid\":\"0.55\", \"best_ask\":\"0.56\"}, {\"asset_id\":\"107603864457683460275633293642179940881969192120168665300712204232021063124301\", \"price\":\"0.48\", \"size\":\"31\", \"side\":\"SELL\", \"hash\":\"0b3d8a414e369ee49f93ab88aef5c905aba9303e\", \"best_bid\":\"0.44\", \"best_ask\":\"0.45\"}], \"timestamp\":\"1785211225834\", \"event_type\":\"price_change\"}","received_at":"2026-07-28T04:00:29.139740Z","schema_version":"clob-market-ws.price_change.v1","sequence":null,"server_hash":null,"server_timestamp":"1785211225834","session_id":"2d607381e3054cee91998cdf45a4231c","source":"clob_market_ws"},"received_at":"2026-07-28T04:00:29.139740Z","record_id":"570b826f4e3cd79617613138dbc30d1913d4fca2a39813e4ea8b13f3c561edd2","schema_fingerprint":"4aa3821a28b0b7c2400bc59aba4bcc0a76e971dadd19610d3ad38c768e124dc7","schema_version":"edge-lab-recorder.raw.v1","sequence":null,"source":"clob_market_ws"}
{"event_at":"2026-07-28T04:00:25.834000Z","event_fingerprint":"cf04767fb4dba8f308e6cc76c5fab7bc6d8294ebe6eea6ccc379ef2488f7af79","payload":{"connection_id":"f6725804f86a4c4eb588e4d5ed7db029","event_at":"2026-07-28T04:00:25.834000Z","event_type":"price_change","frame_hash":"b51330192263bd7820a4bcf198bbc2983ffb3229b67b24c72c177d6552e738c6","frame_index":0,"kind":"data","monotonic_ns":313212193978541,"payload":{"event_type":"price_change","market":"0xd412ce774cfcf8dc9f71164aac78783978aac7b03871702a3b8a481bd9dc9688","price_changes":[{"asset_id":"107603864457683460275633293642179940881969192120168665300712204232021063124301","best_ask":"0.45","best_bid":"0.44","hash":"1d26a397971e07ae6993cb05f70c1be24127041d","price":"0.44","side":"BUY","size":"135.2"},{"asset_id":"96600821790790307414914106093858868634329285205417149685270682748367152458577","best_ask":"0.56","best_bid":"0.55","hash":"8176d184b8cf67d32c2b69c97f9dbce30f624fa5","price":"0.56","side":"SELL","size":"135.2"}],"timestamp":"1785211225834"},"payload_hash":"1883acac22dfa3e04e22113418d6b965aabf47a14b02de45acc2487813126ad2","raw_frame":"{\"market\":\"0xd412ce774cfcf8dc9f71164aac78783978aac7b03871702a3b8a481bd9dc9688\", \"price_changes\":[{\"asset_id\":\"107603864457683460275633293642179940881969192120168665300712204232021063124301\", \"price\":\"0.44\", \"size\":\"135.2\", \"side\":\"BUY\", \"hash\":\"1d26a397971e07ae6993cb05f70c1be24127041d\", \"best_bid\":\"0.44\", \"best_ask\":\"0.45\"}, {\"asset_id\":\"96600821790790307414914106093858868634329285205417149685270682748367152458577\", \"price\":\"0.56\", \"size\":\"135.2\", \"side\":\"SELL\", \"hash\":\"8176d184b8cf67d32c2b69c97f9dbce30f624fa5\", \"best_bid\":\"0.55\", \"best_ask\":\"0.56\"}], \"timestamp\":\"1785211225834\", \"event_type\":\"price_change\"}","received_at":"2026-07-28T04:00:29.145854Z","schema_version":"clob-market-ws.price_change.v1","sequence":null,"server_hash":null,"server_timestamp":"1785211225834","session_id":"2d607381e3054cee91998cdf45a4231c","source":"clob_market_ws"},"received_at":"2026-07-28T04:00:29.145854Z","record_id":"4a090b4fec755e4ef864aa3420512a0832636e94efe037eda0a373a605febd4c","schema_fingerprint":"4aa3821a28b0b7c2400bc59aba4bcc0a76e971dadd19610d3ad38c768e124dc7","schema_version":"edge-lab-recorder.raw.v1","sequence":null,"source":"clob_market_ws"}
{"event_at":"2026-07-28T04:00:25.835000Z","event_fingerprint":"648c2754828e0cc8ea41b569f88b8526e57a12a68a139d2e49f34f59f32cffbe","payload":{"connection_id":"f6725804f86a4c4eb588e4d5ed7db029","event_at":"2026-07-28T04:00:25.835000Z","event_type":"price_change","frame_hash":"5230727dc7e26ab3177224e7476708ea04713042f5a8b44fd9ddde2cd19a4f85","frame_index":0,"kind":"data","monotonic_ns":313212198172125,"payload":{"event_type":"price_change","market":"0xd412ce774cfcf8dc9f71164aac78783978aac7b03871702a3b8a481bd9dc9688","price_changes":[{"asset_id":"96600821790790307414914106093858868634329285205417149685270682748367152458577","best_ask":"0.56","best_bid":"0.55","hash":"783ce9a3c71e5d90d7c4799c6ed121454fc6a8e5","price":"0.01","side":"BUY","size":"7545.02"},{"asset_id":"107603864457683460275633293642179940881969192120168665300712204232021063124301","best_ask":"0.45","best_bid":"0.44","hash":"e8426c14ec90fde1064c60612bce11a439b19a13","price":"0.99","side":"SELL","size":"7545.02"}],"timestamp":"1785211225835"},"payload_hash":"b08cc65a5bac29b6bf78edf4e3cfea4a41857f29ddd41d8353d25fd8c378a326","raw_frame":"{\"market\":\"0xd412ce774cfcf8dc9f71164aac78783978aac7b03871702a3b8a481bd9dc9688\", \"price_changes\":[{\"asset_id\":\"96600821790790307414914106093858868634329285205417149685270682748367152458577\", \"price\":\"0.01\", \"size\":\"7545.02\", \"side\":\"BUY\", \"hash\":\"783ce9a3c71e5d90d7c4799c6ed121454fc6a8e5\", \"best_bid\":\"0.55\", \"best_ask\":\"0.56\"}, {\"asset_id\":\"107603864457683460275633293642179940881969192120168665300712204232021063124301\", \"price\":\"0.99\", \"size\":\"7545.02\", \"side\":\"SELL\", \"hash\":\"e8426c14ec90fde1064c60612bce11a439b19a13\", \"best_bid\":\"0.44\", \"best_ask\":\"0.45\"}], \"timestamp\":\"1785211225835\", \"event_type\":\"price_change\"}","received_at":"2026-07-28T04:00:29.150048Z","schema_version":"clob-market-ws.price_change.v1","sequence":null,"server_hash":null,"server_timestamp":"1785211225835","session_id":"2d607381e3054cee91998cdf45a4231c","source":"clob_market_ws"},"received_at":"2026-07-28T04:00:29.150048Z","record_id":"0fb654c0d7cb0d9ab6c1335e4b0d8146052d40eb65b2e07b393d057c00398fbc","schema_fingerprint":"4aa3821a28b0b7c2400bc59aba4bcc0a76e971dadd19610d3ad38c768e124dc7","schema_version":"edge-lab-recorder.raw.v1","sequence":null,"source":"clob_market_ws"}
{"event_at":"2026-07-28T04:00:25.836000Z","event_fingerprint":"c48a57db397025857b240784d6edb8f5da53b6897e50426466f6306c4e20811d","payload":{"connection_id":"f6725804f86a4c4eb588e4d5ed7db029","event_at":"2026-07-28T04:00:25.836000Z","event_type":"price_change","frame_hash":"ca92a4f3dcb2588a589e5a8c016aa73dc39aaf8965e15d422857d39ab860a518","frame_index":0,"kind":"data","monotonic_ns":313212205795666,"payload":{"event_type":"price_change","market":"0xd412ce774cfcf8dc9f71164aac78783978aac7b03871702a3b8a481bd9dc9688","price_changes":[{"asset_id":"107603864457683460275633293642179940881969192120168665300712204232021063124301","best_ask":"0.45","best_bid":"0.44","hash":"5c5794933e06cbb185ce8b99b44a71f93da7b0e8","price":"0.44","side":"BUY","size":"141.2"},{"asset_id":"96600821790790307414914106093858868634329285205417149685270682748367152458577","best_ask":"0.56","best_bid":"0.55","hash":"e88df6b2bec42ebb6221de7d95ca27865c941156","price":"0.56","side":"SELL","size":"141.2"}],"timestamp":"1785211225836"},"payload_hash":"4786ca73b4242de36fbb52c23356e3b7bf4221609908b5d1718d492d8b9b4f1d","raw_frame":"{\"market\":\"0xd412ce774cfcf8dc9f71164aac78783978aac7b03871702a3b8a481bd9dc9688\", \"price_changes\":[{\"asset_id\":\"107603864457683460275633293642179940881969192120168665300712204232021063124301\", \"price\":\"0.44\", \"size\":\"141.2\", \"side\":\"BUY\", \"hash\":\"5c5794933e06cbb185ce8b99b44a71f93da7b0e8\", \"best_bid\":\"0.44\", \"best_ask\":\"0.45\"}, {\"asset_id\":\"96600821790790307414914106093858868634329285205417149685270682748367152458577\", \"price\":\"0.56\", \"size\":\"141.2\", \"side\":\"SELL\", \"hash\":\"e88df6b2bec42ebb6221de7d95ca27865c941156\", \"best_bid\":\"0.55\", \"best_ask\":\"0.56\"}], \"timestamp\":\"1785211225836\", \"event_type\":\"price_change\"}","received_at":"2026-07-28T04:00:29.157671Z","schema_version":"clob-market-ws.price_change.v1","sequence":null,"server_hash":null,"server_timestamp":"1785211225836","session_id":"2d607381e3054cee91998cdf45a4231c","source":"clob_market_ws"},"received_at":"2026-07-28T04:00:29.157671Z","record_id":"e3464b8c66d454e424abc241afd87a3f0c8de89d5b46ebba100b12288bc7fef7","schema_fingerprint":"4aa3821a28b0b7c2400bc59aba4bcc0a76e971dadd19610d3ad38c768e124dc7","schema_version":"edge-lab-recorder.raw.v1","sequence":null,"source":"clob_market_ws"}
{"event_at":"2026-07-28T04:00:25.837000Z","event_fingerprint":"a6c9de045646aaa7ef0adebacd3a5326283cd803caa6c74d9cb34c2a0093887b","payload":{"connection_id":"f6725804f86a4c4eb588e4d5ed7db029","event_at":"2026-07-28T04:00:25.837000Z","event_type":"price_change","frame_hash":"fdcb77830157eaa39b822ca0160df7789696c5b31b2aeded5221d0da0426ba52","frame_index":0,"kind":"data","monotonic_ns":313212210046833,"payload":{"event_type":"price_change","market":"0xd412ce774cfcf8dc9f71164aac78783978aac7b03871702a3b8a481bd9dc9688","price_changes":[{"asset_id":"96600821790790307414914106093858868634329285205417149685270682748367152458577","best_ask":"0.56","best_bid":"0.55","hash":"b7c7d4aae3541bc56fd95f57b179ae1371635a91","price":"0.5","side":"BUY","size":"59.6"},{"asset_id":"107603864457683460275633293642179940881969192120168665300712204232021063124301","best_ask":"0.45","best_bid":"0.44","hash":"1fc425571bdc1b7eb25d40d9a9f24bc7d2dd018a","price":"0.5","side":"SELL","size":"59.6"}],"timestamp":"1785211225837"},"payload_hash":"1a710787e91440bd777f0ef7c644e576f5e85c07499fc3d78990fa9830e84b68","raw_frame":"{\"market\":\"0xd412ce774cfcf8dc9f71164aac78783978aac7b03871702a3b8a481bd9dc9688\", \"price_changes\":[{\"asset_id\":\"96600821790790307414914106093858868634329285205417149685270682748367152458577\", \"price\":\"0.5\", \"size\":\"59.6\", \"side\":\"BUY\", \"hash\":\"b7c7d4aae3541bc56fd95f57b179ae1371635a91\", \"best_bid\":\"0.55\", \"best_ask\":\"0.56\"}, {\"asset_id\":\"107603864457683460275633293642179940881969192120168665300712204232021063124301\", \"price\":\"0.5\", \"size\":\"59.6\", \"side\":\"SELL\", \"hash\":\"1fc425571bdc1b7eb25d40d9a9f24bc7d2dd018a\", \"best_bid\":\"0.44\", \"best_ask\":\"0.45\"}], \"timestamp\":\"1785211225837\", \"event_type\":\"price_change\"}","received_at":"2026-07-28T04:00:29.161922Z","schema_version":"clob-market-ws.price_change.v1","sequence":null,"server_hash":null,"server_timestamp":"1785211225837","session_id":"2d607381e3054cee91998cdf45a4231c","source":"clob_market_ws"},"received_at":"2026-07-28T04:00:29.161922Z","record_id":"b9fe361201df929d42773096db9cb5f3ca1222f4827b1e3d93c48bb65a307bc9","schema_fingerprint":"4aa3821a28b0b7c2400bc59aba4bcc0a76e971dadd19610d3ad38c768e124dc7","schema_version":"edge-lab-recorder.raw.v1","sequence":null,"source":"clob_market_ws"}
{"event_at":"2026-07-28T04:00:25.838000Z","event_fingerprint":"0d0ef775229f7be332f38a3a884406b17c7371a728578d0ba91fb27f6a83f473","payload":{"connection_id":"f6725804f86a4c4eb588e4d5ed7db029","event_at":"2026-07-28T04:00:25.838000Z","event_type":"best_bid_ask","frame_hash":"5cebc42955aee9f84d5a3ec27bbb50af5b59599128cb71210c0974627635c767","frame_index":0,"kind":"data","monotonic_ns":313212214302583,"payload":{"asset_id":"107603864457683460275633293642179940881969192120168665300712204232021063124301","best_ask":"0.46","best_bid":"0.44","event_type":"best_bid_ask","market":"0xd412ce774cfcf8dc9f71164aac78783978aac7b03871702a3b8a481bd9dc9688","spread":"0.02","timestamp":"1785211225838"},"payload_hash":"de6c2efd02c48dc0e24e3508721cf127e769ffb321f184db59739aea5d1a0474","raw_frame":"{\"market\":\"0xd412ce774cfcf8dc9f71164aac78783978aac7b03871702a3b8a481bd9dc9688\", \"asset_id\":\"107603864457683460275633293642179940881969192120168665300712204232021063124301\", \"best_bid\":\"0.44\", \"best_ask\":\"0.46\", \"spread\":\"0.02\", \"timestamp\":\"1785211225838\", \"event_type\":\"best_bid_ask\"}","received_at":"2026-07-28T04:00:29.166178Z","schema_version":"clob-market-ws.best_bid_ask.v1","sequence":null,"server_hash":null,"server_timestamp":"1785211225838","session_id":"2d607381e3054cee91998cdf45a4231c","source":"clob_market_ws"},"received_at":"2026-07-28T04:00:29.166178Z","record_id":"3a5146bd28114d9f88fd6176724f8789435d31e000972bf80fa8f310a590c1bb","schema_fingerprint":"8488399f31b0337811b13b266be932db7062827c2470b78bd8e9e99bab51d17d","schema_version":"edge-lab-recorder.raw.v1","sequence":null,"source":"clob_market_ws"}
{"event_at":"2026-07-28T04:00:25.838000Z","event_fingerprint":"6dd9a7735eafdb1df04c90147c1c61700b3df03350391da6507499e2f76db41f","payload":{"connection_id":"f6725804f86a4c4eb588e4d5ed7db029","event_at":"2026-07-28T04:00:25.838000Z","event_type":"best_bid_ask","frame_hash":"0d1ecbbb8ded37748cf8f7d6101d9d6c92555ae96d27f1d878b1282d27827162","frame_index":0,"kind":"data","monotonic_ns":313212218281083,"payload":{"asset_id":"96600821790790307414914106093858868634329285205417149685270682748367152458577","best_ask":"0.56","best_bid":"0.54","event_type":"best_bid_ask","market":"0xd412ce774cfcf8dc9f71164aac78783978aac7b03871702a3b8a481bd9dc9688","spread":"0.02","timestamp":"1785211225838"},"payload_hash":"5ac452681832aa6adf54b1215c77f03f0bc5c3f0dc1ade974ebeb760cefa5c71","raw_frame":"{\"market\":\"0xd412ce774cfcf8dc9f71164aac78783978aac7b03871702a3b8a481bd9dc9688\", \"asset_id\":\"96600821790790307414914106093858868634329285205417149685270682748367152458577\", \"best_bid\":\"0.54\", \"best_ask\":\"0.56\", \"spread\":\"0.02\", \"timestamp\":\"1785211225838\", \"event_type\":\"best_bid_ask\"}","received_at":"2026-07-28T04:00:29.170156Z","schema_version":"clob-market-ws.best_bid_ask.v1","sequence":null,"server_hash":null,"server_timestamp":"1785211225838","session_id":"2d607381e3054cee91998cdf45a4231c","source":"clob_market_ws"},"received_at":"2026-07-28T04:00:29.170156Z","record_id":"67632a8bcecbe46a081c5705aa570aff6749b5b44ef3c7b684d4a2633b2e1e63","schema_fingerprint":"8488399f31b0337811b13b266be932db7062827c2470b78bd8e9e99bab51d17d","schema_version":"edge-lab-recorder.raw.v1","sequence":null,"source":"clob_market_ws"}
{"event_at":"2026-07-28T04:00:25.838000Z","event_fingerprint":"4590c18f5dafccf4be93585746b9b916e561a3472f221fff7d2b01cb42c1c246","payload":{"connection_id":"f6725804f86a4c4eb588e4d5ed7db029","event_at":"2026-07-28T04:00:25.838000Z","event_type":"price_change","frame_hash":"1c3e5206b3ae4fbc3bd5425a957c1277c4ca77804c64b58df19ed6565f91a087","frame_index":0,"kind":"data","monotonic_ns":313212223529875,"payload":{"event_type":"price_change","market":"0xd412ce774cfcf8dc9f71164aac78783978aac7b03871702a3b8a481bd9dc9688","price_changes":[{"asset_id":"96600821790790307414914106093858868634329285205417149685270682748367152458577","best_ask":"0.56","best_bid":"0.54","hash":"e5afe46b9bf0d033f26d707d826737ddfbecdc5b","price":"0.55","side":"BUY","size":"0"},{"asset_id":"107603864457683460275633293642179940881969192120168665300712204232021063124301","best_ask":"0.46","best_bid":"0.44","hash":"241dbe3f68076c9e4627e42fc38029ff561bab79","price":"0.45","side":"SELL","size":"0"}],"timestamp":"1785211225838"},"payload_hash":"03dc67f2d1edcee8de9e08277ad879c89c5863fb01f5a2f66acd8e7950e3b6ca","raw_frame":"{\"market\":\"0xd412ce774cfcf8dc9f71164aac78783978aac7b03871702a3b8a481bd9dc9688\", \"price_changes\":[{\"asset_id\":\"96600821790790307414914106093858868634329285205417149685270682748367152458577\", \"price\":\"0.55\", \"size\":\"0\", \"side\":\"BUY\", \"hash\":\"e5afe46b9bf0d033f26d707d826737ddfbecdc5b\", \"best_bid\":\"0.54\", \"best_ask\":\"0.56\"}, {\"asset_id\":\"107603864457683460275633293642179940881969192120168665300712204232021063124301\", \"price\":\"0.45\", \"size\":\"0\", \"side\":\"SELL\", \"hash\":\"241dbe3f68076c9e4627e42fc38029ff561bab79\", \"best_bid\":\"0.44\", \"best_ask\":\"0.46\"}], \"timestamp\":\"1785211225838\", \"event_type\":\"price_change\"}","received_at":"2026-07-28T04:00:29.175405Z","schema_version":"clob-market-ws.price_change.v1","sequence":null,"server_hash":null,"server_timestamp":"1785211225838","session_id":"2d607381e3054cee91998cdf45a4231c","source":"clob_market_ws"},"received_at":"2026-07-28T04:00:29.175405Z","record_id":"0978284ee22ae0ae8046470146f9f80840a96fe58e5cb3042758ba18d364cd3c","schema_fingerprint":"4aa3821a28b0b7c2400bc59aba4bcc0a76e971dadd19610d3ad38c768e124dc7","schema_version":"edge-lab-recorder.raw.v1","sequence":null,"source":"clob_market_ws"}
