{"event_at":"2026-07-28T04:07:44.789000Z","event_fingerprint":"7c9a98a6506efad0709bd3efd1313d4794b7b9517c450a8ef13ac1b0a9aef96f","payload":{"connection_id":"f6725804f86a4c4eb588e4d5ed7db029","event_at":"2026-07-28T04:07:44.789000Z","event_type":"price_change","frame_hash":"453ffee3d54f3e6e41fbcb3bf2670e01ef272c2f81a8c0178d70149f46ac7f17","frame_index":0,"kind":"data","monotonic_ns":313647726024666,"payload":{"event_type":"price_change","market":"0xd412ce774cfcf8dc9f71164aac78783978aac7b03871702a3b8a481bd9dc9688","price_changes":[{"asset_id":"107603864457683460275633293642179940881969192120168665300712204232021063124301","best_ask":"0.67","best_bid":"0.66","hash":"fa6d50b97274b7f799bd2b07eca984fdc69f54b7","price":"0.62","side":"BUY","size":"62.8"},{"asset_id":"96600821790790307414914106093858868634329285205417149685270682748367152458577","best_ask":"0.34","best_bid":"0.33","hash":"c4341fd3f93c24e3487573eb54c4ab88351b5c22","price":"0.38","side":"SELL","size":"62.8"}],"timestamp":"1785211664789"},"payload_hash":"e6b212c77cbd7aa59f0cef59e13ed5bc98882c639a7bdfa743b72e898747ff92","raw_frame":"{\"market\":\"0xd412ce774cfcf8dc9f71164aac78783978aac7b03871702a3b8a481bd9dc9688\", \"price_changes\":[{\"asset_id\":\"107603864457683460275633293642179940881969192120168665300712204232021063124301\", \"price\":\"0.62\", \"size\":\"62.8\", \"side\":\"BUY\", \"hash\":\"fa6d50b97274b7f799bd2b07eca984fdc69f54b7\", \"best_bid\":\"0.66\", \"best_ask\":\"0.67\"}, {\"asset_id\":\"96600821790790307414914106093858868634329285205417149685270682748367152458577\", \"price\":\"0.38\", \"size\":\"62.8\", \"side\":\"SELL\", \"hash\":\"c4341fd3f93c24e3487573eb54c4ab88351b5c22\", \"best_bid\":\"0.33\", \"best_ask\":\"0.34\"}], \"timestamp\":\"1785211664789\", \"event_type\":\"price_change\"}","received_at":"2026-07-28T04:07:44.674669Z","schema_version":"clob-market-ws.price_change.v1","sequence":null,"server_hash":null,"server_timestamp":"1785211664789","session_id":"2d607381e3054cee91998cdf45a4231c","source":"clob_market_ws"},"received_at":"2026-07-28T04:07:44.674669Z","record_id":"2a533f6ffbb0a3a2727eeb9ffa68b53db7a5fbb2598eb2adff22dd3d24ce4faf","schema_fingerprint":"4aa3821a28b0b7c2400bc59aba4bcc0a76e971dadd19610d3ad38c768e124dc7","schema_version":"edge-lab-recorder.raw.v1","sequence":null,"source":"clob_market_ws"}
{"event_at":"2026-07-28T04:07:44.790000Z","event_fingerprint":"eb43f0918cbc9c11c6f8af87a9caea07985b89af6a5123e64ee8b1e6c598e39c","payload":{"connection_id":"f6725804f86a4c4eb588e4d5ed7db029","event_at":"2026-07-28T04:07:44.790000Z","event_type":"price_change","frame_hash":"8a5be081b1b19a72c6e352a0388f314571e77639d6b5fa82d3256755504ff185","frame_index":0,"kind":"data","monotonic_ns":313647732918125,"payload":{"event_type":"price_change","market":"0xd412ce774cfcf8dc9f71164aac78783978aac7b03871702a3b8a481bd9dc9688","price_changes":[{"asset_id":"107603864457683460275633293642179940881969192120168665300712204232021063124301","best_ask":"0.67","best_bid":"0.66","hash":"40d18b20a60d3e2b5d3ec95aea5e74edd30f4f51","price":"0.01","side":"BUY","size":"5643.02"},{"asset_id":"96600821790790307414914106093858868634329285205417149685270682748367152458577","best_ask":"0.34","best_bid":"0.33","hash":"6ac2cfc527c54dff35026abf632ee6c6f134f86c","price":"0.99","side":"SELL","size":"5643.02"}],"timestamp":"1785211664790"},"payload_hash":"717a358b16ad4e7618ce84feef9eea75661cea1559c4615257fd9c59b3ed88d5","raw_frame":"{\"market\":\"0xd412ce774cfcf8dc9f71164aac78783978aac7b03871702a3b8a481bd9dc9688\", \"price_changes\":[{\"asset_id\":\"107603864457683460275633293642179940881969192120168665300712204232021063124301\", \"price\":\"0.01\", \"size\":\"5643.02\", \"side\":\"BUY\", \"hash\":\"40d18b20a60d3e2b5d3ec95aea5e74edd30f4f51\", \"best_bid\":\"0.66\", \"best_ask\":\"0.67\"}, {\"asset_id\":\"96600821790790307414914106093858868634329285205417149685270682748367152458577\", \"price\":\"0.99\", \"size\":\"5643.02\", \"side\":\"SELL\", \"hash\":\"6ac2cfc527c54dff35026abf632ee6c6f134f86c\", \"best_bid\":\"0.33\", \"best_ask\":\"0.34\"}], \"timestamp\":\"1785211664790\", \"event_type\":\"price_change\"}","received_at":"2026-07-28T04:07:44.681561Z","schema_version":"clob-market-ws.price_change.v1","sequence":null,"server_hash":null,"server_timestamp":"1785211664790","session_id":"2d607381e3054cee91998cdf45a4231c","source":"clob_market_ws"},"received_at":"2026-07-28T04:07:44.681561Z","record_id":"0ba02aea6a90a3d62f6062c289a951aeb3f7c671a2ab89eeb1b7da7df7f7abbb","schema_fingerprint":"4aa3821a28b0b7c2400bc59aba4bcc0a76e971dadd19610d3ad38c768e124dc7","schema_version":"edge-lab-recorder.raw.v1","sequence":null,"source":"clob_market_ws"}
{"event_at":"2026-07-28T04:07:44.791000Z","event_fingerprint":"fc06e78ccc564b86703aee94043ddaacd6fab2e707e8d043ecd136789a5d22b0","payload":{"connection_id":"f6725804f86a4c4eb588e4d5ed7db029","event_at":"2026-07-28T04:07:44.791000Z","event_type":"price_change","frame_hash":"16f5ec110cde2333d2b3726ea50fac15e8d2b921fb124ceff8fccc477259917d","frame_index":0,"kind":"data","monotonic_ns":313647735397958,"payload":{"event_type":"price_change","market":"0xd412ce774cfcf8dc9f71164aac78783978aac7b03871702a3b8a481bd9dc9688","price_changes":[{"asset_id":"107603864457683460275633293642179940881969192120168665300712204232021063124301","best_ask":"0.67","best_bid":"0.66","hash":"038965570c60e526c0bd88da8c4a0f07df924240","price":"0.01","side":"BUY","size":"5648.02"},{"asset_id":"96600821790790307414914106093858868634329285205417149685270682748367152458577","best_ask":"0.34","best_bid":"0.33","hash":"bcf11440059760da0fbd032c7fa0858f8bec8d01","price":"0.99","side":"SELL","size":"5648.02"}],"timestamp":"1785211664791"},"payload_hash":"a681595a7c33c7095aafbd3911f9d7594b2660c5348b50b8ba338b8bb3e3babc","raw_frame":"{\"market\":\"0xd412ce774cfcf8dc9f71164aac78783978aac7b03871702a3b8a481bd9dc9688\", \"price_changes\":[{\"asset_id\":\"107603864457683460275633293642179940881969192120168665300712204232021063124301\", \"price\":\"0.01\", \"size\":\"5648.02\", \"side\":\"BUY\", \"hash\":\"038965570c60e526c0bd88da8c4a0f07df924240\", \"best_bid\":\"0.66\", \"best_ask\":\"0.67\"}, {\"asset_id\":\"96600821790790307414914106093858868634329285205417149685270682748367152458577\", \"price\":\"0.99\", \"size\":\"5648.02\", \"side\":\"SELL\", \"hash\":\"bcf11440059760da0fbd032c7fa0858f8bec8d01\", \"best_bid\":\"0.33\", \"best_ask\":\"0.34\"}], \"timestamp\":\"1785211664791\", \"event_type\":\"price_change\"}","received_at":"2026-07-28T04:07:44.684041Z","schema_version":"clob-market-ws.price_change.v1","sequence":null,"server_hash":null,"server_timestamp":"1785211664791","session_id":"2d607381e3054cee91998cdf45a4231c","source":"clob_market_ws"},"received_at":"2026-07-28T04:07:44.684041Z","record_id":"7b2d7075dfbb4bb8bdf5483b27605e884708102abd94b958086aabdf2987cc73","schema_fingerprint":"4aa3821a28b0b7c2400bc59aba4bcc0a76e971dadd19610d3ad38c768e124dc7","schema_version":"edge-lab-recorder.raw.v1","sequence":null,"source":"clob_market_ws"}
{"event_at":"2026-07-28T04:07:44.808000Z","event_fingerprint":"62778dfdb5ec2eb8ff55f7d04477c313f7a1fbab643046a58a766fea50b13b23","payload":{"connection_id":"f6725804f86a4c4eb588e4d5ed7db029","event_at":"2026-07-28T04:07:44.808000Z","event_type":"price_change","frame_hash":"08fbc840868ab805377ea7ea68f2df0bb06f99ed1a92f07c2f34b4cb1abab1be","frame_index":0,"kind":"data","monotonic_ns":313647739180791,"payload":{"event_type":"price_change","market":"0xd412ce774cfcf8dc9f71164aac78783978aac7b03871702a3b8a481bd9dc9688","price_changes":[{"asset_id":"107603864457683460275633293642179940881969192120168665300712204232021063124301","best_ask":"0.67","best_bid":"0.66","hash":"1dfd530b257645d728e2c87d64917756899233d8","price":"0.01","side":"BUY","size":"5643.02"},{"asset_id":"96600821790790307414914106093858868634329285205417149685270682748367152458577","best_ask":"0.34","best_bid":"0.33","hash":"d0e4d204e720cc575ce94ca179b838e84944bb2d","price":"0.99","side":"SELL","size":"5643.02"}],"timestamp":"1785211664808"},"payload_hash":"eee6ed77a4d5a0dbcd29bc63b9c6493e07b07d801bcb81ba2669b53edb17a6b8","raw_frame":"{\"market\":\"0xd412ce774cfcf8dc9f71164aac78783978aac7b03871702a3b8a481bd9dc9688\", \"price_changes\":[{\"asset_id\":\"107603864457683460275633293642179940881969192120168665300712204232021063124301\", \"price\":\"0.01\", \"size\":\"5643.02\", \"side\":\"BUY\", \"hash\":\"1dfd530b257645d728e2c87d64917756899233d8\", \"best_bid\":\"0.66\", \"best_ask\":\"0.67\"}, {\"asset_id\":\"96600821790790307414914106093858868634329285205417149685270682748367152458577\", \"price\":\"0.99\", \"size\":\"5643.02\", \"side\":\"SELL\", \"hash\":\"d0e4d204e720cc575ce94ca179b838e84944bb2d\", \"best_bid\":\"0.33\", \"best_ask\":\"0.34\"}], \"timestamp\":\"1785211664808\", \"event_type\":\"price_change\"}","received_at":"2026-07-28T04:07:44.687825Z","schema_version":"clob-market-ws.price_change.v1","sequence":null,"server_hash":null,"server_timestamp":"1785211664808","session_id":"2d607381e3054cee91998cdf45a4231c","source":"clob_market_ws"},"received_at":"2026-07-28T04:07:44.687825Z","record_id":"bc5e37396474ff4ddadc80de30cb9c52f6f5cd615e311fa3b0792228bbd0ebab","schema_fingerprint":"4aa3821a28b0b7c2400bc59aba4bcc0a76e971dadd19610d3ad38c768e124dc7","schema_version":"edge-lab-recorder.raw.v1","sequence":null,"source":"clob_market_ws"}
{"event_at":"2026-07-28T04:07:44.811000Z","event_fingerprint":"bf924ad9fbfef37c53827d9096815675f21bc9bcd8f1a97f8e90c4e636a17836","payload":{"connection_id":"f6725804f86a4c4eb588e4d5ed7db029","event_at":"2026-07-28T04:07:44.811000Z","event_type":"price_change","frame_hash":"a70ad574868648c34a3eb66747af8776a6a44534185a2949a325c55b278c1914","frame_index":0,"kind":"data","monotonic_ns":313647742287375,"payload":{"event_type":"price_change","market":"0xd412ce774cfcf8dc9f71164aac78783978aac7b03871702a3b8a481bd9dc9688","price_changes":[{"asset_id":"107603864457683460275633293642179940881969192120168665300712204232021063124301","best_ask":"0.67","best_bid":"0.66","hash":"0d3ce1bca2214a7d5d306ac0fe2369b4ca677337","price":"0.01","side":"BUY","size":"5638.02"},{"asset_id":"96600821790790307414914106093858868634329285205417149685270682748367152458577","best_ask":"0.34","best_bid":"0.33","hash":"e9787de21b01f850b2cf0c43e017cdb84cfc87aa","price":"0.99","side":"SELL","size":"5638.02"}],"timestamp":"1785211664811"},"payload_hash":"6fac84367a86bde493f76cef094c4c10624f3f0fb5f2146c33018892f1d145ce","raw_frame":"{\"market\":\"0xd412ce774cfcf8dc9f71164aac78783978aac7b03871702a3b8a481bd9dc9688\", \"price_changes\":[{\"asset_id\":\"107603864457683460275633293642179940881969192120168665300712204232021063124301\", \"price\":\"0.01\", \"size\":\"5638.02\", \"side\":\"BUY\", \"hash\":\"0d3ce1bca2214a7d5d306ac0fe2369b4ca677337\", \"best_bid\":\"0.66\", \"best_ask\":\"0.67\"}, {\"asset_id\":\"96600821790790307414914106093858868634329285205417149685270682748367152458577\", \"price\":\"0.99\", \"size\":\"5638.02\", \"side\":\"SELL\", \"hash\":\"e9787de21b01f850b2cf0c43e017cdb84cfc87aa\", \"best_bid\":\"0.33\", \"best_ask\":\"0.34\"}], \"timestamp\":\"1785211664811\", \"event_type\":\"price_change\"}","received_at":"2026-07-28T04:07:44.690932Z","schema_version":"clob-market-ws.price_change.v1","sequence":null,"server_hash":null,"server_timestamp":"1785211664811","session_id":"2d607381e3054cee91998cdf45a4231c","source":"clob_market_ws"},"received_at":"2026-07-28T04:07:44.690932Z","record_id":"73b31ec2e1b98f71c7eaa9471511aea159777ccfbd233b8beb66a178abb5a526","schema_fingerprint":"4aa3821a28b0b7c2400bc59aba4bcc0a76e971dadd19610d3ad38c768e124dc7","schema_version":"edge-lab-recorder.raw.v1","sequence":null,"source":"clob_market_ws"}
{"event_at":"2026-07-28T04:07:44.811000Z","event_fingerprint":"0d57466be520d0929d1ab14c640bfa15902e62c68a534e46f2cf1e980b8d6cec","payload":{"connection_id":"f6725804f86a4c4eb588e4d5ed7db029","event_at":"2026-07-28T04:07:44.811000Z","event_type":"price_change","frame_hash":"e816e8d7e6329b760ceda80c7371d2a38403a78b2d666d56863d4b526b045651","frame_index":0,"kind":"data","monotonic_ns":313647745185250,"payload":{"event_type":"price_change","market":"0xd412ce774cfcf8dc9f71164aac78783978aac7b03871702a3b8a481bd9dc9688","price_changes":[{"asset_id":"96600821790790307414914106093858868634329285205417149685270682748367152458577","best_ask":"0.34","best_bid":"0.33","hash":"708fa33e770f00e137e944551ea58055255d317b","price":"0.37","side":"SELL","size":"30.6"},{"asset_id":"107603864457683460275633293642179940881969192120168665300712204232021063124301","best_ask":"0.67","best_bid":"0.66","hash":"df27252651715f550a2a7a0dc63a4328f61d75d9","price":"0.63","side":"BUY","size":"30.6"}],"timestamp":"1785211664811"},"payload_hash":"cc04c1a069c0f765bfd65fc80ea78159f894bc548966863751a9b8d8055a7651","raw_frame":"{\"market\":\"0xd412ce774cfcf8dc9f71164aac78783978aac7b03871702a3b8a481bd9dc9688\", \"price_changes\":[{\"asset_id\":\"96600821790790307414914106093858868634329285205417149685270682748367152458577\", \"price\":\"0.37\", \"size\":\"30.6\", \"side\":\"SELL\", \"hash\":\"708fa33e770f00e137e944551ea58055255d317b\", \"best_bid\":\"0.33\", \"best_ask\":\"0.34\"}, {\"asset_id\":\"107603864457683460275633293642179940881969192120168665300712204232021063124301\", \"price\":\"0.63\", \"size\":\"30.6\", \"side\":\"BUY\", \"hash\":\"df27252651715f550a2a7a0dc63a4328f61d75d9\", \"best_bid\":\"0.66\", \"best_ask\":\"0.67\"}], \"timestamp\":\"1785211664811\", \"event_type\":\"price_change\"}","received_at":"2026-07-28T04:07:44.693829Z","schema_version":"clob-market-ws.price_change.v1","sequence":null,"server_hash":null,"server_timestamp":"1785211664811","session_id":"2d607381e3054cee91998cdf45a4231c","source":"clob_market_ws"},"received_at":"2026-07-28T04:07:44.693829Z","record_id":"eeb2e19e0e20a3902d513e986b89ce49500eec57f2fcdc49d85e7829f2bf7218","schema_fingerprint":"4aa3821a28b0b7c2400bc59aba4bcc0a76e971dadd19610d3ad38c768e124dc7","schema_version":"edge-lab-recorder.raw.v1","sequence":null,"source":"clob_market_ws"}
{"event_at":"2026-07-28T04:07:44.812000Z","event_fingerprint":"f10987ddf35d20f2dcdb309d0bc927bd9e14cbc775027f8900c1c87d26ccc22a","payload":{"connection_id":"f6725804f86a4c4eb588e4d5ed7db029","event_at":"2026-07-28T04:07:44.812000Z","event_type":"price_change","frame_hash":"26b4ab2df5d197a9c6b586416ef6a0f7211989f91b12ae4c28e7d7fe642e2058","frame_index":0,"kind":"data","monotonic_ns":313647748392000,"payload":{"event_type":"price_change","market":"0xd412ce774cfcf8dc9f71164aac78783978aac7b03871702a3b8a481bd9dc9688","price_changes":[{"asset_id":"107603864457683460275633293642179940881969192120168665300712204232021063124301","best_ask":"0.67","best_bid":"0.66","hash":"3f1b5bd9982431baa86e8d217e40332be424aaa3","price":"0.63","side":"BUY","size":"55.6"},{"asset_id":"96600821790790307414914106093858868634329285205417149685270682748367152458577","best_ask":"0.34","best_bid":"0.33","hash":"cee467447ab5d2591f41e2b3e6592f29b0361344","price":"0.37","side":"SELL","size":"55.6"}],"timestamp":"1785211664812"},"payload_hash":"6d082c722a16ace5fbe673c405a09b8432353032e2a760559e18b5c501477cf1","raw_frame":"{\"market\":\"0xd412ce774cfcf8dc9f71164aac78783978aac7b03871702a3b8a481bd9dc9688\", \"price_changes\":[{\"asset_id\":\"107603864457683460275633293642179940881969192120168665300712204232021063124301\", \"price\":\"0.63\", \"size\":\"55.6\", \"side\":\"BUY\", \"hash\":\"3f1b5bd9982431baa86e8d217e40332be424aaa3\", \"best_bid\":\"0.66\", \"best_ask\":\"0.67\"}, {\"asset_id\":\"96600821790790307414914106093858868634329285205417149685270682748367152458577\", \"price\":\"0.37\", \"size\":\"55.6\", \"side\":\"SELL\", \"hash\":\"cee467447ab5d2591f41e2b3e6592f29b0361344\", \"best_bid\":\"0.33\", \"best_ask\":\"0.34\"}], \"timestamp\":\"1785211664812\", \"event_type\":\"price_change\"}","received_at":"2026-07-28T04:07:44.697036Z","schema_version":"clob-market-ws.price_change.v1","sequence":null,"server_hash":null,"server_timestamp":"1785211664812","session_id":"2d607381e3054cee91998cdf45a4231c","source":"clob_market_ws"},"received_at":"2026-07-28T04:07:44.697036Z","record_id":"b0cbc6525022ac80da7dee058789b15ab1101ed04829069f475ed213a91ca986","schema_fingerprint":"4aa3821a28b0b7c2400bc59aba4bcc0a76e971dadd19610d3ad38c768e124dc7","schema_version":"edge-lab-recorder.raw.v1","sequence":null,"source":"clob_market_ws"}
{"event_at":"2026-07-28T04:07:44.818000Z","event_fingerprint":"acd14910d9e1326f116a856b5af2faf0b16d847d0e93043ed80f6bb29bdaf4e2","payload":{"connection_id":"f6725804f86a4c4eb588e4d5ed7db029","event_at":"2026-07-28T04:07:44.818000Z","event_type":"price_change","frame_hash":"22b0e81a6ed8d7bc1650a1458e62c0837d4b6064df4b0bd69efee2bc9f2e3035","frame_index":0,"kind":"data","monotonic_ns":313647751292166,"payload":{"event_type":"price_change","market":"0xd412ce774cfcf8dc9f71164aac78783978aac7b03871702a3b8a481bd9dc9688","price_changes":[{"asset_id":"107603864457683460275633293642179940881969192120168665300712204232021063124301","best_ask":"0.67","best_bid":"0.66","hash":"6a58f7504fda0eda1d7bdae860068662c5b7950c","price":"0.04","side":"BUY","size":"618.09"},{"asset_id":"96600821790790307414914106093858868634329285205417149685270682748367152458577","best_ask":"0.34","best_bid":"0.33","hash":"35a42ff80c4e93cb0271e1406235e2f7e1b925ce","price":"0.96","side":"SELL","size":"618.09"}],"timestamp":"1785211664818"},"payload_hash":"ee069a412efee18e7f1dcecd7b6a7caf6c1b5062dbb1a93d445fa00b7040f56c","raw_frame":"{\"market\":\"0xd412ce774cfcf8dc9f71164aac78783978aac7b03871702a3b8a481bd9dc9688\", \"price_changes\":[{\"asset_id\":\"107603864457683460275633293642179940881969192120168665300712204232021063124301\", \"price\":\"0.04\", \"size\":\"618.09\", \"side\":\"BUY\", \"hash\":\"6a58f7504fda0eda1d7bdae860068662c5b7950c\", \"best_bid\":\"0.66\", \"best_ask\":\"0.67\"}, {\"asset_id\":\"96600821790790307414914106093858868634329285205417149685270682748367152458577\", \"price\":\"0.96\", \"size\":\"618.09\", \"side\":\"SELL\", \"hash\":\"35a42ff80c4e93cb0271e1406235e2f7e1b925ce\", \"best_bid\":\"0.33\", \"best_ask\":\"0.34\"}], \"timestamp\":\"1785211664818\", \"event_type\":\"price_change\"}","received_at":"2026-07-28T04:07:44.699936Z","schema_version":"clob-market-ws.price_change.v1","sequence":null,"server_hash":null,"server_timestamp":"1785211664818","session_id":"2d607381e3054cee91998cdf45a4231c","source":"clob_market_ws"},"received_at":"2026-07-28T04:07:44.699936Z","record_id":"733312ee75777cd110cefcfac01a85e73526eb50c29b6a34d972cf695e2d4e9c","schema_fingerprint":"4aa3821a28b0b7c2400bc59aba4bcc0a76e971dadd19610d3ad38c768e124dc7","schema_version":"edge-lab-recorder.raw.v1","sequence":null,"source":"clob_market_ws"}
{"event_at":"2026-07-28T04:07:44.837000Z","event_fingerprint":"f6faff82f7441ade1fbe12442895b6d3a5063ba9e1b3be814740944938619437","payload":{"connection_id":"f6725804f86a4c4eb588e4d5ed7db029","event_at":"2026-07-28T04:07:44.837000Z","event_type":"price_change","frame_hash":"421362240e310f30c9edfe855aee01cef4428862d424de1d6b77e43c79f68f49","frame_index":0,"kind":"data","monotonic_ns":313647754319333,"payload":{"event_type":"price_change","market":"0xd412ce774cfcf8dc9f71164aac78783978aac7b03871702a3b8a481bd9dc9688","price_changes":[{"asset_id":"107603864457683460275633293642179940881969192120168665300712204232021063124301","best_ask":"0.67","best_bid":"0.66","hash":"2e6573acadb36071f95f0be2ac8385d7d4b6ba77","price":"0.4","side":"BUY","size":"243.16"},{"asset_id":"96600821790790307414914106093858868634329285205417149685270682748367152458577","best_ask":"0.34","best_bid":"0.33","hash":"0e63f09a711f63d6e169ee792646dcce2ff3407b","price":"0.6","side":"SELL","size":"243.16"}],"timestamp":"1785211664837"},"payload_hash":"94dfd1294130b33ee2a9637e5d504e508cb0a1bdef196d1abd5131ee3a60951c","raw_frame":"{\"market\":\"0xd412ce774cfcf8dc9f71164aac78783978aac7b03871702a3b8a481bd9dc9688\", \"price_changes\":[{\"asset_id\":\"107603864457683460275633293642179940881969192120168665300712204232021063124301\", \"price\":\"0.4\", \"size\":\"243.16\", \"side\":\"BUY\", \"hash\":\"2e6573acadb36071f95f0be2ac8385d7d4b6ba77\", \"best_bid\":\"0.66\", \"best_ask\":\"0.67\"}, {\"asset_id\":\"96600821790790307414914106093858868634329285205417149685270682748367152458577\", \"price\":\"0.6\", \"size\":\"243.16\", \"side\":\"SELL\", \"hash\":\"0e63f09a711f63d6e169ee792646dcce2ff3407b\", \"best_bid\":\"0.33\", \"best_ask\":\"0.34\"}], \"timestamp\":\"1785211664837\", \"event_type\":\"price_change\"}","received_at":"2026-07-28T04:07:44.702964Z","schema_version":"clob-market-ws.price_change.v1","sequence":null,"server_hash":null,"server_timestamp":"1785211664837","session_id":"2d607381e3054cee91998cdf45a4231c","source":"clob_market_ws"},"received_at":"2026-07-28T04:07:44.702964Z","record_id":"de0917f4aa8661193941d3d17f1859f8f5ba9fdf1d7dc2984492b5da612ed27b","schema_fingerprint":"4aa3821a28b0b7c2400bc59aba4bcc0a76e971dadd19610d3ad38c768e124dc7","schema_version":"edge-lab-recorder.raw.v1","sequence":null,"source":"clob_market_ws"}
{"event_at":"2026-07-28T04:07:44.840000Z","event_fingerprint":"9b1c4082a39062f18985d90e69247fc086fa761e21880091c3e833a3d063b77d","payload":{"connection_id":"f6725804f86a4c4eb588e4d5ed7db029","event_at":"2026-07-28T04:07:44.840000Z","event_type":"price_change","frame_hash":"fdafa00704e1422e541242bf4d4e79e69fa1ff37f0b188d7bad3315378cfc439","frame_index":0,"kind":"data","monotonic_ns":313647757315041,"payload":{"event_type":"price_change","market":"0xd412ce774cfcf8dc9f71164aac78783978aac7b03871702a3b8a481bd9dc9688","price_changes":[{"asset_id":"96600821790790307414914106093858868634329285205417149685270682748367152458577","best_ask":"0.34","best_bid":"0.33","hash":"94584acbfdb2ba1821e1fd70668fef6c82fe6488","price":"0.14","side":"BUY","size":"424.9"},{"asset_id":"107603864457683460275633293642179940881969192120168665300712204232021063124301","best_ask":"0.67","best_bid":"0.66","hash":"ba4e47ad4e83c97c7e785c1614b923fe886faf63","price":"0.86","side":"SELL","size":"424.9"}],"timestamp":"1785211664840"},"payload_hash":"0e9289d67b0d0dabce99a31afc14c060fe27ba92fbe4594a38d2d242a1421be5","raw_frame":"{\"market\":\"0xd412ce774cfcf8dc9f71164aac78783978aac7b03871702a3b8a481bd9dc9688\", \"price_changes\":[{\"asset_id\":\"96600821790790307414914106093858868634329285205417149685270682748367152458577\", \"price\":\"0.14\", \"size\":\"424.9\", \"side\":\"BUY\", \"hash\":\"94584acbfdb2ba1821e1fd70668fef6c82fe6488\", \"best_bid\":\"0.33\", \"best_ask\":\"0.34\"}, {\"asset_id\":\"107603864457683460275633293642179940881969192120168665300712204232021063124301\", \"price\":\"0.86\", \"size\":\"424.9\", \"side\":\"SELL\", \"hash\":\"ba4e47ad4e83c97c7e785c1614b923fe886faf63\", \"best_bid\":\"0.66\", \"best_ask\":\"0.67\"}], \"timestamp\":\"1785211664840\", \"event_type\":\"price_change\"}","received_at":"2026-07-28T04:07:44.705959Z","schema_version":"clob-market-ws.price_change.v1","sequence":null,"server_hash":null,"server_timestamp":"1785211664840","session_id":"2d607381e3054cee91998cdf45a4231c","source":"clob_market_ws"},"received_at":"2026-07-28T04:07:44.705959Z","record_id":"c96c0f46061ec910e0b949247c417a8a2572bd4b74b2dd6becb32bf454b29030","schema_fingerprint":"4aa3821a28b0b7c2400bc59aba4bcc0a76e971dadd19610d3ad38c768e124dc7","schema_version":"edge-lab-recorder.raw.v1","sequence":null,"source":"clob_market_ws"}
{"event_at":"2026-07-28T04:07:44.841000Z","event_fingerprint":"cdc046ef79e73cd8e4c3849a983ee735aa2d7bb2bacb00ae73e615fec733e818","payload":{"connection_id":"f6725804f86a4c4eb588e4d5ed7db029","event_at":"2026-07-28T04:07:44.841000Z","event_type":"price_change","frame_hash":"3cb5cee224637218b8e3e018c1c2544248807feaab5273334905c6c360346f03","frame_index":0,"kind":"data","monotonic_ns":313647760353791,"payload":{"event_type":"price_change","market":"0xd412ce774cfcf8dc9f71164aac78783978aac7b03871702a3b8a481bd9dc9688","price_changes":[{"asset_id":"107603864457683460275633293642179940881969192120168665300712204232021063124301","best_ask":"0.67","best_bid":"0.66","hash":"ff47795727bbd6752de9ca909e596a85180cf0f1","price":"0.4","side":"BUY","size":"159.83"},{"asset_id":"96600821790790307414914106093858868634329285205417149685270682748367152458577","best_ask":"0.34","best_bid":"0.33","hash":"7b39bf4284ed19cf59ecad62cedb60b14d261b10","price":"0.6","side":"SELL","size":"159.83"}],"timestamp":"1785211664841"},"payload_hash":"4f010acd681598fd859e0176f03bc87ddb648e4510d7b2a7ea0d9f1748d1a68a","raw_frame":"{\"market\":\"0xd412ce774cfcf8dc9f71164aac78783978aac7b03871702a3b8a481bd9dc9688\", \"price_changes\":[{\"asset_id\":\"107603864457683460275633293642179940881969192120168665300712204232021063124301\", \"price\":\"0.4\", \"size\":\"159.83\", \"side\":\"BUY\", \"hash\":\"ff47795727bbd6752de9ca909e596a85180cf0f1\", \"best_bid\":\"0.66\", \"best_ask\":\"0.67\"}, {\"asset_id\":\"96600821790790307414914106093858868634329285205417149685270682748367152458577\", \"price\":\"0.6\", \"size\":\"159.83\", \"side\":\"SELL\", \"hash\":\"7b39bf4284ed19cf59ecad62cedb60b14d261b10\", \"best_bid\":\"0.33\", \"best_ask\":\"0.34\"}], \"timestamp\":\"1785211664841\", \"event_type\":\"price_change\"}","received_at":"2026-07-28T04:07:44.708998Z","schema_version":"clob-market-ws.price_change.v1","sequence":null,"server_hash":null,"server_timestamp":"1785211664841","session_id":"2d607381e3054cee91998cdf45a4231c","source":"clob_market_ws"},"received_at":"2026-07-28T04:07:44.708998Z","record_id":"aab2908ebe90b217c26d1658ae1808cd9c8e2ed99044f67cfbd040e48ceeb98f","schema_fingerprint":"4aa3821a28b0b7c2400bc59aba4bcc0a76e971dadd19610d3ad38c768e124dc7","schema_version":"edge-lab-recorder.raw.v1","sequence":null,"source":"clob_market_ws"}
{"event_at":"2026-07-28T04:07:44.843000Z","event_fingerprint":"f5eb807b2573337ed91d19235293032ae8091ae068666a9ed3ffa285ee65c745","payload":{"connection_id":"f6725804f86a4c4eb588e4d5ed7db029","event_at":"2026-07-28T04:07:44.843000Z","event_type":"price_change","frame_hash":"f2550968f040282f129f26794be19215e933726cb519a479380030759d4c7a30","frame_index":0,"kind":"data","monotonic_ns":313647763417166,"payload":{"event_type":"price_change","market":"0xd412ce774cfcf8dc9f71164aac78783978aac7b03871702a3b8a481bd9dc9688","price_changes":[{"asset_id":"96600821790790307414914106093858868634329285205417149685270682748367152458577","best_ask":"0.34","best_bid":"0.33","hash":"9ac4aa12d613b794e3a4d37e0ac933a803a5c39d","price":"0.14","side":"BUY","size":"229.9"},{"asset_id":"107603864457683460275633293642179940881969192120168665300712204232021063124301","best_ask":"0.67","best_bid":"0.66","hash":"1545331590ec78e382023f8a659b5cf0407e56a9","price":"0.86","side":"SELL","size":"229.9"}],"timestamp":"1785211664843"},"payload_hash":"590c755dece31ef6a5da86aa49981b79a71afc9ccb6a101effa55640deedf991","raw_frame":"{\"market\":\"0xd412ce774cfcf8dc9f71164aac78783978aac7b03871702a3b8a481bd9dc9688\", \"price_changes\":[{\"asset_id\":\"96600821790790307414914106093858868634329285205417149685270682748367152458577\", \"price\":\"0.14\", \"size\":\"229.9\", \"side\":\"BUY\", \"hash\":\"9ac4aa12d613b794e3a4d37e0ac933a803a5c39d\", \"best_bid\":\"0.33\", \"best_ask\":\"0.34\"}, {\"asset_id\":\"107603864457683460275633293642179940881969192120168665300712204232021063124301\", \"price\":\"0.86\", \"size\":\"229.9\", \"side\":\"SELL\", \"hash\":\"1545331590ec78e382023f8a659b5cf0407e56a9\", \"best_bid\":\"0.66\", \"best_ask\":\"0.67\"}], \"timestamp\":\"1785211664843\", \"event_type\":\"price_change\"}","received_at":"2026-07-28T04:07:44.712061Z","schema_version":"clob-market-ws.price_change.v1","sequence":null,"server_hash":null,"server_timestamp":"1785211664843","session_id":"2d607381e3054cee91998cdf45a4231c","source":"clob_market_ws"},"received_at":"2026-07-28T04:07:44.712061Z","record_id":"efe8e06af047fb9519856ca49907c36a4fb63fbc472cf3a0f43efac3e3219beb","schema_fingerprint":"4aa3821a28b0b7c2400bc59aba4bcc0a76e971dadd19610d3ad38c768e124dc7","schema_version":"edge-lab-recorder.raw.v1","sequence":null,"source":"clob_market_ws"}
{"event_at":"2026-07-28T04:07:44.846000Z","event_fingerprint":"b9dfe3f1542439bd8f5f4c89c42eef086a11827ac063ea7e02380ba24465e965","payload":{"connection_id":"f6725804f86a4c4eb588e4d5ed7db029","event_at":"2026-07-28T04:07:44.846000Z","event_type":"price_change","frame_hash":"59039c4824c556b84a373c3cf52f13db76492749733a7624213c01f071c9a56e","frame_index":0,"kind":"data","monotonic_ns":313647766504375,"payload":{"event_type":"price_change","market":"0xd412ce774cfcf8dc9f71164aac78783978aac7b03871702a3b8a481bd9dc9688","price_changes":[{"asset_id":"107603864457683460275633293642179940881969192120168665300712204232021063124301","best_ask":"0.67","best_bid":"0.66","hash":"f5e0cdf67feb4274bd499633c3d8233ff109c036","price":"0.4","side":"BUY","size":"76.5"},{"asset_id":"96600821790790307414914106093858868634329285205417149685270682748367152458577","best_ask":"0.34","best_bid":"0.33","hash":"72df3c30c97f90125d84bf8b827a415dc1e12b87","price":"0.6","side":"SELL","size":"76.5"}],"timestamp":"1785211664846"},"payload_hash":"fec708f405002973453d2453224d9c9d3d0a7859e12b625c2ff50bd5e0a2f272","raw_frame":"{\"market\":\"0xd412ce774cfcf8dc9f71164aac78783978aac7b03871702a3b8a481bd9dc9688\", \"price_changes\":[{\"asset_id\":\"107603864457683460275633293642179940881969192120168665300712204232021063124301\", \"price\":\"0.4\", \"size\":\"76.5\", \"side\":\"BUY\", \"hash\":\"f5e0cdf67feb4274bd499633c3d8233ff109c036\", \"best_bid\":\"0.66\", \"best_ask\":\"0.67\"}, {\"asset_id\":\"96600821790790307414914106093858868634329285205417149685270682748367152458577\", \"price\":\"0.6\", \"size\":\"76.5\", \"side\":\"SELL\", \"hash\":\"72df3c30c97f90125d84bf8b827a415dc1e12b87\", \"best_bid\":\"0.33\", \"best_ask\":\"0.34\"}], \"timestamp\":\"1785211664846\", \"event_type\":\"price_change\"}","received_at":"2026-07-28T04:07:44.715148Z","schema_version":"clob-market-ws.price_change.v1","sequence":null,"server_hash":null,"server_timestamp":"1785211664846","session_id":"2d607381e3054cee91998cdf45a4231c","source":"clob_market_ws"},"received_at":"2026-07-28T04:07:44.715148Z","record_id":"c0b80b8a8ac648e82790970c778911adc64e64527ff363d86ef6db679dcbfbdc","schema_fingerprint":"4aa3821a28b0b7c2400bc59aba4bcc0a76e971dadd19610d3ad38c768e124dc7","schema_version":"edge-lab-recorder.raw.v1","sequence":null,"source":"clob_market_ws"}
