{"event_at":"2026-07-28T04:13:40.493000Z","event_fingerprint":"561cad07501ec5187be2902c116790df2f8ccb96469099e18de1a814e8768352","payload":{"connection_id":"f6725804f86a4c4eb588e4d5ed7db029","event_at":"2026-07-28T04:13:40.493000Z","event_type":"price_change","frame_hash":"c57cddc83e1636cbc6ca6e7e9b922d5da7434fab98598d80e958b825ecd803ef","frame_index":0,"kind":"data","monotonic_ns":314004753025166,"payload":{"event_type":"price_change","market":"0xd412ce774cfcf8dc9f71164aac78783978aac7b03871702a3b8a481bd9dc9688","price_changes":[{"asset_id":"107603864457683460275633293642179940881969192120168665300712204232021063124301","best_ask":"0.39","best_bid":"0.35","hash":"5e39c08c97d59fc2662fd4599482941a7c7cf7e8","price":"0.32","side":"BUY","size":"113"},{"asset_id":"96600821790790307414914106093858868634329285205417149685270682748367152458577","best_ask":"0.65","best_bid":"0.61","hash":"cee4737a63ac78b69637fdc29bd63a49f9041017","price":"0.68","side":"SELL","size":"113"}],"timestamp":"1785212020493"},"payload_hash":"8d3b565c302d35ada918a46f4e6e38e7ecbe6168ed2452f146f1d272edb2e034","raw_frame":"{\"market\":\"0xd412ce774cfcf8dc9f71164aac78783978aac7b03871702a3b8a481bd9dc9688\", \"price_changes\":[{\"asset_id\":\"107603864457683460275633293642179940881969192120168665300712204232021063124301\", \"price\":\"0.32\", \"size\":\"113\", \"side\":\"BUY\", \"hash\":\"5e39c08c97d59fc2662fd4599482941a7c7cf7e8\", \"best_bid\":\"0.35\", \"best_ask\":\"0.39\"}, {\"asset_id\":\"96600821790790307414914106093858868634329285205417149685270682748367152458577\", \"price\":\"0.68\", \"size\":\"113\", \"side\":\"SELL\", \"hash\":\"cee4737a63ac78b69637fdc29bd63a49f9041017\", \"best_bid\":\"0.61\", \"best_ask\":\"0.65\"}], \"timestamp\":\"1785212020493\", \"event_type\":\"price_change\"}","received_at":"2026-07-28T04:13:41.674888Z","schema_version":"clob-market-ws.price_change.v1","sequence":null,"server_hash":null,"server_timestamp":"1785212020493","session_id":"2d607381e3054cee91998cdf45a4231c","source":"clob_market_ws"},"received_at":"2026-07-28T04:13:41.674888Z","record_id":"37dc99882bf1d5496535068ee5585ac24fb831228c828a36749794b5d454fe24","schema_fingerprint":"4aa3821a28b0b7c2400bc59aba4bcc0a76e971dadd19610d3ad38c768e124dc7","schema_version":"edge-lab-recorder.raw.v1","sequence":null,"source":"clob_market_ws"}
{"event_at":"2026-07-28T04:13:40.497000Z","event_fingerprint":"1cafe375fdbc84aea257487f3dae19489c8edc07bdef16ad9e6ec9706fb8cbc7","payload":{"connection_id":"f6725804f86a4c4eb588e4d5ed7db029","event_at":"2026-07-28T04:13:40.497000Z","event_type":"price_change","frame_hash":"31226415e1596236e5b1f7362330eabb6bfa810c36412b4318546e569588e319","frame_index":0,"kind":"data","monotonic_ns":314004757959083,"payload":{"event_type":"price_change","market":"0xd412ce774cfcf8dc9f71164aac78783978aac7b03871702a3b8a481bd9dc9688","price_changes":[{"asset_id":"96600821790790307414914106093858868634329285205417149685270682748367152458577","best_ask":"0.65","best_bid":"0.61","hash":"75e83945a65b34667381938f17851f7d7a4db6c8","price":"0.01","side":"BUY","size":"5295.02"},{"asset_id":"107603864457683460275633293642179940881969192120168665300712204232021063124301","best_ask":"0.39","best_bid":"0.35","hash":"7fc3ecc8844958bacdfbee1cf4777f8467de7f0b","price":"0.99","side":"SELL","size":"5295.02"}],"timestamp":"1785212020497"},"payload_hash":"e13bc1d41ae2ceb5311b357bedd92c38c1fadc3f7685a055c72ec082ea2e9683","raw_frame":"{\"market\":\"0xd412ce774cfcf8dc9f71164aac78783978aac7b03871702a3b8a481bd9dc9688\", \"price_changes\":[{\"asset_id\":\"96600821790790307414914106093858868634329285205417149685270682748367152458577\", \"price\":\"0.01\", \"size\":\"5295.02\", \"side\":\"BUY\", \"hash\":\"75e83945a65b34667381938f17851f7d7a4db6c8\", \"best_bid\":\"0.61\", \"best_ask\":\"0.65\"}, {\"asset_id\":\"107603864457683460275633293642179940881969192120168665300712204232021063124301\", \"price\":\"0.99\", \"size\":\"5295.02\", \"side\":\"SELL\", \"hash\":\"7fc3ecc8844958bacdfbee1cf4777f8467de7f0b\", \"best_bid\":\"0.35\", \"best_ask\":\"0.39\"}], \"timestamp\":\"1785212020497\", \"event_type\":\"price_change\"}","received_at":"2026-07-28T04:13:41.679829Z","schema_version":"clob-market-ws.price_change.v1","sequence":null,"server_hash":null,"server_timestamp":"1785212020497","session_id":"2d607381e3054cee91998cdf45a4231c","source":"clob_market_ws"},"received_at":"2026-07-28T04:13:41.679829Z","record_id":"e71961f0a0ace690be5028f31c7f852047283d55fae1da3b2d3d6987717bb25f","schema_fingerprint":"4aa3821a28b0b7c2400bc59aba4bcc0a76e971dadd19610d3ad38c768e124dc7","schema_version":"edge-lab-recorder.raw.v1","sequence":null,"source":"clob_market_ws"}
{"event_at":"2026-07-28T04:13:40.497000Z","event_fingerprint":"d03386255b55156a3c5b3bc3f479357c570079c1d608af5621d64bfdaa60a678","payload":{"connection_id":"f6725804f86a4c4eb588e4d5ed7db029","event_at":"2026-07-28T04:13:40.497000Z","event_type":"price_change","frame_hash":"0e0b6a780f8e36346216740023a05257c524be4c4f080e2720432a614e12de9d","frame_index":0,"kind":"data","monotonic_ns":314004761332750,"payload":{"event_type":"price_change","market":"0xd412ce774cfcf8dc9f71164aac78783978aac7b03871702a3b8a481bd9dc9688","price_changes":[{"asset_id":"96600821790790307414914106093858868634329285205417149685270682748367152458577","best_ask":"0.65","best_bid":"0.61","hash":"a36d56f8f94ddac5c1fb878355b02f2007b2a05e","price":"0.68","side":"SELL","size":"88"},{"asset_id":"107603864457683460275633293642179940881969192120168665300712204232021063124301","best_ask":"0.39","best_bid":"0.35","hash":"f372f96b5bacafb753cda67cc8d2e65dcdcb6da1","price":"0.32","side":"BUY","size":"88"}],"timestamp":"1785212020497"},"payload_hash":"181a336f1a2c018299e9db8038051fb71229743e07f8fa4d5b02915d4cd28f46","raw_frame":"{\"market\":\"0xd412ce774cfcf8dc9f71164aac78783978aac7b03871702a3b8a481bd9dc9688\", \"price_changes\":[{\"asset_id\":\"96600821790790307414914106093858868634329285205417149685270682748367152458577\", \"price\":\"0.68\", \"size\":\"88\", \"side\":\"SELL\", \"hash\":\"a36d56f8f94ddac5c1fb878355b02f2007b2a05e\", \"best_bid\":\"0.61\", \"best_ask\":\"0.65\"}, {\"asset_id\":\"107603864457683460275633293642179940881969192120168665300712204232021063124301\", \"price\":\"0.32\", \"size\":\"88\", \"side\":\"BUY\", \"hash\":\"f372f96b5bacafb753cda67cc8d2e65dcdcb6da1\", \"best_bid\":\"0.35\", \"best_ask\":\"0.39\"}], \"timestamp\":\"1785212020497\", \"event_type\":\"price_change\"}","received_at":"2026-07-28T04:13:41.683196Z","schema_version":"clob-market-ws.price_change.v1","sequence":null,"server_hash":null,"server_timestamp":"1785212020497","session_id":"2d607381e3054cee91998cdf45a4231c","source":"clob_market_ws"},"received_at":"2026-07-28T04:13:41.683196Z","record_id":"41c7d668a505a4fec5cd2960de05f62e6fe865f7c1127ebbdbd1ce4ad5234513","schema_fingerprint":"4aa3821a28b0b7c2400bc59aba4bcc0a76e971dadd19610d3ad38c768e124dc7","schema_version":"edge-lab-recorder.raw.v1","sequence":null,"source":"clob_market_ws"}
{"event_at":"2026-07-28T04:13:40.517000Z","event_fingerprint":"7d2c706a3530c45a658038cfbd35acb54da46b2344b8e4b765decb98968f62cb","payload":{"connection_id":"f6725804f86a4c4eb588e4d5ed7db029","event_at":"2026-07-28T04:13:40.517000Z","event_type":"price_change","frame_hash":"b4c392126e08b00e039f8a9dbebe9bc3bf3e18bffeeb0d5bb8f7f5b84e40fb9e","frame_index":0,"kind":"data","monotonic_ns":314004763744916,"payload":{"event_type":"price_change","market":"0xd412ce774cfcf8dc9f71164aac78783978aac7b03871702a3b8a481bd9dc9688","price_changes":[{"asset_id":"107603864457683460275633293642179940881969192120168665300712204232021063124301","best_ask":"0.39","best_bid":"0.35","hash":"e95c071a43c06689849d7b69fdbf28334d83eea1","price":"0.31","side":"BUY","size":"145"},{"asset_id":"96600821790790307414914106093858868634329285205417149685270682748367152458577","best_ask":"0.65","best_bid":"0.61","hash":"6a06f152c66c06856883ff457545bb91ea3589ff","price":"0.69","side":"SELL","size":"145"}],"timestamp":"1785212020517"},"payload_hash":"56f55176e58602d36f497508965132085e83524ceb0d403e70753d8a1bd36548","raw_frame":"{\"market\":\"0xd412ce774cfcf8dc9f71164aac78783978aac7b03871702a3b8a481bd9dc9688\", \"price_changes\":[{\"asset_id\":\"107603864457683460275633293642179940881969192120168665300712204232021063124301\", \"price\":\"0.31\", \"size\":\"145\", \"side\":\"BUY\", \"hash\":\"e95c071a43c06689849d7b69fdbf28334d83eea1\", \"best_bid\":\"0.35\", \"best_ask\":\"0.39\"}, {\"asset_id\":\"96600821790790307414914106093858868634329285205417149685270682748367152458577\", \"price\":\"0.69\", \"size\":\"145\", \"side\":\"SELL\", \"hash\":\"6a06f152c66c06856883ff457545bb91ea3589ff\", \"best_bid\":\"0.61\", \"best_ask\":\"0.65\"}], \"timestamp\":\"1785212020517\", \"event_type\":\"price_change\"}","received_at":"2026-07-28T04:13:41.685609Z","schema_version":"clob-market-ws.price_change.v1","sequence":null,"server_hash":null,"server_timestamp":"1785212020517","session_id":"2d607381e3054cee91998cdf45a4231c","source":"clob_market_ws"},"received_at":"2026-07-28T04:13:41.685609Z","record_id":"ab6eed2047a40f0f0d8409157e6234b8c855d200c67639b67397be98836fbe19","schema_fingerprint":"4aa3821a28b0b7c2400bc59aba4bcc0a76e971dadd19610d3ad38c768e124dc7","schema_version":"edge-lab-recorder.raw.v1","sequence":null,"source":"clob_market_ws"}
{"event_at":"2026-07-28T04:13:40.519000Z","event_fingerprint":"68419d1af9d8a48fbd32ad3cf4de2118645a5f8d5553c6654b76a3a66d370781","payload":{"connection_id":"f6725804f86a4c4eb588e4d5ed7db029","event_at":"2026-07-28T04:13:40.519000Z","event_type":"price_change","frame_hash":"ee904a502994c591f0808ae5d77aa2eba5c8d2adf59368c0d5f9d4be03e4ab89","frame_index":0,"kind":"data","monotonic_ns":314004765830833,"payload":{"event_type":"price_change","market":"0xd412ce774cfcf8dc9f71164aac78783978aac7b03871702a3b8a481bd9dc9688","price_changes":[{"asset_id":"96600821790790307414914106093858868634329285205417149685270682748367152458577","best_ask":"0.65","best_bid":"0.61","hash":"43c32e4538a135e5ff00b26ee6d35f91ca6f8400","price":"0.69","side":"SELL","size":"170"},{"asset_id":"107603864457683460275633293642179940881969192120168665300712204232021063124301","best_ask":"0.39","best_bid":"0.35","hash":"001cb8c5712bee5e7c3d77c7859502a4afa60720","price":"0.31","side":"BUY","size":"170"}],"timestamp":"1785212020519"},"payload_hash":"efb8bf3cdcc2fef73ebf07375d2b0ec40e5edb53ebeb8d75eadd7f10d6738155","raw_frame":"{\"market\":\"0xd412ce774cfcf8dc9f71164aac78783978aac7b03871702a3b8a481bd9dc9688\", \"price_changes\":[{\"asset_id\":\"96600821790790307414914106093858868634329285205417149685270682748367152458577\", \"price\":\"0.69\", \"size\":\"170\", \"side\":\"SELL\", \"hash\":\"43c32e4538a135e5ff00b26ee6d35f91ca6f8400\", \"best_bid\":\"0.61\", \"best_ask\":\"0.65\"}, {\"asset_id\":\"107603864457683460275633293642179940881969192120168665300712204232021063124301\", \"price\":\"0.31\", \"size\":\"170\", \"side\":\"BUY\", \"hash\":\"001cb8c5712bee5e7c3d77c7859502a4afa60720\", \"best_bid\":\"0.35\", \"best_ask\":\"0.39\"}], \"timestamp\":\"1785212020519\", \"event_type\":\"price_change\"}","received_at":"2026-07-28T04:13:41.687700Z","schema_version":"clob-market-ws.price_change.v1","sequence":null,"server_hash":null,"server_timestamp":"1785212020519","session_id":"2d607381e3054cee91998cdf45a4231c","source":"clob_market_ws"},"received_at":"2026-07-28T04:13:41.687700Z","record_id":"8e33cfb92c9761ca0b1619c5cf275783864c9ecded02149bcfa0bffe23555b29","schema_fingerprint":"4aa3821a28b0b7c2400bc59aba4bcc0a76e971dadd19610d3ad38c768e124dc7","schema_version":"edge-lab-recorder.raw.v1","sequence":null,"source":"clob_market_ws"}
{"event_at":"2026-07-28T04:13:40.534000Z","event_fingerprint":"2ccee6036b779001b8682b0a10ded348d96be7bc070e740724ed7975bbf57e0a","payload":{"connection_id":"f6725804f86a4c4eb588e4d5ed7db029","event_at":"2026-07-28T04:13:40.534000Z","event_type":"price_change","frame_hash":"35d8c71d51c11bff725f85ba6e4a7ff3428166e34dce6ea58da8f9790e2f1fad","frame_index":0,"kind":"data","monotonic_ns":314004766904166,"payload":{"event_type":"price_change","market":"0xd412ce774cfcf8dc9f71164aac78783978aac7b03871702a3b8a481bd9dc9688","price_changes":[{"asset_id":"107603864457683460275633293642179940881969192120168665300712204232021063124301","best_ask":"0.39","best_bid":"0.35","hash":"73c134c3dc9c648a7bb357608abca7e09f36990a","price":"0.28","side":"BUY","size":"141"},{"asset_id":"96600821790790307414914106093858868634329285205417149685270682748367152458577","best_ask":"0.65","best_bid":"0.61","hash":"5a9a799845be2e4ae57ef7d976cc274979e23dfb","price":"0.72","side":"SELL","size":"141"}],"timestamp":"1785212020534"},"payload_hash":"b90b13e73158ee06d78715e8c52a1e03c20671e3caa91b3ac0df66c4faa956ee","raw_frame":"{\"market\":\"0xd412ce774cfcf8dc9f71164aac78783978aac7b03871702a3b8a481bd9dc9688\", \"price_changes\":[{\"asset_id\":\"107603864457683460275633293642179940881969192120168665300712204232021063124301\", \"price\":\"0.28\", \"size\":\"141\", \"side\":\"BUY\", \"hash\":\"73c134c3dc9c648a7bb357608abca7e09f36990a\", \"best_bid\":\"0.35\", \"best_ask\":\"0.39\"}, {\"asset_id\":\"96600821790790307414914106093858868634329285205417149685270682748367152458577\", \"price\":\"0.72\", \"size\":\"141\", \"side\":\"SELL\", \"hash\":\"5a9a799845be2e4ae57ef7d976cc274979e23dfb\", \"best_bid\":\"0.61\", \"best_ask\":\"0.65\"}], \"timestamp\":\"1785212020534\", \"event_type\":\"price_change\"}","received_at":"2026-07-28T04:13:41.688774Z","schema_version":"clob-market-ws.price_change.v1","sequence":null,"server_hash":null,"server_timestamp":"1785212020534","session_id":"2d607381e3054cee91998cdf45a4231c","source":"clob_market_ws"},"received_at":"2026-07-28T04:13:41.688774Z","record_id":"3dcdaf0bfd4daa30bda1952edd913d9cd367abc70bbfb68e84393b631d2831b4","schema_fingerprint":"4aa3821a28b0b7c2400bc59aba4bcc0a76e971dadd19610d3ad38c768e124dc7","schema_version":"edge-lab-recorder.raw.v1","sequence":null,"source":"clob_market_ws"}
{"event_at":"2026-07-28T04:13:40.557000Z","event_fingerprint":"2458140bbd2d5491d835e6e50ec691b75fb5031536c05b4b03338daf8101b189","payload":{"connection_id":"f6725804f86a4c4eb588e4d5ed7db029","event_at":"2026-07-28T04:13:40.557000Z","event_type":"price_change","frame_hash":"8ac5b8b7a92d6e7605694863bdc6103cc85c4dc189446873193f57897eba37f5","frame_index":0,"kind":"data","monotonic_ns":314004768789333,"payload":{"event_type":"price_change","market":"0xd412ce774cfcf8dc9f71164aac78783978aac7b03871702a3b8a481bd9dc9688","price_changes":[{"asset_id":"107603864457683460275633293642179940881969192120168665300712204232021063124301","best_ask":"0.39","best_bid":"0.35","hash":"564e2228225c8dc60d1343bba7dc361c158501bf","price":"0.27","side":"BUY","size":"124.59"},{"asset_id":"96600821790790307414914106093858868634329285205417149685270682748367152458577","best_ask":"0.65","best_bid":"0.61","hash":"c2692b7522ec0d40327ea358a773776c7a34ec67","price":"0.73","side":"SELL","size":"124.59"}],"timestamp":"1785212020557"},"payload_hash":"079690ee13fb16eacfc3b916500f25c1bd443da123003a6f0290a6415aff3e77","raw_frame":"{\"market\":\"0xd412ce774cfcf8dc9f71164aac78783978aac7b03871702a3b8a481bd9dc9688\", \"price_changes\":[{\"asset_id\":\"107603864457683460275633293642179940881969192120168665300712204232021063124301\", \"price\":\"0.27\", \"size\":\"124.59\", \"side\":\"BUY\", \"hash\":\"564e2228225c8dc60d1343bba7dc361c158501bf\", \"best_bid\":\"0.35\", \"best_ask\":\"0.39\"}, {\"asset_id\":\"96600821790790307414914106093858868634329285205417149685270682748367152458577\", \"price\":\"0.73\", \"size\":\"124.59\", \"side\":\"SELL\", \"hash\":\"c2692b7522ec0d40327ea358a773776c7a34ec67\", \"best_bid\":\"0.61\", \"best_ask\":\"0.65\"}], \"timestamp\":\"1785212020557\", \"event_type\":\"price_change\"}","received_at":"2026-07-28T04:13:41.690659Z","schema_version":"clob-market-ws.price_change.v1","sequence":null,"server_hash":null,"server_timestamp":"1785212020557","session_id":"2d607381e3054cee91998cdf45a4231c","source":"clob_market_ws"},"received_at":"2026-07-28T04:13:41.690659Z","record_id":"3c0e7c5f2c41a5024605cfc594e88e3b352b2bdf9bcc1ce18b9616213735b2c8","schema_fingerprint":"4aa3821a28b0b7c2400bc59aba4bcc0a76e971dadd19610d3ad38c768e124dc7","schema_version":"edge-lab-recorder.raw.v1","sequence":null,"source":"clob_market_ws"}
{"event_at":"2026-07-28T04:13:40.558000Z","event_fingerprint":"4b1954236149d070f66b0f8836d11971aa38fa2174e2bb1de6b73dcf16aa6228","payload":{"connection_id":"f6725804f86a4c4eb588e4d5ed7db029","event_at":"2026-07-28T04:13:40.558000Z","event_type":"price_change","frame_hash":"3c4ab95300a7015711a8fa707304dd00818f322bd5600273bc33f5b817cf80f0","frame_index":0,"kind":"data","monotonic_ns":314004770273750,"payload":{"event_type":"price_change","market":"0xd412ce774cfcf8dc9f71164aac78783978aac7b03871702a3b8a481bd9dc9688","price_changes":[{"asset_id":"96600821790790307414914106093858868634329285205417149685270682748367152458577","best_ask":"0.65","best_bid":"0.61","hash":"b4f3dfc4433baef1bd5e046a0ad7ad38008174ec","price":"0.01","side":"BUY","size":"5290.02"},{"asset_id":"107603864457683460275633293642179940881969192120168665300712204232021063124301","best_ask":"0.39","best_bid":"0.35","hash":"9b2e6603ec2c541a3fca9531d4c364ff15d95625","price":"0.99","side":"SELL","size":"5290.02"}],"timestamp":"1785212020558"},"payload_hash":"04f16b462c0a79881fcd9108a891f059f7fd5498e583ad0ac017ce6dbd9303f1","raw_frame":"{\"market\":\"0xd412ce774cfcf8dc9f71164aac78783978aac7b03871702a3b8a481bd9dc9688\", \"price_changes\":[{\"asset_id\":\"96600821790790307414914106093858868634329285205417149685270682748367152458577\", \"price\":\"0.01\", \"size\":\"5290.02\", \"side\":\"BUY\", \"hash\":\"b4f3dfc4433baef1bd5e046a0ad7ad38008174ec\", \"best_bid\":\"0.61\", \"best_ask\":\"0.65\"}, {\"asset_id\":\"107603864457683460275633293642179940881969192120168665300712204232021063124301\", \"price\":\"0.99\", \"size\":\"5290.02\", \"side\":\"SELL\", \"hash\":\"9b2e6603ec2c541a3fca9531d4c364ff15d95625\", \"best_bid\":\"0.35\", \"best_ask\":\"0.39\"}], \"timestamp\":\"1785212020558\", \"event_type\":\"price_change\"}","received_at":"2026-07-28T04:13:41.692142Z","schema_version":"clob-market-ws.price_change.v1","sequence":null,"server_hash":null,"server_timestamp":"1785212020558","session_id":"2d607381e3054cee91998cdf45a4231c","source":"clob_market_ws"},"received_at":"2026-07-28T04:13:41.692142Z","record_id":"31e912704cbc823463553c2fa62984f557b9839bb51d0dedaf1ce71b6b6e8502","schema_fingerprint":"4aa3821a28b0b7c2400bc59aba4bcc0a76e971dadd19610d3ad38c768e124dc7","schema_version":"edge-lab-recorder.raw.v1","sequence":null,"source":"clob_market_ws"}
{"event_at":"2026-07-28T04:13:40.594000Z","event_fingerprint":"18511a9bb66fff44091c469732de448b1eb23bd299dc5865b76ebd63858f6430","payload":{"connection_id":"f6725804f86a4c4eb588e4d5ed7db029","event_at":"2026-07-28T04:13:40.594000Z","event_type":"price_change","frame_hash":"0e060b0a75f3544fe1c084e532ea8911b8fb0e91d7ea47a205714e4e99fa08c4","frame_index":0,"kind":"data","monotonic_ns":314004771433583,"payload":{"event_type":"price_change","market":"0xd412ce774cfcf8dc9f71164aac78783978aac7b03871702a3b8a481bd9dc9688","price_changes":[{"asset_id":"96600821790790307414914106093858868634329285205417149685270682748367152458577","best_ask":"0.65","best_bid":"0.61","hash":"01ba72680fc39b1bf1f157992539645d1f39d02a","price":"0.69","side":"SELL","size":"145"},{"asset_id":"107603864457683460275633293642179940881969192120168665300712204232021063124301","best_ask":"0.39","best_bid":"0.35","hash":"d16e172ad7d41e877263d5c828f7a4c4a50383c4","price":"0.31","side":"BUY","size":"145"}],"timestamp":"1785212020594"},"payload_hash":"1ff013d1772b576984e468d00bafbf3e9cdff3dba40008a50cd08025affc93a3","raw_frame":"{\"market\":\"0xd412ce774cfcf8dc9f71164aac78783978aac7b03871702a3b8a481bd9dc9688\", \"price_changes\":[{\"asset_id\":\"96600821790790307414914106093858868634329285205417149685270682748367152458577\", \"price\":\"0.69\", \"size\":\"145\", \"side\":\"SELL\", \"hash\":\"01ba72680fc39b1bf1f157992539645d1f39d02a\", \"best_bid\":\"0.61\", \"best_ask\":\"0.65\"}, {\"asset_id\":\"107603864457683460275633293642179940881969192120168665300712204232021063124301\", \"price\":\"0.31\", \"size\":\"145\", \"side\":\"BUY\", \"hash\":\"d16e172ad7d41e877263d5c828f7a4c4a50383c4\", \"best_bid\":\"0.35\", \"best_ask\":\"0.39\"}], \"timestamp\":\"1785212020594\", \"event_type\":\"price_change\"}","received_at":"2026-07-28T04:13:41.693303Z","schema_version":"clob-market-ws.price_change.v1","sequence":null,"server_hash":null,"server_timestamp":"1785212020594","session_id":"2d607381e3054cee91998cdf45a4231c","source":"clob_market_ws"},"received_at":"2026-07-28T04:13:41.693303Z","record_id":"4c1b972d8824491c31ab22bcec6e8996ec036036fcc5fe0431a1cb3fe0657f16","schema_fingerprint":"4aa3821a28b0b7c2400bc59aba4bcc0a76e971dadd19610d3ad38c768e124dc7","schema_version":"edge-lab-recorder.raw.v1","sequence":null,"source":"clob_market_ws"}
{"event_at":"2026-07-28T04:13:40.597000Z","event_fingerprint":"c38d7164e39ec26b2eadb7b56e2252cc018acc436866da0aed237c7ab232d8e4","payload":{"connection_id":"f6725804f86a4c4eb588e4d5ed7db029","event_at":"2026-07-28T04:13:40.597000Z","event_type":"price_change","frame_hash":"123655c5d515d1c1b2375e4d95aba426d4292dc97405590f7fc0d2afc243f8ef","frame_index":0,"kind":"data","monotonic_ns":314004772662375,"payload":{"event_type":"price_change","market":"0xd412ce774cfcf8dc9f71164aac78783978aac7b03871702a3b8a481bd9dc9688","price_changes":[{"asset_id":"107603864457683460275633293642179940881969192120168665300712204232021063124301","best_ask":"0.39","best_bid":"0.35","hash":"a65fcd2bbd1e08d00ac6c6a3338eaafe25304373","price":"0.31","side":"BUY","size":"120"},{"asset_id":"96600821790790307414914106093858868634329285205417149685270682748367152458577","best_ask":"0.65","best_bid":"0.61","hash":"9db72bc2c552136ae77b401683c7b833238c0949","price":"0.69","side":"SELL","size":"120"}],"timestamp":"1785212020597"},"payload_hash":"32b111fce4bf8f54c2fe967e6d933b11dadff2283b26e8f389536257a5df5651","raw_frame":"{\"market\":\"0xd412ce774cfcf8dc9f71164aac78783978aac7b03871702a3b8a481bd9dc9688\", \"price_changes\":[{\"asset_id\":\"107603864457683460275633293642179940881969192120168665300712204232021063124301\", \"price\":\"0.31\", \"size\":\"120\", \"side\":\"BUY\", \"hash\":\"a65fcd2bbd1e08d00ac6c6a3338eaafe25304373\", \"best_bid\":\"0.35\", \"best_ask\":\"0.39\"}, {\"asset_id\":\"96600821790790307414914106093858868634329285205417149685270682748367152458577\", \"price\":\"0.69\", \"size\":\"120\", \"side\":\"SELL\", \"hash\":\"9db72bc2c552136ae77b401683c7b833238c0949\", \"best_bid\":\"0.61\", \"best_ask\":\"0.65\"}], \"timestamp\":\"1785212020597\", \"event_type\":\"price_change\"}","received_at":"2026-07-28T04:13:41.694525Z","schema_version":"clob-market-ws.price_change.v1","sequence":null,"server_hash":null,"server_timestamp":"1785212020597","session_id":"2d607381e3054cee91998cdf45a4231c","source":"clob_market_ws"},"received_at":"2026-07-28T04:13:41.694525Z","record_id":"8d0d9e42e524510f39eb39b31b3acca7a12c2b3136e02e74e107db8dc2dd70ce","schema_fingerprint":"4aa3821a28b0b7c2400bc59aba4bcc0a76e971dadd19610d3ad38c768e124dc7","schema_version":"edge-lab-recorder.raw.v1","sequence":null,"source":"clob_market_ws"}
{"event_at":"2026-07-28T04:13:40.600000Z","event_fingerprint":"06fa59da38b1c765ca622663457eb79cba035b90337217378bb25033a9ec4e02","payload":{"connection_id":"f6725804f86a4c4eb588e4d5ed7db029","event_at":"2026-07-28T04:13:40.600000Z","event_type":"best_bid_ask","frame_hash":"1507d9f0506193a93d4e3deb81c3341c1e0c3b10372591ec20303ce29b562e5a","frame_index":0,"kind":"data","monotonic_ns":314004775717416,"payload":{"asset_id":"107603864457683460275633293642179940881969192120168665300712204232021063124301","best_ask":"0.38","best_bid":"0.35","event_type":"best_bid_ask","market":"0xd412ce774cfcf8dc9f71164aac78783978aac7b03871702a3b8a481bd9dc9688","spread":"0.03","timestamp":"1785212020600"},"payload_hash":"8819b197fac135c853e7d4f26569897b37a65852179ad9ccef0523e6bc5bcde8","raw_frame":"{\"market\":\"0xd412ce774cfcf8dc9f71164aac78783978aac7b03871702a3b8a481bd9dc9688\", \"asset_id\":\"107603864457683460275633293642179940881969192120168665300712204232021063124301\", \"best_bid\":\"0.35\", \"best_ask\":\"0.38\", \"spread\":\"0.03\", \"timestamp\":\"1785212020600\", \"event_type\":\"best_bid_ask\"}","received_at":"2026-07-28T04:13:41.697573Z","schema_version":"clob-market-ws.best_bid_ask.v1","sequence":null,"server_hash":null,"server_timestamp":"1785212020600","session_id":"2d607381e3054cee91998cdf45a4231c","source":"clob_market_ws"},"received_at":"2026-07-28T04:13:41.697573Z","record_id":"25e1b20871c5ce9929b4cf40947bcb12235386f2bdbeadce0d85c5dbd269f1a1","schema_fingerprint":"8488399f31b0337811b13b266be932db7062827c2470b78bd8e9e99bab51d17d","schema_version":"edge-lab-recorder.raw.v1","sequence":null,"source":"clob_market_ws"}
{"event_at":"2026-07-28T04:13:40.600000Z","event_fingerprint":"1d6b3e2c6f0b7cd9b24d85be9a74e06779e4428932ceb66f030c081f53d98350","payload":{"connection_id":"f6725804f86a4c4eb588e4d5ed7db029","event_at":"2026-07-28T04:13:40.600000Z","event_type":"best_bid_ask","frame_hash":"cc66f41de10146791a16ffc2f8ce8ccea2b57a922ae980e2205052de24abb274","frame_index":0,"kind":"data","monotonic_ns":314004779302416,"payload":{"asset_id":"96600821790790307414914106093858868634329285205417149685270682748367152458577","best_ask":"0.65","best_bid":"0.62","event_type":"best_bid_ask","market":"0xd412ce774cfcf8dc9f71164aac78783978aac7b03871702a3b8a481bd9dc9688","spread":"0.03","timestamp":"1785212020600"},"payload_hash":"7a6e5ebcdc4695c4229575184ad00c27c8003de8a67b380c4df6a60e44f8d371","raw_frame":"{\"market\":\"0xd412ce774cfcf8dc9f71164aac78783978aac7b03871702a3b8a481bd9dc9688\", \"asset_id\":\"96600821790790307414914106093858868634329285205417149685270682748367152458577\", \"best_bid\":\"0.62\", \"best_ask\":\"0.65\", \"spread\":\"0.03\", \"timestamp\":\"1785212020600\", \"event_type\":\"best_bid_ask\"}","received_at":"2026-07-28T04:13:41.701166Z","schema_version":"clob-market-ws.best_bid_ask.v1","sequence":null,"server_hash":null,"server_timestamp":"1785212020600","session_id":"2d607381e3054cee91998cdf45a4231c","source":"clob_market_ws"},"received_at":"2026-07-28T04:13:41.701166Z","record_id":"082e1c766c0626796d7aeac261e4366266d570e5f7a93635b340dacaaea9c7c6","schema_fingerprint":"8488399f31b0337811b13b266be932db7062827c2470b78bd8e9e99bab51d17d","schema_version":"edge-lab-recorder.raw.v1","sequence":null,"source":"clob_market_ws"}
{"event_at":"2026-07-28T04:13:40.600000Z","event_fingerprint":"c1a9ba032f72b62ee6021fe22bbd849168be3e24f75c7d638f0336a92927678b","payload":{"connection_id":"f6725804f86a4c4eb588e4d5ed7db029","event_at":"2026-07-28T04:13:40.600000Z","event_type":"price_change","frame_hash":"06989fc59f751f83965fd4a1fcae8c8841b71f03576d9db270777346c71c939e","frame_index":0,"kind":"data","monotonic_ns":314004781214125,"payload":{"event_type":"price_change","market":"0xd412ce774cfcf8dc9f71164aac78783978aac7b03871702a3b8a481bd9dc9688","price_changes":[{"asset_id":"107603864457683460275633293642179940881969192120168665300712204232021063124301","best_ask":"0.38","best_bid":"0.35","hash":"debb61b590fa5a2ee9c1aee1cc287d84dbb09c5b","price":"0.38","side":"SELL","size":"5"},{"asset_id":"96600821790790307414914106093858868634329285205417149685270682748367152458577","best_ask":"0.65","best_bid":"0.62","hash":"7c4bdbe56d4e45aaf7701c4d4d1a028ed777f318","price":"0.62","side":"BUY","size":"5"}],"timestamp":"1785212020600"},"payload_hash":"79a9f3a45a352ead735be26706d43f35f2bd36066654fbe91a09294aac2cff9f","raw_frame":"{\"market\":\"0xd412ce774cfcf8dc9f71164aac78783978aac7b03871702a3b8a481bd9dc9688\", \"price_changes\":[{\"asset_id\":\"107603864457683460275633293642179940881969192120168665300712204232021063124301\", \"price\":\"0.38\", \"size\":\"5\", \"side\":\"SELL\", \"hash\":\"debb61b590fa5a2ee9c1aee1cc287d84dbb09c5b\", \"best_bid\":\"0.35\", \"best_ask\":\"0.38\"}, {\"asset_id\":\"96600821790790307414914106093858868634329285205417149685270682748367152458577\", \"price\":\"0.62\", \"size\":\"5\", \"side\":\"BUY\", \"hash\":\"7c4bdbe56d4e45aaf7701c4d4d1a028ed777f318\", \"best_bid\":\"0.62\", \"best_ask\":\"0.65\"}], \"timestamp\":\"1785212020600\", \"event_type\":\"price_change\"}","received_at":"2026-07-28T04:13:41.703072Z","schema_version":"clob-market-ws.price_change.v1","sequence":null,"server_hash":null,"server_timestamp":"1785212020600","session_id":"2d607381e3054cee91998cdf45a4231c","source":"clob_market_ws"},"received_at":"2026-07-28T04:13:41.703072Z","record_id":"3232296d783079295e9b21b8be34b7e62673b4a0fa1107424d153bc2202c2cbf","schema_fingerprint":"4aa3821a28b0b7c2400bc59aba4bcc0a76e971dadd19610d3ad38c768e124dc7","schema_version":"edge-lab-recorder.raw.v1","sequence":null,"source":"clob_market_ws"}
{"event_at":"2026-07-28T04:13:40.601000Z","event_fingerprint":"fa6c5def92e9d3f39673c8eced073892240d0e98d6b30f99d2035df0d974db60","payload":{"connection_id":"f6725804f86a4c4eb588e4d5ed7db029","event_at":"2026-07-28T04:13:40.601000Z","event_type":"price_change","frame_hash":"76ccb522c11905394d6a6ba18372ed9a2de294679d3f44051880b04cc7666222","frame_index":0,"kind":"data","monotonic_ns":314004783510416,"payload":{"event_type":"price_change","market":"0xd412ce774cfcf8dc9f71164aac78783978aac7b03871702a3b8a481bd9dc9688","price_changes":[{"asset_id":"107603864457683460275633293642179940881969192120168665300712204232021063124301","best_ask":"0.38","best_bid":"0.35","hash":"83649310b82c4ffa24011fd78eb200d6452d722b","price":"0.38","side":"SELL","size":"11"},{"asset_id":"96600821790790307414914106093858868634329285205417149685270682748367152458577","best_ask":"0.65","best_bid":"0.62","hash":"90e584b6cc5229e51dbf15d5ea94b9ec601f9ff5","price":"0.62","side":"BUY","size":"11"}],"timestamp":"1785212020601"},"payload_hash":"3c111730bac0cd6f622c1e6dcd9a65d1c53c75ee337615aaba1852ba208d2fc9","raw_frame":"{\"market\":\"0xd412ce774cfcf8dc9f71164aac78783978aac7b03871702a3b8a481bd9dc9688\", \"price_changes\":[{\"asset_id\":\"107603864457683460275633293642179940881969192120168665300712204232021063124301\", \"price\":\"0.38\", \"size\":\"11\", \"side\":\"SELL\", \"hash\":\"83649310b82c4ffa24011fd78eb200d6452d722b\", \"best_bid\":\"0.35\", \"best_ask\":\"0.38\"}, {\"asset_id\":\"96600821790790307414914106093858868634329285205417149685270682748367152458577\", \"price\":\"0.62\", \"size\":\"11\", \"side\":\"BUY\", \"hash\":\"90e584b6cc5229e51dbf15d5ea94b9ec601f9ff5\", \"best_bid\":\"0.62\", \"best_ask\":\"0.65\"}], \"timestamp\":\"1785212020601\", \"event_type\":\"price_change\"}","received_at":"2026-07-28T04:13:41.705380Z","schema_version":"clob-market-ws.price_change.v1","sequence":null,"server_hash":null,"server_timestamp":"1785212020601","session_id":"2d607381e3054cee91998cdf45a4231c","source":"clob_market_ws"},"received_at":"2026-07-28T04:13:41.705380Z","record_id":"4bb6c21620fb97457c4720d4252516adbbc72d2fcd130b986ac098824bb4cdf9","schema_fingerprint":"4aa3821a28b0b7c2400bc59aba4bcc0a76e971dadd19610d3ad38c768e124dc7","schema_version":"edge-lab-recorder.raw.v1","sequence":null,"source":"clob_market_ws"}
{"event_at":"2026-07-28T04:13:40.602000Z","event_fingerprint":"9189cc355c5fae1bd06fc4f265aa53475e11da0101f2eebafd1a7efea5c388b4","payload":{"connection_id":"f6725804f86a4c4eb588e4d5ed7db029","event_at":"2026-07-28T04:13:40.602000Z","event_type":"price_change","frame_hash":"d2ef3d7fc04ef33d9a28b9225e5c2839e65381a3f9af267aa3184db1c61ba673","frame_index":0,"kind":"data","monotonic_ns":314004784159625,"payload":{"event_type":"price_change","market":"0xd412ce774cfcf8dc9f71164aac78783978aac7b03871702a3b8a481bd9dc9688","price_changes":[{"asset_id":"96600821790790307414914106093858868634329285205417149685270682748367152458577","best_ask":"0.65","best_bid":"0.62","hash":"db9fe31f3319273b75d0e3d48398141a1f567b16","price":"0.62","side":"BUY","size":"17"},{"asset_id":"107603864457683460275633293642179940881969192120168665300712204232021063124301","best_ask":"0.38","best_bid":"0.35","hash":"e458c6d8f984dc76d816a751a6b8df5d69c5917c","price":"0.38","side":"SELL","size":"17"}],"timestamp":"1785212020602"},"payload_hash":"404ceae7209078d3bf85f2fb849abe919057cef2ad4457c8926a37803e521ebb","raw_frame":"{\"market\":\"0xd412ce774cfcf8dc9f71164aac78783978aac7b03871702a3b8a481bd9dc9688\", \"price_changes\":[{\"asset_id\":\"96600821790790307414914106093858868634329285205417149685270682748367152458577\", \"price\":\"0.62\", \"size\":\"17\", \"side\":\"BUY\", \"hash\":\"db9fe31f3319273b75d0e3d48398141a1f567b16\", \"best_bid\":\"0.62\", \"best_ask\":\"0.65\"}, {\"asset_id\":\"107603864457683460275633293642179940881969192120168665300712204232021063124301\", \"price\":\"0.38\", \"size\":\"17\", \"side\":\"SELL\", \"hash\":\"e458c6d8f984dc76d816a751a6b8df5d69c5917c\", \"best_bid\":\"0.35\", \"best_ask\":\"0.38\"}], \"timestamp\":\"1785212020602\", \"event_type\":\"price_change\"}","received_at":"2026-07-28T04:13:41.706028Z","schema_version":"clob-market-ws.price_change.v1","sequence":null,"server_hash":null,"server_timestamp":"1785212020602","session_id":"2d607381e3054cee91998cdf45a4231c","source":"clob_market_ws"},"received_at":"2026-07-28T04:13:41.706028Z","record_id":"14c57ae8cac7827d48085b9b5a8b16b27b95138eb8ebefacc9563fd4f156191e","schema_fingerprint":"4aa3821a28b0b7c2400bc59aba4bcc0a76e971dadd19610d3ad38c768e124dc7","schema_version":"edge-lab-recorder.raw.v1","sequence":null,"source":"clob_market_ws"}
{"event_at":"2026-07-28T04:13:40.606000Z","event_fingerprint":"1405e46064dab3ca8be10c8bd05a6fcdbc121e683686c4ac5c54a48b82c4682c","payload":{"connection_id":"f6725804f86a4c4eb588e4d5ed7db029","event_at":"2026-07-28T04:13:40.606000Z","event_type":"best_bid_ask","frame_hash":"9a5f63790a08dfe13efad206fdf875860d61937d3fcff10a37403c50c2a89fb6","frame_index":0,"kind":"data","monotonic_ns":314004784685000,"payload":{"asset_id":"107603864457683460275633293642179940881969192120168665300712204232021063124301","best_ask":"0.38","best_bid":"0.33","event_type":"best_bid_ask","market":"0xd412ce774cfcf8dc9f71164aac78783978aac7b03871702a3b8a481bd9dc9688","spread":"0.05","timestamp":"1785212020606"},"payload_hash":"6f2403f5d54baba1094efb03290dcca1263ef5754f43d8e886666844ada88960","raw_frame":"{\"market\":\"0xd412ce774cfcf8dc9f71164aac78783978aac7b03871702a3b8a481bd9dc9688\", \"asset_id\":\"107603864457683460275633293642179940881969192120168665300712204232021063124301\", \"best_bid\":\"0.33\", \"best_ask\":\"0.38\", \"spread\":\"0.05\", \"timestamp\":\"1785212020606\", \"event_type\":\"best_bid_ask\"}","received_at":"2026-07-28T04:13:41.706554Z","schema_version":"clob-market-ws.best_bid_ask.v1","sequence":null,"server_hash":null,"server_timestamp":"1785212020606","session_id":"2d607381e3054cee91998cdf45a4231c","source":"clob_market_ws"},"received_at":"2026-07-28T04:13:41.706554Z","record_id":"0eb68f5d77c9129efa5e99c789950ce700fb786e40d7bc9527eac78e481a9076","schema_fingerprint":"8488399f31b0337811b13b266be932db7062827c2470b78bd8e9e99bab51d17d","schema_version":"edge-lab-recorder.raw.v1","sequence":null,"source":"clob_market_ws"}
{"event_at":"2026-07-28T04:13:40.606000Z","event_fingerprint":"30901487fd06b0ff6d563ec80f2f3ab20795b3c9b92118103c1f557e1db0aa15","payload":{"connection_id":"f6725804f86a4c4eb588e4d5ed7db029","event_at":"2026-07-28T04:13:40.606000Z","event_type":"best_bid_ask","frame_hash":"021a6d8956646da403b1b2774db7a2b2b8f1cf22fe50808d99869c911b789a26","frame_index":0,"kind":"data","monotonic_ns":314004785063291,"payload":{"asset_id":"96600821790790307414914106093858868634329285205417149685270682748367152458577","best_ask":"0.67","best_bid":"0.62","event_type":"best_bid_ask","market":"0xd412ce774cfcf8dc9f71164aac78783978aac7b03871702a3b8a481bd9dc9688","spread":"0.05","timestamp":"1785212020606"},"payload_hash":"7dcd0fa92b20070df15ea3034bd8d1df232202c5b93072f0a56853d75cf56184","raw_frame":"{\"market\":\"0xd412ce774cfcf8dc9f71164aac78783978aac7b03871702a3b8a481bd9dc9688\", \"asset_id\":\"96600821790790307414914106093858868634329285205417149685270682748367152458577\", \"best_bid\":\"0.62\", \"best_ask\":\"0.67\", \"spread\":\"0.05\", \"timestamp\":\"1785212020606\", \"event_type\":\"best_bid_ask\"}","received_at":"2026-07-28T04:13:41.706933Z","schema_version":"clob-market-ws.best_bid_ask.v1","sequence":null,"server_hash":null,"server_timestamp":"1785212020606","session_id":"2d607381e3054cee91998cdf45a4231c","source":"clob_market_ws"},"received_at":"2026-07-28T04:13:41.706933Z","record_id":"7ca7a8c398d14bf5bece9806786ac087c50f2d48e36324d7161e276e682345ec","schema_fingerprint":"8488399f31b0337811b13b266be932db7062827c2470b78bd8e9e99bab51d17d","schema_version":"edge-lab-recorder.raw.v1","sequence":null,"source":"clob_market_ws"}
{"event_at":"2026-07-28T04:13:40.606000Z","event_fingerprint":"b6968ad50f15a48683029d58b9f81c2d4eb5333f7872f37ff7240db5297ff849","payload":{"connection_id":"f6725804f86a4c4eb588e4d5ed7db029","event_at":"2026-07-28T04:13:40.606000Z","event_type":"price_change","frame_hash":"e7786aac5fab2a506b8c928243101e1fe62d4ccf7a642e9bb3f0674c7970bcb6","frame_index":0,"kind":"data","monotonic_ns":314004785427250,"payload":{"event_type":"price_change","market":"0xd412ce774cfcf8dc9f71164aac78783978aac7b03871702a3b8a481bd9dc9688","price_changes":[{"asset_id":"107603864457683460275633293642179940881969192120168665300712204232021063124301","best_ask":"0.38","best_bid":"0.33","hash":"fb97b4be248049d311e89fee57d8d866fc646d6d","price":"0.35","side":"BUY","size":"0"},{"asset_id":"96600821790790307414914106093858868634329285205417149685270682748367152458577","best_ask":"0.67","best_bid":"0.62","hash":"bd3b9ece3f13bef1602707d7c0f635c3132f7877","price":"0.65","side":"SELL","size":"0"}],"timestamp":"1785212020606"},"payload_hash":"b0dc3fa3321ae540c966e281f6811b4589ac1810a5c101df8ec8200377269fae","raw_frame":"{\"market\":\"0xd412ce774cfcf8dc9f71164aac78783978aac7b03871702a3b8a481bd9dc9688\", \"price_changes\":[{\"asset_id\":\"107603864457683460275633293642179940881969192120168665300712204232021063124301\", \"price\":\"0.35\", \"size\":\"0\", \"side\":\"BUY\", \"hash\":\"fb97b4be248049d311e89fee57d8d866fc646d6d\", \"best_bid\":\"0.33\", \"best_ask\":\"0.38\"}, {\"asset_id\":\"96600821790790307414914106093858868634329285205417149685270682748367152458577\", \"price\":\"0.65\", \"size\":\"0\", \"side\":\"SELL\", \"hash\":\"bd3b9ece3f13bef1602707d7c0f635c3132f7877\", \"best_bid\":\"0.62\", \"best_ask\":\"0.67\"}], \"timestamp\":\"1785212020606\", \"event_type\":\"price_change\"}","received_at":"2026-07-28T04:13:41.707296Z","schema_version":"clob-market-ws.price_change.v1","sequence":null,"server_hash":null,"server_timestamp":"1785212020606","session_id":"2d607381e3054cee91998cdf45a4231c","source":"clob_market_ws"},"received_at":"2026-07-28T04:13:41.707296Z","record_id":"896950ee25519dea961bd8cff62a669c10b3446881cd137aad93e021a5495fa7","schema_fingerprint":"4aa3821a28b0b7c2400bc59aba4bcc0a76e971dadd19610d3ad38c768e124dc7","schema_version":"edge-lab-recorder.raw.v1","sequence":null,"source":"clob_market_ws"}
{"event_at":"2026-07-28T04:13:40.606000Z","event_fingerprint":"65cf6b60da0aefdb8f6d4a43684adf8527a9afb5b4b91cadd171bac76f871839","payload":{"connection_id":"f6725804f86a4c4eb588e4d5ed7db029","event_at":"2026-07-28T04:13:40.606000Z","event_type":"price_change","frame_hash":"dd0de373e0796ec15d7054e3ad02d04eb282b7044bab9b137366065c042d7816","frame_index":0,"kind":"data","monotonic_ns":314004786532041,"payload":{"event_type":"price_change","market":"0xd412ce774cfcf8dc9f71164aac78783978aac7b03871702a3b8a481bd9dc9688","price_changes":[{"asset_id":"96600821790790307414914106093858868634329285205417149685270682748367152458577","best_ask":"0.67","best_bid":"0.62","hash":"c8c9c98d2ce59821bea8789ae07bc66216a1c295","price":"0.62","side":"BUY","size":"22"},{"asset_id":"107603864457683460275633293642179940881969192120168665300712204232021063124301","best_ask":"0.38","best_bid":"0.33","hash":"57ee56c0917195813e54a0ee0f7bb5eeed0b28a6","price":"0.38","side":"SELL","size":"22"}],"timestamp":"1785212020606"},"payload_hash":"d2efd86a605af1c8bea507ee0227c930a69fa1e369d6bde52ac478b25d25c0bf","raw_frame":"{\"market\":\"0xd412ce774cfcf8dc9f71164aac78783978aac7b03871702a3b8a481bd9dc9688\", \"price_changes\":[{\"asset_id\":\"96600821790790307414914106093858868634329285205417149685270682748367152458577\", \"price\":\"0.62\", \"size\":\"22\", \"side\":\"BUY\", \"hash\":\"c8c9c98d2ce59821bea8789ae07bc66216a1c295\", \"best_bid\":\"0.62\", \"best_ask\":\"0.67\"}, {\"asset_id\":\"107603864457683460275633293642179940881969192120168665300712204232021063124301\", \"price\":\"0.38\", \"size\":\"22\", \"side\":\"SELL\", \"hash\":\"57ee56c0917195813e54a0ee0f7bb5eeed0b28a6\", \"best_bid\":\"0.33\", \"best_ask\":\"0.38\"}], \"timestamp\":\"1785212020606\", \"event_type\":\"price_change\"}","received_at":"2026-07-28T04:13:41.708395Z","schema_version":"clob-market-ws.price_change.v1","sequence":null,"server_hash":null,"server_timestamp":"1785212020606","session_id":"2d607381e3054cee91998cdf45a4231c","source":"clob_market_ws"},"received_at":"2026-07-28T04:13:41.708395Z","record_id":"798125b89a5db402f3efb0b5fee03604883f9a2c6eb97e23fa1d9b897b01e94b","schema_fingerprint":"4aa3821a28b0b7c2400bc59aba4bcc0a76e971dadd19610d3ad38c768e124dc7","schema_version":"edge-lab-recorder.raw.v1","sequence":null,"source":"clob_market_ws"}
{"event_at":"2026-07-28T04:13:40.615000Z","event_fingerprint":"96320fbd156b08aa96d2d30b74ac829c05abe5ccc5bee79982a563ab6567283d","payload":{"connection_id":"f6725804f86a4c4eb588e4d5ed7db029","event_at":"2026-07-28T04:13:40.615000Z","event_type":"price_change","frame_hash":"13da7e53d6427c4ad0b6adec7fc0d16503d0201a3ce0642af5f9da3e0083e306","frame_index":0,"kind":"data","monotonic_ns":314004788062541,"payload":{"event_type":"price_change","market":"0xd412ce774cfcf8dc9f71164aac78783978aac7b03871702a3b8a481bd9dc9688","price_changes":[{"asset_id":"96600821790790307414914106093858868634329285205417149685270682748367152458577","best_ask":"0.67","best_bid":"0.62","hash":"3ccbc6063c1c7642b48d3059b70563d5105cbee8","price":"0.62","side":"BUY","size":"17"},{"asset_id":"107603864457683460275633293642179940881969192120168665300712204232021063124301","best_ask":"0.38","best_bid":"0.33","hash":"4c5b1a7bef05dd80b731ee9b054a1bd2cb18702d","price":"0.38","side":"SELL","size":"17"}],"timestamp":"1785212020615"},"payload_hash":"2b9c1c7714e2197b4274e934a411427def7f10a379e2e0e5373f1d5d6de93761","raw_frame":"{\"market\":\"0xd412ce774cfcf8dc9f71164aac78783978aac7b03871702a3b8a481bd9dc9688\", \"price_changes\":[{\"asset_id\":\"96600821790790307414914106093858868634329285205417149685270682748367152458577\", \"price\":\"0.62\", \"size\":\"17\", \"side\":\"BUY\", \"hash\":\"3ccbc6063c1c7642b48d3059b70563d5105cbee8\", \"best_bid\":\"0.62\", \"best_ask\":\"0.67\"}, {\"asset_id\":\"107603864457683460275633293642179940881969192120168665300712204232021063124301\", \"price\":\"0.38\", \"size\":\"17\", \"side\":\"SELL\", \"hash\":\"4c5b1a7bef05dd80b731ee9b054a1bd2cb18702d\", \"best_bid\":\"0.33\", \"best_ask\":\"0.38\"}], \"timestamp\":\"1785212020615\", \"event_type\":\"price_change\"}","received_at":"2026-07-28T04:13:41.709932Z","schema_version":"clob-market-ws.price_change.v1","sequence":null,"server_hash":null,"server_timestamp":"1785212020615","session_id":"2d607381e3054cee91998cdf45a4231c","source":"clob_market_ws"},"received_at":"2026-07-28T04:13:41.709932Z","record_id":"fe0c1ec4575db1a7a5667f87daa8683d94410a197176a70ee888c59362cc4d4f","schema_fingerprint":"4aa3821a28b0b7c2400bc59aba4bcc0a76e971dadd19610d3ad38c768e124dc7","schema_version":"edge-lab-recorder.raw.v1","sequence":null,"source":"clob_market_ws"}
{"event_at":"2026-07-28T04:13:40.618000Z","event_fingerprint":"4e91294dd91888063cea4f5674765ae924193f2e37de2ecce9c10418626a6de2","payload":{"connection_id":"f6725804f86a4c4eb588e4d5ed7db029","event_at":"2026-07-28T04:13:40.618000Z","event_type":"price_change","frame_hash":"f4478cb44b8a5b143d52091264a3bdea8eb2b7a2625bd651838d931c0a325c4f","frame_index":0,"kind":"data","monotonic_ns":314004788589250,"payload":{"event_type":"price_change","market":"0xd412ce774cfcf8dc9f71164aac78783978aac7b03871702a3b8a481bd9dc9688","price_changes":[{"asset_id":"107603864457683460275633293642179940881969192120168665300712204232021063124301","best_ask":"0.38","best_bid":"0.33","hash":"f71ed8e56460ed7130e4842949497bc685a06b32","price":"0.38","side":"SELL","size":"11"},{"asset_id":"96600821790790307414914106093858868634329285205417149685270682748367152458577","best_ask":"0.67","best_bid":"0.62","hash":"cd871312087b01664993100b9ee0ae72273d2ee8","price":"0.62","side":"BUY","size":"11"}],"timestamp":"1785212020618"},"payload_hash":"029bd2f00e6eb2c80cd4881be613a126dbc3b7e3982cb431a6772e3c6ba86bc8","raw_frame":"{\"market\":\"0xd412ce774cfcf8dc9f71164aac78783978aac7b03871702a3b8a481bd9dc9688\", \"price_changes\":[{\"asset_id\":\"107603864457683460275633293642179940881969192120168665300712204232021063124301\", \"price\":\"0.38\", \"size\":\"11\", \"side\":\"SELL\", \"hash\":\"f71ed8e56460ed7130e4842949497bc685a06b32\", \"best_bid\":\"0.33\", \"best_ask\":\"0.38\"}, {\"asset_id\":\"96600821790790307414914106093858868634329285205417149685270682748367152458577\", \"price\":\"0.62\", \"size\":\"11\", \"side\":\"BUY\", \"hash\":\"cd871312087b01664993100b9ee0ae72273d2ee8\", \"best_bid\":\"0.62\", \"best_ask\":\"0.67\"}], \"timestamp\":\"1785212020618\", \"event_type\":\"price_change\"}","received_at":"2026-07-28T04:13:41.710458Z","schema_version":"clob-market-ws.price_change.v1","sequence":null,"server_hash":null,"server_timestamp":"1785212020618","session_id":"2d607381e3054cee91998cdf45a4231c","source":"clob_market_ws"},"received_at":"2026-07-28T04:13:41.710458Z","record_id":"ee754a470151cc1f46f34ca8b524b5331df2310b8d040bb415bcaaeab2a703c0","schema_fingerprint":"4aa3821a28b0b7c2400bc59aba4bcc0a76e971dadd19610d3ad38c768e124dc7","schema_version":"edge-lab-recorder.raw.v1","sequence":null,"source":"clob_market_ws"}
{"event_at":"2026-07-28T04:13:40.618000Z","event_fingerprint":"661dcc34c245afc57bbb96dbef6ef73ef89914446397fe9a73b7393920753fa9","payload":{"connection_id":"f6725804f86a4c4eb588e4d5ed7db029","event_at":"2026-07-28T04:13:40.618000Z","event_type":"price_change","frame_hash":"94eaa5d70bdd84c3894038c496fbbef5228f190f338cf5716c605c52044503e1","frame_index":0,"kind":"data","monotonic_ns":314004790001916,"payload":{"event_type":"price_change","market":"0xd412ce774cfcf8dc9f71164aac78783978aac7b03871702a3b8a481bd9dc9688","price_changes":[{"asset_id":"96600821790790307414914106093858868634329285205417149685270682748367152458577","best_ask":"0.67","best_bid":"0.62","hash":"59bb0fbbc3ba28ca51fab30b79e8251fd7d533a5","price":"0.62","side":"BUY","size":"5"},{"asset_id":"107603864457683460275633293642179940881969192120168665300712204232021063124301","best_ask":"0.38","best_bid":"0.33","hash":"879c72a88075dabe0a0f716fddbdf488420f7b2d","price":"0.38","side":"SELL","size":"5"}],"timestamp":"1785212020618"},"payload_hash":"20acb4fd5553e5d18e5bfdfccca613ab2ac2c1ad55c71134b5c5d04fb3e20ac3","raw_frame":"{\"market\":\"0xd412ce774cfcf8dc9f71164aac78783978aac7b03871702a3b8a481bd9dc9688\", \"price_changes\":[{\"asset_id\":\"96600821790790307414914106093858868634329285205417149685270682748367152458577\", \"price\":\"0.62\", \"size\":\"5\", \"side\":\"BUY\", \"hash\":\"59bb0fbbc3ba28ca51fab30b79e8251fd7d533a5\", \"best_bid\":\"0.62\", \"best_ask\":\"0.67\"}, {\"asset_id\":\"107603864457683460275633293642179940881969192120168665300712204232021063124301\", \"price\":\"0.38\", \"size\":\"5\", \"side\":\"SELL\", \"hash\":\"879c72a88075dabe0a0f716fddbdf488420f7b2d\", \"best_bid\":\"0.33\", \"best_ask\":\"0.38\"}], \"timestamp\":\"1785212020618\", \"event_type\":\"price_change\"}","received_at":"2026-07-28T04:13:41.711864Z","schema_version":"clob-market-ws.price_change.v1","sequence":null,"server_hash":null,"server_timestamp":"1785212020618","session_id":"2d607381e3054cee91998cdf45a4231c","source":"clob_market_ws"},"received_at":"2026-07-28T04:13:41.711864Z","record_id":"f4e6639752141a85bb971857d857d0d55b11b03862c72d0fca74cf9533d63d2a","schema_fingerprint":"4aa3821a28b0b7c2400bc59aba4bcc0a76e971dadd19610d3ad38c768e124dc7","schema_version":"edge-lab-recorder.raw.v1","sequence":null,"source":"clob_market_ws"}
{"event_at":"2026-07-28T04:13:40.619000Z","event_fingerprint":"4485b33444338086ec4ccbd47d2f0386979dc9a33a6c7947290ecda411f2376a","payload":{"connection_id":"f6725804f86a4c4eb588e4d5ed7db029","event_at":"2026-07-28T04:13:40.619000Z","event_type":"best_bid_ask","frame_hash":"99f4516a3d89dce75de4df163f93db64c4105678a92c72ac76cb4250a1127cf1","frame_index":0,"kind":"data","monotonic_ns":314004791582625,"payload":{"asset_id":"107603864457683460275633293642179940881969192120168665300712204232021063124301","best_ask":"0.39","best_bid":"0.33","event_type":"best_bid_ask","market":"0xd412ce774cfcf8dc9f71164aac78783978aac7b03871702a3b8a481bd9dc9688","spread":"0.06","timestamp":"1785212020619"},"payload_hash":"530b9c9645368652dcc1d830def850620ece1dc9e0344fc2c11a2cfc64b1b1e8","raw_frame":"{\"market\":\"0xd412ce774cfcf8dc9f71164aac78783978aac7b03871702a3b8a481bd9dc9688\", \"asset_id\":\"107603864457683460275633293642179940881969192120168665300712204232021063124301\", \"best_bid\":\"0.33\", \"best_ask\":\"0.39\", \"spread\":\"0.06\", \"timestamp\":\"1785212020619\", \"event_type\":\"best_bid_ask\"}","received_at":"2026-07-28T04:13:41.713446Z","schema_version":"clob-market-ws.best_bid_ask.v1","sequence":null,"server_hash":null,"server_timestamp":"1785212020619","session_id":"2d607381e3054cee91998cdf45a4231c","source":"clob_market_ws"},"received_at":"2026-07-28T04:13:41.713446Z","record_id":"85d5e91301d80eab1be779ddba8a082bcc1303b7e9c29b9896c11a4709ecbb0a","schema_fingerprint":"8488399f31b0337811b13b266be932db7062827c2470b78bd8e9e99bab51d17d","schema_version":"edge-lab-recorder.raw.v1","sequence":null,"source":"clob_market_ws"}
{"event_at":"2026-07-28T04:13:40.619000Z","event_fingerprint":"a7efa60945c8e2ddb312ba649c5d33dc5aa9c10f79168760326d465e9796ae89","payload":{"connection_id":"f6725804f86a4c4eb588e4d5ed7db029","event_at":"2026-07-28T04:13:40.619000Z","event_type":"best_bid_ask","frame_hash":"384abbe523a22c35c0e79b5111d8b78393aa51db9a1dc4179826842524d418e3","frame_index":0,"kind":"data","monotonic_ns":314004792153583,"payload":{"asset_id":"96600821790790307414914106093858868634329285205417149685270682748367152458577","best_ask":"0.67","best_bid":"0.61","event_type":"best_bid_ask","market":"0xd412ce774cfcf8dc9f71164aac78783978aac7b03871702a3b8a481bd9dc9688","spread":"0.06","timestamp":"1785212020619"},"payload_hash":"b024cd9549b523679231075115d7923a700547a329e8ae772e45a65c9892f499","raw_frame":"{\"market\":\"0xd412ce774cfcf8dc9f71164aac78783978aac7b03871702a3b8a481bd9dc9688\", \"asset_id\":\"96600821790790307414914106093858868634329285205417149685270682748367152458577\", \"best_bid\":\"0.61\", \"best_ask\":\"0.67\", \"spread\":\"0.06\", \"timestamp\":\"1785212020619\", \"event_type\":\"best_bid_ask\"}","received_at":"2026-07-28T04:13:41.714022Z","schema_version":"clob-market-ws.best_bid_ask.v1","sequence":null,"server_hash":null,"server_timestamp":"1785212020619","session_id":"2d607381e3054cee91998cdf45a4231c","source":"clob_market_ws"},"received_at":"2026-07-28T04:13:41.714022Z","record_id":"e02103545251c5a0ebcfae5e22077e415530698faae448b3504dbb0defba84ba","schema_fingerprint":"8488399f31b0337811b13b266be932db7062827c2470b78bd8e9e99bab51d17d","schema_version":"edge-lab-recorder.raw.v1","sequence":null,"source":"clob_market_ws"}
{"event_at":"2026-07-28T04:13:40.618000Z","event_fingerprint":"aecbafa6b1e74a317c6bf86b19cbc1d6f60ce4cfb6a831f3cc384178ca0c9b54","payload":{"connection_id":"f6725804f86a4c4eb588e4d5ed7db029","event_at":"2026-07-28T04:13:40.618000Z","event_type":"price_change","frame_hash":"1fefb23c7f60c5801d77e60290c8af072bb0a01c2dda11ef905931ee9758816f","frame_index":0,"kind":"data","monotonic_ns":314004792527916,"payload":{"event_type":"price_change","market":"0xd412ce774cfcf8dc9f71164aac78783978aac7b03871702a3b8a481bd9dc9688","price_changes":[{"asset_id":"107603864457683460275633293642179940881969192120168665300712204232021063124301","best_ask":"0.39","best_bid":"0.33","hash":"7469e1e3210545c4fc154efb86c7f110f888e27a","price":"0.38","side":"SELL","size":"0"},{"asset_id":"96600821790790307414914106093858868634329285205417149685270682748367152458577","best_ask":"0.67","best_bid":"0.61","hash":"ca4b11f0fc652f38ec7f95e190639cc6b441b1e9","price":"0.62","side":"BUY","size":"0"}],"timestamp":"1785212020618"},"payload_hash":"621928c14e19e6cba7eb689777299b3950860c53f9d0a0edcc7cb80566da3618","raw_frame":"{\"market\":\"0xd412ce774cfcf8dc9f71164aac78783978aac7b03871702a3b8a481bd9dc9688\", \"price_changes\":[{\"asset_id\":\"107603864457683460275633293642179940881969192120168665300712204232021063124301\", \"price\":\"0.38\", \"size\":\"0\", \"side\":\"SELL\", \"hash\":\"7469e1e3210545c4fc154efb86c7f110f888e27a\", \"best_bid\":\"0.33\", \"best_ask\":\"0.39\"}, {\"asset_id\":\"96600821790790307414914106093858868634329285205417149685270682748367152458577\", \"price\":\"0.62\", \"size\":\"0\", \"side\":\"BUY\", \"hash\":\"ca4b11f0fc652f38ec7f95e190639cc6b441b1e9\", \"best_bid\":\"0.61\", \"best_ask\":\"0.67\"}], \"timestamp\":\"1785212020618\", \"event_type\":\"price_change\"}","received_at":"2026-07-28T04:13:41.714397Z","schema_version":"clob-market-ws.price_change.v1","sequence":null,"server_hash":null,"server_timestamp":"1785212020618","session_id":"2d607381e3054cee91998cdf45a4231c","source":"clob_market_ws"},"received_at":"2026-07-28T04:13:41.714397Z","record_id":"d86c78f19edf31e55412158077ddd64ba209757fa824db5285ae2606e348ff9d","schema_fingerprint":"4aa3821a28b0b7c2400bc59aba4bcc0a76e971dadd19610d3ad38c768e124dc7","schema_version":"edge-lab-recorder.raw.v1","sequence":null,"source":"clob_market_ws"}
{"event_at":"2026-07-28T04:13:40.622000Z","event_fingerprint":"364f9802e48bd10e8d8209d1f4993309849ceeabea7891ada6f493a02121b5b0","payload":{"connection_id":"f6725804f86a4c4eb588e4d5ed7db029","event_at":"2026-07-28T04:13:40.622000Z","event_type":"best_bid_ask","frame_hash":"10a0e383b15375833eec34a363577269d3f3d8a2175a437ff857e1896cccbcfb","frame_index":0,"kind":"data","monotonic_ns":314004793055416,"payload":{"asset_id":"107603864457683460275633293642179940881969192120168665300712204232021063124301","best_ask":"0.4","best_bid":"0.33","event_type":"best_bid_ask","market":"0xd412ce774cfcf8dc9f71164aac78783978aac7b03871702a3b8a481bd9dc9688","spread":"0.07","timestamp":"1785212020622"},"payload_hash":"879574d78180e64a0bf5e802636d73cd29fedbd0e2f514425be74eb508c5e0c6","raw_frame":"{\"market\":\"0xd412ce774cfcf8dc9f71164aac78783978aac7b03871702a3b8a481bd9dc9688\", \"asset_id\":\"107603864457683460275633293642179940881969192120168665300712204232021063124301\", \"best_bid\":\"0.33\", \"best_ask\":\"0.4\", \"spread\":\"0.07\", \"timestamp\":\"1785212020622\", \"event_type\":\"best_bid_ask\"}","received_at":"2026-07-28T04:13:41.714924Z","schema_version":"clob-market-ws.best_bid_ask.v1","sequence":null,"server_hash":null,"server_timestamp":"1785212020622","session_id":"2d607381e3054cee91998cdf45a4231c","source":"clob_market_ws"},"received_at":"2026-07-28T04:13:41.714924Z","record_id":"5b19c32136e9b8228e0192b7bf16147912364fdd703f75f4c0756dc62abf2ecb","schema_fingerprint":"8488399f31b0337811b13b266be932db7062827c2470b78bd8e9e99bab51d17d","schema_version":"edge-lab-recorder.raw.v1","sequence":null,"source":"clob_market_ws"}
{"event_at":"2026-07-28T04:13:40.622000Z","event_fingerprint":"545209f81f300768e4267a1b9e2734221a00bcbfdb216dc97696b7e2835c563e","payload":{"connection_id":"f6725804f86a4c4eb588e4d5ed7db029","event_at":"2026-07-28T04:13:40.622000Z","event_type":"best_bid_ask","frame_hash":"e8d7d5c3ddfaaa4a4ac827d1d39996f6e6ca77e949346e794690901b693444cf","frame_index":0,"kind":"data","monotonic_ns":314004795592333,"payload":{"asset_id":"96600821790790307414914106093858868634329285205417149685270682748367152458577","best_ask":"0.67","best_bid":"0.6","event_type":"best_bid_ask","market":"0xd412ce774cfcf8dc9f71164aac78783978aac7b03871702a3b8a481bd9dc9688","spread":"0.07","timestamp":"1785212020622"},"payload_hash":"2b9394a4ecb5cff261a00ce383c936bdcaa22d93412b36a2586f12142b4879fa","raw_frame":"{\"market\":\"0xd412ce774cfcf8dc9f71164aac78783978aac7b03871702a3b8a481bd9dc9688\", \"asset_id\":\"96600821790790307414914106093858868634329285205417149685270682748367152458577\", \"best_bid\":\"0.6\", \"best_ask\":\"0.67\", \"spread\":\"0.07\", \"timestamp\":\"1785212020622\", \"event_type\":\"best_bid_ask\"}","received_at":"2026-07-28T04:13:41.717455Z","schema_version":"clob-market-ws.best_bid_ask.v1","sequence":null,"server_hash":null,"server_timestamp":"1785212020622","session_id":"2d607381e3054cee91998cdf45a4231c","source":"clob_market_ws"},"received_at":"2026-07-28T04:13:41.717455Z","record_id":"c604d6d902cf1ab1fea9724ebce27d0bae52621f8d21125eb0e6a0e0092bc75e","schema_fingerprint":"8488399f31b0337811b13b266be932db7062827c2470b78bd8e9e99bab51d17d","schema_version":"edge-lab-recorder.raw.v1","sequence":null,"source":"clob_market_ws"}
{"event_at":"2026-07-28T04:13:40.621000Z","event_fingerprint":"0e0566758cc86db51e76205a4f6676d022a23814fccf47c6c006c058d397a5a5","payload":{"connection_id":"f6725804f86a4c4eb588e4d5ed7db029","event_at":"2026-07-28T04:13:40.621000Z","event_type":"price_change","frame_hash":"39eaaf89edc5245fb4d37f4c9d191b72e01073cf27694acdc28af83eb17aadc8","frame_index":0,"kind":"data","monotonic_ns":314004796789208,"payload":{"event_type":"price_change","market":"0xd412ce774cfcf8dc9f71164aac78783978aac7b03871702a3b8a481bd9dc9688","price_changes":[{"asset_id":"96600821790790307414914106093858868634329285205417149685270682748367152458577","best_ask":"0.67","best_bid":"0.6","hash":"58a757bc0999b1250b0d5086303cd0ce0e638aef","price":"0.61","side":"BUY","size":"0"},{"asset_id":"107603864457683460275633293642179940881969192120168665300712204232021063124301","best_ask":"0.4","best_bid":"0.33","hash":"46a428dd4f98701abc204674af8f441db9b76703","price":"0.39","side":"SELL","size":"0"}],"timestamp":"1785212020621"},"payload_hash":"855939d61aeece44843ea8d87cdf619da5373de351c2c20406012f98eec0c95b","raw_frame":"{\"market\":\"0xd412ce774cfcf8dc9f71164aac78783978aac7b03871702a3b8a481bd9dc9688\", \"price_changes\":[{\"asset_id\":\"96600821790790307414914106093858868634329285205417149685270682748367152458577\", \"price\":\"0.61\", \"size\":\"0\", \"side\":\"BUY\", \"hash\":\"58a757bc0999b1250b0d5086303cd0ce0e638aef\", \"best_bid\":\"0.6\", \"best_ask\":\"0.67\"}, {\"asset_id\":\"107603864457683460275633293642179940881969192120168665300712204232021063124301\", \"price\":\"0.39\", \"size\":\"0\", \"side\":\"SELL\", \"hash\":\"46a428dd4f98701abc204674af8f441db9b76703\", \"best_bid\":\"0.33\", \"best_ask\":\"0.4\"}], \"timestamp\":\"1785212020621\", \"event_type\":\"price_change\"}","received_at":"2026-07-28T04:13:41.718652Z","schema_version":"clob-market-ws.price_change.v1","sequence":null,"server_hash":null,"server_timestamp":"1785212020621","session_id":"2d607381e3054cee91998cdf45a4231c","source":"clob_market_ws"},"received_at":"2026-07-28T04:13:41.718652Z","record_id":"a984922f425f99981a78eafbc289413b421f27ae3b3a903d02d60a1c98608624","schema_fingerprint":"4aa3821a28b0b7c2400bc59aba4bcc0a76e971dadd19610d3ad38c768e124dc7","schema_version":"edge-lab-recorder.raw.v1","sequence":null,"source":"clob_market_ws"}
{"event_at":"2026-07-28T04:13:40.643000Z","event_fingerprint":"c0ac5507434cca11fd1bcc10d9586f71ef95c53571801a7f5d96a5ad856df3df","payload":{"connection_id":"f6725804f86a4c4eb588e4d5ed7db029","event_at":"2026-07-28T04:13:40.643000Z","event_type":"best_bid_ask","frame_hash":"b10ac416d0d15cae14160ddbab9628e0f63b9c7cc300a9c926ff88f2c1834284","frame_index":0,"kind":"data","monotonic_ns":314004799794125,"payload":{"asset_id":"107603864457683460275633293642179940881969192120168665300712204232021063124301","best_ask":"0.39","best_bid":"0.33","event_type":"best_bid_ask","market":"0xd412ce774cfcf8dc9f71164aac78783978aac7b03871702a3b8a481bd9dc9688","spread":"0.06","timestamp":"1785212020643"},"payload_hash":"eef8734b095137f8d34d02289b77dd89d76a073925298cff6575362ab79fbe16","raw_frame":"{\"market\":\"0xd412ce774cfcf8dc9f71164aac78783978aac7b03871702a3b8a481bd9dc9688\", \"asset_id\":\"107603864457683460275633293642179940881969192120168665300712204232021063124301\", \"best_bid\":\"0.33\", \"best_ask\":\"0.39\", \"spread\":\"0.06\", \"timestamp\":\"1785212020643\", \"event_type\":\"best_bid_ask\"}","received_at":"2026-07-28T04:13:41.721663Z","schema_version":"clob-market-ws.best_bid_ask.v1","sequence":null,"server_hash":null,"server_timestamp":"1785212020643","session_id":"2d607381e3054cee91998cdf45a4231c","source":"clob_market_ws"},"received_at":"2026-07-28T04:13:41.721663Z","record_id":"bf3dc0c5e050d02d329d17a55aa071a97374fdb31557db9180931d41c942f1ed","schema_fingerprint":"8488399f31b0337811b13b266be932db7062827c2470b78bd8e9e99bab51d17d","schema_version":"edge-lab-recorder.raw.v1","sequence":null,"source":"clob_market_ws"}
{"event_at":"2026-07-28T04:13:40.643000Z","event_fingerprint":"92eddfe3f84134ea9975290c13cdb2b781e652acfd9aee66685c6baeb9028117","payload":{"connection_id":"f6725804f86a4c4eb588e4d5ed7db029","event_at":"2026-07-28T04:13:40.643000Z","event_type":"best_bid_ask","frame_hash":"03d8a7d528ab2ede7fc8c016565f4d4d7735359a19ae2ece68d0194bceaaa99f","frame_index":0,"kind":"data","monotonic_ns":314004800432000,"payload":{"asset_id":"96600821790790307414914106093858868634329285205417149685270682748367152458577","best_ask":"0.67","best_bid":"0.61","event_type":"best_bid_ask","market":"0xd412ce774cfcf8dc9f71164aac78783978aac7b03871702a3b8a481bd9dc9688","spread":"0.06","timestamp":"1785212020643"},"payload_hash":"1c21b03923ff784dabf7b1d16c4db27f56489898c09b7adc45da3680c08b308c","raw_frame":"{\"market\":\"0xd412ce774cfcf8dc9f71164aac78783978aac7b03871702a3b8a481bd9dc9688\", \"asset_id\":\"96600821790790307414914106093858868634329285205417149685270682748367152458577\", \"best_bid\":\"0.61\", \"best_ask\":\"0.67\", \"spread\":\"0.06\", \"timestamp\":\"1785212020643\", \"event_type\":\"best_bid_ask\"}","received_at":"2026-07-28T04:13:41.722301Z","schema_version":"clob-market-ws.best_bid_ask.v1","sequence":null,"server_hash":null,"server_timestamp":"1785212020643","session_id":"2d607381e3054cee91998cdf45a4231c","source":"clob_market_ws"},"received_at":"2026-07-28T04:13:41.722301Z","record_id":"f7246b4fc50dc744d5da366c244f7627c0bcd88b646c6103a4527ae89db5e01f","schema_fingerprint":"8488399f31b0337811b13b266be932db7062827c2470b78bd8e9e99bab51d17d","schema_version":"edge-lab-recorder.raw.v1","sequence":null,"source":"clob_market_ws"}
{"event_at":"2026-07-28T04:13:40.643000Z","event_fingerprint":"7e6e783a18741bdd6229e0fd8cfc644e7e86f7a51c866e838d43de7a134e2dd3","payload":{"connection_id":"f6725804f86a4c4eb588e4d5ed7db029","event_at":"2026-07-28T04:13:40.643000Z","event_type":"price_change","frame_hash":"3747baa395cc6421250cc8d53ef86425d8f9a80b2199e810380eb01431b5b4a2","frame_index":0,"kind":"data","monotonic_ns":314004801058416,"payload":{"event_type":"price_change","market":"0xd412ce774cfcf8dc9f71164aac78783978aac7b03871702a3b8a481bd9dc9688","price_changes":[{"asset_id":"96600821790790307414914106093858868634329285205417149685270682748367152458577","best_ask":"0.67","best_bid":"0.61","hash":"1a4713e7888dea5edaca38d9caad63890fba85e8","price":"0.61","side":"BUY","size":"6"},{"asset_id":"107603864457683460275633293642179940881969192120168665300712204232021063124301","best_ask":"0.39","best_bid":"0.33","hash":"2f7d69ddf0b09a316d0c1bc144e01d0923ac5c91","price":"0.39","side":"SELL","size":"6"}],"timestamp":"1785212020643"},"payload_hash":"3e47ccacab1dccec6dc9c8383af6d0e36b82b422e4d47169c8b1a52125b346b2","raw_frame":"{\"market\":\"0xd412ce774cfcf8dc9f71164aac78783978aac7b03871702a3b8a481bd9dc9688\", \"price_changes\":[{\"asset_id\":\"96600821790790307414914106093858868634329285205417149685270682748367152458577\", \"price\":\"0.61\", \"size\":\"6\", \"side\":\"BUY\", \"hash\":\"1a4713e7888dea5edaca38d9caad63890fba85e8\", \"best_bid\":\"0.61\", \"best_ask\":\"0.67\"}, {\"asset_id\":\"107603864457683460275633293642179940881969192120168665300712204232021063124301\", \"price\":\"0.39\", \"size\":\"6\", \"side\":\"SELL\", \"hash\":\"2f7d69ddf0b09a316d0c1bc144e01d0923ac5c91\", \"best_bid\":\"0.33\", \"best_ask\":\"0.39\"}], \"timestamp\":\"1785212020643\", \"event_type\":\"price_change\"}","received_at":"2026-07-28T04:13:41.722928Z","schema_version":"clob-market-ws.price_change.v1","sequence":null,"server_hash":null,"server_timestamp":"1785212020643","session_id":"2d607381e3054cee91998cdf45a4231c","source":"clob_market_ws"},"received_at":"2026-07-28T04:13:41.722928Z","record_id":"280cc3f0abdc90e60b010cd601f65e586c59f4ee1676249f39165e1d6c86263f","schema_fingerprint":"4aa3821a28b0b7c2400bc59aba4bcc0a76e971dadd19610d3ad38c768e124dc7","schema_version":"edge-lab-recorder.raw.v1","sequence":null,"source":"clob_market_ws"}
{"event_at":"2026-07-28T04:13:40.644000Z","event_fingerprint":"e183438702c4370f598aa4c0e83a612c752eb1170230d7d7a229c4905702cb21","payload":{"connection_id":"f6725804f86a4c4eb588e4d5ed7db029","event_at":"2026-07-28T04:13:40.644000Z","event_type":"price_change","frame_hash":"b66594dbfdbc8f5bd97892d9a4b9d5835e8a755ac9e29065253b765309043938","frame_index":0,"kind":"data","monotonic_ns":314004802165458,"payload":{"event_type":"price_change","market":"0xd412ce774cfcf8dc9f71164aac78783978aac7b03871702a3b8a481bd9dc9688","price_changes":[{"asset_id":"96600821790790307414914106093858868634329285205417149685270682748367152458577","best_ask":"0.67","best_bid":"0.61","hash":"f74c15b62aa6d234383b652df712db85a06bbdb4","price":"0.01","side":"BUY","size":"5295.02"},{"asset_id":"107603864457683460275633293642179940881969192120168665300712204232021063124301","best_ask":"0.39","best_bid":"0.33","hash":"b6dc66ca2ffd2314b24f1b209ac3b5afb1dd3d36","price":"0.99","side":"SELL","size":"5295.02"}],"timestamp":"1785212020644"},"payload_hash":"ba2fba1cee8a15ddd6b97de657893ea1feb77fc03f5c700db434e9270f4da881","raw_frame":"{\"market\":\"0xd412ce774cfcf8dc9f71164aac78783978aac7b03871702a3b8a481bd9dc9688\", \"price_changes\":[{\"asset_id\":\"96600821790790307414914106093858868634329285205417149685270682748367152458577\", \"price\":\"0.01\", \"size\":\"5295.02\", \"side\":\"BUY\", \"hash\":\"f74c15b62aa6d234383b652df712db85a06bbdb4\", \"best_bid\":\"0.61\", \"best_ask\":\"0.67\"}, {\"asset_id\":\"107603864457683460275633293642179940881969192120168665300712204232021063124301\", \"price\":\"0.99\", \"size\":\"5295.02\", \"side\":\"SELL\", \"hash\":\"b6dc66ca2ffd2314b24f1b209ac3b5afb1dd3d36\", \"best_bid\":\"0.33\", \"best_ask\":\"0.39\"}], \"timestamp\":\"1785212020644\", \"event_type\":\"price_change\"}","received_at":"2026-07-28T04:13:41.724027Z","schema_version":"clob-market-ws.price_change.v1","sequence":null,"server_hash":null,"server_timestamp":"1785212020644","session_id":"2d607381e3054cee91998cdf45a4231c","source":"clob_market_ws"},"received_at":"2026-07-28T04:13:41.724027Z","record_id":"61a4b39bba0d3fe370618def9f29c56f2599851f741056f7f3c26fc29f28a732","schema_fingerprint":"4aa3821a28b0b7c2400bc59aba4bcc0a76e971dadd19610d3ad38c768e124dc7","schema_version":"edge-lab-recorder.raw.v1","sequence":null,"source":"clob_market_ws"}
{"event_at":"2026-07-28T04:13:40.644000Z","event_fingerprint":"26a86aafc0988f5a682281e73318c36359a582788983e42d55c069bbbd1a603a","payload":{"connection_id":"f6725804f86a4c4eb588e4d5ed7db029","event_at":"2026-07-28T04:13:40.644000Z","event_type":"price_change","frame_hash":"834352b011ec449fc6baeb6765a8833191b404c2db963eb0ae6ca074d7059318","frame_index":0,"kind":"data","monotonic_ns":314004803713375,"payload":{"event_type":"price_change","market":"0xd412ce774cfcf8dc9f71164aac78783978aac7b03871702a3b8a481bd9dc9688","price_changes":[{"asset_id":"96600821790790307414914106093858868634329285205417149685270682748367152458577","best_ask":"0.67","best_bid":"0.61","hash":"345cc43136010ce76429ce759424fdaf049ec352","price":"0.61","side":"BUY","size":"11"},{"asset_id":"107603864457683460275633293642179940881969192120168665300712204232021063124301","best_ask":"0.39","best_bid":"0.33","hash":"524b8c208fa3f30e94c5d1c7d990c08a45382f53","price":"0.39","side":"SELL","size":"11"}],"timestamp":"1785212020644"},"payload_hash":"47e8712f702ed1ddfc07150370cf4dd9f7d480bf371f97953b0b244c737d8b1a","raw_frame":"{\"market\":\"0xd412ce774cfcf8dc9f71164aac78783978aac7b03871702a3b8a481bd9dc9688\", \"price_changes\":[{\"asset_id\":\"96600821790790307414914106093858868634329285205417149685270682748367152458577\", \"price\":\"0.61\", \"size\":\"11\", \"side\":\"BUY\", \"hash\":\"345cc43136010ce76429ce759424fdaf049ec352\", \"best_bid\":\"0.61\", \"best_ask\":\"0.67\"}, {\"asset_id\":\"107603864457683460275633293642179940881969192120168665300712204232021063124301\", \"price\":\"0.39\", \"size\":\"11\", \"side\":\"SELL\", \"hash\":\"524b8c208fa3f30e94c5d1c7d990c08a45382f53\", \"best_bid\":\"0.33\", \"best_ask\":\"0.39\"}], \"timestamp\":\"1785212020644\", \"event_type\":\"price_change\"}","received_at":"2026-07-28T04:13:41.725575Z","schema_version":"clob-market-ws.price_change.v1","sequence":null,"server_hash":null,"server_timestamp":"1785212020644","session_id":"2d607381e3054cee91998cdf45a4231c","source":"clob_market_ws"},"received_at":"2026-07-28T04:13:41.725575Z","record_id":"98f64c31e21ea2b80147c576d037125b1657392424d4b5b36ce3138776947ada","schema_fingerprint":"4aa3821a28b0b7c2400bc59aba4bcc0a76e971dadd19610d3ad38c768e124dc7","schema_version":"edge-lab-recorder.raw.v1","sequence":null,"source":"clob_market_ws"}
{"event_at":"2026-07-28T04:13:40.647000Z","event_fingerprint":"1f8476670a16ecdead67b2be01b4650e460259e71c0a5a1961d8585520e35f66","payload":{"connection_id":"f6725804f86a4c4eb588e4d5ed7db029","event_at":"2026-07-28T04:13:40.647000Z","event_type":"price_change","frame_hash":"cdf9dd436a3117479aa11e08936c2606aae0c50306a4419dd4caefc634a3905d","frame_index":0,"kind":"data","monotonic_ns":314004805254541,"payload":{"event_type":"price_change","market":"0xd412ce774cfcf8dc9f71164aac78783978aac7b03871702a3b8a481bd9dc9688","price_changes":[{"asset_id":"107603864457683460275633293642179940881969192120168665300712204232021063124301","best_ask":"0.39","best_bid":"0.33","hash":"8d64fd3efcfbf9c5d77bff0cdfb551fb883e2e74","price":"0.39","side":"SELL","size":"16"},{"asset_id":"96600821790790307414914106093858868634329285205417149685270682748367152458577","best_ask":"0.67","best_bid":"0.61","hash":"2db40624ed50a2890a6b239e7eb168a9896b140c","price":"0.61","side":"BUY","size":"16"}],"timestamp":"1785212020647"},"payload_hash":"7587cfe78a1b73ba4fa91142f7ec7e9052845fb20476dea8cb4c665b2e1a5a01","raw_frame":"{\"market\":\"0xd412ce774cfcf8dc9f71164aac78783978aac7b03871702a3b8a481bd9dc9688\", \"price_changes\":[{\"asset_id\":\"107603864457683460275633293642179940881969192120168665300712204232021063124301\", \"price\":\"0.39\", \"size\":\"16\", \"side\":\"SELL\", \"hash\":\"8d64fd3efcfbf9c5d77bff0cdfb551fb883e2e74\", \"best_bid\":\"0.33\", \"best_ask\":\"0.39\"}, {\"asset_id\":\"96600821790790307414914106093858868634329285205417149685270682748367152458577\", \"price\":\"0.61\", \"size\":\"16\", \"side\":\"BUY\", \"hash\":\"2db40624ed50a2890a6b239e7eb168a9896b140c\", \"best_bid\":\"0.61\", \"best_ask\":\"0.67\"}], \"timestamp\":\"1785212020647\", \"event_type\":\"price_change\"}","received_at":"2026-07-28T04:13:41.727117Z","schema_version":"clob-market-ws.price_change.v1","sequence":null,"server_hash":null,"server_timestamp":"1785212020647","session_id":"2d607381e3054cee91998cdf45a4231c","source":"clob_market_ws"},"received_at":"2026-07-28T04:13:41.727117Z","record_id":"1ad2d3984b1cae03aebec664e31f76490b60b43acc527cb2d4570c526a63956b","schema_fingerprint":"4aa3821a28b0b7c2400bc59aba4bcc0a76e971dadd19610d3ad38c768e124dc7","schema_version":"edge-lab-recorder.raw.v1","sequence":null,"source":"clob_market_ws"}
{"event_at":"2026-07-28T04:13:40.655000Z","event_fingerprint":"309f4b7aa7aaa39ea7df04412ecb847dad669dd5411c583e4dffd32d6b3aea6f","payload":{"connection_id":"f6725804f86a4c4eb588e4d5ed7db029","event_at":"2026-07-28T04:13:40.655000Z","event_type":"price_change","frame_hash":"40864c28c5eda20c5a023375deec68be3515510ffef39b14890604bd45375a27","frame_index":0,"kind":"data","monotonic_ns":314004806781500,"payload":{"event_type":"price_change","market":"0xd412ce774cfcf8dc9f71164aac78783978aac7b03871702a3b8a481bd9dc9688","price_changes":[{"asset_id":"96600821790790307414914106093858868634329285205417149685270682748367152458577","best_ask":"0.67","best_bid":"0.61","hash":"ba1774d3d79ef11518f795175cdd71f39243329a","price":"0.54","side":"BUY","size":"90.09"},{"asset_id":"107603864457683460275633293642179940881969192120168665300712204232021063124301","best_ask":"0.39","best_bid":"0.33","hash":"2d3c028ad16aa7e9eb75a98a953bf8eb2b306fe3","price":"0.46","side":"SELL","size":"90.09"}],"timestamp":"1785212020655"},"payload_hash":"9c1f509ffbecb8b65c273f9c74c82d94b94e3a9f8174a81203ac4f1a22ec845a","raw_frame":"{\"market\":\"0xd412ce774cfcf8dc9f71164aac78783978aac7b03871702a3b8a481bd9dc9688\", \"price_changes\":[{\"asset_id\":\"96600821790790307414914106093858868634329285205417149685270682748367152458577\", \"price\":\"0.54\", \"size\":\"90.09\", \"side\":\"BUY\", \"hash\":\"ba1774d3d79ef11518f795175cdd71f39243329a\", \"best_bid\":\"0.61\", \"best_ask\":\"0.67\"}, {\"asset_id\":\"107603864457683460275633293642179940881969192120168665300712204232021063124301\", \"price\":\"0.46\", \"size\":\"90.09\", \"side\":\"SELL\", \"hash\":\"2d3c028ad16aa7e9eb75a98a953bf8eb2b306fe3\", \"best_bid\":\"0.33\", \"best_ask\":\"0.39\"}], \"timestamp\":\"1785212020655\", \"event_type\":\"price_change\"}","received_at":"2026-07-28T04:13:41.728644Z","schema_version":"clob-market-ws.price_change.v1","sequence":null,"server_hash":null,"server_timestamp":"1785212020655","session_id":"2d607381e3054cee91998cdf45a4231c","source":"clob_market_ws"},"received_at":"2026-07-28T04:13:41.728644Z","record_id":"2b7bc3617ce691dc014917e94f30ea4ace4c810d0ac05e506a66ec491bee7528","schema_fingerprint":"4aa3821a28b0b7c2400bc59aba4bcc0a76e971dadd19610d3ad38c768e124dc7","schema_version":"edge-lab-recorder.raw.v1","sequence":null,"source":"clob_market_ws"}
{"event_at":"2026-07-28T04:13:40.658000Z","event_fingerprint":"a85fdfa41e622997f0db3b51f10404ca68460bdb663f8a9c576a80b630285a0e","payload":{"connection_id":"f6725804f86a4c4eb588e4d5ed7db029","event_at":"2026-07-28T04:13:40.658000Z","event_type":"price_change","frame_hash":"60d17935df12fe17f63e77f91acbee2481c661b84ad56cb2169d17c0c9abd6cd","frame_index":0,"kind":"data","monotonic_ns":314004808310458,"payload":{"event_type":"price_change","market":"0xd412ce774cfcf8dc9f71164aac78783978aac7b03871702a3b8a481bd9dc9688","price_changes":[{"asset_id":"107603864457683460275633293642179940881969192120168665300712204232021063124301","best_ask":"0.39","best_bid":"0.33","hash":"10f15294dc43fd1100a3b93440b3e4a7f36c807d","price":"0.39","side":"SELL","size":"11"},{"asset_id":"96600821790790307414914106093858868634329285205417149685270682748367152458577","best_ask":"0.67","best_bid":"0.61","hash":"8b276fcb6636c19b9c2ebb2512bf3c514df12475","price":"0.61","side":"BUY","size":"11"}],"timestamp":"1785212020658"},"payload_hash":"f945ec4720d5d84377a22f8fdac66814649a4194f95e0d97811b25e20f9beb79","raw_frame":"{\"market\":\"0xd412ce774cfcf8dc9f71164aac78783978aac7b03871702a3b8a481bd9dc9688\", \"price_changes\":[{\"asset_id\":\"107603864457683460275633293642179940881969192120168665300712204232021063124301\", \"price\":\"0.39\", \"size\":\"11\", \"side\":\"SELL\", \"hash\":\"10f15294dc43fd1100a3b93440b3e4a7f36c807d\", \"best_bid\":\"0.33\", \"best_ask\":\"0.39\"}, {\"asset_id\":\"96600821790790307414914106093858868634329285205417149685270682748367152458577\", \"price\":\"0.61\", \"size\":\"11\", \"side\":\"BUY\", \"hash\":\"8b276fcb6636c19b9c2ebb2512bf3c514df12475\", \"best_bid\":\"0.61\", \"best_ask\":\"0.67\"}], \"timestamp\":\"1785212020658\", \"event_type\":\"price_change\"}","received_at":"2026-07-28T04:13:41.730173Z","schema_version":"clob-market-ws.price_change.v1","sequence":null,"server_hash":null,"server_timestamp":"1785212020658","session_id":"2d607381e3054cee91998cdf45a4231c","source":"clob_market_ws"},"received_at":"2026-07-28T04:13:41.730173Z","record_id":"891ee15c6a3c6b5c86ae6d86643877e54cc8da62f4d583a2b5835ae8f8927ea0","schema_fingerprint":"4aa3821a28b0b7c2400bc59aba4bcc0a76e971dadd19610d3ad38c768e124dc7","schema_version":"edge-lab-recorder.raw.v1","sequence":null,"source":"clob_market_ws"}
{"event_at":"2026-07-28T04:13:40.658000Z","event_fingerprint":"e5ac3b03ff2e02743f9d8ef3eeed46d43498a35a9901a66c9875d7a468f1a7d0","payload":{"connection_id":"f6725804f86a4c4eb588e4d5ed7db029","event_at":"2026-07-28T04:13:40.658000Z","event_type":"price_change","frame_hash":"decd552fcd7fb45a467ba10d9e5c1bf99e18adc9801d06316509245ced6e7ca8","frame_index":0,"kind":"data","monotonic_ns":314004809839083,"payload":{"event_type":"price_change","market":"0xd412ce774cfcf8dc9f71164aac78783978aac7b03871702a3b8a481bd9dc9688","price_changes":[{"asset_id":"96600821790790307414914106093858868634329285205417149685270682748367152458577","best_ask":"0.67","best_bid":"0.61","hash":"3cde3e0c22b46e8fe1e442a82cbcce9c38e6d6bf","price":"0.61","side":"BUY","size":"6"},{"asset_id":"107603864457683460275633293642179940881969192120168665300712204232021063124301","best_ask":"0.39","best_bid":"0.33","hash":"a3406b3af768c3df381077faa320036922645d0a","price":"0.39","side":"SELL","size":"6"}],"timestamp":"1785212020658"},"payload_hash":"30fdcff412688764bbe97daac0fb19faea41bd9179ed32f4bf6b8ffd1169b70a","raw_frame":"{\"market\":\"0xd412ce774cfcf8dc9f71164aac78783978aac7b03871702a3b8a481bd9dc9688\", \"price_changes\":[{\"asset_id\":\"96600821790790307414914106093858868634329285205417149685270682748367152458577\", \"price\":\"0.61\", \"size\":\"6\", \"side\":\"BUY\", \"hash\":\"3cde3e0c22b46e8fe1e442a82cbcce9c38e6d6bf\", \"best_bid\":\"0.61\", \"best_ask\":\"0.67\"}, {\"asset_id\":\"107603864457683460275633293642179940881969192120168665300712204232021063124301\", \"price\":\"0.39\", \"size\":\"6\", \"side\":\"SELL\", \"hash\":\"a3406b3af768c3df381077faa320036922645d0a\", \"best_bid\":\"0.33\", \"best_ask\":\"0.39\"}], \"timestamp\":\"1785212020658\", \"event_type\":\"price_change\"}","received_at":"2026-07-28T04:13:41.731701Z","schema_version":"clob-market-ws.price_change.v1","sequence":null,"server_hash":null,"server_timestamp":"1785212020658","session_id":"2d607381e3054cee91998cdf45a4231c","source":"clob_market_ws"},"received_at":"2026-07-28T04:13:41.731701Z","record_id":"0cd2825f2bee05b953139e95fe36ab5c63d18c094f46c328c32ae98203c97937","schema_fingerprint":"4aa3821a28b0b7c2400bc59aba4bcc0a76e971dadd19610d3ad38c768e124dc7","schema_version":"edge-lab-recorder.raw.v1","sequence":null,"source":"clob_market_ws"}
{"event_at":"2026-07-28T04:13:40.672000Z","event_fingerprint":"2d2d2966579c6a15ae786676b5ecd7a97bc11faa7ae9a3391d7bec453f3839f5","payload":{"connection_id":"f6725804f86a4c4eb588e4d5ed7db029","event_at":"2026-07-28T04:13:40.672000Z","event_type":"best_bid_ask","frame_hash":"64ecc15d6fcebf7d7fe218f7b74a2da909abdd8aa3f339f4e83db1ded0ea23b4","frame_index":0,"kind":"data","monotonic_ns":314004811443583,"payload":{"asset_id":"107603864457683460275633293642179940881969192120168665300712204232021063124301","best_ask":"0.39","best_bid":"0.34","event_type":"best_bid_ask","market":"0xd412ce774cfcf8dc9f71164aac78783978aac7b03871702a3b8a481bd9dc9688","spread":"0.05","timestamp":"1785212020672"},"payload_hash":"ba554a8bc9591a14f112525ba41368c6c326cf6ad3dbf84a21fda111ef1c6ad6","raw_frame":"{\"market\":\"0xd412ce774cfcf8dc9f71164aac78783978aac7b03871702a3b8a481bd9dc9688\", \"asset_id\":\"107603864457683460275633293642179940881969192120168665300712204232021063124301\", \"best_bid\":\"0.34\", \"best_ask\":\"0.39\", \"spread\":\"0.05\", \"timestamp\":\"1785212020672\", \"event_type\":\"best_bid_ask\"}","received_at":"2026-07-28T04:13:41.733306Z","schema_version":"clob-market-ws.best_bid_ask.v1","sequence":null,"server_hash":null,"server_timestamp":"1785212020672","session_id":"2d607381e3054cee91998cdf45a4231c","source":"clob_market_ws"},"received_at":"2026-07-28T04:13:41.733306Z","record_id":"41637ef4da9f0c0ed0100b0f382c2d00cbce53277e30d2743c327903dfaaaa8f","schema_fingerprint":"8488399f31b0337811b13b266be932db7062827c2470b78bd8e9e99bab51d17d","schema_version":"edge-lab-recorder.raw.v1","sequence":null,"source":"clob_market_ws"}
{"event_at":"2026-07-28T04:13:40.672000Z","event_fingerprint":"854bf3c8c51e4f22deb466c5ad707b343acb8302259913dc19a48a7c1fc2d78a","payload":{"connection_id":"f6725804f86a4c4eb588e4d5ed7db029","event_at":"2026-07-28T04:13:40.672000Z","event_type":"best_bid_ask","frame_hash":"9a57754b3785f46247a6aff45cc65bd788af26a7ac584536583087eb71e66da0","frame_index":0,"kind":"data","monotonic_ns":314004812530916,"payload":{"asset_id":"96600821790790307414914106093858868634329285205417149685270682748367152458577","best_ask":"0.66","best_bid":"0.61","event_type":"best_bid_ask","market":"0xd412ce774cfcf8dc9f71164aac78783978aac7b03871702a3b8a481bd9dc9688","spread":"0.05","timestamp":"1785212020672"},"payload_hash":"273885c0bc118e651819e2dde373d5c0a1e46b87f251216c1b4892b0d1dc3f6f","raw_frame":"{\"market\":\"0xd412ce774cfcf8dc9f71164aac78783978aac7b03871702a3b8a481bd9dc9688\", \"asset_id\":\"96600821790790307414914106093858868634329285205417149685270682748367152458577\", \"best_bid\":\"0.61\", \"best_ask\":\"0.66\", \"spread\":\"0.05\", \"timestamp\":\"1785212020672\", \"event_type\":\"best_bid_ask\"}","received_at":"2026-07-28T04:13:41.734392Z","schema_version":"clob-market-ws.best_bid_ask.v1","sequence":null,"server_hash":null,"server_timestamp":"1785212020672","session_id":"2d607381e3054cee91998cdf45a4231c","source":"clob_market_ws"},"received_at":"2026-07-28T04:13:41.734392Z","record_id":"c51c765ae5a2791afb64bb6ece7e9e3c2d545a59c633d2372dc70e6e846386e1","schema_fingerprint":"8488399f31b0337811b13b266be932db7062827c2470b78bd8e9e99bab51d17d","schema_version":"edge-lab-recorder.raw.v1","sequence":null,"source":"clob_market_ws"}
{"event_at":"2026-07-28T04:13:40.672000Z","event_fingerprint":"fa77358172fdb3ec58c723ac0d96f8f8c481f2d161d86860c5ebeaaed63fd637","payload":{"connection_id":"f6725804f86a4c4eb588e4d5ed7db029","event_at":"2026-07-28T04:13:40.672000Z","event_type":"price_change","frame_hash":"1ac0aecbf12b56b56e60dacb2b090a64a0e8a68f9a7dae16ee32aea60a0161f4","frame_index":0,"kind":"data","monotonic_ns":314004813712041,"payload":{"event_type":"price_change","market":"0xd412ce774cfcf8dc9f71164aac78783978aac7b03871702a3b8a481bd9dc9688","price_changes":[{"asset_id":"107603864457683460275633293642179940881969192120168665300712204232021063124301","best_ask":"0.39","best_bid":"0.34","hash":"04446066e4ef95efb40d57de4f3084b533b81da3","price":"0.34","side":"BUY","size":"6"},{"asset_id":"96600821790790307414914106093858868634329285205417149685270682748367152458577","best_ask":"0.66","best_bid":"0.61","hash":"c980e7a85f9c6c3d325671e2c3b0322ad0be6176","price":"0.66","side":"SELL","size":"6"}],"timestamp":"1785212020672"},"payload_hash":"179b09a41f12d1769263ae22c2e99737745fd9c6c641a623f837dbfd33f9e5aa","raw_frame":"{\"market\":\"0xd412ce774cfcf8dc9f71164aac78783978aac7b03871702a3b8a481bd9dc9688\", \"price_changes\":[{\"asset_id\":\"107603864457683460275633293642179940881969192120168665300712204232021063124301\", \"price\":\"0.34\", \"size\":\"6\", \"side\":\"BUY\", \"hash\":\"04446066e4ef95efb40d57de4f3084b533b81da3\", \"best_bid\":\"0.34\", \"best_ask\":\"0.39\"}, {\"asset_id\":\"96600821790790307414914106093858868634329285205417149685270682748367152458577\", \"price\":\"0.66\", \"size\":\"6\", \"side\":\"SELL\", \"hash\":\"c980e7a85f9c6c3d325671e2c3b0322ad0be6176\", \"best_bid\":\"0.61\", \"best_ask\":\"0.66\"}], \"timestamp\":\"1785212020672\", \"event_type\":\"price_change\"}","received_at":"2026-07-28T04:13:41.735574Z","schema_version":"clob-market-ws.price_change.v1","sequence":null,"server_hash":null,"server_timestamp":"1785212020672","session_id":"2d607381e3054cee91998cdf45a4231c","source":"clob_market_ws"},"received_at":"2026-07-28T04:13:41.735574Z","record_id":"98861b410e7944bb9aadbe08cf963c45019d2e7cf97e643c381c38f319bdb1c8","schema_fingerprint":"4aa3821a28b0b7c2400bc59aba4bcc0a76e971dadd19610d3ad38c768e124dc7","schema_version":"edge-lab-recorder.raw.v1","sequence":null,"source":"clob_market_ws"}
{"event_at":"2026-07-28T04:13:40.675000Z","event_fingerprint":"c47c55107d46dc6c9ed79fae192cc6678920f7ae694a7f462ebd4d98a4477e7d","payload":{"connection_id":"f6725804f86a4c4eb588e4d5ed7db029","event_at":"2026-07-28T04:13:40.675000Z","event_type":"best_bid_ask","frame_hash":"b4344818663b4aede7276575b9aabe6c2f800615badd8ca060da0473ecd71faa","frame_index":0,"kind":"data","monotonic_ns":314004815221291,"payload":{"asset_id":"107603864457683460275633293642179940881969192120168665300712204232021063124301","best_ask":"0.39","best_bid":"0.33","event_type":"best_bid_ask","market":"0xd412ce774cfcf8dc9f71164aac78783978aac7b03871702a3b8a481bd9dc9688","spread":"0.06","timestamp":"1785212020675"},"payload_hash":"2f3194477622c37808a82e457bc7b59838bf29e67388c793bfabfef846dc3a25","raw_frame":"{\"market\":\"0xd412ce774cfcf8dc9f71164aac78783978aac7b03871702a3b8a481bd9dc9688\", \"asset_id\":\"107603864457683460275633293642179940881969192120168665300712204232021063124301\", \"best_bid\":\"0.33\", \"best_ask\":\"0.39\", \"spread\":\"0.06\", \"timestamp\":\"1785212020675\", \"event_type\":\"best_bid_ask\"}","received_at":"2026-07-28T04:13:41.737084Z","schema_version":"clob-market-ws.best_bid_ask.v1","sequence":null,"server_hash":null,"server_timestamp":"1785212020675","session_id":"2d607381e3054cee91998cdf45a4231c","source":"clob_market_ws"},"received_at":"2026-07-28T04:13:41.737084Z","record_id":"b164ac62cab13f3bbecf4b88c75b82395a8fb9eb827533489e98285fdea85e03","schema_fingerprint":"8488399f31b0337811b13b266be932db7062827c2470b78bd8e9e99bab51d17d","schema_version":"edge-lab-recorder.raw.v1","sequence":null,"source":"clob_market_ws"}
{"event_at":"2026-07-28T04:13:40.675000Z","event_fingerprint":"66a9b81adb48844fc6413f40b69122ee753f7dd710ee0753bc3548ac9adc74bc","payload":{"connection_id":"f6725804f86a4c4eb588e4d5ed7db029","event_at":"2026-07-28T04:13:40.675000Z","event_type":"best_bid_ask","frame_hash":"b48c22374d92471eff6d0b722fd07706d4c95904199f0905b0fb7c78677d0ce5","frame_index":0,"kind":"data","monotonic_ns":314004816298458,"payload":{"asset_id":"96600821790790307414914106093858868634329285205417149685270682748367152458577","best_ask":"0.67","best_bid":"0.61","event_type":"best_bid_ask","market":"0xd412ce774cfcf8dc9f71164aac78783978aac7b03871702a3b8a481bd9dc9688","spread":"0.06","timestamp":"1785212020675"},"payload_hash":"13c2e2f7433deb08d9559a8e7c9bb29b0a1b67c6f08423acef093318560600ca","raw_frame":"{\"market\":\"0xd412ce774cfcf8dc9f71164aac78783978aac7b03871702a3b8a481bd9dc9688\", \"asset_id\":\"96600821790790307414914106093858868634329285205417149685270682748367152458577\", \"best_bid\":\"0.61\", \"best_ask\":\"0.67\", \"spread\":\"0.06\", \"timestamp\":\"1785212020675\", \"event_type\":\"best_bid_ask\"}","received_at":"2026-07-28T04:13:41.738162Z","schema_version":"clob-market-ws.best_bid_ask.v1","sequence":null,"server_hash":null,"server_timestamp":"1785212020675","session_id":"2d607381e3054cee91998cdf45a4231c","source":"clob_market_ws"},"received_at":"2026-07-28T04:13:41.738162Z","record_id":"add22e13b520e6c83cb0f1d83e2dfcf628f09d1caf73c39292b4f5ebda7de2eb","schema_fingerprint":"8488399f31b0337811b13b266be932db7062827c2470b78bd8e9e99bab51d17d","schema_version":"edge-lab-recorder.raw.v1","sequence":null,"source":"clob_market_ws"}
{"event_at":"2026-07-28T04:13:40.675000Z","event_fingerprint":"99ada13b83e2bccd48da036fe5ae4c7e329de5994ada390217791eaf860eecf2","payload":{"connection_id":"f6725804f86a4c4eb588e4d5ed7db029","event_at":"2026-07-28T04:13:40.675000Z","event_type":"price_change","frame_hash":"72ac3ed2218f52407c277d27b5d07b4601fb26d45e9a625e36d457641ef62008","frame_index":0,"kind":"data","monotonic_ns":314004817353625,"payload":{"event_type":"price_change","market":"0xd412ce774cfcf8dc9f71164aac78783978aac7b03871702a3b8a481bd9dc9688","price_changes":[{"asset_id":"107603864457683460275633293642179940881969192120168665300712204232021063124301","best_ask":"0.39","best_bid":"0.33","hash":"7ad954fd99c3e85928b6b35b2913ffee39342050","price":"0.34","side":"BUY","size":"0"},{"asset_id":"96600821790790307414914106093858868634329285205417149685270682748367152458577","best_ask":"0.67","best_bid":"0.61","hash":"1ac48bf5159e4ee9a253205f53f4f82da6e72e07","price":"0.66","side":"SELL","size":"0"}],"timestamp":"1785212020675"},"payload_hash":"99a51813be11f289ae4aa74dc0d500e7006c186fc2d85d5e6d7d90147a9aa067","raw_frame":"{\"market\":\"0xd412ce774cfcf8dc9f71164aac78783978aac7b03871702a3b8a481bd9dc9688\", \"price_changes\":[{\"asset_id\":\"107603864457683460275633293642179940881969192120168665300712204232021063124301\", \"price\":\"0.34\", \"size\":\"0\", \"side\":\"BUY\", \"hash\":\"7ad954fd99c3e85928b6b35b2913ffee39342050\", \"best_bid\":\"0.33\", \"best_ask\":\"0.39\"}, {\"asset_id\":\"96600821790790307414914106093858868634329285205417149685270682748367152458577\", \"price\":\"0.66\", \"size\":\"0\", \"side\":\"SELL\", \"hash\":\"1ac48bf5159e4ee9a253205f53f4f82da6e72e07\", \"best_bid\":\"0.61\", \"best_ask\":\"0.67\"}], \"timestamp\":\"1785212020675\", \"event_type\":\"price_change\"}","received_at":"2026-07-28T04:13:41.739216Z","schema_version":"clob-market-ws.price_change.v1","sequence":null,"server_hash":null,"server_timestamp":"1785212020675","session_id":"2d607381e3054cee91998cdf45a4231c","source":"clob_market_ws"},"received_at":"2026-07-28T04:13:41.739216Z","record_id":"ad6424e6080ac1c992b7d8b56b99dea48241ddab0fd28c74a4fa67e71d11f2cf","schema_fingerprint":"4aa3821a28b0b7c2400bc59aba4bcc0a76e971dadd19610d3ad38c768e124dc7","schema_version":"edge-lab-recorder.raw.v1","sequence":null,"source":"clob_market_ws"}
{"event_at":"2026-07-28T04:13:40.696000Z","event_fingerprint":"ece5cb5e7254db038c9a530c15a181089dd1416fc4f1f9f6b5907094d12d4a3e","payload":{"connection_id":"f6725804f86a4c4eb588e4d5ed7db029","event_at":"2026-07-28T04:13:40.696000Z","event_type":"price_change","frame_hash":"18ac4d6033a03d99c70f5468f1a091180e4861c7442626878313d311e260dce1","frame_index":0,"kind":"data","monotonic_ns":314004818852958,"payload":{"event_type":"price_change","market":"0xd412ce774cfcf8dc9f71164aac78783978aac7b03871702a3b8a481bd9dc9688","price_changes":[{"asset_id":"96600821790790307414914106093858868634329285205417149685270682748367152458577","best_ask":"0.67","best_bid":"0.61","hash":"f06aa202226583dc230fc7d779ce2083d1b6332c","price":"0.01","side":"BUY","size":"5290.02"},{"asset_id":"107603864457683460275633293642179940881969192120168665300712204232021063124301","best_ask":"0.39","best_bid":"0.33","hash":"1eeffc84f30483742bc91006be8b371382eede0c","price":"0.99","side":"SELL","size":"5290.02"}],"timestamp":"1785212020696"},"payload_hash":"d19a807a484832d49f8bd71e4c8bf0b1159a07dae7bdc449a730c7b5a4d69aa9","raw_frame":"{\"market\":\"0xd412ce774cfcf8dc9f71164aac78783978aac7b03871702a3b8a481bd9dc9688\", \"price_changes\":[{\"asset_id\":\"96600821790790307414914106093858868634329285205417149685270682748367152458577\", \"price\":\"0.01\", \"size\":\"5290.02\", \"side\":\"BUY\", \"hash\":\"f06aa202226583dc230fc7d779ce2083d1b6332c\", \"best_bid\":\"0.61\", \"best_ask\":\"0.67\"}, {\"asset_id\":\"107603864457683460275633293642179940881969192120168665300712204232021063124301\", \"price\":\"0.99\", \"size\":\"5290.02\", \"side\":\"SELL\", \"hash\":\"1eeffc84f30483742bc91006be8b371382eede0c\", \"best_bid\":\"0.33\", \"best_ask\":\"0.39\"}], \"timestamp\":\"1785212020696\", \"event_type\":\"price_change\"}","received_at":"2026-07-28T04:13:41.740716Z","schema_version":"clob-market-ws.price_change.v1","sequence":null,"server_hash":null,"server_timestamp":"1785212020696","session_id":"2d607381e3054cee91998cdf45a4231c","source":"clob_market_ws"},"received_at":"2026-07-28T04:13:41.740716Z","record_id":"24c433b3266c42d9d847a1c8afbdb40a93f8cbdbb99e81db61b9468ec02a40b8","schema_fingerprint":"4aa3821a28b0b7c2400bc59aba4bcc0a76e971dadd19610d3ad38c768e124dc7","schema_version":"edge-lab-recorder.raw.v1","sequence":null,"source":"clob_market_ws"}
{"event_at":"2026-07-28T04:13:40.717000Z","event_fingerprint":"18d4ca4a919ffe39c051c9de8c7913caf3e069cf30296d4f867edb25a52c2855","payload":{"connection_id":"f6725804f86a4c4eb588e4d5ed7db029","event_at":"2026-07-28T04:13:40.717000Z","event_type":"price_change","frame_hash":"5e60dba2ee524b2a5c38550138ee044f069ad171a3bd1502a3fadc49257520db","frame_index":0,"kind":"data","monotonic_ns":314004820335500,"payload":{"event_type":"price_change","market":"0xd412ce774cfcf8dc9f71164aac78783978aac7b03871702a3b8a481bd9dc9688","price_changes":[{"asset_id":"107603864457683460275633293642179940881969192120168665300712204232021063124301","best_ask":"0.39","best_bid":"0.33","hash":"31f3e955c2c75d0f2aadff3cf63e1153898d6ba9","price":"0.33","side":"BUY","size":"67"},{"asset_id":"96600821790790307414914106093858868634329285205417149685270682748367152458577","best_ask":"0.67","best_bid":"0.61","hash":"5fa927beeadd2133727994203f9aabaf22401828","price":"0.67","side":"SELL","size":"67"}],"timestamp":"1785212020717"},"payload_hash":"09c50eb9be75869831fad63bed9eb36c4c7f75b11b73303e6f614cc7e349d35c","raw_frame":"{\"market\":\"0xd412ce774cfcf8dc9f71164aac78783978aac7b03871702a3b8a481bd9dc9688\", \"price_changes\":[{\"asset_id\":\"107603864457683460275633293642179940881969192120168665300712204232021063124301\", \"price\":\"0.33\", \"size\":\"67\", \"side\":\"BUY\", \"hash\":\"31f3e955c2c75d0f2aadff3cf63e1153898d6ba9\", \"best_bid\":\"0.33\", \"best_ask\":\"0.39\"}, {\"asset_id\":\"96600821790790307414914106093858868634329285205417149685270682748367152458577\", \"price\":\"0.67\", \"size\":\"67\", \"side\":\"SELL\", \"hash\":\"5fa927beeadd2133727994203f9aabaf22401828\", \"best_bid\":\"0.61\", \"best_ask\":\"0.67\"}], \"timestamp\":\"1785212020717\", \"event_type\":\"price_change\"}","received_at":"2026-07-28T04:13:41.742198Z","schema_version":"clob-market-ws.price_change.v1","sequence":null,"server_hash":null,"server_timestamp":"1785212020717","session_id":"2d607381e3054cee91998cdf45a4231c","source":"clob_market_ws"},"received_at":"2026-07-28T04:13:41.742198Z","record_id":"d5fd4613bc4d6f713f36bd182ca878726eeb76dbdc6813ff1520b11339c99048","schema_fingerprint":"4aa3821a28b0b7c2400bc59aba4bcc0a76e971dadd19610d3ad38c768e124dc7","schema_version":"edge-lab-recorder.raw.v1","sequence":null,"source":"clob_market_ws"}
{"event_at":"2026-07-28T04:13:40.718000Z","event_fingerprint":"321590ed69521d0fbdf85e4c1e6686b5a788a6d4750e90c1d643c204a7ba2786","payload":{"connection_id":"f6725804f86a4c4eb588e4d5ed7db029","event_at":"2026-07-28T04:13:40.718000Z","event_type":"price_change","frame_hash":"a6a75d35b5012c5d71cca46b89b8692ec61e52b4b7fcd652b5e3176b072727f3","frame_index":0,"kind":"data","monotonic_ns":314004821920875,"payload":{"event_type":"price_change","market":"0xd412ce774cfcf8dc9f71164aac78783978aac7b03871702a3b8a481bd9dc9688","price_changes":[{"asset_id":"96600821790790307414914106093858868634329285205417149685270682748367152458577","best_ask":"0.67","best_bid":"0.61","hash":"b2bca9c0ba222c6bc7c7a0c8bf3a068335955c3c","price":"0.01","side":"BUY","size":"5295.02"},{"asset_id":"107603864457683460275633293642179940881969192120168665300712204232021063124301","best_ask":"0.39","best_bid":"0.33","hash":"6df162c6024a2ca795f62b59f28bd0c691c8772e","price":"0.99","side":"SELL","size":"5295.02"}],"timestamp":"1785212020718"},"payload_hash":"a75ec38d3e3d41bbe74b57b9a353dd1e817bdd6e19215bac6dcec932c2e8d002","raw_frame":"{\"market\":\"0xd412ce774cfcf8dc9f71164aac78783978aac7b03871702a3b8a481bd9dc9688\", \"price_changes\":[{\"asset_id\":\"96600821790790307414914106093858868634329285205417149685270682748367152458577\", \"price\":\"0.01\", \"size\":\"5295.02\", \"side\":\"BUY\", \"hash\":\"b2bca9c0ba222c6bc7c7a0c8bf3a068335955c3c\", \"best_bid\":\"0.61\", \"best_ask\":\"0.67\"}, {\"asset_id\":\"107603864457683460275633293642179940881969192120168665300712204232021063124301\", \"price\":\"0.99\", \"size\":\"5295.02\", \"side\":\"SELL\", \"hash\":\"6df162c6024a2ca795f62b59f28bd0c691c8772e\", \"best_bid\":\"0.33\", \"best_ask\":\"0.39\"}], \"timestamp\":\"1785212020718\", \"event_type\":\"price_change\"}","received_at":"2026-07-28T04:13:41.743782Z","schema_version":"clob-market-ws.price_change.v1","sequence":null,"server_hash":null,"server_timestamp":"1785212020718","session_id":"2d607381e3054cee91998cdf45a4231c","source":"clob_market_ws"},"received_at":"2026-07-28T04:13:41.743782Z","record_id":"9620922a1f376de39c827967a3f993201c4948e0e9cf57a02cb9b8ba12664f85","schema_fingerprint":"4aa3821a28b0b7c2400bc59aba4bcc0a76e971dadd19610d3ad38c768e124dc7","schema_version":"edge-lab-recorder.raw.v1","sequence":null,"source":"clob_market_ws"}
{"event_at":"2026-07-28T04:13:40.743000Z","event_fingerprint":"a2987adf018f71916cb73d1b38352e0432cf2e8848c83b9879c4ebdc6ec6ca7d","payload":{"connection_id":"f6725804f86a4c4eb588e4d5ed7db029","event_at":"2026-07-28T04:13:40.743000Z","event_type":"price_change","frame_hash":"06298fff69304395c3ba7d75f957b31fd95cb2ffb516b259b321a796e32db481","frame_index":0,"kind":"data","monotonic_ns":314004823494666,"payload":{"event_type":"price_change","market":"0xd412ce774cfcf8dc9f71164aac78783978aac7b03871702a3b8a481bd9dc9688","price_changes":[{"asset_id":"96600821790790307414914106093858868634329285205417149685270682748367152458577","best_ask":"0.67","best_bid":"0.61","hash":"65f7ae9c37eb269376b328c00c5d7bd10d4316ae","price":"0.01","side":"BUY","size":"5290.02"},{"asset_id":"107603864457683460275633293642179940881969192120168665300712204232021063124301","best_ask":"0.39","best_bid":"0.33","hash":"e5e2b8acf57462e7cf9365c56707b8b9289e017f","price":"0.99","side":"SELL","size":"5290.02"}],"timestamp":"1785212020743"},"payload_hash":"289e95ea7f6321ff88cbbca60bac29fa8ab53a47a53b90383b93f5ab9bb901f4","raw_frame":"{\"market\":\"0xd412ce774cfcf8dc9f71164aac78783978aac7b03871702a3b8a481bd9dc9688\", \"price_changes\":[{\"asset_id\":\"96600821790790307414914106093858868634329285205417149685270682748367152458577\", \"price\":\"0.01\", \"size\":\"5290.02\", \"side\":\"BUY\", \"hash\":\"65f7ae9c37eb269376b328c00c5d7bd10d4316ae\", \"best_bid\":\"0.61\", \"best_ask\":\"0.67\"}, {\"asset_id\":\"107603864457683460275633293642179940881969192120168665300712204232021063124301\", \"price\":\"0.99\", \"size\":\"5290.02\", \"side\":\"SELL\", \"hash\":\"e5e2b8acf57462e7cf9365c56707b8b9289e017f\", \"best_bid\":\"0.33\", \"best_ask\":\"0.39\"}], \"timestamp\":\"1785212020743\", \"event_type\":\"price_change\"}","received_at":"2026-07-28T04:13:41.745356Z","schema_version":"clob-market-ws.price_change.v1","sequence":null,"server_hash":null,"server_timestamp":"1785212020743","session_id":"2d607381e3054cee91998cdf45a4231c","source":"clob_market_ws"},"received_at":"2026-07-28T04:13:41.745356Z","record_id":"bc0842db1539522786bb80adb65a9fccc30b110eafa0fbf2cdcd76b46070e6d9","schema_fingerprint":"4aa3821a28b0b7c2400bc59aba4bcc0a76e971dadd19610d3ad38c768e124dc7","schema_version":"edge-lab-recorder.raw.v1","sequence":null,"source":"clob_market_ws"}
{"event_at":"2026-07-28T04:13:40.766000Z","event_fingerprint":"dc431dbb6a7af26d925033356965e2dd965b8145b0243004c94cf9f6453d41e8","payload":{"connection_id":"f6725804f86a4c4eb588e4d5ed7db029","event_at":"2026-07-28T04:13:40.766000Z","event_type":"best_bid_ask","frame_hash":"3c2db0402f2248911446389946fbc3a04467272943dca143d4cec58867bcc142","frame_index":0,"kind":"data","monotonic_ns":314004825023500,"payload":{"asset_id":"107603864457683460275633293642179940881969192120168665300712204232021063124301","best_ask":"0.38","best_bid":"0.33","event_type":"best_bid_ask","market":"0xd412ce774cfcf8dc9f71164aac78783978aac7b03871702a3b8a481bd9dc9688","spread":"0.05","timestamp":"1785212020766"},"payload_hash":"1644dc5f77eb7f23eab3989c022ebd0ace7a0feb689516c544f995fd2240964b","raw_frame":"{\"market\":\"0xd412ce774cfcf8dc9f71164aac78783978aac7b03871702a3b8a481bd9dc9688\", \"asset_id\":\"107603864457683460275633293642179940881969192120168665300712204232021063124301\", \"best_bid\":\"0.33\", \"best_ask\":\"0.38\", \"spread\":\"0.05\", \"timestamp\":\"1785212020766\", \"event_type\":\"best_bid_ask\"}","received_at":"2026-07-28T04:13:41.746885Z","schema_version":"clob-market-ws.best_bid_ask.v1","sequence":null,"server_hash":null,"server_timestamp":"1785212020766","session_id":"2d607381e3054cee91998cdf45a4231c","source":"clob_market_ws"},"received_at":"2026-07-28T04:13:41.746885Z","record_id":"53fba86188ce724c5caba6e43aa8b4d0fc1e3d76f9269d8b9ed35d2485b47e5f","schema_fingerprint":"8488399f31b0337811b13b266be932db7062827c2470b78bd8e9e99bab51d17d","schema_version":"edge-lab-recorder.raw.v1","sequence":null,"source":"clob_market_ws"}
{"event_at":"2026-07-28T04:13:40.766000Z","event_fingerprint":"ce63dfc0127aad39b851348289da1cf52dabf5881f160640f671e2fb44d46027","payload":{"connection_id":"f6725804f86a4c4eb588e4d5ed7db029","event_at":"2026-07-28T04:13:40.766000Z","event_type":"best_bid_ask","frame_hash":"c01e31434e0d1c6900937a9361bf6ad673b4eff11e82ce67f12362fcd31e2f18","frame_index":0,"kind":"data","monotonic_ns":314004826193625,"payload":{"asset_id":"96600821790790307414914106093858868634329285205417149685270682748367152458577","best_ask":"0.67","best_bid":"0.62","event_type":"best_bid_ask","market":"0xd412ce774cfcf8dc9f71164aac78783978aac7b03871702a3b8a481bd9dc9688","spread":"0.05","timestamp":"1785212020766"},"payload_hash":"07db81af758320842d316a372930d836b2732dc7a3b769576903ced31a122774","raw_frame":"{\"market\":\"0xd412ce774cfcf8dc9f71164aac78783978aac7b03871702a3b8a481bd9dc9688\", \"asset_id\":\"96600821790790307414914106093858868634329285205417149685270682748367152458577\", \"best_bid\":\"0.62\", \"best_ask\":\"0.67\", \"spread\":\"0.05\", \"timestamp\":\"1785212020766\", \"event_type\":\"best_bid_ask\"}","received_at":"2026-07-28T04:13:41.748056Z","schema_version":"clob-market-ws.best_bid_ask.v1","sequence":null,"server_hash":null,"server_timestamp":"1785212020766","session_id":"2d607381e3054cee91998cdf45a4231c","source":"clob_market_ws"},"received_at":"2026-07-28T04:13:41.748056Z","record_id":"be5a289ce93b275e3bb89406493d32cd6e0fe3aa149481515aa56a13e698d3ad","schema_fingerprint":"8488399f31b0337811b13b266be932db7062827c2470b78bd8e9e99bab51d17d","schema_version":"edge-lab-recorder.raw.v1","sequence":null,"source":"clob_market_ws"}
{"event_at":"2026-07-28T04:13:40.766000Z","event_fingerprint":"18d1a95297ac2f09207a618bc4ab6b124d2b02e76a91ab9e96bed77c8e622a87","payload":{"connection_id":"f6725804f86a4c4eb588e4d5ed7db029","event_at":"2026-07-28T04:13:40.766000Z","event_type":"price_change","frame_hash":"73aa89556b81d956b45cb5b796cae9cd72a6b5d5c12e6731ab02fe2df4670a31","frame_index":0,"kind":"data","monotonic_ns":314004827256833,"payload":{"event_type":"price_change","market":"0xd412ce774cfcf8dc9f71164aac78783978aac7b03871702a3b8a481bd9dc9688","price_changes":[{"asset_id":"107603864457683460275633293642179940881969192120168665300712204232021063124301","best_ask":"0.38","best_bid":"0.33","hash":"dec5b5cadbc7c5e0d8aa8d78548ae5523d2c2b84","price":"0.38","side":"SELL","size":"6"},{"asset_id":"96600821790790307414914106093858868634329285205417149685270682748367152458577","best_ask":"0.67","best_bid":"0.62","hash":"aadcef253d5d8ff48eb20724b372c30495efa284","price":"0.62","side":"BUY","size":"6"}],"timestamp":"1785212020766"},"payload_hash":"19455730ddbaebf5333c69fe27f10132acd26a5f2cb0c2de107255c14b8f9213","raw_frame":"{\"market\":\"0xd412ce774cfcf8dc9f71164aac78783978aac7b03871702a3b8a481bd9dc9688\", \"price_changes\":[{\"asset_id\":\"107603864457683460275633293642179940881969192120168665300712204232021063124301\", \"price\":\"0.38\", \"size\":\"6\", \"side\":\"SELL\", \"hash\":\"dec5b5cadbc7c5e0d8aa8d78548ae5523d2c2b84\", \"best_bid\":\"0.33\", \"best_ask\":\"0.38\"}, {\"asset_id\":\"96600821790790307414914106093858868634329285205417149685270682748367152458577\", \"price\":\"0.62\", \"size\":\"6\", \"side\":\"BUY\", \"hash\":\"aadcef253d5d8ff48eb20724b372c30495efa284\", \"best_bid\":\"0.62\", \"best_ask\":\"0.67\"}], \"timestamp\":\"1785212020766\", \"event_type\":\"price_change\"}","received_at":"2026-07-28T04:13:41.749119Z","schema_version":"clob-market-ws.price_change.v1","sequence":null,"server_hash":null,"server_timestamp":"1785212020766","session_id":"2d607381e3054cee91998cdf45a4231c","source":"clob_market_ws"},"received_at":"2026-07-28T04:13:41.749119Z","record_id":"7905f5b91cd29b28879c870586609f7ec359657d6541c8bacf584cf86e7dfd31","schema_fingerprint":"4aa3821a28b0b7c2400bc59aba4bcc0a76e971dadd19610d3ad38c768e124dc7","schema_version":"edge-lab-recorder.raw.v1","sequence":null,"source":"clob_market_ws"}
{"event_at":"2026-07-28T04:13:40.775000Z","event_fingerprint":"baef69dab48b70bb2e13bdd1853ffdcdeebd5988b134db8ab02c60c6838bdaaf","payload":{"connection_id":"f6725804f86a4c4eb588e4d5ed7db029","event_at":"2026-07-28T04:13:40.775000Z","event_type":"price_change","frame_hash":"02f590a8e7135ce7b8294d89423dffcb676915ae1277adc0315219a013448f2d","frame_index":0,"kind":"data","monotonic_ns":314004828752041,"payload":{"event_type":"price_change","market":"0xd412ce774cfcf8dc9f71164aac78783978aac7b03871702a3b8a481bd9dc9688","price_changes":[{"asset_id":"96600821790790307414914106093858868634329285205417149685270682748367152458577","best_ask":"0.67","best_bid":"0.62","hash":"b981373b89348c478145bd787e40db9597442393","price":"0.62","side":"BUY","size":"12"},{"asset_id":"107603864457683460275633293642179940881969192120168665300712204232021063124301","best_ask":"0.38","best_bid":"0.33","hash":"bacb959e5d7c8aefafb256cd01fcc70e494dc002","price":"0.38","side":"SELL","size":"12"}],"timestamp":"1785212020775"},"payload_hash":"4e9a808f1980e11b407abffae45882d2cfe29e2eef6b43a5cc86a833828e86e7","raw_frame":"{\"market\":\"0xd412ce774cfcf8dc9f71164aac78783978aac7b03871702a3b8a481bd9dc9688\", \"price_changes\":[{\"asset_id\":\"96600821790790307414914106093858868634329285205417149685270682748367152458577\", \"price\":\"0.62\", \"size\":\"12\", \"side\":\"BUY\", \"hash\":\"b981373b89348c478145bd787e40db9597442393\", \"best_bid\":\"0.62\", \"best_ask\":\"0.67\"}, {\"asset_id\":\"107603864457683460275633293642179940881969192120168665300712204232021063124301\", \"price\":\"0.38\", \"size\":\"12\", \"side\":\"SELL\", \"hash\":\"bacb959e5d7c8aefafb256cd01fcc70e494dc002\", \"best_bid\":\"0.33\", \"best_ask\":\"0.38\"}], \"timestamp\":\"1785212020775\", \"event_type\":\"price_change\"}","received_at":"2026-07-28T04:13:41.750615Z","schema_version":"clob-market-ws.price_change.v1","sequence":null,"server_hash":null,"server_timestamp":"1785212020775","session_id":"2d607381e3054cee91998cdf45a4231c","source":"clob_market_ws"},"received_at":"2026-07-28T04:13:41.750615Z","record_id":"ade024cb6cb8540e915d2ee77aeda45ffdeb91f55b8a475adf4e25ee6af746b8","schema_fingerprint":"4aa3821a28b0b7c2400bc59aba4bcc0a76e971dadd19610d3ad38c768e124dc7","schema_version":"edge-lab-recorder.raw.v1","sequence":null,"source":"clob_market_ws"}
{"event_at":"2026-07-28T04:13:40.778000Z","event_fingerprint":"e96a8eefbb1c1384821fe223f0f37b02473848055d523871a81b71eec7194451","payload":{"connection_id":"f6725804f86a4c4eb588e4d5ed7db029","event_at":"2026-07-28T04:13:40.778000Z","event_type":"price_change","frame_hash":"51419d55e059cd205a85d213eed882260a16867e5d6ef3fd31f889706e0b8877","frame_index":0,"kind":"data","monotonic_ns":314004830282000,"payload":{"event_type":"price_change","market":"0xd412ce774cfcf8dc9f71164aac78783978aac7b03871702a3b8a481bd9dc9688","price_changes":[{"asset_id":"96600821790790307414914106093858868634329285205417149685270682748367152458577","best_ask":"0.67","best_bid":"0.62","hash":"4d5a10fd42dc53c709e7f00c194ecfbde9e115a6","price":"0.62","side":"BUY","size":"17"},{"asset_id":"107603864457683460275633293642179940881969192120168665300712204232021063124301","best_ask":"0.38","best_bid":"0.33","hash":"c984d1b44c7e30ef6756604d366e45e083ab9b38","price":"0.38","side":"SELL","size":"17"}],"timestamp":"1785212020778"},"payload_hash":"367a6704dfa5dd6a512b92a68b8673164f967ece8e09b3ddb78bde547ed80aa8","raw_frame":"{\"market\":\"0xd412ce774cfcf8dc9f71164aac78783978aac7b03871702a3b8a481bd9dc9688\", \"price_changes\":[{\"asset_id\":\"96600821790790307414914106093858868634329285205417149685270682748367152458577\", \"price\":\"0.62\", \"size\":\"17\", \"side\":\"BUY\", \"hash\":\"4d5a10fd42dc53c709e7f00c194ecfbde9e115a6\", \"best_bid\":\"0.62\", \"best_ask\":\"0.67\"}, {\"asset_id\":\"107603864457683460275633293642179940881969192120168665300712204232021063124301\", \"price\":\"0.38\", \"size\":\"17\", \"side\":\"SELL\", \"hash\":\"c984d1b44c7e30ef6756604d366e45e083ab9b38\", \"best_bid\":\"0.33\", \"best_ask\":\"0.38\"}], \"timestamp\":\"1785212020778\", \"event_type\":\"price_change\"}","received_at":"2026-07-28T04:13:41.752144Z","schema_version":"clob-market-ws.price_change.v1","sequence":null,"server_hash":null,"server_timestamp":"1785212020778","session_id":"2d607381e3054cee91998cdf45a4231c","source":"clob_market_ws"},"received_at":"2026-07-28T04:13:41.752144Z","record_id":"cf55a7af9824e7e63b5111952c6b661687743ff9e3d349c6c9c8b4020db1f8d0","schema_fingerprint":"4aa3821a28b0b7c2400bc59aba4bcc0a76e971dadd19610d3ad38c768e124dc7","schema_version":"edge-lab-recorder.raw.v1","sequence":null,"source":"clob_market_ws"}
{"event_at":"2026-07-28T04:13:40.781000Z","event_fingerprint":"e2b1828f16d080cc02a91e855412c65f65ec53746c8a14688e05d57df73dca89","payload":{"connection_id":"f6725804f86a4c4eb588e4d5ed7db029","event_at":"2026-07-28T04:13:40.781000Z","event_type":"price_change","frame_hash":"6a559fc84c90a7e80a2d763d41032b061614fd992b308bee040821437fbc7f24","frame_index":0,"kind":"data","monotonic_ns":314004831799708,"payload":{"event_type":"price_change","market":"0xd412ce774cfcf8dc9f71164aac78783978aac7b03871702a3b8a481bd9dc9688","price_changes":[{"asset_id":"96600821790790307414914106093858868634329285205417149685270682748367152458577","best_ask":"0.67","best_bid":"0.62","hash":"bb8588ebb33d2bc906616e0ea67f860e668321a0","price":"0.61","side":"BUY","size":"0"},{"asset_id":"107603864457683460275633293642179940881969192120168665300712204232021063124301","best_ask":"0.38","best_bid":"0.33","hash":"49658a888a962c755c71d043a995eb6402f7c55d","price":"0.39","side":"SELL","size":"0"}],"timestamp":"1785212020781"},"payload_hash":"19359de71c640d608499b613c745bbe6f671c1286d6e64d202a7bc1a7c558bac","raw_frame":"{\"market\":\"0xd412ce774cfcf8dc9f71164aac78783978aac7b03871702a3b8a481bd9dc9688\", \"price_changes\":[{\"asset_id\":\"96600821790790307414914106093858868634329285205417149685270682748367152458577\", \"price\":\"0.61\", \"size\":\"0\", \"side\":\"BUY\", \"hash\":\"bb8588ebb33d2bc906616e0ea67f860e668321a0\", \"best_bid\":\"0.62\", \"best_ask\":\"0.67\"}, {\"asset_id\":\"107603864457683460275633293642179940881969192120168665300712204232021063124301\", \"price\":\"0.39\", \"size\":\"0\", \"side\":\"SELL\", \"hash\":\"49658a888a962c755c71d043a995eb6402f7c55d\", \"best_bid\":\"0.33\", \"best_ask\":\"0.38\"}], \"timestamp\":\"1785212020781\", \"event_type\":\"price_change\"}","received_at":"2026-07-28T04:13:41.753662Z","schema_version":"clob-market-ws.price_change.v1","sequence":null,"server_hash":null,"server_timestamp":"1785212020781","session_id":"2d607381e3054cee91998cdf45a4231c","source":"clob_market_ws"},"received_at":"2026-07-28T04:13:41.753662Z","record_id":"c427a340804ab4b461f248321d99797a42cb6ad15a16752a3a281815577152a9","schema_fingerprint":"4aa3821a28b0b7c2400bc59aba4bcc0a76e971dadd19610d3ad38c768e124dc7","schema_version":"edge-lab-recorder.raw.v1","sequence":null,"source":"clob_market_ws"}
{"event_at":"2026-07-28T04:13:40.782000Z","event_fingerprint":"d71ee23d7c836a95a40925c7eeb46e83cb01a8b017c7e82f0b49ff92ebdfdf7d","payload":{"connection_id":"f6725804f86a4c4eb588e4d5ed7db029","event_at":"2026-07-28T04:13:40.782000Z","event_type":"price_change","frame_hash":"7887549e9b8d3406f22f84bad66c83bb23a09b10a9cd84a8f962c074bb67313c","frame_index":0,"kind":"data","monotonic_ns":314004833342541,"payload":{"event_type":"price_change","market":"0xd412ce774cfcf8dc9f71164aac78783978aac7b03871702a3b8a481bd9dc9688","price_changes":[{"asset_id":"107603864457683460275633293642179940881969192120168665300712204232021063124301","best_ask":"0.38","best_bid":"0.33","hash":"d53bb75f0ab6c9c86e7c6fdc512b90c00b3bb401","price":"0.38","side":"SELL","size":"11"},{"asset_id":"96600821790790307414914106093858868634329285205417149685270682748367152458577","best_ask":"0.67","best_bid":"0.62","hash":"24031b6e206becde7b07de613ce203e2f7d95142","price":"0.62","side":"BUY","size":"11"}],"timestamp":"1785212020782"},"payload_hash":"b5d196749295391c37bd7f8b8aef2625206cc2788d1932785a25ea9ea4cd22c2","raw_frame":"{\"market\":\"0xd412ce774cfcf8dc9f71164aac78783978aac7b03871702a3b8a481bd9dc9688\", \"price_changes\":[{\"asset_id\":\"107603864457683460275633293642179940881969192120168665300712204232021063124301\", \"price\":\"0.38\", \"size\":\"11\", \"side\":\"SELL\", \"hash\":\"d53bb75f0ab6c9c86e7c6fdc512b90c00b3bb401\", \"best_bid\":\"0.33\", \"best_ask\":\"0.38\"}, {\"asset_id\":\"96600821790790307414914106093858868634329285205417149685270682748367152458577\", \"price\":\"0.62\", \"size\":\"11\", \"side\":\"BUY\", \"hash\":\"24031b6e206becde7b07de613ce203e2f7d95142\", \"best_bid\":\"0.62\", \"best_ask\":\"0.67\"}], \"timestamp\":\"1785212020782\", \"event_type\":\"price_change\"}","received_at":"2026-07-28T04:13:41.755205Z","schema_version":"clob-market-ws.price_change.v1","sequence":null,"server_hash":null,"server_timestamp":"1785212020782","session_id":"2d607381e3054cee91998cdf45a4231c","source":"clob_market_ws"},"received_at":"2026-07-28T04:13:41.755205Z","record_id":"a0aa4297f06f59e816c517b24a1d3134e6e31fea29d7a7db9bdc13870fec4e11","schema_fingerprint":"4aa3821a28b0b7c2400bc59aba4bcc0a76e971dadd19610d3ad38c768e124dc7","schema_version":"edge-lab-recorder.raw.v1","sequence":null,"source":"clob_market_ws"}
{"event_at":"2026-07-28T04:13:40.782000Z","event_fingerprint":"3f862283378d8eb0b69f36e4ead1d28fc645c0c14a7364f30ea9552c697270df","payload":{"connection_id":"f6725804f86a4c4eb588e4d5ed7db029","event_at":"2026-07-28T04:13:40.782000Z","event_type":"price_change","frame_hash":"0480d28f26c2ff3f8487229755726221ae61a26ad4fb7676a81cf64fb63af270","frame_index":0,"kind":"data","monotonic_ns":314004834798083,"payload":{"event_type":"price_change","market":"0xd412ce774cfcf8dc9f71164aac78783978aac7b03871702a3b8a481bd9dc9688","price_changes":[{"asset_id":"96600821790790307414914106093858868634329285205417149685270682748367152458577","best_ask":"0.67","best_bid":"0.62","hash":"e64bafddfc318611e168f6d80003d38315ad3af8","price":"0.62","side":"BUY","size":"5"},{"asset_id":"107603864457683460275633293642179940881969192120168665300712204232021063124301","best_ask":"0.38","best_bid":"0.33","hash":"1df1c22d0938b6ece8252d0999b3cd483b155549","price":"0.38","side":"SELL","size":"5"}],"timestamp":"1785212020782"},"payload_hash":"4d45aec77600ad42b4e2ece39a305cd4cb5c00725916701ae98152b0a90642e3","raw_frame":"{\"market\":\"0xd412ce774cfcf8dc9f71164aac78783978aac7b03871702a3b8a481bd9dc9688\", \"price_changes\":[{\"asset_id\":\"96600821790790307414914106093858868634329285205417149685270682748367152458577\", \"price\":\"0.62\", \"size\":\"5\", \"side\":\"BUY\", \"hash\":\"e64bafddfc318611e168f6d80003d38315ad3af8\", \"best_bid\":\"0.62\", \"best_ask\":\"0.67\"}, {\"asset_id\":\"107603864457683460275633293642179940881969192120168665300712204232021063124301\", \"price\":\"0.38\", \"size\":\"5\", \"side\":\"SELL\", \"hash\":\"1df1c22d0938b6ece8252d0999b3cd483b155549\", \"best_bid\":\"0.33\", \"best_ask\":\"0.38\"}], \"timestamp\":\"1785212020782\", \"event_type\":\"price_change\"}","received_at":"2026-07-28T04:13:41.756662Z","schema_version":"clob-market-ws.price_change.v1","sequence":null,"server_hash":null,"server_timestamp":"1785212020782","session_id":"2d607381e3054cee91998cdf45a4231c","source":"clob_market_ws"},"received_at":"2026-07-28T04:13:41.756662Z","record_id":"84422a1c145b081710332a9d9a80c8de1da65b32a324f2a6dd590c862ba2e67f","schema_fingerprint":"4aa3821a28b0b7c2400bc59aba4bcc0a76e971dadd19610d3ad38c768e124dc7","schema_version":"edge-lab-recorder.raw.v1","sequence":null,"source":"clob_market_ws"}
{"event_at":"2026-07-28T04:13:40.783000Z","event_fingerprint":"3eb9bc092430c393bef629e25f0598e8699c8f2d76894a48445e95c44aff4243","payload":{"connection_id":"f6725804f86a4c4eb588e4d5ed7db029","event_at":"2026-07-28T04:13:40.783000Z","event_type":"best_bid_ask","frame_hash":"e844a6ed947de9cea150005b6dccb091e5f512a6dbc576ba7c51c03220e477fc","frame_index":0,"kind":"data","monotonic_ns":314004836072041,"payload":{"asset_id":"107603864457683460275633293642179940881969192120168665300712204232021063124301","best_ask":"0.4","best_bid":"0.33","event_type":"best_bid_ask","market":"0xd412ce774cfcf8dc9f71164aac78783978aac7b03871702a3b8a481bd9dc9688","spread":"0.07","timestamp":"1785212020783"},"payload_hash":"6190b8de215488f9682099176c4e371a1c0a1fccb646926cfbcba34366ae3292","raw_frame":"{\"market\":\"0xd412ce774cfcf8dc9f71164aac78783978aac7b03871702a3b8a481bd9dc9688\", \"asset_id\":\"107603864457683460275633293642179940881969192120168665300712204232021063124301\", \"best_bid\":\"0.33\", \"best_ask\":\"0.4\", \"spread\":\"0.07\", \"timestamp\":\"1785212020783\", \"event_type\":\"best_bid_ask\"}","received_at":"2026-07-28T04:13:41.757937Z","schema_version":"clob-market-ws.best_bid_ask.v1","sequence":null,"server_hash":null,"server_timestamp":"1785212020783","session_id":"2d607381e3054cee91998cdf45a4231c","source":"clob_market_ws"},"received_at":"2026-07-28T04:13:41.757937Z","record_id":"b81a26b311f9753e858ecce3ed1e0b23e0687723900d124f33f9543343f9092b","schema_fingerprint":"8488399f31b0337811b13b266be932db7062827c2470b78bd8e9e99bab51d17d","schema_version":"edge-lab-recorder.raw.v1","sequence":null,"source":"clob_market_ws"}
{"event_at":"2026-07-28T04:13:40.783000Z","event_fingerprint":"a6275c6d6c926ea9b0d14c5378a311644ea1815190ab81c0e1dd21e17c43f0a6","payload":{"connection_id":"f6725804f86a4c4eb588e4d5ed7db029","event_at":"2026-07-28T04:13:40.783000Z","event_type":"best_bid_ask","frame_hash":"37a5dd69897ea71df703e84b318ced4b50464606ec6649db06329ce68596ca0e","frame_index":0,"kind":"data","monotonic_ns":314004836966041,"payload":{"asset_id":"96600821790790307414914106093858868634329285205417149685270682748367152458577","best_ask":"0.67","best_bid":"0.6","event_type":"best_bid_ask","market":"0xd412ce774cfcf8dc9f71164aac78783978aac7b03871702a3b8a481bd9dc9688","spread":"0.07","timestamp":"1785212020783"},"payload_hash":"46fd84a94ca349dc67e14f77cea8810322475f9aeb8e9f5f72b507b40a54529a","raw_frame":"{\"market\":\"0xd412ce774cfcf8dc9f71164aac78783978aac7b03871702a3b8a481bd9dc9688\", \"asset_id\":\"96600821790790307414914106093858868634329285205417149685270682748367152458577\", \"best_bid\":\"0.6\", \"best_ask\":\"0.67\", \"spread\":\"0.07\", \"timestamp\":\"1785212020783\", \"event_type\":\"best_bid_ask\"}","received_at":"2026-07-28T04:13:41.758828Z","schema_version":"clob-market-ws.best_bid_ask.v1","sequence":null,"server_hash":null,"server_timestamp":"1785212020783","session_id":"2d607381e3054cee91998cdf45a4231c","source":"clob_market_ws"},"received_at":"2026-07-28T04:13:41.758828Z","record_id":"df9bad20138dd9a92fec21c0fb9644219e0b1a8f347383dc443e61f5a8daf709","schema_fingerprint":"8488399f31b0337811b13b266be932db7062827c2470b78bd8e9e99bab51d17d","schema_version":"edge-lab-recorder.raw.v1","sequence":null,"source":"clob_market_ws"}
{"event_at":"2026-07-28T04:13:40.783000Z","event_fingerprint":"853757553691cdceec4e66073174470a6655c7f1892a54d2bce6e7515e498f1f","payload":{"connection_id":"f6725804f86a4c4eb588e4d5ed7db029","event_at":"2026-07-28T04:13:40.783000Z","event_type":"price_change","frame_hash":"682815031decedf12e9f6ca0297bfa61e3262b2368e794b61e3aeca2990e44ad","frame_index":0,"kind":"data","monotonic_ns":314004838081916,"payload":{"event_type":"price_change","market":"0xd412ce774cfcf8dc9f71164aac78783978aac7b03871702a3b8a481bd9dc9688","price_changes":[{"asset_id":"96600821790790307414914106093858868634329285205417149685270682748367152458577","best_ask":"0.67","best_bid":"0.6","hash":"8c8d01d7b7ec99d4d7d2c62709649e8fe9d2f0fe","price":"0.62","side":"BUY","size":"0"},{"asset_id":"107603864457683460275633293642179940881969192120168665300712204232021063124301","best_ask":"0.4","best_bid":"0.33","hash":"baeb7679adac1dec446886a83a2ea0cb6d8853fe","price":"0.38","side":"SELL","size":"0"}],"timestamp":"1785212020783"},"payload_hash":"ae9025b26d9c93169536959a0678159b0134c4acdd38c99253c2aff6f2cb4aac","raw_frame":"{\"market\":\"0xd412ce774cfcf8dc9f71164aac78783978aac7b03871702a3b8a481bd9dc9688\", \"price_changes\":[{\"asset_id\":\"96600821790790307414914106093858868634329285205417149685270682748367152458577\", \"price\":\"0.62\", \"size\":\"0\", \"side\":\"BUY\", \"hash\":\"8c8d01d7b7ec99d4d7d2c62709649e8fe9d2f0fe\", \"best_bid\":\"0.6\", \"best_ask\":\"0.67\"}, {\"asset_id\":\"107603864457683460275633293642179940881969192120168665300712204232021063124301\", \"price\":\"0.38\", \"size\":\"0\", \"side\":\"SELL\", \"hash\":\"baeb7679adac1dec446886a83a2ea0cb6d8853fe\", \"best_bid\":\"0.33\", \"best_ask\":\"0.4\"}], \"timestamp\":\"1785212020783\", \"event_type\":\"price_change\"}","received_at":"2026-07-28T04:13:41.759942Z","schema_version":"clob-market-ws.price_change.v1","sequence":null,"server_hash":null,"server_timestamp":"1785212020783","session_id":"2d607381e3054cee91998cdf45a4231c","source":"clob_market_ws"},"received_at":"2026-07-28T04:13:41.759942Z","record_id":"7d7776d31b26f4fce5cfea403286b1ce8f26e21f52f5cb89afeb698b9a827b3b","schema_fingerprint":"4aa3821a28b0b7c2400bc59aba4bcc0a76e971dadd19610d3ad38c768e124dc7","schema_version":"edge-lab-recorder.raw.v1","sequence":null,"source":"clob_market_ws"}
{"event_at":"2026-07-28T04:13:40.791000Z","event_fingerprint":"2d42526c64f7075cfde384508d6b735ad1a8e53e05920ee35fd4be9a3f5f6330","payload":{"connection_id":"f6725804f86a4c4eb588e4d5ed7db029","event_at":"2026-07-28T04:13:40.791000Z","event_type":"price_change","frame_hash":"89b0fda85b8e4ef22c0a56b7d07ffb836beafe70e0d84b3a4276f4c7a3fe6a13","frame_index":0,"kind":"data","monotonic_ns":314004839675208,"payload":{"event_type":"price_change","market":"0xd412ce774cfcf8dc9f71164aac78783978aac7b03871702a3b8a481bd9dc9688","price_changes":[{"asset_id":"96600821790790307414914106093858868634329285205417149685270682748367152458577","best_ask":"0.67","best_bid":"0.6","hash":"447aaf7a5883f25ddf6dad7d6c2dcd3c302123dc","price":"0.01","side":"BUY","size":"5295.02"},{"asset_id":"107603864457683460275633293642179940881969192120168665300712204232021063124301","best_ask":"0.4","best_bid":"0.33","hash":"a6651cbeeca708eca30cc52454e52ad33c5b519e","price":"0.99","side":"SELL","size":"5295.02"}],"timestamp":"1785212020791"},"payload_hash":"4bf4104966f0f2f45dd712b94dfa9ab61baf02eda21c7fbc47c29b29cfd367fc","raw_frame":"{\"market\":\"0xd412ce774cfcf8dc9f71164aac78783978aac7b03871702a3b8a481bd9dc9688\", \"price_changes\":[{\"asset_id\":\"96600821790790307414914106093858868634329285205417149685270682748367152458577\", \"price\":\"0.01\", \"size\":\"5295.02\", \"side\":\"BUY\", \"hash\":\"447aaf7a5883f25ddf6dad7d6c2dcd3c302123dc\", \"best_bid\":\"0.6\", \"best_ask\":\"0.67\"}, {\"asset_id\":\"107603864457683460275633293642179940881969192120168665300712204232021063124301\", \"price\":\"0.99\", \"size\":\"5295.02\", \"side\":\"SELL\", \"hash\":\"a6651cbeeca708eca30cc52454e52ad33c5b519e\", \"best_bid\":\"0.33\", \"best_ask\":\"0.4\"}], \"timestamp\":\"1785212020791\", \"event_type\":\"price_change\"}","received_at":"2026-07-28T04:13:41.761538Z","schema_version":"clob-market-ws.price_change.v1","sequence":null,"server_hash":null,"server_timestamp":"1785212020791","session_id":"2d607381e3054cee91998cdf45a4231c","source":"clob_market_ws"},"received_at":"2026-07-28T04:13:41.761538Z","record_id":"e84a3acab6b99b898dddcb658b4e57ce8553ed978ae63a0d0128efd9e3093e3c","schema_fingerprint":"4aa3821a28b0b7c2400bc59aba4bcc0a76e971dadd19610d3ad38c768e124dc7","schema_version":"edge-lab-recorder.raw.v1","sequence":null,"source":"clob_market_ws"}
{"event_at":"2026-07-28T04:13:40.800000Z","event_fingerprint":"5b50a87336d8589abb2aa85af0715a85f5913f6a5ec9da2baea2e46cabbe314b","payload":{"connection_id":"f6725804f86a4c4eb588e4d5ed7db029","event_at":"2026-07-28T04:13:40.800000Z","event_type":"best_bid_ask","frame_hash":"93d224cdbf0611e01077e78d8d858d53c864cfa97433e6abfa81e3d905e8669e","frame_index":0,"kind":"data","monotonic_ns":314004841203916,"payload":{"asset_id":"107603864457683460275633293642179940881969192120168665300712204232021063124301","best_ask":"0.37","best_bid":"0.33","event_type":"best_bid_ask","market":"0xd412ce774cfcf8dc9f71164aac78783978aac7b03871702a3b8a481bd9dc9688","spread":"0.04","timestamp":"1785212020800"},"payload_hash":"74552896ca609175b49426d0d74f4c105b0ca592692ab352eb2823755b2a1683","raw_frame":"{\"market\":\"0xd412ce774cfcf8dc9f71164aac78783978aac7b03871702a3b8a481bd9dc9688\", \"asset_id\":\"107603864457683460275633293642179940881969192120168665300712204232021063124301\", \"best_bid\":\"0.33\", \"best_ask\":\"0.37\", \"spread\":\"0.04\", \"timestamp\":\"1785212020800\", \"event_type\":\"best_bid_ask\"}","received_at":"2026-07-28T04:13:41.763065Z","schema_version":"clob-market-ws.best_bid_ask.v1","sequence":null,"server_hash":null,"server_timestamp":"1785212020800","session_id":"2d607381e3054cee91998cdf45a4231c","source":"clob_market_ws"},"received_at":"2026-07-28T04:13:41.763065Z","record_id":"d08961c854d2484019e811e9f3156c1306c8c326cd23b5663a0451373c510e1b","schema_fingerprint":"8488399f31b0337811b13b266be932db7062827c2470b78bd8e9e99bab51d17d","schema_version":"edge-lab-recorder.raw.v1","sequence":null,"source":"clob_market_ws"}
{"event_at":"2026-07-28T04:13:40.800000Z","event_fingerprint":"b36f99f2c9e8623b26f2beceefd9aede6e4df59a808069a62f4134572e425be2","payload":{"connection_id":"f6725804f86a4c4eb588e4d5ed7db029","event_at":"2026-07-28T04:13:40.800000Z","event_type":"best_bid_ask","frame_hash":"e5784d7db7d50e0dc813e72474d02e564080157a762251d899302955e297415a","frame_index":0,"kind":"data","monotonic_ns":314004842338833,"payload":{"asset_id":"96600821790790307414914106093858868634329285205417149685270682748367152458577","best_ask":"0.67","best_bid":"0.63","event_type":"best_bid_ask","market":"0xd412ce774cfcf8dc9f71164aac78783978aac7b03871702a3b8a481bd9dc9688","spread":"0.04","timestamp":"1785212020800"},"payload_hash":"ce7f2016b38ac2652135d4b67793c82e9b395c325e4be6e70a0e29a9d63c69ce","raw_frame":"{\"market\":\"0xd412ce774cfcf8dc9f71164aac78783978aac7b03871702a3b8a481bd9dc9688\", \"asset_id\":\"96600821790790307414914106093858868634329285205417149685270682748367152458577\", \"best_bid\":\"0.63\", \"best_ask\":\"0.67\", \"spread\":\"0.04\", \"timestamp\":\"1785212020800\", \"event_type\":\"best_bid_ask\"}","received_at":"2026-07-28T04:13:41.764199Z","schema_version":"clob-market-ws.best_bid_ask.v1","sequence":null,"server_hash":null,"server_timestamp":"1785212020800","session_id":"2d607381e3054cee91998cdf45a4231c","source":"clob_market_ws"},"received_at":"2026-07-28T04:13:41.764199Z","record_id":"72459b02f4c6b43d8882dba1574897bbb66ec9aac18b07f6de8380f3d06073b3","schema_fingerprint":"8488399f31b0337811b13b266be932db7062827c2470b78bd8e9e99bab51d17d","schema_version":"edge-lab-recorder.raw.v1","sequence":null,"source":"clob_market_ws"}
{"event_at":"2026-07-28T04:13:40.800000Z","event_fingerprint":"33a40b02de7c20b9c10648b60453abab00e81843e2b320d384bad26b4d0d2595","payload":{"connection_id":"f6725804f86a4c4eb588e4d5ed7db029","event_at":"2026-07-28T04:13:40.800000Z","event_type":"price_change","frame_hash":"8ea2cba91d1f982cc7e0e377795ab3b1165a8f914a289d433e1e259a9de088d2","frame_index":0,"kind":"data","monotonic_ns":314004843460833,"payload":{"event_type":"price_change","market":"0xd412ce774cfcf8dc9f71164aac78783978aac7b03871702a3b8a481bd9dc9688","price_changes":[{"asset_id":"96600821790790307414914106093858868634329285205417149685270682748367152458577","best_ask":"0.67","best_bid":"0.63","hash":"999eaf50b474535a2d86fc6941a3ae7355aecbf6","price":"0.63","side":"BUY","size":"6"},{"asset_id":"107603864457683460275633293642179940881969192120168665300712204232021063124301","best_ask":"0.37","best_bid":"0.33","hash":"761eaa9cde0b7963042e88a9bce65e43db7c8fc3","price":"0.37","side":"SELL","size":"6"}],"timestamp":"1785212020800"},"payload_hash":"da3c00bda9821f92de06274102f550aa5aba2794fca8aa4069be849167012a19","raw_frame":"{\"market\":\"0xd412ce774cfcf8dc9f71164aac78783978aac7b03871702a3b8a481bd9dc9688\", \"price_changes\":[{\"asset_id\":\"96600821790790307414914106093858868634329285205417149685270682748367152458577\", \"price\":\"0.63\", \"size\":\"6\", \"side\":\"BUY\", \"hash\":\"999eaf50b474535a2d86fc6941a3ae7355aecbf6\", \"best_bid\":\"0.63\", \"best_ask\":\"0.67\"}, {\"asset_id\":\"107603864457683460275633293642179940881969192120168665300712204232021063124301\", \"price\":\"0.37\", \"size\":\"6\", \"side\":\"SELL\", \"hash\":\"761eaa9cde0b7963042e88a9bce65e43db7c8fc3\", \"best_bid\":\"0.33\", \"best_ask\":\"0.37\"}], \"timestamp\":\"1785212020800\", \"event_type\":\"price_change\"}","received_at":"2026-07-28T04:13:41.765323Z","schema_version":"clob-market-ws.price_change.v1","sequence":null,"server_hash":null,"server_timestamp":"1785212020800","session_id":"2d607381e3054cee91998cdf45a4231c","source":"clob_market_ws"},"received_at":"2026-07-28T04:13:41.765323Z","record_id":"356fcff8e0941abcade15e618f51ad7ad124a576d82aceb23edec1f8c9577cd7","schema_fingerprint":"4aa3821a28b0b7c2400bc59aba4bcc0a76e971dadd19610d3ad38c768e124dc7","schema_version":"edge-lab-recorder.raw.v1","sequence":null,"source":"clob_market_ws"}
{"event_at":"2026-07-28T04:13:40.805000Z","event_fingerprint":"b8c871c70b66e98dd572b03eca265e83971dc9ab4f7ebf637c9b0dda5f5dca1e","payload":{"connection_id":"f6725804f86a4c4eb588e4d5ed7db029","event_at":"2026-07-28T04:13:40.805000Z","event_type":"price_change","frame_hash":"3bfeb483f3ce981882b0d06608edfa5e8e70cadf5f318de69547bb3eb95aebf3","frame_index":0,"kind":"data","monotonic_ns":314004845026875,"payload":{"event_type":"price_change","market":"0xd412ce774cfcf8dc9f71164aac78783978aac7b03871702a3b8a481bd9dc9688","price_changes":[{"asset_id":"107603864457683460275633293642179940881969192120168665300712204232021063124301","best_ask":"0.37","best_bid":"0.33","hash":"25615bc9f15c806db9e615cdba6912baea689d36","price":"0.39","side":"SELL","size":"5"},{"asset_id":"96600821790790307414914106093858868634329285205417149685270682748367152458577","best_ask":"0.67","best_bid":"0.63","hash":"e3dc6647210f8a245242cb2cbd591b710bfd313c","price":"0.61","side":"BUY","size":"5"}],"timestamp":"1785212020805"},"payload_hash":"77755cef8b2e05c71591a874eed9c346f1383333e8dc9b2c065ab1b6631af6cd","raw_frame":"{\"market\":\"0xd412ce774cfcf8dc9f71164aac78783978aac7b03871702a3b8a481bd9dc9688\", \"price_changes\":[{\"asset_id\":\"107603864457683460275633293642179940881969192120168665300712204232021063124301\", \"price\":\"0.39\", \"size\":\"5\", \"side\":\"SELL\", \"hash\":\"25615bc9f15c806db9e615cdba6912baea689d36\", \"best_bid\":\"0.33\", \"best_ask\":\"0.37\"}, {\"asset_id\":\"96600821790790307414914106093858868634329285205417149685270682748367152458577\", \"price\":\"0.61\", \"size\":\"5\", \"side\":\"BUY\", \"hash\":\"e3dc6647210f8a245242cb2cbd591b710bfd313c\", \"best_bid\":\"0.63\", \"best_ask\":\"0.67\"}], \"timestamp\":\"1785212020805\", \"event_type\":\"price_change\"}","received_at":"2026-07-28T04:13:41.766884Z","schema_version":"clob-market-ws.price_change.v1","sequence":null,"server_hash":null,"server_timestamp":"1785212020805","session_id":"2d607381e3054cee91998cdf45a4231c","source":"clob_market_ws"},"received_at":"2026-07-28T04:13:41.766884Z","record_id":"5d54bd253b15a437dbb22db81241ecaea2f82ede12d923990f52f86eb73b3dd6","schema_fingerprint":"4aa3821a28b0b7c2400bc59aba4bcc0a76e971dadd19610d3ad38c768e124dc7","schema_version":"edge-lab-recorder.raw.v1","sequence":null,"source":"clob_market_ws"}
{"event_at":"2026-07-28T04:13:40.807000Z","event_fingerprint":"3bdde80537f99ad4638e59f8369230aa1b3670383593bed95272900fcd942a38","payload":{"connection_id":"f6725804f86a4c4eb588e4d5ed7db029","event_at":"2026-07-28T04:13:40.807000Z","event_type":"price_change","frame_hash":"c2ab0946a1ed37352d9685b9e2dcc906f8fa38399f3411699e133c7814a03567","frame_index":0,"kind":"data","monotonic_ns":314004846776833,"payload":{"event_type":"price_change","market":"0xd412ce774cfcf8dc9f71164aac78783978aac7b03871702a3b8a481bd9dc9688","price_changes":[{"asset_id":"107603864457683460275633293642179940881969192120168665300712204232021063124301","best_ask":"0.37","best_bid":"0.33","hash":"b41da43b5f7060c6663f76df1ed28783e8c63a6c","price":"0.39","side":"SELL","size":"12"},{"asset_id":"96600821790790307414914106093858868634329285205417149685270682748367152458577","best_ask":"0.67","best_bid":"0.63","hash":"4e93df35d0295bc04d13159e649fb2b888060070","price":"0.61","side":"BUY","size":"12"}],"timestamp":"1785212020807"},"payload_hash":"fe035c2d63330f8aa5850ff74e40c0942ef19a5150a53e70a1953bc584c6b1c0","raw_frame":"{\"market\":\"0xd412ce774cfcf8dc9f71164aac78783978aac7b03871702a3b8a481bd9dc9688\", \"price_changes\":[{\"asset_id\":\"107603864457683460275633293642179940881969192120168665300712204232021063124301\", \"price\":\"0.39\", \"size\":\"12\", \"side\":\"SELL\", \"hash\":\"b41da43b5f7060c6663f76df1ed28783e8c63a6c\", \"best_bid\":\"0.33\", \"best_ask\":\"0.37\"}, {\"asset_id\":\"96600821790790307414914106093858868634329285205417149685270682748367152458577\", \"price\":\"0.61\", \"size\":\"12\", \"side\":\"BUY\", \"hash\":\"4e93df35d0295bc04d13159e649fb2b888060070\", \"best_bid\":\"0.63\", \"best_ask\":\"0.67\"}], \"timestamp\":\"1785212020807\", \"event_type\":\"price_change\"}","received_at":"2026-07-28T04:13:41.768636Z","schema_version":"clob-market-ws.price_change.v1","sequence":null,"server_hash":null,"server_timestamp":"1785212020807","session_id":"2d607381e3054cee91998cdf45a4231c","source":"clob_market_ws"},"received_at":"2026-07-28T04:13:41.768636Z","record_id":"5baf21e226553e9bfa0d9f383f03e4b237433f2ae3f48300a32da353f1c44365","schema_fingerprint":"4aa3821a28b0b7c2400bc59aba4bcc0a76e971dadd19610d3ad38c768e124dc7","schema_version":"edge-lab-recorder.raw.v1","sequence":null,"source":"clob_market_ws"}
{"event_at":"2026-07-28T04:13:40.812000Z","event_fingerprint":"6275358a0e4f755f44fbe7fb95e1af7968896c981e80bc3401165f3b70c1c1d9","payload":{"connection_id":"f6725804f86a4c4eb588e4d5ed7db029","event_at":"2026-07-28T04:13:40.812000Z","event_type":"price_change","frame_hash":"e67a0681171ddf8fd1333519c31af23a4548bdf4d5333ce55c6b2ea3591700a3","frame_index":0,"kind":"data","monotonic_ns":314004848539333,"payload":{"event_type":"price_change","market":"0xd412ce774cfcf8dc9f71164aac78783978aac7b03871702a3b8a481bd9dc9688","price_changes":[{"asset_id":"96600821790790307414914106093858868634329285205417149685270682748367152458577","best_ask":"0.67","best_bid":"0.63","hash":"ef2644e85eedcebaa1cd899373cea06ca292dc16","price":"0.61","side":"BUY","size":"19"},{"asset_id":"107603864457683460275633293642179940881969192120168665300712204232021063124301","best_ask":"0.37","best_bid":"0.33","hash":"c879badba482b34e1d6b41e699fd550539c81a2f","price":"0.39","side":"SELL","size":"19"}],"timestamp":"1785212020812"},"payload_hash":"6690f034114401b491f1b2e131e78fb272198da6fda02db9518f7d4359be9901","raw_frame":"{\"market\":\"0xd412ce774cfcf8dc9f71164aac78783978aac7b03871702a3b8a481bd9dc9688\", \"price_changes\":[{\"asset_id\":\"96600821790790307414914106093858868634329285205417149685270682748367152458577\", \"price\":\"0.61\", \"size\":\"19\", \"side\":\"BUY\", \"hash\":\"ef2644e85eedcebaa1cd899373cea06ca292dc16\", \"best_bid\":\"0.63\", \"best_ask\":\"0.67\"}, {\"asset_id\":\"107603864457683460275633293642179940881969192120168665300712204232021063124301\", \"price\":\"0.39\", \"size\":\"19\", \"side\":\"SELL\", \"hash\":\"c879badba482b34e1d6b41e699fd550539c81a2f\", \"best_bid\":\"0.33\", \"best_ask\":\"0.37\"}], \"timestamp\":\"1785212020812\", \"event_type\":\"price_change\"}","received_at":"2026-07-28T04:13:41.770401Z","schema_version":"clob-market-ws.price_change.v1","sequence":null,"server_hash":null,"server_timestamp":"1785212020812","session_id":"2d607381e3054cee91998cdf45a4231c","source":"clob_market_ws"},"received_at":"2026-07-28T04:13:41.770401Z","record_id":"39960bf48ee4c80731aa3780f0a31df48f2ed1d822cd9602d6b659c0d49b5f19","schema_fingerprint":"4aa3821a28b0b7c2400bc59aba4bcc0a76e971dadd19610d3ad38c768e124dc7","schema_version":"edge-lab-recorder.raw.v1","sequence":null,"source":"clob_market_ws"}
{"event_at":"2026-07-28T04:13:40.814000Z","event_fingerprint":"db0507e5e40ad01e8a6a11f3214217033cc8b2f50030cc86a8c686f2a5471c25","payload":{"connection_id":"f6725804f86a4c4eb588e4d5ed7db029","event_at":"2026-07-28T04:13:40.814000Z","event_type":"price_change","frame_hash":"bd914f275cffc7028fbb9a25032f2168b2e47c0c75c58e15b2dc05db1869d33c","frame_index":0,"kind":"data","monotonic_ns":314004850190541,"payload":{"event_type":"price_change","market":"0xd412ce774cfcf8dc9f71164aac78783978aac7b03871702a3b8a481bd9dc9688","price_changes":[{"asset_id":"96600821790790307414914106093858868634329285205417149685270682748367152458577","best_ask":"0.67","best_bid":"0.63","hash":"2108fbb64089aa71bbd347ba065709922ea8597b","price":"0.61","side":"BUY","size":"25"},{"asset_id":"107603864457683460275633293642179940881969192120168665300712204232021063124301","best_ask":"0.37","best_bid":"0.33","hash":"a332a0d67f778437effa2890ffe1498a6f503579","price":"0.39","side":"SELL","size":"25"}],"timestamp":"1785212020814"},"payload_hash":"29a986a9b69ffdfa4ce59295dc2bdc1c6a4a71175b8ee35cb3bbda03ed3a42b8","raw_frame":"{\"market\":\"0xd412ce774cfcf8dc9f71164aac78783978aac7b03871702a3b8a481bd9dc9688\", \"price_changes\":[{\"asset_id\":\"96600821790790307414914106093858868634329285205417149685270682748367152458577\", \"price\":\"0.61\", \"size\":\"25\", \"side\":\"BUY\", \"hash\":\"2108fbb64089aa71bbd347ba065709922ea8597b\", \"best_bid\":\"0.63\", \"best_ask\":\"0.67\"}, {\"asset_id\":\"107603864457683460275633293642179940881969192120168665300712204232021063124301\", \"price\":\"0.39\", \"size\":\"25\", \"side\":\"SELL\", \"hash\":\"a332a0d67f778437effa2890ffe1498a6f503579\", \"best_bid\":\"0.33\", \"best_ask\":\"0.37\"}], \"timestamp\":\"1785212020814\", \"event_type\":\"price_change\"}","received_at":"2026-07-28T04:13:41.772052Z","schema_version":"clob-market-ws.price_change.v1","sequence":null,"server_hash":null,"server_timestamp":"1785212020814","session_id":"2d607381e3054cee91998cdf45a4231c","source":"clob_market_ws"},"received_at":"2026-07-28T04:13:41.772052Z","record_id":"329608e27aed5768137e9cea10ce3fe5944f732e1d7e7b035b97f7f9d975ad42","schema_fingerprint":"4aa3821a28b0b7c2400bc59aba4bcc0a76e971dadd19610d3ad38c768e124dc7","schema_version":"edge-lab-recorder.raw.v1","sequence":null,"source":"clob_market_ws"}
{"event_at":"2026-07-28T04:13:40.815000Z","event_fingerprint":"569308e4cd65f8d1a6b7afb9bffbcb8d6e1595ce47c1a167d591daa3d546b486","payload":{"connection_id":"f6725804f86a4c4eb588e4d5ed7db029","event_at":"2026-07-28T04:13:40.815000Z","event_type":"price_change","frame_hash":"cd722ea8b0a811017343acad693d665e3db5ad903ca5066d1c0055ede256cc08","frame_index":0,"kind":"data","monotonic_ns":314004851775083,"payload":{"event_type":"price_change","market":"0xd412ce774cfcf8dc9f71164aac78783978aac7b03871702a3b8a481bd9dc9688","price_changes":[{"asset_id":"107603864457683460275633293642179940881969192120168665300712204232021063124301","best_ask":"0.37","best_bid":"0.33","hash":"827388df51e50600bda936adf3947edddf22b45b","price":"0.39","side":"SELL","size":"18"},{"asset_id":"96600821790790307414914106093858868634329285205417149685270682748367152458577","best_ask":"0.67","best_bid":"0.63","hash":"c3fe96fa005850ce148e512347f0f2f407c851ba","price":"0.61","side":"BUY","size":"18"}],"timestamp":"1785212020815"},"payload_hash":"2ae49f4a2856c993df3dd6cfbd224edd74d6e137d16fffbc3a9a0c152ef2a449","raw_frame":"{\"market\":\"0xd412ce774cfcf8dc9f71164aac78783978aac7b03871702a3b8a481bd9dc9688\", \"price_changes\":[{\"asset_id\":\"107603864457683460275633293642179940881969192120168665300712204232021063124301\", \"price\":\"0.39\", \"size\":\"18\", \"side\":\"SELL\", \"hash\":\"827388df51e50600bda936adf3947edddf22b45b\", \"best_bid\":\"0.33\", \"best_ask\":\"0.37\"}, {\"asset_id\":\"96600821790790307414914106093858868634329285205417149685270682748367152458577\", \"price\":\"0.61\", \"size\":\"18\", \"side\":\"BUY\", \"hash\":\"c3fe96fa005850ce148e512347f0f2f407c851ba\", \"best_bid\":\"0.63\", \"best_ask\":\"0.67\"}], \"timestamp\":\"1785212020815\", \"event_type\":\"price_change\"}","received_at":"2026-07-28T04:13:41.773637Z","schema_version":"clob-market-ws.price_change.v1","sequence":null,"server_hash":null,"server_timestamp":"1785212020815","session_id":"2d607381e3054cee91998cdf45a4231c","source":"clob_market_ws"},"received_at":"2026-07-28T04:13:41.773637Z","record_id":"4152baa68b460ad47eaccc979c9f7093f6e032a08604776faf1ade07798ce6a8","schema_fingerprint":"4aa3821a28b0b7c2400bc59aba4bcc0a76e971dadd19610d3ad38c768e124dc7","schema_version":"edge-lab-recorder.raw.v1","sequence":null,"source":"clob_market_ws"}
{"event_at":"2026-07-28T04:13:40.815000Z","event_fingerprint":"641361cf0220aa30a9d451480ea580cf76b2c5ae3be39270088eccc36b30212e","payload":{"connection_id":"f6725804f86a4c4eb588e4d5ed7db029","event_at":"2026-07-28T04:13:40.815000Z","event_type":"price_change","frame_hash":"aedc525f53316622ec017f8009f58f7c7bdb1b6d1f21bf124053a744e5d9d956","frame_index":0,"kind":"data","monotonic_ns":314004853281916,"payload":{"event_type":"price_change","market":"0xd412ce774cfcf8dc9f71164aac78783978aac7b03871702a3b8a481bd9dc9688","price_changes":[{"asset_id":"96600821790790307414914106093858868634329285205417149685270682748367152458577","best_ask":"0.67","best_bid":"0.63","hash":"1d321eb76811444a10d92a316de2a5e9254ad429","price":"0.61","side":"BUY","size":"11"},{"asset_id":"107603864457683460275633293642179940881969192120168665300712204232021063124301","best_ask":"0.37","best_bid":"0.33","hash":"bd4a5095f314de4f9ab0bac4270db24c0fec3882","price":"0.39","side":"SELL","size":"11"}],"timestamp":"1785212020815"},"payload_hash":"603968e9ea33b8cd0dac1b91626f24101f5ee8b4b89fba2f0550e5220992d630","raw_frame":"{\"market\":\"0xd412ce774cfcf8dc9f71164aac78783978aac7b03871702a3b8a481bd9dc9688\", \"price_changes\":[{\"asset_id\":\"96600821790790307414914106093858868634329285205417149685270682748367152458577\", \"price\":\"0.61\", \"size\":\"11\", \"side\":\"BUY\", \"hash\":\"1d321eb76811444a10d92a316de2a5e9254ad429\", \"best_bid\":\"0.63\", \"best_ask\":\"0.67\"}, {\"asset_id\":\"107603864457683460275633293642179940881969192120168665300712204232021063124301\", \"price\":\"0.39\", \"size\":\"11\", \"side\":\"SELL\", \"hash\":\"bd4a5095f314de4f9ab0bac4270db24c0fec3882\", \"best_bid\":\"0.33\", \"best_ask\":\"0.37\"}], \"timestamp\":\"1785212020815\", \"event_type\":\"price_change\"}","received_at":"2026-07-28T04:13:41.775144Z","schema_version":"clob-market-ws.price_change.v1","sequence":null,"server_hash":null,"server_timestamp":"1785212020815","session_id":"2d607381e3054cee91998cdf45a4231c","source":"clob_market_ws"},"received_at":"2026-07-28T04:13:41.775144Z","record_id":"833e9aa099bb974b78f9d0d7effdccd1d51d0169b3fa6d8751e07e02d7a341ef","schema_fingerprint":"4aa3821a28b0b7c2400bc59aba4bcc0a76e971dadd19610d3ad38c768e124dc7","schema_version":"edge-lab-recorder.raw.v1","sequence":null,"source":"clob_market_ws"}
{"event_at":"2026-07-28T04:13:40.815000Z","event_fingerprint":"b08dab2f195f7b50ef80d1e3bc85946587bdae4b7462b4c5472302b24af71ff1","payload":{"connection_id":"f6725804f86a4c4eb588e4d5ed7db029","event_at":"2026-07-28T04:13:40.815000Z","event_type":"price_change","frame_hash":"84b1cc92387c48f02e67494873649f88a2112c9ad3185e97f58697fb76a56459","frame_index":0,"kind":"data","monotonic_ns":314004854812083,"payload":{"event_type":"price_change","market":"0xd412ce774cfcf8dc9f71164aac78783978aac7b03871702a3b8a481bd9dc9688","price_changes":[{"asset_id":"96600821790790307414914106093858868634329285205417149685270682748367152458577","best_ask":"0.67","best_bid":"0.63","hash":"ca31823688766c0a7fd3abd6a17f131c717f5b26","price":"0.61","side":"BUY","size":"5"},{"asset_id":"107603864457683460275633293642179940881969192120168665300712204232021063124301","best_ask":"0.37","best_bid":"0.33","hash":"502451a1208c06a64833b401a126d87d7d81db98","price":"0.39","side":"SELL","size":"5"}],"timestamp":"1785212020815"},"payload_hash":"63a910708d75cde0e07963998560911886f9525dd3f033a8f279fb11ef247b9d","raw_frame":"{\"market\":\"0xd412ce774cfcf8dc9f71164aac78783978aac7b03871702a3b8a481bd9dc9688\", \"price_changes\":[{\"asset_id\":\"96600821790790307414914106093858868634329285205417149685270682748367152458577\", \"price\":\"0.61\", \"size\":\"5\", \"side\":\"BUY\", \"hash\":\"ca31823688766c0a7fd3abd6a17f131c717f5b26\", \"best_bid\":\"0.63\", \"best_ask\":\"0.67\"}, {\"asset_id\":\"107603864457683460275633293642179940881969192120168665300712204232021063124301\", \"price\":\"0.39\", \"size\":\"5\", \"side\":\"SELL\", \"hash\":\"502451a1208c06a64833b401a126d87d7d81db98\", \"best_bid\":\"0.33\", \"best_ask\":\"0.37\"}], \"timestamp\":\"1785212020815\", \"event_type\":\"price_change\"}","received_at":"2026-07-28T04:13:41.776675Z","schema_version":"clob-market-ws.price_change.v1","sequence":null,"server_hash":null,"server_timestamp":"1785212020815","session_id":"2d607381e3054cee91998cdf45a4231c","source":"clob_market_ws"},"received_at":"2026-07-28T04:13:41.776675Z","record_id":"22fc773b88ccbca1f12bee8637f9a58896aad6b01f9636478f539d31e65eeadd","schema_fingerprint":"4aa3821a28b0b7c2400bc59aba4bcc0a76e971dadd19610d3ad38c768e124dc7","schema_version":"edge-lab-recorder.raw.v1","sequence":null,"source":"clob_market_ws"}
{"event_at":"2026-07-28T04:13:40.816000Z","event_fingerprint":"7a98df94b876724a93d97ac9e04cc5f9f57a3cc33de27e778c3fa670e6565ed7","payload":{"connection_id":"f6725804f86a4c4eb588e4d5ed7db029","event_at":"2026-07-28T04:13:40.816000Z","event_type":"price_change","frame_hash":"9fe5089501ccfc3d542df5b479f68c484c45f6f982eb375591f4a887bb4e2c91","frame_index":0,"kind":"data","monotonic_ns":314004856356000,"payload":{"event_type":"price_change","market":"0xd412ce774cfcf8dc9f71164aac78783978aac7b03871702a3b8a481bd9dc9688","price_changes":[{"asset_id":"107603864457683460275633293642179940881969192120168665300712204232021063124301","best_ask":"0.37","best_bid":"0.33","hash":"d99e3f04d6f5c058af54f14fca4f909f0f5c3d37","price":"0.39","side":"SELL","size":"0"},{"asset_id":"96600821790790307414914106093858868634329285205417149685270682748367152458577","best_ask":"0.67","best_bid":"0.63","hash":"c9900b425b30d9e25dcf3eeff8f9e30ea7d246b2","price":"0.61","side":"BUY","size":"0"}],"timestamp":"1785212020816"},"payload_hash":"7029a642ef140d266d8e33510bc862e13ecd3bd4f0e1057487cf4bbd52df56cf","raw_frame":"{\"market\":\"0xd412ce774cfcf8dc9f71164aac78783978aac7b03871702a3b8a481bd9dc9688\", \"price_changes\":[{\"asset_id\":\"107603864457683460275633293642179940881969192120168665300712204232021063124301\", \"price\":\"0.39\", \"size\":\"0\", \"side\":\"SELL\", \"hash\":\"d99e3f04d6f5c058af54f14fca4f909f0f5c3d37\", \"best_bid\":\"0.33\", \"best_ask\":\"0.37\"}, {\"asset_id\":\"96600821790790307414914106093858868634329285205417149685270682748367152458577\", \"price\":\"0.61\", \"size\":\"0\", \"side\":\"BUY\", \"hash\":\"c9900b425b30d9e25dcf3eeff8f9e30ea7d246b2\", \"best_bid\":\"0.63\", \"best_ask\":\"0.67\"}], \"timestamp\":\"1785212020816\", \"event_type\":\"price_change\"}","received_at":"2026-07-28T04:13:41.778218Z","schema_version":"clob-market-ws.price_change.v1","sequence":null,"server_hash":null,"server_timestamp":"1785212020816","session_id":"2d607381e3054cee91998cdf45a4231c","source":"clob_market_ws"},"received_at":"2026-07-28T04:13:41.778218Z","record_id":"ea9d2fc69a5d16d51f7faf3a57265841d8dfa33e1d8cbcaf12a38968b5954702","schema_fingerprint":"4aa3821a28b0b7c2400bc59aba4bcc0a76e971dadd19610d3ad38c768e124dc7","schema_version":"edge-lab-recorder.raw.v1","sequence":null,"source":"clob_market_ws"}
{"event_at":"2026-07-28T04:13:40.841000Z","event_fingerprint":"2a255adae113aad6572b665d9fec6d9e3bf338c2683a2bea73cbdeda26d3492f","payload":{"connection_id":"f6725804f86a4c4eb588e4d5ed7db029","event_at":"2026-07-28T04:13:40.841000Z","event_type":"price_change","frame_hash":"2a1ab5e4245e4926e2c46a65414fd996bb021f5bd45e68006ba50ec2ec198c43","frame_index":0,"kind":"data","monotonic_ns":314004857868791,"payload":{"event_type":"price_change","market":"0xd412ce774cfcf8dc9f71164aac78783978aac7b03871702a3b8a481bd9dc9688","price_changes":[{"asset_id":"96600821790790307414914106093858868634329285205417149685270682748367152458577","best_ask":"0.67","best_bid":"0.63","hash":"01e216d093f134fd11c45a01e902ea118e4ec150","price":"0.01","side":"BUY","size":"5290.02"},{"asset_id":"107603864457683460275633293642179940881969192120168665300712204232021063124301","best_ask":"0.37","best_bid":"0.33","hash":"9eca791265236cf005af1c73f063f5a0c1cf1b7c","price":"0.99","side":"SELL","size":"5290.02"}],"timestamp":"1785212020841"},"payload_hash":"1679d3ec10a869dd1e88e213b3ad11656ae517422d43739d9f462f53ebf4b178","raw_frame":"{\"market\":\"0xd412ce774cfcf8dc9f71164aac78783978aac7b03871702a3b8a481bd9dc9688\", \"price_changes\":[{\"asset_id\":\"96600821790790307414914106093858868634329285205417149685270682748367152458577\", \"price\":\"0.01\", \"size\":\"5290.02\", \"side\":\"BUY\", \"hash\":\"01e216d093f134fd11c45a01e902ea118e4ec150\", \"best_bid\":\"0.63\", \"best_ask\":\"0.67\"}, {\"asset_id\":\"107603864457683460275633293642179940881969192120168665300712204232021063124301\", \"price\":\"0.99\", \"size\":\"5290.02\", \"side\":\"SELL\", \"hash\":\"9eca791265236cf005af1c73f063f5a0c1cf1b7c\", \"best_bid\":\"0.33\", \"best_ask\":\"0.37\"}], \"timestamp\":\"1785212020841\", \"event_type\":\"price_change\"}","received_at":"2026-07-28T04:13:41.779731Z","schema_version":"clob-market-ws.price_change.v1","sequence":null,"server_hash":null,"server_timestamp":"1785212020841","session_id":"2d607381e3054cee91998cdf45a4231c","source":"clob_market_ws"},"received_at":"2026-07-28T04:13:41.779731Z","record_id":"8d98e04025a7f23daa1b83718245915964bc540016cc0f2bb60ea53f6f52f34c","schema_fingerprint":"4aa3821a28b0b7c2400bc59aba4bcc0a76e971dadd19610d3ad38c768e124dc7","schema_version":"edge-lab-recorder.raw.v1","sequence":null,"source":"clob_market_ws"}
{"event_at":"2026-07-28T04:13:40.875000Z","event_fingerprint":"f6c21b029dc38e60fa68c5cb452f89ccb9e678ad393204a8e55984cca76d29dc","payload":{"connection_id":"f6725804f86a4c4eb588e4d5ed7db029","event_at":"2026-07-28T04:13:40.875000Z","event_type":"price_change","frame_hash":"48b37312212e6cdf90ac0b655ee87168854714729f6152e4808c37c0a3fcde97","frame_index":0,"kind":"data","monotonic_ns":314004859339333,"payload":{"event_type":"price_change","market":"0xd412ce774cfcf8dc9f71164aac78783978aac7b03871702a3b8a481bd9dc9688","price_changes":[{"asset_id":"96600821790790307414914106093858868634329285205417149685270682748367152458577","best_ask":"0.67","best_bid":"0.63","hash":"e27282de01ca4eb5bf47e47d4e4aa65f5466823f","price":"0.01","side":"BUY","size":"5295.02"},{"asset_id":"107603864457683460275633293642179940881969192120168665300712204232021063124301","best_ask":"0.37","best_bid":"0.33","hash":"4cd5bc5d5dadfc1cce7070869ffc807d158a8639","price":"0.99","side":"SELL","size":"5295.02"}],"timestamp":"1785212020875"},"payload_hash":"2075a8c734d81163808cfcade5d93a6a782aeb84e51e2593f1732761cce64d7b","raw_frame":"{\"market\":\"0xd412ce774cfcf8dc9f71164aac78783978aac7b03871702a3b8a481bd9dc9688\", \"price_changes\":[{\"asset_id\":\"96600821790790307414914106093858868634329285205417149685270682748367152458577\", \"price\":\"0.01\", \"size\":\"5295.02\", \"side\":\"BUY\", \"hash\":\"e27282de01ca4eb5bf47e47d4e4aa65f5466823f\", \"best_bid\":\"0.63\", \"best_ask\":\"0.67\"}, {\"asset_id\":\"107603864457683460275633293642179940881969192120168665300712204232021063124301\", \"price\":\"0.99\", \"size\":\"5295.02\", \"side\":\"SELL\", \"hash\":\"4cd5bc5d5dadfc1cce7070869ffc807d158a8639\", \"best_bid\":\"0.33\", \"best_ask\":\"0.37\"}], \"timestamp\":\"1785212020875\", \"event_type\":\"price_change\"}","received_at":"2026-07-28T04:13:41.781202Z","schema_version":"clob-market-ws.price_change.v1","sequence":null,"server_hash":null,"server_timestamp":"1785212020875","session_id":"2d607381e3054cee91998cdf45a4231c","source":"clob_market_ws"},"received_at":"2026-07-28T04:13:41.781202Z","record_id":"5f5eadce52f717924808081c74fab41f23f91fe48477d25b47ac37255dc4425b","schema_fingerprint":"4aa3821a28b0b7c2400bc59aba4bcc0a76e971dadd19610d3ad38c768e124dc7","schema_version":"edge-lab-recorder.raw.v1","sequence":null,"source":"clob_market_ws"}
{"event_at":"2026-07-28T04:13:40.899000Z","event_fingerprint":"64c9e0632c8eca98b9bc1de8f3d96bba59d37281d8e79902fd21391ad0f83ae5","payload":{"connection_id":"f6725804f86a4c4eb588e4d5ed7db029","event_at":"2026-07-28T04:13:40.899000Z","event_type":"price_change","frame_hash":"68534c20a12f731d0e0d4d7aad2606a0bae759e2c0c6170a9c87b570d29a757a","frame_index":0,"kind":"data","monotonic_ns":314004860835041,"payload":{"event_type":"price_change","market":"0xd412ce774cfcf8dc9f71164aac78783978aac7b03871702a3b8a481bd9dc9688","price_changes":[{"asset_id":"96600821790790307414914106093858868634329285205417149685270682748367152458577","best_ask":"0.67","best_bid":"0.63","hash":"bf2aa39a422335978a197e6cd3436d2f6214ab24","price":"0.01","side":"BUY","size":"5290.02"},{"asset_id":"107603864457683460275633293642179940881969192120168665300712204232021063124301","best_ask":"0.37","best_bid":"0.33","hash":"3e37f4a2764c2ba4ccf2b19e97b072096c5585a2","price":"0.99","side":"SELL","size":"5290.02"}],"timestamp":"1785212020899"},"payload_hash":"5e7a279b8371d2aa9c4e322c2991c6f96857b47da6ac919f0b4c4c07b636885f","raw_frame":"{\"market\":\"0xd412ce774cfcf8dc9f71164aac78783978aac7b03871702a3b8a481bd9dc9688\", \"price_changes\":[{\"asset_id\":\"96600821790790307414914106093858868634329285205417149685270682748367152458577\", \"price\":\"0.01\", \"size\":\"5290.02\", \"side\":\"BUY\", \"hash\":\"bf2aa39a422335978a197e6cd3436d2f6214ab24\", \"best_bid\":\"0.63\", \"best_ask\":\"0.67\"}, {\"asset_id\":\"107603864457683460275633293642179940881969192120168665300712204232021063124301\", \"price\":\"0.99\", \"size\":\"5290.02\", \"side\":\"SELL\", \"hash\":\"3e37f4a2764c2ba4ccf2b19e97b072096c5585a2\", \"best_bid\":\"0.33\", \"best_ask\":\"0.37\"}], \"timestamp\":\"1785212020899\", \"event_type\":\"price_change\"}","received_at":"2026-07-28T04:13:41.782698Z","schema_version":"clob-market-ws.price_change.v1","sequence":null,"server_hash":null,"server_timestamp":"1785212020899","session_id":"2d607381e3054cee91998cdf45a4231c","source":"clob_market_ws"},"received_at":"2026-07-28T04:13:41.782698Z","record_id":"d942d0a6f65acfb9e2f5a2837b93834bb0e597e8aed60d115b06289b58a839b8","schema_fingerprint":"4aa3821a28b0b7c2400bc59aba4bcc0a76e971dadd19610d3ad38c768e124dc7","schema_version":"edge-lab-recorder.raw.v1","sequence":null,"source":"clob_market_ws"}
{"event_at":"2026-07-28T04:13:40.923000Z","event_fingerprint":"f7b767cac02d079ddf09b1f651dac5fc95b0d08c5fd6bcb5510a4bc2db7686e9","payload":{"connection_id":"f6725804f86a4c4eb588e4d5ed7db029","event_at":"2026-07-28T04:13:40.923000Z","event_type":"price_change","frame_hash":"122f77857b081030f67bac8144713a7669d0b010c824008f6810e01f5cf4e5b0","frame_index":0,"kind":"data","monotonic_ns":314004863814875,"payload":{"event_type":"price_change","market":"0xd412ce774cfcf8dc9f71164aac78783978aac7b03871702a3b8a481bd9dc9688","price_changes":[{"asset_id":"96600821790790307414914106093858868634329285205417149685270682748367152458577","best_ask":"0.67","best_bid":"0.63","hash":"794e47fde87a59d903c6fd1b743c5edba6a1df33","price":"0.02","side":"BUY","size":"525"},{"asset_id":"107603864457683460275633293642179940881969192120168665300712204232021063124301","best_ask":"0.37","best_bid":"0.33","hash":"e8807313bcedf5cdc3d189428a9fa5b8d9e93040","price":"0.98","side":"SELL","size":"525"}],"timestamp":"1785212020923"},"payload_hash":"af4e32cdda06271609e572b1b17fbdc34f24e2d64460932c8ff7b5b89fd1d2e1","raw_frame":"{\"market\":\"0xd412ce774cfcf8dc9f71164aac78783978aac7b03871702a3b8a481bd9dc9688\", \"price_changes\":[{\"asset_id\":\"96600821790790307414914106093858868634329285205417149685270682748367152458577\", \"price\":\"0.02\", \"size\":\"525\", \"side\":\"BUY\", \"hash\":\"794e47fde87a59d903c6fd1b743c5edba6a1df33\", \"best_bid\":\"0.63\", \"best_ask\":\"0.67\"}, {\"asset_id\":\"107603864457683460275633293642179940881969192120168665300712204232021063124301\", \"price\":\"0.98\", \"size\":\"525\", \"side\":\"SELL\", \"hash\":\"e8807313bcedf5cdc3d189428a9fa5b8d9e93040\", \"best_bid\":\"0.33\", \"best_ask\":\"0.37\"}], \"timestamp\":\"1785212020923\", \"event_type\":\"price_change\"}","received_at":"2026-07-28T04:13:41.785678Z","schema_version":"clob-market-ws.price_change.v1","sequence":null,"server_hash":null,"server_timestamp":"1785212020923","session_id":"2d607381e3054cee91998cdf45a4231c","source":"clob_market_ws"},"received_at":"2026-07-28T04:13:41.785678Z","record_id":"657478b42ea6b8bad0206a1ab07ac6a9288437f551c85d31e9912574eec724ad","schema_fingerprint":"4aa3821a28b0b7c2400bc59aba4bcc0a76e971dadd19610d3ad38c768e124dc7","schema_version":"edge-lab-recorder.raw.v1","sequence":null,"source":"clob_market_ws"}
{"event_at":"2026-07-28T04:13:40.929000Z","event_fingerprint":"5b33e8136be31ae5199cb15f73f18a5c93b1b7a793d0a1dca494c9def0b7dce5","payload":{"connection_id":"f6725804f86a4c4eb588e4d5ed7db029","event_at":"2026-07-28T04:13:40.929000Z","event_type":"best_bid_ask","frame_hash":"8bf02f1587a78d6d7f98a162172383155abcf6de6290a223b61b2f8c1ca04eda","frame_index":0,"kind":"data","monotonic_ns":314004867079375,"payload":{"asset_id":"107603864457683460275633293642179940881969192120168665300712204232021063124301","best_ask":"0.36","best_bid":"0.33","event_type":"best_bid_ask","market":"0xd412ce774cfcf8dc9f71164aac78783978aac7b03871702a3b8a481bd9dc9688","spread":"0.03","timestamp":"1785212020929"},"payload_hash":"f0a3625d2cc3d88fbf5a65327943d4816aae5a5f10bd7ab8460824e01528274a","raw_frame":"{\"market\":\"0xd412ce774cfcf8dc9f71164aac78783978aac7b03871702a3b8a481bd9dc9688\", \"asset_id\":\"107603864457683460275633293642179940881969192120168665300712204232021063124301\", \"best_bid\":\"0.33\", \"best_ask\":\"0.36\", \"spread\":\"0.03\", \"timestamp\":\"1785212020929\", \"event_type\":\"best_bid_ask\"}","received_at":"2026-07-28T04:13:41.788940Z","schema_version":"clob-market-ws.best_bid_ask.v1","sequence":null,"server_hash":null,"server_timestamp":"1785212020929","session_id":"2d607381e3054cee91998cdf45a4231c","source":"clob_market_ws"},"received_at":"2026-07-28T04:13:41.788940Z","record_id":"4ca974a956d66f7b8382516e6b4341e7d978394922508d861be09f05fdb219d2","schema_fingerprint":"8488399f31b0337811b13b266be932db7062827c2470b78bd8e9e99bab51d17d","schema_version":"edge-lab-recorder.raw.v1","sequence":null,"source":"clob_market_ws"}
{"event_at":"2026-07-28T04:13:40.929000Z","event_fingerprint":"5f484fec34c727a1529d1f1988834171005eca6c0f575257d8430cd2f4a9157e","payload":{"connection_id":"f6725804f86a4c4eb588e4d5ed7db029","event_at":"2026-07-28T04:13:40.929000Z","event_type":"best_bid_ask","frame_hash":"fbf2370407f85cccee7e27ea6ea63bd92c170c8df3c408c60d9702c465225e59","frame_index":0,"kind":"data","monotonic_ns":314004869809041,"payload":{"asset_id":"96600821790790307414914106093858868634329285205417149685270682748367152458577","best_ask":"0.67","best_bid":"0.64","event_type":"best_bid_ask","market":"0xd412ce774cfcf8dc9f71164aac78783978aac7b03871702a3b8a481bd9dc9688","spread":"0.03","timestamp":"1785212020929"},"payload_hash":"d62be395355ecf86b8a47dc97e0723bf0b7956533494e0f25070f6188b48c9e5","raw_frame":"{\"market\":\"0xd412ce774cfcf8dc9f71164aac78783978aac7b03871702a3b8a481bd9dc9688\", \"asset_id\":\"96600821790790307414914106093858868634329285205417149685270682748367152458577\", \"best_bid\":\"0.64\", \"best_ask\":\"0.67\", \"spread\":\"0.03\", \"timestamp\":\"1785212020929\", \"event_type\":\"best_bid_ask\"}","received_at":"2026-07-28T04:13:41.791671Z","schema_version":"clob-market-ws.best_bid_ask.v1","sequence":null,"server_hash":null,"server_timestamp":"1785212020929","session_id":"2d607381e3054cee91998cdf45a4231c","source":"clob_market_ws"},"received_at":"2026-07-28T04:13:41.791671Z","record_id":"fad07185932f03c255b642ea20e26dadf3a4a4a4c5cff63f95b693f94a8a3c94","schema_fingerprint":"8488399f31b0337811b13b266be932db7062827c2470b78bd8e9e99bab51d17d","schema_version":"edge-lab-recorder.raw.v1","sequence":null,"source":"clob_market_ws"}
{"event_at":"2026-07-28T04:13:40.929000Z","event_fingerprint":"82f908cf96d55e447078d7c9007fb1c8c8c3ffd2aadfbe4d084fdfdbad5993df","payload":{"connection_id":"f6725804f86a4c4eb588e4d5ed7db029","event_at":"2026-07-28T04:13:40.929000Z","event_type":"price_change","frame_hash":"83e4fe1e4bfc822b871c06afb0cac5c24ea9c541f5bfab1cd25a8f3e6641efdb","frame_index":0,"kind":"data","monotonic_ns":314004872540333,"payload":{"event_type":"price_change","market":"0xd412ce774cfcf8dc9f71164aac78783978aac7b03871702a3b8a481bd9dc9688","price_changes":[{"asset_id":"96600821790790307414914106093858868634329285205417149685270682748367152458577","best_ask":"0.67","best_bid":"0.64","hash":"d52f22712dddd5d140f85432313e6bf1bec435b2","price":"0.64","side":"BUY","size":"5"},{"asset_id":"107603864457683460275633293642179940881969192120168665300712204232021063124301","best_ask":"0.36","best_bid":"0.33","hash":"248d6ac5660cee8715388f7c23027312a67dab76","price":"0.36","side":"SELL","size":"5"}],"timestamp":"1785212020929"},"payload_hash":"b22f93603de05649b15d575434b29c7ed71736a3099974fd0ff0ece640c981c1","raw_frame":"{\"market\":\"0xd412ce774cfcf8dc9f71164aac78783978aac7b03871702a3b8a481bd9dc9688\", \"price_changes\":[{\"asset_id\":\"96600821790790307414914106093858868634329285205417149685270682748367152458577\", \"price\":\"0.64\", \"size\":\"5\", \"side\":\"BUY\", \"hash\":\"d52f22712dddd5d140f85432313e6bf1bec435b2\", \"best_bid\":\"0.64\", \"best_ask\":\"0.67\"}, {\"asset_id\":\"107603864457683460275633293642179940881969192120168665300712204232021063124301\", \"price\":\"0.36\", \"size\":\"5\", \"side\":\"SELL\", \"hash\":\"248d6ac5660cee8715388f7c23027312a67dab76\", \"best_bid\":\"0.33\", \"best_ask\":\"0.36\"}], \"timestamp\":\"1785212020929\", \"event_type\":\"price_change\"}","received_at":"2026-07-28T04:13:41.794401Z","schema_version":"clob-market-ws.price_change.v1","sequence":null,"server_hash":null,"server_timestamp":"1785212020929","session_id":"2d607381e3054cee91998cdf45a4231c","source":"clob_market_ws"},"received_at":"2026-07-28T04:13:41.794401Z","record_id":"5d49f8562f102ce6145047a8dabb9107dce1b65c6a4cd8e7325b2029f4a3a20c","schema_fingerprint":"4aa3821a28b0b7c2400bc59aba4bcc0a76e971dadd19610d3ad38c768e124dc7","schema_version":"edge-lab-recorder.raw.v1","sequence":null,"source":"clob_market_ws"}
{"event_at":"2026-07-28T04:13:40.930000Z","event_fingerprint":"19bdb3fb27b545bcddc2fe11d30b1bcd9a76401e5bde9c3d61b9ab8847cc471f","payload":{"connection_id":"f6725804f86a4c4eb588e4d5ed7db029","event_at":"2026-07-28T04:13:40.930000Z","event_type":"price_change","frame_hash":"98b862aa8196a041b4aac11f52b8c01112a694b5c0689adf2762ef2fc18dcc85","frame_index":0,"kind":"data","monotonic_ns":314004875107833,"payload":{"event_type":"price_change","market":"0xd412ce774cfcf8dc9f71164aac78783978aac7b03871702a3b8a481bd9dc9688","price_changes":[{"asset_id":"107603864457683460275633293642179940881969192120168665300712204232021063124301","best_ask":"0.36","best_bid":"0.33","hash":"de567ce7c547c1ee69a6929075e518d794be50ef","price":"0.36","side":"SELL","size":"10"},{"asset_id":"96600821790790307414914106093858868634329285205417149685270682748367152458577","best_ask":"0.67","best_bid":"0.64","hash":"3af336050a8c506fdd29b7dc7914c796d6a189bb","price":"0.64","side":"BUY","size":"10"}],"timestamp":"1785212020930"},"payload_hash":"65113a94772d5b29817f7149c088e0d1fecc59f11bc936ee703cb898de6472e5","raw_frame":"{\"market\":\"0xd412ce774cfcf8dc9f71164aac78783978aac7b03871702a3b8a481bd9dc9688\", \"price_changes\":[{\"asset_id\":\"107603864457683460275633293642179940881969192120168665300712204232021063124301\", \"price\":\"0.36\", \"size\":\"10\", \"side\":\"SELL\", \"hash\":\"de567ce7c547c1ee69a6929075e518d794be50ef\", \"best_bid\":\"0.33\", \"best_ask\":\"0.36\"}, {\"asset_id\":\"96600821790790307414914106093858868634329285205417149685270682748367152458577\", \"price\":\"0.64\", \"size\":\"10\", \"side\":\"BUY\", \"hash\":\"3af336050a8c506fdd29b7dc7914c796d6a189bb\", \"best_bid\":\"0.64\", \"best_ask\":\"0.67\"}], \"timestamp\":\"1785212020930\", \"event_type\":\"price_change\"}","received_at":"2026-07-28T04:13:41.796968Z","schema_version":"clob-market-ws.price_change.v1","sequence":null,"server_hash":null,"server_timestamp":"1785212020930","session_id":"2d607381e3054cee91998cdf45a4231c","source":"clob_market_ws"},"received_at":"2026-07-28T04:13:41.796968Z","record_id":"bd5d085c184366905538771e8c9fff3a070aeee8e023eda09240b52ffb9fefc1","schema_fingerprint":"4aa3821a28b0b7c2400bc59aba4bcc0a76e971dadd19610d3ad38c768e124dc7","schema_version":"edge-lab-recorder.raw.v1","sequence":null,"source":"clob_market_ws"}
{"event_at":"2026-07-28T04:13:40.944000Z","event_fingerprint":"8537ffa482ec39d4f8e68e7ef26e0056c6d3f1e74192fc987fa468471b6f095f","payload":{"connection_id":"f6725804f86a4c4eb588e4d5ed7db029","event_at":"2026-07-28T04:13:40.944000Z","event_type":"price_change","frame_hash":"dfeae0dae80d96981d78d369933d568df6e1d97c372928d23cc8c066f752a726","frame_index":0,"kind":"data","monotonic_ns":314004877522625,"payload":{"event_type":"price_change","market":"0xd412ce774cfcf8dc9f71164aac78783978aac7b03871702a3b8a481bd9dc9688","price_changes":[{"asset_id":"96600821790790307414914106093858868634329285205417149685270682748367152458577","best_ask":"0.67","best_bid":"0.64","hash":"c3c5788d9b57d007a5cd4acb7979945452f3d1c7","price":"0.64","side":"BUY","size":"5"},{"asset_id":"107603864457683460275633293642179940881969192120168665300712204232021063124301","best_ask":"0.36","best_bid":"0.33","hash":"2b9ef222e80cf5b6eeb432358f55b60ba10f1ad8","price":"0.36","side":"SELL","size":"5"}],"timestamp":"1785212020944"},"payload_hash":"33fc4387ff32db07163ea21cb9296dbbe02ff7291f58b68f2088587a89b2ca60","raw_frame":"{\"market\":\"0xd412ce774cfcf8dc9f71164aac78783978aac7b03871702a3b8a481bd9dc9688\", \"price_changes\":[{\"asset_id\":\"96600821790790307414914106093858868634329285205417149685270682748367152458577\", \"price\":\"0.64\", \"size\":\"5\", \"side\":\"BUY\", \"hash\":\"c3c5788d9b57d007a5cd4acb7979945452f3d1c7\", \"best_bid\":\"0.64\", \"best_ask\":\"0.67\"}, {\"asset_id\":\"107603864457683460275633293642179940881969192120168665300712204232021063124301\", \"price\":\"0.36\", \"size\":\"5\", \"side\":\"SELL\", \"hash\":\"2b9ef222e80cf5b6eeb432358f55b60ba10f1ad8\", \"best_bid\":\"0.33\", \"best_ask\":\"0.36\"}], \"timestamp\":\"1785212020944\", \"event_type\":\"price_change\"}","received_at":"2026-07-28T04:13:41.799384Z","schema_version":"clob-market-ws.price_change.v1","sequence":null,"server_hash":null,"server_timestamp":"1785212020944","session_id":"2d607381e3054cee91998cdf45a4231c","source":"clob_market_ws"},"received_at":"2026-07-28T04:13:41.799384Z","record_id":"91483ad2c56a162156f4f4c7f57cac0892852b5db9a42ac65f4923c344f766f3","schema_fingerprint":"4aa3821a28b0b7c2400bc59aba4bcc0a76e971dadd19610d3ad38c768e124dc7","schema_version":"edge-lab-recorder.raw.v1","sequence":null,"source":"clob_market_ws"}
{"event_at":"2026-07-28T04:13:40.944000Z","event_fingerprint":"9d03411c91e1475c411a9d143f9e77357814630c43a4a1a0bce908612314d070","payload":{"connection_id":"f6725804f86a4c4eb588e4d5ed7db029","event_at":"2026-07-28T04:13:40.944000Z","event_type":"price_change","frame_hash":"a1675718727cb21f3b9e5fbf997a8300fcefbf555fdc3db28c633704dd8ac1b3","frame_index":0,"kind":"data","monotonic_ns":314004879215500,"payload":{"event_type":"price_change","market":"0xd412ce774cfcf8dc9f71164aac78783978aac7b03871702a3b8a481bd9dc9688","price_changes":[{"asset_id":"96600821790790307414914106093858868634329285205417149685270682748367152458577","best_ask":"0.67","best_bid":"0.64","hash":"28c899f45f4605957f477e7804b8ad73f3e9ad46","price":"0.63","side":"BUY","size":"0"},{"asset_id":"107603864457683460275633293642179940881969192120168665300712204232021063124301","best_ask":"0.36","best_bid":"0.33","hash":"0a7f10bdcf5e03f16b993d3cf21a752d9568ef2b","price":"0.37","side":"SELL","size":"0"}],"timestamp":"1785212020944"},"payload_hash":"3a80cab9904c0dd79404f49fcae950581f48b8adf74b818ca4e30aca3b05b6b7","raw_frame":"{\"market\":\"0xd412ce774cfcf8dc9f71164aac78783978aac7b03871702a3b8a481bd9dc9688\", \"price_changes\":[{\"asset_id\":\"96600821790790307414914106093858868634329285205417149685270682748367152458577\", \"price\":\"0.63\", \"size\":\"0\", \"side\":\"BUY\", \"hash\":\"28c899f45f4605957f477e7804b8ad73f3e9ad46\", \"best_bid\":\"0.64\", \"best_ask\":\"0.67\"}, {\"asset_id\":\"107603864457683460275633293642179940881969192120168665300712204232021063124301\", \"price\":\"0.37\", \"size\":\"0\", \"side\":\"SELL\", \"hash\":\"0a7f10bdcf5e03f16b993d3cf21a752d9568ef2b\", \"best_bid\":\"0.33\", \"best_ask\":\"0.36\"}], \"timestamp\":\"1785212020944\", \"event_type\":\"price_change\"}","received_at":"2026-07-28T04:13:41.801075Z","schema_version":"clob-market-ws.price_change.v1","sequence":null,"server_hash":null,"server_timestamp":"1785212020944","session_id":"2d607381e3054cee91998cdf45a4231c","source":"clob_market_ws"},"received_at":"2026-07-28T04:13:41.801075Z","record_id":"3735802911aae13a7ec3985cd3bdc25f5f0ad459b1c1a89cb01522a680a1336e","schema_fingerprint":"4aa3821a28b0b7c2400bc59aba4bcc0a76e971dadd19610d3ad38c768e124dc7","schema_version":"edge-lab-recorder.raw.v1","sequence":null,"source":"clob_market_ws"}
{"event_at":"2026-07-28T04:13:40.945000Z","event_fingerprint":"e2a7c8fbc4eb103170c70bda429451afa4eed991d2c0e806a9c46642b41925cb","payload":{"connection_id":"f6725804f86a4c4eb588e4d5ed7db029","event_at":"2026-07-28T04:13:40.945000Z","event_type":"best_bid_ask","frame_hash":"84c773405ff9777ea16cbed4d00aac8ed171df21e1db9c6c0249fb956673902b","frame_index":0,"kind":"data","monotonic_ns":314004880841541,"payload":{"asset_id":"107603864457683460275633293642179940881969192120168665300712204232021063124301","best_ask":"0.4","best_bid":"0.33","event_type":"best_bid_ask","market":"0xd412ce774cfcf8dc9f71164aac78783978aac7b03871702a3b8a481bd9dc9688","spread":"0.07","timestamp":"1785212020945"},"payload_hash":"80e9c1e0761b88ad974f3514df4f7337709774f68bb48a838a6b3f3d489a1808","raw_frame":"{\"market\":\"0xd412ce774cfcf8dc9f71164aac78783978aac7b03871702a3b8a481bd9dc9688\", \"asset_id\":\"107603864457683460275633293642179940881969192120168665300712204232021063124301\", \"best_bid\":\"0.33\", \"best_ask\":\"0.4\", \"spread\":\"0.07\", \"timestamp\":\"1785212020945\", \"event_type\":\"best_bid_ask\"}","received_at":"2026-07-28T04:13:41.802702Z","schema_version":"clob-market-ws.best_bid_ask.v1","sequence":null,"server_hash":null,"server_timestamp":"1785212020945","session_id":"2d607381e3054cee91998cdf45a4231c","source":"clob_market_ws"},"received_at":"2026-07-28T04:13:41.802702Z","record_id":"cdd6469218f905f1f62c63fd82ece1d943c75f354bb0b91897a204b5fe0cf871","schema_fingerprint":"8488399f31b0337811b13b266be932db7062827c2470b78bd8e9e99bab51d17d","schema_version":"edge-lab-recorder.raw.v1","sequence":null,"source":"clob_market_ws"}
{"event_at":"2026-07-28T04:13:40.945000Z","event_fingerprint":"c2527b57b6d284aea5a649e4f8029bbc5e48c2cb06e0b0bb024a5a2ba5b09752","payload":{"connection_id":"f6725804f86a4c4eb588e4d5ed7db029","event_at":"2026-07-28T04:13:40.945000Z","event_type":"best_bid_ask","frame_hash":"6a0d2b91c45ecc92acfcaeb362cc25e98532c49af78a6a84aa318b09144ee7e5","frame_index":0,"kind":"data","monotonic_ns":314004883533750,"payload":{"asset_id":"96600821790790307414914106093858868634329285205417149685270682748367152458577","best_ask":"0.67","best_bid":"0.6","event_type":"best_bid_ask","market":"0xd412ce774cfcf8dc9f71164aac78783978aac7b03871702a3b8a481bd9dc9688","spread":"0.07","timestamp":"1785212020945"},"payload_hash":"8caeeea011367e94fa8b9002776a993e7f069791cae0bb04992fd977c44e4def","raw_frame":"{\"market\":\"0xd412ce774cfcf8dc9f71164aac78783978aac7b03871702a3b8a481bd9dc9688\", \"asset_id\":\"96600821790790307414914106093858868634329285205417149685270682748367152458577\", \"best_bid\":\"0.6\", \"best_ask\":\"0.67\", \"spread\":\"0.07\", \"timestamp\":\"1785212020945\", \"event_type\":\"best_bid_ask\"}","received_at":"2026-07-28T04:13:41.805395Z","schema_version":"clob-market-ws.best_bid_ask.v1","sequence":null,"server_hash":null,"server_timestamp":"1785212020945","session_id":"2d607381e3054cee91998cdf45a4231c","source":"clob_market_ws"},"received_at":"2026-07-28T04:13:41.805395Z","record_id":"5cef8464a8ca41544ced111688d5d5cab1829a90d4fc4c2abef0b92faad566d1","schema_fingerprint":"8488399f31b0337811b13b266be932db7062827c2470b78bd8e9e99bab51d17d","schema_version":"edge-lab-recorder.raw.v1","sequence":null,"source":"clob_market_ws"}
{"event_at":"2026-07-28T04:13:40.945000Z","event_fingerprint":"50278875a3fc48bb9560670b82b21111b55fcbc541608e3b195af76113895d60","payload":{"connection_id":"f6725804f86a4c4eb588e4d5ed7db029","event_at":"2026-07-28T04:13:40.945000Z","event_type":"price_change","frame_hash":"fd55db906441ca88f2b3f81213ee7c3c0ac62ff179e81494ebb92569850aaf89","frame_index":0,"kind":"data","monotonic_ns":314004884730958,"payload":{"event_type":"price_change","market":"0xd412ce774cfcf8dc9f71164aac78783978aac7b03871702a3b8a481bd9dc9688","price_changes":[{"asset_id":"107603864457683460275633293642179940881969192120168665300712204232021063124301","best_ask":"0.4","best_bid":"0.33","hash":"473bf5da7ecc2c3cdd9c3c0e300a45273d808483","price":"0.36","side":"SELL","size":"0"},{"asset_id":"96600821790790307414914106093858868634329285205417149685270682748367152458577","best_ask":"0.67","best_bid":"0.6","hash":"9944b05df157e5eb43f4018d60742e6f04703001","price":"0.64","side":"BUY","size":"0"}],"timestamp":"1785212020945"},"payload_hash":"2c3ffdfe508e0cdd86b3a7c84dbc0da631f4a07044adbe596436db8dc81b8581","raw_frame":"{\"market\":\"0xd412ce774cfcf8dc9f71164aac78783978aac7b03871702a3b8a481bd9dc9688\", \"price_changes\":[{\"asset_id\":\"107603864457683460275633293642179940881969192120168665300712204232021063124301\", \"price\":\"0.36\", \"size\":\"0\", \"side\":\"SELL\", \"hash\":\"473bf5da7ecc2c3cdd9c3c0e300a45273d808483\", \"best_bid\":\"0.33\", \"best_ask\":\"0.4\"}, {\"asset_id\":\"96600821790790307414914106093858868634329285205417149685270682748367152458577\", \"price\":\"0.64\", \"size\":\"0\", \"side\":\"BUY\", \"hash\":\"9944b05df157e5eb43f4018d60742e6f04703001\", \"best_bid\":\"0.6\", \"best_ask\":\"0.67\"}], \"timestamp\":\"1785212020945\", \"event_type\":\"price_change\"}","received_at":"2026-07-28T04:13:41.806592Z","schema_version":"clob-market-ws.price_change.v1","sequence":null,"server_hash":null,"server_timestamp":"1785212020945","session_id":"2d607381e3054cee91998cdf45a4231c","source":"clob_market_ws"},"received_at":"2026-07-28T04:13:41.806592Z","record_id":"1672e85c0523ebb9f22db850ee5386d34b5f8c21fa6f8d46732899d603b3ea8b","schema_fingerprint":"4aa3821a28b0b7c2400bc59aba4bcc0a76e971dadd19610d3ad38c768e124dc7","schema_version":"edge-lab-recorder.raw.v1","sequence":null,"source":"clob_market_ws"}
{"event_at":"2026-07-28T04:13:40.962000Z","event_fingerprint":"86849dd7fff1fe0ff6a8435a31ba136a40b69389f514097169a33e03d7640157","payload":{"connection_id":"f6725804f86a4c4eb588e4d5ed7db029","event_at":"2026-07-28T04:13:40.962000Z","event_type":"best_bid_ask","frame_hash":"330bcfd95e7e840ca77e8fb2fe2f65b5961a66f6ec56a592b2cc4839560324ec","frame_index":0,"kind":"data","monotonic_ns":314004886306083,"payload":{"asset_id":"107603864457683460275633293642179940881969192120168665300712204232021063124301","best_ask":"0.35","best_bid":"0.33","event_type":"best_bid_ask","market":"0xd412ce774cfcf8dc9f71164aac78783978aac7b03871702a3b8a481bd9dc9688","spread":"0.02","timestamp":"1785212020962"},"payload_hash":"267a02193d4ec1bc5a01a3cdf3430ed7b2139339d1254108747eefc6bb669901","raw_frame":"{\"market\":\"0xd412ce774cfcf8dc9f71164aac78783978aac7b03871702a3b8a481bd9dc9688\", \"asset_id\":\"107603864457683460275633293642179940881969192120168665300712204232021063124301\", \"best_bid\":\"0.33\", \"best_ask\":\"0.35\", \"spread\":\"0.02\", \"timestamp\":\"1785212020962\", \"event_type\":\"best_bid_ask\"}","received_at":"2026-07-28T04:13:41.808168Z","schema_version":"clob-market-ws.best_bid_ask.v1","sequence":null,"server_hash":null,"server_timestamp":"1785212020962","session_id":"2d607381e3054cee91998cdf45a4231c","source":"clob_market_ws"},"received_at":"2026-07-28T04:13:41.808168Z","record_id":"d52a4baa750861ac6cf23090626e3dbd746bb71b3d30ca28ac5ff6e04c185366","schema_fingerprint":"8488399f31b0337811b13b266be932db7062827c2470b78bd8e9e99bab51d17d","schema_version":"edge-lab-recorder.raw.v1","sequence":null,"source":"clob_market_ws"}
{"event_at":"2026-07-28T04:13:40.962000Z","event_fingerprint":"f70504b548858d2147cced0dd847e8ad6c40cf026564e08096ca2814b550f82f","payload":{"connection_id":"f6725804f86a4c4eb588e4d5ed7db029","event_at":"2026-07-28T04:13:40.962000Z","event_type":"best_bid_ask","frame_hash":"5f1108f8c705cca8f784847672b4ceb67703ea4b3a8e31577e2b16c50e29f32f","frame_index":0,"kind":"data","monotonic_ns":314004887448250,"payload":{"asset_id":"96600821790790307414914106093858868634329285205417149685270682748367152458577","best_ask":"0.67","best_bid":"0.65","event_type":"best_bid_ask","market":"0xd412ce774cfcf8dc9f71164aac78783978aac7b03871702a3b8a481bd9dc9688","spread":"0.02","timestamp":"1785212020962"},"payload_hash":"417d5570c202a06758154ba80a530a4cfa1288f2ce55fe3d28a5d316dea88c20","raw_frame":"{\"market\":\"0xd412ce774cfcf8dc9f71164aac78783978aac7b03871702a3b8a481bd9dc9688\", \"asset_id\":\"96600821790790307414914106093858868634329285205417149685270682748367152458577\", \"best_bid\":\"0.65\", \"best_ask\":\"0.67\", \"spread\":\"0.02\", \"timestamp\":\"1785212020962\", \"event_type\":\"best_bid_ask\"}","received_at":"2026-07-28T04:13:41.809309Z","schema_version":"clob-market-ws.best_bid_ask.v1","sequence":null,"server_hash":null,"server_timestamp":"1785212020962","session_id":"2d607381e3054cee91998cdf45a4231c","source":"clob_market_ws"},"received_at":"2026-07-28T04:13:41.809309Z","record_id":"be350cd67ab7f2920dd4baa0eb0ff12d67e30aad706cb4b74c178ff7c010f851","schema_fingerprint":"8488399f31b0337811b13b266be932db7062827c2470b78bd8e9e99bab51d17d","schema_version":"edge-lab-recorder.raw.v1","sequence":null,"source":"clob_market_ws"}
{"event_at":"2026-07-28T04:13:40.962000Z","event_fingerprint":"fa45d0459f1da9ab7af16aa7d6a24bd8f4087403f0d100c6f7b60d20c365c4b1","payload":{"connection_id":"f6725804f86a4c4eb588e4d5ed7db029","event_at":"2026-07-28T04:13:40.962000Z","event_type":"price_change","frame_hash":"cd732afe5ee83cc821eb7520ed1f9fd668b7ba14652c4db67e359f81d914c16b","frame_index":0,"kind":"data","monotonic_ns":314004888573041,"payload":{"event_type":"price_change","market":"0xd412ce774cfcf8dc9f71164aac78783978aac7b03871702a3b8a481bd9dc9688","price_changes":[{"asset_id":"96600821790790307414914106093858868634329285205417149685270682748367152458577","best_ask":"0.67","best_bid":"0.65","hash":"e0035b523d5cc00d2c68089c7efa22402c1fb417","price":"0.65","side":"BUY","size":"6"},{"asset_id":"107603864457683460275633293642179940881969192120168665300712204232021063124301","best_ask":"0.35","best_bid":"0.33","hash":"632b37d8698f5d8bc09ebaa5b3c1cb845eee64c2","price":"0.35","side":"SELL","size":"6"}],"timestamp":"1785212020962"},"payload_hash":"995ced1fceabd3dc134bc0e43d252bddc670034bc9b24397002afc4781b27ac8","raw_frame":"{\"market\":\"0xd412ce774cfcf8dc9f71164aac78783978aac7b03871702a3b8a481bd9dc9688\", \"price_changes\":[{\"asset_id\":\"96600821790790307414914106093858868634329285205417149685270682748367152458577\", \"price\":\"0.65\", \"size\":\"6\", \"side\":\"BUY\", \"hash\":\"e0035b523d5cc00d2c68089c7efa22402c1fb417\", \"best_bid\":\"0.65\", \"best_ask\":\"0.67\"}, {\"asset_id\":\"107603864457683460275633293642179940881969192120168665300712204232021063124301\", \"price\":\"0.35\", \"size\":\"6\", \"side\":\"SELL\", \"hash\":\"632b37d8698f5d8bc09ebaa5b3c1cb845eee64c2\", \"best_bid\":\"0.33\", \"best_ask\":\"0.35\"}], \"timestamp\":\"1785212020962\", \"event_type\":\"price_change\"}","received_at":"2026-07-28T04:13:41.810434Z","schema_version":"clob-market-ws.price_change.v1","sequence":null,"server_hash":null,"server_timestamp":"1785212020962","session_id":"2d607381e3054cee91998cdf45a4231c","source":"clob_market_ws"},"received_at":"2026-07-28T04:13:41.810434Z","record_id":"f6a8f82fba7dbd531c88df45191c107975f7130919708dbca868706a9dcf68a4","schema_fingerprint":"4aa3821a28b0b7c2400bc59aba4bcc0a76e971dadd19610d3ad38c768e124dc7","schema_version":"edge-lab-recorder.raw.v1","sequence":null,"source":"clob_market_ws"}
{"event_at":"2026-07-28T04:13:40.966000Z","event_fingerprint":"6d3c4cfaa4e61ec556140d6eb1e36a288004842d64df034e996207493124142d","payload":{"connection_id":"f6725804f86a4c4eb588e4d5ed7db029","event_at":"2026-07-28T04:13:40.966000Z","event_type":"price_change","frame_hash":"5985369873a772b0199ca8463fc514a1f4645a807bb806cc3cc7495738e49c96","frame_index":0,"kind":"data","monotonic_ns":314004890155375,"payload":{"event_type":"price_change","market":"0xd412ce774cfcf8dc9f71164aac78783978aac7b03871702a3b8a481bd9dc9688","price_changes":[{"asset_id":"96600821790790307414914106093858868634329285205417149685270682748367152458577","best_ask":"0.67","best_bid":"0.65","hash":"515bee172db91e021cf34eb8a6e69425060217c9","price":"0.61","side":"BUY","size":"7"},{"asset_id":"107603864457683460275633293642179940881969192120168665300712204232021063124301","best_ask":"0.35","best_bid":"0.33","hash":"c8152f63284847bcd457091fa3724d5158f7a04f","price":"0.39","side":"SELL","size":"7"}],"timestamp":"1785212020966"},"payload_hash":"9226ba541b407feb9d4d14eae5dcb247336c69e10c16d6900c360fcd337b60d3","raw_frame":"{\"market\":\"0xd412ce774cfcf8dc9f71164aac78783978aac7b03871702a3b8a481bd9dc9688\", \"price_changes\":[{\"asset_id\":\"96600821790790307414914106093858868634329285205417149685270682748367152458577\", \"price\":\"0.61\", \"size\":\"7\", \"side\":\"BUY\", \"hash\":\"515bee172db91e021cf34eb8a6e69425060217c9\", \"best_bid\":\"0.65\", \"best_ask\":\"0.67\"}, {\"asset_id\":\"107603864457683460275633293642179940881969192120168665300712204232021063124301\", \"price\":\"0.39\", \"size\":\"7\", \"side\":\"SELL\", \"hash\":\"c8152f63284847bcd457091fa3724d5158f7a04f\", \"best_bid\":\"0.33\", \"best_ask\":\"0.35\"}], \"timestamp\":\"1785212020966\", \"event_type\":\"price_change\"}","received_at":"2026-07-28T04:13:41.812016Z","schema_version":"clob-market-ws.price_change.v1","sequence":null,"server_hash":null,"server_timestamp":"1785212020966","session_id":"2d607381e3054cee91998cdf45a4231c","source":"clob_market_ws"},"received_at":"2026-07-28T04:13:41.812016Z","record_id":"c2d7eb42626e3b7e02f59c8aa0504fdc814d191ec2e950c723b255ce1a192b9f","schema_fingerprint":"4aa3821a28b0b7c2400bc59aba4bcc0a76e971dadd19610d3ad38c768e124dc7","schema_version":"edge-lab-recorder.raw.v1","sequence":null,"source":"clob_market_ws"}
{"event_at":"2026-07-28T04:13:40.972000Z","event_fingerprint":"9148c2c1c31391b0a8ef7868236066860578ea250fb1bf9474e8238ebb1f5d55","payload":{"connection_id":"f6725804f86a4c4eb588e4d5ed7db029","event_at":"2026-07-28T04:13:40.972000Z","event_type":"price_change","frame_hash":"98910014be166a72f3071ca8d4807196f2f07377b110d3d5a49211aac0371251","frame_index":0,"kind":"data","monotonic_ns":314004891714708,"payload":{"event_type":"price_change","market":"0xd412ce774cfcf8dc9f71164aac78783978aac7b03871702a3b8a481bd9dc9688","price_changes":[{"asset_id":"107603864457683460275633293642179940881969192120168665300712204232021063124301","best_ask":"0.35","best_bid":"0.33","hash":"faaa38074b4aa493310709f953be63537a7834c2","price":"0.39","side":"SELL","size":"14"},{"asset_id":"96600821790790307414914106093858868634329285205417149685270682748367152458577","best_ask":"0.67","best_bid":"0.65","hash":"8b4578fc73b31a2c1168831996e92e6e874bb7ce","price":"0.61","side":"BUY","size":"14"}],"timestamp":"1785212020972"},"payload_hash":"2247c5a22d55f97c2c11db8c03b05b92c5b1cbcfda839f648024f9247e05344c","raw_frame":"{\"market\":\"0xd412ce774cfcf8dc9f71164aac78783978aac7b03871702a3b8a481bd9dc9688\", \"price_changes\":[{\"asset_id\":\"107603864457683460275633293642179940881969192120168665300712204232021063124301\", \"price\":\"0.39\", \"size\":\"14\", \"side\":\"SELL\", \"hash\":\"faaa38074b4aa493310709f953be63537a7834c2\", \"best_bid\":\"0.33\", \"best_ask\":\"0.35\"}, {\"asset_id\":\"96600821790790307414914106093858868634329285205417149685270682748367152458577\", \"price\":\"0.61\", \"size\":\"14\", \"side\":\"BUY\", \"hash\":\"8b4578fc73b31a2c1168831996e92e6e874bb7ce\", \"best_bid\":\"0.65\", \"best_ask\":\"0.67\"}], \"timestamp\":\"1785212020972\", \"event_type\":\"price_change\"}","received_at":"2026-07-28T04:13:41.813577Z","schema_version":"clob-market-ws.price_change.v1","sequence":null,"server_hash":null,"server_timestamp":"1785212020972","session_id":"2d607381e3054cee91998cdf45a4231c","source":"clob_market_ws"},"received_at":"2026-07-28T04:13:41.813577Z","record_id":"b93653ed66cf883c6879b33aa8c7da1a1099c7ac92c141f9d8accd69ccfe3ffb","schema_fingerprint":"4aa3821a28b0b7c2400bc59aba4bcc0a76e971dadd19610d3ad38c768e124dc7","schema_version":"edge-lab-recorder.raw.v1","sequence":null,"source":"clob_market_ws"}
{"event_at":"2026-07-28T04:13:40.973000Z","event_fingerprint":"6aab04e6e90a808dac53f676a0be6390125d5ce478f88cb12f0956e131742d3a","payload":{"connection_id":"f6725804f86a4c4eb588e4d5ed7db029","event_at":"2026-07-28T04:13:40.973000Z","event_type":"price_change","frame_hash":"736386cc63b0c2338110cde2dd0d8b5fcb34c283234c93ec5e23a748df3367a0","frame_index":0,"kind":"data","monotonic_ns":314004894891583,"payload":{"event_type":"price_change","market":"0xd412ce774cfcf8dc9f71164aac78783978aac7b03871702a3b8a481bd9dc9688","price_changes":[{"asset_id":"96600821790790307414914106093858868634329285205417149685270682748367152458577","best_ask":"0.67","best_bid":"0.65","hash":"62639b31b989a7be612d332f2ade9707137d79d0","price":"0.61","side":"BUY","size":"23"},{"asset_id":"107603864457683460275633293642179940881969192120168665300712204232021063124301","best_ask":"0.35","best_bid":"0.33","hash":"1dce162c6aac2751931bf341927f9ba107bd2b1a","price":"0.39","side":"SELL","size":"23"}],"timestamp":"1785212020973"},"payload_hash":"5595db5ba8e8e8d9171ea499899c9bdea38511ac7ec4927f2414a58ff9b5e375","raw_frame":"{\"market\":\"0xd412ce774cfcf8dc9f71164aac78783978aac7b03871702a3b8a481bd9dc9688\", \"price_changes\":[{\"asset_id\":\"96600821790790307414914106093858868634329285205417149685270682748367152458577\", \"price\":\"0.61\", \"size\":\"23\", \"side\":\"BUY\", \"hash\":\"62639b31b989a7be612d332f2ade9707137d79d0\", \"best_bid\":\"0.65\", \"best_ask\":\"0.67\"}, {\"asset_id\":\"107603864457683460275633293642179940881969192120168665300712204232021063124301\", \"price\":\"0.39\", \"size\":\"23\", \"side\":\"SELL\", \"hash\":\"1dce162c6aac2751931bf341927f9ba107bd2b1a\", \"best_bid\":\"0.33\", \"best_ask\":\"0.35\"}], \"timestamp\":\"1785212020973\", \"event_type\":\"price_change\"}","received_at":"2026-07-28T04:13:41.816753Z","schema_version":"clob-market-ws.price_change.v1","sequence":null,"server_hash":null,"server_timestamp":"1785212020973","session_id":"2d607381e3054cee91998cdf45a4231c","source":"clob_market_ws"},"received_at":"2026-07-28T04:13:41.816753Z","record_id":"6cc8800063fd87027b0d6e059e0b88a00118aab2a6e8d16d2f5e6908eeea5191","schema_fingerprint":"4aa3821a28b0b7c2400bc59aba4bcc0a76e971dadd19610d3ad38c768e124dc7","schema_version":"edge-lab-recorder.raw.v1","sequence":null,"source":"clob_market_ws"}
{"event_at":"2026-07-28T04:13:40.977000Z","event_fingerprint":"87e64cd3387312214755120d6540b223894fefebf8872c9f100a2a0938ed418f","payload":{"connection_id":"f6725804f86a4c4eb588e4d5ed7db029","event_at":"2026-07-28T04:13:40.977000Z","event_type":"price_change","frame_hash":"e1da39459b82597034cbbd2a15168535444bfe46a41793221cac571658ad7b9e","frame_index":0,"kind":"data","monotonic_ns":314004896621291,"payload":{"event_type":"price_change","market":"0xd412ce774cfcf8dc9f71164aac78783978aac7b03871702a3b8a481bd9dc9688","price_changes":[{"asset_id":"96600821790790307414914106093858868634329285205417149685270682748367152458577","best_ask":"0.67","best_bid":"0.65","hash":"6f3be298e91dfd6d47dc798041b02e83302bf45a","price":"0.61","side":"BUY","size":"16"},{"asset_id":"107603864457683460275633293642179940881969192120168665300712204232021063124301","best_ask":"0.35","best_bid":"0.33","hash":"9972f0edde607dececa7593b85ffa18fac791f4c","price":"0.39","side":"SELL","size":"16"}],"timestamp":"1785212020977"},"payload_hash":"2b761365d2afeea403624efbaf995ce6af62328bda99d24fe44a2f53d3609f6c","raw_frame":"{\"market\":\"0xd412ce774cfcf8dc9f71164aac78783978aac7b03871702a3b8a481bd9dc9688\", \"price_changes\":[{\"asset_id\":\"96600821790790307414914106093858868634329285205417149685270682748367152458577\", \"price\":\"0.61\", \"size\":\"16\", \"side\":\"BUY\", \"hash\":\"6f3be298e91dfd6d47dc798041b02e83302bf45a\", \"best_bid\":\"0.65\", \"best_ask\":\"0.67\"}, {\"asset_id\":\"107603864457683460275633293642179940881969192120168665300712204232021063124301\", \"price\":\"0.39\", \"size\":\"16\", \"side\":\"SELL\", \"hash\":\"9972f0edde607dececa7593b85ffa18fac791f4c\", \"best_bid\":\"0.33\", \"best_ask\":\"0.35\"}], \"timestamp\":\"1785212020977\", \"event_type\":\"price_change\"}","received_at":"2026-07-28T04:13:41.818483Z","schema_version":"clob-market-ws.price_change.v1","sequence":null,"server_hash":null,"server_timestamp":"1785212020977","session_id":"2d607381e3054cee91998cdf45a4231c","source":"clob_market_ws"},"received_at":"2026-07-28T04:13:41.818483Z","record_id":"fa4c2672a7d075e18de17d185e9d9a4ddfaa878d96978f417156a907dd111e85","schema_fingerprint":"4aa3821a28b0b7c2400bc59aba4bcc0a76e971dadd19610d3ad38c768e124dc7","schema_version":"edge-lab-recorder.raw.v1","sequence":null,"source":"clob_market_ws"}
{"event_at":"2026-07-28T04:13:40.980000Z","event_fingerprint":"7332c6af57555d80157f2bf6d4f0526752f589d642c76d3b083fbc18be3a8941","payload":{"connection_id":"f6725804f86a4c4eb588e4d5ed7db029","event_at":"2026-07-28T04:13:40.980000Z","event_type":"price_change","frame_hash":"ee0de70a415df0832cc80668090d2012c8069fbadf28067edb08dcdeab6828c4","frame_index":0,"kind":"data","monotonic_ns":314004899740666,"payload":{"event_type":"price_change","market":"0xd412ce774cfcf8dc9f71164aac78783978aac7b03871702a3b8a481bd9dc9688","price_changes":[{"asset_id":"96600821790790307414914106093858868634329285205417149685270682748367152458577","best_ask":"0.67","best_bid":"0.65","hash":"f75b1c60e045079b7c240bea35d39f953afd9abf","price":"0.61","side":"BUY","size":"7"},{"asset_id":"107603864457683460275633293642179940881969192120168665300712204232021063124301","best_ask":"0.35","best_bid":"0.33","hash":"d7a7917edeb9ef0fb3886551450d374f34961f4a","price":"0.39","side":"SELL","size":"7"}],"timestamp":"1785212020980"},"payload_hash":"0f71651e8d0193bfae9774a3a2280ee864978dd96b95ca501474ffa0d1963955","raw_frame":"{\"market\":\"0xd412ce774cfcf8dc9f71164aac78783978aac7b03871702a3b8a481bd9dc9688\", \"price_changes\":[{\"asset_id\":\"96600821790790307414914106093858868634329285205417149685270682748367152458577\", \"price\":\"0.61\", \"size\":\"7\", \"side\":\"BUY\", \"hash\":\"f75b1c60e045079b7c240bea35d39f953afd9abf\", \"best_bid\":\"0.65\", \"best_ask\":\"0.67\"}, {\"asset_id\":\"107603864457683460275633293642179940881969192120168665300712204232021063124301\", \"price\":\"0.39\", \"size\":\"7\", \"side\":\"SELL\", \"hash\":\"d7a7917edeb9ef0fb3886551450d374f34961f4a\", \"best_bid\":\"0.33\", \"best_ask\":\"0.35\"}], \"timestamp\":\"1785212020980\", \"event_type\":\"price_change\"}","received_at":"2026-07-28T04:13:41.821602Z","schema_version":"clob-market-ws.price_change.v1","sequence":null,"server_hash":null,"server_timestamp":"1785212020980","session_id":"2d607381e3054cee91998cdf45a4231c","source":"clob_market_ws"},"received_at":"2026-07-28T04:13:41.821602Z","record_id":"b1d6c17d6a74803b5cfa75db4a54f921a5be19c875ebbfd0ed142b0b68a8adf9","schema_fingerprint":"4aa3821a28b0b7c2400bc59aba4bcc0a76e971dadd19610d3ad38c768e124dc7","schema_version":"edge-lab-recorder.raw.v1","sequence":null,"source":"clob_market_ws"}
{"event_at":"2026-07-28T04:13:40.983000Z","event_fingerprint":"262d9cb2e7ca84946d1cb70278fb82b6e11c1b1d4ba949c5d5704bf0aafe48f1","payload":{"connection_id":"f6725804f86a4c4eb588e4d5ed7db029","event_at":"2026-07-28T04:13:40.983000Z","event_type":"price_change","frame_hash":"ad4cd90608c1f6b79a3edb236cbc53161556291403de2a38aba78fbce0b5fa84","frame_index":0,"kind":"data","monotonic_ns":314004901440333,"payload":{"event_type":"price_change","market":"0xd412ce774cfcf8dc9f71164aac78783978aac7b03871702a3b8a481bd9dc9688","price_changes":[{"asset_id":"107603864457683460275633293642179940881969192120168665300712204232021063124301","best_ask":"0.35","best_bid":"0.33","hash":"a70a54afab25eb213ebe5a951226c4a6d1282da1","price":"0.39","side":"SELL","size":"0"},{"asset_id":"96600821790790307414914106093858868634329285205417149685270682748367152458577","best_ask":"0.67","best_bid":"0.65","hash":"b0d15f2f58b19821265965e2483a394f1bd7ac3c","price":"0.61","side":"BUY","size":"0"}],"timestamp":"1785212020983"},"payload_hash":"20dc77e794ca91f920e87c08f1269a0e720b3fe62446dd804113489361e17b87","raw_frame":"{\"market\":\"0xd412ce774cfcf8dc9f71164aac78783978aac7b03871702a3b8a481bd9dc9688\", \"price_changes\":[{\"asset_id\":\"107603864457683460275633293642179940881969192120168665300712204232021063124301\", \"price\":\"0.39\", \"size\":\"0\", \"side\":\"SELL\", \"hash\":\"a70a54afab25eb213ebe5a951226c4a6d1282da1\", \"best_bid\":\"0.33\", \"best_ask\":\"0.35\"}, {\"asset_id\":\"96600821790790307414914106093858868634329285205417149685270682748367152458577\", \"price\":\"0.61\", \"size\":\"0\", \"side\":\"BUY\", \"hash\":\"b0d15f2f58b19821265965e2483a394f1bd7ac3c\", \"best_bid\":\"0.65\", \"best_ask\":\"0.67\"}], \"timestamp\":\"1785212020983\", \"event_type\":\"price_change\"}","received_at":"2026-07-28T04:13:41.823301Z","schema_version":"clob-market-ws.price_change.v1","sequence":null,"server_hash":null,"server_timestamp":"1785212020983","session_id":"2d607381e3054cee91998cdf45a4231c","source":"clob_market_ws"},"received_at":"2026-07-28T04:13:41.823301Z","record_id":"4d0da9c5e335e64fb7ca357c9d1616c07fef8ce0845fa4aeec76d05ef5d55faa","schema_fingerprint":"4aa3821a28b0b7c2400bc59aba4bcc0a76e971dadd19610d3ad38c768e124dc7","schema_version":"edge-lab-recorder.raw.v1","sequence":null,"source":"clob_market_ws"}
{"event_at":"2026-07-28T04:13:40.999000Z","event_fingerprint":"70c32f791fd44260bf8f6a13bab6de60514356a66f2b784adbd6a99f0f6648db","payload":{"connection_id":"f6725804f86a4c4eb588e4d5ed7db029","event_at":"2026-07-28T04:13:40.999000Z","event_type":"price_change","frame_hash":"af0ad9c6067bf8c9a12f230552239570d84296147867a0872c0bca068efef344","frame_index":0,"kind":"data","monotonic_ns":314004902992958,"payload":{"event_type":"price_change","market":"0xd412ce774cfcf8dc9f71164aac78783978aac7b03871702a3b8a481bd9dc9688","price_changes":[{"asset_id":"96600821790790307414914106093858868634329285205417149685270682748367152458577","best_ask":"0.67","best_bid":"0.65","hash":"3d0af46d8dbc34972dec83fbf82754364325f8e4","price":"0.02","side":"BUY","size":"520"},{"asset_id":"107603864457683460275633293642179940881969192120168665300712204232021063124301","best_ask":"0.35","best_bid":"0.33","hash":"7eb1e3c5af5fee90f24fb8e2dd2b0dfd2e5f906d","price":"0.98","side":"SELL","size":"520"}],"timestamp":"1785212020999"},"payload_hash":"f2c6fdf18f5498871a20941157d9aff510589f3cfe3907d0b4499165f4d373aa","raw_frame":"{\"market\":\"0xd412ce774cfcf8dc9f71164aac78783978aac7b03871702a3b8a481bd9dc9688\", \"price_changes\":[{\"asset_id\":\"96600821790790307414914106093858868634329285205417149685270682748367152458577\", \"price\":\"0.02\", \"size\":\"520\", \"side\":\"BUY\", \"hash\":\"3d0af46d8dbc34972dec83fbf82754364325f8e4\", \"best_bid\":\"0.65\", \"best_ask\":\"0.67\"}, {\"asset_id\":\"107603864457683460275633293642179940881969192120168665300712204232021063124301\", \"price\":\"0.98\", \"size\":\"520\", \"side\":\"SELL\", \"hash\":\"7eb1e3c5af5fee90f24fb8e2dd2b0dfd2e5f906d\", \"best_bid\":\"0.33\", \"best_ask\":\"0.35\"}], \"timestamp\":\"1785212020999\", \"event_type\":\"price_change\"}","received_at":"2026-07-28T04:13:41.824854Z","schema_version":"clob-market-ws.price_change.v1","sequence":null,"server_hash":null,"server_timestamp":"1785212020999","session_id":"2d607381e3054cee91998cdf45a4231c","source":"clob_market_ws"},"received_at":"2026-07-28T04:13:41.824854Z","record_id":"315b3af477eac31f90da78ced769ce1ae177f9f0c495c4655e6fdc12ca64967e","schema_fingerprint":"4aa3821a28b0b7c2400bc59aba4bcc0a76e971dadd19610d3ad38c768e124dc7","schema_version":"edge-lab-recorder.raw.v1","sequence":null,"source":"clob_market_ws"}
