{"event_at":"2026-07-28T04:09:50.857000Z","event_fingerprint":"ee3e6c402c96252a5b6323c413c7dea62b8ee0b35dae376ec1916be4fdbc9af5","payload":{"connection_id":"f6725804f86a4c4eb588e4d5ed7db029","event_at":"2026-07-28T04:09:50.857000Z","event_type":"price_change","frame_hash":"1040643e88ca6c98c5bbd58cc48f271395d9c8cf782420e27da43e70d6703719","frame_index":0,"kind":"data","monotonic_ns":313773858526125,"payload":{"event_type":"price_change","market":"0xd412ce774cfcf8dc9f71164aac78783978aac7b03871702a3b8a481bd9dc9688","price_changes":[{"asset_id":"107603864457683460275633293642179940881969192120168665300712204232021063124301","best_ask":"0.61","best_bid":"0.6","hash":"46c9eed36c0f736f12088d8268c8085f601576f0","price":"0.02","side":"BUY","size":"683.1"},{"asset_id":"96600821790790307414914106093858868634329285205417149685270682748367152458577","best_ask":"0.4","best_bid":"0.39","hash":"8739a95527f971dd4dbe0849a55b18a067e31ba0","price":"0.98","side":"SELL","size":"683.1"}],"timestamp":"1785211790857"},"payload_hash":"7a7308db242587358c442c7668f2b9c3f6f0b4972294720785a3c22383699975","raw_frame":"{\"market\":\"0xd412ce774cfcf8dc9f71164aac78783978aac7b03871702a3b8a481bd9dc9688\", \"price_changes\":[{\"asset_id\":\"107603864457683460275633293642179940881969192120168665300712204232021063124301\", \"price\":\"0.02\", \"size\":\"683.1\", \"side\":\"BUY\", \"hash\":\"46c9eed36c0f736f12088d8268c8085f601576f0\", \"best_bid\":\"0.6\", \"best_ask\":\"0.61\"}, {\"asset_id\":\"96600821790790307414914106093858868634329285205417149685270682748367152458577\", \"price\":\"0.98\", \"size\":\"683.1\", \"side\":\"SELL\", \"hash\":\"8739a95527f971dd4dbe0849a55b18a067e31ba0\", \"best_bid\":\"0.39\", \"best_ask\":\"0.4\"}], \"timestamp\":\"1785211790857\", \"event_type\":\"price_change\"}","received_at":"2026-07-28T04:09:50.782784Z","schema_version":"clob-market-ws.price_change.v1","sequence":null,"server_hash":null,"server_timestamp":"1785211790857","session_id":"2d607381e3054cee91998cdf45a4231c","source":"clob_market_ws"},"received_at":"2026-07-28T04:09:50.782784Z","record_id":"ed6699a8c179df403e6df80c68490ad4d031b2c150828398b0c152cc24bc896c","schema_fingerprint":"4aa3821a28b0b7c2400bc59aba4bcc0a76e971dadd19610d3ad38c768e124dc7","schema_version":"edge-lab-recorder.raw.v1","sequence":null,"source":"clob_market_ws"}
{"event_at":"2026-07-28T04:09:50.858000Z","event_fingerprint":"28f037a3fb22813d6a84f47f8390fcaa080bc7f57a603440d8f2b0efbae7122c","payload":{"connection_id":"f6725804f86a4c4eb588e4d5ed7db029","event_at":"2026-07-28T04:09:50.858000Z","event_type":"price_change","frame_hash":"be3cdd05cef7aa0bfe2539144467adb2c3e44749f734c16009008055a8568792","frame_index":0,"kind":"data","monotonic_ns":313773868269125,"payload":{"event_type":"price_change","market":"0xd412ce774cfcf8dc9f71164aac78783978aac7b03871702a3b8a481bd9dc9688","price_changes":[{"asset_id":"107603864457683460275633293642179940881969192120168665300712204232021063124301","best_ask":"0.61","best_bid":"0.6","hash":"02f4c766f87cc2230ebcf4a5d282c8d8f73a8a29","price":"0.52","side":"BUY","size":"42"},{"asset_id":"96600821790790307414914106093858868634329285205417149685270682748367152458577","best_ask":"0.4","best_bid":"0.39","hash":"19472fa866d3eb254313a5691aac1d03915fe699","price":"0.48","side":"SELL","size":"42"}],"timestamp":"1785211790858"},"payload_hash":"5709a8b132edb7fcb4a1c5892356bee55bd9115f028fbf568174d7d3afe3e406","raw_frame":"{\"market\":\"0xd412ce774cfcf8dc9f71164aac78783978aac7b03871702a3b8a481bd9dc9688\", \"price_changes\":[{\"asset_id\":\"107603864457683460275633293642179940881969192120168665300712204232021063124301\", \"price\":\"0.52\", \"size\":\"42\", \"side\":\"BUY\", \"hash\":\"02f4c766f87cc2230ebcf4a5d282c8d8f73a8a29\", \"best_bid\":\"0.6\", \"best_ask\":\"0.61\"}, {\"asset_id\":\"96600821790790307414914106093858868634329285205417149685270682748367152458577\", \"price\":\"0.48\", \"size\":\"42\", \"side\":\"SELL\", \"hash\":\"19472fa866d3eb254313a5691aac1d03915fe699\", \"best_bid\":\"0.39\", \"best_ask\":\"0.4\"}], \"timestamp\":\"1785211790858\", \"event_type\":\"price_change\"}","received_at":"2026-07-28T04:09:50.792527Z","schema_version":"clob-market-ws.price_change.v1","sequence":null,"server_hash":null,"server_timestamp":"1785211790858","session_id":"2d607381e3054cee91998cdf45a4231c","source":"clob_market_ws"},"received_at":"2026-07-28T04:09:50.792527Z","record_id":"e51b3a8f422caced131ffbe5c0caa0e85addd74beb4664861cd7c49257ac5215","schema_fingerprint":"4aa3821a28b0b7c2400bc59aba4bcc0a76e971dadd19610d3ad38c768e124dc7","schema_version":"edge-lab-recorder.raw.v1","sequence":null,"source":"clob_market_ws"}
{"event_at":"2026-07-28T04:09:50.910000Z","event_fingerprint":"2573515392bc7e4669f45e4ad65dbd6b5ccf4f2e431df351c2654d3bcd9ae94a","payload":{"connection_id":"f6725804f86a4c4eb588e4d5ed7db029","event_at":"2026-07-28T04:09:50.910000Z","event_type":"price_change","frame_hash":"47cf299d76863724d775562957b67733a40a3132aef907bd86dc53fdc12a22b1","frame_index":0,"kind":"data","monotonic_ns":313773873766666,"payload":{"event_type":"price_change","market":"0xd412ce774cfcf8dc9f71164aac78783978aac7b03871702a3b8a481bd9dc9688","price_changes":[{"asset_id":"107603864457683460275633293642179940881969192120168665300712204232021063124301","best_ask":"0.61","best_bid":"0.6","hash":"17c893b5282d4ec006efc6d8654aeabf1d543f2e","price":"0.54","side":"BUY","size":"74.6"},{"asset_id":"96600821790790307414914106093858868634329285205417149685270682748367152458577","best_ask":"0.4","best_bid":"0.39","hash":"f28b37d8d8829897446df19808f2e035627a7950","price":"0.46","side":"SELL","size":"74.6"}],"timestamp":"1785211790910"},"payload_hash":"a57422cef630a3387adddf4fdb6d5aa00f21f582cabba4d0405fa1b68952d248","raw_frame":"{\"market\":\"0xd412ce774cfcf8dc9f71164aac78783978aac7b03871702a3b8a481bd9dc9688\", \"price_changes\":[{\"asset_id\":\"107603864457683460275633293642179940881969192120168665300712204232021063124301\", \"price\":\"0.54\", \"size\":\"74.6\", \"side\":\"BUY\", \"hash\":\"17c893b5282d4ec006efc6d8654aeabf1d543f2e\", \"best_bid\":\"0.6\", \"best_ask\":\"0.61\"}, {\"asset_id\":\"96600821790790307414914106093858868634329285205417149685270682748367152458577\", \"price\":\"0.46\", \"size\":\"74.6\", \"side\":\"SELL\", \"hash\":\"f28b37d8d8829897446df19808f2e035627a7950\", \"best_bid\":\"0.39\", \"best_ask\":\"0.4\"}], \"timestamp\":\"1785211790910\", \"event_type\":\"price_change\"}","received_at":"2026-07-28T04:09:50.798025Z","schema_version":"clob-market-ws.price_change.v1","sequence":null,"server_hash":null,"server_timestamp":"1785211790910","session_id":"2d607381e3054cee91998cdf45a4231c","source":"clob_market_ws"},"received_at":"2026-07-28T04:09:50.798025Z","record_id":"d410c85d72235415b1555a9d7cd6e904698e35e47a2b8ac45346678e91ed9bbc","schema_fingerprint":"4aa3821a28b0b7c2400bc59aba4bcc0a76e971dadd19610d3ad38c768e124dc7","schema_version":"edge-lab-recorder.raw.v1","sequence":null,"source":"clob_market_ws"}
{"event_at":"2026-07-28T04:09:50.912000Z","event_fingerprint":"36e0e0e91d771df900e0e1cd43232bd910b3eb1301ddb3232177f98396b28d28","payload":{"connection_id":"f6725804f86a4c4eb588e4d5ed7db029","event_at":"2026-07-28T04:09:50.912000Z","event_type":"price_change","frame_hash":"89ff32e6db30f2481a58ae7b60bdb64a7c51636dd0e670d88fd1e7776832fe95","frame_index":0,"kind":"data","monotonic_ns":313773878301958,"payload":{"event_type":"price_change","market":"0xd412ce774cfcf8dc9f71164aac78783978aac7b03871702a3b8a481bd9dc9688","price_changes":[{"asset_id":"107603864457683460275633293642179940881969192120168665300712204232021063124301","best_ask":"0.61","best_bid":"0.6","hash":"1be4b27fff5f6183d90d9141e84a14b600b7b99c","price":"0.5","side":"BUY","size":"152"},{"asset_id":"96600821790790307414914106093858868634329285205417149685270682748367152458577","best_ask":"0.4","best_bid":"0.39","hash":"6378c6a1ef3a62149c4aed7e34df3b90f9498767","price":"0.5","side":"SELL","size":"152"}],"timestamp":"1785211790912"},"payload_hash":"ccb0ffa146356ca5877d9f982d62490904a27547b6d7a1470cecaa0169d63296","raw_frame":"{\"market\":\"0xd412ce774cfcf8dc9f71164aac78783978aac7b03871702a3b8a481bd9dc9688\", \"price_changes\":[{\"asset_id\":\"107603864457683460275633293642179940881969192120168665300712204232021063124301\", \"price\":\"0.5\", \"size\":\"152\", \"side\":\"BUY\", \"hash\":\"1be4b27fff5f6183d90d9141e84a14b600b7b99c\", \"best_bid\":\"0.6\", \"best_ask\":\"0.61\"}, {\"asset_id\":\"96600821790790307414914106093858868634329285205417149685270682748367152458577\", \"price\":\"0.5\", \"size\":\"152\", \"side\":\"SELL\", \"hash\":\"6378c6a1ef3a62149c4aed7e34df3b90f9498767\", \"best_bid\":\"0.39\", \"best_ask\":\"0.4\"}], \"timestamp\":\"1785211790912\", \"event_type\":\"price_change\"}","received_at":"2026-07-28T04:09:50.802560Z","schema_version":"clob-market-ws.price_change.v1","sequence":null,"server_hash":null,"server_timestamp":"1785211790912","session_id":"2d607381e3054cee91998cdf45a4231c","source":"clob_market_ws"},"received_at":"2026-07-28T04:09:50.802560Z","record_id":"6e87f14ea805f4f4de36a0cf53441c859e272126a23e36978a3247d57a402b94","schema_fingerprint":"4aa3821a28b0b7c2400bc59aba4bcc0a76e971dadd19610d3ad38c768e124dc7","schema_version":"edge-lab-recorder.raw.v1","sequence":null,"source":"clob_market_ws"}
{"event_at":"2026-07-28T04:09:50.913000Z","event_fingerprint":"d971e77cd716d0a1702666a41d117cb136c557fd608e10176bf11e26d24979e5","payload":{"connection_id":"f6725804f86a4c4eb588e4d5ed7db029","event_at":"2026-07-28T04:09:50.913000Z","event_type":"price_change","frame_hash":"4e025c6da57742511fcd6622d5d14d3d112be0a390b6890ae89eec8bf2d9abc0","frame_index":0,"kind":"data","monotonic_ns":313773884027125,"payload":{"event_type":"price_change","market":"0xd412ce774cfcf8dc9f71164aac78783978aac7b03871702a3b8a481bd9dc9688","price_changes":[{"asset_id":"107603864457683460275633293642179940881969192120168665300712204232021063124301","best_ask":"0.61","best_bid":"0.6","hash":"4690d331ec36675a0562ad825cb8a1dcaaf307fb","price":"0.52","side":"BUY","size":"80"},{"asset_id":"96600821790790307414914106093858868634329285205417149685270682748367152458577","best_ask":"0.4","best_bid":"0.39","hash":"cdfbf7ed97d616d238e1bed43dac97411d099d41","price":"0.48","side":"SELL","size":"80"}],"timestamp":"1785211790913"},"payload_hash":"2a44409c6dd38047997f145e2fbb57306b46facd74b838e7376ee93b9922dc6d","raw_frame":"{\"market\":\"0xd412ce774cfcf8dc9f71164aac78783978aac7b03871702a3b8a481bd9dc9688\", \"price_changes\":[{\"asset_id\":\"107603864457683460275633293642179940881969192120168665300712204232021063124301\", \"price\":\"0.52\", \"size\":\"80\", \"side\":\"BUY\", \"hash\":\"4690d331ec36675a0562ad825cb8a1dcaaf307fb\", \"best_bid\":\"0.6\", \"best_ask\":\"0.61\"}, {\"asset_id\":\"96600821790790307414914106093858868634329285205417149685270682748367152458577\", \"price\":\"0.48\", \"size\":\"80\", \"side\":\"SELL\", \"hash\":\"cdfbf7ed97d616d238e1bed43dac97411d099d41\", \"best_bid\":\"0.39\", \"best_ask\":\"0.4\"}], \"timestamp\":\"1785211790913\", \"event_type\":\"price_change\"}","received_at":"2026-07-28T04:09:50.808285Z","schema_version":"clob-market-ws.price_change.v1","sequence":null,"server_hash":null,"server_timestamp":"1785211790913","session_id":"2d607381e3054cee91998cdf45a4231c","source":"clob_market_ws"},"received_at":"2026-07-28T04:09:50.808285Z","record_id":"d44e94afa7e978034c072d1e0b37d737ff21d5a5c075fdbca0a9fd03ae3f80fc","schema_fingerprint":"4aa3821a28b0b7c2400bc59aba4bcc0a76e971dadd19610d3ad38c768e124dc7","schema_version":"edge-lab-recorder.raw.v1","sequence":null,"source":"clob_market_ws"}
{"event_at":"2026-07-28T04:09:50.913000Z","event_fingerprint":"3f8cb0bea1071a1d884f4ffb78c24450f189753b8e2cb5d84fb79dc373159f40","payload":{"connection_id":"f6725804f86a4c4eb588e4d5ed7db029","event_at":"2026-07-28T04:09:50.913000Z","event_type":"price_change","frame_hash":"17057203ec0cf2286be544128f03a4f50d30ce73b94e107de343f0d1947a2102","frame_index":0,"kind":"data","monotonic_ns":313773889740708,"payload":{"event_type":"price_change","market":"0xd412ce774cfcf8dc9f71164aac78783978aac7b03871702a3b8a481bd9dc9688","price_changes":[{"asset_id":"107603864457683460275633293642179940881969192120168665300712204232021063124301","best_ask":"0.61","best_bid":"0.6","hash":"805df1e83cedb1cb9cde1851f1c65692f6146e6d","price":"0.55","side":"BUY","size":"73.6"},{"asset_id":"96600821790790307414914106093858868634329285205417149685270682748367152458577","best_ask":"0.4","best_bid":"0.39","hash":"ed93769e2358cbbb7204f273df655eecbf168ea8","price":"0.45","side":"SELL","size":"73.6"}],"timestamp":"1785211790913"},"payload_hash":"3af98835e26ba7fd15e23fab5123d8aef2044a5da698074d12a86371edc05ada","raw_frame":"{\"market\":\"0xd412ce774cfcf8dc9f71164aac78783978aac7b03871702a3b8a481bd9dc9688\", \"price_changes\":[{\"asset_id\":\"107603864457683460275633293642179940881969192120168665300712204232021063124301\", \"price\":\"0.55\", \"size\":\"73.6\", \"side\":\"BUY\", \"hash\":\"805df1e83cedb1cb9cde1851f1c65692f6146e6d\", \"best_bid\":\"0.6\", \"best_ask\":\"0.61\"}, {\"asset_id\":\"96600821790790307414914106093858868634329285205417149685270682748367152458577\", \"price\":\"0.45\", \"size\":\"73.6\", \"side\":\"SELL\", \"hash\":\"ed93769e2358cbbb7204f273df655eecbf168ea8\", \"best_bid\":\"0.39\", \"best_ask\":\"0.4\"}], \"timestamp\":\"1785211790913\", \"event_type\":\"price_change\"}","received_at":"2026-07-28T04:09:50.814000Z","schema_version":"clob-market-ws.price_change.v1","sequence":null,"server_hash":null,"server_timestamp":"1785211790913","session_id":"2d607381e3054cee91998cdf45a4231c","source":"clob_market_ws"},"received_at":"2026-07-28T04:09:50.814000Z","record_id":"c2051147d4f2c1a2a646fb235bd1a24a70ca1ff80cf589399ee9d721be7af71c","schema_fingerprint":"4aa3821a28b0b7c2400bc59aba4bcc0a76e971dadd19610d3ad38c768e124dc7","schema_version":"edge-lab-recorder.raw.v1","sequence":null,"source":"clob_market_ws"}
{"event_at":"2026-07-28T04:09:50.914000Z","event_fingerprint":"e302396b91668f7839d6dbcb65f17ecc963cce69a41702d9a242fe481d4a32df","payload":{"connection_id":"f6725804f86a4c4eb588e4d5ed7db029","event_at":"2026-07-28T04:09:50.914000Z","event_type":"price_change","frame_hash":"1227429ba00a5cebc821b8c8bb79fa3ddea1bd1dfd91854b57558776c87cb507","frame_index":0,"kind":"data","monotonic_ns":313773894439166,"payload":{"event_type":"price_change","market":"0xd412ce774cfcf8dc9f71164aac78783978aac7b03871702a3b8a481bd9dc9688","price_changes":[{"asset_id":"107603864457683460275633293642179940881969192120168665300712204232021063124301","best_ask":"0.61","best_bid":"0.6","hash":"ef434045a80d1554b3527a99a0668089a0f93f1a","price":"0.56","side":"BUY","size":"48.6"},{"asset_id":"96600821790790307414914106093858868634329285205417149685270682748367152458577","best_ask":"0.4","best_bid":"0.39","hash":"d85a3bd913ab2704888de9819594e2ace55399ea","price":"0.44","side":"SELL","size":"48.6"}],"timestamp":"1785211790914"},"payload_hash":"9420a6253acd6839a90ea21fb45a22711a5e52924a7dfd31b0695e7e69b3396b","raw_frame":"{\"market\":\"0xd412ce774cfcf8dc9f71164aac78783978aac7b03871702a3b8a481bd9dc9688\", \"price_changes\":[{\"asset_id\":\"107603864457683460275633293642179940881969192120168665300712204232021063124301\", \"price\":\"0.56\", \"size\":\"48.6\", \"side\":\"BUY\", \"hash\":\"ef434045a80d1554b3527a99a0668089a0f93f1a\", \"best_bid\":\"0.6\", \"best_ask\":\"0.61\"}, {\"asset_id\":\"96600821790790307414914106093858868634329285205417149685270682748367152458577\", \"price\":\"0.44\", \"size\":\"48.6\", \"side\":\"SELL\", \"hash\":\"d85a3bd913ab2704888de9819594e2ace55399ea\", \"best_bid\":\"0.39\", \"best_ask\":\"0.4\"}], \"timestamp\":\"1785211790914\", \"event_type\":\"price_change\"}","received_at":"2026-07-28T04:09:50.818697Z","schema_version":"clob-market-ws.price_change.v1","sequence":null,"server_hash":null,"server_timestamp":"1785211790914","session_id":"2d607381e3054cee91998cdf45a4231c","source":"clob_market_ws"},"received_at":"2026-07-28T04:09:50.818697Z","record_id":"a339ed0ff5f4504ad4d63df6c2d56e518ed39aa5a9c3f826b9150ab3af6b6970","schema_fingerprint":"4aa3821a28b0b7c2400bc59aba4bcc0a76e971dadd19610d3ad38c768e124dc7","schema_version":"edge-lab-recorder.raw.v1","sequence":null,"source":"clob_market_ws"}
{"event_at":"2026-07-28T04:09:50.916000Z","event_fingerprint":"60b1ca09947e520920c8943e86e6d3a164e6af2b90c67bbc44ab516b764b2f20","payload":{"connection_id":"f6725804f86a4c4eb588e4d5ed7db029","event_at":"2026-07-28T04:09:50.916000Z","event_type":"price_change","frame_hash":"74544f3fd32e003ce282ba192e8b633d79fd257a4c48cb7e56b95ff5689c534b","frame_index":0,"kind":"data","monotonic_ns":313773900058541,"payload":{"event_type":"price_change","market":"0xd412ce774cfcf8dc9f71164aac78783978aac7b03871702a3b8a481bd9dc9688","price_changes":[{"asset_id":"107603864457683460275633293642179940881969192120168665300712204232021063124301","best_ask":"0.61","best_bid":"0.6","hash":"cda91ad17a65a07769f210d2f88f9b8517fc1fa0","price":"0.51","side":"BUY","size":"60.97"},{"asset_id":"96600821790790307414914106093858868634329285205417149685270682748367152458577","best_ask":"0.4","best_bid":"0.39","hash":"b9e67b4603ca954008924f3f15cec9f9b86babba","price":"0.49","side":"SELL","size":"60.97"}],"timestamp":"1785211790916"},"payload_hash":"4af5683b1b81b66735531fc033d7bcce6dccddeacd802f92b624a13d7a5549be","raw_frame":"{\"market\":\"0xd412ce774cfcf8dc9f71164aac78783978aac7b03871702a3b8a481bd9dc9688\", \"price_changes\":[{\"asset_id\":\"107603864457683460275633293642179940881969192120168665300712204232021063124301\", \"price\":\"0.51\", \"size\":\"60.97\", \"side\":\"BUY\", \"hash\":\"cda91ad17a65a07769f210d2f88f9b8517fc1fa0\", \"best_bid\":\"0.6\", \"best_ask\":\"0.61\"}, {\"asset_id\":\"96600821790790307414914106093858868634329285205417149685270682748367152458577\", \"price\":\"0.49\", \"size\":\"60.97\", \"side\":\"SELL\", \"hash\":\"b9e67b4603ca954008924f3f15cec9f9b86babba\", \"best_bid\":\"0.39\", \"best_ask\":\"0.4\"}], \"timestamp\":\"1785211790916\", \"event_type\":\"price_change\"}","received_at":"2026-07-28T04:09:50.824317Z","schema_version":"clob-market-ws.price_change.v1","sequence":null,"server_hash":null,"server_timestamp":"1785211790916","session_id":"2d607381e3054cee91998cdf45a4231c","source":"clob_market_ws"},"received_at":"2026-07-28T04:09:50.824317Z","record_id":"e6e0a135a3f28ec0912eaa5058b67bfe21688152486bca44b59e17830dcd587a","schema_fingerprint":"4aa3821a28b0b7c2400bc59aba4bcc0a76e971dadd19610d3ad38c768e124dc7","schema_version":"edge-lab-recorder.raw.v1","sequence":null,"source":"clob_market_ws"}
{"event_at":"2026-07-28T04:09:50.916000Z","event_fingerprint":"314d00bcc88277916d0572db9d42058a66bfb7d51fe2d547787d22cc4e30b5c7","payload":{"connection_id":"f6725804f86a4c4eb588e4d5ed7db029","event_at":"2026-07-28T04:09:50.916000Z","event_type":"price_change","frame_hash":"dd73a9af1c946cdf3df8bda6d7f117c22aee46ed9f799ed4bdb305581488fe88","frame_index":0,"kind":"data","monotonic_ns":313773906847000,"payload":{"event_type":"price_change","market":"0xd412ce774cfcf8dc9f71164aac78783978aac7b03871702a3b8a481bd9dc9688","price_changes":[{"asset_id":"107603864457683460275633293642179940881969192120168665300712204232021063124301","best_ask":"0.61","best_bid":"0.6","hash":"def4135c2f9064e3c4b751e08583ea4a038f0aa1","price":"0.53","side":"BUY","size":"103"},{"asset_id":"96600821790790307414914106093858868634329285205417149685270682748367152458577","best_ask":"0.4","best_bid":"0.39","hash":"41c9e6b22796e3631e144c451394ad866fc53a9f","price":"0.47","side":"SELL","size":"103"}],"timestamp":"1785211790916"},"payload_hash":"c3b05c669199caedc0d4accbb6c520e6141c85dc02f2118070d0b96eb3b976be","raw_frame":"{\"market\":\"0xd412ce774cfcf8dc9f71164aac78783978aac7b03871702a3b8a481bd9dc9688\", \"price_changes\":[{\"asset_id\":\"107603864457683460275633293642179940881969192120168665300712204232021063124301\", \"price\":\"0.53\", \"size\":\"103\", \"side\":\"BUY\", \"hash\":\"def4135c2f9064e3c4b751e08583ea4a038f0aa1\", \"best_bid\":\"0.6\", \"best_ask\":\"0.61\"}, {\"asset_id\":\"96600821790790307414914106093858868634329285205417149685270682748367152458577\", \"price\":\"0.47\", \"size\":\"103\", \"side\":\"SELL\", \"hash\":\"41c9e6b22796e3631e144c451394ad866fc53a9f\", \"best_bid\":\"0.39\", \"best_ask\":\"0.4\"}], \"timestamp\":\"1785211790916\", \"event_type\":\"price_change\"}","received_at":"2026-07-28T04:09:50.831105Z","schema_version":"clob-market-ws.price_change.v1","sequence":null,"server_hash":null,"server_timestamp":"1785211790916","session_id":"2d607381e3054cee91998cdf45a4231c","source":"clob_market_ws"},"received_at":"2026-07-28T04:09:50.831105Z","record_id":"415c61bf15568a3dc434008f3b0db86e86117d45a8a07ab727d56154bd11e56a","schema_fingerprint":"4aa3821a28b0b7c2400bc59aba4bcc0a76e971dadd19610d3ad38c768e124dc7","schema_version":"edge-lab-recorder.raw.v1","sequence":null,"source":"clob_market_ws"}
{"event_at":"2026-07-28T04:09:50.917000Z","event_fingerprint":"ca959454b198bb4f1afe62d7e75e943ff28b19716bc0f6adc6b46105e7b997b6","payload":{"connection_id":"f6725804f86a4c4eb588e4d5ed7db029","event_at":"2026-07-28T04:09:50.917000Z","event_type":"price_change","frame_hash":"21009745b7201db3e04a493629b3baf570e0e464df7e1e98ca6a555c570b33cd","frame_index":0,"kind":"data","monotonic_ns":313773911799500,"payload":{"event_type":"price_change","market":"0xd412ce774cfcf8dc9f71164aac78783978aac7b03871702a3b8a481bd9dc9688","price_changes":[{"asset_id":"107603864457683460275633293642179940881969192120168665300712204232021063124301","best_ask":"0.61","best_bid":"0.6","hash":"cc24a0ebafc75022abc9386253a32299f0b7db08","price":"0.01","side":"BUY","size":"5638.02"},{"asset_id":"96600821790790307414914106093858868634329285205417149685270682748367152458577","best_ask":"0.4","best_bid":"0.39","hash":"214a71612cde0db58ede8d28db1c381027d63ef0","price":"0.99","side":"SELL","size":"5638.02"}],"timestamp":"1785211790917"},"payload_hash":"6ef9e5bd143efde1f63d3966eb3a60268d98a58f9ff11767017818d7418794ab","raw_frame":"{\"market\":\"0xd412ce774cfcf8dc9f71164aac78783978aac7b03871702a3b8a481bd9dc9688\", \"price_changes\":[{\"asset_id\":\"107603864457683460275633293642179940881969192120168665300712204232021063124301\", \"price\":\"0.01\", \"size\":\"5638.02\", \"side\":\"BUY\", \"hash\":\"cc24a0ebafc75022abc9386253a32299f0b7db08\", \"best_bid\":\"0.6\", \"best_ask\":\"0.61\"}, {\"asset_id\":\"96600821790790307414914106093858868634329285205417149685270682748367152458577\", \"price\":\"0.99\", \"size\":\"5638.02\", \"side\":\"SELL\", \"hash\":\"214a71612cde0db58ede8d28db1c381027d63ef0\", \"best_bid\":\"0.39\", \"best_ask\":\"0.4\"}], \"timestamp\":\"1785211790917\", \"event_type\":\"price_change\"}","received_at":"2026-07-28T04:09:50.836063Z","schema_version":"clob-market-ws.price_change.v1","sequence":null,"server_hash":null,"server_timestamp":"1785211790917","session_id":"2d607381e3054cee91998cdf45a4231c","source":"clob_market_ws"},"received_at":"2026-07-28T04:09:50.836063Z","record_id":"52a3294b33f9a71da601ed277930c739052fd666d638884b2debd33d2985d262","schema_fingerprint":"4aa3821a28b0b7c2400bc59aba4bcc0a76e971dadd19610d3ad38c768e124dc7","schema_version":"edge-lab-recorder.raw.v1","sequence":null,"source":"clob_market_ws"}
{"event_at":"2026-07-28T04:09:50.918000Z","event_fingerprint":"d656fd847aac2d033cfd7b09a0a9d17722b843f9165bd25fe1ceb8a96457d5ce","payload":{"connection_id":"f6725804f86a4c4eb588e4d5ed7db029","event_at":"2026-07-28T04:09:50.918000Z","event_type":"price_change","frame_hash":"0720c3798a25d5b4184c8d3b61804200c958c8110f6b8d2e7f969d0a13d6fb55","frame_index":0,"kind":"data","monotonic_ns":313773916574208,"payload":{"event_type":"price_change","market":"0xd412ce774cfcf8dc9f71164aac78783978aac7b03871702a3b8a481bd9dc9688","price_changes":[{"asset_id":"107603864457683460275633293642179940881969192120168665300712204232021063124301","best_ask":"0.61","best_bid":"0.6","hash":"53bf5e438b3b78a707895c90e9480efe928aa5f0","price":"0.57","side":"BUY","size":"76.2"},{"asset_id":"96600821790790307414914106093858868634329285205417149685270682748367152458577","best_ask":"0.4","best_bid":"0.39","hash":"d405bf688b9704cea0db3e993550c8cf47b21eb4","price":"0.43","side":"SELL","size":"76.2"}],"timestamp":"1785211790918"},"payload_hash":"f17c30c622b54bce665e0d1036c18de90ba8f21e29bfa1248ce45118f35e035b","raw_frame":"{\"market\":\"0xd412ce774cfcf8dc9f71164aac78783978aac7b03871702a3b8a481bd9dc9688\", \"price_changes\":[{\"asset_id\":\"107603864457683460275633293642179940881969192120168665300712204232021063124301\", \"price\":\"0.57\", \"size\":\"76.2\", \"side\":\"BUY\", \"hash\":\"53bf5e438b3b78a707895c90e9480efe928aa5f0\", \"best_bid\":\"0.6\", \"best_ask\":\"0.61\"}, {\"asset_id\":\"96600821790790307414914106093858868634329285205417149685270682748367152458577\", \"price\":\"0.43\", \"size\":\"76.2\", \"side\":\"SELL\", \"hash\":\"d405bf688b9704cea0db3e993550c8cf47b21eb4\", \"best_bid\":\"0.39\", \"best_ask\":\"0.4\"}], \"timestamp\":\"1785211790918\", \"event_type\":\"price_change\"}","received_at":"2026-07-28T04:09:50.840831Z","schema_version":"clob-market-ws.price_change.v1","sequence":null,"server_hash":null,"server_timestamp":"1785211790918","session_id":"2d607381e3054cee91998cdf45a4231c","source":"clob_market_ws"},"received_at":"2026-07-28T04:09:50.840831Z","record_id":"7ac5edb9d255dce4f4dfc12f9ea0000f71c0d5a75ab37e1f8e42db16b4323925","schema_fingerprint":"4aa3821a28b0b7c2400bc59aba4bcc0a76e971dadd19610d3ad38c768e124dc7","schema_version":"edge-lab-recorder.raw.v1","sequence":null,"source":"clob_market_ws"}
{"event_at":"2026-07-28T04:09:50.919000Z","event_fingerprint":"fda2617550a9fd14ee077d4fd3e0d396f414418fee36883c974b5942898a0361","payload":{"connection_id":"f6725804f86a4c4eb588e4d5ed7db029","event_at":"2026-07-28T04:09:50.919000Z","event_type":"price_change","frame_hash":"ae5911277acdc0297b5c01b1040e043ce231223d58463b70ec3ba088beacaf8c","frame_index":0,"kind":"data","monotonic_ns":313773920928291,"payload":{"event_type":"price_change","market":"0xd412ce774cfcf8dc9f71164aac78783978aac7b03871702a3b8a481bd9dc9688","price_changes":[{"asset_id":"107603864457683460275633293642179940881969192120168665300712204232021063124301","best_ask":"0.61","best_bid":"0.6","hash":"796d4ff30b80b609fc2f6a44a4c4e196aafcbb03","price":"0.58","side":"BUY","size":"78.2"},{"asset_id":"96600821790790307414914106093858868634329285205417149685270682748367152458577","best_ask":"0.4","best_bid":"0.39","hash":"59100f35e896585bb9ffd927030b52fe85dfd8d2","price":"0.42","side":"SELL","size":"78.2"}],"timestamp":"1785211790919"},"payload_hash":"6289d5acff583925754ba945f5b3da7dfe42063723f92d83a9af6b1abbdf0af9","raw_frame":"{\"market\":\"0xd412ce774cfcf8dc9f71164aac78783978aac7b03871702a3b8a481bd9dc9688\", \"price_changes\":[{\"asset_id\":\"107603864457683460275633293642179940881969192120168665300712204232021063124301\", \"price\":\"0.58\", \"size\":\"78.2\", \"side\":\"BUY\", \"hash\":\"796d4ff30b80b609fc2f6a44a4c4e196aafcbb03\", \"best_bid\":\"0.6\", \"best_ask\":\"0.61\"}, {\"asset_id\":\"96600821790790307414914106093858868634329285205417149685270682748367152458577\", \"price\":\"0.42\", \"size\":\"78.2\", \"side\":\"SELL\", \"hash\":\"59100f35e896585bb9ffd927030b52fe85dfd8d2\", \"best_bid\":\"0.39\", \"best_ask\":\"0.4\"}], \"timestamp\":\"1785211790919\", \"event_type\":\"price_change\"}","received_at":"2026-07-28T04:09:50.845186Z","schema_version":"clob-market-ws.price_change.v1","sequence":null,"server_hash":null,"server_timestamp":"1785211790919","session_id":"2d607381e3054cee91998cdf45a4231c","source":"clob_market_ws"},"received_at":"2026-07-28T04:09:50.845186Z","record_id":"9992ec5e5233c82beef20f5396fa0efaecad0568e4dcfefa47cb086274db90da","schema_fingerprint":"4aa3821a28b0b7c2400bc59aba4bcc0a76e971dadd19610d3ad38c768e124dc7","schema_version":"edge-lab-recorder.raw.v1","sequence":null,"source":"clob_market_ws"}
{"event_at":"2026-07-28T04:09:50.920000Z","event_fingerprint":"63a076fc7b6e3be4be819b7194ca798d334d2422b3e25a2e914c76bcc60322bb","payload":{"connection_id":"f6725804f86a4c4eb588e4d5ed7db029","event_at":"2026-07-28T04:09:50.920000Z","event_type":"price_change","frame_hash":"dbe24689c880e43fa6f30cf2ddfc3f7f9247fca8e01f5d007988ecf98f1107d1","frame_index":0,"kind":"data","monotonic_ns":313773925863166,"payload":{"event_type":"price_change","market":"0xd412ce774cfcf8dc9f71164aac78783978aac7b03871702a3b8a481bd9dc9688","price_changes":[{"asset_id":"107603864457683460275633293642179940881969192120168665300712204232021063124301","best_ask":"0.61","best_bid":"0.6","hash":"648f1a97badab0418c0702fef7321fc6334b7d51","price":"0.49","side":"BUY","size":"89.97"},{"asset_id":"96600821790790307414914106093858868634329285205417149685270682748367152458577","best_ask":"0.4","best_bid":"0.39","hash":"73f9fa5ae22a66addc39f595f7fa23fad8dd8633","price":"0.51","side":"SELL","size":"89.97"}],"timestamp":"1785211790920"},"payload_hash":"8c1bccafd43e1ea678fb71d67440edda32c0755bb0da65e705845082ca0109ca","raw_frame":"{\"market\":\"0xd412ce774cfcf8dc9f71164aac78783978aac7b03871702a3b8a481bd9dc9688\", \"price_changes\":[{\"asset_id\":\"107603864457683460275633293642179940881969192120168665300712204232021063124301\", \"price\":\"0.49\", \"size\":\"89.97\", \"side\":\"BUY\", \"hash\":\"648f1a97badab0418c0702fef7321fc6334b7d51\", \"best_bid\":\"0.6\", \"best_ask\":\"0.61\"}, {\"asset_id\":\"96600821790790307414914106093858868634329285205417149685270682748367152458577\", \"price\":\"0.51\", \"size\":\"89.97\", \"side\":\"SELL\", \"hash\":\"73f9fa5ae22a66addc39f595f7fa23fad8dd8633\", \"best_bid\":\"0.39\", \"best_ask\":\"0.4\"}], \"timestamp\":\"1785211790920\", \"event_type\":\"price_change\"}","received_at":"2026-07-28T04:09:50.850121Z","schema_version":"clob-market-ws.price_change.v1","sequence":null,"server_hash":null,"server_timestamp":"1785211790920","session_id":"2d607381e3054cee91998cdf45a4231c","source":"clob_market_ws"},"received_at":"2026-07-28T04:09:50.850121Z","record_id":"830d259682502ed5264ab961162602f231d1d607d00f21902afdf44132159440","schema_fingerprint":"4aa3821a28b0b7c2400bc59aba4bcc0a76e971dadd19610d3ad38c768e124dc7","schema_version":"edge-lab-recorder.raw.v1","sequence":null,"source":"clob_market_ws"}
{"event_at":"2026-07-28T04:09:50.939000Z","event_fingerprint":"d55ddeec76e7b6b5826c1ff67f67794817a708cbabe741af1ee343b05f0a0f36","payload":{"connection_id":"f6725804f86a4c4eb588e4d5ed7db029","event_at":"2026-07-28T04:09:50.939000Z","event_type":"price_change","frame_hash":"3ae13cefbe8369c364fe6bb81c1dd6d77799253db30e9c44b1674d5dc8e6afa5","frame_index":0,"kind":"data","monotonic_ns":313773933090000,"payload":{"event_type":"price_change","market":"0xd412ce774cfcf8dc9f71164aac78783978aac7b03871702a3b8a481bd9dc9688","price_changes":[{"asset_id":"107603864457683460275633293642179940881969192120168665300712204232021063124301","best_ask":"0.61","best_bid":"0.6","hash":"50af847eca644c2feb7a6d7eb5dd038cd24945d1","price":"0.02","side":"BUY","size":"688.1"},{"asset_id":"96600821790790307414914106093858868634329285205417149685270682748367152458577","best_ask":"0.4","best_bid":"0.39","hash":"53cbc98503c8cf048191f55001dd5c5182d273d3","price":"0.98","side":"SELL","size":"688.1"}],"timestamp":"1785211790939"},"payload_hash":"80a5ea65000b1d7f71a649b54450cf824aceb5e2021c0d924c760e03c1844801","raw_frame":"{\"market\":\"0xd412ce774cfcf8dc9f71164aac78783978aac7b03871702a3b8a481bd9dc9688\", \"price_changes\":[{\"asset_id\":\"107603864457683460275633293642179940881969192120168665300712204232021063124301\", \"price\":\"0.02\", \"size\":\"688.1\", \"side\":\"BUY\", \"hash\":\"50af847eca644c2feb7a6d7eb5dd038cd24945d1\", \"best_bid\":\"0.6\", \"best_ask\":\"0.61\"}, {\"asset_id\":\"96600821790790307414914106093858868634329285205417149685270682748367152458577\", \"price\":\"0.98\", \"size\":\"688.1\", \"side\":\"SELL\", \"hash\":\"53cbc98503c8cf048191f55001dd5c5182d273d3\", \"best_bid\":\"0.39\", \"best_ask\":\"0.4\"}], \"timestamp\":\"1785211790939\", \"event_type\":\"price_change\"}","received_at":"2026-07-28T04:09:50.857348Z","schema_version":"clob-market-ws.price_change.v1","sequence":null,"server_hash":null,"server_timestamp":"1785211790939","session_id":"2d607381e3054cee91998cdf45a4231c","source":"clob_market_ws"},"received_at":"2026-07-28T04:09:50.857348Z","record_id":"f0f4d2e74ae121246c0fd41182851b8a297be588294691c466732c37bcd826d6","schema_fingerprint":"4aa3821a28b0b7c2400bc59aba4bcc0a76e971dadd19610d3ad38c768e124dc7","schema_version":"edge-lab-recorder.raw.v1","sequence":null,"source":"clob_market_ws"}
{"event_at":"2026-07-28T04:09:50.939000Z","event_fingerprint":"11cd53cf59ee82afbbe027db468d91263b0c6fce89aeabe86b58cdd24137f1aa","payload":{"connection_id":"f6725804f86a4c4eb588e4d5ed7db029","event_at":"2026-07-28T04:09:50.939000Z","event_type":"price_change","frame_hash":"67ae0a254033042905110589f0c3aea7859962cca56987ba53271e719131cff3","frame_index":0,"kind":"data","monotonic_ns":313773938236458,"payload":{"event_type":"price_change","market":"0xd412ce774cfcf8dc9f71164aac78783978aac7b03871702a3b8a481bd9dc9688","price_changes":[{"asset_id":"107603864457683460275633293642179940881969192120168665300712204232021063124301","best_ask":"0.61","best_bid":"0.6","hash":"612e43f8c840e2d2d4117842e0b35ef91a8e04b9","price":"0.01","side":"BUY","size":"5633.02"},{"asset_id":"96600821790790307414914106093858868634329285205417149685270682748367152458577","best_ask":"0.4","best_bid":"0.39","hash":"a058d5d5c2add6313f09f83bc41afeef14b8b25c","price":"0.99","side":"SELL","size":"5633.02"}],"timestamp":"1785211790939"},"payload_hash":"821c75d0295e37dbf529c284e7f8adf0abbba5e0c221514a4ad854aa0e73c695","raw_frame":"{\"market\":\"0xd412ce774cfcf8dc9f71164aac78783978aac7b03871702a3b8a481bd9dc9688\", \"price_changes\":[{\"asset_id\":\"107603864457683460275633293642179940881969192120168665300712204232021063124301\", \"price\":\"0.01\", \"size\":\"5633.02\", \"side\":\"BUY\", \"hash\":\"612e43f8c840e2d2d4117842e0b35ef91a8e04b9\", \"best_bid\":\"0.6\", \"best_ask\":\"0.61\"}, {\"asset_id\":\"96600821790790307414914106093858868634329285205417149685270682748367152458577\", \"price\":\"0.99\", \"size\":\"5633.02\", \"side\":\"SELL\", \"hash\":\"a058d5d5c2add6313f09f83bc41afeef14b8b25c\", \"best_bid\":\"0.39\", \"best_ask\":\"0.4\"}], \"timestamp\":\"1785211790939\", \"event_type\":\"price_change\"}","received_at":"2026-07-28T04:09:50.862494Z","schema_version":"clob-market-ws.price_change.v1","sequence":null,"server_hash":null,"server_timestamp":"1785211790939","session_id":"2d607381e3054cee91998cdf45a4231c","source":"clob_market_ws"},"received_at":"2026-07-28T04:09:50.862494Z","record_id":"c8f29186d8d3ec496b59910c44162b66a04eddb835aad8b387ce25dd971d0fce","schema_fingerprint":"4aa3821a28b0b7c2400bc59aba4bcc0a76e971dadd19610d3ad38c768e124dc7","schema_version":"edge-lab-recorder.raw.v1","sequence":null,"source":"clob_market_ws"}
{"event_at":"2026-07-28T04:09:50.966000Z","event_fingerprint":"d7b37c904393be0c30cb20ac5fb3fecfacdbf2e55201ae663e5dff4411e30a3c","payload":{"connection_id":"f6725804f86a4c4eb588e4d5ed7db029","event_at":"2026-07-28T04:09:50.966000Z","event_type":"price_change","frame_hash":"8e1b5202aa6f2cdddeef560b542ad0cba74f0a020fdb1227b892839c18eaa23b","frame_index":0,"kind":"data","monotonic_ns":313773942991500,"payload":{"event_type":"price_change","market":"0xd412ce774cfcf8dc9f71164aac78783978aac7b03871702a3b8a481bd9dc9688","price_changes":[{"asset_id":"107603864457683460275633293642179940881969192120168665300712204232021063124301","best_ask":"0.61","best_bid":"0.6","hash":"94831e5f0140999a03beb3895f6f483ab716ead1","price":"0.59","side":"BUY","size":"66.6"},{"asset_id":"96600821790790307414914106093858868634329285205417149685270682748367152458577","best_ask":"0.4","best_bid":"0.39","hash":"4751600bc5fc6a2abab069f6aa64c16305192a15","price":"0.41","side":"SELL","size":"66.6"}],"timestamp":"1785211790966"},"payload_hash":"8a2a4e203e71ee53ad788ba33fd148db118428c3ac35d30cf650b166e8455762","raw_frame":"{\"market\":\"0xd412ce774cfcf8dc9f71164aac78783978aac7b03871702a3b8a481bd9dc9688\", \"price_changes\":[{\"asset_id\":\"107603864457683460275633293642179940881969192120168665300712204232021063124301\", \"price\":\"0.59\", \"size\":\"66.6\", \"side\":\"BUY\", \"hash\":\"94831e5f0140999a03beb3895f6f483ab716ead1\", \"best_bid\":\"0.6\", \"best_ask\":\"0.61\"}, {\"asset_id\":\"96600821790790307414914106093858868634329285205417149685270682748367152458577\", \"price\":\"0.41\", \"size\":\"66.6\", \"side\":\"SELL\", \"hash\":\"4751600bc5fc6a2abab069f6aa64c16305192a15\", \"best_bid\":\"0.39\", \"best_ask\":\"0.4\"}], \"timestamp\":\"1785211790966\", \"event_type\":\"price_change\"}","received_at":"2026-07-28T04:09:50.867250Z","schema_version":"clob-market-ws.price_change.v1","sequence":null,"server_hash":null,"server_timestamp":"1785211790966","session_id":"2d607381e3054cee91998cdf45a4231c","source":"clob_market_ws"},"received_at":"2026-07-28T04:09:50.867250Z","record_id":"179c19edba8ec54279e26ca131b1d492b3a2cb70c3f6ab1999253072cfd1b270","schema_fingerprint":"4aa3821a28b0b7c2400bc59aba4bcc0a76e971dadd19610d3ad38c768e124dc7","schema_version":"edge-lab-recorder.raw.v1","sequence":null,"source":"clob_market_ws"}
{"event_at":"2026-07-28T04:09:50.976000Z","event_fingerprint":"4c2cbf5b068222c960d3aec94b657ea7d2cfc2fa04cf51d00fd4673a7ab48db4","payload":{"connection_id":"f6725804f86a4c4eb588e4d5ed7db029","event_at":"2026-07-28T04:09:50.976000Z","event_type":"price_change","frame_hash":"b8928d1d3e46c69267d1f3f2e735f9b62ed8e508d7fe2c0b12242c08f05cf2d0","frame_index":0,"kind":"data","monotonic_ns":313773949056708,"payload":{"event_type":"price_change","market":"0xd412ce774cfcf8dc9f71164aac78783978aac7b03871702a3b8a481bd9dc9688","price_changes":[{"asset_id":"96600821790790307414914106093858868634329285205417149685270682748367152458577","best_ask":"0.4","best_bid":"0.39","hash":"683520364f45e9a782d96f256872811fe04f8992","price":"0.41","side":"SELL","size":"41.6"},{"asset_id":"107603864457683460275633293642179940881969192120168665300712204232021063124301","best_ask":"0.61","best_bid":"0.6","hash":"1bc3643813f2c7bbc3fd3b956851073122e7e155","price":"0.59","side":"BUY","size":"41.6"}],"timestamp":"1785211790976"},"payload_hash":"d72487d4c7971d8f293dc98bf1de97cc083448b1b3446d6e7f733f4b4cf9e0e4","raw_frame":"{\"market\":\"0xd412ce774cfcf8dc9f71164aac78783978aac7b03871702a3b8a481bd9dc9688\", \"price_changes\":[{\"asset_id\":\"96600821790790307414914106093858868634329285205417149685270682748367152458577\", \"price\":\"0.41\", \"size\":\"41.6\", \"side\":\"SELL\", \"hash\":\"683520364f45e9a782d96f256872811fe04f8992\", \"best_bid\":\"0.39\", \"best_ask\":\"0.4\"}, {\"asset_id\":\"107603864457683460275633293642179940881969192120168665300712204232021063124301\", \"price\":\"0.59\", \"size\":\"41.6\", \"side\":\"BUY\", \"hash\":\"1bc3643813f2c7bbc3fd3b956851073122e7e155\", \"best_bid\":\"0.6\", \"best_ask\":\"0.61\"}], \"timestamp\":\"1785211790976\", \"event_type\":\"price_change\"}","received_at":"2026-07-28T04:09:50.873315Z","schema_version":"clob-market-ws.price_change.v1","sequence":null,"server_hash":null,"server_timestamp":"1785211790976","session_id":"2d607381e3054cee91998cdf45a4231c","source":"clob_market_ws"},"received_at":"2026-07-28T04:09:50.873315Z","record_id":"cd0ed065b16959079dce7d63acd0bec63f0989b182c4fb31bc0ca03601b7232e","schema_fingerprint":"4aa3821a28b0b7c2400bc59aba4bcc0a76e971dadd19610d3ad38c768e124dc7","schema_version":"edge-lab-recorder.raw.v1","sequence":null,"source":"clob_market_ws"}
{"event_at":"2026-07-28T04:09:50.988000Z","event_fingerprint":"4c0667dd561170beb997caebfae6aff3508f0b1e01fbc7de6cd7bdae966e179c","payload":{"connection_id":"f6725804f86a4c4eb588e4d5ed7db029","event_at":"2026-07-28T04:09:50.988000Z","event_type":"price_change","frame_hash":"b678f82fe721499507e4fb00ab8be7c6ea63bfbc6bdbabf38a59408387066af0","frame_index":0,"kind":"data","monotonic_ns":313773954865666,"payload":{"event_type":"price_change","market":"0xd412ce774cfcf8dc9f71164aac78783978aac7b03871702a3b8a481bd9dc9688","price_changes":[{"asset_id":"107603864457683460275633293642179940881969192120168665300712204232021063124301","best_ask":"0.61","best_bid":"0.6","hash":"9730d73b79b40944c9082303094e60d2c2248306","price":"0.58","side":"BUY","size":"103.2"},{"asset_id":"96600821790790307414914106093858868634329285205417149685270682748367152458577","best_ask":"0.4","best_bid":"0.39","hash":"2598f5c955c50692e69d93350a183425a9746e62","price":"0.42","side":"SELL","size":"103.2"}],"timestamp":"1785211790988"},"payload_hash":"554eba7254328e2531513d999ec1ec805b23094b032285af69eb37cd7ad2684d","raw_frame":"{\"market\":\"0xd412ce774cfcf8dc9f71164aac78783978aac7b03871702a3b8a481bd9dc9688\", \"price_changes\":[{\"asset_id\":\"107603864457683460275633293642179940881969192120168665300712204232021063124301\", \"price\":\"0.58\", \"size\":\"103.2\", \"side\":\"BUY\", \"hash\":\"9730d73b79b40944c9082303094e60d2c2248306\", \"best_bid\":\"0.6\", \"best_ask\":\"0.61\"}, {\"asset_id\":\"96600821790790307414914106093858868634329285205417149685270682748367152458577\", \"price\":\"0.42\", \"size\":\"103.2\", \"side\":\"SELL\", \"hash\":\"2598f5c955c50692e69d93350a183425a9746e62\", \"best_bid\":\"0.39\", \"best_ask\":\"0.4\"}], \"timestamp\":\"1785211790988\", \"event_type\":\"price_change\"}","received_at":"2026-07-28T04:09:50.879123Z","schema_version":"clob-market-ws.price_change.v1","sequence":null,"server_hash":null,"server_timestamp":"1785211790988","session_id":"2d607381e3054cee91998cdf45a4231c","source":"clob_market_ws"},"received_at":"2026-07-28T04:09:50.879123Z","record_id":"f81318464edb7bf0bcfc1ad7157daa5994b475f5bc7d851bcf8e4eae894ff2f0","schema_fingerprint":"4aa3821a28b0b7c2400bc59aba4bcc0a76e971dadd19610d3ad38c768e124dc7","schema_version":"edge-lab-recorder.raw.v1","sequence":null,"source":"clob_market_ws"}
{"event_at":"2026-07-28T04:09:50.993000Z","event_fingerprint":"32ecaaa8ab0712a642e8a05bde6a2626c5e60757c5c11ea2319e7de858e21a85","payload":{"connection_id":"f6725804f86a4c4eb588e4d5ed7db029","event_at":"2026-07-28T04:09:50.993000Z","event_type":"price_change","frame_hash":"8ed4ab504b8d4e2e09a9468b4c3ac8ad7c759034d809f738f430528aa8489f10","frame_index":0,"kind":"data","monotonic_ns":313773959718291,"payload":{"event_type":"price_change","market":"0xd412ce774cfcf8dc9f71164aac78783978aac7b03871702a3b8a481bd9dc9688","price_changes":[{"asset_id":"107603864457683460275633293642179940881969192120168665300712204232021063124301","best_ask":"0.61","best_bid":"0.6","hash":"2cf76cf389800f7876478718ad8cbe50164e20a5","price":"0.02","side":"BUY","size":"683.1"},{"asset_id":"96600821790790307414914106093858868634329285205417149685270682748367152458577","best_ask":"0.4","best_bid":"0.39","hash":"4ba7cbffb231ea251c758606c75fe298518b6872","price":"0.98","side":"SELL","size":"683.1"}],"timestamp":"1785211790993"},"payload_hash":"687855aac516bc5950252c6cdd968ffc134bf32295a6bc2463d40a2cfc6308a6","raw_frame":"{\"market\":\"0xd412ce774cfcf8dc9f71164aac78783978aac7b03871702a3b8a481bd9dc9688\", \"price_changes\":[{\"asset_id\":\"107603864457683460275633293642179940881969192120168665300712204232021063124301\", \"price\":\"0.02\", \"size\":\"683.1\", \"side\":\"BUY\", \"hash\":\"2cf76cf389800f7876478718ad8cbe50164e20a5\", \"best_bid\":\"0.6\", \"best_ask\":\"0.61\"}, {\"asset_id\":\"96600821790790307414914106093858868634329285205417149685270682748367152458577\", \"price\":\"0.98\", \"size\":\"683.1\", \"side\":\"SELL\", \"hash\":\"4ba7cbffb231ea251c758606c75fe298518b6872\", \"best_bid\":\"0.39\", \"best_ask\":\"0.4\"}], \"timestamp\":\"1785211790993\", \"event_type\":\"price_change\"}","received_at":"2026-07-28T04:09:50.883976Z","schema_version":"clob-market-ws.price_change.v1","sequence":null,"server_hash":null,"server_timestamp":"1785211790993","session_id":"2d607381e3054cee91998cdf45a4231c","source":"clob_market_ws"},"received_at":"2026-07-28T04:09:50.883976Z","record_id":"5edae4d6574deb139ea220bfb36d23dc0eabe47bac284dec60467e079c230455","schema_fingerprint":"4aa3821a28b0b7c2400bc59aba4bcc0a76e971dadd19610d3ad38c768e124dc7","schema_version":"edge-lab-recorder.raw.v1","sequence":null,"source":"clob_market_ws"}
{"event_at":"2026-07-28T04:09:50.998000Z","event_fingerprint":"b6872885453058108034515e19163847cb295e7f1fd2baa9329b8f0b4c74a92f","payload":{"connection_id":"f6725804f86a4c4eb588e4d5ed7db029","event_at":"2026-07-28T04:09:50.998000Z","event_type":"price_change","frame_hash":"4c00c2fdace8d8495ecbd4772035d6049df7a36454fa1f6ef3ff4945ff2f4e38","frame_index":0,"kind":"data","monotonic_ns":313773964901333,"payload":{"event_type":"price_change","market":"0xd412ce774cfcf8dc9f71164aac78783978aac7b03871702a3b8a481bd9dc9688","price_changes":[{"asset_id":"96600821790790307414914106093858868634329285205417149685270682748367152458577","best_ask":"0.4","best_bid":"0.39","hash":"52145ddce2160294a8c02e8f7bafffcc3b943bac","price":"0.42","side":"SELL","size":"128.2"},{"asset_id":"107603864457683460275633293642179940881969192120168665300712204232021063124301","best_ask":"0.61","best_bid":"0.6","hash":"671796dd0df07ab83f744e521ee3d4532cb13f9a","price":"0.58","side":"BUY","size":"128.2"}],"timestamp":"1785211790998"},"payload_hash":"0d3428ec9da0f18a4fa353d93865e3f7617355e8e0cf36fe1f66ccc237247284","raw_frame":"{\"market\":\"0xd412ce774cfcf8dc9f71164aac78783978aac7b03871702a3b8a481bd9dc9688\", \"price_changes\":[{\"asset_id\":\"96600821790790307414914106093858868634329285205417149685270682748367152458577\", \"price\":\"0.42\", \"size\":\"128.2\", \"side\":\"SELL\", \"hash\":\"52145ddce2160294a8c02e8f7bafffcc3b943bac\", \"best_bid\":\"0.39\", \"best_ask\":\"0.4\"}, {\"asset_id\":\"107603864457683460275633293642179940881969192120168665300712204232021063124301\", \"price\":\"0.58\", \"size\":\"128.2\", \"side\":\"BUY\", \"hash\":\"671796dd0df07ab83f744e521ee3d4532cb13f9a\", \"best_bid\":\"0.6\", \"best_ask\":\"0.61\"}], \"timestamp\":\"1785211790998\", \"event_type\":\"price_change\"}","received_at":"2026-07-28T04:09:50.889159Z","schema_version":"clob-market-ws.price_change.v1","sequence":null,"server_hash":null,"server_timestamp":"1785211790998","session_id":"2d607381e3054cee91998cdf45a4231c","source":"clob_market_ws"},"received_at":"2026-07-28T04:09:50.889159Z","record_id":"eb5a3ecee9fb45840ef04f09e83abdbea12dcfa066ff9207c5950e7ba693f16f","schema_fingerprint":"4aa3821a28b0b7c2400bc59aba4bcc0a76e971dadd19610d3ad38c768e124dc7","schema_version":"edge-lab-recorder.raw.v1","sequence":null,"source":"clob_market_ws"}
{"event_at":"2026-07-28T04:09:51.023000Z","event_fingerprint":"288a72e474137f091bc4479fb46a51d0fd3ed91d68bd93e92a5a0d067bc7481e","payload":{"connection_id":"f6725804f86a4c4eb588e4d5ed7db029","event_at":"2026-07-28T04:09:51.023000Z","event_type":"price_change","frame_hash":"956380441d6c9fe58fd3e7ff9ba8bee1ed91ea580d2f1e82e20fdc8737330f1d","frame_index":0,"kind":"data","monotonic_ns":313773969080250,"payload":{"event_type":"price_change","market":"0xd412ce774cfcf8dc9f71164aac78783978aac7b03871702a3b8a481bd9dc9688","price_changes":[{"asset_id":"96600821790790307414914106093858868634329285205417149685270682748367152458577","best_ask":"0.4","best_bid":"0.39","hash":"3b1fadc52b7cd70af7a41a200c1e92d0fc3eb39b","price":"0.01","side":"BUY","size":"5608.02"},{"asset_id":"107603864457683460275633293642179940881969192120168665300712204232021063124301","best_ask":"0.61","best_bid":"0.6","hash":"ed8ae038b35f20c8e94ca1087da53829cf1769d4","price":"0.99","side":"SELL","size":"5608.02"}],"timestamp":"1785211791023"},"payload_hash":"878b94d2b7b68f5853cb8d33030055001924a468303146c1d074df097c89acca","raw_frame":"{\"market\":\"0xd412ce774cfcf8dc9f71164aac78783978aac7b03871702a3b8a481bd9dc9688\", \"price_changes\":[{\"asset_id\":\"96600821790790307414914106093858868634329285205417149685270682748367152458577\", \"price\":\"0.01\", \"size\":\"5608.02\", \"side\":\"BUY\", \"hash\":\"3b1fadc52b7cd70af7a41a200c1e92d0fc3eb39b\", \"best_bid\":\"0.39\", \"best_ask\":\"0.4\"}, {\"asset_id\":\"107603864457683460275633293642179940881969192120168665300712204232021063124301\", \"price\":\"0.99\", \"size\":\"5608.02\", \"side\":\"SELL\", \"hash\":\"ed8ae038b35f20c8e94ca1087da53829cf1769d4\", \"best_bid\":\"0.6\", \"best_ask\":\"0.61\"}], \"timestamp\":\"1785211791023\", \"event_type\":\"price_change\"}","received_at":"2026-07-28T04:09:50.893338Z","schema_version":"clob-market-ws.price_change.v1","sequence":null,"server_hash":null,"server_timestamp":"1785211791023","session_id":"2d607381e3054cee91998cdf45a4231c","source":"clob_market_ws"},"received_at":"2026-07-28T04:09:50.893338Z","record_id":"d4f79d4e0388cfd89ae8f632d2efbbf0d94672e086d26e2cb6b0d2b61c8b5ad8","schema_fingerprint":"4aa3821a28b0b7c2400bc59aba4bcc0a76e971dadd19610d3ad38c768e124dc7","schema_version":"edge-lab-recorder.raw.v1","sequence":null,"source":"clob_market_ws"}
{"event_at":"2026-07-28T04:09:51.028000Z","event_fingerprint":"a5d4d2c7575a36ba582075e6e59c8c095c2770ff699c2546ecb44aaadf88b1bc","payload":{"connection_id":"f6725804f86a4c4eb588e4d5ed7db029","event_at":"2026-07-28T04:09:51.028000Z","event_type":"price_change","frame_hash":"7de7d607f0f1895007b29202ed417114051972357176ccf6faf6d56d830c1a6d","frame_index":0,"kind":"data","monotonic_ns":313773974859208,"payload":{"event_type":"price_change","market":"0xd412ce774cfcf8dc9f71164aac78783978aac7b03871702a3b8a481bd9dc9688","price_changes":[{"asset_id":"96600821790790307414914106093858868634329285205417149685270682748367152458577","best_ask":"0.4","best_bid":"0.39","hash":"74ebfba841b2134ec79f79cf0440762a520f9fed","price":"0.01","side":"BUY","size":"5613.02"},{"asset_id":"107603864457683460275633293642179940881969192120168665300712204232021063124301","best_ask":"0.61","best_bid":"0.6","hash":"a6639804cd8253091da5800e5af3e4aae7069bf8","price":"0.99","side":"SELL","size":"5613.02"}],"timestamp":"1785211791028"},"payload_hash":"1c53d88b490adf423311b352025a0082c3f38544a80e0478e74ec9fede020a05","raw_frame":"{\"market\":\"0xd412ce774cfcf8dc9f71164aac78783978aac7b03871702a3b8a481bd9dc9688\", \"price_changes\":[{\"asset_id\":\"96600821790790307414914106093858868634329285205417149685270682748367152458577\", \"price\":\"0.01\", \"size\":\"5613.02\", \"side\":\"BUY\", \"hash\":\"74ebfba841b2134ec79f79cf0440762a520f9fed\", \"best_bid\":\"0.39\", \"best_ask\":\"0.4\"}, {\"asset_id\":\"107603864457683460275633293642179940881969192120168665300712204232021063124301\", \"price\":\"0.99\", \"size\":\"5613.02\", \"side\":\"SELL\", \"hash\":\"a6639804cd8253091da5800e5af3e4aae7069bf8\", \"best_bid\":\"0.6\", \"best_ask\":\"0.61\"}], \"timestamp\":\"1785211791028\", \"event_type\":\"price_change\"}","received_at":"2026-07-28T04:09:50.899115Z","schema_version":"clob-market-ws.price_change.v1","sequence":null,"server_hash":null,"server_timestamp":"1785211791028","session_id":"2d607381e3054cee91998cdf45a4231c","source":"clob_market_ws"},"received_at":"2026-07-28T04:09:50.899115Z","record_id":"48859121ea5eb0bc0f845858b95ca4bbfe504fd16f0f7fc9aeb5aaba4d7292c9","schema_fingerprint":"4aa3821a28b0b7c2400bc59aba4bcc0a76e971dadd19610d3ad38c768e124dc7","schema_version":"edge-lab-recorder.raw.v1","sequence":null,"source":"clob_market_ws"}
{"event_at":"2026-07-28T04:09:51.050000Z","event_fingerprint":"3900ee928534efd1d01725aefc5742f47949599dbd2607e20163a2520e552970","payload":{"connection_id":"f6725804f86a4c4eb588e4d5ed7db029","event_at":"2026-07-28T04:09:51.050000Z","event_type":"price_change","frame_hash":"a7f4e523b137f2ab410fa5ee322c2fbfa25f3e180b0fbf19f1d13cb9159fca15","frame_index":0,"kind":"data","monotonic_ns":313773981370541,"payload":{"event_type":"price_change","market":"0xd412ce774cfcf8dc9f71164aac78783978aac7b03871702a3b8a481bd9dc9688","price_changes":[{"asset_id":"96600821790790307414914106093858868634329285205417149685270682748367152458577","best_ask":"0.4","best_bid":"0.39","hash":"37b916e32237fac3f313edfd8a952b9096786d81","price":"0.01","side":"BUY","size":"5608.02"},{"asset_id":"107603864457683460275633293642179940881969192120168665300712204232021063124301","best_ask":"0.61","best_bid":"0.6","hash":"6916e0d57a7d19af7e32ec0ab8497228f613d762","price":"0.99","side":"SELL","size":"5608.02"}],"timestamp":"1785211791050"},"payload_hash":"d2686f21217beb75053d47a777c00917ef860401584235555ab9b1822d2b45b2","raw_frame":"{\"market\":\"0xd412ce774cfcf8dc9f71164aac78783978aac7b03871702a3b8a481bd9dc9688\", \"price_changes\":[{\"asset_id\":\"96600821790790307414914106093858868634329285205417149685270682748367152458577\", \"price\":\"0.01\", \"size\":\"5608.02\", \"side\":\"BUY\", \"hash\":\"37b916e32237fac3f313edfd8a952b9096786d81\", \"best_bid\":\"0.39\", \"best_ask\":\"0.4\"}, {\"asset_id\":\"107603864457683460275633293642179940881969192120168665300712204232021063124301\", \"price\":\"0.99\", \"size\":\"5608.02\", \"side\":\"SELL\", \"hash\":\"6916e0d57a7d19af7e32ec0ab8497228f613d762\", \"best_bid\":\"0.6\", \"best_ask\":\"0.61\"}], \"timestamp\":\"1785211791050\", \"event_type\":\"price_change\"}","received_at":"2026-07-28T04:09:50.905626Z","schema_version":"clob-market-ws.price_change.v1","sequence":null,"server_hash":null,"server_timestamp":"1785211791050","session_id":"2d607381e3054cee91998cdf45a4231c","source":"clob_market_ws"},"received_at":"2026-07-28T04:09:50.905626Z","record_id":"4c22a1e833b6996a20ae0f313b9838d5dc46ad30796f4a558ec8f1fd4e769c0b","schema_fingerprint":"4aa3821a28b0b7c2400bc59aba4bcc0a76e971dadd19610d3ad38c768e124dc7","schema_version":"edge-lab-recorder.raw.v1","sequence":null,"source":"clob_market_ws"}
{"event_at":"2026-07-28T04:09:51.064000Z","event_fingerprint":"e40419fcf31358766585aaf7e11414675595f983c0b831a885b9f39405a80b16","payload":{"connection_id":"f6725804f86a4c4eb588e4d5ed7db029","event_at":"2026-07-28T04:09:51.064000Z","event_type":"price_change","frame_hash":"4e3b1dcac7ce9b5a9108f69a10f70e489d599411f27d6a54d541a233619a7893","frame_index":0,"kind":"data","monotonic_ns":313773995908250,"payload":{"event_type":"price_change","market":"0xd412ce774cfcf8dc9f71164aac78783978aac7b03871702a3b8a481bd9dc9688","price_changes":[{"asset_id":"107603864457683460275633293642179940881969192120168665300712204232021063124301","best_ask":"0.61","best_bid":"0.6","hash":"dbc85eb11e933bdbd731f988f70912d9d23d3145","price":"0.58","side":"BUY","size":"103.2"},{"asset_id":"96600821790790307414914106093858868634329285205417149685270682748367152458577","best_ask":"0.4","best_bid":"0.39","hash":"4cdbd040b1cca3ccf37804fe12370cf4d1847c59","price":"0.42","side":"SELL","size":"103.2"}],"timestamp":"1785211791064"},"payload_hash":"66a3dcba614ffd3c837e685ef48abc3f26b98d8a3242ef7dbc60e26585dae7e2","raw_frame":"{\"market\":\"0xd412ce774cfcf8dc9f71164aac78783978aac7b03871702a3b8a481bd9dc9688\", \"price_changes\":[{\"asset_id\":\"107603864457683460275633293642179940881969192120168665300712204232021063124301\", \"price\":\"0.58\", \"size\":\"103.2\", \"side\":\"BUY\", \"hash\":\"dbc85eb11e933bdbd731f988f70912d9d23d3145\", \"best_bid\":\"0.6\", \"best_ask\":\"0.61\"}, {\"asset_id\":\"96600821790790307414914106093858868634329285205417149685270682748367152458577\", \"price\":\"0.42\", \"size\":\"103.2\", \"side\":\"SELL\", \"hash\":\"4cdbd040b1cca3ccf37804fe12370cf4d1847c59\", \"best_bid\":\"0.39\", \"best_ask\":\"0.4\"}], \"timestamp\":\"1785211791064\", \"event_type\":\"price_change\"}","received_at":"2026-07-28T04:09:50.920164Z","schema_version":"clob-market-ws.price_change.v1","sequence":null,"server_hash":null,"server_timestamp":"1785211791064","session_id":"2d607381e3054cee91998cdf45a4231c","source":"clob_market_ws"},"received_at":"2026-07-28T04:09:50.920164Z","record_id":"5596a80d7d66c7d315b14406f224c6f170b9eb09346081be0adfde1f3d75b20a","schema_fingerprint":"4aa3821a28b0b7c2400bc59aba4bcc0a76e971dadd19610d3ad38c768e124dc7","schema_version":"edge-lab-recorder.raw.v1","sequence":null,"source":"clob_market_ws"}
{"event_at":"2026-07-28T04:09:51.065000Z","event_fingerprint":"c1229a787cb903b48d4e8f6c31e5a58262879ed665b2a4dc12e71d49bb2b3e33","payload":{"connection_id":"f6725804f86a4c4eb588e4d5ed7db029","event_at":"2026-07-28T04:09:51.065000Z","event_type":"price_change","frame_hash":"a15761b53be013509054b137e8250f4b4acd0b1f5af4393f38a66e3a734a11b2","frame_index":0,"kind":"data","monotonic_ns":313773999736541,"payload":{"event_type":"price_change","market":"0xd412ce774cfcf8dc9f71164aac78783978aac7b03871702a3b8a481bd9dc9688","price_changes":[{"asset_id":"96600821790790307414914106093858868634329285205417149685270682748367152458577","best_ask":"0.4","best_bid":"0.39","hash":"fc0817d4ebaa2bb25c50961337afb40c43320431","price":"0.42","side":"SELL","size":"78.2"},{"asset_id":"107603864457683460275633293642179940881969192120168665300712204232021063124301","best_ask":"0.61","best_bid":"0.6","hash":"4450530ed5db9f2641849cbd00f66d2cad165497","price":"0.58","side":"BUY","size":"78.2"}],"timestamp":"1785211791065"},"payload_hash":"42978373669cf633694e67809e938768886d1fbc7ee8c6ebba0d3b645923d728","raw_frame":"{\"market\":\"0xd412ce774cfcf8dc9f71164aac78783978aac7b03871702a3b8a481bd9dc9688\", \"price_changes\":[{\"asset_id\":\"96600821790790307414914106093858868634329285205417149685270682748367152458577\", \"price\":\"0.42\", \"size\":\"78.2\", \"side\":\"SELL\", \"hash\":\"fc0817d4ebaa2bb25c50961337afb40c43320431\", \"best_bid\":\"0.39\", \"best_ask\":\"0.4\"}, {\"asset_id\":\"107603864457683460275633293642179940881969192120168665300712204232021063124301\", \"price\":\"0.58\", \"size\":\"78.2\", \"side\":\"BUY\", \"hash\":\"4450530ed5db9f2641849cbd00f66d2cad165497\", \"best_bid\":\"0.6\", \"best_ask\":\"0.61\"}], \"timestamp\":\"1785211791065\", \"event_type\":\"price_change\"}","received_at":"2026-07-28T04:09:50.923993Z","schema_version":"clob-market-ws.price_change.v1","sequence":null,"server_hash":null,"server_timestamp":"1785211791065","session_id":"2d607381e3054cee91998cdf45a4231c","source":"clob_market_ws"},"received_at":"2026-07-28T04:09:50.923993Z","record_id":"1d807a9c4de8b953f8df6c9f4cc06b68bfed1484d3344798e1c36ca652937746","schema_fingerprint":"4aa3821a28b0b7c2400bc59aba4bcc0a76e971dadd19610d3ad38c768e124dc7","schema_version":"edge-lab-recorder.raw.v1","sequence":null,"source":"clob_market_ws"}
{"event_at":"2026-07-28T04:09:51.077000Z","event_fingerprint":"a7dcb0f056e632c3e8b265768ba1535085d784751735fd3d3887885203d2f903","payload":{"connection_id":"f6725804f86a4c4eb588e4d5ed7db029","event_at":"2026-07-28T04:09:51.077000Z","event_type":"price_change","frame_hash":"9cefd7c8194d3d55557f8a6a826df1d411e865e2721a8249e1241a6150cd8411","frame_index":0,"kind":"data","monotonic_ns":313774002374666,"payload":{"event_type":"price_change","market":"0xd412ce774cfcf8dc9f71164aac78783978aac7b03871702a3b8a481bd9dc9688","price_changes":[{"asset_id":"107603864457683460275633293642179940881969192120168665300712204232021063124301","best_ask":"0.61","best_bid":"0.6","hash":"62aafe82922cb5677f7c5651391b56107bfb0905","price":"0.03","side":"BUY","size":"618.1"},{"asset_id":"96600821790790307414914106093858868634329285205417149685270682748367152458577","best_ask":"0.4","best_bid":"0.39","hash":"69fcd6723dcbe1f74818bffa0a1ba1696b2b0c16","price":"0.97","side":"SELL","size":"618.1"}],"timestamp":"1785211791077"},"payload_hash":"8b1a9ecc6422d2f64a2021783880e5f314e9d21de0af364e458d2d744542a078","raw_frame":"{\"market\":\"0xd412ce774cfcf8dc9f71164aac78783978aac7b03871702a3b8a481bd9dc9688\", \"price_changes\":[{\"asset_id\":\"107603864457683460275633293642179940881969192120168665300712204232021063124301\", \"price\":\"0.03\", \"size\":\"618.1\", \"side\":\"BUY\", \"hash\":\"62aafe82922cb5677f7c5651391b56107bfb0905\", \"best_bid\":\"0.6\", \"best_ask\":\"0.61\"}, {\"asset_id\":\"96600821790790307414914106093858868634329285205417149685270682748367152458577\", \"price\":\"0.97\", \"size\":\"618.1\", \"side\":\"SELL\", \"hash\":\"69fcd6723dcbe1f74818bffa0a1ba1696b2b0c16\", \"best_bid\":\"0.39\", \"best_ask\":\"0.4\"}], \"timestamp\":\"1785211791077\", \"event_type\":\"price_change\"}","received_at":"2026-07-28T04:09:50.926632Z","schema_version":"clob-market-ws.price_change.v1","sequence":null,"server_hash":null,"server_timestamp":"1785211791077","session_id":"2d607381e3054cee91998cdf45a4231c","source":"clob_market_ws"},"received_at":"2026-07-28T04:09:50.926632Z","record_id":"7814ce647f0cff247206dad65854ea941ece146150a1fa0c6155ff5db32a9400","schema_fingerprint":"4aa3821a28b0b7c2400bc59aba4bcc0a76e971dadd19610d3ad38c768e124dc7","schema_version":"edge-lab-recorder.raw.v1","sequence":null,"source":"clob_market_ws"}
{"event_at":"2026-07-28T04:09:51.127000Z","event_fingerprint":"a43f688653df2ad334c7ad8e3de2420f7a2c5696ce71b0bcfefe84859d443c63","payload":{"connection_id":"f6725804f86a4c4eb588e4d5ed7db029","event_at":"2026-07-28T04:09:51.127000Z","event_type":"price_change","frame_hash":"199d32fae176fda8a9149ba70132200ad9b3b79d449c4a57238d03048facb538","frame_index":0,"kind":"data","monotonic_ns":313774006123875,"payload":{"event_type":"price_change","market":"0xd412ce774cfcf8dc9f71164aac78783978aac7b03871702a3b8a481bd9dc9688","price_changes":[{"asset_id":"96600821790790307414914106093858868634329285205417149685270682748367152458577","best_ask":"0.4","best_bid":"0.39","hash":"31a2c20b6fc423b2207f8490748fc2799518bb9b","price":"0.01","side":"BUY","size":"5603.02"},{"asset_id":"107603864457683460275633293642179940881969192120168665300712204232021063124301","best_ask":"0.61","best_bid":"0.6","hash":"53a11c9673f6b3f1fbe85b7174d58a8c6b166dc6","price":"0.99","side":"SELL","size":"5603.02"}],"timestamp":"1785211791127"},"payload_hash":"0b092daad9eeb0a9330357d19d6dc04af7082e75c0635d3893c8c27b752e5124","raw_frame":"{\"market\":\"0xd412ce774cfcf8dc9f71164aac78783978aac7b03871702a3b8a481bd9dc9688\", \"price_changes\":[{\"asset_id\":\"96600821790790307414914106093858868634329285205417149685270682748367152458577\", \"price\":\"0.01\", \"size\":\"5603.02\", \"side\":\"BUY\", \"hash\":\"31a2c20b6fc423b2207f8490748fc2799518bb9b\", \"best_bid\":\"0.39\", \"best_ask\":\"0.4\"}, {\"asset_id\":\"107603864457683460275633293642179940881969192120168665300712204232021063124301\", \"price\":\"0.99\", \"size\":\"5603.02\", \"side\":\"SELL\", \"hash\":\"53a11c9673f6b3f1fbe85b7174d58a8c6b166dc6\", \"best_bid\":\"0.6\", \"best_ask\":\"0.61\"}], \"timestamp\":\"1785211791127\", \"event_type\":\"price_change\"}","received_at":"2026-07-28T04:09:50.930381Z","schema_version":"clob-market-ws.price_change.v1","sequence":null,"server_hash":null,"server_timestamp":"1785211791127","session_id":"2d607381e3054cee91998cdf45a4231c","source":"clob_market_ws"},"received_at":"2026-07-28T04:09:50.930381Z","record_id":"987e96a155cf49beac3ef72b08a94eb975ddad8bd1dda82df52ba97327fe27f5","schema_fingerprint":"4aa3821a28b0b7c2400bc59aba4bcc0a76e971dadd19610d3ad38c768e124dc7","schema_version":"edge-lab-recorder.raw.v1","sequence":null,"source":"clob_market_ws"}
{"event_at":"2026-07-28T04:09:51.151000Z","event_fingerprint":"b1c655feed92b2bdc04cdb3c89e3e28eb3390784bf23706f5511f23c87323990","payload":{"connection_id":"f6725804f86a4c4eb588e4d5ed7db029","event_at":"2026-07-28T04:09:51.151000Z","event_type":"price_change","frame_hash":"70a914ad0d4b5eadd98a625080adedecef6b436ccfad3174e1b529a34f2bc26a","frame_index":0,"kind":"data","monotonic_ns":313774010435250,"payload":{"event_type":"price_change","market":"0xd412ce774cfcf8dc9f71164aac78783978aac7b03871702a3b8a481bd9dc9688","price_changes":[{"asset_id":"107603864457683460275633293642179940881969192120168665300712204232021063124301","best_ask":"0.61","best_bid":"0.6","hash":"4a30972ad0b9b258608c969f0a1f12f91ddc64b1","price":"0.03","side":"BUY","size":"613.1"},{"asset_id":"96600821790790307414914106093858868634329285205417149685270682748367152458577","best_ask":"0.4","best_bid":"0.39","hash":"b18d8e79d8838c107c6ee6e1c6534c94703ff12f","price":"0.97","side":"SELL","size":"613.1"}],"timestamp":"1785211791151"},"payload_hash":"7eb975d175ed34cc9d30de40c36f65b33332980d8b4af12be260a9e7c6ec3ca0","raw_frame":"{\"market\":\"0xd412ce774cfcf8dc9f71164aac78783978aac7b03871702a3b8a481bd9dc9688\", \"price_changes\":[{\"asset_id\":\"107603864457683460275633293642179940881969192120168665300712204232021063124301\", \"price\":\"0.03\", \"size\":\"613.1\", \"side\":\"BUY\", \"hash\":\"4a30972ad0b9b258608c969f0a1f12f91ddc64b1\", \"best_bid\":\"0.6\", \"best_ask\":\"0.61\"}, {\"asset_id\":\"96600821790790307414914106093858868634329285205417149685270682748367152458577\", \"price\":\"0.97\", \"size\":\"613.1\", \"side\":\"SELL\", \"hash\":\"b18d8e79d8838c107c6ee6e1c6534c94703ff12f\", \"best_bid\":\"0.39\", \"best_ask\":\"0.4\"}], \"timestamp\":\"1785211791151\", \"event_type\":\"price_change\"}","received_at":"2026-07-28T04:09:50.934692Z","schema_version":"clob-market-ws.price_change.v1","sequence":null,"server_hash":null,"server_timestamp":"1785211791151","session_id":"2d607381e3054cee91998cdf45a4231c","source":"clob_market_ws"},"received_at":"2026-07-28T04:09:50.934692Z","record_id":"70c283199549a7212c21f47580b181f0e846bb5784bfc439ae5ffe4b8d262bf1","schema_fingerprint":"4aa3821a28b0b7c2400bc59aba4bcc0a76e971dadd19610d3ad38c768e124dc7","schema_version":"edge-lab-recorder.raw.v1","sequence":null,"source":"clob_market_ws"}
{"event_at":"2026-07-28T04:09:51.169000Z","event_fingerprint":"d6fb613c892ab54f8ab05f0f7b1c9a8ae23e447123d3f7e4215723a77c7404fb","payload":{"connection_id":"f6725804f86a4c4eb588e4d5ed7db029","event_at":"2026-07-28T04:09:51.169000Z","event_type":"price_change","frame_hash":"725a211121ed9eb4ceac16f3fb8744f7a0afbe940e63afe9382c3c9ca2777c51","frame_index":0,"kind":"data","monotonic_ns":313774018779666,"payload":{"event_type":"price_change","market":"0xd412ce774cfcf8dc9f71164aac78783978aac7b03871702a3b8a481bd9dc9688","price_changes":[{"asset_id":"96600821790790307414914106093858868634329285205417149685270682748367152458577","best_ask":"0.4","best_bid":"0.39","hash":"c69214f53a82e05d24bf00fecc52f751b0a8abb1","price":"0.29","side":"BUY","size":"126.91"},{"asset_id":"107603864457683460275633293642179940881969192120168665300712204232021063124301","best_ask":"0.61","best_bid":"0.6","hash":"826fdb6e4ee7c0bf894d80b6e79189fc8993727d","price":"0.71","side":"SELL","size":"126.91"}],"timestamp":"1785211791169"},"payload_hash":"39d0957c7f789ecb8d84c132d46d56cbb00dbcedb26a276f92d04baee171147c","raw_frame":"{\"market\":\"0xd412ce774cfcf8dc9f71164aac78783978aac7b03871702a3b8a481bd9dc9688\", \"price_changes\":[{\"asset_id\":\"96600821790790307414914106093858868634329285205417149685270682748367152458577\", \"price\":\"0.29\", \"size\":\"126.91\", \"side\":\"BUY\", \"hash\":\"c69214f53a82e05d24bf00fecc52f751b0a8abb1\", \"best_bid\":\"0.39\", \"best_ask\":\"0.4\"}, {\"asset_id\":\"107603864457683460275633293642179940881969192120168665300712204232021063124301\", \"price\":\"0.71\", \"size\":\"126.91\", \"side\":\"SELL\", \"hash\":\"826fdb6e4ee7c0bf894d80b6e79189fc8993727d\", \"best_bid\":\"0.6\", \"best_ask\":\"0.61\"}], \"timestamp\":\"1785211791169\", \"event_type\":\"price_change\"}","received_at":"2026-07-28T04:09:50.943035Z","schema_version":"clob-market-ws.price_change.v1","sequence":null,"server_hash":null,"server_timestamp":"1785211791169","session_id":"2d607381e3054cee91998cdf45a4231c","source":"clob_market_ws"},"received_at":"2026-07-28T04:09:50.943035Z","record_id":"a3b7c741526ccecdd9a83de3157feb94b4806e8ddbf4eece71500a919d142915","schema_fingerprint":"4aa3821a28b0b7c2400bc59aba4bcc0a76e971dadd19610d3ad38c768e124dc7","schema_version":"edge-lab-recorder.raw.v1","sequence":null,"source":"clob_market_ws"}
{"event_at":"2026-07-28T04:09:51.205000Z","event_fingerprint":"f6b3fceed7c771b262280d3dba0afabf4665872d124b9703d2e88fedeaf667ed","payload":{"connection_id":"f6725804f86a4c4eb588e4d5ed7db029","event_at":"2026-07-28T04:09:51.205000Z","event_type":"price_change","frame_hash":"d6315b90a79b4e99fa0babd22533f6e6234a424dc69a1c3165ac2bf23b340dba","frame_index":0,"kind":"data","monotonic_ns":313774058086125,"payload":{"event_type":"price_change","market":"0xd412ce774cfcf8dc9f71164aac78783978aac7b03871702a3b8a481bd9dc9688","price_changes":[{"asset_id":"107603864457683460275633293642179940881969192120168665300712204232021063124301","best_ask":"0.61","best_bid":"0.6","hash":"f2720e0cddc4c42f17d19044d4ecfa1b1c6298e4","price":"0.38","side":"BUY","size":"42.7"},{"asset_id":"96600821790790307414914106093858868634329285205417149685270682748367152458577","best_ask":"0.4","best_bid":"0.39","hash":"94e9f49dac2f95373e96f284954db42806e682b9","price":"0.62","side":"SELL","size":"42.7"}],"timestamp":"1785211791205"},"payload_hash":"9d8e1046ed0c8bfb5f778d81b882f5889ebf2c34f293a15d673ebb3b3144a557","raw_frame":"{\"market\":\"0xd412ce774cfcf8dc9f71164aac78783978aac7b03871702a3b8a481bd9dc9688\", \"price_changes\":[{\"asset_id\":\"107603864457683460275633293642179940881969192120168665300712204232021063124301\", \"price\":\"0.38\", \"size\":\"42.7\", \"side\":\"BUY\", \"hash\":\"f2720e0cddc4c42f17d19044d4ecfa1b1c6298e4\", \"best_bid\":\"0.6\", \"best_ask\":\"0.61\"}, {\"asset_id\":\"96600821790790307414914106093858868634329285205417149685270682748367152458577\", \"price\":\"0.62\", \"size\":\"42.7\", \"side\":\"SELL\", \"hash\":\"94e9f49dac2f95373e96f284954db42806e682b9\", \"best_bid\":\"0.39\", \"best_ask\":\"0.4\"}], \"timestamp\":\"1785211791205\", \"event_type\":\"price_change\"}","received_at":"2026-07-28T04:09:50.982341Z","schema_version":"clob-market-ws.price_change.v1","sequence":null,"server_hash":null,"server_timestamp":"1785211791205","session_id":"2d607381e3054cee91998cdf45a4231c","source":"clob_market_ws"},"received_at":"2026-07-28T04:09:50.982341Z","record_id":"06fb3c068159ae45ee5c30435f0c19bfd561a502b3e6a8aa41edf4289e3ffc96","schema_fingerprint":"4aa3821a28b0b7c2400bc59aba4bcc0a76e971dadd19610d3ad38c768e124dc7","schema_version":"edge-lab-recorder.raw.v1","sequence":null,"source":"clob_market_ws"}
{"event_at":"2026-07-28T04:09:51.206000Z","event_fingerprint":"22363ed533449f00c19f1b2f8f6824b8d29f4bf323528a43ca86f9afdd93a77d","payload":{"connection_id":"f6725804f86a4c4eb588e4d5ed7db029","event_at":"2026-07-28T04:09:51.206000Z","event_type":"price_change","frame_hash":"dd9b94684538130a3d86872daa1fd9a8ae49bb96a418adb015f6548e119e575a","frame_index":0,"kind":"data","monotonic_ns":313774062079333,"payload":{"event_type":"price_change","market":"0xd412ce774cfcf8dc9f71164aac78783978aac7b03871702a3b8a481bd9dc9688","price_changes":[{"asset_id":"96600821790790307414914106093858868634329285205417149685270682748367152458577","best_ask":"0.4","best_bid":"0.39","hash":"7174a9c9db6d0bc197164ae251e4a4fe24f59367","price":"0.3","side":"BUY","size":"267.3"},{"asset_id":"107603864457683460275633293642179940881969192120168665300712204232021063124301","best_ask":"0.61","best_bid":"0.6","hash":"1865f8c43227f74ab5d993cf4258ac33e823be15","price":"0.7","side":"SELL","size":"267.3"}],"timestamp":"1785211791206"},"payload_hash":"92493ce69152ee054bb0ab3a8af34d91db83f4d89b3fc5348d84bb1d330c5feb","raw_frame":"{\"market\":\"0xd412ce774cfcf8dc9f71164aac78783978aac7b03871702a3b8a481bd9dc9688\", \"price_changes\":[{\"asset_id\":\"96600821790790307414914106093858868634329285205417149685270682748367152458577\", \"price\":\"0.3\", \"size\":\"267.3\", \"side\":\"BUY\", \"hash\":\"7174a9c9db6d0bc197164ae251e4a4fe24f59367\", \"best_bid\":\"0.39\", \"best_ask\":\"0.4\"}, {\"asset_id\":\"107603864457683460275633293642179940881969192120168665300712204232021063124301\", \"price\":\"0.7\", \"size\":\"267.3\", \"side\":\"SELL\", \"hash\":\"1865f8c43227f74ab5d993cf4258ac33e823be15\", \"best_bid\":\"0.6\", \"best_ask\":\"0.61\"}], \"timestamp\":\"1785211791206\", \"event_type\":\"price_change\"}","received_at":"2026-07-28T04:09:50.986336Z","schema_version":"clob-market-ws.price_change.v1","sequence":null,"server_hash":null,"server_timestamp":"1785211791206","session_id":"2d607381e3054cee91998cdf45a4231c","source":"clob_market_ws"},"received_at":"2026-07-28T04:09:50.986336Z","record_id":"ff38a6d57ca842e4f077d3e94864ebfda996de28ea915607415189636af2339d","schema_fingerprint":"4aa3821a28b0b7c2400bc59aba4bcc0a76e971dadd19610d3ad38c768e124dc7","schema_version":"edge-lab-recorder.raw.v1","sequence":null,"source":"clob_market_ws"}
{"event_at":"2026-07-28T04:09:51.207000Z","event_fingerprint":"03e71ed87c789020599e370d5b27d17db9ee22f4f8ea07ebb5caf768027c2d74","payload":{"connection_id":"f6725804f86a4c4eb588e4d5ed7db029","event_at":"2026-07-28T04:09:51.207000Z","event_type":"price_change","frame_hash":"b3c421d5fa1f92dc710750f5248e185ffa59045280762cdeff43cee49e23b9ac","frame_index":0,"kind":"data","monotonic_ns":313774070706916,"payload":{"event_type":"price_change","market":"0xd412ce774cfcf8dc9f71164aac78783978aac7b03871702a3b8a481bd9dc9688","price_changes":[{"asset_id":"96600821790790307414914106093858868634329285205417149685270682748367152458577","best_ask":"0.4","best_bid":"0.39","hash":"0d7254f5f18a61d67cebdd0c57f5fc7ed5240ace","price":"0.34","side":"BUY","size":"237.19"},{"asset_id":"107603864457683460275633293642179940881969192120168665300712204232021063124301","best_ask":"0.61","best_bid":"0.6","hash":"6a119ee397a9631ec6a375ad76f137d79c729754","price":"0.66","side":"SELL","size":"237.19"}],"timestamp":"1785211791207"},"payload_hash":"17d7412a06632b9cc2f3b28f218c76068801c23643fb21cd1773271f81bfbe05","raw_frame":"{\"market\":\"0xd412ce774cfcf8dc9f71164aac78783978aac7b03871702a3b8a481bd9dc9688\", \"price_changes\":[{\"asset_id\":\"96600821790790307414914106093858868634329285205417149685270682748367152458577\", \"price\":\"0.34\", \"size\":\"237.19\", \"side\":\"BUY\", \"hash\":\"0d7254f5f18a61d67cebdd0c57f5fc7ed5240ace\", \"best_bid\":\"0.39\", \"best_ask\":\"0.4\"}, {\"asset_id\":\"107603864457683460275633293642179940881969192120168665300712204232021063124301\", \"price\":\"0.66\", \"size\":\"237.19\", \"side\":\"SELL\", \"hash\":\"6a119ee397a9631ec6a375ad76f137d79c729754\", \"best_bid\":\"0.6\", \"best_ask\":\"0.61\"}], \"timestamp\":\"1785211791207\", \"event_type\":\"price_change\"}","received_at":"2026-07-28T04:09:50.994963Z","schema_version":"clob-market-ws.price_change.v1","sequence":null,"server_hash":null,"server_timestamp":"1785211791207","session_id":"2d607381e3054cee91998cdf45a4231c","source":"clob_market_ws"},"received_at":"2026-07-28T04:09:50.994963Z","record_id":"eafcb125a35f56d700aec42fef490a9470fdc7705856eee83bd0355d2704fb6c","schema_fingerprint":"4aa3821a28b0b7c2400bc59aba4bcc0a76e971dadd19610d3ad38c768e124dc7","schema_version":"edge-lab-recorder.raw.v1","sequence":null,"source":"clob_market_ws"}
{"event_at":"2026-07-28T04:09:51.208000Z","event_fingerprint":"4235a42a07eb58d1b29cf5da5eb2099d14a3cba66c96d36f5138660ba9ba2188","payload":{"connection_id":"f6725804f86a4c4eb588e4d5ed7db029","event_at":"2026-07-28T04:09:51.208000Z","event_type":"price_change","frame_hash":"75d37cbf6bb7faa65d4bfa80f5421b02da8a0e8a071089b9de038de4a2ef529c","frame_index":0,"kind":"data","monotonic_ns":313774074806375,"payload":{"event_type":"price_change","market":"0xd412ce774cfcf8dc9f71164aac78783978aac7b03871702a3b8a481bd9dc9688","price_changes":[{"asset_id":"96600821790790307414914106093858868634329285205417149685270682748367152458577","best_ask":"0.4","best_bid":"0.39","hash":"818ff87deb714aedf5de409ab70bf806883503c4","price":"0.39","side":"BUY","size":"96.2"},{"asset_id":"107603864457683460275633293642179940881969192120168665300712204232021063124301","best_ask":"0.61","best_bid":"0.6","hash":"1f7f455846ecade149541ca486e72f91d5c37964","price":"0.61","side":"SELL","size":"96.2"}],"timestamp":"1785211791208"},"payload_hash":"5a4578c8131baa15658945ffd13a3af5c785d33dc745e7c7b3eb66f6b5955759","raw_frame":"{\"market\":\"0xd412ce774cfcf8dc9f71164aac78783978aac7b03871702a3b8a481bd9dc9688\", \"price_changes\":[{\"asset_id\":\"96600821790790307414914106093858868634329285205417149685270682748367152458577\", \"price\":\"0.39\", \"size\":\"96.2\", \"side\":\"BUY\", \"hash\":\"818ff87deb714aedf5de409ab70bf806883503c4\", \"best_bid\":\"0.39\", \"best_ask\":\"0.4\"}, {\"asset_id\":\"107603864457683460275633293642179940881969192120168665300712204232021063124301\", \"price\":\"0.61\", \"size\":\"96.2\", \"side\":\"SELL\", \"hash\":\"1f7f455846ecade149541ca486e72f91d5c37964\", \"best_bid\":\"0.6\", \"best_ask\":\"0.61\"}], \"timestamp\":\"1785211791208\", \"event_type\":\"price_change\"}","received_at":"2026-07-28T04:09:50.999058Z","schema_version":"clob-market-ws.price_change.v1","sequence":null,"server_hash":null,"server_timestamp":"1785211791208","session_id":"2d607381e3054cee91998cdf45a4231c","source":"clob_market_ws"},"received_at":"2026-07-28T04:09:50.999058Z","record_id":"dd59399937a24c149f1f4b6123292af3e738fa102875083d6de5a3d58e3f776d","schema_fingerprint":"4aa3821a28b0b7c2400bc59aba4bcc0a76e971dadd19610d3ad38c768e124dc7","schema_version":"edge-lab-recorder.raw.v1","sequence":null,"source":"clob_market_ws"}
{"event_at":"2026-07-28T04:09:51.214000Z","event_fingerprint":"16fb8b612a0fb9eb30b8bb7eae55f671a5c67118ed37db363e3fbf55eb2a5670","payload":{"connection_id":"f6725804f86a4c4eb588e4d5ed7db029","event_at":"2026-07-28T04:09:51.214000Z","event_type":"price_change","frame_hash":"8c492ca5cd4f26c6020d6094af8d87e05ad1e974f77836e33f6223eec9676c3b","frame_index":0,"kind":"data","monotonic_ns":313774083955166,"payload":{"event_type":"price_change","market":"0xd412ce774cfcf8dc9f71164aac78783978aac7b03871702a3b8a481bd9dc9688","price_changes":[{"asset_id":"96600821790790307414914106093858868634329285205417149685270682748367152458577","best_ask":"0.4","best_bid":"0.39","hash":"2f2903ccc3308dd38d1187a0c5dc3bc9cc43849d","price":"0.39","side":"BUY","size":"102.2"},{"asset_id":"107603864457683460275633293642179940881969192120168665300712204232021063124301","best_ask":"0.61","best_bid":"0.6","hash":"4ada896f03edf614bd307aca3ad9f3fd173bad53","price":"0.61","side":"SELL","size":"102.2"}],"timestamp":"1785211791214"},"payload_hash":"e676153d7e699b7a0cd7b4c672cc92980d3591cf2511b19ac24bbbb988adba01","raw_frame":"{\"market\":\"0xd412ce774cfcf8dc9f71164aac78783978aac7b03871702a3b8a481bd9dc9688\", \"price_changes\":[{\"asset_id\":\"96600821790790307414914106093858868634329285205417149685270682748367152458577\", \"price\":\"0.39\", \"size\":\"102.2\", \"side\":\"BUY\", \"hash\":\"2f2903ccc3308dd38d1187a0c5dc3bc9cc43849d\", \"best_bid\":\"0.39\", \"best_ask\":\"0.4\"}, {\"asset_id\":\"107603864457683460275633293642179940881969192120168665300712204232021063124301\", \"price\":\"0.61\", \"size\":\"102.2\", \"side\":\"SELL\", \"hash\":\"4ada896f03edf614bd307aca3ad9f3fd173bad53\", \"best_bid\":\"0.6\", \"best_ask\":\"0.61\"}], \"timestamp\":\"1785211791214\", \"event_type\":\"price_change\"}","received_at":"2026-07-28T04:09:51.008209Z","schema_version":"clob-market-ws.price_change.v1","sequence":null,"server_hash":null,"server_timestamp":"1785211791214","session_id":"2d607381e3054cee91998cdf45a4231c","source":"clob_market_ws"},"received_at":"2026-07-28T04:09:51.008209Z","record_id":"03dbeb86f3625869990fd59008180e27a52915888e1969a0de53c32a17e44713","schema_fingerprint":"4aa3821a28b0b7c2400bc59aba4bcc0a76e971dadd19610d3ad38c768e124dc7","schema_version":"edge-lab-recorder.raw.v1","sequence":null,"source":"clob_market_ws"}
{"event_at":"2026-07-28T04:09:51.229000Z","event_fingerprint":"e17fe90fedc76be67e41a5692a6b26d1048ee43013d5ebdcf9b9999937cac776","payload":{"connection_id":"f6725804f86a4c4eb588e4d5ed7db029","event_at":"2026-07-28T04:09:51.229000Z","event_type":"price_change","frame_hash":"b31fbc9d3007bdfc9aa6b47ab3052a6904a1daba97e4a32e1af27d94e1bf8559","frame_index":0,"kind":"data","monotonic_ns":313774090015708,"payload":{"event_type":"price_change","market":"0xd412ce774cfcf8dc9f71164aac78783978aac7b03871702a3b8a481bd9dc9688","price_changes":[{"asset_id":"107603864457683460275633293642179940881969192120168665300712204232021063124301","best_ask":"0.61","best_bid":"0.6","hash":"49e2370e181b2b76847f863da4ae9494d44af66f","price":"0.01","side":"BUY","size":"5638.02"},{"asset_id":"96600821790790307414914106093858868634329285205417149685270682748367152458577","best_ask":"0.4","best_bid":"0.39","hash":"65b554cf0eb3cf4b864bac72877297bf3e782b65","price":"0.99","side":"SELL","size":"5638.02"}],"timestamp":"1785211791229"},"payload_hash":"1c1f9d9cc7584391c47ea3f4410a7786b49d875fb176be921b8626c9d3a42bbc","raw_frame":"{\"market\":\"0xd412ce774cfcf8dc9f71164aac78783978aac7b03871702a3b8a481bd9dc9688\", \"price_changes\":[{\"asset_id\":\"107603864457683460275633293642179940881969192120168665300712204232021063124301\", \"price\":\"0.01\", \"size\":\"5638.02\", \"side\":\"BUY\", \"hash\":\"49e2370e181b2b76847f863da4ae9494d44af66f\", \"best_bid\":\"0.6\", \"best_ask\":\"0.61\"}, {\"asset_id\":\"96600821790790307414914106093858868634329285205417149685270682748367152458577\", \"price\":\"0.99\", \"size\":\"5638.02\", \"side\":\"SELL\", \"hash\":\"65b554cf0eb3cf4b864bac72877297bf3e782b65\", \"best_bid\":\"0.39\", \"best_ask\":\"0.4\"}], \"timestamp\":\"1785211791229\", \"event_type\":\"price_change\"}","received_at":"2026-07-28T04:09:51.014270Z","schema_version":"clob-market-ws.price_change.v1","sequence":null,"server_hash":null,"server_timestamp":"1785211791229","session_id":"2d607381e3054cee91998cdf45a4231c","source":"clob_market_ws"},"received_at":"2026-07-28T04:09:51.014270Z","record_id":"eb84ee718f8e3485a9d114ffd8a3bce490cb083aa8702226009d6d17c79ca62a","schema_fingerprint":"4aa3821a28b0b7c2400bc59aba4bcc0a76e971dadd19610d3ad38c768e124dc7","schema_version":"edge-lab-recorder.raw.v1","sequence":null,"source":"clob_market_ws"}
{"event_at":"2026-07-28T04:09:51.278000Z","event_fingerprint":"ecae1557f289a88ae2d02d0e2a1a342f831ca6e7f9b530e6d7b6a2fa81d7759e","payload":{"connection_id":"f6725804f86a4c4eb588e4d5ed7db029","event_at":"2026-07-28T04:09:51.278000Z","event_type":"price_change","frame_hash":"e5d4c5588b1478f2955c40eec0fc43f4611bb3dceb31ca551962885dcd3b3771","frame_index":0,"kind":"data","monotonic_ns":313774129735166,"payload":{"event_type":"price_change","market":"0xd412ce774cfcf8dc9f71164aac78783978aac7b03871702a3b8a481bd9dc9688","price_changes":[{"asset_id":"107603864457683460275633293642179940881969192120168665300712204232021063124301","best_ask":"0.61","best_bid":"0.6","hash":"01ca10e5a5fa11f0646e18c31e472cf084d71059","price":"0.01","side":"BUY","size":"5643.02"},{"asset_id":"96600821790790307414914106093858868634329285205417149685270682748367152458577","best_ask":"0.4","best_bid":"0.39","hash":"27e77d3210391cf33a8431b86508b91f260fc518","price":"0.99","side":"SELL","size":"5643.02"}],"timestamp":"1785211791278"},"payload_hash":"df69db95527d09563c2428d227afc8d2bcc0914f1d828c6fc7010dc6a5ea9b8d","raw_frame":"{\"market\":\"0xd412ce774cfcf8dc9f71164aac78783978aac7b03871702a3b8a481bd9dc9688\", \"price_changes\":[{\"asset_id\":\"107603864457683460275633293642179940881969192120168665300712204232021063124301\", \"price\":\"0.01\", \"size\":\"5643.02\", \"side\":\"BUY\", \"hash\":\"01ca10e5a5fa11f0646e18c31e472cf084d71059\", \"best_bid\":\"0.6\", \"best_ask\":\"0.61\"}, {\"asset_id\":\"96600821790790307414914106093858868634329285205417149685270682748367152458577\", \"price\":\"0.99\", \"size\":\"5643.02\", \"side\":\"SELL\", \"hash\":\"27e77d3210391cf33a8431b86508b91f260fc518\", \"best_bid\":\"0.39\", \"best_ask\":\"0.4\"}], \"timestamp\":\"1785211791278\", \"event_type\":\"price_change\"}","received_at":"2026-07-28T04:09:51.053991Z","schema_version":"clob-market-ws.price_change.v1","sequence":null,"server_hash":null,"server_timestamp":"1785211791278","session_id":"2d607381e3054cee91998cdf45a4231c","source":"clob_market_ws"},"received_at":"2026-07-28T04:09:51.053991Z","record_id":"2cbff005cb0d5335bc37c31aff60d7ed3ef24a720203d4a8065c3fd2b7dce5e5","schema_fingerprint":"4aa3821a28b0b7c2400bc59aba4bcc0a76e971dadd19610d3ad38c768e124dc7","schema_version":"edge-lab-recorder.raw.v1","sequence":null,"source":"clob_market_ws"}
{"event_at":"2026-07-28T04:09:51.296000Z","event_fingerprint":"693ac896f1b12ce9d3791ce8f800d0bcd2eae8711e43217a1a9b5a45cebc6023","payload":{"connection_id":"f6725804f86a4c4eb588e4d5ed7db029","event_at":"2026-07-28T04:09:51.296000Z","event_type":"price_change","frame_hash":"cf8ea3ce82e0115209e407c1b5c09c710852a725bd8eec50afe4d00940a4127e","frame_index":0,"kind":"data","monotonic_ns":313774149775500,"payload":{"event_type":"price_change","market":"0xd412ce774cfcf8dc9f71164aac78783978aac7b03871702a3b8a481bd9dc9688","price_changes":[{"asset_id":"107603864457683460275633293642179940881969192120168665300712204232021063124301","best_ask":"0.61","best_bid":"0.6","hash":"25288cbfa04e8af34aee396272000fccd4c19eee","price":"0.01","side":"BUY","size":"5638.02"},{"asset_id":"96600821790790307414914106093858868634329285205417149685270682748367152458577","best_ask":"0.4","best_bid":"0.39","hash":"cd9803c29aaf05ef784fbe93da9145b8410b2b3f","price":"0.99","side":"SELL","size":"5638.02"}],"timestamp":"1785211791296"},"payload_hash":"2182a60a32b40b3efcfe6f25366dec38dab2b66d87d970017e12171396543421","raw_frame":"{\"market\":\"0xd412ce774cfcf8dc9f71164aac78783978aac7b03871702a3b8a481bd9dc9688\", \"price_changes\":[{\"asset_id\":\"107603864457683460275633293642179940881969192120168665300712204232021063124301\", \"price\":\"0.01\", \"size\":\"5638.02\", \"side\":\"BUY\", \"hash\":\"25288cbfa04e8af34aee396272000fccd4c19eee\", \"best_bid\":\"0.6\", \"best_ask\":\"0.61\"}, {\"asset_id\":\"96600821790790307414914106093858868634329285205417149685270682748367152458577\", \"price\":\"0.99\", \"size\":\"5638.02\", \"side\":\"SELL\", \"hash\":\"cd9803c29aaf05ef784fbe93da9145b8410b2b3f\", \"best_bid\":\"0.39\", \"best_ask\":\"0.4\"}], \"timestamp\":\"1785211791296\", \"event_type\":\"price_change\"}","received_at":"2026-07-28T04:09:51.074031Z","schema_version":"clob-market-ws.price_change.v1","sequence":null,"server_hash":null,"server_timestamp":"1785211791296","session_id":"2d607381e3054cee91998cdf45a4231c","source":"clob_market_ws"},"received_at":"2026-07-28T04:09:51.074031Z","record_id":"7f062ddd857bcca6d170110347b10acf8de9766b86c6fc48929d902b5365238f","schema_fingerprint":"4aa3821a28b0b7c2400bc59aba4bcc0a76e971dadd19610d3ad38c768e124dc7","schema_version":"edge-lab-recorder.raw.v1","sequence":null,"source":"clob_market_ws"}
{"event_at":"2026-07-28T04:09:51.307000Z","event_fingerprint":"6dae917d94312cb989d0206881e61a823f6bf60d3e449f3491e4dae2883aef0e","payload":{"connection_id":"f6725804f86a4c4eb588e4d5ed7db029","event_at":"2026-07-28T04:09:51.307000Z","event_type":"price_change","frame_hash":"562038d2e5406a720989c0933ce361cedab41b138fc57982e9cbe4e5f4a35c6e","frame_index":0,"kind":"data","monotonic_ns":313774158277708,"payload":{"event_type":"price_change","market":"0xd412ce774cfcf8dc9f71164aac78783978aac7b03871702a3b8a481bd9dc9688","price_changes":[{"asset_id":"107603864457683460275633293642179940881969192120168665300712204232021063124301","best_ask":"0.61","best_bid":"0.6","hash":"50c4afeaf426b4810981a6f12e3c1d8e4cedeab8","price":"0.01","side":"BUY","size":"5633.02"},{"asset_id":"96600821790790307414914106093858868634329285205417149685270682748367152458577","best_ask":"0.4","best_bid":"0.39","hash":"24baaf3a0a49805dffbf2022f02d23fed08a9206","price":"0.99","side":"SELL","size":"5633.02"}],"timestamp":"1785211791307"},"payload_hash":"879fed992e700db66ad6acdba9375ad088be142ae1ca2ad7c5a4a2f37aebe84e","raw_frame":"{\"market\":\"0xd412ce774cfcf8dc9f71164aac78783978aac7b03871702a3b8a481bd9dc9688\", \"price_changes\":[{\"asset_id\":\"107603864457683460275633293642179940881969192120168665300712204232021063124301\", \"price\":\"0.01\", \"size\":\"5633.02\", \"side\":\"BUY\", \"hash\":\"50c4afeaf426b4810981a6f12e3c1d8e4cedeab8\", \"best_bid\":\"0.6\", \"best_ask\":\"0.61\"}, {\"asset_id\":\"96600821790790307414914106093858868634329285205417149685270682748367152458577\", \"price\":\"0.99\", \"size\":\"5633.02\", \"side\":\"SELL\", \"hash\":\"24baaf3a0a49805dffbf2022f02d23fed08a9206\", \"best_bid\":\"0.39\", \"best_ask\":\"0.4\"}], \"timestamp\":\"1785211791307\", \"event_type\":\"price_change\"}","received_at":"2026-07-28T04:09:51.082531Z","schema_version":"clob-market-ws.price_change.v1","sequence":null,"server_hash":null,"server_timestamp":"1785211791307","session_id":"2d607381e3054cee91998cdf45a4231c","source":"clob_market_ws"},"received_at":"2026-07-28T04:09:51.082531Z","record_id":"ece9ca611a67f15d3f7e0e6982296ec68c245af99fb7be13b63e055eb1c2c324","schema_fingerprint":"4aa3821a28b0b7c2400bc59aba4bcc0a76e971dadd19610d3ad38c768e124dc7","schema_version":"edge-lab-recorder.raw.v1","sequence":null,"source":"clob_market_ws"}
{"event_at":"2026-07-28T04:09:51.317000Z","event_fingerprint":"f49aee1e9e91e20edd8918bce5605c41e9cdc73eb82ce5d117bff8558d3888fc","payload":{"connection_id":"f6725804f86a4c4eb588e4d5ed7db029","event_at":"2026-07-28T04:09:51.317000Z","event_type":"price_change","frame_hash":"d63e475ff8203f3058ab618f2a7da9ed1feb7c0bcd826635d677c6a899e9c712","frame_index":0,"kind":"data","monotonic_ns":313774168971500,"payload":{"event_type":"price_change","market":"0xd412ce774cfcf8dc9f71164aac78783978aac7b03871702a3b8a481bd9dc9688","price_changes":[{"asset_id":"107603864457683460275633293642179940881969192120168665300712204232021063124301","best_ask":"0.61","best_bid":"0.6","hash":"9aee89c635fdfe5a274184d1881ecd9313709778","price":"0.01","side":"BUY","size":"5638.02"},{"asset_id":"96600821790790307414914106093858868634329285205417149685270682748367152458577","best_ask":"0.4","best_bid":"0.39","hash":"e4822374761bb14d6689dd4899cef259b2a09001","price":"0.99","side":"SELL","size":"5638.02"}],"timestamp":"1785211791317"},"payload_hash":"e6f53a36077b2f0d03b18faf40654c5378428983c9e2cef58f98afb71b811328","raw_frame":"{\"market\":\"0xd412ce774cfcf8dc9f71164aac78783978aac7b03871702a3b8a481bd9dc9688\", \"price_changes\":[{\"asset_id\":\"107603864457683460275633293642179940881969192120168665300712204232021063124301\", \"price\":\"0.01\", \"size\":\"5638.02\", \"side\":\"BUY\", \"hash\":\"9aee89c635fdfe5a274184d1881ecd9313709778\", \"best_bid\":\"0.6\", \"best_ask\":\"0.61\"}, {\"asset_id\":\"96600821790790307414914106093858868634329285205417149685270682748367152458577\", \"price\":\"0.99\", \"size\":\"5638.02\", \"side\":\"SELL\", \"hash\":\"e4822374761bb14d6689dd4899cef259b2a09001\", \"best_bid\":\"0.39\", \"best_ask\":\"0.4\"}], \"timestamp\":\"1785211791317\", \"event_type\":\"price_change\"}","received_at":"2026-07-28T04:09:51.093225Z","schema_version":"clob-market-ws.price_change.v1","sequence":null,"server_hash":null,"server_timestamp":"1785211791317","session_id":"2d607381e3054cee91998cdf45a4231c","source":"clob_market_ws"},"received_at":"2026-07-28T04:09:51.093225Z","record_id":"6561048e0109e0e09c91e93719133f8f029f02b32a990275d1d03f8b4472ed42","schema_fingerprint":"4aa3821a28b0b7c2400bc59aba4bcc0a76e971dadd19610d3ad38c768e124dc7","schema_version":"edge-lab-recorder.raw.v1","sequence":null,"source":"clob_market_ws"}
{"event_at":"2026-07-28T04:09:51.335000Z","event_fingerprint":"6dab1f335174453d45803f9a64901a36a073b6383f303799287c522e280fec71","payload":{"connection_id":"f6725804f86a4c4eb588e4d5ed7db029","event_at":"2026-07-28T04:09:51.335000Z","event_type":"price_change","frame_hash":"7ecca546897fdcc73d908dbc84ca3a0b288f472605a09b46fb0e516aa115621b","frame_index":0,"kind":"data","monotonic_ns":313774186621458,"payload":{"event_type":"price_change","market":"0xd412ce774cfcf8dc9f71164aac78783978aac7b03871702a3b8a481bd9dc9688","price_changes":[{"asset_id":"107603864457683460275633293642179940881969192120168665300712204232021063124301","best_ask":"0.61","best_bid":"0.6","hash":"8cef29143ba6c392147cb5bc421007a5e622d1a8","price":"0.01","side":"BUY","size":"5633.02"},{"asset_id":"96600821790790307414914106093858868634329285205417149685270682748367152458577","best_ask":"0.4","best_bid":"0.39","hash":"4786f7e37942e70624218c8cf76480651c250c0f","price":"0.99","side":"SELL","size":"5633.02"}],"timestamp":"1785211791335"},"payload_hash":"a0ef7e28b412bd0733ec48e7af2311b8278d5078d034f373042dc494561f92ce","raw_frame":"{\"market\":\"0xd412ce774cfcf8dc9f71164aac78783978aac7b03871702a3b8a481bd9dc9688\", \"price_changes\":[{\"asset_id\":\"107603864457683460275633293642179940881969192120168665300712204232021063124301\", \"price\":\"0.01\", \"size\":\"5633.02\", \"side\":\"BUY\", \"hash\":\"8cef29143ba6c392147cb5bc421007a5e622d1a8\", \"best_bid\":\"0.6\", \"best_ask\":\"0.61\"}, {\"asset_id\":\"96600821790790307414914106093858868634329285205417149685270682748367152458577\", \"price\":\"0.99\", \"size\":\"5633.02\", \"side\":\"SELL\", \"hash\":\"4786f7e37942e70624218c8cf76480651c250c0f\", \"best_bid\":\"0.39\", \"best_ask\":\"0.4\"}], \"timestamp\":\"1785211791335\", \"event_type\":\"price_change\"}","received_at":"2026-07-28T04:09:51.110875Z","schema_version":"clob-market-ws.price_change.v1","sequence":null,"server_hash":null,"server_timestamp":"1785211791335","session_id":"2d607381e3054cee91998cdf45a4231c","source":"clob_market_ws"},"received_at":"2026-07-28T04:09:51.110875Z","record_id":"56ef67a6ce2d249dd0bb3fc3fd5eef44f17646c46dc0d8f3736087d91daa6d1d","schema_fingerprint":"4aa3821a28b0b7c2400bc59aba4bcc0a76e971dadd19610d3ad38c768e124dc7","schema_version":"edge-lab-recorder.raw.v1","sequence":null,"source":"clob_market_ws"}
{"event_at":"2026-07-28T04:09:51.350000Z","event_fingerprint":"d06fcb466102bb58e7a8d208b136f35d3c7687d5bab2daf97cda6c2979209548","payload":{"connection_id":"f6725804f86a4c4eb588e4d5ed7db029","event_at":"2026-07-28T04:09:51.350000Z","event_type":"price_change","frame_hash":"57d46e55a389bf01997b2ae38afb715cacd6d6bdb67ccf2f57f3bb43bc5ebcf1","frame_index":0,"kind":"data","monotonic_ns":313774200165833,"payload":{"event_type":"price_change","market":"0xd412ce774cfcf8dc9f71164aac78783978aac7b03871702a3b8a481bd9dc9688","price_changes":[{"asset_id":"107603864457683460275633293642179940881969192120168665300712204232021063124301","best_ask":"0.61","best_bid":"0.6","hash":"29c2d646e821f084a1a675d5b925d7f305b813de","price":"0.39","side":"BUY","size":"17.6"},{"asset_id":"96600821790790307414914106093858868634329285205417149685270682748367152458577","best_ask":"0.4","best_bid":"0.39","hash":"0e8e8d012269ad18714311d00b6616a2d1a0dc3f","price":"0.61","side":"SELL","size":"17.6"}],"timestamp":"1785211791350"},"payload_hash":"85f9dc124c0f7ffc41381d1cdc2440e5323549e04856c844c511a264442a8d41","raw_frame":"{\"market\":\"0xd412ce774cfcf8dc9f71164aac78783978aac7b03871702a3b8a481bd9dc9688\", \"price_changes\":[{\"asset_id\":\"107603864457683460275633293642179940881969192120168665300712204232021063124301\", \"price\":\"0.39\", \"size\":\"17.6\", \"side\":\"BUY\", \"hash\":\"29c2d646e821f084a1a675d5b925d7f305b813de\", \"best_bid\":\"0.6\", \"best_ask\":\"0.61\"}, {\"asset_id\":\"96600821790790307414914106093858868634329285205417149685270682748367152458577\", \"price\":\"0.61\", \"size\":\"17.6\", \"side\":\"SELL\", \"hash\":\"0e8e8d012269ad18714311d00b6616a2d1a0dc3f\", \"best_bid\":\"0.39\", \"best_ask\":\"0.4\"}], \"timestamp\":\"1785211791350\", \"event_type\":\"price_change\"}","received_at":"2026-07-28T04:09:51.124419Z","schema_version":"clob-market-ws.price_change.v1","sequence":null,"server_hash":null,"server_timestamp":"1785211791350","session_id":"2d607381e3054cee91998cdf45a4231c","source":"clob_market_ws"},"received_at":"2026-07-28T04:09:51.124419Z","record_id":"9761279590ab6ebfabb686f04f82d3cc6e0b9ab05286685214a361d03949068a","schema_fingerprint":"4aa3821a28b0b7c2400bc59aba4bcc0a76e971dadd19610d3ad38c768e124dc7","schema_version":"edge-lab-recorder.raw.v1","sequence":null,"source":"clob_market_ws"}
{"event_at":"2026-07-28T04:09:51.368000Z","event_fingerprint":"c5808eb677b5e08ac5740608fae150340e76c0f99de20ffd1178f54b64f47867","payload":{"connection_id":"f6725804f86a4c4eb588e4d5ed7db029","event_at":"2026-07-28T04:09:51.368000Z","event_type":"price_change","frame_hash":"c383f75978bc25027fa36263bc3f9c0a2c43ef466ded6f42e47d96e80099c2dc","frame_index":0,"kind":"data","monotonic_ns":313774218909958,"payload":{"event_type":"price_change","market":"0xd412ce774cfcf8dc9f71164aac78783978aac7b03871702a3b8a481bd9dc9688","price_changes":[{"asset_id":"107603864457683460275633293642179940881969192120168665300712204232021063124301","best_ask":"0.61","best_bid":"0.6","hash":"79be8a8ac624fe4a39a0efbca6de203b82eed4a3","price":"0.58","side":"BUY","size":"103.2"},{"asset_id":"96600821790790307414914106093858868634329285205417149685270682748367152458577","best_ask":"0.4","best_bid":"0.39","hash":"0ac3df9e1dd37fad95d3ce8b45baa9def766edba","price":"0.42","side":"SELL","size":"103.2"}],"timestamp":"1785211791368"},"payload_hash":"120ea2d9d6ec4a1e3e2d3f7bed901a3b761a1ed86f3c640940edf81d9739cd56","raw_frame":"{\"market\":\"0xd412ce774cfcf8dc9f71164aac78783978aac7b03871702a3b8a481bd9dc9688\", \"price_changes\":[{\"asset_id\":\"107603864457683460275633293642179940881969192120168665300712204232021063124301\", \"price\":\"0.58\", \"size\":\"103.2\", \"side\":\"BUY\", \"hash\":\"79be8a8ac624fe4a39a0efbca6de203b82eed4a3\", \"best_bid\":\"0.6\", \"best_ask\":\"0.61\"}, {\"asset_id\":\"96600821790790307414914106093858868634329285205417149685270682748367152458577\", \"price\":\"0.42\", \"size\":\"103.2\", \"side\":\"SELL\", \"hash\":\"0ac3df9e1dd37fad95d3ce8b45baa9def766edba\", \"best_bid\":\"0.39\", \"best_ask\":\"0.4\"}], \"timestamp\":\"1785211791368\", \"event_type\":\"price_change\"}","received_at":"2026-07-28T04:09:51.143163Z","schema_version":"clob-market-ws.price_change.v1","sequence":null,"server_hash":null,"server_timestamp":"1785211791368","session_id":"2d607381e3054cee91998cdf45a4231c","source":"clob_market_ws"},"received_at":"2026-07-28T04:09:51.143163Z","record_id":"8260f716df2b7276cb10526aa8d28c63dda520c8cf570ba1fe4d3cb1252a6032","schema_fingerprint":"4aa3821a28b0b7c2400bc59aba4bcc0a76e971dadd19610d3ad38c768e124dc7","schema_version":"edge-lab-recorder.raw.v1","sequence":null,"source":"clob_market_ws"}
{"event_at":"2026-07-28T04:09:51.370000Z","event_fingerprint":"6b8bd44610ea5cf6829ee3ecee6b622bd0a4013d0b37ec6c74696b47688499b3","payload":{"connection_id":"f6725804f86a4c4eb588e4d5ed7db029","event_at":"2026-07-28T04:09:51.370000Z","event_type":"price_change","frame_hash":"1c643871922734ca0fda5937284fb5fcb1f1d8a351b940be449a354ad3275b9f","frame_index":0,"kind":"data","monotonic_ns":313774224790041,"payload":{"event_type":"price_change","market":"0xd412ce774cfcf8dc9f71164aac78783978aac7b03871702a3b8a481bd9dc9688","price_changes":[{"asset_id":"96600821790790307414914106093858868634329285205417149685270682748367152458577","best_ask":"0.4","best_bid":"0.39","hash":"8a9a183049b3aeeebf8c18bd4c3908212ceaf860","price":"0.42","side":"SELL","size":"128.2"},{"asset_id":"107603864457683460275633293642179940881969192120168665300712204232021063124301","best_ask":"0.61","best_bid":"0.6","hash":"2b5861962e74b74bb125cb797e06b7995e167784","price":"0.58","side":"BUY","size":"128.2"}],"timestamp":"1785211791370"},"payload_hash":"7d715b17eca86ec9fda6e7116cbf49c60facce4dcc3d8fce8108667587949e63","raw_frame":"{\"market\":\"0xd412ce774cfcf8dc9f71164aac78783978aac7b03871702a3b8a481bd9dc9688\", \"price_changes\":[{\"asset_id\":\"96600821790790307414914106093858868634329285205417149685270682748367152458577\", \"price\":\"0.42\", \"size\":\"128.2\", \"side\":\"SELL\", \"hash\":\"8a9a183049b3aeeebf8c18bd4c3908212ceaf860\", \"best_bid\":\"0.39\", \"best_ask\":\"0.4\"}, {\"asset_id\":\"107603864457683460275633293642179940881969192120168665300712204232021063124301\", \"price\":\"0.58\", \"size\":\"128.2\", \"side\":\"BUY\", \"hash\":\"2b5861962e74b74bb125cb797e06b7995e167784\", \"best_bid\":\"0.6\", \"best_ask\":\"0.61\"}], \"timestamp\":\"1785211791370\", \"event_type\":\"price_change\"}","received_at":"2026-07-28T04:09:51.149044Z","schema_version":"clob-market-ws.price_change.v1","sequence":null,"server_hash":null,"server_timestamp":"1785211791370","session_id":"2d607381e3054cee91998cdf45a4231c","source":"clob_market_ws"},"received_at":"2026-07-28T04:09:51.149044Z","record_id":"fb935968215074950212174518684d67840c03a79d3dc47864aca96ba69559f1","schema_fingerprint":"4aa3821a28b0b7c2400bc59aba4bcc0a76e971dadd19610d3ad38c768e124dc7","schema_version":"edge-lab-recorder.raw.v1","sequence":null,"source":"clob_market_ws"}
{"event_at":"2026-07-28T04:09:51.373000Z","event_fingerprint":"a016a113251369a8c4d6a80b10b5916affd46883ada9e629a2979edce757f5e7","payload":{"connection_id":"f6725804f86a4c4eb588e4d5ed7db029","event_at":"2026-07-28T04:09:51.373000Z","event_type":"price_change","frame_hash":"8a0c90abf0de26bda6d79291622c9546fcdf7e4e03564cdbd25f47a3dcab6867","frame_index":0,"kind":"data","monotonic_ns":313774228565416,"payload":{"event_type":"price_change","market":"0xd412ce774cfcf8dc9f71164aac78783978aac7b03871702a3b8a481bd9dc9688","price_changes":[{"asset_id":"107603864457683460275633293642179940881969192120168665300712204232021063124301","best_ask":"0.61","best_bid":"0.6","hash":"08fc6ad9f20a662ddd1f5add257ebdd9e1329a48","price":"0.01","side":"BUY","size":"5638.02"},{"asset_id":"96600821790790307414914106093858868634329285205417149685270682748367152458577","best_ask":"0.4","best_bid":"0.39","hash":"65fb413a55bbae7e9fe7f6edd210ca0f2d415a12","price":"0.99","side":"SELL","size":"5638.02"}],"timestamp":"1785211791373"},"payload_hash":"738a4d852c9fd51274d37730a3f8ee137bfdcb83e917a1ce84b3da988fc9b01f","raw_frame":"{\"market\":\"0xd412ce774cfcf8dc9f71164aac78783978aac7b03871702a3b8a481bd9dc9688\", \"price_changes\":[{\"asset_id\":\"107603864457683460275633293642179940881969192120168665300712204232021063124301\", \"price\":\"0.01\", \"size\":\"5638.02\", \"side\":\"BUY\", \"hash\":\"08fc6ad9f20a662ddd1f5add257ebdd9e1329a48\", \"best_bid\":\"0.6\", \"best_ask\":\"0.61\"}, {\"asset_id\":\"96600821790790307414914106093858868634329285205417149685270682748367152458577\", \"price\":\"0.99\", \"size\":\"5638.02\", \"side\":\"SELL\", \"hash\":\"65fb413a55bbae7e9fe7f6edd210ca0f2d415a12\", \"best_bid\":\"0.39\", \"best_ask\":\"0.4\"}], \"timestamp\":\"1785211791373\", \"event_type\":\"price_change\"}","received_at":"2026-07-28T04:09:51.152818Z","schema_version":"clob-market-ws.price_change.v1","sequence":null,"server_hash":null,"server_timestamp":"1785211791373","session_id":"2d607381e3054cee91998cdf45a4231c","source":"clob_market_ws"},"received_at":"2026-07-28T04:09:51.152818Z","record_id":"ec9a39265cc8644f732f7b02981ee69db37be8ee3def6351819921f23c7f49db","schema_fingerprint":"4aa3821a28b0b7c2400bc59aba4bcc0a76e971dadd19610d3ad38c768e124dc7","schema_version":"edge-lab-recorder.raw.v1","sequence":null,"source":"clob_market_ws"}
{"event_at":"2026-07-28T04:09:51.382000Z","event_fingerprint":"883a74f7992ec42cbdcd3c8ff2d682e12ead46ebac42cf8f22a1d95281338054","payload":{"connection_id":"f6725804f86a4c4eb588e4d5ed7db029","event_at":"2026-07-28T04:09:51.382000Z","event_type":"price_change","frame_hash":"a177b5cd3c1b0cb30ac2ef15115ab562fa9f5794e7a53774f76e523c8c81aac7","frame_index":0,"kind":"data","monotonic_ns":313774239035125,"payload":{"event_type":"price_change","market":"0xd412ce774cfcf8dc9f71164aac78783978aac7b03871702a3b8a481bd9dc9688","price_changes":[{"asset_id":"107603864457683460275633293642179940881969192120168665300712204232021063124301","best_ask":"0.61","best_bid":"0.6","hash":"92f466a8744a347eaa7ff75285fdcb85f03565e4","price":"0.32","side":"BUY","size":"34.8"},{"asset_id":"96600821790790307414914106093858868634329285205417149685270682748367152458577","best_ask":"0.4","best_bid":"0.39","hash":"dab4e92b52b1a5a24fa79e655a239aa14f20c920","price":"0.68","side":"SELL","size":"34.8"}],"timestamp":"1785211791382"},"payload_hash":"a99adbdaa6af19c05e49b9a14ac24f4fca4b6cba30ec58e65179328b8feb7f47","raw_frame":"{\"market\":\"0xd412ce774cfcf8dc9f71164aac78783978aac7b03871702a3b8a481bd9dc9688\", \"price_changes\":[{\"asset_id\":\"107603864457683460275633293642179940881969192120168665300712204232021063124301\", \"price\":\"0.32\", \"size\":\"34.8\", \"side\":\"BUY\", \"hash\":\"92f466a8744a347eaa7ff75285fdcb85f03565e4\", \"best_bid\":\"0.6\", \"best_ask\":\"0.61\"}, {\"asset_id\":\"96600821790790307414914106093858868634329285205417149685270682748367152458577\", \"price\":\"0.68\", \"size\":\"34.8\", \"side\":\"SELL\", \"hash\":\"dab4e92b52b1a5a24fa79e655a239aa14f20c920\", \"best_bid\":\"0.39\", \"best_ask\":\"0.4\"}], \"timestamp\":\"1785211791382\", \"event_type\":\"price_change\"}","received_at":"2026-07-28T04:09:51.163290Z","schema_version":"clob-market-ws.price_change.v1","sequence":null,"server_hash":null,"server_timestamp":"1785211791382","session_id":"2d607381e3054cee91998cdf45a4231c","source":"clob_market_ws"},"received_at":"2026-07-28T04:09:51.163290Z","record_id":"b55e84a071d37a3b98e3123a050239176ca51850257ffbb60c2120d67f02a613","schema_fingerprint":"4aa3821a28b0b7c2400bc59aba4bcc0a76e971dadd19610d3ad38c768e124dc7","schema_version":"edge-lab-recorder.raw.v1","sequence":null,"source":"clob_market_ws"}
{"event_at":"2026-07-28T04:09:51.410000Z","event_fingerprint":"52da480ad491bad6d2eaba9fe31a1d12d797545e4eed6dbdbcaa78753c8d1c4a","payload":{"connection_id":"f6725804f86a4c4eb588e4d5ed7db029","event_at":"2026-07-28T04:09:51.410000Z","event_type":"price_change","frame_hash":"92605eb7f87e21dbfe889ffbbcddaf45b47e8e27de033fbad56631d3e613a035","frame_index":0,"kind":"data","monotonic_ns":313774259523000,"payload":{"event_type":"price_change","market":"0xd412ce774cfcf8dc9f71164aac78783978aac7b03871702a3b8a481bd9dc9688","price_changes":[{"asset_id":"107603864457683460275633293642179940881969192120168665300712204232021063124301","best_ask":"0.61","best_bid":"0.6","hash":"946cedad90b0dee03aa6499108baaeaf8db15774","price":"0.81","side":"SELL","size":"27.5"},{"asset_id":"96600821790790307414914106093858868634329285205417149685270682748367152458577","best_ask":"0.4","best_bid":"0.39","hash":"5383022531bc3713bae6c030d02883c48792228e","price":"0.19","side":"BUY","size":"27.5"}],"timestamp":"1785211791410"},"payload_hash":"bffd9c9553be4576113c2895209ddabd44375ae5c79a89aba9ac1cf3e9e1c4f5","raw_frame":"{\"market\":\"0xd412ce774cfcf8dc9f71164aac78783978aac7b03871702a3b8a481bd9dc9688\", \"price_changes\":[{\"asset_id\":\"107603864457683460275633293642179940881969192120168665300712204232021063124301\", \"price\":\"0.81\", \"size\":\"27.5\", \"side\":\"SELL\", \"hash\":\"946cedad90b0dee03aa6499108baaeaf8db15774\", \"best_bid\":\"0.6\", \"best_ask\":\"0.61\"}, {\"asset_id\":\"96600821790790307414914106093858868634329285205417149685270682748367152458577\", \"price\":\"0.19\", \"size\":\"27.5\", \"side\":\"BUY\", \"hash\":\"5383022531bc3713bae6c030d02883c48792228e\", \"best_bid\":\"0.39\", \"best_ask\":\"0.4\"}], \"timestamp\":\"1785211791410\", \"event_type\":\"price_change\"}","received_at":"2026-07-28T04:09:51.183776Z","schema_version":"clob-market-ws.price_change.v1","sequence":null,"server_hash":null,"server_timestamp":"1785211791410","session_id":"2d607381e3054cee91998cdf45a4231c","source":"clob_market_ws"},"received_at":"2026-07-28T04:09:51.183776Z","record_id":"68f6230cadf9c3392d1a5ab4fc33c6d259d641819b0aed83e210cadc9b90b900","schema_fingerprint":"4aa3821a28b0b7c2400bc59aba4bcc0a76e971dadd19610d3ad38c768e124dc7","schema_version":"edge-lab-recorder.raw.v1","sequence":null,"source":"clob_market_ws"}
{"event_at":"2026-07-28T04:09:51.414000Z","event_fingerprint":"dcadd6f40ade46186749b28b8ff2c8c0b0272b43a8f4a428fa2502ed2fc16c56","payload":{"connection_id":"f6725804f86a4c4eb588e4d5ed7db029","event_at":"2026-07-28T04:09:51.414000Z","event_type":"price_change","frame_hash":"31ab2f0ec1a40ba5f9459e1e8a35d6da91c9c4010488e8edd4b424b18e391451","frame_index":0,"kind":"data","monotonic_ns":313774264148500,"payload":{"event_type":"price_change","market":"0xd412ce774cfcf8dc9f71164aac78783978aac7b03871702a3b8a481bd9dc9688","price_changes":[{"asset_id":"96600821790790307414914106093858868634329285205417149685270682748367152458577","best_ask":"0.4","best_bid":"0.39","hash":"582b8c6272c0eb64bfd3b129fc3c05257261f6ee","price":"0.39","side":"BUY","size":"87.2"},{"asset_id":"107603864457683460275633293642179940881969192120168665300712204232021063124301","best_ask":"0.61","best_bid":"0.6","hash":"e34cef66d3257e625ee121bfcac268c5f8db28ee","price":"0.61","side":"SELL","size":"87.2"}],"timestamp":"1785211791414"},"payload_hash":"46142d30c31d0a675fe14f835b352b4a8d46994daaf7b9f7fcb4e73bfe84b88f","raw_frame":"{\"market\":\"0xd412ce774cfcf8dc9f71164aac78783978aac7b03871702a3b8a481bd9dc9688\", \"price_changes\":[{\"asset_id\":\"96600821790790307414914106093858868634329285205417149685270682748367152458577\", \"price\":\"0.39\", \"size\":\"87.2\", \"side\":\"BUY\", \"hash\":\"582b8c6272c0eb64bfd3b129fc3c05257261f6ee\", \"best_bid\":\"0.39\", \"best_ask\":\"0.4\"}, {\"asset_id\":\"107603864457683460275633293642179940881969192120168665300712204232021063124301\", \"price\":\"0.61\", \"size\":\"87.2\", \"side\":\"SELL\", \"hash\":\"e34cef66d3257e625ee121bfcac268c5f8db28ee\", \"best_bid\":\"0.6\", \"best_ask\":\"0.61\"}], \"timestamp\":\"1785211791414\", \"event_type\":\"price_change\"}","received_at":"2026-07-28T04:09:51.188401Z","schema_version":"clob-market-ws.price_change.v1","sequence":null,"server_hash":null,"server_timestamp":"1785211791414","session_id":"2d607381e3054cee91998cdf45a4231c","source":"clob_market_ws"},"received_at":"2026-07-28T04:09:51.188401Z","record_id":"82bef39df3f7fada8360087b83084fcfa8dca2ec9debec778831e547ba2087f0","schema_fingerprint":"4aa3821a28b0b7c2400bc59aba4bcc0a76e971dadd19610d3ad38c768e124dc7","schema_version":"edge-lab-recorder.raw.v1","sequence":null,"source":"clob_market_ws"}
{"event_at":"2026-07-28T04:09:51.414000Z","event_fingerprint":"5622bcf47f9fc3d3dcbb6cee4fc1596fecefebb47555f463f2b10d0ca9bf13da","payload":{"connection_id":"f6725804f86a4c4eb588e4d5ed7db029","event_at":"2026-07-28T04:09:51.414000Z","event_type":"price_change","frame_hash":"52c70c08aeba83f96402fff29098721b75c70b5a4764d0273485fd01cf006712","frame_index":0,"kind":"data","monotonic_ns":313774267059875,"payload":{"event_type":"price_change","market":"0xd412ce774cfcf8dc9f71164aac78783978aac7b03871702a3b8a481bd9dc9688","price_changes":[{"asset_id":"107603864457683460275633293642179940881969192120168665300712204232021063124301","best_ask":"0.61","best_bid":"0.6","hash":"e34cef66d3257e625ee121bfcac268c5f8db28ee","price":"0.32","side":"BUY","size":"19.8"},{"asset_id":"96600821790790307414914106093858868634329285205417149685270682748367152458577","best_ask":"0.4","best_bid":"0.39","hash":"582b8c6272c0eb64bfd3b129fc3c05257261f6ee","price":"0.68","side":"SELL","size":"19.8"}],"timestamp":"1785211791414"},"payload_hash":"737c3c8e352131549da3041cc31719a9bdb0ddd10269347df9e812eb06c848ad","raw_frame":"{\"market\":\"0xd412ce774cfcf8dc9f71164aac78783978aac7b03871702a3b8a481bd9dc9688\", \"price_changes\":[{\"asset_id\":\"107603864457683460275633293642179940881969192120168665300712204232021063124301\", \"price\":\"0.32\", \"size\":\"19.8\", \"side\":\"BUY\", \"hash\":\"e34cef66d3257e625ee121bfcac268c5f8db28ee\", \"best_bid\":\"0.6\", \"best_ask\":\"0.61\"}, {\"asset_id\":\"96600821790790307414914106093858868634329285205417149685270682748367152458577\", \"price\":\"0.68\", \"size\":\"19.8\", \"side\":\"SELL\", \"hash\":\"582b8c6272c0eb64bfd3b129fc3c05257261f6ee\", \"best_bid\":\"0.39\", \"best_ask\":\"0.4\"}], \"timestamp\":\"1785211791414\", \"event_type\":\"price_change\"}","received_at":"2026-07-28T04:09:51.191313Z","schema_version":"clob-market-ws.price_change.v1","sequence":null,"server_hash":null,"server_timestamp":"1785211791414","session_id":"2d607381e3054cee91998cdf45a4231c","source":"clob_market_ws"},"received_at":"2026-07-28T04:09:51.191313Z","record_id":"62534b5b36cc7b3560c613c88d5f50c6cb663d39d324da1ca9883afe7a183287","schema_fingerprint":"4aa3821a28b0b7c2400bc59aba4bcc0a76e971dadd19610d3ad38c768e124dc7","schema_version":"edge-lab-recorder.raw.v1","sequence":null,"source":"clob_market_ws"}
{"event_at":"2026-07-28T04:09:51.423000Z","event_fingerprint":"2d4993e8000278ac4de08eacfae7242de9caeab610526f7a8b5e7098a45e5151","payload":{"connection_id":"f6725804f86a4c4eb588e4d5ed7db029","event_at":"2026-07-28T04:09:51.423000Z","event_type":"price_change","frame_hash":"170dbb2f38e20870556b9dfabf86413d3bf3cd836c0c2aff550e9df122ae8639","frame_index":0,"kind":"data","monotonic_ns":313774272362208,"payload":{"event_type":"price_change","market":"0xd412ce774cfcf8dc9f71164aac78783978aac7b03871702a3b8a481bd9dc9688","price_changes":[{"asset_id":"107603864457683460275633293642179940881969192120168665300712204232021063124301","best_ask":"0.61","best_bid":"0.6","hash":"be89f177df1ac91bf3d0ffe082951318a0d39b11","price":"0.57","side":"BUY","size":"66.2"},{"asset_id":"96600821790790307414914106093858868634329285205417149685270682748367152458577","best_ask":"0.4","best_bid":"0.39","hash":"4d327302fba2a56f12d5bab0a62fbbfc878effbf","price":"0.43","side":"SELL","size":"66.2"}],"timestamp":"1785211791423"},"payload_hash":"2fc0a71ecc584383352d43be9ee538592942121cd1baaee3807db527f2125573","raw_frame":"{\"market\":\"0xd412ce774cfcf8dc9f71164aac78783978aac7b03871702a3b8a481bd9dc9688\", \"price_changes\":[{\"asset_id\":\"107603864457683460275633293642179940881969192120168665300712204232021063124301\", \"price\":\"0.57\", \"size\":\"66.2\", \"side\":\"BUY\", \"hash\":\"be89f177df1ac91bf3d0ffe082951318a0d39b11\", \"best_bid\":\"0.6\", \"best_ask\":\"0.61\"}, {\"asset_id\":\"96600821790790307414914106093858868634329285205417149685270682748367152458577\", \"price\":\"0.43\", \"size\":\"66.2\", \"side\":\"SELL\", \"hash\":\"4d327302fba2a56f12d5bab0a62fbbfc878effbf\", \"best_bid\":\"0.39\", \"best_ask\":\"0.4\"}], \"timestamp\":\"1785211791423\", \"event_type\":\"price_change\"}","received_at":"2026-07-28T04:09:51.196614Z","schema_version":"clob-market-ws.price_change.v1","sequence":null,"server_hash":null,"server_timestamp":"1785211791423","session_id":"2d607381e3054cee91998cdf45a4231c","source":"clob_market_ws"},"received_at":"2026-07-28T04:09:51.196614Z","record_id":"675f9e4d270ec9b325509b07feaaf78ca94afcc1a0b62b43626626072cc4dd5a","schema_fingerprint":"4aa3821a28b0b7c2400bc59aba4bcc0a76e971dadd19610d3ad38c768e124dc7","schema_version":"edge-lab-recorder.raw.v1","sequence":null,"source":"clob_market_ws"}
{"event_at":"2026-07-28T04:09:51.423000Z","event_fingerprint":"c608b1ce707fae4e2d0b965bfcc4df5d8b5fd1f63dc72f48eda07358d64bf8ff","payload":{"connection_id":"f6725804f86a4c4eb588e4d5ed7db029","event_at":"2026-07-28T04:09:51.423000Z","event_type":"price_change","frame_hash":"9739310ae14c57e478858875796185bed1e86900737e12077db72333303148cc","frame_index":0,"kind":"data","monotonic_ns":313774275274416,"payload":{"event_type":"price_change","market":"0xd412ce774cfcf8dc9f71164aac78783978aac7b03871702a3b8a481bd9dc9688","price_changes":[{"asset_id":"96600821790790307414914106093858868634329285205417149685270682748367152458577","best_ask":"0.4","best_bid":"0.39","hash":"4d327302fba2a56f12d5bab0a62fbbfc878effbf","price":"0.32","side":"BUY","size":"232.62"},{"asset_id":"107603864457683460275633293642179940881969192120168665300712204232021063124301","best_ask":"0.61","best_bid":"0.6","hash":"be89f177df1ac91bf3d0ffe082951318a0d39b11","price":"0.68","side":"SELL","size":"232.62"}],"timestamp":"1785211791423"},"payload_hash":"84e1457dbb1143eb9243970bdb000f1e41ff3c8dbe59388246a5ca1c68c8caae","raw_frame":"{\"market\":\"0xd412ce774cfcf8dc9f71164aac78783978aac7b03871702a3b8a481bd9dc9688\", \"price_changes\":[{\"asset_id\":\"96600821790790307414914106093858868634329285205417149685270682748367152458577\", \"price\":\"0.32\", \"size\":\"232.62\", \"side\":\"BUY\", \"hash\":\"4d327302fba2a56f12d5bab0a62fbbfc878effbf\", \"best_bid\":\"0.39\", \"best_ask\":\"0.4\"}, {\"asset_id\":\"107603864457683460275633293642179940881969192120168665300712204232021063124301\", \"price\":\"0.68\", \"size\":\"232.62\", \"side\":\"SELL\", \"hash\":\"be89f177df1ac91bf3d0ffe082951318a0d39b11\", \"best_bid\":\"0.6\", \"best_ask\":\"0.61\"}], \"timestamp\":\"1785211791423\", \"event_type\":\"price_change\"}","received_at":"2026-07-28T04:09:51.199527Z","schema_version":"clob-market-ws.price_change.v1","sequence":null,"server_hash":null,"server_timestamp":"1785211791423","session_id":"2d607381e3054cee91998cdf45a4231c","source":"clob_market_ws"},"received_at":"2026-07-28T04:09:51.199527Z","record_id":"9e418a67131e1d4dddd8bc9c20170601e2bf53bd727b2f43ef62284026a636ce","schema_fingerprint":"4aa3821a28b0b7c2400bc59aba4bcc0a76e971dadd19610d3ad38c768e124dc7","schema_version":"edge-lab-recorder.raw.v1","sequence":null,"source":"clob_market_ws"}
{"event_at":"2026-07-28T04:09:51.436000Z","event_fingerprint":"699d8c6cefbcb5e1d1d07fa7560947d7018f785b922f4102f9428fbe761ddc86","payload":{"connection_id":"f6725804f86a4c4eb588e4d5ed7db029","event_at":"2026-07-28T04:09:51.436000Z","event_type":"price_change","frame_hash":"cc5ffaca3ae607207ed412e252fb3d260e2dc4988915ff445e96ce905f4c1d2a","frame_index":0,"kind":"data","monotonic_ns":313774287402791,"payload":{"event_type":"price_change","market":"0xd412ce774cfcf8dc9f71164aac78783978aac7b03871702a3b8a481bd9dc9688","price_changes":[{"asset_id":"107603864457683460275633293642179940881969192120168665300712204232021063124301","best_ask":"0.61","best_bid":"0.6","hash":"d1ceddbcb31a28a1f9196f7aa40cb0d4514a3497","price":"0.01","side":"BUY","size":"5633.02"},{"asset_id":"96600821790790307414914106093858868634329285205417149685270682748367152458577","best_ask":"0.4","best_bid":"0.39","hash":"a3ba7950212f24ffa72cc182947ad634f04d9eb8","price":"0.99","side":"SELL","size":"5633.02"}],"timestamp":"1785211791436"},"payload_hash":"79adda44a4a60976e9a1a7db070e147db1dbd6cc7bc3a98cb00b69c1c5d9e91c","raw_frame":"{\"market\":\"0xd412ce774cfcf8dc9f71164aac78783978aac7b03871702a3b8a481bd9dc9688\", \"price_changes\":[{\"asset_id\":\"107603864457683460275633293642179940881969192120168665300712204232021063124301\", \"price\":\"0.01\", \"size\":\"5633.02\", \"side\":\"BUY\", \"hash\":\"d1ceddbcb31a28a1f9196f7aa40cb0d4514a3497\", \"best_bid\":\"0.6\", \"best_ask\":\"0.61\"}, {\"asset_id\":\"96600821790790307414914106093858868634329285205417149685270682748367152458577\", \"price\":\"0.99\", \"size\":\"5633.02\", \"side\":\"SELL\", \"hash\":\"a3ba7950212f24ffa72cc182947ad634f04d9eb8\", \"best_bid\":\"0.39\", \"best_ask\":\"0.4\"}], \"timestamp\":\"1785211791436\", \"event_type\":\"price_change\"}","received_at":"2026-07-28T04:09:51.211661Z","schema_version":"clob-market-ws.price_change.v1","sequence":null,"server_hash":null,"server_timestamp":"1785211791436","session_id":"2d607381e3054cee91998cdf45a4231c","source":"clob_market_ws"},"received_at":"2026-07-28T04:09:51.211661Z","record_id":"5f1e248fab329d2ea95b5550ae64c2d6194d72ce965751a1c557675d188523dc","schema_fingerprint":"4aa3821a28b0b7c2400bc59aba4bcc0a76e971dadd19610d3ad38c768e124dc7","schema_version":"edge-lab-recorder.raw.v1","sequence":null,"source":"clob_market_ws"}
{"event_at":"2026-07-28T04:09:51.441000Z","event_fingerprint":"d2755239d6e71383f3f4fc623b3790ee385e0f41755f8ee4eef653b65359dbfe","payload":{"connection_id":"f6725804f86a4c4eb588e4d5ed7db029","event_at":"2026-07-28T04:09:51.441000Z","event_type":"price_change","frame_hash":"2e0ae2df00e2bd0f74fa74bdaaf8c8638144488dd8c9698e43a825ab260e9fcf","frame_index":0,"kind":"data","monotonic_ns":313774290830791,"payload":{"event_type":"price_change","market":"0xd412ce774cfcf8dc9f71164aac78783978aac7b03871702a3b8a481bd9dc9688","price_changes":[{"asset_id":"107603864457683460275633293642179940881969192120168665300712204232021063124301","best_ask":"0.61","best_bid":"0.6","hash":"35897439cdc5201c8e04804cf149989d1caf7018","price":"0.8","side":"SELL","size":"62.3"},{"asset_id":"96600821790790307414914106093858868634329285205417149685270682748367152458577","best_ask":"0.4","best_bid":"0.39","hash":"875cc484c40471bc19970d2a867c1ccdd15ec73d","price":"0.2","side":"BUY","size":"62.3"}],"timestamp":"1785211791441"},"payload_hash":"c361927909e0316ea4b5a87a226301f049fcd73c7ff1fd38557089efd2d875e4","raw_frame":"{\"market\":\"0xd412ce774cfcf8dc9f71164aac78783978aac7b03871702a3b8a481bd9dc9688\", \"price_changes\":[{\"asset_id\":\"107603864457683460275633293642179940881969192120168665300712204232021063124301\", \"price\":\"0.8\", \"size\":\"62.3\", \"side\":\"SELL\", \"hash\":\"35897439cdc5201c8e04804cf149989d1caf7018\", \"best_bid\":\"0.6\", \"best_ask\":\"0.61\"}, {\"asset_id\":\"96600821790790307414914106093858868634329285205417149685270682748367152458577\", \"price\":\"0.2\", \"size\":\"62.3\", \"side\":\"BUY\", \"hash\":\"875cc484c40471bc19970d2a867c1ccdd15ec73d\", \"best_bid\":\"0.39\", \"best_ask\":\"0.4\"}], \"timestamp\":\"1785211791441\", \"event_type\":\"price_change\"}","received_at":"2026-07-28T04:09:51.215090Z","schema_version":"clob-market-ws.price_change.v1","sequence":null,"server_hash":null,"server_timestamp":"1785211791441","session_id":"2d607381e3054cee91998cdf45a4231c","source":"clob_market_ws"},"received_at":"2026-07-28T04:09:51.215090Z","record_id":"1813c6060f638b6a1ee6d4edc8de926c62cb8be1f50342aa859a4216344d049e","schema_fingerprint":"4aa3821a28b0b7c2400bc59aba4bcc0a76e971dadd19610d3ad38c768e124dc7","schema_version":"edge-lab-recorder.raw.v1","sequence":null,"source":"clob_market_ws"}
{"event_at":"2026-07-28T04:09:51.451000Z","event_fingerprint":"c0d6712b0f5a18e02663d0c3878229b2e6434f2c908fc09f8c0a9c3418268114","payload":{"connection_id":"f6725804f86a4c4eb588e4d5ed7db029","event_at":"2026-07-28T04:09:51.451000Z","event_type":"price_change","frame_hash":"03c38f19e38fbbd160d18bc3267c3762ae63eacee45491de207d1868bf461fd9","frame_index":0,"kind":"data","monotonic_ns":313774302641625,"payload":{"event_type":"price_change","market":"0xd412ce774cfcf8dc9f71164aac78783978aac7b03871702a3b8a481bd9dc9688","price_changes":[{"asset_id":"107603864457683460275633293642179940881969192120168665300712204232021063124301","best_ask":"0.61","best_bid":"0.6","hash":"2dbdb49c80400ab31df86262785950a184946230","price":"0.56","side":"BUY","size":"58.6"},{"asset_id":"96600821790790307414914106093858868634329285205417149685270682748367152458577","best_ask":"0.4","best_bid":"0.39","hash":"ca5fed487dde5a7517b1e173348abb65009e9c3c","price":"0.44","side":"SELL","size":"58.6"}],"timestamp":"1785211791451"},"payload_hash":"b274c1b36b52ead844101ec85f194f7b7e65ab31b88de7a43a92d009e106f0b8","raw_frame":"{\"market\":\"0xd412ce774cfcf8dc9f71164aac78783978aac7b03871702a3b8a481bd9dc9688\", \"price_changes\":[{\"asset_id\":\"107603864457683460275633293642179940881969192120168665300712204232021063124301\", \"price\":\"0.56\", \"size\":\"58.6\", \"side\":\"BUY\", \"hash\":\"2dbdb49c80400ab31df86262785950a184946230\", \"best_bid\":\"0.6\", \"best_ask\":\"0.61\"}, {\"asset_id\":\"96600821790790307414914106093858868634329285205417149685270682748367152458577\", \"price\":\"0.44\", \"size\":\"58.6\", \"side\":\"SELL\", \"hash\":\"ca5fed487dde5a7517b1e173348abb65009e9c3c\", \"best_bid\":\"0.39\", \"best_ask\":\"0.4\"}], \"timestamp\":\"1785211791451\", \"event_type\":\"price_change\"}","received_at":"2026-07-28T04:09:51.226892Z","schema_version":"clob-market-ws.price_change.v1","sequence":null,"server_hash":null,"server_timestamp":"1785211791451","session_id":"2d607381e3054cee91998cdf45a4231c","source":"clob_market_ws"},"received_at":"2026-07-28T04:09:51.226892Z","record_id":"d9729086f940874cdca0e122bb567e6a11bc556b56fdb0d11f4f9d60204fc701","schema_fingerprint":"4aa3821a28b0b7c2400bc59aba4bcc0a76e971dadd19610d3ad38c768e124dc7","schema_version":"edge-lab-recorder.raw.v1","sequence":null,"source":"clob_market_ws"}
{"event_at":"2026-07-28T04:09:51.454000Z","event_fingerprint":"d14d9d74ef19e36187e38f801b33da35917bd667aa219380376ea2c2d05ed576","payload":{"connection_id":"f6725804f86a4c4eb588e4d5ed7db029","event_at":"2026-07-28T04:09:51.454000Z","event_type":"price_change","frame_hash":"9411c48c7022dc2f8100a5135ff26fa5c0c021e8c0135dcdbaf93c7189152b1c","frame_index":0,"kind":"data","monotonic_ns":313774306282000,"payload":{"event_type":"price_change","market":"0xd412ce774cfcf8dc9f71164aac78783978aac7b03871702a3b8a481bd9dc9688","price_changes":[{"asset_id":"96600821790790307414914106093858868634329285205417149685270682748367152458577","best_ask":"0.4","best_bid":"0.39","hash":"8be93705222835697343006e8a1082f93152e63d","price":"0.34","side":"BUY","size":"247.19"},{"asset_id":"107603864457683460275633293642179940881969192120168665300712204232021063124301","best_ask":"0.61","best_bid":"0.6","hash":"15d8f6954d5a250266212e9ebe8bb326be49701b","price":"0.66","side":"SELL","size":"247.19"}],"timestamp":"1785211791454"},"payload_hash":"6f8cd3438d61ea89f20eadeaa5f42fc037f422824f51deca51bf4a375ccdfbb0","raw_frame":"{\"market\":\"0xd412ce774cfcf8dc9f71164aac78783978aac7b03871702a3b8a481bd9dc9688\", \"price_changes\":[{\"asset_id\":\"96600821790790307414914106093858868634329285205417149685270682748367152458577\", \"price\":\"0.34\", \"size\":\"247.19\", \"side\":\"BUY\", \"hash\":\"8be93705222835697343006e8a1082f93152e63d\", \"best_bid\":\"0.39\", \"best_ask\":\"0.4\"}, {\"asset_id\":\"107603864457683460275633293642179940881969192120168665300712204232021063124301\", \"price\":\"0.66\", \"size\":\"247.19\", \"side\":\"SELL\", \"hash\":\"15d8f6954d5a250266212e9ebe8bb326be49701b\", \"best_bid\":\"0.6\", \"best_ask\":\"0.61\"}], \"timestamp\":\"1785211791454\", \"event_type\":\"price_change\"}","received_at":"2026-07-28T04:09:51.230533Z","schema_version":"clob-market-ws.price_change.v1","sequence":null,"server_hash":null,"server_timestamp":"1785211791454","session_id":"2d607381e3054cee91998cdf45a4231c","source":"clob_market_ws"},"received_at":"2026-07-28T04:09:51.230533Z","record_id":"7170d8c3f7c29e2ae1670480b6168af18ca48258bc1e6306ec13e68248c1808f","schema_fingerprint":"4aa3821a28b0b7c2400bc59aba4bcc0a76e971dadd19610d3ad38c768e124dc7","schema_version":"edge-lab-recorder.raw.v1","sequence":null,"source":"clob_market_ws"}
{"event_at":"2026-07-28T04:09:51.464000Z","event_fingerprint":"8c4a2e1e6b7ffd77ba1f13ae7eca386fd72044dd891e6542a4d4f8af1c4a537a","payload":{"connection_id":"f6725804f86a4c4eb588e4d5ed7db029","event_at":"2026-07-28T04:09:51.464000Z","event_type":"price_change","frame_hash":"762fe37088f9b3c3caf8e8bb9d7e328e7d2f1c9e211338c22fc528af86e53835","frame_index":0,"kind":"data","monotonic_ns":313774314049916,"payload":{"event_type":"price_change","market":"0xd412ce774cfcf8dc9f71164aac78783978aac7b03871702a3b8a481bd9dc9688","price_changes":[{"asset_id":"107603864457683460275633293642179940881969192120168665300712204232021063124301","best_ask":"0.61","best_bid":"0.6","hash":"dbb782b29dab89a6d97aa5808cae7e6e12f8d34f","price":"0.58","side":"BUY","size":"103.2"},{"asset_id":"96600821790790307414914106093858868634329285205417149685270682748367152458577","best_ask":"0.4","best_bid":"0.39","hash":"30e165b51818a2d29a6b845caa6026b5c5532225","price":"0.42","side":"SELL","size":"103.2"}],"timestamp":"1785211791464"},"payload_hash":"f826f8467f98023d7c28b48f9e9a9f1b91be7c2943b352d95efbf0c20b81b8ff","raw_frame":"{\"market\":\"0xd412ce774cfcf8dc9f71164aac78783978aac7b03871702a3b8a481bd9dc9688\", \"price_changes\":[{\"asset_id\":\"107603864457683460275633293642179940881969192120168665300712204232021063124301\", \"price\":\"0.58\", \"size\":\"103.2\", \"side\":\"BUY\", \"hash\":\"dbb782b29dab89a6d97aa5808cae7e6e12f8d34f\", \"best_bid\":\"0.6\", \"best_ask\":\"0.61\"}, {\"asset_id\":\"96600821790790307414914106093858868634329285205417149685270682748367152458577\", \"price\":\"0.42\", \"size\":\"103.2\", \"side\":\"SELL\", \"hash\":\"30e165b51818a2d29a6b845caa6026b5c5532225\", \"best_bid\":\"0.39\", \"best_ask\":\"0.4\"}], \"timestamp\":\"1785211791464\", \"event_type\":\"price_change\"}","received_at":"2026-07-28T04:09:51.238302Z","schema_version":"clob-market-ws.price_change.v1","sequence":null,"server_hash":null,"server_timestamp":"1785211791464","session_id":"2d607381e3054cee91998cdf45a4231c","source":"clob_market_ws"},"received_at":"2026-07-28T04:09:51.238302Z","record_id":"7a2c0ae1125eca1fad834c18338bb3af6a6fe15b0c88da9ca498782e88f1f8a8","schema_fingerprint":"4aa3821a28b0b7c2400bc59aba4bcc0a76e971dadd19610d3ad38c768e124dc7","schema_version":"edge-lab-recorder.raw.v1","sequence":null,"source":"clob_market_ws"}
{"event_at":"2026-07-28T04:09:51.466000Z","event_fingerprint":"dfd19c86e1f59e53c00428064670e2a9769f745757f08875880d2d06aeb7fc69","payload":{"connection_id":"f6725804f86a4c4eb588e4d5ed7db029","event_at":"2026-07-28T04:09:51.466000Z","event_type":"price_change","frame_hash":"eb60061cf29fc1d5ed4b398358f9e86fe88b029552c36d5250dfc080fa76ca31","frame_index":0,"kind":"data","monotonic_ns":313774316768958,"payload":{"event_type":"price_change","market":"0xd412ce774cfcf8dc9f71164aac78783978aac7b03871702a3b8a481bd9dc9688","price_changes":[{"asset_id":"96600821790790307414914106093858868634329285205417149685270682748367152458577","best_ask":"0.4","best_bid":"0.39","hash":"fb47712ebc2c7c271b62dc7e50d7704c5bda80a6","price":"0.35","side":"BUY","size":"161.13"},{"asset_id":"107603864457683460275633293642179940881969192120168665300712204232021063124301","best_ask":"0.61","best_bid":"0.6","hash":"6f03188d90654978a91ba42993e9a869a14784ed","price":"0.65","side":"SELL","size":"161.13"}],"timestamp":"1785211791466"},"payload_hash":"2485a095dd8255db86f05e59ca136b4221ef252b406219b165b9c8e1c80f6742","raw_frame":"{\"market\":\"0xd412ce774cfcf8dc9f71164aac78783978aac7b03871702a3b8a481bd9dc9688\", \"price_changes\":[{\"asset_id\":\"96600821790790307414914106093858868634329285205417149685270682748367152458577\", \"price\":\"0.35\", \"size\":\"161.13\", \"side\":\"BUY\", \"hash\":\"fb47712ebc2c7c271b62dc7e50d7704c5bda80a6\", \"best_bid\":\"0.39\", \"best_ask\":\"0.4\"}, {\"asset_id\":\"107603864457683460275633293642179940881969192120168665300712204232021063124301\", \"price\":\"0.65\", \"size\":\"161.13\", \"side\":\"SELL\", \"hash\":\"6f03188d90654978a91ba42993e9a869a14784ed\", \"best_bid\":\"0.6\", \"best_ask\":\"0.61\"}], \"timestamp\":\"1785211791466\", \"event_type\":\"price_change\"}","received_at":"2026-07-28T04:09:51.241020Z","schema_version":"clob-market-ws.price_change.v1","sequence":null,"server_hash":null,"server_timestamp":"1785211791466","session_id":"2d607381e3054cee91998cdf45a4231c","source":"clob_market_ws"},"received_at":"2026-07-28T04:09:51.241020Z","record_id":"843ad63ec2dfae30bec31cc807d23bec807f87eb23caf7845553717ae9d26781","schema_fingerprint":"4aa3821a28b0b7c2400bc59aba4bcc0a76e971dadd19610d3ad38c768e124dc7","schema_version":"edge-lab-recorder.raw.v1","sequence":null,"source":"clob_market_ws"}
{"event_at":"2026-07-28T04:09:51.467000Z","event_fingerprint":"c0f57503c6abe348af0d1bb293c5d2c7933271d0c5adcb45c1f97179963ee035","payload":{"connection_id":"f6725804f86a4c4eb588e4d5ed7db029","event_at":"2026-07-28T04:09:51.467000Z","event_type":"price_change","frame_hash":"5309ad4aae83e790b70098bfa5419ea32b478efe5342c57abea2c72cfb15604e","frame_index":0,"kind":"data","monotonic_ns":313774319279625,"payload":{"event_type":"price_change","market":"0xd412ce774cfcf8dc9f71164aac78783978aac7b03871702a3b8a481bd9dc9688","price_changes":[{"asset_id":"96600821790790307414914106093858868634329285205417149685270682748367152458577","best_ask":"0.4","best_bid":"0.39","hash":"cf2977b3f8ee4624990c0ac0ec2bb98b77b72684","price":"0.42","side":"SELL","size":"78.2"},{"asset_id":"107603864457683460275633293642179940881969192120168665300712204232021063124301","best_ask":"0.61","best_bid":"0.6","hash":"aae3c75917a3cc1f770e84210271ee3c5f515923","price":"0.58","side":"BUY","size":"78.2"}],"timestamp":"1785211791467"},"payload_hash":"bfa177a685c96d8e2f1e29eb6dbd608fefd67999b90c13bd45480b532fdd6fe9","raw_frame":"{\"market\":\"0xd412ce774cfcf8dc9f71164aac78783978aac7b03871702a3b8a481bd9dc9688\", \"price_changes\":[{\"asset_id\":\"96600821790790307414914106093858868634329285205417149685270682748367152458577\", \"price\":\"0.42\", \"size\":\"78.2\", \"side\":\"SELL\", \"hash\":\"cf2977b3f8ee4624990c0ac0ec2bb98b77b72684\", \"best_bid\":\"0.39\", \"best_ask\":\"0.4\"}, {\"asset_id\":\"107603864457683460275633293642179940881969192120168665300712204232021063124301\", \"price\":\"0.58\", \"size\":\"78.2\", \"side\":\"BUY\", \"hash\":\"aae3c75917a3cc1f770e84210271ee3c5f515923\", \"best_bid\":\"0.6\", \"best_ask\":\"0.61\"}], \"timestamp\":\"1785211791467\", \"event_type\":\"price_change\"}","received_at":"2026-07-28T04:09:51.243532Z","schema_version":"clob-market-ws.price_change.v1","sequence":null,"server_hash":null,"server_timestamp":"1785211791467","session_id":"2d607381e3054cee91998cdf45a4231c","source":"clob_market_ws"},"received_at":"2026-07-28T04:09:51.243532Z","record_id":"ef7a61b54678ed088ea7f2b20b6f52a6aa1ad796387caf0169d6b14f0bb88f9d","schema_fingerprint":"4aa3821a28b0b7c2400bc59aba4bcc0a76e971dadd19610d3ad38c768e124dc7","schema_version":"edge-lab-recorder.raw.v1","sequence":null,"source":"clob_market_ws"}
{"event_at":"2026-07-28T04:09:51.487000Z","event_fingerprint":"4c518b3570bbb8d279d375a557704d6646dc35501cd15f89d65d8e26f470900b","payload":{"connection_id":"f6725804f86a4c4eb588e4d5ed7db029","event_at":"2026-07-28T04:09:51.487000Z","event_type":"price_change","frame_hash":"bf30fec1fb47c38d93af6b7b4375a6489c6ebd4e3b0acd99f7f942233805ff2d","frame_index":0,"kind":"data","monotonic_ns":313774338878875,"payload":{"event_type":"price_change","market":"0xd412ce774cfcf8dc9f71164aac78783978aac7b03871702a3b8a481bd9dc9688","price_changes":[{"asset_id":"96600821790790307414914106093858868634329285205417149685270682748367152458577","best_ask":"0.4","best_bid":"0.39","hash":"d70d952c759ccfcbec231c67efd294f5e988f2e9","price":"0.36","side":"BUY","size":"124"},{"asset_id":"107603864457683460275633293642179940881969192120168665300712204232021063124301","best_ask":"0.61","best_bid":"0.6","hash":"093024340f3bff7db28e31c23ef7d332364cd007","price":"0.64","side":"SELL","size":"124"}],"timestamp":"1785211791487"},"payload_hash":"f4f0d69cfc434088f9de9e01dae97add7ca65d40b981b7499ba8140615f17be6","raw_frame":"{\"market\":\"0xd412ce774cfcf8dc9f71164aac78783978aac7b03871702a3b8a481bd9dc9688\", \"price_changes\":[{\"asset_id\":\"96600821790790307414914106093858868634329285205417149685270682748367152458577\", \"price\":\"0.36\", \"size\":\"124\", \"side\":\"BUY\", \"hash\":\"d70d952c759ccfcbec231c67efd294f5e988f2e9\", \"best_bid\":\"0.39\", \"best_ask\":\"0.4\"}, {\"asset_id\":\"107603864457683460275633293642179940881969192120168665300712204232021063124301\", \"price\":\"0.64\", \"size\":\"124\", \"side\":\"SELL\", \"hash\":\"093024340f3bff7db28e31c23ef7d332364cd007\", \"best_bid\":\"0.6\", \"best_ask\":\"0.61\"}], \"timestamp\":\"1785211791487\", \"event_type\":\"price_change\"}","received_at":"2026-07-28T04:09:51.263128Z","schema_version":"clob-market-ws.price_change.v1","sequence":null,"server_hash":null,"server_timestamp":"1785211791487","session_id":"2d607381e3054cee91998cdf45a4231c","source":"clob_market_ws"},"received_at":"2026-07-28T04:09:51.263128Z","record_id":"e9d77e831568fac1aefc21c412451dd2cd57658a95e716ab924aabe6635c2b66","schema_fingerprint":"4aa3821a28b0b7c2400bc59aba4bcc0a76e971dadd19610d3ad38c768e124dc7","schema_version":"edge-lab-recorder.raw.v1","sequence":null,"source":"clob_market_ws"}
{"event_at":"2026-07-28T04:09:51.557000Z","event_fingerprint":"2e7a2f02e4b1dd3957d743a1726744408f5cda331c47ea071d6692b2ca0fc811","payload":{"connection_id":"f6725804f86a4c4eb588e4d5ed7db029","event_at":"2026-07-28T04:09:51.557000Z","event_type":"price_change","frame_hash":"6f50057e0d5a78c0a40b256207d258338cbd5148705c335bd46eff04823981df","frame_index":0,"kind":"data","monotonic_ns":313774407589250,"payload":{"event_type":"price_change","market":"0xd412ce774cfcf8dc9f71164aac78783978aac7b03871702a3b8a481bd9dc9688","price_changes":[{"asset_id":"107603864457683460275633293642179940881969192120168665300712204232021063124301","best_ask":"0.61","best_bid":"0.6","hash":"190cb5ca69de9b0da0f4cdc3b7dad073d43f9daf","price":"0.49","side":"BUY","size":"84.97"},{"asset_id":"96600821790790307414914106093858868634329285205417149685270682748367152458577","best_ask":"0.4","best_bid":"0.39","hash":"db01135be09f79a696c0196bb4c9d74e2538f033","price":"0.51","side":"SELL","size":"84.97"}],"timestamp":"1785211791557"},"payload_hash":"5f392c5a40b29b8e8def2b44359629b9d9eaf8e0f35b0051c75e9c8927817f5e","raw_frame":"{\"market\":\"0xd412ce774cfcf8dc9f71164aac78783978aac7b03871702a3b8a481bd9dc9688\", \"price_changes\":[{\"asset_id\":\"107603864457683460275633293642179940881969192120168665300712204232021063124301\", \"price\":\"0.49\", \"size\":\"84.97\", \"side\":\"BUY\", \"hash\":\"190cb5ca69de9b0da0f4cdc3b7dad073d43f9daf\", \"best_bid\":\"0.6\", \"best_ask\":\"0.61\"}, {\"asset_id\":\"96600821790790307414914106093858868634329285205417149685270682748367152458577\", \"price\":\"0.51\", \"size\":\"84.97\", \"side\":\"SELL\", \"hash\":\"db01135be09f79a696c0196bb4c9d74e2538f033\", \"best_bid\":\"0.39\", \"best_ask\":\"0.4\"}], \"timestamp\":\"1785211791557\", \"event_type\":\"price_change\"}","received_at":"2026-07-28T04:09:51.331838Z","schema_version":"clob-market-ws.price_change.v1","sequence":null,"server_hash":null,"server_timestamp":"1785211791557","session_id":"2d607381e3054cee91998cdf45a4231c","source":"clob_market_ws"},"received_at":"2026-07-28T04:09:51.331838Z","record_id":"91f0c1c297ac69cd1b350d06f6e59e0dcac6f3adc61201079d56bf3a8a7f9998","schema_fingerprint":"4aa3821a28b0b7c2400bc59aba4bcc0a76e971dadd19610d3ad38c768e124dc7","schema_version":"edge-lab-recorder.raw.v1","sequence":null,"source":"clob_market_ws"}
{"event_at":"2026-07-28T04:09:51.583000Z","event_fingerprint":"5db80c99623ac15661c5fc8f663a933c897bec0fc8195779a9bd0862efdfaf82","payload":{"connection_id":"f6725804f86a4c4eb588e4d5ed7db029","event_at":"2026-07-28T04:09:51.583000Z","event_type":"price_change","frame_hash":"82a9fa1711a9a2d9b0f971d3a80965df5fa77c118ef94316d85b88c04bef7959","frame_index":0,"kind":"data","monotonic_ns":313774433059958,"payload":{"event_type":"price_change","market":"0xd412ce774cfcf8dc9f71164aac78783978aac7b03871702a3b8a481bd9dc9688","price_changes":[{"asset_id":"107603864457683460275633293642179940881969192120168665300712204232021063124301","best_ask":"0.61","best_bid":"0.6","hash":"1119a20afc2787c7fad730d6f805634b1291159f","price":"0.04","side":"BUY","size":"623.09"},{"asset_id":"96600821790790307414914106093858868634329285205417149685270682748367152458577","best_ask":"0.4","best_bid":"0.39","hash":"46455ca1c249d129584ad338ddef2e65fe7a5f6b","price":"0.96","side":"SELL","size":"623.09"}],"timestamp":"1785211791583"},"payload_hash":"ac5c27670bfa8fb72145abc9b81b871e4ff22fe3767937ed1571dac8dfdddbcf","raw_frame":"{\"market\":\"0xd412ce774cfcf8dc9f71164aac78783978aac7b03871702a3b8a481bd9dc9688\", \"price_changes\":[{\"asset_id\":\"107603864457683460275633293642179940881969192120168665300712204232021063124301\", \"price\":\"0.04\", \"size\":\"623.09\", \"side\":\"BUY\", \"hash\":\"1119a20afc2787c7fad730d6f805634b1291159f\", \"best_bid\":\"0.6\", \"best_ask\":\"0.61\"}, {\"asset_id\":\"96600821790790307414914106093858868634329285205417149685270682748367152458577\", \"price\":\"0.96\", \"size\":\"623.09\", \"side\":\"SELL\", \"hash\":\"46455ca1c249d129584ad338ddef2e65fe7a5f6b\", \"best_bid\":\"0.39\", \"best_ask\":\"0.4\"}], \"timestamp\":\"1785211791583\", \"event_type\":\"price_change\"}","received_at":"2026-07-28T04:09:51.357309Z","schema_version":"clob-market-ws.price_change.v1","sequence":null,"server_hash":null,"server_timestamp":"1785211791583","session_id":"2d607381e3054cee91998cdf45a4231c","source":"clob_market_ws"},"received_at":"2026-07-28T04:09:51.357309Z","record_id":"65f17966dbed7c2b4bf605aa3638acd5c8e220b2fac310c5acd0ca291a97a2c7","schema_fingerprint":"4aa3821a28b0b7c2400bc59aba4bcc0a76e971dadd19610d3ad38c768e124dc7","schema_version":"edge-lab-recorder.raw.v1","sequence":null,"source":"clob_market_ws"}
{"event_at":"2026-07-28T04:09:51.625000Z","event_fingerprint":"7f78d469d57fdb4f1556929f17372df555c8fd137a64c9727241fdc65bfa4a34","payload":{"connection_id":"f6725804f86a4c4eb588e4d5ed7db029","event_at":"2026-07-28T04:09:51.625000Z","event_type":"price_change","frame_hash":"1400d9f16e53e15f11d3f94db70bb03965057b1d6dfdc8146d54d3d4b13b0571","frame_index":0,"kind":"data","monotonic_ns":313774475505500,"payload":{"event_type":"price_change","market":"0xd412ce774cfcf8dc9f71164aac78783978aac7b03871702a3b8a481bd9dc9688","price_changes":[{"asset_id":"107603864457683460275633293642179940881969192120168665300712204232021063124301","best_ask":"0.61","best_bid":"0.6","hash":"8e7de49824f87730506b081562ab691afc81d0d3","price":"0.41","side":"BUY","size":"29.8"},{"asset_id":"96600821790790307414914106093858868634329285205417149685270682748367152458577","best_ask":"0.4","best_bid":"0.39","hash":"cac4b1df7ed38fd311f36af5fc0d5812fb8e1c09","price":"0.59","side":"SELL","size":"29.8"}],"timestamp":"1785211791625"},"payload_hash":"6004f854ebadd2da2a3ebe9bde7d96f9a31e97155fdbed0fe64e7f9bc8f4b8e0","raw_frame":"{\"market\":\"0xd412ce774cfcf8dc9f71164aac78783978aac7b03871702a3b8a481bd9dc9688\", \"price_changes\":[{\"asset_id\":\"107603864457683460275633293642179940881969192120168665300712204232021063124301\", \"price\":\"0.41\", \"size\":\"29.8\", \"side\":\"BUY\", \"hash\":\"8e7de49824f87730506b081562ab691afc81d0d3\", \"best_bid\":\"0.6\", \"best_ask\":\"0.61\"}, {\"asset_id\":\"96600821790790307414914106093858868634329285205417149685270682748367152458577\", \"price\":\"0.59\", \"size\":\"29.8\", \"side\":\"SELL\", \"hash\":\"cac4b1df7ed38fd311f36af5fc0d5812fb8e1c09\", \"best_bid\":\"0.39\", \"best_ask\":\"0.4\"}], \"timestamp\":\"1785211791625\", \"event_type\":\"price_change\"}","received_at":"2026-07-28T04:09:51.399755Z","schema_version":"clob-market-ws.price_change.v1","sequence":null,"server_hash":null,"server_timestamp":"1785211791625","session_id":"2d607381e3054cee91998cdf45a4231c","source":"clob_market_ws"},"received_at":"2026-07-28T04:09:51.399755Z","record_id":"c3c4a8ea2893e1a8c71007df3bbcf3d72c4315d87f9ed31798f7cb0930fc9b0a","schema_fingerprint":"4aa3821a28b0b7c2400bc59aba4bcc0a76e971dadd19610d3ad38c768e124dc7","schema_version":"edge-lab-recorder.raw.v1","sequence":null,"source":"clob_market_ws"}
{"event_at":"2026-07-28T04:09:51.648000Z","event_fingerprint":"2b0ba89d378edddd33c3b29f1b8e7a85a9d46ade323a64e74ebdf74eec9fe8c1","payload":{"connection_id":"f6725804f86a4c4eb588e4d5ed7db029","event_at":"2026-07-28T04:09:51.648000Z","event_type":"price_change","frame_hash":"716ed44f357dbfb5121ccbc676c5b13bddd9f7ccedf691646d06ff89fed9ef5e","frame_index":0,"kind":"data","monotonic_ns":313774497452166,"payload":{"event_type":"price_change","market":"0xd412ce774cfcf8dc9f71164aac78783978aac7b03871702a3b8a481bd9dc9688","price_changes":[{"asset_id":"107603864457683460275633293642179940881969192120168665300712204232021063124301","best_ask":"0.61","best_bid":"0.6","hash":"ae625cc1b18bf5337f3718d32ea3471aacc0207f","price":"0.04","side":"BUY","size":"618.09"},{"asset_id":"96600821790790307414914106093858868634329285205417149685270682748367152458577","best_ask":"0.4","best_bid":"0.39","hash":"5413ef497312c7a4311fdbba93cbe9f055bcfaa6","price":"0.96","side":"SELL","size":"618.09"}],"timestamp":"1785211791648"},"payload_hash":"4fc13bce72983c405e5b2de8ec06494530732fed590aca0adf456205463cfe5e","raw_frame":"{\"market\":\"0xd412ce774cfcf8dc9f71164aac78783978aac7b03871702a3b8a481bd9dc9688\", \"price_changes\":[{\"asset_id\":\"107603864457683460275633293642179940881969192120168665300712204232021063124301\", \"price\":\"0.04\", \"size\":\"618.09\", \"side\":\"BUY\", \"hash\":\"ae625cc1b18bf5337f3718d32ea3471aacc0207f\", \"best_bid\":\"0.6\", \"best_ask\":\"0.61\"}, {\"asset_id\":\"96600821790790307414914106093858868634329285205417149685270682748367152458577\", \"price\":\"0.96\", \"size\":\"618.09\", \"side\":\"SELL\", \"hash\":\"5413ef497312c7a4311fdbba93cbe9f055bcfaa6\", \"best_bid\":\"0.39\", \"best_ask\":\"0.4\"}], \"timestamp\":\"1785211791648\", \"event_type\":\"price_change\"}","received_at":"2026-07-28T04:09:51.421708Z","schema_version":"clob-market-ws.price_change.v1","sequence":null,"server_hash":null,"server_timestamp":"1785211791648","session_id":"2d607381e3054cee91998cdf45a4231c","source":"clob_market_ws"},"received_at":"2026-07-28T04:09:51.421708Z","record_id":"155da133a2a2f49ce66b4008d0e4499fd697f4879513fd5c7e8f20276252683e","schema_fingerprint":"4aa3821a28b0b7c2400bc59aba4bcc0a76e971dadd19610d3ad38c768e124dc7","schema_version":"edge-lab-recorder.raw.v1","sequence":null,"source":"clob_market_ws"}
{"event_at":"2026-07-28T04:09:51.659000Z","event_fingerprint":"8aa65dadd61c76acd1df81dd0ea8075fc346be860a499110b43d692ecfe3445f","payload":{"connection_id":"f6725804f86a4c4eb588e4d5ed7db029","event_at":"2026-07-28T04:09:51.659000Z","event_type":"price_change","frame_hash":"47768102a4f2e179b309d9ffe6239350dc79568ceb1246617ed8228718ec75f6","frame_index":0,"kind":"data","monotonic_ns":313774510931375,"payload":{"event_type":"price_change","market":"0xd412ce774cfcf8dc9f71164aac78783978aac7b03871702a3b8a481bd9dc9688","price_changes":[{"asset_id":"107603864457683460275633293642179940881969192120168665300712204232021063124301","best_ask":"0.61","best_bid":"0.6","hash":"1915f0a88e34cd3e7b2c32b282bc0642f2cb9678","price":"0.42","side":"BUY","size":"134.91"},{"asset_id":"96600821790790307414914106093858868634329285205417149685270682748367152458577","best_ask":"0.4","best_bid":"0.39","hash":"4c2f4942c8b3d70c3f39cf747b6d9bea275734ba","price":"0.58","side":"SELL","size":"134.91"}],"timestamp":"1785211791659"},"payload_hash":"e248b2130804df020bf1cd82a6d5dfed4ffd13dcd19bcc7dd338298af4528fe9","raw_frame":"{\"market\":\"0xd412ce774cfcf8dc9f71164aac78783978aac7b03871702a3b8a481bd9dc9688\", \"price_changes\":[{\"asset_id\":\"107603864457683460275633293642179940881969192120168665300712204232021063124301\", \"price\":\"0.42\", \"size\":\"134.91\", \"side\":\"BUY\", \"hash\":\"1915f0a88e34cd3e7b2c32b282bc0642f2cb9678\", \"best_bid\":\"0.6\", \"best_ask\":\"0.61\"}, {\"asset_id\":\"96600821790790307414914106093858868634329285205417149685270682748367152458577\", \"price\":\"0.58\", \"size\":\"134.91\", \"side\":\"SELL\", \"hash\":\"4c2f4942c8b3d70c3f39cf747b6d9bea275734ba\", \"best_bid\":\"0.39\", \"best_ask\":\"0.4\"}], \"timestamp\":\"1785211791659\", \"event_type\":\"price_change\"}","received_at":"2026-07-28T04:09:51.435181Z","schema_version":"clob-market-ws.price_change.v1","sequence":null,"server_hash":null,"server_timestamp":"1785211791659","session_id":"2d607381e3054cee91998cdf45a4231c","source":"clob_market_ws"},"received_at":"2026-07-28T04:09:51.435181Z","record_id":"20acb2744a40b665cd960d8a7aa8bc2eb08d2a63ea3bf296a05f7363cfe8b4e4","schema_fingerprint":"4aa3821a28b0b7c2400bc59aba4bcc0a76e971dadd19610d3ad38c768e124dc7","schema_version":"edge-lab-recorder.raw.v1","sequence":null,"source":"clob_market_ws"}
{"event_at":"2026-07-28T04:09:51.716000Z","event_fingerprint":"29d0f00e25214b1d0a817d30d96fbc02c29501054863f8dade1cdde5f04cd8f0","payload":{"connection_id":"f6725804f86a4c4eb588e4d5ed7db029","event_at":"2026-07-28T04:09:51.716000Z","event_type":"price_change","frame_hash":"5b03ab04531ac05a9712bf356ee1739a38d4ff4763a305b78c18f4152f9b0505","frame_index":0,"kind":"data","monotonic_ns":313774566656500,"payload":{"event_type":"price_change","market":"0xd412ce774cfcf8dc9f71164aac78783978aac7b03871702a3b8a481bd9dc9688","price_changes":[{"asset_id":"107603864457683460275633293642179940881969192120168665300712204232021063124301","best_ask":"0.61","best_bid":"0.6","hash":"cac9b2dd0093e942d20d6c3d225f383058d669de","price":"0.01","side":"BUY","size":"5638.02"},{"asset_id":"96600821790790307414914106093858868634329285205417149685270682748367152458577","best_ask":"0.4","best_bid":"0.39","hash":"ed7a3ad6409e7c9209d8e3ee9d6f59117dc112c4","price":"0.99","side":"SELL","size":"5638.02"}],"timestamp":"1785211791716"},"payload_hash":"a1e724f9183e699625fc3b56a85ace5c0e9b9a819403e452005d9e7b6ec538aa","raw_frame":"{\"market\":\"0xd412ce774cfcf8dc9f71164aac78783978aac7b03871702a3b8a481bd9dc9688\", \"price_changes\":[{\"asset_id\":\"107603864457683460275633293642179940881969192120168665300712204232021063124301\", \"price\":\"0.01\", \"size\":\"5638.02\", \"side\":\"BUY\", \"hash\":\"cac9b2dd0093e942d20d6c3d225f383058d669de\", \"best_bid\":\"0.6\", \"best_ask\":\"0.61\"}, {\"asset_id\":\"96600821790790307414914106093858868634329285205417149685270682748367152458577\", \"price\":\"0.99\", \"size\":\"5638.02\", \"side\":\"SELL\", \"hash\":\"ed7a3ad6409e7c9209d8e3ee9d6f59117dc112c4\", \"best_bid\":\"0.39\", \"best_ask\":\"0.4\"}], \"timestamp\":\"1785211791716\", \"event_type\":\"price_change\"}","received_at":"2026-07-28T04:09:51.490905Z","schema_version":"clob-market-ws.price_change.v1","sequence":null,"server_hash":null,"server_timestamp":"1785211791716","session_id":"2d607381e3054cee91998cdf45a4231c","source":"clob_market_ws"},"received_at":"2026-07-28T04:09:51.490905Z","record_id":"6fec35b3bad946ae4a7a732ba6d74c49996931c2fa3f69a0fd08842fd8d6dd79","schema_fingerprint":"4aa3821a28b0b7c2400bc59aba4bcc0a76e971dadd19610d3ad38c768e124dc7","schema_version":"edge-lab-recorder.raw.v1","sequence":null,"source":"clob_market_ws"}
{"event_at":"2026-07-28T04:09:51.738000Z","event_fingerprint":"8614ffbb7b427f687ffbe0b01b88c1546587aaa9cdb78c16bbf0eb39c20630af","payload":{"connection_id":"f6725804f86a4c4eb588e4d5ed7db029","event_at":"2026-07-28T04:09:51.738000Z","event_type":"price_change","frame_hash":"bfda8ebd887b12deb3b69e8396efbc6568d91ef00001d9438d714a82a1f116ac","frame_index":0,"kind":"data","monotonic_ns":313774587570583,"payload":{"event_type":"price_change","market":"0xd412ce774cfcf8dc9f71164aac78783978aac7b03871702a3b8a481bd9dc9688","price_changes":[{"asset_id":"107603864457683460275633293642179940881969192120168665300712204232021063124301","best_ask":"0.61","best_bid":"0.6","hash":"47b2571511cdfbdea6e7ee73b0794a2884a7a8bd","price":"0.01","side":"BUY","size":"5633.02"},{"asset_id":"96600821790790307414914106093858868634329285205417149685270682748367152458577","best_ask":"0.4","best_bid":"0.39","hash":"55d5cb135410e3a19fc28d2385ead48ef98cd005","price":"0.99","side":"SELL","size":"5633.02"}],"timestamp":"1785211791738"},"payload_hash":"8c7f5026ce575debce2558c8fd0d43b348f738142413253829b43ff322816d58","raw_frame":"{\"market\":\"0xd412ce774cfcf8dc9f71164aac78783978aac7b03871702a3b8a481bd9dc9688\", \"price_changes\":[{\"asset_id\":\"107603864457683460275633293642179940881969192120168665300712204232021063124301\", \"price\":\"0.01\", \"size\":\"5633.02\", \"side\":\"BUY\", \"hash\":\"47b2571511cdfbdea6e7ee73b0794a2884a7a8bd\", \"best_bid\":\"0.6\", \"best_ask\":\"0.61\"}, {\"asset_id\":\"96600821790790307414914106093858868634329285205417149685270682748367152458577\", \"price\":\"0.99\", \"size\":\"5633.02\", \"side\":\"SELL\", \"hash\":\"55d5cb135410e3a19fc28d2385ead48ef98cd005\", \"best_bid\":\"0.39\", \"best_ask\":\"0.4\"}], \"timestamp\":\"1785211791738\", \"event_type\":\"price_change\"}","received_at":"2026-07-28T04:09:51.511818Z","schema_version":"clob-market-ws.price_change.v1","sequence":null,"server_hash":null,"server_timestamp":"1785211791738","session_id":"2d607381e3054cee91998cdf45a4231c","source":"clob_market_ws"},"received_at":"2026-07-28T04:09:51.511818Z","record_id":"c98adb1143adbe069fbae83c17c73e899d8bfc600596530c54a1341eda6cd0b5","schema_fingerprint":"4aa3821a28b0b7c2400bc59aba4bcc0a76e971dadd19610d3ad38c768e124dc7","schema_version":"edge-lab-recorder.raw.v1","sequence":null,"source":"clob_market_ws"}
{"event_at":"2026-07-28T04:09:51.750000Z","event_fingerprint":"c5041f0f401091f3d4d717cf5808bf40f75df73ed1e85799723200240eca1a34","payload":{"connection_id":"f6725804f86a4c4eb588e4d5ed7db029","event_at":"2026-07-28T04:09:51.750000Z","event_type":"price_change","frame_hash":"3aa67adb77b1d7ac1a16e77a20b7229e06f9c447241962c5b9be9a7f1a5ce268","frame_index":0,"kind":"data","monotonic_ns":313774601691916,"payload":{"event_type":"price_change","market":"0xd412ce774cfcf8dc9f71164aac78783978aac7b03871702a3b8a481bd9dc9688","price_changes":[{"asset_id":"107603864457683460275633293642179940881969192120168665300712204232021063124301","best_ask":"0.61","best_bid":"0.6","hash":"8c3a071b848ac4d6c875c92873d7b4bffdaa7e12","price":"0.37","side":"BUY","size":"47.9"},{"asset_id":"96600821790790307414914106093858868634329285205417149685270682748367152458577","best_ask":"0.4","best_bid":"0.39","hash":"52115a4eab893291ab703d23e2aaf25947430c64","price":"0.63","side":"SELL","size":"47.9"}],"timestamp":"1785211791750"},"payload_hash":"bd782a54a2fedbc9145cdcecf24fdf9516ab5bc3cf0808a21f53481775955c1b","raw_frame":"{\"market\":\"0xd412ce774cfcf8dc9f71164aac78783978aac7b03871702a3b8a481bd9dc9688\", \"price_changes\":[{\"asset_id\":\"107603864457683460275633293642179940881969192120168665300712204232021063124301\", \"price\":\"0.37\", \"size\":\"47.9\", \"side\":\"BUY\", \"hash\":\"8c3a071b848ac4d6c875c92873d7b4bffdaa7e12\", \"best_bid\":\"0.6\", \"best_ask\":\"0.61\"}, {\"asset_id\":\"96600821790790307414914106093858868634329285205417149685270682748367152458577\", \"price\":\"0.63\", \"size\":\"47.9\", \"side\":\"SELL\", \"hash\":\"52115a4eab893291ab703d23e2aaf25947430c64\", \"best_bid\":\"0.39\", \"best_ask\":\"0.4\"}], \"timestamp\":\"1785211791750\", \"event_type\":\"price_change\"}","received_at":"2026-07-28T04:09:51.525940Z","schema_version":"clob-market-ws.price_change.v1","sequence":null,"server_hash":null,"server_timestamp":"1785211791750","session_id":"2d607381e3054cee91998cdf45a4231c","source":"clob_market_ws"},"received_at":"2026-07-28T04:09:51.525940Z","record_id":"ed3d9da535c98ef863c914c27a3c8f763de099e48640c859ec7416dd1d7b4da0","schema_fingerprint":"4aa3821a28b0b7c2400bc59aba4bcc0a76e971dadd19610d3ad38c768e124dc7","schema_version":"edge-lab-recorder.raw.v1","sequence":null,"source":"clob_market_ws"}
{"event_at":"2026-07-28T04:09:51.752000Z","event_fingerprint":"509ec3d7dcb51e750696b4212e184ffb17b86fbdb5b1cc2fb18057efb72c17aa","payload":{"connection_id":"f6725804f86a4c4eb588e4d5ed7db029","event_at":"2026-07-28T04:09:51.752000Z","event_type":"price_change","frame_hash":"6946d58f466cd6f901d966bdddae20c03b5809da84e881532ba2e923ba35a8a7","frame_index":0,"kind":"data","monotonic_ns":313774604778208,"payload":{"event_type":"price_change","market":"0xd412ce774cfcf8dc9f71164aac78783978aac7b03871702a3b8a481bd9dc9688","price_changes":[{"asset_id":"107603864457683460275633293642179940881969192120168665300712204232021063124301","best_ask":"0.61","best_bid":"0.6","hash":"20043e7bf0d9d3550bc890cbffe4f02f0567a5e7","price":"0.04","side":"BUY","size":"623.09"},{"asset_id":"96600821790790307414914106093858868634329285205417149685270682748367152458577","best_ask":"0.4","best_bid":"0.39","hash":"1fca8e7e2bc326740d544862491520bbd733f679","price":"0.96","side":"SELL","size":"623.09"}],"timestamp":"1785211791752"},"payload_hash":"7983e0a1efa89935b1eba51062c6b1a35d9228e0fd274ab99342e7f6ecf02ed7","raw_frame":"{\"market\":\"0xd412ce774cfcf8dc9f71164aac78783978aac7b03871702a3b8a481bd9dc9688\", \"price_changes\":[{\"asset_id\":\"107603864457683460275633293642179940881969192120168665300712204232021063124301\", \"price\":\"0.04\", \"size\":\"623.09\", \"side\":\"BUY\", \"hash\":\"20043e7bf0d9d3550bc890cbffe4f02f0567a5e7\", \"best_bid\":\"0.6\", \"best_ask\":\"0.61\"}, {\"asset_id\":\"96600821790790307414914106093858868634329285205417149685270682748367152458577\", \"price\":\"0.96\", \"size\":\"623.09\", \"side\":\"SELL\", \"hash\":\"1fca8e7e2bc326740d544862491520bbd733f679\", \"best_bid\":\"0.39\", \"best_ask\":\"0.4\"}], \"timestamp\":\"1785211791752\", \"event_type\":\"price_change\"}","received_at":"2026-07-28T04:09:51.529026Z","schema_version":"clob-market-ws.price_change.v1","sequence":null,"server_hash":null,"server_timestamp":"1785211791752","session_id":"2d607381e3054cee91998cdf45a4231c","source":"clob_market_ws"},"received_at":"2026-07-28T04:09:51.529026Z","record_id":"bd7b8c97c393b00c7c937a5e9dee3754bf1573d4a9de72c543642cb304f286a5","schema_fingerprint":"4aa3821a28b0b7c2400bc59aba4bcc0a76e971dadd19610d3ad38c768e124dc7","schema_version":"edge-lab-recorder.raw.v1","sequence":null,"source":"clob_market_ws"}
{"event_at":"2026-07-28T04:09:51.767000Z","event_fingerprint":"4187dfc4b04894b7ec871947c77e60574751722086112f102f20714f194fb391","payload":{"connection_id":"f6725804f86a4c4eb588e4d5ed7db029","event_at":"2026-07-28T04:09:51.767000Z","event_type":"price_change","frame_hash":"003ab2096fd9fb3f2ac13a4332391cea908521fb6f414e05d5b1a29cb374dff4","frame_index":0,"kind":"data","monotonic_ns":313774617490041,"payload":{"event_type":"price_change","market":"0xd412ce774cfcf8dc9f71164aac78783978aac7b03871702a3b8a481bd9dc9688","price_changes":[{"asset_id":"107603864457683460275633293642179940881969192120168665300712204232021063124301","best_ask":"0.61","best_bid":"0.6","hash":"671bfa832cd551d7e5e4df4fa01d064dedc4dec8","price":"0.57","side":"BUY","size":"91.2"},{"asset_id":"96600821790790307414914106093858868634329285205417149685270682748367152458577","best_ask":"0.4","best_bid":"0.39","hash":"c674b7f21d4211139f942344270b3f54ea7d6101","price":"0.43","side":"SELL","size":"91.2"}],"timestamp":"1785211791767"},"payload_hash":"5ceb70806b2e1711dd5d95eb84d046e9c25d3acb7d0d12349445963f0f0b042c","raw_frame":"{\"market\":\"0xd412ce774cfcf8dc9f71164aac78783978aac7b03871702a3b8a481bd9dc9688\", \"price_changes\":[{\"asset_id\":\"107603864457683460275633293642179940881969192120168665300712204232021063124301\", \"price\":\"0.57\", \"size\":\"91.2\", \"side\":\"BUY\", \"hash\":\"671bfa832cd551d7e5e4df4fa01d064dedc4dec8\", \"best_bid\":\"0.6\", \"best_ask\":\"0.61\"}, {\"asset_id\":\"96600821790790307414914106093858868634329285205417149685270682748367152458577\", \"price\":\"0.43\", \"size\":\"91.2\", \"side\":\"SELL\", \"hash\":\"c674b7f21d4211139f942344270b3f54ea7d6101\", \"best_bid\":\"0.39\", \"best_ask\":\"0.4\"}], \"timestamp\":\"1785211791767\", \"event_type\":\"price_change\"}","received_at":"2026-07-28T04:09:51.541738Z","schema_version":"clob-market-ws.price_change.v1","sequence":null,"server_hash":null,"server_timestamp":"1785211791767","session_id":"2d607381e3054cee91998cdf45a4231c","source":"clob_market_ws"},"received_at":"2026-07-28T04:09:51.541738Z","record_id":"087f25132cc32bf2cdab77d8fde0cd1fe0053e1df004b70d6fdc305b96a3f00e","schema_fingerprint":"4aa3821a28b0b7c2400bc59aba4bcc0a76e971dadd19610d3ad38c768e124dc7","schema_version":"edge-lab-recorder.raw.v1","sequence":null,"source":"clob_market_ws"}
{"event_at":"2026-07-28T04:09:51.770000Z","event_fingerprint":"1e1fc516c54d00498ef7221b8841ba0da9d14417c574261703fa3d7765ee9f8b","payload":{"connection_id":"f6725804f86a4c4eb588e4d5ed7db029","event_at":"2026-07-28T04:09:51.770000Z","event_type":"price_change","frame_hash":"dd7e3fbf3432398e636f395f922e224aaefc8e2933c161b702de6267270e4e61","frame_index":0,"kind":"data","monotonic_ns":313774620858666,"payload":{"event_type":"price_change","market":"0xd412ce774cfcf8dc9f71164aac78783978aac7b03871702a3b8a481bd9dc9688","price_changes":[{"asset_id":"96600821790790307414914106093858868634329285205417149685270682748367152458577","best_ask":"0.4","best_bid":"0.39","hash":"5a93cae254ed24f372ac91e289171c24c9b5fb4a","price":"0.43","side":"SELL","size":"116.2"},{"asset_id":"107603864457683460275633293642179940881969192120168665300712204232021063124301","best_ask":"0.61","best_bid":"0.6","hash":"328843d2e77e01817e143a780a0a0f199c4eed20","price":"0.57","side":"BUY","size":"116.2"}],"timestamp":"1785211791770"},"payload_hash":"651566fafca41872759542fd601b6c75e0aaafcc3749ff9971a4d9cffd58dcda","raw_frame":"{\"market\":\"0xd412ce774cfcf8dc9f71164aac78783978aac7b03871702a3b8a481bd9dc9688\", \"price_changes\":[{\"asset_id\":\"96600821790790307414914106093858868634329285205417149685270682748367152458577\", \"price\":\"0.43\", \"size\":\"116.2\", \"side\":\"SELL\", \"hash\":\"5a93cae254ed24f372ac91e289171c24c9b5fb4a\", \"best_bid\":\"0.39\", \"best_ask\":\"0.4\"}, {\"asset_id\":\"107603864457683460275633293642179940881969192120168665300712204232021063124301\", \"price\":\"0.57\", \"size\":\"116.2\", \"side\":\"BUY\", \"hash\":\"328843d2e77e01817e143a780a0a0f199c4eed20\", \"best_bid\":\"0.6\", \"best_ask\":\"0.61\"}], \"timestamp\":\"1785211791770\", \"event_type\":\"price_change\"}","received_at":"2026-07-28T04:09:51.545107Z","schema_version":"clob-market-ws.price_change.v1","sequence":null,"server_hash":null,"server_timestamp":"1785211791770","session_id":"2d607381e3054cee91998cdf45a4231c","source":"clob_market_ws"},"received_at":"2026-07-28T04:09:51.545107Z","record_id":"f071d8b88f5352346d7e77ed5bb88f8d0da353548ffc933d68013edce2159635","schema_fingerprint":"4aa3821a28b0b7c2400bc59aba4bcc0a76e971dadd19610d3ad38c768e124dc7","schema_version":"edge-lab-recorder.raw.v1","sequence":null,"source":"clob_market_ws"}
{"event_at":"2026-07-28T04:09:51.777000Z","event_fingerprint":"f423d327a113ef64fbcf8b44c33ccb7f8166f1daa3b1c2a9b518def8140f54db","payload":{"connection_id":"f6725804f86a4c4eb588e4d5ed7db029","event_at":"2026-07-28T04:09:51.777000Z","event_type":"price_change","frame_hash":"791b01f939d7a83c49652835b1268d72d3bbda50280dfb2c6fa39559058cb931","frame_index":0,"kind":"data","monotonic_ns":313774627485125,"payload":{"event_type":"price_change","market":"0xd412ce774cfcf8dc9f71164aac78783978aac7b03871702a3b8a481bd9dc9688","price_changes":[{"asset_id":"107603864457683460275633293642179940881969192120168665300712204232021063124301","best_ask":"0.61","best_bid":"0.6","hash":"7c971613e08ed2e3a8d2958d7da600e4dd81e103","price":"0.01","side":"BUY","size":"5638.02"},{"asset_id":"96600821790790307414914106093858868634329285205417149685270682748367152458577","best_ask":"0.4","best_bid":"0.39","hash":"883ea9639dc7b5ba95e10eca510bc137ccf8d81c","price":"0.99","side":"SELL","size":"5638.02"}],"timestamp":"1785211791777"},"payload_hash":"423c2e8bb18fbdb9fb1e0fe303d4c653d6c680d0742c82aaa9677383f4445c05","raw_frame":"{\"market\":\"0xd412ce774cfcf8dc9f71164aac78783978aac7b03871702a3b8a481bd9dc9688\", \"price_changes\":[{\"asset_id\":\"107603864457683460275633293642179940881969192120168665300712204232021063124301\", \"price\":\"0.01\", \"size\":\"5638.02\", \"side\":\"BUY\", \"hash\":\"7c971613e08ed2e3a8d2958d7da600e4dd81e103\", \"best_bid\":\"0.6\", \"best_ask\":\"0.61\"}, {\"asset_id\":\"96600821790790307414914106093858868634329285205417149685270682748367152458577\", \"price\":\"0.99\", \"size\":\"5638.02\", \"side\":\"SELL\", \"hash\":\"883ea9639dc7b5ba95e10eca510bc137ccf8d81c\", \"best_bid\":\"0.39\", \"best_ask\":\"0.4\"}], \"timestamp\":\"1785211791777\", \"event_type\":\"price_change\"}","received_at":"2026-07-28T04:09:51.551733Z","schema_version":"clob-market-ws.price_change.v1","sequence":null,"server_hash":null,"server_timestamp":"1785211791777","session_id":"2d607381e3054cee91998cdf45a4231c","source":"clob_market_ws"},"received_at":"2026-07-28T04:09:51.551733Z","record_id":"585b4e1873b7b22e5456df988d68d8e36250c53d6d2c2b9d574f16b2fc521f09","schema_fingerprint":"4aa3821a28b0b7c2400bc59aba4bcc0a76e971dadd19610d3ad38c768e124dc7","schema_version":"edge-lab-recorder.raw.v1","sequence":null,"source":"clob_market_ws"}
{"event_at":"2026-07-28T04:09:51.784000Z","event_fingerprint":"35ca7fddb0cfe8241cad4afb42eccec03dad464a67b2235d5c118e4706b2d796","payload":{"connection_id":"f6725804f86a4c4eb588e4d5ed7db029","event_at":"2026-07-28T04:09:51.784000Z","event_type":"price_change","frame_hash":"9d4ca1756eb30fd112e90fd086fdc67f5e42c38abb4b8e82ad5dbe52d62ee624","frame_index":0,"kind":"data","monotonic_ns":313774635674458,"payload":{"event_type":"price_change","market":"0xd412ce774cfcf8dc9f71164aac78783978aac7b03871702a3b8a481bd9dc9688","price_changes":[{"asset_id":"107603864457683460275633293642179940881969192120168665300712204232021063124301","best_ask":"0.61","best_bid":"0.6","hash":"8648e793fe0e494895633ad7508110fb1b2c70af","price":"0.39","side":"BUY","size":"32.6"},{"asset_id":"96600821790790307414914106093858868634329285205417149685270682748367152458577","best_ask":"0.4","best_bid":"0.39","hash":"e35f644eb88d011e44deaa275d61654a61bbcc00","price":"0.61","side":"SELL","size":"32.6"}],"timestamp":"1785211791784"},"payload_hash":"04e47cf3553f4e77995c265581d6994747b1118a8d03c58fcb714024858ee3cd","raw_frame":"{\"market\":\"0xd412ce774cfcf8dc9f71164aac78783978aac7b03871702a3b8a481bd9dc9688\", \"price_changes\":[{\"asset_id\":\"107603864457683460275633293642179940881969192120168665300712204232021063124301\", \"price\":\"0.39\", \"size\":\"32.6\", \"side\":\"BUY\", \"hash\":\"8648e793fe0e494895633ad7508110fb1b2c70af\", \"best_bid\":\"0.6\", \"best_ask\":\"0.61\"}, {\"asset_id\":\"96600821790790307414914106093858868634329285205417149685270682748367152458577\", \"price\":\"0.61\", \"size\":\"32.6\", \"side\":\"SELL\", \"hash\":\"e35f644eb88d011e44deaa275d61654a61bbcc00\", \"best_bid\":\"0.39\", \"best_ask\":\"0.4\"}], \"timestamp\":\"1785211791784\", \"event_type\":\"price_change\"}","received_at":"2026-07-28T04:09:51.559920Z","schema_version":"clob-market-ws.price_change.v1","sequence":null,"server_hash":null,"server_timestamp":"1785211791784","session_id":"2d607381e3054cee91998cdf45a4231c","source":"clob_market_ws"},"received_at":"2026-07-28T04:09:51.559920Z","record_id":"01abc7f565d35a661dd04023d2becb32176a083dcc8ca301f705c6f15be36b3d","schema_fingerprint":"4aa3821a28b0b7c2400bc59aba4bcc0a76e971dadd19610d3ad38c768e124dc7","schema_version":"edge-lab-recorder.raw.v1","sequence":null,"source":"clob_market_ws"}
{"event_at":"2026-07-28T04:09:51.785000Z","event_fingerprint":"e1e0e8de9ca964204a00e787252e74fa433a079c95f4b7e9e703c8391f30272a","payload":{"connection_id":"f6725804f86a4c4eb588e4d5ed7db029","event_at":"2026-07-28T04:09:51.785000Z","event_type":"price_change","frame_hash":"108dfe53beec3a7f182934b2fbcc708c96a951e73ea02524f4575224eb00869b","frame_index":0,"kind":"data","monotonic_ns":313774638722541,"payload":{"event_type":"price_change","market":"0xd412ce774cfcf8dc9f71164aac78783978aac7b03871702a3b8a481bd9dc9688","price_changes":[{"asset_id":"96600821790790307414914106093858868634329285205417149685270682748367152458577","best_ask":"0.4","best_bid":"0.39","hash":"bbf52c1f2edc94e9dc90b481a3d676565c718888","price":"0.39","side":"BUY","size":"102.2"},{"asset_id":"107603864457683460275633293642179940881969192120168665300712204232021063124301","best_ask":"0.61","best_bid":"0.6","hash":"343685d492f069e5709c5de8b2aa2521db6942f4","price":"0.61","side":"SELL","size":"102.2"}],"timestamp":"1785211791785"},"payload_hash":"e1309d508e4bdb34305c9aedd420cb12524e71c712dd9a861112d9bd6ea9b409","raw_frame":"{\"market\":\"0xd412ce774cfcf8dc9f71164aac78783978aac7b03871702a3b8a481bd9dc9688\", \"price_changes\":[{\"asset_id\":\"96600821790790307414914106093858868634329285205417149685270682748367152458577\", \"price\":\"0.39\", \"size\":\"102.2\", \"side\":\"BUY\", \"hash\":\"bbf52c1f2edc94e9dc90b481a3d676565c718888\", \"best_bid\":\"0.39\", \"best_ask\":\"0.4\"}, {\"asset_id\":\"107603864457683460275633293642179940881969192120168665300712204232021063124301\", \"price\":\"0.61\", \"size\":\"102.2\", \"side\":\"SELL\", \"hash\":\"343685d492f069e5709c5de8b2aa2521db6942f4\", \"best_bid\":\"0.6\", \"best_ask\":\"0.61\"}], \"timestamp\":\"1785211791785\", \"event_type\":\"price_change\"}","received_at":"2026-07-28T04:09:51.562971Z","schema_version":"clob-market-ws.price_change.v1","sequence":null,"server_hash":null,"server_timestamp":"1785211791785","session_id":"2d607381e3054cee91998cdf45a4231c","source":"clob_market_ws"},"received_at":"2026-07-28T04:09:51.562971Z","record_id":"be9c2e74b862247909df82f7926493ad2a1fd3797eb57fbc762f21609db6d058","schema_fingerprint":"4aa3821a28b0b7c2400bc59aba4bcc0a76e971dadd19610d3ad38c768e124dc7","schema_version":"edge-lab-recorder.raw.v1","sequence":null,"source":"clob_market_ws"}
{"event_at":"2026-07-28T04:09:51.791000Z","event_fingerprint":"3a839e8d6aceb9777ee068c26f4e6e0965f1944b24e599a136c07b0e4f31ace5","payload":{"connection_id":"f6725804f86a4c4eb588e4d5ed7db029","event_at":"2026-07-28T04:09:51.791000Z","event_type":"price_change","frame_hash":"efad2b7462269d67d2ca070bb511000fe3cf3356aede79d9586c7af6a409278d","frame_index":0,"kind":"data","monotonic_ns":313774641353458,"payload":{"event_type":"price_change","market":"0xd412ce774cfcf8dc9f71164aac78783978aac7b03871702a3b8a481bd9dc9688","price_changes":[{"asset_id":"107603864457683460275633293642179940881969192120168665300712204232021063124301","best_ask":"0.61","best_bid":"0.6","hash":"a2f4fdec7ba554b286579a5626e707884f981d64","price":"0.04","side":"BUY","size":"618.09"},{"asset_id":"96600821790790307414914106093858868634329285205417149685270682748367152458577","best_ask":"0.4","best_bid":"0.39","hash":"4bb3599a907e623fe7b81c7db91f15b13202ce26","price":"0.96","side":"SELL","size":"618.09"}],"timestamp":"1785211791791"},"payload_hash":"d5567462fd03d22ff119a27931c479cfac5580d79567e368eb13030f02b6f33b","raw_frame":"{\"market\":\"0xd412ce774cfcf8dc9f71164aac78783978aac7b03871702a3b8a481bd9dc9688\", \"price_changes\":[{\"asset_id\":\"107603864457683460275633293642179940881969192120168665300712204232021063124301\", \"price\":\"0.04\", \"size\":\"618.09\", \"side\":\"BUY\", \"hash\":\"a2f4fdec7ba554b286579a5626e707884f981d64\", \"best_bid\":\"0.6\", \"best_ask\":\"0.61\"}, {\"asset_id\":\"96600821790790307414914106093858868634329285205417149685270682748367152458577\", \"price\":\"0.96\", \"size\":\"618.09\", \"side\":\"SELL\", \"hash\":\"4bb3599a907e623fe7b81c7db91f15b13202ce26\", \"best_bid\":\"0.39\", \"best_ask\":\"0.4\"}], \"timestamp\":\"1785211791791\", \"event_type\":\"price_change\"}","received_at":"2026-07-28T04:09:51.565602Z","schema_version":"clob-market-ws.price_change.v1","sequence":null,"server_hash":null,"server_timestamp":"1785211791791","session_id":"2d607381e3054cee91998cdf45a4231c","source":"clob_market_ws"},"received_at":"2026-07-28T04:09:51.565602Z","record_id":"ecd0ff8db66808009bb2adc4355a170266a88f76684e8a8c76fe39f2765e0074","schema_fingerprint":"4aa3821a28b0b7c2400bc59aba4bcc0a76e971dadd19610d3ad38c768e124dc7","schema_version":"edge-lab-recorder.raw.v1","sequence":null,"source":"clob_market_ws"}
{"event_at":"2026-07-28T04:09:51.806000Z","event_fingerprint":"e0a5e6c24711d8d9a08bd802e91b03314bbc2ff8d4b1b9f8f40d69bbe3101f54","payload":{"connection_id":"f6725804f86a4c4eb588e4d5ed7db029","event_at":"2026-07-28T04:09:51.806000Z","event_type":"price_change","frame_hash":"a9b47fe90e5503690a9b0e70643799773987f27099d833ccf29acf73bcc27487","frame_index":0,"kind":"data","monotonic_ns":313774657215500,"payload":{"event_type":"price_change","market":"0xd412ce774cfcf8dc9f71164aac78783978aac7b03871702a3b8a481bd9dc9688","price_changes":[{"asset_id":"107603864457683460275633293642179940881969192120168665300712204232021063124301","best_ask":"0.61","best_bid":"0.6","hash":"6135fa5b9688dc97a992e8c616dab2371763d933","price":"0.01","side":"BUY","size":"5633.02"},{"asset_id":"96600821790790307414914106093858868634329285205417149685270682748367152458577","best_ask":"0.4","best_bid":"0.39","hash":"7a3bc1f843ec86d01c7f507407e593a616e1cf81","price":"0.99","side":"SELL","size":"5633.02"}],"timestamp":"1785211791806"},"payload_hash":"4f7f235be30d55731909ce6d9bbd98af2e0964c9093f6339b3a12cfeca1dda08","raw_frame":"{\"market\":\"0xd412ce774cfcf8dc9f71164aac78783978aac7b03871702a3b8a481bd9dc9688\", \"price_changes\":[{\"asset_id\":\"107603864457683460275633293642179940881969192120168665300712204232021063124301\", \"price\":\"0.01\", \"size\":\"5633.02\", \"side\":\"BUY\", \"hash\":\"6135fa5b9688dc97a992e8c616dab2371763d933\", \"best_bid\":\"0.6\", \"best_ask\":\"0.61\"}, {\"asset_id\":\"96600821790790307414914106093858868634329285205417149685270682748367152458577\", \"price\":\"0.99\", \"size\":\"5633.02\", \"side\":\"SELL\", \"hash\":\"7a3bc1f843ec86d01c7f507407e593a616e1cf81\", \"best_bid\":\"0.39\", \"best_ask\":\"0.4\"}], \"timestamp\":\"1785211791806\", \"event_type\":\"price_change\"}","received_at":"2026-07-28T04:09:51.581464Z","schema_version":"clob-market-ws.price_change.v1","sequence":null,"server_hash":null,"server_timestamp":"1785211791806","session_id":"2d607381e3054cee91998cdf45a4231c","source":"clob_market_ws"},"received_at":"2026-07-28T04:09:51.581464Z","record_id":"2282dc291a779c45d70913f7935b0d55a8d50501e1a800c81d557798c6fdab90","schema_fingerprint":"4aa3821a28b0b7c2400bc59aba4bcc0a76e971dadd19610d3ad38c768e124dc7","schema_version":"edge-lab-recorder.raw.v1","sequence":null,"source":"clob_market_ws"}
{"event_at":"2026-07-28T04:09:51.899000Z","event_fingerprint":"743c3e3194b10eff337400f0b4c57dfebfc7300ab6aa221649def1969a9d6eab","payload":{"connection_id":"f6725804f86a4c4eb588e4d5ed7db029","event_at":"2026-07-28T04:09:51.899000Z","event_type":"price_change","frame_hash":"21c1b2bd238b301064376e28effb5d817912f2853ae3ed6d60dd6f83faa9dfa7","frame_index":0,"kind":"data","monotonic_ns":313774749522166,"payload":{"event_type":"price_change","market":"0xd412ce774cfcf8dc9f71164aac78783978aac7b03871702a3b8a481bd9dc9688","price_changes":[{"asset_id":"107603864457683460275633293642179940881969192120168665300712204232021063124301","best_ask":"0.61","best_bid":"0.6","hash":"0cc503d23206a5f00f3409f60ac9e47fac196442","price":"0.02","side":"BUY","size":"688.1"},{"asset_id":"96600821790790307414914106093858868634329285205417149685270682748367152458577","best_ask":"0.4","best_bid":"0.39","hash":"c0f8725cd186e4eabbaf6b5040346428dca1aed6","price":"0.98","side":"SELL","size":"688.1"}],"timestamp":"1785211791899"},"payload_hash":"3ed4d76d4b508e2c4d8a6660b7d5a3a01004885f70db53f3f305eca91eed7be7","raw_frame":"{\"market\":\"0xd412ce774cfcf8dc9f71164aac78783978aac7b03871702a3b8a481bd9dc9688\", \"price_changes\":[{\"asset_id\":\"107603864457683460275633293642179940881969192120168665300712204232021063124301\", \"price\":\"0.02\", \"size\":\"688.1\", \"side\":\"BUY\", \"hash\":\"0cc503d23206a5f00f3409f60ac9e47fac196442\", \"best_bid\":\"0.6\", \"best_ask\":\"0.61\"}, {\"asset_id\":\"96600821790790307414914106093858868634329285205417149685270682748367152458577\", \"price\":\"0.98\", \"size\":\"688.1\", \"side\":\"SELL\", \"hash\":\"c0f8725cd186e4eabbaf6b5040346428dca1aed6\", \"best_bid\":\"0.39\", \"best_ask\":\"0.4\"}], \"timestamp\":\"1785211791899\", \"event_type\":\"price_change\"}","received_at":"2026-07-28T04:09:51.673768Z","schema_version":"clob-market-ws.price_change.v1","sequence":null,"server_hash":null,"server_timestamp":"1785211791899","session_id":"2d607381e3054cee91998cdf45a4231c","source":"clob_market_ws"},"received_at":"2026-07-28T04:09:51.673768Z","record_id":"25eb5e9cdf151dc605806991d5d48e49df91f15de14ff3d1f6c8d9aa2e67bb17","schema_fingerprint":"4aa3821a28b0b7c2400bc59aba4bcc0a76e971dadd19610d3ad38c768e124dc7","schema_version":"edge-lab-recorder.raw.v1","sequence":null,"source":"clob_market_ws"}
{"event_at":"2026-07-28T04:09:51.953000Z","event_fingerprint":"6a22becf4a06d514444beb08eb909399428e285df7ac79fc408c1baf2c361d23","payload":{"connection_id":"f6725804f86a4c4eb588e4d5ed7db029","event_at":"2026-07-28T04:09:51.953000Z","event_type":"price_change","frame_hash":"e9f483a8b77942f9b677de0fcf14f7d48ebe3052ccacfc1cebcce258ab7ee35e","frame_index":0,"kind":"data","monotonic_ns":313774803221083,"payload":{"event_type":"price_change","market":"0xd412ce774cfcf8dc9f71164aac78783978aac7b03871702a3b8a481bd9dc9688","price_changes":[{"asset_id":"107603864457683460275633293642179940881969192120168665300712204232021063124301","best_ask":"0.61","best_bid":"0.6","hash":"6d17eb0de9312d4db3fecd66e06f17171fc65427","price":"0.48","side":"BUY","size":"21"},{"asset_id":"96600821790790307414914106093858868634329285205417149685270682748367152458577","best_ask":"0.4","best_bid":"0.39","hash":"ea5ab33ecd60e9c3885a737327d6e9c6e8900d2d","price":"0.52","side":"SELL","size":"21"}],"timestamp":"1785211791953"},"payload_hash":"08b3c753233def11423f2cfdc10ccffaf9c71230353cfc35ebeaaa343ca3ee95","raw_frame":"{\"market\":\"0xd412ce774cfcf8dc9f71164aac78783978aac7b03871702a3b8a481bd9dc9688\", \"price_changes\":[{\"asset_id\":\"107603864457683460275633293642179940881969192120168665300712204232021063124301\", \"price\":\"0.48\", \"size\":\"21\", \"side\":\"BUY\", \"hash\":\"6d17eb0de9312d4db3fecd66e06f17171fc65427\", \"best_bid\":\"0.6\", \"best_ask\":\"0.61\"}, {\"asset_id\":\"96600821790790307414914106093858868634329285205417149685270682748367152458577\", \"price\":\"0.52\", \"size\":\"21\", \"side\":\"SELL\", \"hash\":\"ea5ab33ecd60e9c3885a737327d6e9c6e8900d2d\", \"best_bid\":\"0.39\", \"best_ask\":\"0.4\"}], \"timestamp\":\"1785211791953\", \"event_type\":\"price_change\"}","received_at":"2026-07-28T04:09:51.727466Z","schema_version":"clob-market-ws.price_change.v1","sequence":null,"server_hash":null,"server_timestamp":"1785211791953","session_id":"2d607381e3054cee91998cdf45a4231c","source":"clob_market_ws"},"received_at":"2026-07-28T04:09:51.727466Z","record_id":"ccbe29d78be22b28302e7cf3e4822bcf24269d680bdfa1b33f832930cc5b5789","schema_fingerprint":"4aa3821a28b0b7c2400bc59aba4bcc0a76e971dadd19610d3ad38c768e124dc7","schema_version":"edge-lab-recorder.raw.v1","sequence":null,"source":"clob_market_ws"}
{"event_at":"2026-07-28T04:09:51.977000Z","event_fingerprint":"2301861755d0b794f928c705e36582a5d980c899fb0343226fe3868eea1f3335","payload":{"connection_id":"f6725804f86a4c4eb588e4d5ed7db029","event_at":"2026-07-28T04:09:51.977000Z","event_type":"price_change","frame_hash":"4333ee57e1b2f62430bfe78a25901084325a9019e286354064172837c5e22a31","frame_index":0,"kind":"data","monotonic_ns":313774827092083,"payload":{"event_type":"price_change","market":"0xd412ce774cfcf8dc9f71164aac78783978aac7b03871702a3b8a481bd9dc9688","price_changes":[{"asset_id":"107603864457683460275633293642179940881969192120168665300712204232021063124301","best_ask":"0.61","best_bid":"0.6","hash":"546fea4be5583d3fef183555118e345da4cf79e9","price":"0.02","side":"BUY","size":"683.1"},{"asset_id":"96600821790790307414914106093858868634329285205417149685270682748367152458577","best_ask":"0.4","best_bid":"0.39","hash":"ed59f1feeb1fb6fa21fcea72c34399488a9fcd2f","price":"0.98","side":"SELL","size":"683.1"}],"timestamp":"1785211791977"},"payload_hash":"d6ed8dc76d44ffa8ab0166e8d2be16cada66403f48c74a0da01af007cabe6f8e","raw_frame":"{\"market\":\"0xd412ce774cfcf8dc9f71164aac78783978aac7b03871702a3b8a481bd9dc9688\", \"price_changes\":[{\"asset_id\":\"107603864457683460275633293642179940881969192120168665300712204232021063124301\", \"price\":\"0.02\", \"size\":\"683.1\", \"side\":\"BUY\", \"hash\":\"546fea4be5583d3fef183555118e345da4cf79e9\", \"best_bid\":\"0.6\", \"best_ask\":\"0.61\"}, {\"asset_id\":\"96600821790790307414914106093858868634329285205417149685270682748367152458577\", \"price\":\"0.98\", \"size\":\"683.1\", \"side\":\"SELL\", \"hash\":\"ed59f1feeb1fb6fa21fcea72c34399488a9fcd2f\", \"best_bid\":\"0.39\", \"best_ask\":\"0.4\"}], \"timestamp\":\"1785211791977\", \"event_type\":\"price_change\"}","received_at":"2026-07-28T04:09:51.751337Z","schema_version":"clob-market-ws.price_change.v1","sequence":null,"server_hash":null,"server_timestamp":"1785211791977","session_id":"2d607381e3054cee91998cdf45a4231c","source":"clob_market_ws"},"received_at":"2026-07-28T04:09:51.751337Z","record_id":"e21430635fe3d88a19e0f4bb2a51f587ead61fa4fa610513e34490e127ea2a79","schema_fingerprint":"4aa3821a28b0b7c2400bc59aba4bcc0a76e971dadd19610d3ad38c768e124dc7","schema_version":"edge-lab-recorder.raw.v1","sequence":null,"source":"clob_market_ws"}
{"event_at":"2026-07-28T04:09:51.999000Z","event_fingerprint":"1a43a6c3bea01aec6983fcf176d85c27d47c44cc5b6ffd80df73c42ff4a593ea","payload":{"connection_id":"f6725804f86a4c4eb588e4d5ed7db029","event_at":"2026-07-28T04:09:51.999000Z","event_type":"price_change","frame_hash":"916d714f885507f2647ee47c531590bdfdf734bbd7d06482f21cced8e4655843","frame_index":0,"kind":"data","monotonic_ns":313774854775541,"payload":{"event_type":"price_change","market":"0xd412ce774cfcf8dc9f71164aac78783978aac7b03871702a3b8a481bd9dc9688","price_changes":[{"asset_id":"107603864457683460275633293642179940881969192120168665300712204232021063124301","best_ask":"0.61","best_bid":"0.6","hash":"e81984e67e343e8ac4b876639ae980fa578a70f1","price":"0.36","side":"BUY","size":"18"},{"asset_id":"96600821790790307414914106093858868634329285205417149685270682748367152458577","best_ask":"0.4","best_bid":"0.39","hash":"253b7baced073421beddcd09390f82f2851d5fbf","price":"0.64","side":"SELL","size":"18"}],"timestamp":"1785211791999"},"payload_hash":"774177042e4cccee474009d8cea6ea1fe6a0ecefebae30ba9773dca5bd0bac50","raw_frame":"{\"market\":\"0xd412ce774cfcf8dc9f71164aac78783978aac7b03871702a3b8a481bd9dc9688\", \"price_changes\":[{\"asset_id\":\"107603864457683460275633293642179940881969192120168665300712204232021063124301\", \"price\":\"0.36\", \"size\":\"18\", \"side\":\"BUY\", \"hash\":\"e81984e67e343e8ac4b876639ae980fa578a70f1\", \"best_bid\":\"0.6\", \"best_ask\":\"0.61\"}, {\"asset_id\":\"96600821790790307414914106093858868634329285205417149685270682748367152458577\", \"price\":\"0.64\", \"size\":\"18\", \"side\":\"SELL\", \"hash\":\"253b7baced073421beddcd09390f82f2851d5fbf\", \"best_bid\":\"0.39\", \"best_ask\":\"0.4\"}], \"timestamp\":\"1785211791999\", \"event_type\":\"price_change\"}","received_at":"2026-07-28T04:09:51.779024Z","schema_version":"clob-market-ws.price_change.v1","sequence":null,"server_hash":null,"server_timestamp":"1785211791999","session_id":"2d607381e3054cee91998cdf45a4231c","source":"clob_market_ws"},"received_at":"2026-07-28T04:09:51.779024Z","record_id":"83e6be88180bccc6ccbb13645ee9b5d833aaf1d7007ee4dffbd3572336fb8b67","schema_fingerprint":"4aa3821a28b0b7c2400bc59aba4bcc0a76e971dadd19610d3ad38c768e124dc7","schema_version":"edge-lab-recorder.raw.v1","sequence":null,"source":"clob_market_ws"}
{"event_at":"2026-07-28T04:09:52.026000Z","event_fingerprint":"e52b9f8c196ab25bfa31182d6a693a9c8e061a66000bd24c412c422062ed4766","payload":{"connection_id":"f6725804f86a4c4eb588e4d5ed7db029","event_at":"2026-07-28T04:09:52.026000Z","event_type":"price_change","frame_hash":"8a64a7fdb0337f4baf294ae95f0818294c7282623beefdd0034a70b291afe9e7","frame_index":0,"kind":"data","monotonic_ns":313774877872041,"payload":{"event_type":"price_change","market":"0xd412ce774cfcf8dc9f71164aac78783978aac7b03871702a3b8a481bd9dc9688","price_changes":[{"asset_id":"96600821790790307414914106093858868634329285205417149685270682748367152458577","best_ask":"0.4","best_bid":"0.39","hash":"35490f870ea64e257d7ff79d05e31243777626ec","price":"0.01","side":"BUY","size":"5608.02"},{"asset_id":"107603864457683460275633293642179940881969192120168665300712204232021063124301","best_ask":"0.61","best_bid":"0.6","hash":"47a2bf34b4fc00c28f559021d72704c540f0c020","price":"0.99","side":"SELL","size":"5608.02"}],"timestamp":"1785211792026"},"payload_hash":"82961168e99d34dda64ce1827a26ff170c153588081b6f5c39f9ed3d08099efa","raw_frame":"{\"market\":\"0xd412ce774cfcf8dc9f71164aac78783978aac7b03871702a3b8a481bd9dc9688\", \"price_changes\":[{\"asset_id\":\"96600821790790307414914106093858868634329285205417149685270682748367152458577\", \"price\":\"0.01\", \"size\":\"5608.02\", \"side\":\"BUY\", \"hash\":\"35490f870ea64e257d7ff79d05e31243777626ec\", \"best_bid\":\"0.39\", \"best_ask\":\"0.4\"}, {\"asset_id\":\"107603864457683460275633293642179940881969192120168665300712204232021063124301\", \"price\":\"0.99\", \"size\":\"5608.02\", \"side\":\"SELL\", \"hash\":\"47a2bf34b4fc00c28f559021d72704c540f0c020\", \"best_bid\":\"0.6\", \"best_ask\":\"0.61\"}], \"timestamp\":\"1785211792026\", \"event_type\":\"price_change\"}","received_at":"2026-07-28T04:09:51.802122Z","schema_version":"clob-market-ws.price_change.v1","sequence":null,"server_hash":null,"server_timestamp":"1785211792026","session_id":"2d607381e3054cee91998cdf45a4231c","source":"clob_market_ws"},"received_at":"2026-07-28T04:09:51.802122Z","record_id":"4378079d7e9c097c760a4d1d538ae9ccde8dbeb03e3b6c27a2712aa335622898","schema_fingerprint":"4aa3821a28b0b7c2400bc59aba4bcc0a76e971dadd19610d3ad38c768e124dc7","schema_version":"edge-lab-recorder.raw.v1","sequence":null,"source":"clob_market_ws"}
{"event_at":"2026-07-28T04:09:52.031000Z","event_fingerprint":"36ab08d0f122f6d7b758dec27bcb2fc2b8cd0b6561c81c098d8bb4419bfb4fd7","payload":{"connection_id":"f6725804f86a4c4eb588e4d5ed7db029","event_at":"2026-07-28T04:09:52.031000Z","event_type":"price_change","frame_hash":"2429a295e4285aa9c7b7a1aaee6c2f5b60372cf7aecce60dee39cf025cb4ddf6","frame_index":0,"kind":"data","monotonic_ns":313774882399000,"payload":{"event_type":"price_change","market":"0xd412ce774cfcf8dc9f71164aac78783978aac7b03871702a3b8a481bd9dc9688","price_changes":[{"asset_id":"107603864457683460275633293642179940881969192120168665300712204232021063124301","best_ask":"0.61","best_bid":"0.6","hash":"014d6ceedaff6aa05786b1bfa37f463b499c031b","price":"0.37","side":"BUY","size":"62.9"},{"asset_id":"96600821790790307414914106093858868634329285205417149685270682748367152458577","best_ask":"0.4","best_bid":"0.39","hash":"a5ca9f4e766a05c2f305a9b88dfd140d93aeb882","price":"0.63","side":"SELL","size":"62.9"}],"timestamp":"1785211792031"},"payload_hash":"7c4e4fea991939ff48f8bf51d3b1021c88b7617dfd4bcd61f8146b21849afa20","raw_frame":"{\"market\":\"0xd412ce774cfcf8dc9f71164aac78783978aac7b03871702a3b8a481bd9dc9688\", \"price_changes\":[{\"asset_id\":\"107603864457683460275633293642179940881969192120168665300712204232021063124301\", \"price\":\"0.37\", \"size\":\"62.9\", \"side\":\"BUY\", \"hash\":\"014d6ceedaff6aa05786b1bfa37f463b499c031b\", \"best_bid\":\"0.6\", \"best_ask\":\"0.61\"}, {\"asset_id\":\"96600821790790307414914106093858868634329285205417149685270682748367152458577\", \"price\":\"0.63\", \"size\":\"62.9\", \"side\":\"SELL\", \"hash\":\"a5ca9f4e766a05c2f305a9b88dfd140d93aeb882\", \"best_bid\":\"0.39\", \"best_ask\":\"0.4\"}], \"timestamp\":\"1785211792031\", \"event_type\":\"price_change\"}","received_at":"2026-07-28T04:09:51.806651Z","schema_version":"clob-market-ws.price_change.v1","sequence":null,"server_hash":null,"server_timestamp":"1785211792031","session_id":"2d607381e3054cee91998cdf45a4231c","source":"clob_market_ws"},"received_at":"2026-07-28T04:09:51.806651Z","record_id":"68ae01593978647119a413e7f977988f30a86ace5811cd634e6bf44469bd4b07","schema_fingerprint":"4aa3821a28b0b7c2400bc59aba4bcc0a76e971dadd19610d3ad38c768e124dc7","schema_version":"edge-lab-recorder.raw.v1","sequence":null,"source":"clob_market_ws"}
{"event_at":"2026-07-28T04:09:52.033000Z","event_fingerprint":"9a4ea1d3eb469ea76e1f4985ed4659b8acec3dcaced99dfccfda85dd892c54ad","payload":{"connection_id":"f6725804f86a4c4eb588e4d5ed7db029","event_at":"2026-07-28T04:09:52.033000Z","event_type":"price_change","frame_hash":"5b55f051abab90600d8ab7ed15855e49e173fc24380f9be37f53b6814acf8f8f","frame_index":0,"kind":"data","monotonic_ns":313774885644625,"payload":{"event_type":"price_change","market":"0xd412ce774cfcf8dc9f71164aac78783978aac7b03871702a3b8a481bd9dc9688","price_changes":[{"asset_id":"107603864457683460275633293642179940881969192120168665300712204232021063124301","best_ask":"0.61","best_bid":"0.6","hash":"f87bcec8dbb76791ab8506c90b8df3c2468614a2","price":"0.32","side":"BUY","size":"34.8"},{"asset_id":"96600821790790307414914106093858868634329285205417149685270682748367152458577","best_ask":"0.4","best_bid":"0.39","hash":"81025bbc71acdff5ba3d6dd1b3999d4fef32834e","price":"0.68","side":"SELL","size":"34.8"}],"timestamp":"1785211792033"},"payload_hash":"9e9b2c0aa8185052c63f012032b2fdffb7e3b3b7d5237e0a3f5627c4363141d2","raw_frame":"{\"market\":\"0xd412ce774cfcf8dc9f71164aac78783978aac7b03871702a3b8a481bd9dc9688\", \"price_changes\":[{\"asset_id\":\"107603864457683460275633293642179940881969192120168665300712204232021063124301\", \"price\":\"0.32\", \"size\":\"34.8\", \"side\":\"BUY\", \"hash\":\"f87bcec8dbb76791ab8506c90b8df3c2468614a2\", \"best_bid\":\"0.6\", \"best_ask\":\"0.61\"}, {\"asset_id\":\"96600821790790307414914106093858868634329285205417149685270682748367152458577\", \"price\":\"0.68\", \"size\":\"34.8\", \"side\":\"SELL\", \"hash\":\"81025bbc71acdff5ba3d6dd1b3999d4fef32834e\", \"best_bid\":\"0.39\", \"best_ask\":\"0.4\"}], \"timestamp\":\"1785211792033\", \"event_type\":\"price_change\"}","received_at":"2026-07-28T04:09:51.809896Z","schema_version":"clob-market-ws.price_change.v1","sequence":null,"server_hash":null,"server_timestamp":"1785211792033","session_id":"2d607381e3054cee91998cdf45a4231c","source":"clob_market_ws"},"received_at":"2026-07-28T04:09:51.809896Z","record_id":"e1566f1d7b0724b007adc8f466d32104e83620ef8cfa464c55c794aa80072333","schema_fingerprint":"4aa3821a28b0b7c2400bc59aba4bcc0a76e971dadd19610d3ad38c768e124dc7","schema_version":"edge-lab-recorder.raw.v1","sequence":null,"source":"clob_market_ws"}
{"event_at":"2026-07-28T04:09:52.034000Z","event_fingerprint":"40d7de216e1a3cbef348ab0d63bfa4affdda9256998d05e68864da14b4c9be3d","payload":{"connection_id":"f6725804f86a4c4eb588e4d5ed7db029","event_at":"2026-07-28T04:09:52.034000Z","event_type":"price_change","frame_hash":"0958a1cd0fa033859ed5e06ecbf700925bafb18fc50044dc284bb6606ebc3158","frame_index":0,"kind":"data","monotonic_ns":313774887442250,"payload":{"event_type":"price_change","market":"0xd412ce774cfcf8dc9f71164aac78783978aac7b03871702a3b8a481bd9dc9688","price_changes":[{"asset_id":"96600821790790307414914106093858868634329285205417149685270682748367152458577","best_ask":"0.4","best_bid":"0.39","hash":"be79bdb12058a43e3e83f06c569ba7c7119e2e8a","price":"0.01","side":"BUY","size":"5613.02"},{"asset_id":"107603864457683460275633293642179940881969192120168665300712204232021063124301","best_ask":"0.61","best_bid":"0.6","hash":"e2806961c76d6ec8d1f0373438c0f76b570e0b1a","price":"0.99","side":"SELL","size":"5613.02"}],"timestamp":"1785211792034"},"payload_hash":"87ca8affe2e4083e9712798a9293c00cd3fe87f10e60cfd78a7955344199aef6","raw_frame":"{\"market\":\"0xd412ce774cfcf8dc9f71164aac78783978aac7b03871702a3b8a481bd9dc9688\", \"price_changes\":[{\"asset_id\":\"96600821790790307414914106093858868634329285205417149685270682748367152458577\", \"price\":\"0.01\", \"size\":\"5613.02\", \"side\":\"BUY\", \"hash\":\"be79bdb12058a43e3e83f06c569ba7c7119e2e8a\", \"best_bid\":\"0.39\", \"best_ask\":\"0.4\"}, {\"asset_id\":\"107603864457683460275633293642179940881969192120168665300712204232021063124301\", \"price\":\"0.99\", \"size\":\"5613.02\", \"side\":\"SELL\", \"hash\":\"e2806961c76d6ec8d1f0373438c0f76b570e0b1a\", \"best_bid\":\"0.6\", \"best_ask\":\"0.61\"}], \"timestamp\":\"1785211792034\", \"event_type\":\"price_change\"}","received_at":"2026-07-28T04:09:51.811693Z","schema_version":"clob-market-ws.price_change.v1","sequence":null,"server_hash":null,"server_timestamp":"1785211792034","session_id":"2d607381e3054cee91998cdf45a4231c","source":"clob_market_ws"},"received_at":"2026-07-28T04:09:51.811693Z","record_id":"0840ae0e8430f37c4fdac59a178b08113ad0f24724b03cba07fd0fda987a100c","schema_fingerprint":"4aa3821a28b0b7c2400bc59aba4bcc0a76e971dadd19610d3ad38c768e124dc7","schema_version":"edge-lab-recorder.raw.v1","sequence":null,"source":"clob_market_ws"}
{"event_at":"2026-07-28T04:09:52.054000Z","event_fingerprint":"cf0fd6cef34d6eccd2cece2c1de6fd4ce48416ba40daa537e48ece55dc5066c4","payload":{"connection_id":"f6725804f86a4c4eb588e4d5ed7db029","event_at":"2026-07-28T04:09:52.054000Z","event_type":"price_change","frame_hash":"f6f6223ded36eb6a8191279c1d47496f5bfa3000ff31c407b022a6810ed16973","frame_index":0,"kind":"data","monotonic_ns":313774907511666,"payload":{"event_type":"price_change","market":"0xd412ce774cfcf8dc9f71164aac78783978aac7b03871702a3b8a481bd9dc9688","price_changes":[{"asset_id":"96600821790790307414914106093858868634329285205417149685270682748367152458577","best_ask":"0.4","best_bid":"0.39","hash":"b2cd1f756b0e6a7fff398ebd45c95c8bdec85dcb","price":"0.01","side":"BUY","size":"5608.02"},{"asset_id":"107603864457683460275633293642179940881969192120168665300712204232021063124301","best_ask":"0.61","best_bid":"0.6","hash":"1945e543a4dc3d4977e55cee6afca413be614532","price":"0.99","side":"SELL","size":"5608.02"}],"timestamp":"1785211792054"},"payload_hash":"6560b0b50c5f22c6b31870d343134320f7bc410a94dbaf51b240f141b5e18f3b","raw_frame":"{\"market\":\"0xd412ce774cfcf8dc9f71164aac78783978aac7b03871702a3b8a481bd9dc9688\", \"price_changes\":[{\"asset_id\":\"96600821790790307414914106093858868634329285205417149685270682748367152458577\", \"price\":\"0.01\", \"size\":\"5608.02\", \"side\":\"BUY\", \"hash\":\"b2cd1f756b0e6a7fff398ebd45c95c8bdec85dcb\", \"best_bid\":\"0.39\", \"best_ask\":\"0.4\"}, {\"asset_id\":\"107603864457683460275633293642179940881969192120168665300712204232021063124301\", \"price\":\"0.99\", \"size\":\"5608.02\", \"side\":\"SELL\", \"hash\":\"1945e543a4dc3d4977e55cee6afca413be614532\", \"best_bid\":\"0.6\", \"best_ask\":\"0.61\"}], \"timestamp\":\"1785211792054\", \"event_type\":\"price_change\"}","received_at":"2026-07-28T04:09:51.831758Z","schema_version":"clob-market-ws.price_change.v1","sequence":null,"server_hash":null,"server_timestamp":"1785211792054","session_id":"2d607381e3054cee91998cdf45a4231c","source":"clob_market_ws"},"received_at":"2026-07-28T04:09:51.831758Z","record_id":"ba51c19bc667d7722a69ad645800c6ad8ea5d764e9216bd07d56d956f21e0856","schema_fingerprint":"4aa3821a28b0b7c2400bc59aba4bcc0a76e971dadd19610d3ad38c768e124dc7","schema_version":"edge-lab-recorder.raw.v1","sequence":null,"source":"clob_market_ws"}
{"event_at":"2026-07-28T04:09:52.057000Z","event_fingerprint":"cd60710fb7398f4a1ee9278cf48844b50e82414e44c90f72be3a89e506bcd00e","payload":{"connection_id":"f6725804f86a4c4eb588e4d5ed7db029","event_at":"2026-07-28T04:09:52.057000Z","event_type":"price_change","frame_hash":"f5121fbda30006d32e6943e8dd6e6661bf51037a1a761b700b71b8012d1031e6","frame_index":0,"kind":"data","monotonic_ns":313774911080833,"payload":{"event_type":"price_change","market":"0xd412ce774cfcf8dc9f71164aac78783978aac7b03871702a3b8a481bd9dc9688","price_changes":[{"asset_id":"107603864457683460275633293642179940881969192120168665300712204232021063124301","best_ask":"0.61","best_bid":"0.6","hash":"9d076ef380d7fa0a57bef129f2474aaa2af70762","price":"0.03","side":"BUY","size":"618.1"},{"asset_id":"96600821790790307414914106093858868634329285205417149685270682748367152458577","best_ask":"0.4","best_bid":"0.39","hash":"e1d055d8c0b017921723f40a564daf319c571961","price":"0.97","side":"SELL","size":"618.1"}],"timestamp":"1785211792057"},"payload_hash":"e766364dd8779aaaff44d34d4babcdbe0453921b04130b2c0d0c58e92d388186","raw_frame":"{\"market\":\"0xd412ce774cfcf8dc9f71164aac78783978aac7b03871702a3b8a481bd9dc9688\", \"price_changes\":[{\"asset_id\":\"107603864457683460275633293642179940881969192120168665300712204232021063124301\", \"price\":\"0.03\", \"size\":\"618.1\", \"side\":\"BUY\", \"hash\":\"9d076ef380d7fa0a57bef129f2474aaa2af70762\", \"best_bid\":\"0.6\", \"best_ask\":\"0.61\"}, {\"asset_id\":\"96600821790790307414914106093858868634329285205417149685270682748367152458577\", \"price\":\"0.97\", \"size\":\"618.1\", \"side\":\"SELL\", \"hash\":\"e1d055d8c0b017921723f40a564daf319c571961\", \"best_bid\":\"0.39\", \"best_ask\":\"0.4\"}], \"timestamp\":\"1785211792057\", \"event_type\":\"price_change\"}","received_at":"2026-07-28T04:09:51.835323Z","schema_version":"clob-market-ws.price_change.v1","sequence":null,"server_hash":null,"server_timestamp":"1785211792057","session_id":"2d607381e3054cee91998cdf45a4231c","source":"clob_market_ws"},"received_at":"2026-07-28T04:09:51.835323Z","record_id":"e52e9009dd13d26468f8c090f24c6eb764347aca9e039140ebe59242c04e12a9","schema_fingerprint":"4aa3821a28b0b7c2400bc59aba4bcc0a76e971dadd19610d3ad38c768e124dc7","schema_version":"edge-lab-recorder.raw.v1","sequence":null,"source":"clob_market_ws"}
{"event_at":"2026-07-28T04:09:52.100000Z","event_fingerprint":"1e1c03707ef0267d5d7076699ac3ad13d60371093062d5dfa9b5d19a3b1282c2","payload":{"connection_id":"f6725804f86a4c4eb588e4d5ed7db029","event_at":"2026-07-28T04:09:52.100000Z","event_type":"price_change","frame_hash":"9de6d1cdd2974c0a639a46e3bd4f25d5a9be2fe9909fbd7c80faf69bc1e1a326","frame_index":0,"kind":"data","monotonic_ns":313774950785708,"payload":{"event_type":"price_change","market":"0xd412ce774cfcf8dc9f71164aac78783978aac7b03871702a3b8a481bd9dc9688","price_changes":[{"asset_id":"107603864457683460275633293642179940881969192120168665300712204232021063124301","best_ask":"0.61","best_bid":"0.6","hash":"e48008f5770614f045e1f48bd94d5836ed4cd86d","price":"0.32","side":"BUY","size":"19.8"},{"asset_id":"96600821790790307414914106093858868634329285205417149685270682748367152458577","best_ask":"0.4","best_bid":"0.39","hash":"9c8ab8c96573b66cf38819dfaa618019ea51a559","price":"0.68","side":"SELL","size":"19.8"}],"timestamp":"1785211792100"},"payload_hash":"9667956a863a5f5345e9df485622e06e21d149fc9cc33a38022d864576e0f3ee","raw_frame":"{\"market\":\"0xd412ce774cfcf8dc9f71164aac78783978aac7b03871702a3b8a481bd9dc9688\", \"price_changes\":[{\"asset_id\":\"107603864457683460275633293642179940881969192120168665300712204232021063124301\", \"price\":\"0.32\", \"size\":\"19.8\", \"side\":\"BUY\", \"hash\":\"e48008f5770614f045e1f48bd94d5836ed4cd86d\", \"best_bid\":\"0.6\", \"best_ask\":\"0.61\"}, {\"asset_id\":\"96600821790790307414914106093858868634329285205417149685270682748367152458577\", \"price\":\"0.68\", \"size\":\"19.8\", \"side\":\"SELL\", \"hash\":\"9c8ab8c96573b66cf38819dfaa618019ea51a559\", \"best_bid\":\"0.39\", \"best_ask\":\"0.4\"}], \"timestamp\":\"1785211792100\", \"event_type\":\"price_change\"}","received_at":"2026-07-28T04:09:51.875030Z","schema_version":"clob-market-ws.price_change.v1","sequence":null,"server_hash":null,"server_timestamp":"1785211792100","session_id":"2d607381e3054cee91998cdf45a4231c","source":"clob_market_ws"},"received_at":"2026-07-28T04:09:51.875030Z","record_id":"e61d59b91bcaf6a2c66cc8948f9ae0529ae9bb4686c3746af7f24d3a16c734f7","schema_fingerprint":"4aa3821a28b0b7c2400bc59aba4bcc0a76e971dadd19610d3ad38c768e124dc7","schema_version":"edge-lab-recorder.raw.v1","sequence":null,"source":"clob_market_ws"}
