{"event_at":"2026-07-28T04:08:26.062000Z","event_fingerprint":"f4427463ade81356eab7f837e4d4ebcee95b488fcfc1f2a879edbce7ce43ae9d","payload":{"connection_id":"f6725804f86a4c4eb588e4d5ed7db029","event_at":"2026-07-28T04:08:26.062000Z","event_type":"price_change","frame_hash":"de4fbc1d4c8ae2e3a493b98e7b18c3375ca15e15ff23ee631da52967e1d62a7e","frame_index":0,"kind":"data","monotonic_ns":313692927429208,"payload":{"event_type":"price_change","market":"0xd412ce774cfcf8dc9f71164aac78783978aac7b03871702a3b8a481bd9dc9688","price_changes":[{"asset_id":"107603864457683460275633293642179940881969192120168665300712204232021063124301","best_ask":"0.63","best_bid":"0.62","hash":"b811ddd88c1f3eb12143594c5c2d446b67b3143b","price":"0.04","side":"BUY","size":"623.09"},{"asset_id":"96600821790790307414914106093858868634329285205417149685270682748367152458577","best_ask":"0.38","best_bid":"0.37","hash":"0d5db6dde3c1483d4f3d0ee5f839daa1c11b05f4","price":"0.96","side":"SELL","size":"623.09"}],"timestamp":"1785211706062"},"payload_hash":"bc88cb6b3f75d9d03c96675f0072a0aecb034e7fa490e9ca2b5b276e6c1db27a","raw_frame":"{\"market\":\"0xd412ce774cfcf8dc9f71164aac78783978aac7b03871702a3b8a481bd9dc9688\", \"price_changes\":[{\"asset_id\":\"107603864457683460275633293642179940881969192120168665300712204232021063124301\", \"price\":\"0.04\", \"size\":\"623.09\", \"side\":\"BUY\", \"hash\":\"b811ddd88c1f3eb12143594c5c2d446b67b3143b\", \"best_bid\":\"0.62\", \"best_ask\":\"0.63\"}, {\"asset_id\":\"96600821790790307414914106093858868634329285205417149685270682748367152458577\", \"price\":\"0.96\", \"size\":\"623.09\", \"side\":\"SELL\", \"hash\":\"0d5db6dde3c1483d4f3d0ee5f839daa1c11b05f4\", \"best_bid\":\"0.37\", \"best_ask\":\"0.38\"}], \"timestamp\":\"1785211706062\", \"event_type\":\"price_change\"}","received_at":"2026-07-28T04:08:29.859937Z","schema_version":"clob-market-ws.price_change.v1","sequence":null,"server_hash":null,"server_timestamp":"1785211706062","session_id":"2d607381e3054cee91998cdf45a4231c","source":"clob_market_ws"},"received_at":"2026-07-28T04:08:29.859937Z","record_id":"f74b516071db78be2780108c31eab0a39073a14a3bebddf583b9661f9d648a5a","schema_fingerprint":"4aa3821a28b0b7c2400bc59aba4bcc0a76e971dadd19610d3ad38c768e124dc7","schema_version":"edge-lab-recorder.raw.v1","sequence":null,"source":"clob_market_ws"}
{"event_at":"2026-07-28T04:08:26.063000Z","event_fingerprint":"a602b718f97140baf1eef399bc98da53c6b664b1b337a06b98433e593f6a39da","payload":{"connection_id":"f6725804f86a4c4eb588e4d5ed7db029","event_at":"2026-07-28T04:08:26.063000Z","event_type":"price_change","frame_hash":"762deb0a2eb151055b3366c8a11883c2de47d2ff59cd4a2a5aea325fe0cf4a64","frame_index":0,"kind":"data","monotonic_ns":313692933461125,"payload":{"event_type":"price_change","market":"0xd412ce774cfcf8dc9f71164aac78783978aac7b03871702a3b8a481bd9dc9688","price_changes":[{"asset_id":"107603864457683460275633293642179940881969192120168665300712204232021063124301","best_ask":"0.63","best_bid":"0.62","hash":"eab41c7c7bab9a8d7e4ee34843ee30f40ea26c0b","price":"0.34","side":"BUY","size":"64.4"},{"asset_id":"96600821790790307414914106093858868634329285205417149685270682748367152458577","best_ask":"0.38","best_bid":"0.37","hash":"29961a6c6747aac0005ef52d5b44306cc7e52f94","price":"0.66","side":"SELL","size":"64.4"}],"timestamp":"1785211706063"},"payload_hash":"d2a9d03712603dce8f9dc1d17b8da54efab9e4881502f22efc129171ae4f519d","raw_frame":"{\"market\":\"0xd412ce774cfcf8dc9f71164aac78783978aac7b03871702a3b8a481bd9dc9688\", \"price_changes\":[{\"asset_id\":\"107603864457683460275633293642179940881969192120168665300712204232021063124301\", \"price\":\"0.34\", \"size\":\"64.4\", \"side\":\"BUY\", \"hash\":\"eab41c7c7bab9a8d7e4ee34843ee30f40ea26c0b\", \"best_bid\":\"0.62\", \"best_ask\":\"0.63\"}, {\"asset_id\":\"96600821790790307414914106093858868634329285205417149685270682748367152458577\", \"price\":\"0.66\", \"size\":\"64.4\", \"side\":\"SELL\", \"hash\":\"29961a6c6747aac0005ef52d5b44306cc7e52f94\", \"best_bid\":\"0.37\", \"best_ask\":\"0.38\"}], \"timestamp\":\"1785211706063\", \"event_type\":\"price_change\"}","received_at":"2026-07-28T04:08:29.865966Z","schema_version":"clob-market-ws.price_change.v1","sequence":null,"server_hash":null,"server_timestamp":"1785211706063","session_id":"2d607381e3054cee91998cdf45a4231c","source":"clob_market_ws"},"received_at":"2026-07-28T04:08:29.865966Z","record_id":"aa645103a2878d867281dce88974a5dedab4141c5230a1efa5acc9e69a7c5799","schema_fingerprint":"4aa3821a28b0b7c2400bc59aba4bcc0a76e971dadd19610d3ad38c768e124dc7","schema_version":"edge-lab-recorder.raw.v1","sequence":null,"source":"clob_market_ws"}
{"event_at":"2026-07-28T04:08:26.064000Z","event_fingerprint":"2e4c0a9170f5ea8a58c3e6a40d56e1f16730cb93a7f7c14829af9b5297e24044","payload":{"connection_id":"f6725804f86a4c4eb588e4d5ed7db029","event_at":"2026-07-28T04:08:26.064000Z","event_type":"price_change","frame_hash":"e170c3420f74b85cedf7cb6b9749ec3b5e3a8db68fc837f18751b45d5471883b","frame_index":0,"kind":"data","monotonic_ns":313692936209666,"payload":{"event_type":"price_change","market":"0xd412ce774cfcf8dc9f71164aac78783978aac7b03871702a3b8a481bd9dc9688","price_changes":[{"asset_id":"96600821790790307414914106093858868634329285205417149685270682748367152458577","best_ask":"0.38","best_bid":"0.37","hash":"3696de7b1b7bc152a1da3d716836987bb3802417","price":"0.37","side":"BUY","size":"290.88"},{"asset_id":"107603864457683460275633293642179940881969192120168665300712204232021063124301","best_ask":"0.63","best_bid":"0.62","hash":"0a9a4997dd598719c2e7a48bab485a3adaeba1c6","price":"0.63","side":"SELL","size":"290.88"}],"timestamp":"1785211706064"},"payload_hash":"cd4868304eb413ed7acd70aff880a031835f8fd82ee1312ae8f4f101275ea04e","raw_frame":"{\"market\":\"0xd412ce774cfcf8dc9f71164aac78783978aac7b03871702a3b8a481bd9dc9688\", \"price_changes\":[{\"asset_id\":\"96600821790790307414914106093858868634329285205417149685270682748367152458577\", \"price\":\"0.37\", \"size\":\"290.88\", \"side\":\"BUY\", \"hash\":\"3696de7b1b7bc152a1da3d716836987bb3802417\", \"best_bid\":\"0.37\", \"best_ask\":\"0.38\"}, {\"asset_id\":\"107603864457683460275633293642179940881969192120168665300712204232021063124301\", \"price\":\"0.63\", \"size\":\"290.88\", \"side\":\"SELL\", \"hash\":\"0a9a4997dd598719c2e7a48bab485a3adaeba1c6\", \"best_bid\":\"0.62\", \"best_ask\":\"0.63\"}], \"timestamp\":\"1785211706064\", \"event_type\":\"price_change\"}","received_at":"2026-07-28T04:08:29.868713Z","schema_version":"clob-market-ws.price_change.v1","sequence":null,"server_hash":null,"server_timestamp":"1785211706064","session_id":"2d607381e3054cee91998cdf45a4231c","source":"clob_market_ws"},"received_at":"2026-07-28T04:08:29.868713Z","record_id":"6164c1d4777929cd078fbfee1217322b51b373ac0b2778d8580faed0a8859760","schema_fingerprint":"4aa3821a28b0b7c2400bc59aba4bcc0a76e971dadd19610d3ad38c768e124dc7","schema_version":"edge-lab-recorder.raw.v1","sequence":null,"source":"clob_market_ws"}
{"event_at":"2026-07-28T04:08:26.065000Z","event_fingerprint":"9f17378d0419f5b2796f27074fa45f68639357aa5eb53a32f3744b269a7bc6de","payload":{"connection_id":"f6725804f86a4c4eb588e4d5ed7db029","event_at":"2026-07-28T04:08:26.065000Z","event_type":"price_change","frame_hash":"bda41dddb2abed1d7e2966293eee2fe6c46dcc0f34f84f7f5dcb3c7cf36cb111","frame_index":0,"kind":"data","monotonic_ns":313692938742833,"payload":{"event_type":"price_change","market":"0xd412ce774cfcf8dc9f71164aac78783978aac7b03871702a3b8a481bd9dc9688","price_changes":[{"asset_id":"107603864457683460275633293642179940881969192120168665300712204232021063124301","best_ask":"0.63","best_bid":"0.62","hash":"c6d4d0388fab63fdb2031d4a48ea47dc18863e28","price":"0.76","side":"SELL","size":"261.89"},{"asset_id":"96600821790790307414914106093858868634329285205417149685270682748367152458577","best_ask":"0.38","best_bid":"0.37","hash":"a52a8293998ffd9a4ab1e011a8212796510db280","price":"0.24","side":"BUY","size":"261.89"}],"timestamp":"1785211706065"},"payload_hash":"e56230a1770e9b965c21246f38bb9d3659645a1856de299f2d7ee71afe15c3b9","raw_frame":"{\"market\":\"0xd412ce774cfcf8dc9f71164aac78783978aac7b03871702a3b8a481bd9dc9688\", \"price_changes\":[{\"asset_id\":\"107603864457683460275633293642179940881969192120168665300712204232021063124301\", \"price\":\"0.76\", \"size\":\"261.89\", \"side\":\"SELL\", \"hash\":\"c6d4d0388fab63fdb2031d4a48ea47dc18863e28\", \"best_bid\":\"0.62\", \"best_ask\":\"0.63\"}, {\"asset_id\":\"96600821790790307414914106093858868634329285205417149685270682748367152458577\", \"price\":\"0.24\", \"size\":\"261.89\", \"side\":\"BUY\", \"hash\":\"a52a8293998ffd9a4ab1e011a8212796510db280\", \"best_bid\":\"0.37\", \"best_ask\":\"0.38\"}], \"timestamp\":\"1785211706065\", \"event_type\":\"price_change\"}","received_at":"2026-07-28T04:08:29.871243Z","schema_version":"clob-market-ws.price_change.v1","sequence":null,"server_hash":null,"server_timestamp":"1785211706065","session_id":"2d607381e3054cee91998cdf45a4231c","source":"clob_market_ws"},"received_at":"2026-07-28T04:08:29.871243Z","record_id":"209422eb9de7917ab03e132bfff09b21be3404f9ccb0d8a51a35ff1cf06c7f87","schema_fingerprint":"4aa3821a28b0b7c2400bc59aba4bcc0a76e971dadd19610d3ad38c768e124dc7","schema_version":"edge-lab-recorder.raw.v1","sequence":null,"source":"clob_market_ws"}
{"event_at":"2026-07-28T04:08:26.069000Z","event_fingerprint":"f56d70bcb207bcc482219f9247c1b6d9f4138568f939d32bcc63bc37324c92cc","payload":{"connection_id":"f6725804f86a4c4eb588e4d5ed7db029","event_at":"2026-07-28T04:08:26.069000Z","event_type":"price_change","frame_hash":"f157f1aff8c83dc8e27206bdb2b6c650a8b041e96f80eafa823d57bfa30ba91d","frame_index":0,"kind":"data","monotonic_ns":313692941850041,"payload":{"event_type":"price_change","market":"0xd412ce774cfcf8dc9f71164aac78783978aac7b03871702a3b8a481bd9dc9688","price_changes":[{"asset_id":"107603864457683460275633293642179940881969192120168665300712204232021063124301","best_ask":"0.63","best_bid":"0.62","hash":"ec8751ac293bad8d1d50a0df11595a5742fe779b","price":"0.5","side":"BUY","size":"188"},{"asset_id":"96600821790790307414914106093858868634329285205417149685270682748367152458577","best_ask":"0.38","best_bid":"0.37","hash":"d0bf02673cd7ceb836edaf1b1ff5b12bfbdc07e4","price":"0.5","side":"SELL","size":"188"}],"timestamp":"1785211706069"},"payload_hash":"b6422f5a71898d89fd7220ad45432707cfd3d61713092c2b372ce2a7b66eebea","raw_frame":"{\"market\":\"0xd412ce774cfcf8dc9f71164aac78783978aac7b03871702a3b8a481bd9dc9688\", \"price_changes\":[{\"asset_id\":\"107603864457683460275633293642179940881969192120168665300712204232021063124301\", \"price\":\"0.5\", \"size\":\"188\", \"side\":\"BUY\", \"hash\":\"ec8751ac293bad8d1d50a0df11595a5742fe779b\", \"best_bid\":\"0.62\", \"best_ask\":\"0.63\"}, {\"asset_id\":\"96600821790790307414914106093858868634329285205417149685270682748367152458577\", \"price\":\"0.5\", \"size\":\"188\", \"side\":\"SELL\", \"hash\":\"d0bf02673cd7ceb836edaf1b1ff5b12bfbdc07e4\", \"best_bid\":\"0.37\", \"best_ask\":\"0.38\"}], \"timestamp\":\"1785211706069\", \"event_type\":\"price_change\"}","received_at":"2026-07-28T04:08:29.874351Z","schema_version":"clob-market-ws.price_change.v1","sequence":null,"server_hash":null,"server_timestamp":"1785211706069","session_id":"2d607381e3054cee91998cdf45a4231c","source":"clob_market_ws"},"received_at":"2026-07-28T04:08:29.874351Z","record_id":"66dacf35d32d97e7f39d15c48e430bb028a5c2af43df92f2b8d3cbd514caa062","schema_fingerprint":"4aa3821a28b0b7c2400bc59aba4bcc0a76e971dadd19610d3ad38c768e124dc7","schema_version":"edge-lab-recorder.raw.v1","sequence":null,"source":"clob_market_ws"}
{"event_at":"2026-07-28T04:08:26.070000Z","event_fingerprint":"e163d5762fd5bc025c6abb4f84ad7c0d747c17dfefff7e10309004e1b2363976","payload":{"connection_id":"f6725804f86a4c4eb588e4d5ed7db029","event_at":"2026-07-28T04:08:26.070000Z","event_type":"price_change","frame_hash":"6b6e053c2abfeafd1c996062c8e1baf7998961875d6748fd5e3d6e6163baad16","frame_index":0,"kind":"data","monotonic_ns":313692944954333,"payload":{"event_type":"price_change","market":"0xd412ce774cfcf8dc9f71164aac78783978aac7b03871702a3b8a481bd9dc9688","price_changes":[{"asset_id":"96600821790790307414914106093858868634329285205417149685270682748367152458577","best_ask":"0.38","best_bid":"0.37","hash":"be22b1462d407c578f65bc7c6c92b5c15b5e014d","price":"0.28","side":"BUY","size":"201.9"},{"asset_id":"107603864457683460275633293642179940881969192120168665300712204232021063124301","best_ask":"0.63","best_bid":"0.62","hash":"6366b2ea41fc18bc2c6832f7a33fdba2bb499cf1","price":"0.72","side":"SELL","size":"201.9"}],"timestamp":"1785211706070"},"payload_hash":"f74c720d7699ef14abb9e3325e89173a40a6cd08994160d81c18c2291d7438c8","raw_frame":"{\"market\":\"0xd412ce774cfcf8dc9f71164aac78783978aac7b03871702a3b8a481bd9dc9688\", \"price_changes\":[{\"asset_id\":\"96600821790790307414914106093858868634329285205417149685270682748367152458577\", \"price\":\"0.28\", \"size\":\"201.9\", \"side\":\"BUY\", \"hash\":\"be22b1462d407c578f65bc7c6c92b5c15b5e014d\", \"best_bid\":\"0.37\", \"best_ask\":\"0.38\"}, {\"asset_id\":\"107603864457683460275633293642179940881969192120168665300712204232021063124301\", \"price\":\"0.72\", \"size\":\"201.9\", \"side\":\"SELL\", \"hash\":\"6366b2ea41fc18bc2c6832f7a33fdba2bb499cf1\", \"best_bid\":\"0.62\", \"best_ask\":\"0.63\"}], \"timestamp\":\"1785211706070\", \"event_type\":\"price_change\"}","received_at":"2026-07-28T04:08:29.877454Z","schema_version":"clob-market-ws.price_change.v1","sequence":null,"server_hash":null,"server_timestamp":"1785211706070","session_id":"2d607381e3054cee91998cdf45a4231c","source":"clob_market_ws"},"received_at":"2026-07-28T04:08:29.877454Z","record_id":"0d19aa8e2e65a2c9c89f9126407e1b44380035c2ca762a50c57f2e3864ad6647","schema_fingerprint":"4aa3821a28b0b7c2400bc59aba4bcc0a76e971dadd19610d3ad38c768e124dc7","schema_version":"edge-lab-recorder.raw.v1","sequence":null,"source":"clob_market_ws"}
{"event_at":"2026-07-28T04:08:26.078000Z","event_fingerprint":"90156a561f70f441e0b200beaa55115eee2c1f675f529cc5c71f1b24e540bac3","payload":{"connection_id":"f6725804f86a4c4eb588e4d5ed7db029","event_at":"2026-07-28T04:08:26.078000Z","event_type":"price_change","frame_hash":"9a1183cdfdde82dadaf18ec8746b5e7bd025de20b100e78a412fbf69cf055650","frame_index":0,"kind":"data","monotonic_ns":313692947601291,"payload":{"event_type":"price_change","market":"0xd412ce774cfcf8dc9f71164aac78783978aac7b03871702a3b8a481bd9dc9688","price_changes":[{"asset_id":"96600821790790307414914106093858868634329285205417149685270682748367152458577","best_ask":"0.38","best_bid":"0.37","hash":"5dcd5cb685538eb1bece9a6d3310e21819ef6b8e","price":"0.31","side":"BUY","size":"127.38"},{"asset_id":"107603864457683460275633293642179940881969192120168665300712204232021063124301","best_ask":"0.63","best_bid":"0.62","hash":"342b612dad03cc4289d24d52c00ec7fbd4a581a1","price":"0.69","side":"SELL","size":"127.38"}],"timestamp":"1785211706078"},"payload_hash":"21b457d815abfda8af9d6559279883dc63d83387440e1df364faaafd48d5536f","raw_frame":"{\"market\":\"0xd412ce774cfcf8dc9f71164aac78783978aac7b03871702a3b8a481bd9dc9688\", \"price_changes\":[{\"asset_id\":\"96600821790790307414914106093858868634329285205417149685270682748367152458577\", \"price\":\"0.31\", \"size\":\"127.38\", \"side\":\"BUY\", \"hash\":\"5dcd5cb685538eb1bece9a6d3310e21819ef6b8e\", \"best_bid\":\"0.37\", \"best_ask\":\"0.38\"}, {\"asset_id\":\"107603864457683460275633293642179940881969192120168665300712204232021063124301\", \"price\":\"0.69\", \"size\":\"127.38\", \"side\":\"SELL\", \"hash\":\"342b612dad03cc4289d24d52c00ec7fbd4a581a1\", \"best_bid\":\"0.62\", \"best_ask\":\"0.63\"}], \"timestamp\":\"1785211706078\", \"event_type\":\"price_change\"}","received_at":"2026-07-28T04:08:29.880099Z","schema_version":"clob-market-ws.price_change.v1","sequence":null,"server_hash":null,"server_timestamp":"1785211706078","session_id":"2d607381e3054cee91998cdf45a4231c","source":"clob_market_ws"},"received_at":"2026-07-28T04:08:29.880099Z","record_id":"98b0e9defc4a2e6a0975f917f83063c68aabe40f32881f444e6197db488ca10c","schema_fingerprint":"4aa3821a28b0b7c2400bc59aba4bcc0a76e971dadd19610d3ad38c768e124dc7","schema_version":"edge-lab-recorder.raw.v1","sequence":null,"source":"clob_market_ws"}
{"event_at":"2026-07-28T04:08:26.081000Z","event_fingerprint":"e387e88f303097bd57a211b022298064eaa9b31e30bd2bd51a3ac27a2a6631de","payload":{"connection_id":"f6725804f86a4c4eb588e4d5ed7db029","event_at":"2026-07-28T04:08:26.081000Z","event_type":"price_change","frame_hash":"a26c4f9cf684afb1fbb2d545280576fdef5ddd7de7789e3394bf70cbef36c5a1","frame_index":0,"kind":"data","monotonic_ns":313692950183416,"payload":{"event_type":"price_change","market":"0xd412ce774cfcf8dc9f71164aac78783978aac7b03871702a3b8a481bd9dc9688","price_changes":[{"asset_id":"96600821790790307414914106093858868634329285205417149685270682748367152458577","best_ask":"0.38","best_bid":"0.37","hash":"27a2faf61f8ac0a7c90c40e89dde3ccc4099fbc1","price":"0.29","side":"BUY","size":"292.31"},{"asset_id":"107603864457683460275633293642179940881969192120168665300712204232021063124301","best_ask":"0.63","best_bid":"0.62","hash":"3d313bb3725e03becadd4fcbc2afee49a86a1e7e","price":"0.71","side":"SELL","size":"292.31"}],"timestamp":"1785211706081"},"payload_hash":"7f1e23824fd76b7769530e2c371b0e406ed4d19bd0de285f70f33764a3060633","raw_frame":"{\"market\":\"0xd412ce774cfcf8dc9f71164aac78783978aac7b03871702a3b8a481bd9dc9688\", \"price_changes\":[{\"asset_id\":\"96600821790790307414914106093858868634329285205417149685270682748367152458577\", \"price\":\"0.29\", \"size\":\"292.31\", \"side\":\"BUY\", \"hash\":\"27a2faf61f8ac0a7c90c40e89dde3ccc4099fbc1\", \"best_bid\":\"0.37\", \"best_ask\":\"0.38\"}, {\"asset_id\":\"107603864457683460275633293642179940881969192120168665300712204232021063124301\", \"price\":\"0.71\", \"size\":\"292.31\", \"side\":\"SELL\", \"hash\":\"3d313bb3725e03becadd4fcbc2afee49a86a1e7e\", \"best_bid\":\"0.62\", \"best_ask\":\"0.63\"}], \"timestamp\":\"1785211706081\", \"event_type\":\"price_change\"}","received_at":"2026-07-28T04:08:29.882680Z","schema_version":"clob-market-ws.price_change.v1","sequence":null,"server_hash":null,"server_timestamp":"1785211706081","session_id":"2d607381e3054cee91998cdf45a4231c","source":"clob_market_ws"},"received_at":"2026-07-28T04:08:29.882680Z","record_id":"9b76cb37812e503f1a4f3b27670c6af9dfb3f9248fac0cfbbcbd079d5524317e","schema_fingerprint":"4aa3821a28b0b7c2400bc59aba4bcc0a76e971dadd19610d3ad38c768e124dc7","schema_version":"edge-lab-recorder.raw.v1","sequence":null,"source":"clob_market_ws"}
{"event_at":"2026-07-28T04:08:26.087000Z","event_fingerprint":"c36989708f9fdc9b561139e1df45fddc27a2ee7b6e7463f68f72ab088fb4c8f7","payload":{"connection_id":"f6725804f86a4c4eb588e4d5ed7db029","event_at":"2026-07-28T04:08:26.087000Z","event_type":"price_change","frame_hash":"fbdbd594721d1bdefb9082bd70654706eceb90770d675e1ac8be991e680d1dc3","frame_index":0,"kind":"data","monotonic_ns":313692953181083,"payload":{"event_type":"price_change","market":"0xd412ce774cfcf8dc9f71164aac78783978aac7b03871702a3b8a481bd9dc9688","price_changes":[{"asset_id":"107603864457683460275633293642179940881969192120168665300712204232021063124301","best_ask":"0.63","best_bid":"0.62","hash":"412b15d77dd99acd06e1731758d014169a6a7e5e","price":"0.5","side":"BUY","size":"218"},{"asset_id":"96600821790790307414914106093858868634329285205417149685270682748367152458577","best_ask":"0.38","best_bid":"0.37","hash":"a54ebe46d5d1a78b9296bf689cf3086959034e74","price":"0.5","side":"SELL","size":"218"}],"timestamp":"1785211706087"},"payload_hash":"0d54bea07ede3eb812b22347eee832a1ad1c1e026c2b4eb9d971e1f147855688","raw_frame":"{\"market\":\"0xd412ce774cfcf8dc9f71164aac78783978aac7b03871702a3b8a481bd9dc9688\", \"price_changes\":[{\"asset_id\":\"107603864457683460275633293642179940881969192120168665300712204232021063124301\", \"price\":\"0.5\", \"size\":\"218\", \"side\":\"BUY\", \"hash\":\"412b15d77dd99acd06e1731758d014169a6a7e5e\", \"best_bid\":\"0.62\", \"best_ask\":\"0.63\"}, {\"asset_id\":\"96600821790790307414914106093858868634329285205417149685270682748367152458577\", \"price\":\"0.5\", \"size\":\"218\", \"side\":\"SELL\", \"hash\":\"a54ebe46d5d1a78b9296bf689cf3086959034e74\", \"best_bid\":\"0.37\", \"best_ask\":\"0.38\"}], \"timestamp\":\"1785211706087\", \"event_type\":\"price_change\"}","received_at":"2026-07-28T04:08:29.885677Z","schema_version":"clob-market-ws.price_change.v1","sequence":null,"server_hash":null,"server_timestamp":"1785211706087","session_id":"2d607381e3054cee91998cdf45a4231c","source":"clob_market_ws"},"received_at":"2026-07-28T04:08:29.885677Z","record_id":"7ca7e013aee0190fd2d400549f2fd758861621b17eb35e84b2e1b2bd6bc0d311","schema_fingerprint":"4aa3821a28b0b7c2400bc59aba4bcc0a76e971dadd19610d3ad38c768e124dc7","schema_version":"edge-lab-recorder.raw.v1","sequence":null,"source":"clob_market_ws"}
{"event_at":"2026-07-28T04:08:26.089000Z","event_fingerprint":"f7c142a62c6d738038a730a9632454ae03a2c6a8d01cb1245456dedce71ee0c1","payload":{"connection_id":"f6725804f86a4c4eb588e4d5ed7db029","event_at":"2026-07-28T04:08:26.089000Z","event_type":"price_change","frame_hash":"568b26df2066cb080a80b8f586666f5b216780eb5abf8b2037df79d50418da15","frame_index":0,"kind":"data","monotonic_ns":313692956158041,"payload":{"event_type":"price_change","market":"0xd412ce774cfcf8dc9f71164aac78783978aac7b03871702a3b8a481bd9dc9688","price_changes":[{"asset_id":"96600821790790307414914106093858868634329285205417149685270682748367152458577","best_ask":"0.38","best_bid":"0.37","hash":"ae6412c83d555ec0744aaf3b280dc769f4627372","price":"0.16","side":"BUY","size":"431.3"},{"asset_id":"107603864457683460275633293642179940881969192120168665300712204232021063124301","best_ask":"0.63","best_bid":"0.62","hash":"ee0d678ea392ec87645a7d4a9d573934edab8890","price":"0.84","side":"SELL","size":"431.3"}],"timestamp":"1785211706089"},"payload_hash":"da4ec295af34348a1fd68be9cc7da9410c15b459768225c7df189b000e56b2c5","raw_frame":"{\"market\":\"0xd412ce774cfcf8dc9f71164aac78783978aac7b03871702a3b8a481bd9dc9688\", \"price_changes\":[{\"asset_id\":\"96600821790790307414914106093858868634329285205417149685270682748367152458577\", \"price\":\"0.16\", \"size\":\"431.3\", \"side\":\"BUY\", \"hash\":\"ae6412c83d555ec0744aaf3b280dc769f4627372\", \"best_bid\":\"0.37\", \"best_ask\":\"0.38\"}, {\"asset_id\":\"107603864457683460275633293642179940881969192120168665300712204232021063124301\", \"price\":\"0.84\", \"size\":\"431.3\", \"side\":\"SELL\", \"hash\":\"ee0d678ea392ec87645a7d4a9d573934edab8890\", \"best_bid\":\"0.62\", \"best_ask\":\"0.63\"}], \"timestamp\":\"1785211706089\", \"event_type\":\"price_change\"}","received_at":"2026-07-28T04:08:29.888652Z","schema_version":"clob-market-ws.price_change.v1","sequence":null,"server_hash":null,"server_timestamp":"1785211706089","session_id":"2d607381e3054cee91998cdf45a4231c","source":"clob_market_ws"},"received_at":"2026-07-28T04:08:29.888652Z","record_id":"ab4de29c195d79b0d9caf1c22224a8330a706526200a2ad3f7e623bc188f603c","schema_fingerprint":"4aa3821a28b0b7c2400bc59aba4bcc0a76e971dadd19610d3ad38c768e124dc7","schema_version":"edge-lab-recorder.raw.v1","sequence":null,"source":"clob_market_ws"}
{"event_at":"2026-07-28T04:08:26.092000Z","event_fingerprint":"1cb845cb7d1f4662cc154f69c28358ef5b7ababe2cfde1c659fa2231897fb8f0","payload":{"connection_id":"f6725804f86a4c4eb588e4d5ed7db029","event_at":"2026-07-28T04:08:26.092000Z","event_type":"price_change","frame_hash":"046dbb2428c1d9b9cebf89ee9bd861cdf8204b3d9b7cad5b1f1ebc6d51452436","frame_index":0,"kind":"data","monotonic_ns":313692959194166,"payload":{"event_type":"price_change","market":"0xd412ce774cfcf8dc9f71164aac78783978aac7b03871702a3b8a481bd9dc9688","price_changes":[{"asset_id":"96600821790790307414914106093858868634329285205417149685270682748367152458577","best_ask":"0.38","best_bid":"0.37","hash":"e99b926d4e5a17f95c57658778160237d4726f5a","price":"0.31","side":"BUY","size":"114.38"},{"asset_id":"107603864457683460275633293642179940881969192120168665300712204232021063124301","best_ask":"0.63","best_bid":"0.62","hash":"6b37e7747331a3f686d8f9e05acd8c1bc1fb2413","price":"0.69","side":"SELL","size":"114.38"}],"timestamp":"1785211706092"},"payload_hash":"5c6b9cf9c5f3c3eee40daf0c32a3a8d02c578e4ca09c7729f863082fcfe14e2e","raw_frame":"{\"market\":\"0xd412ce774cfcf8dc9f71164aac78783978aac7b03871702a3b8a481bd9dc9688\", \"price_changes\":[{\"asset_id\":\"96600821790790307414914106093858868634329285205417149685270682748367152458577\", \"price\":\"0.31\", \"size\":\"114.38\", \"side\":\"BUY\", \"hash\":\"e99b926d4e5a17f95c57658778160237d4726f5a\", \"best_bid\":\"0.37\", \"best_ask\":\"0.38\"}, {\"asset_id\":\"107603864457683460275633293642179940881969192120168665300712204232021063124301\", \"price\":\"0.69\", \"size\":\"114.38\", \"side\":\"SELL\", \"hash\":\"6b37e7747331a3f686d8f9e05acd8c1bc1fb2413\", \"best_bid\":\"0.62\", \"best_ask\":\"0.63\"}], \"timestamp\":\"1785211706092\", \"event_type\":\"price_change\"}","received_at":"2026-07-28T04:08:29.891686Z","schema_version":"clob-market-ws.price_change.v1","sequence":null,"server_hash":null,"server_timestamp":"1785211706092","session_id":"2d607381e3054cee91998cdf45a4231c","source":"clob_market_ws"},"received_at":"2026-07-28T04:08:29.891686Z","record_id":"04008364184f3b3b6045d01d1d04fa98537345faa275399323487b80c5f94905","schema_fingerprint":"4aa3821a28b0b7c2400bc59aba4bcc0a76e971dadd19610d3ad38c768e124dc7","schema_version":"edge-lab-recorder.raw.v1","sequence":null,"source":"clob_market_ws"}
{"event_at":"2026-07-28T04:08:26.097000Z","event_fingerprint":"c174725cd91dff7e4b66a377952ee41a38d7b55fdaedd8e40a9cc0ed4b356179","payload":{"connection_id":"f6725804f86a4c4eb588e4d5ed7db029","event_at":"2026-07-28T04:08:26.097000Z","event_type":"price_change","frame_hash":"95bb7c84c07ed41a0d038b3c84e5902ffa22cadffa32636cb909542a6780080f","frame_index":0,"kind":"data","monotonic_ns":313692962311750,"payload":{"event_type":"price_change","market":"0xd412ce774cfcf8dc9f71164aac78783978aac7b03871702a3b8a481bd9dc9688","price_changes":[{"asset_id":"107603864457683460275633293642179940881969192120168665300712204232021063124301","best_ask":"0.63","best_bid":"0.62","hash":"e26798ee962c58f6caeb34c48d86e7614c0708bf","price":"0.5","side":"BUY","size":"248"},{"asset_id":"96600821790790307414914106093858868634329285205417149685270682748367152458577","best_ask":"0.38","best_bid":"0.37","hash":"83a37c799e83af8ef1c8cb469df5f2612fb941ee","price":"0.5","side":"SELL","size":"248"}],"timestamp":"1785211706097"},"payload_hash":"b599da2c791267d55078d2378bc0a8cd24ae80b280bc41587b18ef393c175b3e","raw_frame":"{\"market\":\"0xd412ce774cfcf8dc9f71164aac78783978aac7b03871702a3b8a481bd9dc9688\", \"price_changes\":[{\"asset_id\":\"107603864457683460275633293642179940881969192120168665300712204232021063124301\", \"price\":\"0.5\", \"size\":\"248\", \"side\":\"BUY\", \"hash\":\"e26798ee962c58f6caeb34c48d86e7614c0708bf\", \"best_bid\":\"0.62\", \"best_ask\":\"0.63\"}, {\"asset_id\":\"96600821790790307414914106093858868634329285205417149685270682748367152458577\", \"price\":\"0.5\", \"size\":\"248\", \"side\":\"SELL\", \"hash\":\"83a37c799e83af8ef1c8cb469df5f2612fb941ee\", \"best_bid\":\"0.37\", \"best_ask\":\"0.38\"}], \"timestamp\":\"1785211706097\", \"event_type\":\"price_change\"}","received_at":"2026-07-28T04:08:29.894802Z","schema_version":"clob-market-ws.price_change.v1","sequence":null,"server_hash":null,"server_timestamp":"1785211706097","session_id":"2d607381e3054cee91998cdf45a4231c","source":"clob_market_ws"},"received_at":"2026-07-28T04:08:29.894802Z","record_id":"afa832aa604cfe6fcec0ba8b2efb4c3b5bd54e7374c8d770d2e4c12539708056","schema_fingerprint":"4aa3821a28b0b7c2400bc59aba4bcc0a76e971dadd19610d3ad38c768e124dc7","schema_version":"edge-lab-recorder.raw.v1","sequence":null,"source":"clob_market_ws"}
{"event_at":"2026-07-28T04:08:26.105000Z","event_fingerprint":"09b9b3f75102de03276f0035a3a367f3e6a7ab88c3fad0e4861794c508ba2acf","payload":{"connection_id":"f6725804f86a4c4eb588e4d5ed7db029","event_at":"2026-07-28T04:08:26.105000Z","event_type":"price_change","frame_hash":"ff862afc432dd93227ecc13839242374435507f6dfb626662b8e6307028f20ff","frame_index":0,"kind":"data","monotonic_ns":313692965389083,"payload":{"event_type":"price_change","market":"0xd412ce774cfcf8dc9f71164aac78783978aac7b03871702a3b8a481bd9dc9688","price_changes":[{"asset_id":"107603864457683460275633293642179940881969192120168665300712204232021063124301","best_ask":"0.63","best_bid":"0.62","hash":"15e9ba57139fe528eeb668909efae21112d7989c","price":"0.3","side":"BUY","size":"47.3"},{"asset_id":"96600821790790307414914106093858868634329285205417149685270682748367152458577","best_ask":"0.38","best_bid":"0.37","hash":"e0b146b77d2714e42cc38f80c9ad130cdedbc8ae","price":"0.7","side":"SELL","size":"47.3"}],"timestamp":"1785211706105"},"payload_hash":"febf1d0a0537af3782a6c2ec7528b2736618700657338f8fdf6b29bd6db0d113","raw_frame":"{\"market\":\"0xd412ce774cfcf8dc9f71164aac78783978aac7b03871702a3b8a481bd9dc9688\", \"price_changes\":[{\"asset_id\":\"107603864457683460275633293642179940881969192120168665300712204232021063124301\", \"price\":\"0.3\", \"size\":\"47.3\", \"side\":\"BUY\", \"hash\":\"15e9ba57139fe528eeb668909efae21112d7989c\", \"best_bid\":\"0.62\", \"best_ask\":\"0.63\"}, {\"asset_id\":\"96600821790790307414914106093858868634329285205417149685270682748367152458577\", \"price\":\"0.7\", \"size\":\"47.3\", \"side\":\"SELL\", \"hash\":\"e0b146b77d2714e42cc38f80c9ad130cdedbc8ae\", \"best_bid\":\"0.37\", \"best_ask\":\"0.38\"}], \"timestamp\":\"1785211706105\", \"event_type\":\"price_change\"}","received_at":"2026-07-28T04:08:29.897879Z","schema_version":"clob-market-ws.price_change.v1","sequence":null,"server_hash":null,"server_timestamp":"1785211706105","session_id":"2d607381e3054cee91998cdf45a4231c","source":"clob_market_ws"},"received_at":"2026-07-28T04:08:29.897879Z","record_id":"2c8e187733829695c70150655ceaeb1b8da45eadae2426be39cd4778d70953f7","schema_fingerprint":"4aa3821a28b0b7c2400bc59aba4bcc0a76e971dadd19610d3ad38c768e124dc7","schema_version":"edge-lab-recorder.raw.v1","sequence":null,"source":"clob_market_ws"}
{"event_at":"2026-07-28T04:08:26.114000Z","event_fingerprint":"f6a4640c45785bf83603d9d01f7b3fa66847b361bb920a859a9e5484b81e28ac","payload":{"connection_id":"f6725804f86a4c4eb588e4d5ed7db029","event_at":"2026-07-28T04:08:26.114000Z","event_type":"price_change","frame_hash":"91d3ea00ab10eedb36dd01a7d2d339371e638f72aefe58b93640cf684e1cf807","frame_index":0,"kind":"data","monotonic_ns":313692968525625,"payload":{"event_type":"price_change","market":"0xd412ce774cfcf8dc9f71164aac78783978aac7b03871702a3b8a481bd9dc9688","price_changes":[{"asset_id":"107603864457683460275633293642179940881969192120168665300712204232021063124301","best_ask":"0.63","best_bid":"0.62","hash":"96fef0c745922811d287cba642ae81a7a1db8fb4","price":"0.04","side":"BUY","size":"618.09"},{"asset_id":"96600821790790307414914106093858868634329285205417149685270682748367152458577","best_ask":"0.38","best_bid":"0.37","hash":"ab03e379893c8e0e438c48170c08b3c4704d7637","price":"0.96","side":"SELL","size":"618.09"}],"timestamp":"1785211706114"},"payload_hash":"1f8041e24258a98d4ce5ccb129070976b4cbeddde0ecbb54081098f1f4f9f1b9","raw_frame":"{\"market\":\"0xd412ce774cfcf8dc9f71164aac78783978aac7b03871702a3b8a481bd9dc9688\", \"price_changes\":[{\"asset_id\":\"107603864457683460275633293642179940881969192120168665300712204232021063124301\", \"price\":\"0.04\", \"size\":\"618.09\", \"side\":\"BUY\", \"hash\":\"96fef0c745922811d287cba642ae81a7a1db8fb4\", \"best_bid\":\"0.62\", \"best_ask\":\"0.63\"}, {\"asset_id\":\"96600821790790307414914106093858868634329285205417149685270682748367152458577\", \"price\":\"0.96\", \"size\":\"618.09\", \"side\":\"SELL\", \"hash\":\"ab03e379893c8e0e438c48170c08b3c4704d7637\", \"best_bid\":\"0.37\", \"best_ask\":\"0.38\"}], \"timestamp\":\"1785211706114\", \"event_type\":\"price_change\"}","received_at":"2026-07-28T04:08:29.901013Z","schema_version":"clob-market-ws.price_change.v1","sequence":null,"server_hash":null,"server_timestamp":"1785211706114","session_id":"2d607381e3054cee91998cdf45a4231c","source":"clob_market_ws"},"received_at":"2026-07-28T04:08:29.901013Z","record_id":"ab270d58c2208b9ab79401672ccb1cbc4e3380c4d8b906ad8dc365753d8fd452","schema_fingerprint":"4aa3821a28b0b7c2400bc59aba4bcc0a76e971dadd19610d3ad38c768e124dc7","schema_version":"edge-lab-recorder.raw.v1","sequence":null,"source":"clob_market_ws"}
{"event_at":"2026-07-28T04:08:26.108000Z","event_fingerprint":"35a5151b009e80f3dfeb60e58b387b4987538ffc13e2fc22b44fcc3a8d2caafd","payload":{"connection_id":"f6725804f86a4c4eb588e4d5ed7db029","event_at":"2026-07-28T04:08:26.108000Z","event_type":"last_trade_price","frame_hash":"cca7ae6ad5de0e113274733acd341173f8e24409b5d094b153f539c427a32baf","frame_index":0,"kind":"data","monotonic_ns":313692970420500,"payload":{"asset_id":"107603864457683460275633293642179940881969192120168665300712204232021063124301","event_type":"last_trade_price","fee_rate_bps":"0","market":"0xd412ce774cfcf8dc9f71164aac78783978aac7b03871702a3b8a481bd9dc9688","price":"0.62","side":"SELL","size":"0.02","timestamp":"1785211706108","transaction_hash":"0xcf9ded4ca885851353356b853ed5eae661f731172c19e2d4844624e3334d2ac4"},"payload_hash":"dce58d45b90f4599de013240afdaf089d26a6c1609e6b767a098c95d84f66f25","raw_frame":"{\"market\":\"0xd412ce774cfcf8dc9f71164aac78783978aac7b03871702a3b8a481bd9dc9688\", \"asset_id\":\"107603864457683460275633293642179940881969192120168665300712204232021063124301\", \"price\":\"0.62\", \"size\":\"0.02\", \"fee_rate_bps\":\"0\", \"side\":\"SELL\", \"timestamp\":\"1785211706108\", \"event_type\":\"last_trade_price\", \"transaction_hash\":\"0xcf9ded4ca885851353356b853ed5eae661f731172c19e2d4844624e3334d2ac4\"}","received_at":"2026-07-28T04:08:29.902913Z","schema_version":"clob-market-ws.last_trade_price.v1","sequence":null,"server_hash":null,"server_timestamp":"1785211706108","session_id":"2d607381e3054cee91998cdf45a4231c","source":"clob_market_ws"},"received_at":"2026-07-28T04:08:29.902913Z","record_id":"41e2bdf957ca789fbcc2dbe69eafe0b6b198b58811aca7e9ed9f36db7408ad4f","schema_fingerprint":"95ad9be75a4b695cd99991e12b2592bc7346f3f5388a82d0000ba65bc0d9fd0a","schema_version":"edge-lab-recorder.raw.v1","sequence":null,"source":"clob_market_ws"}
{"event_at":"2026-07-28T04:08:26.118000Z","event_fingerprint":"125eff742c1c322e77f0867d6548cff1a0255a749ade5720a4efc6cb7dd09c29","payload":{"connection_id":"f6725804f86a4c4eb588e4d5ed7db029","event_at":"2026-07-28T04:08:26.118000Z","event_type":"price_change","frame_hash":"7144b27061d9e8f04eb7105c6b5247a94212a7d64791a3b89609b974adf4381a","frame_index":0,"kind":"data","monotonic_ns":313692972129291,"payload":{"event_type":"price_change","market":"0xd412ce774cfcf8dc9f71164aac78783978aac7b03871702a3b8a481bd9dc9688","price_changes":[{"asset_id":"96600821790790307414914106093858868634329285205417149685270682748367152458577","best_ask":"0.38","best_bid":"0.37","hash":"d9a4c846473c2cd71e055395ed0a0128766a6049","price":"0.37","side":"BUY","size":"226.88"},{"asset_id":"107603864457683460275633293642179940881969192120168665300712204232021063124301","best_ask":"0.63","best_bid":"0.62","hash":"7eccc64b6689d08d675fe94a3130b84c20e94e1d","price":"0.63","side":"SELL","size":"226.88"}],"timestamp":"1785211706118"},"payload_hash":"c5100e0a8707a7fa158855641326d6fe22ca8fabb81d91398682446b9b776538","raw_frame":"{\"market\":\"0xd412ce774cfcf8dc9f71164aac78783978aac7b03871702a3b8a481bd9dc9688\", \"price_changes\":[{\"asset_id\":\"96600821790790307414914106093858868634329285205417149685270682748367152458577\", \"price\":\"0.37\", \"size\":\"226.88\", \"side\":\"BUY\", \"hash\":\"d9a4c846473c2cd71e055395ed0a0128766a6049\", \"best_bid\":\"0.37\", \"best_ask\":\"0.38\"}, {\"asset_id\":\"107603864457683460275633293642179940881969192120168665300712204232021063124301\", \"price\":\"0.63\", \"size\":\"226.88\", \"side\":\"SELL\", \"hash\":\"7eccc64b6689d08d675fe94a3130b84c20e94e1d\", \"best_bid\":\"0.62\", \"best_ask\":\"0.63\"}], \"timestamp\":\"1785211706118\", \"event_type\":\"price_change\"}","received_at":"2026-07-28T04:08:29.904615Z","schema_version":"clob-market-ws.price_change.v1","sequence":null,"server_hash":null,"server_timestamp":"1785211706118","session_id":"2d607381e3054cee91998cdf45a4231c","source":"clob_market_ws"},"received_at":"2026-07-28T04:08:29.904615Z","record_id":"4390184525b8b4cd2f07d616a26c02f38b0b0d16bab10f5dc9c31b92024df686","schema_fingerprint":"4aa3821a28b0b7c2400bc59aba4bcc0a76e971dadd19610d3ad38c768e124dc7","schema_version":"edge-lab-recorder.raw.v1","sequence":null,"source":"clob_market_ws"}
{"event_at":"2026-07-28T04:08:26.133000Z","event_fingerprint":"d72491c1498f0e2a6948cfc55e0f61e562835dcfe7ac2df4f41c78db1c743058","payload":{"connection_id":"f6725804f86a4c4eb588e4d5ed7db029","event_at":"2026-07-28T04:08:26.133000Z","event_type":"price_change","frame_hash":"032a2c5065a3c180aef7f5d3107e1e187080e4ea13cfee303b7e3f7a96583619","frame_index":0,"kind":"data","monotonic_ns":313692975186916,"payload":{"event_type":"price_change","market":"0xd412ce774cfcf8dc9f71164aac78783978aac7b03871702a3b8a481bd9dc9688","price_changes":[{"asset_id":"107603864457683460275633293642179940881969192120168665300712204232021063124301","best_ask":"0.63","best_bid":"0.62","hash":"f62f668c183d4dbd37602289d9aaf9ce1839fb72","price":"0.41","side":"BUY","size":"35.14"},{"asset_id":"96600821790790307414914106093858868634329285205417149685270682748367152458577","best_ask":"0.38","best_bid":"0.37","hash":"924a2eb5fb97b41ccb90637a25dd54314221b9c0","price":"0.59","side":"SELL","size":"35.14"}],"timestamp":"1785211706133"},"payload_hash":"ac4d6ed9265484718b95454b92bf410ffeec4e66691c2d52c55e8c5fabbca58c","raw_frame":"{\"market\":\"0xd412ce774cfcf8dc9f71164aac78783978aac7b03871702a3b8a481bd9dc9688\", \"price_changes\":[{\"asset_id\":\"107603864457683460275633293642179940881969192120168665300712204232021063124301\", \"price\":\"0.41\", \"size\":\"35.14\", \"side\":\"BUY\", \"hash\":\"f62f668c183d4dbd37602289d9aaf9ce1839fb72\", \"best_bid\":\"0.62\", \"best_ask\":\"0.63\"}, {\"asset_id\":\"96600821790790307414914106093858868634329285205417149685270682748367152458577\", \"price\":\"0.59\", \"size\":\"35.14\", \"side\":\"SELL\", \"hash\":\"924a2eb5fb97b41ccb90637a25dd54314221b9c0\", \"best_bid\":\"0.37\", \"best_ask\":\"0.38\"}], \"timestamp\":\"1785211706133\", \"event_type\":\"price_change\"}","received_at":"2026-07-28T04:08:29.907670Z","schema_version":"clob-market-ws.price_change.v1","sequence":null,"server_hash":null,"server_timestamp":"1785211706133","session_id":"2d607381e3054cee91998cdf45a4231c","source":"clob_market_ws"},"received_at":"2026-07-28T04:08:29.907670Z","record_id":"b5373dbccbfdb19028560f0774ace44f191b3d62a8fb44d1fdbfce9df65705e7","schema_fingerprint":"4aa3821a28b0b7c2400bc59aba4bcc0a76e971dadd19610d3ad38c768e124dc7","schema_version":"edge-lab-recorder.raw.v1","sequence":null,"source":"clob_market_ws"}
{"event_at":"2026-07-28T04:08:26.164000Z","event_fingerprint":"738104ba2308a218005afb446ec555ab4763d51641952fb7b1cef47d75e3f0d6","payload":{"connection_id":"f6725804f86a4c4eb588e4d5ed7db029","event_at":"2026-07-28T04:08:26.164000Z","event_type":"best_bid_ask","frame_hash":"4458b26f683d921bee7a80a9a6b98fea99145f58d73d172b80233569ab6053f4","frame_index":0,"kind":"data","monotonic_ns":313692978176791,"payload":{"asset_id":"107603864457683460275633293642179940881969192120168665300712204232021063124301","best_ask":"0.63","best_bid":"0.58","event_type":"best_bid_ask","market":"0xd412ce774cfcf8dc9f71164aac78783978aac7b03871702a3b8a481bd9dc9688","spread":"0.05","timestamp":"1785211706164"},"payload_hash":"f49d8a64be157f7c546e1b7c5bb0c8733376f836e8e78b9b1458c89fd51d46e3","raw_frame":"{\"market\":\"0xd412ce774cfcf8dc9f71164aac78783978aac7b03871702a3b8a481bd9dc9688\", \"asset_id\":\"107603864457683460275633293642179940881969192120168665300712204232021063124301\", \"best_bid\":\"0.58\", \"best_ask\":\"0.63\", \"spread\":\"0.05\", \"timestamp\":\"1785211706164\", \"event_type\":\"best_bid_ask\"}","received_at":"2026-07-28T04:08:29.910659Z","schema_version":"clob-market-ws.best_bid_ask.v1","sequence":null,"server_hash":null,"server_timestamp":"1785211706164","session_id":"2d607381e3054cee91998cdf45a4231c","source":"clob_market_ws"},"received_at":"2026-07-28T04:08:29.910659Z","record_id":"0009aced8b67a300a9f96e71afdc6278a9f14fe0a83030c43866040c1e24d0a5","schema_fingerprint":"8488399f31b0337811b13b266be932db7062827c2470b78bd8e9e99bab51d17d","schema_version":"edge-lab-recorder.raw.v1","sequence":null,"source":"clob_market_ws"}
{"event_at":"2026-07-28T04:08:26.164000Z","event_fingerprint":"5eec60869f53165a6697fcd58488de7238c297b939cc72b0ad499596c0110311","payload":{"connection_id":"f6725804f86a4c4eb588e4d5ed7db029","event_at":"2026-07-28T04:08:26.164000Z","event_type":"best_bid_ask","frame_hash":"3cb1bf00bb1290d3a7c415f0124ae15b8e346a9e5fcc799f935b25a4a4fd8d3d","frame_index":0,"kind":"data","monotonic_ns":313692980785791,"payload":{"asset_id":"96600821790790307414914106093858868634329285205417149685270682748367152458577","best_ask":"0.42","best_bid":"0.37","event_type":"best_bid_ask","market":"0xd412ce774cfcf8dc9f71164aac78783978aac7b03871702a3b8a481bd9dc9688","spread":"0.05","timestamp":"1785211706164"},"payload_hash":"9e8af21995a02cc60904ba6e31a2e0e0b6db80a7089f33de7d62465584174a13","raw_frame":"{\"market\":\"0xd412ce774cfcf8dc9f71164aac78783978aac7b03871702a3b8a481bd9dc9688\", \"asset_id\":\"96600821790790307414914106093858868634329285205417149685270682748367152458577\", \"best_bid\":\"0.37\", \"best_ask\":\"0.42\", \"spread\":\"0.05\", \"timestamp\":\"1785211706164\", \"event_type\":\"best_bid_ask\"}","received_at":"2026-07-28T04:08:29.913268Z","schema_version":"clob-market-ws.best_bid_ask.v1","sequence":null,"server_hash":null,"server_timestamp":"1785211706164","session_id":"2d607381e3054cee91998cdf45a4231c","source":"clob_market_ws"},"received_at":"2026-07-28T04:08:29.913268Z","record_id":"3d36a8bed84e6d0491a64c79e468c5200b8648ace9bd5604754d41ba3310e040","schema_fingerprint":"8488399f31b0337811b13b266be932db7062827c2470b78bd8e9e99bab51d17d","schema_version":"edge-lab-recorder.raw.v1","sequence":null,"source":"clob_market_ws"}
{"event_at":"2026-07-28T04:08:26.164000Z","event_fingerprint":"13e110e1f2ff9dfc1ea3e97f503edbf6fd72d17fa669f700d96260392ef2cb32","payload":{"connection_id":"f6725804f86a4c4eb588e4d5ed7db029","event_at":"2026-07-28T04:08:26.164000Z","event_type":"price_change","frame_hash":"0ebedee7adaac88af6a22871fdccda147ecc70e2e2242005fe2e0166f8e8e496","frame_index":0,"kind":"data","monotonic_ns":313692983254333,"payload":{"event_type":"price_change","market":"0xd412ce774cfcf8dc9f71164aac78783978aac7b03871702a3b8a481bd9dc9688","price_changes":[{"asset_id":"107603864457683460275633293642179940881969192120168665300712204232021063124301","best_ask":"0.63","best_bid":"0.58","hash":"59257587819e9857597a4ef120f81b6be70722ed","price":"0.62","side":"BUY","size":"0"},{"asset_id":"96600821790790307414914106093858868634329285205417149685270682748367152458577","best_ask":"0.42","best_bid":"0.37","hash":"95ab8d1c5ceab88548f9d16ec6dd6583ff803375","price":"0.38","side":"SELL","size":"0"}],"timestamp":"1785211706164"},"payload_hash":"175830f099f33a2140dedd1ba9ce884159122f0665e64fb777956bfa1bc10928","raw_frame":"{\"market\":\"0xd412ce774cfcf8dc9f71164aac78783978aac7b03871702a3b8a481bd9dc9688\", \"price_changes\":[{\"asset_id\":\"107603864457683460275633293642179940881969192120168665300712204232021063124301\", \"price\":\"0.62\", \"size\":\"0\", \"side\":\"BUY\", \"hash\":\"59257587819e9857597a4ef120f81b6be70722ed\", \"best_bid\":\"0.58\", \"best_ask\":\"0.63\"}, {\"asset_id\":\"96600821790790307414914106093858868634329285205417149685270682748367152458577\", \"price\":\"0.38\", \"size\":\"0\", \"side\":\"SELL\", \"hash\":\"95ab8d1c5ceab88548f9d16ec6dd6583ff803375\", \"best_bid\":\"0.37\", \"best_ask\":\"0.42\"}], \"timestamp\":\"1785211706164\", \"event_type\":\"price_change\"}","received_at":"2026-07-28T04:08:29.915735Z","schema_version":"clob-market-ws.price_change.v1","sequence":null,"server_hash":null,"server_timestamp":"1785211706164","session_id":"2d607381e3054cee91998cdf45a4231c","source":"clob_market_ws"},"received_at":"2026-07-28T04:08:29.915735Z","record_id":"3e5289e423b2dd92a1830ff70e6fa0ba038d720f205edce744704e78a5010b5c","schema_fingerprint":"4aa3821a28b0b7c2400bc59aba4bcc0a76e971dadd19610d3ad38c768e124dc7","schema_version":"edge-lab-recorder.raw.v1","sequence":null,"source":"clob_market_ws"}
{"event_at":"2026-07-28T04:08:26.164000Z","event_fingerprint":"c995b4294038f9de363699bbf4aa615c538077eaaa25b36731d1ed94f75767d4","payload":{"connection_id":"f6725804f86a4c4eb588e4d5ed7db029","event_at":"2026-07-28T04:08:26.164000Z","event_type":"book","frame_hash":"80ea87b88989f6176ebfc62d3b5463283da49c3ae005d6c82469b6415a9414a1","frame_index":0,"kind":"data","monotonic_ns":313692986460375,"payload":{"asks":[{"price":"0.99","size":"5608.02"},{"price":"0.98","size":"778.1"},{"price":"0.97","size":"648.1"},{"price":"0.96","size":"588.09"},{"price":"0.95","size":"676.2"},{"price":"0.94","size":"605.2"},{"price":"0.93","size":"65.1"},{"price":"0.92","size":"67.79"},{"price":"0.91","size":"81.6"},{"price":"0.9","size":"102.29"},{"price":"0.89","size":"43.6"},{"price":"0.88","size":"80.4"},{"price":"0.87","size":"37.5"},{"price":"0.86","size":"34.9"},{"price":"0.85","size":"87.5"},{"price":"0.84","size":"431.3"},{"price":"0.83","size":"130.3"},{"price":"0.82","size":"158.3"},{"price":"0.81","size":"127.5"},{"price":"0.8","size":"154.8"},{"price":"0.79","size":"156.1"},{"price":"0.78","size":"130.5"},{"price":"0.77","size":"216.89"},{"price":"0.76","size":"261.89"},{"price":"0.75","size":"228"},{"price":"0.74","size":"209.6"},{"price":"0.73","size":"234.2"},{"price":"0.72","size":"201.9"},{"price":"0.71","size":"292.31"},{"price":"0.7","size":"112"},{"price":"0.69","size":"114.38"},{"price":"0.68","size":"115.98"},{"price":"0.67","size":"185.98"},{"price":"0.66","size":"140.29"},{"price":"0.65","size":"143.45"},{"price":"0.64","size":"183.2"},{"price":"0.63","size":"226.88"}],"asset_id":"107603864457683460275633293642179940881969192120168665300712204232021063124301","bids":[{"price":"0.01","size":"5638.02"},{"price":"0.02","size":"688.1"},{"price":"0.03","size":"618.1"},{"price":"0.04","size":"618.09"},{"price":"0.05","size":"653.2"},{"price":"0.06","size":"553.2"},{"price":"0.07","size":"576.1"},{"price":"0.08","size":"550.79"},{"price":"0.09","size":"536.6"},{"price":"0.1","size":"218.29"},{"price":"0.11","size":"30.6"},{"price":"0.12","size":"38.4"},{"price":"0.13","size":"56.5"},{"price":"0.14","size":"34.9"},{"price":"0.15","size":"64.5"},{"price":"0.16","size":"71.3"},{"price":"0.17","size":"30.3"},{"price":"0.18","size":"28.3"},{"price":"0.19","size":"57.5"},{"price":"0.2","size":"59.8"},{"price":"0.21","size":"26.1"},{"price":"0.22","size":"54.5"},{"price":"0.23","size":"23.89"},{"price":"0.24","size":"23.39"},{"price":"0.25","size":"82"},{"price":"0.26","size":"21.6"},{"price":"0.27","size":"21.2"},{"price":"0.28","size":"50.9"},{"price":"0.29","size":"20.6"},{"price":"0.3","size":"47.3"},{"price":"0.31","size":"50"},{"price":"0.32","size":"123.96"},{"price":"0.33","size":"120.61"},{"price":"0.34","size":"64.4"},{"price":"0.35","size":"38.2"},{"price":"0.36","size":"18"},{"price":"0.37","size":"47.9"},{"price":"0.38","size":"27.7"},{"price":"0.39","size":"30.15"},{"price":"0.4","size":"73.96"},{"price":"0.41","size":"35.14"},{"price":"0.42","size":"29.59"},{"price":"0.43","size":"52.2"},{"price":"0.44","size":"5"},{"price":"0.45","size":"13"},{"price":"0.46","size":"35"},{"price":"0.47","size":"5"},{"price":"0.48","size":"147"},{"price":"0.49","size":"176"},{"price":"0.5","size":"248"},{"price":"0.51","size":"163"},{"price":"0.52","size":"200"},{"price":"0.53","size":"163.02"},{"price":"0.54","size":"156"},{"price":"0.55","size":"151"},{"price":"0.56","size":"47"},{"price":"0.57","size":"35"},{"price":"0.58","size":"34"}],"event_type":"book","hash":"59257587819e9857597a4ef120f81b6be70722ed","market":"0xd412ce774cfcf8dc9f71164aac78783978aac7b03871702a3b8a481bd9dc9688","timestamp":"1785211706164"},"payload_hash":"225bc9f8af6e60e29522dadca117a6261a4ec5d26dd0b20f5c6e4527ac85d377","raw_frame":"{\"market\":\"0xd412ce774cfcf8dc9f71164aac78783978aac7b03871702a3b8a481bd9dc9688\", \"asset_id\":\"107603864457683460275633293642179940881969192120168665300712204232021063124301\", \"bids\":[{\"price\":\"0.01\", \"size\":\"5638.02\"}, {\"price\":\"0.02\", \"size\":\"688.1\"}, {\"price\":\"0.03\", \"size\":\"618.1\"}, {\"price\":\"0.04\", \"size\":\"618.09\"}, {\"price\":\"0.05\", \"size\":\"653.2\"}, {\"price\":\"0.06\", \"size\":\"553.2\"}, {\"price\":\"0.07\", \"size\":\"576.1\"}, {\"price\":\"0.08\", \"size\":\"550.79\"}, {\"price\":\"0.09\", \"size\":\"536.6\"}, {\"price\":\"0.1\", \"size\":\"218.29\"}, {\"price\":\"0.11\", \"size\":\"30.6\"}, {\"price\":\"0.12\", \"size\":\"38.4\"}, {\"price\":\"0.13\", \"size\":\"56.5\"}, {\"price\":\"0.14\", \"size\":\"34.9\"}, {\"price\":\"0.15\", \"size\":\"64.5\"}, {\"price\":\"0.16\", \"size\":\"71.3\"}, {\"price\":\"0.17\", \"size\":\"30.3\"}, {\"price\":\"0.18\", \"size\":\"28.3\"}, {\"price\":\"0.19\", \"size\":\"57.5\"}, {\"price\":\"0.2\", \"size\":\"59.8\"}, {\"price\":\"0.21\", \"size\":\"26.1\"}, {\"price\":\"0.22\", \"size\":\"54.5\"}, {\"price\":\"0.23\", \"size\":\"23.89\"}, {\"price\":\"0.24\", \"size\":\"23.39\"}, {\"price\":\"0.25\", \"size\":\"82\"}, {\"price\":\"0.26\", \"size\":\"21.6\"}, {\"price\":\"0.27\", \"size\":\"21.2\"}, {\"price\":\"0.28\", \"size\":\"50.9\"}, {\"price\":\"0.29\", \"size\":\"20.6\"}, {\"price\":\"0.3\", \"size\":\"47.3\"}, {\"price\":\"0.31\", \"size\":\"50\"}, {\"price\":\"0.32\", \"size\":\"123.96\"}, {\"price\":\"0.33\", \"size\":\"120.61\"}, {\"price\":\"0.34\", \"size\":\"64.4\"}, {\"price\":\"0.35\", \"size\":\"38.2\"}, {\"price\":\"0.36\", \"size\":\"18\"}, {\"price\":\"0.37\", \"size\":\"47.9\"}, {\"price\":\"0.38\", \"size\":\"27.7\"}, {\"price\":\"0.39\", \"size\":\"30.15\"}, {\"price\":\"0.4\", \"size\":\"73.96\"}, {\"price\":\"0.41\", \"size\":\"35.14\"}, {\"price\":\"0.42\", \"size\":\"29.59\"}, {\"price\":\"0.43\", \"size\":\"52.2\"}, {\"price\":\"0.44\", \"size\":\"5\"}, {\"price\":\"0.45\", \"size\":\"13\"}, {\"price\":\"0.46\", \"size\":\"35\"}, {\"price\":\"0.47\", \"size\":\"5\"}, {\"price\":\"0.48\", \"size\":\"147\"}, {\"price\":\"0.49\", \"size\":\"176\"}, {\"price\":\"0.5\", \"size\":\"248\"}, {\"price\":\"0.51\", \"size\":\"163\"}, {\"price\":\"0.52\", \"size\":\"200\"}, {\"price\":\"0.53\", \"size\":\"163.02\"}, {\"price\":\"0.54\", \"size\":\"156\"}, {\"price\":\"0.55\", \"size\":\"151\"}, {\"price\":\"0.56\", \"size\":\"47\"}, {\"price\":\"0.57\", \"size\":\"35\"}, {\"price\":\"0.58\", \"size\":\"34\"}], \"asks\":[{\"price\":\"0.99\", \"size\":\"5608.02\"}, {\"price\":\"0.98\", \"size\":\"778.1\"}, {\"price\":\"0.97\", \"size\":\"648.1\"}, {\"price\":\"0.96\", \"size\":\"588.09\"}, {\"price\":\"0.95\", \"size\":\"676.2\"}, {\"price\":\"0.94\", \"size\":\"605.2\"}, {\"price\":\"0.93\", \"size\":\"65.1\"}, {\"price\":\"0.92\", \"size\":\"67.79\"}, {\"price\":\"0.91\", \"size\":\"81.6\"}, {\"price\":\"0.9\", \"size\":\"102.29\"}, {\"price\":\"0.89\", \"size\":\"43.6\"}, {\"price\":\"0.88\", \"size\":\"80.4\"}, {\"price\":\"0.87\", \"size\":\"37.5\"}, {\"price\":\"0.86\", \"size\":\"34.9\"}, {\"price\":\"0.85\", \"size\":\"87.5\"}, {\"price\":\"0.84\", \"size\":\"431.3\"}, {\"price\":\"0.83\", \"size\":\"130.3\"}, {\"price\":\"0.82\", \"size\":\"158.3\"}, {\"price\":\"0.81\", \"size\":\"127.5\"}, {\"price\":\"0.8\", \"size\":\"154.8\"}, {\"price\":\"0.79\", \"size\":\"156.1\"}, {\"price\":\"0.78\", \"size\":\"130.5\"}, {\"price\":\"0.77\", \"size\":\"216.89\"}, {\"price\":\"0.76\", \"size\":\"261.89\"}, {\"price\":\"0.75\", \"size\":\"228\"}, {\"price\":\"0.74\", \"size\":\"209.6\"}, {\"price\":\"0.73\", \"size\":\"234.2\"}, {\"price\":\"0.72\", \"size\":\"201.9\"}, {\"price\":\"0.71\", \"size\":\"292.31\"}, {\"price\":\"0.7\", \"size\":\"112\"}, {\"price\":\"0.69\", \"size\":\"114.38\"}, {\"price\":\"0.68\", \"size\":\"115.98\"}, {\"price\":\"0.67\", \"size\":\"185.98\"}, {\"price\":\"0.66\", \"size\":\"140.29\"}, {\"price\":\"0.65\", \"size\":\"143.45\"}, {\"price\":\"0.64\", \"size\":\"183.2\"}, {\"price\":\"0.63\", \"size\":\"226.88\"}], \"hash\":\"59257587819e9857597a4ef120f81b6be70722ed\", \"timestamp\":\"1785211706164\", \"event_type\":\"book\"}","received_at":"2026-07-28T04:08:29.918940Z","schema_version":"clob-market-ws.book.v1","sequence":null,"server_hash":"59257587819e9857597a4ef120f81b6be70722ed","server_timestamp":"1785211706164","session_id":"2d607381e3054cee91998cdf45a4231c","source":"clob_market_ws"},"received_at":"2026-07-28T04:08:29.918940Z","record_id":"9fb86874aef6f7b963e151aa4c8e6ed6e03f4c085e687e08156c417d680b899b","schema_fingerprint":"dc2caa1c89c6a7426e2e07ff925910cd4d0a8a223a515d4092d91d6d127aacb6","schema_version":"edge-lab-recorder.raw.v1","sequence":null,"source":"clob_market_ws"}
{"event_at":"2026-07-28T04:08:26.164000Z","event_fingerprint":"1870a93cb5074443bb9bf3af994d497ec1ecac80c7f7c947120399804c0c8896","payload":{"connection_id":"f6725804f86a4c4eb588e4d5ed7db029","event_at":"2026-07-28T04:08:26.164000Z","event_type":"book","frame_hash":"25c5d8539a944b2701be82781e21e0c72311d0742fc6ac0585943b5aa32fa073","frame_index":0,"kind":"data","monotonic_ns":313692997079625,"payload":{"asks":[{"price":"0.99","size":"5638.02"},{"price":"0.98","size":"688.1"},{"price":"0.97","size":"618.1"},{"price":"0.96","size":"618.09"},{"price":"0.95","size":"653.2"},{"price":"0.94","size":"553.2"},{"price":"0.93","size":"576.1"},{"price":"0.92","size":"550.79"},{"price":"0.91","size":"536.6"},{"price":"0.9","size":"218.29"},{"price":"0.89","size":"30.6"},{"price":"0.88","size":"38.4"},{"price":"0.87","size":"56.5"},{"price":"0.86","size":"34.9"},{"price":"0.85","size":"64.5"},{"price":"0.84","size":"71.3"},{"price":"0.83","size":"30.3"},{"price":"0.82","size":"28.3"},{"price":"0.81","size":"57.5"},{"price":"0.8","size":"59.8"},{"price":"0.79","size":"26.1"},{"price":"0.78","size":"54.5"},{"price":"0.77","size":"23.89"},{"price":"0.76","size":"23.39"},{"price":"0.75","size":"82"},{"price":"0.74","size":"21.6"},{"price":"0.73","size":"21.2"},{"price":"0.72","size":"50.9"},{"price":"0.71","size":"20.6"},{"price":"0.7","size":"47.3"},{"price":"0.69","size":"50"},{"price":"0.68","size":"123.96"},{"price":"0.67","size":"120.61"},{"price":"0.66","size":"64.4"},{"price":"0.65","size":"38.2"},{"price":"0.64","size":"18"},{"price":"0.63","size":"47.9"},{"price":"0.62","size":"27.7"},{"price":"0.61","size":"30.15"},{"price":"0.6","size":"73.96"},{"price":"0.59","size":"35.14"},{"price":"0.58","size":"29.59"},{"price":"0.57","size":"52.2"},{"price":"0.56","size":"5"},{"price":"0.55","size":"13"},{"price":"0.54","size":"35"},{"price":"0.53","size":"5"},{"price":"0.52","size":"147"},{"price":"0.51","size":"176"},{"price":"0.5","size":"248"},{"price":"0.49","size":"163"},{"price":"0.48","size":"200"},{"price":"0.47","size":"163.02"},{"price":"0.46","size":"156"},{"price":"0.45","size":"151"},{"price":"0.44","size":"47"},{"price":"0.43","size":"35"},{"price":"0.42","size":"34"}],"asset_id":"96600821790790307414914106093858868634329285205417149685270682748367152458577","bids":[{"price":"0.01","size":"5608.02"},{"price":"0.02","size":"778.1"},{"price":"0.03","size":"648.1"},{"price":"0.04","size":"588.09"},{"price":"0.05","size":"676.2"},{"price":"0.06","size":"605.2"},{"price":"0.07","size":"65.1"},{"price":"0.08","size":"67.79"},{"price":"0.09","size":"81.6"},{"price":"0.1","size":"102.29"},{"price":"0.11","size":"43.6"},{"price":"0.12","size":"80.4"},{"price":"0.13","size":"37.5"},{"price":"0.14","size":"34.9"},{"price":"0.15","size":"87.5"},{"price":"0.16","size":"431.3"},{"price":"0.17","size":"130.3"},{"price":"0.18","size":"158.3"},{"price":"0.19","size":"127.5"},{"price":"0.2","size":"154.8"},{"price":"0.21","size":"156.1"},{"price":"0.22","size":"130.5"},{"price":"0.23","size":"216.89"},{"price":"0.24","size":"261.89"},{"price":"0.25","size":"228"},{"price":"0.26","size":"209.6"},{"price":"0.27","size":"234.2"},{"price":"0.28","size":"201.9"},{"price":"0.29","size":"292.31"},{"price":"0.3","size":"112"},{"price":"0.31","size":"114.38"},{"price":"0.32","size":"115.98"},{"price":"0.33","size":"185.98"},{"price":"0.34","size":"140.29"},{"price":"0.35","size":"143.45"},{"price":"0.36","size":"183.2"},{"price":"0.37","size":"226.88"}],"event_type":"book","hash":"95ab8d1c5ceab88548f9d16ec6dd6583ff803375","market":"0xd412ce774cfcf8dc9f71164aac78783978aac7b03871702a3b8a481bd9dc9688","timestamp":"1785211706164"},"payload_hash":"d143818841d72665ec57d17e6150ee1e04f1a9ab7ae5a2f8eef3473efa1b3e44","raw_frame":"{\"market\":\"0xd412ce774cfcf8dc9f71164aac78783978aac7b03871702a3b8a481bd9dc9688\", \"asset_id\":\"96600821790790307414914106093858868634329285205417149685270682748367152458577\", \"bids\":[{\"price\":\"0.01\", \"size\":\"5608.02\"}, {\"price\":\"0.02\", \"size\":\"778.1\"}, {\"price\":\"0.03\", \"size\":\"648.1\"}, {\"price\":\"0.04\", \"size\":\"588.09\"}, {\"price\":\"0.05\", \"size\":\"676.2\"}, {\"price\":\"0.06\", \"size\":\"605.2\"}, {\"price\":\"0.07\", \"size\":\"65.1\"}, {\"price\":\"0.08\", \"size\":\"67.79\"}, {\"price\":\"0.09\", \"size\":\"81.6\"}, {\"price\":\"0.1\", \"size\":\"102.29\"}, {\"price\":\"0.11\", \"size\":\"43.6\"}, {\"price\":\"0.12\", \"size\":\"80.4\"}, {\"price\":\"0.13\", \"size\":\"37.5\"}, {\"price\":\"0.14\", \"size\":\"34.9\"}, {\"price\":\"0.15\", \"size\":\"87.5\"}, {\"price\":\"0.16\", \"size\":\"431.3\"}, {\"price\":\"0.17\", \"size\":\"130.3\"}, {\"price\":\"0.18\", \"size\":\"158.3\"}, {\"price\":\"0.19\", \"size\":\"127.5\"}, {\"price\":\"0.2\", \"size\":\"154.8\"}, {\"price\":\"0.21\", \"size\":\"156.1\"}, {\"price\":\"0.22\", \"size\":\"130.5\"}, {\"price\":\"0.23\", \"size\":\"216.89\"}, {\"price\":\"0.24\", \"size\":\"261.89\"}, {\"price\":\"0.25\", \"size\":\"228\"}, {\"price\":\"0.26\", \"size\":\"209.6\"}, {\"price\":\"0.27\", \"size\":\"234.2\"}, {\"price\":\"0.28\", \"size\":\"201.9\"}, {\"price\":\"0.29\", \"size\":\"292.31\"}, {\"price\":\"0.3\", \"size\":\"112\"}, {\"price\":\"0.31\", \"size\":\"114.38\"}, {\"price\":\"0.32\", \"size\":\"115.98\"}, {\"price\":\"0.33\", \"size\":\"185.98\"}, {\"price\":\"0.34\", \"size\":\"140.29\"}, {\"price\":\"0.35\", \"size\":\"143.45\"}, {\"price\":\"0.36\", \"size\":\"183.2\"}, {\"price\":\"0.37\", \"size\":\"226.88\"}], \"asks\":[{\"price\":\"0.99\", \"size\":\"5638.02\"}, {\"price\":\"0.98\", \"size\":\"688.1\"}, {\"price\":\"0.97\", \"size\":\"618.1\"}, {\"price\":\"0.96\", \"size\":\"618.09\"}, {\"price\":\"0.95\", \"size\":\"653.2\"}, {\"price\":\"0.94\", \"size\":\"553.2\"}, {\"price\":\"0.93\", \"size\":\"576.1\"}, {\"price\":\"0.92\", \"size\":\"550.79\"}, {\"price\":\"0.91\", \"size\":\"536.6\"}, {\"price\":\"0.9\", \"size\":\"218.29\"}, {\"price\":\"0.89\", \"size\":\"30.6\"}, {\"price\":\"0.88\", \"size\":\"38.4\"}, {\"price\":\"0.87\", \"size\":\"56.5\"}, {\"price\":\"0.86\", \"size\":\"34.9\"}, {\"price\":\"0.85\", \"size\":\"64.5\"}, {\"price\":\"0.84\", \"size\":\"71.3\"}, {\"price\":\"0.83\", \"size\":\"30.3\"}, {\"price\":\"0.82\", \"size\":\"28.3\"}, {\"price\":\"0.81\", \"size\":\"57.5\"}, {\"price\":\"0.8\", \"size\":\"59.8\"}, {\"price\":\"0.79\", \"size\":\"26.1\"}, {\"price\":\"0.78\", \"size\":\"54.5\"}, {\"price\":\"0.77\", \"size\":\"23.89\"}, {\"price\":\"0.76\", \"size\":\"23.39\"}, {\"price\":\"0.75\", \"size\":\"82\"}, {\"price\":\"0.74\", \"size\":\"21.6\"}, {\"price\":\"0.73\", \"size\":\"21.2\"}, {\"price\":\"0.72\", \"size\":\"50.9\"}, {\"price\":\"0.71\", \"size\":\"20.6\"}, {\"price\":\"0.7\", \"size\":\"47.3\"}, {\"price\":\"0.69\", \"size\":\"50\"}, {\"price\":\"0.68\", \"size\":\"123.96\"}, {\"price\":\"0.67\", \"size\":\"120.61\"}, {\"price\":\"0.66\", \"size\":\"64.4\"}, {\"price\":\"0.65\", \"size\":\"38.2\"}, {\"price\":\"0.64\", \"size\":\"18\"}, {\"price\":\"0.63\", \"size\":\"47.9\"}, {\"price\":\"0.62\", \"size\":\"27.7\"}, {\"price\":\"0.61\", \"size\":\"30.15\"}, {\"price\":\"0.6\", \"size\":\"73.96\"}, {\"price\":\"0.59\", \"size\":\"35.14\"}, {\"price\":\"0.58\", \"size\":\"29.59\"}, {\"price\":\"0.57\", \"size\":\"52.2\"}, {\"price\":\"0.56\", \"size\":\"5\"}, {\"price\":\"0.55\", \"size\":\"13\"}, {\"price\":\"0.54\", \"size\":\"35\"}, {\"price\":\"0.53\", \"size\":\"5\"}, {\"price\":\"0.52\", \"size\":\"147\"}, {\"price\":\"0.51\", \"size\":\"176\"}, {\"price\":\"0.5\", \"size\":\"248\"}, {\"price\":\"0.49\", \"size\":\"163\"}, {\"price\":\"0.48\", \"size\":\"200\"}, {\"price\":\"0.47\", \"size\":\"163.02\"}, {\"price\":\"0.46\", \"size\":\"156\"}, {\"price\":\"0.45\", \"size\":\"151\"}, {\"price\":\"0.44\", \"size\":\"47\"}, {\"price\":\"0.43\", \"size\":\"35\"}, {\"price\":\"0.42\", \"size\":\"34\"}], \"hash\":\"95ab8d1c5ceab88548f9d16ec6dd6583ff803375\", \"timestamp\":\"1785211706164\", \"event_type\":\"book\"}","received_at":"2026-07-28T04:08:29.929552Z","schema_version":"clob-market-ws.book.v1","sequence":null,"server_hash":"95ab8d1c5ceab88548f9d16ec6dd6583ff803375","server_timestamp":"1785211706164","session_id":"2d607381e3054cee91998cdf45a4231c","source":"clob_market_ws"},"received_at":"2026-07-28T04:08:29.929552Z","record_id":"71a608d11c7e0be7595de8064a3eb1c5b85005ba87b1d0a9585ba4a5fa4a0363","schema_fingerprint":"dc2caa1c89c6a7426e2e07ff925910cd4d0a8a223a515d4092d91d6d127aacb6","schema_version":"edge-lab-recorder.raw.v1","sequence":null,"source":"clob_market_ws"}
{"event_at":"2026-07-28T04:08:26.180000Z","event_fingerprint":"4dc54f27efeeb89b13d6b5a882e03183df568afd79bb4f2dbfc9465595bcb7a8","payload":{"connection_id":"f6725804f86a4c4eb588e4d5ed7db029","event_at":"2026-07-28T04:08:26.180000Z","event_type":"price_change","frame_hash":"c3f5906871b3984a76a8a7ddd0960ec154c5800f2a49c88abaedab1f15fd026a","frame_index":0,"kind":"data","monotonic_ns":313693008762416,"payload":{"event_type":"price_change","market":"0xd412ce774cfcf8dc9f71164aac78783978aac7b03871702a3b8a481bd9dc9688","price_changes":[{"asset_id":"96600821790790307414914106093858868634329285205417149685270682748367152458577","best_ask":"0.42","best_bid":"0.37","hash":"1973926915ddec0a139c8d52f661c894afc6bbb5","price":"0.37","side":"BUY","size":"185.88"},{"asset_id":"107603864457683460275633293642179940881969192120168665300712204232021063124301","best_ask":"0.63","best_bid":"0.58","hash":"3386f17674efb59f844e1789e2ae406299465ca9","price":"0.63","side":"SELL","size":"185.88"}],"timestamp":"1785211706180"},"payload_hash":"0ce4cd5d6b1160e341ad1e2009dcf269d5ea8ca19f9e01e4635e636c4b2ba1d7","raw_frame":"{\"market\":\"0xd412ce774cfcf8dc9f71164aac78783978aac7b03871702a3b8a481bd9dc9688\", \"price_changes\":[{\"asset_id\":\"96600821790790307414914106093858868634329285205417149685270682748367152458577\", \"price\":\"0.37\", \"size\":\"185.88\", \"side\":\"BUY\", \"hash\":\"1973926915ddec0a139c8d52f661c894afc6bbb5\", \"best_bid\":\"0.37\", \"best_ask\":\"0.42\"}, {\"asset_id\":\"107603864457683460275633293642179940881969192120168665300712204232021063124301\", \"price\":\"0.63\", \"size\":\"185.88\", \"side\":\"SELL\", \"hash\":\"3386f17674efb59f844e1789e2ae406299465ca9\", \"best_bid\":\"0.58\", \"best_ask\":\"0.63\"}], \"timestamp\":\"1785211706180\", \"event_type\":\"price_change\"}","received_at":"2026-07-28T04:08:29.941229Z","schema_version":"clob-market-ws.price_change.v1","sequence":null,"server_hash":null,"server_timestamp":"1785211706180","session_id":"2d607381e3054cee91998cdf45a4231c","source":"clob_market_ws"},"received_at":"2026-07-28T04:08:29.941229Z","record_id":"45fb90f27dd7f18f4f8b4ec9e4c242bfacb69d515b3a2886b702bb99870dbe16","schema_fingerprint":"4aa3821a28b0b7c2400bc59aba4bcc0a76e971dadd19610d3ad38c768e124dc7","schema_version":"edge-lab-recorder.raw.v1","sequence":null,"source":"clob_market_ws"}
{"event_at":"2026-07-28T04:08:26.187000Z","event_fingerprint":"7f9bae07a0e5f75e41b4b968d1173ea8890c87fe8894062c9d4796b41e331696","payload":{"connection_id":"f6725804f86a4c4eb588e4d5ed7db029","event_at":"2026-07-28T04:08:26.187000Z","event_type":"price_change","frame_hash":"50eeaf23f6ff5b8e67537d5c79d0c2a7a13acc2ad339e23dc88f95b2b95bc3fe","frame_index":0,"kind":"data","monotonic_ns":313693011958541,"payload":{"event_type":"price_change","market":"0xd412ce774cfcf8dc9f71164aac78783978aac7b03871702a3b8a481bd9dc9688","price_changes":[{"asset_id":"107603864457683460275633293642179940881969192120168665300712204232021063124301","best_ask":"0.63","best_bid":"0.58","hash":"9478a0948b36ab032e39038695bde18f652720c7","price":"0.64","side":"SELL","size":"161.45"},{"asset_id":"96600821790790307414914106093858868634329285205417149685270682748367152458577","best_ask":"0.42","best_bid":"0.37","hash":"a6b13c92ea794f101139c7c0fd1aa55d0cf8da5f","price":"0.36","side":"BUY","size":"161.45"}],"timestamp":"1785211706187"},"payload_hash":"33729cd3f91980aa7f4bfebb088a7af7fe9b788ee658896d3e513c410e2f6a17","raw_frame":"{\"market\":\"0xd412ce774cfcf8dc9f71164aac78783978aac7b03871702a3b8a481bd9dc9688\", \"price_changes\":[{\"asset_id\":\"107603864457683460275633293642179940881969192120168665300712204232021063124301\", \"price\":\"0.64\", \"size\":\"161.45\", \"side\":\"SELL\", \"hash\":\"9478a0948b36ab032e39038695bde18f652720c7\", \"best_bid\":\"0.58\", \"best_ask\":\"0.63\"}, {\"asset_id\":\"96600821790790307414914106093858868634329285205417149685270682748367152458577\", \"price\":\"0.36\", \"size\":\"161.45\", \"side\":\"BUY\", \"hash\":\"a6b13c92ea794f101139c7c0fd1aa55d0cf8da5f\", \"best_bid\":\"0.37\", \"best_ask\":\"0.42\"}], \"timestamp\":\"1785211706187\", \"event_type\":\"price_change\"}","received_at":"2026-07-28T04:08:29.944425Z","schema_version":"clob-market-ws.price_change.v1","sequence":null,"server_hash":null,"server_timestamp":"1785211706187","session_id":"2d607381e3054cee91998cdf45a4231c","source":"clob_market_ws"},"received_at":"2026-07-28T04:08:29.944425Z","record_id":"3bdb50709ffd6ac68113e7ec05f8edd0820212ba5e5dfe8a986173a2a89f1d31","schema_fingerprint":"4aa3821a28b0b7c2400bc59aba4bcc0a76e971dadd19610d3ad38c768e124dc7","schema_version":"edge-lab-recorder.raw.v1","sequence":null,"source":"clob_market_ws"}
{"event_at":"2026-07-28T04:08:26.187000Z","event_fingerprint":"f556d376d83da587944add73fb7cf7d2bb1319486ef4453bd6dbde9190b3b016","payload":{"connection_id":"f6725804f86a4c4eb588e4d5ed7db029","event_at":"2026-07-28T04:08:26.187000Z","event_type":"price_change","frame_hash":"763966ee5f5ec58420a2e9654d181146c786f38ff164c1c3bf4278b0964290fa","frame_index":0,"kind":"data","monotonic_ns":313693015011875,"payload":{"event_type":"price_change","market":"0xd412ce774cfcf8dc9f71164aac78783978aac7b03871702a3b8a481bd9dc9688","price_changes":[{"asset_id":"96600821790790307414914106093858868634329285205417149685270682748367152458577","best_ask":"0.42","best_bid":"0.37","hash":"763181222405a902667d0fa1ee0b4f0d8c768662","price":"0.3","side":"BUY","size":"124"},{"asset_id":"107603864457683460275633293642179940881969192120168665300712204232021063124301","best_ask":"0.63","best_bid":"0.58","hash":"11dac7f247143a5795e7e0242cfeb62e08d1c0e3","price":"0.7","side":"SELL","size":"124"}],"timestamp":"1785211706187"},"payload_hash":"ad9837bb8c386cb2152f19ae8ff84c6e58569e3073e30a43c55e932bd988dd21","raw_frame":"{\"market\":\"0xd412ce774cfcf8dc9f71164aac78783978aac7b03871702a3b8a481bd9dc9688\", \"price_changes\":[{\"asset_id\":\"96600821790790307414914106093858868634329285205417149685270682748367152458577\", \"price\":\"0.3\", \"size\":\"124\", \"side\":\"BUY\", \"hash\":\"763181222405a902667d0fa1ee0b4f0d8c768662\", \"best_bid\":\"0.37\", \"best_ask\":\"0.42\"}, {\"asset_id\":\"107603864457683460275633293642179940881969192120168665300712204232021063124301\", \"price\":\"0.7\", \"size\":\"124\", \"side\":\"SELL\", \"hash\":\"11dac7f247143a5795e7e0242cfeb62e08d1c0e3\", \"best_bid\":\"0.58\", \"best_ask\":\"0.63\"}], \"timestamp\":\"1785211706187\", \"event_type\":\"price_change\"}","received_at":"2026-07-28T04:08:29.947477Z","schema_version":"clob-market-ws.price_change.v1","sequence":null,"server_hash":null,"server_timestamp":"1785211706187","session_id":"2d607381e3054cee91998cdf45a4231c","source":"clob_market_ws"},"received_at":"2026-07-28T04:08:29.947477Z","record_id":"ae20aa458af34f610995193ecbc809650f690adc4627e4178fa59b909b46f2b8","schema_fingerprint":"4aa3821a28b0b7c2400bc59aba4bcc0a76e971dadd19610d3ad38c768e124dc7","schema_version":"edge-lab-recorder.raw.v1","sequence":null,"source":"clob_market_ws"}
{"event_at":"2026-07-28T04:08:26.188000Z","event_fingerprint":"537d152867dab7f9530adc942525c13637f9cac1f76bdeff167d7888c7dadec8","payload":{"connection_id":"f6725804f86a4c4eb588e4d5ed7db029","event_at":"2026-07-28T04:08:26.188000Z","event_type":"price_change","frame_hash":"a7a07edac9b231f0948941ed6f395ef0e6280f4a811e4de924d763292809998f","frame_index":0,"kind":"data","monotonic_ns":313693018129791,"payload":{"event_type":"price_change","market":"0xd412ce774cfcf8dc9f71164aac78783978aac7b03871702a3b8a481bd9dc9688","price_changes":[{"asset_id":"107603864457683460275633293642179940881969192120168665300712204232021063124301","best_ask":"0.63","best_bid":"0.58","hash":"d9964167e451dd2daa43ef05294e1a22050d947d","price":"0.63","side":"SELL","size":"205.5"},{"asset_id":"96600821790790307414914106093858868634329285205417149685270682748367152458577","best_ask":"0.42","best_bid":"0.37","hash":"1ec267560fcd4de82b4e01c83951884cd6a96e8b","price":"0.37","side":"BUY","size":"205.5"}],"timestamp":"1785211706188"},"payload_hash":"4fc9a7020a93f8fa7448e418e5b7cd3daebd79171db02052f93fb9b8d091707b","raw_frame":"{\"market\":\"0xd412ce774cfcf8dc9f71164aac78783978aac7b03871702a3b8a481bd9dc9688\", \"price_changes\":[{\"asset_id\":\"107603864457683460275633293642179940881969192120168665300712204232021063124301\", \"price\":\"0.63\", \"size\":\"205.5\", \"side\":\"SELL\", \"hash\":\"d9964167e451dd2daa43ef05294e1a22050d947d\", \"best_bid\":\"0.58\", \"best_ask\":\"0.63\"}, {\"asset_id\":\"96600821790790307414914106093858868634329285205417149685270682748367152458577\", \"price\":\"0.37\", \"size\":\"205.5\", \"side\":\"BUY\", \"hash\":\"1ec267560fcd4de82b4e01c83951884cd6a96e8b\", \"best_bid\":\"0.37\", \"best_ask\":\"0.42\"}], \"timestamp\":\"1785211706188\", \"event_type\":\"price_change\"}","received_at":"2026-07-28T04:08:29.950593Z","schema_version":"clob-market-ws.price_change.v1","sequence":null,"server_hash":null,"server_timestamp":"1785211706188","session_id":"2d607381e3054cee91998cdf45a4231c","source":"clob_market_ws"},"received_at":"2026-07-28T04:08:29.950593Z","record_id":"5dbbeae8c350e66442b9db084a91a78ab7e3bd339c02f7d600df278f82b59571","schema_fingerprint":"4aa3821a28b0b7c2400bc59aba4bcc0a76e971dadd19610d3ad38c768e124dc7","schema_version":"edge-lab-recorder.raw.v1","sequence":null,"source":"clob_market_ws"}
{"event_at":"2026-07-28T04:08:26.189000Z","event_fingerprint":"d24b1ac29896fc900000704c1efdb573b64e08d15f06f5daf26ee14384b25954","payload":{"connection_id":"f6725804f86a4c4eb588e4d5ed7db029","event_at":"2026-07-28T04:08:26.189000Z","event_type":"price_change","frame_hash":"2b35b14a8ef1e88ad0c47554cd3d5136bc34944dc40ba442fc92de6557d18868","frame_index":0,"kind":"data","monotonic_ns":313693021219333,"payload":{"event_type":"price_change","market":"0xd412ce774cfcf8dc9f71164aac78783978aac7b03871702a3b8a481bd9dc9688","price_changes":[{"asset_id":"96600821790790307414914106093858868634329285205417149685270682748367152458577","best_ask":"0.42","best_bid":"0.37","hash":"e9503309a6ea8c093e8111f18bdaade3af47fc9d","price":"0.36","side":"BUY","size":"136.45"},{"asset_id":"107603864457683460275633293642179940881969192120168665300712204232021063124301","best_ask":"0.63","best_bid":"0.58","hash":"9cfe88ba4ee617dc52ebefe231e7a97da50c6cb3","price":"0.64","side":"SELL","size":"136.45"}],"timestamp":"1785211706189"},"payload_hash":"64cd617827fa5ce360e7dacb6f628e86b16de66f53cb6c276d9a9c2cd0d4912b","raw_frame":"{\"market\":\"0xd412ce774cfcf8dc9f71164aac78783978aac7b03871702a3b8a481bd9dc9688\", \"price_changes\":[{\"asset_id\":\"96600821790790307414914106093858868634329285205417149685270682748367152458577\", \"price\":\"0.36\", \"size\":\"136.45\", \"side\":\"BUY\", \"hash\":\"e9503309a6ea8c093e8111f18bdaade3af47fc9d\", \"best_bid\":\"0.37\", \"best_ask\":\"0.42\"}, {\"asset_id\":\"107603864457683460275633293642179940881969192120168665300712204232021063124301\", \"price\":\"0.64\", \"size\":\"136.45\", \"side\":\"SELL\", \"hash\":\"9cfe88ba4ee617dc52ebefe231e7a97da50c6cb3\", \"best_bid\":\"0.58\", \"best_ask\":\"0.63\"}], \"timestamp\":\"1785211706189\", \"event_type\":\"price_change\"}","received_at":"2026-07-28T04:08:29.953681Z","schema_version":"clob-market-ws.price_change.v1","sequence":null,"server_hash":null,"server_timestamp":"1785211706189","session_id":"2d607381e3054cee91998cdf45a4231c","source":"clob_market_ws"},"received_at":"2026-07-28T04:08:29.953681Z","record_id":"8c2d71bf1aaf61926eb502fa41735b7925a99e77acbc94f033593bef98b4c33b","schema_fingerprint":"4aa3821a28b0b7c2400bc59aba4bcc0a76e971dadd19610d3ad38c768e124dc7","schema_version":"edge-lab-recorder.raw.v1","sequence":null,"source":"clob_market_ws"}
{"event_at":"2026-07-28T04:08:26.190000Z","event_fingerprint":"c60e700c9d234a06c1bc10958a04a736c550e520da1bd3c87bf343f31e864ace","payload":{"connection_id":"f6725804f86a4c4eb588e4d5ed7db029","event_at":"2026-07-28T04:08:26.190000Z","event_type":"best_bid_ask","frame_hash":"5b690caba9786df0f9eccaee30562e48f572c02d813619ead78155e114364460","frame_index":0,"kind":"data","monotonic_ns":313693024254958,"payload":{"asset_id":"107603864457683460275633293642179940881969192120168665300712204232021063124301","best_ask":"0.6","best_bid":"0.58","event_type":"best_bid_ask","market":"0xd412ce774cfcf8dc9f71164aac78783978aac7b03871702a3b8a481bd9dc9688","spread":"0.02","timestamp":"1785211706190"},"payload_hash":"e71761af8f1ec7093f10f2d85c110d98834ba1b092918c84a952ceaef15bf6ed","raw_frame":"{\"market\":\"0xd412ce774cfcf8dc9f71164aac78783978aac7b03871702a3b8a481bd9dc9688\", \"asset_id\":\"107603864457683460275633293642179940881969192120168665300712204232021063124301\", \"best_bid\":\"0.58\", \"best_ask\":\"0.6\", \"spread\":\"0.02\", \"timestamp\":\"1785211706190\", \"event_type\":\"best_bid_ask\"}","received_at":"2026-07-28T04:08:29.956716Z","schema_version":"clob-market-ws.best_bid_ask.v1","sequence":null,"server_hash":null,"server_timestamp":"1785211706190","session_id":"2d607381e3054cee91998cdf45a4231c","source":"clob_market_ws"},"received_at":"2026-07-28T04:08:29.956716Z","record_id":"a10a7cc9d8e54f303e89c8dec34866c246cd043797d966e5b9459528f6de4c24","schema_fingerprint":"8488399f31b0337811b13b266be932db7062827c2470b78bd8e9e99bab51d17d","schema_version":"edge-lab-recorder.raw.v1","sequence":null,"source":"clob_market_ws"}
{"event_at":"2026-07-28T04:08:26.190000Z","event_fingerprint":"df385699f49304d9844de225c57572c1da582b29e7494504343fff2805237db3","payload":{"connection_id":"f6725804f86a4c4eb588e4d5ed7db029","event_at":"2026-07-28T04:08:26.190000Z","event_type":"best_bid_ask","frame_hash":"7096075903b5c193db4faa397c17f5c3acf84f29d8f2ded24b77064d9d0a1e80","frame_index":0,"kind":"data","monotonic_ns":313693026988125,"payload":{"asset_id":"96600821790790307414914106093858868634329285205417149685270682748367152458577","best_ask":"0.42","best_bid":"0.4","event_type":"best_bid_ask","market":"0xd412ce774cfcf8dc9f71164aac78783978aac7b03871702a3b8a481bd9dc9688","spread":"0.02","timestamp":"1785211706190"},"payload_hash":"a05c0896caba025fe1e86a76b01b60c73184c47066ea1e469142085085246c81","raw_frame":"{\"market\":\"0xd412ce774cfcf8dc9f71164aac78783978aac7b03871702a3b8a481bd9dc9688\", \"asset_id\":\"96600821790790307414914106093858868634329285205417149685270682748367152458577\", \"best_bid\":\"0.4\", \"best_ask\":\"0.42\", \"spread\":\"0.02\", \"timestamp\":\"1785211706190\", \"event_type\":\"best_bid_ask\"}","received_at":"2026-07-28T04:08:29.959446Z","schema_version":"clob-market-ws.best_bid_ask.v1","sequence":null,"server_hash":null,"server_timestamp":"1785211706190","session_id":"2d607381e3054cee91998cdf45a4231c","source":"clob_market_ws"},"received_at":"2026-07-28T04:08:29.959446Z","record_id":"95ce48b6db6b58da69ae9906e914df86438422b44285acba4ee39bf5c8bafc72","schema_fingerprint":"8488399f31b0337811b13b266be932db7062827c2470b78bd8e9e99bab51d17d","schema_version":"edge-lab-recorder.raw.v1","sequence":null,"source":"clob_market_ws"}
{"event_at":"2026-07-28T04:08:26.190000Z","event_fingerprint":"5c0d95560e0c75772f5f58c83ef2d324a3a70eb6cd02f759ce2430a7bdaad433","payload":{"connection_id":"f6725804f86a4c4eb588e4d5ed7db029","event_at":"2026-07-28T04:08:26.190000Z","event_type":"price_change","frame_hash":"afef2294a8b1bbcc0e67ab05fd28ec6e7dda5dd38ce4df49c07bb28709b5e9c9","frame_index":0,"kind":"data","monotonic_ns":313693034218250,"payload":{"event_type":"price_change","market":"0xd412ce774cfcf8dc9f71164aac78783978aac7b03871702a3b8a481bd9dc9688","price_changes":[{"asset_id":"96600821790790307414914106093858868634329285205417149685270682748367152458577","best_ask":"0.42","best_bid":"0.4","hash":"0cb8077d265c63d99a2542ebd9bdfb038d98342b","price":"0.4","side":"BUY","size":"12.6"},{"asset_id":"107603864457683460275633293642179940881969192120168665300712204232021063124301","best_ask":"0.6","best_bid":"0.58","hash":"91ef7b65b969b1a4a692ac944c3a43f181ba1458","price":"0.6","side":"SELL","size":"12.6"}],"timestamp":"1785211706190"},"payload_hash":"628edf98aacbb2fff1b3653fdeac70a42d5b6543764e360a8603e2fdc1215a8f","raw_frame":"{\"market\":\"0xd412ce774cfcf8dc9f71164aac78783978aac7b03871702a3b8a481bd9dc9688\", \"price_changes\":[{\"asset_id\":\"96600821790790307414914106093858868634329285205417149685270682748367152458577\", \"price\":\"0.4\", \"size\":\"12.6\", \"side\":\"BUY\", \"hash\":\"0cb8077d265c63d99a2542ebd9bdfb038d98342b\", \"best_bid\":\"0.4\", \"best_ask\":\"0.42\"}, {\"asset_id\":\"107603864457683460275633293642179940881969192120168665300712204232021063124301\", \"price\":\"0.6\", \"size\":\"12.6\", \"side\":\"SELL\", \"hash\":\"91ef7b65b969b1a4a692ac944c3a43f181ba1458\", \"best_bid\":\"0.58\", \"best_ask\":\"0.6\"}], \"timestamp\":\"1785211706190\", \"event_type\":\"price_change\"}","received_at":"2026-07-28T04:08:29.966668Z","schema_version":"clob-market-ws.price_change.v1","sequence":null,"server_hash":null,"server_timestamp":"1785211706190","session_id":"2d607381e3054cee91998cdf45a4231c","source":"clob_market_ws"},"received_at":"2026-07-28T04:08:29.966668Z","record_id":"ca9517cdc97065258e4785953f6ef026b9786afc7f89df6e7156fab598f9325f","schema_fingerprint":"4aa3821a28b0b7c2400bc59aba4bcc0a76e971dadd19610d3ad38c768e124dc7","schema_version":"edge-lab-recorder.raw.v1","sequence":null,"source":"clob_market_ws"}
{"event_at":"2026-07-28T04:08:26.191000Z","event_fingerprint":"81fb290b8728777c61428a888ec6c48bb874b8f50b2ee173d1635eacdb8348a6","payload":{"connection_id":"f6725804f86a4c4eb588e4d5ed7db029","event_at":"2026-07-28T04:08:26.191000Z","event_type":"price_change","frame_hash":"b3d8beed6772471bd66086ebe58b7f8c9a846b922f1b8cb1c494ee8c1bd2b8bb","frame_index":0,"kind":"data","monotonic_ns":313693037277125,"payload":{"event_type":"price_change","market":"0xd412ce774cfcf8dc9f71164aac78783978aac7b03871702a3b8a481bd9dc9688","price_changes":[{"asset_id":"96600821790790307414914106093858868634329285205417149685270682748367152458577","best_ask":"0.42","best_bid":"0.4","hash":"c748ba0abc943eebea5c07776832bbe619f3d368","price":"0.37","side":"BUY","size":"226.88"},{"asset_id":"107603864457683460275633293642179940881969192120168665300712204232021063124301","best_ask":"0.6","best_bid":"0.58","hash":"f15b20338e4343226a5cf310daf21890fa85362d","price":"0.63","side":"SELL","size":"226.88"}],"timestamp":"1785211706191"},"payload_hash":"979a12e6b327fc170afbdc511bc18a17b8d1717271025f693eaa120cd1b9887b","raw_frame":"{\"market\":\"0xd412ce774cfcf8dc9f71164aac78783978aac7b03871702a3b8a481bd9dc9688\", \"price_changes\":[{\"asset_id\":\"96600821790790307414914106093858868634329285205417149685270682748367152458577\", \"price\":\"0.37\", \"size\":\"226.88\", \"side\":\"BUY\", \"hash\":\"c748ba0abc943eebea5c07776832bbe619f3d368\", \"best_bid\":\"0.4\", \"best_ask\":\"0.42\"}, {\"asset_id\":\"107603864457683460275633293642179940881969192120168665300712204232021063124301\", \"price\":\"0.63\", \"size\":\"226.88\", \"side\":\"SELL\", \"hash\":\"f15b20338e4343226a5cf310daf21890fa85362d\", \"best_bid\":\"0.58\", \"best_ask\":\"0.6\"}], \"timestamp\":\"1785211706191\", \"event_type\":\"price_change\"}","received_at":"2026-07-28T04:08:29.969731Z","schema_version":"clob-market-ws.price_change.v1","sequence":null,"server_hash":null,"server_timestamp":"1785211706191","session_id":"2d607381e3054cee91998cdf45a4231c","source":"clob_market_ws"},"received_at":"2026-07-28T04:08:29.969731Z","record_id":"656343e589309125252050652ab8e1b6fc193adcf7155828b97c90b28678adfb","schema_fingerprint":"4aa3821a28b0b7c2400bc59aba4bcc0a76e971dadd19610d3ad38c768e124dc7","schema_version":"edge-lab-recorder.raw.v1","sequence":null,"source":"clob_market_ws"}
{"event_at":"2026-07-28T04:08:26.192000Z","event_fingerprint":"437de4fee8de5ca5c6b20cb79b0ffb1b8dc92a8cb7a67866f59838db34c99653","payload":{"connection_id":"f6725804f86a4c4eb588e4d5ed7db029","event_at":"2026-07-28T04:08:26.192000Z","event_type":"best_bid_ask","frame_hash":"46f3b766b86653713700c16ee90c0a462c46a1650c81ea665d7cf6c6748075a0","frame_index":0,"kind":"data","monotonic_ns":313693040389666,"payload":{"asset_id":"107603864457683460275633293642179940881969192120168665300712204232021063124301","best_ask":"0.59","best_bid":"0.58","event_type":"best_bid_ask","market":"0xd412ce774cfcf8dc9f71164aac78783978aac7b03871702a3b8a481bd9dc9688","spread":"0.01","timestamp":"1785211706192"},"payload_hash":"021fc974e3ef3997f52f28c1d540b6924d1aba9ed16199b4132fa3675b2b7daa","raw_frame":"{\"market\":\"0xd412ce774cfcf8dc9f71164aac78783978aac7b03871702a3b8a481bd9dc9688\", \"asset_id\":\"107603864457683460275633293642179940881969192120168665300712204232021063124301\", \"best_bid\":\"0.58\", \"best_ask\":\"0.59\", \"spread\":\"0.01\", \"timestamp\":\"1785211706192\", \"event_type\":\"best_bid_ask\"}","received_at":"2026-07-28T04:08:29.972842Z","schema_version":"clob-market-ws.best_bid_ask.v1","sequence":null,"server_hash":null,"server_timestamp":"1785211706192","session_id":"2d607381e3054cee91998cdf45a4231c","source":"clob_market_ws"},"received_at":"2026-07-28T04:08:29.972842Z","record_id":"66ab3283bfc98d6dbd1bd6889c5d26926ddafeefe11bc6349a3281a58bb3dede","schema_fingerprint":"8488399f31b0337811b13b266be932db7062827c2470b78bd8e9e99bab51d17d","schema_version":"edge-lab-recorder.raw.v1","sequence":null,"source":"clob_market_ws"}
{"event_at":"2026-07-28T04:08:26.192000Z","event_fingerprint":"a0da6fa06c4778c3a5400f95e421836879a20f33195508ad1fb1e02ecf9794a8","payload":{"connection_id":"f6725804f86a4c4eb588e4d5ed7db029","event_at":"2026-07-28T04:08:26.192000Z","event_type":"best_bid_ask","frame_hash":"1e8f0f447632dfd54b1b680505fe717a303aaf4fc7134defdba0394a5b3fb513","frame_index":0,"kind":"data","monotonic_ns":313693043567041,"payload":{"asset_id":"96600821790790307414914106093858868634329285205417149685270682748367152458577","best_ask":"0.42","best_bid":"0.41","event_type":"best_bid_ask","market":"0xd412ce774cfcf8dc9f71164aac78783978aac7b03871702a3b8a481bd9dc9688","spread":"0.01","timestamp":"1785211706192"},"payload_hash":"d8db7cb6d9e38dc77c6ee8c723080181672568ac0dcbd4d6e0b8b8266f3e3ccf","raw_frame":"{\"market\":\"0xd412ce774cfcf8dc9f71164aac78783978aac7b03871702a3b8a481bd9dc9688\", \"asset_id\":\"96600821790790307414914106093858868634329285205417149685270682748367152458577\", \"best_bid\":\"0.41\", \"best_ask\":\"0.42\", \"spread\":\"0.01\", \"timestamp\":\"1785211706192\", \"event_type\":\"best_bid_ask\"}","received_at":"2026-07-28T04:08:29.976018Z","schema_version":"clob-market-ws.best_bid_ask.v1","sequence":null,"server_hash":null,"server_timestamp":"1785211706192","session_id":"2d607381e3054cee91998cdf45a4231c","source":"clob_market_ws"},"received_at":"2026-07-28T04:08:29.976018Z","record_id":"68090593f15e4c7713d339398a2863a1043d2b582bcba2e16efd2d516848b269","schema_fingerprint":"8488399f31b0337811b13b266be932db7062827c2470b78bd8e9e99bab51d17d","schema_version":"edge-lab-recorder.raw.v1","sequence":null,"source":"clob_market_ws"}
{"event_at":"2026-07-28T04:08:26.192000Z","event_fingerprint":"38ea128dd82fa7fde7464c0c6706c98a13a03984ba1685f7628aee947ad757f6","payload":{"connection_id":"f6725804f86a4c4eb588e4d5ed7db029","event_at":"2026-07-28T04:08:26.192000Z","event_type":"price_change","frame_hash":"03d0e6c63bbcae0b16059c4a178d6d634873a55c75c66f497deb24c7e7f48cfe","frame_index":0,"kind":"data","monotonic_ns":313693046126333,"payload":{"event_type":"price_change","market":"0xd412ce774cfcf8dc9f71164aac78783978aac7b03871702a3b8a481bd9dc9688","price_changes":[{"asset_id":"96600821790790307414914106093858868634329285205417149685270682748367152458577","best_ask":"0.42","best_bid":"0.41","hash":"37f6a394b2cdca20aa6484cd47b7d55d5413cfe5","price":"0.41","side":"BUY","size":"6"},{"asset_id":"107603864457683460275633293642179940881969192120168665300712204232021063124301","best_ask":"0.59","best_bid":"0.58","hash":"8f551e36d23408c8869c52b941dbe0fc2219ff22","price":"0.59","side":"SELL","size":"6"}],"timestamp":"1785211706192"},"payload_hash":"ea7710c4bba9dc785a55bb4bc36e5416c98508c0aed2ff871fa8dc80942b9ab7","raw_frame":"{\"market\":\"0xd412ce774cfcf8dc9f71164aac78783978aac7b03871702a3b8a481bd9dc9688\", \"price_changes\":[{\"asset_id\":\"96600821790790307414914106093858868634329285205417149685270682748367152458577\", \"price\":\"0.41\", \"size\":\"6\", \"side\":\"BUY\", \"hash\":\"37f6a394b2cdca20aa6484cd47b7d55d5413cfe5\", \"best_bid\":\"0.41\", \"best_ask\":\"0.42\"}, {\"asset_id\":\"107603864457683460275633293642179940881969192120168665300712204232021063124301\", \"price\":\"0.59\", \"size\":\"6\", \"side\":\"SELL\", \"hash\":\"8f551e36d23408c8869c52b941dbe0fc2219ff22\", \"best_bid\":\"0.58\", \"best_ask\":\"0.59\"}], \"timestamp\":\"1785211706192\", \"event_type\":\"price_change\"}","received_at":"2026-07-28T04:08:29.978577Z","schema_version":"clob-market-ws.price_change.v1","sequence":null,"server_hash":null,"server_timestamp":"1785211706192","session_id":"2d607381e3054cee91998cdf45a4231c","source":"clob_market_ws"},"received_at":"2026-07-28T04:08:29.978577Z","record_id":"9717d12806106b5a417e986d51976661f0eaf08262b253b39c1192526b00daf9","schema_fingerprint":"4aa3821a28b0b7c2400bc59aba4bcc0a76e971dadd19610d3ad38c768e124dc7","schema_version":"edge-lab-recorder.raw.v1","sequence":null,"source":"clob_market_ws"}
{"event_at":"2026-07-28T04:08:26.193000Z","event_fingerprint":"26033e665bf02f7ea113787017aeead4a95a004e1e35caf13c3b58dbf9b1ecb3","payload":{"connection_id":"f6725804f86a4c4eb588e4d5ed7db029","event_at":"2026-07-28T04:08:26.193000Z","event_type":"price_change","frame_hash":"54c0b91051d185009e1b1c33a74b4b76ac280cc9a01fab76562d5716f7759812","frame_index":0,"kind":"data","monotonic_ns":313693049227333,"payload":{"event_type":"price_change","market":"0xd412ce774cfcf8dc9f71164aac78783978aac7b03871702a3b8a481bd9dc9688","price_changes":[{"asset_id":"96600821790790307414914106093858868634329285205417149685270682748367152458577","best_ask":"0.42","best_bid":"0.41","hash":"f206633c14ba764fa6652d7e426ea3e5babcb6e1","price":"0.36","side":"BUY","size":"130.45"},{"asset_id":"107603864457683460275633293642179940881969192120168665300712204232021063124301","best_ask":"0.59","best_bid":"0.58","hash":"24e965742f71191f5d38412797cfaa23a2026927","price":"0.64","side":"SELL","size":"130.45"}],"timestamp":"1785211706193"},"payload_hash":"56c096a8800007a4f01863f167505d177f4664d5356c235c3322b3863ef953fb","raw_frame":"{\"market\":\"0xd412ce774cfcf8dc9f71164aac78783978aac7b03871702a3b8a481bd9dc9688\", \"price_changes\":[{\"asset_id\":\"96600821790790307414914106093858868634329285205417149685270682748367152458577\", \"price\":\"0.36\", \"size\":\"130.45\", \"side\":\"BUY\", \"hash\":\"f206633c14ba764fa6652d7e426ea3e5babcb6e1\", \"best_bid\":\"0.41\", \"best_ask\":\"0.42\"}, {\"asset_id\":\"107603864457683460275633293642179940881969192120168665300712204232021063124301\", \"price\":\"0.64\", \"size\":\"130.45\", \"side\":\"SELL\", \"hash\":\"24e965742f71191f5d38412797cfaa23a2026927\", \"best_bid\":\"0.58\", \"best_ask\":\"0.59\"}], \"timestamp\":\"1785211706193\", \"event_type\":\"price_change\"}","received_at":"2026-07-28T04:08:29.981675Z","schema_version":"clob-market-ws.price_change.v1","sequence":null,"server_hash":null,"server_timestamp":"1785211706193","session_id":"2d607381e3054cee91998cdf45a4231c","source":"clob_market_ws"},"received_at":"2026-07-28T04:08:29.981675Z","record_id":"b5540f75a1c7c2c502e55cbb8d81ffb8758f620ed99a2765c7dec0709b7da5af","schema_fingerprint":"4aa3821a28b0b7c2400bc59aba4bcc0a76e971dadd19610d3ad38c768e124dc7","schema_version":"edge-lab-recorder.raw.v1","sequence":null,"source":"clob_market_ws"}
{"event_at":"2026-07-28T04:08:26.193000Z","event_fingerprint":"fe2eda74941356c05c20092de3285226c436374e5aa29b7c7c847b4e3f1e3d64","payload":{"connection_id":"f6725804f86a4c4eb588e4d5ed7db029","event_at":"2026-07-28T04:08:26.193000Z","event_type":"price_change","frame_hash":"e71436bd687709e4a63d94116a3ec820a8b4a078d5aa87ea43c60b4411846608","frame_index":0,"kind":"data","monotonic_ns":313693052179083,"payload":{"event_type":"price_change","market":"0xd412ce774cfcf8dc9f71164aac78783978aac7b03871702a3b8a481bd9dc9688","price_changes":[{"asset_id":"96600821790790307414914106093858868634329285205417149685270682748367152458577","best_ask":"0.42","best_bid":"0.41","hash":"b514ec93738e6e651e5798a33b561a77082a931c","price":"0.37","side":"BUY","size":"208.88"},{"asset_id":"107603864457683460275633293642179940881969192120168665300712204232021063124301","best_ask":"0.59","best_bid":"0.58","hash":"68ffe81ab7ef852b335fde76a0630b24ee7a46cc","price":"0.63","side":"SELL","size":"208.88"}],"timestamp":"1785211706193"},"payload_hash":"dbe34003602348365b0858d515dcc8a09a115bbc42802cc34774fb8c1b73f1ae","raw_frame":"{\"market\":\"0xd412ce774cfcf8dc9f71164aac78783978aac7b03871702a3b8a481bd9dc9688\", \"price_changes\":[{\"asset_id\":\"96600821790790307414914106093858868634329285205417149685270682748367152458577\", \"price\":\"0.37\", \"size\":\"208.88\", \"side\":\"BUY\", \"hash\":\"b514ec93738e6e651e5798a33b561a77082a931c\", \"best_bid\":\"0.41\", \"best_ask\":\"0.42\"}, {\"asset_id\":\"107603864457683460275633293642179940881969192120168665300712204232021063124301\", \"price\":\"0.63\", \"size\":\"208.88\", \"side\":\"SELL\", \"hash\":\"68ffe81ab7ef852b335fde76a0630b24ee7a46cc\", \"best_bid\":\"0.58\", \"best_ask\":\"0.59\"}], \"timestamp\":\"1785211706193\", \"event_type\":\"price_change\"}","received_at":"2026-07-28T04:08:29.984626Z","schema_version":"clob-market-ws.price_change.v1","sequence":null,"server_hash":null,"server_timestamp":"1785211706193","session_id":"2d607381e3054cee91998cdf45a4231c","source":"clob_market_ws"},"received_at":"2026-07-28T04:08:29.984626Z","record_id":"7c4f9010ab78c42014a74dcdc048c33b706af25d904e3736e0330408c16f2008","schema_fingerprint":"4aa3821a28b0b7c2400bc59aba4bcc0a76e971dadd19610d3ad38c768e124dc7","schema_version":"edge-lab-recorder.raw.v1","sequence":null,"source":"clob_market_ws"}
{"event_at":"2026-07-28T04:08:26.194000Z","event_fingerprint":"f713cea20df8c98955fc42f6f2583dcd04783d1cab3a9dad94cf416c05113db3","payload":{"connection_id":"f6725804f86a4c4eb588e4d5ed7db029","event_at":"2026-07-28T04:08:26.194000Z","event_type":"price_change","frame_hash":"39f62f9e3427664766f6ab105d70f56164a7b998cecd8ee28f7898e5637f0eb5","frame_index":0,"kind":"data","monotonic_ns":313693055233541,"payload":{"event_type":"price_change","market":"0xd412ce774cfcf8dc9f71164aac78783978aac7b03871702a3b8a481bd9dc9688","price_changes":[{"asset_id":"107603864457683460275633293642179940881969192120168665300712204232021063124301","best_ask":"0.59","best_bid":"0.58","hash":"d3efb8e7b2bda660feba8ca5ded30ae5cf029b24","price":"0.63","side":"SELL","size":"190.88"},{"asset_id":"96600821790790307414914106093858868634329285205417149685270682748367152458577","best_ask":"0.42","best_bid":"0.41","hash":"2dd4b347765bda7a2ed04e1ed9ec1ac3a7c3d8f5","price":"0.37","side":"BUY","size":"190.88"}],"timestamp":"1785211706194"},"payload_hash":"e48ad350543631e95e25d4af66c6f57c25b95abe61d5d04a2e75ec3c06c34e2e","raw_frame":"{\"market\":\"0xd412ce774cfcf8dc9f71164aac78783978aac7b03871702a3b8a481bd9dc9688\", \"price_changes\":[{\"asset_id\":\"107603864457683460275633293642179940881969192120168665300712204232021063124301\", \"price\":\"0.63\", \"size\":\"190.88\", \"side\":\"SELL\", \"hash\":\"d3efb8e7b2bda660feba8ca5ded30ae5cf029b24\", \"best_bid\":\"0.58\", \"best_ask\":\"0.59\"}, {\"asset_id\":\"96600821790790307414914106093858868634329285205417149685270682748367152458577\", \"price\":\"0.37\", \"size\":\"190.88\", \"side\":\"BUY\", \"hash\":\"2dd4b347765bda7a2ed04e1ed9ec1ac3a7c3d8f5\", \"best_bid\":\"0.41\", \"best_ask\":\"0.42\"}], \"timestamp\":\"1785211706194\", \"event_type\":\"price_change\"}","received_at":"2026-07-28T04:08:29.987678Z","schema_version":"clob-market-ws.price_change.v1","sequence":null,"server_hash":null,"server_timestamp":"1785211706194","session_id":"2d607381e3054cee91998cdf45a4231c","source":"clob_market_ws"},"received_at":"2026-07-28T04:08:29.987678Z","record_id":"b84e1fe55d52bc4b85cf1737bfd5b37fc64152d1b2a58b2801bb6519d23ca485","schema_fingerprint":"4aa3821a28b0b7c2400bc59aba4bcc0a76e971dadd19610d3ad38c768e124dc7","schema_version":"edge-lab-recorder.raw.v1","sequence":null,"source":"clob_market_ws"}
{"event_at":"2026-07-28T04:08:26.194000Z","event_fingerprint":"233f0762a8ede03119fcc2196e24be4a70aef4f27ca5072f91c29ea8e144bda1","payload":{"connection_id":"f6725804f86a4c4eb588e4d5ed7db029","event_at":"2026-07-28T04:08:26.194000Z","event_type":"price_change","frame_hash":"f41f79b0054e0841a831b47bbc7a63d20105007a02e34600ee10cb86aa0ce095","frame_index":0,"kind":"data","monotonic_ns":313693058256791,"payload":{"event_type":"price_change","market":"0xd412ce774cfcf8dc9f71164aac78783978aac7b03871702a3b8a481bd9dc9688","price_changes":[{"asset_id":"96600821790790307414914106093858868634329285205417149685270682748367152458577","best_ask":"0.42","best_bid":"0.41","hash":"6c4a88844f3329dc3f6f2238fcacc6e75ca0ba90","price":"0.31","side":"BUY","size":"108.38"},{"asset_id":"107603864457683460275633293642179940881969192120168665300712204232021063124301","best_ask":"0.59","best_bid":"0.58","hash":"1fd72d9cc40e780ce8b0805d0babeb7133716bd5","price":"0.69","side":"SELL","size":"108.38"}],"timestamp":"1785211706194"},"payload_hash":"2f7d8dba2ff9b12e41f2f51d5424f17c902a2c922c23e7a81a50fc0668f8484a","raw_frame":"{\"market\":\"0xd412ce774cfcf8dc9f71164aac78783978aac7b03871702a3b8a481bd9dc9688\", \"price_changes\":[{\"asset_id\":\"96600821790790307414914106093858868634329285205417149685270682748367152458577\", \"price\":\"0.31\", \"size\":\"108.38\", \"side\":\"BUY\", \"hash\":\"6c4a88844f3329dc3f6f2238fcacc6e75ca0ba90\", \"best_bid\":\"0.41\", \"best_ask\":\"0.42\"}, {\"asset_id\":\"107603864457683460275633293642179940881969192120168665300712204232021063124301\", \"price\":\"0.69\", \"size\":\"108.38\", \"side\":\"SELL\", \"hash\":\"1fd72d9cc40e780ce8b0805d0babeb7133716bd5\", \"best_bid\":\"0.58\", \"best_ask\":\"0.59\"}], \"timestamp\":\"1785211706194\", \"event_type\":\"price_change\"}","received_at":"2026-07-28T04:08:29.990700Z","schema_version":"clob-market-ws.price_change.v1","sequence":null,"server_hash":null,"server_timestamp":"1785211706194","session_id":"2d607381e3054cee91998cdf45a4231c","source":"clob_market_ws"},"received_at":"2026-07-28T04:08:29.990700Z","record_id":"7d347a6b5448669e93865f9971a5305b1f91ef448ba3952cc4162ff4a9a98872","schema_fingerprint":"4aa3821a28b0b7c2400bc59aba4bcc0a76e971dadd19610d3ad38c768e124dc7","schema_version":"edge-lab-recorder.raw.v1","sequence":null,"source":"clob_market_ws"}
{"event_at":"2026-07-28T04:08:26.194000Z","event_fingerprint":"18d51771c43bfa15a1484c9f1c9da1c00cbad39a1b13e2beab5133a3a35e1cff","payload":{"connection_id":"f6725804f86a4c4eb588e4d5ed7db029","event_at":"2026-07-28T04:08:26.194000Z","event_type":"price_change","frame_hash":"3a1a8d040df493bbfa1e7f6d14f82f91c8b2239ff8401352a26e604ebcd3e90c","frame_index":0,"kind":"data","monotonic_ns":313693061257833,"payload":{"event_type":"price_change","market":"0xd412ce774cfcf8dc9f71164aac78783978aac7b03871702a3b8a481bd9dc9688","price_changes":[{"asset_id":"96600821790790307414914106093858868634329285205417149685270682748367152458577","best_ask":"0.42","best_bid":"0.41","hash":"3408f732aac8464b4a6a9b16f8e308adc941026c","price":"0.37","side":"BUY","size":"175.88"},{"asset_id":"107603864457683460275633293642179940881969192120168665300712204232021063124301","best_ask":"0.59","best_bid":"0.58","hash":"b9d6a543a5176141e77cfb448f6b0ec3a6c2d932","price":"0.63","side":"SELL","size":"175.88"}],"timestamp":"1785211706194"},"payload_hash":"fcd6b28fa14ee361cec6b50c66508590308691f6d79d9cc927c120c8e7e456c4","raw_frame":"{\"market\":\"0xd412ce774cfcf8dc9f71164aac78783978aac7b03871702a3b8a481bd9dc9688\", \"price_changes\":[{\"asset_id\":\"96600821790790307414914106093858868634329285205417149685270682748367152458577\", \"price\":\"0.37\", \"size\":\"175.88\", \"side\":\"BUY\", \"hash\":\"3408f732aac8464b4a6a9b16f8e308adc941026c\", \"best_bid\":\"0.41\", \"best_ask\":\"0.42\"}, {\"asset_id\":\"107603864457683460275633293642179940881969192120168665300712204232021063124301\", \"price\":\"0.63\", \"size\":\"175.88\", \"side\":\"SELL\", \"hash\":\"b9d6a543a5176141e77cfb448f6b0ec3a6c2d932\", \"best_bid\":\"0.58\", \"best_ask\":\"0.59\"}], \"timestamp\":\"1785211706194\", \"event_type\":\"price_change\"}","received_at":"2026-07-28T04:08:29.993700Z","schema_version":"clob-market-ws.price_change.v1","sequence":null,"server_hash":null,"server_timestamp":"1785211706194","session_id":"2d607381e3054cee91998cdf45a4231c","source":"clob_market_ws"},"received_at":"2026-07-28T04:08:29.993700Z","record_id":"c9a5b686a16be1bc502f9ca26c7621b187dc39a27c4b06de5edf33b61c14ff4c","schema_fingerprint":"4aa3821a28b0b7c2400bc59aba4bcc0a76e971dadd19610d3ad38c768e124dc7","schema_version":"edge-lab-recorder.raw.v1","sequence":null,"source":"clob_market_ws"}
{"event_at":"2026-07-28T04:08:26.195000Z","event_fingerprint":"fb2522235f16be87cab1acd59758e99b1433f05f70cbc867a187b7276ef613cf","payload":{"connection_id":"f6725804f86a4c4eb588e4d5ed7db029","event_at":"2026-07-28T04:08:26.195000Z","event_type":"price_change","frame_hash":"5f1515da76fb654f796eae3b573531398859cfd2c21e2b3985db1c4632d51a52","frame_index":0,"kind":"data","monotonic_ns":313693064183875,"payload":{"event_type":"price_change","market":"0xd412ce774cfcf8dc9f71164aac78783978aac7b03871702a3b8a481bd9dc9688","price_changes":[{"asset_id":"107603864457683460275633293642179940881969192120168665300712204232021063124301","best_ask":"0.59","best_bid":"0.58","hash":"293dfb43d593a433c80c7d62ca81c1b25cf9eb6d","price":"0.63","side":"SELL","size":"158.88"},{"asset_id":"96600821790790307414914106093858868634329285205417149685270682748367152458577","best_ask":"0.42","best_bid":"0.41","hash":"caacfb81e0f859255c0f1d344f3a1f909480d488","price":"0.37","side":"BUY","size":"158.88"}],"timestamp":"1785211706195"},"payload_hash":"b34b28878b9d981a76c8d9ceee7c50913b899e93e9f7803c0bee946fc4de9d3c","raw_frame":"{\"market\":\"0xd412ce774cfcf8dc9f71164aac78783978aac7b03871702a3b8a481bd9dc9688\", \"price_changes\":[{\"asset_id\":\"107603864457683460275633293642179940881969192120168665300712204232021063124301\", \"price\":\"0.63\", \"size\":\"158.88\", \"side\":\"SELL\", \"hash\":\"293dfb43d593a433c80c7d62ca81c1b25cf9eb6d\", \"best_bid\":\"0.58\", \"best_ask\":\"0.59\"}, {\"asset_id\":\"96600821790790307414914106093858868634329285205417149685270682748367152458577\", \"price\":\"0.37\", \"size\":\"158.88\", \"side\":\"BUY\", \"hash\":\"caacfb81e0f859255c0f1d344f3a1f909480d488\", \"best_bid\":\"0.41\", \"best_ask\":\"0.42\"}], \"timestamp\":\"1785211706195\", \"event_type\":\"price_change\"}","received_at":"2026-07-28T04:08:29.996625Z","schema_version":"clob-market-ws.price_change.v1","sequence":null,"server_hash":null,"server_timestamp":"1785211706195","session_id":"2d607381e3054cee91998cdf45a4231c","source":"clob_market_ws"},"received_at":"2026-07-28T04:08:29.996625Z","record_id":"98199513e029f0561ff4c3e021c2a0b1764cb724cc72deb345dd560820c03ff4","schema_fingerprint":"4aa3821a28b0b7c2400bc59aba4bcc0a76e971dadd19610d3ad38c768e124dc7","schema_version":"edge-lab-recorder.raw.v1","sequence":null,"source":"clob_market_ws"}
{"event_at":"2026-07-28T04:08:26.195000Z","event_fingerprint":"7db16aa2b12dd2b27d83ad396e52aa403e5ea03f5aa9667621caa2194d0ec9b3","payload":{"connection_id":"f6725804f86a4c4eb588e4d5ed7db029","event_at":"2026-07-28T04:08:26.195000Z","event_type":"price_change","frame_hash":"c9d5aa129c94a8e41649f19bc49bf703998e431521ba1afce1fc54f63b10e92a","frame_index":0,"kind":"data","monotonic_ns":313693067250916,"payload":{"event_type":"price_change","market":"0xd412ce774cfcf8dc9f71164aac78783978aac7b03871702a3b8a481bd9dc9688","price_changes":[{"asset_id":"96600821790790307414914106093858868634329285205417149685270682748367152458577","best_ask":"0.42","best_bid":"0.41","hash":"4ae18911e897196bcbb429b16563a926a0ad653a","price":"0.38","side":"BUY","size":"6"},{"asset_id":"107603864457683460275633293642179940881969192120168665300712204232021063124301","best_ask":"0.59","best_bid":"0.58","hash":"f736a66c050e3e412f6553910b9cbf5a27684e38","price":"0.62","side":"SELL","size":"6"}],"timestamp":"1785211706195"},"payload_hash":"cef66a56ae8616a1bb20c8e61d16f75f87780179cb6182d1f243c10999ea3529","raw_frame":"{\"market\":\"0xd412ce774cfcf8dc9f71164aac78783978aac7b03871702a3b8a481bd9dc9688\", \"price_changes\":[{\"asset_id\":\"96600821790790307414914106093858868634329285205417149685270682748367152458577\", \"price\":\"0.38\", \"size\":\"6\", \"side\":\"BUY\", \"hash\":\"4ae18911e897196bcbb429b16563a926a0ad653a\", \"best_bid\":\"0.41\", \"best_ask\":\"0.42\"}, {\"asset_id\":\"107603864457683460275633293642179940881969192120168665300712204232021063124301\", \"price\":\"0.62\", \"size\":\"6\", \"side\":\"SELL\", \"hash\":\"f736a66c050e3e412f6553910b9cbf5a27684e38\", \"best_bid\":\"0.58\", \"best_ask\":\"0.59\"}], \"timestamp\":\"1785211706195\", \"event_type\":\"price_change\"}","received_at":"2026-07-28T04:08:29.999689Z","schema_version":"clob-market-ws.price_change.v1","sequence":null,"server_hash":null,"server_timestamp":"1785211706195","session_id":"2d607381e3054cee91998cdf45a4231c","source":"clob_market_ws"},"received_at":"2026-07-28T04:08:29.999689Z","record_id":"3a3066e0f8edfa7a1fee5364d7ad81b3e9f9c2234190daeaeaeb52cc6c8e968c","schema_fingerprint":"4aa3821a28b0b7c2400bc59aba4bcc0a76e971dadd19610d3ad38c768e124dc7","schema_version":"edge-lab-recorder.raw.v1","sequence":null,"source":"clob_market_ws"}
{"event_at":"2026-07-28T04:08:26.196000Z","event_fingerprint":"aa68a2799ac03731e057d212b9ce3349d8f7c2f6501555015d92072ac5016cd8","payload":{"connection_id":"f6725804f86a4c4eb588e4d5ed7db029","event_at":"2026-07-28T04:08:26.196000Z","event_type":"price_change","frame_hash":"811afbdafc28895be8a1aae54c5d0c9b07123e9224e2b5a0dfc0b03ee9e6361f","frame_index":0,"kind":"data","monotonic_ns":313693070224500,"payload":{"event_type":"price_change","market":"0xd412ce774cfcf8dc9f71164aac78783978aac7b03871702a3b8a481bd9dc9688","price_changes":[{"asset_id":"96600821790790307414914106093858868634329285205417149685270682748367152458577","best_ask":"0.42","best_bid":"0.41","hash":"b7fecd43a50baefc57618967fb5304f9bf8cad3d","price":"0.16","side":"BUY","size":"626.3"},{"asset_id":"107603864457683460275633293642179940881969192120168665300712204232021063124301","best_ask":"0.59","best_bid":"0.58","hash":"3cb875e6459d1b02acea246ffa2d7120fbef9f99","price":"0.84","side":"SELL","size":"626.3"}],"timestamp":"1785211706196"},"payload_hash":"c964b32efbf149acea80cd1009729d1de74dcf01b23701c5f1b89fb20d2634c8","raw_frame":"{\"market\":\"0xd412ce774cfcf8dc9f71164aac78783978aac7b03871702a3b8a481bd9dc9688\", \"price_changes\":[{\"asset_id\":\"96600821790790307414914106093858868634329285205417149685270682748367152458577\", \"price\":\"0.16\", \"size\":\"626.3\", \"side\":\"BUY\", \"hash\":\"b7fecd43a50baefc57618967fb5304f9bf8cad3d\", \"best_bid\":\"0.41\", \"best_ask\":\"0.42\"}, {\"asset_id\":\"107603864457683460275633293642179940881969192120168665300712204232021063124301\", \"price\":\"0.84\", \"size\":\"626.3\", \"side\":\"SELL\", \"hash\":\"3cb875e6459d1b02acea246ffa2d7120fbef9f99\", \"best_bid\":\"0.58\", \"best_ask\":\"0.59\"}], \"timestamp\":\"1785211706196\", \"event_type\":\"price_change\"}","received_at":"2026-07-28T04:08:30.002661Z","schema_version":"clob-market-ws.price_change.v1","sequence":null,"server_hash":null,"server_timestamp":"1785211706196","session_id":"2d607381e3054cee91998cdf45a4231c","source":"clob_market_ws"},"received_at":"2026-07-28T04:08:30.002661Z","record_id":"f53740720c4cd73453766b4da000a1dd78a152f7848ca2d1daea3924cd93ddd0","schema_fingerprint":"4aa3821a28b0b7c2400bc59aba4bcc0a76e971dadd19610d3ad38c768e124dc7","schema_version":"edge-lab-recorder.raw.v1","sequence":null,"source":"clob_market_ws"}
{"event_at":"2026-07-28T04:08:26.198000Z","event_fingerprint":"185539359fdac4a324b59e1b2266a783843c777f05f2ac1716dd354f6c84da56","payload":{"connection_id":"f6725804f86a4c4eb588e4d5ed7db029","event_at":"2026-07-28T04:08:26.198000Z","event_type":"price_change","frame_hash":"4d488552ded8b355af40862212e6b2eb3ffacfc1819d3501f63186629949cb43","frame_index":0,"kind":"data","monotonic_ns":313693073303291,"payload":{"event_type":"price_change","market":"0xd412ce774cfcf8dc9f71164aac78783978aac7b03871702a3b8a481bd9dc9688","price_changes":[{"asset_id":"96600821790790307414914106093858868634329285205417149685270682748367152458577","best_ask":"0.42","best_bid":"0.41","hash":"8b51a4ca694380327cfe3a3cec3dbe0fec0e8d39","price":"0.36","side":"BUY","size":"136.45"},{"asset_id":"107603864457683460275633293642179940881969192120168665300712204232021063124301","best_ask":"0.59","best_bid":"0.58","hash":"f96048461738ee55cb4792ef0e9f458ad0a9da0e","price":"0.64","side":"SELL","size":"136.45"}],"timestamp":"1785211706198"},"payload_hash":"77566a4db5dc5939ed3aaf57634495592808f66447fdcbae488bc804c070ddd7","raw_frame":"{\"market\":\"0xd412ce774cfcf8dc9f71164aac78783978aac7b03871702a3b8a481bd9dc9688\", \"price_changes\":[{\"asset_id\":\"96600821790790307414914106093858868634329285205417149685270682748367152458577\", \"price\":\"0.36\", \"size\":\"136.45\", \"side\":\"BUY\", \"hash\":\"8b51a4ca694380327cfe3a3cec3dbe0fec0e8d39\", \"best_bid\":\"0.41\", \"best_ask\":\"0.42\"}, {\"asset_id\":\"107603864457683460275633293642179940881969192120168665300712204232021063124301\", \"price\":\"0.64\", \"size\":\"136.45\", \"side\":\"SELL\", \"hash\":\"f96048461738ee55cb4792ef0e9f458ad0a9da0e\", \"best_bid\":\"0.58\", \"best_ask\":\"0.59\"}], \"timestamp\":\"1785211706198\", \"event_type\":\"price_change\"}","received_at":"2026-07-28T04:08:30.005739Z","schema_version":"clob-market-ws.price_change.v1","sequence":null,"server_hash":null,"server_timestamp":"1785211706198","session_id":"2d607381e3054cee91998cdf45a4231c","source":"clob_market_ws"},"received_at":"2026-07-28T04:08:30.005739Z","record_id":"bbfaac7d429ea23f7a253aa72aa21bda544845ec150056ce6518502aa1896cec","schema_fingerprint":"4aa3821a28b0b7c2400bc59aba4bcc0a76e971dadd19610d3ad38c768e124dc7","schema_version":"edge-lab-recorder.raw.v1","sequence":null,"source":"clob_market_ws"}
{"event_at":"2026-07-28T04:08:26.198000Z","event_fingerprint":"a4b5103387492449956e888131b98f7821875aa590d37ed3795e65fe3ae7cf21","payload":{"connection_id":"f6725804f86a4c4eb588e4d5ed7db029","event_at":"2026-07-28T04:08:26.198000Z","event_type":"price_change","frame_hash":"bdee8d3383e086c6327d81e14e33b8c35599acae1e159ce61e24bf668493d530","frame_index":0,"kind":"data","monotonic_ns":313693075795500,"payload":{"event_type":"price_change","market":"0xd412ce774cfcf8dc9f71164aac78783978aac7b03871702a3b8a481bd9dc9688","price_changes":[{"asset_id":"107603864457683460275633293642179940881969192120168665300712204232021063124301","best_ask":"0.59","best_bid":"0.58","hash":"8c0dac06e1d9007a92293649e9c1685bcbaf77ff","price":"0.01","side":"BUY","size":"5643.02"},{"asset_id":"96600821790790307414914106093858868634329285205417149685270682748367152458577","best_ask":"0.42","best_bid":"0.41","hash":"bb86adb6fd069004a96838a6c24fe5bfbecdb0bd","price":"0.99","side":"SELL","size":"5643.02"}],"timestamp":"1785211706198"},"payload_hash":"ea4b4587aff4626be5c2247adf5982675170ddcc1643a8a18a8dff6f3391b2a7","raw_frame":"{\"market\":\"0xd412ce774cfcf8dc9f71164aac78783978aac7b03871702a3b8a481bd9dc9688\", \"price_changes\":[{\"asset_id\":\"107603864457683460275633293642179940881969192120168665300712204232021063124301\", \"price\":\"0.01\", \"size\":\"5643.02\", \"side\":\"BUY\", \"hash\":\"8c0dac06e1d9007a92293649e9c1685bcbaf77ff\", \"best_bid\":\"0.58\", \"best_ask\":\"0.59\"}, {\"asset_id\":\"96600821790790307414914106093858868634329285205417149685270682748367152458577\", \"price\":\"0.99\", \"size\":\"5643.02\", \"side\":\"SELL\", \"hash\":\"bb86adb6fd069004a96838a6c24fe5bfbecdb0bd\", \"best_bid\":\"0.41\", \"best_ask\":\"0.42\"}], \"timestamp\":\"1785211706198\", \"event_type\":\"price_change\"}","received_at":"2026-07-28T04:08:30.008230Z","schema_version":"clob-market-ws.price_change.v1","sequence":null,"server_hash":null,"server_timestamp":"1785211706198","session_id":"2d607381e3054cee91998cdf45a4231c","source":"clob_market_ws"},"received_at":"2026-07-28T04:08:30.008230Z","record_id":"754ec6f746340bde26fe303ca9626e49d4b772ee632cfd570ee44c35341e6248","schema_fingerprint":"4aa3821a28b0b7c2400bc59aba4bcc0a76e971dadd19610d3ad38c768e124dc7","schema_version":"edge-lab-recorder.raw.v1","sequence":null,"source":"clob_market_ws"}
{"event_at":"2026-07-28T04:08:26.199000Z","event_fingerprint":"dc5c35963d1f8461f33e3bbc2099da7fabeb04290a26ade07df194c5d36ca8dd","payload":{"connection_id":"f6725804f86a4c4eb588e4d5ed7db029","event_at":"2026-07-28T04:08:26.199000Z","event_type":"price_change","frame_hash":"746893df045abdcd06d2f096341c33fcafd0e6c3bc99ecd0d8d42eca6d36faf8","frame_index":0,"kind":"data","monotonic_ns":313693078335000,"payload":{"event_type":"price_change","market":"0xd412ce774cfcf8dc9f71164aac78783978aac7b03871702a3b8a481bd9dc9688","price_changes":[{"asset_id":"107603864457683460275633293642179940881969192120168665300712204232021063124301","best_ask":"0.59","best_bid":"0.58","hash":"df0d285910b7ed133f170c562feee856b03aea2a","price":"0.56","side":"BUY","size":"59.6"},{"asset_id":"96600821790790307414914106093858868634329285205417149685270682748367152458577","best_ask":"0.42","best_bid":"0.41","hash":"5484057802fb446fe6462a352edfb1ccfb65a6d4","price":"0.44","side":"SELL","size":"59.6"}],"timestamp":"1785211706199"},"payload_hash":"15d202049f2ec90d13bee412be649beaf7f79eb8ed9f8f438f1da80650319fc0","raw_frame":"{\"market\":\"0xd412ce774cfcf8dc9f71164aac78783978aac7b03871702a3b8a481bd9dc9688\", \"price_changes\":[{\"asset_id\":\"107603864457683460275633293642179940881969192120168665300712204232021063124301\", \"price\":\"0.56\", \"size\":\"59.6\", \"side\":\"BUY\", \"hash\":\"df0d285910b7ed133f170c562feee856b03aea2a\", \"best_bid\":\"0.58\", \"best_ask\":\"0.59\"}, {\"asset_id\":\"96600821790790307414914106093858868634329285205417149685270682748367152458577\", \"price\":\"0.44\", \"size\":\"59.6\", \"side\":\"SELL\", \"hash\":\"5484057802fb446fe6462a352edfb1ccfb65a6d4\", \"best_bid\":\"0.41\", \"best_ask\":\"0.42\"}], \"timestamp\":\"1785211706199\", \"event_type\":\"price_change\"}","received_at":"2026-07-28T04:08:30.010769Z","schema_version":"clob-market-ws.price_change.v1","sequence":null,"server_hash":null,"server_timestamp":"1785211706199","session_id":"2d607381e3054cee91998cdf45a4231c","source":"clob_market_ws"},"received_at":"2026-07-28T04:08:30.010769Z","record_id":"b3ff9d89074c90f7216ae32481aa342369c995f89db2c50524c0f18d4350d3cc","schema_fingerprint":"4aa3821a28b0b7c2400bc59aba4bcc0a76e971dadd19610d3ad38c768e124dc7","schema_version":"edge-lab-recorder.raw.v1","sequence":null,"source":"clob_market_ws"}
{"event_at":"2026-07-28T04:08:26.200000Z","event_fingerprint":"f1c9ed8b9763cda0ad3e960c7316ca2fec6b4d737c398ba74bd3d37d8705c0c1","payload":{"connection_id":"f6725804f86a4c4eb588e4d5ed7db029","event_at":"2026-07-28T04:08:26.200000Z","event_type":"price_change","frame_hash":"e1c073d83fe8b485d85494a93a2c7c17dfaa6b20e56519a056e4413a8431858b","frame_index":0,"kind":"data","monotonic_ns":313693081307583,"payload":{"event_type":"price_change","market":"0xd412ce774cfcf8dc9f71164aac78783978aac7b03871702a3b8a481bd9dc9688","price_changes":[{"asset_id":"107603864457683460275633293642179940881969192120168665300712204232021063124301","best_ask":"0.59","best_bid":"0.58","hash":"57f88f6a51d8e070197d9ac43f4c2baae2a77316","price":"0.33","side":"BUY","size":"221.62"},{"asset_id":"96600821790790307414914106093858868634329285205417149685270682748367152458577","best_ask":"0.42","best_bid":"0.41","hash":"dd4eae775afea37b3edad94a3585b78a472b972a","price":"0.67","side":"SELL","size":"221.62"}],"timestamp":"1785211706200"},"payload_hash":"c52aebbc2515fda2e756681cb764e62a69dd9de1fdce98e267e5239f3a36962a","raw_frame":"{\"market\":\"0xd412ce774cfcf8dc9f71164aac78783978aac7b03871702a3b8a481bd9dc9688\", \"price_changes\":[{\"asset_id\":\"107603864457683460275633293642179940881969192120168665300712204232021063124301\", \"price\":\"0.33\", \"size\":\"221.62\", \"side\":\"BUY\", \"hash\":\"57f88f6a51d8e070197d9ac43f4c2baae2a77316\", \"best_bid\":\"0.58\", \"best_ask\":\"0.59\"}, {\"asset_id\":\"96600821790790307414914106093858868634329285205417149685270682748367152458577\", \"price\":\"0.67\", \"size\":\"221.62\", \"side\":\"SELL\", \"hash\":\"dd4eae775afea37b3edad94a3585b78a472b972a\", \"best_bid\":\"0.41\", \"best_ask\":\"0.42\"}], \"timestamp\":\"1785211706200\", \"event_type\":\"price_change\"}","received_at":"2026-07-28T04:08:30.013740Z","schema_version":"clob-market-ws.price_change.v1","sequence":null,"server_hash":null,"server_timestamp":"1785211706200","session_id":"2d607381e3054cee91998cdf45a4231c","source":"clob_market_ws"},"received_at":"2026-07-28T04:08:30.013740Z","record_id":"7c61d5e7380e421f0afbb521dc8c5d046961d68d7fca6a24a98be0891c71306d","schema_fingerprint":"4aa3821a28b0b7c2400bc59aba4bcc0a76e971dadd19610d3ad38c768e124dc7","schema_version":"edge-lab-recorder.raw.v1","sequence":null,"source":"clob_market_ws"}
{"event_at":"2026-07-28T04:08:26.201000Z","event_fingerprint":"14b3c2e81ecd37afc1b9ff3792fa47db49ea43d968a3e3bbc732127c6f1d16b5","payload":{"connection_id":"f6725804f86a4c4eb588e4d5ed7db029","event_at":"2026-07-28T04:08:26.201000Z","event_type":"price_change","frame_hash":"2809c2413454f7a5203bd1d3583a313e6de5acee776553744f3f237448b50d0a","frame_index":0,"kind":"data","monotonic_ns":313693084287666,"payload":{"event_type":"price_change","market":"0xd412ce774cfcf8dc9f71164aac78783978aac7b03871702a3b8a481bd9dc9688","price_changes":[{"asset_id":"96600821790790307414914106093858868634329285205417149685270682748367152458577","best_ask":"0.42","best_bid":"0.41","hash":"e778e70560a162c451fdd00f1309aa45d8129f23","price":"0.32","side":"BUY","size":"103.38"},{"asset_id":"107603864457683460275633293642179940881969192120168665300712204232021063124301","best_ask":"0.59","best_bid":"0.58","hash":"7955c32f36eebf4eac284b5707ec119723a3e7e9","price":"0.68","side":"SELL","size":"103.38"}],"timestamp":"1785211706201"},"payload_hash":"2c626c80b5e989e324706a0f347048930095e67f4c7fe5f6c393c53cdb0ea6f5","raw_frame":"{\"market\":\"0xd412ce774cfcf8dc9f71164aac78783978aac7b03871702a3b8a481bd9dc9688\", \"price_changes\":[{\"asset_id\":\"96600821790790307414914106093858868634329285205417149685270682748367152458577\", \"price\":\"0.32\", \"size\":\"103.38\", \"side\":\"BUY\", \"hash\":\"e778e70560a162c451fdd00f1309aa45d8129f23\", \"best_bid\":\"0.41\", \"best_ask\":\"0.42\"}, {\"asset_id\":\"107603864457683460275633293642179940881969192120168665300712204232021063124301\", \"price\":\"0.68\", \"size\":\"103.38\", \"side\":\"SELL\", \"hash\":\"7955c32f36eebf4eac284b5707ec119723a3e7e9\", \"best_bid\":\"0.58\", \"best_ask\":\"0.59\"}], \"timestamp\":\"1785211706201\", \"event_type\":\"price_change\"}","received_at":"2026-07-28T04:08:30.016718Z","schema_version":"clob-market-ws.price_change.v1","sequence":null,"server_hash":null,"server_timestamp":"1785211706201","session_id":"2d607381e3054cee91998cdf45a4231c","source":"clob_market_ws"},"received_at":"2026-07-28T04:08:30.016718Z","record_id":"b1d7978b0995fa8b7de23adfc085f4e95c21fe891f0d06fac9943a697b7c1698","schema_fingerprint":"4aa3821a28b0b7c2400bc59aba4bcc0a76e971dadd19610d3ad38c768e124dc7","schema_version":"edge-lab-recorder.raw.v1","sequence":null,"source":"clob_market_ws"}
{"event_at":"2026-07-28T04:08:26.203000Z","event_fingerprint":"361fa91fe9a1ae1bc6224473c05ec8c9b52c94eaa2a938c065c8804c981b1798","payload":{"connection_id":"f6725804f86a4c4eb588e4d5ed7db029","event_at":"2026-07-28T04:08:26.203000Z","event_type":"price_change","frame_hash":"7d8da5c818e70303f609b7cee1e2c04028f3a36c8f546498dde94a6b365a01c3","frame_index":0,"kind":"data","monotonic_ns":313693087309666,"payload":{"event_type":"price_change","market":"0xd412ce774cfcf8dc9f71164aac78783978aac7b03871702a3b8a481bd9dc9688","price_changes":[{"asset_id":"96600821790790307414914106093858868634329285205417149685270682748367152458577","best_ask":"0.42","best_bid":"0.41","hash":"ec49c5aac20bc60f6fa3c64cdbda3e9259da2148","price":"0.38","side":"BUY","size":"18.6"},{"asset_id":"107603864457683460275633293642179940881969192120168665300712204232021063124301","best_ask":"0.59","best_bid":"0.58","hash":"06f460138568471040dda738730e49c8b114b4b1","price":"0.62","side":"SELL","size":"18.6"}],"timestamp":"1785211706203"},"payload_hash":"71feddce6f506894b063c89561b72c0f190854e4472b9e24a14141982072194b","raw_frame":"{\"market\":\"0xd412ce774cfcf8dc9f71164aac78783978aac7b03871702a3b8a481bd9dc9688\", \"price_changes\":[{\"asset_id\":\"96600821790790307414914106093858868634329285205417149685270682748367152458577\", \"price\":\"0.38\", \"size\":\"18.6\", \"side\":\"BUY\", \"hash\":\"ec49c5aac20bc60f6fa3c64cdbda3e9259da2148\", \"best_bid\":\"0.41\", \"best_ask\":\"0.42\"}, {\"asset_id\":\"107603864457683460275633293642179940881969192120168665300712204232021063124301\", \"price\":\"0.62\", \"size\":\"18.6\", \"side\":\"SELL\", \"hash\":\"06f460138568471040dda738730e49c8b114b4b1\", \"best_bid\":\"0.58\", \"best_ask\":\"0.59\"}], \"timestamp\":\"1785211706203\", \"event_type\":\"price_change\"}","received_at":"2026-07-28T04:08:30.019738Z","schema_version":"clob-market-ws.price_change.v1","sequence":null,"server_hash":null,"server_timestamp":"1785211706203","session_id":"2d607381e3054cee91998cdf45a4231c","source":"clob_market_ws"},"received_at":"2026-07-28T04:08:30.019738Z","record_id":"98608923ba0af941ba8f27c3f9b6d74d5940c993ffcc2ab43846030c29ea2f42","schema_fingerprint":"4aa3821a28b0b7c2400bc59aba4bcc0a76e971dadd19610d3ad38c768e124dc7","schema_version":"edge-lab-recorder.raw.v1","sequence":null,"source":"clob_market_ws"}
{"event_at":"2026-07-28T04:08:26.206000Z","event_fingerprint":"0568b039ccba57757f03e18d759b52a19c4d60c9491140d965bd7f9748632b41","payload":{"connection_id":"f6725804f86a4c4eb588e4d5ed7db029","event_at":"2026-07-28T04:08:26.206000Z","event_type":"price_change","frame_hash":"5401c0bf2a884965ecacca4e1bbea24b8e3f30ebfa3df5a95c05907751b90fb7","frame_index":0,"kind":"data","monotonic_ns":313693090443875,"payload":{"event_type":"price_change","market":"0xd412ce774cfcf8dc9f71164aac78783978aac7b03871702a3b8a481bd9dc9688","price_changes":[{"asset_id":"96600821790790307414914106093858868634329285205417149685270682748367152458577","best_ask":"0.42","best_bid":"0.41","hash":"e4ffaa4a72897f1ae0b23a2e5201e544ad16af43","price":"0.37","side":"BUY","size":"152.88"},{"asset_id":"107603864457683460275633293642179940881969192120168665300712204232021063124301","best_ask":"0.59","best_bid":"0.58","hash":"bc54bbb541c81f4b4dac3cdfd914e1699e58733f","price":"0.63","side":"SELL","size":"152.88"}],"timestamp":"1785211706206"},"payload_hash":"61275cc5e844b790fa4d44e76ccd6851b8b21bcea1b1afc81769b7de1b3494ff","raw_frame":"{\"market\":\"0xd412ce774cfcf8dc9f71164aac78783978aac7b03871702a3b8a481bd9dc9688\", \"price_changes\":[{\"asset_id\":\"96600821790790307414914106093858868634329285205417149685270682748367152458577\", \"price\":\"0.37\", \"size\":\"152.88\", \"side\":\"BUY\", \"hash\":\"e4ffaa4a72897f1ae0b23a2e5201e544ad16af43\", \"best_bid\":\"0.41\", \"best_ask\":\"0.42\"}, {\"asset_id\":\"107603864457683460275633293642179940881969192120168665300712204232021063124301\", \"price\":\"0.63\", \"size\":\"152.88\", \"side\":\"SELL\", \"hash\":\"bc54bbb541c81f4b4dac3cdfd914e1699e58733f\", \"best_bid\":\"0.58\", \"best_ask\":\"0.59\"}], \"timestamp\":\"1785211706206\", \"event_type\":\"price_change\"}","received_at":"2026-07-28T04:08:30.022871Z","schema_version":"clob-market-ws.price_change.v1","sequence":null,"server_hash":null,"server_timestamp":"1785211706206","session_id":"2d607381e3054cee91998cdf45a4231c","source":"clob_market_ws"},"received_at":"2026-07-28T04:08:30.022871Z","record_id":"f1d013bb3e35c19d105177e5ece75e744ffa2a25184671c474d8a4f2d1dd7b27","schema_fingerprint":"4aa3821a28b0b7c2400bc59aba4bcc0a76e971dadd19610d3ad38c768e124dc7","schema_version":"edge-lab-recorder.raw.v1","sequence":null,"source":"clob_market_ws"}
{"event_at":"2026-07-28T04:08:26.206000Z","event_fingerprint":"f58f071a0294aaabff66d4127f4eb741cf71220e8c6f6536113fee046c620d9b","payload":{"connection_id":"f6725804f86a4c4eb588e4d5ed7db029","event_at":"2026-07-28T04:08:26.206000Z","event_type":"price_change","frame_hash":"156c3325e3fa848e6b6a8aad626b0ef4de8b54c268d016aa388cade6f81a35cd","frame_index":0,"kind":"data","monotonic_ns":313693093392458,"payload":{"event_type":"price_change","market":"0xd412ce774cfcf8dc9f71164aac78783978aac7b03871702a3b8a481bd9dc9688","price_changes":[{"asset_id":"96600821790790307414914106093858868634329285205417149685270682748367152458577","best_ask":"0.42","best_bid":"0.41","hash":"c33ea888792753de5b9823a831de62d4cdc34063","price":"0.38","side":"BUY","size":"12.6"},{"asset_id":"107603864457683460275633293642179940881969192120168665300712204232021063124301","best_ask":"0.59","best_bid":"0.58","hash":"9718a3ba57d784ecef46c14112c87936b7ce54d5","price":"0.62","side":"SELL","size":"12.6"}],"timestamp":"1785211706206"},"payload_hash":"512b45717c587574ef606073f365e5488892c3558d5cca40b2af6d39ad657611","raw_frame":"{\"market\":\"0xd412ce774cfcf8dc9f71164aac78783978aac7b03871702a3b8a481bd9dc9688\", \"price_changes\":[{\"asset_id\":\"96600821790790307414914106093858868634329285205417149685270682748367152458577\", \"price\":\"0.38\", \"size\":\"12.6\", \"side\":\"BUY\", \"hash\":\"c33ea888792753de5b9823a831de62d4cdc34063\", \"best_bid\":\"0.41\", \"best_ask\":\"0.42\"}, {\"asset_id\":\"107603864457683460275633293642179940881969192120168665300712204232021063124301\", \"price\":\"0.62\", \"size\":\"12.6\", \"side\":\"SELL\", \"hash\":\"9718a3ba57d784ecef46c14112c87936b7ce54d5\", \"best_bid\":\"0.58\", \"best_ask\":\"0.59\"}], \"timestamp\":\"1785211706206\", \"event_type\":\"price_change\"}","received_at":"2026-07-28T04:08:30.025819Z","schema_version":"clob-market-ws.price_change.v1","sequence":null,"server_hash":null,"server_timestamp":"1785211706206","session_id":"2d607381e3054cee91998cdf45a4231c","source":"clob_market_ws"},"received_at":"2026-07-28T04:08:30.025819Z","record_id":"34970ce5e3c2aa4a106249fc398239722312c28f7fe01721f3e99712e5364c9f","schema_fingerprint":"4aa3821a28b0b7c2400bc59aba4bcc0a76e971dadd19610d3ad38c768e124dc7","schema_version":"edge-lab-recorder.raw.v1","sequence":null,"source":"clob_market_ws"}
{"event_at":"2026-07-28T04:08:26.208000Z","event_fingerprint":"16a9fb64047412e0180d4be8079df046d13fd76d2df5210d06b63451306d8517","payload":{"connection_id":"f6725804f86a4c4eb588e4d5ed7db029","event_at":"2026-07-28T04:08:26.208000Z","event_type":"price_change","frame_hash":"cb4e3aeaf5091371c8cbe468bf0ae5041c853cb8744120e5e03e8e7044cd6ff8","frame_index":0,"kind":"data","monotonic_ns":313693096467875,"payload":{"event_type":"price_change","market":"0xd412ce774cfcf8dc9f71164aac78783978aac7b03871702a3b8a481bd9dc9688","price_changes":[{"asset_id":"96600821790790307414914106093858868634329285205417149685270682748367152458577","best_ask":"0.42","best_bid":"0.41","hash":"207795cef77b2980ca9e5e38edfbbfb7465b3d2a","price":"0.38","side":"BUY","size":"18.6"},{"asset_id":"107603864457683460275633293642179940881969192120168665300712204232021063124301","best_ask":"0.59","best_bid":"0.58","hash":"dbf5077e69859a567feafe4d9cdf10994d2dda65","price":"0.62","side":"SELL","size":"18.6"}],"timestamp":"1785211706208"},"payload_hash":"a4db109a0eda95d1f5140d23296611b61d185b2c9ed29e030d85063e9cf20547","raw_frame":"{\"market\":\"0xd412ce774cfcf8dc9f71164aac78783978aac7b03871702a3b8a481bd9dc9688\", \"price_changes\":[{\"asset_id\":\"96600821790790307414914106093858868634329285205417149685270682748367152458577\", \"price\":\"0.38\", \"size\":\"18.6\", \"side\":\"BUY\", \"hash\":\"207795cef77b2980ca9e5e38edfbbfb7465b3d2a\", \"best_bid\":\"0.41\", \"best_ask\":\"0.42\"}, {\"asset_id\":\"107603864457683460275633293642179940881969192120168665300712204232021063124301\", \"price\":\"0.62\", \"size\":\"18.6\", \"side\":\"SELL\", \"hash\":\"dbf5077e69859a567feafe4d9cdf10994d2dda65\", \"best_bid\":\"0.58\", \"best_ask\":\"0.59\"}], \"timestamp\":\"1785211706208\", \"event_type\":\"price_change\"}","received_at":"2026-07-28T04:08:30.028893Z","schema_version":"clob-market-ws.price_change.v1","sequence":null,"server_hash":null,"server_timestamp":"1785211706208","session_id":"2d607381e3054cee91998cdf45a4231c","source":"clob_market_ws"},"received_at":"2026-07-28T04:08:30.028893Z","record_id":"49003f855844e3fe85547a21ac131c45163a4dc1a11db964082779f3d60373cc","schema_fingerprint":"4aa3821a28b0b7c2400bc59aba4bcc0a76e971dadd19610d3ad38c768e124dc7","schema_version":"edge-lab-recorder.raw.v1","sequence":null,"source":"clob_market_ws"}
{"event_at":"2026-07-28T04:08:26.209000Z","event_fingerprint":"75d2283773e4b58c4bc76079fd2ec399eeb47c00989e4ea6d863c68292876ad1","payload":{"connection_id":"f6725804f86a4c4eb588e4d5ed7db029","event_at":"2026-07-28T04:08:26.209000Z","event_type":"price_change","frame_hash":"95070ac2a20563d03c848c50d5a16d4ffb29d1e0520badb2e4d5dea9ae068f47","frame_index":0,"kind":"data","monotonic_ns":313693099599208,"payload":{"event_type":"price_change","market":"0xd412ce774cfcf8dc9f71164aac78783978aac7b03871702a3b8a481bd9dc9688","price_changes":[{"asset_id":"96600821790790307414914106093858868634329285205417149685270682748367152458577","best_ask":"0.42","best_bid":"0.41","hash":"1297bb5251ba827e6bdb154e9d21343a4272eab5","price":"0.38","side":"BUY","size":"12.6"},{"asset_id":"107603864457683460275633293642179940881969192120168665300712204232021063124301","best_ask":"0.59","best_bid":"0.58","hash":"643f2dcb914a5b45a83be9cdbb43796a554ee8bf","price":"0.62","side":"SELL","size":"12.6"}],"timestamp":"1785211706209"},"payload_hash":"8b5f0be367124158c2b084b887b14b2c60703c45977da9d02ae701e06bba5ece","raw_frame":"{\"market\":\"0xd412ce774cfcf8dc9f71164aac78783978aac7b03871702a3b8a481bd9dc9688\", \"price_changes\":[{\"asset_id\":\"96600821790790307414914106093858868634329285205417149685270682748367152458577\", \"price\":\"0.38\", \"size\":\"12.6\", \"side\":\"BUY\", \"hash\":\"1297bb5251ba827e6bdb154e9d21343a4272eab5\", \"best_bid\":\"0.41\", \"best_ask\":\"0.42\"}, {\"asset_id\":\"107603864457683460275633293642179940881969192120168665300712204232021063124301\", \"price\":\"0.62\", \"size\":\"12.6\", \"side\":\"SELL\", \"hash\":\"643f2dcb914a5b45a83be9cdbb43796a554ee8bf\", \"best_bid\":\"0.58\", \"best_ask\":\"0.59\"}], \"timestamp\":\"1785211706209\", \"event_type\":\"price_change\"}","received_at":"2026-07-28T04:08:30.032022Z","schema_version":"clob-market-ws.price_change.v1","sequence":null,"server_hash":null,"server_timestamp":"1785211706209","session_id":"2d607381e3054cee91998cdf45a4231c","source":"clob_market_ws"},"received_at":"2026-07-28T04:08:30.032022Z","record_id":"36ec1c411704343be48663590e68c449a75a3c44858f9eacaa6bd4dc3e908189","schema_fingerprint":"4aa3821a28b0b7c2400bc59aba4bcc0a76e971dadd19610d3ad38c768e124dc7","schema_version":"edge-lab-recorder.raw.v1","sequence":null,"source":"clob_market_ws"}
{"event_at":"2026-07-28T04:08:26.209000Z","event_fingerprint":"cd188a73621e45e58d2b4e46fd202c931125dd05fdc1cdacd7a68e2e11d0e3f1","payload":{"connection_id":"f6725804f86a4c4eb588e4d5ed7db029","event_at":"2026-07-28T04:08:26.209000Z","event_type":"price_change","frame_hash":"793944f5550dc93efdce7b0e452aa556fa770326931de80e449d7a6f90077cc7","frame_index":0,"kind":"data","monotonic_ns":313693102625291,"payload":{"event_type":"price_change","market":"0xd412ce774cfcf8dc9f71164aac78783978aac7b03871702a3b8a481bd9dc9688","price_changes":[{"asset_id":"96600821790790307414914106093858868634329285205417149685270682748367152458577","best_ask":"0.42","best_bid":"0.41","hash":"331cb5b3f25ead6444e4043e85025677d95ac885","price":"0.35","side":"BUY","size":"128.45"},{"asset_id":"107603864457683460275633293642179940881969192120168665300712204232021063124301","best_ask":"0.59","best_bid":"0.58","hash":"ea558ed0fe7c06eac8a03ac85379ef0ed91f3b89","price":"0.65","side":"SELL","size":"128.45"}],"timestamp":"1785211706209"},"payload_hash":"75bb0d0ba4e294d1bb362222c1da11d0b8ed9e8298eeef6eb1d65765fd725a23","raw_frame":"{\"market\":\"0xd412ce774cfcf8dc9f71164aac78783978aac7b03871702a3b8a481bd9dc9688\", \"price_changes\":[{\"asset_id\":\"96600821790790307414914106093858868634329285205417149685270682748367152458577\", \"price\":\"0.35\", \"size\":\"128.45\", \"side\":\"BUY\", \"hash\":\"331cb5b3f25ead6444e4043e85025677d95ac885\", \"best_bid\":\"0.41\", \"best_ask\":\"0.42\"}, {\"asset_id\":\"107603864457683460275633293642179940881969192120168665300712204232021063124301\", \"price\":\"0.65\", \"size\":\"128.45\", \"side\":\"SELL\", \"hash\":\"ea558ed0fe7c06eac8a03ac85379ef0ed91f3b89\", \"best_bid\":\"0.58\", \"best_ask\":\"0.59\"}], \"timestamp\":\"1785211706209\", \"event_type\":\"price_change\"}","received_at":"2026-07-28T04:08:30.035047Z","schema_version":"clob-market-ws.price_change.v1","sequence":null,"server_hash":null,"server_timestamp":"1785211706209","session_id":"2d607381e3054cee91998cdf45a4231c","source":"clob_market_ws"},"received_at":"2026-07-28T04:08:30.035047Z","record_id":"bd9ace8d9f6377a62b7265b3945ae40a3ef4846a04916766d33598600fa37e5c","schema_fingerprint":"4aa3821a28b0b7c2400bc59aba4bcc0a76e971dadd19610d3ad38c768e124dc7","schema_version":"edge-lab-recorder.raw.v1","sequence":null,"source":"clob_market_ws"}
{"event_at":"2026-07-28T04:08:26.209000Z","event_fingerprint":"55b374c7d75cbe6ad164dd8fdd21668829f0c0f8a9d43789627215ab3cdac34c","payload":{"connection_id":"f6725804f86a4c4eb588e4d5ed7db029","event_at":"2026-07-28T04:08:26.209000Z","event_type":"price_change","frame_hash":"adeb6e8b9c398b840547abcbf529ff09fe44c40a66251542109b4ce1a54c907f","frame_index":0,"kind":"data","monotonic_ns":313693105688958,"payload":{"event_type":"price_change","market":"0xd412ce774cfcf8dc9f71164aac78783978aac7b03871702a3b8a481bd9dc9688","price_changes":[{"asset_id":"96600821790790307414914106093858868634329285205417149685270682748367152458577","best_ask":"0.42","best_bid":"0.41","hash":"331cb5b3f25ead6444e4043e85025677d95ac885","price":"0.34","side":"BUY","size":"125.29"},{"asset_id":"107603864457683460275633293642179940881969192120168665300712204232021063124301","best_ask":"0.59","best_bid":"0.58","hash":"ea558ed0fe7c06eac8a03ac85379ef0ed91f3b89","price":"0.66","side":"SELL","size":"125.29"}],"timestamp":"1785211706209"},"payload_hash":"03c09a83aa8ff0896faee9a2e62d8923c185c9390e83915f78714f74bdbbbdba","raw_frame":"{\"market\":\"0xd412ce774cfcf8dc9f71164aac78783978aac7b03871702a3b8a481bd9dc9688\", \"price_changes\":[{\"asset_id\":\"96600821790790307414914106093858868634329285205417149685270682748367152458577\", \"price\":\"0.34\", \"size\":\"125.29\", \"side\":\"BUY\", \"hash\":\"331cb5b3f25ead6444e4043e85025677d95ac885\", \"best_bid\":\"0.41\", \"best_ask\":\"0.42\"}, {\"asset_id\":\"107603864457683460275633293642179940881969192120168665300712204232021063124301\", \"price\":\"0.66\", \"size\":\"125.29\", \"side\":\"SELL\", \"hash\":\"ea558ed0fe7c06eac8a03ac85379ef0ed91f3b89\", \"best_bid\":\"0.58\", \"best_ask\":\"0.59\"}], \"timestamp\":\"1785211706209\", \"event_type\":\"price_change\"}","received_at":"2026-07-28T04:08:30.038109Z","schema_version":"clob-market-ws.price_change.v1","sequence":null,"server_hash":null,"server_timestamp":"1785211706209","session_id":"2d607381e3054cee91998cdf45a4231c","source":"clob_market_ws"},"received_at":"2026-07-28T04:08:30.038109Z","record_id":"e5e20e94cfde5a307884dee2033e6784121071c7df29de837ff7ba240e72ae52","schema_fingerprint":"4aa3821a28b0b7c2400bc59aba4bcc0a76e971dadd19610d3ad38c768e124dc7","schema_version":"edge-lab-recorder.raw.v1","sequence":null,"source":"clob_market_ws"}
{"event_at":"2026-07-28T04:08:26.209000Z","event_fingerprint":"f708de2b16f463b58962274e1c098ba339ec6c53ed3c3971f904d35c11e687db","payload":{"connection_id":"f6725804f86a4c4eb588e4d5ed7db029","event_at":"2026-07-28T04:08:26.209000Z","event_type":"price_change","frame_hash":"b9c6a930ebcfec5555f0dc4e3fc9fbf2afc2644dbe99f386794626a800bb5b58","frame_index":0,"kind":"data","monotonic_ns":313693108639166,"payload":{"event_type":"price_change","market":"0xd412ce774cfcf8dc9f71164aac78783978aac7b03871702a3b8a481bd9dc9688","price_changes":[{"asset_id":"96600821790790307414914106093858868634329285205417149685270682748367152458577","best_ask":"0.42","best_bid":"0.41","hash":"331cb5b3f25ead6444e4043e85025677d95ac885","price":"0.31","side":"BUY","size":"93.38"},{"asset_id":"107603864457683460275633293642179940881969192120168665300712204232021063124301","best_ask":"0.59","best_bid":"0.58","hash":"ea558ed0fe7c06eac8a03ac85379ef0ed91f3b89","price":"0.69","side":"SELL","size":"93.38"}],"timestamp":"1785211706209"},"payload_hash":"4c7cee409ef17d18fd0ea34551a5aff91c774179585d393cbc5bd295bb7e9071","raw_frame":"{\"market\":\"0xd412ce774cfcf8dc9f71164aac78783978aac7b03871702a3b8a481bd9dc9688\", \"price_changes\":[{\"asset_id\":\"96600821790790307414914106093858868634329285205417149685270682748367152458577\", \"price\":\"0.31\", \"size\":\"93.38\", \"side\":\"BUY\", \"hash\":\"331cb5b3f25ead6444e4043e85025677d95ac885\", \"best_bid\":\"0.41\", \"best_ask\":\"0.42\"}, {\"asset_id\":\"107603864457683460275633293642179940881969192120168665300712204232021063124301\", \"price\":\"0.69\", \"size\":\"93.38\", \"side\":\"SELL\", \"hash\":\"ea558ed0fe7c06eac8a03ac85379ef0ed91f3b89\", \"best_bid\":\"0.58\", \"best_ask\":\"0.59\"}], \"timestamp\":\"1785211706209\", \"event_type\":\"price_change\"}","received_at":"2026-07-28T04:08:30.041058Z","schema_version":"clob-market-ws.price_change.v1","sequence":null,"server_hash":null,"server_timestamp":"1785211706209","session_id":"2d607381e3054cee91998cdf45a4231c","source":"clob_market_ws"},"received_at":"2026-07-28T04:08:30.041058Z","record_id":"a89ff8c95bf8cc32f76116d426bf3bdc5fa6476fa390ca58bb28c7d2ed7fdf75","schema_fingerprint":"4aa3821a28b0b7c2400bc59aba4bcc0a76e971dadd19610d3ad38c768e124dc7","schema_version":"edge-lab-recorder.raw.v1","sequence":null,"source":"clob_market_ws"}
{"event_at":"2026-07-28T04:08:26.209000Z","event_fingerprint":"8d31b164074a9999e7a2527ccea8aac934c05bc01529f84994ac7728f3b8c49b","payload":{"connection_id":"f6725804f86a4c4eb588e4d5ed7db029","event_at":"2026-07-28T04:08:26.209000Z","event_type":"price_change","frame_hash":"13c45c371bfe7ee8b1c2220334624d398ee53ff84cde9d00fb12f989aa2b34de","frame_index":0,"kind":"data","monotonic_ns":313693111709208,"payload":{"event_type":"price_change","market":"0xd412ce774cfcf8dc9f71164aac78783978aac7b03871702a3b8a481bd9dc9688","price_changes":[{"asset_id":"96600821790790307414914106093858868634329285205417149685270682748367152458577","best_ask":"0.42","best_bid":"0.41","hash":"26430ce6de082d4b9ea6197526030448a40f2c93","price":"0.41","side":"BUY","size":"12"},{"asset_id":"107603864457683460275633293642179940881969192120168665300712204232021063124301","best_ask":"0.59","best_bid":"0.58","hash":"27cc9195ec3825c76aa69837ed0afb1f20241f13","price":"0.59","side":"SELL","size":"12"}],"timestamp":"1785211706209"},"payload_hash":"714e4a9a79bbe056d0146a3a4096e811f6f59f4a2ca6f397a123dfdd21c9f2d9","raw_frame":"{\"market\":\"0xd412ce774cfcf8dc9f71164aac78783978aac7b03871702a3b8a481bd9dc9688\", \"price_changes\":[{\"asset_id\":\"96600821790790307414914106093858868634329285205417149685270682748367152458577\", \"price\":\"0.41\", \"size\":\"12\", \"side\":\"BUY\", \"hash\":\"26430ce6de082d4b9ea6197526030448a40f2c93\", \"best_bid\":\"0.41\", \"best_ask\":\"0.42\"}, {\"asset_id\":\"107603864457683460275633293642179940881969192120168665300712204232021063124301\", \"price\":\"0.59\", \"size\":\"12\", \"side\":\"SELL\", \"hash\":\"27cc9195ec3825c76aa69837ed0afb1f20241f13\", \"best_bid\":\"0.58\", \"best_ask\":\"0.59\"}], \"timestamp\":\"1785211706209\", \"event_type\":\"price_change\"}","received_at":"2026-07-28T04:08:30.044126Z","schema_version":"clob-market-ws.price_change.v1","sequence":null,"server_hash":null,"server_timestamp":"1785211706209","session_id":"2d607381e3054cee91998cdf45a4231c","source":"clob_market_ws"},"received_at":"2026-07-28T04:08:30.044126Z","record_id":"484e5dfb640a6b1b792b548b4017cfdce02621ff6505199c2ac543a28fd71e74","schema_fingerprint":"4aa3821a28b0b7c2400bc59aba4bcc0a76e971dadd19610d3ad38c768e124dc7","schema_version":"edge-lab-recorder.raw.v1","sequence":null,"source":"clob_market_ws"}
{"event_at":"2026-07-28T04:08:26.210000Z","event_fingerprint":"cc6e05b77b73bbf085d33c59830388bed1892d07d07fc0dc4f97a2bf636c86db","payload":{"connection_id":"f6725804f86a4c4eb588e4d5ed7db029","event_at":"2026-07-28T04:08:26.210000Z","event_type":"price_change","frame_hash":"e9d8c557e0a78eecac1f0f41288089bf249bd822a5725a9c7fded99417761c2f","frame_index":0,"kind":"data","monotonic_ns":313693114665666,"payload":{"event_type":"price_change","market":"0xd412ce774cfcf8dc9f71164aac78783978aac7b03871702a3b8a481bd9dc9688","price_changes":[{"asset_id":"96600821790790307414914106093858868634329285205417149685270682748367152458577","best_ask":"0.42","best_bid":"0.41","hash":"ac98f6b7cc36787ecd9520b77c4c9034e1ce4a1b","price":"0.37","side":"BUY","size":"177.88"},{"asset_id":"107603864457683460275633293642179940881969192120168665300712204232021063124301","best_ask":"0.59","best_bid":"0.58","hash":"f581592174b451c9c5b039c0e3fe64f4ba0c592f","price":"0.63","side":"SELL","size":"177.88"}],"timestamp":"1785211706210"},"payload_hash":"5598cb54486708baaff4fe8cddebccec797c2b093d84593b956a7234fa70e86c","raw_frame":"{\"market\":\"0xd412ce774cfcf8dc9f71164aac78783978aac7b03871702a3b8a481bd9dc9688\", \"price_changes\":[{\"asset_id\":\"96600821790790307414914106093858868634329285205417149685270682748367152458577\", \"price\":\"0.37\", \"size\":\"177.88\", \"side\":\"BUY\", \"hash\":\"ac98f6b7cc36787ecd9520b77c4c9034e1ce4a1b\", \"best_bid\":\"0.41\", \"best_ask\":\"0.42\"}, {\"asset_id\":\"107603864457683460275633293642179940881969192120168665300712204232021063124301\", \"price\":\"0.63\", \"size\":\"177.88\", \"side\":\"SELL\", \"hash\":\"f581592174b451c9c5b039c0e3fe64f4ba0c592f\", \"best_bid\":\"0.58\", \"best_ask\":\"0.59\"}], \"timestamp\":\"1785211706210\", \"event_type\":\"price_change\"}","received_at":"2026-07-28T04:08:30.047082Z","schema_version":"clob-market-ws.price_change.v1","sequence":null,"server_hash":null,"server_timestamp":"1785211706210","session_id":"2d607381e3054cee91998cdf45a4231c","source":"clob_market_ws"},"received_at":"2026-07-28T04:08:30.047082Z","record_id":"5f6747939db94416453a3b628ed293280862d5e66e2f6e027245736aed163fa7","schema_fingerprint":"4aa3821a28b0b7c2400bc59aba4bcc0a76e971dadd19610d3ad38c768e124dc7","schema_version":"edge-lab-recorder.raw.v1","sequence":null,"source":"clob_market_ws"}
{"event_at":"2026-07-28T04:08:26.212000Z","event_fingerprint":"93a2c946578e403615ab3f3d9220e9405d93baa5c79ab521cfaab74564ed242c","payload":{"connection_id":"f6725804f86a4c4eb588e4d5ed7db029","event_at":"2026-07-28T04:08:26.212000Z","event_type":"price_change","frame_hash":"45ab2c669756b122f846c761038a340b3a5ee625be38ec9dc8f3c5b87fa17b86","frame_index":0,"kind":"data","monotonic_ns":313693117585500,"payload":{"event_type":"price_change","market":"0xd412ce774cfcf8dc9f71164aac78783978aac7b03871702a3b8a481bd9dc9688","price_changes":[{"asset_id":"96600821790790307414914106093858868634329285205417149685270682748367152458577","best_ask":"0.42","best_bid":"0.41","hash":"5b92c880eab21050782b8eb4901780ffc3e24844","price":"0.39","side":"BUY","size":"6"},{"asset_id":"107603864457683460275633293642179940881969192120168665300712204232021063124301","best_ask":"0.59","best_bid":"0.58","hash":"6c2432eed13f5b8874423b556b890522b6498370","price":"0.61","side":"SELL","size":"6"}],"timestamp":"1785211706212"},"payload_hash":"10eac088c3644596de9f28ba0f51b5bd89aa9b6f865479db4625031adf9d0189","raw_frame":"{\"market\":\"0xd412ce774cfcf8dc9f71164aac78783978aac7b03871702a3b8a481bd9dc9688\", \"price_changes\":[{\"asset_id\":\"96600821790790307414914106093858868634329285205417149685270682748367152458577\", \"price\":\"0.39\", \"size\":\"6\", \"side\":\"BUY\", \"hash\":\"5b92c880eab21050782b8eb4901780ffc3e24844\", \"best_bid\":\"0.41\", \"best_ask\":\"0.42\"}, {\"asset_id\":\"107603864457683460275633293642179940881969192120168665300712204232021063124301\", \"price\":\"0.61\", \"size\":\"6\", \"side\":\"SELL\", \"hash\":\"6c2432eed13f5b8874423b556b890522b6498370\", \"best_bid\":\"0.58\", \"best_ask\":\"0.59\"}], \"timestamp\":\"1785211706212\", \"event_type\":\"price_change\"}","received_at":"2026-07-28T04:08:30.050000Z","schema_version":"clob-market-ws.price_change.v1","sequence":null,"server_hash":null,"server_timestamp":"1785211706212","session_id":"2d607381e3054cee91998cdf45a4231c","source":"clob_market_ws"},"received_at":"2026-07-28T04:08:30.050000Z","record_id":"1eac741c3eef79d47270f40e80f072e5a75c993e1be5d1c03cafc5f5135357d5","schema_fingerprint":"4aa3821a28b0b7c2400bc59aba4bcc0a76e971dadd19610d3ad38c768e124dc7","schema_version":"edge-lab-recorder.raw.v1","sequence":null,"source":"clob_market_ws"}
{"event_at":"2026-07-28T04:08:26.213000Z","event_fingerprint":"865883f56db83711197ba030311f25c24a9c3f3550e3676a2d1b20b4ba447bb6","payload":{"connection_id":"f6725804f86a4c4eb588e4d5ed7db029","event_at":"2026-07-28T04:08:26.213000Z","event_type":"price_change","frame_hash":"69243a625cbf8f836c249161b571984724986d1e6b292b657dae795e67762f3c","frame_index":0,"kind":"data","monotonic_ns":313693120590250,"payload":{"event_type":"price_change","market":"0xd412ce774cfcf8dc9f71164aac78783978aac7b03871702a3b8a481bd9dc9688","price_changes":[{"asset_id":"107603864457683460275633293642179940881969192120168665300712204232021063124301","best_ask":"0.59","best_bid":"0.58","hash":"0c2eed671167da6c0ae439617ca41f782833c722","price":"0.63","side":"SELL","size":"198.88"},{"asset_id":"96600821790790307414914106093858868634329285205417149685270682748367152458577","best_ask":"0.42","best_bid":"0.41","hash":"ee4f41e3a4288eb09b8643fc62cfce78ce666c62","price":"0.37","side":"BUY","size":"198.88"}],"timestamp":"1785211706213"},"payload_hash":"f8ccbc1ced8a6d29f37342afd71255a73c990dd94feb3549c6ad7bf5c0f75f41","raw_frame":"{\"market\":\"0xd412ce774cfcf8dc9f71164aac78783978aac7b03871702a3b8a481bd9dc9688\", \"price_changes\":[{\"asset_id\":\"107603864457683460275633293642179940881969192120168665300712204232021063124301\", \"price\":\"0.63\", \"size\":\"198.88\", \"side\":\"SELL\", \"hash\":\"0c2eed671167da6c0ae439617ca41f782833c722\", \"best_bid\":\"0.58\", \"best_ask\":\"0.59\"}, {\"asset_id\":\"96600821790790307414914106093858868634329285205417149685270682748367152458577\", \"price\":\"0.37\", \"size\":\"198.88\", \"side\":\"BUY\", \"hash\":\"ee4f41e3a4288eb09b8643fc62cfce78ce666c62\", \"best_bid\":\"0.41\", \"best_ask\":\"0.42\"}], \"timestamp\":\"1785211706213\", \"event_type\":\"price_change\"}","received_at":"2026-07-28T04:08:30.053003Z","schema_version":"clob-market-ws.price_change.v1","sequence":null,"server_hash":null,"server_timestamp":"1785211706213","session_id":"2d607381e3054cee91998cdf45a4231c","source":"clob_market_ws"},"received_at":"2026-07-28T04:08:30.053003Z","record_id":"e2cc2e7ce0054221a4f551cd5577c9aa752e9cc976926d6147470955510b1409","schema_fingerprint":"4aa3821a28b0b7c2400bc59aba4bcc0a76e971dadd19610d3ad38c768e124dc7","schema_version":"edge-lab-recorder.raw.v1","sequence":null,"source":"clob_market_ws"}
{"event_at":"2026-07-28T04:08:26.214000Z","event_fingerprint":"21753c153fc62a97e26384ca0201d9d4505de2d2f4cd0626c610e763adc4ab3b","payload":{"connection_id":"f6725804f86a4c4eb588e4d5ed7db029","event_at":"2026-07-28T04:08:26.214000Z","event_type":"price_change","frame_hash":"bf6308ae1e87275a9ad04f4752aa901636f2eebbf1b9f873e37beba7d1657fcd","frame_index":0,"kind":"data","monotonic_ns":313693123739333,"payload":{"event_type":"price_change","market":"0xd412ce774cfcf8dc9f71164aac78783978aac7b03871702a3b8a481bd9dc9688","price_changes":[{"asset_id":"96600821790790307414914106093858868634329285205417149685270682748367152458577","best_ask":"0.42","best_bid":"0.41","hash":"90f6866c897438e2c3a55a3f08dbc4a38e7ade86","price":"0.41","side":"BUY","size":"17.64"},{"asset_id":"107603864457683460275633293642179940881969192120168665300712204232021063124301","best_ask":"0.59","best_bid":"0.58","hash":"afbb8f3ac224e3b4c5faac7da9e2c648d35ff8a7","price":"0.59","side":"SELL","size":"17.64"}],"timestamp":"1785211706214"},"payload_hash":"a8c1423283c9fddf61d116a689d78ccb7d850c5146d212f8b31afbf0ca3835dd","raw_frame":"{\"market\":\"0xd412ce774cfcf8dc9f71164aac78783978aac7b03871702a3b8a481bd9dc9688\", \"price_changes\":[{\"asset_id\":\"96600821790790307414914106093858868634329285205417149685270682748367152458577\", \"price\":\"0.41\", \"size\":\"17.64\", \"side\":\"BUY\", \"hash\":\"90f6866c897438e2c3a55a3f08dbc4a38e7ade86\", \"best_bid\":\"0.41\", \"best_ask\":\"0.42\"}, {\"asset_id\":\"107603864457683460275633293642179940881969192120168665300712204232021063124301\", \"price\":\"0.59\", \"size\":\"17.64\", \"side\":\"SELL\", \"hash\":\"afbb8f3ac224e3b4c5faac7da9e2c648d35ff8a7\", \"best_bid\":\"0.58\", \"best_ask\":\"0.59\"}], \"timestamp\":\"1785211706214\", \"event_type\":\"price_change\"}","received_at":"2026-07-28T04:08:30.056150Z","schema_version":"clob-market-ws.price_change.v1","sequence":null,"server_hash":null,"server_timestamp":"1785211706214","session_id":"2d607381e3054cee91998cdf45a4231c","source":"clob_market_ws"},"received_at":"2026-07-28T04:08:30.056150Z","record_id":"ae9b57237c06b8f1e5008be72f0010c5d9f3cadce036c86f4609e8a6ecd37422","schema_fingerprint":"4aa3821a28b0b7c2400bc59aba4bcc0a76e971dadd19610d3ad38c768e124dc7","schema_version":"edge-lab-recorder.raw.v1","sequence":null,"source":"clob_market_ws"}
{"event_at":"2026-07-28T04:08:26.216000Z","event_fingerprint":"a8bc2fbc71420712cdf88805c6fa970f3c85fef381bac4ed28d70ec677b77b63","payload":{"connection_id":"f6725804f86a4c4eb588e4d5ed7db029","event_at":"2026-07-28T04:08:26.216000Z","event_type":"price_change","frame_hash":"83c63c8a60264d462c78deadd836fadeffa479da2d048ca6b11ac3f5983b75a0","frame_index":0,"kind":"data","monotonic_ns":313693126711458,"payload":{"event_type":"price_change","market":"0xd412ce774cfcf8dc9f71164aac78783978aac7b03871702a3b8a481bd9dc9688","price_changes":[{"asset_id":"96600821790790307414914106093858868634329285205417149685270682748367152458577","best_ask":"0.42","best_bid":"0.41","hash":"33a7b02ec1fb0fad57b711a249f3f3e333064429","price":"0.41","side":"BUY","size":"23.28"},{"asset_id":"107603864457683460275633293642179940881969192120168665300712204232021063124301","best_ask":"0.59","best_bid":"0.58","hash":"3841c29d19e925c4864cf28eb9b7aabe059470fc","price":"0.59","side":"SELL","size":"23.28"}],"timestamp":"1785211706216"},"payload_hash":"4442c77d3df5895afe2defc67459827c7cd23c5d0066180aa5c948aeef100462","raw_frame":"{\"market\":\"0xd412ce774cfcf8dc9f71164aac78783978aac7b03871702a3b8a481bd9dc9688\", \"price_changes\":[{\"asset_id\":\"96600821790790307414914106093858868634329285205417149685270682748367152458577\", \"price\":\"0.41\", \"size\":\"23.28\", \"side\":\"BUY\", \"hash\":\"33a7b02ec1fb0fad57b711a249f3f3e333064429\", \"best_bid\":\"0.41\", \"best_ask\":\"0.42\"}, {\"asset_id\":\"107603864457683460275633293642179940881969192120168665300712204232021063124301\", \"price\":\"0.59\", \"size\":\"23.28\", \"side\":\"SELL\", \"hash\":\"3841c29d19e925c4864cf28eb9b7aabe059470fc\", \"best_bid\":\"0.58\", \"best_ask\":\"0.59\"}], \"timestamp\":\"1785211706216\", \"event_type\":\"price_change\"}","received_at":"2026-07-28T04:08:30.059120Z","schema_version":"clob-market-ws.price_change.v1","sequence":null,"server_hash":null,"server_timestamp":"1785211706216","session_id":"2d607381e3054cee91998cdf45a4231c","source":"clob_market_ws"},"received_at":"2026-07-28T04:08:30.059120Z","record_id":"85dd26a665c2d039f17bdc42fc937db4d5cb75bdb1ff67c831815956bb5dfdef","schema_fingerprint":"4aa3821a28b0b7c2400bc59aba4bcc0a76e971dadd19610d3ad38c768e124dc7","schema_version":"edge-lab-recorder.raw.v1","sequence":null,"source":"clob_market_ws"}
{"event_at":"2026-07-28T04:08:26.217000Z","event_fingerprint":"1ba038ce8e70e244cbecaea7413c2e7d2641912114944b066e0935b60568240e","payload":{"connection_id":"f6725804f86a4c4eb588e4d5ed7db029","event_at":"2026-07-28T04:08:26.217000Z","event_type":"price_change","frame_hash":"ada7ae56f581ebb8fa1c5256d7baa2be59b877c0c0ad3c30e02c67f6b94f03fd","frame_index":0,"kind":"data","monotonic_ns":313693129948333,"payload":{"event_type":"price_change","market":"0xd412ce774cfcf8dc9f71164aac78783978aac7b03871702a3b8a481bd9dc9688","price_changes":[{"asset_id":"96600821790790307414914106093858868634329285205417149685270682748367152458577","best_ask":"0.42","best_bid":"0.41","hash":"468f636016e18ceed51d696ab698ca5da96ee13f","price":"0.33","side":"BUY","size":"173.38"},{"asset_id":"107603864457683460275633293642179940881969192120168665300712204232021063124301","best_ask":"0.59","best_bid":"0.58","hash":"45aabc938c2de076cab4f1f6e4c0d463087cbefa","price":"0.67","side":"SELL","size":"173.38"}],"timestamp":"1785211706217"},"payload_hash":"7a715e7ad5e4c38e308817cade1494ee041c86c350f72a1be13f61b2246ef026","raw_frame":"{\"market\":\"0xd412ce774cfcf8dc9f71164aac78783978aac7b03871702a3b8a481bd9dc9688\", \"price_changes\":[{\"asset_id\":\"96600821790790307414914106093858868634329285205417149685270682748367152458577\", \"price\":\"0.33\", \"size\":\"173.38\", \"side\":\"BUY\", \"hash\":\"468f636016e18ceed51d696ab698ca5da96ee13f\", \"best_bid\":\"0.41\", \"best_ask\":\"0.42\"}, {\"asset_id\":\"107603864457683460275633293642179940881969192120168665300712204232021063124301\", \"price\":\"0.67\", \"size\":\"173.38\", \"side\":\"SELL\", \"hash\":\"45aabc938c2de076cab4f1f6e4c0d463087cbefa\", \"best_bid\":\"0.58\", \"best_ask\":\"0.59\"}], \"timestamp\":\"1785211706217\", \"event_type\":\"price_change\"}","received_at":"2026-07-28T04:08:30.062356Z","schema_version":"clob-market-ws.price_change.v1","sequence":null,"server_hash":null,"server_timestamp":"1785211706217","session_id":"2d607381e3054cee91998cdf45a4231c","source":"clob_market_ws"},"received_at":"2026-07-28T04:08:30.062356Z","record_id":"7b0186359fe15f1475d79d2640adee4ef1ca5e4c9decf4952e1682b7a0e8ac13","schema_fingerprint":"4aa3821a28b0b7c2400bc59aba4bcc0a76e971dadd19610d3ad38c768e124dc7","schema_version":"edge-lab-recorder.raw.v1","sequence":null,"source":"clob_market_ws"}
{"event_at":"2026-07-28T04:08:26.218000Z","event_fingerprint":"75be04f0154f640a86ee175c5553dde9ec7499c33315a771999fcb859a48256a","payload":{"connection_id":"f6725804f86a4c4eb588e4d5ed7db029","event_at":"2026-07-28T04:08:26.218000Z","event_type":"price_change","frame_hash":"5d7feda0ab305c2bf064e9b271e36f48e9f111637c35af035c38518e9c937503","frame_index":0,"kind":"data","monotonic_ns":313693133032875,"payload":{"event_type":"price_change","market":"0xd412ce774cfcf8dc9f71164aac78783978aac7b03871702a3b8a481bd9dc9688","price_changes":[{"asset_id":"96600821790790307414914106093858868634329285205417149685270682748367152458577","best_ask":"0.42","best_bid":"0.41","hash":"e58f3137b7934b82a0d8ee8f0be42fe65431bcb6","price":"0.33","side":"BUY","size":"160.78"},{"asset_id":"107603864457683460275633293642179940881969192120168665300712204232021063124301","best_ask":"0.59","best_bid":"0.58","hash":"25cacd00eff2949c5672e00ed4f5414332262fe1","price":"0.67","side":"SELL","size":"160.78"}],"timestamp":"1785211706218"},"payload_hash":"569cb56d86643eedf81b5a66e058f6c5cb52528484d91fafcefb62a5b09f78f2","raw_frame":"{\"market\":\"0xd412ce774cfcf8dc9f71164aac78783978aac7b03871702a3b8a481bd9dc9688\", \"price_changes\":[{\"asset_id\":\"96600821790790307414914106093858868634329285205417149685270682748367152458577\", \"price\":\"0.33\", \"size\":\"160.78\", \"side\":\"BUY\", \"hash\":\"e58f3137b7934b82a0d8ee8f0be42fe65431bcb6\", \"best_bid\":\"0.41\", \"best_ask\":\"0.42\"}, {\"asset_id\":\"107603864457683460275633293642179940881969192120168665300712204232021063124301\", \"price\":\"0.67\", \"size\":\"160.78\", \"side\":\"SELL\", \"hash\":\"25cacd00eff2949c5672e00ed4f5414332262fe1\", \"best_bid\":\"0.58\", \"best_ask\":\"0.59\"}], \"timestamp\":\"1785211706218\", \"event_type\":\"price_change\"}","received_at":"2026-07-28T04:08:30.065439Z","schema_version":"clob-market-ws.price_change.v1","sequence":null,"server_hash":null,"server_timestamp":"1785211706218","session_id":"2d607381e3054cee91998cdf45a4231c","source":"clob_market_ws"},"received_at":"2026-07-28T04:08:30.065439Z","record_id":"57beb3747cd4f320e0be9dfd872512296d61e0f3fe0cbffe005fd6ba40496f18","schema_fingerprint":"4aa3821a28b0b7c2400bc59aba4bcc0a76e971dadd19610d3ad38c768e124dc7","schema_version":"edge-lab-recorder.raw.v1","sequence":null,"source":"clob_market_ws"}
{"event_at":"2026-07-28T04:08:26.219000Z","event_fingerprint":"85a2ad064459e7b78f8b9fffae54404c29fd3ef71e53bd43ee80147366c0ebc2","payload":{"connection_id":"f6725804f86a4c4eb588e4d5ed7db029","event_at":"2026-07-28T04:08:26.219000Z","event_type":"price_change","frame_hash":"996d8b963459015fa480280a73c1fb26a11fb73bebd6840fd7f0f51e38c84aab","frame_index":0,"kind":"data","monotonic_ns":313693136211375,"payload":{"event_type":"price_change","market":"0xd412ce774cfcf8dc9f71164aac78783978aac7b03871702a3b8a481bd9dc9688","price_changes":[{"asset_id":"96600821790790307414914106093858868634329285205417149685270682748367152458577","best_ask":"0.42","best_bid":"0.41","hash":"1590b6141fd763e206bc74879cc4088be429849a","price":"0.41","side":"BUY","size":"30.28"},{"asset_id":"107603864457683460275633293642179940881969192120168665300712204232021063124301","best_ask":"0.59","best_bid":"0.58","hash":"89e9d5a49d2695e40bde9ca3922e813c224b437d","price":"0.59","side":"SELL","size":"30.28"}],"timestamp":"1785211706219"},"payload_hash":"fa33c9715210ccc3a8de4cefb435985d1ab9bf95ec41a58b388ee0c38bfdb9ca","raw_frame":"{\"market\":\"0xd412ce774cfcf8dc9f71164aac78783978aac7b03871702a3b8a481bd9dc9688\", \"price_changes\":[{\"asset_id\":\"96600821790790307414914106093858868634329285205417149685270682748367152458577\", \"price\":\"0.41\", \"size\":\"30.28\", \"side\":\"BUY\", \"hash\":\"1590b6141fd763e206bc74879cc4088be429849a\", \"best_bid\":\"0.41\", \"best_ask\":\"0.42\"}, {\"asset_id\":\"107603864457683460275633293642179940881969192120168665300712204232021063124301\", \"price\":\"0.59\", \"size\":\"30.28\", \"side\":\"SELL\", \"hash\":\"89e9d5a49d2695e40bde9ca3922e813c224b437d\", \"best_bid\":\"0.58\", \"best_ask\":\"0.59\"}], \"timestamp\":\"1785211706219\", \"event_type\":\"price_change\"}","received_at":"2026-07-28T04:08:30.068615Z","schema_version":"clob-market-ws.price_change.v1","sequence":null,"server_hash":null,"server_timestamp":"1785211706219","session_id":"2d607381e3054cee91998cdf45a4231c","source":"clob_market_ws"},"received_at":"2026-07-28T04:08:30.068615Z","record_id":"c59f545e7c4ce8ae5fedfed7fe3a9fa93a9623c50ffd272ce4336964db4ec03d","schema_fingerprint":"4aa3821a28b0b7c2400bc59aba4bcc0a76e971dadd19610d3ad38c768e124dc7","schema_version":"edge-lab-recorder.raw.v1","sequence":null,"source":"clob_market_ws"}
{"event_at":"2026-07-28T04:08:26.223000Z","event_fingerprint":"9d8d6a81fcf69e249f515cf1e64cecc25e8db7977ebdc2f86485182e38e3556b","payload":{"connection_id":"f6725804f86a4c4eb588e4d5ed7db029","event_at":"2026-07-28T04:08:26.223000Z","event_type":"price_change","frame_hash":"2c5d0b8eb7d7629ddc38cb4e542016d4405d923c8bb6312ba97da518e9a7334c","frame_index":0,"kind":"data","monotonic_ns":313693139226458,"payload":{"event_type":"price_change","market":"0xd412ce774cfcf8dc9f71164aac78783978aac7b03871702a3b8a481bd9dc9688","price_changes":[{"asset_id":"107603864457683460275633293642179940881969192120168665300712204232021063124301","best_ask":"0.59","best_bid":"0.58","hash":"b9e20dfcf101f9e13514715975ce55b36ce11118","price":"0.63","side":"SELL","size":"179.26"},{"asset_id":"96600821790790307414914106093858868634329285205417149685270682748367152458577","best_ask":"0.42","best_bid":"0.41","hash":"fe26f346c203a092adc6e8e2879617799576d929","price":"0.37","side":"BUY","size":"179.26"}],"timestamp":"1785211706223"},"payload_hash":"270d3f561b7bb3d2ddf1aca5bcf27cf0ef7e0106618e4b49841f3a61d1274f02","raw_frame":"{\"market\":\"0xd412ce774cfcf8dc9f71164aac78783978aac7b03871702a3b8a481bd9dc9688\", \"price_changes\":[{\"asset_id\":\"107603864457683460275633293642179940881969192120168665300712204232021063124301\", \"price\":\"0.63\", \"size\":\"179.26\", \"side\":\"SELL\", \"hash\":\"b9e20dfcf101f9e13514715975ce55b36ce11118\", \"best_bid\":\"0.58\", \"best_ask\":\"0.59\"}, {\"asset_id\":\"96600821790790307414914106093858868634329285205417149685270682748367152458577\", \"price\":\"0.37\", \"size\":\"179.26\", \"side\":\"BUY\", \"hash\":\"fe26f346c203a092adc6e8e2879617799576d929\", \"best_bid\":\"0.41\", \"best_ask\":\"0.42\"}], \"timestamp\":\"1785211706223\", \"event_type\":\"price_change\"}","received_at":"2026-07-28T04:08:30.071629Z","schema_version":"clob-market-ws.price_change.v1","sequence":null,"server_hash":null,"server_timestamp":"1785211706223","session_id":"2d607381e3054cee91998cdf45a4231c","source":"clob_market_ws"},"received_at":"2026-07-28T04:08:30.071629Z","record_id":"5d9bf9a28e3330d2ec28d6e130afeb7f7d9be54d44d83e2eb625805442e74dfc","schema_fingerprint":"4aa3821a28b0b7c2400bc59aba4bcc0a76e971dadd19610d3ad38c768e124dc7","schema_version":"edge-lab-recorder.raw.v1","sequence":null,"source":"clob_market_ws"}
{"event_at":"2026-07-28T04:08:26.223000Z","event_fingerprint":"e65370393033c3a31a9691e558655f887e28714dfd944adcc92efe451b0c0060","payload":{"connection_id":"f6725804f86a4c4eb588e4d5ed7db029","event_at":"2026-07-28T04:08:26.223000Z","event_type":"price_change","frame_hash":"f53fdc2dfa4194a400652328efc30bcd17e0ba7b026f50fec7f969d63f3e8d5f","frame_index":0,"kind":"data","monotonic_ns":313693142241291,"payload":{"event_type":"price_change","market":"0xd412ce774cfcf8dc9f71164aac78783978aac7b03871702a3b8a481bd9dc9688","price_changes":[{"asset_id":"96600821790790307414914106093858868634329285205417149685270682748367152458577","best_ask":"0.42","best_bid":"0.41","hash":"14b0fd71e0e66aec4ad72298c87c333ec09a868e","price":"0.37","side":"BUY","size":"157.88"},{"asset_id":"107603864457683460275633293642179940881969192120168665300712204232021063124301","best_ask":"0.59","best_bid":"0.58","hash":"308fdb42855825450c1ed0924e545ca6199329e2","price":"0.63","side":"SELL","size":"157.88"}],"timestamp":"1785211706223"},"payload_hash":"651356177670add3edfbe81d51c86bf2b9ccd9d8fc138e283dbfb6c4282f4056","raw_frame":"{\"market\":\"0xd412ce774cfcf8dc9f71164aac78783978aac7b03871702a3b8a481bd9dc9688\", \"price_changes\":[{\"asset_id\":\"96600821790790307414914106093858868634329285205417149685270682748367152458577\", \"price\":\"0.37\", \"size\":\"157.88\", \"side\":\"BUY\", \"hash\":\"14b0fd71e0e66aec4ad72298c87c333ec09a868e\", \"best_bid\":\"0.41\", \"best_ask\":\"0.42\"}, {\"asset_id\":\"107603864457683460275633293642179940881969192120168665300712204232021063124301\", \"price\":\"0.63\", \"size\":\"157.88\", \"side\":\"SELL\", \"hash\":\"308fdb42855825450c1ed0924e545ca6199329e2\", \"best_bid\":\"0.58\", \"best_ask\":\"0.59\"}], \"timestamp\":\"1785211706223\", \"event_type\":\"price_change\"}","received_at":"2026-07-28T04:08:30.074643Z","schema_version":"clob-market-ws.price_change.v1","sequence":null,"server_hash":null,"server_timestamp":"1785211706223","session_id":"2d607381e3054cee91998cdf45a4231c","source":"clob_market_ws"},"received_at":"2026-07-28T04:08:30.074643Z","record_id":"3dda7f93af6d963cc4d261916d502e9e1d1a3e57428f1b03e30151d86bcd0484","schema_fingerprint":"4aa3821a28b0b7c2400bc59aba4bcc0a76e971dadd19610d3ad38c768e124dc7","schema_version":"edge-lab-recorder.raw.v1","sequence":null,"source":"clob_market_ws"}
{"event_at":"2026-07-28T04:08:26.224000Z","event_fingerprint":"7cc531e5a8dc637c04b89a4454eea71b76fec7a8e0b406be66e5d900a420dec2","payload":{"connection_id":"f6725804f86a4c4eb588e4d5ed7db029","event_at":"2026-07-28T04:08:26.224000Z","event_type":"price_change","frame_hash":"406ba66d800601581aabdee1a6da4e8928fad095ccd45ff4321adc3d3a168206","frame_index":0,"kind":"data","monotonic_ns":313693144570291,"payload":{"event_type":"price_change","market":"0xd412ce774cfcf8dc9f71164aac78783978aac7b03871702a3b8a481bd9dc9688","price_changes":[{"asset_id":"107603864457683460275633293642179940881969192120168665300712204232021063124301","best_ask":"0.59","best_bid":"0.58","hash":"669af4f5ce7402c4cc95146bd7e0c5b3d8f531f4","price":"0.59","side":"SELL","size":"36.28"},{"asset_id":"96600821790790307414914106093858868634329285205417149685270682748367152458577","best_ask":"0.42","best_bid":"0.41","hash":"82f5b20d4400e165d1013b29ac6f4ff2239c6aac","price":"0.41","side":"BUY","size":"36.28"}],"timestamp":"1785211706224"},"payload_hash":"1ea26652e7d742d9452330ec4e94d679fbe99814780268a202fc9741ab6f1233","raw_frame":"{\"market\":\"0xd412ce774cfcf8dc9f71164aac78783978aac7b03871702a3b8a481bd9dc9688\", \"price_changes\":[{\"asset_id\":\"107603864457683460275633293642179940881969192120168665300712204232021063124301\", \"price\":\"0.59\", \"size\":\"36.28\", \"side\":\"SELL\", \"hash\":\"669af4f5ce7402c4cc95146bd7e0c5b3d8f531f4\", \"best_bid\":\"0.58\", \"best_ask\":\"0.59\"}, {\"asset_id\":\"96600821790790307414914106093858868634329285205417149685270682748367152458577\", \"price\":\"0.41\", \"size\":\"36.28\", \"side\":\"BUY\", \"hash\":\"82f5b20d4400e165d1013b29ac6f4ff2239c6aac\", \"best_bid\":\"0.41\", \"best_ask\":\"0.42\"}], \"timestamp\":\"1785211706224\", \"event_type\":\"price_change\"}","received_at":"2026-07-28T04:08:30.076972Z","schema_version":"clob-market-ws.price_change.v1","sequence":null,"server_hash":null,"server_timestamp":"1785211706224","session_id":"2d607381e3054cee91998cdf45a4231c","source":"clob_market_ws"},"received_at":"2026-07-28T04:08:30.076972Z","record_id":"54bcef93436600e8389e1ae082a1405a2b6d48ddf4dce9e03d51b44066cd08fa","schema_fingerprint":"4aa3821a28b0b7c2400bc59aba4bcc0a76e971dadd19610d3ad38c768e124dc7","schema_version":"edge-lab-recorder.raw.v1","sequence":null,"source":"clob_market_ws"}
{"event_at":"2026-07-28T04:08:26.227000Z","event_fingerprint":"bd56a9e15fc18cba6074ac28d1b0a09ec798eeb4a4051ac4acfe89f9d0d4d9dc","payload":{"connection_id":"f6725804f86a4c4eb588e4d5ed7db029","event_at":"2026-07-28T04:08:26.227000Z","event_type":"price_change","frame_hash":"2bd1be58aa8f44521e53d97611c5d052cfc380444beb75a5ef0b1e4759390114","frame_index":0,"kind":"data","monotonic_ns":313693147561708,"payload":{"event_type":"price_change","market":"0xd412ce774cfcf8dc9f71164aac78783978aac7b03871702a3b8a481bd9dc9688","price_changes":[{"asset_id":"96600821790790307414914106093858868634329285205417149685270682748367152458577","best_ask":"0.42","best_bid":"0.41","hash":"08052623f024ca9c9d013fa98a9765cb2ec6a25b","price":"0.35","side":"BUY","size":"115.85"},{"asset_id":"107603864457683460275633293642179940881969192120168665300712204232021063124301","best_ask":"0.59","best_bid":"0.58","hash":"0890c6dfaa7a1562414bb155738c738b19ed31ac","price":"0.65","side":"SELL","size":"115.85"}],"timestamp":"1785211706227"},"payload_hash":"52276fa23cc01f06dc51b9c417b3a23003262819fe4dfe3dfa79da491a4477e8","raw_frame":"{\"market\":\"0xd412ce774cfcf8dc9f71164aac78783978aac7b03871702a3b8a481bd9dc9688\", \"price_changes\":[{\"asset_id\":\"96600821790790307414914106093858868634329285205417149685270682748367152458577\", \"price\":\"0.35\", \"size\":\"115.85\", \"side\":\"BUY\", \"hash\":\"08052623f024ca9c9d013fa98a9765cb2ec6a25b\", \"best_bid\":\"0.41\", \"best_ask\":\"0.42\"}, {\"asset_id\":\"107603864457683460275633293642179940881969192120168665300712204232021063124301\", \"price\":\"0.65\", \"size\":\"115.85\", \"side\":\"SELL\", \"hash\":\"0890c6dfaa7a1562414bb155738c738b19ed31ac\", \"best_bid\":\"0.58\", \"best_ask\":\"0.59\"}], \"timestamp\":\"1785211706227\", \"event_type\":\"price_change\"}","received_at":"2026-07-28T04:08:30.079961Z","schema_version":"clob-market-ws.price_change.v1","sequence":null,"server_hash":null,"server_timestamp":"1785211706227","session_id":"2d607381e3054cee91998cdf45a4231c","source":"clob_market_ws"},"received_at":"2026-07-28T04:08:30.079961Z","record_id":"834f5ae411971b7f955655ec5fe9f9f9f54e87a9b7807a09ee793ae9196de5eb","schema_fingerprint":"4aa3821a28b0b7c2400bc59aba4bcc0a76e971dadd19610d3ad38c768e124dc7","schema_version":"edge-lab-recorder.raw.v1","sequence":null,"source":"clob_market_ws"}
{"event_at":"2026-07-28T04:08:26.227000Z","event_fingerprint":"5e072e49b9b4f6bb22492455719a92aaf23ed271006fc10264fe10f70cbb391d","payload":{"connection_id":"f6725804f86a4c4eb588e4d5ed7db029","event_at":"2026-07-28T04:08:26.227000Z","event_type":"price_change","frame_hash":"709830a975709d2baeeadf0130bef3c0d696213816ea5b77e8347f629b2e05f7","frame_index":0,"kind":"data","monotonic_ns":313693151349791,"payload":{"event_type":"price_change","market":"0xd412ce774cfcf8dc9f71164aac78783978aac7b03871702a3b8a481bd9dc9688","price_changes":[{"asset_id":"96600821790790307414914106093858868634329285205417149685270682748367152458577","best_ask":"0.42","best_bid":"0.41","hash":"9c5b0fbca2df9f53f97cda23f8e4e5e217d3ee4d","price":"0.38","side":"BUY","size":"46.6"},{"asset_id":"107603864457683460275633293642179940881969192120168665300712204232021063124301","best_ask":"0.59","best_bid":"0.58","hash":"0505280b0b765c839955732487e376d91c5f4efa","price":"0.62","side":"SELL","size":"46.6"}],"timestamp":"1785211706227"},"payload_hash":"463c560f8bcfc11dc20c14f395b93954f3968c44a218362fae217944106913f8","raw_frame":"{\"market\":\"0xd412ce774cfcf8dc9f71164aac78783978aac7b03871702a3b8a481bd9dc9688\", \"price_changes\":[{\"asset_id\":\"96600821790790307414914106093858868634329285205417149685270682748367152458577\", \"price\":\"0.38\", \"size\":\"46.6\", \"side\":\"BUY\", \"hash\":\"9c5b0fbca2df9f53f97cda23f8e4e5e217d3ee4d\", \"best_bid\":\"0.41\", \"best_ask\":\"0.42\"}, {\"asset_id\":\"107603864457683460275633293642179940881969192120168665300712204232021063124301\", \"price\":\"0.62\", \"size\":\"46.6\", \"side\":\"SELL\", \"hash\":\"0505280b0b765c839955732487e376d91c5f4efa\", \"best_bid\":\"0.58\", \"best_ask\":\"0.59\"}], \"timestamp\":\"1785211706227\", \"event_type\":\"price_change\"}","received_at":"2026-07-28T04:08:30.083746Z","schema_version":"clob-market-ws.price_change.v1","sequence":null,"server_hash":null,"server_timestamp":"1785211706227","session_id":"2d607381e3054cee91998cdf45a4231c","source":"clob_market_ws"},"received_at":"2026-07-28T04:08:30.083746Z","record_id":"6f1d3174b03ae6953c7738a57474e8dcb6c38d6283ae201643a0280dc7dca606","schema_fingerprint":"4aa3821a28b0b7c2400bc59aba4bcc0a76e971dadd19610d3ad38c768e124dc7","schema_version":"edge-lab-recorder.raw.v1","sequence":null,"source":"clob_market_ws"}
{"event_at":"2026-07-28T04:08:26.228000Z","event_fingerprint":"522d7631c2e8cfcb8a0514ee62792b0a06c2008c43c1de66dcd256d4bdda53bb","payload":{"connection_id":"f6725804f86a4c4eb588e4d5ed7db029","event_at":"2026-07-28T04:08:26.228000Z","event_type":"price_change","frame_hash":"10e6564bd8801fad60ec009795d68c1ce2a74618ea486c8a58a3a30c9447d8ec","frame_index":0,"kind":"data","monotonic_ns":313693154490208,"payload":{"event_type":"price_change","market":"0xd412ce774cfcf8dc9f71164aac78783978aac7b03871702a3b8a481bd9dc9688","price_changes":[{"asset_id":"96600821790790307414914106093858868634329285205417149685270682748367152458577","best_ask":"0.42","best_bid":"0.41","hash":"770ac1ff6101e2d69e3076ff443bad5efa594ed3","price":"0.37","side":"BUY","size":"165.88"},{"asset_id":"107603864457683460275633293642179940881969192120168665300712204232021063124301","best_ask":"0.59","best_bid":"0.58","hash":"856f55f234db640ee954c93f28cea0be818b8c03","price":"0.63","side":"SELL","size":"165.88"}],"timestamp":"1785211706228"},"payload_hash":"e34a533249f742fc7588cedaedc4d32462560eb496e724e5a570c3f273ec665a","raw_frame":"{\"market\":\"0xd412ce774cfcf8dc9f71164aac78783978aac7b03871702a3b8a481bd9dc9688\", \"price_changes\":[{\"asset_id\":\"96600821790790307414914106093858868634329285205417149685270682748367152458577\", \"price\":\"0.37\", \"size\":\"165.88\", \"side\":\"BUY\", \"hash\":\"770ac1ff6101e2d69e3076ff443bad5efa594ed3\", \"best_bid\":\"0.41\", \"best_ask\":\"0.42\"}, {\"asset_id\":\"107603864457683460275633293642179940881969192120168665300712204232021063124301\", \"price\":\"0.63\", \"size\":\"165.88\", \"side\":\"SELL\", \"hash\":\"856f55f234db640ee954c93f28cea0be818b8c03\", \"best_bid\":\"0.58\", \"best_ask\":\"0.59\"}], \"timestamp\":\"1785211706228\", \"event_type\":\"price_change\"}","received_at":"2026-07-28T04:08:30.086885Z","schema_version":"clob-market-ws.price_change.v1","sequence":null,"server_hash":null,"server_timestamp":"1785211706228","session_id":"2d607381e3054cee91998cdf45a4231c","source":"clob_market_ws"},"received_at":"2026-07-28T04:08:30.086885Z","record_id":"a2a1e6b7821a400226bfa3a22a19d230b56b0be77b74205fd77f9ee05fe46ad3","schema_fingerprint":"4aa3821a28b0b7c2400bc59aba4bcc0a76e971dadd19610d3ad38c768e124dc7","schema_version":"edge-lab-recorder.raw.v1","sequence":null,"source":"clob_market_ws"}
{"event_at":"2026-07-28T04:08:26.237000Z","event_fingerprint":"8778b106df2712e957be95d567f86addc118626f9b5957a91799146642530b56","payload":{"connection_id":"f6725804f86a4c4eb588e4d5ed7db029","event_at":"2026-07-28T04:08:26.237000Z","event_type":"price_change","frame_hash":"90034846e6f63bdabcfa9d406afd40e52b91c927a128148e9f9f32e04bd90548","frame_index":0,"kind":"data","monotonic_ns":313693157561208,"payload":{"event_type":"price_change","market":"0xd412ce774cfcf8dc9f71164aac78783978aac7b03871702a3b8a481bd9dc9688","price_changes":[{"asset_id":"107603864457683460275633293642179940881969192120168665300712204232021063124301","best_ask":"0.59","best_bid":"0.58","hash":"4617b7566cbc8c69ddeb23884083628c81f0fd34","price":"0.01","side":"BUY","size":"5648.02"},{"asset_id":"96600821790790307414914106093858868634329285205417149685270682748367152458577","best_ask":"0.42","best_bid":"0.41","hash":"c0345b01308b4b4e7ab3feab45a8441969fa7c5b","price":"0.99","side":"SELL","size":"5648.02"}],"timestamp":"1785211706237"},"payload_hash":"3366e5b959e87aa909091165c36fc72b5989036abb4567f0b405292f57405ab4","raw_frame":"{\"market\":\"0xd412ce774cfcf8dc9f71164aac78783978aac7b03871702a3b8a481bd9dc9688\", \"price_changes\":[{\"asset_id\":\"107603864457683460275633293642179940881969192120168665300712204232021063124301\", \"price\":\"0.01\", \"size\":\"5648.02\", \"side\":\"BUY\", \"hash\":\"4617b7566cbc8c69ddeb23884083628c81f0fd34\", \"best_bid\":\"0.58\", \"best_ask\":\"0.59\"}, {\"asset_id\":\"96600821790790307414914106093858868634329285205417149685270682748367152458577\", \"price\":\"0.99\", \"size\":\"5648.02\", \"side\":\"SELL\", \"hash\":\"c0345b01308b4b4e7ab3feab45a8441969fa7c5b\", \"best_bid\":\"0.41\", \"best_ask\":\"0.42\"}], \"timestamp\":\"1785211706237\", \"event_type\":\"price_change\"}","received_at":"2026-07-28T04:08:30.089954Z","schema_version":"clob-market-ws.price_change.v1","sequence":null,"server_hash":null,"server_timestamp":"1785211706237","session_id":"2d607381e3054cee91998cdf45a4231c","source":"clob_market_ws"},"received_at":"2026-07-28T04:08:30.089954Z","record_id":"6cf115b5f0240a2dc8fc8a39a7523a6a55b676317d3decc4374c641a32783e9c","schema_fingerprint":"4aa3821a28b0b7c2400bc59aba4bcc0a76e971dadd19610d3ad38c768e124dc7","schema_version":"edge-lab-recorder.raw.v1","sequence":null,"source":"clob_market_ws"}
{"event_at":"2026-07-28T04:08:26.238000Z","event_fingerprint":"39379da7e002436da205cd018f8eb59ef5d8d16614b4c0e7b10e83dfe0aef3dc","payload":{"connection_id":"f6725804f86a4c4eb588e4d5ed7db029","event_at":"2026-07-28T04:08:26.238000Z","event_type":"price_change","frame_hash":"d5fc8cfe5e47d108738849077e0bdc8690da59d6b2bb0902c16ed425a87e6d00","frame_index":0,"kind":"data","monotonic_ns":313693160780041,"payload":{"event_type":"price_change","market":"0xd412ce774cfcf8dc9f71164aac78783978aac7b03871702a3b8a481bd9dc9688","price_changes":[{"asset_id":"96600821790790307414914106093858868634329285205417149685270682748367152458577","best_ask":"0.42","best_bid":"0.41","hash":"83abd77236ccd277823ddf7a3d0a1f84aee21380","price":"0.4","side":"BUY","size":"25.2"},{"asset_id":"107603864457683460275633293642179940881969192120168665300712204232021063124301","best_ask":"0.59","best_bid":"0.58","hash":"3dd53672bf3fb02aa465801fd333dce7f6df6fa7","price":"0.6","side":"SELL","size":"25.2"}],"timestamp":"1785211706238"},"payload_hash":"04b72f7fcece1f9a55024570c30ad706a762280c06140f81362e80607d20776e","raw_frame":"{\"market\":\"0xd412ce774cfcf8dc9f71164aac78783978aac7b03871702a3b8a481bd9dc9688\", \"price_changes\":[{\"asset_id\":\"96600821790790307414914106093858868634329285205417149685270682748367152458577\", \"price\":\"0.4\", \"size\":\"25.2\", \"side\":\"BUY\", \"hash\":\"83abd77236ccd277823ddf7a3d0a1f84aee21380\", \"best_bid\":\"0.41\", \"best_ask\":\"0.42\"}, {\"asset_id\":\"107603864457683460275633293642179940881969192120168665300712204232021063124301\", \"price\":\"0.6\", \"size\":\"25.2\", \"side\":\"SELL\", \"hash\":\"3dd53672bf3fb02aa465801fd333dce7f6df6fa7\", \"best_bid\":\"0.58\", \"best_ask\":\"0.59\"}], \"timestamp\":\"1785211706238\", \"event_type\":\"price_change\"}","received_at":"2026-07-28T04:08:30.093172Z","schema_version":"clob-market-ws.price_change.v1","sequence":null,"server_hash":null,"server_timestamp":"1785211706238","session_id":"2d607381e3054cee91998cdf45a4231c","source":"clob_market_ws"},"received_at":"2026-07-28T04:08:30.093172Z","record_id":"07bc48014068762d454d1d3171df37a3b5ee28ab9e09264c6eb282b14556392f","schema_fingerprint":"4aa3821a28b0b7c2400bc59aba4bcc0a76e971dadd19610d3ad38c768e124dc7","schema_version":"edge-lab-recorder.raw.v1","sequence":null,"source":"clob_market_ws"}
{"event_at":"2026-07-28T04:08:26.239000Z","event_fingerprint":"12f34622a0b1ec65bb08cb0ac3144f87caab00d60e450fb7528171755529869a","payload":{"connection_id":"f6725804f86a4c4eb588e4d5ed7db029","event_at":"2026-07-28T04:08:26.239000Z","event_type":"price_change","frame_hash":"c67133ac13ec1c75127cbca37e780bb18faa71b669f6ee193ff77ad7a5fb29b1","frame_index":0,"kind":"data","monotonic_ns":313693163829708,"payload":{"event_type":"price_change","market":"0xd412ce774cfcf8dc9f71164aac78783978aac7b03871702a3b8a481bd9dc9688","price_changes":[{"asset_id":"107603864457683460275633293642179940881969192120168665300712204232021063124301","best_ask":"0.59","best_bid":"0.58","hash":"c59eec549586ccf0492bac10134d87599751c62b","price":"0.41","side":"BUY","size":"22.77"},{"asset_id":"96600821790790307414914106093858868634329285205417149685270682748367152458577","best_ask":"0.42","best_bid":"0.41","hash":"d0b698e2fa16ce7e91ceea6d457fcaa32337aac0","price":"0.59","side":"SELL","size":"22.77"}],"timestamp":"1785211706239"},"payload_hash":"f1131c89dc7fff6ec05be5be835fb010cb7eeebb5939a2eacb6ef7965f4af8dc","raw_frame":"{\"market\":\"0xd412ce774cfcf8dc9f71164aac78783978aac7b03871702a3b8a481bd9dc9688\", \"price_changes\":[{\"asset_id\":\"107603864457683460275633293642179940881969192120168665300712204232021063124301\", \"price\":\"0.41\", \"size\":\"22.77\", \"side\":\"BUY\", \"hash\":\"c59eec549586ccf0492bac10134d87599751c62b\", \"best_bid\":\"0.58\", \"best_ask\":\"0.59\"}, {\"asset_id\":\"96600821790790307414914106093858868634329285205417149685270682748367152458577\", \"price\":\"0.59\", \"size\":\"22.77\", \"side\":\"SELL\", \"hash\":\"d0b698e2fa16ce7e91ceea6d457fcaa32337aac0\", \"best_bid\":\"0.41\", \"best_ask\":\"0.42\"}], \"timestamp\":\"1785211706239\", \"event_type\":\"price_change\"}","received_at":"2026-07-28T04:08:30.096221Z","schema_version":"clob-market-ws.price_change.v1","sequence":null,"server_hash":null,"server_timestamp":"1785211706239","session_id":"2d607381e3054cee91998cdf45a4231c","source":"clob_market_ws"},"received_at":"2026-07-28T04:08:30.096221Z","record_id":"8d02cb352b27b95242c033fea448a9dd5299567896bcb4b66ecff11066637b1e","schema_fingerprint":"4aa3821a28b0b7c2400bc59aba4bcc0a76e971dadd19610d3ad38c768e124dc7","schema_version":"edge-lab-recorder.raw.v1","sequence":null,"source":"clob_market_ws"}
{"event_at":"2026-07-28T04:08:26.239000Z","event_fingerprint":"e945606c8dd7b50b1f94b98c9c293367ee9812f6a7e9b27e661e567ef14658c1","payload":{"connection_id":"f6725804f86a4c4eb588e4d5ed7db029","event_at":"2026-07-28T04:08:26.239000Z","event_type":"price_change","frame_hash":"393f00770d3094f38e97fdb2a2174251bbf0dd1fe5dc7eb3f16b54bbed434e39","frame_index":0,"kind":"data","monotonic_ns":313693166850625,"payload":{"event_type":"price_change","market":"0xd412ce774cfcf8dc9f71164aac78783978aac7b03871702a3b8a481bd9dc9688","price_changes":[{"asset_id":"107603864457683460275633293642179940881969192120168665300712204232021063124301","best_ask":"0.59","best_bid":"0.58","hash":"c59eec549586ccf0492bac10134d87599751c62b","price":"0.4","side":"BUY","size":"61.5"},{"asset_id":"96600821790790307414914106093858868634329285205417149685270682748367152458577","best_ask":"0.42","best_bid":"0.41","hash":"d0b698e2fa16ce7e91ceea6d457fcaa32337aac0","price":"0.6","side":"SELL","size":"61.5"}],"timestamp":"1785211706239"},"payload_hash":"ae0154b6b17eace02dcea3214a3b8796d461f52a8df1aad5236102b166fe82d2","raw_frame":"{\"market\":\"0xd412ce774cfcf8dc9f71164aac78783978aac7b03871702a3b8a481bd9dc9688\", \"price_changes\":[{\"asset_id\":\"107603864457683460275633293642179940881969192120168665300712204232021063124301\", \"price\":\"0.4\", \"size\":\"61.5\", \"side\":\"BUY\", \"hash\":\"c59eec549586ccf0492bac10134d87599751c62b\", \"best_bid\":\"0.58\", \"best_ask\":\"0.59\"}, {\"asset_id\":\"96600821790790307414914106093858868634329285205417149685270682748367152458577\", \"price\":\"0.6\", \"size\":\"61.5\", \"side\":\"SELL\", \"hash\":\"d0b698e2fa16ce7e91ceea6d457fcaa32337aac0\", \"best_bid\":\"0.41\", \"best_ask\":\"0.42\"}], \"timestamp\":\"1785211706239\", \"event_type\":\"price_change\"}","received_at":"2026-07-28T04:08:30.099239Z","schema_version":"clob-market-ws.price_change.v1","sequence":null,"server_hash":null,"server_timestamp":"1785211706239","session_id":"2d607381e3054cee91998cdf45a4231c","source":"clob_market_ws"},"received_at":"2026-07-28T04:08:30.099239Z","record_id":"199af4f7a5fc4435304d8d8f76566f995c9704a040ee2e7048ec6dbacea75e71","schema_fingerprint":"4aa3821a28b0b7c2400bc59aba4bcc0a76e971dadd19610d3ad38c768e124dc7","schema_version":"edge-lab-recorder.raw.v1","sequence":null,"source":"clob_market_ws"}
{"event_at":"2026-07-28T04:08:26.239000Z","event_fingerprint":"1007a0a52017b0f34013748205689c95d3d34250c25b3e420c6c486bff08328f","payload":{"connection_id":"f6725804f86a4c4eb588e4d5ed7db029","event_at":"2026-07-28T04:08:26.239000Z","event_type":"price_change","frame_hash":"768da424dfddc8829a9ca5e08a7a05efe074eeb4cfb0d97b9a57a771a5a891a3","frame_index":0,"kind":"data","monotonic_ns":313693169967416,"payload":{"event_type":"price_change","market":"0xd412ce774cfcf8dc9f71164aac78783978aac7b03871702a3b8a481bd9dc9688","price_changes":[{"asset_id":"107603864457683460275633293642179940881969192120168665300712204232021063124301","best_ask":"0.59","best_bid":"0.58","hash":"c59eec549586ccf0492bac10134d87599751c62b","price":"0.39","side":"BUY","size":"17.6"},{"asset_id":"96600821790790307414914106093858868634329285205417149685270682748367152458577","best_ask":"0.42","best_bid":"0.41","hash":"d0b698e2fa16ce7e91ceea6d457fcaa32337aac0","price":"0.61","side":"SELL","size":"17.6"}],"timestamp":"1785211706239"},"payload_hash":"9dcedb191a75c9da10d19d5d9d1441f97b2c84a805e53ee1171b0a67feb7c0eb","raw_frame":"{\"market\":\"0xd412ce774cfcf8dc9f71164aac78783978aac7b03871702a3b8a481bd9dc9688\", \"price_changes\":[{\"asset_id\":\"107603864457683460275633293642179940881969192120168665300712204232021063124301\", \"price\":\"0.39\", \"size\":\"17.6\", \"side\":\"BUY\", \"hash\":\"c59eec549586ccf0492bac10134d87599751c62b\", \"best_bid\":\"0.58\", \"best_ask\":\"0.59\"}, {\"asset_id\":\"96600821790790307414914106093858868634329285205417149685270682748367152458577\", \"price\":\"0.61\", \"size\":\"17.6\", \"side\":\"SELL\", \"hash\":\"d0b698e2fa16ce7e91ceea6d457fcaa32337aac0\", \"best_bid\":\"0.41\", \"best_ask\":\"0.42\"}], \"timestamp\":\"1785211706239\", \"event_type\":\"price_change\"}","received_at":"2026-07-28T04:08:30.102356Z","schema_version":"clob-market-ws.price_change.v1","sequence":null,"server_hash":null,"server_timestamp":"1785211706239","session_id":"2d607381e3054cee91998cdf45a4231c","source":"clob_market_ws"},"received_at":"2026-07-28T04:08:30.102356Z","record_id":"1ec7f07da06317341b7dab2f57be3a0969db73be16eb7e9caf09997b209ce388","schema_fingerprint":"4aa3821a28b0b7c2400bc59aba4bcc0a76e971dadd19610d3ad38c768e124dc7","schema_version":"edge-lab-recorder.raw.v1","sequence":null,"source":"clob_market_ws"}
{"event_at":"2026-07-28T04:08:26.239000Z","event_fingerprint":"5e8e011b1897ed595a34c57fac55bb6b233854d3faea7fa919ad553335267692","payload":{"connection_id":"f6725804f86a4c4eb588e4d5ed7db029","event_at":"2026-07-28T04:08:26.239000Z","event_type":"price_change","frame_hash":"753c73304bd0e0f12481328ce436800384288a59802510ca61fa13b41693838d","frame_index":0,"kind":"data","monotonic_ns":313693172972833,"payload":{"event_type":"price_change","market":"0xd412ce774cfcf8dc9f71164aac78783978aac7b03871702a3b8a481bd9dc9688","price_changes":[{"asset_id":"96600821790790307414914106093858868634329285205417149685270682748367152458577","best_ask":"0.42","best_bid":"0.41","hash":"d0b698e2fa16ce7e91ceea6d457fcaa32337aac0","price":"0.34","side":"BUY","size":"111.98"},{"asset_id":"107603864457683460275633293642179940881969192120168665300712204232021063124301","best_ask":"0.59","best_bid":"0.58","hash":"c59eec549586ccf0492bac10134d87599751c62b","price":"0.66","side":"SELL","size":"111.98"}],"timestamp":"1785211706239"},"payload_hash":"2c0b1313af5edfccaf3e894fc7a1ebe79782425cc090bf8ac3a83c7667949630","raw_frame":"{\"market\":\"0xd412ce774cfcf8dc9f71164aac78783978aac7b03871702a3b8a481bd9dc9688\", \"price_changes\":[{\"asset_id\":\"96600821790790307414914106093858868634329285205417149685270682748367152458577\", \"price\":\"0.34\", \"size\":\"111.98\", \"side\":\"BUY\", \"hash\":\"d0b698e2fa16ce7e91ceea6d457fcaa32337aac0\", \"best_bid\":\"0.41\", \"best_ask\":\"0.42\"}, {\"asset_id\":\"107603864457683460275633293642179940881969192120168665300712204232021063124301\", \"price\":\"0.66\", \"size\":\"111.98\", \"side\":\"SELL\", \"hash\":\"c59eec549586ccf0492bac10134d87599751c62b\", \"best_bid\":\"0.58\", \"best_ask\":\"0.59\"}], \"timestamp\":\"1785211706239\", \"event_type\":\"price_change\"}","received_at":"2026-07-28T04:08:30.105360Z","schema_version":"clob-market-ws.price_change.v1","sequence":null,"server_hash":null,"server_timestamp":"1785211706239","session_id":"2d607381e3054cee91998cdf45a4231c","source":"clob_market_ws"},"received_at":"2026-07-28T04:08:30.105360Z","record_id":"a92a83088d6b7ee849d38e9a95cabad23181abdf57aa788a8a00ed0e27408dfb","schema_fingerprint":"4aa3821a28b0b7c2400bc59aba4bcc0a76e971dadd19610d3ad38c768e124dc7","schema_version":"edge-lab-recorder.raw.v1","sequence":null,"source":"clob_market_ws"}
{"event_at":"2026-07-28T04:08:26.239000Z","event_fingerprint":"e9fe743bd094453d73eca82c38138c4272bab7e3b48425a6d71f5d31caa1dcae","payload":{"connection_id":"f6725804f86a4c4eb588e4d5ed7db029","event_at":"2026-07-28T04:08:26.239000Z","event_type":"price_change","frame_hash":"5edee9bf96a7999ff6c59484edd34109a625196b3b08bed67ce61a59fcdcddb7","frame_index":0,"kind":"data","monotonic_ns":313693175989791,"payload":{"event_type":"price_change","market":"0xd412ce774cfcf8dc9f71164aac78783978aac7b03871702a3b8a481bd9dc9688","price_changes":[{"asset_id":"96600821790790307414914106093858868634329285205417149685270682748367152458577","best_ask":"0.42","best_bid":"0.41","hash":"d0b698e2fa16ce7e91ceea6d457fcaa32337aac0","price":"0.33","side":"BUY","size":"147.38"},{"asset_id":"107603864457683460275633293642179940881969192120168665300712204232021063124301","best_ask":"0.59","best_bid":"0.58","hash":"c59eec549586ccf0492bac10134d87599751c62b","price":"0.67","side":"SELL","size":"147.38"}],"timestamp":"1785211706239"},"payload_hash":"b0743a7221b8a34ecf0f7360c33b4dc824c7b6c59e4194f1a3eb47e815717bcc","raw_frame":"{\"market\":\"0xd412ce774cfcf8dc9f71164aac78783978aac7b03871702a3b8a481bd9dc9688\", \"price_changes\":[{\"asset_id\":\"96600821790790307414914106093858868634329285205417149685270682748367152458577\", \"price\":\"0.33\", \"size\":\"147.38\", \"side\":\"BUY\", \"hash\":\"d0b698e2fa16ce7e91ceea6d457fcaa32337aac0\", \"best_bid\":\"0.41\", \"best_ask\":\"0.42\"}, {\"asset_id\":\"107603864457683460275633293642179940881969192120168665300712204232021063124301\", \"price\":\"0.67\", \"size\":\"147.38\", \"side\":\"SELL\", \"hash\":\"c59eec549586ccf0492bac10134d87599751c62b\", \"best_bid\":\"0.58\", \"best_ask\":\"0.59\"}], \"timestamp\":\"1785211706239\", \"event_type\":\"price_change\"}","received_at":"2026-07-28T04:08:30.108374Z","schema_version":"clob-market-ws.price_change.v1","sequence":null,"server_hash":null,"server_timestamp":"1785211706239","session_id":"2d607381e3054cee91998cdf45a4231c","source":"clob_market_ws"},"received_at":"2026-07-28T04:08:30.108374Z","record_id":"dc28c102e9b642e93359770e7f7ad6339db0eb779ba90dbf5f5d6c096d77b447","schema_fingerprint":"4aa3821a28b0b7c2400bc59aba4bcc0a76e971dadd19610d3ad38c768e124dc7","schema_version":"edge-lab-recorder.raw.v1","sequence":null,"source":"clob_market_ws"}
{"event_at":"2026-07-28T04:08:26.240000Z","event_fingerprint":"da4b76bf1fdcfd78b1213a81c298a0f0ce1b840e94e41be3543ef746d33a743e","payload":{"connection_id":"f6725804f86a4c4eb588e4d5ed7db029","event_at":"2026-07-28T04:08:26.240000Z","event_type":"price_change","frame_hash":"2a0746ca6e350f3622a9d8683e28587b3fdee9fbf33d9bfa502c869ad3cba833","frame_index":0,"kind":"data","monotonic_ns":313693179040041,"payload":{"event_type":"price_change","market":"0xd412ce774cfcf8dc9f71164aac78783978aac7b03871702a3b8a481bd9dc9688","price_changes":[{"asset_id":"96600821790790307414914106093858868634329285205417149685270682748367152458577","best_ask":"0.42","best_bid":"0.41","hash":"836a011cd54f05391ea5fcfe660e1b3ce08b0dd7","price":"0.01","side":"BUY","size":"5603.02"},{"asset_id":"107603864457683460275633293642179940881969192120168665300712204232021063124301","best_ask":"0.59","best_bid":"0.58","hash":"f8d549d780e45e20ffd2af1b6ed3c6e1d42a72ef","price":"0.99","side":"SELL","size":"5603.02"}],"timestamp":"1785211706240"},"payload_hash":"ad4be590b5cdcf383aa98a4a176c00794d34dba025329a8745597c1175f48773","raw_frame":"{\"market\":\"0xd412ce774cfcf8dc9f71164aac78783978aac7b03871702a3b8a481bd9dc9688\", \"price_changes\":[{\"asset_id\":\"96600821790790307414914106093858868634329285205417149685270682748367152458577\", \"price\":\"0.01\", \"size\":\"5603.02\", \"side\":\"BUY\", \"hash\":\"836a011cd54f05391ea5fcfe660e1b3ce08b0dd7\", \"best_bid\":\"0.41\", \"best_ask\":\"0.42\"}, {\"asset_id\":\"107603864457683460275633293642179940881969192120168665300712204232021063124301\", \"price\":\"0.99\", \"size\":\"5603.02\", \"side\":\"SELL\", \"hash\":\"f8d549d780e45e20ffd2af1b6ed3c6e1d42a72ef\", \"best_bid\":\"0.58\", \"best_ask\":\"0.59\"}], \"timestamp\":\"1785211706240\", \"event_type\":\"price_change\"}","received_at":"2026-07-28T04:08:30.111423Z","schema_version":"clob-market-ws.price_change.v1","sequence":null,"server_hash":null,"server_timestamp":"1785211706240","session_id":"2d607381e3054cee91998cdf45a4231c","source":"clob_market_ws"},"received_at":"2026-07-28T04:08:30.111423Z","record_id":"02f500286748fbb04a3a25bfecfabfe780661624d9ec2463a32a23d6b893f2b5","schema_fingerprint":"4aa3821a28b0b7c2400bc59aba4bcc0a76e971dadd19610d3ad38c768e124dc7","schema_version":"edge-lab-recorder.raw.v1","sequence":null,"source":"clob_market_ws"}
{"event_at":"2026-07-28T04:08:26.240000Z","event_fingerprint":"82f4386156e89b7fc5c219cebd27d616fd1a65dadf511747b008009250b8ce90","payload":{"connection_id":"f6725804f86a4c4eb588e4d5ed7db029","event_at":"2026-07-28T04:08:26.240000Z","event_type":"price_change","frame_hash":"f2052f563e97d5bbe1f793920f9257bdd0614b7e417e61c680e36e908672de7e","frame_index":0,"kind":"data","monotonic_ns":313693182014666,"payload":{"event_type":"price_change","market":"0xd412ce774cfcf8dc9f71164aac78783978aac7b03871702a3b8a481bd9dc9688","price_changes":[{"asset_id":"107603864457683460275633293642179940881969192120168665300712204232021063124301","best_ask":"0.59","best_bid":"0.58","hash":"afbc16d707ee05f0541451d2494654db9af62b49","price":"0.63","side":"SELL","size":"144.88"},{"asset_id":"96600821790790307414914106093858868634329285205417149685270682748367152458577","best_ask":"0.42","best_bid":"0.41","hash":"e285982a416a416a5675929a4ee2c29aa5b1ffdd","price":"0.37","side":"BUY","size":"144.88"}],"timestamp":"1785211706240"},"payload_hash":"8bd3d0c73517fdc000920451bcf26212bbeb6d9821c63c26569f5e48e785ef29","raw_frame":"{\"market\":\"0xd412ce774cfcf8dc9f71164aac78783978aac7b03871702a3b8a481bd9dc9688\", \"price_changes\":[{\"asset_id\":\"107603864457683460275633293642179940881969192120168665300712204232021063124301\", \"price\":\"0.63\", \"size\":\"144.88\", \"side\":\"SELL\", \"hash\":\"afbc16d707ee05f0541451d2494654db9af62b49\", \"best_bid\":\"0.58\", \"best_ask\":\"0.59\"}, {\"asset_id\":\"96600821790790307414914106093858868634329285205417149685270682748367152458577\", \"price\":\"0.37\", \"size\":\"144.88\", \"side\":\"BUY\", \"hash\":\"e285982a416a416a5675929a4ee2c29aa5b1ffdd\", \"best_bid\":\"0.41\", \"best_ask\":\"0.42\"}], \"timestamp\":\"1785211706240\", \"event_type\":\"price_change\"}","received_at":"2026-07-28T04:08:30.114403Z","schema_version":"clob-market-ws.price_change.v1","sequence":null,"server_hash":null,"server_timestamp":"1785211706240","session_id":"2d607381e3054cee91998cdf45a4231c","source":"clob_market_ws"},"received_at":"2026-07-28T04:08:30.114403Z","record_id":"4240e001108d752e97fe829a4bb3e578fdc39ba773c7ed87b03004940f6e42bf","schema_fingerprint":"4aa3821a28b0b7c2400bc59aba4bcc0a76e971dadd19610d3ad38c768e124dc7","schema_version":"edge-lab-recorder.raw.v1","sequence":null,"source":"clob_market_ws"}
{"event_at":"2026-07-28T04:08:26.241000Z","event_fingerprint":"41e609e05f3136bab1a07bb6afbdcd09f1d4d27edbfc16c350534b3677f8dfd9","payload":{"connection_id":"f6725804f86a4c4eb588e4d5ed7db029","event_at":"2026-07-28T04:08:26.241000Z","event_type":"price_change","frame_hash":"b3116014168ae45231745a15657e8c93d85eda86d0a818859f143d3a40300bb5","frame_index":0,"kind":"data","monotonic_ns":313693184179750,"payload":{"event_type":"price_change","market":"0xd412ce774cfcf8dc9f71164aac78783978aac7b03871702a3b8a481bd9dc9688","price_changes":[{"asset_id":"96600821790790307414914106093858868634329285205417149685270682748367152458577","best_ask":"0.42","best_bid":"0.41","hash":"8c90f78abdded2e1cee0f7a98c3ecc3dd1c24bc3","price":"0.37","side":"BUY","size":"119.88"},{"asset_id":"107603864457683460275633293642179940881969192120168665300712204232021063124301","best_ask":"0.59","best_bid":"0.58","hash":"21f0ec81714649e4f9d029e926761c0002f04f17","price":"0.63","side":"SELL","size":"119.88"}],"timestamp":"1785211706241"},"payload_hash":"fee72830262af5dbe239b97594fe486df3c7e7bca52cfe4d7731c32f945e7dc0","raw_frame":"{\"market\":\"0xd412ce774cfcf8dc9f71164aac78783978aac7b03871702a3b8a481bd9dc9688\", \"price_changes\":[{\"asset_id\":\"96600821790790307414914106093858868634329285205417149685270682748367152458577\", \"price\":\"0.37\", \"size\":\"119.88\", \"side\":\"BUY\", \"hash\":\"8c90f78abdded2e1cee0f7a98c3ecc3dd1c24bc3\", \"best_bid\":\"0.41\", \"best_ask\":\"0.42\"}, {\"asset_id\":\"107603864457683460275633293642179940881969192120168665300712204232021063124301\", \"price\":\"0.63\", \"size\":\"119.88\", \"side\":\"SELL\", \"hash\":\"21f0ec81714649e4f9d029e926761c0002f04f17\", \"best_bid\":\"0.58\", \"best_ask\":\"0.59\"}], \"timestamp\":\"1785211706241\", \"event_type\":\"price_change\"}","received_at":"2026-07-28T04:08:30.116560Z","schema_version":"clob-market-ws.price_change.v1","sequence":null,"server_hash":null,"server_timestamp":"1785211706241","session_id":"2d607381e3054cee91998cdf45a4231c","source":"clob_market_ws"},"received_at":"2026-07-28T04:08:30.116560Z","record_id":"2f9d4ce3c19bc80adf2be7452310df06741fbca3d1e8665e962552ca17976830","schema_fingerprint":"4aa3821a28b0b7c2400bc59aba4bcc0a76e971dadd19610d3ad38c768e124dc7","schema_version":"edge-lab-recorder.raw.v1","sequence":null,"source":"clob_market_ws"}
{"event_at":"2026-07-28T04:08:26.247000Z","event_fingerprint":"7c1167ab558a3523290a1820287d9f3f5f3dc20fc43f78ced98912459e48e1d7","payload":{"connection_id":"f6725804f86a4c4eb588e4d5ed7db029","event_at":"2026-07-28T04:08:26.247000Z","event_type":"price_change","frame_hash":"2b46c9db4fe63604a17aa94bc12a456c8bc97e7835d1c7ae33880709d8c1809f","frame_index":0,"kind":"data","monotonic_ns":313693187202958,"payload":{"event_type":"price_change","market":"0xd412ce774cfcf8dc9f71164aac78783978aac7b03871702a3b8a481bd9dc9688","price_changes":[{"asset_id":"96600821790790307414914106093858868634329285205417149685270682748367152458577","best_ask":"0.42","best_bid":"0.41","hash":"bd6b5537b972e6e85635288ded800806e8e21685","price":"0.39","side":"BUY","size":"21"},{"asset_id":"107603864457683460275633293642179940881969192120168665300712204232021063124301","best_ask":"0.59","best_bid":"0.58","hash":"312231cb34157785fb4c8b33981c88c5c9668bf5","price":"0.61","side":"SELL","size":"21"}],"timestamp":"1785211706247"},"payload_hash":"b1e04f4a6a90f03714a8ba337740e369a507f476961a22fb2461b613dd707ca0","raw_frame":"{\"market\":\"0xd412ce774cfcf8dc9f71164aac78783978aac7b03871702a3b8a481bd9dc9688\", \"price_changes\":[{\"asset_id\":\"96600821790790307414914106093858868634329285205417149685270682748367152458577\", \"price\":\"0.39\", \"size\":\"21\", \"side\":\"BUY\", \"hash\":\"bd6b5537b972e6e85635288ded800806e8e21685\", \"best_bid\":\"0.41\", \"best_ask\":\"0.42\"}, {\"asset_id\":\"107603864457683460275633293642179940881969192120168665300712204232021063124301\", \"price\":\"0.61\", \"size\":\"21\", \"side\":\"SELL\", \"hash\":\"312231cb34157785fb4c8b33981c88c5c9668bf5\", \"best_bid\":\"0.58\", \"best_ask\":\"0.59\"}], \"timestamp\":\"1785211706247\", \"event_type\":\"price_change\"}","received_at":"2026-07-28T04:08:30.119583Z","schema_version":"clob-market-ws.price_change.v1","sequence":null,"server_hash":null,"server_timestamp":"1785211706247","session_id":"2d607381e3054cee91998cdf45a4231c","source":"clob_market_ws"},"received_at":"2026-07-28T04:08:30.119583Z","record_id":"7c9082f17e7eff7f2c68da0daad611ec6dc8a0b984f42e3606e91b7a98edc9f6","schema_fingerprint":"4aa3821a28b0b7c2400bc59aba4bcc0a76e971dadd19610d3ad38c768e124dc7","schema_version":"edge-lab-recorder.raw.v1","sequence":null,"source":"clob_market_ws"}
{"event_at":"2026-07-28T04:08:26.248000Z","event_fingerprint":"5aa342d9b335f5296c70c7c7911c67606f1d7a85059f4c0d6423f82d5138df9b","payload":{"connection_id":"f6725804f86a4c4eb588e4d5ed7db029","event_at":"2026-07-28T04:08:26.248000Z","event_type":"price_change","frame_hash":"efbb6c7984c560628c1967ef03fb2573d0a46c4c907a593480aba30ec864abd3","frame_index":0,"kind":"data","monotonic_ns":313693190269291,"payload":{"event_type":"price_change","market":"0xd412ce774cfcf8dc9f71164aac78783978aac7b03871702a3b8a481bd9dc9688","price_changes":[{"asset_id":"107603864457683460275633293642179940881969192120168665300712204232021063124301","best_ask":"0.59","best_bid":"0.58","hash":"17f8b8bc8c8158e690e30ea6689ef1fcf1f99e80","price":"0.32","side":"BUY","size":"138.96"},{"asset_id":"96600821790790307414914106093858868634329285205417149685270682748367152458577","best_ask":"0.42","best_bid":"0.41","hash":"cd98b61dd234aca83ce7efe60b2584a702ddec85","price":"0.68","side":"SELL","size":"138.96"}],"timestamp":"1785211706248"},"payload_hash":"3a5eb8ac10355ddb497c0b3cd2b59c967d6bcb8756cbfdcb2d8a89f882684867","raw_frame":"{\"market\":\"0xd412ce774cfcf8dc9f71164aac78783978aac7b03871702a3b8a481bd9dc9688\", \"price_changes\":[{\"asset_id\":\"107603864457683460275633293642179940881969192120168665300712204232021063124301\", \"price\":\"0.32\", \"size\":\"138.96\", \"side\":\"BUY\", \"hash\":\"17f8b8bc8c8158e690e30ea6689ef1fcf1f99e80\", \"best_bid\":\"0.58\", \"best_ask\":\"0.59\"}, {\"asset_id\":\"96600821790790307414914106093858868634329285205417149685270682748367152458577\", \"price\":\"0.68\", \"size\":\"138.96\", \"side\":\"SELL\", \"hash\":\"cd98b61dd234aca83ce7efe60b2584a702ddec85\", \"best_bid\":\"0.41\", \"best_ask\":\"0.42\"}], \"timestamp\":\"1785211706248\", \"event_type\":\"price_change\"}","received_at":"2026-07-28T04:08:30.122648Z","schema_version":"clob-market-ws.price_change.v1","sequence":null,"server_hash":null,"server_timestamp":"1785211706248","session_id":"2d607381e3054cee91998cdf45a4231c","source":"clob_market_ws"},"received_at":"2026-07-28T04:08:30.122648Z","record_id":"e92c8c34658866c32b01789a300e2f92c0217a64107cb0bb6e40b3f0dd2fef1c","schema_fingerprint":"4aa3821a28b0b7c2400bc59aba4bcc0a76e971dadd19610d3ad38c768e124dc7","schema_version":"edge-lab-recorder.raw.v1","sequence":null,"source":"clob_market_ws"}
