{"event_at":"2026-07-28T04:02:56.101000Z","event_fingerprint":"d3b62d204d27d4138f8714592abcfb40d5c6280b2236e7a1034b493d07ea3619","payload":{"connection_id":"f6725804f86a4c4eb588e4d5ed7db029","event_at":"2026-07-28T04:02:56.101000Z","event_type":"best_bid_ask","frame_hash":"f9543c6e957f9d9ec19a09db1c3b7a51e971ab82bb255c1379bb0147e267a085","frame_index":0,"kind":"data","monotonic_ns":313362852318791,"payload":{"asset_id":"96600821790790307414914106093858868634329285205417149685270682748367152458577","best_ask":"0.43","best_bid":"0.41","event_type":"best_bid_ask","market":"0xd412ce774cfcf8dc9f71164aac78783978aac7b03871702a3b8a481bd9dc9688","spread":"0.02","timestamp":"1785211376101"},"payload_hash":"04ae08c5bf479031a3d172a9b0ba9a96fabd9a6d98ba88d41e7ab19bb9bc4dfd","raw_frame":"{\"market\":\"0xd412ce774cfcf8dc9f71164aac78783978aac7b03871702a3b8a481bd9dc9688\", \"asset_id\":\"96600821790790307414914106093858868634329285205417149685270682748367152458577\", \"best_bid\":\"0.41\", \"best_ask\":\"0.43\", \"spread\":\"0.02\", \"timestamp\":\"1785211376101\", \"event_type\":\"best_bid_ask\"}","received_at":"2026-07-28T04:02:59.803071Z","schema_version":"clob-market-ws.best_bid_ask.v1","sequence":null,"server_hash":null,"server_timestamp":"1785211376101","session_id":"2d607381e3054cee91998cdf45a4231c","source":"clob_market_ws"},"received_at":"2026-07-28T04:02:59.803071Z","record_id":"f8896700ae8d7140900d02849f82a010f0c9d4cffa7f60bf292b573d1324e162","schema_fingerprint":"8488399f31b0337811b13b266be932db7062827c2470b78bd8e9e99bab51d17d","schema_version":"edge-lab-recorder.raw.v1","sequence":null,"source":"clob_market_ws"}
{"event_at":"2026-07-28T04:02:56.101000Z","event_fingerprint":"dfa6c106e6986f0607e6eb9d00cb9fab6de3e52520612e04d2ffaf3f0fbfa687","payload":{"connection_id":"f6725804f86a4c4eb588e4d5ed7db029","event_at":"2026-07-28T04:02:56.101000Z","event_type":"price_change","frame_hash":"e11a248a0a46caa0688860b1c502ccf7dca907dbc739cb4c6d8dce0dbfea10da","frame_index":0,"kind":"data","monotonic_ns":313362854085458,"payload":{"event_type":"price_change","market":"0xd412ce774cfcf8dc9f71164aac78783978aac7b03871702a3b8a481bd9dc9688","price_changes":[{"asset_id":"96600821790790307414914106093858868634329285205417149685270682748367152458577","best_ask":"0.43","best_bid":"0.41","hash":"80f4add9fed50cddd1595d4cceb6a1bd61008adb","price":"0.42","side":"SELL","size":"0"},{"asset_id":"107603864457683460275633293642179940881969192120168665300712204232021063124301","best_ask":"0.59","best_bid":"0.57","hash":"7c9a610526ce8e9e6e67e5db8b184c49cbb645a7","price":"0.58","side":"BUY","size":"0"}],"timestamp":"1785211376101"},"payload_hash":"89858f54be64b443bbda3538684c7b6688ee4e20b4f7f66cf8bc4b9fad64bf97","raw_frame":"{\"market\":\"0xd412ce774cfcf8dc9f71164aac78783978aac7b03871702a3b8a481bd9dc9688\", \"price_changes\":[{\"asset_id\":\"96600821790790307414914106093858868634329285205417149685270682748367152458577\", \"price\":\"0.42\", \"size\":\"0\", \"side\":\"SELL\", \"hash\":\"80f4add9fed50cddd1595d4cceb6a1bd61008adb\", \"best_bid\":\"0.41\", \"best_ask\":\"0.43\"}, {\"asset_id\":\"107603864457683460275633293642179940881969192120168665300712204232021063124301\", \"price\":\"0.58\", \"size\":\"0\", \"side\":\"BUY\", \"hash\":\"7c9a610526ce8e9e6e67e5db8b184c49cbb645a7\", \"best_bid\":\"0.57\", \"best_ask\":\"0.59\"}], \"timestamp\":\"1785211376101\", \"event_type\":\"price_change\"}","received_at":"2026-07-28T04:02:59.804842Z","schema_version":"clob-market-ws.price_change.v1","sequence":null,"server_hash":null,"server_timestamp":"1785211376101","session_id":"2d607381e3054cee91998cdf45a4231c","source":"clob_market_ws"},"received_at":"2026-07-28T04:02:59.804842Z","record_id":"60235975319dacdc757e2fd41eef754ce9ead58f9c7f2b404d72e209d00e2110","schema_fingerprint":"4aa3821a28b0b7c2400bc59aba4bcc0a76e971dadd19610d3ad38c768e124dc7","schema_version":"edge-lab-recorder.raw.v1","sequence":null,"source":"clob_market_ws"}
{"event_at":"2026-07-28T04:02:56.102000Z","event_fingerprint":"73fa06777b2e20e6ce3d119440de79b76a67baa278d4e43acd87d7f35898972e","payload":{"connection_id":"f6725804f86a4c4eb588e4d5ed7db029","event_at":"2026-07-28T04:02:56.102000Z","event_type":"price_change","frame_hash":"74bd40813ea2d2cc7402a22488c981e941355ec37c8fac6e25def80c3efd949b","frame_index":0,"kind":"data","monotonic_ns":313362855607291,"payload":{"event_type":"price_change","market":"0xd412ce774cfcf8dc9f71164aac78783978aac7b03871702a3b8a481bd9dc9688","price_changes":[{"asset_id":"96600821790790307414914106093858868634329285205417149685270682748367152458577","best_ask":"0.43","best_bid":"0.41","hash":"38a68b64e7b3ce15d0770a44d9898d866094400b","price":"0.44","side":"SELL","size":"6"},{"asset_id":"107603864457683460275633293642179940881969192120168665300712204232021063124301","best_ask":"0.59","best_bid":"0.57","hash":"615ca81955ad63cea90e60f4420a6ef0e9b48937","price":"0.56","side":"BUY","size":"6"}],"timestamp":"1785211376102"},"payload_hash":"532a7db6c44a0b951f373abe475c5c9615e0d68583c273b404db2dcd78f5e92b","raw_frame":"{\"market\":\"0xd412ce774cfcf8dc9f71164aac78783978aac7b03871702a3b8a481bd9dc9688\", \"price_changes\":[{\"asset_id\":\"96600821790790307414914106093858868634329285205417149685270682748367152458577\", \"price\":\"0.44\", \"size\":\"6\", \"side\":\"SELL\", \"hash\":\"38a68b64e7b3ce15d0770a44d9898d866094400b\", \"best_bid\":\"0.41\", \"best_ask\":\"0.43\"}, {\"asset_id\":\"107603864457683460275633293642179940881969192120168665300712204232021063124301\", \"price\":\"0.56\", \"size\":\"6\", \"side\":\"BUY\", \"hash\":\"615ca81955ad63cea90e60f4420a6ef0e9b48937\", \"best_bid\":\"0.57\", \"best_ask\":\"0.59\"}], \"timestamp\":\"1785211376102\", \"event_type\":\"price_change\"}","received_at":"2026-07-28T04:02:59.806363Z","schema_version":"clob-market-ws.price_change.v1","sequence":null,"server_hash":null,"server_timestamp":"1785211376102","session_id":"2d607381e3054cee91998cdf45a4231c","source":"clob_market_ws"},"received_at":"2026-07-28T04:02:59.806363Z","record_id":"bcc528b64395be0407e307b928cf8eb3e8a36773f75c8c562830787548ff5eb8","schema_fingerprint":"4aa3821a28b0b7c2400bc59aba4bcc0a76e971dadd19610d3ad38c768e124dc7","schema_version":"edge-lab-recorder.raw.v1","sequence":null,"source":"clob_market_ws"}
{"event_at":"2026-07-28T04:02:56.103000Z","event_fingerprint":"316f73b40c332fb1ada2e744badd6b0245b5e9e8e34ff2f1eb8eee27a4001337","payload":{"connection_id":"f6725804f86a4c4eb588e4d5ed7db029","event_at":"2026-07-28T04:02:56.103000Z","event_type":"price_change","frame_hash":"36abf070c38af4a33ef8f727def0792cf2f4671a814b45f3c3a962fedffb8520","frame_index":0,"kind":"data","monotonic_ns":313362857160791,"payload":{"event_type":"price_change","market":"0xd412ce774cfcf8dc9f71164aac78783978aac7b03871702a3b8a481bd9dc9688","price_changes":[{"asset_id":"96600821790790307414914106093858868634329285205417149685270682748367152458577","best_ask":"0.43","best_bid":"0.41","hash":"a57e980382f53f5940ba47cf3d51f4396dc9371e","price":"0.22","side":"BUY","size":"176.01"},{"asset_id":"107603864457683460275633293642179940881969192120168665300712204232021063124301","best_ask":"0.59","best_bid":"0.57","hash":"c59e8333bdce6a4d7d927ea0d1c7a7e15980f74f","price":"0.78","side":"SELL","size":"176.01"}],"timestamp":"1785211376103"},"payload_hash":"5bbf8c169f1e296d791c0b330b1931dc94b752ec8518d41aaccd17f78d8ede62","raw_frame":"{\"market\":\"0xd412ce774cfcf8dc9f71164aac78783978aac7b03871702a3b8a481bd9dc9688\", \"price_changes\":[{\"asset_id\":\"96600821790790307414914106093858868634329285205417149685270682748367152458577\", \"price\":\"0.22\", \"size\":\"176.01\", \"side\":\"BUY\", \"hash\":\"a57e980382f53f5940ba47cf3d51f4396dc9371e\", \"best_bid\":\"0.41\", \"best_ask\":\"0.43\"}, {\"asset_id\":\"107603864457683460275633293642179940881969192120168665300712204232021063124301\", \"price\":\"0.78\", \"size\":\"176.01\", \"side\":\"SELL\", \"hash\":\"c59e8333bdce6a4d7d927ea0d1c7a7e15980f74f\", \"best_bid\":\"0.57\", \"best_ask\":\"0.59\"}], \"timestamp\":\"1785211376103\", \"event_type\":\"price_change\"}","received_at":"2026-07-28T04:02:59.807918Z","schema_version":"clob-market-ws.price_change.v1","sequence":null,"server_hash":null,"server_timestamp":"1785211376103","session_id":"2d607381e3054cee91998cdf45a4231c","source":"clob_market_ws"},"received_at":"2026-07-28T04:02:59.807918Z","record_id":"76835f4e0e14a840701195cb1786a70251728f480e2c59edbbec47b94711d34d","schema_fingerprint":"4aa3821a28b0b7c2400bc59aba4bcc0a76e971dadd19610d3ad38c768e124dc7","schema_version":"edge-lab-recorder.raw.v1","sequence":null,"source":"clob_market_ws"}
{"event_at":"2026-07-28T04:02:56.105000Z","event_fingerprint":"cec0f2f4fd54cc2cea55c4fb5e2f72d14805e50a8c4fa9068dec19e9df02538a","payload":{"connection_id":"f6725804f86a4c4eb588e4d5ed7db029","event_at":"2026-07-28T04:02:56.105000Z","event_type":"price_change","frame_hash":"9c20b7bf045df8f2e7e04decf5d15fa730c909b433d4fa3955240f74035789de","frame_index":0,"kind":"data","monotonic_ns":313362858658083,"payload":{"event_type":"price_change","market":"0xd412ce774cfcf8dc9f71164aac78783978aac7b03871702a3b8a481bd9dc9688","price_changes":[{"asset_id":"96600821790790307414914106093858868634329285205417149685270682748367152458577","best_ask":"0.43","best_bid":"0.41","hash":"9ce407b563f45d72a0bde6f94e4befeac3fa767b","price":"0.41","side":"BUY","size":"81.88"},{"asset_id":"107603864457683460275633293642179940881969192120168665300712204232021063124301","best_ask":"0.59","best_bid":"0.57","hash":"3ced682b16b3df9491a199394c08dba0758454f3","price":"0.59","side":"SELL","size":"81.88"}],"timestamp":"1785211376105"},"payload_hash":"b34e023036c78dcaaf450d9e39f2989e1399fe10cb4ace9db43881f194906e72","raw_frame":"{\"market\":\"0xd412ce774cfcf8dc9f71164aac78783978aac7b03871702a3b8a481bd9dc9688\", \"price_changes\":[{\"asset_id\":\"96600821790790307414914106093858868634329285205417149685270682748367152458577\", \"price\":\"0.41\", \"size\":\"81.88\", \"side\":\"BUY\", \"hash\":\"9ce407b563f45d72a0bde6f94e4befeac3fa767b\", \"best_bid\":\"0.41\", \"best_ask\":\"0.43\"}, {\"asset_id\":\"107603864457683460275633293642179940881969192120168665300712204232021063124301\", \"price\":\"0.59\", \"size\":\"81.88\", \"side\":\"SELL\", \"hash\":\"3ced682b16b3df9491a199394c08dba0758454f3\", \"best_bid\":\"0.57\", \"best_ask\":\"0.59\"}], \"timestamp\":\"1785211376105\", \"event_type\":\"price_change\"}","received_at":"2026-07-28T04:02:59.809415Z","schema_version":"clob-market-ws.price_change.v1","sequence":null,"server_hash":null,"server_timestamp":"1785211376105","session_id":"2d607381e3054cee91998cdf45a4231c","source":"clob_market_ws"},"received_at":"2026-07-28T04:02:59.809415Z","record_id":"183854290257e2df96049a27a4245152332926057c0673aedab78f2b51d43e64","schema_fingerprint":"4aa3821a28b0b7c2400bc59aba4bcc0a76e971dadd19610d3ad38c768e124dc7","schema_version":"edge-lab-recorder.raw.v1","sequence":null,"source":"clob_market_ws"}
{"event_at":"2026-07-28T04:02:56.106000Z","event_fingerprint":"75ae9a3ee43728626a2ef30040c69fcc61bf3f7dec1028d7d0bd62dcd4a58833","payload":{"connection_id":"f6725804f86a4c4eb588e4d5ed7db029","event_at":"2026-07-28T04:02:56.106000Z","event_type":"best_bid_ask","frame_hash":"528d39469d4bee5db33ea1ece00b57403a6dc09b008e5879353e97f3c1cdf7db","frame_index":0,"kind":"data","monotonic_ns":313362860153125,"payload":{"asset_id":"107603864457683460275633293642179940881969192120168665300712204232021063124301","best_ask":"0.58","best_bid":"0.57","event_type":"best_bid_ask","market":"0xd412ce774cfcf8dc9f71164aac78783978aac7b03871702a3b8a481bd9dc9688","spread":"0.01","timestamp":"1785211376106"},"payload_hash":"db638e635da9f0cc0992c340eb0bb3c67ba739b164e4909491423af475f57b0f","raw_frame":"{\"market\":\"0xd412ce774cfcf8dc9f71164aac78783978aac7b03871702a3b8a481bd9dc9688\", \"asset_id\":\"107603864457683460275633293642179940881969192120168665300712204232021063124301\", \"best_bid\":\"0.57\", \"best_ask\":\"0.58\", \"spread\":\"0.01\", \"timestamp\":\"1785211376106\", \"event_type\":\"best_bid_ask\"}","received_at":"2026-07-28T04:02:59.810911Z","schema_version":"clob-market-ws.best_bid_ask.v1","sequence":null,"server_hash":null,"server_timestamp":"1785211376106","session_id":"2d607381e3054cee91998cdf45a4231c","source":"clob_market_ws"},"received_at":"2026-07-28T04:02:59.810911Z","record_id":"747de9a45d02790e61e28ec33081de904307ecf16473f027222395f0b6ea3af8","schema_fingerprint":"8488399f31b0337811b13b266be932db7062827c2470b78bd8e9e99bab51d17d","schema_version":"edge-lab-recorder.raw.v1","sequence":null,"source":"clob_market_ws"}
{"event_at":"2026-07-28T04:02:56.106000Z","event_fingerprint":"69bf8789215aa56fca9f9e0584031c0faebcf93291c5c4cdfa91b5f6252b0a09","payload":{"connection_id":"f6725804f86a4c4eb588e4d5ed7db029","event_at":"2026-07-28T04:02:56.106000Z","event_type":"best_bid_ask","frame_hash":"fd24afb52083b1a1ead263c12993661f695228b42d10c5231ca35b1d66c3adf8","frame_index":0,"kind":"data","monotonic_ns":313362861240208,"payload":{"asset_id":"96600821790790307414914106093858868634329285205417149685270682748367152458577","best_ask":"0.43","best_bid":"0.42","event_type":"best_bid_ask","market":"0xd412ce774cfcf8dc9f71164aac78783978aac7b03871702a3b8a481bd9dc9688","spread":"0.01","timestamp":"1785211376106"},"payload_hash":"03e7e3e25c01410f2ca89f7905a55ef34124358dc32d278024111195ddf7fd5f","raw_frame":"{\"market\":\"0xd412ce774cfcf8dc9f71164aac78783978aac7b03871702a3b8a481bd9dc9688\", \"asset_id\":\"96600821790790307414914106093858868634329285205417149685270682748367152458577\", \"best_bid\":\"0.42\", \"best_ask\":\"0.43\", \"spread\":\"0.01\", \"timestamp\":\"1785211376106\", \"event_type\":\"best_bid_ask\"}","received_at":"2026-07-28T04:02:59.811996Z","schema_version":"clob-market-ws.best_bid_ask.v1","sequence":null,"server_hash":null,"server_timestamp":"1785211376106","session_id":"2d607381e3054cee91998cdf45a4231c","source":"clob_market_ws"},"received_at":"2026-07-28T04:02:59.811996Z","record_id":"76521f2f7b2e663ad98881066665875208b9148df7b1413b926892ccaf690a92","schema_fingerprint":"8488399f31b0337811b13b266be932db7062827c2470b78bd8e9e99bab51d17d","schema_version":"edge-lab-recorder.raw.v1","sequence":null,"source":"clob_market_ws"}
{"event_at":"2026-07-28T04:02:56.106000Z","event_fingerprint":"5acafcf792bac82e711153395169ce1c29d129c74ea24f35639aad64f9af4c10","payload":{"connection_id":"f6725804f86a4c4eb588e4d5ed7db029","event_at":"2026-07-28T04:02:56.106000Z","event_type":"price_change","frame_hash":"621fcdf4eded78281918343a34152a5ebc330b8b38bb80372be1588675806d97","frame_index":0,"kind":"data","monotonic_ns":313362862328458,"payload":{"event_type":"price_change","market":"0xd412ce774cfcf8dc9f71164aac78783978aac7b03871702a3b8a481bd9dc9688","price_changes":[{"asset_id":"96600821790790307414914106093858868634329285205417149685270682748367152458577","best_ask":"0.43","best_bid":"0.42","hash":"015274db5b6782b4743b72548422bebf2ee2be97","price":"0.42","side":"BUY","size":"5"},{"asset_id":"107603864457683460275633293642179940881969192120168665300712204232021063124301","best_ask":"0.58","best_bid":"0.57","hash":"d75dd36b662fd4169872e8cdf155747437f33e0a","price":"0.58","side":"SELL","size":"5"}],"timestamp":"1785211376106"},"payload_hash":"917708ef4ca0c9c80c1db6756476d4a112a39f46ad87c784b451ff7dd3b1e95e","raw_frame":"{\"market\":\"0xd412ce774cfcf8dc9f71164aac78783978aac7b03871702a3b8a481bd9dc9688\", \"price_changes\":[{\"asset_id\":\"96600821790790307414914106093858868634329285205417149685270682748367152458577\", \"price\":\"0.42\", \"size\":\"5\", \"side\":\"BUY\", \"hash\":\"015274db5b6782b4743b72548422bebf2ee2be97\", \"best_bid\":\"0.42\", \"best_ask\":\"0.43\"}, {\"asset_id\":\"107603864457683460275633293642179940881969192120168665300712204232021063124301\", \"price\":\"0.58\", \"size\":\"5\", \"side\":\"SELL\", \"hash\":\"d75dd36b662fd4169872e8cdf155747437f33e0a\", \"best_bid\":\"0.57\", \"best_ask\":\"0.58\"}], \"timestamp\":\"1785211376106\", \"event_type\":\"price_change\"}","received_at":"2026-07-28T04:02:59.813086Z","schema_version":"clob-market-ws.price_change.v1","sequence":null,"server_hash":null,"server_timestamp":"1785211376106","session_id":"2d607381e3054cee91998cdf45a4231c","source":"clob_market_ws"},"received_at":"2026-07-28T04:02:59.813086Z","record_id":"f812054bf2e7717f75d470442a872e26016429a62abb839c8df096e6ef8d2b9c","schema_fingerprint":"4aa3821a28b0b7c2400bc59aba4bcc0a76e971dadd19610d3ad38c768e124dc7","schema_version":"edge-lab-recorder.raw.v1","sequence":null,"source":"clob_market_ws"}
{"event_at":"2026-07-28T04:02:56.108000Z","event_fingerprint":"0b82fe1e65c2e43b31ab5e7b50fc48870cbdb93eba21575b13ab7d4724b0990b","payload":{"connection_id":"f6725804f86a4c4eb588e4d5ed7db029","event_at":"2026-07-28T04:02:56.108000Z","event_type":"price_change","frame_hash":"7c2fff339787f0ca39763ba0ba4f8daf5fe19e7bca2a250c09ff9b8f8703d97e","frame_index":0,"kind":"data","monotonic_ns":313362863916541,"payload":{"event_type":"price_change","market":"0xd412ce774cfcf8dc9f71164aac78783978aac7b03871702a3b8a481bd9dc9688","price_changes":[{"asset_id":"107603864457683460275633293642179940881969192120168665300712204232021063124301","best_ask":"0.58","best_bid":"0.57","hash":"94d37535271522ccd385015fe35f0ddab13c30cb","price":"0.57","side":"BUY","size":"32.6"},{"asset_id":"96600821790790307414914106093858868634329285205417149685270682748367152458577","best_ask":"0.43","best_bid":"0.42","hash":"7901ea5d6e6c516689ea193d506d5caa5c1382cc","price":"0.43","side":"SELL","size":"32.6"}],"timestamp":"1785211376108"},"payload_hash":"21dc40005335817a02fbb04afcbd1781b79adba640a59325ef2f724e8a8e016a","raw_frame":"{\"market\":\"0xd412ce774cfcf8dc9f71164aac78783978aac7b03871702a3b8a481bd9dc9688\", \"price_changes\":[{\"asset_id\":\"107603864457683460275633293642179940881969192120168665300712204232021063124301\", \"price\":\"0.57\", \"size\":\"32.6\", \"side\":\"BUY\", \"hash\":\"94d37535271522ccd385015fe35f0ddab13c30cb\", \"best_bid\":\"0.57\", \"best_ask\":\"0.58\"}, {\"asset_id\":\"96600821790790307414914106093858868634329285205417149685270682748367152458577\", \"price\":\"0.43\", \"size\":\"32.6\", \"side\":\"SELL\", \"hash\":\"7901ea5d6e6c516689ea193d506d5caa5c1382cc\", \"best_bid\":\"0.42\", \"best_ask\":\"0.43\"}], \"timestamp\":\"1785211376108\", \"event_type\":\"price_change\"}","received_at":"2026-07-28T04:02:59.814674Z","schema_version":"clob-market-ws.price_change.v1","sequence":null,"server_hash":null,"server_timestamp":"1785211376108","session_id":"2d607381e3054cee91998cdf45a4231c","source":"clob_market_ws"},"received_at":"2026-07-28T04:02:59.814674Z","record_id":"b553eefbcb09b630225f93780c783131307e20d07661213ad52c127fee827df2","schema_fingerprint":"4aa3821a28b0b7c2400bc59aba4bcc0a76e971dadd19610d3ad38c768e124dc7","schema_version":"edge-lab-recorder.raw.v1","sequence":null,"source":"clob_market_ws"}
{"event_at":"2026-07-28T04:02:56.109000Z","event_fingerprint":"794eba1889250865ef366f8b942fedc5f5d290146959f3be9a336d9d58b94112","payload":{"connection_id":"f6725804f86a4c4eb588e4d5ed7db029","event_at":"2026-07-28T04:02:56.109000Z","event_type":"price_change","frame_hash":"ed89dff550579ca16c3a80bf4e136aae1cc13052a902143081ea1676b7c56d3f","frame_index":0,"kind":"data","monotonic_ns":313362865388791,"payload":{"event_type":"price_change","market":"0xd412ce774cfcf8dc9f71164aac78783978aac7b03871702a3b8a481bd9dc9688","price_changes":[{"asset_id":"107603864457683460275633293642179940881969192120168665300712204232021063124301","best_ask":"0.58","best_bid":"0.57","hash":"7f995a7f86b2e77cbbfb2a83787d5647b21a1679","price":"0.47","side":"BUY","size":"177"},{"asset_id":"96600821790790307414914106093858868634329285205417149685270682748367152458577","best_ask":"0.43","best_bid":"0.42","hash":"87057910c90fb73965601d9ccb5c4a986fae2ddc","price":"0.53","side":"SELL","size":"177"}],"timestamp":"1785211376109"},"payload_hash":"e42a8bc3b07d0e546434a16c8acf9f543188ee33d92d0be372900a170e16a68d","raw_frame":"{\"market\":\"0xd412ce774cfcf8dc9f71164aac78783978aac7b03871702a3b8a481bd9dc9688\", \"price_changes\":[{\"asset_id\":\"107603864457683460275633293642179940881969192120168665300712204232021063124301\", \"price\":\"0.47\", \"size\":\"177\", \"side\":\"BUY\", \"hash\":\"7f995a7f86b2e77cbbfb2a83787d5647b21a1679\", \"best_bid\":\"0.57\", \"best_ask\":\"0.58\"}, {\"asset_id\":\"96600821790790307414914106093858868634329285205417149685270682748367152458577\", \"price\":\"0.53\", \"size\":\"177\", \"side\":\"SELL\", \"hash\":\"87057910c90fb73965601d9ccb5c4a986fae2ddc\", \"best_bid\":\"0.42\", \"best_ask\":\"0.43\"}], \"timestamp\":\"1785211376109\", \"event_type\":\"price_change\"}","received_at":"2026-07-28T04:02:59.816145Z","schema_version":"clob-market-ws.price_change.v1","sequence":null,"server_hash":null,"server_timestamp":"1785211376109","session_id":"2d607381e3054cee91998cdf45a4231c","source":"clob_market_ws"},"received_at":"2026-07-28T04:02:59.816145Z","record_id":"c08152b6d9a2531c11c846d2409c089c842ae74cecb8a4cba455f651edc510ef","schema_fingerprint":"4aa3821a28b0b7c2400bc59aba4bcc0a76e971dadd19610d3ad38c768e124dc7","schema_version":"edge-lab-recorder.raw.v1","sequence":null,"source":"clob_market_ws"}
{"event_at":"2026-07-28T04:02:56.110000Z","event_fingerprint":"d787eec5661bec8774b057e973f9731fb4ea5585580e59092777075c396ac4ee","payload":{"connection_id":"f6725804f86a4c4eb588e4d5ed7db029","event_at":"2026-07-28T04:02:56.110000Z","event_type":"price_change","frame_hash":"c7bb7df29294890ad1aaabd2c484286e29cc3dc9167277a66505790c66ebe658","frame_index":0,"kind":"data","monotonic_ns":313362866869333,"payload":{"event_type":"price_change","market":"0xd412ce774cfcf8dc9f71164aac78783978aac7b03871702a3b8a481bd9dc9688","price_changes":[{"asset_id":"96600821790790307414914106093858868634329285205417149685270682748367152458577","best_ask":"0.43","best_bid":"0.42","hash":"7fcd4806aebb012e2934bce7d801e545fbc641be","price":"0.42","side":"BUY","size":"11"},{"asset_id":"107603864457683460275633293642179940881969192120168665300712204232021063124301","best_ask":"0.58","best_bid":"0.57","hash":"f95694e8abb1e94be1f21c3476afaef969974633","price":"0.58","side":"SELL","size":"11"}],"timestamp":"1785211376110"},"payload_hash":"b6c14afcc69bf93940527313e3cb514b63b9c85f9ef0be400c1a01429af7e19e","raw_frame":"{\"market\":\"0xd412ce774cfcf8dc9f71164aac78783978aac7b03871702a3b8a481bd9dc9688\", \"price_changes\":[{\"asset_id\":\"96600821790790307414914106093858868634329285205417149685270682748367152458577\", \"price\":\"0.42\", \"size\":\"11\", \"side\":\"BUY\", \"hash\":\"7fcd4806aebb012e2934bce7d801e545fbc641be\", \"best_bid\":\"0.42\", \"best_ask\":\"0.43\"}, {\"asset_id\":\"107603864457683460275633293642179940881969192120168665300712204232021063124301\", \"price\":\"0.58\", \"size\":\"11\", \"side\":\"SELL\", \"hash\":\"f95694e8abb1e94be1f21c3476afaef969974633\", \"best_bid\":\"0.57\", \"best_ask\":\"0.58\"}], \"timestamp\":\"1785211376110\", \"event_type\":\"price_change\"}","received_at":"2026-07-28T04:02:59.817627Z","schema_version":"clob-market-ws.price_change.v1","sequence":null,"server_hash":null,"server_timestamp":"1785211376110","session_id":"2d607381e3054cee91998cdf45a4231c","source":"clob_market_ws"},"received_at":"2026-07-28T04:02:59.817627Z","record_id":"12e08f7a00c20f8c9f455c7bb7f9ee80311bad5f65acfd61eb455e15bce3270c","schema_fingerprint":"4aa3821a28b0b7c2400bc59aba4bcc0a76e971dadd19610d3ad38c768e124dc7","schema_version":"edge-lab-recorder.raw.v1","sequence":null,"source":"clob_market_ws"}
{"event_at":"2026-07-28T04:02:56.111000Z","event_fingerprint":"9cbb7146240e1038c053688f54a21b79cefeb6615829d08c4173c55598c927f2","payload":{"connection_id":"f6725804f86a4c4eb588e4d5ed7db029","event_at":"2026-07-28T04:02:56.111000Z","event_type":"price_change","frame_hash":"18e5c2b399cc55e557ac010c9b82ce02cd3eccd52122feb7666302eb8a935947","frame_index":0,"kind":"data","monotonic_ns":313362868329083,"payload":{"event_type":"price_change","market":"0xd412ce774cfcf8dc9f71164aac78783978aac7b03871702a3b8a481bd9dc9688","price_changes":[{"asset_id":"107603864457683460275633293642179940881969192120168665300712204232021063124301","best_ask":"0.58","best_bid":"0.57","hash":"6ee33708aa2c9eb6f4f420ac500745f9c1a081d0","price":"0.55","side":"BUY","size":"16"},{"asset_id":"96600821790790307414914106093858868634329285205417149685270682748367152458577","best_ask":"0.43","best_bid":"0.42","hash":"a8d81ec4d49f01cb585b386121f365c944097f47","price":"0.45","side":"SELL","size":"16"}],"timestamp":"1785211376111"},"payload_hash":"fc75f6f3e6e4df1be65f57b70770e88da64bc6d02d185ce11137a9b7bd9e8181","raw_frame":"{\"market\":\"0xd412ce774cfcf8dc9f71164aac78783978aac7b03871702a3b8a481bd9dc9688\", \"price_changes\":[{\"asset_id\":\"107603864457683460275633293642179940881969192120168665300712204232021063124301\", \"price\":\"0.55\", \"size\":\"16\", \"side\":\"BUY\", \"hash\":\"6ee33708aa2c9eb6f4f420ac500745f9c1a081d0\", \"best_bid\":\"0.57\", \"best_ask\":\"0.58\"}, {\"asset_id\":\"96600821790790307414914106093858868634329285205417149685270682748367152458577\", \"price\":\"0.45\", \"size\":\"16\", \"side\":\"SELL\", \"hash\":\"a8d81ec4d49f01cb585b386121f365c944097f47\", \"best_bid\":\"0.42\", \"best_ask\":\"0.43\"}], \"timestamp\":\"1785211376111\", \"event_type\":\"price_change\"}","received_at":"2026-07-28T04:02:59.819087Z","schema_version":"clob-market-ws.price_change.v1","sequence":null,"server_hash":null,"server_timestamp":"1785211376111","session_id":"2d607381e3054cee91998cdf45a4231c","source":"clob_market_ws"},"received_at":"2026-07-28T04:02:59.819087Z","record_id":"7c8f2865079fdcbca9897f02a9125dbb931a54082065c487ac2d46c3910df239","schema_fingerprint":"4aa3821a28b0b7c2400bc59aba4bcc0a76e971dadd19610d3ad38c768e124dc7","schema_version":"edge-lab-recorder.raw.v1","sequence":null,"source":"clob_market_ws"}
{"event_at":"2026-07-28T04:02:56.111000Z","event_fingerprint":"d3cc251d8004ae9c83107561b17f98573447726d9b7b7e8a7bbd02ce87462f6f","payload":{"connection_id":"f6725804f86a4c4eb588e4d5ed7db029","event_at":"2026-07-28T04:02:56.111000Z","event_type":"price_change","frame_hash":"6c064b80c4693c1063ff480592aa3f1a50b81b8e1c4cec596610132d6739145a","frame_index":0,"kind":"data","monotonic_ns":313362869846750,"payload":{"event_type":"price_change","market":"0xd412ce774cfcf8dc9f71164aac78783978aac7b03871702a3b8a481bd9dc9688","price_changes":[{"asset_id":"96600821790790307414914106093858868634329285205417149685270682748367152458577","best_ask":"0.43","best_bid":"0.42","hash":"bb24916f75c893df6098f4fc3deec15e7b0a76a6","price":"0.42","side":"BUY","size":"23.6"},{"asset_id":"107603864457683460275633293642179940881969192120168665300712204232021063124301","best_ask":"0.58","best_bid":"0.57","hash":"69fefdc00f6d977166a3c7a74930a0d3a9df96a2","price":"0.58","side":"SELL","size":"23.6"}],"timestamp":"1785211376111"},"payload_hash":"e4f8532b8aee57234f189130ec59f9399442269e52522d57536579fb9dfe111c","raw_frame":"{\"market\":\"0xd412ce774cfcf8dc9f71164aac78783978aac7b03871702a3b8a481bd9dc9688\", \"price_changes\":[{\"asset_id\":\"96600821790790307414914106093858868634329285205417149685270682748367152458577\", \"price\":\"0.42\", \"size\":\"23.6\", \"side\":\"BUY\", \"hash\":\"bb24916f75c893df6098f4fc3deec15e7b0a76a6\", \"best_bid\":\"0.42\", \"best_ask\":\"0.43\"}, {\"asset_id\":\"107603864457683460275633293642179940881969192120168665300712204232021063124301\", \"price\":\"0.58\", \"size\":\"23.6\", \"side\":\"SELL\", \"hash\":\"69fefdc00f6d977166a3c7a74930a0d3a9df96a2\", \"best_bid\":\"0.57\", \"best_ask\":\"0.58\"}], \"timestamp\":\"1785211376111\", \"event_type\":\"price_change\"}","received_at":"2026-07-28T04:02:59.820600Z","schema_version":"clob-market-ws.price_change.v1","sequence":null,"server_hash":null,"server_timestamp":"1785211376111","session_id":"2d607381e3054cee91998cdf45a4231c","source":"clob_market_ws"},"received_at":"2026-07-28T04:02:59.820600Z","record_id":"a2ab9b09c2e663a49d3d0a1f7fe7f8e39dd649911e573514c2023f4b58752dd7","schema_fingerprint":"4aa3821a28b0b7c2400bc59aba4bcc0a76e971dadd19610d3ad38c768e124dc7","schema_version":"edge-lab-recorder.raw.v1","sequence":null,"source":"clob_market_ws"}
{"event_at":"2026-07-28T04:02:56.112000Z","event_fingerprint":"4b09723fcca713640e904db4161cc2598ac2ad8a40e1945bfe6032fce4ec565a","payload":{"connection_id":"f6725804f86a4c4eb588e4d5ed7db029","event_at":"2026-07-28T04:02:56.112000Z","event_type":"price_change","frame_hash":"46736042c93d442b465245a43ac1ae99ad47d885e6737d70bf5fa3f40056d709","frame_index":0,"kind":"data","monotonic_ns":313362871389500,"payload":{"event_type":"price_change","market":"0xd412ce774cfcf8dc9f71164aac78783978aac7b03871702a3b8a481bd9dc9688","price_changes":[{"asset_id":"107603864457683460275633293642179940881969192120168665300712204232021063124301","best_ask":"0.58","best_bid":"0.57","hash":"95b395f3cfe4531d94bacb07415597f35fc4d0e7","price":"0.56","side":"BUY","size":"15"},{"asset_id":"96600821790790307414914106093858868634329285205417149685270682748367152458577","best_ask":"0.43","best_bid":"0.42","hash":"83bcd0573662e6e25d873137a7a1ace21e2129bb","price":"0.44","side":"SELL","size":"15"}],"timestamp":"1785211376112"},"payload_hash":"9d6c8a9fb6dab16f0e1090f7515101e8ac17504d52e5abbcff3cd87d56880e44","raw_frame":"{\"market\":\"0xd412ce774cfcf8dc9f71164aac78783978aac7b03871702a3b8a481bd9dc9688\", \"price_changes\":[{\"asset_id\":\"107603864457683460275633293642179940881969192120168665300712204232021063124301\", \"price\":\"0.56\", \"size\":\"15\", \"side\":\"BUY\", \"hash\":\"95b395f3cfe4531d94bacb07415597f35fc4d0e7\", \"best_bid\":\"0.57\", \"best_ask\":\"0.58\"}, {\"asset_id\":\"96600821790790307414914106093858868634329285205417149685270682748367152458577\", \"price\":\"0.44\", \"size\":\"15\", \"side\":\"SELL\", \"hash\":\"83bcd0573662e6e25d873137a7a1ace21e2129bb\", \"best_bid\":\"0.42\", \"best_ask\":\"0.43\"}], \"timestamp\":\"1785211376112\", \"event_type\":\"price_change\"}","received_at":"2026-07-28T04:02:59.822147Z","schema_version":"clob-market-ws.price_change.v1","sequence":null,"server_hash":null,"server_timestamp":"1785211376112","session_id":"2d607381e3054cee91998cdf45a4231c","source":"clob_market_ws"},"received_at":"2026-07-28T04:02:59.822147Z","record_id":"d9d430dc465508862a40d1e3ab594a4cd54c7fa41fbe4c85bdb384abe223a54c","schema_fingerprint":"4aa3821a28b0b7c2400bc59aba4bcc0a76e971dadd19610d3ad38c768e124dc7","schema_version":"edge-lab-recorder.raw.v1","sequence":null,"source":"clob_market_ws"}
{"event_at":"2026-07-28T04:02:56.113000Z","event_fingerprint":"f3090177579063597951931ee3d8acf8bbf2e877ad71f273659a0fe562a1ad95","payload":{"connection_id":"f6725804f86a4c4eb588e4d5ed7db029","event_at":"2026-07-28T04:02:56.113000Z","event_type":"price_change","frame_hash":"375213d9453105417fd7989ad5d5793debc8f1a01c7722b8f62615b60efb6c53","frame_index":0,"kind":"data","monotonic_ns":313362872865500,"payload":{"event_type":"price_change","market":"0xd412ce774cfcf8dc9f71164aac78783978aac7b03871702a3b8a481bd9dc9688","price_changes":[{"asset_id":"107603864457683460275633293642179940881969192120168665300712204232021063124301","best_ask":"0.58","best_bid":"0.57","hash":"daf0254f9176869ee482454891913df33b1fc017","price":"0.01","side":"BUY","size":"7888.02"},{"asset_id":"96600821790790307414914106093858868634329285205417149685270682748367152458577","best_ask":"0.43","best_bid":"0.42","hash":"e1adb5e99a3132df7a5ab654df4ac4f08a49f8ca","price":"0.99","side":"SELL","size":"7888.02"}],"timestamp":"1785211376113"},"payload_hash":"2c6e55bfa8f2a57273ddd23b31e2fd997ad6ebc4a2bf8542568f3015cb5ce256","raw_frame":"{\"market\":\"0xd412ce774cfcf8dc9f71164aac78783978aac7b03871702a3b8a481bd9dc9688\", \"price_changes\":[{\"asset_id\":\"107603864457683460275633293642179940881969192120168665300712204232021063124301\", \"price\":\"0.01\", \"size\":\"7888.02\", \"side\":\"BUY\", \"hash\":\"daf0254f9176869ee482454891913df33b1fc017\", \"best_bid\":\"0.57\", \"best_ask\":\"0.58\"}, {\"asset_id\":\"96600821790790307414914106093858868634329285205417149685270682748367152458577\", \"price\":\"0.99\", \"size\":\"7888.02\", \"side\":\"SELL\", \"hash\":\"e1adb5e99a3132df7a5ab654df4ac4f08a49f8ca\", \"best_bid\":\"0.42\", \"best_ask\":\"0.43\"}], \"timestamp\":\"1785211376113\", \"event_type\":\"price_change\"}","received_at":"2026-07-28T04:02:59.823621Z","schema_version":"clob-market-ws.price_change.v1","sequence":null,"server_hash":null,"server_timestamp":"1785211376113","session_id":"2d607381e3054cee91998cdf45a4231c","source":"clob_market_ws"},"received_at":"2026-07-28T04:02:59.823621Z","record_id":"c25e82ce9180b4ed35dcb68693d020ba60c0720ae0106c37976b47677c71cc75","schema_fingerprint":"4aa3821a28b0b7c2400bc59aba4bcc0a76e971dadd19610d3ad38c768e124dc7","schema_version":"edge-lab-recorder.raw.v1","sequence":null,"source":"clob_market_ws"}
{"event_at":"2026-07-28T04:02:56.115000Z","event_fingerprint":"54f7392f3bf884b4c070a95d7ad0d8ec43cbb0de734ce52bdbc0cfe808016d73","payload":{"connection_id":"f6725804f86a4c4eb588e4d5ed7db029","event_at":"2026-07-28T04:02:56.115000Z","event_type":"new_market","frame_hash":"d86cd2a08d24b002606627c93a0eddf9bc8430f2f0ff851fcf97fa443bb0e582","frame_index":0,"kind":"data","monotonic_ns":313362874387625,"payload":{"active":true,"assets_ids":["45654129313250996646501631813867287204758466613851523480335831395518257545590","107663686831321815108474488913948289504667970610920771337210347437186852046272"],"clob_token_ids":["45654129313250996646501631813867287204758466613851523480335831395518257545590","107663686831321815108474488913948289504667970610920771337210347437186852046272"],"condition_id":"0xcb1b2f0186985383a1863488fce45931bc4db15a115dc26c7dedad4a758fdb43","description":"In the upcoming match between Barnsley FC and Wigan Athletic FC, scheduled for August 8, 2026 at 10:00 AM ET: This market will resolve to \"Barnsley FC\" if Barnsley FC are the first to score within the first 90 minutes of regular play plus stoppage time. This market will resolve to \"Wigan Athletic FC\" if Wigan Athletic FC are the first to score within the first 90 minutes of regular play plus stoppage time. If neither team scores within the first 90 minutes of regular play plus stoppage time, this market will resolve \"Neither\". If the game is postponed, this market will remain open until the game has been completed. If the game is canceled entirely, with no make-up game, this market will resolve to \"Neither\". This market refers only to the outcome within the first 90 minutes of regular play plus stoppage time. Extra time and penalty shoot-outs are excluded. The primary resolution source for this market is the official statistics of the event as recognized by the governing body or event organizers. However, if the governing body or event organizers have not published final match statistics within 2 hours after the event's conclusion, a consensus of credible reporting may be used instead. All markets will settle based on the official final result as recognized by the governing body or event organizers. Revisions to officially declared final scores made after market resolution will not be accounted for in determining the outcome.","event_message":{"description":"In the upcoming match between Barnsley FC and Wigan Athletic FC, scheduled for August 8, 2026 at 10:00 AM ET: This market will resolve to \"Barnsley FC\" if Barnsley FC are the first to score within the first 90 minutes of regular play plus stoppage time. This market will resolve to \"Wigan Athletic FC\" if Wigan Athletic FC are the first to score within the first 90 minutes of regular play plus stoppage time. If neither team scores within the first 90 minutes of regular play plus stoppage time, this market will resolve \"Neither\". If the game is postponed, this market will remain open until the game has been completed. If the game is canceled entirely, with no make-up game, this market will resolve to \"Neither\". This market refers only to the outcome within the first 90 minutes of regular play plus stoppage time. Extra time and penalty shoot-outs are excluded. The primary resolution source for this market is the official statistics of the event as recognized by the governing body or event organizers. However, if the governing body or event organizers have not published final match statistics within 2 hours after the event's conclusion, a consensus of credible reporting may be used instead. All markets will settle based on the official final result as recognized by the governing body or event organizers. Revisions to officially declared final scores made after market resolution will not be accounted for in determining the outcome.","id":"759537","slug":"efl-bar1-wig-2026-08-08-first-to-score","ticker":"efl-bar1-wig-2026-08-08-first-to-score","title":"Barnsley FC vs. Wigan Athletic FC - First Team to Score"},"event_type":"new_market","fee_schedule":{"exponent":"1","rate":"0.05","rebate_rate":"0.15","taker_only":true},"fees_enabled":true,"game_start_time":"2026-08-08 14:00:00+00","group_item_title":"Barnsley FC","id":"3146692","line":"","market":"0xcb1b2f0186985383a1863488fce45931bc4db15a115dc26c7dedad4a758fdb43","order_price_min_tick_size":"0.01","outcomes":["Yes","No"],"question":"Barnsley FC to score first vs. Wigan Athletic FC?","slug":"efl-bar1-wig-2026-08-08-first-to-score-home","sports_market_type":"soccer_first_to_score","tags":[],"taker_base_fee":"1000","timestamp":"1785211376115"},"payload_hash":"37f8de8172337a1f14688a1bf081fe8681ce4f9365849951196b64f70a20b7ea","raw_frame":"{\"id\":\"3146692\", \"question\":\"Barnsley FC to score first vs. Wigan Athletic FC?\", \"market\":\"0xcb1b2f0186985383a1863488fce45931bc4db15a115dc26c7dedad4a758fdb43\", \"slug\":\"efl-bar1-wig-2026-08-08-first-to-score-home\", \"description\":\"In the upcoming match between Barnsley FC and Wigan Athletic FC, scheduled for August 8, 2026 at 10:00 AM ET: This market will resolve to \\\"Barnsley FC\\\" if Barnsley FC are the first to score within the first 90 minutes of regular play plus stoppage time. This market will resolve to \\\"Wigan Athletic FC\\\" if Wigan Athletic FC are the first to score within the first 90 minutes of regular play plus stoppage time. If neither team scores within the first 90 minutes of regular play plus stoppage time, this market will resolve \\\"Neither\\\". If the game is postponed, this market will remain open until the game has been completed. If the game is canceled entirely, with no make-up game, this market will resolve to \\\"Neither\\\". This market refers only to the outcome within the first 90 minutes of regular play plus stoppage time. Extra time and penalty shoot-outs are excluded. The primary resolution source for this market is the official statistics of the event as recognized by the governing body or event organizers. However, if the governing body or event organizers have not published final match statistics within 2 hours after the event's conclusion, a consensus of credible reporting may be used instead. All markets will settle based on the official final result as recognized by the governing body or event organizers. Revisions to officially declared final scores made after market resolution will not be accounted for in determining the outcome.\", \"assets_ids\":[\"45654129313250996646501631813867287204758466613851523480335831395518257545590\", \"107663686831321815108474488913948289504667970610920771337210347437186852046272\"], \"outcomes\":[\"Yes\", \"No\"], \"event_message\":{\"id\":\"759537\", \"ticker\":\"efl-bar1-wig-2026-08-08-first-to-score\", \"slug\":\"efl-bar1-wig-2026-08-08-first-to-score\", \"title\":\"Barnsley FC vs. Wigan Athletic FC - First Team to Score\", \"description\":\"In the upcoming match between Barnsley FC and Wigan Athletic FC, scheduled for August 8, 2026 at 10:00 AM ET: This market will resolve to \\\"Barnsley FC\\\" if Barnsley FC are the first to score within the first 90 minutes of regular play plus stoppage time. This market will resolve to \\\"Wigan Athletic FC\\\" if Wigan Athletic FC are the first to score within the first 90 minutes of regular play plus stoppage time. If neither team scores within the first 90 minutes of regular play plus stoppage time, this market will resolve \\\"Neither\\\". If the game is postponed, this market will remain open until the game has been completed. If the game is canceled entirely, with no make-up game, this market will resolve to \\\"Neither\\\". This market refers only to the outcome within the first 90 minutes of regular play plus stoppage time. Extra time and penalty shoot-outs are excluded. The primary resolution source for this market is the official statistics of the event as recognized by the governing body or event organizers. However, if the governing body or event organizers have not published final match statistics within 2 hours after the event's conclusion, a consensus of credible reporting may be used instead. All markets will settle based on the official final result as recognized by the governing body or event organizers. Revisions to officially declared final scores made after market resolution will not be accounted for in determining the outcome.\"}, \"timestamp\":\"1785211376115\", \"event_type\":\"new_market\", \"tags\":[], \"condition_id\":\"0xcb1b2f0186985383a1863488fce45931bc4db15a115dc26c7dedad4a758fdb43\", \"active\":true, \"clob_token_ids\":[\"45654129313250996646501631813867287204758466613851523480335831395518257545590\", \"107663686831321815108474488913948289504667970610920771337210347437186852046272\"], \"sports_market_type\":\"soccer_first_to_score\", \"line\":\"\", \"game_start_time\":\"2026-08-08 14:00:00+00\", \"order_price_min_tick_size\":\"0.01\", \"group_item_title\":\"Barnsley FC\", \"taker_base_fee\":\"1000\", \"fees_enabled\":true, \"fee_schedule\":{\"exponent\":\"1\", \"rate\":\"0.05\", \"taker_only\":true, \"rebate_rate\":\"0.15\"}}","received_at":"2026-07-28T04:02:59.825145Z","schema_version":"clob-market-ws.new_market.v1","sequence":null,"server_hash":null,"server_timestamp":"1785211376115","session_id":"2d607381e3054cee91998cdf45a4231c","source":"clob_market_ws"},"received_at":"2026-07-28T04:02:59.825145Z","record_id":"08642f25d1da89249cbdc63eac45c45deea43d887211cd34994cc45153580bff","schema_fingerprint":"6639a822a7b79cfa4c3fc0044066e4f66ba8611f5bf361772bd6902a2319b82d","schema_version":"edge-lab-recorder.raw.v1","sequence":null,"source":"clob_market_ws"}
{"event_at":"2026-07-28T04:02:56.118000Z","event_fingerprint":"7ca1abb6386152b5df5e5cb402b0880d7d6d23c9fde38b02784a039d002e474c","payload":{"connection_id":"f6725804f86a4c4eb588e4d5ed7db029","event_at":"2026-07-28T04:02:56.118000Z","event_type":"price_change","frame_hash":"c630d0a2fbe7614da62af83a48b22fd8be8c113251eed499418eef9ce6a02048","frame_index":0,"kind":"data","monotonic_ns":313362876522291,"payload":{"event_type":"price_change","market":"0xd412ce774cfcf8dc9f71164aac78783978aac7b03871702a3b8a481bd9dc9688","price_changes":[{"asset_id":"96600821790790307414914106093858868634329285205417149685270682748367152458577","best_ask":"0.43","best_bid":"0.42","hash":"d0e870cf217d2ac07059f715b523eec8ab7d59ff","price":"0.42","side":"BUY","size":"47.6"},{"asset_id":"107603864457683460275633293642179940881969192120168665300712204232021063124301","best_ask":"0.58","best_bid":"0.57","hash":"63b42eae44a39c2c1b70ec81210081aabccf4800","price":"0.58","side":"SELL","size":"47.6"}],"timestamp":"1785211376118"},"payload_hash":"b7d2c0765f31f7e377ff2cf069403374ac2791c855161107c613dc824be89306","raw_frame":"{\"market\":\"0xd412ce774cfcf8dc9f71164aac78783978aac7b03871702a3b8a481bd9dc9688\", \"price_changes\":[{\"asset_id\":\"96600821790790307414914106093858868634329285205417149685270682748367152458577\", \"price\":\"0.42\", \"size\":\"47.6\", \"side\":\"BUY\", \"hash\":\"d0e870cf217d2ac07059f715b523eec8ab7d59ff\", \"best_bid\":\"0.42\", \"best_ask\":\"0.43\"}, {\"asset_id\":\"107603864457683460275633293642179940881969192120168665300712204232021063124301\", \"price\":\"0.58\", \"size\":\"47.6\", \"side\":\"SELL\", \"hash\":\"63b42eae44a39c2c1b70ec81210081aabccf4800\", \"best_bid\":\"0.57\", \"best_ask\":\"0.58\"}], \"timestamp\":\"1785211376118\", \"event_type\":\"price_change\"}","received_at":"2026-07-28T04:02:59.827279Z","schema_version":"clob-market-ws.price_change.v1","sequence":null,"server_hash":null,"server_timestamp":"1785211376118","session_id":"2d607381e3054cee91998cdf45a4231c","source":"clob_market_ws"},"received_at":"2026-07-28T04:02:59.827279Z","record_id":"a4e0d8cb33826ed648d1817b26c3a1dc575843e8043307a591c4ddcb94d9dc32","schema_fingerprint":"4aa3821a28b0b7c2400bc59aba4bcc0a76e971dadd19610d3ad38c768e124dc7","schema_version":"edge-lab-recorder.raw.v1","sequence":null,"source":"clob_market_ws"}
{"event_at":"2026-07-28T04:02:56.118000Z","event_fingerprint":"1a811dcaa36ff94d68b8885de68f7e738df7fb32edf039fdc3dfc8b58d230b77","payload":{"connection_id":"f6725804f86a4c4eb588e4d5ed7db029","event_at":"2026-07-28T04:02:56.118000Z","event_type":"new_market","frame_hash":"a383d7bd8b5a1681059916a3af5cee4eec549b82456fd5efc7ec806150ff448f","frame_index":0,"kind":"data","monotonic_ns":313362878071958,"payload":{"active":true,"assets_ids":["57177221020972137068436222170421119298377031696193702692158450350920643268017","96516366946412345324089486457769589958304336896057495473132858991155685476457"],"clob_token_ids":["57177221020972137068436222170421119298377031696193702692158450350920643268017","96516366946412345324089486457769589958304336896057495473132858991155685476457"],"condition_id":"0xa6ead21b3ac2d1ff211ef8dc506733aa85fa03290e06240ae5be1fa9fef03ab4","description":"In the upcoming match between Barnsley FC and Wigan Athletic FC, scheduled for August 8, 2026 at 10:00 AM ET: This market will resolve to \"Barnsley FC\" if Barnsley FC are the first to score within the first 90 minutes of regular play plus stoppage time. This market will resolve to \"Wigan Athletic FC\" if Wigan Athletic FC are the first to score within the first 90 minutes of regular play plus stoppage time. If neither team scores within the first 90 minutes of regular play plus stoppage time, this market will resolve \"Neither\". If the game is postponed, this market will remain open until the game has been completed. If the game is canceled entirely, with no make-up game, this market will resolve to \"Neither\". This market refers only to the outcome within the first 90 minutes of regular play plus stoppage time. Extra time and penalty shoot-outs are excluded. The primary resolution source for this market is the official statistics of the event as recognized by the governing body or event organizers. However, if the governing body or event organizers have not published final match statistics within 2 hours after the event's conclusion, a consensus of credible reporting may be used instead. All markets will settle based on the official final result as recognized by the governing body or event organizers. Revisions to officially declared final scores made after market resolution will not be accounted for in determining the outcome.","event_message":{"description":"In the upcoming match between Barnsley FC and Wigan Athletic FC, scheduled for August 8, 2026 at 10:00 AM ET: This market will resolve to \"Barnsley FC\" if Barnsley FC are the first to score within the first 90 minutes of regular play plus stoppage time. This market will resolve to \"Wigan Athletic FC\" if Wigan Athletic FC are the first to score within the first 90 minutes of regular play plus stoppage time. If neither team scores within the first 90 minutes of regular play plus stoppage time, this market will resolve \"Neither\". If the game is postponed, this market will remain open until the game has been completed. If the game is canceled entirely, with no make-up game, this market will resolve to \"Neither\". This market refers only to the outcome within the first 90 minutes of regular play plus stoppage time. Extra time and penalty shoot-outs are excluded. The primary resolution source for this market is the official statistics of the event as recognized by the governing body or event organizers. However, if the governing body or event organizers have not published final match statistics within 2 hours after the event's conclusion, a consensus of credible reporting may be used instead. All markets will settle based on the official final result as recognized by the governing body or event organizers. Revisions to officially declared final scores made after market resolution will not be accounted for in determining the outcome.","id":"759537","slug":"efl-bar1-wig-2026-08-08-first-to-score","ticker":"efl-bar1-wig-2026-08-08-first-to-score","title":"Barnsley FC vs. Wigan Athletic FC - First Team to Score"},"event_type":"new_market","fee_schedule":{"exponent":"1","rate":"0.05","rebate_rate":"0.15","taker_only":true},"fees_enabled":true,"game_start_time":"2026-08-08 14:00:00+00","group_item_title":"Neither","id":"3146695","line":"","market":"0xa6ead21b3ac2d1ff211ef8dc506733aa85fa03290e06240ae5be1fa9fef03ab4","order_price_min_tick_size":"0.01","outcomes":["Yes","No"],"question":"Barnsley FC vs. Wigan Athletic FC: Neither team to score first?","slug":"efl-bar1-wig-2026-08-08-first-to-score-neither","sports_market_type":"soccer_first_to_score","tags":[],"taker_base_fee":"1000","timestamp":"1785211376118"},"payload_hash":"fb399dac704496e992beeb6ad7a970cca303e987d6893704e672e19b54bae26c","raw_frame":"{\"id\":\"3146695\", \"question\":\"Barnsley FC vs. Wigan Athletic FC: Neither team to score first?\", \"market\":\"0xa6ead21b3ac2d1ff211ef8dc506733aa85fa03290e06240ae5be1fa9fef03ab4\", \"slug\":\"efl-bar1-wig-2026-08-08-first-to-score-neither\", \"description\":\"In the upcoming match between Barnsley FC and Wigan Athletic FC, scheduled for August 8, 2026 at 10:00 AM ET: This market will resolve to \\\"Barnsley FC\\\" if Barnsley FC are the first to score within the first 90 minutes of regular play plus stoppage time. This market will resolve to \\\"Wigan Athletic FC\\\" if Wigan Athletic FC are the first to score within the first 90 minutes of regular play plus stoppage time. If neither team scores within the first 90 minutes of regular play plus stoppage time, this market will resolve \\\"Neither\\\". If the game is postponed, this market will remain open until the game has been completed. If the game is canceled entirely, with no make-up game, this market will resolve to \\\"Neither\\\". This market refers only to the outcome within the first 90 minutes of regular play plus stoppage time. Extra time and penalty shoot-outs are excluded. The primary resolution source for this market is the official statistics of the event as recognized by the governing body or event organizers. However, if the governing body or event organizers have not published final match statistics within 2 hours after the event's conclusion, a consensus of credible reporting may be used instead. All markets will settle based on the official final result as recognized by the governing body or event organizers. Revisions to officially declared final scores made after market resolution will not be accounted for in determining the outcome.\", \"assets_ids\":[\"57177221020972137068436222170421119298377031696193702692158450350920643268017\", \"96516366946412345324089486457769589958304336896057495473132858991155685476457\"], \"outcomes\":[\"Yes\", \"No\"], \"event_message\":{\"id\":\"759537\", \"ticker\":\"efl-bar1-wig-2026-08-08-first-to-score\", \"slug\":\"efl-bar1-wig-2026-08-08-first-to-score\", \"title\":\"Barnsley FC vs. Wigan Athletic FC - First Team to Score\", \"description\":\"In the upcoming match between Barnsley FC and Wigan Athletic FC, scheduled for August 8, 2026 at 10:00 AM ET: This market will resolve to \\\"Barnsley FC\\\" if Barnsley FC are the first to score within the first 90 minutes of regular play plus stoppage time. This market will resolve to \\\"Wigan Athletic FC\\\" if Wigan Athletic FC are the first to score within the first 90 minutes of regular play plus stoppage time. If neither team scores within the first 90 minutes of regular play plus stoppage time, this market will resolve \\\"Neither\\\". If the game is postponed, this market will remain open until the game has been completed. If the game is canceled entirely, with no make-up game, this market will resolve to \\\"Neither\\\". This market refers only to the outcome within the first 90 minutes of regular play plus stoppage time. Extra time and penalty shoot-outs are excluded. The primary resolution source for this market is the official statistics of the event as recognized by the governing body or event organizers. However, if the governing body or event organizers have not published final match statistics within 2 hours after the event's conclusion, a consensus of credible reporting may be used instead. All markets will settle based on the official final result as recognized by the governing body or event organizers. Revisions to officially declared final scores made after market resolution will not be accounted for in determining the outcome.\"}, \"timestamp\":\"1785211376118\", \"event_type\":\"new_market\", \"tags\":[], \"condition_id\":\"0xa6ead21b3ac2d1ff211ef8dc506733aa85fa03290e06240ae5be1fa9fef03ab4\", \"active\":true, \"clob_token_ids\":[\"57177221020972137068436222170421119298377031696193702692158450350920643268017\", \"96516366946412345324089486457769589958304336896057495473132858991155685476457\"], \"sports_market_type\":\"soccer_first_to_score\", \"line\":\"\", \"game_start_time\":\"2026-08-08 14:00:00+00\", \"order_price_min_tick_size\":\"0.01\", \"group_item_title\":\"Neither\", \"taker_base_fee\":\"1000\", \"fees_enabled\":true, \"fee_schedule\":{\"exponent\":\"1\", \"rate\":\"0.05\", \"taker_only\":true, \"rebate_rate\":\"0.15\"}}","received_at":"2026-07-28T04:02:59.828828Z","schema_version":"clob-market-ws.new_market.v1","sequence":null,"server_hash":null,"server_timestamp":"1785211376118","session_id":"2d607381e3054cee91998cdf45a4231c","source":"clob_market_ws"},"received_at":"2026-07-28T04:02:59.828828Z","record_id":"6d2e23995f4ff0ccfb7979b4111adfffc7de5b28ac4fd8dcfb15a89737fa6c6e","schema_fingerprint":"6639a822a7b79cfa4c3fc0044066e4f66ba8611f5bf361772bd6902a2319b82d","schema_version":"edge-lab-recorder.raw.v1","sequence":null,"source":"clob_market_ws"}
{"event_at":"2026-07-28T04:02:56.119000Z","event_fingerprint":"65938c8328d377848f266e5e4de16e3c08f9be396d82f26ffd67bf730c8fd1e5","payload":{"connection_id":"f6725804f86a4c4eb588e4d5ed7db029","event_at":"2026-07-28T04:02:56.119000Z","event_type":"price_change","frame_hash":"16e30f69c1ce4ec5532985364aa4c65cdcfdf73ae905ae032ff0efcc29835f0f","frame_index":0,"kind":"data","monotonic_ns":313362880322250,"payload":{"event_type":"price_change","market":"0xd412ce774cfcf8dc9f71164aac78783978aac7b03871702a3b8a481bd9dc9688","price_changes":[{"asset_id":"96600821790790307414914106093858868634329285205417149685270682748367152458577","best_ask":"0.43","best_bid":"0.42","hash":"e82f21077dbeb0f9c7f2b44e09d283fe981c4f51","price":"0.42","side":"BUY","size":"60.6"},{"asset_id":"107603864457683460275633293642179940881969192120168665300712204232021063124301","best_ask":"0.58","best_bid":"0.57","hash":"6cea84540f4caca9faac550f20cdda541fc2ea1f","price":"0.58","side":"SELL","size":"60.6"}],"timestamp":"1785211376119"},"payload_hash":"82f2bb3d0119333f507bff621ccd67ed4014db5b645121ecdf46671bc045f16e","raw_frame":"{\"market\":\"0xd412ce774cfcf8dc9f71164aac78783978aac7b03871702a3b8a481bd9dc9688\", \"price_changes\":[{\"asset_id\":\"96600821790790307414914106093858868634329285205417149685270682748367152458577\", \"price\":\"0.42\", \"size\":\"60.6\", \"side\":\"BUY\", \"hash\":\"e82f21077dbeb0f9c7f2b44e09d283fe981c4f51\", \"best_bid\":\"0.42\", \"best_ask\":\"0.43\"}, {\"asset_id\":\"107603864457683460275633293642179940881969192120168665300712204232021063124301\", \"price\":\"0.58\", \"size\":\"60.6\", \"side\":\"SELL\", \"hash\":\"6cea84540f4caca9faac550f20cdda541fc2ea1f\", \"best_bid\":\"0.57\", \"best_ask\":\"0.58\"}], \"timestamp\":\"1785211376119\", \"event_type\":\"price_change\"}","received_at":"2026-07-28T04:02:59.831078Z","schema_version":"clob-market-ws.price_change.v1","sequence":null,"server_hash":null,"server_timestamp":"1785211376119","session_id":"2d607381e3054cee91998cdf45a4231c","source":"clob_market_ws"},"received_at":"2026-07-28T04:02:59.831078Z","record_id":"2ca1f856ce700d93deab0a570ced510226f85772708b4c5c0c0d13d7ffc2aa68","schema_fingerprint":"4aa3821a28b0b7c2400bc59aba4bcc0a76e971dadd19610d3ad38c768e124dc7","schema_version":"edge-lab-recorder.raw.v1","sequence":null,"source":"clob_market_ws"}
{"event_at":"2026-07-28T04:02:56.120000Z","event_fingerprint":"3df8a492bbdd068ee821204526e970d2cedc64f40dc9b42e17bec623fae32c5b","payload":{"connection_id":"f6725804f86a4c4eb588e4d5ed7db029","event_at":"2026-07-28T04:02:56.120000Z","event_type":"price_change","frame_hash":"1f484ad6f44a06389265efed5e8cc992860dcd95abbc6523220f2d78236ba4f3","frame_index":0,"kind":"data","monotonic_ns":313362881837166,"payload":{"event_type":"price_change","market":"0xd412ce774cfcf8dc9f71164aac78783978aac7b03871702a3b8a481bd9dc9688","price_changes":[{"asset_id":"96600821790790307414914106093858868634329285205417149685270682748367152458577","best_ask":"0.43","best_bid":"0.42","hash":"63ad8d5608af8e2be5ba6895224558a53e4c6c78","price":"0.42","side":"BUY","size":"82.6"},{"asset_id":"107603864457683460275633293642179940881969192120168665300712204232021063124301","best_ask":"0.58","best_bid":"0.57","hash":"94f2227047042736487da125324a978c00a35b41","price":"0.58","side":"SELL","size":"82.6"}],"timestamp":"1785211376120"},"payload_hash":"1df9859a07455758bca9427e46a38433752aa7ebf9d968ccb6e3719ba25c9dbf","raw_frame":"{\"market\":\"0xd412ce774cfcf8dc9f71164aac78783978aac7b03871702a3b8a481bd9dc9688\", \"price_changes\":[{\"asset_id\":\"96600821790790307414914106093858868634329285205417149685270682748367152458577\", \"price\":\"0.42\", \"size\":\"82.6\", \"side\":\"BUY\", \"hash\":\"63ad8d5608af8e2be5ba6895224558a53e4c6c78\", \"best_bid\":\"0.42\", \"best_ask\":\"0.43\"}, {\"asset_id\":\"107603864457683460275633293642179940881969192120168665300712204232021063124301\", \"price\":\"0.58\", \"size\":\"82.6\", \"side\":\"SELL\", \"hash\":\"94f2227047042736487da125324a978c00a35b41\", \"best_bid\":\"0.57\", \"best_ask\":\"0.58\"}], \"timestamp\":\"1785211376120\", \"event_type\":\"price_change\"}","received_at":"2026-07-28T04:02:59.832593Z","schema_version":"clob-market-ws.price_change.v1","sequence":null,"server_hash":null,"server_timestamp":"1785211376120","session_id":"2d607381e3054cee91998cdf45a4231c","source":"clob_market_ws"},"received_at":"2026-07-28T04:02:59.832593Z","record_id":"4e4eeda449ea2ca8b5d3af35f3c9b05fa24d90ebad83ebc4e6bab1de922830f5","schema_fingerprint":"4aa3821a28b0b7c2400bc59aba4bcc0a76e971dadd19610d3ad38c768e124dc7","schema_version":"edge-lab-recorder.raw.v1","sequence":null,"source":"clob_market_ws"}
{"event_at":"2026-07-28T04:02:56.121000Z","event_fingerprint":"616e428cc1fe7e7af34733ed514b934db96cd29526924e94689b0a45c324e613","payload":{"connection_id":"f6725804f86a4c4eb588e4d5ed7db029","event_at":"2026-07-28T04:02:56.121000Z","event_type":"price_change","frame_hash":"64c71c7a14e438e9f2ca0f93d7c8972c94b63f42393cd9685d0546c648d30edd","frame_index":0,"kind":"data","monotonic_ns":313362883345500,"payload":{"event_type":"price_change","market":"0xd412ce774cfcf8dc9f71164aac78783978aac7b03871702a3b8a481bd9dc9688","price_changes":[{"asset_id":"107603864457683460275633293642179940881969192120168665300712204232021063124301","best_ask":"0.58","best_bid":"0.57","hash":"95a9eeca24ce5937aae30f9916ef414bbfc6f3eb","price":"0.57","side":"BUY","size":"26.6"},{"asset_id":"96600821790790307414914106093858868634329285205417149685270682748367152458577","best_ask":"0.43","best_bid":"0.42","hash":"eedfe8a4b5df34db473d900e3fb6f4c0df6f4710","price":"0.43","side":"SELL","size":"26.6"}],"timestamp":"1785211376121"},"payload_hash":"acab60568e88e0405b9f66a2ea6d8e4c8a14c429c7bc54d44e92568cfe741d3a","raw_frame":"{\"market\":\"0xd412ce774cfcf8dc9f71164aac78783978aac7b03871702a3b8a481bd9dc9688\", \"price_changes\":[{\"asset_id\":\"107603864457683460275633293642179940881969192120168665300712204232021063124301\", \"price\":\"0.57\", \"size\":\"26.6\", \"side\":\"BUY\", \"hash\":\"95a9eeca24ce5937aae30f9916ef414bbfc6f3eb\", \"best_bid\":\"0.57\", \"best_ask\":\"0.58\"}, {\"asset_id\":\"96600821790790307414914106093858868634329285205417149685270682748367152458577\", \"price\":\"0.43\", \"size\":\"26.6\", \"side\":\"SELL\", \"hash\":\"eedfe8a4b5df34db473d900e3fb6f4c0df6f4710\", \"best_bid\":\"0.42\", \"best_ask\":\"0.43\"}], \"timestamp\":\"1785211376121\", \"event_type\":\"price_change\"}","received_at":"2026-07-28T04:02:59.834103Z","schema_version":"clob-market-ws.price_change.v1","sequence":null,"server_hash":null,"server_timestamp":"1785211376121","session_id":"2d607381e3054cee91998cdf45a4231c","source":"clob_market_ws"},"received_at":"2026-07-28T04:02:59.834103Z","record_id":"b9c9e3968a6b7723ea483fe2c4d106c9c2b9c6217177c7f9e0db1c2f9517bf2a","schema_fingerprint":"4aa3821a28b0b7c2400bc59aba4bcc0a76e971dadd19610d3ad38c768e124dc7","schema_version":"edge-lab-recorder.raw.v1","sequence":null,"source":"clob_market_ws"}
{"event_at":"2026-07-28T04:02:56.121000Z","event_fingerprint":"386f3bbea27701316d9f92c3bcf0f91d801fffae028132646c76c2ac29eac386","payload":{"connection_id":"f6725804f86a4c4eb588e4d5ed7db029","event_at":"2026-07-28T04:02:56.121000Z","event_type":"price_change","frame_hash":"60e3195251f340c747b14a0695a5be82dff134f271851c992967bca96209d33e","frame_index":0,"kind":"data","monotonic_ns":313362884813208,"payload":{"event_type":"price_change","market":"0xd412ce774cfcf8dc9f71164aac78783978aac7b03871702a3b8a481bd9dc9688","price_changes":[{"asset_id":"107603864457683460275633293642179940881969192120168665300712204232021063124301","best_ask":"0.58","best_bid":"0.57","hash":"90f3905134e9fa076db321d0886f7ee3993ea781","price":"0.01","side":"BUY","size":"7893.02"},{"asset_id":"96600821790790307414914106093858868634329285205417149685270682748367152458577","best_ask":"0.43","best_bid":"0.42","hash":"c5ddbdab84e42a6c6e557f06e185946dd99a8c7f","price":"0.99","side":"SELL","size":"7893.02"}],"timestamp":"1785211376121"},"payload_hash":"8c633a2d352e6775b786d6bf97dcb664e73116e18d15de6caeabd4bfddda6ef3","raw_frame":"{\"market\":\"0xd412ce774cfcf8dc9f71164aac78783978aac7b03871702a3b8a481bd9dc9688\", \"price_changes\":[{\"asset_id\":\"107603864457683460275633293642179940881969192120168665300712204232021063124301\", \"price\":\"0.01\", \"size\":\"7893.02\", \"side\":\"BUY\", \"hash\":\"90f3905134e9fa076db321d0886f7ee3993ea781\", \"best_bid\":\"0.57\", \"best_ask\":\"0.58\"}, {\"asset_id\":\"96600821790790307414914106093858868634329285205417149685270682748367152458577\", \"price\":\"0.99\", \"size\":\"7893.02\", \"side\":\"SELL\", \"hash\":\"c5ddbdab84e42a6c6e557f06e185946dd99a8c7f\", \"best_bid\":\"0.42\", \"best_ask\":\"0.43\"}], \"timestamp\":\"1785211376121\", \"event_type\":\"price_change\"}","received_at":"2026-07-28T04:02:59.835570Z","schema_version":"clob-market-ws.price_change.v1","sequence":null,"server_hash":null,"server_timestamp":"1785211376121","session_id":"2d607381e3054cee91998cdf45a4231c","source":"clob_market_ws"},"received_at":"2026-07-28T04:02:59.835570Z","record_id":"2898c7607c92776ce9942cd45d80b3736ae4a1a623a602a02407f7a42ce2b35a","schema_fingerprint":"4aa3821a28b0b7c2400bc59aba4bcc0a76e971dadd19610d3ad38c768e124dc7","schema_version":"edge-lab-recorder.raw.v1","sequence":null,"source":"clob_market_ws"}
{"event_at":"2026-07-28T04:02:56.122000Z","event_fingerprint":"b09c8a6b27df695d44e0c05aae1466817f59b311710572f059da44260b832176","payload":{"connection_id":"f6725804f86a4c4eb588e4d5ed7db029","event_at":"2026-07-28T04:02:56.122000Z","event_type":"price_change","frame_hash":"b837e2634e2fd90294b940259b1a462484dc0154666abe278bd69e00e739b28d","frame_index":0,"kind":"data","monotonic_ns":313362886298666,"payload":{"event_type":"price_change","market":"0xd412ce774cfcf8dc9f71164aac78783978aac7b03871702a3b8a481bd9dc9688","price_changes":[{"asset_id":"96600821790790307414914106093858868634329285205417149685270682748367152458577","best_ask":"0.43","best_bid":"0.42","hash":"3a905301e53f67aed9c937a24894bf5353673e2c","price":"0.41","side":"BUY","size":"86.88"},{"asset_id":"107603864457683460275633293642179940881969192120168665300712204232021063124301","best_ask":"0.58","best_bid":"0.57","hash":"b1fb56cd2374b0d18983a11760312ca0e1178ab3","price":"0.59","side":"SELL","size":"86.88"}],"timestamp":"1785211376122"},"payload_hash":"38d3b5fd265258a52b1fd91463aa80af49743038df6fb312bf7bd5e6bad617d9","raw_frame":"{\"market\":\"0xd412ce774cfcf8dc9f71164aac78783978aac7b03871702a3b8a481bd9dc9688\", \"price_changes\":[{\"asset_id\":\"96600821790790307414914106093858868634329285205417149685270682748367152458577\", \"price\":\"0.41\", \"size\":\"86.88\", \"side\":\"BUY\", \"hash\":\"3a905301e53f67aed9c937a24894bf5353673e2c\", \"best_bid\":\"0.42\", \"best_ask\":\"0.43\"}, {\"asset_id\":\"107603864457683460275633293642179940881969192120168665300712204232021063124301\", \"price\":\"0.59\", \"size\":\"86.88\", \"side\":\"SELL\", \"hash\":\"b1fb56cd2374b0d18983a11760312ca0e1178ab3\", \"best_bid\":\"0.57\", \"best_ask\":\"0.58\"}], \"timestamp\":\"1785211376122\", \"event_type\":\"price_change\"}","received_at":"2026-07-28T04:02:59.837056Z","schema_version":"clob-market-ws.price_change.v1","sequence":null,"server_hash":null,"server_timestamp":"1785211376122","session_id":"2d607381e3054cee91998cdf45a4231c","source":"clob_market_ws"},"received_at":"2026-07-28T04:02:59.837056Z","record_id":"1ff43eec92764f76675820b230b3de4ee2098a2f6f3fa052e53df7b3bd39d31f","schema_fingerprint":"4aa3821a28b0b7c2400bc59aba4bcc0a76e971dadd19610d3ad38c768e124dc7","schema_version":"edge-lab-recorder.raw.v1","sequence":null,"source":"clob_market_ws"}
{"event_at":"2026-07-28T04:02:56.123000Z","event_fingerprint":"38a205c29f5cbc3cb203315f5cb60a7cc5c4d35fe7394200bacbc2d0ef0c07b3","payload":{"connection_id":"f6725804f86a4c4eb588e4d5ed7db029","event_at":"2026-07-28T04:02:56.123000Z","event_type":"price_change","frame_hash":"6439926a9aaa1adcdd8e91fc5ab68d4db7a9c98d99c23f52b87fc44773e52fe4","frame_index":0,"kind":"data","monotonic_ns":313362887771583,"payload":{"event_type":"price_change","market":"0xd412ce774cfcf8dc9f71164aac78783978aac7b03871702a3b8a481bd9dc9688","price_changes":[{"asset_id":"107603864457683460275633293642179940881969192120168665300712204232021063124301","best_ask":"0.58","best_bid":"0.57","hash":"15e1839ffb0a755ada180825800afd7170976f7b","price":"0.59","side":"SELL","size":"81.88"},{"asset_id":"96600821790790307414914106093858868634329285205417149685270682748367152458577","best_ask":"0.43","best_bid":"0.42","hash":"2e36bcc80c9479078d1e0b95c69badeb2492f5ed","price":"0.41","side":"BUY","size":"81.88"}],"timestamp":"1785211376123"},"payload_hash":"d742c9276a421b54c24912cd730ea0c5f6198a8116f862f44ff6faae184a79e9","raw_frame":"{\"market\":\"0xd412ce774cfcf8dc9f71164aac78783978aac7b03871702a3b8a481bd9dc9688\", \"price_changes\":[{\"asset_id\":\"107603864457683460275633293642179940881969192120168665300712204232021063124301\", \"price\":\"0.59\", \"size\":\"81.88\", \"side\":\"SELL\", \"hash\":\"15e1839ffb0a755ada180825800afd7170976f7b\", \"best_bid\":\"0.57\", \"best_ask\":\"0.58\"}, {\"asset_id\":\"96600821790790307414914106093858868634329285205417149685270682748367152458577\", \"price\":\"0.41\", \"size\":\"81.88\", \"side\":\"BUY\", \"hash\":\"2e36bcc80c9479078d1e0b95c69badeb2492f5ed\", \"best_bid\":\"0.42\", \"best_ask\":\"0.43\"}], \"timestamp\":\"1785211376123\", \"event_type\":\"price_change\"}","received_at":"2026-07-28T04:02:59.838529Z","schema_version":"clob-market-ws.price_change.v1","sequence":null,"server_hash":null,"server_timestamp":"1785211376123","session_id":"2d607381e3054cee91998cdf45a4231c","source":"clob_market_ws"},"received_at":"2026-07-28T04:02:59.838529Z","record_id":"95e56f7f1b68158b347a5e8fc36f96bb4b305646af461c5ebe885d4af6853421","schema_fingerprint":"4aa3821a28b0b7c2400bc59aba4bcc0a76e971dadd19610d3ad38c768e124dc7","schema_version":"edge-lab-recorder.raw.v1","sequence":null,"source":"clob_market_ws"}
{"event_at":"2026-07-28T04:02:56.124000Z","event_fingerprint":"3e6262f6b1d628b3c313c2b79984a78b27c5bea1f773be22cb54749df702d1aa","payload":{"connection_id":"f6725804f86a4c4eb588e4d5ed7db029","event_at":"2026-07-28T04:02:56.124000Z","event_type":"price_change","frame_hash":"8b91a5106c9e3a807cb10fa80d696aff8f634c969be4150ee6be71af49fcad38","frame_index":0,"kind":"data","monotonic_ns":313362889225291,"payload":{"event_type":"price_change","market":"0xd412ce774cfcf8dc9f71164aac78783978aac7b03871702a3b8a481bd9dc9688","price_changes":[{"asset_id":"96600821790790307414914106093858868634329285205417149685270682748367152458577","best_ask":"0.43","best_bid":"0.42","hash":"42aaba1fa47ef65bcdc771e3261b3254874204d5","price":"0.42","side":"BUY","size":"122.6"},{"asset_id":"107603864457683460275633293642179940881969192120168665300712204232021063124301","best_ask":"0.58","best_bid":"0.57","hash":"b877c1977064df11551484decd75f42871454fd9","price":"0.58","side":"SELL","size":"122.6"}],"timestamp":"1785211376124"},"payload_hash":"0d79d7c969dc191b74230b0304b5758a98b59c8b71f57a1c4265ffab94949426","raw_frame":"{\"market\":\"0xd412ce774cfcf8dc9f71164aac78783978aac7b03871702a3b8a481bd9dc9688\", \"price_changes\":[{\"asset_id\":\"96600821790790307414914106093858868634329285205417149685270682748367152458577\", \"price\":\"0.42\", \"size\":\"122.6\", \"side\":\"BUY\", \"hash\":\"42aaba1fa47ef65bcdc771e3261b3254874204d5\", \"best_bid\":\"0.42\", \"best_ask\":\"0.43\"}, {\"asset_id\":\"107603864457683460275633293642179940881969192120168665300712204232021063124301\", \"price\":\"0.58\", \"size\":\"122.6\", \"side\":\"SELL\", \"hash\":\"b877c1977064df11551484decd75f42871454fd9\", \"best_bid\":\"0.57\", \"best_ask\":\"0.58\"}], \"timestamp\":\"1785211376124\", \"event_type\":\"price_change\"}","received_at":"2026-07-28T04:02:59.839983Z","schema_version":"clob-market-ws.price_change.v1","sequence":null,"server_hash":null,"server_timestamp":"1785211376124","session_id":"2d607381e3054cee91998cdf45a4231c","source":"clob_market_ws"},"received_at":"2026-07-28T04:02:59.839983Z","record_id":"ef4a31cc47756e1bf7a9757a09d6d17e50134c3f5e322149063314cac19d4124","schema_fingerprint":"4aa3821a28b0b7c2400bc59aba4bcc0a76e971dadd19610d3ad38c768e124dc7","schema_version":"edge-lab-recorder.raw.v1","sequence":null,"source":"clob_market_ws"}
{"event_at":"2026-07-28T04:02:56.127000Z","event_fingerprint":"c183cba33dfd72b534567e828bcb36fcb0bd5641bc84daf32b468ba4d9ef759e","payload":{"connection_id":"f6725804f86a4c4eb588e4d5ed7db029","event_at":"2026-07-28T04:02:56.127000Z","event_type":"price_change","frame_hash":"23a624825ff979339bd3c52d6c1335cf2665abaa5d1ed764b630e2f8c8f62cd0","frame_index":0,"kind":"data","monotonic_ns":313362890681416,"payload":{"event_type":"price_change","market":"0xd412ce774cfcf8dc9f71164aac78783978aac7b03871702a3b8a481bd9dc9688","price_changes":[{"asset_id":"107603864457683460275633293642179940881969192120168665300712204232021063124301","best_ask":"0.58","best_bid":"0.57","hash":"11ed21dead60f3bf3abd0592ed5a7eca5522a915","price":"0.56","side":"BUY","size":"21"},{"asset_id":"96600821790790307414914106093858868634329285205417149685270682748367152458577","best_ask":"0.43","best_bid":"0.42","hash":"22a2ce4d47dec4d1cbd0833123119fefcfb832b9","price":"0.44","side":"SELL","size":"21"}],"timestamp":"1785211376127"},"payload_hash":"631bff91f90d9ea8a9997a518cf0f285a20b5a81282b062064ad1c0fd64e288e","raw_frame":"{\"market\":\"0xd412ce774cfcf8dc9f71164aac78783978aac7b03871702a3b8a481bd9dc9688\", \"price_changes\":[{\"asset_id\":\"107603864457683460275633293642179940881969192120168665300712204232021063124301\", \"price\":\"0.56\", \"size\":\"21\", \"side\":\"BUY\", \"hash\":\"11ed21dead60f3bf3abd0592ed5a7eca5522a915\", \"best_bid\":\"0.57\", \"best_ask\":\"0.58\"}, {\"asset_id\":\"96600821790790307414914106093858868634329285205417149685270682748367152458577\", \"price\":\"0.44\", \"size\":\"21\", \"side\":\"SELL\", \"hash\":\"22a2ce4d47dec4d1cbd0833123119fefcfb832b9\", \"best_bid\":\"0.42\", \"best_ask\":\"0.43\"}], \"timestamp\":\"1785211376127\", \"event_type\":\"price_change\"}","received_at":"2026-07-28T04:02:59.841439Z","schema_version":"clob-market-ws.price_change.v1","sequence":null,"server_hash":null,"server_timestamp":"1785211376127","session_id":"2d607381e3054cee91998cdf45a4231c","source":"clob_market_ws"},"received_at":"2026-07-28T04:02:59.841439Z","record_id":"fbcc31f8774398b96e22e3cd0279d3d1d2ce66b5b383ec80e06c30f7b23742b3","schema_fingerprint":"4aa3821a28b0b7c2400bc59aba4bcc0a76e971dadd19610d3ad38c768e124dc7","schema_version":"edge-lab-recorder.raw.v1","sequence":null,"source":"clob_market_ws"}
{"event_at":"2026-07-28T04:02:56.128000Z","event_fingerprint":"4a9c109f8299634fa7d1dc117edf5907b8aca03a69d677581f75545520aa1bd1","payload":{"connection_id":"f6725804f86a4c4eb588e4d5ed7db029","event_at":"2026-07-28T04:02:56.128000Z","event_type":"price_change","frame_hash":"843abc540ffefa47739f2912db78db6108326700bc757f193699fa1289a2acf8","frame_index":0,"kind":"data","monotonic_ns":313362892125625,"payload":{"event_type":"price_change","market":"0xd412ce774cfcf8dc9f71164aac78783978aac7b03871702a3b8a481bd9dc9688","price_changes":[{"asset_id":"107603864457683460275633293642179940881969192120168665300712204232021063124301","best_ask":"0.58","best_bid":"0.57","hash":"433d10493ce69e89798c33ffc45a624c5b3b736e","price":"0.03","side":"BUY","size":"618.1"},{"asset_id":"96600821790790307414914106093858868634329285205417149685270682748367152458577","best_ask":"0.43","best_bid":"0.42","hash":"0fcad1428211cdd494dadc2aa5f79148fb2cb700","price":"0.97","side":"SELL","size":"618.1"}],"timestamp":"1785211376128"},"payload_hash":"f0dfcf4d3a6f55f78a5b021c41b1290593581ef21291886ef6c03eb16cbc1baa","raw_frame":"{\"market\":\"0xd412ce774cfcf8dc9f71164aac78783978aac7b03871702a3b8a481bd9dc9688\", \"price_changes\":[{\"asset_id\":\"107603864457683460275633293642179940881969192120168665300712204232021063124301\", \"price\":\"0.03\", \"size\":\"618.1\", \"side\":\"BUY\", \"hash\":\"433d10493ce69e89798c33ffc45a624c5b3b736e\", \"best_bid\":\"0.57\", \"best_ask\":\"0.58\"}, {\"asset_id\":\"96600821790790307414914106093858868634329285205417149685270682748367152458577\", \"price\":\"0.97\", \"size\":\"618.1\", \"side\":\"SELL\", \"hash\":\"0fcad1428211cdd494dadc2aa5f79148fb2cb700\", \"best_bid\":\"0.42\", \"best_ask\":\"0.43\"}], \"timestamp\":\"1785211376128\", \"event_type\":\"price_change\"}","received_at":"2026-07-28T04:02:59.842883Z","schema_version":"clob-market-ws.price_change.v1","sequence":null,"server_hash":null,"server_timestamp":"1785211376128","session_id":"2d607381e3054cee91998cdf45a4231c","source":"clob_market_ws"},"received_at":"2026-07-28T04:02:59.842883Z","record_id":"bce713457aeaf33c4eedcf730f5e86d55879f3a382d8c3e4ab605a7bcf71e921","schema_fingerprint":"4aa3821a28b0b7c2400bc59aba4bcc0a76e971dadd19610d3ad38c768e124dc7","schema_version":"edge-lab-recorder.raw.v1","sequence":null,"source":"clob_market_ws"}
{"event_at":"2026-07-28T04:02:56.132000Z","event_fingerprint":"5823918e38ddc2ed00346bbedbb21ade3c7ef94e001d6cd73b12071f53029c45","payload":{"connection_id":"f6725804f86a4c4eb588e4d5ed7db029","event_at":"2026-07-28T04:02:56.132000Z","event_type":"price_change","frame_hash":"b125fd3658784e5e8ee3a9b103064e66536ac22a46fbd3b30aeb0e8c0957f6a1","frame_index":0,"kind":"data","monotonic_ns":313362893598666,"payload":{"event_type":"price_change","market":"0xd412ce774cfcf8dc9f71164aac78783978aac7b03871702a3b8a481bd9dc9688","price_changes":[{"asset_id":"107603864457683460275633293642179940881969192120168665300712204232021063124301","best_ask":"0.58","best_bid":"0.57","hash":"2d5e3fa15ca187f22e39f8e58ec6710ca67e324d","price":"0.54","side":"BUY","size":"68.1"},{"asset_id":"96600821790790307414914106093858868634329285205417149685270682748367152458577","best_ask":"0.43","best_bid":"0.42","hash":"883a04837f5d11120bbd4847b2b97b6e7ccecc69","price":"0.46","side":"SELL","size":"68.1"}],"timestamp":"1785211376132"},"payload_hash":"461df4d75d5856bbd4f8d6fbdae3c8a13b03769873db0853772c370a320c89ed","raw_frame":"{\"market\":\"0xd412ce774cfcf8dc9f71164aac78783978aac7b03871702a3b8a481bd9dc9688\", \"price_changes\":[{\"asset_id\":\"107603864457683460275633293642179940881969192120168665300712204232021063124301\", \"price\":\"0.54\", \"size\":\"68.1\", \"side\":\"BUY\", \"hash\":\"2d5e3fa15ca187f22e39f8e58ec6710ca67e324d\", \"best_bid\":\"0.57\", \"best_ask\":\"0.58\"}, {\"asset_id\":\"96600821790790307414914106093858868634329285205417149685270682748367152458577\", \"price\":\"0.46\", \"size\":\"68.1\", \"side\":\"SELL\", \"hash\":\"883a04837f5d11120bbd4847b2b97b6e7ccecc69\", \"best_bid\":\"0.42\", \"best_ask\":\"0.43\"}], \"timestamp\":\"1785211376132\", \"event_type\":\"price_change\"}","received_at":"2026-07-28T04:02:59.844356Z","schema_version":"clob-market-ws.price_change.v1","sequence":null,"server_hash":null,"server_timestamp":"1785211376132","session_id":"2d607381e3054cee91998cdf45a4231c","source":"clob_market_ws"},"received_at":"2026-07-28T04:02:59.844356Z","record_id":"25012e2e8dcff0721c3949a5e89e214799be92a1a21a911e7a8a391fa51aef01","schema_fingerprint":"4aa3821a28b0b7c2400bc59aba4bcc0a76e971dadd19610d3ad38c768e124dc7","schema_version":"edge-lab-recorder.raw.v1","sequence":null,"source":"clob_market_ws"}
{"event_at":"2026-07-28T04:02:56.135000Z","event_fingerprint":"869463203543e991bbc4c116bc61c66262b10d4bcdad570dbee4841c1f180617","payload":{"connection_id":"f6725804f86a4c4eb588e4d5ed7db029","event_at":"2026-07-28T04:02:56.135000Z","event_type":"price_change","frame_hash":"93a3e6b00285c1ad01f4915f6f4593f0ae97f09c1dff094456ed5e41ab10454e","frame_index":0,"kind":"data","monotonic_ns":313362895035000,"payload":{"event_type":"price_change","market":"0xd412ce774cfcf8dc9f71164aac78783978aac7b03871702a3b8a481bd9dc9688","price_changes":[{"asset_id":"96600821790790307414914106093858868634329285205417149685270682748367152458577","best_ask":"0.43","best_bid":"0.42","hash":"57480b5d198b122989fd5bc3e9e5174f9980b20d","price":"0.42","side":"BUY","size":"117.6"},{"asset_id":"107603864457683460275633293642179940881969192120168665300712204232021063124301","best_ask":"0.58","best_bid":"0.57","hash":"893aa22f1957124d8390b23413e59e5f031c899d","price":"0.58","side":"SELL","size":"117.6"}],"timestamp":"1785211376135"},"payload_hash":"27547aa7ed0b867fd99206879d51a8d19899e44f4b0a7fa3f3c62b870fd23399","raw_frame":"{\"market\":\"0xd412ce774cfcf8dc9f71164aac78783978aac7b03871702a3b8a481bd9dc9688\", \"price_changes\":[{\"asset_id\":\"96600821790790307414914106093858868634329285205417149685270682748367152458577\", \"price\":\"0.42\", \"size\":\"117.6\", \"side\":\"BUY\", \"hash\":\"57480b5d198b122989fd5bc3e9e5174f9980b20d\", \"best_bid\":\"0.42\", \"best_ask\":\"0.43\"}, {\"asset_id\":\"107603864457683460275633293642179940881969192120168665300712204232021063124301\", \"price\":\"0.58\", \"size\":\"117.6\", \"side\":\"SELL\", \"hash\":\"893aa22f1957124d8390b23413e59e5f031c899d\", \"best_bid\":\"0.57\", \"best_ask\":\"0.58\"}], \"timestamp\":\"1785211376135\", \"event_type\":\"price_change\"}","received_at":"2026-07-28T04:02:59.845792Z","schema_version":"clob-market-ws.price_change.v1","sequence":null,"server_hash":null,"server_timestamp":"1785211376135","session_id":"2d607381e3054cee91998cdf45a4231c","source":"clob_market_ws"},"received_at":"2026-07-28T04:02:59.845792Z","record_id":"c8713c311f3efe2b4b7bf391cfc5357fa11ebc311a9dbbad5c3394a19d4d72a5","schema_fingerprint":"4aa3821a28b0b7c2400bc59aba4bcc0a76e971dadd19610d3ad38c768e124dc7","schema_version":"edge-lab-recorder.raw.v1","sequence":null,"source":"clob_market_ws"}
{"event_at":"2026-07-28T04:02:56.120000Z","event_fingerprint":"119a64dd32d85c0b4b3615ba27852a1e3fd7450951d3e5a2a886684a3e95f4fe","payload":{"connection_id":"f6725804f86a4c4eb588e4d5ed7db029","event_at":"2026-07-28T04:02:56.120000Z","event_type":"new_market","frame_hash":"ed09637ae4dee4969e3a4d676458dafff2ee61dd1d3b0cdd13ba957d50558756","frame_index":0,"kind":"data","monotonic_ns":313362896492208,"payload":{"active":true,"assets_ids":["75996424328869236634294978937045671870931734399943064068356239857052055752234","69038168289237559751909162224644568041422475615256203223497463504742833770230"],"clob_token_ids":["75996424328869236634294978937045671870931734399943064068356239857052055752234","69038168289237559751909162224644568041422475615256203223497463504742833770230"],"condition_id":"0xf2ca6281ffa8ee73994a6eec505e311b3a0a01fcba6bfd6489ad8c8c1e76de95","description":"In the upcoming game, scheduled for August 8, 2026 If the game ends in a draw within the first 45 minutes of regular play plus stoppage time, this market will resolve to \"Yes\". Otherwise, this market will resolve to \"No\". If the game is postponed, this market will remain open until the game has been completed. If the game is canceled entirely, with no make-up game, this market will resolve to \"Yes\". This market refers only to the outcome within the first 45 minutes of regular play plus stoppage time.The primary resolution source for this market is the official statistics of the event as recognized by the governing body or event organizers. However, if the governing body or event organizers have not published final match statistics within 24 hours after the event's conclusion, a consensus of credible reporting may be used instead. All markets will settle based on the official final result as recognized by the governing body or event organizers. Revisions to officially declared final scores made after market resolution will not be accounted for in determining the outcome.","event_message":{"description":"In the upcoming EFL Cup (Carabao Cup) game between Swansea City AFC and Birmingham City FC, scheduled for August 8, 2026 at 10:00 AM ET: This event contains halftime result markets for home, draw, and away outcomes within the first 45 minutes of regular play plus stoppage time.","id":"759538","slug":"efl-swa-bir-2026-08-08-halftime-result","ticker":"efl-swa-bir-2026-08-08-halftime-result","title":"Swansea City AFC vs. Birmingham City FC - Halftime Result"},"event_type":"new_market","fee_schedule":{"exponent":"1","rate":"0.05","rebate_rate":"0.15","taker_only":true},"fees_enabled":true,"game_start_time":"2026-08-08 14:00:00+00","group_item_title":"Draw","id":"3146701","line":"","market":"0xf2ca6281ffa8ee73994a6eec505e311b3a0a01fcba6bfd6489ad8c8c1e76de95","order_price_min_tick_size":"0.01","outcomes":["Yes","No"],"question":"Swansea City AFC vs. Birmingham City FC: Draw at halftime?","slug":"efl-swa-bir-2026-08-08-halftime-result-draw","sports_market_type":"soccer_halftime_result","tags":[],"taker_base_fee":"1000","timestamp":"1785211376120"},"payload_hash":"d728e211e5014fe463be9e9344247f42a5b290b76b42a612072cd7ac870ba5cb","raw_frame":"{\"id\":\"3146701\", \"question\":\"Swansea City AFC vs. Birmingham City FC: Draw at halftime?\", \"market\":\"0xf2ca6281ffa8ee73994a6eec505e311b3a0a01fcba6bfd6489ad8c8c1e76de95\", \"slug\":\"efl-swa-bir-2026-08-08-halftime-result-draw\", \"description\":\"In the upcoming game, scheduled for August 8, 2026 If the game ends in a draw within the first 45 minutes of regular play plus stoppage time, this market will resolve to \\\"Yes\\\". Otherwise, this market will resolve to \\\"No\\\". If the game is postponed, this market will remain open until the game has been completed. If the game is canceled entirely, with no make-up game, this market will resolve to \\\"Yes\\\". This market refers only to the outcome within the first 45 minutes of regular play plus stoppage time.The primary resolution source for this market is the official statistics of the event as recognized by the governing body or event organizers. However, if the governing body or event organizers have not published final match statistics within 24 hours after the event's conclusion, a consensus of credible reporting may be used instead. All markets will settle based on the official final result as recognized by the governing body or event organizers. Revisions to officially declared final scores made after market resolution will not be accounted for in determining the outcome.\", \"assets_ids\":[\"75996424328869236634294978937045671870931734399943064068356239857052055752234\", \"69038168289237559751909162224644568041422475615256203223497463504742833770230\"], \"outcomes\":[\"Yes\", \"No\"], \"event_message\":{\"id\":\"759538\", \"ticker\":\"efl-swa-bir-2026-08-08-halftime-result\", \"slug\":\"efl-swa-bir-2026-08-08-halftime-result\", \"title\":\"Swansea City AFC vs. Birmingham City FC - Halftime Result\", \"description\":\"In the upcoming EFL Cup (Carabao Cup) game between Swansea City AFC and Birmingham City FC, scheduled for August 8, 2026 at 10:00 AM ET: This event contains halftime result markets for home, draw, and away outcomes within the first 45 minutes of regular play plus stoppage time.\"}, \"timestamp\":\"1785211376120\", \"event_type\":\"new_market\", \"tags\":[], \"condition_id\":\"0xf2ca6281ffa8ee73994a6eec505e311b3a0a01fcba6bfd6489ad8c8c1e76de95\", \"active\":true, \"clob_token_ids\":[\"75996424328869236634294978937045671870931734399943064068356239857052055752234\", \"69038168289237559751909162224644568041422475615256203223497463504742833770230\"], \"sports_market_type\":\"soccer_halftime_result\", \"line\":\"\", \"game_start_time\":\"2026-08-08 14:00:00+00\", \"order_price_min_tick_size\":\"0.01\", \"group_item_title\":\"Draw\", \"taker_base_fee\":\"1000\", \"fees_enabled\":true, \"fee_schedule\":{\"exponent\":\"1\", \"rate\":\"0.05\", \"taker_only\":true, \"rebate_rate\":\"0.15\"}}","received_at":"2026-07-28T04:02:59.847250Z","schema_version":"clob-market-ws.new_market.v1","sequence":null,"server_hash":null,"server_timestamp":"1785211376120","session_id":"2d607381e3054cee91998cdf45a4231c","source":"clob_market_ws"},"received_at":"2026-07-28T04:02:59.847250Z","record_id":"d1f080fef7938ee54c9c98cc1eecb713d719216af615027aae4d324263438ce6","schema_fingerprint":"6639a822a7b79cfa4c3fc0044066e4f66ba8611f5bf361772bd6902a2319b82d","schema_version":"edge-lab-recorder.raw.v1","sequence":null,"source":"clob_market_ws"}
{"event_at":"2026-07-28T04:02:56.144000Z","event_fingerprint":"f946fd4803e6f476ba020691f48278db149249bb8dc28dc8862e63e782b0b154","payload":{"connection_id":"f6725804f86a4c4eb588e4d5ed7db029","event_at":"2026-07-28T04:02:56.144000Z","event_type":"price_change","frame_hash":"4ad613277c85c10a718d570aa62c208858c1b0523e03353908404471508e49b0","frame_index":0,"kind":"data","monotonic_ns":313362898382208,"payload":{"event_type":"price_change","market":"0xd412ce774cfcf8dc9f71164aac78783978aac7b03871702a3b8a481bd9dc9688","price_changes":[{"asset_id":"107603864457683460275633293642179940881969192120168665300712204232021063124301","best_ask":"0.58","best_bid":"0.57","hash":"4ec229906df11be720d80091fb9cdc78b19afe44","price":"0.01","side":"BUY","size":"7888.02"},{"asset_id":"96600821790790307414914106093858868634329285205417149685270682748367152458577","best_ask":"0.43","best_bid":"0.42","hash":"f6ab83d4e519449ca3d0f83756972da9a27ae578","price":"0.99","side":"SELL","size":"7888.02"}],"timestamp":"1785211376144"},"payload_hash":"b7704ebb22cba96d61ebf4165479596ae3f25cf930ec2b8225790df6d915c75c","raw_frame":"{\"market\":\"0xd412ce774cfcf8dc9f71164aac78783978aac7b03871702a3b8a481bd9dc9688\", \"price_changes\":[{\"asset_id\":\"107603864457683460275633293642179940881969192120168665300712204232021063124301\", \"price\":\"0.01\", \"size\":\"7888.02\", \"side\":\"BUY\", \"hash\":\"4ec229906df11be720d80091fb9cdc78b19afe44\", \"best_bid\":\"0.57\", \"best_ask\":\"0.58\"}, {\"asset_id\":\"96600821790790307414914106093858868634329285205417149685270682748367152458577\", \"price\":\"0.99\", \"size\":\"7888.02\", \"side\":\"SELL\", \"hash\":\"f6ab83d4e519449ca3d0f83756972da9a27ae578\", \"best_bid\":\"0.42\", \"best_ask\":\"0.43\"}], \"timestamp\":\"1785211376144\", \"event_type\":\"price_change\"}","received_at":"2026-07-28T04:02:59.849139Z","schema_version":"clob-market-ws.price_change.v1","sequence":null,"server_hash":null,"server_timestamp":"1785211376144","session_id":"2d607381e3054cee91998cdf45a4231c","source":"clob_market_ws"},"received_at":"2026-07-28T04:02:59.849139Z","record_id":"17fb753926286acd06b092dd57e1bc0b3167f81376cf39bd85a2df4e350eeff5","schema_fingerprint":"4aa3821a28b0b7c2400bc59aba4bcc0a76e971dadd19610d3ad38c768e124dc7","schema_version":"edge-lab-recorder.raw.v1","sequence":null,"source":"clob_market_ws"}
{"event_at":"2026-07-28T04:02:56.145000Z","event_fingerprint":"87453ebcba5621daf2bd5338f32e2aa5112d3c4fc53b74b9a7dea24f018ca176","payload":{"connection_id":"f6725804f86a4c4eb588e4d5ed7db029","event_at":"2026-07-28T04:02:56.145000Z","event_type":"price_change","frame_hash":"b27b1368ab9fec85ce13cb3ae031d68609dc35ec2af753e1824935064d25d4f3","frame_index":0,"kind":"data","monotonic_ns":313362899825916,"payload":{"event_type":"price_change","market":"0xd412ce774cfcf8dc9f71164aac78783978aac7b03871702a3b8a481bd9dc9688","price_changes":[{"asset_id":"96600821790790307414914106093858868634329285205417149685270682748367152458577","best_ask":"0.43","best_bid":"0.42","hash":"d243e2ec8cf5bebe13feffb15d41bfedcb7854af","price":"0.41","side":"BUY","size":"72.88"},{"asset_id":"107603864457683460275633293642179940881969192120168665300712204232021063124301","best_ask":"0.58","best_bid":"0.57","hash":"fb1e5fe051febe940d2ed5ccaae623fa581c10af","price":"0.59","side":"SELL","size":"72.88"}],"timestamp":"1785211376145"},"payload_hash":"90502f90eee2cb9f85ff49fab425bd3f2655c70e0f84b26952b15d86e78238bb","raw_frame":"{\"market\":\"0xd412ce774cfcf8dc9f71164aac78783978aac7b03871702a3b8a481bd9dc9688\", \"price_changes\":[{\"asset_id\":\"96600821790790307414914106093858868634329285205417149685270682748367152458577\", \"price\":\"0.41\", \"size\":\"72.88\", \"side\":\"BUY\", \"hash\":\"d243e2ec8cf5bebe13feffb15d41bfedcb7854af\", \"best_bid\":\"0.42\", \"best_ask\":\"0.43\"}, {\"asset_id\":\"107603864457683460275633293642179940881969192120168665300712204232021063124301\", \"price\":\"0.59\", \"size\":\"72.88\", \"side\":\"SELL\", \"hash\":\"fb1e5fe051febe940d2ed5ccaae623fa581c10af\", \"best_bid\":\"0.57\", \"best_ask\":\"0.58\"}], \"timestamp\":\"1785211376145\", \"event_type\":\"price_change\"}","received_at":"2026-07-28T04:02:59.850583Z","schema_version":"clob-market-ws.price_change.v1","sequence":null,"server_hash":null,"server_timestamp":"1785211376145","session_id":"2d607381e3054cee91998cdf45a4231c","source":"clob_market_ws"},"received_at":"2026-07-28T04:02:59.850583Z","record_id":"d10699a4e3cf6a0179d17ea4d8f86e045121fb9cee99ce214ffd53f9b977939e","schema_fingerprint":"4aa3821a28b0b7c2400bc59aba4bcc0a76e971dadd19610d3ad38c768e124dc7","schema_version":"edge-lab-recorder.raw.v1","sequence":null,"source":"clob_market_ws"}
{"event_at":"2026-07-28T04:02:56.146000Z","event_fingerprint":"30fd6ce8eaf997619b85d02be6e45085ee5524b7f0043f86a524908d881f27cc","payload":{"connection_id":"f6725804f86a4c4eb588e4d5ed7db029","event_at":"2026-07-28T04:02:56.146000Z","event_type":"price_change","frame_hash":"49cdd9cbb3729f44a105c7bb3fe72a403e5a6069cd4bee3560f50ce3ba179d7a","frame_index":0,"kind":"data","monotonic_ns":313362901301125,"payload":{"event_type":"price_change","market":"0xd412ce774cfcf8dc9f71164aac78783978aac7b03871702a3b8a481bd9dc9688","price_changes":[{"asset_id":"96600821790790307414914106093858868634329285205417149685270682748367152458577","best_ask":"0.43","best_bid":"0.42","hash":"a344692cd6abba8a640ea692204815cf8634798d","price":"0.42","side":"BUY","size":"93.6"},{"asset_id":"107603864457683460275633293642179940881969192120168665300712204232021063124301","best_ask":"0.58","best_bid":"0.57","hash":"28aeadbb5e11e948ddb95efb64d1fa5b51bed1ea","price":"0.58","side":"SELL","size":"93.6"}],"timestamp":"1785211376146"},"payload_hash":"2bbb114cdb4071975dc5e1c7074e6ad268d475770e69605fc75f7b09e95894be","raw_frame":"{\"market\":\"0xd412ce774cfcf8dc9f71164aac78783978aac7b03871702a3b8a481bd9dc9688\", \"price_changes\":[{\"asset_id\":\"96600821790790307414914106093858868634329285205417149685270682748367152458577\", \"price\":\"0.42\", \"size\":\"93.6\", \"side\":\"BUY\", \"hash\":\"a344692cd6abba8a640ea692204815cf8634798d\", \"best_bid\":\"0.42\", \"best_ask\":\"0.43\"}, {\"asset_id\":\"107603864457683460275633293642179940881969192120168665300712204232021063124301\", \"price\":\"0.58\", \"size\":\"93.6\", \"side\":\"SELL\", \"hash\":\"28aeadbb5e11e948ddb95efb64d1fa5b51bed1ea\", \"best_bid\":\"0.57\", \"best_ask\":\"0.58\"}], \"timestamp\":\"1785211376146\", \"event_type\":\"price_change\"}","received_at":"2026-07-28T04:02:59.852058Z","schema_version":"clob-market-ws.price_change.v1","sequence":null,"server_hash":null,"server_timestamp":"1785211376146","session_id":"2d607381e3054cee91998cdf45a4231c","source":"clob_market_ws"},"received_at":"2026-07-28T04:02:59.852058Z","record_id":"453f165ac45849e0ca80ad8907bbc28b9e1b15199d26f70315a3122dd84df7ba","schema_fingerprint":"4aa3821a28b0b7c2400bc59aba4bcc0a76e971dadd19610d3ad38c768e124dc7","schema_version":"edge-lab-recorder.raw.v1","sequence":null,"source":"clob_market_ws"}
{"event_at":"2026-07-28T04:02:56.148000Z","event_fingerprint":"ae064e25fae4896af6da9cf3bf642fd8585c0b31c71810cccdfc81614467f9b5","payload":{"connection_id":"f6725804f86a4c4eb588e4d5ed7db029","event_at":"2026-07-28T04:02:56.148000Z","event_type":"price_change","frame_hash":"0f8f40863082268f6b9a4f91efa858444eae5a3c0da373a30c6b3902ce489e05","frame_index":0,"kind":"data","monotonic_ns":313362902740750,"payload":{"event_type":"price_change","market":"0xd412ce774cfcf8dc9f71164aac78783978aac7b03871702a3b8a481bd9dc9688","price_changes":[{"asset_id":"107603864457683460275633293642179940881969192120168665300712204232021063124301","best_ask":"0.58","best_bid":"0.57","hash":"9e6c492d9fcc19cc11d5b1dad51e12f6f11606ed","price":"0.48","side":"BUY","size":"221"},{"asset_id":"96600821790790307414914106093858868634329285205417149685270682748367152458577","best_ask":"0.43","best_bid":"0.42","hash":"62aa79b70c0eaae464ee3857da20ac4d4e059b5a","price":"0.52","side":"SELL","size":"221"}],"timestamp":"1785211376148"},"payload_hash":"c6b78ad41b04660b4d04214ff113643e5edc2e698e336e9ebecea4c3367f950a","raw_frame":"{\"market\":\"0xd412ce774cfcf8dc9f71164aac78783978aac7b03871702a3b8a481bd9dc9688\", \"price_changes\":[{\"asset_id\":\"107603864457683460275633293642179940881969192120168665300712204232021063124301\", \"price\":\"0.48\", \"size\":\"221\", \"side\":\"BUY\", \"hash\":\"9e6c492d9fcc19cc11d5b1dad51e12f6f11606ed\", \"best_bid\":\"0.57\", \"best_ask\":\"0.58\"}, {\"asset_id\":\"96600821790790307414914106093858868634329285205417149685270682748367152458577\", \"price\":\"0.52\", \"size\":\"221\", \"side\":\"SELL\", \"hash\":\"62aa79b70c0eaae464ee3857da20ac4d4e059b5a\", \"best_bid\":\"0.42\", \"best_ask\":\"0.43\"}], \"timestamp\":\"1785211376148\", \"event_type\":\"price_change\"}","received_at":"2026-07-28T04:02:59.853498Z","schema_version":"clob-market-ws.price_change.v1","sequence":null,"server_hash":null,"server_timestamp":"1785211376148","session_id":"2d607381e3054cee91998cdf45a4231c","source":"clob_market_ws"},"received_at":"2026-07-28T04:02:59.853498Z","record_id":"b34483cc15069f4cedfe9b11deea2135f645f8e0d9604d365660f7a49c1eb5e8","schema_fingerprint":"4aa3821a28b0b7c2400bc59aba4bcc0a76e971dadd19610d3ad38c768e124dc7","schema_version":"edge-lab-recorder.raw.v1","sequence":null,"source":"clob_market_ws"}
{"event_at":"2026-07-28T04:02:56.151000Z","event_fingerprint":"0ae52eab322b6488f596d89d12a950ed8a3e51cec4419765621af947a63b6f08","payload":{"connection_id":"f6725804f86a4c4eb588e4d5ed7db029","event_at":"2026-07-28T04:02:56.151000Z","event_type":"best_bid_ask","frame_hash":"80645872e0170fe20d159499fe2d01664ce62db692c7f72a24ec2f9035729eef","frame_index":0,"kind":"data","monotonic_ns":313362904198333,"payload":{"asset_id":"107603864457683460275633293642179940881969192120168665300712204232021063124301","best_ask":"0.58","best_bid":"0.57","event_type":"best_bid_ask","market":"0xd412ce774cfcf8dc9f71164aac78783978aac7b03871702a3b8a481bd9dc9688","spread":"0.01","timestamp":"1785211376151"},"payload_hash":"0b04b728d2a5005134b3fdd3538ba2685a8c7086ef75871a2c08f47ddb98a1b1","raw_frame":"{\"market\":\"0xd412ce774cfcf8dc9f71164aac78783978aac7b03871702a3b8a481bd9dc9688\", \"asset_id\":\"107603864457683460275633293642179940881969192120168665300712204232021063124301\", \"best_bid\":\"0.57\", \"best_ask\":\"0.58\", \"spread\":\"0.01\", \"timestamp\":\"1785211376151\", \"event_type\":\"best_bid_ask\"}","received_at":"2026-07-28T04:02:59.854956Z","schema_version":"clob-market-ws.best_bid_ask.v1","sequence":null,"server_hash":null,"server_timestamp":"1785211376151","session_id":"2d607381e3054cee91998cdf45a4231c","source":"clob_market_ws"},"received_at":"2026-07-28T04:02:59.854956Z","record_id":"56c368a64321a73c0e460d936855a4df3a171c12be80548b5accdcde348c1928","schema_fingerprint":"8488399f31b0337811b13b266be932db7062827c2470b78bd8e9e99bab51d17d","schema_version":"edge-lab-recorder.raw.v1","sequence":null,"source":"clob_market_ws"}
{"event_at":"2026-07-28T04:02:56.151000Z","event_fingerprint":"9ef8edd7e35da1441142077a7315eb9a349e21025ad0eee57bcf48add042a600","payload":{"connection_id":"f6725804f86a4c4eb588e4d5ed7db029","event_at":"2026-07-28T04:02:56.151000Z","event_type":"best_bid_ask","frame_hash":"e2b749aba49fca789307695ac308b1613c8d05670e28cbf3839eb397e90fd9d1","frame_index":0,"kind":"data","monotonic_ns":313362905222750,"payload":{"asset_id":"96600821790790307414914106093858868634329285205417149685270682748367152458577","best_ask":"0.43","best_bid":"0.42","event_type":"best_bid_ask","market":"0xd412ce774cfcf8dc9f71164aac78783978aac7b03871702a3b8a481bd9dc9688","spread":"0.01","timestamp":"1785211376151"},"payload_hash":"d01cb5d25b60e01ab4be33a36a1731a084afb0f03c0a22cda53c81eb55448405","raw_frame":"{\"market\":\"0xd412ce774cfcf8dc9f71164aac78783978aac7b03871702a3b8a481bd9dc9688\", \"asset_id\":\"96600821790790307414914106093858868634329285205417149685270682748367152458577\", \"best_bid\":\"0.42\", \"best_ask\":\"0.43\", \"spread\":\"0.01\", \"timestamp\":\"1785211376151\", \"event_type\":\"best_bid_ask\"}","received_at":"2026-07-28T04:02:59.855980Z","schema_version":"clob-market-ws.best_bid_ask.v1","sequence":null,"server_hash":null,"server_timestamp":"1785211376151","session_id":"2d607381e3054cee91998cdf45a4231c","source":"clob_market_ws"},"received_at":"2026-07-28T04:02:59.855980Z","record_id":"8805a581177acc7a69560eec5ebdf3864ad68a21a93928b091ae9db2664c5f50","schema_fingerprint":"8488399f31b0337811b13b266be932db7062827c2470b78bd8e9e99bab51d17d","schema_version":"edge-lab-recorder.raw.v1","sequence":null,"source":"clob_market_ws"}
{"event_at":"2026-07-28T04:02:56.151000Z","event_fingerprint":"8621b3b0954897c056347c3222973fe6c2f0d32b43122fad22e3e5465e79ae05","payload":{"connection_id":"f6725804f86a4c4eb588e4d5ed7db029","event_at":"2026-07-28T04:02:56.151000Z","event_type":"price_change","frame_hash":"5fa38deec511e927f6003940b6593d6e69fdd52e985c2541e4c55a253d3592bc","frame_index":0,"kind":"data","monotonic_ns":313362906314666,"payload":{"event_type":"price_change","market":"0xd412ce774cfcf8dc9f71164aac78783978aac7b03871702a3b8a481bd9dc9688","price_changes":[{"asset_id":"107603864457683460275633293642179940881969192120168665300712204232021063124301","best_ask":"0.58","best_bid":"0.57","hash":"3e0b53049f2f58eca7eb572769d7a42b56233342","price":"0.57","side":"BUY","size":"26.58"},{"asset_id":"96600821790790307414914106093858868634329285205417149685270682748367152458577","best_ask":"0.43","best_bid":"0.42","hash":"ab59a2a660e3264b8ca59378f8801b80671e1a3f","price":"0.43","side":"SELL","size":"26.58"}],"timestamp":"1785211376151"},"payload_hash":"94da4ae9ef2b213e5534dd36f1269f93ce247260acf290a512ba3e6818b86989","raw_frame":"{\"market\":\"0xd412ce774cfcf8dc9f71164aac78783978aac7b03871702a3b8a481bd9dc9688\", \"price_changes\":[{\"asset_id\":\"107603864457683460275633293642179940881969192120168665300712204232021063124301\", \"price\":\"0.57\", \"size\":\"26.58\", \"side\":\"BUY\", \"hash\":\"3e0b53049f2f58eca7eb572769d7a42b56233342\", \"best_bid\":\"0.57\", \"best_ask\":\"0.58\"}, {\"asset_id\":\"96600821790790307414914106093858868634329285205417149685270682748367152458577\", \"price\":\"0.43\", \"size\":\"26.58\", \"side\":\"SELL\", \"hash\":\"ab59a2a660e3264b8ca59378f8801b80671e1a3f\", \"best_bid\":\"0.42\", \"best_ask\":\"0.43\"}], \"timestamp\":\"1785211376151\", \"event_type\":\"price_change\"}","received_at":"2026-07-28T04:02:59.857072Z","schema_version":"clob-market-ws.price_change.v1","sequence":null,"server_hash":null,"server_timestamp":"1785211376151","session_id":"2d607381e3054cee91998cdf45a4231c","source":"clob_market_ws"},"received_at":"2026-07-28T04:02:59.857072Z","record_id":"6bf3facc81947f4d16b9184da46ce15df34f4e9798c7a09a533ba2310bc2af6c","schema_fingerprint":"4aa3821a28b0b7c2400bc59aba4bcc0a76e971dadd19610d3ad38c768e124dc7","schema_version":"edge-lab-recorder.raw.v1","sequence":null,"source":"clob_market_ws"}
{"event_at":"2026-07-28T04:02:56.151000Z","event_fingerprint":"9760f4aa847f8c31c3f6802a24fdf62b9307e3d3958f796ee826a6b951aa35ee","payload":{"connection_id":"f6725804f86a4c4eb588e4d5ed7db029","event_at":"2026-07-28T04:02:56.151000Z","event_type":"book","frame_hash":"c49a831ddfa82905b8c1aea53b6580b05b4f8e7e0dc0ac79d4dbd669f7c1a0e1","frame_index":0,"kind":"data","monotonic_ns":313362907743666,"payload":{"asks":[{"price":"0.99","size":"7853.02"},{"price":"0.98","size":"728.1"},{"price":"0.97","size":"776.43"},{"price":"0.96","size":"638.09"},{"price":"0.95","size":"726.2"},{"price":"0.94","size":"675.2"},{"price":"0.93","size":"565.1"},{"price":"0.92","size":"567.79"},{"price":"0.91","size":"581.6"},{"price":"0.9","size":"107.29"},{"price":"0.89","size":"43.6"},{"price":"0.88","size":"80.4"},{"price":"0.87","size":"37.5"},{"price":"0.86","size":"34.9"},{"price":"0.85","size":"87.5"},{"price":"0.84","size":"41.3"},{"price":"0.83","size":"30.3"},{"price":"0.82","size":"58.3"},{"price":"0.81","size":"27.5"},{"price":"0.8","size":"54.8"},{"price":"0.79","size":"56.1"},{"price":"0.78","size":"176.01"},{"price":"0.77","size":"176.3"},{"price":"0.76","size":"53.39"},{"price":"0.75","size":"45"},{"price":"0.74","size":"28.6"},{"price":"0.73","size":"58.2"},{"price":"0.72","size":"20.9"},{"price":"0.71","size":"26.91"},{"price":"0.7","size":"56.3"},{"price":"0.69","size":"13.79"},{"price":"0.68","size":"29.58"},{"price":"0.67","size":"64.41"},{"price":"0.66","size":"134.65"},{"price":"0.65","size":"14"},{"price":"0.64","size":"64.38"},{"price":"0.63","size":"44.38"},{"price":"0.62","size":"40.38"},{"price":"0.61","size":"19"},{"price":"0.6","size":"56.58"},{"price":"0.59","size":"72.88"},{"price":"0.58","size":"93.6"}],"asset_id":"107603864457683460275633293642179940881969192120168665300712204232021063124301","bids":[{"price":"0.01","size":"7888.02"},{"price":"0.02","size":"733.1"},{"price":"0.03","size":"618.1"},{"price":"0.04","size":"668.09"},{"price":"0.05","size":"803.2"},{"price":"0.06","size":"623.2"},{"price":"0.07","size":"576.1"},{"price":"0.08","size":"550.79"},{"price":"0.09","size":"536.6"},{"price":"0.1","size":"123.29"},{"price":"0.11","size":"43.6"},{"price":"0.12","size":"50.4"},{"price":"0.13","size":"67.5"},{"price":"0.14","size":"34.9"},{"price":"0.15","size":"64.5"},{"price":"0.16","size":"71.3"},{"price":"0.17","size":"30.3"},{"price":"0.18","size":"28.3"},{"price":"0.19","size":"57.5"},{"price":"0.2","size":"59.8"},{"price":"0.21","size":"26.1"},{"price":"0.22","size":"54.5"},{"price":"0.23","size":"23.89"},{"price":"0.24","size":"23.39"},{"price":"0.25","size":"82"},{"price":"0.26","size":"21.6"},{"price":"0.27","size":"21.2"},{"price":"0.28","size":"50.9"},{"price":"0.29","size":"20.6"},{"price":"0.3","size":"47.3"},{"price":"0.31","size":"50"},{"price":"0.32","size":"19.8"},{"price":"0.33","size":"120.61"},{"price":"0.34","size":"49.4"},{"price":"0.35","size":"38.2"},{"price":"0.36","size":"18"},{"price":"0.37","size":"47.9"},{"price":"0.38","size":"27.7"},{"price":"0.39","size":"117.6"},{"price":"0.4","size":"171.5"},{"price":"0.41","size":"117.4"},{"price":"0.42","size":"62.63"},{"price":"0.43","size":"52.2"},{"price":"0.44","size":"62.2"},{"price":"0.45","size":"70"},{"price":"0.46","size":"87"},{"price":"0.47","size":"177"},{"price":"0.48","size":"221"},{"price":"0.49","size":"228.99"},{"price":"0.5","size":"269.99"},{"price":"0.51","size":"159"},{"price":"0.52","size":"168"},{"price":"0.53","size":"54"},{"price":"0.54","size":"68.1"},{"price":"0.55","size":"16"},{"price":"0.56","size":"21"},{"price":"0.57","size":"26.58"}],"event_type":"book","hash":"3e0b53049f2f58eca7eb572769d7a42b56233342","market":"0xd412ce774cfcf8dc9f71164aac78783978aac7b03871702a3b8a481bd9dc9688","timestamp":"1785211376151"},"payload_hash":"a8fd0c1dd0f26d5ac96fa2ef68f94205893df3b95e1a42ba2c88715ec7baa174","raw_frame":"{\"market\":\"0xd412ce774cfcf8dc9f71164aac78783978aac7b03871702a3b8a481bd9dc9688\", \"asset_id\":\"107603864457683460275633293642179940881969192120168665300712204232021063124301\", \"bids\":[{\"price\":\"0.01\", \"size\":\"7888.02\"}, {\"price\":\"0.02\", \"size\":\"733.1\"}, {\"price\":\"0.03\", \"size\":\"618.1\"}, {\"price\":\"0.04\", \"size\":\"668.09\"}, {\"price\":\"0.05\", \"size\":\"803.2\"}, {\"price\":\"0.06\", \"size\":\"623.2\"}, {\"price\":\"0.07\", \"size\":\"576.1\"}, {\"price\":\"0.08\", \"size\":\"550.79\"}, {\"price\":\"0.09\", \"size\":\"536.6\"}, {\"price\":\"0.1\", \"size\":\"123.29\"}, {\"price\":\"0.11\", \"size\":\"43.6\"}, {\"price\":\"0.12\", \"size\":\"50.4\"}, {\"price\":\"0.13\", \"size\":\"67.5\"}, {\"price\":\"0.14\", \"size\":\"34.9\"}, {\"price\":\"0.15\", \"size\":\"64.5\"}, {\"price\":\"0.16\", \"size\":\"71.3\"}, {\"price\":\"0.17\", \"size\":\"30.3\"}, {\"price\":\"0.18\", \"size\":\"28.3\"}, {\"price\":\"0.19\", \"size\":\"57.5\"}, {\"price\":\"0.2\", \"size\":\"59.8\"}, {\"price\":\"0.21\", \"size\":\"26.1\"}, {\"price\":\"0.22\", \"size\":\"54.5\"}, {\"price\":\"0.23\", \"size\":\"23.89\"}, {\"price\":\"0.24\", \"size\":\"23.39\"}, {\"price\":\"0.25\", \"size\":\"82\"}, {\"price\":\"0.26\", \"size\":\"21.6\"}, {\"price\":\"0.27\", \"size\":\"21.2\"}, {\"price\":\"0.28\", \"size\":\"50.9\"}, {\"price\":\"0.29\", \"size\":\"20.6\"}, {\"price\":\"0.3\", \"size\":\"47.3\"}, {\"price\":\"0.31\", \"size\":\"50\"}, {\"price\":\"0.32\", \"size\":\"19.8\"}, {\"price\":\"0.33\", \"size\":\"120.61\"}, {\"price\":\"0.34\", \"size\":\"49.4\"}, {\"price\":\"0.35\", \"size\":\"38.2\"}, {\"price\":\"0.36\", \"size\":\"18\"}, {\"price\":\"0.37\", \"size\":\"47.9\"}, {\"price\":\"0.38\", \"size\":\"27.7\"}, {\"price\":\"0.39\", \"size\":\"117.6\"}, {\"price\":\"0.4\", \"size\":\"171.5\"}, {\"price\":\"0.41\", \"size\":\"117.4\"}, {\"price\":\"0.42\", \"size\":\"62.63\"}, {\"price\":\"0.43\", \"size\":\"52.2\"}, {\"price\":\"0.44\", \"size\":\"62.2\"}, {\"price\":\"0.45\", \"size\":\"70\"}, {\"price\":\"0.46\", \"size\":\"87\"}, {\"price\":\"0.47\", \"size\":\"177\"}, {\"price\":\"0.48\", \"size\":\"221\"}, {\"price\":\"0.49\", \"size\":\"228.99\"}, {\"price\":\"0.5\", \"size\":\"269.99\"}, {\"price\":\"0.51\", \"size\":\"159\"}, {\"price\":\"0.52\", \"size\":\"168\"}, {\"price\":\"0.53\", \"size\":\"54\"}, {\"price\":\"0.54\", \"size\":\"68.1\"}, {\"price\":\"0.55\", \"size\":\"16\"}, {\"price\":\"0.56\", \"size\":\"21\"}, {\"price\":\"0.57\", \"size\":\"26.58\"}], \"asks\":[{\"price\":\"0.99\", \"size\":\"7853.02\"}, {\"price\":\"0.98\", \"size\":\"728.1\"}, {\"price\":\"0.97\", \"size\":\"776.43\"}, {\"price\":\"0.96\", \"size\":\"638.09\"}, {\"price\":\"0.95\", \"size\":\"726.2\"}, {\"price\":\"0.94\", \"size\":\"675.2\"}, {\"price\":\"0.93\", \"size\":\"565.1\"}, {\"price\":\"0.92\", \"size\":\"567.79\"}, {\"price\":\"0.91\", \"size\":\"581.6\"}, {\"price\":\"0.9\", \"size\":\"107.29\"}, {\"price\":\"0.89\", \"size\":\"43.6\"}, {\"price\":\"0.88\", \"size\":\"80.4\"}, {\"price\":\"0.87\", \"size\":\"37.5\"}, {\"price\":\"0.86\", \"size\":\"34.9\"}, {\"price\":\"0.85\", \"size\":\"87.5\"}, {\"price\":\"0.84\", \"size\":\"41.3\"}, {\"price\":\"0.83\", \"size\":\"30.3\"}, {\"price\":\"0.82\", \"size\":\"58.3\"}, {\"price\":\"0.81\", \"size\":\"27.5\"}, {\"price\":\"0.8\", \"size\":\"54.8\"}, {\"price\":\"0.79\", \"size\":\"56.1\"}, {\"price\":\"0.78\", \"size\":\"176.01\"}, {\"price\":\"0.77\", \"size\":\"176.3\"}, {\"price\":\"0.76\", \"size\":\"53.39\"}, {\"price\":\"0.75\", \"size\":\"45\"}, {\"price\":\"0.74\", \"size\":\"28.6\"}, {\"price\":\"0.73\", \"size\":\"58.2\"}, {\"price\":\"0.72\", \"size\":\"20.9\"}, {\"price\":\"0.71\", \"size\":\"26.91\"}, {\"price\":\"0.7\", \"size\":\"56.3\"}, {\"price\":\"0.69\", \"size\":\"13.79\"}, {\"price\":\"0.68\", \"size\":\"29.58\"}, {\"price\":\"0.67\", \"size\":\"64.41\"}, {\"price\":\"0.66\", \"size\":\"134.65\"}, {\"price\":\"0.65\", \"size\":\"14\"}, {\"price\":\"0.64\", \"size\":\"64.38\"}, {\"price\":\"0.63\", \"size\":\"44.38\"}, {\"price\":\"0.62\", \"size\":\"40.38\"}, {\"price\":\"0.61\", \"size\":\"19\"}, {\"price\":\"0.6\", \"size\":\"56.58\"}, {\"price\":\"0.59\", \"size\":\"72.88\"}, {\"price\":\"0.58\", \"size\":\"93.6\"}], \"hash\":\"3e0b53049f2f58eca7eb572769d7a42b56233342\", \"timestamp\":\"1785211376151\", \"event_type\":\"book\"}","received_at":"2026-07-28T04:02:59.858501Z","schema_version":"clob-market-ws.book.v1","sequence":null,"server_hash":"3e0b53049f2f58eca7eb572769d7a42b56233342","server_timestamp":"1785211376151","session_id":"2d607381e3054cee91998cdf45a4231c","source":"clob_market_ws"},"received_at":"2026-07-28T04:02:59.858501Z","record_id":"c0ec498db77c51ff6d95ba6dbd5a7a2491dd37c30727e0873a09b07d80f4e168","schema_fingerprint":"dc2caa1c89c6a7426e2e07ff925910cd4d0a8a223a515d4092d91d6d127aacb6","schema_version":"edge-lab-recorder.raw.v1","sequence":null,"source":"clob_market_ws"}
{"event_at":"2026-07-28T04:02:56.151000Z","event_fingerprint":"ab887a71ea76d10ad508d7b01551810b1d249d81c17a4791c1c37b82fffdbee2","payload":{"connection_id":"f6725804f86a4c4eb588e4d5ed7db029","event_at":"2026-07-28T04:02:56.151000Z","event_type":"book","frame_hash":"aa47c92a0b507bb3f618946c1f7f74dd09132196050037d260624350e8fe71ca","frame_index":0,"kind":"data","monotonic_ns":313362919855583,"payload":{"asks":[{"price":"0.99","size":"7888.02"},{"price":"0.98","size":"733.1"},{"price":"0.97","size":"618.1"},{"price":"0.96","size":"668.09"},{"price":"0.95","size":"803.2"},{"price":"0.94","size":"623.2"},{"price":"0.93","size":"576.1"},{"price":"0.92","size":"550.79"},{"price":"0.91","size":"536.6"},{"price":"0.9","size":"123.29"},{"price":"0.89","size":"43.6"},{"price":"0.88","size":"50.4"},{"price":"0.87","size":"67.5"},{"price":"0.86","size":"34.9"},{"price":"0.85","size":"64.5"},{"price":"0.84","size":"71.3"},{"price":"0.83","size":"30.3"},{"price":"0.82","size":"28.3"},{"price":"0.81","size":"57.5"},{"price":"0.8","size":"59.8"},{"price":"0.79","size":"26.1"},{"price":"0.78","size":"54.5"},{"price":"0.77","size":"23.89"},{"price":"0.76","size":"23.39"},{"price":"0.75","size":"82"},{"price":"0.74","size":"21.6"},{"price":"0.73","size":"21.2"},{"price":"0.72","size":"50.9"},{"price":"0.71","size":"20.6"},{"price":"0.7","size":"47.3"},{"price":"0.69","size":"50"},{"price":"0.68","size":"19.8"},{"price":"0.67","size":"120.61"},{"price":"0.66","size":"49.4"},{"price":"0.65","size":"38.2"},{"price":"0.64","size":"18"},{"price":"0.63","size":"47.9"},{"price":"0.62","size":"27.7"},{"price":"0.61","size":"117.6"},{"price":"0.6","size":"171.5"},{"price":"0.59","size":"117.4"},{"price":"0.58","size":"62.63"},{"price":"0.57","size":"52.2"},{"price":"0.56","size":"62.2"},{"price":"0.55","size":"70"},{"price":"0.54","size":"87"},{"price":"0.53","size":"177"},{"price":"0.52","size":"221"},{"price":"0.51","size":"228.99"},{"price":"0.5","size":"269.99"},{"price":"0.49","size":"159"},{"price":"0.48","size":"168"},{"price":"0.47","size":"54"},{"price":"0.46","size":"68.1"},{"price":"0.45","size":"16"},{"price":"0.44","size":"21"},{"price":"0.43","size":"26.58"}],"asset_id":"96600821790790307414914106093858868634329285205417149685270682748367152458577","bids":[{"price":"0.01","size":"7853.02"},{"price":"0.02","size":"728.1"},{"price":"0.03","size":"776.43"},{"price":"0.04","size":"638.09"},{"price":"0.05","size":"726.2"},{"price":"0.06","size":"675.2"},{"price":"0.07","size":"565.1"},{"price":"0.08","size":"567.79"},{"price":"0.09","size":"581.6"},{"price":"0.1","size":"107.29"},{"price":"0.11","size":"43.6"},{"price":"0.12","size":"80.4"},{"price":"0.13","size":"37.5"},{"price":"0.14","size":"34.9"},{"price":"0.15","size":"87.5"},{"price":"0.16","size":"41.3"},{"price":"0.17","size":"30.3"},{"price":"0.18","size":"58.3"},{"price":"0.19","size":"27.5"},{"price":"0.2","size":"54.8"},{"price":"0.21","size":"56.1"},{"price":"0.22","size":"176.01"},{"price":"0.23","size":"176.3"},{"price":"0.24","size":"53.39"},{"price":"0.25","size":"45"},{"price":"0.26","size":"28.6"},{"price":"0.27","size":"58.2"},{"price":"0.28","size":"20.9"},{"price":"0.29","size":"26.91"},{"price":"0.3","size":"56.3"},{"price":"0.31","size":"13.79"},{"price":"0.32","size":"29.58"},{"price":"0.33","size":"64.41"},{"price":"0.34","size":"134.65"},{"price":"0.35","size":"14"},{"price":"0.36","size":"64.38"},{"price":"0.37","size":"44.38"},{"price":"0.38","size":"40.38"},{"price":"0.39","size":"19"},{"price":"0.4","size":"56.58"},{"price":"0.41","size":"72.88"},{"price":"0.42","size":"93.6"}],"event_type":"book","hash":"ab59a2a660e3264b8ca59378f8801b80671e1a3f","market":"0xd412ce774cfcf8dc9f71164aac78783978aac7b03871702a3b8a481bd9dc9688","timestamp":"1785211376151"},"payload_hash":"a68a8354f467888852c86b7842f2bd8f7b69366ae68e911ff3305ad2b8e78d1a","raw_frame":"{\"market\":\"0xd412ce774cfcf8dc9f71164aac78783978aac7b03871702a3b8a481bd9dc9688\", \"asset_id\":\"96600821790790307414914106093858868634329285205417149685270682748367152458577\", \"bids\":[{\"price\":\"0.01\", \"size\":\"7853.02\"}, {\"price\":\"0.02\", \"size\":\"728.1\"}, {\"price\":\"0.03\", \"size\":\"776.43\"}, {\"price\":\"0.04\", \"size\":\"638.09\"}, {\"price\":\"0.05\", \"size\":\"726.2\"}, {\"price\":\"0.06\", \"size\":\"675.2\"}, {\"price\":\"0.07\", \"size\":\"565.1\"}, {\"price\":\"0.08\", \"size\":\"567.79\"}, {\"price\":\"0.09\", \"size\":\"581.6\"}, {\"price\":\"0.1\", \"size\":\"107.29\"}, {\"price\":\"0.11\", \"size\":\"43.6\"}, {\"price\":\"0.12\", \"size\":\"80.4\"}, {\"price\":\"0.13\", \"size\":\"37.5\"}, {\"price\":\"0.14\", \"size\":\"34.9\"}, {\"price\":\"0.15\", \"size\":\"87.5\"}, {\"price\":\"0.16\", \"size\":\"41.3\"}, {\"price\":\"0.17\", \"size\":\"30.3\"}, {\"price\":\"0.18\", \"size\":\"58.3\"}, {\"price\":\"0.19\", \"size\":\"27.5\"}, {\"price\":\"0.2\", \"size\":\"54.8\"}, {\"price\":\"0.21\", \"size\":\"56.1\"}, {\"price\":\"0.22\", \"size\":\"176.01\"}, {\"price\":\"0.23\", \"size\":\"176.3\"}, {\"price\":\"0.24\", \"size\":\"53.39\"}, {\"price\":\"0.25\", \"size\":\"45\"}, {\"price\":\"0.26\", \"size\":\"28.6\"}, {\"price\":\"0.27\", \"size\":\"58.2\"}, {\"price\":\"0.28\", \"size\":\"20.9\"}, {\"price\":\"0.29\", \"size\":\"26.91\"}, {\"price\":\"0.3\", \"size\":\"56.3\"}, {\"price\":\"0.31\", \"size\":\"13.79\"}, {\"price\":\"0.32\", \"size\":\"29.58\"}, {\"price\":\"0.33\", \"size\":\"64.41\"}, {\"price\":\"0.34\", \"size\":\"134.65\"}, {\"price\":\"0.35\", \"size\":\"14\"}, {\"price\":\"0.36\", \"size\":\"64.38\"}, {\"price\":\"0.37\", \"size\":\"44.38\"}, {\"price\":\"0.38\", \"size\":\"40.38\"}, {\"price\":\"0.39\", \"size\":\"19\"}, {\"price\":\"0.4\", \"size\":\"56.58\"}, {\"price\":\"0.41\", \"size\":\"72.88\"}, {\"price\":\"0.42\", \"size\":\"93.6\"}], \"asks\":[{\"price\":\"0.99\", \"size\":\"7888.02\"}, {\"price\":\"0.98\", \"size\":\"733.1\"}, {\"price\":\"0.97\", \"size\":\"618.1\"}, {\"price\":\"0.96\", \"size\":\"668.09\"}, {\"price\":\"0.95\", \"size\":\"803.2\"}, {\"price\":\"0.94\", \"size\":\"623.2\"}, {\"price\":\"0.93\", \"size\":\"576.1\"}, {\"price\":\"0.92\", \"size\":\"550.79\"}, {\"price\":\"0.91\", \"size\":\"536.6\"}, {\"price\":\"0.9\", \"size\":\"123.29\"}, {\"price\":\"0.89\", \"size\":\"43.6\"}, {\"price\":\"0.88\", \"size\":\"50.4\"}, {\"price\":\"0.87\", \"size\":\"67.5\"}, {\"price\":\"0.86\", \"size\":\"34.9\"}, {\"price\":\"0.85\", \"size\":\"64.5\"}, {\"price\":\"0.84\", \"size\":\"71.3\"}, {\"price\":\"0.83\", \"size\":\"30.3\"}, {\"price\":\"0.82\", \"size\":\"28.3\"}, {\"price\":\"0.81\", \"size\":\"57.5\"}, {\"price\":\"0.8\", \"size\":\"59.8\"}, {\"price\":\"0.79\", \"size\":\"26.1\"}, {\"price\":\"0.78\", \"size\":\"54.5\"}, {\"price\":\"0.77\", \"size\":\"23.89\"}, {\"price\":\"0.76\", \"size\":\"23.39\"}, {\"price\":\"0.75\", \"size\":\"82\"}, {\"price\":\"0.74\", \"size\":\"21.6\"}, {\"price\":\"0.73\", \"size\":\"21.2\"}, {\"price\":\"0.72\", \"size\":\"50.9\"}, {\"price\":\"0.71\", \"size\":\"20.6\"}, {\"price\":\"0.7\", \"size\":\"47.3\"}, {\"price\":\"0.69\", \"size\":\"50\"}, {\"price\":\"0.68\", \"size\":\"19.8\"}, {\"price\":\"0.67\", \"size\":\"120.61\"}, {\"price\":\"0.66\", \"size\":\"49.4\"}, {\"price\":\"0.65\", \"size\":\"38.2\"}, {\"price\":\"0.64\", \"size\":\"18\"}, {\"price\":\"0.63\", \"size\":\"47.9\"}, {\"price\":\"0.62\", \"size\":\"27.7\"}, {\"price\":\"0.61\", \"size\":\"117.6\"}, {\"price\":\"0.6\", \"size\":\"171.5\"}, {\"price\":\"0.59\", \"size\":\"117.4\"}, {\"price\":\"0.58\", \"size\":\"62.63\"}, {\"price\":\"0.57\", \"size\":\"52.2\"}, {\"price\":\"0.56\", \"size\":\"62.2\"}, {\"price\":\"0.55\", \"size\":\"70\"}, {\"price\":\"0.54\", \"size\":\"87\"}, {\"price\":\"0.53\", \"size\":\"177\"}, {\"price\":\"0.52\", \"size\":\"221\"}, {\"price\":\"0.51\", \"size\":\"228.99\"}, {\"price\":\"0.5\", \"size\":\"269.99\"}, {\"price\":\"0.49\", \"size\":\"159\"}, {\"price\":\"0.48\", \"size\":\"168\"}, {\"price\":\"0.47\", \"size\":\"54\"}, {\"price\":\"0.46\", \"size\":\"68.1\"}, {\"price\":\"0.45\", \"size\":\"16\"}, {\"price\":\"0.44\", \"size\":\"21\"}, {\"price\":\"0.43\", \"size\":\"26.58\"}], \"hash\":\"ab59a2a660e3264b8ca59378f8801b80671e1a3f\", \"timestamp\":\"1785211376151\", \"event_type\":\"book\"}","received_at":"2026-07-28T04:02:59.870611Z","schema_version":"clob-market-ws.book.v1","sequence":null,"server_hash":"ab59a2a660e3264b8ca59378f8801b80671e1a3f","server_timestamp":"1785211376151","session_id":"2d607381e3054cee91998cdf45a4231c","source":"clob_market_ws"},"received_at":"2026-07-28T04:02:59.870611Z","record_id":"350ddad93ead94a730eea59cd8189202594d7d2d74fdacdbbb16757838126e89","schema_fingerprint":"dc2caa1c89c6a7426e2e07ff925910cd4d0a8a223a515d4092d91d6d127aacb6","schema_version":"edge-lab-recorder.raw.v1","sequence":null,"source":"clob_market_ws"}
{"event_at":"2026-07-28T04:02:56.155000Z","event_fingerprint":"b789332b91250fc8fbf6dea2e9dd0c94f6e7ddaf2658759c4b84027b0ce8239a","payload":{"connection_id":"f6725804f86a4c4eb588e4d5ed7db029","event_at":"2026-07-28T04:02:56.155000Z","event_type":"price_change","frame_hash":"d53bac1bd1d27be549f2fdd245924cde9319e3180bb27a812529e4e6baf685dd","frame_index":0,"kind":"data","monotonic_ns":313362930420291,"payload":{"event_type":"price_change","market":"0xd412ce774cfcf8dc9f71164aac78783978aac7b03871702a3b8a481bd9dc9688","price_changes":[{"asset_id":"107603864457683460275633293642179940881969192120168665300712204232021063124301","best_ask":"0.58","best_bid":"0.57","hash":"cbf7a8ca609f2a4084f46512a3c514f94b5c7d40","price":"0.56","side":"BUY","size":"15"},{"asset_id":"96600821790790307414914106093858868634329285205417149685270682748367152458577","best_ask":"0.43","best_bid":"0.42","hash":"81071b411c75a5a7b1f606e2b2a861fd220d734b","price":"0.44","side":"SELL","size":"15"}],"timestamp":"1785211376155"},"payload_hash":"a47d7a70011c10c49e7ff27902f4d3a0db89d13c46faeb4811730c9ede7384a9","raw_frame":"{\"market\":\"0xd412ce774cfcf8dc9f71164aac78783978aac7b03871702a3b8a481bd9dc9688\", \"price_changes\":[{\"asset_id\":\"107603864457683460275633293642179940881969192120168665300712204232021063124301\", \"price\":\"0.56\", \"size\":\"15\", \"side\":\"BUY\", \"hash\":\"cbf7a8ca609f2a4084f46512a3c514f94b5c7d40\", \"best_bid\":\"0.57\", \"best_ask\":\"0.58\"}, {\"asset_id\":\"96600821790790307414914106093858868634329285205417149685270682748367152458577\", \"price\":\"0.44\", \"size\":\"15\", \"side\":\"SELL\", \"hash\":\"81071b411c75a5a7b1f606e2b2a861fd220d734b\", \"best_bid\":\"0.42\", \"best_ask\":\"0.43\"}], \"timestamp\":\"1785211376155\", \"event_type\":\"price_change\"}","received_at":"2026-07-28T04:02:59.881172Z","schema_version":"clob-market-ws.price_change.v1","sequence":null,"server_hash":null,"server_timestamp":"1785211376155","session_id":"2d607381e3054cee91998cdf45a4231c","source":"clob_market_ws"},"received_at":"2026-07-28T04:02:59.881172Z","record_id":"ba9b7ab8a68ad40af1bc4d8952077a3720a4915107b59b07d9d9d38b0ce1df99","schema_fingerprint":"4aa3821a28b0b7c2400bc59aba4bcc0a76e971dadd19610d3ad38c768e124dc7","schema_version":"edge-lab-recorder.raw.v1","sequence":null,"source":"clob_market_ws"}
{"event_at":"2026-07-28T04:02:56.155000Z","event_fingerprint":"54fbd5d3029583aac7fa34744a347e4029b933804ca980c88a5eddcd973b3d68","payload":{"connection_id":"f6725804f86a4c4eb588e4d5ed7db029","event_at":"2026-07-28T04:02:56.155000Z","event_type":"price_change","frame_hash":"37625b90f861d374b43ece5bffcc574ff0e3c1ddb046726217df8ca05fe0ae33","frame_index":0,"kind":"data","monotonic_ns":313362932642666,"payload":{"event_type":"price_change","market":"0xd412ce774cfcf8dc9f71164aac78783978aac7b03871702a3b8a481bd9dc9688","price_changes":[{"asset_id":"107603864457683460275633293642179940881969192120168665300712204232021063124301","best_ask":"0.58","best_bid":"0.57","hash":"1c03331f5c827269f2e0a405580c5d905234eb65","price":"0.57","side":"BUY","size":"20.6"},{"asset_id":"96600821790790307414914106093858868634329285205417149685270682748367152458577","best_ask":"0.43","best_bid":"0.42","hash":"1fc3f07d8668cb6705d57ae72365dfa63507fd0f","price":"0.43","side":"SELL","size":"20.6"}],"timestamp":"1785211376155"},"payload_hash":"6a0a7ea897d21e0ddda35cc8978b8bfafe61f421ef7d7cadc5ae0b0325104392","raw_frame":"{\"market\":\"0xd412ce774cfcf8dc9f71164aac78783978aac7b03871702a3b8a481bd9dc9688\", \"price_changes\":[{\"asset_id\":\"107603864457683460275633293642179940881969192120168665300712204232021063124301\", \"price\":\"0.57\", \"size\":\"20.6\", \"side\":\"BUY\", \"hash\":\"1c03331f5c827269f2e0a405580c5d905234eb65\", \"best_bid\":\"0.57\", \"best_ask\":\"0.58\"}, {\"asset_id\":\"96600821790790307414914106093858868634329285205417149685270682748367152458577\", \"price\":\"0.43\", \"size\":\"20.6\", \"side\":\"SELL\", \"hash\":\"1fc3f07d8668cb6705d57ae72365dfa63507fd0f\", \"best_bid\":\"0.42\", \"best_ask\":\"0.43\"}], \"timestamp\":\"1785211376155\", \"event_type\":\"price_change\"}","received_at":"2026-07-28T04:02:59.883397Z","schema_version":"clob-market-ws.price_change.v1","sequence":null,"server_hash":null,"server_timestamp":"1785211376155","session_id":"2d607381e3054cee91998cdf45a4231c","source":"clob_market_ws"},"received_at":"2026-07-28T04:02:59.883397Z","record_id":"3c8e56d07b9223c095931988660e99d96acd7872759ed4221e01bd8ca627ec81","schema_fingerprint":"4aa3821a28b0b7c2400bc59aba4bcc0a76e971dadd19610d3ad38c768e124dc7","schema_version":"edge-lab-recorder.raw.v1","sequence":null,"source":"clob_market_ws"}
{"event_at":"2026-07-28T04:02:56.157000Z","event_fingerprint":"b08a1ab59f3dd216573579a471a83f0d873f522dbe6fdd2f31469a7df5312e78","payload":{"connection_id":"f6725804f86a4c4eb588e4d5ed7db029","event_at":"2026-07-28T04:02:56.157000Z","event_type":"price_change","frame_hash":"d6777ba2a2ea7b230bc353209f3c58ff16bd579491435e919b1bdf5f91395e3a","frame_index":0,"kind":"data","monotonic_ns":313362934326708,"payload":{"event_type":"price_change","market":"0xd412ce774cfcf8dc9f71164aac78783978aac7b03871702a3b8a481bd9dc9688","price_changes":[{"asset_id":"107603864457683460275633293642179940881969192120168665300712204232021063124301","best_ask":"0.58","best_bid":"0.57","hash":"948eb9c2edc754dac6fc05bd10fc03755a4c3d81","price":"0.48","side":"BUY","size":"191"},{"asset_id":"96600821790790307414914106093858868634329285205417149685270682748367152458577","best_ask":"0.43","best_bid":"0.42","hash":"f1a182ff0330f3f6e91aed264ab16c7a77f84582","price":"0.52","side":"SELL","size":"191"}],"timestamp":"1785211376157"},"payload_hash":"ec004754b0e8f71d657548f8152a7a42bde41e9b7a9833e16ea9ce81907d7793","raw_frame":"{\"market\":\"0xd412ce774cfcf8dc9f71164aac78783978aac7b03871702a3b8a481bd9dc9688\", \"price_changes\":[{\"asset_id\":\"107603864457683460275633293642179940881969192120168665300712204232021063124301\", \"price\":\"0.48\", \"size\":\"191\", \"side\":\"BUY\", \"hash\":\"948eb9c2edc754dac6fc05bd10fc03755a4c3d81\", \"best_bid\":\"0.57\", \"best_ask\":\"0.58\"}, {\"asset_id\":\"96600821790790307414914106093858868634329285205417149685270682748367152458577\", \"price\":\"0.52\", \"size\":\"191\", \"side\":\"SELL\", \"hash\":\"f1a182ff0330f3f6e91aed264ab16c7a77f84582\", \"best_bid\":\"0.42\", \"best_ask\":\"0.43\"}], \"timestamp\":\"1785211376157\", \"event_type\":\"price_change\"}","received_at":"2026-07-28T04:02:59.885082Z","schema_version":"clob-market-ws.price_change.v1","sequence":null,"server_hash":null,"server_timestamp":"1785211376157","session_id":"2d607381e3054cee91998cdf45a4231c","source":"clob_market_ws"},"received_at":"2026-07-28T04:02:59.885082Z","record_id":"3c5c309522ec46adb22b75c0722b924096e05b052dac3fb2da2a97c5ae212b3f","schema_fingerprint":"4aa3821a28b0b7c2400bc59aba4bcc0a76e971dadd19610d3ad38c768e124dc7","schema_version":"edge-lab-recorder.raw.v1","sequence":null,"source":"clob_market_ws"}
{"event_at":"2026-07-28T04:02:56.157000Z","event_fingerprint":"eeae9eda5b4d6ae63bdbda6487c20fb4ca21e603a49e0ebbf8c649a7e446019c","payload":{"connection_id":"f6725804f86a4c4eb588e4d5ed7db029","event_at":"2026-07-28T04:02:56.157000Z","event_type":"price_change","frame_hash":"de4934d81d67d9f80c55be79d1c410bac3c212c11f44e376ba621d4e18622133","frame_index":0,"kind":"data","monotonic_ns":313362935863500,"payload":{"event_type":"price_change","market":"0xd412ce774cfcf8dc9f71164aac78783978aac7b03871702a3b8a481bd9dc9688","price_changes":[{"asset_id":"107603864457683460275633293642179940881969192120168665300712204232021063124301","best_ask":"0.58","best_bid":"0.57","hash":"dff6ff28108db19262d12d157406d39bceaae4b5","price":"0.48","side":"BUY","size":"161"},{"asset_id":"96600821790790307414914106093858868634329285205417149685270682748367152458577","best_ask":"0.43","best_bid":"0.42","hash":"37db2af8e9944d3dc1ccbd6faf63004f23bc2c04","price":"0.52","side":"SELL","size":"161"}],"timestamp":"1785211376157"},"payload_hash":"628d40dacf1be648b3eab3ed10a2567a4560214b02fe2949efe6624cc52bdca7","raw_frame":"{\"market\":\"0xd412ce774cfcf8dc9f71164aac78783978aac7b03871702a3b8a481bd9dc9688\", \"price_changes\":[{\"asset_id\":\"107603864457683460275633293642179940881969192120168665300712204232021063124301\", \"price\":\"0.48\", \"size\":\"161\", \"side\":\"BUY\", \"hash\":\"dff6ff28108db19262d12d157406d39bceaae4b5\", \"best_bid\":\"0.57\", \"best_ask\":\"0.58\"}, {\"asset_id\":\"96600821790790307414914106093858868634329285205417149685270682748367152458577\", \"price\":\"0.52\", \"size\":\"161\", \"side\":\"SELL\", \"hash\":\"37db2af8e9944d3dc1ccbd6faf63004f23bc2c04\", \"best_bid\":\"0.42\", \"best_ask\":\"0.43\"}], \"timestamp\":\"1785211376157\", \"event_type\":\"price_change\"}","received_at":"2026-07-28T04:02:59.886619Z","schema_version":"clob-market-ws.price_change.v1","sequence":null,"server_hash":null,"server_timestamp":"1785211376157","session_id":"2d607381e3054cee91998cdf45a4231c","source":"clob_market_ws"},"received_at":"2026-07-28T04:02:59.886619Z","record_id":"b7ddab96030eec20fa268286d94589ba4474931b8bed5b3b4e3b532ce21d7d81","schema_fingerprint":"4aa3821a28b0b7c2400bc59aba4bcc0a76e971dadd19610d3ad38c768e124dc7","schema_version":"edge-lab-recorder.raw.v1","sequence":null,"source":"clob_market_ws"}
{"event_at":"2026-07-28T04:02:56.160000Z","event_fingerprint":"0a28f03ae9e3ab0903e6e6dbd79bb21774d3f20c093dfdac1a5aeeadc5b5c7c7","payload":{"connection_id":"f6725804f86a4c4eb588e4d5ed7db029","event_at":"2026-07-28T04:02:56.160000Z","event_type":"price_change","frame_hash":"f77f30380065aeff92b67fe3f56bc6b5c426ff4b5412f26289163881c32f1d5a","frame_index":0,"kind":"data","monotonic_ns":313362937384625,"payload":{"event_type":"price_change","market":"0xd412ce774cfcf8dc9f71164aac78783978aac7b03871702a3b8a481bd9dc9688","price_changes":[{"asset_id":"107603864457683460275633293642179940881969192120168665300712204232021063124301","best_ask":"0.58","best_bid":"0.57","hash":"257a134a9cd9140487d67c6dd08df60a980ce0b5","price":"0.47","side":"BUY","size":"182"},{"asset_id":"96600821790790307414914106093858868634329285205417149685270682748367152458577","best_ask":"0.43","best_bid":"0.42","hash":"08235acbaf5079f85d840c92f649e7477b1d7543","price":"0.53","side":"SELL","size":"182"}],"timestamp":"1785211376160"},"payload_hash":"aaa32f21133edc5c473ae56f3a68f9ab3646f18340975564b5d696b28ea69a82","raw_frame":"{\"market\":\"0xd412ce774cfcf8dc9f71164aac78783978aac7b03871702a3b8a481bd9dc9688\", \"price_changes\":[{\"asset_id\":\"107603864457683460275633293642179940881969192120168665300712204232021063124301\", \"price\":\"0.47\", \"size\":\"182\", \"side\":\"BUY\", \"hash\":\"257a134a9cd9140487d67c6dd08df60a980ce0b5\", \"best_bid\":\"0.57\", \"best_ask\":\"0.58\"}, {\"asset_id\":\"96600821790790307414914106093858868634329285205417149685270682748367152458577\", \"price\":\"0.53\", \"size\":\"182\", \"side\":\"SELL\", \"hash\":\"08235acbaf5079f85d840c92f649e7477b1d7543\", \"best_bid\":\"0.42\", \"best_ask\":\"0.43\"}], \"timestamp\":\"1785211376160\", \"event_type\":\"price_change\"}","received_at":"2026-07-28T04:02:59.888141Z","schema_version":"clob-market-ws.price_change.v1","sequence":null,"server_hash":null,"server_timestamp":"1785211376160","session_id":"2d607381e3054cee91998cdf45a4231c","source":"clob_market_ws"},"received_at":"2026-07-28T04:02:59.888141Z","record_id":"cf4ee4206e926fb0cfe34e498e149eedb8a9aadc05bc0a453571a79a81f8f2b8","schema_fingerprint":"4aa3821a28b0b7c2400bc59aba4bcc0a76e971dadd19610d3ad38c768e124dc7","schema_version":"edge-lab-recorder.raw.v1","sequence":null,"source":"clob_market_ws"}
{"event_at":"2026-07-28T04:02:56.161000Z","event_fingerprint":"cd9c68502c2ed9ceaa13659f7f66bd0f5545d77a6b380b91f943b5893e9820f3","payload":{"connection_id":"f6725804f86a4c4eb588e4d5ed7db029","event_at":"2026-07-28T04:02:56.161000Z","event_type":"price_change","frame_hash":"3576ff05e54161259e3d9a2c99a8fd06b958d179699371cbc2fdc75123883009","frame_index":0,"kind":"data","monotonic_ns":313362938867291,"payload":{"event_type":"price_change","market":"0xd412ce774cfcf8dc9f71164aac78783978aac7b03871702a3b8a481bd9dc9688","price_changes":[{"asset_id":"96600821790790307414914106093858868634329285205417149685270682748367152458577","best_ask":"0.43","best_bid":"0.42","hash":"784b61d6893deadcf929c9bb2ddcb7682a62f056","price":"0.43","side":"SELL","size":"25.6"},{"asset_id":"107603864457683460275633293642179940881969192120168665300712204232021063124301","best_ask":"0.58","best_bid":"0.57","hash":"38ca66e5e0afb129e6c60f38cd4c86e1231b1daa","price":"0.57","side":"BUY","size":"25.6"}],"timestamp":"1785211376161"},"payload_hash":"e5c6a0d0a97e6f62e218fd07cf01e488a854e76d714f1e0b1ef32e96ade6a5e9","raw_frame":"{\"market\":\"0xd412ce774cfcf8dc9f71164aac78783978aac7b03871702a3b8a481bd9dc9688\", \"price_changes\":[{\"asset_id\":\"96600821790790307414914106093858868634329285205417149685270682748367152458577\", \"price\":\"0.43\", \"size\":\"25.6\", \"side\":\"SELL\", \"hash\":\"784b61d6893deadcf929c9bb2ddcb7682a62f056\", \"best_bid\":\"0.42\", \"best_ask\":\"0.43\"}, {\"asset_id\":\"107603864457683460275633293642179940881969192120168665300712204232021063124301\", \"price\":\"0.57\", \"size\":\"25.6\", \"side\":\"BUY\", \"hash\":\"38ca66e5e0afb129e6c60f38cd4c86e1231b1daa\", \"best_bid\":\"0.57\", \"best_ask\":\"0.58\"}], \"timestamp\":\"1785211376161\", \"event_type\":\"price_change\"}","received_at":"2026-07-28T04:02:59.889624Z","schema_version":"clob-market-ws.price_change.v1","sequence":null,"server_hash":null,"server_timestamp":"1785211376161","session_id":"2d607381e3054cee91998cdf45a4231c","source":"clob_market_ws"},"received_at":"2026-07-28T04:02:59.889624Z","record_id":"bfb7f0fecf51a772e46d5d656ca176fd48fb50be3f484529e9e451c8c59a664f","schema_fingerprint":"4aa3821a28b0b7c2400bc59aba4bcc0a76e971dadd19610d3ad38c768e124dc7","schema_version":"edge-lab-recorder.raw.v1","sequence":null,"source":"clob_market_ws"}
{"event_at":"2026-07-28T04:02:56.163000Z","event_fingerprint":"cbffff2281b058a184d2ec6f6c402bd23be330aae5d9db699d9fb00f8916c4c9","payload":{"connection_id":"f6725804f86a4c4eb588e4d5ed7db029","event_at":"2026-07-28T04:02:56.163000Z","event_type":"price_change","frame_hash":"a0a6461816f9359108db9ea0bd0a64b821c4303471f715723922fa211d5d5883","frame_index":0,"kind":"data","monotonic_ns":313362940356750,"payload":{"event_type":"price_change","market":"0xd412ce774cfcf8dc9f71164aac78783978aac7b03871702a3b8a481bd9dc9688","price_changes":[{"asset_id":"107603864457683460275633293642179940881969192120168665300712204232021063124301","best_ask":"0.58","best_bid":"0.57","hash":"3dcf2d0bc0cd077931f5df11bdbd88ee86d4e7dd","price":"0.48","side":"BUY","size":"166"},{"asset_id":"96600821790790307414914106093858868634329285205417149685270682748367152458577","best_ask":"0.43","best_bid":"0.42","hash":"133d70c6a35e22e49b2eadbea4920143dcc535ad","price":"0.52","side":"SELL","size":"166"}],"timestamp":"1785211376163"},"payload_hash":"74b42d31e4a6b7ce6844f2dc28e8fcbbcde5563da93df49acbae476b7c04fbc7","raw_frame":"{\"market\":\"0xd412ce774cfcf8dc9f71164aac78783978aac7b03871702a3b8a481bd9dc9688\", \"price_changes\":[{\"asset_id\":\"107603864457683460275633293642179940881969192120168665300712204232021063124301\", \"price\":\"0.48\", \"size\":\"166\", \"side\":\"BUY\", \"hash\":\"3dcf2d0bc0cd077931f5df11bdbd88ee86d4e7dd\", \"best_bid\":\"0.57\", \"best_ask\":\"0.58\"}, {\"asset_id\":\"96600821790790307414914106093858868634329285205417149685270682748367152458577\", \"price\":\"0.52\", \"size\":\"166\", \"side\":\"SELL\", \"hash\":\"133d70c6a35e22e49b2eadbea4920143dcc535ad\", \"best_bid\":\"0.42\", \"best_ask\":\"0.43\"}], \"timestamp\":\"1785211376163\", \"event_type\":\"price_change\"}","received_at":"2026-07-28T04:02:59.891114Z","schema_version":"clob-market-ws.price_change.v1","sequence":null,"server_hash":null,"server_timestamp":"1785211376163","session_id":"2d607381e3054cee91998cdf45a4231c","source":"clob_market_ws"},"received_at":"2026-07-28T04:02:59.891114Z","record_id":"994476d1b70e6d0cb341778401f5029133aa88668e393510a48b04417343609e","schema_fingerprint":"4aa3821a28b0b7c2400bc59aba4bcc0a76e971dadd19610d3ad38c768e124dc7","schema_version":"edge-lab-recorder.raw.v1","sequence":null,"source":"clob_market_ws"}
{"event_at":"2026-07-28T04:02:56.165000Z","event_fingerprint":"888c802d364bd4c19aa1cbf4bf69c08edacc94519a63cd310d86bfaf7112a9b3","payload":{"connection_id":"f6725804f86a4c4eb588e4d5ed7db029","event_at":"2026-07-28T04:02:56.165000Z","event_type":"price_change","frame_hash":"453b87cac4f955ac702d08f16e4e21faa9ea240a764d12dd6dd6121154b4686c","frame_index":0,"kind":"data","monotonic_ns":313362941835875,"payload":{"event_type":"price_change","market":"0xd412ce774cfcf8dc9f71164aac78783978aac7b03871702a3b8a481bd9dc9688","price_changes":[{"asset_id":"96600821790790307414914106093858868634329285205417149685270682748367152458577","best_ask":"0.43","best_bid":"0.42","hash":"f53307f42ad22791817c1b0090fde73d4ffb517a","price":"0.31","side":"BUY","size":"19.79"},{"asset_id":"107603864457683460275633293642179940881969192120168665300712204232021063124301","best_ask":"0.58","best_bid":"0.57","hash":"b457775a44b0f91cfde2eb7efd499acc3411e620","price":"0.69","side":"SELL","size":"19.79"}],"timestamp":"1785211376165"},"payload_hash":"50f5c2f5d5103c8e066e7b5df8e062ffb13d1b9edab19f6b851dd3ab73576a54","raw_frame":"{\"market\":\"0xd412ce774cfcf8dc9f71164aac78783978aac7b03871702a3b8a481bd9dc9688\", \"price_changes\":[{\"asset_id\":\"96600821790790307414914106093858868634329285205417149685270682748367152458577\", \"price\":\"0.31\", \"size\":\"19.79\", \"side\":\"BUY\", \"hash\":\"f53307f42ad22791817c1b0090fde73d4ffb517a\", \"best_bid\":\"0.42\", \"best_ask\":\"0.43\"}, {\"asset_id\":\"107603864457683460275633293642179940881969192120168665300712204232021063124301\", \"price\":\"0.69\", \"size\":\"19.79\", \"side\":\"SELL\", \"hash\":\"b457775a44b0f91cfde2eb7efd499acc3411e620\", \"best_bid\":\"0.57\", \"best_ask\":\"0.58\"}], \"timestamp\":\"1785211376165\", \"event_type\":\"price_change\"}","received_at":"2026-07-28T04:02:59.892593Z","schema_version":"clob-market-ws.price_change.v1","sequence":null,"server_hash":null,"server_timestamp":"1785211376165","session_id":"2d607381e3054cee91998cdf45a4231c","source":"clob_market_ws"},"received_at":"2026-07-28T04:02:59.892593Z","record_id":"843c3f56e81e90fe2c7c89068e6f59040e16dcbbd67e32924665068f391104ac","schema_fingerprint":"4aa3821a28b0b7c2400bc59aba4bcc0a76e971dadd19610d3ad38c768e124dc7","schema_version":"edge-lab-recorder.raw.v1","sequence":null,"source":"clob_market_ws"}
{"event_at":"2026-07-28T04:02:56.166000Z","event_fingerprint":"9133f51f8224b8ebdb907ad96e321f27d284a36b7ab2b7a26429b84715b245bd","payload":{"connection_id":"f6725804f86a4c4eb588e4d5ed7db029","event_at":"2026-07-28T04:02:56.166000Z","event_type":"price_change","frame_hash":"1fbe962074f7f1b9a3a2625d5d6a435bed93b07c9e25d94083c08285faa4a65e","frame_index":0,"kind":"data","monotonic_ns":313362943306833,"payload":{"event_type":"price_change","market":"0xd412ce774cfcf8dc9f71164aac78783978aac7b03871702a3b8a481bd9dc9688","price_changes":[{"asset_id":"96600821790790307414914106093858868634329285205417149685270682748367152458577","best_ask":"0.43","best_bid":"0.42","hash":"fa3ea13aa3af216745b8666e9111baa0147f18c4","price":"0.3","side":"BUY","size":"62.3"},{"asset_id":"107603864457683460275633293642179940881969192120168665300712204232021063124301","best_ask":"0.58","best_bid":"0.57","hash":"fceb57006fbc72af96ddc55dc981ab5c5647cc47","price":"0.7","side":"SELL","size":"62.3"}],"timestamp":"1785211376166"},"payload_hash":"f093ea82be9a1548c294c15c12851e508771cac9ca7701ecfb6dd1c6232a7936","raw_frame":"{\"market\":\"0xd412ce774cfcf8dc9f71164aac78783978aac7b03871702a3b8a481bd9dc9688\", \"price_changes\":[{\"asset_id\":\"96600821790790307414914106093858868634329285205417149685270682748367152458577\", \"price\":\"0.3\", \"size\":\"62.3\", \"side\":\"BUY\", \"hash\":\"fa3ea13aa3af216745b8666e9111baa0147f18c4\", \"best_bid\":\"0.42\", \"best_ask\":\"0.43\"}, {\"asset_id\":\"107603864457683460275633293642179940881969192120168665300712204232021063124301\", \"price\":\"0.7\", \"size\":\"62.3\", \"side\":\"SELL\", \"hash\":\"fceb57006fbc72af96ddc55dc981ab5c5647cc47\", \"best_bid\":\"0.57\", \"best_ask\":\"0.58\"}], \"timestamp\":\"1785211376166\", \"event_type\":\"price_change\"}","received_at":"2026-07-28T04:02:59.894063Z","schema_version":"clob-market-ws.price_change.v1","sequence":null,"server_hash":null,"server_timestamp":"1785211376166","session_id":"2d607381e3054cee91998cdf45a4231c","source":"clob_market_ws"},"received_at":"2026-07-28T04:02:59.894063Z","record_id":"8802f32e051fb916a7db1d529d051878b9deff97578b42bcc59512c78a90696a","schema_fingerprint":"4aa3821a28b0b7c2400bc59aba4bcc0a76e971dadd19610d3ad38c768e124dc7","schema_version":"edge-lab-recorder.raw.v1","sequence":null,"source":"clob_market_ws"}
{"event_at":"2026-07-28T04:02:56.174000Z","event_fingerprint":"43dd90ea6fc3e392b1a3e51b7b6bc9b5a25942e31bcccd5e55ad0bb64c504e0a","payload":{"connection_id":"f6725804f86a4c4eb588e4d5ed7db029","event_at":"2026-07-28T04:02:56.174000Z","event_type":"price_change","frame_hash":"180e5b89699fb892cf491468bfe503f5d6357e47821496f21f18284527dadaed","frame_index":0,"kind":"data","monotonic_ns":313362944788000,"payload":{"event_type":"price_change","market":"0xd412ce774cfcf8dc9f71164aac78783978aac7b03871702a3b8a481bd9dc9688","price_changes":[{"asset_id":"96600821790790307414914106093858868634329285205417149685270682748367152458577","best_ask":"0.43","best_bid":"0.42","hash":"961285c4f5e584a09e457deb02bc8938b2008112","price":"0.32","side":"BUY","size":"35.58"},{"asset_id":"107603864457683460275633293642179940881969192120168665300712204232021063124301","best_ask":"0.58","best_bid":"0.57","hash":"b8470028ecb2acc64e0e619eb052d48b6f191b9e","price":"0.68","side":"SELL","size":"35.58"}],"timestamp":"1785211376174"},"payload_hash":"6827fdf1b359c97c6bc329c75be2037c0d4dd830eee5468d2c955b5ed50f702b","raw_frame":"{\"market\":\"0xd412ce774cfcf8dc9f71164aac78783978aac7b03871702a3b8a481bd9dc9688\", \"price_changes\":[{\"asset_id\":\"96600821790790307414914106093858868634329285205417149685270682748367152458577\", \"price\":\"0.32\", \"size\":\"35.58\", \"side\":\"BUY\", \"hash\":\"961285c4f5e584a09e457deb02bc8938b2008112\", \"best_bid\":\"0.42\", \"best_ask\":\"0.43\"}, {\"asset_id\":\"107603864457683460275633293642179940881969192120168665300712204232021063124301\", \"price\":\"0.68\", \"size\":\"35.58\", \"side\":\"SELL\", \"hash\":\"b8470028ecb2acc64e0e619eb052d48b6f191b9e\", \"best_bid\":\"0.57\", \"best_ask\":\"0.58\"}], \"timestamp\":\"1785211376174\", \"event_type\":\"price_change\"}","received_at":"2026-07-28T04:02:59.895545Z","schema_version":"clob-market-ws.price_change.v1","sequence":null,"server_hash":null,"server_timestamp":"1785211376174","session_id":"2d607381e3054cee91998cdf45a4231c","source":"clob_market_ws"},"received_at":"2026-07-28T04:02:59.895545Z","record_id":"526503753713703619133b2d2cba90510eb8d90c5a8915f72050310db784c0e1","schema_fingerprint":"4aa3821a28b0b7c2400bc59aba4bcc0a76e971dadd19610d3ad38c768e124dc7","schema_version":"edge-lab-recorder.raw.v1","sequence":null,"source":"clob_market_ws"}
{"event_at":"2026-07-28T04:02:56.175000Z","event_fingerprint":"06108f80e4363f2aa0e284d0b8c277cf85490d00a7ea7a3890a9da3250383e1b","payload":{"connection_id":"f6725804f86a4c4eb588e4d5ed7db029","event_at":"2026-07-28T04:02:56.175000Z","event_type":"price_change","frame_hash":"609e8e6a07992f636ddf3215f1f6fd7c3d732b257403b08acd0b49a286dc1442","frame_index":0,"kind":"data","monotonic_ns":313362946246666,"payload":{"event_type":"price_change","market":"0xd412ce774cfcf8dc9f71164aac78783978aac7b03871702a3b8a481bd9dc9688","price_changes":[{"asset_id":"107603864457683460275633293642179940881969192120168665300712204232021063124301","best_ask":"0.58","best_bid":"0.57","hash":"05c445bb00d1863e19d4209f128e731573808edd","price":"0.5","side":"BUY","size":"294.99"},{"asset_id":"96600821790790307414914106093858868634329285205417149685270682748367152458577","best_ask":"0.43","best_bid":"0.42","hash":"83a69b029c7b77b2f8ed564afdb99c337a3f8c01","price":"0.5","side":"SELL","size":"294.99"}],"timestamp":"1785211376175"},"payload_hash":"f3416009945e5495cd9a13a13a8746c6162bc1ac96aa1ba540eda9110b21db72","raw_frame":"{\"market\":\"0xd412ce774cfcf8dc9f71164aac78783978aac7b03871702a3b8a481bd9dc9688\", \"price_changes\":[{\"asset_id\":\"107603864457683460275633293642179940881969192120168665300712204232021063124301\", \"price\":\"0.5\", \"size\":\"294.99\", \"side\":\"BUY\", \"hash\":\"05c445bb00d1863e19d4209f128e731573808edd\", \"best_bid\":\"0.57\", \"best_ask\":\"0.58\"}, {\"asset_id\":\"96600821790790307414914106093858868634329285205417149685270682748367152458577\", \"price\":\"0.5\", \"size\":\"294.99\", \"side\":\"SELL\", \"hash\":\"83a69b029c7b77b2f8ed564afdb99c337a3f8c01\", \"best_bid\":\"0.42\", \"best_ask\":\"0.43\"}], \"timestamp\":\"1785211376175\", \"event_type\":\"price_change\"}","received_at":"2026-07-28T04:02:59.897003Z","schema_version":"clob-market-ws.price_change.v1","sequence":null,"server_hash":null,"server_timestamp":"1785211376175","session_id":"2d607381e3054cee91998cdf45a4231c","source":"clob_market_ws"},"received_at":"2026-07-28T04:02:59.897003Z","record_id":"951c2fdbe969c93d9357f72566a32185f2e96552d8653dfba7083e90e56298cc","schema_fingerprint":"4aa3821a28b0b7c2400bc59aba4bcc0a76e971dadd19610d3ad38c768e124dc7","schema_version":"edge-lab-recorder.raw.v1","sequence":null,"source":"clob_market_ws"}
{"event_at":"2026-07-28T04:02:56.178000Z","event_fingerprint":"95f2967d5f9d105df16a2b44d62ff79ab7ba39a6b47363cd529be8c92914dee4","payload":{"connection_id":"f6725804f86a4c4eb588e4d5ed7db029","event_at":"2026-07-28T04:02:56.178000Z","event_type":"price_change","frame_hash":"5c25484ec00648edb52001a557bfb170981ca4f9508f3f49b4fcbf3166bc5739","frame_index":0,"kind":"data","monotonic_ns":313362947721041,"payload":{"event_type":"price_change","market":"0xd412ce774cfcf8dc9f71164aac78783978aac7b03871702a3b8a481bd9dc9688","price_changes":[{"asset_id":"107603864457683460275633293642179940881969192120168665300712204232021063124301","best_ask":"0.58","best_bid":"0.57","hash":"9ff8df47a7fc294b8bc3cc19d13293d5334ae434","price":"0.33","side":"BUY","size":"221.62"},{"asset_id":"96600821790790307414914106093858868634329285205417149685270682748367152458577","best_ask":"0.43","best_bid":"0.42","hash":"942f981f33901597fca2de2876d710007f8589d1","price":"0.67","side":"SELL","size":"221.62"}],"timestamp":"1785211376178"},"payload_hash":"ffe8b3716d4f7c0b778345f0fb6e8dd2538929fd887a4a68f6f09ea07576ffe4","raw_frame":"{\"market\":\"0xd412ce774cfcf8dc9f71164aac78783978aac7b03871702a3b8a481bd9dc9688\", \"price_changes\":[{\"asset_id\":\"107603864457683460275633293642179940881969192120168665300712204232021063124301\", \"price\":\"0.33\", \"size\":\"221.62\", \"side\":\"BUY\", \"hash\":\"9ff8df47a7fc294b8bc3cc19d13293d5334ae434\", \"best_bid\":\"0.57\", \"best_ask\":\"0.58\"}, {\"asset_id\":\"96600821790790307414914106093858868634329285205417149685270682748367152458577\", \"price\":\"0.67\", \"size\":\"221.62\", \"side\":\"SELL\", \"hash\":\"942f981f33901597fca2de2876d710007f8589d1\", \"best_bid\":\"0.42\", \"best_ask\":\"0.43\"}], \"timestamp\":\"1785211376178\", \"event_type\":\"price_change\"}","received_at":"2026-07-28T04:02:59.898478Z","schema_version":"clob-market-ws.price_change.v1","sequence":null,"server_hash":null,"server_timestamp":"1785211376178","session_id":"2d607381e3054cee91998cdf45a4231c","source":"clob_market_ws"},"received_at":"2026-07-28T04:02:59.898478Z","record_id":"4c69f6eaaf1e6319b7967e046a97bd734169371360677233002b568edfe7fc89","schema_fingerprint":"4aa3821a28b0b7c2400bc59aba4bcc0a76e971dadd19610d3ad38c768e124dc7","schema_version":"edge-lab-recorder.raw.v1","sequence":null,"source":"clob_market_ws"}
{"event_at":"2026-07-28T04:02:56.179000Z","event_fingerprint":"f7285ed6b792fe4020a1689ae40941bd092c99b27ba46ba97a0bc7bee3199cbd","payload":{"connection_id":"f6725804f86a4c4eb588e4d5ed7db029","event_at":"2026-07-28T04:02:56.179000Z","event_type":"price_change","frame_hash":"05b5e7f0a0d5089bc8400c48b749ebe738b77fd6f2011ef9ca0be6ddeb787fd8","frame_index":0,"kind":"data","monotonic_ns":313362949182458,"payload":{"event_type":"price_change","market":"0xd412ce774cfcf8dc9f71164aac78783978aac7b03871702a3b8a481bd9dc9688","price_changes":[{"asset_id":"107603864457683460275633293642179940881969192120168665300712204232021063124301","best_ask":"0.58","best_bid":"0.57","hash":"8361c143c626b667b60c8366c0bfa712c8b76848","price":"0.54","side":"BUY","size":"74.1"},{"asset_id":"96600821790790307414914106093858868634329285205417149685270682748367152458577","best_ask":"0.43","best_bid":"0.42","hash":"d4b46dac29d75318fd33f1d9e17ee9c64791df8f","price":"0.46","side":"SELL","size":"74.1"}],"timestamp":"1785211376179"},"payload_hash":"bc035049da633fc872b4e1442fc744424209c2c231d601d4ccf728562e8b8edd","raw_frame":"{\"market\":\"0xd412ce774cfcf8dc9f71164aac78783978aac7b03871702a3b8a481bd9dc9688\", \"price_changes\":[{\"asset_id\":\"107603864457683460275633293642179940881969192120168665300712204232021063124301\", \"price\":\"0.54\", \"size\":\"74.1\", \"side\":\"BUY\", \"hash\":\"8361c143c626b667b60c8366c0bfa712c8b76848\", \"best_bid\":\"0.57\", \"best_ask\":\"0.58\"}, {\"asset_id\":\"96600821790790307414914106093858868634329285205417149685270682748367152458577\", \"price\":\"0.46\", \"size\":\"74.1\", \"side\":\"SELL\", \"hash\":\"d4b46dac29d75318fd33f1d9e17ee9c64791df8f\", \"best_bid\":\"0.42\", \"best_ask\":\"0.43\"}], \"timestamp\":\"1785211376179\", \"event_type\":\"price_change\"}","received_at":"2026-07-28T04:02:59.899939Z","schema_version":"clob-market-ws.price_change.v1","sequence":null,"server_hash":null,"server_timestamp":"1785211376179","session_id":"2d607381e3054cee91998cdf45a4231c","source":"clob_market_ws"},"received_at":"2026-07-28T04:02:59.899939Z","record_id":"44df2c2fea43af4d1f960b04aaff36e255b05c40aca240f018d4d4f8e2792a78","schema_fingerprint":"4aa3821a28b0b7c2400bc59aba4bcc0a76e971dadd19610d3ad38c768e124dc7","schema_version":"edge-lab-recorder.raw.v1","sequence":null,"source":"clob_market_ws"}
{"event_at":"2026-07-28T04:02:56.180000Z","event_fingerprint":"92750f35f90a67de1207d8fd4e5c3bca5df7bbab0b22448073674e5039fd24b8","payload":{"connection_id":"f6725804f86a4c4eb588e4d5ed7db029","event_at":"2026-07-28T04:02:56.180000Z","event_type":"price_change","frame_hash":"58879b074d233702d38d19d204600eb7055b064b1933b8face06b240b94e6e46","frame_index":0,"kind":"data","monotonic_ns":313362950679916,"payload":{"event_type":"price_change","market":"0xd412ce774cfcf8dc9f71164aac78783978aac7b03871702a3b8a481bd9dc9688","price_changes":[{"asset_id":"96600821790790307414914106093858868634329285205417149685270682748367152458577","best_ask":"0.43","best_bid":"0.42","hash":"66759d3ba23762124893e46530114011de7c0219","price":"0.5","side":"SELL","size":"319.99"},{"asset_id":"107603864457683460275633293642179940881969192120168665300712204232021063124301","best_ask":"0.58","best_bid":"0.57","hash":"3319c379c36b6c2da998f892891e11fe1bf54db1","price":"0.5","side":"BUY","size":"319.99"}],"timestamp":"1785211376180"},"payload_hash":"8cd9032b858decda727776382e38e685f5a5880038218e01614cb15b89d70827","raw_frame":"{\"market\":\"0xd412ce774cfcf8dc9f71164aac78783978aac7b03871702a3b8a481bd9dc9688\", \"price_changes\":[{\"asset_id\":\"96600821790790307414914106093858868634329285205417149685270682748367152458577\", \"price\":\"0.5\", \"size\":\"319.99\", \"side\":\"SELL\", \"hash\":\"66759d3ba23762124893e46530114011de7c0219\", \"best_bid\":\"0.42\", \"best_ask\":\"0.43\"}, {\"asset_id\":\"107603864457683460275633293642179940881969192120168665300712204232021063124301\", \"price\":\"0.5\", \"size\":\"319.99\", \"side\":\"BUY\", \"hash\":\"3319c379c36b6c2da998f892891e11fe1bf54db1\", \"best_bid\":\"0.57\", \"best_ask\":\"0.58\"}], \"timestamp\":\"1785211376180\", \"event_type\":\"price_change\"}","received_at":"2026-07-28T04:02:59.901437Z","schema_version":"clob-market-ws.price_change.v1","sequence":null,"server_hash":null,"server_timestamp":"1785211376180","session_id":"2d607381e3054cee91998cdf45a4231c","source":"clob_market_ws"},"received_at":"2026-07-28T04:02:59.901437Z","record_id":"1892db0e8c9d9374e0975b6bc8864ee4961dc4771fea0f3e779ae946fe076fdf","schema_fingerprint":"4aa3821a28b0b7c2400bc59aba4bcc0a76e971dadd19610d3ad38c768e124dc7","schema_version":"edge-lab-recorder.raw.v1","sequence":null,"source":"clob_market_ws"}
{"event_at":"2026-07-28T04:02:56.180000Z","event_fingerprint":"771995a1a6a9548bdc29ab728a59a875f223c9e643f876a70381f26583834fe1","payload":{"connection_id":"f6725804f86a4c4eb588e4d5ed7db029","event_at":"2026-07-28T04:02:56.180000Z","event_type":"price_change","frame_hash":"cc3db42cda9e82bc822d2a918452cf4b4b9dc7db9d69889eaa74cbba7a657ffa","frame_index":0,"kind":"data","monotonic_ns":313362952165708,"payload":{"event_type":"price_change","market":"0xd412ce774cfcf8dc9f71164aac78783978aac7b03871702a3b8a481bd9dc9688","price_changes":[{"asset_id":"107603864457683460275633293642179940881969192120168665300712204232021063124301","best_ask":"0.58","best_bid":"0.57","hash":"2dc122a16a086ed4d459fbbd1d30ef11b1f418fb","price":"0.03","side":"BUY","size":"613.1"},{"asset_id":"96600821790790307414914106093858868634329285205417149685270682748367152458577","best_ask":"0.43","best_bid":"0.42","hash":"8c8ffb552eb8fbe5780af9d213753fb3b11bfa8a","price":"0.97","side":"SELL","size":"613.1"}],"timestamp":"1785211376180"},"payload_hash":"163ba6a236f35aabfaf0d6a3251eaa8211f4a40ce58b96c027277a0eb0b9e001","raw_frame":"{\"market\":\"0xd412ce774cfcf8dc9f71164aac78783978aac7b03871702a3b8a481bd9dc9688\", \"price_changes\":[{\"asset_id\":\"107603864457683460275633293642179940881969192120168665300712204232021063124301\", \"price\":\"0.03\", \"size\":\"613.1\", \"side\":\"BUY\", \"hash\":\"2dc122a16a086ed4d459fbbd1d30ef11b1f418fb\", \"best_bid\":\"0.57\", \"best_ask\":\"0.58\"}, {\"asset_id\":\"96600821790790307414914106093858868634329285205417149685270682748367152458577\", \"price\":\"0.97\", \"size\":\"613.1\", \"side\":\"SELL\", \"hash\":\"8c8ffb552eb8fbe5780af9d213753fb3b11bfa8a\", \"best_bid\":\"0.42\", \"best_ask\":\"0.43\"}], \"timestamp\":\"1785211376180\", \"event_type\":\"price_change\"}","received_at":"2026-07-28T04:02:59.902922Z","schema_version":"clob-market-ws.price_change.v1","sequence":null,"server_hash":null,"server_timestamp":"1785211376180","session_id":"2d607381e3054cee91998cdf45a4231c","source":"clob_market_ws"},"received_at":"2026-07-28T04:02:59.902922Z","record_id":"36f87cfc5c6ce1bc3cfc15a2b54adda32316d9ab01513ceab9ddc123b384c913","schema_fingerprint":"4aa3821a28b0b7c2400bc59aba4bcc0a76e971dadd19610d3ad38c768e124dc7","schema_version":"edge-lab-recorder.raw.v1","sequence":null,"source":"clob_market_ws"}
{"event_at":"2026-07-28T04:02:56.181000Z","event_fingerprint":"b916605b2980b2257224107df2691850b56f91ed50df05f954c41184c60d29e2","payload":{"connection_id":"f6725804f86a4c4eb588e4d5ed7db029","event_at":"2026-07-28T04:02:56.181000Z","event_type":"price_change","frame_hash":"a8afe81c39b52c3c76c60b30e798c099a16618c860da2af49c532ed17a9d26aa","frame_index":0,"kind":"data","monotonic_ns":313362953638500,"payload":{"event_type":"price_change","market":"0xd412ce774cfcf8dc9f71164aac78783978aac7b03871702a3b8a481bd9dc9688","price_changes":[{"asset_id":"96600821790790307414914106093858868634329285205417149685270682748367152458577","best_ask":"0.43","best_bid":"0.42","hash":"b0b38f491268297a8ef70f8c4699a71b17d1b0d9","price":"0.42","side":"BUY","size":"53.6"},{"asset_id":"107603864457683460275633293642179940881969192120168665300712204232021063124301","best_ask":"0.58","best_bid":"0.57","hash":"4e43e654dbffa340e3baf672558b1b3052dc4419","price":"0.58","side":"SELL","size":"53.6"}],"timestamp":"1785211376181"},"payload_hash":"b3fda01e78553bb7dc41bfb41d2ec6584597d16a31fe93ee991a85f98ec7ab5b","raw_frame":"{\"market\":\"0xd412ce774cfcf8dc9f71164aac78783978aac7b03871702a3b8a481bd9dc9688\", \"price_changes\":[{\"asset_id\":\"96600821790790307414914106093858868634329285205417149685270682748367152458577\", \"price\":\"0.42\", \"size\":\"53.6\", \"side\":\"BUY\", \"hash\":\"b0b38f491268297a8ef70f8c4699a71b17d1b0d9\", \"best_bid\":\"0.42\", \"best_ask\":\"0.43\"}, {\"asset_id\":\"107603864457683460275633293642179940881969192120168665300712204232021063124301\", \"price\":\"0.58\", \"size\":\"53.6\", \"side\":\"SELL\", \"hash\":\"4e43e654dbffa340e3baf672558b1b3052dc4419\", \"best_bid\":\"0.57\", \"best_ask\":\"0.58\"}], \"timestamp\":\"1785211376181\", \"event_type\":\"price_change\"}","received_at":"2026-07-28T04:02:59.904395Z","schema_version":"clob-market-ws.price_change.v1","sequence":null,"server_hash":null,"server_timestamp":"1785211376181","session_id":"2d607381e3054cee91998cdf45a4231c","source":"clob_market_ws"},"received_at":"2026-07-28T04:02:59.904395Z","record_id":"844317972195dc4b3c4877b1433e673c6e8243754595eae04566e74006464b86","schema_fingerprint":"4aa3821a28b0b7c2400bc59aba4bcc0a76e971dadd19610d3ad38c768e124dc7","schema_version":"edge-lab-recorder.raw.v1","sequence":null,"source":"clob_market_ws"}
{"event_at":"2026-07-28T04:02:56.181000Z","event_fingerprint":"ad3158ae9658ddb12f7941397683f38935ffac5156e10deb999e6343cc57491d","payload":{"connection_id":"f6725804f86a4c4eb588e4d5ed7db029","event_at":"2026-07-28T04:02:56.181000Z","event_type":"price_change","frame_hash":"be565da68128e169d71a9351ee7748c19cd55ec97a5228c6d97adeccfeca8ae1","frame_index":0,"kind":"data","monotonic_ns":313362955117250,"payload":{"event_type":"price_change","market":"0xd412ce774cfcf8dc9f71164aac78783978aac7b03871702a3b8a481bd9dc9688","price_changes":[{"asset_id":"107603864457683460275633293642179940881969192120168665300712204232021063124301","best_ask":"0.58","best_bid":"0.57","hash":"5343b915265637a798697681b3654e6a7a46dec9","price":"0.01","side":"BUY","size":"7883.02"},{"asset_id":"96600821790790307414914106093858868634329285205417149685270682748367152458577","best_ask":"0.43","best_bid":"0.42","hash":"1128e66c42e804f080425817bc257a8fd3ecfa0e","price":"0.99","side":"SELL","size":"7883.02"}],"timestamp":"1785211376181"},"payload_hash":"1d2ea3434d52e3df09a93b848f5ce08e3f7004a9e149b9493e153b5bd84b1b6e","raw_frame":"{\"market\":\"0xd412ce774cfcf8dc9f71164aac78783978aac7b03871702a3b8a481bd9dc9688\", \"price_changes\":[{\"asset_id\":\"107603864457683460275633293642179940881969192120168665300712204232021063124301\", \"price\":\"0.01\", \"size\":\"7883.02\", \"side\":\"BUY\", \"hash\":\"5343b915265637a798697681b3654e6a7a46dec9\", \"best_bid\":\"0.57\", \"best_ask\":\"0.58\"}, {\"asset_id\":\"96600821790790307414914106093858868634329285205417149685270682748367152458577\", \"price\":\"0.99\", \"size\":\"7883.02\", \"side\":\"SELL\", \"hash\":\"1128e66c42e804f080425817bc257a8fd3ecfa0e\", \"best_bid\":\"0.42\", \"best_ask\":\"0.43\"}], \"timestamp\":\"1785211376181\", \"event_type\":\"price_change\"}","received_at":"2026-07-28T04:02:59.905874Z","schema_version":"clob-market-ws.price_change.v1","sequence":null,"server_hash":null,"server_timestamp":"1785211376181","session_id":"2d607381e3054cee91998cdf45a4231c","source":"clob_market_ws"},"received_at":"2026-07-28T04:02:59.905874Z","record_id":"09d4f26854e856d5f6540bd8cea3b690a9894b7a5f77e560abbbab8dfc1f595e","schema_fingerprint":"4aa3821a28b0b7c2400bc59aba4bcc0a76e971dadd19610d3ad38c768e124dc7","schema_version":"edge-lab-recorder.raw.v1","sequence":null,"source":"clob_market_ws"}
{"event_at":"2026-07-28T04:02:56.181000Z","event_fingerprint":"1e619c484bdfe7857c716a079c82fb5db29e9625916760f74a4dce17b45ab9cf","payload":{"connection_id":"f6725804f86a4c4eb588e4d5ed7db029","event_at":"2026-07-28T04:02:56.181000Z","event_type":"price_change","frame_hash":"4b26c8ee5da7885ff0fefc83b144b7472fda9405d40417a12d55bd9d8ac24d03","frame_index":0,"kind":"data","monotonic_ns":313362956579250,"payload":{"event_type":"price_change","market":"0xd412ce774cfcf8dc9f71164aac78783978aac7b03871702a3b8a481bd9dc9688","price_changes":[{"asset_id":"96600821790790307414914106093858868634329285205417149685270682748367152458577","best_ask":"0.43","best_bid":"0.42","hash":"a0ac26aaf7825ff83a08718719f0bcd3fe2ee9f5","price":"0.42","side":"BUY","size":"78.6"},{"asset_id":"107603864457683460275633293642179940881969192120168665300712204232021063124301","best_ask":"0.58","best_bid":"0.57","hash":"fff9d0ad120552af25b5d69cb725265ef466b875","price":"0.58","side":"SELL","size":"78.6"}],"timestamp":"1785211376181"},"payload_hash":"11be81c12cbda93a4ed8c650a877d5b3a8eb06a29452b03f3c77c606f65f76ef","raw_frame":"{\"market\":\"0xd412ce774cfcf8dc9f71164aac78783978aac7b03871702a3b8a481bd9dc9688\", \"price_changes\":[{\"asset_id\":\"96600821790790307414914106093858868634329285205417149685270682748367152458577\", \"price\":\"0.42\", \"size\":\"78.6\", \"side\":\"BUY\", \"hash\":\"a0ac26aaf7825ff83a08718719f0bcd3fe2ee9f5\", \"best_bid\":\"0.42\", \"best_ask\":\"0.43\"}, {\"asset_id\":\"107603864457683460275633293642179940881969192120168665300712204232021063124301\", \"price\":\"0.58\", \"size\":\"78.6\", \"side\":\"SELL\", \"hash\":\"fff9d0ad120552af25b5d69cb725265ef466b875\", \"best_bid\":\"0.57\", \"best_ask\":\"0.58\"}], \"timestamp\":\"1785211376181\", \"event_type\":\"price_change\"}","received_at":"2026-07-28T04:02:59.907336Z","schema_version":"clob-market-ws.price_change.v1","sequence":null,"server_hash":null,"server_timestamp":"1785211376181","session_id":"2d607381e3054cee91998cdf45a4231c","source":"clob_market_ws"},"received_at":"2026-07-28T04:02:59.907336Z","record_id":"7dca43ab27a7bbe4ea8bd5790e0891f94d754cd9e8e9a692b7a6b603b2d32268","schema_fingerprint":"4aa3821a28b0b7c2400bc59aba4bcc0a76e971dadd19610d3ad38c768e124dc7","schema_version":"edge-lab-recorder.raw.v1","sequence":null,"source":"clob_market_ws"}
{"event_at":"2026-07-28T04:02:56.183000Z","event_fingerprint":"b1d5af06310b95b89fcd5794639a861b53f69e20bd9b004ac80932b3bc70297d","payload":{"connection_id":"f6725804f86a4c4eb588e4d5ed7db029","event_at":"2026-07-28T04:02:56.183000Z","event_type":"price_change","frame_hash":"9c36846593e411b801081b653ae51067f8e8f45e52183fffbe80a6db09d264c1","frame_index":0,"kind":"data","monotonic_ns":313362958060958,"payload":{"event_type":"price_change","market":"0xd412ce774cfcf8dc9f71164aac78783978aac7b03871702a3b8a481bd9dc9688","price_changes":[{"asset_id":"96600821790790307414914106093858868634329285205417149685270682748367152458577","best_ask":"0.43","best_bid":"0.42","hash":"85c8028e442847f22093aab19ea2099a6dc45fd0","price":"0.42","side":"BUY","size":"56.6"},{"asset_id":"107603864457683460275633293642179940881969192120168665300712204232021063124301","best_ask":"0.58","best_bid":"0.57","hash":"51a7bfd0964ed666e723e6991d68e70d54f09d86","price":"0.58","side":"SELL","size":"56.6"}],"timestamp":"1785211376183"},"payload_hash":"00e24437da974a47f404b890cf80984a090dbbab9195bf8b82a8f1b34284089f","raw_frame":"{\"market\":\"0xd412ce774cfcf8dc9f71164aac78783978aac7b03871702a3b8a481bd9dc9688\", \"price_changes\":[{\"asset_id\":\"96600821790790307414914106093858868634329285205417149685270682748367152458577\", \"price\":\"0.42\", \"size\":\"56.6\", \"side\":\"BUY\", \"hash\":\"85c8028e442847f22093aab19ea2099a6dc45fd0\", \"best_bid\":\"0.42\", \"best_ask\":\"0.43\"}, {\"asset_id\":\"107603864457683460275633293642179940881969192120168665300712204232021063124301\", \"price\":\"0.58\", \"size\":\"56.6\", \"side\":\"SELL\", \"hash\":\"51a7bfd0964ed666e723e6991d68e70d54f09d86\", \"best_bid\":\"0.57\", \"best_ask\":\"0.58\"}], \"timestamp\":\"1785211376183\", \"event_type\":\"price_change\"}","received_at":"2026-07-28T04:02:59.908818Z","schema_version":"clob-market-ws.price_change.v1","sequence":null,"server_hash":null,"server_timestamp":"1785211376183","session_id":"2d607381e3054cee91998cdf45a4231c","source":"clob_market_ws"},"received_at":"2026-07-28T04:02:59.908818Z","record_id":"40a44ed44b56cbdcfdcfe0255bf6ef868785d8bc12dff16753bd1dfeef3d314f","schema_fingerprint":"4aa3821a28b0b7c2400bc59aba4bcc0a76e971dadd19610d3ad38c768e124dc7","schema_version":"edge-lab-recorder.raw.v1","sequence":null,"source":"clob_market_ws"}
{"event_at":"2026-07-28T04:02:56.184000Z","event_fingerprint":"7cd80731d7ea3fbe059f27205aa91bfed9d9e6b796aa2797f37cb6691619e698","payload":{"connection_id":"f6725804f86a4c4eb588e4d5ed7db029","event_at":"2026-07-28T04:02:56.184000Z","event_type":"price_change","frame_hash":"b7de89c6623f686d61cfc38d20d4c48b43adfac23ed29bda2353a6d9e4780d8f","frame_index":0,"kind":"data","monotonic_ns":313362959501125,"payload":{"event_type":"price_change","market":"0xd412ce774cfcf8dc9f71164aac78783978aac7b03871702a3b8a481bd9dc9688","price_changes":[{"asset_id":"96600821790790307414914106093858868634329285205417149685270682748367152458577","best_ask":"0.43","best_bid":"0.42","hash":"f1b698644538b813320d548b8c0c9aadbe5b986b","price":"0.32","side":"BUY","size":"135.58"},{"asset_id":"107603864457683460275633293642179940881969192120168665300712204232021063124301","best_ask":"0.58","best_bid":"0.57","hash":"195afa10e8fc20f1028ff8a8a1378d9a112a57f4","price":"0.68","side":"SELL","size":"135.58"}],"timestamp":"1785211376184"},"payload_hash":"52865092953945ce8500f2b23b782c231d77a4913c61569a121c787a48098f13","raw_frame":"{\"market\":\"0xd412ce774cfcf8dc9f71164aac78783978aac7b03871702a3b8a481bd9dc9688\", \"price_changes\":[{\"asset_id\":\"96600821790790307414914106093858868634329285205417149685270682748367152458577\", \"price\":\"0.32\", \"size\":\"135.58\", \"side\":\"BUY\", \"hash\":\"f1b698644538b813320d548b8c0c9aadbe5b986b\", \"best_bid\":\"0.42\", \"best_ask\":\"0.43\"}, {\"asset_id\":\"107603864457683460275633293642179940881969192120168665300712204232021063124301\", \"price\":\"0.68\", \"size\":\"135.58\", \"side\":\"SELL\", \"hash\":\"195afa10e8fc20f1028ff8a8a1378d9a112a57f4\", \"best_bid\":\"0.57\", \"best_ask\":\"0.58\"}], \"timestamp\":\"1785211376184\", \"event_type\":\"price_change\"}","received_at":"2026-07-28T04:02:59.910258Z","schema_version":"clob-market-ws.price_change.v1","sequence":null,"server_hash":null,"server_timestamp":"1785211376184","session_id":"2d607381e3054cee91998cdf45a4231c","source":"clob_market_ws"},"received_at":"2026-07-28T04:02:59.910258Z","record_id":"a9ddeb278ebfcb2c0e8571fb722fb54144797c66e9ee0d167a0abef0adc00577","schema_fingerprint":"4aa3821a28b0b7c2400bc59aba4bcc0a76e971dadd19610d3ad38c768e124dc7","schema_version":"edge-lab-recorder.raw.v1","sequence":null,"source":"clob_market_ws"}
{"event_at":"2026-07-28T04:02:56.185000Z","event_fingerprint":"ee76b4060df23cb2f2749f633ff780c1ab450421ccda858a54bf69315ba14550","payload":{"connection_id":"f6725804f86a4c4eb588e4d5ed7db029","event_at":"2026-07-28T04:02:56.185000Z","event_type":"price_change","frame_hash":"6ab16fd0ac46c81283bd4202abd6601006bc1e71cb4df3471c6d5fcc9ec971b5","frame_index":0,"kind":"data","monotonic_ns":313362961062750,"payload":{"event_type":"price_change","market":"0xd412ce774cfcf8dc9f71164aac78783978aac7b03871702a3b8a481bd9dc9688","price_changes":[{"asset_id":"96600821790790307414914106093858868634329285205417149685270682748367152458577","best_ask":"0.43","best_bid":"0.42","hash":"3a1384ed1f53d91b468f08d696a75cc268a8bf88","price":"0.33","side":"BUY","size":"164.41"},{"asset_id":"107603864457683460275633293642179940881969192120168665300712204232021063124301","best_ask":"0.58","best_bid":"0.57","hash":"47fbed8168c06d8cc9f50a851f2c9e58f6e97e32","price":"0.67","side":"SELL","size":"164.41"}],"timestamp":"1785211376185"},"payload_hash":"11fb9fea110c8cd6db71a3d83298dc246f7e74cf04b38577feb18aefd72cce84","raw_frame":"{\"market\":\"0xd412ce774cfcf8dc9f71164aac78783978aac7b03871702a3b8a481bd9dc9688\", \"price_changes\":[{\"asset_id\":\"96600821790790307414914106093858868634329285205417149685270682748367152458577\", \"price\":\"0.33\", \"size\":\"164.41\", \"side\":\"BUY\", \"hash\":\"3a1384ed1f53d91b468f08d696a75cc268a8bf88\", \"best_bid\":\"0.42\", \"best_ask\":\"0.43\"}, {\"asset_id\":\"107603864457683460275633293642179940881969192120168665300712204232021063124301\", \"price\":\"0.67\", \"size\":\"164.41\", \"side\":\"SELL\", \"hash\":\"47fbed8168c06d8cc9f50a851f2c9e58f6e97e32\", \"best_bid\":\"0.57\", \"best_ask\":\"0.58\"}], \"timestamp\":\"1785211376185\", \"event_type\":\"price_change\"}","received_at":"2026-07-28T04:02:59.911815Z","schema_version":"clob-market-ws.price_change.v1","sequence":null,"server_hash":null,"server_timestamp":"1785211376185","session_id":"2d607381e3054cee91998cdf45a4231c","source":"clob_market_ws"},"received_at":"2026-07-28T04:02:59.911815Z","record_id":"d85e4000024a6eedf6224e5072751dad2a24012e350481ba3099481d0cd28ed6","schema_fingerprint":"4aa3821a28b0b7c2400bc59aba4bcc0a76e971dadd19610d3ad38c768e124dc7","schema_version":"edge-lab-recorder.raw.v1","sequence":null,"source":"clob_market_ws"}
{"event_at":"2026-07-28T04:02:56.185000Z","event_fingerprint":"4fd28bf2dde98ef44bcdca32b9f7df0d41d7c80e8d853fcb5cd97aabbb65635d","payload":{"connection_id":"f6725804f86a4c4eb588e4d5ed7db029","event_at":"2026-07-28T04:02:56.185000Z","event_type":"price_change","frame_hash":"be1298ddb84a4e7c680ec68211c12895353b6fea4878f57ea5a6fe4ad94ef28a","frame_index":0,"kind":"data","monotonic_ns":313362962622416,"payload":{"event_type":"price_change","market":"0xd412ce774cfcf8dc9f71164aac78783978aac7b03871702a3b8a481bd9dc9688","price_changes":[{"asset_id":"107603864457683460275633293642179940881969192120168665300712204232021063124301","best_ask":"0.58","best_bid":"0.57","hash":"9e637e254246f1d7812058344386be0984e67390","price":"0.43","side":"BUY","size":"152.2"},{"asset_id":"96600821790790307414914106093858868634329285205417149685270682748367152458577","best_ask":"0.43","best_bid":"0.42","hash":"a24f8e0319493d549438784e03530263ff88a427","price":"0.57","side":"SELL","size":"152.2"}],"timestamp":"1785211376185"},"payload_hash":"0ad1f99e93cfc882e8bd4b4c5ffa0a50292017411deae699884e7f45964c3211","raw_frame":"{\"market\":\"0xd412ce774cfcf8dc9f71164aac78783978aac7b03871702a3b8a481bd9dc9688\", \"price_changes\":[{\"asset_id\":\"107603864457683460275633293642179940881969192120168665300712204232021063124301\", \"price\":\"0.43\", \"size\":\"152.2\", \"side\":\"BUY\", \"hash\":\"9e637e254246f1d7812058344386be0984e67390\", \"best_bid\":\"0.57\", \"best_ask\":\"0.58\"}, {\"asset_id\":\"96600821790790307414914106093858868634329285205417149685270682748367152458577\", \"price\":\"0.57\", \"size\":\"152.2\", \"side\":\"SELL\", \"hash\":\"a24f8e0319493d549438784e03530263ff88a427\", \"best_bid\":\"0.42\", \"best_ask\":\"0.43\"}], \"timestamp\":\"1785211376185\", \"event_type\":\"price_change\"}","received_at":"2026-07-28T04:02:59.913378Z","schema_version":"clob-market-ws.price_change.v1","sequence":null,"server_hash":null,"server_timestamp":"1785211376185","session_id":"2d607381e3054cee91998cdf45a4231c","source":"clob_market_ws"},"received_at":"2026-07-28T04:02:59.913378Z","record_id":"8b8a8063d878d5721316410c9c0b245c990e40ed79728e6be989bd7dd4934c34","schema_fingerprint":"4aa3821a28b0b7c2400bc59aba4bcc0a76e971dadd19610d3ad38c768e124dc7","schema_version":"edge-lab-recorder.raw.v1","sequence":null,"source":"clob_market_ws"}
{"event_at":"2026-07-28T04:02:56.186000Z","event_fingerprint":"c52a10a751e75bc5dd20a569efcda0deeb4caa6d7e57fe8a8a9d3ee2e0beb5bf","payload":{"connection_id":"f6725804f86a4c4eb588e4d5ed7db029","event_at":"2026-07-28T04:02:56.186000Z","event_type":"price_change","frame_hash":"8515f745dc3c8af68ee95be64daa0197141f91390467a07f4f0d8e34eb8d0049","frame_index":0,"kind":"data","monotonic_ns":313362964110791,"payload":{"event_type":"price_change","market":"0xd412ce774cfcf8dc9f71164aac78783978aac7b03871702a3b8a481bd9dc9688","price_changes":[{"asset_id":"96600821790790307414914106093858868634329285205417149685270682748367152458577","best_ask":"0.43","best_bid":"0.42","hash":"823a0a7fa399493572766a1a4c11d651d3bf2d98","price":"0.31","side":"BUY","size":"119.79"},{"asset_id":"107603864457683460275633293642179940881969192120168665300712204232021063124301","best_ask":"0.58","best_bid":"0.57","hash":"be45abaf8c314beeb5c78c0efd14cba5d3711506","price":"0.69","side":"SELL","size":"119.79"}],"timestamp":"1785211376186"},"payload_hash":"ca3b287810c00b0ccda1252bb94657318770f013ba433a40b28818d9778be69c","raw_frame":"{\"market\":\"0xd412ce774cfcf8dc9f71164aac78783978aac7b03871702a3b8a481bd9dc9688\", \"price_changes\":[{\"asset_id\":\"96600821790790307414914106093858868634329285205417149685270682748367152458577\", \"price\":\"0.31\", \"size\":\"119.79\", \"side\":\"BUY\", \"hash\":\"823a0a7fa399493572766a1a4c11d651d3bf2d98\", \"best_bid\":\"0.42\", \"best_ask\":\"0.43\"}, {\"asset_id\":\"107603864457683460275633293642179940881969192120168665300712204232021063124301\", \"price\":\"0.69\", \"size\":\"119.79\", \"side\":\"SELL\", \"hash\":\"be45abaf8c314beeb5c78c0efd14cba5d3711506\", \"best_bid\":\"0.57\", \"best_ask\":\"0.58\"}], \"timestamp\":\"1785211376186\", \"event_type\":\"price_change\"}","received_at":"2026-07-28T04:02:59.914865Z","schema_version":"clob-market-ws.price_change.v1","sequence":null,"server_hash":null,"server_timestamp":"1785211376186","session_id":"2d607381e3054cee91998cdf45a4231c","source":"clob_market_ws"},"received_at":"2026-07-28T04:02:59.914865Z","record_id":"a2c76d06382cc9f0fe0a057354850903729c6cc078e1f1a1fe36a7d6a5ff17c1","schema_fingerprint":"4aa3821a28b0b7c2400bc59aba4bcc0a76e971dadd19610d3ad38c768e124dc7","schema_version":"edge-lab-recorder.raw.v1","sequence":null,"source":"clob_market_ws"}
{"event_at":"2026-07-28T04:02:56.187000Z","event_fingerprint":"b40e7d1cf324116d073b8c731b1913cbaa5cd13831d7201d10f501626eeb4dac","payload":{"connection_id":"f6725804f86a4c4eb588e4d5ed7db029","event_at":"2026-07-28T04:02:56.187000Z","event_type":"price_change","frame_hash":"9e60e739e13617030888d05a1896723bf593aae5e70c0d0c396a309de0f4fe3e","frame_index":0,"kind":"data","monotonic_ns":313362965661833,"payload":{"event_type":"price_change","market":"0xd412ce774cfcf8dc9f71164aac78783978aac7b03871702a3b8a481bd9dc9688","price_changes":[{"asset_id":"96600821790790307414914106093858868634329285205417149685270682748367152458577","best_ask":"0.43","best_bid":"0.42","hash":"42e4fe8f2ced1790b2677e396d8984b197fe26a9","price":"0.35","side":"BUY","size":"114"},{"asset_id":"107603864457683460275633293642179940881969192120168665300712204232021063124301","best_ask":"0.58","best_bid":"0.57","hash":"ebfe66a093c16c917dac5bdb76d0a408124774c8","price":"0.65","side":"SELL","size":"114"}],"timestamp":"1785211376187"},"payload_hash":"85cb44aacc6d94707d93da68c4f791972d8117e4be13e74de8f5e02d859bc4e4","raw_frame":"{\"market\":\"0xd412ce774cfcf8dc9f71164aac78783978aac7b03871702a3b8a481bd9dc9688\", \"price_changes\":[{\"asset_id\":\"96600821790790307414914106093858868634329285205417149685270682748367152458577\", \"price\":\"0.35\", \"size\":\"114\", \"side\":\"BUY\", \"hash\":\"42e4fe8f2ced1790b2677e396d8984b197fe26a9\", \"best_bid\":\"0.42\", \"best_ask\":\"0.43\"}, {\"asset_id\":\"107603864457683460275633293642179940881969192120168665300712204232021063124301\", \"price\":\"0.65\", \"size\":\"114\", \"side\":\"SELL\", \"hash\":\"ebfe66a093c16c917dac5bdb76d0a408124774c8\", \"best_bid\":\"0.57\", \"best_ask\":\"0.58\"}], \"timestamp\":\"1785211376187\", \"event_type\":\"price_change\"}","received_at":"2026-07-28T04:02:59.916418Z","schema_version":"clob-market-ws.price_change.v1","sequence":null,"server_hash":null,"server_timestamp":"1785211376187","session_id":"2d607381e3054cee91998cdf45a4231c","source":"clob_market_ws"},"received_at":"2026-07-28T04:02:59.916418Z","record_id":"1da7357a6bc8f0e4ab85a97f74803ddf9654d7807635097b109760a92cbe4cbe","schema_fingerprint":"4aa3821a28b0b7c2400bc59aba4bcc0a76e971dadd19610d3ad38c768e124dc7","schema_version":"edge-lab-recorder.raw.v1","sequence":null,"source":"clob_market_ws"}
{"event_at":"2026-07-28T04:02:56.194000Z","event_fingerprint":"253ca601f63b09bc588832cb614979760821e7db373e94823973a7d178305186","payload":{"connection_id":"f6725804f86a4c4eb588e4d5ed7db029","event_at":"2026-07-28T04:02:56.194000Z","event_type":"price_change","frame_hash":"bec100c052e55ce4e940920cf5de393c3625b201e17aca3b983266a5feb0c9df","frame_index":0,"kind":"data","monotonic_ns":313362967135791,"payload":{"event_type":"price_change","market":"0xd412ce774cfcf8dc9f71164aac78783978aac7b03871702a3b8a481bd9dc9688","price_changes":[{"asset_id":"96600821790790307414914106093858868634329285205417149685270682748367152458577","best_ask":"0.43","best_bid":"0.42","hash":"5c65319c610aea10758be759911a6fd94d714a3f","price":"0.42","side":"BUY","size":"61.6"},{"asset_id":"107603864457683460275633293642179940881969192120168665300712204232021063124301","best_ask":"0.58","best_bid":"0.57","hash":"ba857ffb80000e26fcc016e84a1b750ddb8f6d7c","price":"0.58","side":"SELL","size":"61.6"}],"timestamp":"1785211376194"},"payload_hash":"632d2e3db95ce6bdda1425123e67c084ff980f1572fdc2d9e4414d7f20525309","raw_frame":"{\"market\":\"0xd412ce774cfcf8dc9f71164aac78783978aac7b03871702a3b8a481bd9dc9688\", \"price_changes\":[{\"asset_id\":\"96600821790790307414914106093858868634329285205417149685270682748367152458577\", \"price\":\"0.42\", \"size\":\"61.6\", \"side\":\"BUY\", \"hash\":\"5c65319c610aea10758be759911a6fd94d714a3f\", \"best_bid\":\"0.42\", \"best_ask\":\"0.43\"}, {\"asset_id\":\"107603864457683460275633293642179940881969192120168665300712204232021063124301\", \"price\":\"0.58\", \"size\":\"61.6\", \"side\":\"SELL\", \"hash\":\"ba857ffb80000e26fcc016e84a1b750ddb8f6d7c\", \"best_bid\":\"0.57\", \"best_ask\":\"0.58\"}], \"timestamp\":\"1785211376194\", \"event_type\":\"price_change\"}","received_at":"2026-07-28T04:02:59.917890Z","schema_version":"clob-market-ws.price_change.v1","sequence":null,"server_hash":null,"server_timestamp":"1785211376194","session_id":"2d607381e3054cee91998cdf45a4231c","source":"clob_market_ws"},"received_at":"2026-07-28T04:02:59.917890Z","record_id":"3b8f8f3c6b873188a1c0e87288f2bb8e7c1570116fd82b6239147c2a51357ab6","schema_fingerprint":"4aa3821a28b0b7c2400bc59aba4bcc0a76e971dadd19610d3ad38c768e124dc7","schema_version":"edge-lab-recorder.raw.v1","sequence":null,"source":"clob_market_ws"}
{"event_at":"2026-07-28T04:02:56.202000Z","event_fingerprint":"9d042cb9b365c39534553ca7d5e3e1fbdfbd2aee7e63ed9ffd710d5e0159e1da","payload":{"connection_id":"f6725804f86a4c4eb588e4d5ed7db029","event_at":"2026-07-28T04:02:56.202000Z","event_type":"price_change","frame_hash":"87d9aa1ecf7827684e5dc14fae0a94df264011883cb11f5d44985dbc3fa6db1e","frame_index":0,"kind":"data","monotonic_ns":313362968802666,"payload":{"event_type":"price_change","market":"0xd412ce774cfcf8dc9f71164aac78783978aac7b03871702a3b8a481bd9dc9688","price_changes":[{"asset_id":"107603864457683460275633293642179940881969192120168665300712204232021063124301","best_ask":"0.58","best_bid":"0.57","hash":"b31515d482e1c3afca00865e5b53dcc894dd8262","price":"0.57","side":"BUY","size":"30.6"},{"asset_id":"96600821790790307414914106093858868634329285205417149685270682748367152458577","best_ask":"0.43","best_bid":"0.42","hash":"16bebe55636ba82ffc0043c009fa1a6c0f13a33c","price":"0.43","side":"SELL","size":"30.6"}],"timestamp":"1785211376202"},"payload_hash":"74a2de93d90395bf19a80ffca11d5a0d4be169abcde3ef876168cb9c8d203e52","raw_frame":"{\"market\":\"0xd412ce774cfcf8dc9f71164aac78783978aac7b03871702a3b8a481bd9dc9688\", \"price_changes\":[{\"asset_id\":\"107603864457683460275633293642179940881969192120168665300712204232021063124301\", \"price\":\"0.57\", \"size\":\"30.6\", \"side\":\"BUY\", \"hash\":\"b31515d482e1c3afca00865e5b53dcc894dd8262\", \"best_bid\":\"0.57\", \"best_ask\":\"0.58\"}, {\"asset_id\":\"96600821790790307414914106093858868634329285205417149685270682748367152458577\", \"price\":\"0.43\", \"size\":\"30.6\", \"side\":\"SELL\", \"hash\":\"16bebe55636ba82ffc0043c009fa1a6c0f13a33c\", \"best_bid\":\"0.42\", \"best_ask\":\"0.43\"}], \"timestamp\":\"1785211376202\", \"event_type\":\"price_change\"}","received_at":"2026-07-28T04:02:59.919557Z","schema_version":"clob-market-ws.price_change.v1","sequence":null,"server_hash":null,"server_timestamp":"1785211376202","session_id":"2d607381e3054cee91998cdf45a4231c","source":"clob_market_ws"},"received_at":"2026-07-28T04:02:59.919557Z","record_id":"2164a558f58fc0826306188e375b0ca76cbc8922ac12a84f8e026d0cbfd7f83b","schema_fingerprint":"4aa3821a28b0b7c2400bc59aba4bcc0a76e971dadd19610d3ad38c768e124dc7","schema_version":"edge-lab-recorder.raw.v1","sequence":null,"source":"clob_market_ws"}
{"event_at":"2026-07-28T04:02:56.204000Z","event_fingerprint":"656701f61df017ea9437a1d892012fbd3ec2f8f99435181dee4b914ab0a137fb","payload":{"connection_id":"f6725804f86a4c4eb588e4d5ed7db029","event_at":"2026-07-28T04:02:56.204000Z","event_type":"price_change","frame_hash":"62f95bf732f8c940410a581aee28085a8d5f42cb92f172ba8a68a5e0d13ca8b5","frame_index":0,"kind":"data","monotonic_ns":313362970334500,"payload":{"event_type":"price_change","market":"0xd412ce774cfcf8dc9f71164aac78783978aac7b03871702a3b8a481bd9dc9688","price_changes":[{"asset_id":"96600821790790307414914106093858868634329285205417149685270682748367152458577","best_ask":"0.43","best_bid":"0.42","hash":"ede6408a2adc371525654ed4f7c8dfc4abeb0335","price":"0.31","side":"BUY","size":"133.79"},{"asset_id":"107603864457683460275633293642179940881969192120168665300712204232021063124301","best_ask":"0.58","best_bid":"0.57","hash":"c38b7ae378043d9a96e098dea9c301dab1d0ab7a","price":"0.69","side":"SELL","size":"133.79"}],"timestamp":"1785211376204"},"payload_hash":"4ca87a7906184d3c8cd7bb479582d86627dae659cd519a875fd4183ed4225276","raw_frame":"{\"market\":\"0xd412ce774cfcf8dc9f71164aac78783978aac7b03871702a3b8a481bd9dc9688\", \"price_changes\":[{\"asset_id\":\"96600821790790307414914106093858868634329285205417149685270682748367152458577\", \"price\":\"0.31\", \"size\":\"133.79\", \"side\":\"BUY\", \"hash\":\"ede6408a2adc371525654ed4f7c8dfc4abeb0335\", \"best_bid\":\"0.42\", \"best_ask\":\"0.43\"}, {\"asset_id\":\"107603864457683460275633293642179940881969192120168665300712204232021063124301\", \"price\":\"0.69\", \"size\":\"133.79\", \"side\":\"SELL\", \"hash\":\"c38b7ae378043d9a96e098dea9c301dab1d0ab7a\", \"best_bid\":\"0.57\", \"best_ask\":\"0.58\"}], \"timestamp\":\"1785211376204\", \"event_type\":\"price_change\"}","received_at":"2026-07-28T04:02:59.921091Z","schema_version":"clob-market-ws.price_change.v1","sequence":null,"server_hash":null,"server_timestamp":"1785211376204","session_id":"2d607381e3054cee91998cdf45a4231c","source":"clob_market_ws"},"received_at":"2026-07-28T04:02:59.921091Z","record_id":"552d8cf0fe4244316784d7639f586913bbe37f3e0227c34f1e3f5d704afea45e","schema_fingerprint":"4aa3821a28b0b7c2400bc59aba4bcc0a76e971dadd19610d3ad38c768e124dc7","schema_version":"edge-lab-recorder.raw.v1","sequence":null,"source":"clob_market_ws"}
{"event_at":"2026-07-28T04:02:56.206000Z","event_fingerprint":"64e0189985ab5b0987e567bb0d0c5b86a3c64d77ca0b11501f4b89afaeb2ff78","payload":{"connection_id":"f6725804f86a4c4eb588e4d5ed7db029","event_at":"2026-07-28T04:02:56.206000Z","event_type":"price_change","frame_hash":"2005d43ed64f80a1305f8076a9cf3561513d664d9e6c1de8daac31043a5a9829","frame_index":0,"kind":"data","monotonic_ns":313362971847291,"payload":{"event_type":"price_change","market":"0xd412ce774cfcf8dc9f71164aac78783978aac7b03871702a3b8a481bd9dc9688","price_changes":[{"asset_id":"107603864457683460275633293642179940881969192120168665300712204232021063124301","best_ask":"0.58","best_bid":"0.57","hash":"f19bd828d3a2e47e9c59209bb924bbfd3b409d81","price":"0.57","side":"BUY","size":"18"},{"asset_id":"96600821790790307414914106093858868634329285205417149685270682748367152458577","best_ask":"0.43","best_bid":"0.42","hash":"9f03b580d69d00f528d7bd27a64fdbded3940510","price":"0.43","side":"SELL","size":"18"}],"timestamp":"1785211376206"},"payload_hash":"327b06aeac30dbb2ec2eab73dfcbec4289d1175db17ec4f1fb3db2990fbff6d4","raw_frame":"{\"market\":\"0xd412ce774cfcf8dc9f71164aac78783978aac7b03871702a3b8a481bd9dc9688\", \"price_changes\":[{\"asset_id\":\"107603864457683460275633293642179940881969192120168665300712204232021063124301\", \"price\":\"0.57\", \"size\":\"18\", \"side\":\"BUY\", \"hash\":\"f19bd828d3a2e47e9c59209bb924bbfd3b409d81\", \"best_bid\":\"0.57\", \"best_ask\":\"0.58\"}, {\"asset_id\":\"96600821790790307414914106093858868634329285205417149685270682748367152458577\", \"price\":\"0.43\", \"size\":\"18\", \"side\":\"SELL\", \"hash\":\"9f03b580d69d00f528d7bd27a64fdbded3940510\", \"best_bid\":\"0.42\", \"best_ask\":\"0.43\"}], \"timestamp\":\"1785211376206\", \"event_type\":\"price_change\"}","received_at":"2026-07-28T04:02:59.922601Z","schema_version":"clob-market-ws.price_change.v1","sequence":null,"server_hash":null,"server_timestamp":"1785211376206","session_id":"2d607381e3054cee91998cdf45a4231c","source":"clob_market_ws"},"received_at":"2026-07-28T04:02:59.922601Z","record_id":"f517ff05bc6ee7c018acf8712b3faba78380e7f615e294a1122d834a42dcaeb9","schema_fingerprint":"4aa3821a28b0b7c2400bc59aba4bcc0a76e971dadd19610d3ad38c768e124dc7","schema_version":"edge-lab-recorder.raw.v1","sequence":null,"source":"clob_market_ws"}
{"event_at":"2026-07-28T04:02:56.208000Z","event_fingerprint":"b9e565d4a58d33266defdbc7b867b5e88148344f7967ef907bcdd6da2573ad7f","payload":{"connection_id":"f6725804f86a4c4eb588e4d5ed7db029","event_at":"2026-07-28T04:02:56.208000Z","event_type":"price_change","frame_hash":"19b442118a18bae1bd155a00eaf0a097fe21d034e965f4ac1b7e9757da99e2a1","frame_index":0,"kind":"data","monotonic_ns":313362973446375,"payload":{"event_type":"price_change","market":"0xd412ce774cfcf8dc9f71164aac78783978aac7b03871702a3b8a481bd9dc9688","price_changes":[{"asset_id":"96600821790790307414914106093858868634329285205417149685270682748367152458577","best_ask":"0.43","best_bid":"0.42","hash":"468b65c53974bcb71ecb79ff56a50e12522a398c","price":"0.44","side":"SELL","size":"24"},{"asset_id":"107603864457683460275633293642179940881969192120168665300712204232021063124301","best_ask":"0.58","best_bid":"0.57","hash":"9a0b6d2d730ffefbecd3e23857aed90b017a71a6","price":"0.56","side":"BUY","size":"24"}],"timestamp":"1785211376208"},"payload_hash":"0108e048aeead45e79433fb9eee912ea506a3a5a984583c639c0ac51b31437b3","raw_frame":"{\"market\":\"0xd412ce774cfcf8dc9f71164aac78783978aac7b03871702a3b8a481bd9dc9688\", \"price_changes\":[{\"asset_id\":\"96600821790790307414914106093858868634329285205417149685270682748367152458577\", \"price\":\"0.44\", \"size\":\"24\", \"side\":\"SELL\", \"hash\":\"468b65c53974bcb71ecb79ff56a50e12522a398c\", \"best_bid\":\"0.42\", \"best_ask\":\"0.43\"}, {\"asset_id\":\"107603864457683460275633293642179940881969192120168665300712204232021063124301\", \"price\":\"0.56\", \"size\":\"24\", \"side\":\"BUY\", \"hash\":\"9a0b6d2d730ffefbecd3e23857aed90b017a71a6\", \"best_bid\":\"0.57\", \"best_ask\":\"0.58\"}], \"timestamp\":\"1785211376208\", \"event_type\":\"price_change\"}","received_at":"2026-07-28T04:02:59.924202Z","schema_version":"clob-market-ws.price_change.v1","sequence":null,"server_hash":null,"server_timestamp":"1785211376208","session_id":"2d607381e3054cee91998cdf45a4231c","source":"clob_market_ws"},"received_at":"2026-07-28T04:02:59.924202Z","record_id":"dc2944359bfd8793fad0651aff777b66b71771c4e4e49f1cf043a20b9e21ec6d","schema_fingerprint":"4aa3821a28b0b7c2400bc59aba4bcc0a76e971dadd19610d3ad38c768e124dc7","schema_version":"edge-lab-recorder.raw.v1","sequence":null,"source":"clob_market_ws"}
{"event_at":"2026-07-28T04:02:56.210000Z","event_fingerprint":"47c7e6864fcf5f4785444df9e42d7ca44c438eaeb85fbee9096935e1d930cc39","payload":{"connection_id":"f6725804f86a4c4eb588e4d5ed7db029","event_at":"2026-07-28T04:02:56.210000Z","event_type":"price_change","frame_hash":"8c975f0905774bb0726d9379ff68c0c89b841c61ad00cba63599f83e50d5d1f6","frame_index":0,"kind":"data","monotonic_ns":313362974944625,"payload":{"event_type":"price_change","market":"0xd412ce774cfcf8dc9f71164aac78783978aac7b03871702a3b8a481bd9dc9688","price_changes":[{"asset_id":"96600821790790307414914106093858868634329285205417149685270682748367152458577","best_ask":"0.43","best_bid":"0.42","hash":"5dc96a7a8a3dab8a98e1e18febcf6c9e5214fd14","price":"0.39","side":"BUY","size":"24.38"},{"asset_id":"107603864457683460275633293642179940881969192120168665300712204232021063124301","best_ask":"0.58","best_bid":"0.57","hash":"87fb2c4d1f5257c6f1549bc4660e4524f4869bf7","price":"0.61","side":"SELL","size":"24.38"}],"timestamp":"1785211376210"},"payload_hash":"4b4eac3d25c5f111eef23290100b836832bd9e4ead99081d413807ef3bfcb19b","raw_frame":"{\"market\":\"0xd412ce774cfcf8dc9f71164aac78783978aac7b03871702a3b8a481bd9dc9688\", \"price_changes\":[{\"asset_id\":\"96600821790790307414914106093858868634329285205417149685270682748367152458577\", \"price\":\"0.39\", \"size\":\"24.38\", \"side\":\"BUY\", \"hash\":\"5dc96a7a8a3dab8a98e1e18febcf6c9e5214fd14\", \"best_bid\":\"0.42\", \"best_ask\":\"0.43\"}, {\"asset_id\":\"107603864457683460275633293642179940881969192120168665300712204232021063124301\", \"price\":\"0.61\", \"size\":\"24.38\", \"side\":\"SELL\", \"hash\":\"87fb2c4d1f5257c6f1549bc4660e4524f4869bf7\", \"best_bid\":\"0.57\", \"best_ask\":\"0.58\"}], \"timestamp\":\"1785211376210\", \"event_type\":\"price_change\"}","received_at":"2026-07-28T04:02:59.925701Z","schema_version":"clob-market-ws.price_change.v1","sequence":null,"server_hash":null,"server_timestamp":"1785211376210","session_id":"2d607381e3054cee91998cdf45a4231c","source":"clob_market_ws"},"received_at":"2026-07-28T04:02:59.925701Z","record_id":"4a8a7e5e0ff1f16770443590a08f41bdfaae1d91aa985b8a243b1b3a47c5b57a","schema_fingerprint":"4aa3821a28b0b7c2400bc59aba4bcc0a76e971dadd19610d3ad38c768e124dc7","schema_version":"edge-lab-recorder.raw.v1","sequence":null,"source":"clob_market_ws"}
{"event_at":"2026-07-28T04:02:56.211000Z","event_fingerprint":"124b618374a4b582f9212bf7462880d1468bf0ed98ad9ca812f8045d6af58ef6","payload":{"connection_id":"f6725804f86a4c4eb588e4d5ed7db029","event_at":"2026-07-28T04:02:56.211000Z","event_type":"price_change","frame_hash":"e0a593ed594d7fe73b2fc962f52293c5d88dbb23fa9edd897480a54d697d6da3","frame_index":0,"kind":"data","monotonic_ns":313362976410875,"payload":{"event_type":"price_change","market":"0xd412ce774cfcf8dc9f71164aac78783978aac7b03871702a3b8a481bd9dc9688","price_changes":[{"asset_id":"96600821790790307414914106093858868634329285205417149685270682748367152458577","best_ask":"0.43","best_bid":"0.42","hash":"f86575387b3a3fb958f2950b23f4f26a2394427e","price":"0.41","side":"BUY","size":"62.88"},{"asset_id":"107603864457683460275633293642179940881969192120168665300712204232021063124301","best_ask":"0.58","best_bid":"0.57","hash":"5158ab9cb33febbe705e2211c6f2b879257113fb","price":"0.59","side":"SELL","size":"62.88"}],"timestamp":"1785211376211"},"payload_hash":"60831af0a390fc51b5e7a45d51b7e6d27abb78a6ee25b0d9c6770ef106c8c1f5","raw_frame":"{\"market\":\"0xd412ce774cfcf8dc9f71164aac78783978aac7b03871702a3b8a481bd9dc9688\", \"price_changes\":[{\"asset_id\":\"96600821790790307414914106093858868634329285205417149685270682748367152458577\", \"price\":\"0.41\", \"size\":\"62.88\", \"side\":\"BUY\", \"hash\":\"f86575387b3a3fb958f2950b23f4f26a2394427e\", \"best_bid\":\"0.42\", \"best_ask\":\"0.43\"}, {\"asset_id\":\"107603864457683460275633293642179940881969192120168665300712204232021063124301\", \"price\":\"0.59\", \"size\":\"62.88\", \"side\":\"SELL\", \"hash\":\"5158ab9cb33febbe705e2211c6f2b879257113fb\", \"best_bid\":\"0.57\", \"best_ask\":\"0.58\"}], \"timestamp\":\"1785211376211\", \"event_type\":\"price_change\"}","received_at":"2026-07-28T04:02:59.927167Z","schema_version":"clob-market-ws.price_change.v1","sequence":null,"server_hash":null,"server_timestamp":"1785211376211","session_id":"2d607381e3054cee91998cdf45a4231c","source":"clob_market_ws"},"received_at":"2026-07-28T04:02:59.927167Z","record_id":"fce2cb0225040107602a40b931a0e5d93ad4ade40d07c91bf6254a9486498b7f","schema_fingerprint":"4aa3821a28b0b7c2400bc59aba4bcc0a76e971dadd19610d3ad38c768e124dc7","schema_version":"edge-lab-recorder.raw.v1","sequence":null,"source":"clob_market_ws"}
{"event_at":"2026-07-28T04:02:56.214000Z","event_fingerprint":"408a33803782fe73044ba419da15f9603af83e023ce1a18771d36a572f904a89","payload":{"connection_id":"f6725804f86a4c4eb588e4d5ed7db029","event_at":"2026-07-28T04:02:56.214000Z","event_type":"price_change","frame_hash":"9faa07bec1f1d4216e1f05ed7d4946512f97c7d661e1ed6e0043ad110edaf2cf","frame_index":0,"kind":"data","monotonic_ns":313362977876833,"payload":{"event_type":"price_change","market":"0xd412ce774cfcf8dc9f71164aac78783978aac7b03871702a3b8a481bd9dc9688","price_changes":[{"asset_id":"107603864457683460275633293642179940881969192120168665300712204232021063124301","best_ask":"0.58","best_bid":"0.57","hash":"101bd157a65d47ccaec59a5b339a983ed92759c3","price":"0.56","side":"BUY","size":"15"},{"asset_id":"96600821790790307414914106093858868634329285205417149685270682748367152458577","best_ask":"0.43","best_bid":"0.42","hash":"662a1a4333a87d54f7e58040364a804f4ae16f9a","price":"0.44","side":"SELL","size":"15"}],"timestamp":"1785211376214"},"payload_hash":"eb4d7d51d0069706ed369439239bb68c0b6037147ca9a575c97b812d83e6568b","raw_frame":"{\"market\":\"0xd412ce774cfcf8dc9f71164aac78783978aac7b03871702a3b8a481bd9dc9688\", \"price_changes\":[{\"asset_id\":\"107603864457683460275633293642179940881969192120168665300712204232021063124301\", \"price\":\"0.56\", \"size\":\"15\", \"side\":\"BUY\", \"hash\":\"101bd157a65d47ccaec59a5b339a983ed92759c3\", \"best_bid\":\"0.57\", \"best_ask\":\"0.58\"}, {\"asset_id\":\"96600821790790307414914106093858868634329285205417149685270682748367152458577\", \"price\":\"0.44\", \"size\":\"15\", \"side\":\"SELL\", \"hash\":\"662a1a4333a87d54f7e58040364a804f4ae16f9a\", \"best_bid\":\"0.42\", \"best_ask\":\"0.43\"}], \"timestamp\":\"1785211376214\", \"event_type\":\"price_change\"}","received_at":"2026-07-28T04:02:59.928634Z","schema_version":"clob-market-ws.price_change.v1","sequence":null,"server_hash":null,"server_timestamp":"1785211376214","session_id":"2d607381e3054cee91998cdf45a4231c","source":"clob_market_ws"},"received_at":"2026-07-28T04:02:59.928634Z","record_id":"abcb65a0d14afb757ff0580e5959a3b5a6d078c9e7fb54be885b6aeb30fa0e08","schema_fingerprint":"4aa3821a28b0b7c2400bc59aba4bcc0a76e971dadd19610d3ad38c768e124dc7","schema_version":"edge-lab-recorder.raw.v1","sequence":null,"source":"clob_market_ws"}
{"event_at":"2026-07-28T04:02:56.222000Z","event_fingerprint":"b27e5f799291a4a51b1f635608efd412267907d9ed38c13b58bc338f818cd16f","payload":{"connection_id":"f6725804f86a4c4eb588e4d5ed7db029","event_at":"2026-07-28T04:02:56.222000Z","event_type":"price_change","frame_hash":"78dac175ac1fed1b196769374fba18e9c54464d84f953237f97e41192b7fc318","frame_index":0,"kind":"data","monotonic_ns":313362980937291,"payload":{"event_type":"price_change","market":"0xd412ce774cfcf8dc9f71164aac78783978aac7b03871702a3b8a481bd9dc9688","price_changes":[{"asset_id":"107603864457683460275633293642179940881969192120168665300712204232021063124301","best_ask":"0.58","best_bid":"0.57","hash":"c5e922c777e68431dae0ab5024998616141970fd","price":"0.56","side":"BUY","size":"21"},{"asset_id":"96600821790790307414914106093858868634329285205417149685270682748367152458577","best_ask":"0.43","best_bid":"0.42","hash":"225fca4ab46be037539b531001ca10bcfb42c904","price":"0.44","side":"SELL","size":"21"}],"timestamp":"1785211376222"},"payload_hash":"db1e59e612faeafc16098eb898f0bd19332445b9c475576c8b0063b1a07604c8","raw_frame":"{\"market\":\"0xd412ce774cfcf8dc9f71164aac78783978aac7b03871702a3b8a481bd9dc9688\", \"price_changes\":[{\"asset_id\":\"107603864457683460275633293642179940881969192120168665300712204232021063124301\", \"price\":\"0.56\", \"size\":\"21\", \"side\":\"BUY\", \"hash\":\"c5e922c777e68431dae0ab5024998616141970fd\", \"best_bid\":\"0.57\", \"best_ask\":\"0.58\"}, {\"asset_id\":\"96600821790790307414914106093858868634329285205417149685270682748367152458577\", \"price\":\"0.44\", \"size\":\"21\", \"side\":\"SELL\", \"hash\":\"225fca4ab46be037539b531001ca10bcfb42c904\", \"best_bid\":\"0.42\", \"best_ask\":\"0.43\"}], \"timestamp\":\"1785211376222\", \"event_type\":\"price_change\"}","received_at":"2026-07-28T04:02:59.931694Z","schema_version":"clob-market-ws.price_change.v1","sequence":null,"server_hash":null,"server_timestamp":"1785211376222","session_id":"2d607381e3054cee91998cdf45a4231c","source":"clob_market_ws"},"received_at":"2026-07-28T04:02:59.931694Z","record_id":"91a4252708b1245a6d8cec8ae3c220e6851e37a1e73e5d42805a4a1262084693","schema_fingerprint":"4aa3821a28b0b7c2400bc59aba4bcc0a76e971dadd19610d3ad38c768e124dc7","schema_version":"edge-lab-recorder.raw.v1","sequence":null,"source":"clob_market_ws"}
{"event_at":"2026-07-28T04:02:56.224000Z","event_fingerprint":"7ba4538a733b31503cb15bbc3aceb258ce73dd7d4ba0548eeef591adb574b306","payload":{"connection_id":"f6725804f86a4c4eb588e4d5ed7db029","event_at":"2026-07-28T04:02:56.224000Z","event_type":"price_change","frame_hash":"cbf976479843c7634a022993b11c195e6c8634610483bb390b97f780fe1bfd6b","frame_index":0,"kind":"data","monotonic_ns":313362983093000,"payload":{"event_type":"price_change","market":"0xd412ce774cfcf8dc9f71164aac78783978aac7b03871702a3b8a481bd9dc9688","price_changes":[{"asset_id":"107603864457683460275633293642179940881969192120168665300712204232021063124301","best_ask":"0.58","best_bid":"0.57","hash":"445d1566dda81b6de8c8a7f8f8a4e15bba5ba9b1","price":"0.56","side":"BUY","size":"15"},{"asset_id":"96600821790790307414914106093858868634329285205417149685270682748367152458577","best_ask":"0.43","best_bid":"0.42","hash":"940e9c941bfb5c8dcb82708f86e70536285f349d","price":"0.44","side":"SELL","size":"15"}],"timestamp":"1785211376224"},"payload_hash":"ce066cce3d6c226cceb6abf0499494b267c4fe75d0931c5ccfc9d8bbd81760ff","raw_frame":"{\"market\":\"0xd412ce774cfcf8dc9f71164aac78783978aac7b03871702a3b8a481bd9dc9688\", \"price_changes\":[{\"asset_id\":\"107603864457683460275633293642179940881969192120168665300712204232021063124301\", \"price\":\"0.56\", \"size\":\"15\", \"side\":\"BUY\", \"hash\":\"445d1566dda81b6de8c8a7f8f8a4e15bba5ba9b1\", \"best_bid\":\"0.57\", \"best_ask\":\"0.58\"}, {\"asset_id\":\"96600821790790307414914106093858868634329285205417149685270682748367152458577\", \"price\":\"0.44\", \"size\":\"15\", \"side\":\"SELL\", \"hash\":\"940e9c941bfb5c8dcb82708f86e70536285f349d\", \"best_bid\":\"0.42\", \"best_ask\":\"0.43\"}], \"timestamp\":\"1785211376224\", \"event_type\":\"price_change\"}","received_at":"2026-07-28T04:02:59.933844Z","schema_version":"clob-market-ws.price_change.v1","sequence":null,"server_hash":null,"server_timestamp":"1785211376224","session_id":"2d607381e3054cee91998cdf45a4231c","source":"clob_market_ws"},"received_at":"2026-07-28T04:02:59.933844Z","record_id":"8ebc3a0c6c24052fd3a01d9884493b419a4e62190a14f73eab88acc8eb06e9c1","schema_fingerprint":"4aa3821a28b0b7c2400bc59aba4bcc0a76e971dadd19610d3ad38c768e124dc7","schema_version":"edge-lab-recorder.raw.v1","sequence":null,"source":"clob_market_ws"}
