{"event_at":"2026-07-28T02:58:08.663000Z","event_fingerprint":"91e7b23032b25d60e6e6e5e23c8272e70523d786a2f8e5b4c97fd8799e5c6790","payload":{"connection_id":"955646bd8bf740759faf38750c0f263f","event_at":"2026-07-28T02:58:08.663000Z","event_type":"price_change","frame_hash":"2877a3d318ce20257f5a66783730cf7b5c06c360bdfa22d859c70143172a6827","frame_index":0,"kind":"data","monotonic_ns":309471564983083,"payload":{"event_type":"price_change","market":"0x0f70d07969bc69eaa97d0987de651885fdca02263688026aa11e7678af8f87aa","price_changes":[{"asset_id":"58313761654877669244690227616056238030136603415514645252000528337391143520538","best_ask":"0.37","best_bid":"0.36","hash":"231ca546bd6ecd90e9447dc4f9297f5f661edf7a","price":"0.31","side":"BUY","size":"299.43"},{"asset_id":"64053005904884194822931764831592250494815136296598204104072528088122126148949","best_ask":"0.64","best_bid":"0.63","hash":"16e981484cc627f0e0d059d547a76b945d349aec","price":"0.69","side":"SELL","size":"299.43"}],"timestamp":"1785207488663"},"payload_hash":"99228104113d6daa718582884f2ae1daaaf0881b41c89d6fa0628fbe29dd3783","raw_frame":"{\"market\":\"0x0f70d07969bc69eaa97d0987de651885fdca02263688026aa11e7678af8f87aa\", \"price_changes\":[{\"asset_id\":\"58313761654877669244690227616056238030136603415514645252000528337391143520538\", \"price\":\"0.31\", \"size\":\"299.43\", \"side\":\"BUY\", \"hash\":\"231ca546bd6ecd90e9447dc4f9297f5f661edf7a\", \"best_bid\":\"0.36\", \"best_ask\":\"0.37\"}, {\"asset_id\":\"64053005904884194822931764831592250494815136296598204104072528088122126148949\", \"price\":\"0.69\", \"size\":\"299.43\", \"side\":\"SELL\", \"hash\":\"16e981484cc627f0e0d059d547a76b945d349aec\", \"best_bid\":\"0.63\", \"best_ask\":\"0.64\"}], \"timestamp\":\"1785207488663\", \"event_type\":\"price_change\"}","received_at":"2026-07-28T02:58:08.547421Z","schema_version":"clob-market-ws.price_change.v1","sequence":null,"server_hash":null,"server_timestamp":"1785207488663","session_id":"5aad79be415c487c84df42bebd84ee93","source":"clob_market_ws"},"received_at":"2026-07-28T02:58:08.547421Z","record_id":"1ec3cd54695935d5fe61489ac2b364583ec2be03c4232fed80b92023af5bfd6b","schema_fingerprint":"4aa3821a28b0b7c2400bc59aba4bcc0a76e971dadd19610d3ad38c768e124dc7","schema_version":"edge-lab-recorder.raw.v1","sequence":null,"source":"clob_market_ws"}
{"event_at":"2026-07-28T02:58:08.670000Z","event_fingerprint":"970c989c6f7a18835029963ef19ff7aabe3b45a5ddd27c19e77a8159f0a0637d","payload":{"connection_id":"955646bd8bf740759faf38750c0f263f","event_at":"2026-07-28T02:58:08.670000Z","event_type":"price_change","frame_hash":"19ef4021e54c88950497e1604982e4404caca72ed769a8eb11ac4ad9e4d74e56","frame_index":0,"kind":"data","monotonic_ns":309471567512750,"payload":{"event_type":"price_change","market":"0x0f70d07969bc69eaa97d0987de651885fdca02263688026aa11e7678af8f87aa","price_changes":[{"asset_id":"58313761654877669244690227616056238030136603415514645252000528337391143520538","best_ask":"0.37","best_bid":"0.36","hash":"2039343355ae608a3620e20ca1ce0e81d2baac4f","price":"0.33","side":"BUY","size":"234.33"},{"asset_id":"64053005904884194822931764831592250494815136296598204104072528088122126148949","best_ask":"0.64","best_bid":"0.63","hash":"3bc7b0d66256036dfb21cc04d7e0e631168f57ef","price":"0.67","side":"SELL","size":"234.33"}],"timestamp":"1785207488670"},"payload_hash":"d434442bf2f27d899985a6504e519e9b30b5c0a222a91ac10e0d2e98b663a421","raw_frame":"{\"market\":\"0x0f70d07969bc69eaa97d0987de651885fdca02263688026aa11e7678af8f87aa\", \"price_changes\":[{\"asset_id\":\"58313761654877669244690227616056238030136603415514645252000528337391143520538\", \"price\":\"0.33\", \"size\":\"234.33\", \"side\":\"BUY\", \"hash\":\"2039343355ae608a3620e20ca1ce0e81d2baac4f\", \"best_bid\":\"0.36\", \"best_ask\":\"0.37\"}, {\"asset_id\":\"64053005904884194822931764831592250494815136296598204104072528088122126148949\", \"price\":\"0.67\", \"size\":\"234.33\", \"side\":\"SELL\", \"hash\":\"3bc7b0d66256036dfb21cc04d7e0e631168f57ef\", \"best_bid\":\"0.63\", \"best_ask\":\"0.64\"}], \"timestamp\":\"1785207488670\", \"event_type\":\"price_change\"}","received_at":"2026-07-28T02:58:08.549951Z","schema_version":"clob-market-ws.price_change.v1","sequence":null,"server_hash":null,"server_timestamp":"1785207488670","session_id":"5aad79be415c487c84df42bebd84ee93","source":"clob_market_ws"},"received_at":"2026-07-28T02:58:08.549951Z","record_id":"75c1ffb1aa24932ebf9720eb723e240be20dc1f3ffaabece509a1533b1fa2b4f","schema_fingerprint":"4aa3821a28b0b7c2400bc59aba4bcc0a76e971dadd19610d3ad38c768e124dc7","schema_version":"edge-lab-recorder.raw.v1","sequence":null,"source":"clob_market_ws"}
{"event_at":"2026-07-28T02:58:08.673000Z","event_fingerprint":"9d743118ce6e51a4292cb572fcc840d7f54ee9f9191d50293e49149002e1589a","payload":{"connection_id":"955646bd8bf740759faf38750c0f263f","event_at":"2026-07-28T02:58:08.673000Z","event_type":"price_change","frame_hash":"36432b5285bf5476eae53402917b42ccdfee74a2edb4523fb311270be7401396","frame_index":0,"kind":"data","monotonic_ns":309471569181583,"payload":{"event_type":"price_change","market":"0x0f70d07969bc69eaa97d0987de651885fdca02263688026aa11e7678af8f87aa","price_changes":[{"asset_id":"58313761654877669244690227616056238030136603415514645252000528337391143520538","best_ask":"0.37","best_bid":"0.36","hash":"00f89113ed59840d211254eba0a97a269a944f48","price":"0.37","side":"SELL","size":"268.65"},{"asset_id":"64053005904884194822931764831592250494815136296598204104072528088122126148949","best_ask":"0.64","best_bid":"0.63","hash":"675aad99bdb2efc41a2397d9ecbdc2631decd472","price":"0.63","side":"BUY","size":"268.65"}],"timestamp":"1785207488673"},"payload_hash":"d2dfb4b0d6991da4bddd388da633557eb8e6736c1d5434fd7c7485bd66fc9a64","raw_frame":"{\"market\":\"0x0f70d07969bc69eaa97d0987de651885fdca02263688026aa11e7678af8f87aa\", \"price_changes\":[{\"asset_id\":\"58313761654877669244690227616056238030136603415514645252000528337391143520538\", \"price\":\"0.37\", \"size\":\"268.65\", \"side\":\"SELL\", \"hash\":\"00f89113ed59840d211254eba0a97a269a944f48\", \"best_bid\":\"0.36\", \"best_ask\":\"0.37\"}, {\"asset_id\":\"64053005904884194822931764831592250494815136296598204104072528088122126148949\", \"price\":\"0.63\", \"size\":\"268.65\", \"side\":\"BUY\", \"hash\":\"675aad99bdb2efc41a2397d9ecbdc2631decd472\", \"best_bid\":\"0.63\", \"best_ask\":\"0.64\"}], \"timestamp\":\"1785207488673\", \"event_type\":\"price_change\"}","received_at":"2026-07-28T02:58:08.551622Z","schema_version":"clob-market-ws.price_change.v1","sequence":null,"server_hash":null,"server_timestamp":"1785207488673","session_id":"5aad79be415c487c84df42bebd84ee93","source":"clob_market_ws"},"received_at":"2026-07-28T02:58:08.551622Z","record_id":"ee6c72a13c96e85bf5f2d65e9b55b44161da5f57236e87a34535b16728c0f2aa","schema_fingerprint":"4aa3821a28b0b7c2400bc59aba4bcc0a76e971dadd19610d3ad38c768e124dc7","schema_version":"edge-lab-recorder.raw.v1","sequence":null,"source":"clob_market_ws"}
{"event_at":"2026-07-28T02:58:08.674000Z","event_fingerprint":"a4b77290118bdaddeca53d78784c211187eec573ad90f33c57daac57c2870ba6","payload":{"connection_id":"955646bd8bf740759faf38750c0f263f","event_at":"2026-07-28T02:58:08.674000Z","event_type":"price_change","frame_hash":"70aa60bc84d0743432b85639d3c22dc42e5a8ac78c81d4c45679d00836891e65","frame_index":0,"kind":"data","monotonic_ns":309471572167958,"payload":{"event_type":"price_change","market":"0x0f70d07969bc69eaa97d0987de651885fdca02263688026aa11e7678af8f87aa","price_changes":[{"asset_id":"64053005904884194822931764831592250494815136296598204104072528088122126148949","best_ask":"0.64","best_bid":"0.63","hash":"4038d3f83d22a393b0c29f7523a905fd9579bd90","price":"0.63","side":"BUY","size":"276.65"},{"asset_id":"58313761654877669244690227616056238030136603415514645252000528337391143520538","best_ask":"0.37","best_bid":"0.36","hash":"34add15cd3727f7555bb5589fa09267e4f305549","price":"0.37","side":"SELL","size":"276.65"}],"timestamp":"1785207488674"},"payload_hash":"e19b198589d15e9be89d91b1a71a3b1d1dc9bbd7b45e6a3dcdb15184e29ee107","raw_frame":"{\"market\":\"0x0f70d07969bc69eaa97d0987de651885fdca02263688026aa11e7678af8f87aa\", \"price_changes\":[{\"asset_id\":\"64053005904884194822931764831592250494815136296598204104072528088122126148949\", \"price\":\"0.63\", \"size\":\"276.65\", \"side\":\"BUY\", \"hash\":\"4038d3f83d22a393b0c29f7523a905fd9579bd90\", \"best_bid\":\"0.63\", \"best_ask\":\"0.64\"}, {\"asset_id\":\"58313761654877669244690227616056238030136603415514645252000528337391143520538\", \"price\":\"0.37\", \"size\":\"276.65\", \"side\":\"SELL\", \"hash\":\"34add15cd3727f7555bb5589fa09267e4f305549\", \"best_bid\":\"0.36\", \"best_ask\":\"0.37\"}], \"timestamp\":\"1785207488674\", \"event_type\":\"price_change\"}","received_at":"2026-07-28T02:58:08.554604Z","schema_version":"clob-market-ws.price_change.v1","sequence":null,"server_hash":null,"server_timestamp":"1785207488674","session_id":"5aad79be415c487c84df42bebd84ee93","source":"clob_market_ws"},"received_at":"2026-07-28T02:58:08.554604Z","record_id":"6dc14ab7c06f40b7f7a81a4dede6f67b0d25cc1c4b68a1a0864132206e0f3873","schema_fingerprint":"4aa3821a28b0b7c2400bc59aba4bcc0a76e971dadd19610d3ad38c768e124dc7","schema_version":"edge-lab-recorder.raw.v1","sequence":null,"source":"clob_market_ws"}
{"event_at":"2026-07-28T02:58:08.675000Z","event_fingerprint":"7f1cbb0888b57e306f3c7c8f27f051f76d636509d7683ca1045fcfd88f413732","payload":{"connection_id":"955646bd8bf740759faf38750c0f263f","event_at":"2026-07-28T02:58:08.675000Z","event_type":"price_change","frame_hash":"5331b3071e6c991b81ad79ddd08f4fdd537b85ad78ce466014924812e81d5566","frame_index":0,"kind":"data","monotonic_ns":309471573850375,"payload":{"event_type":"price_change","market":"0x0f70d07969bc69eaa97d0987de651885fdca02263688026aa11e7678af8f87aa","price_changes":[{"asset_id":"58313761654877669244690227616056238030136603415514645252000528337391143520538","best_ask":"0.37","best_bid":"0.36","hash":"92b5ea32d84be41ff56da7f81d5b6b09dd7ddf77","price":"0.27","side":"BUY","size":"87.8"},{"asset_id":"64053005904884194822931764831592250494815136296598204104072528088122126148949","best_ask":"0.64","best_bid":"0.63","hash":"0c9960f1ba4d9c7cb9d590d4ea43983d38dc10d6","price":"0.73","side":"SELL","size":"87.8"}],"timestamp":"1785207488675"},"payload_hash":"db3a384823b72bedea5d8e46280ba197d8a29d9166b8b38fe4529edb928eb50e","raw_frame":"{\"market\":\"0x0f70d07969bc69eaa97d0987de651885fdca02263688026aa11e7678af8f87aa\", \"price_changes\":[{\"asset_id\":\"58313761654877669244690227616056238030136603415514645252000528337391143520538\", \"price\":\"0.27\", \"size\":\"87.8\", \"side\":\"BUY\", \"hash\":\"92b5ea32d84be41ff56da7f81d5b6b09dd7ddf77\", \"best_bid\":\"0.36\", \"best_ask\":\"0.37\"}, {\"asset_id\":\"64053005904884194822931764831592250494815136296598204104072528088122126148949\", \"price\":\"0.73\", \"size\":\"87.8\", \"side\":\"SELL\", \"hash\":\"0c9960f1ba4d9c7cb9d590d4ea43983d38dc10d6\", \"best_bid\":\"0.63\", \"best_ask\":\"0.64\"}], \"timestamp\":\"1785207488675\", \"event_type\":\"price_change\"}","received_at":"2026-07-28T02:58:08.556291Z","schema_version":"clob-market-ws.price_change.v1","sequence":null,"server_hash":null,"server_timestamp":"1785207488675","session_id":"5aad79be415c487c84df42bebd84ee93","source":"clob_market_ws"},"received_at":"2026-07-28T02:58:08.556291Z","record_id":"2f79f27f9e347ee613b0bba4eaa6d0d9494ee3ffac29287f8c2ea1bf90842fb0","schema_fingerprint":"4aa3821a28b0b7c2400bc59aba4bcc0a76e971dadd19610d3ad38c768e124dc7","schema_version":"edge-lab-recorder.raw.v1","sequence":null,"source":"clob_market_ws"}
{"event_at":"2026-07-28T02:58:08.676000Z","event_fingerprint":"3c692ed954689078745e1c92c8a7f68bc7f33dd4f6e16a62cc72bd9cdcd75d12","payload":{"connection_id":"955646bd8bf740759faf38750c0f263f","event_at":"2026-07-28T02:58:08.676000Z","event_type":"price_change","frame_hash":"0d10f9ff82d80fd6cca6e44513a73eda762f5fa3b0c3abda0d4e839ffa7a0f04","frame_index":0,"kind":"data","monotonic_ns":309471575399333,"payload":{"event_type":"price_change","market":"0x0f70d07969bc69eaa97d0987de651885fdca02263688026aa11e7678af8f87aa","price_changes":[{"asset_id":"58313761654877669244690227616056238030136603415514645252000528337391143520538","best_ask":"0.37","best_bid":"0.36","hash":"953c0a556711e55bdc192af6074bededc6143bbf","price":"0.34","side":"BUY","size":"122.18"},{"asset_id":"64053005904884194822931764831592250494815136296598204104072528088122126148949","best_ask":"0.64","best_bid":"0.63","hash":"d572914608ae0c3e614d3bd0a41ed04dd70f5020","price":"0.66","side":"SELL","size":"122.18"}],"timestamp":"1785207488676"},"payload_hash":"1a3aa96e113d786f8353eea48ae4273baf2232bb95b6c48a2a4096f74348cd47","raw_frame":"{\"market\":\"0x0f70d07969bc69eaa97d0987de651885fdca02263688026aa11e7678af8f87aa\", \"price_changes\":[{\"asset_id\":\"58313761654877669244690227616056238030136603415514645252000528337391143520538\", \"price\":\"0.34\", \"size\":\"122.18\", \"side\":\"BUY\", \"hash\":\"953c0a556711e55bdc192af6074bededc6143bbf\", \"best_bid\":\"0.36\", \"best_ask\":\"0.37\"}, {\"asset_id\":\"64053005904884194822931764831592250494815136296598204104072528088122126148949\", \"price\":\"0.66\", \"size\":\"122.18\", \"side\":\"SELL\", \"hash\":\"d572914608ae0c3e614d3bd0a41ed04dd70f5020\", \"best_bid\":\"0.63\", \"best_ask\":\"0.64\"}], \"timestamp\":\"1785207488676\", \"event_type\":\"price_change\"}","received_at":"2026-07-28T02:58:08.557838Z","schema_version":"clob-market-ws.price_change.v1","sequence":null,"server_hash":null,"server_timestamp":"1785207488676","session_id":"5aad79be415c487c84df42bebd84ee93","source":"clob_market_ws"},"received_at":"2026-07-28T02:58:08.557838Z","record_id":"7cb3061e1b87ab0385028373f05bbfc90e84f23ef8a7f8b528b26480c8c02ee3","schema_fingerprint":"4aa3821a28b0b7c2400bc59aba4bcc0a76e971dadd19610d3ad38c768e124dc7","schema_version":"edge-lab-recorder.raw.v1","sequence":null,"source":"clob_market_ws"}
{"event_at":"2026-07-28T02:58:08.677000Z","event_fingerprint":"19577f39857e657484093b5fbb815341dbded1b5a6ad3a28f8bbf671ba6e29f7","payload":{"connection_id":"955646bd8bf740759faf38750c0f263f","event_at":"2026-07-28T02:58:08.677000Z","event_type":"price_change","frame_hash":"544a8ccb382535d261a326ca756dbc165ee246b8c7e8b0517038962a33e6cdd2","frame_index":0,"kind":"data","monotonic_ns":309471594538250,"payload":{"event_type":"price_change","market":"0x0f70d07969bc69eaa97d0987de651885fdca02263688026aa11e7678af8f87aa","price_changes":[{"asset_id":"58313761654877669244690227616056238030136603415514645252000528337391143520538","best_ask":"0.37","best_bid":"0.36","hash":"fd75cfd26cbad625f7df62bf23dcc24bb9974fcb","price":"0.35","side":"BUY","size":"91.46"},{"asset_id":"64053005904884194822931764831592250494815136296598204104072528088122126148949","best_ask":"0.64","best_bid":"0.63","hash":"18f9d8786541847357e0e147a89444799072dccc","price":"0.65","side":"SELL","size":"91.46"}],"timestamp":"1785207488677"},"payload_hash":"75044b7f388735aff0e8ae5a35d32e4fcebcab6a9adf9f74535bdae106c44c39","raw_frame":"{\"market\":\"0x0f70d07969bc69eaa97d0987de651885fdca02263688026aa11e7678af8f87aa\", \"price_changes\":[{\"asset_id\":\"58313761654877669244690227616056238030136603415514645252000528337391143520538\", \"price\":\"0.35\", \"size\":\"91.46\", \"side\":\"BUY\", \"hash\":\"fd75cfd26cbad625f7df62bf23dcc24bb9974fcb\", \"best_bid\":\"0.36\", \"best_ask\":\"0.37\"}, {\"asset_id\":\"64053005904884194822931764831592250494815136296598204104072528088122126148949\", \"price\":\"0.65\", \"size\":\"91.46\", \"side\":\"SELL\", \"hash\":\"18f9d8786541847357e0e147a89444799072dccc\", \"best_bid\":\"0.63\", \"best_ask\":\"0.64\"}], \"timestamp\":\"1785207488677\", \"event_type\":\"price_change\"}","received_at":"2026-07-28T02:58:08.576975Z","schema_version":"clob-market-ws.price_change.v1","sequence":null,"server_hash":null,"server_timestamp":"1785207488677","session_id":"5aad79be415c487c84df42bebd84ee93","source":"clob_market_ws"},"received_at":"2026-07-28T02:58:08.576975Z","record_id":"b59737a4b5959599f0880480bbaf111876aad86fb32dc0d51758baea0096fc81","schema_fingerprint":"4aa3821a28b0b7c2400bc59aba4bcc0a76e971dadd19610d3ad38c768e124dc7","schema_version":"edge-lab-recorder.raw.v1","sequence":null,"source":"clob_market_ws"}
{"event_at":"2026-07-28T02:58:08.677000Z","event_fingerprint":"b3076baebf141618ed2ae141ea1bf89377861b59479ad109b428f5729336d8f0","payload":{"connection_id":"955646bd8bf740759faf38750c0f263f","event_at":"2026-07-28T02:58:08.677000Z","event_type":"price_change","frame_hash":"5b1138da88dbf253a37da13dd4dd6efd181e93153596a051eb92f1ff1575e111","frame_index":0,"kind":"data","monotonic_ns":309471596304500,"payload":{"event_type":"price_change","market":"0x0f70d07969bc69eaa97d0987de651885fdca02263688026aa11e7678af8f87aa","price_changes":[{"asset_id":"58313761654877669244690227616056238030136603415514645252000528337391143520538","best_ask":"0.37","best_bid":"0.36","hash":"19d23aa17f48c955e9d27922ed17bf0fd6721292","price":"0.29","side":"BUY","size":"240.89"},{"asset_id":"64053005904884194822931764831592250494815136296598204104072528088122126148949","best_ask":"0.64","best_bid":"0.63","hash":"85565ef6ce27ad8b412093850c1d59ee4a2d28f0","price":"0.71","side":"SELL","size":"240.89"}],"timestamp":"1785207488677"},"payload_hash":"3ecde295d03814d6e9d3102ebdcd538da0fbfb423ac2a611a3982a584e7f56b1","raw_frame":"{\"market\":\"0x0f70d07969bc69eaa97d0987de651885fdca02263688026aa11e7678af8f87aa\", \"price_changes\":[{\"asset_id\":\"58313761654877669244690227616056238030136603415514645252000528337391143520538\", \"price\":\"0.29\", \"size\":\"240.89\", \"side\":\"BUY\", \"hash\":\"19d23aa17f48c955e9d27922ed17bf0fd6721292\", \"best_bid\":\"0.36\", \"best_ask\":\"0.37\"}, {\"asset_id\":\"64053005904884194822931764831592250494815136296598204104072528088122126148949\", \"price\":\"0.71\", \"size\":\"240.89\", \"side\":\"SELL\", \"hash\":\"85565ef6ce27ad8b412093850c1d59ee4a2d28f0\", \"best_bid\":\"0.63\", \"best_ask\":\"0.64\"}], \"timestamp\":\"1785207488677\", \"event_type\":\"price_change\"}","received_at":"2026-07-28T02:58:08.578744Z","schema_version":"clob-market-ws.price_change.v1","sequence":null,"server_hash":null,"server_timestamp":"1785207488677","session_id":"5aad79be415c487c84df42bebd84ee93","source":"clob_market_ws"},"received_at":"2026-07-28T02:58:08.578744Z","record_id":"0273afd68223fa0882fb99a163281c87b7fcb542b74e1708151fc2d2bf158ecb","schema_fingerprint":"4aa3821a28b0b7c2400bc59aba4bcc0a76e971dadd19610d3ad38c768e124dc7","schema_version":"edge-lab-recorder.raw.v1","sequence":null,"source":"clob_market_ws"}
{"event_at":"2026-07-28T02:58:08.678000Z","event_fingerprint":"c51687fa340338a0763f79b5ad2e38a9f005bb0bb9bbe4162e272f8d3f8c8f7e","payload":{"connection_id":"955646bd8bf740759faf38750c0f263f","event_at":"2026-07-28T02:58:08.678000Z","event_type":"price_change","frame_hash":"5f651b3c566314f029be82cf766d6746fc5e43d76c13ef05c2b53959dd0b500d","frame_index":0,"kind":"data","monotonic_ns":309471597885541,"payload":{"event_type":"price_change","market":"0x0f70d07969bc69eaa97d0987de651885fdca02263688026aa11e7678af8f87aa","price_changes":[{"asset_id":"64053005904884194822931764831592250494815136296598204104072528088122126148949","best_ask":"0.64","best_bid":"0.63","hash":"827802e6091de7ba5f8dcbc29a113dda14570d75","price":"0.58","side":"BUY","size":"109.39"},{"asset_id":"58313761654877669244690227616056238030136603415514645252000528337391143520538","best_ask":"0.37","best_bid":"0.36","hash":"9e2c7254d2bdb88aeeca534b531bae773ea8c9cd","price":"0.42","side":"SELL","size":"109.39"}],"timestamp":"1785207488678"},"payload_hash":"367c641dd62ecf57f95b69cff4d6ac7fe7756648cdbccc14f169f511be406a08","raw_frame":"{\"market\":\"0x0f70d07969bc69eaa97d0987de651885fdca02263688026aa11e7678af8f87aa\", \"price_changes\":[{\"asset_id\":\"64053005904884194822931764831592250494815136296598204104072528088122126148949\", \"price\":\"0.58\", \"size\":\"109.39\", \"side\":\"BUY\", \"hash\":\"827802e6091de7ba5f8dcbc29a113dda14570d75\", \"best_bid\":\"0.63\", \"best_ask\":\"0.64\"}, {\"asset_id\":\"58313761654877669244690227616056238030136603415514645252000528337391143520538\", \"price\":\"0.42\", \"size\":\"109.39\", \"side\":\"SELL\", \"hash\":\"9e2c7254d2bdb88aeeca534b531bae773ea8c9cd\", \"best_bid\":\"0.36\", \"best_ask\":\"0.37\"}], \"timestamp\":\"1785207488678\", \"event_type\":\"price_change\"}","received_at":"2026-07-28T02:58:08.580326Z","schema_version":"clob-market-ws.price_change.v1","sequence":null,"server_hash":null,"server_timestamp":"1785207488678","session_id":"5aad79be415c487c84df42bebd84ee93","source":"clob_market_ws"},"received_at":"2026-07-28T02:58:08.580326Z","record_id":"b08f71d20330d992e839c81c6016431ba8e364496b5fce70d91e8a5137cd31f8","schema_fingerprint":"4aa3821a28b0b7c2400bc59aba4bcc0a76e971dadd19610d3ad38c768e124dc7","schema_version":"edge-lab-recorder.raw.v1","sequence":null,"source":"clob_market_ws"}
{"event_at":"2026-07-28T02:58:08.678000Z","event_fingerprint":"d96ce1608ae3556dbd8ba9650880d0e96d9bf2b9205ecb2b6691cba417a018c5","payload":{"connection_id":"955646bd8bf740759faf38750c0f263f","event_at":"2026-07-28T02:58:08.678000Z","event_type":"price_change","frame_hash":"c83edd8d95fdf0165a5a233dc2fc8f767dba4b5b00721c3c8bca1dc472d2a40d","frame_index":0,"kind":"data","monotonic_ns":309471599472208,"payload":{"event_type":"price_change","market":"0x0f70d07969bc69eaa97d0987de651885fdca02263688026aa11e7678af8f87aa","price_changes":[{"asset_id":"58313761654877669244690227616056238030136603415514645252000528337391143520538","best_ask":"0.37","best_bid":"0.36","hash":"9e2c7254d2bdb88aeeca534b531bae773ea8c9cd","price":"0.33","side":"BUY","size":"214.33"},{"asset_id":"64053005904884194822931764831592250494815136296598204104072528088122126148949","best_ask":"0.64","best_bid":"0.63","hash":"827802e6091de7ba5f8dcbc29a113dda14570d75","price":"0.67","side":"SELL","size":"214.33"}],"timestamp":"1785207488678"},"payload_hash":"2e93f357955d61a53fe72b830f75dde3f6252514e8b533f6fbd64ab556b6bdf1","raw_frame":"{\"market\":\"0x0f70d07969bc69eaa97d0987de651885fdca02263688026aa11e7678af8f87aa\", \"price_changes\":[{\"asset_id\":\"58313761654877669244690227616056238030136603415514645252000528337391143520538\", \"price\":\"0.33\", \"size\":\"214.33\", \"side\":\"BUY\", \"hash\":\"9e2c7254d2bdb88aeeca534b531bae773ea8c9cd\", \"best_bid\":\"0.36\", \"best_ask\":\"0.37\"}, {\"asset_id\":\"64053005904884194822931764831592250494815136296598204104072528088122126148949\", \"price\":\"0.67\", \"size\":\"214.33\", \"side\":\"SELL\", \"hash\":\"827802e6091de7ba5f8dcbc29a113dda14570d75\", \"best_bid\":\"0.63\", \"best_ask\":\"0.64\"}], \"timestamp\":\"1785207488678\", \"event_type\":\"price_change\"}","received_at":"2026-07-28T02:58:08.581910Z","schema_version":"clob-market-ws.price_change.v1","sequence":null,"server_hash":null,"server_timestamp":"1785207488678","session_id":"5aad79be415c487c84df42bebd84ee93","source":"clob_market_ws"},"received_at":"2026-07-28T02:58:08.581910Z","record_id":"edce1c5c814df0a69901313d7d5c729996d81240d13331427f35ccd77d3d2f8f","schema_fingerprint":"4aa3821a28b0b7c2400bc59aba4bcc0a76e971dadd19610d3ad38c768e124dc7","schema_version":"edge-lab-recorder.raw.v1","sequence":null,"source":"clob_market_ws"}
