{"event_at":"2026-07-28T02:59:24.889000Z","event_fingerprint":"ed650c8fba1c9c238c9c696af6df6106917c187a3c02163211b4b9f6726ed0b4","payload":{"connection_id":"955646bd8bf740759faf38750c0f263f","event_at":"2026-07-28T02:59:24.889000Z","event_type":"price_change","frame_hash":"80f363c07b5508a12b6c65fbfb4fba0e133bb6255a88e34110217ce39a70e09e","frame_index":0,"kind":"data","monotonic_ns":309547786129291,"payload":{"event_type":"price_change","market":"0x0f70d07969bc69eaa97d0987de651885fdca02263688026aa11e7678af8f87aa","price_changes":[{"asset_id":"64053005904884194822931764831592250494815136296598204104072528088122126148949","best_ask":"0.2","best_bid":"0.19","hash":"4b14f13a0e4776dd420f86263f67330ac749a392","price":"0.07","side":"BUY","size":"333.2"},{"asset_id":"58313761654877669244690227616056238030136603415514645252000528337391143520538","best_ask":"0.81","best_bid":"0.8","hash":"fd8c408a602ad152d9285048381fd290057d7097","price":"0.93","side":"SELL","size":"333.2"}],"timestamp":"1785207564889"},"payload_hash":"5fcf771d6077a56c608dc3cd5ea5c898a43e2019602901a956033a56b3a30b1b","raw_frame":"{\"market\":\"0x0f70d07969bc69eaa97d0987de651885fdca02263688026aa11e7678af8f87aa\", \"price_changes\":[{\"asset_id\":\"64053005904884194822931764831592250494815136296598204104072528088122126148949\", \"price\":\"0.07\", \"size\":\"333.2\", \"side\":\"BUY\", \"hash\":\"4b14f13a0e4776dd420f86263f67330ac749a392\", \"best_bid\":\"0.19\", \"best_ask\":\"0.2\"}, {\"asset_id\":\"58313761654877669244690227616056238030136603415514645252000528337391143520538\", \"price\":\"0.93\", \"size\":\"333.2\", \"side\":\"SELL\", \"hash\":\"fd8c408a602ad152d9285048381fd290057d7097\", \"best_bid\":\"0.8\", \"best_ask\":\"0.81\"}], \"timestamp\":\"1785207564889\", \"event_type\":\"price_change\"}","received_at":"2026-07-28T02:59:24.768018Z","schema_version":"clob-market-ws.price_change.v1","sequence":null,"server_hash":null,"server_timestamp":"1785207564889","session_id":"5aad79be415c487c84df42bebd84ee93","source":"clob_market_ws"},"received_at":"2026-07-28T02:59:24.768018Z","record_id":"758bc0aebe02a76c7f5fe707ffad9e67e692f4f5607f1fb679973763fadbcbc6","schema_fingerprint":"4aa3821a28b0b7c2400bc59aba4bcc0a76e971dadd19610d3ad38c768e124dc7","schema_version":"edge-lab-recorder.raw.v1","sequence":null,"source":"clob_market_ws"}
{"event_at":"2026-07-28T02:59:24.891000Z","event_fingerprint":"118f23b40fcc6a0d0483400f90c6304d0526b8218d67074d2a6c51e613257e9f","payload":{"connection_id":"955646bd8bf740759faf38750c0f263f","event_at":"2026-07-28T02:59:24.891000Z","event_type":"price_change","frame_hash":"29fe11699f65105974ddc7086bed67ae12977d992a17e226c268900d24d99dd6","frame_index":0,"kind":"data","monotonic_ns":309547788435333,"payload":{"event_type":"price_change","market":"0x0f70d07969bc69eaa97d0987de651885fdca02263688026aa11e7678af8f87aa","price_changes":[{"asset_id":"58313761654877669244690227616056238030136603415514645252000528337391143520538","best_ask":"0.81","best_bid":"0.8","hash":"0a3b27bc70a152af83697e64a174ff477b174d5a","price":"0.68","side":"BUY","size":"96.29"},{"asset_id":"64053005904884194822931764831592250494815136296598204104072528088122126148949","best_ask":"0.2","best_bid":"0.19","hash":"63203bff79a17d9bab868166f89e9c8278164b5a","price":"0.32","side":"SELL","size":"96.29"}],"timestamp":"1785207564891"},"payload_hash":"6f3ad0496ceeda66d8d801841ed4e6a1f7a6ad629a6c544c34d144e2a537c271","raw_frame":"{\"market\":\"0x0f70d07969bc69eaa97d0987de651885fdca02263688026aa11e7678af8f87aa\", \"price_changes\":[{\"asset_id\":\"58313761654877669244690227616056238030136603415514645252000528337391143520538\", \"price\":\"0.68\", \"size\":\"96.29\", \"side\":\"BUY\", \"hash\":\"0a3b27bc70a152af83697e64a174ff477b174d5a\", \"best_bid\":\"0.8\", \"best_ask\":\"0.81\"}, {\"asset_id\":\"64053005904884194822931764831592250494815136296598204104072528088122126148949\", \"price\":\"0.32\", \"size\":\"96.29\", \"side\":\"SELL\", \"hash\":\"63203bff79a17d9bab868166f89e9c8278164b5a\", \"best_bid\":\"0.19\", \"best_ask\":\"0.2\"}], \"timestamp\":\"1785207564891\", \"event_type\":\"price_change\"}","received_at":"2026-07-28T02:59:24.770324Z","schema_version":"clob-market-ws.price_change.v1","sequence":null,"server_hash":null,"server_timestamp":"1785207564891","session_id":"5aad79be415c487c84df42bebd84ee93","source":"clob_market_ws"},"received_at":"2026-07-28T02:59:24.770324Z","record_id":"07d04a5edcc090bdff02644ef89dc19ba507fdca213c92f0b2da10d27899616e","schema_fingerprint":"4aa3821a28b0b7c2400bc59aba4bcc0a76e971dadd19610d3ad38c768e124dc7","schema_version":"edge-lab-recorder.raw.v1","sequence":null,"source":"clob_market_ws"}
{"event_at":"2026-07-28T02:59:24.893000Z","event_fingerprint":"af6e842c4cb788b100161193eaf83d74d5b1c633720c99a4885db9328fca9c7a","payload":{"connection_id":"955646bd8bf740759faf38750c0f263f","event_at":"2026-07-28T02:59:24.893000Z","event_type":"price_change","frame_hash":"495899fbbdad5667ad810ebbe8d315a2ca8cb023dff55bd1c0063692b7d2153e","frame_index":0,"kind":"data","monotonic_ns":309547790113833,"payload":{"event_type":"price_change","market":"0x0f70d07969bc69eaa97d0987de651885fdca02263688026aa11e7678af8f87aa","price_changes":[{"asset_id":"64053005904884194822931764831592250494815136296598204104072528088122126148949","best_ask":"0.2","best_bid":"0.19","hash":"17b74379e15a662389a44b44635488f3aa0bf06b","price":"0.07","side":"BUY","size":"283.2"},{"asset_id":"58313761654877669244690227616056238030136603415514645252000528337391143520538","best_ask":"0.81","best_bid":"0.8","hash":"0c2751e24488f64bfb55f23b3b44108b487e686b","price":"0.93","side":"SELL","size":"283.2"}],"timestamp":"1785207564893"},"payload_hash":"56dca3bf7a06bcd540514e0c00b65683d30faea0666c5545a0bd2021b55070fc","raw_frame":"{\"market\":\"0x0f70d07969bc69eaa97d0987de651885fdca02263688026aa11e7678af8f87aa\", \"price_changes\":[{\"asset_id\":\"64053005904884194822931764831592250494815136296598204104072528088122126148949\", \"price\":\"0.07\", \"size\":\"283.2\", \"side\":\"BUY\", \"hash\":\"17b74379e15a662389a44b44635488f3aa0bf06b\", \"best_bid\":\"0.19\", \"best_ask\":\"0.2\"}, {\"asset_id\":\"58313761654877669244690227616056238030136603415514645252000528337391143520538\", \"price\":\"0.93\", \"size\":\"283.2\", \"side\":\"SELL\", \"hash\":\"0c2751e24488f64bfb55f23b3b44108b487e686b\", \"best_bid\":\"0.8\", \"best_ask\":\"0.81\"}], \"timestamp\":\"1785207564893\", \"event_type\":\"price_change\"}","received_at":"2026-07-28T02:59:24.772004Z","schema_version":"clob-market-ws.price_change.v1","sequence":null,"server_hash":null,"server_timestamp":"1785207564893","session_id":"5aad79be415c487c84df42bebd84ee93","source":"clob_market_ws"},"received_at":"2026-07-28T02:59:24.772004Z","record_id":"cd9ae876240367d0babd952e5e52fcd71410a39a3ed0ea3afa57f090deb91930","schema_fingerprint":"4aa3821a28b0b7c2400bc59aba4bcc0a76e971dadd19610d3ad38c768e124dc7","schema_version":"edge-lab-recorder.raw.v1","sequence":null,"source":"clob_market_ws"}
{"event_at":"2026-07-28T02:59:24.894000Z","event_fingerprint":"6c1a07117f0578db8c5e83e09a4f0053c5154cc6f09e35b439ef63f44dadec33","payload":{"connection_id":"955646bd8bf740759faf38750c0f263f","event_at":"2026-07-28T02:59:24.894000Z","event_type":"price_change","frame_hash":"ef439c4b215190cf1196fb16c4498fc9a3c60d79788153f801568f4bb39de9b4","frame_index":0,"kind":"data","monotonic_ns":309547791673333,"payload":{"event_type":"price_change","market":"0x0f70d07969bc69eaa97d0987de651885fdca02263688026aa11e7678af8f87aa","price_changes":[{"asset_id":"64053005904884194822931764831592250494815136296598204104072528088122126148949","best_ask":"0.2","best_bid":"0.19","hash":"6fe0b803cf5359f59660b3b853128dedc947113c","price":"0.07","side":"BUY","size":"233.2"},{"asset_id":"58313761654877669244690227616056238030136603415514645252000528337391143520538","best_ask":"0.81","best_bid":"0.8","hash":"ad405a611c0537e5961b2a88dc6cd818ceb19e67","price":"0.93","side":"SELL","size":"233.2"}],"timestamp":"1785207564894"},"payload_hash":"01252133dbdf6604a95d827f5fb828d3f1852d668f040bc1ceaa49c3b64ba005","raw_frame":"{\"market\":\"0x0f70d07969bc69eaa97d0987de651885fdca02263688026aa11e7678af8f87aa\", \"price_changes\":[{\"asset_id\":\"64053005904884194822931764831592250494815136296598204104072528088122126148949\", \"price\":\"0.07\", \"size\":\"233.2\", \"side\":\"BUY\", \"hash\":\"6fe0b803cf5359f59660b3b853128dedc947113c\", \"best_bid\":\"0.19\", \"best_ask\":\"0.2\"}, {\"asset_id\":\"58313761654877669244690227616056238030136603415514645252000528337391143520538\", \"price\":\"0.93\", \"size\":\"233.2\", \"side\":\"SELL\", \"hash\":\"ad405a611c0537e5961b2a88dc6cd818ceb19e67\", \"best_bid\":\"0.8\", \"best_ask\":\"0.81\"}], \"timestamp\":\"1785207564894\", \"event_type\":\"price_change\"}","received_at":"2026-07-28T02:59:24.773562Z","schema_version":"clob-market-ws.price_change.v1","sequence":null,"server_hash":null,"server_timestamp":"1785207564894","session_id":"5aad79be415c487c84df42bebd84ee93","source":"clob_market_ws"},"received_at":"2026-07-28T02:59:24.773562Z","record_id":"d28c6c89fae53436af5b75d96a08cd8f3537dcddf77688e3ee0be58c2b66555b","schema_fingerprint":"4aa3821a28b0b7c2400bc59aba4bcc0a76e971dadd19610d3ad38c768e124dc7","schema_version":"edge-lab-recorder.raw.v1","sequence":null,"source":"clob_market_ws"}
{"event_at":"2026-07-28T02:59:24.900000Z","event_fingerprint":"22dd91dc707936e8458502fe3e0cbf68f252c13c8ffc5dd2e6bab08d822d1824","payload":{"connection_id":"955646bd8bf740759faf38750c0f263f","event_at":"2026-07-28T02:59:24.900000Z","event_type":"price_change","frame_hash":"4e7166e23569cfdb7090ec6f088cad8587563d776992999d05d96670034e2e0b","frame_index":0,"kind":"data","monotonic_ns":309547793448625,"payload":{"event_type":"price_change","market":"0x0f70d07969bc69eaa97d0987de651885fdca02263688026aa11e7678af8f87aa","price_changes":[{"asset_id":"64053005904884194822931764831592250494815136296598204104072528088122126148949","best_ask":"0.2","best_bid":"0.19","hash":"a6210eea437f008e47372bc16d5c0f70036eee43","price":"0.01","side":"BUY","size":"2984.4"},{"asset_id":"58313761654877669244690227616056238030136603415514645252000528337391143520538","best_ask":"0.81","best_bid":"0.8","hash":"0f31cd986f8a913624c4df69440cc45c0e6e7f4a","price":"0.99","side":"SELL","size":"2984.4"}],"timestamp":"1785207564900"},"payload_hash":"c2d58d1a9f7b21421b556c18d81a0d03f54884c5a140cbb4a00210676c594d16","raw_frame":"{\"market\":\"0x0f70d07969bc69eaa97d0987de651885fdca02263688026aa11e7678af8f87aa\", \"price_changes\":[{\"asset_id\":\"64053005904884194822931764831592250494815136296598204104072528088122126148949\", \"price\":\"0.01\", \"size\":\"2984.4\", \"side\":\"BUY\", \"hash\":\"a6210eea437f008e47372bc16d5c0f70036eee43\", \"best_bid\":\"0.19\", \"best_ask\":\"0.2\"}, {\"asset_id\":\"58313761654877669244690227616056238030136603415514645252000528337391143520538\", \"price\":\"0.99\", \"size\":\"2984.4\", \"side\":\"SELL\", \"hash\":\"0f31cd986f8a913624c4df69440cc45c0e6e7f4a\", \"best_bid\":\"0.8\", \"best_ask\":\"0.81\"}], \"timestamp\":\"1785207564900\", \"event_type\":\"price_change\"}","received_at":"2026-07-28T02:59:24.775337Z","schema_version":"clob-market-ws.price_change.v1","sequence":null,"server_hash":null,"server_timestamp":"1785207564900","session_id":"5aad79be415c487c84df42bebd84ee93","source":"clob_market_ws"},"received_at":"2026-07-28T02:59:24.775337Z","record_id":"9f0812a8362e76524a6a8fe30df1b99a8218d8112a1cb620769cf8ad14f94e59","schema_fingerprint":"4aa3821a28b0b7c2400bc59aba4bcc0a76e971dadd19610d3ad38c768e124dc7","schema_version":"edge-lab-recorder.raw.v1","sequence":null,"source":"clob_market_ws"}
{"event_at":"2026-07-28T02:59:24.900000Z","event_fingerprint":"06d69b9a08e6c38b7d22c38175f21f7153b5595360a4028e3de00c2ac1f2a364","payload":{"connection_id":"955646bd8bf740759faf38750c0f263f","event_at":"2026-07-28T02:59:24.900000Z","event_type":"price_change","frame_hash":"f01f7c3563e17b3b8490fcea946170efe7f0d5dad9cb5a20737aa9ece0173d06","frame_index":0,"kind":"data","monotonic_ns":309547795049458,"payload":{"event_type":"price_change","market":"0x0f70d07969bc69eaa97d0987de651885fdca02263688026aa11e7678af8f87aa","price_changes":[{"asset_id":"58313761654877669244690227616056238030136603415514645252000528337391143520538","best_ask":"0.81","best_bid":"0.8","hash":"0ce5df9cf47b34a094d454cd684b1232413a12e2","price":"0.01","side":"BUY","size":"2359.22"},{"asset_id":"64053005904884194822931764831592250494815136296598204104072528088122126148949","best_ask":"0.2","best_bid":"0.19","hash":"dc714adc3dcd2b9e447548c351f20c7a3aa206fa","price":"0.99","side":"SELL","size":"2359.22"}],"timestamp":"1785207564900"},"payload_hash":"5cfe43550d1240406cbe73c109e6366b29df4520f293c68b5d5ea339935fd125","raw_frame":"{\"market\":\"0x0f70d07969bc69eaa97d0987de651885fdca02263688026aa11e7678af8f87aa\", \"price_changes\":[{\"asset_id\":\"58313761654877669244690227616056238030136603415514645252000528337391143520538\", \"price\":\"0.01\", \"size\":\"2359.22\", \"side\":\"BUY\", \"hash\":\"0ce5df9cf47b34a094d454cd684b1232413a12e2\", \"best_bid\":\"0.8\", \"best_ask\":\"0.81\"}, {\"asset_id\":\"64053005904884194822931764831592250494815136296598204104072528088122126148949\", \"price\":\"0.99\", \"size\":\"2359.22\", \"side\":\"SELL\", \"hash\":\"dc714adc3dcd2b9e447548c351f20c7a3aa206fa\", \"best_bid\":\"0.19\", \"best_ask\":\"0.2\"}], \"timestamp\":\"1785207564900\", \"event_type\":\"price_change\"}","received_at":"2026-07-28T02:59:24.776939Z","schema_version":"clob-market-ws.price_change.v1","sequence":null,"server_hash":null,"server_timestamp":"1785207564900","session_id":"5aad79be415c487c84df42bebd84ee93","source":"clob_market_ws"},"received_at":"2026-07-28T02:59:24.776939Z","record_id":"096264c0a2966cdbf6c90ad2cfb43c97d558c0358df77bd910b5e11e10bd518f","schema_fingerprint":"4aa3821a28b0b7c2400bc59aba4bcc0a76e971dadd19610d3ad38c768e124dc7","schema_version":"edge-lab-recorder.raw.v1","sequence":null,"source":"clob_market_ws"}
{"event_at":"2026-07-28T02:59:24.914000Z","event_fingerprint":"9b562a71a1cbdbd778a83795d58817f8abff89c4adc05897c52b2957257b6a5c","payload":{"connection_id":"955646bd8bf740759faf38750c0f263f","event_at":"2026-07-28T02:59:24.914000Z","event_type":"price_change","frame_hash":"735628049e14a2a7071188911b11f3b99ccacd1da0b804ebd799a9c454d8a281","frame_index":0,"kind":"data","monotonic_ns":309547796606750,"payload":{"event_type":"price_change","market":"0x0f70d07969bc69eaa97d0987de651885fdca02263688026aa11e7678af8f87aa","price_changes":[{"asset_id":"64053005904884194822931764831592250494815136296598204104072528088122126148949","best_ask":"0.2","best_bid":"0.19","hash":"ab63dffe5a1656e201497ab8b05db4947904abde","price":"0.08","side":"BUY","size":"244.59"},{"asset_id":"58313761654877669244690227616056238030136603415514645252000528337391143520538","best_ask":"0.81","best_bid":"0.8","hash":"454d7f0c6ed7c72807aa917acbad2ee1bc139d73","price":"0.92","side":"SELL","size":"244.59"}],"timestamp":"1785207564914"},"payload_hash":"0b57a1234fdd9c4f8780a7e1fbba4bb807c50363a5cf7ec60da3f638ba3e9cb7","raw_frame":"{\"market\":\"0x0f70d07969bc69eaa97d0987de651885fdca02263688026aa11e7678af8f87aa\", \"price_changes\":[{\"asset_id\":\"64053005904884194822931764831592250494815136296598204104072528088122126148949\", \"price\":\"0.08\", \"size\":\"244.59\", \"side\":\"BUY\", \"hash\":\"ab63dffe5a1656e201497ab8b05db4947904abde\", \"best_bid\":\"0.19\", \"best_ask\":\"0.2\"}, {\"asset_id\":\"58313761654877669244690227616056238030136603415514645252000528337391143520538\", \"price\":\"0.92\", \"size\":\"244.59\", \"side\":\"SELL\", \"hash\":\"454d7f0c6ed7c72807aa917acbad2ee1bc139d73\", \"best_bid\":\"0.8\", \"best_ask\":\"0.81\"}], \"timestamp\":\"1785207564914\", \"event_type\":\"price_change\"}","received_at":"2026-07-28T02:59:24.778497Z","schema_version":"clob-market-ws.price_change.v1","sequence":null,"server_hash":null,"server_timestamp":"1785207564914","session_id":"5aad79be415c487c84df42bebd84ee93","source":"clob_market_ws"},"received_at":"2026-07-28T02:59:24.778497Z","record_id":"c8c9477a1d15b5b62ed8f2a5b92483696b0d7880fff19838183d99d04e898ea3","schema_fingerprint":"4aa3821a28b0b7c2400bc59aba4bcc0a76e971dadd19610d3ad38c768e124dc7","schema_version":"edge-lab-recorder.raw.v1","sequence":null,"source":"clob_market_ws"}
{"event_at":"2026-07-28T02:59:24.917000Z","event_fingerprint":"e54f996d2e95afb984dfecbe653264bb0c74c841be0de2c5fda878f1a2e69254","payload":{"connection_id":"955646bd8bf740759faf38750c0f263f","event_at":"2026-07-28T02:59:24.917000Z","event_type":"price_change","frame_hash":"56063055277ccc6e07a77638fcef5745a1538fd823b5aa7dd86cf86366993e1b","frame_index":0,"kind":"data","monotonic_ns":309547798087333,"payload":{"event_type":"price_change","market":"0x0f70d07969bc69eaa97d0987de651885fdca02263688026aa11e7678af8f87aa","price_changes":[{"asset_id":"64053005904884194822931764831592250494815136296598204104072528088122126148949","best_ask":"0.2","best_bid":"0.19","hash":"aac96c71660e9e11c17c70abb1cc3a5cd82682fa","price":"0.14","side":"BUY","size":"130.2"},{"asset_id":"58313761654877669244690227616056238030136603415514645252000528337391143520538","best_ask":"0.81","best_bid":"0.8","hash":"6375ede9ed5a06fedc769a4fb89ec4b95db35fdd","price":"0.86","side":"SELL","size":"130.2"}],"timestamp":"1785207564917"},"payload_hash":"12a883c9683b81eac98b9ce1ebf6486c78154f5c7a283df90d1bc7bd44328771","raw_frame":"{\"market\":\"0x0f70d07969bc69eaa97d0987de651885fdca02263688026aa11e7678af8f87aa\", \"price_changes\":[{\"asset_id\":\"64053005904884194822931764831592250494815136296598204104072528088122126148949\", \"price\":\"0.14\", \"size\":\"130.2\", \"side\":\"BUY\", \"hash\":\"aac96c71660e9e11c17c70abb1cc3a5cd82682fa\", \"best_bid\":\"0.19\", \"best_ask\":\"0.2\"}, {\"asset_id\":\"58313761654877669244690227616056238030136603415514645252000528337391143520538\", \"price\":\"0.86\", \"size\":\"130.2\", \"side\":\"SELL\", \"hash\":\"6375ede9ed5a06fedc769a4fb89ec4b95db35fdd\", \"best_bid\":\"0.8\", \"best_ask\":\"0.81\"}], \"timestamp\":\"1785207564917\", \"event_type\":\"price_change\"}","received_at":"2026-07-28T02:59:24.779977Z","schema_version":"clob-market-ws.price_change.v1","sequence":null,"server_hash":null,"server_timestamp":"1785207564917","session_id":"5aad79be415c487c84df42bebd84ee93","source":"clob_market_ws"},"received_at":"2026-07-28T02:59:24.779977Z","record_id":"e7de12a1776b24f17c595b0cb1845d6e421e7f1f6606a57abb7cf92227af7130","schema_fingerprint":"4aa3821a28b0b7c2400bc59aba4bcc0a76e971dadd19610d3ad38c768e124dc7","schema_version":"edge-lab-recorder.raw.v1","sequence":null,"source":"clob_market_ws"}
{"event_at":"2026-07-28T02:59:24.917000Z","event_fingerprint":"be941dfe1592e08aa33414124e991b02008b5acb94bc7c8f3fbda2d17f83b020","payload":{"connection_id":"955646bd8bf740759faf38750c0f263f","event_at":"2026-07-28T02:59:24.917000Z","event_type":"price_change","frame_hash":"bebba68ad3582a5f797ddf815f3c88666f67cb5b96e90cc452e4cb2b1b43cbc5","frame_index":0,"kind":"data","monotonic_ns":309547799596250,"payload":{"event_type":"price_change","market":"0x0f70d07969bc69eaa97d0987de651885fdca02263688026aa11e7678af8f87aa","price_changes":[{"asset_id":"58313761654877669244690227616056238030136603415514645252000528337391143520538","best_ask":"0.81","best_bid":"0.8","hash":"505dc444d13a4b68ba14c0d9ea35d44d0d9bb47a","price":"0.7","side":"BUY","size":"82.4"},{"asset_id":"64053005904884194822931764831592250494815136296598204104072528088122126148949","best_ask":"0.2","best_bid":"0.19","hash":"8ddad359720278bf0805df3c822671970ee9863d","price":"0.3","side":"SELL","size":"82.4"}],"timestamp":"1785207564917"},"payload_hash":"dbfd8b98e98139cf1c05e6fac1d250af6015cf7c94c36e6fd8a3b312cc42e530","raw_frame":"{\"market\":\"0x0f70d07969bc69eaa97d0987de651885fdca02263688026aa11e7678af8f87aa\", \"price_changes\":[{\"asset_id\":\"58313761654877669244690227616056238030136603415514645252000528337391143520538\", \"price\":\"0.7\", \"size\":\"82.4\", \"side\":\"BUY\", \"hash\":\"505dc444d13a4b68ba14c0d9ea35d44d0d9bb47a\", \"best_bid\":\"0.8\", \"best_ask\":\"0.81\"}, {\"asset_id\":\"64053005904884194822931764831592250494815136296598204104072528088122126148949\", \"price\":\"0.3\", \"size\":\"82.4\", \"side\":\"SELL\", \"hash\":\"8ddad359720278bf0805df3c822671970ee9863d\", \"best_bid\":\"0.19\", \"best_ask\":\"0.2\"}], \"timestamp\":\"1785207564917\", \"event_type\":\"price_change\"}","received_at":"2026-07-28T02:59:24.781487Z","schema_version":"clob-market-ws.price_change.v1","sequence":null,"server_hash":null,"server_timestamp":"1785207564917","session_id":"5aad79be415c487c84df42bebd84ee93","source":"clob_market_ws"},"received_at":"2026-07-28T02:59:24.781487Z","record_id":"8e9a0122a2c9f9e26b8235bd219a8bc8a130b1b43f472f98b39f6439929c77ac","schema_fingerprint":"4aa3821a28b0b7c2400bc59aba4bcc0a76e971dadd19610d3ad38c768e124dc7","schema_version":"edge-lab-recorder.raw.v1","sequence":null,"source":"clob_market_ws"}
{"event_at":"2026-07-28T02:59:24.918000Z","event_fingerprint":"c51e2058ece7039cc561a173f28febf749330896a23530498840e8a52eaec56a","payload":{"connection_id":"955646bd8bf740759faf38750c0f263f","event_at":"2026-07-28T02:59:24.918000Z","event_type":"price_change","frame_hash":"26ffce531454d56ca359d3ed86ef867bdaa7a285ae16e103f61c8bf683d9b27f","frame_index":0,"kind":"data","monotonic_ns":309547801095458,"payload":{"event_type":"price_change","market":"0x0f70d07969bc69eaa97d0987de651885fdca02263688026aa11e7678af8f87aa","price_changes":[{"asset_id":"64053005904884194822931764831592250494815136296598204104072528088122126148949","best_ask":"0.2","best_bid":"0.19","hash":"98e34d70a09d4008b6bdade48d1aa660525835e0","price":"0.08","side":"BUY","size":"294.59"},{"asset_id":"58313761654877669244690227616056238030136603415514645252000528337391143520538","best_ask":"0.81","best_bid":"0.8","hash":"3e5d676aaac92a9d975c39ecbc32bfb7ef4d3741","price":"0.92","side":"SELL","size":"294.59"}],"timestamp":"1785207564918"},"payload_hash":"af5343b084d391492544788240908357eea3ae8b05904109cf0acf70a744b5df","raw_frame":"{\"market\":\"0x0f70d07969bc69eaa97d0987de651885fdca02263688026aa11e7678af8f87aa\", \"price_changes\":[{\"asset_id\":\"64053005904884194822931764831592250494815136296598204104072528088122126148949\", \"price\":\"0.08\", \"size\":\"294.59\", \"side\":\"BUY\", \"hash\":\"98e34d70a09d4008b6bdade48d1aa660525835e0\", \"best_bid\":\"0.19\", \"best_ask\":\"0.2\"}, {\"asset_id\":\"58313761654877669244690227616056238030136603415514645252000528337391143520538\", \"price\":\"0.92\", \"size\":\"294.59\", \"side\":\"SELL\", \"hash\":\"3e5d676aaac92a9d975c39ecbc32bfb7ef4d3741\", \"best_bid\":\"0.8\", \"best_ask\":\"0.81\"}], \"timestamp\":\"1785207564918\", \"event_type\":\"price_change\"}","received_at":"2026-07-28T02:59:24.782987Z","schema_version":"clob-market-ws.price_change.v1","sequence":null,"server_hash":null,"server_timestamp":"1785207564918","session_id":"5aad79be415c487c84df42bebd84ee93","source":"clob_market_ws"},"received_at":"2026-07-28T02:59:24.782987Z","record_id":"ce65856b31e3ffa204a15199e7104dd59e54b66fc779c876f7921b8ebc169ea1","schema_fingerprint":"4aa3821a28b0b7c2400bc59aba4bcc0a76e971dadd19610d3ad38c768e124dc7","schema_version":"edge-lab-recorder.raw.v1","sequence":null,"source":"clob_market_ws"}
{"event_at":"2026-07-28T02:59:24.924000Z","event_fingerprint":"d22e120d0b84383699dad5f7d692314d7fe259e3f18bcb5c620477d1eaceed2b","payload":{"connection_id":"955646bd8bf740759faf38750c0f263f","event_at":"2026-07-28T02:59:24.924000Z","event_type":"price_change","frame_hash":"62973488798cf2a82c7a17c633d5ed018cf70f2af2a9938ff567dde65fa983ca","frame_index":0,"kind":"data","monotonic_ns":309547804061250,"payload":{"event_type":"price_change","market":"0x0f70d07969bc69eaa97d0987de651885fdca02263688026aa11e7678af8f87aa","price_changes":[{"asset_id":"64053005904884194822931764831592250494815136296598204104072528088122126148949","best_ask":"0.2","best_bid":"0.19","hash":"d89efdcc2ded9a71f804a95ef02b86ec95c3a2cd","price":"0.08","side":"BUY","size":"344.59"},{"asset_id":"58313761654877669244690227616056238030136603415514645252000528337391143520538","best_ask":"0.81","best_bid":"0.8","hash":"a546196896f4e0447ffc023633525e447939cad2","price":"0.92","side":"SELL","size":"344.59"}],"timestamp":"1785207564924"},"payload_hash":"cdbed41b8cc7824c57b2b043cedec9af5ab96342120c6c2892e2cecac5f234ec","raw_frame":"{\"market\":\"0x0f70d07969bc69eaa97d0987de651885fdca02263688026aa11e7678af8f87aa\", \"price_changes\":[{\"asset_id\":\"64053005904884194822931764831592250494815136296598204104072528088122126148949\", \"price\":\"0.08\", \"size\":\"344.59\", \"side\":\"BUY\", \"hash\":\"d89efdcc2ded9a71f804a95ef02b86ec95c3a2cd\", \"best_bid\":\"0.19\", \"best_ask\":\"0.2\"}, {\"asset_id\":\"58313761654877669244690227616056238030136603415514645252000528337391143520538\", \"price\":\"0.92\", \"size\":\"344.59\", \"side\":\"SELL\", \"hash\":\"a546196896f4e0447ffc023633525e447939cad2\", \"best_bid\":\"0.8\", \"best_ask\":\"0.81\"}], \"timestamp\":\"1785207564924\", \"event_type\":\"price_change\"}","received_at":"2026-07-28T02:59:24.785950Z","schema_version":"clob-market-ws.price_change.v1","sequence":null,"server_hash":null,"server_timestamp":"1785207564924","session_id":"5aad79be415c487c84df42bebd84ee93","source":"clob_market_ws"},"received_at":"2026-07-28T02:59:24.785950Z","record_id":"1aca6cdd0ec957dd43a50266834f5d349af6cc81e4a33eb8fdf49723e750cf85","schema_fingerprint":"4aa3821a28b0b7c2400bc59aba4bcc0a76e971dadd19610d3ad38c768e124dc7","schema_version":"edge-lab-recorder.raw.v1","sequence":null,"source":"clob_market_ws"}
{"event_at":"2026-07-28T02:59:24.925000Z","event_fingerprint":"96d4ae948c60e221216cfb9982ae1d37f1a22c88de923de95610cebcee24f504","payload":{"connection_id":"955646bd8bf740759faf38750c0f263f","event_at":"2026-07-28T02:59:24.925000Z","event_type":"price_change","frame_hash":"3e577bee04eaffdcc215e40c93b204d941c8b2770f5a45411d290673b244888e","frame_index":0,"kind":"data","monotonic_ns":309547805491375,"payload":{"event_type":"price_change","market":"0x0f70d07969bc69eaa97d0987de651885fdca02263688026aa11e7678af8f87aa","price_changes":[{"asset_id":"58313761654877669244690227616056238030136603415514645252000528337391143520538","best_ask":"0.81","best_bid":"0.8","hash":"974cd4ef3be9eebd71ee23c22cf144fb950d7929","price":"0.13","side":"BUY","size":"112.9"},{"asset_id":"64053005904884194822931764831592250494815136296598204104072528088122126148949","best_ask":"0.2","best_bid":"0.19","hash":"ec6e628c8dad4cf2495cdebb632e66d09f268767","price":"0.87","side":"SELL","size":"112.9"}],"timestamp":"1785207564925"},"payload_hash":"b6e2c425e62716e01b7b8ce4a78e77b6c600531992b72345d4ec73b47555fbb1","raw_frame":"{\"market\":\"0x0f70d07969bc69eaa97d0987de651885fdca02263688026aa11e7678af8f87aa\", \"price_changes\":[{\"asset_id\":\"58313761654877669244690227616056238030136603415514645252000528337391143520538\", \"price\":\"0.13\", \"size\":\"112.9\", \"side\":\"BUY\", \"hash\":\"974cd4ef3be9eebd71ee23c22cf144fb950d7929\", \"best_bid\":\"0.8\", \"best_ask\":\"0.81\"}, {\"asset_id\":\"64053005904884194822931764831592250494815136296598204104072528088122126148949\", \"price\":\"0.87\", \"size\":\"112.9\", \"side\":\"SELL\", \"hash\":\"ec6e628c8dad4cf2495cdebb632e66d09f268767\", \"best_bid\":\"0.19\", \"best_ask\":\"0.2\"}], \"timestamp\":\"1785207564925\", \"event_type\":\"price_change\"}","received_at":"2026-07-28T02:59:24.787385Z","schema_version":"clob-market-ws.price_change.v1","sequence":null,"server_hash":null,"server_timestamp":"1785207564925","session_id":"5aad79be415c487c84df42bebd84ee93","source":"clob_market_ws"},"received_at":"2026-07-28T02:59:24.787385Z","record_id":"16597cfadcea83cc614975453fa8f04620835fdd615abd256a253dac7b2bf988","schema_fingerprint":"4aa3821a28b0b7c2400bc59aba4bcc0a76e971dadd19610d3ad38c768e124dc7","schema_version":"edge-lab-recorder.raw.v1","sequence":null,"source":"clob_market_ws"}
{"event_at":"2026-07-28T02:59:24.926000Z","event_fingerprint":"fb4c0defd7068e6bc3e36398eaf3e5c7cf893eea0bccfbe439e4e30e5641ee33","payload":{"connection_id":"955646bd8bf740759faf38750c0f263f","event_at":"2026-07-28T02:59:24.926000Z","event_type":"price_change","frame_hash":"609add95b360525e2de9425608919042d9094f405818c69f17ec15b87c720283","frame_index":0,"kind":"data","monotonic_ns":309547806474291,"payload":{"event_type":"price_change","market":"0x0f70d07969bc69eaa97d0987de651885fdca02263688026aa11e7678af8f87aa","price_changes":[{"asset_id":"58313761654877669244690227616056238030136603415514645252000528337391143520538","best_ask":"0.81","best_bid":"0.8","hash":"1b3df2ccf06a8f202ffbddd6964b14abb51f8805","price":"0.03","side":"BUY","size":"480.8"},{"asset_id":"64053005904884194822931764831592250494815136296598204104072528088122126148949","best_ask":"0.2","best_bid":"0.19","hash":"3a97177e6bc7734308c1d4a92140e1639801d714","price":"0.97","side":"SELL","size":"480.8"}],"timestamp":"1785207564926"},"payload_hash":"e2c13dede927b19acb6b08d576d7662300e713cdfe218255c7508f20244391c1","raw_frame":"{\"market\":\"0x0f70d07969bc69eaa97d0987de651885fdca02263688026aa11e7678af8f87aa\", \"price_changes\":[{\"asset_id\":\"58313761654877669244690227616056238030136603415514645252000528337391143520538\", \"price\":\"0.03\", \"size\":\"480.8\", \"side\":\"BUY\", \"hash\":\"1b3df2ccf06a8f202ffbddd6964b14abb51f8805\", \"best_bid\":\"0.8\", \"best_ask\":\"0.81\"}, {\"asset_id\":\"64053005904884194822931764831592250494815136296598204104072528088122126148949\", \"price\":\"0.97\", \"size\":\"480.8\", \"side\":\"SELL\", \"hash\":\"3a97177e6bc7734308c1d4a92140e1639801d714\", \"best_bid\":\"0.19\", \"best_ask\":\"0.2\"}], \"timestamp\":\"1785207564926\", \"event_type\":\"price_change\"}","received_at":"2026-07-28T02:59:24.788365Z","schema_version":"clob-market-ws.price_change.v1","sequence":null,"server_hash":null,"server_timestamp":"1785207564926","session_id":"5aad79be415c487c84df42bebd84ee93","source":"clob_market_ws"},"received_at":"2026-07-28T02:59:24.788365Z","record_id":"83ed4524a9e8fea820af9df48c5b8400d2413c5bbf3d51599e65e8d8e4df24e4","schema_fingerprint":"4aa3821a28b0b7c2400bc59aba4bcc0a76e971dadd19610d3ad38c768e124dc7","schema_version":"edge-lab-recorder.raw.v1","sequence":null,"source":"clob_market_ws"}
{"event_at":"2026-07-28T02:59:24.930000Z","event_fingerprint":"9cdac947392e6b91b8eb404cb488bbde53b87534a1a57a9f34ef208294cb644f","payload":{"connection_id":"955646bd8bf740759faf38750c0f263f","event_at":"2026-07-28T02:59:24.930000Z","event_type":"price_change","frame_hash":"a6409ebc9a94c6a83f5a7b7a76d6fc3a71c8afce25d9778a13722b49f5da7d74","frame_index":0,"kind":"data","monotonic_ns":309547808058791,"payload":{"event_type":"price_change","market":"0x0f70d07969bc69eaa97d0987de651885fdca02263688026aa11e7678af8f87aa","price_changes":[{"asset_id":"64053005904884194822931764831592250494815136296598204104072528088122126148949","best_ask":"0.2","best_bid":"0.19","hash":"248f715bf051b1b34e68777387cac146d33da80f","price":"0.13","side":"BUY","size":"156.5"},{"asset_id":"58313761654877669244690227616056238030136603415514645252000528337391143520538","best_ask":"0.81","best_bid":"0.8","hash":"d1143a4fcb7b7ba3e9186740ce1a827e42ac1bdb","price":"0.87","side":"SELL","size":"156.5"}],"timestamp":"1785207564930"},"payload_hash":"fa8529a3cf067dc19b1c05d9b4fca89ff18c585f635c85fbf4c2514da3c3aac9","raw_frame":"{\"market\":\"0x0f70d07969bc69eaa97d0987de651885fdca02263688026aa11e7678af8f87aa\", \"price_changes\":[{\"asset_id\":\"64053005904884194822931764831592250494815136296598204104072528088122126148949\", \"price\":\"0.13\", \"size\":\"156.5\", \"side\":\"BUY\", \"hash\":\"248f715bf051b1b34e68777387cac146d33da80f\", \"best_bid\":\"0.19\", \"best_ask\":\"0.2\"}, {\"asset_id\":\"58313761654877669244690227616056238030136603415514645252000528337391143520538\", \"price\":\"0.87\", \"size\":\"156.5\", \"side\":\"SELL\", \"hash\":\"d1143a4fcb7b7ba3e9186740ce1a827e42ac1bdb\", \"best_bid\":\"0.8\", \"best_ask\":\"0.81\"}], \"timestamp\":\"1785207564930\", \"event_type\":\"price_change\"}","received_at":"2026-07-28T02:59:24.789948Z","schema_version":"clob-market-ws.price_change.v1","sequence":null,"server_hash":null,"server_timestamp":"1785207564930","session_id":"5aad79be415c487c84df42bebd84ee93","source":"clob_market_ws"},"received_at":"2026-07-28T02:59:24.789948Z","record_id":"33b79448dd69ed7d265a728742288ec7926c590694afd23911d403afaf44ec71","schema_fingerprint":"4aa3821a28b0b7c2400bc59aba4bcc0a76e971dadd19610d3ad38c768e124dc7","schema_version":"edge-lab-recorder.raw.v1","sequence":null,"source":"clob_market_ws"}
{"event_at":"2026-07-28T02:59:24.952000Z","event_fingerprint":"ebb888e90ec210bbfde1f7cc9bf415bf8ace8a5fd25ae387f69bbfd9bf62130b","payload":{"connection_id":"955646bd8bf740759faf38750c0f263f","event_at":"2026-07-28T02:59:24.952000Z","event_type":"price_change","frame_hash":"c696de3c48ac35f5bdbc667bf78cda96a5db80e11bcbeb80462b143c793d1f18","frame_index":0,"kind":"data","monotonic_ns":309547826354083,"payload":{"event_type":"price_change","market":"0x0f70d07969bc69eaa97d0987de651885fdca02263688026aa11e7678af8f87aa","price_changes":[{"asset_id":"58313761654877669244690227616056238030136603415514645252000528337391143520538","best_ask":"0.81","best_bid":"0.8","hash":"951d07df5c3b880b4e6607c1f91ba0be2dfebdd2","price":"0.1","side":"BUY","size":"439.93"},{"asset_id":"64053005904884194822931764831592250494815136296598204104072528088122126148949","best_ask":"0.2","best_bid":"0.19","hash":"eef4fca57f0eb5d42139934545751833bfc88e06","price":"0.9","side":"SELL","size":"439.93"}],"timestamp":"1785207564952"},"payload_hash":"282810724961afd654f2fc6d9362480ee70291eae5c976a507a25c0a0ce86c4f","raw_frame":"{\"market\":\"0x0f70d07969bc69eaa97d0987de651885fdca02263688026aa11e7678af8f87aa\", \"price_changes\":[{\"asset_id\":\"58313761654877669244690227616056238030136603415514645252000528337391143520538\", \"price\":\"0.1\", \"size\":\"439.93\", \"side\":\"BUY\", \"hash\":\"951d07df5c3b880b4e6607c1f91ba0be2dfebdd2\", \"best_bid\":\"0.8\", \"best_ask\":\"0.81\"}, {\"asset_id\":\"64053005904884194822931764831592250494815136296598204104072528088122126148949\", \"price\":\"0.9\", \"size\":\"439.93\", \"side\":\"SELL\", \"hash\":\"eef4fca57f0eb5d42139934545751833bfc88e06\", \"best_bid\":\"0.19\", \"best_ask\":\"0.2\"}], \"timestamp\":\"1785207564952\", \"event_type\":\"price_change\"}","received_at":"2026-07-28T02:59:24.808243Z","schema_version":"clob-market-ws.price_change.v1","sequence":null,"server_hash":null,"server_timestamp":"1785207564952","session_id":"5aad79be415c487c84df42bebd84ee93","source":"clob_market_ws"},"received_at":"2026-07-28T02:59:24.808243Z","record_id":"767fad0c19712cb6983589878f50171cc313b6d9b052a376265fdfa3535a40a7","schema_fingerprint":"4aa3821a28b0b7c2400bc59aba4bcc0a76e971dadd19610d3ad38c768e124dc7","schema_version":"edge-lab-recorder.raw.v1","sequence":null,"source":"clob_market_ws"}
{"event_at":"2026-07-28T02:59:24.970000Z","event_fingerprint":"3b95fd4aba41c838e5ae07d568abb9968d2e924822bba45936629ed2308409aa","payload":{"connection_id":"955646bd8bf740759faf38750c0f263f","event_at":"2026-07-28T02:59:24.970000Z","event_type":"price_change","frame_hash":"3876f762f38f073b337733c9920c8324aeb16f5f147a7d4113ee0c932f956bca","frame_index":0,"kind":"data","monotonic_ns":309547846367500,"payload":{"event_type":"price_change","market":"0x0f70d07969bc69eaa97d0987de651885fdca02263688026aa11e7678af8f87aa","price_changes":[{"asset_id":"58313761654877669244690227616056238030136603415514645252000528337391143520538","best_ask":"0.81","best_bid":"0.8","hash":"484fa7380cf0e5a139397121b186f34383c4c4c6","price":"0.72","side":"BUY","size":"125.7"},{"asset_id":"64053005904884194822931764831592250494815136296598204104072528088122126148949","best_ask":"0.2","best_bid":"0.19","hash":"0122304631eed7f62d58c2f2ac8653d4209a8242","price":"0.28","side":"SELL","size":"125.7"}],"timestamp":"1785207564970"},"payload_hash":"8e4051b19e069f9ee983bad904d8525d939311499350481eb7df74c12eae8788","raw_frame":"{\"market\":\"0x0f70d07969bc69eaa97d0987de651885fdca02263688026aa11e7678af8f87aa\", \"price_changes\":[{\"asset_id\":\"58313761654877669244690227616056238030136603415514645252000528337391143520538\", \"price\":\"0.72\", \"size\":\"125.7\", \"side\":\"BUY\", \"hash\":\"484fa7380cf0e5a139397121b186f34383c4c4c6\", \"best_bid\":\"0.8\", \"best_ask\":\"0.81\"}, {\"asset_id\":\"64053005904884194822931764831592250494815136296598204104072528088122126148949\", \"price\":\"0.28\", \"size\":\"125.7\", \"side\":\"SELL\", \"hash\":\"0122304631eed7f62d58c2f2ac8653d4209a8242\", \"best_bid\":\"0.19\", \"best_ask\":\"0.2\"}], \"timestamp\":\"1785207564970\", \"event_type\":\"price_change\"}","received_at":"2026-07-28T02:59:24.828256Z","schema_version":"clob-market-ws.price_change.v1","sequence":null,"server_hash":null,"server_timestamp":"1785207564970","session_id":"5aad79be415c487c84df42bebd84ee93","source":"clob_market_ws"},"received_at":"2026-07-28T02:59:24.828256Z","record_id":"6dd52c6da6ccd2e1e4ed49309390a6a338b223e3f13fbda3f4d8f5aa1dcf4bd9","schema_fingerprint":"4aa3821a28b0b7c2400bc59aba4bcc0a76e971dadd19610d3ad38c768e124dc7","schema_version":"edge-lab-recorder.raw.v1","sequence":null,"source":"clob_market_ws"}
{"event_at":"2026-07-28T02:59:24.977000Z","event_fingerprint":"8df681126e0969a474a6820b0129967882b2fb5f6e3cb2a95690ea9c57376f27","payload":{"connection_id":"955646bd8bf740759faf38750c0f263f","event_at":"2026-07-28T02:59:24.977000Z","event_type":"price_change","frame_hash":"db8ab1ecf52761fa42df5641ce5b0fc9738103afd78c3949b37c4c7066d46cda","frame_index":0,"kind":"data","monotonic_ns":309547857282958,"payload":{"event_type":"price_change","market":"0x0f70d07969bc69eaa97d0987de651885fdca02263688026aa11e7678af8f87aa","price_changes":[{"asset_id":"58313761654877669244690227616056238030136603415514645252000528337391143520538","best_ask":"0.81","best_bid":"0.8","hash":"650231c80aa2c91d0a8de77fe02a202f262bfb56","price":"0.03","side":"BUY","size":"475.8"},{"asset_id":"64053005904884194822931764831592250494815136296598204104072528088122126148949","best_ask":"0.2","best_bid":"0.19","hash":"0a6c508b9d3097530ac6eeef33d9a49ed3be788e","price":"0.97","side":"SELL","size":"475.8"}],"timestamp":"1785207564977"},"payload_hash":"055bd8f7611c4d28a70126bce31a7b737b89e956c095c2b9f1c9cb47d0ae8b84","raw_frame":"{\"market\":\"0x0f70d07969bc69eaa97d0987de651885fdca02263688026aa11e7678af8f87aa\", \"price_changes\":[{\"asset_id\":\"58313761654877669244690227616056238030136603415514645252000528337391143520538\", \"price\":\"0.03\", \"size\":\"475.8\", \"side\":\"BUY\", \"hash\":\"650231c80aa2c91d0a8de77fe02a202f262bfb56\", \"best_bid\":\"0.8\", \"best_ask\":\"0.81\"}, {\"asset_id\":\"64053005904884194822931764831592250494815136296598204104072528088122126148949\", \"price\":\"0.97\", \"size\":\"475.8\", \"side\":\"SELL\", \"hash\":\"0a6c508b9d3097530ac6eeef33d9a49ed3be788e\", \"best_bid\":\"0.19\", \"best_ask\":\"0.2\"}], \"timestamp\":\"1785207564977\", \"event_type\":\"price_change\"}","received_at":"2026-07-28T02:59:24.839171Z","schema_version":"clob-market-ws.price_change.v1","sequence":null,"server_hash":null,"server_timestamp":"1785207564977","session_id":"5aad79be415c487c84df42bebd84ee93","source":"clob_market_ws"},"received_at":"2026-07-28T02:59:24.839171Z","record_id":"667b6e407d37e2f72a18cff2784989285248b93dae1f3b7d0e16e6156cffd5b3","schema_fingerprint":"4aa3821a28b0b7c2400bc59aba4bcc0a76e971dadd19610d3ad38c768e124dc7","schema_version":"edge-lab-recorder.raw.v1","sequence":null,"source":"clob_market_ws"}
{"event_at":"2026-07-28T02:59:24.983000Z","event_fingerprint":"12fe50b198c485c2a8e09b7ec15ef90845859e88fe2dcde6059a0492983e2bf0","payload":{"connection_id":"955646bd8bf740759faf38750c0f263f","event_at":"2026-07-28T02:59:24.983000Z","event_type":"price_change","frame_hash":"f30fbfe9b389496e248d15af2f6162a23ec731db798c7c671e144be033dbe4cc","frame_index":0,"kind":"data","monotonic_ns":309547859609208,"payload":{"event_type":"price_change","market":"0x0f70d07969bc69eaa97d0987de651885fdca02263688026aa11e7678af8f87aa","price_changes":[{"asset_id":"58313761654877669244690227616056238030136603415514645252000528337391143520538","best_ask":"0.81","best_bid":"0.8","hash":"849c079c9636cbd9cdf8f34f95fbef06a7c59449","price":"0.71","side":"BUY","size":"86.09"},{"asset_id":"64053005904884194822931764831592250494815136296598204104072528088122126148949","best_ask":"0.2","best_bid":"0.19","hash":"89fc45ecfc0f7e0e3c4d5333be2e4ca94c126b03","price":"0.29","side":"SELL","size":"86.09"}],"timestamp":"1785207564983"},"payload_hash":"53d58438ccaf04b4f05e30e6d47cd59b7c4520e243f7e86df465e9c56a1bd86e","raw_frame":"{\"market\":\"0x0f70d07969bc69eaa97d0987de651885fdca02263688026aa11e7678af8f87aa\", \"price_changes\":[{\"asset_id\":\"58313761654877669244690227616056238030136603415514645252000528337391143520538\", \"price\":\"0.71\", \"size\":\"86.09\", \"side\":\"BUY\", \"hash\":\"849c079c9636cbd9cdf8f34f95fbef06a7c59449\", \"best_bid\":\"0.8\", \"best_ask\":\"0.81\"}, {\"asset_id\":\"64053005904884194822931764831592250494815136296598204104072528088122126148949\", \"price\":\"0.29\", \"size\":\"86.09\", \"side\":\"SELL\", \"hash\":\"89fc45ecfc0f7e0e3c4d5333be2e4ca94c126b03\", \"best_bid\":\"0.19\", \"best_ask\":\"0.2\"}], \"timestamp\":\"1785207564983\", \"event_type\":\"price_change\"}","received_at":"2026-07-28T02:59:24.841498Z","schema_version":"clob-market-ws.price_change.v1","sequence":null,"server_hash":null,"server_timestamp":"1785207564983","session_id":"5aad79be415c487c84df42bebd84ee93","source":"clob_market_ws"},"received_at":"2026-07-28T02:59:24.841498Z","record_id":"c48e926cab3f65a6e229d2289b370b7fd396e4223b68e13617c6ebb75581a137","schema_fingerprint":"4aa3821a28b0b7c2400bc59aba4bcc0a76e971dadd19610d3ad38c768e124dc7","schema_version":"edge-lab-recorder.raw.v1","sequence":null,"source":"clob_market_ws"}
{"event_at":"2026-07-28T02:59:24.997000Z","event_fingerprint":"49f5b4d2bf01d2c2331b3063588c26bed0045fc394a560813a5512c381e74f38","payload":{"connection_id":"955646bd8bf740759faf38750c0f263f","event_at":"2026-07-28T02:59:24.997000Z","event_type":"price_change","frame_hash":"b3a954f4a985f36d3a13b4393c230523de21ad437a340f25a26f3a0e345a271e","frame_index":0,"kind":"data","monotonic_ns":309547874796583,"payload":{"event_type":"price_change","market":"0x0f70d07969bc69eaa97d0987de651885fdca02263688026aa11e7678af8f87aa","price_changes":[{"asset_id":"64053005904884194822931764831592250494815136296598204104072528088122126148949","best_ask":"0.2","best_bid":"0.19","hash":"ec9ac7d29bbb384e6fa75cf9c3fd86ef03cada36","price":"0.11","side":"BUY","size":"134.5"},{"asset_id":"58313761654877669244690227616056238030136603415514645252000528337391143520538","best_ask":"0.81","best_bid":"0.8","hash":"e6884f3a0b6949b665db03cf708d95296eb8a802","price":"0.89","side":"SELL","size":"134.5"}],"timestamp":"1785207564997"},"payload_hash":"2b90aea98b6f63c9db6dafc85133aceae095d7da149c6af73fcb792156217a9f","raw_frame":"{\"market\":\"0x0f70d07969bc69eaa97d0987de651885fdca02263688026aa11e7678af8f87aa\", \"price_changes\":[{\"asset_id\":\"64053005904884194822931764831592250494815136296598204104072528088122126148949\", \"price\":\"0.11\", \"size\":\"134.5\", \"side\":\"BUY\", \"hash\":\"ec9ac7d29bbb384e6fa75cf9c3fd86ef03cada36\", \"best_bid\":\"0.19\", \"best_ask\":\"0.2\"}, {\"asset_id\":\"58313761654877669244690227616056238030136603415514645252000528337391143520538\", \"price\":\"0.89\", \"size\":\"134.5\", \"side\":\"SELL\", \"hash\":\"e6884f3a0b6949b665db03cf708d95296eb8a802\", \"best_bid\":\"0.8\", \"best_ask\":\"0.81\"}], \"timestamp\":\"1785207564997\", \"event_type\":\"price_change\"}","received_at":"2026-07-28T02:59:24.856685Z","schema_version":"clob-market-ws.price_change.v1","sequence":null,"server_hash":null,"server_timestamp":"1785207564997","session_id":"5aad79be415c487c84df42bebd84ee93","source":"clob_market_ws"},"received_at":"2026-07-28T02:59:24.856685Z","record_id":"0e76fd96fa491d7a188a56e75ec9833457d3d91e0fc758be6de5e1e011be1759","schema_fingerprint":"4aa3821a28b0b7c2400bc59aba4bcc0a76e971dadd19610d3ad38c768e124dc7","schema_version":"edge-lab-recorder.raw.v1","sequence":null,"source":"clob_market_ws"}
{"event_at":"2026-07-28T02:59:24.998000Z","event_fingerprint":"3f9bc17b72349f834d601687f2c9bd1bba4472bc39df93f93aa1121bec47f457","payload":{"connection_id":"955646bd8bf740759faf38750c0f263f","event_at":"2026-07-28T02:59:24.998000Z","event_type":"price_change","frame_hash":"5b0fc23e5b0d7311fdc5899be06d6e63f070e65d43b6c344a133c6d2c5394b98","frame_index":0,"kind":"data","monotonic_ns":309547876318333,"payload":{"event_type":"price_change","market":"0x0f70d07969bc69eaa97d0987de651885fdca02263688026aa11e7678af8f87aa","price_changes":[{"asset_id":"58313761654877669244690227616056238030136603415514645252000528337391143520538","best_ask":"0.81","best_bid":"0.8","hash":"7099ab12d15d2807b19deed983d30069ff037651","price":"0.73","side":"BUY","size":"20"},{"asset_id":"64053005904884194822931764831592250494815136296598204104072528088122126148949","best_ask":"0.2","best_bid":"0.19","hash":"4f7daa36c6072c7b44ba0c3c6b4989ef017cffc2","price":"0.27","side":"SELL","size":"20"}],"timestamp":"1785207564998"},"payload_hash":"219d7c9181bb1d29c59f50d95ee25aaa89e4604bdb931c86c9e7ff720fd7758c","raw_frame":"{\"market\":\"0x0f70d07969bc69eaa97d0987de651885fdca02263688026aa11e7678af8f87aa\", \"price_changes\":[{\"asset_id\":\"58313761654877669244690227616056238030136603415514645252000528337391143520538\", \"price\":\"0.73\", \"size\":\"20\", \"side\":\"BUY\", \"hash\":\"7099ab12d15d2807b19deed983d30069ff037651\", \"best_bid\":\"0.8\", \"best_ask\":\"0.81\"}, {\"asset_id\":\"64053005904884194822931764831592250494815136296598204104072528088122126148949\", \"price\":\"0.27\", \"size\":\"20\", \"side\":\"SELL\", \"hash\":\"4f7daa36c6072c7b44ba0c3c6b4989ef017cffc2\", \"best_bid\":\"0.19\", \"best_ask\":\"0.2\"}], \"timestamp\":\"1785207564998\", \"event_type\":\"price_change\"}","received_at":"2026-07-28T02:59:24.858207Z","schema_version":"clob-market-ws.price_change.v1","sequence":null,"server_hash":null,"server_timestamp":"1785207564998","session_id":"5aad79be415c487c84df42bebd84ee93","source":"clob_market_ws"},"received_at":"2026-07-28T02:59:24.858207Z","record_id":"9d9eba59cdcf3bdbea6c61c5cf1f78ddff56c79878c32a88851ea21a5b598985","schema_fingerprint":"4aa3821a28b0b7c2400bc59aba4bcc0a76e971dadd19610d3ad38c768e124dc7","schema_version":"edge-lab-recorder.raw.v1","sequence":null,"source":"clob_market_ws"}
{"event_at":"2026-07-28T02:59:25.003000Z","event_fingerprint":"16cc830f5ed3a8299c57aefff7c6068bee0b30ff64cefe5320f378140f8b1253","payload":{"connection_id":"955646bd8bf740759faf38750c0f263f","event_at":"2026-07-28T02:59:25.003000Z","event_type":"price_change","frame_hash":"542f01f16725f56f15bd148649e11c88385a0b3c36b047464d50078bd85aaa07","frame_index":0,"kind":"data","monotonic_ns":309547880924500,"payload":{"event_type":"price_change","market":"0x0f70d07969bc69eaa97d0987de651885fdca02263688026aa11e7678af8f87aa","price_changes":[{"asset_id":"58313761654877669244690227616056238030136603415514645252000528337391143520538","best_ask":"0.81","best_bid":"0.8","hash":"5f27f78357031a0d8a40881a22dcd076dc3cf1b4","price":"0.7","side":"BUY","size":"67.4"},{"asset_id":"64053005904884194822931764831592250494815136296598204104072528088122126148949","best_ask":"0.2","best_bid":"0.19","hash":"8f010e5130e7abae68cb142773df061a7c84286c","price":"0.3","side":"SELL","size":"67.4"}],"timestamp":"1785207565003"},"payload_hash":"b01ea50b775182545be40c4a30f5c04ed01bb2114a9aa7057446945af07f51d7","raw_frame":"{\"market\":\"0x0f70d07969bc69eaa97d0987de651885fdca02263688026aa11e7678af8f87aa\", \"price_changes\":[{\"asset_id\":\"58313761654877669244690227616056238030136603415514645252000528337391143520538\", \"price\":\"0.7\", \"size\":\"67.4\", \"side\":\"BUY\", \"hash\":\"5f27f78357031a0d8a40881a22dcd076dc3cf1b4\", \"best_bid\":\"0.8\", \"best_ask\":\"0.81\"}, {\"asset_id\":\"64053005904884194822931764831592250494815136296598204104072528088122126148949\", \"price\":\"0.3\", \"size\":\"67.4\", \"side\":\"SELL\", \"hash\":\"8f010e5130e7abae68cb142773df061a7c84286c\", \"best_bid\":\"0.19\", \"best_ask\":\"0.2\"}], \"timestamp\":\"1785207565003\", \"event_type\":\"price_change\"}","received_at":"2026-07-28T02:59:24.862810Z","schema_version":"clob-market-ws.price_change.v1","sequence":null,"server_hash":null,"server_timestamp":"1785207565003","session_id":"5aad79be415c487c84df42bebd84ee93","source":"clob_market_ws"},"received_at":"2026-07-28T02:59:24.862810Z","record_id":"ee608e9461518d61d47d6ccf5c63ee6854ef3eebf3b80f83f396573f52c472b2","schema_fingerprint":"4aa3821a28b0b7c2400bc59aba4bcc0a76e971dadd19610d3ad38c768e124dc7","schema_version":"edge-lab-recorder.raw.v1","sequence":null,"source":"clob_market_ws"}
{"event_at":"2026-07-28T02:59:25.003000Z","event_fingerprint":"7dd3cb6e1de00d99dc9004bb53c063f1675321a37392fda4cda46be9d5d2e5c1","payload":{"connection_id":"955646bd8bf740759faf38750c0f263f","event_at":"2026-07-28T02:59:25.003000Z","event_type":"price_change","frame_hash":"fb75aa8012c8bdf13e3db04e1193689bbe82f69457457f354a0e4ce45b643024","frame_index":0,"kind":"data","monotonic_ns":309547882513125,"payload":{"event_type":"price_change","market":"0x0f70d07969bc69eaa97d0987de651885fdca02263688026aa11e7678af8f87aa","price_changes":[{"asset_id":"64053005904884194822931764831592250494815136296598204104072528088122126148949","best_ask":"0.2","best_bid":"0.19","hash":"d312a7db1df20b1314dc87e61fa8c521a07ef217","price":"0.07","side":"BUY","size":"243.2"},{"asset_id":"58313761654877669244690227616056238030136603415514645252000528337391143520538","best_ask":"0.81","best_bid":"0.8","hash":"bd20dc819b6685334af2ab8e4cbf5dc8d1bdcf45","price":"0.93","side":"SELL","size":"243.2"}],"timestamp":"1785207565003"},"payload_hash":"d38376986db2ea249899d9cf1928a0f6dd7fe7766d16b49a3425e81ae46be1fa","raw_frame":"{\"market\":\"0x0f70d07969bc69eaa97d0987de651885fdca02263688026aa11e7678af8f87aa\", \"price_changes\":[{\"asset_id\":\"64053005904884194822931764831592250494815136296598204104072528088122126148949\", \"price\":\"0.07\", \"size\":\"243.2\", \"side\":\"BUY\", \"hash\":\"d312a7db1df20b1314dc87e61fa8c521a07ef217\", \"best_bid\":\"0.19\", \"best_ask\":\"0.2\"}, {\"asset_id\":\"58313761654877669244690227616056238030136603415514645252000528337391143520538\", \"price\":\"0.93\", \"size\":\"243.2\", \"side\":\"SELL\", \"hash\":\"bd20dc819b6685334af2ab8e4cbf5dc8d1bdcf45\", \"best_bid\":\"0.8\", \"best_ask\":\"0.81\"}], \"timestamp\":\"1785207565003\", \"event_type\":\"price_change\"}","received_at":"2026-07-28T02:59:24.864403Z","schema_version":"clob-market-ws.price_change.v1","sequence":null,"server_hash":null,"server_timestamp":"1785207565003","session_id":"5aad79be415c487c84df42bebd84ee93","source":"clob_market_ws"},"received_at":"2026-07-28T02:59:24.864403Z","record_id":"6bcbe77f8a439038404997a633e61d2b499673dd0ef1677087fea6b3b16e1af7","schema_fingerprint":"4aa3821a28b0b7c2400bc59aba4bcc0a76e971dadd19610d3ad38c768e124dc7","schema_version":"edge-lab-recorder.raw.v1","sequence":null,"source":"clob_market_ws"}
{"event_at":"2026-07-28T02:59:25.005000Z","event_fingerprint":"98e1c8b3a1e7f8e9448ecd8ceb8233812c6635051abb7e22e378f31a7d073637","payload":{"connection_id":"955646bd8bf740759faf38750c0f263f","event_at":"2026-07-28T02:59:25.005000Z","event_type":"price_change","frame_hash":"08fcbb712cb6adca623e900c6b856513cde5bd139bdb424c69477a77c4381505","frame_index":0,"kind":"data","monotonic_ns":309547884006416,"payload":{"event_type":"price_change","market":"0x0f70d07969bc69eaa97d0987de651885fdca02263688026aa11e7678af8f87aa","price_changes":[{"asset_id":"64053005904884194822931764831592250494815136296598204104072528088122126148949","best_ask":"0.2","best_bid":"0.19","hash":"36a580c920da61219924415a25a6dac19fb515ba","price":"0.13","side":"BUY","size":"141.5"},{"asset_id":"58313761654877669244690227616056238030136603415514645252000528337391143520538","best_ask":"0.81","best_bid":"0.8","hash":"8568f7e794228a2454a307d0b71e3e74de426b33","price":"0.87","side":"SELL","size":"141.5"}],"timestamp":"1785207565005"},"payload_hash":"d1cf4ab9d4a860592e3431da4808957f1cd70ae53aaca7e2c973d6ba517720e9","raw_frame":"{\"market\":\"0x0f70d07969bc69eaa97d0987de651885fdca02263688026aa11e7678af8f87aa\", \"price_changes\":[{\"asset_id\":\"64053005904884194822931764831592250494815136296598204104072528088122126148949\", \"price\":\"0.13\", \"size\":\"141.5\", \"side\":\"BUY\", \"hash\":\"36a580c920da61219924415a25a6dac19fb515ba\", \"best_bid\":\"0.19\", \"best_ask\":\"0.2\"}, {\"asset_id\":\"58313761654877669244690227616056238030136603415514645252000528337391143520538\", \"price\":\"0.87\", \"size\":\"141.5\", \"side\":\"SELL\", \"hash\":\"8568f7e794228a2454a307d0b71e3e74de426b33\", \"best_bid\":\"0.8\", \"best_ask\":\"0.81\"}], \"timestamp\":\"1785207565005\", \"event_type\":\"price_change\"}","received_at":"2026-07-28T02:59:24.865896Z","schema_version":"clob-market-ws.price_change.v1","sequence":null,"server_hash":null,"server_timestamp":"1785207565005","session_id":"5aad79be415c487c84df42bebd84ee93","source":"clob_market_ws"},"received_at":"2026-07-28T02:59:24.865896Z","record_id":"86e7df7773af878a7900b8698a131a3b1f2f63dce4282e33f68620ab882ad199","schema_fingerprint":"4aa3821a28b0b7c2400bc59aba4bcc0a76e971dadd19610d3ad38c768e124dc7","schema_version":"edge-lab-recorder.raw.v1","sequence":null,"source":"clob_market_ws"}
{"event_at":"2026-07-28T02:59:25.005000Z","event_fingerprint":"9b0a8100912e7165c1432e52fa5cdd1099f78fd0abeb35881c6556d17b8a7347","payload":{"connection_id":"955646bd8bf740759faf38750c0f263f","event_at":"2026-07-28T02:59:25.005000Z","event_type":"price_change","frame_hash":"1878d4e1ab588bebc5be8a71de1135d96b21a1208bf7e17439bd2c3a0ffd983a","frame_index":0,"kind":"data","monotonic_ns":309547887472125,"payload":{"event_type":"price_change","market":"0x0f70d07969bc69eaa97d0987de651885fdca02263688026aa11e7678af8f87aa","price_changes":[{"asset_id":"58313761654877669244690227616056238030136603415514645252000528337391143520538","best_ask":"0.81","best_bid":"0.8","hash":"75d173bccca1c56d3902f4b2f5512cca612e06ec","price":"0.77","side":"BUY","size":"254.17"},{"asset_id":"64053005904884194822931764831592250494815136296598204104072528088122126148949","best_ask":"0.2","best_bid":"0.19","hash":"81ce687309deafe7c2512cff24c2d6af828759dc","price":"0.23","side":"SELL","size":"254.17"}],"timestamp":"1785207565005"},"payload_hash":"d8818254858d5169d8e74dad4a96704291f18bda70c513e3eb35c5bd3c18e77c","raw_frame":"{\"market\":\"0x0f70d07969bc69eaa97d0987de651885fdca02263688026aa11e7678af8f87aa\", \"price_changes\":[{\"asset_id\":\"58313761654877669244690227616056238030136603415514645252000528337391143520538\", \"price\":\"0.77\", \"size\":\"254.17\", \"side\":\"BUY\", \"hash\":\"75d173bccca1c56d3902f4b2f5512cca612e06ec\", \"best_bid\":\"0.8\", \"best_ask\":\"0.81\"}, {\"asset_id\":\"64053005904884194822931764831592250494815136296598204104072528088122126148949\", \"price\":\"0.23\", \"size\":\"254.17\", \"side\":\"SELL\", \"hash\":\"81ce687309deafe7c2512cff24c2d6af828759dc\", \"best_bid\":\"0.19\", \"best_ask\":\"0.2\"}], \"timestamp\":\"1785207565005\", \"event_type\":\"price_change\"}","received_at":"2026-07-28T02:59:24.869359Z","schema_version":"clob-market-ws.price_change.v1","sequence":null,"server_hash":null,"server_timestamp":"1785207565005","session_id":"5aad79be415c487c84df42bebd84ee93","source":"clob_market_ws"},"received_at":"2026-07-28T02:59:24.869359Z","record_id":"b6d35e6a67985faa74f58f51a73066b856f25a8ec9c8ce959cebe3529f092b9b","schema_fingerprint":"4aa3821a28b0b7c2400bc59aba4bcc0a76e971dadd19610d3ad38c768e124dc7","schema_version":"edge-lab-recorder.raw.v1","sequence":null,"source":"clob_market_ws"}
{"event_at":"2026-07-28T02:59:25.018000Z","event_fingerprint":"38086e46ed2b2382f837518d4a29ac3b4b29578abb8cb29182afda9fcb64ff13","payload":{"connection_id":"955646bd8bf740759faf38750c0f263f","event_at":"2026-07-28T02:59:25.018000Z","event_type":"price_change","frame_hash":"ec77b8bb2e0d5257d603c03c9f242c57529278fd2026cad804b3a78de549ceb8","frame_index":0,"kind":"data","monotonic_ns":309547892720625,"payload":{"event_type":"price_change","market":"0x0f70d07969bc69eaa97d0987de651885fdca02263688026aa11e7678af8f87aa","price_changes":[{"asset_id":"64053005904884194822931764831592250494815136296598204104072528088122126148949","best_ask":"0.2","best_bid":"0.19","hash":"d7b11d81b9569638ee99cdf9b8f85e9045748214","price":"0.01","side":"BUY","size":"2989.4"},{"asset_id":"58313761654877669244690227616056238030136603415514645252000528337391143520538","best_ask":"0.81","best_bid":"0.8","hash":"ec9b8d7e7a34f9370810365619d969541169c116","price":"0.99","side":"SELL","size":"2989.4"}],"timestamp":"1785207565018"},"payload_hash":"95efda4d9b4c3023c80d84a9bef1db200dc195f45d0df57bacefb563cfc6a5a1","raw_frame":"{\"market\":\"0x0f70d07969bc69eaa97d0987de651885fdca02263688026aa11e7678af8f87aa\", \"price_changes\":[{\"asset_id\":\"64053005904884194822931764831592250494815136296598204104072528088122126148949\", \"price\":\"0.01\", \"size\":\"2989.4\", \"side\":\"BUY\", \"hash\":\"d7b11d81b9569638ee99cdf9b8f85e9045748214\", \"best_bid\":\"0.19\", \"best_ask\":\"0.2\"}, {\"asset_id\":\"58313761654877669244690227616056238030136603415514645252000528337391143520538\", \"price\":\"0.99\", \"size\":\"2989.4\", \"side\":\"SELL\", \"hash\":\"ec9b8d7e7a34f9370810365619d969541169c116\", \"best_bid\":\"0.8\", \"best_ask\":\"0.81\"}], \"timestamp\":\"1785207565018\", \"event_type\":\"price_change\"}","received_at":"2026-07-28T02:59:24.874608Z","schema_version":"clob-market-ws.price_change.v1","sequence":null,"server_hash":null,"server_timestamp":"1785207565018","session_id":"5aad79be415c487c84df42bebd84ee93","source":"clob_market_ws"},"received_at":"2026-07-28T02:59:24.874608Z","record_id":"dd5eed0c055c3f7b4255de4a809618887d891298e32872b1125613ec0b6eff33","schema_fingerprint":"4aa3821a28b0b7c2400bc59aba4bcc0a76e971dadd19610d3ad38c768e124dc7","schema_version":"edge-lab-recorder.raw.v1","sequence":null,"source":"clob_market_ws"}
