{"event_at":"2026-07-28T02:55:42.412000Z","event_fingerprint":"cca8259a0d0594bdad6b4cd875cc5a13fc654bac1afbb2fd4a900ba4c9280c3a","payload":{"connection_id":"955646bd8bf740759faf38750c0f263f","event_at":"2026-07-28T02:55:42.412000Z","event_type":"price_change","frame_hash":"6e7bf97d00b4f096b44405bf92407e0d94c6c87638e2a11cec17812a65d0be26","frame_index":0,"kind":"data","monotonic_ns":309326784667125,"payload":{"event_type":"price_change","market":"0x0f70d07969bc69eaa97d0987de651885fdca02263688026aa11e7678af8f87aa","price_changes":[{"asset_id":"58313761654877669244690227616056238030136603415514645252000528337391143520538","best_ask":"0.56","best_bid":"0.55","hash":"40d4a965eb00e975a4af89732e0696996987e8e1","price":"0.54","side":"BUY","size":"77.44"},{"asset_id":"64053005904884194822931764831592250494815136296598204104072528088122126148949","best_ask":"0.45","best_bid":"0.44","hash":"7113839cad3fbf1a25fad165e084581b09532ec0","price":"0.46","side":"SELL","size":"77.44"}],"timestamp":"1785207342412"},"payload_hash":"0564ffed6fe3e56d50f36af483963ad8971bc4c77f441c3cd01da9666eed0e5e","raw_frame":"{\"market\":\"0x0f70d07969bc69eaa97d0987de651885fdca02263688026aa11e7678af8f87aa\", \"price_changes\":[{\"asset_id\":\"58313761654877669244690227616056238030136603415514645252000528337391143520538\", \"price\":\"0.54\", \"size\":\"77.44\", \"side\":\"BUY\", \"hash\":\"40d4a965eb00e975a4af89732e0696996987e8e1\", \"best_bid\":\"0.55\", \"best_ask\":\"0.56\"}, {\"asset_id\":\"64053005904884194822931764831592250494815136296598204104072528088122126148949\", \"price\":\"0.46\", \"size\":\"77.44\", \"side\":\"SELL\", \"hash\":\"7113839cad3fbf1a25fad165e084581b09532ec0\", \"best_bid\":\"0.44\", \"best_ask\":\"0.45\"}], \"timestamp\":\"1785207342412\", \"event_type\":\"price_change\"}","received_at":"2026-07-28T02:55:43.768145Z","schema_version":"clob-market-ws.price_change.v1","sequence":null,"server_hash":null,"server_timestamp":"1785207342412","session_id":"5aad79be415c487c84df42bebd84ee93","source":"clob_market_ws"},"received_at":"2026-07-28T02:55:43.768145Z","record_id":"cca6a2c4417fae1dbc48eac3a664844f4b0f155d19b8b899ea657d6593913ac3","schema_fingerprint":"4aa3821a28b0b7c2400bc59aba4bcc0a76e971dadd19610d3ad38c768e124dc7","schema_version":"edge-lab-recorder.raw.v1","sequence":null,"source":"clob_market_ws"}
{"event_at":"2026-07-28T02:55:42.418000Z","event_fingerprint":"8a06050bc3c0e7ee7d3142763f2d3564a8bf13a7534ca482bddae1e18ee05827","payload":{"connection_id":"955646bd8bf740759faf38750c0f263f","event_at":"2026-07-28T02:55:42.418000Z","event_type":"price_change","frame_hash":"a751f6933117e72e819ebda4136f4bc092959c93ae0e107522d048f89f2c24bb","frame_index":0,"kind":"data","monotonic_ns":309326791535333,"payload":{"event_type":"price_change","market":"0x0f70d07969bc69eaa97d0987de651885fdca02263688026aa11e7678af8f87aa","price_changes":[{"asset_id":"58313761654877669244690227616056238030136603415514645252000528337391143520538","best_ask":"0.56","best_bid":"0.55","hash":"7bc588fd2d5ecd463c52ceeff681e1af47dcfe13","price":"0.55","side":"BUY","size":"138.22"},{"asset_id":"64053005904884194822931764831592250494815136296598204104072528088122126148949","best_ask":"0.45","best_bid":"0.44","hash":"cfe4ab248ea6e40d4505c23e1e646dd3290f1470","price":"0.45","side":"SELL","size":"138.22"}],"timestamp":"1785207342418"},"payload_hash":"a1cf6f23e9e58dc3d2c9e5bcbc40fd14e77a6c5c377f713b9a99c57e172015a4","raw_frame":"{\"market\":\"0x0f70d07969bc69eaa97d0987de651885fdca02263688026aa11e7678af8f87aa\", \"price_changes\":[{\"asset_id\":\"58313761654877669244690227616056238030136603415514645252000528337391143520538\", \"price\":\"0.55\", \"size\":\"138.22\", \"side\":\"BUY\", \"hash\":\"7bc588fd2d5ecd463c52ceeff681e1af47dcfe13\", \"best_bid\":\"0.55\", \"best_ask\":\"0.56\"}, {\"asset_id\":\"64053005904884194822931764831592250494815136296598204104072528088122126148949\", \"price\":\"0.45\", \"size\":\"138.22\", \"side\":\"SELL\", \"hash\":\"cfe4ab248ea6e40d4505c23e1e646dd3290f1470\", \"best_bid\":\"0.44\", \"best_ask\":\"0.45\"}], \"timestamp\":\"1785207342418\", \"event_type\":\"price_change\"}","received_at":"2026-07-28T02:55:43.775022Z","schema_version":"clob-market-ws.price_change.v1","sequence":null,"server_hash":null,"server_timestamp":"1785207342418","session_id":"5aad79be415c487c84df42bebd84ee93","source":"clob_market_ws"},"received_at":"2026-07-28T02:55:43.775022Z","record_id":"807cc0aaa5a6a0baeb3f3cb451ef5a3a64ca4def3a92ec3993c3145ba073db10","schema_fingerprint":"4aa3821a28b0b7c2400bc59aba4bcc0a76e971dadd19610d3ad38c768e124dc7","schema_version":"edge-lab-recorder.raw.v1","sequence":null,"source":"clob_market_ws"}
{"event_at":"2026-07-28T02:55:42.419000Z","event_fingerprint":"f3dc966cfa17cb2d02738144a584e6199b93a83485657672598d43f3c1754c5e","payload":{"connection_id":"955646bd8bf740759faf38750c0f263f","event_at":"2026-07-28T02:55:42.419000Z","event_type":"price_change","frame_hash":"02ecaa1ed7f4fb645f09cf9626babcdf48b6b48a4a2313ab3b04c8a24ad6c038","frame_index":0,"kind":"data","monotonic_ns":309326796106041,"payload":{"event_type":"price_change","market":"0x0f70d07969bc69eaa97d0987de651885fdca02263688026aa11e7678af8f87aa","price_changes":[{"asset_id":"58313761654877669244690227616056238030136603415514645252000528337391143520538","best_ask":"0.56","best_bid":"0.55","hash":"e1ef7e9310e126682c9053482c20802e62a68087","price":"0.01","side":"BUY","size":"2724.52"},{"asset_id":"64053005904884194822931764831592250494815136296598204104072528088122126148949","best_ask":"0.45","best_bid":"0.44","hash":"78857395816b7e985175c9d375527f32399115a0","price":"0.99","side":"SELL","size":"2724.52"}],"timestamp":"1785207342419"},"payload_hash":"d59b8a514e7984b5ea1e227ecf87c6451a72ea65b6b3f9aad781b89e63f866a6","raw_frame":"{\"market\":\"0x0f70d07969bc69eaa97d0987de651885fdca02263688026aa11e7678af8f87aa\", \"price_changes\":[{\"asset_id\":\"58313761654877669244690227616056238030136603415514645252000528337391143520538\", \"price\":\"0.01\", \"size\":\"2724.52\", \"side\":\"BUY\", \"hash\":\"e1ef7e9310e126682c9053482c20802e62a68087\", \"best_bid\":\"0.55\", \"best_ask\":\"0.56\"}, {\"asset_id\":\"64053005904884194822931764831592250494815136296598204104072528088122126148949\", \"price\":\"0.99\", \"size\":\"2724.52\", \"side\":\"SELL\", \"hash\":\"78857395816b7e985175c9d375527f32399115a0\", \"best_bid\":\"0.44\", \"best_ask\":\"0.45\"}], \"timestamp\":\"1785207342419\", \"event_type\":\"price_change\"}","received_at":"2026-07-28T02:55:43.779593Z","schema_version":"clob-market-ws.price_change.v1","sequence":null,"server_hash":null,"server_timestamp":"1785207342419","session_id":"5aad79be415c487c84df42bebd84ee93","source":"clob_market_ws"},"received_at":"2026-07-28T02:55:43.779593Z","record_id":"049717468ec7d8fde24c9a73bd72a11307af833f251b6edfcae2561dbb3a31ef","schema_fingerprint":"4aa3821a28b0b7c2400bc59aba4bcc0a76e971dadd19610d3ad38c768e124dc7","schema_version":"edge-lab-recorder.raw.v1","sequence":null,"source":"clob_market_ws"}
{"event_at":"2026-07-28T02:55:42.426000Z","event_fingerprint":"8397e96943ebcc7c8d62de1f140c3fa0f8794f2c122b648c25a74f1fa1d8984a","payload":{"connection_id":"955646bd8bf740759faf38750c0f263f","event_at":"2026-07-28T02:55:42.426000Z","event_type":"price_change","frame_hash":"367d2d5cbd1ecaf5a21585baba5a617c000b893dee781b7156b4f076547866fc","frame_index":0,"kind":"data","monotonic_ns":309326799378500,"payload":{"event_type":"price_change","market":"0x0f70d07969bc69eaa97d0987de651885fdca02263688026aa11e7678af8f87aa","price_changes":[{"asset_id":"64053005904884194822931764831592250494815136296598204104072528088122126148949","best_ask":"0.45","best_bid":"0.44","hash":"eb82654f7ea0b9613ff4d750313251e5f996d0b9","price":"0.41","side":"BUY","size":"89"},{"asset_id":"58313761654877669244690227616056238030136603415514645252000528337391143520538","best_ask":"0.56","best_bid":"0.55","hash":"b69c1e08e9764971ac628420f69dc25113d62970","price":"0.59","side":"SELL","size":"89"}],"timestamp":"1785207342426"},"payload_hash":"ef1d336eba59d161892df62de0a4387183fc3cfbb16e07c7c4582c4d4d85a81c","raw_frame":"{\"market\":\"0x0f70d07969bc69eaa97d0987de651885fdca02263688026aa11e7678af8f87aa\", \"price_changes\":[{\"asset_id\":\"64053005904884194822931764831592250494815136296598204104072528088122126148949\", \"price\":\"0.41\", \"size\":\"89\", \"side\":\"BUY\", \"hash\":\"eb82654f7ea0b9613ff4d750313251e5f996d0b9\", \"best_bid\":\"0.44\", \"best_ask\":\"0.45\"}, {\"asset_id\":\"58313761654877669244690227616056238030136603415514645252000528337391143520538\", \"price\":\"0.59\", \"size\":\"89\", \"side\":\"SELL\", \"hash\":\"b69c1e08e9764971ac628420f69dc25113d62970\", \"best_bid\":\"0.55\", \"best_ask\":\"0.56\"}], \"timestamp\":\"1785207342426\", \"event_type\":\"price_change\"}","received_at":"2026-07-28T02:55:43.782866Z","schema_version":"clob-market-ws.price_change.v1","sequence":null,"server_hash":null,"server_timestamp":"1785207342426","session_id":"5aad79be415c487c84df42bebd84ee93","source":"clob_market_ws"},"received_at":"2026-07-28T02:55:43.782866Z","record_id":"f3f6cfa6280ddd7a2ae7d2397e3224fdbbc041aeee10de53fcf95afe54c1cefe","schema_fingerprint":"4aa3821a28b0b7c2400bc59aba4bcc0a76e971dadd19610d3ad38c768e124dc7","schema_version":"edge-lab-recorder.raw.v1","sequence":null,"source":"clob_market_ws"}
{"event_at":"2026-07-28T02:55:42.431000Z","event_fingerprint":"2fd1e9cd26fb34d62965ec4806e2557c31aac6ad0198be5ee1d06e12336bfe30","payload":{"connection_id":"955646bd8bf740759faf38750c0f263f","event_at":"2026-07-28T02:55:42.431000Z","event_type":"price_change","frame_hash":"bffa889bc2c72047bc6db5ce79c1392c25443fd856a161abe60125bd24efa640","frame_index":0,"kind":"data","monotonic_ns":309326802685708,"payload":{"event_type":"price_change","market":"0x0f70d07969bc69eaa97d0987de651885fdca02263688026aa11e7678af8f87aa","price_changes":[{"asset_id":"64053005904884194822931764831592250494815136296598204104072528088122126148949","best_ask":"0.45","best_bid":"0.44","hash":"8365cc47b21256506e7502effe827cb337afd95e","price":"0.34","side":"BUY","size":"165.8"},{"asset_id":"58313761654877669244690227616056238030136603415514645252000528337391143520538","best_ask":"0.56","best_bid":"0.55","hash":"0f0581251d3589f54197e090d0b3fd9ab06f320d","price":"0.66","side":"SELL","size":"165.8"}],"timestamp":"1785207342431"},"payload_hash":"12bde430c947b5750f4cc942a19f481fa3c718f6da30f54256699b82d213515f","raw_frame":"{\"market\":\"0x0f70d07969bc69eaa97d0987de651885fdca02263688026aa11e7678af8f87aa\", \"price_changes\":[{\"asset_id\":\"64053005904884194822931764831592250494815136296598204104072528088122126148949\", \"price\":\"0.34\", \"size\":\"165.8\", \"side\":\"BUY\", \"hash\":\"8365cc47b21256506e7502effe827cb337afd95e\", \"best_bid\":\"0.44\", \"best_ask\":\"0.45\"}, {\"asset_id\":\"58313761654877669244690227616056238030136603415514645252000528337391143520538\", \"price\":\"0.66\", \"size\":\"165.8\", \"side\":\"SELL\", \"hash\":\"0f0581251d3589f54197e090d0b3fd9ab06f320d\", \"best_bid\":\"0.55\", \"best_ask\":\"0.56\"}], \"timestamp\":\"1785207342431\", \"event_type\":\"price_change\"}","received_at":"2026-07-28T02:55:43.786172Z","schema_version":"clob-market-ws.price_change.v1","sequence":null,"server_hash":null,"server_timestamp":"1785207342431","session_id":"5aad79be415c487c84df42bebd84ee93","source":"clob_market_ws"},"received_at":"2026-07-28T02:55:43.786172Z","record_id":"830c96c49eac62c34127d7947680cca9ebd64f86bb7e7dc1912c3e220ad216ac","schema_fingerprint":"4aa3821a28b0b7c2400bc59aba4bcc0a76e971dadd19610d3ad38c768e124dc7","schema_version":"edge-lab-recorder.raw.v1","sequence":null,"source":"clob_market_ws"}
{"event_at":"2026-07-28T02:55:42.431000Z","event_fingerprint":"8ebef15ba19682ba8825ea4f22d6ca180c6e276445916b700f4722812344efe3","payload":{"connection_id":"955646bd8bf740759faf38750c0f263f","event_at":"2026-07-28T02:55:42.431000Z","event_type":"price_change","frame_hash":"7d8229e5188109724f8dee9560635f6db2d1a1f7095691518961d257ea30de75","frame_index":0,"kind":"data","monotonic_ns":309326805843000,"payload":{"event_type":"price_change","market":"0x0f70d07969bc69eaa97d0987de651885fdca02263688026aa11e7678af8f87aa","price_changes":[{"asset_id":"64053005904884194822931764831592250494815136296598204104072528088122126148949","best_ask":"0.45","best_bid":"0.44","hash":"34ec092d5106ef7ae524740279de9d0d769dd164","price":"0.33","side":"BUY","size":"192.1"},{"asset_id":"58313761654877669244690227616056238030136603415514645252000528337391143520538","best_ask":"0.56","best_bid":"0.55","hash":"bfb45b331ce14ae0edb47557489347d86acef44d","price":"0.67","side":"SELL","size":"192.1"}],"timestamp":"1785207342431"},"payload_hash":"931cf277463eaf842ac78f574ff7ef1b6bee1a5fb1fe7befef81e7ec455c9271","raw_frame":"{\"market\":\"0x0f70d07969bc69eaa97d0987de651885fdca02263688026aa11e7678af8f87aa\", \"price_changes\":[{\"asset_id\":\"64053005904884194822931764831592250494815136296598204104072528088122126148949\", \"price\":\"0.33\", \"size\":\"192.1\", \"side\":\"BUY\", \"hash\":\"34ec092d5106ef7ae524740279de9d0d769dd164\", \"best_bid\":\"0.44\", \"best_ask\":\"0.45\"}, {\"asset_id\":\"58313761654877669244690227616056238030136603415514645252000528337391143520538\", \"price\":\"0.67\", \"size\":\"192.1\", \"side\":\"SELL\", \"hash\":\"bfb45b331ce14ae0edb47557489347d86acef44d\", \"best_bid\":\"0.55\", \"best_ask\":\"0.56\"}], \"timestamp\":\"1785207342431\", \"event_type\":\"price_change\"}","received_at":"2026-07-28T02:55:43.789328Z","schema_version":"clob-market-ws.price_change.v1","sequence":null,"server_hash":null,"server_timestamp":"1785207342431","session_id":"5aad79be415c487c84df42bebd84ee93","source":"clob_market_ws"},"received_at":"2026-07-28T02:55:43.789328Z","record_id":"1ee52c1db936402f8053053e58cf149b7ad28fcb465735a22eae28a68586b18c","schema_fingerprint":"4aa3821a28b0b7c2400bc59aba4bcc0a76e971dadd19610d3ad38c768e124dc7","schema_version":"edge-lab-recorder.raw.v1","sequence":null,"source":"clob_market_ws"}
{"event_at":"2026-07-28T02:55:42.432000Z","event_fingerprint":"72cbcfa1571414b36bb00f2fba739e31533745d7ffb9b4bbdb093ff7842c86d1","payload":{"connection_id":"955646bd8bf740759faf38750c0f263f","event_at":"2026-07-28T02:55:42.432000Z","event_type":"price_change","frame_hash":"78321b0194ac3606f3a60c023d3325a1d9874dc0b9a8f71a9aef848125529313","frame_index":0,"kind":"data","monotonic_ns":309326809070083,"payload":{"event_type":"price_change","market":"0x0f70d07969bc69eaa97d0987de651885fdca02263688026aa11e7678af8f87aa","price_changes":[{"asset_id":"64053005904884194822931764831592250494815136296598204104072528088122126148949","best_ask":"0.45","best_bid":"0.44","hash":"d97de55bbcb78fcc9077eb12f1c906100d318d7f","price":"0.44","side":"BUY","size":"98.58"},{"asset_id":"58313761654877669244690227616056238030136603415514645252000528337391143520538","best_ask":"0.56","best_bid":"0.55","hash":"4133adffc11f7d0e6e099b1700b2178aa4decb42","price":"0.56","side":"SELL","size":"98.58"}],"timestamp":"1785207342432"},"payload_hash":"8d3969d4d1fc7d8937ebed8453724bc4b6727a711cac4f8877ecc9e4ed7b4f32","raw_frame":"{\"market\":\"0x0f70d07969bc69eaa97d0987de651885fdca02263688026aa11e7678af8f87aa\", \"price_changes\":[{\"asset_id\":\"64053005904884194822931764831592250494815136296598204104072528088122126148949\", \"price\":\"0.44\", \"size\":\"98.58\", \"side\":\"BUY\", \"hash\":\"d97de55bbcb78fcc9077eb12f1c906100d318d7f\", \"best_bid\":\"0.44\", \"best_ask\":\"0.45\"}, {\"asset_id\":\"58313761654877669244690227616056238030136603415514645252000528337391143520538\", \"price\":\"0.56\", \"size\":\"98.58\", \"side\":\"SELL\", \"hash\":\"4133adffc11f7d0e6e099b1700b2178aa4decb42\", \"best_bid\":\"0.55\", \"best_ask\":\"0.56\"}], \"timestamp\":\"1785207342432\", \"event_type\":\"price_change\"}","received_at":"2026-07-28T02:55:43.792556Z","schema_version":"clob-market-ws.price_change.v1","sequence":null,"server_hash":null,"server_timestamp":"1785207342432","session_id":"5aad79be415c487c84df42bebd84ee93","source":"clob_market_ws"},"received_at":"2026-07-28T02:55:43.792556Z","record_id":"3f1093cc4bfacb46709c12a74e6eca1dc59e82a6f335e783c0b182a91aad4bf0","schema_fingerprint":"4aa3821a28b0b7c2400bc59aba4bcc0a76e971dadd19610d3ad38c768e124dc7","schema_version":"edge-lab-recorder.raw.v1","sequence":null,"source":"clob_market_ws"}
{"event_at":"2026-07-28T02:55:42.433000Z","event_fingerprint":"2abbe911e9776cd634c052e166482dc071224689a3f9eaa0fa99b04f826451d1","payload":{"connection_id":"955646bd8bf740759faf38750c0f263f","event_at":"2026-07-28T02:55:42.433000Z","event_type":"price_change","frame_hash":"49395ecc283f8bd9fce6182b83febfd89f2904a958c151d5998e3ee38894e40c","frame_index":0,"kind":"data","monotonic_ns":309326812264750,"payload":{"event_type":"price_change","market":"0x0f70d07969bc69eaa97d0987de651885fdca02263688026aa11e7678af8f87aa","price_changes":[{"asset_id":"58313761654877669244690227616056238030136603415514645252000528337391143520538","best_ask":"0.56","best_bid":"0.55","hash":"ae8ed8da16d3b52024c7394e2dbf965cc9da4e99","price":"0.55","side":"BUY","size":"128.22"},{"asset_id":"64053005904884194822931764831592250494815136296598204104072528088122126148949","best_ask":"0.45","best_bid":"0.44","hash":"587c1cc54c2979b9576969e87cb9a61a960ffea4","price":"0.45","side":"SELL","size":"128.22"}],"timestamp":"1785207342433"},"payload_hash":"2a8d778837a21d94ac15008ed58b7666263e9c97fefc2658193497510c0cbe67","raw_frame":"{\"market\":\"0x0f70d07969bc69eaa97d0987de651885fdca02263688026aa11e7678af8f87aa\", \"price_changes\":[{\"asset_id\":\"58313761654877669244690227616056238030136603415514645252000528337391143520538\", \"price\":\"0.55\", \"size\":\"128.22\", \"side\":\"BUY\", \"hash\":\"ae8ed8da16d3b52024c7394e2dbf965cc9da4e99\", \"best_bid\":\"0.55\", \"best_ask\":\"0.56\"}, {\"asset_id\":\"64053005904884194822931764831592250494815136296598204104072528088122126148949\", \"price\":\"0.45\", \"size\":\"128.22\", \"side\":\"SELL\", \"hash\":\"587c1cc54c2979b9576969e87cb9a61a960ffea4\", \"best_bid\":\"0.44\", \"best_ask\":\"0.45\"}], \"timestamp\":\"1785207342433\", \"event_type\":\"price_change\"}","received_at":"2026-07-28T02:55:43.795745Z","schema_version":"clob-market-ws.price_change.v1","sequence":null,"server_hash":null,"server_timestamp":"1785207342433","session_id":"5aad79be415c487c84df42bebd84ee93","source":"clob_market_ws"},"received_at":"2026-07-28T02:55:43.795745Z","record_id":"910421c9069246b6288a38e2e609177e935625677a7eaa9c410d85d315cb566b","schema_fingerprint":"4aa3821a28b0b7c2400bc59aba4bcc0a76e971dadd19610d3ad38c768e124dc7","schema_version":"edge-lab-recorder.raw.v1","sequence":null,"source":"clob_market_ws"}
{"event_at":"2026-07-28T02:55:42.434000Z","event_fingerprint":"a91abdb88894b41349d0e81017fcd8fa51ffff233f870eda189c84ca687cd59c","payload":{"connection_id":"955646bd8bf740759faf38750c0f263f","event_at":"2026-07-28T02:55:42.434000Z","event_type":"price_change","frame_hash":"2980b0cc550c006f3de261e31f217eed9a01d1b0dbae5efb4c4160c9f66e31bc","frame_index":0,"kind":"data","monotonic_ns":309326815437541,"payload":{"event_type":"price_change","market":"0x0f70d07969bc69eaa97d0987de651885fdca02263688026aa11e7678af8f87aa","price_changes":[{"asset_id":"64053005904884194822931764831592250494815136296598204104072528088122126148949","best_ask":"0.45","best_bid":"0.44","hash":"cb063f998c1aa2e0e165022a7b41b9396bed60e4","price":"0.33","side":"BUY","size":"203.9"},{"asset_id":"58313761654877669244690227616056238030136603415514645252000528337391143520538","best_ask":"0.56","best_bid":"0.55","hash":"019a065905359fc1ad202e2feae22a7e05b0868c","price":"0.67","side":"SELL","size":"203.9"}],"timestamp":"1785207342434"},"payload_hash":"9b8799a34fc9ae4f2542721f158800e6384c7edaa9023ea24a6dd5871ff9bc9f","raw_frame":"{\"market\":\"0x0f70d07969bc69eaa97d0987de651885fdca02263688026aa11e7678af8f87aa\", \"price_changes\":[{\"asset_id\":\"64053005904884194822931764831592250494815136296598204104072528088122126148949\", \"price\":\"0.33\", \"size\":\"203.9\", \"side\":\"BUY\", \"hash\":\"cb063f998c1aa2e0e165022a7b41b9396bed60e4\", \"best_bid\":\"0.44\", \"best_ask\":\"0.45\"}, {\"asset_id\":\"58313761654877669244690227616056238030136603415514645252000528337391143520538\", \"price\":\"0.67\", \"size\":\"203.9\", \"side\":\"SELL\", \"hash\":\"019a065905359fc1ad202e2feae22a7e05b0868c\", \"best_bid\":\"0.55\", \"best_ask\":\"0.56\"}], \"timestamp\":\"1785207342434\", \"event_type\":\"price_change\"}","received_at":"2026-07-28T02:55:43.798925Z","schema_version":"clob-market-ws.price_change.v1","sequence":null,"server_hash":null,"server_timestamp":"1785207342434","session_id":"5aad79be415c487c84df42bebd84ee93","source":"clob_market_ws"},"received_at":"2026-07-28T02:55:43.798925Z","record_id":"139499f79c0c64fef34e0c6dc24277d11781585ec8e98cc1e6819b5f870341ee","schema_fingerprint":"4aa3821a28b0b7c2400bc59aba4bcc0a76e971dadd19610d3ad38c768e124dc7","schema_version":"edge-lab-recorder.raw.v1","sequence":null,"source":"clob_market_ws"}
{"event_at":"2026-07-28T02:55:42.435000Z","event_fingerprint":"98ac8240753bc9458b820317e9f511ffea00640c184fb3688e6113818435178e","payload":{"connection_id":"955646bd8bf740759faf38750c0f263f","event_at":"2026-07-28T02:55:42.435000Z","event_type":"price_change","frame_hash":"5d1fba2ff29e77580c56df894a6c842b3a07ef70ebc624088635213c7992097b","frame_index":0,"kind":"data","monotonic_ns":309326818564291,"payload":{"event_type":"price_change","market":"0x0f70d07969bc69eaa97d0987de651885fdca02263688026aa11e7678af8f87aa","price_changes":[{"asset_id":"58313761654877669244690227616056238030136603415514645252000528337391143520538","best_ask":"0.56","best_bid":"0.55","hash":"32b517b6feaa1e9ad1553cc18f52e5023a41df99","price":"0.55","side":"BUY","size":"121.22"},{"asset_id":"64053005904884194822931764831592250494815136296598204104072528088122126148949","best_ask":"0.45","best_bid":"0.44","hash":"27470bd181359b8017433636d00ced686be61057","price":"0.45","side":"SELL","size":"121.22"}],"timestamp":"1785207342435"},"payload_hash":"78821b7b4c403aa7852e91237c63cb0b8c6b874a1efa9b8b09402a7a84723a53","raw_frame":"{\"market\":\"0x0f70d07969bc69eaa97d0987de651885fdca02263688026aa11e7678af8f87aa\", \"price_changes\":[{\"asset_id\":\"58313761654877669244690227616056238030136603415514645252000528337391143520538\", \"price\":\"0.55\", \"size\":\"121.22\", \"side\":\"BUY\", \"hash\":\"32b517b6feaa1e9ad1553cc18f52e5023a41df99\", \"best_bid\":\"0.55\", \"best_ask\":\"0.56\"}, {\"asset_id\":\"64053005904884194822931764831592250494815136296598204104072528088122126148949\", \"price\":\"0.45\", \"size\":\"121.22\", \"side\":\"SELL\", \"hash\":\"27470bd181359b8017433636d00ced686be61057\", \"best_bid\":\"0.44\", \"best_ask\":\"0.45\"}], \"timestamp\":\"1785207342435\", \"event_type\":\"price_change\"}","received_at":"2026-07-28T02:55:43.802051Z","schema_version":"clob-market-ws.price_change.v1","sequence":null,"server_hash":null,"server_timestamp":"1785207342435","session_id":"5aad79be415c487c84df42bebd84ee93","source":"clob_market_ws"},"received_at":"2026-07-28T02:55:43.802051Z","record_id":"f1b1cfa3e33d251e66d60b8ae8e93e32e6718cefbbe2584d0fc10b9edc6bd8a1","schema_fingerprint":"4aa3821a28b0b7c2400bc59aba4bcc0a76e971dadd19610d3ad38c768e124dc7","schema_version":"edge-lab-recorder.raw.v1","sequence":null,"source":"clob_market_ws"}
{"event_at":"2026-07-28T02:55:42.436000Z","event_fingerprint":"c152c0788445e5a747f0c9a7bdd0eafffefd110f978d2ec73b394126b56ba966","payload":{"connection_id":"955646bd8bf740759faf38750c0f263f","event_at":"2026-07-28T02:55:42.436000Z","event_type":"price_change","frame_hash":"061955066ce22a9cfc51a675bb2304156d26436c789d6c10b20ad7b0277cb42a","frame_index":0,"kind":"data","monotonic_ns":309326821690500,"payload":{"event_type":"price_change","market":"0x0f70d07969bc69eaa97d0987de651885fdca02263688026aa11e7678af8f87aa","price_changes":[{"asset_id":"64053005904884194822931764831592250494815136296598204104072528088122126148949","best_ask":"0.45","best_bid":"0.44","hash":"0ab1a66269837a08d4672b45301c77530f981199","price":"0.36","side":"BUY","size":"206.65"},{"asset_id":"58313761654877669244690227616056238030136603415514645252000528337391143520538","best_ask":"0.56","best_bid":"0.55","hash":"74aa9ab887afbc0d166d375b20dbba2f7d071dae","price":"0.64","side":"SELL","size":"206.65"}],"timestamp":"1785207342436"},"payload_hash":"eee5b92c5935e35aaf2403c29d34544e5716efb4fa5bb36e5ce5ed9681564f50","raw_frame":"{\"market\":\"0x0f70d07969bc69eaa97d0987de651885fdca02263688026aa11e7678af8f87aa\", \"price_changes\":[{\"asset_id\":\"64053005904884194822931764831592250494815136296598204104072528088122126148949\", \"price\":\"0.36\", \"size\":\"206.65\", \"side\":\"BUY\", \"hash\":\"0ab1a66269837a08d4672b45301c77530f981199\", \"best_bid\":\"0.44\", \"best_ask\":\"0.45\"}, {\"asset_id\":\"58313761654877669244690227616056238030136603415514645252000528337391143520538\", \"price\":\"0.64\", \"size\":\"206.65\", \"side\":\"SELL\", \"hash\":\"74aa9ab887afbc0d166d375b20dbba2f7d071dae\", \"best_bid\":\"0.55\", \"best_ask\":\"0.56\"}], \"timestamp\":\"1785207342436\", \"event_type\":\"price_change\"}","received_at":"2026-07-28T02:55:43.805177Z","schema_version":"clob-market-ws.price_change.v1","sequence":null,"server_hash":null,"server_timestamp":"1785207342436","session_id":"5aad79be415c487c84df42bebd84ee93","source":"clob_market_ws"},"received_at":"2026-07-28T02:55:43.805177Z","record_id":"ecd495410cd06a0f32111957e8ca963690bfebd84abef32c1ec239b43a0527ad","schema_fingerprint":"4aa3821a28b0b7c2400bc59aba4bcc0a76e971dadd19610d3ad38c768e124dc7","schema_version":"edge-lab-recorder.raw.v1","sequence":null,"source":"clob_market_ws"}
{"event_at":"2026-07-28T02:55:42.439000Z","event_fingerprint":"bbd2520c20259efce47a52fc31bf30d7fb82dbb76eba395828a444fae4ed99ea","payload":{"connection_id":"955646bd8bf740759faf38750c0f263f","event_at":"2026-07-28T02:55:42.439000Z","event_type":"price_change","frame_hash":"2d71a36f5bd67d26de21698722f797043f1302efc4346f7ea8b87d45dd3021e3","frame_index":0,"kind":"data","monotonic_ns":309326824716500,"payload":{"event_type":"price_change","market":"0x0f70d07969bc69eaa97d0987de651885fdca02263688026aa11e7678af8f87aa","price_changes":[{"asset_id":"64053005904884194822931764831592250494815136296598204104072528088122126148949","best_ask":"0.45","best_bid":"0.44","hash":"c709db39dcfdeebb97036c12bc7da9497eb0b4dc","price":"0.37","side":"BUY","size":"207.17"},{"asset_id":"58313761654877669244690227616056238030136603415514645252000528337391143520538","best_ask":"0.56","best_bid":"0.55","hash":"842bd54697c43685172324759bbb00c6ed80ba76","price":"0.63","side":"SELL","size":"207.17"}],"timestamp":"1785207342439"},"payload_hash":"dd1bf430213ad33e39758901dbb4a0be2c9d20cf4b1222f51698742ad5f57726","raw_frame":"{\"market\":\"0x0f70d07969bc69eaa97d0987de651885fdca02263688026aa11e7678af8f87aa\", \"price_changes\":[{\"asset_id\":\"64053005904884194822931764831592250494815136296598204104072528088122126148949\", \"price\":\"0.37\", \"size\":\"207.17\", \"side\":\"BUY\", \"hash\":\"c709db39dcfdeebb97036c12bc7da9497eb0b4dc\", \"best_bid\":\"0.44\", \"best_ask\":\"0.45\"}, {\"asset_id\":\"58313761654877669244690227616056238030136603415514645252000528337391143520538\", \"price\":\"0.63\", \"size\":\"207.17\", \"side\":\"SELL\", \"hash\":\"842bd54697c43685172324759bbb00c6ed80ba76\", \"best_bid\":\"0.55\", \"best_ask\":\"0.56\"}], \"timestamp\":\"1785207342439\", \"event_type\":\"price_change\"}","received_at":"2026-07-28T02:55:43.808202Z","schema_version":"clob-market-ws.price_change.v1","sequence":null,"server_hash":null,"server_timestamp":"1785207342439","session_id":"5aad79be415c487c84df42bebd84ee93","source":"clob_market_ws"},"received_at":"2026-07-28T02:55:43.808202Z","record_id":"e94cbc72554aab5f061e5b2677cf1c2ce9659312d84f6698e0ea64d93cdbcc7e","schema_fingerprint":"4aa3821a28b0b7c2400bc59aba4bcc0a76e971dadd19610d3ad38c768e124dc7","schema_version":"edge-lab-recorder.raw.v1","sequence":null,"source":"clob_market_ws"}
{"event_at":"2026-07-28T02:55:42.440000Z","event_fingerprint":"34c87ec528b366d75afa6ab95c9753734328f40113ad008eb901cb14c935f920","payload":{"connection_id":"955646bd8bf740759faf38750c0f263f","event_at":"2026-07-28T02:55:42.440000Z","event_type":"price_change","frame_hash":"f75e11f82cab592bcd731ff90506bef94a89a19042d89031ea7579401748b21c","frame_index":0,"kind":"data","monotonic_ns":309326827812541,"payload":{"event_type":"price_change","market":"0x0f70d07969bc69eaa97d0987de651885fdca02263688026aa11e7678af8f87aa","price_changes":[{"asset_id":"58313761654877669244690227616056238030136603415514645252000528337391143520538","best_ask":"0.56","best_bid":"0.55","hash":"bcfb62808d7cace75b715726d6a5007280288f26","price":"0.01","side":"BUY","size":"2719.52"},{"asset_id":"64053005904884194822931764831592250494815136296598204104072528088122126148949","best_ask":"0.45","best_bid":"0.44","hash":"96a37ffc72e2fad0443e40922d2c3687be40d273","price":"0.99","side":"SELL","size":"2719.52"}],"timestamp":"1785207342440"},"payload_hash":"0ea4f1bc4b643142b358668fce411caceae1906cbcbe441fb6281f2520a5788f","raw_frame":"{\"market\":\"0x0f70d07969bc69eaa97d0987de651885fdca02263688026aa11e7678af8f87aa\", \"price_changes\":[{\"asset_id\":\"58313761654877669244690227616056238030136603415514645252000528337391143520538\", \"price\":\"0.01\", \"size\":\"2719.52\", \"side\":\"BUY\", \"hash\":\"bcfb62808d7cace75b715726d6a5007280288f26\", \"best_bid\":\"0.55\", \"best_ask\":\"0.56\"}, {\"asset_id\":\"64053005904884194822931764831592250494815136296598204104072528088122126148949\", \"price\":\"0.99\", \"size\":\"2719.52\", \"side\":\"SELL\", \"hash\":\"96a37ffc72e2fad0443e40922d2c3687be40d273\", \"best_bid\":\"0.44\", \"best_ask\":\"0.45\"}], \"timestamp\":\"1785207342440\", \"event_type\":\"price_change\"}","received_at":"2026-07-28T02:55:43.811299Z","schema_version":"clob-market-ws.price_change.v1","sequence":null,"server_hash":null,"server_timestamp":"1785207342440","session_id":"5aad79be415c487c84df42bebd84ee93","source":"clob_market_ws"},"received_at":"2026-07-28T02:55:43.811299Z","record_id":"6b5ed297d2525b1413ba75ecdcb70cefa71355c8e0374eccc6f126c0bf27bb76","schema_fingerprint":"4aa3821a28b0b7c2400bc59aba4bcc0a76e971dadd19610d3ad38c768e124dc7","schema_version":"edge-lab-recorder.raw.v1","sequence":null,"source":"clob_market_ws"}
{"event_at":"2026-07-28T02:55:42.440000Z","event_fingerprint":"c60dc829aceab993f0ea32828c2af70f1b1ed0e025f4c5fb843c701637a401f2","payload":{"connection_id":"955646bd8bf740759faf38750c0f263f","event_at":"2026-07-28T02:55:42.440000Z","event_type":"price_change","frame_hash":"119ec559b693933b05d886d1467e92cedbbd2c1d941e97a473e8e167cee3bab4","frame_index":0,"kind":"data","monotonic_ns":309326830802458,"payload":{"event_type":"price_change","market":"0x0f70d07969bc69eaa97d0987de651885fdca02263688026aa11e7678af8f87aa","price_changes":[{"asset_id":"64053005904884194822931764831592250494815136296598204104072528088122126148949","best_ask":"0.45","best_bid":"0.44","hash":"6f4b798986ac128ddf39d43027002f8d3946b022","price":"0.38","side":"BUY","size":"219.64"},{"asset_id":"58313761654877669244690227616056238030136603415514645252000528337391143520538","best_ask":"0.56","best_bid":"0.55","hash":"064b0e1c4239841f7dd877ac9247539cc470dbd8","price":"0.62","side":"SELL","size":"219.64"}],"timestamp":"1785207342440"},"payload_hash":"4df1275bd0ee6c59372a33d0a9335a7d99fd36d21a66a6fcaae136bdaa3a6825","raw_frame":"{\"market\":\"0x0f70d07969bc69eaa97d0987de651885fdca02263688026aa11e7678af8f87aa\", \"price_changes\":[{\"asset_id\":\"64053005904884194822931764831592250494815136296598204104072528088122126148949\", \"price\":\"0.38\", \"size\":\"219.64\", \"side\":\"BUY\", \"hash\":\"6f4b798986ac128ddf39d43027002f8d3946b022\", \"best_bid\":\"0.44\", \"best_ask\":\"0.45\"}, {\"asset_id\":\"58313761654877669244690227616056238030136603415514645252000528337391143520538\", \"price\":\"0.62\", \"size\":\"219.64\", \"side\":\"SELL\", \"hash\":\"064b0e1c4239841f7dd877ac9247539cc470dbd8\", \"best_bid\":\"0.55\", \"best_ask\":\"0.56\"}], \"timestamp\":\"1785207342440\", \"event_type\":\"price_change\"}","received_at":"2026-07-28T02:55:43.814289Z","schema_version":"clob-market-ws.price_change.v1","sequence":null,"server_hash":null,"server_timestamp":"1785207342440","session_id":"5aad79be415c487c84df42bebd84ee93","source":"clob_market_ws"},"received_at":"2026-07-28T02:55:43.814289Z","record_id":"1992bd6743da738a1a990502a3be46bf16e8d8e3422571a1089a7f3cf43af0e5","schema_fingerprint":"4aa3821a28b0b7c2400bc59aba4bcc0a76e971dadd19610d3ad38c768e124dc7","schema_version":"edge-lab-recorder.raw.v1","sequence":null,"source":"clob_market_ws"}
{"event_at":"2026-07-28T02:55:42.441000Z","event_fingerprint":"60e5f4338c46b7a11ed9f62ee0772a49f85aa1751e7876929ea6bf7134943771","payload":{"connection_id":"955646bd8bf740759faf38750c0f263f","event_at":"2026-07-28T02:55:42.441000Z","event_type":"price_change","frame_hash":"a838d62734f746c6b0accc8332e8540fd931fccf3ba6157b874778b4c98e9de4","frame_index":0,"kind":"data","monotonic_ns":309326833913916,"payload":{"event_type":"price_change","market":"0x0f70d07969bc69eaa97d0987de651885fdca02263688026aa11e7678af8f87aa","price_changes":[{"asset_id":"64053005904884194822931764831592250494815136296598204104072528088122126148949","best_ask":"0.45","best_bid":"0.44","hash":"af412c5a71a606ea1e39160f3b15a0d0277ffc8e","price":"0.44","side":"BUY","size":"106.98"},{"asset_id":"58313761654877669244690227616056238030136603415514645252000528337391143520538","best_ask":"0.56","best_bid":"0.55","hash":"362c4c0b51fed9450d97ab4533e5e15871afd5ce","price":"0.56","side":"SELL","size":"106.98"}],"timestamp":"1785207342441"},"payload_hash":"0574a19f7ce172a3ce1748dce9b69db310316532d1ec5c8cb30b2bb59d2a00ed","raw_frame":"{\"market\":\"0x0f70d07969bc69eaa97d0987de651885fdca02263688026aa11e7678af8f87aa\", \"price_changes\":[{\"asset_id\":\"64053005904884194822931764831592250494815136296598204104072528088122126148949\", \"price\":\"0.44\", \"size\":\"106.98\", \"side\":\"BUY\", \"hash\":\"af412c5a71a606ea1e39160f3b15a0d0277ffc8e\", \"best_bid\":\"0.44\", \"best_ask\":\"0.45\"}, {\"asset_id\":\"58313761654877669244690227616056238030136603415514645252000528337391143520538\", \"price\":\"0.56\", \"size\":\"106.98\", \"side\":\"SELL\", \"hash\":\"362c4c0b51fed9450d97ab4533e5e15871afd5ce\", \"best_bid\":\"0.55\", \"best_ask\":\"0.56\"}], \"timestamp\":\"1785207342441\", \"event_type\":\"price_change\"}","received_at":"2026-07-28T02:55:43.817401Z","schema_version":"clob-market-ws.price_change.v1","sequence":null,"server_hash":null,"server_timestamp":"1785207342441","session_id":"5aad79be415c487c84df42bebd84ee93","source":"clob_market_ws"},"received_at":"2026-07-28T02:55:43.817401Z","record_id":"7332fd896f581c1352c9821bc5712b4690002178e9c91ae8c0724a3d2d30b1ca","schema_fingerprint":"4aa3821a28b0b7c2400bc59aba4bcc0a76e971dadd19610d3ad38c768e124dc7","schema_version":"edge-lab-recorder.raw.v1","sequence":null,"source":"clob_market_ws"}
{"event_at":"2026-07-28T02:55:42.441000Z","event_fingerprint":"67522923d1614f84f15489f2a5b3fdfb91532412b5376d532d33d942809a93ff","payload":{"connection_id":"955646bd8bf740759faf38750c0f263f","event_at":"2026-07-28T02:55:42.441000Z","event_type":"price_change","frame_hash":"1c8240bc00be586b6729c5103447273695c637bb20c60fdbb4cb1961fae4c92e","frame_index":0,"kind":"data","monotonic_ns":309326837047458,"payload":{"event_type":"price_change","market":"0x0f70d07969bc69eaa97d0987de651885fdca02263688026aa11e7678af8f87aa","price_changes":[{"asset_id":"58313761654877669244690227616056238030136603415514645252000528337391143520538","best_ask":"0.56","best_bid":"0.55","hash":"14cdca5be047e5e435e852763eb436bd3b874b5a","price":"0.51","side":"BUY","size":"325.98"},{"asset_id":"64053005904884194822931764831592250494815136296598204104072528088122126148949","best_ask":"0.45","best_bid":"0.44","hash":"d2c5bedbbaa4fb9c0ebcfdc053f414458bca1d5c","price":"0.49","side":"SELL","size":"325.98"}],"timestamp":"1785207342441"},"payload_hash":"d8623e631be140577efaca727e95e7ea83893816aa10ffab1ddc57f4a62d87d5","raw_frame":"{\"market\":\"0x0f70d07969bc69eaa97d0987de651885fdca02263688026aa11e7678af8f87aa\", \"price_changes\":[{\"asset_id\":\"58313761654877669244690227616056238030136603415514645252000528337391143520538\", \"price\":\"0.51\", \"size\":\"325.98\", \"side\":\"BUY\", \"hash\":\"14cdca5be047e5e435e852763eb436bd3b874b5a\", \"best_bid\":\"0.55\", \"best_ask\":\"0.56\"}, {\"asset_id\":\"64053005904884194822931764831592250494815136296598204104072528088122126148949\", \"price\":\"0.49\", \"size\":\"325.98\", \"side\":\"SELL\", \"hash\":\"d2c5bedbbaa4fb9c0ebcfdc053f414458bca1d5c\", \"best_bid\":\"0.44\", \"best_ask\":\"0.45\"}], \"timestamp\":\"1785207342441\", \"event_type\":\"price_change\"}","received_at":"2026-07-28T02:55:43.820528Z","schema_version":"clob-market-ws.price_change.v1","sequence":null,"server_hash":null,"server_timestamp":"1785207342441","session_id":"5aad79be415c487c84df42bebd84ee93","source":"clob_market_ws"},"received_at":"2026-07-28T02:55:43.820528Z","record_id":"130f60cd6e89b044e9e8d502f9571bd9f2544c88d45f9a1ba9c64397bb559de6","schema_fingerprint":"4aa3821a28b0b7c2400bc59aba4bcc0a76e971dadd19610d3ad38c768e124dc7","schema_version":"edge-lab-recorder.raw.v1","sequence":null,"source":"clob_market_ws"}
{"event_at":"2026-07-28T02:55:42.447000Z","event_fingerprint":"db347af86e839b3684c49e5d8f464e18e0183b4570cef57d3e514e91b3f9a9c5","payload":{"connection_id":"955646bd8bf740759faf38750c0f263f","event_at":"2026-07-28T02:55:42.447000Z","event_type":"price_change","frame_hash":"ad13f255ab492703475285807d55c56a2e0d3371769429f7280d5f2cbb399526","frame_index":0,"kind":"data","monotonic_ns":309326840147666,"payload":{"event_type":"price_change","market":"0x0f70d07969bc69eaa97d0987de651885fdca02263688026aa11e7678af8f87aa","price_changes":[{"asset_id":"64053005904884194822931764831592250494815136296598204104072528088122126148949","best_ask":"0.45","best_bid":"0.44","hash":"4d6338a6917022c8710c1c850c3531103b21076b","price":"0.35","side":"BUY","size":"164.6"},{"asset_id":"58313761654877669244690227616056238030136603415514645252000528337391143520538","best_ask":"0.56","best_bid":"0.55","hash":"60ed3a8c8d2daaab175e6172bae935b1ea5db934","price":"0.65","side":"SELL","size":"164.6"}],"timestamp":"1785207342447"},"payload_hash":"62f6ebfaeca8f82813f35afbb4ac3c582f20e69950197165e4996d2b6cdea004","raw_frame":"{\"market\":\"0x0f70d07969bc69eaa97d0987de651885fdca02263688026aa11e7678af8f87aa\", \"price_changes\":[{\"asset_id\":\"64053005904884194822931764831592250494815136296598204104072528088122126148949\", \"price\":\"0.35\", \"size\":\"164.6\", \"side\":\"BUY\", \"hash\":\"4d6338a6917022c8710c1c850c3531103b21076b\", \"best_bid\":\"0.44\", \"best_ask\":\"0.45\"}, {\"asset_id\":\"58313761654877669244690227616056238030136603415514645252000528337391143520538\", \"price\":\"0.65\", \"size\":\"164.6\", \"side\":\"SELL\", \"hash\":\"60ed3a8c8d2daaab175e6172bae935b1ea5db934\", \"best_bid\":\"0.55\", \"best_ask\":\"0.56\"}], \"timestamp\":\"1785207342447\", \"event_type\":\"price_change\"}","received_at":"2026-07-28T02:55:43.823634Z","schema_version":"clob-market-ws.price_change.v1","sequence":null,"server_hash":null,"server_timestamp":"1785207342447","session_id":"5aad79be415c487c84df42bebd84ee93","source":"clob_market_ws"},"received_at":"2026-07-28T02:55:43.823634Z","record_id":"f8d5a64b320bb272c29930e307ee2ad784136615abf06e673ac4e76a0f861a84","schema_fingerprint":"4aa3821a28b0b7c2400bc59aba4bcc0a76e971dadd19610d3ad38c768e124dc7","schema_version":"edge-lab-recorder.raw.v1","sequence":null,"source":"clob_market_ws"}
{"event_at":"2026-07-28T02:55:42.449000Z","event_fingerprint":"3ce317d25aa29797d0f618232252da4d3f073a3b061c38de84736ca4e580f609","payload":{"connection_id":"955646bd8bf740759faf38750c0f263f","event_at":"2026-07-28T02:55:42.449000Z","event_type":"price_change","frame_hash":"502964c997de09315f123d26a232e7cb5c4e3e6e5ccc590221c6141c7855d2a3","frame_index":0,"kind":"data","monotonic_ns":309326843219625,"payload":{"event_type":"price_change","market":"0x0f70d07969bc69eaa97d0987de651885fdca02263688026aa11e7678af8f87aa","price_changes":[{"asset_id":"64053005904884194822931764831592250494815136296598204104072528088122126148949","best_ask":"0.45","best_bid":"0.44","hash":"58e848e31db725032565113c4a99146b748947ae","price":"0.41","side":"BUY","size":"96"},{"asset_id":"58313761654877669244690227616056238030136603415514645252000528337391143520538","best_ask":"0.56","best_bid":"0.55","hash":"9736ef38b4981f1114b49c89620f70a182437d63","price":"0.59","side":"SELL","size":"96"}],"timestamp":"1785207342449"},"payload_hash":"ec0a5adde6ae516be2edad177de5ccc8a957a6ac432f55212a43fd811d8763a2","raw_frame":"{\"market\":\"0x0f70d07969bc69eaa97d0987de651885fdca02263688026aa11e7678af8f87aa\", \"price_changes\":[{\"asset_id\":\"64053005904884194822931764831592250494815136296598204104072528088122126148949\", \"price\":\"0.41\", \"size\":\"96\", \"side\":\"BUY\", \"hash\":\"58e848e31db725032565113c4a99146b748947ae\", \"best_bid\":\"0.44\", \"best_ask\":\"0.45\"}, {\"asset_id\":\"58313761654877669244690227616056238030136603415514645252000528337391143520538\", \"price\":\"0.59\", \"size\":\"96\", \"side\":\"SELL\", \"hash\":\"9736ef38b4981f1114b49c89620f70a182437d63\", \"best_bid\":\"0.55\", \"best_ask\":\"0.56\"}], \"timestamp\":\"1785207342449\", \"event_type\":\"price_change\"}","received_at":"2026-07-28T02:55:43.826706Z","schema_version":"clob-market-ws.price_change.v1","sequence":null,"server_hash":null,"server_timestamp":"1785207342449","session_id":"5aad79be415c487c84df42bebd84ee93","source":"clob_market_ws"},"received_at":"2026-07-28T02:55:43.826706Z","record_id":"5b8bab02dc8ed371ca3785521611eb4fb4bdedee1bbf225991ddba35a0ce1447","schema_fingerprint":"4aa3821a28b0b7c2400bc59aba4bcc0a76e971dadd19610d3ad38c768e124dc7","schema_version":"edge-lab-recorder.raw.v1","sequence":null,"source":"clob_market_ws"}
{"event_at":"2026-07-28T02:55:42.464000Z","event_fingerprint":"b48226e4d7f383e93a65243973a7700e73af4b3cb300e9ca392818a8fc0f13ca","payload":{"connection_id":"955646bd8bf740759faf38750c0f263f","event_at":"2026-07-28T02:55:42.464000Z","event_type":"price_change","frame_hash":"73b33aa004c1b75c361a0a5fe9b5437adcf266c8040bc7f7be3c7eb50449409b","frame_index":0,"kind":"data","monotonic_ns":309326846269541,"payload":{"event_type":"price_change","market":"0x0f70d07969bc69eaa97d0987de651885fdca02263688026aa11e7678af8f87aa","price_changes":[{"asset_id":"58313761654877669244690227616056238030136603415514645252000528337391143520538","best_ask":"0.56","best_bid":"0.55","hash":"e26e5a630a343c6737fd0a8025ae6b55aee1d4f4","price":"0.55","side":"BUY","size":"128.22"},{"asset_id":"64053005904884194822931764831592250494815136296598204104072528088122126148949","best_ask":"0.45","best_bid":"0.44","hash":"15977f4aebd374d1b9576caa967832f7294b2e52","price":"0.45","side":"SELL","size":"128.22"}],"timestamp":"1785207342464"},"payload_hash":"de355e96dc42f8692d9d10015ed722a5eeb6d44768be909c3fc78d5806f306de","raw_frame":"{\"market\":\"0x0f70d07969bc69eaa97d0987de651885fdca02263688026aa11e7678af8f87aa\", \"price_changes\":[{\"asset_id\":\"58313761654877669244690227616056238030136603415514645252000528337391143520538\", \"price\":\"0.55\", \"size\":\"128.22\", \"side\":\"BUY\", \"hash\":\"e26e5a630a343c6737fd0a8025ae6b55aee1d4f4\", \"best_bid\":\"0.55\", \"best_ask\":\"0.56\"}, {\"asset_id\":\"64053005904884194822931764831592250494815136296598204104072528088122126148949\", \"price\":\"0.45\", \"size\":\"128.22\", \"side\":\"SELL\", \"hash\":\"15977f4aebd374d1b9576caa967832f7294b2e52\", \"best_bid\":\"0.44\", \"best_ask\":\"0.45\"}], \"timestamp\":\"1785207342464\", \"event_type\":\"price_change\"}","received_at":"2026-07-28T02:55:43.829754Z","schema_version":"clob-market-ws.price_change.v1","sequence":null,"server_hash":null,"server_timestamp":"1785207342464","session_id":"5aad79be415c487c84df42bebd84ee93","source":"clob_market_ws"},"received_at":"2026-07-28T02:55:43.829754Z","record_id":"22466c7346edc3db0767f0e075bb8a6749fb203282c160e011527e5f52e61ea6","schema_fingerprint":"4aa3821a28b0b7c2400bc59aba4bcc0a76e971dadd19610d3ad38c768e124dc7","schema_version":"edge-lab-recorder.raw.v1","sequence":null,"source":"clob_market_ws"}
{"event_at":"2026-07-28T02:55:42.465000Z","event_fingerprint":"e52a4c64ec2284efa30db4af86d1843e49210804f4077a7b02c0e008cb1cd3fb","payload":{"connection_id":"955646bd8bf740759faf38750c0f263f","event_at":"2026-07-28T02:55:42.465000Z","event_type":"price_change","frame_hash":"1647399d69f7e789744efd23b5b09892a7c1c49840b459df9e04242db9662bfe","frame_index":0,"kind":"data","monotonic_ns":309326849411000,"payload":{"event_type":"price_change","market":"0x0f70d07969bc69eaa97d0987de651885fdca02263688026aa11e7678af8f87aa","price_changes":[{"asset_id":"64053005904884194822931764831592250494815136296598204104072528088122126148949","best_ask":"0.45","best_bid":"0.44","hash":"af92f0532bc442b38f3d34b95f9661b19a0d8cc7","price":"0.41","side":"BUY","size":"89"},{"asset_id":"58313761654877669244690227616056238030136603415514645252000528337391143520538","best_ask":"0.56","best_bid":"0.55","hash":"88265d3cc4a3eda4573e2cce5601911ed437e822","price":"0.59","side":"SELL","size":"89"}],"timestamp":"1785207342465"},"payload_hash":"99b10a5434f8dd85222ea120d42b5f4327b6fa4d4eefdda30f4e76691f32730e","raw_frame":"{\"market\":\"0x0f70d07969bc69eaa97d0987de651885fdca02263688026aa11e7678af8f87aa\", \"price_changes\":[{\"asset_id\":\"64053005904884194822931764831592250494815136296598204104072528088122126148949\", \"price\":\"0.41\", \"size\":\"89\", \"side\":\"BUY\", \"hash\":\"af92f0532bc442b38f3d34b95f9661b19a0d8cc7\", \"best_bid\":\"0.44\", \"best_ask\":\"0.45\"}, {\"asset_id\":\"58313761654877669244690227616056238030136603415514645252000528337391143520538\", \"price\":\"0.59\", \"size\":\"89\", \"side\":\"SELL\", \"hash\":\"88265d3cc4a3eda4573e2cce5601911ed437e822\", \"best_bid\":\"0.55\", \"best_ask\":\"0.56\"}], \"timestamp\":\"1785207342465\", \"event_type\":\"price_change\"}","received_at":"2026-07-28T02:55:43.832897Z","schema_version":"clob-market-ws.price_change.v1","sequence":null,"server_hash":null,"server_timestamp":"1785207342465","session_id":"5aad79be415c487c84df42bebd84ee93","source":"clob_market_ws"},"received_at":"2026-07-28T02:55:43.832897Z","record_id":"52a20b7b342ae531fae7862092d2a0221af8f870f276912a9fe2cb17453c9100","schema_fingerprint":"4aa3821a28b0b7c2400bc59aba4bcc0a76e971dadd19610d3ad38c768e124dc7","schema_version":"edge-lab-recorder.raw.v1","sequence":null,"source":"clob_market_ws"}
{"event_at":"2026-07-28T02:55:42.466000Z","event_fingerprint":"177c7b7df709b5434b1a27620d04e513fcd20712c071e0e76f7604badce10305","payload":{"connection_id":"955646bd8bf740759faf38750c0f263f","event_at":"2026-07-28T02:55:42.466000Z","event_type":"price_change","frame_hash":"bbfe498e76e6270fc274d374210e72e09f5559a2b8f6b23e355dfc92c30cde3a","frame_index":0,"kind":"data","monotonic_ns":309326852536500,"payload":{"event_type":"price_change","market":"0x0f70d07969bc69eaa97d0987de651885fdca02263688026aa11e7678af8f87aa","price_changes":[{"asset_id":"58313761654877669244690227616056238030136603415514645252000528337391143520538","best_ask":"0.56","best_bid":"0.55","hash":"4b3eee921f68d255bf402f4a5088fdde1dca684e","price":"0.01","side":"BUY","size":"2724.52"},{"asset_id":"64053005904884194822931764831592250494815136296598204104072528088122126148949","best_ask":"0.45","best_bid":"0.44","hash":"a0acbb9258a683708861950c1014e441e41fc854","price":"0.99","side":"SELL","size":"2724.52"}],"timestamp":"1785207342466"},"payload_hash":"fda28bee71ea9ab13ed59c2d37dc3c741c26f912938ece45a56927635e5dce3f","raw_frame":"{\"market\":\"0x0f70d07969bc69eaa97d0987de651885fdca02263688026aa11e7678af8f87aa\", \"price_changes\":[{\"asset_id\":\"58313761654877669244690227616056238030136603415514645252000528337391143520538\", \"price\":\"0.01\", \"size\":\"2724.52\", \"side\":\"BUY\", \"hash\":\"4b3eee921f68d255bf402f4a5088fdde1dca684e\", \"best_bid\":\"0.55\", \"best_ask\":\"0.56\"}, {\"asset_id\":\"64053005904884194822931764831592250494815136296598204104072528088122126148949\", \"price\":\"0.99\", \"size\":\"2724.52\", \"side\":\"SELL\", \"hash\":\"a0acbb9258a683708861950c1014e441e41fc854\", \"best_bid\":\"0.44\", \"best_ask\":\"0.45\"}], \"timestamp\":\"1785207342466\", \"event_type\":\"price_change\"}","received_at":"2026-07-28T02:55:43.836022Z","schema_version":"clob-market-ws.price_change.v1","sequence":null,"server_hash":null,"server_timestamp":"1785207342466","session_id":"5aad79be415c487c84df42bebd84ee93","source":"clob_market_ws"},"received_at":"2026-07-28T02:55:43.836022Z","record_id":"07a40ddd9a1b3fbced8743cb1b1c4f06b96a0c9355d12756816a9c99a19f8bbb","schema_fingerprint":"4aa3821a28b0b7c2400bc59aba4bcc0a76e971dadd19610d3ad38c768e124dc7","schema_version":"edge-lab-recorder.raw.v1","sequence":null,"source":"clob_market_ws"}
{"event_at":"2026-07-28T02:55:42.473000Z","event_fingerprint":"4af0a74d2ffd937157247486267283472ffe224c5f6ca3f75e32d29e05435862","payload":{"connection_id":"955646bd8bf740759faf38750c0f263f","event_at":"2026-07-28T02:55:42.473000Z","event_type":"price_change","frame_hash":"383de9cb71b92a0ed47ee4591e1d6e7b4a7c0ed1ced4e97ebf195293e75eea6d","frame_index":0,"kind":"data","monotonic_ns":309326854666583,"payload":{"event_type":"price_change","market":"0x0f70d07969bc69eaa97d0987de651885fdca02263688026aa11e7678af8f87aa","price_changes":[{"asset_id":"64053005904884194822931764831592250494815136296598204104072528088122126148949","best_ask":"0.45","best_bid":"0.44","hash":"f7bd4402a57eb1a8e0ad4b47280147f7fc64cd2e","price":"0.39","side":"BUY","size":"287.17"},{"asset_id":"58313761654877669244690227616056238030136603415514645252000528337391143520538","best_ask":"0.56","best_bid":"0.55","hash":"ed7ccc9c19564e32652a3791d451ea151e744120","price":"0.61","side":"SELL","size":"287.17"}],"timestamp":"1785207342473"},"payload_hash":"af2ddff017e3f7099fe6290b95e6caf1d99ea1d443bb75d9e24a3789c10ae714","raw_frame":"{\"market\":\"0x0f70d07969bc69eaa97d0987de651885fdca02263688026aa11e7678af8f87aa\", \"price_changes\":[{\"asset_id\":\"64053005904884194822931764831592250494815136296598204104072528088122126148949\", \"price\":\"0.39\", \"size\":\"287.17\", \"side\":\"BUY\", \"hash\":\"f7bd4402a57eb1a8e0ad4b47280147f7fc64cd2e\", \"best_bid\":\"0.44\", \"best_ask\":\"0.45\"}, {\"asset_id\":\"58313761654877669244690227616056238030136603415514645252000528337391143520538\", \"price\":\"0.61\", \"size\":\"287.17\", \"side\":\"SELL\", \"hash\":\"ed7ccc9c19564e32652a3791d451ea151e744120\", \"best_bid\":\"0.55\", \"best_ask\":\"0.56\"}], \"timestamp\":\"1785207342473\", \"event_type\":\"price_change\"}","received_at":"2026-07-28T02:55:43.838155Z","schema_version":"clob-market-ws.price_change.v1","sequence":null,"server_hash":null,"server_timestamp":"1785207342473","session_id":"5aad79be415c487c84df42bebd84ee93","source":"clob_market_ws"},"received_at":"2026-07-28T02:55:43.838155Z","record_id":"7fc4d39b0e7f39aa7865a31c65dfc6b3749becb71b849f31896d8d3ab0d90f0b","schema_fingerprint":"4aa3821a28b0b7c2400bc59aba4bcc0a76e971dadd19610d3ad38c768e124dc7","schema_version":"edge-lab-recorder.raw.v1","sequence":null,"source":"clob_market_ws"}
