{"event_at":"2026-07-28T02:57:45.821000Z","event_fingerprint":"f1e2eba5ade00eb5c341572c0575e38b893376073fecdd11edb460ff79de57d9","payload":{"connection_id":"955646bd8bf740759faf38750c0f263f","event_at":"2026-07-28T02:57:45.821000Z","event_type":"price_change","frame_hash":"99aeb1495e02cdcf1d2cba3f2455fdd5aa2340a5fa042b1dfeb9f7b4dca694a2","frame_index":0,"kind":"data","monotonic_ns":309449046147583,"payload":{"event_type":"price_change","market":"0x0f70d07969bc69eaa97d0987de651885fdca02263688026aa11e7678af8f87aa","price_changes":[{"asset_id":"64053005904884194822931764831592250494815136296598204104072528088122126148949","best_ask":"0.47","best_bid":"0.45","hash":"a4ad5af155cf72e6cdd8a803461326b7dd9238b8","price":"0.42","side":"BUY","size":"33.95"},{"asset_id":"58313761654877669244690227616056238030136603415514645252000528337391143520538","best_ask":"0.55","best_bid":"0.53","hash":"edb380d9f0ca13db4a78bf58d4472386914fe45c","price":"0.58","side":"SELL","size":"33.95"}],"timestamp":"1785207465821"},"payload_hash":"26c6c923402ae37e0a797a4f1c60108e83da2702a2c8e83042199eb727af91ac","raw_frame":"{\"market\":\"0x0f70d07969bc69eaa97d0987de651885fdca02263688026aa11e7678af8f87aa\", \"price_changes\":[{\"asset_id\":\"64053005904884194822931764831592250494815136296598204104072528088122126148949\", \"price\":\"0.42\", \"size\":\"33.95\", \"side\":\"BUY\", \"hash\":\"a4ad5af155cf72e6cdd8a803461326b7dd9238b8\", \"best_bid\":\"0.45\", \"best_ask\":\"0.47\"}, {\"asset_id\":\"58313761654877669244690227616056238030136603415514645252000528337391143520538\", \"price\":\"0.58\", \"size\":\"33.95\", \"side\":\"SELL\", \"hash\":\"edb380d9f0ca13db4a78bf58d4472386914fe45c\", \"best_bid\":\"0.53\", \"best_ask\":\"0.55\"}], \"timestamp\":\"1785207465821\", \"event_type\":\"price_change\"}","received_at":"2026-07-28T02:57:46.028751Z","schema_version":"clob-market-ws.price_change.v1","sequence":null,"server_hash":null,"server_timestamp":"1785207465821","session_id":"5aad79be415c487c84df42bebd84ee93","source":"clob_market_ws"},"received_at":"2026-07-28T02:57:46.028751Z","record_id":"a297ca102d2b756fa89146632f98f1dad9a6d8dd78d25333554a85c0bb7b1ca3","schema_fingerprint":"4aa3821a28b0b7c2400bc59aba4bcc0a76e971dadd19610d3ad38c768e124dc7","schema_version":"edge-lab-recorder.raw.v1","sequence":null,"source":"clob_market_ws"}
{"event_at":"2026-07-28T02:57:45.821000Z","event_fingerprint":"5735df65bc6f2d76aa23fa747bb948df855306dab097e5f633b4052c5bf6a3cb","payload":{"connection_id":"955646bd8bf740759faf38750c0f263f","event_at":"2026-07-28T02:57:45.821000Z","event_type":"price_change","frame_hash":"48b3a1c467053fda465fe62e8132205706223d3e28027faa731bf1912103b4ff","frame_index":0,"kind":"data","monotonic_ns":309449048216583,"payload":{"event_type":"price_change","market":"0x0f70d07969bc69eaa97d0987de651885fdca02263688026aa11e7678af8f87aa","price_changes":[{"asset_id":"58313761654877669244690227616056238030136603415514645252000528337391143520538","best_ask":"0.55","best_bid":"0.53","hash":"3a73c4c26945d0b9aa481af7af7ed0ee983c4283","price":"0.52","side":"BUY","size":"94.3"},{"asset_id":"64053005904884194822931764831592250494815136296598204104072528088122126148949","best_ask":"0.47","best_bid":"0.45","hash":"47f36701753cf09418273bb95671e9e5b18409b2","price":"0.48","side":"SELL","size":"94.3"}],"timestamp":"1785207465821"},"payload_hash":"3a4e1297df374adf840d6794cdf20d14a68e561c8f772c5e0aaf6dc45fc25135","raw_frame":"{\"market\":\"0x0f70d07969bc69eaa97d0987de651885fdca02263688026aa11e7678af8f87aa\", \"price_changes\":[{\"asset_id\":\"58313761654877669244690227616056238030136603415514645252000528337391143520538\", \"price\":\"0.52\", \"size\":\"94.3\", \"side\":\"BUY\", \"hash\":\"3a73c4c26945d0b9aa481af7af7ed0ee983c4283\", \"best_bid\":\"0.53\", \"best_ask\":\"0.55\"}, {\"asset_id\":\"64053005904884194822931764831592250494815136296598204104072528088122126148949\", \"price\":\"0.48\", \"size\":\"94.3\", \"side\":\"SELL\", \"hash\":\"47f36701753cf09418273bb95671e9e5b18409b2\", \"best_bid\":\"0.45\", \"best_ask\":\"0.47\"}], \"timestamp\":\"1785207465821\", \"event_type\":\"price_change\"}","received_at":"2026-07-28T02:57:46.030820Z","schema_version":"clob-market-ws.price_change.v1","sequence":null,"server_hash":null,"server_timestamp":"1785207465821","session_id":"5aad79be415c487c84df42bebd84ee93","source":"clob_market_ws"},"received_at":"2026-07-28T02:57:46.030820Z","record_id":"b3f75220a4003d80a2ede82c9d3ffb1966c48b9d2562f0c0fa4d6d1b91dea119","schema_fingerprint":"4aa3821a28b0b7c2400bc59aba4bcc0a76e971dadd19610d3ad38c768e124dc7","schema_version":"edge-lab-recorder.raw.v1","sequence":null,"source":"clob_market_ws"}
{"event_at":"2026-07-28T02:57:45.822000Z","event_fingerprint":"b2c96824c424c82be317446bc7e665ce8229ccc6889c5ab20a487d4dace5a5ba","payload":{"connection_id":"955646bd8bf740759faf38750c0f263f","event_at":"2026-07-28T02:57:45.822000Z","event_type":"price_change","frame_hash":"76c1a4dc9edeb20834d46e257a1124e904f2f0bbae85d1d2deaa403e01b80039","frame_index":0,"kind":"data","monotonic_ns":309449049745125,"payload":{"event_type":"price_change","market":"0x0f70d07969bc69eaa97d0987de651885fdca02263688026aa11e7678af8f87aa","price_changes":[{"asset_id":"64053005904884194822931764831592250494815136296598204104072528088122126148949","best_ask":"0.47","best_bid":"0.45","hash":"5fb6b0898747c5a3108f179bb77664ee6d0a12f9","price":"0.42","side":"BUY","size":"28.95"},{"asset_id":"58313761654877669244690227616056238030136603415514645252000528337391143520538","best_ask":"0.55","best_bid":"0.53","hash":"e970a7ff56f177e29f470b9a2fc2f5c886fde1a4","price":"0.58","side":"SELL","size":"28.95"}],"timestamp":"1785207465822"},"payload_hash":"566f680c6ffc116d2b8fc5d32edc1f573693d17a3d8864e2f4de3d192df7223c","raw_frame":"{\"market\":\"0x0f70d07969bc69eaa97d0987de651885fdca02263688026aa11e7678af8f87aa\", \"price_changes\":[{\"asset_id\":\"64053005904884194822931764831592250494815136296598204104072528088122126148949\", \"price\":\"0.42\", \"size\":\"28.95\", \"side\":\"BUY\", \"hash\":\"5fb6b0898747c5a3108f179bb77664ee6d0a12f9\", \"best_bid\":\"0.45\", \"best_ask\":\"0.47\"}, {\"asset_id\":\"58313761654877669244690227616056238030136603415514645252000528337391143520538\", \"price\":\"0.58\", \"size\":\"28.95\", \"side\":\"SELL\", \"hash\":\"e970a7ff56f177e29f470b9a2fc2f5c886fde1a4\", \"best_bid\":\"0.53\", \"best_ask\":\"0.55\"}], \"timestamp\":\"1785207465822\", \"event_type\":\"price_change\"}","received_at":"2026-07-28T02:57:46.032349Z","schema_version":"clob-market-ws.price_change.v1","sequence":null,"server_hash":null,"server_timestamp":"1785207465822","session_id":"5aad79be415c487c84df42bebd84ee93","source":"clob_market_ws"},"received_at":"2026-07-28T02:57:46.032349Z","record_id":"da10e0d5a88af5376d5f75c86ecf689c70b8e09e04a5496d9f1d26f57fa8560f","schema_fingerprint":"4aa3821a28b0b7c2400bc59aba4bcc0a76e971dadd19610d3ad38c768e124dc7","schema_version":"edge-lab-recorder.raw.v1","sequence":null,"source":"clob_market_ws"}
{"event_at":"2026-07-28T02:57:45.822000Z","event_fingerprint":"62c3ec6519ce40c131d493dee00b28972562845bbda60364a901a58fd5a4ce0c","payload":{"connection_id":"955646bd8bf740759faf38750c0f263f","event_at":"2026-07-28T02:57:45.822000Z","event_type":"price_change","frame_hash":"0f53ca891acc2a338ca914ba7dd24a8fe66e840c5a5bbb1253270e1507635007","frame_index":0,"kind":"data","monotonic_ns":309449051255875,"payload":{"event_type":"price_change","market":"0x0f70d07969bc69eaa97d0987de651885fdca02263688026aa11e7678af8f87aa","price_changes":[{"asset_id":"64053005904884194822931764831592250494815136296598204104072528088122126148949","best_ask":"0.47","best_bid":"0.45","hash":"09691efa64f2dd9c116062f4317f9a8bfb762d4f","price":"0.42","side":"BUY","size":"22.95"},{"asset_id":"58313761654877669244690227616056238030136603415514645252000528337391143520538","best_ask":"0.55","best_bid":"0.53","hash":"75e2ecdfc67479ec6c9f59c06ed1ad921fe3a688","price":"0.58","side":"SELL","size":"22.95"}],"timestamp":"1785207465822"},"payload_hash":"3e12399e9d8997ff098a7a760b3a691f7fda2b4a2fb7bf39c8461ecf63b7c307","raw_frame":"{\"market\":\"0x0f70d07969bc69eaa97d0987de651885fdca02263688026aa11e7678af8f87aa\", \"price_changes\":[{\"asset_id\":\"64053005904884194822931764831592250494815136296598204104072528088122126148949\", \"price\":\"0.42\", \"size\":\"22.95\", \"side\":\"BUY\", \"hash\":\"09691efa64f2dd9c116062f4317f9a8bfb762d4f\", \"best_bid\":\"0.45\", \"best_ask\":\"0.47\"}, {\"asset_id\":\"58313761654877669244690227616056238030136603415514645252000528337391143520538\", \"price\":\"0.58\", \"size\":\"22.95\", \"side\":\"SELL\", \"hash\":\"75e2ecdfc67479ec6c9f59c06ed1ad921fe3a688\", \"best_bid\":\"0.53\", \"best_ask\":\"0.55\"}], \"timestamp\":\"1785207465822\", \"event_type\":\"price_change\"}","received_at":"2026-07-28T02:57:46.033860Z","schema_version":"clob-market-ws.price_change.v1","sequence":null,"server_hash":null,"server_timestamp":"1785207465822","session_id":"5aad79be415c487c84df42bebd84ee93","source":"clob_market_ws"},"received_at":"2026-07-28T02:57:46.033860Z","record_id":"26492c2ead976af4a57717d9f2100f69d7d1b96a7226b71aafdb3a951587b09d","schema_fingerprint":"4aa3821a28b0b7c2400bc59aba4bcc0a76e971dadd19610d3ad38c768e124dc7","schema_version":"edge-lab-recorder.raw.v1","sequence":null,"source":"clob_market_ws"}
{"event_at":"2026-07-28T02:57:45.823000Z","event_fingerprint":"20ce2e4a628dd898365e967b95e1ae60d4d58a883c50e866695f2f4c53c31a0c","payload":{"connection_id":"955646bd8bf740759faf38750c0f263f","event_at":"2026-07-28T02:57:45.823000Z","event_type":"price_change","frame_hash":"58da7a74f41857fb7c8ba3419628a0d571a6d2f8cb96876974321aa74a2de3ae","frame_index":0,"kind":"data","monotonic_ns":309449052741166,"payload":{"event_type":"price_change","market":"0x0f70d07969bc69eaa97d0987de651885fdca02263688026aa11e7678af8f87aa","price_changes":[{"asset_id":"64053005904884194822931764831592250494815136296598204104072528088122126148949","best_ask":"0.47","best_bid":"0.45","hash":"3fb01c36d48830b9aa1e0ad22bf46d34e42b6809","price":"0.23","side":"BUY","size":"111.99"},{"asset_id":"58313761654877669244690227616056238030136603415514645252000528337391143520538","best_ask":"0.55","best_bid":"0.53","hash":"6a3f58b6b975138e20765bab20beea779698fceb","price":"0.77","side":"SELL","size":"111.99"}],"timestamp":"1785207465823"},"payload_hash":"63e95a127ad9f2abe6b177e35b36ded02afd8485c80ee5d44e2029f6a9a20f50","raw_frame":"{\"market\":\"0x0f70d07969bc69eaa97d0987de651885fdca02263688026aa11e7678af8f87aa\", \"price_changes\":[{\"asset_id\":\"64053005904884194822931764831592250494815136296598204104072528088122126148949\", \"price\":\"0.23\", \"size\":\"111.99\", \"side\":\"BUY\", \"hash\":\"3fb01c36d48830b9aa1e0ad22bf46d34e42b6809\", \"best_bid\":\"0.45\", \"best_ask\":\"0.47\"}, {\"asset_id\":\"58313761654877669244690227616056238030136603415514645252000528337391143520538\", \"price\":\"0.77\", \"size\":\"111.99\", \"side\":\"SELL\", \"hash\":\"6a3f58b6b975138e20765bab20beea779698fceb\", \"best_bid\":\"0.53\", \"best_ask\":\"0.55\"}], \"timestamp\":\"1785207465823\", \"event_type\":\"price_change\"}","received_at":"2026-07-28T02:57:46.035345Z","schema_version":"clob-market-ws.price_change.v1","sequence":null,"server_hash":null,"server_timestamp":"1785207465823","session_id":"5aad79be415c487c84df42bebd84ee93","source":"clob_market_ws"},"received_at":"2026-07-28T02:57:46.035345Z","record_id":"74063fd6f1ac2a82f0817b1e9d9bcb717669725569b2e633eebe283aa6ef4d38","schema_fingerprint":"4aa3821a28b0b7c2400bc59aba4bcc0a76e971dadd19610d3ad38c768e124dc7","schema_version":"edge-lab-recorder.raw.v1","sequence":null,"source":"clob_market_ws"}
{"event_at":"2026-07-28T02:57:45.826000Z","event_fingerprint":"7984af103e01bd0908128140d6c28eaf55853da1ca8263b823f4b0e7f9023e6a","payload":{"connection_id":"955646bd8bf740759faf38750c0f263f","event_at":"2026-07-28T02:57:45.826000Z","event_type":"price_change","frame_hash":"5ad20674dd56be0c2118a60b7ca412fcd0ef78415d6696aa154e3de48a5568b1","frame_index":0,"kind":"data","monotonic_ns":309449054294250,"payload":{"event_type":"price_change","market":"0x0f70d07969bc69eaa97d0987de651885fdca02263688026aa11e7678af8f87aa","price_changes":[{"asset_id":"58313761654877669244690227616056238030136603415514645252000528337391143520538","best_ask":"0.55","best_bid":"0.53","hash":"57adb0c1b78029d9f78f995ea25fd8066b9b69ac","price":"0.01","side":"BUY","size":"2381.24"},{"asset_id":"64053005904884194822931764831592250494815136296598204104072528088122126148949","best_ask":"0.47","best_bid":"0.45","hash":"9445c256582709297094108b83ecd6905004e2a8","price":"0.99","side":"SELL","size":"2381.24"}],"timestamp":"1785207465826"},"payload_hash":"ac905a49b068c88cbf7dd385a3617787a9646c0a42dfb93e3ea80e4f8708f2f9","raw_frame":"{\"market\":\"0x0f70d07969bc69eaa97d0987de651885fdca02263688026aa11e7678af8f87aa\", \"price_changes\":[{\"asset_id\":\"58313761654877669244690227616056238030136603415514645252000528337391143520538\", \"price\":\"0.01\", \"size\":\"2381.24\", \"side\":\"BUY\", \"hash\":\"57adb0c1b78029d9f78f995ea25fd8066b9b69ac\", \"best_bid\":\"0.53\", \"best_ask\":\"0.55\"}, {\"asset_id\":\"64053005904884194822931764831592250494815136296598204104072528088122126148949\", \"price\":\"0.99\", \"size\":\"2381.24\", \"side\":\"SELL\", \"hash\":\"9445c256582709297094108b83ecd6905004e2a8\", \"best_bid\":\"0.45\", \"best_ask\":\"0.47\"}], \"timestamp\":\"1785207465826\", \"event_type\":\"price_change\"}","received_at":"2026-07-28T02:57:46.036897Z","schema_version":"clob-market-ws.price_change.v1","sequence":null,"server_hash":null,"server_timestamp":"1785207465826","session_id":"5aad79be415c487c84df42bebd84ee93","source":"clob_market_ws"},"received_at":"2026-07-28T02:57:46.036897Z","record_id":"b52c60eb9289fa83bad927861af0b5aeb8403a434e284d3eddbf4209b3ca3695","schema_fingerprint":"4aa3821a28b0b7c2400bc59aba4bcc0a76e971dadd19610d3ad38c768e124dc7","schema_version":"edge-lab-recorder.raw.v1","sequence":null,"source":"clob_market_ws"}
{"event_at":"2026-07-28T02:57:45.827000Z","event_fingerprint":"ee6e590b060520885318f2250e1352ada31400c0ff774785d2ad1d52e85d0460","payload":{"connection_id":"955646bd8bf740759faf38750c0f263f","event_at":"2026-07-28T02:57:45.827000Z","event_type":"price_change","frame_hash":"c928650d9507c11b25e3c1bcea868d0ce046586321546d770b028c7cd4ac3c5c","frame_index":0,"kind":"data","monotonic_ns":309449055934666,"payload":{"event_type":"price_change","market":"0x0f70d07969bc69eaa97d0987de651885fdca02263688026aa11e7678af8f87aa","price_changes":[{"asset_id":"64053005904884194822931764831592250494815136296598204104072528088122126148949","best_ask":"0.47","best_bid":"0.45","hash":"1c2daef12b046e5d2e73b7a9bd34428747bb04f0","price":"0.2","side":"BUY","size":"160.6"},{"asset_id":"58313761654877669244690227616056238030136603415514645252000528337391143520538","best_ask":"0.55","best_bid":"0.53","hash":"ef598710911bacdc23ddcf5767e2ca79309c4434","price":"0.8","side":"SELL","size":"160.6"}],"timestamp":"1785207465827"},"payload_hash":"60391eb180dab87a420bff3fa843d5718a9ad0793af96692da527c00a3e570a5","raw_frame":"{\"market\":\"0x0f70d07969bc69eaa97d0987de651885fdca02263688026aa11e7678af8f87aa\", \"price_changes\":[{\"asset_id\":\"64053005904884194822931764831592250494815136296598204104072528088122126148949\", \"price\":\"0.2\", \"size\":\"160.6\", \"side\":\"BUY\", \"hash\":\"1c2daef12b046e5d2e73b7a9bd34428747bb04f0\", \"best_bid\":\"0.45\", \"best_ask\":\"0.47\"}, {\"asset_id\":\"58313761654877669244690227616056238030136603415514645252000528337391143520538\", \"price\":\"0.8\", \"size\":\"160.6\", \"side\":\"SELL\", \"hash\":\"ef598710911bacdc23ddcf5767e2ca79309c4434\", \"best_bid\":\"0.53\", \"best_ask\":\"0.55\"}], \"timestamp\":\"1785207465827\", \"event_type\":\"price_change\"}","received_at":"2026-07-28T02:57:46.038537Z","schema_version":"clob-market-ws.price_change.v1","sequence":null,"server_hash":null,"server_timestamp":"1785207465827","session_id":"5aad79be415c487c84df42bebd84ee93","source":"clob_market_ws"},"received_at":"2026-07-28T02:57:46.038537Z","record_id":"32a6980bef752b35bec0f24dd3e1e02b0c34efeeb41306babfef6c008efe351e","schema_fingerprint":"4aa3821a28b0b7c2400bc59aba4bcc0a76e971dadd19610d3ad38c768e124dc7","schema_version":"edge-lab-recorder.raw.v1","sequence":null,"source":"clob_market_ws"}
{"event_at":"2026-07-28T02:57:45.828000Z","event_fingerprint":"40c064aeac57d0661e2b2b5a6fdaaf57376a1803f3460b87a1b512ffa1dd7f62","payload":{"connection_id":"955646bd8bf740759faf38750c0f263f","event_at":"2026-07-28T02:57:45.828000Z","event_type":"price_change","frame_hash":"48aa7261eb355cae59eb95e4c20fe32a718be8f4fb69fd18f9e84255aa7a415e","frame_index":0,"kind":"data","monotonic_ns":309449057557125,"payload":{"event_type":"price_change","market":"0x0f70d07969bc69eaa97d0987de651885fdca02263688026aa11e7678af8f87aa","price_changes":[{"asset_id":"58313761654877669244690227616056238030136603415514645252000528337391143520538","best_ask":"0.55","best_bid":"0.53","hash":"cbf2685b369e121757b6931e04c5da4921e9f651","price":"0.5","side":"BUY","size":"129.59"},{"asset_id":"64053005904884194822931764831592250494815136296598204104072528088122126148949","best_ask":"0.47","best_bid":"0.45","hash":"e649c988d8b182fb8538b91409051010a15cf704","price":"0.5","side":"SELL","size":"129.59"}],"timestamp":"1785207465828"},"payload_hash":"da4f275fc0f532b86ac092107edc44ab4308d9e01110a9ca9da99929b5cc10d3","raw_frame":"{\"market\":\"0x0f70d07969bc69eaa97d0987de651885fdca02263688026aa11e7678af8f87aa\", \"price_changes\":[{\"asset_id\":\"58313761654877669244690227616056238030136603415514645252000528337391143520538\", \"price\":\"0.5\", \"size\":\"129.59\", \"side\":\"BUY\", \"hash\":\"cbf2685b369e121757b6931e04c5da4921e9f651\", \"best_bid\":\"0.53\", \"best_ask\":\"0.55\"}, {\"asset_id\":\"64053005904884194822931764831592250494815136296598204104072528088122126148949\", \"price\":\"0.5\", \"size\":\"129.59\", \"side\":\"SELL\", \"hash\":\"e649c988d8b182fb8538b91409051010a15cf704\", \"best_bid\":\"0.45\", \"best_ask\":\"0.47\"}], \"timestamp\":\"1785207465828\", \"event_type\":\"price_change\"}","received_at":"2026-07-28T02:57:46.040160Z","schema_version":"clob-market-ws.price_change.v1","sequence":null,"server_hash":null,"server_timestamp":"1785207465828","session_id":"5aad79be415c487c84df42bebd84ee93","source":"clob_market_ws"},"received_at":"2026-07-28T02:57:46.040160Z","record_id":"500762327a7022afa5fc3b48abf329a53d0aaea0de40952b277cd84aef01cb3c","schema_fingerprint":"4aa3821a28b0b7c2400bc59aba4bcc0a76e971dadd19610d3ad38c768e124dc7","schema_version":"edge-lab-recorder.raw.v1","sequence":null,"source":"clob_market_ws"}
{"event_at":"2026-07-28T02:57:45.830000Z","event_fingerprint":"e0016d3dbdbee00139ef91979556d5e4a4e2e66f47b685039f8ac95425510ad3","payload":{"connection_id":"955646bd8bf740759faf38750c0f263f","event_at":"2026-07-28T02:57:45.830000Z","event_type":"price_change","frame_hash":"4b352af1d7dc1b7d5a63b66d9e2dde814c418ce806472c82f27bb1056cbbb317","frame_index":0,"kind":"data","monotonic_ns":309449059120458,"payload":{"event_type":"price_change","market":"0x0f70d07969bc69eaa97d0987de651885fdca02263688026aa11e7678af8f87aa","price_changes":[{"asset_id":"58313761654877669244690227616056238030136603415514645252000528337391143520538","best_ask":"0.55","best_bid":"0.53","hash":"06cff2a38a79e646120b4e11275304e57a59bb9a","price":"0.52","side":"BUY","size":"89.3"},{"asset_id":"64053005904884194822931764831592250494815136296598204104072528088122126148949","best_ask":"0.47","best_bid":"0.45","hash":"776cbac6d59d966ec2533aaf335cf594fd50cf91","price":"0.48","side":"SELL","size":"89.3"}],"timestamp":"1785207465830"},"payload_hash":"b8196d8d901be2e35ec4f78071b87238951e1b77bdd8dabc041b876145d4413d","raw_frame":"{\"market\":\"0x0f70d07969bc69eaa97d0987de651885fdca02263688026aa11e7678af8f87aa\", \"price_changes\":[{\"asset_id\":\"58313761654877669244690227616056238030136603415514645252000528337391143520538\", \"price\":\"0.52\", \"size\":\"89.3\", \"side\":\"BUY\", \"hash\":\"06cff2a38a79e646120b4e11275304e57a59bb9a\", \"best_bid\":\"0.53\", \"best_ask\":\"0.55\"}, {\"asset_id\":\"64053005904884194822931764831592250494815136296598204104072528088122126148949\", \"price\":\"0.48\", \"size\":\"89.3\", \"side\":\"SELL\", \"hash\":\"776cbac6d59d966ec2533aaf335cf594fd50cf91\", \"best_bid\":\"0.45\", \"best_ask\":\"0.47\"}], \"timestamp\":\"1785207465830\", \"event_type\":\"price_change\"}","received_at":"2026-07-28T02:57:46.041723Z","schema_version":"clob-market-ws.price_change.v1","sequence":null,"server_hash":null,"server_timestamp":"1785207465830","session_id":"5aad79be415c487c84df42bebd84ee93","source":"clob_market_ws"},"received_at":"2026-07-28T02:57:46.041723Z","record_id":"c24db8acebc7f1c137dc5e580a76d7bf931d7c967151aa75f1ec86535a578502","schema_fingerprint":"4aa3821a28b0b7c2400bc59aba4bcc0a76e971dadd19610d3ad38c768e124dc7","schema_version":"edge-lab-recorder.raw.v1","sequence":null,"source":"clob_market_ws"}
{"event_at":"2026-07-28T02:57:45.830000Z","event_fingerprint":"419094cfe6e833047a89666828e875e7739c38537561f6a9469c8354f9047e7e","payload":{"connection_id":"955646bd8bf740759faf38750c0f263f","event_at":"2026-07-28T02:57:45.830000Z","event_type":"price_change","frame_hash":"55274c6c39687ed2727e6c6f91c7a5e7059efb097199f6f34b39573bff52317c","frame_index":0,"kind":"data","monotonic_ns":309449060698250,"payload":{"event_type":"price_change","market":"0x0f70d07969bc69eaa97d0987de651885fdca02263688026aa11e7678af8f87aa","price_changes":[{"asset_id":"64053005904884194822931764831592250494815136296598204104072528088122126148949","best_ask":"0.47","best_bid":"0.45","hash":"776cbac6d59d966ec2533aaf335cf594fd50cf91","price":"0.39","side":"BUY","size":"11.3"},{"asset_id":"58313761654877669244690227616056238030136603415514645252000528337391143520538","best_ask":"0.55","best_bid":"0.53","hash":"06cff2a38a79e646120b4e11275304e57a59bb9a","price":"0.61","side":"SELL","size":"11.3"}],"timestamp":"1785207465830"},"payload_hash":"75af6059d7457dc00d6398d1642d4acd68383072d6311fffd762c5d734ab3564","raw_frame":"{\"market\":\"0x0f70d07969bc69eaa97d0987de651885fdca02263688026aa11e7678af8f87aa\", \"price_changes\":[{\"asset_id\":\"64053005904884194822931764831592250494815136296598204104072528088122126148949\", \"price\":\"0.39\", \"size\":\"11.3\", \"side\":\"BUY\", \"hash\":\"776cbac6d59d966ec2533aaf335cf594fd50cf91\", \"best_bid\":\"0.45\", \"best_ask\":\"0.47\"}, {\"asset_id\":\"58313761654877669244690227616056238030136603415514645252000528337391143520538\", \"price\":\"0.61\", \"size\":\"11.3\", \"side\":\"SELL\", \"hash\":\"06cff2a38a79e646120b4e11275304e57a59bb9a\", \"best_bid\":\"0.53\", \"best_ask\":\"0.55\"}], \"timestamp\":\"1785207465830\", \"event_type\":\"price_change\"}","received_at":"2026-07-28T02:57:46.043300Z","schema_version":"clob-market-ws.price_change.v1","sequence":null,"server_hash":null,"server_timestamp":"1785207465830","session_id":"5aad79be415c487c84df42bebd84ee93","source":"clob_market_ws"},"received_at":"2026-07-28T02:57:46.043300Z","record_id":"8d20800855ad7d89029adcce04f9d6369c8abec6296b4524d4a328af0fd13d67","schema_fingerprint":"4aa3821a28b0b7c2400bc59aba4bcc0a76e971dadd19610d3ad38c768e124dc7","schema_version":"edge-lab-recorder.raw.v1","sequence":null,"source":"clob_market_ws"}
{"event_at":"2026-07-28T02:57:45.830000Z","event_fingerprint":"27ce72605540150f7634771e437efd5fbb1e32300f75db0406621d09fb6a3ee1","payload":{"connection_id":"955646bd8bf740759faf38750c0f263f","event_at":"2026-07-28T02:57:45.830000Z","event_type":"price_change","frame_hash":"ae43282c60995edd1c58f987d50141763c4e155d63ed8021514084e4374e2880","frame_index":0,"kind":"data","monotonic_ns":309449062202916,"payload":{"event_type":"price_change","market":"0x0f70d07969bc69eaa97d0987de651885fdca02263688026aa11e7678af8f87aa","price_changes":[{"asset_id":"64053005904884194822931764831592250494815136296598204104072528088122126148949","best_ask":"0.47","best_bid":"0.45","hash":"776cbac6d59d966ec2533aaf335cf594fd50cf91","price":"0.5","side":"SELL","size":"124.59"},{"asset_id":"58313761654877669244690227616056238030136603415514645252000528337391143520538","best_ask":"0.55","best_bid":"0.53","hash":"06cff2a38a79e646120b4e11275304e57a59bb9a","price":"0.5","side":"BUY","size":"124.59"}],"timestamp":"1785207465830"},"payload_hash":"f71767fca3428c896c024dd7d7fe86e195463bebe309d520643dcfb35b29511c","raw_frame":"{\"market\":\"0x0f70d07969bc69eaa97d0987de651885fdca02263688026aa11e7678af8f87aa\", \"price_changes\":[{\"asset_id\":\"64053005904884194822931764831592250494815136296598204104072528088122126148949\", \"price\":\"0.5\", \"size\":\"124.59\", \"side\":\"SELL\", \"hash\":\"776cbac6d59d966ec2533aaf335cf594fd50cf91\", \"best_bid\":\"0.45\", \"best_ask\":\"0.47\"}, {\"asset_id\":\"58313761654877669244690227616056238030136603415514645252000528337391143520538\", \"price\":\"0.5\", \"size\":\"124.59\", \"side\":\"BUY\", \"hash\":\"06cff2a38a79e646120b4e11275304e57a59bb9a\", \"best_bid\":\"0.53\", \"best_ask\":\"0.55\"}], \"timestamp\":\"1785207465830\", \"event_type\":\"price_change\"}","received_at":"2026-07-28T02:57:46.044806Z","schema_version":"clob-market-ws.price_change.v1","sequence":null,"server_hash":null,"server_timestamp":"1785207465830","session_id":"5aad79be415c487c84df42bebd84ee93","source":"clob_market_ws"},"received_at":"2026-07-28T02:57:46.044806Z","record_id":"993c8acb3ed61ae1728f369e22208a8795b1fb14efad69a59780c7a02ffa3a7a","schema_fingerprint":"4aa3821a28b0b7c2400bc59aba4bcc0a76e971dadd19610d3ad38c768e124dc7","schema_version":"edge-lab-recorder.raw.v1","sequence":null,"source":"clob_market_ws"}
{"event_at":"2026-07-28T02:57:45.833000Z","event_fingerprint":"4ee4a092ef905e8c387023a6e99703fd205cd36f09604b6c5b5691a7c6c73460","payload":{"connection_id":"955646bd8bf740759faf38750c0f263f","event_at":"2026-07-28T02:57:45.833000Z","event_type":"price_change","frame_hash":"fecc7206e1f75c35b0e00d167cbbf9a84c1069b625caece042c1942f55d4aaa9","frame_index":0,"kind":"data","monotonic_ns":309449063715291,"payload":{"event_type":"price_change","market":"0x0f70d07969bc69eaa97d0987de651885fdca02263688026aa11e7678af8f87aa","price_changes":[{"asset_id":"64053005904884194822931764831592250494815136296598204104072528088122126148949","best_ask":"0.47","best_bid":"0.45","hash":"cbd636b7eeccac8f854e27632298ed371ba37801","price":"0.44","side":"BUY","size":"75"},{"asset_id":"58313761654877669244690227616056238030136603415514645252000528337391143520538","best_ask":"0.55","best_bid":"0.53","hash":"513fcb042c265a0875701c2a4b0359a98d2e577f","price":"0.56","side":"SELL","size":"75"}],"timestamp":"1785207465833"},"payload_hash":"77cec862e9c4b857c3cb368f0a6516c6ce08a2714fa2c195df7c013cab345aea","raw_frame":"{\"market\":\"0x0f70d07969bc69eaa97d0987de651885fdca02263688026aa11e7678af8f87aa\", \"price_changes\":[{\"asset_id\":\"64053005904884194822931764831592250494815136296598204104072528088122126148949\", \"price\":\"0.44\", \"size\":\"75\", \"side\":\"BUY\", \"hash\":\"cbd636b7eeccac8f854e27632298ed371ba37801\", \"best_bid\":\"0.45\", \"best_ask\":\"0.47\"}, {\"asset_id\":\"58313761654877669244690227616056238030136603415514645252000528337391143520538\", \"price\":\"0.56\", \"size\":\"75\", \"side\":\"SELL\", \"hash\":\"513fcb042c265a0875701c2a4b0359a98d2e577f\", \"best_bid\":\"0.53\", \"best_ask\":\"0.55\"}], \"timestamp\":\"1785207465833\", \"event_type\":\"price_change\"}","received_at":"2026-07-28T02:57:46.046319Z","schema_version":"clob-market-ws.price_change.v1","sequence":null,"server_hash":null,"server_timestamp":"1785207465833","session_id":"5aad79be415c487c84df42bebd84ee93","source":"clob_market_ws"},"received_at":"2026-07-28T02:57:46.046319Z","record_id":"91723f5fa4121aa468fece163516e63485701b7afe8c19a12c0691a044b2715c","schema_fingerprint":"4aa3821a28b0b7c2400bc59aba4bcc0a76e971dadd19610d3ad38c768e124dc7","schema_version":"edge-lab-recorder.raw.v1","sequence":null,"source":"clob_market_ws"}
{"event_at":"2026-07-28T02:57:45.834000Z","event_fingerprint":"ebecb57b4ff45ba8d059283d138ff0b5f17ce50ee175cd0d32305b95d4d108a1","payload":{"connection_id":"955646bd8bf740759faf38750c0f263f","event_at":"2026-07-28T02:57:45.834000Z","event_type":"price_change","frame_hash":"dd204dc01871b55d9ea2a3f41cf55f5d0a19fcec358109b9fcc2319259d62e91","frame_index":0,"kind":"data","monotonic_ns":309449065213625,"payload":{"event_type":"price_change","market":"0x0f70d07969bc69eaa97d0987de651885fdca02263688026aa11e7678af8f87aa","price_changes":[{"asset_id":"64053005904884194822931764831592250494815136296598204104072528088122126148949","best_ask":"0.47","best_bid":"0.45","hash":"282d70fa811d29144b154a5a09133a35af042521","price":"0.38","side":"BUY","size":"47"},{"asset_id":"58313761654877669244690227616056238030136603415514645252000528337391143520538","best_ask":"0.55","best_bid":"0.53","hash":"ce197fa74bceb84ecfa0c9cb29681bb292622d86","price":"0.62","side":"SELL","size":"47"}],"timestamp":"1785207465834"},"payload_hash":"5f09d3d90058e5d24b3202d2eb16759bc12926bc8166e5ab730581357d28e184","raw_frame":"{\"market\":\"0x0f70d07969bc69eaa97d0987de651885fdca02263688026aa11e7678af8f87aa\", \"price_changes\":[{\"asset_id\":\"64053005904884194822931764831592250494815136296598204104072528088122126148949\", \"price\":\"0.38\", \"size\":\"47\", \"side\":\"BUY\", \"hash\":\"282d70fa811d29144b154a5a09133a35af042521\", \"best_bid\":\"0.45\", \"best_ask\":\"0.47\"}, {\"asset_id\":\"58313761654877669244690227616056238030136603415514645252000528337391143520538\", \"price\":\"0.62\", \"size\":\"47\", \"side\":\"SELL\", \"hash\":\"ce197fa74bceb84ecfa0c9cb29681bb292622d86\", \"best_bid\":\"0.53\", \"best_ask\":\"0.55\"}], \"timestamp\":\"1785207465834\", \"event_type\":\"price_change\"}","received_at":"2026-07-28T02:57:46.047817Z","schema_version":"clob-market-ws.price_change.v1","sequence":null,"server_hash":null,"server_timestamp":"1785207465834","session_id":"5aad79be415c487c84df42bebd84ee93","source":"clob_market_ws"},"received_at":"2026-07-28T02:57:46.047817Z","record_id":"4634b0fc64eddacbcffccf8d7ca179ff5b5836c03a801841eac5971335c553d4","schema_fingerprint":"4aa3821a28b0b7c2400bc59aba4bcc0a76e971dadd19610d3ad38c768e124dc7","schema_version":"edge-lab-recorder.raw.v1","sequence":null,"source":"clob_market_ws"}
{"event_at":"2026-07-28T02:57:45.834000Z","event_fingerprint":"372afc7595326ddc851f284656485e8f8f6e83fe9344881a6c9e044371e4369c","payload":{"connection_id":"955646bd8bf740759faf38750c0f263f","event_at":"2026-07-28T02:57:45.834000Z","event_type":"price_change","frame_hash":"e7d9a15e5dbe4c71d0df51e72a751849f75f7b519767aea4d000b4a4bfb58443","frame_index":0,"kind":"data","monotonic_ns":309449066674375,"payload":{"event_type":"price_change","market":"0x0f70d07969bc69eaa97d0987de651885fdca02263688026aa11e7678af8f87aa","price_changes":[{"asset_id":"64053005904884194822931764831592250494815136296598204104072528088122126148949","best_ask":"0.47","best_bid":"0.45","hash":"2ad7333a2be5cbedaaa8b9ee4ad961c9255ad77e","price":"0.43","side":"BUY","size":"25.53"},{"asset_id":"58313761654877669244690227616056238030136603415514645252000528337391143520538","best_ask":"0.55","best_bid":"0.53","hash":"fe1d6db95bf83c1b3fd2ae75207c607bcb92a896","price":"0.57","side":"SELL","size":"25.53"}],"timestamp":"1785207465834"},"payload_hash":"d6ce3e4edbeea34fa420ceab2e33b6e28491524dfe0dbaa7511063207a7537ed","raw_frame":"{\"market\":\"0x0f70d07969bc69eaa97d0987de651885fdca02263688026aa11e7678af8f87aa\", \"price_changes\":[{\"asset_id\":\"64053005904884194822931764831592250494815136296598204104072528088122126148949\", \"price\":\"0.43\", \"size\":\"25.53\", \"side\":\"BUY\", \"hash\":\"2ad7333a2be5cbedaaa8b9ee4ad961c9255ad77e\", \"best_bid\":\"0.45\", \"best_ask\":\"0.47\"}, {\"asset_id\":\"58313761654877669244690227616056238030136603415514645252000528337391143520538\", \"price\":\"0.57\", \"size\":\"25.53\", \"side\":\"SELL\", \"hash\":\"fe1d6db95bf83c1b3fd2ae75207c607bcb92a896\", \"best_bid\":\"0.53\", \"best_ask\":\"0.55\"}], \"timestamp\":\"1785207465834\", \"event_type\":\"price_change\"}","received_at":"2026-07-28T02:57:46.049277Z","schema_version":"clob-market-ws.price_change.v1","sequence":null,"server_hash":null,"server_timestamp":"1785207465834","session_id":"5aad79be415c487c84df42bebd84ee93","source":"clob_market_ws"},"received_at":"2026-07-28T02:57:46.049277Z","record_id":"61776cb7d0825ac7f9ccd7968c6c7ba1119d4bb28a042f866f47dabe0fe83bd8","schema_fingerprint":"4aa3821a28b0b7c2400bc59aba4bcc0a76e971dadd19610d3ad38c768e124dc7","schema_version":"edge-lab-recorder.raw.v1","sequence":null,"source":"clob_market_ws"}
{"event_at":"2026-07-28T02:57:45.837000Z","event_fingerprint":"3a2cf2e8fd9ae5d8ca6b66a275057271f38e3d2f4c4989609b6aec03651c9abd","payload":{"connection_id":"955646bd8bf740759faf38750c0f263f","event_at":"2026-07-28T02:57:45.837000Z","event_type":"price_change","frame_hash":"75b774863ea035016b2c99145760f09b94a78fac3eb8d9a0c3192ccd90dc9d1d","frame_index":0,"kind":"data","monotonic_ns":309449068159833,"payload":{"event_type":"price_change","market":"0x0f70d07969bc69eaa97d0987de651885fdca02263688026aa11e7678af8f87aa","price_changes":[{"asset_id":"64053005904884194822931764831592250494815136296598204104072528088122126148949","best_ask":"0.47","best_bid":"0.45","hash":"95cacb77cbe955da45559988830601a50fcb1e6c","price":"0.31","side":"BUY","size":"104.7"},{"asset_id":"58313761654877669244690227616056238030136603415514645252000528337391143520538","best_ask":"0.55","best_bid":"0.53","hash":"c7fe4854e33c16ab221d065da32c455f4c808db2","price":"0.69","side":"SELL","size":"104.7"}],"timestamp":"1785207465837"},"payload_hash":"a4ee819e9e3ace16b73de0156034dc2aa4d82e840a4786171b6276ace722f349","raw_frame":"{\"market\":\"0x0f70d07969bc69eaa97d0987de651885fdca02263688026aa11e7678af8f87aa\", \"price_changes\":[{\"asset_id\":\"64053005904884194822931764831592250494815136296598204104072528088122126148949\", \"price\":\"0.31\", \"size\":\"104.7\", \"side\":\"BUY\", \"hash\":\"95cacb77cbe955da45559988830601a50fcb1e6c\", \"best_bid\":\"0.45\", \"best_ask\":\"0.47\"}, {\"asset_id\":\"58313761654877669244690227616056238030136603415514645252000528337391143520538\", \"price\":\"0.69\", \"size\":\"104.7\", \"side\":\"SELL\", \"hash\":\"c7fe4854e33c16ab221d065da32c455f4c808db2\", \"best_bid\":\"0.53\", \"best_ask\":\"0.55\"}], \"timestamp\":\"1785207465837\", \"event_type\":\"price_change\"}","received_at":"2026-07-28T02:57:46.050764Z","schema_version":"clob-market-ws.price_change.v1","sequence":null,"server_hash":null,"server_timestamp":"1785207465837","session_id":"5aad79be415c487c84df42bebd84ee93","source":"clob_market_ws"},"received_at":"2026-07-28T02:57:46.050764Z","record_id":"fd2afa6e840509fa05bc36e4fcf522a7db4949883422726a8a800908b664fd53","schema_fingerprint":"4aa3821a28b0b7c2400bc59aba4bcc0a76e971dadd19610d3ad38c768e124dc7","schema_version":"edge-lab-recorder.raw.v1","sequence":null,"source":"clob_market_ws"}
{"event_at":"2026-07-28T02:57:45.839000Z","event_fingerprint":"fdca96a9bf3fbeadcb7b90ca8a586dc3e7c91023647e870592a8d4c869f09dff","payload":{"connection_id":"955646bd8bf740759faf38750c0f263f","event_at":"2026-07-28T02:57:45.839000Z","event_type":"price_change","frame_hash":"f851d840b6cecde8f20691dc995672e8b2870d77f93765cf76165286db79c8f3","frame_index":0,"kind":"data","monotonic_ns":309449070748250,"payload":{"event_type":"price_change","market":"0x0f70d07969bc69eaa97d0987de651885fdca02263688026aa11e7678af8f87aa","price_changes":[{"asset_id":"64053005904884194822931764831592250494815136296598204104072528088122126148949","best_ask":"0.47","best_bid":"0.45","hash":"9214b7187fb30ca41830dea1e42a2ca19454c3ac","price":"0.43","side":"BUY","size":"18.4"},{"asset_id":"58313761654877669244690227616056238030136603415514645252000528337391143520538","best_ask":"0.55","best_bid":"0.53","hash":"32a4f78c5eece3cdf04603227a51468a4c9ca9df","price":"0.57","side":"SELL","size":"18.4"}],"timestamp":"1785207465839"},"payload_hash":"b657636380ad0d48b2bd11e7312d519e5e348e419a8e616693f2abc08dfa12a1","raw_frame":"{\"market\":\"0x0f70d07969bc69eaa97d0987de651885fdca02263688026aa11e7678af8f87aa\", \"price_changes\":[{\"asset_id\":\"64053005904884194822931764831592250494815136296598204104072528088122126148949\", \"price\":\"0.43\", \"size\":\"18.4\", \"side\":\"BUY\", \"hash\":\"9214b7187fb30ca41830dea1e42a2ca19454c3ac\", \"best_bid\":\"0.45\", \"best_ask\":\"0.47\"}, {\"asset_id\":\"58313761654877669244690227616056238030136603415514645252000528337391143520538\", \"price\":\"0.57\", \"size\":\"18.4\", \"side\":\"SELL\", \"hash\":\"32a4f78c5eece3cdf04603227a51468a4c9ca9df\", \"best_bid\":\"0.53\", \"best_ask\":\"0.55\"}], \"timestamp\":\"1785207465839\", \"event_type\":\"price_change\"}","received_at":"2026-07-28T02:57:46.053351Z","schema_version":"clob-market-ws.price_change.v1","sequence":null,"server_hash":null,"server_timestamp":"1785207465839","session_id":"5aad79be415c487c84df42bebd84ee93","source":"clob_market_ws"},"received_at":"2026-07-28T02:57:46.053351Z","record_id":"f8bb54a5b9131028c5ad24f7e3ccfb9deb16fa6b9dde96db1b0a21d9bbefaa76","schema_fingerprint":"4aa3821a28b0b7c2400bc59aba4bcc0a76e971dadd19610d3ad38c768e124dc7","schema_version":"edge-lab-recorder.raw.v1","sequence":null,"source":"clob_market_ws"}
{"event_at":"2026-07-28T02:57:45.839000Z","event_fingerprint":"10a23643ee2173dcd31cfb740cdb371513aa275dd0873242c63a98acd1cbc898","payload":{"connection_id":"955646bd8bf740759faf38750c0f263f","event_at":"2026-07-28T02:57:45.839000Z","event_type":"price_change","frame_hash":"8d8b583aef5a8c0855e3f1c747ecd6ba26009798974cfffbe726a65d88e78bbf","frame_index":0,"kind":"data","monotonic_ns":309449072464208,"payload":{"event_type":"price_change","market":"0x0f70d07969bc69eaa97d0987de651885fdca02263688026aa11e7678af8f87aa","price_changes":[{"asset_id":"64053005904884194822931764831592250494815136296598204104072528088122126148949","best_ask":"0.47","best_bid":"0.45","hash":"9214b7187fb30ca41830dea1e42a2ca19454c3ac","price":"0.42","side":"BUY","size":"12.01"},{"asset_id":"58313761654877669244690227616056238030136603415514645252000528337391143520538","best_ask":"0.55","best_bid":"0.53","hash":"32a4f78c5eece3cdf04603227a51468a4c9ca9df","price":"0.58","side":"SELL","size":"12.01"}],"timestamp":"1785207465839"},"payload_hash":"5ae33a346aea2fd72838b569cbb8ffa7c6682989a9f4db404526ee843516a8d7","raw_frame":"{\"market\":\"0x0f70d07969bc69eaa97d0987de651885fdca02263688026aa11e7678af8f87aa\", \"price_changes\":[{\"asset_id\":\"64053005904884194822931764831592250494815136296598204104072528088122126148949\", \"price\":\"0.42\", \"size\":\"12.01\", \"side\":\"BUY\", \"hash\":\"9214b7187fb30ca41830dea1e42a2ca19454c3ac\", \"best_bid\":\"0.45\", \"best_ask\":\"0.47\"}, {\"asset_id\":\"58313761654877669244690227616056238030136603415514645252000528337391143520538\", \"price\":\"0.58\", \"size\":\"12.01\", \"side\":\"SELL\", \"hash\":\"32a4f78c5eece3cdf04603227a51468a4c9ca9df\", \"best_bid\":\"0.53\", \"best_ask\":\"0.55\"}], \"timestamp\":\"1785207465839\", \"event_type\":\"price_change\"}","received_at":"2026-07-28T02:57:46.055067Z","schema_version":"clob-market-ws.price_change.v1","sequence":null,"server_hash":null,"server_timestamp":"1785207465839","session_id":"5aad79be415c487c84df42bebd84ee93","source":"clob_market_ws"},"received_at":"2026-07-28T02:57:46.055067Z","record_id":"b1720ee47a1e93c3a78a29d57b2d8b01e4d6d44df138e828219c8fc1d7671164","schema_fingerprint":"4aa3821a28b0b7c2400bc59aba4bcc0a76e971dadd19610d3ad38c768e124dc7","schema_version":"edge-lab-recorder.raw.v1","sequence":null,"source":"clob_market_ws"}
{"event_at":"2026-07-28T02:57:45.841000Z","event_fingerprint":"46c307cb169fc12df43f9ac22bc37802cc4325cd2fc631a176c5019e137e31eb","payload":{"connection_id":"955646bd8bf740759faf38750c0f263f","event_at":"2026-07-28T02:57:45.841000Z","event_type":"price_change","frame_hash":"5d7600c04977b3c28eb4e2b6fab7731a3965a9cbad96a9eb8139a1deb3face70","frame_index":0,"kind":"data","monotonic_ns":309449074139833,"payload":{"event_type":"price_change","market":"0x0f70d07969bc69eaa97d0987de651885fdca02263688026aa11e7678af8f87aa","price_changes":[{"asset_id":"64053005904884194822931764831592250494815136296598204104072528088122126148949","best_ask":"0.47","best_bid":"0.45","hash":"b802d0aece1e46e51f165f0f669c9e88686dcad4","price":"0.23","side":"BUY","size":"127.99"},{"asset_id":"58313761654877669244690227616056238030136603415514645252000528337391143520538","best_ask":"0.55","best_bid":"0.53","hash":"4a8dffbbeae97586eb4030f13776600fdb4f2aa6","price":"0.77","side":"SELL","size":"127.99"}],"timestamp":"1785207465841"},"payload_hash":"cfafb0c1c0e53295f1998a23284ab37d19a9b25d68f5c4aca4e756b5a9227168","raw_frame":"{\"market\":\"0x0f70d07969bc69eaa97d0987de651885fdca02263688026aa11e7678af8f87aa\", \"price_changes\":[{\"asset_id\":\"64053005904884194822931764831592250494815136296598204104072528088122126148949\", \"price\":\"0.23\", \"size\":\"127.99\", \"side\":\"BUY\", \"hash\":\"b802d0aece1e46e51f165f0f669c9e88686dcad4\", \"best_bid\":\"0.45\", \"best_ask\":\"0.47\"}, {\"asset_id\":\"58313761654877669244690227616056238030136603415514645252000528337391143520538\", \"price\":\"0.77\", \"size\":\"127.99\", \"side\":\"SELL\", \"hash\":\"4a8dffbbeae97586eb4030f13776600fdb4f2aa6\", \"best_bid\":\"0.53\", \"best_ask\":\"0.55\"}], \"timestamp\":\"1785207465841\", \"event_type\":\"price_change\"}","received_at":"2026-07-28T02:57:46.056741Z","schema_version":"clob-market-ws.price_change.v1","sequence":null,"server_hash":null,"server_timestamp":"1785207465841","session_id":"5aad79be415c487c84df42bebd84ee93","source":"clob_market_ws"},"received_at":"2026-07-28T02:57:46.056741Z","record_id":"b00c22e99629fcedf8b32b39b64d883b1c6a9ca776c850ff39857737c8e70f53","schema_fingerprint":"4aa3821a28b0b7c2400bc59aba4bcc0a76e971dadd19610d3ad38c768e124dc7","schema_version":"edge-lab-recorder.raw.v1","sequence":null,"source":"clob_market_ws"}
{"event_at":"2026-07-28T02:57:45.842000Z","event_fingerprint":"992165254522ff13bcaa1569e26ac2e5ecf712d1f25a6ea7bd8b40fc41a96644","payload":{"connection_id":"955646bd8bf740759faf38750c0f263f","event_at":"2026-07-28T02:57:45.842000Z","event_type":"price_change","frame_hash":"d0e39ca4974031e66c6c368a23d4749c0a3015f0cd9381b053a8833a1fa81e5c","frame_index":0,"kind":"data","monotonic_ns":309449076481500,"payload":{"event_type":"price_change","market":"0x0f70d07969bc69eaa97d0987de651885fdca02263688026aa11e7678af8f87aa","price_changes":[{"asset_id":"58313761654877669244690227616056238030136603415514645252000528337391143520538","best_ask":"0.55","best_bid":"0.53","hash":"7d017c563d9084e35838c6a22b731d4380ea8a6f","price":"0.31","side":"BUY","size":"112.63"},{"asset_id":"64053005904884194822931764831592250494815136296598204104072528088122126148949","best_ask":"0.47","best_bid":"0.45","hash":"5f6601335e85d90d386370de9aa600ea8092cf90","price":"0.69","side":"SELL","size":"112.63"}],"timestamp":"1785207465842"},"payload_hash":"ea9ffc5204764cd3e7ca7379411f2800b8bcdab41218963ad543d0bb94fc5e9d","raw_frame":"{\"market\":\"0x0f70d07969bc69eaa97d0987de651885fdca02263688026aa11e7678af8f87aa\", \"price_changes\":[{\"asset_id\":\"58313761654877669244690227616056238030136603415514645252000528337391143520538\", \"price\":\"0.31\", \"size\":\"112.63\", \"side\":\"BUY\", \"hash\":\"7d017c563d9084e35838c6a22b731d4380ea8a6f\", \"best_bid\":\"0.53\", \"best_ask\":\"0.55\"}, {\"asset_id\":\"64053005904884194822931764831592250494815136296598204104072528088122126148949\", \"price\":\"0.69\", \"size\":\"112.63\", \"side\":\"SELL\", \"hash\":\"5f6601335e85d90d386370de9aa600ea8092cf90\", \"best_bid\":\"0.45\", \"best_ask\":\"0.47\"}], \"timestamp\":\"1785207465842\", \"event_type\":\"price_change\"}","received_at":"2026-07-28T02:57:46.059082Z","schema_version":"clob-market-ws.price_change.v1","sequence":null,"server_hash":null,"server_timestamp":"1785207465842","session_id":"5aad79be415c487c84df42bebd84ee93","source":"clob_market_ws"},"received_at":"2026-07-28T02:57:46.059082Z","record_id":"81f1022085ce904aa955e096fa0443f47f8034733747a6c33500379f351be59d","schema_fingerprint":"4aa3821a28b0b7c2400bc59aba4bcc0a76e971dadd19610d3ad38c768e124dc7","schema_version":"edge-lab-recorder.raw.v1","sequence":null,"source":"clob_market_ws"}
{"event_at":"2026-07-28T02:57:45.843000Z","event_fingerprint":"21061db22fd4c18509fedc626cb42df46e9ec4cc344aa8f9410aef7a7782319a","payload":{"connection_id":"955646bd8bf740759faf38750c0f263f","event_at":"2026-07-28T02:57:45.843000Z","event_type":"price_change","frame_hash":"4b494b59642a82134333be40fb3045b37b3bb4af67d0f132d7725cdf78477845","frame_index":0,"kind":"data","monotonic_ns":309449078044375,"payload":{"event_type":"price_change","market":"0x0f70d07969bc69eaa97d0987de651885fdca02263688026aa11e7678af8f87aa","price_changes":[{"asset_id":"58313761654877669244690227616056238030136603415514645252000528337391143520538","best_ask":"0.55","best_bid":"0.53","hash":"b634604e19d1fde6e260ba4531ce4a83bbc0cc84","price":"0.53","side":"BUY","size":"118.46"},{"asset_id":"64053005904884194822931764831592250494815136296598204104072528088122126148949","best_ask":"0.47","best_bid":"0.45","hash":"6ebf143c58b6daa60d703573284873e55309b732","price":"0.47","side":"SELL","size":"118.46"}],"timestamp":"1785207465843"},"payload_hash":"d0ad178d029a987dacad1cbefe58bd99daefacd8cc19af52e1a28f14d0b127ca","raw_frame":"{\"market\":\"0x0f70d07969bc69eaa97d0987de651885fdca02263688026aa11e7678af8f87aa\", \"price_changes\":[{\"asset_id\":\"58313761654877669244690227616056238030136603415514645252000528337391143520538\", \"price\":\"0.53\", \"size\":\"118.46\", \"side\":\"BUY\", \"hash\":\"b634604e19d1fde6e260ba4531ce4a83bbc0cc84\", \"best_bid\":\"0.53\", \"best_ask\":\"0.55\"}, {\"asset_id\":\"64053005904884194822931764831592250494815136296598204104072528088122126148949\", \"price\":\"0.47\", \"size\":\"118.46\", \"side\":\"SELL\", \"hash\":\"6ebf143c58b6daa60d703573284873e55309b732\", \"best_bid\":\"0.45\", \"best_ask\":\"0.47\"}], \"timestamp\":\"1785207465843\", \"event_type\":\"price_change\"}","received_at":"2026-07-28T02:57:46.060647Z","schema_version":"clob-market-ws.price_change.v1","sequence":null,"server_hash":null,"server_timestamp":"1785207465843","session_id":"5aad79be415c487c84df42bebd84ee93","source":"clob_market_ws"},"received_at":"2026-07-28T02:57:46.060647Z","record_id":"9ecb3cdebf37fcfd51b136e9a82236b07783e6eefd5279d423d09e9144775f6b","schema_fingerprint":"4aa3821a28b0b7c2400bc59aba4bcc0a76e971dadd19610d3ad38c768e124dc7","schema_version":"edge-lab-recorder.raw.v1","sequence":null,"source":"clob_market_ws"}
{"event_at":"2026-07-28T02:57:45.846000Z","event_fingerprint":"0392c5b622e8f8e2ba75b1fb185a75d225150104adb44f9f98135b92d9e37dc2","payload":{"connection_id":"955646bd8bf740759faf38750c0f263f","event_at":"2026-07-28T02:57:45.846000Z","event_type":"price_change","frame_hash":"c5d4bff68a551d3ee435d8dc8814e7671b9363d750a4fc44fc328a113b3a938e","frame_index":0,"kind":"data","monotonic_ns":309449079587666,"payload":{"event_type":"price_change","market":"0x0f70d07969bc69eaa97d0987de651885fdca02263688026aa11e7678af8f87aa","price_changes":[{"asset_id":"64053005904884194822931764831592250494815136296598204104072528088122126148949","best_ask":"0.47","best_bid":"0.45","hash":"289679284923a03bb453582490643b5d9be8e282","price":"0.48","side":"SELL","size":"84.3"},{"asset_id":"58313761654877669244690227616056238030136603415514645252000528337391143520538","best_ask":"0.55","best_bid":"0.53","hash":"03372c95495585d79ef459620041251e8c383f13","price":"0.52","side":"BUY","size":"84.3"}],"timestamp":"1785207465846"},"payload_hash":"4b14d153953d89608ced6b631050863504a6392bcbbaed68e02aa1dbe9cd69be","raw_frame":"{\"market\":\"0x0f70d07969bc69eaa97d0987de651885fdca02263688026aa11e7678af8f87aa\", \"price_changes\":[{\"asset_id\":\"64053005904884194822931764831592250494815136296598204104072528088122126148949\", \"price\":\"0.48\", \"size\":\"84.3\", \"side\":\"SELL\", \"hash\":\"289679284923a03bb453582490643b5d9be8e282\", \"best_bid\":\"0.45\", \"best_ask\":\"0.47\"}, {\"asset_id\":\"58313761654877669244690227616056238030136603415514645252000528337391143520538\", \"price\":\"0.52\", \"size\":\"84.3\", \"side\":\"BUY\", \"hash\":\"03372c95495585d79ef459620041251e8c383f13\", \"best_bid\":\"0.53\", \"best_ask\":\"0.55\"}], \"timestamp\":\"1785207465846\", \"event_type\":\"price_change\"}","received_at":"2026-07-28T02:57:46.062192Z","schema_version":"clob-market-ws.price_change.v1","sequence":null,"server_hash":null,"server_timestamp":"1785207465846","session_id":"5aad79be415c487c84df42bebd84ee93","source":"clob_market_ws"},"received_at":"2026-07-28T02:57:46.062192Z","record_id":"674e1d74ca21d51e3712ad2f9c3773ad291b73377ff0f7e466d33307ede06e93","schema_fingerprint":"4aa3821a28b0b7c2400bc59aba4bcc0a76e971dadd19610d3ad38c768e124dc7","schema_version":"edge-lab-recorder.raw.v1","sequence":null,"source":"clob_market_ws"}
{"event_at":"2026-07-28T02:57:45.846000Z","event_fingerprint":"6729f47a1f9c6c9a56f2623c541c997c51de1615427b2f41a6be7b236bd441db","payload":{"connection_id":"955646bd8bf740759faf38750c0f263f","event_at":"2026-07-28T02:57:45.846000Z","event_type":"price_change","frame_hash":"8f18dfcf8b876a29fd96f65ee1f0fa04b1b7d6e1cdacd2d93f3afabd3a4e0735","frame_index":0,"kind":"data","monotonic_ns":309449081074916,"payload":{"event_type":"price_change","market":"0x0f70d07969bc69eaa97d0987de651885fdca02263688026aa11e7678af8f87aa","price_changes":[{"asset_id":"58313761654877669244690227616056238030136603415514645252000528337391143520538","best_ask":"0.55","best_bid":"0.53","hash":"ee46ad97a2deb4b8deb17234b946713613695f59","price":"0.01","side":"BUY","size":"2376.24"},{"asset_id":"64053005904884194822931764831592250494815136296598204104072528088122126148949","best_ask":"0.47","best_bid":"0.45","hash":"c35e2bc67c0e252432925a530c69d5ebe036427e","price":"0.99","side":"SELL","size":"2376.24"}],"timestamp":"1785207465846"},"payload_hash":"b5f850e08f44d27f89a684de7e9599210bdd0e8afdb113a916994b7167cba8e5","raw_frame":"{\"market\":\"0x0f70d07969bc69eaa97d0987de651885fdca02263688026aa11e7678af8f87aa\", \"price_changes\":[{\"asset_id\":\"58313761654877669244690227616056238030136603415514645252000528337391143520538\", \"price\":\"0.01\", \"size\":\"2376.24\", \"side\":\"BUY\", \"hash\":\"ee46ad97a2deb4b8deb17234b946713613695f59\", \"best_bid\":\"0.53\", \"best_ask\":\"0.55\"}, {\"asset_id\":\"64053005904884194822931764831592250494815136296598204104072528088122126148949\", \"price\":\"0.99\", \"size\":\"2376.24\", \"side\":\"SELL\", \"hash\":\"c35e2bc67c0e252432925a530c69d5ebe036427e\", \"best_bid\":\"0.45\", \"best_ask\":\"0.47\"}], \"timestamp\":\"1785207465846\", \"event_type\":\"price_change\"}","received_at":"2026-07-28T02:57:46.063678Z","schema_version":"clob-market-ws.price_change.v1","sequence":null,"server_hash":null,"server_timestamp":"1785207465846","session_id":"5aad79be415c487c84df42bebd84ee93","source":"clob_market_ws"},"received_at":"2026-07-28T02:57:46.063678Z","record_id":"b2a0e6167005aeb4c168204dfae33a4517e497e6749a67228fbacde16cb778b9","schema_fingerprint":"4aa3821a28b0b7c2400bc59aba4bcc0a76e971dadd19610d3ad38c768e124dc7","schema_version":"edge-lab-recorder.raw.v1","sequence":null,"source":"clob_market_ws"}
{"event_at":"2026-07-28T02:57:45.847000Z","event_fingerprint":"159bf5006978b6a36b1625a45ed44ae0ae1d8754cf4a3b267df5426703a2ac57","payload":{"connection_id":"955646bd8bf740759faf38750c0f263f","event_at":"2026-07-28T02:57:45.847000Z","event_type":"price_change","frame_hash":"aff740f2ff37b96b8022f34edec5f55d7fb10dbe82ccff87f341fae6524570c5","frame_index":0,"kind":"data","monotonic_ns":309449082608791,"payload":{"event_type":"price_change","market":"0x0f70d07969bc69eaa97d0987de651885fdca02263688026aa11e7678af8f87aa","price_changes":[{"asset_id":"64053005904884194822931764831592250494815136296598204104072528088122126148949","best_ask":"0.47","best_bid":"0.45","hash":"88e40fca822264be0d17de43e58e2a357469d10d","price":"0.51","side":"SELL","size":"273.97"},{"asset_id":"58313761654877669244690227616056238030136603415514645252000528337391143520538","best_ask":"0.55","best_bid":"0.53","hash":"87b33728011aaf9e7e5461f1e0d33be25da59816","price":"0.49","side":"BUY","size":"273.97"}],"timestamp":"1785207465847"},"payload_hash":"483d7a93382cc6cbeb8cbc5baf8377f3d1f17594746ca7b7ce453fb0f5e165ce","raw_frame":"{\"market\":\"0x0f70d07969bc69eaa97d0987de651885fdca02263688026aa11e7678af8f87aa\", \"price_changes\":[{\"asset_id\":\"64053005904884194822931764831592250494815136296598204104072528088122126148949\", \"price\":\"0.51\", \"size\":\"273.97\", \"side\":\"SELL\", \"hash\":\"88e40fca822264be0d17de43e58e2a357469d10d\", \"best_bid\":\"0.45\", \"best_ask\":\"0.47\"}, {\"asset_id\":\"58313761654877669244690227616056238030136603415514645252000528337391143520538\", \"price\":\"0.49\", \"size\":\"273.97\", \"side\":\"BUY\", \"hash\":\"87b33728011aaf9e7e5461f1e0d33be25da59816\", \"best_bid\":\"0.53\", \"best_ask\":\"0.55\"}], \"timestamp\":\"1785207465847\", \"event_type\":\"price_change\"}","received_at":"2026-07-28T02:57:46.065212Z","schema_version":"clob-market-ws.price_change.v1","sequence":null,"server_hash":null,"server_timestamp":"1785207465847","session_id":"5aad79be415c487c84df42bebd84ee93","source":"clob_market_ws"},"received_at":"2026-07-28T02:57:46.065212Z","record_id":"13642d79e1d47e45b8b6a3d8b0379fe06c3b13d93457ad18910d0c6c57d6604a","schema_fingerprint":"4aa3821a28b0b7c2400bc59aba4bcc0a76e971dadd19610d3ad38c768e124dc7","schema_version":"edge-lab-recorder.raw.v1","sequence":null,"source":"clob_market_ws"}
{"event_at":"2026-07-28T02:57:45.852000Z","event_fingerprint":"efd57084b7c555180081b2c2c5a6b16e9ae4873d04cd3cb79eb2787eb7570286","payload":{"connection_id":"955646bd8bf740759faf38750c0f263f","event_at":"2026-07-28T02:57:45.852000Z","event_type":"price_change","frame_hash":"f3460d0eb2bb77f7658e6b8360c8d01555d1c779508056d9864a7fad0fbd194a","frame_index":0,"kind":"data","monotonic_ns":309449084087625,"payload":{"event_type":"price_change","market":"0x0f70d07969bc69eaa97d0987de651885fdca02263688026aa11e7678af8f87aa","price_changes":[{"asset_id":"58313761654877669244690227616056238030136603415514645252000528337391143520538","best_ask":"0.55","best_bid":"0.53","hash":"e99177fed9fd7e81682ee2c894550b72ae127cc7","price":"0.48","side":"BUY","size":"150.08"},{"asset_id":"64053005904884194822931764831592250494815136296598204104072528088122126148949","best_ask":"0.47","best_bid":"0.45","hash":"4987dfbd64af67d79a697759714d884c91f329eb","price":"0.52","side":"SELL","size":"150.08"}],"timestamp":"1785207465852"},"payload_hash":"4098da4c01349ba3af3b6cf095b3e4bd449c0f7468f45a89f4a1bee31301432d","raw_frame":"{\"market\":\"0x0f70d07969bc69eaa97d0987de651885fdca02263688026aa11e7678af8f87aa\", \"price_changes\":[{\"asset_id\":\"58313761654877669244690227616056238030136603415514645252000528337391143520538\", \"price\":\"0.48\", \"size\":\"150.08\", \"side\":\"BUY\", \"hash\":\"e99177fed9fd7e81682ee2c894550b72ae127cc7\", \"best_bid\":\"0.53\", \"best_ask\":\"0.55\"}, {\"asset_id\":\"64053005904884194822931764831592250494815136296598204104072528088122126148949\", \"price\":\"0.52\", \"size\":\"150.08\", \"side\":\"SELL\", \"hash\":\"4987dfbd64af67d79a697759714d884c91f329eb\", \"best_bid\":\"0.45\", \"best_ask\":\"0.47\"}], \"timestamp\":\"1785207465852\", \"event_type\":\"price_change\"}","received_at":"2026-07-28T02:57:46.066691Z","schema_version":"clob-market-ws.price_change.v1","sequence":null,"server_hash":null,"server_timestamp":"1785207465852","session_id":"5aad79be415c487c84df42bebd84ee93","source":"clob_market_ws"},"received_at":"2026-07-28T02:57:46.066691Z","record_id":"07b7036014fc43d4f80195b4ba508c41fc89e3264a2e4be7e48ad947d4818ea8","schema_fingerprint":"4aa3821a28b0b7c2400bc59aba4bcc0a76e971dadd19610d3ad38c768e124dc7","schema_version":"edge-lab-recorder.raw.v1","sequence":null,"source":"clob_market_ws"}
{"event_at":"2026-07-28T02:57:45.856000Z","event_fingerprint":"406f012eac71a8dd046c9e246bc0f43687ee933b3f618795e5af24653cab2005","payload":{"connection_id":"955646bd8bf740759faf38750c0f263f","event_at":"2026-07-28T02:57:45.856000Z","event_type":"price_change","frame_hash":"bd701d4abe9a9fb04f5ce9e0eab5ae56ea14ed568136e3e0f9dfd6d8f57af864","frame_index":0,"kind":"data","monotonic_ns":309449085655916,"payload":{"event_type":"price_change","market":"0x0f70d07969bc69eaa97d0987de651885fdca02263688026aa11e7678af8f87aa","price_changes":[{"asset_id":"58313761654877669244690227616056238030136603415514645252000528337391143520538","best_ask":"0.55","best_bid":"0.53","hash":"881c10e6c95d7a194d0e98d0a46260b7873cb176","price":"0.34","side":"BUY","size":"97.79"},{"asset_id":"64053005904884194822931764831592250494815136296598204104072528088122126148949","best_ask":"0.47","best_bid":"0.45","hash":"f2efda8a3885b5be482906ae68d4bc6c15855d28","price":"0.66","side":"SELL","size":"97.79"}],"timestamp":"1785207465856"},"payload_hash":"1bedaf7f5fe0db332cc1f436cdb48065215b5a3ca63662b016136e725871a528","raw_frame":"{\"market\":\"0x0f70d07969bc69eaa97d0987de651885fdca02263688026aa11e7678af8f87aa\", \"price_changes\":[{\"asset_id\":\"58313761654877669244690227616056238030136603415514645252000528337391143520538\", \"price\":\"0.34\", \"size\":\"97.79\", \"side\":\"BUY\", \"hash\":\"881c10e6c95d7a194d0e98d0a46260b7873cb176\", \"best_bid\":\"0.53\", \"best_ask\":\"0.55\"}, {\"asset_id\":\"64053005904884194822931764831592250494815136296598204104072528088122126148949\", \"price\":\"0.66\", \"size\":\"97.79\", \"side\":\"SELL\", \"hash\":\"f2efda8a3885b5be482906ae68d4bc6c15855d28\", \"best_bid\":\"0.45\", \"best_ask\":\"0.47\"}], \"timestamp\":\"1785207465856\", \"event_type\":\"price_change\"}","received_at":"2026-07-28T02:57:46.068258Z","schema_version":"clob-market-ws.price_change.v1","sequence":null,"server_hash":null,"server_timestamp":"1785207465856","session_id":"5aad79be415c487c84df42bebd84ee93","source":"clob_market_ws"},"received_at":"2026-07-28T02:57:46.068258Z","record_id":"337816165be3d9f4ca40029ead92590556e4218e58a74142dee53f07726e38a7","schema_fingerprint":"4aa3821a28b0b7c2400bc59aba4bcc0a76e971dadd19610d3ad38c768e124dc7","schema_version":"edge-lab-recorder.raw.v1","sequence":null,"source":"clob_market_ws"}
{"event_at":"2026-07-28T02:57:45.859000Z","event_fingerprint":"aa0f19eee2ab6aa4389a41f27238a737645f116b871885a01d7663c87e8f2cc9","payload":{"connection_id":"955646bd8bf740759faf38750c0f263f","event_at":"2026-07-28T02:57:45.859000Z","event_type":"price_change","frame_hash":"6480f7447c19f265f836af526929412efb22e751f42e5321789887d348f87f17","frame_index":0,"kind":"data","monotonic_ns":309449087225458,"payload":{"event_type":"price_change","market":"0x0f70d07969bc69eaa97d0987de651885fdca02263688026aa11e7678af8f87aa","price_changes":[{"asset_id":"64053005904884194822931764831592250494815136296598204104072528088122126148949","best_ask":"0.47","best_bid":"0.45","hash":"1056c9d2c8e8fca76030a242c0d2ce3b6917a75d","price":"0.42","side":"BUY","size":"17.01"},{"asset_id":"58313761654877669244690227616056238030136603415514645252000528337391143520538","best_ask":"0.55","best_bid":"0.53","hash":"6feb3ffc963111162263135256e2d65ba8509228","price":"0.58","side":"SELL","size":"17.01"}],"timestamp":"1785207465859"},"payload_hash":"f8afb840ebe56f498a98f00ee240eedf97f63deeabb52bae4b0aa68e312fb1f8","raw_frame":"{\"market\":\"0x0f70d07969bc69eaa97d0987de651885fdca02263688026aa11e7678af8f87aa\", \"price_changes\":[{\"asset_id\":\"64053005904884194822931764831592250494815136296598204104072528088122126148949\", \"price\":\"0.42\", \"size\":\"17.01\", \"side\":\"BUY\", \"hash\":\"1056c9d2c8e8fca76030a242c0d2ce3b6917a75d\", \"best_bid\":\"0.45\", \"best_ask\":\"0.47\"}, {\"asset_id\":\"58313761654877669244690227616056238030136603415514645252000528337391143520538\", \"price\":\"0.58\", \"size\":\"17.01\", \"side\":\"SELL\", \"hash\":\"6feb3ffc963111162263135256e2d65ba8509228\", \"best_bid\":\"0.53\", \"best_ask\":\"0.55\"}], \"timestamp\":\"1785207465859\", \"event_type\":\"price_change\"}","received_at":"2026-07-28T02:57:46.069829Z","schema_version":"clob-market-ws.price_change.v1","sequence":null,"server_hash":null,"server_timestamp":"1785207465859","session_id":"5aad79be415c487c84df42bebd84ee93","source":"clob_market_ws"},"received_at":"2026-07-28T02:57:46.069829Z","record_id":"eed9c6a64a6f6b0272f080e5335db80532cd0d8b3dbc0d5c9784ea255fef349e","schema_fingerprint":"4aa3821a28b0b7c2400bc59aba4bcc0a76e971dadd19610d3ad38c768e124dc7","schema_version":"edge-lab-recorder.raw.v1","sequence":null,"source":"clob_market_ws"}
{"event_at":"2026-07-28T02:57:45.860000Z","event_fingerprint":"b7dd6521a321e8410cd6483db233b7e93a1f5f5103a8365d0fdb09a7deb7530a","payload":{"connection_id":"955646bd8bf740759faf38750c0f263f","event_at":"2026-07-28T02:57:45.860000Z","event_type":"price_change","frame_hash":"9fac401f434607be01692f6440355e89a311d98b97a38d02db574dedee9e5864","frame_index":0,"kind":"data","monotonic_ns":309449088712041,"payload":{"event_type":"price_change","market":"0x0f70d07969bc69eaa97d0987de651885fdca02263688026aa11e7678af8f87aa","price_changes":[{"asset_id":"58313761654877669244690227616056238030136603415514645252000528337391143520538","best_ask":"0.55","best_bid":"0.53","hash":"9b54d102070cca7883882897c2b7c1d5ca1d892a","price":"0.49","side":"BUY","size":"278.97"},{"asset_id":"64053005904884194822931764831592250494815136296598204104072528088122126148949","best_ask":"0.47","best_bid":"0.45","hash":"2075b43152fae6accf02229ce91ea86283919765","price":"0.51","side":"SELL","size":"278.97"}],"timestamp":"1785207465860"},"payload_hash":"b2fe6f611996871298901a8060957bd0a33638f197861854c4fe4f548f15ca25","raw_frame":"{\"market\":\"0x0f70d07969bc69eaa97d0987de651885fdca02263688026aa11e7678af8f87aa\", \"price_changes\":[{\"asset_id\":\"58313761654877669244690227616056238030136603415514645252000528337391143520538\", \"price\":\"0.49\", \"size\":\"278.97\", \"side\":\"BUY\", \"hash\":\"9b54d102070cca7883882897c2b7c1d5ca1d892a\", \"best_bid\":\"0.53\", \"best_ask\":\"0.55\"}, {\"asset_id\":\"64053005904884194822931764831592250494815136296598204104072528088122126148949\", \"price\":\"0.51\", \"size\":\"278.97\", \"side\":\"SELL\", \"hash\":\"2075b43152fae6accf02229ce91ea86283919765\", \"best_bid\":\"0.45\", \"best_ask\":\"0.47\"}], \"timestamp\":\"1785207465860\", \"event_type\":\"price_change\"}","received_at":"2026-07-28T02:57:46.071315Z","schema_version":"clob-market-ws.price_change.v1","sequence":null,"server_hash":null,"server_timestamp":"1785207465860","session_id":"5aad79be415c487c84df42bebd84ee93","source":"clob_market_ws"},"received_at":"2026-07-28T02:57:46.071315Z","record_id":"c6e004ef4469797a01dbc984e664a4a44a7586810952755cd7fde41050ec6056","schema_fingerprint":"4aa3821a28b0b7c2400bc59aba4bcc0a76e971dadd19610d3ad38c768e124dc7","schema_version":"edge-lab-recorder.raw.v1","sequence":null,"source":"clob_market_ws"}
{"event_at":"2026-07-28T02:57:45.862000Z","event_fingerprint":"6c07260f75fd8b0c3a5fbff0b54bdb1f02ab8d40a4a38d674f1756c048d72ccd","payload":{"connection_id":"955646bd8bf740759faf38750c0f263f","event_at":"2026-07-28T02:57:45.862000Z","event_type":"price_change","frame_hash":"d3e0f3336c42604ea253720cc9117eb07547d983c8d152fbe4e4ede8f48da961","frame_index":0,"kind":"data","monotonic_ns":309449090268416,"payload":{"event_type":"price_change","market":"0x0f70d07969bc69eaa97d0987de651885fdca02263688026aa11e7678af8f87aa","price_changes":[{"asset_id":"58313761654877669244690227616056238030136603415514645252000528337391143520538","best_ask":"0.55","best_bid":"0.53","hash":"7b1f44625721e4c4155bc1ff01b601ae108458b9","price":"0.02","side":"BUY","size":"1060.79"},{"asset_id":"64053005904884194822931764831592250494815136296598204104072528088122126148949","best_ask":"0.47","best_bid":"0.45","hash":"f369011afbcb956cf90f5716c0a75408c406e539","price":"0.98","side":"SELL","size":"1060.79"}],"timestamp":"1785207465862"},"payload_hash":"d0485587c5432a538fb962fa44b1761222f08ed6059efd797e1dc7cdaa21e35b","raw_frame":"{\"market\":\"0x0f70d07969bc69eaa97d0987de651885fdca02263688026aa11e7678af8f87aa\", \"price_changes\":[{\"asset_id\":\"58313761654877669244690227616056238030136603415514645252000528337391143520538\", \"price\":\"0.02\", \"size\":\"1060.79\", \"side\":\"BUY\", \"hash\":\"7b1f44625721e4c4155bc1ff01b601ae108458b9\", \"best_bid\":\"0.53\", \"best_ask\":\"0.55\"}, {\"asset_id\":\"64053005904884194822931764831592250494815136296598204104072528088122126148949\", \"price\":\"0.98\", \"size\":\"1060.79\", \"side\":\"SELL\", \"hash\":\"f369011afbcb956cf90f5716c0a75408c406e539\", \"best_bid\":\"0.45\", \"best_ask\":\"0.47\"}], \"timestamp\":\"1785207465862\", \"event_type\":\"price_change\"}","received_at":"2026-07-28T02:57:46.072870Z","schema_version":"clob-market-ws.price_change.v1","sequence":null,"server_hash":null,"server_timestamp":"1785207465862","session_id":"5aad79be415c487c84df42bebd84ee93","source":"clob_market_ws"},"received_at":"2026-07-28T02:57:46.072870Z","record_id":"d52347f910b6c732c52c8b88351077a1d9e100ab41412deda8b941a4815b34a4","schema_fingerprint":"4aa3821a28b0b7c2400bc59aba4bcc0a76e971dadd19610d3ad38c768e124dc7","schema_version":"edge-lab-recorder.raw.v1","sequence":null,"source":"clob_market_ws"}
{"event_at":"2026-07-28T02:57:45.871000Z","event_fingerprint":"301557b405849390844599e3bd9ea724d168f6be3bdaa0a503f6af6fc2772694","payload":{"connection_id":"955646bd8bf740759faf38750c0f263f","event_at":"2026-07-28T02:57:45.871000Z","event_type":"price_change","frame_hash":"31e819961106c9d3e6b77da6b2f25e0a29a939efe4891963f96f9d54feb4b9a1","frame_index":0,"kind":"data","monotonic_ns":309449091862375,"payload":{"event_type":"price_change","market":"0x0f70d07969bc69eaa97d0987de651885fdca02263688026aa11e7678af8f87aa","price_changes":[{"asset_id":"64053005904884194822931764831592250494815136296598204104072528088122126148949","best_ask":"0.47","best_bid":"0.45","hash":"7fba568254332334ca7961846fa1d1e34055fa3c","price":"0.2","side":"BUY","size":"142.6"},{"asset_id":"58313761654877669244690227616056238030136603415514645252000528337391143520538","best_ask":"0.55","best_bid":"0.53","hash":"22cba4da6f9c04bd81215f66a7fcafa3ba6f11c7","price":"0.8","side":"SELL","size":"142.6"}],"timestamp":"1785207465871"},"payload_hash":"9e79a902a271af5f7cf3d9d0d443490d977a9d705d7cb425287031ee6360b229","raw_frame":"{\"market\":\"0x0f70d07969bc69eaa97d0987de651885fdca02263688026aa11e7678af8f87aa\", \"price_changes\":[{\"asset_id\":\"64053005904884194822931764831592250494815136296598204104072528088122126148949\", \"price\":\"0.2\", \"size\":\"142.6\", \"side\":\"BUY\", \"hash\":\"7fba568254332334ca7961846fa1d1e34055fa3c\", \"best_bid\":\"0.45\", \"best_ask\":\"0.47\"}, {\"asset_id\":\"58313761654877669244690227616056238030136603415514645252000528337391143520538\", \"price\":\"0.8\", \"size\":\"142.6\", \"side\":\"SELL\", \"hash\":\"22cba4da6f9c04bd81215f66a7fcafa3ba6f11c7\", \"best_bid\":\"0.53\", \"best_ask\":\"0.55\"}], \"timestamp\":\"1785207465871\", \"event_type\":\"price_change\"}","received_at":"2026-07-28T02:57:46.074466Z","schema_version":"clob-market-ws.price_change.v1","sequence":null,"server_hash":null,"server_timestamp":"1785207465871","session_id":"5aad79be415c487c84df42bebd84ee93","source":"clob_market_ws"},"received_at":"2026-07-28T02:57:46.074466Z","record_id":"07839a5a007bdd8fb1897623f197334e18cae818b70ec8c9b0cacddd18518803","schema_fingerprint":"4aa3821a28b0b7c2400bc59aba4bcc0a76e971dadd19610d3ad38c768e124dc7","schema_version":"edge-lab-recorder.raw.v1","sequence":null,"source":"clob_market_ws"}
{"event_at":"2026-07-28T02:57:45.874000Z","event_fingerprint":"fea50411fa2597bb2bbd05b2c7dcb117da1791d1d58bc21258d1a81b02967298","payload":{"connection_id":"955646bd8bf740759faf38750c0f263f","event_at":"2026-07-28T02:57:45.874000Z","event_type":"price_change","frame_hash":"7e64d92b7987739946e06244973ef5fb5f535b5adc28b20d90fe265f454fccbb","frame_index":0,"kind":"data","monotonic_ns":309449093448625,"payload":{"event_type":"price_change","market":"0x0f70d07969bc69eaa97d0987de651885fdca02263688026aa11e7678af8f87aa","price_changes":[{"asset_id":"64053005904884194822931764831592250494815136296598204104072528088122126148949","best_ask":"0.47","best_bid":"0.45","hash":"312270aa23d187deac2451ce717dbe8da4089b5d","price":"0.49","side":"SELL","size":"126.6"},{"asset_id":"58313761654877669244690227616056238030136603415514645252000528337391143520538","best_ask":"0.55","best_bid":"0.53","hash":"14bbc5a1e4a55c85112fb77dae7aa159f3477861","price":"0.51","side":"BUY","size":"126.6"}],"timestamp":"1785207465874"},"payload_hash":"99be66565d256f2c90b558058be85746db28b389dbd3ed90d966e8604ffbd152","raw_frame":"{\"market\":\"0x0f70d07969bc69eaa97d0987de651885fdca02263688026aa11e7678af8f87aa\", \"price_changes\":[{\"asset_id\":\"64053005904884194822931764831592250494815136296598204104072528088122126148949\", \"price\":\"0.49\", \"size\":\"126.6\", \"side\":\"SELL\", \"hash\":\"312270aa23d187deac2451ce717dbe8da4089b5d\", \"best_bid\":\"0.45\", \"best_ask\":\"0.47\"}, {\"asset_id\":\"58313761654877669244690227616056238030136603415514645252000528337391143520538\", \"price\":\"0.51\", \"size\":\"126.6\", \"side\":\"BUY\", \"hash\":\"14bbc5a1e4a55c85112fb77dae7aa159f3477861\", \"best_bid\":\"0.53\", \"best_ask\":\"0.55\"}], \"timestamp\":\"1785207465874\", \"event_type\":\"price_change\"}","received_at":"2026-07-28T02:57:46.076052Z","schema_version":"clob-market-ws.price_change.v1","sequence":null,"server_hash":null,"server_timestamp":"1785207465874","session_id":"5aad79be415c487c84df42bebd84ee93","source":"clob_market_ws"},"received_at":"2026-07-28T02:57:46.076052Z","record_id":"9d4d1ed4f166ad63bb82e0c69b212b798c935f9cb71bcce720cb00dc7eac555d","schema_fingerprint":"4aa3821a28b0b7c2400bc59aba4bcc0a76e971dadd19610d3ad38c768e124dc7","schema_version":"edge-lab-recorder.raw.v1","sequence":null,"source":"clob_market_ws"}
{"event_at":"2026-07-28T02:57:45.874000Z","event_fingerprint":"9585da8cd9640e56f662e16317406e231450ce4667c596ebacdb48c0ccc1713c","payload":{"connection_id":"955646bd8bf740759faf38750c0f263f","event_at":"2026-07-28T02:57:45.874000Z","event_type":"price_change","frame_hash":"d3779ca7c4b7dd1f22e82528e7637e6f6b431616fffc9976932829b18b2e2eb1","frame_index":0,"kind":"data","monotonic_ns":309449094958208,"payload":{"event_type":"price_change","market":"0x0f70d07969bc69eaa97d0987de651885fdca02263688026aa11e7678af8f87aa","price_changes":[{"asset_id":"58313761654877669244690227616056238030136603415514645252000528337391143520538","best_ask":"0.55","best_bid":"0.53","hash":"0fb0af22f424bbde6eb922f3ce7be795782e748a","price":"0.29","side":"BUY","size":"100.81"},{"asset_id":"64053005904884194822931764831592250494815136296598204104072528088122126148949","best_ask":"0.47","best_bid":"0.45","hash":"d0f99fa94eb07d91e0979a2652f46a7e77d51488","price":"0.71","side":"SELL","size":"100.81"}],"timestamp":"1785207465874"},"payload_hash":"e61586cacb215b992e94aa48e2f5b75998fb4785ecf7c8fddb3232764eeec046","raw_frame":"{\"market\":\"0x0f70d07969bc69eaa97d0987de651885fdca02263688026aa11e7678af8f87aa\", \"price_changes\":[{\"asset_id\":\"58313761654877669244690227616056238030136603415514645252000528337391143520538\", \"price\":\"0.29\", \"size\":\"100.81\", \"side\":\"BUY\", \"hash\":\"0fb0af22f424bbde6eb922f3ce7be795782e748a\", \"best_bid\":\"0.53\", \"best_ask\":\"0.55\"}, {\"asset_id\":\"64053005904884194822931764831592250494815136296598204104072528088122126148949\", \"price\":\"0.71\", \"size\":\"100.81\", \"side\":\"SELL\", \"hash\":\"d0f99fa94eb07d91e0979a2652f46a7e77d51488\", \"best_bid\":\"0.45\", \"best_ask\":\"0.47\"}], \"timestamp\":\"1785207465874\", \"event_type\":\"price_change\"}","received_at":"2026-07-28T02:57:46.077562Z","schema_version":"clob-market-ws.price_change.v1","sequence":null,"server_hash":null,"server_timestamp":"1785207465874","session_id":"5aad79be415c487c84df42bebd84ee93","source":"clob_market_ws"},"received_at":"2026-07-28T02:57:46.077562Z","record_id":"7d7554b23bae39d38ba5140228d7d7df147652d7c39dd3e39fe07e719b7bfbb2","schema_fingerprint":"4aa3821a28b0b7c2400bc59aba4bcc0a76e971dadd19610d3ad38c768e124dc7","schema_version":"edge-lab-recorder.raw.v1","sequence":null,"source":"clob_market_ws"}
{"event_at":"2026-07-28T02:57:45.880000Z","event_fingerprint":"20a1eaf9c83460c04e83154144b70a7711733cf492b2f0ee5d3c9c1bdc620cc4","payload":{"connection_id":"955646bd8bf740759faf38750c0f263f","event_at":"2026-07-28T02:57:45.880000Z","event_type":"price_change","frame_hash":"394734cd88712e626ff4970ba12e86ddf8b0a53caeeb4f39084ac3898f09b070","frame_index":0,"kind":"data","monotonic_ns":309449096463708,"payload":{"event_type":"price_change","market":"0x0f70d07969bc69eaa97d0987de651885fdca02263688026aa11e7678af8f87aa","price_changes":[{"asset_id":"64053005904884194822931764831592250494815136296598204104072528088122126148949","best_ask":"0.47","best_bid":"0.45","hash":"7fb057241698f3d708ef542c318ff7eaf7a828b6","price":"0.77","side":"SELL","size":"113.3"},{"asset_id":"58313761654877669244690227616056238030136603415514645252000528337391143520538","best_ask":"0.55","best_bid":"0.53","hash":"8f51dcceb6246ba7f13f26113fc553a7ac198842","price":"0.23","side":"BUY","size":"113.3"}],"timestamp":"1785207465880"},"payload_hash":"30a42bcd3e86141c509c489625f11bfef63b63a64cd65d5148a4c5360532bad5","raw_frame":"{\"market\":\"0x0f70d07969bc69eaa97d0987de651885fdca02263688026aa11e7678af8f87aa\", \"price_changes\":[{\"asset_id\":\"64053005904884194822931764831592250494815136296598204104072528088122126148949\", \"price\":\"0.77\", \"size\":\"113.3\", \"side\":\"SELL\", \"hash\":\"7fb057241698f3d708ef542c318ff7eaf7a828b6\", \"best_bid\":\"0.45\", \"best_ask\":\"0.47\"}, {\"asset_id\":\"58313761654877669244690227616056238030136603415514645252000528337391143520538\", \"price\":\"0.23\", \"size\":\"113.3\", \"side\":\"BUY\", \"hash\":\"8f51dcceb6246ba7f13f26113fc553a7ac198842\", \"best_bid\":\"0.53\", \"best_ask\":\"0.55\"}], \"timestamp\":\"1785207465880\", \"event_type\":\"price_change\"}","received_at":"2026-07-28T02:57:46.079066Z","schema_version":"clob-market-ws.price_change.v1","sequence":null,"server_hash":null,"server_timestamp":"1785207465880","session_id":"5aad79be415c487c84df42bebd84ee93","source":"clob_market_ws"},"received_at":"2026-07-28T02:57:46.079066Z","record_id":"2ca3147fa3f92d1fb092cd88206f57d712d9cba27a9ffbcc3312adefd7495c88","schema_fingerprint":"4aa3821a28b0b7c2400bc59aba4bcc0a76e971dadd19610d3ad38c768e124dc7","schema_version":"edge-lab-recorder.raw.v1","sequence":null,"source":"clob_market_ws"}
{"event_at":"2026-07-28T02:57:45.890000Z","event_fingerprint":"757e32762cc74def71d2a0f40d69308980d125057110ce58ac8f575e84d105b5","payload":{"connection_id":"955646bd8bf740759faf38750c0f263f","event_at":"2026-07-28T02:57:45.890000Z","event_type":"price_change","frame_hash":"ee6e652f3888b5f44bc30ad2d3f27eef00c4245ce05a45ff6916eda6dcfabc40","frame_index":0,"kind":"data","monotonic_ns":309449097974500,"payload":{"event_type":"price_change","market":"0x0f70d07969bc69eaa97d0987de651885fdca02263688026aa11e7678af8f87aa","price_changes":[{"asset_id":"64053005904884194822931764831592250494815136296598204104072528088122126148949","best_ask":"0.47","best_bid":"0.45","hash":"4dc89ec50b4ddb7ca89282cf19d3188843c616f4","price":"0.3","side":"BUY","size":"187.99"},{"asset_id":"58313761654877669244690227616056238030136603415514645252000528337391143520538","best_ask":"0.55","best_bid":"0.53","hash":"4b3970af78e44661951f6ef3abac8689e494abfa","price":"0.7","side":"SELL","size":"187.99"}],"timestamp":"1785207465890"},"payload_hash":"c99ed0c769df6c3a2d402dd06bfb90a6f6713374f4e5a108b78ec5bd51cdf7d4","raw_frame":"{\"market\":\"0x0f70d07969bc69eaa97d0987de651885fdca02263688026aa11e7678af8f87aa\", \"price_changes\":[{\"asset_id\":\"64053005904884194822931764831592250494815136296598204104072528088122126148949\", \"price\":\"0.3\", \"size\":\"187.99\", \"side\":\"BUY\", \"hash\":\"4dc89ec50b4ddb7ca89282cf19d3188843c616f4\", \"best_bid\":\"0.45\", \"best_ask\":\"0.47\"}, {\"asset_id\":\"58313761654877669244690227616056238030136603415514645252000528337391143520538\", \"price\":\"0.7\", \"size\":\"187.99\", \"side\":\"SELL\", \"hash\":\"4b3970af78e44661951f6ef3abac8689e494abfa\", \"best_bid\":\"0.53\", \"best_ask\":\"0.55\"}], \"timestamp\":\"1785207465890\", \"event_type\":\"price_change\"}","received_at":"2026-07-28T02:57:46.080578Z","schema_version":"clob-market-ws.price_change.v1","sequence":null,"server_hash":null,"server_timestamp":"1785207465890","session_id":"5aad79be415c487c84df42bebd84ee93","source":"clob_market_ws"},"received_at":"2026-07-28T02:57:46.080578Z","record_id":"ea2db0d2666d432430768378aad3fae686f88622d1ab28773ea2ccd752e17841","schema_fingerprint":"4aa3821a28b0b7c2400bc59aba4bcc0a76e971dadd19610d3ad38c768e124dc7","schema_version":"edge-lab-recorder.raw.v1","sequence":null,"source":"clob_market_ws"}
{"event_at":"2026-07-28T02:57:45.893000Z","event_fingerprint":"33d4c5c9b22fd967222dcef07387735dde80b309c8fb0f5c1fb7105558f4ba08","payload":{"connection_id":"955646bd8bf740759faf38750c0f263f","event_at":"2026-07-28T02:57:45.893000Z","event_type":"price_change","frame_hash":"d46db84c3a634b2c31649834635e9d31d5be329bea1bb354ede1eff7ff4b8222","frame_index":0,"kind":"data","monotonic_ns":309449099457000,"payload":{"event_type":"price_change","market":"0x0f70d07969bc69eaa97d0987de651885fdca02263688026aa11e7678af8f87aa","price_changes":[{"asset_id":"64053005904884194822931764831592250494815136296598204104072528088122126148949","best_ask":"0.47","best_bid":"0.45","hash":"9832d50d85e5c3d01fc18ca87d7d4ae879c90d70","price":"0.36","side":"BUY","size":"105.39"},{"asset_id":"58313761654877669244690227616056238030136603415514645252000528337391143520538","best_ask":"0.55","best_bid":"0.53","hash":"9090c307df0081a70fe94288032448043aa63c31","price":"0.64","side":"SELL","size":"105.39"}],"timestamp":"1785207465893"},"payload_hash":"a930d056c04440fb8d786e7699dffa2185dd1a28dfd2f2599b5f633c020a05e3","raw_frame":"{\"market\":\"0x0f70d07969bc69eaa97d0987de651885fdca02263688026aa11e7678af8f87aa\", \"price_changes\":[{\"asset_id\":\"64053005904884194822931764831592250494815136296598204104072528088122126148949\", \"price\":\"0.36\", \"size\":\"105.39\", \"side\":\"BUY\", \"hash\":\"9832d50d85e5c3d01fc18ca87d7d4ae879c90d70\", \"best_bid\":\"0.45\", \"best_ask\":\"0.47\"}, {\"asset_id\":\"58313761654877669244690227616056238030136603415514645252000528337391143520538\", \"price\":\"0.64\", \"size\":\"105.39\", \"side\":\"SELL\", \"hash\":\"9090c307df0081a70fe94288032448043aa63c31\", \"best_bid\":\"0.53\", \"best_ask\":\"0.55\"}], \"timestamp\":\"1785207465893\", \"event_type\":\"price_change\"}","received_at":"2026-07-28T02:57:46.082061Z","schema_version":"clob-market-ws.price_change.v1","sequence":null,"server_hash":null,"server_timestamp":"1785207465893","session_id":"5aad79be415c487c84df42bebd84ee93","source":"clob_market_ws"},"received_at":"2026-07-28T02:57:46.082061Z","record_id":"5450285a86d1f5c5386464541dc1dced9f0c1c711b8264f30102a597128ed3fc","schema_fingerprint":"4aa3821a28b0b7c2400bc59aba4bcc0a76e971dadd19610d3ad38c768e124dc7","schema_version":"edge-lab-recorder.raw.v1","sequence":null,"source":"clob_market_ws"}
{"event_at":"2026-07-28T02:57:45.901000Z","event_fingerprint":"c29b4d9c50231e632d2125312383489dc1c3ad9f9ba712f85e2d486c9e450708","payload":{"connection_id":"955646bd8bf740759faf38750c0f263f","event_at":"2026-07-28T02:57:45.901000Z","event_type":"price_change","frame_hash":"72eafbb4fd548f0f2c4c4cb32e7fd61ebe08733eb901a4d0b0581cf23b3f2c8f","frame_index":0,"kind":"data","monotonic_ns":309449100949250,"payload":{"event_type":"price_change","market":"0x0f70d07969bc69eaa97d0987de651885fdca02263688026aa11e7678af8f87aa","price_changes":[{"asset_id":"64053005904884194822931764831592250494815136296598204104072528088122126148949","best_ask":"0.47","best_bid":"0.45","hash":"f374b46297dd1c5a3bbb90cb1b29c59b24c2fcc9","price":"0.01","side":"BUY","size":"2895.52"},{"asset_id":"58313761654877669244690227616056238030136603415514645252000528337391143520538","best_ask":"0.55","best_bid":"0.53","hash":"9d3767aecb03a99791c658fcecd593748f017af4","price":"0.99","side":"SELL","size":"2895.52"}],"timestamp":"1785207465901"},"payload_hash":"fa39ea44c606e729b71557a4fb9cbc7d9198176ba1118e7425f0eed23e8d99b6","raw_frame":"{\"market\":\"0x0f70d07969bc69eaa97d0987de651885fdca02263688026aa11e7678af8f87aa\", \"price_changes\":[{\"asset_id\":\"64053005904884194822931764831592250494815136296598204104072528088122126148949\", \"price\":\"0.01\", \"size\":\"2895.52\", \"side\":\"BUY\", \"hash\":\"f374b46297dd1c5a3bbb90cb1b29c59b24c2fcc9\", \"best_bid\":\"0.45\", \"best_ask\":\"0.47\"}, {\"asset_id\":\"58313761654877669244690227616056238030136603415514645252000528337391143520538\", \"price\":\"0.99\", \"size\":\"2895.52\", \"side\":\"SELL\", \"hash\":\"9d3767aecb03a99791c658fcecd593748f017af4\", \"best_bid\":\"0.53\", \"best_ask\":\"0.55\"}], \"timestamp\":\"1785207465901\", \"event_type\":\"price_change\"}","received_at":"2026-07-28T02:57:46.083553Z","schema_version":"clob-market-ws.price_change.v1","sequence":null,"server_hash":null,"server_timestamp":"1785207465901","session_id":"5aad79be415c487c84df42bebd84ee93","source":"clob_market_ws"},"received_at":"2026-07-28T02:57:46.083553Z","record_id":"a718aea572d36031c694ccb69b10582ba5de5c54b518cf730aad37b757c00721","schema_fingerprint":"4aa3821a28b0b7c2400bc59aba4bcc0a76e971dadd19610d3ad38c768e124dc7","schema_version":"edge-lab-recorder.raw.v1","sequence":null,"source":"clob_market_ws"}
{"event_at":"2026-07-28T02:57:45.903000Z","event_fingerprint":"ea99769005e0c890ae30c7f0668099d79d7f77533b42a01d45132db4e93732af","payload":{"connection_id":"955646bd8bf740759faf38750c0f263f","event_at":"2026-07-28T02:57:45.903000Z","event_type":"price_change","frame_hash":"3f247720c8f8e6ea9a32252faf8c7b753c40ce996e20ddefdb9a6c5270ca1d26","frame_index":0,"kind":"data","monotonic_ns":309449102413333,"payload":{"event_type":"price_change","market":"0x0f70d07969bc69eaa97d0987de651885fdca02263688026aa11e7678af8f87aa","price_changes":[{"asset_id":"58313761654877669244690227616056238030136603415514645252000528337391143520538","best_ask":"0.55","best_bid":"0.53","hash":"e3586fe21484fa884b55e609a25f1c811d0f92fb","price":"0.01","side":"BUY","size":"2371.24"},{"asset_id":"64053005904884194822931764831592250494815136296598204104072528088122126148949","best_ask":"0.47","best_bid":"0.45","hash":"5a9e59d6be11f1f5014cbfe5eeea32d1c46c3404","price":"0.99","side":"SELL","size":"2371.24"}],"timestamp":"1785207465903"},"payload_hash":"f19c9dd4d13bc2fe18294d57ded386480f28a21b6a1f5edef077a488c55ea8a4","raw_frame":"{\"market\":\"0x0f70d07969bc69eaa97d0987de651885fdca02263688026aa11e7678af8f87aa\", \"price_changes\":[{\"asset_id\":\"58313761654877669244690227616056238030136603415514645252000528337391143520538\", \"price\":\"0.01\", \"size\":\"2371.24\", \"side\":\"BUY\", \"hash\":\"e3586fe21484fa884b55e609a25f1c811d0f92fb\", \"best_bid\":\"0.53\", \"best_ask\":\"0.55\"}, {\"asset_id\":\"64053005904884194822931764831592250494815136296598204104072528088122126148949\", \"price\":\"0.99\", \"size\":\"2371.24\", \"side\":\"SELL\", \"hash\":\"5a9e59d6be11f1f5014cbfe5eeea32d1c46c3404\", \"best_bid\":\"0.45\", \"best_ask\":\"0.47\"}], \"timestamp\":\"1785207465903\", \"event_type\":\"price_change\"}","received_at":"2026-07-28T02:57:46.085017Z","schema_version":"clob-market-ws.price_change.v1","sequence":null,"server_hash":null,"server_timestamp":"1785207465903","session_id":"5aad79be415c487c84df42bebd84ee93","source":"clob_market_ws"},"received_at":"2026-07-28T02:57:46.085017Z","record_id":"4b6c5b48ea7dbde58b0a2da1409562a67e0bb545b6c30bc23ec842b2197807fe","schema_fingerprint":"4aa3821a28b0b7c2400bc59aba4bcc0a76e971dadd19610d3ad38c768e124dc7","schema_version":"edge-lab-recorder.raw.v1","sequence":null,"source":"clob_market_ws"}
{"event_at":"2026-07-28T02:57:45.909000Z","event_fingerprint":"6ff1afb0a885c05083f2405a575f938edcd23ec294960cfc20abd0066bb6777f","payload":{"connection_id":"955646bd8bf740759faf38750c0f263f","event_at":"2026-07-28T02:57:45.909000Z","event_type":"price_change","frame_hash":"95bb6dd13d018ad0f7ddcccb9fafa0f228b9ed6555e24317eec245eeb2f09e3b","frame_index":0,"kind":"data","monotonic_ns":309449103920125,"payload":{"event_type":"price_change","market":"0x0f70d07969bc69eaa97d0987de651885fdca02263688026aa11e7678af8f87aa","price_changes":[{"asset_id":"64053005904884194822931764831592250494815136296598204104072528088122126148949","best_ask":"0.47","best_bid":"0.45","hash":"1006a7bd5ec428d1f1e478ef1a585f154e9b775c","price":"0.42","side":"BUY","size":"5"},{"asset_id":"58313761654877669244690227616056238030136603415514645252000528337391143520538","best_ask":"0.55","best_bid":"0.53","hash":"360bd9488dc1e10434837cf87e709945d7aeb57c","price":"0.58","side":"SELL","size":"5"}],"timestamp":"1785207465909"},"payload_hash":"1506b16c5d0b21bb7a05118604b192f8799fafc1926825ebbb84879f1e2222d6","raw_frame":"{\"market\":\"0x0f70d07969bc69eaa97d0987de651885fdca02263688026aa11e7678af8f87aa\", \"price_changes\":[{\"asset_id\":\"64053005904884194822931764831592250494815136296598204104072528088122126148949\", \"price\":\"0.42\", \"size\":\"5\", \"side\":\"BUY\", \"hash\":\"1006a7bd5ec428d1f1e478ef1a585f154e9b775c\", \"best_bid\":\"0.45\", \"best_ask\":\"0.47\"}, {\"asset_id\":\"58313761654877669244690227616056238030136603415514645252000528337391143520538\", \"price\":\"0.58\", \"size\":\"5\", \"side\":\"SELL\", \"hash\":\"360bd9488dc1e10434837cf87e709945d7aeb57c\", \"best_bid\":\"0.53\", \"best_ask\":\"0.55\"}], \"timestamp\":\"1785207465909\", \"event_type\":\"price_change\"}","received_at":"2026-07-28T02:57:46.086523Z","schema_version":"clob-market-ws.price_change.v1","sequence":null,"server_hash":null,"server_timestamp":"1785207465909","session_id":"5aad79be415c487c84df42bebd84ee93","source":"clob_market_ws"},"received_at":"2026-07-28T02:57:46.086523Z","record_id":"2e271f0b4df11e70cbcb6060ce68663f05b73f318372dc990ede32349a2fc7ef","schema_fingerprint":"4aa3821a28b0b7c2400bc59aba4bcc0a76e971dadd19610d3ad38c768e124dc7","schema_version":"edge-lab-recorder.raw.v1","sequence":null,"source":"clob_market_ws"}
{"event_at":"2026-07-28T02:57:45.913000Z","event_fingerprint":"5fd6a05304b3238e82983bf03787d25af781cc9d7d22696630fd26f364a432fd","payload":{"connection_id":"955646bd8bf740759faf38750c0f263f","event_at":"2026-07-28T02:57:45.913000Z","event_type":"price_change","frame_hash":"a28cab74dfced3d422b8fdafdcedebea9f04af053c8f745b49e29283ae663d17","frame_index":0,"kind":"data","monotonic_ns":309449108234708,"payload":{"event_type":"price_change","market":"0x0f70d07969bc69eaa97d0987de651885fdca02263688026aa11e7678af8f87aa","price_changes":[{"asset_id":"64053005904884194822931764831592250494815136296598204104072528088122126148949","best_ask":"0.47","best_bid":"0.45","hash":"8b1fafc1e316c1fdb94bda26c937e070682c8434","price":"0.45","side":"BUY","size":"16.01"},{"asset_id":"58313761654877669244690227616056238030136603415514645252000528337391143520538","best_ask":"0.55","best_bid":"0.53","hash":"3574c5fc52459a4c022c5409b705c76b913fe253","price":"0.55","side":"SELL","size":"16.01"}],"timestamp":"1785207465913"},"payload_hash":"798239e26742729fa486deaadadadae87d24793507af3bae162bcced71a06dbc","raw_frame":"{\"market\":\"0x0f70d07969bc69eaa97d0987de651885fdca02263688026aa11e7678af8f87aa\", \"price_changes\":[{\"asset_id\":\"64053005904884194822931764831592250494815136296598204104072528088122126148949\", \"price\":\"0.45\", \"size\":\"16.01\", \"side\":\"BUY\", \"hash\":\"8b1fafc1e316c1fdb94bda26c937e070682c8434\", \"best_bid\":\"0.45\", \"best_ask\":\"0.47\"}, {\"asset_id\":\"58313761654877669244690227616056238030136603415514645252000528337391143520538\", \"price\":\"0.55\", \"size\":\"16.01\", \"side\":\"SELL\", \"hash\":\"3574c5fc52459a4c022c5409b705c76b913fe253\", \"best_bid\":\"0.53\", \"best_ask\":\"0.55\"}], \"timestamp\":\"1785207465913\", \"event_type\":\"price_change\"}","received_at":"2026-07-28T02:57:46.090837Z","schema_version":"clob-market-ws.price_change.v1","sequence":null,"server_hash":null,"server_timestamp":"1785207465913","session_id":"5aad79be415c487c84df42bebd84ee93","source":"clob_market_ws"},"received_at":"2026-07-28T02:57:46.090837Z","record_id":"480a4e459616c9df03ed4b5681856f8820a29ecb2805e7946b5f4c530b63d202","schema_fingerprint":"4aa3821a28b0b7c2400bc59aba4bcc0a76e971dadd19610d3ad38c768e124dc7","schema_version":"edge-lab-recorder.raw.v1","sequence":null,"source":"clob_market_ws"}
{"event_at":"2026-07-28T02:57:45.934000Z","event_fingerprint":"9d2049a7a084b8ea476634b65f1ac8a621b38b6e0b611b35c3c59f53c1375382","payload":{"connection_id":"955646bd8bf740759faf38750c0f263f","event_at":"2026-07-28T02:57:45.934000Z","event_type":"price_change","frame_hash":"5b1cfc31a83c4f8bf90c00aae2ff5fcbcc238073bf4279eb930ea7e5a98bd6fd","frame_index":0,"kind":"data","monotonic_ns":309449110686916,"payload":{"event_type":"price_change","market":"0x0f70d07969bc69eaa97d0987de651885fdca02263688026aa11e7678af8f87aa","price_changes":[{"asset_id":"64053005904884194822931764831592250494815136296598204104072528088122126148949","best_ask":"0.47","best_bid":"0.45","hash":"ee48c8981b86530305ff1097e1d12bc8531463c7","price":"0.45","side":"BUY","size":"23.01"},{"asset_id":"58313761654877669244690227616056238030136603415514645252000528337391143520538","best_ask":"0.55","best_bid":"0.53","hash":"654ca30f29515b287e7f6cd81f5fa3587077d0cb","price":"0.55","side":"SELL","size":"23.01"}],"timestamp":"1785207465934"},"payload_hash":"b347ca2537790de3ca33202b3d201521b7aebc8b1770a28238e3ddab84077aa2","raw_frame":"{\"market\":\"0x0f70d07969bc69eaa97d0987de651885fdca02263688026aa11e7678af8f87aa\", \"price_changes\":[{\"asset_id\":\"64053005904884194822931764831592250494815136296598204104072528088122126148949\", \"price\":\"0.45\", \"size\":\"23.01\", \"side\":\"BUY\", \"hash\":\"ee48c8981b86530305ff1097e1d12bc8531463c7\", \"best_bid\":\"0.45\", \"best_ask\":\"0.47\"}, {\"asset_id\":\"58313761654877669244690227616056238030136603415514645252000528337391143520538\", \"price\":\"0.55\", \"size\":\"23.01\", \"side\":\"SELL\", \"hash\":\"654ca30f29515b287e7f6cd81f5fa3587077d0cb\", \"best_bid\":\"0.53\", \"best_ask\":\"0.55\"}], \"timestamp\":\"1785207465934\", \"event_type\":\"price_change\"}","received_at":"2026-07-28T02:57:46.093289Z","schema_version":"clob-market-ws.price_change.v1","sequence":null,"server_hash":null,"server_timestamp":"1785207465934","session_id":"5aad79be415c487c84df42bebd84ee93","source":"clob_market_ws"},"received_at":"2026-07-28T02:57:46.093289Z","record_id":"d6dacc34d78ffe93fb3752651de2c03ce8eb1ec2185be04dd2027ca2b574ed8e","schema_fingerprint":"4aa3821a28b0b7c2400bc59aba4bcc0a76e971dadd19610d3ad38c768e124dc7","schema_version":"edge-lab-recorder.raw.v1","sequence":null,"source":"clob_market_ws"}
{"event_at":"2026-07-28T02:57:45.947000Z","event_fingerprint":"51295a204f8a248febce4e93a71680b3972795a97444ac293624b109ca919c95","payload":{"connection_id":"955646bd8bf740759faf38750c0f263f","event_at":"2026-07-28T02:57:45.947000Z","event_type":"price_change","frame_hash":"f8d88b1fca370dc057451f3512d748dda51f23dc5bca44f14db133f00342ee5c","frame_index":0,"kind":"data","monotonic_ns":309449113281000,"payload":{"event_type":"price_change","market":"0x0f70d07969bc69eaa97d0987de651885fdca02263688026aa11e7678af8f87aa","price_changes":[{"asset_id":"58313761654877669244690227616056238030136603415514645252000528337391143520538","best_ask":"0.55","best_bid":"0.53","hash":"83e98198bbe27c76843733c18813aec1e86ffb13","price":"0.5","side":"BUY","size":"114.7"},{"asset_id":"64053005904884194822931764831592250494815136296598204104072528088122126148949","best_ask":"0.47","best_bid":"0.45","hash":"188e1caa50d7e50aa3b0a682388b29976e87d3c8","price":"0.5","side":"SELL","size":"114.7"}],"timestamp":"1785207465947"},"payload_hash":"020ff5361f6b98b8a81af500fc8bfd08b95f7b1539abb0302739a79c442c6289","raw_frame":"{\"market\":\"0x0f70d07969bc69eaa97d0987de651885fdca02263688026aa11e7678af8f87aa\", \"price_changes\":[{\"asset_id\":\"58313761654877669244690227616056238030136603415514645252000528337391143520538\", \"price\":\"0.5\", \"size\":\"114.7\", \"side\":\"BUY\", \"hash\":\"83e98198bbe27c76843733c18813aec1e86ffb13\", \"best_bid\":\"0.53\", \"best_ask\":\"0.55\"}, {\"asset_id\":\"64053005904884194822931764831592250494815136296598204104072528088122126148949\", \"price\":\"0.5\", \"size\":\"114.7\", \"side\":\"SELL\", \"hash\":\"188e1caa50d7e50aa3b0a682388b29976e87d3c8\", \"best_bid\":\"0.45\", \"best_ask\":\"0.47\"}], \"timestamp\":\"1785207465947\", \"event_type\":\"price_change\"}","received_at":"2026-07-28T02:57:46.095884Z","schema_version":"clob-market-ws.price_change.v1","sequence":null,"server_hash":null,"server_timestamp":"1785207465947","session_id":"5aad79be415c487c84df42bebd84ee93","source":"clob_market_ws"},"received_at":"2026-07-28T02:57:46.095884Z","record_id":"62f6f8c5c8a392e27db81ade5705aba636943dd7bb219c895d41553755f2bc3a","schema_fingerprint":"4aa3821a28b0b7c2400bc59aba4bcc0a76e971dadd19610d3ad38c768e124dc7","schema_version":"edge-lab-recorder.raw.v1","sequence":null,"source":"clob_market_ws"}
{"event_at":"2026-07-28T02:57:45.960000Z","event_fingerprint":"23ecb001d2219688b2945bf001a99a942e8d3e72d2c32431e26a8324947b95a0","payload":{"connection_id":"955646bd8bf740759faf38750c0f263f","event_at":"2026-07-28T02:57:45.960000Z","event_type":"price_change","frame_hash":"9e0f06e5f9896d74f9d84e89b31f95bd7f872a6810a47421975ff6ef1b0d6634","frame_index":0,"kind":"data","monotonic_ns":309449124457041,"payload":{"event_type":"price_change","market":"0x0f70d07969bc69eaa97d0987de651885fdca02263688026aa11e7678af8f87aa","price_changes":[{"asset_id":"58313761654877669244690227616056238030136603415514645252000528337391143520538","best_ask":"0.55","best_bid":"0.53","hash":"df674771c0298d21cb90e64f764b21d39ed06c7c","price":"0.02","side":"BUY","size":"1065.79"},{"asset_id":"64053005904884194822931764831592250494815136296598204104072528088122126148949","best_ask":"0.47","best_bid":"0.45","hash":"e6b15da498d2d5e46972977c2e05c9d7d759e486","price":"0.98","side":"SELL","size":"1065.79"}],"timestamp":"1785207465960"},"payload_hash":"29443b6dbdbe4f6c44949c0f0e9e76385ac75eb255f0c413635e279a3730560f","raw_frame":"{\"market\":\"0x0f70d07969bc69eaa97d0987de651885fdca02263688026aa11e7678af8f87aa\", \"price_changes\":[{\"asset_id\":\"58313761654877669244690227616056238030136603415514645252000528337391143520538\", \"price\":\"0.02\", \"size\":\"1065.79\", \"side\":\"BUY\", \"hash\":\"df674771c0298d21cb90e64f764b21d39ed06c7c\", \"best_bid\":\"0.53\", \"best_ask\":\"0.55\"}, {\"asset_id\":\"64053005904884194822931764831592250494815136296598204104072528088122126148949\", \"price\":\"0.98\", \"size\":\"1065.79\", \"side\":\"SELL\", \"hash\":\"e6b15da498d2d5e46972977c2e05c9d7d759e486\", \"best_bid\":\"0.45\", \"best_ask\":\"0.47\"}], \"timestamp\":\"1785207465960\", \"event_type\":\"price_change\"}","received_at":"2026-07-28T02:57:46.107055Z","schema_version":"clob-market-ws.price_change.v1","sequence":null,"server_hash":null,"server_timestamp":"1785207465960","session_id":"5aad79be415c487c84df42bebd84ee93","source":"clob_market_ws"},"received_at":"2026-07-28T02:57:46.107055Z","record_id":"6b628c8207a67e7907f0b8c1128e3fa33b499ee28626e1252f3854b0399315a1","schema_fingerprint":"4aa3821a28b0b7c2400bc59aba4bcc0a76e971dadd19610d3ad38c768e124dc7","schema_version":"edge-lab-recorder.raw.v1","sequence":null,"source":"clob_market_ws"}
{"event_at":"2026-07-28T02:57:45.980000Z","event_fingerprint":"c07966c4ab3e1b78f7c3b037adae9350ddaf9bab6fb379ce7b94f863a9a91e9d","payload":{"connection_id":"955646bd8bf740759faf38750c0f263f","event_at":"2026-07-28T02:57:45.980000Z","event_type":"price_change","frame_hash":"c427adadb93bdc75cc2410ae63043fcf91c1601387d842479ebc4e11cf262d83","frame_index":0,"kind":"data","monotonic_ns":309449126230291,"payload":{"event_type":"price_change","market":"0x0f70d07969bc69eaa97d0987de651885fdca02263688026aa11e7678af8f87aa","price_changes":[{"asset_id":"64053005904884194822931764831592250494815136296598204104072528088122126148949","best_ask":"0.47","best_bid":"0.45","hash":"4b7fe101affc2306d473ec9d4cce7e4745f3b951","price":"0.31","side":"BUY","size":"122.9"},{"asset_id":"58313761654877669244690227616056238030136603415514645252000528337391143520538","best_ask":"0.55","best_bid":"0.53","hash":"1dabe1a0b818a7d54f638e1f83c666d92ed79d7c","price":"0.69","side":"SELL","size":"122.9"}],"timestamp":"1785207465980"},"payload_hash":"3d5d030d0c2e623c6f16563498e05cf92cded81471e0b5f881259d140d9208e2","raw_frame":"{\"market\":\"0x0f70d07969bc69eaa97d0987de651885fdca02263688026aa11e7678af8f87aa\", \"price_changes\":[{\"asset_id\":\"64053005904884194822931764831592250494815136296598204104072528088122126148949\", \"price\":\"0.31\", \"size\":\"122.9\", \"side\":\"BUY\", \"hash\":\"4b7fe101affc2306d473ec9d4cce7e4745f3b951\", \"best_bid\":\"0.45\", \"best_ask\":\"0.47\"}, {\"asset_id\":\"58313761654877669244690227616056238030136603415514645252000528337391143520538\", \"price\":\"0.69\", \"size\":\"122.9\", \"side\":\"SELL\", \"hash\":\"1dabe1a0b818a7d54f638e1f83c666d92ed79d7c\", \"best_bid\":\"0.53\", \"best_ask\":\"0.55\"}], \"timestamp\":\"1785207465980\", \"event_type\":\"price_change\"}","received_at":"2026-07-28T02:57:46.108831Z","schema_version":"clob-market-ws.price_change.v1","sequence":null,"server_hash":null,"server_timestamp":"1785207465980","session_id":"5aad79be415c487c84df42bebd84ee93","source":"clob_market_ws"},"received_at":"2026-07-28T02:57:46.108831Z","record_id":"bed874e59c3824038b281cb15406ad1ed245c71e38670c149777bb3da5fb9397","schema_fingerprint":"4aa3821a28b0b7c2400bc59aba4bcc0a76e971dadd19610d3ad38c768e124dc7","schema_version":"edge-lab-recorder.raw.v1","sequence":null,"source":"clob_market_ws"}
{"event_at":"2026-07-28T02:57:46.009000Z","event_fingerprint":"5dbf165371f91b14341119a0188bf75a055268e0d0728297bdd7944e919d57c4","payload":{"connection_id":"955646bd8bf740759faf38750c0f263f","event_at":"2026-07-28T02:57:46.009000Z","event_type":"price_change","frame_hash":"f7d556416bff43298164cf5e0cb2bab9b6cf90c4e0a5824be318be948c3702ba","frame_index":0,"kind":"data","monotonic_ns":309449127795750,"payload":{"event_type":"price_change","market":"0x0f70d07969bc69eaa97d0987de651885fdca02263688026aa11e7678af8f87aa","price_changes":[{"asset_id":"58313761654877669244690227616056238030136603415514645252000528337391143520538","best_ask":"0.55","best_bid":"0.53","hash":"eaf37a32291828631a9b1ec5596c2068137f0a08","price":"0.02","side":"BUY","size":"1060.79"},{"asset_id":"64053005904884194822931764831592250494815136296598204104072528088122126148949","best_ask":"0.47","best_bid":"0.45","hash":"b77b81a0195d09d3cf9f9a8598eebd9383550473","price":"0.98","side":"SELL","size":"1060.79"}],"timestamp":"1785207466009"},"payload_hash":"080387925c10f8bcf9f7ac42bb4fea5350bf2e4d838749f93dbc9e87db580ae4","raw_frame":"{\"market\":\"0x0f70d07969bc69eaa97d0987de651885fdca02263688026aa11e7678af8f87aa\", \"price_changes\":[{\"asset_id\":\"58313761654877669244690227616056238030136603415514645252000528337391143520538\", \"price\":\"0.02\", \"size\":\"1060.79\", \"side\":\"BUY\", \"hash\":\"eaf37a32291828631a9b1ec5596c2068137f0a08\", \"best_bid\":\"0.53\", \"best_ask\":\"0.55\"}, {\"asset_id\":\"64053005904884194822931764831592250494815136296598204104072528088122126148949\", \"price\":\"0.98\", \"size\":\"1060.79\", \"side\":\"SELL\", \"hash\":\"b77b81a0195d09d3cf9f9a8598eebd9383550473\", \"best_bid\":\"0.45\", \"best_ask\":\"0.47\"}], \"timestamp\":\"1785207466009\", \"event_type\":\"price_change\"}","received_at":"2026-07-28T02:57:46.110398Z","schema_version":"clob-market-ws.price_change.v1","sequence":null,"server_hash":null,"server_timestamp":"1785207466009","session_id":"5aad79be415c487c84df42bebd84ee93","source":"clob_market_ws"},"received_at":"2026-07-28T02:57:46.110398Z","record_id":"eda1fa6e3022133e12b8fde1405ce11965d13e6ae6fdac8bc6c07199eea7c5fd","schema_fingerprint":"4aa3821a28b0b7c2400bc59aba4bcc0a76e971dadd19610d3ad38c768e124dc7","schema_version":"edge-lab-recorder.raw.v1","sequence":null,"source":"clob_market_ws"}
{"event_at":"2026-07-28T02:57:46.010000Z","event_fingerprint":"64869b49c7cf411a56d2c628e71ad546ed002311efee8238337f0e82627eeaf2","payload":{"connection_id":"955646bd8bf740759faf38750c0f263f","event_at":"2026-07-28T02:57:46.010000Z","event_type":"price_change","frame_hash":"1d60727a56d42842baafd6ead9cf3146f49f12843c85b37b90760e0ad3dec17a","frame_index":0,"kind":"data","monotonic_ns":309449129449708,"payload":{"event_type":"price_change","market":"0x0f70d07969bc69eaa97d0987de651885fdca02263688026aa11e7678af8f87aa","price_changes":[{"asset_id":"58313761654877669244690227616056238030136603415514645252000528337391143520538","best_ask":"0.55","best_bid":"0.53","hash":"83690d9c58082f9d87e97107faa722083282a15e","price":"0.39","side":"BUY","size":"253.09"},{"asset_id":"64053005904884194822931764831592250494815136296598204104072528088122126148949","best_ask":"0.47","best_bid":"0.45","hash":"081fba475acb4a258340fe3e5532c36dccec2fc5","price":"0.61","side":"SELL","size":"253.09"}],"timestamp":"1785207466010"},"payload_hash":"2c67cf974bce13c8ca47b978daf6e40135851077476830a4f68dd617d9e6de91","raw_frame":"{\"market\":\"0x0f70d07969bc69eaa97d0987de651885fdca02263688026aa11e7678af8f87aa\", \"price_changes\":[{\"asset_id\":\"58313761654877669244690227616056238030136603415514645252000528337391143520538\", \"price\":\"0.39\", \"size\":\"253.09\", \"side\":\"BUY\", \"hash\":\"83690d9c58082f9d87e97107faa722083282a15e\", \"best_bid\":\"0.53\", \"best_ask\":\"0.55\"}, {\"asset_id\":\"64053005904884194822931764831592250494815136296598204104072528088122126148949\", \"price\":\"0.61\", \"size\":\"253.09\", \"side\":\"SELL\", \"hash\":\"081fba475acb4a258340fe3e5532c36dccec2fc5\", \"best_bid\":\"0.45\", \"best_ask\":\"0.47\"}], \"timestamp\":\"1785207466010\", \"event_type\":\"price_change\"}","received_at":"2026-07-28T02:57:46.112052Z","schema_version":"clob-market-ws.price_change.v1","sequence":null,"server_hash":null,"server_timestamp":"1785207466010","session_id":"5aad79be415c487c84df42bebd84ee93","source":"clob_market_ws"},"received_at":"2026-07-28T02:57:46.112052Z","record_id":"d85db2f8bcb82f08330d1bf10a0d8cddff96a1fd9a9710dc56e3949a10b6b193","schema_fingerprint":"4aa3821a28b0b7c2400bc59aba4bcc0a76e971dadd19610d3ad38c768e124dc7","schema_version":"edge-lab-recorder.raw.v1","sequence":null,"source":"clob_market_ws"}
{"event_at":"2026-07-28T02:57:46.016000Z","event_fingerprint":"927b5a1894bce3ceedf82d4294cbc5bb031df360eb8d4d00190a682cb62eede0","payload":{"connection_id":"955646bd8bf740759faf38750c0f263f","event_at":"2026-07-28T02:57:46.016000Z","event_type":"price_change","frame_hash":"2daca41185bf8e800169684deaa2fe189fc4ca024ae67c0d7d415b9a26f77d32","frame_index":0,"kind":"data","monotonic_ns":309449131004625,"payload":{"event_type":"price_change","market":"0x0f70d07969bc69eaa97d0987de651885fdca02263688026aa11e7678af8f87aa","price_changes":[{"asset_id":"64053005904884194822931764831592250494815136296598204104072528088122126148949","best_ask":"0.47","best_bid":"0.45","hash":"24cff1f600f24f17009aceec3576a8868bcf7a90","price":"0.01","side":"BUY","size":"2900.52"},{"asset_id":"58313761654877669244690227616056238030136603415514645252000528337391143520538","best_ask":"0.55","best_bid":"0.53","hash":"77905f1a59567e03c74da3b09346ad1ecc33540c","price":"0.99","side":"SELL","size":"2900.52"}],"timestamp":"1785207466016"},"payload_hash":"e3c8f755137025e07269a9cf1e7293648e03c406b588b72bf2831f9230de9946","raw_frame":"{\"market\":\"0x0f70d07969bc69eaa97d0987de651885fdca02263688026aa11e7678af8f87aa\", \"price_changes\":[{\"asset_id\":\"64053005904884194822931764831592250494815136296598204104072528088122126148949\", \"price\":\"0.01\", \"size\":\"2900.52\", \"side\":\"BUY\", \"hash\":\"24cff1f600f24f17009aceec3576a8868bcf7a90\", \"best_bid\":\"0.45\", \"best_ask\":\"0.47\"}, {\"asset_id\":\"58313761654877669244690227616056238030136603415514645252000528337391143520538\", \"price\":\"0.99\", \"size\":\"2900.52\", \"side\":\"SELL\", \"hash\":\"77905f1a59567e03c74da3b09346ad1ecc33540c\", \"best_bid\":\"0.53\", \"best_ask\":\"0.55\"}], \"timestamp\":\"1785207466016\", \"event_type\":\"price_change\"}","received_at":"2026-07-28T02:57:46.113607Z","schema_version":"clob-market-ws.price_change.v1","sequence":null,"server_hash":null,"server_timestamp":"1785207466016","session_id":"5aad79be415c487c84df42bebd84ee93","source":"clob_market_ws"},"received_at":"2026-07-28T02:57:46.113607Z","record_id":"2441dc1daca671edd4bc079025fbb67ddf1370f42e860b1b44dce853fe59b6d0","schema_fingerprint":"4aa3821a28b0b7c2400bc59aba4bcc0a76e971dadd19610d3ad38c768e124dc7","schema_version":"edge-lab-recorder.raw.v1","sequence":null,"source":"clob_market_ws"}
{"event_at":"2026-07-28T02:57:46.017000Z","event_fingerprint":"a7497dff03179d235f519d710b7103b8591c9e74d8f517461d218cb4cd700672","payload":{"connection_id":"955646bd8bf740759faf38750c0f263f","event_at":"2026-07-28T02:57:46.017000Z","event_type":"price_change","frame_hash":"5f0b2c3bfefff3b3a695357b2df362ccc609f14f02cae8bad8ab28e900da27d7","frame_index":0,"kind":"data","monotonic_ns":309449132563041,"payload":{"event_type":"price_change","market":"0x0f70d07969bc69eaa97d0987de651885fdca02263688026aa11e7678af8f87aa","price_changes":[{"asset_id":"64053005904884194822931764831592250494815136296598204104072528088122126148949","best_ask":"0.47","best_bid":"0.45","hash":"877620a4c69f231f6dee47edd7030c8085ac4bdf","price":"0.01","side":"BUY","size":"2905.52"},{"asset_id":"58313761654877669244690227616056238030136603415514645252000528337391143520538","best_ask":"0.55","best_bid":"0.53","hash":"046ce07dd036125ebabf59e4930300ea6a768595","price":"0.99","side":"SELL","size":"2905.52"}],"timestamp":"1785207466017"},"payload_hash":"1cf80993613948f56efd403138b6c535baa629d56b00edd7b5cb69f7f0250a5d","raw_frame":"{\"market\":\"0x0f70d07969bc69eaa97d0987de651885fdca02263688026aa11e7678af8f87aa\", \"price_changes\":[{\"asset_id\":\"64053005904884194822931764831592250494815136296598204104072528088122126148949\", \"price\":\"0.01\", \"size\":\"2905.52\", \"side\":\"BUY\", \"hash\":\"877620a4c69f231f6dee47edd7030c8085ac4bdf\", \"best_bid\":\"0.45\", \"best_ask\":\"0.47\"}, {\"asset_id\":\"58313761654877669244690227616056238030136603415514645252000528337391143520538\", \"price\":\"0.99\", \"size\":\"2905.52\", \"side\":\"SELL\", \"hash\":\"046ce07dd036125ebabf59e4930300ea6a768595\", \"best_bid\":\"0.53\", \"best_ask\":\"0.55\"}], \"timestamp\":\"1785207466017\", \"event_type\":\"price_change\"}","received_at":"2026-07-28T02:57:46.115166Z","schema_version":"clob-market-ws.price_change.v1","sequence":null,"server_hash":null,"server_timestamp":"1785207466017","session_id":"5aad79be415c487c84df42bebd84ee93","source":"clob_market_ws"},"received_at":"2026-07-28T02:57:46.115166Z","record_id":"a099604919f5c59eb03bc15aabd52762be016e6ef85379ccc8c4ccc035261920","schema_fingerprint":"4aa3821a28b0b7c2400bc59aba4bcc0a76e971dadd19610d3ad38c768e124dc7","schema_version":"edge-lab-recorder.raw.v1","sequence":null,"source":"clob_market_ws"}
{"event_at":"2026-07-28T02:57:46.019000Z","event_fingerprint":"9169e751c525811ab13b510933737999a28589f03fab9e3dc81d66774936c27e","payload":{"connection_id":"955646bd8bf740759faf38750c0f263f","event_at":"2026-07-28T02:57:46.019000Z","event_type":"price_change","frame_hash":"9c3e14a96f21ac90735b2477c1ac7ea6d31de5081e237e524e1e56d3b3137e16","frame_index":0,"kind":"data","monotonic_ns":309449134072750,"payload":{"event_type":"price_change","market":"0x0f70d07969bc69eaa97d0987de651885fdca02263688026aa11e7678af8f87aa","price_changes":[{"asset_id":"58313761654877669244690227616056238030136603415514645252000528337391143520538","best_ask":"0.55","best_bid":"0.53","hash":"b6726b53cb9e5851c5b072f3337b55ca48052911","price":"0.01","side":"BUY","size":"2376.24"},{"asset_id":"64053005904884194822931764831592250494815136296598204104072528088122126148949","best_ask":"0.47","best_bid":"0.45","hash":"d97fc6e8ae49c3073e28215b61aef57f34609ef1","price":"0.99","side":"SELL","size":"2376.24"}],"timestamp":"1785207466019"},"payload_hash":"4d6fb27c9ddb9320a6c225a7b9c8d1b48dff7886be00dc52ec35ad493403f51a","raw_frame":"{\"market\":\"0x0f70d07969bc69eaa97d0987de651885fdca02263688026aa11e7678af8f87aa\", \"price_changes\":[{\"asset_id\":\"58313761654877669244690227616056238030136603415514645252000528337391143520538\", \"price\":\"0.01\", \"size\":\"2376.24\", \"side\":\"BUY\", \"hash\":\"b6726b53cb9e5851c5b072f3337b55ca48052911\", \"best_bid\":\"0.53\", \"best_ask\":\"0.55\"}, {\"asset_id\":\"64053005904884194822931764831592250494815136296598204104072528088122126148949\", \"price\":\"0.99\", \"size\":\"2376.24\", \"side\":\"SELL\", \"hash\":\"d97fc6e8ae49c3073e28215b61aef57f34609ef1\", \"best_bid\":\"0.45\", \"best_ask\":\"0.47\"}], \"timestamp\":\"1785207466019\", \"event_type\":\"price_change\"}","received_at":"2026-07-28T02:57:46.116676Z","schema_version":"clob-market-ws.price_change.v1","sequence":null,"server_hash":null,"server_timestamp":"1785207466019","session_id":"5aad79be415c487c84df42bebd84ee93","source":"clob_market_ws"},"received_at":"2026-07-28T02:57:46.116676Z","record_id":"53554234d3d9cc28914211b36813976a4087d47a463dceb031c71967962fbe18","schema_fingerprint":"4aa3821a28b0b7c2400bc59aba4bcc0a76e971dadd19610d3ad38c768e124dc7","schema_version":"edge-lab-recorder.raw.v1","sequence":null,"source":"clob_market_ws"}
{"event_at":"2026-07-28T02:57:46.022000Z","event_fingerprint":"762b81ffc8fb48bf9005a978e07992962e83dce1f1000fa31762202023a8afa6","payload":{"connection_id":"955646bd8bf740759faf38750c0f263f","event_at":"2026-07-28T02:57:46.022000Z","event_type":"price_change","frame_hash":"e2b168fef1f332d8c7d001c77fe9eb118bc693ba55d20cb3aa699643151a245c","frame_index":0,"kind":"data","monotonic_ns":309449135571750,"payload":{"event_type":"price_change","market":"0x0f70d07969bc69eaa97d0987de651885fdca02263688026aa11e7678af8f87aa","price_changes":[{"asset_id":"58313761654877669244690227616056238030136603415514645252000528337391143520538","best_ask":"0.55","best_bid":"0.53","hash":"9b2a10462e3a8158b929c54ca8491307012b33da","price":"0.45","side":"BUY","size":"181.5"},{"asset_id":"64053005904884194822931764831592250494815136296598204104072528088122126148949","best_ask":"0.47","best_bid":"0.45","hash":"a278d2b9347c46611864b342eb56bdf7aaaeea0f","price":"0.55","side":"SELL","size":"181.5"}],"timestamp":"1785207466022"},"payload_hash":"52133346f20e5282f0f238c09a86c2be3272d742e6965b48507ffadc4984d97f","raw_frame":"{\"market\":\"0x0f70d07969bc69eaa97d0987de651885fdca02263688026aa11e7678af8f87aa\", \"price_changes\":[{\"asset_id\":\"58313761654877669244690227616056238030136603415514645252000528337391143520538\", \"price\":\"0.45\", \"size\":\"181.5\", \"side\":\"BUY\", \"hash\":\"9b2a10462e3a8158b929c54ca8491307012b33da\", \"best_bid\":\"0.53\", \"best_ask\":\"0.55\"}, {\"asset_id\":\"64053005904884194822931764831592250494815136296598204104072528088122126148949\", \"price\":\"0.55\", \"size\":\"181.5\", \"side\":\"SELL\", \"hash\":\"a278d2b9347c46611864b342eb56bdf7aaaeea0f\", \"best_bid\":\"0.45\", \"best_ask\":\"0.47\"}], \"timestamp\":\"1785207466022\", \"event_type\":\"price_change\"}","received_at":"2026-07-28T02:57:46.118174Z","schema_version":"clob-market-ws.price_change.v1","sequence":null,"server_hash":null,"server_timestamp":"1785207466022","session_id":"5aad79be415c487c84df42bebd84ee93","source":"clob_market_ws"},"received_at":"2026-07-28T02:57:46.118174Z","record_id":"096f6718d9fd864596cb519ff7473dc5f60aee71c9e011fc139845473e7b2fcc","schema_fingerprint":"4aa3821a28b0b7c2400bc59aba4bcc0a76e971dadd19610d3ad38c768e124dc7","schema_version":"edge-lab-recorder.raw.v1","sequence":null,"source":"clob_market_ws"}
{"event_at":"2026-07-28T02:57:46.036000Z","event_fingerprint":"0cbfb76580941f1b715d8fe8f803565287a37ab68a810ab2f0243c3c875dc937","payload":{"connection_id":"955646bd8bf740759faf38750c0f263f","event_at":"2026-07-28T02:57:46.036000Z","event_type":"price_change","frame_hash":"230589ca03ed019d5f5bca15486ef2bb1506611982bd0856f6b4d57da8cbcf6b","frame_index":0,"kind":"data","monotonic_ns":309449137086916,"payload":{"event_type":"price_change","market":"0x0f70d07969bc69eaa97d0987de651885fdca02263688026aa11e7678af8f87aa","price_changes":[{"asset_id":"64053005904884194822931764831592250494815136296598204104072528088122126148949","best_ask":"0.47","best_bid":"0.45","hash":"be7e994f670ce76929ff65a48be1bb4c29131d80","price":"0.01","side":"BUY","size":"2900.52"},{"asset_id":"58313761654877669244690227616056238030136603415514645252000528337391143520538","best_ask":"0.55","best_bid":"0.53","hash":"8c25505402d6cd89c0312f26cd56351608c879e4","price":"0.99","side":"SELL","size":"2900.52"}],"timestamp":"1785207466036"},"payload_hash":"295470e8d2db1c1c034737f719809108563f1dc083222498a7c488c76d142bc6","raw_frame":"{\"market\":\"0x0f70d07969bc69eaa97d0987de651885fdca02263688026aa11e7678af8f87aa\", \"price_changes\":[{\"asset_id\":\"64053005904884194822931764831592250494815136296598204104072528088122126148949\", \"price\":\"0.01\", \"size\":\"2900.52\", \"side\":\"BUY\", \"hash\":\"be7e994f670ce76929ff65a48be1bb4c29131d80\", \"best_bid\":\"0.45\", \"best_ask\":\"0.47\"}, {\"asset_id\":\"58313761654877669244690227616056238030136603415514645252000528337391143520538\", \"price\":\"0.99\", \"size\":\"2900.52\", \"side\":\"SELL\", \"hash\":\"8c25505402d6cd89c0312f26cd56351608c879e4\", \"best_bid\":\"0.53\", \"best_ask\":\"0.55\"}], \"timestamp\":\"1785207466036\", \"event_type\":\"price_change\"}","received_at":"2026-07-28T02:57:46.119689Z","schema_version":"clob-market-ws.price_change.v1","sequence":null,"server_hash":null,"server_timestamp":"1785207466036","session_id":"5aad79be415c487c84df42bebd84ee93","source":"clob_market_ws"},"received_at":"2026-07-28T02:57:46.119689Z","record_id":"deea3dee4044183452f960ed259d00162a12fb4423af206f296e25cea17f0627","schema_fingerprint":"4aa3821a28b0b7c2400bc59aba4bcc0a76e971dadd19610d3ad38c768e124dc7","schema_version":"edge-lab-recorder.raw.v1","sequence":null,"source":"clob_market_ws"}
{"event_at":"2026-07-28T02:57:46.036000Z","event_fingerprint":"72c061b5198079f81275d6f9a85e4d0d2288f6228a5bfc8f198b9320da380039","payload":{"connection_id":"955646bd8bf740759faf38750c0f263f","event_at":"2026-07-28T02:57:46.036000Z","event_type":"price_change","frame_hash":"9b5ed89c606badcdb5fb34e266016e1dd85f699e8e9efb908130923453c39a9d","frame_index":0,"kind":"data","monotonic_ns":309449139654625,"payload":{"event_type":"price_change","market":"0x0f70d07969bc69eaa97d0987de651885fdca02263688026aa11e7678af8f87aa","price_changes":[{"asset_id":"64053005904884194822931764831592250494815136296598204104072528088122126148949","best_ask":"0.47","best_bid":"0.45","hash":"4e6e6470705f3f31ad99393d335de76f69031248","price":"0.33","side":"BUY","size":"61.9"},{"asset_id":"58313761654877669244690227616056238030136603415514645252000528337391143520538","best_ask":"0.55","best_bid":"0.53","hash":"169b903971cb62c1283107e9c093d3a0f8c2e436","price":"0.67","side":"SELL","size":"61.9"}],"timestamp":"1785207466036"},"payload_hash":"7ea3894ae4608d38f90ff03f811bdfae1e69e6b97bf8c06af91d058757d243bc","raw_frame":"{\"market\":\"0x0f70d07969bc69eaa97d0987de651885fdca02263688026aa11e7678af8f87aa\", \"price_changes\":[{\"asset_id\":\"64053005904884194822931764831592250494815136296598204104072528088122126148949\", \"price\":\"0.33\", \"size\":\"61.9\", \"side\":\"BUY\", \"hash\":\"4e6e6470705f3f31ad99393d335de76f69031248\", \"best_bid\":\"0.45\", \"best_ask\":\"0.47\"}, {\"asset_id\":\"58313761654877669244690227616056238030136603415514645252000528337391143520538\", \"price\":\"0.67\", \"size\":\"61.9\", \"side\":\"SELL\", \"hash\":\"169b903971cb62c1283107e9c093d3a0f8c2e436\", \"best_bid\":\"0.53\", \"best_ask\":\"0.55\"}], \"timestamp\":\"1785207466036\", \"event_type\":\"price_change\"}","received_at":"2026-07-28T02:57:46.122254Z","schema_version":"clob-market-ws.price_change.v1","sequence":null,"server_hash":null,"server_timestamp":"1785207466036","session_id":"5aad79be415c487c84df42bebd84ee93","source":"clob_market_ws"},"received_at":"2026-07-28T02:57:46.122254Z","record_id":"dbc08f02a7f842a2e8b4faa697a001de246e00909d69142edfd1f5102b914df7","schema_fingerprint":"4aa3821a28b0b7c2400bc59aba4bcc0a76e971dadd19610d3ad38c768e124dc7","schema_version":"edge-lab-recorder.raw.v1","sequence":null,"source":"clob_market_ws"}
{"event_at":"2026-07-28T02:57:46.041000Z","event_fingerprint":"961007d8d34297238f5e1ce96cbe48b3eea81919ce9f5f527fea4a275d47b92e","payload":{"connection_id":"955646bd8bf740759faf38750c0f263f","event_at":"2026-07-28T02:57:46.041000Z","event_type":"price_change","frame_hash":"08bd759a9cc20c63f748a8f979f2279c8029fcd6001b781e4547bb8c3947ff2b","frame_index":0,"kind":"data","monotonic_ns":309449141289750,"payload":{"event_type":"price_change","market":"0x0f70d07969bc69eaa97d0987de651885fdca02263688026aa11e7678af8f87aa","price_changes":[{"asset_id":"58313761654877669244690227616056238030136603415514645252000528337391143520538","best_ask":"0.55","best_bid":"0.53","hash":"a50144bf580db6ee21ffc62e2ea9699ab68e6c64","price":"0.01","side":"BUY","size":"2371.24"},{"asset_id":"64053005904884194822931764831592250494815136296598204104072528088122126148949","best_ask":"0.47","best_bid":"0.45","hash":"6c20c536281711b83bcefd45b2d078e7982f474a","price":"0.99","side":"SELL","size":"2371.24"}],"timestamp":"1785207466041"},"payload_hash":"fd6d0d7ca0098e6051e47ecf30974073be81cb49c326f51b5fc59d70f1f08d13","raw_frame":"{\"market\":\"0x0f70d07969bc69eaa97d0987de651885fdca02263688026aa11e7678af8f87aa\", \"price_changes\":[{\"asset_id\":\"58313761654877669244690227616056238030136603415514645252000528337391143520538\", \"price\":\"0.01\", \"size\":\"2371.24\", \"side\":\"BUY\", \"hash\":\"a50144bf580db6ee21ffc62e2ea9699ab68e6c64\", \"best_bid\":\"0.53\", \"best_ask\":\"0.55\"}, {\"asset_id\":\"64053005904884194822931764831592250494815136296598204104072528088122126148949\", \"price\":\"0.99\", \"size\":\"2371.24\", \"side\":\"SELL\", \"hash\":\"6c20c536281711b83bcefd45b2d078e7982f474a\", \"best_bid\":\"0.45\", \"best_ask\":\"0.47\"}], \"timestamp\":\"1785207466041\", \"event_type\":\"price_change\"}","received_at":"2026-07-28T02:57:46.123893Z","schema_version":"clob-market-ws.price_change.v1","sequence":null,"server_hash":null,"server_timestamp":"1785207466041","session_id":"5aad79be415c487c84df42bebd84ee93","source":"clob_market_ws"},"received_at":"2026-07-28T02:57:46.123893Z","record_id":"8350a8bd76595350872fa6c89c407c4e3de393dce0f5dcca94d1bfd152f1ebf1","schema_fingerprint":"4aa3821a28b0b7c2400bc59aba4bcc0a76e971dadd19610d3ad38c768e124dc7","schema_version":"edge-lab-recorder.raw.v1","sequence":null,"source":"clob_market_ws"}
{"event_at":"2026-07-28T02:57:46.042000Z","event_fingerprint":"39eda1578a1d72ab0d74f30d7175dbe3bcedf2643690df6a8b1cf54c48930af2","payload":{"connection_id":"955646bd8bf740759faf38750c0f263f","event_at":"2026-07-28T02:57:46.042000Z","event_type":"price_change","frame_hash":"16581f1aff8c8d7f645f27cbcde7ac7803dde9df843d6dc483802f800fc7e73e","frame_index":0,"kind":"data","monotonic_ns":309449142774166,"payload":{"event_type":"price_change","market":"0x0f70d07969bc69eaa97d0987de651885fdca02263688026aa11e7678af8f87aa","price_changes":[{"asset_id":"64053005904884194822931764831592250494815136296598204104072528088122126148949","best_ask":"0.47","best_bid":"0.45","hash":"15fb5eeba7fd1d433ac036e978c3ac62c0cc42aa","price":"0.01","side":"BUY","size":"2895.52"},{"asset_id":"58313761654877669244690227616056238030136603415514645252000528337391143520538","best_ask":"0.55","best_bid":"0.53","hash":"c8ff6e1a6602eb54de98dcafa5323c82d81a7c4d","price":"0.99","side":"SELL","size":"2895.52"}],"timestamp":"1785207466042"},"payload_hash":"1eb91ccaf7021d7c3ce5d953b17cb500320d9e977acec2b2534e774f937e7864","raw_frame":"{\"market\":\"0x0f70d07969bc69eaa97d0987de651885fdca02263688026aa11e7678af8f87aa\", \"price_changes\":[{\"asset_id\":\"64053005904884194822931764831592250494815136296598204104072528088122126148949\", \"price\":\"0.01\", \"size\":\"2895.52\", \"side\":\"BUY\", \"hash\":\"15fb5eeba7fd1d433ac036e978c3ac62c0cc42aa\", \"best_bid\":\"0.45\", \"best_ask\":\"0.47\"}, {\"asset_id\":\"58313761654877669244690227616056238030136603415514645252000528337391143520538\", \"price\":\"0.99\", \"size\":\"2895.52\", \"side\":\"SELL\", \"hash\":\"c8ff6e1a6602eb54de98dcafa5323c82d81a7c4d\", \"best_bid\":\"0.53\", \"best_ask\":\"0.55\"}], \"timestamp\":\"1785207466042\", \"event_type\":\"price_change\"}","received_at":"2026-07-28T02:57:46.125377Z","schema_version":"clob-market-ws.price_change.v1","sequence":null,"server_hash":null,"server_timestamp":"1785207466042","session_id":"5aad79be415c487c84df42bebd84ee93","source":"clob_market_ws"},"received_at":"2026-07-28T02:57:46.125377Z","record_id":"b7903f4829154daeaaa1b7a3e2954f696eab13e352f0ecce048d3ca3c1036b31","schema_fingerprint":"4aa3821a28b0b7c2400bc59aba4bcc0a76e971dadd19610d3ad38c768e124dc7","schema_version":"edge-lab-recorder.raw.v1","sequence":null,"source":"clob_market_ws"}
{"event_at":"2026-07-28T02:57:46.042000Z","event_fingerprint":"db5d6aea8c6a3b3c7ff92642fe47270a44cc68a3637d83368e64cd9733da0351","payload":{"connection_id":"955646bd8bf740759faf38750c0f263f","event_at":"2026-07-28T02:57:46.042000Z","event_type":"price_change","frame_hash":"2593c32f96a13c9993070e1f797df4b127e1f2d05e61d01a0b41c4be55c482fd","frame_index":0,"kind":"data","monotonic_ns":309449145669166,"payload":{"event_type":"price_change","market":"0x0f70d07969bc69eaa97d0987de651885fdca02263688026aa11e7678af8f87aa","price_changes":[{"asset_id":"64053005904884194822931764831592250494815136296598204104072528088122126148949","best_ask":"0.47","best_bid":"0.45","hash":"42cdc5b747755d342d3643ecfed358d7a3f0096a","price":"0.32","side":"BUY","size":"67.99"},{"asset_id":"58313761654877669244690227616056238030136603415514645252000528337391143520538","best_ask":"0.55","best_bid":"0.53","hash":"0559ebe34d723de02093f292dabec10219ade654","price":"0.68","side":"SELL","size":"67.99"}],"timestamp":"1785207466042"},"payload_hash":"c55b3ee6345a7ad91804569d9476a615657d228bda9b75663989db179d5cdf5d","raw_frame":"{\"market\":\"0x0f70d07969bc69eaa97d0987de651885fdca02263688026aa11e7678af8f87aa\", \"price_changes\":[{\"asset_id\":\"64053005904884194822931764831592250494815136296598204104072528088122126148949\", \"price\":\"0.32\", \"size\":\"67.99\", \"side\":\"BUY\", \"hash\":\"42cdc5b747755d342d3643ecfed358d7a3f0096a\", \"best_bid\":\"0.45\", \"best_ask\":\"0.47\"}, {\"asset_id\":\"58313761654877669244690227616056238030136603415514645252000528337391143520538\", \"price\":\"0.68\", \"size\":\"67.99\", \"side\":\"SELL\", \"hash\":\"0559ebe34d723de02093f292dabec10219ade654\", \"best_bid\":\"0.53\", \"best_ask\":\"0.55\"}], \"timestamp\":\"1785207466042\", \"event_type\":\"price_change\"}","received_at":"2026-07-28T02:57:46.128271Z","schema_version":"clob-market-ws.price_change.v1","sequence":null,"server_hash":null,"server_timestamp":"1785207466042","session_id":"5aad79be415c487c84df42bebd84ee93","source":"clob_market_ws"},"received_at":"2026-07-28T02:57:46.128271Z","record_id":"bb80aa935d54e5c0a27357de370455690929c57afe60f4ae531c2aa93d847aa6","schema_fingerprint":"4aa3821a28b0b7c2400bc59aba4bcc0a76e971dadd19610d3ad38c768e124dc7","schema_version":"edge-lab-recorder.raw.v1","sequence":null,"source":"clob_market_ws"}
{"event_at":"2026-07-28T02:57:46.066000Z","event_fingerprint":"4bd53b00e0aa1bcfa7b36b99a0cb9f276779060aa3fc2ed6580055f4e96c0718","payload":{"connection_id":"955646bd8bf740759faf38750c0f263f","event_at":"2026-07-28T02:57:46.066000Z","event_type":"price_change","frame_hash":"04147b7036f19d15c35ca055003a059253b2375f971a07173705b3e8711dda50","frame_index":0,"kind":"data","monotonic_ns":309449148787791,"payload":{"event_type":"price_change","market":"0x0f70d07969bc69eaa97d0987de651885fdca02263688026aa11e7678af8f87aa","price_changes":[{"asset_id":"58313761654877669244690227616056238030136603415514645252000528337391143520538","best_ask":"0.55","best_bid":"0.53","hash":"913bfe1ddfd2adbf31cbed2403419c2866dd3a33","price":"0.51","side":"BUY","size":"141.6"},{"asset_id":"64053005904884194822931764831592250494815136296598204104072528088122126148949","best_ask":"0.47","best_bid":"0.45","hash":"31452b757fdc7086b065bee64e19697b08dbe978","price":"0.49","side":"SELL","size":"141.6"}],"timestamp":"1785207466066"},"payload_hash":"be5e9e91f55e4bbb1f8ccc5daecfdb0b1342d3779ac7506be0d2a41455642a79","raw_frame":"{\"market\":\"0x0f70d07969bc69eaa97d0987de651885fdca02263688026aa11e7678af8f87aa\", \"price_changes\":[{\"asset_id\":\"58313761654877669244690227616056238030136603415514645252000528337391143520538\", \"price\":\"0.51\", \"size\":\"141.6\", \"side\":\"BUY\", \"hash\":\"913bfe1ddfd2adbf31cbed2403419c2866dd3a33\", \"best_bid\":\"0.53\", \"best_ask\":\"0.55\"}, {\"asset_id\":\"64053005904884194822931764831592250494815136296598204104072528088122126148949\", \"price\":\"0.49\", \"size\":\"141.6\", \"side\":\"SELL\", \"hash\":\"31452b757fdc7086b065bee64e19697b08dbe978\", \"best_bid\":\"0.45\", \"best_ask\":\"0.47\"}], \"timestamp\":\"1785207466066\", \"event_type\":\"price_change\"}","received_at":"2026-07-28T02:57:46.131391Z","schema_version":"clob-market-ws.price_change.v1","sequence":null,"server_hash":null,"server_timestamp":"1785207466066","session_id":"5aad79be415c487c84df42bebd84ee93","source":"clob_market_ws"},"received_at":"2026-07-28T02:57:46.131391Z","record_id":"86d4cbff4d319b3b5ef459a4b996412606854f50c25b781d31052611733bcd42","schema_fingerprint":"4aa3821a28b0b7c2400bc59aba4bcc0a76e971dadd19610d3ad38c768e124dc7","schema_version":"edge-lab-recorder.raw.v1","sequence":null,"source":"clob_market_ws"}
{"event_at":"2026-07-28T02:57:46.072000Z","event_fingerprint":"b8c573f1dcabc2fe6bdeb4c9f49575754703b970045487117af4cb78795835f8","payload":{"connection_id":"955646bd8bf740759faf38750c0f263f","event_at":"2026-07-28T02:57:46.072000Z","event_type":"price_change","frame_hash":"fa3982896ce6d42b3a064c48dd3744987885cb17201cf653ebe87407427afdc2","frame_index":0,"kind":"data","monotonic_ns":309449151615958,"payload":{"event_type":"price_change","market":"0x0f70d07969bc69eaa97d0987de651885fdca02263688026aa11e7678af8f87aa","price_changes":[{"asset_id":"58313761654877669244690227616056238030136603415514645252000528337391143520538","best_ask":"0.55","best_bid":"0.53","hash":"08efe23ccf4d81aeb3b4602deab035c2dca6836d","price":"0.48","side":"BUY","size":"155.08"},{"asset_id":"64053005904884194822931764831592250494815136296598204104072528088122126148949","best_ask":"0.47","best_bid":"0.45","hash":"e7c71e5ef4edb55bd40310fb68add0c664dfae3f","price":"0.52","side":"SELL","size":"155.08"}],"timestamp":"1785207466072"},"payload_hash":"dfa66a9ea790fa8902d5a76a1c4426208884b82a115f10dcd0539e1efb7e2c1c","raw_frame":"{\"market\":\"0x0f70d07969bc69eaa97d0987de651885fdca02263688026aa11e7678af8f87aa\", \"price_changes\":[{\"asset_id\":\"58313761654877669244690227616056238030136603415514645252000528337391143520538\", \"price\":\"0.48\", \"size\":\"155.08\", \"side\":\"BUY\", \"hash\":\"08efe23ccf4d81aeb3b4602deab035c2dca6836d\", \"best_bid\":\"0.53\", \"best_ask\":\"0.55\"}, {\"asset_id\":\"64053005904884194822931764831592250494815136296598204104072528088122126148949\", \"price\":\"0.52\", \"size\":\"155.08\", \"side\":\"SELL\", \"hash\":\"e7c71e5ef4edb55bd40310fb68add0c664dfae3f\", \"best_bid\":\"0.45\", \"best_ask\":\"0.47\"}], \"timestamp\":\"1785207466072\", \"event_type\":\"price_change\"}","received_at":"2026-07-28T02:57:46.134218Z","schema_version":"clob-market-ws.price_change.v1","sequence":null,"server_hash":null,"server_timestamp":"1785207466072","session_id":"5aad79be415c487c84df42bebd84ee93","source":"clob_market_ws"},"received_at":"2026-07-28T02:57:46.134218Z","record_id":"a748be2727520f9fb3a443449473cbafd1db9d4503e2820a6019f036d4c72d4c","schema_fingerprint":"4aa3821a28b0b7c2400bc59aba4bcc0a76e971dadd19610d3ad38c768e124dc7","schema_version":"edge-lab-recorder.raw.v1","sequence":null,"source":"clob_market_ws"}
{"event_at":"2026-07-28T02:57:46.073000Z","event_fingerprint":"93b7879f0288b32187769dc048d64d1ed30fa75f2050bd3df9595f199f10e284","payload":{"connection_id":"955646bd8bf740759faf38750c0f263f","event_at":"2026-07-28T02:57:46.073000Z","event_type":"price_change","frame_hash":"fb9dc1843dd7eb765ad61cc699c3e71029d53393185dc6d0ccfd01ff674480e3","frame_index":0,"kind":"data","monotonic_ns":309449160632375,"payload":{"event_type":"price_change","market":"0x0f70d07969bc69eaa97d0987de651885fdca02263688026aa11e7678af8f87aa","price_changes":[{"asset_id":"58313761654877669244690227616056238030136603415514645252000528337391143520538","best_ask":"0.55","best_bid":"0.53","hash":"f0bb3112c516380337381d5162f7b56519f6067e","price":"0.6","side":"SELL","size":"115.97"},{"asset_id":"64053005904884194822931764831592250494815136296598204104072528088122126148949","best_ask":"0.47","best_bid":"0.45","hash":"f543b64ca3539e849dfe9856bf40f29de01a0efb","price":"0.4","side":"BUY","size":"115.97"}],"timestamp":"1785207466073"},"payload_hash":"4a99b040b7d5519715c8ac9cf793ebdc405c993ec79ee789682b9c09b7a04363","raw_frame":"{\"market\":\"0x0f70d07969bc69eaa97d0987de651885fdca02263688026aa11e7678af8f87aa\", \"price_changes\":[{\"asset_id\":\"58313761654877669244690227616056238030136603415514645252000528337391143520538\", \"price\":\"0.6\", \"size\":\"115.97\", \"side\":\"SELL\", \"hash\":\"f0bb3112c516380337381d5162f7b56519f6067e\", \"best_bid\":\"0.53\", \"best_ask\":\"0.55\"}, {\"asset_id\":\"64053005904884194822931764831592250494815136296598204104072528088122126148949\", \"price\":\"0.4\", \"size\":\"115.97\", \"side\":\"BUY\", \"hash\":\"f543b64ca3539e849dfe9856bf40f29de01a0efb\", \"best_bid\":\"0.45\", \"best_ask\":\"0.47\"}], \"timestamp\":\"1785207466073\", \"event_type\":\"price_change\"}","received_at":"2026-07-28T02:57:46.143233Z","schema_version":"clob-market-ws.price_change.v1","sequence":null,"server_hash":null,"server_timestamp":"1785207466073","session_id":"5aad79be415c487c84df42bebd84ee93","source":"clob_market_ws"},"received_at":"2026-07-28T02:57:46.143233Z","record_id":"67b14226fe7d88070af5b38e270faad090b34e17f59fbf2c829797fd5f8b497a","schema_fingerprint":"4aa3821a28b0b7c2400bc59aba4bcc0a76e971dadd19610d3ad38c768e124dc7","schema_version":"edge-lab-recorder.raw.v1","sequence":null,"source":"clob_market_ws"}
{"event_at":"2026-07-28T02:57:46.074000Z","event_fingerprint":"4bf21c1508b649c0379c13535cde922ca24adb3ecbdbe89bbfc8ef512ad247b9","payload":{"connection_id":"955646bd8bf740759faf38750c0f263f","event_at":"2026-07-28T02:57:46.074000Z","event_type":"price_change","frame_hash":"09b459ece105e4bad0b6f4524da1ed2c9a1221913ab3ca346d4e9d30fbebdcfb","frame_index":0,"kind":"data","monotonic_ns":309449162208041,"payload":{"event_type":"price_change","market":"0x0f70d07969bc69eaa97d0987de651885fdca02263688026aa11e7678af8f87aa","price_changes":[{"asset_id":"64053005904884194822931764831592250494815136296598204104072528088122126148949","best_ask":"0.47","best_bid":"0.45","hash":"69ebc5cfb83edf7c33e0cc235c9e18251980bbc3","price":"0.4","side":"BUY","size":"120.97"},{"asset_id":"58313761654877669244690227616056238030136603415514645252000528337391143520538","best_ask":"0.55","best_bid":"0.53","hash":"1f41804aaa364dd659ec2213b17d7afff010e82c","price":"0.6","side":"SELL","size":"120.97"}],"timestamp":"1785207466074"},"payload_hash":"a8bc3f04209c295eb3711150250c72831768e2274ca2b89d33977e5977221611","raw_frame":"{\"market\":\"0x0f70d07969bc69eaa97d0987de651885fdca02263688026aa11e7678af8f87aa\", \"price_changes\":[{\"asset_id\":\"64053005904884194822931764831592250494815136296598204104072528088122126148949\", \"price\":\"0.4\", \"size\":\"120.97\", \"side\":\"BUY\", \"hash\":\"69ebc5cfb83edf7c33e0cc235c9e18251980bbc3\", \"best_bid\":\"0.45\", \"best_ask\":\"0.47\"}, {\"asset_id\":\"58313761654877669244690227616056238030136603415514645252000528337391143520538\", \"price\":\"0.6\", \"size\":\"120.97\", \"side\":\"SELL\", \"hash\":\"1f41804aaa364dd659ec2213b17d7afff010e82c\", \"best_bid\":\"0.53\", \"best_ask\":\"0.55\"}], \"timestamp\":\"1785207466074\", \"event_type\":\"price_change\"}","received_at":"2026-07-28T02:57:46.144812Z","schema_version":"clob-market-ws.price_change.v1","sequence":null,"server_hash":null,"server_timestamp":"1785207466074","session_id":"5aad79be415c487c84df42bebd84ee93","source":"clob_market_ws"},"received_at":"2026-07-28T02:57:46.144812Z","record_id":"3691a2cb23ac45153fe2ca50c99b02726b6b572aac99abbc5269ea6c4f4a8900","schema_fingerprint":"4aa3821a28b0b7c2400bc59aba4bcc0a76e971dadd19610d3ad38c768e124dc7","schema_version":"edge-lab-recorder.raw.v1","sequence":null,"source":"clob_market_ws"}
{"event_at":"2026-07-28T02:57:46.079000Z","event_fingerprint":"48c539e32dd3013a09b50e0351b4788c599a5dff6ae993802a4797576d29e742","payload":{"connection_id":"955646bd8bf740759faf38750c0f263f","event_at":"2026-07-28T02:57:46.079000Z","event_type":"price_change","frame_hash":"5e3ce298f62855022a50c27e644ece45e396d0e7d1ce42ae1a08bbe2902d2052","frame_index":0,"kind":"data","monotonic_ns":309449163777041,"payload":{"event_type":"price_change","market":"0x0f70d07969bc69eaa97d0987de651885fdca02263688026aa11e7678af8f87aa","price_changes":[{"asset_id":"64053005904884194822931764831592250494815136296598204104072528088122126148949","best_ask":"0.47","best_bid":"0.45","hash":"93cb330ee8fef628f59aa7e59f95e9563282c649","price":"0.31","side":"BUY","size":"117.1"},{"asset_id":"58313761654877669244690227616056238030136603415514645252000528337391143520538","best_ask":"0.55","best_bid":"0.53","hash":"b1b147bed3ed74a9d7eecbe9c1c14603011879c3","price":"0.69","side":"SELL","size":"117.1"}],"timestamp":"1785207466079"},"payload_hash":"e52880c19742d036748d962a66fb3cc6373e8701e600f177692c898cac748433","raw_frame":"{\"market\":\"0x0f70d07969bc69eaa97d0987de651885fdca02263688026aa11e7678af8f87aa\", \"price_changes\":[{\"asset_id\":\"64053005904884194822931764831592250494815136296598204104072528088122126148949\", \"price\":\"0.31\", \"size\":\"117.1\", \"side\":\"BUY\", \"hash\":\"93cb330ee8fef628f59aa7e59f95e9563282c649\", \"best_bid\":\"0.45\", \"best_ask\":\"0.47\"}, {\"asset_id\":\"58313761654877669244690227616056238030136603415514645252000528337391143520538\", \"price\":\"0.69\", \"size\":\"117.1\", \"side\":\"SELL\", \"hash\":\"b1b147bed3ed74a9d7eecbe9c1c14603011879c3\", \"best_bid\":\"0.53\", \"best_ask\":\"0.55\"}], \"timestamp\":\"1785207466079\", \"event_type\":\"price_change\"}","received_at":"2026-07-28T02:57:46.146378Z","schema_version":"clob-market-ws.price_change.v1","sequence":null,"server_hash":null,"server_timestamp":"1785207466079","session_id":"5aad79be415c487c84df42bebd84ee93","source":"clob_market_ws"},"received_at":"2026-07-28T02:57:46.146378Z","record_id":"cede1bf0e32d6011764c75dd34e572af5836bfa692cbe66aba4e993f5e12b3c6","schema_fingerprint":"4aa3821a28b0b7c2400bc59aba4bcc0a76e971dadd19610d3ad38c768e124dc7","schema_version":"edge-lab-recorder.raw.v1","sequence":null,"source":"clob_market_ws"}
{"event_at":"2026-07-28T02:57:46.090000Z","event_fingerprint":"9d2b421f8d5930bb4372b7822c74de80380c279f4ada730d6e4091830a4a23d0","payload":{"connection_id":"955646bd8bf740759faf38750c0f263f","event_at":"2026-07-28T02:57:46.090000Z","event_type":"price_change","frame_hash":"5410dd48a07deb48d170602f2f7abc0db1281027be5aceb825ec5a78c0f5a3c1","frame_index":0,"kind":"data","monotonic_ns":309449165294125,"payload":{"event_type":"price_change","market":"0x0f70d07969bc69eaa97d0987de651885fdca02263688026aa11e7678af8f87aa","price_changes":[{"asset_id":"58313761654877669244690227616056238030136603415514645252000528337391143520538","best_ask":"0.55","best_bid":"0.53","hash":"5efe3cc53475accecbaf15c91047c97a8ddbab9c","price":"0.02","side":"BUY","size":"1065.79"},{"asset_id":"64053005904884194822931764831592250494815136296598204104072528088122126148949","best_ask":"0.47","best_bid":"0.45","hash":"2943caa47f4a7070be03f115d17d4b76dd567b24","price":"0.98","side":"SELL","size":"1065.79"}],"timestamp":"1785207466090"},"payload_hash":"c76cbe9f8d731ef4ff782f847690e1f4b43562a144aa3164e4bf6da3192cdb7f","raw_frame":"{\"market\":\"0x0f70d07969bc69eaa97d0987de651885fdca02263688026aa11e7678af8f87aa\", \"price_changes\":[{\"asset_id\":\"58313761654877669244690227616056238030136603415514645252000528337391143520538\", \"price\":\"0.02\", \"size\":\"1065.79\", \"side\":\"BUY\", \"hash\":\"5efe3cc53475accecbaf15c91047c97a8ddbab9c\", \"best_bid\":\"0.53\", \"best_ask\":\"0.55\"}, {\"asset_id\":\"64053005904884194822931764831592250494815136296598204104072528088122126148949\", \"price\":\"0.98\", \"size\":\"1065.79\", \"side\":\"SELL\", \"hash\":\"2943caa47f4a7070be03f115d17d4b76dd567b24\", \"best_bid\":\"0.45\", \"best_ask\":\"0.47\"}], \"timestamp\":\"1785207466090\", \"event_type\":\"price_change\"}","received_at":"2026-07-28T02:57:46.147896Z","schema_version":"clob-market-ws.price_change.v1","sequence":null,"server_hash":null,"server_timestamp":"1785207466090","session_id":"5aad79be415c487c84df42bebd84ee93","source":"clob_market_ws"},"received_at":"2026-07-28T02:57:46.147896Z","record_id":"8d293980e718937e47871cd83b51091eca6a315504e209ae6c431d1323f2c9a8","schema_fingerprint":"4aa3821a28b0b7c2400bc59aba4bcc0a76e971dadd19610d3ad38c768e124dc7","schema_version":"edge-lab-recorder.raw.v1","sequence":null,"source":"clob_market_ws"}
{"event_at":"2026-07-28T02:57:46.092000Z","event_fingerprint":"12847f1f9bc4605f8c0e969b12d5837550b84330721ff669972db4334c0c40c7","payload":{"connection_id":"955646bd8bf740759faf38750c0f263f","event_at":"2026-07-28T02:57:46.092000Z","event_type":"price_change","frame_hash":"1c456376b39d875b070ffe2008bcfce9cc536dcb4d900628c2aa8ee352b4bb62","frame_index":0,"kind":"data","monotonic_ns":309449166862375,"payload":{"event_type":"price_change","market":"0x0f70d07969bc69eaa97d0987de651885fdca02263688026aa11e7678af8f87aa","price_changes":[{"asset_id":"58313761654877669244690227616056238030136603415514645252000528337391143520538","best_ask":"0.55","best_bid":"0.53","hash":"631070fddebd781b6bf2c73fc8bd5cb161ddfb4e","price":"0.51","side":"BUY","size":"126.6"},{"asset_id":"64053005904884194822931764831592250494815136296598204104072528088122126148949","best_ask":"0.47","best_bid":"0.45","hash":"bfff7f01188cefd7932f60d533bd6071744666f4","price":"0.49","side":"SELL","size":"126.6"}],"timestamp":"1785207466092"},"payload_hash":"00d70efa5afbbf88057ffc5ecd18146f5af4f335d9e7c90653bdb9eca2da11c2","raw_frame":"{\"market\":\"0x0f70d07969bc69eaa97d0987de651885fdca02263688026aa11e7678af8f87aa\", \"price_changes\":[{\"asset_id\":\"58313761654877669244690227616056238030136603415514645252000528337391143520538\", \"price\":\"0.51\", \"size\":\"126.6\", \"side\":\"BUY\", \"hash\":\"631070fddebd781b6bf2c73fc8bd5cb161ddfb4e\", \"best_bid\":\"0.53\", \"best_ask\":\"0.55\"}, {\"asset_id\":\"64053005904884194822931764831592250494815136296598204104072528088122126148949\", \"price\":\"0.49\", \"size\":\"126.6\", \"side\":\"SELL\", \"hash\":\"bfff7f01188cefd7932f60d533bd6071744666f4\", \"best_bid\":\"0.45\", \"best_ask\":\"0.47\"}], \"timestamp\":\"1785207466092\", \"event_type\":\"price_change\"}","received_at":"2026-07-28T02:57:46.149465Z","schema_version":"clob-market-ws.price_change.v1","sequence":null,"server_hash":null,"server_timestamp":"1785207466092","session_id":"5aad79be415c487c84df42bebd84ee93","source":"clob_market_ws"},"received_at":"2026-07-28T02:57:46.149465Z","record_id":"2108a7691bcd145c5b66d4820889dae67efe1ea71eedbec9549119a9ac0b4068","schema_fingerprint":"4aa3821a28b0b7c2400bc59aba4bcc0a76e971dadd19610d3ad38c768e124dc7","schema_version":"edge-lab-recorder.raw.v1","sequence":null,"source":"clob_market_ws"}
{"event_at":"2026-07-28T02:57:46.093000Z","event_fingerprint":"3c3beabc40bf614f16be30892ffec5c0d0c04336f6f8b989e14ac15876fd3785","payload":{"connection_id":"955646bd8bf740759faf38750c0f263f","event_at":"2026-07-28T02:57:46.093000Z","event_type":"price_change","frame_hash":"0f369bd48b25c247c73ceb5a5e83b649222f574c48124098ebb1dce8c2549ad9","frame_index":0,"kind":"data","monotonic_ns":309449168357291,"payload":{"event_type":"price_change","market":"0x0f70d07969bc69eaa97d0987de651885fdca02263688026aa11e7678af8f87aa","price_changes":[{"asset_id":"64053005904884194822931764831592250494815136296598204104072528088122126148949","best_ask":"0.47","best_bid":"0.45","hash":"cce31d758c8e5194f489f8dbfff4c9403bd6abf9","price":"0.37","side":"BUY","size":"83.32"},{"asset_id":"58313761654877669244690227616056238030136603415514645252000528337391143520538","best_ask":"0.55","best_bid":"0.53","hash":"6891d2512d17713ce686df0a6fa29432dd234f24","price":"0.63","side":"SELL","size":"83.32"}],"timestamp":"1785207466093"},"payload_hash":"c272dfb5556e23e5243748723167a8dcbe51970b9223255be1f50a03e87e42b9","raw_frame":"{\"market\":\"0x0f70d07969bc69eaa97d0987de651885fdca02263688026aa11e7678af8f87aa\", \"price_changes\":[{\"asset_id\":\"64053005904884194822931764831592250494815136296598204104072528088122126148949\", \"price\":\"0.37\", \"size\":\"83.32\", \"side\":\"BUY\", \"hash\":\"cce31d758c8e5194f489f8dbfff4c9403bd6abf9\", \"best_bid\":\"0.45\", \"best_ask\":\"0.47\"}, {\"asset_id\":\"58313761654877669244690227616056238030136603415514645252000528337391143520538\", \"price\":\"0.63\", \"size\":\"83.32\", \"side\":\"SELL\", \"hash\":\"6891d2512d17713ce686df0a6fa29432dd234f24\", \"best_bid\":\"0.53\", \"best_ask\":\"0.55\"}], \"timestamp\":\"1785207466093\", \"event_type\":\"price_change\"}","received_at":"2026-07-28T02:57:46.150960Z","schema_version":"clob-market-ws.price_change.v1","sequence":null,"server_hash":null,"server_timestamp":"1785207466093","session_id":"5aad79be415c487c84df42bebd84ee93","source":"clob_market_ws"},"received_at":"2026-07-28T02:57:46.150960Z","record_id":"40c1000e4610ccd420a2cb4d838d7f3eb587494e64c602ab1452693644828dbe","schema_fingerprint":"4aa3821a28b0b7c2400bc59aba4bcc0a76e971dadd19610d3ad38c768e124dc7","schema_version":"edge-lab-recorder.raw.v1","sequence":null,"source":"clob_market_ws"}
{"event_at":"2026-07-28T02:57:46.115000Z","event_fingerprint":"6824a9f97b7c837ffee1e91a57adad3503b50fb944841058b7c7a58371a4fded","payload":{"connection_id":"955646bd8bf740759faf38750c0f263f","event_at":"2026-07-28T02:57:46.115000Z","event_type":"price_change","frame_hash":"6657ba5241c7572396e3fe623085ffa35aa16db76934db73017fc02dfdaa02eb","frame_index":0,"kind":"data","monotonic_ns":309449169841041,"payload":{"event_type":"price_change","market":"0x0f70d07969bc69eaa97d0987de651885fdca02263688026aa11e7678af8f87aa","price_changes":[{"asset_id":"64053005904884194822931764831592250494815136296598204104072528088122126148949","best_ask":"0.47","best_bid":"0.45","hash":"8959aa50e96c778b80f425118d4cb9b9c69712e0","price":"0.07","side":"BUY","size":"302.2"},{"asset_id":"58313761654877669244690227616056238030136603415514645252000528337391143520538","best_ask":"0.55","best_bid":"0.53","hash":"7e0982af750472b8f1031f023b659440aef03b95","price":"0.93","side":"SELL","size":"302.2"}],"timestamp":"1785207466115"},"payload_hash":"fc54601c2fa568153838a919a6a5f2f94435448309ef2c79dbd3a320e388ba0f","raw_frame":"{\"market\":\"0x0f70d07969bc69eaa97d0987de651885fdca02263688026aa11e7678af8f87aa\", \"price_changes\":[{\"asset_id\":\"64053005904884194822931764831592250494815136296598204104072528088122126148949\", \"price\":\"0.07\", \"size\":\"302.2\", \"side\":\"BUY\", \"hash\":\"8959aa50e96c778b80f425118d4cb9b9c69712e0\", \"best_bid\":\"0.45\", \"best_ask\":\"0.47\"}, {\"asset_id\":\"58313761654877669244690227616056238030136603415514645252000528337391143520538\", \"price\":\"0.93\", \"size\":\"302.2\", \"side\":\"SELL\", \"hash\":\"7e0982af750472b8f1031f023b659440aef03b95\", \"best_bid\":\"0.53\", \"best_ask\":\"0.55\"}], \"timestamp\":\"1785207466115\", \"event_type\":\"price_change\"}","received_at":"2026-07-28T02:57:46.152444Z","schema_version":"clob-market-ws.price_change.v1","sequence":null,"server_hash":null,"server_timestamp":"1785207466115","session_id":"5aad79be415c487c84df42bebd84ee93","source":"clob_market_ws"},"received_at":"2026-07-28T02:57:46.152444Z","record_id":"fc6d5799c9c9985db9fc73e711f8a3cb1ca58b87e5d98d24332e04bf772384c6","schema_fingerprint":"4aa3821a28b0b7c2400bc59aba4bcc0a76e971dadd19610d3ad38c768e124dc7","schema_version":"edge-lab-recorder.raw.v1","sequence":null,"source":"clob_market_ws"}
{"event_at":"2026-07-28T02:57:46.115000Z","event_fingerprint":"c09df2f7e7a8eac1e4534d8f8370579d68250f49202d09eb748685e048c87c49","payload":{"connection_id":"955646bd8bf740759faf38750c0f263f","event_at":"2026-07-28T02:57:46.115000Z","event_type":"price_change","frame_hash":"d1ef6a5b3cacb897d580fbd0d113c0eb8a8a24d1a70f257cb6270a71e7cd7d30","frame_index":0,"kind":"data","monotonic_ns":309449171329458,"payload":{"event_type":"price_change","market":"0x0f70d07969bc69eaa97d0987de651885fdca02263688026aa11e7678af8f87aa","price_changes":[{"asset_id":"64053005904884194822931764831592250494815136296598204104072528088122126148949","best_ask":"0.47","best_bid":"0.45","hash":"8959aa50e96c778b80f425118d4cb9b9c69712e0","price":"0.13","side":"BUY","size":"772.56"},{"asset_id":"58313761654877669244690227616056238030136603415514645252000528337391143520538","best_ask":"0.55","best_bid":"0.53","hash":"7e0982af750472b8f1031f023b659440aef03b95","price":"0.87","side":"SELL","size":"772.56"}],"timestamp":"1785207466115"},"payload_hash":"3a698295db106ffc3524dc18ab9a2f1c357e76747bc57696ad50ef878004571f","raw_frame":"{\"market\":\"0x0f70d07969bc69eaa97d0987de651885fdca02263688026aa11e7678af8f87aa\", \"price_changes\":[{\"asset_id\":\"64053005904884194822931764831592250494815136296598204104072528088122126148949\", \"price\":\"0.13\", \"size\":\"772.56\", \"side\":\"BUY\", \"hash\":\"8959aa50e96c778b80f425118d4cb9b9c69712e0\", \"best_bid\":\"0.45\", \"best_ask\":\"0.47\"}, {\"asset_id\":\"58313761654877669244690227616056238030136603415514645252000528337391143520538\", \"price\":\"0.87\", \"size\":\"772.56\", \"side\":\"SELL\", \"hash\":\"7e0982af750472b8f1031f023b659440aef03b95\", \"best_bid\":\"0.53\", \"best_ask\":\"0.55\"}], \"timestamp\":\"1785207466115\", \"event_type\":\"price_change\"}","received_at":"2026-07-28T02:57:46.153932Z","schema_version":"clob-market-ws.price_change.v1","sequence":null,"server_hash":null,"server_timestamp":"1785207466115","session_id":"5aad79be415c487c84df42bebd84ee93","source":"clob_market_ws"},"received_at":"2026-07-28T02:57:46.153932Z","record_id":"3b7c9ddb216362e8e949cd1f520969923866ca65a0561ecbf63d29be8e4193c0","schema_fingerprint":"4aa3821a28b0b7c2400bc59aba4bcc0a76e971dadd19610d3ad38c768e124dc7","schema_version":"edge-lab-recorder.raw.v1","sequence":null,"source":"clob_market_ws"}
{"event_at":"2026-07-28T02:57:46.115000Z","event_fingerprint":"de930b95df5ae20cab0aa2559456577f6236aca30c0c1fc4cf42558ad570b5c0","payload":{"connection_id":"955646bd8bf740759faf38750c0f263f","event_at":"2026-07-28T02:57:46.115000Z","event_type":"price_change","frame_hash":"1a0d490396ab71467d0cd06b700b0e6c9e11fbee8a86fe61cd14df9bcd624997","frame_index":0,"kind":"data","monotonic_ns":309449172797166,"payload":{"event_type":"price_change","market":"0x0f70d07969bc69eaa97d0987de651885fdca02263688026aa11e7678af8f87aa","price_changes":[{"asset_id":"64053005904884194822931764831592250494815136296598204104072528088122126148949","best_ask":"0.47","best_bid":"0.45","hash":"8959aa50e96c778b80f425118d4cb9b9c69712e0","price":"0.17","side":"BUY","size":"115.29"},{"asset_id":"58313761654877669244690227616056238030136603415514645252000528337391143520538","best_ask":"0.55","best_bid":"0.53","hash":"7e0982af750472b8f1031f023b659440aef03b95","price":"0.83","side":"SELL","size":"115.29"}],"timestamp":"1785207466115"},"payload_hash":"5867f1b9566d977b09fc075a25b95a966bb3c7a9df7eadb27afae0208cbb2544","raw_frame":"{\"market\":\"0x0f70d07969bc69eaa97d0987de651885fdca02263688026aa11e7678af8f87aa\", \"price_changes\":[{\"asset_id\":\"64053005904884194822931764831592250494815136296598204104072528088122126148949\", \"price\":\"0.17\", \"size\":\"115.29\", \"side\":\"BUY\", \"hash\":\"8959aa50e96c778b80f425118d4cb9b9c69712e0\", \"best_bid\":\"0.45\", \"best_ask\":\"0.47\"}, {\"asset_id\":\"58313761654877669244690227616056238030136603415514645252000528337391143520538\", \"price\":\"0.83\", \"size\":\"115.29\", \"side\":\"SELL\", \"hash\":\"7e0982af750472b8f1031f023b659440aef03b95\", \"best_bid\":\"0.53\", \"best_ask\":\"0.55\"}], \"timestamp\":\"1785207466115\", \"event_type\":\"price_change\"}","received_at":"2026-07-28T02:57:46.155400Z","schema_version":"clob-market-ws.price_change.v1","sequence":null,"server_hash":null,"server_timestamp":"1785207466115","session_id":"5aad79be415c487c84df42bebd84ee93","source":"clob_market_ws"},"received_at":"2026-07-28T02:57:46.155400Z","record_id":"db7bde915c22b997da32d967506934122399b57450903e03d0e37ecdd9e4a823","schema_fingerprint":"4aa3821a28b0b7c2400bc59aba4bcc0a76e971dadd19610d3ad38c768e124dc7","schema_version":"edge-lab-recorder.raw.v1","sequence":null,"source":"clob_market_ws"}
{"event_at":"2026-07-28T02:57:46.121000Z","event_fingerprint":"ffa335a7dcb9ed2fc45c73678d4a4368982868f21330e0ebd352adf15ee2b834","payload":{"connection_id":"955646bd8bf740759faf38750c0f263f","event_at":"2026-07-28T02:57:46.121000Z","event_type":"price_change","frame_hash":"80662bf9c4d0f1604642b970d2eba31db65372a280295f201c43524e5787078f","frame_index":0,"kind":"data","monotonic_ns":309449174331833,"payload":{"event_type":"price_change","market":"0x0f70d07969bc69eaa97d0987de651885fdca02263688026aa11e7678af8f87aa","price_changes":[{"asset_id":"58313761654877669244690227616056238030136603415514645252000528337391143520538","best_ask":"0.55","best_bid":"0.53","hash":"4c8a57f6cd9976615baa08099a4b9ac746b82b02","price":"0.44","side":"BUY","size":"139.6"},{"asset_id":"64053005904884194822931764831592250494815136296598204104072528088122126148949","best_ask":"0.47","best_bid":"0.45","hash":"65c0ee1e1125be8450b278ffd2145c5c84137d7b","price":"0.56","side":"SELL","size":"139.6"}],"timestamp":"1785207466121"},"payload_hash":"17e6576ec600b7b63847ce5c4e11e1a34dd0b5b919c63577f846845fa1a06827","raw_frame":"{\"market\":\"0x0f70d07969bc69eaa97d0987de651885fdca02263688026aa11e7678af8f87aa\", \"price_changes\":[{\"asset_id\":\"58313761654877669244690227616056238030136603415514645252000528337391143520538\", \"price\":\"0.44\", \"size\":\"139.6\", \"side\":\"BUY\", \"hash\":\"4c8a57f6cd9976615baa08099a4b9ac746b82b02\", \"best_bid\":\"0.53\", \"best_ask\":\"0.55\"}, {\"asset_id\":\"64053005904884194822931764831592250494815136296598204104072528088122126148949\", \"price\":\"0.56\", \"size\":\"139.6\", \"side\":\"SELL\", \"hash\":\"65c0ee1e1125be8450b278ffd2145c5c84137d7b\", \"best_bid\":\"0.45\", \"best_ask\":\"0.47\"}], \"timestamp\":\"1785207466121\", \"event_type\":\"price_change\"}","received_at":"2026-07-28T02:57:46.156935Z","schema_version":"clob-market-ws.price_change.v1","sequence":null,"server_hash":null,"server_timestamp":"1785207466121","session_id":"5aad79be415c487c84df42bebd84ee93","source":"clob_market_ws"},"received_at":"2026-07-28T02:57:46.156935Z","record_id":"47a0b818e4148992902b219673bdc93089a5e18b305cb809facbee706462ebe2","schema_fingerprint":"4aa3821a28b0b7c2400bc59aba4bcc0a76e971dadd19610d3ad38c768e124dc7","schema_version":"edge-lab-recorder.raw.v1","sequence":null,"source":"clob_market_ws"}
{"event_at":"2026-07-28T02:57:46.127000Z","event_fingerprint":"511601c5343a247d36bf84e4dac0bf67ad089575232306e5516a4264c554669d","payload":{"connection_id":"955646bd8bf740759faf38750c0f263f","event_at":"2026-07-28T02:57:46.127000Z","event_type":"price_change","frame_hash":"a2659b1513a38835af04a642da45ffdc7b6f32aaa33f7762dd10ddaddcf58472","frame_index":0,"kind":"data","monotonic_ns":309449175784375,"payload":{"event_type":"price_change","market":"0x0f70d07969bc69eaa97d0987de651885fdca02263688026aa11e7678af8f87aa","price_changes":[{"asset_id":"64053005904884194822931764831592250494815136296598204104072528088122126148949","best_ask":"0.47","best_bid":"0.45","hash":"630e402e4d38dea71db73db01123fef2786a631f","price":"0.44","side":"BUY","size":"82"},{"asset_id":"58313761654877669244690227616056238030136603415514645252000528337391143520538","best_ask":"0.55","best_bid":"0.53","hash":"4ac1c73de86691c94669fb419edfff0d5ab8c216","price":"0.56","side":"SELL","size":"82"}],"timestamp":"1785207466127"},"payload_hash":"724e48b87444ae4aaecc62803df822cd24021560c05381a351da8980426078a9","raw_frame":"{\"market\":\"0x0f70d07969bc69eaa97d0987de651885fdca02263688026aa11e7678af8f87aa\", \"price_changes\":[{\"asset_id\":\"64053005904884194822931764831592250494815136296598204104072528088122126148949\", \"price\":\"0.44\", \"size\":\"82\", \"side\":\"BUY\", \"hash\":\"630e402e4d38dea71db73db01123fef2786a631f\", \"best_bid\":\"0.45\", \"best_ask\":\"0.47\"}, {\"asset_id\":\"58313761654877669244690227616056238030136603415514645252000528337391143520538\", \"price\":\"0.56\", \"size\":\"82\", \"side\":\"SELL\", \"hash\":\"4ac1c73de86691c94669fb419edfff0d5ab8c216\", \"best_bid\":\"0.53\", \"best_ask\":\"0.55\"}], \"timestamp\":\"1785207466127\", \"event_type\":\"price_change\"}","received_at":"2026-07-28T02:57:46.158386Z","schema_version":"clob-market-ws.price_change.v1","sequence":null,"server_hash":null,"server_timestamp":"1785207466127","session_id":"5aad79be415c487c84df42bebd84ee93","source":"clob_market_ws"},"received_at":"2026-07-28T02:57:46.158386Z","record_id":"56260b14dbc3c766fd3d0139a65c5b48f5884a0235292983ac79e5a7a34e6af7","schema_fingerprint":"4aa3821a28b0b7c2400bc59aba4bcc0a76e971dadd19610d3ad38c768e124dc7","schema_version":"edge-lab-recorder.raw.v1","sequence":null,"source":"clob_market_ws"}
{"event_at":"2026-07-28T02:57:46.128000Z","event_fingerprint":"3cf5ab5fe879d6b8979749a774823565e6c944b2c5a523439722bdc7dbc1fc79","payload":{"connection_id":"955646bd8bf740759faf38750c0f263f","event_at":"2026-07-28T02:57:46.128000Z","event_type":"price_change","frame_hash":"fd7a9759f163a11c555a95856db2a905f01ba7f94738fe1304d3ec2f0f03052e","frame_index":0,"kind":"data","monotonic_ns":309449177320541,"payload":{"event_type":"price_change","market":"0x0f70d07969bc69eaa97d0987de651885fdca02263688026aa11e7678af8f87aa","price_changes":[{"asset_id":"58313761654877669244690227616056238030136603415514645252000528337391143520538","best_ask":"0.55","best_bid":"0.53","hash":"a5abffe62cffe5e919f773ba0c4256ad2ac66ab1","price":"0.44","side":"BUY","size":"124.6"},{"asset_id":"64053005904884194822931764831592250494815136296598204104072528088122126148949","best_ask":"0.47","best_bid":"0.45","hash":"7dbbffa65c0f5b1dce01b4104f6fe00df6bd09c3","price":"0.56","side":"SELL","size":"124.6"}],"timestamp":"1785207466128"},"payload_hash":"163a1602733581055abf40fbce86e06c1276b62bd6413d4fc3776f2413676e87","raw_frame":"{\"market\":\"0x0f70d07969bc69eaa97d0987de651885fdca02263688026aa11e7678af8f87aa\", \"price_changes\":[{\"asset_id\":\"58313761654877669244690227616056238030136603415514645252000528337391143520538\", \"price\":\"0.44\", \"size\":\"124.6\", \"side\":\"BUY\", \"hash\":\"a5abffe62cffe5e919f773ba0c4256ad2ac66ab1\", \"best_bid\":\"0.53\", \"best_ask\":\"0.55\"}, {\"asset_id\":\"64053005904884194822931764831592250494815136296598204104072528088122126148949\", \"price\":\"0.56\", \"size\":\"124.6\", \"side\":\"SELL\", \"hash\":\"7dbbffa65c0f5b1dce01b4104f6fe00df6bd09c3\", \"best_bid\":\"0.45\", \"best_ask\":\"0.47\"}], \"timestamp\":\"1785207466128\", \"event_type\":\"price_change\"}","received_at":"2026-07-28T02:57:46.159923Z","schema_version":"clob-market-ws.price_change.v1","sequence":null,"server_hash":null,"server_timestamp":"1785207466128","session_id":"5aad79be415c487c84df42bebd84ee93","source":"clob_market_ws"},"received_at":"2026-07-28T02:57:46.159923Z","record_id":"0801f6cbb4055c9f672641c2b55c9908812ecd218932bd0baf65b8ade7d34228","schema_fingerprint":"4aa3821a28b0b7c2400bc59aba4bcc0a76e971dadd19610d3ad38c768e124dc7","schema_version":"edge-lab-recorder.raw.v1","sequence":null,"source":"clob_market_ws"}
{"event_at":"2026-07-28T02:57:46.128000Z","event_fingerprint":"b26ec5337a7810a2999367034f9ce0414fe4cc67eac0f9d9ee87750974bcd71c","payload":{"connection_id":"955646bd8bf740759faf38750c0f263f","event_at":"2026-07-28T02:57:46.128000Z","event_type":"price_change","frame_hash":"44dd13114f3e43f9d9a763e183354a77431d0bfe4f8082230b29f02fbf6ed223","frame_index":0,"kind":"data","monotonic_ns":309449178797833,"payload":{"event_type":"price_change","market":"0x0f70d07969bc69eaa97d0987de651885fdca02263688026aa11e7678af8f87aa","price_changes":[{"asset_id":"64053005904884194822931764831592250494815136296598204104072528088122126148949","best_ask":"0.47","best_bid":"0.45","hash":"97d22cd8b5be7d9c76369c6b58eda647be6235dd","price":"0.41","side":"BUY","size":"55.2"},{"asset_id":"58313761654877669244690227616056238030136603415514645252000528337391143520538","best_ask":"0.55","best_bid":"0.53","hash":"3c3554d0b3feb5f46a8db4d918b864781027bbd5","price":"0.59","side":"SELL","size":"55.2"}],"timestamp":"1785207466128"},"payload_hash":"24d2c34c59464932ad644c44d38865a37c46ed4f6021fea3e649de3ceb124f8c","raw_frame":"{\"market\":\"0x0f70d07969bc69eaa97d0987de651885fdca02263688026aa11e7678af8f87aa\", \"price_changes\":[{\"asset_id\":\"64053005904884194822931764831592250494815136296598204104072528088122126148949\", \"price\":\"0.41\", \"size\":\"55.2\", \"side\":\"BUY\", \"hash\":\"97d22cd8b5be7d9c76369c6b58eda647be6235dd\", \"best_bid\":\"0.45\", \"best_ask\":\"0.47\"}, {\"asset_id\":\"58313761654877669244690227616056238030136603415514645252000528337391143520538\", \"price\":\"0.59\", \"size\":\"55.2\", \"side\":\"SELL\", \"hash\":\"3c3554d0b3feb5f46a8db4d918b864781027bbd5\", \"best_bid\":\"0.53\", \"best_ask\":\"0.55\"}], \"timestamp\":\"1785207466128\", \"event_type\":\"price_change\"}","received_at":"2026-07-28T02:57:46.161401Z","schema_version":"clob-market-ws.price_change.v1","sequence":null,"server_hash":null,"server_timestamp":"1785207466128","session_id":"5aad79be415c487c84df42bebd84ee93","source":"clob_market_ws"},"received_at":"2026-07-28T02:57:46.161401Z","record_id":"153602def229b4e703751da63f681c992f08dd1fa2bc28a5cc969e19bbeb3918","schema_fingerprint":"4aa3821a28b0b7c2400bc59aba4bcc0a76e971dadd19610d3ad38c768e124dc7","schema_version":"edge-lab-recorder.raw.v1","sequence":null,"source":"clob_market_ws"}
{"event_at":"2026-07-28T02:57:46.131000Z","event_fingerprint":"1617c9c6c6c77a443941854298634c982b6a90b32f3b718cd909773916363ae4","payload":{"connection_id":"955646bd8bf740759faf38750c0f263f","event_at":"2026-07-28T02:57:46.131000Z","event_type":"price_change","frame_hash":"ac4cb9decb6e1111d661d9282f5c539c2d4850d232366c9768aaded225ed9329","frame_index":0,"kind":"data","monotonic_ns":309449180248000,"payload":{"event_type":"price_change","market":"0x0f70d07969bc69eaa97d0987de651885fdca02263688026aa11e7678af8f87aa","price_changes":[{"asset_id":"58313761654877669244690227616056238030136603415514645252000528337391143520538","best_ask":"0.55","best_bid":"0.53","hash":"11eca725e6d29e133c082f70c24a828653f54335","price":"0.5","side":"BUY","size":"99.7"},{"asset_id":"64053005904884194822931764831592250494815136296598204104072528088122126148949","best_ask":"0.47","best_bid":"0.45","hash":"46c10d3d6fc8b1724115d4c228214635fe432b1c","price":"0.5","side":"SELL","size":"99.7"}],"timestamp":"1785207466131"},"payload_hash":"de6337a6221fea745fa3880c4ab6c50f1e779f66e0ad8e9e389cdccd8f5727fe","raw_frame":"{\"market\":\"0x0f70d07969bc69eaa97d0987de651885fdca02263688026aa11e7678af8f87aa\", \"price_changes\":[{\"asset_id\":\"58313761654877669244690227616056238030136603415514645252000528337391143520538\", \"price\":\"0.5\", \"size\":\"99.7\", \"side\":\"BUY\", \"hash\":\"11eca725e6d29e133c082f70c24a828653f54335\", \"best_bid\":\"0.53\", \"best_ask\":\"0.55\"}, {\"asset_id\":\"64053005904884194822931764831592250494815136296598204104072528088122126148949\", \"price\":\"0.5\", \"size\":\"99.7\", \"side\":\"SELL\", \"hash\":\"46c10d3d6fc8b1724115d4c228214635fe432b1c\", \"best_bid\":\"0.45\", \"best_ask\":\"0.47\"}], \"timestamp\":\"1785207466131\", \"event_type\":\"price_change\"}","received_at":"2026-07-28T02:57:46.162852Z","schema_version":"clob-market-ws.price_change.v1","sequence":null,"server_hash":null,"server_timestamp":"1785207466131","session_id":"5aad79be415c487c84df42bebd84ee93","source":"clob_market_ws"},"received_at":"2026-07-28T02:57:46.162852Z","record_id":"7a14196a840aa6f8fba5051d7fc2a3583d60d5576f6f3f752c0354acece90106","schema_fingerprint":"4aa3821a28b0b7c2400bc59aba4bcc0a76e971dadd19610d3ad38c768e124dc7","schema_version":"edge-lab-recorder.raw.v1","sequence":null,"source":"clob_market_ws"}
{"event_at":"2026-07-28T02:57:46.131000Z","event_fingerprint":"e763228575b93c9d9f6b0515cec3b25524750fcfcfbcd971158cf768623331e9","payload":{"connection_id":"955646bd8bf740759faf38750c0f263f","event_at":"2026-07-28T02:57:46.131000Z","event_type":"price_change","frame_hash":"209ec83896f55c6b426f0e267184c2dc4811266f5c943697ad95631f26d6d4a2","frame_index":0,"kind":"data","monotonic_ns":309449181710166,"payload":{"event_type":"price_change","market":"0x0f70d07969bc69eaa97d0987de651885fdca02263688026aa11e7678af8f87aa","price_changes":[{"asset_id":"64053005904884194822931764831592250494815136296598204104072528088122126148949","best_ask":"0.47","best_bid":"0.45","hash":"d5f8c26c0369274c4fa624e57d7734f0f14f7c40","price":"0.44","side":"BUY","size":"139"},{"asset_id":"58313761654877669244690227616056238030136603415514645252000528337391143520538","best_ask":"0.55","best_bid":"0.53","hash":"4e8a6b6d506e757790740fa854dde8cda631abaa","price":"0.56","side":"SELL","size":"139"}],"timestamp":"1785207466131"},"payload_hash":"b243eda56f3be9116c091b7a3563c1391abdfe3f7c8f9df72ada3975eedb68b7","raw_frame":"{\"market\":\"0x0f70d07969bc69eaa97d0987de651885fdca02263688026aa11e7678af8f87aa\", \"price_changes\":[{\"asset_id\":\"64053005904884194822931764831592250494815136296598204104072528088122126148949\", \"price\":\"0.44\", \"size\":\"139\", \"side\":\"BUY\", \"hash\":\"d5f8c26c0369274c4fa624e57d7734f0f14f7c40\", \"best_bid\":\"0.45\", \"best_ask\":\"0.47\"}, {\"asset_id\":\"58313761654877669244690227616056238030136603415514645252000528337391143520538\", \"price\":\"0.56\", \"size\":\"139\", \"side\":\"SELL\", \"hash\":\"4e8a6b6d506e757790740fa854dde8cda631abaa\", \"best_bid\":\"0.53\", \"best_ask\":\"0.55\"}], \"timestamp\":\"1785207466131\", \"event_type\":\"price_change\"}","received_at":"2026-07-28T02:57:46.164313Z","schema_version":"clob-market-ws.price_change.v1","sequence":null,"server_hash":null,"server_timestamp":"1785207466131","session_id":"5aad79be415c487c84df42bebd84ee93","source":"clob_market_ws"},"received_at":"2026-07-28T02:57:46.164313Z","record_id":"086858698b834cd09259843f4a3d8590d867eeef078e7715f004ff6507b74653","schema_fingerprint":"4aa3821a28b0b7c2400bc59aba4bcc0a76e971dadd19610d3ad38c768e124dc7","schema_version":"edge-lab-recorder.raw.v1","sequence":null,"source":"clob_market_ws"}
{"event_at":"2026-07-28T02:57:46.133000Z","event_fingerprint":"4132e066cfd849966d659cb819973854c77b7e19a148d1fa8a3b0c9fbcd1dbd0","payload":{"connection_id":"955646bd8bf740759faf38750c0f263f","event_at":"2026-07-28T02:57:46.133000Z","event_type":"price_change","frame_hash":"d18495e30e7f4932933b183bd3cea32d1e562e6ea376060cc27e8940f2369e93","frame_index":0,"kind":"data","monotonic_ns":309449183172791,"payload":{"event_type":"price_change","market":"0x0f70d07969bc69eaa97d0987de651885fdca02263688026aa11e7678af8f87aa","price_changes":[{"asset_id":"64053005904884194822931764831592250494815136296598204104072528088122126148949","best_ask":"0.47","best_bid":"0.45","hash":"cb812e807d3ec0f959623fc34319e37ec6f2a56c","price":"0.43","side":"BUY","size":"153.4"},{"asset_id":"58313761654877669244690227616056238030136603415514645252000528337391143520538","best_ask":"0.55","best_bid":"0.53","hash":"72a5dc9e9c688a07bdca497011a70db739a314eb","price":"0.57","side":"SELL","size":"153.4"}],"timestamp":"1785207466133"},"payload_hash":"df1c68c763f4bbbf0405c63f319ffd7ec804effe0d70e89e1169e7a0ef99d4a5","raw_frame":"{\"market\":\"0x0f70d07969bc69eaa97d0987de651885fdca02263688026aa11e7678af8f87aa\", \"price_changes\":[{\"asset_id\":\"64053005904884194822931764831592250494815136296598204104072528088122126148949\", \"price\":\"0.43\", \"size\":\"153.4\", \"side\":\"BUY\", \"hash\":\"cb812e807d3ec0f959623fc34319e37ec6f2a56c\", \"best_bid\":\"0.45\", \"best_ask\":\"0.47\"}, {\"asset_id\":\"58313761654877669244690227616056238030136603415514645252000528337391143520538\", \"price\":\"0.57\", \"size\":\"153.4\", \"side\":\"SELL\", \"hash\":\"72a5dc9e9c688a07bdca497011a70db739a314eb\", \"best_bid\":\"0.53\", \"best_ask\":\"0.55\"}], \"timestamp\":\"1785207466133\", \"event_type\":\"price_change\"}","received_at":"2026-07-28T02:57:46.165776Z","schema_version":"clob-market-ws.price_change.v1","sequence":null,"server_hash":null,"server_timestamp":"1785207466133","session_id":"5aad79be415c487c84df42bebd84ee93","source":"clob_market_ws"},"received_at":"2026-07-28T02:57:46.165776Z","record_id":"e9df2fb69ab08475c5e030ab519e0ddf092c2a230a053012208acb6c6fe38616","schema_fingerprint":"4aa3821a28b0b7c2400bc59aba4bcc0a76e971dadd19610d3ad38c768e124dc7","schema_version":"edge-lab-recorder.raw.v1","sequence":null,"source":"clob_market_ws"}
{"event_at":"2026-07-28T02:57:46.136000Z","event_fingerprint":"4c42d15f5ec700a344e42a2dc33049a7d79163a7aa33dd2a31f74abc9ab3468d","payload":{"connection_id":"955646bd8bf740759faf38750c0f263f","event_at":"2026-07-28T02:57:46.136000Z","event_type":"price_change","frame_hash":"f774cdeaa5d3c9bf39bdadebdaf59d6d357a6b2f4dc3b504bb6feb6cf084c2a0","frame_index":0,"kind":"data","monotonic_ns":309449184650333,"payload":{"event_type":"price_change","market":"0x0f70d07969bc69eaa97d0987de651885fdca02263688026aa11e7678af8f87aa","price_changes":[{"asset_id":"58313761654877669244690227616056238030136603415514645252000528337391143520538","best_ask":"0.55","best_bid":"0.53","hash":"d491c48660a2ef29b85a580147285be3c1fe321c","price":"0.53","side":"BUY","size":"91.58"},{"asset_id":"64053005904884194822931764831592250494815136296598204104072528088122126148949","best_ask":"0.47","best_bid":"0.45","hash":"51b1ebf55109850af0aa665efb5636345afeb3d9","price":"0.47","side":"SELL","size":"91.58"}],"timestamp":"1785207466136"},"payload_hash":"dde14ebdbf92a14b4dedd4667f1d79ad00602bdaa403dd35d6947b36b809f36d","raw_frame":"{\"market\":\"0x0f70d07969bc69eaa97d0987de651885fdca02263688026aa11e7678af8f87aa\", \"price_changes\":[{\"asset_id\":\"58313761654877669244690227616056238030136603415514645252000528337391143520538\", \"price\":\"0.53\", \"size\":\"91.58\", \"side\":\"BUY\", \"hash\":\"d491c48660a2ef29b85a580147285be3c1fe321c\", \"best_bid\":\"0.53\", \"best_ask\":\"0.55\"}, {\"asset_id\":\"64053005904884194822931764831592250494815136296598204104072528088122126148949\", \"price\":\"0.47\", \"size\":\"91.58\", \"side\":\"SELL\", \"hash\":\"51b1ebf55109850af0aa665efb5636345afeb3d9\", \"best_bid\":\"0.45\", \"best_ask\":\"0.47\"}], \"timestamp\":\"1785207466136\", \"event_type\":\"price_change\"}","received_at":"2026-07-28T02:57:46.167253Z","schema_version":"clob-market-ws.price_change.v1","sequence":null,"server_hash":null,"server_timestamp":"1785207466136","session_id":"5aad79be415c487c84df42bebd84ee93","source":"clob_market_ws"},"received_at":"2026-07-28T02:57:46.167253Z","record_id":"fd7c6a6e4f925d0f9435570d3fc2f0984cce3fd0941b28b5d0d8ac1024523389","schema_fingerprint":"4aa3821a28b0b7c2400bc59aba4bcc0a76e971dadd19610d3ad38c768e124dc7","schema_version":"edge-lab-recorder.raw.v1","sequence":null,"source":"clob_market_ws"}
{"event_at":"2026-07-28T02:57:46.139000Z","event_fingerprint":"a89460d3e3bcdd2743f009c8839813a2aab4e2bb92f2be1b19e8d0e41aa9fc2a","payload":{"connection_id":"955646bd8bf740759faf38750c0f263f","event_at":"2026-07-28T02:57:46.139000Z","event_type":"price_change","frame_hash":"ed0003186ea2700737b01b3ec1f1aef0e233e71a5129d5cd50c00f393a6bbed0","frame_index":0,"kind":"data","monotonic_ns":309449186194791,"payload":{"event_type":"price_change","market":"0x0f70d07969bc69eaa97d0987de651885fdca02263688026aa11e7678af8f87aa","price_changes":[{"asset_id":"64053005904884194822931764831592250494815136296598204104072528088122126148949","best_ask":"0.47","best_bid":"0.45","hash":"fdd27ead39af25afe630d2af50dd367999d80175","price":"0.45","side":"BUY","size":"28.01"},{"asset_id":"58313761654877669244690227616056238030136603415514645252000528337391143520538","best_ask":"0.55","best_bid":"0.53","hash":"740e877045727729c11b35329205806319ce9955","price":"0.55","side":"SELL","size":"28.01"}],"timestamp":"1785207466139"},"payload_hash":"9dd19385b6767d668c163c101d7a6f0554458564767666bbaf06cf1abce2e4ae","raw_frame":"{\"market\":\"0x0f70d07969bc69eaa97d0987de651885fdca02263688026aa11e7678af8f87aa\", \"price_changes\":[{\"asset_id\":\"64053005904884194822931764831592250494815136296598204104072528088122126148949\", \"price\":\"0.45\", \"size\":\"28.01\", \"side\":\"BUY\", \"hash\":\"fdd27ead39af25afe630d2af50dd367999d80175\", \"best_bid\":\"0.45\", \"best_ask\":\"0.47\"}, {\"asset_id\":\"58313761654877669244690227616056238030136603415514645252000528337391143520538\", \"price\":\"0.55\", \"size\":\"28.01\", \"side\":\"SELL\", \"hash\":\"740e877045727729c11b35329205806319ce9955\", \"best_bid\":\"0.53\", \"best_ask\":\"0.55\"}], \"timestamp\":\"1785207466139\", \"event_type\":\"price_change\"}","received_at":"2026-07-28T02:57:46.168796Z","schema_version":"clob-market-ws.price_change.v1","sequence":null,"server_hash":null,"server_timestamp":"1785207466139","session_id":"5aad79be415c487c84df42bebd84ee93","source":"clob_market_ws"},"received_at":"2026-07-28T02:57:46.168796Z","record_id":"5e148a40e1ffa3f3b0d3c6bce7d906991c766c770246bd1bfb1ef9591d762a5d","schema_fingerprint":"4aa3821a28b0b7c2400bc59aba4bcc0a76e971dadd19610d3ad38c768e124dc7","schema_version":"edge-lab-recorder.raw.v1","sequence":null,"source":"clob_market_ws"}
{"event_at":"2026-07-28T02:57:46.141000Z","event_fingerprint":"54c2ebff602998f8908901d4135a6ed717264718a2e8ec7097c7e661cdf8b873","payload":{"connection_id":"955646bd8bf740759faf38750c0f263f","event_at":"2026-07-28T02:57:46.141000Z","event_type":"price_change","frame_hash":"3692444b3acc84bb6d17fe678d1bc411a1c9bec95bde87a901992bf212ddf987","frame_index":0,"kind":"data","monotonic_ns":309449187779875,"payload":{"event_type":"price_change","market":"0x0f70d07969bc69eaa97d0987de651885fdca02263688026aa11e7678af8f87aa","price_changes":[{"asset_id":"58313761654877669244690227616056238030136603415514645252000528337391143520538","best_ask":"0.55","best_bid":"0.53","hash":"2d248166f954d71331105e7eb5caf0ecf9fc0ed4","price":"0.02","side":"BUY","size":"1060.79"},{"asset_id":"64053005904884194822931764831592250494815136296598204104072528088122126148949","best_ask":"0.47","best_bid":"0.45","hash":"0db62fe6964b2c5158b317c6b77eb447004afa99","price":"0.98","side":"SELL","size":"1060.79"}],"timestamp":"1785207466141"},"payload_hash":"75ce0a77fe9a216f59aaa923052991ce55399d6c934f4659aeb2a83d49ce9f11","raw_frame":"{\"market\":\"0x0f70d07969bc69eaa97d0987de651885fdca02263688026aa11e7678af8f87aa\", \"price_changes\":[{\"asset_id\":\"58313761654877669244690227616056238030136603415514645252000528337391143520538\", \"price\":\"0.02\", \"size\":\"1060.79\", \"side\":\"BUY\", \"hash\":\"2d248166f954d71331105e7eb5caf0ecf9fc0ed4\", \"best_bid\":\"0.53\", \"best_ask\":\"0.55\"}, {\"asset_id\":\"64053005904884194822931764831592250494815136296598204104072528088122126148949\", \"price\":\"0.98\", \"size\":\"1060.79\", \"side\":\"SELL\", \"hash\":\"0db62fe6964b2c5158b317c6b77eb447004afa99\", \"best_bid\":\"0.45\", \"best_ask\":\"0.47\"}], \"timestamp\":\"1785207466141\", \"event_type\":\"price_change\"}","received_at":"2026-07-28T02:57:46.170383Z","schema_version":"clob-market-ws.price_change.v1","sequence":null,"server_hash":null,"server_timestamp":"1785207466141","session_id":"5aad79be415c487c84df42bebd84ee93","source":"clob_market_ws"},"received_at":"2026-07-28T02:57:46.170383Z","record_id":"807abcfdce52dcee3b2d637dc28327a2c4bf5b38d934eb4e31bcc2bc1ebaf4c7","schema_fingerprint":"4aa3821a28b0b7c2400bc59aba4bcc0a76e971dadd19610d3ad38c768e124dc7","schema_version":"edge-lab-recorder.raw.v1","sequence":null,"source":"clob_market_ws"}
{"event_at":"2026-07-28T02:57:46.154000Z","event_fingerprint":"9bbc88d77c687f31957f621a578a4d7d7d5ddf5360c5d5867c40f323bf55f462","payload":{"connection_id":"955646bd8bf740759faf38750c0f263f","event_at":"2026-07-28T02:57:46.154000Z","event_type":"price_change","frame_hash":"aaedb9f5e0d8b4fdbe15052a0c5779961362fab57c1eb66ff45f6346ba5b9b3d","frame_index":0,"kind":"data","monotonic_ns":309449189313791,"payload":{"event_type":"price_change","market":"0x0f70d07969bc69eaa97d0987de651885fdca02263688026aa11e7678af8f87aa","price_changes":[{"asset_id":"58313761654877669244690227616056238030136603415514645252000528337391143520538","best_ask":"0.55","best_bid":"0.53","hash":"8e547c1528948404370292df8caee76b521a179f","price":"0.45","side":"BUY","size":"165.3"},{"asset_id":"64053005904884194822931764831592250494815136296598204104072528088122126148949","best_ask":"0.47","best_bid":"0.45","hash":"17511801bad1832542e4f27534adab79b3d7b908","price":"0.55","side":"SELL","size":"165.3"}],"timestamp":"1785207466154"},"payload_hash":"b6fe9a6139d5f350e18d4aa450b23f33ac7e35aba6b290e94af7a892648ff7e6","raw_frame":"{\"market\":\"0x0f70d07969bc69eaa97d0987de651885fdca02263688026aa11e7678af8f87aa\", \"price_changes\":[{\"asset_id\":\"58313761654877669244690227616056238030136603415514645252000528337391143520538\", \"price\":\"0.45\", \"size\":\"165.3\", \"side\":\"BUY\", \"hash\":\"8e547c1528948404370292df8caee76b521a179f\", \"best_bid\":\"0.53\", \"best_ask\":\"0.55\"}, {\"asset_id\":\"64053005904884194822931764831592250494815136296598204104072528088122126148949\", \"price\":\"0.55\", \"size\":\"165.3\", \"side\":\"SELL\", \"hash\":\"17511801bad1832542e4f27534adab79b3d7b908\", \"best_bid\":\"0.45\", \"best_ask\":\"0.47\"}], \"timestamp\":\"1785207466154\", \"event_type\":\"price_change\"}","received_at":"2026-07-28T02:57:46.171916Z","schema_version":"clob-market-ws.price_change.v1","sequence":null,"server_hash":null,"server_timestamp":"1785207466154","session_id":"5aad79be415c487c84df42bebd84ee93","source":"clob_market_ws"},"received_at":"2026-07-28T02:57:46.171916Z","record_id":"529d1d5dfdfa2020012862a5d4e15a9d29b98b262b86df9376d410f1e8abd37e","schema_fingerprint":"4aa3821a28b0b7c2400bc59aba4bcc0a76e971dadd19610d3ad38c768e124dc7","schema_version":"edge-lab-recorder.raw.v1","sequence":null,"source":"clob_market_ws"}
{"event_at":"2026-07-28T02:57:46.152000Z","event_fingerprint":"74a34adfde2942f5c70d82bccd18557fcb03aa1246f81273d321a7c7036517ee","payload":{"connection_id":"955646bd8bf740759faf38750c0f263f","event_at":"2026-07-28T02:57:46.152000Z","event_type":"last_trade_price","frame_hash":"fbb4241b26f595f14476873f857aab24568bd20ef675375557da5d5c98dfebc5","frame_index":0,"kind":"data","monotonic_ns":309449190790125,"payload":{"asset_id":"64053005904884194822931764831592250494815136296598204104072528088122126148949","event_type":"last_trade_price","fee_rate_bps":"0","market":"0x0f70d07969bc69eaa97d0987de651885fdca02263688026aa11e7678af8f87aa","price":"0.43","side":"SELL","size":"518.86","timestamp":"1785207466152","transaction_hash":"0xf68cc9f08c2496632e8e366b1fe51e2d0f2813cdb9a24681f4a0516ed6d6f4bb"},"payload_hash":"24c8612ff3d68adb75cd2619a54ae4e341a78b7e324c09b59dd8acb1168385c6","raw_frame":"{\"market\":\"0x0f70d07969bc69eaa97d0987de651885fdca02263688026aa11e7678af8f87aa\", \"asset_id\":\"64053005904884194822931764831592250494815136296598204104072528088122126148949\", \"price\":\"0.43\", \"size\":\"518.86\", \"fee_rate_bps\":\"0\", \"side\":\"SELL\", \"timestamp\":\"1785207466152\", \"event_type\":\"last_trade_price\", \"transaction_hash\":\"0xf68cc9f08c2496632e8e366b1fe51e2d0f2813cdb9a24681f4a0516ed6d6f4bb\"}","received_at":"2026-07-28T02:57:46.173393Z","schema_version":"clob-market-ws.last_trade_price.v1","sequence":null,"server_hash":null,"server_timestamp":"1785207466152","session_id":"5aad79be415c487c84df42bebd84ee93","source":"clob_market_ws"},"received_at":"2026-07-28T02:57:46.173393Z","record_id":"2ca1cb4b080ba5c4fc04a4db28a3071a623e48c511c85fe688dfafe030cc18b7","schema_fingerprint":"95ad9be75a4b695cd99991e12b2592bc7346f3f5388a82d0000ba65bc0d9fd0a","schema_version":"edge-lab-recorder.raw.v1","sequence":null,"source":"clob_market_ws"}
{"event_at":"2026-07-28T02:57:46.179000Z","event_fingerprint":"23f9aafa8efcddbff314ead7be9b5c841cb12d95019513a92676fc98ebc23262","payload":{"connection_id":"955646bd8bf740759faf38750c0f263f","event_at":"2026-07-28T02:57:46.179000Z","event_type":"price_change","frame_hash":"a7739c694ab4607a55cd84eaa0086d759019aeeaf1c37322da43ac270a5c4a07","frame_index":0,"kind":"data","monotonic_ns":309449191947583,"payload":{"event_type":"price_change","market":"0x0f70d07969bc69eaa97d0987de651885fdca02263688026aa11e7678af8f87aa","price_changes":[{"asset_id":"64053005904884194822931764831592250494815136296598204104072528088122126148949","best_ask":"0.47","best_bid":"0.45","hash":"ce3799593befcbe5c7e93746402b00985802c236","price":"0.41","side":"BUY","size":"65.2"},{"asset_id":"58313761654877669244690227616056238030136603415514645252000528337391143520538","best_ask":"0.55","best_bid":"0.53","hash":"4212eafea499a00390c3454d67d20de59acaed6c","price":"0.59","side":"SELL","size":"65.2"}],"timestamp":"1785207466179"},"payload_hash":"0c2b85ce4313bbcc721a0a28e6cecb27a4c3a0429fa835021fbe1acf98491ab2","raw_frame":"{\"market\":\"0x0f70d07969bc69eaa97d0987de651885fdca02263688026aa11e7678af8f87aa\", \"price_changes\":[{\"asset_id\":\"64053005904884194822931764831592250494815136296598204104072528088122126148949\", \"price\":\"0.41\", \"size\":\"65.2\", \"side\":\"BUY\", \"hash\":\"ce3799593befcbe5c7e93746402b00985802c236\", \"best_bid\":\"0.45\", \"best_ask\":\"0.47\"}, {\"asset_id\":\"58313761654877669244690227616056238030136603415514645252000528337391143520538\", \"price\":\"0.59\", \"size\":\"65.2\", \"side\":\"SELL\", \"hash\":\"4212eafea499a00390c3454d67d20de59acaed6c\", \"best_bid\":\"0.53\", \"best_ask\":\"0.55\"}], \"timestamp\":\"1785207466179\", \"event_type\":\"price_change\"}","received_at":"2026-07-28T02:57:46.174551Z","schema_version":"clob-market-ws.price_change.v1","sequence":null,"server_hash":null,"server_timestamp":"1785207466179","session_id":"5aad79be415c487c84df42bebd84ee93","source":"clob_market_ws"},"received_at":"2026-07-28T02:57:46.174551Z","record_id":"b8376fe86a27c5cb0279c4067e65d584bd2891b6bed06df8f4f7fced44e50a35","schema_fingerprint":"4aa3821a28b0b7c2400bc59aba4bcc0a76e971dadd19610d3ad38c768e124dc7","schema_version":"edge-lab-recorder.raw.v1","sequence":null,"source":"clob_market_ws"}
{"event_at":"2026-07-28T02:57:46.180000Z","event_fingerprint":"0e710445a5c3ae7260d5f474885d6c5f73ad7ba689b318400bf5dcf08a0e0695","payload":{"connection_id":"955646bd8bf740759faf38750c0f263f","event_at":"2026-07-28T02:57:46.180000Z","event_type":"price_change","frame_hash":"d62479a7a0ea0c266b518330d621537ab9f728e93c0828edd4c05e50e8c9add4","frame_index":0,"kind":"data","monotonic_ns":309449193444416,"payload":{"event_type":"price_change","market":"0x0f70d07969bc69eaa97d0987de651885fdca02263688026aa11e7678af8f87aa","price_changes":[{"asset_id":"64053005904884194822931764831592250494815136296598204104072528088122126148949","best_ask":"0.47","best_bid":"0.45","hash":"53d6078bb751144adb568aab7dc492712110a76b","price":"0.44","side":"BUY","size":"132"},{"asset_id":"58313761654877669244690227616056238030136603415514645252000528337391143520538","best_ask":"0.55","best_bid":"0.53","hash":"eb2b39fc1734c22592b87dee82e2b76fbf25af81","price":"0.56","side":"SELL","size":"132"}],"timestamp":"1785207466180"},"payload_hash":"53b579ec2f1e518d85f16776f0542f15c48c0796396faef223c0ebf505b9e6a6","raw_frame":"{\"market\":\"0x0f70d07969bc69eaa97d0987de651885fdca02263688026aa11e7678af8f87aa\", \"price_changes\":[{\"asset_id\":\"64053005904884194822931764831592250494815136296598204104072528088122126148949\", \"price\":\"0.44\", \"size\":\"132\", \"side\":\"BUY\", \"hash\":\"53d6078bb751144adb568aab7dc492712110a76b\", \"best_bid\":\"0.45\", \"best_ask\":\"0.47\"}, {\"asset_id\":\"58313761654877669244690227616056238030136603415514645252000528337391143520538\", \"price\":\"0.56\", \"size\":\"132\", \"side\":\"SELL\", \"hash\":\"eb2b39fc1734c22592b87dee82e2b76fbf25af81\", \"best_bid\":\"0.53\", \"best_ask\":\"0.55\"}], \"timestamp\":\"1785207466180\", \"event_type\":\"price_change\"}","received_at":"2026-07-28T02:57:46.176046Z","schema_version":"clob-market-ws.price_change.v1","sequence":null,"server_hash":null,"server_timestamp":"1785207466180","session_id":"5aad79be415c487c84df42bebd84ee93","source":"clob_market_ws"},"received_at":"2026-07-28T02:57:46.176046Z","record_id":"891b44259c389664f9eda0984156a1fe0b06188648b0fa2adead4a58b2c5e7b7","schema_fingerprint":"4aa3821a28b0b7c2400bc59aba4bcc0a76e971dadd19610d3ad38c768e124dc7","schema_version":"edge-lab-recorder.raw.v1","sequence":null,"source":"clob_market_ws"}
{"event_at":"2026-07-28T02:57:46.181000Z","event_fingerprint":"e5d3398d52503ae0b37053fe0f4d2749ea55c6594311a543296a53b79bfaf275","payload":{"connection_id":"955646bd8bf740759faf38750c0f263f","event_at":"2026-07-28T02:57:46.181000Z","event_type":"price_change","frame_hash":"3c4c9cd7f16ffd349b030c388ac46088275cf151a6d828716d9887ad5957522a","frame_index":0,"kind":"data","monotonic_ns":309449195032583,"payload":{"event_type":"price_change","market":"0x0f70d07969bc69eaa97d0987de651885fdca02263688026aa11e7678af8f87aa","price_changes":[{"asset_id":"58313761654877669244690227616056238030136603415514645252000528337391143520538","best_ask":"0.55","best_bid":"0.53","hash":"3530b72b5a592c9d61aad5f40ad32fbb69d93c0f","price":"0.52","side":"BUY","size":"94.3"},{"asset_id":"64053005904884194822931764831592250494815136296598204104072528088122126148949","best_ask":"0.47","best_bid":"0.45","hash":"34d4ad910c076188d1ff8e264fd677c61a665451","price":"0.48","side":"SELL","size":"94.3"}],"timestamp":"1785207466181"},"payload_hash":"e27a6cc092efb7cf41c0c7bca5c2e72d0cd29b2fa2c31805a45ce16ed29dcae4","raw_frame":"{\"market\":\"0x0f70d07969bc69eaa97d0987de651885fdca02263688026aa11e7678af8f87aa\", \"price_changes\":[{\"asset_id\":\"58313761654877669244690227616056238030136603415514645252000528337391143520538\", \"price\":\"0.52\", \"size\":\"94.3\", \"side\":\"BUY\", \"hash\":\"3530b72b5a592c9d61aad5f40ad32fbb69d93c0f\", \"best_bid\":\"0.53\", \"best_ask\":\"0.55\"}, {\"asset_id\":\"64053005904884194822931764831592250494815136296598204104072528088122126148949\", \"price\":\"0.48\", \"size\":\"94.3\", \"side\":\"SELL\", \"hash\":\"34d4ad910c076188d1ff8e264fd677c61a665451\", \"best_bid\":\"0.45\", \"best_ask\":\"0.47\"}], \"timestamp\":\"1785207466181\", \"event_type\":\"price_change\"}","received_at":"2026-07-28T02:57:46.177635Z","schema_version":"clob-market-ws.price_change.v1","sequence":null,"server_hash":null,"server_timestamp":"1785207466181","session_id":"5aad79be415c487c84df42bebd84ee93","source":"clob_market_ws"},"received_at":"2026-07-28T02:57:46.177635Z","record_id":"98c0c1cf65dc726df680d253cf60066955d006893c76d9c8c873552f79829f5d","schema_fingerprint":"4aa3821a28b0b7c2400bc59aba4bcc0a76e971dadd19610d3ad38c768e124dc7","schema_version":"edge-lab-recorder.raw.v1","sequence":null,"source":"clob_market_ws"}
{"event_at":"2026-07-28T02:57:46.181000Z","event_fingerprint":"a0e4047d2a7bef36dc829733c14c00687a9dcf202460dd9479a0607a7dadbe36","payload":{"connection_id":"955646bd8bf740759faf38750c0f263f","event_at":"2026-07-28T02:57:46.181000Z","event_type":"price_change","frame_hash":"ab1b5b1c0cea9b27e9d6f9092c2c692092e0c1d5345882f2f19d75ee6df48928","frame_index":0,"kind":"data","monotonic_ns":309449196513208,"payload":{"event_type":"price_change","market":"0x0f70d07969bc69eaa97d0987de651885fdca02263688026aa11e7678af8f87aa","price_changes":[{"asset_id":"64053005904884194822931764831592250494815136296598204104072528088122126148949","best_ask":"0.47","best_bid":"0.45","hash":"91bf28a0edcd03e8577654ea4869682354be4aea","price":"0.45","side":"BUY","size":"41.01"},{"asset_id":"58313761654877669244690227616056238030136603415514645252000528337391143520538","best_ask":"0.55","best_bid":"0.53","hash":"bc92d855a825bb93679309000e019c5822f4ef3d","price":"0.55","side":"SELL","size":"41.01"}],"timestamp":"1785207466181"},"payload_hash":"09d4e4868ea0b9c936add28f1a782a8f4edd23a285b83eebbee0692fce540f1d","raw_frame":"{\"market\":\"0x0f70d07969bc69eaa97d0987de651885fdca02263688026aa11e7678af8f87aa\", \"price_changes\":[{\"asset_id\":\"64053005904884194822931764831592250494815136296598204104072528088122126148949\", \"price\":\"0.45\", \"size\":\"41.01\", \"side\":\"BUY\", \"hash\":\"91bf28a0edcd03e8577654ea4869682354be4aea\", \"best_bid\":\"0.45\", \"best_ask\":\"0.47\"}, {\"asset_id\":\"58313761654877669244690227616056238030136603415514645252000528337391143520538\", \"price\":\"0.55\", \"size\":\"41.01\", \"side\":\"SELL\", \"hash\":\"bc92d855a825bb93679309000e019c5822f4ef3d\", \"best_bid\":\"0.53\", \"best_ask\":\"0.55\"}], \"timestamp\":\"1785207466181\", \"event_type\":\"price_change\"}","received_at":"2026-07-28T02:57:46.179116Z","schema_version":"clob-market-ws.price_change.v1","sequence":null,"server_hash":null,"server_timestamp":"1785207466181","session_id":"5aad79be415c487c84df42bebd84ee93","source":"clob_market_ws"},"received_at":"2026-07-28T02:57:46.179116Z","record_id":"334fe827116668e54425befbd0f45655c5d5fb44c954bd2a2d0627c58c23d58d","schema_fingerprint":"4aa3821a28b0b7c2400bc59aba4bcc0a76e971dadd19610d3ad38c768e124dc7","schema_version":"edge-lab-recorder.raw.v1","sequence":null,"source":"clob_market_ws"}
{"event_at":"2026-07-28T02:57:46.184000Z","event_fingerprint":"fe7c4ed2c6055916a02f99c4b204ef73a533bf32fbea35d93915035aebd5a0e7","payload":{"connection_id":"955646bd8bf740759faf38750c0f263f","event_at":"2026-07-28T02:57:46.184000Z","event_type":"price_change","frame_hash":"158be61597460496f3d44da0d96d0528bd522b1fe06bbd620657c67be8dac63f","frame_index":0,"kind":"data","monotonic_ns":309449197985208,"payload":{"event_type":"price_change","market":"0x0f70d07969bc69eaa97d0987de651885fdca02263688026aa11e7678af8f87aa","price_changes":[{"asset_id":"64053005904884194822931764831592250494815136296598204104072528088122126148949","best_ask":"0.47","best_bid":"0.45","hash":"88189ab3272004033c023c80591161e19a843a24","price":"0.41","side":"BUY","size":"72.2"},{"asset_id":"58313761654877669244690227616056238030136603415514645252000528337391143520538","best_ask":"0.55","best_bid":"0.53","hash":"ca2b894d911d6d20c3f53b16fa4e5f502650310a","price":"0.59","side":"SELL","size":"72.2"}],"timestamp":"1785207466184"},"payload_hash":"5f7ce5b400a59b1aa9fa6ef4809d1885f308556a41a950c2b0457548c9180be5","raw_frame":"{\"market\":\"0x0f70d07969bc69eaa97d0987de651885fdca02263688026aa11e7678af8f87aa\", \"price_changes\":[{\"asset_id\":\"64053005904884194822931764831592250494815136296598204104072528088122126148949\", \"price\":\"0.41\", \"size\":\"72.2\", \"side\":\"BUY\", \"hash\":\"88189ab3272004033c023c80591161e19a843a24\", \"best_bid\":\"0.45\", \"best_ask\":\"0.47\"}, {\"asset_id\":\"58313761654877669244690227616056238030136603415514645252000528337391143520538\", \"price\":\"0.59\", \"size\":\"72.2\", \"side\":\"SELL\", \"hash\":\"ca2b894d911d6d20c3f53b16fa4e5f502650310a\", \"best_bid\":\"0.53\", \"best_ask\":\"0.55\"}], \"timestamp\":\"1785207466184\", \"event_type\":\"price_change\"}","received_at":"2026-07-28T02:57:46.180588Z","schema_version":"clob-market-ws.price_change.v1","sequence":null,"server_hash":null,"server_timestamp":"1785207466184","session_id":"5aad79be415c487c84df42bebd84ee93","source":"clob_market_ws"},"received_at":"2026-07-28T02:57:46.180588Z","record_id":"6ab862ffd3cbf1a4b7cde14b3f3b813b66d824d97ced10bc52d5185b7d169c08","schema_fingerprint":"4aa3821a28b0b7c2400bc59aba4bcc0a76e971dadd19610d3ad38c768e124dc7","schema_version":"edge-lab-recorder.raw.v1","sequence":null,"source":"clob_market_ws"}
{"event_at":"2026-07-28T02:57:46.185000Z","event_fingerprint":"90558b9accceaafc6ae59366e589232a86f9088dde150db61a6fa8bc15b8cdf5","payload":{"connection_id":"955646bd8bf740759faf38750c0f263f","event_at":"2026-07-28T02:57:46.185000Z","event_type":"price_change","frame_hash":"562d289d5953a5daff5e551577973cf607b6ded5d728b2cf0f64a967393a3745","frame_index":0,"kind":"data","monotonic_ns":309449199430333,"payload":{"event_type":"price_change","market":"0x0f70d07969bc69eaa97d0987de651885fdca02263688026aa11e7678af8f87aa","price_changes":[{"asset_id":"58313761654877669244690227616056238030136603415514645252000528337391143520538","best_ask":"0.55","best_bid":"0.53","hash":"d0925a91e2dbb31dd601316e8180110d31f25de3","price":"0.52","side":"BUY","size":"84.3"},{"asset_id":"64053005904884194822931764831592250494815136296598204104072528088122126148949","best_ask":"0.47","best_bid":"0.45","hash":"fe7fc316972f172214affec772f0aeaef48bf4ce","price":"0.48","side":"SELL","size":"84.3"}],"timestamp":"1785207466185"},"payload_hash":"5caddab5426406cdfbd6e3346210f44cfb13ad4060d31504aa7f2f7a01ae5261","raw_frame":"{\"market\":\"0x0f70d07969bc69eaa97d0987de651885fdca02263688026aa11e7678af8f87aa\", \"price_changes\":[{\"asset_id\":\"58313761654877669244690227616056238030136603415514645252000528337391143520538\", \"price\":\"0.52\", \"size\":\"84.3\", \"side\":\"BUY\", \"hash\":\"d0925a91e2dbb31dd601316e8180110d31f25de3\", \"best_bid\":\"0.53\", \"best_ask\":\"0.55\"}, {\"asset_id\":\"64053005904884194822931764831592250494815136296598204104072528088122126148949\", \"price\":\"0.48\", \"size\":\"84.3\", \"side\":\"SELL\", \"hash\":\"fe7fc316972f172214affec772f0aeaef48bf4ce\", \"best_bid\":\"0.45\", \"best_ask\":\"0.47\"}], \"timestamp\":\"1785207466185\", \"event_type\":\"price_change\"}","received_at":"2026-07-28T02:57:46.182033Z","schema_version":"clob-market-ws.price_change.v1","sequence":null,"server_hash":null,"server_timestamp":"1785207466185","session_id":"5aad79be415c487c84df42bebd84ee93","source":"clob_market_ws"},"received_at":"2026-07-28T02:57:46.182033Z","record_id":"2b29d0c5677725f1b491327f350baf6be7e2d8a0adec78fc821244ffada517da","schema_fingerprint":"4aa3821a28b0b7c2400bc59aba4bcc0a76e971dadd19610d3ad38c768e124dc7","schema_version":"edge-lab-recorder.raw.v1","sequence":null,"source":"clob_market_ws"}
{"event_at":"2026-07-28T02:57:46.185000Z","event_fingerprint":"f06c298413ddc3c8fedf2fea38e3d3f0e31f132736aba33ced6f259d73c345e9","payload":{"connection_id":"955646bd8bf740759faf38750c0f263f","event_at":"2026-07-28T02:57:46.185000Z","event_type":"price_change","frame_hash":"246534510d9e2e5ddfc3436f6b118682cab82fcc1cd8f2e4bb4c79c103898eca","frame_index":0,"kind":"data","monotonic_ns":309449200938125,"payload":{"event_type":"price_change","market":"0x0f70d07969bc69eaa97d0987de651885fdca02263688026aa11e7678af8f87aa","price_changes":[{"asset_id":"64053005904884194822931764831592250494815136296598204104072528088122126148949","best_ask":"0.47","best_bid":"0.45","hash":"fe7fc316972f172214affec772f0aeaef48bf4ce","price":"0.36","side":"BUY","size":"85.39"},{"asset_id":"58313761654877669244690227616056238030136603415514645252000528337391143520538","best_ask":"0.55","best_bid":"0.53","hash":"d0925a91e2dbb31dd601316e8180110d31f25de3","price":"0.64","side":"SELL","size":"85.39"}],"timestamp":"1785207466185"},"payload_hash":"c6f9a165f770395e847df5636f6f66077944c5c817f809442e91d6ea6ac38bb4","raw_frame":"{\"market\":\"0x0f70d07969bc69eaa97d0987de651885fdca02263688026aa11e7678af8f87aa\", \"price_changes\":[{\"asset_id\":\"64053005904884194822931764831592250494815136296598204104072528088122126148949\", \"price\":\"0.36\", \"size\":\"85.39\", \"side\":\"BUY\", \"hash\":\"fe7fc316972f172214affec772f0aeaef48bf4ce\", \"best_bid\":\"0.45\", \"best_ask\":\"0.47\"}, {\"asset_id\":\"58313761654877669244690227616056238030136603415514645252000528337391143520538\", \"price\":\"0.64\", \"size\":\"85.39\", \"side\":\"SELL\", \"hash\":\"d0925a91e2dbb31dd601316e8180110d31f25de3\", \"best_bid\":\"0.53\", \"best_ask\":\"0.55\"}], \"timestamp\":\"1785207466185\", \"event_type\":\"price_change\"}","received_at":"2026-07-28T02:57:46.183538Z","schema_version":"clob-market-ws.price_change.v1","sequence":null,"server_hash":null,"server_timestamp":"1785207466185","session_id":"5aad79be415c487c84df42bebd84ee93","source":"clob_market_ws"},"received_at":"2026-07-28T02:57:46.183538Z","record_id":"126e07d7168b06e1e5fe679d43ee7999578b2c4e812686e886174391dacde106","schema_fingerprint":"4aa3821a28b0b7c2400bc59aba4bcc0a76e971dadd19610d3ad38c768e124dc7","schema_version":"edge-lab-recorder.raw.v1","sequence":null,"source":"clob_market_ws"}
{"event_at":"2026-07-28T02:57:46.185000Z","event_fingerprint":"e9a84e5aa4affea58d1a0286dfff2bd778478d82a9e7849010df39c764ce37c7","payload":{"connection_id":"955646bd8bf740759faf38750c0f263f","event_at":"2026-07-28T02:57:46.185000Z","event_type":"price_change","frame_hash":"61763acbdfcdf0cfb3fa820cc5df20fd7df4d120876e0f33ec740b86c2e654c9","frame_index":0,"kind":"data","monotonic_ns":309449202561625,"payload":{"event_type":"price_change","market":"0x0f70d07969bc69eaa97d0987de651885fdca02263688026aa11e7678af8f87aa","price_changes":[{"asset_id":"64053005904884194822931764831592250494815136296598204104072528088122126148949","best_ask":"0.47","best_bid":"0.45","hash":"fe7fc316972f172214affec772f0aeaef48bf4ce","price":"0.43","side":"BUY","size":"143.4"},{"asset_id":"58313761654877669244690227616056238030136603415514645252000528337391143520538","best_ask":"0.55","best_bid":"0.53","hash":"d0925a91e2dbb31dd601316e8180110d31f25de3","price":"0.57","side":"SELL","size":"143.4"}],"timestamp":"1785207466185"},"payload_hash":"bb222d55f515a5e324895d2117bad58f594aa467675ecd72254d5eff53bff902","raw_frame":"{\"market\":\"0x0f70d07969bc69eaa97d0987de651885fdca02263688026aa11e7678af8f87aa\", \"price_changes\":[{\"asset_id\":\"64053005904884194822931764831592250494815136296598204104072528088122126148949\", \"price\":\"0.43\", \"size\":\"143.4\", \"side\":\"BUY\", \"hash\":\"fe7fc316972f172214affec772f0aeaef48bf4ce\", \"best_bid\":\"0.45\", \"best_ask\":\"0.47\"}, {\"asset_id\":\"58313761654877669244690227616056238030136603415514645252000528337391143520538\", \"price\":\"0.57\", \"size\":\"143.4\", \"side\":\"SELL\", \"hash\":\"d0925a91e2dbb31dd601316e8180110d31f25de3\", \"best_bid\":\"0.53\", \"best_ask\":\"0.55\"}], \"timestamp\":\"1785207466185\", \"event_type\":\"price_change\"}","received_at":"2026-07-28T02:57:46.185163Z","schema_version":"clob-market-ws.price_change.v1","sequence":null,"server_hash":null,"server_timestamp":"1785207466185","session_id":"5aad79be415c487c84df42bebd84ee93","source":"clob_market_ws"},"received_at":"2026-07-28T02:57:46.185163Z","record_id":"68be4bfa20cfb6c3d8ec8821d8b62ff0161aac3b1f42680921ab39cbe0beb1cf","schema_fingerprint":"4aa3821a28b0b7c2400bc59aba4bcc0a76e971dadd19610d3ad38c768e124dc7","schema_version":"edge-lab-recorder.raw.v1","sequence":null,"source":"clob_market_ws"}
{"event_at":"2026-07-28T02:57:46.185000Z","event_fingerprint":"8d4dec2422fd78040813233f1ce9a6e9341d179c801d4cbe9fdd87dbdf7c3965","payload":{"connection_id":"955646bd8bf740759faf38750c0f263f","event_at":"2026-07-28T02:57:46.185000Z","event_type":"price_change","frame_hash":"6c18dc5312a902b491a4549bc5ac59e52878cfd46f2d19eb7f0678193c9df6e6","frame_index":0,"kind":"data","monotonic_ns":309449204043375,"payload":{"event_type":"price_change","market":"0x0f70d07969bc69eaa97d0987de651885fdca02263688026aa11e7678af8f87aa","price_changes":[{"asset_id":"64053005904884194822931764831592250494815136296598204104072528088122126148949","best_ask":"0.47","best_bid":"0.45","hash":"fe7fc316972f172214affec772f0aeaef48bf4ce","price":"0.34","side":"BUY","size":"250.8"},{"asset_id":"58313761654877669244690227616056238030136603415514645252000528337391143520538","best_ask":"0.55","best_bid":"0.53","hash":"d0925a91e2dbb31dd601316e8180110d31f25de3","price":"0.66","side":"SELL","size":"250.8"}],"timestamp":"1785207466185"},"payload_hash":"9b44dcfc8dae9d05178c9078350dbda6d54b59de1f0af5bdc30ab8b67cc0fe38","raw_frame":"{\"market\":\"0x0f70d07969bc69eaa97d0987de651885fdca02263688026aa11e7678af8f87aa\", \"price_changes\":[{\"asset_id\":\"64053005904884194822931764831592250494815136296598204104072528088122126148949\", \"price\":\"0.34\", \"size\":\"250.8\", \"side\":\"BUY\", \"hash\":\"fe7fc316972f172214affec772f0aeaef48bf4ce\", \"best_bid\":\"0.45\", \"best_ask\":\"0.47\"}, {\"asset_id\":\"58313761654877669244690227616056238030136603415514645252000528337391143520538\", \"price\":\"0.66\", \"size\":\"250.8\", \"side\":\"SELL\", \"hash\":\"d0925a91e2dbb31dd601316e8180110d31f25de3\", \"best_bid\":\"0.53\", \"best_ask\":\"0.55\"}], \"timestamp\":\"1785207466185\", \"event_type\":\"price_change\"}","received_at":"2026-07-28T02:57:46.186647Z","schema_version":"clob-market-ws.price_change.v1","sequence":null,"server_hash":null,"server_timestamp":"1785207466185","session_id":"5aad79be415c487c84df42bebd84ee93","source":"clob_market_ws"},"received_at":"2026-07-28T02:57:46.186647Z","record_id":"2b55b974be7a8e079a4764a3ecccd90be5af8b6cb10013723ea14529a500c1e4","schema_fingerprint":"4aa3821a28b0b7c2400bc59aba4bcc0a76e971dadd19610d3ad38c768e124dc7","schema_version":"edge-lab-recorder.raw.v1","sequence":null,"source":"clob_market_ws"}
{"event_at":"2026-07-28T02:57:46.190000Z","event_fingerprint":"b67f6e4a967da94d55858790b994b37490f67a63ede778fe1807a17cf9840c91","payload":{"connection_id":"955646bd8bf740759faf38750c0f263f","event_at":"2026-07-28T02:57:46.190000Z","event_type":"price_change","frame_hash":"44069e5dbbaea2a22f9a6e5b1cae2ac912bd7aaba1cfc8e89c0c26099db7af46","frame_index":0,"kind":"data","monotonic_ns":309449205576708,"payload":{"event_type":"price_change","market":"0x0f70d07969bc69eaa97d0987de651885fdca02263688026aa11e7678af8f87aa","price_changes":[{"asset_id":"64053005904884194822931764831592250494815136296598204104072528088122126148949","best_ask":"0.47","best_bid":"0.45","hash":"3686d809ddd457011877c146a34b41924bc3615d","price":"0.45","side":"BUY","size":"30"},{"asset_id":"58313761654877669244690227616056238030136603415514645252000528337391143520538","best_ask":"0.55","best_bid":"0.53","hash":"310bbef0f78c56b31193dcf5e851395da63f4144","price":"0.55","side":"SELL","size":"30"}],"timestamp":"1785207466190"},"payload_hash":"44d62e6efc49df23dc19d4c02b4c11d76ade3ef8adcca96f6bec3d8643a1c04e","raw_frame":"{\"market\":\"0x0f70d07969bc69eaa97d0987de651885fdca02263688026aa11e7678af8f87aa\", \"price_changes\":[{\"asset_id\":\"64053005904884194822931764831592250494815136296598204104072528088122126148949\", \"price\":\"0.45\", \"size\":\"30\", \"side\":\"BUY\", \"hash\":\"3686d809ddd457011877c146a34b41924bc3615d\", \"best_bid\":\"0.45\", \"best_ask\":\"0.47\"}, {\"asset_id\":\"58313761654877669244690227616056238030136603415514645252000528337391143520538\", \"price\":\"0.55\", \"size\":\"30\", \"side\":\"SELL\", \"hash\":\"310bbef0f78c56b31193dcf5e851395da63f4144\", \"best_bid\":\"0.53\", \"best_ask\":\"0.55\"}], \"timestamp\":\"1785207466190\", \"event_type\":\"price_change\"}","received_at":"2026-07-28T02:57:46.188179Z","schema_version":"clob-market-ws.price_change.v1","sequence":null,"server_hash":null,"server_timestamp":"1785207466190","session_id":"5aad79be415c487c84df42bebd84ee93","source":"clob_market_ws"},"received_at":"2026-07-28T02:57:46.188179Z","record_id":"f6c039378e0093e8971932b7d56ee7ffaeab8a14b5470f69193220398db98281","schema_fingerprint":"4aa3821a28b0b7c2400bc59aba4bcc0a76e971dadd19610d3ad38c768e124dc7","schema_version":"edge-lab-recorder.raw.v1","sequence":null,"source":"clob_market_ws"}
