{"event_at":"2026-07-28T02:58:45.288000Z","event_fingerprint":"80952b086e6c368a481a54d1f19070eea8dce8b61e90a05aa6f933270a839d34","payload":{"connection_id":"955646bd8bf740759faf38750c0f263f","event_at":"2026-07-28T02:58:45.288000Z","event_type":"price_change","frame_hash":"7a75f2aa6c96d49f1ecf0afaaf69c78462383842aad1b3442df6b4651fc8e273","frame_index":0,"kind":"data","monotonic_ns":309508188594666,"payload":{"event_type":"price_change","market":"0x0f70d07969bc69eaa97d0987de651885fdca02263688026aa11e7678af8f87aa","price_changes":[{"asset_id":"58313761654877669244690227616056238030136603415514645252000528337391143520538","best_ask":"0.34","best_bid":"0.33","hash":"4138c276dcbf200bb928715d158d33d511be881d","price":"0.24","side":"BUY","size":"210.3"},{"asset_id":"64053005904884194822931764831592250494815136296598204104072528088122126148949","best_ask":"0.67","best_bid":"0.66","hash":"d49402cdad7818f3f5eae5525521497317ef29a5","price":"0.76","side":"SELL","size":"210.3"}],"timestamp":"1785207525288"},"payload_hash":"a62bee0e7fa779e50e80d078b2c7389987b9bac14da7952de67794c0849d76e0","raw_frame":"{\"market\":\"0x0f70d07969bc69eaa97d0987de651885fdca02263688026aa11e7678af8f87aa\", \"price_changes\":[{\"asset_id\":\"58313761654877669244690227616056238030136603415514645252000528337391143520538\", \"price\":\"0.24\", \"size\":\"210.3\", \"side\":\"BUY\", \"hash\":\"4138c276dcbf200bb928715d158d33d511be881d\", \"best_bid\":\"0.33\", \"best_ask\":\"0.34\"}, {\"asset_id\":\"64053005904884194822931764831592250494815136296598204104072528088122126148949\", \"price\":\"0.76\", \"size\":\"210.3\", \"side\":\"SELL\", \"hash\":\"d49402cdad7818f3f5eae5525521497317ef29a5\", \"best_bid\":\"0.66\", \"best_ask\":\"0.67\"}], \"timestamp\":\"1785207525288\", \"event_type\":\"price_change\"}","received_at":"2026-07-28T02:58:45.170767Z","schema_version":"clob-market-ws.price_change.v1","sequence":null,"server_hash":null,"server_timestamp":"1785207525288","session_id":"5aad79be415c487c84df42bebd84ee93","source":"clob_market_ws"},"received_at":"2026-07-28T02:58:45.170767Z","record_id":"42f4182c68c0d4d853ef80a6234481506151e1cc8aefc23fcabbaf9b4fbfcb19","schema_fingerprint":"4aa3821a28b0b7c2400bc59aba4bcc0a76e971dadd19610d3ad38c768e124dc7","schema_version":"edge-lab-recorder.raw.v1","sequence":null,"source":"clob_market_ws"}
{"event_at":"2026-07-28T02:58:45.301000Z","event_fingerprint":"ef48dbec6988f3564723aab4307011bef77bb6725536593cacfbead4803656bf","payload":{"connection_id":"955646bd8bf740759faf38750c0f263f","event_at":"2026-07-28T02:58:45.301000Z","event_type":"price_change","frame_hash":"9af7b34ff797624c5e44d7e1904ab0c7e118fc69ee2b4556e71cd11cb69ef659","frame_index":0,"kind":"data","monotonic_ns":309508190723333,"payload":{"event_type":"price_change","market":"0x0f70d07969bc69eaa97d0987de651885fdca02263688026aa11e7678af8f87aa","price_changes":[{"asset_id":"58313761654877669244690227616056238030136603415514645252000528337391143520538","best_ask":"0.34","best_bid":"0.33","hash":"61e7a4b59dbadf6fbc1203a455cb406407f4de01","price":"0.29","side":"BUY","size":"109.1"},{"asset_id":"64053005904884194822931764831592250494815136296598204104072528088122126148949","best_ask":"0.67","best_bid":"0.66","hash":"adfe8c39e5b131a8fb621c8542d57c75579b72ec","price":"0.71","side":"SELL","size":"109.1"}],"timestamp":"1785207525301"},"payload_hash":"15f04f4e843ee832fdf188818a79ed2652445ca6e3c5d19b2301f2051cd1c054","raw_frame":"{\"market\":\"0x0f70d07969bc69eaa97d0987de651885fdca02263688026aa11e7678af8f87aa\", \"price_changes\":[{\"asset_id\":\"58313761654877669244690227616056238030136603415514645252000528337391143520538\", \"price\":\"0.29\", \"size\":\"109.1\", \"side\":\"BUY\", \"hash\":\"61e7a4b59dbadf6fbc1203a455cb406407f4de01\", \"best_bid\":\"0.33\", \"best_ask\":\"0.34\"}, {\"asset_id\":\"64053005904884194822931764831592250494815136296598204104072528088122126148949\", \"price\":\"0.71\", \"size\":\"109.1\", \"side\":\"SELL\", \"hash\":\"adfe8c39e5b131a8fb621c8542d57c75579b72ec\", \"best_bid\":\"0.66\", \"best_ask\":\"0.67\"}], \"timestamp\":\"1785207525301\", \"event_type\":\"price_change\"}","received_at":"2026-07-28T02:58:45.172898Z","schema_version":"clob-market-ws.price_change.v1","sequence":null,"server_hash":null,"server_timestamp":"1785207525301","session_id":"5aad79be415c487c84df42bebd84ee93","source":"clob_market_ws"},"received_at":"2026-07-28T02:58:45.172898Z","record_id":"ce690deb5d849e68bc8990c5bee7adec454f402b3ab3cbd11c5fe5dc011f47d2","schema_fingerprint":"4aa3821a28b0b7c2400bc59aba4bcc0a76e971dadd19610d3ad38c768e124dc7","schema_version":"edge-lab-recorder.raw.v1","sequence":null,"source":"clob_market_ws"}
{"event_at":"2026-07-28T02:58:45.323000Z","event_fingerprint":"39f23fde1ab17cfed0447347959990809994c464389c3eb4222508f92c822682","payload":{"connection_id":"955646bd8bf740759faf38750c0f263f","event_at":"2026-07-28T02:58:45.323000Z","event_type":"price_change","frame_hash":"119ea9d354a08be3666d4b0870d0f2b33f1fc80b3b28073bf831748f69c96621","frame_index":0,"kind":"data","monotonic_ns":309508197788208,"payload":{"event_type":"price_change","market":"0x0f70d07969bc69eaa97d0987de651885fdca02263688026aa11e7678af8f87aa","price_changes":[{"asset_id":"58313761654877669244690227616056238030136603415514645252000528337391143520538","best_ask":"0.34","best_bid":"0.33","hash":"15f66c9a77f1d4908d63f2ffb468f1e92e91e915","price":"0.28","side":"BUY","size":"127.03"},{"asset_id":"64053005904884194822931764831592250494815136296598204104072528088122126148949","best_ask":"0.67","best_bid":"0.66","hash":"2079ad3b18d72e643bfdc08a1687c4040ac87f56","price":"0.72","side":"SELL","size":"127.03"}],"timestamp":"1785207525323"},"payload_hash":"d4b673d9ccbba2ed5cb554b17c3b32e5cfe4ab365569b097f083a4ba8273282d","raw_frame":"{\"market\":\"0x0f70d07969bc69eaa97d0987de651885fdca02263688026aa11e7678af8f87aa\", \"price_changes\":[{\"asset_id\":\"58313761654877669244690227616056238030136603415514645252000528337391143520538\", \"price\":\"0.28\", \"size\":\"127.03\", \"side\":\"BUY\", \"hash\":\"15f66c9a77f1d4908d63f2ffb468f1e92e91e915\", \"best_bid\":\"0.33\", \"best_ask\":\"0.34\"}, {\"asset_id\":\"64053005904884194822931764831592250494815136296598204104072528088122126148949\", \"price\":\"0.72\", \"size\":\"127.03\", \"side\":\"SELL\", \"hash\":\"2079ad3b18d72e643bfdc08a1687c4040ac87f56\", \"best_bid\":\"0.66\", \"best_ask\":\"0.67\"}], \"timestamp\":\"1785207525323\", \"event_type\":\"price_change\"}","received_at":"2026-07-28T02:58:45.179963Z","schema_version":"clob-market-ws.price_change.v1","sequence":null,"server_hash":null,"server_timestamp":"1785207525323","session_id":"5aad79be415c487c84df42bebd84ee93","source":"clob_market_ws"},"received_at":"2026-07-28T02:58:45.179963Z","record_id":"c40634efda359337fab470a53b275eab1d0d279a696f53684cf5fb4ac0a28a26","schema_fingerprint":"4aa3821a28b0b7c2400bc59aba4bcc0a76e971dadd19610d3ad38c768e124dc7","schema_version":"edge-lab-recorder.raw.v1","sequence":null,"source":"clob_market_ws"}
{"event_at":"2026-07-28T02:58:45.323000Z","event_fingerprint":"c2d09b4db0800e639f6f0a688497879f48325ad2e823d303202a223bfd3c2332","payload":{"connection_id":"955646bd8bf740759faf38750c0f263f","event_at":"2026-07-28T02:58:45.323000Z","event_type":"price_change","frame_hash":"16b2e4d3f050c70bb2051047a1929e7870910767d6264deeb1825f22be8522c5","frame_index":0,"kind":"data","monotonic_ns":309508199309541,"payload":{"event_type":"price_change","market":"0x0f70d07969bc69eaa97d0987de651885fdca02263688026aa11e7678af8f87aa","price_changes":[{"asset_id":"64053005904884194822931764831592250494815136296598204104072528088122126148949","best_ask":"0.67","best_bid":"0.66","hash":"8380219c7f0014970e7ca8df7995ccc470a10a8f","price":"0.01","side":"BUY","size":"2695.52"},{"asset_id":"58313761654877669244690227616056238030136603415514645252000528337391143520538","best_ask":"0.34","best_bid":"0.33","hash":"84beed92258edf9d6fa47104d84312e8f28fe36f","price":"0.99","side":"SELL","size":"2695.52"}],"timestamp":"1785207525323"},"payload_hash":"b0f3279f013c5c0bb06e61a43c4abb0099858c44431766c03d30dd6aa90a3837","raw_frame":"{\"market\":\"0x0f70d07969bc69eaa97d0987de651885fdca02263688026aa11e7678af8f87aa\", \"price_changes\":[{\"asset_id\":\"64053005904884194822931764831592250494815136296598204104072528088122126148949\", \"price\":\"0.01\", \"size\":\"2695.52\", \"side\":\"BUY\", \"hash\":\"8380219c7f0014970e7ca8df7995ccc470a10a8f\", \"best_bid\":\"0.66\", \"best_ask\":\"0.67\"}, {\"asset_id\":\"58313761654877669244690227616056238030136603415514645252000528337391143520538\", \"price\":\"0.99\", \"size\":\"2695.52\", \"side\":\"SELL\", \"hash\":\"84beed92258edf9d6fa47104d84312e8f28fe36f\", \"best_bid\":\"0.33\", \"best_ask\":\"0.34\"}], \"timestamp\":\"1785207525323\", \"event_type\":\"price_change\"}","received_at":"2026-07-28T02:58:45.181486Z","schema_version":"clob-market-ws.price_change.v1","sequence":null,"server_hash":null,"server_timestamp":"1785207525323","session_id":"5aad79be415c487c84df42bebd84ee93","source":"clob_market_ws"},"received_at":"2026-07-28T02:58:45.181486Z","record_id":"456d8d34b18d740820ee4d9fc343816bbfaee564b9b68c8844568b4c2605c495","schema_fingerprint":"4aa3821a28b0b7c2400bc59aba4bcc0a76e971dadd19610d3ad38c768e124dc7","schema_version":"edge-lab-recorder.raw.v1","sequence":null,"source":"clob_market_ws"}
{"event_at":"2026-07-28T02:58:45.345000Z","event_fingerprint":"79f0bb78cddd813d1d10abcaf33cd5a1a694916531257d18d61bb9183059553d","payload":{"connection_id":"955646bd8bf740759faf38750c0f263f","event_at":"2026-07-28T02:58:45.345000Z","event_type":"price_change","frame_hash":"06429cb810dc0cf64eedc2172169fc55a259a8273090def731dc60316156650a","frame_index":0,"kind":"data","monotonic_ns":309508220502333,"payload":{"event_type":"price_change","market":"0x0f70d07969bc69eaa97d0987de651885fdca02263688026aa11e7678af8f87aa","price_changes":[{"asset_id":"58313761654877669244690227616056238030136603415514645252000528337391143520538","best_ask":"0.34","best_bid":"0.33","hash":"d167532f0c0de4891bedf8b4f217cc4b90d9d00a","price":"0.02","side":"BUY","size":"907.79"},{"asset_id":"64053005904884194822931764831592250494815136296598204104072528088122126148949","best_ask":"0.67","best_bid":"0.66","hash":"83237087094501fd977e95cd9c3890da02b00c32","price":"0.98","side":"SELL","size":"907.79"}],"timestamp":"1785207525345"},"payload_hash":"c14fc3d440919b51cc06858c6079df8687216d88dff8d84376df291ed89e6864","raw_frame":"{\"market\":\"0x0f70d07969bc69eaa97d0987de651885fdca02263688026aa11e7678af8f87aa\", \"price_changes\":[{\"asset_id\":\"58313761654877669244690227616056238030136603415514645252000528337391143520538\", \"price\":\"0.02\", \"size\":\"907.79\", \"side\":\"BUY\", \"hash\":\"d167532f0c0de4891bedf8b4f217cc4b90d9d00a\", \"best_bid\":\"0.33\", \"best_ask\":\"0.34\"}, {\"asset_id\":\"64053005904884194822931764831592250494815136296598204104072528088122126148949\", \"price\":\"0.98\", \"size\":\"907.79\", \"side\":\"SELL\", \"hash\":\"83237087094501fd977e95cd9c3890da02b00c32\", \"best_bid\":\"0.66\", \"best_ask\":\"0.67\"}], \"timestamp\":\"1785207525345\", \"event_type\":\"price_change\"}","received_at":"2026-07-28T02:58:45.202675Z","schema_version":"clob-market-ws.price_change.v1","sequence":null,"server_hash":null,"server_timestamp":"1785207525345","session_id":"5aad79be415c487c84df42bebd84ee93","source":"clob_market_ws"},"received_at":"2026-07-28T02:58:45.202675Z","record_id":"70b9d1c2cb345d899958adbb846febbaa53d1a48aa82f35b2e3ff0ac35d5218b","schema_fingerprint":"4aa3821a28b0b7c2400bc59aba4bcc0a76e971dadd19610d3ad38c768e124dc7","schema_version":"edge-lab-recorder.raw.v1","sequence":null,"source":"clob_market_ws"}
{"event_at":"2026-07-28T02:58:45.351000Z","event_fingerprint":"0a95b492d89ec34b522dc8937f3237ac8610824161b99c75a49c24393a40dcff","payload":{"connection_id":"955646bd8bf740759faf38750c0f263f","event_at":"2026-07-28T02:58:45.351000Z","event_type":"price_change","frame_hash":"b347a05f66a0338e8c637889536ab537c6cf7fb1a9f68ad32e0107d279ce3c0a","frame_index":0,"kind":"data","monotonic_ns":309508226350125,"payload":{"event_type":"price_change","market":"0x0f70d07969bc69eaa97d0987de651885fdca02263688026aa11e7678af8f87aa","price_changes":[{"asset_id":"64053005904884194822931764831592250494815136296598204104072528088122126148949","best_ask":"0.67","best_bid":"0.66","hash":"f266297cf9142d1b078c5b6386e65293224b1f16","price":"0.01","side":"BUY","size":"2700.52"},{"asset_id":"58313761654877669244690227616056238030136603415514645252000528337391143520538","best_ask":"0.34","best_bid":"0.33","hash":"ce31245e2586f52ec7f9cb17b3daa5a80f4c9335","price":"0.99","side":"SELL","size":"2700.52"}],"timestamp":"1785207525351"},"payload_hash":"71c8044bbe51100e42a0b6343b8c58778b3da77e2d14778dcae0dd12905cb01b","raw_frame":"{\"market\":\"0x0f70d07969bc69eaa97d0987de651885fdca02263688026aa11e7678af8f87aa\", \"price_changes\":[{\"asset_id\":\"64053005904884194822931764831592250494815136296598204104072528088122126148949\", \"price\":\"0.01\", \"size\":\"2700.52\", \"side\":\"BUY\", \"hash\":\"f266297cf9142d1b078c5b6386e65293224b1f16\", \"best_bid\":\"0.66\", \"best_ask\":\"0.67\"}, {\"asset_id\":\"58313761654877669244690227616056238030136603415514645252000528337391143520538\", \"price\":\"0.99\", \"size\":\"2700.52\", \"side\":\"SELL\", \"hash\":\"ce31245e2586f52ec7f9cb17b3daa5a80f4c9335\", \"best_bid\":\"0.33\", \"best_ask\":\"0.34\"}], \"timestamp\":\"1785207525351\", \"event_type\":\"price_change\"}","received_at":"2026-07-28T02:58:45.208527Z","schema_version":"clob-market-ws.price_change.v1","sequence":null,"server_hash":null,"server_timestamp":"1785207525351","session_id":"5aad79be415c487c84df42bebd84ee93","source":"clob_market_ws"},"received_at":"2026-07-28T02:58:45.208527Z","record_id":"3a96d48f11877304673de6b4cf57c954a192d651c03bea855860c9d27a64da41","schema_fingerprint":"4aa3821a28b0b7c2400bc59aba4bcc0a76e971dadd19610d3ad38c768e124dc7","schema_version":"edge-lab-recorder.raw.v1","sequence":null,"source":"clob_market_ws"}
{"event_at":"2026-07-28T02:58:45.375000Z","event_fingerprint":"bb589ddf6b31e0ee81ef6cd16df2a42c3b2d4e285cf78ab9ae86c6266849f23b","payload":{"connection_id":"955646bd8bf740759faf38750c0f263f","event_at":"2026-07-28T02:58:45.375000Z","event_type":"price_change","frame_hash":"fc7ef777d41f47dc9e948a202209ca6a840034f3bb0b5e4e226e312d0fff794f","frame_index":0,"kind":"data","monotonic_ns":309508251061291,"payload":{"event_type":"price_change","market":"0x0f70d07969bc69eaa97d0987de651885fdca02263688026aa11e7678af8f87aa","price_changes":[{"asset_id":"64053005904884194822931764831592250494815136296598204104072528088122126148949","best_ask":"0.67","best_bid":"0.66","hash":"da685b5e7398bd9ee91d793769ffbbbfac8e6d77","price":"0.01","side":"BUY","size":"2695.52"},{"asset_id":"58313761654877669244690227616056238030136603415514645252000528337391143520538","best_ask":"0.34","best_bid":"0.33","hash":"246bf388092d434891f82be8c7a45ef8bb735b50","price":"0.99","side":"SELL","size":"2695.52"}],"timestamp":"1785207525375"},"payload_hash":"41527fb460cf3384059cbd1d60cff6b185892494521b5b949686a295a8736e4a","raw_frame":"{\"market\":\"0x0f70d07969bc69eaa97d0987de651885fdca02263688026aa11e7678af8f87aa\", \"price_changes\":[{\"asset_id\":\"64053005904884194822931764831592250494815136296598204104072528088122126148949\", \"price\":\"0.01\", \"size\":\"2695.52\", \"side\":\"BUY\", \"hash\":\"da685b5e7398bd9ee91d793769ffbbbfac8e6d77\", \"best_bid\":\"0.66\", \"best_ask\":\"0.67\"}, {\"asset_id\":\"58313761654877669244690227616056238030136603415514645252000528337391143520538\", \"price\":\"0.99\", \"size\":\"2695.52\", \"side\":\"SELL\", \"hash\":\"246bf388092d434891f82be8c7a45ef8bb735b50\", \"best_bid\":\"0.33\", \"best_ask\":\"0.34\"}], \"timestamp\":\"1785207525375\", \"event_type\":\"price_change\"}","received_at":"2026-07-28T02:58:45.233235Z","schema_version":"clob-market-ws.price_change.v1","sequence":null,"server_hash":null,"server_timestamp":"1785207525375","session_id":"5aad79be415c487c84df42bebd84ee93","source":"clob_market_ws"},"received_at":"2026-07-28T02:58:45.233235Z","record_id":"5e30b24ffa93e4d0cb96cfda42e27bdb37a52cdf60c662543f9e6bf06c918de3","schema_fingerprint":"4aa3821a28b0b7c2400bc59aba4bcc0a76e971dadd19610d3ad38c768e124dc7","schema_version":"edge-lab-recorder.raw.v1","sequence":null,"source":"clob_market_ws"}
{"event_at":"2026-07-28T02:58:45.376000Z","event_fingerprint":"65c88bbee2ce0bafca2efb8079ac449bae965f0762a498f68364fc21d10b962f","payload":{"connection_id":"955646bd8bf740759faf38750c0f263f","event_at":"2026-07-28T02:58:45.376000Z","event_type":"price_change","frame_hash":"3d4730ca6c93163ca4c2d480f7be02bd4aee60bf0ee3d265dff1ca19bcb37b1e","frame_index":0,"kind":"data","monotonic_ns":309508252581666,"payload":{"event_type":"price_change","market":"0x0f70d07969bc69eaa97d0987de651885fdca02263688026aa11e7678af8f87aa","price_changes":[{"asset_id":"64053005904884194822931764831592250494815136296598204104072528088122126148949","best_ask":"0.67","best_bid":"0.66","hash":"55d70575a383bbaacfdc83926c8b70a046c39632","price":"0.01","side":"BUY","size":"2690.52"},{"asset_id":"58313761654877669244690227616056238030136603415514645252000528337391143520538","best_ask":"0.34","best_bid":"0.33","hash":"67b8155727e17675434988ec2677d0a8cb7d9a5b","price":"0.99","side":"SELL","size":"2690.52"}],"timestamp":"1785207525376"},"payload_hash":"25f31f8f6b86a72e09452d13d2a2422ea7abb2495d7793076e0436a250cad3f4","raw_frame":"{\"market\":\"0x0f70d07969bc69eaa97d0987de651885fdca02263688026aa11e7678af8f87aa\", \"price_changes\":[{\"asset_id\":\"64053005904884194822931764831592250494815136296598204104072528088122126148949\", \"price\":\"0.01\", \"size\":\"2690.52\", \"side\":\"BUY\", \"hash\":\"55d70575a383bbaacfdc83926c8b70a046c39632\", \"best_bid\":\"0.66\", \"best_ask\":\"0.67\"}, {\"asset_id\":\"58313761654877669244690227616056238030136603415514645252000528337391143520538\", \"price\":\"0.99\", \"size\":\"2690.52\", \"side\":\"SELL\", \"hash\":\"67b8155727e17675434988ec2677d0a8cb7d9a5b\", \"best_bid\":\"0.33\", \"best_ask\":\"0.34\"}], \"timestamp\":\"1785207525376\", \"event_type\":\"price_change\"}","received_at":"2026-07-28T02:58:45.234756Z","schema_version":"clob-market-ws.price_change.v1","sequence":null,"server_hash":null,"server_timestamp":"1785207525376","session_id":"5aad79be415c487c84df42bebd84ee93","source":"clob_market_ws"},"received_at":"2026-07-28T02:58:45.234756Z","record_id":"c2e56cd958f905b740d6021a607d66c4263e3eb8ef52078b494a03d79f053395","schema_fingerprint":"4aa3821a28b0b7c2400bc59aba4bcc0a76e971dadd19610d3ad38c768e124dc7","schema_version":"edge-lab-recorder.raw.v1","sequence":null,"source":"clob_market_ws"}
{"event_at":"2026-07-28T02:58:45.494000Z","event_fingerprint":"c12a3fc844d80b93a00dcba087bd5629185079087f5b05b0339cc4b844fb7200","payload":{"connection_id":"955646bd8bf740759faf38750c0f263f","event_at":"2026-07-28T02:58:45.494000Z","event_type":"price_change","frame_hash":"78240204ce1e231c00bcd0995b0159ac9efc941f8a9da6d3575958ec819f7772","frame_index":0,"kind":"data","monotonic_ns":309508372326500,"payload":{"event_type":"price_change","market":"0x0f70d07969bc69eaa97d0987de651885fdca02263688026aa11e7678af8f87aa","price_changes":[{"asset_id":"58313761654877669244690227616056238030136603415514645252000528337391143520538","best_ask":"0.34","best_bid":"0.33","hash":"5b789dc71e0545ff134cf2429f6c73f3b7a57484","price":"0.24","side":"BUY","size":"224.6"},{"asset_id":"64053005904884194822931764831592250494815136296598204104072528088122126148949","best_ask":"0.67","best_bid":"0.66","hash":"07a55ce10d0fd838419cbfc113a0c6be7e9acd52","price":"0.76","side":"SELL","size":"224.6"}],"timestamp":"1785207525494"},"payload_hash":"9796172c03aa866b393d82deaef038972f9a59405613ae986ac0d62ba7913ea3","raw_frame":"{\"market\":\"0x0f70d07969bc69eaa97d0987de651885fdca02263688026aa11e7678af8f87aa\", \"price_changes\":[{\"asset_id\":\"58313761654877669244690227616056238030136603415514645252000528337391143520538\", \"price\":\"0.24\", \"size\":\"224.6\", \"side\":\"BUY\", \"hash\":\"5b789dc71e0545ff134cf2429f6c73f3b7a57484\", \"best_bid\":\"0.33\", \"best_ask\":\"0.34\"}, {\"asset_id\":\"64053005904884194822931764831592250494815136296598204104072528088122126148949\", \"price\":\"0.76\", \"size\":\"224.6\", \"side\":\"SELL\", \"hash\":\"07a55ce10d0fd838419cbfc113a0c6be7e9acd52\", \"best_bid\":\"0.66\", \"best_ask\":\"0.67\"}], \"timestamp\":\"1785207525494\", \"event_type\":\"price_change\"}","received_at":"2026-07-28T02:58:45.354492Z","schema_version":"clob-market-ws.price_change.v1","sequence":null,"server_hash":null,"server_timestamp":"1785207525494","session_id":"5aad79be415c487c84df42bebd84ee93","source":"clob_market_ws"},"received_at":"2026-07-28T02:58:45.354492Z","record_id":"cf64240714747147183fc47f6135f54fc159dac47d7d101ceb8913aba776f036","schema_fingerprint":"4aa3821a28b0b7c2400bc59aba4bcc0a76e971dadd19610d3ad38c768e124dc7","schema_version":"edge-lab-recorder.raw.v1","sequence":null,"source":"clob_market_ws"}
{"event_at":"2026-07-28T02:58:45.500000Z","event_fingerprint":"3fba659e31f6271d13e2eaab85595fc0ebad8548ca97bf604a8568de8d77f6dd","payload":{"connection_id":"955646bd8bf740759faf38750c0f263f","event_at":"2026-07-28T02:58:45.500000Z","event_type":"price_change","frame_hash":"a86306682357a7c534d28017e7c116e3a43458d0717a25fa62b005799b4caf9d","frame_index":0,"kind":"data","monotonic_ns":309508377606666,"payload":{"event_type":"price_change","market":"0x0f70d07969bc69eaa97d0987de651885fdca02263688026aa11e7678af8f87aa","price_changes":[{"asset_id":"58313761654877669244690227616056238030136603415514645252000528337391143520538","best_ask":"0.34","best_bid":"0.33","hash":"72323b18077c1301172a087c4d4133f948d4fc72","price":"0.28","side":"BUY","size":"118.03"},{"asset_id":"64053005904884194822931764831592250494815136296598204104072528088122126148949","best_ask":"0.67","best_bid":"0.66","hash":"6bec782191cfb1a3774d79a52d8dceae3ff080a7","price":"0.72","side":"SELL","size":"118.03"}],"timestamp":"1785207525500"},"payload_hash":"ad1f724723ed0d584deed1a49098ae491758060d10221a549ba1928563a4610c","raw_frame":"{\"market\":\"0x0f70d07969bc69eaa97d0987de651885fdca02263688026aa11e7678af8f87aa\", \"price_changes\":[{\"asset_id\":\"58313761654877669244690227616056238030136603415514645252000528337391143520538\", \"price\":\"0.28\", \"size\":\"118.03\", \"side\":\"BUY\", \"hash\":\"72323b18077c1301172a087c4d4133f948d4fc72\", \"best_bid\":\"0.33\", \"best_ask\":\"0.34\"}, {\"asset_id\":\"64053005904884194822931764831592250494815136296598204104072528088122126148949\", \"price\":\"0.72\", \"size\":\"118.03\", \"side\":\"SELL\", \"hash\":\"6bec782191cfb1a3774d79a52d8dceae3ff080a7\", \"best_bid\":\"0.66\", \"best_ask\":\"0.67\"}], \"timestamp\":\"1785207525500\", \"event_type\":\"price_change\"}","received_at":"2026-07-28T02:58:45.359776Z","schema_version":"clob-market-ws.price_change.v1","sequence":null,"server_hash":null,"server_timestamp":"1785207525500","session_id":"5aad79be415c487c84df42bebd84ee93","source":"clob_market_ws"},"received_at":"2026-07-28T02:58:45.359776Z","record_id":"459a3a5315d864d8a150468d6751e746e07f2a9fdb4f55d943048aa86291aa15","schema_fingerprint":"4aa3821a28b0b7c2400bc59aba4bcc0a76e971dadd19610d3ad38c768e124dc7","schema_version":"edge-lab-recorder.raw.v1","sequence":null,"source":"clob_market_ws"}
{"event_at":"2026-07-28T02:58:45.510000Z","event_fingerprint":"f8f813acc3e7318a1895cfa4bc50cccdde99177d386064940dfd7bdae7f8e158","payload":{"connection_id":"955646bd8bf740759faf38750c0f263f","event_at":"2026-07-28T02:58:45.510000Z","event_type":"price_change","frame_hash":"ac2f002d2678cce83eb9d3e5a52727403a2fc43fa5cf7531575daca1912bf526","frame_index":0,"kind":"data","monotonic_ns":309508384812000,"payload":{"event_type":"price_change","market":"0x0f70d07969bc69eaa97d0987de651885fdca02263688026aa11e7678af8f87aa","price_changes":[{"asset_id":"64053005904884194822931764831592250494815136296598204104072528088122126148949","best_ask":"0.67","best_bid":"0.66","hash":"ce4b6c5ac8b65569b4e83a4e29060262a5022566","price":"0.04","side":"BUY","size":"385.5"},{"asset_id":"58313761654877669244690227616056238030136603415514645252000528337391143520538","best_ask":"0.34","best_bid":"0.33","hash":"7d7f78a48291be841619e8acb107e89126f9902a","price":"0.96","side":"SELL","size":"385.5"}],"timestamp":"1785207525510"},"payload_hash":"9f4f30d60b475e8577e9821d2d4e5a040d0a6deb60c598efb2516ff275e691ac","raw_frame":"{\"market\":\"0x0f70d07969bc69eaa97d0987de651885fdca02263688026aa11e7678af8f87aa\", \"price_changes\":[{\"asset_id\":\"64053005904884194822931764831592250494815136296598204104072528088122126148949\", \"price\":\"0.04\", \"size\":\"385.5\", \"side\":\"BUY\", \"hash\":\"ce4b6c5ac8b65569b4e83a4e29060262a5022566\", \"best_bid\":\"0.66\", \"best_ask\":\"0.67\"}, {\"asset_id\":\"58313761654877669244690227616056238030136603415514645252000528337391143520538\", \"price\":\"0.96\", \"size\":\"385.5\", \"side\":\"SELL\", \"hash\":\"7d7f78a48291be841619e8acb107e89126f9902a\", \"best_bid\":\"0.33\", \"best_ask\":\"0.34\"}], \"timestamp\":\"1785207525510\", \"event_type\":\"price_change\"}","received_at":"2026-07-28T02:58:45.366984Z","schema_version":"clob-market-ws.price_change.v1","sequence":null,"server_hash":null,"server_timestamp":"1785207525510","session_id":"5aad79be415c487c84df42bebd84ee93","source":"clob_market_ws"},"received_at":"2026-07-28T02:58:45.366984Z","record_id":"4b1bbe651da245a528fd3b06a67908649183641fa421e53f366e7fdb8cf53f49","schema_fingerprint":"4aa3821a28b0b7c2400bc59aba4bcc0a76e971dadd19610d3ad38c768e124dc7","schema_version":"edge-lab-recorder.raw.v1","sequence":null,"source":"clob_market_ws"}
{"event_at":"2026-07-28T02:58:45.521000Z","event_fingerprint":"9456b0bb1d5d93a2acfae9538537a58460213532ce3a61cd34bca6e3055da17c","payload":{"connection_id":"955646bd8bf740759faf38750c0f263f","event_at":"2026-07-28T02:58:45.521000Z","event_type":"price_change","frame_hash":"cd9cb9ca56debe3a71cf4e36d6eb1e9de5a97d7c6d7e523128a2815ee961be79","frame_index":0,"kind":"data","monotonic_ns":309508395236291,"payload":{"event_type":"price_change","market":"0x0f70d07969bc69eaa97d0987de651885fdca02263688026aa11e7678af8f87aa","price_changes":[{"asset_id":"58313761654877669244690227616056238030136603415514645252000528337391143520538","best_ask":"0.34","best_bid":"0.33","hash":"3b29309dbf0367b923407143ea33f7b2f1a38d31","price":"0.29","side":"BUY","size":"118.1"},{"asset_id":"64053005904884194822931764831592250494815136296598204104072528088122126148949","best_ask":"0.67","best_bid":"0.66","hash":"568a9aa7d331cf72896b5b5f00b571c32e92dbfe","price":"0.71","side":"SELL","size":"118.1"}],"timestamp":"1785207525521"},"payload_hash":"b06bb3caff90d9046dee9c12d71392a51a2a6f580d191fdfd9775f522306c39a","raw_frame":"{\"market\":\"0x0f70d07969bc69eaa97d0987de651885fdca02263688026aa11e7678af8f87aa\", \"price_changes\":[{\"asset_id\":\"58313761654877669244690227616056238030136603415514645252000528337391143520538\", \"price\":\"0.29\", \"size\":\"118.1\", \"side\":\"BUY\", \"hash\":\"3b29309dbf0367b923407143ea33f7b2f1a38d31\", \"best_bid\":\"0.33\", \"best_ask\":\"0.34\"}, {\"asset_id\":\"64053005904884194822931764831592250494815136296598204104072528088122126148949\", \"price\":\"0.71\", \"size\":\"118.1\", \"side\":\"SELL\", \"hash\":\"568a9aa7d331cf72896b5b5f00b571c32e92dbfe\", \"best_bid\":\"0.66\", \"best_ask\":\"0.67\"}], \"timestamp\":\"1785207525521\", \"event_type\":\"price_change\"}","received_at":"2026-07-28T02:58:45.377411Z","schema_version":"clob-market-ws.price_change.v1","sequence":null,"server_hash":null,"server_timestamp":"1785207525521","session_id":"5aad79be415c487c84df42bebd84ee93","source":"clob_market_ws"},"received_at":"2026-07-28T02:58:45.377411Z","record_id":"827776b0f729bc03ef5db63f1ab853828676dddee3a77b1f813dd6900d9c74af","schema_fingerprint":"4aa3821a28b0b7c2400bc59aba4bcc0a76e971dadd19610d3ad38c768e124dc7","schema_version":"edge-lab-recorder.raw.v1","sequence":null,"source":"clob_market_ws"}
{"event_at":"2026-07-28T02:58:45.609000Z","event_fingerprint":"886288ff7d57902393011558a4f8a670a5dd75a0202a5ec885418b6805cd2af7","payload":{"connection_id":"955646bd8bf740759faf38750c0f263f","event_at":"2026-07-28T02:58:45.609000Z","event_type":"price_change","frame_hash":"c73ee420f4cdd869c7519767cb6184a1810cd9ceae26bb394b56ce94abee95dc","frame_index":0,"kind":"data","monotonic_ns":309508485293083,"payload":{"event_type":"price_change","market":"0x0f70d07969bc69eaa97d0987de651885fdca02263688026aa11e7678af8f87aa","price_changes":[{"asset_id":"64053005904884194822931764831592250494815136296598204104072528088122126148949","best_ask":"0.67","best_bid":"0.66","hash":"28453c111cf4c19e452c3a1ee96c5525f6c0c5ec","price":"0.04","side":"BUY","size":"380.5"},{"asset_id":"58313761654877669244690227616056238030136603415514645252000528337391143520538","best_ask":"0.34","best_bid":"0.33","hash":"363eea1e945640ed65319a4654497ff2d9b9e748","price":"0.96","side":"SELL","size":"380.5"}],"timestamp":"1785207525609"},"payload_hash":"cfce06cba1892f28b1c3cb2fbcbf5264ab3a5d9f43e8bd55c4fcfa08e372a8b0","raw_frame":"{\"market\":\"0x0f70d07969bc69eaa97d0987de651885fdca02263688026aa11e7678af8f87aa\", \"price_changes\":[{\"asset_id\":\"64053005904884194822931764831592250494815136296598204104072528088122126148949\", \"price\":\"0.04\", \"size\":\"380.5\", \"side\":\"BUY\", \"hash\":\"28453c111cf4c19e452c3a1ee96c5525f6c0c5ec\", \"best_bid\":\"0.66\", \"best_ask\":\"0.67\"}, {\"asset_id\":\"58313761654877669244690227616056238030136603415514645252000528337391143520538\", \"price\":\"0.96\", \"size\":\"380.5\", \"side\":\"SELL\", \"hash\":\"363eea1e945640ed65319a4654497ff2d9b9e748\", \"best_bid\":\"0.33\", \"best_ask\":\"0.34\"}], \"timestamp\":\"1785207525609\", \"event_type\":\"price_change\"}","received_at":"2026-07-28T02:58:45.467456Z","schema_version":"clob-market-ws.price_change.v1","sequence":null,"server_hash":null,"server_timestamp":"1785207525609","session_id":"5aad79be415c487c84df42bebd84ee93","source":"clob_market_ws"},"received_at":"2026-07-28T02:58:45.467456Z","record_id":"63fa3583e9be4225498c289a8e3d410f77660a0d2527f068aa5de8c935311e5d","schema_fingerprint":"4aa3821a28b0b7c2400bc59aba4bcc0a76e971dadd19610d3ad38c768e124dc7","schema_version":"edge-lab-recorder.raw.v1","sequence":null,"source":"clob_market_ws"}
{"event_at":"2026-07-28T02:58:45.618000Z","event_fingerprint":"8c1492e570329376d119592732f1a995546a9b56ee910255b91bf8df47bafc70","payload":{"connection_id":"955646bd8bf740759faf38750c0f263f","event_at":"2026-07-28T02:58:45.618000Z","event_type":"price_change","frame_hash":"763fb49c903eac186e683d4de548f0fdc1e36824fb7495e1f10bd77d3cbf9630","frame_index":0,"kind":"data","monotonic_ns":309508492730666,"payload":{"event_type":"price_change","market":"0x0f70d07969bc69eaa97d0987de651885fdca02263688026aa11e7678af8f87aa","price_changes":[{"asset_id":"64053005904884194822931764831592250494815136296598204104072528088122126148949","best_ask":"0.67","best_bid":"0.66","hash":"22a7ba0214af3dfaf245f37c748d5dd6c7143d82","price":"0.01","side":"BUY","size":"2695.52"},{"asset_id":"58313761654877669244690227616056238030136603415514645252000528337391143520538","best_ask":"0.34","best_bid":"0.33","hash":"599a41fa9d5ce6b4d99c358ef9de4c3d4170b535","price":"0.99","side":"SELL","size":"2695.52"}],"timestamp":"1785207525618"},"payload_hash":"0c9299e83d175ac66511b0f45dfecbf12465b67832379d43a4785584d9b12bc5","raw_frame":"{\"market\":\"0x0f70d07969bc69eaa97d0987de651885fdca02263688026aa11e7678af8f87aa\", \"price_changes\":[{\"asset_id\":\"64053005904884194822931764831592250494815136296598204104072528088122126148949\", \"price\":\"0.01\", \"size\":\"2695.52\", \"side\":\"BUY\", \"hash\":\"22a7ba0214af3dfaf245f37c748d5dd6c7143d82\", \"best_bid\":\"0.66\", \"best_ask\":\"0.67\"}, {\"asset_id\":\"58313761654877669244690227616056238030136603415514645252000528337391143520538\", \"price\":\"0.99\", \"size\":\"2695.52\", \"side\":\"SELL\", \"hash\":\"599a41fa9d5ce6b4d99c358ef9de4c3d4170b535\", \"best_bid\":\"0.33\", \"best_ask\":\"0.34\"}], \"timestamp\":\"1785207525618\", \"event_type\":\"price_change\"}","received_at":"2026-07-28T02:58:45.474902Z","schema_version":"clob-market-ws.price_change.v1","sequence":null,"server_hash":null,"server_timestamp":"1785207525618","session_id":"5aad79be415c487c84df42bebd84ee93","source":"clob_market_ws"},"received_at":"2026-07-28T02:58:45.474902Z","record_id":"2db418f2e179065f86898c327af6af5171f31b2a591c11366a518d3fec7d364e","schema_fingerprint":"4aa3821a28b0b7c2400bc59aba4bcc0a76e971dadd19610d3ad38c768e124dc7","schema_version":"edge-lab-recorder.raw.v1","sequence":null,"source":"clob_market_ws"}
{"event_at":"2026-07-28T02:58:45.632000Z","event_fingerprint":"5b54723408331cd962ff926e88aa3bfbf177548c98cc29110efd3d05b3f30c6b","payload":{"connection_id":"955646bd8bf740759faf38750c0f263f","event_at":"2026-07-28T02:58:45.632000Z","event_type":"price_change","frame_hash":"efcd46789a2433a09f50e97d3a29e55051cd5b027b136f3dbedf64e13f28eb48","frame_index":0,"kind":"data","monotonic_ns":309508506840416,"payload":{"event_type":"price_change","market":"0x0f70d07969bc69eaa97d0987de651885fdca02263688026aa11e7678af8f87aa","price_changes":[{"asset_id":"64053005904884194822931764831592250494815136296598204104072528088122126148949","best_ask":"0.67","best_bid":"0.66","hash":"15017cd3f9bbea15174fff7a8a09bc17d93e3974","price":"0.01","side":"BUY","size":"2690.52"},{"asset_id":"58313761654877669244690227616056238030136603415514645252000528337391143520538","best_ask":"0.34","best_bid":"0.33","hash":"eb0cc06caac08e06e0e3210f764c2e91107882c6","price":"0.99","side":"SELL","size":"2690.52"}],"timestamp":"1785207525632"},"payload_hash":"fd51e5f31f96335a9f53d6a298c24e39b2883180d7c6b53ecc57ae10e25af1a1","raw_frame":"{\"market\":\"0x0f70d07969bc69eaa97d0987de651885fdca02263688026aa11e7678af8f87aa\", \"price_changes\":[{\"asset_id\":\"64053005904884194822931764831592250494815136296598204104072528088122126148949\", \"price\":\"0.01\", \"size\":\"2690.52\", \"side\":\"BUY\", \"hash\":\"15017cd3f9bbea15174fff7a8a09bc17d93e3974\", \"best_bid\":\"0.66\", \"best_ask\":\"0.67\"}, {\"asset_id\":\"58313761654877669244690227616056238030136603415514645252000528337391143520538\", \"price\":\"0.99\", \"size\":\"2690.52\", \"side\":\"SELL\", \"hash\":\"eb0cc06caac08e06e0e3210f764c2e91107882c6\", \"best_bid\":\"0.33\", \"best_ask\":\"0.34\"}], \"timestamp\":\"1785207525632\", \"event_type\":\"price_change\"}","received_at":"2026-07-28T02:58:45.489010Z","schema_version":"clob-market-ws.price_change.v1","sequence":null,"server_hash":null,"server_timestamp":"1785207525632","session_id":"5aad79be415c487c84df42bebd84ee93","source":"clob_market_ws"},"received_at":"2026-07-28T02:58:45.489010Z","record_id":"ce2c274202bb9ca19d4aeb634baf789564e0349a5074c6c9e82e7592586f1785","schema_fingerprint":"4aa3821a28b0b7c2400bc59aba4bcc0a76e971dadd19610d3ad38c768e124dc7","schema_version":"edge-lab-recorder.raw.v1","sequence":null,"source":"clob_market_ws"}
{"event_at":"2026-07-28T02:58:45.636000Z","event_fingerprint":"288415b8bc5d180f01e483fbb880dac348eb717d375333db52091b8680de2d79","payload":{"connection_id":"955646bd8bf740759faf38750c0f263f","event_at":"2026-07-28T02:58:45.636000Z","event_type":"price_change","frame_hash":"fab54480feb1b4c2c1e4556bef87c6e075f7f6fc734da317754e489b823465bf","frame_index":0,"kind":"data","monotonic_ns":309508512126333,"payload":{"event_type":"price_change","market":"0x0f70d07969bc69eaa97d0987de651885fdca02263688026aa11e7678af8f87aa","price_changes":[{"asset_id":"58313761654877669244690227616056238030136603415514645252000528337391143520538","best_ask":"0.34","best_bid":"0.33","hash":"9d6dccbd0177272641e8e3726f74f5de5b9bfe28","price":"0.01","side":"BUY","size":"2571.24"},{"asset_id":"64053005904884194822931764831592250494815136296598204104072528088122126148949","best_ask":"0.67","best_bid":"0.66","hash":"47c1eaf83d23bb5b90c4f2a4509633fa9ee85a83","price":"0.99","side":"SELL","size":"2571.24"}],"timestamp":"1785207525636"},"payload_hash":"2b7a35b54342991beb34a9bd8dbfaaed9211b80355e7ec20978d3cb065626fde","raw_frame":"{\"market\":\"0x0f70d07969bc69eaa97d0987de651885fdca02263688026aa11e7678af8f87aa\", \"price_changes\":[{\"asset_id\":\"58313761654877669244690227616056238030136603415514645252000528337391143520538\", \"price\":\"0.01\", \"size\":\"2571.24\", \"side\":\"BUY\", \"hash\":\"9d6dccbd0177272641e8e3726f74f5de5b9bfe28\", \"best_bid\":\"0.33\", \"best_ask\":\"0.34\"}, {\"asset_id\":\"64053005904884194822931764831592250494815136296598204104072528088122126148949\", \"price\":\"0.99\", \"size\":\"2571.24\", \"side\":\"SELL\", \"hash\":\"47c1eaf83d23bb5b90c4f2a4509633fa9ee85a83\", \"best_bid\":\"0.66\", \"best_ask\":\"0.67\"}], \"timestamp\":\"1785207525636\", \"event_type\":\"price_change\"}","received_at":"2026-07-28T02:58:45.494299Z","schema_version":"clob-market-ws.price_change.v1","sequence":null,"server_hash":null,"server_timestamp":"1785207525636","session_id":"5aad79be415c487c84df42bebd84ee93","source":"clob_market_ws"},"received_at":"2026-07-28T02:58:45.494299Z","record_id":"fdcf9405ee6d62661b02aae360eab3484e7f50b226758c9c5484636ea001bd26","schema_fingerprint":"4aa3821a28b0b7c2400bc59aba4bcc0a76e971dadd19610d3ad38c768e124dc7","schema_version":"edge-lab-recorder.raw.v1","sequence":null,"source":"clob_market_ws"}
{"event_at":"2026-07-28T02:58:45.640000Z","event_fingerprint":"cb2cf4dd09064bb40cb852c947a32b9bcef69238ada2701cb38c1802a2951b79","payload":{"connection_id":"955646bd8bf740759faf38750c0f263f","event_at":"2026-07-28T02:58:45.640000Z","event_type":"price_change","frame_hash":"542a92b2c96f34a42990f236454c3dae9e9c6036ef0493475977ab208d7685aa","frame_index":0,"kind":"data","monotonic_ns":309508516248500,"payload":{"event_type":"price_change","market":"0x0f70d07969bc69eaa97d0987de651885fdca02263688026aa11e7678af8f87aa","price_changes":[{"asset_id":"64053005904884194822931764831592250494815136296598204104072528088122126148949","best_ask":"0.67","best_bid":"0.66","hash":"c39d8a439cfbda876f34b2462cb4c88e61eee99d","price":"0.01","side":"BUY","size":"2685.52"},{"asset_id":"58313761654877669244690227616056238030136603415514645252000528337391143520538","best_ask":"0.34","best_bid":"0.33","hash":"000d7f2660257c739e9b23ce98e71218519c3c10","price":"0.99","side":"SELL","size":"2685.52"}],"timestamp":"1785207525640"},"payload_hash":"473cfd23b8736987542c4e876f39ea74db8df7115cf719a3c5fbf9ac7a5913fc","raw_frame":"{\"market\":\"0x0f70d07969bc69eaa97d0987de651885fdca02263688026aa11e7678af8f87aa\", \"price_changes\":[{\"asset_id\":\"64053005904884194822931764831592250494815136296598204104072528088122126148949\", \"price\":\"0.01\", \"size\":\"2685.52\", \"side\":\"BUY\", \"hash\":\"c39d8a439cfbda876f34b2462cb4c88e61eee99d\", \"best_bid\":\"0.66\", \"best_ask\":\"0.67\"}, {\"asset_id\":\"58313761654877669244690227616056238030136603415514645252000528337391143520538\", \"price\":\"0.99\", \"size\":\"2685.52\", \"side\":\"SELL\", \"hash\":\"000d7f2660257c739e9b23ce98e71218519c3c10\", \"best_bid\":\"0.33\", \"best_ask\":\"0.34\"}], \"timestamp\":\"1785207525640\", \"event_type\":\"price_change\"}","received_at":"2026-07-28T02:58:45.498419Z","schema_version":"clob-market-ws.price_change.v1","sequence":null,"server_hash":null,"server_timestamp":"1785207525640","session_id":"5aad79be415c487c84df42bebd84ee93","source":"clob_market_ws"},"received_at":"2026-07-28T02:58:45.498419Z","record_id":"1c2b98e8998feef179c32d7d0d0935e7c06db03b56bfbde11ef0defcb905d993","schema_fingerprint":"4aa3821a28b0b7c2400bc59aba4bcc0a76e971dadd19610d3ad38c768e124dc7","schema_version":"edge-lab-recorder.raw.v1","sequence":null,"source":"clob_market_ws"}
{"event_at":"2026-07-28T02:58:45.687000Z","event_fingerprint":"0a013f43081cc9e669217f905ca077e890d2e37a6f8004de8427dfcbc0dadbdd","payload":{"connection_id":"955646bd8bf740759faf38750c0f263f","event_at":"2026-07-28T02:58:45.687000Z","event_type":"price_change","frame_hash":"583afe2270a6819533fb7caffe860afd524c9783ab80827c22b1c946bd6e490b","frame_index":0,"kind":"data","monotonic_ns":309508561405208,"payload":{"event_type":"price_change","market":"0x0f70d07969bc69eaa97d0987de651885fdca02263688026aa11e7678af8f87aa","price_changes":[{"asset_id":"64053005904884194822931764831592250494815136296598204104072528088122126148949","best_ask":"0.67","best_bid":"0.66","hash":"ae9c85790b65c5570903dcfa7eb10fdc45c014cd","price":"0.66","side":"BUY","size":"309.68"},{"asset_id":"58313761654877669244690227616056238030136603415514645252000528337391143520538","best_ask":"0.34","best_bid":"0.33","hash":"d3e44f6d3f36edb1346aae5bfad05d4ab511d8b1","price":"0.34","side":"SELL","size":"309.68"}],"timestamp":"1785207525687"},"payload_hash":"a58f411b3f18bbc94d2679f4cb364fa16a422575bac42d9f1402633abe29d51b","raw_frame":"{\"market\":\"0x0f70d07969bc69eaa97d0987de651885fdca02263688026aa11e7678af8f87aa\", \"price_changes\":[{\"asset_id\":\"64053005904884194822931764831592250494815136296598204104072528088122126148949\", \"price\":\"0.66\", \"size\":\"309.68\", \"side\":\"BUY\", \"hash\":\"ae9c85790b65c5570903dcfa7eb10fdc45c014cd\", \"best_bid\":\"0.66\", \"best_ask\":\"0.67\"}, {\"asset_id\":\"58313761654877669244690227616056238030136603415514645252000528337391143520538\", \"price\":\"0.34\", \"size\":\"309.68\", \"side\":\"SELL\", \"hash\":\"d3e44f6d3f36edb1346aae5bfad05d4ab511d8b1\", \"best_bid\":\"0.33\", \"best_ask\":\"0.34\"}], \"timestamp\":\"1785207525687\", \"event_type\":\"price_change\"}","received_at":"2026-07-28T02:58:45.543572Z","schema_version":"clob-market-ws.price_change.v1","sequence":null,"server_hash":null,"server_timestamp":"1785207525687","session_id":"5aad79be415c487c84df42bebd84ee93","source":"clob_market_ws"},"received_at":"2026-07-28T02:58:45.543572Z","record_id":"a6892a0fc421afa180f0b2c6e1593d7ccd01b5e9e91b50e55b2e440b221bff45","schema_fingerprint":"4aa3821a28b0b7c2400bc59aba4bcc0a76e971dadd19610d3ad38c768e124dc7","schema_version":"edge-lab-recorder.raw.v1","sequence":null,"source":"clob_market_ws"}
{"event_at":"2026-07-28T02:58:45.703000Z","event_fingerprint":"d5c79b2c447446e0e50986e3115ffb067a02c93f1fb659b2d07f36f81f40674b","payload":{"connection_id":"955646bd8bf740759faf38750c0f263f","event_at":"2026-07-28T02:58:45.703000Z","event_type":"price_change","frame_hash":"5fa1d1f29601202c357b4c0da72fd04193c52dce13711e4d4475d64dde6a225c","frame_index":0,"kind":"data","monotonic_ns":309508577836250,"payload":{"event_type":"price_change","market":"0x0f70d07969bc69eaa97d0987de651885fdca02263688026aa11e7678af8f87aa","price_changes":[{"asset_id":"64053005904884194822931764831592250494815136296598204104072528088122126148949","best_ask":"0.67","best_bid":"0.66","hash":"9e583a53f58dd724b0a2935d9db90cd63184a86f","price":"0.56","side":"BUY","size":"254.6"},{"asset_id":"58313761654877669244690227616056238030136603415514645252000528337391143520538","best_ask":"0.34","best_bid":"0.33","hash":"8d32fe64231dad0355779a03448c15129f9ae9ce","price":"0.44","side":"SELL","size":"254.6"}],"timestamp":"1785207525703"},"payload_hash":"5ecbc9363f005b15998247990026840a727010e57e1143e9ba5c393ced364c25","raw_frame":"{\"market\":\"0x0f70d07969bc69eaa97d0987de651885fdca02263688026aa11e7678af8f87aa\", \"price_changes\":[{\"asset_id\":\"64053005904884194822931764831592250494815136296598204104072528088122126148949\", \"price\":\"0.56\", \"size\":\"254.6\", \"side\":\"BUY\", \"hash\":\"9e583a53f58dd724b0a2935d9db90cd63184a86f\", \"best_bid\":\"0.66\", \"best_ask\":\"0.67\"}, {\"asset_id\":\"58313761654877669244690227616056238030136603415514645252000528337391143520538\", \"price\":\"0.44\", \"size\":\"254.6\", \"side\":\"SELL\", \"hash\":\"8d32fe64231dad0355779a03448c15129f9ae9ce\", \"best_bid\":\"0.33\", \"best_ask\":\"0.34\"}], \"timestamp\":\"1785207525703\", \"event_type\":\"price_change\"}","received_at":"2026-07-28T02:58:45.560008Z","schema_version":"clob-market-ws.price_change.v1","sequence":null,"server_hash":null,"server_timestamp":"1785207525703","session_id":"5aad79be415c487c84df42bebd84ee93","source":"clob_market_ws"},"received_at":"2026-07-28T02:58:45.560008Z","record_id":"a2351bfa15949a7e20752518eea7571715992b76418224a92ec55e8753d5d464","schema_fingerprint":"4aa3821a28b0b7c2400bc59aba4bcc0a76e971dadd19610d3ad38c768e124dc7","schema_version":"edge-lab-recorder.raw.v1","sequence":null,"source":"clob_market_ws"}
{"event_at":"2026-07-28T02:58:45.707000Z","event_fingerprint":"f3bd0f2aa2621af49e0d52da7661d8298de10e49d2105a1a1635da96bcf5d832","payload":{"connection_id":"955646bd8bf740759faf38750c0f263f","event_at":"2026-07-28T02:58:45.707000Z","event_type":"price_change","frame_hash":"ccb994612188693be857c641742128e9199f682d5f47f024bb21b195704b285b","frame_index":0,"kind":"data","monotonic_ns":309508581361666,"payload":{"event_type":"price_change","market":"0x0f70d07969bc69eaa97d0987de651885fdca02263688026aa11e7678af8f87aa","price_changes":[{"asset_id":"64053005904884194822931764831592250494815136296598204104072528088122126148949","best_ask":"0.67","best_bid":"0.66","hash":"f098273ec69d3e21a52722aab8d8034e746097a5","price":"0.56","side":"BUY","size":"204.6"},{"asset_id":"58313761654877669244690227616056238030136603415514645252000528337391143520538","best_ask":"0.34","best_bid":"0.33","hash":"87af12ca0ffe3c137b6324c165edbbcfdf8bb377","price":"0.44","side":"SELL","size":"204.6"}],"timestamp":"1785207525707"},"payload_hash":"da0d85dd5552fc7e9f219e9e781f579a5936195553a9a312ce21139fd47f31e4","raw_frame":"{\"market\":\"0x0f70d07969bc69eaa97d0987de651885fdca02263688026aa11e7678af8f87aa\", \"price_changes\":[{\"asset_id\":\"64053005904884194822931764831592250494815136296598204104072528088122126148949\", \"price\":\"0.56\", \"size\":\"204.6\", \"side\":\"BUY\", \"hash\":\"f098273ec69d3e21a52722aab8d8034e746097a5\", \"best_bid\":\"0.66\", \"best_ask\":\"0.67\"}, {\"asset_id\":\"58313761654877669244690227616056238030136603415514645252000528337391143520538\", \"price\":\"0.44\", \"size\":\"204.6\", \"side\":\"SELL\", \"hash\":\"87af12ca0ffe3c137b6324c165edbbcfdf8bb377\", \"best_bid\":\"0.33\", \"best_ask\":\"0.34\"}], \"timestamp\":\"1785207525707\", \"event_type\":\"price_change\"}","received_at":"2026-07-28T02:58:45.563535Z","schema_version":"clob-market-ws.price_change.v1","sequence":null,"server_hash":null,"server_timestamp":"1785207525707","session_id":"5aad79be415c487c84df42bebd84ee93","source":"clob_market_ws"},"received_at":"2026-07-28T02:58:45.563535Z","record_id":"2afafb10e2f1c729ac7eaa9f36136407b3e4ee6e5faec7d438dbe3f7e776c967","schema_fingerprint":"4aa3821a28b0b7c2400bc59aba4bcc0a76e971dadd19610d3ad38c768e124dc7","schema_version":"edge-lab-recorder.raw.v1","sequence":null,"source":"clob_market_ws"}
{"event_at":"2026-07-28T02:58:45.710000Z","event_fingerprint":"a5523ab1bfc3d42d740af2063c7a0ddbfbfac4ada8504259af13ae91cb3e1501","payload":{"connection_id":"955646bd8bf740759faf38750c0f263f","event_at":"2026-07-28T02:58:45.710000Z","event_type":"price_change","frame_hash":"43a1cf25a54f0cb25b10f7732b56f2f542fc3c3c95c3186c2a2bc056695cf755","frame_index":0,"kind":"data","monotonic_ns":309508584901125,"payload":{"event_type":"price_change","market":"0x0f70d07969bc69eaa97d0987de651885fdca02263688026aa11e7678af8f87aa","price_changes":[{"asset_id":"64053005904884194822931764831592250494815136296598204104072528088122126148949","best_ask":"0.67","best_bid":"0.66","hash":"512b080fe095a379e75bdeace0fa0aacbf76aeeb","price":"0.03","side":"BUY","size":"550.8"},{"asset_id":"58313761654877669244690227616056238030136603415514645252000528337391143520538","best_ask":"0.34","best_bid":"0.33","hash":"ae8e31ce37099754669868eee77316b96fd5351c","price":"0.97","side":"SELL","size":"550.8"}],"timestamp":"1785207525710"},"payload_hash":"2930a2645e802a8ecaa6b1306986ed645d4ddd215f49561ab8f86e684373d92e","raw_frame":"{\"market\":\"0x0f70d07969bc69eaa97d0987de651885fdca02263688026aa11e7678af8f87aa\", \"price_changes\":[{\"asset_id\":\"64053005904884194822931764831592250494815136296598204104072528088122126148949\", \"price\":\"0.03\", \"size\":\"550.8\", \"side\":\"BUY\", \"hash\":\"512b080fe095a379e75bdeace0fa0aacbf76aeeb\", \"best_bid\":\"0.66\", \"best_ask\":\"0.67\"}, {\"asset_id\":\"58313761654877669244690227616056238030136603415514645252000528337391143520538\", \"price\":\"0.97\", \"size\":\"550.8\", \"side\":\"SELL\", \"hash\":\"ae8e31ce37099754669868eee77316b96fd5351c\", \"best_bid\":\"0.33\", \"best_ask\":\"0.34\"}], \"timestamp\":\"1785207525710\", \"event_type\":\"price_change\"}","received_at":"2026-07-28T02:58:45.567074Z","schema_version":"clob-market-ws.price_change.v1","sequence":null,"server_hash":null,"server_timestamp":"1785207525710","session_id":"5aad79be415c487c84df42bebd84ee93","source":"clob_market_ws"},"received_at":"2026-07-28T02:58:45.567074Z","record_id":"c3b006591f16cb09645417e8e49789b00ac1a12ff6e91afb9b485fa4c2dcb7f0","schema_fingerprint":"4aa3821a28b0b7c2400bc59aba4bcc0a76e971dadd19610d3ad38c768e124dc7","schema_version":"edge-lab-recorder.raw.v1","sequence":null,"source":"clob_market_ws"}
{"event_at":"2026-07-28T02:58:45.728000Z","event_fingerprint":"49710413374c7d4a6138db6d84f39af5635af4845c1580b15819bbf6771fe1d6","payload":{"connection_id":"955646bd8bf740759faf38750c0f263f","event_at":"2026-07-28T02:58:45.728000Z","event_type":"price_change","frame_hash":"88f37a88013a79e0d4dda2f2b3463015e07e2871b544107801827a91204144bf","frame_index":0,"kind":"data","monotonic_ns":309508606170958,"payload":{"event_type":"price_change","market":"0x0f70d07969bc69eaa97d0987de651885fdca02263688026aa11e7678af8f87aa","price_changes":[{"asset_id":"64053005904884194822931764831592250494815136296598204104072528088122126148949","best_ask":"0.67","best_bid":"0.66","hash":"2f0bce06491595c6360a03a00d5b08ce9c457eb6","price":"0.57","side":"BUY","size":"144.9"},{"asset_id":"58313761654877669244690227616056238030136603415514645252000528337391143520538","best_ask":"0.34","best_bid":"0.33","hash":"853ed2f80c454f0a2e026f4d71375328c60df750","price":"0.43","side":"SELL","size":"144.9"}],"timestamp":"1785207525728"},"payload_hash":"81529747b8884a139338b6ded5d1adb7e91b774e4bbca420ee50d040a7205506","raw_frame":"{\"market\":\"0x0f70d07969bc69eaa97d0987de651885fdca02263688026aa11e7678af8f87aa\", \"price_changes\":[{\"asset_id\":\"64053005904884194822931764831592250494815136296598204104072528088122126148949\", \"price\":\"0.57\", \"size\":\"144.9\", \"side\":\"BUY\", \"hash\":\"2f0bce06491595c6360a03a00d5b08ce9c457eb6\", \"best_bid\":\"0.66\", \"best_ask\":\"0.67\"}, {\"asset_id\":\"58313761654877669244690227616056238030136603415514645252000528337391143520538\", \"price\":\"0.43\", \"size\":\"144.9\", \"side\":\"SELL\", \"hash\":\"853ed2f80c454f0a2e026f4d71375328c60df750\", \"best_bid\":\"0.33\", \"best_ask\":\"0.34\"}], \"timestamp\":\"1785207525728\", \"event_type\":\"price_change\"}","received_at":"2026-07-28T02:58:45.588343Z","schema_version":"clob-market-ws.price_change.v1","sequence":null,"server_hash":null,"server_timestamp":"1785207525728","session_id":"5aad79be415c487c84df42bebd84ee93","source":"clob_market_ws"},"received_at":"2026-07-28T02:58:45.588343Z","record_id":"089d20f3db02a77ea189094d50b0b4d8288f8b16008860851fa4e35c3139f3c8","schema_fingerprint":"4aa3821a28b0b7c2400bc59aba4bcc0a76e971dadd19610d3ad38c768e124dc7","schema_version":"edge-lab-recorder.raw.v1","sequence":null,"source":"clob_market_ws"}
{"event_at":"2026-07-28T02:58:45.733000Z","event_fingerprint":"7005181db6eda080b0ab46e529e89ed5e87f1e350c2a421720593876147377cb","payload":{"connection_id":"955646bd8bf740759faf38750c0f263f","event_at":"2026-07-28T02:58:45.733000Z","event_type":"price_change","frame_hash":"f049933c64d6d9aef70b4d7cc802c92eda96160b8cf29465cc1aee3bdd146ebc","frame_index":0,"kind":"data","monotonic_ns":309508608639458,"payload":{"event_type":"price_change","market":"0x0f70d07969bc69eaa97d0987de651885fdca02263688026aa11e7678af8f87aa","price_changes":[{"asset_id":"64053005904884194822931764831592250494815136296598204104072528088122126148949","best_ask":"0.67","best_bid":"0.66","hash":"e0c7de074a77517fa3fcfa66ef9f12e811f251b4","price":"0.57","side":"BUY","size":"194.9"},{"asset_id":"58313761654877669244690227616056238030136603415514645252000528337391143520538","best_ask":"0.34","best_bid":"0.33","hash":"f8f61706a29400eba1e6a0fd5a4ad279f77f391f","price":"0.43","side":"SELL","size":"194.9"}],"timestamp":"1785207525733"},"payload_hash":"09cb4f2d2ce6bc5077f069f790e4df1724046c12a6c81353c25dd507c093dd07","raw_frame":"{\"market\":\"0x0f70d07969bc69eaa97d0987de651885fdca02263688026aa11e7678af8f87aa\", \"price_changes\":[{\"asset_id\":\"64053005904884194822931764831592250494815136296598204104072528088122126148949\", \"price\":\"0.57\", \"size\":\"194.9\", \"side\":\"BUY\", \"hash\":\"e0c7de074a77517fa3fcfa66ef9f12e811f251b4\", \"best_bid\":\"0.66\", \"best_ask\":\"0.67\"}, {\"asset_id\":\"58313761654877669244690227616056238030136603415514645252000528337391143520538\", \"price\":\"0.43\", \"size\":\"194.9\", \"side\":\"SELL\", \"hash\":\"f8f61706a29400eba1e6a0fd5a4ad279f77f391f\", \"best_bid\":\"0.33\", \"best_ask\":\"0.34\"}], \"timestamp\":\"1785207525733\", \"event_type\":\"price_change\"}","received_at":"2026-07-28T02:58:45.590810Z","schema_version":"clob-market-ws.price_change.v1","sequence":null,"server_hash":null,"server_timestamp":"1785207525733","session_id":"5aad79be415c487c84df42bebd84ee93","source":"clob_market_ws"},"received_at":"2026-07-28T02:58:45.590810Z","record_id":"4dc3228b208106dceb8be6c16067cadbdf19bc16b7f1b0f092f50024d0195efe","schema_fingerprint":"4aa3821a28b0b7c2400bc59aba4bcc0a76e971dadd19610d3ad38c768e124dc7","schema_version":"edge-lab-recorder.raw.v1","sequence":null,"source":"clob_market_ws"}
{"event_at":"2026-07-28T02:58:45.811000Z","event_fingerprint":"e3cc540fc88be4dc25a7e5370734c99693aa83777609a2a037fd29d30890a553","payload":{"connection_id":"955646bd8bf740759faf38750c0f263f","event_at":"2026-07-28T02:58:45.811000Z","event_type":"price_change","frame_hash":"f5c904ba8b7454d69e5e1f438a5908be3fd5bdbfbf43cc74227bee3aaa665c6a","frame_index":0,"kind":"data","monotonic_ns":309508688826375,"payload":{"event_type":"price_change","market":"0x0f70d07969bc69eaa97d0987de651885fdca02263688026aa11e7678af8f87aa","price_changes":[{"asset_id":"64053005904884194822931764831592250494815136296598204104072528088122126148949","best_ask":"0.67","best_bid":"0.66","hash":"4dfff979bdad5a3384b5582a710c3ff1202585ab","price":"0.03","side":"BUY","size":"545.8"},{"asset_id":"58313761654877669244690227616056238030136603415514645252000528337391143520538","best_ask":"0.34","best_bid":"0.33","hash":"c7d707854f2be88d2ff6c4cbfdd0b192d0c72bf1","price":"0.97","side":"SELL","size":"545.8"}],"timestamp":"1785207525811"},"payload_hash":"c8aed5862c60d56e79d82d552a1b236fa11f47a14f33ac83068975e08ca086a7","raw_frame":"{\"market\":\"0x0f70d07969bc69eaa97d0987de651885fdca02263688026aa11e7678af8f87aa\", \"price_changes\":[{\"asset_id\":\"64053005904884194822931764831592250494815136296598204104072528088122126148949\", \"price\":\"0.03\", \"size\":\"545.8\", \"side\":\"BUY\", \"hash\":\"4dfff979bdad5a3384b5582a710c3ff1202585ab\", \"best_bid\":\"0.66\", \"best_ask\":\"0.67\"}, {\"asset_id\":\"58313761654877669244690227616056238030136603415514645252000528337391143520538\", \"price\":\"0.97\", \"size\":\"545.8\", \"side\":\"SELL\", \"hash\":\"c7d707854f2be88d2ff6c4cbfdd0b192d0c72bf1\", \"best_bid\":\"0.33\", \"best_ask\":\"0.34\"}], \"timestamp\":\"1785207525811\", \"event_type\":\"price_change\"}","received_at":"2026-07-28T02:58:45.670994Z","schema_version":"clob-market-ws.price_change.v1","sequence":null,"server_hash":null,"server_timestamp":"1785207525811","session_id":"5aad79be415c487c84df42bebd84ee93","source":"clob_market_ws"},"received_at":"2026-07-28T02:58:45.670994Z","record_id":"727a285dcc5e79336202051032fd483c74c94aa34c8fcaa587efb6de6da42890","schema_fingerprint":"4aa3821a28b0b7c2400bc59aba4bcc0a76e971dadd19610d3ad38c768e124dc7","schema_version":"edge-lab-recorder.raw.v1","sequence":null,"source":"clob_market_ws"}
{"event_at":"2026-07-28T02:58:45.839000Z","event_fingerprint":"4835ee2e00b567f87c8639347dae57ad91410d20d9137c5539b21318dc7a3eb8","payload":{"connection_id":"955646bd8bf740759faf38750c0f263f","event_at":"2026-07-28T02:58:45.839000Z","event_type":"price_change","frame_hash":"c547bc0953d0398eb5ddd418b9da8e9ca4521b40cc0642eedd4833312e6e9084","frame_index":0,"kind":"data","monotonic_ns":309508713588791,"payload":{"event_type":"price_change","market":"0x0f70d07969bc69eaa97d0987de651885fdca02263688026aa11e7678af8f87aa","price_changes":[{"asset_id":"58313761654877669244690227616056238030136603415514645252000528337391143520538","best_ask":"0.34","best_bid":"0.33","hash":"57bf0b984e3b341556c846035edbe904c60b6e28","price":"0.24","side":"BUY","size":"231.5"},{"asset_id":"64053005904884194822931764831592250494815136296598204104072528088122126148949","best_ask":"0.67","best_bid":"0.66","hash":"8c4397251c0035b2e0bcdad73a31aaffb91336c3","price":"0.76","side":"SELL","size":"231.5"}],"timestamp":"1785207525839"},"payload_hash":"8a10fee05c11b7e22a26957279112cd8bb94a595ccd50da7b3bcec9f49bf4247","raw_frame":"{\"market\":\"0x0f70d07969bc69eaa97d0987de651885fdca02263688026aa11e7678af8f87aa\", \"price_changes\":[{\"asset_id\":\"58313761654877669244690227616056238030136603415514645252000528337391143520538\", \"price\":\"0.24\", \"size\":\"231.5\", \"side\":\"BUY\", \"hash\":\"57bf0b984e3b341556c846035edbe904c60b6e28\", \"best_bid\":\"0.33\", \"best_ask\":\"0.34\"}, {\"asset_id\":\"64053005904884194822931764831592250494815136296598204104072528088122126148949\", \"price\":\"0.76\", \"size\":\"231.5\", \"side\":\"SELL\", \"hash\":\"8c4397251c0035b2e0bcdad73a31aaffb91336c3\", \"best_bid\":\"0.66\", \"best_ask\":\"0.67\"}], \"timestamp\":\"1785207525839\", \"event_type\":\"price_change\"}","received_at":"2026-07-28T02:58:45.695759Z","schema_version":"clob-market-ws.price_change.v1","sequence":null,"server_hash":null,"server_timestamp":"1785207525839","session_id":"5aad79be415c487c84df42bebd84ee93","source":"clob_market_ws"},"received_at":"2026-07-28T02:58:45.695759Z","record_id":"94c488badc1c2d61cc757c317704e1780c7fdfdd5e7e3d10307629989b4ae246","schema_fingerprint":"4aa3821a28b0b7c2400bc59aba4bcc0a76e971dadd19610d3ad38c768e124dc7","schema_version":"edge-lab-recorder.raw.v1","sequence":null,"source":"clob_market_ws"}
{"event_at":"2026-07-28T02:58:45.842000Z","event_fingerprint":"aca94f20da42916146549e7a738b48a9ce36372b73597cc134cdccb67895e5c2","payload":{"connection_id":"955646bd8bf740759faf38750c0f263f","event_at":"2026-07-28T02:58:45.842000Z","event_type":"price_change","frame_hash":"338c241550eac25226486e6e1c44360a2f7a01a998d1ea432a8fd43015d9f646","frame_index":0,"kind":"data","monotonic_ns":309508716882875,"payload":{"event_type":"price_change","market":"0x0f70d07969bc69eaa97d0987de651885fdca02263688026aa11e7678af8f87aa","price_changes":[{"asset_id":"64053005904884194822931764831592250494815136296598204104072528088122126148949","best_ask":"0.67","best_bid":"0.66","hash":"f7c36eecfa3ebf3096a2864bd7f91c6cc1255b88","price":"0.01","side":"BUY","size":"2690.52"},{"asset_id":"58313761654877669244690227616056238030136603415514645252000528337391143520538","best_ask":"0.34","best_bid":"0.33","hash":"8de07f3e8f432915477f953eacd99d0253b7db16","price":"0.99","side":"SELL","size":"2690.52"}],"timestamp":"1785207525842"},"payload_hash":"cc2052111dc0b1d1a44420380f1b642f021d038a06c6de344c157a3b83ebf25c","raw_frame":"{\"market\":\"0x0f70d07969bc69eaa97d0987de651885fdca02263688026aa11e7678af8f87aa\", \"price_changes\":[{\"asset_id\":\"64053005904884194822931764831592250494815136296598204104072528088122126148949\", \"price\":\"0.01\", \"size\":\"2690.52\", \"side\":\"BUY\", \"hash\":\"f7c36eecfa3ebf3096a2864bd7f91c6cc1255b88\", \"best_bid\":\"0.66\", \"best_ask\":\"0.67\"}, {\"asset_id\":\"58313761654877669244690227616056238030136603415514645252000528337391143520538\", \"price\":\"0.99\", \"size\":\"2690.52\", \"side\":\"SELL\", \"hash\":\"8de07f3e8f432915477f953eacd99d0253b7db16\", \"best_bid\":\"0.33\", \"best_ask\":\"0.34\"}], \"timestamp\":\"1785207525842\", \"event_type\":\"price_change\"}","received_at":"2026-07-28T02:58:45.699055Z","schema_version":"clob-market-ws.price_change.v1","sequence":null,"server_hash":null,"server_timestamp":"1785207525842","session_id":"5aad79be415c487c84df42bebd84ee93","source":"clob_market_ws"},"received_at":"2026-07-28T02:58:45.699055Z","record_id":"f429d9091e1c5bfe2d15560439fe751b11c8645c57758a9960aff3fb4c0baa7d","schema_fingerprint":"4aa3821a28b0b7c2400bc59aba4bcc0a76e971dadd19610d3ad38c768e124dc7","schema_version":"edge-lab-recorder.raw.v1","sequence":null,"source":"clob_market_ws"}
{"event_at":"2026-07-28T02:58:45.860000Z","event_fingerprint":"c710fe9f948d771dbc8b98602b415a12b95017f8deaf149211dfcd87417183a6","payload":{"connection_id":"955646bd8bf740759faf38750c0f263f","event_at":"2026-07-28T02:58:45.860000Z","event_type":"price_change","frame_hash":"10cd470a31cfba23bed4c6d3e76f3a12bad3558ffa9dea25fe8e601e5a918d76","frame_index":0,"kind":"data","monotonic_ns":309508734624833,"payload":{"event_type":"price_change","market":"0x0f70d07969bc69eaa97d0987de651885fdca02263688026aa11e7678af8f87aa","price_changes":[{"asset_id":"64053005904884194822931764831592250494815136296598204104072528088122126148949","best_ask":"0.67","best_bid":"0.66","hash":"9f89c627c4884b5f482cad6c853ae4837795d810","price":"0.66","side":"BUY","size":"314.68"},{"asset_id":"58313761654877669244690227616056238030136603415514645252000528337391143520538","best_ask":"0.34","best_bid":"0.33","hash":"642e69fcdfe959922711e31bf0c659539439be71","price":"0.34","side":"SELL","size":"314.68"}],"timestamp":"1785207525860"},"payload_hash":"9e6f4732f963319a1d00a654199ef73e5f2e0491fdb0579afd9a17b5a853f881","raw_frame":"{\"market\":\"0x0f70d07969bc69eaa97d0987de651885fdca02263688026aa11e7678af8f87aa\", \"price_changes\":[{\"asset_id\":\"64053005904884194822931764831592250494815136296598204104072528088122126148949\", \"price\":\"0.66\", \"size\":\"314.68\", \"side\":\"BUY\", \"hash\":\"9f89c627c4884b5f482cad6c853ae4837795d810\", \"best_bid\":\"0.66\", \"best_ask\":\"0.67\"}, {\"asset_id\":\"58313761654877669244690227616056238030136603415514645252000528337391143520538\", \"price\":\"0.34\", \"size\":\"314.68\", \"side\":\"SELL\", \"hash\":\"642e69fcdfe959922711e31bf0c659539439be71\", \"best_bid\":\"0.33\", \"best_ask\":\"0.34\"}], \"timestamp\":\"1785207525860\", \"event_type\":\"price_change\"}","received_at":"2026-07-28T02:58:45.716796Z","schema_version":"clob-market-ws.price_change.v1","sequence":null,"server_hash":null,"server_timestamp":"1785207525860","session_id":"5aad79be415c487c84df42bebd84ee93","source":"clob_market_ws"},"received_at":"2026-07-28T02:58:45.716796Z","record_id":"d7d4846d87965892e0c5a784a22d62fa027af085eb5a8ef795fbc260046dc283","schema_fingerprint":"4aa3821a28b0b7c2400bc59aba4bcc0a76e971dadd19610d3ad38c768e124dc7","schema_version":"edge-lab-recorder.raw.v1","sequence":null,"source":"clob_market_ws"}
{"event_at":"2026-07-28T02:58:45.861000Z","event_fingerprint":"893b1eaadd0e10aa0b52088a6ae0b44a2fdd8e35d320ea6943b70217c8c5fd0f","payload":{"connection_id":"955646bd8bf740759faf38750c0f263f","event_at":"2026-07-28T02:58:45.861000Z","event_type":"price_change","frame_hash":"3ac4261134d21020bc2226d00ad579c3dfa5ac9636f058a86fc28ff2cfd1238d","frame_index":0,"kind":"data","monotonic_ns":309508738393041,"payload":{"event_type":"price_change","market":"0x0f70d07969bc69eaa97d0987de651885fdca02263688026aa11e7678af8f87aa","price_changes":[{"asset_id":"64053005904884194822931764831592250494815136296598204104072528088122126148949","best_ask":"0.67","best_bid":"0.66","hash":"13fa2abbfcf33f68abdae7aecd5ff2709c951e2d","price":"0.01","side":"BUY","size":"2685.52"},{"asset_id":"58313761654877669244690227616056238030136603415514645252000528337391143520538","best_ask":"0.34","best_bid":"0.33","hash":"8e40968b70137149ad99a986a1ee5bc1ae3c204e","price":"0.99","side":"SELL","size":"2685.52"}],"timestamp":"1785207525861"},"payload_hash":"b9181c85a2b7c807cbf5697b65935485fb35c990cc232b501901daeb26e62c7e","raw_frame":"{\"market\":\"0x0f70d07969bc69eaa97d0987de651885fdca02263688026aa11e7678af8f87aa\", \"price_changes\":[{\"asset_id\":\"64053005904884194822931764831592250494815136296598204104072528088122126148949\", \"price\":\"0.01\", \"size\":\"2685.52\", \"side\":\"BUY\", \"hash\":\"13fa2abbfcf33f68abdae7aecd5ff2709c951e2d\", \"best_bid\":\"0.66\", \"best_ask\":\"0.67\"}, {\"asset_id\":\"58313761654877669244690227616056238030136603415514645252000528337391143520538\", \"price\":\"0.99\", \"size\":\"2685.52\", \"side\":\"SELL\", \"hash\":\"8e40968b70137149ad99a986a1ee5bc1ae3c204e\", \"best_bid\":\"0.33\", \"best_ask\":\"0.34\"}], \"timestamp\":\"1785207525861\", \"event_type\":\"price_change\"}","received_at":"2026-07-28T02:58:45.720564Z","schema_version":"clob-market-ws.price_change.v1","sequence":null,"server_hash":null,"server_timestamp":"1785207525861","session_id":"5aad79be415c487c84df42bebd84ee93","source":"clob_market_ws"},"received_at":"2026-07-28T02:58:45.720564Z","record_id":"f9b29ffcdfa590e5ca1af40fcfb33448c0dcf1c1fbe6f4d86d1b5d8d6e9967e2","schema_fingerprint":"4aa3821a28b0b7c2400bc59aba4bcc0a76e971dadd19610d3ad38c768e124dc7","schema_version":"edge-lab-recorder.raw.v1","sequence":null,"source":"clob_market_ws"}
{"event_at":"2026-07-28T02:58:45.909000Z","event_fingerprint":"05aab47d0d4e0b1f3d7786bc30ed51dfb18803f407aa680036b8655320f329b6","payload":{"connection_id":"955646bd8bf740759faf38750c0f263f","event_at":"2026-07-28T02:58:45.909000Z","event_type":"price_change","frame_hash":"b9646c5e261ff3e322dc6a58afa2843838156c03afde0c78826a3cf4a2b62ac7","frame_index":0,"kind":"data","monotonic_ns":309508784660083,"payload":{"event_type":"price_change","market":"0x0f70d07969bc69eaa97d0987de651885fdca02263688026aa11e7678af8f87aa","price_changes":[{"asset_id":"64053005904884194822931764831592250494815136296598204104072528088122126148949","best_ask":"0.67","best_bid":"0.66","hash":"5318a05075342cd7415cca7c0ec0f9c8df70f594","price":"0.01","side":"BUY","size":"2690.52"},{"asset_id":"58313761654877669244690227616056238030136603415514645252000528337391143520538","best_ask":"0.34","best_bid":"0.33","hash":"df5ed74e9f970b9a1a9d3d1b29c66dbf7c8112ba","price":"0.99","side":"SELL","size":"2690.52"}],"timestamp":"1785207525909"},"payload_hash":"2c44d48e60e2339f964e946e298293aa1ef088971a262e6b57cd60e6ab49c86e","raw_frame":"{\"market\":\"0x0f70d07969bc69eaa97d0987de651885fdca02263688026aa11e7678af8f87aa\", \"price_changes\":[{\"asset_id\":\"64053005904884194822931764831592250494815136296598204104072528088122126148949\", \"price\":\"0.01\", \"size\":\"2690.52\", \"side\":\"BUY\", \"hash\":\"5318a05075342cd7415cca7c0ec0f9c8df70f594\", \"best_bid\":\"0.66\", \"best_ask\":\"0.67\"}, {\"asset_id\":\"58313761654877669244690227616056238030136603415514645252000528337391143520538\", \"price\":\"0.99\", \"size\":\"2690.52\", \"side\":\"SELL\", \"hash\":\"df5ed74e9f970b9a1a9d3d1b29c66dbf7c8112ba\", \"best_bid\":\"0.33\", \"best_ask\":\"0.34\"}], \"timestamp\":\"1785207525909\", \"event_type\":\"price_change\"}","received_at":"2026-07-28T02:58:45.766828Z","schema_version":"clob-market-ws.price_change.v1","sequence":null,"server_hash":null,"server_timestamp":"1785207525909","session_id":"5aad79be415c487c84df42bebd84ee93","source":"clob_market_ws"},"received_at":"2026-07-28T02:58:45.766828Z","record_id":"51db2511bbc29037ee4ca2669aa14e76a13834536e47013e8afefd271c4a6e41","schema_fingerprint":"4aa3821a28b0b7c2400bc59aba4bcc0a76e971dadd19610d3ad38c768e124dc7","schema_version":"edge-lab-recorder.raw.v1","sequence":null,"source":"clob_market_ws"}
{"event_at":"2026-07-28T02:58:45.932000Z","event_fingerprint":"dc4f7f02b9974f8c34016e26a4808128fab3ecd69f754f5c403f8f89bfd5e49b","payload":{"connection_id":"955646bd8bf740759faf38750c0f263f","event_at":"2026-07-28T02:58:45.932000Z","event_type":"price_change","frame_hash":"da2d131e1a3fb79568cd052731eeb5015d9274cec1f04d3e2deac28074cf96a1","frame_index":0,"kind":"data","monotonic_ns":309508807725625,"payload":{"event_type":"price_change","market":"0x0f70d07969bc69eaa97d0987de651885fdca02263688026aa11e7678af8f87aa","price_changes":[{"asset_id":"64053005904884194822931764831592250494815136296598204104072528088122126148949","best_ask":"0.67","best_bid":"0.66","hash":"9da4a543dbbbd83733c784ae851ace0116127b9a","price":"0.01","side":"BUY","size":"2695.52"},{"asset_id":"58313761654877669244690227616056238030136603415514645252000528337391143520538","best_ask":"0.34","best_bid":"0.33","hash":"858eeed199e0a57b0c0b383105b3e44688fa4a82","price":"0.99","side":"SELL","size":"2695.52"}],"timestamp":"1785207525932"},"payload_hash":"f558034e78a8d406ca8e9f6de8c7206e064cd133d88943cc8b9220621bb59fa1","raw_frame":"{\"market\":\"0x0f70d07969bc69eaa97d0987de651885fdca02263688026aa11e7678af8f87aa\", \"price_changes\":[{\"asset_id\":\"64053005904884194822931764831592250494815136296598204104072528088122126148949\", \"price\":\"0.01\", \"size\":\"2695.52\", \"side\":\"BUY\", \"hash\":\"9da4a543dbbbd83733c784ae851ace0116127b9a\", \"best_bid\":\"0.66\", \"best_ask\":\"0.67\"}, {\"asset_id\":\"58313761654877669244690227616056238030136603415514645252000528337391143520538\", \"price\":\"0.99\", \"size\":\"2695.52\", \"side\":\"SELL\", \"hash\":\"858eeed199e0a57b0c0b383105b3e44688fa4a82\", \"best_bid\":\"0.33\", \"best_ask\":\"0.34\"}], \"timestamp\":\"1785207525932\", \"event_type\":\"price_change\"}","received_at":"2026-07-28T02:58:45.789895Z","schema_version":"clob-market-ws.price_change.v1","sequence":null,"server_hash":null,"server_timestamp":"1785207525932","session_id":"5aad79be415c487c84df42bebd84ee93","source":"clob_market_ws"},"received_at":"2026-07-28T02:58:45.789895Z","record_id":"2fc48489a2e8975ff501e78b7393fcf18173a50c5136da5074a3338435555797","schema_fingerprint":"4aa3821a28b0b7c2400bc59aba4bcc0a76e971dadd19610d3ad38c768e124dc7","schema_version":"edge-lab-recorder.raw.v1","sequence":null,"source":"clob_market_ws"}
{"event_at":"2026-07-28T02:58:45.934000Z","event_fingerprint":"ce3ad74b18942cedf0479eea95f5d29b083078bd0cf9703cd402a3a0a91a3f54","payload":{"connection_id":"955646bd8bf740759faf38750c0f263f","event_at":"2026-07-28T02:58:45.934000Z","event_type":"price_change","frame_hash":"f5b81addc77d69ee80d00f97d1fb848d274d59046c5bddaca68e455611cf460e","frame_index":0,"kind":"data","monotonic_ns":309508809947291,"payload":{"event_type":"price_change","market":"0x0f70d07969bc69eaa97d0987de651885fdca02263688026aa11e7678af8f87aa","price_changes":[{"asset_id":"64053005904884194822931764831592250494815136296598204104072528088122126148949","best_ask":"0.67","best_bid":"0.66","hash":"5adf1e695ea21ecd24bbd49afe402f6f81403798","price":"0.56","side":"BUY","size":"179.6"},{"asset_id":"58313761654877669244690227616056238030136603415514645252000528337391143520538","best_ask":"0.34","best_bid":"0.33","hash":"2474f81d5ec960867f183216ab49f2077c2d93cc","price":"0.44","side":"SELL","size":"179.6"}],"timestamp":"1785207525934"},"payload_hash":"a5c421c5c05a627d0407950eefdc43bcba13f916dad17f0fe32205ec41a2f7c2","raw_frame":"{\"market\":\"0x0f70d07969bc69eaa97d0987de651885fdca02263688026aa11e7678af8f87aa\", \"price_changes\":[{\"asset_id\":\"64053005904884194822931764831592250494815136296598204104072528088122126148949\", \"price\":\"0.56\", \"size\":\"179.6\", \"side\":\"BUY\", \"hash\":\"5adf1e695ea21ecd24bbd49afe402f6f81403798\", \"best_bid\":\"0.66\", \"best_ask\":\"0.67\"}, {\"asset_id\":\"58313761654877669244690227616056238030136603415514645252000528337391143520538\", \"price\":\"0.44\", \"size\":\"179.6\", \"side\":\"SELL\", \"hash\":\"2474f81d5ec960867f183216ab49f2077c2d93cc\", \"best_bid\":\"0.33\", \"best_ask\":\"0.34\"}], \"timestamp\":\"1785207525934\", \"event_type\":\"price_change\"}","received_at":"2026-07-28T02:58:45.792117Z","schema_version":"clob-market-ws.price_change.v1","sequence":null,"server_hash":null,"server_timestamp":"1785207525934","session_id":"5aad79be415c487c84df42bebd84ee93","source":"clob_market_ws"},"received_at":"2026-07-28T02:58:45.792117Z","record_id":"1e3fc122c5f88fb61f4feb7c96699632657399660a45512437a56cde0ab9f11e","schema_fingerprint":"4aa3821a28b0b7c2400bc59aba4bcc0a76e971dadd19610d3ad38c768e124dc7","schema_version":"edge-lab-recorder.raw.v1","sequence":null,"source":"clob_market_ws"}
{"event_at":"2026-07-28T02:58:45.935000Z","event_fingerprint":"81606654de7654ce10ce5f7994b8a5d6b891882473a3223fda71e2bfb178c9f7","payload":{"connection_id":"955646bd8bf740759faf38750c0f263f","event_at":"2026-07-28T02:58:45.935000Z","event_type":"price_change","frame_hash":"4fc4c6d77601216c71e6dbb7c89d7b88a9f692094f935484e2c04c3f1712922f","frame_index":0,"kind":"data","monotonic_ns":309508811471583,"payload":{"event_type":"price_change","market":"0x0f70d07969bc69eaa97d0987de651885fdca02263688026aa11e7678af8f87aa","price_changes":[{"asset_id":"58313761654877669244690227616056238030136603415514645252000528337391143520538","best_ask":"0.34","best_bid":"0.33","hash":"3c59aaa78de6ab41f46a7bef8ff7a4f5148b53ab","price":"0.01","side":"BUY","size":"2566.24"},{"asset_id":"64053005904884194822931764831592250494815136296598204104072528088122126148949","best_ask":"0.67","best_bid":"0.66","hash":"5fa704ec14d7bc59fbfea16b234c43f4be02f51d","price":"0.99","side":"SELL","size":"2566.24"}],"timestamp":"1785207525935"},"payload_hash":"0b3d318eac42185ff6c90d4d0dd72538fb64918e7640b42f19a0278d19746dca","raw_frame":"{\"market\":\"0x0f70d07969bc69eaa97d0987de651885fdca02263688026aa11e7678af8f87aa\", \"price_changes\":[{\"asset_id\":\"58313761654877669244690227616056238030136603415514645252000528337391143520538\", \"price\":\"0.01\", \"size\":\"2566.24\", \"side\":\"BUY\", \"hash\":\"3c59aaa78de6ab41f46a7bef8ff7a4f5148b53ab\", \"best_bid\":\"0.33\", \"best_ask\":\"0.34\"}, {\"asset_id\":\"64053005904884194822931764831592250494815136296598204104072528088122126148949\", \"price\":\"0.99\", \"size\":\"2566.24\", \"side\":\"SELL\", \"hash\":\"5fa704ec14d7bc59fbfea16b234c43f4be02f51d\", \"best_bid\":\"0.66\", \"best_ask\":\"0.67\"}], \"timestamp\":\"1785207525935\", \"event_type\":\"price_change\"}","received_at":"2026-07-28T02:58:45.793642Z","schema_version":"clob-market-ws.price_change.v1","sequence":null,"server_hash":null,"server_timestamp":"1785207525935","session_id":"5aad79be415c487c84df42bebd84ee93","source":"clob_market_ws"},"received_at":"2026-07-28T02:58:45.793642Z","record_id":"9bc890a08e6229a1c42e45822bc6d1acc3fbb15f4a0a54de6c9cba1305e45805","schema_fingerprint":"4aa3821a28b0b7c2400bc59aba4bcc0a76e971dadd19610d3ad38c768e124dc7","schema_version":"edge-lab-recorder.raw.v1","sequence":null,"source":"clob_market_ws"}
{"event_at":"2026-07-28T02:58:45.941000Z","event_fingerprint":"48f74aadf34a2fa077c0ed5fd98fb1e44740f33eca494fefde00dcf08c627699","payload":{"connection_id":"955646bd8bf740759faf38750c0f263f","event_at":"2026-07-28T02:58:45.941000Z","event_type":"price_change","frame_hash":"024e63b22ba6d123e63b508e1512bd8cd4923a2fd20d498f17a452819c159603","frame_index":0,"kind":"data","monotonic_ns":309508815866166,"payload":{"event_type":"price_change","market":"0x0f70d07969bc69eaa97d0987de651885fdca02263688026aa11e7678af8f87aa","price_changes":[{"asset_id":"64053005904884194822931764831592250494815136296598204104072528088122126148949","best_ask":"0.67","best_bid":"0.66","hash":"146d02bc63bbb3318d0a6ccc7804a0079899b256","price":"0.56","side":"BUY","size":"154.6"},{"asset_id":"58313761654877669244690227616056238030136603415514645252000528337391143520538","best_ask":"0.34","best_bid":"0.33","hash":"db4c05b00bb39645d6813c289c216aa09ca6012e","price":"0.44","side":"SELL","size":"154.6"}],"timestamp":"1785207525941"},"payload_hash":"6938087388d9ea50e96bb9f9d2f150b204cbdc75c725a81b6df25410a2528572","raw_frame":"{\"market\":\"0x0f70d07969bc69eaa97d0987de651885fdca02263688026aa11e7678af8f87aa\", \"price_changes\":[{\"asset_id\":\"64053005904884194822931764831592250494815136296598204104072528088122126148949\", \"price\":\"0.56\", \"size\":\"154.6\", \"side\":\"BUY\", \"hash\":\"146d02bc63bbb3318d0a6ccc7804a0079899b256\", \"best_bid\":\"0.66\", \"best_ask\":\"0.67\"}, {\"asset_id\":\"58313761654877669244690227616056238030136603415514645252000528337391143520538\", \"price\":\"0.44\", \"size\":\"154.6\", \"side\":\"SELL\", \"hash\":\"db4c05b00bb39645d6813c289c216aa09ca6012e\", \"best_bid\":\"0.33\", \"best_ask\":\"0.34\"}], \"timestamp\":\"1785207525941\", \"event_type\":\"price_change\"}","received_at":"2026-07-28T02:58:45.798037Z","schema_version":"clob-market-ws.price_change.v1","sequence":null,"server_hash":null,"server_timestamp":"1785207525941","session_id":"5aad79be415c487c84df42bebd84ee93","source":"clob_market_ws"},"received_at":"2026-07-28T02:58:45.798037Z","record_id":"3d5d5a4e6dcd439956cacf961111d50ce4ca3423e3ea59d9359d1a6b2ae5e07e","schema_fingerprint":"4aa3821a28b0b7c2400bc59aba4bcc0a76e971dadd19610d3ad38c768e124dc7","schema_version":"edge-lab-recorder.raw.v1","sequence":null,"source":"clob_market_ws"}
{"event_at":"2026-07-28T02:58:45.941000Z","event_fingerprint":"d6bf42d09a01d4d9b8d3a06644a1a1e005ccb63fb18a07d80466f35d94dfd177","payload":{"connection_id":"955646bd8bf740759faf38750c0f263f","event_at":"2026-07-28T02:58:45.941000Z","event_type":"price_change","frame_hash":"38d90004934be67b8952558f089ea34c0ea37ebf1aedcaf545dd29685ba34817","frame_index":0,"kind":"data","monotonic_ns":309508817351750,"payload":{"event_type":"price_change","market":"0x0f70d07969bc69eaa97d0987de651885fdca02263688026aa11e7678af8f87aa","price_changes":[{"asset_id":"58313761654877669244690227616056238030136603415514645252000528337391143520538","best_ask":"0.34","best_bid":"0.33","hash":"db4c05b00bb39645d6813c289c216aa09ca6012e","price":"0.25","side":"BUY","size":"176.3"},{"asset_id":"64053005904884194822931764831592250494815136296598204104072528088122126148949","best_ask":"0.67","best_bid":"0.66","hash":"146d02bc63bbb3318d0a6ccc7804a0079899b256","price":"0.75","side":"SELL","size":"176.3"}],"timestamp":"1785207525941"},"payload_hash":"25ff1c865a9c68f6d4fa375af2207a0c88ecc66afab6729126a82b38570a5922","raw_frame":"{\"market\":\"0x0f70d07969bc69eaa97d0987de651885fdca02263688026aa11e7678af8f87aa\", \"price_changes\":[{\"asset_id\":\"58313761654877669244690227616056238030136603415514645252000528337391143520538\", \"price\":\"0.25\", \"size\":\"176.3\", \"side\":\"BUY\", \"hash\":\"db4c05b00bb39645d6813c289c216aa09ca6012e\", \"best_bid\":\"0.33\", \"best_ask\":\"0.34\"}, {\"asset_id\":\"64053005904884194822931764831592250494815136296598204104072528088122126148949\", \"price\":\"0.75\", \"size\":\"176.3\", \"side\":\"SELL\", \"hash\":\"146d02bc63bbb3318d0a6ccc7804a0079899b256\", \"best_bid\":\"0.66\", \"best_ask\":\"0.67\"}], \"timestamp\":\"1785207525941\", \"event_type\":\"price_change\"}","received_at":"2026-07-28T02:58:45.799522Z","schema_version":"clob-market-ws.price_change.v1","sequence":null,"server_hash":null,"server_timestamp":"1785207525941","session_id":"5aad79be415c487c84df42bebd84ee93","source":"clob_market_ws"},"received_at":"2026-07-28T02:58:45.799522Z","record_id":"94c3a9fb74df39d2b9a70d62fbb9906d8e83e52f01437f4bd1e59daea0f61c09","schema_fingerprint":"4aa3821a28b0b7c2400bc59aba4bcc0a76e971dadd19610d3ad38c768e124dc7","schema_version":"edge-lab-recorder.raw.v1","sequence":null,"source":"clob_market_ws"}
{"event_at":"2026-07-28T02:58:45.959000Z","event_fingerprint":"ca906c6be0f5369e0cd104a404d1598a4a7da6baadf84d8dcac186fd8b4d99aa","payload":{"connection_id":"955646bd8bf740759faf38750c0f263f","event_at":"2026-07-28T02:58:45.959000Z","event_type":"price_change","frame_hash":"3589243f20d9da6bc93e9eba7c83b14e140efabfdd5bab485f1f12788cd6ed6c","frame_index":0,"kind":"data","monotonic_ns":309508832922541,"payload":{"event_type":"price_change","market":"0x0f70d07969bc69eaa97d0987de651885fdca02263688026aa11e7678af8f87aa","price_changes":[{"asset_id":"64053005904884194822931764831592250494815136296598204104072528088122126148949","best_ask":"0.67","best_bid":"0.66","hash":"5e567a020a76f7583c5197405b6cc89542123ed1","price":"0.01","side":"BUY","size":"2690.52"},{"asset_id":"58313761654877669244690227616056238030136603415514645252000528337391143520538","best_ask":"0.34","best_bid":"0.33","hash":"f96334dbab3deb61cfa8f361b6615e00c3bb2b47","price":"0.99","side":"SELL","size":"2690.52"}],"timestamp":"1785207525959"},"payload_hash":"643c7c912ed155e1de5d256930c1675eada02b61c5f298cf423e305a3e471ce5","raw_frame":"{\"market\":\"0x0f70d07969bc69eaa97d0987de651885fdca02263688026aa11e7678af8f87aa\", \"price_changes\":[{\"asset_id\":\"64053005904884194822931764831592250494815136296598204104072528088122126148949\", \"price\":\"0.01\", \"size\":\"2690.52\", \"side\":\"BUY\", \"hash\":\"5e567a020a76f7583c5197405b6cc89542123ed1\", \"best_bid\":\"0.66\", \"best_ask\":\"0.67\"}, {\"asset_id\":\"58313761654877669244690227616056238030136603415514645252000528337391143520538\", \"price\":\"0.99\", \"size\":\"2690.52\", \"side\":\"SELL\", \"hash\":\"f96334dbab3deb61cfa8f361b6615e00c3bb2b47\", \"best_bid\":\"0.33\", \"best_ask\":\"0.34\"}], \"timestamp\":\"1785207525959\", \"event_type\":\"price_change\"}","received_at":"2026-07-28T02:58:45.815088Z","schema_version":"clob-market-ws.price_change.v1","sequence":null,"server_hash":null,"server_timestamp":"1785207525959","session_id":"5aad79be415c487c84df42bebd84ee93","source":"clob_market_ws"},"received_at":"2026-07-28T02:58:45.815088Z","record_id":"8ea54c18f2e1bc476af4f39cfdcd0f72808aad18a124e61dfe8db8c47d0059b9","schema_fingerprint":"4aa3821a28b0b7c2400bc59aba4bcc0a76e971dadd19610d3ad38c768e124dc7","schema_version":"edge-lab-recorder.raw.v1","sequence":null,"source":"clob_market_ws"}
{"event_at":"2026-07-28T02:58:45.979000Z","event_fingerprint":"ee9b92e6f1c10b333b41473829acb71d19627f712cb7955b42ef5e3ff6e8b15d","payload":{"connection_id":"955646bd8bf740759faf38750c0f263f","event_at":"2026-07-28T02:58:45.979000Z","event_type":"price_change","frame_hash":"1707ee306efa729c65e9c5f44b68f4db30b4131575432fbe26c74486431d1e2d","frame_index":0,"kind":"data","monotonic_ns":309508853805958,"payload":{"event_type":"price_change","market":"0x0f70d07969bc69eaa97d0987de651885fdca02263688026aa11e7678af8f87aa","price_changes":[{"asset_id":"64053005904884194822931764831592250494815136296598204104072528088122126148949","best_ask":"0.67","best_bid":"0.66","hash":"4ae02592b42e49be753510ee97e6726eff3929a0","price":"0.61","side":"BUY","size":"85.19"},{"asset_id":"58313761654877669244690227616056238030136603415514645252000528337391143520538","best_ask":"0.34","best_bid":"0.33","hash":"3f32ba678ee404be0f14d4e31c4457a993dd5dca","price":"0.39","side":"SELL","size":"85.19"}],"timestamp":"1785207525979"},"payload_hash":"654b936f7bbe7280b28f364c4c17123898915fb4d50a26145e14ed86f7af0595","raw_frame":"{\"market\":\"0x0f70d07969bc69eaa97d0987de651885fdca02263688026aa11e7678af8f87aa\", \"price_changes\":[{\"asset_id\":\"64053005904884194822931764831592250494815136296598204104072528088122126148949\", \"price\":\"0.61\", \"size\":\"85.19\", \"side\":\"BUY\", \"hash\":\"4ae02592b42e49be753510ee97e6726eff3929a0\", \"best_bid\":\"0.66\", \"best_ask\":\"0.67\"}, {\"asset_id\":\"58313761654877669244690227616056238030136603415514645252000528337391143520538\", \"price\":\"0.39\", \"size\":\"85.19\", \"side\":\"SELL\", \"hash\":\"3f32ba678ee404be0f14d4e31c4457a993dd5dca\", \"best_bid\":\"0.33\", \"best_ask\":\"0.34\"}], \"timestamp\":\"1785207525979\", \"event_type\":\"price_change\"}","received_at":"2026-07-28T02:58:45.835974Z","schema_version":"clob-market-ws.price_change.v1","sequence":null,"server_hash":null,"server_timestamp":"1785207525979","session_id":"5aad79be415c487c84df42bebd84ee93","source":"clob_market_ws"},"received_at":"2026-07-28T02:58:45.835974Z","record_id":"e618108e14a42dfef5fc54c6e24482e7788c17c117cc2a29025ab7dc45306c69","schema_fingerprint":"4aa3821a28b0b7c2400bc59aba4bcc0a76e971dadd19610d3ad38c768e124dc7","schema_version":"edge-lab-recorder.raw.v1","sequence":null,"source":"clob_market_ws"}
{"event_at":"2026-07-28T02:58:45.981000Z","event_fingerprint":"67d57d18714bb4ad6498e669b7960424efcee9728fc0dad40f54de920f8dc25b","payload":{"connection_id":"955646bd8bf740759faf38750c0f263f","event_at":"2026-07-28T02:58:45.981000Z","event_type":"price_change","frame_hash":"b3601e5cea44b44c1c7f719a9d8c6694cb3b040e65a1e9a87d9848f776d4b761","frame_index":0,"kind":"data","monotonic_ns":309508858683833,"payload":{"event_type":"price_change","market":"0x0f70d07969bc69eaa97d0987de651885fdca02263688026aa11e7678af8f87aa","price_changes":[{"asset_id":"64053005904884194822931764831592250494815136296598204104072528088122126148949","best_ask":"0.67","best_bid":"0.66","hash":"5f15518aec3c571ed822a685d09859d31d4e8672","price":"0.6","side":"BUY","size":"79.9"},{"asset_id":"58313761654877669244690227616056238030136603415514645252000528337391143520538","best_ask":"0.34","best_bid":"0.33","hash":"90d5ad63cc8518de30e46119b9969e431a09a8e4","price":"0.4","side":"SELL","size":"79.9"}],"timestamp":"1785207525981"},"payload_hash":"5f0c0f764083e4f748749f3158fc4698d756f96482089f131d5a3284b52e50a9","raw_frame":"{\"market\":\"0x0f70d07969bc69eaa97d0987de651885fdca02263688026aa11e7678af8f87aa\", \"price_changes\":[{\"asset_id\":\"64053005904884194822931764831592250494815136296598204104072528088122126148949\", \"price\":\"0.6\", \"size\":\"79.9\", \"side\":\"BUY\", \"hash\":\"5f15518aec3c571ed822a685d09859d31d4e8672\", \"best_bid\":\"0.66\", \"best_ask\":\"0.67\"}, {\"asset_id\":\"58313761654877669244690227616056238030136603415514645252000528337391143520538\", \"price\":\"0.4\", \"size\":\"79.9\", \"side\":\"SELL\", \"hash\":\"90d5ad63cc8518de30e46119b9969e431a09a8e4\", \"best_bid\":\"0.33\", \"best_ask\":\"0.34\"}], \"timestamp\":\"1785207525981\", \"event_type\":\"price_change\"}","received_at":"2026-07-28T02:58:45.840854Z","schema_version":"clob-market-ws.price_change.v1","sequence":null,"server_hash":null,"server_timestamp":"1785207525981","session_id":"5aad79be415c487c84df42bebd84ee93","source":"clob_market_ws"},"received_at":"2026-07-28T02:58:45.840854Z","record_id":"a8ee3f0b8dc855d247f3bcfeb949f556e9d0d6ac7ae9a7eabd517d5d4d1c7c38","schema_fingerprint":"4aa3821a28b0b7c2400bc59aba4bcc0a76e971dadd19610d3ad38c768e124dc7","schema_version":"edge-lab-recorder.raw.v1","sequence":null,"source":"clob_market_ws"}
{"event_at":"2026-07-28T02:58:45.986000Z","event_fingerprint":"3338dccb9040a70f16a641106e48db36ab978bf042c3c07e6c434ff3c3c49270","payload":{"connection_id":"955646bd8bf740759faf38750c0f263f","event_at":"2026-07-28T02:58:45.986000Z","event_type":"price_change","frame_hash":"9228b4a29018f0518a5c3065fa25c0e3010e1a7e27316632869f9d4ef3f9d8ec","frame_index":0,"kind":"data","monotonic_ns":309508860688333,"payload":{"event_type":"price_change","market":"0x0f70d07969bc69eaa97d0987de651885fdca02263688026aa11e7678af8f87aa","price_changes":[{"asset_id":"64053005904884194822931764831592250494815136296598204104072528088122126148949","best_ask":"0.67","best_bid":"0.66","hash":"bf7f51c47935f1bb6da29f9ac82b0b1175243287","price":"0.65","side":"BUY","size":"147.91"},{"asset_id":"58313761654877669244690227616056238030136603415514645252000528337391143520538","best_ask":"0.34","best_bid":"0.33","hash":"4d8baf85c41d47c33472652233fdd31713964ca9","price":"0.35","side":"SELL","size":"147.91"}],"timestamp":"1785207525986"},"payload_hash":"47c989244b11e1dbaa142e7081108b02d18232310b895847fa2ac80e6f1bc55b","raw_frame":"{\"market\":\"0x0f70d07969bc69eaa97d0987de651885fdca02263688026aa11e7678af8f87aa\", \"price_changes\":[{\"asset_id\":\"64053005904884194822931764831592250494815136296598204104072528088122126148949\", \"price\":\"0.65\", \"size\":\"147.91\", \"side\":\"BUY\", \"hash\":\"bf7f51c47935f1bb6da29f9ac82b0b1175243287\", \"best_bid\":\"0.66\", \"best_ask\":\"0.67\"}, {\"asset_id\":\"58313761654877669244690227616056238030136603415514645252000528337391143520538\", \"price\":\"0.35\", \"size\":\"147.91\", \"side\":\"SELL\", \"hash\":\"4d8baf85c41d47c33472652233fdd31713964ca9\", \"best_bid\":\"0.33\", \"best_ask\":\"0.34\"}], \"timestamp\":\"1785207525986\", \"event_type\":\"price_change\"}","received_at":"2026-07-28T02:58:45.842857Z","schema_version":"clob-market-ws.price_change.v1","sequence":null,"server_hash":null,"server_timestamp":"1785207525986","session_id":"5aad79be415c487c84df42bebd84ee93","source":"clob_market_ws"},"received_at":"2026-07-28T02:58:45.842857Z","record_id":"8dc50f2f05957607bd3bac9d4bafb529d368202852740b72c6173498aacca3bc","schema_fingerprint":"4aa3821a28b0b7c2400bc59aba4bcc0a76e971dadd19610d3ad38c768e124dc7","schema_version":"edge-lab-recorder.raw.v1","sequence":null,"source":"clob_market_ws"}
{"event_at":"2026-07-28T02:58:45.994000Z","event_fingerprint":"619b4d1c89187c3509fc9fda95838583f0577e834b22a93980a6b22694952fe0","payload":{"connection_id":"955646bd8bf740759faf38750c0f263f","event_at":"2026-07-28T02:58:45.994000Z","event_type":"price_change","frame_hash":"244c3351292de967d1233019cfba0c7d5dffb22465b20708d44d425391fecf33","frame_index":0,"kind":"data","monotonic_ns":309508868965583,"payload":{"event_type":"price_change","market":"0x0f70d07969bc69eaa97d0987de651885fdca02263688026aa11e7678af8f87aa","price_changes":[{"asset_id":"64053005904884194822931764831592250494815136296598204104072528088122126148949","best_ask":"0.67","best_bid":"0.66","hash":"f1da73f1154aefbf7c34d2f1dc977b597b7b9b86","price":"0.56","side":"BUY","size":"129.6"},{"asset_id":"58313761654877669244690227616056238030136603415514645252000528337391143520538","best_ask":"0.34","best_bid":"0.33","hash":"2abd1b81b3e68fa7179b985058cf84eac7715395","price":"0.44","side":"SELL","size":"129.6"}],"timestamp":"1785207525994"},"payload_hash":"807da8735ac9caa47cc9f372f8b2f443854f567e9203d76791e5ad24e5556ef9","raw_frame":"{\"market\":\"0x0f70d07969bc69eaa97d0987de651885fdca02263688026aa11e7678af8f87aa\", \"price_changes\":[{\"asset_id\":\"64053005904884194822931764831592250494815136296598204104072528088122126148949\", \"price\":\"0.56\", \"size\":\"129.6\", \"side\":\"BUY\", \"hash\":\"f1da73f1154aefbf7c34d2f1dc977b597b7b9b86\", \"best_bid\":\"0.66\", \"best_ask\":\"0.67\"}, {\"asset_id\":\"58313761654877669244690227616056238030136603415514645252000528337391143520538\", \"price\":\"0.44\", \"size\":\"129.6\", \"side\":\"SELL\", \"hash\":\"2abd1b81b3e68fa7179b985058cf84eac7715395\", \"best_bid\":\"0.33\", \"best_ask\":\"0.34\"}], \"timestamp\":\"1785207525994\", \"event_type\":\"price_change\"}","received_at":"2026-07-28T02:58:45.851134Z","schema_version":"clob-market-ws.price_change.v1","sequence":null,"server_hash":null,"server_timestamp":"1785207525994","session_id":"5aad79be415c487c84df42bebd84ee93","source":"clob_market_ws"},"received_at":"2026-07-28T02:58:45.851134Z","record_id":"02a7e8f76de6f792cefb2ba5e73baeab4bea29fc50052c0f736c4fcfc2f1b444","schema_fingerprint":"4aa3821a28b0b7c2400bc59aba4bcc0a76e971dadd19610d3ad38c768e124dc7","schema_version":"edge-lab-recorder.raw.v1","sequence":null,"source":"clob_market_ws"}
{"event_at":"2026-07-28T02:58:45.994000Z","event_fingerprint":"120f36b2515a153fea8a78e10fe6b1a2ffdc05e7d29a353f2f9b253f3a147dd7","payload":{"connection_id":"955646bd8bf740759faf38750c0f263f","event_at":"2026-07-28T02:58:45.994000Z","event_type":"price_change","frame_hash":"4a2e4e361ad0297eeb791dd806d3094fdc7224b9b2e1b75bc35037eeb8925930","frame_index":0,"kind":"data","monotonic_ns":309508870555458,"payload":{"event_type":"price_change","market":"0x0f70d07969bc69eaa97d0987de651885fdca02263688026aa11e7678af8f87aa","price_changes":[{"asset_id":"58313761654877669244690227616056238030136603415514645252000528337391143520538","best_ask":"0.34","best_bid":"0.33","hash":"2abd1b81b3e68fa7179b985058cf84eac7715395","price":"0.25","side":"BUY","size":"151.3"},{"asset_id":"64053005904884194822931764831592250494815136296598204104072528088122126148949","best_ask":"0.67","best_bid":"0.66","hash":"f1da73f1154aefbf7c34d2f1dc977b597b7b9b86","price":"0.75","side":"SELL","size":"151.3"}],"timestamp":"1785207525994"},"payload_hash":"7abf11e625bc8ae1419a780b80477529909771da512db0cff481cc65e73ec666","raw_frame":"{\"market\":\"0x0f70d07969bc69eaa97d0987de651885fdca02263688026aa11e7678af8f87aa\", \"price_changes\":[{\"asset_id\":\"58313761654877669244690227616056238030136603415514645252000528337391143520538\", \"price\":\"0.25\", \"size\":\"151.3\", \"side\":\"BUY\", \"hash\":\"2abd1b81b3e68fa7179b985058cf84eac7715395\", \"best_bid\":\"0.33\", \"best_ask\":\"0.34\"}, {\"asset_id\":\"64053005904884194822931764831592250494815136296598204104072528088122126148949\", \"price\":\"0.75\", \"size\":\"151.3\", \"side\":\"SELL\", \"hash\":\"f1da73f1154aefbf7c34d2f1dc977b597b7b9b86\", \"best_bid\":\"0.66\", \"best_ask\":\"0.67\"}], \"timestamp\":\"1785207525994\", \"event_type\":\"price_change\"}","received_at":"2026-07-28T02:58:45.852725Z","schema_version":"clob-market-ws.price_change.v1","sequence":null,"server_hash":null,"server_timestamp":"1785207525994","session_id":"5aad79be415c487c84df42bebd84ee93","source":"clob_market_ws"},"received_at":"2026-07-28T02:58:45.852725Z","record_id":"1ce5b3ccbff9c023589f7f70e7fd1bd3be0736b847cfa120413aa6d357f18692","schema_fingerprint":"4aa3821a28b0b7c2400bc59aba4bcc0a76e971dadd19610d3ad38c768e124dc7","schema_version":"edge-lab-recorder.raw.v1","sequence":null,"source":"clob_market_ws"}
{"event_at":"2026-07-28T02:58:46.010000Z","event_fingerprint":"e7603db5e650cef5992d062cca382d76bc71f89236a9ab3d61e1e1bfdd83f94c","payload":{"connection_id":"955646bd8bf740759faf38750c0f263f","event_at":"2026-07-28T02:58:46.010000Z","event_type":"price_change","frame_hash":"6cb16d305ef5ee90c0018c1afc98f026706b82743fff01d1fe9ae3ba32eeeb2f","frame_index":0,"kind":"data","monotonic_ns":309508886257541,"payload":{"event_type":"price_change","market":"0x0f70d07969bc69eaa97d0987de651885fdca02263688026aa11e7678af8f87aa","price_changes":[{"asset_id":"64053005904884194822931764831592250494815136296598204104072528088122126148949","best_ask":"0.67","best_bid":"0.66","hash":"6a48d18a64fc59aa85c03c0a92f05f8217b03e9f","price":"0.64","side":"BUY","size":"188.58"},{"asset_id":"58313761654877669244690227616056238030136603415514645252000528337391143520538","best_ask":"0.34","best_bid":"0.33","hash":"a950f3d6d415ec38e2935e31e855033c09377775","price":"0.36","side":"SELL","size":"188.58"}],"timestamp":"1785207526010"},"payload_hash":"5013d74507041509b2ae3921b38bb8feefae4fab1d773a5ff307d2ecad47a787","raw_frame":"{\"market\":\"0x0f70d07969bc69eaa97d0987de651885fdca02263688026aa11e7678af8f87aa\", \"price_changes\":[{\"asset_id\":\"64053005904884194822931764831592250494815136296598204104072528088122126148949\", \"price\":\"0.64\", \"size\":\"188.58\", \"side\":\"BUY\", \"hash\":\"6a48d18a64fc59aa85c03c0a92f05f8217b03e9f\", \"best_bid\":\"0.66\", \"best_ask\":\"0.67\"}, {\"asset_id\":\"58313761654877669244690227616056238030136603415514645252000528337391143520538\", \"price\":\"0.36\", \"size\":\"188.58\", \"side\":\"SELL\", \"hash\":\"a950f3d6d415ec38e2935e31e855033c09377775\", \"best_bid\":\"0.33\", \"best_ask\":\"0.34\"}], \"timestamp\":\"1785207526010\", \"event_type\":\"price_change\"}","received_at":"2026-07-28T02:58:45.868428Z","schema_version":"clob-market-ws.price_change.v1","sequence":null,"server_hash":null,"server_timestamp":"1785207526010","session_id":"5aad79be415c487c84df42bebd84ee93","source":"clob_market_ws"},"received_at":"2026-07-28T02:58:45.868428Z","record_id":"5f009d596a5ef5290910183619d3aca8262f03da5ba9ef936c1dedf184083f19","schema_fingerprint":"4aa3821a28b0b7c2400bc59aba4bcc0a76e971dadd19610d3ad38c768e124dc7","schema_version":"edge-lab-recorder.raw.v1","sequence":null,"source":"clob_market_ws"}
{"event_at":"2026-07-28T02:58:46.017000Z","event_fingerprint":"11e3213389ba1d110cbbf658caa825b23eebd019a00c6ac13254b92a3f7463f7","payload":{"connection_id":"955646bd8bf740759faf38750c0f263f","event_at":"2026-07-28T02:58:46.017000Z","event_type":"price_change","frame_hash":"477203d0c50484af2f4d33b7c428eb09346f770c0f489b0fc175a353062681cc","frame_index":0,"kind":"data","monotonic_ns":309508892425125,"payload":{"event_type":"price_change","market":"0x0f70d07969bc69eaa97d0987de651885fdca02263688026aa11e7678af8f87aa","price_changes":[{"asset_id":"64053005904884194822931764831592250494815136296598204104072528088122126148949","best_ask":"0.67","best_bid":"0.66","hash":"6e7593351f125ba78318f5965207b1ea1d314c60","price":"0.01","side":"BUY","size":"2695.52"},{"asset_id":"58313761654877669244690227616056238030136603415514645252000528337391143520538","best_ask":"0.34","best_bid":"0.33","hash":"43a84ec6c44f14fd8fa1ff052025357df25b2d56","price":"0.99","side":"SELL","size":"2695.52"}],"timestamp":"1785207526017"},"payload_hash":"388420f42eecd4f030ed2da6b0b2cda98082d827d9d609a9f7620a78644a7b0b","raw_frame":"{\"market\":\"0x0f70d07969bc69eaa97d0987de651885fdca02263688026aa11e7678af8f87aa\", \"price_changes\":[{\"asset_id\":\"64053005904884194822931764831592250494815136296598204104072528088122126148949\", \"price\":\"0.01\", \"size\":\"2695.52\", \"side\":\"BUY\", \"hash\":\"6e7593351f125ba78318f5965207b1ea1d314c60\", \"best_bid\":\"0.66\", \"best_ask\":\"0.67\"}, {\"asset_id\":\"58313761654877669244690227616056238030136603415514645252000528337391143520538\", \"price\":\"0.99\", \"size\":\"2695.52\", \"side\":\"SELL\", \"hash\":\"43a84ec6c44f14fd8fa1ff052025357df25b2d56\", \"best_bid\":\"0.33\", \"best_ask\":\"0.34\"}], \"timestamp\":\"1785207526017\", \"event_type\":\"price_change\"}","received_at":"2026-07-28T02:58:45.874595Z","schema_version":"clob-market-ws.price_change.v1","sequence":null,"server_hash":null,"server_timestamp":"1785207526017","session_id":"5aad79be415c487c84df42bebd84ee93","source":"clob_market_ws"},"received_at":"2026-07-28T02:58:45.874595Z","record_id":"3a3a804716201c44c3eecce3b043a3aaeea51954769cf981dfffe32982960ab0","schema_fingerprint":"4aa3821a28b0b7c2400bc59aba4bcc0a76e971dadd19610d3ad38c768e124dc7","schema_version":"edge-lab-recorder.raw.v1","sequence":null,"source":"clob_market_ws"}
{"event_at":"2026-07-28T02:58:46.021000Z","event_fingerprint":"c9b9839852fc83e876a34480f7d8fb6d2cbd3055c0d7c93ea5afb25607decaf2","payload":{"connection_id":"955646bd8bf740759faf38750c0f263f","event_at":"2026-07-28T02:58:46.021000Z","event_type":"price_change","frame_hash":"b4534becf5c20bd455c8b29e4b5adbe4f3c72cc2eeed5e94ccbcc569060d4a05","frame_index":0,"kind":"data","monotonic_ns":309508895193958,"payload":{"event_type":"price_change","market":"0x0f70d07969bc69eaa97d0987de651885fdca02263688026aa11e7678af8f87aa","price_changes":[{"asset_id":"58313761654877669244690227616056238030136603415514645252000528337391143520538","best_ask":"0.34","best_bid":"0.33","hash":"356c7c6d1793c7f2965dabcf323489cc9909dcab","price":"0.01","side":"BUY","size":"2571.24"},{"asset_id":"64053005904884194822931764831592250494815136296598204104072528088122126148949","best_ask":"0.67","best_bid":"0.66","hash":"54e0aa255661f6bbb16bdb88835cf80a5f750ae9","price":"0.99","side":"SELL","size":"2571.24"}],"timestamp":"1785207526021"},"payload_hash":"2fdd4568cf76a1bac23e4b1d053a8f2e4614457345cc405c446b350f6d849e58","raw_frame":"{\"market\":\"0x0f70d07969bc69eaa97d0987de651885fdca02263688026aa11e7678af8f87aa\", \"price_changes\":[{\"asset_id\":\"58313761654877669244690227616056238030136603415514645252000528337391143520538\", \"price\":\"0.01\", \"size\":\"2571.24\", \"side\":\"BUY\", \"hash\":\"356c7c6d1793c7f2965dabcf323489cc9909dcab\", \"best_bid\":\"0.33\", \"best_ask\":\"0.34\"}, {\"asset_id\":\"64053005904884194822931764831592250494815136296598204104072528088122126148949\", \"price\":\"0.99\", \"size\":\"2571.24\", \"side\":\"SELL\", \"hash\":\"54e0aa255661f6bbb16bdb88835cf80a5f750ae9\", \"best_bid\":\"0.66\", \"best_ask\":\"0.67\"}], \"timestamp\":\"1785207526021\", \"event_type\":\"price_change\"}","received_at":"2026-07-28T02:58:45.877364Z","schema_version":"clob-market-ws.price_change.v1","sequence":null,"server_hash":null,"server_timestamp":"1785207526021","session_id":"5aad79be415c487c84df42bebd84ee93","source":"clob_market_ws"},"received_at":"2026-07-28T02:58:45.877364Z","record_id":"add55990a230308727cef72bdfe502da7ebcc317c44f20f67556a474100bb653","schema_fingerprint":"4aa3821a28b0b7c2400bc59aba4bcc0a76e971dadd19610d3ad38c768e124dc7","schema_version":"edge-lab-recorder.raw.v1","sequence":null,"source":"clob_market_ws"}
{"event_at":"2026-07-28T02:58:46.021000Z","event_fingerprint":"67b3922ce841746071966ffdc270909813c322e72313382476524e98b7a3b16a","payload":{"connection_id":"955646bd8bf740759faf38750c0f263f","event_at":"2026-07-28T02:58:46.021000Z","event_type":"price_change","frame_hash":"c333b3bd60e4ca8de2c0e9bda619d3155d70f63ff91090e1016c67fbd43bffe1","frame_index":0,"kind":"data","monotonic_ns":309508896715666,"payload":{"event_type":"price_change","market":"0x0f70d07969bc69eaa97d0987de651885fdca02263688026aa11e7678af8f87aa","price_changes":[{"asset_id":"58313761654877669244690227616056238030136603415514645252000528337391143520538","best_ask":"0.34","best_bid":"0.33","hash":"f2750b15815867e97771083e24f72b9d08917610","price":"0.23","side":"BUY","size":"317.4"},{"asset_id":"64053005904884194822931764831592250494815136296598204104072528088122126148949","best_ask":"0.67","best_bid":"0.66","hash":"9946242fa73791ed68288cc7b6847f8f3a23ed39","price":"0.77","side":"SELL","size":"317.4"}],"timestamp":"1785207526021"},"payload_hash":"13b19c57e7cd8146f1357a2021d6a33426c54a31b387318ef49aea3d698d3ab9","raw_frame":"{\"market\":\"0x0f70d07969bc69eaa97d0987de651885fdca02263688026aa11e7678af8f87aa\", \"price_changes\":[{\"asset_id\":\"58313761654877669244690227616056238030136603415514645252000528337391143520538\", \"price\":\"0.23\", \"size\":\"317.4\", \"side\":\"BUY\", \"hash\":\"f2750b15815867e97771083e24f72b9d08917610\", \"best_bid\":\"0.33\", \"best_ask\":\"0.34\"}, {\"asset_id\":\"64053005904884194822931764831592250494815136296598204104072528088122126148949\", \"price\":\"0.77\", \"size\":\"317.4\", \"side\":\"SELL\", \"hash\":\"9946242fa73791ed68288cc7b6847f8f3a23ed39\", \"best_bid\":\"0.66\", \"best_ask\":\"0.67\"}], \"timestamp\":\"1785207526021\", \"event_type\":\"price_change\"}","received_at":"2026-07-28T02:58:45.878886Z","schema_version":"clob-market-ws.price_change.v1","sequence":null,"server_hash":null,"server_timestamp":"1785207526021","session_id":"5aad79be415c487c84df42bebd84ee93","source":"clob_market_ws"},"received_at":"2026-07-28T02:58:45.878886Z","record_id":"5953a2fefb05dbb9e946e9544a8aa42a0a09a6d558b2a59aaab8434aed38d032","schema_fingerprint":"4aa3821a28b0b7c2400bc59aba4bcc0a76e971dadd19610d3ad38c768e124dc7","schema_version":"edge-lab-recorder.raw.v1","sequence":null,"source":"clob_market_ws"}
{"event_at":"2026-07-28T02:58:46.022000Z","event_fingerprint":"1293ba66716afbec31b45eadd231e8207f1cf424c7900802097f3a1c552c0512","payload":{"connection_id":"955646bd8bf740759faf38750c0f263f","event_at":"2026-07-28T02:58:46.022000Z","event_type":"price_change","frame_hash":"ad08c94f36d474f685985445f531bc659cdeb66efed55b09f3798eca4b71d854","frame_index":0,"kind":"data","monotonic_ns":309508898381208,"payload":{"event_type":"price_change","market":"0x0f70d07969bc69eaa97d0987de651885fdca02263688026aa11e7678af8f87aa","price_changes":[{"asset_id":"58313761654877669244690227616056238030136603415514645252000528337391143520538","best_ask":"0.34","best_bid":"0.33","hash":"6e512dcebdee19c37299665c09441c95d3e15fa0","price":"0.23","side":"BUY","size":"267.4"},{"asset_id":"64053005904884194822931764831592250494815136296598204104072528088122126148949","best_ask":"0.67","best_bid":"0.66","hash":"9d1c49863dd027a278f62122cf778f1e4b101e0b","price":"0.77","side":"SELL","size":"267.4"}],"timestamp":"1785207526022"},"payload_hash":"0dcd22ba24e02f86ef896cd9a8bf3459f3e609aa30969014f8585f15381b969b","raw_frame":"{\"market\":\"0x0f70d07969bc69eaa97d0987de651885fdca02263688026aa11e7678af8f87aa\", \"price_changes\":[{\"asset_id\":\"58313761654877669244690227616056238030136603415514645252000528337391143520538\", \"price\":\"0.23\", \"size\":\"267.4\", \"side\":\"BUY\", \"hash\":\"6e512dcebdee19c37299665c09441c95d3e15fa0\", \"best_bid\":\"0.33\", \"best_ask\":\"0.34\"}, {\"asset_id\":\"64053005904884194822931764831592250494815136296598204104072528088122126148949\", \"price\":\"0.77\", \"size\":\"267.4\", \"side\":\"SELL\", \"hash\":\"9d1c49863dd027a278f62122cf778f1e4b101e0b\", \"best_bid\":\"0.66\", \"best_ask\":\"0.67\"}], \"timestamp\":\"1785207526022\", \"event_type\":\"price_change\"}","received_at":"2026-07-28T02:58:45.880551Z","schema_version":"clob-market-ws.price_change.v1","sequence":null,"server_hash":null,"server_timestamp":"1785207526022","session_id":"5aad79be415c487c84df42bebd84ee93","source":"clob_market_ws"},"received_at":"2026-07-28T02:58:45.880551Z","record_id":"895c999034c4191410c18e48efbeb707044504e2f39ad4fbfe7baf02d4036320","schema_fingerprint":"4aa3821a28b0b7c2400bc59aba4bcc0a76e971dadd19610d3ad38c768e124dc7","schema_version":"edge-lab-recorder.raw.v1","sequence":null,"source":"clob_market_ws"}
{"event_at":"2026-07-28T02:58:46.022000Z","event_fingerprint":"e1c54c3f6bb52bde7e880b54d60bc3ba937d2a3fa552995cea276f7884436aba","payload":{"connection_id":"955646bd8bf740759faf38750c0f263f","event_at":"2026-07-28T02:58:46.022000Z","event_type":"price_change","frame_hash":"b7cb46e8189c0dfc101f8149ea20d823bc450e79750caa5cf0ec46e14ca6ee71","frame_index":0,"kind":"data","monotonic_ns":309508900037625,"payload":{"event_type":"price_change","market":"0x0f70d07969bc69eaa97d0987de651885fdca02263688026aa11e7678af8f87aa","price_changes":[{"asset_id":"58313761654877669244690227616056238030136603415514645252000528337391143520538","best_ask":"0.34","best_bid":"0.33","hash":"39069b298e808b04d97e9cf961d376dd0b9d3e01","price":"0.01","side":"BUY","size":"2576.24"},{"asset_id":"64053005904884194822931764831592250494815136296598204104072528088122126148949","best_ask":"0.67","best_bid":"0.66","hash":"0c48c13f87a37afe651613105e4dc1957d9b0761","price":"0.99","side":"SELL","size":"2576.24"}],"timestamp":"1785207526022"},"payload_hash":"162d327597f7ff8d942ea87353f9a70fd9920004fe2867e251f93a0b1c472556","raw_frame":"{\"market\":\"0x0f70d07969bc69eaa97d0987de651885fdca02263688026aa11e7678af8f87aa\", \"price_changes\":[{\"asset_id\":\"58313761654877669244690227616056238030136603415514645252000528337391143520538\", \"price\":\"0.01\", \"size\":\"2576.24\", \"side\":\"BUY\", \"hash\":\"39069b298e808b04d97e9cf961d376dd0b9d3e01\", \"best_bid\":\"0.33\", \"best_ask\":\"0.34\"}, {\"asset_id\":\"64053005904884194822931764831592250494815136296598204104072528088122126148949\", \"price\":\"0.99\", \"size\":\"2576.24\", \"side\":\"SELL\", \"hash\":\"0c48c13f87a37afe651613105e4dc1957d9b0761\", \"best_bid\":\"0.66\", \"best_ask\":\"0.67\"}], \"timestamp\":\"1785207526022\", \"event_type\":\"price_change\"}","received_at":"2026-07-28T02:58:45.882209Z","schema_version":"clob-market-ws.price_change.v1","sequence":null,"server_hash":null,"server_timestamp":"1785207526022","session_id":"5aad79be415c487c84df42bebd84ee93","source":"clob_market_ws"},"received_at":"2026-07-28T02:58:45.882209Z","record_id":"ce4c7d53ac0cce1a28b65485c9f5912ba6a30461c839035490f8d73848d97ffc","schema_fingerprint":"4aa3821a28b0b7c2400bc59aba4bcc0a76e971dadd19610d3ad38c768e124dc7","schema_version":"edge-lab-recorder.raw.v1","sequence":null,"source":"clob_market_ws"}
{"event_at":"2026-07-28T02:58:46.023000Z","event_fingerprint":"005bad9310cf098b4d4cb30a35f7945a619ce46b476b7bc61b4da9fe7df461c9","payload":{"connection_id":"955646bd8bf740759faf38750c0f263f","event_at":"2026-07-28T02:58:46.023000Z","event_type":"price_change","frame_hash":"6698fbae1d20f7013e42b05f42bc55fffd1a55355b5830e54e05a524da18fc30","frame_index":0,"kind":"data","monotonic_ns":309508901543875,"payload":{"event_type":"price_change","market":"0x0f70d07969bc69eaa97d0987de651885fdca02263688026aa11e7678af8f87aa","price_changes":[{"asset_id":"58313761654877669244690227616056238030136603415514645252000528337391143520538","best_ask":"0.34","best_bid":"0.33","hash":"35fae35a602d6232339b01cee96bb681020eb239","price":"0.23","side":"BUY","size":"217.4"},{"asset_id":"64053005904884194822931764831592250494815136296598204104072528088122126148949","best_ask":"0.67","best_bid":"0.66","hash":"3884dcdb99e0caf2ff7cfa379bc06ea315a30002","price":"0.77","side":"SELL","size":"217.4"}],"timestamp":"1785207526023"},"payload_hash":"9d49349eda9b1662e7850abcf4d73bf7d4870aed1aa5318adcf5e6f90c687c16","raw_frame":"{\"market\":\"0x0f70d07969bc69eaa97d0987de651885fdca02263688026aa11e7678af8f87aa\", \"price_changes\":[{\"asset_id\":\"58313761654877669244690227616056238030136603415514645252000528337391143520538\", \"price\":\"0.23\", \"size\":\"217.4\", \"side\":\"BUY\", \"hash\":\"35fae35a602d6232339b01cee96bb681020eb239\", \"best_bid\":\"0.33\", \"best_ask\":\"0.34\"}, {\"asset_id\":\"64053005904884194822931764831592250494815136296598204104072528088122126148949\", \"price\":\"0.77\", \"size\":\"217.4\", \"side\":\"SELL\", \"hash\":\"3884dcdb99e0caf2ff7cfa379bc06ea315a30002\", \"best_bid\":\"0.66\", \"best_ask\":\"0.67\"}], \"timestamp\":\"1785207526023\", \"event_type\":\"price_change\"}","received_at":"2026-07-28T02:58:45.883715Z","schema_version":"clob-market-ws.price_change.v1","sequence":null,"server_hash":null,"server_timestamp":"1785207526023","session_id":"5aad79be415c487c84df42bebd84ee93","source":"clob_market_ws"},"received_at":"2026-07-28T02:58:45.883715Z","record_id":"dd70c5d2a6b25b3d2bbf37dfb13a03225451cea837f8d56451f63864f8d57e2f","schema_fingerprint":"4aa3821a28b0b7c2400bc59aba4bcc0a76e971dadd19610d3ad38c768e124dc7","schema_version":"edge-lab-recorder.raw.v1","sequence":null,"source":"clob_market_ws"}
{"event_at":"2026-07-28T02:58:46.025000Z","event_fingerprint":"f1204d7e7a1b5bc2c390d3748251177158f204c6e78ae94efe6b765c444da7f3","payload":{"connection_id":"955646bd8bf740759faf38750c0f263f","event_at":"2026-07-28T02:58:46.025000Z","event_type":"price_change","frame_hash":"c85d794e11f1ae511f020cf9cae9ae78d1c53181c4619244bf18666182d28d60","frame_index":0,"kind":"data","monotonic_ns":309508903110583,"payload":{"event_type":"price_change","market":"0x0f70d07969bc69eaa97d0987de651885fdca02263688026aa11e7678af8f87aa","price_changes":[{"asset_id":"64053005904884194822931764831592250494815136296598204104072528088122126148949","best_ask":"0.67","best_bid":"0.66","hash":"b790f1706392ae3ab68e4bb5cb225b38d37efc1d","price":"0.56","side":"BUY","size":"79.6"},{"asset_id":"58313761654877669244690227616056238030136603415514645252000528337391143520538","best_ask":"0.34","best_bid":"0.33","hash":"01a56a5eb14e970bc3e599c980330be1080e93ee","price":"0.44","side":"SELL","size":"79.6"}],"timestamp":"1785207526025"},"payload_hash":"d034c7dcd0368ff964786b379c403cb85b8af7c4bb135c24bc4f0a781dbdb82b","raw_frame":"{\"market\":\"0x0f70d07969bc69eaa97d0987de651885fdca02263688026aa11e7678af8f87aa\", \"price_changes\":[{\"asset_id\":\"64053005904884194822931764831592250494815136296598204104072528088122126148949\", \"price\":\"0.56\", \"size\":\"79.6\", \"side\":\"BUY\", \"hash\":\"b790f1706392ae3ab68e4bb5cb225b38d37efc1d\", \"best_bid\":\"0.66\", \"best_ask\":\"0.67\"}, {\"asset_id\":\"58313761654877669244690227616056238030136603415514645252000528337391143520538\", \"price\":\"0.44\", \"size\":\"79.6\", \"side\":\"SELL\", \"hash\":\"01a56a5eb14e970bc3e599c980330be1080e93ee\", \"best_bid\":\"0.33\", \"best_ask\":\"0.34\"}], \"timestamp\":\"1785207526025\", \"event_type\":\"price_change\"}","received_at":"2026-07-28T02:58:45.885282Z","schema_version":"clob-market-ws.price_change.v1","sequence":null,"server_hash":null,"server_timestamp":"1785207526025","session_id":"5aad79be415c487c84df42bebd84ee93","source":"clob_market_ws"},"received_at":"2026-07-28T02:58:45.885282Z","record_id":"6bbe523f57ec674af14daa41911a1bd7181c0bf88fc677040859cb59196c447f","schema_fingerprint":"4aa3821a28b0b7c2400bc59aba4bcc0a76e971dadd19610d3ad38c768e124dc7","schema_version":"edge-lab-recorder.raw.v1","sequence":null,"source":"clob_market_ws"}
{"event_at":"2026-07-28T02:58:46.025000Z","event_fingerprint":"9875b02ccd63109ab360557eb6ea1df81f72419976fec4406bd031bea38b378b","payload":{"connection_id":"955646bd8bf740759faf38750c0f263f","event_at":"2026-07-28T02:58:46.025000Z","event_type":"price_change","frame_hash":"04ef9d71270f1be203e410da806548ab59fb30a32329e834fff574c7e21f2ecd","frame_index":0,"kind":"data","monotonic_ns":309508904614666,"payload":{"event_type":"price_change","market":"0x0f70d07969bc69eaa97d0987de651885fdca02263688026aa11e7678af8f87aa","price_changes":[{"asset_id":"58313761654877669244690227616056238030136603415514645252000528337391143520538","best_ask":"0.34","best_bid":"0.33","hash":"3c76ca34acc5a30db016b25966a6cb0da01f5829","price":"0.29","side":"BUY","size":"106.1"},{"asset_id":"64053005904884194822931764831592250494815136296598204104072528088122126148949","best_ask":"0.67","best_bid":"0.66","hash":"53afb768c7198f5ae4fa46ccdf9506a9fcda42f8","price":"0.71","side":"SELL","size":"106.1"}],"timestamp":"1785207526025"},"payload_hash":"d7ecb46a738ccb82a8cdff3c357f02d9a737ba0d2f118132801b2f0d54cafb82","raw_frame":"{\"market\":\"0x0f70d07969bc69eaa97d0987de651885fdca02263688026aa11e7678af8f87aa\", \"price_changes\":[{\"asset_id\":\"58313761654877669244690227616056238030136603415514645252000528337391143520538\", \"price\":\"0.29\", \"size\":\"106.1\", \"side\":\"BUY\", \"hash\":\"3c76ca34acc5a30db016b25966a6cb0da01f5829\", \"best_bid\":\"0.33\", \"best_ask\":\"0.34\"}, {\"asset_id\":\"64053005904884194822931764831592250494815136296598204104072528088122126148949\", \"price\":\"0.71\", \"size\":\"106.1\", \"side\":\"SELL\", \"hash\":\"53afb768c7198f5ae4fa46ccdf9506a9fcda42f8\", \"best_bid\":\"0.66\", \"best_ask\":\"0.67\"}], \"timestamp\":\"1785207526025\", \"event_type\":\"price_change\"}","received_at":"2026-07-28T02:58:45.886786Z","schema_version":"clob-market-ws.price_change.v1","sequence":null,"server_hash":null,"server_timestamp":"1785207526025","session_id":"5aad79be415c487c84df42bebd84ee93","source":"clob_market_ws"},"received_at":"2026-07-28T02:58:45.886786Z","record_id":"042eb01b83a3809139986a8a4bef9d338d8bd4fe99f9f022da7df0798e860de7","schema_fingerprint":"4aa3821a28b0b7c2400bc59aba4bcc0a76e971dadd19610d3ad38c768e124dc7","schema_version":"edge-lab-recorder.raw.v1","sequence":null,"source":"clob_market_ws"}
{"event_at":"2026-07-28T02:58:46.025000Z","event_fingerprint":"e74592dba20d0e61176085dcb70fecb870b7a30ca921fc06242e7e362de54522","payload":{"connection_id":"955646bd8bf740759faf38750c0f263f","event_at":"2026-07-28T02:58:46.025000Z","event_type":"price_change","frame_hash":"531c8ff3ac447be5754a24454ef18d7b8a9b885a376062d4aa404e55f8c212dd","frame_index":0,"kind":"data","monotonic_ns":309508906053791,"payload":{"event_type":"price_change","market":"0x0f70d07969bc69eaa97d0987de651885fdca02263688026aa11e7678af8f87aa","price_changes":[{"asset_id":"58313761654877669244690227616056238030136603415514645252000528337391143520538","best_ask":"0.34","best_bid":"0.33","hash":"589ff8c5611e3e00f294a93e73454c2770a4e895","price":"0.29","side":"BUY","size":"98.1"},{"asset_id":"64053005904884194822931764831592250494815136296598204104072528088122126148949","best_ask":"0.67","best_bid":"0.66","hash":"c4a91daebf9b7572d1d98387c1a75668fd5fe281","price":"0.71","side":"SELL","size":"98.1"}],"timestamp":"1785207526025"},"payload_hash":"2ac9d08b2b0b643299e5cada998af6c8e698150e6a6e910d817fc289d11a099b","raw_frame":"{\"market\":\"0x0f70d07969bc69eaa97d0987de651885fdca02263688026aa11e7678af8f87aa\", \"price_changes\":[{\"asset_id\":\"58313761654877669244690227616056238030136603415514645252000528337391143520538\", \"price\":\"0.29\", \"size\":\"98.1\", \"side\":\"BUY\", \"hash\":\"589ff8c5611e3e00f294a93e73454c2770a4e895\", \"best_bid\":\"0.33\", \"best_ask\":\"0.34\"}, {\"asset_id\":\"64053005904884194822931764831592250494815136296598204104072528088122126148949\", \"price\":\"0.71\", \"size\":\"98.1\", \"side\":\"SELL\", \"hash\":\"c4a91daebf9b7572d1d98387c1a75668fd5fe281\", \"best_bid\":\"0.66\", \"best_ask\":\"0.67\"}], \"timestamp\":\"1785207526025\", \"event_type\":\"price_change\"}","received_at":"2026-07-28T02:58:45.888226Z","schema_version":"clob-market-ws.price_change.v1","sequence":null,"server_hash":null,"server_timestamp":"1785207526025","session_id":"5aad79be415c487c84df42bebd84ee93","source":"clob_market_ws"},"received_at":"2026-07-28T02:58:45.888226Z","record_id":"1d17e8b491b137280f77a06e92517c2f37553d156f637ad77f16e3c6d52b703a","schema_fingerprint":"4aa3821a28b0b7c2400bc59aba4bcc0a76e971dadd19610d3ad38c768e124dc7","schema_version":"edge-lab-recorder.raw.v1","sequence":null,"source":"clob_market_ws"}
{"event_at":"2026-07-28T02:58:46.032000Z","event_fingerprint":"8a3ffecf21d2eacfd441649635430074a17650b842a226ef4b31c20bbc4cc173","payload":{"connection_id":"955646bd8bf740759faf38750c0f263f","event_at":"2026-07-28T02:58:46.032000Z","event_type":"price_change","frame_hash":"dc235938d8d4abae5f845ed94de843ff6c43f6a30f893a2ee6770b26ea1c4b28","frame_index":0,"kind":"data","monotonic_ns":309508907629041,"payload":{"event_type":"price_change","market":"0x0f70d07969bc69eaa97d0987de651885fdca02263688026aa11e7678af8f87aa","price_changes":[{"asset_id":"58313761654877669244690227616056238030136603415514645252000528337391143520538","best_ask":"0.34","best_bid":"0.33","hash":"bd0dd8d455fb7c8a2bd43541041e07870e0a2bb7","price":"0.29","side":"BUY","size":"233.1"},{"asset_id":"64053005904884194822931764831592250494815136296598204104072528088122126148949","best_ask":"0.67","best_bid":"0.66","hash":"b24b7def015bac19947ab50aee333069872e0299","price":"0.71","side":"SELL","size":"233.1"}],"timestamp":"1785207526032"},"payload_hash":"56fd20e0b6f90de05cb290976d7b45f5f06a8a4ed3f67ea17986cbcf0e02694f","raw_frame":"{\"market\":\"0x0f70d07969bc69eaa97d0987de651885fdca02263688026aa11e7678af8f87aa\", \"price_changes\":[{\"asset_id\":\"58313761654877669244690227616056238030136603415514645252000528337391143520538\", \"price\":\"0.29\", \"size\":\"233.1\", \"side\":\"BUY\", \"hash\":\"bd0dd8d455fb7c8a2bd43541041e07870e0a2bb7\", \"best_bid\":\"0.33\", \"best_ask\":\"0.34\"}, {\"asset_id\":\"64053005904884194822931764831592250494815136296598204104072528088122126148949\", \"price\":\"0.71\", \"size\":\"233.1\", \"side\":\"SELL\", \"hash\":\"b24b7def015bac19947ab50aee333069872e0299\", \"best_bid\":\"0.66\", \"best_ask\":\"0.67\"}], \"timestamp\":\"1785207526032\", \"event_type\":\"price_change\"}","received_at":"2026-07-28T02:58:45.889800Z","schema_version":"clob-market-ws.price_change.v1","sequence":null,"server_hash":null,"server_timestamp":"1785207526032","session_id":"5aad79be415c487c84df42bebd84ee93","source":"clob_market_ws"},"received_at":"2026-07-28T02:58:45.889800Z","record_id":"a12cb51e61413dcd429c89ed0de80d769238fe04c374939bc7de26795689165f","schema_fingerprint":"4aa3821a28b0b7c2400bc59aba4bcc0a76e971dadd19610d3ad38c768e124dc7","schema_version":"edge-lab-recorder.raw.v1","sequence":null,"source":"clob_market_ws"}
{"event_at":"2026-07-28T02:58:46.038000Z","event_fingerprint":"43307728a64f7a1699076ca06eafda0e6f8d8ba1adc8664bb44f172d131b85ea","payload":{"connection_id":"955646bd8bf740759faf38750c0f263f","event_at":"2026-07-28T02:58:46.038000Z","event_type":"price_change","frame_hash":"105ea40aab6b28b7123b7a48ea6f24da098a2fee6cc316a994d00c6d91a91a80","frame_index":0,"kind":"data","monotonic_ns":309508917014375,"payload":{"event_type":"price_change","market":"0x0f70d07969bc69eaa97d0987de651885fdca02263688026aa11e7678af8f87aa","price_changes":[{"asset_id":"58313761654877669244690227616056238030136603415514645252000528337391143520538","best_ask":"0.34","best_bid":"0.33","hash":"a64d3fe2ac3a65a8cb8674f85bad2e4afaf9c1e2","price":"0.3","side":"BUY","size":"67"},{"asset_id":"64053005904884194822931764831592250494815136296598204104072528088122126148949","best_ask":"0.67","best_bid":"0.66","hash":"832de5f4bd0ceaf5f5e6626941023c65ee8cffb9","price":"0.7","side":"SELL","size":"67"}],"timestamp":"1785207526038"},"payload_hash":"00d4ae041f554d7f6612935527d076cc6b069a5140a6e13f85302b7b14f716d6","raw_frame":"{\"market\":\"0x0f70d07969bc69eaa97d0987de651885fdca02263688026aa11e7678af8f87aa\", \"price_changes\":[{\"asset_id\":\"58313761654877669244690227616056238030136603415514645252000528337391143520538\", \"price\":\"0.3\", \"size\":\"67\", \"side\":\"BUY\", \"hash\":\"a64d3fe2ac3a65a8cb8674f85bad2e4afaf9c1e2\", \"best_bid\":\"0.33\", \"best_ask\":\"0.34\"}, {\"asset_id\":\"64053005904884194822931764831592250494815136296598204104072528088122126148949\", \"price\":\"0.7\", \"size\":\"67\", \"side\":\"SELL\", \"hash\":\"832de5f4bd0ceaf5f5e6626941023c65ee8cffb9\", \"best_bid\":\"0.66\", \"best_ask\":\"0.67\"}], \"timestamp\":\"1785207526038\", \"event_type\":\"price_change\"}","received_at":"2026-07-28T02:58:45.899185Z","schema_version":"clob-market-ws.price_change.v1","sequence":null,"server_hash":null,"server_timestamp":"1785207526038","session_id":"5aad79be415c487c84df42bebd84ee93","source":"clob_market_ws"},"received_at":"2026-07-28T02:58:45.899185Z","record_id":"ff74e8c70196498d24aa5b31423242cab49480c51353b79cabb78b33d9aee61b","schema_fingerprint":"4aa3821a28b0b7c2400bc59aba4bcc0a76e971dadd19610d3ad38c768e124dc7","schema_version":"edge-lab-recorder.raw.v1","sequence":null,"source":"clob_market_ws"}
{"event_at":"2026-07-28T02:58:46.041000Z","event_fingerprint":"e7687b563eb8146c07d57a07c6fdf0193decf4910d5e293a1f430a4bcdfa0483","payload":{"connection_id":"955646bd8bf740759faf38750c0f263f","event_at":"2026-07-28T02:58:46.041000Z","event_type":"price_change","frame_hash":"cfb9ffd743e82091f615d1cc7c6da32eb99aca7dca8aec74019c68f01038c620","frame_index":0,"kind":"data","monotonic_ns":309508918492750,"payload":{"event_type":"price_change","market":"0x0f70d07969bc69eaa97d0987de651885fdca02263688026aa11e7678af8f87aa","price_changes":[{"asset_id":"64053005904884194822931764831592250494815136296598204104072528088122126148949","best_ask":"0.67","best_bid":"0.66","hash":"a8fc47ddfc445f8c9a282325576deefd38e08ae1","price":"0.03","side":"BUY","size":"550.8"},{"asset_id":"58313761654877669244690227616056238030136603415514645252000528337391143520538","best_ask":"0.34","best_bid":"0.33","hash":"a5eb0ff91bfcb2188b2a1bf0aad525607771776e","price":"0.97","side":"SELL","size":"550.8"}],"timestamp":"1785207526041"},"payload_hash":"a95fe7785f202e07c0092f434195481cf1b775834b13cb268683ad7de04825ee","raw_frame":"{\"market\":\"0x0f70d07969bc69eaa97d0987de651885fdca02263688026aa11e7678af8f87aa\", \"price_changes\":[{\"asset_id\":\"64053005904884194822931764831592250494815136296598204104072528088122126148949\", \"price\":\"0.03\", \"size\":\"550.8\", \"side\":\"BUY\", \"hash\":\"a8fc47ddfc445f8c9a282325576deefd38e08ae1\", \"best_bid\":\"0.66\", \"best_ask\":\"0.67\"}, {\"asset_id\":\"58313761654877669244690227616056238030136603415514645252000528337391143520538\", \"price\":\"0.97\", \"size\":\"550.8\", \"side\":\"SELL\", \"hash\":\"a5eb0ff91bfcb2188b2a1bf0aad525607771776e\", \"best_bid\":\"0.33\", \"best_ask\":\"0.34\"}], \"timestamp\":\"1785207526041\", \"event_type\":\"price_change\"}","received_at":"2026-07-28T02:58:45.900664Z","schema_version":"clob-market-ws.price_change.v1","sequence":null,"server_hash":null,"server_timestamp":"1785207526041","session_id":"5aad79be415c487c84df42bebd84ee93","source":"clob_market_ws"},"received_at":"2026-07-28T02:58:45.900664Z","record_id":"1d377a0e761e0e7b617b43e1fee6b910261334dd3d6dd9c192f0b1941e9b568c","schema_fingerprint":"4aa3821a28b0b7c2400bc59aba4bcc0a76e971dadd19610d3ad38c768e124dc7","schema_version":"edge-lab-recorder.raw.v1","sequence":null,"source":"clob_market_ws"}
{"event_at":"2026-07-28T02:58:46.042000Z","event_fingerprint":"eccdd4766df9e6ac9d63c02fe80225e158c5697ff04618b5d99c95a56a520e27","payload":{"connection_id":"955646bd8bf740759faf38750c0f263f","event_at":"2026-07-28T02:58:46.042000Z","event_type":"price_change","frame_hash":"0627e0be6210a2cb8a142d06ea76e35d2ba5098a71f183f6f3e7b31f0ab58ffd","frame_index":0,"kind":"data","monotonic_ns":309508919990000,"payload":{"event_type":"price_change","market":"0x0f70d07969bc69eaa97d0987de651885fdca02263688026aa11e7678af8f87aa","price_changes":[{"asset_id":"64053005904884194822931764831592250494815136296598204104072528088122126148949","best_ask":"0.67","best_bid":"0.66","hash":"a4870e7b1d65eecd530f7c847f620f9fe486d782","price":"0.66","side":"BUY","size":"355.68"},{"asset_id":"58313761654877669244690227616056238030136603415514645252000528337391143520538","best_ask":"0.34","best_bid":"0.33","hash":"ea8054e84d38927e3520d40ad373643067a2a427","price":"0.34","side":"SELL","size":"355.68"}],"timestamp":"1785207526042"},"payload_hash":"446d0478d28f93e0adf6a86653520c419334e05859887743dfacdf664f2521ec","raw_frame":"{\"market\":\"0x0f70d07969bc69eaa97d0987de651885fdca02263688026aa11e7678af8f87aa\", \"price_changes\":[{\"asset_id\":\"64053005904884194822931764831592250494815136296598204104072528088122126148949\", \"price\":\"0.66\", \"size\":\"355.68\", \"side\":\"BUY\", \"hash\":\"a4870e7b1d65eecd530f7c847f620f9fe486d782\", \"best_bid\":\"0.66\", \"best_ask\":\"0.67\"}, {\"asset_id\":\"58313761654877669244690227616056238030136603415514645252000528337391143520538\", \"price\":\"0.34\", \"size\":\"355.68\", \"side\":\"SELL\", \"hash\":\"ea8054e84d38927e3520d40ad373643067a2a427\", \"best_bid\":\"0.33\", \"best_ask\":\"0.34\"}], \"timestamp\":\"1785207526042\", \"event_type\":\"price_change\"}","received_at":"2026-07-28T02:58:45.902161Z","schema_version":"clob-market-ws.price_change.v1","sequence":null,"server_hash":null,"server_timestamp":"1785207526042","session_id":"5aad79be415c487c84df42bebd84ee93","source":"clob_market_ws"},"received_at":"2026-07-28T02:58:45.902161Z","record_id":"a65a30929ad1cdf611fe211fe7e2acbb3cb0c50e455f6b5240737f9dcbb9a449","schema_fingerprint":"4aa3821a28b0b7c2400bc59aba4bcc0a76e971dadd19610d3ad38c768e124dc7","schema_version":"edge-lab-recorder.raw.v1","sequence":null,"source":"clob_market_ws"}
{"event_at":"2026-07-28T02:58:46.042000Z","event_fingerprint":"55414d048ab5b810d57f6f1df137a325329421d7799f41c32cc00824057317b5","payload":{"connection_id":"955646bd8bf740759faf38750c0f263f","event_at":"2026-07-28T02:58:46.042000Z","event_type":"price_change","frame_hash":"f86c73b145183fe264b5fc8aa809348a5e91a51968c59fad6954fcc184112cca","frame_index":0,"kind":"data","monotonic_ns":309508923255916,"payload":{"event_type":"price_change","market":"0x0f70d07969bc69eaa97d0987de651885fdca02263688026aa11e7678af8f87aa","price_changes":[{"asset_id":"64053005904884194822931764831592250494815136296598204104072528088122126148949","best_ask":"0.67","best_bid":"0.66","hash":"7460ef5c2820ae592c002393b43ca6766d685437","price":"0.01","side":"BUY","size":"2690.52"},{"asset_id":"58313761654877669244690227616056238030136603415514645252000528337391143520538","best_ask":"0.34","best_bid":"0.33","hash":"64823ab72aa3b343b2c621b760d617f7e97fef81","price":"0.99","side":"SELL","size":"2690.52"}],"timestamp":"1785207526042"},"payload_hash":"e143acb4b6ee85d25209874cb1520cd6b2e481acdd2f4ca55f078d4729bc6f0f","raw_frame":"{\"market\":\"0x0f70d07969bc69eaa97d0987de651885fdca02263688026aa11e7678af8f87aa\", \"price_changes\":[{\"asset_id\":\"64053005904884194822931764831592250494815136296598204104072528088122126148949\", \"price\":\"0.01\", \"size\":\"2690.52\", \"side\":\"BUY\", \"hash\":\"7460ef5c2820ae592c002393b43ca6766d685437\", \"best_bid\":\"0.66\", \"best_ask\":\"0.67\"}, {\"asset_id\":\"58313761654877669244690227616056238030136603415514645252000528337391143520538\", \"price\":\"0.99\", \"size\":\"2690.52\", \"side\":\"SELL\", \"hash\":\"64823ab72aa3b343b2c621b760d617f7e97fef81\", \"best_bid\":\"0.33\", \"best_ask\":\"0.34\"}], \"timestamp\":\"1785207526042\", \"event_type\":\"price_change\"}","received_at":"2026-07-28T02:58:45.905426Z","schema_version":"clob-market-ws.price_change.v1","sequence":null,"server_hash":null,"server_timestamp":"1785207526042","session_id":"5aad79be415c487c84df42bebd84ee93","source":"clob_market_ws"},"received_at":"2026-07-28T02:58:45.905426Z","record_id":"45b90cba89d67a7b879b13529a90d141769975cc90bba701b22398f1cde1d2cd","schema_fingerprint":"4aa3821a28b0b7c2400bc59aba4bcc0a76e971dadd19610d3ad38c768e124dc7","schema_version":"edge-lab-recorder.raw.v1","sequence":null,"source":"clob_market_ws"}
{"event_at":"2026-07-28T02:58:46.047000Z","event_fingerprint":"64e6fec3d8105afde12a2a36f85b76782052b334dde3a41294c6c1196d62060f","payload":{"connection_id":"955646bd8bf740759faf38750c0f263f","event_at":"2026-07-28T02:58:46.047000Z","event_type":"price_change","frame_hash":"d9f01f8bb50f9267c1f55756dd28397875098b6eba2408bf95b32e6a3bb2d0b6","frame_index":0,"kind":"data","monotonic_ns":309508924785041,"payload":{"event_type":"price_change","market":"0x0f70d07969bc69eaa97d0987de651885fdca02263688026aa11e7678af8f87aa","price_changes":[{"asset_id":"58313761654877669244690227616056238030136603415514645252000528337391143520538","best_ask":"0.34","best_bid":"0.33","hash":"0c3769f1f328c4d9dc0a53e752fe8f1b7a668b27","price":"0.22","side":"BUY","size":"241.2"},{"asset_id":"64053005904884194822931764831592250494815136296598204104072528088122126148949","best_ask":"0.67","best_bid":"0.66","hash":"6a9b25baa0dad017329db6d79e64c223cafe1f13","price":"0.78","side":"SELL","size":"241.2"}],"timestamp":"1785207526047"},"payload_hash":"7ebdc0bf525909c3a8dbb673354b28f0c77c83e1721508ac61e3b13b6787d11f","raw_frame":"{\"market\":\"0x0f70d07969bc69eaa97d0987de651885fdca02263688026aa11e7678af8f87aa\", \"price_changes\":[{\"asset_id\":\"58313761654877669244690227616056238030136603415514645252000528337391143520538\", \"price\":\"0.22\", \"size\":\"241.2\", \"side\":\"BUY\", \"hash\":\"0c3769f1f328c4d9dc0a53e752fe8f1b7a668b27\", \"best_bid\":\"0.33\", \"best_ask\":\"0.34\"}, {\"asset_id\":\"64053005904884194822931764831592250494815136296598204104072528088122126148949\", \"price\":\"0.78\", \"size\":\"241.2\", \"side\":\"SELL\", \"hash\":\"6a9b25baa0dad017329db6d79e64c223cafe1f13\", \"best_bid\":\"0.66\", \"best_ask\":\"0.67\"}], \"timestamp\":\"1785207526047\", \"event_type\":\"price_change\"}","received_at":"2026-07-28T02:58:45.906957Z","schema_version":"clob-market-ws.price_change.v1","sequence":null,"server_hash":null,"server_timestamp":"1785207526047","session_id":"5aad79be415c487c84df42bebd84ee93","source":"clob_market_ws"},"received_at":"2026-07-28T02:58:45.906957Z","record_id":"9eb05f5f3e0360a769dea601f349431526ad801a9a6a8a3bee3fe86f5347c01c","schema_fingerprint":"4aa3821a28b0b7c2400bc59aba4bcc0a76e971dadd19610d3ad38c768e124dc7","schema_version":"edge-lab-recorder.raw.v1","sequence":null,"source":"clob_market_ws"}
{"event_at":"2026-07-28T02:58:46.048000Z","event_fingerprint":"691cd6c30d723a6f3dd6fff18289adbb2c875a620a6afd200ce61e98d502abe2","payload":{"connection_id":"955646bd8bf740759faf38750c0f263f","event_at":"2026-07-28T02:58:46.048000Z","event_type":"price_change","frame_hash":"dc7323b4ed4bdd6315961fc8143ec5e58f737d4ce4a6a8a39e8cc99cf0b68dc1","frame_index":0,"kind":"data","monotonic_ns":309508926419000,"payload":{"event_type":"price_change","market":"0x0f70d07969bc69eaa97d0987de651885fdca02263688026aa11e7678af8f87aa","price_changes":[{"asset_id":"58313761654877669244690227616056238030136603415514645252000528337391143520538","best_ask":"0.34","best_bid":"0.33","hash":"f03fccab7cddc922b803d1365ac95523e885c353","price":"0.24","side":"BUY","size":"209.6"},{"asset_id":"64053005904884194822931764831592250494815136296598204104072528088122126148949","best_ask":"0.67","best_bid":"0.66","hash":"bf47b33485c678e7d76990bf7e2bedac89314c5d","price":"0.76","side":"SELL","size":"209.6"}],"timestamp":"1785207526048"},"payload_hash":"21846ae80f242248574e3d3bcc0581a685d854d62356168ab6faa48a6626fed1","raw_frame":"{\"market\":\"0x0f70d07969bc69eaa97d0987de651885fdca02263688026aa11e7678af8f87aa\", \"price_changes\":[{\"asset_id\":\"58313761654877669244690227616056238030136603415514645252000528337391143520538\", \"price\":\"0.24\", \"size\":\"209.6\", \"side\":\"BUY\", \"hash\":\"f03fccab7cddc922b803d1365ac95523e885c353\", \"best_bid\":\"0.33\", \"best_ask\":\"0.34\"}, {\"asset_id\":\"64053005904884194822931764831592250494815136296598204104072528088122126148949\", \"price\":\"0.76\", \"size\":\"209.6\", \"side\":\"SELL\", \"hash\":\"bf47b33485c678e7d76990bf7e2bedac89314c5d\", \"best_bid\":\"0.66\", \"best_ask\":\"0.67\"}], \"timestamp\":\"1785207526048\", \"event_type\":\"price_change\"}","received_at":"2026-07-28T02:58:45.908590Z","schema_version":"clob-market-ws.price_change.v1","sequence":null,"server_hash":null,"server_timestamp":"1785207526048","session_id":"5aad79be415c487c84df42bebd84ee93","source":"clob_market_ws"},"received_at":"2026-07-28T02:58:45.908590Z","record_id":"24ef6d10f54adccdde5396e5611c5dc0b720eaf48d801ba276c1f5afdaaf2200","schema_fingerprint":"4aa3821a28b0b7c2400bc59aba4bcc0a76e971dadd19610d3ad38c768e124dc7","schema_version":"edge-lab-recorder.raw.v1","sequence":null,"source":"clob_market_ws"}
{"event_at":"2026-07-28T02:58:46.048000Z","event_fingerprint":"f217fe00aa881a309506e735c4d628dd76a702c055dc9776463f2873d4efb7aa","payload":{"connection_id":"955646bd8bf740759faf38750c0f263f","event_at":"2026-07-28T02:58:46.048000Z","event_type":"price_change","frame_hash":"b80e0576fda03fbe30d5450ad8add67bf55ac2a99cd7396c2366ec5484fdf873","frame_index":0,"kind":"data","monotonic_ns":309508928025791,"payload":{"event_type":"price_change","market":"0x0f70d07969bc69eaa97d0987de651885fdca02263688026aa11e7678af8f87aa","price_changes":[{"asset_id":"58313761654877669244690227616056238030136603415514645252000528337391143520538","best_ask":"0.34","best_bid":"0.33","hash":"08cb223e229bee1b5859aa2b2e74f669894730e8","price":"0.22","side":"BUY","size":"291.2"},{"asset_id":"64053005904884194822931764831592250494815136296598204104072528088122126148949","best_ask":"0.67","best_bid":"0.66","hash":"bf1bdca10825ed2b914aa5971fe67950f27b23d9","price":"0.78","side":"SELL","size":"291.2"}],"timestamp":"1785207526048"},"payload_hash":"63aaa2400499d9830e681873857caee675a9ccaa91dabc43fb200e1b7b73fee8","raw_frame":"{\"market\":\"0x0f70d07969bc69eaa97d0987de651885fdca02263688026aa11e7678af8f87aa\", \"price_changes\":[{\"asset_id\":\"58313761654877669244690227616056238030136603415514645252000528337391143520538\", \"price\":\"0.22\", \"size\":\"291.2\", \"side\":\"BUY\", \"hash\":\"08cb223e229bee1b5859aa2b2e74f669894730e8\", \"best_bid\":\"0.33\", \"best_ask\":\"0.34\"}, {\"asset_id\":\"64053005904884194822931764831592250494815136296598204104072528088122126148949\", \"price\":\"0.78\", \"size\":\"291.2\", \"side\":\"SELL\", \"hash\":\"bf1bdca10825ed2b914aa5971fe67950f27b23d9\", \"best_bid\":\"0.66\", \"best_ask\":\"0.67\"}], \"timestamp\":\"1785207526048\", \"event_type\":\"price_change\"}","received_at":"2026-07-28T02:58:45.910197Z","schema_version":"clob-market-ws.price_change.v1","sequence":null,"server_hash":null,"server_timestamp":"1785207526048","session_id":"5aad79be415c487c84df42bebd84ee93","source":"clob_market_ws"},"received_at":"2026-07-28T02:58:45.910197Z","record_id":"29e26de85fc513d5eb144e1053b1e9d4dc2369940c091df7eab4ec86e3fbfdf2","schema_fingerprint":"4aa3821a28b0b7c2400bc59aba4bcc0a76e971dadd19610d3ad38c768e124dc7","schema_version":"edge-lab-recorder.raw.v1","sequence":null,"source":"clob_market_ws"}
{"event_at":"2026-07-28T02:58:46.049000Z","event_fingerprint":"fc7bf5d734b32005ebd869b81dc8ab57c7a2d5132897e759ccbf6fc860a11245","payload":{"connection_id":"955646bd8bf740759faf38750c0f263f","event_at":"2026-07-28T02:58:46.049000Z","event_type":"price_change","frame_hash":"f857e6d11be0f0dbdeec7c824694664e450f951a7a4981b902c0dd52b9cdbe67","frame_index":0,"kind":"data","monotonic_ns":309508929476083,"payload":{"event_type":"price_change","market":"0x0f70d07969bc69eaa97d0987de651885fdca02263688026aa11e7678af8f87aa","price_changes":[{"asset_id":"58313761654877669244690227616056238030136603415514645252000528337391143520538","best_ask":"0.34","best_bid":"0.33","hash":"beb1491b57e09824136dec865f26088f60c004c9","price":"0.01","side":"BUY","size":"2571.24"},{"asset_id":"64053005904884194822931764831592250494815136296598204104072528088122126148949","best_ask":"0.67","best_bid":"0.66","hash":"d986a462bb6c6e3ca41f19d458bdb54330915a03","price":"0.99","side":"SELL","size":"2571.24"}],"timestamp":"1785207526049"},"payload_hash":"313d4316a3cf6be4d64621441fb37a7e9ab2ace360c2a9b1c6591113ea24535a","raw_frame":"{\"market\":\"0x0f70d07969bc69eaa97d0987de651885fdca02263688026aa11e7678af8f87aa\", \"price_changes\":[{\"asset_id\":\"58313761654877669244690227616056238030136603415514645252000528337391143520538\", \"price\":\"0.01\", \"size\":\"2571.24\", \"side\":\"BUY\", \"hash\":\"beb1491b57e09824136dec865f26088f60c004c9\", \"best_bid\":\"0.33\", \"best_ask\":\"0.34\"}, {\"asset_id\":\"64053005904884194822931764831592250494815136296598204104072528088122126148949\", \"price\":\"0.99\", \"size\":\"2571.24\", \"side\":\"SELL\", \"hash\":\"d986a462bb6c6e3ca41f19d458bdb54330915a03\", \"best_bid\":\"0.66\", \"best_ask\":\"0.67\"}], \"timestamp\":\"1785207526049\", \"event_type\":\"price_change\"}","received_at":"2026-07-28T02:58:45.911646Z","schema_version":"clob-market-ws.price_change.v1","sequence":null,"server_hash":null,"server_timestamp":"1785207526049","session_id":"5aad79be415c487c84df42bebd84ee93","source":"clob_market_ws"},"received_at":"2026-07-28T02:58:45.911646Z","record_id":"c235892446d551e69adc903e53620498ac00626f7b01a523ea895fa407ea2718","schema_fingerprint":"4aa3821a28b0b7c2400bc59aba4bcc0a76e971dadd19610d3ad38c768e124dc7","schema_version":"edge-lab-recorder.raw.v1","sequence":null,"source":"clob_market_ws"}
{"event_at":"2026-07-28T02:58:46.050000Z","event_fingerprint":"4dbf6234cc7089bc14c048cf70031cbf1023ded549e0de9c6ddd6eef12848bad","payload":{"connection_id":"955646bd8bf740759faf38750c0f263f","event_at":"2026-07-28T02:58:46.050000Z","event_type":"price_change","frame_hash":"f780675d87e2246a78b7ca0854069a3d2a3139303d938cb524ebbbf7b579e731","frame_index":0,"kind":"data","monotonic_ns":309508931097500,"payload":{"event_type":"price_change","market":"0x0f70d07969bc69eaa97d0987de651885fdca02263688026aa11e7678af8f87aa","price_changes":[{"asset_id":"58313761654877669244690227616056238030136603415514645252000528337391143520538","best_ask":"0.34","best_bid":"0.33","hash":"c464aac0b6d454c9f1b6f5d29251481913be459e","price":"0.23","side":"BUY","size":"232.4"},{"asset_id":"64053005904884194822931764831592250494815136296598204104072528088122126148949","best_ask":"0.67","best_bid":"0.66","hash":"575cdf04dc61a501fd02c80837d30b269dc5d2d4","price":"0.77","side":"SELL","size":"232.4"}],"timestamp":"1785207526050"},"payload_hash":"5f0d824da81265119d910e8425d25f3afc41ba3cdf862d3a7dbf1e19617b5251","raw_frame":"{\"market\":\"0x0f70d07969bc69eaa97d0987de651885fdca02263688026aa11e7678af8f87aa\", \"price_changes\":[{\"asset_id\":\"58313761654877669244690227616056238030136603415514645252000528337391143520538\", \"price\":\"0.23\", \"size\":\"232.4\", \"side\":\"BUY\", \"hash\":\"c464aac0b6d454c9f1b6f5d29251481913be459e\", \"best_bid\":\"0.33\", \"best_ask\":\"0.34\"}, {\"asset_id\":\"64053005904884194822931764831592250494815136296598204104072528088122126148949\", \"price\":\"0.77\", \"size\":\"232.4\", \"side\":\"SELL\", \"hash\":\"575cdf04dc61a501fd02c80837d30b269dc5d2d4\", \"best_bid\":\"0.66\", \"best_ask\":\"0.67\"}], \"timestamp\":\"1785207526050\", \"event_type\":\"price_change\"}","received_at":"2026-07-28T02:58:45.913269Z","schema_version":"clob-market-ws.price_change.v1","sequence":null,"server_hash":null,"server_timestamp":"1785207526050","session_id":"5aad79be415c487c84df42bebd84ee93","source":"clob_market_ws"},"received_at":"2026-07-28T02:58:45.913269Z","record_id":"115e3c95cadda8eaddaebb0cca9b1978151f5c53069e266063628ca328c42675","schema_fingerprint":"4aa3821a28b0b7c2400bc59aba4bcc0a76e971dadd19610d3ad38c768e124dc7","schema_version":"edge-lab-recorder.raw.v1","sequence":null,"source":"clob_market_ws"}
{"event_at":"2026-07-28T02:58:46.051000Z","event_fingerprint":"7aa242eb40b25b7ea958828c8c87493cfe89e3931c9d845ff77ec6f88375702a","payload":{"connection_id":"955646bd8bf740759faf38750c0f263f","event_at":"2026-07-28T02:58:46.051000Z","event_type":"price_change","frame_hash":"9a6d1a5a304d92508bf8eb2d62fa8a5a2827b278c73a186695325f5a1a91b64d","frame_index":0,"kind":"data","monotonic_ns":309508932609250,"payload":{"event_type":"price_change","market":"0x0f70d07969bc69eaa97d0987de651885fdca02263688026aa11e7678af8f87aa","price_changes":[{"asset_id":"64053005904884194822931764831592250494815136296598204104072528088122126148949","best_ask":"0.67","best_bid":"0.66","hash":"14e57b8c6398cff40af89916b269d91dd0603d2e","price":"0.65","side":"BUY","size":"162.91"},{"asset_id":"58313761654877669244690227616056238030136603415514645252000528337391143520538","best_ask":"0.34","best_bid":"0.33","hash":"e6cbbdda67b9176ffc220b18f9fee6e4f77bc5d0","price":"0.35","side":"SELL","size":"162.91"}],"timestamp":"1785207526051"},"payload_hash":"ef43243d46d374331faceb6af7beca9259470ff4bfdbb8f4f3ee22ed6b54f8be","raw_frame":"{\"market\":\"0x0f70d07969bc69eaa97d0987de651885fdca02263688026aa11e7678af8f87aa\", \"price_changes\":[{\"asset_id\":\"64053005904884194822931764831592250494815136296598204104072528088122126148949\", \"price\":\"0.65\", \"size\":\"162.91\", \"side\":\"BUY\", \"hash\":\"14e57b8c6398cff40af89916b269d91dd0603d2e\", \"best_bid\":\"0.66\", \"best_ask\":\"0.67\"}, {\"asset_id\":\"58313761654877669244690227616056238030136603415514645252000528337391143520538\", \"price\":\"0.35\", \"size\":\"162.91\", \"side\":\"SELL\", \"hash\":\"e6cbbdda67b9176ffc220b18f9fee6e4f77bc5d0\", \"best_bid\":\"0.33\", \"best_ask\":\"0.34\"}], \"timestamp\":\"1785207526051\", \"event_type\":\"price_change\"}","received_at":"2026-07-28T02:58:45.914781Z","schema_version":"clob-market-ws.price_change.v1","sequence":null,"server_hash":null,"server_timestamp":"1785207526051","session_id":"5aad79be415c487c84df42bebd84ee93","source":"clob_market_ws"},"received_at":"2026-07-28T02:58:45.914781Z","record_id":"c506beab4f06532f284a25eb44336f6b2ccfdf560ed5d2bd043aa479a0b52319","schema_fingerprint":"4aa3821a28b0b7c2400bc59aba4bcc0a76e971dadd19610d3ad38c768e124dc7","schema_version":"edge-lab-recorder.raw.v1","sequence":null,"source":"clob_market_ws"}
{"event_at":"2026-07-28T02:58:46.052000Z","event_fingerprint":"dae52b1671bdf4db6691aee6d83799e55bee892bbc070c8a9fa1da2719109893","payload":{"connection_id":"955646bd8bf740759faf38750c0f263f","event_at":"2026-07-28T02:58:46.052000Z","event_type":"price_change","frame_hash":"9caddcb9d499ce928e5845d44f0ab4dd52a3adf62509155b25a9aa34a3240b4d","frame_index":0,"kind":"data","monotonic_ns":309508934047958,"payload":{"event_type":"price_change","market":"0x0f70d07969bc69eaa97d0987de651885fdca02263688026aa11e7678af8f87aa","price_changes":[{"asset_id":"58313761654877669244690227616056238030136603415514645252000528337391143520538","best_ask":"0.34","best_bid":"0.33","hash":"91beb969949a9a43963e4642e54f9bcd37b20171","price":"0.22","side":"BUY","size":"341.2"},{"asset_id":"64053005904884194822931764831592250494815136296598204104072528088122126148949","best_ask":"0.67","best_bid":"0.66","hash":"40224cce4dfbaedf256370205c963e31abe76f22","price":"0.78","side":"SELL","size":"341.2"}],"timestamp":"1785207526052"},"payload_hash":"fa751b18623152dd0d62065e38d60ef7c64e0ca655f5440038f2c1d6c0f55630","raw_frame":"{\"market\":\"0x0f70d07969bc69eaa97d0987de651885fdca02263688026aa11e7678af8f87aa\", \"price_changes\":[{\"asset_id\":\"58313761654877669244690227616056238030136603415514645252000528337391143520538\", \"price\":\"0.22\", \"size\":\"341.2\", \"side\":\"BUY\", \"hash\":\"91beb969949a9a43963e4642e54f9bcd37b20171\", \"best_bid\":\"0.33\", \"best_ask\":\"0.34\"}, {\"asset_id\":\"64053005904884194822931764831592250494815136296598204104072528088122126148949\", \"price\":\"0.78\", \"size\":\"341.2\", \"side\":\"SELL\", \"hash\":\"40224cce4dfbaedf256370205c963e31abe76f22\", \"best_bid\":\"0.66\", \"best_ask\":\"0.67\"}], \"timestamp\":\"1785207526052\", \"event_type\":\"price_change\"}","received_at":"2026-07-28T02:58:45.916219Z","schema_version":"clob-market-ws.price_change.v1","sequence":null,"server_hash":null,"server_timestamp":"1785207526052","session_id":"5aad79be415c487c84df42bebd84ee93","source":"clob_market_ws"},"received_at":"2026-07-28T02:58:45.916219Z","record_id":"69d95c4206b300d3577f9186c1239b371acad295a5009561ee444ce55f3cac96","schema_fingerprint":"4aa3821a28b0b7c2400bc59aba4bcc0a76e971dadd19610d3ad38c768e124dc7","schema_version":"edge-lab-recorder.raw.v1","sequence":null,"source":"clob_market_ws"}
{"event_at":"2026-07-28T02:58:46.053000Z","event_fingerprint":"1dee7332c14841ce391788f0a7ec11866fabfe0e2a08bff215df8bd36491e2c0","payload":{"connection_id":"955646bd8bf740759faf38750c0f263f","event_at":"2026-07-28T02:58:46.053000Z","event_type":"price_change","frame_hash":"f886c0ae7db91ab8ce0f11e18d0a6a3ea4a97a072097012115ad82c7cb82c808","frame_index":0,"kind":"data","monotonic_ns":309508935522416,"payload":{"event_type":"price_change","market":"0x0f70d07969bc69eaa97d0987de651885fdca02263688026aa11e7678af8f87aa","price_changes":[{"asset_id":"64053005904884194822931764831592250494815136296598204104072528088122126148949","best_ask":"0.67","best_bid":"0.66","hash":"7eb90b5905a7728ba9b354271f8c7ce5bb82ea41","price":"0.57","side":"BUY","size":"244.9"},{"asset_id":"58313761654877669244690227616056238030136603415514645252000528337391143520538","best_ask":"0.34","best_bid":"0.33","hash":"d2e39e0c9caa998476ff5f4aa76b1e6299484d69","price":"0.43","side":"SELL","size":"244.9"}],"timestamp":"1785207526053"},"payload_hash":"70c058211e7a90b9942a0ed58aea1e596a72da72cfd380a844206020af23061f","raw_frame":"{\"market\":\"0x0f70d07969bc69eaa97d0987de651885fdca02263688026aa11e7678af8f87aa\", \"price_changes\":[{\"asset_id\":\"64053005904884194822931764831592250494815136296598204104072528088122126148949\", \"price\":\"0.57\", \"size\":\"244.9\", \"side\":\"BUY\", \"hash\":\"7eb90b5905a7728ba9b354271f8c7ce5bb82ea41\", \"best_bid\":\"0.66\", \"best_ask\":\"0.67\"}, {\"asset_id\":\"58313761654877669244690227616056238030136603415514645252000528337391143520538\", \"price\":\"0.43\", \"size\":\"244.9\", \"side\":\"SELL\", \"hash\":\"d2e39e0c9caa998476ff5f4aa76b1e6299484d69\", \"best_bid\":\"0.33\", \"best_ask\":\"0.34\"}], \"timestamp\":\"1785207526053\", \"event_type\":\"price_change\"}","received_at":"2026-07-28T02:58:45.917694Z","schema_version":"clob-market-ws.price_change.v1","sequence":null,"server_hash":null,"server_timestamp":"1785207526053","session_id":"5aad79be415c487c84df42bebd84ee93","source":"clob_market_ws"},"received_at":"2026-07-28T02:58:45.917694Z","record_id":"c053a95ff584c1e07f216c98ce3620e6be5ffa3d9681dd5fb4bf8ced011a8899","schema_fingerprint":"4aa3821a28b0b7c2400bc59aba4bcc0a76e971dadd19610d3ad38c768e124dc7","schema_version":"edge-lab-recorder.raw.v1","sequence":null,"source":"clob_market_ws"}
{"event_at":"2026-07-28T02:58:46.067000Z","event_fingerprint":"0bd9f30fa338fdad76559e4343a21071e90ffbd663cbe4c1b56dcf55b8694fb1","payload":{"connection_id":"955646bd8bf740759faf38750c0f263f","event_at":"2026-07-28T02:58:46.067000Z","event_type":"price_change","frame_hash":"23b8ca25f7a19d1884fdc3dd8b8ca6b7c89dd66db09d7b6696beefaaf7670461","frame_index":0,"kind":"data","monotonic_ns":309508945587125,"payload":{"event_type":"price_change","market":"0x0f70d07969bc69eaa97d0987de651885fdca02263688026aa11e7678af8f87aa","price_changes":[{"asset_id":"64053005904884194822931764831592250494815136296598204104072528088122126148949","best_ask":"0.67","best_bid":"0.66","hash":"71ae45d96dad1fd6f1335db123fd6bc13f46b09b","price":"0.63","side":"BUY","size":"196.9"},{"asset_id":"58313761654877669244690227616056238030136603415514645252000528337391143520538","best_ask":"0.34","best_bid":"0.33","hash":"68df256ca5a69c673e3d89b88a223af3cd960945","price":"0.37","side":"SELL","size":"196.9"}],"timestamp":"1785207526067"},"payload_hash":"f35f0cf57dbd915725b1eada88ede3b05399124c97ad5ddbee0a22cd0e286957","raw_frame":"{\"market\":\"0x0f70d07969bc69eaa97d0987de651885fdca02263688026aa11e7678af8f87aa\", \"price_changes\":[{\"asset_id\":\"64053005904884194822931764831592250494815136296598204104072528088122126148949\", \"price\":\"0.63\", \"size\":\"196.9\", \"side\":\"BUY\", \"hash\":\"71ae45d96dad1fd6f1335db123fd6bc13f46b09b\", \"best_bid\":\"0.66\", \"best_ask\":\"0.67\"}, {\"asset_id\":\"58313761654877669244690227616056238030136603415514645252000528337391143520538\", \"price\":\"0.37\", \"size\":\"196.9\", \"side\":\"SELL\", \"hash\":\"68df256ca5a69c673e3d89b88a223af3cd960945\", \"best_bid\":\"0.33\", \"best_ask\":\"0.34\"}], \"timestamp\":\"1785207526067\", \"event_type\":\"price_change\"}","received_at":"2026-07-28T02:58:45.927757Z","schema_version":"clob-market-ws.price_change.v1","sequence":null,"server_hash":null,"server_timestamp":"1785207526067","session_id":"5aad79be415c487c84df42bebd84ee93","source":"clob_market_ws"},"received_at":"2026-07-28T02:58:45.927757Z","record_id":"3732817df7dcd91454c148f503b93875ccf87a81b160d4e154b3034517af02dd","schema_fingerprint":"4aa3821a28b0b7c2400bc59aba4bcc0a76e971dadd19610d3ad38c768e124dc7","schema_version":"edge-lab-recorder.raw.v1","sequence":null,"source":"clob_market_ws"}
{"event_at":"2026-07-28T02:58:46.069000Z","event_fingerprint":"d13844fd6bca89c90614c6e6f92b54bddaf4404a2f0b33fc7de515b8583bab8b","payload":{"connection_id":"955646bd8bf740759faf38750c0f263f","event_at":"2026-07-28T02:58:46.069000Z","event_type":"price_change","frame_hash":"715c49c60b91ee52ed4411a0fe2c5cce289c0e64c17ce6f48cec8f181b029ac0","frame_index":0,"kind":"data","monotonic_ns":309508947138375,"payload":{"event_type":"price_change","market":"0x0f70d07969bc69eaa97d0987de651885fdca02263688026aa11e7678af8f87aa","price_changes":[{"asset_id":"58313761654877669244690227616056238030136603415514645252000528337391143520538","best_ask":"0.34","best_bid":"0.33","hash":"c694e94b387c1ddbd44e143cc839af16df4098a7","price":"0.24","side":"BUY","size":"195.3"},{"asset_id":"64053005904884194822931764831592250494815136296598204104072528088122126148949","best_ask":"0.67","best_bid":"0.66","hash":"8b6046700d26580990aeb61f0c72f68439b2fed0","price":"0.76","side":"SELL","size":"195.3"}],"timestamp":"1785207526069"},"payload_hash":"1f14cb6a5edd38aa17ac25e72478cf5c6b0408237f4e72dfd30364d3dc15313d","raw_frame":"{\"market\":\"0x0f70d07969bc69eaa97d0987de651885fdca02263688026aa11e7678af8f87aa\", \"price_changes\":[{\"asset_id\":\"58313761654877669244690227616056238030136603415514645252000528337391143520538\", \"price\":\"0.24\", \"size\":\"195.3\", \"side\":\"BUY\", \"hash\":\"c694e94b387c1ddbd44e143cc839af16df4098a7\", \"best_bid\":\"0.33\", \"best_ask\":\"0.34\"}, {\"asset_id\":\"64053005904884194822931764831592250494815136296598204104072528088122126148949\", \"price\":\"0.76\", \"size\":\"195.3\", \"side\":\"SELL\", \"hash\":\"8b6046700d26580990aeb61f0c72f68439b2fed0\", \"best_bid\":\"0.66\", \"best_ask\":\"0.67\"}], \"timestamp\":\"1785207526069\", \"event_type\":\"price_change\"}","received_at":"2026-07-28T02:58:45.929308Z","schema_version":"clob-market-ws.price_change.v1","sequence":null,"server_hash":null,"server_timestamp":"1785207526069","session_id":"5aad79be415c487c84df42bebd84ee93","source":"clob_market_ws"},"received_at":"2026-07-28T02:58:45.929308Z","record_id":"d06f034137ecc222a87a8158ae0b09f61f0a00d03477fb453c262132445cba99","schema_fingerprint":"4aa3821a28b0b7c2400bc59aba4bcc0a76e971dadd19610d3ad38c768e124dc7","schema_version":"edge-lab-recorder.raw.v1","sequence":null,"source":"clob_market_ws"}
{"event_at":"2026-07-28T02:58:46.071000Z","event_fingerprint":"f880d70a5427b13ded28e4545ef9bc231dac91fbd3fd8cfc2a28040c27c070d2","payload":{"connection_id":"955646bd8bf740759faf38750c0f263f","event_at":"2026-07-28T02:58:46.071000Z","event_type":"price_change","frame_hash":"1973a4de3cb0a9236fa6ee7a8c0e77fff98270323c60fb1d3ac9de2e41886d0c","frame_index":0,"kind":"data","monotonic_ns":309508948741375,"payload":{"event_type":"price_change","market":"0x0f70d07969bc69eaa97d0987de651885fdca02263688026aa11e7678af8f87aa","price_changes":[{"asset_id":"64053005904884194822931764831592250494815136296598204104072528088122126148949","best_ask":"0.67","best_bid":"0.66","hash":"62cf677e25f28945f66ec0f544840570ae838992","price":"0.65","side":"BUY","size":"152.91"},{"asset_id":"58313761654877669244690227616056238030136603415514645252000528337391143520538","best_ask":"0.34","best_bid":"0.33","hash":"a3916d6b432c3830573a53420f95fc3337729986","price":"0.35","side":"SELL","size":"152.91"}],"timestamp":"1785207526071"},"payload_hash":"b1bbc9c022234a29d2c64147bdc3d62101aa73272b5e7e2287e3dfa0d0fe00a2","raw_frame":"{\"market\":\"0x0f70d07969bc69eaa97d0987de651885fdca02263688026aa11e7678af8f87aa\", \"price_changes\":[{\"asset_id\":\"64053005904884194822931764831592250494815136296598204104072528088122126148949\", \"price\":\"0.65\", \"size\":\"152.91\", \"side\":\"BUY\", \"hash\":\"62cf677e25f28945f66ec0f544840570ae838992\", \"best_bid\":\"0.66\", \"best_ask\":\"0.67\"}, {\"asset_id\":\"58313761654877669244690227616056238030136603415514645252000528337391143520538\", \"price\":\"0.35\", \"size\":\"152.91\", \"side\":\"SELL\", \"hash\":\"a3916d6b432c3830573a53420f95fc3337729986\", \"best_bid\":\"0.33\", \"best_ask\":\"0.34\"}], \"timestamp\":\"1785207526071\", \"event_type\":\"price_change\"}","received_at":"2026-07-28T02:58:45.930912Z","schema_version":"clob-market-ws.price_change.v1","sequence":null,"server_hash":null,"server_timestamp":"1785207526071","session_id":"5aad79be415c487c84df42bebd84ee93","source":"clob_market_ws"},"received_at":"2026-07-28T02:58:45.930912Z","record_id":"9cf73a792681a5438f0adf60bfe1fbcbb120ce9879086fecb192a066406d0785","schema_fingerprint":"4aa3821a28b0b7c2400bc59aba4bcc0a76e971dadd19610d3ad38c768e124dc7","schema_version":"edge-lab-recorder.raw.v1","sequence":null,"source":"clob_market_ws"}
{"event_at":"2026-07-28T02:58:46.079000Z","event_fingerprint":"db0b0d5603c5d6060534ee9c6ca92f2d66dca1daa29705826d6da938bfeb05c7","payload":{"connection_id":"955646bd8bf740759faf38750c0f263f","event_at":"2026-07-28T02:58:46.079000Z","event_type":"price_change","frame_hash":"7a177900e2e2f375cbb22e39ca3dfae4686362608e607d97be09f6a862c3a92a","frame_index":0,"kind":"data","monotonic_ns":309508953758750,"payload":{"event_type":"price_change","market":"0x0f70d07969bc69eaa97d0987de651885fdca02263688026aa11e7678af8f87aa","price_changes":[{"asset_id":"64053005904884194822931764831592250494815136296598204104072528088122126148949","best_ask":"0.67","best_bid":"0.66","hash":"8f82b5a248a81de1958b60ae549641110c1f188a","price":"0.61","side":"BUY","size":"95.19"},{"asset_id":"58313761654877669244690227616056238030136603415514645252000528337391143520538","best_ask":"0.34","best_bid":"0.33","hash":"159a5a15ff92bab9a3fa51691398752c17a4024f","price":"0.39","side":"SELL","size":"95.19"}],"timestamp":"1785207526079"},"payload_hash":"a28f20a6234246bb6991dba51221c495d81ec0737d47834769cffd0a744a4247","raw_frame":"{\"market\":\"0x0f70d07969bc69eaa97d0987de651885fdca02263688026aa11e7678af8f87aa\", \"price_changes\":[{\"asset_id\":\"64053005904884194822931764831592250494815136296598204104072528088122126148949\", \"price\":\"0.61\", \"size\":\"95.19\", \"side\":\"BUY\", \"hash\":\"8f82b5a248a81de1958b60ae549641110c1f188a\", \"best_bid\":\"0.66\", \"best_ask\":\"0.67\"}, {\"asset_id\":\"58313761654877669244690227616056238030136603415514645252000528337391143520538\", \"price\":\"0.39\", \"size\":\"95.19\", \"side\":\"SELL\", \"hash\":\"159a5a15ff92bab9a3fa51691398752c17a4024f\", \"best_bid\":\"0.33\", \"best_ask\":\"0.34\"}], \"timestamp\":\"1785207526079\", \"event_type\":\"price_change\"}","received_at":"2026-07-28T02:58:45.935929Z","schema_version":"clob-market-ws.price_change.v1","sequence":null,"server_hash":null,"server_timestamp":"1785207526079","session_id":"5aad79be415c487c84df42bebd84ee93","source":"clob_market_ws"},"received_at":"2026-07-28T02:58:45.935929Z","record_id":"66c6367cea84a989a579a6a2cb6047ab462848a0b298470191b35cc0900b11bb","schema_fingerprint":"4aa3821a28b0b7c2400bc59aba4bcc0a76e971dadd19610d3ad38c768e124dc7","schema_version":"edge-lab-recorder.raw.v1","sequence":null,"source":"clob_market_ws"}
{"event_at":"2026-07-28T02:58:46.080000Z","event_fingerprint":"476c2e8c761252f2c1bf01e02590ce83cfa9e9d64214fd937cac91a00389d8db","payload":{"connection_id":"955646bd8bf740759faf38750c0f263f","event_at":"2026-07-28T02:58:46.080000Z","event_type":"price_change","frame_hash":"429232ac1829e29b0a1d7ec4721f637cdc959d038691041003e098ae182ca3a1","frame_index":0,"kind":"data","monotonic_ns":309508955327000,"payload":{"event_type":"price_change","market":"0x0f70d07969bc69eaa97d0987de651885fdca02263688026aa11e7678af8f87aa","price_changes":[{"asset_id":"64053005904884194822931764831592250494815136296598204104072528088122126148949","best_ask":"0.67","best_bid":"0.66","hash":"346c80706f72ac518d395d1147d31d439f448d6b","price":"0.64","side":"BUY","size":"178.58"},{"asset_id":"58313761654877669244690227616056238030136603415514645252000528337391143520538","best_ask":"0.34","best_bid":"0.33","hash":"f1b6a708d2dd9df54013208ed7bcb5d10d970bcb","price":"0.36","side":"SELL","size":"178.58"}],"timestamp":"1785207526080"},"payload_hash":"185c711ae8028dba37b76e118f67728349f09de5ef106a898568058804e9db1c","raw_frame":"{\"market\":\"0x0f70d07969bc69eaa97d0987de651885fdca02263688026aa11e7678af8f87aa\", \"price_changes\":[{\"asset_id\":\"64053005904884194822931764831592250494815136296598204104072528088122126148949\", \"price\":\"0.64\", \"size\":\"178.58\", \"side\":\"BUY\", \"hash\":\"346c80706f72ac518d395d1147d31d439f448d6b\", \"best_bid\":\"0.66\", \"best_ask\":\"0.67\"}, {\"asset_id\":\"58313761654877669244690227616056238030136603415514645252000528337391143520538\", \"price\":\"0.36\", \"size\":\"178.58\", \"side\":\"SELL\", \"hash\":\"f1b6a708d2dd9df54013208ed7bcb5d10d970bcb\", \"best_bid\":\"0.33\", \"best_ask\":\"0.34\"}], \"timestamp\":\"1785207526080\", \"event_type\":\"price_change\"}","received_at":"2026-07-28T02:58:45.937496Z","schema_version":"clob-market-ws.price_change.v1","sequence":null,"server_hash":null,"server_timestamp":"1785207526080","session_id":"5aad79be415c487c84df42bebd84ee93","source":"clob_market_ws"},"received_at":"2026-07-28T02:58:45.937496Z","record_id":"72010ddb261f7f698b688390f627b8a5b85774a796e1465fdb23875dfee352c6","schema_fingerprint":"4aa3821a28b0b7c2400bc59aba4bcc0a76e971dadd19610d3ad38c768e124dc7","schema_version":"edge-lab-recorder.raw.v1","sequence":null,"source":"clob_market_ws"}
{"event_at":"2026-07-28T02:58:46.080000Z","event_fingerprint":"75409a5787050f9c5a95ad37ecb67d4003acdd9fbb73eb4e0e80cfdb6313bd3f","payload":{"connection_id":"955646bd8bf740759faf38750c0f263f","event_at":"2026-07-28T02:58:46.080000Z","event_type":"price_change","frame_hash":"ccdfa46d881af3808a1bba6adc8dfdc7461c42bc0c8cedfa617f716ab03ae466","frame_index":0,"kind":"data","monotonic_ns":309508956945916,"payload":{"event_type":"price_change","market":"0x0f70d07969bc69eaa97d0987de651885fdca02263688026aa11e7678af8f87aa","price_changes":[{"asset_id":"64053005904884194822931764831592250494815136296598204104072528088122126148949","best_ask":"0.67","best_bid":"0.66","hash":"2989d28633444a81fa81aaeadcd0ea6bd9ce2c6a","price":"0.6","side":"BUY","size":"89.9"},{"asset_id":"58313761654877669244690227616056238030136603415514645252000528337391143520538","best_ask":"0.34","best_bid":"0.33","hash":"55e19cd6616fdae759d3f2db9742df270a1924d6","price":"0.4","side":"SELL","size":"89.9"}],"timestamp":"1785207526080"},"payload_hash":"0861bf369425f7fefef74a88f1209c7fcded197aff27f54576545ff31272c849","raw_frame":"{\"market\":\"0x0f70d07969bc69eaa97d0987de651885fdca02263688026aa11e7678af8f87aa\", \"price_changes\":[{\"asset_id\":\"64053005904884194822931764831592250494815136296598204104072528088122126148949\", \"price\":\"0.6\", \"size\":\"89.9\", \"side\":\"BUY\", \"hash\":\"2989d28633444a81fa81aaeadcd0ea6bd9ce2c6a\", \"best_bid\":\"0.66\", \"best_ask\":\"0.67\"}, {\"asset_id\":\"58313761654877669244690227616056238030136603415514645252000528337391143520538\", \"price\":\"0.4\", \"size\":\"89.9\", \"side\":\"SELL\", \"hash\":\"55e19cd6616fdae759d3f2db9742df270a1924d6\", \"best_bid\":\"0.33\", \"best_ask\":\"0.34\"}], \"timestamp\":\"1785207526080\", \"event_type\":\"price_change\"}","received_at":"2026-07-28T02:58:45.939117Z","schema_version":"clob-market-ws.price_change.v1","sequence":null,"server_hash":null,"server_timestamp":"1785207526080","session_id":"5aad79be415c487c84df42bebd84ee93","source":"clob_market_ws"},"received_at":"2026-07-28T02:58:45.939117Z","record_id":"671764d9f23407d5ed403f3e37e47672ffccbb51d55c0bdae4353328f91d5931","schema_fingerprint":"4aa3821a28b0b7c2400bc59aba4bcc0a76e971dadd19610d3ad38c768e124dc7","schema_version":"edge-lab-recorder.raw.v1","sequence":null,"source":"clob_market_ws"}
{"event_at":"2026-07-28T02:58:46.094000Z","event_fingerprint":"df868441353e177ac525dc9d80ea3864f72c0c1679dfe9b5fe1b614dfd633903","payload":{"connection_id":"955646bd8bf740759faf38750c0f263f","event_at":"2026-07-28T02:58:46.094000Z","event_type":"price_change","frame_hash":"1be7a2e77b2037a531adaf10db6cb4715e2f87d706548f898c6cc284bab16dd1","frame_index":0,"kind":"data","monotonic_ns":309508968164333,"payload":{"event_type":"price_change","market":"0x0f70d07969bc69eaa97d0987de651885fdca02263688026aa11e7678af8f87aa","price_changes":[{"asset_id":"64053005904884194822931764831592250494815136296598204104072528088122126148949","best_ask":"0.67","best_bid":"0.66","hash":"a4983dea4958f7646ad45588a8056fd4b10f153a","price":"0.03","side":"BUY","size":"545.8"},{"asset_id":"58313761654877669244690227616056238030136603415514645252000528337391143520538","best_ask":"0.34","best_bid":"0.33","hash":"6a2fcf6d3899d3c77b61b42779b0c01f6929e864","price":"0.97","side":"SELL","size":"545.8"}],"timestamp":"1785207526094"},"payload_hash":"731d6290063cc4c8abba3bbffc2b2dbe91b668aac1f7a132f090f321e6970770","raw_frame":"{\"market\":\"0x0f70d07969bc69eaa97d0987de651885fdca02263688026aa11e7678af8f87aa\", \"price_changes\":[{\"asset_id\":\"64053005904884194822931764831592250494815136296598204104072528088122126148949\", \"price\":\"0.03\", \"size\":\"545.8\", \"side\":\"BUY\", \"hash\":\"a4983dea4958f7646ad45588a8056fd4b10f153a\", \"best_bid\":\"0.66\", \"best_ask\":\"0.67\"}, {\"asset_id\":\"58313761654877669244690227616056238030136603415514645252000528337391143520538\", \"price\":\"0.97\", \"size\":\"545.8\", \"side\":\"SELL\", \"hash\":\"6a2fcf6d3899d3c77b61b42779b0c01f6929e864\", \"best_bid\":\"0.33\", \"best_ask\":\"0.34\"}], \"timestamp\":\"1785207526094\", \"event_type\":\"price_change\"}","received_at":"2026-07-28T02:58:45.950334Z","schema_version":"clob-market-ws.price_change.v1","sequence":null,"server_hash":null,"server_timestamp":"1785207526094","session_id":"5aad79be415c487c84df42bebd84ee93","source":"clob_market_ws"},"received_at":"2026-07-28T02:58:45.950334Z","record_id":"8ce5d6168132367422e28f31f3413b40df531261352a7137f57c0c2c83a51895","schema_fingerprint":"4aa3821a28b0b7c2400bc59aba4bcc0a76e971dadd19610d3ad38c768e124dc7","schema_version":"edge-lab-recorder.raw.v1","sequence":null,"source":"clob_market_ws"}
{"event_at":"2026-07-28T02:58:46.101000Z","event_fingerprint":"60be109d39f7a0dd621039597b590cf27794ec9696a7446445d6f584672b70fc","payload":{"connection_id":"955646bd8bf740759faf38750c0f263f","event_at":"2026-07-28T02:58:46.101000Z","event_type":"price_change","frame_hash":"5e4901d79c92aa8f1d0d162e3edd8193f032ca15c6758fcead30edc597f970c0","frame_index":0,"kind":"data","monotonic_ns":309508976280708,"payload":{"event_type":"price_change","market":"0x0f70d07969bc69eaa97d0987de651885fdca02263688026aa11e7678af8f87aa","price_changes":[{"asset_id":"58313761654877669244690227616056238030136603415514645252000528337391143520538","best_ask":"0.34","best_bid":"0.33","hash":"d4323a4d850a47f70435b258ae475b95e10494e3","price":"0.29","side":"BUY","size":"224.1"},{"asset_id":"64053005904884194822931764831592250494815136296598204104072528088122126148949","best_ask":"0.67","best_bid":"0.66","hash":"0922d0bb3116714220bca1f3f17b2d44d65d3581","price":"0.71","side":"SELL","size":"224.1"}],"timestamp":"1785207526101"},"payload_hash":"1c348e15e4d7cb55b65721bc382a2951ecec34d957df1f722e8c974dc39fc810","raw_frame":"{\"market\":\"0x0f70d07969bc69eaa97d0987de651885fdca02263688026aa11e7678af8f87aa\", \"price_changes\":[{\"asset_id\":\"58313761654877669244690227616056238030136603415514645252000528337391143520538\", \"price\":\"0.29\", \"size\":\"224.1\", \"side\":\"BUY\", \"hash\":\"d4323a4d850a47f70435b258ae475b95e10494e3\", \"best_bid\":\"0.33\", \"best_ask\":\"0.34\"}, {\"asset_id\":\"64053005904884194822931764831592250494815136296598204104072528088122126148949\", \"price\":\"0.71\", \"size\":\"224.1\", \"side\":\"SELL\", \"hash\":\"0922d0bb3116714220bca1f3f17b2d44d65d3581\", \"best_bid\":\"0.66\", \"best_ask\":\"0.67\"}], \"timestamp\":\"1785207526101\", \"event_type\":\"price_change\"}","received_at":"2026-07-28T02:58:45.958450Z","schema_version":"clob-market-ws.price_change.v1","sequence":null,"server_hash":null,"server_timestamp":"1785207526101","session_id":"5aad79be415c487c84df42bebd84ee93","source":"clob_market_ws"},"received_at":"2026-07-28T02:58:45.958450Z","record_id":"fa1c0f9e569a9ffc930420e1cfd9b9e9bde43abadc7025ec8179f70f69c1f5d4","schema_fingerprint":"4aa3821a28b0b7c2400bc59aba4bcc0a76e971dadd19610d3ad38c768e124dc7","schema_version":"edge-lab-recorder.raw.v1","sequence":null,"source":"clob_market_ws"}
{"event_at":"2026-07-28T02:58:46.102000Z","event_fingerprint":"135ba4fd5b9f01d6b13653381b6f9a80f512bcdf0a988aa16ca6f82fc7f154b7","payload":{"connection_id":"955646bd8bf740759faf38750c0f263f","event_at":"2026-07-28T02:58:46.102000Z","event_type":"price_change","frame_hash":"0da1a46d220ed258435684edea4cbc502752f13b9682407a71bf58f64c0375ad","frame_index":0,"kind":"data","monotonic_ns":309508977803125,"payload":{"event_type":"price_change","market":"0x0f70d07969bc69eaa97d0987de651885fdca02263688026aa11e7678af8f87aa","price_changes":[{"asset_id":"64053005904884194822931764831592250494815136296598204104072528088122126148949","best_ask":"0.67","best_bid":"0.66","hash":"d76e292f7c8968e7a889f28aaa14e4635e3cd0a8","price":"0.64","side":"BUY","size":"165.58"},{"asset_id":"58313761654877669244690227616056238030136603415514645252000528337391143520538","best_ask":"0.34","best_bid":"0.33","hash":"13bd91cc3de5d9cc340f70741a921437df02544a","price":"0.36","side":"SELL","size":"165.58"}],"timestamp":"1785207526102"},"payload_hash":"78066f4cfe5b9507fd434f3ec962fbe2c9fbc0da1ccc4f3a4578f09b4fc58306","raw_frame":"{\"market\":\"0x0f70d07969bc69eaa97d0987de651885fdca02263688026aa11e7678af8f87aa\", \"price_changes\":[{\"asset_id\":\"64053005904884194822931764831592250494815136296598204104072528088122126148949\", \"price\":\"0.64\", \"size\":\"165.58\", \"side\":\"BUY\", \"hash\":\"d76e292f7c8968e7a889f28aaa14e4635e3cd0a8\", \"best_bid\":\"0.66\", \"best_ask\":\"0.67\"}, {\"asset_id\":\"58313761654877669244690227616056238030136603415514645252000528337391143520538\", \"price\":\"0.36\", \"size\":\"165.58\", \"side\":\"SELL\", \"hash\":\"13bd91cc3de5d9cc340f70741a921437df02544a\", \"best_bid\":\"0.33\", \"best_ask\":\"0.34\"}], \"timestamp\":\"1785207526102\", \"event_type\":\"price_change\"}","received_at":"2026-07-28T02:58:45.959972Z","schema_version":"clob-market-ws.price_change.v1","sequence":null,"server_hash":null,"server_timestamp":"1785207526102","session_id":"5aad79be415c487c84df42bebd84ee93","source":"clob_market_ws"},"received_at":"2026-07-28T02:58:45.959972Z","record_id":"c9322f6b797639e0d17037c102ac7703353292bb1040e21d89b492537c74488a","schema_fingerprint":"4aa3821a28b0b7c2400bc59aba4bcc0a76e971dadd19610d3ad38c768e124dc7","schema_version":"edge-lab-recorder.raw.v1","sequence":null,"source":"clob_market_ws"}
{"event_at":"2026-07-28T02:58:46.103000Z","event_fingerprint":"704a44cf23ee8e32e5ff3372de3445c06593713f39acf6320e009ba4befc1890","payload":{"connection_id":"955646bd8bf740759faf38750c0f263f","event_at":"2026-07-28T02:58:46.103000Z","event_type":"price_change","frame_hash":"94f483e9f0197a54a2e4cf6d88fc1a2b6b38d281e44a96a28b13fc8501ebad9f","frame_index":0,"kind":"data","monotonic_ns":309508979502333,"payload":{"event_type":"price_change","market":"0x0f70d07969bc69eaa97d0987de651885fdca02263688026aa11e7678af8f87aa","price_changes":[{"asset_id":"58313761654877669244690227616056238030136603415514645252000528337391143520538","best_ask":"0.34","best_bid":"0.33","hash":"750989bd4914b3b37378b838da63518e32bd58e4","price":"0.36","side":"SELL","size":"152.58"},{"asset_id":"64053005904884194822931764831592250494815136296598204104072528088122126148949","best_ask":"0.67","best_bid":"0.66","hash":"5c42819491acac67ae763434fa5aebfab7b6b75a","price":"0.64","side":"BUY","size":"152.58"}],"timestamp":"1785207526103"},"payload_hash":"e205d5d24d249addcaba79411303cab7373919fbdd4cfb9f5e8b92936f27823e","raw_frame":"{\"market\":\"0x0f70d07969bc69eaa97d0987de651885fdca02263688026aa11e7678af8f87aa\", \"price_changes\":[{\"asset_id\":\"58313761654877669244690227616056238030136603415514645252000528337391143520538\", \"price\":\"0.36\", \"size\":\"152.58\", \"side\":\"SELL\", \"hash\":\"750989bd4914b3b37378b838da63518e32bd58e4\", \"best_bid\":\"0.33\", \"best_ask\":\"0.34\"}, {\"asset_id\":\"64053005904884194822931764831592250494815136296598204104072528088122126148949\", \"price\":\"0.64\", \"size\":\"152.58\", \"side\":\"BUY\", \"hash\":\"5c42819491acac67ae763434fa5aebfab7b6b75a\", \"best_bid\":\"0.66\", \"best_ask\":\"0.67\"}], \"timestamp\":\"1785207526103\", \"event_type\":\"price_change\"}","received_at":"2026-07-28T02:58:45.961671Z","schema_version":"clob-market-ws.price_change.v1","sequence":null,"server_hash":null,"server_timestamp":"1785207526103","session_id":"5aad79be415c487c84df42bebd84ee93","source":"clob_market_ws"},"received_at":"2026-07-28T02:58:45.961671Z","record_id":"1fa378c241f8862252f60726405b4f8bf70a7e8aa4978198052d23489b23155a","schema_fingerprint":"4aa3821a28b0b7c2400bc59aba4bcc0a76e971dadd19610d3ad38c768e124dc7","schema_version":"edge-lab-recorder.raw.v1","sequence":null,"source":"clob_market_ws"}
{"event_at":"2026-07-28T02:58:46.104000Z","event_fingerprint":"991cb3cabf3058ac137510e5bf8f4348e198d20adc79105148086eea684a2c5a","payload":{"connection_id":"955646bd8bf740759faf38750c0f263f","event_at":"2026-07-28T02:58:46.104000Z","event_type":"price_change","frame_hash":"09e9729c7b9f1892cfb3779435fe5c9b3ad4496b944198edd236969bea1fbc66","frame_index":0,"kind":"data","monotonic_ns":309508981181083,"payload":{"event_type":"price_change","market":"0x0f70d07969bc69eaa97d0987de651885fdca02263688026aa11e7678af8f87aa","price_changes":[{"asset_id":"58313761654877669244690227616056238030136603415514645252000528337391143520538","best_ask":"0.34","best_bid":"0.33","hash":"b9c740bb89599c955c85a2ea1d00655827274476","price":"0.23","side":"BUY","size":"217.7"},{"asset_id":"64053005904884194822931764831592250494815136296598204104072528088122126148949","best_ask":"0.67","best_bid":"0.66","hash":"ac740ad7af81cd5f5e425af282903c1aac0a6fa6","price":"0.77","side":"SELL","size":"217.7"}],"timestamp":"1785207526104"},"payload_hash":"058e30dd4cda352f5d1e672dd74a2049d7c2e2e73ea20a13c2d331708a045698","raw_frame":"{\"market\":\"0x0f70d07969bc69eaa97d0987de651885fdca02263688026aa11e7678af8f87aa\", \"price_changes\":[{\"asset_id\":\"58313761654877669244690227616056238030136603415514645252000528337391143520538\", \"price\":\"0.23\", \"size\":\"217.7\", \"side\":\"BUY\", \"hash\":\"b9c740bb89599c955c85a2ea1d00655827274476\", \"best_bid\":\"0.33\", \"best_ask\":\"0.34\"}, {\"asset_id\":\"64053005904884194822931764831592250494815136296598204104072528088122126148949\", \"price\":\"0.77\", \"size\":\"217.7\", \"side\":\"SELL\", \"hash\":\"ac740ad7af81cd5f5e425af282903c1aac0a6fa6\", \"best_bid\":\"0.66\", \"best_ask\":\"0.67\"}], \"timestamp\":\"1785207526104\", \"event_type\":\"price_change\"}","received_at":"2026-07-28T02:58:45.963349Z","schema_version":"clob-market-ws.price_change.v1","sequence":null,"server_hash":null,"server_timestamp":"1785207526104","session_id":"5aad79be415c487c84df42bebd84ee93","source":"clob_market_ws"},"received_at":"2026-07-28T02:58:45.963349Z","record_id":"b00426ab24914ff057e53d006b08f6baef940b7577a8fac030aaf037262e3f46","schema_fingerprint":"4aa3821a28b0b7c2400bc59aba4bcc0a76e971dadd19610d3ad38c768e124dc7","schema_version":"edge-lab-recorder.raw.v1","sequence":null,"source":"clob_market_ws"}
{"event_at":"2026-07-28T02:58:46.105000Z","event_fingerprint":"2902abd7254de688300825675149e0256f1367e3cb2f119db9e18784b8bc692a","payload":{"connection_id":"955646bd8bf740759faf38750c0f263f","event_at":"2026-07-28T02:58:46.105000Z","event_type":"price_change","frame_hash":"fe0b571dd873d6f00d45aede6ef256ba0a4b87fb57529e277aae8dfa783fe3c6","frame_index":0,"kind":"data","monotonic_ns":309508982715416,"payload":{"event_type":"price_change","market":"0x0f70d07969bc69eaa97d0987de651885fdca02263688026aa11e7678af8f87aa","price_changes":[{"asset_id":"64053005904884194822931764831592250494815136296598204104072528088122126148949","best_ask":"0.67","best_bid":"0.66","hash":"a5684f45531baaa793e56d7596919d494c0252ad","price":"0.63","side":"BUY","size":"191.9"},{"asset_id":"58313761654877669244690227616056238030136603415514645252000528337391143520538","best_ask":"0.34","best_bid":"0.33","hash":"c76207d759e5a715d67cd4598202fbed36ff572e","price":"0.37","side":"SELL","size":"191.9"}],"timestamp":"1785207526105"},"payload_hash":"6cbbc09b4e27c3a1e29fa5d80c70ac116df26217aded62b9f856817cb731f90a","raw_frame":"{\"market\":\"0x0f70d07969bc69eaa97d0987de651885fdca02263688026aa11e7678af8f87aa\", \"price_changes\":[{\"asset_id\":\"64053005904884194822931764831592250494815136296598204104072528088122126148949\", \"price\":\"0.63\", \"size\":\"191.9\", \"side\":\"BUY\", \"hash\":\"a5684f45531baaa793e56d7596919d494c0252ad\", \"best_bid\":\"0.66\", \"best_ask\":\"0.67\"}, {\"asset_id\":\"58313761654877669244690227616056238030136603415514645252000528337391143520538\", \"price\":\"0.37\", \"size\":\"191.9\", \"side\":\"SELL\", \"hash\":\"c76207d759e5a715d67cd4598202fbed36ff572e\", \"best_bid\":\"0.33\", \"best_ask\":\"0.34\"}], \"timestamp\":\"1785207526105\", \"event_type\":\"price_change\"}","received_at":"2026-07-28T02:58:45.964885Z","schema_version":"clob-market-ws.price_change.v1","sequence":null,"server_hash":null,"server_timestamp":"1785207526105","session_id":"5aad79be415c487c84df42bebd84ee93","source":"clob_market_ws"},"received_at":"2026-07-28T02:58:45.964885Z","record_id":"73fb41e8f5990e5d9da6e87fe6baac49234f3c08caa30f202dd903ad9c2870e2","schema_fingerprint":"4aa3821a28b0b7c2400bc59aba4bcc0a76e971dadd19610d3ad38c768e124dc7","schema_version":"edge-lab-recorder.raw.v1","sequence":null,"source":"clob_market_ws"}
{"event_at":"2026-07-28T02:58:46.108000Z","event_fingerprint":"68f68d95aee88363207fefb37adf4b2462345dc4161fb124079b2eb3a0870d7b","payload":{"connection_id":"955646bd8bf740759faf38750c0f263f","event_at":"2026-07-28T02:58:46.108000Z","event_type":"price_change","frame_hash":"b3178d3b0e133c64c3a020b25b4cc9c5a6c099df9a5298f32f76138f7bdf4eaa","frame_index":0,"kind":"data","monotonic_ns":309508984299166,"payload":{"event_type":"price_change","market":"0x0f70d07969bc69eaa97d0987de651885fdca02263688026aa11e7678af8f87aa","price_changes":[{"asset_id":"58313761654877669244690227616056238030136603415514645252000528337391143520538","best_ask":"0.34","best_bid":"0.33","hash":"c5445c9c2a33b085fb7ebaa1cccaa5959eab4009","price":"0.01","side":"BUY","size":"2566.24"},{"asset_id":"64053005904884194822931764831592250494815136296598204104072528088122126148949","best_ask":"0.67","best_bid":"0.66","hash":"4d77ca791445d12d05ec9343a375e425c7e0c099","price":"0.99","side":"SELL","size":"2566.24"}],"timestamp":"1785207526108"},"payload_hash":"ba3ce3e407ea80a55cd6ffeb8bcdc9f8efab07171453efb06ac354386e1b4486","raw_frame":"{\"market\":\"0x0f70d07969bc69eaa97d0987de651885fdca02263688026aa11e7678af8f87aa\", \"price_changes\":[{\"asset_id\":\"58313761654877669244690227616056238030136603415514645252000528337391143520538\", \"price\":\"0.01\", \"size\":\"2566.24\", \"side\":\"BUY\", \"hash\":\"c5445c9c2a33b085fb7ebaa1cccaa5959eab4009\", \"best_bid\":\"0.33\", \"best_ask\":\"0.34\"}, {\"asset_id\":\"64053005904884194822931764831592250494815136296598204104072528088122126148949\", \"price\":\"0.99\", \"size\":\"2566.24\", \"side\":\"SELL\", \"hash\":\"4d77ca791445d12d05ec9343a375e425c7e0c099\", \"best_bid\":\"0.66\", \"best_ask\":\"0.67\"}], \"timestamp\":\"1785207526108\", \"event_type\":\"price_change\"}","received_at":"2026-07-28T02:58:45.966470Z","schema_version":"clob-market-ws.price_change.v1","sequence":null,"server_hash":null,"server_timestamp":"1785207526108","session_id":"5aad79be415c487c84df42bebd84ee93","source":"clob_market_ws"},"received_at":"2026-07-28T02:58:45.966470Z","record_id":"dd56c4471331967a4551fc7e6f6492969754f832a3a2367ec0cabfc0859c71c9","schema_fingerprint":"4aa3821a28b0b7c2400bc59aba4bcc0a76e971dadd19610d3ad38c768e124dc7","schema_version":"edge-lab-recorder.raw.v1","sequence":null,"source":"clob_market_ws"}
{"event_at":"2026-07-28T02:58:46.121000Z","event_fingerprint":"e6929c544d965f26b1b0718dbe2a24865913efd3fb8154e6a2a925ab7bb07bd9","payload":{"connection_id":"955646bd8bf740759faf38750c0f263f","event_at":"2026-07-28T02:58:46.121000Z","event_type":"price_change","frame_hash":"bd8dddd8e151cb73903a09a1ef0475c9971abb6f31ddd399695f774fa9992e70","frame_index":0,"kind":"data","monotonic_ns":309508998578458,"payload":{"event_type":"price_change","market":"0x0f70d07969bc69eaa97d0987de651885fdca02263688026aa11e7678af8f87aa","price_changes":[{"asset_id":"58313761654877669244690227616056238030136603415514645252000528337391143520538","best_ask":"0.34","best_bid":"0.33","hash":"b506d226336342b864de580e66a107aae0a4db07","price":"0.23","side":"BUY","size":"202.7"},{"asset_id":"64053005904884194822931764831592250494815136296598204104072528088122126148949","best_ask":"0.67","best_bid":"0.66","hash":"4b7e4cc63c3d3a8ea0aae5b871b118d0e2461c18","price":"0.77","side":"SELL","size":"202.7"}],"timestamp":"1785207526121"},"payload_hash":"fa3c06b00cdac3cfbc8e26859f26cc562a8e34756ec32523ea2785afda18c0e7","raw_frame":"{\"market\":\"0x0f70d07969bc69eaa97d0987de651885fdca02263688026aa11e7678af8f87aa\", \"price_changes\":[{\"asset_id\":\"58313761654877669244690227616056238030136603415514645252000528337391143520538\", \"price\":\"0.23\", \"size\":\"202.7\", \"side\":\"BUY\", \"hash\":\"b506d226336342b864de580e66a107aae0a4db07\", \"best_bid\":\"0.33\", \"best_ask\":\"0.34\"}, {\"asset_id\":\"64053005904884194822931764831592250494815136296598204104072528088122126148949\", \"price\":\"0.77\", \"size\":\"202.7\", \"side\":\"SELL\", \"hash\":\"4b7e4cc63c3d3a8ea0aae5b871b118d0e2461c18\", \"best_bid\":\"0.66\", \"best_ask\":\"0.67\"}], \"timestamp\":\"1785207526121\", \"event_type\":\"price_change\"}","received_at":"2026-07-28T02:58:45.980747Z","schema_version":"clob-market-ws.price_change.v1","sequence":null,"server_hash":null,"server_timestamp":"1785207526121","session_id":"5aad79be415c487c84df42bebd84ee93","source":"clob_market_ws"},"received_at":"2026-07-28T02:58:45.980747Z","record_id":"8f5ec375b0388c663b3b99479a5b2216ca354ddf156096750176c8fc8b7c3fe4","schema_fingerprint":"4aa3821a28b0b7c2400bc59aba4bcc0a76e971dadd19610d3ad38c768e124dc7","schema_version":"edge-lab-recorder.raw.v1","sequence":null,"source":"clob_market_ws"}
{"event_at":"2026-07-28T02:58:46.124000Z","event_fingerprint":"6be405ace80043dd319f44c6891e9acaba8ab2942939cce5c3b6ffb1e60be4b2","payload":{"connection_id":"955646bd8bf740759faf38750c0f263f","event_at":"2026-07-28T02:58:46.124000Z","event_type":"price_change","frame_hash":"f2eab75b6eaace61fb693cf29c5ca820460df069a2aeb8c833ff643c1e7281be","frame_index":0,"kind":"data","monotonic_ns":309509000793750,"payload":{"event_type":"price_change","market":"0x0f70d07969bc69eaa97d0987de651885fdca02263688026aa11e7678af8f87aa","price_changes":[{"asset_id":"58313761654877669244690227616056238030136603415514645252000528337391143520538","best_ask":"0.34","best_bid":"0.33","hash":"7e26ecbfa17f8d8fd57ca79df8eec775305b07a4","price":"0.34","side":"SELL","size":"368.68"},{"asset_id":"64053005904884194822931764831592250494815136296598204104072528088122126148949","best_ask":"0.67","best_bid":"0.66","hash":"cf4a581866dead8e52a2fc5de7abd7a141e137ff","price":"0.66","side":"BUY","size":"368.68"}],"timestamp":"1785207526124"},"payload_hash":"d4416f05bab3106f44150edcb0fd6c1dff38657357e76e569171b267f6d060fb","raw_frame":"{\"market\":\"0x0f70d07969bc69eaa97d0987de651885fdca02263688026aa11e7678af8f87aa\", \"price_changes\":[{\"asset_id\":\"58313761654877669244690227616056238030136603415514645252000528337391143520538\", \"price\":\"0.34\", \"size\":\"368.68\", \"side\":\"SELL\", \"hash\":\"7e26ecbfa17f8d8fd57ca79df8eec775305b07a4\", \"best_bid\":\"0.33\", \"best_ask\":\"0.34\"}, {\"asset_id\":\"64053005904884194822931764831592250494815136296598204104072528088122126148949\", \"price\":\"0.66\", \"size\":\"368.68\", \"side\":\"BUY\", \"hash\":\"cf4a581866dead8e52a2fc5de7abd7a141e137ff\", \"best_bid\":\"0.66\", \"best_ask\":\"0.67\"}], \"timestamp\":\"1785207526124\", \"event_type\":\"price_change\"}","received_at":"2026-07-28T02:58:45.982963Z","schema_version":"clob-market-ws.price_change.v1","sequence":null,"server_hash":null,"server_timestamp":"1785207526124","session_id":"5aad79be415c487c84df42bebd84ee93","source":"clob_market_ws"},"received_at":"2026-07-28T02:58:45.982963Z","record_id":"cfe2ce579fd50f465482a46b595fc1ef3f180a1db036ec6847b67ebf17734db7","schema_fingerprint":"4aa3821a28b0b7c2400bc59aba4bcc0a76e971dadd19610d3ad38c768e124dc7","schema_version":"edge-lab-recorder.raw.v1","sequence":null,"source":"clob_market_ws"}
{"event_at":"2026-07-28T02:58:46.125000Z","event_fingerprint":"28eea69b4af0ea43ca2ed187a35c16c3fc1a1078561446a4fd4304ceeac315b7","payload":{"connection_id":"955646bd8bf740759faf38750c0f263f","event_at":"2026-07-28T02:58:46.125000Z","event_type":"price_change","frame_hash":"18837840483342fc18e2d564c075a1d54991ce55686e50c377ce39a10b2c347d","frame_index":0,"kind":"data","monotonic_ns":309509002403666,"payload":{"event_type":"price_change","market":"0x0f70d07969bc69eaa97d0987de651885fdca02263688026aa11e7678af8f87aa","price_changes":[{"asset_id":"58313761654877669244690227616056238030136603415514645252000528337391143520538","best_ask":"0.34","best_bid":"0.33","hash":"8b8112a9bece6e714ab8cbc738d8b63f897f03fb","price":"0.27","side":"BUY","size":"172.93"},{"asset_id":"64053005904884194822931764831592250494815136296598204104072528088122126148949","best_ask":"0.67","best_bid":"0.66","hash":"a4253fb9a0ffa43b6e1ed3ec69a2e6f98f2cfdfb","price":"0.73","side":"SELL","size":"172.93"}],"timestamp":"1785207526125"},"payload_hash":"5cf1404c3561e627ed5f82d50e59498b142da0f6d32f82c40a346ef676175118","raw_frame":"{\"market\":\"0x0f70d07969bc69eaa97d0987de651885fdca02263688026aa11e7678af8f87aa\", \"price_changes\":[{\"asset_id\":\"58313761654877669244690227616056238030136603415514645252000528337391143520538\", \"price\":\"0.27\", \"size\":\"172.93\", \"side\":\"BUY\", \"hash\":\"8b8112a9bece6e714ab8cbc738d8b63f897f03fb\", \"best_bid\":\"0.33\", \"best_ask\":\"0.34\"}, {\"asset_id\":\"64053005904884194822931764831592250494815136296598204104072528088122126148949\", \"price\":\"0.73\", \"size\":\"172.93\", \"side\":\"SELL\", \"hash\":\"a4253fb9a0ffa43b6e1ed3ec69a2e6f98f2cfdfb\", \"best_bid\":\"0.66\", \"best_ask\":\"0.67\"}], \"timestamp\":\"1785207526125\", \"event_type\":\"price_change\"}","received_at":"2026-07-28T02:58:45.984575Z","schema_version":"clob-market-ws.price_change.v1","sequence":null,"server_hash":null,"server_timestamp":"1785207526125","session_id":"5aad79be415c487c84df42bebd84ee93","source":"clob_market_ws"},"received_at":"2026-07-28T02:58:45.984575Z","record_id":"b0821adc2d43cf1adf748a302d74de7538421e396d12325aa8780da4e97935d0","schema_fingerprint":"4aa3821a28b0b7c2400bc59aba4bcc0a76e971dadd19610d3ad38c768e124dc7","schema_version":"edge-lab-recorder.raw.v1","sequence":null,"source":"clob_market_ws"}
{"event_at":"2026-07-28T02:58:46.126000Z","event_fingerprint":"a52b92e28b5bef6364d4a51e4ae1bcd73193b09a8c8345f5c526d762d96b8e71","payload":{"connection_id":"955646bd8bf740759faf38750c0f263f","event_at":"2026-07-28T02:58:46.126000Z","event_type":"price_change","frame_hash":"b562b0dc530a174f4c1442af09b9b5fd1f60210d24647bc34bc220e65f27473c","frame_index":0,"kind":"data","monotonic_ns":309509003896833,"payload":{"event_type":"price_change","market":"0x0f70d07969bc69eaa97d0987de651885fdca02263688026aa11e7678af8f87aa","price_changes":[{"asset_id":"58313761654877669244690227616056238030136603415514645252000528337391143520538","best_ask":"0.34","best_bid":"0.33","hash":"cbb10513605527f8a7f68aa71d8cde467e7e9409","price":"0.25","side":"BUY","size":"176.3"},{"asset_id":"64053005904884194822931764831592250494815136296598204104072528088122126148949","best_ask":"0.67","best_bid":"0.66","hash":"65623a5471deda559c83771c7b2836c4920a379f","price":"0.75","side":"SELL","size":"176.3"}],"timestamp":"1785207526126"},"payload_hash":"90391a3003b16df51e2775c0db022d129735951159c277024f7722f16ae12e3c","raw_frame":"{\"market\":\"0x0f70d07969bc69eaa97d0987de651885fdca02263688026aa11e7678af8f87aa\", \"price_changes\":[{\"asset_id\":\"58313761654877669244690227616056238030136603415514645252000528337391143520538\", \"price\":\"0.25\", \"size\":\"176.3\", \"side\":\"BUY\", \"hash\":\"cbb10513605527f8a7f68aa71d8cde467e7e9409\", \"best_bid\":\"0.33\", \"best_ask\":\"0.34\"}, {\"asset_id\":\"64053005904884194822931764831592250494815136296598204104072528088122126148949\", \"price\":\"0.75\", \"size\":\"176.3\", \"side\":\"SELL\", \"hash\":\"65623a5471deda559c83771c7b2836c4920a379f\", \"best_bid\":\"0.66\", \"best_ask\":\"0.67\"}], \"timestamp\":\"1785207526126\", \"event_type\":\"price_change\"}","received_at":"2026-07-28T02:58:45.986067Z","schema_version":"clob-market-ws.price_change.v1","sequence":null,"server_hash":null,"server_timestamp":"1785207526126","session_id":"5aad79be415c487c84df42bebd84ee93","source":"clob_market_ws"},"received_at":"2026-07-28T02:58:45.986067Z","record_id":"64faff494125a12b267f7ac84cb4a7a5c94d74fccccddcf7968de52efa6d8de8","schema_fingerprint":"4aa3821a28b0b7c2400bc59aba4bcc0a76e971dadd19610d3ad38c768e124dc7","schema_version":"edge-lab-recorder.raw.v1","sequence":null,"source":"clob_market_ws"}
{"event_at":"2026-07-28T02:58:46.126000Z","event_fingerprint":"14eece9792b14d8ae1fb046046366b225d6f961e4059d7ad5d76008e34a02553","payload":{"connection_id":"955646bd8bf740759faf38750c0f263f","event_at":"2026-07-28T02:58:46.126000Z","event_type":"price_change","frame_hash":"33134417b4341badc6e2dcdadd5032e3f7290f1613cf5b944b79aeb136ee2743","frame_index":0,"kind":"data","monotonic_ns":309509005494250,"payload":{"event_type":"price_change","market":"0x0f70d07969bc69eaa97d0987de651885fdca02263688026aa11e7678af8f87aa","price_changes":[{"asset_id":"64053005904884194822931764831592250494815136296598204104072528088122126148949","best_ask":"0.67","best_bid":"0.66","hash":"f227ee8d626c35c03211930bfd7cbbf7f44ba804","price":"0.57","side":"BUY","size":"269.9"},{"asset_id":"58313761654877669244690227616056238030136603415514645252000528337391143520538","best_ask":"0.34","best_bid":"0.33","hash":"33d8f4e9fec71bb09adc9c1bd812390850f8d5af","price":"0.43","side":"SELL","size":"269.9"}],"timestamp":"1785207526126"},"payload_hash":"be845930d3d26225b0a50455ea7778b9a02fc1fc4d7f03eb45547cafeff7d9ca","raw_frame":"{\"market\":\"0x0f70d07969bc69eaa97d0987de651885fdca02263688026aa11e7678af8f87aa\", \"price_changes\":[{\"asset_id\":\"64053005904884194822931764831592250494815136296598204104072528088122126148949\", \"price\":\"0.57\", \"size\":\"269.9\", \"side\":\"BUY\", \"hash\":\"f227ee8d626c35c03211930bfd7cbbf7f44ba804\", \"best_bid\":\"0.66\", \"best_ask\":\"0.67\"}, {\"asset_id\":\"58313761654877669244690227616056238030136603415514645252000528337391143520538\", \"price\":\"0.43\", \"size\":\"269.9\", \"side\":\"SELL\", \"hash\":\"33d8f4e9fec71bb09adc9c1bd812390850f8d5af\", \"best_bid\":\"0.33\", \"best_ask\":\"0.34\"}], \"timestamp\":\"1785207526126\", \"event_type\":\"price_change\"}","received_at":"2026-07-28T02:58:45.987665Z","schema_version":"clob-market-ws.price_change.v1","sequence":null,"server_hash":null,"server_timestamp":"1785207526126","session_id":"5aad79be415c487c84df42bebd84ee93","source":"clob_market_ws"},"received_at":"2026-07-28T02:58:45.987665Z","record_id":"0bd6768429a1761d0e95569f6558f50bc13c61d79483118458396fdc6c7091e2","schema_fingerprint":"4aa3821a28b0b7c2400bc59aba4bcc0a76e971dadd19610d3ad38c768e124dc7","schema_version":"edge-lab-recorder.raw.v1","sequence":null,"source":"clob_market_ws"}
{"event_at":"2026-07-28T02:58:46.128000Z","event_fingerprint":"3120bc56781db664d3ecba1f68428966a5547438fdb44d7fccd570d6dfd5d842","payload":{"connection_id":"955646bd8bf740759faf38750c0f263f","event_at":"2026-07-28T02:58:46.128000Z","event_type":"price_change","frame_hash":"a217b6a4413ef00a287132e68b22bbdd3640f9d161f423cd8004b6532112173e","frame_index":0,"kind":"data","monotonic_ns":309509006963750,"payload":{"event_type":"price_change","market":"0x0f70d07969bc69eaa97d0987de651885fdca02263688026aa11e7678af8f87aa","price_changes":[{"asset_id":"58313761654877669244690227616056238030136603415514645252000528337391143520538","best_ask":"0.34","best_bid":"0.33","hash":"954b8d95541afac625cefe18e2cbd21d3b4db579","price":"0.28","side":"BUY","size":"98.03"},{"asset_id":"64053005904884194822931764831592250494815136296598204104072528088122126148949","best_ask":"0.67","best_bid":"0.66","hash":"615eeec9626533d07251f8883e90f617039cd443","price":"0.72","side":"SELL","size":"98.03"}],"timestamp":"1785207526128"},"payload_hash":"d1bb39900b650bb684456fdf28d2b02fe7d671b5a26323187ed1fbbcc23131f2","raw_frame":"{\"market\":\"0x0f70d07969bc69eaa97d0987de651885fdca02263688026aa11e7678af8f87aa\", \"price_changes\":[{\"asset_id\":\"58313761654877669244690227616056238030136603415514645252000528337391143520538\", \"price\":\"0.28\", \"size\":\"98.03\", \"side\":\"BUY\", \"hash\":\"954b8d95541afac625cefe18e2cbd21d3b4db579\", \"best_bid\":\"0.33\", \"best_ask\":\"0.34\"}, {\"asset_id\":\"64053005904884194822931764831592250494815136296598204104072528088122126148949\", \"price\":\"0.72\", \"size\":\"98.03\", \"side\":\"SELL\", \"hash\":\"615eeec9626533d07251f8883e90f617039cd443\", \"best_bid\":\"0.66\", \"best_ask\":\"0.67\"}], \"timestamp\":\"1785207526128\", \"event_type\":\"price_change\"}","received_at":"2026-07-28T02:58:45.989133Z","schema_version":"clob-market-ws.price_change.v1","sequence":null,"server_hash":null,"server_timestamp":"1785207526128","session_id":"5aad79be415c487c84df42bebd84ee93","source":"clob_market_ws"},"received_at":"2026-07-28T02:58:45.989133Z","record_id":"df0d3c5ce5021c3ef7db3c8e80251821e8de3a1eae59bf52de3f4db1f00d0479","schema_fingerprint":"4aa3821a28b0b7c2400bc59aba4bcc0a76e971dadd19610d3ad38c768e124dc7","schema_version":"edge-lab-recorder.raw.v1","sequence":null,"source":"clob_market_ws"}
{"event_at":"2026-07-28T02:58:46.132000Z","event_fingerprint":"684cd81eecbffe3fd0f3c5a280e056d11a31bfa91a19c7a2a6a7bf1309104470","payload":{"connection_id":"955646bd8bf740759faf38750c0f263f","event_at":"2026-07-28T02:58:46.132000Z","event_type":"price_change","frame_hash":"b8e5a6b08c417a955fc97e74275212480cea99947a59617833f64c58589f6006","frame_index":0,"kind":"data","monotonic_ns":309509008566083,"payload":{"event_type":"price_change","market":"0x0f70d07969bc69eaa97d0987de651885fdca02263688026aa11e7678af8f87aa","price_changes":[{"asset_id":"64053005904884194822931764831592250494815136296598204104072528088122126148949","best_ask":"0.67","best_bid":"0.66","hash":"47fa7be5e51959f4441bca515faa54f9312b85f8","price":"0.58","side":"BUY","size":"125.19"},{"asset_id":"58313761654877669244690227616056238030136603415514645252000528337391143520538","best_ask":"0.34","best_bid":"0.33","hash":"463fca9d260d9823ad222f2678f15666430e84f4","price":"0.42","side":"SELL","size":"125.19"}],"timestamp":"1785207526132"},"payload_hash":"eaadf6944dacd6987a4ddf8a97b2430454001f8e3c0b37ed70a1e743be9da245","raw_frame":"{\"market\":\"0x0f70d07969bc69eaa97d0987de651885fdca02263688026aa11e7678af8f87aa\", \"price_changes\":[{\"asset_id\":\"64053005904884194822931764831592250494815136296598204104072528088122126148949\", \"price\":\"0.58\", \"size\":\"125.19\", \"side\":\"BUY\", \"hash\":\"47fa7be5e51959f4441bca515faa54f9312b85f8\", \"best_bid\":\"0.66\", \"best_ask\":\"0.67\"}, {\"asset_id\":\"58313761654877669244690227616056238030136603415514645252000528337391143520538\", \"price\":\"0.42\", \"size\":\"125.19\", \"side\":\"SELL\", \"hash\":\"463fca9d260d9823ad222f2678f15666430e84f4\", \"best_bid\":\"0.33\", \"best_ask\":\"0.34\"}], \"timestamp\":\"1785207526132\", \"event_type\":\"price_change\"}","received_at":"2026-07-28T02:58:45.990737Z","schema_version":"clob-market-ws.price_change.v1","sequence":null,"server_hash":null,"server_timestamp":"1785207526132","session_id":"5aad79be415c487c84df42bebd84ee93","source":"clob_market_ws"},"received_at":"2026-07-28T02:58:45.990737Z","record_id":"e2b45d87dbd53add763b421fcb8cb93f7eb8f170f38f988e75f33257b9a1c0cb","schema_fingerprint":"4aa3821a28b0b7c2400bc59aba4bcc0a76e971dadd19610d3ad38c768e124dc7","schema_version":"edge-lab-recorder.raw.v1","sequence":null,"source":"clob_market_ws"}
{"event_at":"2026-07-28T02:58:46.132000Z","event_fingerprint":"6861df24f97f8bb97d66a67b358ef69bc04b000df5cb603def4487063f59fce1","payload":{"connection_id":"955646bd8bf740759faf38750c0f263f","event_at":"2026-07-28T02:58:46.132000Z","event_type":"price_change","frame_hash":"128f952258e362263c56bf9505b45646beab574757c866c2455898d709a7943b","frame_index":0,"kind":"data","monotonic_ns":309509010035500,"payload":{"event_type":"price_change","market":"0x0f70d07969bc69eaa97d0987de651885fdca02263688026aa11e7678af8f87aa","price_changes":[{"asset_id":"58313761654877669244690227616056238030136603415514645252000528337391143520538","best_ask":"0.34","best_bid":"0.33","hash":"13edd6ebf13f035105fa1f7bd20d67b8f55f27a1","price":"0.32","side":"BUY","size":"0"},{"asset_id":"64053005904884194822931764831592250494815136296598204104072528088122126148949","best_ask":"0.67","best_bid":"0.66","hash":"320a97678e732de1b464cff98228ddaa9a58dd0d","price":"0.68","side":"SELL","size":"0"}],"timestamp":"1785207526132"},"payload_hash":"34f4a62b736fa278078e82b522aca04cc35b2de148a899cf64b5762bd3b2a62f","raw_frame":"{\"market\":\"0x0f70d07969bc69eaa97d0987de651885fdca02263688026aa11e7678af8f87aa\", \"price_changes\":[{\"asset_id\":\"58313761654877669244690227616056238030136603415514645252000528337391143520538\", \"price\":\"0.32\", \"size\":\"0\", \"side\":\"BUY\", \"hash\":\"13edd6ebf13f035105fa1f7bd20d67b8f55f27a1\", \"best_bid\":\"0.33\", \"best_ask\":\"0.34\"}, {\"asset_id\":\"64053005904884194822931764831592250494815136296598204104072528088122126148949\", \"price\":\"0.68\", \"size\":\"0\", \"side\":\"SELL\", \"hash\":\"320a97678e732de1b464cff98228ddaa9a58dd0d\", \"best_bid\":\"0.66\", \"best_ask\":\"0.67\"}], \"timestamp\":\"1785207526132\", \"event_type\":\"price_change\"}","received_at":"2026-07-28T02:58:45.992206Z","schema_version":"clob-market-ws.price_change.v1","sequence":null,"server_hash":null,"server_timestamp":"1785207526132","session_id":"5aad79be415c487c84df42bebd84ee93","source":"clob_market_ws"},"received_at":"2026-07-28T02:58:45.992206Z","record_id":"b0e3ce623e1897879e1f69e4d5c6d9f642f487f8f9b293e7325b89bab1457864","schema_fingerprint":"4aa3821a28b0b7c2400bc59aba4bcc0a76e971dadd19610d3ad38c768e124dc7","schema_version":"edge-lab-recorder.raw.v1","sequence":null,"source":"clob_market_ws"}
{"event_at":"2026-07-28T02:58:46.133000Z","event_fingerprint":"f23a697ff453c8160ebd0c20bed744e8c84e387f9c5f0a71683d20010bf069fb","payload":{"connection_id":"955646bd8bf740759faf38750c0f263f","event_at":"2026-07-28T02:58:46.133000Z","event_type":"price_change","frame_hash":"ecb8eadf9138ca47700caad1a0fa8d15d497233b63761c5a013d315758212223","frame_index":0,"kind":"data","monotonic_ns":309509011664833,"payload":{"event_type":"price_change","market":"0x0f70d07969bc69eaa97d0987de651885fdca02263688026aa11e7678af8f87aa","price_changes":[{"asset_id":"58313761654877669244690227616056238030136603415514645252000528337391143520538","best_ask":"0.34","best_bid":"0.33","hash":"6d8a15e780c826fe27ab9cac9614031601e0fd11","price":"0.28","side":"BUY","size":"155.03"},{"asset_id":"64053005904884194822931764831592250494815136296598204104072528088122126148949","best_ask":"0.67","best_bid":"0.66","hash":"df1587e49ff0f21540ea51c9018fa10d97eb5198","price":"0.72","side":"SELL","size":"155.03"}],"timestamp":"1785207526133"},"payload_hash":"b78b8ac24336ef2cad7b6a121519137668e6ce332dcc54620423200d16b64b97","raw_frame":"{\"market\":\"0x0f70d07969bc69eaa97d0987de651885fdca02263688026aa11e7678af8f87aa\", \"price_changes\":[{\"asset_id\":\"58313761654877669244690227616056238030136603415514645252000528337391143520538\", \"price\":\"0.28\", \"size\":\"155.03\", \"side\":\"BUY\", \"hash\":\"6d8a15e780c826fe27ab9cac9614031601e0fd11\", \"best_bid\":\"0.33\", \"best_ask\":\"0.34\"}, {\"asset_id\":\"64053005904884194822931764831592250494815136296598204104072528088122126148949\", \"price\":\"0.72\", \"size\":\"155.03\", \"side\":\"SELL\", \"hash\":\"df1587e49ff0f21540ea51c9018fa10d97eb5198\", \"best_bid\":\"0.66\", \"best_ask\":\"0.67\"}], \"timestamp\":\"1785207526133\", \"event_type\":\"price_change\"}","received_at":"2026-07-28T02:58:45.993835Z","schema_version":"clob-market-ws.price_change.v1","sequence":null,"server_hash":null,"server_timestamp":"1785207526133","session_id":"5aad79be415c487c84df42bebd84ee93","source":"clob_market_ws"},"received_at":"2026-07-28T02:58:45.993835Z","record_id":"602bc0d3880b3b279ab38682d6878b6a1aa82342da4f7f331fcda41ae18be188","schema_fingerprint":"4aa3821a28b0b7c2400bc59aba4bcc0a76e971dadd19610d3ad38c768e124dc7","schema_version":"edge-lab-recorder.raw.v1","sequence":null,"source":"clob_market_ws"}
