{"event_at":"2026-07-28T02:57:26.889000Z","event_fingerprint":"e7ce72824b7096627a735c9853442a54262f6b75d6982c0dc3b8685e6b67afe0","payload":{"connection_id":"955646bd8bf740759faf38750c0f263f","event_at":"2026-07-28T02:57:26.889000Z","event_type":"price_change","frame_hash":"78be76d1f2d28d04748272396d3b522e29740e2a1a6ce08c5920704682db8698","frame_index":0,"kind":"data","monotonic_ns":309430263355208,"payload":{"event_type":"price_change","market":"0x0f70d07969bc69eaa97d0987de651885fdca02263688026aa11e7678af8f87aa","price_changes":[{"asset_id":"64053005904884194822931764831592250494815136296598204104072528088122126148949","best_ask":"0.53","best_bid":"0.52","hash":"75a5f7a8f8c0b1e3efa817112ce63910df07e82d","price":"0.34","side":"BUY","size":"208.39"},{"asset_id":"58313761654877669244690227616056238030136603415514645252000528337391143520538","best_ask":"0.48","best_bid":"0.47","hash":"ea740ef4f931981569bd765875eb0131490c0abf","price":"0.66","side":"SELL","size":"208.39"}],"timestamp":"1785207446889"},"payload_hash":"fdf6ccbd981c89ef61a9ee8b80b68a3b3f4f1faab732f6ae136251999d6b572f","raw_frame":"{\"market\":\"0x0f70d07969bc69eaa97d0987de651885fdca02263688026aa11e7678af8f87aa\", \"price_changes\":[{\"asset_id\":\"64053005904884194822931764831592250494815136296598204104072528088122126148949\", \"price\":\"0.34\", \"size\":\"208.39\", \"side\":\"BUY\", \"hash\":\"75a5f7a8f8c0b1e3efa817112ce63910df07e82d\", \"best_bid\":\"0.52\", \"best_ask\":\"0.53\"}, {\"asset_id\":\"58313761654877669244690227616056238030136603415514645252000528337391143520538\", \"price\":\"0.66\", \"size\":\"208.39\", \"side\":\"SELL\", \"hash\":\"ea740ef4f931981569bd765875eb0131490c0abf\", \"best_bid\":\"0.47\", \"best_ask\":\"0.48\"}], \"timestamp\":\"1785207446889\", \"event_type\":\"price_change\"}","received_at":"2026-07-28T02:57:27.246092Z","schema_version":"clob-market-ws.price_change.v1","sequence":null,"server_hash":null,"server_timestamp":"1785207446889","session_id":"5aad79be415c487c84df42bebd84ee93","source":"clob_market_ws"},"received_at":"2026-07-28T02:57:27.246092Z","record_id":"0f774bc22901d1ec9d091522b19642fdebe4dd13b9cc10840656e1ae5bbe4f2f","schema_fingerprint":"4aa3821a28b0b7c2400bc59aba4bcc0a76e971dadd19610d3ad38c768e124dc7","schema_version":"edge-lab-recorder.raw.v1","sequence":null,"source":"clob_market_ws"}
{"event_at":"2026-07-28T02:57:26.892000Z","event_fingerprint":"2e843de34e264e6f7c1feb2a538d5ed1c872573b19542a85880caded17331cbf","payload":{"connection_id":"955646bd8bf740759faf38750c0f263f","event_at":"2026-07-28T02:57:26.892000Z","event_type":"price_change","frame_hash":"3ebbe7f0dbd1e1ca78f83cdca2323c9316acc16967e54d31075b0a3a8cc00bf8","frame_index":0,"kind":"data","monotonic_ns":309430265700875,"payload":{"event_type":"price_change","market":"0x0f70d07969bc69eaa97d0987de651885fdca02263688026aa11e7678af8f87aa","price_changes":[{"asset_id":"64053005904884194822931764831592250494815136296598204104072528088122126148949","best_ask":"0.53","best_bid":"0.52","hash":"da82d766c3265022092aae261b0b2ddecaf7c05c","price":"0.51","side":"BUY","size":"225.1"},{"asset_id":"58313761654877669244690227616056238030136603415514645252000528337391143520538","best_ask":"0.48","best_bid":"0.47","hash":"80fd0a2e891bee171ce8583b5e73fbc1b83c8a8e","price":"0.49","side":"SELL","size":"225.1"}],"timestamp":"1785207446892"},"payload_hash":"1397cd6cc64959fc2e505b84f9a0fa1473fe8f90c1125645065aafebe6982913","raw_frame":"{\"market\":\"0x0f70d07969bc69eaa97d0987de651885fdca02263688026aa11e7678af8f87aa\", \"price_changes\":[{\"asset_id\":\"64053005904884194822931764831592250494815136296598204104072528088122126148949\", \"price\":\"0.51\", \"size\":\"225.1\", \"side\":\"BUY\", \"hash\":\"da82d766c3265022092aae261b0b2ddecaf7c05c\", \"best_bid\":\"0.52\", \"best_ask\":\"0.53\"}, {\"asset_id\":\"58313761654877669244690227616056238030136603415514645252000528337391143520538\", \"price\":\"0.49\", \"size\":\"225.1\", \"side\":\"SELL\", \"hash\":\"80fd0a2e891bee171ce8583b5e73fbc1b83c8a8e\", \"best_bid\":\"0.47\", \"best_ask\":\"0.48\"}], \"timestamp\":\"1785207446892\", \"event_type\":\"price_change\"}","received_at":"2026-07-28T02:57:27.248440Z","schema_version":"clob-market-ws.price_change.v1","sequence":null,"server_hash":null,"server_timestamp":"1785207446892","session_id":"5aad79be415c487c84df42bebd84ee93","source":"clob_market_ws"},"received_at":"2026-07-28T02:57:27.248440Z","record_id":"9036882447f29e5083770d6399de67f79ad51157dbde5c8132dd44aee9e7e859","schema_fingerprint":"4aa3821a28b0b7c2400bc59aba4bcc0a76e971dadd19610d3ad38c768e124dc7","schema_version":"edge-lab-recorder.raw.v1","sequence":null,"source":"clob_market_ws"}
{"event_at":"2026-07-28T02:57:26.895000Z","event_fingerprint":"d37fb56be0c3dcfc6c649bf7af49ca230cbe8123c3ba8152ef090a3186fe724c","payload":{"connection_id":"955646bd8bf740759faf38750c0f263f","event_at":"2026-07-28T02:57:26.895000Z","event_type":"price_change","frame_hash":"dbf1c5457dbde32ca3f244dd4b6bb58f214e314ec5addc45b8c5125be90bb692","frame_index":0,"kind":"data","monotonic_ns":309430267274666,"payload":{"event_type":"price_change","market":"0x0f70d07969bc69eaa97d0987de651885fdca02263688026aa11e7678af8f87aa","price_changes":[{"asset_id":"64053005904884194822931764831592250494815136296598204104072528088122126148949","best_ask":"0.53","best_bid":"0.52","hash":"30eae96f8144e697f237028c2924b228945987e7","price":"0.52","side":"BUY","size":"199.1"},{"asset_id":"58313761654877669244690227616056238030136603415514645252000528337391143520538","best_ask":"0.48","best_bid":"0.47","hash":"9c6a6ba728aae77ef0009258c572c20bdf6e2b0b","price":"0.48","side":"SELL","size":"199.1"}],"timestamp":"1785207446895"},"payload_hash":"a75952b8843888980c0f8c58ecd8f6a5422b0a836da62c5fc163e7bba6b24357","raw_frame":"{\"market\":\"0x0f70d07969bc69eaa97d0987de651885fdca02263688026aa11e7678af8f87aa\", \"price_changes\":[{\"asset_id\":\"64053005904884194822931764831592250494815136296598204104072528088122126148949\", \"price\":\"0.52\", \"size\":\"199.1\", \"side\":\"BUY\", \"hash\":\"30eae96f8144e697f237028c2924b228945987e7\", \"best_bid\":\"0.52\", \"best_ask\":\"0.53\"}, {\"asset_id\":\"58313761654877669244690227616056238030136603415514645252000528337391143520538\", \"price\":\"0.48\", \"size\":\"199.1\", \"side\":\"SELL\", \"hash\":\"9c6a6ba728aae77ef0009258c572c20bdf6e2b0b\", \"best_bid\":\"0.47\", \"best_ask\":\"0.48\"}], \"timestamp\":\"1785207446895\", \"event_type\":\"price_change\"}","received_at":"2026-07-28T02:57:27.250012Z","schema_version":"clob-market-ws.price_change.v1","sequence":null,"server_hash":null,"server_timestamp":"1785207446895","session_id":"5aad79be415c487c84df42bebd84ee93","source":"clob_market_ws"},"received_at":"2026-07-28T02:57:27.250012Z","record_id":"0896d366cd889e61b05cb235e4fc42ae46404d3ddd14c14006fe4c72407ca2e7","schema_fingerprint":"4aa3821a28b0b7c2400bc59aba4bcc0a76e971dadd19610d3ad38c768e124dc7","schema_version":"edge-lab-recorder.raw.v1","sequence":null,"source":"clob_market_ws"}
{"event_at":"2026-07-28T02:57:26.897000Z","event_fingerprint":"dfd9ef91557e47a88fbec162f0f0079032fab4b3b105bf9b631326b4eed931f8","payload":{"connection_id":"955646bd8bf740759faf38750c0f263f","event_at":"2026-07-28T02:57:26.897000Z","event_type":"price_change","frame_hash":"65bf4e8f59120d7f8ecdc1e735f51a8366331f1145fcce2643dc4bc6ceaf2d33","frame_index":0,"kind":"data","monotonic_ns":309430268804916,"payload":{"event_type":"price_change","market":"0x0f70d07969bc69eaa97d0987de651885fdca02263688026aa11e7678af8f87aa","price_changes":[{"asset_id":"58313761654877669244690227616056238030136603415514645252000528337391143520538","best_ask":"0.48","best_bid":"0.47","hash":"9953473c5d22daf495d05d7a6bb37f83677b5e79","price":"0.45","side":"BUY","size":"74.8"},{"asset_id":"64053005904884194822931764831592250494815136296598204104072528088122126148949","best_ask":"0.53","best_bid":"0.52","hash":"96bebc2ed0ba7d4a3a52864107c1222a7ab6dbe6","price":"0.55","side":"SELL","size":"74.8"}],"timestamp":"1785207446897"},"payload_hash":"7f4d5d722b85627ccfb382d47818908e03556ba863d24f7defbcc345d4d3584e","raw_frame":"{\"market\":\"0x0f70d07969bc69eaa97d0987de651885fdca02263688026aa11e7678af8f87aa\", \"price_changes\":[{\"asset_id\":\"58313761654877669244690227616056238030136603415514645252000528337391143520538\", \"price\":\"0.45\", \"size\":\"74.8\", \"side\":\"BUY\", \"hash\":\"9953473c5d22daf495d05d7a6bb37f83677b5e79\", \"best_bid\":\"0.47\", \"best_ask\":\"0.48\"}, {\"asset_id\":\"64053005904884194822931764831592250494815136296598204104072528088122126148949\", \"price\":\"0.55\", \"size\":\"74.8\", \"side\":\"SELL\", \"hash\":\"96bebc2ed0ba7d4a3a52864107c1222a7ab6dbe6\", \"best_bid\":\"0.52\", \"best_ask\":\"0.53\"}], \"timestamp\":\"1785207446897\", \"event_type\":\"price_change\"}","received_at":"2026-07-28T02:57:27.251544Z","schema_version":"clob-market-ws.price_change.v1","sequence":null,"server_hash":null,"server_timestamp":"1785207446897","session_id":"5aad79be415c487c84df42bebd84ee93","source":"clob_market_ws"},"received_at":"2026-07-28T02:57:27.251544Z","record_id":"da9ffa958a9511c62db0c5608ffbdca6006109ee6d1ea490018785291b9ebc22","schema_fingerprint":"4aa3821a28b0b7c2400bc59aba4bcc0a76e971dadd19610d3ad38c768e124dc7","schema_version":"edge-lab-recorder.raw.v1","sequence":null,"source":"clob_market_ws"}
{"event_at":"2026-07-28T02:57:26.898000Z","event_fingerprint":"d4dde292fa6726585c9dd99e06193cf5737590540d840f69585cd768887b4a21","payload":{"connection_id":"955646bd8bf740759faf38750c0f263f","event_at":"2026-07-28T02:57:26.898000Z","event_type":"price_change","frame_hash":"a93d17a00040b8f123d329d7362fd34fd0af35197f3d9b5b5e07239e4fe697a8","frame_index":0,"kind":"data","monotonic_ns":309430270447291,"payload":{"event_type":"price_change","market":"0x0f70d07969bc69eaa97d0987de651885fdca02263688026aa11e7678af8f87aa","price_changes":[{"asset_id":"64053005904884194822931764831592250494815136296598204104072528088122126148949","best_ask":"0.53","best_bid":"0.52","hash":"2fa9f587a4d7ac43781616cac85730019b9ecf31","price":"0.46","side":"BUY","size":"133.64"},{"asset_id":"58313761654877669244690227616056238030136603415514645252000528337391143520538","best_ask":"0.48","best_bid":"0.47","hash":"7e2f6b76f36ae5c70368c750ce52026dfd943151","price":"0.54","side":"SELL","size":"133.64"}],"timestamp":"1785207446898"},"payload_hash":"d339971ec2dcf281947198eb6ba85374ddad4c20703c3e1021c4b693ce3fa54a","raw_frame":"{\"market\":\"0x0f70d07969bc69eaa97d0987de651885fdca02263688026aa11e7678af8f87aa\", \"price_changes\":[{\"asset_id\":\"64053005904884194822931764831592250494815136296598204104072528088122126148949\", \"price\":\"0.46\", \"size\":\"133.64\", \"side\":\"BUY\", \"hash\":\"2fa9f587a4d7ac43781616cac85730019b9ecf31\", \"best_bid\":\"0.52\", \"best_ask\":\"0.53\"}, {\"asset_id\":\"58313761654877669244690227616056238030136603415514645252000528337391143520538\", \"price\":\"0.54\", \"size\":\"133.64\", \"side\":\"SELL\", \"hash\":\"7e2f6b76f36ae5c70368c750ce52026dfd943151\", \"best_bid\":\"0.47\", \"best_ask\":\"0.48\"}], \"timestamp\":\"1785207446898\", \"event_type\":\"price_change\"}","received_at":"2026-07-28T02:57:27.253183Z","schema_version":"clob-market-ws.price_change.v1","sequence":null,"server_hash":null,"server_timestamp":"1785207446898","session_id":"5aad79be415c487c84df42bebd84ee93","source":"clob_market_ws"},"received_at":"2026-07-28T02:57:27.253183Z","record_id":"bfd1a82a4678263eec520adf2fabda0cb516077ca9f4bf92a248190b0963bef6","schema_fingerprint":"4aa3821a28b0b7c2400bc59aba4bcc0a76e971dadd19610d3ad38c768e124dc7","schema_version":"edge-lab-recorder.raw.v1","sequence":null,"source":"clob_market_ws"}
{"event_at":"2026-07-28T02:57:26.898000Z","event_fingerprint":"af8b55057091cfd782ea3c6b51a9eb566806f428070df8051f53c023c293c991","payload":{"connection_id":"955646bd8bf740759faf38750c0f263f","event_at":"2026-07-28T02:57:26.898000Z","event_type":"price_change","frame_hash":"3487621f17d1502ae85910d38e111b3de7f0c46f132e2868dc41a94fc3e820d0","frame_index":0,"kind":"data","monotonic_ns":309430271992291,"payload":{"event_type":"price_change","market":"0x0f70d07969bc69eaa97d0987de651885fdca02263688026aa11e7678af8f87aa","price_changes":[{"asset_id":"64053005904884194822931764831592250494815136296598204104072528088122126148949","best_ask":"0.53","best_bid":"0.52","hash":"cae96feb05cc6d842ebe3fc60f2929c5c2c9feec","price":"0.01","side":"BUY","size":"2587.52"},{"asset_id":"58313761654877669244690227616056238030136603415514645252000528337391143520538","best_ask":"0.48","best_bid":"0.47","hash":"44d153e48f9906167be678f58cffa7e4e94dcb71","price":"0.99","side":"SELL","size":"2587.52"}],"timestamp":"1785207446898"},"payload_hash":"4dbc9dc2a52807b6ffaeacf0766a924bf49be0cb31eac43cab9adc2fad2c37a2","raw_frame":"{\"market\":\"0x0f70d07969bc69eaa97d0987de651885fdca02263688026aa11e7678af8f87aa\", \"price_changes\":[{\"asset_id\":\"64053005904884194822931764831592250494815136296598204104072528088122126148949\", \"price\":\"0.01\", \"size\":\"2587.52\", \"side\":\"BUY\", \"hash\":\"cae96feb05cc6d842ebe3fc60f2929c5c2c9feec\", \"best_bid\":\"0.52\", \"best_ask\":\"0.53\"}, {\"asset_id\":\"58313761654877669244690227616056238030136603415514645252000528337391143520538\", \"price\":\"0.99\", \"size\":\"2587.52\", \"side\":\"SELL\", \"hash\":\"44d153e48f9906167be678f58cffa7e4e94dcb71\", \"best_bid\":\"0.47\", \"best_ask\":\"0.48\"}], \"timestamp\":\"1785207446898\", \"event_type\":\"price_change\"}","received_at":"2026-07-28T02:57:27.254730Z","schema_version":"clob-market-ws.price_change.v1","sequence":null,"server_hash":null,"server_timestamp":"1785207446898","session_id":"5aad79be415c487c84df42bebd84ee93","source":"clob_market_ws"},"received_at":"2026-07-28T02:57:27.254730Z","record_id":"5f396d0916c54aacf9aae9b8247c3a131ca215f49236ae35853a479a007c1e43","schema_fingerprint":"4aa3821a28b0b7c2400bc59aba4bcc0a76e971dadd19610d3ad38c768e124dc7","schema_version":"edge-lab-recorder.raw.v1","sequence":null,"source":"clob_market_ws"}
{"event_at":"2026-07-28T02:57:26.899000Z","event_fingerprint":"8c389457e199b387e46926f25fddfd85b93412cd0cbc3a772e77f57577505451","payload":{"connection_id":"955646bd8bf740759faf38750c0f263f","event_at":"2026-07-28T02:57:26.899000Z","event_type":"price_change","frame_hash":"8b3b7d4dcd1f0290095cbd06a2c6b74362b17f707d610e8dd0489835147cad8f","frame_index":0,"kind":"data","monotonic_ns":309430273517666,"payload":{"event_type":"price_change","market":"0x0f70d07969bc69eaa97d0987de651885fdca02263688026aa11e7678af8f87aa","price_changes":[{"asset_id":"58313761654877669244690227616056238030136603415514645252000528337391143520538","best_ask":"0.48","best_bid":"0.47","hash":"d855d6e02a1985723ba9e38dff7c2c72cd759f96","price":"0.35","side":"BUY","size":"98.1"},{"asset_id":"64053005904884194822931764831592250494815136296598204104072528088122126148949","best_ask":"0.53","best_bid":"0.52","hash":"dfab51a40727b677eaa0a8cd551bf3cd6f63d773","price":"0.65","side":"SELL","size":"98.1"}],"timestamp":"1785207446899"},"payload_hash":"2369746c053b1b4ad9ec42cfab1efa2b18c4fb0a18a2309d6841010fe87a132f","raw_frame":"{\"market\":\"0x0f70d07969bc69eaa97d0987de651885fdca02263688026aa11e7678af8f87aa\", \"price_changes\":[{\"asset_id\":\"58313761654877669244690227616056238030136603415514645252000528337391143520538\", \"price\":\"0.35\", \"size\":\"98.1\", \"side\":\"BUY\", \"hash\":\"d855d6e02a1985723ba9e38dff7c2c72cd759f96\", \"best_bid\":\"0.47\", \"best_ask\":\"0.48\"}, {\"asset_id\":\"64053005904884194822931764831592250494815136296598204104072528088122126148949\", \"price\":\"0.65\", \"size\":\"98.1\", \"side\":\"SELL\", \"hash\":\"dfab51a40727b677eaa0a8cd551bf3cd6f63d773\", \"best_bid\":\"0.52\", \"best_ask\":\"0.53\"}], \"timestamp\":\"1785207446899\", \"event_type\":\"price_change\"}","received_at":"2026-07-28T02:57:27.256257Z","schema_version":"clob-market-ws.price_change.v1","sequence":null,"server_hash":null,"server_timestamp":"1785207446899","session_id":"5aad79be415c487c84df42bebd84ee93","source":"clob_market_ws"},"received_at":"2026-07-28T02:57:27.256257Z","record_id":"2f21ee3b1fe94cb396b69572f463545e123fe22009a9fe7068fa5eca38fabe4a","schema_fingerprint":"4aa3821a28b0b7c2400bc59aba4bcc0a76e971dadd19610d3ad38c768e124dc7","schema_version":"edge-lab-recorder.raw.v1","sequence":null,"source":"clob_market_ws"}
{"event_at":"2026-07-28T02:57:26.900000Z","event_fingerprint":"1681eb4c9116776183e2bc8cfe4d4456c870ab259b8279eaab1bfb3aa36a1a81","payload":{"connection_id":"955646bd8bf740759faf38750c0f263f","event_at":"2026-07-28T02:57:26.900000Z","event_type":"price_change","frame_hash":"c31e69e2d492bf68de9a58b79d648ee04e15e85ce43b37a66b8388ad569b52b5","frame_index":0,"kind":"data","monotonic_ns":309430275057083,"payload":{"event_type":"price_change","market":"0x0f70d07969bc69eaa97d0987de651885fdca02263688026aa11e7678af8f87aa","price_changes":[{"asset_id":"64053005904884194822931764831592250494815136296598204104072528088122126148949","best_ask":"0.53","best_bid":"0.52","hash":"a7d4b3d56d120e3438d310b936d575de8f9b6073","price":"0.52","side":"BUY","size":"214.1"},{"asset_id":"58313761654877669244690227616056238030136603415514645252000528337391143520538","best_ask":"0.48","best_bid":"0.47","hash":"ab433baa98afbb23332ae90ab962de8ba374401f","price":"0.48","side":"SELL","size":"214.1"}],"timestamp":"1785207446900"},"payload_hash":"619ff1792748a328ef6bcbb80d3c08ec12d043f2cb0a08a5c66e787c64bd6925","raw_frame":"{\"market\":\"0x0f70d07969bc69eaa97d0987de651885fdca02263688026aa11e7678af8f87aa\", \"price_changes\":[{\"asset_id\":\"64053005904884194822931764831592250494815136296598204104072528088122126148949\", \"price\":\"0.52\", \"size\":\"214.1\", \"side\":\"BUY\", \"hash\":\"a7d4b3d56d120e3438d310b936d575de8f9b6073\", \"best_bid\":\"0.52\", \"best_ask\":\"0.53\"}, {\"asset_id\":\"58313761654877669244690227616056238030136603415514645252000528337391143520538\", \"price\":\"0.48\", \"size\":\"214.1\", \"side\":\"SELL\", \"hash\":\"ab433baa98afbb23332ae90ab962de8ba374401f\", \"best_bid\":\"0.47\", \"best_ask\":\"0.48\"}], \"timestamp\":\"1785207446900\", \"event_type\":\"price_change\"}","received_at":"2026-07-28T02:57:27.257794Z","schema_version":"clob-market-ws.price_change.v1","sequence":null,"server_hash":null,"server_timestamp":"1785207446900","session_id":"5aad79be415c487c84df42bebd84ee93","source":"clob_market_ws"},"received_at":"2026-07-28T02:57:27.257794Z","record_id":"97465a7e5876899fddc308fb5037d55b955f32709eb40f0f339c753c97af667c","schema_fingerprint":"4aa3821a28b0b7c2400bc59aba4bcc0a76e971dadd19610d3ad38c768e124dc7","schema_version":"edge-lab-recorder.raw.v1","sequence":null,"source":"clob_market_ws"}
{"event_at":"2026-07-28T02:57:26.901000Z","event_fingerprint":"b5eb6a889a0589780d8937e868c85c863596eaa1bdf91b46d36794da33b109e3","payload":{"connection_id":"955646bd8bf740759faf38750c0f263f","event_at":"2026-07-28T02:57:26.901000Z","event_type":"price_change","frame_hash":"647ba81dfac83c5702404d6e588278b622fabf97d49a6218a76fb3d3921439f1","frame_index":0,"kind":"data","monotonic_ns":309430276594458,"payload":{"event_type":"price_change","market":"0x0f70d07969bc69eaa97d0987de651885fdca02263688026aa11e7678af8f87aa","price_changes":[{"asset_id":"64053005904884194822931764831592250494815136296598204104072528088122126148949","best_ask":"0.53","best_bid":"0.52","hash":"c0a369bc3b012949bc931b211b3e5fbd46234521","price":"0.02","side":"BUY","size":"1065.79"},{"asset_id":"58313761654877669244690227616056238030136603415514645252000528337391143520538","best_ask":"0.48","best_bid":"0.47","hash":"77fa4b8530b9b0d7938d6745ce16f5a3bed1f390","price":"0.98","side":"SELL","size":"1065.79"}],"timestamp":"1785207446901"},"payload_hash":"2eb12bd77d1cea5abcce621a8657d65a94d046dd3b0eb06ccebc0b0b6f84fda9","raw_frame":"{\"market\":\"0x0f70d07969bc69eaa97d0987de651885fdca02263688026aa11e7678af8f87aa\", \"price_changes\":[{\"asset_id\":\"64053005904884194822931764831592250494815136296598204104072528088122126148949\", \"price\":\"0.02\", \"size\":\"1065.79\", \"side\":\"BUY\", \"hash\":\"c0a369bc3b012949bc931b211b3e5fbd46234521\", \"best_bid\":\"0.52\", \"best_ask\":\"0.53\"}, {\"asset_id\":\"58313761654877669244690227616056238030136603415514645252000528337391143520538\", \"price\":\"0.98\", \"size\":\"1065.79\", \"side\":\"SELL\", \"hash\":\"77fa4b8530b9b0d7938d6745ce16f5a3bed1f390\", \"best_bid\":\"0.47\", \"best_ask\":\"0.48\"}], \"timestamp\":\"1785207446901\", \"event_type\":\"price_change\"}","received_at":"2026-07-28T02:57:27.259334Z","schema_version":"clob-market-ws.price_change.v1","sequence":null,"server_hash":null,"server_timestamp":"1785207446901","session_id":"5aad79be415c487c84df42bebd84ee93","source":"clob_market_ws"},"received_at":"2026-07-28T02:57:27.259334Z","record_id":"9eacbf1378ee3d8265b46fb71c86a617d94b164c4f2320f7f135873128d45d67","schema_fingerprint":"4aa3821a28b0b7c2400bc59aba4bcc0a76e971dadd19610d3ad38c768e124dc7","schema_version":"edge-lab-recorder.raw.v1","sequence":null,"source":"clob_market_ws"}
{"event_at":"2026-07-28T02:57:26.902000Z","event_fingerprint":"8cf144d44de8be42ec8ed5a6fbdb5eecfbd9273c11c89ed4e68bc0032992f1b9","payload":{"connection_id":"955646bd8bf740759faf38750c0f263f","event_at":"2026-07-28T02:57:26.902000Z","event_type":"price_change","frame_hash":"4a38e8feec46a5f6a2870ad19a47ba199bfed92a4758373b22c00cf5db959f2d","frame_index":0,"kind":"data","monotonic_ns":309430278068291,"payload":{"event_type":"price_change","market":"0x0f70d07969bc69eaa97d0987de651885fdca02263688026aa11e7678af8f87aa","price_changes":[{"asset_id":"58313761654877669244690227616056238030136603415514645252000528337391143520538","best_ask":"0.48","best_bid":"0.47","hash":"10b887e02b79d90a15829fa626462469c8f9d162","price":"0.01","side":"BUY","size":"2376.24"},{"asset_id":"64053005904884194822931764831592250494815136296598204104072528088122126148949","best_ask":"0.53","best_bid":"0.52","hash":"3eec8c4728d1d4977b0951d3ff92218039c0c455","price":"0.99","side":"SELL","size":"2376.24"}],"timestamp":"1785207446902"},"payload_hash":"dd3bbb8e05e0f1fab77d7f70e4adcd31468e3346753c7c099043ec3ac6c9919b","raw_frame":"{\"market\":\"0x0f70d07969bc69eaa97d0987de651885fdca02263688026aa11e7678af8f87aa\", \"price_changes\":[{\"asset_id\":\"58313761654877669244690227616056238030136603415514645252000528337391143520538\", \"price\":\"0.01\", \"size\":\"2376.24\", \"side\":\"BUY\", \"hash\":\"10b887e02b79d90a15829fa626462469c8f9d162\", \"best_bid\":\"0.47\", \"best_ask\":\"0.48\"}, {\"asset_id\":\"64053005904884194822931764831592250494815136296598204104072528088122126148949\", \"price\":\"0.99\", \"size\":\"2376.24\", \"side\":\"SELL\", \"hash\":\"3eec8c4728d1d4977b0951d3ff92218039c0c455\", \"best_bid\":\"0.52\", \"best_ask\":\"0.53\"}], \"timestamp\":\"1785207446902\", \"event_type\":\"price_change\"}","received_at":"2026-07-28T02:57:27.260807Z","schema_version":"clob-market-ws.price_change.v1","sequence":null,"server_hash":null,"server_timestamp":"1785207446902","session_id":"5aad79be415c487c84df42bebd84ee93","source":"clob_market_ws"},"received_at":"2026-07-28T02:57:27.260807Z","record_id":"8e36b8aba0cc1978dee6e41147ee8880ed81dc40828f1ee67af32df1349bfa8c","schema_fingerprint":"4aa3821a28b0b7c2400bc59aba4bcc0a76e971dadd19610d3ad38c768e124dc7","schema_version":"edge-lab-recorder.raw.v1","sequence":null,"source":"clob_market_ws"}
{"event_at":"2026-07-28T02:57:26.907000Z","event_fingerprint":"e1305c03ee75bf0cec654499adb27f8776f92572ca6459f77a9fb300d020836a","payload":{"connection_id":"955646bd8bf740759faf38750c0f263f","event_at":"2026-07-28T02:57:26.907000Z","event_type":"price_change","frame_hash":"174aeb74089f566f8610b4a9b41577b4df249c5093bba58a4c895058c7d50ee4","frame_index":0,"kind":"data","monotonic_ns":309430279548666,"payload":{"event_type":"price_change","market":"0x0f70d07969bc69eaa97d0987de651885fdca02263688026aa11e7678af8f87aa","price_changes":[{"asset_id":"58313761654877669244690227616056238030136603415514645252000528337391143520538","best_ask":"0.48","best_bid":"0.47","hash":"18db1a2e4712fc8aafa6be16f6d54bbfbaf9a628","price":"0.49","side":"SELL","size":"238.1"},{"asset_id":"64053005904884194822931764831592250494815136296598204104072528088122126148949","best_ask":"0.53","best_bid":"0.52","hash":"7d438f939e5e8ea0e9429243d55485c817682085","price":"0.51","side":"BUY","size":"238.1"}],"timestamp":"1785207446907"},"payload_hash":"d2438c021084116f4f1dc5a88b63685d24b620bc6c5e6ef0da385e612c80a6c2","raw_frame":"{\"market\":\"0x0f70d07969bc69eaa97d0987de651885fdca02263688026aa11e7678af8f87aa\", \"price_changes\":[{\"asset_id\":\"58313761654877669244690227616056238030136603415514645252000528337391143520538\", \"price\":\"0.49\", \"size\":\"238.1\", \"side\":\"SELL\", \"hash\":\"18db1a2e4712fc8aafa6be16f6d54bbfbaf9a628\", \"best_bid\":\"0.47\", \"best_ask\":\"0.48\"}, {\"asset_id\":\"64053005904884194822931764831592250494815136296598204104072528088122126148949\", \"price\":\"0.51\", \"size\":\"238.1\", \"side\":\"BUY\", \"hash\":\"7d438f939e5e8ea0e9429243d55485c817682085\", \"best_bid\":\"0.52\", \"best_ask\":\"0.53\"}], \"timestamp\":\"1785207446907\", \"event_type\":\"price_change\"}","received_at":"2026-07-28T02:57:27.262288Z","schema_version":"clob-market-ws.price_change.v1","sequence":null,"server_hash":null,"server_timestamp":"1785207446907","session_id":"5aad79be415c487c84df42bebd84ee93","source":"clob_market_ws"},"received_at":"2026-07-28T02:57:27.262288Z","record_id":"e5b7d33d40facece897a7d39cf025e961fed1109ec0cf3c442fa23d3a04a34ca","schema_fingerprint":"4aa3821a28b0b7c2400bc59aba4bcc0a76e971dadd19610d3ad38c768e124dc7","schema_version":"edge-lab-recorder.raw.v1","sequence":null,"source":"clob_market_ws"}
{"event_at":"2026-07-28T02:57:26.913000Z","event_fingerprint":"1eada87a6fcb4d6ed83ae7ec160e3d3d398ad5f5b8fe4f1dd6799fa5b518b488","payload":{"connection_id":"955646bd8bf740759faf38750c0f263f","event_at":"2026-07-28T02:57:26.913000Z","event_type":"price_change","frame_hash":"cb647aa8daa7623e4de532f6855a1682824614fec0e19af2c6d613f3e16d5401","frame_index":0,"kind":"data","monotonic_ns":309430284392666,"payload":{"event_type":"price_change","market":"0x0f70d07969bc69eaa97d0987de651885fdca02263688026aa11e7678af8f87aa","price_changes":[{"asset_id":"64053005904884194822931764831592250494815136296598204104072528088122126148949","best_ask":"0.53","best_bid":"0.52","hash":"f7ca97f2ba02eb4b004a03c2dec4c16048300a91","price":"0.51","side":"BUY","size":"245.1"},{"asset_id":"58313761654877669244690227616056238030136603415514645252000528337391143520538","best_ask":"0.48","best_bid":"0.47","hash":"cad24e344a4dfddd247fed40226805b9df10c5e1","price":"0.49","side":"SELL","size":"245.1"}],"timestamp":"1785207446913"},"payload_hash":"b9318687c267ea9f103fc3aa9c808f9ad92522e5f666455e728efac015a71534","raw_frame":"{\"market\":\"0x0f70d07969bc69eaa97d0987de651885fdca02263688026aa11e7678af8f87aa\", \"price_changes\":[{\"asset_id\":\"64053005904884194822931764831592250494815136296598204104072528088122126148949\", \"price\":\"0.51\", \"size\":\"245.1\", \"side\":\"BUY\", \"hash\":\"f7ca97f2ba02eb4b004a03c2dec4c16048300a91\", \"best_bid\":\"0.52\", \"best_ask\":\"0.53\"}, {\"asset_id\":\"58313761654877669244690227616056238030136603415514645252000528337391143520538\", \"price\":\"0.49\", \"size\":\"245.1\", \"side\":\"SELL\", \"hash\":\"cad24e344a4dfddd247fed40226805b9df10c5e1\", \"best_bid\":\"0.47\", \"best_ask\":\"0.48\"}], \"timestamp\":\"1785207446913\", \"event_type\":\"price_change\"}","received_at":"2026-07-28T02:57:27.267131Z","schema_version":"clob-market-ws.price_change.v1","sequence":null,"server_hash":null,"server_timestamp":"1785207446913","session_id":"5aad79be415c487c84df42bebd84ee93","source":"clob_market_ws"},"received_at":"2026-07-28T02:57:27.267131Z","record_id":"4964b6b9b67f1376cf52ce29c8bc008e01b964abfbad64033580eea105e2b3e5","schema_fingerprint":"4aa3821a28b0b7c2400bc59aba4bcc0a76e971dadd19610d3ad38c768e124dc7","schema_version":"edge-lab-recorder.raw.v1","sequence":null,"source":"clob_market_ws"}
{"event_at":"2026-07-28T02:57:26.923000Z","event_fingerprint":"b2ecce6e06955d18c4397caa130f603bc1cae7f0703d048c672d210e5068a239","payload":{"connection_id":"955646bd8bf740759faf38750c0f263f","event_at":"2026-07-28T02:57:26.923000Z","event_type":"price_change","frame_hash":"cb3d3f8e7f0ff7523d411e86f1736c383657bef23cf0a61620d90fe8a3b61d63","frame_index":0,"kind":"data","monotonic_ns":309430285867250,"payload":{"event_type":"price_change","market":"0x0f70d07969bc69eaa97d0987de651885fdca02263688026aa11e7678af8f87aa","price_changes":[{"asset_id":"64053005904884194822931764831592250494815136296598204104072528088122126148949","best_ask":"0.53","best_bid":"0.52","hash":"052c6db2901013a7731391259aa285e09fcb97e2","price":"0.51","side":"BUY","size":"258.1"},{"asset_id":"58313761654877669244690227616056238030136603415514645252000528337391143520538","best_ask":"0.48","best_bid":"0.47","hash":"864cd1217c19a4367db00f2a2d8c1856ccd392d3","price":"0.49","side":"SELL","size":"258.1"}],"timestamp":"1785207446923"},"payload_hash":"f7ed350a272754526285d14329c4cfa75b6bfd321017b4b63672403ee5b8ddd5","raw_frame":"{\"market\":\"0x0f70d07969bc69eaa97d0987de651885fdca02263688026aa11e7678af8f87aa\", \"price_changes\":[{\"asset_id\":\"64053005904884194822931764831592250494815136296598204104072528088122126148949\", \"price\":\"0.51\", \"size\":\"258.1\", \"side\":\"BUY\", \"hash\":\"052c6db2901013a7731391259aa285e09fcb97e2\", \"best_bid\":\"0.52\", \"best_ask\":\"0.53\"}, {\"asset_id\":\"58313761654877669244690227616056238030136603415514645252000528337391143520538\", \"price\":\"0.49\", \"size\":\"258.1\", \"side\":\"SELL\", \"hash\":\"864cd1217c19a4367db00f2a2d8c1856ccd392d3\", \"best_bid\":\"0.47\", \"best_ask\":\"0.48\"}], \"timestamp\":\"1785207446923\", \"event_type\":\"price_change\"}","received_at":"2026-07-28T02:57:27.268606Z","schema_version":"clob-market-ws.price_change.v1","sequence":null,"server_hash":null,"server_timestamp":"1785207446923","session_id":"5aad79be415c487c84df42bebd84ee93","source":"clob_market_ws"},"received_at":"2026-07-28T02:57:27.268606Z","record_id":"84056d4f8bc9289af70da084968dd32880c22f4a74d96800ff5934db45a36e2c","schema_fingerprint":"4aa3821a28b0b7c2400bc59aba4bcc0a76e971dadd19610d3ad38c768e124dc7","schema_version":"edge-lab-recorder.raw.v1","sequence":null,"source":"clob_market_ws"}
