{"event_at":"2026-07-28T02:50:14.407000Z","event_fingerprint":"0e313e270f01a13a5b61275e23ea5160efe5548cf6d53de6546886935d109fe7","payload":{"connection_id":"955646bd8bf740759faf38750c0f263f","event_at":"2026-07-28T02:50:14.407000Z","event_type":"price_change","frame_hash":"9eca14475f3f1dcb2069df43fdaad2510168b370f3951f56b1dcd85f40c3c85d","frame_index":0,"kind":"data","monotonic_ns":308997290851333,"payload":{"event_type":"price_change","market":"0x0f70d07969bc69eaa97d0987de651885fdca02263688026aa11e7678af8f87aa","price_changes":[{"asset_id":"64053005904884194822931764831592250494815136296598204104072528088122126148949","best_ask":"0.51","best_bid":"0.5","hash":"6dbd9bf9c1695df10a96e1051245cfbbd7b8d7e1","price":"0.38","side":"BUY","size":"196.25"},{"asset_id":"58313761654877669244690227616056238030136603415514645252000528337391143520538","best_ask":"0.5","best_bid":"0.49","hash":"50a2a7b24ce103ee48d15440c78864318af8e230","price":"0.62","side":"SELL","size":"196.25"}],"timestamp":"1785207014407"},"payload_hash":"c8222b9f896eb521763e123a307801d265c99506d83bb966cc6309a99f416cb9","raw_frame":"{\"market\":\"0x0f70d07969bc69eaa97d0987de651885fdca02263688026aa11e7678af8f87aa\", \"price_changes\":[{\"asset_id\":\"64053005904884194822931764831592250494815136296598204104072528088122126148949\", \"price\":\"0.38\", \"size\":\"196.25\", \"side\":\"BUY\", \"hash\":\"6dbd9bf9c1695df10a96e1051245cfbbd7b8d7e1\", \"best_bid\":\"0.5\", \"best_ask\":\"0.51\"}, {\"asset_id\":\"58313761654877669244690227616056238030136603415514645252000528337391143520538\", \"price\":\"0.62\", \"size\":\"196.25\", \"side\":\"SELL\", \"hash\":\"50a2a7b24ce103ee48d15440c78864318af8e230\", \"best_bid\":\"0.49\", \"best_ask\":\"0.5\"}], \"timestamp\":\"1785207014407\", \"event_type\":\"price_change\"}","received_at":"2026-07-28T02:50:14.276715Z","schema_version":"clob-market-ws.price_change.v1","sequence":null,"server_hash":null,"server_timestamp":"1785207014407","session_id":"5aad79be415c487c84df42bebd84ee93","source":"clob_market_ws"},"received_at":"2026-07-28T02:50:14.276715Z","record_id":"5107d3a5cd300b683def827f7787173710cf2ce22dd1413005b2a6bcdaaf7d02","schema_fingerprint":"4aa3821a28b0b7c2400bc59aba4bcc0a76e971dadd19610d3ad38c768e124dc7","schema_version":"edge-lab-recorder.raw.v1","sequence":null,"source":"clob_market_ws"}
{"event_at":"2026-07-28T02:50:14.440000Z","event_fingerprint":"c7313946d210a2e26102f55419a4ef5a7d0e3ebae6fa539c1caaa9232a2ce5aa","payload":{"connection_id":"955646bd8bf740759faf38750c0f263f","event_at":"2026-07-28T02:50:14.440000Z","event_type":"price_change","frame_hash":"34d7a5cf91356607142427dcfd3cc9758842dca64c5beecdc82e6fca2d2f7605","frame_index":0,"kind":"data","monotonic_ns":308997324759333,"payload":{"event_type":"price_change","market":"0x0f70d07969bc69eaa97d0987de651885fdca02263688026aa11e7678af8f87aa","price_changes":[{"asset_id":"58313761654877669244690227616056238030136603415514645252000528337391143520538","best_ask":"0.5","best_bid":"0.49","hash":"abfe3ed5cd7a8d2023592d6b5d5d88d45b46f660","price":"0.38","side":"BUY","size":"281.25"},{"asset_id":"64053005904884194822931764831592250494815136296598204104072528088122126148949","best_ask":"0.51","best_bid":"0.5","hash":"bd2bde1208407efd763e86ecf4a3aed199400c7b","price":"0.62","side":"SELL","size":"281.25"}],"timestamp":"1785207014440"},"payload_hash":"00af1208933362f9e3ebb526b9b28f2fa32b7715060665502050f333d4037a63","raw_frame":"{\"market\":\"0x0f70d07969bc69eaa97d0987de651885fdca02263688026aa11e7678af8f87aa\", \"price_changes\":[{\"asset_id\":\"58313761654877669244690227616056238030136603415514645252000528337391143520538\", \"price\":\"0.38\", \"size\":\"281.25\", \"side\":\"BUY\", \"hash\":\"abfe3ed5cd7a8d2023592d6b5d5d88d45b46f660\", \"best_bid\":\"0.49\", \"best_ask\":\"0.5\"}, {\"asset_id\":\"64053005904884194822931764831592250494815136296598204104072528088122126148949\", \"price\":\"0.62\", \"size\":\"281.25\", \"side\":\"SELL\", \"hash\":\"bd2bde1208407efd763e86ecf4a3aed199400c7b\", \"best_bid\":\"0.5\", \"best_ask\":\"0.51\"}], \"timestamp\":\"1785207014440\", \"event_type\":\"price_change\"}","received_at":"2026-07-28T02:50:14.310625Z","schema_version":"clob-market-ws.price_change.v1","sequence":null,"server_hash":null,"server_timestamp":"1785207014440","session_id":"5aad79be415c487c84df42bebd84ee93","source":"clob_market_ws"},"received_at":"2026-07-28T02:50:14.310625Z","record_id":"b74a8410a3fc36f7a0ec8d48faad3e8d012c489969346c3cfbe7b66ff89c0f8d","schema_fingerprint":"4aa3821a28b0b7c2400bc59aba4bcc0a76e971dadd19610d3ad38c768e124dc7","schema_version":"edge-lab-recorder.raw.v1","sequence":null,"source":"clob_market_ws"}
{"event_at":"2026-07-28T02:50:14.577000Z","event_fingerprint":"dd1b00c6e594d3a9b404862757b8486d3b6da32b52326b2304c5a0da77e23101","payload":{"connection_id":"955646bd8bf740759faf38750c0f263f","event_at":"2026-07-28T02:50:14.577000Z","event_type":"price_change","frame_hash":"14c673221536580014cbae4165129fd0a7c0a7907233022c73fb11cd6b1413fe","frame_index":0,"kind":"data","monotonic_ns":308997468540541,"payload":{"event_type":"price_change","market":"0x0f70d07969bc69eaa97d0987de651885fdca02263688026aa11e7678af8f87aa","price_changes":[{"asset_id":"64053005904884194822931764831592250494815136296598204104072528088122126148949","best_ask":"0.51","best_bid":"0.5","hash":"adb304b62a857b52164d3ad1e1da338cbed60cbb","price":"0.41","side":"BUY","size":"117.01"},{"asset_id":"58313761654877669244690227616056238030136603415514645252000528337391143520538","best_ask":"0.5","best_bid":"0.49","hash":"b3c7af65cc7bcc7a95021477fc0691ef9e75ed98","price":"0.59","side":"SELL","size":"117.01"}],"timestamp":"1785207014577"},"payload_hash":"1d5338fb221eb1ceeed5268675b6d1897d280dd7fa5e7a5eea1f51de243445ec","raw_frame":"{\"market\":\"0x0f70d07969bc69eaa97d0987de651885fdca02263688026aa11e7678af8f87aa\", \"price_changes\":[{\"asset_id\":\"64053005904884194822931764831592250494815136296598204104072528088122126148949\", \"price\":\"0.41\", \"size\":\"117.01\", \"side\":\"BUY\", \"hash\":\"adb304b62a857b52164d3ad1e1da338cbed60cbb\", \"best_bid\":\"0.5\", \"best_ask\":\"0.51\"}, {\"asset_id\":\"58313761654877669244690227616056238030136603415514645252000528337391143520538\", \"price\":\"0.59\", \"size\":\"117.01\", \"side\":\"SELL\", \"hash\":\"b3c7af65cc7bcc7a95021477fc0691ef9e75ed98\", \"best_bid\":\"0.49\", \"best_ask\":\"0.5\"}], \"timestamp\":\"1785207014577\", \"event_type\":\"price_change\"}","received_at":"2026-07-28T02:50:14.454406Z","schema_version":"clob-market-ws.price_change.v1","sequence":null,"server_hash":null,"server_timestamp":"1785207014577","session_id":"5aad79be415c487c84df42bebd84ee93","source":"clob_market_ws"},"received_at":"2026-07-28T02:50:14.454406Z","record_id":"eae4cdf02d9d5928430d0c56b07389e788489129c189bea6ff99ed749f554292","schema_fingerprint":"4aa3821a28b0b7c2400bc59aba4bcc0a76e971dadd19610d3ad38c768e124dc7","schema_version":"edge-lab-recorder.raw.v1","sequence":null,"source":"clob_market_ws"}
{"event_at":"2026-07-28T02:50:14.609000Z","event_fingerprint":"649db39303f43c2782915cc126773b3cb8cb2f8fe22f9740aae2147f88a93dc6","payload":{"connection_id":"955646bd8bf740759faf38750c0f263f","event_at":"2026-07-28T02:50:14.609000Z","event_type":"price_change","frame_hash":"8d628aab8748134af707dcb5dfaa167194c2b914f1fb19c094c186d3087b6046","frame_index":0,"kind":"data","monotonic_ns":308997506138625,"payload":{"event_type":"price_change","market":"0x0f70d07969bc69eaa97d0987de651885fdca02263688026aa11e7678af8f87aa","price_changes":[{"asset_id":"58313761654877669244690227616056238030136603415514645252000528337391143520538","best_ask":"0.5","best_bid":"0.49","hash":"bcab806aac011c48f6466f4793d578dad86f2a57","price":"0.41","side":"BUY","size":"217.01"},{"asset_id":"64053005904884194822931764831592250494815136296598204104072528088122126148949","best_ask":"0.51","best_bid":"0.5","hash":"b5b1a67677c668f56b4fe23969ee05f2134df5ab","price":"0.59","side":"SELL","size":"217.01"}],"timestamp":"1785207014609"},"payload_hash":"786ee601233edf8cff270fc4e642806ed41bf53f9dbb43814814cd4978ae8ee3","raw_frame":"{\"market\":\"0x0f70d07969bc69eaa97d0987de651885fdca02263688026aa11e7678af8f87aa\", \"price_changes\":[{\"asset_id\":\"58313761654877669244690227616056238030136603415514645252000528337391143520538\", \"price\":\"0.41\", \"size\":\"217.01\", \"side\":\"BUY\", \"hash\":\"bcab806aac011c48f6466f4793d578dad86f2a57\", \"best_bid\":\"0.49\", \"best_ask\":\"0.5\"}, {\"asset_id\":\"64053005904884194822931764831592250494815136296598204104072528088122126148949\", \"price\":\"0.59\", \"size\":\"217.01\", \"side\":\"SELL\", \"hash\":\"b5b1a67677c668f56b4fe23969ee05f2134df5ab\", \"best_bid\":\"0.5\", \"best_ask\":\"0.51\"}], \"timestamp\":\"1785207014609\", \"event_type\":\"price_change\"}","received_at":"2026-07-28T02:50:14.491998Z","schema_version":"clob-market-ws.price_change.v1","sequence":null,"server_hash":null,"server_timestamp":"1785207014609","session_id":"5aad79be415c487c84df42bebd84ee93","source":"clob_market_ws"},"received_at":"2026-07-28T02:50:14.491998Z","record_id":"dd6b2d84eab6c500739bd5e5d74a8b05449dfaf4566136a65698708b9079123b","schema_fingerprint":"4aa3821a28b0b7c2400bc59aba4bcc0a76e971dadd19610d3ad38c768e124dc7","schema_version":"edge-lab-recorder.raw.v1","sequence":null,"source":"clob_market_ws"}
{"event_at":"2026-07-28T02:50:16.045000Z","event_fingerprint":"0ad7a4a55e7ba06e2e1e983ef1d17e41c10045d9aad8d65e70d7fc42c242b7c0","payload":{"connection_id":"955646bd8bf740759faf38750c0f263f","event_at":"2026-07-28T02:50:16.045000Z","event_type":"best_bid_ask","frame_hash":"7a3ce79f523cc67e49bac7badbea10f018bf5f595da90b20343c37e2dea2c752","frame_index":0,"kind":"data","monotonic_ns":309003174175375,"payload":{"asset_id":"64053005904884194822931764831592250494815136296598204104072528088122126148949","best_ask":"0.51","best_bid":"0.5","event_type":"best_bid_ask","market":"0x0f70d07969bc69eaa97d0987de651885fdca02263688026aa11e7678af8f87aa","spread":"0.01","timestamp":"1785207016045"},"payload_hash":"28b1f64f1ec31f21f80aad8032997a6ebda4b805067e0d3baba3fc6218d7ed26","raw_frame":"{\"market\":\"0x0f70d07969bc69eaa97d0987de651885fdca02263688026aa11e7678af8f87aa\", \"asset_id\":\"64053005904884194822931764831592250494815136296598204104072528088122126148949\", \"best_bid\":\"0.5\", \"best_ask\":\"0.51\", \"spread\":\"0.01\", \"timestamp\":\"1785207016045\", \"event_type\":\"best_bid_ask\"}","received_at":"2026-07-28T02:50:20.159997Z","schema_version":"clob-market-ws.best_bid_ask.v1","sequence":null,"server_hash":null,"server_timestamp":"1785207016045","session_id":"5aad79be415c487c84df42bebd84ee93","source":"clob_market_ws"},"received_at":"2026-07-28T02:50:20.159997Z","record_id":"3aa142642b901769fc3cf78f9bfaaa96256a3e8aee4d7ec4d4c96adfd164c159","schema_fingerprint":"8488399f31b0337811b13b266be932db7062827c2470b78bd8e9e99bab51d17d","schema_version":"edge-lab-recorder.raw.v1","sequence":null,"source":"clob_market_ws"}
{"event_at":null,"event_fingerprint":"382c28a4c33dedab40c11910b0ce5160486bba2170b151f58736ac6ced935fe6","payload":{"connection_id":"955646bd8bf740759faf38750c0f263f","detail":{"interval_seconds":10.0,"message":"PING"},"event_type":"heartbeat","kind":"lifecycle","monotonic_ns":309003180102541,"received_at":"2026-07-28T02:50:20.165927Z","schema_version":"edge-lab-recorder.lifecycle.v1","session_id":"5aad79be415c487c84df42bebd84ee93","source":"clob_market_ws"},"received_at":"2026-07-28T02:50:20.165927Z","record_id":"208bc0631ea0e88a43c8f52e8eefd3abf4dddf0e8a453d7b5441ede644b584a9","schema_fingerprint":"cb8aa3aa4cb168a4b724fd9077bee6ecfb9bc586c57cfdf0ab89f00d82045e3c","schema_version":"edge-lab-recorder.raw.v1","sequence":null,"source":"clob_market_ws"}
{"event_at":"2026-07-28T02:50:16.045000Z","event_fingerprint":"638b8fdc7960af0085b9f0d1baf122094c52e5fedbe4e7737d66a2f387593a4e","payload":{"connection_id":"955646bd8bf740759faf38750c0f263f","event_at":"2026-07-28T02:50:16.045000Z","event_type":"best_bid_ask","frame_hash":"398640edece6823e02029e66b7268abbdb279bdcc981eb486072bc9057a6d815","frame_index":0,"kind":"data","monotonic_ns":309003180201791,"payload":{"asset_id":"58313761654877669244690227616056238030136603415514645252000528337391143520538","best_ask":"0.5","best_bid":"0.49","event_type":"best_bid_ask","market":"0x0f70d07969bc69eaa97d0987de651885fdca02263688026aa11e7678af8f87aa","spread":"0.01","timestamp":"1785207016045"},"payload_hash":"7fef8f90b73a85fb5ce96561ea681d3e2e67bbf6e943b6b31c2c4a962c8fa07f","raw_frame":"{\"market\":\"0x0f70d07969bc69eaa97d0987de651885fdca02263688026aa11e7678af8f87aa\", \"asset_id\":\"58313761654877669244690227616056238030136603415514645252000528337391143520538\", \"best_bid\":\"0.49\", \"best_ask\":\"0.5\", \"spread\":\"0.01\", \"timestamp\":\"1785207016045\", \"event_type\":\"best_bid_ask\"}","received_at":"2026-07-28T02:50:20.166027Z","schema_version":"clob-market-ws.best_bid_ask.v1","sequence":null,"server_hash":null,"server_timestamp":"1785207016045","session_id":"5aad79be415c487c84df42bebd84ee93","source":"clob_market_ws"},"received_at":"2026-07-28T02:50:20.166027Z","record_id":"c9bb464e7ad7251af4196494d4f568c81da3cb12d788db50d9eae498013b7b1d","schema_fingerprint":"8488399f31b0337811b13b266be932db7062827c2470b78bd8e9e99bab51d17d","schema_version":"edge-lab-recorder.raw.v1","sequence":null,"source":"clob_market_ws"}
{"event_at":"2026-07-28T02:50:16.045000Z","event_fingerprint":"427ca476f674e72001f4349883b29968699e92cf668ec1331635d03c9920e58d","payload":{"connection_id":"955646bd8bf740759faf38750c0f263f","event_at":"2026-07-28T02:50:16.045000Z","event_type":"price_change","frame_hash":"8c25106d136917be43cb11bbad6ee9b239f40c0d70186fc505c18f089aa335e6","frame_index":0,"kind":"data","monotonic_ns":309003187659375,"payload":{"event_type":"price_change","market":"0x0f70d07969bc69eaa97d0987de651885fdca02263688026aa11e7678af8f87aa","price_changes":[{"asset_id":"64053005904884194822931764831592250494815136296598204104072528088122126148949","best_ask":"0.51","best_bid":"0.5","hash":"f439b0b3b9a2ad98aabe11a1d12d6a03b8ada5a3","price":"0.5","side":"BUY","size":"225.11"},{"asset_id":"58313761654877669244690227616056238030136603415514645252000528337391143520538","best_ask":"0.5","best_bid":"0.49","hash":"d226f44a41833c3383ddee2a616ac21816b886fb","price":"0.5","side":"SELL","size":"225.11"}],"timestamp":"1785207016045"},"payload_hash":"2ba4351d63b7f920760cd196db81df950b8a722ad6a3f06b14adaaed470537b4","raw_frame":"{\"market\":\"0x0f70d07969bc69eaa97d0987de651885fdca02263688026aa11e7678af8f87aa\", \"price_changes\":[{\"asset_id\":\"64053005904884194822931764831592250494815136296598204104072528088122126148949\", \"price\":\"0.5\", \"size\":\"225.11\", \"side\":\"BUY\", \"hash\":\"f439b0b3b9a2ad98aabe11a1d12d6a03b8ada5a3\", \"best_bid\":\"0.5\", \"best_ask\":\"0.51\"}, {\"asset_id\":\"58313761654877669244690227616056238030136603415514645252000528337391143520538\", \"price\":\"0.5\", \"size\":\"225.11\", \"side\":\"SELL\", \"hash\":\"d226f44a41833c3383ddee2a616ac21816b886fb\", \"best_bid\":\"0.49\", \"best_ask\":\"0.5\"}], \"timestamp\":\"1785207016045\", \"event_type\":\"price_change\"}","received_at":"2026-07-28T02:50:20.173480Z","schema_version":"clob-market-ws.price_change.v1","sequence":null,"server_hash":null,"server_timestamp":"1785207016045","session_id":"5aad79be415c487c84df42bebd84ee93","source":"clob_market_ws"},"received_at":"2026-07-28T02:50:20.173480Z","record_id":"0d96e1192372d72949b72422d489123edef16fcb9bc134a33bd3a0e1b2d79252","schema_fingerprint":"4aa3821a28b0b7c2400bc59aba4bcc0a76e971dadd19610d3ad38c768e124dc7","schema_version":"edge-lab-recorder.raw.v1","sequence":null,"source":"clob_market_ws"}
{"event_at":"2026-07-28T02:50:16.045000Z","event_fingerprint":"f63e8d79a37e876e65ce6baa93e898aa75ab6fd26938102ef0214010f3213604","payload":{"connection_id":"955646bd8bf740759faf38750c0f263f","event_at":"2026-07-28T02:50:16.045000Z","event_type":"book","frame_hash":"e66e3897af34ac96cbc2296dfce2690bc5581d6a7e78d281f9c6a5f66fe55a70","frame_index":0,"kind":"data","monotonic_ns":309003194557708,"payload":{"asks":[{"price":"0.99","size":"2260.42"},{"price":"0.98","size":"625.41"},{"price":"0.97","size":"419.75"},{"price":"0.96","size":"315"},{"price":"0.95","size":"275.42"},{"price":"0.94","size":"121.09"},{"price":"0.93","size":"98"},{"price":"0.92","size":"80"},{"price":"0.91","size":"75"},{"price":"0.9","size":"267"},{"price":"0.89","size":"57"},{"price":"0.88","size":"40"},{"price":"0.87","size":"41"},{"price":"0.86","size":"47"},{"price":"0.85","size":"109.66"},{"price":"0.84","size":"34"},{"price":"0.83","size":"32"},{"price":"0.82","size":"30"},{"price":"0.81","size":"26"},{"price":"0.8","size":"70"},{"price":"0.79","size":"10"},{"price":"0.78","size":"20"},{"price":"0.77","size":"700"},{"price":"0.76","size":"20"},{"price":"0.75","size":"20"},{"price":"0.74","size":"20"},{"price":"0.73","size":"10"},{"price":"0.72","size":"350"},{"price":"0.71","size":"15"},{"price":"0.7","size":"115"},{"price":"0.69","size":"10"},{"price":"0.68","size":"90"},{"price":"0.67","size":"186"},{"price":"0.66","size":"60"},{"price":"0.65","size":"15"},{"price":"0.64","size":"155"},{"price":"0.63","size":"42.85"},{"price":"0.62","size":"281.25"},{"price":"0.61","size":"21.73"},{"price":"0.6","size":"40.62"},{"price":"0.59","size":"217.01"},{"price":"0.58","size":"123.41"},{"price":"0.57","size":"118.95"},{"price":"0.56","size":"210"},{"price":"0.55","size":"244.78"},{"price":"0.54","size":"249.57"},{"price":"0.53","size":"229.36"},{"price":"0.52","size":"11.25"},{"price":"0.51","size":"36.25"}],"asset_id":"64053005904884194822931764831592250494815136296598204104072528088122126148949","bids":[{"price":"0.01","size":"2220.02"},{"price":"0.02","size":"605"},{"price":"0.03","size":"406"},{"price":"0.04","size":"315"},{"price":"0.05","size":"267"},{"price":"0.06","size":"114"},{"price":"0.07","size":"98"},{"price":"0.08","size":"80"},{"price":"0.09","size":"70"},{"price":"0.1","size":"262"},{"price":"0.11","size":"52"},{"price":"0.12","size":"40"},{"price":"0.13","size":"36"},{"price":"0.14","size":"42"},{"price":"0.15","size":"104.66"},{"price":"0.16","size":"34"},{"price":"0.17","size":"32"},{"price":"0.18","size":"30"},{"price":"0.19","size":"26"},{"price":"0.2","size":"70"},{"price":"0.21","size":"10"},{"price":"0.22","size":"20"},{"price":"0.23","size":"20"},{"price":"0.24","size":"20"},{"price":"0.25","size":"20"},{"price":"0.26","size":"20"},{"price":"0.27","size":"690"},{"price":"0.28","size":"10"},{"price":"0.29","size":"15"},{"price":"0.3","size":"115"},{"price":"0.31","size":"10"},{"price":"0.32","size":"430"},{"price":"0.33","size":"16"},{"price":"0.34","size":"60"},{"price":"0.35","size":"15"},{"price":"0.36","size":"155"},{"price":"0.37","size":"212.85"},{"price":"0.38","size":"196.25"},{"price":"0.39","size":"21.73"},{"price":"0.4","size":"40.62"},{"price":"0.41","size":"117.01"},{"price":"0.42","size":"208.41"},{"price":"0.43","size":"118.95"},{"price":"0.44","size":"115.68"},{"price":"0.45","size":"225.33"},{"price":"0.46","size":"45"},{"price":"0.47","size":"29.67"},{"price":"0.48","size":"211.25"},{"price":"0.49","size":"256.25"},{"price":"0.5","size":"225.11"}],"event_type":"book","hash":"f439b0b3b9a2ad98aabe11a1d12d6a03b8ada5a3","market":"0x0f70d07969bc69eaa97d0987de651885fdca02263688026aa11e7678af8f87aa","timestamp":"1785207016045"},"payload_hash":"36e53f4b3fdffc078d9f4abb5a54bbc37b21586f89f065170f287fa273f13aa9","raw_frame":"{\"market\":\"0x0f70d07969bc69eaa97d0987de651885fdca02263688026aa11e7678af8f87aa\", \"asset_id\":\"64053005904884194822931764831592250494815136296598204104072528088122126148949\", \"bids\":[{\"price\":\"0.01\", \"size\":\"2220.02\"}, {\"price\":\"0.02\", \"size\":\"605\"}, {\"price\":\"0.03\", \"size\":\"406\"}, {\"price\":\"0.04\", \"size\":\"315\"}, {\"price\":\"0.05\", \"size\":\"267\"}, {\"price\":\"0.06\", \"size\":\"114\"}, {\"price\":\"0.07\", \"size\":\"98\"}, {\"price\":\"0.08\", \"size\":\"80\"}, {\"price\":\"0.09\", \"size\":\"70\"}, {\"price\":\"0.1\", \"size\":\"262\"}, {\"price\":\"0.11\", \"size\":\"52\"}, {\"price\":\"0.12\", \"size\":\"40\"}, {\"price\":\"0.13\", \"size\":\"36\"}, {\"price\":\"0.14\", \"size\":\"42\"}, {\"price\":\"0.15\", \"size\":\"104.66\"}, {\"price\":\"0.16\", \"size\":\"34\"}, {\"price\":\"0.17\", \"size\":\"32\"}, {\"price\":\"0.18\", \"size\":\"30\"}, {\"price\":\"0.19\", \"size\":\"26\"}, {\"price\":\"0.2\", \"size\":\"70\"}, {\"price\":\"0.21\", \"size\":\"10\"}, {\"price\":\"0.22\", \"size\":\"20\"}, {\"price\":\"0.23\", \"size\":\"20\"}, {\"price\":\"0.24\", \"size\":\"20\"}, {\"price\":\"0.25\", \"size\":\"20\"}, {\"price\":\"0.26\", \"size\":\"20\"}, {\"price\":\"0.27\", \"size\":\"690\"}, {\"price\":\"0.28\", \"size\":\"10\"}, {\"price\":\"0.29\", \"size\":\"15\"}, {\"price\":\"0.3\", \"size\":\"115\"}, {\"price\":\"0.31\", \"size\":\"10\"}, {\"price\":\"0.32\", \"size\":\"430\"}, {\"price\":\"0.33\", \"size\":\"16\"}, {\"price\":\"0.34\", \"size\":\"60\"}, {\"price\":\"0.35\", \"size\":\"15\"}, {\"price\":\"0.36\", \"size\":\"155\"}, {\"price\":\"0.37\", \"size\":\"212.85\"}, {\"price\":\"0.38\", \"size\":\"196.25\"}, {\"price\":\"0.39\", \"size\":\"21.73\"}, {\"price\":\"0.4\", \"size\":\"40.62\"}, {\"price\":\"0.41\", \"size\":\"117.01\"}, {\"price\":\"0.42\", \"size\":\"208.41\"}, {\"price\":\"0.43\", \"size\":\"118.95\"}, {\"price\":\"0.44\", \"size\":\"115.68\"}, {\"price\":\"0.45\", \"size\":\"225.33\"}, {\"price\":\"0.46\", \"size\":\"45\"}, {\"price\":\"0.47\", \"size\":\"29.67\"}, {\"price\":\"0.48\", \"size\":\"211.25\"}, {\"price\":\"0.49\", \"size\":\"256.25\"}, {\"price\":\"0.5\", \"size\":\"225.11\"}], \"asks\":[{\"price\":\"0.99\", \"size\":\"2260.42\"}, {\"price\":\"0.98\", \"size\":\"625.41\"}, {\"price\":\"0.97\", \"size\":\"419.75\"}, {\"price\":\"0.96\", \"size\":\"315\"}, {\"price\":\"0.95\", \"size\":\"275.42\"}, {\"price\":\"0.94\", \"size\":\"121.09\"}, {\"price\":\"0.93\", \"size\":\"98\"}, {\"price\":\"0.92\", \"size\":\"80\"}, {\"price\":\"0.91\", \"size\":\"75\"}, {\"price\":\"0.9\", \"size\":\"267\"}, {\"price\":\"0.89\", \"size\":\"57\"}, {\"price\":\"0.88\", \"size\":\"40\"}, {\"price\":\"0.87\", \"size\":\"41\"}, {\"price\":\"0.86\", \"size\":\"47\"}, {\"price\":\"0.85\", \"size\":\"109.66\"}, {\"price\":\"0.84\", \"size\":\"34\"}, {\"price\":\"0.83\", \"size\":\"32\"}, {\"price\":\"0.82\", \"size\":\"30\"}, {\"price\":\"0.81\", \"size\":\"26\"}, {\"price\":\"0.8\", \"size\":\"70\"}, {\"price\":\"0.79\", \"size\":\"10\"}, {\"price\":\"0.78\", \"size\":\"20\"}, {\"price\":\"0.77\", \"size\":\"700\"}, {\"price\":\"0.76\", \"size\":\"20\"}, {\"price\":\"0.75\", \"size\":\"20\"}, {\"price\":\"0.74\", \"size\":\"20\"}, {\"price\":\"0.73\", \"size\":\"10\"}, {\"price\":\"0.72\", \"size\":\"350\"}, {\"price\":\"0.71\", \"size\":\"15\"}, {\"price\":\"0.7\", \"size\":\"115\"}, {\"price\":\"0.69\", \"size\":\"10\"}, {\"price\":\"0.68\", \"size\":\"90\"}, {\"price\":\"0.67\", \"size\":\"186\"}, {\"price\":\"0.66\", \"size\":\"60\"}, {\"price\":\"0.65\", \"size\":\"15\"}, {\"price\":\"0.64\", \"size\":\"155\"}, {\"price\":\"0.63\", \"size\":\"42.85\"}, {\"price\":\"0.62\", \"size\":\"281.25\"}, {\"price\":\"0.61\", \"size\":\"21.73\"}, {\"price\":\"0.6\", \"size\":\"40.62\"}, {\"price\":\"0.59\", \"size\":\"217.01\"}, {\"price\":\"0.58\", \"size\":\"123.41\"}, {\"price\":\"0.57\", \"size\":\"118.95\"}, {\"price\":\"0.56\", \"size\":\"210\"}, {\"price\":\"0.55\", \"size\":\"244.78\"}, {\"price\":\"0.54\", \"size\":\"249.57\"}, {\"price\":\"0.53\", \"size\":\"229.36\"}, {\"price\":\"0.52\", \"size\":\"11.25\"}, {\"price\":\"0.51\", \"size\":\"36.25\"}], \"hash\":\"f439b0b3b9a2ad98aabe11a1d12d6a03b8ada5a3\", \"timestamp\":\"1785207016045\", \"event_type\":\"book\"}","received_at":"2026-07-28T02:50:20.180381Z","schema_version":"clob-market-ws.book.v1","sequence":null,"server_hash":"f439b0b3b9a2ad98aabe11a1d12d6a03b8ada5a3","server_timestamp":"1785207016045","session_id":"5aad79be415c487c84df42bebd84ee93","source":"clob_market_ws"},"received_at":"2026-07-28T02:50:20.180381Z","record_id":"c8037ea36656472befdba3f6496a51bc64cb7ff9983874cb9bad6c3a3c15e0d1","schema_fingerprint":"dc2caa1c89c6a7426e2e07ff925910cd4d0a8a223a515d4092d91d6d127aacb6","schema_version":"edge-lab-recorder.raw.v1","sequence":null,"source":"clob_market_ws"}
{"event_at":"2026-07-28T02:50:16.045000Z","event_fingerprint":"9546f1a8b4762cdc7b60d7c77ec362ef3c4206a624ce00b62f85885aec7ba296","payload":{"connection_id":"955646bd8bf740759faf38750c0f263f","event_at":"2026-07-28T02:50:16.045000Z","event_type":"book","frame_hash":"c5025dea4be3513bcd016b1bc6077cf66fad1899985587aa3ef8ba1a2efe1ca8","frame_index":0,"kind":"data","monotonic_ns":309003208096791,"payload":{"asks":[{"price":"0.99","size":"2220.02"},{"price":"0.98","size":"605"},{"price":"0.97","size":"406"},{"price":"0.96","size":"315"},{"price":"0.95","size":"267"},{"price":"0.94","size":"114"},{"price":"0.93","size":"98"},{"price":"0.92","size":"80"},{"price":"0.91","size":"70"},{"price":"0.9","size":"262"},{"price":"0.89","size":"52"},{"price":"0.88","size":"40"},{"price":"0.87","size":"36"},{"price":"0.86","size":"42"},{"price":"0.85","size":"104.66"},{"price":"0.84","size":"34"},{"price":"0.83","size":"32"},{"price":"0.82","size":"30"},{"price":"0.81","size":"26"},{"price":"0.8","size":"70"},{"price":"0.79","size":"10"},{"price":"0.78","size":"20"},{"price":"0.77","size":"20"},{"price":"0.76","size":"20"},{"price":"0.75","size":"20"},{"price":"0.74","size":"20"},{"price":"0.73","size":"690"},{"price":"0.72","size":"10"},{"price":"0.71","size":"15"},{"price":"0.7","size":"115"},{"price":"0.69","size":"10"},{"price":"0.68","size":"430"},{"price":"0.67","size":"16"},{"price":"0.66","size":"60"},{"price":"0.65","size":"15"},{"price":"0.64","size":"155"},{"price":"0.63","size":"212.85"},{"price":"0.62","size":"196.25"},{"price":"0.61","size":"21.73"},{"price":"0.6","size":"40.62"},{"price":"0.59","size":"117.01"},{"price":"0.58","size":"208.41"},{"price":"0.57","size":"118.95"},{"price":"0.56","size":"115.68"},{"price":"0.55","size":"225.33"},{"price":"0.54","size":"45"},{"price":"0.53","size":"29.67"},{"price":"0.52","size":"211.25"},{"price":"0.51","size":"256.25"},{"price":"0.5","size":"225.11"}],"asset_id":"58313761654877669244690227616056238030136603415514645252000528337391143520538","bids":[{"price":"0.01","size":"2260.42"},{"price":"0.02","size":"625.41"},{"price":"0.03","size":"419.75"},{"price":"0.04","size":"315"},{"price":"0.05","size":"275.42"},{"price":"0.06","size":"121.09"},{"price":"0.07","size":"98"},{"price":"0.08","size":"80"},{"price":"0.09","size":"75"},{"price":"0.1","size":"267"},{"price":"0.11","size":"57"},{"price":"0.12","size":"40"},{"price":"0.13","size":"41"},{"price":"0.14","size":"47"},{"price":"0.15","size":"109.66"},{"price":"0.16","size":"34"},{"price":"0.17","size":"32"},{"price":"0.18","size":"30"},{"price":"0.19","size":"26"},{"price":"0.2","size":"70"},{"price":"0.21","size":"10"},{"price":"0.22","size":"20"},{"price":"0.23","size":"700"},{"price":"0.24","size":"20"},{"price":"0.25","size":"20"},{"price":"0.26","size":"20"},{"price":"0.27","size":"10"},{"price":"0.28","size":"350"},{"price":"0.29","size":"15"},{"price":"0.3","size":"115"},{"price":"0.31","size":"10"},{"price":"0.32","size":"90"},{"price":"0.33","size":"186"},{"price":"0.34","size":"60"},{"price":"0.35","size":"15"},{"price":"0.36","size":"155"},{"price":"0.37","size":"42.85"},{"price":"0.38","size":"281.25"},{"price":"0.39","size":"21.73"},{"price":"0.4","size":"40.62"},{"price":"0.41","size":"217.01"},{"price":"0.42","size":"123.41"},{"price":"0.43","size":"118.95"},{"price":"0.44","size":"210"},{"price":"0.45","size":"244.78"},{"price":"0.46","size":"249.57"},{"price":"0.47","size":"229.36"},{"price":"0.48","size":"11.25"},{"price":"0.49","size":"36.25"}],"event_type":"book","hash":"d226f44a41833c3383ddee2a616ac21816b886fb","market":"0x0f70d07969bc69eaa97d0987de651885fdca02263688026aa11e7678af8f87aa","timestamp":"1785207016045"},"payload_hash":"6c453f64f0bf80ee4f86efefc521a48506d8bd9a48f39d2fd547610991599221","raw_frame":"{\"market\":\"0x0f70d07969bc69eaa97d0987de651885fdca02263688026aa11e7678af8f87aa\", \"asset_id\":\"58313761654877669244690227616056238030136603415514645252000528337391143520538\", \"bids\":[{\"price\":\"0.01\", \"size\":\"2260.42\"}, {\"price\":\"0.02\", \"size\":\"625.41\"}, {\"price\":\"0.03\", \"size\":\"419.75\"}, {\"price\":\"0.04\", \"size\":\"315\"}, {\"price\":\"0.05\", \"size\":\"275.42\"}, {\"price\":\"0.06\", \"size\":\"121.09\"}, {\"price\":\"0.07\", \"size\":\"98\"}, {\"price\":\"0.08\", \"size\":\"80\"}, {\"price\":\"0.09\", \"size\":\"75\"}, {\"price\":\"0.1\", \"size\":\"267\"}, {\"price\":\"0.11\", \"size\":\"57\"}, {\"price\":\"0.12\", \"size\":\"40\"}, {\"price\":\"0.13\", \"size\":\"41\"}, {\"price\":\"0.14\", \"size\":\"47\"}, {\"price\":\"0.15\", \"size\":\"109.66\"}, {\"price\":\"0.16\", \"size\":\"34\"}, {\"price\":\"0.17\", \"size\":\"32\"}, {\"price\":\"0.18\", \"size\":\"30\"}, {\"price\":\"0.19\", \"size\":\"26\"}, {\"price\":\"0.2\", \"size\":\"70\"}, {\"price\":\"0.21\", \"size\":\"10\"}, {\"price\":\"0.22\", \"size\":\"20\"}, {\"price\":\"0.23\", \"size\":\"700\"}, {\"price\":\"0.24\", \"size\":\"20\"}, {\"price\":\"0.25\", \"size\":\"20\"}, {\"price\":\"0.26\", \"size\":\"20\"}, {\"price\":\"0.27\", \"size\":\"10\"}, {\"price\":\"0.28\", \"size\":\"350\"}, {\"price\":\"0.29\", \"size\":\"15\"}, {\"price\":\"0.3\", \"size\":\"115\"}, {\"price\":\"0.31\", \"size\":\"10\"}, {\"price\":\"0.32\", \"size\":\"90\"}, {\"price\":\"0.33\", \"size\":\"186\"}, {\"price\":\"0.34\", \"size\":\"60\"}, {\"price\":\"0.35\", \"size\":\"15\"}, {\"price\":\"0.36\", \"size\":\"155\"}, {\"price\":\"0.37\", \"size\":\"42.85\"}, {\"price\":\"0.38\", \"size\":\"281.25\"}, {\"price\":\"0.39\", \"size\":\"21.73\"}, {\"price\":\"0.4\", \"size\":\"40.62\"}, {\"price\":\"0.41\", \"size\":\"217.01\"}, {\"price\":\"0.42\", \"size\":\"123.41\"}, {\"price\":\"0.43\", \"size\":\"118.95\"}, {\"price\":\"0.44\", \"size\":\"210\"}, {\"price\":\"0.45\", \"size\":\"244.78\"}, {\"price\":\"0.46\", \"size\":\"249.57\"}, {\"price\":\"0.47\", \"size\":\"229.36\"}, {\"price\":\"0.48\", \"size\":\"11.25\"}, {\"price\":\"0.49\", \"size\":\"36.25\"}], \"asks\":[{\"price\":\"0.99\", \"size\":\"2220.02\"}, {\"price\":\"0.98\", \"size\":\"605\"}, {\"price\":\"0.97\", \"size\":\"406\"}, {\"price\":\"0.96\", \"size\":\"315\"}, {\"price\":\"0.95\", \"size\":\"267\"}, {\"price\":\"0.94\", \"size\":\"114\"}, {\"price\":\"0.93\", \"size\":\"98\"}, {\"price\":\"0.92\", \"size\":\"80\"}, {\"price\":\"0.91\", \"size\":\"70\"}, {\"price\":\"0.9\", \"size\":\"262\"}, {\"price\":\"0.89\", \"size\":\"52\"}, {\"price\":\"0.88\", \"size\":\"40\"}, {\"price\":\"0.87\", \"size\":\"36\"}, {\"price\":\"0.86\", \"size\":\"42\"}, {\"price\":\"0.85\", \"size\":\"104.66\"}, {\"price\":\"0.84\", \"size\":\"34\"}, {\"price\":\"0.83\", \"size\":\"32\"}, {\"price\":\"0.82\", \"size\":\"30\"}, {\"price\":\"0.81\", \"size\":\"26\"}, {\"price\":\"0.8\", \"size\":\"70\"}, {\"price\":\"0.79\", \"size\":\"10\"}, {\"price\":\"0.78\", \"size\":\"20\"}, {\"price\":\"0.77\", \"size\":\"20\"}, {\"price\":\"0.76\", \"size\":\"20\"}, {\"price\":\"0.75\", \"size\":\"20\"}, {\"price\":\"0.74\", \"size\":\"20\"}, {\"price\":\"0.73\", \"size\":\"690\"}, {\"price\":\"0.72\", \"size\":\"10\"}, {\"price\":\"0.71\", \"size\":\"15\"}, {\"price\":\"0.7\", \"size\":\"115\"}, {\"price\":\"0.69\", \"size\":\"10\"}, {\"price\":\"0.68\", \"size\":\"430\"}, {\"price\":\"0.67\", \"size\":\"16\"}, {\"price\":\"0.66\", \"size\":\"60\"}, {\"price\":\"0.65\", \"size\":\"15\"}, {\"price\":\"0.64\", \"size\":\"155\"}, {\"price\":\"0.63\", \"size\":\"212.85\"}, {\"price\":\"0.62\", \"size\":\"196.25\"}, {\"price\":\"0.61\", \"size\":\"21.73\"}, {\"price\":\"0.6\", \"size\":\"40.62\"}, {\"price\":\"0.59\", \"size\":\"117.01\"}, {\"price\":\"0.58\", \"size\":\"208.41\"}, {\"price\":\"0.57\", \"size\":\"118.95\"}, {\"price\":\"0.56\", \"size\":\"115.68\"}, {\"price\":\"0.55\", \"size\":\"225.33\"}, {\"price\":\"0.54\", \"size\":\"45\"}, {\"price\":\"0.53\", \"size\":\"29.67\"}, {\"price\":\"0.52\", \"size\":\"211.25\"}, {\"price\":\"0.51\", \"size\":\"256.25\"}, {\"price\":\"0.5\", \"size\":\"225.11\"}], \"hash\":\"d226f44a41833c3383ddee2a616ac21816b886fb\", \"timestamp\":\"1785207016045\", \"event_type\":\"book\"}","received_at":"2026-07-28T02:50:20.193921Z","schema_version":"clob-market-ws.book.v1","sequence":null,"server_hash":"d226f44a41833c3383ddee2a616ac21816b886fb","server_timestamp":"1785207016045","session_id":"5aad79be415c487c84df42bebd84ee93","source":"clob_market_ws"},"received_at":"2026-07-28T02:50:20.193921Z","record_id":"a523d2e89dade77a6f15ce3d6e72415dabc31ce9e0212fc77123958eec629885","schema_fingerprint":"dc2caa1c89c6a7426e2e07ff925910cd4d0a8a223a515d4092d91d6d127aacb6","schema_version":"edge-lab-recorder.raw.v1","sequence":null,"source":"clob_market_ws"}
{"event_at":"2026-07-28T02:50:16.214000Z","event_fingerprint":"30e13877c77639fe37e3490e3971931ea1a1cb636a8924c43419d4033fec96dc","payload":{"connection_id":"955646bd8bf740759faf38750c0f263f","event_at":"2026-07-28T02:50:16.214000Z","event_type":"last_trade_price","frame_hash":"5a7f72176a5a236c8ef50dba837690a3f8f118ec168ffcecf959b2f3e434e147","frame_index":0,"kind":"data","monotonic_ns":309003222161458,"payload":{"asset_id":"58313761654877669244690227616056238030136603415514645252000528337391143520538","event_type":"last_trade_price","fee_rate_bps":"0","market":"0x0f70d07969bc69eaa97d0987de651885fdca02263688026aa11e7678af8f87aa","price":"0.5","side":"BUY","size":"5.89","timestamp":"1785207016214","transaction_hash":"0xf7d1f54c60c32a2bde6d6dae70ea66752b50ea37b4eb31b50a63fd85a0f4a832"},"payload_hash":"d4fafe5b404800dab2ef526ee6b6aaee09b0b027eed0332849b7ecddf1828c76","raw_frame":"{\"market\":\"0x0f70d07969bc69eaa97d0987de651885fdca02263688026aa11e7678af8f87aa\", \"asset_id\":\"58313761654877669244690227616056238030136603415514645252000528337391143520538\", \"price\":\"0.5\", \"size\":\"5.89\", \"fee_rate_bps\":\"0\", \"side\":\"BUY\", \"timestamp\":\"1785207016214\", \"event_type\":\"last_trade_price\", \"transaction_hash\":\"0xf7d1f54c60c32a2bde6d6dae70ea66752b50ea37b4eb31b50a63fd85a0f4a832\"}","received_at":"2026-07-28T02:50:20.207986Z","schema_version":"clob-market-ws.last_trade_price.v1","sequence":null,"server_hash":null,"server_timestamp":"1785207016214","session_id":"5aad79be415c487c84df42bebd84ee93","source":"clob_market_ws"},"received_at":"2026-07-28T02:50:20.207986Z","record_id":"5be80ba27e095634f026952247b6115fdb833fa01d8fbc21a39d4e4d08dfbf79","schema_fingerprint":"95ad9be75a4b695cd99991e12b2592bc7346f3f5388a82d0000ba65bc0d9fd0a","schema_version":"edge-lab-recorder.raw.v1","sequence":null,"source":"clob_market_ws"}
{"event_at":"2026-07-28T02:50:17.263000Z","event_fingerprint":"9b62a4ef185c7ff9aa08b6e5936ab164bf61ee301fe7d0cf78232912abf4c3a3","payload":{"connection_id":"955646bd8bf740759faf38750c0f263f","event_at":"2026-07-28T02:50:17.263000Z","event_type":"price_change","frame_hash":"82190f54f050ef5a80550bbdf0f896e90d8c8d79eab60b05f648b28e3c7c062a","frame_index":0,"kind":"data","monotonic_ns":309003229871625,"payload":{"event_type":"price_change","market":"0x0f70d07969bc69eaa97d0987de651885fdca02263688026aa11e7678af8f87aa","price_changes":[{"asset_id":"64053005904884194822931764831592250494815136296598204104072528088122126148949","best_ask":"0.51","best_bid":"0.5","hash":"c3ea895e026019d5987834b303688c294d02c007","price":"0.5","side":"BUY","size":"220.11"},{"asset_id":"58313761654877669244690227616056238030136603415514645252000528337391143520538","best_ask":"0.5","best_bid":"0.49","hash":"fe7ca03346db0d5f2fb154f216b096948a5fb4d2","price":"0.5","side":"SELL","size":"220.11"}],"timestamp":"1785207017263"},"payload_hash":"a050ad1b9aa0dbbfc357b838882dcc88159ffd3d365410889588562bef678164","raw_frame":"{\"market\":\"0x0f70d07969bc69eaa97d0987de651885fdca02263688026aa11e7678af8f87aa\", \"price_changes\":[{\"asset_id\":\"64053005904884194822931764831592250494815136296598204104072528088122126148949\", \"price\":\"0.5\", \"size\":\"220.11\", \"side\":\"BUY\", \"hash\":\"c3ea895e026019d5987834b303688c294d02c007\", \"best_bid\":\"0.5\", \"best_ask\":\"0.51\"}, {\"asset_id\":\"58313761654877669244690227616056238030136603415514645252000528337391143520538\", \"price\":\"0.5\", \"size\":\"220.11\", \"side\":\"SELL\", \"hash\":\"fe7ca03346db0d5f2fb154f216b096948a5fb4d2\", \"best_bid\":\"0.49\", \"best_ask\":\"0.5\"}], \"timestamp\":\"1785207017263\", \"event_type\":\"price_change\"}","received_at":"2026-07-28T02:50:20.215695Z","schema_version":"clob-market-ws.price_change.v1","sequence":null,"server_hash":null,"server_timestamp":"1785207017263","session_id":"5aad79be415c487c84df42bebd84ee93","source":"clob_market_ws"},"received_at":"2026-07-28T02:50:20.215695Z","record_id":"c140c7b1868ae41fcf31016b86e35fc7ee4222f140249fe9b866561fba5854b6","schema_fingerprint":"4aa3821a28b0b7c2400bc59aba4bcc0a76e971dadd19610d3ad38c768e124dc7","schema_version":"edge-lab-recorder.raw.v1","sequence":null,"source":"clob_market_ws"}
{"event_at":"2026-07-28T02:50:17.263000Z","event_fingerprint":"a5cec59caf531fe5ae42eb68a80c7e99cf0f3b49916cd692795bb571911d7b5d","payload":{"connection_id":"955646bd8bf740759faf38750c0f263f","event_at":"2026-07-28T02:50:17.263000Z","event_type":"price_change","frame_hash":"e0a2120ed707fd809aed935b1a6b3691b2fb3f867bbcd275cf28c2c499fefb18","frame_index":0,"kind":"data","monotonic_ns":309003235059000,"payload":{"event_type":"price_change","market":"0x0f70d07969bc69eaa97d0987de651885fdca02263688026aa11e7678af8f87aa","price_changes":[{"asset_id":"58313761654877669244690227616056238030136603415514645252000528337391143520538","best_ask":"0.5","best_bid":"0.49","hash":"fe7ca03346db0d5f2fb154f216b096948a5fb4d2","price":"0.23","side":"BUY","size":"20"},{"asset_id":"64053005904884194822931764831592250494815136296598204104072528088122126148949","best_ask":"0.51","best_bid":"0.5","hash":"c3ea895e026019d5987834b303688c294d02c007","price":"0.77","side":"SELL","size":"20"}],"timestamp":"1785207017263"},"payload_hash":"eacbe175c2f6f363454a54e8821aa0e175ca3237839f24c224d55a01741cbc0b","raw_frame":"{\"market\":\"0x0f70d07969bc69eaa97d0987de651885fdca02263688026aa11e7678af8f87aa\", \"price_changes\":[{\"asset_id\":\"58313761654877669244690227616056238030136603415514645252000528337391143520538\", \"price\":\"0.23\", \"size\":\"20\", \"side\":\"BUY\", \"hash\":\"fe7ca03346db0d5f2fb154f216b096948a5fb4d2\", \"best_bid\":\"0.49\", \"best_ask\":\"0.5\"}, {\"asset_id\":\"64053005904884194822931764831592250494815136296598204104072528088122126148949\", \"price\":\"0.77\", \"size\":\"20\", \"side\":\"SELL\", \"hash\":\"c3ea895e026019d5987834b303688c294d02c007\", \"best_bid\":\"0.5\", \"best_ask\":\"0.51\"}], \"timestamp\":\"1785207017263\", \"event_type\":\"price_change\"}","received_at":"2026-07-28T02:50:20.220877Z","schema_version":"clob-market-ws.price_change.v1","sequence":null,"server_hash":null,"server_timestamp":"1785207017263","session_id":"5aad79be415c487c84df42bebd84ee93","source":"clob_market_ws"},"received_at":"2026-07-28T02:50:20.220877Z","record_id":"5df2553b939b02d8945a75cf6734f111966ef8a8eb6497542d607dfe86d0d529","schema_fingerprint":"4aa3821a28b0b7c2400bc59aba4bcc0a76e971dadd19610d3ad38c768e124dc7","schema_version":"edge-lab-recorder.raw.v1","sequence":null,"source":"clob_market_ws"}
{"event_at":"2026-07-28T02:50:17.263000Z","event_fingerprint":"f4fdcf9de12d0e30bc8260f31f577aff58d67ad4a0c35f5fc7334ba6eb8a397b","payload":{"connection_id":"955646bd8bf740759faf38750c0f263f","event_at":"2026-07-28T02:50:17.263000Z","event_type":"price_change","frame_hash":"9aa06f32643ff8608c0828bb862cbc103aca3014f576a635860178a5454ea90d","frame_index":0,"kind":"data","monotonic_ns":309003239741708,"payload":{"event_type":"price_change","market":"0x0f70d07969bc69eaa97d0987de651885fdca02263688026aa11e7678af8f87aa","price_changes":[{"asset_id":"64053005904884194822931764831592250494815136296598204104072528088122126148949","best_ask":"0.51","best_bid":"0.5","hash":"c3ea895e026019d5987834b303688c294d02c007","price":"0.37","side":"BUY","size":"42.85"},{"asset_id":"58313761654877669244690227616056238030136603415514645252000528337391143520538","best_ask":"0.5","best_bid":"0.49","hash":"fe7ca03346db0d5f2fb154f216b096948a5fb4d2","price":"0.63","side":"SELL","size":"42.85"}],"timestamp":"1785207017263"},"payload_hash":"7f7e435d7990f7b4a585a1ad4609c944bc28ea3efb7493bbf3f3b5b8178357d2","raw_frame":"{\"market\":\"0x0f70d07969bc69eaa97d0987de651885fdca02263688026aa11e7678af8f87aa\", \"price_changes\":[{\"asset_id\":\"64053005904884194822931764831592250494815136296598204104072528088122126148949\", \"price\":\"0.37\", \"size\":\"42.85\", \"side\":\"BUY\", \"hash\":\"c3ea895e026019d5987834b303688c294d02c007\", \"best_bid\":\"0.5\", \"best_ask\":\"0.51\"}, {\"asset_id\":\"58313761654877669244690227616056238030136603415514645252000528337391143520538\", \"price\":\"0.63\", \"size\":\"42.85\", \"side\":\"SELL\", \"hash\":\"fe7ca03346db0d5f2fb154f216b096948a5fb4d2\", \"best_bid\":\"0.49\", \"best_ask\":\"0.5\"}], \"timestamp\":\"1785207017263\", \"event_type\":\"price_change\"}","received_at":"2026-07-28T02:50:20.225565Z","schema_version":"clob-market-ws.price_change.v1","sequence":null,"server_hash":null,"server_timestamp":"1785207017263","session_id":"5aad79be415c487c84df42bebd84ee93","source":"clob_market_ws"},"received_at":"2026-07-28T02:50:20.225565Z","record_id":"df6a597fe5dd269c6d133f2af05190d5bae1f93d49f9bb69d23d52a62a2f8a80","schema_fingerprint":"4aa3821a28b0b7c2400bc59aba4bcc0a76e971dadd19610d3ad38c768e124dc7","schema_version":"edge-lab-recorder.raw.v1","sequence":null,"source":"clob_market_ws"}
{"event_at":"2026-07-28T02:50:17.263000Z","event_fingerprint":"c72ad2ff1f501796ae5616700001417e43a5c945838c810a09316d0fe417f04a","payload":{"connection_id":"955646bd8bf740759faf38750c0f263f","event_at":"2026-07-28T02:50:17.263000Z","event_type":"price_change","frame_hash":"5dd4ba893771fc6633ba624470355152d1d799d2907dc68b0a74c0c864ae6569","frame_index":0,"kind":"data","monotonic_ns":309003245052791,"payload":{"event_type":"price_change","market":"0x0f70d07969bc69eaa97d0987de651885fdca02263688026aa11e7678af8f87aa","price_changes":[{"asset_id":"64053005904884194822931764831592250494815136296598204104072528088122126148949","best_ask":"0.51","best_bid":"0.5","hash":"c3ea895e026019d5987834b303688c294d02c007","price":"0.49","side":"BUY","size":"246.25"},{"asset_id":"58313761654877669244690227616056238030136603415514645252000528337391143520538","best_ask":"0.5","best_bid":"0.49","hash":"fe7ca03346db0d5f2fb154f216b096948a5fb4d2","price":"0.51","side":"SELL","size":"246.25"}],"timestamp":"1785207017263"},"payload_hash":"d494d46d89654731e7675f254ae2f3786d37997d01653857b49e3a8ebc45c09a","raw_frame":"{\"market\":\"0x0f70d07969bc69eaa97d0987de651885fdca02263688026aa11e7678af8f87aa\", \"price_changes\":[{\"asset_id\":\"64053005904884194822931764831592250494815136296598204104072528088122126148949\", \"price\":\"0.49\", \"size\":\"246.25\", \"side\":\"BUY\", \"hash\":\"c3ea895e026019d5987834b303688c294d02c007\", \"best_bid\":\"0.5\", \"best_ask\":\"0.51\"}, {\"asset_id\":\"58313761654877669244690227616056238030136603415514645252000528337391143520538\", \"price\":\"0.51\", \"size\":\"246.25\", \"side\":\"SELL\", \"hash\":\"fe7ca03346db0d5f2fb154f216b096948a5fb4d2\", \"best_bid\":\"0.49\", \"best_ask\":\"0.5\"}], \"timestamp\":\"1785207017263\", \"event_type\":\"price_change\"}","received_at":"2026-07-28T02:50:20.230878Z","schema_version":"clob-market-ws.price_change.v1","sequence":null,"server_hash":null,"server_timestamp":"1785207017263","session_id":"5aad79be415c487c84df42bebd84ee93","source":"clob_market_ws"},"received_at":"2026-07-28T02:50:20.230878Z","record_id":"2aef144bf6861c67c28cb72a1e709c77126f683eb2f0cee90f16f7ade1e02cd6","schema_fingerprint":"4aa3821a28b0b7c2400bc59aba4bcc0a76e971dadd19610d3ad38c768e124dc7","schema_version":"edge-lab-recorder.raw.v1","sequence":null,"source":"clob_market_ws"}
{"event_at":"2026-07-28T02:50:17.263000Z","event_fingerprint":"46ea15aaff87a832a67d9118c4fa9fdc7e66725de0f26c1e535b1d28d4c72eea","payload":{"connection_id":"955646bd8bf740759faf38750c0f263f","event_at":"2026-07-28T02:50:17.263000Z","event_type":"price_change","frame_hash":"b2a98271f2f9a077ced0d3f827c45dc1b11a332c5a0fbb6311b2a8723c2691c0","frame_index":0,"kind":"data","monotonic_ns":309003250242291,"payload":{"event_type":"price_change","market":"0x0f70d07969bc69eaa97d0987de651885fdca02263688026aa11e7678af8f87aa","price_changes":[{"asset_id":"64053005904884194822931764831592250494815136296598204104072528088122126148949","best_ask":"0.51","best_bid":"0.5","hash":"c3ea895e026019d5987834b303688c294d02c007","price":"0.32","side":"BUY","size":"90"},{"asset_id":"58313761654877669244690227616056238030136603415514645252000528337391143520538","best_ask":"0.5","best_bid":"0.49","hash":"fe7ca03346db0d5f2fb154f216b096948a5fb4d2","price":"0.68","side":"SELL","size":"90"}],"timestamp":"1785207017263"},"payload_hash":"bbe0ad60e0f16fdcb5e626e4ff75b74f11aaecb946a606d43ba23408a9945656","raw_frame":"{\"market\":\"0x0f70d07969bc69eaa97d0987de651885fdca02263688026aa11e7678af8f87aa\", \"price_changes\":[{\"asset_id\":\"64053005904884194822931764831592250494815136296598204104072528088122126148949\", \"price\":\"0.32\", \"size\":\"90\", \"side\":\"BUY\", \"hash\":\"c3ea895e026019d5987834b303688c294d02c007\", \"best_bid\":\"0.5\", \"best_ask\":\"0.51\"}, {\"asset_id\":\"58313761654877669244690227616056238030136603415514645252000528337391143520538\", \"price\":\"0.68\", \"size\":\"90\", \"side\":\"SELL\", \"hash\":\"fe7ca03346db0d5f2fb154f216b096948a5fb4d2\", \"best_bid\":\"0.49\", \"best_ask\":\"0.5\"}], \"timestamp\":\"1785207017263\", \"event_type\":\"price_change\"}","received_at":"2026-07-28T02:50:20.236067Z","schema_version":"clob-market-ws.price_change.v1","sequence":null,"server_hash":null,"server_timestamp":"1785207017263","session_id":"5aad79be415c487c84df42bebd84ee93","source":"clob_market_ws"},"received_at":"2026-07-28T02:50:20.236067Z","record_id":"4be0dd4eefd8359f41d57fcb33ab8c8f574048427b0d623a83d557b941120d64","schema_fingerprint":"4aa3821a28b0b7c2400bc59aba4bcc0a76e971dadd19610d3ad38c768e124dc7","schema_version":"edge-lab-recorder.raw.v1","sequence":null,"source":"clob_market_ws"}
{"event_at":"2026-07-28T02:50:17.263000Z","event_fingerprint":"40e9577d156752cf6a659eace25ec4a54314143653aef7682bad205305dc4fb7","payload":{"connection_id":"955646bd8bf740759faf38750c0f263f","event_at":"2026-07-28T02:50:17.263000Z","event_type":"price_change","frame_hash":"3dff221b0bf95a1863d9817bc50da876de4db2690df446b19f36bc93fb334323","frame_index":0,"kind":"data","monotonic_ns":309003255377250,"payload":{"event_type":"price_change","market":"0x0f70d07969bc69eaa97d0987de651885fdca02263688026aa11e7678af8f87aa","price_changes":[{"asset_id":"58313761654877669244690227616056238030136603415514645252000528337391143520538","best_ask":"0.5","best_bid":"0.49","hash":"fe7ca03346db0d5f2fb154f216b096948a5fb4d2","price":"0.38","side":"BUY","size":"196.25"},{"asset_id":"64053005904884194822931764831592250494815136296598204104072528088122126148949","best_ask":"0.51","best_bid":"0.5","hash":"c3ea895e026019d5987834b303688c294d02c007","price":"0.62","side":"SELL","size":"196.25"}],"timestamp":"1785207017263"},"payload_hash":"786fd531153d682ca89cdcd1ae2e8dbeac8706c151b42874f0a63e60d09460ea","raw_frame":"{\"market\":\"0x0f70d07969bc69eaa97d0987de651885fdca02263688026aa11e7678af8f87aa\", \"price_changes\":[{\"asset_id\":\"58313761654877669244690227616056238030136603415514645252000528337391143520538\", \"price\":\"0.38\", \"size\":\"196.25\", \"side\":\"BUY\", \"hash\":\"fe7ca03346db0d5f2fb154f216b096948a5fb4d2\", \"best_bid\":\"0.49\", \"best_ask\":\"0.5\"}, {\"asset_id\":\"64053005904884194822931764831592250494815136296598204104072528088122126148949\", \"price\":\"0.62\", \"size\":\"196.25\", \"side\":\"SELL\", \"hash\":\"c3ea895e026019d5987834b303688c294d02c007\", \"best_bid\":\"0.5\", \"best_ask\":\"0.51\"}], \"timestamp\":\"1785207017263\", \"event_type\":\"price_change\"}","received_at":"2026-07-28T02:50:20.241201Z","schema_version":"clob-market-ws.price_change.v1","sequence":null,"server_hash":null,"server_timestamp":"1785207017263","session_id":"5aad79be415c487c84df42bebd84ee93","source":"clob_market_ws"},"received_at":"2026-07-28T02:50:20.241201Z","record_id":"6d72b59e4f01e1b936a0e525559c5a53b1c4834f7218496be66d60416499e9b0","schema_fingerprint":"4aa3821a28b0b7c2400bc59aba4bcc0a76e971dadd19610d3ad38c768e124dc7","schema_version":"edge-lab-recorder.raw.v1","sequence":null,"source":"clob_market_ws"}
{"event_at":"2026-07-28T02:50:17.263000Z","event_fingerprint":"bf58802f5e8b8a4c0bc1936f62cb50c83fc73ce5c587e97c8a17058b096148e7","payload":{"connection_id":"955646bd8bf740759faf38750c0f263f","event_at":"2026-07-28T02:50:17.263000Z","event_type":"price_change","frame_hash":"2e57545407de523bf3b43075a74d5f12167e1def3a0b7900f9cf1db382e6b8bb","frame_index":0,"kind":"data","monotonic_ns":309003260237333,"payload":{"event_type":"price_change","market":"0x0f70d07969bc69eaa97d0987de651885fdca02263688026aa11e7678af8f87aa","price_changes":[{"asset_id":"64053005904884194822931764831592250494815136296598204104072528088122126148949","best_ask":"0.51","best_bid":"0.5","hash":"c3ea895e026019d5987834b303688c294d02c007","price":"0.27","side":"BUY","size":"10"},{"asset_id":"58313761654877669244690227616056238030136603415514645252000528337391143520538","best_ask":"0.5","best_bid":"0.49","hash":"fe7ca03346db0d5f2fb154f216b096948a5fb4d2","price":"0.73","side":"SELL","size":"10"}],"timestamp":"1785207017263"},"payload_hash":"11cd61877f8a6abc39384f2fb660a3e37be81c55a44d9aded691cb9f11933f04","raw_frame":"{\"market\":\"0x0f70d07969bc69eaa97d0987de651885fdca02263688026aa11e7678af8f87aa\", \"price_changes\":[{\"asset_id\":\"64053005904884194822931764831592250494815136296598204104072528088122126148949\", \"price\":\"0.27\", \"size\":\"10\", \"side\":\"BUY\", \"hash\":\"c3ea895e026019d5987834b303688c294d02c007\", \"best_bid\":\"0.5\", \"best_ask\":\"0.51\"}, {\"asset_id\":\"58313761654877669244690227616056238030136603415514645252000528337391143520538\", \"price\":\"0.73\", \"size\":\"10\", \"side\":\"SELL\", \"hash\":\"fe7ca03346db0d5f2fb154f216b096948a5fb4d2\", \"best_bid\":\"0.49\", \"best_ask\":\"0.5\"}], \"timestamp\":\"1785207017263\", \"event_type\":\"price_change\"}","received_at":"2026-07-28T02:50:20.246064Z","schema_version":"clob-market-ws.price_change.v1","sequence":null,"server_hash":null,"server_timestamp":"1785207017263","session_id":"5aad79be415c487c84df42bebd84ee93","source":"clob_market_ws"},"received_at":"2026-07-28T02:50:20.246064Z","record_id":"743715f434d4af650bdf579a0b9c165af68238ef029ae6f5327feded63499596","schema_fingerprint":"4aa3821a28b0b7c2400bc59aba4bcc0a76e971dadd19610d3ad38c768e124dc7","schema_version":"edge-lab-recorder.raw.v1","sequence":null,"source":"clob_market_ws"}
{"event_at":"2026-07-28T02:50:17.263000Z","event_fingerprint":"176edcca4348705b654b01553908f6e0bd98453766abe0e9f4f16a678de8541c","payload":{"connection_id":"955646bd8bf740759faf38750c0f263f","event_at":"2026-07-28T02:50:17.263000Z","event_type":"price_change","frame_hash":"6fac0229bf5b2bbb160816801a07a5aa204c1fa3f8f825ebf4f790310ade53e3","frame_index":0,"kind":"data","monotonic_ns":309003263565250,"payload":{"event_type":"price_change","market":"0x0f70d07969bc69eaa97d0987de651885fdca02263688026aa11e7678af8f87aa","price_changes":[{"asset_id":"58313761654877669244690227616056238030136603415514645252000528337391143520538","best_ask":"0.5","best_bid":"0.49","hash":"fe7ca03346db0d5f2fb154f216b096948a5fb4d2","price":"0.33","side":"BUY","size":"16"},{"asset_id":"64053005904884194822931764831592250494815136296598204104072528088122126148949","best_ask":"0.51","best_bid":"0.5","hash":"c3ea895e026019d5987834b303688c294d02c007","price":"0.67","side":"SELL","size":"16"}],"timestamp":"1785207017263"},"payload_hash":"3b0828d97db1f20986965065a89f782f7e01db33bbefacc40fdde408b62ee44b","raw_frame":"{\"market\":\"0x0f70d07969bc69eaa97d0987de651885fdca02263688026aa11e7678af8f87aa\", \"price_changes\":[{\"asset_id\":\"58313761654877669244690227616056238030136603415514645252000528337391143520538\", \"price\":\"0.33\", \"size\":\"16\", \"side\":\"BUY\", \"hash\":\"fe7ca03346db0d5f2fb154f216b096948a5fb4d2\", \"best_bid\":\"0.49\", \"best_ask\":\"0.5\"}, {\"asset_id\":\"64053005904884194822931764831592250494815136296598204104072528088122126148949\", \"price\":\"0.67\", \"size\":\"16\", \"side\":\"SELL\", \"hash\":\"c3ea895e026019d5987834b303688c294d02c007\", \"best_bid\":\"0.5\", \"best_ask\":\"0.51\"}], \"timestamp\":\"1785207017263\", \"event_type\":\"price_change\"}","received_at":"2026-07-28T02:50:20.249392Z","schema_version":"clob-market-ws.price_change.v1","sequence":null,"server_hash":null,"server_timestamp":"1785207017263","session_id":"5aad79be415c487c84df42bebd84ee93","source":"clob_market_ws"},"received_at":"2026-07-28T02:50:20.249392Z","record_id":"a3a151933245bf5a735de8f4b2940e87b52e5a77c4dc626cd7a14eaadbf55ab1","schema_fingerprint":"4aa3821a28b0b7c2400bc59aba4bcc0a76e971dadd19610d3ad38c768e124dc7","schema_version":"edge-lab-recorder.raw.v1","sequence":null,"source":"clob_market_ws"}
{"event_at":"2026-07-28T02:50:17.263000Z","event_fingerprint":"34fa4ccfec9afcd310d6a20d6a7d4fb71083af7cddae661bcf99e7156e1a308b","payload":{"connection_id":"955646bd8bf740759faf38750c0f263f","event_at":"2026-07-28T02:50:17.263000Z","event_type":"price_change","frame_hash":"02f518669269c48f2989a0afca0bd55b95fac5c41bce47d1a141fae09e26b546","frame_index":0,"kind":"data","monotonic_ns":309003266725750,"payload":{"event_type":"price_change","market":"0x0f70d07969bc69eaa97d0987de651885fdca02263688026aa11e7678af8f87aa","price_changes":[{"asset_id":"58313761654877669244690227616056238030136603415514645252000528337391143520538","best_ask":"0.5","best_bid":"0.49","hash":"fe7ca03346db0d5f2fb154f216b096948a5fb4d2","price":"0.45","side":"BUY","size":"224.78"},{"asset_id":"64053005904884194822931764831592250494815136296598204104072528088122126148949","best_ask":"0.51","best_bid":"0.5","hash":"c3ea895e026019d5987834b303688c294d02c007","price":"0.55","side":"SELL","size":"224.78"}],"timestamp":"1785207017263"},"payload_hash":"84e7d597832b619122ae11fbb700a338f2b8df4bc67fab2e71492e9162cb83f0","raw_frame":"{\"market\":\"0x0f70d07969bc69eaa97d0987de651885fdca02263688026aa11e7678af8f87aa\", \"price_changes\":[{\"asset_id\":\"58313761654877669244690227616056238030136603415514645252000528337391143520538\", \"price\":\"0.45\", \"size\":\"224.78\", \"side\":\"BUY\", \"hash\":\"fe7ca03346db0d5f2fb154f216b096948a5fb4d2\", \"best_bid\":\"0.49\", \"best_ask\":\"0.5\"}, {\"asset_id\":\"64053005904884194822931764831592250494815136296598204104072528088122126148949\", \"price\":\"0.55\", \"size\":\"224.78\", \"side\":\"SELL\", \"hash\":\"c3ea895e026019d5987834b303688c294d02c007\", \"best_bid\":\"0.5\", \"best_ask\":\"0.51\"}], \"timestamp\":\"1785207017263\", \"event_type\":\"price_change\"}","received_at":"2026-07-28T02:50:20.252552Z","schema_version":"clob-market-ws.price_change.v1","sequence":null,"server_hash":null,"server_timestamp":"1785207017263","session_id":"5aad79be415c487c84df42bebd84ee93","source":"clob_market_ws"},"received_at":"2026-07-28T02:50:20.252552Z","record_id":"719da06e15a44fadefb8e48b80e592af228a0d5ec89b0b970e9d0d0cf7e09f68","schema_fingerprint":"4aa3821a28b0b7c2400bc59aba4bcc0a76e971dadd19610d3ad38c768e124dc7","schema_version":"edge-lab-recorder.raw.v1","sequence":null,"source":"clob_market_ws"}
{"event_at":"2026-07-28T02:50:17.263000Z","event_fingerprint":"b48b7f4007f4addadd62ebb22c805399ceedd4be6d0077712e8774cef3f4c8f0","payload":{"connection_id":"955646bd8bf740759faf38750c0f263f","event_at":"2026-07-28T02:50:17.263000Z","event_type":"price_change","frame_hash":"b62a8ddf36a5ad3a1a96a71285daaf5e0d8fe302a6ffe00a845c76df3144fa9f","frame_index":0,"kind":"data","monotonic_ns":309003271055958,"payload":{"event_type":"price_change","market":"0x0f70d07969bc69eaa97d0987de651885fdca02263688026aa11e7678af8f87aa","price_changes":[{"asset_id":"58313761654877669244690227616056238030136603415514645252000528337391143520538","best_ask":"0.5","best_bid":"0.49","hash":"fe7ca03346db0d5f2fb154f216b096948a5fb4d2","price":"0.28","side":"BUY","size":"10"},{"asset_id":"64053005904884194822931764831592250494815136296598204104072528088122126148949","best_ask":"0.51","best_bid":"0.5","hash":"c3ea895e026019d5987834b303688c294d02c007","price":"0.72","side":"SELL","size":"10"}],"timestamp":"1785207017263"},"payload_hash":"2d6334d5147f3cc88d2ecced21aadbe02e9f9d1e1311a283773d823b625da99a","raw_frame":"{\"market\":\"0x0f70d07969bc69eaa97d0987de651885fdca02263688026aa11e7678af8f87aa\", \"price_changes\":[{\"asset_id\":\"58313761654877669244690227616056238030136603415514645252000528337391143520538\", \"price\":\"0.28\", \"size\":\"10\", \"side\":\"BUY\", \"hash\":\"fe7ca03346db0d5f2fb154f216b096948a5fb4d2\", \"best_bid\":\"0.49\", \"best_ask\":\"0.5\"}, {\"asset_id\":\"64053005904884194822931764831592250494815136296598204104072528088122126148949\", \"price\":\"0.72\", \"size\":\"10\", \"side\":\"SELL\", \"hash\":\"c3ea895e026019d5987834b303688c294d02c007\", \"best_bid\":\"0.5\", \"best_ask\":\"0.51\"}], \"timestamp\":\"1785207017263\", \"event_type\":\"price_change\"}","received_at":"2026-07-28T02:50:20.256882Z","schema_version":"clob-market-ws.price_change.v1","sequence":null,"server_hash":null,"server_timestamp":"1785207017263","session_id":"5aad79be415c487c84df42bebd84ee93","source":"clob_market_ws"},"received_at":"2026-07-28T02:50:20.256882Z","record_id":"a58a4d24e5b64cf513813564fbb7262ccb5085a9168e7fb5868ce4b01ec49983","schema_fingerprint":"4aa3821a28b0b7c2400bc59aba4bcc0a76e971dadd19610d3ad38c768e124dc7","schema_version":"edge-lab-recorder.raw.v1","sequence":null,"source":"clob_market_ws"}
{"event_at":"2026-07-28T02:50:17.263000Z","event_fingerprint":"016732ea376ee1f54ab46bd75577222c6bb3d2d4b5e7db1048d002e3928b13c9","payload":{"connection_id":"955646bd8bf740759faf38750c0f263f","event_at":"2026-07-28T02:50:17.263000Z","event_type":"price_change","frame_hash":"ab38873ac2ce8884c7c840ad4d791dd642ef7228f4886338e66be9bb3881cff0","frame_index":0,"kind":"data","monotonic_ns":309003274373291,"payload":{"event_type":"price_change","market":"0x0f70d07969bc69eaa97d0987de651885fdca02263688026aa11e7678af8f87aa","price_changes":[{"asset_id":"64053005904884194822931764831592250494815136296598204104072528088122126148949","best_ask":"0.51","best_bid":"0.5","hash":"c3ea895e026019d5987834b303688c294d02c007","price":"0.42","side":"BUY","size":"123.41"},{"asset_id":"58313761654877669244690227616056238030136603415514645252000528337391143520538","best_ask":"0.5","best_bid":"0.49","hash":"fe7ca03346db0d5f2fb154f216b096948a5fb4d2","price":"0.58","side":"SELL","size":"123.41"}],"timestamp":"1785207017263"},"payload_hash":"24116e115d3e8d4859bcc76ead29c9678e35b2019aa1082edda818a9d838dfd8","raw_frame":"{\"market\":\"0x0f70d07969bc69eaa97d0987de651885fdca02263688026aa11e7678af8f87aa\", \"price_changes\":[{\"asset_id\":\"64053005904884194822931764831592250494815136296598204104072528088122126148949\", \"price\":\"0.42\", \"size\":\"123.41\", \"side\":\"BUY\", \"hash\":\"c3ea895e026019d5987834b303688c294d02c007\", \"best_bid\":\"0.5\", \"best_ask\":\"0.51\"}, {\"asset_id\":\"58313761654877669244690227616056238030136603415514645252000528337391143520538\", \"price\":\"0.58\", \"size\":\"123.41\", \"side\":\"SELL\", \"hash\":\"fe7ca03346db0d5f2fb154f216b096948a5fb4d2\", \"best_bid\":\"0.49\", \"best_ask\":\"0.5\"}], \"timestamp\":\"1785207017263\", \"event_type\":\"price_change\"}","received_at":"2026-07-28T02:50:20.260199Z","schema_version":"clob-market-ws.price_change.v1","sequence":null,"server_hash":null,"server_timestamp":"1785207017263","session_id":"5aad79be415c487c84df42bebd84ee93","source":"clob_market_ws"},"received_at":"2026-07-28T02:50:20.260199Z","record_id":"c4b71a3070a8ffbeb71598b464bcefdeb2aec915b69d5682b7b06e9a0f8b2888","schema_fingerprint":"4aa3821a28b0b7c2400bc59aba4bcc0a76e971dadd19610d3ad38c768e124dc7","schema_version":"edge-lab-recorder.raw.v1","sequence":null,"source":"clob_market_ws"}
{"event_at":"2026-07-28T02:50:17.477000Z","event_fingerprint":"c1c5554125dad1ef547b0a6c9f1a2c7c0f0a1fb60cd9c01574edd93e354c2b5e","payload":{"connection_id":"955646bd8bf740759faf38750c0f263f","event_at":"2026-07-28T02:50:17.477000Z","event_type":"price_change","frame_hash":"5c69a04ecd5f3ab1d3eb3e5c95803bf922bb0f8a55b77a50079f94f2364400c0","frame_index":0,"kind":"data","monotonic_ns":309003277209541,"payload":{"event_type":"price_change","market":"0x0f70d07969bc69eaa97d0987de651885fdca02263688026aa11e7678af8f87aa","price_changes":[{"asset_id":"64053005904884194822931764831592250494815136296598204104072528088122126148949","best_ask":"0.51","best_bid":"0.5","hash":"d2e3b9b6ab0ce56826182af4a25d7d48a6ee118f","price":"0.48","side":"BUY","size":"231.25"},{"asset_id":"58313761654877669244690227616056238030136603415514645252000528337391143520538","best_ask":"0.5","best_bid":"0.49","hash":"7d460311bf5d7b8e2a6360c94cf5065951d62a21","price":"0.52","side":"SELL","size":"231.25"}],"timestamp":"1785207017477"},"payload_hash":"82e57835c6eb2aaa62c4d7fb5b5fc56df68e3b51702c2fdd736bee87da3b9546","raw_frame":"{\"market\":\"0x0f70d07969bc69eaa97d0987de651885fdca02263688026aa11e7678af8f87aa\", \"price_changes\":[{\"asset_id\":\"64053005904884194822931764831592250494815136296598204104072528088122126148949\", \"price\":\"0.48\", \"size\":\"231.25\", \"side\":\"BUY\", \"hash\":\"d2e3b9b6ab0ce56826182af4a25d7d48a6ee118f\", \"best_bid\":\"0.5\", \"best_ask\":\"0.51\"}, {\"asset_id\":\"58313761654877669244690227616056238030136603415514645252000528337391143520538\", \"price\":\"0.52\", \"size\":\"231.25\", \"side\":\"SELL\", \"hash\":\"7d460311bf5d7b8e2a6360c94cf5065951d62a21\", \"best_bid\":\"0.49\", \"best_ask\":\"0.5\"}], \"timestamp\":\"1785207017477\", \"event_type\":\"price_change\"}","received_at":"2026-07-28T02:50:20.263037Z","schema_version":"clob-market-ws.price_change.v1","sequence":null,"server_hash":null,"server_timestamp":"1785207017477","session_id":"5aad79be415c487c84df42bebd84ee93","source":"clob_market_ws"},"received_at":"2026-07-28T02:50:20.263037Z","record_id":"29ce9990f242851337fdc57d5c0c3bf4ac8ab3a922da355c7ba2787a3399b2f3","schema_fingerprint":"4aa3821a28b0b7c2400bc59aba4bcc0a76e971dadd19610d3ad38c768e124dc7","schema_version":"edge-lab-recorder.raw.v1","sequence":null,"source":"clob_market_ws"}
{"event_at":"2026-07-28T02:50:17.478000Z","event_fingerprint":"476931e34c886b31f5b547cbfe8788c53b78b31896aa66efd4c3588a29cdad40","payload":{"connection_id":"955646bd8bf740759faf38750c0f263f","event_at":"2026-07-28T02:50:17.478000Z","event_type":"price_change","frame_hash":"59cd27db824a6b96392b2e1309ee61b61493a2233087ea6f0e5160912efb9d37","frame_index":0,"kind":"data","monotonic_ns":309003279139875,"payload":{"event_type":"price_change","market":"0x0f70d07969bc69eaa97d0987de651885fdca02263688026aa11e7678af8f87aa","price_changes":[{"asset_id":"64053005904884194822931764831592250494815136296598204104072528088122126148949","best_ask":"0.51","best_bid":"0.5","hash":"d0a72eb10e33428ecef5924a68897b2972576398","price":"0.36","side":"BUY","size":"325"},{"asset_id":"58313761654877669244690227616056238030136603415514645252000528337391143520538","best_ask":"0.5","best_bid":"0.49","hash":"739b8e01489ad2ab796bc1c4734e7d4ba6ab8db5","price":"0.64","side":"SELL","size":"325"}],"timestamp":"1785207017478"},"payload_hash":"d4da376de86f19dcd5441736f766e5e119bf4024465eaa894306420f0398c3ef","raw_frame":"{\"market\":\"0x0f70d07969bc69eaa97d0987de651885fdca02263688026aa11e7678af8f87aa\", \"price_changes\":[{\"asset_id\":\"64053005904884194822931764831592250494815136296598204104072528088122126148949\", \"price\":\"0.36\", \"size\":\"325\", \"side\":\"BUY\", \"hash\":\"d0a72eb10e33428ecef5924a68897b2972576398\", \"best_bid\":\"0.5\", \"best_ask\":\"0.51\"}, {\"asset_id\":\"58313761654877669244690227616056238030136603415514645252000528337391143520538\", \"price\":\"0.64\", \"size\":\"325\", \"side\":\"SELL\", \"hash\":\"739b8e01489ad2ab796bc1c4734e7d4ba6ab8db5\", \"best_bid\":\"0.49\", \"best_ask\":\"0.5\"}], \"timestamp\":\"1785207017478\", \"event_type\":\"price_change\"}","received_at":"2026-07-28T02:50:20.264968Z","schema_version":"clob-market-ws.price_change.v1","sequence":null,"server_hash":null,"server_timestamp":"1785207017478","session_id":"5aad79be415c487c84df42bebd84ee93","source":"clob_market_ws"},"received_at":"2026-07-28T02:50:20.264968Z","record_id":"47c058ee07c21ff1b37f7703cd18f76efbf82f38128f79660ccbb7cfd3e7ee43","schema_fingerprint":"4aa3821a28b0b7c2400bc59aba4bcc0a76e971dadd19610d3ad38c768e124dc7","schema_version":"edge-lab-recorder.raw.v1","sequence":null,"source":"clob_market_ws"}
{"event_at":"2026-07-28T02:50:17.479000Z","event_fingerprint":"0e00769bade9a06c7baeba0696bbe3b6281556aa1a3ab556fa943781e4511a7d","payload":{"connection_id":"955646bd8bf740759faf38750c0f263f","event_at":"2026-07-28T02:50:17.479000Z","event_type":"price_change","frame_hash":"aed53711dc1266e2b255f9b5871a3674b6af0ce490ffe5f51c37c179346b9d12","frame_index":0,"kind":"data","monotonic_ns":309003282471333,"payload":{"event_type":"price_change","market":"0x0f70d07969bc69eaa97d0987de651885fdca02263688026aa11e7678af8f87aa","price_changes":[{"asset_id":"58313761654877669244690227616056238030136603415514645252000528337391143520538","best_ask":"0.5","best_bid":"0.49","hash":"2e166330a4ca9c8a57c777c740fb77319367194b","price":"0.34","side":"BUY","size":"230"},{"asset_id":"64053005904884194822931764831592250494815136296598204104072528088122126148949","best_ask":"0.51","best_bid":"0.5","hash":"001450728abedec2c4893bb89c2ddd552e102247","price":"0.66","side":"SELL","size":"230"}],"timestamp":"1785207017479"},"payload_hash":"c30dddd7132e7fe964c136a5b6ee883d6d39b6888e5355233de7d47d2baf5598","raw_frame":"{\"market\":\"0x0f70d07969bc69eaa97d0987de651885fdca02263688026aa11e7678af8f87aa\", \"price_changes\":[{\"asset_id\":\"58313761654877669244690227616056238030136603415514645252000528337391143520538\", \"price\":\"0.34\", \"size\":\"230\", \"side\":\"BUY\", \"hash\":\"2e166330a4ca9c8a57c777c740fb77319367194b\", \"best_bid\":\"0.49\", \"best_ask\":\"0.5\"}, {\"asset_id\":\"64053005904884194822931764831592250494815136296598204104072528088122126148949\", \"price\":\"0.66\", \"size\":\"230\", \"side\":\"SELL\", \"hash\":\"001450728abedec2c4893bb89c2ddd552e102247\", \"best_bid\":\"0.5\", \"best_ask\":\"0.51\"}], \"timestamp\":\"1785207017479\", \"event_type\":\"price_change\"}","received_at":"2026-07-28T02:50:20.268299Z","schema_version":"clob-market-ws.price_change.v1","sequence":null,"server_hash":null,"server_timestamp":"1785207017479","session_id":"5aad79be415c487c84df42bebd84ee93","source":"clob_market_ws"},"received_at":"2026-07-28T02:50:20.268299Z","record_id":"44fea922252752db62447a08a3ced0ed066c615dea982a1887d57281f9951b91","schema_fingerprint":"4aa3821a28b0b7c2400bc59aba4bcc0a76e971dadd19610d3ad38c768e124dc7","schema_version":"edge-lab-recorder.raw.v1","sequence":null,"source":"clob_market_ws"}
{"event_at":"2026-07-28T02:50:17.480000Z","event_fingerprint":"6e0df0d4ae454a87d873cd97d17fab03497c98ee315daebae6eb0cf08fe86de0","payload":{"connection_id":"955646bd8bf740759faf38750c0f263f","event_at":"2026-07-28T02:50:17.480000Z","event_type":"price_change","frame_hash":"72b35e4e6b7751282373efe4bd53c2781bf49d43fee5fdc86db7aae39bd49070","frame_index":0,"kind":"data","monotonic_ns":309003285366666,"payload":{"event_type":"price_change","market":"0x0f70d07969bc69eaa97d0987de651885fdca02263688026aa11e7678af8f87aa","price_changes":[{"asset_id":"58313761654877669244690227616056238030136603415514645252000528337391143520538","best_ask":"0.5","best_bid":"0.49","hash":"3017b64a6f4604ec31d9aec0b1dad419794d2080","price":"0.24","side":"BUY","size":"700"},{"asset_id":"64053005904884194822931764831592250494815136296598204104072528088122126148949","best_ask":"0.51","best_bid":"0.5","hash":"562ad4a45be0e7bb6d6ba8405a670d9c48c14bfe","price":"0.76","side":"SELL","size":"700"}],"timestamp":"1785207017480"},"payload_hash":"f2c80ede3483f412fc52ab6aa0aed2b621f5929abcd156893ab19b2ffdd7f407","raw_frame":"{\"market\":\"0x0f70d07969bc69eaa97d0987de651885fdca02263688026aa11e7678af8f87aa\", \"price_changes\":[{\"asset_id\":\"58313761654877669244690227616056238030136603415514645252000528337391143520538\", \"price\":\"0.24\", \"size\":\"700\", \"side\":\"BUY\", \"hash\":\"3017b64a6f4604ec31d9aec0b1dad419794d2080\", \"best_bid\":\"0.49\", \"best_ask\":\"0.5\"}, {\"asset_id\":\"64053005904884194822931764831592250494815136296598204104072528088122126148949\", \"price\":\"0.76\", \"size\":\"700\", \"side\":\"SELL\", \"hash\":\"562ad4a45be0e7bb6d6ba8405a670d9c48c14bfe\", \"best_bid\":\"0.5\", \"best_ask\":\"0.51\"}], \"timestamp\":\"1785207017480\", \"event_type\":\"price_change\"}","received_at":"2026-07-28T02:50:20.271195Z","schema_version":"clob-market-ws.price_change.v1","sequence":null,"server_hash":null,"server_timestamp":"1785207017480","session_id":"5aad79be415c487c84df42bebd84ee93","source":"clob_market_ws"},"received_at":"2026-07-28T02:50:20.271195Z","record_id":"ab5d23ceada084357614fbc5971b47382afaceb367b094ee5ed67d9d2aaf8e2d","schema_fingerprint":"4aa3821a28b0b7c2400bc59aba4bcc0a76e971dadd19610d3ad38c768e124dc7","schema_version":"edge-lab-recorder.raw.v1","sequence":null,"source":"clob_market_ws"}
{"event_at":"2026-07-28T02:50:17.481000Z","event_fingerprint":"7bddc1f435a86b87d424a78af1844e54877e2639c94d948a186e18a86a2c6414","payload":{"connection_id":"955646bd8bf740759faf38750c0f263f","event_at":"2026-07-28T02:50:17.481000Z","event_type":"price_change","frame_hash":"9128c8a7bff6a71df11609393957253865d73d80bbae4a1b342ace4a4a97ac90","frame_index":0,"kind":"data","monotonic_ns":309003287262375,"payload":{"event_type":"price_change","market":"0x0f70d07969bc69eaa97d0987de651885fdca02263688026aa11e7678af8f87aa","price_changes":[{"asset_id":"58313761654877669244690227616056238030136603415514645252000528337391143520538","best_ask":"0.5","best_bid":"0.49","hash":"02296ee7f327ce7418b9d1f9893cadb26480145c","price":"0.48","side":"BUY","size":"16.25"},{"asset_id":"64053005904884194822931764831592250494815136296598204104072528088122126148949","best_ask":"0.51","best_bid":"0.5","hash":"b108a486b15e417b15075c88b631f6071dffdb9b","price":"0.52","side":"SELL","size":"16.25"}],"timestamp":"1785207017481"},"payload_hash":"9f4807203f353235324e03845eda3dc33334ab33f9f155db85025b1358171f53","raw_frame":"{\"market\":\"0x0f70d07969bc69eaa97d0987de651885fdca02263688026aa11e7678af8f87aa\", \"price_changes\":[{\"asset_id\":\"58313761654877669244690227616056238030136603415514645252000528337391143520538\", \"price\":\"0.48\", \"size\":\"16.25\", \"side\":\"BUY\", \"hash\":\"02296ee7f327ce7418b9d1f9893cadb26480145c\", \"best_bid\":\"0.49\", \"best_ask\":\"0.5\"}, {\"asset_id\":\"64053005904884194822931764831592250494815136296598204104072528088122126148949\", \"price\":\"0.52\", \"size\":\"16.25\", \"side\":\"SELL\", \"hash\":\"b108a486b15e417b15075c88b631f6071dffdb9b\", \"best_bid\":\"0.5\", \"best_ask\":\"0.51\"}], \"timestamp\":\"1785207017481\", \"event_type\":\"price_change\"}","received_at":"2026-07-28T02:50:20.273085Z","schema_version":"clob-market-ws.price_change.v1","sequence":null,"server_hash":null,"server_timestamp":"1785207017481","session_id":"5aad79be415c487c84df42bebd84ee93","source":"clob_market_ws"},"received_at":"2026-07-28T02:50:20.273085Z","record_id":"8573f5021993406228bfbf84682cd10bd41cea3c8c157121919f9634074f2222","schema_fingerprint":"4aa3821a28b0b7c2400bc59aba4bcc0a76e971dadd19610d3ad38c768e124dc7","schema_version":"edge-lab-recorder.raw.v1","sequence":null,"source":"clob_market_ws"}
{"event_at":"2026-07-28T02:50:17.482000Z","event_fingerprint":"eae9420d1b3c004e4c6b779d75e880aee7fe5f61f9844a572546a18f440e6b01","payload":{"connection_id":"955646bd8bf740759faf38750c0f263f","event_at":"2026-07-28T02:50:17.482000Z","event_type":"price_change","frame_hash":"aff78e4d5cc94f1345200d7ba2fdefd8e18bb95bf8b462d5f0121f25ddec81d6","frame_index":0,"kind":"data","monotonic_ns":309003289710958,"payload":{"event_type":"price_change","market":"0x0f70d07969bc69eaa97d0987de651885fdca02263688026aa11e7678af8f87aa","price_changes":[{"asset_id":"58313761654877669244690227616056238030136603415514645252000528337391143520538","best_ask":"0.5","best_bid":"0.49","hash":"f46e2c770761c91fc614c7222dcc42b2bdcbbfc2","price":"0.29","side":"BUY","size":"355"},{"asset_id":"64053005904884194822931764831592250494815136296598204104072528088122126148949","best_ask":"0.51","best_bid":"0.5","hash":"baf259e1765b68320f755acac2661665b4c95b9c","price":"0.71","side":"SELL","size":"355"}],"timestamp":"1785207017482"},"payload_hash":"aa346cdeca0298d8763979c802fdc29dc683b4e80d7808456467b5daf8bffe2b","raw_frame":"{\"market\":\"0x0f70d07969bc69eaa97d0987de651885fdca02263688026aa11e7678af8f87aa\", \"price_changes\":[{\"asset_id\":\"58313761654877669244690227616056238030136603415514645252000528337391143520538\", \"price\":\"0.29\", \"size\":\"355\", \"side\":\"BUY\", \"hash\":\"f46e2c770761c91fc614c7222dcc42b2bdcbbfc2\", \"best_bid\":\"0.49\", \"best_ask\":\"0.5\"}, {\"asset_id\":\"64053005904884194822931764831592250494815136296598204104072528088122126148949\", \"price\":\"0.71\", \"size\":\"355\", \"side\":\"SELL\", \"hash\":\"baf259e1765b68320f755acac2661665b4c95b9c\", \"best_bid\":\"0.5\", \"best_ask\":\"0.51\"}], \"timestamp\":\"1785207017482\", \"event_type\":\"price_change\"}","received_at":"2026-07-28T02:50:20.275540Z","schema_version":"clob-market-ws.price_change.v1","sequence":null,"server_hash":null,"server_timestamp":"1785207017482","session_id":"5aad79be415c487c84df42bebd84ee93","source":"clob_market_ws"},"received_at":"2026-07-28T02:50:20.275540Z","record_id":"b9ad50599b25dc6bd12f532a6f067f7903449abc1c8eb022dd02ee115f94b738","schema_fingerprint":"4aa3821a28b0b7c2400bc59aba4bcc0a76e971dadd19610d3ad38c768e124dc7","schema_version":"edge-lab-recorder.raw.v1","sequence":null,"source":"clob_market_ws"}
{"event_at":"2026-07-28T02:50:17.483000Z","event_fingerprint":"af07aa35bb687d0f189f4ac43d33527c155c457cee204df9a8ccde56b31f6511","payload":{"connection_id":"955646bd8bf740759faf38750c0f263f","event_at":"2026-07-28T02:50:17.483000Z","event_type":"price_change","frame_hash":"2c577f2b149a4ea79ae445df1db25d5d1b2ee0f683cd3716f6b989b6536fafaa","frame_index":0,"kind":"data","monotonic_ns":309003291695750,"payload":{"event_type":"price_change","market":"0x0f70d07969bc69eaa97d0987de651885fdca02263688026aa11e7678af8f87aa","price_changes":[{"asset_id":"64053005904884194822931764831592250494815136296598204104072528088122126148949","best_ask":"0.51","best_bid":"0.5","hash":"6355205be5caccafbd28b92620a75568800bbdf9","price":"0.41","side":"BUY","size":"202.01"},{"asset_id":"58313761654877669244690227616056238030136603415514645252000528337391143520538","best_ask":"0.5","best_bid":"0.49","hash":"855410f33e7c18ea2173cc7608ec38594634a763","price":"0.59","side":"SELL","size":"202.01"}],"timestamp":"1785207017483"},"payload_hash":"b635914a50776384186e8e4cf4e7152226f3cfb6189f636459e0bc08e7cfaba4","raw_frame":"{\"market\":\"0x0f70d07969bc69eaa97d0987de651885fdca02263688026aa11e7678af8f87aa\", \"price_changes\":[{\"asset_id\":\"64053005904884194822931764831592250494815136296598204104072528088122126148949\", \"price\":\"0.41\", \"size\":\"202.01\", \"side\":\"BUY\", \"hash\":\"6355205be5caccafbd28b92620a75568800bbdf9\", \"best_bid\":\"0.5\", \"best_ask\":\"0.51\"}, {\"asset_id\":\"58313761654877669244690227616056238030136603415514645252000528337391143520538\", \"price\":\"0.59\", \"size\":\"202.01\", \"side\":\"SELL\", \"hash\":\"855410f33e7c18ea2173cc7608ec38594634a763\", \"best_bid\":\"0.49\", \"best_ask\":\"0.5\"}], \"timestamp\":\"1785207017483\", \"event_type\":\"price_change\"}","received_at":"2026-07-28T02:50:20.277525Z","schema_version":"clob-market-ws.price_change.v1","sequence":null,"server_hash":null,"server_timestamp":"1785207017483","session_id":"5aad79be415c487c84df42bebd84ee93","source":"clob_market_ws"},"received_at":"2026-07-28T02:50:20.277525Z","record_id":"5ac235c9e37212b7d08417c25a0418fbb51cd84047e29fc8d4f83f31c468451d","schema_fingerprint":"4aa3821a28b0b7c2400bc59aba4bcc0a76e971dadd19610d3ad38c768e124dc7","schema_version":"edge-lab-recorder.raw.v1","sequence":null,"source":"clob_market_ws"}
{"event_at":"2026-07-28T02:50:17.484000Z","event_fingerprint":"6b4fa13e3ff4e3a3de05346612926bd45e5e127cc8a934e9dc13db8dbc72219c","payload":{"connection_id":"955646bd8bf740759faf38750c0f263f","event_at":"2026-07-28T02:50:17.484000Z","event_type":"price_change","frame_hash":"3d6246c1d2e0f51030db19f3cd14fe5f32f477032ec5e35fb9508bd13f4955a5","frame_index":0,"kind":"data","monotonic_ns":309003293478500,"payload":{"event_type":"price_change","market":"0x0f70d07969bc69eaa97d0987de651885fdca02263688026aa11e7678af8f87aa","price_changes":[{"asset_id":"58313761654877669244690227616056238030136603415514645252000528337391143520538","best_ask":"0.5","best_bid":"0.49","hash":"54c7ae1b4e2700f287e265ae2770f0cfec7dfa4a","price":"0.47","side":"BUY","size":"234.36"},{"asset_id":"64053005904884194822931764831592250494815136296598204104072528088122126148949","best_ask":"0.51","best_bid":"0.5","hash":"c66296fc980d18a7dc4642fdc5afe64d00223738","price":"0.53","side":"SELL","size":"234.36"}],"timestamp":"1785207017484"},"payload_hash":"c148161b6ba06f0b86de5b6232b2204fd1599858d0150cf9b331b534d37fe7f3","raw_frame":"{\"market\":\"0x0f70d07969bc69eaa97d0987de651885fdca02263688026aa11e7678af8f87aa\", \"price_changes\":[{\"asset_id\":\"58313761654877669244690227616056238030136603415514645252000528337391143520538\", \"price\":\"0.47\", \"size\":\"234.36\", \"side\":\"BUY\", \"hash\":\"54c7ae1b4e2700f287e265ae2770f0cfec7dfa4a\", \"best_bid\":\"0.49\", \"best_ask\":\"0.5\"}, {\"asset_id\":\"64053005904884194822931764831592250494815136296598204104072528088122126148949\", \"price\":\"0.53\", \"size\":\"234.36\", \"side\":\"SELL\", \"hash\":\"c66296fc980d18a7dc4642fdc5afe64d00223738\", \"best_bid\":\"0.5\", \"best_ask\":\"0.51\"}], \"timestamp\":\"1785207017484\", \"event_type\":\"price_change\"}","received_at":"2026-07-28T02:50:20.279307Z","schema_version":"clob-market-ws.price_change.v1","sequence":null,"server_hash":null,"server_timestamp":"1785207017484","session_id":"5aad79be415c487c84df42bebd84ee93","source":"clob_market_ws"},"received_at":"2026-07-28T02:50:20.279307Z","record_id":"de52a9d2b85dc6dd127edca3bde1cf29185872453255d81be6bc17b058d1b1c5","schema_fingerprint":"4aa3821a28b0b7c2400bc59aba4bcc0a76e971dadd19610d3ad38c768e124dc7","schema_version":"edge-lab-recorder.raw.v1","sequence":null,"source":"clob_market_ws"}
{"event_at":"2026-07-28T02:50:17.484000Z","event_fingerprint":"1318dd3e9d0ac3bfc0c685b615dceb0e900bd0954fdf2953dd874575ebe966f7","payload":{"connection_id":"955646bd8bf740759faf38750c0f263f","event_at":"2026-07-28T02:50:17.484000Z","event_type":"price_change","frame_hash":"2c009ac72532b90f5ff03d28c3ea0168ccce62472b7abe5cf78a9c2e9664ae24","frame_index":0,"kind":"data","monotonic_ns":309003295475833,"payload":{"event_type":"price_change","market":"0x0f70d07969bc69eaa97d0987de651885fdca02263688026aa11e7678af8f87aa","price_changes":[{"asset_id":"58313761654877669244690227616056238030136603415514645252000528337391143520538","best_ask":"0.5","best_bid":"0.49","hash":"4467958ebdb83dc8e1d93f7862fc3ceafbbf7ef8","price":"0.39","side":"BUY","size":"106.73"},{"asset_id":"64053005904884194822931764831592250494815136296598204104072528088122126148949","best_ask":"0.51","best_bid":"0.5","hash":"3b63763a6049e38f30bdd01614e008847f8f283a","price":"0.61","side":"SELL","size":"106.73"}],"timestamp":"1785207017484"},"payload_hash":"7a97c2fbc9fac4bdc634001c62c7f94b267dfbd7eed2a0d0a2b79aef6e2a8840","raw_frame":"{\"market\":\"0x0f70d07969bc69eaa97d0987de651885fdca02263688026aa11e7678af8f87aa\", \"price_changes\":[{\"asset_id\":\"58313761654877669244690227616056238030136603415514645252000528337391143520538\", \"price\":\"0.39\", \"size\":\"106.73\", \"side\":\"BUY\", \"hash\":\"4467958ebdb83dc8e1d93f7862fc3ceafbbf7ef8\", \"best_bid\":\"0.49\", \"best_ask\":\"0.5\"}, {\"asset_id\":\"64053005904884194822931764831592250494815136296598204104072528088122126148949\", \"price\":\"0.61\", \"size\":\"106.73\", \"side\":\"SELL\", \"hash\":\"3b63763a6049e38f30bdd01614e008847f8f283a\", \"best_bid\":\"0.5\", \"best_ask\":\"0.51\"}], \"timestamp\":\"1785207017484\", \"event_type\":\"price_change\"}","received_at":"2026-07-28T02:50:20.281304Z","schema_version":"clob-market-ws.price_change.v1","sequence":null,"server_hash":null,"server_timestamp":"1785207017484","session_id":"5aad79be415c487c84df42bebd84ee93","source":"clob_market_ws"},"received_at":"2026-07-28T02:50:20.281304Z","record_id":"ec175fb2012c6914caa5242e55d4936168f12cec37be4de818ed6cfa5f5a9559","schema_fingerprint":"4aa3821a28b0b7c2400bc59aba4bcc0a76e971dadd19610d3ad38c768e124dc7","schema_version":"edge-lab-recorder.raw.v1","sequence":null,"source":"clob_market_ws"}
{"event_at":"2026-07-28T02:50:17.485000Z","event_fingerprint":"077259d3b000a5f1d2b2d113a7991aacef4d88233a9106da5eafa85897796f25","payload":{"connection_id":"955646bd8bf740759faf38750c0f263f","event_at":"2026-07-28T02:50:17.485000Z","event_type":"price_change","frame_hash":"6527886f4c67ca6bf04ab04117d912c37116e7aac4eab4d62bb47654d0d0445d","frame_index":0,"kind":"data","monotonic_ns":309003297696000,"payload":{"event_type":"price_change","market":"0x0f70d07969bc69eaa97d0987de651885fdca02263688026aa11e7678af8f87aa","price_changes":[{"asset_id":"58313761654877669244690227616056238030136603415514645252000528337391143520538","best_ask":"0.5","best_bid":"0.49","hash":"94cd6b7f8ae3c1168266757ab5e214e55bd439a5","price":"0.46","side":"BUY","size":"259.57"},{"asset_id":"64053005904884194822931764831592250494815136296598204104072528088122126148949","best_ask":"0.51","best_bid":"0.5","hash":"dda63ba9002ccd046e185d1eca12d7cd2029a63a","price":"0.54","side":"SELL","size":"259.57"}],"timestamp":"1785207017485"},"payload_hash":"187347944c49c6f8b9f8c49c8f8eafb84331f36e2b2109edf73bc500eb9413df","raw_frame":"{\"market\":\"0x0f70d07969bc69eaa97d0987de651885fdca02263688026aa11e7678af8f87aa\", \"price_changes\":[{\"asset_id\":\"58313761654877669244690227616056238030136603415514645252000528337391143520538\", \"price\":\"0.46\", \"size\":\"259.57\", \"side\":\"BUY\", \"hash\":\"94cd6b7f8ae3c1168266757ab5e214e55bd439a5\", \"best_bid\":\"0.49\", \"best_ask\":\"0.5\"}, {\"asset_id\":\"64053005904884194822931764831592250494815136296598204104072528088122126148949\", \"price\":\"0.54\", \"size\":\"259.57\", \"side\":\"SELL\", \"hash\":\"dda63ba9002ccd046e185d1eca12d7cd2029a63a\", \"best_bid\":\"0.5\", \"best_ask\":\"0.51\"}], \"timestamp\":\"1785207017485\", \"event_type\":\"price_change\"}","received_at":"2026-07-28T02:50:20.283525Z","schema_version":"clob-market-ws.price_change.v1","sequence":null,"server_hash":null,"server_timestamp":"1785207017485","session_id":"5aad79be415c487c84df42bebd84ee93","source":"clob_market_ws"},"received_at":"2026-07-28T02:50:20.283525Z","record_id":"7c814aae1f7f25ed2627144b85c348a71639e7e09a9c3864059595de7c639a73","schema_fingerprint":"4aa3821a28b0b7c2400bc59aba4bcc0a76e971dadd19610d3ad38c768e124dc7","schema_version":"edge-lab-recorder.raw.v1","sequence":null,"source":"clob_market_ws"}
{"event_at":"2026-07-28T02:50:17.486000Z","event_fingerprint":"82e83b1141690b2678d75b787b8cef8b4a5b8cfe31d1b3a830152a3133acf5f6","payload":{"connection_id":"955646bd8bf740759faf38750c0f263f","event_at":"2026-07-28T02:50:17.486000Z","event_type":"price_change","frame_hash":"0c3114c1c1f504fcd2a74ea756136b8198271f43bfd79c11abfe5a6bde26e266","frame_index":0,"kind":"data","monotonic_ns":309003299393000,"payload":{"event_type":"price_change","market":"0x0f70d07969bc69eaa97d0987de651885fdca02263688026aa11e7678af8f87aa","price_changes":[{"asset_id":"64053005904884194822931764831592250494815136296598204104072528088122126148949","best_ask":"0.51","best_bid":"0.5","hash":"953c5bfca0548d04c5baba7b21603ff14c359951","price":"0.31","side":"BUY","size":"350"},{"asset_id":"58313761654877669244690227616056238030136603415514645252000528337391143520538","best_ask":"0.5","best_bid":"0.49","hash":"3628376ae8add07d4e600908ffa781d54e7c9fba","price":"0.69","side":"SELL","size":"350"}],"timestamp":"1785207017486"},"payload_hash":"9f936ff3de79cfe1af905511d915dc13098dceb5af1b6bca3b67f1e3161970c0","raw_frame":"{\"market\":\"0x0f70d07969bc69eaa97d0987de651885fdca02263688026aa11e7678af8f87aa\", \"price_changes\":[{\"asset_id\":\"64053005904884194822931764831592250494815136296598204104072528088122126148949\", \"price\":\"0.31\", \"size\":\"350\", \"side\":\"BUY\", \"hash\":\"953c5bfca0548d04c5baba7b21603ff14c359951\", \"best_bid\":\"0.5\", \"best_ask\":\"0.51\"}, {\"asset_id\":\"58313761654877669244690227616056238030136603415514645252000528337391143520538\", \"price\":\"0.69\", \"size\":\"350\", \"side\":\"SELL\", \"hash\":\"3628376ae8add07d4e600908ffa781d54e7c9fba\", \"best_bid\":\"0.49\", \"best_ask\":\"0.5\"}], \"timestamp\":\"1785207017486\", \"event_type\":\"price_change\"}","received_at":"2026-07-28T02:50:20.285222Z","schema_version":"clob-market-ws.price_change.v1","sequence":null,"server_hash":null,"server_timestamp":"1785207017486","session_id":"5aad79be415c487c84df42bebd84ee93","source":"clob_market_ws"},"received_at":"2026-07-28T02:50:20.285222Z","record_id":"e5856ece5de7f684e20eac6d256663a5a3489f4a809dd37aea97911cea02c1f4","schema_fingerprint":"4aa3821a28b0b7c2400bc59aba4bcc0a76e971dadd19610d3ad38c768e124dc7","schema_version":"edge-lab-recorder.raw.v1","sequence":null,"source":"clob_market_ws"}
{"event_at":"2026-07-28T02:50:17.487000Z","event_fingerprint":"499d91b471f53bfcd196c1226f87154e54cbd3212c6e9b5ec177f7abe0ed5d4c","payload":{"connection_id":"955646bd8bf740759faf38750c0f263f","event_at":"2026-07-28T02:50:17.487000Z","event_type":"price_change","frame_hash":"55ac7be0b7ba91ecc531a1171647b79354492878582d68e1e5f2d6a8dc5dff3d","frame_index":0,"kind":"data","monotonic_ns":309003301388041,"payload":{"event_type":"price_change","market":"0x0f70d07969bc69eaa97d0987de651885fdca02263688026aa11e7678af8f87aa","price_changes":[{"asset_id":"64053005904884194822931764831592250494815136296598204104072528088122126148949","best_ask":"0.51","best_bid":"0.5","hash":"e8867e0f7f5cf0e62ec2d1b5c102a5a20353201b","price":"0.26","side":"BUY","size":"700"},{"asset_id":"58313761654877669244690227616056238030136603415514645252000528337391143520538","best_ask":"0.5","best_bid":"0.49","hash":"0767aaf8e473785abc7d21f77db7f7741e6ecb9e","price":"0.74","side":"SELL","size":"700"}],"timestamp":"1785207017487"},"payload_hash":"42e6e590faa4fbb4cb2e94f7a943407acee879dae481b459d7a9be1529875d9b","raw_frame":"{\"market\":\"0x0f70d07969bc69eaa97d0987de651885fdca02263688026aa11e7678af8f87aa\", \"price_changes\":[{\"asset_id\":\"64053005904884194822931764831592250494815136296598204104072528088122126148949\", \"price\":\"0.26\", \"size\":\"700\", \"side\":\"BUY\", \"hash\":\"e8867e0f7f5cf0e62ec2d1b5c102a5a20353201b\", \"best_bid\":\"0.5\", \"best_ask\":\"0.51\"}, {\"asset_id\":\"58313761654877669244690227616056238030136603415514645252000528337391143520538\", \"price\":\"0.74\", \"size\":\"700\", \"side\":\"SELL\", \"hash\":\"0767aaf8e473785abc7d21f77db7f7741e6ecb9e\", \"best_bid\":\"0.49\", \"best_ask\":\"0.5\"}], \"timestamp\":\"1785207017487\", \"event_type\":\"price_change\"}","received_at":"2026-07-28T02:50:20.287217Z","schema_version":"clob-market-ws.price_change.v1","sequence":null,"server_hash":null,"server_timestamp":"1785207017487","session_id":"5aad79be415c487c84df42bebd84ee93","source":"clob_market_ws"},"received_at":"2026-07-28T02:50:20.287217Z","record_id":"2985009e21d14a4837d55553f72f3d7fb4fec6d12135831f7e93ab16c5396428","schema_fingerprint":"4aa3821a28b0b7c2400bc59aba4bcc0a76e971dadd19610d3ad38c768e124dc7","schema_version":"edge-lab-recorder.raw.v1","sequence":null,"source":"clob_market_ws"}
{"event_at":"2026-07-28T02:50:17.855000Z","event_fingerprint":"3d3bebebbcc8a9e986b17775e7513d291a504f137d52ffe2d13cee60e5dd71ee","payload":{"connection_id":"955646bd8bf740759faf38750c0f263f","event_at":"2026-07-28T02:50:17.855000Z","event_type":"price_change","frame_hash":"1561cd9819c90feec7e06ea3ac3cc61bf475c2d1160148fb967a48bf0c903e9c","frame_index":0,"kind":"data","monotonic_ns":309003304195416,"payload":{"event_type":"price_change","market":"0x0f70d07969bc69eaa97d0987de651885fdca02263688026aa11e7678af8f87aa","price_changes":[{"asset_id":"58313761654877669244690227616056238030136603415514645252000528337391143520538","best_ask":"0.5","best_bid":"0.49","hash":"f2d5aef80b49f65dca3da87618975a5ff1368888","price":"0.45","side":"BUY","size":"124.78"},{"asset_id":"64053005904884194822931764831592250494815136296598204104072528088122126148949","best_ask":"0.51","best_bid":"0.5","hash":"392ad84d3d5ac8b1c2d52a453ab57b1661a42d08","price":"0.55","side":"SELL","size":"124.78"}],"timestamp":"1785207017855"},"payload_hash":"6ea6e0d69299faf4403e11e6e0674e1ed070d94e9e1dffd8b33fc29d96e25b4f","raw_frame":"{\"market\":\"0x0f70d07969bc69eaa97d0987de651885fdca02263688026aa11e7678af8f87aa\", \"price_changes\":[{\"asset_id\":\"58313761654877669244690227616056238030136603415514645252000528337391143520538\", \"price\":\"0.45\", \"size\":\"124.78\", \"side\":\"BUY\", \"hash\":\"f2d5aef80b49f65dca3da87618975a5ff1368888\", \"best_bid\":\"0.49\", \"best_ask\":\"0.5\"}, {\"asset_id\":\"64053005904884194822931764831592250494815136296598204104072528088122126148949\", \"price\":\"0.55\", \"size\":\"124.78\", \"side\":\"SELL\", \"hash\":\"392ad84d3d5ac8b1c2d52a453ab57b1661a42d08\", \"best_bid\":\"0.5\", \"best_ask\":\"0.51\"}], \"timestamp\":\"1785207017855\", \"event_type\":\"price_change\"}","received_at":"2026-07-28T02:50:20.290025Z","schema_version":"clob-market-ws.price_change.v1","sequence":null,"server_hash":null,"server_timestamp":"1785207017855","session_id":"5aad79be415c487c84df42bebd84ee93","source":"clob_market_ws"},"received_at":"2026-07-28T02:50:20.290025Z","record_id":"adf5307917aa9a451488be2b1885cf8ffa17cd98f63321500edd5a8b0dbf2c50","schema_fingerprint":"4aa3821a28b0b7c2400bc59aba4bcc0a76e971dadd19610d3ad38c768e124dc7","schema_version":"edge-lab-recorder.raw.v1","sequence":null,"source":"clob_market_ws"}
{"event_at":"2026-07-28T02:50:17.858000Z","event_fingerprint":"3b1da539a862885df7d3db78331393d29ccb79bb432437828269a34b3b2e0a2f","payload":{"connection_id":"955646bd8bf740759faf38750c0f263f","event_at":"2026-07-28T02:50:17.858000Z","event_type":"price_change","frame_hash":"c61bfdd8897b056df63fdd435f6a7c6e5a00fb0daa538d85f128a53e1eae8ab5","frame_index":0,"kind":"data","monotonic_ns":309003305931958,"payload":{"event_type":"price_change","market":"0x0f70d07969bc69eaa97d0987de651885fdca02263688026aa11e7678af8f87aa","price_changes":[{"asset_id":"58313761654877669244690227616056238030136603415514645252000528337391143520538","best_ask":"0.5","best_bid":"0.49","hash":"d9b40563930a3126b033578157cb40eba19d2813","price":"0.45","side":"BUY","size":"24.78"},{"asset_id":"64053005904884194822931764831592250494815136296598204104072528088122126148949","best_ask":"0.51","best_bid":"0.5","hash":"7930affcad78ea59769a0fbdaf09c57f5579e1b3","price":"0.55","side":"SELL","size":"24.78"}],"timestamp":"1785207017858"},"payload_hash":"fb6d1ab07669a65722d67010f5e99f6422e13a3a60f8b0ccc9695fd8ac99fda2","raw_frame":"{\"market\":\"0x0f70d07969bc69eaa97d0987de651885fdca02263688026aa11e7678af8f87aa\", \"price_changes\":[{\"asset_id\":\"58313761654877669244690227616056238030136603415514645252000528337391143520538\", \"price\":\"0.45\", \"size\":\"24.78\", \"side\":\"BUY\", \"hash\":\"d9b40563930a3126b033578157cb40eba19d2813\", \"best_bid\":\"0.49\", \"best_ask\":\"0.5\"}, {\"asset_id\":\"64053005904884194822931764831592250494815136296598204104072528088122126148949\", \"price\":\"0.55\", \"size\":\"24.78\", \"side\":\"SELL\", \"hash\":\"7930affcad78ea59769a0fbdaf09c57f5579e1b3\", \"best_bid\":\"0.5\", \"best_ask\":\"0.51\"}], \"timestamp\":\"1785207017858\", \"event_type\":\"price_change\"}","received_at":"2026-07-28T02:50:20.291761Z","schema_version":"clob-market-ws.price_change.v1","sequence":null,"server_hash":null,"server_timestamp":"1785207017858","session_id":"5aad79be415c487c84df42bebd84ee93","source":"clob_market_ws"},"received_at":"2026-07-28T02:50:20.291761Z","record_id":"553ba09e52315aee8c7c7cc7edf168bfbadc234960b4a18bdcf9c75f4a9c131b","schema_fingerprint":"4aa3821a28b0b7c2400bc59aba4bcc0a76e971dadd19610d3ad38c768e124dc7","schema_version":"edge-lab-recorder.raw.v1","sequence":null,"source":"clob_market_ws"}
{"event_at":"2026-07-28T02:50:17.894000Z","event_fingerprint":"b44f8dfd5bfb30a2474cc9ce93784a0ba964c30528ab893d6ef0ddf7fec4777c","payload":{"connection_id":"955646bd8bf740759faf38750c0f263f","event_at":"2026-07-28T02:50:17.894000Z","event_type":"price_change","frame_hash":"2a890daf9281ada782a7d253ee54df2a7e6c2556c1aa41c8eaf25e02fc216b2d","frame_index":0,"kind":"data","monotonic_ns":309003311005125,"payload":{"event_type":"price_change","market":"0x0f70d07969bc69eaa97d0987de651885fdca02263688026aa11e7678af8f87aa","price_changes":[{"asset_id":"58313761654877669244690227616056238030136603415514645252000528337391143520538","best_ask":"0.5","best_bid":"0.49","hash":"1c476dbd30bf9b845c9fb5708adfaee684092a69","price":"0.48","side":"BUY","size":"21.25"},{"asset_id":"64053005904884194822931764831592250494815136296598204104072528088122126148949","best_ask":"0.51","best_bid":"0.5","hash":"51e72c958117293e35418f6c05b6eb545a84b9a4","price":"0.52","side":"SELL","size":"21.25"}],"timestamp":"1785207017894"},"payload_hash":"0672ec3950bb0212f41b8a70b2040a06aa8699d77fa8ac862395a55e2c30a651","raw_frame":"{\"market\":\"0x0f70d07969bc69eaa97d0987de651885fdca02263688026aa11e7678af8f87aa\", \"price_changes\":[{\"asset_id\":\"58313761654877669244690227616056238030136603415514645252000528337391143520538\", \"price\":\"0.48\", \"size\":\"21.25\", \"side\":\"BUY\", \"hash\":\"1c476dbd30bf9b845c9fb5708adfaee684092a69\", \"best_bid\":\"0.49\", \"best_ask\":\"0.5\"}, {\"asset_id\":\"64053005904884194822931764831592250494815136296598204104072528088122126148949\", \"price\":\"0.52\", \"size\":\"21.25\", \"side\":\"SELL\", \"hash\":\"51e72c958117293e35418f6c05b6eb545a84b9a4\", \"best_bid\":\"0.5\", \"best_ask\":\"0.51\"}], \"timestamp\":\"1785207017894\", \"event_type\":\"price_change\"}","received_at":"2026-07-28T02:50:20.296829Z","schema_version":"clob-market-ws.price_change.v1","sequence":null,"server_hash":null,"server_timestamp":"1785207017894","session_id":"5aad79be415c487c84df42bebd84ee93","source":"clob_market_ws"},"received_at":"2026-07-28T02:50:20.296829Z","record_id":"c86e63c900fd4171f0c005cfeced97044988d28e28945b2cff4e10d7cb43bd74","schema_fingerprint":"4aa3821a28b0b7c2400bc59aba4bcc0a76e971dadd19610d3ad38c768e124dc7","schema_version":"edge-lab-recorder.raw.v1","sequence":null,"source":"clob_market_ws"}
{"event_at":"2026-07-28T02:50:17.894000Z","event_fingerprint":"c834da4a4a5909b8bb1628a776eec442406bbdb56065ab759c53029b12babb39","payload":{"connection_id":"955646bd8bf740759faf38750c0f263f","event_at":"2026-07-28T02:50:17.894000Z","event_type":"price_change","frame_hash":"369e906934945b38c6f1a36264309c39ea9a544800d28b8776a2f792c7ae9b2d","frame_index":0,"kind":"data","monotonic_ns":309003315959291,"payload":{"event_type":"price_change","market":"0x0f70d07969bc69eaa97d0987de651885fdca02263688026aa11e7678af8f87aa","price_changes":[{"asset_id":"58313761654877669244690227616056238030136603415514645252000528337391143520538","best_ask":"0.5","best_bid":"0.49","hash":"ef131dad2e17e9a3f30a63c38a0ab74f2492e20b","price":"0.48","side":"BUY","size":"26.25"},{"asset_id":"64053005904884194822931764831592250494815136296598204104072528088122126148949","best_ask":"0.51","best_bid":"0.5","hash":"9d7c9634fee7dbeb6c6de9c5470b273244e05794","price":"0.52","side":"SELL","size":"26.25"}],"timestamp":"1785207017894"},"payload_hash":"a510dd4e9e86b34788bc9f2c349407ec2baa6fe65f3a582eab0a898f4967cbad","raw_frame":"{\"market\":\"0x0f70d07969bc69eaa97d0987de651885fdca02263688026aa11e7678af8f87aa\", \"price_changes\":[{\"asset_id\":\"58313761654877669244690227616056238030136603415514645252000528337391143520538\", \"price\":\"0.48\", \"size\":\"26.25\", \"side\":\"BUY\", \"hash\":\"ef131dad2e17e9a3f30a63c38a0ab74f2492e20b\", \"best_bid\":\"0.49\", \"best_ask\":\"0.5\"}, {\"asset_id\":\"64053005904884194822931764831592250494815136296598204104072528088122126148949\", \"price\":\"0.52\", \"size\":\"26.25\", \"side\":\"SELL\", \"hash\":\"9d7c9634fee7dbeb6c6de9c5470b273244e05794\", \"best_bid\":\"0.5\", \"best_ask\":\"0.51\"}], \"timestamp\":\"1785207017894\", \"event_type\":\"price_change\"}","received_at":"2026-07-28T02:50:20.301783Z","schema_version":"clob-market-ws.price_change.v1","sequence":null,"server_hash":null,"server_timestamp":"1785207017894","session_id":"5aad79be415c487c84df42bebd84ee93","source":"clob_market_ws"},"received_at":"2026-07-28T02:50:20.301783Z","record_id":"e613f7f1029c11ce4c62b3478c80e9b0d72867964f91111a6c3296f6dd70c0f7","schema_fingerprint":"4aa3821a28b0b7c2400bc59aba4bcc0a76e971dadd19610d3ad38c768e124dc7","schema_version":"edge-lab-recorder.raw.v1","sequence":null,"source":"clob_market_ws"}
{"event_at":"2026-07-28T02:50:17.895000Z","event_fingerprint":"011e2b783dfa490fbca88ccfd547a386375be9b685bb660006b452febeb4a787","payload":{"connection_id":"955646bd8bf740759faf38750c0f263f","event_at":"2026-07-28T02:50:17.895000Z","event_type":"price_change","frame_hash":"9ce02493e93b1d8911ab1a13a027dc375785832e915d63fc75fc958d22e99be2","frame_index":0,"kind":"data","monotonic_ns":309003319391500,"payload":{"event_type":"price_change","market":"0x0f70d07969bc69eaa97d0987de651885fdca02263688026aa11e7678af8f87aa","price_changes":[{"asset_id":"58313761654877669244690227616056238030136603415514645252000528337391143520538","best_ask":"0.5","best_bid":"0.49","hash":"4d33d26a4ee3aca3926061cf46dd3ef3e6db4b08","price":"0.48","side":"BUY","size":"31.25"},{"asset_id":"64053005904884194822931764831592250494815136296598204104072528088122126148949","best_ask":"0.51","best_bid":"0.5","hash":"34e7d46ccc1a1c2ba395e010fd2c3c51ff134a69","price":"0.52","side":"SELL","size":"31.25"}],"timestamp":"1785207017895"},"payload_hash":"b86af00974f7eada5f279a5beeaf390d7108a8f34f771b16b6956c6f4f818051","raw_frame":"{\"market\":\"0x0f70d07969bc69eaa97d0987de651885fdca02263688026aa11e7678af8f87aa\", \"price_changes\":[{\"asset_id\":\"58313761654877669244690227616056238030136603415514645252000528337391143520538\", \"price\":\"0.48\", \"size\":\"31.25\", \"side\":\"BUY\", \"hash\":\"4d33d26a4ee3aca3926061cf46dd3ef3e6db4b08\", \"best_bid\":\"0.49\", \"best_ask\":\"0.5\"}, {\"asset_id\":\"64053005904884194822931764831592250494815136296598204104072528088122126148949\", \"price\":\"0.52\", \"size\":\"31.25\", \"side\":\"SELL\", \"hash\":\"34e7d46ccc1a1c2ba395e010fd2c3c51ff134a69\", \"best_bid\":\"0.5\", \"best_ask\":\"0.51\"}], \"timestamp\":\"1785207017895\", \"event_type\":\"price_change\"}","received_at":"2026-07-28T02:50:20.305214Z","schema_version":"clob-market-ws.price_change.v1","sequence":null,"server_hash":null,"server_timestamp":"1785207017895","session_id":"5aad79be415c487c84df42bebd84ee93","source":"clob_market_ws"},"received_at":"2026-07-28T02:50:20.305214Z","record_id":"3d65fa0929735f349ab6b0525b4f75809c393c38399bc0607412345fcd4c5d2c","schema_fingerprint":"4aa3821a28b0b7c2400bc59aba4bcc0a76e971dadd19610d3ad38c768e124dc7","schema_version":"edge-lab-recorder.raw.v1","sequence":null,"source":"clob_market_ws"}
{"event_at":"2026-07-28T02:50:17.896000Z","event_fingerprint":"4edbfba108cc631f32c756eab9fece5054572fbf936a0069ce948368ed592eb8","payload":{"connection_id":"955646bd8bf740759faf38750c0f263f","event_at":"2026-07-28T02:50:17.896000Z","event_type":"price_change","frame_hash":"598dbe6b861a72ff2965a1b8d518f7b7edc74a837f741ce362de48c4ac36cbce","frame_index":0,"kind":"data","monotonic_ns":309003324326208,"payload":{"event_type":"price_change","market":"0x0f70d07969bc69eaa97d0987de651885fdca02263688026aa11e7678af8f87aa","price_changes":[{"asset_id":"58313761654877669244690227616056238030136603415514645252000528337391143520538","best_ask":"0.5","best_bid":"0.49","hash":"095e882250feca546303d4c6fed4ac6534e92587","price":"0.48","side":"BUY","size":"36.25"},{"asset_id":"64053005904884194822931764831592250494815136296598204104072528088122126148949","best_ask":"0.51","best_bid":"0.5","hash":"4e8dce1a6401fc2bd5540127edd2430c6cd308b5","price":"0.52","side":"SELL","size":"36.25"}],"timestamp":"1785207017896"},"payload_hash":"041913f039e714899b576e1430b1f3fc962320ac65484f2988c15d53cd9fcc53","raw_frame":"{\"market\":\"0x0f70d07969bc69eaa97d0987de651885fdca02263688026aa11e7678af8f87aa\", \"price_changes\":[{\"asset_id\":\"58313761654877669244690227616056238030136603415514645252000528337391143520538\", \"price\":\"0.48\", \"size\":\"36.25\", \"side\":\"BUY\", \"hash\":\"095e882250feca546303d4c6fed4ac6534e92587\", \"best_bid\":\"0.49\", \"best_ask\":\"0.5\"}, {\"asset_id\":\"64053005904884194822931764831592250494815136296598204104072528088122126148949\", \"price\":\"0.52\", \"size\":\"36.25\", \"side\":\"SELL\", \"hash\":\"4e8dce1a6401fc2bd5540127edd2430c6cd308b5\", \"best_bid\":\"0.5\", \"best_ask\":\"0.51\"}], \"timestamp\":\"1785207017896\", \"event_type\":\"price_change\"}","received_at":"2026-07-28T02:50:20.310149Z","schema_version":"clob-market-ws.price_change.v1","sequence":null,"server_hash":null,"server_timestamp":"1785207017896","session_id":"5aad79be415c487c84df42bebd84ee93","source":"clob_market_ws"},"received_at":"2026-07-28T02:50:20.310149Z","record_id":"87266c2ce2e8f034887e8f81a62086847205605cf7806e9a73a3cb0c4e17692d","schema_fingerprint":"4aa3821a28b0b7c2400bc59aba4bcc0a76e971dadd19610d3ad38c768e124dc7","schema_version":"edge-lab-recorder.raw.v1","sequence":null,"source":"clob_market_ws"}
{"event_at":"2026-07-28T02:50:17.897000Z","event_fingerprint":"b80e1b0fc6081f3c2535e82b8f885805422bf28750186d30dd5dbc8c40a39d12","payload":{"connection_id":"955646bd8bf740759faf38750c0f263f","event_at":"2026-07-28T02:50:17.897000Z","event_type":"price_change","frame_hash":"e5bed3861c8897c6faed4ae757235f927a77f4cd889d855e7526d0188aa0f2ab","frame_index":0,"kind":"data","monotonic_ns":309003327581125,"payload":{"event_type":"price_change","market":"0x0f70d07969bc69eaa97d0987de651885fdca02263688026aa11e7678af8f87aa","price_changes":[{"asset_id":"58313761654877669244690227616056238030136603415514645252000528337391143520538","best_ask":"0.5","best_bid":"0.49","hash":"f4ff7063112f307bbef09a3e72c5f7bdfcf221d7","price":"0.48","side":"BUY","size":"41.25"},{"asset_id":"64053005904884194822931764831592250494815136296598204104072528088122126148949","best_ask":"0.51","best_bid":"0.5","hash":"7f4a66620cc41324deb517fed3bf4d2515464c97","price":"0.52","side":"SELL","size":"41.25"}],"timestamp":"1785207017897"},"payload_hash":"1130df229cf8ff363d8d4a51beeaa22124d11a575c1bcc30a46154725adf474f","raw_frame":"{\"market\":\"0x0f70d07969bc69eaa97d0987de651885fdca02263688026aa11e7678af8f87aa\", \"price_changes\":[{\"asset_id\":\"58313761654877669244690227616056238030136603415514645252000528337391143520538\", \"price\":\"0.48\", \"size\":\"41.25\", \"side\":\"BUY\", \"hash\":\"f4ff7063112f307bbef09a3e72c5f7bdfcf221d7\", \"best_bid\":\"0.49\", \"best_ask\":\"0.5\"}, {\"asset_id\":\"64053005904884194822931764831592250494815136296598204104072528088122126148949\", \"price\":\"0.52\", \"size\":\"41.25\", \"side\":\"SELL\", \"hash\":\"7f4a66620cc41324deb517fed3bf4d2515464c97\", \"best_bid\":\"0.5\", \"best_ask\":\"0.51\"}], \"timestamp\":\"1785207017897\", \"event_type\":\"price_change\"}","received_at":"2026-07-28T02:50:20.313404Z","schema_version":"clob-market-ws.price_change.v1","sequence":null,"server_hash":null,"server_timestamp":"1785207017897","session_id":"5aad79be415c487c84df42bebd84ee93","source":"clob_market_ws"},"received_at":"2026-07-28T02:50:20.313404Z","record_id":"1dc69289b2321c376b6472c2356c5c63401a6ad77072d15a17ad5f3441527cdf","schema_fingerprint":"4aa3821a28b0b7c2400bc59aba4bcc0a76e971dadd19610d3ad38c768e124dc7","schema_version":"edge-lab-recorder.raw.v1","sequence":null,"source":"clob_market_ws"}
{"event_at":"2026-07-28T02:50:17.898000Z","event_fingerprint":"12a5b143c19fa296f8f5ed8d30d0bd3210c2aee5099d0aaf178fe473af9acf90","payload":{"connection_id":"955646bd8bf740759faf38750c0f263f","event_at":"2026-07-28T02:50:17.898000Z","event_type":"price_change","frame_hash":"ee8b677de59d96795c44f38de7abf6f041afa163e4c32840572a56730db61c35","frame_index":0,"kind":"data","monotonic_ns":309003330422666,"payload":{"event_type":"price_change","market":"0x0f70d07969bc69eaa97d0987de651885fdca02263688026aa11e7678af8f87aa","price_changes":[{"asset_id":"58313761654877669244690227616056238030136603415514645252000528337391143520538","best_ask":"0.5","best_bid":"0.49","hash":"3d535dc26cc817ee325891494a2164927d57d141","price":"0.48","side":"BUY","size":"46.25"},{"asset_id":"64053005904884194822931764831592250494815136296598204104072528088122126148949","best_ask":"0.51","best_bid":"0.5","hash":"614231745a20a11681947d4aa57376881fb0c795","price":"0.52","side":"SELL","size":"46.25"}],"timestamp":"1785207017898"},"payload_hash":"f4fe0452ccba1ce483f7c99ff6a78185cf9a37280502eebeeff977790a9c8bc6","raw_frame":"{\"market\":\"0x0f70d07969bc69eaa97d0987de651885fdca02263688026aa11e7678af8f87aa\", \"price_changes\":[{\"asset_id\":\"58313761654877669244690227616056238030136603415514645252000528337391143520538\", \"price\":\"0.48\", \"size\":\"46.25\", \"side\":\"BUY\", \"hash\":\"3d535dc26cc817ee325891494a2164927d57d141\", \"best_bid\":\"0.49\", \"best_ask\":\"0.5\"}, {\"asset_id\":\"64053005904884194822931764831592250494815136296598204104072528088122126148949\", \"price\":\"0.52\", \"size\":\"46.25\", \"side\":\"SELL\", \"hash\":\"614231745a20a11681947d4aa57376881fb0c795\", \"best_bid\":\"0.5\", \"best_ask\":\"0.51\"}], \"timestamp\":\"1785207017898\", \"event_type\":\"price_change\"}","received_at":"2026-07-28T02:50:20.316246Z","schema_version":"clob-market-ws.price_change.v1","sequence":null,"server_hash":null,"server_timestamp":"1785207017898","session_id":"5aad79be415c487c84df42bebd84ee93","source":"clob_market_ws"},"received_at":"2026-07-28T02:50:20.316246Z","record_id":"982ad2d44432a9ba881a0a36a6bacb79f839cf52abdc2e400ace540eec631385","schema_fingerprint":"4aa3821a28b0b7c2400bc59aba4bcc0a76e971dadd19610d3ad38c768e124dc7","schema_version":"edge-lab-recorder.raw.v1","sequence":null,"source":"clob_market_ws"}
{"event_at":"2026-07-28T02:50:17.899000Z","event_fingerprint":"3d236bf287f04775147914bcc427c92f9180bd5b18a94d83f31400d7b2bacc41","payload":{"connection_id":"955646bd8bf740759faf38750c0f263f","event_at":"2026-07-28T02:50:17.899000Z","event_type":"price_change","frame_hash":"06c1056eb0aad658c7ef0184f761cfe6e216af40699b1d61311e24074d7a0ab6","frame_index":0,"kind":"data","monotonic_ns":309003335026458,"payload":{"event_type":"price_change","market":"0x0f70d07969bc69eaa97d0987de651885fdca02263688026aa11e7678af8f87aa","price_changes":[{"asset_id":"58313761654877669244690227616056238030136603415514645252000528337391143520538","best_ask":"0.5","best_bid":"0.49","hash":"060357939f65de65d3a29a9be5d96f6093c24bc8","price":"0.48","side":"BUY","size":"51.25"},{"asset_id":"64053005904884194822931764831592250494815136296598204104072528088122126148949","best_ask":"0.51","best_bid":"0.5","hash":"bf5048db4b5bcc06251c6e38733a1b0c819dd210","price":"0.52","side":"SELL","size":"51.25"}],"timestamp":"1785207017899"},"payload_hash":"9ee93536eb7f9c5de60b4a38bf0152ea27cc19ab982c59836f11777232c9a3fc","raw_frame":"{\"market\":\"0x0f70d07969bc69eaa97d0987de651885fdca02263688026aa11e7678af8f87aa\", \"price_changes\":[{\"asset_id\":\"58313761654877669244690227616056238030136603415514645252000528337391143520538\", \"price\":\"0.48\", \"size\":\"51.25\", \"side\":\"BUY\", \"hash\":\"060357939f65de65d3a29a9be5d96f6093c24bc8\", \"best_bid\":\"0.49\", \"best_ask\":\"0.5\"}, {\"asset_id\":\"64053005904884194822931764831592250494815136296598204104072528088122126148949\", \"price\":\"0.52\", \"size\":\"51.25\", \"side\":\"SELL\", \"hash\":\"bf5048db4b5bcc06251c6e38733a1b0c819dd210\", \"best_bid\":\"0.5\", \"best_ask\":\"0.51\"}], \"timestamp\":\"1785207017899\", \"event_type\":\"price_change\"}","received_at":"2026-07-28T02:50:20.320850Z","schema_version":"clob-market-ws.price_change.v1","sequence":null,"server_hash":null,"server_timestamp":"1785207017899","session_id":"5aad79be415c487c84df42bebd84ee93","source":"clob_market_ws"},"received_at":"2026-07-28T02:50:20.320850Z","record_id":"5bca3133bf1c83d33a41a14f11d009d14543d197ffe62deb4dcce42a1bebab6f","schema_fingerprint":"4aa3821a28b0b7c2400bc59aba4bcc0a76e971dadd19610d3ad38c768e124dc7","schema_version":"edge-lab-recorder.raw.v1","sequence":null,"source":"clob_market_ws"}
{"event_at":"2026-07-28T02:50:17.899000Z","event_fingerprint":"5783ee4c7c87daf340c5a0429f9616fc77aa4e38e07fba09b42c1419048c8839","payload":{"connection_id":"955646bd8bf740759faf38750c0f263f","event_at":"2026-07-28T02:50:17.899000Z","event_type":"price_change","frame_hash":"390b45c75084346a7c42011dc37a743b49595425cc855cda085860870deed497","frame_index":0,"kind":"data","monotonic_ns":309003340404708,"payload":{"event_type":"price_change","market":"0x0f70d07969bc69eaa97d0987de651885fdca02263688026aa11e7678af8f87aa","price_changes":[{"asset_id":"58313761654877669244690227616056238030136603415514645252000528337391143520538","best_ask":"0.5","best_bid":"0.49","hash":"23b429606d8bed7ab511787959146c09c0d452dc","price":"0.48","side":"BUY","size":"56.25"},{"asset_id":"64053005904884194822931764831592250494815136296598204104072528088122126148949","best_ask":"0.51","best_bid":"0.5","hash":"1db6c5fc06b692719002fa96bf5d463290af6651","price":"0.52","side":"SELL","size":"56.25"}],"timestamp":"1785207017899"},"payload_hash":"3adea5175aa5e721a563b051482b5488ce19946bc8083406bcb72c72ed5dde6f","raw_frame":"{\"market\":\"0x0f70d07969bc69eaa97d0987de651885fdca02263688026aa11e7678af8f87aa\", \"price_changes\":[{\"asset_id\":\"58313761654877669244690227616056238030136603415514645252000528337391143520538\", \"price\":\"0.48\", \"size\":\"56.25\", \"side\":\"BUY\", \"hash\":\"23b429606d8bed7ab511787959146c09c0d452dc\", \"best_bid\":\"0.49\", \"best_ask\":\"0.5\"}, {\"asset_id\":\"64053005904884194822931764831592250494815136296598204104072528088122126148949\", \"price\":\"0.52\", \"size\":\"56.25\", \"side\":\"SELL\", \"hash\":\"1db6c5fc06b692719002fa96bf5d463290af6651\", \"best_bid\":\"0.5\", \"best_ask\":\"0.51\"}], \"timestamp\":\"1785207017899\", \"event_type\":\"price_change\"}","received_at":"2026-07-28T02:50:20.326227Z","schema_version":"clob-market-ws.price_change.v1","sequence":null,"server_hash":null,"server_timestamp":"1785207017899","session_id":"5aad79be415c487c84df42bebd84ee93","source":"clob_market_ws"},"received_at":"2026-07-28T02:50:20.326227Z","record_id":"d21b95982511e8893fafa84ddc0bcb8f53bc39379072656363d563ed079568fa","schema_fingerprint":"4aa3821a28b0b7c2400bc59aba4bcc0a76e971dadd19610d3ad38c768e124dc7","schema_version":"edge-lab-recorder.raw.v1","sequence":null,"source":"clob_market_ws"}
{"event_at":"2026-07-28T02:50:17.900000Z","event_fingerprint":"0e895e8f90a9e4aff00691a54a91614a613b0b323107555ef5d255116429e93b","payload":{"connection_id":"955646bd8bf740759faf38750c0f263f","event_at":"2026-07-28T02:50:17.900000Z","event_type":"price_change","frame_hash":"27d377c0787c160a6ee21051af9b368a2fb3ad8e48b3ccc09648c570e71fbe9c","frame_index":0,"kind":"data","monotonic_ns":309003352086625,"payload":{"event_type":"price_change","market":"0x0f70d07969bc69eaa97d0987de651885fdca02263688026aa11e7678af8f87aa","price_changes":[{"asset_id":"58313761654877669244690227616056238030136603415514645252000528337391143520538","best_ask":"0.5","best_bid":"0.49","hash":"d011dfc62ff2aa54bc8c9d52198325944f5ac9d1","price":"0.48","side":"BUY","size":"61.25"},{"asset_id":"64053005904884194822931764831592250494815136296598204104072528088122126148949","best_ask":"0.51","best_bid":"0.5","hash":"66d2e3e47686f717d2e9a9866441ce8e00cbef0b","price":"0.52","side":"SELL","size":"61.25"}],"timestamp":"1785207017900"},"payload_hash":"23b090da6ed89dacd10887d1c520a36e7dcb6ec1729f334caaef12e9a1037584","raw_frame":"{\"market\":\"0x0f70d07969bc69eaa97d0987de651885fdca02263688026aa11e7678af8f87aa\", \"price_changes\":[{\"asset_id\":\"58313761654877669244690227616056238030136603415514645252000528337391143520538\", \"price\":\"0.48\", \"size\":\"61.25\", \"side\":\"BUY\", \"hash\":\"d011dfc62ff2aa54bc8c9d52198325944f5ac9d1\", \"best_bid\":\"0.49\", \"best_ask\":\"0.5\"}, {\"asset_id\":\"64053005904884194822931764831592250494815136296598204104072528088122126148949\", \"price\":\"0.52\", \"size\":\"61.25\", \"side\":\"SELL\", \"hash\":\"66d2e3e47686f717d2e9a9866441ce8e00cbef0b\", \"best_bid\":\"0.5\", \"best_ask\":\"0.51\"}], \"timestamp\":\"1785207017900\", \"event_type\":\"price_change\"}","received_at":"2026-07-28T02:50:20.337910Z","schema_version":"clob-market-ws.price_change.v1","sequence":null,"server_hash":null,"server_timestamp":"1785207017900","session_id":"5aad79be415c487c84df42bebd84ee93","source":"clob_market_ws"},"received_at":"2026-07-28T02:50:20.337910Z","record_id":"fa6d7b690af07712a26ba1b9b5420f52bc0a8fbfdf5d8dac1ed869e9d5b69697","schema_fingerprint":"4aa3821a28b0b7c2400bc59aba4bcc0a76e971dadd19610d3ad38c768e124dc7","schema_version":"edge-lab-recorder.raw.v1","sequence":null,"source":"clob_market_ws"}
{"event_at":"2026-07-28T02:50:17.901000Z","event_fingerprint":"a7473c2084b6e1b2d5fe468e9ce61fcea32481b482ee6731b262eae1bd5ce25d","payload":{"connection_id":"955646bd8bf740759faf38750c0f263f","event_at":"2026-07-28T02:50:17.901000Z","event_type":"price_change","frame_hash":"0aead153acb99bad249e29b403d5de377dcc7bc7c245bb67798c6da90a62c746","frame_index":0,"kind":"data","monotonic_ns":309003360811291,"payload":{"event_type":"price_change","market":"0x0f70d07969bc69eaa97d0987de651885fdca02263688026aa11e7678af8f87aa","price_changes":[{"asset_id":"64053005904884194822931764831592250494815136296598204104072528088122126148949","best_ask":"0.51","best_bid":"0.5","hash":"5e914cb74980ead54da2b4110c77c68b18118094","price":"0.36","side":"BUY","size":"330"},{"asset_id":"58313761654877669244690227616056238030136603415514645252000528337391143520538","best_ask":"0.5","best_bid":"0.49","hash":"b27a89ecb48559b9174f77179cddb08fe7afefda","price":"0.64","side":"SELL","size":"330"}],"timestamp":"1785207017901"},"payload_hash":"3d5da96cf48215a77dab8ed9f4f868361f73536be3c4f09527b717de8caea28e","raw_frame":"{\"market\":\"0x0f70d07969bc69eaa97d0987de651885fdca02263688026aa11e7678af8f87aa\", \"price_changes\":[{\"asset_id\":\"64053005904884194822931764831592250494815136296598204104072528088122126148949\", \"price\":\"0.36\", \"size\":\"330\", \"side\":\"BUY\", \"hash\":\"5e914cb74980ead54da2b4110c77c68b18118094\", \"best_bid\":\"0.5\", \"best_ask\":\"0.51\"}, {\"asset_id\":\"58313761654877669244690227616056238030136603415514645252000528337391143520538\", \"price\":\"0.64\", \"size\":\"330\", \"side\":\"SELL\", \"hash\":\"b27a89ecb48559b9174f77179cddb08fe7afefda\", \"best_bid\":\"0.49\", \"best_ask\":\"0.5\"}], \"timestamp\":\"1785207017901\", \"event_type\":\"price_change\"}","received_at":"2026-07-28T02:50:20.346635Z","schema_version":"clob-market-ws.price_change.v1","sequence":null,"server_hash":null,"server_timestamp":"1785207017901","session_id":"5aad79be415c487c84df42bebd84ee93","source":"clob_market_ws"},"received_at":"2026-07-28T02:50:20.346635Z","record_id":"06055d2e4e09e6045d0c2c4bab729f31c688f652086921b1f9cb45e32b1b32ba","schema_fingerprint":"4aa3821a28b0b7c2400bc59aba4bcc0a76e971dadd19610d3ad38c768e124dc7","schema_version":"edge-lab-recorder.raw.v1","sequence":null,"source":"clob_market_ws"}
{"event_at":"2026-07-28T02:50:17.901000Z","event_fingerprint":"62ea95295ce40a9e3ec7bdbaefd81021407a740ad3d1d8f4392ff31b35fc77c1","payload":{"connection_id":"955646bd8bf740759faf38750c0f263f","event_at":"2026-07-28T02:50:17.901000Z","event_type":"price_change","frame_hash":"b4c83c76e330ca62b0b3be617bdcb828a6ba1d7fa00e95fd0fb57216ca8fb86b","frame_index":0,"kind":"data","monotonic_ns":309003364535666,"payload":{"event_type":"price_change","market":"0x0f70d07969bc69eaa97d0987de651885fdca02263688026aa11e7678af8f87aa","price_changes":[{"asset_id":"58313761654877669244690227616056238030136603415514645252000528337391143520538","best_ask":"0.5","best_bid":"0.49","hash":"8170fd3c2d82966433cfba041793ea2009e21c7c","price":"0.48","side":"BUY","size":"66.25"},{"asset_id":"64053005904884194822931764831592250494815136296598204104072528088122126148949","best_ask":"0.51","best_bid":"0.5","hash":"1e2aa8edb63351b0d56dc51cf9de513a98493bac","price":"0.52","side":"SELL","size":"66.25"}],"timestamp":"1785207017901"},"payload_hash":"9db86b81a6eac246fa0f5f826f9352b8d7a75245ce2544b5bfaab93202d6dbd8","raw_frame":"{\"market\":\"0x0f70d07969bc69eaa97d0987de651885fdca02263688026aa11e7678af8f87aa\", \"price_changes\":[{\"asset_id\":\"58313761654877669244690227616056238030136603415514645252000528337391143520538\", \"price\":\"0.48\", \"size\":\"66.25\", \"side\":\"BUY\", \"hash\":\"8170fd3c2d82966433cfba041793ea2009e21c7c\", \"best_bid\":\"0.49\", \"best_ask\":\"0.5\"}, {\"asset_id\":\"64053005904884194822931764831592250494815136296598204104072528088122126148949\", \"price\":\"0.52\", \"size\":\"66.25\", \"side\":\"SELL\", \"hash\":\"1e2aa8edb63351b0d56dc51cf9de513a98493bac\", \"best_bid\":\"0.5\", \"best_ask\":\"0.51\"}], \"timestamp\":\"1785207017901\", \"event_type\":\"price_change\"}","received_at":"2026-07-28T02:50:20.350360Z","schema_version":"clob-market-ws.price_change.v1","sequence":null,"server_hash":null,"server_timestamp":"1785207017901","session_id":"5aad79be415c487c84df42bebd84ee93","source":"clob_market_ws"},"received_at":"2026-07-28T02:50:20.350360Z","record_id":"07045b154a108e90a4d8e9b8cc758e4177028fa0c82a04154140bba3e882c4de","schema_fingerprint":"4aa3821a28b0b7c2400bc59aba4bcc0a76e971dadd19610d3ad38c768e124dc7","schema_version":"edge-lab-recorder.raw.v1","sequence":null,"source":"clob_market_ws"}
{"event_at":"2026-07-28T02:50:17.902000Z","event_fingerprint":"cdadd903017a0a75fddb82f88e5e6b4d24e46ccf69718f53863b213b9c918af0","payload":{"connection_id":"955646bd8bf740759faf38750c0f263f","event_at":"2026-07-28T02:50:17.902000Z","event_type":"price_change","frame_hash":"9cb1ad70a557f436d9887c081aac1ba12b3de65c0a481c1966bba4ae53eb1dcb","frame_index":0,"kind":"data","monotonic_ns":309003372093458,"payload":{"event_type":"price_change","market":"0x0f70d07969bc69eaa97d0987de651885fdca02263688026aa11e7678af8f87aa","price_changes":[{"asset_id":"64053005904884194822931764831592250494815136296598204104072528088122126148949","best_ask":"0.51","best_bid":"0.5","hash":"1bd72dabc1af1d601b5915def029e80753310bc7","price":"0.4","side":"BUY","size":"45.62"},{"asset_id":"58313761654877669244690227616056238030136603415514645252000528337391143520538","best_ask":"0.5","best_bid":"0.49","hash":"97314740c377513c02a95c8132829745da63d267","price":"0.6","side":"SELL","size":"45.62"}],"timestamp":"1785207017902"},"payload_hash":"03ae9df2d49b92501c5147128de526e82fe289a8b56ef6e480b86a0517a7038e","raw_frame":"{\"market\":\"0x0f70d07969bc69eaa97d0987de651885fdca02263688026aa11e7678af8f87aa\", \"price_changes\":[{\"asset_id\":\"64053005904884194822931764831592250494815136296598204104072528088122126148949\", \"price\":\"0.4\", \"size\":\"45.62\", \"side\":\"BUY\", \"hash\":\"1bd72dabc1af1d601b5915def029e80753310bc7\", \"best_bid\":\"0.5\", \"best_ask\":\"0.51\"}, {\"asset_id\":\"58313761654877669244690227616056238030136603415514645252000528337391143520538\", \"price\":\"0.6\", \"size\":\"45.62\", \"side\":\"SELL\", \"hash\":\"97314740c377513c02a95c8132829745da63d267\", \"best_bid\":\"0.49\", \"best_ask\":\"0.5\"}], \"timestamp\":\"1785207017902\", \"event_type\":\"price_change\"}","received_at":"2026-07-28T02:50:20.357916Z","schema_version":"clob-market-ws.price_change.v1","sequence":null,"server_hash":null,"server_timestamp":"1785207017902","session_id":"5aad79be415c487c84df42bebd84ee93","source":"clob_market_ws"},"received_at":"2026-07-28T02:50:20.357916Z","record_id":"dddb99ec8a42eba0c6f1524307a578b254a90200f02165467afbcb55649396a2","schema_fingerprint":"4aa3821a28b0b7c2400bc59aba4bcc0a76e971dadd19610d3ad38c768e124dc7","schema_version":"edge-lab-recorder.raw.v1","sequence":null,"source":"clob_market_ws"}
{"event_at":"2026-07-28T02:50:17.903000Z","event_fingerprint":"9424d967213b8e367e684890db508b07cedfab7db8a7a08ee28e9f44719f4a91","payload":{"connection_id":"955646bd8bf740759faf38750c0f263f","event_at":"2026-07-28T02:50:17.903000Z","event_type":"price_change","frame_hash":"3a288acc47c090d1c4e9723846288150ec3b65d9af529141b88bd97e01b0aca2","frame_index":0,"kind":"data","monotonic_ns":309003377143791,"payload":{"event_type":"price_change","market":"0x0f70d07969bc69eaa97d0987de651885fdca02263688026aa11e7678af8f87aa","price_changes":[{"asset_id":"64053005904884194822931764831592250494815136296598204104072528088122126148949","best_ask":"0.51","best_bid":"0.5","hash":"cc5ad6a7ea0bbc2bdc14da193d8a5a57cd49bb10","price":"0.28","side":"BUY","size":"30"},{"asset_id":"58313761654877669244690227616056238030136603415514645252000528337391143520538","best_ask":"0.5","best_bid":"0.49","hash":"48f0bc9ae4c4d23ab988fd9c7c92275934f0d9f6","price":"0.72","side":"SELL","size":"30"}],"timestamp":"1785207017903"},"payload_hash":"7c976a8c09fb2b067aab8020eafa547a44d8110aa95cad8127b6e433b2155f39","raw_frame":"{\"market\":\"0x0f70d07969bc69eaa97d0987de651885fdca02263688026aa11e7678af8f87aa\", \"price_changes\":[{\"asset_id\":\"64053005904884194822931764831592250494815136296598204104072528088122126148949\", \"price\":\"0.28\", \"size\":\"30\", \"side\":\"BUY\", \"hash\":\"cc5ad6a7ea0bbc2bdc14da193d8a5a57cd49bb10\", \"best_bid\":\"0.5\", \"best_ask\":\"0.51\"}, {\"asset_id\":\"58313761654877669244690227616056238030136603415514645252000528337391143520538\", \"price\":\"0.72\", \"size\":\"30\", \"side\":\"SELL\", \"hash\":\"48f0bc9ae4c4d23ab988fd9c7c92275934f0d9f6\", \"best_bid\":\"0.49\", \"best_ask\":\"0.5\"}], \"timestamp\":\"1785207017903\", \"event_type\":\"price_change\"}","received_at":"2026-07-28T02:50:20.362966Z","schema_version":"clob-market-ws.price_change.v1","sequence":null,"server_hash":null,"server_timestamp":"1785207017903","session_id":"5aad79be415c487c84df42bebd84ee93","source":"clob_market_ws"},"received_at":"2026-07-28T02:50:20.362966Z","record_id":"90234c6314a7c964ba3caddf50309dba2f576fceb871dcf82d6b5fe0f04dcc9c","schema_fingerprint":"4aa3821a28b0b7c2400bc59aba4bcc0a76e971dadd19610d3ad38c768e124dc7","schema_version":"edge-lab-recorder.raw.v1","sequence":null,"source":"clob_market_ws"}
{"event_at":"2026-07-28T02:50:17.904000Z","event_fingerprint":"45bb0cb8ab349c5507d7e375c91f07017fca55b83f62802122328e535386dce5","payload":{"connection_id":"955646bd8bf740759faf38750c0f263f","event_at":"2026-07-28T02:50:17.904000Z","event_type":"price_change","frame_hash":"a28dce0e3b4e5dbd3871a90af545a64839a90a35db929230349a1b37c944d948","frame_index":0,"kind":"data","monotonic_ns":309003382685416,"payload":{"event_type":"price_change","market":"0x0f70d07969bc69eaa97d0987de651885fdca02263688026aa11e7678af8f87aa","price_changes":[{"asset_id":"58313761654877669244690227616056238030136603415514645252000528337391143520538","best_ask":"0.5","best_bid":"0.49","hash":"182a33df05cf76110f3715a733c3ed6308707a1a","price":"0.32","side":"BUY","size":"100"},{"asset_id":"64053005904884194822931764831592250494815136296598204104072528088122126148949","best_ask":"0.51","best_bid":"0.5","hash":"7dc18d0313b05b52bd1c7bf45bdf1398f2f597dc","price":"0.68","side":"SELL","size":"100"}],"timestamp":"1785207017904"},"payload_hash":"9c1f7255031ec050a0a7a96eef8b4ce8157e88fbbc017915765a787cd33d21fa","raw_frame":"{\"market\":\"0x0f70d07969bc69eaa97d0987de651885fdca02263688026aa11e7678af8f87aa\", \"price_changes\":[{\"asset_id\":\"58313761654877669244690227616056238030136603415514645252000528337391143520538\", \"price\":\"0.32\", \"size\":\"100\", \"side\":\"BUY\", \"hash\":\"182a33df05cf76110f3715a733c3ed6308707a1a\", \"best_bid\":\"0.49\", \"best_ask\":\"0.5\"}, {\"asset_id\":\"64053005904884194822931764831592250494815136296598204104072528088122126148949\", \"price\":\"0.68\", \"size\":\"100\", \"side\":\"SELL\", \"hash\":\"7dc18d0313b05b52bd1c7bf45bdf1398f2f597dc\", \"best_bid\":\"0.5\", \"best_ask\":\"0.51\"}], \"timestamp\":\"1785207017904\", \"event_type\":\"price_change\"}","received_at":"2026-07-28T02:50:20.368508Z","schema_version":"clob-market-ws.price_change.v1","sequence":null,"server_hash":null,"server_timestamp":"1785207017904","session_id":"5aad79be415c487c84df42bebd84ee93","source":"clob_market_ws"},"received_at":"2026-07-28T02:50:20.368508Z","record_id":"1b7cab539d443169515e8c045264d6f323285fdecade877f5773d9ebd775818c","schema_fingerprint":"4aa3821a28b0b7c2400bc59aba4bcc0a76e971dadd19610d3ad38c768e124dc7","schema_version":"edge-lab-recorder.raw.v1","sequence":null,"source":"clob_market_ws"}
{"event_at":"2026-07-28T02:50:17.905000Z","event_fingerprint":"2e27d9cc6cedc92c89e76c9a8b695ee415a20e20a834e3cca686f911ab255df1","payload":{"connection_id":"955646bd8bf740759faf38750c0f263f","event_at":"2026-07-28T02:50:17.905000Z","event_type":"price_change","frame_hash":"63c844bae91c9d3334eec9468d0f5b9d392d6de81839bea6370e4e77fb3fb568","frame_index":0,"kind":"data","monotonic_ns":309003393126791,"payload":{"event_type":"price_change","market":"0x0f70d07969bc69eaa97d0987de651885fdca02263688026aa11e7678af8f87aa","price_changes":[{"asset_id":"64053005904884194822931764831592250494815136296598204104072528088122126148949","best_ask":"0.51","best_bid":"0.5","hash":"d0a80d8c60da240c2d1bb715f9218b1e9768c3fe","price":"0.32","side":"BUY","size":"100"},{"asset_id":"58313761654877669244690227616056238030136603415514645252000528337391143520538","best_ask":"0.5","best_bid":"0.49","hash":"39b6a4ae9ef49f36846439253341592801224a4f","price":"0.68","side":"SELL","size":"100"}],"timestamp":"1785207017905"},"payload_hash":"6995851f06a3f9b1d61ee194764f22e8bd1a61ff44ebcb0d4e0498e177c06673","raw_frame":"{\"market\":\"0x0f70d07969bc69eaa97d0987de651885fdca02263688026aa11e7678af8f87aa\", \"price_changes\":[{\"asset_id\":\"64053005904884194822931764831592250494815136296598204104072528088122126148949\", \"price\":\"0.32\", \"size\":\"100\", \"side\":\"BUY\", \"hash\":\"d0a80d8c60da240c2d1bb715f9218b1e9768c3fe\", \"best_bid\":\"0.5\", \"best_ask\":\"0.51\"}, {\"asset_id\":\"58313761654877669244690227616056238030136603415514645252000528337391143520538\", \"price\":\"0.68\", \"size\":\"100\", \"side\":\"SELL\", \"hash\":\"39b6a4ae9ef49f36846439253341592801224a4f\", \"best_bid\":\"0.49\", \"best_ask\":\"0.5\"}], \"timestamp\":\"1785207017905\", \"event_type\":\"price_change\"}","received_at":"2026-07-28T02:50:20.378948Z","schema_version":"clob-market-ws.price_change.v1","sequence":null,"server_hash":null,"server_timestamp":"1785207017905","session_id":"5aad79be415c487c84df42bebd84ee93","source":"clob_market_ws"},"received_at":"2026-07-28T02:50:20.378948Z","record_id":"d55f7ab53c330db40f66e28a34791a874e008eae0012fec2f4bdf3e7657e393c","schema_fingerprint":"4aa3821a28b0b7c2400bc59aba4bcc0a76e971dadd19610d3ad38c768e124dc7","schema_version":"edge-lab-recorder.raw.v1","sequence":null,"source":"clob_market_ws"}
{"event_at":"2026-07-28T02:50:17.906000Z","event_fingerprint":"c125f1fdef1fb898b112623c4f7a11be5164243c9c2d4124aeb4a7f53f19b562","payload":{"connection_id":"955646bd8bf740759faf38750c0f263f","event_at":"2026-07-28T02:50:17.906000Z","event_type":"price_change","frame_hash":"752303f795a3c8feb31e36855a8d75a0f2cefa6b40cc3b43afee5681033b4ea7","frame_index":0,"kind":"data","monotonic_ns":309003397499875,"payload":{"event_type":"price_change","market":"0x0f70d07969bc69eaa97d0987de651885fdca02263688026aa11e7678af8f87aa","price_changes":[{"asset_id":"58313761654877669244690227616056238030136603415514645252000528337391143520538","best_ask":"0.5","best_bid":"0.49","hash":"8c264da646377d5381602a9fa0dddf1e75f17742","price":"0.24","side":"BUY","size":"740"},{"asset_id":"64053005904884194822931764831592250494815136296598204104072528088122126148949","best_ask":"0.51","best_bid":"0.5","hash":"51cb8dd8cd1ceb5b05840467ce796eb9c900ccf3","price":"0.76","side":"SELL","size":"740"}],"timestamp":"1785207017906"},"payload_hash":"a4d7c8c8f22a364b314f1a471fabffcbfefd9f2787412444a3e23bf171870499","raw_frame":"{\"market\":\"0x0f70d07969bc69eaa97d0987de651885fdca02263688026aa11e7678af8f87aa\", \"price_changes\":[{\"asset_id\":\"58313761654877669244690227616056238030136603415514645252000528337391143520538\", \"price\":\"0.24\", \"size\":\"740\", \"side\":\"BUY\", \"hash\":\"8c264da646377d5381602a9fa0dddf1e75f17742\", \"best_bid\":\"0.49\", \"best_ask\":\"0.5\"}, {\"asset_id\":\"64053005904884194822931764831592250494815136296598204104072528088122126148949\", \"price\":\"0.76\", \"size\":\"740\", \"side\":\"SELL\", \"hash\":\"51cb8dd8cd1ceb5b05840467ce796eb9c900ccf3\", \"best_bid\":\"0.5\", \"best_ask\":\"0.51\"}], \"timestamp\":\"1785207017906\", \"event_type\":\"price_change\"}","received_at":"2026-07-28T02:50:20.383323Z","schema_version":"clob-market-ws.price_change.v1","sequence":null,"server_hash":null,"server_timestamp":"1785207017906","session_id":"5aad79be415c487c84df42bebd84ee93","source":"clob_market_ws"},"received_at":"2026-07-28T02:50:20.383323Z","record_id":"cc8f4250147d3e749e361ed7b41413ed3d821bb2e2c029af7b5ba7f376257edf","schema_fingerprint":"4aa3821a28b0b7c2400bc59aba4bcc0a76e971dadd19610d3ad38c768e124dc7","schema_version":"edge-lab-recorder.raw.v1","sequence":null,"source":"clob_market_ws"}
{"event_at":"2026-07-28T02:50:17.906000Z","event_fingerprint":"1472396bbabee48fb491a2c574eff7c0d6d0eee64d928c10bca1da2b2d92badd","payload":{"connection_id":"955646bd8bf740759faf38750c0f263f","event_at":"2026-07-28T02:50:17.906000Z","event_type":"price_change","frame_hash":"da30fdfd7c992f802a84100a4053219ceff267da7a774880890a6ee2a3704da4","frame_index":0,"kind":"data","monotonic_ns":309003403876208,"payload":{"event_type":"price_change","market":"0x0f70d07969bc69eaa97d0987de651885fdca02263688026aa11e7678af8f87aa","price_changes":[{"asset_id":"58313761654877669244690227616056238030136603415514645252000528337391143520538","best_ask":"0.5","best_bid":"0.49","hash":"136bcfe89ce9b0726a3199ebebb99843ea2e4575","price":"0.36","side":"BUY","size":"160"},{"asset_id":"64053005904884194822931764831592250494815136296598204104072528088122126148949","best_ask":"0.51","best_bid":"0.5","hash":"617a03a229eb3d07ea44b0b23061411d3d2e1392","price":"0.64","side":"SELL","size":"160"}],"timestamp":"1785207017906"},"payload_hash":"5172ed06b881242d057f5456053861f275fa48830193b67479565ac5f2934426","raw_frame":"{\"market\":\"0x0f70d07969bc69eaa97d0987de651885fdca02263688026aa11e7678af8f87aa\", \"price_changes\":[{\"asset_id\":\"58313761654877669244690227616056238030136603415514645252000528337391143520538\", \"price\":\"0.36\", \"size\":\"160\", \"side\":\"BUY\", \"hash\":\"136bcfe89ce9b0726a3199ebebb99843ea2e4575\", \"best_bid\":\"0.49\", \"best_ask\":\"0.5\"}, {\"asset_id\":\"64053005904884194822931764831592250494815136296598204104072528088122126148949\", \"price\":\"0.64\", \"size\":\"160\", \"side\":\"SELL\", \"hash\":\"617a03a229eb3d07ea44b0b23061411d3d2e1392\", \"best_bid\":\"0.5\", \"best_ask\":\"0.51\"}], \"timestamp\":\"1785207017906\", \"event_type\":\"price_change\"}","received_at":"2026-07-28T02:50:20.389699Z","schema_version":"clob-market-ws.price_change.v1","sequence":null,"server_hash":null,"server_timestamp":"1785207017906","session_id":"5aad79be415c487c84df42bebd84ee93","source":"clob_market_ws"},"received_at":"2026-07-28T02:50:20.389699Z","record_id":"063144c27d6730c8f1fe481ca4e7c74e47a0d14fc469bce507ba6cebe64dac34","schema_fingerprint":"4aa3821a28b0b7c2400bc59aba4bcc0a76e971dadd19610d3ad38c768e124dc7","schema_version":"edge-lab-recorder.raw.v1","sequence":null,"source":"clob_market_ws"}
{"event_at":"2026-07-28T02:50:17.907000Z","event_fingerprint":"488014c8e0f6cd91b4eeff32f89675d9572d2aacf591603d97cc23d9930d6719","payload":{"connection_id":"955646bd8bf740759faf38750c0f263f","event_at":"2026-07-28T02:50:17.907000Z","event_type":"price_change","frame_hash":"8d17d177332990fd3a711fb83458fea33db95a6fd763b47c5d0611ec85d8f038","frame_index":0,"kind":"data","monotonic_ns":309003410539291,"payload":{"event_type":"price_change","market":"0x0f70d07969bc69eaa97d0987de651885fdca02263688026aa11e7678af8f87aa","price_changes":[{"asset_id":"64053005904884194822931764831592250494815136296598204104072528088122126148949","best_ask":"0.51","best_bid":"0.5","hash":"570dea53407f14f0be8cfc5f13ced6e1dc917e01","price":"0.24","side":"BUY","size":"60"},{"asset_id":"58313761654877669244690227616056238030136603415514645252000528337391143520538","best_ask":"0.5","best_bid":"0.49","hash":"f0a49764ec09b724543bcc7347ef2b2d9a4931a5","price":"0.76","side":"SELL","size":"60"}],"timestamp":"1785207017907"},"payload_hash":"31a08c4d0a413aee242a2dd915144dc117b18f44ace7b28321b32facb376e552","raw_frame":"{\"market\":\"0x0f70d07969bc69eaa97d0987de651885fdca02263688026aa11e7678af8f87aa\", \"price_changes\":[{\"asset_id\":\"64053005904884194822931764831592250494815136296598204104072528088122126148949\", \"price\":\"0.24\", \"size\":\"60\", \"side\":\"BUY\", \"hash\":\"570dea53407f14f0be8cfc5f13ced6e1dc917e01\", \"best_bid\":\"0.5\", \"best_ask\":\"0.51\"}, {\"asset_id\":\"58313761654877669244690227616056238030136603415514645252000528337391143520538\", \"price\":\"0.76\", \"size\":\"60\", \"side\":\"SELL\", \"hash\":\"f0a49764ec09b724543bcc7347ef2b2d9a4931a5\", \"best_bid\":\"0.49\", \"best_ask\":\"0.5\"}], \"timestamp\":\"1785207017907\", \"event_type\":\"price_change\"}","received_at":"2026-07-28T02:50:20.396361Z","schema_version":"clob-market-ws.price_change.v1","sequence":null,"server_hash":null,"server_timestamp":"1785207017907","session_id":"5aad79be415c487c84df42bebd84ee93","source":"clob_market_ws"},"received_at":"2026-07-28T02:50:20.396361Z","record_id":"5816d52c160d01ebcc9e26555a858caf4a739baac9fe77b04712d268b5809897","schema_fingerprint":"4aa3821a28b0b7c2400bc59aba4bcc0a76e971dadd19610d3ad38c768e124dc7","schema_version":"edge-lab-recorder.raw.v1","sequence":null,"source":"clob_market_ws"}
{"event_at":"2026-07-28T02:50:17.908000Z","event_fingerprint":"d7b2e262840fd6e548377e1428b378ac8c2315d2449e95cf59186a4f94615ba0","payload":{"connection_id":"955646bd8bf740759faf38750c0f263f","event_at":"2026-07-28T02:50:17.908000Z","event_type":"price_change","frame_hash":"fe4f56d67546ed2b1e9cf97e885614e1af1c9d06c570a028f22e53bc57b132c9","frame_index":0,"kind":"data","monotonic_ns":309003415551041,"payload":{"event_type":"price_change","market":"0x0f70d07969bc69eaa97d0987de651885fdca02263688026aa11e7678af8f87aa","price_changes":[{"asset_id":"58313761654877669244690227616056238030136603415514645252000528337391143520538","best_ask":"0.5","best_bid":"0.49","hash":"b23ce239dc9feb1992634d8e645bf6b2970629fd","price":"0.4","side":"BUY","size":"45.62"},{"asset_id":"64053005904884194822931764831592250494815136296598204104072528088122126148949","best_ask":"0.51","best_bid":"0.5","hash":"4812ec34c3dd4897dd50de128e68d62e647f37a6","price":"0.6","side":"SELL","size":"45.62"}],"timestamp":"1785207017908"},"payload_hash":"7199255bc63d4585e862205f1d8bf103e54c8d9cac68a65797efc56dd8306af0","raw_frame":"{\"market\":\"0x0f70d07969bc69eaa97d0987de651885fdca02263688026aa11e7678af8f87aa\", \"price_changes\":[{\"asset_id\":\"58313761654877669244690227616056238030136603415514645252000528337391143520538\", \"price\":\"0.4\", \"size\":\"45.62\", \"side\":\"BUY\", \"hash\":\"b23ce239dc9feb1992634d8e645bf6b2970629fd\", \"best_bid\":\"0.49\", \"best_ask\":\"0.5\"}, {\"asset_id\":\"64053005904884194822931764831592250494815136296598204104072528088122126148949\", \"price\":\"0.6\", \"size\":\"45.62\", \"side\":\"SELL\", \"hash\":\"4812ec34c3dd4897dd50de128e68d62e647f37a6\", \"best_bid\":\"0.5\", \"best_ask\":\"0.51\"}], \"timestamp\":\"1785207017908\", \"event_type\":\"price_change\"}","received_at":"2026-07-28T02:50:20.401374Z","schema_version":"clob-market-ws.price_change.v1","sequence":null,"server_hash":null,"server_timestamp":"1785207017908","session_id":"5aad79be415c487c84df42bebd84ee93","source":"clob_market_ws"},"received_at":"2026-07-28T02:50:20.401374Z","record_id":"ebded0b6e6bbf2702e74e02fbd504180fe7890e7e1761ed7f641205c9da95be8","schema_fingerprint":"4aa3821a28b0b7c2400bc59aba4bcc0a76e971dadd19610d3ad38c768e124dc7","schema_version":"edge-lab-recorder.raw.v1","sequence":null,"source":"clob_market_ws"}
{"event_at":"2026-07-28T02:50:17.909000Z","event_fingerprint":"7b4e36671e6c569bb7d71ab2a32d4e772a0558e8e8247e52fe9f261eb8d4a9c0","payload":{"connection_id":"955646bd8bf740759faf38750c0f263f","event_at":"2026-07-28T02:50:17.909000Z","event_type":"price_change","frame_hash":"76cb773440b49789fca143080c3fe8f7caa905e704c3be382a97600d5334f42c","frame_index":0,"kind":"data","monotonic_ns":309003421249583,"payload":{"event_type":"price_change","market":"0x0f70d07969bc69eaa97d0987de651885fdca02263688026aa11e7678af8f87aa","price_changes":[{"asset_id":"58313761654877669244690227616056238030136603415514645252000528337391143520538","best_ask":"0.5","best_bid":"0.49","hash":"749030cc793f77e4d99b249f3c8030234bf54330","price":"0.28","side":"BUY","size":"30"},{"asset_id":"64053005904884194822931764831592250494815136296598204104072528088122126148949","best_ask":"0.51","best_bid":"0.5","hash":"622e826a5ef238107c882ddf7e0999b77c4593b6","price":"0.72","side":"SELL","size":"30"}],"timestamp":"1785207017909"},"payload_hash":"e19190ab14d705acf78daca0841fb313244d5c299ea0ed53680457d0370d2007","raw_frame":"{\"market\":\"0x0f70d07969bc69eaa97d0987de651885fdca02263688026aa11e7678af8f87aa\", \"price_changes\":[{\"asset_id\":\"58313761654877669244690227616056238030136603415514645252000528337391143520538\", \"price\":\"0.28\", \"size\":\"30\", \"side\":\"BUY\", \"hash\":\"749030cc793f77e4d99b249f3c8030234bf54330\", \"best_bid\":\"0.49\", \"best_ask\":\"0.5\"}, {\"asset_id\":\"64053005904884194822931764831592250494815136296598204104072528088122126148949\", \"price\":\"0.72\", \"size\":\"30\", \"side\":\"SELL\", \"hash\":\"622e826a5ef238107c882ddf7e0999b77c4593b6\", \"best_bid\":\"0.5\", \"best_ask\":\"0.51\"}], \"timestamp\":\"1785207017909\", \"event_type\":\"price_change\"}","received_at":"2026-07-28T02:50:20.407072Z","schema_version":"clob-market-ws.price_change.v1","sequence":null,"server_hash":null,"server_timestamp":"1785207017909","session_id":"5aad79be415c487c84df42bebd84ee93","source":"clob_market_ws"},"received_at":"2026-07-28T02:50:20.407072Z","record_id":"3da55097d8b4ffba7a98c0e40e88a6fb38d362ffb154b4b3288681e556ee62c6","schema_fingerprint":"4aa3821a28b0b7c2400bc59aba4bcc0a76e971dadd19610d3ad38c768e124dc7","schema_version":"edge-lab-recorder.raw.v1","sequence":null,"source":"clob_market_ws"}
{"event_at":"2026-07-28T02:50:17.911000Z","event_fingerprint":"07b9546ce1046fd724bf2bc753df8ce6142bdcd04905cf1180d1d9951343c5f4","payload":{"connection_id":"955646bd8bf740759faf38750c0f263f","event_at":"2026-07-28T02:50:17.911000Z","event_type":"price_change","frame_hash":"62e0fe6ef8ccafe4df5a976259990f4b56d5505be7615e620159a10517c7f1d5","frame_index":0,"kind":"data","monotonic_ns":309003427813958,"payload":{"event_type":"price_change","market":"0x0f70d07969bc69eaa97d0987de651885fdca02263688026aa11e7678af8f87aa","price_changes":[{"asset_id":"58313761654877669244690227616056238030136603415514645252000528337391143520538","best_ask":"0.5","best_bid":"0.49","hash":"847b7cb5a2b326840f8161850c2b423d2f1b7e4f","price":"0.48","side":"BUY","size":"71.25"},{"asset_id":"64053005904884194822931764831592250494815136296598204104072528088122126148949","best_ask":"0.51","best_bid":"0.5","hash":"711cd6dc80b9975bc1915335b5ec60848d55b9c0","price":"0.52","side":"SELL","size":"71.25"}],"timestamp":"1785207017911"},"payload_hash":"530ee170888b9a4b9614b63fafa7971a380952fef0821ff55f23828856a56e8d","raw_frame":"{\"market\":\"0x0f70d07969bc69eaa97d0987de651885fdca02263688026aa11e7678af8f87aa\", \"price_changes\":[{\"asset_id\":\"58313761654877669244690227616056238030136603415514645252000528337391143520538\", \"price\":\"0.48\", \"size\":\"71.25\", \"side\":\"BUY\", \"hash\":\"847b7cb5a2b326840f8161850c2b423d2f1b7e4f\", \"best_bid\":\"0.49\", \"best_ask\":\"0.5\"}, {\"asset_id\":\"64053005904884194822931764831592250494815136296598204104072528088122126148949\", \"price\":\"0.52\", \"size\":\"71.25\", \"side\":\"SELL\", \"hash\":\"711cd6dc80b9975bc1915335b5ec60848d55b9c0\", \"best_bid\":\"0.5\", \"best_ask\":\"0.51\"}], \"timestamp\":\"1785207017911\", \"event_type\":\"price_change\"}","received_at":"2026-07-28T02:50:20.413636Z","schema_version":"clob-market-ws.price_change.v1","sequence":null,"server_hash":null,"server_timestamp":"1785207017911","session_id":"5aad79be415c487c84df42bebd84ee93","source":"clob_market_ws"},"received_at":"2026-07-28T02:50:20.413636Z","record_id":"a2ecc9ccb97b63c8bafe92d191f007557050b2b340931c68ece5172737d718af","schema_fingerprint":"4aa3821a28b0b7c2400bc59aba4bcc0a76e971dadd19610d3ad38c768e124dc7","schema_version":"edge-lab-recorder.raw.v1","sequence":null,"source":"clob_market_ws"}
{"event_at":"2026-07-28T02:50:17.916000Z","event_fingerprint":"bdc38a26b11e40493f578de1db76108f40e16ae251c932ce00542937676639b4","payload":{"connection_id":"955646bd8bf740759faf38750c0f263f","event_at":"2026-07-28T02:50:17.916000Z","event_type":"price_change","frame_hash":"345e34f242c0e6fc483b2dc3febe28ce9244fa0f0c87c92d0269893c7b8e0e4a","frame_index":0,"kind":"data","monotonic_ns":309003432943208,"payload":{"event_type":"price_change","market":"0x0f70d07969bc69eaa97d0987de651885fdca02263688026aa11e7678af8f87aa","price_changes":[{"asset_id":"58313761654877669244690227616056238030136603415514645252000528337391143520538","best_ask":"0.5","best_bid":"0.49","hash":"a0b32c061e693ea207e91cc0043d233759b9c8b2","price":"0.48","side":"BUY","size":"76.25"},{"asset_id":"64053005904884194822931764831592250494815136296598204104072528088122126148949","best_ask":"0.51","best_bid":"0.5","hash":"f7c6970fab77e2341b27ec437f89d8273b39a313","price":"0.52","side":"SELL","size":"76.25"}],"timestamp":"1785207017916"},"payload_hash":"50722ad135bc03dc04ced600341367829abc7068399effb16fb73e694d0bb2a9","raw_frame":"{\"market\":\"0x0f70d07969bc69eaa97d0987de651885fdca02263688026aa11e7678af8f87aa\", \"price_changes\":[{\"asset_id\":\"58313761654877669244690227616056238030136603415514645252000528337391143520538\", \"price\":\"0.48\", \"size\":\"76.25\", \"side\":\"BUY\", \"hash\":\"a0b32c061e693ea207e91cc0043d233759b9c8b2\", \"best_bid\":\"0.49\", \"best_ask\":\"0.5\"}, {\"asset_id\":\"64053005904884194822931764831592250494815136296598204104072528088122126148949\", \"price\":\"0.52\", \"size\":\"76.25\", \"side\":\"SELL\", \"hash\":\"f7c6970fab77e2341b27ec437f89d8273b39a313\", \"best_bid\":\"0.5\", \"best_ask\":\"0.51\"}], \"timestamp\":\"1785207017916\", \"event_type\":\"price_change\"}","received_at":"2026-07-28T02:50:20.418766Z","schema_version":"clob-market-ws.price_change.v1","sequence":null,"server_hash":null,"server_timestamp":"1785207017916","session_id":"5aad79be415c487c84df42bebd84ee93","source":"clob_market_ws"},"received_at":"2026-07-28T02:50:20.418766Z","record_id":"d60ee8ce7899579946ea807fe81398e836393fb4c22f75d8808212393a4342db","schema_fingerprint":"4aa3821a28b0b7c2400bc59aba4bcc0a76e971dadd19610d3ad38c768e124dc7","schema_version":"edge-lab-recorder.raw.v1","sequence":null,"source":"clob_market_ws"}
{"event_at":"2026-07-28T02:50:17.917000Z","event_fingerprint":"e114db69a53f0d6a5a15cc8eb7b84165b48369915bca54dda2ad18bf38f904a6","payload":{"connection_id":"955646bd8bf740759faf38750c0f263f","event_at":"2026-07-28T02:50:17.917000Z","event_type":"price_change","frame_hash":"28119c8bd0d16871828103b09e3bdaef05e4b4a342adc9b5196fdfee6cc2afb9","frame_index":0,"kind":"data","monotonic_ns":309003438305916,"payload":{"event_type":"price_change","market":"0x0f70d07969bc69eaa97d0987de651885fdca02263688026aa11e7678af8f87aa","price_changes":[{"asset_id":"58313761654877669244690227616056238030136603415514645252000528337391143520538","best_ask":"0.5","best_bid":"0.49","hash":"cb1da0830da5619e4da749aed385c1c39aee550c","price":"0.48","side":"BUY","size":"81.25"},{"asset_id":"64053005904884194822931764831592250494815136296598204104072528088122126148949","best_ask":"0.51","best_bid":"0.5","hash":"84f32da108a91f996da22e66dee8cc14eb3f238d","price":"0.52","side":"SELL","size":"81.25"}],"timestamp":"1785207017917"},"payload_hash":"77ff145e2b208ba6ed22a793e7bcb7f05cba5f3704078961620cacd234812d72","raw_frame":"{\"market\":\"0x0f70d07969bc69eaa97d0987de651885fdca02263688026aa11e7678af8f87aa\", \"price_changes\":[{\"asset_id\":\"58313761654877669244690227616056238030136603415514645252000528337391143520538\", \"price\":\"0.48\", \"size\":\"81.25\", \"side\":\"BUY\", \"hash\":\"cb1da0830da5619e4da749aed385c1c39aee550c\", \"best_bid\":\"0.49\", \"best_ask\":\"0.5\"}, {\"asset_id\":\"64053005904884194822931764831592250494815136296598204104072528088122126148949\", \"price\":\"0.52\", \"size\":\"81.25\", \"side\":\"SELL\", \"hash\":\"84f32da108a91f996da22e66dee8cc14eb3f238d\", \"best_bid\":\"0.5\", \"best_ask\":\"0.51\"}], \"timestamp\":\"1785207017917\", \"event_type\":\"price_change\"}","received_at":"2026-07-28T02:50:20.424129Z","schema_version":"clob-market-ws.price_change.v1","sequence":null,"server_hash":null,"server_timestamp":"1785207017917","session_id":"5aad79be415c487c84df42bebd84ee93","source":"clob_market_ws"},"received_at":"2026-07-28T02:50:20.424129Z","record_id":"926790d5821ba145bfbeb6d89bed90c241ea1d064974bef0b4612c4b07f9084e","schema_fingerprint":"4aa3821a28b0b7c2400bc59aba4bcc0a76e971dadd19610d3ad38c768e124dc7","schema_version":"edge-lab-recorder.raw.v1","sequence":null,"source":"clob_market_ws"}
{"event_at":"2026-07-28T02:50:17.917000Z","event_fingerprint":"c10a8f40a19749ce5bd05044445aa6535f9a0a90a4ba9260a51dd3848c50ecb4","payload":{"connection_id":"955646bd8bf740759faf38750c0f263f","event_at":"2026-07-28T02:50:17.917000Z","event_type":"price_change","frame_hash":"4537cb84c559fa131ae2182332608109ebc4ce5250ce2262c7dd902417da736a","frame_index":0,"kind":"data","monotonic_ns":309003442901708,"payload":{"event_type":"price_change","market":"0x0f70d07969bc69eaa97d0987de651885fdca02263688026aa11e7678af8f87aa","price_changes":[{"asset_id":"58313761654877669244690227616056238030136603415514645252000528337391143520538","best_ask":"0.5","best_bid":"0.49","hash":"ac1e2cc1a81b29cb152a00c43e0ce2482f75da82","price":"0.48","side":"BUY","size":"86.25"},{"asset_id":"64053005904884194822931764831592250494815136296598204104072528088122126148949","best_ask":"0.51","best_bid":"0.5","hash":"6929a96502fdfeb86efdd1b5d99f2ee3ef08c785","price":"0.52","side":"SELL","size":"86.25"}],"timestamp":"1785207017917"},"payload_hash":"d3ddbc2501a35f7e663f9794262c543a477b0c025d3cf77c65b7d360d19df99b","raw_frame":"{\"market\":\"0x0f70d07969bc69eaa97d0987de651885fdca02263688026aa11e7678af8f87aa\", \"price_changes\":[{\"asset_id\":\"58313761654877669244690227616056238030136603415514645252000528337391143520538\", \"price\":\"0.48\", \"size\":\"86.25\", \"side\":\"BUY\", \"hash\":\"ac1e2cc1a81b29cb152a00c43e0ce2482f75da82\", \"best_bid\":\"0.49\", \"best_ask\":\"0.5\"}, {\"asset_id\":\"64053005904884194822931764831592250494815136296598204104072528088122126148949\", \"price\":\"0.52\", \"size\":\"86.25\", \"side\":\"SELL\", \"hash\":\"6929a96502fdfeb86efdd1b5d99f2ee3ef08c785\", \"best_bid\":\"0.5\", \"best_ask\":\"0.51\"}], \"timestamp\":\"1785207017917\", \"event_type\":\"price_change\"}","received_at":"2026-07-28T02:50:20.428725Z","schema_version":"clob-market-ws.price_change.v1","sequence":null,"server_hash":null,"server_timestamp":"1785207017917","session_id":"5aad79be415c487c84df42bebd84ee93","source":"clob_market_ws"},"received_at":"2026-07-28T02:50:20.428725Z","record_id":"255103efec29135dae36a371af222cc6f8b625494d02ed2e926e368c960bc70f","schema_fingerprint":"4aa3821a28b0b7c2400bc59aba4bcc0a76e971dadd19610d3ad38c768e124dc7","schema_version":"edge-lab-recorder.raw.v1","sequence":null,"source":"clob_market_ws"}
{"event_at":"2026-07-28T02:50:17.918000Z","event_fingerprint":"6e972baaf2ce96beeeb72b447cbec0fa4c6f943187009accc50080c2e24568b0","payload":{"connection_id":"955646bd8bf740759faf38750c0f263f","event_at":"2026-07-28T02:50:17.918000Z","event_type":"price_change","frame_hash":"345ae61657f9769ad3a15f5a4726f25603611c97f08ae75f8de2890bd81eaf80","frame_index":0,"kind":"data","monotonic_ns":309003448307500,"payload":{"event_type":"price_change","market":"0x0f70d07969bc69eaa97d0987de651885fdca02263688026aa11e7678af8f87aa","price_changes":[{"asset_id":"58313761654877669244690227616056238030136603415514645252000528337391143520538","best_ask":"0.5","best_bid":"0.49","hash":"42bc83b3f922e775786d3a07d9fdb1c8f0bac77f","price":"0.48","side":"BUY","size":"91.25"},{"asset_id":"64053005904884194822931764831592250494815136296598204104072528088122126148949","best_ask":"0.51","best_bid":"0.5","hash":"0f97ead5bc7c9d0dfed0cc51e128da8994c2dbc8","price":"0.52","side":"SELL","size":"91.25"}],"timestamp":"1785207017918"},"payload_hash":"1e721e8c6588fe098b7b901d489ff65711452648e810efb62e43c6d237377417","raw_frame":"{\"market\":\"0x0f70d07969bc69eaa97d0987de651885fdca02263688026aa11e7678af8f87aa\", \"price_changes\":[{\"asset_id\":\"58313761654877669244690227616056238030136603415514645252000528337391143520538\", \"price\":\"0.48\", \"size\":\"91.25\", \"side\":\"BUY\", \"hash\":\"42bc83b3f922e775786d3a07d9fdb1c8f0bac77f\", \"best_bid\":\"0.49\", \"best_ask\":\"0.5\"}, {\"asset_id\":\"64053005904884194822931764831592250494815136296598204104072528088122126148949\", \"price\":\"0.52\", \"size\":\"91.25\", \"side\":\"SELL\", \"hash\":\"0f97ead5bc7c9d0dfed0cc51e128da8994c2dbc8\", \"best_bid\":\"0.5\", \"best_ask\":\"0.51\"}], \"timestamp\":\"1785207017918\", \"event_type\":\"price_change\"}","received_at":"2026-07-28T02:50:20.434130Z","schema_version":"clob-market-ws.price_change.v1","sequence":null,"server_hash":null,"server_timestamp":"1785207017918","session_id":"5aad79be415c487c84df42bebd84ee93","source":"clob_market_ws"},"received_at":"2026-07-28T02:50:20.434130Z","record_id":"a9cc5fdfa165e3115f7e61c2815c1217043143ee0420958104780928f4d95a65","schema_fingerprint":"4aa3821a28b0b7c2400bc59aba4bcc0a76e971dadd19610d3ad38c768e124dc7","schema_version":"edge-lab-recorder.raw.v1","sequence":null,"source":"clob_market_ws"}
{"event_at":"2026-07-28T02:50:17.919000Z","event_fingerprint":"e10bd415f137895eb4d88bb3636edaac621c98467e6f4c7250907fc1a1e1f27d","payload":{"connection_id":"955646bd8bf740759faf38750c0f263f","event_at":"2026-07-28T02:50:17.919000Z","event_type":"price_change","frame_hash":"42b16111de418547e40e663176dcd38b34bbf35a0820996542fa0044e9aa1eb3","frame_index":0,"kind":"data","monotonic_ns":309003454629166,"payload":{"event_type":"price_change","market":"0x0f70d07969bc69eaa97d0987de651885fdca02263688026aa11e7678af8f87aa","price_changes":[{"asset_id":"58313761654877669244690227616056238030136603415514645252000528337391143520538","best_ask":"0.5","best_bid":"0.49","hash":"6ee205a5224c641c9d4f587a216aab0e6bd85af5","price":"0.48","side":"BUY","size":"96.25"},{"asset_id":"64053005904884194822931764831592250494815136296598204104072528088122126148949","best_ask":"0.51","best_bid":"0.5","hash":"c31a49eb4c71897e4962dc9b48b8b517d350fb32","price":"0.52","side":"SELL","size":"96.25"}],"timestamp":"1785207017919"},"payload_hash":"8b66712a9f1b5ba6efb92afdb7d1afb2e15404791b10ed1c0bba45a973450c20","raw_frame":"{\"market\":\"0x0f70d07969bc69eaa97d0987de651885fdca02263688026aa11e7678af8f87aa\", \"price_changes\":[{\"asset_id\":\"58313761654877669244690227616056238030136603415514645252000528337391143520538\", \"price\":\"0.48\", \"size\":\"96.25\", \"side\":\"BUY\", \"hash\":\"6ee205a5224c641c9d4f587a216aab0e6bd85af5\", \"best_bid\":\"0.49\", \"best_ask\":\"0.5\"}, {\"asset_id\":\"64053005904884194822931764831592250494815136296598204104072528088122126148949\", \"price\":\"0.52\", \"size\":\"96.25\", \"side\":\"SELL\", \"hash\":\"c31a49eb4c71897e4962dc9b48b8b517d350fb32\", \"best_bid\":\"0.5\", \"best_ask\":\"0.51\"}], \"timestamp\":\"1785207017919\", \"event_type\":\"price_change\"}","received_at":"2026-07-28T02:50:20.440452Z","schema_version":"clob-market-ws.price_change.v1","sequence":null,"server_hash":null,"server_timestamp":"1785207017919","session_id":"5aad79be415c487c84df42bebd84ee93","source":"clob_market_ws"},"received_at":"2026-07-28T02:50:20.440452Z","record_id":"fb893a1758532afd1c4617a084d80495ba0b00888ac18e9cf262d567985c609b","schema_fingerprint":"4aa3821a28b0b7c2400bc59aba4bcc0a76e971dadd19610d3ad38c768e124dc7","schema_version":"edge-lab-recorder.raw.v1","sequence":null,"source":"clob_market_ws"}
{"event_at":"2026-07-28T02:50:17.921000Z","event_fingerprint":"454d195e6940ba70e2ca40bcb3cffbc76fe171ebf18c8bb79039c3142bba2838","payload":{"connection_id":"955646bd8bf740759faf38750c0f263f","event_at":"2026-07-28T02:50:17.921000Z","event_type":"price_change","frame_hash":"654213315bb68edbb6ccd55a36f4dfeeb7fc051a8b15ab00cb0572a313b93357","frame_index":0,"kind":"data","monotonic_ns":309003460401250,"payload":{"event_type":"price_change","market":"0x0f70d07969bc69eaa97d0987de651885fdca02263688026aa11e7678af8f87aa","price_changes":[{"asset_id":"58313761654877669244690227616056238030136603415514645252000528337391143520538","best_ask":"0.5","best_bid":"0.49","hash":"3448e94fa75d2bffc87bdaa8f6115e651d0ea012","price":"0.48","side":"BUY","size":"101.25"},{"asset_id":"64053005904884194822931764831592250494815136296598204104072528088122126148949","best_ask":"0.51","best_bid":"0.5","hash":"046baa5c1c176ccdb30e5e60875d4e0137548ad4","price":"0.52","side":"SELL","size":"101.25"}],"timestamp":"1785207017921"},"payload_hash":"c36bc23129cb9f0829c6a6480c2bfc6e6e2a1160852c1393ec0095f58e19aaa4","raw_frame":"{\"market\":\"0x0f70d07969bc69eaa97d0987de651885fdca02263688026aa11e7678af8f87aa\", \"price_changes\":[{\"asset_id\":\"58313761654877669244690227616056238030136603415514645252000528337391143520538\", \"price\":\"0.48\", \"size\":\"101.25\", \"side\":\"BUY\", \"hash\":\"3448e94fa75d2bffc87bdaa8f6115e651d0ea012\", \"best_bid\":\"0.49\", \"best_ask\":\"0.5\"}, {\"asset_id\":\"64053005904884194822931764831592250494815136296598204104072528088122126148949\", \"price\":\"0.52\", \"size\":\"101.25\", \"side\":\"SELL\", \"hash\":\"046baa5c1c176ccdb30e5e60875d4e0137548ad4\", \"best_bid\":\"0.5\", \"best_ask\":\"0.51\"}], \"timestamp\":\"1785207017921\", \"event_type\":\"price_change\"}","received_at":"2026-07-28T02:50:20.446223Z","schema_version":"clob-market-ws.price_change.v1","sequence":null,"server_hash":null,"server_timestamp":"1785207017921","session_id":"5aad79be415c487c84df42bebd84ee93","source":"clob_market_ws"},"received_at":"2026-07-28T02:50:20.446223Z","record_id":"081bd00af9573c79804f846ace3a414353349a7e8f5e43d6b33bb8b0643af971","schema_fingerprint":"4aa3821a28b0b7c2400bc59aba4bcc0a76e971dadd19610d3ad38c768e124dc7","schema_version":"edge-lab-recorder.raw.v1","sequence":null,"source":"clob_market_ws"}
{"event_at":"2026-07-28T02:50:17.921000Z","event_fingerprint":"3fc56b670e77053832b0cdd3324f1eb6efb50a21f7dbe8a5146b56d90b1b3977","payload":{"connection_id":"955646bd8bf740759faf38750c0f263f","event_at":"2026-07-28T02:50:17.921000Z","event_type":"price_change","frame_hash":"ce1aae9f501b0a7057a2189362ead2a62cfab985f6fc666a1dee25bb26061720","frame_index":0,"kind":"data","monotonic_ns":309003464246625,"payload":{"event_type":"price_change","market":"0x0f70d07969bc69eaa97d0987de651885fdca02263688026aa11e7678af8f87aa","price_changes":[{"asset_id":"58313761654877669244690227616056238030136603415514645252000528337391143520538","best_ask":"0.5","best_bid":"0.49","hash":"152c3574ff4a73128abf398012dffdd561029b29","price":"0.48","side":"BUY","size":"106.25"},{"asset_id":"64053005904884194822931764831592250494815136296598204104072528088122126148949","best_ask":"0.51","best_bid":"0.5","hash":"9787ce0b548ba0034042a0ca71b495802bdc70c1","price":"0.52","side":"SELL","size":"106.25"}],"timestamp":"1785207017921"},"payload_hash":"3ed129ae1c69cde1aa617bda574d599a700483b67278eb8e2d867e89b68ff992","raw_frame":"{\"market\":\"0x0f70d07969bc69eaa97d0987de651885fdca02263688026aa11e7678af8f87aa\", \"price_changes\":[{\"asset_id\":\"58313761654877669244690227616056238030136603415514645252000528337391143520538\", \"price\":\"0.48\", \"size\":\"106.25\", \"side\":\"BUY\", \"hash\":\"152c3574ff4a73128abf398012dffdd561029b29\", \"best_bid\":\"0.49\", \"best_ask\":\"0.5\"}, {\"asset_id\":\"64053005904884194822931764831592250494815136296598204104072528088122126148949\", \"price\":\"0.52\", \"size\":\"106.25\", \"side\":\"SELL\", \"hash\":\"9787ce0b548ba0034042a0ca71b495802bdc70c1\", \"best_bid\":\"0.5\", \"best_ask\":\"0.51\"}], \"timestamp\":\"1785207017921\", \"event_type\":\"price_change\"}","received_at":"2026-07-28T02:50:20.450069Z","schema_version":"clob-market-ws.price_change.v1","sequence":null,"server_hash":null,"server_timestamp":"1785207017921","session_id":"5aad79be415c487c84df42bebd84ee93","source":"clob_market_ws"},"received_at":"2026-07-28T02:50:20.450069Z","record_id":"2252648968be6bd0e093f09a05f1bd03762f9a40d707c6ae4108056d3513e1a8","schema_fingerprint":"4aa3821a28b0b7c2400bc59aba4bcc0a76e971dadd19610d3ad38c768e124dc7","schema_version":"edge-lab-recorder.raw.v1","sequence":null,"source":"clob_market_ws"}
{"event_at":"2026-07-28T02:50:17.922000Z","event_fingerprint":"10a1ffbf1bed8e108c7e50a66ce2b8dfa32d59a7eeefc90b91d47a070dd3a14e","payload":{"connection_id":"955646bd8bf740759faf38750c0f263f","event_at":"2026-07-28T02:50:17.922000Z","event_type":"price_change","frame_hash":"674335da48b657b23e55ca84bd90573597af973f58ad969b7f78a21063f12cfc","frame_index":0,"kind":"data","monotonic_ns":309003468062000,"payload":{"event_type":"price_change","market":"0x0f70d07969bc69eaa97d0987de651885fdca02263688026aa11e7678af8f87aa","price_changes":[{"asset_id":"58313761654877669244690227616056238030136603415514645252000528337391143520538","best_ask":"0.5","best_bid":"0.49","hash":"fa9f84b1a0f6ccc1b2e02f198ef2e4a8abad3a5d","price":"0.48","side":"BUY","size":"111.25"},{"asset_id":"64053005904884194822931764831592250494815136296598204104072528088122126148949","best_ask":"0.51","best_bid":"0.5","hash":"8b562f111890cab033281331ecb0cdb3ce5498d1","price":"0.52","side":"SELL","size":"111.25"}],"timestamp":"1785207017922"},"payload_hash":"cf46e93f2e16e51e9995c9ff6f71508ee84b9c750d05567f607efa36746896cd","raw_frame":"{\"market\":\"0x0f70d07969bc69eaa97d0987de651885fdca02263688026aa11e7678af8f87aa\", \"price_changes\":[{\"asset_id\":\"58313761654877669244690227616056238030136603415514645252000528337391143520538\", \"price\":\"0.48\", \"size\":\"111.25\", \"side\":\"BUY\", \"hash\":\"fa9f84b1a0f6ccc1b2e02f198ef2e4a8abad3a5d\", \"best_bid\":\"0.49\", \"best_ask\":\"0.5\"}, {\"asset_id\":\"64053005904884194822931764831592250494815136296598204104072528088122126148949\", \"price\":\"0.52\", \"size\":\"111.25\", \"side\":\"SELL\", \"hash\":\"8b562f111890cab033281331ecb0cdb3ce5498d1\", \"best_bid\":\"0.5\", \"best_ask\":\"0.51\"}], \"timestamp\":\"1785207017922\", \"event_type\":\"price_change\"}","received_at":"2026-07-28T02:50:20.453884Z","schema_version":"clob-market-ws.price_change.v1","sequence":null,"server_hash":null,"server_timestamp":"1785207017922","session_id":"5aad79be415c487c84df42bebd84ee93","source":"clob_market_ws"},"received_at":"2026-07-28T02:50:20.453884Z","record_id":"db85959554556dc0ea010292483793cdbca36c89f46ea07b8552b68e966c94c6","schema_fingerprint":"4aa3821a28b0b7c2400bc59aba4bcc0a76e971dadd19610d3ad38c768e124dc7","schema_version":"edge-lab-recorder.raw.v1","sequence":null,"source":"clob_market_ws"}
{"event_at":"2026-07-28T02:50:17.923000Z","event_fingerprint":"18d3e6afa63644f72bb17e5badc26d3e17363c66f9dc3f9846c5c33da32def41","payload":{"connection_id":"955646bd8bf740759faf38750c0f263f","event_at":"2026-07-28T02:50:17.923000Z","event_type":"price_change","frame_hash":"7e21b0769d2f118028c9b135a0ed8f176f3d5f9afc877e02d362c5ffc12c5bc2","frame_index":0,"kind":"data","monotonic_ns":309003471887125,"payload":{"event_type":"price_change","market":"0x0f70d07969bc69eaa97d0987de651885fdca02263688026aa11e7678af8f87aa","price_changes":[{"asset_id":"58313761654877669244690227616056238030136603415514645252000528337391143520538","best_ask":"0.5","best_bid":"0.49","hash":"491c0e5184786abe6f383394ec1165c4ee702dec","price":"0.48","side":"BUY","size":"116.25"},{"asset_id":"64053005904884194822931764831592250494815136296598204104072528088122126148949","best_ask":"0.51","best_bid":"0.5","hash":"4a392e2c512754eab08d4c8a66648bb19c566494","price":"0.52","side":"SELL","size":"116.25"}],"timestamp":"1785207017923"},"payload_hash":"42c49a72fc1ebdece4ad13ed8c51154e2c5f1c538c33451641fe3e59c7126e17","raw_frame":"{\"market\":\"0x0f70d07969bc69eaa97d0987de651885fdca02263688026aa11e7678af8f87aa\", \"price_changes\":[{\"asset_id\":\"58313761654877669244690227616056238030136603415514645252000528337391143520538\", \"price\":\"0.48\", \"size\":\"116.25\", \"side\":\"BUY\", \"hash\":\"491c0e5184786abe6f383394ec1165c4ee702dec\", \"best_bid\":\"0.49\", \"best_ask\":\"0.5\"}, {\"asset_id\":\"64053005904884194822931764831592250494815136296598204104072528088122126148949\", \"price\":\"0.52\", \"size\":\"116.25\", \"side\":\"SELL\", \"hash\":\"4a392e2c512754eab08d4c8a66648bb19c566494\", \"best_bid\":\"0.5\", \"best_ask\":\"0.51\"}], \"timestamp\":\"1785207017923\", \"event_type\":\"price_change\"}","received_at":"2026-07-28T02:50:20.457709Z","schema_version":"clob-market-ws.price_change.v1","sequence":null,"server_hash":null,"server_timestamp":"1785207017923","session_id":"5aad79be415c487c84df42bebd84ee93","source":"clob_market_ws"},"received_at":"2026-07-28T02:50:20.457709Z","record_id":"a799dcfb78ec3a75ec2474ba6cdf1630d95ff31fe920e95d9789765ff66737fe","schema_fingerprint":"4aa3821a28b0b7c2400bc59aba4bcc0a76e971dadd19610d3ad38c768e124dc7","schema_version":"edge-lab-recorder.raw.v1","sequence":null,"source":"clob_market_ws"}
{"event_at":"2026-07-28T02:50:17.924000Z","event_fingerprint":"d67d7ec5abc16b6a550a1f37ef86ce6439aca7050f3c7c54401daebcb7568bea","payload":{"connection_id":"955646bd8bf740759faf38750c0f263f","event_at":"2026-07-28T02:50:17.924000Z","event_type":"price_change","frame_hash":"2ce38adeff5dfcfe8d9567dad33abf14ea499079bcf0ebebbb36fe6183128f46","frame_index":0,"kind":"data","monotonic_ns":309003476154416,"payload":{"event_type":"price_change","market":"0x0f70d07969bc69eaa97d0987de651885fdca02263688026aa11e7678af8f87aa","price_changes":[{"asset_id":"58313761654877669244690227616056238030136603415514645252000528337391143520538","best_ask":"0.5","best_bid":"0.49","hash":"7096f31d180b40b05523deed1fc2f045d6177725","price":"0.48","side":"BUY","size":"121.25"},{"asset_id":"64053005904884194822931764831592250494815136296598204104072528088122126148949","best_ask":"0.51","best_bid":"0.5","hash":"75de2f0f9feb187cb27065b855831d2f91e3ed1e","price":"0.52","side":"SELL","size":"121.25"}],"timestamp":"1785207017924"},"payload_hash":"31836cf84c864f91ff90ff424166c6a7a603376f53c217bc37e1d2df7f6e3c4d","raw_frame":"{\"market\":\"0x0f70d07969bc69eaa97d0987de651885fdca02263688026aa11e7678af8f87aa\", \"price_changes\":[{\"asset_id\":\"58313761654877669244690227616056238030136603415514645252000528337391143520538\", \"price\":\"0.48\", \"size\":\"121.25\", \"side\":\"BUY\", \"hash\":\"7096f31d180b40b05523deed1fc2f045d6177725\", \"best_bid\":\"0.49\", \"best_ask\":\"0.5\"}, {\"asset_id\":\"64053005904884194822931764831592250494815136296598204104072528088122126148949\", \"price\":\"0.52\", \"size\":\"121.25\", \"side\":\"SELL\", \"hash\":\"75de2f0f9feb187cb27065b855831d2f91e3ed1e\", \"best_bid\":\"0.5\", \"best_ask\":\"0.51\"}], \"timestamp\":\"1785207017924\", \"event_type\":\"price_change\"}","received_at":"2026-07-28T02:50:20.461977Z","schema_version":"clob-market-ws.price_change.v1","sequence":null,"server_hash":null,"server_timestamp":"1785207017924","session_id":"5aad79be415c487c84df42bebd84ee93","source":"clob_market_ws"},"received_at":"2026-07-28T02:50:20.461977Z","record_id":"eb7ae6fdc9691517b77750069fbaa0fe2dbbce24a2a5a54b7829dd31f92e334f","schema_fingerprint":"4aa3821a28b0b7c2400bc59aba4bcc0a76e971dadd19610d3ad38c768e124dc7","schema_version":"edge-lab-recorder.raw.v1","sequence":null,"source":"clob_market_ws"}
{"event_at":"2026-07-28T02:50:17.924000Z","event_fingerprint":"b2d922e51d216e4b83d80fa6e57e6b7d4e8070c02bd8643b9d23c3581c17fcb2","payload":{"connection_id":"955646bd8bf740759faf38750c0f263f","event_at":"2026-07-28T02:50:17.924000Z","event_type":"price_change","frame_hash":"55c5bf5394f439c017d663000ca92cbda3db9d715988cddbd8a9973d63de574f","frame_index":0,"kind":"data","monotonic_ns":309003480464000,"payload":{"event_type":"price_change","market":"0x0f70d07969bc69eaa97d0987de651885fdca02263688026aa11e7678af8f87aa","price_changes":[{"asset_id":"58313761654877669244690227616056238030136603415514645252000528337391143520538","best_ask":"0.5","best_bid":"0.49","hash":"48c0b1b87c49651a39d9ca9e5fdbb2bdcd9c4f2c","price":"0.48","side":"BUY","size":"126.25"},{"asset_id":"64053005904884194822931764831592250494815136296598204104072528088122126148949","best_ask":"0.51","best_bid":"0.5","hash":"f9ecd5a01addad13b957c89462af8863c7046eb2","price":"0.52","side":"SELL","size":"126.25"}],"timestamp":"1785207017924"},"payload_hash":"f58df2aae36c4dabb3aba1e9311eb7f201b8f7b8262eba03d2abb36a5e710718","raw_frame":"{\"market\":\"0x0f70d07969bc69eaa97d0987de651885fdca02263688026aa11e7678af8f87aa\", \"price_changes\":[{\"asset_id\":\"58313761654877669244690227616056238030136603415514645252000528337391143520538\", \"price\":\"0.48\", \"size\":\"126.25\", \"side\":\"BUY\", \"hash\":\"48c0b1b87c49651a39d9ca9e5fdbb2bdcd9c4f2c\", \"best_bid\":\"0.49\", \"best_ask\":\"0.5\"}, {\"asset_id\":\"64053005904884194822931764831592250494815136296598204104072528088122126148949\", \"price\":\"0.52\", \"size\":\"126.25\", \"side\":\"SELL\", \"hash\":\"f9ecd5a01addad13b957c89462af8863c7046eb2\", \"best_bid\":\"0.5\", \"best_ask\":\"0.51\"}], \"timestamp\":\"1785207017924\", \"event_type\":\"price_change\"}","received_at":"2026-07-28T02:50:20.466286Z","schema_version":"clob-market-ws.price_change.v1","sequence":null,"server_hash":null,"server_timestamp":"1785207017924","session_id":"5aad79be415c487c84df42bebd84ee93","source":"clob_market_ws"},"received_at":"2026-07-28T02:50:20.466286Z","record_id":"8d9318a00bff189f0d35865897744fd91ba82e7495edd67e2b2350e8e96659a8","schema_fingerprint":"4aa3821a28b0b7c2400bc59aba4bcc0a76e971dadd19610d3ad38c768e124dc7","schema_version":"edge-lab-recorder.raw.v1","sequence":null,"source":"clob_market_ws"}
{"event_at":"2026-07-28T02:50:17.925000Z","event_fingerprint":"e43b044688b5de9f1108e40061b173a3a2c320d98f7d1a204c58984fab331bb9","payload":{"connection_id":"955646bd8bf740759faf38750c0f263f","event_at":"2026-07-28T02:50:17.925000Z","event_type":"price_change","frame_hash":"98938926a8862e88cd8656b5b4524e397c944726bb374e5684ee84e8563bdb16","frame_index":0,"kind":"data","monotonic_ns":309003484803708,"payload":{"event_type":"price_change","market":"0x0f70d07969bc69eaa97d0987de651885fdca02263688026aa11e7678af8f87aa","price_changes":[{"asset_id":"58313761654877669244690227616056238030136603415514645252000528337391143520538","best_ask":"0.5","best_bid":"0.49","hash":"4a6a82458083f54d149b2c38b96f3691872f6910","price":"0.48","side":"BUY","size":"131.25"},{"asset_id":"64053005904884194822931764831592250494815136296598204104072528088122126148949","best_ask":"0.51","best_bid":"0.5","hash":"de5409c7c1b4cb9597e727fbad36842e398f269b","price":"0.52","side":"SELL","size":"131.25"}],"timestamp":"1785207017925"},"payload_hash":"07d24d982d9a592910cae1360f8274541607f6b05fc598767ac642d023cd72db","raw_frame":"{\"market\":\"0x0f70d07969bc69eaa97d0987de651885fdca02263688026aa11e7678af8f87aa\", \"price_changes\":[{\"asset_id\":\"58313761654877669244690227616056238030136603415514645252000528337391143520538\", \"price\":\"0.48\", \"size\":\"131.25\", \"side\":\"BUY\", \"hash\":\"4a6a82458083f54d149b2c38b96f3691872f6910\", \"best_bid\":\"0.49\", \"best_ask\":\"0.5\"}, {\"asset_id\":\"64053005904884194822931764831592250494815136296598204104072528088122126148949\", \"price\":\"0.52\", \"size\":\"131.25\", \"side\":\"SELL\", \"hash\":\"de5409c7c1b4cb9597e727fbad36842e398f269b\", \"best_bid\":\"0.5\", \"best_ask\":\"0.51\"}], \"timestamp\":\"1785207017925\", \"event_type\":\"price_change\"}","received_at":"2026-07-28T02:50:20.470626Z","schema_version":"clob-market-ws.price_change.v1","sequence":null,"server_hash":null,"server_timestamp":"1785207017925","session_id":"5aad79be415c487c84df42bebd84ee93","source":"clob_market_ws"},"received_at":"2026-07-28T02:50:20.470626Z","record_id":"45c9fb3ce839ccfae4129e9b41126b6164d6d80d4832178910af99b2a11f8a9e","schema_fingerprint":"4aa3821a28b0b7c2400bc59aba4bcc0a76e971dadd19610d3ad38c768e124dc7","schema_version":"edge-lab-recorder.raw.v1","sequence":null,"source":"clob_market_ws"}
{"event_at":"2026-07-28T02:50:17.926000Z","event_fingerprint":"9b412d91e1aced073db323f0c4ee93313320e47df3d8793144a7868d6dac9cd1","payload":{"connection_id":"955646bd8bf740759faf38750c0f263f","event_at":"2026-07-28T02:50:17.926000Z","event_type":"price_change","frame_hash":"e52e02d1238160a156498bcf23b5d97f5fbdc417916a4358b905f0b731c3e725","frame_index":0,"kind":"data","monotonic_ns":309003487945333,"payload":{"event_type":"price_change","market":"0x0f70d07969bc69eaa97d0987de651885fdca02263688026aa11e7678af8f87aa","price_changes":[{"asset_id":"58313761654877669244690227616056238030136603415514645252000528337391143520538","best_ask":"0.5","best_bid":"0.49","hash":"cecc78931e3617d7f61ede62edc66e64fa7bac70","price":"0.48","side":"BUY","size":"136.25"},{"asset_id":"64053005904884194822931764831592250494815136296598204104072528088122126148949","best_ask":"0.51","best_bid":"0.5","hash":"fa25e00b1f85976d586911a7aab6c206d981f920","price":"0.52","side":"SELL","size":"136.25"}],"timestamp":"1785207017926"},"payload_hash":"d572116c09d31ab713a1f0c665e1ef46e1456a671e4d7135540fe72c98d52e86","raw_frame":"{\"market\":\"0x0f70d07969bc69eaa97d0987de651885fdca02263688026aa11e7678af8f87aa\", \"price_changes\":[{\"asset_id\":\"58313761654877669244690227616056238030136603415514645252000528337391143520538\", \"price\":\"0.48\", \"size\":\"136.25\", \"side\":\"BUY\", \"hash\":\"cecc78931e3617d7f61ede62edc66e64fa7bac70\", \"best_bid\":\"0.49\", \"best_ask\":\"0.5\"}, {\"asset_id\":\"64053005904884194822931764831592250494815136296598204104072528088122126148949\", \"price\":\"0.52\", \"size\":\"136.25\", \"side\":\"SELL\", \"hash\":\"fa25e00b1f85976d586911a7aab6c206d981f920\", \"best_bid\":\"0.5\", \"best_ask\":\"0.51\"}], \"timestamp\":\"1785207017926\", \"event_type\":\"price_change\"}","received_at":"2026-07-28T02:50:20.473767Z","schema_version":"clob-market-ws.price_change.v1","sequence":null,"server_hash":null,"server_timestamp":"1785207017926","session_id":"5aad79be415c487c84df42bebd84ee93","source":"clob_market_ws"},"received_at":"2026-07-28T02:50:20.473767Z","record_id":"9dd058b6e08064fb0cdd3757b229f1a401dfe275c6d0d57c4365fd5b7ec419ee","schema_fingerprint":"4aa3821a28b0b7c2400bc59aba4bcc0a76e971dadd19610d3ad38c768e124dc7","schema_version":"edge-lab-recorder.raw.v1","sequence":null,"source":"clob_market_ws"}
{"event_at":"2026-07-28T02:50:17.927000Z","event_fingerprint":"e53eae994f929319e4c3735ca1216a389f4ad177c593dd02d3aa731272427d1b","payload":{"connection_id":"955646bd8bf740759faf38750c0f263f","event_at":"2026-07-28T02:50:17.927000Z","event_type":"price_change","frame_hash":"1a58374e0d269d9e0dd75573c4e0c07b21046fae802df5d691fafbe400a2ada2","frame_index":0,"kind":"data","monotonic_ns":309003492212166,"payload":{"event_type":"price_change","market":"0x0f70d07969bc69eaa97d0987de651885fdca02263688026aa11e7678af8f87aa","price_changes":[{"asset_id":"58313761654877669244690227616056238030136603415514645252000528337391143520538","best_ask":"0.5","best_bid":"0.49","hash":"233a0d6920a0c1a302ae230e040f210a7ed04c8c","price":"0.48","side":"BUY","size":"141.25"},{"asset_id":"64053005904884194822931764831592250494815136296598204104072528088122126148949","best_ask":"0.51","best_bid":"0.5","hash":"ca3d6998472e4dd9a698977ba147df3ec2c7f3d9","price":"0.52","side":"SELL","size":"141.25"}],"timestamp":"1785207017927"},"payload_hash":"e22d98ba7b9ae075190935185a20e3e72bfa3de2bced5ef39a0831bc2f25d892","raw_frame":"{\"market\":\"0x0f70d07969bc69eaa97d0987de651885fdca02263688026aa11e7678af8f87aa\", \"price_changes\":[{\"asset_id\":\"58313761654877669244690227616056238030136603415514645252000528337391143520538\", \"price\":\"0.48\", \"size\":\"141.25\", \"side\":\"BUY\", \"hash\":\"233a0d6920a0c1a302ae230e040f210a7ed04c8c\", \"best_bid\":\"0.49\", \"best_ask\":\"0.5\"}, {\"asset_id\":\"64053005904884194822931764831592250494815136296598204104072528088122126148949\", \"price\":\"0.52\", \"size\":\"141.25\", \"side\":\"SELL\", \"hash\":\"ca3d6998472e4dd9a698977ba147df3ec2c7f3d9\", \"best_bid\":\"0.5\", \"best_ask\":\"0.51\"}], \"timestamp\":\"1785207017927\", \"event_type\":\"price_change\"}","received_at":"2026-07-28T02:50:20.478034Z","schema_version":"clob-market-ws.price_change.v1","sequence":null,"server_hash":null,"server_timestamp":"1785207017927","session_id":"5aad79be415c487c84df42bebd84ee93","source":"clob_market_ws"},"received_at":"2026-07-28T02:50:20.478034Z","record_id":"ea2d091c56d7f85024528a12cbbc46aab393c6f4a8cfdf10e691f608b3f62ac4","schema_fingerprint":"4aa3821a28b0b7c2400bc59aba4bcc0a76e971dadd19610d3ad38c768e124dc7","schema_version":"edge-lab-recorder.raw.v1","sequence":null,"source":"clob_market_ws"}
{"event_at":"2026-07-28T02:50:17.928000Z","event_fingerprint":"2882921f5885762ae8c52d2baccd578d242ce00a3f00daff358d65ea0471ec79","payload":{"connection_id":"955646bd8bf740759faf38750c0f263f","event_at":"2026-07-28T02:50:17.928000Z","event_type":"price_change","frame_hash":"f76e7c87d55e85f2cdfab8f8c1b4faa2aa7d7853489fd6c92b84d29e0cfcf478","frame_index":0,"kind":"data","monotonic_ns":309003496396500,"payload":{"event_type":"price_change","market":"0x0f70d07969bc69eaa97d0987de651885fdca02263688026aa11e7678af8f87aa","price_changes":[{"asset_id":"58313761654877669244690227616056238030136603415514645252000528337391143520538","best_ask":"0.5","best_bid":"0.49","hash":"7e98b33b7fc9a671d13ac368190308539fe0b16c","price":"0.48","side":"BUY","size":"146.25"},{"asset_id":"64053005904884194822931764831592250494815136296598204104072528088122126148949","best_ask":"0.51","best_bid":"0.5","hash":"d3441f8c94a93b2aec6351266c3d86a629c28c83","price":"0.52","side":"SELL","size":"146.25"}],"timestamp":"1785207017928"},"payload_hash":"d85953fbdb7228ed30f1e1e340bbc9e9c28678a71880ff856baf144fbe07f233","raw_frame":"{\"market\":\"0x0f70d07969bc69eaa97d0987de651885fdca02263688026aa11e7678af8f87aa\", \"price_changes\":[{\"asset_id\":\"58313761654877669244690227616056238030136603415514645252000528337391143520538\", \"price\":\"0.48\", \"size\":\"146.25\", \"side\":\"BUY\", \"hash\":\"7e98b33b7fc9a671d13ac368190308539fe0b16c\", \"best_bid\":\"0.49\", \"best_ask\":\"0.5\"}, {\"asset_id\":\"64053005904884194822931764831592250494815136296598204104072528088122126148949\", \"price\":\"0.52\", \"size\":\"146.25\", \"side\":\"SELL\", \"hash\":\"d3441f8c94a93b2aec6351266c3d86a629c28c83\", \"best_bid\":\"0.5\", \"best_ask\":\"0.51\"}], \"timestamp\":\"1785207017928\", \"event_type\":\"price_change\"}","received_at":"2026-07-28T02:50:20.482219Z","schema_version":"clob-market-ws.price_change.v1","sequence":null,"server_hash":null,"server_timestamp":"1785207017928","session_id":"5aad79be415c487c84df42bebd84ee93","source":"clob_market_ws"},"received_at":"2026-07-28T02:50:20.482219Z","record_id":"4de2e6f49015396053a9f4cf4582c30036af3d18928b5f45a47ec5c025200b20","schema_fingerprint":"4aa3821a28b0b7c2400bc59aba4bcc0a76e971dadd19610d3ad38c768e124dc7","schema_version":"edge-lab-recorder.raw.v1","sequence":null,"source":"clob_market_ws"}
{"event_at":"2026-07-28T02:50:17.928000Z","event_fingerprint":"d8f9ad2c541d6aed9d859d14706b85114516e3dce4f6c53fa28d189824f4f6f9","payload":{"connection_id":"955646bd8bf740759faf38750c0f263f","event_at":"2026-07-28T02:50:17.928000Z","event_type":"price_change","frame_hash":"e8eec3520d01ef40ef1f85e87f6e2bec451461b248496afc20cfeb1cb648822e","frame_index":0,"kind":"data","monotonic_ns":309003500654041,"payload":{"event_type":"price_change","market":"0x0f70d07969bc69eaa97d0987de651885fdca02263688026aa11e7678af8f87aa","price_changes":[{"asset_id":"58313761654877669244690227616056238030136603415514645252000528337391143520538","best_ask":"0.5","best_bid":"0.49","hash":"e5fd80f4851e85090490d772815b98814903de5f","price":"0.48","side":"BUY","size":"151.25"},{"asset_id":"64053005904884194822931764831592250494815136296598204104072528088122126148949","best_ask":"0.51","best_bid":"0.5","hash":"2f36f0c1c98e8fb798c8c38c9213c8783037b146","price":"0.52","side":"SELL","size":"151.25"}],"timestamp":"1785207017928"},"payload_hash":"7e3588d95c5f1727c30e2b86a19490b0c0077a134975199c2bcedc7eb5f9fc96","raw_frame":"{\"market\":\"0x0f70d07969bc69eaa97d0987de651885fdca02263688026aa11e7678af8f87aa\", \"price_changes\":[{\"asset_id\":\"58313761654877669244690227616056238030136603415514645252000528337391143520538\", \"price\":\"0.48\", \"size\":\"151.25\", \"side\":\"BUY\", \"hash\":\"e5fd80f4851e85090490d772815b98814903de5f\", \"best_bid\":\"0.49\", \"best_ask\":\"0.5\"}, {\"asset_id\":\"64053005904884194822931764831592250494815136296598204104072528088122126148949\", \"price\":\"0.52\", \"size\":\"151.25\", \"side\":\"SELL\", \"hash\":\"2f36f0c1c98e8fb798c8c38c9213c8783037b146\", \"best_bid\":\"0.5\", \"best_ask\":\"0.51\"}], \"timestamp\":\"1785207017928\", \"event_type\":\"price_change\"}","received_at":"2026-07-28T02:50:20.486476Z","schema_version":"clob-market-ws.price_change.v1","sequence":null,"server_hash":null,"server_timestamp":"1785207017928","session_id":"5aad79be415c487c84df42bebd84ee93","source":"clob_market_ws"},"received_at":"2026-07-28T02:50:20.486476Z","record_id":"c8bc41894f94896c109715d986b9c7551d963058f779d69c968694524c2bd623","schema_fingerprint":"4aa3821a28b0b7c2400bc59aba4bcc0a76e971dadd19610d3ad38c768e124dc7","schema_version":"edge-lab-recorder.raw.v1","sequence":null,"source":"clob_market_ws"}
{"event_at":"2026-07-28T02:50:17.929000Z","event_fingerprint":"9f6894f0c388d60c6e3574850bdffc1ba416ef8a0c13f24085ba50867969f5a9","payload":{"connection_id":"955646bd8bf740759faf38750c0f263f","event_at":"2026-07-28T02:50:17.929000Z","event_type":"price_change","frame_hash":"8e87e490745e35334c9e8a1a74a93055bc7a1c507161a1e24ee9939c60dd8cc2","frame_index":0,"kind":"data","monotonic_ns":309003503817833,"payload":{"event_type":"price_change","market":"0x0f70d07969bc69eaa97d0987de651885fdca02263688026aa11e7678af8f87aa","price_changes":[{"asset_id":"58313761654877669244690227616056238030136603415514645252000528337391143520538","best_ask":"0.5","best_bid":"0.49","hash":"8e775fba469810d34d0795a53ad3bcd9d7fd0d78","price":"0.48","side":"BUY","size":"156.25"},{"asset_id":"64053005904884194822931764831592250494815136296598204104072528088122126148949","best_ask":"0.51","best_bid":"0.5","hash":"4fc7db063c34be5b7e3efdf4d5df3c6df0f47010","price":"0.52","side":"SELL","size":"156.25"}],"timestamp":"1785207017929"},"payload_hash":"e5efdd0f69ebc827304e3dd779d399acaf21a6438ec7bca4f1d400ab65b93c19","raw_frame":"{\"market\":\"0x0f70d07969bc69eaa97d0987de651885fdca02263688026aa11e7678af8f87aa\", \"price_changes\":[{\"asset_id\":\"58313761654877669244690227616056238030136603415514645252000528337391143520538\", \"price\":\"0.48\", \"size\":\"156.25\", \"side\":\"BUY\", \"hash\":\"8e775fba469810d34d0795a53ad3bcd9d7fd0d78\", \"best_bid\":\"0.49\", \"best_ask\":\"0.5\"}, {\"asset_id\":\"64053005904884194822931764831592250494815136296598204104072528088122126148949\", \"price\":\"0.52\", \"size\":\"156.25\", \"side\":\"SELL\", \"hash\":\"4fc7db063c34be5b7e3efdf4d5df3c6df0f47010\", \"best_bid\":\"0.5\", \"best_ask\":\"0.51\"}], \"timestamp\":\"1785207017929\", \"event_type\":\"price_change\"}","received_at":"2026-07-28T02:50:20.489640Z","schema_version":"clob-market-ws.price_change.v1","sequence":null,"server_hash":null,"server_timestamp":"1785207017929","session_id":"5aad79be415c487c84df42bebd84ee93","source":"clob_market_ws"},"received_at":"2026-07-28T02:50:20.489640Z","record_id":"2b6f77d3bcac7fc771f13d902d9a600739a3ba31c86a2294b76e833c1a8ddd93","schema_fingerprint":"4aa3821a28b0b7c2400bc59aba4bcc0a76e971dadd19610d3ad38c768e124dc7","schema_version":"edge-lab-recorder.raw.v1","sequence":null,"source":"clob_market_ws"}
{"event_at":"2026-07-28T02:50:17.930000Z","event_fingerprint":"846c5074db0639eb05e85d03f4bbba9f42ebaa59b4f180d6d852e12911bbfd3a","payload":{"connection_id":"955646bd8bf740759faf38750c0f263f","event_at":"2026-07-28T02:50:17.930000Z","event_type":"price_change","frame_hash":"0ccf57b950c3cbf0c1aac2be6e2e6eae3a01a0dc7c8fb6b83ea3e4ba04a6c818","frame_index":0,"kind":"data","monotonic_ns":309003507881916,"payload":{"event_type":"price_change","market":"0x0f70d07969bc69eaa97d0987de651885fdca02263688026aa11e7678af8f87aa","price_changes":[{"asset_id":"58313761654877669244690227616056238030136603415514645252000528337391143520538","best_ask":"0.5","best_bid":"0.49","hash":"d1a0e77a63d90df2c516a949941820e800b0096e","price":"0.48","side":"BUY","size":"161.25"},{"asset_id":"64053005904884194822931764831592250494815136296598204104072528088122126148949","best_ask":"0.51","best_bid":"0.5","hash":"515e1d7dc7ae3d08777351c87f5fad5e25269ad1","price":"0.52","side":"SELL","size":"161.25"}],"timestamp":"1785207017930"},"payload_hash":"74b65dde27ce517fda6cbbed418ad45754697e597bead3f28fd596ddc8219ede","raw_frame":"{\"market\":\"0x0f70d07969bc69eaa97d0987de651885fdca02263688026aa11e7678af8f87aa\", \"price_changes\":[{\"asset_id\":\"58313761654877669244690227616056238030136603415514645252000528337391143520538\", \"price\":\"0.48\", \"size\":\"161.25\", \"side\":\"BUY\", \"hash\":\"d1a0e77a63d90df2c516a949941820e800b0096e\", \"best_bid\":\"0.49\", \"best_ask\":\"0.5\"}, {\"asset_id\":\"64053005904884194822931764831592250494815136296598204104072528088122126148949\", \"price\":\"0.52\", \"size\":\"161.25\", \"side\":\"SELL\", \"hash\":\"515e1d7dc7ae3d08777351c87f5fad5e25269ad1\", \"best_bid\":\"0.5\", \"best_ask\":\"0.51\"}], \"timestamp\":\"1785207017930\", \"event_type\":\"price_change\"}","received_at":"2026-07-28T02:50:20.493704Z","schema_version":"clob-market-ws.price_change.v1","sequence":null,"server_hash":null,"server_timestamp":"1785207017930","session_id":"5aad79be415c487c84df42bebd84ee93","source":"clob_market_ws"},"received_at":"2026-07-28T02:50:20.493704Z","record_id":"7b00b83491a92a2e8bb4e96024759951a7684dae69b613735db981b2e552661d","schema_fingerprint":"4aa3821a28b0b7c2400bc59aba4bcc0a76e971dadd19610d3ad38c768e124dc7","schema_version":"edge-lab-recorder.raw.v1","sequence":null,"source":"clob_market_ws"}
{"event_at":"2026-07-28T02:50:17.931000Z","event_fingerprint":"5c90c136dd44abc5aaa4bc228466e46c8f6301e50b1cec8aef47b41c8edb791d","payload":{"connection_id":"955646bd8bf740759faf38750c0f263f","event_at":"2026-07-28T02:50:17.931000Z","event_type":"price_change","frame_hash":"1fcf4d830694d198c3422f05774814570ba44fcbddac3c0e92cb52de56d12e4a","frame_index":0,"kind":"data","monotonic_ns":309003513390500,"payload":{"event_type":"price_change","market":"0x0f70d07969bc69eaa97d0987de651885fdca02263688026aa11e7678af8f87aa","price_changes":[{"asset_id":"58313761654877669244690227616056238030136603415514645252000528337391143520538","best_ask":"0.5","best_bid":"0.49","hash":"87ec3d15dfa3d88ed6764f895b6ceccaef94db5e","price":"0.48","side":"BUY","size":"166.25"},{"asset_id":"64053005904884194822931764831592250494815136296598204104072528088122126148949","best_ask":"0.51","best_bid":"0.5","hash":"37b33476710a13af098185f29bb233a8594f05b0","price":"0.52","side":"SELL","size":"166.25"}],"timestamp":"1785207017931"},"payload_hash":"024938584c5720a5e78307603569c5e364c2efe36e2521dd66e8784ed13486e2","raw_frame":"{\"market\":\"0x0f70d07969bc69eaa97d0987de651885fdca02263688026aa11e7678af8f87aa\", \"price_changes\":[{\"asset_id\":\"58313761654877669244690227616056238030136603415514645252000528337391143520538\", \"price\":\"0.48\", \"size\":\"166.25\", \"side\":\"BUY\", \"hash\":\"87ec3d15dfa3d88ed6764f895b6ceccaef94db5e\", \"best_bid\":\"0.49\", \"best_ask\":\"0.5\"}, {\"asset_id\":\"64053005904884194822931764831592250494815136296598204104072528088122126148949\", \"price\":\"0.52\", \"size\":\"166.25\", \"side\":\"SELL\", \"hash\":\"37b33476710a13af098185f29bb233a8594f05b0\", \"best_bid\":\"0.5\", \"best_ask\":\"0.51\"}], \"timestamp\":\"1785207017931\", \"event_type\":\"price_change\"}","received_at":"2026-07-28T02:50:20.499213Z","schema_version":"clob-market-ws.price_change.v1","sequence":null,"server_hash":null,"server_timestamp":"1785207017931","session_id":"5aad79be415c487c84df42bebd84ee93","source":"clob_market_ws"},"received_at":"2026-07-28T02:50:20.499213Z","record_id":"bcd8d93d9f4fb0f08d080a5a061ff47a7c7300109c14083e2bec72ebbfea7ea5","schema_fingerprint":"4aa3821a28b0b7c2400bc59aba4bcc0a76e971dadd19610d3ad38c768e124dc7","schema_version":"edge-lab-recorder.raw.v1","sequence":null,"source":"clob_market_ws"}
{"event_at":"2026-07-28T02:50:17.932000Z","event_fingerprint":"bf431b3dcc87b1f18ea235e22277f81bbdae8f7358b16524ce900c9757d3ea58","payload":{"connection_id":"955646bd8bf740759faf38750c0f263f","event_at":"2026-07-28T02:50:17.932000Z","event_type":"price_change","frame_hash":"6b05313a1acde84748eb87dd2c6269b1f154b28553afccae40b36994d04b0d26","frame_index":0,"kind":"data","monotonic_ns":309003527858125,"payload":{"event_type":"price_change","market":"0x0f70d07969bc69eaa97d0987de651885fdca02263688026aa11e7678af8f87aa","price_changes":[{"asset_id":"58313761654877669244690227616056238030136603415514645252000528337391143520538","best_ask":"0.5","best_bid":"0.49","hash":"b1bacc085c0bf1725ab535245e781d6f0db24ff0","price":"0.48","side":"BUY","size":"171.25"},{"asset_id":"64053005904884194822931764831592250494815136296598204104072528088122126148949","best_ask":"0.51","best_bid":"0.5","hash":"b35701f50446eb3f1bd31f66aa4739111aaef3ec","price":"0.52","side":"SELL","size":"171.25"}],"timestamp":"1785207017932"},"payload_hash":"da145db290b18e889f8435e958d1bd376cdbe6071862b318117c390f9ef5051b","raw_frame":"{\"market\":\"0x0f70d07969bc69eaa97d0987de651885fdca02263688026aa11e7678af8f87aa\", \"price_changes\":[{\"asset_id\":\"58313761654877669244690227616056238030136603415514645252000528337391143520538\", \"price\":\"0.48\", \"size\":\"171.25\", \"side\":\"BUY\", \"hash\":\"b1bacc085c0bf1725ab535245e781d6f0db24ff0\", \"best_bid\":\"0.49\", \"best_ask\":\"0.5\"}, {\"asset_id\":\"64053005904884194822931764831592250494815136296598204104072528088122126148949\", \"price\":\"0.52\", \"size\":\"171.25\", \"side\":\"SELL\", \"hash\":\"b35701f50446eb3f1bd31f66aa4739111aaef3ec\", \"best_bid\":\"0.5\", \"best_ask\":\"0.51\"}], \"timestamp\":\"1785207017932\", \"event_type\":\"price_change\"}","received_at":"2026-07-28T02:50:20.513679Z","schema_version":"clob-market-ws.price_change.v1","sequence":null,"server_hash":null,"server_timestamp":"1785207017932","session_id":"5aad79be415c487c84df42bebd84ee93","source":"clob_market_ws"},"received_at":"2026-07-28T02:50:20.513679Z","record_id":"6ad8b3fba0ccd4e4e17759803b81aecfa1b3a6f2c25bcd4bcc83e07dc06fe6ad","schema_fingerprint":"4aa3821a28b0b7c2400bc59aba4bcc0a76e971dadd19610d3ad38c768e124dc7","schema_version":"edge-lab-recorder.raw.v1","sequence":null,"source":"clob_market_ws"}
{"event_at":"2026-07-28T02:50:17.933000Z","event_fingerprint":"aab57228c48a17236bd77ba729ae40c6b948f1e9dff5f6ae9478dbbe20573a37","payload":{"connection_id":"955646bd8bf740759faf38750c0f263f","event_at":"2026-07-28T02:50:17.933000Z","event_type":"price_change","frame_hash":"5dd34b89a8998d874ec42996a3f90514d9f05438cbfc64510344ccf5d6aa9378","frame_index":0,"kind":"data","monotonic_ns":309003533866583,"payload":{"event_type":"price_change","market":"0x0f70d07969bc69eaa97d0987de651885fdca02263688026aa11e7678af8f87aa","price_changes":[{"asset_id":"58313761654877669244690227616056238030136603415514645252000528337391143520538","best_ask":"0.5","best_bid":"0.49","hash":"84c8a7f2f4f8f9d5c7bf4e0b27d21f360d587af7","price":"0.48","side":"BUY","size":"176.25"},{"asset_id":"64053005904884194822931764831592250494815136296598204104072528088122126148949","best_ask":"0.51","best_bid":"0.5","hash":"af5f9c7137b0ac9900d46b0b2fd8e05aaf6b63a9","price":"0.52","side":"SELL","size":"176.25"}],"timestamp":"1785207017933"},"payload_hash":"6f91d75a60544a5c5ebe0d9180004df69bf80bacb60f8efe71c6ba80a836c653","raw_frame":"{\"market\":\"0x0f70d07969bc69eaa97d0987de651885fdca02263688026aa11e7678af8f87aa\", \"price_changes\":[{\"asset_id\":\"58313761654877669244690227616056238030136603415514645252000528337391143520538\", \"price\":\"0.48\", \"size\":\"176.25\", \"side\":\"BUY\", \"hash\":\"84c8a7f2f4f8f9d5c7bf4e0b27d21f360d587af7\", \"best_bid\":\"0.49\", \"best_ask\":\"0.5\"}, {\"asset_id\":\"64053005904884194822931764831592250494815136296598204104072528088122126148949\", \"price\":\"0.52\", \"size\":\"176.25\", \"side\":\"SELL\", \"hash\":\"af5f9c7137b0ac9900d46b0b2fd8e05aaf6b63a9\", \"best_bid\":\"0.5\", \"best_ask\":\"0.51\"}], \"timestamp\":\"1785207017933\", \"event_type\":\"price_change\"}","received_at":"2026-07-28T02:50:20.519688Z","schema_version":"clob-market-ws.price_change.v1","sequence":null,"server_hash":null,"server_timestamp":"1785207017933","session_id":"5aad79be415c487c84df42bebd84ee93","source":"clob_market_ws"},"received_at":"2026-07-28T02:50:20.519688Z","record_id":"687aaa72741ee35b3bf7844303a5efe1c8f3c1d2eaa779ffc627250a144d2332","schema_fingerprint":"4aa3821a28b0b7c2400bc59aba4bcc0a76e971dadd19610d3ad38c768e124dc7","schema_version":"edge-lab-recorder.raw.v1","sequence":null,"source":"clob_market_ws"}
{"event_at":"2026-07-28T02:50:17.934000Z","event_fingerprint":"6d42262e7406ea8a04cba979e07f7a33f06eb55f193f85b90a51a1e77d57aaa9","payload":{"connection_id":"955646bd8bf740759faf38750c0f263f","event_at":"2026-07-28T02:50:17.934000Z","event_type":"price_change","frame_hash":"f49a2e524daa4e03ea164c079680a63c31b15e96d6840059fdd4bdfb5c41798b","frame_index":0,"kind":"data","monotonic_ns":309003538279000,"payload":{"event_type":"price_change","market":"0x0f70d07969bc69eaa97d0987de651885fdca02263688026aa11e7678af8f87aa","price_changes":[{"asset_id":"58313761654877669244690227616056238030136603415514645252000528337391143520538","best_ask":"0.5","best_bid":"0.49","hash":"c5d1c07b8287adcd9093e12fc79f00a5db2fb745","price":"0.48","side":"BUY","size":"181.25"},{"asset_id":"64053005904884194822931764831592250494815136296598204104072528088122126148949","best_ask":"0.51","best_bid":"0.5","hash":"2bff1e3182b535df7bc46be2550cac63cf60711e","price":"0.52","side":"SELL","size":"181.25"}],"timestamp":"1785207017934"},"payload_hash":"e2614e69c4aa5d72d64705c03ececc7bb861430c9c67b4dc4f7174722c6fb78e","raw_frame":"{\"market\":\"0x0f70d07969bc69eaa97d0987de651885fdca02263688026aa11e7678af8f87aa\", \"price_changes\":[{\"asset_id\":\"58313761654877669244690227616056238030136603415514645252000528337391143520538\", \"price\":\"0.48\", \"size\":\"181.25\", \"side\":\"BUY\", \"hash\":\"c5d1c07b8287adcd9093e12fc79f00a5db2fb745\", \"best_bid\":\"0.49\", \"best_ask\":\"0.5\"}, {\"asset_id\":\"64053005904884194822931764831592250494815136296598204104072528088122126148949\", \"price\":\"0.52\", \"size\":\"181.25\", \"side\":\"SELL\", \"hash\":\"2bff1e3182b535df7bc46be2550cac63cf60711e\", \"best_bid\":\"0.5\", \"best_ask\":\"0.51\"}], \"timestamp\":\"1785207017934\", \"event_type\":\"price_change\"}","received_at":"2026-07-28T02:50:20.524101Z","schema_version":"clob-market-ws.price_change.v1","sequence":null,"server_hash":null,"server_timestamp":"1785207017934","session_id":"5aad79be415c487c84df42bebd84ee93","source":"clob_market_ws"},"received_at":"2026-07-28T02:50:20.524101Z","record_id":"84526cad93d646eab1130652d9b14e21309237a8465299c33b70f8db67c6c9f6","schema_fingerprint":"4aa3821a28b0b7c2400bc59aba4bcc0a76e971dadd19610d3ad38c768e124dc7","schema_version":"edge-lab-recorder.raw.v1","sequence":null,"source":"clob_market_ws"}
{"event_at":"2026-07-28T02:50:17.936000Z","event_fingerprint":"84fbd09e85011da03671b14734c0b1e4bb2fd79f9b7b76d0efac907d48e59652","payload":{"connection_id":"955646bd8bf740759faf38750c0f263f","event_at":"2026-07-28T02:50:17.936000Z","event_type":"price_change","frame_hash":"ae252369d38ccf37c8ead50b80953193b834c4135cd6e8ced1410df50149e594","frame_index":0,"kind":"data","monotonic_ns":309003542118750,"payload":{"event_type":"price_change","market":"0x0f70d07969bc69eaa97d0987de651885fdca02263688026aa11e7678af8f87aa","price_changes":[{"asset_id":"58313761654877669244690227616056238030136603415514645252000528337391143520538","best_ask":"0.5","best_bid":"0.49","hash":"084240f5a0f1072260c09092609665e146617b9c","price":"0.48","side":"BUY","size":"186.25"},{"asset_id":"64053005904884194822931764831592250494815136296598204104072528088122126148949","best_ask":"0.51","best_bid":"0.5","hash":"18d07d946bc0f47abacaa8dec9621da037fb4be7","price":"0.52","side":"SELL","size":"186.25"}],"timestamp":"1785207017936"},"payload_hash":"81cb16885ea774ed171fab110cc1eee25cb12b365f1de3b6e4f0b51dde0a92ba","raw_frame":"{\"market\":\"0x0f70d07969bc69eaa97d0987de651885fdca02263688026aa11e7678af8f87aa\", \"price_changes\":[{\"asset_id\":\"58313761654877669244690227616056238030136603415514645252000528337391143520538\", \"price\":\"0.48\", \"size\":\"186.25\", \"side\":\"BUY\", \"hash\":\"084240f5a0f1072260c09092609665e146617b9c\", \"best_bid\":\"0.49\", \"best_ask\":\"0.5\"}, {\"asset_id\":\"64053005904884194822931764831592250494815136296598204104072528088122126148949\", \"price\":\"0.52\", \"size\":\"186.25\", \"side\":\"SELL\", \"hash\":\"18d07d946bc0f47abacaa8dec9621da037fb4be7\", \"best_bid\":\"0.5\", \"best_ask\":\"0.51\"}], \"timestamp\":\"1785207017936\", \"event_type\":\"price_change\"}","received_at":"2026-07-28T02:50:20.527940Z","schema_version":"clob-market-ws.price_change.v1","sequence":null,"server_hash":null,"server_timestamp":"1785207017936","session_id":"5aad79be415c487c84df42bebd84ee93","source":"clob_market_ws"},"received_at":"2026-07-28T02:50:20.527940Z","record_id":"c00894933ee0e01df244f1c74f3406d3f943a6b4483ae1044c2974a9b733903c","schema_fingerprint":"4aa3821a28b0b7c2400bc59aba4bcc0a76e971dadd19610d3ad38c768e124dc7","schema_version":"edge-lab-recorder.raw.v1","sequence":null,"source":"clob_market_ws"}
{"event_at":"2026-07-28T02:50:17.937000Z","event_fingerprint":"87bc80e86bdf93a6b7b90cfb1ef96109c4c77ad38fa6daff9e30d75104f18354","payload":{"connection_id":"955646bd8bf740759faf38750c0f263f","event_at":"2026-07-28T02:50:17.937000Z","event_type":"price_change","frame_hash":"14adbf3dd033387e4940bc57124451b00b7e1ae1aa1930d670bee7f5554b87c0","frame_index":0,"kind":"data","monotonic_ns":309003546025250,"payload":{"event_type":"price_change","market":"0x0f70d07969bc69eaa97d0987de651885fdca02263688026aa11e7678af8f87aa","price_changes":[{"asset_id":"58313761654877669244690227616056238030136603415514645252000528337391143520538","best_ask":"0.5","best_bid":"0.49","hash":"110533cab0bbe3eea07e48bc286970c4387dc285","price":"0.48","side":"BUY","size":"191.25"},{"asset_id":"64053005904884194822931764831592250494815136296598204104072528088122126148949","best_ask":"0.51","best_bid":"0.5","hash":"59dceee5cfdb61f7c676e1ca7afba720bae7a0fc","price":"0.52","side":"SELL","size":"191.25"}],"timestamp":"1785207017937"},"payload_hash":"ed01e6feef0cf1ebd0490c42846e29155fd3ab53f41ab5728a553ee50bbe17e3","raw_frame":"{\"market\":\"0x0f70d07969bc69eaa97d0987de651885fdca02263688026aa11e7678af8f87aa\", \"price_changes\":[{\"asset_id\":\"58313761654877669244690227616056238030136603415514645252000528337391143520538\", \"price\":\"0.48\", \"size\":\"191.25\", \"side\":\"BUY\", \"hash\":\"110533cab0bbe3eea07e48bc286970c4387dc285\", \"best_bid\":\"0.49\", \"best_ask\":\"0.5\"}, {\"asset_id\":\"64053005904884194822931764831592250494815136296598204104072528088122126148949\", \"price\":\"0.52\", \"size\":\"191.25\", \"side\":\"SELL\", \"hash\":\"59dceee5cfdb61f7c676e1ca7afba720bae7a0fc\", \"best_bid\":\"0.5\", \"best_ask\":\"0.51\"}], \"timestamp\":\"1785207017937\", \"event_type\":\"price_change\"}","received_at":"2026-07-28T02:50:20.531844Z","schema_version":"clob-market-ws.price_change.v1","sequence":null,"server_hash":null,"server_timestamp":"1785207017937","session_id":"5aad79be415c487c84df42bebd84ee93","source":"clob_market_ws"},"received_at":"2026-07-28T02:50:20.531844Z","record_id":"57a1f35aeb076201b67833181636d847ecda4c84c970f26afd57f3735bdb1972","schema_fingerprint":"4aa3821a28b0b7c2400bc59aba4bcc0a76e971dadd19610d3ad38c768e124dc7","schema_version":"edge-lab-recorder.raw.v1","sequence":null,"source":"clob_market_ws"}
{"event_at":"2026-07-28T02:50:17.938000Z","event_fingerprint":"1d059438362ff04c8182bd8fb010e8800658156b8834bc820aa037de2e2474fb","payload":{"connection_id":"955646bd8bf740759faf38750c0f263f","event_at":"2026-07-28T02:50:17.938000Z","event_type":"price_change","frame_hash":"d3b20c2de4515ef1cbea014c60c3929514953da9da44baed7070f541e9ccb8f6","frame_index":0,"kind":"data","monotonic_ns":309003550369666,"payload":{"event_type":"price_change","market":"0x0f70d07969bc69eaa97d0987de651885fdca02263688026aa11e7678af8f87aa","price_changes":[{"asset_id":"58313761654877669244690227616056238030136603415514645252000528337391143520538","best_ask":"0.5","best_bid":"0.49","hash":"2fe114ba66e41368cdd5b4ac6962750d3869568b","price":"0.48","side":"BUY","size":"196.25"},{"asset_id":"64053005904884194822931764831592250494815136296598204104072528088122126148949","best_ask":"0.51","best_bid":"0.5","hash":"8293f91d3ff46772e7014f70efa095fd83826e2c","price":"0.52","side":"SELL","size":"196.25"}],"timestamp":"1785207017938"},"payload_hash":"f566509851b61630bd51e7a17c758781d8707ca6ed31c2bc23c051d9299f2c9a","raw_frame":"{\"market\":\"0x0f70d07969bc69eaa97d0987de651885fdca02263688026aa11e7678af8f87aa\", \"price_changes\":[{\"asset_id\":\"58313761654877669244690227616056238030136603415514645252000528337391143520538\", \"price\":\"0.48\", \"size\":\"196.25\", \"side\":\"BUY\", \"hash\":\"2fe114ba66e41368cdd5b4ac6962750d3869568b\", \"best_bid\":\"0.49\", \"best_ask\":\"0.5\"}, {\"asset_id\":\"64053005904884194822931764831592250494815136296598204104072528088122126148949\", \"price\":\"0.52\", \"size\":\"196.25\", \"side\":\"SELL\", \"hash\":\"8293f91d3ff46772e7014f70efa095fd83826e2c\", \"best_bid\":\"0.5\", \"best_ask\":\"0.51\"}], \"timestamp\":\"1785207017938\", \"event_type\":\"price_change\"}","received_at":"2026-07-28T02:50:20.536191Z","schema_version":"clob-market-ws.price_change.v1","sequence":null,"server_hash":null,"server_timestamp":"1785207017938","session_id":"5aad79be415c487c84df42bebd84ee93","source":"clob_market_ws"},"received_at":"2026-07-28T02:50:20.536191Z","record_id":"bf92be0a0ec3a3d81c3e81f4f2d128ac6834dddfd0e293a5452a38c42c32b03a","schema_fingerprint":"4aa3821a28b0b7c2400bc59aba4bcc0a76e971dadd19610d3ad38c768e124dc7","schema_version":"edge-lab-recorder.raw.v1","sequence":null,"source":"clob_market_ws"}
