{"event_at":"2026-07-28T02:57:06.707000Z","event_fingerprint":"f8f4e4dad3cb6bc8cf4b491035baac01472d4636ac6a4c84132615d857b18e00","payload":{"connection_id":"955646bd8bf740759faf38750c0f263f","event_at":"2026-07-28T02:57:06.707000Z","event_type":"price_change","frame_hash":"0415e35139b8b3f482250a7246c7c1daf23d68f17184fd9644c426dcb16e865d","frame_index":0,"kind":"data","monotonic_ns":309409620303416,"payload":{"event_type":"price_change","market":"0x0f70d07969bc69eaa97d0987de651885fdca02263688026aa11e7678af8f87aa","price_changes":[{"asset_id":"64053005904884194822931764831592250494815136296598204104072528088122126148949","best_ask":"0.6","best_bid":"0.59","hash":"01de154a23b5d1ee61c715f3e8fa1e27af7ba5f7","price":"0.58","side":"BUY","size":"108.63"},{"asset_id":"58313761654877669244690227616056238030136603415514645252000528337391143520538","best_ask":"0.41","best_bid":"0.4","hash":"88975d100581e08bceda60c4e44fc78c683c37f3","price":"0.42","side":"SELL","size":"108.63"}],"timestamp":"1785207426707"},"payload_hash":"c8ee8c9f11a799931382855e6fd763629ae70a07bcb11bc7ff73f9849cb83394","raw_frame":"{\"market\":\"0x0f70d07969bc69eaa97d0987de651885fdca02263688026aa11e7678af8f87aa\", \"price_changes\":[{\"asset_id\":\"64053005904884194822931764831592250494815136296598204104072528088122126148949\", \"price\":\"0.58\", \"size\":\"108.63\", \"side\":\"BUY\", \"hash\":\"01de154a23b5d1ee61c715f3e8fa1e27af7ba5f7\", \"best_bid\":\"0.59\", \"best_ask\":\"0.6\"}, {\"asset_id\":\"58313761654877669244690227616056238030136603415514645252000528337391143520538\", \"price\":\"0.42\", \"size\":\"108.63\", \"side\":\"SELL\", \"hash\":\"88975d100581e08bceda60c4e44fc78c683c37f3\", \"best_bid\":\"0.4\", \"best_ask\":\"0.41\"}], \"timestamp\":\"1785207426707\", \"event_type\":\"price_change\"}","received_at":"2026-07-28T02:57:06.603190Z","schema_version":"clob-market-ws.price_change.v1","sequence":null,"server_hash":null,"server_timestamp":"1785207426707","session_id":"5aad79be415c487c84df42bebd84ee93","source":"clob_market_ws"},"received_at":"2026-07-28T02:57:06.603190Z","record_id":"a1abb1285800616d1a74938a9f2b7b8ed29fa029993d1a69e2d567425874d845","schema_fingerprint":"4aa3821a28b0b7c2400bc59aba4bcc0a76e971dadd19610d3ad38c768e124dc7","schema_version":"edge-lab-recorder.raw.v1","sequence":null,"source":"clob_market_ws"}
{"event_at":"2026-07-28T02:57:06.707000Z","event_fingerprint":"fa3fc869ee805222586fee009fdf47e3a9ce2fee34db7deab79e151576e7bf99","payload":{"connection_id":"955646bd8bf740759faf38750c0f263f","event_at":"2026-07-28T02:57:06.707000Z","event_type":"price_change","frame_hash":"8565fb7937dec0ff058b43a30a80eac48ac32db0022a462f9ca7aa37e1ace030","frame_index":0,"kind":"data","monotonic_ns":309409622588958,"payload":{"event_type":"price_change","market":"0x0f70d07969bc69eaa97d0987de651885fdca02263688026aa11e7678af8f87aa","price_changes":[{"asset_id":"58313761654877669244690227616056238030136603415514645252000528337391143520538","best_ask":"0.41","best_bid":"0.4","hash":"719ddc5db45c6e5d27ad4f7e8fe5e27c038d7363","price":"0.3","side":"BUY","size":"290"},{"asset_id":"64053005904884194822931764831592250494815136296598204104072528088122126148949","best_ask":"0.6","best_bid":"0.59","hash":"369706015f214e68569bd7188ff044aae4ea68ea","price":"0.7","side":"SELL","size":"290"}],"timestamp":"1785207426707"},"payload_hash":"ed4d9e413390e5836d821b54bd7dc3cb7c1675c84f3f7b68000be997bce2d6a7","raw_frame":"{\"market\":\"0x0f70d07969bc69eaa97d0987de651885fdca02263688026aa11e7678af8f87aa\", \"price_changes\":[{\"asset_id\":\"58313761654877669244690227616056238030136603415514645252000528337391143520538\", \"price\":\"0.3\", \"size\":\"290\", \"side\":\"BUY\", \"hash\":\"719ddc5db45c6e5d27ad4f7e8fe5e27c038d7363\", \"best_bid\":\"0.4\", \"best_ask\":\"0.41\"}, {\"asset_id\":\"64053005904884194822931764831592250494815136296598204104072528088122126148949\", \"price\":\"0.7\", \"size\":\"290\", \"side\":\"SELL\", \"hash\":\"369706015f214e68569bd7188ff044aae4ea68ea\", \"best_bid\":\"0.59\", \"best_ask\":\"0.6\"}], \"timestamp\":\"1785207426707\", \"event_type\":\"price_change\"}","received_at":"2026-07-28T02:57:06.605475Z","schema_version":"clob-market-ws.price_change.v1","sequence":null,"server_hash":null,"server_timestamp":"1785207426707","session_id":"5aad79be415c487c84df42bebd84ee93","source":"clob_market_ws"},"received_at":"2026-07-28T02:57:06.605475Z","record_id":"9c337afe8cb286b2446461a377740e32edfc37f5425f7f4ee1cca298402677da","schema_fingerprint":"4aa3821a28b0b7c2400bc59aba4bcc0a76e971dadd19610d3ad38c768e124dc7","schema_version":"edge-lab-recorder.raw.v1","sequence":null,"source":"clob_market_ws"}
{"event_at":"2026-07-28T02:57:06.707000Z","event_fingerprint":"ae9785b9a0edda17f04e7267c969d153c9768929bcde979ea3c8f164871bf29a","payload":{"connection_id":"955646bd8bf740759faf38750c0f263f","event_at":"2026-07-28T02:57:06.707000Z","event_type":"price_change","frame_hash":"28f7160081e04511b224c63613d8a35c1a348d89fbed0acc6f35562905dda94c","frame_index":0,"kind":"data","monotonic_ns":309409624192791,"payload":{"event_type":"price_change","market":"0x0f70d07969bc69eaa97d0987de651885fdca02263688026aa11e7678af8f87aa","price_changes":[{"asset_id":"58313761654877669244690227616056238030136603415514645252000528337391143520538","best_ask":"0.41","best_bid":"0.4","hash":"7637525ece1a479f0e4148b0dab4dc5e199a2dac","price":"0.3","side":"BUY","size":"240"},{"asset_id":"64053005904884194822931764831592250494815136296598204104072528088122126148949","best_ask":"0.6","best_bid":"0.59","hash":"887ebcc3d2fd45fe4b78f1e652a72a7890065fa4","price":"0.7","side":"SELL","size":"240"}],"timestamp":"1785207426707"},"payload_hash":"2b868ae0b0f5e05b3898680a2a6d11a7a4129d4e8da6f231b3b96027d1ae860d","raw_frame":"{\"market\":\"0x0f70d07969bc69eaa97d0987de651885fdca02263688026aa11e7678af8f87aa\", \"price_changes\":[{\"asset_id\":\"58313761654877669244690227616056238030136603415514645252000528337391143520538\", \"price\":\"0.3\", \"size\":\"240\", \"side\":\"BUY\", \"hash\":\"7637525ece1a479f0e4148b0dab4dc5e199a2dac\", \"best_bid\":\"0.4\", \"best_ask\":\"0.41\"}, {\"asset_id\":\"64053005904884194822931764831592250494815136296598204104072528088122126148949\", \"price\":\"0.7\", \"size\":\"240\", \"side\":\"SELL\", \"hash\":\"887ebcc3d2fd45fe4b78f1e652a72a7890065fa4\", \"best_bid\":\"0.59\", \"best_ask\":\"0.6\"}], \"timestamp\":\"1785207426707\", \"event_type\":\"price_change\"}","received_at":"2026-07-28T02:57:06.607081Z","schema_version":"clob-market-ws.price_change.v1","sequence":null,"server_hash":null,"server_timestamp":"1785207426707","session_id":"5aad79be415c487c84df42bebd84ee93","source":"clob_market_ws"},"received_at":"2026-07-28T02:57:06.607081Z","record_id":"9deb450f2feffb1061e9e163d6d4b5ce6b6215f5a56d33e9ae85d4054943a376","schema_fingerprint":"4aa3821a28b0b7c2400bc59aba4bcc0a76e971dadd19610d3ad38c768e124dc7","schema_version":"edge-lab-recorder.raw.v1","sequence":null,"source":"clob_market_ws"}
{"event_at":"2026-07-28T02:57:06.707000Z","event_fingerprint":"4a284967e969ae347aaf01f2217488644ebad7b9a57c16d9543c14622453b96b","payload":{"connection_id":"955646bd8bf740759faf38750c0f263f","event_at":"2026-07-28T02:57:06.707000Z","event_type":"price_change","frame_hash":"ab7643543b11ceda2df7f09d36f929b64b4c2cdb1ee93c45adb599f1b39df106","frame_index":0,"kind":"data","monotonic_ns":309409625677916,"payload":{"event_type":"price_change","market":"0x0f70d07969bc69eaa97d0987de651885fdca02263688026aa11e7678af8f87aa","price_changes":[{"asset_id":"58313761654877669244690227616056238030136603415514645252000528337391143520538","best_ask":"0.41","best_bid":"0.4","hash":"4c6d494dc127ce1d6ecb3cae1590b4f8d7a59662","price":"0.19","side":"BUY","size":"232.19"},{"asset_id":"64053005904884194822931764831592250494815136296598204104072528088122126148949","best_ask":"0.6","best_bid":"0.59","hash":"df8eea50b0ef73ddb613258dbc9a2775a251f845","price":"0.81","side":"SELL","size":"232.19"}],"timestamp":"1785207426707"},"payload_hash":"c786dbc7f1bfdbc07d7523d2b65690f67ff4fc3598a6d582b2b106cd3a02d05f","raw_frame":"{\"market\":\"0x0f70d07969bc69eaa97d0987de651885fdca02263688026aa11e7678af8f87aa\", \"price_changes\":[{\"asset_id\":\"58313761654877669244690227616056238030136603415514645252000528337391143520538\", \"price\":\"0.19\", \"size\":\"232.19\", \"side\":\"BUY\", \"hash\":\"4c6d494dc127ce1d6ecb3cae1590b4f8d7a59662\", \"best_bid\":\"0.4\", \"best_ask\":\"0.41\"}, {\"asset_id\":\"64053005904884194822931764831592250494815136296598204104072528088122126148949\", \"price\":\"0.81\", \"size\":\"232.19\", \"side\":\"SELL\", \"hash\":\"df8eea50b0ef73ddb613258dbc9a2775a251f845\", \"best_bid\":\"0.59\", \"best_ask\":\"0.6\"}], \"timestamp\":\"1785207426707\", \"event_type\":\"price_change\"}","received_at":"2026-07-28T02:57:06.608566Z","schema_version":"clob-market-ws.price_change.v1","sequence":null,"server_hash":null,"server_timestamp":"1785207426707","session_id":"5aad79be415c487c84df42bebd84ee93","source":"clob_market_ws"},"received_at":"2026-07-28T02:57:06.608566Z","record_id":"9a31486b3bfa659b045667c9f025a0547af9b3fe16d84bed46a94fa31c40a79a","schema_fingerprint":"4aa3821a28b0b7c2400bc59aba4bcc0a76e971dadd19610d3ad38c768e124dc7","schema_version":"edge-lab-recorder.raw.v1","sequence":null,"source":"clob_market_ws"}
{"event_at":"2026-07-28T02:57:06.708000Z","event_fingerprint":"1b08c0bc724fa5a50e0f1d6357fe20292611870591b2774d50a0bc4a153be379","payload":{"connection_id":"955646bd8bf740759faf38750c0f263f","event_at":"2026-07-28T02:57:06.708000Z","event_type":"price_change","frame_hash":"534c911ce09113467ba1a21a594f53ad36623e23d7df88094ab6dd86254d4fb7","frame_index":0,"kind":"data","monotonic_ns":309409627295333,"payload":{"event_type":"price_change","market":"0x0f70d07969bc69eaa97d0987de651885fdca02263688026aa11e7678af8f87aa","price_changes":[{"asset_id":"58313761654877669244690227616056238030136603415514645252000528337391143520538","best_ask":"0.41","best_bid":"0.4","hash":"c65c6259dca70ba2fb304d5a4adac35b57dcc49f","price":"0.3","side":"BUY","size":"190"},{"asset_id":"64053005904884194822931764831592250494815136296598204104072528088122126148949","best_ask":"0.6","best_bid":"0.59","hash":"f838506f6e0c16f8f3eccba392304438d246bc18","price":"0.7","side":"SELL","size":"190"}],"timestamp":"1785207426708"},"payload_hash":"e9f7348facc01fe78316074d84b68ab70742c0b89de7f37bd04a40b8d82db2ce","raw_frame":"{\"market\":\"0x0f70d07969bc69eaa97d0987de651885fdca02263688026aa11e7678af8f87aa\", \"price_changes\":[{\"asset_id\":\"58313761654877669244690227616056238030136603415514645252000528337391143520538\", \"price\":\"0.3\", \"size\":\"190\", \"side\":\"BUY\", \"hash\":\"c65c6259dca70ba2fb304d5a4adac35b57dcc49f\", \"best_bid\":\"0.4\", \"best_ask\":\"0.41\"}, {\"asset_id\":\"64053005904884194822931764831592250494815136296598204104072528088122126148949\", \"price\":\"0.7\", \"size\":\"190\", \"side\":\"SELL\", \"hash\":\"f838506f6e0c16f8f3eccba392304438d246bc18\", \"best_bid\":\"0.59\", \"best_ask\":\"0.6\"}], \"timestamp\":\"1785207426708\", \"event_type\":\"price_change\"}","received_at":"2026-07-28T02:57:06.610183Z","schema_version":"clob-market-ws.price_change.v1","sequence":null,"server_hash":null,"server_timestamp":"1785207426708","session_id":"5aad79be415c487c84df42bebd84ee93","source":"clob_market_ws"},"received_at":"2026-07-28T02:57:06.610183Z","record_id":"db4704fc58638865142ba38cb9eb316871c5926ded39ada1cd13918e9266381f","schema_fingerprint":"4aa3821a28b0b7c2400bc59aba4bcc0a76e971dadd19610d3ad38c768e124dc7","schema_version":"edge-lab-recorder.raw.v1","sequence":null,"source":"clob_market_ws"}
{"event_at":"2026-07-28T02:57:06.708000Z","event_fingerprint":"b6d8469cbca1fc559ff7f5b74be5cbf32f4feaa33d24f69e5b5b5af6b7921f1b","payload":{"connection_id":"955646bd8bf740759faf38750c0f263f","event_at":"2026-07-28T02:57:06.708000Z","event_type":"price_change","frame_hash":"47fd9386d02b5a70e973626508a63752c1ec7e855e74fdc903fca8ebc3d095a9","frame_index":0,"kind":"data","monotonic_ns":309409628813458,"payload":{"event_type":"price_change","market":"0x0f70d07969bc69eaa97d0987de651885fdca02263688026aa11e7678af8f87aa","price_changes":[{"asset_id":"64053005904884194822931764831592250494815136296598204104072528088122126148949","best_ask":"0.6","best_bid":"0.59","hash":"729c4a85b3ccd4bd7d6842894f05433a9a6d4a72","price":"0.6","side":"SELL","size":"111.36"},{"asset_id":"58313761654877669244690227616056238030136603415514645252000528337391143520538","best_ask":"0.41","best_bid":"0.4","hash":"651e1ed5e4c4f4752d85fdb4bbc16609d39b5ff8","price":"0.4","side":"BUY","size":"111.36"}],"timestamp":"1785207426708"},"payload_hash":"2a47e19950197cee48a680cca11728dce94051289b215de1e7487016cd47d712","raw_frame":"{\"market\":\"0x0f70d07969bc69eaa97d0987de651885fdca02263688026aa11e7678af8f87aa\", \"price_changes\":[{\"asset_id\":\"64053005904884194822931764831592250494815136296598204104072528088122126148949\", \"price\":\"0.6\", \"size\":\"111.36\", \"side\":\"SELL\", \"hash\":\"729c4a85b3ccd4bd7d6842894f05433a9a6d4a72\", \"best_bid\":\"0.59\", \"best_ask\":\"0.6\"}, {\"asset_id\":\"58313761654877669244690227616056238030136603415514645252000528337391143520538\", \"price\":\"0.4\", \"size\":\"111.36\", \"side\":\"BUY\", \"hash\":\"651e1ed5e4c4f4752d85fdb4bbc16609d39b5ff8\", \"best_bid\":\"0.4\", \"best_ask\":\"0.41\"}], \"timestamp\":\"1785207426708\", \"event_type\":\"price_change\"}","received_at":"2026-07-28T02:57:06.611702Z","schema_version":"clob-market-ws.price_change.v1","sequence":null,"server_hash":null,"server_timestamp":"1785207426708","session_id":"5aad79be415c487c84df42bebd84ee93","source":"clob_market_ws"},"received_at":"2026-07-28T02:57:06.611702Z","record_id":"7d27d1e96141e4120f3f7609a34f93aa86adda99b73eaee4f1aecdbbfd150213","schema_fingerprint":"4aa3821a28b0b7c2400bc59aba4bcc0a76e971dadd19610d3ad38c768e124dc7","schema_version":"edge-lab-recorder.raw.v1","sequence":null,"source":"clob_market_ws"}
{"event_at":"2026-07-28T02:57:06.705000Z","event_fingerprint":"a793049e22a8f7abd197e805ab8ec94fdad97bc48b4fdd934427f53fc7cff297","payload":{"connection_id":"955646bd8bf740759faf38750c0f263f","event_at":"2026-07-28T02:57:06.705000Z","event_type":"last_trade_price","frame_hash":"2fa6936457dc4012738a4ce563c9a548b2878593ed219944fe474c5fea797ddb","frame_index":0,"kind":"data","monotonic_ns":309409631002500,"payload":{"asset_id":"64053005904884194822931764831592250494815136296598204104072528088122126148949","event_type":"last_trade_price","fee_rate_bps":"0","market":"0x0f70d07969bc69eaa97d0987de651885fdca02263688026aa11e7678af8f87aa","price":"0.6","side":"BUY","size":"5","timestamp":"1785207426705","transaction_hash":"0x0a39d6adab46bf4ec5857c54180f7bfb0612b4326c9da8239b59811a3f40c3a7"},"payload_hash":"c67540c88ff1a9d435e991fd29ba555c6403c9016e7e1bd507506737f67498a1","raw_frame":"{\"market\":\"0x0f70d07969bc69eaa97d0987de651885fdca02263688026aa11e7678af8f87aa\", \"asset_id\":\"64053005904884194822931764831592250494815136296598204104072528088122126148949\", \"price\":\"0.6\", \"size\":\"5\", \"fee_rate_bps\":\"0\", \"side\":\"BUY\", \"timestamp\":\"1785207426705\", \"event_type\":\"last_trade_price\", \"transaction_hash\":\"0x0a39d6adab46bf4ec5857c54180f7bfb0612b4326c9da8239b59811a3f40c3a7\"}","received_at":"2026-07-28T02:57:06.613890Z","schema_version":"clob-market-ws.last_trade_price.v1","sequence":null,"server_hash":null,"server_timestamp":"1785207426705","session_id":"5aad79be415c487c84df42bebd84ee93","source":"clob_market_ws"},"received_at":"2026-07-28T02:57:06.613890Z","record_id":"340760d7d02a1757d99430f1b897597e9c19b080f433df50bfdb46e446c48b35","schema_fingerprint":"95ad9be75a4b695cd99991e12b2592bc7346f3f5388a82d0000ba65bc0d9fd0a","schema_version":"edge-lab-recorder.raw.v1","sequence":null,"source":"clob_market_ws"}
{"event_at":"2026-07-28T02:57:06.709000Z","event_fingerprint":"2da4c33e250f2d65eac8f96f6001f1c2f9712da114d8acf032ea33d9a8249de9","payload":{"connection_id":"955646bd8bf740759faf38750c0f263f","event_at":"2026-07-28T02:57:06.709000Z","event_type":"price_change","frame_hash":"f22baf01fac428256d9a1578fb344bbeef10d691d3511b16972ad9e184af3b6f","frame_index":0,"kind":"data","monotonic_ns":309409632182458,"payload":{"event_type":"price_change","market":"0x0f70d07969bc69eaa97d0987de651885fdca02263688026aa11e7678af8f87aa","price_changes":[{"asset_id":"58313761654877669244690227616056238030136603415514645252000528337391143520538","best_ask":"0.41","best_bid":"0.4","hash":"27a796ebef89d88b8f8ecac5c818bd924805a93c","price":"0.39","side":"BUY","size":"65.88"},{"asset_id":"64053005904884194822931764831592250494815136296598204104072528088122126148949","best_ask":"0.6","best_bid":"0.59","hash":"a7acacca78116c5558235b5ccf24412154d9d05f","price":"0.61","side":"SELL","size":"65.88"}],"timestamp":"1785207426709"},"payload_hash":"4cedfeb3f29d85920820387ec4dab7ac931b9ead970fcf394f09409d823f8525","raw_frame":"{\"market\":\"0x0f70d07969bc69eaa97d0987de651885fdca02263688026aa11e7678af8f87aa\", \"price_changes\":[{\"asset_id\":\"58313761654877669244690227616056238030136603415514645252000528337391143520538\", \"price\":\"0.39\", \"size\":\"65.88\", \"side\":\"BUY\", \"hash\":\"27a796ebef89d88b8f8ecac5c818bd924805a93c\", \"best_bid\":\"0.4\", \"best_ask\":\"0.41\"}, {\"asset_id\":\"64053005904884194822931764831592250494815136296598204104072528088122126148949\", \"price\":\"0.61\", \"size\":\"65.88\", \"side\":\"SELL\", \"hash\":\"a7acacca78116c5558235b5ccf24412154d9d05f\", \"best_bid\":\"0.59\", \"best_ask\":\"0.6\"}], \"timestamp\":\"1785207426709\", \"event_type\":\"price_change\"}","received_at":"2026-07-28T02:57:06.615070Z","schema_version":"clob-market-ws.price_change.v1","sequence":null,"server_hash":null,"server_timestamp":"1785207426709","session_id":"5aad79be415c487c84df42bebd84ee93","source":"clob_market_ws"},"received_at":"2026-07-28T02:57:06.615070Z","record_id":"0d4faa606baca176c517ebcd81b11a44a04218895198bfb4480d0efb2bd1f390","schema_fingerprint":"4aa3821a28b0b7c2400bc59aba4bcc0a76e971dadd19610d3ad38c768e124dc7","schema_version":"edge-lab-recorder.raw.v1","sequence":null,"source":"clob_market_ws"}
{"event_at":"2026-07-28T02:57:06.709000Z","event_fingerprint":"c30428e0010bf53393e94b20bb48e25d1ff8a0b563036a1e097b44d9998e2324","payload":{"connection_id":"955646bd8bf740759faf38750c0f263f","event_at":"2026-07-28T02:57:06.709000Z","event_type":"price_change","frame_hash":"0ea2c889ced35e98f47dfdb0dbdb702fcb3e0e2421057aa1c413be9480c95898","frame_index":0,"kind":"data","monotonic_ns":309409633766125,"payload":{"event_type":"price_change","market":"0x0f70d07969bc69eaa97d0987de651885fdca02263688026aa11e7678af8f87aa","price_changes":[{"asset_id":"64053005904884194822931764831592250494815136296598204104072528088122126148949","best_ask":"0.6","best_bid":"0.59","hash":"a7acacca78116c5558235b5ccf24412154d9d05f","price":"0.54","side":"BUY","size":"150.6"},{"asset_id":"58313761654877669244690227616056238030136603415514645252000528337391143520538","best_ask":"0.41","best_bid":"0.4","hash":"27a796ebef89d88b8f8ecac5c818bd924805a93c","price":"0.46","side":"SELL","size":"150.6"}],"timestamp":"1785207426709"},"payload_hash":"ea8eb471049ecfaaa644183ee52b7479ed12d49e830ec4201a32c921d45171ec","raw_frame":"{\"market\":\"0x0f70d07969bc69eaa97d0987de651885fdca02263688026aa11e7678af8f87aa\", \"price_changes\":[{\"asset_id\":\"64053005904884194822931764831592250494815136296598204104072528088122126148949\", \"price\":\"0.54\", \"size\":\"150.6\", \"side\":\"BUY\", \"hash\":\"a7acacca78116c5558235b5ccf24412154d9d05f\", \"best_bid\":\"0.59\", \"best_ask\":\"0.6\"}, {\"asset_id\":\"58313761654877669244690227616056238030136603415514645252000528337391143520538\", \"price\":\"0.46\", \"size\":\"150.6\", \"side\":\"SELL\", \"hash\":\"27a796ebef89d88b8f8ecac5c818bd924805a93c\", \"best_bid\":\"0.4\", \"best_ask\":\"0.41\"}], \"timestamp\":\"1785207426709\", \"event_type\":\"price_change\"}","received_at":"2026-07-28T02:57:06.616654Z","schema_version":"clob-market-ws.price_change.v1","sequence":null,"server_hash":null,"server_timestamp":"1785207426709","session_id":"5aad79be415c487c84df42bebd84ee93","source":"clob_market_ws"},"received_at":"2026-07-28T02:57:06.616654Z","record_id":"47bc15e9c6c9442aec30cca157ed9d4f727a014a3b149d43a7e76e6c49f5aa6b","schema_fingerprint":"4aa3821a28b0b7c2400bc59aba4bcc0a76e971dadd19610d3ad38c768e124dc7","schema_version":"edge-lab-recorder.raw.v1","sequence":null,"source":"clob_market_ws"}
{"event_at":"2026-07-28T02:57:06.709000Z","event_fingerprint":"2c3186c3952956d308499e7af41c5ecb4ce0da100380bde9799fe39e3ba2647b","payload":{"connection_id":"955646bd8bf740759faf38750c0f263f","event_at":"2026-07-28T02:57:06.709000Z","event_type":"price_change","frame_hash":"c5fae4ceb319772594b56cdf9c3281128d36a3bbf96a8a88d2807d2bc3f914ef","frame_index":0,"kind":"data","monotonic_ns":309409635272083,"payload":{"event_type":"price_change","market":"0x0f70d07969bc69eaa97d0987de651885fdca02263688026aa11e7678af8f87aa","price_changes":[{"asset_id":"58313761654877669244690227616056238030136603415514645252000528337391143520538","best_ask":"0.41","best_bid":"0.4","hash":"4989e11fb259b6a1ae2486941ad2308a6568e2ee","price":"0.4","side":"BUY","size":"121.36"},{"asset_id":"64053005904884194822931764831592250494815136296598204104072528088122126148949","best_ask":"0.6","best_bid":"0.59","hash":"60270f2855ecb8774ed2fa92dbb243e14419ce48","price":"0.6","side":"SELL","size":"121.36"}],"timestamp":"1785207426709"},"payload_hash":"c50d3574da4aeca80cf93da58c5b56249ef535e15c8b493aa0d764b5757131ba","raw_frame":"{\"market\":\"0x0f70d07969bc69eaa97d0987de651885fdca02263688026aa11e7678af8f87aa\", \"price_changes\":[{\"asset_id\":\"58313761654877669244690227616056238030136603415514645252000528337391143520538\", \"price\":\"0.4\", \"size\":\"121.36\", \"side\":\"BUY\", \"hash\":\"4989e11fb259b6a1ae2486941ad2308a6568e2ee\", \"best_bid\":\"0.4\", \"best_ask\":\"0.41\"}, {\"asset_id\":\"64053005904884194822931764831592250494815136296598204104072528088122126148949\", \"price\":\"0.6\", \"size\":\"121.36\", \"side\":\"SELL\", \"hash\":\"60270f2855ecb8774ed2fa92dbb243e14419ce48\", \"best_bid\":\"0.59\", \"best_ask\":\"0.6\"}], \"timestamp\":\"1785207426709\", \"event_type\":\"price_change\"}","received_at":"2026-07-28T02:57:06.618160Z","schema_version":"clob-market-ws.price_change.v1","sequence":null,"server_hash":null,"server_timestamp":"1785207426709","session_id":"5aad79be415c487c84df42bebd84ee93","source":"clob_market_ws"},"received_at":"2026-07-28T02:57:06.618160Z","record_id":"6df5d70b938889ddea7907d754888cf5af50bb6607fc8397d8db7fa354ea8eac","schema_fingerprint":"4aa3821a28b0b7c2400bc59aba4bcc0a76e971dadd19610d3ad38c768e124dc7","schema_version":"edge-lab-recorder.raw.v1","sequence":null,"source":"clob_market_ws"}
{"event_at":"2026-07-28T02:57:06.710000Z","event_fingerprint":"cf44f0767962e04bb57a0130951dc0344909e87f03d0c13e9985d55060a04113","payload":{"connection_id":"955646bd8bf740759faf38750c0f263f","event_at":"2026-07-28T02:57:06.710000Z","event_type":"price_change","frame_hash":"bbc6293b242de605d90186afe096136e96c2ca151531c4761888dd9b9f88c2ae","frame_index":0,"kind":"data","monotonic_ns":309409636754333,"payload":{"event_type":"price_change","market":"0x0f70d07969bc69eaa97d0987de651885fdca02263688026aa11e7678af8f87aa","price_changes":[{"asset_id":"64053005904884194822931764831592250494815136296598204104072528088122126148949","best_ask":"0.6","best_bid":"0.59","hash":"2b609a425f32798b71332f7cb69cc3b650fac2ab","price":"0.53","side":"BUY","size":"269.64"},{"asset_id":"58313761654877669244690227616056238030136603415514645252000528337391143520538","best_ask":"0.41","best_bid":"0.4","hash":"dde1f9c81893a40a410ca000c527531b3f8c4d94","price":"0.47","side":"SELL","size":"269.64"}],"timestamp":"1785207426710"},"payload_hash":"fa7aa87912812ead743c3f6ec40715d07246757b870796e45cd971c62092aac9","raw_frame":"{\"market\":\"0x0f70d07969bc69eaa97d0987de651885fdca02263688026aa11e7678af8f87aa\", \"price_changes\":[{\"asset_id\":\"64053005904884194822931764831592250494815136296598204104072528088122126148949\", \"price\":\"0.53\", \"size\":\"269.64\", \"side\":\"BUY\", \"hash\":\"2b609a425f32798b71332f7cb69cc3b650fac2ab\", \"best_bid\":\"0.59\", \"best_ask\":\"0.6\"}, {\"asset_id\":\"58313761654877669244690227616056238030136603415514645252000528337391143520538\", \"price\":\"0.47\", \"size\":\"269.64\", \"side\":\"SELL\", \"hash\":\"dde1f9c81893a40a410ca000c527531b3f8c4d94\", \"best_bid\":\"0.4\", \"best_ask\":\"0.41\"}], \"timestamp\":\"1785207426710\", \"event_type\":\"price_change\"}","received_at":"2026-07-28T02:57:06.619642Z","schema_version":"clob-market-ws.price_change.v1","sequence":null,"server_hash":null,"server_timestamp":"1785207426710","session_id":"5aad79be415c487c84df42bebd84ee93","source":"clob_market_ws"},"received_at":"2026-07-28T02:57:06.619642Z","record_id":"5d90891a57a46f45c46938d9861a21d1fdd1ff9719eb1394461ff61bb0c18678","schema_fingerprint":"4aa3821a28b0b7c2400bc59aba4bcc0a76e971dadd19610d3ad38c768e124dc7","schema_version":"edge-lab-recorder.raw.v1","sequence":null,"source":"clob_market_ws"}
{"event_at":"2026-07-28T02:57:06.711000Z","event_fingerprint":"8f44873dae470016693c0f87c264383627ef0973309a21b95ac1f979192e6e6d","payload":{"connection_id":"955646bd8bf740759faf38750c0f263f","event_at":"2026-07-28T02:57:06.711000Z","event_type":"price_change","frame_hash":"6de0f4017d6d1e4192e8748c5f98ebfac049173bd4e5b2706269b53458bde54c","frame_index":0,"kind":"data","monotonic_ns":309409638242208,"payload":{"event_type":"price_change","market":"0x0f70d07969bc69eaa97d0987de651885fdca02263688026aa11e7678af8f87aa","price_changes":[{"asset_id":"64053005904884194822931764831592250494815136296598204104072528088122126148949","best_ask":"0.6","best_bid":"0.59","hash":"a3e09894332ac99592dedefbfedda1ce3747823f","price":"0.54","side":"BUY","size":"207.6"},{"asset_id":"58313761654877669244690227616056238030136603415514645252000528337391143520538","best_ask":"0.41","best_bid":"0.4","hash":"7ddce000dc3c90a14fd607b9ad90ad3be3184e0b","price":"0.46","side":"SELL","size":"207.6"}],"timestamp":"1785207426711"},"payload_hash":"d610f9376a3739828223b2e0139216d50a1c7eaca63181663a0f33b442880dde","raw_frame":"{\"market\":\"0x0f70d07969bc69eaa97d0987de651885fdca02263688026aa11e7678af8f87aa\", \"price_changes\":[{\"asset_id\":\"64053005904884194822931764831592250494815136296598204104072528088122126148949\", \"price\":\"0.54\", \"size\":\"207.6\", \"side\":\"BUY\", \"hash\":\"a3e09894332ac99592dedefbfedda1ce3747823f\", \"best_bid\":\"0.59\", \"best_ask\":\"0.6\"}, {\"asset_id\":\"58313761654877669244690227616056238030136603415514645252000528337391143520538\", \"price\":\"0.46\", \"size\":\"207.6\", \"side\":\"SELL\", \"hash\":\"7ddce000dc3c90a14fd607b9ad90ad3be3184e0b\", \"best_bid\":\"0.4\", \"best_ask\":\"0.41\"}], \"timestamp\":\"1785207426711\", \"event_type\":\"price_change\"}","received_at":"2026-07-28T02:57:06.621131Z","schema_version":"clob-market-ws.price_change.v1","sequence":null,"server_hash":null,"server_timestamp":"1785207426711","session_id":"5aad79be415c487c84df42bebd84ee93","source":"clob_market_ws"},"received_at":"2026-07-28T02:57:06.621131Z","record_id":"425ba3820606a71c81eec7391dc147287d0d5a13e4e431598b4911c1b3cb251e","schema_fingerprint":"4aa3821a28b0b7c2400bc59aba4bcc0a76e971dadd19610d3ad38c768e124dc7","schema_version":"edge-lab-recorder.raw.v1","sequence":null,"source":"clob_market_ws"}
{"event_at":"2026-07-28T02:57:06.712000Z","event_fingerprint":"dec25bbd44735ec21bc5ee27afcb9409f90da8d23198b5e7383ab72d54d4170b","payload":{"connection_id":"955646bd8bf740759faf38750c0f263f","event_at":"2026-07-28T02:57:06.712000Z","event_type":"price_change","frame_hash":"a2779a7f9bc373d05c259b9ae69ba0c2c11c0dcceef0df638a9358a72953169f","frame_index":0,"kind":"data","monotonic_ns":309409639764750,"payload":{"event_type":"price_change","market":"0x0f70d07969bc69eaa97d0987de651885fdca02263688026aa11e7678af8f87aa","price_changes":[{"asset_id":"58313761654877669244690227616056238030136603415514645252000528337391143520538","best_ask":"0.41","best_bid":"0.4","hash":"5235d297c95acf0540b76deea6e186d7bb471f36","price":"0.32","side":"BUY","size":"189.18"},{"asset_id":"64053005904884194822931764831592250494815136296598204104072528088122126148949","best_ask":"0.6","best_bid":"0.59","hash":"9cfd47b4764f18339b11e7ad38230e49dc0cf965","price":"0.68","side":"SELL","size":"189.18"}],"timestamp":"1785207426712"},"payload_hash":"6c812120c60a307f9e23a08538bbc0045555d1a249cafc9c2a8be59c282cf5f9","raw_frame":"{\"market\":\"0x0f70d07969bc69eaa97d0987de651885fdca02263688026aa11e7678af8f87aa\", \"price_changes\":[{\"asset_id\":\"58313761654877669244690227616056238030136603415514645252000528337391143520538\", \"price\":\"0.32\", \"size\":\"189.18\", \"side\":\"BUY\", \"hash\":\"5235d297c95acf0540b76deea6e186d7bb471f36\", \"best_bid\":\"0.4\", \"best_ask\":\"0.41\"}, {\"asset_id\":\"64053005904884194822931764831592250494815136296598204104072528088122126148949\", \"price\":\"0.68\", \"size\":\"189.18\", \"side\":\"SELL\", \"hash\":\"9cfd47b4764f18339b11e7ad38230e49dc0cf965\", \"best_bid\":\"0.59\", \"best_ask\":\"0.6\"}], \"timestamp\":\"1785207426712\", \"event_type\":\"price_change\"}","received_at":"2026-07-28T02:57:06.622653Z","schema_version":"clob-market-ws.price_change.v1","sequence":null,"server_hash":null,"server_timestamp":"1785207426712","session_id":"5aad79be415c487c84df42bebd84ee93","source":"clob_market_ws"},"received_at":"2026-07-28T02:57:06.622653Z","record_id":"09c8aaf399cab1292093f1f70f5dca778b82817d54a8faac3f818047c4fca2a1","schema_fingerprint":"4aa3821a28b0b7c2400bc59aba4bcc0a76e971dadd19610d3ad38c768e124dc7","schema_version":"edge-lab-recorder.raw.v1","sequence":null,"source":"clob_market_ws"}
{"event_at":"2026-07-28T02:57:06.712000Z","event_fingerprint":"4785147b265d152aa646e4169f62f826278122c61445c5ce47a82d4d42e04390","payload":{"connection_id":"955646bd8bf740759faf38750c0f263f","event_at":"2026-07-28T02:57:06.712000Z","event_type":"price_change","frame_hash":"ea7e17afb2eeb9deeda3a915ceaf3b00dc9c96cc42be8c32abaece6035d5ed92","frame_index":0,"kind":"data","monotonic_ns":309409641296000,"payload":{"event_type":"price_change","market":"0x0f70d07969bc69eaa97d0987de651885fdca02263688026aa11e7678af8f87aa","price_changes":[{"asset_id":"58313761654877669244690227616056238030136603415514645252000528337391143520538","best_ask":"0.41","best_bid":"0.4","hash":"4907be407cdc20bd5eb8921f5e8b37e9c438bb55","price":"0.37","side":"BUY","size":"104.37"},{"asset_id":"64053005904884194822931764831592250494815136296598204104072528088122126148949","best_ask":"0.6","best_bid":"0.59","hash":"d21cd885368661bfdad2c9bd0c53c139b500cca7","price":"0.63","side":"SELL","size":"104.37"}],"timestamp":"1785207426712"},"payload_hash":"5a8b9eea91f403cbcd25132fd0b04a3a526b5253c47b761734857563a30e29ba","raw_frame":"{\"market\":\"0x0f70d07969bc69eaa97d0987de651885fdca02263688026aa11e7678af8f87aa\", \"price_changes\":[{\"asset_id\":\"58313761654877669244690227616056238030136603415514645252000528337391143520538\", \"price\":\"0.37\", \"size\":\"104.37\", \"side\":\"BUY\", \"hash\":\"4907be407cdc20bd5eb8921f5e8b37e9c438bb55\", \"best_bid\":\"0.4\", \"best_ask\":\"0.41\"}, {\"asset_id\":\"64053005904884194822931764831592250494815136296598204104072528088122126148949\", \"price\":\"0.63\", \"size\":\"104.37\", \"side\":\"SELL\", \"hash\":\"d21cd885368661bfdad2c9bd0c53c139b500cca7\", \"best_bid\":\"0.59\", \"best_ask\":\"0.6\"}], \"timestamp\":\"1785207426712\", \"event_type\":\"price_change\"}","received_at":"2026-07-28T02:57:06.624184Z","schema_version":"clob-market-ws.price_change.v1","sequence":null,"server_hash":null,"server_timestamp":"1785207426712","session_id":"5aad79be415c487c84df42bebd84ee93","source":"clob_market_ws"},"received_at":"2026-07-28T02:57:06.624184Z","record_id":"d93db6b88849fccda1554067e20c9efa5023513a18a5872dcc2c98ba5e2cc314","schema_fingerprint":"4aa3821a28b0b7c2400bc59aba4bcc0a76e971dadd19610d3ad38c768e124dc7","schema_version":"edge-lab-recorder.raw.v1","sequence":null,"source":"clob_market_ws"}
{"event_at":"2026-07-28T02:57:06.713000Z","event_fingerprint":"2984c608e0ce9e85a11ae942f22da9530b6a63a5abb5632f755cb08856c520c8","payload":{"connection_id":"955646bd8bf740759faf38750c0f263f","event_at":"2026-07-28T02:57:06.713000Z","event_type":"price_change","frame_hash":"fde906f02e52eb0223c74b80909e112c425b65daf4a1136542c95dc4d2012219","frame_index":0,"kind":"data","monotonic_ns":309409642767875,"payload":{"event_type":"price_change","market":"0x0f70d07969bc69eaa97d0987de651885fdca02263688026aa11e7678af8f87aa","price_changes":[{"asset_id":"58313761654877669244690227616056238030136603415514645252000528337391143520538","best_ask":"0.41","best_bid":"0.4","hash":"c651446858ec18c3dd0d768ff21a459279175ea6","price":"0.4","side":"BUY","size":"129.76"},{"asset_id":"64053005904884194822931764831592250494815136296598204104072528088122126148949","best_ask":"0.6","best_bid":"0.59","hash":"e9a7d5c99495695edb5ef88aca1ad0afd73d4773","price":"0.6","side":"SELL","size":"129.76"}],"timestamp":"1785207426713"},"payload_hash":"49bb3b4901d6c09408246e39970ee4ff6f93272b1f859fc42f44ef046afcc6ca","raw_frame":"{\"market\":\"0x0f70d07969bc69eaa97d0987de651885fdca02263688026aa11e7678af8f87aa\", \"price_changes\":[{\"asset_id\":\"58313761654877669244690227616056238030136603415514645252000528337391143520538\", \"price\":\"0.4\", \"size\":\"129.76\", \"side\":\"BUY\", \"hash\":\"c651446858ec18c3dd0d768ff21a459279175ea6\", \"best_bid\":\"0.4\", \"best_ask\":\"0.41\"}, {\"asset_id\":\"64053005904884194822931764831592250494815136296598204104072528088122126148949\", \"price\":\"0.6\", \"size\":\"129.76\", \"side\":\"SELL\", \"hash\":\"e9a7d5c99495695edb5ef88aca1ad0afd73d4773\", \"best_bid\":\"0.59\", \"best_ask\":\"0.6\"}], \"timestamp\":\"1785207426713\", \"event_type\":\"price_change\"}","received_at":"2026-07-28T02:57:06.625657Z","schema_version":"clob-market-ws.price_change.v1","sequence":null,"server_hash":null,"server_timestamp":"1785207426713","session_id":"5aad79be415c487c84df42bebd84ee93","source":"clob_market_ws"},"received_at":"2026-07-28T02:57:06.625657Z","record_id":"96c48cf342db469eb2868dc1de6853ac6b8a7cb1aa75e3cdffdfa0bb4edcb826","schema_fingerprint":"4aa3821a28b0b7c2400bc59aba4bcc0a76e971dadd19610d3ad38c768e124dc7","schema_version":"edge-lab-recorder.raw.v1","sequence":null,"source":"clob_market_ws"}
{"event_at":"2026-07-28T02:57:06.714000Z","event_fingerprint":"c47d00c5e490c3229b28189b4b805aca18a5644fd826f2c6c24280f99e82782c","payload":{"connection_id":"955646bd8bf740759faf38750c0f263f","event_at":"2026-07-28T02:57:06.714000Z","event_type":"price_change","frame_hash":"40d8715a8e9ea6cd71d279ce7de28d8a9b0f2c2aecbe2dc4667b6174b1b80d65","frame_index":0,"kind":"data","monotonic_ns":309409644213541,"payload":{"event_type":"price_change","market":"0x0f70d07969bc69eaa97d0987de651885fdca02263688026aa11e7678af8f87aa","price_changes":[{"asset_id":"64053005904884194822931764831592250494815136296598204104072528088122126148949","best_ask":"0.6","best_bid":"0.59","hash":"ba61999903a5b2a82dd765d0c97ca1eb025e3254","price":"0.57","side":"BUY","size":"67.7"},{"asset_id":"58313761654877669244690227616056238030136603415514645252000528337391143520538","best_ask":"0.41","best_bid":"0.4","hash":"308bfb956e7cdb80b2013d9a8a5eb04b7b87ee18","price":"0.43","side":"SELL","size":"67.7"}],"timestamp":"1785207426714"},"payload_hash":"2283efaa3a610ab6263408c3fcfe13f9b3fec3443f8d59dcd412919f08bd2cbd","raw_frame":"{\"market\":\"0x0f70d07969bc69eaa97d0987de651885fdca02263688026aa11e7678af8f87aa\", \"price_changes\":[{\"asset_id\":\"64053005904884194822931764831592250494815136296598204104072528088122126148949\", \"price\":\"0.57\", \"size\":\"67.7\", \"side\":\"BUY\", \"hash\":\"ba61999903a5b2a82dd765d0c97ca1eb025e3254\", \"best_bid\":\"0.59\", \"best_ask\":\"0.6\"}, {\"asset_id\":\"58313761654877669244690227616056238030136603415514645252000528337391143520538\", \"price\":\"0.43\", \"size\":\"67.7\", \"side\":\"SELL\", \"hash\":\"308bfb956e7cdb80b2013d9a8a5eb04b7b87ee18\", \"best_bid\":\"0.4\", \"best_ask\":\"0.41\"}], \"timestamp\":\"1785207426714\", \"event_type\":\"price_change\"}","received_at":"2026-07-28T02:57:06.627102Z","schema_version":"clob-market-ws.price_change.v1","sequence":null,"server_hash":null,"server_timestamp":"1785207426714","session_id":"5aad79be415c487c84df42bebd84ee93","source":"clob_market_ws"},"received_at":"2026-07-28T02:57:06.627102Z","record_id":"281e34b3c7623859ea66b7cd1106fa896622a57b9efb9f7e17d9ce16db507a22","schema_fingerprint":"4aa3821a28b0b7c2400bc59aba4bcc0a76e971dadd19610d3ad38c768e124dc7","schema_version":"edge-lab-recorder.raw.v1","sequence":null,"source":"clob_market_ws"}
{"event_at":"2026-07-28T02:57:06.714000Z","event_fingerprint":"9af7d13447d4489c22f1565c28c632423f0096ebae6f5d3f075944e4f53295c8","payload":{"connection_id":"955646bd8bf740759faf38750c0f263f","event_at":"2026-07-28T02:57:06.714000Z","event_type":"price_change","frame_hash":"5c645ab5e9835a7af3dbf27deb443454e2c2f0b513ab29d74c45abb3b8a369c8","frame_index":0,"kind":"data","monotonic_ns":309409645665083,"payload":{"event_type":"price_change","market":"0x0f70d07969bc69eaa97d0987de651885fdca02263688026aa11e7678af8f87aa","price_changes":[{"asset_id":"64053005904884194822931764831592250494815136296598204104072528088122126148949","best_ask":"0.6","best_bid":"0.59","hash":"0737b033ddb2faf55f25cc8cff0fa45c52e12c7c","price":"0.58","side":"BUY","size":"33.63"},{"asset_id":"58313761654877669244690227616056238030136603415514645252000528337391143520538","best_ask":"0.41","best_bid":"0.4","hash":"9d3a1c184ff3f6ad197e0ff6c46452fde622dc50","price":"0.42","side":"SELL","size":"33.63"}],"timestamp":"1785207426714"},"payload_hash":"a25ca6c12134011c7aca70df4d54eb4b4e6491da3c49b8a9dc6f45388473c0a3","raw_frame":"{\"market\":\"0x0f70d07969bc69eaa97d0987de651885fdca02263688026aa11e7678af8f87aa\", \"price_changes\":[{\"asset_id\":\"64053005904884194822931764831592250494815136296598204104072528088122126148949\", \"price\":\"0.58\", \"size\":\"33.63\", \"side\":\"BUY\", \"hash\":\"0737b033ddb2faf55f25cc8cff0fa45c52e12c7c\", \"best_bid\":\"0.59\", \"best_ask\":\"0.6\"}, {\"asset_id\":\"58313761654877669244690227616056238030136603415514645252000528337391143520538\", \"price\":\"0.42\", \"size\":\"33.63\", \"side\":\"SELL\", \"hash\":\"9d3a1c184ff3f6ad197e0ff6c46452fde622dc50\", \"best_bid\":\"0.4\", \"best_ask\":\"0.41\"}], \"timestamp\":\"1785207426714\", \"event_type\":\"price_change\"}","received_at":"2026-07-28T02:57:06.628554Z","schema_version":"clob-market-ws.price_change.v1","sequence":null,"server_hash":null,"server_timestamp":"1785207426714","session_id":"5aad79be415c487c84df42bebd84ee93","source":"clob_market_ws"},"received_at":"2026-07-28T02:57:06.628554Z","record_id":"25037ee94c5ccd6a7a2284bfb5d6749808e1268376b0535859b6f29fcb0a75b7","schema_fingerprint":"4aa3821a28b0b7c2400bc59aba4bcc0a76e971dadd19610d3ad38c768e124dc7","schema_version":"edge-lab-recorder.raw.v1","sequence":null,"source":"clob_market_ws"}
{"event_at":"2026-07-28T02:57:06.714000Z","event_fingerprint":"6ba51b7880bd320da32fc21d00474647dac45e4180d68784a207493bb8bf4662","payload":{"connection_id":"955646bd8bf740759faf38750c0f263f","event_at":"2026-07-28T02:57:06.714000Z","event_type":"price_change","frame_hash":"f7dcbc6ba4561ba0ec8ee7168543be5b4458fc9e5d604768f8753bbcabfd32ff","frame_index":0,"kind":"data","monotonic_ns":309409647128708,"payload":{"event_type":"price_change","market":"0x0f70d07969bc69eaa97d0987de651885fdca02263688026aa11e7678af8f87aa","price_changes":[{"asset_id":"64053005904884194822931764831592250494815136296598204104072528088122126148949","best_ask":"0.6","best_bid":"0.59","hash":"11f15b73be7f0aad48e853ba9f49ced2e3c26bf9","price":"0.58","side":"BUY","size":"25.23"},{"asset_id":"58313761654877669244690227616056238030136603415514645252000528337391143520538","best_ask":"0.41","best_bid":"0.4","hash":"a602d3e1da35354ae6289f2402f613327775d370","price":"0.42","side":"SELL","size":"25.23"}],"timestamp":"1785207426714"},"payload_hash":"4421294ac27bedcbf4b10129aea0a136aeef5bb59810d2ed7d1480fefe03c989","raw_frame":"{\"market\":\"0x0f70d07969bc69eaa97d0987de651885fdca02263688026aa11e7678af8f87aa\", \"price_changes\":[{\"asset_id\":\"64053005904884194822931764831592250494815136296598204104072528088122126148949\", \"price\":\"0.58\", \"size\":\"25.23\", \"side\":\"BUY\", \"hash\":\"11f15b73be7f0aad48e853ba9f49ced2e3c26bf9\", \"best_bid\":\"0.59\", \"best_ask\":\"0.6\"}, {\"asset_id\":\"58313761654877669244690227616056238030136603415514645252000528337391143520538\", \"price\":\"0.42\", \"size\":\"25.23\", \"side\":\"SELL\", \"hash\":\"a602d3e1da35354ae6289f2402f613327775d370\", \"best_bid\":\"0.4\", \"best_ask\":\"0.41\"}], \"timestamp\":\"1785207426714\", \"event_type\":\"price_change\"}","received_at":"2026-07-28T02:57:06.630017Z","schema_version":"clob-market-ws.price_change.v1","sequence":null,"server_hash":null,"server_timestamp":"1785207426714","session_id":"5aad79be415c487c84df42bebd84ee93","source":"clob_market_ws"},"received_at":"2026-07-28T02:57:06.630017Z","record_id":"80b9aed9da0be6c48606c1fc17929fffc34d23abb562dd633a910fe5bc7e1b21","schema_fingerprint":"4aa3821a28b0b7c2400bc59aba4bcc0a76e971dadd19610d3ad38c768e124dc7","schema_version":"edge-lab-recorder.raw.v1","sequence":null,"source":"clob_market_ws"}
{"event_at":"2026-07-28T02:57:06.714000Z","event_fingerprint":"250d3db416b6d3d69978b1297dad8c2c2865f324bb288fddf01a669cf044c7e6","payload":{"connection_id":"955646bd8bf740759faf38750c0f263f","event_at":"2026-07-28T02:57:06.714000Z","event_type":"price_change","frame_hash":"3a9e3882a293feb5dfb30e998d56510bde6cda98acebf68140d419e174870243","frame_index":0,"kind":"data","monotonic_ns":309409648557458,"payload":{"event_type":"price_change","market":"0x0f70d07969bc69eaa97d0987de651885fdca02263688026aa11e7678af8f87aa","price_changes":[{"asset_id":"64053005904884194822931764831592250494815136296598204104072528088122126148949","best_ask":"0.6","best_bid":"0.59","hash":"a8641ccb9828cb88cb592a422b5d40ad43afce2c","price":"0.58","side":"BUY","size":"14.73"},{"asset_id":"58313761654877669244690227616056238030136603415514645252000528337391143520538","best_ask":"0.41","best_bid":"0.4","hash":"0b7b6f4031af2fa836bfc4eace42ee919bdf8ff1","price":"0.42","side":"SELL","size":"14.73"}],"timestamp":"1785207426714"},"payload_hash":"f474260523180f5ba39020c209d06a6efc27d0d5f514b26f4cd1e35e89bd216d","raw_frame":"{\"market\":\"0x0f70d07969bc69eaa97d0987de651885fdca02263688026aa11e7678af8f87aa\", \"price_changes\":[{\"asset_id\":\"64053005904884194822931764831592250494815136296598204104072528088122126148949\", \"price\":\"0.58\", \"size\":\"14.73\", \"side\":\"BUY\", \"hash\":\"a8641ccb9828cb88cb592a422b5d40ad43afce2c\", \"best_bid\":\"0.59\", \"best_ask\":\"0.6\"}, {\"asset_id\":\"58313761654877669244690227616056238030136603415514645252000528337391143520538\", \"price\":\"0.42\", \"size\":\"14.73\", \"side\":\"SELL\", \"hash\":\"0b7b6f4031af2fa836bfc4eace42ee919bdf8ff1\", \"best_bid\":\"0.4\", \"best_ask\":\"0.41\"}], \"timestamp\":\"1785207426714\", \"event_type\":\"price_change\"}","received_at":"2026-07-28T02:57:06.631446Z","schema_version":"clob-market-ws.price_change.v1","sequence":null,"server_hash":null,"server_timestamp":"1785207426714","session_id":"5aad79be415c487c84df42bebd84ee93","source":"clob_market_ws"},"received_at":"2026-07-28T02:57:06.631446Z","record_id":"a6578c4a77b62387b7db0331166982ba39c5ffbd03ab86926dae9aaebc3f2134","schema_fingerprint":"4aa3821a28b0b7c2400bc59aba4bcc0a76e971dadd19610d3ad38c768e124dc7","schema_version":"edge-lab-recorder.raw.v1","sequence":null,"source":"clob_market_ws"}
{"event_at":"2026-07-28T02:57:06.714000Z","event_fingerprint":"0103410babb133d6e84cd48fc53294756b324e4ea28cfa93fc831df5334d59a5","payload":{"connection_id":"955646bd8bf740759faf38750c0f263f","event_at":"2026-07-28T02:57:06.714000Z","event_type":"price_change","frame_hash":"95a6cc1fff0c8e95280ac8643c7828d855c27aee46b793f92b800f4acb0c7ba6","frame_index":0,"kind":"data","monotonic_ns":309409650066208,"payload":{"event_type":"price_change","market":"0x0f70d07969bc69eaa97d0987de651885fdca02263688026aa11e7678af8f87aa","price_changes":[{"asset_id":"58313761654877669244690227616056238030136603415514645252000528337391143520538","best_ask":"0.41","best_bid":"0.4","hash":"03285e03f81f17c0d1a335f19b8d11c446c89f8e","price":"0.33","side":"BUY","size":"182.2"},{"asset_id":"64053005904884194822931764831592250494815136296598204104072528088122126148949","best_ask":"0.6","best_bid":"0.59","hash":"2a7415ebe92844497543fef3b800501c3f8c68bb","price":"0.67","side":"SELL","size":"182.2"}],"timestamp":"1785207426714"},"payload_hash":"b2f916edce54bd193eb4707c9f613877479fb285cdfc35d22d874b3c00ae6eba","raw_frame":"{\"market\":\"0x0f70d07969bc69eaa97d0987de651885fdca02263688026aa11e7678af8f87aa\", \"price_changes\":[{\"asset_id\":\"58313761654877669244690227616056238030136603415514645252000528337391143520538\", \"price\":\"0.33\", \"size\":\"182.2\", \"side\":\"BUY\", \"hash\":\"03285e03f81f17c0d1a335f19b8d11c446c89f8e\", \"best_bid\":\"0.4\", \"best_ask\":\"0.41\"}, {\"asset_id\":\"64053005904884194822931764831592250494815136296598204104072528088122126148949\", \"price\":\"0.67\", \"size\":\"182.2\", \"side\":\"SELL\", \"hash\":\"2a7415ebe92844497543fef3b800501c3f8c68bb\", \"best_bid\":\"0.59\", \"best_ask\":\"0.6\"}], \"timestamp\":\"1785207426714\", \"event_type\":\"price_change\"}","received_at":"2026-07-28T02:57:06.632952Z","schema_version":"clob-market-ws.price_change.v1","sequence":null,"server_hash":null,"server_timestamp":"1785207426714","session_id":"5aad79be415c487c84df42bebd84ee93","source":"clob_market_ws"},"received_at":"2026-07-28T02:57:06.632952Z","record_id":"4b632d236989936438d33286ebd3ecea8ef45fa124bffcd6763ff94f3d55a7f0","schema_fingerprint":"4aa3821a28b0b7c2400bc59aba4bcc0a76e971dadd19610d3ad38c768e124dc7","schema_version":"edge-lab-recorder.raw.v1","sequence":null,"source":"clob_market_ws"}
{"event_at":"2026-07-28T02:57:06.715000Z","event_fingerprint":"529beb14210483539fd78ae8672596f178adedae0cd8a2953bb4a79366fa19ce","payload":{"connection_id":"955646bd8bf740759faf38750c0f263f","event_at":"2026-07-28T02:57:06.715000Z","event_type":"price_change","frame_hash":"94b12ce1a300b7f4dff9c8d0a9bfac8b5cc1a39cc1d4f306bc616f425e296021","frame_index":0,"kind":"data","monotonic_ns":309409651595750,"payload":{"event_type":"price_change","market":"0x0f70d07969bc69eaa97d0987de651885fdca02263688026aa11e7678af8f87aa","price_changes":[{"asset_id":"64053005904884194822931764831592250494815136296598204104072528088122126148949","best_ask":"0.6","best_bid":"0.59","hash":"e030773c69e77a5421f5063bcb073d92ace92f5d","price":"0.48","side":"BUY","size":"244.71"},{"asset_id":"58313761654877669244690227616056238030136603415514645252000528337391143520538","best_ask":"0.41","best_bid":"0.4","hash":"21549585df567091765646319363b8c7c30ace34","price":"0.52","side":"SELL","size":"244.71"}],"timestamp":"1785207426715"},"payload_hash":"cde7cad507b8d44b2023ef44fcbe1ece4743aaa0bda0ea3ac7773a0752e53291","raw_frame":"{\"market\":\"0x0f70d07969bc69eaa97d0987de651885fdca02263688026aa11e7678af8f87aa\", \"price_changes\":[{\"asset_id\":\"64053005904884194822931764831592250494815136296598204104072528088122126148949\", \"price\":\"0.48\", \"size\":\"244.71\", \"side\":\"BUY\", \"hash\":\"e030773c69e77a5421f5063bcb073d92ace92f5d\", \"best_bid\":\"0.59\", \"best_ask\":\"0.6\"}, {\"asset_id\":\"58313761654877669244690227616056238030136603415514645252000528337391143520538\", \"price\":\"0.52\", \"size\":\"244.71\", \"side\":\"SELL\", \"hash\":\"21549585df567091765646319363b8c7c30ace34\", \"best_bid\":\"0.4\", \"best_ask\":\"0.41\"}], \"timestamp\":\"1785207426715\", \"event_type\":\"price_change\"}","received_at":"2026-07-28T02:57:06.634484Z","schema_version":"clob-market-ws.price_change.v1","sequence":null,"server_hash":null,"server_timestamp":"1785207426715","session_id":"5aad79be415c487c84df42bebd84ee93","source":"clob_market_ws"},"received_at":"2026-07-28T02:57:06.634484Z","record_id":"67d07b87945d8ebff580ba83e6656aeffae031da4ac1ccea8235ce57566672a8","schema_fingerprint":"4aa3821a28b0b7c2400bc59aba4bcc0a76e971dadd19610d3ad38c768e124dc7","schema_version":"edge-lab-recorder.raw.v1","sequence":null,"source":"clob_market_ws"}
{"event_at":"2026-07-28T02:57:06.715000Z","event_fingerprint":"ec14c8678a1363f76bd35f5750223bd001c85cdafaec8b77155961331212e33e","payload":{"connection_id":"955646bd8bf740759faf38750c0f263f","event_at":"2026-07-28T02:57:06.715000Z","event_type":"price_change","frame_hash":"4f4b4fde368f476d987f4b7558cfb8467ac0b253dbd2f47ef31d50c8484d10a5","frame_index":0,"kind":"data","monotonic_ns":309409653121291,"payload":{"event_type":"price_change","market":"0x0f70d07969bc69eaa97d0987de651885fdca02263688026aa11e7678af8f87aa","price_changes":[{"asset_id":"64053005904884194822931764831592250494815136296598204104072528088122126148949","best_ask":"0.6","best_bid":"0.59","hash":"5527abe6d5a6c95062f086c6ffc64847a802068a","price":"0.52","side":"BUY","size":"153.35"},{"asset_id":"58313761654877669244690227616056238030136603415514645252000528337391143520538","best_ask":"0.41","best_bid":"0.4","hash":"19c25b3f9a88af2ebba70dc8754f6b79d679e7e7","price":"0.48","side":"SELL","size":"153.35"}],"timestamp":"1785207426715"},"payload_hash":"3cc3c40d53216a15df15359c0f4b10bcc79ecdffc6e23e9c909151a1ee2b72a4","raw_frame":"{\"market\":\"0x0f70d07969bc69eaa97d0987de651885fdca02263688026aa11e7678af8f87aa\", \"price_changes\":[{\"asset_id\":\"64053005904884194822931764831592250494815136296598204104072528088122126148949\", \"price\":\"0.52\", \"size\":\"153.35\", \"side\":\"BUY\", \"hash\":\"5527abe6d5a6c95062f086c6ffc64847a802068a\", \"best_bid\":\"0.59\", \"best_ask\":\"0.6\"}, {\"asset_id\":\"58313761654877669244690227616056238030136603415514645252000528337391143520538\", \"price\":\"0.48\", \"size\":\"153.35\", \"side\":\"SELL\", \"hash\":\"19c25b3f9a88af2ebba70dc8754f6b79d679e7e7\", \"best_bid\":\"0.4\", \"best_ask\":\"0.41\"}], \"timestamp\":\"1785207426715\", \"event_type\":\"price_change\"}","received_at":"2026-07-28T02:57:06.636010Z","schema_version":"clob-market-ws.price_change.v1","sequence":null,"server_hash":null,"server_timestamp":"1785207426715","session_id":"5aad79be415c487c84df42bebd84ee93","source":"clob_market_ws"},"received_at":"2026-07-28T02:57:06.636010Z","record_id":"40f7e982bdc8d7ea8554b83be438bc06f523e8abb2045b3c43ac902c023dddc2","schema_fingerprint":"4aa3821a28b0b7c2400bc59aba4bcc0a76e971dadd19610d3ad38c768e124dc7","schema_version":"edge-lab-recorder.raw.v1","sequence":null,"source":"clob_market_ws"}
{"event_at":"2026-07-28T02:57:06.716000Z","event_fingerprint":"853c9828b2505d73b0106ac8531a8ab3361f8a584cd2943b8b59664a35536dd0","payload":{"connection_id":"955646bd8bf740759faf38750c0f263f","event_at":"2026-07-28T02:57:06.716000Z","event_type":"price_change","frame_hash":"aae827a93abf49baddc87bd9c664cb2926c1ec0b035aa6055c14c267ecb48c4d","frame_index":0,"kind":"data","monotonic_ns":309409654585916,"payload":{"event_type":"price_change","market":"0x0f70d07969bc69eaa97d0987de651885fdca02263688026aa11e7678af8f87aa","price_changes":[{"asset_id":"64053005904884194822931764831592250494815136296598204104072528088122126148949","best_ask":"0.6","best_bid":"0.59","hash":"8006101938d70b7b7d0892776e4d463148321a95","price":"0.51","side":"BUY","size":"110.3"},{"asset_id":"58313761654877669244690227616056238030136603415514645252000528337391143520538","best_ask":"0.41","best_bid":"0.4","hash":"691b769dbd1484a8587d85ff24e7d93f334609e4","price":"0.49","side":"SELL","size":"110.3"}],"timestamp":"1785207426716"},"payload_hash":"edfc0557e322c9d5588f3e433df5e97954ea0d81944d33f0456c3a20db811dec","raw_frame":"{\"market\":\"0x0f70d07969bc69eaa97d0987de651885fdca02263688026aa11e7678af8f87aa\", \"price_changes\":[{\"asset_id\":\"64053005904884194822931764831592250494815136296598204104072528088122126148949\", \"price\":\"0.51\", \"size\":\"110.3\", \"side\":\"BUY\", \"hash\":\"8006101938d70b7b7d0892776e4d463148321a95\", \"best_bid\":\"0.59\", \"best_ask\":\"0.6\"}, {\"asset_id\":\"58313761654877669244690227616056238030136603415514645252000528337391143520538\", \"price\":\"0.49\", \"size\":\"110.3\", \"side\":\"SELL\", \"hash\":\"691b769dbd1484a8587d85ff24e7d93f334609e4\", \"best_bid\":\"0.4\", \"best_ask\":\"0.41\"}], \"timestamp\":\"1785207426716\", \"event_type\":\"price_change\"}","received_at":"2026-07-28T02:57:06.637474Z","schema_version":"clob-market-ws.price_change.v1","sequence":null,"server_hash":null,"server_timestamp":"1785207426716","session_id":"5aad79be415c487c84df42bebd84ee93","source":"clob_market_ws"},"received_at":"2026-07-28T02:57:06.637474Z","record_id":"2607a5f560ac3cd71562b960a43993d6d83197073ca34fb9ed3ac4d62b00779b","schema_fingerprint":"4aa3821a28b0b7c2400bc59aba4bcc0a76e971dadd19610d3ad38c768e124dc7","schema_version":"edge-lab-recorder.raw.v1","sequence":null,"source":"clob_market_ws"}
{"event_at":"2026-07-28T02:57:06.717000Z","event_fingerprint":"4cb7f0cb285350a817060aa4aac688c471093ae1388d2a83a731e755601247cd","payload":{"connection_id":"955646bd8bf740759faf38750c0f263f","event_at":"2026-07-28T02:57:06.717000Z","event_type":"price_change","frame_hash":"738a7ba8056545d3a400aa374a0c0d2b6b0753b2bd04ab21cd381b8247b4ca11","frame_index":0,"kind":"data","monotonic_ns":309409656095166,"payload":{"event_type":"price_change","market":"0x0f70d07969bc69eaa97d0987de651885fdca02263688026aa11e7678af8f87aa","price_changes":[{"asset_id":"58313761654877669244690227616056238030136603415514645252000528337391143520538","best_ask":"0.41","best_bid":"0.4","hash":"f4191314c0c6a1f19d0dd305b8ebfff73a746bd8","price":"0.39","side":"BUY","size":"74.28"},{"asset_id":"64053005904884194822931764831592250494815136296598204104072528088122126148949","best_ask":"0.6","best_bid":"0.59","hash":"f94117d22f02f0be109ae813ac7d538493efcdb4","price":"0.61","side":"SELL","size":"74.28"}],"timestamp":"1785207426717"},"payload_hash":"38951e83ad3011eafd0865ea74efd6105a4e5435c7234763e6fa14755333b041","raw_frame":"{\"market\":\"0x0f70d07969bc69eaa97d0987de651885fdca02263688026aa11e7678af8f87aa\", \"price_changes\":[{\"asset_id\":\"58313761654877669244690227616056238030136603415514645252000528337391143520538\", \"price\":\"0.39\", \"size\":\"74.28\", \"side\":\"BUY\", \"hash\":\"f4191314c0c6a1f19d0dd305b8ebfff73a746bd8\", \"best_bid\":\"0.4\", \"best_ask\":\"0.41\"}, {\"asset_id\":\"64053005904884194822931764831592250494815136296598204104072528088122126148949\", \"price\":\"0.61\", \"size\":\"74.28\", \"side\":\"SELL\", \"hash\":\"f94117d22f02f0be109ae813ac7d538493efcdb4\", \"best_bid\":\"0.59\", \"best_ask\":\"0.6\"}], \"timestamp\":\"1785207426717\", \"event_type\":\"price_change\"}","received_at":"2026-07-28T02:57:06.638984Z","schema_version":"clob-market-ws.price_change.v1","sequence":null,"server_hash":null,"server_timestamp":"1785207426717","session_id":"5aad79be415c487c84df42bebd84ee93","source":"clob_market_ws"},"received_at":"2026-07-28T02:57:06.638984Z","record_id":"c0b3fe63fb8aac9a314d4a669d398f8593a581bf054b693265ebc8ae6ce7edfb","schema_fingerprint":"4aa3821a28b0b7c2400bc59aba4bcc0a76e971dadd19610d3ad38c768e124dc7","schema_version":"edge-lab-recorder.raw.v1","sequence":null,"source":"clob_market_ws"}
{"event_at":"2026-07-28T02:57:06.718000Z","event_fingerprint":"6da6fc7ea62944a0270ef425f8cd6780b14e85ac487d98da992c03b649eab71f","payload":{"connection_id":"955646bd8bf740759faf38750c0f263f","event_at":"2026-07-28T02:57:06.718000Z","event_type":"price_change","frame_hash":"6578bd2c31848d4220440f5679263ee9f9f771e05a4fe3bbc3e44647738609ee","frame_index":0,"kind":"data","monotonic_ns":309409657550958,"payload":{"event_type":"price_change","market":"0x0f70d07969bc69eaa97d0987de651885fdca02263688026aa11e7678af8f87aa","price_changes":[{"asset_id":"64053005904884194822931764831592250494815136296598204104072528088122126148949","best_ask":"0.6","best_bid":"0.59","hash":"886ef190cb5bfd9307c648ad90d093bac2915133","price":"0.47","side":"BUY","size":"94.78"},{"asset_id":"58313761654877669244690227616056238030136603415514645252000528337391143520538","best_ask":"0.41","best_bid":"0.4","hash":"d2a49cd91be8ea9690dbb8a4e4e147763dc855e6","price":"0.53","side":"SELL","size":"94.78"}],"timestamp":"1785207426718"},"payload_hash":"4b13704750a9dea642389b0f2e2f382bd0f694735f42a9a4390e429d9918238f","raw_frame":"{\"market\":\"0x0f70d07969bc69eaa97d0987de651885fdca02263688026aa11e7678af8f87aa\", \"price_changes\":[{\"asset_id\":\"64053005904884194822931764831592250494815136296598204104072528088122126148949\", \"price\":\"0.47\", \"size\":\"94.78\", \"side\":\"BUY\", \"hash\":\"886ef190cb5bfd9307c648ad90d093bac2915133\", \"best_bid\":\"0.59\", \"best_ask\":\"0.6\"}, {\"asset_id\":\"58313761654877669244690227616056238030136603415514645252000528337391143520538\", \"price\":\"0.53\", \"size\":\"94.78\", \"side\":\"SELL\", \"hash\":\"d2a49cd91be8ea9690dbb8a4e4e147763dc855e6\", \"best_bid\":\"0.4\", \"best_ask\":\"0.41\"}], \"timestamp\":\"1785207426718\", \"event_type\":\"price_change\"}","received_at":"2026-07-28T02:57:06.640439Z","schema_version":"clob-market-ws.price_change.v1","sequence":null,"server_hash":null,"server_timestamp":"1785207426718","session_id":"5aad79be415c487c84df42bebd84ee93","source":"clob_market_ws"},"received_at":"2026-07-28T02:57:06.640439Z","record_id":"bfffff37921a93404cb28f63555361256823ee60b2bc827662ec0c22c5dbbed9","schema_fingerprint":"4aa3821a28b0b7c2400bc59aba4bcc0a76e971dadd19610d3ad38c768e124dc7","schema_version":"edge-lab-recorder.raw.v1","sequence":null,"source":"clob_market_ws"}
{"event_at":"2026-07-28T02:57:06.718000Z","event_fingerprint":"3635f74300178d34636ff58039efbedc022af7352e1e037f66a791e6d50133a4","payload":{"connection_id":"955646bd8bf740759faf38750c0f263f","event_at":"2026-07-28T02:57:06.718000Z","event_type":"price_change","frame_hash":"5bdab8404d2643086ffd4848ada79f7169136246dca7eef33e8588f93f0ea5fb","frame_index":0,"kind":"data","monotonic_ns":309409659022625,"payload":{"event_type":"price_change","market":"0x0f70d07969bc69eaa97d0987de651885fdca02263688026aa11e7678af8f87aa","price_changes":[{"asset_id":"64053005904884194822931764831592250494815136296598204104072528088122126148949","best_ask":"0.6","best_bid":"0.59","hash":"0d7735e1dc4a4c2b2ac8ba92fb2bfc991377e8c4","price":"0.56","side":"BUY","size":"51.3"},{"asset_id":"58313761654877669244690227616056238030136603415514645252000528337391143520538","best_ask":"0.41","best_bid":"0.4","hash":"62fbfae24d4bd5abb0124d32ec159f77c2820704","price":"0.44","side":"SELL","size":"51.3"}],"timestamp":"1785207426718"},"payload_hash":"21059f8960ae769a29933b58cc27a4da99f963d0ac09f788572903a31cb192e6","raw_frame":"{\"market\":\"0x0f70d07969bc69eaa97d0987de651885fdca02263688026aa11e7678af8f87aa\", \"price_changes\":[{\"asset_id\":\"64053005904884194822931764831592250494815136296598204104072528088122126148949\", \"price\":\"0.56\", \"size\":\"51.3\", \"side\":\"BUY\", \"hash\":\"0d7735e1dc4a4c2b2ac8ba92fb2bfc991377e8c4\", \"best_bid\":\"0.59\", \"best_ask\":\"0.6\"}, {\"asset_id\":\"58313761654877669244690227616056238030136603415514645252000528337391143520538\", \"price\":\"0.44\", \"size\":\"51.3\", \"side\":\"SELL\", \"hash\":\"62fbfae24d4bd5abb0124d32ec159f77c2820704\", \"best_bid\":\"0.4\", \"best_ask\":\"0.41\"}], \"timestamp\":\"1785207426718\", \"event_type\":\"price_change\"}","received_at":"2026-07-28T02:57:06.641911Z","schema_version":"clob-market-ws.price_change.v1","sequence":null,"server_hash":null,"server_timestamp":"1785207426718","session_id":"5aad79be415c487c84df42bebd84ee93","source":"clob_market_ws"},"received_at":"2026-07-28T02:57:06.641911Z","record_id":"1c7528a87b488245e2f70a79ffa06fe1af869cad83107eb5aac8bf36e45b838a","schema_fingerprint":"4aa3821a28b0b7c2400bc59aba4bcc0a76e971dadd19610d3ad38c768e124dc7","schema_version":"edge-lab-recorder.raw.v1","sequence":null,"source":"clob_market_ws"}
{"event_at":"2026-07-28T02:57:06.718000Z","event_fingerprint":"cd4a9baab7b551da8f68e44d65bad9ab53fb2cd545ba18f2fef8eaf3d89c4dd4","payload":{"connection_id":"955646bd8bf740759faf38750c0f263f","event_at":"2026-07-28T02:57:06.718000Z","event_type":"price_change","frame_hash":"2de28afb5c8407796231605d7253911ed08a629083c71081729d183583a56b4e","frame_index":0,"kind":"data","monotonic_ns":309409660447916,"payload":{"event_type":"price_change","market":"0x0f70d07969bc69eaa97d0987de651885fdca02263688026aa11e7678af8f87aa","price_changes":[{"asset_id":"64053005904884194822931764831592250494815136296598204104072528088122126148949","best_ask":"0.6","best_bid":"0.59","hash":"d14a0434785bd88d073409ddffae96e50c118332","price":"0.28","side":"BUY","size":"120"},{"asset_id":"58313761654877669244690227616056238030136603415514645252000528337391143520538","best_ask":"0.41","best_bid":"0.4","hash":"16fa8ce72fb65a5871d4a7a60564ea1e2b411e84","price":"0.72","side":"SELL","size":"120"}],"timestamp":"1785207426718"},"payload_hash":"77c11902c14705101f829ea05a0f7ed6163ab52d04158df8b5f1882ad3830568","raw_frame":"{\"market\":\"0x0f70d07969bc69eaa97d0987de651885fdca02263688026aa11e7678af8f87aa\", \"price_changes\":[{\"asset_id\":\"64053005904884194822931764831592250494815136296598204104072528088122126148949\", \"price\":\"0.28\", \"size\":\"120\", \"side\":\"BUY\", \"hash\":\"d14a0434785bd88d073409ddffae96e50c118332\", \"best_bid\":\"0.59\", \"best_ask\":\"0.6\"}, {\"asset_id\":\"58313761654877669244690227616056238030136603415514645252000528337391143520538\", \"price\":\"0.72\", \"size\":\"120\", \"side\":\"SELL\", \"hash\":\"16fa8ce72fb65a5871d4a7a60564ea1e2b411e84\", \"best_bid\":\"0.4\", \"best_ask\":\"0.41\"}], \"timestamp\":\"1785207426718\", \"event_type\":\"price_change\"}","received_at":"2026-07-28T02:57:06.643336Z","schema_version":"clob-market-ws.price_change.v1","sequence":null,"server_hash":null,"server_timestamp":"1785207426718","session_id":"5aad79be415c487c84df42bebd84ee93","source":"clob_market_ws"},"received_at":"2026-07-28T02:57:06.643336Z","record_id":"f7d3928740bb103ca0987bac076dc062a85bd48b710ce90e3737b1dbde9da995","schema_fingerprint":"4aa3821a28b0b7c2400bc59aba4bcc0a76e971dadd19610d3ad38c768e124dc7","schema_version":"edge-lab-recorder.raw.v1","sequence":null,"source":"clob_market_ws"}
{"event_at":"2026-07-28T02:57:06.719000Z","event_fingerprint":"4c4700da4424383f2f1706e84b89d291c6e064bdbc37d2abc9d5139af88e98d6","payload":{"connection_id":"955646bd8bf740759faf38750c0f263f","event_at":"2026-07-28T02:57:06.719000Z","event_type":"price_change","frame_hash":"696a00fd97bcd1840360e834f4ac702013fc44b4e0fbec5ce058960e18fc240d","frame_index":0,"kind":"data","monotonic_ns":309409661905458,"payload":{"event_type":"price_change","market":"0x0f70d07969bc69eaa97d0987de651885fdca02263688026aa11e7678af8f87aa","price_changes":[{"asset_id":"64053005904884194822931764831592250494815136296598204104072528088122126148949","best_ask":"0.6","best_bid":"0.59","hash":"866e66981d7556ffc8822dcb0e9308cb66105194","price":"0.5","side":"BUY","size":"122.04"},{"asset_id":"58313761654877669244690227616056238030136603415514645252000528337391143520538","best_ask":"0.41","best_bid":"0.4","hash":"d11939185e407a8378bcb1d49e98a289307cdbf0","price":"0.5","side":"SELL","size":"122.04"}],"timestamp":"1785207426719"},"payload_hash":"dd4a30296127e04ad9d795abc7122fbb696a0a90603058c0477fc809d8671fde","raw_frame":"{\"market\":\"0x0f70d07969bc69eaa97d0987de651885fdca02263688026aa11e7678af8f87aa\", \"price_changes\":[{\"asset_id\":\"64053005904884194822931764831592250494815136296598204104072528088122126148949\", \"price\":\"0.5\", \"size\":\"122.04\", \"side\":\"BUY\", \"hash\":\"866e66981d7556ffc8822dcb0e9308cb66105194\", \"best_bid\":\"0.59\", \"best_ask\":\"0.6\"}, {\"asset_id\":\"58313761654877669244690227616056238030136603415514645252000528337391143520538\", \"price\":\"0.5\", \"size\":\"122.04\", \"side\":\"SELL\", \"hash\":\"d11939185e407a8378bcb1d49e98a289307cdbf0\", \"best_bid\":\"0.4\", \"best_ask\":\"0.41\"}], \"timestamp\":\"1785207426719\", \"event_type\":\"price_change\"}","received_at":"2026-07-28T02:57:06.644794Z","schema_version":"clob-market-ws.price_change.v1","sequence":null,"server_hash":null,"server_timestamp":"1785207426719","session_id":"5aad79be415c487c84df42bebd84ee93","source":"clob_market_ws"},"received_at":"2026-07-28T02:57:06.644794Z","record_id":"4dddf48b089a06a76d9f66dd76b16a21711070aea069efb459289e244c3cd22c","schema_fingerprint":"4aa3821a28b0b7c2400bc59aba4bcc0a76e971dadd19610d3ad38c768e124dc7","schema_version":"edge-lab-recorder.raw.v1","sequence":null,"source":"clob_market_ws"}
{"event_at":"2026-07-28T02:57:06.719000Z","event_fingerprint":"29e6c1d5e7df73efab3200be515bd4c0e8af6811985841ef8cfce9e13fcb9a33","payload":{"connection_id":"955646bd8bf740759faf38750c0f263f","event_at":"2026-07-28T02:57:06.719000Z","event_type":"price_change","frame_hash":"1c5aa7901cae767b7e91ff903d2976357c28cac4809e1fa4da1264eae91695ee","frame_index":0,"kind":"data","monotonic_ns":309409663347541,"payload":{"event_type":"price_change","market":"0x0f70d07969bc69eaa97d0987de651885fdca02263688026aa11e7678af8f87aa","price_changes":[{"asset_id":"64053005904884194822931764831592250494815136296598204104072528088122126148949","best_ask":"0.6","best_bid":"0.59","hash":"098056d4d1e31cdda89a075782eea8c876f51d37","price":"0.01","side":"BUY","size":"2700.52"},{"asset_id":"58313761654877669244690227616056238030136603415514645252000528337391143520538","best_ask":"0.41","best_bid":"0.4","hash":"68988a298388f1af889e2dea9a45e5a2887b0607","price":"0.99","side":"SELL","size":"2700.52"}],"timestamp":"1785207426719"},"payload_hash":"847f066a7ca1dcaa1292b5d5dabee3a06bd09d19c35f4f40443afb916470e645","raw_frame":"{\"market\":\"0x0f70d07969bc69eaa97d0987de651885fdca02263688026aa11e7678af8f87aa\", \"price_changes\":[{\"asset_id\":\"64053005904884194822931764831592250494815136296598204104072528088122126148949\", \"price\":\"0.01\", \"size\":\"2700.52\", \"side\":\"BUY\", \"hash\":\"098056d4d1e31cdda89a075782eea8c876f51d37\", \"best_bid\":\"0.59\", \"best_ask\":\"0.6\"}, {\"asset_id\":\"58313761654877669244690227616056238030136603415514645252000528337391143520538\", \"price\":\"0.99\", \"size\":\"2700.52\", \"side\":\"SELL\", \"hash\":\"68988a298388f1af889e2dea9a45e5a2887b0607\", \"best_bid\":\"0.4\", \"best_ask\":\"0.41\"}], \"timestamp\":\"1785207426719\", \"event_type\":\"price_change\"}","received_at":"2026-07-28T02:57:06.646236Z","schema_version":"clob-market-ws.price_change.v1","sequence":null,"server_hash":null,"server_timestamp":"1785207426719","session_id":"5aad79be415c487c84df42bebd84ee93","source":"clob_market_ws"},"received_at":"2026-07-28T02:57:06.646236Z","record_id":"e409ce952d083f372848bdf23b12427761cf771ee8b1282ff8e5151de7a1b043","schema_fingerprint":"4aa3821a28b0b7c2400bc59aba4bcc0a76e971dadd19610d3ad38c768e124dc7","schema_version":"edge-lab-recorder.raw.v1","sequence":null,"source":"clob_market_ws"}
{"event_at":"2026-07-28T02:57:06.720000Z","event_fingerprint":"13db89db0992a9ebc756ffdd83e272aed5e4164dfb08780eea142895e074b50d","payload":{"connection_id":"955646bd8bf740759faf38750c0f263f","event_at":"2026-07-28T02:57:06.720000Z","event_type":"price_change","frame_hash":"1e1f46ae682f31d41927ece1293d97edcc4db1269b828b9d6421e5c39aa2dcdc","frame_index":0,"kind":"data","monotonic_ns":309409664808458,"payload":{"event_type":"price_change","market":"0x0f70d07969bc69eaa97d0987de651885fdca02263688026aa11e7678af8f87aa","price_changes":[{"asset_id":"64053005904884194822931764831592250494815136296598204104072528088122126148949","best_ask":"0.6","best_bid":"0.59","hash":"bfb362ad73c9c6bb9316eb0c9c992461b827a74b","price":"0.55","side":"BUY","size":"148.6"},{"asset_id":"58313761654877669244690227616056238030136603415514645252000528337391143520538","best_ask":"0.41","best_bid":"0.4","hash":"d816b5246613c4e4a9d1844f520ee9e485734cbb","price":"0.45","side":"SELL","size":"148.6"}],"timestamp":"1785207426720"},"payload_hash":"7e8ba1c62ec65497ebfb5471d7085865a0ac1b9890de6f294517b9a5f9614a78","raw_frame":"{\"market\":\"0x0f70d07969bc69eaa97d0987de651885fdca02263688026aa11e7678af8f87aa\", \"price_changes\":[{\"asset_id\":\"64053005904884194822931764831592250494815136296598204104072528088122126148949\", \"price\":\"0.55\", \"size\":\"148.6\", \"side\":\"BUY\", \"hash\":\"bfb362ad73c9c6bb9316eb0c9c992461b827a74b\", \"best_bid\":\"0.59\", \"best_ask\":\"0.6\"}, {\"asset_id\":\"58313761654877669244690227616056238030136603415514645252000528337391143520538\", \"price\":\"0.45\", \"size\":\"148.6\", \"side\":\"SELL\", \"hash\":\"d816b5246613c4e4a9d1844f520ee9e485734cbb\", \"best_bid\":\"0.4\", \"best_ask\":\"0.41\"}], \"timestamp\":\"1785207426720\", \"event_type\":\"price_change\"}","received_at":"2026-07-28T02:57:06.647698Z","schema_version":"clob-market-ws.price_change.v1","sequence":null,"server_hash":null,"server_timestamp":"1785207426720","session_id":"5aad79be415c487c84df42bebd84ee93","source":"clob_market_ws"},"received_at":"2026-07-28T02:57:06.647698Z","record_id":"2fa6c50edcfa9c0b909f328b959d2caed78e97b31b73ecff9266c1dcc6f8ab94","schema_fingerprint":"4aa3821a28b0b7c2400bc59aba4bcc0a76e971dadd19610d3ad38c768e124dc7","schema_version":"edge-lab-recorder.raw.v1","sequence":null,"source":"clob_market_ws"}
{"event_at":"2026-07-28T02:57:06.720000Z","event_fingerprint":"2e5c10d3a1cee256b6d2a29616c90447495a664dea492b8663362de737cc3364","payload":{"connection_id":"955646bd8bf740759faf38750c0f263f","event_at":"2026-07-28T02:57:06.720000Z","event_type":"price_change","frame_hash":"03f3b5a01d925c2746bddad9681b9ef12a179f00525ffeb763a575fd48a53e88","frame_index":0,"kind":"data","monotonic_ns":309409666247791,"payload":{"event_type":"price_change","market":"0x0f70d07969bc69eaa97d0987de651885fdca02263688026aa11e7678af8f87aa","price_changes":[{"asset_id":"64053005904884194822931764831592250494815136296598204104072528088122126148949","best_ask":"0.6","best_bid":"0.59","hash":"832677abb88b7235e791dc44764b111a48cc16e3","price":"0.49","side":"BUY","size":"136.31"},{"asset_id":"58313761654877669244690227616056238030136603415514645252000528337391143520538","best_ask":"0.41","best_bid":"0.4","hash":"3757ca8f3473483b596e217c39ed5d1912f2c7e0","price":"0.51","side":"SELL","size":"136.31"}],"timestamp":"1785207426720"},"payload_hash":"ec4297cf5c6ff5f71336c7292505206ee54c1e75ffbcdc8871eb1bd9dd037e47","raw_frame":"{\"market\":\"0x0f70d07969bc69eaa97d0987de651885fdca02263688026aa11e7678af8f87aa\", \"price_changes\":[{\"asset_id\":\"64053005904884194822931764831592250494815136296598204104072528088122126148949\", \"price\":\"0.49\", \"size\":\"136.31\", \"side\":\"BUY\", \"hash\":\"832677abb88b7235e791dc44764b111a48cc16e3\", \"best_bid\":\"0.59\", \"best_ask\":\"0.6\"}, {\"asset_id\":\"58313761654877669244690227616056238030136603415514645252000528337391143520538\", \"price\":\"0.51\", \"size\":\"136.31\", \"side\":\"SELL\", \"hash\":\"3757ca8f3473483b596e217c39ed5d1912f2c7e0\", \"best_bid\":\"0.4\", \"best_ask\":\"0.41\"}], \"timestamp\":\"1785207426720\", \"event_type\":\"price_change\"}","received_at":"2026-07-28T02:57:06.649137Z","schema_version":"clob-market-ws.price_change.v1","sequence":null,"server_hash":null,"server_timestamp":"1785207426720","session_id":"5aad79be415c487c84df42bebd84ee93","source":"clob_market_ws"},"received_at":"2026-07-28T02:57:06.649137Z","record_id":"582d1a9a98be8cf9bf307613f88f63e3429a7db76a7b0fb947c6027a11789262","schema_fingerprint":"4aa3821a28b0b7c2400bc59aba4bcc0a76e971dadd19610d3ad38c768e124dc7","schema_version":"edge-lab-recorder.raw.v1","sequence":null,"source":"clob_market_ws"}
{"event_at":"2026-07-28T02:57:06.721000Z","event_fingerprint":"8a9f6971d32f8e951f62eb640e754834479c8cab88be925c01b8bb1293a14087","payload":{"connection_id":"955646bd8bf740759faf38750c0f263f","event_at":"2026-07-28T02:57:06.721000Z","event_type":"price_change","frame_hash":"2de69321625afc5d06a44484fdc46d0c72a554d694debfc7305edb83321a17e7","frame_index":0,"kind":"data","monotonic_ns":309409667743083,"payload":{"event_type":"price_change","market":"0x0f70d07969bc69eaa97d0987de651885fdca02263688026aa11e7678af8f87aa","price_changes":[{"asset_id":"64053005904884194822931764831592250494815136296598204104072528088122126148949","best_ask":"0.6","best_bid":"0.59","hash":"ce5c5c23b45195cb4de468566582a24d02992115","price":"0.48","side":"BUY","size":"228.71"},{"asset_id":"58313761654877669244690227616056238030136603415514645252000528337391143520538","best_ask":"0.41","best_bid":"0.4","hash":"2caea5d0ad148863b36705bdf5a195df9080e4ce","price":"0.52","side":"SELL","size":"228.71"}],"timestamp":"1785207426721"},"payload_hash":"46841645a52d6490ba3a7ffb4a3c867f2c32de3a0e33636ceb7f4c189bee5c79","raw_frame":"{\"market\":\"0x0f70d07969bc69eaa97d0987de651885fdca02263688026aa11e7678af8f87aa\", \"price_changes\":[{\"asset_id\":\"64053005904884194822931764831592250494815136296598204104072528088122126148949\", \"price\":\"0.48\", \"size\":\"228.71\", \"side\":\"BUY\", \"hash\":\"ce5c5c23b45195cb4de468566582a24d02992115\", \"best_bid\":\"0.59\", \"best_ask\":\"0.6\"}, {\"asset_id\":\"58313761654877669244690227616056238030136603415514645252000528337391143520538\", \"price\":\"0.52\", \"size\":\"228.71\", \"side\":\"SELL\", \"hash\":\"2caea5d0ad148863b36705bdf5a195df9080e4ce\", \"best_bid\":\"0.4\", \"best_ask\":\"0.41\"}], \"timestamp\":\"1785207426721\", \"event_type\":\"price_change\"}","received_at":"2026-07-28T02:57:06.650630Z","schema_version":"clob-market-ws.price_change.v1","sequence":null,"server_hash":null,"server_timestamp":"1785207426721","session_id":"5aad79be415c487c84df42bebd84ee93","source":"clob_market_ws"},"received_at":"2026-07-28T02:57:06.650630Z","record_id":"87246e5166ba14a73d7c68f8ac2cc153e580167241a542c8c3682749aaa5d352","schema_fingerprint":"4aa3821a28b0b7c2400bc59aba4bcc0a76e971dadd19610d3ad38c768e124dc7","schema_version":"edge-lab-recorder.raw.v1","sequence":null,"source":"clob_market_ws"}
{"event_at":"2026-07-28T02:57:06.721000Z","event_fingerprint":"a88ee5d16da14792adfeb59d3535e8cc988a3341fe47e57cd0002b374a5efbf2","payload":{"connection_id":"955646bd8bf740759faf38750c0f263f","event_at":"2026-07-28T02:57:06.721000Z","event_type":"price_change","frame_hash":"03dd39c62ebb4c6d976a5d62a3a96f18038dc3a728f01f1b35b042135de59d91","frame_index":0,"kind":"data","monotonic_ns":309409669237583,"payload":{"event_type":"price_change","market":"0x0f70d07969bc69eaa97d0987de651885fdca02263688026aa11e7678af8f87aa","price_changes":[{"asset_id":"58313761654877669244690227616056238030136603415514645252000528337391143520538","best_ask":"0.41","best_bid":"0.4","hash":"6f2596d488bd780b41ce093ec22753094f6f3224","price":"0.33","side":"BUY","size":"176.5"},{"asset_id":"64053005904884194822931764831592250494815136296598204104072528088122126148949","best_ask":"0.6","best_bid":"0.59","hash":"1669079e4b2c0fb798e13f315b525cf727cf60d9","price":"0.67","side":"SELL","size":"176.5"}],"timestamp":"1785207426721"},"payload_hash":"ea9c9a6f1444fcd39b865236d33986b4541fae9ed62b31f86405a17b872894e8","raw_frame":"{\"market\":\"0x0f70d07969bc69eaa97d0987de651885fdca02263688026aa11e7678af8f87aa\", \"price_changes\":[{\"asset_id\":\"58313761654877669244690227616056238030136603415514645252000528337391143520538\", \"price\":\"0.33\", \"size\":\"176.5\", \"side\":\"BUY\", \"hash\":\"6f2596d488bd780b41ce093ec22753094f6f3224\", \"best_bid\":\"0.4\", \"best_ask\":\"0.41\"}, {\"asset_id\":\"64053005904884194822931764831592250494815136296598204104072528088122126148949\", \"price\":\"0.67\", \"size\":\"176.5\", \"side\":\"SELL\", \"hash\":\"1669079e4b2c0fb798e13f315b525cf727cf60d9\", \"best_bid\":\"0.59\", \"best_ask\":\"0.6\"}], \"timestamp\":\"1785207426721\", \"event_type\":\"price_change\"}","received_at":"2026-07-28T02:57:06.652126Z","schema_version":"clob-market-ws.price_change.v1","sequence":null,"server_hash":null,"server_timestamp":"1785207426721","session_id":"5aad79be415c487c84df42bebd84ee93","source":"clob_market_ws"},"received_at":"2026-07-28T02:57:06.652126Z","record_id":"4cfe246f8a396dd3ea24b7dca431545c3ad2e7911de6825af225c814ddd80362","schema_fingerprint":"4aa3821a28b0b7c2400bc59aba4bcc0a76e971dadd19610d3ad38c768e124dc7","schema_version":"edge-lab-recorder.raw.v1","sequence":null,"source":"clob_market_ws"}
{"event_at":"2026-07-28T02:57:06.721000Z","event_fingerprint":"ec3d28cc340a96bed24f08eab21aa4c906a64fce6a006637f92bea82a42e822c","payload":{"connection_id":"955646bd8bf740759faf38750c0f263f","event_at":"2026-07-28T02:57:06.721000Z","event_type":"price_change","frame_hash":"412d84fae5faa05df068f9d3948d30e56d88a05228532c656f393aa04315372b","frame_index":0,"kind":"data","monotonic_ns":309409670841583,"payload":{"event_type":"price_change","market":"0x0f70d07969bc69eaa97d0987de651885fdca02263688026aa11e7678af8f87aa","price_changes":[{"asset_id":"58313761654877669244690227616056238030136603415514645252000528337391143520538","best_ask":"0.41","best_bid":"0.4","hash":"4fb953e0a6f8146c35c4f4eff79e64000ad3925e","price":"0.34","side":"BUY","size":"191.22"},{"asset_id":"64053005904884194822931764831592250494815136296598204104072528088122126148949","best_ask":"0.6","best_bid":"0.59","hash":"286fadeb86763e735e84d23ee9ddd79fdc4e32b0","price":"0.66","side":"SELL","size":"191.22"}],"timestamp":"1785207426721"},"payload_hash":"6e1069a134983b98cac44feeccbb7d835e48a6c931f0ec94bebc426c35ba4364","raw_frame":"{\"market\":\"0x0f70d07969bc69eaa97d0987de651885fdca02263688026aa11e7678af8f87aa\", \"price_changes\":[{\"asset_id\":\"58313761654877669244690227616056238030136603415514645252000528337391143520538\", \"price\":\"0.34\", \"size\":\"191.22\", \"side\":\"BUY\", \"hash\":\"4fb953e0a6f8146c35c4f4eff79e64000ad3925e\", \"best_bid\":\"0.4\", \"best_ask\":\"0.41\"}, {\"asset_id\":\"64053005904884194822931764831592250494815136296598204104072528088122126148949\", \"price\":\"0.66\", \"size\":\"191.22\", \"side\":\"SELL\", \"hash\":\"286fadeb86763e735e84d23ee9ddd79fdc4e32b0\", \"best_bid\":\"0.59\", \"best_ask\":\"0.6\"}], \"timestamp\":\"1785207426721\", \"event_type\":\"price_change\"}","received_at":"2026-07-28T02:57:06.653730Z","schema_version":"clob-market-ws.price_change.v1","sequence":null,"server_hash":null,"server_timestamp":"1785207426721","session_id":"5aad79be415c487c84df42bebd84ee93","source":"clob_market_ws"},"received_at":"2026-07-28T02:57:06.653730Z","record_id":"57cabf8b21a40ec4095a55085e47c19fc90a64bdc06c7b6b189aada555645cbe","schema_fingerprint":"4aa3821a28b0b7c2400bc59aba4bcc0a76e971dadd19610d3ad38c768e124dc7","schema_version":"edge-lab-recorder.raw.v1","sequence":null,"source":"clob_market_ws"}
{"event_at":"2026-07-28T02:57:06.722000Z","event_fingerprint":"48a72958d0e77b276f6bea2da8da7798d91e1ef762d79d04def9dc2fefbb249f","payload":{"connection_id":"955646bd8bf740759faf38750c0f263f","event_at":"2026-07-28T02:57:06.722000Z","event_type":"price_change","frame_hash":"034a2f4eb3b9726bb3541905b9c4c8893f6b542e1e5e8ff294cd4a373ce70e50","frame_index":0,"kind":"data","monotonic_ns":309409672435750,"payload":{"event_type":"price_change","market":"0x0f70d07969bc69eaa97d0987de651885fdca02263688026aa11e7678af8f87aa","price_changes":[{"asset_id":"58313761654877669244690227616056238030136603415514645252000528337391143520538","best_ask":"0.41","best_bid":"0.4","hash":"106dd9cd989291d3d51a935600af2405d7fab633","price":"0.14","side":"BUY","size":"129.2"},{"asset_id":"64053005904884194822931764831592250494815136296598204104072528088122126148949","best_ask":"0.6","best_bid":"0.59","hash":"cb3e459afe1dc0594ce3e8d35e523aca72fbddb3","price":"0.86","side":"SELL","size":"129.2"}],"timestamp":"1785207426722"},"payload_hash":"0af577d255517fbbc5672da5fdc4e3f5056bf78ec55541459b80acf7ff78f68c","raw_frame":"{\"market\":\"0x0f70d07969bc69eaa97d0987de651885fdca02263688026aa11e7678af8f87aa\", \"price_changes\":[{\"asset_id\":\"58313761654877669244690227616056238030136603415514645252000528337391143520538\", \"price\":\"0.14\", \"size\":\"129.2\", \"side\":\"BUY\", \"hash\":\"106dd9cd989291d3d51a935600af2405d7fab633\", \"best_bid\":\"0.4\", \"best_ask\":\"0.41\"}, {\"asset_id\":\"64053005904884194822931764831592250494815136296598204104072528088122126148949\", \"price\":\"0.86\", \"size\":\"129.2\", \"side\":\"SELL\", \"hash\":\"cb3e459afe1dc0594ce3e8d35e523aca72fbddb3\", \"best_bid\":\"0.59\", \"best_ask\":\"0.6\"}], \"timestamp\":\"1785207426722\", \"event_type\":\"price_change\"}","received_at":"2026-07-28T02:57:06.655324Z","schema_version":"clob-market-ws.price_change.v1","sequence":null,"server_hash":null,"server_timestamp":"1785207426722","session_id":"5aad79be415c487c84df42bebd84ee93","source":"clob_market_ws"},"received_at":"2026-07-28T02:57:06.655324Z","record_id":"f1e6f05d89912e83d7d6c21edfd52e46a347577e89c05b2c8431bfe526b3952f","schema_fingerprint":"4aa3821a28b0b7c2400bc59aba4bcc0a76e971dadd19610d3ad38c768e124dc7","schema_version":"edge-lab-recorder.raw.v1","sequence":null,"source":"clob_market_ws"}
{"event_at":"2026-07-28T02:57:06.722000Z","event_fingerprint":"2dcceb34ba60d159153dce694f25bcc0860daf8c01a14ff9d07282e219c2a862","payload":{"connection_id":"955646bd8bf740759faf38750c0f263f","event_at":"2026-07-28T02:57:06.722000Z","event_type":"price_change","frame_hash":"80e49bb08e924ca83b558ac8bb90cd575ad701c1f8a4cad853d2bae68d05b286","frame_index":0,"kind":"data","monotonic_ns":309409673913666,"payload":{"event_type":"price_change","market":"0x0f70d07969bc69eaa97d0987de651885fdca02263688026aa11e7678af8f87aa","price_changes":[{"asset_id":"58313761654877669244690227616056238030136603415514645252000528337391143520538","best_ask":"0.41","best_bid":"0.4","hash":"88a0c1bf967a6d09f20ea18f6b4e322213e92e4f","price":"0.32","side":"BUY","size":"164.18"},{"asset_id":"64053005904884194822931764831592250494815136296598204104072528088122126148949","best_ask":"0.6","best_bid":"0.59","hash":"61db6ee063eb2c482ac34b2fd4089a76358a5e11","price":"0.68","side":"SELL","size":"164.18"}],"timestamp":"1785207426722"},"payload_hash":"a25f00b6d62ab230cacb12859e08106bc248d38528a300fe09e3baaa435d0ab3","raw_frame":"{\"market\":\"0x0f70d07969bc69eaa97d0987de651885fdca02263688026aa11e7678af8f87aa\", \"price_changes\":[{\"asset_id\":\"58313761654877669244690227616056238030136603415514645252000528337391143520538\", \"price\":\"0.32\", \"size\":\"164.18\", \"side\":\"BUY\", \"hash\":\"88a0c1bf967a6d09f20ea18f6b4e322213e92e4f\", \"best_bid\":\"0.4\", \"best_ask\":\"0.41\"}, {\"asset_id\":\"64053005904884194822931764831592250494815136296598204104072528088122126148949\", \"price\":\"0.68\", \"size\":\"164.18\", \"side\":\"SELL\", \"hash\":\"61db6ee063eb2c482ac34b2fd4089a76358a5e11\", \"best_bid\":\"0.59\", \"best_ask\":\"0.6\"}], \"timestamp\":\"1785207426722\", \"event_type\":\"price_change\"}","received_at":"2026-07-28T02:57:06.656802Z","schema_version":"clob-market-ws.price_change.v1","sequence":null,"server_hash":null,"server_timestamp":"1785207426722","session_id":"5aad79be415c487c84df42bebd84ee93","source":"clob_market_ws"},"received_at":"2026-07-28T02:57:06.656802Z","record_id":"ff8f8825f65594f4c98c7e84af52bcf7e2ebf14b115eea0b25dfe38aafb6f8ef","schema_fingerprint":"4aa3821a28b0b7c2400bc59aba4bcc0a76e971dadd19610d3ad38c768e124dc7","schema_version":"edge-lab-recorder.raw.v1","sequence":null,"source":"clob_market_ws"}
{"event_at":"2026-07-28T02:57:06.722000Z","event_fingerprint":"6010e60ff300c7547e9708a32fb08c47ce9017aa145155a873ebdf26faac08b9","payload":{"connection_id":"955646bd8bf740759faf38750c0f263f","event_at":"2026-07-28T02:57:06.722000Z","event_type":"price_change","frame_hash":"41865557c81b68941ab74a95bc2d80fc520b64397fd4719f4e266cc6e91935eb","frame_index":0,"kind":"data","monotonic_ns":309409675408416,"payload":{"event_type":"price_change","market":"0x0f70d07969bc69eaa97d0987de651885fdca02263688026aa11e7678af8f87aa","price_changes":[{"asset_id":"64053005904884194822931764831592250494815136296598204104072528088122126148949","best_ask":"0.6","best_bid":"0.59","hash":"61db6ee063eb2c482ac34b2fd4089a76358a5e11","price":"0.57","side":"BUY","size":"62.7"},{"asset_id":"58313761654877669244690227616056238030136603415514645252000528337391143520538","best_ask":"0.41","best_bid":"0.4","hash":"88a0c1bf967a6d09f20ea18f6b4e322213e92e4f","price":"0.43","side":"SELL","size":"62.7"}],"timestamp":"1785207426722"},"payload_hash":"0d5c3c0e1e3bb06db45c8cb684f56dd50cfae6cc9aa40ac6f491507667331378","raw_frame":"{\"market\":\"0x0f70d07969bc69eaa97d0987de651885fdca02263688026aa11e7678af8f87aa\", \"price_changes\":[{\"asset_id\":\"64053005904884194822931764831592250494815136296598204104072528088122126148949\", \"price\":\"0.57\", \"size\":\"62.7\", \"side\":\"BUY\", \"hash\":\"61db6ee063eb2c482ac34b2fd4089a76358a5e11\", \"best_bid\":\"0.59\", \"best_ask\":\"0.6\"}, {\"asset_id\":\"58313761654877669244690227616056238030136603415514645252000528337391143520538\", \"price\":\"0.43\", \"size\":\"62.7\", \"side\":\"SELL\", \"hash\":\"88a0c1bf967a6d09f20ea18f6b4e322213e92e4f\", \"best_bid\":\"0.4\", \"best_ask\":\"0.41\"}], \"timestamp\":\"1785207426722\", \"event_type\":\"price_change\"}","received_at":"2026-07-28T02:57:06.658296Z","schema_version":"clob-market-ws.price_change.v1","sequence":null,"server_hash":null,"server_timestamp":"1785207426722","session_id":"5aad79be415c487c84df42bebd84ee93","source":"clob_market_ws"},"received_at":"2026-07-28T02:57:06.658296Z","record_id":"ee9b44f9ad67512b2770caebb18bada0d62c1cef11aff5aa579e96e52c50090b","schema_fingerprint":"4aa3821a28b0b7c2400bc59aba4bcc0a76e971dadd19610d3ad38c768e124dc7","schema_version":"edge-lab-recorder.raw.v1","sequence":null,"source":"clob_market_ws"}
{"event_at":"2026-07-28T02:57:06.722000Z","event_fingerprint":"d45c8776756f872b06964fc7b39029884daf3f8aa32673d639a1ba2c575b88bf","payload":{"connection_id":"955646bd8bf740759faf38750c0f263f","event_at":"2026-07-28T02:57:06.722000Z","event_type":"price_change","frame_hash":"5a94f2e38567e4047db6c9de43ba6ce6145243d4edcb397bfa74d52de07389bd","frame_index":0,"kind":"data","monotonic_ns":309409676906708,"payload":{"event_type":"price_change","market":"0x0f70d07969bc69eaa97d0987de651885fdca02263688026aa11e7678af8f87aa","price_changes":[{"asset_id":"58313761654877669244690227616056238030136603415514645252000528337391143520538","best_ask":"0.41","best_bid":"0.4","hash":"88a0c1bf967a6d09f20ea18f6b4e322213e92e4f","price":"0.3","side":"BUY","size":"185"},{"asset_id":"64053005904884194822931764831592250494815136296598204104072528088122126148949","best_ask":"0.6","best_bid":"0.59","hash":"61db6ee063eb2c482ac34b2fd4089a76358a5e11","price":"0.7","side":"SELL","size":"185"}],"timestamp":"1785207426722"},"payload_hash":"cee8705a47334498c69672da96acdd5ef85501fc65b4005b91b5d9b4fac80eae","raw_frame":"{\"market\":\"0x0f70d07969bc69eaa97d0987de651885fdca02263688026aa11e7678af8f87aa\", \"price_changes\":[{\"asset_id\":\"58313761654877669244690227616056238030136603415514645252000528337391143520538\", \"price\":\"0.3\", \"size\":\"185\", \"side\":\"BUY\", \"hash\":\"88a0c1bf967a6d09f20ea18f6b4e322213e92e4f\", \"best_bid\":\"0.4\", \"best_ask\":\"0.41\"}, {\"asset_id\":\"64053005904884194822931764831592250494815136296598204104072528088122126148949\", \"price\":\"0.7\", \"size\":\"185\", \"side\":\"SELL\", \"hash\":\"61db6ee063eb2c482ac34b2fd4089a76358a5e11\", \"best_bid\":\"0.59\", \"best_ask\":\"0.6\"}], \"timestamp\":\"1785207426722\", \"event_type\":\"price_change\"}","received_at":"2026-07-28T02:57:06.659795Z","schema_version":"clob-market-ws.price_change.v1","sequence":null,"server_hash":null,"server_timestamp":"1785207426722","session_id":"5aad79be415c487c84df42bebd84ee93","source":"clob_market_ws"},"received_at":"2026-07-28T02:57:06.659795Z","record_id":"a8979fff8c92ef88c616a39042e8af2203e2ac94e42cbead14aa0b36667bf0af","schema_fingerprint":"4aa3821a28b0b7c2400bc59aba4bcc0a76e971dadd19610d3ad38c768e124dc7","schema_version":"edge-lab-recorder.raw.v1","sequence":null,"source":"clob_market_ws"}
{"event_at":"2026-07-28T02:57:06.722000Z","event_fingerprint":"e62ff461dc1280bec3dce85d80b8f7d240a126dd242cd654c412a5e806501083","payload":{"connection_id":"955646bd8bf740759faf38750c0f263f","event_at":"2026-07-28T02:57:06.722000Z","event_type":"price_change","frame_hash":"ea5530d05efe8db8e345b73a0fda0758a9db81613f0ab37701da01d4adc0d8cd","frame_index":0,"kind":"data","monotonic_ns":309409678413875,"payload":{"event_type":"price_change","market":"0x0f70d07969bc69eaa97d0987de651885fdca02263688026aa11e7678af8f87aa","price_changes":[{"asset_id":"58313761654877669244690227616056238030136603415514645252000528337391143520538","best_ask":"0.41","best_bid":"0.4","hash":"efa1064e5d78860c5862ca723d44ddca5ba54345","price":"0.36","side":"BUY","size":"181.42"},{"asset_id":"64053005904884194822931764831592250494815136296598204104072528088122126148949","best_ask":"0.6","best_bid":"0.59","hash":"813083b8a01f1e929159b8a9e29c3d081cba003a","price":"0.64","side":"SELL","size":"181.42"}],"timestamp":"1785207426722"},"payload_hash":"84a5d715fa4e629424b6990a94b02f70a74cb0fe689fe3a612dea65c69961336","raw_frame":"{\"market\":\"0x0f70d07969bc69eaa97d0987de651885fdca02263688026aa11e7678af8f87aa\", \"price_changes\":[{\"asset_id\":\"58313761654877669244690227616056238030136603415514645252000528337391143520538\", \"price\":\"0.36\", \"size\":\"181.42\", \"side\":\"BUY\", \"hash\":\"efa1064e5d78860c5862ca723d44ddca5ba54345\", \"best_bid\":\"0.4\", \"best_ask\":\"0.41\"}, {\"asset_id\":\"64053005904884194822931764831592250494815136296598204104072528088122126148949\", \"price\":\"0.64\", \"size\":\"181.42\", \"side\":\"SELL\", \"hash\":\"813083b8a01f1e929159b8a9e29c3d081cba003a\", \"best_bid\":\"0.59\", \"best_ask\":\"0.6\"}], \"timestamp\":\"1785207426722\", \"event_type\":\"price_change\"}","received_at":"2026-07-28T02:57:06.661301Z","schema_version":"clob-market-ws.price_change.v1","sequence":null,"server_hash":null,"server_timestamp":"1785207426722","session_id":"5aad79be415c487c84df42bebd84ee93","source":"clob_market_ws"},"received_at":"2026-07-28T02:57:06.661301Z","record_id":"532e5acae778c7e47e5392ee5cb5b9e560c60953eaa5ff584a5922e6a449cd27","schema_fingerprint":"4aa3821a28b0b7c2400bc59aba4bcc0a76e971dadd19610d3ad38c768e124dc7","schema_version":"edge-lab-recorder.raw.v1","sequence":null,"source":"clob_market_ws"}
{"event_at":"2026-07-28T02:57:06.722000Z","event_fingerprint":"c650bb17384e7434654952fe0f1a5663ec36d4c73932002cdfe130d3beb8a1f6","payload":{"connection_id":"955646bd8bf740759faf38750c0f263f","event_at":"2026-07-28T02:57:06.722000Z","event_type":"price_change","frame_hash":"cae8fb35d58b05f8794a9c38db1963359313561ce24d02044118953be0771d30","frame_index":0,"kind":"data","monotonic_ns":309409679994916,"payload":{"event_type":"price_change","market":"0x0f70d07969bc69eaa97d0987de651885fdca02263688026aa11e7678af8f87aa","price_changes":[{"asset_id":"58313761654877669244690227616056238030136603415514645252000528337391143520538","best_ask":"0.41","best_bid":"0.4","hash":"efa1064e5d78860c5862ca723d44ddca5ba54345","price":"0.44","side":"SELL","size":"41.3"},{"asset_id":"64053005904884194822931764831592250494815136296598204104072528088122126148949","best_ask":"0.6","best_bid":"0.59","hash":"813083b8a01f1e929159b8a9e29c3d081cba003a","price":"0.56","side":"BUY","size":"41.3"}],"timestamp":"1785207426722"},"payload_hash":"6978c3d4a96b325243ce902db88a9c31d630232be9dfcbce55436b096757f8e3","raw_frame":"{\"market\":\"0x0f70d07969bc69eaa97d0987de651885fdca02263688026aa11e7678af8f87aa\", \"price_changes\":[{\"asset_id\":\"58313761654877669244690227616056238030136603415514645252000528337391143520538\", \"price\":\"0.44\", \"size\":\"41.3\", \"side\":\"SELL\", \"hash\":\"efa1064e5d78860c5862ca723d44ddca5ba54345\", \"best_bid\":\"0.4\", \"best_ask\":\"0.41\"}, {\"asset_id\":\"64053005904884194822931764831592250494815136296598204104072528088122126148949\", \"price\":\"0.56\", \"size\":\"41.3\", \"side\":\"BUY\", \"hash\":\"813083b8a01f1e929159b8a9e29c3d081cba003a\", \"best_bid\":\"0.59\", \"best_ask\":\"0.6\"}], \"timestamp\":\"1785207426722\", \"event_type\":\"price_change\"}","received_at":"2026-07-28T02:57:06.662876Z","schema_version":"clob-market-ws.price_change.v1","sequence":null,"server_hash":null,"server_timestamp":"1785207426722","session_id":"5aad79be415c487c84df42bebd84ee93","source":"clob_market_ws"},"received_at":"2026-07-28T02:57:06.662876Z","record_id":"b388279f628907f5009bf0bfc136d3d083f8d6f64dc3c240296be64069fc12cd","schema_fingerprint":"4aa3821a28b0b7c2400bc59aba4bcc0a76e971dadd19610d3ad38c768e124dc7","schema_version":"edge-lab-recorder.raw.v1","sequence":null,"source":"clob_market_ws"}
{"event_at":"2026-07-28T02:57:06.722000Z","event_fingerprint":"2d143262fed6921c93424a65c45be60ee88abb9ef42e4f805722e2c385f6aac2","payload":{"connection_id":"955646bd8bf740759faf38750c0f263f","event_at":"2026-07-28T02:57:06.722000Z","event_type":"price_change","frame_hash":"4b0aa576fe90aed7b6244d33f9a5492183295bc3f48190d9c4ec9e0c10046e0e","frame_index":0,"kind":"data","monotonic_ns":309409682937916,"payload":{"event_type":"price_change","market":"0x0f70d07969bc69eaa97d0987de651885fdca02263688026aa11e7678af8f87aa","price_changes":[{"asset_id":"58313761654877669244690227616056238030136603415514645252000528337391143520538","best_ask":"0.41","best_bid":"0.4","hash":"efa1064e5d78860c5862ca723d44ddca5ba54345","price":"0.46","side":"SELL","size":"202.6"},{"asset_id":"64053005904884194822931764831592250494815136296598204104072528088122126148949","best_ask":"0.6","best_bid":"0.59","hash":"813083b8a01f1e929159b8a9e29c3d081cba003a","price":"0.54","side":"BUY","size":"202.6"}],"timestamp":"1785207426722"},"payload_hash":"49f39089654eccb63802151a528cd5c84f075d5e9d1d65eabf4f418ebabfbac0","raw_frame":"{\"market\":\"0x0f70d07969bc69eaa97d0987de651885fdca02263688026aa11e7678af8f87aa\", \"price_changes\":[{\"asset_id\":\"58313761654877669244690227616056238030136603415514645252000528337391143520538\", \"price\":\"0.46\", \"size\":\"202.6\", \"side\":\"SELL\", \"hash\":\"efa1064e5d78860c5862ca723d44ddca5ba54345\", \"best_bid\":\"0.4\", \"best_ask\":\"0.41\"}, {\"asset_id\":\"64053005904884194822931764831592250494815136296598204104072528088122126148949\", \"price\":\"0.54\", \"size\":\"202.6\", \"side\":\"BUY\", \"hash\":\"813083b8a01f1e929159b8a9e29c3d081cba003a\", \"best_bid\":\"0.59\", \"best_ask\":\"0.6\"}], \"timestamp\":\"1785207426722\", \"event_type\":\"price_change\"}","received_at":"2026-07-28T02:57:06.665825Z","schema_version":"clob-market-ws.price_change.v1","sequence":null,"server_hash":null,"server_timestamp":"1785207426722","session_id":"5aad79be415c487c84df42bebd84ee93","source":"clob_market_ws"},"received_at":"2026-07-28T02:57:06.665825Z","record_id":"1ff51163cc1db277644b46f98fdc08fae1d6941a8775334328a7e45973a2cacc","schema_fingerprint":"4aa3821a28b0b7c2400bc59aba4bcc0a76e971dadd19610d3ad38c768e124dc7","schema_version":"edge-lab-recorder.raw.v1","sequence":null,"source":"clob_market_ws"}
{"event_at":"2026-07-28T02:57:06.722000Z","event_fingerprint":"8b7396e21db1e540d86ca4bee0b49b7f2f959547a717767cbeb07cf6a6758466","payload":{"connection_id":"955646bd8bf740759faf38750c0f263f","event_at":"2026-07-28T02:57:06.722000Z","event_type":"price_change","frame_hash":"9df5ec87e8a4fe82cc1ed1b81d922d1223ee1114108bbd10169ac77f12d2c7f8","frame_index":0,"kind":"data","monotonic_ns":309409685535083,"payload":{"event_type":"price_change","market":"0x0f70d07969bc69eaa97d0987de651885fdca02263688026aa11e7678af8f87aa","price_changes":[{"asset_id":"64053005904884194822931764831592250494815136296598204104072528088122126148949","best_ask":"0.6","best_bid":"0.59","hash":"813083b8a01f1e929159b8a9e29c3d081cba003a","price":"0.56","side":"BUY","size":"41.3"},{"asset_id":"58313761654877669244690227616056238030136603415514645252000528337391143520538","best_ask":"0.41","best_bid":"0.4","hash":"efa1064e5d78860c5862ca723d44ddca5ba54345","price":"0.44","side":"SELL","size":"41.3"}],"timestamp":"1785207426722"},"payload_hash":"5ad6ecbee0d464e467143327e08b74708832d0c38734e2df5bad88d60b818cf8","raw_frame":"{\"market\":\"0x0f70d07969bc69eaa97d0987de651885fdca02263688026aa11e7678af8f87aa\", \"price_changes\":[{\"asset_id\":\"64053005904884194822931764831592250494815136296598204104072528088122126148949\", \"price\":\"0.56\", \"size\":\"41.3\", \"side\":\"BUY\", \"hash\":\"813083b8a01f1e929159b8a9e29c3d081cba003a\", \"best_bid\":\"0.59\", \"best_ask\":\"0.6\"}, {\"asset_id\":\"58313761654877669244690227616056238030136603415514645252000528337391143520538\", \"price\":\"0.44\", \"size\":\"41.3\", \"side\":\"SELL\", \"hash\":\"efa1064e5d78860c5862ca723d44ddca5ba54345\", \"best_bid\":\"0.4\", \"best_ask\":\"0.41\"}], \"timestamp\":\"1785207426722\", \"event_type\":\"price_change\"}","received_at":"2026-07-28T02:57:06.668422Z","schema_version":"clob-market-ws.price_change.v1","sequence":null,"server_hash":null,"server_timestamp":"1785207426722","session_id":"5aad79be415c487c84df42bebd84ee93","source":"clob_market_ws"},"received_at":"2026-07-28T02:57:06.668422Z","record_id":"dcbcd25fccd8401667e540d686d2ec383c722c2eef820bc56bc804a7a4cde000","schema_fingerprint":"4aa3821a28b0b7c2400bc59aba4bcc0a76e971dadd19610d3ad38c768e124dc7","schema_version":"edge-lab-recorder.raw.v1","sequence":null,"source":"clob_market_ws"}
{"event_at":"2026-07-28T02:57:06.722000Z","event_fingerprint":"33aef2ea2bca09c4f5c54dbde01c98da9b9575a30a89432c1dc7c79fb94da654","payload":{"connection_id":"955646bd8bf740759faf38750c0f263f","event_at":"2026-07-28T02:57:06.722000Z","event_type":"price_change","frame_hash":"4bbc8b712e679cec213dc2d6897d51682dba8b118115ee819bde1b43fe4ae78c","frame_index":0,"kind":"data","monotonic_ns":309409687236250,"payload":{"event_type":"price_change","market":"0x0f70d07969bc69eaa97d0987de651885fdca02263688026aa11e7678af8f87aa","price_changes":[{"asset_id":"64053005904884194822931764831592250494815136296598204104072528088122126148949","best_ask":"0.6","best_bid":"0.59","hash":"813083b8a01f1e929159b8a9e29c3d081cba003a","price":"0.64","side":"SELL","size":"181.42"},{"asset_id":"58313761654877669244690227616056238030136603415514645252000528337391143520538","best_ask":"0.41","best_bid":"0.4","hash":"efa1064e5d78860c5862ca723d44ddca5ba54345","price":"0.36","side":"BUY","size":"181.42"}],"timestamp":"1785207426722"},"payload_hash":"48048b50ae15330f5e8c8606776e2e2dd98703700da5e64a231deeac53a0a0e9","raw_frame":"{\"market\":\"0x0f70d07969bc69eaa97d0987de651885fdca02263688026aa11e7678af8f87aa\", \"price_changes\":[{\"asset_id\":\"64053005904884194822931764831592250494815136296598204104072528088122126148949\", \"price\":\"0.64\", \"size\":\"181.42\", \"side\":\"SELL\", \"hash\":\"813083b8a01f1e929159b8a9e29c3d081cba003a\", \"best_bid\":\"0.59\", \"best_ask\":\"0.6\"}, {\"asset_id\":\"58313761654877669244690227616056238030136603415514645252000528337391143520538\", \"price\":\"0.36\", \"size\":\"181.42\", \"side\":\"BUY\", \"hash\":\"efa1064e5d78860c5862ca723d44ddca5ba54345\", \"best_bid\":\"0.4\", \"best_ask\":\"0.41\"}], \"timestamp\":\"1785207426722\", \"event_type\":\"price_change\"}","received_at":"2026-07-28T02:57:06.670124Z","schema_version":"clob-market-ws.price_change.v1","sequence":null,"server_hash":null,"server_timestamp":"1785207426722","session_id":"5aad79be415c487c84df42bebd84ee93","source":"clob_market_ws"},"received_at":"2026-07-28T02:57:06.670124Z","record_id":"91920bf050d3b7ade39693ee402e85184fd0e45f5efeb56ec2de9625cf515907","schema_fingerprint":"4aa3821a28b0b7c2400bc59aba4bcc0a76e971dadd19610d3ad38c768e124dc7","schema_version":"edge-lab-recorder.raw.v1","sequence":null,"source":"clob_market_ws"}
{"event_at":"2026-07-28T02:57:06.723000Z","event_fingerprint":"1627e0a221d8d05431e3f9ee10e5eee754705610dfa18c5faac1e5fc912d972b","payload":{"connection_id":"955646bd8bf740759faf38750c0f263f","event_at":"2026-07-28T02:57:06.723000Z","event_type":"price_change","frame_hash":"613d9f5e009544e46d4b639f2d2fa54ca43330958037ebdf21a4f2cccf14636b","frame_index":0,"kind":"data","monotonic_ns":309409688762750,"payload":{"event_type":"price_change","market":"0x0f70d07969bc69eaa97d0987de651885fdca02263688026aa11e7678af8f87aa","price_changes":[{"asset_id":"58313761654877669244690227616056238030136603415514645252000528337391143520538","best_ask":"0.41","best_bid":"0.4","hash":"7801a55ffc430a324cea0da3d7540b570d4f438f","price":"0.48","side":"SELL","size":"158.35"},{"asset_id":"64053005904884194822931764831592250494815136296598204104072528088122126148949","best_ask":"0.6","best_bid":"0.59","hash":"ad02c8cf117de50143940d9440478a779afd3e48","price":"0.52","side":"BUY","size":"158.35"}],"timestamp":"1785207426723"},"payload_hash":"29e52243a82ce5e64c40e9f8c858ab454b93cbe6f1f90fe01422619423752586","raw_frame":"{\"market\":\"0x0f70d07969bc69eaa97d0987de651885fdca02263688026aa11e7678af8f87aa\", \"price_changes\":[{\"asset_id\":\"58313761654877669244690227616056238030136603415514645252000528337391143520538\", \"price\":\"0.48\", \"size\":\"158.35\", \"side\":\"SELL\", \"hash\":\"7801a55ffc430a324cea0da3d7540b570d4f438f\", \"best_bid\":\"0.4\", \"best_ask\":\"0.41\"}, {\"asset_id\":\"64053005904884194822931764831592250494815136296598204104072528088122126148949\", \"price\":\"0.52\", \"size\":\"158.35\", \"side\":\"BUY\", \"hash\":\"ad02c8cf117de50143940d9440478a779afd3e48\", \"best_bid\":\"0.59\", \"best_ask\":\"0.6\"}], \"timestamp\":\"1785207426723\", \"event_type\":\"price_change\"}","received_at":"2026-07-28T02:57:06.671649Z","schema_version":"clob-market-ws.price_change.v1","sequence":null,"server_hash":null,"server_timestamp":"1785207426723","session_id":"5aad79be415c487c84df42bebd84ee93","source":"clob_market_ws"},"received_at":"2026-07-28T02:57:06.671649Z","record_id":"21932bc7c9b5097fa8618d6f11ead512c1906ca238eafaffe118bc5a94211351","schema_fingerprint":"4aa3821a28b0b7c2400bc59aba4bcc0a76e971dadd19610d3ad38c768e124dc7","schema_version":"edge-lab-recorder.raw.v1","sequence":null,"source":"clob_market_ws"}
{"event_at":"2026-07-28T02:57:06.723000Z","event_fingerprint":"ea98625871bfa1416b217b4acb7848fbcb2950a2fec5cd74473eadba4b7cca72","payload":{"connection_id":"955646bd8bf740759faf38750c0f263f","event_at":"2026-07-28T02:57:06.723000Z","event_type":"price_change","frame_hash":"f65edd07133d51981c0d2918621dfc7e57421371e7a8dfae7ebf56d056b948fa","frame_index":0,"kind":"data","monotonic_ns":309409690280791,"payload":{"event_type":"price_change","market":"0x0f70d07969bc69eaa97d0987de651885fdca02263688026aa11e7678af8f87aa","price_changes":[{"asset_id":"58313761654877669244690227616056238030136603415514645252000528337391143520538","best_ask":"0.41","best_bid":"0.4","hash":"a34c38d7df3e0dcaebced4f0be60c1b7c2bba5e8","price":"0.4","side":"BUY","size":"140.26"},{"asset_id":"64053005904884194822931764831592250494815136296598204104072528088122126148949","best_ask":"0.6","best_bid":"0.59","hash":"855ec379e76d5a4da2284a6caabf9599dac57483","price":"0.6","side":"SELL","size":"140.26"}],"timestamp":"1785207426723"},"payload_hash":"afc674df62ce01d69a2e32b7336100d1aab66bd499cbf9407e1bb6ae26b3ab80","raw_frame":"{\"market\":\"0x0f70d07969bc69eaa97d0987de651885fdca02263688026aa11e7678af8f87aa\", \"price_changes\":[{\"asset_id\":\"58313761654877669244690227616056238030136603415514645252000528337391143520538\", \"price\":\"0.4\", \"size\":\"140.26\", \"side\":\"BUY\", \"hash\":\"a34c38d7df3e0dcaebced4f0be60c1b7c2bba5e8\", \"best_bid\":\"0.4\", \"best_ask\":\"0.41\"}, {\"asset_id\":\"64053005904884194822931764831592250494815136296598204104072528088122126148949\", \"price\":\"0.6\", \"size\":\"140.26\", \"side\":\"SELL\", \"hash\":\"855ec379e76d5a4da2284a6caabf9599dac57483\", \"best_bid\":\"0.59\", \"best_ask\":\"0.6\"}], \"timestamp\":\"1785207426723\", \"event_type\":\"price_change\"}","received_at":"2026-07-28T02:57:06.673168Z","schema_version":"clob-market-ws.price_change.v1","sequence":null,"server_hash":null,"server_timestamp":"1785207426723","session_id":"5aad79be415c487c84df42bebd84ee93","source":"clob_market_ws"},"received_at":"2026-07-28T02:57:06.673168Z","record_id":"d8d8b2f3c68ebcaeb6230044a3c85c93a462871a285836b06efe6d2a1cb07884","schema_fingerprint":"4aa3821a28b0b7c2400bc59aba4bcc0a76e971dadd19610d3ad38c768e124dc7","schema_version":"edge-lab-recorder.raw.v1","sequence":null,"source":"clob_market_ws"}
{"event_at":"2026-07-28T02:57:06.724000Z","event_fingerprint":"f1d91c7bba550a1d147d5cffe1e7a06dbe0c9319465b1d16a3159e2050ea9fc8","payload":{"connection_id":"955646bd8bf740759faf38750c0f263f","event_at":"2026-07-28T02:57:06.724000Z","event_type":"price_change","frame_hash":"082f11e0f99fe2d592c33684fdc8fd663046c5f05c0c91ae8558da4cbab67d58","frame_index":0,"kind":"data","monotonic_ns":309409691809333,"payload":{"event_type":"price_change","market":"0x0f70d07969bc69eaa97d0987de651885fdca02263688026aa11e7678af8f87aa","price_changes":[{"asset_id":"64053005904884194822931764831592250494815136296598204104072528088122126148949","best_ask":"0.6","best_bid":"0.59","hash":"b8d6b6b5b2c3a99efe9a6007a6c35e6b2dc98195","price":"0.62","side":"SELL","size":"91.8"},{"asset_id":"58313761654877669244690227616056238030136603415514645252000528337391143520538","best_ask":"0.41","best_bid":"0.4","hash":"3a6510dabf64eb80daf4e781c974f0af07ff5980","price":"0.38","side":"BUY","size":"91.8"}],"timestamp":"1785207426724"},"payload_hash":"ab38e64900ab085659406e491ec4af55fad6fdf382b15957c9d5fb1d1b9e910f","raw_frame":"{\"market\":\"0x0f70d07969bc69eaa97d0987de651885fdca02263688026aa11e7678af8f87aa\", \"price_changes\":[{\"asset_id\":\"64053005904884194822931764831592250494815136296598204104072528088122126148949\", \"price\":\"0.62\", \"size\":\"91.8\", \"side\":\"SELL\", \"hash\":\"b8d6b6b5b2c3a99efe9a6007a6c35e6b2dc98195\", \"best_bid\":\"0.59\", \"best_ask\":\"0.6\"}, {\"asset_id\":\"58313761654877669244690227616056238030136603415514645252000528337391143520538\", \"price\":\"0.38\", \"size\":\"91.8\", \"side\":\"BUY\", \"hash\":\"3a6510dabf64eb80daf4e781c974f0af07ff5980\", \"best_bid\":\"0.4\", \"best_ask\":\"0.41\"}], \"timestamp\":\"1785207426724\", \"event_type\":\"price_change\"}","received_at":"2026-07-28T02:57:06.674697Z","schema_version":"clob-market-ws.price_change.v1","sequence":null,"server_hash":null,"server_timestamp":"1785207426724","session_id":"5aad79be415c487c84df42bebd84ee93","source":"clob_market_ws"},"received_at":"2026-07-28T02:57:06.674697Z","record_id":"597b2b38feade3fbc9ca7d77a9427603ff3904297904a6aadb72d149a1bb0150","schema_fingerprint":"4aa3821a28b0b7c2400bc59aba4bcc0a76e971dadd19610d3ad38c768e124dc7","schema_version":"edge-lab-recorder.raw.v1","sequence":null,"source":"clob_market_ws"}
{"event_at":"2026-07-28T02:57:06.725000Z","event_fingerprint":"63703014dbda2fb25c972e5b8e40114b71100b2297087b2ce8a54bbee8e5c28d","payload":{"connection_id":"955646bd8bf740759faf38750c0f263f","event_at":"2026-07-28T02:57:06.725000Z","event_type":"price_change","frame_hash":"0192db03ce6f0b3056bc5b2a3af009e57bb99915bf7795116be3ce7cfb79b434","frame_index":0,"kind":"data","monotonic_ns":309409693282541,"payload":{"event_type":"price_change","market":"0x0f70d07969bc69eaa97d0987de651885fdca02263688026aa11e7678af8f87aa","price_changes":[{"asset_id":"58313761654877669244690227616056238030136603415514645252000528337391143520538","best_ask":"0.41","best_bid":"0.4","hash":"c66c04880762ebfd7d115b25cb71d26d7690cf83","price":"0.38","side":"BUY","size":"96.8"},{"asset_id":"64053005904884194822931764831592250494815136296598204104072528088122126148949","best_ask":"0.6","best_bid":"0.59","hash":"c3d2ecd9245ad982ce3150936aeba56a47e39fbf","price":"0.62","side":"SELL","size":"96.8"}],"timestamp":"1785207426725"},"payload_hash":"b2fec22419307d80fe0e90c5bcd521886295fd41c3e406ac9ea597679592ccf5","raw_frame":"{\"market\":\"0x0f70d07969bc69eaa97d0987de651885fdca02263688026aa11e7678af8f87aa\", \"price_changes\":[{\"asset_id\":\"58313761654877669244690227616056238030136603415514645252000528337391143520538\", \"price\":\"0.38\", \"size\":\"96.8\", \"side\":\"BUY\", \"hash\":\"c66c04880762ebfd7d115b25cb71d26d7690cf83\", \"best_bid\":\"0.4\", \"best_ask\":\"0.41\"}, {\"asset_id\":\"64053005904884194822931764831592250494815136296598204104072528088122126148949\", \"price\":\"0.62\", \"size\":\"96.8\", \"side\":\"SELL\", \"hash\":\"c3d2ecd9245ad982ce3150936aeba56a47e39fbf\", \"best_bid\":\"0.59\", \"best_ask\":\"0.6\"}], \"timestamp\":\"1785207426725\", \"event_type\":\"price_change\"}","received_at":"2026-07-28T02:57:06.676170Z","schema_version":"clob-market-ws.price_change.v1","sequence":null,"server_hash":null,"server_timestamp":"1785207426725","session_id":"5aad79be415c487c84df42bebd84ee93","source":"clob_market_ws"},"received_at":"2026-07-28T02:57:06.676170Z","record_id":"dc556bc7bac357585c8b1972b6abbfc3fd266bb8a367b351a2f8022c94396ff3","schema_fingerprint":"4aa3821a28b0b7c2400bc59aba4bcc0a76e971dadd19610d3ad38c768e124dc7","schema_version":"edge-lab-recorder.raw.v1","sequence":null,"source":"clob_market_ws"}
{"event_at":"2026-07-28T02:57:06.726000Z","event_fingerprint":"841bde3b9843e7e7ccd0b5dd8efa6ee914bcbd8e427a22c28ddb7ea81157d430","payload":{"connection_id":"955646bd8bf740759faf38750c0f263f","event_at":"2026-07-28T02:57:06.726000Z","event_type":"price_change","frame_hash":"b49a5a93544b251cb8d126191ca32f9415137ea09de56db64a1f08fa2bf91975","frame_index":0,"kind":"data","monotonic_ns":309409694831083,"payload":{"event_type":"price_change","market":"0x0f70d07969bc69eaa97d0987de651885fdca02263688026aa11e7678af8f87aa","price_changes":[{"asset_id":"64053005904884194822931764831592250494815136296598204104072528088122126148949","best_ask":"0.6","best_bid":"0.59","hash":"cae4ba6581d519e40602d39f3bb2020e8f1e6a44","price":"0.57","side":"BUY","size":"57.7"},{"asset_id":"58313761654877669244690227616056238030136603415514645252000528337391143520538","best_ask":"0.41","best_bid":"0.4","hash":"bbd820157c506dbdecea66a22d4230fbc9a97fce","price":"0.43","side":"SELL","size":"57.7"}],"timestamp":"1785207426726"},"payload_hash":"655b5963b8a16b8b66cb892032b396828b5e0bf66d3aafe1ed6f42f8e8d38022","raw_frame":"{\"market\":\"0x0f70d07969bc69eaa97d0987de651885fdca02263688026aa11e7678af8f87aa\", \"price_changes\":[{\"asset_id\":\"64053005904884194822931764831592250494815136296598204104072528088122126148949\", \"price\":\"0.57\", \"size\":\"57.7\", \"side\":\"BUY\", \"hash\":\"cae4ba6581d519e40602d39f3bb2020e8f1e6a44\", \"best_bid\":\"0.59\", \"best_ask\":\"0.6\"}, {\"asset_id\":\"58313761654877669244690227616056238030136603415514645252000528337391143520538\", \"price\":\"0.43\", \"size\":\"57.7\", \"side\":\"SELL\", \"hash\":\"bbd820157c506dbdecea66a22d4230fbc9a97fce\", \"best_bid\":\"0.4\", \"best_ask\":\"0.41\"}], \"timestamp\":\"1785207426726\", \"event_type\":\"price_change\"}","received_at":"2026-07-28T02:57:06.677719Z","schema_version":"clob-market-ws.price_change.v1","sequence":null,"server_hash":null,"server_timestamp":"1785207426726","session_id":"5aad79be415c487c84df42bebd84ee93","source":"clob_market_ws"},"received_at":"2026-07-28T02:57:06.677719Z","record_id":"1d7ed25e11398afa2bcfd518b4cc114a38214f405cde8dab4194e05454a9432d","schema_fingerprint":"4aa3821a28b0b7c2400bc59aba4bcc0a76e971dadd19610d3ad38c768e124dc7","schema_version":"edge-lab-recorder.raw.v1","sequence":null,"source":"clob_market_ws"}
{"event_at":"2026-07-28T02:57:06.726000Z","event_fingerprint":"a7ecb11bb57ca44b3793a312ae27ec6d62d13469fb3e9507023346953efd2c55","payload":{"connection_id":"955646bd8bf740759faf38750c0f263f","event_at":"2026-07-28T02:57:06.726000Z","event_type":"price_change","frame_hash":"f4d84e8748fe85963c37da546f09e4a2c40ed2ab1272a82ea94d5432a6e08f99","frame_index":0,"kind":"data","monotonic_ns":309409696349666,"payload":{"event_type":"price_change","market":"0x0f70d07969bc69eaa97d0987de651885fdca02263688026aa11e7678af8f87aa","price_changes":[{"asset_id":"64053005904884194822931764831592250494815136296598204104072528088122126148949","best_ask":"0.6","best_bid":"0.59","hash":"cae4ba6581d519e40602d39f3bb2020e8f1e6a44","price":"0.59","side":"BUY","size":"10"},{"asset_id":"58313761654877669244690227616056238030136603415514645252000528337391143520538","best_ask":"0.41","best_bid":"0.4","hash":"bbd820157c506dbdecea66a22d4230fbc9a97fce","price":"0.41","side":"SELL","size":"10"}],"timestamp":"1785207426726"},"payload_hash":"2ec1f558c61b487a569d1c65f998a00bc6228e5182fb079677c564fc3e24280b","raw_frame":"{\"market\":\"0x0f70d07969bc69eaa97d0987de651885fdca02263688026aa11e7678af8f87aa\", \"price_changes\":[{\"asset_id\":\"64053005904884194822931764831592250494815136296598204104072528088122126148949\", \"price\":\"0.59\", \"size\":\"10\", \"side\":\"BUY\", \"hash\":\"cae4ba6581d519e40602d39f3bb2020e8f1e6a44\", \"best_bid\":\"0.59\", \"best_ask\":\"0.6\"}, {\"asset_id\":\"58313761654877669244690227616056238030136603415514645252000528337391143520538\", \"price\":\"0.41\", \"size\":\"10\", \"side\":\"SELL\", \"hash\":\"bbd820157c506dbdecea66a22d4230fbc9a97fce\", \"best_bid\":\"0.4\", \"best_ask\":\"0.41\"}], \"timestamp\":\"1785207426726\", \"event_type\":\"price_change\"}","received_at":"2026-07-28T02:57:06.679238Z","schema_version":"clob-market-ws.price_change.v1","sequence":null,"server_hash":null,"server_timestamp":"1785207426726","session_id":"5aad79be415c487c84df42bebd84ee93","source":"clob_market_ws"},"received_at":"2026-07-28T02:57:06.679238Z","record_id":"68d790febc9b36bda0470ba7eb711f430e22edd6090c31c7b1c0bacb14b1aafd","schema_fingerprint":"4aa3821a28b0b7c2400bc59aba4bcc0a76e971dadd19610d3ad38c768e124dc7","schema_version":"edge-lab-recorder.raw.v1","sequence":null,"source":"clob_market_ws"}
{"event_at":"2026-07-28T02:57:06.726000Z","event_fingerprint":"37544bdaf7def3c5390937da6e140d8855a8711c93c7dd9c1b4717d978148d6d","payload":{"connection_id":"955646bd8bf740759faf38750c0f263f","event_at":"2026-07-28T02:57:06.726000Z","event_type":"price_change","frame_hash":"f0e8d0c9d55af89f37ab1cbe1ffee1d98d1055d3576b933c1aab024b8e1ab1eb","frame_index":0,"kind":"data","monotonic_ns":309409697839208,"payload":{"event_type":"price_change","market":"0x0f70d07969bc69eaa97d0987de651885fdca02263688026aa11e7678af8f87aa","price_changes":[{"asset_id":"58313761654877669244690227616056238030136603415514645252000528337391143520538","best_ask":"0.41","best_bid":"0.4","hash":"faff13cabcbce82f0c52b184dd50b439e4271c97","price":"0.37","side":"BUY","size":"94.37"},{"asset_id":"64053005904884194822931764831592250494815136296598204104072528088122126148949","best_ask":"0.6","best_bid":"0.59","hash":"d3b178e03accc845ed7407d2825cad38287c4aa9","price":"0.63","side":"SELL","size":"94.37"}],"timestamp":"1785207426726"},"payload_hash":"2b481203c240b3400082a07533572c4e24cdb3b16e3452db64bc9157cd1c12a4","raw_frame":"{\"market\":\"0x0f70d07969bc69eaa97d0987de651885fdca02263688026aa11e7678af8f87aa\", \"price_changes\":[{\"asset_id\":\"58313761654877669244690227616056238030136603415514645252000528337391143520538\", \"price\":\"0.37\", \"size\":\"94.37\", \"side\":\"BUY\", \"hash\":\"faff13cabcbce82f0c52b184dd50b439e4271c97\", \"best_bid\":\"0.4\", \"best_ask\":\"0.41\"}, {\"asset_id\":\"64053005904884194822931764831592250494815136296598204104072528088122126148949\", \"price\":\"0.63\", \"size\":\"94.37\", \"side\":\"SELL\", \"hash\":\"d3b178e03accc845ed7407d2825cad38287c4aa9\", \"best_bid\":\"0.59\", \"best_ask\":\"0.6\"}], \"timestamp\":\"1785207426726\", \"event_type\":\"price_change\"}","received_at":"2026-07-28T02:57:06.680727Z","schema_version":"clob-market-ws.price_change.v1","sequence":null,"server_hash":null,"server_timestamp":"1785207426726","session_id":"5aad79be415c487c84df42bebd84ee93","source":"clob_market_ws"},"received_at":"2026-07-28T02:57:06.680727Z","record_id":"01c4c95ced7e8469ab989b915fda82c10657e4353917f8124436b80c2e47e3bc","schema_fingerprint":"4aa3821a28b0b7c2400bc59aba4bcc0a76e971dadd19610d3ad38c768e124dc7","schema_version":"edge-lab-recorder.raw.v1","sequence":null,"source":"clob_market_ws"}
{"event_at":"2026-07-28T02:57:06.726000Z","event_fingerprint":"b82a88b32521c853a9df56c3ee7238bb9d712b68b8d55d3cd82490d0d197bff9","payload":{"connection_id":"955646bd8bf740759faf38750c0f263f","event_at":"2026-07-28T02:57:06.726000Z","event_type":"price_change","frame_hash":"00a2e0985cb65d288680b14d1fcf5a321ece6bdfa75f02d660be3e4a28575bc4","frame_index":0,"kind":"data","monotonic_ns":309409699362625,"payload":{"event_type":"price_change","market":"0x0f70d07969bc69eaa97d0987de651885fdca02263688026aa11e7678af8f87aa","price_changes":[{"asset_id":"64053005904884194822931764831592250494815136296598204104072528088122126148949","best_ask":"0.6","best_bid":"0.59","hash":"d3b178e03accc845ed7407d2825cad38287c4aa9","price":"0.55","side":"BUY","size":"143.6"},{"asset_id":"58313761654877669244690227616056238030136603415514645252000528337391143520538","best_ask":"0.41","best_bid":"0.4","hash":"faff13cabcbce82f0c52b184dd50b439e4271c97","price":"0.45","side":"SELL","size":"143.6"}],"timestamp":"1785207426726"},"payload_hash":"bd4b23efa3822475d5040864d87b746fc2ee975895fc7b6e5ac537553fa88cf5","raw_frame":"{\"market\":\"0x0f70d07969bc69eaa97d0987de651885fdca02263688026aa11e7678af8f87aa\", \"price_changes\":[{\"asset_id\":\"64053005904884194822931764831592250494815136296598204104072528088122126148949\", \"price\":\"0.55\", \"size\":\"143.6\", \"side\":\"BUY\", \"hash\":\"d3b178e03accc845ed7407d2825cad38287c4aa9\", \"best_bid\":\"0.59\", \"best_ask\":\"0.6\"}, {\"asset_id\":\"58313761654877669244690227616056238030136603415514645252000528337391143520538\", \"price\":\"0.45\", \"size\":\"143.6\", \"side\":\"SELL\", \"hash\":\"faff13cabcbce82f0c52b184dd50b439e4271c97\", \"best_bid\":\"0.4\", \"best_ask\":\"0.41\"}], \"timestamp\":\"1785207426726\", \"event_type\":\"price_change\"}","received_at":"2026-07-28T02:57:06.682251Z","schema_version":"clob-market-ws.price_change.v1","sequence":null,"server_hash":null,"server_timestamp":"1785207426726","session_id":"5aad79be415c487c84df42bebd84ee93","source":"clob_market_ws"},"received_at":"2026-07-28T02:57:06.682251Z","record_id":"f8b21814e8a486cd764eb5fa3c1eb377d5c673575f223f73cfa34877b6140e09","schema_fingerprint":"4aa3821a28b0b7c2400bc59aba4bcc0a76e971dadd19610d3ad38c768e124dc7","schema_version":"edge-lab-recorder.raw.v1","sequence":null,"source":"clob_market_ws"}
{"event_at":"2026-07-28T02:57:06.726000Z","event_fingerprint":"d1d5d85ffdecf9dfd3b5b526883e04e521f28abf70a1906f53a1e0428b535ff7","payload":{"connection_id":"955646bd8bf740759faf38750c0f263f","event_at":"2026-07-28T02:57:06.726000Z","event_type":"price_change","frame_hash":"91db5dc8ad3c08b10974c136cbf5d652783db574e623988ebc95c45724bf26f3","frame_index":0,"kind":"data","monotonic_ns":309409700819916,"payload":{"event_type":"price_change","market":"0x0f70d07969bc69eaa97d0987de651885fdca02263688026aa11e7678af8f87aa","price_changes":[{"asset_id":"64053005904884194822931764831592250494815136296598204104072528088122126148949","best_ask":"0.6","best_bid":"0.59","hash":"d3b178e03accc845ed7407d2825cad38287c4aa9","price":"0.63","side":"SELL","size":"94.37"},{"asset_id":"58313761654877669244690227616056238030136603415514645252000528337391143520538","best_ask":"0.41","best_bid":"0.4","hash":"faff13cabcbce82f0c52b184dd50b439e4271c97","price":"0.37","side":"BUY","size":"94.37"}],"timestamp":"1785207426726"},"payload_hash":"12d82758dbe4df2772571de69c00c3674ead285afaff09bae2d2e19ae34f7078","raw_frame":"{\"market\":\"0x0f70d07969bc69eaa97d0987de651885fdca02263688026aa11e7678af8f87aa\", \"price_changes\":[{\"asset_id\":\"64053005904884194822931764831592250494815136296598204104072528088122126148949\", \"price\":\"0.63\", \"size\":\"94.37\", \"side\":\"SELL\", \"hash\":\"d3b178e03accc845ed7407d2825cad38287c4aa9\", \"best_bid\":\"0.59\", \"best_ask\":\"0.6\"}, {\"asset_id\":\"58313761654877669244690227616056238030136603415514645252000528337391143520538\", \"price\":\"0.37\", \"size\":\"94.37\", \"side\":\"BUY\", \"hash\":\"faff13cabcbce82f0c52b184dd50b439e4271c97\", \"best_bid\":\"0.4\", \"best_ask\":\"0.41\"}], \"timestamp\":\"1785207426726\", \"event_type\":\"price_change\"}","received_at":"2026-07-28T02:57:06.683708Z","schema_version":"clob-market-ws.price_change.v1","sequence":null,"server_hash":null,"server_timestamp":"1785207426726","session_id":"5aad79be415c487c84df42bebd84ee93","source":"clob_market_ws"},"received_at":"2026-07-28T02:57:06.683708Z","record_id":"4003279ddb1608e5b206647221cf2143eb5786bf8aa1adba807dcf97a16e1d29","schema_fingerprint":"4aa3821a28b0b7c2400bc59aba4bcc0a76e971dadd19610d3ad38c768e124dc7","schema_version":"edge-lab-recorder.raw.v1","sequence":null,"source":"clob_market_ws"}
{"event_at":"2026-07-28T02:57:06.726000Z","event_fingerprint":"f198e41adf567b6a256c6af12c520c7b526b83ef9babd5496b7f0bc5f1e278a2","payload":{"connection_id":"955646bd8bf740759faf38750c0f263f","event_at":"2026-07-28T02:57:06.726000Z","event_type":"price_change","frame_hash":"074fc86d4b08e28fd81efeaf32419be54c1e5dbec5ef97bcee157a6b0306d6b0","frame_index":0,"kind":"data","monotonic_ns":309409702311416,"payload":{"event_type":"price_change","market":"0x0f70d07969bc69eaa97d0987de651885fdca02263688026aa11e7678af8f87aa","price_changes":[{"asset_id":"64053005904884194822931764831592250494815136296598204104072528088122126148949","best_ask":"0.6","best_bid":"0.59","hash":"b5c736d4367219173e044ef7a9248dd850786ce7","price":"0.53","side":"BUY","size":"256.64"},{"asset_id":"58313761654877669244690227616056238030136603415514645252000528337391143520538","best_ask":"0.41","best_bid":"0.4","hash":"b5b3ec1a8cb8c71b3291178571a759e531725bc4","price":"0.47","side":"SELL","size":"256.64"}],"timestamp":"1785207426726"},"payload_hash":"3a5bcb065fdae374a556f9f489d0de08d78374e387c4b35992b230c94d5db39f","raw_frame":"{\"market\":\"0x0f70d07969bc69eaa97d0987de651885fdca02263688026aa11e7678af8f87aa\", \"price_changes\":[{\"asset_id\":\"64053005904884194822931764831592250494815136296598204104072528088122126148949\", \"price\":\"0.53\", \"size\":\"256.64\", \"side\":\"BUY\", \"hash\":\"b5c736d4367219173e044ef7a9248dd850786ce7\", \"best_bid\":\"0.59\", \"best_ask\":\"0.6\"}, {\"asset_id\":\"58313761654877669244690227616056238030136603415514645252000528337391143520538\", \"price\":\"0.47\", \"size\":\"256.64\", \"side\":\"SELL\", \"hash\":\"b5b3ec1a8cb8c71b3291178571a759e531725bc4\", \"best_bid\":\"0.4\", \"best_ask\":\"0.41\"}], \"timestamp\":\"1785207426726\", \"event_type\":\"price_change\"}","received_at":"2026-07-28T02:57:06.685200Z","schema_version":"clob-market-ws.price_change.v1","sequence":null,"server_hash":null,"server_timestamp":"1785207426726","session_id":"5aad79be415c487c84df42bebd84ee93","source":"clob_market_ws"},"received_at":"2026-07-28T02:57:06.685200Z","record_id":"f46fdca70d312e77102efd287292b8997b38857cc584c6eecdc36cc1023ed388","schema_fingerprint":"4aa3821a28b0b7c2400bc59aba4bcc0a76e971dadd19610d3ad38c768e124dc7","schema_version":"edge-lab-recorder.raw.v1","sequence":null,"source":"clob_market_ws"}
{"event_at":"2026-07-28T02:57:06.726000Z","event_fingerprint":"affacc37e04e3b10fdedc7314012759d402371f004956717c8bedfd148c1b8d8","payload":{"connection_id":"955646bd8bf740759faf38750c0f263f","event_at":"2026-07-28T02:57:06.726000Z","event_type":"price_change","frame_hash":"82e2f7287a305aa2213e6e578644625c9f3d2d0b6e91592ae62bbbf7a5f883cd","frame_index":0,"kind":"data","monotonic_ns":309409703750833,"payload":{"event_type":"price_change","market":"0x0f70d07969bc69eaa97d0987de651885fdca02263688026aa11e7678af8f87aa","price_changes":[{"asset_id":"64053005904884194822931764831592250494815136296598204104072528088122126148949","best_ask":"0.6","best_bid":"0.59","hash":"7798f5cf0854761959a05cda73c1908428116c39","price":"0.57","side":"BUY","size":"51.4"},{"asset_id":"58313761654877669244690227616056238030136603415514645252000528337391143520538","best_ask":"0.41","best_bid":"0.4","hash":"18ea9f6dc81c0d6e3a352fd1ab21f940cf7cda9e","price":"0.43","side":"SELL","size":"51.4"}],"timestamp":"1785207426726"},"payload_hash":"06e7e6f103354f8bec70be0bc2f9a266a82ebaa85991df5c748a7b2346ff5ece","raw_frame":"{\"market\":\"0x0f70d07969bc69eaa97d0987de651885fdca02263688026aa11e7678af8f87aa\", \"price_changes\":[{\"asset_id\":\"64053005904884194822931764831592250494815136296598204104072528088122126148949\", \"price\":\"0.57\", \"size\":\"51.4\", \"side\":\"BUY\", \"hash\":\"7798f5cf0854761959a05cda73c1908428116c39\", \"best_bid\":\"0.59\", \"best_ask\":\"0.6\"}, {\"asset_id\":\"58313761654877669244690227616056238030136603415514645252000528337391143520538\", \"price\":\"0.43\", \"size\":\"51.4\", \"side\":\"SELL\", \"hash\":\"18ea9f6dc81c0d6e3a352fd1ab21f940cf7cda9e\", \"best_bid\":\"0.4\", \"best_ask\":\"0.41\"}], \"timestamp\":\"1785207426726\", \"event_type\":\"price_change\"}","received_at":"2026-07-28T02:57:06.686639Z","schema_version":"clob-market-ws.price_change.v1","sequence":null,"server_hash":null,"server_timestamp":"1785207426726","session_id":"5aad79be415c487c84df42bebd84ee93","source":"clob_market_ws"},"received_at":"2026-07-28T02:57:06.686639Z","record_id":"3c217f5d3a499010ab44000a3e64c9cad971d37a22e21f6b9ee9e879c5991576","schema_fingerprint":"4aa3821a28b0b7c2400bc59aba4bcc0a76e971dadd19610d3ad38c768e124dc7","schema_version":"edge-lab-recorder.raw.v1","sequence":null,"source":"clob_market_ws"}
{"event_at":"2026-07-28T02:57:06.726000Z","event_fingerprint":"15b476b507c62f77c85c0f7722ec14e114f6548b6604a5c7a15d79aba899226e","payload":{"connection_id":"955646bd8bf740759faf38750c0f263f","event_at":"2026-07-28T02:57:06.726000Z","event_type":"price_change","frame_hash":"0ce85e9acdc7a171bd04d31a07afb6a18e7c2a8d0cafaff15f16a915d3cfe935","frame_index":0,"kind":"data","monotonic_ns":309409705234791,"payload":{"event_type":"price_change","market":"0x0f70d07969bc69eaa97d0987de651885fdca02263688026aa11e7678af8f87aa","price_changes":[{"asset_id":"64053005904884194822931764831592250494815136296598204104072528088122126148949","best_ask":"0.6","best_bid":"0.59","hash":"138706ec36a7c2717a846ad30e88b4dcafd4593b","price":"0.47","side":"BUY","size":"84.84"},{"asset_id":"58313761654877669244690227616056238030136603415514645252000528337391143520538","best_ask":"0.41","best_bid":"0.4","hash":"9f6d24112054263aa2e789470dab86e1f1bc59dd","price":"0.53","side":"SELL","size":"84.84"}],"timestamp":"1785207426726"},"payload_hash":"6d4581a1d31c286993b2c688e1d12136be94d3f83f492a36e85b6abea3529fc1","raw_frame":"{\"market\":\"0x0f70d07969bc69eaa97d0987de651885fdca02263688026aa11e7678af8f87aa\", \"price_changes\":[{\"asset_id\":\"64053005904884194822931764831592250494815136296598204104072528088122126148949\", \"price\":\"0.47\", \"size\":\"84.84\", \"side\":\"BUY\", \"hash\":\"138706ec36a7c2717a846ad30e88b4dcafd4593b\", \"best_bid\":\"0.59\", \"best_ask\":\"0.6\"}, {\"asset_id\":\"58313761654877669244690227616056238030136603415514645252000528337391143520538\", \"price\":\"0.53\", \"size\":\"84.84\", \"side\":\"SELL\", \"hash\":\"9f6d24112054263aa2e789470dab86e1f1bc59dd\", \"best_bid\":\"0.4\", \"best_ask\":\"0.41\"}], \"timestamp\":\"1785207426726\", \"event_type\":\"price_change\"}","received_at":"2026-07-28T02:57:06.688123Z","schema_version":"clob-market-ws.price_change.v1","sequence":null,"server_hash":null,"server_timestamp":"1785207426726","session_id":"5aad79be415c487c84df42bebd84ee93","source":"clob_market_ws"},"received_at":"2026-07-28T02:57:06.688123Z","record_id":"6583706bf31dff8e0eadb06469f526ab18176607d8e303ef086c4267ffd6832f","schema_fingerprint":"4aa3821a28b0b7c2400bc59aba4bcc0a76e971dadd19610d3ad38c768e124dc7","schema_version":"edge-lab-recorder.raw.v1","sequence":null,"source":"clob_market_ws"}
{"event_at":"2026-07-28T02:57:06.727000Z","event_fingerprint":"b3ac8f6aa3dbad2288c69c1528006be4b7d6d5394051695e4708c61f4a3aa0a6","payload":{"connection_id":"955646bd8bf740759faf38750c0f263f","event_at":"2026-07-28T02:57:06.727000Z","event_type":"price_change","frame_hash":"ac400b7076a2d3abfce7743a924dfa898e2f44cde39541d00443044472c8aae6","frame_index":0,"kind":"data","monotonic_ns":309409706711250,"payload":{"event_type":"price_change","market":"0x0f70d07969bc69eaa97d0987de651885fdca02263688026aa11e7678af8f87aa","price_changes":[{"asset_id":"64053005904884194822931764831592250494815136296598204104072528088122126148949","best_ask":"0.6","best_bid":"0.59","hash":"bc1e1770845bdadbcc615d36074e001e59d56e47","price":"0.55","side":"BUY","size":"128.6"},{"asset_id":"58313761654877669244690227616056238030136603415514645252000528337391143520538","best_ask":"0.41","best_bid":"0.4","hash":"c7401f3b83fdc5f96a0d6ff627c67a108a567881","price":"0.45","side":"SELL","size":"128.6"}],"timestamp":"1785207426727"},"payload_hash":"7c064bfb325728dfe808aff75432425d5281c4ba3f03951bc726d92c8f4929e8","raw_frame":"{\"market\":\"0x0f70d07969bc69eaa97d0987de651885fdca02263688026aa11e7678af8f87aa\", \"price_changes\":[{\"asset_id\":\"64053005904884194822931764831592250494815136296598204104072528088122126148949\", \"price\":\"0.55\", \"size\":\"128.6\", \"side\":\"BUY\", \"hash\":\"bc1e1770845bdadbcc615d36074e001e59d56e47\", \"best_bid\":\"0.59\", \"best_ask\":\"0.6\"}, {\"asset_id\":\"58313761654877669244690227616056238030136603415514645252000528337391143520538\", \"price\":\"0.45\", \"size\":\"128.6\", \"side\":\"SELL\", \"hash\":\"c7401f3b83fdc5f96a0d6ff627c67a108a567881\", \"best_bid\":\"0.4\", \"best_ask\":\"0.41\"}], \"timestamp\":\"1785207426727\", \"event_type\":\"price_change\"}","received_at":"2026-07-28T02:57:06.689600Z","schema_version":"clob-market-ws.price_change.v1","sequence":null,"server_hash":null,"server_timestamp":"1785207426727","session_id":"5aad79be415c487c84df42bebd84ee93","source":"clob_market_ws"},"received_at":"2026-07-28T02:57:06.689600Z","record_id":"04d157a3b121eadbab2672aa400b41eae48b3d8dcab20b6620bea6ea7c693fb1","schema_fingerprint":"4aa3821a28b0b7c2400bc59aba4bcc0a76e971dadd19610d3ad38c768e124dc7","schema_version":"edge-lab-recorder.raw.v1","sequence":null,"source":"clob_market_ws"}
{"event_at":"2026-07-28T02:57:06.727000Z","event_fingerprint":"d10e9da41d1a96d19dcd13cc97ddabc664ed57ef0bf1aca73dd747b1b332c6be","payload":{"connection_id":"955646bd8bf740759faf38750c0f263f","event_at":"2026-07-28T02:57:06.727000Z","event_type":"price_change","frame_hash":"4b6272b064f4fb75a92d5f41d7bac32339eb61a87df161d02f156f293b17e5b7","frame_index":0,"kind":"data","monotonic_ns":309409708185250,"payload":{"event_type":"price_change","market":"0x0f70d07969bc69eaa97d0987de651885fdca02263688026aa11e7678af8f87aa","price_changes":[{"asset_id":"64053005904884194822931764831592250494815136296598204104072528088122126148949","best_ask":"0.6","best_bid":"0.59","hash":"8347d3e41f726971a971ea665c63949b5b2c457c","price":"0.53","side":"BUY","size":"261.64"},{"asset_id":"58313761654877669244690227616056238030136603415514645252000528337391143520538","best_ask":"0.41","best_bid":"0.4","hash":"e1fe7290cb6516170c9d45afa216695c9cc0a16d","price":"0.47","side":"SELL","size":"261.64"}],"timestamp":"1785207426727"},"payload_hash":"4ec002f34b76fae6ddd9aa888042af1fd43d145e277062df4e7936102df1dc66","raw_frame":"{\"market\":\"0x0f70d07969bc69eaa97d0987de651885fdca02263688026aa11e7678af8f87aa\", \"price_changes\":[{\"asset_id\":\"64053005904884194822931764831592250494815136296598204104072528088122126148949\", \"price\":\"0.53\", \"size\":\"261.64\", \"side\":\"BUY\", \"hash\":\"8347d3e41f726971a971ea665c63949b5b2c457c\", \"best_bid\":\"0.59\", \"best_ask\":\"0.6\"}, {\"asset_id\":\"58313761654877669244690227616056238030136603415514645252000528337391143520538\", \"price\":\"0.47\", \"size\":\"261.64\", \"side\":\"SELL\", \"hash\":\"e1fe7290cb6516170c9d45afa216695c9cc0a16d\", \"best_bid\":\"0.4\", \"best_ask\":\"0.41\"}], \"timestamp\":\"1785207426727\", \"event_type\":\"price_change\"}","received_at":"2026-07-28T02:57:06.691074Z","schema_version":"clob-market-ws.price_change.v1","sequence":null,"server_hash":null,"server_timestamp":"1785207426727","session_id":"5aad79be415c487c84df42bebd84ee93","source":"clob_market_ws"},"received_at":"2026-07-28T02:57:06.691074Z","record_id":"a71cbd8809e64a42a1e17a553b1749e10633c71a06a4b22f2b9a578d4abc5227","schema_fingerprint":"4aa3821a28b0b7c2400bc59aba4bcc0a76e971dadd19610d3ad38c768e124dc7","schema_version":"edge-lab-recorder.raw.v1","sequence":null,"source":"clob_market_ws"}
{"event_at":"2026-07-28T02:57:06.728000Z","event_fingerprint":"b924f4069e9b2d666722386962fa690c87cb9ed7b284b93172a2f2717a096a50","payload":{"connection_id":"955646bd8bf740759faf38750c0f263f","event_at":"2026-07-28T02:57:06.728000Z","event_type":"price_change","frame_hash":"17569d459996f7fde13f0e4fcf225db25fbd6daa102b4a669d746c5e1312c7bc","frame_index":0,"kind":"data","monotonic_ns":309409709646875,"payload":{"event_type":"price_change","market":"0x0f70d07969bc69eaa97d0987de651885fdca02263688026aa11e7678af8f87aa","price_changes":[{"asset_id":"64053005904884194822931764831592250494815136296598204104072528088122126148949","best_ask":"0.6","best_bid":"0.59","hash":"3f9263815faf4c26295c8754e871e79403ed24c9","price":"0.48","side":"BUY","size":"213.71"},{"asset_id":"58313761654877669244690227616056238030136603415514645252000528337391143520538","best_ask":"0.41","best_bid":"0.4","hash":"7b755319aed0becc44b987a00f1afc3d1a8d8e28","price":"0.52","side":"SELL","size":"213.71"}],"timestamp":"1785207426728"},"payload_hash":"e279b7eb81a9b6dde11af880b788d141109517728897684f7c4515d7587f2a78","raw_frame":"{\"market\":\"0x0f70d07969bc69eaa97d0987de651885fdca02263688026aa11e7678af8f87aa\", \"price_changes\":[{\"asset_id\":\"64053005904884194822931764831592250494815136296598204104072528088122126148949\", \"price\":\"0.48\", \"size\":\"213.71\", \"side\":\"BUY\", \"hash\":\"3f9263815faf4c26295c8754e871e79403ed24c9\", \"best_bid\":\"0.59\", \"best_ask\":\"0.6\"}, {\"asset_id\":\"58313761654877669244690227616056238030136603415514645252000528337391143520538\", \"price\":\"0.52\", \"size\":\"213.71\", \"side\":\"SELL\", \"hash\":\"7b755319aed0becc44b987a00f1afc3d1a8d8e28\", \"best_bid\":\"0.4\", \"best_ask\":\"0.41\"}], \"timestamp\":\"1785207426728\", \"event_type\":\"price_change\"}","received_at":"2026-07-28T02:57:06.692535Z","schema_version":"clob-market-ws.price_change.v1","sequence":null,"server_hash":null,"server_timestamp":"1785207426728","session_id":"5aad79be415c487c84df42bebd84ee93","source":"clob_market_ws"},"received_at":"2026-07-28T02:57:06.692535Z","record_id":"85337a9add20f8b8866af5aa7dbe3bb070f47ed249771f0e1b8ee51806b1ffd1","schema_fingerprint":"4aa3821a28b0b7c2400bc59aba4bcc0a76e971dadd19610d3ad38c768e124dc7","schema_version":"edge-lab-recorder.raw.v1","sequence":null,"source":"clob_market_ws"}
{"event_at":"2026-07-28T02:57:06.730000Z","event_fingerprint":"d849654bc90eeedf0d949ee3667f3010a7380cb62c4845335c5bced90dc32a34","payload":{"connection_id":"955646bd8bf740759faf38750c0f263f","event_at":"2026-07-28T02:57:06.730000Z","event_type":"price_change","frame_hash":"12449034d7c3113d2f1b77e6cfe33bf3c20fcb2e6718043edd5c384f448be242","frame_index":0,"kind":"data","monotonic_ns":309409711221750,"payload":{"event_type":"price_change","market":"0x0f70d07969bc69eaa97d0987de651885fdca02263688026aa11e7678af8f87aa","price_changes":[{"asset_id":"58313761654877669244690227616056238030136603415514645252000528337391143520538","best_ask":"0.41","best_bid":"0.4","hash":"e983b49bbbe3a41490dcfe4e10fbbdb936beedb5","price":"0.34","side":"BUY","size":"241.22"},{"asset_id":"64053005904884194822931764831592250494815136296598204104072528088122126148949","best_ask":"0.6","best_bid":"0.59","hash":"8f52eaad869dca88aab595fa916faefac6d954f1","price":"0.66","side":"SELL","size":"241.22"}],"timestamp":"1785207426730"},"payload_hash":"aeeb8ccf02842b69f2e6b5a72273b762aaa7ae217501f90d60c67eda0cc6e13b","raw_frame":"{\"market\":\"0x0f70d07969bc69eaa97d0987de651885fdca02263688026aa11e7678af8f87aa\", \"price_changes\":[{\"asset_id\":\"58313761654877669244690227616056238030136603415514645252000528337391143520538\", \"price\":\"0.34\", \"size\":\"241.22\", \"side\":\"BUY\", \"hash\":\"e983b49bbbe3a41490dcfe4e10fbbdb936beedb5\", \"best_bid\":\"0.4\", \"best_ask\":\"0.41\"}, {\"asset_id\":\"64053005904884194822931764831592250494815136296598204104072528088122126148949\", \"price\":\"0.66\", \"size\":\"241.22\", \"side\":\"SELL\", \"hash\":\"8f52eaad869dca88aab595fa916faefac6d954f1\", \"best_bid\":\"0.59\", \"best_ask\":\"0.6\"}], \"timestamp\":\"1785207426730\", \"event_type\":\"price_change\"}","received_at":"2026-07-28T02:57:06.694105Z","schema_version":"clob-market-ws.price_change.v1","sequence":null,"server_hash":null,"server_timestamp":"1785207426730","session_id":"5aad79be415c487c84df42bebd84ee93","source":"clob_market_ws"},"received_at":"2026-07-28T02:57:06.694105Z","record_id":"9ba412856ab9d061f175d468a6295ae59c748078490fb4874f3c14206abafdb8","schema_fingerprint":"4aa3821a28b0b7c2400bc59aba4bcc0a76e971dadd19610d3ad38c768e124dc7","schema_version":"edge-lab-recorder.raw.v1","sequence":null,"source":"clob_market_ws"}
{"event_at":"2026-07-28T02:57:06.730000Z","event_fingerprint":"227ace26b025dda9187023470bb41aec5ca47c0d6768fc7cfaf6931710e65325","payload":{"connection_id":"955646bd8bf740759faf38750c0f263f","event_at":"2026-07-28T02:57:06.730000Z","event_type":"price_change","frame_hash":"bcb72faafa3dec4bb0deedc8784e462f769f6c313b763be28e3828cf97786421","frame_index":0,"kind":"data","monotonic_ns":309409712858958,"payload":{"event_type":"price_change","market":"0x0f70d07969bc69eaa97d0987de651885fdca02263688026aa11e7678af8f87aa","price_changes":[{"asset_id":"64053005904884194822931764831592250494815136296598204104072528088122126148949","best_ask":"0.6","best_bid":"0.59","hash":"710d057320ded2e8a497b12f7038a27d4d8ca3f8","price":"0.01","side":"BUY","size":"2695.52"},{"asset_id":"58313761654877669244690227616056238030136603415514645252000528337391143520538","best_ask":"0.41","best_bid":"0.4","hash":"26319744158925a1e60228e91ad66d247138150c","price":"0.99","side":"SELL","size":"2695.52"}],"timestamp":"1785207426730"},"payload_hash":"f8174ae98af1e1e85d4e467a8c96d857b33878afd4640ab42b0a2c9a6352e616","raw_frame":"{\"market\":\"0x0f70d07969bc69eaa97d0987de651885fdca02263688026aa11e7678af8f87aa\", \"price_changes\":[{\"asset_id\":\"64053005904884194822931764831592250494815136296598204104072528088122126148949\", \"price\":\"0.01\", \"size\":\"2695.52\", \"side\":\"BUY\", \"hash\":\"710d057320ded2e8a497b12f7038a27d4d8ca3f8\", \"best_bid\":\"0.59\", \"best_ask\":\"0.6\"}, {\"asset_id\":\"58313761654877669244690227616056238030136603415514645252000528337391143520538\", \"price\":\"0.99\", \"size\":\"2695.52\", \"side\":\"SELL\", \"hash\":\"26319744158925a1e60228e91ad66d247138150c\", \"best_bid\":\"0.4\", \"best_ask\":\"0.41\"}], \"timestamp\":\"1785207426730\", \"event_type\":\"price_change\"}","received_at":"2026-07-28T02:57:06.695747Z","schema_version":"clob-market-ws.price_change.v1","sequence":null,"server_hash":null,"server_timestamp":"1785207426730","session_id":"5aad79be415c487c84df42bebd84ee93","source":"clob_market_ws"},"received_at":"2026-07-28T02:57:06.695747Z","record_id":"8e078536de73cd1a28ba913f7bf740036f3322223b1923920b89c561188d592c","schema_fingerprint":"4aa3821a28b0b7c2400bc59aba4bcc0a76e971dadd19610d3ad38c768e124dc7","schema_version":"edge-lab-recorder.raw.v1","sequence":null,"source":"clob_market_ws"}
{"event_at":"2026-07-28T02:57:06.735000Z","event_fingerprint":"7096e2ac6812f651089f783e7233e8599b1c22072c954a4d5be1f52beceb4420","payload":{"connection_id":"955646bd8bf740759faf38750c0f263f","event_at":"2026-07-28T02:57:06.735000Z","event_type":"price_change","frame_hash":"faa1a8567979280a0d8a66f9e6fba10aa24b7844ec31158fae9904d094d11ed1","frame_index":0,"kind":"data","monotonic_ns":309409714346458,"payload":{"event_type":"price_change","market":"0x0f70d07969bc69eaa97d0987de651885fdca02263688026aa11e7678af8f87aa","price_changes":[{"asset_id":"58313761654877669244690227616056238030136603415514645252000528337391143520538","best_ask":"0.41","best_bid":"0.4","hash":"772f25221f66a1a783c63952c0a8bf596c66672b","price":"0.34","side":"BUY","size":"291.22"},{"asset_id":"64053005904884194822931764831592250494815136296598204104072528088122126148949","best_ask":"0.6","best_bid":"0.59","hash":"4cfebe5e6bddb075e4c3ae6d7f1a2a8d26e174a2","price":"0.66","side":"SELL","size":"291.22"}],"timestamp":"1785207426735"},"payload_hash":"40dbdaa1f0782b02a936425e7db9ab6df97759da72bcf28d47e80b6844ec620f","raw_frame":"{\"market\":\"0x0f70d07969bc69eaa97d0987de651885fdca02263688026aa11e7678af8f87aa\", \"price_changes\":[{\"asset_id\":\"58313761654877669244690227616056238030136603415514645252000528337391143520538\", \"price\":\"0.34\", \"size\":\"291.22\", \"side\":\"BUY\", \"hash\":\"772f25221f66a1a783c63952c0a8bf596c66672b\", \"best_bid\":\"0.4\", \"best_ask\":\"0.41\"}, {\"asset_id\":\"64053005904884194822931764831592250494815136296598204104072528088122126148949\", \"price\":\"0.66\", \"size\":\"291.22\", \"side\":\"SELL\", \"hash\":\"4cfebe5e6bddb075e4c3ae6d7f1a2a8d26e174a2\", \"best_bid\":\"0.59\", \"best_ask\":\"0.6\"}], \"timestamp\":\"1785207426735\", \"event_type\":\"price_change\"}","received_at":"2026-07-28T02:57:06.697234Z","schema_version":"clob-market-ws.price_change.v1","sequence":null,"server_hash":null,"server_timestamp":"1785207426735","session_id":"5aad79be415c487c84df42bebd84ee93","source":"clob_market_ws"},"received_at":"2026-07-28T02:57:06.697234Z","record_id":"9613b33ff5b8dc77525496c52e2ca6dee1d05da7945509d9ea732d55556ad69b","schema_fingerprint":"4aa3821a28b0b7c2400bc59aba4bcc0a76e971dadd19610d3ad38c768e124dc7","schema_version":"edge-lab-recorder.raw.v1","sequence":null,"source":"clob_market_ws"}
{"event_at":"2026-07-28T02:57:06.736000Z","event_fingerprint":"cc31ec49d747b69211fac47160183870b0fa2dd8a4b451b2e8c70d43958b8cdd","payload":{"connection_id":"955646bd8bf740759faf38750c0f263f","event_at":"2026-07-28T02:57:06.736000Z","event_type":"price_change","frame_hash":"4194e025fb13a90f8f240592124e4a790fc6ac5a0e1bb5bba77d0a9e75d269e2","frame_index":0,"kind":"data","monotonic_ns":309409715909083,"payload":{"event_type":"price_change","market":"0x0f70d07969bc69eaa97d0987de651885fdca02263688026aa11e7678af8f87aa","price_changes":[{"asset_id":"58313761654877669244690227616056238030136603415514645252000528337391143520538","best_ask":"0.41","best_bid":"0.4","hash":"02f5b8a0dc4c30fff3be1ed01bef57bd528149c0","price":"0.18","side":"BUY","size":"257.1"},{"asset_id":"64053005904884194822931764831592250494815136296598204104072528088122126148949","best_ask":"0.6","best_bid":"0.59","hash":"05b0f6cbc51259345907c4cc9fb59b29439ddbe4","price":"0.82","side":"SELL","size":"257.1"}],"timestamp":"1785207426736"},"payload_hash":"e24fb0c92e68d73af856a0c7ce230c2ad0b22576fd510267ae9ee4a80e04884f","raw_frame":"{\"market\":\"0x0f70d07969bc69eaa97d0987de651885fdca02263688026aa11e7678af8f87aa\", \"price_changes\":[{\"asset_id\":\"58313761654877669244690227616056238030136603415514645252000528337391143520538\", \"price\":\"0.18\", \"size\":\"257.1\", \"side\":\"BUY\", \"hash\":\"02f5b8a0dc4c30fff3be1ed01bef57bd528149c0\", \"best_bid\":\"0.4\", \"best_ask\":\"0.41\"}, {\"asset_id\":\"64053005904884194822931764831592250494815136296598204104072528088122126148949\", \"price\":\"0.82\", \"size\":\"257.1\", \"side\":\"SELL\", \"hash\":\"05b0f6cbc51259345907c4cc9fb59b29439ddbe4\", \"best_bid\":\"0.59\", \"best_ask\":\"0.6\"}], \"timestamp\":\"1785207426736\", \"event_type\":\"price_change\"}","received_at":"2026-07-28T02:57:06.698796Z","schema_version":"clob-market-ws.price_change.v1","sequence":null,"server_hash":null,"server_timestamp":"1785207426736","session_id":"5aad79be415c487c84df42bebd84ee93","source":"clob_market_ws"},"received_at":"2026-07-28T02:57:06.698796Z","record_id":"91297af3e61b9699d95788f53710202b3d20cefac64629628754f74aaff14d73","schema_fingerprint":"4aa3821a28b0b7c2400bc59aba4bcc0a76e971dadd19610d3ad38c768e124dc7","schema_version":"edge-lab-recorder.raw.v1","sequence":null,"source":"clob_market_ws"}
{"event_at":"2026-07-28T02:57:06.738000Z","event_fingerprint":"65d4d0bfada05d3777710ccc7ad3f5ea47482688690809ae8d2926a8b80c4085","payload":{"connection_id":"955646bd8bf740759faf38750c0f263f","event_at":"2026-07-28T02:57:06.738000Z","event_type":"price_change","frame_hash":"317f9feabf770b773cce5621878e6adba14e539361bbe8719e99edac95f5ccb4","frame_index":0,"kind":"data","monotonic_ns":309409717400541,"payload":{"event_type":"price_change","market":"0x0f70d07969bc69eaa97d0987de651885fdca02263688026aa11e7678af8f87aa","price_changes":[{"asset_id":"58313761654877669244690227616056238030136603415514645252000528337391143520538","best_ask":"0.41","best_bid":"0.4","hash":"01949872c4886989371084c6c7769f816a7e47e0","price":"0.21","side":"BUY","size":"246.3"},{"asset_id":"64053005904884194822931764831592250494815136296598204104072528088122126148949","best_ask":"0.6","best_bid":"0.59","hash":"3ae736b2a70fcb9c01ae9581bacb26a74680e4f7","price":"0.79","side":"SELL","size":"246.3"}],"timestamp":"1785207426738"},"payload_hash":"6263414fe1f44d20ba7a220f9c00d5a93aca954d6bd0720c36d1af6be761f626","raw_frame":"{\"market\":\"0x0f70d07969bc69eaa97d0987de651885fdca02263688026aa11e7678af8f87aa\", \"price_changes\":[{\"asset_id\":\"58313761654877669244690227616056238030136603415514645252000528337391143520538\", \"price\":\"0.21\", \"size\":\"246.3\", \"side\":\"BUY\", \"hash\":\"01949872c4886989371084c6c7769f816a7e47e0\", \"best_bid\":\"0.4\", \"best_ask\":\"0.41\"}, {\"asset_id\":\"64053005904884194822931764831592250494815136296598204104072528088122126148949\", \"price\":\"0.79\", \"size\":\"246.3\", \"side\":\"SELL\", \"hash\":\"3ae736b2a70fcb9c01ae9581bacb26a74680e4f7\", \"best_bid\":\"0.59\", \"best_ask\":\"0.6\"}], \"timestamp\":\"1785207426738\", \"event_type\":\"price_change\"}","received_at":"2026-07-28T02:57:06.700288Z","schema_version":"clob-market-ws.price_change.v1","sequence":null,"server_hash":null,"server_timestamp":"1785207426738","session_id":"5aad79be415c487c84df42bebd84ee93","source":"clob_market_ws"},"received_at":"2026-07-28T02:57:06.700288Z","record_id":"66a6fda308eba99a258f043ab3572c4a3f72e7b6cea8e0d9ae9a3a9a6b4ab523","schema_fingerprint":"4aa3821a28b0b7c2400bc59aba4bcc0a76e971dadd19610d3ad38c768e124dc7","schema_version":"edge-lab-recorder.raw.v1","sequence":null,"source":"clob_market_ws"}
{"event_at":"2026-07-28T02:57:06.740000Z","event_fingerprint":"fde96526232ad25eddf4fe21e4c742dec73c508460ec05dbd05be2f655faf6d4","payload":{"connection_id":"955646bd8bf740759faf38750c0f263f","event_at":"2026-07-28T02:57:06.740000Z","event_type":"price_change","frame_hash":"5291609c28dec83d94310a99ff5a386e5289aa5b6af68d7c5a684c233f5ff110","frame_index":0,"kind":"data","monotonic_ns":309409718900250,"payload":{"event_type":"price_change","market":"0x0f70d07969bc69eaa97d0987de651885fdca02263688026aa11e7678af8f87aa","price_changes":[{"asset_id":"58313761654877669244690227616056238030136603415514645252000528337391143520538","best_ask":"0.41","best_bid":"0.4","hash":"229363c763e07b3a90b5c207365dd17a90beaedc","price":"0.4","side":"BUY","size":"145.26"},{"asset_id":"64053005904884194822931764831592250494815136296598204104072528088122126148949","best_ask":"0.6","best_bid":"0.59","hash":"87a717f22d4b405d2a7e147391aa53eb9330664a","price":"0.6","side":"SELL","size":"145.26"}],"timestamp":"1785207426740"},"payload_hash":"cd8c8ff233ba6245dc69c6dca3f3bd3454c0773eaff5eaa90cb2f4b1a3df1d57","raw_frame":"{\"market\":\"0x0f70d07969bc69eaa97d0987de651885fdca02263688026aa11e7678af8f87aa\", \"price_changes\":[{\"asset_id\":\"58313761654877669244690227616056238030136603415514645252000528337391143520538\", \"price\":\"0.4\", \"size\":\"145.26\", \"side\":\"BUY\", \"hash\":\"229363c763e07b3a90b5c207365dd17a90beaedc\", \"best_bid\":\"0.4\", \"best_ask\":\"0.41\"}, {\"asset_id\":\"64053005904884194822931764831592250494815136296598204104072528088122126148949\", \"price\":\"0.6\", \"size\":\"145.26\", \"side\":\"SELL\", \"hash\":\"87a717f22d4b405d2a7e147391aa53eb9330664a\", \"best_bid\":\"0.59\", \"best_ask\":\"0.6\"}], \"timestamp\":\"1785207426740\", \"event_type\":\"price_change\"}","received_at":"2026-07-28T02:57:06.701787Z","schema_version":"clob-market-ws.price_change.v1","sequence":null,"server_hash":null,"server_timestamp":"1785207426740","session_id":"5aad79be415c487c84df42bebd84ee93","source":"clob_market_ws"},"received_at":"2026-07-28T02:57:06.701787Z","record_id":"6e9664d02d40c3c8e4777803ed74c94b0caea67e392835e0949f435058c12701","schema_fingerprint":"4aa3821a28b0b7c2400bc59aba4bcc0a76e971dadd19610d3ad38c768e124dc7","schema_version":"edge-lab-recorder.raw.v1","sequence":null,"source":"clob_market_ws"}
{"event_at":"2026-07-28T02:57:06.745000Z","event_fingerprint":"1a986698cee4ccce081e58d47750753de1f2bc7cad3b51f5d64959bff9f90dd2","payload":{"connection_id":"955646bd8bf740759faf38750c0f263f","event_at":"2026-07-28T02:57:06.745000Z","event_type":"price_change","frame_hash":"570edcae35c266b26286c454fca5348f027e3fa456b94f529c9f11afc5df5a42","frame_index":0,"kind":"data","monotonic_ns":309409721061583,"payload":{"event_type":"price_change","market":"0x0f70d07969bc69eaa97d0987de651885fdca02263688026aa11e7678af8f87aa","price_changes":[{"asset_id":"58313761654877669244690227616056238030136603415514645252000528337391143520538","best_ask":"0.41","best_bid":"0.4","hash":"d1b275d53ceb9380de327252f1d625cfdb8d1c26","price":"0.47","side":"SELL","size":"248.64"},{"asset_id":"64053005904884194822931764831592250494815136296598204104072528088122126148949","best_ask":"0.6","best_bid":"0.59","hash":"8fc41f61c4d8b0470e6548427387aa271b5b95fe","price":"0.53","side":"BUY","size":"248.64"}],"timestamp":"1785207426745"},"payload_hash":"0c63b897d96d219d5dc07b7ae3811776f966e66e511508e1c7ad9b2d4f343f0b","raw_frame":"{\"market\":\"0x0f70d07969bc69eaa97d0987de651885fdca02263688026aa11e7678af8f87aa\", \"price_changes\":[{\"asset_id\":\"58313761654877669244690227616056238030136603415514645252000528337391143520538\", \"price\":\"0.47\", \"size\":\"248.64\", \"side\":\"SELL\", \"hash\":\"d1b275d53ceb9380de327252f1d625cfdb8d1c26\", \"best_bid\":\"0.4\", \"best_ask\":\"0.41\"}, {\"asset_id\":\"64053005904884194822931764831592250494815136296598204104072528088122126148949\", \"price\":\"0.53\", \"size\":\"248.64\", \"side\":\"BUY\", \"hash\":\"8fc41f61c4d8b0470e6548427387aa271b5b95fe\", \"best_bid\":\"0.59\", \"best_ask\":\"0.6\"}], \"timestamp\":\"1785207426745\", \"event_type\":\"price_change\"}","received_at":"2026-07-28T02:57:06.703949Z","schema_version":"clob-market-ws.price_change.v1","sequence":null,"server_hash":null,"server_timestamp":"1785207426745","session_id":"5aad79be415c487c84df42bebd84ee93","source":"clob_market_ws"},"received_at":"2026-07-28T02:57:06.703949Z","record_id":"7f43c03236675b8efb451d8c303fd1f269ffe8c7aae13647d48978be94b31203","schema_fingerprint":"4aa3821a28b0b7c2400bc59aba4bcc0a76e971dadd19610d3ad38c768e124dc7","schema_version":"edge-lab-recorder.raw.v1","sequence":null,"source":"clob_market_ws"}
{"event_at":"2026-07-28T02:57:06.747000Z","event_fingerprint":"4c4094abf302945b5aec1454108da10e81155e06cc5945cf7dfe060da7a1ebd3","payload":{"connection_id":"955646bd8bf740759faf38750c0f263f","event_at":"2026-07-28T02:57:06.747000Z","event_type":"price_change","frame_hash":"fd3a1a1fa89d74e97b35b2b1554c93b74edef88dc68c1d86acf7c9899944cd26","frame_index":0,"kind":"data","monotonic_ns":309409722534666,"payload":{"event_type":"price_change","market":"0x0f70d07969bc69eaa97d0987de651885fdca02263688026aa11e7678af8f87aa","price_changes":[{"asset_id":"58313761654877669244690227616056238030136603415514645252000528337391143520538","best_ask":"0.41","best_bid":"0.4","hash":"c7685fcf9f46a2a3e1338e9b11dfab78793a3444","price":"0.34","side":"BUY","size":"341.22"},{"asset_id":"64053005904884194822931764831592250494815136296598204104072528088122126148949","best_ask":"0.6","best_bid":"0.59","hash":"612c8ba219d896b7346ba39814c57aa30dc6e4e7","price":"0.66","side":"SELL","size":"341.22"}],"timestamp":"1785207426747"},"payload_hash":"10441deecaa16b24d38851c947773bd600b6c6332583573ee62a7a87f8a72fe9","raw_frame":"{\"market\":\"0x0f70d07969bc69eaa97d0987de651885fdca02263688026aa11e7678af8f87aa\", \"price_changes\":[{\"asset_id\":\"58313761654877669244690227616056238030136603415514645252000528337391143520538\", \"price\":\"0.34\", \"size\":\"341.22\", \"side\":\"BUY\", \"hash\":\"c7685fcf9f46a2a3e1338e9b11dfab78793a3444\", \"best_bid\":\"0.4\", \"best_ask\":\"0.41\"}, {\"asset_id\":\"64053005904884194822931764831592250494815136296598204104072528088122126148949\", \"price\":\"0.66\", \"size\":\"341.22\", \"side\":\"SELL\", \"hash\":\"612c8ba219d896b7346ba39814c57aa30dc6e4e7\", \"best_bid\":\"0.59\", \"best_ask\":\"0.6\"}], \"timestamp\":\"1785207426747\", \"event_type\":\"price_change\"}","received_at":"2026-07-28T02:57:06.705421Z","schema_version":"clob-market-ws.price_change.v1","sequence":null,"server_hash":null,"server_timestamp":"1785207426747","session_id":"5aad79be415c487c84df42bebd84ee93","source":"clob_market_ws"},"received_at":"2026-07-28T02:57:06.705421Z","record_id":"dba551daeb983982d9da4ecc51048b6abbbdf42cb6cf78f810e79d0f1ce682fa","schema_fingerprint":"4aa3821a28b0b7c2400bc59aba4bcc0a76e971dadd19610d3ad38c768e124dc7","schema_version":"edge-lab-recorder.raw.v1","sequence":null,"source":"clob_market_ws"}
{"event_at":"2026-07-28T02:57:06.748000Z","event_fingerprint":"bd20473344454d6d0cda60568148acf9bb1aedb2575e988edbc6ce8d047cf35d","payload":{"connection_id":"955646bd8bf740759faf38750c0f263f","event_at":"2026-07-28T02:57:06.748000Z","event_type":"price_change","frame_hash":"33cd0c7263cf9d523cb83783df51581199ae22c3584823cb02f78bdc455a62bd","frame_index":0,"kind":"data","monotonic_ns":309409724058750,"payload":{"event_type":"price_change","market":"0x0f70d07969bc69eaa97d0987de651885fdca02263688026aa11e7678af8f87aa","price_changes":[{"asset_id":"64053005904884194822931764831592250494815136296598204104072528088122126148949","best_ask":"0.6","best_bid":"0.59","hash":"a504ffebf1bd8b1cfd2b5400720929c407e46dd6","price":"0.47","side":"BUY","size":"68.74"},{"asset_id":"58313761654877669244690227616056238030136603415514645252000528337391143520538","best_ask":"0.41","best_bid":"0.4","hash":"b72dc4fbd7dfa907e916fcc671b0053330334a25","price":"0.53","side":"SELL","size":"68.74"}],"timestamp":"1785207426748"},"payload_hash":"75858efdfa5aeefca2d4ddf2c020d7f6f6d32cc2af7bf3b3665238935ddbb31a","raw_frame":"{\"market\":\"0x0f70d07969bc69eaa97d0987de651885fdca02263688026aa11e7678af8f87aa\", \"price_changes\":[{\"asset_id\":\"64053005904884194822931764831592250494815136296598204104072528088122126148949\", \"price\":\"0.47\", \"size\":\"68.74\", \"side\":\"BUY\", \"hash\":\"a504ffebf1bd8b1cfd2b5400720929c407e46dd6\", \"best_bid\":\"0.59\", \"best_ask\":\"0.6\"}, {\"asset_id\":\"58313761654877669244690227616056238030136603415514645252000528337391143520538\", \"price\":\"0.53\", \"size\":\"68.74\", \"side\":\"SELL\", \"hash\":\"b72dc4fbd7dfa907e916fcc671b0053330334a25\", \"best_bid\":\"0.4\", \"best_ask\":\"0.41\"}], \"timestamp\":\"1785207426748\", \"event_type\":\"price_change\"}","received_at":"2026-07-28T02:57:06.706947Z","schema_version":"clob-market-ws.price_change.v1","sequence":null,"server_hash":null,"server_timestamp":"1785207426748","session_id":"5aad79be415c487c84df42bebd84ee93","source":"clob_market_ws"},"received_at":"2026-07-28T02:57:06.706947Z","record_id":"f161fce5b59495769617df2ae65278819ce28b02286efbf12b2f520c2ec59e23","schema_fingerprint":"4aa3821a28b0b7c2400bc59aba4bcc0a76e971dadd19610d3ad38c768e124dc7","schema_version":"edge-lab-recorder.raw.v1","sequence":null,"source":"clob_market_ws"}
{"event_at":"2026-07-28T02:57:06.751000Z","event_fingerprint":"5e2999d4de81495d6c999b7b0b5a40009165962c7533dbd87f7e583667a194d7","payload":{"connection_id":"955646bd8bf740759faf38750c0f263f","event_at":"2026-07-28T02:57:06.751000Z","event_type":"price_change","frame_hash":"c78d40be79fe8706e6cac7e17f6ad108e753117cdb2a655b9e7eb6d770e5f1a2","frame_index":0,"kind":"data","monotonic_ns":309409725532625,"payload":{"event_type":"price_change","market":"0x0f70d07969bc69eaa97d0987de651885fdca02263688026aa11e7678af8f87aa","price_changes":[{"asset_id":"64053005904884194822931764831592250494815136296598204104072528088122126148949","best_ask":"0.6","best_bid":"0.59","hash":"54a430e07793341bb229f5357658265f05bbd5f3","price":"0.43","side":"BUY","size":"104.3"},{"asset_id":"58313761654877669244690227616056238030136603415514645252000528337391143520538","best_ask":"0.41","best_bid":"0.4","hash":"9ddf103eeb6066331bb3acb6cf901eaf8355a2d6","price":"0.57","side":"SELL","size":"104.3"}],"timestamp":"1785207426751"},"payload_hash":"4f2186fcb7185e67bcca803e0b1f424a76cad5bc64112799c1de319d312bc649","raw_frame":"{\"market\":\"0x0f70d07969bc69eaa97d0987de651885fdca02263688026aa11e7678af8f87aa\", \"price_changes\":[{\"asset_id\":\"64053005904884194822931764831592250494815136296598204104072528088122126148949\", \"price\":\"0.43\", \"size\":\"104.3\", \"side\":\"BUY\", \"hash\":\"54a430e07793341bb229f5357658265f05bbd5f3\", \"best_bid\":\"0.59\", \"best_ask\":\"0.6\"}, {\"asset_id\":\"58313761654877669244690227616056238030136603415514645252000528337391143520538\", \"price\":\"0.57\", \"size\":\"104.3\", \"side\":\"SELL\", \"hash\":\"9ddf103eeb6066331bb3acb6cf901eaf8355a2d6\", \"best_bid\":\"0.4\", \"best_ask\":\"0.41\"}], \"timestamp\":\"1785207426751\", \"event_type\":\"price_change\"}","received_at":"2026-07-28T02:57:06.708421Z","schema_version":"clob-market-ws.price_change.v1","sequence":null,"server_hash":null,"server_timestamp":"1785207426751","session_id":"5aad79be415c487c84df42bebd84ee93","source":"clob_market_ws"},"received_at":"2026-07-28T02:57:06.708421Z","record_id":"5e4718942e237e4a40585d9d9598ea6ced124a214c1e00fd3d85f391acb84735","schema_fingerprint":"4aa3821a28b0b7c2400bc59aba4bcc0a76e971dadd19610d3ad38c768e124dc7","schema_version":"edge-lab-recorder.raw.v1","sequence":null,"source":"clob_market_ws"}
{"event_at":"2026-07-28T02:57:06.752000Z","event_fingerprint":"5436f60ac1cd02a837baba8d2c9fb387ab578b6b661be6040b27c761732b3935","payload":{"connection_id":"955646bd8bf740759faf38750c0f263f","event_at":"2026-07-28T02:57:06.752000Z","event_type":"price_change","frame_hash":"eaf6a3cf02510a90f10e4c7bd27dd9e8870346f9fa703294a5e7ac859fe88d30","frame_index":0,"kind":"data","monotonic_ns":309409727019291,"payload":{"event_type":"price_change","market":"0x0f70d07969bc69eaa97d0987de651885fdca02263688026aa11e7678af8f87aa","price_changes":[{"asset_id":"64053005904884194822931764831592250494815136296598204104072528088122126148949","best_ask":"0.6","best_bid":"0.59","hash":"338d0b958195f5e815f625162d0d0912de4c8d44","price":"0.51","side":"BUY","size":"123.3"},{"asset_id":"58313761654877669244690227616056238030136603415514645252000528337391143520538","best_ask":"0.41","best_bid":"0.4","hash":"51a8652ccbaa60aa99fedd753f007db596ec2332","price":"0.49","side":"SELL","size":"123.3"}],"timestamp":"1785207426752"},"payload_hash":"ce63b40924dd42915a283f016bb5bdfa1bb813e576ffc7ca605a43721829c4ea","raw_frame":"{\"market\":\"0x0f70d07969bc69eaa97d0987de651885fdca02263688026aa11e7678af8f87aa\", \"price_changes\":[{\"asset_id\":\"64053005904884194822931764831592250494815136296598204104072528088122126148949\", \"price\":\"0.51\", \"size\":\"123.3\", \"side\":\"BUY\", \"hash\":\"338d0b958195f5e815f625162d0d0912de4c8d44\", \"best_bid\":\"0.59\", \"best_ask\":\"0.6\"}, {\"asset_id\":\"58313761654877669244690227616056238030136603415514645252000528337391143520538\", \"price\":\"0.49\", \"size\":\"123.3\", \"side\":\"SELL\", \"hash\":\"51a8652ccbaa60aa99fedd753f007db596ec2332\", \"best_bid\":\"0.4\", \"best_ask\":\"0.41\"}], \"timestamp\":\"1785207426752\", \"event_type\":\"price_change\"}","received_at":"2026-07-28T02:57:06.709908Z","schema_version":"clob-market-ws.price_change.v1","sequence":null,"server_hash":null,"server_timestamp":"1785207426752","session_id":"5aad79be415c487c84df42bebd84ee93","source":"clob_market_ws"},"received_at":"2026-07-28T02:57:06.709908Z","record_id":"f06258f5a619904325bea65598924edc2f5f4477c4e2eca5deb141e6eb44828d","schema_fingerprint":"4aa3821a28b0b7c2400bc59aba4bcc0a76e971dadd19610d3ad38c768e124dc7","schema_version":"edge-lab-recorder.raw.v1","sequence":null,"source":"clob_market_ws"}
{"event_at":"2026-07-28T02:57:06.753000Z","event_fingerprint":"b1e1bb3d909cbc55bcc01ee289c9a49f2906b1ce5d80081e41630478934ce1a3","payload":{"connection_id":"955646bd8bf740759faf38750c0f263f","event_at":"2026-07-28T02:57:06.753000Z","event_type":"price_change","frame_hash":"9194f5a48343e579f27a97608cdb29388ddeef3c11e9d72d25f5fef7c3786b7a","frame_index":0,"kind":"data","monotonic_ns":309409728491750,"payload":{"event_type":"price_change","market":"0x0f70d07969bc69eaa97d0987de651885fdca02263688026aa11e7678af8f87aa","price_changes":[{"asset_id":"58313761654877669244690227616056238030136603415514645252000528337391143520538","best_ask":"0.41","best_bid":"0.4","hash":"35214cbcdc7787709e4f6212c6426d5b600348e3","price":"0.17","side":"BUY","size":"468.58"},{"asset_id":"64053005904884194822931764831592250494815136296598204104072528088122126148949","best_ask":"0.6","best_bid":"0.59","hash":"2280cc8f588db1409098d08e003c637d983194d4","price":"0.83","side":"SELL","size":"468.58"}],"timestamp":"1785207426753"},"payload_hash":"1ab1b66eae5acd149d1487b90196c94b81d714742ba324b76afb61aac2ca64f5","raw_frame":"{\"market\":\"0x0f70d07969bc69eaa97d0987de651885fdca02263688026aa11e7678af8f87aa\", \"price_changes\":[{\"asset_id\":\"58313761654877669244690227616056238030136603415514645252000528337391143520538\", \"price\":\"0.17\", \"size\":\"468.58\", \"side\":\"BUY\", \"hash\":\"35214cbcdc7787709e4f6212c6426d5b600348e3\", \"best_bid\":\"0.4\", \"best_ask\":\"0.41\"}, {\"asset_id\":\"64053005904884194822931764831592250494815136296598204104072528088122126148949\", \"price\":\"0.83\", \"size\":\"468.58\", \"side\":\"SELL\", \"hash\":\"2280cc8f588db1409098d08e003c637d983194d4\", \"best_bid\":\"0.59\", \"best_ask\":\"0.6\"}], \"timestamp\":\"1785207426753\", \"event_type\":\"price_change\"}","received_at":"2026-07-28T02:57:06.711380Z","schema_version":"clob-market-ws.price_change.v1","sequence":null,"server_hash":null,"server_timestamp":"1785207426753","session_id":"5aad79be415c487c84df42bebd84ee93","source":"clob_market_ws"},"received_at":"2026-07-28T02:57:06.711380Z","record_id":"30bb10fa1b6644acde33e90e99076385b0e53e41a2214021ccc17ca9e46e6e6c","schema_fingerprint":"4aa3821a28b0b7c2400bc59aba4bcc0a76e971dadd19610d3ad38c768e124dc7","schema_version":"edge-lab-recorder.raw.v1","sequence":null,"source":"clob_market_ws"}
{"event_at":"2026-07-28T02:57:06.754000Z","event_fingerprint":"160cad97cf742abc33671db83c3871706087e01efb7727b56c7beeb0e7221596","payload":{"connection_id":"955646bd8bf740759faf38750c0f263f","event_at":"2026-07-28T02:57:06.754000Z","event_type":"price_change","frame_hash":"ca7346ca8f0ab6f05bc6aff1ec575b45eb4631b06d19cf1b27bb534091f07c49","frame_index":0,"kind":"data","monotonic_ns":309409729933750,"payload":{"event_type":"price_change","market":"0x0f70d07969bc69eaa97d0987de651885fdca02263688026aa11e7678af8f87aa","price_changes":[{"asset_id":"64053005904884194822931764831592250494815136296598204104072528088122126148949","best_ask":"0.6","best_bid":"0.59","hash":"155136ed289c94a4efbcd6920d47967570bac4b7","price":"0.57","side":"BUY","size":"57.7"},{"asset_id":"58313761654877669244690227616056238030136603415514645252000528337391143520538","best_ask":"0.41","best_bid":"0.4","hash":"cfcc84db351bf3405c997202d7dbe6c466de6bc0","price":"0.43","side":"SELL","size":"57.7"}],"timestamp":"1785207426754"},"payload_hash":"33535bcef827b9c0a2952edf7cb8c43f6167c8b62c5b7739b0ab7e8763eb1c13","raw_frame":"{\"market\":\"0x0f70d07969bc69eaa97d0987de651885fdca02263688026aa11e7678af8f87aa\", \"price_changes\":[{\"asset_id\":\"64053005904884194822931764831592250494815136296598204104072528088122126148949\", \"price\":\"0.57\", \"size\":\"57.7\", \"side\":\"BUY\", \"hash\":\"155136ed289c94a4efbcd6920d47967570bac4b7\", \"best_bid\":\"0.59\", \"best_ask\":\"0.6\"}, {\"asset_id\":\"58313761654877669244690227616056238030136603415514645252000528337391143520538\", \"price\":\"0.43\", \"size\":\"57.7\", \"side\":\"SELL\", \"hash\":\"cfcc84db351bf3405c997202d7dbe6c466de6bc0\", \"best_bid\":\"0.4\", \"best_ask\":\"0.41\"}], \"timestamp\":\"1785207426754\", \"event_type\":\"price_change\"}","received_at":"2026-07-28T02:57:06.712822Z","schema_version":"clob-market-ws.price_change.v1","sequence":null,"server_hash":null,"server_timestamp":"1785207426754","session_id":"5aad79be415c487c84df42bebd84ee93","source":"clob_market_ws"},"received_at":"2026-07-28T02:57:06.712822Z","record_id":"47c578504281a8d576b63112ccf679475d0dd6ec208e6ba1d2cb6ca6be3ea623","schema_fingerprint":"4aa3821a28b0b7c2400bc59aba4bcc0a76e971dadd19610d3ad38c768e124dc7","schema_version":"edge-lab-recorder.raw.v1","sequence":null,"source":"clob_market_ws"}
{"event_at":"2026-07-28T02:57:06.756000Z","event_fingerprint":"98fc2afa8536e67839e55c2d82e10a6fa5354ff243233afc733f1d52120025d1","payload":{"connection_id":"955646bd8bf740759faf38750c0f263f","event_at":"2026-07-28T02:57:06.756000Z","event_type":"price_change","frame_hash":"fdf5f5584f82e6c2cbaaa0405e2ec29907085840f3e3a58d75286a4c12b08a83","frame_index":0,"kind":"data","monotonic_ns":309409731427041,"payload":{"event_type":"price_change","market":"0x0f70d07969bc69eaa97d0987de651885fdca02263688026aa11e7678af8f87aa","price_changes":[{"asset_id":"64053005904884194822931764831592250494815136296598204104072528088122126148949","best_ask":"0.6","best_bid":"0.59","hash":"f73013ffde2ca7fd1b6f7dfd5f5aad9b9883ba37","price":"0.61","side":"SELL","size":"79.28"},{"asset_id":"58313761654877669244690227616056238030136603415514645252000528337391143520538","best_ask":"0.41","best_bid":"0.4","hash":"478883ccd9d3d5ec9d61bb58f3e1d757a1addbe6","price":"0.39","side":"BUY","size":"79.28"}],"timestamp":"1785207426756"},"payload_hash":"529db0b2f7abea33250d4a86a186f9e63967785ae7f567016ae9f7325e46a435","raw_frame":"{\"market\":\"0x0f70d07969bc69eaa97d0987de651885fdca02263688026aa11e7678af8f87aa\", \"price_changes\":[{\"asset_id\":\"64053005904884194822931764831592250494815136296598204104072528088122126148949\", \"price\":\"0.61\", \"size\":\"79.28\", \"side\":\"SELL\", \"hash\":\"f73013ffde2ca7fd1b6f7dfd5f5aad9b9883ba37\", \"best_bid\":\"0.59\", \"best_ask\":\"0.6\"}, {\"asset_id\":\"58313761654877669244690227616056238030136603415514645252000528337391143520538\", \"price\":\"0.39\", \"size\":\"79.28\", \"side\":\"BUY\", \"hash\":\"478883ccd9d3d5ec9d61bb58f3e1d757a1addbe6\", \"best_bid\":\"0.4\", \"best_ask\":\"0.41\"}], \"timestamp\":\"1785207426756\", \"event_type\":\"price_change\"}","received_at":"2026-07-28T02:57:06.714315Z","schema_version":"clob-market-ws.price_change.v1","sequence":null,"server_hash":null,"server_timestamp":"1785207426756","session_id":"5aad79be415c487c84df42bebd84ee93","source":"clob_market_ws"},"received_at":"2026-07-28T02:57:06.714315Z","record_id":"cd46bdbd02435f28b2d90e3ec6e7df85ce70f57ee3e73cd397ffaadcd07dff42","schema_fingerprint":"4aa3821a28b0b7c2400bc59aba4bcc0a76e971dadd19610d3ad38c768e124dc7","schema_version":"edge-lab-recorder.raw.v1","sequence":null,"source":"clob_market_ws"}
{"event_at":"2026-07-28T02:57:06.756000Z","event_fingerprint":"23ac8e2a2d5e331ca1ad6cc85a638e330cf0e9dd7d93579a0132b18ce799e49a","payload":{"connection_id":"955646bd8bf740759faf38750c0f263f","event_at":"2026-07-28T02:57:06.756000Z","event_type":"price_change","frame_hash":"3f8290c2644f9f822c867630f47e5bb13d8fe5f750836d31c5d7c464a13a57c8","frame_index":0,"kind":"data","monotonic_ns":309409732876000,"payload":{"event_type":"price_change","market":"0x0f70d07969bc69eaa97d0987de651885fdca02263688026aa11e7678af8f87aa","price_changes":[{"asset_id":"58313761654877669244690227616056238030136603415514645252000528337391143520538","best_ask":"0.41","best_bid":"0.4","hash":"916c158dd7f29837d820b1806bcb42ff0ae6595e","price":"0.49","side":"SELL","size":"128.3"},{"asset_id":"64053005904884194822931764831592250494815136296598204104072528088122126148949","best_ask":"0.6","best_bid":"0.59","hash":"c08f09ada34398eba67a1663dfda0b0fec1ba6e8","price":"0.51","side":"BUY","size":"128.3"}],"timestamp":"1785207426756"},"payload_hash":"77fd0c7baba75563e2204df40a80797db388c95bba800ea763afa30fbe0cfa27","raw_frame":"{\"market\":\"0x0f70d07969bc69eaa97d0987de651885fdca02263688026aa11e7678af8f87aa\", \"price_changes\":[{\"asset_id\":\"58313761654877669244690227616056238030136603415514645252000528337391143520538\", \"price\":\"0.49\", \"size\":\"128.3\", \"side\":\"SELL\", \"hash\":\"916c158dd7f29837d820b1806bcb42ff0ae6595e\", \"best_bid\":\"0.4\", \"best_ask\":\"0.41\"}, {\"asset_id\":\"64053005904884194822931764831592250494815136296598204104072528088122126148949\", \"price\":\"0.51\", \"size\":\"128.3\", \"side\":\"BUY\", \"hash\":\"c08f09ada34398eba67a1663dfda0b0fec1ba6e8\", \"best_bid\":\"0.59\", \"best_ask\":\"0.6\"}], \"timestamp\":\"1785207426756\", \"event_type\":\"price_change\"}","received_at":"2026-07-28T02:57:06.715764Z","schema_version":"clob-market-ws.price_change.v1","sequence":null,"server_hash":null,"server_timestamp":"1785207426756","session_id":"5aad79be415c487c84df42bebd84ee93","source":"clob_market_ws"},"received_at":"2026-07-28T02:57:06.715764Z","record_id":"f9f71822ce373990aaac2197f19d4c4fe87f5ab5e6cf37f3b8af5a2e520679e8","schema_fingerprint":"4aa3821a28b0b7c2400bc59aba4bcc0a76e971dadd19610d3ad38c768e124dc7","schema_version":"edge-lab-recorder.raw.v1","sequence":null,"source":"clob_market_ws"}
{"event_at":"2026-07-28T02:57:06.757000Z","event_fingerprint":"8be3378adac5260314f9b5dcf1df659013ec76b5d14f39f1ed441b40f94d3348","payload":{"connection_id":"955646bd8bf740759faf38750c0f263f","event_at":"2026-07-28T02:57:06.757000Z","event_type":"price_change","frame_hash":"cc5bb18e7a313a308e230301f7d0448535d58c0229c6b91b0ad66a73730bbba7","frame_index":0,"kind":"data","monotonic_ns":309409734353708,"payload":{"event_type":"price_change","market":"0x0f70d07969bc69eaa97d0987de651885fdca02263688026aa11e7678af8f87aa","price_changes":[{"asset_id":"58313761654877669244690227616056238030136603415514645252000528337391143520538","best_ask":"0.41","best_bid":"0.4","hash":"bfb745d8915ec14eb8d9cc5e72ddf6f11804e189","price":"0.46","side":"SELL","size":"207.6"},{"asset_id":"64053005904884194822931764831592250494815136296598204104072528088122126148949","best_ask":"0.6","best_bid":"0.59","hash":"93e6aa0dbcb70f452753a05c44d7d1e23c296ff8","price":"0.54","side":"BUY","size":"207.6"}],"timestamp":"1785207426757"},"payload_hash":"588841282073eb65fcb4a6583f914f0dbd3b8cc90138489c99803379d4c93ff8","raw_frame":"{\"market\":\"0x0f70d07969bc69eaa97d0987de651885fdca02263688026aa11e7678af8f87aa\", \"price_changes\":[{\"asset_id\":\"58313761654877669244690227616056238030136603415514645252000528337391143520538\", \"price\":\"0.46\", \"size\":\"207.6\", \"side\":\"SELL\", \"hash\":\"bfb745d8915ec14eb8d9cc5e72ddf6f11804e189\", \"best_bid\":\"0.4\", \"best_ask\":\"0.41\"}, {\"asset_id\":\"64053005904884194822931764831592250494815136296598204104072528088122126148949\", \"price\":\"0.54\", \"size\":\"207.6\", \"side\":\"BUY\", \"hash\":\"93e6aa0dbcb70f452753a05c44d7d1e23c296ff8\", \"best_bid\":\"0.59\", \"best_ask\":\"0.6\"}], \"timestamp\":\"1785207426757\", \"event_type\":\"price_change\"}","received_at":"2026-07-28T02:57:06.717242Z","schema_version":"clob-market-ws.price_change.v1","sequence":null,"server_hash":null,"server_timestamp":"1785207426757","session_id":"5aad79be415c487c84df42bebd84ee93","source":"clob_market_ws"},"received_at":"2026-07-28T02:57:06.717242Z","record_id":"5165a2ec3a5665d9fb42181eb0095bb76bac415e31da283d99040603a185cc6e","schema_fingerprint":"4aa3821a28b0b7c2400bc59aba4bcc0a76e971dadd19610d3ad38c768e124dc7","schema_version":"edge-lab-recorder.raw.v1","sequence":null,"source":"clob_market_ws"}
{"event_at":"2026-07-28T02:57:06.760000Z","event_fingerprint":"bca2c4f55642b40ffbbb26cb9a14beb8fabcf5b015838159eaeb8b6a6b5eccf4","payload":{"connection_id":"955646bd8bf740759faf38750c0f263f","event_at":"2026-07-28T02:57:06.760000Z","event_type":"price_change","frame_hash":"b17197eb73b56363168d19505ab6acd711a4fc16e1b64c244d5894a22beed5ac","frame_index":0,"kind":"data","monotonic_ns":309409735814500,"payload":{"event_type":"price_change","market":"0x0f70d07969bc69eaa97d0987de651885fdca02263688026aa11e7678af8f87aa","price_changes":[{"asset_id":"64053005904884194822931764831592250494815136296598204104072528088122126148949","best_ask":"0.6","best_bid":"0.59","hash":"356a37d5d75826d74ead165cde5925fdeadaa611","price":"0.53","side":"BUY","size":"263.64"},{"asset_id":"58313761654877669244690227616056238030136603415514645252000528337391143520538","best_ask":"0.41","best_bid":"0.4","hash":"5cb981f1459ef4316ee708ee184b88ba1029d1cc","price":"0.47","side":"SELL","size":"263.64"}],"timestamp":"1785207426760"},"payload_hash":"43d6e6b69e962e97874f20866e08b49592f966a083dd2150ac8df897d92353bb","raw_frame":"{\"market\":\"0x0f70d07969bc69eaa97d0987de651885fdca02263688026aa11e7678af8f87aa\", \"price_changes\":[{\"asset_id\":\"64053005904884194822931764831592250494815136296598204104072528088122126148949\", \"price\":\"0.53\", \"size\":\"263.64\", \"side\":\"BUY\", \"hash\":\"356a37d5d75826d74ead165cde5925fdeadaa611\", \"best_bid\":\"0.59\", \"best_ask\":\"0.6\"}, {\"asset_id\":\"58313761654877669244690227616056238030136603415514645252000528337391143520538\", \"price\":\"0.47\", \"size\":\"263.64\", \"side\":\"SELL\", \"hash\":\"5cb981f1459ef4316ee708ee184b88ba1029d1cc\", \"best_bid\":\"0.4\", \"best_ask\":\"0.41\"}], \"timestamp\":\"1785207426760\", \"event_type\":\"price_change\"}","received_at":"2026-07-28T02:57:06.718702Z","schema_version":"clob-market-ws.price_change.v1","sequence":null,"server_hash":null,"server_timestamp":"1785207426760","session_id":"5aad79be415c487c84df42bebd84ee93","source":"clob_market_ws"},"received_at":"2026-07-28T02:57:06.718702Z","record_id":"d9f408fccffc27a5ba4cd53875ecf733dd0c5c662352bdec4da8cf601146f2ef","schema_fingerprint":"4aa3821a28b0b7c2400bc59aba4bcc0a76e971dadd19610d3ad38c768e124dc7","schema_version":"edge-lab-recorder.raw.v1","sequence":null,"source":"clob_market_ws"}
{"event_at":"2026-07-28T02:57:06.760000Z","event_fingerprint":"500e928af98738fe930f313adf3eccbfdbb6bcc1ead28d4f6dcf246be38460d9","payload":{"connection_id":"955646bd8bf740759faf38750c0f263f","event_at":"2026-07-28T02:57:06.760000Z","event_type":"price_change","frame_hash":"7ceec24fa90d7523e4ab82f7c8f0546904334329cf9fa2770bfbe2421ff4e065","frame_index":0,"kind":"data","monotonic_ns":309409737287916,"payload":{"event_type":"price_change","market":"0x0f70d07969bc69eaa97d0987de651885fdca02263688026aa11e7678af8f87aa","price_changes":[{"asset_id":"58313761654877669244690227616056238030136603415514645252000528337391143520538","best_ask":"0.41","best_bid":"0.4","hash":"963adabc05ae9497750af1e87f2ed55d5e60540f","price":"0.4","side":"BUY","size":"160.26"},{"asset_id":"64053005904884194822931764831592250494815136296598204104072528088122126148949","best_ask":"0.6","best_bid":"0.59","hash":"a616ebf8fd4d121bf3ee1299b01e0bd8ed9b5fef","price":"0.6","side":"SELL","size":"160.26"}],"timestamp":"1785207426760"},"payload_hash":"e15b4ad860696f6a8542ded5dff60de7c1ac7c594aa7ed0ed3bea87d6e4a2cef","raw_frame":"{\"market\":\"0x0f70d07969bc69eaa97d0987de651885fdca02263688026aa11e7678af8f87aa\", \"price_changes\":[{\"asset_id\":\"58313761654877669244690227616056238030136603415514645252000528337391143520538\", \"price\":\"0.4\", \"size\":\"160.26\", \"side\":\"BUY\", \"hash\":\"963adabc05ae9497750af1e87f2ed55d5e60540f\", \"best_bid\":\"0.4\", \"best_ask\":\"0.41\"}, {\"asset_id\":\"64053005904884194822931764831592250494815136296598204104072528088122126148949\", \"price\":\"0.6\", \"size\":\"160.26\", \"side\":\"SELL\", \"hash\":\"a616ebf8fd4d121bf3ee1299b01e0bd8ed9b5fef\", \"best_bid\":\"0.59\", \"best_ask\":\"0.6\"}], \"timestamp\":\"1785207426760\", \"event_type\":\"price_change\"}","received_at":"2026-07-28T02:57:06.720175Z","schema_version":"clob-market-ws.price_change.v1","sequence":null,"server_hash":null,"server_timestamp":"1785207426760","session_id":"5aad79be415c487c84df42bebd84ee93","source":"clob_market_ws"},"received_at":"2026-07-28T02:57:06.720175Z","record_id":"ca0d575a67f1429ed2cc3a1419fb28ff9c91bba0642107558b610bdcef8a44e8","schema_fingerprint":"4aa3821a28b0b7c2400bc59aba4bcc0a76e971dadd19610d3ad38c768e124dc7","schema_version":"edge-lab-recorder.raw.v1","sequence":null,"source":"clob_market_ws"}
{"event_at":"2026-07-28T02:57:06.761000Z","event_fingerprint":"985d1f8351e3b56e5f6057c93f9f72c462c6755dc913834fe7694b0dd6d32ca8","payload":{"connection_id":"955646bd8bf740759faf38750c0f263f","event_at":"2026-07-28T02:57:06.761000Z","event_type":"price_change","frame_hash":"adba6beed7215c08341efcce1043d0127e059f8fcfe6e6f79894dd1258a4f008","frame_index":0,"kind":"data","monotonic_ns":309409738751291,"payload":{"event_type":"price_change","market":"0x0f70d07969bc69eaa97d0987de651885fdca02263688026aa11e7678af8f87aa","price_changes":[{"asset_id":"64053005904884194822931764831592250494815136296598204104072528088122126148949","best_ask":"0.6","best_bid":"0.59","hash":"5c0278641ef546477353c3046a1c60cf5526031b","price":"0.52","side":"BUY","size":"163.35"},{"asset_id":"58313761654877669244690227616056238030136603415514645252000528337391143520538","best_ask":"0.41","best_bid":"0.4","hash":"4dcbcdc1fdbbb0d3c8a16bce34babbd8708c65c1","price":"0.48","side":"SELL","size":"163.35"}],"timestamp":"1785207426761"},"payload_hash":"741c50075ffe9d807387c4a848acc47d48b33202f13bef05b3aee5ded5009870","raw_frame":"{\"market\":\"0x0f70d07969bc69eaa97d0987de651885fdca02263688026aa11e7678af8f87aa\", \"price_changes\":[{\"asset_id\":\"64053005904884194822931764831592250494815136296598204104072528088122126148949\", \"price\":\"0.52\", \"size\":\"163.35\", \"side\":\"BUY\", \"hash\":\"5c0278641ef546477353c3046a1c60cf5526031b\", \"best_bid\":\"0.59\", \"best_ask\":\"0.6\"}, {\"asset_id\":\"58313761654877669244690227616056238030136603415514645252000528337391143520538\", \"price\":\"0.48\", \"size\":\"163.35\", \"side\":\"SELL\", \"hash\":\"4dcbcdc1fdbbb0d3c8a16bce34babbd8708c65c1\", \"best_bid\":\"0.4\", \"best_ask\":\"0.41\"}], \"timestamp\":\"1785207426761\", \"event_type\":\"price_change\"}","received_at":"2026-07-28T02:57:06.721640Z","schema_version":"clob-market-ws.price_change.v1","sequence":null,"server_hash":null,"server_timestamp":"1785207426761","session_id":"5aad79be415c487c84df42bebd84ee93","source":"clob_market_ws"},"received_at":"2026-07-28T02:57:06.721640Z","record_id":"491e4519542907e6013740c206aaf92159594bd426e20026d53cefd3deba29f1","schema_fingerprint":"4aa3821a28b0b7c2400bc59aba4bcc0a76e971dadd19610d3ad38c768e124dc7","schema_version":"edge-lab-recorder.raw.v1","sequence":null,"source":"clob_market_ws"}
{"event_at":"2026-07-28T02:57:06.762000Z","event_fingerprint":"a26c135caa04a40dfa967bc051521aef74ca5309d8a2179d0153feb40a983960","payload":{"connection_id":"955646bd8bf740759faf38750c0f263f","event_at":"2026-07-28T02:57:06.762000Z","event_type":"price_change","frame_hash":"512474e99daf4814d414d512887012cc84d6f15ec209dfe6b8570c853b6b4a2e","frame_index":0,"kind":"data","monotonic_ns":309409740277625,"payload":{"event_type":"price_change","market":"0x0f70d07969bc69eaa97d0987de651885fdca02263688026aa11e7678af8f87aa","price_changes":[{"asset_id":"58313761654877669244690227616056238030136603415514645252000528337391143520538","best_ask":"0.41","best_bid":"0.4","hash":"74747e49c4ce8c977904623b9082e4cdc6a4b94c","price":"0.39","side":"BUY","size":"84.28"},{"asset_id":"64053005904884194822931764831592250494815136296598204104072528088122126148949","best_ask":"0.6","best_bid":"0.59","hash":"92ca94fb46fca812ac221f325c7cbfd2298ea6f6","price":"0.61","side":"SELL","size":"84.28"}],"timestamp":"1785207426762"},"payload_hash":"a424c7dbd33a3d3fa6919a2ab58fe6bd2e24569c983ce5dfa6321bc77821c838","raw_frame":"{\"market\":\"0x0f70d07969bc69eaa97d0987de651885fdca02263688026aa11e7678af8f87aa\", \"price_changes\":[{\"asset_id\":\"58313761654877669244690227616056238030136603415514645252000528337391143520538\", \"price\":\"0.39\", \"size\":\"84.28\", \"side\":\"BUY\", \"hash\":\"74747e49c4ce8c977904623b9082e4cdc6a4b94c\", \"best_bid\":\"0.4\", \"best_ask\":\"0.41\"}, {\"asset_id\":\"64053005904884194822931764831592250494815136296598204104072528088122126148949\", \"price\":\"0.61\", \"size\":\"84.28\", \"side\":\"SELL\", \"hash\":\"92ca94fb46fca812ac221f325c7cbfd2298ea6f6\", \"best_bid\":\"0.59\", \"best_ask\":\"0.6\"}], \"timestamp\":\"1785207426762\", \"event_type\":\"price_change\"}","received_at":"2026-07-28T02:57:06.723164Z","schema_version":"clob-market-ws.price_change.v1","sequence":null,"server_hash":null,"server_timestamp":"1785207426762","session_id":"5aad79be415c487c84df42bebd84ee93","source":"clob_market_ws"},"received_at":"2026-07-28T02:57:06.723164Z","record_id":"d1887f5331df29452c965703e6de2099b3686edbf96ad707ef41938fda48a3b6","schema_fingerprint":"4aa3821a28b0b7c2400bc59aba4bcc0a76e971dadd19610d3ad38c768e124dc7","schema_version":"edge-lab-recorder.raw.v1","sequence":null,"source":"clob_market_ws"}
{"event_at":"2026-07-28T02:57:06.763000Z","event_fingerprint":"129017937724b372b3e18afd59f42e31385cf045a03e4e84facb2aeae8fba614","payload":{"connection_id":"955646bd8bf740759faf38750c0f263f","event_at":"2026-07-28T02:57:06.763000Z","event_type":"price_change","frame_hash":"8207145f248453b259fff70e1c242e58ea70c3c33c340094e10fc3a982d8bbcd","frame_index":0,"kind":"data","monotonic_ns":309409741774833,"payload":{"event_type":"price_change","market":"0x0f70d07969bc69eaa97d0987de651885fdca02263688026aa11e7678af8f87aa","price_changes":[{"asset_id":"64053005904884194822931764831592250494815136296598204104072528088122126148949","best_ask":"0.6","best_bid":"0.59","hash":"7acce71a660ccc0bd87181843792a43e1f17ef88","price":"0.52","side":"BUY","size":"178.35"},{"asset_id":"58313761654877669244690227616056238030136603415514645252000528337391143520538","best_ask":"0.41","best_bid":"0.4","hash":"f9c5a1faa6d4bfe0aa1337a0868194bd50b7e965","price":"0.48","side":"SELL","size":"178.35"}],"timestamp":"1785207426763"},"payload_hash":"1ad38cdf5f7c105d8a1e0ecf3d4d884c9bbe16b309d126962c039dd52cb2ad0f","raw_frame":"{\"market\":\"0x0f70d07969bc69eaa97d0987de651885fdca02263688026aa11e7678af8f87aa\", \"price_changes\":[{\"asset_id\":\"64053005904884194822931764831592250494815136296598204104072528088122126148949\", \"price\":\"0.52\", \"size\":\"178.35\", \"side\":\"BUY\", \"hash\":\"7acce71a660ccc0bd87181843792a43e1f17ef88\", \"best_bid\":\"0.59\", \"best_ask\":\"0.6\"}, {\"asset_id\":\"58313761654877669244690227616056238030136603415514645252000528337391143520538\", \"price\":\"0.48\", \"size\":\"178.35\", \"side\":\"SELL\", \"hash\":\"f9c5a1faa6d4bfe0aa1337a0868194bd50b7e965\", \"best_bid\":\"0.4\", \"best_ask\":\"0.41\"}], \"timestamp\":\"1785207426763\", \"event_type\":\"price_change\"}","received_at":"2026-07-28T02:57:06.724663Z","schema_version":"clob-market-ws.price_change.v1","sequence":null,"server_hash":null,"server_timestamp":"1785207426763","session_id":"5aad79be415c487c84df42bebd84ee93","source":"clob_market_ws"},"received_at":"2026-07-28T02:57:06.724663Z","record_id":"f8ed964c9e0c0fc552a19e087c0a5cb4f27c83419e9c81df24c206105de71051","schema_fingerprint":"4aa3821a28b0b7c2400bc59aba4bcc0a76e971dadd19610d3ad38c768e124dc7","schema_version":"edge-lab-recorder.raw.v1","sequence":null,"source":"clob_market_ws"}
{"event_at":"2026-07-28T02:57:06.770000Z","event_fingerprint":"c472acd56b9d3ec2996b5df5a03e5bbc7e7239c662e37099a63fd301fd66ad8c","payload":{"connection_id":"955646bd8bf740759faf38750c0f263f","event_at":"2026-07-28T02:57:06.770000Z","event_type":"price_change","frame_hash":"0415616e3cb2ac467b4421e7e4e9dd7e05b6aa6d72ae206576a67d4a50e41501","frame_index":0,"kind":"data","monotonic_ns":309409743246208,"payload":{"event_type":"price_change","market":"0x0f70d07969bc69eaa97d0987de651885fdca02263688026aa11e7678af8f87aa","price_changes":[{"asset_id":"64053005904884194822931764831592250494815136296598204104072528088122126148949","best_ask":"0.6","best_bid":"0.59","hash":"7825fac28e0dc1ef3178a87f5ccc19777fb444c8","price":"0.47","side":"BUY","size":"58.7"},{"asset_id":"58313761654877669244690227616056238030136603415514645252000528337391143520538","best_ask":"0.41","best_bid":"0.4","hash":"e66a681162bdfd6744e6a4915b57782185212928","price":"0.53","side":"SELL","size":"58.7"}],"timestamp":"1785207426770"},"payload_hash":"704ddac536d73670abf63cb7d984d4b6aa46393e953533feeff76df36895b489","raw_frame":"{\"market\":\"0x0f70d07969bc69eaa97d0987de651885fdca02263688026aa11e7678af8f87aa\", \"price_changes\":[{\"asset_id\":\"64053005904884194822931764831592250494815136296598204104072528088122126148949\", \"price\":\"0.47\", \"size\":\"58.7\", \"side\":\"BUY\", \"hash\":\"7825fac28e0dc1ef3178a87f5ccc19777fb444c8\", \"best_bid\":\"0.59\", \"best_ask\":\"0.6\"}, {\"asset_id\":\"58313761654877669244690227616056238030136603415514645252000528337391143520538\", \"price\":\"0.53\", \"size\":\"58.7\", \"side\":\"SELL\", \"hash\":\"e66a681162bdfd6744e6a4915b57782185212928\", \"best_bid\":\"0.4\", \"best_ask\":\"0.41\"}], \"timestamp\":\"1785207426770\", \"event_type\":\"price_change\"}","received_at":"2026-07-28T02:57:06.726134Z","schema_version":"clob-market-ws.price_change.v1","sequence":null,"server_hash":null,"server_timestamp":"1785207426770","session_id":"5aad79be415c487c84df42bebd84ee93","source":"clob_market_ws"},"received_at":"2026-07-28T02:57:06.726134Z","record_id":"0a40de399915ca9cfc286b579d318e5991a300807896179235742bbcb2da3bba","schema_fingerprint":"4aa3821a28b0b7c2400bc59aba4bcc0a76e971dadd19610d3ad38c768e124dc7","schema_version":"edge-lab-recorder.raw.v1","sequence":null,"source":"clob_market_ws"}
{"event_at":"2026-07-28T02:57:06.770000Z","event_fingerprint":"3bb64f7cecbc0a2dad00491b42b7c8a5885f8b978d3f4a1306391d513287c1b1","payload":{"connection_id":"955646bd8bf740759faf38750c0f263f","event_at":"2026-07-28T02:57:06.770000Z","event_type":"price_change","frame_hash":"039b5825314e238edac7d71d9fdc7cf320338853be88200e5cf9993f28233bad","frame_index":0,"kind":"data","monotonic_ns":309409744743458,"payload":{"event_type":"price_change","market":"0x0f70d07969bc69eaa97d0987de651885fdca02263688026aa11e7678af8f87aa","price_changes":[{"asset_id":"64053005904884194822931764831592250494815136296598204104072528088122126148949","best_ask":"0.6","best_bid":"0.59","hash":"7825fac28e0dc1ef3178a87f5ccc19777fb444c8","price":"0.49","side":"BUY","size":"126.31"},{"asset_id":"58313761654877669244690227616056238030136603415514645252000528337391143520538","best_ask":"0.41","best_bid":"0.4","hash":"e66a681162bdfd6744e6a4915b57782185212928","price":"0.51","side":"SELL","size":"126.31"}],"timestamp":"1785207426770"},"payload_hash":"604971b0b9624cae9b1787c9fed0649560bfbf2dda22349ea0518528710f2686","raw_frame":"{\"market\":\"0x0f70d07969bc69eaa97d0987de651885fdca02263688026aa11e7678af8f87aa\", \"price_changes\":[{\"asset_id\":\"64053005904884194822931764831592250494815136296598204104072528088122126148949\", \"price\":\"0.49\", \"size\":\"126.31\", \"side\":\"BUY\", \"hash\":\"7825fac28e0dc1ef3178a87f5ccc19777fb444c8\", \"best_bid\":\"0.59\", \"best_ask\":\"0.6\"}, {\"asset_id\":\"58313761654877669244690227616056238030136603415514645252000528337391143520538\", \"price\":\"0.51\", \"size\":\"126.31\", \"side\":\"SELL\", \"hash\":\"e66a681162bdfd6744e6a4915b57782185212928\", \"best_bid\":\"0.4\", \"best_ask\":\"0.41\"}], \"timestamp\":\"1785207426770\", \"event_type\":\"price_change\"}","received_at":"2026-07-28T02:57:06.727631Z","schema_version":"clob-market-ws.price_change.v1","sequence":null,"server_hash":null,"server_timestamp":"1785207426770","session_id":"5aad79be415c487c84df42bebd84ee93","source":"clob_market_ws"},"received_at":"2026-07-28T02:57:06.727631Z","record_id":"e46acf50cce5227a1b2c612b054c7a22ca0baf7cafe8a36b0749c63d91949e36","schema_fingerprint":"4aa3821a28b0b7c2400bc59aba4bcc0a76e971dadd19610d3ad38c768e124dc7","schema_version":"edge-lab-recorder.raw.v1","sequence":null,"source":"clob_market_ws"}
{"event_at":"2026-07-28T02:57:06.770000Z","event_fingerprint":"3a2fa82e6bc496c57ef2bd911e774ff5ff693fcbf57111d9fe49fc59c1a650ca","payload":{"connection_id":"955646bd8bf740759faf38750c0f263f","event_at":"2026-07-28T02:57:06.770000Z","event_type":"price_change","frame_hash":"dce84e34048bd99d9deb0f843b47b2a2cbb5de8d8111713fb7f1fb10f3209e71","frame_index":0,"kind":"data","monotonic_ns":309409746209041,"payload":{"event_type":"price_change","market":"0x0f70d07969bc69eaa97d0987de651885fdca02263688026aa11e7678af8f87aa","price_changes":[{"asset_id":"64053005904884194822931764831592250494815136296598204104072528088122126148949","best_ask":"0.6","best_bid":"0.59","hash":"7825fac28e0dc1ef3178a87f5ccc19777fb444c8","price":"0.5","side":"BUY","size":"112.04"},{"asset_id":"58313761654877669244690227616056238030136603415514645252000528337391143520538","best_ask":"0.41","best_bid":"0.4","hash":"e66a681162bdfd6744e6a4915b57782185212928","price":"0.5","side":"SELL","size":"112.04"}],"timestamp":"1785207426770"},"payload_hash":"e48735b83b358e5f096648c0846d917d0ebabf6bb36f2838e64c0f0019ed12ba","raw_frame":"{\"market\":\"0x0f70d07969bc69eaa97d0987de651885fdca02263688026aa11e7678af8f87aa\", \"price_changes\":[{\"asset_id\":\"64053005904884194822931764831592250494815136296598204104072528088122126148949\", \"price\":\"0.5\", \"size\":\"112.04\", \"side\":\"BUY\", \"hash\":\"7825fac28e0dc1ef3178a87f5ccc19777fb444c8\", \"best_bid\":\"0.59\", \"best_ask\":\"0.6\"}, {\"asset_id\":\"58313761654877669244690227616056238030136603415514645252000528337391143520538\", \"price\":\"0.5\", \"size\":\"112.04\", \"side\":\"SELL\", \"hash\":\"e66a681162bdfd6744e6a4915b57782185212928\", \"best_bid\":\"0.4\", \"best_ask\":\"0.41\"}], \"timestamp\":\"1785207426770\", \"event_type\":\"price_change\"}","received_at":"2026-07-28T02:57:06.729097Z","schema_version":"clob-market-ws.price_change.v1","sequence":null,"server_hash":null,"server_timestamp":"1785207426770","session_id":"5aad79be415c487c84df42bebd84ee93","source":"clob_market_ws"},"received_at":"2026-07-28T02:57:06.729097Z","record_id":"9bde438041835fdf99080dcd3d52c77a66a6b0f4148da3fd937eac2ffaef933e","schema_fingerprint":"4aa3821a28b0b7c2400bc59aba4bcc0a76e971dadd19610d3ad38c768e124dc7","schema_version":"edge-lab-recorder.raw.v1","sequence":null,"source":"clob_market_ws"}
{"event_at":"2026-07-28T02:57:06.770000Z","event_fingerprint":"5d09218f89a644b7c33f8d21c70866d592739722d1ca6291c598aa3f4c9ac544","payload":{"connection_id":"955646bd8bf740759faf38750c0f263f","event_at":"2026-07-28T02:57:06.770000Z","event_type":"price_change","frame_hash":"a5a6a2bbbcd6bd1646c466d2bf2d3a02638cf72c35debe6dfd3dc1fc3556236e","frame_index":0,"kind":"data","monotonic_ns":309409747658333,"payload":{"event_type":"price_change","market":"0x0f70d07969bc69eaa97d0987de651885fdca02263688026aa11e7678af8f87aa","price_changes":[{"asset_id":"58313761654877669244690227616056238030136603415514645252000528337391143520538","best_ask":"0.41","best_bid":"0.4","hash":"e66a681162bdfd6744e6a4915b57782185212928","price":"0.24","side":"BUY","size":"209.6"},{"asset_id":"64053005904884194822931764831592250494815136296598204104072528088122126148949","best_ask":"0.6","best_bid":"0.59","hash":"7825fac28e0dc1ef3178a87f5ccc19777fb444c8","price":"0.76","side":"SELL","size":"209.6"}],"timestamp":"1785207426770"},"payload_hash":"b20caa8c5b65ab9f49f08d4dd0d8caedb91d42a9436e46dfb8d6c591e30d742f","raw_frame":"{\"market\":\"0x0f70d07969bc69eaa97d0987de651885fdca02263688026aa11e7678af8f87aa\", \"price_changes\":[{\"asset_id\":\"58313761654877669244690227616056238030136603415514645252000528337391143520538\", \"price\":\"0.24\", \"size\":\"209.6\", \"side\":\"BUY\", \"hash\":\"e66a681162bdfd6744e6a4915b57782185212928\", \"best_bid\":\"0.4\", \"best_ask\":\"0.41\"}, {\"asset_id\":\"64053005904884194822931764831592250494815136296598204104072528088122126148949\", \"price\":\"0.76\", \"size\":\"209.6\", \"side\":\"SELL\", \"hash\":\"7825fac28e0dc1ef3178a87f5ccc19777fb444c8\", \"best_bid\":\"0.59\", \"best_ask\":\"0.6\"}], \"timestamp\":\"1785207426770\", \"event_type\":\"price_change\"}","received_at":"2026-07-28T02:57:06.730546Z","schema_version":"clob-market-ws.price_change.v1","sequence":null,"server_hash":null,"server_timestamp":"1785207426770","session_id":"5aad79be415c487c84df42bebd84ee93","source":"clob_market_ws"},"received_at":"2026-07-28T02:57:06.730546Z","record_id":"602c16f4dd7cd098a19d6d1d3eecfc49f373ed41d6d6d73c48af00ce5eebd5c2","schema_fingerprint":"4aa3821a28b0b7c2400bc59aba4bcc0a76e971dadd19610d3ad38c768e124dc7","schema_version":"edge-lab-recorder.raw.v1","sequence":null,"source":"clob_market_ws"}
{"event_at":"2026-07-28T02:57:06.770000Z","event_fingerprint":"9b761e383ef35a1cc4504ca2331aebbda98e70da518fe033b9b66695b2506e6e","payload":{"connection_id":"955646bd8bf740759faf38750c0f263f","event_at":"2026-07-28T02:57:06.770000Z","event_type":"price_change","frame_hash":"3835e0d81b86eaf1d1b4b0b80b5de3ee867632694f110c5a02fecfe80e9cb545","frame_index":0,"kind":"data","monotonic_ns":309409749101041,"payload":{"event_type":"price_change","market":"0x0f70d07969bc69eaa97d0987de651885fdca02263688026aa11e7678af8f87aa","price_changes":[{"asset_id":"58313761654877669244690227616056238030136603415514645252000528337391143520538","best_ask":"0.41","best_bid":"0.4","hash":"e66a681162bdfd6744e6a4915b57782185212928","price":"0.23","side":"BUY","size":"195.3"},{"asset_id":"64053005904884194822931764831592250494815136296598204104072528088122126148949","best_ask":"0.6","best_bid":"0.59","hash":"7825fac28e0dc1ef3178a87f5ccc19777fb444c8","price":"0.77","side":"SELL","size":"195.3"}],"timestamp":"1785207426770"},"payload_hash":"52be4bbb1e24784e3faa874d16607bc0e465f0dcd086f0497ab302eee7957f45","raw_frame":"{\"market\":\"0x0f70d07969bc69eaa97d0987de651885fdca02263688026aa11e7678af8f87aa\", \"price_changes\":[{\"asset_id\":\"58313761654877669244690227616056238030136603415514645252000528337391143520538\", \"price\":\"0.23\", \"size\":\"195.3\", \"side\":\"BUY\", \"hash\":\"e66a681162bdfd6744e6a4915b57782185212928\", \"best_bid\":\"0.4\", \"best_ask\":\"0.41\"}, {\"asset_id\":\"64053005904884194822931764831592250494815136296598204104072528088122126148949\", \"price\":\"0.77\", \"size\":\"195.3\", \"side\":\"SELL\", \"hash\":\"7825fac28e0dc1ef3178a87f5ccc19777fb444c8\", \"best_bid\":\"0.59\", \"best_ask\":\"0.6\"}], \"timestamp\":\"1785207426770\", \"event_type\":\"price_change\"}","received_at":"2026-07-28T02:57:06.731989Z","schema_version":"clob-market-ws.price_change.v1","sequence":null,"server_hash":null,"server_timestamp":"1785207426770","session_id":"5aad79be415c487c84df42bebd84ee93","source":"clob_market_ws"},"received_at":"2026-07-28T02:57:06.731989Z","record_id":"788c14d2ee7436e9b72d3fcd9e37557c4718fb33c7bcf6b338a1f008e75f5629","schema_fingerprint":"4aa3821a28b0b7c2400bc59aba4bcc0a76e971dadd19610d3ad38c768e124dc7","schema_version":"edge-lab-recorder.raw.v1","sequence":null,"source":"clob_market_ws"}
{"event_at":"2026-07-28T02:57:06.770000Z","event_fingerprint":"179e799513193191b069a989ac8422f3c6a92486530e8ab21b7f7903d39715e5","payload":{"connection_id":"955646bd8bf740759faf38750c0f263f","event_at":"2026-07-28T02:57:06.770000Z","event_type":"price_change","frame_hash":"f7141ce17e1056eb3eb02e5cd3ac8fb1bab46cc02c394eeb20873b4e6e2fbd83","frame_index":0,"kind":"data","monotonic_ns":309409750566666,"payload":{"event_type":"price_change","market":"0x0f70d07969bc69eaa97d0987de651885fdca02263688026aa11e7678af8f87aa","price_changes":[{"asset_id":"58313761654877669244690227616056238030136603415514645252000528337391143520538","best_ask":"0.41","best_bid":"0.4","hash":"e66a681162bdfd6744e6a4915b57782185212928","price":"0.22","side":"BUY","size":"191.2"},{"asset_id":"64053005904884194822931764831592250494815136296598204104072528088122126148949","best_ask":"0.6","best_bid":"0.59","hash":"7825fac28e0dc1ef3178a87f5ccc19777fb444c8","price":"0.78","side":"SELL","size":"191.2"}],"timestamp":"1785207426770"},"payload_hash":"4637a3ae25a581dd947e42ed4be10a11793c2a9eb3ef6e69884a85da36f9d3ae","raw_frame":"{\"market\":\"0x0f70d07969bc69eaa97d0987de651885fdca02263688026aa11e7678af8f87aa\", \"price_changes\":[{\"asset_id\":\"58313761654877669244690227616056238030136603415514645252000528337391143520538\", \"price\":\"0.22\", \"size\":\"191.2\", \"side\":\"BUY\", \"hash\":\"e66a681162bdfd6744e6a4915b57782185212928\", \"best_bid\":\"0.4\", \"best_ask\":\"0.41\"}, {\"asset_id\":\"64053005904884194822931764831592250494815136296598204104072528088122126148949\", \"price\":\"0.78\", \"size\":\"191.2\", \"side\":\"SELL\", \"hash\":\"7825fac28e0dc1ef3178a87f5ccc19777fb444c8\", \"best_bid\":\"0.59\", \"best_ask\":\"0.6\"}], \"timestamp\":\"1785207426770\", \"event_type\":\"price_change\"}","received_at":"2026-07-28T02:57:06.733455Z","schema_version":"clob-market-ws.price_change.v1","sequence":null,"server_hash":null,"server_timestamp":"1785207426770","session_id":"5aad79be415c487c84df42bebd84ee93","source":"clob_market_ws"},"received_at":"2026-07-28T02:57:06.733455Z","record_id":"15ef19e8d8f2b7250b013e1605b27e8916a6d313717f6b4624c08d498a87702b","schema_fingerprint":"4aa3821a28b0b7c2400bc59aba4bcc0a76e971dadd19610d3ad38c768e124dc7","schema_version":"edge-lab-recorder.raw.v1","sequence":null,"source":"clob_market_ws"}
{"event_at":"2026-07-28T02:57:06.775000Z","event_fingerprint":"aecf5038b7881cb1a7e1c2e6b955ade323d491c51180b5ee40a7d4572e9c40bf","payload":{"connection_id":"955646bd8bf740759faf38750c0f263f","event_at":"2026-07-28T02:57:06.775000Z","event_type":"price_change","frame_hash":"1db78fb9e6403fdff47842781a88ffc9a3afc8e21cdead358aa79abb7230bb04","frame_index":0,"kind":"data","monotonic_ns":309409752011416,"payload":{"event_type":"price_change","market":"0x0f70d07969bc69eaa97d0987de651885fdca02263688026aa11e7678af8f87aa","price_changes":[{"asset_id":"58313761654877669244690227616056238030136603415514645252000528337391143520538","best_ask":"0.41","best_bid":"0.4","hash":"a9678acb4d4d6fd180e906b96ad6a79474f9e7ef","price":"0.19","side":"BUY","size":"213.19"},{"asset_id":"64053005904884194822931764831592250494815136296598204104072528088122126148949","best_ask":"0.6","best_bid":"0.59","hash":"e96b240803ec2d15d7297324f0d4a8ddfde4b62a","price":"0.81","side":"SELL","size":"213.19"}],"timestamp":"1785207426775"},"payload_hash":"f88b43747c1119b4eb7151eb5b5867a6c88f2f51e095db8befc5b7431c00600b","raw_frame":"{\"market\":\"0x0f70d07969bc69eaa97d0987de651885fdca02263688026aa11e7678af8f87aa\", \"price_changes\":[{\"asset_id\":\"58313761654877669244690227616056238030136603415514645252000528337391143520538\", \"price\":\"0.19\", \"size\":\"213.19\", \"side\":\"BUY\", \"hash\":\"a9678acb4d4d6fd180e906b96ad6a79474f9e7ef\", \"best_bid\":\"0.4\", \"best_ask\":\"0.41\"}, {\"asset_id\":\"64053005904884194822931764831592250494815136296598204104072528088122126148949\", \"price\":\"0.81\", \"size\":\"213.19\", \"side\":\"SELL\", \"hash\":\"e96b240803ec2d15d7297324f0d4a8ddfde4b62a\", \"best_bid\":\"0.59\", \"best_ask\":\"0.6\"}], \"timestamp\":\"1785207426775\", \"event_type\":\"price_change\"}","received_at":"2026-07-28T02:57:06.734899Z","schema_version":"clob-market-ws.price_change.v1","sequence":null,"server_hash":null,"server_timestamp":"1785207426775","session_id":"5aad79be415c487c84df42bebd84ee93","source":"clob_market_ws"},"received_at":"2026-07-28T02:57:06.734899Z","record_id":"a4e0b1fb226c621c2e9e80fa16e28af8a4f31fb240a6cfb18560a8189301d0f4","schema_fingerprint":"4aa3821a28b0b7c2400bc59aba4bcc0a76e971dadd19610d3ad38c768e124dc7","schema_version":"edge-lab-recorder.raw.v1","sequence":null,"source":"clob_market_ws"}
