{"event_at":"2026-07-28T02:57:26.932000Z","event_fingerprint":"305443c3bcc7d9f26de79039edbb088deadd0830c69d9cf1f9850770290e3fa4","payload":{"connection_id":"955646bd8bf740759faf38750c0f263f","event_at":"2026-07-28T02:57:26.932000Z","event_type":"price_change","frame_hash":"ff52db33debf1e8bf55f44ec21bcd3204925d3031b2a2f4a60943a7dd5c4a6b9","frame_index":0,"kind":"data","monotonic_ns":309430291895375,"payload":{"event_type":"price_change","market":"0x0f70d07969bc69eaa97d0987de651885fdca02263688026aa11e7678af8f87aa","price_changes":[{"asset_id":"64053005904884194822931764831592250494815136296598204104072528088122126148949","best_ask":"0.53","best_bid":"0.52","hash":"5df9b4abf5768a6864124ab0abcea070e48425c2","price":"0.51","side":"BUY","size":"251.1"},{"asset_id":"58313761654877669244690227616056238030136603415514645252000528337391143520538","best_ask":"0.48","best_bid":"0.47","hash":"682b777d0ddba6d7488431470d145644acd5c612","price":"0.49","side":"SELL","size":"251.1"}],"timestamp":"1785207446932"},"payload_hash":"1a3ce7a3c3513a3d8e2d43f0818d52ef06022c46231a7a46cbd464dbf5876490","raw_frame":"{\"market\":\"0x0f70d07969bc69eaa97d0987de651885fdca02263688026aa11e7678af8f87aa\", \"price_changes\":[{\"asset_id\":\"64053005904884194822931764831592250494815136296598204104072528088122126148949\", \"price\":\"0.51\", \"size\":\"251.1\", \"side\":\"BUY\", \"hash\":\"5df9b4abf5768a6864124ab0abcea070e48425c2\", \"best_bid\":\"0.52\", \"best_ask\":\"0.53\"}, {\"asset_id\":\"58313761654877669244690227616056238030136603415514645252000528337391143520538\", \"price\":\"0.49\", \"size\":\"251.1\", \"side\":\"SELL\", \"hash\":\"682b777d0ddba6d7488431470d145644acd5c612\", \"best_bid\":\"0.47\", \"best_ask\":\"0.48\"}], \"timestamp\":\"1785207446932\", \"event_type\":\"price_change\"}","received_at":"2026-07-28T02:57:27.274634Z","schema_version":"clob-market-ws.price_change.v1","sequence":null,"server_hash":null,"server_timestamp":"1785207446932","session_id":"5aad79be415c487c84df42bebd84ee93","source":"clob_market_ws"},"received_at":"2026-07-28T02:57:27.274634Z","record_id":"f42c7ce68ca9c62777704ecd215a1d4783c8a19ccc375f8eae9a2bc4b3546f04","schema_fingerprint":"4aa3821a28b0b7c2400bc59aba4bcc0a76e971dadd19610d3ad38c768e124dc7","schema_version":"edge-lab-recorder.raw.v1","sequence":null,"source":"clob_market_ws"}
{"event_at":"2026-07-28T02:57:26.937000Z","event_fingerprint":"cdf18e88279dcec198697883ed9c8b680a542ec9c8d6e579758104d58d4ce206","payload":{"connection_id":"955646bd8bf740759faf38750c0f263f","event_at":"2026-07-28T02:57:26.937000Z","event_type":"price_change","frame_hash":"0f9c7df654e161c292096a24a295f7e0bf9337831dd51d98f923eff94d02fdc1","frame_index":0,"kind":"data","monotonic_ns":309430293981583,"payload":{"event_type":"price_change","market":"0x0f70d07969bc69eaa97d0987de651885fdca02263688026aa11e7678af8f87aa","price_changes":[{"asset_id":"64053005904884194822931764831592250494815136296598204104072528088122126148949","best_ask":"0.53","best_bid":"0.52","hash":"bb963d6a34e661ffa14f89ad3d94c94689d234b1","price":"0.48","side":"BUY","size":"63.49"},{"asset_id":"58313761654877669244690227616056238030136603415514645252000528337391143520538","best_ask":"0.48","best_bid":"0.47","hash":"c4c23134abde57b6e50bff14963f703440fbb007","price":"0.52","side":"SELL","size":"63.49"}],"timestamp":"1785207446937"},"payload_hash":"8fbda08b74ba4e0bebd1d0aecc2f4b3e4c10d5c68c9b0a3ec2dc9b3732bb9502","raw_frame":"{\"market\":\"0x0f70d07969bc69eaa97d0987de651885fdca02263688026aa11e7678af8f87aa\", \"price_changes\":[{\"asset_id\":\"64053005904884194822931764831592250494815136296598204104072528088122126148949\", \"price\":\"0.48\", \"size\":\"63.49\", \"side\":\"BUY\", \"hash\":\"bb963d6a34e661ffa14f89ad3d94c94689d234b1\", \"best_bid\":\"0.52\", \"best_ask\":\"0.53\"}, {\"asset_id\":\"58313761654877669244690227616056238030136603415514645252000528337391143520538\", \"price\":\"0.52\", \"size\":\"63.49\", \"side\":\"SELL\", \"hash\":\"c4c23134abde57b6e50bff14963f703440fbb007\", \"best_bid\":\"0.47\", \"best_ask\":\"0.48\"}], \"timestamp\":\"1785207446937\", \"event_type\":\"price_change\"}","received_at":"2026-07-28T02:57:27.276719Z","schema_version":"clob-market-ws.price_change.v1","sequence":null,"server_hash":null,"server_timestamp":"1785207446937","session_id":"5aad79be415c487c84df42bebd84ee93","source":"clob_market_ws"},"received_at":"2026-07-28T02:57:27.276719Z","record_id":"cd19050c2271d2cf2c6cc2635c987e2d144f92a6fd782780cc7bd669315e074e","schema_fingerprint":"4aa3821a28b0b7c2400bc59aba4bcc0a76e971dadd19610d3ad38c768e124dc7","schema_version":"edge-lab-recorder.raw.v1","sequence":null,"source":"clob_market_ws"}
{"event_at":"2026-07-28T02:57:26.952000Z","event_fingerprint":"b74f0f7fe41e75e163bb5cea36ffaec4693945032ef4a484366c70c3fe904fc0","payload":{"connection_id":"955646bd8bf740759faf38750c0f263f","event_at":"2026-07-28T02:57:26.952000Z","event_type":"price_change","frame_hash":"204c2fe3b797d1d1e74e58ba997bf4c4a2fb6cfeb1087d4dd7d4c12bee97b283","frame_index":0,"kind":"data","monotonic_ns":309430295500291,"payload":{"event_type":"price_change","market":"0x0f70d07969bc69eaa97d0987de651885fdca02263688026aa11e7678af8f87aa","price_changes":[{"asset_id":"58313761654877669244690227616056238030136603415514645252000528337391143520538","best_ask":"0.48","best_bid":"0.47","hash":"45a26e6f6f623924ccc7a992b2bddb4aeba9ece6","price":"0.43","side":"BUY","size":"208.17"},{"asset_id":"64053005904884194822931764831592250494815136296598204104072528088122126148949","best_ask":"0.53","best_bid":"0.52","hash":"cd7594d624359f9b0cac7027148d07004b2dbff9","price":"0.57","side":"SELL","size":"208.17"}],"timestamp":"1785207446952"},"payload_hash":"600cce056835215be1e7218047686056dbcc78ac7f9dcb017e8cdefab2f63a19","raw_frame":"{\"market\":\"0x0f70d07969bc69eaa97d0987de651885fdca02263688026aa11e7678af8f87aa\", \"price_changes\":[{\"asset_id\":\"58313761654877669244690227616056238030136603415514645252000528337391143520538\", \"price\":\"0.43\", \"size\":\"208.17\", \"side\":\"BUY\", \"hash\":\"45a26e6f6f623924ccc7a992b2bddb4aeba9ece6\", \"best_bid\":\"0.47\", \"best_ask\":\"0.48\"}, {\"asset_id\":\"64053005904884194822931764831592250494815136296598204104072528088122126148949\", \"price\":\"0.57\", \"size\":\"208.17\", \"side\":\"SELL\", \"hash\":\"cd7594d624359f9b0cac7027148d07004b2dbff9\", \"best_bid\":\"0.52\", \"best_ask\":\"0.53\"}], \"timestamp\":\"1785207446952\", \"event_type\":\"price_change\"}","received_at":"2026-07-28T02:57:27.278240Z","schema_version":"clob-market-ws.price_change.v1","sequence":null,"server_hash":null,"server_timestamp":"1785207446952","session_id":"5aad79be415c487c84df42bebd84ee93","source":"clob_market_ws"},"received_at":"2026-07-28T02:57:27.278240Z","record_id":"0e97688a5780f3fb70376eb088214b471a343c0a72e4e37033fff403a1fb19c1","schema_fingerprint":"4aa3821a28b0b7c2400bc59aba4bcc0a76e971dadd19610d3ad38c768e124dc7","schema_version":"edge-lab-recorder.raw.v1","sequence":null,"source":"clob_market_ws"}
{"event_at":"2026-07-28T02:57:26.952000Z","event_fingerprint":"b9613db06bcabe55a0a7776afd35e7989a75fef8e4dc175ddc1b313fba1fc922","payload":{"connection_id":"955646bd8bf740759faf38750c0f263f","event_at":"2026-07-28T02:57:26.952000Z","event_type":"price_change","frame_hash":"56ff8521a6c35f98b70d50735862d4162fbc1d26fc1589b46cb15ecf41ddca4b","frame_index":0,"kind":"data","monotonic_ns":309430296980625,"payload":{"event_type":"price_change","market":"0x0f70d07969bc69eaa97d0987de651885fdca02263688026aa11e7678af8f87aa","price_changes":[{"asset_id":"58313761654877669244690227616056238030136603415514645252000528337391143520538","best_ask":"0.48","best_bid":"0.47","hash":"478fbd5511cdbdd72363ab3d487e02eeb8681c60","price":"0.44","side":"BUY","size":"259.31"},{"asset_id":"64053005904884194822931764831592250494815136296598204104072528088122126148949","best_ask":"0.53","best_bid":"0.52","hash":"ec748d08d66c7b29772aca6952d78cd328b5ed3e","price":"0.56","side":"SELL","size":"259.31"}],"timestamp":"1785207446952"},"payload_hash":"a5a5e5a6174c40ea77bb331680e9ef92aa711c9b58115b4209a98092030ba0c4","raw_frame":"{\"market\":\"0x0f70d07969bc69eaa97d0987de651885fdca02263688026aa11e7678af8f87aa\", \"price_changes\":[{\"asset_id\":\"58313761654877669244690227616056238030136603415514645252000528337391143520538\", \"price\":\"0.44\", \"size\":\"259.31\", \"side\":\"BUY\", \"hash\":\"478fbd5511cdbdd72363ab3d487e02eeb8681c60\", \"best_bid\":\"0.47\", \"best_ask\":\"0.48\"}, {\"asset_id\":\"64053005904884194822931764831592250494815136296598204104072528088122126148949\", \"price\":\"0.56\", \"size\":\"259.31\", \"side\":\"SELL\", \"hash\":\"ec748d08d66c7b29772aca6952d78cd328b5ed3e\", \"best_bid\":\"0.52\", \"best_ask\":\"0.53\"}], \"timestamp\":\"1785207446952\", \"event_type\":\"price_change\"}","received_at":"2026-07-28T02:57:27.279720Z","schema_version":"clob-market-ws.price_change.v1","sequence":null,"server_hash":null,"server_timestamp":"1785207446952","session_id":"5aad79be415c487c84df42bebd84ee93","source":"clob_market_ws"},"received_at":"2026-07-28T02:57:27.279720Z","record_id":"a6f3bbfe03ffd99f88f233e73f17df1b707f2f2535063b4277fc92cad1be1366","schema_fingerprint":"4aa3821a28b0b7c2400bc59aba4bcc0a76e971dadd19610d3ad38c768e124dc7","schema_version":"edge-lab-recorder.raw.v1","sequence":null,"source":"clob_market_ws"}
{"event_at":"2026-07-28T02:57:26.958000Z","event_fingerprint":"e3e07ca807d1ff904a3487825b254125500f2dca82575f3c8ae064aae39d32f2","payload":{"connection_id":"955646bd8bf740759faf38750c0f263f","event_at":"2026-07-28T02:57:26.958000Z","event_type":"price_change","frame_hash":"19655db534395f0eadc2d314121f9d086fe49c2da9ec01974805dc9f56d961ad","frame_index":0,"kind":"data","monotonic_ns":309430298441250,"payload":{"event_type":"price_change","market":"0x0f70d07969bc69eaa97d0987de651885fdca02263688026aa11e7678af8f87aa","price_changes":[{"asset_id":"64053005904884194822931764831592250494815136296598204104072528088122126148949","best_ask":"0.53","best_bid":"0.52","hash":"8d9c577e7be19b225565fc565f87230d5c816cd5","price":"0.02","side":"BUY","size":"1060.79"},{"asset_id":"58313761654877669244690227616056238030136603415514645252000528337391143520538","best_ask":"0.48","best_bid":"0.47","hash":"122bc00dbe226ec9eb84182b08903972b0d3b78d","price":"0.98","side":"SELL","size":"1060.79"}],"timestamp":"1785207446958"},"payload_hash":"7e5d27e2bd4d9905261761ea81dfcdc842747a4964e7145e2f0ff552776cd06e","raw_frame":"{\"market\":\"0x0f70d07969bc69eaa97d0987de651885fdca02263688026aa11e7678af8f87aa\", \"price_changes\":[{\"asset_id\":\"64053005904884194822931764831592250494815136296598204104072528088122126148949\", \"price\":\"0.02\", \"size\":\"1060.79\", \"side\":\"BUY\", \"hash\":\"8d9c577e7be19b225565fc565f87230d5c816cd5\", \"best_bid\":\"0.52\", \"best_ask\":\"0.53\"}, {\"asset_id\":\"58313761654877669244690227616056238030136603415514645252000528337391143520538\", \"price\":\"0.98\", \"size\":\"1060.79\", \"side\":\"SELL\", \"hash\":\"122bc00dbe226ec9eb84182b08903972b0d3b78d\", \"best_bid\":\"0.47\", \"best_ask\":\"0.48\"}], \"timestamp\":\"1785207446958\", \"event_type\":\"price_change\"}","received_at":"2026-07-28T02:57:27.281181Z","schema_version":"clob-market-ws.price_change.v1","sequence":null,"server_hash":null,"server_timestamp":"1785207446958","session_id":"5aad79be415c487c84df42bebd84ee93","source":"clob_market_ws"},"received_at":"2026-07-28T02:57:27.281181Z","record_id":"2aac5470e7cb5c38e7ccf0f445c8aea9d0822dfc38d2d525c3417efcf0d41d0d","schema_fingerprint":"4aa3821a28b0b7c2400bc59aba4bcc0a76e971dadd19610d3ad38c768e124dc7","schema_version":"edge-lab-recorder.raw.v1","sequence":null,"source":"clob_market_ws"}
{"event_at":"2026-07-28T02:57:26.959000Z","event_fingerprint":"ba29f2ff2311a11f5eba7ee5dc454cb473560c88022453b61d72bee0a77404b6","payload":{"connection_id":"955646bd8bf740759faf38750c0f263f","event_at":"2026-07-28T02:57:26.959000Z","event_type":"price_change","frame_hash":"8371adb25438d0b5e393fd4af3677fa991fc0f2847c8893869a3757afc1b71c8","frame_index":0,"kind":"data","monotonic_ns":309430299928083,"payload":{"event_type":"price_change","market":"0x0f70d07969bc69eaa97d0987de651885fdca02263688026aa11e7678af8f87aa","price_changes":[{"asset_id":"64053005904884194822931764831592250494815136296598204104072528088122126148949","best_ask":"0.53","best_bid":"0.52","hash":"eedc1a7a34d216ed58dbb7677864dbcf4d78f1c8","price":"0.51","side":"BUY","size":"258.1"},{"asset_id":"58313761654877669244690227616056238030136603415514645252000528337391143520538","best_ask":"0.48","best_bid":"0.47","hash":"4542cd15b152c3114dc6a50d57db52bcc48ef9bb","price":"0.49","side":"SELL","size":"258.1"}],"timestamp":"1785207446959"},"payload_hash":"d65ba8690ea3aaeaedf2094e6a4cfe4e8896ab40db5b745b96c9ae322eefd1f3","raw_frame":"{\"market\":\"0x0f70d07969bc69eaa97d0987de651885fdca02263688026aa11e7678af8f87aa\", \"price_changes\":[{\"asset_id\":\"64053005904884194822931764831592250494815136296598204104072528088122126148949\", \"price\":\"0.51\", \"size\":\"258.1\", \"side\":\"BUY\", \"hash\":\"eedc1a7a34d216ed58dbb7677864dbcf4d78f1c8\", \"best_bid\":\"0.52\", \"best_ask\":\"0.53\"}, {\"asset_id\":\"58313761654877669244690227616056238030136603415514645252000528337391143520538\", \"price\":\"0.49\", \"size\":\"258.1\", \"side\":\"SELL\", \"hash\":\"4542cd15b152c3114dc6a50d57db52bcc48ef9bb\", \"best_bid\":\"0.47\", \"best_ask\":\"0.48\"}], \"timestamp\":\"1785207446959\", \"event_type\":\"price_change\"}","received_at":"2026-07-28T02:57:27.282668Z","schema_version":"clob-market-ws.price_change.v1","sequence":null,"server_hash":null,"server_timestamp":"1785207446959","session_id":"5aad79be415c487c84df42bebd84ee93","source":"clob_market_ws"},"received_at":"2026-07-28T02:57:27.282668Z","record_id":"04484580cd5f6c769547b1ebeffb4f2603f79ff4b263fcdd72f5bcd786ca5c0c","schema_fingerprint":"4aa3821a28b0b7c2400bc59aba4bcc0a76e971dadd19610d3ad38c768e124dc7","schema_version":"edge-lab-recorder.raw.v1","sequence":null,"source":"clob_market_ws"}
{"event_at":"2026-07-28T02:57:26.961000Z","event_fingerprint":"004499c64f0129b14feb40cbb863cc8113fd8404a27b72f873215905e0cd4adb","payload":{"connection_id":"955646bd8bf740759faf38750c0f263f","event_at":"2026-07-28T02:57:26.961000Z","event_type":"price_change","frame_hash":"22b0272e2637350fa584a7177b10472db1b84eae390c9d6c22e0ae6859c26817","frame_index":0,"kind":"data","monotonic_ns":309430301419875,"payload":{"event_type":"price_change","market":"0x0f70d07969bc69eaa97d0987de651885fdca02263688026aa11e7678af8f87aa","price_changes":[{"asset_id":"64053005904884194822931764831592250494815136296598204104072528088122126148949","best_ask":"0.53","best_bid":"0.52","hash":"090703973e37887dfed0d8058a4ff017eecfe1eb","price":"0.51","side":"BUY","size":"123.1"},{"asset_id":"58313761654877669244690227616056238030136603415514645252000528337391143520538","best_ask":"0.48","best_bid":"0.47","hash":"640b234b1fb6b37af39b9bcedec14099f06194dc","price":"0.49","side":"SELL","size":"123.1"}],"timestamp":"1785207446961"},"payload_hash":"799a5d3231bfcbe77102f5658271ab60f0f0799df06cd04668b9c4b66c1e6f82","raw_frame":"{\"market\":\"0x0f70d07969bc69eaa97d0987de651885fdca02263688026aa11e7678af8f87aa\", \"price_changes\":[{\"asset_id\":\"64053005904884194822931764831592250494815136296598204104072528088122126148949\", \"price\":\"0.51\", \"size\":\"123.1\", \"side\":\"BUY\", \"hash\":\"090703973e37887dfed0d8058a4ff017eecfe1eb\", \"best_bid\":\"0.52\", \"best_ask\":\"0.53\"}, {\"asset_id\":\"58313761654877669244690227616056238030136603415514645252000528337391143520538\", \"price\":\"0.49\", \"size\":\"123.1\", \"side\":\"SELL\", \"hash\":\"640b234b1fb6b37af39b9bcedec14099f06194dc\", \"best_bid\":\"0.47\", \"best_ask\":\"0.48\"}], \"timestamp\":\"1785207446961\", \"event_type\":\"price_change\"}","received_at":"2026-07-28T02:57:27.284158Z","schema_version":"clob-market-ws.price_change.v1","sequence":null,"server_hash":null,"server_timestamp":"1785207446961","session_id":"5aad79be415c487c84df42bebd84ee93","source":"clob_market_ws"},"received_at":"2026-07-28T02:57:27.284158Z","record_id":"882f4772fe390b68c492b931b48d000234fb471f98b9b9094132390f3ead5794","schema_fingerprint":"4aa3821a28b0b7c2400bc59aba4bcc0a76e971dadd19610d3ad38c768e124dc7","schema_version":"edge-lab-recorder.raw.v1","sequence":null,"source":"clob_market_ws"}
{"event_at":"2026-07-28T02:57:26.966000Z","event_fingerprint":"b743e9b35b0c5132b8eda24af87bb56a50b3338297049546aedcb41a136ce64c","payload":{"connection_id":"955646bd8bf740759faf38750c0f263f","event_at":"2026-07-28T02:57:26.966000Z","event_type":"price_change","frame_hash":"f2a9a594b808b0240353599e7eb3bba76e73a6d2eee3e56f6c8f3e186e9707cc","frame_index":0,"kind":"data","monotonic_ns":309430302923500,"payload":{"event_type":"price_change","market":"0x0f70d07969bc69eaa97d0987de651885fdca02263688026aa11e7678af8f87aa","price_changes":[{"asset_id":"58313761654877669244690227616056238030136603415514645252000528337391143520538","best_ask":"0.48","best_bid":"0.47","hash":"fc0ad6ee9bf00d7d41e511880b917634a5a71624","price":"0.56","side":"SELL","size":"77"},{"asset_id":"64053005904884194822931764831592250494815136296598204104072528088122126148949","best_ask":"0.53","best_bid":"0.52","hash":"9671d53ebb226f47909d2ae79000053450de007c","price":"0.44","side":"BUY","size":"77"}],"timestamp":"1785207446966"},"payload_hash":"06c3eaca613072e14dac1593bb29dc2bbf35a56e92abae1353440345d2e42ab7","raw_frame":"{\"market\":\"0x0f70d07969bc69eaa97d0987de651885fdca02263688026aa11e7678af8f87aa\", \"price_changes\":[{\"asset_id\":\"58313761654877669244690227616056238030136603415514645252000528337391143520538\", \"price\":\"0.56\", \"size\":\"77\", \"side\":\"SELL\", \"hash\":\"fc0ad6ee9bf00d7d41e511880b917634a5a71624\", \"best_bid\":\"0.47\", \"best_ask\":\"0.48\"}, {\"asset_id\":\"64053005904884194822931764831592250494815136296598204104072528088122126148949\", \"price\":\"0.44\", \"size\":\"77\", \"side\":\"BUY\", \"hash\":\"9671d53ebb226f47909d2ae79000053450de007c\", \"best_bid\":\"0.52\", \"best_ask\":\"0.53\"}], \"timestamp\":\"1785207446966\", \"event_type\":\"price_change\"}","received_at":"2026-07-28T02:57:27.285663Z","schema_version":"clob-market-ws.price_change.v1","sequence":null,"server_hash":null,"server_timestamp":"1785207446966","session_id":"5aad79be415c487c84df42bebd84ee93","source":"clob_market_ws"},"received_at":"2026-07-28T02:57:27.285663Z","record_id":"d876f166df53925573c93fec410a181bd3815b8377ca50f5128e9b5a4924e2c2","schema_fingerprint":"4aa3821a28b0b7c2400bc59aba4bcc0a76e971dadd19610d3ad38c768e124dc7","schema_version":"edge-lab-recorder.raw.v1","sequence":null,"source":"clob_market_ws"}
{"event_at":"2026-07-28T02:57:26.967000Z","event_fingerprint":"758f397e9ecc3e978393639b03e12ac18aee71f0ca22ec9e46564ff966aa7781","payload":{"connection_id":"955646bd8bf740759faf38750c0f263f","event_at":"2026-07-28T02:57:26.967000Z","event_type":"price_change","frame_hash":"d869b57c3fe2afda5efb08252c8544cbe38a31b4fad216530c20e4c7f4f5e5e4","frame_index":0,"kind":"data","monotonic_ns":309430304392250,"payload":{"event_type":"price_change","market":"0x0f70d07969bc69eaa97d0987de651885fdca02263688026aa11e7678af8f87aa","price_changes":[{"asset_id":"64053005904884194822931764831592250494815136296598204104072528088122126148949","best_ask":"0.53","best_bid":"0.52","hash":"e719be8e611d88b6d40923cfceea6afb1f8f356e","price":"0.44","side":"BUY","size":"82"},{"asset_id":"58313761654877669244690227616056238030136603415514645252000528337391143520538","best_ask":"0.48","best_bid":"0.47","hash":"0f3245583b1c081420a5f1f8ff1ded3e7c570f80","price":"0.56","side":"SELL","size":"82"}],"timestamp":"1785207446967"},"payload_hash":"519640ab0787a0d9f4c60fabcd5c993f714ecdd19f7ce911db7a1e75fc11796c","raw_frame":"{\"market\":\"0x0f70d07969bc69eaa97d0987de651885fdca02263688026aa11e7678af8f87aa\", \"price_changes\":[{\"asset_id\":\"64053005904884194822931764831592250494815136296598204104072528088122126148949\", \"price\":\"0.44\", \"size\":\"82\", \"side\":\"BUY\", \"hash\":\"e719be8e611d88b6d40923cfceea6afb1f8f356e\", \"best_bid\":\"0.52\", \"best_ask\":\"0.53\"}, {\"asset_id\":\"58313761654877669244690227616056238030136603415514645252000528337391143520538\", \"price\":\"0.56\", \"size\":\"82\", \"side\":\"SELL\", \"hash\":\"0f3245583b1c081420a5f1f8ff1ded3e7c570f80\", \"best_bid\":\"0.47\", \"best_ask\":\"0.48\"}], \"timestamp\":\"1785207446967\", \"event_type\":\"price_change\"}","received_at":"2026-07-28T02:57:27.287131Z","schema_version":"clob-market-ws.price_change.v1","sequence":null,"server_hash":null,"server_timestamp":"1785207446967","session_id":"5aad79be415c487c84df42bebd84ee93","source":"clob_market_ws"},"received_at":"2026-07-28T02:57:27.287131Z","record_id":"409a1e79fb5e140804450fca176e3c82f6042cb7cc3ebe3c7537826283be5d4d","schema_fingerprint":"4aa3821a28b0b7c2400bc59aba4bcc0a76e971dadd19610d3ad38c768e124dc7","schema_version":"edge-lab-recorder.raw.v1","sequence":null,"source":"clob_market_ws"}
{"event_at":"2026-07-28T02:57:26.973000Z","event_fingerprint":"0166ecc666f91524355a14a7086b295db673a1dcf39f5c609c0ee7fa421e34d8","payload":{"connection_id":"955646bd8bf740759faf38750c0f263f","event_at":"2026-07-28T02:57:26.973000Z","event_type":"price_change","frame_hash":"76f6010957b40d82e3264bee706b0d18dda26c31a9269b3b8052c34df4b5fcd0","frame_index":0,"kind":"data","monotonic_ns":309430305868958,"payload":{"event_type":"price_change","market":"0x0f70d07969bc69eaa97d0987de651885fdca02263688026aa11e7678af8f87aa","price_changes":[{"asset_id":"64053005904884194822931764831592250494815136296598204104072528088122126148949","best_ask":"0.53","best_bid":"0.52","hash":"6bc6fe76a9b8626ba6fe52a0b68362510dc9a402","price":"0.16","side":"BUY","size":"166.1"},{"asset_id":"58313761654877669244690227616056238030136603415514645252000528337391143520538","best_ask":"0.48","best_bid":"0.47","hash":"db207583edb724d5534fc324fdea766d75adf3c3","price":"0.84","side":"SELL","size":"166.1"}],"timestamp":"1785207446973"},"payload_hash":"7ed847b371c7769bf51fe34cc9212a5c5478f1fcc356663e882ea6ed3d146803","raw_frame":"{\"market\":\"0x0f70d07969bc69eaa97d0987de651885fdca02263688026aa11e7678af8f87aa\", \"price_changes\":[{\"asset_id\":\"64053005904884194822931764831592250494815136296598204104072528088122126148949\", \"price\":\"0.16\", \"size\":\"166.1\", \"side\":\"BUY\", \"hash\":\"6bc6fe76a9b8626ba6fe52a0b68362510dc9a402\", \"best_bid\":\"0.52\", \"best_ask\":\"0.53\"}, {\"asset_id\":\"58313761654877669244690227616056238030136603415514645252000528337391143520538\", \"price\":\"0.84\", \"size\":\"166.1\", \"side\":\"SELL\", \"hash\":\"db207583edb724d5534fc324fdea766d75adf3c3\", \"best_bid\":\"0.47\", \"best_ask\":\"0.48\"}], \"timestamp\":\"1785207446973\", \"event_type\":\"price_change\"}","received_at":"2026-07-28T02:57:27.288609Z","schema_version":"clob-market-ws.price_change.v1","sequence":null,"server_hash":null,"server_timestamp":"1785207446973","session_id":"5aad79be415c487c84df42bebd84ee93","source":"clob_market_ws"},"received_at":"2026-07-28T02:57:27.288609Z","record_id":"624ffd1f1bd483b3182d0a0a7a2d8f6388e22e0785c3a5b702367b38abe1eb82","schema_fingerprint":"4aa3821a28b0b7c2400bc59aba4bcc0a76e971dadd19610d3ad38c768e124dc7","schema_version":"edge-lab-recorder.raw.v1","sequence":null,"source":"clob_market_ws"}
{"event_at":"2026-07-28T02:57:26.976000Z","event_fingerprint":"dbe922663ab439d1d2202888e2d931ebb9d69b7722df7d8f0d12651883c90f19","payload":{"connection_id":"955646bd8bf740759faf38750c0f263f","event_at":"2026-07-28T02:57:26.976000Z","event_type":"price_change","frame_hash":"dea5642894b1067f8ba437c8c485d3e4e457db026b0786928dfca62591bf25f3","frame_index":0,"kind":"data","monotonic_ns":309430307305666,"payload":{"event_type":"price_change","market":"0x0f70d07969bc69eaa97d0987de651885fdca02263688026aa11e7678af8f87aa","price_changes":[{"asset_id":"64053005904884194822931764831592250494815136296598204104072528088122126148949","best_ask":"0.53","best_bid":"0.52","hash":"3cc7ecf90251d2f5a79bb6bcb2075dc527100bae","price":"0.51","side":"BUY","size":"116.1"},{"asset_id":"58313761654877669244690227616056238030136603415514645252000528337391143520538","best_ask":"0.48","best_bid":"0.47","hash":"61e251126b981864092ff749712c6506698bf165","price":"0.49","side":"SELL","size":"116.1"}],"timestamp":"1785207446976"},"payload_hash":"465c88ec9f8c071ef84442b80d772ea00f8e677a43f5585ef2bbecd91321c1fc","raw_frame":"{\"market\":\"0x0f70d07969bc69eaa97d0987de651885fdca02263688026aa11e7678af8f87aa\", \"price_changes\":[{\"asset_id\":\"64053005904884194822931764831592250494815136296598204104072528088122126148949\", \"price\":\"0.51\", \"size\":\"116.1\", \"side\":\"BUY\", \"hash\":\"3cc7ecf90251d2f5a79bb6bcb2075dc527100bae\", \"best_bid\":\"0.52\", \"best_ask\":\"0.53\"}, {\"asset_id\":\"58313761654877669244690227616056238030136603415514645252000528337391143520538\", \"price\":\"0.49\", \"size\":\"116.1\", \"side\":\"SELL\", \"hash\":\"61e251126b981864092ff749712c6506698bf165\", \"best_bid\":\"0.47\", \"best_ask\":\"0.48\"}], \"timestamp\":\"1785207446976\", \"event_type\":\"price_change\"}","received_at":"2026-07-28T02:57:27.290045Z","schema_version":"clob-market-ws.price_change.v1","sequence":null,"server_hash":null,"server_timestamp":"1785207446976","session_id":"5aad79be415c487c84df42bebd84ee93","source":"clob_market_ws"},"received_at":"2026-07-28T02:57:27.290045Z","record_id":"7b67ed0d5b921bf26bd2ace32badc1c9be38a4e5e95f51a4b3d726310a883239","schema_fingerprint":"4aa3821a28b0b7c2400bc59aba4bcc0a76e971dadd19610d3ad38c768e124dc7","schema_version":"edge-lab-recorder.raw.v1","sequence":null,"source":"clob_market_ws"}
{"event_at":"2026-07-28T02:57:26.983000Z","event_fingerprint":"fbd6bbb4ae3c19b4de7e405ee3c1c3699ffefbea48c2015f20a3482b5752e6ec","payload":{"connection_id":"955646bd8bf740759faf38750c0f263f","event_at":"2026-07-28T02:57:26.983000Z","event_type":"price_change","frame_hash":"8ae4c5712a43141e70f5dcc5b513ae6435d480d6f0ca2c8645b2e21fa508434e","frame_index":0,"kind":"data","monotonic_ns":309430308755625,"payload":{"event_type":"price_change","market":"0x0f70d07969bc69eaa97d0987de651885fdca02263688026aa11e7678af8f87aa","price_changes":[{"asset_id":"64053005904884194822931764831592250494815136296598204104072528088122126148949","best_ask":"0.53","best_bid":"0.52","hash":"dd6e20005405fc537c46177a82ffe0c42f8cd2fc","price":"0.78","side":"SELL","size":"100.2"},{"asset_id":"58313761654877669244690227616056238030136603415514645252000528337391143520538","best_ask":"0.48","best_bid":"0.47","hash":"dff6d391535dc377c1294d1ea562c2768034ecf9","price":"0.22","side":"BUY","size":"100.2"}],"timestamp":"1785207446983"},"payload_hash":"99cc943fd4cdbd3c748d5d02fa4e98ea14ae08bd4d0ce53a0489db41dbe00040","raw_frame":"{\"market\":\"0x0f70d07969bc69eaa97d0987de651885fdca02263688026aa11e7678af8f87aa\", \"price_changes\":[{\"asset_id\":\"64053005904884194822931764831592250494815136296598204104072528088122126148949\", \"price\":\"0.78\", \"size\":\"100.2\", \"side\":\"SELL\", \"hash\":\"dd6e20005405fc537c46177a82ffe0c42f8cd2fc\", \"best_bid\":\"0.52\", \"best_ask\":\"0.53\"}, {\"asset_id\":\"58313761654877669244690227616056238030136603415514645252000528337391143520538\", \"price\":\"0.22\", \"size\":\"100.2\", \"side\":\"BUY\", \"hash\":\"dff6d391535dc377c1294d1ea562c2768034ecf9\", \"best_bid\":\"0.47\", \"best_ask\":\"0.48\"}], \"timestamp\":\"1785207446983\", \"event_type\":\"price_change\"}","received_at":"2026-07-28T02:57:27.291495Z","schema_version":"clob-market-ws.price_change.v1","sequence":null,"server_hash":null,"server_timestamp":"1785207446983","session_id":"5aad79be415c487c84df42bebd84ee93","source":"clob_market_ws"},"received_at":"2026-07-28T02:57:27.291495Z","record_id":"0923422475a72ed1fafa70c9bac9a792275240b6bf25527d6f0fe4614b41bff7","schema_fingerprint":"4aa3821a28b0b7c2400bc59aba4bcc0a76e971dadd19610d3ad38c768e124dc7","schema_version":"edge-lab-recorder.raw.v1","sequence":null,"source":"clob_market_ws"}
{"event_at":"2026-07-28T02:57:26.989000Z","event_fingerprint":"915a229d6580225feae9bed3257dc563ac85e37ee768262f6cd60c41fa9eff30","payload":{"connection_id":"955646bd8bf740759faf38750c0f263f","event_at":"2026-07-28T02:57:26.989000Z","event_type":"price_change","frame_hash":"6dda7eb856cbaeeda072c60d49bff79e0da28e91822a6a8fbb18a6df87f3caa4","frame_index":0,"kind":"data","monotonic_ns":309430310209708,"payload":{"event_type":"price_change","market":"0x0f70d07969bc69eaa97d0987de651885fdca02263688026aa11e7678af8f87aa","price_changes":[{"asset_id":"64053005904884194822931764831592250494815136296598204104072528088122126148949","best_ask":"0.53","best_bid":"0.52","hash":"74f0e4c89dcd9ef1479803d96fb81a0fe6e89196","price":"0.46","side":"BUY","size":"127.67"},{"asset_id":"58313761654877669244690227616056238030136603415514645252000528337391143520538","best_ask":"0.48","best_bid":"0.47","hash":"a469490d76f88526087421da7de2abf9536ca887","price":"0.54","side":"SELL","size":"127.67"}],"timestamp":"1785207446989"},"payload_hash":"026407ab7cc31e340c0fa52916a3dea2d543a3c2aca0358f2360be46680808a7","raw_frame":"{\"market\":\"0x0f70d07969bc69eaa97d0987de651885fdca02263688026aa11e7678af8f87aa\", \"price_changes\":[{\"asset_id\":\"64053005904884194822931764831592250494815136296598204104072528088122126148949\", \"price\":\"0.46\", \"size\":\"127.67\", \"side\":\"BUY\", \"hash\":\"74f0e4c89dcd9ef1479803d96fb81a0fe6e89196\", \"best_bid\":\"0.52\", \"best_ask\":\"0.53\"}, {\"asset_id\":\"58313761654877669244690227616056238030136603415514645252000528337391143520538\", \"price\":\"0.54\", \"size\":\"127.67\", \"side\":\"SELL\", \"hash\":\"a469490d76f88526087421da7de2abf9536ca887\", \"best_bid\":\"0.47\", \"best_ask\":\"0.48\"}], \"timestamp\":\"1785207446989\", \"event_type\":\"price_change\"}","received_at":"2026-07-28T02:57:27.292948Z","schema_version":"clob-market-ws.price_change.v1","sequence":null,"server_hash":null,"server_timestamp":"1785207446989","session_id":"5aad79be415c487c84df42bebd84ee93","source":"clob_market_ws"},"received_at":"2026-07-28T02:57:27.292948Z","record_id":"ad8964f8e560046b6caeb1d8cb20b301b929529da324146b0327906b4ec7b58f","schema_fingerprint":"4aa3821a28b0b7c2400bc59aba4bcc0a76e971dadd19610d3ad38c768e124dc7","schema_version":"edge-lab-recorder.raw.v1","sequence":null,"source":"clob_market_ws"}
{"event_at":"2026-07-28T02:57:26.998000Z","event_fingerprint":"64a35b03e2762ec27379fbea01845ee07ded72f1e7ba86e446f355a90d1c1230","payload":{"connection_id":"955646bd8bf740759faf38750c0f263f","event_at":"2026-07-28T02:57:26.998000Z","event_type":"price_change","frame_hash":"d5373351a7d13175ea9856b6b0cf812eba3eabc13db33b330b4ca5b25f29505d","frame_index":0,"kind":"data","monotonic_ns":309430311746125,"payload":{"event_type":"price_change","market":"0x0f70d07969bc69eaa97d0987de651885fdca02263688026aa11e7678af8f87aa","price_changes":[{"asset_id":"64053005904884194822931764831592250494815136296598204104072528088122126148949","best_ask":"0.53","best_bid":"0.52","hash":"36e6f80aab2fe8ab40551eea485b94e9f18b68ff","price":"0.51","side":"BUY","size":"123.1"},{"asset_id":"58313761654877669244690227616056238030136603415514645252000528337391143520538","best_ask":"0.48","best_bid":"0.47","hash":"785682a7eae56b38ebcd8c21afe79864fb70931b","price":"0.49","side":"SELL","size":"123.1"}],"timestamp":"1785207446998"},"payload_hash":"f6f207d10d4996fb0dba66f0b1eed297922f43e47244fec08bc69a108396a58c","raw_frame":"{\"market\":\"0x0f70d07969bc69eaa97d0987de651885fdca02263688026aa11e7678af8f87aa\", \"price_changes\":[{\"asset_id\":\"64053005904884194822931764831592250494815136296598204104072528088122126148949\", \"price\":\"0.51\", \"size\":\"123.1\", \"side\":\"BUY\", \"hash\":\"36e6f80aab2fe8ab40551eea485b94e9f18b68ff\", \"best_bid\":\"0.52\", \"best_ask\":\"0.53\"}, {\"asset_id\":\"58313761654877669244690227616056238030136603415514645252000528337391143520538\", \"price\":\"0.49\", \"size\":\"123.1\", \"side\":\"SELL\", \"hash\":\"785682a7eae56b38ebcd8c21afe79864fb70931b\", \"best_bid\":\"0.47\", \"best_ask\":\"0.48\"}], \"timestamp\":\"1785207446998\", \"event_type\":\"price_change\"}","received_at":"2026-07-28T02:57:27.294486Z","schema_version":"clob-market-ws.price_change.v1","sequence":null,"server_hash":null,"server_timestamp":"1785207446998","session_id":"5aad79be415c487c84df42bebd84ee93","source":"clob_market_ws"},"received_at":"2026-07-28T02:57:27.294486Z","record_id":"cac6f310208c6ced9e6670e0825902a8c12129a599ca421678b97a1025d8f6bc","schema_fingerprint":"4aa3821a28b0b7c2400bc59aba4bcc0a76e971dadd19610d3ad38c768e124dc7","schema_version":"edge-lab-recorder.raw.v1","sequence":null,"source":"clob_market_ws"}
{"event_at":"2026-07-28T02:57:27.005000Z","event_fingerprint":"b2b6fbb4276b916c7bbe51116f84a2a824e02eacff7a28b47056a25e82ecac61","payload":{"connection_id":"955646bd8bf740759faf38750c0f263f","event_at":"2026-07-28T02:57:27.005000Z","event_type":"price_change","frame_hash":"ab0084f1c673dde208a10dc3d4e7d3c115a647921a9a3d8be7c880b991c98065","frame_index":0,"kind":"data","monotonic_ns":309430313206000,"payload":{"event_type":"price_change","market":"0x0f70d07969bc69eaa97d0987de651885fdca02263688026aa11e7678af8f87aa","price_changes":[{"asset_id":"58313761654877669244690227616056238030136603415514645252000528337391143520538","best_ask":"0.48","best_bid":"0.47","hash":"16d3b5f270bef4e7f86e5b4a37962f6a6cd4d5cd","price":"0.38","side":"BUY","size":"350.84"},{"asset_id":"64053005904884194822931764831592250494815136296598204104072528088122126148949","best_ask":"0.53","best_bid":"0.52","hash":"21621fef7773fb5dc8add9ba54f0ce069d7c6100","price":"0.62","side":"SELL","size":"350.84"}],"timestamp":"1785207447005"},"payload_hash":"bdd13a90b7368d9a55a26bab9ee38ebc4217263bbe8bea94cd58a3eaa1e7d454","raw_frame":"{\"market\":\"0x0f70d07969bc69eaa97d0987de651885fdca02263688026aa11e7678af8f87aa\", \"price_changes\":[{\"asset_id\":\"58313761654877669244690227616056238030136603415514645252000528337391143520538\", \"price\":\"0.38\", \"size\":\"350.84\", \"side\":\"BUY\", \"hash\":\"16d3b5f270bef4e7f86e5b4a37962f6a6cd4d5cd\", \"best_bid\":\"0.47\", \"best_ask\":\"0.48\"}, {\"asset_id\":\"64053005904884194822931764831592250494815136296598204104072528088122126148949\", \"price\":\"0.62\", \"size\":\"350.84\", \"side\":\"SELL\", \"hash\":\"21621fef7773fb5dc8add9ba54f0ce069d7c6100\", \"best_bid\":\"0.52\", \"best_ask\":\"0.53\"}], \"timestamp\":\"1785207447005\", \"event_type\":\"price_change\"}","received_at":"2026-07-28T02:57:27.295945Z","schema_version":"clob-market-ws.price_change.v1","sequence":null,"server_hash":null,"server_timestamp":"1785207447005","session_id":"5aad79be415c487c84df42bebd84ee93","source":"clob_market_ws"},"received_at":"2026-07-28T02:57:27.295945Z","record_id":"e0449f6ec6d5f60b5219a85af23461c5667fdd3ffef928104ef559502273ee63","schema_fingerprint":"4aa3821a28b0b7c2400bc59aba4bcc0a76e971dadd19610d3ad38c768e124dc7","schema_version":"edge-lab-recorder.raw.v1","sequence":null,"source":"clob_market_ws"}
{"event_at":"2026-07-28T02:57:27.006000Z","event_fingerprint":"cf9674bfb7389d0e3f0f526ad0ef7ca2d88bdab1884fc1a9d8b9fe4b6c0aa157","payload":{"connection_id":"955646bd8bf740759faf38750c0f263f","event_at":"2026-07-28T02:57:27.006000Z","event_type":"price_change","frame_hash":"644c98adfa298721ab56f4797d2b7716e4378f50f774c357a31fd0bbdfe4a355","frame_index":0,"kind":"data","monotonic_ns":309430314672375,"payload":{"event_type":"price_change","market":"0x0f70d07969bc69eaa97d0987de651885fdca02263688026aa11e7678af8f87aa","price_changes":[{"asset_id":"64053005904884194822931764831592250494815136296598204104072528088122126148949","best_ask":"0.53","best_bid":"0.52","hash":"0f4aead3b421668f4f48718ef15deb41d9c7643f","price":"0.38","side":"BUY","size":"170.6"},{"asset_id":"58313761654877669244690227616056238030136603415514645252000528337391143520538","best_ask":"0.48","best_bid":"0.47","hash":"98b66772f3d3404a3c2558dc2dbe297535865687","price":"0.62","side":"SELL","size":"170.6"}],"timestamp":"1785207447006"},"payload_hash":"7de27e4c42dd8298d68b1d860e7edd9a990043a741297ce25793485d78cf0a64","raw_frame":"{\"market\":\"0x0f70d07969bc69eaa97d0987de651885fdca02263688026aa11e7678af8f87aa\", \"price_changes\":[{\"asset_id\":\"64053005904884194822931764831592250494815136296598204104072528088122126148949\", \"price\":\"0.38\", \"size\":\"170.6\", \"side\":\"BUY\", \"hash\":\"0f4aead3b421668f4f48718ef15deb41d9c7643f\", \"best_bid\":\"0.52\", \"best_ask\":\"0.53\"}, {\"asset_id\":\"58313761654877669244690227616056238030136603415514645252000528337391143520538\", \"price\":\"0.62\", \"size\":\"170.6\", \"side\":\"SELL\", \"hash\":\"98b66772f3d3404a3c2558dc2dbe297535865687\", \"best_bid\":\"0.47\", \"best_ask\":\"0.48\"}], \"timestamp\":\"1785207447006\", \"event_type\":\"price_change\"}","received_at":"2026-07-28T02:57:27.297412Z","schema_version":"clob-market-ws.price_change.v1","sequence":null,"server_hash":null,"server_timestamp":"1785207447006","session_id":"5aad79be415c487c84df42bebd84ee93","source":"clob_market_ws"},"received_at":"2026-07-28T02:57:27.297412Z","record_id":"81f2d0e097e8b07a327df44734a628df9cd6e7a1c71c4b2cbc6027ddc35ce28e","schema_fingerprint":"4aa3821a28b0b7c2400bc59aba4bcc0a76e971dadd19610d3ad38c768e124dc7","schema_version":"edge-lab-recorder.raw.v1","sequence":null,"source":"clob_market_ws"}
{"event_at":"2026-07-28T02:57:27.006000Z","event_fingerprint":"ed84ae306f65f29d7c0f8958e2b100e66f8be8fe90d6a585bf636badada29e84","payload":{"connection_id":"955646bd8bf740759faf38750c0f263f","event_at":"2026-07-28T02:57:27.006000Z","event_type":"price_change","frame_hash":"8338ae21ce1f819107496deeede2342652f296416aa21d0be58d3489a2f00396","frame_index":0,"kind":"data","monotonic_ns":309430316141083,"payload":{"event_type":"price_change","market":"0x0f70d07969bc69eaa97d0987de651885fdca02263688026aa11e7678af8f87aa","price_changes":[{"asset_id":"64053005904884194822931764831592250494815136296598204104072528088122126148949","best_ask":"0.53","best_bid":"0.52","hash":"b417d5b990ec94fe9f2f9cacfb0667377205e557","price":"0.38","side":"BUY","size":"120.6"},{"asset_id":"58313761654877669244690227616056238030136603415514645252000528337391143520538","best_ask":"0.48","best_bid":"0.47","hash":"e2c578fd5ecb01b0b4ea97c009ce4a7a057d8749","price":"0.62","side":"SELL","size":"120.6"}],"timestamp":"1785207447006"},"payload_hash":"b08bdf9638d3f6449810e260b803e8f21cf222d187afd56c1cf82c4150d27b8d","raw_frame":"{\"market\":\"0x0f70d07969bc69eaa97d0987de651885fdca02263688026aa11e7678af8f87aa\", \"price_changes\":[{\"asset_id\":\"64053005904884194822931764831592250494815136296598204104072528088122126148949\", \"price\":\"0.38\", \"size\":\"120.6\", \"side\":\"BUY\", \"hash\":\"b417d5b990ec94fe9f2f9cacfb0667377205e557\", \"best_bid\":\"0.52\", \"best_ask\":\"0.53\"}, {\"asset_id\":\"58313761654877669244690227616056238030136603415514645252000528337391143520538\", \"price\":\"0.62\", \"size\":\"120.6\", \"side\":\"SELL\", \"hash\":\"e2c578fd5ecb01b0b4ea97c009ce4a7a057d8749\", \"best_bid\":\"0.47\", \"best_ask\":\"0.48\"}], \"timestamp\":\"1785207447006\", \"event_type\":\"price_change\"}","received_at":"2026-07-28T02:57:27.298880Z","schema_version":"clob-market-ws.price_change.v1","sequence":null,"server_hash":null,"server_timestamp":"1785207447006","session_id":"5aad79be415c487c84df42bebd84ee93","source":"clob_market_ws"},"received_at":"2026-07-28T02:57:27.298880Z","record_id":"cf909ac869eae740c14499ee5ce28acae765fde6dba27adf2cd3393b675a36ed","schema_fingerprint":"4aa3821a28b0b7c2400bc59aba4bcc0a76e971dadd19610d3ad38c768e124dc7","schema_version":"edge-lab-recorder.raw.v1","sequence":null,"source":"clob_market_ws"}
{"event_at":"2026-07-28T02:57:27.007000Z","event_fingerprint":"41bfffcb3c1102faaecfcf3f80a635dd9ae65b11bea4231183551dc5164c777b","payload":{"connection_id":"955646bd8bf740759faf38750c0f263f","event_at":"2026-07-28T02:57:27.007000Z","event_type":"price_change","frame_hash":"f601900701a26f6b5606f1a0754eb16fb55de0883c817449fda74568b00ba689","frame_index":0,"kind":"data","monotonic_ns":309430317655833,"payload":{"event_type":"price_change","market":"0x0f70d07969bc69eaa97d0987de651885fdca02263688026aa11e7678af8f87aa","price_changes":[{"asset_id":"58313761654877669244690227616056238030136603415514645252000528337391143520538","best_ask":"0.48","best_bid":"0.47","hash":"7d87c3f20514a5b5937679be96b373e1946192d2","price":"0.38","side":"BUY","size":"300.84"},{"asset_id":"64053005904884194822931764831592250494815136296598204104072528088122126148949","best_ask":"0.53","best_bid":"0.52","hash":"c0f410c26754c1af2b28a314bea0603af353a6af","price":"0.62","side":"SELL","size":"300.84"}],"timestamp":"1785207447007"},"payload_hash":"9fb308c38c36766e645ec9b81047a11f2b8da4e19b0c3c0ca097fbfaac96fab4","raw_frame":"{\"market\":\"0x0f70d07969bc69eaa97d0987de651885fdca02263688026aa11e7678af8f87aa\", \"price_changes\":[{\"asset_id\":\"58313761654877669244690227616056238030136603415514645252000528337391143520538\", \"price\":\"0.38\", \"size\":\"300.84\", \"side\":\"BUY\", \"hash\":\"7d87c3f20514a5b5937679be96b373e1946192d2\", \"best_bid\":\"0.47\", \"best_ask\":\"0.48\"}, {\"asset_id\":\"64053005904884194822931764831592250494815136296598204104072528088122126148949\", \"price\":\"0.62\", \"size\":\"300.84\", \"side\":\"SELL\", \"hash\":\"c0f410c26754c1af2b28a314bea0603af353a6af\", \"best_bid\":\"0.52\", \"best_ask\":\"0.53\"}], \"timestamp\":\"1785207447007\", \"event_type\":\"price_change\"}","received_at":"2026-07-28T02:57:27.300394Z","schema_version":"clob-market-ws.price_change.v1","sequence":null,"server_hash":null,"server_timestamp":"1785207447007","session_id":"5aad79be415c487c84df42bebd84ee93","source":"clob_market_ws"},"received_at":"2026-07-28T02:57:27.300394Z","record_id":"193d21604cb803423e7ac7d7256abf08c8eb6174761197041f5df495aba16bd4","schema_fingerprint":"4aa3821a28b0b7c2400bc59aba4bcc0a76e971dadd19610d3ad38c768e124dc7","schema_version":"edge-lab-recorder.raw.v1","sequence":null,"source":"clob_market_ws"}
{"event_at":"2026-07-28T02:57:27.007000Z","event_fingerprint":"7f44d651ee8a8124e0e1b32f1ff7ea41e351f86338650f180503cf451f6dc97b","payload":{"connection_id":"955646bd8bf740759faf38750c0f263f","event_at":"2026-07-28T02:57:27.007000Z","event_type":"price_change","frame_hash":"25650b2e55ca4e8cf329ef97ce3be5f5c8b82ac3e08ee27f641e35c4059732ce","frame_index":0,"kind":"data","monotonic_ns":309430319146750,"payload":{"event_type":"price_change","market":"0x0f70d07969bc69eaa97d0987de651885fdca02263688026aa11e7678af8f87aa","price_changes":[{"asset_id":"64053005904884194822931764831592250494815136296598204104072528088122126148949","best_ask":"0.53","best_bid":"0.52","hash":"e5a46545fdb1c2f9a24a29fe904492b6a687a8e7","price":"0.38","side":"BUY","size":"70.6"},{"asset_id":"58313761654877669244690227616056238030136603415514645252000528337391143520538","best_ask":"0.48","best_bid":"0.47","hash":"5bad3b7979648f67e1ff75e0fcc5a5c4431dd5ee","price":"0.62","side":"SELL","size":"70.6"}],"timestamp":"1785207447007"},"payload_hash":"644fe9c3e36384e4e39347aea87a2265ff20d152010c4c8625088deb59781dd1","raw_frame":"{\"market\":\"0x0f70d07969bc69eaa97d0987de651885fdca02263688026aa11e7678af8f87aa\", \"price_changes\":[{\"asset_id\":\"64053005904884194822931764831592250494815136296598204104072528088122126148949\", \"price\":\"0.38\", \"size\":\"70.6\", \"side\":\"BUY\", \"hash\":\"e5a46545fdb1c2f9a24a29fe904492b6a687a8e7\", \"best_bid\":\"0.52\", \"best_ask\":\"0.53\"}, {\"asset_id\":\"58313761654877669244690227616056238030136603415514645252000528337391143520538\", \"price\":\"0.62\", \"size\":\"70.6\", \"side\":\"SELL\", \"hash\":\"5bad3b7979648f67e1ff75e0fcc5a5c4431dd5ee\", \"best_bid\":\"0.47\", \"best_ask\":\"0.48\"}], \"timestamp\":\"1785207447007\", \"event_type\":\"price_change\"}","received_at":"2026-07-28T02:57:27.301886Z","schema_version":"clob-market-ws.price_change.v1","sequence":null,"server_hash":null,"server_timestamp":"1785207447007","session_id":"5aad79be415c487c84df42bebd84ee93","source":"clob_market_ws"},"received_at":"2026-07-28T02:57:27.301886Z","record_id":"e8cc87fa118785e94f4a9b520bed05add11ca9cb62703c52a7c27c846cf59a8d","schema_fingerprint":"4aa3821a28b0b7c2400bc59aba4bcc0a76e971dadd19610d3ad38c768e124dc7","schema_version":"edge-lab-recorder.raw.v1","sequence":null,"source":"clob_market_ws"}
{"event_at":"2026-07-28T02:57:27.009000Z","event_fingerprint":"01d0def9528c22924c49be3461aa3d4d8321fd84f8b8381c7b227b9bc280d97d","payload":{"connection_id":"955646bd8bf740759faf38750c0f263f","event_at":"2026-07-28T02:57:27.009000Z","event_type":"price_change","frame_hash":"098b9d8451c6e6463002cc017e3f1ef2162ef3468dfd395d4c5abd567aaa036e","frame_index":0,"kind":"data","monotonic_ns":309430320598625,"payload":{"event_type":"price_change","market":"0x0f70d07969bc69eaa97d0987de651885fdca02263688026aa11e7678af8f87aa","price_changes":[{"asset_id":"58313761654877669244690227616056238030136603415514645252000528337391143520538","best_ask":"0.48","best_bid":"0.47","hash":"7eb8809a962d9a5cec4f17813038a629942c1fdb","price":"0.38","side":"BUY","size":"285.84"},{"asset_id":"64053005904884194822931764831592250494815136296598204104072528088122126148949","best_ask":"0.53","best_bid":"0.52","hash":"a66ff9cb7ea0612cf861fcf638744dc9cb412529","price":"0.62","side":"SELL","size":"285.84"}],"timestamp":"1785207447009"},"payload_hash":"e667f8112985c5445b38d24e0f1ca051d6dca9f0e6bfcd66b160fed53d5b2630","raw_frame":"{\"market\":\"0x0f70d07969bc69eaa97d0987de651885fdca02263688026aa11e7678af8f87aa\", \"price_changes\":[{\"asset_id\":\"58313761654877669244690227616056238030136603415514645252000528337391143520538\", \"price\":\"0.38\", \"size\":\"285.84\", \"side\":\"BUY\", \"hash\":\"7eb8809a962d9a5cec4f17813038a629942c1fdb\", \"best_bid\":\"0.47\", \"best_ask\":\"0.48\"}, {\"asset_id\":\"64053005904884194822931764831592250494815136296598204104072528088122126148949\", \"price\":\"0.62\", \"size\":\"285.84\", \"side\":\"SELL\", \"hash\":\"a66ff9cb7ea0612cf861fcf638744dc9cb412529\", \"best_bid\":\"0.52\", \"best_ask\":\"0.53\"}], \"timestamp\":\"1785207447009\", \"event_type\":\"price_change\"}","received_at":"2026-07-28T02:57:27.303338Z","schema_version":"clob-market-ws.price_change.v1","sequence":null,"server_hash":null,"server_timestamp":"1785207447009","session_id":"5aad79be415c487c84df42bebd84ee93","source":"clob_market_ws"},"received_at":"2026-07-28T02:57:27.303338Z","record_id":"fd050d21a44e25a671a5a528db4fafd08ba7f03c015494ababfa5a26e57f4f86","schema_fingerprint":"4aa3821a28b0b7c2400bc59aba4bcc0a76e971dadd19610d3ad38c768e124dc7","schema_version":"edge-lab-recorder.raw.v1","sequence":null,"source":"clob_market_ws"}
{"event_at":"2026-07-28T02:57:27.012000Z","event_fingerprint":"b5289c709a9fbacb2a8c8fb22dfff87623ee5657c966f211371478524217c447","payload":{"connection_id":"955646bd8bf740759faf38750c0f263f","event_at":"2026-07-28T02:57:27.012000Z","event_type":"price_change","frame_hash":"375c47d2f8cb9fc28309efca0123d0ca1fdc0e078b497cb649138ea580c0ba33","frame_index":0,"kind":"data","monotonic_ns":309430322073125,"payload":{"event_type":"price_change","market":"0x0f70d07969bc69eaa97d0987de651885fdca02263688026aa11e7678af8f87aa","price_changes":[{"asset_id":"64053005904884194822931764831592250494815136296598204104072528088122126148949","best_ask":"0.53","best_bid":"0.52","hash":"599dfc7b0d083786b5f450e57bd7ee258a1aa9c7","price":"0.49","side":"BUY","size":"109.81"},{"asset_id":"58313761654877669244690227616056238030136603415514645252000528337391143520538","best_ask":"0.48","best_bid":"0.47","hash":"d17d27491c87eb9a758702b8d56e3200c0f83913","price":"0.51","side":"SELL","size":"109.81"}],"timestamp":"1785207447012"},"payload_hash":"2772395b32aa47d26d6bbfc704afc0f7b4c47039659889f0362b9b7eebfeb5d0","raw_frame":"{\"market\":\"0x0f70d07969bc69eaa97d0987de651885fdca02263688026aa11e7678af8f87aa\", \"price_changes\":[{\"asset_id\":\"64053005904884194822931764831592250494815136296598204104072528088122126148949\", \"price\":\"0.49\", \"size\":\"109.81\", \"side\":\"BUY\", \"hash\":\"599dfc7b0d083786b5f450e57bd7ee258a1aa9c7\", \"best_bid\":\"0.52\", \"best_ask\":\"0.53\"}, {\"asset_id\":\"58313761654877669244690227616056238030136603415514645252000528337391143520538\", \"price\":\"0.51\", \"size\":\"109.81\", \"side\":\"SELL\", \"hash\":\"d17d27491c87eb9a758702b8d56e3200c0f83913\", \"best_bid\":\"0.47\", \"best_ask\":\"0.48\"}], \"timestamp\":\"1785207447012\", \"event_type\":\"price_change\"}","received_at":"2026-07-28T02:57:27.304812Z","schema_version":"clob-market-ws.price_change.v1","sequence":null,"server_hash":null,"server_timestamp":"1785207447012","session_id":"5aad79be415c487c84df42bebd84ee93","source":"clob_market_ws"},"received_at":"2026-07-28T02:57:27.304812Z","record_id":"29d679c8e8a18f0a23a393e702aab254c6a4c332dd1b319523f607d937ccae6c","schema_fingerprint":"4aa3821a28b0b7c2400bc59aba4bcc0a76e971dadd19610d3ad38c768e124dc7","schema_version":"edge-lab-recorder.raw.v1","sequence":null,"source":"clob_market_ws"}
{"event_at":"2026-07-28T02:57:27.013000Z","event_fingerprint":"d8f4170076fd6630e37854c26d6afaa8870732406219a7ca3ec4efac093416fd","payload":{"connection_id":"955646bd8bf740759faf38750c0f263f","event_at":"2026-07-28T02:57:27.013000Z","event_type":"price_change","frame_hash":"374aad9d33156200b3499edf4c76c098a6127d20ce9c8b6b47cb603f235e7b8e","frame_index":0,"kind":"data","monotonic_ns":309430323457166,"payload":{"event_type":"price_change","market":"0x0f70d07969bc69eaa97d0987de651885fdca02263688026aa11e7678af8f87aa","price_changes":[{"asset_id":"58313761654877669244690227616056238030136603415514645252000528337391143520538","best_ask":"0.48","best_bid":"0.47","hash":"bd96736bdbe317ca635e5286ddf819b3944322f3","price":"0.38","side":"BUY","size":"235.84"},{"asset_id":"64053005904884194822931764831592250494815136296598204104072528088122126148949","best_ask":"0.53","best_bid":"0.52","hash":"587112d1a6ea3613ce320a8b09e1f0e18e58aa3d","price":"0.62","side":"SELL","size":"235.84"}],"timestamp":"1785207447013"},"payload_hash":"37c3a5d0c1f80eecfe796f8a5faab6ca4b38ce53c3eab91bab1c8afa3ba27cb4","raw_frame":"{\"market\":\"0x0f70d07969bc69eaa97d0987de651885fdca02263688026aa11e7678af8f87aa\", \"price_changes\":[{\"asset_id\":\"58313761654877669244690227616056238030136603415514645252000528337391143520538\", \"price\":\"0.38\", \"size\":\"235.84\", \"side\":\"BUY\", \"hash\":\"bd96736bdbe317ca635e5286ddf819b3944322f3\", \"best_bid\":\"0.47\", \"best_ask\":\"0.48\"}, {\"asset_id\":\"64053005904884194822931764831592250494815136296598204104072528088122126148949\", \"price\":\"0.62\", \"size\":\"235.84\", \"side\":\"SELL\", \"hash\":\"587112d1a6ea3613ce320a8b09e1f0e18e58aa3d\", \"best_bid\":\"0.52\", \"best_ask\":\"0.53\"}], \"timestamp\":\"1785207447013\", \"event_type\":\"price_change\"}","received_at":"2026-07-28T02:57:27.306197Z","schema_version":"clob-market-ws.price_change.v1","sequence":null,"server_hash":null,"server_timestamp":"1785207447013","session_id":"5aad79be415c487c84df42bebd84ee93","source":"clob_market_ws"},"received_at":"2026-07-28T02:57:27.306197Z","record_id":"2cd58084de5bbd46741d97a81e17655fe4778cf905e8c252730bbbb33216261a","schema_fingerprint":"4aa3821a28b0b7c2400bc59aba4bcc0a76e971dadd19610d3ad38c768e124dc7","schema_version":"edge-lab-recorder.raw.v1","sequence":null,"source":"clob_market_ws"}
{"event_at":"2026-07-28T02:57:27.013000Z","event_fingerprint":"e2079566755879fafb2c5f6a5bade1e249972fcd7f355699925d011472ef8f4f","payload":{"connection_id":"955646bd8bf740759faf38750c0f263f","event_at":"2026-07-28T02:57:27.013000Z","event_type":"price_change","frame_hash":"8d2bdf8157a4ba4da658967e385e4f0c1d2f15aa3703e82f39514c796582779b","frame_index":0,"kind":"data","monotonic_ns":309430324495166,"payload":{"event_type":"price_change","market":"0x0f70d07969bc69eaa97d0987de651885fdca02263688026aa11e7678af8f87aa","price_changes":[{"asset_id":"64053005904884194822931764831592250494815136296598204104072528088122126148949","best_ask":"0.53","best_bid":"0.52","hash":"8207373881817bccbfc527c4cb573c446a568197","price":"0.46","side":"BUY","size":"119.27"},{"asset_id":"58313761654877669244690227616056238030136603415514645252000528337391143520538","best_ask":"0.48","best_bid":"0.47","hash":"6309aca94adc787aed0a100c519b804f551e9234","price":"0.54","side":"SELL","size":"119.27"}],"timestamp":"1785207447013"},"payload_hash":"1b6b76bfb8a14277d6a1addd49f0d989704d67ec6c529fafcaa4b26b51637354","raw_frame":"{\"market\":\"0x0f70d07969bc69eaa97d0987de651885fdca02263688026aa11e7678af8f87aa\", \"price_changes\":[{\"asset_id\":\"64053005904884194822931764831592250494815136296598204104072528088122126148949\", \"price\":\"0.46\", \"size\":\"119.27\", \"side\":\"BUY\", \"hash\":\"8207373881817bccbfc527c4cb573c446a568197\", \"best_bid\":\"0.52\", \"best_ask\":\"0.53\"}, {\"asset_id\":\"58313761654877669244690227616056238030136603415514645252000528337391143520538\", \"price\":\"0.54\", \"size\":\"119.27\", \"side\":\"SELL\", \"hash\":\"6309aca94adc787aed0a100c519b804f551e9234\", \"best_bid\":\"0.47\", \"best_ask\":\"0.48\"}], \"timestamp\":\"1785207447013\", \"event_type\":\"price_change\"}","received_at":"2026-07-28T02:57:27.307235Z","schema_version":"clob-market-ws.price_change.v1","sequence":null,"server_hash":null,"server_timestamp":"1785207447013","session_id":"5aad79be415c487c84df42bebd84ee93","source":"clob_market_ws"},"received_at":"2026-07-28T02:57:27.307235Z","record_id":"4cb7278fb18dd7449d266149f32f3f8168a98f79233040095643826b060f6502","schema_fingerprint":"4aa3821a28b0b7c2400bc59aba4bcc0a76e971dadd19610d3ad38c768e124dc7","schema_version":"edge-lab-recorder.raw.v1","sequence":null,"source":"clob_market_ws"}
{"event_at":"2026-07-28T02:57:27.014000Z","event_fingerprint":"2636ba344086cd6d43f545d09ad225e844e6c5fb7f26bc19a9f4935c45d2ea70","payload":{"connection_id":"955646bd8bf740759faf38750c0f263f","event_at":"2026-07-28T02:57:27.014000Z","event_type":"price_change","frame_hash":"e573d96ac3dee86d59d01505347efe69e011a446b306740b76d70f6141e17f07","frame_index":0,"kind":"data","monotonic_ns":309430325953375,"payload":{"event_type":"price_change","market":"0x0f70d07969bc69eaa97d0987de651885fdca02263688026aa11e7678af8f87aa","price_changes":[{"asset_id":"58313761654877669244690227616056238030136603415514645252000528337391143520538","best_ask":"0.48","best_bid":"0.47","hash":"3c92036252ec3178a722146ca1702d5d9d23f2e0","price":"0.45","side":"BUY","size":"85.3"},{"asset_id":"64053005904884194822931764831592250494815136296598204104072528088122126148949","best_ask":"0.53","best_bid":"0.52","hash":"e4dd20628fd6df0a6ba1da485d48352685f84a1e","price":"0.55","side":"SELL","size":"85.3"}],"timestamp":"1785207447014"},"payload_hash":"50574b52a6890854fa01cc0aab673a19acaec4ce125282ed273f4d61b7c6841f","raw_frame":"{\"market\":\"0x0f70d07969bc69eaa97d0987de651885fdca02263688026aa11e7678af8f87aa\", \"price_changes\":[{\"asset_id\":\"58313761654877669244690227616056238030136603415514645252000528337391143520538\", \"price\":\"0.45\", \"size\":\"85.3\", \"side\":\"BUY\", \"hash\":\"3c92036252ec3178a722146ca1702d5d9d23f2e0\", \"best_bid\":\"0.47\", \"best_ask\":\"0.48\"}, {\"asset_id\":\"64053005904884194822931764831592250494815136296598204104072528088122126148949\", \"price\":\"0.55\", \"size\":\"85.3\", \"side\":\"SELL\", \"hash\":\"e4dd20628fd6df0a6ba1da485d48352685f84a1e\", \"best_bid\":\"0.52\", \"best_ask\":\"0.53\"}], \"timestamp\":\"1785207447014\", \"event_type\":\"price_change\"}","received_at":"2026-07-28T02:57:27.308691Z","schema_version":"clob-market-ws.price_change.v1","sequence":null,"server_hash":null,"server_timestamp":"1785207447014","session_id":"5aad79be415c487c84df42bebd84ee93","source":"clob_market_ws"},"received_at":"2026-07-28T02:57:27.308691Z","record_id":"ce2152745b1db5e5ec5569d39188c6f92b24a64d9d9434ebd292b27a24b62d8a","schema_fingerprint":"4aa3821a28b0b7c2400bc59aba4bcc0a76e971dadd19610d3ad38c768e124dc7","schema_version":"edge-lab-recorder.raw.v1","sequence":null,"source":"clob_market_ws"}
{"event_at":"2026-07-28T02:57:27.015000Z","event_fingerprint":"e0e83a9482f367ebeb70fd2db65fc3d37d18aeac5c4a41b844a115a5fef2b71d","payload":{"connection_id":"955646bd8bf740759faf38750c0f263f","event_at":"2026-07-28T02:57:27.015000Z","event_type":"price_change","frame_hash":"d90f5d2bacf93e7198df3ccd2034b4352383a0a9413a5886bb6352f47c55a34a","frame_index":0,"kind":"data","monotonic_ns":309430327413000,"payload":{"event_type":"price_change","market":"0x0f70d07969bc69eaa97d0987de651885fdca02263688026aa11e7678af8f87aa","price_changes":[{"asset_id":"58313761654877669244690227616056238030136603415514645252000528337391143520538","best_ask":"0.48","best_bid":"0.47","hash":"2e722a8864f6c87ddf05cd08acd55a83b51500ed","price":"0.45","side":"BUY","size":"91.6"},{"asset_id":"64053005904884194822931764831592250494815136296598204104072528088122126148949","best_ask":"0.53","best_bid":"0.52","hash":"bb149de886a178603b2d83a28ee6d6bc9d5c2361","price":"0.55","side":"SELL","size":"91.6"}],"timestamp":"1785207447015"},"payload_hash":"084766f6a4ed9ee0a0dd34229f6b2da41e7989c6fa4bc1a91cb97b1b68f0da22","raw_frame":"{\"market\":\"0x0f70d07969bc69eaa97d0987de651885fdca02263688026aa11e7678af8f87aa\", \"price_changes\":[{\"asset_id\":\"58313761654877669244690227616056238030136603415514645252000528337391143520538\", \"price\":\"0.45\", \"size\":\"91.6\", \"side\":\"BUY\", \"hash\":\"2e722a8864f6c87ddf05cd08acd55a83b51500ed\", \"best_bid\":\"0.47\", \"best_ask\":\"0.48\"}, {\"asset_id\":\"64053005904884194822931764831592250494815136296598204104072528088122126148949\", \"price\":\"0.55\", \"size\":\"91.6\", \"side\":\"SELL\", \"hash\":\"bb149de886a178603b2d83a28ee6d6bc9d5c2361\", \"best_bid\":\"0.52\", \"best_ask\":\"0.53\"}], \"timestamp\":\"1785207447015\", \"event_type\":\"price_change\"}","received_at":"2026-07-28T02:57:27.310152Z","schema_version":"clob-market-ws.price_change.v1","sequence":null,"server_hash":null,"server_timestamp":"1785207447015","session_id":"5aad79be415c487c84df42bebd84ee93","source":"clob_market_ws"},"received_at":"2026-07-28T02:57:27.310152Z","record_id":"b517291c294cf4fb8571c522addf99120b6b6f8c4c6c6eda0f0992cc36ed2f89","schema_fingerprint":"4aa3821a28b0b7c2400bc59aba4bcc0a76e971dadd19610d3ad38c768e124dc7","schema_version":"edge-lab-recorder.raw.v1","sequence":null,"source":"clob_market_ws"}
{"event_at":"2026-07-28T02:57:27.016000Z","event_fingerprint":"88b4a6be37e13c47afc2a80511a86a793d63466d60e5aa0c890b0a29adb12132","payload":{"connection_id":"955646bd8bf740759faf38750c0f263f","event_at":"2026-07-28T02:57:27.016000Z","event_type":"price_change","frame_hash":"b96d8ba120c7b945b976ffbdb3bdd63ba334e470e1eb2d7a25a67045f5c8621c","frame_index":0,"kind":"data","monotonic_ns":309430328866500,"payload":{"event_type":"price_change","market":"0x0f70d07969bc69eaa97d0987de651885fdca02263688026aa11e7678af8f87aa","price_changes":[{"asset_id":"58313761654877669244690227616056238030136603415514645252000528337391143520538","best_ask":"0.48","best_bid":"0.47","hash":"cc8ba0659d46486a4fede8da29fb62e848e3f913","price":"0.46","side":"BUY","size":"37.5"},{"asset_id":"64053005904884194822931764831592250494815136296598204104072528088122126148949","best_ask":"0.53","best_bid":"0.52","hash":"a9a4c7ac15b2f6426eb89cf854bdcae7827d7374","price":"0.54","side":"SELL","size":"37.5"}],"timestamp":"1785207447016"},"payload_hash":"ecf025bb9efa5cca4ae913a9b0b0aa102994024bc999d333f566c8649878b1a1","raw_frame":"{\"market\":\"0x0f70d07969bc69eaa97d0987de651885fdca02263688026aa11e7678af8f87aa\", \"price_changes\":[{\"asset_id\":\"58313761654877669244690227616056238030136603415514645252000528337391143520538\", \"price\":\"0.46\", \"size\":\"37.5\", \"side\":\"BUY\", \"hash\":\"cc8ba0659d46486a4fede8da29fb62e848e3f913\", \"best_bid\":\"0.47\", \"best_ask\":\"0.48\"}, {\"asset_id\":\"64053005904884194822931764831592250494815136296598204104072528088122126148949\", \"price\":\"0.54\", \"size\":\"37.5\", \"side\":\"SELL\", \"hash\":\"a9a4c7ac15b2f6426eb89cf854bdcae7827d7374\", \"best_bid\":\"0.52\", \"best_ask\":\"0.53\"}], \"timestamp\":\"1785207447016\", \"event_type\":\"price_change\"}","received_at":"2026-07-28T02:57:27.311606Z","schema_version":"clob-market-ws.price_change.v1","sequence":null,"server_hash":null,"server_timestamp":"1785207447016","session_id":"5aad79be415c487c84df42bebd84ee93","source":"clob_market_ws"},"received_at":"2026-07-28T02:57:27.311606Z","record_id":"01f9f56a0265a8f4e946995a6f9882adda7a61ff08b28af3cc11aa56371a6c55","schema_fingerprint":"4aa3821a28b0b7c2400bc59aba4bcc0a76e971dadd19610d3ad38c768e124dc7","schema_version":"edge-lab-recorder.raw.v1","sequence":null,"source":"clob_market_ws"}
{"event_at":"2026-07-28T02:57:27.016000Z","event_fingerprint":"104ee690e4d394644dd9cae180510cf0b606468ca66ee17bc6ec37383e6d62af","payload":{"connection_id":"955646bd8bf740759faf38750c0f263f","event_at":"2026-07-28T02:57:27.016000Z","event_type":"price_change","frame_hash":"d96b307bb2a91e6cd2a4cf4137e09e6a0990eb9b222cd4dfaf0e3393e80094c1","frame_index":0,"kind":"data","monotonic_ns":309430330283000,"payload":{"event_type":"price_change","market":"0x0f70d07969bc69eaa97d0987de651885fdca02263688026aa11e7678af8f87aa","price_changes":[{"asset_id":"58313761654877669244690227616056238030136603415514645252000528337391143520538","best_ask":"0.48","best_bid":"0.47","hash":"bcaed221bdbf70f247bdd8296b4ddea1fecb4861","price":"0.46","side":"BUY","size":"27"},{"asset_id":"64053005904884194822931764831592250494815136296598204104072528088122126148949","best_ask":"0.53","best_bid":"0.52","hash":"7ebb570cae273cc3bb576ad95d86bb5977d6b729","price":"0.54","side":"SELL","size":"27"}],"timestamp":"1785207447016"},"payload_hash":"cdb5330b324396a313236d5ab5839be3c83994ea64e726e25ecf40c880416a19","raw_frame":"{\"market\":\"0x0f70d07969bc69eaa97d0987de651885fdca02263688026aa11e7678af8f87aa\", \"price_changes\":[{\"asset_id\":\"58313761654877669244690227616056238030136603415514645252000528337391143520538\", \"price\":\"0.46\", \"size\":\"27\", \"side\":\"BUY\", \"hash\":\"bcaed221bdbf70f247bdd8296b4ddea1fecb4861\", \"best_bid\":\"0.47\", \"best_ask\":\"0.48\"}, {\"asset_id\":\"64053005904884194822931764831592250494815136296598204104072528088122126148949\", \"price\":\"0.54\", \"size\":\"27\", \"side\":\"SELL\", \"hash\":\"7ebb570cae273cc3bb576ad95d86bb5977d6b729\", \"best_bid\":\"0.52\", \"best_ask\":\"0.53\"}], \"timestamp\":\"1785207447016\", \"event_type\":\"price_change\"}","received_at":"2026-07-28T02:57:27.313022Z","schema_version":"clob-market-ws.price_change.v1","sequence":null,"server_hash":null,"server_timestamp":"1785207447016","session_id":"5aad79be415c487c84df42bebd84ee93","source":"clob_market_ws"},"received_at":"2026-07-28T02:57:27.313022Z","record_id":"4520a7dbd0be87d086a24d631490050ec104bc2ea2f38788a505535afc509e56","schema_fingerprint":"4aa3821a28b0b7c2400bc59aba4bcc0a76e971dadd19610d3ad38c768e124dc7","schema_version":"edge-lab-recorder.raw.v1","sequence":null,"source":"clob_market_ws"}
{"event_at":"2026-07-28T02:57:27.016000Z","event_fingerprint":"b8d4a9c82f16041f7fba43a846aea73b01fec91fa719aaa00b5321c1a6eab5c6","payload":{"connection_id":"955646bd8bf740759faf38750c0f263f","event_at":"2026-07-28T02:57:27.016000Z","event_type":"price_change","frame_hash":"3311cc1b57314036f2c4a9f3de32531db557ade2b8bea6c26888ed9a05f8843b","frame_index":0,"kind":"data","monotonic_ns":309430331816416,"payload":{"event_type":"price_change","market":"0x0f70d07969bc69eaa97d0987de651885fdca02263688026aa11e7678af8f87aa","price_changes":[{"asset_id":"64053005904884194822931764831592250494815136296598204104072528088122126148949","best_ask":"0.53","best_bid":"0.52","hash":"467b609ed59442e5b04ba53e24967ed69e52e56d","price":"0.48","side":"BUY","size":"52.99"},{"asset_id":"58313761654877669244690227616056238030136603415514645252000528337391143520538","best_ask":"0.48","best_bid":"0.47","hash":"c40f3d162462de8f270cdc0e0b4bb583bcb3f8d2","price":"0.52","side":"SELL","size":"52.99"}],"timestamp":"1785207447016"},"payload_hash":"49bb5dc05ba6153e115a6553b22bd504df33e7319ddb42e60de2832832fb4a22","raw_frame":"{\"market\":\"0x0f70d07969bc69eaa97d0987de651885fdca02263688026aa11e7678af8f87aa\", \"price_changes\":[{\"asset_id\":\"64053005904884194822931764831592250494815136296598204104072528088122126148949\", \"price\":\"0.48\", \"size\":\"52.99\", \"side\":\"BUY\", \"hash\":\"467b609ed59442e5b04ba53e24967ed69e52e56d\", \"best_bid\":\"0.52\", \"best_ask\":\"0.53\"}, {\"asset_id\":\"58313761654877669244690227616056238030136603415514645252000528337391143520538\", \"price\":\"0.52\", \"size\":\"52.99\", \"side\":\"SELL\", \"hash\":\"c40f3d162462de8f270cdc0e0b4bb583bcb3f8d2\", \"best_bid\":\"0.47\", \"best_ask\":\"0.48\"}], \"timestamp\":\"1785207447016\", \"event_type\":\"price_change\"}","received_at":"2026-07-28T02:57:27.314555Z","schema_version":"clob-market-ws.price_change.v1","sequence":null,"server_hash":null,"server_timestamp":"1785207447016","session_id":"5aad79be415c487c84df42bebd84ee93","source":"clob_market_ws"},"received_at":"2026-07-28T02:57:27.314555Z","record_id":"566b17e9994a9d2baca6220c9d7bbd9ce40fbfb8ce3f41c4105ce26b1900055e","schema_fingerprint":"4aa3821a28b0b7c2400bc59aba4bcc0a76e971dadd19610d3ad38c768e124dc7","schema_version":"edge-lab-recorder.raw.v1","sequence":null,"source":"clob_market_ws"}
{"event_at":"2026-07-28T02:57:27.017000Z","event_fingerprint":"997702f267b15b794aac43508c9dbb2e868ddff4b0f2d34e0acd30d2b585c052","payload":{"connection_id":"955646bd8bf740759faf38750c0f263f","event_at":"2026-07-28T02:57:27.017000Z","event_type":"price_change","frame_hash":"94bb7487724efe3f8e174c96dc286b90ce9cf0dd21294001e9bb9c416589eadb","frame_index":0,"kind":"data","monotonic_ns":309430333466625,"payload":{"event_type":"price_change","market":"0x0f70d07969bc69eaa97d0987de651885fdca02263688026aa11e7678af8f87aa","price_changes":[{"asset_id":"58313761654877669244690227616056238030136603415514645252000528337391143520538","best_ask":"0.48","best_bid":"0.47","hash":"5c23fd58a66984941366dc3d5350909cba353437","price":"0.45","side":"BUY","size":"100"},{"asset_id":"64053005904884194822931764831592250494815136296598204104072528088122126148949","best_ask":"0.53","best_bid":"0.52","hash":"feaf5a9283c1a429263fb792e01b458d067fb5c0","price":"0.55","side":"SELL","size":"100"}],"timestamp":"1785207447017"},"payload_hash":"00a905f1599a0551ce44117185e15ceff7febf3a6e53b12612c0ec7c37812f45","raw_frame":"{\"market\":\"0x0f70d07969bc69eaa97d0987de651885fdca02263688026aa11e7678af8f87aa\", \"price_changes\":[{\"asset_id\":\"58313761654877669244690227616056238030136603415514645252000528337391143520538\", \"price\":\"0.45\", \"size\":\"100\", \"side\":\"BUY\", \"hash\":\"5c23fd58a66984941366dc3d5350909cba353437\", \"best_bid\":\"0.47\", \"best_ask\":\"0.48\"}, {\"asset_id\":\"64053005904884194822931764831592250494815136296598204104072528088122126148949\", \"price\":\"0.55\", \"size\":\"100\", \"side\":\"SELL\", \"hash\":\"feaf5a9283c1a429263fb792e01b458d067fb5c0\", \"best_bid\":\"0.52\", \"best_ask\":\"0.53\"}], \"timestamp\":\"1785207447017\", \"event_type\":\"price_change\"}","received_at":"2026-07-28T02:57:27.316204Z","schema_version":"clob-market-ws.price_change.v1","sequence":null,"server_hash":null,"server_timestamp":"1785207447017","session_id":"5aad79be415c487c84df42bebd84ee93","source":"clob_market_ws"},"received_at":"2026-07-28T02:57:27.316204Z","record_id":"42919e6ddd8a36c77d3d1c3075453f547796edce5a21b4232f483ab34b4e6dac","schema_fingerprint":"4aa3821a28b0b7c2400bc59aba4bcc0a76e971dadd19610d3ad38c768e124dc7","schema_version":"edge-lab-recorder.raw.v1","sequence":null,"source":"clob_market_ws"}
{"event_at":"2026-07-28T02:57:27.018000Z","event_fingerprint":"2d5df656f8b05231057d4be21bb90409305dd9e26c95c31dee07bd316075ad6a","payload":{"connection_id":"955646bd8bf740759faf38750c0f263f","event_at":"2026-07-28T02:57:27.018000Z","event_type":"price_change","frame_hash":"9696d571f0cf978b3deac2fdc1c02e0896040e0b957f8151b25ccec54b36694e","frame_index":0,"kind":"data","monotonic_ns":309430335050041,"payload":{"event_type":"price_change","market":"0x0f70d07969bc69eaa97d0987de651885fdca02263688026aa11e7678af8f87aa","price_changes":[{"asset_id":"64053005904884194822931764831592250494815136296598204104072528088122126148949","best_ask":"0.53","best_bid":"0.52","hash":"8b33bce255f84302f5bc176fc13c517ff71ab217","price":"0.49","side":"BUY","size":"116.11"},{"asset_id":"58313761654877669244690227616056238030136603415514645252000528337391143520538","best_ask":"0.48","best_bid":"0.47","hash":"d8d2948fcd6b075ea7b7f2aea604fbd08d93d846","price":"0.51","side":"SELL","size":"116.11"}],"timestamp":"1785207447018"},"payload_hash":"e1703f5c5b957ea92dea608743ee111a770502d4d86d96299e39937c02afce17","raw_frame":"{\"market\":\"0x0f70d07969bc69eaa97d0987de651885fdca02263688026aa11e7678af8f87aa\", \"price_changes\":[{\"asset_id\":\"64053005904884194822931764831592250494815136296598204104072528088122126148949\", \"price\":\"0.49\", \"size\":\"116.11\", \"side\":\"BUY\", \"hash\":\"8b33bce255f84302f5bc176fc13c517ff71ab217\", \"best_bid\":\"0.52\", \"best_ask\":\"0.53\"}, {\"asset_id\":\"58313761654877669244690227616056238030136603415514645252000528337391143520538\", \"price\":\"0.51\", \"size\":\"116.11\", \"side\":\"SELL\", \"hash\":\"d8d2948fcd6b075ea7b7f2aea604fbd08d93d846\", \"best_bid\":\"0.47\", \"best_ask\":\"0.48\"}], \"timestamp\":\"1785207447018\", \"event_type\":\"price_change\"}","received_at":"2026-07-28T02:57:27.317788Z","schema_version":"clob-market-ws.price_change.v1","sequence":null,"server_hash":null,"server_timestamp":"1785207447018","session_id":"5aad79be415c487c84df42bebd84ee93","source":"clob_market_ws"},"received_at":"2026-07-28T02:57:27.317788Z","record_id":"71de5bb3ff248d4085805cca82a7a37aeb663d10388d60dc66ae3372ce4f7523","schema_fingerprint":"4aa3821a28b0b7c2400bc59aba4bcc0a76e971dadd19610d3ad38c768e124dc7","schema_version":"edge-lab-recorder.raw.v1","sequence":null,"source":"clob_market_ws"}
{"event_at":"2026-07-28T02:57:27.019000Z","event_fingerprint":"66032c39ad7eb8429124fe6b9cd7839cbdfef9a4a484443039d1487e2b50362c","payload":{"connection_id":"955646bd8bf740759faf38750c0f263f","event_at":"2026-07-28T02:57:27.019000Z","event_type":"price_change","frame_hash":"74c93884e81fa291e4610a5b21d74cc16de0bbf105843ba47e9bb93757dcd2d4","frame_index":0,"kind":"data","monotonic_ns":309430336582833,"payload":{"event_type":"price_change","market":"0x0f70d07969bc69eaa97d0987de651885fdca02263688026aa11e7678af8f87aa","price_changes":[{"asset_id":"64053005904884194822931764831592250494815136296598204104072528088122126148949","best_ask":"0.53","best_bid":"0.52","hash":"92e7f33e8f7719e64565a2cbef07e05b6fa3eef9","price":"0.01","side":"BUY","size":"2592.52"},{"asset_id":"58313761654877669244690227616056238030136603415514645252000528337391143520538","best_ask":"0.48","best_bid":"0.47","hash":"366ee1ef3a2426ff4b6007d6fdfd7d15d547c6cb","price":"0.99","side":"SELL","size":"2592.52"}],"timestamp":"1785207447019"},"payload_hash":"a3063b174310c0bccdccfd99cbf732b3acb880dc648e0fa29099245b1fa781be","raw_frame":"{\"market\":\"0x0f70d07969bc69eaa97d0987de651885fdca02263688026aa11e7678af8f87aa\", \"price_changes\":[{\"asset_id\":\"64053005904884194822931764831592250494815136296598204104072528088122126148949\", \"price\":\"0.01\", \"size\":\"2592.52\", \"side\":\"BUY\", \"hash\":\"92e7f33e8f7719e64565a2cbef07e05b6fa3eef9\", \"best_bid\":\"0.52\", \"best_ask\":\"0.53\"}, {\"asset_id\":\"58313761654877669244690227616056238030136603415514645252000528337391143520538\", \"price\":\"0.99\", \"size\":\"2592.52\", \"side\":\"SELL\", \"hash\":\"366ee1ef3a2426ff4b6007d6fdfd7d15d547c6cb\", \"best_bid\":\"0.47\", \"best_ask\":\"0.48\"}], \"timestamp\":\"1785207447019\", \"event_type\":\"price_change\"}","received_at":"2026-07-28T02:57:27.319319Z","schema_version":"clob-market-ws.price_change.v1","sequence":null,"server_hash":null,"server_timestamp":"1785207447019","session_id":"5aad79be415c487c84df42bebd84ee93","source":"clob_market_ws"},"received_at":"2026-07-28T02:57:27.319319Z","record_id":"72f74461efd4d2c0138b9af082969196f9662b5d5311a0e7e9a08120870e233c","schema_fingerprint":"4aa3821a28b0b7c2400bc59aba4bcc0a76e971dadd19610d3ad38c768e124dc7","schema_version":"edge-lab-recorder.raw.v1","sequence":null,"source":"clob_market_ws"}
{"event_at":"2026-07-28T02:57:27.020000Z","event_fingerprint":"30fe877b5483a53092ac6346697d35ff5112a271529f6993606a0fdde8b352c4","payload":{"connection_id":"955646bd8bf740759faf38750c0f263f","event_at":"2026-07-28T02:57:27.020000Z","event_type":"price_change","frame_hash":"4a872391f060847d9786fe44d32535cf423326b0887cab228d52139522b22ef9","frame_index":0,"kind":"data","monotonic_ns":309430338198791,"payload":{"event_type":"price_change","market":"0x0f70d07969bc69eaa97d0987de651885fdca02263688026aa11e7678af8f87aa","price_changes":[{"asset_id":"64053005904884194822931764831592250494815136296598204104072528088122126148949","best_ask":"0.53","best_bid":"0.52","hash":"bf357259c92e707d9653eb6cc92d2c7a9f261338","price":"0.51","side":"BUY","size":"116.1"},{"asset_id":"58313761654877669244690227616056238030136603415514645252000528337391143520538","best_ask":"0.48","best_bid":"0.47","hash":"6b0703538cd46d743beb412a3234aa8b14c9d37b","price":"0.49","side":"SELL","size":"116.1"}],"timestamp":"1785207447020"},"payload_hash":"299972f71b82ed1dd02571063599696b2b36319bec23ec0362cb61d9377e50ed","raw_frame":"{\"market\":\"0x0f70d07969bc69eaa97d0987de651885fdca02263688026aa11e7678af8f87aa\", \"price_changes\":[{\"asset_id\":\"64053005904884194822931764831592250494815136296598204104072528088122126148949\", \"price\":\"0.51\", \"size\":\"116.1\", \"side\":\"BUY\", \"hash\":\"bf357259c92e707d9653eb6cc92d2c7a9f261338\", \"best_bid\":\"0.52\", \"best_ask\":\"0.53\"}, {\"asset_id\":\"58313761654877669244690227616056238030136603415514645252000528337391143520538\", \"price\":\"0.49\", \"size\":\"116.1\", \"side\":\"SELL\", \"hash\":\"6b0703538cd46d743beb412a3234aa8b14c9d37b\", \"best_bid\":\"0.47\", \"best_ask\":\"0.48\"}], \"timestamp\":\"1785207447020\", \"event_type\":\"price_change\"}","received_at":"2026-07-28T02:57:27.320936Z","schema_version":"clob-market-ws.price_change.v1","sequence":null,"server_hash":null,"server_timestamp":"1785207447020","session_id":"5aad79be415c487c84df42bebd84ee93","source":"clob_market_ws"},"received_at":"2026-07-28T02:57:27.320936Z","record_id":"513f47e124384960bc1efd844af7837dfa8290f86e728059f332190f07b3dff3","schema_fingerprint":"4aa3821a28b0b7c2400bc59aba4bcc0a76e971dadd19610d3ad38c768e124dc7","schema_version":"edge-lab-recorder.raw.v1","sequence":null,"source":"clob_market_ws"}
{"event_at":"2026-07-28T02:57:27.020000Z","event_fingerprint":"a10b3f83d7d627c02a4b6089c56dd489040ace0ed98720a7ff793ef7b3689f3a","payload":{"connection_id":"955646bd8bf740759faf38750c0f263f","event_at":"2026-07-28T02:57:27.020000Z","event_type":"price_change","frame_hash":"001d6faea8dfebd28c8f1028d5798a0ecdd64fbf52db50326bd495068b2052c7","frame_index":0,"kind":"data","monotonic_ns":309430339706791,"payload":{"event_type":"price_change","market":"0x0f70d07969bc69eaa97d0987de651885fdca02263688026aa11e7678af8f87aa","price_changes":[{"asset_id":"58313761654877669244690227616056238030136603415514645252000528337391143520538","best_ask":"0.48","best_bid":"0.47","hash":"ba12eec1f78445edbe310c97cba6bd8c08486d80","price":"0.46","side":"BUY","size":"20.7"},{"asset_id":"64053005904884194822931764831592250494815136296598204104072528088122126148949","best_ask":"0.53","best_bid":"0.52","hash":"f1f4ee1890d0569c58aa6e842e907ee6cae89620","price":"0.54","side":"SELL","size":"20.7"}],"timestamp":"1785207447020"},"payload_hash":"e9aa2e16bc2b96320e5c2c998edd9006580fde348254554ebe3640c43b4b3838","raw_frame":"{\"market\":\"0x0f70d07969bc69eaa97d0987de651885fdca02263688026aa11e7678af8f87aa\", \"price_changes\":[{\"asset_id\":\"58313761654877669244690227616056238030136603415514645252000528337391143520538\", \"price\":\"0.46\", \"size\":\"20.7\", \"side\":\"BUY\", \"hash\":\"ba12eec1f78445edbe310c97cba6bd8c08486d80\", \"best_bid\":\"0.47\", \"best_ask\":\"0.48\"}, {\"asset_id\":\"64053005904884194822931764831592250494815136296598204104072528088122126148949\", \"price\":\"0.54\", \"size\":\"20.7\", \"side\":\"SELL\", \"hash\":\"f1f4ee1890d0569c58aa6e842e907ee6cae89620\", \"best_bid\":\"0.52\", \"best_ask\":\"0.53\"}], \"timestamp\":\"1785207447020\", \"event_type\":\"price_change\"}","received_at":"2026-07-28T02:57:27.322444Z","schema_version":"clob-market-ws.price_change.v1","sequence":null,"server_hash":null,"server_timestamp":"1785207447020","session_id":"5aad79be415c487c84df42bebd84ee93","source":"clob_market_ws"},"received_at":"2026-07-28T02:57:27.322444Z","record_id":"62e021d69c966350bf32d72feb5aca8a532db2b7f4f86854241fb13953833df4","schema_fingerprint":"4aa3821a28b0b7c2400bc59aba4bcc0a76e971dadd19610d3ad38c768e124dc7","schema_version":"edge-lab-recorder.raw.v1","sequence":null,"source":"clob_market_ws"}
{"event_at":"2026-07-28T02:57:27.021000Z","event_fingerprint":"ba0c546514e0d54d91034ed9494e06fc3d6b1a46a4efa19367a54601dfa277e0","payload":{"connection_id":"955646bd8bf740759faf38750c0f263f","event_at":"2026-07-28T02:57:27.021000Z","event_type":"price_change","frame_hash":"bbc9d1fd3af13e7c81efed86bb6c5939a68da8ee72592146e53582034eff0799","frame_index":0,"kind":"data","monotonic_ns":309430341202041,"payload":{"event_type":"price_change","market":"0x0f70d07969bc69eaa97d0987de651885fdca02263688026aa11e7678af8f87aa","price_changes":[{"asset_id":"58313761654877669244690227616056238030136603415514645252000528337391143520538","best_ask":"0.48","best_bid":"0.47","hash":"ff528f3db5b0d70862310dbcaa1bac9ad5b4d4ce","price":"0.44","side":"BUY","size":"265.61"},{"asset_id":"64053005904884194822931764831592250494815136296598204104072528088122126148949","best_ask":"0.53","best_bid":"0.52","hash":"beabfb30561181e32c844ae3aad4ec7cd1488c55","price":"0.56","side":"SELL","size":"265.61"}],"timestamp":"1785207447021"},"payload_hash":"63d9bac9773ebe5df71fefdb5ad0ae553e5e74ba378562e536954081458ca967","raw_frame":"{\"market\":\"0x0f70d07969bc69eaa97d0987de651885fdca02263688026aa11e7678af8f87aa\", \"price_changes\":[{\"asset_id\":\"58313761654877669244690227616056238030136603415514645252000528337391143520538\", \"price\":\"0.44\", \"size\":\"265.61\", \"side\":\"BUY\", \"hash\":\"ff528f3db5b0d70862310dbcaa1bac9ad5b4d4ce\", \"best_bid\":\"0.47\", \"best_ask\":\"0.48\"}, {\"asset_id\":\"64053005904884194822931764831592250494815136296598204104072528088122126148949\", \"price\":\"0.56\", \"size\":\"265.61\", \"side\":\"SELL\", \"hash\":\"beabfb30561181e32c844ae3aad4ec7cd1488c55\", \"best_bid\":\"0.52\", \"best_ask\":\"0.53\"}], \"timestamp\":\"1785207447021\", \"event_type\":\"price_change\"}","received_at":"2026-07-28T02:57:27.323940Z","schema_version":"clob-market-ws.price_change.v1","sequence":null,"server_hash":null,"server_timestamp":"1785207447021","session_id":"5aad79be415c487c84df42bebd84ee93","source":"clob_market_ws"},"received_at":"2026-07-28T02:57:27.323940Z","record_id":"c9f826116e0a2fd517b7b2d60ce5d05ef122d55ee6abd947b59a3431aa42a468","schema_fingerprint":"4aa3821a28b0b7c2400bc59aba4bcc0a76e971dadd19610d3ad38c768e124dc7","schema_version":"edge-lab-recorder.raw.v1","sequence":null,"source":"clob_market_ws"}
{"event_at":"2026-07-28T02:57:27.021000Z","event_fingerprint":"2d010531cfa697a28b622a2ac75296944c0183e208630ab1c2bd4639e9ea9bba","payload":{"connection_id":"955646bd8bf740759faf38750c0f263f","event_at":"2026-07-28T02:57:27.021000Z","event_type":"price_change","frame_hash":"65f40113ed3ba19631b4eaa0a2a7f64d521da1be4c16c8ec76383a1f47844f9d","frame_index":0,"kind":"data","monotonic_ns":309430342623458,"payload":{"event_type":"price_change","market":"0x0f70d07969bc69eaa97d0987de651885fdca02263688026aa11e7678af8f87aa","price_changes":[{"asset_id":"64053005904884194822931764831592250494815136296598204104072528088122126148949","best_ask":"0.53","best_bid":"0.52","hash":"b40182d8172d85de901189722b5badd9d3ebd619","price":"0.5","side":"BUY","size":"130.5"},{"asset_id":"58313761654877669244690227616056238030136603415514645252000528337391143520538","best_ask":"0.48","best_bid":"0.47","hash":"ecd3e2ac683b50c6dcf7a161ad05ce518ddca39c","price":"0.5","side":"SELL","size":"130.5"}],"timestamp":"1785207447021"},"payload_hash":"45de49fb6bf164dd2c0b6cb6a5e4acd86528ad8140b6fd1f57a9091f4b98c85d","raw_frame":"{\"market\":\"0x0f70d07969bc69eaa97d0987de651885fdca02263688026aa11e7678af8f87aa\", \"price_changes\":[{\"asset_id\":\"64053005904884194822931764831592250494815136296598204104072528088122126148949\", \"price\":\"0.5\", \"size\":\"130.5\", \"side\":\"BUY\", \"hash\":\"b40182d8172d85de901189722b5badd9d3ebd619\", \"best_bid\":\"0.52\", \"best_ask\":\"0.53\"}, {\"asset_id\":\"58313761654877669244690227616056238030136603415514645252000528337391143520538\", \"price\":\"0.5\", \"size\":\"130.5\", \"side\":\"SELL\", \"hash\":\"ecd3e2ac683b50c6dcf7a161ad05ce518ddca39c\", \"best_bid\":\"0.47\", \"best_ask\":\"0.48\"}], \"timestamp\":\"1785207447021\", \"event_type\":\"price_change\"}","received_at":"2026-07-28T02:57:27.325366Z","schema_version":"clob-market-ws.price_change.v1","sequence":null,"server_hash":null,"server_timestamp":"1785207447021","session_id":"5aad79be415c487c84df42bebd84ee93","source":"clob_market_ws"},"received_at":"2026-07-28T02:57:27.325366Z","record_id":"e34e2b6cdb13d54205ebf93779940931f2cc40fd36c4f24fbf81f3ba73b5c9f4","schema_fingerprint":"4aa3821a28b0b7c2400bc59aba4bcc0a76e971dadd19610d3ad38c768e124dc7","schema_version":"edge-lab-recorder.raw.v1","sequence":null,"source":"clob_market_ws"}
{"event_at":"2026-07-28T02:57:27.023000Z","event_fingerprint":"0bb6ea9bd5d50ecca4b872d7caae6f33826df323dc8fd56cbfb82840f69befa3","payload":{"connection_id":"955646bd8bf740759faf38750c0f263f","event_at":"2026-07-28T02:57:27.023000Z","event_type":"price_change","frame_hash":"896d81718420f8f29519f0e6801191814ff62b74893261ecd3be13e258721d00","frame_index":0,"kind":"data","monotonic_ns":309430343557458,"payload":{"event_type":"price_change","market":"0x0f70d07969bc69eaa97d0987de651885fdca02263688026aa11e7678af8f87aa","price_changes":[{"asset_id":"58313761654877669244690227616056238030136603415514645252000528337391143520538","best_ask":"0.48","best_bid":"0.47","hash":"51fcfe9fb0d1cc31343715063886502ab16235ae","price":"0.01","side":"BUY","size":"2381.24"},{"asset_id":"64053005904884194822931764831592250494815136296598204104072528088122126148949","best_ask":"0.53","best_bid":"0.52","hash":"09c5d2d1303db2befdf1792d92026dde07be04dc","price":"0.99","side":"SELL","size":"2381.24"}],"timestamp":"1785207447023"},"payload_hash":"e5516e963c3c91639bc8a9475e55c88aa2735aeedd2f6fa52049de1d77dac1e8","raw_frame":"{\"market\":\"0x0f70d07969bc69eaa97d0987de651885fdca02263688026aa11e7678af8f87aa\", \"price_changes\":[{\"asset_id\":\"58313761654877669244690227616056238030136603415514645252000528337391143520538\", \"price\":\"0.01\", \"size\":\"2381.24\", \"side\":\"BUY\", \"hash\":\"51fcfe9fb0d1cc31343715063886502ab16235ae\", \"best_bid\":\"0.47\", \"best_ask\":\"0.48\"}, {\"asset_id\":\"64053005904884194822931764831592250494815136296598204104072528088122126148949\", \"price\":\"0.99\", \"size\":\"2381.24\", \"side\":\"SELL\", \"hash\":\"09c5d2d1303db2befdf1792d92026dde07be04dc\", \"best_bid\":\"0.52\", \"best_ask\":\"0.53\"}], \"timestamp\":\"1785207447023\", \"event_type\":\"price_change\"}","received_at":"2026-07-28T02:57:27.326300Z","schema_version":"clob-market-ws.price_change.v1","sequence":null,"server_hash":null,"server_timestamp":"1785207447023","session_id":"5aad79be415c487c84df42bebd84ee93","source":"clob_market_ws"},"received_at":"2026-07-28T02:57:27.326300Z","record_id":"234009b0067d7961690ed5421af18d3251ebb78535842df3856ba27fe5bf09a9","schema_fingerprint":"4aa3821a28b0b7c2400bc59aba4bcc0a76e971dadd19610d3ad38c768e124dc7","schema_version":"edge-lab-recorder.raw.v1","sequence":null,"source":"clob_market_ws"}
{"event_at":"2026-07-28T02:57:27.026000Z","event_fingerprint":"3785f635e6379a946bbf6a1287743dcbd0a85d74ac880ec1b69bb9ff91f022a2","payload":{"connection_id":"955646bd8bf740759faf38750c0f263f","event_at":"2026-07-28T02:57:27.026000Z","event_type":"price_change","frame_hash":"48d1b4d9d23183129ceda9360602be41a46382cd5e23e77690aefa041313a2be","frame_index":0,"kind":"data","monotonic_ns":309430344528333,"payload":{"event_type":"price_change","market":"0x0f70d07969bc69eaa97d0987de651885fdca02263688026aa11e7678af8f87aa","price_changes":[{"asset_id":"58313761654877669244690227616056238030136603415514645252000528337391143520538","best_ask":"0.48","best_bid":"0.47","hash":"99d8f1e115faeab1ec6c34ab5a7e17eb6d57a0fa","price":"0.01","side":"BUY","size":"2386.24"},{"asset_id":"64053005904884194822931764831592250494815136296598204104072528088122126148949","best_ask":"0.53","best_bid":"0.52","hash":"d7eb7d9ee383948508b083218dbb61a58b823491","price":"0.99","side":"SELL","size":"2386.24"}],"timestamp":"1785207447026"},"payload_hash":"919a6f1f1345d89665ab782a0d526ae000a738eab096cf1c4c1d624b4ab2b853","raw_frame":"{\"market\":\"0x0f70d07969bc69eaa97d0987de651885fdca02263688026aa11e7678af8f87aa\", \"price_changes\":[{\"asset_id\":\"58313761654877669244690227616056238030136603415514645252000528337391143520538\", \"price\":\"0.01\", \"size\":\"2386.24\", \"side\":\"BUY\", \"hash\":\"99d8f1e115faeab1ec6c34ab5a7e17eb6d57a0fa\", \"best_bid\":\"0.47\", \"best_ask\":\"0.48\"}, {\"asset_id\":\"64053005904884194822931764831592250494815136296598204104072528088122126148949\", \"price\":\"0.99\", \"size\":\"2386.24\", \"side\":\"SELL\", \"hash\":\"d7eb7d9ee383948508b083218dbb61a58b823491\", \"best_bid\":\"0.52\", \"best_ask\":\"0.53\"}], \"timestamp\":\"1785207447026\", \"event_type\":\"price_change\"}","received_at":"2026-07-28T02:57:27.327266Z","schema_version":"clob-market-ws.price_change.v1","sequence":null,"server_hash":null,"server_timestamp":"1785207447026","session_id":"5aad79be415c487c84df42bebd84ee93","source":"clob_market_ws"},"received_at":"2026-07-28T02:57:27.327266Z","record_id":"c118712cd1b26ff4dda569cd194db2b01aa7de5dc9882c54982c69e29788a256","schema_fingerprint":"4aa3821a28b0b7c2400bc59aba4bcc0a76e971dadd19610d3ad38c768e124dc7","schema_version":"edge-lab-recorder.raw.v1","sequence":null,"source":"clob_market_ws"}
{"event_at":"2026-07-28T02:57:27.030000Z","event_fingerprint":"666641555cb163b81bd503899e9631ecc2892e5ef89dd60ae1bca6f4f430d6d0","payload":{"connection_id":"955646bd8bf740759faf38750c0f263f","event_at":"2026-07-28T02:57:27.030000Z","event_type":"price_change","frame_hash":"959a4786c78374696712077c07d09c3e189e5180279390cf6e0dbe3929cf984d","frame_index":0,"kind":"data","monotonic_ns":309430346068916,"payload":{"event_type":"price_change","market":"0x0f70d07969bc69eaa97d0987de651885fdca02263688026aa11e7678af8f87aa","price_changes":[{"asset_id":"64053005904884194822931764831592250494815136296598204104072528088122126148949","best_ask":"0.53","best_bid":"0.52","hash":"ebe1c63b883daff391bc4a95ebb03a38755549db","price":"0.42","side":"BUY","size":"117"},{"asset_id":"58313761654877669244690227616056238030136603415514645252000528337391143520538","best_ask":"0.48","best_bid":"0.47","hash":"194ff38e537210a2453717f772545723cea75032","price":"0.58","side":"SELL","size":"117"}],"timestamp":"1785207447030"},"payload_hash":"2ab899a2a76b617972c9f6e575e68941a7eb8ac61d4fba10fc672760a1848793","raw_frame":"{\"market\":\"0x0f70d07969bc69eaa97d0987de651885fdca02263688026aa11e7678af8f87aa\", \"price_changes\":[{\"asset_id\":\"64053005904884194822931764831592250494815136296598204104072528088122126148949\", \"price\":\"0.42\", \"size\":\"117\", \"side\":\"BUY\", \"hash\":\"ebe1c63b883daff391bc4a95ebb03a38755549db\", \"best_bid\":\"0.52\", \"best_ask\":\"0.53\"}, {\"asset_id\":\"58313761654877669244690227616056238030136603415514645252000528337391143520538\", \"price\":\"0.58\", \"size\":\"117\", \"side\":\"SELL\", \"hash\":\"194ff38e537210a2453717f772545723cea75032\", \"best_bid\":\"0.47\", \"best_ask\":\"0.48\"}], \"timestamp\":\"1785207447030\", \"event_type\":\"price_change\"}","received_at":"2026-07-28T02:57:27.328806Z","schema_version":"clob-market-ws.price_change.v1","sequence":null,"server_hash":null,"server_timestamp":"1785207447030","session_id":"5aad79be415c487c84df42bebd84ee93","source":"clob_market_ws"},"received_at":"2026-07-28T02:57:27.328806Z","record_id":"9d9faf20f8e9d596db6bd61446b3d29b2a40e097a7d64bcc6c3cfec057c8b061","schema_fingerprint":"4aa3821a28b0b7c2400bc59aba4bcc0a76e971dadd19610d3ad38c768e124dc7","schema_version":"edge-lab-recorder.raw.v1","sequence":null,"source":"clob_market_ws"}
{"event_at":"2026-07-28T02:57:27.034000Z","event_fingerprint":"b3f41c25fc7bbd8f82b8da3602b46f954b8874eedecf7b6ad642de5f316d75d9","payload":{"connection_id":"955646bd8bf740759faf38750c0f263f","event_at":"2026-07-28T02:57:27.034000Z","event_type":"price_change","frame_hash":"718fee3d4b85a8450ca23fe44c2a37388642b2200fbd9c9a6304f3cf94c1a454","frame_index":0,"kind":"data","monotonic_ns":309430347589375,"payload":{"event_type":"price_change","market":"0x0f70d07969bc69eaa97d0987de651885fdca02263688026aa11e7678af8f87aa","price_changes":[{"asset_id":"64053005904884194822931764831592250494815136296598204104072528088122126148949","best_ask":"0.53","best_bid":"0.52","hash":"418ab1c2e1b9bed944ff52e32491e54d1cea5f4b","price":"0.42","side":"BUY","size":"167"},{"asset_id":"58313761654877669244690227616056238030136603415514645252000528337391143520538","best_ask":"0.48","best_bid":"0.47","hash":"ce25b7346a9efe9e19761ff5769d5e856f48b9eb","price":"0.58","side":"SELL","size":"167"}],"timestamp":"1785207447034"},"payload_hash":"9b442eba7a12feb7b292027c13fb82d4c654db0d1467926e7c091262d25b1266","raw_frame":"{\"market\":\"0x0f70d07969bc69eaa97d0987de651885fdca02263688026aa11e7678af8f87aa\", \"price_changes\":[{\"asset_id\":\"64053005904884194822931764831592250494815136296598204104072528088122126148949\", \"price\":\"0.42\", \"size\":\"167\", \"side\":\"BUY\", \"hash\":\"418ab1c2e1b9bed944ff52e32491e54d1cea5f4b\", \"best_bid\":\"0.52\", \"best_ask\":\"0.53\"}, {\"asset_id\":\"58313761654877669244690227616056238030136603415514645252000528337391143520538\", \"price\":\"0.58\", \"size\":\"167\", \"side\":\"SELL\", \"hash\":\"ce25b7346a9efe9e19761ff5769d5e856f48b9eb\", \"best_bid\":\"0.47\", \"best_ask\":\"0.48\"}], \"timestamp\":\"1785207447034\", \"event_type\":\"price_change\"}","received_at":"2026-07-28T02:57:27.330329Z","schema_version":"clob-market-ws.price_change.v1","sequence":null,"server_hash":null,"server_timestamp":"1785207447034","session_id":"5aad79be415c487c84df42bebd84ee93","source":"clob_market_ws"},"received_at":"2026-07-28T02:57:27.330329Z","record_id":"a5fa4565a1fe3f99f8469edf719a651b1747bbdcf16d8b9b9ccca138c70b8a10","schema_fingerprint":"4aa3821a28b0b7c2400bc59aba4bcc0a76e971dadd19610d3ad38c768e124dc7","schema_version":"edge-lab-recorder.raw.v1","sequence":null,"source":"clob_market_ws"}
{"event_at":"2026-07-28T02:57:27.035000Z","event_fingerprint":"4fa13b10e5b23589f5bda140cf87fed6c58dd8e42932e543dc261a483f721b0d","payload":{"connection_id":"955646bd8bf740759faf38750c0f263f","event_at":"2026-07-28T02:57:27.035000Z","event_type":"price_change","frame_hash":"6509724e2ecb87b5fa6e354971984840fb73d642fdbbd8449887d1aee71342ba","frame_index":0,"kind":"data","monotonic_ns":309430349068458,"payload":{"event_type":"price_change","market":"0x0f70d07969bc69eaa97d0987de651885fdca02263688026aa11e7678af8f87aa","price_changes":[{"asset_id":"64053005904884194822931764831592250494815136296598204104072528088122126148949","best_ask":"0.53","best_bid":"0.52","hash":"a97609971202608f10f84800e0ce39b3e92d5859","price":"0.42","side":"BUY","size":"217"},{"asset_id":"58313761654877669244690227616056238030136603415514645252000528337391143520538","best_ask":"0.48","best_bid":"0.47","hash":"315bfefe02eb002c96d9f897487091190272063f","price":"0.58","side":"SELL","size":"217"}],"timestamp":"1785207447035"},"payload_hash":"1124331f21b88610d2404ed77676cbbf129c8bb8ba4a087367f57334ebb99e4d","raw_frame":"{\"market\":\"0x0f70d07969bc69eaa97d0987de651885fdca02263688026aa11e7678af8f87aa\", \"price_changes\":[{\"asset_id\":\"64053005904884194822931764831592250494815136296598204104072528088122126148949\", \"price\":\"0.42\", \"size\":\"217\", \"side\":\"BUY\", \"hash\":\"a97609971202608f10f84800e0ce39b3e92d5859\", \"best_bid\":\"0.52\", \"best_ask\":\"0.53\"}, {\"asset_id\":\"58313761654877669244690227616056238030136603415514645252000528337391143520538\", \"price\":\"0.58\", \"size\":\"217\", \"side\":\"SELL\", \"hash\":\"315bfefe02eb002c96d9f897487091190272063f\", \"best_bid\":\"0.47\", \"best_ask\":\"0.48\"}], \"timestamp\":\"1785207447035\", \"event_type\":\"price_change\"}","received_at":"2026-07-28T02:57:27.331807Z","schema_version":"clob-market-ws.price_change.v1","sequence":null,"server_hash":null,"server_timestamp":"1785207447035","session_id":"5aad79be415c487c84df42bebd84ee93","source":"clob_market_ws"},"received_at":"2026-07-28T02:57:27.331807Z","record_id":"f35f643af16ada600bd4999aa424fdb22cb1b27439a7d4316facdfcee6176007","schema_fingerprint":"4aa3821a28b0b7c2400bc59aba4bcc0a76e971dadd19610d3ad38c768e124dc7","schema_version":"edge-lab-recorder.raw.v1","sequence":null,"source":"clob_market_ws"}
{"event_at":"2026-07-28T02:57:27.037000Z","event_fingerprint":"70304bab15c94f44a42907b9afda1852dcdc3d3ab44c23c62fbeb506e6eda544","payload":{"connection_id":"955646bd8bf740759faf38750c0f263f","event_at":"2026-07-28T02:57:27.037000Z","event_type":"price_change","frame_hash":"055bca5a6aab6074fa6828c89f87bb23ca5407afe26337213504bc273b632339","frame_index":0,"kind":"data","monotonic_ns":309430350545625,"payload":{"event_type":"price_change","market":"0x0f70d07969bc69eaa97d0987de651885fdca02263688026aa11e7678af8f87aa","price_changes":[{"asset_id":"64053005904884194822931764831592250494815136296598204104072528088122126148949","best_ask":"0.53","best_bid":"0.52","hash":"d88238ceb7c850fe7ec59b0b253072f739443e4e","price":"0.51","side":"BUY","size":"131.1"},{"asset_id":"58313761654877669244690227616056238030136603415514645252000528337391143520538","best_ask":"0.48","best_bid":"0.47","hash":"ef7cbd8822e6e781b25a44727e054498d7523e2c","price":"0.49","side":"SELL","size":"131.1"}],"timestamp":"1785207447037"},"payload_hash":"18945c240e5bb7feefdd210895b3523fe7d0b1c0e7aa5897b4d1ca0b25a8816e","raw_frame":"{\"market\":\"0x0f70d07969bc69eaa97d0987de651885fdca02263688026aa11e7678af8f87aa\", \"price_changes\":[{\"asset_id\":\"64053005904884194822931764831592250494815136296598204104072528088122126148949\", \"price\":\"0.51\", \"size\":\"131.1\", \"side\":\"BUY\", \"hash\":\"d88238ceb7c850fe7ec59b0b253072f739443e4e\", \"best_bid\":\"0.52\", \"best_ask\":\"0.53\"}, {\"asset_id\":\"58313761654877669244690227616056238030136603415514645252000528337391143520538\", \"price\":\"0.49\", \"size\":\"131.1\", \"side\":\"SELL\", \"hash\":\"ef7cbd8822e6e781b25a44727e054498d7523e2c\", \"best_bid\":\"0.47\", \"best_ask\":\"0.48\"}], \"timestamp\":\"1785207447037\", \"event_type\":\"price_change\"}","received_at":"2026-07-28T02:57:27.333285Z","schema_version":"clob-market-ws.price_change.v1","sequence":null,"server_hash":null,"server_timestamp":"1785207447037","session_id":"5aad79be415c487c84df42bebd84ee93","source":"clob_market_ws"},"received_at":"2026-07-28T02:57:27.333285Z","record_id":"97677641cec70183de6a2dd43eeef8542e4218d6c87489d8f34dfbe1d473adc0","schema_fingerprint":"4aa3821a28b0b7c2400bc59aba4bcc0a76e971dadd19610d3ad38c768e124dc7","schema_version":"edge-lab-recorder.raw.v1","sequence":null,"source":"clob_market_ws"}
{"event_at":"2026-07-28T02:57:27.038000Z","event_fingerprint":"a497ae6c6b12cf346aaadccaf82824f18d2077ce7219b7548e193945dadb3c50","payload":{"connection_id":"955646bd8bf740759faf38750c0f263f","event_at":"2026-07-28T02:57:27.038000Z","event_type":"price_change","frame_hash":"b0266ee59f1d22fa9c7066e6916e766776dccd4fa6d71a4ac395e1f4c7607589","frame_index":0,"kind":"data","monotonic_ns":309430352010333,"payload":{"event_type":"price_change","market":"0x0f70d07969bc69eaa97d0987de651885fdca02263688026aa11e7678af8f87aa","price_changes":[{"asset_id":"64053005904884194822931764831592250494815136296598204104072528088122126148949","best_ask":"0.53","best_bid":"0.52","hash":"1a4d14b06fff1d740b01461f17d66d2f3e164614","price":"0.04","side":"BUY","size":"385.5"},{"asset_id":"58313761654877669244690227616056238030136603415514645252000528337391143520538","best_ask":"0.48","best_bid":"0.47","hash":"01c8be6f897197f5bebec818f6c3194d3675c150","price":"0.96","side":"SELL","size":"385.5"}],"timestamp":"1785207447038"},"payload_hash":"3948da60a9151c6c245f993cc44a63814156285f66cafffd2627f8c98c98042c","raw_frame":"{\"market\":\"0x0f70d07969bc69eaa97d0987de651885fdca02263688026aa11e7678af8f87aa\", \"price_changes\":[{\"asset_id\":\"64053005904884194822931764831592250494815136296598204104072528088122126148949\", \"price\":\"0.04\", \"size\":\"385.5\", \"side\":\"BUY\", \"hash\":\"1a4d14b06fff1d740b01461f17d66d2f3e164614\", \"best_bid\":\"0.52\", \"best_ask\":\"0.53\"}, {\"asset_id\":\"58313761654877669244690227616056238030136603415514645252000528337391143520538\", \"price\":\"0.96\", \"size\":\"385.5\", \"side\":\"SELL\", \"hash\":\"01c8be6f897197f5bebec818f6c3194d3675c150\", \"best_bid\":\"0.47\", \"best_ask\":\"0.48\"}], \"timestamp\":\"1785207447038\", \"event_type\":\"price_change\"}","received_at":"2026-07-28T02:57:27.334750Z","schema_version":"clob-market-ws.price_change.v1","sequence":null,"server_hash":null,"server_timestamp":"1785207447038","session_id":"5aad79be415c487c84df42bebd84ee93","source":"clob_market_ws"},"received_at":"2026-07-28T02:57:27.334750Z","record_id":"1a9b77e0e7d1891eab7b09008d27bb4b9ae6e9642a0fa7611b202eacb78cbe85","schema_fingerprint":"4aa3821a28b0b7c2400bc59aba4bcc0a76e971dadd19610d3ad38c768e124dc7","schema_version":"edge-lab-recorder.raw.v1","sequence":null,"source":"clob_market_ws"}
{"event_at":"2026-07-28T02:57:27.039000Z","event_fingerprint":"55f0978bc894c7c11a213017849327de541eb8725177878016a63a818b0f8d07","payload":{"connection_id":"955646bd8bf740759faf38750c0f263f","event_at":"2026-07-28T02:57:27.039000Z","event_type":"price_change","frame_hash":"8774d2314f2bd1ae15947332b034842ec0cf78d64010a341e4dc6d7b97fc7733","frame_index":0,"kind":"data","monotonic_ns":309430353463583,"payload":{"event_type":"price_change","market":"0x0f70d07969bc69eaa97d0987de651885fdca02263688026aa11e7678af8f87aa","price_changes":[{"asset_id":"64053005904884194822931764831592250494815136296598204104072528088122126148949","best_ask":"0.53","best_bid":"0.52","hash":"99ca0bcdb417688b15e4c09476906eaef930b003","price":"0.17","side":"BUY","size":"580.87"},{"asset_id":"58313761654877669244690227616056238030136603415514645252000528337391143520538","best_ask":"0.48","best_bid":"0.47","hash":"f84233b45c876282826d6b06e3c5ddb75f93466e","price":"0.83","side":"SELL","size":"580.87"}],"timestamp":"1785207447039"},"payload_hash":"7aee881ff7b3f1ffac5848074fe6016a0288cca5d680f6e24e8a0978b4e83835","raw_frame":"{\"market\":\"0x0f70d07969bc69eaa97d0987de651885fdca02263688026aa11e7678af8f87aa\", \"price_changes\":[{\"asset_id\":\"64053005904884194822931764831592250494815136296598204104072528088122126148949\", \"price\":\"0.17\", \"size\":\"580.87\", \"side\":\"BUY\", \"hash\":\"99ca0bcdb417688b15e4c09476906eaef930b003\", \"best_bid\":\"0.52\", \"best_ask\":\"0.53\"}, {\"asset_id\":\"58313761654877669244690227616056238030136603415514645252000528337391143520538\", \"price\":\"0.83\", \"size\":\"580.87\", \"side\":\"SELL\", \"hash\":\"f84233b45c876282826d6b06e3c5ddb75f93466e\", \"best_bid\":\"0.47\", \"best_ask\":\"0.48\"}], \"timestamp\":\"1785207447039\", \"event_type\":\"price_change\"}","received_at":"2026-07-28T02:57:27.336202Z","schema_version":"clob-market-ws.price_change.v1","sequence":null,"server_hash":null,"server_timestamp":"1785207447039","session_id":"5aad79be415c487c84df42bebd84ee93","source":"clob_market_ws"},"received_at":"2026-07-28T02:57:27.336202Z","record_id":"c9f562a14860ad9a521c0a1ef8918c3070a812b2fa0afd0232b0f55117e64d4a","schema_fingerprint":"4aa3821a28b0b7c2400bc59aba4bcc0a76e971dadd19610d3ad38c768e124dc7","schema_version":"edge-lab-recorder.raw.v1","sequence":null,"source":"clob_market_ws"}
{"event_at":"2026-07-28T02:57:27.039000Z","event_fingerprint":"5eb13d4117f574ca8c451bab01053afcd8e782a068078d6cebee3ad62bc75501","payload":{"connection_id":"955646bd8bf740759faf38750c0f263f","event_at":"2026-07-28T02:57:27.039000Z","event_type":"price_change","frame_hash":"e393fa2d150c2a91bd5f2808184abc7a4dc5954865d2985b76f39dcd01de7606","frame_index":0,"kind":"data","monotonic_ns":309430354912250,"payload":{"event_type":"price_change","market":"0x0f70d07969bc69eaa97d0987de651885fdca02263688026aa11e7678af8f87aa","price_changes":[{"asset_id":"58313761654877669244690227616056238030136603415514645252000528337391143520538","best_ask":"0.48","best_bid":"0.47","hash":"cf912aa7f97b62f408be143221497fe0e29d8b4a","price":"0.24","side":"BUY","size":"459.92"},{"asset_id":"64053005904884194822931764831592250494815136296598204104072528088122126148949","best_ask":"0.53","best_bid":"0.52","hash":"879d680e8d6c6caaaf3c07d9bf066c72026e3d32","price":"0.76","side":"SELL","size":"459.92"}],"timestamp":"1785207447039"},"payload_hash":"f4fd0236a334f5157ffa240fc203933c359de06c1bdee53b969c0a4f5cfc6ee2","raw_frame":"{\"market\":\"0x0f70d07969bc69eaa97d0987de651885fdca02263688026aa11e7678af8f87aa\", \"price_changes\":[{\"asset_id\":\"58313761654877669244690227616056238030136603415514645252000528337391143520538\", \"price\":\"0.24\", \"size\":\"459.92\", \"side\":\"BUY\", \"hash\":\"cf912aa7f97b62f408be143221497fe0e29d8b4a\", \"best_bid\":\"0.47\", \"best_ask\":\"0.48\"}, {\"asset_id\":\"64053005904884194822931764831592250494815136296598204104072528088122126148949\", \"price\":\"0.76\", \"size\":\"459.92\", \"side\":\"SELL\", \"hash\":\"879d680e8d6c6caaaf3c07d9bf066c72026e3d32\", \"best_bid\":\"0.52\", \"best_ask\":\"0.53\"}], \"timestamp\":\"1785207447039\", \"event_type\":\"price_change\"}","received_at":"2026-07-28T02:57:27.337652Z","schema_version":"clob-market-ws.price_change.v1","sequence":null,"server_hash":null,"server_timestamp":"1785207447039","session_id":"5aad79be415c487c84df42bebd84ee93","source":"clob_market_ws"},"received_at":"2026-07-28T02:57:27.337652Z","record_id":"8a69e944132419c2a5c175a87355a923e399e136ce2a9eb75452b4277f73ee3e","schema_fingerprint":"4aa3821a28b0b7c2400bc59aba4bcc0a76e971dadd19610d3ad38c768e124dc7","schema_version":"edge-lab-recorder.raw.v1","sequence":null,"source":"clob_market_ws"}
{"event_at":"2026-07-28T02:57:27.039000Z","event_fingerprint":"52a78f11684362e0cee73d0e75e34dab538e7587b00fdd2262ac6c42c3db21d4","payload":{"connection_id":"955646bd8bf740759faf38750c0f263f","event_at":"2026-07-28T02:57:27.039000Z","event_type":"price_change","frame_hash":"efa89cad33581220d13db0b4529475015eeb856141fa7842f2479e7fce32b8d2","frame_index":0,"kind":"data","monotonic_ns":309430356367500,"payload":{"event_type":"price_change","market":"0x0f70d07969bc69eaa97d0987de651885fdca02263688026aa11e7678af8f87aa","price_changes":[{"asset_id":"58313761654877669244690227616056238030136603415514645252000528337391143520538","best_ask":"0.48","best_bid":"0.47","hash":"97846ff5d981c906456eee2af99f7cd43660756b","price":"0.24","side":"BUY","size":"293.26"},{"asset_id":"64053005904884194822931764831592250494815136296598204104072528088122126148949","best_ask":"0.53","best_bid":"0.52","hash":"42e7332a64ca56c4ec969ba72e7eaf17d2b37716","price":"0.76","side":"SELL","size":"293.26"}],"timestamp":"1785207447039"},"payload_hash":"fd33ab3301eb31f80a1570ebfccd62d3eceef98a9f009b06a08a34d7f8ac8186","raw_frame":"{\"market\":\"0x0f70d07969bc69eaa97d0987de651885fdca02263688026aa11e7678af8f87aa\", \"price_changes\":[{\"asset_id\":\"58313761654877669244690227616056238030136603415514645252000528337391143520538\", \"price\":\"0.24\", \"size\":\"293.26\", \"side\":\"BUY\", \"hash\":\"97846ff5d981c906456eee2af99f7cd43660756b\", \"best_bid\":\"0.47\", \"best_ask\":\"0.48\"}, {\"asset_id\":\"64053005904884194822931764831592250494815136296598204104072528088122126148949\", \"price\":\"0.76\", \"size\":\"293.26\", \"side\":\"SELL\", \"hash\":\"42e7332a64ca56c4ec969ba72e7eaf17d2b37716\", \"best_bid\":\"0.52\", \"best_ask\":\"0.53\"}], \"timestamp\":\"1785207447039\", \"event_type\":\"price_change\"}","received_at":"2026-07-28T02:57:27.339107Z","schema_version":"clob-market-ws.price_change.v1","sequence":null,"server_hash":null,"server_timestamp":"1785207447039","session_id":"5aad79be415c487c84df42bebd84ee93","source":"clob_market_ws"},"received_at":"2026-07-28T02:57:27.339107Z","record_id":"6bb39823633da40269e71516c25ffb5966f50801b0cae41480c0abddbfd8c61f","schema_fingerprint":"4aa3821a28b0b7c2400bc59aba4bcc0a76e971dadd19610d3ad38c768e124dc7","schema_version":"edge-lab-recorder.raw.v1","sequence":null,"source":"clob_market_ws"}
{"event_at":"2026-07-28T02:57:27.040000Z","event_fingerprint":"d9ae1c627a8b0cf54b7a1dcc4c6a8fc1d8ec5eb2a23253acf8f41409c85c7bf4","payload":{"connection_id":"955646bd8bf740759faf38750c0f263f","event_at":"2026-07-28T02:57:27.040000Z","event_type":"price_change","frame_hash":"5faeb051b0dcb7878ca03f91ba84e2a97778c02eeeef6dbc20d3fa3f4999573a","frame_index":0,"kind":"data","monotonic_ns":309430357891291,"payload":{"event_type":"price_change","market":"0x0f70d07969bc69eaa97d0987de651885fdca02263688026aa11e7678af8f87aa","price_changes":[{"asset_id":"58313761654877669244690227616056238030136603415514645252000528337391143520538","best_ask":"0.48","best_bid":"0.47","hash":"83f789d6b2f12d6c4bd72f1bbfeb165fbd817f37","price":"0.24","side":"BUY","size":"126.6"},{"asset_id":"64053005904884194822931764831592250494815136296598204104072528088122126148949","best_ask":"0.53","best_bid":"0.52","hash":"bb78afc5e0bf3460a8350a02215a2a26e783e404","price":"0.76","side":"SELL","size":"126.6"}],"timestamp":"1785207447040"},"payload_hash":"f2819062b755edacd983dc83fdea372424e01ba896ea6aae8488d669b87f9061","raw_frame":"{\"market\":\"0x0f70d07969bc69eaa97d0987de651885fdca02263688026aa11e7678af8f87aa\", \"price_changes\":[{\"asset_id\":\"58313761654877669244690227616056238030136603415514645252000528337391143520538\", \"price\":\"0.24\", \"size\":\"126.6\", \"side\":\"BUY\", \"hash\":\"83f789d6b2f12d6c4bd72f1bbfeb165fbd817f37\", \"best_bid\":\"0.47\", \"best_ask\":\"0.48\"}, {\"asset_id\":\"64053005904884194822931764831592250494815136296598204104072528088122126148949\", \"price\":\"0.76\", \"size\":\"126.6\", \"side\":\"SELL\", \"hash\":\"bb78afc5e0bf3460a8350a02215a2a26e783e404\", \"best_bid\":\"0.52\", \"best_ask\":\"0.53\"}], \"timestamp\":\"1785207447040\", \"event_type\":\"price_change\"}","received_at":"2026-07-28T02:57:27.340630Z","schema_version":"clob-market-ws.price_change.v1","sequence":null,"server_hash":null,"server_timestamp":"1785207447040","session_id":"5aad79be415c487c84df42bebd84ee93","source":"clob_market_ws"},"received_at":"2026-07-28T02:57:27.340630Z","record_id":"f5dfe04334d90c72f6e7e8c8b6b1836cce3c801c1770544845b810a73a305da7","schema_fingerprint":"4aa3821a28b0b7c2400bc59aba4bcc0a76e971dadd19610d3ad38c768e124dc7","schema_version":"edge-lab-recorder.raw.v1","sequence":null,"source":"clob_market_ws"}
{"event_at":"2026-07-28T02:57:27.042000Z","event_fingerprint":"4ddbb67b3881b17b079180e10440b243a3b7fce79ebfbcc567c40c387d54b541","payload":{"connection_id":"955646bd8bf740759faf38750c0f263f","event_at":"2026-07-28T02:57:27.042000Z","event_type":"price_change","frame_hash":"2e5f6bc679ffb094832d19215869d1c317e16f05cb1eaada8af0aac3b9cda77d","frame_index":0,"kind":"data","monotonic_ns":309430361022750,"payload":{"event_type":"price_change","market":"0x0f70d07969bc69eaa97d0987de651885fdca02263688026aa11e7678af8f87aa","price_changes":[{"asset_id":"64053005904884194822931764831592250494815136296598204104072528088122126148949","best_ask":"0.53","best_bid":"0.52","hash":"e7a880dd333a27f35565ab870396d1f52c02457b","price":"0.17","side":"BUY","size":"345.58"},{"asset_id":"58313761654877669244690227616056238030136603415514645252000528337391143520538","best_ask":"0.48","best_bid":"0.47","hash":"97994b7fc206876d4f007853b54858b99f4446b3","price":"0.83","side":"SELL","size":"345.58"}],"timestamp":"1785207447042"},"payload_hash":"275e44133add445c6891266ebd5bb090c8234eaeda7af626c41fb9b6441562de","raw_frame":"{\"market\":\"0x0f70d07969bc69eaa97d0987de651885fdca02263688026aa11e7678af8f87aa\", \"price_changes\":[{\"asset_id\":\"64053005904884194822931764831592250494815136296598204104072528088122126148949\", \"price\":\"0.17\", \"size\":\"345.58\", \"side\":\"BUY\", \"hash\":\"e7a880dd333a27f35565ab870396d1f52c02457b\", \"best_bid\":\"0.52\", \"best_ask\":\"0.53\"}, {\"asset_id\":\"58313761654877669244690227616056238030136603415514645252000528337391143520538\", \"price\":\"0.83\", \"size\":\"345.58\", \"side\":\"SELL\", \"hash\":\"97994b7fc206876d4f007853b54858b99f4446b3\", \"best_bid\":\"0.47\", \"best_ask\":\"0.48\"}], \"timestamp\":\"1785207447042\", \"event_type\":\"price_change\"}","received_at":"2026-07-28T02:57:27.343760Z","schema_version":"clob-market-ws.price_change.v1","sequence":null,"server_hash":null,"server_timestamp":"1785207447042","session_id":"5aad79be415c487c84df42bebd84ee93","source":"clob_market_ws"},"received_at":"2026-07-28T02:57:27.343760Z","record_id":"079a0c52be38a73570ca5e138b7d4503f3bdf5e98e349f089272aadcdb2faa47","schema_fingerprint":"4aa3821a28b0b7c2400bc59aba4bcc0a76e971dadd19610d3ad38c768e124dc7","schema_version":"edge-lab-recorder.raw.v1","sequence":null,"source":"clob_market_ws"}
{"event_at":"2026-07-28T02:57:27.043000Z","event_fingerprint":"55d31ba9b7fd65b63c26c5be7ce8f087e7a56ac11d16a04d8151cfd12dd899a9","payload":{"connection_id":"955646bd8bf740759faf38750c0f263f","event_at":"2026-07-28T02:57:27.043000Z","event_type":"price_change","frame_hash":"288b3b6b8f66aaf6ee53bc23199fb011133812bb4223453d85ed01c22f310438","frame_index":0,"kind":"data","monotonic_ns":309430364355625,"payload":{"event_type":"price_change","market":"0x0f70d07969bc69eaa97d0987de651885fdca02263688026aa11e7678af8f87aa","price_changes":[{"asset_id":"64053005904884194822931764831592250494815136296598204104072528088122126148949","best_ask":"0.53","best_bid":"0.52","hash":"7fa9390eee31cbcdcc6a21c9501d5afbc05dfc9b","price":"0.51","side":"BUY","size":"138.1"},{"asset_id":"58313761654877669244690227616056238030136603415514645252000528337391143520538","best_ask":"0.48","best_bid":"0.47","hash":"c15482160ef12309665a0e6c4be5a0abf30e269a","price":"0.49","side":"SELL","size":"138.1"}],"timestamp":"1785207447043"},"payload_hash":"e267b5b4a4332cfdf962f1fcc7153d26023d6309297a0da516079d768df8ec09","raw_frame":"{\"market\":\"0x0f70d07969bc69eaa97d0987de651885fdca02263688026aa11e7678af8f87aa\", \"price_changes\":[{\"asset_id\":\"64053005904884194822931764831592250494815136296598204104072528088122126148949\", \"price\":\"0.51\", \"size\":\"138.1\", \"side\":\"BUY\", \"hash\":\"7fa9390eee31cbcdcc6a21c9501d5afbc05dfc9b\", \"best_bid\":\"0.52\", \"best_ask\":\"0.53\"}, {\"asset_id\":\"58313761654877669244690227616056238030136603415514645252000528337391143520538\", \"price\":\"0.49\", \"size\":\"138.1\", \"side\":\"SELL\", \"hash\":\"c15482160ef12309665a0e6c4be5a0abf30e269a\", \"best_bid\":\"0.47\", \"best_ask\":\"0.48\"}], \"timestamp\":\"1785207447043\", \"event_type\":\"price_change\"}","received_at":"2026-07-28T02:57:27.347094Z","schema_version":"clob-market-ws.price_change.v1","sequence":null,"server_hash":null,"server_timestamp":"1785207447043","session_id":"5aad79be415c487c84df42bebd84ee93","source":"clob_market_ws"},"received_at":"2026-07-28T02:57:27.347094Z","record_id":"2bb68e776973a6cb9864f540b3ec1e93868c7af8f45f1194b3b6505338a2dbf6","schema_fingerprint":"4aa3821a28b0b7c2400bc59aba4bcc0a76e971dadd19610d3ad38c768e124dc7","schema_version":"edge-lab-recorder.raw.v1","sequence":null,"source":"clob_market_ws"}
{"event_at":"2026-07-28T02:57:27.044000Z","event_fingerprint":"eb0c1e52284c9c3eb671808e6ce276725f0a576b0761c90b360d0ba2470b1729","payload":{"connection_id":"955646bd8bf740759faf38750c0f263f","event_at":"2026-07-28T02:57:27.044000Z","event_type":"price_change","frame_hash":"3affdab6aed152b207f2201f97ef504ff6407f9871a1dd2b77de7d377f4236f8","frame_index":0,"kind":"data","monotonic_ns":309430367355166,"payload":{"event_type":"price_change","market":"0x0f70d07969bc69eaa97d0987de651885fdca02263688026aa11e7678af8f87aa","price_changes":[{"asset_id":"58313761654877669244690227616056238030136603415514645252000528337391143520538","best_ask":"0.48","best_bid":"0.47","hash":"236cf0f5228ef424a6b8c87f0ca52ee4350539ca","price":"0.01","side":"BUY","size":"2381.24"},{"asset_id":"64053005904884194822931764831592250494815136296598204104072528088122126148949","best_ask":"0.53","best_bid":"0.52","hash":"8c503fb60154a95a913368b9a24c93ba660a674a","price":"0.99","side":"SELL","size":"2381.24"}],"timestamp":"1785207447044"},"payload_hash":"799bc7422740b278cacac4aaa969fac2e7b71ae7f4ff4255ff07cdfc02bc2bb6","raw_frame":"{\"market\":\"0x0f70d07969bc69eaa97d0987de651885fdca02263688026aa11e7678af8f87aa\", \"price_changes\":[{\"asset_id\":\"58313761654877669244690227616056238030136603415514645252000528337391143520538\", \"price\":\"0.01\", \"size\":\"2381.24\", \"side\":\"BUY\", \"hash\":\"236cf0f5228ef424a6b8c87f0ca52ee4350539ca\", \"best_bid\":\"0.47\", \"best_ask\":\"0.48\"}, {\"asset_id\":\"64053005904884194822931764831592250494815136296598204104072528088122126148949\", \"price\":\"0.99\", \"size\":\"2381.24\", \"side\":\"SELL\", \"hash\":\"8c503fb60154a95a913368b9a24c93ba660a674a\", \"best_bid\":\"0.52\", \"best_ask\":\"0.53\"}], \"timestamp\":\"1785207447044\", \"event_type\":\"price_change\"}","received_at":"2026-07-28T02:57:27.350094Z","schema_version":"clob-market-ws.price_change.v1","sequence":null,"server_hash":null,"server_timestamp":"1785207447044","session_id":"5aad79be415c487c84df42bebd84ee93","source":"clob_market_ws"},"received_at":"2026-07-28T02:57:27.350094Z","record_id":"526cfabd30798c527f7d8f4b76fd78f5b105a27f4ee47150a5b59dff1554e34d","schema_fingerprint":"4aa3821a28b0b7c2400bc59aba4bcc0a76e971dadd19610d3ad38c768e124dc7","schema_version":"edge-lab-recorder.raw.v1","sequence":null,"source":"clob_market_ws"}
{"event_at":"2026-07-28T02:57:27.044000Z","event_fingerprint":"35d923d3886a9f9b77cbe783d9be9f4e208f2bb318bc974203bbed91faea5756","payload":{"connection_id":"955646bd8bf740759faf38750c0f263f","event_at":"2026-07-28T02:57:27.044000Z","event_type":"price_change","frame_hash":"7df51bde29515d69af8d8714a8804f31e0027382b1d31591d7cebabde8679dcd","frame_index":0,"kind":"data","monotonic_ns":309430370495375,"payload":{"event_type":"price_change","market":"0x0f70d07969bc69eaa97d0987de651885fdca02263688026aa11e7678af8f87aa","price_changes":[{"asset_id":"64053005904884194822931764831592250494815136296598204104072528088122126148949","best_ask":"0.53","best_bid":"0.52","hash":"951280eee06e6dcf8a47e5df75022158a68fe168","price":"0.01","side":"BUY","size":"2587.52"},{"asset_id":"58313761654877669244690227616056238030136603415514645252000528337391143520538","best_ask":"0.48","best_bid":"0.47","hash":"04e377eff2642ccdcbc93fe590d54fb083c0f820","price":"0.99","side":"SELL","size":"2587.52"}],"timestamp":"1785207447044"},"payload_hash":"cd69cbffcda2b6990c8ddafcceaabc2f4ddeed0d63060fd468ba2da41209d868","raw_frame":"{\"market\":\"0x0f70d07969bc69eaa97d0987de651885fdca02263688026aa11e7678af8f87aa\", \"price_changes\":[{\"asset_id\":\"64053005904884194822931764831592250494815136296598204104072528088122126148949\", \"price\":\"0.01\", \"size\":\"2587.52\", \"side\":\"BUY\", \"hash\":\"951280eee06e6dcf8a47e5df75022158a68fe168\", \"best_bid\":\"0.52\", \"best_ask\":\"0.53\"}, {\"asset_id\":\"58313761654877669244690227616056238030136603415514645252000528337391143520538\", \"price\":\"0.99\", \"size\":\"2587.52\", \"side\":\"SELL\", \"hash\":\"04e377eff2642ccdcbc93fe590d54fb083c0f820\", \"best_bid\":\"0.47\", \"best_ask\":\"0.48\"}], \"timestamp\":\"1785207447044\", \"event_type\":\"price_change\"}","received_at":"2026-07-28T02:57:27.353234Z","schema_version":"clob-market-ws.price_change.v1","sequence":null,"server_hash":null,"server_timestamp":"1785207447044","session_id":"5aad79be415c487c84df42bebd84ee93","source":"clob_market_ws"},"received_at":"2026-07-28T02:57:27.353234Z","record_id":"4c759e95c82f8d0e09db5813898fdcee20865f05cc4c18d372f1765d63de9096","schema_fingerprint":"4aa3821a28b0b7c2400bc59aba4bcc0a76e971dadd19610d3ad38c768e124dc7","schema_version":"edge-lab-recorder.raw.v1","sequence":null,"source":"clob_market_ws"}
{"event_at":"2026-07-28T02:57:27.044000Z","event_fingerprint":"593d0b918a05f4cc0df3f7c4edbbe251c344dcff728a33939750d9e87e9d4d89","payload":{"connection_id":"955646bd8bf740759faf38750c0f263f","event_at":"2026-07-28T02:57:27.044000Z","event_type":"price_change","frame_hash":"816b8c7eea2d682f3e98c76d42aadab9b3ad7ad7454bb2a4db25424b080a0c99","frame_index":0,"kind":"data","monotonic_ns":309430373432458,"payload":{"event_type":"price_change","market":"0x0f70d07969bc69eaa97d0987de651885fdca02263688026aa11e7678af8f87aa","price_changes":[{"asset_id":"64053005904884194822931764831592250494815136296598204104072528088122126148949","best_ask":"0.53","best_bid":"0.52","hash":"0ac45466e3d52e85cc6199cbc18f3cd0fe611e37","price":"0.17","side":"BUY","size":"110.29"},{"asset_id":"58313761654877669244690227616056238030136603415514645252000528337391143520538","best_ask":"0.48","best_bid":"0.47","hash":"e87ef37acccfbe49288d07179af996f1724798a7","price":"0.83","side":"SELL","size":"110.29"}],"timestamp":"1785207447044"},"payload_hash":"d0b102ae4365f59d75e644caae4b634447f1ed81f4a65f5c4c1ef7de69915f92","raw_frame":"{\"market\":\"0x0f70d07969bc69eaa97d0987de651885fdca02263688026aa11e7678af8f87aa\", \"price_changes\":[{\"asset_id\":\"64053005904884194822931764831592250494815136296598204104072528088122126148949\", \"price\":\"0.17\", \"size\":\"110.29\", \"side\":\"BUY\", \"hash\":\"0ac45466e3d52e85cc6199cbc18f3cd0fe611e37\", \"best_bid\":\"0.52\", \"best_ask\":\"0.53\"}, {\"asset_id\":\"58313761654877669244690227616056238030136603415514645252000528337391143520538\", \"price\":\"0.83\", \"size\":\"110.29\", \"side\":\"SELL\", \"hash\":\"e87ef37acccfbe49288d07179af996f1724798a7\", \"best_bid\":\"0.47\", \"best_ask\":\"0.48\"}], \"timestamp\":\"1785207447044\", \"event_type\":\"price_change\"}","received_at":"2026-07-28T02:57:27.356171Z","schema_version":"clob-market-ws.price_change.v1","sequence":null,"server_hash":null,"server_timestamp":"1785207447044","session_id":"5aad79be415c487c84df42bebd84ee93","source":"clob_market_ws"},"received_at":"2026-07-28T02:57:27.356171Z","record_id":"4d53c7de4ad503bfe241025f68d490b954d9df460932d062ed5729604d993b47","schema_fingerprint":"4aa3821a28b0b7c2400bc59aba4bcc0a76e971dadd19610d3ad38c768e124dc7","schema_version":"edge-lab-recorder.raw.v1","sequence":null,"source":"clob_market_ws"}
{"event_at":"2026-07-28T02:57:27.045000Z","event_fingerprint":"73339c46546e0a05c82740de45dde776a7d144535491fb83a174fc45d013454b","payload":{"connection_id":"955646bd8bf740759faf38750c0f263f","event_at":"2026-07-28T02:57:27.045000Z","event_type":"price_change","frame_hash":"7348bead1cd76b9618909367f6e2f12b7826972c8a8835252616a2db73c2ae3d","frame_index":0,"kind":"data","monotonic_ns":309430376506791,"payload":{"event_type":"price_change","market":"0x0f70d07969bc69eaa97d0987de651885fdca02263688026aa11e7678af8f87aa","price_changes":[{"asset_id":"58313761654877669244690227616056238030136603415514645252000528337391143520538","best_ask":"0.48","best_bid":"0.47","hash":"56c939cb7d343205716e1a89dffc468559e7d3d1","price":"0.46","side":"BUY","size":"63.7"},{"asset_id":"64053005904884194822931764831592250494815136296598204104072528088122126148949","best_ask":"0.53","best_bid":"0.52","hash":"8660116374248e02e4ea68304d27483f773a4589","price":"0.54","side":"SELL","size":"63.7"}],"timestamp":"1785207447045"},"payload_hash":"a8065af32dcb3ee9ec346bf8a4d4f5e13af800b9b962a539067189bf76ec293a","raw_frame":"{\"market\":\"0x0f70d07969bc69eaa97d0987de651885fdca02263688026aa11e7678af8f87aa\", \"price_changes\":[{\"asset_id\":\"58313761654877669244690227616056238030136603415514645252000528337391143520538\", \"price\":\"0.46\", \"size\":\"63.7\", \"side\":\"BUY\", \"hash\":\"56c939cb7d343205716e1a89dffc468559e7d3d1\", \"best_bid\":\"0.47\", \"best_ask\":\"0.48\"}, {\"asset_id\":\"64053005904884194822931764831592250494815136296598204104072528088122126148949\", \"price\":\"0.54\", \"size\":\"63.7\", \"side\":\"SELL\", \"hash\":\"8660116374248e02e4ea68304d27483f773a4589\", \"best_bid\":\"0.52\", \"best_ask\":\"0.53\"}], \"timestamp\":\"1785207447045\", \"event_type\":\"price_change\"}","received_at":"2026-07-28T02:57:27.359245Z","schema_version":"clob-market-ws.price_change.v1","sequence":null,"server_hash":null,"server_timestamp":"1785207447045","session_id":"5aad79be415c487c84df42bebd84ee93","source":"clob_market_ws"},"received_at":"2026-07-28T02:57:27.359245Z","record_id":"08734e44279062b85910124efec0df05b9c748b70dec70608dc1767f0f27fa98","schema_fingerprint":"4aa3821a28b0b7c2400bc59aba4bcc0a76e971dadd19610d3ad38c768e124dc7","schema_version":"edge-lab-recorder.raw.v1","sequence":null,"source":"clob_market_ws"}
{"event_at":"2026-07-28T02:57:27.046000Z","event_fingerprint":"3d530aa6f26b2c40174dc55f5c22a26b53a656a2a2f9863baa44aae07ac2831d","payload":{"connection_id":"955646bd8bf740759faf38750c0f263f","event_at":"2026-07-28T02:57:27.046000Z","event_type":"price_change","frame_hash":"efbf77d68b9f360d12245061b18a177f2b1f0f7da167bb8738e01fd15c3fa134","frame_index":0,"kind":"data","monotonic_ns":309430379442625,"payload":{"event_type":"price_change","market":"0x0f70d07969bc69eaa97d0987de651885fdca02263688026aa11e7678af8f87aa","price_changes":[{"asset_id":"64053005904884194822931764831592250494815136296598204104072528088122126148949","best_ask":"0.53","best_bid":"0.52","hash":"2fd6b7565818a6b98c622c8da290e90faa00bb37","price":"0.31","side":"BUY","size":"131.1"},{"asset_id":"58313761654877669244690227616056238030136603415514645252000528337391143520538","best_ask":"0.48","best_bid":"0.47","hash":"0f2b5c95729b0411336aa9a1c6bb3b9e2f9b11bd","price":"0.69","side":"SELL","size":"131.1"}],"timestamp":"1785207447046"},"payload_hash":"58f07f53c7686a75a763b3bf7a15f3a842b16e4b48656c301ce2e3568c8b0741","raw_frame":"{\"market\":\"0x0f70d07969bc69eaa97d0987de651885fdca02263688026aa11e7678af8f87aa\", \"price_changes\":[{\"asset_id\":\"64053005904884194822931764831592250494815136296598204104072528088122126148949\", \"price\":\"0.31\", \"size\":\"131.1\", \"side\":\"BUY\", \"hash\":\"2fd6b7565818a6b98c622c8da290e90faa00bb37\", \"best_bid\":\"0.52\", \"best_ask\":\"0.53\"}, {\"asset_id\":\"58313761654877669244690227616056238030136603415514645252000528337391143520538\", \"price\":\"0.69\", \"size\":\"131.1\", \"side\":\"SELL\", \"hash\":\"0f2b5c95729b0411336aa9a1c6bb3b9e2f9b11bd\", \"best_bid\":\"0.47\", \"best_ask\":\"0.48\"}], \"timestamp\":\"1785207447046\", \"event_type\":\"price_change\"}","received_at":"2026-07-28T02:57:27.362181Z","schema_version":"clob-market-ws.price_change.v1","sequence":null,"server_hash":null,"server_timestamp":"1785207447046","session_id":"5aad79be415c487c84df42bebd84ee93","source":"clob_market_ws"},"received_at":"2026-07-28T02:57:27.362181Z","record_id":"cd5730f2dc23ec02c862dc79e054a45970d91a346be4046fa38560bdaa4d9628","schema_fingerprint":"4aa3821a28b0b7c2400bc59aba4bcc0a76e971dadd19610d3ad38c768e124dc7","schema_version":"edge-lab-recorder.raw.v1","sequence":null,"source":"clob_market_ws"}
{"event_at":"2026-07-28T02:57:27.046000Z","event_fingerprint":"0eb23ec41fdbb08b4e1eccc797815303662f8fd58c3e757d7b5f2a32ec43028e","payload":{"connection_id":"955646bd8bf740759faf38750c0f263f","event_at":"2026-07-28T02:57:27.046000Z","event_type":"price_change","frame_hash":"f619244dc833d06c64e01445625ddb393e9ff5009709af43840b817508318f4f","frame_index":0,"kind":"data","monotonic_ns":309430382435958,"payload":{"event_type":"price_change","market":"0x0f70d07969bc69eaa97d0987de651885fdca02263688026aa11e7678af8f87aa","price_changes":[{"asset_id":"58313761654877669244690227616056238030136603415514645252000528337391143520538","best_ask":"0.48","best_bid":"0.47","hash":"0f2b5c95729b0411336aa9a1c6bb3b9e2f9b11bd","price":"0.39","side":"BUY","size":"261.26"},{"asset_id":"64053005904884194822931764831592250494815136296598204104072528088122126148949","best_ask":"0.53","best_bid":"0.52","hash":"2fd6b7565818a6b98c622c8da290e90faa00bb37","price":"0.61","side":"SELL","size":"261.26"}],"timestamp":"1785207447046"},"payload_hash":"b410a5bd630a3f75c3d8820aa81070ce92846c6007aef0ebebf4c9cf96746eee","raw_frame":"{\"market\":\"0x0f70d07969bc69eaa97d0987de651885fdca02263688026aa11e7678af8f87aa\", \"price_changes\":[{\"asset_id\":\"58313761654877669244690227616056238030136603415514645252000528337391143520538\", \"price\":\"0.39\", \"size\":\"261.26\", \"side\":\"BUY\", \"hash\":\"0f2b5c95729b0411336aa9a1c6bb3b9e2f9b11bd\", \"best_bid\":\"0.47\", \"best_ask\":\"0.48\"}, {\"asset_id\":\"64053005904884194822931764831592250494815136296598204104072528088122126148949\", \"price\":\"0.61\", \"size\":\"261.26\", \"side\":\"SELL\", \"hash\":\"2fd6b7565818a6b98c622c8da290e90faa00bb37\", \"best_bid\":\"0.52\", \"best_ask\":\"0.53\"}], \"timestamp\":\"1785207447046\", \"event_type\":\"price_change\"}","received_at":"2026-07-28T02:57:27.365174Z","schema_version":"clob-market-ws.price_change.v1","sequence":null,"server_hash":null,"server_timestamp":"1785207447046","session_id":"5aad79be415c487c84df42bebd84ee93","source":"clob_market_ws"},"received_at":"2026-07-28T02:57:27.365174Z","record_id":"4112a1ff01804f4b2fead082de23ed70d6b5c978ddfc39953218ce16f9c49752","schema_fingerprint":"4aa3821a28b0b7c2400bc59aba4bcc0a76e971dadd19610d3ad38c768e124dc7","schema_version":"edge-lab-recorder.raw.v1","sequence":null,"source":"clob_market_ws"}
{"event_at":"2026-07-28T02:57:27.050000Z","event_fingerprint":"785742126a65ceceff3bada228ccfe9351501a9902abe6e425040b479d5a1c4c","payload":{"connection_id":"955646bd8bf740759faf38750c0f263f","event_at":"2026-07-28T02:57:27.050000Z","event_type":"price_change","frame_hash":"925a8125029dc742049be1bea27fef967ddfb32ccce374fc6c3e9e9d2bc8c62b","frame_index":0,"kind":"data","monotonic_ns":309430385373541,"payload":{"event_type":"price_change","market":"0x0f70d07969bc69eaa97d0987de651885fdca02263688026aa11e7678af8f87aa","price_changes":[{"asset_id":"58313761654877669244690227616056238030136603415514645252000528337391143520538","best_ask":"0.48","best_bid":"0.47","hash":"51872463541629c92406714518c6d33463d91895","price":"0.47","side":"BUY","size":"17.23"},{"asset_id":"64053005904884194822931764831592250494815136296598204104072528088122126148949","best_ask":"0.53","best_bid":"0.52","hash":"8390fa7c06d31b33276bc218c41f9f5b7b2930d8","price":"0.53","side":"SELL","size":"17.23"}],"timestamp":"1785207447050"},"payload_hash":"727c8c76b9547de60d6f6ab85dc0e6d1c81d95a5287f8ac3e35128471c39bab3","raw_frame":"{\"market\":\"0x0f70d07969bc69eaa97d0987de651885fdca02263688026aa11e7678af8f87aa\", \"price_changes\":[{\"asset_id\":\"58313761654877669244690227616056238030136603415514645252000528337391143520538\", \"price\":\"0.47\", \"size\":\"17.23\", \"side\":\"BUY\", \"hash\":\"51872463541629c92406714518c6d33463d91895\", \"best_bid\":\"0.47\", \"best_ask\":\"0.48\"}, {\"asset_id\":\"64053005904884194822931764831592250494815136296598204104072528088122126148949\", \"price\":\"0.53\", \"size\":\"17.23\", \"side\":\"SELL\", \"hash\":\"8390fa7c06d31b33276bc218c41f9f5b7b2930d8\", \"best_bid\":\"0.52\", \"best_ask\":\"0.53\"}], \"timestamp\":\"1785207447050\", \"event_type\":\"price_change\"}","received_at":"2026-07-28T02:57:27.368112Z","schema_version":"clob-market-ws.price_change.v1","sequence":null,"server_hash":null,"server_timestamp":"1785207447050","session_id":"5aad79be415c487c84df42bebd84ee93","source":"clob_market_ws"},"received_at":"2026-07-28T02:57:27.368112Z","record_id":"b11a92daa7aa44a16ae42f40d4927dcab26e061fd138de06dfddeebebb681972","schema_fingerprint":"4aa3821a28b0b7c2400bc59aba4bcc0a76e971dadd19610d3ad38c768e124dc7","schema_version":"edge-lab-recorder.raw.v1","sequence":null,"source":"clob_market_ws"}
{"event_at":"2026-07-28T02:57:27.052000Z","event_fingerprint":"7d3f5f30eaf8648345893e0e13b85402a33c698ffaed850420ab77f5be2dac80","payload":{"connection_id":"955646bd8bf740759faf38750c0f263f","event_at":"2026-07-28T02:57:27.052000Z","event_type":"price_change","frame_hash":"e206fa084f5ae7f246fe1abe5ce9f557ca7f828344cb02da8c89f78eaf61ab0b","frame_index":0,"kind":"data","monotonic_ns":309430388287833,"payload":{"event_type":"price_change","market":"0x0f70d07969bc69eaa97d0987de651885fdca02263688026aa11e7678af8f87aa","price_changes":[{"asset_id":"58313761654877669244690227616056238030136603415514645252000528337391143520538","best_ask":"0.48","best_bid":"0.47","hash":"245ddc8187e65d8540cfd5a02d376d88c07cb06c","price":"0.38","side":"BUY","size":"224.84"},{"asset_id":"64053005904884194822931764831592250494815136296598204104072528088122126148949","best_ask":"0.53","best_bid":"0.52","hash":"a4bbabdb29bcdaf698836dc29bc5c06293846b42","price":"0.62","side":"SELL","size":"224.84"}],"timestamp":"1785207447052"},"payload_hash":"60a69edc86b82d10e4228ebfa3946484f0a008a2529812a640ee5d415c6e456f","raw_frame":"{\"market\":\"0x0f70d07969bc69eaa97d0987de651885fdca02263688026aa11e7678af8f87aa\", \"price_changes\":[{\"asset_id\":\"58313761654877669244690227616056238030136603415514645252000528337391143520538\", \"price\":\"0.38\", \"size\":\"224.84\", \"side\":\"BUY\", \"hash\":\"245ddc8187e65d8540cfd5a02d376d88c07cb06c\", \"best_bid\":\"0.47\", \"best_ask\":\"0.48\"}, {\"asset_id\":\"64053005904884194822931764831592250494815136296598204104072528088122126148949\", \"price\":\"0.62\", \"size\":\"224.84\", \"side\":\"SELL\", \"hash\":\"a4bbabdb29bcdaf698836dc29bc5c06293846b42\", \"best_bid\":\"0.52\", \"best_ask\":\"0.53\"}], \"timestamp\":\"1785207447052\", \"event_type\":\"price_change\"}","received_at":"2026-07-28T02:57:27.371027Z","schema_version":"clob-market-ws.price_change.v1","sequence":null,"server_hash":null,"server_timestamp":"1785207447052","session_id":"5aad79be415c487c84df42bebd84ee93","source":"clob_market_ws"},"received_at":"2026-07-28T02:57:27.371027Z","record_id":"7e9749daa79808610f132d74982d2b6167d08817f401a1c97e08954c3bbc290b","schema_fingerprint":"4aa3821a28b0b7c2400bc59aba4bcc0a76e971dadd19610d3ad38c768e124dc7","schema_version":"edge-lab-recorder.raw.v1","sequence":null,"source":"clob_market_ws"}
{"event_at":"2026-07-28T02:57:27.052000Z","event_fingerprint":"f91c094787f7b48f645cf97f1ba1e9e48efd9af932c54caef4ea4c7f87a66e08","payload":{"connection_id":"955646bd8bf740759faf38750c0f263f","event_at":"2026-07-28T02:57:27.052000Z","event_type":"price_change","frame_hash":"392f2234b020d83c85a118abaf2766136b09d4bb4145bf1afd976c960327fcbd","frame_index":0,"kind":"data","monotonic_ns":309430391180291,"payload":{"event_type":"price_change","market":"0x0f70d07969bc69eaa97d0987de651885fdca02263688026aa11e7678af8f87aa","price_changes":[{"asset_id":"58313761654877669244690227616056238030136603415514645252000528337391143520538","best_ask":"0.48","best_bid":"0.47","hash":"245ddc8187e65d8540cfd5a02d376d88c07cb06c","price":"0.39","side":"BUY","size":"250.36"},{"asset_id":"64053005904884194822931764831592250494815136296598204104072528088122126148949","best_ask":"0.53","best_bid":"0.52","hash":"a4bbabdb29bcdaf698836dc29bc5c06293846b42","price":"0.61","side":"SELL","size":"250.36"}],"timestamp":"1785207447052"},"payload_hash":"fd98eb37a250477f42834d834282c057aead81428bebb1a1831e57778f87bf7b","raw_frame":"{\"market\":\"0x0f70d07969bc69eaa97d0987de651885fdca02263688026aa11e7678af8f87aa\", \"price_changes\":[{\"asset_id\":\"58313761654877669244690227616056238030136603415514645252000528337391143520538\", \"price\":\"0.39\", \"size\":\"250.36\", \"side\":\"BUY\", \"hash\":\"245ddc8187e65d8540cfd5a02d376d88c07cb06c\", \"best_bid\":\"0.47\", \"best_ask\":\"0.48\"}, {\"asset_id\":\"64053005904884194822931764831592250494815136296598204104072528088122126148949\", \"price\":\"0.61\", \"size\":\"250.36\", \"side\":\"SELL\", \"hash\":\"a4bbabdb29bcdaf698836dc29bc5c06293846b42\", \"best_bid\":\"0.52\", \"best_ask\":\"0.53\"}], \"timestamp\":\"1785207447052\", \"event_type\":\"price_change\"}","received_at":"2026-07-28T02:57:27.373919Z","schema_version":"clob-market-ws.price_change.v1","sequence":null,"server_hash":null,"server_timestamp":"1785207447052","session_id":"5aad79be415c487c84df42bebd84ee93","source":"clob_market_ws"},"received_at":"2026-07-28T02:57:27.373919Z","record_id":"2f48a15880ed4554efc3b7c914aaa3d7587fcdc130978edfd29a5f45ba3e873d","schema_fingerprint":"4aa3821a28b0b7c2400bc59aba4bcc0a76e971dadd19610d3ad38c768e124dc7","schema_version":"edge-lab-recorder.raw.v1","sequence":null,"source":"clob_market_ws"}
{"event_at":"2026-07-28T02:57:27.052000Z","event_fingerprint":"f2632d2fe7d609a8469e7138604665b76b1acada28c15e056d7408c21030cb29","payload":{"connection_id":"955646bd8bf740759faf38750c0f263f","event_at":"2026-07-28T02:57:27.052000Z","event_type":"price_change","frame_hash":"6382f0313530e1051c16ccc20f5939f0702e8ab7bf4f24edeaa50ae7fb874101","frame_index":0,"kind":"data","monotonic_ns":309430394063833,"payload":{"event_type":"price_change","market":"0x0f70d07969bc69eaa97d0987de651885fdca02263688026aa11e7678af8f87aa","price_changes":[{"asset_id":"58313761654877669244690227616056238030136603415514645252000528337391143520538","best_ask":"0.48","best_bid":"0.47","hash":"245ddc8187e65d8540cfd5a02d376d88c07cb06c","price":"0.4","side":"BUY","size":"206.43"},{"asset_id":"64053005904884194822931764831592250494815136296598204104072528088122126148949","best_ask":"0.53","best_bid":"0.52","hash":"a4bbabdb29bcdaf698836dc29bc5c06293846b42","price":"0.6","side":"SELL","size":"206.43"}],"timestamp":"1785207447052"},"payload_hash":"6ea4dd6269d69dc071d1b920fd6acc792184368ea9f375862e4ea70705bbcd86","raw_frame":"{\"market\":\"0x0f70d07969bc69eaa97d0987de651885fdca02263688026aa11e7678af8f87aa\", \"price_changes\":[{\"asset_id\":\"58313761654877669244690227616056238030136603415514645252000528337391143520538\", \"price\":\"0.4\", \"size\":\"206.43\", \"side\":\"BUY\", \"hash\":\"245ddc8187e65d8540cfd5a02d376d88c07cb06c\", \"best_bid\":\"0.47\", \"best_ask\":\"0.48\"}, {\"asset_id\":\"64053005904884194822931764831592250494815136296598204104072528088122126148949\", \"price\":\"0.6\", \"size\":\"206.43\", \"side\":\"SELL\", \"hash\":\"a4bbabdb29bcdaf698836dc29bc5c06293846b42\", \"best_bid\":\"0.52\", \"best_ask\":\"0.53\"}], \"timestamp\":\"1785207447052\", \"event_type\":\"price_change\"}","received_at":"2026-07-28T02:57:27.376802Z","schema_version":"clob-market-ws.price_change.v1","sequence":null,"server_hash":null,"server_timestamp":"1785207447052","session_id":"5aad79be415c487c84df42bebd84ee93","source":"clob_market_ws"},"received_at":"2026-07-28T02:57:27.376802Z","record_id":"e67ec0f7dabd59df87e15302496e0dc9369fe361dab682dd61127c5546617bf1","schema_fingerprint":"4aa3821a28b0b7c2400bc59aba4bcc0a76e971dadd19610d3ad38c768e124dc7","schema_version":"edge-lab-recorder.raw.v1","sequence":null,"source":"clob_market_ws"}
{"event_at":"2026-07-28T02:57:27.054000Z","event_fingerprint":"11e208c86754062afe5eb6df49198fa3825271a6d75ee697b7efab8155501d01","payload":{"connection_id":"955646bd8bf740759faf38750c0f263f","event_at":"2026-07-28T02:57:27.054000Z","event_type":"price_change","frame_hash":"b113fb97893dc83a6ee4bd1f6d1404dd23f35686f7efa81a099ed2ab26b4b34d","frame_index":0,"kind":"data","monotonic_ns":309430395653375,"payload":{"event_type":"price_change","market":"0x0f70d07969bc69eaa97d0987de651885fdca02263688026aa11e7678af8f87aa","price_changes":[{"asset_id":"64053005904884194822931764831592250494815136296598204104072528088122126148949","best_ask":"0.53","best_bid":"0.52","hash":"de7dd6575f884943c7793a1386687291d541d5cb","price":"0.39","side":"BUY","size":"88.19"},{"asset_id":"58313761654877669244690227616056238030136603415514645252000528337391143520538","best_ask":"0.48","best_bid":"0.47","hash":"e6a9f36668682009d609f0d19df1fbc37ee0bef0","price":"0.61","side":"SELL","size":"88.19"}],"timestamp":"1785207447054"},"payload_hash":"c3a832b9a2135b8b63f250934f1cbb2add88e65ed87ae39b01596b8621489760","raw_frame":"{\"market\":\"0x0f70d07969bc69eaa97d0987de651885fdca02263688026aa11e7678af8f87aa\", \"price_changes\":[{\"asset_id\":\"64053005904884194822931764831592250494815136296598204104072528088122126148949\", \"price\":\"0.39\", \"size\":\"88.19\", \"side\":\"BUY\", \"hash\":\"de7dd6575f884943c7793a1386687291d541d5cb\", \"best_bid\":\"0.52\", \"best_ask\":\"0.53\"}, {\"asset_id\":\"58313761654877669244690227616056238030136603415514645252000528337391143520538\", \"price\":\"0.61\", \"size\":\"88.19\", \"side\":\"SELL\", \"hash\":\"e6a9f36668682009d609f0d19df1fbc37ee0bef0\", \"best_bid\":\"0.47\", \"best_ask\":\"0.48\"}], \"timestamp\":\"1785207447054\", \"event_type\":\"price_change\"}","received_at":"2026-07-28T02:57:27.378391Z","schema_version":"clob-market-ws.price_change.v1","sequence":null,"server_hash":null,"server_timestamp":"1785207447054","session_id":"5aad79be415c487c84df42bebd84ee93","source":"clob_market_ws"},"received_at":"2026-07-28T02:57:27.378391Z","record_id":"98aebf7036a8d7fbe3b6ac7b6ae3c78b1f2b1b7dfcd2f2ee8fc126cdc1472ff6","schema_fingerprint":"4aa3821a28b0b7c2400bc59aba4bcc0a76e971dadd19610d3ad38c768e124dc7","schema_version":"edge-lab-recorder.raw.v1","sequence":null,"source":"clob_market_ws"}
{"event_at":"2026-07-28T02:57:27.055000Z","event_fingerprint":"a3a213d5c99cfac20cfec5ee2b0faaa8e8ac3665d9b2189ad7340f50a5116bb4","payload":{"connection_id":"955646bd8bf740759faf38750c0f263f","event_at":"2026-07-28T02:57:27.055000Z","event_type":"price_change","frame_hash":"75ef7954dd3fcf3d28bac8c549bcd238ca641cb2f256203d08c2a04c9bf388e3","frame_index":0,"kind":"data","monotonic_ns":309430397177291,"payload":{"event_type":"price_change","market":"0x0f70d07969bc69eaa97d0987de651885fdca02263688026aa11e7678af8f87aa","price_changes":[{"asset_id":"64053005904884194822931764831592250494815136296598204104072528088122126148949","best_ask":"0.53","best_bid":"0.52","hash":"e6792369992e29af21e7b4f9b2de340050b16710","price":"0.35","side":"BUY","size":"158.1"},{"asset_id":"58313761654877669244690227616056238030136603415514645252000528337391143520538","best_ask":"0.48","best_bid":"0.47","hash":"331c087befbf7bd2c67cb983c1b308b8fa68e032","price":"0.65","side":"SELL","size":"158.1"}],"timestamp":"1785207447055"},"payload_hash":"ac8eccfe0e8094fecac3e842649046d4286e8ede8b80efecdf5eeba606150068","raw_frame":"{\"market\":\"0x0f70d07969bc69eaa97d0987de651885fdca02263688026aa11e7678af8f87aa\", \"price_changes\":[{\"asset_id\":\"64053005904884194822931764831592250494815136296598204104072528088122126148949\", \"price\":\"0.35\", \"size\":\"158.1\", \"side\":\"BUY\", \"hash\":\"e6792369992e29af21e7b4f9b2de340050b16710\", \"best_bid\":\"0.52\", \"best_ask\":\"0.53\"}, {\"asset_id\":\"58313761654877669244690227616056238030136603415514645252000528337391143520538\", \"price\":\"0.65\", \"size\":\"158.1\", \"side\":\"SELL\", \"hash\":\"331c087befbf7bd2c67cb983c1b308b8fa68e032\", \"best_bid\":\"0.47\", \"best_ask\":\"0.48\"}], \"timestamp\":\"1785207447055\", \"event_type\":\"price_change\"}","received_at":"2026-07-28T02:57:27.379915Z","schema_version":"clob-market-ws.price_change.v1","sequence":null,"server_hash":null,"server_timestamp":"1785207447055","session_id":"5aad79be415c487c84df42bebd84ee93","source":"clob_market_ws"},"received_at":"2026-07-28T02:57:27.379915Z","record_id":"1df860a6d4f4e2f0af92b073bca1edd445ccea38416b494a1af0253b182841a5","schema_fingerprint":"4aa3821a28b0b7c2400bc59aba4bcc0a76e971dadd19610d3ad38c768e124dc7","schema_version":"edge-lab-recorder.raw.v1","sequence":null,"source":"clob_market_ws"}
{"event_at":"2026-07-28T02:57:27.055000Z","event_fingerprint":"0971c10aa5146081f5f8d1b2a5923b46f3d0228ee869d6eee438286c857583e4","payload":{"connection_id":"955646bd8bf740759faf38750c0f263f","event_at":"2026-07-28T02:57:27.055000Z","event_type":"price_change","frame_hash":"dd3fcc1fdf7f08fd733c85fdc0f069fd932a8cfaada06ee2945a5d578d2221e1","frame_index":0,"kind":"data","monotonic_ns":309430398696416,"payload":{"event_type":"price_change","market":"0x0f70d07969bc69eaa97d0987de651885fdca02263688026aa11e7678af8f87aa","price_changes":[{"asset_id":"64053005904884194822931764831592250494815136296598204104072528088122126148949","best_ask":"0.53","best_bid":"0.52","hash":"e6792369992e29af21e7b4f9b2de340050b16710","price":"0.27","side":"BUY","size":"91.3"},{"asset_id":"58313761654877669244690227616056238030136603415514645252000528337391143520538","best_ask":"0.48","best_bid":"0.47","hash":"331c087befbf7bd2c67cb983c1b308b8fa68e032","price":"0.73","side":"SELL","size":"91.3"}],"timestamp":"1785207447055"},"payload_hash":"2439683ca7baf3e58687f236a59583d9e51ec0fb53eb57ce2a7e12507d4f6871","raw_frame":"{\"market\":\"0x0f70d07969bc69eaa97d0987de651885fdca02263688026aa11e7678af8f87aa\", \"price_changes\":[{\"asset_id\":\"64053005904884194822931764831592250494815136296598204104072528088122126148949\", \"price\":\"0.27\", \"size\":\"91.3\", \"side\":\"BUY\", \"hash\":\"e6792369992e29af21e7b4f9b2de340050b16710\", \"best_bid\":\"0.52\", \"best_ask\":\"0.53\"}, {\"asset_id\":\"58313761654877669244690227616056238030136603415514645252000528337391143520538\", \"price\":\"0.73\", \"size\":\"91.3\", \"side\":\"SELL\", \"hash\":\"331c087befbf7bd2c67cb983c1b308b8fa68e032\", \"best_bid\":\"0.47\", \"best_ask\":\"0.48\"}], \"timestamp\":\"1785207447055\", \"event_type\":\"price_change\"}","received_at":"2026-07-28T02:57:27.381435Z","schema_version":"clob-market-ws.price_change.v1","sequence":null,"server_hash":null,"server_timestamp":"1785207447055","session_id":"5aad79be415c487c84df42bebd84ee93","source":"clob_market_ws"},"received_at":"2026-07-28T02:57:27.381435Z","record_id":"beeb01663a4a2de1ec61f563e2619dd677dd66a678ddd01682bbd33bc7fa4ccd","schema_fingerprint":"4aa3821a28b0b7c2400bc59aba4bcc0a76e971dadd19610d3ad38c768e124dc7","schema_version":"edge-lab-recorder.raw.v1","sequence":null,"source":"clob_market_ws"}
{"event_at":"2026-07-28T02:57:27.055000Z","event_fingerprint":"529bd0488933512ee84d61a1b988e7256e4897fd8eab10a3b636ddbe166c06aa","payload":{"connection_id":"955646bd8bf740759faf38750c0f263f","event_at":"2026-07-28T02:57:27.055000Z","event_type":"price_change","frame_hash":"5b0818149ef531a5620bf03904138e37d9b11f5c2bdf3f3db0d8009301fe29d2","frame_index":0,"kind":"data","monotonic_ns":309430400188916,"payload":{"event_type":"price_change","market":"0x0f70d07969bc69eaa97d0987de651885fdca02263688026aa11e7678af8f87aa","price_changes":[{"asset_id":"64053005904884194822931764831592250494815136296598204104072528088122126148949","best_ask":"0.53","best_bid":"0.52","hash":"e6792369992e29af21e7b4f9b2de340050b16710","price":"0.26","side":"BUY","size":"108.6"},{"asset_id":"58313761654877669244690227616056238030136603415514645252000528337391143520538","best_ask":"0.48","best_bid":"0.47","hash":"331c087befbf7bd2c67cb983c1b308b8fa68e032","price":"0.74","side":"SELL","size":"108.6"}],"timestamp":"1785207447055"},"payload_hash":"ca5f45d243aacd8ac838ac479f10f326b5fde538e982efd634e547d9fef66097","raw_frame":"{\"market\":\"0x0f70d07969bc69eaa97d0987de651885fdca02263688026aa11e7678af8f87aa\", \"price_changes\":[{\"asset_id\":\"64053005904884194822931764831592250494815136296598204104072528088122126148949\", \"price\":\"0.26\", \"size\":\"108.6\", \"side\":\"BUY\", \"hash\":\"e6792369992e29af21e7b4f9b2de340050b16710\", \"best_bid\":\"0.52\", \"best_ask\":\"0.53\"}, {\"asset_id\":\"58313761654877669244690227616056238030136603415514645252000528337391143520538\", \"price\":\"0.74\", \"size\":\"108.6\", \"side\":\"SELL\", \"hash\":\"331c087befbf7bd2c67cb983c1b308b8fa68e032\", \"best_bid\":\"0.47\", \"best_ask\":\"0.48\"}], \"timestamp\":\"1785207447055\", \"event_type\":\"price_change\"}","received_at":"2026-07-28T02:57:27.382928Z","schema_version":"clob-market-ws.price_change.v1","sequence":null,"server_hash":null,"server_timestamp":"1785207447055","session_id":"5aad79be415c487c84df42bebd84ee93","source":"clob_market_ws"},"received_at":"2026-07-28T02:57:27.382928Z","record_id":"9fb82479c60f9129099421dc977e03fbabe4e026c9ab9b9301332cdd5eaf8d6a","schema_fingerprint":"4aa3821a28b0b7c2400bc59aba4bcc0a76e971dadd19610d3ad38c768e124dc7","schema_version":"edge-lab-recorder.raw.v1","sequence":null,"source":"clob_market_ws"}
{"event_at":"2026-07-28T02:57:27.055000Z","event_fingerprint":"7d7f821463b87a1a7edbac460d5adc0a94328859c12bb385041eb8000f871cf9","payload":{"connection_id":"955646bd8bf740759faf38750c0f263f","event_at":"2026-07-28T02:57:27.055000Z","event_type":"price_change","frame_hash":"5c7d37bd42af6ee3e449c7adb00bf1c5b11138d27f237edf61131d2689cf2d5c","frame_index":0,"kind":"data","monotonic_ns":309430401665583,"payload":{"event_type":"price_change","market":"0x0f70d07969bc69eaa97d0987de651885fdca02263688026aa11e7678af8f87aa","price_changes":[{"asset_id":"58313761654877669244690227616056238030136603415514645252000528337391143520538","best_ask":"0.48","best_bid":"0.47","hash":"331c087befbf7bd2c67cb983c1b308b8fa68e032","price":"0.31","side":"BUY","size":"87.1"},{"asset_id":"64053005904884194822931764831592250494815136296598204104072528088122126148949","best_ask":"0.53","best_bid":"0.52","hash":"e6792369992e29af21e7b4f9b2de340050b16710","price":"0.69","side":"SELL","size":"87.1"}],"timestamp":"1785207447055"},"payload_hash":"1fc171aab5c8ca7dd8021ac9aae903759f20ea8b7ad4b16d403a6b0aeb309e9c","raw_frame":"{\"market\":\"0x0f70d07969bc69eaa97d0987de651885fdca02263688026aa11e7678af8f87aa\", \"price_changes\":[{\"asset_id\":\"58313761654877669244690227616056238030136603415514645252000528337391143520538\", \"price\":\"0.31\", \"size\":\"87.1\", \"side\":\"BUY\", \"hash\":\"331c087befbf7bd2c67cb983c1b308b8fa68e032\", \"best_bid\":\"0.47\", \"best_ask\":\"0.48\"}, {\"asset_id\":\"64053005904884194822931764831592250494815136296598204104072528088122126148949\", \"price\":\"0.69\", \"size\":\"87.1\", \"side\":\"SELL\", \"hash\":\"e6792369992e29af21e7b4f9b2de340050b16710\", \"best_bid\":\"0.52\", \"best_ask\":\"0.53\"}], \"timestamp\":\"1785207447055\", \"event_type\":\"price_change\"}","received_at":"2026-07-28T02:57:27.384404Z","schema_version":"clob-market-ws.price_change.v1","sequence":null,"server_hash":null,"server_timestamp":"1785207447055","session_id":"5aad79be415c487c84df42bebd84ee93","source":"clob_market_ws"},"received_at":"2026-07-28T02:57:27.384404Z","record_id":"546b9cc85a5c91228ba1f6b37233f0ca5437c1aa30475ec3734240c83cd207e3","schema_fingerprint":"4aa3821a28b0b7c2400bc59aba4bcc0a76e971dadd19610d3ad38c768e124dc7","schema_version":"edge-lab-recorder.raw.v1","sequence":null,"source":"clob_market_ws"}
{"event_at":"2026-07-28T02:57:27.055000Z","event_fingerprint":"9099e53d18f23fe6819818160926b625b4add95913a82b339ac9cfa7b96c545f","payload":{"connection_id":"955646bd8bf740759faf38750c0f263f","event_at":"2026-07-28T02:57:27.055000Z","event_type":"price_change","frame_hash":"564062823dc74794ea5c3b44a139357daf6caa86e82d3f3e5f14e2dfc5c4e2af","frame_index":0,"kind":"data","monotonic_ns":309430403220375,"payload":{"event_type":"price_change","market":"0x0f70d07969bc69eaa97d0987de651885fdca02263688026aa11e7678af8f87aa","price_changes":[{"asset_id":"58313761654877669244690227616056238030136603415514645252000528337391143520538","best_ask":"0.48","best_bid":"0.47","hash":"331c087befbf7bd2c67cb983c1b308b8fa68e032","price":"0.33","side":"BUY","size":"115.5"},{"asset_id":"64053005904884194822931764831592250494815136296598204104072528088122126148949","best_ask":"0.53","best_bid":"0.52","hash":"e6792369992e29af21e7b4f9b2de340050b16710","price":"0.67","side":"SELL","size":"115.5"}],"timestamp":"1785207447055"},"payload_hash":"c75ae57a9366260ea7c5af9cd828c84100baa26d4293b5b44dee195f2ec969f2","raw_frame":"{\"market\":\"0x0f70d07969bc69eaa97d0987de651885fdca02263688026aa11e7678af8f87aa\", \"price_changes\":[{\"asset_id\":\"58313761654877669244690227616056238030136603415514645252000528337391143520538\", \"price\":\"0.33\", \"size\":\"115.5\", \"side\":\"BUY\", \"hash\":\"331c087befbf7bd2c67cb983c1b308b8fa68e032\", \"best_bid\":\"0.47\", \"best_ask\":\"0.48\"}, {\"asset_id\":\"64053005904884194822931764831592250494815136296598204104072528088122126148949\", \"price\":\"0.67\", \"size\":\"115.5\", \"side\":\"SELL\", \"hash\":\"e6792369992e29af21e7b4f9b2de340050b16710\", \"best_bid\":\"0.52\", \"best_ask\":\"0.53\"}], \"timestamp\":\"1785207447055\", \"event_type\":\"price_change\"}","received_at":"2026-07-28T02:57:27.385959Z","schema_version":"clob-market-ws.price_change.v1","sequence":null,"server_hash":null,"server_timestamp":"1785207447055","session_id":"5aad79be415c487c84df42bebd84ee93","source":"clob_market_ws"},"received_at":"2026-07-28T02:57:27.385959Z","record_id":"69454ffb130bd9d24f1a0af5ae2a786cabce8d8f56004048264a34db7977a35d","schema_fingerprint":"4aa3821a28b0b7c2400bc59aba4bcc0a76e971dadd19610d3ad38c768e124dc7","schema_version":"edge-lab-recorder.raw.v1","sequence":null,"source":"clob_market_ws"}
{"event_at":"2026-07-28T02:57:27.055000Z","event_fingerprint":"d5ee63131bba32797c0a42f741c0c1bd13ed71e88f1932120617b9121b596a3b","payload":{"connection_id":"955646bd8bf740759faf38750c0f263f","event_at":"2026-07-28T02:57:27.055000Z","event_type":"price_change","frame_hash":"5953ecbafb6588b079736a8ec45f9e785debd9c8122836dbada269ddf161f3eb","frame_index":0,"kind":"data","monotonic_ns":309430404738666,"payload":{"event_type":"price_change","market":"0x0f70d07969bc69eaa97d0987de651885fdca02263688026aa11e7678af8f87aa","price_changes":[{"asset_id":"58313761654877669244690227616056238030136603415514645252000528337391143520538","best_ask":"0.48","best_bid":"0.47","hash":"331c087befbf7bd2c67cb983c1b308b8fa68e032","price":"0.34","side":"BUY","size":"84.79"},{"asset_id":"64053005904884194822931764831592250494815136296598204104072528088122126148949","best_ask":"0.53","best_bid":"0.52","hash":"e6792369992e29af21e7b4f9b2de340050b16710","price":"0.66","side":"SELL","size":"84.79"}],"timestamp":"1785207447055"},"payload_hash":"1e042f61d7722b5641ffd7392a4460833fe277fe728462ddc2cfa808707b878f","raw_frame":"{\"market\":\"0x0f70d07969bc69eaa97d0987de651885fdca02263688026aa11e7678af8f87aa\", \"price_changes\":[{\"asset_id\":\"58313761654877669244690227616056238030136603415514645252000528337391143520538\", \"price\":\"0.34\", \"size\":\"84.79\", \"side\":\"BUY\", \"hash\":\"331c087befbf7bd2c67cb983c1b308b8fa68e032\", \"best_bid\":\"0.47\", \"best_ask\":\"0.48\"}, {\"asset_id\":\"64053005904884194822931764831592250494815136296598204104072528088122126148949\", \"price\":\"0.66\", \"size\":\"84.79\", \"side\":\"SELL\", \"hash\":\"e6792369992e29af21e7b4f9b2de340050b16710\", \"best_bid\":\"0.52\", \"best_ask\":\"0.53\"}], \"timestamp\":\"1785207447055\", \"event_type\":\"price_change\"}","received_at":"2026-07-28T02:57:27.387477Z","schema_version":"clob-market-ws.price_change.v1","sequence":null,"server_hash":null,"server_timestamp":"1785207447055","session_id":"5aad79be415c487c84df42bebd84ee93","source":"clob_market_ws"},"received_at":"2026-07-28T02:57:27.387477Z","record_id":"2078c7da127d753a363c042e9b5e41c79ccb7129a67d40849e7fa20960a354ee","schema_fingerprint":"4aa3821a28b0b7c2400bc59aba4bcc0a76e971dadd19610d3ad38c768e124dc7","schema_version":"edge-lab-recorder.raw.v1","sequence":null,"source":"clob_market_ws"}
{"event_at":"2026-07-28T02:57:27.055000Z","event_fingerprint":"5c8992091fcc740f28177a320f966f2bbee56642ad67048ee20ab23b2637f93b","payload":{"connection_id":"955646bd8bf740759faf38750c0f263f","event_at":"2026-07-28T02:57:27.055000Z","event_type":"price_change","frame_hash":"6745a8d2aa483d4a85acc5a261dadd720b2802f43c07b8a968e816f433e160de","frame_index":0,"kind":"data","monotonic_ns":309430406210791,"payload":{"event_type":"price_change","market":"0x0f70d07969bc69eaa97d0987de651885fdca02263688026aa11e7678af8f87aa","price_changes":[{"asset_id":"64053005904884194822931764831592250494815136296598204104072528088122126148949","best_ask":"0.53","best_bid":"0.52","hash":"56f8ab407fea4bd8f39701447ec99d4054e3144c","price":"0.47","side":"BUY","size":"100.81"},{"asset_id":"58313761654877669244690227616056238030136603415514645252000528337391143520538","best_ask":"0.48","best_bid":"0.47","hash":"0b6c9c8ee5d2b15feebee06d475863160f3f3175","price":"0.53","side":"SELL","size":"100.81"}],"timestamp":"1785207447055"},"payload_hash":"2473ad646e1c87cbb9c654a67389103ef227e40d2213fc27a61c17839e98eb55","raw_frame":"{\"market\":\"0x0f70d07969bc69eaa97d0987de651885fdca02263688026aa11e7678af8f87aa\", \"price_changes\":[{\"asset_id\":\"64053005904884194822931764831592250494815136296598204104072528088122126148949\", \"price\":\"0.47\", \"size\":\"100.81\", \"side\":\"BUY\", \"hash\":\"56f8ab407fea4bd8f39701447ec99d4054e3144c\", \"best_bid\":\"0.52\", \"best_ask\":\"0.53\"}, {\"asset_id\":\"58313761654877669244690227616056238030136603415514645252000528337391143520538\", \"price\":\"0.53\", \"size\":\"100.81\", \"side\":\"SELL\", \"hash\":\"0b6c9c8ee5d2b15feebee06d475863160f3f3175\", \"best_bid\":\"0.47\", \"best_ask\":\"0.48\"}], \"timestamp\":\"1785207447055\", \"event_type\":\"price_change\"}","received_at":"2026-07-28T02:57:27.388950Z","schema_version":"clob-market-ws.price_change.v1","sequence":null,"server_hash":null,"server_timestamp":"1785207447055","session_id":"5aad79be415c487c84df42bebd84ee93","source":"clob_market_ws"},"received_at":"2026-07-28T02:57:27.388950Z","record_id":"3a5e543503cbccb12bd33002ebfbfc88b90646b954b90c094d76de33bee680c2","schema_fingerprint":"4aa3821a28b0b7c2400bc59aba4bcc0a76e971dadd19610d3ad38c768e124dc7","schema_version":"edge-lab-recorder.raw.v1","sequence":null,"source":"clob_market_ws"}
{"event_at":"2026-07-28T02:57:27.055000Z","event_fingerprint":"b66164cb51633e81237529764a30acc15e1fa3089c770704c689a62c15df6729","payload":{"connection_id":"955646bd8bf740759faf38750c0f263f","event_at":"2026-07-28T02:57:27.055000Z","event_type":"price_change","frame_hash":"ddf1541f9a2df2f8318ad406f5857ec534d570bd3041cfbb9b9f2b4c9dcf54c5","frame_index":0,"kind":"data","monotonic_ns":309430407685041,"payload":{"event_type":"price_change","market":"0x0f70d07969bc69eaa97d0987de651885fdca02263688026aa11e7678af8f87aa","price_changes":[{"asset_id":"64053005904884194822931764831592250494815136296598204104072528088122126148949","best_ask":"0.53","best_bid":"0.52","hash":"56f8ab407fea4bd8f39701447ec99d4054e3144c","price":"0.46","side":"BUY","size":"109.27"},{"asset_id":"58313761654877669244690227616056238030136603415514645252000528337391143520538","best_ask":"0.48","best_bid":"0.47","hash":"0b6c9c8ee5d2b15feebee06d475863160f3f3175","price":"0.54","side":"SELL","size":"109.27"}],"timestamp":"1785207447055"},"payload_hash":"3494220b194314326810a850d4ac73f2c25c2d47e205ddcb34b97f961b914ef1","raw_frame":"{\"market\":\"0x0f70d07969bc69eaa97d0987de651885fdca02263688026aa11e7678af8f87aa\", \"price_changes\":[{\"asset_id\":\"64053005904884194822931764831592250494815136296598204104072528088122126148949\", \"price\":\"0.46\", \"size\":\"109.27\", \"side\":\"BUY\", \"hash\":\"56f8ab407fea4bd8f39701447ec99d4054e3144c\", \"best_bid\":\"0.52\", \"best_ask\":\"0.53\"}, {\"asset_id\":\"58313761654877669244690227616056238030136603415514645252000528337391143520538\", \"price\":\"0.54\", \"size\":\"109.27\", \"side\":\"SELL\", \"hash\":\"0b6c9c8ee5d2b15feebee06d475863160f3f3175\", \"best_bid\":\"0.47\", \"best_ask\":\"0.48\"}], \"timestamp\":\"1785207447055\", \"event_type\":\"price_change\"}","received_at":"2026-07-28T02:57:27.390423Z","schema_version":"clob-market-ws.price_change.v1","sequence":null,"server_hash":null,"server_timestamp":"1785207447055","session_id":"5aad79be415c487c84df42bebd84ee93","source":"clob_market_ws"},"received_at":"2026-07-28T02:57:27.390423Z","record_id":"972bd81038a87534bdf116a14f933ac9e7fc43eeb77ffded15ebe4c4d1fbddda","schema_fingerprint":"4aa3821a28b0b7c2400bc59aba4bcc0a76e971dadd19610d3ad38c768e124dc7","schema_version":"edge-lab-recorder.raw.v1","sequence":null,"source":"clob_market_ws"}
{"event_at":"2026-07-28T02:57:27.055000Z","event_fingerprint":"2d038b92b1e3d2e2a47e7d52244d72501ffb520deb97497605aecd82c5455ecd","payload":{"connection_id":"955646bd8bf740759faf38750c0f263f","event_at":"2026-07-28T02:57:27.055000Z","event_type":"price_change","frame_hash":"08d3d925a527a531a5632b7eea2bfee6b070b6a5c42589649a48d2f4c5ca1aca","frame_index":0,"kind":"data","monotonic_ns":309430409182208,"payload":{"event_type":"price_change","market":"0x0f70d07969bc69eaa97d0987de651885fdca02263688026aa11e7678af8f87aa","price_changes":[{"asset_id":"64053005904884194822931764831592250494815136296598204104072528088122126148949","best_ask":"0.53","best_bid":"0.52","hash":"56f8ab407fea4bd8f39701447ec99d4054e3144c","price":"0.48","side":"BUY","size":"42.99"},{"asset_id":"58313761654877669244690227616056238030136603415514645252000528337391143520538","best_ask":"0.48","best_bid":"0.47","hash":"0b6c9c8ee5d2b15feebee06d475863160f3f3175","price":"0.52","side":"SELL","size":"42.99"}],"timestamp":"1785207447055"},"payload_hash":"83e9fe636c973f0ff425ad6608a89af5e5e292ba02d160a43520a5551318f45d","raw_frame":"{\"market\":\"0x0f70d07969bc69eaa97d0987de651885fdca02263688026aa11e7678af8f87aa\", \"price_changes\":[{\"asset_id\":\"64053005904884194822931764831592250494815136296598204104072528088122126148949\", \"price\":\"0.48\", \"size\":\"42.99\", \"side\":\"BUY\", \"hash\":\"56f8ab407fea4bd8f39701447ec99d4054e3144c\", \"best_bid\":\"0.52\", \"best_ask\":\"0.53\"}, {\"asset_id\":\"58313761654877669244690227616056238030136603415514645252000528337391143520538\", \"price\":\"0.52\", \"size\":\"42.99\", \"side\":\"SELL\", \"hash\":\"0b6c9c8ee5d2b15feebee06d475863160f3f3175\", \"best_bid\":\"0.47\", \"best_ask\":\"0.48\"}], \"timestamp\":\"1785207447055\", \"event_type\":\"price_change\"}","received_at":"2026-07-28T02:57:27.391921Z","schema_version":"clob-market-ws.price_change.v1","sequence":null,"server_hash":null,"server_timestamp":"1785207447055","session_id":"5aad79be415c487c84df42bebd84ee93","source":"clob_market_ws"},"received_at":"2026-07-28T02:57:27.391921Z","record_id":"6c3ee77c164530b5cbc286f29701b4dad222dfcc8dc165e7b384357d405a9aa1","schema_fingerprint":"4aa3821a28b0b7c2400bc59aba4bcc0a76e971dadd19610d3ad38c768e124dc7","schema_version":"edge-lab-recorder.raw.v1","sequence":null,"source":"clob_market_ws"}
{"event_at":"2026-07-28T02:57:27.055000Z","event_fingerprint":"e967561ee2d4883cd669c3772af4055e4f4e771a920feb2ea7901b48832e8b50","payload":{"connection_id":"955646bd8bf740759faf38750c0f263f","event_at":"2026-07-28T02:57:27.055000Z","event_type":"price_change","frame_hash":"75533e643998138d4d8e3c8e3cc910d27748cdff60994945ac32b4fcf4772ef9","frame_index":0,"kind":"data","monotonic_ns":309430410702875,"payload":{"event_type":"price_change","market":"0x0f70d07969bc69eaa97d0987de651885fdca02263688026aa11e7678af8f87aa","price_changes":[{"asset_id":"64053005904884194822931764831592250494815136296598204104072528088122126148949","best_ask":"0.53","best_bid":"0.52","hash":"56f8ab407fea4bd8f39701447ec99d4054e3144c","price":"0.45","side":"BUY","size":"32"},{"asset_id":"58313761654877669244690227616056238030136603415514645252000528337391143520538","best_ask":"0.48","best_bid":"0.47","hash":"0b6c9c8ee5d2b15feebee06d475863160f3f3175","price":"0.55","side":"SELL","size":"32"}],"timestamp":"1785207447055"},"payload_hash":"9880a8725915484473b72485162f1fa30db61fb945500c3fa1407245f4bc654b","raw_frame":"{\"market\":\"0x0f70d07969bc69eaa97d0987de651885fdca02263688026aa11e7678af8f87aa\", \"price_changes\":[{\"asset_id\":\"64053005904884194822931764831592250494815136296598204104072528088122126148949\", \"price\":\"0.45\", \"size\":\"32\", \"side\":\"BUY\", \"hash\":\"56f8ab407fea4bd8f39701447ec99d4054e3144c\", \"best_bid\":\"0.52\", \"best_ask\":\"0.53\"}, {\"asset_id\":\"58313761654877669244690227616056238030136603415514645252000528337391143520538\", \"price\":\"0.55\", \"size\":\"32\", \"side\":\"SELL\", \"hash\":\"0b6c9c8ee5d2b15feebee06d475863160f3f3175\", \"best_bid\":\"0.47\", \"best_ask\":\"0.48\"}], \"timestamp\":\"1785207447055\", \"event_type\":\"price_change\"}","received_at":"2026-07-28T02:57:27.393439Z","schema_version":"clob-market-ws.price_change.v1","sequence":null,"server_hash":null,"server_timestamp":"1785207447055","session_id":"5aad79be415c487c84df42bebd84ee93","source":"clob_market_ws"},"received_at":"2026-07-28T02:57:27.393439Z","record_id":"f58f63d4c425ff7414e5a5b1db844a220a68337ac589c363284ad3a024b71d2d","schema_fingerprint":"4aa3821a28b0b7c2400bc59aba4bcc0a76e971dadd19610d3ad38c768e124dc7","schema_version":"edge-lab-recorder.raw.v1","sequence":null,"source":"clob_market_ws"}
{"event_at":"2026-07-28T02:57:27.059000Z","event_fingerprint":"6770c27a70a5786b82ce548ec560337439a871619041e02da6c7b2d23c2914f3","payload":{"connection_id":"955646bd8bf740759faf38750c0f263f","event_at":"2026-07-28T02:57:27.059000Z","event_type":"price_change","frame_hash":"e7714d2faf60417e51d0055d474c22753abf5206446d863a43a925f3cea559fb","frame_index":0,"kind":"data","monotonic_ns":309430412295333,"payload":{"event_type":"price_change","market":"0x0f70d07969bc69eaa97d0987de651885fdca02263688026aa11e7678af8f87aa","price_changes":[{"asset_id":"64053005904884194822931764831592250494815136296598204104072528088122126148949","best_ask":"0.53","best_bid":"0.52","hash":"8f9111ebac531ce8134926234cce1491766fded1","price":"0.41","side":"BUY","size":"53.5"},{"asset_id":"58313761654877669244690227616056238030136603415514645252000528337391143520538","best_ask":"0.48","best_bid":"0.47","hash":"201cdbf1a58ee8ad29d79855ce30c414839ed56b","price":"0.59","side":"SELL","size":"53.5"}],"timestamp":"1785207447059"},"payload_hash":"92b5cb08b95f564d9b63937cd7707c38533d09065cabf486b9ef61b2f1cd675c","raw_frame":"{\"market\":\"0x0f70d07969bc69eaa97d0987de651885fdca02263688026aa11e7678af8f87aa\", \"price_changes\":[{\"asset_id\":\"64053005904884194822931764831592250494815136296598204104072528088122126148949\", \"price\":\"0.41\", \"size\":\"53.5\", \"side\":\"BUY\", \"hash\":\"8f9111ebac531ce8134926234cce1491766fded1\", \"best_bid\":\"0.52\", \"best_ask\":\"0.53\"}, {\"asset_id\":\"58313761654877669244690227616056238030136603415514645252000528337391143520538\", \"price\":\"0.59\", \"size\":\"53.5\", \"side\":\"SELL\", \"hash\":\"201cdbf1a58ee8ad29d79855ce30c414839ed56b\", \"best_bid\":\"0.47\", \"best_ask\":\"0.48\"}], \"timestamp\":\"1785207447059\", \"event_type\":\"price_change\"}","received_at":"2026-07-28T02:57:27.395033Z","schema_version":"clob-market-ws.price_change.v1","sequence":null,"server_hash":null,"server_timestamp":"1785207447059","session_id":"5aad79be415c487c84df42bebd84ee93","source":"clob_market_ws"},"received_at":"2026-07-28T02:57:27.395033Z","record_id":"d049519d8da0b887fd806874f2af2fb9fd8ca27ef65d592ad67c2e5b02bd6dea","schema_fingerprint":"4aa3821a28b0b7c2400bc59aba4bcc0a76e971dadd19610d3ad38c768e124dc7","schema_version":"edge-lab-recorder.raw.v1","sequence":null,"source":"clob_market_ws"}
{"event_at":"2026-07-28T02:57:27.061000Z","event_fingerprint":"d350edf3a229a1ac6c2f8b4ca49ee14467fa2ea83d47823a984a2d307f4cd3fc","payload":{"connection_id":"955646bd8bf740759faf38750c0f263f","event_at":"2026-07-28T02:57:27.061000Z","event_type":"price_change","frame_hash":"4bbebcccae180f67b093757dec763f9efde1bdab459dad0120fa81c763a157aa","frame_index":0,"kind":"data","monotonic_ns":309430413767833,"payload":{"event_type":"price_change","market":"0x0f70d07969bc69eaa97d0987de651885fdca02263688026aa11e7678af8f87aa","price_changes":[{"asset_id":"64053005904884194822931764831592250494815136296598204104072528088122126148949","best_ask":"0.53","best_bid":"0.52","hash":"33843b574830f4d6e8b85409517203c8d370f1a5","price":"0.51","side":"BUY","size":"131.1"},{"asset_id":"58313761654877669244690227616056238030136603415514645252000528337391143520538","best_ask":"0.48","best_bid":"0.47","hash":"1429fe508723f9d47fb1768ec68bf2222589ae57","price":"0.49","side":"SELL","size":"131.1"}],"timestamp":"1785207447061"},"payload_hash":"6fec5681d6d934e4db549ac6f51034420913240e4d70d9e52029a218437c5fc5","raw_frame":"{\"market\":\"0x0f70d07969bc69eaa97d0987de651885fdca02263688026aa11e7678af8f87aa\", \"price_changes\":[{\"asset_id\":\"64053005904884194822931764831592250494815136296598204104072528088122126148949\", \"price\":\"0.51\", \"size\":\"131.1\", \"side\":\"BUY\", \"hash\":\"33843b574830f4d6e8b85409517203c8d370f1a5\", \"best_bid\":\"0.52\", \"best_ask\":\"0.53\"}, {\"asset_id\":\"58313761654877669244690227616056238030136603415514645252000528337391143520538\", \"price\":\"0.49\", \"size\":\"131.1\", \"side\":\"SELL\", \"hash\":\"1429fe508723f9d47fb1768ec68bf2222589ae57\", \"best_bid\":\"0.47\", \"best_ask\":\"0.48\"}], \"timestamp\":\"1785207447061\", \"event_type\":\"price_change\"}","received_at":"2026-07-28T02:57:27.396506Z","schema_version":"clob-market-ws.price_change.v1","sequence":null,"server_hash":null,"server_timestamp":"1785207447061","session_id":"5aad79be415c487c84df42bebd84ee93","source":"clob_market_ws"},"received_at":"2026-07-28T02:57:27.396506Z","record_id":"196c7378ec71bb7465511aff88570a5dd6b6b95f84b126743d5f54a41f0b0246","schema_fingerprint":"4aa3821a28b0b7c2400bc59aba4bcc0a76e971dadd19610d3ad38c768e124dc7","schema_version":"edge-lab-recorder.raw.v1","sequence":null,"source":"clob_market_ws"}
{"event_at":"2026-07-28T02:57:27.061000Z","event_fingerprint":"b63a9c516aecd26643c64f12ad64e2b567c0bc3375030e39862799188b22c23f","payload":{"connection_id":"955646bd8bf740759faf38750c0f263f","event_at":"2026-07-28T02:57:27.061000Z","event_type":"price_change","frame_hash":"41f15f3359f18abc2d1e2ddd6663e6fb6b52ccc58c680bebca34841348ff19fb","frame_index":0,"kind":"data","monotonic_ns":309430415253625,"payload":{"event_type":"price_change","market":"0x0f70d07969bc69eaa97d0987de651885fdca02263688026aa11e7678af8f87aa","price_changes":[{"asset_id":"58313761654877669244690227616056238030136603415514645252000528337391143520538","best_ask":"0.48","best_bid":"0.47","hash":"e954002e8cfb1697f2dbefdf92d4ee61e6e933fa","price":"0.56","side":"SELL","size":"77"},{"asset_id":"64053005904884194822931764831592250494815136296598204104072528088122126148949","best_ask":"0.53","best_bid":"0.52","hash":"59f5fd8a09fc4bc5995112355bba76f43320f863","price":"0.44","side":"BUY","size":"77"}],"timestamp":"1785207447061"},"payload_hash":"0923bc31f2ebb7a7da07e1a8130783374fd466f5160d3479cf5881acf83037b9","raw_frame":"{\"market\":\"0x0f70d07969bc69eaa97d0987de651885fdca02263688026aa11e7678af8f87aa\", \"price_changes\":[{\"asset_id\":\"58313761654877669244690227616056238030136603415514645252000528337391143520538\", \"price\":\"0.56\", \"size\":\"77\", \"side\":\"SELL\", \"hash\":\"e954002e8cfb1697f2dbefdf92d4ee61e6e933fa\", \"best_bid\":\"0.47\", \"best_ask\":\"0.48\"}, {\"asset_id\":\"64053005904884194822931764831592250494815136296598204104072528088122126148949\", \"price\":\"0.44\", \"size\":\"77\", \"side\":\"BUY\", \"hash\":\"59f5fd8a09fc4bc5995112355bba76f43320f863\", \"best_bid\":\"0.52\", \"best_ask\":\"0.53\"}], \"timestamp\":\"1785207447061\", \"event_type\":\"price_change\"}","received_at":"2026-07-28T02:57:27.397992Z","schema_version":"clob-market-ws.price_change.v1","sequence":null,"server_hash":null,"server_timestamp":"1785207447061","session_id":"5aad79be415c487c84df42bebd84ee93","source":"clob_market_ws"},"received_at":"2026-07-28T02:57:27.397992Z","record_id":"003d287f849e87f1ed3805168501f440665503285454ce249fd69b12c187d413","schema_fingerprint":"4aa3821a28b0b7c2400bc59aba4bcc0a76e971dadd19610d3ad38c768e124dc7","schema_version":"edge-lab-recorder.raw.v1","sequence":null,"source":"clob_market_ws"}
{"event_at":"2026-07-28T02:57:27.061000Z","event_fingerprint":"c9e2d52f37525c73826e37cd21746c3a33e0a2e99adf837548b79cbfbef3eb19","payload":{"connection_id":"955646bd8bf740759faf38750c0f263f","event_at":"2026-07-28T02:57:27.061000Z","event_type":"price_change","frame_hash":"876a134e8fd423e307b20d485230d9b7ac6d90836a26c82d2d0a06461bcb53d0","frame_index":0,"kind":"data","monotonic_ns":309430416755500,"payload":{"event_type":"price_change","market":"0x0f70d07969bc69eaa97d0987de651885fdca02263688026aa11e7678af8f87aa","price_changes":[{"asset_id":"64053005904884194822931764831592250494815136296598204104072528088122126148949","best_ask":"0.53","best_bid":"0.52","hash":"f4b6bceacaca4cc99b20979d75dbeb2273165217","price":"0.49","side":"BUY","size":"126.11"},{"asset_id":"58313761654877669244690227616056238030136603415514645252000528337391143520538","best_ask":"0.48","best_bid":"0.47","hash":"dfea4a8ba618ab9fac7c231671b4e4352d74a35c","price":"0.51","side":"SELL","size":"126.11"}],"timestamp":"1785207447061"},"payload_hash":"38faa582f9e741e8088f137e9d2f1939d4c51d9fc28d098b18c8023e70d3a8a6","raw_frame":"{\"market\":\"0x0f70d07969bc69eaa97d0987de651885fdca02263688026aa11e7678af8f87aa\", \"price_changes\":[{\"asset_id\":\"64053005904884194822931764831592250494815136296598204104072528088122126148949\", \"price\":\"0.49\", \"size\":\"126.11\", \"side\":\"BUY\", \"hash\":\"f4b6bceacaca4cc99b20979d75dbeb2273165217\", \"best_bid\":\"0.52\", \"best_ask\":\"0.53\"}, {\"asset_id\":\"58313761654877669244690227616056238030136603415514645252000528337391143520538\", \"price\":\"0.51\", \"size\":\"126.11\", \"side\":\"SELL\", \"hash\":\"dfea4a8ba618ab9fac7c231671b4e4352d74a35c\", \"best_bid\":\"0.47\", \"best_ask\":\"0.48\"}], \"timestamp\":\"1785207447061\", \"event_type\":\"price_change\"}","received_at":"2026-07-28T02:57:27.399493Z","schema_version":"clob-market-ws.price_change.v1","sequence":null,"server_hash":null,"server_timestamp":"1785207447061","session_id":"5aad79be415c487c84df42bebd84ee93","source":"clob_market_ws"},"received_at":"2026-07-28T02:57:27.399493Z","record_id":"3dd6842dd27b177647e459fdb668403c261816edc4974b111ba9f02d2061e0de","schema_fingerprint":"4aa3821a28b0b7c2400bc59aba4bcc0a76e971dadd19610d3ad38c768e124dc7","schema_version":"edge-lab-recorder.raw.v1","sequence":null,"source":"clob_market_ws"}
{"event_at":"2026-07-28T02:57:27.062000Z","event_fingerprint":"ef5aabf4c4fdcd85c8742872e1e7895b1d8a381a8c5911148ccc094708a2a271","payload":{"connection_id":"955646bd8bf740759faf38750c0f263f","event_at":"2026-07-28T02:57:27.062000Z","event_type":"price_change","frame_hash":"c000be8ad4c5160544dda792b05e1ba73903f89df784ff3a0c3512e7558ef139","frame_index":0,"kind":"data","monotonic_ns":309430418347458,"payload":{"event_type":"price_change","market":"0x0f70d07969bc69eaa97d0987de651885fdca02263688026aa11e7678af8f87aa","price_changes":[{"asset_id":"64053005904884194822931764831592250494815136296598204104072528088122126148949","best_ask":"0.53","best_bid":"0.52","hash":"666864535a85be8b64fe1d4732f8ddda5cdf768b","price":"0.44","side":"BUY","size":"72"},{"asset_id":"58313761654877669244690227616056238030136603415514645252000528337391143520538","best_ask":"0.48","best_bid":"0.47","hash":"d91cf247657d723dff38e1738644043796abd187","price":"0.56","side":"SELL","size":"72"}],"timestamp":"1785207447062"},"payload_hash":"02130dd44af05b1528bff072371283c3063ce2b4a90c87f5af6d22c91b14f898","raw_frame":"{\"market\":\"0x0f70d07969bc69eaa97d0987de651885fdca02263688026aa11e7678af8f87aa\", \"price_changes\":[{\"asset_id\":\"64053005904884194822931764831592250494815136296598204104072528088122126148949\", \"price\":\"0.44\", \"size\":\"72\", \"side\":\"BUY\", \"hash\":\"666864535a85be8b64fe1d4732f8ddda5cdf768b\", \"best_bid\":\"0.52\", \"best_ask\":\"0.53\"}, {\"asset_id\":\"58313761654877669244690227616056238030136603415514645252000528337391143520538\", \"price\":\"0.56\", \"size\":\"72\", \"side\":\"SELL\", \"hash\":\"d91cf247657d723dff38e1738644043796abd187\", \"best_bid\":\"0.47\", \"best_ask\":\"0.48\"}], \"timestamp\":\"1785207447062\", \"event_type\":\"price_change\"}","received_at":"2026-07-28T02:57:27.401085Z","schema_version":"clob-market-ws.price_change.v1","sequence":null,"server_hash":null,"server_timestamp":"1785207447062","session_id":"5aad79be415c487c84df42bebd84ee93","source":"clob_market_ws"},"received_at":"2026-07-28T02:57:27.401085Z","record_id":"a46503190f0c4fc154aa8fd159f60cfa9874b78b9e26e48bbc91f3b646c2f32f","schema_fingerprint":"4aa3821a28b0b7c2400bc59aba4bcc0a76e971dadd19610d3ad38c768e124dc7","schema_version":"edge-lab-recorder.raw.v1","sequence":null,"source":"clob_market_ws"}
{"event_at":"2026-07-28T02:57:27.063000Z","event_fingerprint":"b8a5309d08fd3ddee3547c5810a3e65cbed739c5d44d4247a139c6d98f194aa0","payload":{"connection_id":"955646bd8bf740759faf38750c0f263f","event_at":"2026-07-28T02:57:27.063000Z","event_type":"price_change","frame_hash":"172e04bbdf40ada69715fd5f30283a00c426cbc55c330cb183cb8cb676a79441","frame_index":0,"kind":"data","monotonic_ns":309430419911708,"payload":{"event_type":"price_change","market":"0x0f70d07969bc69eaa97d0987de651885fdca02263688026aa11e7678af8f87aa","price_changes":[{"asset_id":"58313761654877669244690227616056238030136603415514645252000528337391143520538","best_ask":"0.48","best_bid":"0.47","hash":"32c9d36ba7101d29a743e887973a14aa5b5e8867","price":"0.46","side":"BUY","size":"58.7"},{"asset_id":"64053005904884194822931764831592250494815136296598204104072528088122126148949","best_ask":"0.53","best_bid":"0.52","hash":"25b2f1f829f3134992c85da57821ac5b4cc0e427","price":"0.54","side":"SELL","size":"58.7"}],"timestamp":"1785207447063"},"payload_hash":"90f345db6b382b45afee21b136fe7bd81c0ac0b9db4c73b5a99c6edebb537cd7","raw_frame":"{\"market\":\"0x0f70d07969bc69eaa97d0987de651885fdca02263688026aa11e7678af8f87aa\", \"price_changes\":[{\"asset_id\":\"58313761654877669244690227616056238030136603415514645252000528337391143520538\", \"price\":\"0.46\", \"size\":\"58.7\", \"side\":\"BUY\", \"hash\":\"32c9d36ba7101d29a743e887973a14aa5b5e8867\", \"best_bid\":\"0.47\", \"best_ask\":\"0.48\"}, {\"asset_id\":\"64053005904884194822931764831592250494815136296598204104072528088122126148949\", \"price\":\"0.54\", \"size\":\"58.7\", \"side\":\"SELL\", \"hash\":\"25b2f1f829f3134992c85da57821ac5b4cc0e427\", \"best_bid\":\"0.52\", \"best_ask\":\"0.53\"}], \"timestamp\":\"1785207447063\", \"event_type\":\"price_change\"}","received_at":"2026-07-28T02:57:27.402649Z","schema_version":"clob-market-ws.price_change.v1","sequence":null,"server_hash":null,"server_timestamp":"1785207447063","session_id":"5aad79be415c487c84df42bebd84ee93","source":"clob_market_ws"},"received_at":"2026-07-28T02:57:27.402649Z","record_id":"c93ff61a9a3278948b487837804500bfebf6e670f99bf10c3f4fb2956d540848","schema_fingerprint":"4aa3821a28b0b7c2400bc59aba4bcc0a76e971dadd19610d3ad38c768e124dc7","schema_version":"edge-lab-recorder.raw.v1","sequence":null,"source":"clob_market_ws"}
{"event_at":"2026-07-28T02:57:27.063000Z","event_fingerprint":"a029e70515d4418d7e433a98111bba8d583f9c16c012e1ed851e97d960046577","payload":{"connection_id":"955646bd8bf740759faf38750c0f263f","event_at":"2026-07-28T02:57:27.063000Z","event_type":"price_change","frame_hash":"232b294fe6d5c20a73fa162dbb6e0baae5ea5785914ea81376062984d3c3ec43","frame_index":0,"kind":"data","monotonic_ns":309430421621875,"payload":{"event_type":"price_change","market":"0x0f70d07969bc69eaa97d0987de651885fdca02263688026aa11e7678af8f87aa","price_changes":[{"asset_id":"58313761654877669244690227616056238030136603415514645252000528337391143520538","best_ask":"0.48","best_bid":"0.47","hash":"902e0c1a43857d48f5779a80ff308703742bf468","price":"0.19","side":"BUY","size":"318.71"},{"asset_id":"64053005904884194822931764831592250494815136296598204104072528088122126148949","best_ask":"0.53","best_bid":"0.52","hash":"287aade368e6f6ac26c8badbca95a439d9c91c9a","price":"0.81","side":"SELL","size":"318.71"}],"timestamp":"1785207447063"},"payload_hash":"ea2544f840133ad427de6a62aaa64f6ca67e732fef85dd28dc471b1eceb812ef","raw_frame":"{\"market\":\"0x0f70d07969bc69eaa97d0987de651885fdca02263688026aa11e7678af8f87aa\", \"price_changes\":[{\"asset_id\":\"58313761654877669244690227616056238030136603415514645252000528337391143520538\", \"price\":\"0.19\", \"size\":\"318.71\", \"side\":\"BUY\", \"hash\":\"902e0c1a43857d48f5779a80ff308703742bf468\", \"best_bid\":\"0.47\", \"best_ask\":\"0.48\"}, {\"asset_id\":\"64053005904884194822931764831592250494815136296598204104072528088122126148949\", \"price\":\"0.81\", \"size\":\"318.71\", \"side\":\"SELL\", \"hash\":\"287aade368e6f6ac26c8badbca95a439d9c91c9a\", \"best_bid\":\"0.52\", \"best_ask\":\"0.53\"}], \"timestamp\":\"1785207447063\", \"event_type\":\"price_change\"}","received_at":"2026-07-28T02:57:27.404357Z","schema_version":"clob-market-ws.price_change.v1","sequence":null,"server_hash":null,"server_timestamp":"1785207447063","session_id":"5aad79be415c487c84df42bebd84ee93","source":"clob_market_ws"},"received_at":"2026-07-28T02:57:27.404357Z","record_id":"b9c63a818913a26631fb19661cfa6a4053a4038f662fbc7805287242bb884327","schema_fingerprint":"4aa3821a28b0b7c2400bc59aba4bcc0a76e971dadd19610d3ad38c768e124dc7","schema_version":"edge-lab-recorder.raw.v1","sequence":null,"source":"clob_market_ws"}
{"event_at":"2026-07-28T02:57:27.064000Z","event_fingerprint":"9937c0db7834f9f516efe80ed3a707ca144f76b1d90bded59a7cc79cf28faaf5","payload":{"connection_id":"955646bd8bf740759faf38750c0f263f","event_at":"2026-07-28T02:57:27.064000Z","event_type":"price_change","frame_hash":"4379d176dbbb8bf5d11b24e01fcc06638e016a5349de47f570aebe2453081cd2","frame_index":0,"kind":"data","monotonic_ns":309430422976083,"payload":{"event_type":"price_change","market":"0x0f70d07969bc69eaa97d0987de651885fdca02263688026aa11e7678af8f87aa","price_changes":[{"asset_id":"64053005904884194822931764831592250494815136296598204104072528088122126148949","best_ask":"0.53","best_bid":"0.52","hash":"8b97c7b0a496084566f2e0b12f584c4d5a7d0fc1","price":"0.5","side":"BUY","size":"140.5"},{"asset_id":"58313761654877669244690227616056238030136603415514645252000528337391143520538","best_ask":"0.48","best_bid":"0.47","hash":"7e2d0665fa610079c8e8145557b016959db1f6cb","price":"0.5","side":"SELL","size":"140.5"}],"timestamp":"1785207447064"},"payload_hash":"cf7db52174f78c29a963f8970d3e02069b9f2b2bf05a00d2971651a4d81aae70","raw_frame":"{\"market\":\"0x0f70d07969bc69eaa97d0987de651885fdca02263688026aa11e7678af8f87aa\", \"price_changes\":[{\"asset_id\":\"64053005904884194822931764831592250494815136296598204104072528088122126148949\", \"price\":\"0.5\", \"size\":\"140.5\", \"side\":\"BUY\", \"hash\":\"8b97c7b0a496084566f2e0b12f584c4d5a7d0fc1\", \"best_bid\":\"0.52\", \"best_ask\":\"0.53\"}, {\"asset_id\":\"58313761654877669244690227616056238030136603415514645252000528337391143520538\", \"price\":\"0.5\", \"size\":\"140.5\", \"side\":\"SELL\", \"hash\":\"7e2d0665fa610079c8e8145557b016959db1f6cb\", \"best_bid\":\"0.47\", \"best_ask\":\"0.48\"}], \"timestamp\":\"1785207447064\", \"event_type\":\"price_change\"}","received_at":"2026-07-28T02:57:27.405713Z","schema_version":"clob-market-ws.price_change.v1","sequence":null,"server_hash":null,"server_timestamp":"1785207447064","session_id":"5aad79be415c487c84df42bebd84ee93","source":"clob_market_ws"},"received_at":"2026-07-28T02:57:27.405713Z","record_id":"21c8eb12ca7be2792bdcf5851f63bcd2ebb11b9f27590f19fc3b09295de60b3f","schema_fingerprint":"4aa3821a28b0b7c2400bc59aba4bcc0a76e971dadd19610d3ad38c768e124dc7","schema_version":"edge-lab-recorder.raw.v1","sequence":null,"source":"clob_market_ws"}
{"event_at":"2026-07-28T02:57:27.065000Z","event_fingerprint":"0023871f6b4d1329844b18f5c763da35ec357f728d683b39e78a669e48edefa4","payload":{"connection_id":"955646bd8bf740759faf38750c0f263f","event_at":"2026-07-28T02:57:27.065000Z","event_type":"price_change","frame_hash":"b89dbcb96dc36c3b026145480c956216d1f50820ab32a41e5578d23260d71192","frame_index":0,"kind":"data","monotonic_ns":309430424475250,"payload":{"event_type":"price_change","market":"0x0f70d07969bc69eaa97d0987de651885fdca02263688026aa11e7678af8f87aa","price_changes":[{"asset_id":"58313761654877669244690227616056238030136603415514645252000528337391143520538","best_ask":"0.48","best_bid":"0.47","hash":"0616d9ac7c0f1d2258e60d7dd9bb808706e99c47","price":"0.38","side":"BUY","size":"207.84"},{"asset_id":"64053005904884194822931764831592250494815136296598204104072528088122126148949","best_ask":"0.53","best_bid":"0.52","hash":"75c692198358238c6937bf880bfefcade838b599","price":"0.62","side":"SELL","size":"207.84"}],"timestamp":"1785207447065"},"payload_hash":"81440b9220a7436ccb3f8c94865cf16d2dced20390cadbae69d6a298796d9d6f","raw_frame":"{\"market\":\"0x0f70d07969bc69eaa97d0987de651885fdca02263688026aa11e7678af8f87aa\", \"price_changes\":[{\"asset_id\":\"58313761654877669244690227616056238030136603415514645252000528337391143520538\", \"price\":\"0.38\", \"size\":\"207.84\", \"side\":\"BUY\", \"hash\":\"0616d9ac7c0f1d2258e60d7dd9bb808706e99c47\", \"best_bid\":\"0.47\", \"best_ask\":\"0.48\"}, {\"asset_id\":\"64053005904884194822931764831592250494815136296598204104072528088122126148949\", \"price\":\"0.62\", \"size\":\"207.84\", \"side\":\"SELL\", \"hash\":\"75c692198358238c6937bf880bfefcade838b599\", \"best_bid\":\"0.52\", \"best_ask\":\"0.53\"}], \"timestamp\":\"1785207447065\", \"event_type\":\"price_change\"}","received_at":"2026-07-28T02:57:27.407214Z","schema_version":"clob-market-ws.price_change.v1","sequence":null,"server_hash":null,"server_timestamp":"1785207447065","session_id":"5aad79be415c487c84df42bebd84ee93","source":"clob_market_ws"},"received_at":"2026-07-28T02:57:27.407214Z","record_id":"565999b0cd9fef58495b2253521558187657340da0095951e7f8da5ddffdbcde","schema_fingerprint":"4aa3821a28b0b7c2400bc59aba4bcc0a76e971dadd19610d3ad38c768e124dc7","schema_version":"edge-lab-recorder.raw.v1","sequence":null,"source":"clob_market_ws"}
{"event_at":"2026-07-28T02:57:27.065000Z","event_fingerprint":"18a20c3dd3685cd6b799d9d0ae4aa85da2b1a3bd0f3750da4b0e9aece99424cf","payload":{"connection_id":"955646bd8bf740759faf38750c0f263f","event_at":"2026-07-28T02:57:27.065000Z","event_type":"price_change","frame_hash":"9081cd76ef91aca3e09cb7b7d016c58811144d8a4559fc15f13cb8f0f55816bb","frame_index":0,"kind":"data","monotonic_ns":309430425948291,"payload":{"event_type":"price_change","market":"0x0f70d07969bc69eaa97d0987de651885fdca02263688026aa11e7678af8f87aa","price_changes":[{"asset_id":"58313761654877669244690227616056238030136603415514645252000528337391143520538","best_ask":"0.48","best_bid":"0.47","hash":"0616d9ac7c0f1d2258e60d7dd9bb808706e99c47","price":"0.39","side":"BUY","size":"233.56"},{"asset_id":"64053005904884194822931764831592250494815136296598204104072528088122126148949","best_ask":"0.53","best_bid":"0.52","hash":"75c692198358238c6937bf880bfefcade838b599","price":"0.61","side":"SELL","size":"233.56"}],"timestamp":"1785207447065"},"payload_hash":"e962fec6a065e8d89a836da712669e7a0023bdc92aa8801463bbf7d42a79aa7a","raw_frame":"{\"market\":\"0x0f70d07969bc69eaa97d0987de651885fdca02263688026aa11e7678af8f87aa\", \"price_changes\":[{\"asset_id\":\"58313761654877669244690227616056238030136603415514645252000528337391143520538\", \"price\":\"0.39\", \"size\":\"233.56\", \"side\":\"BUY\", \"hash\":\"0616d9ac7c0f1d2258e60d7dd9bb808706e99c47\", \"best_bid\":\"0.47\", \"best_ask\":\"0.48\"}, {\"asset_id\":\"64053005904884194822931764831592250494815136296598204104072528088122126148949\", \"price\":\"0.61\", \"size\":\"233.56\", \"side\":\"SELL\", \"hash\":\"75c692198358238c6937bf880bfefcade838b599\", \"best_bid\":\"0.52\", \"best_ask\":\"0.53\"}], \"timestamp\":\"1785207447065\", \"event_type\":\"price_change\"}","received_at":"2026-07-28T02:57:27.408687Z","schema_version":"clob-market-ws.price_change.v1","sequence":null,"server_hash":null,"server_timestamp":"1785207447065","session_id":"5aad79be415c487c84df42bebd84ee93","source":"clob_market_ws"},"received_at":"2026-07-28T02:57:27.408687Z","record_id":"22557ed9e161310473bb99db100548c9426b256284351c2dea7a72fbc635e0ae","schema_fingerprint":"4aa3821a28b0b7c2400bc59aba4bcc0a76e971dadd19610d3ad38c768e124dc7","schema_version":"edge-lab-recorder.raw.v1","sequence":null,"source":"clob_market_ws"}
{"event_at":"2026-07-28T02:57:27.065000Z","event_fingerprint":"90e31bfe17982e0abd22584a24ef8a3d5e0620054c9c739bb15feef245feec9b","payload":{"connection_id":"955646bd8bf740759faf38750c0f263f","event_at":"2026-07-28T02:57:27.065000Z","event_type":"price_change","frame_hash":"9d9dd571ea9cee40fad4edfba16029d182b4c7f6d6a5d46d9f1ed25257ac0a58","frame_index":0,"kind":"data","monotonic_ns":309430427425791,"payload":{"event_type":"price_change","market":"0x0f70d07969bc69eaa97d0987de651885fdca02263688026aa11e7678af8f87aa","price_changes":[{"asset_id":"58313761654877669244690227616056238030136603415514645252000528337391143520538","best_ask":"0.48","best_bid":"0.47","hash":"0616d9ac7c0f1d2258e60d7dd9bb808706e99c47","price":"0.4","side":"BUY","size":"189.73"},{"asset_id":"64053005904884194822931764831592250494815136296598204104072528088122126148949","best_ask":"0.53","best_bid":"0.52","hash":"75c692198358238c6937bf880bfefcade838b599","price":"0.6","side":"SELL","size":"189.73"}],"timestamp":"1785207447065"},"payload_hash":"40abf22e8bfce15bc7a0dbca81cc58235134004921daf3fdabee4fa3109696e7","raw_frame":"{\"market\":\"0x0f70d07969bc69eaa97d0987de651885fdca02263688026aa11e7678af8f87aa\", \"price_changes\":[{\"asset_id\":\"58313761654877669244690227616056238030136603415514645252000528337391143520538\", \"price\":\"0.4\", \"size\":\"189.73\", \"side\":\"BUY\", \"hash\":\"0616d9ac7c0f1d2258e60d7dd9bb808706e99c47\", \"best_bid\":\"0.47\", \"best_ask\":\"0.48\"}, {\"asset_id\":\"64053005904884194822931764831592250494815136296598204104072528088122126148949\", \"price\":\"0.6\", \"size\":\"189.73\", \"side\":\"SELL\", \"hash\":\"75c692198358238c6937bf880bfefcade838b599\", \"best_bid\":\"0.52\", \"best_ask\":\"0.53\"}], \"timestamp\":\"1785207447065\", \"event_type\":\"price_change\"}","received_at":"2026-07-28T02:57:27.410165Z","schema_version":"clob-market-ws.price_change.v1","sequence":null,"server_hash":null,"server_timestamp":"1785207447065","session_id":"5aad79be415c487c84df42bebd84ee93","source":"clob_market_ws"},"received_at":"2026-07-28T02:57:27.410165Z","record_id":"dea6069dc4c2e7fd4d22b59b67d78f3d08399917fa0451e6a46fc386a18510d5","schema_fingerprint":"4aa3821a28b0b7c2400bc59aba4bcc0a76e971dadd19610d3ad38c768e124dc7","schema_version":"edge-lab-recorder.raw.v1","sequence":null,"source":"clob_market_ws"}
{"event_at":"2026-07-28T02:57:27.065000Z","event_fingerprint":"8077150b5193b575ec94d82492f5f4f66a7f2cfc3607a255465e4038c9e37da5","payload":{"connection_id":"955646bd8bf740759faf38750c0f263f","event_at":"2026-07-28T02:57:27.065000Z","event_type":"price_change","frame_hash":"46219be36a6c9f44b47a527425c9f566722160dc76973b4aacc4fa5102a317ef","frame_index":0,"kind":"data","monotonic_ns":309430428892833,"payload":{"event_type":"price_change","market":"0x0f70d07969bc69eaa97d0987de651885fdca02263688026aa11e7678af8f87aa","price_changes":[{"asset_id":"58313761654877669244690227616056238030136603415514645252000528337391143520538","best_ask":"0.48","best_bid":"0.47","hash":"0616d9ac7c0f1d2258e60d7dd9bb808706e99c47","price":"0.41","side":"BUY","size":"229.29"},{"asset_id":"64053005904884194822931764831592250494815136296598204104072528088122126148949","best_ask":"0.53","best_bid":"0.52","hash":"75c692198358238c6937bf880bfefcade838b599","price":"0.59","side":"SELL","size":"229.29"}],"timestamp":"1785207447065"},"payload_hash":"ceb311775beac40a0e8ae59334d9a76792b1c66255a4060fc2041a60442a4a3c","raw_frame":"{\"market\":\"0x0f70d07969bc69eaa97d0987de651885fdca02263688026aa11e7678af8f87aa\", \"price_changes\":[{\"asset_id\":\"58313761654877669244690227616056238030136603415514645252000528337391143520538\", \"price\":\"0.41\", \"size\":\"229.29\", \"side\":\"BUY\", \"hash\":\"0616d9ac7c0f1d2258e60d7dd9bb808706e99c47\", \"best_bid\":\"0.47\", \"best_ask\":\"0.48\"}, {\"asset_id\":\"64053005904884194822931764831592250494815136296598204104072528088122126148949\", \"price\":\"0.59\", \"size\":\"229.29\", \"side\":\"SELL\", \"hash\":\"75c692198358238c6937bf880bfefcade838b599\", \"best_bid\":\"0.52\", \"best_ask\":\"0.53\"}], \"timestamp\":\"1785207447065\", \"event_type\":\"price_change\"}","received_at":"2026-07-28T02:57:27.411632Z","schema_version":"clob-market-ws.price_change.v1","sequence":null,"server_hash":null,"server_timestamp":"1785207447065","session_id":"5aad79be415c487c84df42bebd84ee93","source":"clob_market_ws"},"received_at":"2026-07-28T02:57:27.411632Z","record_id":"780410d1b16f473e4fec747c90475881d99d089b2442bfa525943b5719eb582d","schema_fingerprint":"4aa3821a28b0b7c2400bc59aba4bcc0a76e971dadd19610d3ad38c768e124dc7","schema_version":"edge-lab-recorder.raw.v1","sequence":null,"source":"clob_market_ws"}
{"event_at":"2026-07-28T02:57:27.065000Z","event_fingerprint":"0d21bc16d14a7e59ec0c5f1f375e74ab38671459025d6a9584193da68c1918af","payload":{"connection_id":"955646bd8bf740759faf38750c0f263f","event_at":"2026-07-28T02:57:27.065000Z","event_type":"price_change","frame_hash":"e7dcf4e15ba323acee0679069c0a66612e82e48754abb783bd6645c390112e72","frame_index":0,"kind":"data","monotonic_ns":309430430396000,"payload":{"event_type":"price_change","market":"0x0f70d07969bc69eaa97d0987de651885fdca02263688026aa11e7678af8f87aa","price_changes":[{"asset_id":"64053005904884194822931764831592250494815136296598204104072528088122126148949","best_ask":"0.53","best_bid":"0.52","hash":"9433a2f5b243256425d1a4d545aa91e117d611e4","price":"0.51","side":"BUY","size":"141.1"},{"asset_id":"58313761654877669244690227616056238030136603415514645252000528337391143520538","best_ask":"0.48","best_bid":"0.47","hash":"f22c3dd008a3a91ce57e3e76850f566615762a8c","price":"0.49","side":"SELL","size":"141.1"}],"timestamp":"1785207447065"},"payload_hash":"4892e70ca9584968674890fd9edfe1fada4b1a206db4a1e8b2bc9613d85e413d","raw_frame":"{\"market\":\"0x0f70d07969bc69eaa97d0987de651885fdca02263688026aa11e7678af8f87aa\", \"price_changes\":[{\"asset_id\":\"64053005904884194822931764831592250494815136296598204104072528088122126148949\", \"price\":\"0.51\", \"size\":\"141.1\", \"side\":\"BUY\", \"hash\":\"9433a2f5b243256425d1a4d545aa91e117d611e4\", \"best_bid\":\"0.52\", \"best_ask\":\"0.53\"}, {\"asset_id\":\"58313761654877669244690227616056238030136603415514645252000528337391143520538\", \"price\":\"0.49\", \"size\":\"141.1\", \"side\":\"SELL\", \"hash\":\"f22c3dd008a3a91ce57e3e76850f566615762a8c\", \"best_bid\":\"0.47\", \"best_ask\":\"0.48\"}], \"timestamp\":\"1785207447065\", \"event_type\":\"price_change\"}","received_at":"2026-07-28T02:57:27.413135Z","schema_version":"clob-market-ws.price_change.v1","sequence":null,"server_hash":null,"server_timestamp":"1785207447065","session_id":"5aad79be415c487c84df42bebd84ee93","source":"clob_market_ws"},"received_at":"2026-07-28T02:57:27.413135Z","record_id":"51862aa7300294449156cf5939b0cf24d604831f6eb87e04a87971308c271d79","schema_fingerprint":"4aa3821a28b0b7c2400bc59aba4bcc0a76e971dadd19610d3ad38c768e124dc7","schema_version":"edge-lab-recorder.raw.v1","sequence":null,"source":"clob_market_ws"}
{"event_at":"2026-07-28T02:57:27.068000Z","event_fingerprint":"8a4f69b03fe2ee711a92d0f02bd9b02a62c147dd0da74d3d3ddcfa3888b928e4","payload":{"connection_id":"955646bd8bf740759faf38750c0f263f","event_at":"2026-07-28T02:57:27.068000Z","event_type":"price_change","frame_hash":"9c15951e4d6c47cf26491f7cf22dff1f22b3a7eedf7b2fd2faedd4147ccc3e9f","frame_index":0,"kind":"data","monotonic_ns":309430431856625,"payload":{"event_type":"price_change","market":"0x0f70d07969bc69eaa97d0987de651885fdca02263688026aa11e7678af8f87aa","price_changes":[{"asset_id":"64053005904884194822931764831592250494815136296598204104072528088122126148949","best_ask":"0.53","best_bid":"0.52","hash":"966331e1fdaaa88c245f18ea9ed794d23408c754","price":"0.19","side":"BUY","size":"343.71"},{"asset_id":"58313761654877669244690227616056238030136603415514645252000528337391143520538","best_ask":"0.48","best_bid":"0.47","hash":"d201994c35152f934704e4d5ddc61ecff6d594d3","price":"0.81","side":"SELL","size":"343.71"}],"timestamp":"1785207447068"},"payload_hash":"87e491f92ab78e15eb5c70b89b82b65f56a92c2909fab6563eefd99c43d9d106","raw_frame":"{\"market\":\"0x0f70d07969bc69eaa97d0987de651885fdca02263688026aa11e7678af8f87aa\", \"price_changes\":[{\"asset_id\":\"64053005904884194822931764831592250494815136296598204104072528088122126148949\", \"price\":\"0.19\", \"size\":\"343.71\", \"side\":\"BUY\", \"hash\":\"966331e1fdaaa88c245f18ea9ed794d23408c754\", \"best_bid\":\"0.52\", \"best_ask\":\"0.53\"}, {\"asset_id\":\"58313761654877669244690227616056238030136603415514645252000528337391143520538\", \"price\":\"0.81\", \"size\":\"343.71\", \"side\":\"SELL\", \"hash\":\"d201994c35152f934704e4d5ddc61ecff6d594d3\", \"best_bid\":\"0.47\", \"best_ask\":\"0.48\"}], \"timestamp\":\"1785207447068\", \"event_type\":\"price_change\"}","received_at":"2026-07-28T02:57:27.414595Z","schema_version":"clob-market-ws.price_change.v1","sequence":null,"server_hash":null,"server_timestamp":"1785207447068","session_id":"5aad79be415c487c84df42bebd84ee93","source":"clob_market_ws"},"received_at":"2026-07-28T02:57:27.414595Z","record_id":"03ec71e6e52b49d089af40df2062a1d2e283f1bb8af8bac02545b3142454c3ef","schema_fingerprint":"4aa3821a28b0b7c2400bc59aba4bcc0a76e971dadd19610d3ad38c768e124dc7","schema_version":"edge-lab-recorder.raw.v1","sequence":null,"source":"clob_market_ws"}
{"event_at":"2026-07-28T02:57:27.070000Z","event_fingerprint":"a15f0aed7f526f1ea7cfe9b0b63e2626a7e5ae8d6e424ca33ea55ee73b0871e8","payload":{"connection_id":"955646bd8bf740759faf38750c0f263f","event_at":"2026-07-28T02:57:27.070000Z","event_type":"price_change","frame_hash":"56b40de1a13e90e8e24e8b33b3d00d30e5d9ff41a00de29260cf670fc46d8bf7","frame_index":0,"kind":"data","monotonic_ns":309430433313333,"payload":{"event_type":"price_change","market":"0x0f70d07969bc69eaa97d0987de651885fdca02263688026aa11e7678af8f87aa","price_changes":[{"asset_id":"64053005904884194822931764831592250494815136296598204104072528088122126148949","best_ask":"0.53","best_bid":"0.52","hash":"601c3cd0cad7ab541c59598e3e0af67691837162","price":"0.38","side":"BUY","size":"81.19"},{"asset_id":"58313761654877669244690227616056238030136603415514645252000528337391143520538","best_ask":"0.48","best_bid":"0.47","hash":"6e30672d0c3f00c0d0566768e118d00122e6c0c6","price":"0.62","side":"SELL","size":"81.19"}],"timestamp":"1785207447070"},"payload_hash":"1a7de20dd6100c6de2d44132b0c62999b07d5380c690b77fe2619cc43abc06a2","raw_frame":"{\"market\":\"0x0f70d07969bc69eaa97d0987de651885fdca02263688026aa11e7678af8f87aa\", \"price_changes\":[{\"asset_id\":\"64053005904884194822931764831592250494815136296598204104072528088122126148949\", \"price\":\"0.38\", \"size\":\"81.19\", \"side\":\"BUY\", \"hash\":\"601c3cd0cad7ab541c59598e3e0af67691837162\", \"best_bid\":\"0.52\", \"best_ask\":\"0.53\"}, {\"asset_id\":\"58313761654877669244690227616056238030136603415514645252000528337391143520538\", \"price\":\"0.62\", \"size\":\"81.19\", \"side\":\"SELL\", \"hash\":\"6e30672d0c3f00c0d0566768e118d00122e6c0c6\", \"best_bid\":\"0.47\", \"best_ask\":\"0.48\"}], \"timestamp\":\"1785207447070\", \"event_type\":\"price_change\"}","received_at":"2026-07-28T02:57:27.416052Z","schema_version":"clob-market-ws.price_change.v1","sequence":null,"server_hash":null,"server_timestamp":"1785207447070","session_id":"5aad79be415c487c84df42bebd84ee93","source":"clob_market_ws"},"received_at":"2026-07-28T02:57:27.416052Z","record_id":"74df19cc4f76c50e07cfa80aa0ed30ef87814f1009bed76172e93075a7272692","schema_fingerprint":"4aa3821a28b0b7c2400bc59aba4bcc0a76e971dadd19610d3ad38c768e124dc7","schema_version":"edge-lab-recorder.raw.v1","sequence":null,"source":"clob_market_ws"}
{"event_at":"2026-07-28T02:57:27.071000Z","event_fingerprint":"3b5a1953b597f7771c31abbde7e4c34ffb9668f9d59e900ad7617c1a3a4329fa","payload":{"connection_id":"955646bd8bf740759faf38750c0f263f","event_at":"2026-07-28T02:57:27.071000Z","event_type":"price_change","frame_hash":"6bce27f6e6e595c8481ca887e8eb1cb86a1722af9bb8619ae9b02c9082125702","frame_index":0,"kind":"data","monotonic_ns":309430434892250,"payload":{"event_type":"price_change","market":"0x0f70d07969bc69eaa97d0987de651885fdca02263688026aa11e7678af8f87aa","price_changes":[{"asset_id":"64053005904884194822931764831592250494815136296598204104072528088122126148949","best_ask":"0.53","best_bid":"0.52","hash":"a0109238a06d4260373ac7d52bf151d45c9aacf6","price":"0.39","side":"BUY","size":"63.19"},{"asset_id":"58313761654877669244690227616056238030136603415514645252000528337391143520538","best_ask":"0.48","best_bid":"0.47","hash":"397a7981b49b74e0764be359b14922172b7013c2","price":"0.61","side":"SELL","size":"63.19"}],"timestamp":"1785207447071"},"payload_hash":"e632c5a28a5a610da44b8a650a81f52db6c7a1926157af29ffd97a4c65a65f39","raw_frame":"{\"market\":\"0x0f70d07969bc69eaa97d0987de651885fdca02263688026aa11e7678af8f87aa\", \"price_changes\":[{\"asset_id\":\"64053005904884194822931764831592250494815136296598204104072528088122126148949\", \"price\":\"0.39\", \"size\":\"63.19\", \"side\":\"BUY\", \"hash\":\"a0109238a06d4260373ac7d52bf151d45c9aacf6\", \"best_bid\":\"0.52\", \"best_ask\":\"0.53\"}, {\"asset_id\":\"58313761654877669244690227616056238030136603415514645252000528337391143520538\", \"price\":\"0.61\", \"size\":\"63.19\", \"side\":\"SELL\", \"hash\":\"397a7981b49b74e0764be359b14922172b7013c2\", \"best_bid\":\"0.47\", \"best_ask\":\"0.48\"}], \"timestamp\":\"1785207447071\", \"event_type\":\"price_change\"}","received_at":"2026-07-28T02:57:27.417629Z","schema_version":"clob-market-ws.price_change.v1","sequence":null,"server_hash":null,"server_timestamp":"1785207447071","session_id":"5aad79be415c487c84df42bebd84ee93","source":"clob_market_ws"},"received_at":"2026-07-28T02:57:27.417629Z","record_id":"e1bac3e1e7cfa4152415facf4061976400138ae60545d57a20103fd438bb55ed","schema_fingerprint":"4aa3821a28b0b7c2400bc59aba4bcc0a76e971dadd19610d3ad38c768e124dc7","schema_version":"edge-lab-recorder.raw.v1","sequence":null,"source":"clob_market_ws"}
