{"event_at":"2026-07-28T03:07:41.324000Z","event_fingerprint":"0f9e7a876360caaa8c7bf5cc98085315f90e7032db0ef0b4be802ce22c546947","payload":{"connection_id":"a6b55582af5f430fb37ad02bf0922475","event_at":"2026-07-28T03:07:41.324000Z","event_type":"price_change","frame_hash":"6663ae43fa1968dd53ef1b94cd40058a6b604ecc7965eb86b4a2be15fbcdc59f","frame_index":0,"kind":"data","monotonic_ns":310048818924291,"payload":{"event_type":"price_change","market":"0x779291bef19b6709f61e9764a954aafe9ffae488d50ae674aabdcb4f248006d5","price_changes":[{"asset_id":"14965588658799411272385430903075831224615961675357217884735713260981483529984","best_ask":"0.49","best_bid":"0.48","hash":"26af48c0adc3a66dc63c0a0dfdedc07a5cde5a67","price":"0.47","side":"BUY","size":"337.6"},{"asset_id":"8761897749749422724209054078244794145777693856614463256546737399611489089783","best_ask":"0.52","best_bid":"0.51","hash":"5e8fded4b0169467afe97b07732b10e170bca6ff","price":"0.53","side":"SELL","size":"337.6"}],"timestamp":"1785208061324"},"payload_hash":"aecc34bab693e562df5a4834c85701ee9e95dce24e846a42f045d45f4660840d","raw_frame":"{\"market\":\"0x779291bef19b6709f61e9764a954aafe9ffae488d50ae674aabdcb4f248006d5\", \"price_changes\":[{\"asset_id\":\"14965588658799411272385430903075831224615961675357217884735713260981483529984\", \"price\":\"0.47\", \"size\":\"337.6\", \"side\":\"BUY\", \"hash\":\"26af48c0adc3a66dc63c0a0dfdedc07a5cde5a67\", \"best_bid\":\"0.48\", \"best_ask\":\"0.49\"}, {\"asset_id\":\"8761897749749422724209054078244794145777693856614463256546737399611489089783\", \"price\":\"0.53\", \"size\":\"337.6\", \"side\":\"SELL\", \"hash\":\"5e8fded4b0169467afe97b07732b10e170bca6ff\", \"best_bid\":\"0.51\", \"best_ask\":\"0.52\"}], \"timestamp\":\"1785208061324\", \"event_type\":\"price_change\"}","received_at":"2026-07-28T03:07:45.786779Z","schema_version":"clob-market-ws.price_change.v1","sequence":null,"server_hash":null,"server_timestamp":"1785208061324","session_id":"3e519d9098404c15b234d96025eb1a2b","source":"clob_market_ws"},"received_at":"2026-07-28T03:07:45.786779Z","record_id":"127b62e38a90fad4ddd4a28d32aeb61a6c73fbac9105c74757d65d2b0a5374b4","schema_fingerprint":"4aa3821a28b0b7c2400bc59aba4bcc0a76e971dadd19610d3ad38c768e124dc7","schema_version":"edge-lab-recorder.raw.v1","sequence":null,"source":"clob_market_ws"}
{"event_at":"2026-07-28T03:07:41.325000Z","event_fingerprint":"734bbb124ec8eca2e802205aca6ba8a7c0b79943ecfc22458c75966eaee1531e","payload":{"connection_id":"a6b55582af5f430fb37ad02bf0922475","event_at":"2026-07-28T03:07:41.325000Z","event_type":"price_change","frame_hash":"f0ee98ccabb7fe6133daf98bbd40437355d309c7e55f7e1a4fc33d65e14b3f25","frame_index":0,"kind":"data","monotonic_ns":310048825229208,"payload":{"event_type":"price_change","market":"0x779291bef19b6709f61e9764a954aafe9ffae488d50ae674aabdcb4f248006d5","price_changes":[{"asset_id":"14965588658799411272385430903075831224615961675357217884735713260981483529984","best_ask":"0.49","best_bid":"0.48","hash":"7801ba1ae7f5ebf5caa3422efddeda8ec0fa4d38","price":"0.48","side":"BUY","size":"182.6"},{"asset_id":"8761897749749422724209054078244794145777693856614463256546737399611489089783","best_ask":"0.52","best_bid":"0.51","hash":"9bafadeda10592b5d1de32d1f928a90ebbf22706","price":"0.52","side":"SELL","size":"182.6"}],"timestamp":"1785208061325"},"payload_hash":"75db94ccc18222978d8521e0b50f38fefa0414622ba2064e5ee0e9bf4432c5fa","raw_frame":"{\"market\":\"0x779291bef19b6709f61e9764a954aafe9ffae488d50ae674aabdcb4f248006d5\", \"price_changes\":[{\"asset_id\":\"14965588658799411272385430903075831224615961675357217884735713260981483529984\", \"price\":\"0.48\", \"size\":\"182.6\", \"side\":\"BUY\", \"hash\":\"7801ba1ae7f5ebf5caa3422efddeda8ec0fa4d38\", \"best_bid\":\"0.48\", \"best_ask\":\"0.49\"}, {\"asset_id\":\"8761897749749422724209054078244794145777693856614463256546737399611489089783\", \"price\":\"0.52\", \"size\":\"182.6\", \"side\":\"SELL\", \"hash\":\"9bafadeda10592b5d1de32d1f928a90ebbf22706\", \"best_bid\":\"0.51\", \"best_ask\":\"0.52\"}], \"timestamp\":\"1785208061325\", \"event_type\":\"price_change\"}","received_at":"2026-07-28T03:07:45.793083Z","schema_version":"clob-market-ws.price_change.v1","sequence":null,"server_hash":null,"server_timestamp":"1785208061325","session_id":"3e519d9098404c15b234d96025eb1a2b","source":"clob_market_ws"},"received_at":"2026-07-28T03:07:45.793083Z","record_id":"5a1b6a4e1575ed9936feb9759ccc859663ac10798350abd98aeeb41d55478c69","schema_fingerprint":"4aa3821a28b0b7c2400bc59aba4bcc0a76e971dadd19610d3ad38c768e124dc7","schema_version":"edge-lab-recorder.raw.v1","sequence":null,"source":"clob_market_ws"}
{"event_at":"2026-07-28T03:07:41.325000Z","event_fingerprint":"733f10c391a3dfe06a93ce02052e008b6428a2926bd41fc6ed25f2e7b8d90a1d","payload":{"connection_id":"a6b55582af5f430fb37ad02bf0922475","event_at":"2026-07-28T03:07:41.325000Z","event_type":"price_change","frame_hash":"d64129a0d1ea9de6346cd8cd0a8bad0a337654a6c365084c9272444a02a3cbe2","frame_index":0,"kind":"data","monotonic_ns":310048828249875,"payload":{"event_type":"price_change","market":"0x779291bef19b6709f61e9764a954aafe9ffae488d50ae674aabdcb4f248006d5","price_changes":[{"asset_id":"14965588658799411272385430903075831224615961675357217884735713260981483529984","best_ask":"0.49","best_bid":"0.48","hash":"30d9723c6ee66427ec182cf40003a65026c28dcd","price":"0.46","side":"BUY","size":"353.6"},{"asset_id":"8761897749749422724209054078244794145777693856614463256546737399611489089783","best_ask":"0.52","best_bid":"0.51","hash":"381c3fe72eb659fe034cd68637734ae07c067b7c","price":"0.54","side":"SELL","size":"353.6"}],"timestamp":"1785208061325"},"payload_hash":"c2dcee666ee16d1ab25d5c99018b7f802a5e69924d404655d2762cd11f75d2bc","raw_frame":"{\"market\":\"0x779291bef19b6709f61e9764a954aafe9ffae488d50ae674aabdcb4f248006d5\", \"price_changes\":[{\"asset_id\":\"14965588658799411272385430903075831224615961675357217884735713260981483529984\", \"price\":\"0.46\", \"size\":\"353.6\", \"side\":\"BUY\", \"hash\":\"30d9723c6ee66427ec182cf40003a65026c28dcd\", \"best_bid\":\"0.48\", \"best_ask\":\"0.49\"}, {\"asset_id\":\"8761897749749422724209054078244794145777693856614463256546737399611489089783\", \"price\":\"0.54\", \"size\":\"353.6\", \"side\":\"SELL\", \"hash\":\"381c3fe72eb659fe034cd68637734ae07c067b7c\", \"best_bid\":\"0.51\", \"best_ask\":\"0.52\"}], \"timestamp\":\"1785208061325\", \"event_type\":\"price_change\"}","received_at":"2026-07-28T03:07:45.796105Z","schema_version":"clob-market-ws.price_change.v1","sequence":null,"server_hash":null,"server_timestamp":"1785208061325","session_id":"3e519d9098404c15b234d96025eb1a2b","source":"clob_market_ws"},"received_at":"2026-07-28T03:07:45.796105Z","record_id":"ed9f86576120d7517486f1d769f31e4a0100b85e5243b8b370c2312a63d32687","schema_fingerprint":"4aa3821a28b0b7c2400bc59aba4bcc0a76e971dadd19610d3ad38c768e124dc7","schema_version":"edge-lab-recorder.raw.v1","sequence":null,"source":"clob_market_ws"}
{"event_at":"2026-07-28T03:07:41.325000Z","event_fingerprint":"b0ba4957fa39dc7f702ebf02fd31c3ff4c6c19628fe13ca69ce26ed98eda2ce9","payload":{"connection_id":"a6b55582af5f430fb37ad02bf0922475","event_at":"2026-07-28T03:07:41.325000Z","event_type":"price_change","frame_hash":"b23332528786d30aa7690178e2a3cb018c64cb26b078cf62695460f5efe7a742","frame_index":0,"kind":"data","monotonic_ns":310048831225083,"payload":{"event_type":"price_change","market":"0x779291bef19b6709f61e9764a954aafe9ffae488d50ae674aabdcb4f248006d5","price_changes":[{"asset_id":"14965588658799411272385430903075831224615961675357217884735713260981483529984","best_ask":"0.49","best_bid":"0.48","hash":"70878a5f49bac25e2ff4d670b0ffe1e1196c3cb0","price":"0.43","side":"BUY","size":"98"},{"asset_id":"8761897749749422724209054078244794145777693856614463256546737399611489089783","best_ask":"0.52","best_bid":"0.51","hash":"279acafda2553c7461dfcc63667dcf150061cf81","price":"0.57","side":"SELL","size":"98"}],"timestamp":"1785208061325"},"payload_hash":"b96236fc49357fac92302fbb145afa99ed19335be51ea94aef0b734eea722805","raw_frame":"{\"market\":\"0x779291bef19b6709f61e9764a954aafe9ffae488d50ae674aabdcb4f248006d5\", \"price_changes\":[{\"asset_id\":\"14965588658799411272385430903075831224615961675357217884735713260981483529984\", \"price\":\"0.43\", \"size\":\"98\", \"side\":\"BUY\", \"hash\":\"70878a5f49bac25e2ff4d670b0ffe1e1196c3cb0\", \"best_bid\":\"0.48\", \"best_ask\":\"0.49\"}, {\"asset_id\":\"8761897749749422724209054078244794145777693856614463256546737399611489089783\", \"price\":\"0.57\", \"size\":\"98\", \"side\":\"SELL\", \"hash\":\"279acafda2553c7461dfcc63667dcf150061cf81\", \"best_bid\":\"0.51\", \"best_ask\":\"0.52\"}], \"timestamp\":\"1785208061325\", \"event_type\":\"price_change\"}","received_at":"2026-07-28T03:07:45.799080Z","schema_version":"clob-market-ws.price_change.v1","sequence":null,"server_hash":null,"server_timestamp":"1785208061325","session_id":"3e519d9098404c15b234d96025eb1a2b","source":"clob_market_ws"},"received_at":"2026-07-28T03:07:45.799080Z","record_id":"37cc0a1d5929d57953bd55b7dbfe7a6e9ab1cf007063eef618df96b62cda1414","schema_fingerprint":"4aa3821a28b0b7c2400bc59aba4bcc0a76e971dadd19610d3ad38c768e124dc7","schema_version":"edge-lab-recorder.raw.v1","sequence":null,"source":"clob_market_ws"}
{"event_at":"2026-07-28T03:07:41.326000Z","event_fingerprint":"0700e7986a51467b2f373e320cfeb6cf7dd1c20b94f25f1964caad723517f6a7","payload":{"connection_id":"a6b55582af5f430fb37ad02bf0922475","event_at":"2026-07-28T03:07:41.326000Z","event_type":"price_change","frame_hash":"b72af3a38129ec1928f7fbf2a4d3115924ef74c597990bc7055c51b5e7896fc4","frame_index":0,"kind":"data","monotonic_ns":310048834194375,"payload":{"event_type":"price_change","market":"0x779291bef19b6709f61e9764a954aafe9ffae488d50ae674aabdcb4f248006d5","price_changes":[{"asset_id":"8761897749749422724209054078244794145777693856614463256546737399611489089783","best_ask":"0.52","best_bid":"0.51","hash":"e8dc09e1650e58896b563425b15dc7f50f51de2d","price":"0.04","side":"BUY","size":"593.09"},{"asset_id":"14965588658799411272385430903075831224615961675357217884735713260981483529984","best_ask":"0.49","best_bid":"0.48","hash":"10b263fc0f90eb400fcea8c1ed3ba49954161a63","price":"0.96","side":"SELL","size":"593.09"}],"timestamp":"1785208061326"},"payload_hash":"b0152f2f2e063451ce0ee1a6173349f5c3e163c1b589f9507156895127c3fee7","raw_frame":"{\"market\":\"0x779291bef19b6709f61e9764a954aafe9ffae488d50ae674aabdcb4f248006d5\", \"price_changes\":[{\"asset_id\":\"8761897749749422724209054078244794145777693856614463256546737399611489089783\", \"price\":\"0.04\", \"size\":\"593.09\", \"side\":\"BUY\", \"hash\":\"e8dc09e1650e58896b563425b15dc7f50f51de2d\", \"best_bid\":\"0.51\", \"best_ask\":\"0.52\"}, {\"asset_id\":\"14965588658799411272385430903075831224615961675357217884735713260981483529984\", \"price\":\"0.96\", \"size\":\"593.09\", \"side\":\"SELL\", \"hash\":\"10b263fc0f90eb400fcea8c1ed3ba49954161a63\", \"best_bid\":\"0.48\", \"best_ask\":\"0.49\"}], \"timestamp\":\"1785208061326\", \"event_type\":\"price_change\"}","received_at":"2026-07-28T03:07:45.802049Z","schema_version":"clob-market-ws.price_change.v1","sequence":null,"server_hash":null,"server_timestamp":"1785208061326","session_id":"3e519d9098404c15b234d96025eb1a2b","source":"clob_market_ws"},"received_at":"2026-07-28T03:07:45.802049Z","record_id":"77f454892c450ce5a8d2cc92ce8e13e72a7d8d64fc58303609e225838522db77","schema_fingerprint":"4aa3821a28b0b7c2400bc59aba4bcc0a76e971dadd19610d3ad38c768e124dc7","schema_version":"edge-lab-recorder.raw.v1","sequence":null,"source":"clob_market_ws"}
{"event_at":"2026-07-28T03:07:41.327000Z","event_fingerprint":"2fd5b3cb050870396617864a199ea19eb1dd57730866dba09d67b54eecc4bb34","payload":{"connection_id":"a6b55582af5f430fb37ad02bf0922475","event_at":"2026-07-28T03:07:41.327000Z","event_type":"price_change","frame_hash":"6870a86aaf6803bd335afc697f4f07d2566ffa8b5d70724b9b7a64fe72d97543","frame_index":0,"kind":"data","monotonic_ns":310048837109458,"payload":{"event_type":"price_change","market":"0x779291bef19b6709f61e9764a954aafe9ffae488d50ae674aabdcb4f248006d5","price_changes":[{"asset_id":"14965588658799411272385430903075831224615961675357217884735713260981483529984","best_ask":"0.49","best_bid":"0.48","hash":"5507d5d6f962c3d27c02972be74eb9ba226e13e6","price":"0.46","side":"BUY","size":"83.6"},{"asset_id":"8761897749749422724209054078244794145777693856614463256546737399611489089783","best_ask":"0.52","best_bid":"0.51","hash":"d697824c4fe94e1af217cfc2c89f7a499df5d6b7","price":"0.54","side":"SELL","size":"83.6"}],"timestamp":"1785208061327"},"payload_hash":"bd23dd202925bb5f2c28aed2b0160488bbde5f6f6487fbfaf438588ce436bc46","raw_frame":"{\"market\":\"0x779291bef19b6709f61e9764a954aafe9ffae488d50ae674aabdcb4f248006d5\", \"price_changes\":[{\"asset_id\":\"14965588658799411272385430903075831224615961675357217884735713260981483529984\", \"price\":\"0.46\", \"size\":\"83.6\", \"side\":\"BUY\", \"hash\":\"5507d5d6f962c3d27c02972be74eb9ba226e13e6\", \"best_bid\":\"0.48\", \"best_ask\":\"0.49\"}, {\"asset_id\":\"8761897749749422724209054078244794145777693856614463256546737399611489089783\", \"price\":\"0.54\", \"size\":\"83.6\", \"side\":\"SELL\", \"hash\":\"d697824c4fe94e1af217cfc2c89f7a499df5d6b7\", \"best_bid\":\"0.51\", \"best_ask\":\"0.52\"}], \"timestamp\":\"1785208061327\", \"event_type\":\"price_change\"}","received_at":"2026-07-28T03:07:45.804964Z","schema_version":"clob-market-ws.price_change.v1","sequence":null,"server_hash":null,"server_timestamp":"1785208061327","session_id":"3e519d9098404c15b234d96025eb1a2b","source":"clob_market_ws"},"received_at":"2026-07-28T03:07:45.804964Z","record_id":"69e411ec28238d8daa8477077da3155bdf70b5488aa8f322e3799cfffbbd4c1f","schema_fingerprint":"4aa3821a28b0b7c2400bc59aba4bcc0a76e971dadd19610d3ad38c768e124dc7","schema_version":"edge-lab-recorder.raw.v1","sequence":null,"source":"clob_market_ws"}
{"event_at":"2026-07-28T03:07:41.334000Z","event_fingerprint":"10834302a81bbe114e8b00cf6bf3fec6240ee352fcb08cdac65d84d7a5b426ba","payload":{"connection_id":"a6b55582af5f430fb37ad02bf0922475","event_at":"2026-07-28T03:07:41.334000Z","event_type":"best_bid_ask","frame_hash":"3d583e935e7394fe697d2e4cfa9e9df49f932a29f67ca4c2ef5c22f36627a51c","frame_index":0,"kind":"data","monotonic_ns":310048840053708,"payload":{"asset_id":"14965588658799411272385430903075831224615961675357217884735713260981483529984","best_ask":"0.5","best_bid":"0.48","event_type":"best_bid_ask","market":"0x779291bef19b6709f61e9764a954aafe9ffae488d50ae674aabdcb4f248006d5","spread":"0.02","timestamp":"1785208061334"},"payload_hash":"7ef158a71b352f844e18aae24a0f62d018bf14cf1f1c31d79bf3c1a978c61a96","raw_frame":"{\"market\":\"0x779291bef19b6709f61e9764a954aafe9ffae488d50ae674aabdcb4f248006d5\", \"asset_id\":\"14965588658799411272385430903075831224615961675357217884735713260981483529984\", \"best_bid\":\"0.48\", \"best_ask\":\"0.5\", \"spread\":\"0.02\", \"timestamp\":\"1785208061334\", \"event_type\":\"best_bid_ask\"}","received_at":"2026-07-28T03:07:45.807908Z","schema_version":"clob-market-ws.best_bid_ask.v1","sequence":null,"server_hash":null,"server_timestamp":"1785208061334","session_id":"3e519d9098404c15b234d96025eb1a2b","source":"clob_market_ws"},"received_at":"2026-07-28T03:07:45.807908Z","record_id":"59752c596a3fad637a1f3635d8320a04d651c8dfd9456c712935d3bbe3411a35","schema_fingerprint":"8488399f31b0337811b13b266be932db7062827c2470b78bd8e9e99bab51d17d","schema_version":"edge-lab-recorder.raw.v1","sequence":null,"source":"clob_market_ws"}
{"event_at":"2026-07-28T03:07:41.334000Z","event_fingerprint":"377941e3a4c18b65a56a9fc8b6923ae1d88512cf3b750d60c66629a44a273a20","payload":{"connection_id":"a6b55582af5f430fb37ad02bf0922475","event_at":"2026-07-28T03:07:41.334000Z","event_type":"best_bid_ask","frame_hash":"cf2908f79ac72cd9110fcf3613376f46bc33c51db4311fdec5af7a6e076ae169","frame_index":0,"kind":"data","monotonic_ns":310048842612583,"payload":{"asset_id":"8761897749749422724209054078244794145777693856614463256546737399611489089783","best_ask":"0.52","best_bid":"0.5","event_type":"best_bid_ask","market":"0x779291bef19b6709f61e9764a954aafe9ffae488d50ae674aabdcb4f248006d5","spread":"0.02","timestamp":"1785208061334"},"payload_hash":"775f199e365c9483591ac3410b53e69b1a99a00beeb2e8d07403a99aff15b7d0","raw_frame":"{\"market\":\"0x779291bef19b6709f61e9764a954aafe9ffae488d50ae674aabdcb4f248006d5\", \"asset_id\":\"8761897749749422724209054078244794145777693856614463256546737399611489089783\", \"best_bid\":\"0.5\", \"best_ask\":\"0.52\", \"spread\":\"0.02\", \"timestamp\":\"1785208061334\", \"event_type\":\"best_bid_ask\"}","received_at":"2026-07-28T03:07:45.810468Z","schema_version":"clob-market-ws.best_bid_ask.v1","sequence":null,"server_hash":null,"server_timestamp":"1785208061334","session_id":"3e519d9098404c15b234d96025eb1a2b","source":"clob_market_ws"},"received_at":"2026-07-28T03:07:45.810468Z","record_id":"bc996b293b8593049a169e462b85aaddc99b2d60c977a0de194fb64164f796a8","schema_fingerprint":"8488399f31b0337811b13b266be932db7062827c2470b78bd8e9e99bab51d17d","schema_version":"edge-lab-recorder.raw.v1","sequence":null,"source":"clob_market_ws"}
{"event_at":"2026-07-28T03:07:41.333000Z","event_fingerprint":"b0ba03fe0379a98f45c9b0978c1f4c6ad0a308f2aa1ca4c1728ef8e81040c9a3","payload":{"connection_id":"a6b55582af5f430fb37ad02bf0922475","event_at":"2026-07-28T03:07:41.333000Z","event_type":"price_change","frame_hash":"97fd0230f66dd8153bae799ff387da5d947652e643aebb49ed2a54f4fbe842f7","frame_index":0,"kind":"data","monotonic_ns":310048844069291,"payload":{"event_type":"price_change","market":"0x779291bef19b6709f61e9764a954aafe9ffae488d50ae674aabdcb4f248006d5","price_changes":[{"asset_id":"8761897749749422724209054078244794145777693856614463256546737399611489089783","best_ask":"0.52","best_bid":"0.5","hash":"e91b012ec57d124da7b922cc7cbc9e75d6d7273f","price":"0.51","side":"BUY","size":"0"},{"asset_id":"14965588658799411272385430903075831224615961675357217884735713260981483529984","best_ask":"0.5","best_bid":"0.48","hash":"4b4b837903afda905885bed3de9f9f312caaef74","price":"0.49","side":"SELL","size":"0"}],"timestamp":"1785208061333"},"payload_hash":"df3c408eef7bba3430425205a9298a20e97c7c6f3572050e623f7a8f4d9a614f","raw_frame":"{\"market\":\"0x779291bef19b6709f61e9764a954aafe9ffae488d50ae674aabdcb4f248006d5\", \"price_changes\":[{\"asset_id\":\"8761897749749422724209054078244794145777693856614463256546737399611489089783\", \"price\":\"0.51\", \"size\":\"0\", \"side\":\"BUY\", \"hash\":\"e91b012ec57d124da7b922cc7cbc9e75d6d7273f\", \"best_bid\":\"0.5\", \"best_ask\":\"0.52\"}, {\"asset_id\":\"14965588658799411272385430903075831224615961675357217884735713260981483529984\", \"price\":\"0.49\", \"size\":\"0\", \"side\":\"SELL\", \"hash\":\"4b4b837903afda905885bed3de9f9f312caaef74\", \"best_bid\":\"0.48\", \"best_ask\":\"0.5\"}], \"timestamp\":\"1785208061333\", \"event_type\":\"price_change\"}","received_at":"2026-07-28T03:07:45.811930Z","schema_version":"clob-market-ws.price_change.v1","sequence":null,"server_hash":null,"server_timestamp":"1785208061333","session_id":"3e519d9098404c15b234d96025eb1a2b","source":"clob_market_ws"},"received_at":"2026-07-28T03:07:45.811930Z","record_id":"a5626388a1db6ff950851cdce2adf6fceb6dc7e71ed63b7f1c9ebe1af1832569","schema_fingerprint":"4aa3821a28b0b7c2400bc59aba4bcc0a76e971dadd19610d3ad38c768e124dc7","schema_version":"edge-lab-recorder.raw.v1","sequence":null,"source":"clob_market_ws"}
{"event_at":"2026-07-28T03:07:41.334000Z","event_fingerprint":"7a14ffb2c5b5c9d66f2c378af3a398cac15286d93b6fc7f5ef6265ea17770776","payload":{"connection_id":"a6b55582af5f430fb37ad02bf0922475","event_at":"2026-07-28T03:07:41.334000Z","event_type":"price_change","frame_hash":"5281e4cd6487cbaae74e793cc8fb188996e55149252ad365f86d9f0abb09043e","frame_index":0,"kind":"data","monotonic_ns":310048845694625,"payload":{"event_type":"price_change","market":"0x779291bef19b6709f61e9764a954aafe9ffae488d50ae674aabdcb4f248006d5","price_changes":[{"asset_id":"8761897749749422724209054078244794145777693856614463256546737399611489089783","best_ask":"0.52","best_bid":"0.5","hash":"83988fcacc581fbd80be6e7ebe5b85d072d835b2","price":"0.5","side":"BUY","size":"103.6"},{"asset_id":"14965588658799411272385430903075831224615961675357217884735713260981483529984","best_ask":"0.5","best_bid":"0.48","hash":"d19a90f9bc5836319d537e2db47750eb1746a387","price":"0.5","side":"SELL","size":"103.6"}],"timestamp":"1785208061334"},"payload_hash":"c43d06608418c7c6e8d6810e777ce02bfe086abe81231cbc6cb2202992e07a97","raw_frame":"{\"market\":\"0x779291bef19b6709f61e9764a954aafe9ffae488d50ae674aabdcb4f248006d5\", \"price_changes\":[{\"asset_id\":\"8761897749749422724209054078244794145777693856614463256546737399611489089783\", \"price\":\"0.5\", \"size\":\"103.6\", \"side\":\"BUY\", \"hash\":\"83988fcacc581fbd80be6e7ebe5b85d072d835b2\", \"best_bid\":\"0.5\", \"best_ask\":\"0.52\"}, {\"asset_id\":\"14965588658799411272385430903075831224615961675357217884735713260981483529984\", \"price\":\"0.5\", \"size\":\"103.6\", \"side\":\"SELL\", \"hash\":\"d19a90f9bc5836319d537e2db47750eb1746a387\", \"best_bid\":\"0.48\", \"best_ask\":\"0.5\"}], \"timestamp\":\"1785208061334\", \"event_type\":\"price_change\"}","received_at":"2026-07-28T03:07:45.813555Z","schema_version":"clob-market-ws.price_change.v1","sequence":null,"server_hash":null,"server_timestamp":"1785208061334","session_id":"3e519d9098404c15b234d96025eb1a2b","source":"clob_market_ws"},"received_at":"2026-07-28T03:07:45.813555Z","record_id":"93f74d2bbfb340beb63f7e37495b3668fa614da76851d92a1293db593c71fbc5","schema_fingerprint":"4aa3821a28b0b7c2400bc59aba4bcc0a76e971dadd19610d3ad38c768e124dc7","schema_version":"edge-lab-recorder.raw.v1","sequence":null,"source":"clob_market_ws"}
{"event_at":"2026-07-28T03:07:41.342000Z","event_fingerprint":"e680e473c62a0fe32f233fae9d5b8206a399b80a5de05bbf4e8020f7435362e3","payload":{"connection_id":"a6b55582af5f430fb37ad02bf0922475","event_at":"2026-07-28T03:07:41.342000Z","event_type":"price_change","frame_hash":"b4afd12150db3a1916aec9e9ed69f84ba11ca99b919e258395dc75c52e51660d","frame_index":0,"kind":"data","monotonic_ns":310048846844041,"payload":{"event_type":"price_change","market":"0x779291bef19b6709f61e9764a954aafe9ffae488d50ae674aabdcb4f248006d5","price_changes":[{"asset_id":"8761897749749422724209054078244794145777693856614463256546737399611489089783","best_ask":"0.52","best_bid":"0.5","hash":"c58edb67cb64ce9d74dc457f18d506bc98395589","price":"0.5","side":"BUY","size":"97.6"},{"asset_id":"14965588658799411272385430903075831224615961675357217884735713260981483529984","best_ask":"0.5","best_bid":"0.48","hash":"ab02e70e037a639dc7533bbf76bfb654decb0314","price":"0.5","side":"SELL","size":"97.6"}],"timestamp":"1785208061342"},"payload_hash":"c9d6fa90d97f96f30135f4c242d41a1e906b0ad5fa021f37ba7f90400e301ded","raw_frame":"{\"market\":\"0x779291bef19b6709f61e9764a954aafe9ffae488d50ae674aabdcb4f248006d5\", \"price_changes\":[{\"asset_id\":\"8761897749749422724209054078244794145777693856614463256546737399611489089783\", \"price\":\"0.5\", \"size\":\"97.6\", \"side\":\"BUY\", \"hash\":\"c58edb67cb64ce9d74dc457f18d506bc98395589\", \"best_bid\":\"0.5\", \"best_ask\":\"0.52\"}, {\"asset_id\":\"14965588658799411272385430903075831224615961675357217884735713260981483529984\", \"price\":\"0.5\", \"size\":\"97.6\", \"side\":\"SELL\", \"hash\":\"ab02e70e037a639dc7533bbf76bfb654decb0314\", \"best_bid\":\"0.48\", \"best_ask\":\"0.5\"}], \"timestamp\":\"1785208061342\", \"event_type\":\"price_change\"}","received_at":"2026-07-28T03:07:45.814703Z","schema_version":"clob-market-ws.price_change.v1","sequence":null,"server_hash":null,"server_timestamp":"1785208061342","session_id":"3e519d9098404c15b234d96025eb1a2b","source":"clob_market_ws"},"received_at":"2026-07-28T03:07:45.814703Z","record_id":"3caff687393fcec682b1ee6e4bc8787dd1fcd56bd64849de1111dd716c17eb58","schema_fingerprint":"4aa3821a28b0b7c2400bc59aba4bcc0a76e971dadd19610d3ad38c768e124dc7","schema_version":"edge-lab-recorder.raw.v1","sequence":null,"source":"clob_market_ws"}
{"event_at":"2026-07-28T03:07:41.344000Z","event_fingerprint":"06ea232793e0d1b89845007afc09e53456a4aeb2699e304f331af2fad3ef1abc","payload":{"connection_id":"a6b55582af5f430fb37ad02bf0922475","event_at":"2026-07-28T03:07:41.344000Z","event_type":"price_change","frame_hash":"4ef51876dfcb0131e08b0385a81aecbea7d433623a4bdabe72499cc3421c9643","frame_index":0,"kind":"data","monotonic_ns":310048847694833,"payload":{"event_type":"price_change","market":"0x779291bef19b6709f61e9764a954aafe9ffae488d50ae674aabdcb4f248006d5","price_changes":[{"asset_id":"8761897749749422724209054078244794145777693856614463256546737399611489089783","best_ask":"0.52","best_bid":"0.5","hash":"5b602d0d30851bf1d7c7305413f644a3069f23c0","price":"0.5","side":"BUY","size":"82.6"},{"asset_id":"14965588658799411272385430903075831224615961675357217884735713260981483529984","best_ask":"0.5","best_bid":"0.48","hash":"e47ac186105f9e46a26c5d2d50b982d195626868","price":"0.5","side":"SELL","size":"82.6"}],"timestamp":"1785208061344"},"payload_hash":"55fecd30e4bd816be64f8f6af8256492da933b5155ed2d7f21db012b77f736b4","raw_frame":"{\"market\":\"0x779291bef19b6709f61e9764a954aafe9ffae488d50ae674aabdcb4f248006d5\", \"price_changes\":[{\"asset_id\":\"8761897749749422724209054078244794145777693856614463256546737399611489089783\", \"price\":\"0.5\", \"size\":\"82.6\", \"side\":\"BUY\", \"hash\":\"5b602d0d30851bf1d7c7305413f644a3069f23c0\", \"best_bid\":\"0.5\", \"best_ask\":\"0.52\"}, {\"asset_id\":\"14965588658799411272385430903075831224615961675357217884735713260981483529984\", \"price\":\"0.5\", \"size\":\"82.6\", \"side\":\"SELL\", \"hash\":\"e47ac186105f9e46a26c5d2d50b982d195626868\", \"best_bid\":\"0.48\", \"best_ask\":\"0.5\"}], \"timestamp\":\"1785208061344\", \"event_type\":\"price_change\"}","received_at":"2026-07-28T03:07:45.815555Z","schema_version":"clob-market-ws.price_change.v1","sequence":null,"server_hash":null,"server_timestamp":"1785208061344","session_id":"3e519d9098404c15b234d96025eb1a2b","source":"clob_market_ws"},"received_at":"2026-07-28T03:07:45.815555Z","record_id":"efab52832a93e2d91b97acf7251d25d19e9b906c85831cc4a5196941e9aea209","schema_fingerprint":"4aa3821a28b0b7c2400bc59aba4bcc0a76e971dadd19610d3ad38c768e124dc7","schema_version":"edge-lab-recorder.raw.v1","sequence":null,"source":"clob_market_ws"}
{"event_at":"2026-07-28T03:07:41.344000Z","event_fingerprint":"dab1e2511ba0fae9d1b432c7bd2755ef1d954117ccc43227b96193b5498f6b62","payload":{"connection_id":"a6b55582af5f430fb37ad02bf0922475","event_at":"2026-07-28T03:07:41.344000Z","event_type":"price_change","frame_hash":"7417efe556f4711fb7765a3f7714f89387ce154fa60fdd2a574942486af670c3","frame_index":0,"kind":"data","monotonic_ns":310048848799625,"payload":{"event_type":"price_change","market":"0x779291bef19b6709f61e9764a954aafe9ffae488d50ae674aabdcb4f248006d5","price_changes":[{"asset_id":"8761897749749422724209054078244794145777693856614463256546737399611489089783","best_ask":"0.52","best_bid":"0.5","hash":"8cfc28986063a1edad1773fb43303926cff88d46","price":"0.01","side":"BUY","size":"5608.02"},{"asset_id":"14965588658799411272385430903075831224615961675357217884735713260981483529984","best_ask":"0.5","best_bid":"0.48","hash":"609cb4ab490fc15968ae0c3b633ed8b742b28b81","price":"0.99","side":"SELL","size":"5608.02"}],"timestamp":"1785208061344"},"payload_hash":"ff7a46ab3ece26f499a973c1a07d6e5d0ae33b438d74f9535addf9303a0ab104","raw_frame":"{\"market\":\"0x779291bef19b6709f61e9764a954aafe9ffae488d50ae674aabdcb4f248006d5\", \"price_changes\":[{\"asset_id\":\"8761897749749422724209054078244794145777693856614463256546737399611489089783\", \"price\":\"0.01\", \"size\":\"5608.02\", \"side\":\"BUY\", \"hash\":\"8cfc28986063a1edad1773fb43303926cff88d46\", \"best_bid\":\"0.5\", \"best_ask\":\"0.52\"}, {\"asset_id\":\"14965588658799411272385430903075831224615961675357217884735713260981483529984\", \"price\":\"0.99\", \"size\":\"5608.02\", \"side\":\"SELL\", \"hash\":\"609cb4ab490fc15968ae0c3b633ed8b742b28b81\", \"best_bid\":\"0.48\", \"best_ask\":\"0.5\"}], \"timestamp\":\"1785208061344\", \"event_type\":\"price_change\"}","received_at":"2026-07-28T03:07:45.816660Z","schema_version":"clob-market-ws.price_change.v1","sequence":null,"server_hash":null,"server_timestamp":"1785208061344","session_id":"3e519d9098404c15b234d96025eb1a2b","source":"clob_market_ws"},"received_at":"2026-07-28T03:07:45.816660Z","record_id":"984420ed7a5060d78ff5e9cf11dba114de39744f8f90ecccfc376609ba12923d","schema_fingerprint":"4aa3821a28b0b7c2400bc59aba4bcc0a76e971dadd19610d3ad38c768e124dc7","schema_version":"edge-lab-recorder.raw.v1","sequence":null,"source":"clob_market_ws"}
{"event_at":"2026-07-28T03:07:41.349000Z","event_fingerprint":"0ce0c47ed6ba58b076629a3918914c6161b904166c1f27242e92e43d18746d99","payload":{"connection_id":"a6b55582af5f430fb37ad02bf0922475","event_at":"2026-07-28T03:07:41.349000Z","event_type":"price_change","frame_hash":"868cda650250080607005ff297f2f79d819001344b3f0da371284f3750e38027","frame_index":0,"kind":"data","monotonic_ns":310048851379041,"payload":{"event_type":"price_change","market":"0x779291bef19b6709f61e9764a954aafe9ffae488d50ae674aabdcb4f248006d5","price_changes":[{"asset_id":"8761897749749422724209054078244794145777693856614463256546737399611489089783","best_ask":"0.52","best_bid":"0.5","hash":"c2f81e7d8688a7f7d53d38568f9d1f09d8208b67","price":"0.49","side":"BUY","size":"81"},{"asset_id":"14965588658799411272385430903075831224615961675357217884735713260981483529984","best_ask":"0.5","best_bid":"0.48","hash":"030d09eb5ae4e76f82d8c89512200cbe6d210708","price":"0.51","side":"SELL","size":"81"}],"timestamp":"1785208061349"},"payload_hash":"ff983c411c08622e15d1622bbacdcf9c8081a646e827f1d404609b52309a8df1","raw_frame":"{\"market\":\"0x779291bef19b6709f61e9764a954aafe9ffae488d50ae674aabdcb4f248006d5\", \"price_changes\":[{\"asset_id\":\"8761897749749422724209054078244794145777693856614463256546737399611489089783\", \"price\":\"0.49\", \"size\":\"81\", \"side\":\"BUY\", \"hash\":\"c2f81e7d8688a7f7d53d38568f9d1f09d8208b67\", \"best_bid\":\"0.5\", \"best_ask\":\"0.52\"}, {\"asset_id\":\"14965588658799411272385430903075831224615961675357217884735713260981483529984\", \"price\":\"0.51\", \"size\":\"81\", \"side\":\"SELL\", \"hash\":\"030d09eb5ae4e76f82d8c89512200cbe6d210708\", \"best_bid\":\"0.48\", \"best_ask\":\"0.5\"}], \"timestamp\":\"1785208061349\", \"event_type\":\"price_change\"}","received_at":"2026-07-28T03:07:45.819233Z","schema_version":"clob-market-ws.price_change.v1","sequence":null,"server_hash":null,"server_timestamp":"1785208061349","session_id":"3e519d9098404c15b234d96025eb1a2b","source":"clob_market_ws"},"received_at":"2026-07-28T03:07:45.819233Z","record_id":"aee7a40c4133f4677e1d61e727d89e85846729c41245334e04563428f171a859","schema_fingerprint":"4aa3821a28b0b7c2400bc59aba4bcc0a76e971dadd19610d3ad38c768e124dc7","schema_version":"edge-lab-recorder.raw.v1","sequence":null,"source":"clob_market_ws"}
{"event_at":"2026-07-28T03:07:41.349000Z","event_fingerprint":"c4dfa1c30d013a20d71e9a69ac5f7b8b29e361814421f433a5e97b97c50a61ff","payload":{"connection_id":"a6b55582af5f430fb37ad02bf0922475","event_at":"2026-07-28T03:07:41.349000Z","event_type":"price_change","frame_hash":"8b54d46704494de9fda7da60b65688bb7c29db2a0e5281ea804c075b58b36bec","frame_index":0,"kind":"data","monotonic_ns":310048854993625,"payload":{"event_type":"price_change","market":"0x779291bef19b6709f61e9764a954aafe9ffae488d50ae674aabdcb4f248006d5","price_changes":[{"asset_id":"14965588658799411272385430903075831224615961675357217884735713260981483529984","best_ask":"0.5","best_bid":"0.48","hash":"b8a0419c74d7eeddf9df6f38a22ffd981e804a1e","price":"0.47","side":"BUY","size":"331.6"},{"asset_id":"8761897749749422724209054078244794145777693856614463256546737399611489089783","best_ask":"0.52","best_bid":"0.5","hash":"b0850bfd027df4685570880146e7cb4f4632d108","price":"0.53","side":"SELL","size":"331.6"}],"timestamp":"1785208061349"},"payload_hash":"6cfa714b47d400093acec19a2c0a0ba00e448eaf405cbf3ba149411bdcde22b3","raw_frame":"{\"market\":\"0x779291bef19b6709f61e9764a954aafe9ffae488d50ae674aabdcb4f248006d5\", \"price_changes\":[{\"asset_id\":\"14965588658799411272385430903075831224615961675357217884735713260981483529984\", \"price\":\"0.47\", \"size\":\"331.6\", \"side\":\"BUY\", \"hash\":\"b8a0419c74d7eeddf9df6f38a22ffd981e804a1e\", \"best_bid\":\"0.48\", \"best_ask\":\"0.5\"}, {\"asset_id\":\"8761897749749422724209054078244794145777693856614463256546737399611489089783\", \"price\":\"0.53\", \"size\":\"331.6\", \"side\":\"SELL\", \"hash\":\"b0850bfd027df4685570880146e7cb4f4632d108\", \"best_bid\":\"0.5\", \"best_ask\":\"0.52\"}], \"timestamp\":\"1785208061349\", \"event_type\":\"price_change\"}","received_at":"2026-07-28T03:07:45.822847Z","schema_version":"clob-market-ws.price_change.v1","sequence":null,"server_hash":null,"server_timestamp":"1785208061349","session_id":"3e519d9098404c15b234d96025eb1a2b","source":"clob_market_ws"},"received_at":"2026-07-28T03:07:45.822847Z","record_id":"39156a3b5a446d45e214a3648524868dd5a930825f0960d06d62e27f696ff3c7","schema_fingerprint":"4aa3821a28b0b7c2400bc59aba4bcc0a76e971dadd19610d3ad38c768e124dc7","schema_version":"edge-lab-recorder.raw.v1","sequence":null,"source":"clob_market_ws"}
{"event_at":"2026-07-28T03:07:41.350000Z","event_fingerprint":"6fa964aff35f16f1432d2a9bc2f026fc34b87aab27b8fa64ea17d4cc2924f4a8","payload":{"connection_id":"a6b55582af5f430fb37ad02bf0922475","event_at":"2026-07-28T03:07:41.350000Z","event_type":"price_change","frame_hash":"bf7b36523d3a6b7ed316f1bcdfc7fa9d7da04000b9bfab17f863172a7d2cbda7","frame_index":0,"kind":"data","monotonic_ns":310048857957375,"payload":{"event_type":"price_change","market":"0x779291bef19b6709f61e9764a954aafe9ffae488d50ae674aabdcb4f248006d5","price_changes":[{"asset_id":"8761897749749422724209054078244794145777693856614463256546737399611489089783","best_ask":"0.52","best_bid":"0.5","hash":"2214ac46e2099994ab78675fa95f0e0e336a17e9","price":"0.4","side":"BUY","size":"144"},{"asset_id":"14965588658799411272385430903075831224615961675357217884735713260981483529984","best_ask":"0.5","best_bid":"0.48","hash":"b9830b5fea52dd0b939c336a924a27879c5d3d24","price":"0.6","side":"SELL","size":"144"}],"timestamp":"1785208061350"},"payload_hash":"8c7cab54d9086069acc79c4675732cb8ab363946b82c2b7a1f3eb6634c7e29ae","raw_frame":"{\"market\":\"0x779291bef19b6709f61e9764a954aafe9ffae488d50ae674aabdcb4f248006d5\", \"price_changes\":[{\"asset_id\":\"8761897749749422724209054078244794145777693856614463256546737399611489089783\", \"price\":\"0.4\", \"size\":\"144\", \"side\":\"BUY\", \"hash\":\"2214ac46e2099994ab78675fa95f0e0e336a17e9\", \"best_bid\":\"0.5\", \"best_ask\":\"0.52\"}, {\"asset_id\":\"14965588658799411272385430903075831224615961675357217884735713260981483529984\", \"price\":\"0.6\", \"size\":\"144\", \"side\":\"SELL\", \"hash\":\"b9830b5fea52dd0b939c336a924a27879c5d3d24\", \"best_bid\":\"0.48\", \"best_ask\":\"0.5\"}], \"timestamp\":\"1785208061350\", \"event_type\":\"price_change\"}","received_at":"2026-07-28T03:07:45.825812Z","schema_version":"clob-market-ws.price_change.v1","sequence":null,"server_hash":null,"server_timestamp":"1785208061350","session_id":"3e519d9098404c15b234d96025eb1a2b","source":"clob_market_ws"},"received_at":"2026-07-28T03:07:45.825812Z","record_id":"6150fa7212da09412d9ecf90cf7b08f2ca214b3326364492ff8eb4153d070162","schema_fingerprint":"4aa3821a28b0b7c2400bc59aba4bcc0a76e971dadd19610d3ad38c768e124dc7","schema_version":"edge-lab-recorder.raw.v1","sequence":null,"source":"clob_market_ws"}
{"event_at":"2026-07-28T03:07:41.350000Z","event_fingerprint":"a188530955f8ab843800683efea3d6312a33df70b91c7f6737897769c63b9460","payload":{"connection_id":"a6b55582af5f430fb37ad02bf0922475","event_at":"2026-07-28T03:07:41.350000Z","event_type":"price_change","frame_hash":"2b3cde951b675b1764f48d236e3d143bf1de55587e7c9d6ba1fdddb947d0ba40","frame_index":0,"kind":"data","monotonic_ns":310048860013208,"payload":{"event_type":"price_change","market":"0x779291bef19b6709f61e9764a954aafe9ffae488d50ae674aabdcb4f248006d5","price_changes":[{"asset_id":"8761897749749422724209054078244794145777693856614463256546737399611489089783","best_ask":"0.52","best_bid":"0.5","hash":"5b24cddaead1558b228238ec3492e544889c2fb9","price":"0.5","side":"BUY","size":"42.6"},{"asset_id":"14965588658799411272385430903075831224615961675357217884735713260981483529984","best_ask":"0.5","best_bid":"0.48","hash":"7748bba3a9da0cffcc7babe51ef99d5154800f94","price":"0.5","side":"SELL","size":"42.6"}],"timestamp":"1785208061350"},"payload_hash":"b7edcaf982a9716f8e4e6f0a9d4003af351b6ba501b341a26d2130f3856dd5ec","raw_frame":"{\"market\":\"0x779291bef19b6709f61e9764a954aafe9ffae488d50ae674aabdcb4f248006d5\", \"price_changes\":[{\"asset_id\":\"8761897749749422724209054078244794145777693856614463256546737399611489089783\", \"price\":\"0.5\", \"size\":\"42.6\", \"side\":\"BUY\", \"hash\":\"5b24cddaead1558b228238ec3492e544889c2fb9\", \"best_bid\":\"0.5\", \"best_ask\":\"0.52\"}, {\"asset_id\":\"14965588658799411272385430903075831224615961675357217884735713260981483529984\", \"price\":\"0.5\", \"size\":\"42.6\", \"side\":\"SELL\", \"hash\":\"7748bba3a9da0cffcc7babe51ef99d5154800f94\", \"best_bid\":\"0.48\", \"best_ask\":\"0.5\"}], \"timestamp\":\"1785208061350\", \"event_type\":\"price_change\"}","received_at":"2026-07-28T03:07:45.827874Z","schema_version":"clob-market-ws.price_change.v1","sequence":null,"server_hash":null,"server_timestamp":"1785208061350","session_id":"3e519d9098404c15b234d96025eb1a2b","source":"clob_market_ws"},"received_at":"2026-07-28T03:07:45.827874Z","record_id":"1a5966b0eb300621abfb23c91b83b6d470eeb10d367200c5e66402826a4c1438","schema_fingerprint":"4aa3821a28b0b7c2400bc59aba4bcc0a76e971dadd19610d3ad38c768e124dc7","schema_version":"edge-lab-recorder.raw.v1","sequence":null,"source":"clob_market_ws"}
{"event_at":"2026-07-28T03:07:41.352000Z","event_fingerprint":"0a035aa8096269b50797243ba75d1f4fdefb195c4f83821fb79be73619629468","payload":{"connection_id":"a6b55582af5f430fb37ad02bf0922475","event_at":"2026-07-28T03:07:41.352000Z","event_type":"best_bid_ask","frame_hash":"a0f6bb1fbcaafd4ee93727913f8a0799de288bc0e65c47b1fe0866265fe223f7","frame_index":0,"kind":"data","monotonic_ns":310048862630958,"payload":{"asset_id":"14965588658799411272385430903075831224615961675357217884735713260981483529984","best_ask":"0.5","best_bid":"0.49","event_type":"best_bid_ask","market":"0x779291bef19b6709f61e9764a954aafe9ffae488d50ae674aabdcb4f248006d5","spread":"0.01","timestamp":"1785208061352"},"payload_hash":"c048a90e2e32027d7ee5b1367ef75762b0bb866a0983dfea21bad74ebb37abe3","raw_frame":"{\"market\":\"0x779291bef19b6709f61e9764a954aafe9ffae488d50ae674aabdcb4f248006d5\", \"asset_id\":\"14965588658799411272385430903075831224615961675357217884735713260981483529984\", \"best_bid\":\"0.49\", \"best_ask\":\"0.5\", \"spread\":\"0.01\", \"timestamp\":\"1785208061352\", \"event_type\":\"best_bid_ask\"}","received_at":"2026-07-28T03:07:45.830485Z","schema_version":"clob-market-ws.best_bid_ask.v1","sequence":null,"server_hash":null,"server_timestamp":"1785208061352","session_id":"3e519d9098404c15b234d96025eb1a2b","source":"clob_market_ws"},"received_at":"2026-07-28T03:07:45.830485Z","record_id":"8b0b798a645303f8cc3eac34129743fce9708074b7490e62339b33c434de247f","schema_fingerprint":"8488399f31b0337811b13b266be932db7062827c2470b78bd8e9e99bab51d17d","schema_version":"edge-lab-recorder.raw.v1","sequence":null,"source":"clob_market_ws"}
{"event_at":"2026-07-28T03:07:41.352000Z","event_fingerprint":"1eb0da1c355170b1edbc52f1e06d660a8cb9298aae05d436ab30a53bd0033aad","payload":{"connection_id":"a6b55582af5f430fb37ad02bf0922475","event_at":"2026-07-28T03:07:41.352000Z","event_type":"best_bid_ask","frame_hash":"ad36167b42a37c297eadd9e70ee355496863ce5ea76a2d6494b856a64b51c2ea","frame_index":0,"kind":"data","monotonic_ns":310048865163958,"payload":{"asset_id":"8761897749749422724209054078244794145777693856614463256546737399611489089783","best_ask":"0.51","best_bid":"0.5","event_type":"best_bid_ask","market":"0x779291bef19b6709f61e9764a954aafe9ffae488d50ae674aabdcb4f248006d5","spread":"0.01","timestamp":"1785208061352"},"payload_hash":"b8f494dd11f4c2c892c1da0ba93b9174b9628fbdbb9848c9a0d6cb87c6407f50","raw_frame":"{\"market\":\"0x779291bef19b6709f61e9764a954aafe9ffae488d50ae674aabdcb4f248006d5\", \"asset_id\":\"8761897749749422724209054078244794145777693856614463256546737399611489089783\", \"best_bid\":\"0.5\", \"best_ask\":\"0.51\", \"spread\":\"0.01\", \"timestamp\":\"1785208061352\", \"event_type\":\"best_bid_ask\"}","received_at":"2026-07-28T03:07:45.833018Z","schema_version":"clob-market-ws.best_bid_ask.v1","sequence":null,"server_hash":null,"server_timestamp":"1785208061352","session_id":"3e519d9098404c15b234d96025eb1a2b","source":"clob_market_ws"},"received_at":"2026-07-28T03:07:45.833018Z","record_id":"662efbebcca1da34d298adaa690cb05efbd41c07d07fd86c7aa97febb1aeb937","schema_fingerprint":"8488399f31b0337811b13b266be932db7062827c2470b78bd8e9e99bab51d17d","schema_version":"edge-lab-recorder.raw.v1","sequence":null,"source":"clob_market_ws"}
{"event_at":"2026-07-28T03:07:41.352000Z","event_fingerprint":"eff01a2e2c7e7a106527f9032afa330ed926b6f932b88f7a0b1c3b8df8cf3c69","payload":{"connection_id":"a6b55582af5f430fb37ad02bf0922475","event_at":"2026-07-28T03:07:41.352000Z","event_type":"price_change","frame_hash":"39dac2dcf5f108c6d688109f6307f7a1db323b50925deb2900acf2acd8498f16","frame_index":0,"kind":"data","monotonic_ns":310048867678708,"payload":{"event_type":"price_change","market":"0x779291bef19b6709f61e9764a954aafe9ffae488d50ae674aabdcb4f248006d5","price_changes":[{"asset_id":"14965588658799411272385430903075831224615961675357217884735713260981483529984","best_ask":"0.5","best_bid":"0.49","hash":"482b51df46cdb15abfbc64fbb9c1db2397c70582","price":"0.49","side":"BUY","size":"6"},{"asset_id":"8761897749749422724209054078244794145777693856614463256546737399611489089783","best_ask":"0.51","best_bid":"0.5","hash":"f926f6332a43f97e3d55320d2fcedfa135634b95","price":"0.51","side":"SELL","size":"6"}],"timestamp":"1785208061352"},"payload_hash":"cd3686504c5a404834c75794a86d10e6900311d80eebc061716748793cc510cf","raw_frame":"{\"market\":\"0x779291bef19b6709f61e9764a954aafe9ffae488d50ae674aabdcb4f248006d5\", \"price_changes\":[{\"asset_id\":\"14965588658799411272385430903075831224615961675357217884735713260981483529984\", \"price\":\"0.49\", \"size\":\"6\", \"side\":\"BUY\", \"hash\":\"482b51df46cdb15abfbc64fbb9c1db2397c70582\", \"best_bid\":\"0.49\", \"best_ask\":\"0.5\"}, {\"asset_id\":\"8761897749749422724209054078244794145777693856614463256546737399611489089783\", \"price\":\"0.51\", \"size\":\"6\", \"side\":\"SELL\", \"hash\":\"f926f6332a43f97e3d55320d2fcedfa135634b95\", \"best_bid\":\"0.5\", \"best_ask\":\"0.51\"}], \"timestamp\":\"1785208061352\", \"event_type\":\"price_change\"}","received_at":"2026-07-28T03:07:45.835533Z","schema_version":"clob-market-ws.price_change.v1","sequence":null,"server_hash":null,"server_timestamp":"1785208061352","session_id":"3e519d9098404c15b234d96025eb1a2b","source":"clob_market_ws"},"received_at":"2026-07-28T03:07:45.835533Z","record_id":"22ae560f47070e12c642e246ffcd9705ed8f06e6825d42900cb9477e1edff193","schema_fingerprint":"4aa3821a28b0b7c2400bc59aba4bcc0a76e971dadd19610d3ad38c768e124dc7","schema_version":"edge-lab-recorder.raw.v1","sequence":null,"source":"clob_market_ws"}
{"event_at":"2026-07-28T03:07:41.352000Z","event_fingerprint":"f6187076fafe09cb0ab65473547d73d0b7c616dc9d46836dd90070be75f4ae76","payload":{"connection_id":"a6b55582af5f430fb37ad02bf0922475","event_at":"2026-07-28T03:07:41.352000Z","event_type":"price_change","frame_hash":"39abf9725b65ce778646aeaebbd8832b2b43478e94b6bdfc69ee8e2aaddb2d61","frame_index":0,"kind":"data","monotonic_ns":310048870612458,"payload":{"event_type":"price_change","market":"0x779291bef19b6709f61e9764a954aafe9ffae488d50ae674aabdcb4f248006d5","price_changes":[{"asset_id":"8761897749749422724209054078244794145777693856614463256546737399611489089783","best_ask":"0.51","best_bid":"0.5","hash":"8396005b3c228182c5b3efe13959c79eeab98a14","price":"0.4","side":"BUY","size":"139"},{"asset_id":"14965588658799411272385430903075831224615961675357217884735713260981483529984","best_ask":"0.5","best_bid":"0.49","hash":"49bb6c3d49da2d89df98d327c14ad090a3861af4","price":"0.6","side":"SELL","size":"139"}],"timestamp":"1785208061352"},"payload_hash":"f7c995fe72b6d4c569039e926a482c372e614cc33409f201e06a062535563821","raw_frame":"{\"market\":\"0x779291bef19b6709f61e9764a954aafe9ffae488d50ae674aabdcb4f248006d5\", \"price_changes\":[{\"asset_id\":\"8761897749749422724209054078244794145777693856614463256546737399611489089783\", \"price\":\"0.4\", \"size\":\"139\", \"side\":\"BUY\", \"hash\":\"8396005b3c228182c5b3efe13959c79eeab98a14\", \"best_bid\":\"0.5\", \"best_ask\":\"0.51\"}, {\"asset_id\":\"14965588658799411272385430903075831224615961675357217884735713260981483529984\", \"price\":\"0.6\", \"size\":\"139\", \"side\":\"SELL\", \"hash\":\"49bb6c3d49da2d89df98d327c14ad090a3861af4\", \"best_bid\":\"0.49\", \"best_ask\":\"0.5\"}], \"timestamp\":\"1785208061352\", \"event_type\":\"price_change\"}","received_at":"2026-07-28T03:07:45.838467Z","schema_version":"clob-market-ws.price_change.v1","sequence":null,"server_hash":null,"server_timestamp":"1785208061352","session_id":"3e519d9098404c15b234d96025eb1a2b","source":"clob_market_ws"},"received_at":"2026-07-28T03:07:45.838467Z","record_id":"13ba955256260317d6e8ca8aff1ee98e926c7cbd2cc292139893a467eee123a5","schema_fingerprint":"4aa3821a28b0b7c2400bc59aba4bcc0a76e971dadd19610d3ad38c768e124dc7","schema_version":"edge-lab-recorder.raw.v1","sequence":null,"source":"clob_market_ws"}
{"event_at":"2026-07-28T03:07:41.352000Z","event_fingerprint":"88d43599cb9f62633daefa1929b766ea10b53291936fe5d5da7365c187f3ae14","payload":{"connection_id":"a6b55582af5f430fb37ad02bf0922475","event_at":"2026-07-28T03:07:41.352000Z","event_type":"price_change","frame_hash":"619201f36b34bca8965174e9070c33f21cbf414fbda769fbf59317f2cc7bddbb","frame_index":0,"kind":"data","monotonic_ns":310048874432166,"payload":{"event_type":"price_change","market":"0x779291bef19b6709f61e9764a954aafe9ffae488d50ae674aabdcb4f248006d5","price_changes":[{"asset_id":"8761897749749422724209054078244794145777693856614463256546737399611489089783","best_ask":"0.51","best_bid":"0.5","hash":"830aff77ae79834122a1374933417ece141c9ff1","price":"0.47","side":"BUY","size":"141.6"},{"asset_id":"14965588658799411272385430903075831224615961675357217884735713260981483529984","best_ask":"0.5","best_bid":"0.49","hash":"c3a4e88db29b1e48f0b9de89af689a7f57e16632","price":"0.53","side":"SELL","size":"141.6"}],"timestamp":"1785208061352"},"payload_hash":"47748cc60b44ced2ec3c3a28f26860b928f3476df2530292422966aee004cea9","raw_frame":"{\"market\":\"0x779291bef19b6709f61e9764a954aafe9ffae488d50ae674aabdcb4f248006d5\", \"price_changes\":[{\"asset_id\":\"8761897749749422724209054078244794145777693856614463256546737399611489089783\", \"price\":\"0.47\", \"size\":\"141.6\", \"side\":\"BUY\", \"hash\":\"830aff77ae79834122a1374933417ece141c9ff1\", \"best_bid\":\"0.5\", \"best_ask\":\"0.51\"}, {\"asset_id\":\"14965588658799411272385430903075831224615961675357217884735713260981483529984\", \"price\":\"0.53\", \"size\":\"141.6\", \"side\":\"SELL\", \"hash\":\"c3a4e88db29b1e48f0b9de89af689a7f57e16632\", \"best_bid\":\"0.49\", \"best_ask\":\"0.5\"}], \"timestamp\":\"1785208061352\", \"event_type\":\"price_change\"}","received_at":"2026-07-28T03:07:45.842287Z","schema_version":"clob-market-ws.price_change.v1","sequence":null,"server_hash":null,"server_timestamp":"1785208061352","session_id":"3e519d9098404c15b234d96025eb1a2b","source":"clob_market_ws"},"received_at":"2026-07-28T03:07:45.842287Z","record_id":"129df45e568bf006bdbdc054a6aeeefd66a9fd4dcb219d245243039c8cc290c1","schema_fingerprint":"4aa3821a28b0b7c2400bc59aba4bcc0a76e971dadd19610d3ad38c768e124dc7","schema_version":"edge-lab-recorder.raw.v1","sequence":null,"source":"clob_market_ws"}
{"event_at":"2026-07-28T03:07:41.355000Z","event_fingerprint":"deca0f1449bd4ac4a3dc1110fb6d66eede5200e139b207852d0292edd23d96df","payload":{"connection_id":"a6b55582af5f430fb37ad02bf0922475","event_at":"2026-07-28T03:07:41.355000Z","event_type":"price_change","frame_hash":"daa502fedb08fd7b0a5af4327a5d64a5b07ee9671df6e67b1dba9737e0a5fe2b","frame_index":0,"kind":"data","monotonic_ns":310048892511208,"payload":{"event_type":"price_change","market":"0x779291bef19b6709f61e9764a954aafe9ffae488d50ae674aabdcb4f248006d5","price_changes":[{"asset_id":"8761897749749422724209054078244794145777693856614463256546737399611489089783","best_ask":"0.51","best_bid":"0.5","hash":"e4ef1f271dad6934e421df9d3d5f0ae9f937b466","price":"0.4","side":"BUY","size":"189"},{"asset_id":"14965588658799411272385430903075831224615961675357217884735713260981483529984","best_ask":"0.5","best_bid":"0.49","hash":"b162c46b6fff13f8c6bab72b504acbdf83bbe0e3","price":"0.6","side":"SELL","size":"189"}],"timestamp":"1785208061355"},"payload_hash":"2c4f114106a92dc61f42d03254b321ce491c4ea2f9aa7bf8b5eb63958f2063fd","raw_frame":"{\"market\":\"0x779291bef19b6709f61e9764a954aafe9ffae488d50ae674aabdcb4f248006d5\", \"price_changes\":[{\"asset_id\":\"8761897749749422724209054078244794145777693856614463256546737399611489089783\", \"price\":\"0.4\", \"size\":\"189\", \"side\":\"BUY\", \"hash\":\"e4ef1f271dad6934e421df9d3d5f0ae9f937b466\", \"best_bid\":\"0.5\", \"best_ask\":\"0.51\"}, {\"asset_id\":\"14965588658799411272385430903075831224615961675357217884735713260981483529984\", \"price\":\"0.6\", \"size\":\"189\", \"side\":\"SELL\", \"hash\":\"b162c46b6fff13f8c6bab72b504acbdf83bbe0e3\", \"best_bid\":\"0.49\", \"best_ask\":\"0.5\"}], \"timestamp\":\"1785208061355\", \"event_type\":\"price_change\"}","received_at":"2026-07-28T03:07:45.860364Z","schema_version":"clob-market-ws.price_change.v1","sequence":null,"server_hash":null,"server_timestamp":"1785208061355","session_id":"3e519d9098404c15b234d96025eb1a2b","source":"clob_market_ws"},"received_at":"2026-07-28T03:07:45.860364Z","record_id":"4a64b365c984bab3da484019f5ce0c2187085a9a734342770b8affd3528e8801","schema_fingerprint":"4aa3821a28b0b7c2400bc59aba4bcc0a76e971dadd19610d3ad38c768e124dc7","schema_version":"edge-lab-recorder.raw.v1","sequence":null,"source":"clob_market_ws"}
{"event_at":"2026-07-28T03:07:41.356000Z","event_fingerprint":"81e5597cb31e631f2a07aa8405554988d733bcac0e8287916d173f0f69c99675","payload":{"connection_id":"a6b55582af5f430fb37ad02bf0922475","event_at":"2026-07-28T03:07:41.356000Z","event_type":"price_change","frame_hash":"5faf9a8fa36bef6a6be77dfc1086f436424e7e3e61046738d9c12c07f589a2b1","frame_index":0,"kind":"data","monotonic_ns":310048897993833,"payload":{"event_type":"price_change","market":"0x779291bef19b6709f61e9764a954aafe9ffae488d50ae674aabdcb4f248006d5","price_changes":[{"asset_id":"8761897749749422724209054078244794145777693856614463256546737399611489089783","best_ask":"0.51","best_bid":"0.5","hash":"0d07eaff07acbff083ca0ba20d5238133f783679","price":"0.43","side":"BUY","size":"219"},{"asset_id":"14965588658799411272385430903075831224615961675357217884735713260981483529984","best_ask":"0.5","best_bid":"0.49","hash":"16279df52bc3db3b7ae533d70d61dbd6f9161045","price":"0.57","side":"SELL","size":"219"}],"timestamp":"1785208061356"},"payload_hash":"dd655171c26bad12e6698ec27c73e0ecc04eaed002673856feaaad9b98cc3832","raw_frame":"{\"market\":\"0x779291bef19b6709f61e9764a954aafe9ffae488d50ae674aabdcb4f248006d5\", \"price_changes\":[{\"asset_id\":\"8761897749749422724209054078244794145777693856614463256546737399611489089783\", \"price\":\"0.43\", \"size\":\"219\", \"side\":\"BUY\", \"hash\":\"0d07eaff07acbff083ca0ba20d5238133f783679\", \"best_bid\":\"0.5\", \"best_ask\":\"0.51\"}, {\"asset_id\":\"14965588658799411272385430903075831224615961675357217884735713260981483529984\", \"price\":\"0.57\", \"size\":\"219\", \"side\":\"SELL\", \"hash\":\"16279df52bc3db3b7ae533d70d61dbd6f9161045\", \"best_bid\":\"0.49\", \"best_ask\":\"0.5\"}], \"timestamp\":\"1785208061356\", \"event_type\":\"price_change\"}","received_at":"2026-07-28T03:07:45.865847Z","schema_version":"clob-market-ws.price_change.v1","sequence":null,"server_hash":null,"server_timestamp":"1785208061356","session_id":"3e519d9098404c15b234d96025eb1a2b","source":"clob_market_ws"},"received_at":"2026-07-28T03:07:45.865847Z","record_id":"647aa91db3230f1b738c23c8389af202fecbb1bec0e4395da8b3243c2abca16f","schema_fingerprint":"4aa3821a28b0b7c2400bc59aba4bcc0a76e971dadd19610d3ad38c768e124dc7","schema_version":"edge-lab-recorder.raw.v1","sequence":null,"source":"clob_market_ws"}
{"event_at":"2026-07-28T03:07:41.356000Z","event_fingerprint":"83873d6a831a3023f9a3a6babf0c981900a5287b7605d3abf24ed68949866528","payload":{"connection_id":"a6b55582af5f430fb37ad02bf0922475","event_at":"2026-07-28T03:07:41.356000Z","event_type":"price_change","frame_hash":"0bc1622528ae51960cb68447045fd002d0c42b54c6eae694b6752768ac14450a","frame_index":0,"kind":"data","monotonic_ns":310048909627041,"payload":{"event_type":"price_change","market":"0x779291bef19b6709f61e9764a954aafe9ffae488d50ae674aabdcb4f248006d5","price_changes":[{"asset_id":"8761897749749422724209054078244794145777693856614463256546737399611489089783","best_ask":"0.51","best_bid":"0.5","hash":"cd0d815a98b9623b6953c290a88f1a1c18d41382","price":"0.43","side":"BUY","size":"224"},{"asset_id":"14965588658799411272385430903075831224615961675357217884735713260981483529984","best_ask":"0.5","best_bid":"0.49","hash":"70b4ea1cf074a4e96f5d5436a2604afb0e1f3a9e","price":"0.57","side":"SELL","size":"224"}],"timestamp":"1785208061356"},"payload_hash":"421ede28832dc45606e8a353f8677ad90f078a40da759a6ca00e5fff86e0ef5d","raw_frame":"{\"market\":\"0x779291bef19b6709f61e9764a954aafe9ffae488d50ae674aabdcb4f248006d5\", \"price_changes\":[{\"asset_id\":\"8761897749749422724209054078244794145777693856614463256546737399611489089783\", \"price\":\"0.43\", \"size\":\"224\", \"side\":\"BUY\", \"hash\":\"cd0d815a98b9623b6953c290a88f1a1c18d41382\", \"best_bid\":\"0.5\", \"best_ask\":\"0.51\"}, {\"asset_id\":\"14965588658799411272385430903075831224615961675357217884735713260981483529984\", \"price\":\"0.57\", \"size\":\"224\", \"side\":\"SELL\", \"hash\":\"70b4ea1cf074a4e96f5d5436a2604afb0e1f3a9e\", \"best_bid\":\"0.49\", \"best_ask\":\"0.5\"}], \"timestamp\":\"1785208061356\", \"event_type\":\"price_change\"}","received_at":"2026-07-28T03:07:45.877480Z","schema_version":"clob-market-ws.price_change.v1","sequence":null,"server_hash":null,"server_timestamp":"1785208061356","session_id":"3e519d9098404c15b234d96025eb1a2b","source":"clob_market_ws"},"received_at":"2026-07-28T03:07:45.877480Z","record_id":"fc27cbb2934c45b3bf9cdf364be5a711915c01c7466beb92601b059b6806c0e5","schema_fingerprint":"4aa3821a28b0b7c2400bc59aba4bcc0a76e971dadd19610d3ad38c768e124dc7","schema_version":"edge-lab-recorder.raw.v1","sequence":null,"source":"clob_market_ws"}
{"event_at":"2026-07-28T03:07:41.357000Z","event_fingerprint":"ba1708dc31cf838cebbe6f026ac7c735735ddb9a3aacfadf12843625bd903122","payload":{"connection_id":"a6b55582af5f430fb37ad02bf0922475","event_at":"2026-07-28T03:07:41.357000Z","event_type":"price_change","frame_hash":"08b69c446b347b8cf5e722faa2ca8e19da00c16347359c04e9bfb9fc8f491ce1","frame_index":0,"kind":"data","monotonic_ns":310048912688041,"payload":{"event_type":"price_change","market":"0x779291bef19b6709f61e9764a954aafe9ffae488d50ae674aabdcb4f248006d5","price_changes":[{"asset_id":"14965588658799411272385430903075831224615961675357217884735713260981483529984","best_ask":"0.5","best_bid":"0.49","hash":"fa306c2722fbdf3fa0ea1a2a470d22b9612f0812","price":"0.49","side":"BUY","size":"25"},{"asset_id":"8761897749749422724209054078244794145777693856614463256546737399611489089783","best_ask":"0.51","best_bid":"0.5","hash":"e62a90b81f9512fffcff9b7bacbf849990d46e96","price":"0.51","side":"SELL","size":"25"}],"timestamp":"1785208061357"},"payload_hash":"ed34b597aee9450ff298af3d6fa9c2efc1fc4ee03ab69d424de09385a58b18cb","raw_frame":"{\"market\":\"0x779291bef19b6709f61e9764a954aafe9ffae488d50ae674aabdcb4f248006d5\", \"price_changes\":[{\"asset_id\":\"14965588658799411272385430903075831224615961675357217884735713260981483529984\", \"price\":\"0.49\", \"size\":\"25\", \"side\":\"BUY\", \"hash\":\"fa306c2722fbdf3fa0ea1a2a470d22b9612f0812\", \"best_bid\":\"0.49\", \"best_ask\":\"0.5\"}, {\"asset_id\":\"8761897749749422724209054078244794145777693856614463256546737399611489089783\", \"price\":\"0.51\", \"size\":\"25\", \"side\":\"SELL\", \"hash\":\"e62a90b81f9512fffcff9b7bacbf849990d46e96\", \"best_bid\":\"0.5\", \"best_ask\":\"0.51\"}], \"timestamp\":\"1785208061357\", \"event_type\":\"price_change\"}","received_at":"2026-07-28T03:07:45.880542Z","schema_version":"clob-market-ws.price_change.v1","sequence":null,"server_hash":null,"server_timestamp":"1785208061357","session_id":"3e519d9098404c15b234d96025eb1a2b","source":"clob_market_ws"},"received_at":"2026-07-28T03:07:45.880542Z","record_id":"d0d7e3761e849d36f17b7f939441a76b3718af542bea19cf317802df8d4dcb7a","schema_fingerprint":"4aa3821a28b0b7c2400bc59aba4bcc0a76e971dadd19610d3ad38c768e124dc7","schema_version":"edge-lab-recorder.raw.v1","sequence":null,"source":"clob_market_ws"}
{"event_at":"2026-07-28T03:07:41.358000Z","event_fingerprint":"e8506b4496c54eb92c18c04c7f169d4deb44e62f9cb0d971e72c9e9e58aa6f5a","payload":{"connection_id":"a6b55582af5f430fb37ad02bf0922475","event_at":"2026-07-28T03:07:41.358000Z","event_type":"price_change","frame_hash":"12f3ba7b1774e2bed034e3a6770572c45f51aac09525bcd0b43dae98706d4717","frame_index":0,"kind":"data","monotonic_ns":310048915750125,"payload":{"event_type":"price_change","market":"0x779291bef19b6709f61e9764a954aafe9ffae488d50ae674aabdcb4f248006d5","price_changes":[{"asset_id":"8761897749749422724209054078244794145777693856614463256546737399611489089783","best_ask":"0.51","best_bid":"0.5","hash":"aa3b43ee77b7d481b4e7eab833d16350b8a9dd52","price":"0.5","side":"BUY","size":"82.6"},{"asset_id":"14965588658799411272385430903075831224615961675357217884735713260981483529984","best_ask":"0.5","best_bid":"0.49","hash":"51ed6f8390237c75df20ba52c5e633b46b20cfbe","price":"0.5","side":"SELL","size":"82.6"}],"timestamp":"1785208061358"},"payload_hash":"b004eef3b61bc871f5bc255f1c6c94c901123536160c5c2db1532ff8ff983f43","raw_frame":"{\"market\":\"0x779291bef19b6709f61e9764a954aafe9ffae488d50ae674aabdcb4f248006d5\", \"price_changes\":[{\"asset_id\":\"8761897749749422724209054078244794145777693856614463256546737399611489089783\", \"price\":\"0.5\", \"size\":\"82.6\", \"side\":\"BUY\", \"hash\":\"aa3b43ee77b7d481b4e7eab833d16350b8a9dd52\", \"best_bid\":\"0.5\", \"best_ask\":\"0.51\"}, {\"asset_id\":\"14965588658799411272385430903075831224615961675357217884735713260981483529984\", \"price\":\"0.5\", \"size\":\"82.6\", \"side\":\"SELL\", \"hash\":\"51ed6f8390237c75df20ba52c5e633b46b20cfbe\", \"best_bid\":\"0.49\", \"best_ask\":\"0.5\"}], \"timestamp\":\"1785208061358\", \"event_type\":\"price_change\"}","received_at":"2026-07-28T03:07:45.883604Z","schema_version":"clob-market-ws.price_change.v1","sequence":null,"server_hash":null,"server_timestamp":"1785208061358","session_id":"3e519d9098404c15b234d96025eb1a2b","source":"clob_market_ws"},"received_at":"2026-07-28T03:07:45.883604Z","record_id":"73659882adf7c1443b8bee5b88122e782d6081f8e5eeed7294a5e2737c3a9fd5","schema_fingerprint":"4aa3821a28b0b7c2400bc59aba4bcc0a76e971dadd19610d3ad38c768e124dc7","schema_version":"edge-lab-recorder.raw.v1","sequence":null,"source":"clob_market_ws"}
{"event_at":"2026-07-28T03:07:41.362000Z","event_fingerprint":"26fd3d38a2c2d7e0b6774af183195c2b45be885c26fd38eb86be24d8ecb1c80c","payload":{"connection_id":"a6b55582af5f430fb37ad02bf0922475","event_at":"2026-07-28T03:07:41.362000Z","event_type":"price_change","frame_hash":"293d30cbb939eca6008326b45887642036243927195a064562dd7bb96709aaf7","frame_index":0,"kind":"data","monotonic_ns":310048922486500,"payload":{"event_type":"price_change","market":"0x779291bef19b6709f61e9764a954aafe9ffae488d50ae674aabdcb4f248006d5","price_changes":[{"asset_id":"14965588658799411272385430903075831224615961675357217884735713260981483529984","best_ask":"0.5","best_bid":"0.49","hash":"6c7d246debc348a131e3b8d7e4e7fd7cd3ccc2ef","price":"0.53","side":"SELL","size":"146.6"},{"asset_id":"8761897749749422724209054078244794145777693856614463256546737399611489089783","best_ask":"0.51","best_bid":"0.5","hash":"72aa5f802b0a67433a4ac46d9dc363d5bba49112","price":"0.47","side":"BUY","size":"146.6"}],"timestamp":"1785208061362"},"payload_hash":"10ba4c67c60af3e8b56a7b0a2115801f0583bf24fb9697d5a37a4eec50a022a4","raw_frame":"{\"market\":\"0x779291bef19b6709f61e9764a954aafe9ffae488d50ae674aabdcb4f248006d5\", \"price_changes\":[{\"asset_id\":\"14965588658799411272385430903075831224615961675357217884735713260981483529984\", \"price\":\"0.53\", \"size\":\"146.6\", \"side\":\"SELL\", \"hash\":\"6c7d246debc348a131e3b8d7e4e7fd7cd3ccc2ef\", \"best_bid\":\"0.49\", \"best_ask\":\"0.5\"}, {\"asset_id\":\"8761897749749422724209054078244794145777693856614463256546737399611489089783\", \"price\":\"0.47\", \"size\":\"146.6\", \"side\":\"BUY\", \"hash\":\"72aa5f802b0a67433a4ac46d9dc363d5bba49112\", \"best_bid\":\"0.5\", \"best_ask\":\"0.51\"}], \"timestamp\":\"1785208061362\", \"event_type\":\"price_change\"}","received_at":"2026-07-28T03:07:45.890340Z","schema_version":"clob-market-ws.price_change.v1","sequence":null,"server_hash":null,"server_timestamp":"1785208061362","session_id":"3e519d9098404c15b234d96025eb1a2b","source":"clob_market_ws"},"received_at":"2026-07-28T03:07:45.890340Z","record_id":"95a97179e7b65e3574de5b076543b8ee2b1cfc8d88521d14fa67843c746ba611","schema_fingerprint":"4aa3821a28b0b7c2400bc59aba4bcc0a76e971dadd19610d3ad38c768e124dc7","schema_version":"edge-lab-recorder.raw.v1","sequence":null,"source":"clob_market_ws"}
{"event_at":"2026-07-28T03:07:41.362000Z","event_fingerprint":"c9452b3065bad80fcf710dc2f0c7e2448bddd3e18c50b627cd126bf41c938430","payload":{"connection_id":"a6b55582af5f430fb37ad02bf0922475","event_at":"2026-07-28T03:07:41.362000Z","event_type":"price_change","frame_hash":"7a16d5066ac364c8f44bb9e210d77df6f1d51228f792c477b48ecbc8e0e2506c","frame_index":0,"kind":"data","monotonic_ns":310048925435083,"payload":{"event_type":"price_change","market":"0x779291bef19b6709f61e9764a954aafe9ffae488d50ae674aabdcb4f248006d5","price_changes":[{"asset_id":"8761897749749422724209054078244794145777693856614463256546737399611489089783","best_ask":"0.51","best_bid":"0.5","hash":"5f575a7929a659835252475ce462745d1b68ff61","price":"0.47","side":"BUY","size":"152.6"},{"asset_id":"14965588658799411272385430903075831224615961675357217884735713260981483529984","best_ask":"0.5","best_bid":"0.49","hash":"dfb6a186dba202ab03a234571cd066a66142ad82","price":"0.53","side":"SELL","size":"152.6"}],"timestamp":"1785208061362"},"payload_hash":"d873fbf09eac277c428ebc357fd95ab10ae732676e774810579b87d73dbf4c7b","raw_frame":"{\"market\":\"0x779291bef19b6709f61e9764a954aafe9ffae488d50ae674aabdcb4f248006d5\", \"price_changes\":[{\"asset_id\":\"8761897749749422724209054078244794145777693856614463256546737399611489089783\", \"price\":\"0.47\", \"size\":\"152.6\", \"side\":\"BUY\", \"hash\":\"5f575a7929a659835252475ce462745d1b68ff61\", \"best_bid\":\"0.5\", \"best_ask\":\"0.51\"}, {\"asset_id\":\"14965588658799411272385430903075831224615961675357217884735713260981483529984\", \"price\":\"0.53\", \"size\":\"152.6\", \"side\":\"SELL\", \"hash\":\"dfb6a186dba202ab03a234571cd066a66142ad82\", \"best_bid\":\"0.49\", \"best_ask\":\"0.5\"}], \"timestamp\":\"1785208061362\", \"event_type\":\"price_change\"}","received_at":"2026-07-28T03:07:45.893288Z","schema_version":"clob-market-ws.price_change.v1","sequence":null,"server_hash":null,"server_timestamp":"1785208061362","session_id":"3e519d9098404c15b234d96025eb1a2b","source":"clob_market_ws"},"received_at":"2026-07-28T03:07:45.893288Z","record_id":"a122f96d9712d1fa11ef0a35b2d425722d882522bfbd131a8df460c977e1276c","schema_fingerprint":"4aa3821a28b0b7c2400bc59aba4bcc0a76e971dadd19610d3ad38c768e124dc7","schema_version":"edge-lab-recorder.raw.v1","sequence":null,"source":"clob_market_ws"}
{"event_at":"2026-07-28T03:07:41.378000Z","event_fingerprint":"21f056a3220afc1a11eddf8cf4d3097c45c8b865771abbb7a674e7c7b0a91db3","payload":{"connection_id":"a6b55582af5f430fb37ad02bf0922475","event_at":"2026-07-28T03:07:41.378000Z","event_type":"price_change","frame_hash":"461052cc3957210af8c5c25f9630bc9099727d2196eb619f9b4eed3a14651f9e","frame_index":0,"kind":"data","monotonic_ns":310048928444041,"payload":{"event_type":"price_change","market":"0x779291bef19b6709f61e9764a954aafe9ffae488d50ae674aabdcb4f248006d5","price_changes":[{"asset_id":"8761897749749422724209054078244794145777693856614463256546737399611489089783","best_ask":"0.51","best_bid":"0.5","hash":"862fac7798320257cf6f045445268c489be9421a","price":"0.04","side":"BUY","size":"588.09"},{"asset_id":"14965588658799411272385430903075831224615961675357217884735713260981483529984","best_ask":"0.5","best_bid":"0.49","hash":"61a5552b0e4c7831675434682b5f0653939e796d","price":"0.96","side":"SELL","size":"588.09"}],"timestamp":"1785208061378"},"payload_hash":"af3c1191a86088be04b121fca8fb7e75ae4835033acea3fe1e9737a791e143fd","raw_frame":"{\"market\":\"0x779291bef19b6709f61e9764a954aafe9ffae488d50ae674aabdcb4f248006d5\", \"price_changes\":[{\"asset_id\":\"8761897749749422724209054078244794145777693856614463256546737399611489089783\", \"price\":\"0.04\", \"size\":\"588.09\", \"side\":\"BUY\", \"hash\":\"862fac7798320257cf6f045445268c489be9421a\", \"best_bid\":\"0.5\", \"best_ask\":\"0.51\"}, {\"asset_id\":\"14965588658799411272385430903075831224615961675357217884735713260981483529984\", \"price\":\"0.96\", \"size\":\"588.09\", \"side\":\"SELL\", \"hash\":\"61a5552b0e4c7831675434682b5f0653939e796d\", \"best_bid\":\"0.49\", \"best_ask\":\"0.5\"}], \"timestamp\":\"1785208061378\", \"event_type\":\"price_change\"}","received_at":"2026-07-28T03:07:45.896297Z","schema_version":"clob-market-ws.price_change.v1","sequence":null,"server_hash":null,"server_timestamp":"1785208061378","session_id":"3e519d9098404c15b234d96025eb1a2b","source":"clob_market_ws"},"received_at":"2026-07-28T03:07:45.896297Z","record_id":"05bc4a057f51417df7a0326c2e7ac2880977b18ddf08c2ce6ca2fdac78333c4c","schema_fingerprint":"4aa3821a28b0b7c2400bc59aba4bcc0a76e971dadd19610d3ad38c768e124dc7","schema_version":"edge-lab-recorder.raw.v1","sequence":null,"source":"clob_market_ws"}
{"event_at":"2026-07-28T03:07:41.381000Z","event_fingerprint":"bc3b4f87d0f3044c613ce54717dc3d6184458991a83df1cfaa9fc097bea1a767","payload":{"connection_id":"a6b55582af5f430fb37ad02bf0922475","event_at":"2026-07-28T03:07:41.381000Z","event_type":"price_change","frame_hash":"71c628d8de4d18cfd9f5d2cd3a21058fe57305d5dfa05eaa8ff72373addd8ef8","frame_index":0,"kind":"data","monotonic_ns":310048931472958,"payload":{"event_type":"price_change","market":"0x779291bef19b6709f61e9764a954aafe9ffae488d50ae674aabdcb4f248006d5","price_changes":[{"asset_id":"8761897749749422724209054078244794145777693856614463256546737399611489089783","best_ask":"0.51","best_bid":"0.5","hash":"829e13b5bc0f38ac2b1bbc5a99cc694bb0d35091","price":"0.5","side":"BUY","size":"42.6"},{"asset_id":"14965588658799411272385430903075831224615961675357217884735713260981483529984","best_ask":"0.5","best_bid":"0.49","hash":"6028b3da6ce396a8e53bcaecde3fac5a5c8a5528","price":"0.5","side":"SELL","size":"42.6"}],"timestamp":"1785208061381"},"payload_hash":"bbecbe1919a1ad6da87a5ceb670c1a5eed65acad3dccf4ebafbffcf54858c2a0","raw_frame":"{\"market\":\"0x779291bef19b6709f61e9764a954aafe9ffae488d50ae674aabdcb4f248006d5\", \"price_changes\":[{\"asset_id\":\"8761897749749422724209054078244794145777693856614463256546737399611489089783\", \"price\":\"0.5\", \"size\":\"42.6\", \"side\":\"BUY\", \"hash\":\"829e13b5bc0f38ac2b1bbc5a99cc694bb0d35091\", \"best_bid\":\"0.5\", \"best_ask\":\"0.51\"}, {\"asset_id\":\"14965588658799411272385430903075831224615961675357217884735713260981483529984\", \"price\":\"0.5\", \"size\":\"42.6\", \"side\":\"SELL\", \"hash\":\"6028b3da6ce396a8e53bcaecde3fac5a5c8a5528\", \"best_bid\":\"0.49\", \"best_ask\":\"0.5\"}], \"timestamp\":\"1785208061381\", \"event_type\":\"price_change\"}","received_at":"2026-07-28T03:07:45.899326Z","schema_version":"clob-market-ws.price_change.v1","sequence":null,"server_hash":null,"server_timestamp":"1785208061381","session_id":"3e519d9098404c15b234d96025eb1a2b","source":"clob_market_ws"},"received_at":"2026-07-28T03:07:45.899326Z","record_id":"ec03595087eb130bbbbdb62f65539c3cb45a4c28b26be738a7e82accd714008e","schema_fingerprint":"4aa3821a28b0b7c2400bc59aba4bcc0a76e971dadd19610d3ad38c768e124dc7","schema_version":"edge-lab-recorder.raw.v1","sequence":null,"source":"clob_market_ws"}
{"event_at":"2026-07-28T03:07:41.387000Z","event_fingerprint":"c9a770df08aa164777b60acd640a917b16d7e97cd15d36033c093dc4faa3c12f","payload":{"connection_id":"a6b55582af5f430fb37ad02bf0922475","event_at":"2026-07-28T03:07:41.387000Z","event_type":"price_change","frame_hash":"9823ecf839cffb680aeed3fed3ff89663841c49f01d7d78c0eecb5dc03f1ee62","frame_index":0,"kind":"data","monotonic_ns":310048934436875,"payload":{"event_type":"price_change","market":"0x779291bef19b6709f61e9764a954aafe9ffae488d50ae674aabdcb4f248006d5","price_changes":[{"asset_id":"14965588658799411272385430903075831224615961675357217884735713260981483529984","best_ask":"0.5","best_bid":"0.49","hash":"3f4a714d7e087d913ad23f94fbc3676e6925a08c","price":"0.49","side":"BUY","size":"45"},{"asset_id":"8761897749749422724209054078244794145777693856614463256546737399611489089783","best_ask":"0.51","best_bid":"0.5","hash":"a7797cded4cbcb7cb46a74ce9dd9e5a38aee1d2c","price":"0.51","side":"SELL","size":"45"}],"timestamp":"1785208061387"},"payload_hash":"c0d1e8caf52760fe4b4c7c4bf04e4dea2869a3897e379c5477c37eb9b9612eeb","raw_frame":"{\"market\":\"0x779291bef19b6709f61e9764a954aafe9ffae488d50ae674aabdcb4f248006d5\", \"price_changes\":[{\"asset_id\":\"14965588658799411272385430903075831224615961675357217884735713260981483529984\", \"price\":\"0.49\", \"size\":\"45\", \"side\":\"BUY\", \"hash\":\"3f4a714d7e087d913ad23f94fbc3676e6925a08c\", \"best_bid\":\"0.49\", \"best_ask\":\"0.5\"}, {\"asset_id\":\"8761897749749422724209054078244794145777693856614463256546737399611489089783\", \"price\":\"0.51\", \"size\":\"45\", \"side\":\"SELL\", \"hash\":\"a7797cded4cbcb7cb46a74ce9dd9e5a38aee1d2c\", \"best_bid\":\"0.5\", \"best_ask\":\"0.51\"}], \"timestamp\":\"1785208061387\", \"event_type\":\"price_change\"}","received_at":"2026-07-28T03:07:45.902290Z","schema_version":"clob-market-ws.price_change.v1","sequence":null,"server_hash":null,"server_timestamp":"1785208061387","session_id":"3e519d9098404c15b234d96025eb1a2b","source":"clob_market_ws"},"received_at":"2026-07-28T03:07:45.902290Z","record_id":"dd77d8a06e3f8cf2cfef8cfe499f0923f1d439c45888de4fdd316374a6310d52","schema_fingerprint":"4aa3821a28b0b7c2400bc59aba4bcc0a76e971dadd19610d3ad38c768e124dc7","schema_version":"edge-lab-recorder.raw.v1","sequence":null,"source":"clob_market_ws"}
{"event_at":"2026-07-28T03:07:41.389000Z","event_fingerprint":"88739d653b648383755f9488ea089fa56c535042fb661b045bd17b1e1f9eefb8","payload":{"connection_id":"a6b55582af5f430fb37ad02bf0922475","event_at":"2026-07-28T03:07:41.389000Z","event_type":"price_change","frame_hash":"14feff1b245e3f6050481925b14bdf441f9af9fc34ffe229701098c0b61986aa","frame_index":0,"kind":"data","monotonic_ns":310048937342625,"payload":{"event_type":"price_change","market":"0x779291bef19b6709f61e9764a954aafe9ffae488d50ae674aabdcb4f248006d5","price_changes":[{"asset_id":"8761897749749422724209054078244794145777693856614463256546737399611489089783","best_ask":"0.51","best_bid":"0.5","hash":"8023a49e47873251809bab25e0acbab4a7d2d1ab","price":"0.48","side":"BUY","size":"201.6"},{"asset_id":"14965588658799411272385430903075831224615961675357217884735713260981483529984","best_ask":"0.5","best_bid":"0.49","hash":"7f7e6d58837e1d8354e01ebfd498b8f33be2b6ee","price":"0.52","side":"SELL","size":"201.6"}],"timestamp":"1785208061389"},"payload_hash":"0c7956d7fa6a0c690f1769ad111b5514db81b75e71341c96cc757c85ceeb589f","raw_frame":"{\"market\":\"0x779291bef19b6709f61e9764a954aafe9ffae488d50ae674aabdcb4f248006d5\", \"price_changes\":[{\"asset_id\":\"8761897749749422724209054078244794145777693856614463256546737399611489089783\", \"price\":\"0.48\", \"size\":\"201.6\", \"side\":\"BUY\", \"hash\":\"8023a49e47873251809bab25e0acbab4a7d2d1ab\", \"best_bid\":\"0.5\", \"best_ask\":\"0.51\"}, {\"asset_id\":\"14965588658799411272385430903075831224615961675357217884735713260981483529984\", \"price\":\"0.52\", \"size\":\"201.6\", \"side\":\"SELL\", \"hash\":\"7f7e6d58837e1d8354e01ebfd498b8f33be2b6ee\", \"best_bid\":\"0.49\", \"best_ask\":\"0.5\"}], \"timestamp\":\"1785208061389\", \"event_type\":\"price_change\"}","received_at":"2026-07-28T03:07:45.905196Z","schema_version":"clob-market-ws.price_change.v1","sequence":null,"server_hash":null,"server_timestamp":"1785208061389","session_id":"3e519d9098404c15b234d96025eb1a2b","source":"clob_market_ws"},"received_at":"2026-07-28T03:07:45.905196Z","record_id":"74cf8f20735a8dac73e619e260b1a0252d6c2c5af7f6bfc4b68c013bec2b4b28","schema_fingerprint":"4aa3821a28b0b7c2400bc59aba4bcc0a76e971dadd19610d3ad38c768e124dc7","schema_version":"edge-lab-recorder.raw.v1","sequence":null,"source":"clob_market_ws"}
{"event_at":"2026-07-28T03:07:41.391000Z","event_fingerprint":"a00bdd4815ad86920f987648e7c430b54783cc0d53fd60f9d2b2c0e934b590b3","payload":{"connection_id":"a6b55582af5f430fb37ad02bf0922475","event_at":"2026-07-28T03:07:41.391000Z","event_type":"price_change","frame_hash":"60cf75f2dc3836e9dbef23a0fd94dc4f450c5cb1cc292b49466a08ddb5a3633e","frame_index":0,"kind":"data","monotonic_ns":310048940276500,"payload":{"event_type":"price_change","market":"0x779291bef19b6709f61e9764a954aafe9ffae488d50ae674aabdcb4f248006d5","price_changes":[{"asset_id":"14965588658799411272385430903075831224615961675357217884735713260981483529984","best_ask":"0.5","best_bid":"0.49","hash":"aaca1132bdd8848f476dfed1f1eb5da5df091186","price":"0.47","side":"BUY","size":"341.6"},{"asset_id":"8761897749749422724209054078244794145777693856614463256546737399611489089783","best_ask":"0.51","best_bid":"0.5","hash":"ae611ea1974828a10ede139a80b9bba948e38b51","price":"0.53","side":"SELL","size":"341.6"}],"timestamp":"1785208061391"},"payload_hash":"c80cc48ec958d220a7914c0a63798e84ce0184c34cfcafa7ee388b4e7bf9d8a8","raw_frame":"{\"market\":\"0x779291bef19b6709f61e9764a954aafe9ffae488d50ae674aabdcb4f248006d5\", \"price_changes\":[{\"asset_id\":\"14965588658799411272385430903075831224615961675357217884735713260981483529984\", \"price\":\"0.47\", \"size\":\"341.6\", \"side\":\"BUY\", \"hash\":\"aaca1132bdd8848f476dfed1f1eb5da5df091186\", \"best_bid\":\"0.49\", \"best_ask\":\"0.5\"}, {\"asset_id\":\"8761897749749422724209054078244794145777693856614463256546737399611489089783\", \"price\":\"0.53\", \"size\":\"341.6\", \"side\":\"SELL\", \"hash\":\"ae611ea1974828a10ede139a80b9bba948e38b51\", \"best_bid\":\"0.5\", \"best_ask\":\"0.51\"}], \"timestamp\":\"1785208061391\", \"event_type\":\"price_change\"}","received_at":"2026-07-28T03:07:45.908130Z","schema_version":"clob-market-ws.price_change.v1","sequence":null,"server_hash":null,"server_timestamp":"1785208061391","session_id":"3e519d9098404c15b234d96025eb1a2b","source":"clob_market_ws"},"received_at":"2026-07-28T03:07:45.908130Z","record_id":"4b5ed6975bc9be5a08c6cafa7785d7f063e41bf6eff0000f0b62f0ebd66500e7","schema_fingerprint":"4aa3821a28b0b7c2400bc59aba4bcc0a76e971dadd19610d3ad38c768e124dc7","schema_version":"edge-lab-recorder.raw.v1","sequence":null,"source":"clob_market_ws"}
{"event_at":"2026-07-28T03:07:41.392000Z","event_fingerprint":"574032796e0452ea80fc54335fef4c2e4dff39d54d9bec0ca4b9d639f099778a","payload":{"connection_id":"a6b55582af5f430fb37ad02bf0922475","event_at":"2026-07-28T03:07:41.392000Z","event_type":"price_change","frame_hash":"576d42017877442eba60b041e5bd719dcb4a3ba35693af74235aacd08d11b428","frame_index":0,"kind":"data","monotonic_ns":310048943186125,"payload":{"event_type":"price_change","market":"0x779291bef19b6709f61e9764a954aafe9ffae488d50ae674aabdcb4f248006d5","price_changes":[{"asset_id":"14965588658799411272385430903075831224615961675357217884735713260981483529984","best_ask":"0.5","best_bid":"0.49","hash":"c4f8c7cda246e30f38f4bb83b1202681752b07ff","price":"0.48","side":"BUY","size":"452.6"},{"asset_id":"8761897749749422724209054078244794145777693856614463256546737399611489089783","best_ask":"0.51","best_bid":"0.5","hash":"a44818e1c0c12188f5efd7e34476e8c0671c669d","price":"0.52","side":"SELL","size":"452.6"}],"timestamp":"1785208061392"},"payload_hash":"1c9793606d9b38680a26136f10ec16942a4a758fc46b5b3e642865985de2646f","raw_frame":"{\"market\":\"0x779291bef19b6709f61e9764a954aafe9ffae488d50ae674aabdcb4f248006d5\", \"price_changes\":[{\"asset_id\":\"14965588658799411272385430903075831224615961675357217884735713260981483529984\", \"price\":\"0.48\", \"size\":\"452.6\", \"side\":\"BUY\", \"hash\":\"c4f8c7cda246e30f38f4bb83b1202681752b07ff\", \"best_bid\":\"0.49\", \"best_ask\":\"0.5\"}, {\"asset_id\":\"8761897749749422724209054078244794145777693856614463256546737399611489089783\", \"price\":\"0.52\", \"size\":\"452.6\", \"side\":\"SELL\", \"hash\":\"a44818e1c0c12188f5efd7e34476e8c0671c669d\", \"best_bid\":\"0.5\", \"best_ask\":\"0.51\"}], \"timestamp\":\"1785208061392\", \"event_type\":\"price_change\"}","received_at":"2026-07-28T03:07:45.911039Z","schema_version":"clob-market-ws.price_change.v1","sequence":null,"server_hash":null,"server_timestamp":"1785208061392","session_id":"3e519d9098404c15b234d96025eb1a2b","source":"clob_market_ws"},"received_at":"2026-07-28T03:07:45.911039Z","record_id":"b4e6ec149ac1ab64f4e050148eed7f24e4e5fb6344f01c1c80d811e6f2fa9cbb","schema_fingerprint":"4aa3821a28b0b7c2400bc59aba4bcc0a76e971dadd19610d3ad38c768e124dc7","schema_version":"edge-lab-recorder.raw.v1","sequence":null,"source":"clob_market_ws"}
{"event_at":"2026-07-28T03:07:41.393000Z","event_fingerprint":"1b075607690ca00b044ceb85852d85ae00cf58ef2ab6f87b384aeca21801d99a","payload":{"connection_id":"a6b55582af5f430fb37ad02bf0922475","event_at":"2026-07-28T03:07:41.393000Z","event_type":"price_change","frame_hash":"d298b5308f02ced1748a58d8ce106595838678ed3936f5ec08f7fe999ba75c05","frame_index":0,"kind":"data","monotonic_ns":310048946133166,"payload":{"event_type":"price_change","market":"0x779291bef19b6709f61e9764a954aafe9ffae488d50ae674aabdcb4f248006d5","price_changes":[{"asset_id":"14965588658799411272385430903075831224615961675357217884735713260981483529984","best_ask":"0.5","best_bid":"0.49","hash":"6b7ee6e9f8b97cdc61f28dd22be48d5ec864f211","price":"0.48","side":"BUY","size":"472.6"},{"asset_id":"8761897749749422724209054078244794145777693856614463256546737399611489089783","best_ask":"0.51","best_bid":"0.5","hash":"4386e1ac5be8833284846d53bc2fa9266c612e7b","price":"0.52","side":"SELL","size":"472.6"}],"timestamp":"1785208061393"},"payload_hash":"91dd08a226b61dd84c0af993ae943a30b0d057054dd8779a17cc16f32a787d75","raw_frame":"{\"market\":\"0x779291bef19b6709f61e9764a954aafe9ffae488d50ae674aabdcb4f248006d5\", \"price_changes\":[{\"asset_id\":\"14965588658799411272385430903075831224615961675357217884735713260981483529984\", \"price\":\"0.48\", \"size\":\"472.6\", \"side\":\"BUY\", \"hash\":\"6b7ee6e9f8b97cdc61f28dd22be48d5ec864f211\", \"best_bid\":\"0.49\", \"best_ask\":\"0.5\"}, {\"asset_id\":\"8761897749749422724209054078244794145777693856614463256546737399611489089783\", \"price\":\"0.52\", \"size\":\"472.6\", \"side\":\"SELL\", \"hash\":\"4386e1ac5be8833284846d53bc2fa9266c612e7b\", \"best_bid\":\"0.5\", \"best_ask\":\"0.51\"}], \"timestamp\":\"1785208061393\", \"event_type\":\"price_change\"}","received_at":"2026-07-28T03:07:45.913987Z","schema_version":"clob-market-ws.price_change.v1","sequence":null,"server_hash":null,"server_timestamp":"1785208061393","session_id":"3e519d9098404c15b234d96025eb1a2b","source":"clob_market_ws"},"received_at":"2026-07-28T03:07:45.913987Z","record_id":"2aaa756de350fdd1cc3f552b3ab626c54aa2fe13fa2595d6205138cee16be9d2","schema_fingerprint":"4aa3821a28b0b7c2400bc59aba4bcc0a76e971dadd19610d3ad38c768e124dc7","schema_version":"edge-lab-recorder.raw.v1","sequence":null,"source":"clob_market_ws"}
{"event_at":"2026-07-28T03:07:41.393000Z","event_fingerprint":"5cc75a67dc2f5d905b4c3cde7292570a77388092f301f6bd9779cdb4aa6072c2","payload":{"connection_id":"a6b55582af5f430fb37ad02bf0922475","event_at":"2026-07-28T03:07:41.393000Z","event_type":"price_change","frame_hash":"44229f26f9943e3e579c0f60dd86ffe19d325958605f8c33c72631245ec8bad1","frame_index":0,"kind":"data","monotonic_ns":310048949051000,"payload":{"event_type":"price_change","market":"0x779291bef19b6709f61e9764a954aafe9ffae488d50ae674aabdcb4f248006d5","price_changes":[{"asset_id":"14965588658799411272385430903075831224615961675357217884735713260981483529984","best_ask":"0.5","best_bid":"0.49","hash":"f9028b0c8fe4241177d4759d5c90d54f4a9cbc4c","price":"0.47","side":"BUY","size":"71.6"},{"asset_id":"8761897749749422724209054078244794145777693856614463256546737399611489089783","best_ask":"0.51","best_bid":"0.5","hash":"3f9f58582ba84dfd30b93dd79aa5d4f3958878fd","price":"0.53","side":"SELL","size":"71.6"}],"timestamp":"1785208061393"},"payload_hash":"38803160809e968bf4d77cc7a637b6b293e2610bfaa5ab257b5dcb293708f60e","raw_frame":"{\"market\":\"0x779291bef19b6709f61e9764a954aafe9ffae488d50ae674aabdcb4f248006d5\", \"price_changes\":[{\"asset_id\":\"14965588658799411272385430903075831224615961675357217884735713260981483529984\", \"price\":\"0.47\", \"size\":\"71.6\", \"side\":\"BUY\", \"hash\":\"f9028b0c8fe4241177d4759d5c90d54f4a9cbc4c\", \"best_bid\":\"0.49\", \"best_ask\":\"0.5\"}, {\"asset_id\":\"8761897749749422724209054078244794145777693856614463256546737399611489089783\", \"price\":\"0.53\", \"size\":\"71.6\", \"side\":\"SELL\", \"hash\":\"3f9f58582ba84dfd30b93dd79aa5d4f3958878fd\", \"best_bid\":\"0.5\", \"best_ask\":\"0.51\"}], \"timestamp\":\"1785208061393\", \"event_type\":\"price_change\"}","received_at":"2026-07-28T03:07:45.916905Z","schema_version":"clob-market-ws.price_change.v1","sequence":null,"server_hash":null,"server_timestamp":"1785208061393","session_id":"3e519d9098404c15b234d96025eb1a2b","source":"clob_market_ws"},"received_at":"2026-07-28T03:07:45.916905Z","record_id":"24c1ff956011f8b76f600fc1dcc35f22e5fa25524f7f204d6137f86f594e642c","schema_fingerprint":"4aa3821a28b0b7c2400bc59aba4bcc0a76e971dadd19610d3ad38c768e124dc7","schema_version":"edge-lab-recorder.raw.v1","sequence":null,"source":"clob_market_ws"}
{"event_at":"2026-07-28T03:07:41.393000Z","event_fingerprint":"70e2f9d12937c85be4c5ca0905d7715ac97bbc770ab4ea9ae1571b6b69724e7e","payload":{"connection_id":"a6b55582af5f430fb37ad02bf0922475","event_at":"2026-07-28T03:07:41.393000Z","event_type":"price_change","frame_hash":"833648afb4ae4e429adeb361ba24be793d97234798bc55679c6c7d291ed89e32","frame_index":0,"kind":"data","monotonic_ns":310048951995958,"payload":{"event_type":"price_change","market":"0x779291bef19b6709f61e9764a954aafe9ffae488d50ae674aabdcb4f248006d5","price_changes":[{"asset_id":"14965588658799411272385430903075831224615961675357217884735713260981483529984","best_ask":"0.5","best_bid":"0.49","hash":"e819f2339af08b56339cab83ac4a87affedc982e","price":"0.49","side":"BUY","size":"55"},{"asset_id":"8761897749749422724209054078244794145777693856614463256546737399611489089783","best_ask":"0.51","best_bid":"0.5","hash":"b694d8d9fe2d95347908085f360cded900aff650","price":"0.51","side":"SELL","size":"55"}],"timestamp":"1785208061393"},"payload_hash":"cd7dd3961e08590033d0dc0248cf90d95a5db1908b1e2d8230c273e22e5c4f82","raw_frame":"{\"market\":\"0x779291bef19b6709f61e9764a954aafe9ffae488d50ae674aabdcb4f248006d5\", \"price_changes\":[{\"asset_id\":\"14965588658799411272385430903075831224615961675357217884735713260981483529984\", \"price\":\"0.49\", \"size\":\"55\", \"side\":\"BUY\", \"hash\":\"e819f2339af08b56339cab83ac4a87affedc982e\", \"best_bid\":\"0.49\", \"best_ask\":\"0.5\"}, {\"asset_id\":\"8761897749749422724209054078244794145777693856614463256546737399611489089783\", \"price\":\"0.51\", \"size\":\"55\", \"side\":\"SELL\", \"hash\":\"b694d8d9fe2d95347908085f360cded900aff650\", \"best_bid\":\"0.5\", \"best_ask\":\"0.51\"}], \"timestamp\":\"1785208061393\", \"event_type\":\"price_change\"}","received_at":"2026-07-28T03:07:45.919849Z","schema_version":"clob-market-ws.price_change.v1","sequence":null,"server_hash":null,"server_timestamp":"1785208061393","session_id":"3e519d9098404c15b234d96025eb1a2b","source":"clob_market_ws"},"received_at":"2026-07-28T03:07:45.919849Z","record_id":"cf3a9882e6893260898bae2ad2d21dd5752d4867807bfcd43f9ee9712baae2fc","schema_fingerprint":"4aa3821a28b0b7c2400bc59aba4bcc0a76e971dadd19610d3ad38c768e124dc7","schema_version":"edge-lab-recorder.raw.v1","sequence":null,"source":"clob_market_ws"}
{"event_at":"2026-07-28T03:07:41.394000Z","event_fingerprint":"121057af18973620d23e9cc3b35b1b4a2aeb8b1ad7d534142034f57e3b504408","payload":{"connection_id":"a6b55582af5f430fb37ad02bf0922475","event_at":"2026-07-28T03:07:41.394000Z","event_type":"price_change","frame_hash":"ef5586920240be52a21d3c8d67c990b0aac594a1c50ea69930f73e6f12d63371","frame_index":0,"kind":"data","monotonic_ns":310048955010666,"payload":{"event_type":"price_change","market":"0x779291bef19b6709f61e9764a954aafe9ffae488d50ae674aabdcb4f248006d5","price_changes":[{"asset_id":"14965588658799411272385430903075831224615961675357217884735713260981483529984","best_ask":"0.5","best_bid":"0.49","hash":"b562ed289d08cc38a2a6ca309d7b815fb4358f23","price":"0.38","side":"BUY","size":"221.38"},{"asset_id":"8761897749749422724209054078244794145777693856614463256546737399611489089783","best_ask":"0.51","best_bid":"0.5","hash":"c2d1141f76e203260dba3e610f05198527354c80","price":"0.62","side":"SELL","size":"221.38"}],"timestamp":"1785208061394"},"payload_hash":"ff16f81cf62bc1c3ed9c38c1422c0e58d809f32eb8a010cd9f80f6d4f4e58dce","raw_frame":"{\"market\":\"0x779291bef19b6709f61e9764a954aafe9ffae488d50ae674aabdcb4f248006d5\", \"price_changes\":[{\"asset_id\":\"14965588658799411272385430903075831224615961675357217884735713260981483529984\", \"price\":\"0.38\", \"size\":\"221.38\", \"side\":\"BUY\", \"hash\":\"b562ed289d08cc38a2a6ca309d7b815fb4358f23\", \"best_bid\":\"0.49\", \"best_ask\":\"0.5\"}, {\"asset_id\":\"8761897749749422724209054078244794145777693856614463256546737399611489089783\", \"price\":\"0.62\", \"size\":\"221.38\", \"side\":\"SELL\", \"hash\":\"c2d1141f76e203260dba3e610f05198527354c80\", \"best_bid\":\"0.5\", \"best_ask\":\"0.51\"}], \"timestamp\":\"1785208061394\", \"event_type\":\"price_change\"}","received_at":"2026-07-28T03:07:45.922864Z","schema_version":"clob-market-ws.price_change.v1","sequence":null,"server_hash":null,"server_timestamp":"1785208061394","session_id":"3e519d9098404c15b234d96025eb1a2b","source":"clob_market_ws"},"received_at":"2026-07-28T03:07:45.922864Z","record_id":"3467d4ecdbff590ba2dd6b00235222e9f8ebe3dc5af1214b2f6bf7e0d91fd9fe","schema_fingerprint":"4aa3821a28b0b7c2400bc59aba4bcc0a76e971dadd19610d3ad38c768e124dc7","schema_version":"edge-lab-recorder.raw.v1","sequence":null,"source":"clob_market_ws"}
{"event_at":"2026-07-28T03:07:41.398000Z","event_fingerprint":"7dba517360de08d4edd4915a127f6f3dc7229a43ce43e5a1f19477863c846715","payload":{"connection_id":"a6b55582af5f430fb37ad02bf0922475","event_at":"2026-07-28T03:07:41.398000Z","event_type":"price_change","frame_hash":"98f1d03eeae5fe0087f201f622abe7b143e03b12f5181c36cad63cd0c80baf1c","frame_index":0,"kind":"data","monotonic_ns":310048957959750,"payload":{"event_type":"price_change","market":"0x779291bef19b6709f61e9764a954aafe9ffae488d50ae674aabdcb4f248006d5","price_changes":[{"asset_id":"8761897749749422724209054078244794145777693856614463256546737399611489089783","best_ask":"0.51","best_bid":"0.5","hash":"9455b62b77dfd206775921421e0f9c5e430466da","price":"0.47","side":"BUY","size":"147.6"},{"asset_id":"14965588658799411272385430903075831224615961675357217884735713260981483529984","best_ask":"0.5","best_bid":"0.49","hash":"f3a330fbd1f4da6f0f18ef2ae09e38d109ee005b","price":"0.53","side":"SELL","size":"147.6"}],"timestamp":"1785208061398"},"payload_hash":"ec722cef4c30cc5080b50d6eb23947220eb0144f77d0f5c8f59a90f069f058fb","raw_frame":"{\"market\":\"0x779291bef19b6709f61e9764a954aafe9ffae488d50ae674aabdcb4f248006d5\", \"price_changes\":[{\"asset_id\":\"8761897749749422724209054078244794145777693856614463256546737399611489089783\", \"price\":\"0.47\", \"size\":\"147.6\", \"side\":\"BUY\", \"hash\":\"9455b62b77dfd206775921421e0f9c5e430466da\", \"best_bid\":\"0.5\", \"best_ask\":\"0.51\"}, {\"asset_id\":\"14965588658799411272385430903075831224615961675357217884735713260981483529984\", \"price\":\"0.53\", \"size\":\"147.6\", \"side\":\"SELL\", \"hash\":\"f3a330fbd1f4da6f0f18ef2ae09e38d109ee005b\", \"best_bid\":\"0.49\", \"best_ask\":\"0.5\"}], \"timestamp\":\"1785208061398\", \"event_type\":\"price_change\"}","received_at":"2026-07-28T03:07:45.925814Z","schema_version":"clob-market-ws.price_change.v1","sequence":null,"server_hash":null,"server_timestamp":"1785208061398","session_id":"3e519d9098404c15b234d96025eb1a2b","source":"clob_market_ws"},"received_at":"2026-07-28T03:07:45.925814Z","record_id":"d5be0a83d0906a6bddf774ba9560e0b424c5e73aa9817ea1031244977ff74ead","schema_fingerprint":"4aa3821a28b0b7c2400bc59aba4bcc0a76e971dadd19610d3ad38c768e124dc7","schema_version":"edge-lab-recorder.raw.v1","sequence":null,"source":"clob_market_ws"}
{"event_at":"2026-07-28T03:07:41.398000Z","event_fingerprint":"4b1fe994368e24bd601cc5d560e4406f9fa8bb8d7725e60b6d8d7ae64d1aeb47","payload":{"connection_id":"a6b55582af5f430fb37ad02bf0922475","event_at":"2026-07-28T03:07:41.398000Z","event_type":"price_change","frame_hash":"1903da5e140e19a0df75c1cec8e73c6a1e342a03a782620dd20353abb29f4288","frame_index":0,"kind":"data","monotonic_ns":310048961116500,"payload":{"event_type":"price_change","market":"0x779291bef19b6709f61e9764a954aafe9ffae488d50ae674aabdcb4f248006d5","price_changes":[{"asset_id":"8761897749749422724209054078244794145777693856614463256546737399611489089783","best_ask":"0.51","best_bid":"0.5","hash":"798ea3de25b2d2abc0164b2450a5ffdf8c8a3bce","price":"0.49","side":"BUY","size":"40"},{"asset_id":"14965588658799411272385430903075831224615961675357217884735713260981483529984","best_ask":"0.5","best_bid":"0.49","hash":"bcddc9e30faf49117ea788f324dbc9d29f42fb08","price":"0.51","side":"SELL","size":"40"}],"timestamp":"1785208061398"},"payload_hash":"dbcb78f765e9cbecae11e405ddebb0b0d1462435462653bd637b60e00d7beb62","raw_frame":"{\"market\":\"0x779291bef19b6709f61e9764a954aafe9ffae488d50ae674aabdcb4f248006d5\", \"price_changes\":[{\"asset_id\":\"8761897749749422724209054078244794145777693856614463256546737399611489089783\", \"price\":\"0.49\", \"size\":\"40\", \"side\":\"BUY\", \"hash\":\"798ea3de25b2d2abc0164b2450a5ffdf8c8a3bce\", \"best_bid\":\"0.5\", \"best_ask\":\"0.51\"}, {\"asset_id\":\"14965588658799411272385430903075831224615961675357217884735713260981483529984\", \"price\":\"0.51\", \"size\":\"40\", \"side\":\"SELL\", \"hash\":\"bcddc9e30faf49117ea788f324dbc9d29f42fb08\", \"best_bid\":\"0.49\", \"best_ask\":\"0.5\"}], \"timestamp\":\"1785208061398\", \"event_type\":\"price_change\"}","received_at":"2026-07-28T03:07:45.928970Z","schema_version":"clob-market-ws.price_change.v1","sequence":null,"server_hash":null,"server_timestamp":"1785208061398","session_id":"3e519d9098404c15b234d96025eb1a2b","source":"clob_market_ws"},"received_at":"2026-07-28T03:07:45.928970Z","record_id":"2d9ac5fedd3bdd369f10fefd0694579606403998767b4abf69c753d0f0d1676f","schema_fingerprint":"4aa3821a28b0b7c2400bc59aba4bcc0a76e971dadd19610d3ad38c768e124dc7","schema_version":"edge-lab-recorder.raw.v1","sequence":null,"source":"clob_market_ws"}
{"event_at":"2026-07-28T03:07:41.401000Z","event_fingerprint":"43341080c5e9d4f910f2c3854547fc9fee7c5fe8b645d640c19988a114561bf8","payload":{"connection_id":"a6b55582af5f430fb37ad02bf0922475","event_at":"2026-07-28T03:07:41.401000Z","event_type":"price_change","frame_hash":"f6afe179f2facf6e262fba98281358b78dc33fb55dba18131ef8e0ede36e3eb3","frame_index":0,"kind":"data","monotonic_ns":310048963669500,"payload":{"event_type":"price_change","market":"0x779291bef19b6709f61e9764a954aafe9ffae488d50ae674aabdcb4f248006d5","price_changes":[{"asset_id":"14965588658799411272385430903075831224615961675357217884735713260981483529984","best_ask":"0.5","best_bid":"0.49","hash":"d9e38bd43ac45fd9f19e48d9565b75da1621b039","price":"0.48","side":"BUY","size":"487.6"},{"asset_id":"8761897749749422724209054078244794145777693856614463256546737399611489089783","best_ask":"0.51","best_bid":"0.5","hash":"851762f76110ec0e4adf58ad24fb0ab0e780456b","price":"0.52","side":"SELL","size":"487.6"}],"timestamp":"1785208061401"},"payload_hash":"b582a6798af9468da3596ef481c82ad92f29e12b18da6190cc716215c7f46170","raw_frame":"{\"market\":\"0x779291bef19b6709f61e9764a954aafe9ffae488d50ae674aabdcb4f248006d5\", \"price_changes\":[{\"asset_id\":\"14965588658799411272385430903075831224615961675357217884735713260981483529984\", \"price\":\"0.48\", \"size\":\"487.6\", \"side\":\"BUY\", \"hash\":\"d9e38bd43ac45fd9f19e48d9565b75da1621b039\", \"best_bid\":\"0.49\", \"best_ask\":\"0.5\"}, {\"asset_id\":\"8761897749749422724209054078244794145777693856614463256546737399611489089783\", \"price\":\"0.52\", \"size\":\"487.6\", \"side\":\"SELL\", \"hash\":\"851762f76110ec0e4adf58ad24fb0ab0e780456b\", \"best_bid\":\"0.5\", \"best_ask\":\"0.51\"}], \"timestamp\":\"1785208061401\", \"event_type\":\"price_change\"}","received_at":"2026-07-28T03:07:45.931523Z","schema_version":"clob-market-ws.price_change.v1","sequence":null,"server_hash":null,"server_timestamp":"1785208061401","session_id":"3e519d9098404c15b234d96025eb1a2b","source":"clob_market_ws"},"received_at":"2026-07-28T03:07:45.931523Z","record_id":"31834ac026b4a44be9f721fea767b7cd1d1128cc69d640c98906a5ba9994a8ea","schema_fingerprint":"4aa3821a28b0b7c2400bc59aba4bcc0a76e971dadd19610d3ad38c768e124dc7","schema_version":"edge-lab-recorder.raw.v1","sequence":null,"source":"clob_market_ws"}
{"event_at":"2026-07-28T03:07:41.402000Z","event_fingerprint":"9b799ff9ec8d110202f06aaa1e1f59f1713a8dbfef5dc13e56085c4fb5ec54eb","payload":{"connection_id":"a6b55582af5f430fb37ad02bf0922475","event_at":"2026-07-28T03:07:41.402000Z","event_type":"price_change","frame_hash":"06962124d13402137d075f760468304b02a8a1de32db0777b3558fa2381abb4a","frame_index":0,"kind":"data","monotonic_ns":310048965933916,"payload":{"event_type":"price_change","market":"0x779291bef19b6709f61e9764a954aafe9ffae488d50ae674aabdcb4f248006d5","price_changes":[{"asset_id":"8761897749749422724209054078244794145777693856614463256546737399611489089783","best_ask":"0.51","best_bid":"0.5","hash":"f0c159671b0f2e93242affb5d03c5beb7541fc1a","price":"0.46","side":"BUY","size":"162.06"},{"asset_id":"14965588658799411272385430903075831224615961675357217884735713260981483529984","best_ask":"0.5","best_bid":"0.49","hash":"081800970439c39f5b8e59c83a6bf160c1a2a459","price":"0.54","side":"SELL","size":"162.06"}],"timestamp":"1785208061402"},"payload_hash":"f686877d8c50c8b3430078f6f193b7d5de6593bb74a4abef0a5835b451b88ad4","raw_frame":"{\"market\":\"0x779291bef19b6709f61e9764a954aafe9ffae488d50ae674aabdcb4f248006d5\", \"price_changes\":[{\"asset_id\":\"8761897749749422724209054078244794145777693856614463256546737399611489089783\", \"price\":\"0.46\", \"size\":\"162.06\", \"side\":\"BUY\", \"hash\":\"f0c159671b0f2e93242affb5d03c5beb7541fc1a\", \"best_bid\":\"0.5\", \"best_ask\":\"0.51\"}, {\"asset_id\":\"14965588658799411272385430903075831224615961675357217884735713260981483529984\", \"price\":\"0.54\", \"size\":\"162.06\", \"side\":\"SELL\", \"hash\":\"081800970439c39f5b8e59c83a6bf160c1a2a459\", \"best_bid\":\"0.49\", \"best_ask\":\"0.5\"}], \"timestamp\":\"1785208061402\", \"event_type\":\"price_change\"}","received_at":"2026-07-28T03:07:45.933789Z","schema_version":"clob-market-ws.price_change.v1","sequence":null,"server_hash":null,"server_timestamp":"1785208061402","session_id":"3e519d9098404c15b234d96025eb1a2b","source":"clob_market_ws"},"received_at":"2026-07-28T03:07:45.933789Z","record_id":"93bd8bf2f1cbbd73b4ef8cf6eceb61f97cc675bdf2a04fce2f84023775a9ef67","schema_fingerprint":"4aa3821a28b0b7c2400bc59aba4bcc0a76e971dadd19610d3ad38c768e124dc7","schema_version":"edge-lab-recorder.raw.v1","sequence":null,"source":"clob_market_ws"}
{"event_at":"2026-07-28T03:07:41.404000Z","event_fingerprint":"0e47736d5e7ec4267882aa006344c9de6b23965245d529e3ea8e360f240c77f9","payload":{"connection_id":"a6b55582af5f430fb37ad02bf0922475","event_at":"2026-07-28T03:07:41.404000Z","event_type":"price_change","frame_hash":"d4588a323d4be1b68450d5c75cd23ff493485ab72ff0e519bd6dac3a7ddbff07","frame_index":0,"kind":"data","monotonic_ns":310048969205958,"payload":{"event_type":"price_change","market":"0x779291bef19b6709f61e9764a954aafe9ffae488d50ae674aabdcb4f248006d5","price_changes":[{"asset_id":"14965588658799411272385430903075831224615961675357217884735713260981483529984","best_ask":"0.5","best_bid":"0.49","hash":"8c26cfb1df1a428429dedf4e66395b422d848b20","price":"0.48","side":"BUY","size":"497.6"},{"asset_id":"8761897749749422724209054078244794145777693856614463256546737399611489089783","best_ask":"0.51","best_bid":"0.5","hash":"369711e9467ad3bb9b8dff29c7e873e08e909f12","price":"0.52","side":"SELL","size":"497.6"}],"timestamp":"1785208061404"},"payload_hash":"1959c614053033ac8c9578374354d5b6ee531eb65c956c35c258968ff5b226ff","raw_frame":"{\"market\":\"0x779291bef19b6709f61e9764a954aafe9ffae488d50ae674aabdcb4f248006d5\", \"price_changes\":[{\"asset_id\":\"14965588658799411272385430903075831224615961675357217884735713260981483529984\", \"price\":\"0.48\", \"size\":\"497.6\", \"side\":\"BUY\", \"hash\":\"8c26cfb1df1a428429dedf4e66395b422d848b20\", \"best_bid\":\"0.49\", \"best_ask\":\"0.5\"}, {\"asset_id\":\"8761897749749422724209054078244794145777693856614463256546737399611489089783\", \"price\":\"0.52\", \"size\":\"497.6\", \"side\":\"SELL\", \"hash\":\"369711e9467ad3bb9b8dff29c7e873e08e909f12\", \"best_bid\":\"0.5\", \"best_ask\":\"0.51\"}], \"timestamp\":\"1785208061404\", \"event_type\":\"price_change\"}","received_at":"2026-07-28T03:07:45.937058Z","schema_version":"clob-market-ws.price_change.v1","sequence":null,"server_hash":null,"server_timestamp":"1785208061404","session_id":"3e519d9098404c15b234d96025eb1a2b","source":"clob_market_ws"},"received_at":"2026-07-28T03:07:45.937058Z","record_id":"448f6af92a7ab4576ac9d2da591396778da07627227be06fc54f81daf2345343","schema_fingerprint":"4aa3821a28b0b7c2400bc59aba4bcc0a76e971dadd19610d3ad38c768e124dc7","schema_version":"edge-lab-recorder.raw.v1","sequence":null,"source":"clob_market_ws"}
{"event_at":"2026-07-28T03:07:41.406000Z","event_fingerprint":"65a40ff2a26c70cf10d77aa975dd9ba034e731d6841d82d424b57ce2436e9895","payload":{"connection_id":"a6b55582af5f430fb37ad02bf0922475","event_at":"2026-07-28T03:07:41.406000Z","event_type":"price_change","frame_hash":"89fd5a53019892c9c5822ba0f6b5ea95ae8865b276e0d3384bc7e1259a26d668","frame_index":0,"kind":"data","monotonic_ns":310048976368333,"payload":{"event_type":"price_change","market":"0x779291bef19b6709f61e9764a954aafe9ffae488d50ae674aabdcb4f248006d5","price_changes":[{"asset_id":"14965588658799411272385430903075831224615961675357217884735713260981483529984","best_ask":"0.5","best_bid":"0.49","hash":"e8f815a124830f2c997ff3d480e99a6f5fd6c284","price":"0.32","side":"BUY","size":"225.8"},{"asset_id":"8761897749749422724209054078244794145777693856614463256546737399611489089783","best_ask":"0.51","best_bid":"0.5","hash":"6b9a2e31732fe10d5b69ad6a05879045d3834654","price":"0.68","side":"SELL","size":"225.8"}],"timestamp":"1785208061406"},"payload_hash":"9c9ab5d99c422c6200cc25ce9d39c1f686e72240c907b7c46bc9639d0014c6e6","raw_frame":"{\"market\":\"0x779291bef19b6709f61e9764a954aafe9ffae488d50ae674aabdcb4f248006d5\", \"price_changes\":[{\"asset_id\":\"14965588658799411272385430903075831224615961675357217884735713260981483529984\", \"price\":\"0.32\", \"size\":\"225.8\", \"side\":\"BUY\", \"hash\":\"e8f815a124830f2c997ff3d480e99a6f5fd6c284\", \"best_bid\":\"0.49\", \"best_ask\":\"0.5\"}, {\"asset_id\":\"8761897749749422724209054078244794145777693856614463256546737399611489089783\", \"price\":\"0.68\", \"size\":\"225.8\", \"side\":\"SELL\", \"hash\":\"6b9a2e31732fe10d5b69ad6a05879045d3834654\", \"best_bid\":\"0.5\", \"best_ask\":\"0.51\"}], \"timestamp\":\"1785208061406\", \"event_type\":\"price_change\"}","received_at":"2026-07-28T03:07:45.944222Z","schema_version":"clob-market-ws.price_change.v1","sequence":null,"server_hash":null,"server_timestamp":"1785208061406","session_id":"3e519d9098404c15b234d96025eb1a2b","source":"clob_market_ws"},"received_at":"2026-07-28T03:07:45.944222Z","record_id":"e5cceee3b24a436077df151ea593e90dcfff9cf565303748ddb3b176505585ee","schema_fingerprint":"4aa3821a28b0b7c2400bc59aba4bcc0a76e971dadd19610d3ad38c768e124dc7","schema_version":"edge-lab-recorder.raw.v1","sequence":null,"source":"clob_market_ws"}
{"event_at":"2026-07-28T03:07:41.408000Z","event_fingerprint":"1288fe1b6907346a28fb815280ba661e357651ad4876359bc73331717588ee33","payload":{"connection_id":"a6b55582af5f430fb37ad02bf0922475","event_at":"2026-07-28T03:07:41.408000Z","event_type":"price_change","frame_hash":"b57f1610694d38e5933054dc2cfc31cb2fc93f2e0ebb02b3095a72717b78394b","frame_index":0,"kind":"data","monotonic_ns":310048981733750,"payload":{"event_type":"price_change","market":"0x779291bef19b6709f61e9764a954aafe9ffae488d50ae674aabdcb4f248006d5","price_changes":[{"asset_id":"8761897749749422724209054078244794145777693856614463256546737399611489089783","best_ask":"0.51","best_bid":"0.5","hash":"094ce798333c5f873e01ea9e7ab5fd0d95734662","price":"0.39","side":"BUY","size":"216"},{"asset_id":"14965588658799411272385430903075831224615961675357217884735713260981483529984","best_ask":"0.5","best_bid":"0.49","hash":"e5d2a843493e57d3debecb22e5bdd38c79ddbf47","price":"0.61","side":"SELL","size":"216"}],"timestamp":"1785208061408"},"payload_hash":"268cb3e6ed3bae77a18fb02e6e02bc86d53a4a13edf5f7470df18084ce245714","raw_frame":"{\"market\":\"0x779291bef19b6709f61e9764a954aafe9ffae488d50ae674aabdcb4f248006d5\", \"price_changes\":[{\"asset_id\":\"8761897749749422724209054078244794145777693856614463256546737399611489089783\", \"price\":\"0.39\", \"size\":\"216\", \"side\":\"BUY\", \"hash\":\"094ce798333c5f873e01ea9e7ab5fd0d95734662\", \"best_bid\":\"0.5\", \"best_ask\":\"0.51\"}, {\"asset_id\":\"14965588658799411272385430903075831224615961675357217884735713260981483529984\", \"price\":\"0.61\", \"size\":\"216\", \"side\":\"SELL\", \"hash\":\"e5d2a843493e57d3debecb22e5bdd38c79ddbf47\", \"best_bid\":\"0.49\", \"best_ask\":\"0.5\"}], \"timestamp\":\"1785208061408\", \"event_type\":\"price_change\"}","received_at":"2026-07-28T03:07:45.949586Z","schema_version":"clob-market-ws.price_change.v1","sequence":null,"server_hash":null,"server_timestamp":"1785208061408","session_id":"3e519d9098404c15b234d96025eb1a2b","source":"clob_market_ws"},"received_at":"2026-07-28T03:07:45.949586Z","record_id":"cf1ef20c3e67710e43da8104e5e502882dc581fd16040ed32dff0c45411524d2","schema_fingerprint":"4aa3821a28b0b7c2400bc59aba4bcc0a76e971dadd19610d3ad38c768e124dc7","schema_version":"edge-lab-recorder.raw.v1","sequence":null,"source":"clob_market_ws"}
{"event_at":"2026-07-28T03:07:41.409000Z","event_fingerprint":"79eaaf11b8f1046b0be98bb4adfbae6b6ffc3e4e1863ca98452500890ef833db","payload":{"connection_id":"a6b55582af5f430fb37ad02bf0922475","event_at":"2026-07-28T03:07:41.409000Z","event_type":"price_change","frame_hash":"37b532be5592a14fca3c26e4edccf2d45b9f500e3ead5f3bc3ef2c0b1a3303ed","frame_index":0,"kind":"data","monotonic_ns":310048988151791,"payload":{"event_type":"price_change","market":"0x779291bef19b6709f61e9764a954aafe9ffae488d50ae674aabdcb4f248006d5","price_changes":[{"asset_id":"8761897749749422724209054078244794145777693856614463256546737399611489089783","best_ask":"0.51","best_bid":"0.5","hash":"34e2351f08f01b7b268849a836fbcae7b7488d88","price":"0.5","side":"BUY","size":"82.6"},{"asset_id":"14965588658799411272385430903075831224615961675357217884735713260981483529984","best_ask":"0.5","best_bid":"0.49","hash":"b2b950b11c9b3318f388b845e5f95c0a96cd50e3","price":"0.5","side":"SELL","size":"82.6"}],"timestamp":"1785208061409"},"payload_hash":"5c47176cb91a63b4f0aa859baaf21b00047fea1491b15d3c4542147200775aa0","raw_frame":"{\"market\":\"0x779291bef19b6709f61e9764a954aafe9ffae488d50ae674aabdcb4f248006d5\", \"price_changes\":[{\"asset_id\":\"8761897749749422724209054078244794145777693856614463256546737399611489089783\", \"price\":\"0.5\", \"size\":\"82.6\", \"side\":\"BUY\", \"hash\":\"34e2351f08f01b7b268849a836fbcae7b7488d88\", \"best_bid\":\"0.5\", \"best_ask\":\"0.51\"}, {\"asset_id\":\"14965588658799411272385430903075831224615961675357217884735713260981483529984\", \"price\":\"0.5\", \"size\":\"82.6\", \"side\":\"SELL\", \"hash\":\"b2b950b11c9b3318f388b845e5f95c0a96cd50e3\", \"best_bid\":\"0.49\", \"best_ask\":\"0.5\"}], \"timestamp\":\"1785208061409\", \"event_type\":\"price_change\"}","received_at":"2026-07-28T03:07:45.956005Z","schema_version":"clob-market-ws.price_change.v1","sequence":null,"server_hash":null,"server_timestamp":"1785208061409","session_id":"3e519d9098404c15b234d96025eb1a2b","source":"clob_market_ws"},"received_at":"2026-07-28T03:07:45.956005Z","record_id":"e88eafa14e60f864bf09885ef4e18279b251f0949dd03dbc81e09b7d05dca241","schema_fingerprint":"4aa3821a28b0b7c2400bc59aba4bcc0a76e971dadd19610d3ad38c768e124dc7","schema_version":"edge-lab-recorder.raw.v1","sequence":null,"source":"clob_market_ws"}
{"event_at":"2026-07-28T03:07:41.411000Z","event_fingerprint":"8160b07be93d231e35fa40be2d862d3332f0d887ba4cf1ee3289112dd3a154c5","payload":{"connection_id":"a6b55582af5f430fb37ad02bf0922475","event_at":"2026-07-28T03:07:41.411000Z","event_type":"price_change","frame_hash":"64d19867a07d9964b27f97bea484ebaedcc64cb0037cdc3cf4e0b4963c01d9c6","frame_index":0,"kind":"data","monotonic_ns":310048993469583,"payload":{"event_type":"price_change","market":"0x779291bef19b6709f61e9764a954aafe9ffae488d50ae674aabdcb4f248006d5","price_changes":[{"asset_id":"8761897749749422724209054078244794145777693856614463256546737399611489089783","best_ask":"0.51","best_bid":"0.5","hash":"a6b0431266d631732e7ff63be3fe6f7bc6150c66","price":"0.49","side":"BUY","size":"81"},{"asset_id":"14965588658799411272385430903075831224615961675357217884735713260981483529984","best_ask":"0.5","best_bid":"0.49","hash":"963d12339045d52882269963ca239257cafb0d21","price":"0.51","side":"SELL","size":"81"}],"timestamp":"1785208061411"},"payload_hash":"65c2b7869b4d964337149f97bc3bb8b1500413fb7fb3a7d6fd6306b7954bb996","raw_frame":"{\"market\":\"0x779291bef19b6709f61e9764a954aafe9ffae488d50ae674aabdcb4f248006d5\", \"price_changes\":[{\"asset_id\":\"8761897749749422724209054078244794145777693856614463256546737399611489089783\", \"price\":\"0.49\", \"size\":\"81\", \"side\":\"BUY\", \"hash\":\"a6b0431266d631732e7ff63be3fe6f7bc6150c66\", \"best_bid\":\"0.5\", \"best_ask\":\"0.51\"}, {\"asset_id\":\"14965588658799411272385430903075831224615961675357217884735713260981483529984\", \"price\":\"0.51\", \"size\":\"81\", \"side\":\"SELL\", \"hash\":\"963d12339045d52882269963ca239257cafb0d21\", \"best_bid\":\"0.49\", \"best_ask\":\"0.5\"}], \"timestamp\":\"1785208061411\", \"event_type\":\"price_change\"}","received_at":"2026-07-28T03:07:45.961322Z","schema_version":"clob-market-ws.price_change.v1","sequence":null,"server_hash":null,"server_timestamp":"1785208061411","session_id":"3e519d9098404c15b234d96025eb1a2b","source":"clob_market_ws"},"received_at":"2026-07-28T03:07:45.961322Z","record_id":"bce75f3b8e9a90adee53717950f4f800c15fe727b9d4ec96bf43b0e833062f7e","schema_fingerprint":"4aa3821a28b0b7c2400bc59aba4bcc0a76e971dadd19610d3ad38c768e124dc7","schema_version":"edge-lab-recorder.raw.v1","sequence":null,"source":"clob_market_ws"}
{"event_at":"2026-07-28T03:07:41.417000Z","event_fingerprint":"3b2bcc175b492212171669b2582e79a00cfd5fe9f325a995485f53db7c246b9f","payload":{"connection_id":"a6b55582af5f430fb37ad02bf0922475","event_at":"2026-07-28T03:07:41.417000Z","event_type":"price_change","frame_hash":"c6bbd420420273877a62d035bf952985355b274b292eb6435a7641de2b9c4cfe","frame_index":0,"kind":"data","monotonic_ns":310048996271625,"payload":{"event_type":"price_change","market":"0x779291bef19b6709f61e9764a954aafe9ffae488d50ae674aabdcb4f248006d5","price_changes":[{"asset_id":"14965588658799411272385430903075831224615961675357217884735713260981483529984","best_ask":"0.5","best_bid":"0.49","hash":"6fde005a3ea6ef9c5b93b0cbc2bf476d892cba2c","price":"0.48","side":"BUY","size":"510.2"},{"asset_id":"8761897749749422724209054078244794145777693856614463256546737399611489089783","best_ask":"0.51","best_bid":"0.5","hash":"95ea5bbfab176a8dc2ffd304f7b461c979815645","price":"0.52","side":"SELL","size":"510.2"}],"timestamp":"1785208061417"},"payload_hash":"7f026d03667a8d8e190824a418e5a26342b1be8c8b4dd6f4b2eb5cf5b5cbfa67","raw_frame":"{\"market\":\"0x779291bef19b6709f61e9764a954aafe9ffae488d50ae674aabdcb4f248006d5\", \"price_changes\":[{\"asset_id\":\"14965588658799411272385430903075831224615961675357217884735713260981483529984\", \"price\":\"0.48\", \"size\":\"510.2\", \"side\":\"BUY\", \"hash\":\"6fde005a3ea6ef9c5b93b0cbc2bf476d892cba2c\", \"best_bid\":\"0.49\", \"best_ask\":\"0.5\"}, {\"asset_id\":\"8761897749749422724209054078244794145777693856614463256546737399611489089783\", \"price\":\"0.52\", \"size\":\"510.2\", \"side\":\"SELL\", \"hash\":\"95ea5bbfab176a8dc2ffd304f7b461c979815645\", \"best_bid\":\"0.5\", \"best_ask\":\"0.51\"}], \"timestamp\":\"1785208061417\", \"event_type\":\"price_change\"}","received_at":"2026-07-28T03:07:45.964124Z","schema_version":"clob-market-ws.price_change.v1","sequence":null,"server_hash":null,"server_timestamp":"1785208061417","session_id":"3e519d9098404c15b234d96025eb1a2b","source":"clob_market_ws"},"received_at":"2026-07-28T03:07:45.964124Z","record_id":"8664562f73ee40cc8495079c728b85cca11e0f9ca72e64080c9a148143d66e5a","schema_fingerprint":"4aa3821a28b0b7c2400bc59aba4bcc0a76e971dadd19610d3ad38c768e124dc7","schema_version":"edge-lab-recorder.raw.v1","sequence":null,"source":"clob_market_ws"}
{"event_at":"2026-07-28T03:07:41.421000Z","event_fingerprint":"93b4900c7c7a677377f6a036f628e60aeb6449994a58b442b9ede7524e34050e","payload":{"connection_id":"a6b55582af5f430fb37ad02bf0922475","event_at":"2026-07-28T03:07:41.421000Z","event_type":"price_change","frame_hash":"0021c360ebef60bee173a8230eab0a273b058fef893ef05e7028b16087c990a6","frame_index":0,"kind":"data","monotonic_ns":310048999254583,"payload":{"event_type":"price_change","market":"0x779291bef19b6709f61e9764a954aafe9ffae488d50ae674aabdcb4f248006d5","price_changes":[{"asset_id":"14965588658799411272385430903075831224615961675357217884735713260981483529984","best_ask":"0.5","best_bid":"0.49","hash":"77db0f4d44d25533ccb93622dbb9dc76164ee9ee","price":"0.48","side":"BUY","size":"497.6"},{"asset_id":"8761897749749422724209054078244794145777693856614463256546737399611489089783","best_ask":"0.51","best_bid":"0.5","hash":"154a552e3bcedacc419775559e3d3aed92a73bc8","price":"0.52","side":"SELL","size":"497.6"}],"timestamp":"1785208061421"},"payload_hash":"f74f2c17d180011957c35e05a87d474a20d7a91143eb7244e13eba0d7128ba2d","raw_frame":"{\"market\":\"0x779291bef19b6709f61e9764a954aafe9ffae488d50ae674aabdcb4f248006d5\", \"price_changes\":[{\"asset_id\":\"14965588658799411272385430903075831224615961675357217884735713260981483529984\", \"price\":\"0.48\", \"size\":\"497.6\", \"side\":\"BUY\", \"hash\":\"77db0f4d44d25533ccb93622dbb9dc76164ee9ee\", \"best_bid\":\"0.49\", \"best_ask\":\"0.5\"}, {\"asset_id\":\"8761897749749422724209054078244794145777693856614463256546737399611489089783\", \"price\":\"0.52\", \"size\":\"497.6\", \"side\":\"SELL\", \"hash\":\"154a552e3bcedacc419775559e3d3aed92a73bc8\", \"best_bid\":\"0.5\", \"best_ask\":\"0.51\"}], \"timestamp\":\"1785208061421\", \"event_type\":\"price_change\"}","received_at":"2026-07-28T03:07:45.967108Z","schema_version":"clob-market-ws.price_change.v1","sequence":null,"server_hash":null,"server_timestamp":"1785208061421","session_id":"3e519d9098404c15b234d96025eb1a2b","source":"clob_market_ws"},"received_at":"2026-07-28T03:07:45.967108Z","record_id":"e218187b3840fa155cc8efcd6847c42033d58d85c65417d2c566310ee630949e","schema_fingerprint":"4aa3821a28b0b7c2400bc59aba4bcc0a76e971dadd19610d3ad38c768e124dc7","schema_version":"edge-lab-recorder.raw.v1","sequence":null,"source":"clob_market_ws"}
{"event_at":"2026-07-28T03:07:41.431000Z","event_fingerprint":"a51fd2aefeb14a96cedfd366cbc1bd5e20b3400deb5b1297b9073d49cebea110","payload":{"connection_id":"a6b55582af5f430fb37ad02bf0922475","event_at":"2026-07-28T03:07:41.431000Z","event_type":"price_change","frame_hash":"e5497eed6298bcaee976f0c2db1614fec080a5b655dcc5777c2e0d0d122635d8","frame_index":0,"kind":"data","monotonic_ns":310049002264083,"payload":{"event_type":"price_change","market":"0x779291bef19b6709f61e9764a954aafe9ffae488d50ae674aabdcb4f248006d5","price_changes":[{"asset_id":"14965588658799411272385430903075831224615961675357217884735713260981483529984","best_ask":"0.5","best_bid":"0.49","hash":"8eed962e8d73979d1159d3e3f6aca030072d7654","price":"0.48","side":"BUY","size":"472.6"},{"asset_id":"8761897749749422724209054078244794145777693856614463256546737399611489089783","best_ask":"0.51","best_bid":"0.5","hash":"8b1b9a6af2701ccf748d34c0980d6a230ff9ba45","price":"0.52","side":"SELL","size":"472.6"}],"timestamp":"1785208061431"},"payload_hash":"35e1cbd5356d4c0653c3c50e2ca5bb09b223bd1d76e37cf3c4bf6c046127f58d","raw_frame":"{\"market\":\"0x779291bef19b6709f61e9764a954aafe9ffae488d50ae674aabdcb4f248006d5\", \"price_changes\":[{\"asset_id\":\"14965588658799411272385430903075831224615961675357217884735713260981483529984\", \"price\":\"0.48\", \"size\":\"472.6\", \"side\":\"BUY\", \"hash\":\"8eed962e8d73979d1159d3e3f6aca030072d7654\", \"best_bid\":\"0.49\", \"best_ask\":\"0.5\"}, {\"asset_id\":\"8761897749749422724209054078244794145777693856614463256546737399611489089783\", \"price\":\"0.52\", \"size\":\"472.6\", \"side\":\"SELL\", \"hash\":\"8b1b9a6af2701ccf748d34c0980d6a230ff9ba45\", \"best_bid\":\"0.5\", \"best_ask\":\"0.51\"}], \"timestamp\":\"1785208061431\", \"event_type\":\"price_change\"}","received_at":"2026-07-28T03:07:45.970118Z","schema_version":"clob-market-ws.price_change.v1","sequence":null,"server_hash":null,"server_timestamp":"1785208061431","session_id":"3e519d9098404c15b234d96025eb1a2b","source":"clob_market_ws"},"received_at":"2026-07-28T03:07:45.970118Z","record_id":"55055a6c27ea3fe150306c61d2038c2dc0f293bb9996eeed19e9a2b658377399","schema_fingerprint":"4aa3821a28b0b7c2400bc59aba4bcc0a76e971dadd19610d3ad38c768e124dc7","schema_version":"edge-lab-recorder.raw.v1","sequence":null,"source":"clob_market_ws"}
{"event_at":"2026-07-28T03:07:41.431000Z","event_fingerprint":"2e4bbf049f62771d9e9714f48feb86c9c092a222dd7649fdb54e37e2ec0c2ceb","payload":{"connection_id":"a6b55582af5f430fb37ad02bf0922475","event_at":"2026-07-28T03:07:41.431000Z","event_type":"price_change","frame_hash":"2190664768e14cf3768f206a2bd317b624c3109ec6a7d88f7ebf14a8509eddd8","frame_index":0,"kind":"data","monotonic_ns":310049005227833,"payload":{"event_type":"price_change","market":"0x779291bef19b6709f61e9764a954aafe9ffae488d50ae674aabdcb4f248006d5","price_changes":[{"asset_id":"8761897749749422724209054078244794145777693856614463256546737399611489089783","best_ask":"0.51","best_bid":"0.5","hash":"bb667bc51be096f2b37aeabb32edbd9b44d41a1a","price":"0.52","side":"SELL","size":"447.6"},{"asset_id":"14965588658799411272385430903075831224615961675357217884735713260981483529984","best_ask":"0.5","best_bid":"0.49","hash":"149ca0fcd6a391a6e16af75b61d38d58cf3fcb87","price":"0.48","side":"BUY","size":"447.6"}],"timestamp":"1785208061431"},"payload_hash":"fadc7166faced7a9ef8eab149af7f99cd2b62c3efe42c2a670d7b677ae3392ad","raw_frame":"{\"market\":\"0x779291bef19b6709f61e9764a954aafe9ffae488d50ae674aabdcb4f248006d5\", \"price_changes\":[{\"asset_id\":\"8761897749749422724209054078244794145777693856614463256546737399611489089783\", \"price\":\"0.52\", \"size\":\"447.6\", \"side\":\"SELL\", \"hash\":\"bb667bc51be096f2b37aeabb32edbd9b44d41a1a\", \"best_bid\":\"0.5\", \"best_ask\":\"0.51\"}, {\"asset_id\":\"14965588658799411272385430903075831224615961675357217884735713260981483529984\", \"price\":\"0.48\", \"size\":\"447.6\", \"side\":\"BUY\", \"hash\":\"149ca0fcd6a391a6e16af75b61d38d58cf3fcb87\", \"best_bid\":\"0.49\", \"best_ask\":\"0.5\"}], \"timestamp\":\"1785208061431\", \"event_type\":\"price_change\"}","received_at":"2026-07-28T03:07:45.973081Z","schema_version":"clob-market-ws.price_change.v1","sequence":null,"server_hash":null,"server_timestamp":"1785208061431","session_id":"3e519d9098404c15b234d96025eb1a2b","source":"clob_market_ws"},"received_at":"2026-07-28T03:07:45.973081Z","record_id":"75ed2e43e67ee27bd00c55516e92862a383651152640bb1e6cd9c24b15da98ea","schema_fingerprint":"4aa3821a28b0b7c2400bc59aba4bcc0a76e971dadd19610d3ad38c768e124dc7","schema_version":"edge-lab-recorder.raw.v1","sequence":null,"source":"clob_market_ws"}
{"event_at":"2026-07-28T03:07:41.437000Z","event_fingerprint":"61aa6cf2b2f3a87229c1e136c56808856b84406158e00e8375f06b4566d02216","payload":{"connection_id":"a6b55582af5f430fb37ad02bf0922475","event_at":"2026-07-28T03:07:41.437000Z","event_type":"price_change","frame_hash":"b4ff5a387670aac3643d452f53faa3d218572a70bf59b819c8563e947eeafbd6","frame_index":0,"kind":"data","monotonic_ns":310049008147958,"payload":{"event_type":"price_change","market":"0x779291bef19b6709f61e9764a954aafe9ffae488d50ae674aabdcb4f248006d5","price_changes":[{"asset_id":"14965588658799411272385430903075831224615961675357217884735713260981483529984","best_ask":"0.5","best_bid":"0.49","hash":"c176e1aab906406a7da675f5e16da8ea6570bc62","price":"0.46","side":"BUY","size":"77.6"},{"asset_id":"8761897749749422724209054078244794145777693856614463256546737399611489089783","best_ask":"0.51","best_bid":"0.5","hash":"7513dd369ada906b9ac5766b9b81dd11b26f3db1","price":"0.54","side":"SELL","size":"77.6"}],"timestamp":"1785208061437"},"payload_hash":"e5f90de1355f5576e75e533d45e5693e46027699e6fb89a1f7aa470b2c3b1706","raw_frame":"{\"market\":\"0x779291bef19b6709f61e9764a954aafe9ffae488d50ae674aabdcb4f248006d5\", \"price_changes\":[{\"asset_id\":\"14965588658799411272385430903075831224615961675357217884735713260981483529984\", \"price\":\"0.46\", \"size\":\"77.6\", \"side\":\"BUY\", \"hash\":\"c176e1aab906406a7da675f5e16da8ea6570bc62\", \"best_bid\":\"0.49\", \"best_ask\":\"0.5\"}, {\"asset_id\":\"8761897749749422724209054078244794145777693856614463256546737399611489089783\", \"price\":\"0.54\", \"size\":\"77.6\", \"side\":\"SELL\", \"hash\":\"7513dd369ada906b9ac5766b9b81dd11b26f3db1\", \"best_bid\":\"0.5\", \"best_ask\":\"0.51\"}], \"timestamp\":\"1785208061437\", \"event_type\":\"price_change\"}","received_at":"2026-07-28T03:07:45.976001Z","schema_version":"clob-market-ws.price_change.v1","sequence":null,"server_hash":null,"server_timestamp":"1785208061437","session_id":"3e519d9098404c15b234d96025eb1a2b","source":"clob_market_ws"},"received_at":"2026-07-28T03:07:45.976001Z","record_id":"5b6156ea689e07eeea6152de4d7938ad5618c499c257b4c0ce48f327a5abb0b6","schema_fingerprint":"4aa3821a28b0b7c2400bc59aba4bcc0a76e971dadd19610d3ad38c768e124dc7","schema_version":"edge-lab-recorder.raw.v1","sequence":null,"source":"clob_market_ws"}
{"event_at":"2026-07-28T03:07:41.438000Z","event_fingerprint":"8f3ef9f39f192ead02d3d6b9c81cfdc82ca039af1725147123750127d98d0b6c","payload":{"connection_id":"a6b55582af5f430fb37ad02bf0922475","event_at":"2026-07-28T03:07:41.438000Z","event_type":"price_change","frame_hash":"ada83aeabb7b4c539ced00e50acd9fb07eaeacfeccb4a09b6058aa29cd7863e3","frame_index":0,"kind":"data","monotonic_ns":310049011095250,"payload":{"event_type":"price_change","market":"0x779291bef19b6709f61e9764a954aafe9ffae488d50ae674aabdcb4f248006d5","price_changes":[{"asset_id":"14965588658799411272385430903075831224615961675357217884735713260981483529984","best_ask":"0.5","best_bid":"0.49","hash":"7172ac83294f6de902951fde54eff7f851543a76","price":"0.33","side":"BUY","size":"236.97"},{"asset_id":"8761897749749422724209054078244794145777693856614463256546737399611489089783","best_ask":"0.51","best_bid":"0.5","hash":"fe514afff22567ca991377df323f451bd45cef28","price":"0.67","side":"SELL","size":"236.97"}],"timestamp":"1785208061438"},"payload_hash":"9574f7c73efac2c3fd12ddeb67295493490bc0feed02c25e7363ea1e8640930b","raw_frame":"{\"market\":\"0x779291bef19b6709f61e9764a954aafe9ffae488d50ae674aabdcb4f248006d5\", \"price_changes\":[{\"asset_id\":\"14965588658799411272385430903075831224615961675357217884735713260981483529984\", \"price\":\"0.33\", \"size\":\"236.97\", \"side\":\"BUY\", \"hash\":\"7172ac83294f6de902951fde54eff7f851543a76\", \"best_bid\":\"0.49\", \"best_ask\":\"0.5\"}, {\"asset_id\":\"8761897749749422724209054078244794145777693856614463256546737399611489089783\", \"price\":\"0.67\", \"size\":\"236.97\", \"side\":\"SELL\", \"hash\":\"fe514afff22567ca991377df323f451bd45cef28\", \"best_bid\":\"0.5\", \"best_ask\":\"0.51\"}], \"timestamp\":\"1785208061438\", \"event_type\":\"price_change\"}","received_at":"2026-07-28T03:07:45.978949Z","schema_version":"clob-market-ws.price_change.v1","sequence":null,"server_hash":null,"server_timestamp":"1785208061438","session_id":"3e519d9098404c15b234d96025eb1a2b","source":"clob_market_ws"},"received_at":"2026-07-28T03:07:45.978949Z","record_id":"61bd96a178727d9ad49b74b756da78611d6208b23b1a0638ec2182151f3239b3","schema_fingerprint":"4aa3821a28b0b7c2400bc59aba4bcc0a76e971dadd19610d3ad38c768e124dc7","schema_version":"edge-lab-recorder.raw.v1","sequence":null,"source":"clob_market_ws"}
{"event_at":"2026-07-28T03:07:41.439000Z","event_fingerprint":"58718668389f3ba7df9abe7b1d188cff482933eeba31dd994c6d28facb50b1fb","payload":{"connection_id":"a6b55582af5f430fb37ad02bf0922475","event_at":"2026-07-28T03:07:41.439000Z","event_type":"price_change","frame_hash":"c619f04c21ccc1c79efca14bf3295f07163640de65324177e4e133521a20f372","frame_index":0,"kind":"data","monotonic_ns":310049014015375,"payload":{"event_type":"price_change","market":"0x779291bef19b6709f61e9764a954aafe9ffae488d50ae674aabdcb4f248006d5","price_changes":[{"asset_id":"14965588658799411272385430903075831224615961675357217884735713260981483529984","best_ask":"0.5","best_bid":"0.49","hash":"77aa5716711180616a9b210f6e41223519e1475f","price":"0.47","side":"BUY","size":"77.6"},{"asset_id":"8761897749749422724209054078244794145777693856614463256546737399611489089783","best_ask":"0.51","best_bid":"0.5","hash":"47655c619e24b2fb77e5e8182d4039030381949a","price":"0.53","side":"SELL","size":"77.6"}],"timestamp":"1785208061439"},"payload_hash":"31dcf3ae1e774da84d522b1fe323745a9670e63215c4338d70da42f00757ffdd","raw_frame":"{\"market\":\"0x779291bef19b6709f61e9764a954aafe9ffae488d50ae674aabdcb4f248006d5\", \"price_changes\":[{\"asset_id\":\"14965588658799411272385430903075831224615961675357217884735713260981483529984\", \"price\":\"0.47\", \"size\":\"77.6\", \"side\":\"BUY\", \"hash\":\"77aa5716711180616a9b210f6e41223519e1475f\", \"best_bid\":\"0.49\", \"best_ask\":\"0.5\"}, {\"asset_id\":\"8761897749749422724209054078244794145777693856614463256546737399611489089783\", \"price\":\"0.53\", \"size\":\"77.6\", \"side\":\"SELL\", \"hash\":\"47655c619e24b2fb77e5e8182d4039030381949a\", \"best_bid\":\"0.5\", \"best_ask\":\"0.51\"}], \"timestamp\":\"1785208061439\", \"event_type\":\"price_change\"}","received_at":"2026-07-28T03:07:45.981869Z","schema_version":"clob-market-ws.price_change.v1","sequence":null,"server_hash":null,"server_timestamp":"1785208061439","session_id":"3e519d9098404c15b234d96025eb1a2b","source":"clob_market_ws"},"received_at":"2026-07-28T03:07:45.981869Z","record_id":"8be46e03b9f9ac862f6890ee3ffdf8a12d4e99c4bb853a29f15f93ca0c4db156","schema_fingerprint":"4aa3821a28b0b7c2400bc59aba4bcc0a76e971dadd19610d3ad38c768e124dc7","schema_version":"edge-lab-recorder.raw.v1","sequence":null,"source":"clob_market_ws"}
{"event_at":"2026-07-28T03:07:41.440000Z","event_fingerprint":"3e827a839ba0a7f99322913f25f27ccc973f8d0f690ceea20c58ef4e6f67d317","payload":{"connection_id":"a6b55582af5f430fb37ad02bf0922475","event_at":"2026-07-28T03:07:41.440000Z","event_type":"price_change","frame_hash":"c1b4bac174bc4d4388063b90f47288d39cbfebad054146066c0f5f53ec6d8b95","frame_index":0,"kind":"data","monotonic_ns":310049016997791,"payload":{"event_type":"price_change","market":"0x779291bef19b6709f61e9764a954aafe9ffae488d50ae674aabdcb4f248006d5","price_changes":[{"asset_id":"14965588658799411272385430903075831224615961675357217884735713260981483529984","best_ask":"0.5","best_bid":"0.49","hash":"1d20b61868c5b8bc65026f81238594f3425b955d","price":"0.39","side":"BUY","size":"299.6"},{"asset_id":"8761897749749422724209054078244794145777693856614463256546737399611489089783","best_ask":"0.51","best_bid":"0.5","hash":"e1a9da75759fd56b9ef8f5902b1afdebcff6a8ea","price":"0.61","side":"SELL","size":"299.6"}],"timestamp":"1785208061440"},"payload_hash":"0e64ecfe914b1fc7ef287ba35938f8eca732734bda8dc838c1a8be3dff0f654e","raw_frame":"{\"market\":\"0x779291bef19b6709f61e9764a954aafe9ffae488d50ae674aabdcb4f248006d5\", \"price_changes\":[{\"asset_id\":\"14965588658799411272385430903075831224615961675357217884735713260981483529984\", \"price\":\"0.39\", \"size\":\"299.6\", \"side\":\"BUY\", \"hash\":\"1d20b61868c5b8bc65026f81238594f3425b955d\", \"best_bid\":\"0.49\", \"best_ask\":\"0.5\"}, {\"asset_id\":\"8761897749749422724209054078244794145777693856614463256546737399611489089783\", \"price\":\"0.61\", \"size\":\"299.6\", \"side\":\"SELL\", \"hash\":\"e1a9da75759fd56b9ef8f5902b1afdebcff6a8ea\", \"best_bid\":\"0.5\", \"best_ask\":\"0.51\"}], \"timestamp\":\"1785208061440\", \"event_type\":\"price_change\"}","received_at":"2026-07-28T03:07:45.984851Z","schema_version":"clob-market-ws.price_change.v1","sequence":null,"server_hash":null,"server_timestamp":"1785208061440","session_id":"3e519d9098404c15b234d96025eb1a2b","source":"clob_market_ws"},"received_at":"2026-07-28T03:07:45.984851Z","record_id":"68968e1bbdb3b92b552af2767205523df2ed0d3874dd9d895dee3a5a6e84a803","schema_fingerprint":"4aa3821a28b0b7c2400bc59aba4bcc0a76e971dadd19610d3ad38c768e124dc7","schema_version":"edge-lab-recorder.raw.v1","sequence":null,"source":"clob_market_ws"}
{"event_at":"2026-07-28T03:07:41.444000Z","event_fingerprint":"f323dca716f097fb75a54f16a3f53c73b35a6928b2edd24627fc894e493df57f","payload":{"connection_id":"a6b55582af5f430fb37ad02bf0922475","event_at":"2026-07-28T03:07:41.444000Z","event_type":"price_change","frame_hash":"218caedb2644e58957aa29c62c0f55f15cfb864654f3ccf8468645b85da95510","frame_index":0,"kind":"data","monotonic_ns":310049019923666,"payload":{"event_type":"price_change","market":"0x779291bef19b6709f61e9764a954aafe9ffae488d50ae674aabdcb4f248006d5","price_changes":[{"asset_id":"8761897749749422724209054078244794145777693856614463256546737399611489089783","best_ask":"0.51","best_bid":"0.5","hash":"7aa37d5a81b47083a504b0fe8aa918d917241671","price":"0.5","side":"BUY","size":"42.6"},{"asset_id":"14965588658799411272385430903075831224615961675357217884735713260981483529984","best_ask":"0.5","best_bid":"0.49","hash":"44c0341bdecf0da3e76bce92bc7fc361491e2cb1","price":"0.5","side":"SELL","size":"42.6"}],"timestamp":"1785208061444"},"payload_hash":"5e7408ca6fff45ce00212fb2488a7838c43d5ebc6e46a34d5fa21b6f9b7409c3","raw_frame":"{\"market\":\"0x779291bef19b6709f61e9764a954aafe9ffae488d50ae674aabdcb4f248006d5\", \"price_changes\":[{\"asset_id\":\"8761897749749422724209054078244794145777693856614463256546737399611489089783\", \"price\":\"0.5\", \"size\":\"42.6\", \"side\":\"BUY\", \"hash\":\"7aa37d5a81b47083a504b0fe8aa918d917241671\", \"best_bid\":\"0.5\", \"best_ask\":\"0.51\"}, {\"asset_id\":\"14965588658799411272385430903075831224615961675357217884735713260981483529984\", \"price\":\"0.5\", \"size\":\"42.6\", \"side\":\"SELL\", \"hash\":\"44c0341bdecf0da3e76bce92bc7fc361491e2cb1\", \"best_bid\":\"0.49\", \"best_ask\":\"0.5\"}], \"timestamp\":\"1785208061444\", \"event_type\":\"price_change\"}","received_at":"2026-07-28T03:07:45.987776Z","schema_version":"clob-market-ws.price_change.v1","sequence":null,"server_hash":null,"server_timestamp":"1785208061444","session_id":"3e519d9098404c15b234d96025eb1a2b","source":"clob_market_ws"},"received_at":"2026-07-28T03:07:45.987776Z","record_id":"706759b1fb09ae9f8e648baae78f39a6d32fc43c23d4ac116142c8ac36fc48ec","schema_fingerprint":"4aa3821a28b0b7c2400bc59aba4bcc0a76e971dadd19610d3ad38c768e124dc7","schema_version":"edge-lab-recorder.raw.v1","sequence":null,"source":"clob_market_ws"}
{"event_at":"2026-07-28T03:07:41.446000Z","event_fingerprint":"6fbace374e1903515e6ffea3d11d88955881e781421b2daed17ef8585f845bde","payload":{"connection_id":"a6b55582af5f430fb37ad02bf0922475","event_at":"2026-07-28T03:07:41.446000Z","event_type":"price_change","frame_hash":"d2ca2c4a3996815245633d2fd1c2c506945b226eb0d87076ff97474d40461174","frame_index":0,"kind":"data","monotonic_ns":310049022835791,"payload":{"event_type":"price_change","market":"0x779291bef19b6709f61e9764a954aafe9ffae488d50ae674aabdcb4f248006d5","price_changes":[{"asset_id":"8761897749749422724209054078244794145777693856614463256546737399611489089783","best_ask":"0.51","best_bid":"0.5","hash":"604427c167eddffba10d978e56d592f045755044","price":"0.48","side":"BUY","size":"195.6"},{"asset_id":"14965588658799411272385430903075831224615961675357217884735713260981483529984","best_ask":"0.5","best_bid":"0.49","hash":"ab04ae791aaf51c60f194fbc6fcbc48ec011e31d","price":"0.52","side":"SELL","size":"195.6"}],"timestamp":"1785208061446"},"payload_hash":"55c0c47b24bf6e25e629bf8ffe7b25d010c80a062fe112c10db67710f233a73d","raw_frame":"{\"market\":\"0x779291bef19b6709f61e9764a954aafe9ffae488d50ae674aabdcb4f248006d5\", \"price_changes\":[{\"asset_id\":\"8761897749749422724209054078244794145777693856614463256546737399611489089783\", \"price\":\"0.48\", \"size\":\"195.6\", \"side\":\"BUY\", \"hash\":\"604427c167eddffba10d978e56d592f045755044\", \"best_bid\":\"0.5\", \"best_ask\":\"0.51\"}, {\"asset_id\":\"14965588658799411272385430903075831224615961675357217884735713260981483529984\", \"price\":\"0.52\", \"size\":\"195.6\", \"side\":\"SELL\", \"hash\":\"ab04ae791aaf51c60f194fbc6fcbc48ec011e31d\", \"best_bid\":\"0.49\", \"best_ask\":\"0.5\"}], \"timestamp\":\"1785208061446\", \"event_type\":\"price_change\"}","received_at":"2026-07-28T03:07:45.990689Z","schema_version":"clob-market-ws.price_change.v1","sequence":null,"server_hash":null,"server_timestamp":"1785208061446","session_id":"3e519d9098404c15b234d96025eb1a2b","source":"clob_market_ws"},"received_at":"2026-07-28T03:07:45.990689Z","record_id":"c63eb2965a27d27b2fe3c536c9373222acdae787f3bab0da2b60471c21da06e5","schema_fingerprint":"4aa3821a28b0b7c2400bc59aba4bcc0a76e971dadd19610d3ad38c768e124dc7","schema_version":"edge-lab-recorder.raw.v1","sequence":null,"source":"clob_market_ws"}
{"event_at":"2026-07-28T03:07:41.448000Z","event_fingerprint":"d5fcc054277f0fdc753afd106c893730aff38a1ca08383a58e53e80eb5c02396","payload":{"connection_id":"a6b55582af5f430fb37ad02bf0922475","event_at":"2026-07-28T03:07:41.448000Z","event_type":"price_change","frame_hash":"13c3d400966a0bb4a437b5e07325d621c6a5d2bc20afc8b9395f7a148e50e3df","frame_index":0,"kind":"data","monotonic_ns":310049025785833,"payload":{"event_type":"price_change","market":"0x779291bef19b6709f61e9764a954aafe9ffae488d50ae674aabdcb4f248006d5","price_changes":[{"asset_id":"14965588658799411272385430903075831224615961675357217884735713260981483529984","best_ask":"0.5","best_bid":"0.49","hash":"7136f66115faaf8d7ccf6837c91afe37e7194f97","price":"0.46","side":"BUY","size":"83.6"},{"asset_id":"8761897749749422724209054078244794145777693856614463256546737399611489089783","best_ask":"0.51","best_bid":"0.5","hash":"4841844f2d2415641ba8a0f1ebeb683c1b544727","price":"0.54","side":"SELL","size":"83.6"}],"timestamp":"1785208061448"},"payload_hash":"332882f7d6d123c93267bac9f62334a5e8f769dc27edb998937967c8e3fe9b93","raw_frame":"{\"market\":\"0x779291bef19b6709f61e9764a954aafe9ffae488d50ae674aabdcb4f248006d5\", \"price_changes\":[{\"asset_id\":\"14965588658799411272385430903075831224615961675357217884735713260981483529984\", \"price\":\"0.46\", \"size\":\"83.6\", \"side\":\"BUY\", \"hash\":\"7136f66115faaf8d7ccf6837c91afe37e7194f97\", \"best_bid\":\"0.49\", \"best_ask\":\"0.5\"}, {\"asset_id\":\"8761897749749422724209054078244794145777693856614463256546737399611489089783\", \"price\":\"0.54\", \"size\":\"83.6\", \"side\":\"SELL\", \"hash\":\"4841844f2d2415641ba8a0f1ebeb683c1b544727\", \"best_bid\":\"0.5\", \"best_ask\":\"0.51\"}], \"timestamp\":\"1785208061448\", \"event_type\":\"price_change\"}","received_at":"2026-07-28T03:07:45.993638Z","schema_version":"clob-market-ws.price_change.v1","sequence":null,"server_hash":null,"server_timestamp":"1785208061448","session_id":"3e519d9098404c15b234d96025eb1a2b","source":"clob_market_ws"},"received_at":"2026-07-28T03:07:45.993638Z","record_id":"303187751b1a13b7744246621d89daab2d3c585fda7caa5719a530fbc6054106","schema_fingerprint":"4aa3821a28b0b7c2400bc59aba4bcc0a76e971dadd19610d3ad38c768e124dc7","schema_version":"edge-lab-recorder.raw.v1","sequence":null,"source":"clob_market_ws"}
{"event_at":"2026-07-28T03:07:41.451000Z","event_fingerprint":"b35c929b1878ae988cf363e3e545dc2cbf5203d5d59d60d6015a9d17c76cad1f","payload":{"connection_id":"a6b55582af5f430fb37ad02bf0922475","event_at":"2026-07-28T03:07:41.451000Z","event_type":"price_change","frame_hash":"d2e55e4232eec82a18ca912c5e562d266fa5dfb651ae7f762f042773ee1c285c","frame_index":0,"kind":"data","monotonic_ns":310049028727541,"payload":{"event_type":"price_change","market":"0x779291bef19b6709f61e9764a954aafe9ffae488d50ae674aabdcb4f248006d5","price_changes":[{"asset_id":"14965588658799411272385430903075831224615961675357217884735713260981483529984","best_ask":"0.5","best_bid":"0.49","hash":"b56b9504bc3aa4f5e966f71795dc986f0cfb446d","price":"0.53","side":"SELL","size":"142.6"},{"asset_id":"8761897749749422724209054078244794145777693856614463256546737399611489089783","best_ask":"0.51","best_bid":"0.5","hash":"55d46b5f71d996c109a062c759a570c21e11d868","price":"0.47","side":"BUY","size":"142.6"}],"timestamp":"1785208061451"},"payload_hash":"af8e73c1d2c8fbab436670fe566d9d3ce56ec11f5d5428bdf69df67a13233b8a","raw_frame":"{\"market\":\"0x779291bef19b6709f61e9764a954aafe9ffae488d50ae674aabdcb4f248006d5\", \"price_changes\":[{\"asset_id\":\"14965588658799411272385430903075831224615961675357217884735713260981483529984\", \"price\":\"0.53\", \"size\":\"142.6\", \"side\":\"SELL\", \"hash\":\"b56b9504bc3aa4f5e966f71795dc986f0cfb446d\", \"best_bid\":\"0.49\", \"best_ask\":\"0.5\"}, {\"asset_id\":\"8761897749749422724209054078244794145777693856614463256546737399611489089783\", \"price\":\"0.47\", \"size\":\"142.6\", \"side\":\"BUY\", \"hash\":\"55d46b5f71d996c109a062c759a570c21e11d868\", \"best_bid\":\"0.5\", \"best_ask\":\"0.51\"}], \"timestamp\":\"1785208061451\", \"event_type\":\"price_change\"}","received_at":"2026-07-28T03:07:45.996580Z","schema_version":"clob-market-ws.price_change.v1","sequence":null,"server_hash":null,"server_timestamp":"1785208061451","session_id":"3e519d9098404c15b234d96025eb1a2b","source":"clob_market_ws"},"received_at":"2026-07-28T03:07:45.996580Z","record_id":"8f175920165ebc6fb118eadad711ad84a60f0866430d3a17c6ca26e40599a970","schema_fingerprint":"4aa3821a28b0b7c2400bc59aba4bcc0a76e971dadd19610d3ad38c768e124dc7","schema_version":"edge-lab-recorder.raw.v1","sequence":null,"source":"clob_market_ws"}
{"event_at":"2026-07-28T03:07:41.454000Z","event_fingerprint":"c3ceb8fd966eefcf590ba129257045a7726a344032d2d37a348b6b41cf052df4","payload":{"connection_id":"a6b55582af5f430fb37ad02bf0922475","event_at":"2026-07-28T03:07:41.454000Z","event_type":"price_change","frame_hash":"bb72d59ce5df86c247a5a2182ae2fb483fce6ac89961eae25c640da2b2c6cc79","frame_index":0,"kind":"data","monotonic_ns":310049031673166,"payload":{"event_type":"price_change","market":"0x779291bef19b6709f61e9764a954aafe9ffae488d50ae674aabdcb4f248006d5","price_changes":[{"asset_id":"14965588658799411272385430903075831224615961675357217884735713260981483529984","best_ask":"0.5","best_bid":"0.49","hash":"8e5c579d0b21029e17ca4dd89e65da6b9df63926","price":"0.49","side":"BUY","size":"80"},{"asset_id":"8761897749749422724209054078244794145777693856614463256546737399611489089783","best_ask":"0.51","best_bid":"0.5","hash":"b311363888f371926dad50f480f57cfc657cd577","price":"0.51","side":"SELL","size":"80"}],"timestamp":"1785208061454"},"payload_hash":"dcebcb207127224e37db576df826371142c7e0ee523e4c3dcc5466aa644b36d1","raw_frame":"{\"market\":\"0x779291bef19b6709f61e9764a954aafe9ffae488d50ae674aabdcb4f248006d5\", \"price_changes\":[{\"asset_id\":\"14965588658799411272385430903075831224615961675357217884735713260981483529984\", \"price\":\"0.49\", \"size\":\"80\", \"side\":\"BUY\", \"hash\":\"8e5c579d0b21029e17ca4dd89e65da6b9df63926\", \"best_bid\":\"0.49\", \"best_ask\":\"0.5\"}, {\"asset_id\":\"8761897749749422724209054078244794145777693856614463256546737399611489089783\", \"price\":\"0.51\", \"size\":\"80\", \"side\":\"SELL\", \"hash\":\"b311363888f371926dad50f480f57cfc657cd577\", \"best_bid\":\"0.5\", \"best_ask\":\"0.51\"}], \"timestamp\":\"1785208061454\", \"event_type\":\"price_change\"}","received_at":"2026-07-28T03:07:45.999527Z","schema_version":"clob-market-ws.price_change.v1","sequence":null,"server_hash":null,"server_timestamp":"1785208061454","session_id":"3e519d9098404c15b234d96025eb1a2b","source":"clob_market_ws"},"received_at":"2026-07-28T03:07:45.999527Z","record_id":"81254b6f30caad56d21fbeb145f9ef18e56c4341b3ce6737f5bef26b4a59e2ac","schema_fingerprint":"4aa3821a28b0b7c2400bc59aba4bcc0a76e971dadd19610d3ad38c768e124dc7","schema_version":"edge-lab-recorder.raw.v1","sequence":null,"source":"clob_market_ws"}
{"event_at":"2026-07-28T03:07:41.455000Z","event_fingerprint":"850c325ed6426055986edfc6497409067834c3a1c004aac883d8b5ea3b77e47b","payload":{"connection_id":"a6b55582af5f430fb37ad02bf0922475","event_at":"2026-07-28T03:07:41.455000Z","event_type":"price_change","frame_hash":"43e95cdecb614355ddd1af13f8cb597dd1a2b9e818a45ea07e325c5b3f64b6b0","frame_index":0,"kind":"data","monotonic_ns":310049034570708,"payload":{"event_type":"price_change","market":"0x779291bef19b6709f61e9764a954aafe9ffae488d50ae674aabdcb4f248006d5","price_changes":[{"asset_id":"8761897749749422724209054078244794145777693856614463256546737399611489089783","best_ask":"0.51","best_bid":"0.5","hash":"3048e1f4e909f0465926d5a40b359e2c7e5e9504","price":"0.03","side":"BUY","size":"653.1"},{"asset_id":"14965588658799411272385430903075831224615961675357217884735713260981483529984","best_ask":"0.5","best_bid":"0.49","hash":"7533af1c93bb0cd920f159372182ef2142b559e1","price":"0.97","side":"SELL","size":"653.1"}],"timestamp":"1785208061455"},"payload_hash":"3ac7dc52097790b13a4b205ba7fbfa6a9f7702de730eda7be7413a06d33bd5be","raw_frame":"{\"market\":\"0x779291bef19b6709f61e9764a954aafe9ffae488d50ae674aabdcb4f248006d5\", \"price_changes\":[{\"asset_id\":\"8761897749749422724209054078244794145777693856614463256546737399611489089783\", \"price\":\"0.03\", \"size\":\"653.1\", \"side\":\"BUY\", \"hash\":\"3048e1f4e909f0465926d5a40b359e2c7e5e9504\", \"best_bid\":\"0.5\", \"best_ask\":\"0.51\"}, {\"asset_id\":\"14965588658799411272385430903075831224615961675357217884735713260981483529984\", \"price\":\"0.97\", \"size\":\"653.1\", \"side\":\"SELL\", \"hash\":\"7533af1c93bb0cd920f159372182ef2142b559e1\", \"best_bid\":\"0.49\", \"best_ask\":\"0.5\"}], \"timestamp\":\"1785208061455\", \"event_type\":\"price_change\"}","received_at":"2026-07-28T03:07:46.002423Z","schema_version":"clob-market-ws.price_change.v1","sequence":null,"server_hash":null,"server_timestamp":"1785208061455","session_id":"3e519d9098404c15b234d96025eb1a2b","source":"clob_market_ws"},"received_at":"2026-07-28T03:07:46.002423Z","record_id":"f9ce2ae3dcbd6891e7022eafd602b2b899b26626ad9e279615d7d1a00cdbc88f","schema_fingerprint":"4aa3821a28b0b7c2400bc59aba4bcc0a76e971dadd19610d3ad38c768e124dc7","schema_version":"edge-lab-recorder.raw.v1","sequence":null,"source":"clob_market_ws"}
{"event_at":"2026-07-28T03:07:41.456000Z","event_fingerprint":"c95dd3150f818bc1e7d9bf5ecac85823d6c4780f2fa7f0710aa23ac4c58185ee","payload":{"connection_id":"a6b55582af5f430fb37ad02bf0922475","event_at":"2026-07-28T03:07:41.456000Z","event_type":"price_change","frame_hash":"d81725637e962cfad4ed29ba5882e84cfe83ab8fef09d169975acfccd1734656","frame_index":0,"kind":"data","monotonic_ns":310049037470416,"payload":{"event_type":"price_change","market":"0x779291bef19b6709f61e9764a954aafe9ffae488d50ae674aabdcb4f248006d5","price_changes":[{"asset_id":"8761897749749422724209054078244794145777693856614463256546737399611489089783","best_ask":"0.51","best_bid":"0.5","hash":"a663d35fd3862f0a5cb577932fbb9d3a032bfad3","price":"0.41","side":"BUY","size":"295"},{"asset_id":"14965588658799411272385430903075831224615961675357217884735713260981483529984","best_ask":"0.5","best_bid":"0.49","hash":"24ea59a36264e426afdc23a74c6ff51fb2a7673b","price":"0.59","side":"SELL","size":"295"}],"timestamp":"1785208061456"},"payload_hash":"546089b749495245725c17cdc7c759bb6c55f1af90d384de9e2b9a4e0279907b","raw_frame":"{\"market\":\"0x779291bef19b6709f61e9764a954aafe9ffae488d50ae674aabdcb4f248006d5\", \"price_changes\":[{\"asset_id\":\"8761897749749422724209054078244794145777693856614463256546737399611489089783\", \"price\":\"0.41\", \"size\":\"295\", \"side\":\"BUY\", \"hash\":\"a663d35fd3862f0a5cb577932fbb9d3a032bfad3\", \"best_bid\":\"0.5\", \"best_ask\":\"0.51\"}, {\"asset_id\":\"14965588658799411272385430903075831224615961675357217884735713260981483529984\", \"price\":\"0.59\", \"size\":\"295\", \"side\":\"SELL\", \"hash\":\"24ea59a36264e426afdc23a74c6ff51fb2a7673b\", \"best_bid\":\"0.49\", \"best_ask\":\"0.5\"}], \"timestamp\":\"1785208061456\", \"event_type\":\"price_change\"}","received_at":"2026-07-28T03:07:46.005322Z","schema_version":"clob-market-ws.price_change.v1","sequence":null,"server_hash":null,"server_timestamp":"1785208061456","session_id":"3e519d9098404c15b234d96025eb1a2b","source":"clob_market_ws"},"received_at":"2026-07-28T03:07:46.005322Z","record_id":"56de758ae4c3889cbbb25b4e4a4b794abbd1cd8d67fdc4b44167b4ac8f23c485","schema_fingerprint":"4aa3821a28b0b7c2400bc59aba4bcc0a76e971dadd19610d3ad38c768e124dc7","schema_version":"edge-lab-recorder.raw.v1","sequence":null,"source":"clob_market_ws"}
{"event_at":"2026-07-28T03:07:41.457000Z","event_fingerprint":"59a141fcfe8797af52d9ded20afcaa9eb5de6e44096badf90230213e519cfa7b","payload":{"connection_id":"a6b55582af5f430fb37ad02bf0922475","event_at":"2026-07-28T03:07:41.457000Z","event_type":"price_change","frame_hash":"fd35e930cc2272e384b20aba5aabf0906932a6f08776e497a3902ef36fc5b415","frame_index":0,"kind":"data","monotonic_ns":310049040366958,"payload":{"event_type":"price_change","market":"0x779291bef19b6709f61e9764a954aafe9ffae488d50ae674aabdcb4f248006d5","price_changes":[{"asset_id":"8761897749749422724209054078244794145777693856614463256546737399611489089783","best_ask":"0.51","best_bid":"0.5","hash":"6ecf624a3d863d2ccb1f92bf0d6320af040b2ef1","price":"0.51","side":"SELL","size":"105"},{"asset_id":"14965588658799411272385430903075831224615961675357217884735713260981483529984","best_ask":"0.5","best_bid":"0.49","hash":"7d9a637507cf27031a209fbb532f783564915287","price":"0.49","side":"BUY","size":"105"}],"timestamp":"1785208061457"},"payload_hash":"60346d9301928328dfad8edcd274f8e1b99f84703d3bc3e9c80f8f0511130eda","raw_frame":"{\"market\":\"0x779291bef19b6709f61e9764a954aafe9ffae488d50ae674aabdcb4f248006d5\", \"price_changes\":[{\"asset_id\":\"8761897749749422724209054078244794145777693856614463256546737399611489089783\", \"price\":\"0.51\", \"size\":\"105\", \"side\":\"SELL\", \"hash\":\"6ecf624a3d863d2ccb1f92bf0d6320af040b2ef1\", \"best_bid\":\"0.5\", \"best_ask\":\"0.51\"}, {\"asset_id\":\"14965588658799411272385430903075831224615961675357217884735713260981483529984\", \"price\":\"0.49\", \"size\":\"105\", \"side\":\"BUY\", \"hash\":\"7d9a637507cf27031a209fbb532f783564915287\", \"best_bid\":\"0.49\", \"best_ask\":\"0.5\"}], \"timestamp\":\"1785208061457\", \"event_type\":\"price_change\"}","received_at":"2026-07-28T03:07:46.008220Z","schema_version":"clob-market-ws.price_change.v1","sequence":null,"server_hash":null,"server_timestamp":"1785208061457","session_id":"3e519d9098404c15b234d96025eb1a2b","source":"clob_market_ws"},"received_at":"2026-07-28T03:07:46.008220Z","record_id":"b9b53da6d357ec9317fac33c00666064bffb8f3411f227804895fed9b39a1cac","schema_fingerprint":"4aa3821a28b0b7c2400bc59aba4bcc0a76e971dadd19610d3ad38c768e124dc7","schema_version":"edge-lab-recorder.raw.v1","sequence":null,"source":"clob_market_ws"}
{"event_at":"2026-07-28T03:07:41.467000Z","event_fingerprint":"670ae82b8ef4f11f28164c7818a18ea9d68716157e8631043108c0922c8f3e54","payload":{"connection_id":"a6b55582af5f430fb37ad02bf0922475","event_at":"2026-07-28T03:07:41.467000Z","event_type":"price_change","frame_hash":"2cf4f15ec76b97be3b56b2fc6e640b90945d3043a7dcd812142df0efb501d409","frame_index":0,"kind":"data","monotonic_ns":310049043324500,"payload":{"event_type":"price_change","market":"0x779291bef19b6709f61e9764a954aafe9ffae488d50ae674aabdcb4f248006d5","price_changes":[{"asset_id":"14965588658799411272385430903075831224615961675357217884735713260981483529984","best_ask":"0.5","best_bid":"0.49","hash":"fbf2677e0fdcdcf49da3264838689dddad112283","price":"0.45","side":"BUY","size":"117.6"},{"asset_id":"8761897749749422724209054078244794145777693856614463256546737399611489089783","best_ask":"0.51","best_bid":"0.5","hash":"45002af57e3687ab1c21b3b0e276844f3eae8063","price":"0.55","side":"SELL","size":"117.6"}],"timestamp":"1785208061467"},"payload_hash":"9f9168a875cc36dbb6546ab9d7884f294ecafa9b2b80d97fc853f3108cde63ea","raw_frame":"{\"market\":\"0x779291bef19b6709f61e9764a954aafe9ffae488d50ae674aabdcb4f248006d5\", \"price_changes\":[{\"asset_id\":\"14965588658799411272385430903075831224615961675357217884735713260981483529984\", \"price\":\"0.45\", \"size\":\"117.6\", \"side\":\"BUY\", \"hash\":\"fbf2677e0fdcdcf49da3264838689dddad112283\", \"best_bid\":\"0.49\", \"best_ask\":\"0.5\"}, {\"asset_id\":\"8761897749749422724209054078244794145777693856614463256546737399611489089783\", \"price\":\"0.55\", \"size\":\"117.6\", \"side\":\"SELL\", \"hash\":\"45002af57e3687ab1c21b3b0e276844f3eae8063\", \"best_bid\":\"0.5\", \"best_ask\":\"0.51\"}], \"timestamp\":\"1785208061467\", \"event_type\":\"price_change\"}","received_at":"2026-07-28T03:07:46.011178Z","schema_version":"clob-market-ws.price_change.v1","sequence":null,"server_hash":null,"server_timestamp":"1785208061467","session_id":"3e519d9098404c15b234d96025eb1a2b","source":"clob_market_ws"},"received_at":"2026-07-28T03:07:46.011178Z","record_id":"40e6c568a1803caafc47620035443bf65f12234f64bb094ca55e8bfabf3b896b","schema_fingerprint":"4aa3821a28b0b7c2400bc59aba4bcc0a76e971dadd19610d3ad38c768e124dc7","schema_version":"edge-lab-recorder.raw.v1","sequence":null,"source":"clob_market_ws"}
{"event_at":"2026-07-28T03:07:41.471000Z","event_fingerprint":"6955730297685bd383ba0d5d796ae08770bba0c971f90d1d277208183f7285d8","payload":{"connection_id":"a6b55582af5f430fb37ad02bf0922475","event_at":"2026-07-28T03:07:41.471000Z","event_type":"price_change","frame_hash":"9aebce6758bfe990bf083e2b7bed73701ce4f1df5c668df24e15e81ab3862cea","frame_index":0,"kind":"data","monotonic_ns":310049046256125,"payload":{"event_type":"price_change","market":"0x779291bef19b6709f61e9764a954aafe9ffae488d50ae674aabdcb4f248006d5","price_changes":[{"asset_id":"8761897749749422724209054078244794145777693856614463256546737399611489089783","best_ask":"0.51","best_bid":"0.5","hash":"9132cc92c97b597cd5b749b7fa83bca659b83c4a","price":"0.49","side":"BUY","size":"40"},{"asset_id":"14965588658799411272385430903075831224615961675357217884735713260981483529984","best_ask":"0.5","best_bid":"0.49","hash":"97cc5356363d7e48846abff41feef61426ba02f8","price":"0.51","side":"SELL","size":"40"}],"timestamp":"1785208061471"},"payload_hash":"764dd57bbe57e6cb9d05ccebfaf5bd001285d22d577dccfc2e04951f3c393f34","raw_frame":"{\"market\":\"0x779291bef19b6709f61e9764a954aafe9ffae488d50ae674aabdcb4f248006d5\", \"price_changes\":[{\"asset_id\":\"8761897749749422724209054078244794145777693856614463256546737399611489089783\", \"price\":\"0.49\", \"size\":\"40\", \"side\":\"BUY\", \"hash\":\"9132cc92c97b597cd5b749b7fa83bca659b83c4a\", \"best_bid\":\"0.5\", \"best_ask\":\"0.51\"}, {\"asset_id\":\"14965588658799411272385430903075831224615961675357217884735713260981483529984\", \"price\":\"0.51\", \"size\":\"40\", \"side\":\"SELL\", \"hash\":\"97cc5356363d7e48846abff41feef61426ba02f8\", \"best_bid\":\"0.49\", \"best_ask\":\"0.5\"}], \"timestamp\":\"1785208061471\", \"event_type\":\"price_change\"}","received_at":"2026-07-28T03:07:46.014109Z","schema_version":"clob-market-ws.price_change.v1","sequence":null,"server_hash":null,"server_timestamp":"1785208061471","session_id":"3e519d9098404c15b234d96025eb1a2b","source":"clob_market_ws"},"received_at":"2026-07-28T03:07:46.014109Z","record_id":"065a03042de240fe7ca1a30d2a17986c055daf6ea10770c4c3fe7b0dc4ad95dd","schema_fingerprint":"4aa3821a28b0b7c2400bc59aba4bcc0a76e971dadd19610d3ad38c768e124dc7","schema_version":"edge-lab-recorder.raw.v1","sequence":null,"source":"clob_market_ws"}
{"event_at":"2026-07-28T03:07:41.473000Z","event_fingerprint":"34c46933565bc38fcf362432b16b76ae545d4c33da7e949616cf784c895eb75c","payload":{"connection_id":"a6b55582af5f430fb37ad02bf0922475","event_at":"2026-07-28T03:07:41.473000Z","event_type":"price_change","frame_hash":"e8ab7069a1064ecdb090ccccf3484d6a4c77c3c00c0d13a8db81d7e92909ebbd","frame_index":0,"kind":"data","monotonic_ns":310049049138458,"payload":{"event_type":"price_change","market":"0x779291bef19b6709f61e9764a954aafe9ffae488d50ae674aabdcb4f248006d5","price_changes":[{"asset_id":"8761897749749422724209054078244794145777693856614463256546737399611489089783","best_ask":"0.51","best_bid":"0.5","hash":"4b71e1acbbe9b13955336a5d3d6e14c27475c12b","price":"0.5","side":"BUY","size":"82.6"},{"asset_id":"14965588658799411272385430903075831224615961675357217884735713260981483529984","best_ask":"0.5","best_bid":"0.49","hash":"beeb9b4e693b493150f4ba9a08e42b13524a924f","price":"0.5","side":"SELL","size":"82.6"}],"timestamp":"1785208061473"},"payload_hash":"7a13da8449c5dbc90e730e91934d623384cac431ff48dae0ddc1007ea3bb5550","raw_frame":"{\"market\":\"0x779291bef19b6709f61e9764a954aafe9ffae488d50ae674aabdcb4f248006d5\", \"price_changes\":[{\"asset_id\":\"8761897749749422724209054078244794145777693856614463256546737399611489089783\", \"price\":\"0.5\", \"size\":\"82.6\", \"side\":\"BUY\", \"hash\":\"4b71e1acbbe9b13955336a5d3d6e14c27475c12b\", \"best_bid\":\"0.5\", \"best_ask\":\"0.51\"}, {\"asset_id\":\"14965588658799411272385430903075831224615961675357217884735713260981483529984\", \"price\":\"0.5\", \"size\":\"82.6\", \"side\":\"SELL\", \"hash\":\"beeb9b4e693b493150f4ba9a08e42b13524a924f\", \"best_bid\":\"0.49\", \"best_ask\":\"0.5\"}], \"timestamp\":\"1785208061473\", \"event_type\":\"price_change\"}","received_at":"2026-07-28T03:07:46.016992Z","schema_version":"clob-market-ws.price_change.v1","sequence":null,"server_hash":null,"server_timestamp":"1785208061473","session_id":"3e519d9098404c15b234d96025eb1a2b","source":"clob_market_ws"},"received_at":"2026-07-28T03:07:46.016992Z","record_id":"98567a1c6db4051f2241a6fb41eea46153f08a12284d7aff40f11c0ea7adaaf2","schema_fingerprint":"4aa3821a28b0b7c2400bc59aba4bcc0a76e971dadd19610d3ad38c768e124dc7","schema_version":"edge-lab-recorder.raw.v1","sequence":null,"source":"clob_market_ws"}
{"event_at":"2026-07-28T03:07:41.477000Z","event_fingerprint":"470a6f4ee7e03848fbb83f30e31b5cd1a27b74107e2c5928e34509a91465e732","payload":{"connection_id":"a6b55582af5f430fb37ad02bf0922475","event_at":"2026-07-28T03:07:41.477000Z","event_type":"price_change","frame_hash":"63d1de68eb99d3d50e61a13761ad1b4bd72e2fd929bf4dfd2aef48e9ba03a0bf","frame_index":0,"kind":"data","monotonic_ns":310049052088416,"payload":{"event_type":"price_change","market":"0x779291bef19b6709f61e9764a954aafe9ffae488d50ae674aabdcb4f248006d5","price_changes":[{"asset_id":"8761897749749422724209054078244794145777693856614463256546737399611489089783","best_ask":"0.51","best_bid":"0.5","hash":"4bb8ee82495c91865f39c5f83cc94ac7cf60577f","price":"0.49","side":"BUY","size":"81"},{"asset_id":"14965588658799411272385430903075831224615961675357217884735713260981483529984","best_ask":"0.5","best_bid":"0.49","hash":"93d8a05f2ccc80514b4438cd7fa8bdee33945dc3","price":"0.51","side":"SELL","size":"81"}],"timestamp":"1785208061477"},"payload_hash":"56ef22090af591bbc0bbf48e46eb964be52c02db391d83977652cd3fed05bbcb","raw_frame":"{\"market\":\"0x779291bef19b6709f61e9764a954aafe9ffae488d50ae674aabdcb4f248006d5\", \"price_changes\":[{\"asset_id\":\"8761897749749422724209054078244794145777693856614463256546737399611489089783\", \"price\":\"0.49\", \"size\":\"81\", \"side\":\"BUY\", \"hash\":\"4bb8ee82495c91865f39c5f83cc94ac7cf60577f\", \"best_bid\":\"0.5\", \"best_ask\":\"0.51\"}, {\"asset_id\":\"14965588658799411272385430903075831224615961675357217884735713260981483529984\", \"price\":\"0.51\", \"size\":\"81\", \"side\":\"SELL\", \"hash\":\"93d8a05f2ccc80514b4438cd7fa8bdee33945dc3\", \"best_bid\":\"0.49\", \"best_ask\":\"0.5\"}], \"timestamp\":\"1785208061477\", \"event_type\":\"price_change\"}","received_at":"2026-07-28T03:07:46.019941Z","schema_version":"clob-market-ws.price_change.v1","sequence":null,"server_hash":null,"server_timestamp":"1785208061477","session_id":"3e519d9098404c15b234d96025eb1a2b","source":"clob_market_ws"},"received_at":"2026-07-28T03:07:46.019941Z","record_id":"77b1361aceddb999ae953660b7c3f018a2c9bc39d72f07bfbf1ec1357074101c","schema_fingerprint":"4aa3821a28b0b7c2400bc59aba4bcc0a76e971dadd19610d3ad38c768e124dc7","schema_version":"edge-lab-recorder.raw.v1","sequence":null,"source":"clob_market_ws"}
{"event_at":"2026-07-28T03:07:41.482000Z","event_fingerprint":"2540f5d93aeef48d705cfe9ea46176539939cd64c8754d499fa8a9693e9e4408","payload":{"connection_id":"a6b55582af5f430fb37ad02bf0922475","event_at":"2026-07-28T03:07:41.482000Z","event_type":"price_change","frame_hash":"51889e28dbf07097b2c84be5c89d056ea82f2c2546d07717043d6a330dd19fd0","frame_index":0,"kind":"data","monotonic_ns":310049055009458,"payload":{"event_type":"price_change","market":"0x779291bef19b6709f61e9764a954aafe9ffae488d50ae674aabdcb4f248006d5","price_changes":[{"asset_id":"8761897749749422724209054078244794145777693856614463256546737399611489089783","best_ask":"0.51","best_bid":"0.5","hash":"3919b6d34b262e17f391a2838182aaf0459046b1","price":"0.49","side":"BUY","size":"96"},{"asset_id":"14965588658799411272385430903075831224615961675357217884735713260981483529984","best_ask":"0.5","best_bid":"0.49","hash":"7225944ef7972f8ea4b42e8dd9739b0fd99cc63a","price":"0.51","side":"SELL","size":"96"}],"timestamp":"1785208061482"},"payload_hash":"47c20207e35377fecbdc91c1bff5764e87e974ab2d74082f6c8872c3ff93f4eb","raw_frame":"{\"market\":\"0x779291bef19b6709f61e9764a954aafe9ffae488d50ae674aabdcb4f248006d5\", \"price_changes\":[{\"asset_id\":\"8761897749749422724209054078244794145777693856614463256546737399611489089783\", \"price\":\"0.49\", \"size\":\"96\", \"side\":\"BUY\", \"hash\":\"3919b6d34b262e17f391a2838182aaf0459046b1\", \"best_bid\":\"0.5\", \"best_ask\":\"0.51\"}, {\"asset_id\":\"14965588658799411272385430903075831224615961675357217884735713260981483529984\", \"price\":\"0.51\", \"size\":\"96\", \"side\":\"SELL\", \"hash\":\"7225944ef7972f8ea4b42e8dd9739b0fd99cc63a\", \"best_bid\":\"0.49\", \"best_ask\":\"0.5\"}], \"timestamp\":\"1785208061482\", \"event_type\":\"price_change\"}","received_at":"2026-07-28T03:07:46.022862Z","schema_version":"clob-market-ws.price_change.v1","sequence":null,"server_hash":null,"server_timestamp":"1785208061482","session_id":"3e519d9098404c15b234d96025eb1a2b","source":"clob_market_ws"},"received_at":"2026-07-28T03:07:46.022862Z","record_id":"514703738cc62c91b7d73cf0f11387f3ed6bc9518913ee850598e7983a03e737","schema_fingerprint":"4aa3821a28b0b7c2400bc59aba4bcc0a76e971dadd19610d3ad38c768e124dc7","schema_version":"edge-lab-recorder.raw.v1","sequence":null,"source":"clob_market_ws"}
{"event_at":"2026-07-28T03:07:41.483000Z","event_fingerprint":"a4b096be96df1983dc9603b35d981c5f012f95a42712f4308d7aa4e999b60210","payload":{"connection_id":"a6b55582af5f430fb37ad02bf0922475","event_at":"2026-07-28T03:07:41.483000Z","event_type":"price_change","frame_hash":"9292e4e7f138ed65cab7a844df0c9302498b1c9759a0e6776f40a4e31c526240","frame_index":0,"kind":"data","monotonic_ns":310049057961041,"payload":{"event_type":"price_change","market":"0x779291bef19b6709f61e9764a954aafe9ffae488d50ae674aabdcb4f248006d5","price_changes":[{"asset_id":"8761897749749422724209054078244794145777693856614463256546737399611489089783","best_ask":"0.51","best_bid":"0.5","hash":"27360c274b32d60dde314e50e0eb205d84e80166","price":"0.49","side":"BUY","size":"76"},{"asset_id":"14965588658799411272385430903075831224615961675357217884735713260981483529984","best_ask":"0.5","best_bid":"0.49","hash":"4870d049546812ef2a5555288b59e2e7f607f7c1","price":"0.51","side":"SELL","size":"76"}],"timestamp":"1785208061483"},"payload_hash":"780a406211fb1cb1e111de3107e6eff51936b0b56057f522a84fa3149b5ae0e1","raw_frame":"{\"market\":\"0x779291bef19b6709f61e9764a954aafe9ffae488d50ae674aabdcb4f248006d5\", \"price_changes\":[{\"asset_id\":\"8761897749749422724209054078244794145777693856614463256546737399611489089783\", \"price\":\"0.49\", \"size\":\"76\", \"side\":\"BUY\", \"hash\":\"27360c274b32d60dde314e50e0eb205d84e80166\", \"best_bid\":\"0.5\", \"best_ask\":\"0.51\"}, {\"asset_id\":\"14965588658799411272385430903075831224615961675357217884735713260981483529984\", \"price\":\"0.51\", \"size\":\"76\", \"side\":\"SELL\", \"hash\":\"4870d049546812ef2a5555288b59e2e7f607f7c1\", \"best_bid\":\"0.49\", \"best_ask\":\"0.5\"}], \"timestamp\":\"1785208061483\", \"event_type\":\"price_change\"}","received_at":"2026-07-28T03:07:46.025814Z","schema_version":"clob-market-ws.price_change.v1","sequence":null,"server_hash":null,"server_timestamp":"1785208061483","session_id":"3e519d9098404c15b234d96025eb1a2b","source":"clob_market_ws"},"received_at":"2026-07-28T03:07:46.025814Z","record_id":"81d92d90700fbf904d471ac17ed04492af871a13d9aae4a41ef7e63439beeafb","schema_fingerprint":"4aa3821a28b0b7c2400bc59aba4bcc0a76e971dadd19610d3ad38c768e124dc7","schema_version":"edge-lab-recorder.raw.v1","sequence":null,"source":"clob_market_ws"}
{"event_at":"2026-07-28T03:07:41.483000Z","event_fingerprint":"f1cb1913ed365c59720ff99cc73d7afe3fb7f8df90e9876e582ba705ee4640cb","payload":{"connection_id":"a6b55582af5f430fb37ad02bf0922475","event_at":"2026-07-28T03:07:41.483000Z","event_type":"price_change","frame_hash":"c45651cc3efc4296e79833a2d470279455a580d9a56a8e8b8b58198bc8f606ee","frame_index":0,"kind":"data","monotonic_ns":310049060889583,"payload":{"event_type":"price_change","market":"0x779291bef19b6709f61e9764a954aafe9ffae488d50ae674aabdcb4f248006d5","price_changes":[{"asset_id":"8761897749749422724209054078244794145777693856614463256546737399611489089783","best_ask":"0.51","best_bid":"0.5","hash":"11e2d450b0f4319ad88aa7b9def6af15c4243531","price":"0.5","side":"BUY","size":"62.6"},{"asset_id":"14965588658799411272385430903075831224615961675357217884735713260981483529984","best_ask":"0.5","best_bid":"0.49","hash":"f3408b9999a631e6e2a157452d9ffb8519d9b4ea","price":"0.5","side":"SELL","size":"62.6"}],"timestamp":"1785208061483"},"payload_hash":"d33dc507b81152b415bf33382e7cd55fea2d44cd7d77689acf3ecaa809946ba2","raw_frame":"{\"market\":\"0x779291bef19b6709f61e9764a954aafe9ffae488d50ae674aabdcb4f248006d5\", \"price_changes\":[{\"asset_id\":\"8761897749749422724209054078244794145777693856614463256546737399611489089783\", \"price\":\"0.5\", \"size\":\"62.6\", \"side\":\"BUY\", \"hash\":\"11e2d450b0f4319ad88aa7b9def6af15c4243531\", \"best_bid\":\"0.5\", \"best_ask\":\"0.51\"}, {\"asset_id\":\"14965588658799411272385430903075831224615961675357217884735713260981483529984\", \"price\":\"0.5\", \"size\":\"62.6\", \"side\":\"SELL\", \"hash\":\"f3408b9999a631e6e2a157452d9ffb8519d9b4ea\", \"best_bid\":\"0.49\", \"best_ask\":\"0.5\"}], \"timestamp\":\"1785208061483\", \"event_type\":\"price_change\"}","received_at":"2026-07-28T03:07:46.028743Z","schema_version":"clob-market-ws.price_change.v1","sequence":null,"server_hash":null,"server_timestamp":"1785208061483","session_id":"3e519d9098404c15b234d96025eb1a2b","source":"clob_market_ws"},"received_at":"2026-07-28T03:07:46.028743Z","record_id":"f0c25e5ffbf9596d296c436a698a92afd2b7b834b760efae88d2fdeda5f21c12","schema_fingerprint":"4aa3821a28b0b7c2400bc59aba4bcc0a76e971dadd19610d3ad38c768e124dc7","schema_version":"edge-lab-recorder.raw.v1","sequence":null,"source":"clob_market_ws"}
{"event_at":"2026-07-28T03:07:41.483000Z","event_fingerprint":"2df3538b40a4dfaba0528710c7728746bbf815db1ad6ba480cca803f120459a3","payload":{"connection_id":"a6b55582af5f430fb37ad02bf0922475","event_at":"2026-07-28T03:07:41.483000Z","event_type":"price_change","frame_hash":"f1c9b59b819c58b3e9233dfc6c5693c15c843525f93dcfbb361c778b5e1244c5","frame_index":0,"kind":"data","monotonic_ns":310049063479041,"payload":{"event_type":"price_change","market":"0x779291bef19b6709f61e9764a954aafe9ffae488d50ae674aabdcb4f248006d5","price_changes":[{"asset_id":"8761897749749422724209054078244794145777693856614463256546737399611489089783","best_ask":"0.51","best_bid":"0.5","hash":"68772dce187eceb8e6c5752c2d92fc815a5c0438","price":"0.48","side":"BUY","size":"175.6"},{"asset_id":"14965588658799411272385430903075831224615961675357217884735713260981483529984","best_ask":"0.5","best_bid":"0.49","hash":"ff01fdbcd1f8159461bc8f7fc2850b019e2a2327","price":"0.52","side":"SELL","size":"175.6"}],"timestamp":"1785208061483"},"payload_hash":"d880deee67803974f156ac8c83926ba75d523a7c334e11898ebd852dfedcba8d","raw_frame":"{\"market\":\"0x779291bef19b6709f61e9764a954aafe9ffae488d50ae674aabdcb4f248006d5\", \"price_changes\":[{\"asset_id\":\"8761897749749422724209054078244794145777693856614463256546737399611489089783\", \"price\":\"0.48\", \"size\":\"175.6\", \"side\":\"BUY\", \"hash\":\"68772dce187eceb8e6c5752c2d92fc815a5c0438\", \"best_bid\":\"0.5\", \"best_ask\":\"0.51\"}, {\"asset_id\":\"14965588658799411272385430903075831224615961675357217884735713260981483529984\", \"price\":\"0.52\", \"size\":\"175.6\", \"side\":\"SELL\", \"hash\":\"ff01fdbcd1f8159461bc8f7fc2850b019e2a2327\", \"best_bid\":\"0.49\", \"best_ask\":\"0.5\"}], \"timestamp\":\"1785208061483\", \"event_type\":\"price_change\"}","received_at":"2026-07-28T03:07:46.031332Z","schema_version":"clob-market-ws.price_change.v1","sequence":null,"server_hash":null,"server_timestamp":"1785208061483","session_id":"3e519d9098404c15b234d96025eb1a2b","source":"clob_market_ws"},"received_at":"2026-07-28T03:07:46.031332Z","record_id":"98492abd480548d5bc2ae795a7c5b81478fdbb2c9af619492f7590d4e46a85cb","schema_fingerprint":"4aa3821a28b0b7c2400bc59aba4bcc0a76e971dadd19610d3ad38c768e124dc7","schema_version":"edge-lab-recorder.raw.v1","sequence":null,"source":"clob_market_ws"}
{"event_at":"2026-07-28T03:07:41.484000Z","event_fingerprint":"5304c7fd3a85129646cdb465031b7c6adc621685f6ed87aaae8a7c7dc5f8081b","payload":{"connection_id":"a6b55582af5f430fb37ad02bf0922475","event_at":"2026-07-28T03:07:41.484000Z","event_type":"price_change","frame_hash":"7a54e5e99a6a4bc4a2d951ebeaa401077e0adf1d23bcee7e2917b33717f09c0b","frame_index":0,"kind":"data","monotonic_ns":310049067253833,"payload":{"event_type":"price_change","market":"0x779291bef19b6709f61e9764a954aafe9ffae488d50ae674aabdcb4f248006d5","price_changes":[{"asset_id":"8761897749749422724209054078244794145777693856614463256546737399611489089783","best_ask":"0.51","best_bid":"0.5","hash":"e444e0c108d3b9dcd3ca039e1edc5adbb71c8655","price":"0.47","side":"BUY","size":"122.6"},{"asset_id":"14965588658799411272385430903075831224615961675357217884735713260981483529984","best_ask":"0.5","best_bid":"0.49","hash":"46a2b88076e90ebe5cd017fc5dbbf4d1d5478dd0","price":"0.53","side":"SELL","size":"122.6"}],"timestamp":"1785208061484"},"payload_hash":"38927be4d4c68aa5db632e9fff6aee26caea3dca6bc02e83c1488f86ce47cf0b","raw_frame":"{\"market\":\"0x779291bef19b6709f61e9764a954aafe9ffae488d50ae674aabdcb4f248006d5\", \"price_changes\":[{\"asset_id\":\"8761897749749422724209054078244794145777693856614463256546737399611489089783\", \"price\":\"0.47\", \"size\":\"122.6\", \"side\":\"BUY\", \"hash\":\"e444e0c108d3b9dcd3ca039e1edc5adbb71c8655\", \"best_bid\":\"0.5\", \"best_ask\":\"0.51\"}, {\"asset_id\":\"14965588658799411272385430903075831224615961675357217884735713260981483529984\", \"price\":\"0.53\", \"size\":\"122.6\", \"side\":\"SELL\", \"hash\":\"46a2b88076e90ebe5cd017fc5dbbf4d1d5478dd0\", \"best_bid\":\"0.49\", \"best_ask\":\"0.5\"}], \"timestamp\":\"1785208061484\", \"event_type\":\"price_change\"}","received_at":"2026-07-28T03:07:46.035107Z","schema_version":"clob-market-ws.price_change.v1","sequence":null,"server_hash":null,"server_timestamp":"1785208061484","session_id":"3e519d9098404c15b234d96025eb1a2b","source":"clob_market_ws"},"received_at":"2026-07-28T03:07:46.035107Z","record_id":"4366b27e513ff88c5b513be8f258eaeb3e31e67171d42ae51bfe1d08579b6268","schema_fingerprint":"4aa3821a28b0b7c2400bc59aba4bcc0a76e971dadd19610d3ad38c768e124dc7","schema_version":"edge-lab-recorder.raw.v1","sequence":null,"source":"clob_market_ws"}
{"event_at":"2026-07-28T03:07:41.489000Z","event_fingerprint":"20316214e3e4b6f659d2cb8f1db6604a00ad409d01ce9f2a831dcfb59eb1fa40","payload":{"connection_id":"a6b55582af5f430fb37ad02bf0922475","event_at":"2026-07-28T03:07:41.489000Z","event_type":"price_change","frame_hash":"3c24c51490aeb9e70a1b002a17d8dee6f8068f1e89ffe50d9cdc940da6cc23ea","frame_index":0,"kind":"data","monotonic_ns":310049070214458,"payload":{"event_type":"price_change","market":"0x779291bef19b6709f61e9764a954aafe9ffae488d50ae674aabdcb4f248006d5","price_changes":[{"asset_id":"8761897749749422724209054078244794145777693856614463256546737399611489089783","best_ask":"0.51","best_bid":"0.5","hash":"5e4e23884fcac1f17ccf66db23036348ec0aee74","price":"0.46","side":"BUY","size":"142.06"},{"asset_id":"14965588658799411272385430903075831224615961675357217884735713260981483529984","best_ask":"0.5","best_bid":"0.49","hash":"35196881a919604119cc0af8185a34c10f78cc32","price":"0.54","side":"SELL","size":"142.06"}],"timestamp":"1785208061489"},"payload_hash":"a2f6c003405675689da4700e4fcd8f65ffed0b2d7f3cf66d727b2d6abdd4017f","raw_frame":"{\"market\":\"0x779291bef19b6709f61e9764a954aafe9ffae488d50ae674aabdcb4f248006d5\", \"price_changes\":[{\"asset_id\":\"8761897749749422724209054078244794145777693856614463256546737399611489089783\", \"price\":\"0.46\", \"size\":\"142.06\", \"side\":\"BUY\", \"hash\":\"5e4e23884fcac1f17ccf66db23036348ec0aee74\", \"best_bid\":\"0.5\", \"best_ask\":\"0.51\"}, {\"asset_id\":\"14965588658799411272385430903075831224615961675357217884735713260981483529984\", \"price\":\"0.54\", \"size\":\"142.06\", \"side\":\"SELL\", \"hash\":\"35196881a919604119cc0af8185a34c10f78cc32\", \"best_bid\":\"0.49\", \"best_ask\":\"0.5\"}], \"timestamp\":\"1785208061489\", \"event_type\":\"price_change\"}","received_at":"2026-07-28T03:07:46.038067Z","schema_version":"clob-market-ws.price_change.v1","sequence":null,"server_hash":null,"server_timestamp":"1785208061489","session_id":"3e519d9098404c15b234d96025eb1a2b","source":"clob_market_ws"},"received_at":"2026-07-28T03:07:46.038067Z","record_id":"ab85fac558bb3d2e42d53e686959995f8fa7eb555eba82df89a45ef878639434","schema_fingerprint":"4aa3821a28b0b7c2400bc59aba4bcc0a76e971dadd19610d3ad38c768e124dc7","schema_version":"edge-lab-recorder.raw.v1","sequence":null,"source":"clob_market_ws"}
{"event_at":"2026-07-28T03:07:41.501000Z","event_fingerprint":"296cc87bf23602beab1694d6b4da255151a0af090a5b1ba84dc489819b90dd7e","payload":{"connection_id":"a6b55582af5f430fb37ad02bf0922475","event_at":"2026-07-28T03:07:41.501000Z","event_type":"price_change","frame_hash":"225ca1fa349ef00ca56001b6ead6a4cdac69774758f6c59d3c3f7b2cc587bdd2","frame_index":0,"kind":"data","monotonic_ns":310049073138416,"payload":{"event_type":"price_change","market":"0x779291bef19b6709f61e9764a954aafe9ffae488d50ae674aabdcb4f248006d5","price_changes":[{"asset_id":"14965588658799411272385430903075831224615961675357217884735713260981483529984","best_ask":"0.5","best_bid":"0.49","hash":"7ab9d565ecda93c0fdc2189d47a135d740700756","price":"0.46","side":"BUY","size":"93.6"},{"asset_id":"8761897749749422724209054078244794145777693856614463256546737399611489089783","best_ask":"0.51","best_bid":"0.5","hash":"232affda5cb013d09e76d94b430f66938cf7f9ae","price":"0.54","side":"SELL","size":"93.6"}],"timestamp":"1785208061501"},"payload_hash":"c0461cbb082408ff10b33361c8ff58322845d918ec098158bddf21b830d3f0b3","raw_frame":"{\"market\":\"0x779291bef19b6709f61e9764a954aafe9ffae488d50ae674aabdcb4f248006d5\", \"price_changes\":[{\"asset_id\":\"14965588658799411272385430903075831224615961675357217884735713260981483529984\", \"price\":\"0.46\", \"size\":\"93.6\", \"side\":\"BUY\", \"hash\":\"7ab9d565ecda93c0fdc2189d47a135d740700756\", \"best_bid\":\"0.49\", \"best_ask\":\"0.5\"}, {\"asset_id\":\"8761897749749422724209054078244794145777693856614463256546737399611489089783\", \"price\":\"0.54\", \"size\":\"93.6\", \"side\":\"SELL\", \"hash\":\"232affda5cb013d09e76d94b430f66938cf7f9ae\", \"best_bid\":\"0.5\", \"best_ask\":\"0.51\"}], \"timestamp\":\"1785208061501\", \"event_type\":\"price_change\"}","received_at":"2026-07-28T03:07:46.040991Z","schema_version":"clob-market-ws.price_change.v1","sequence":null,"server_hash":null,"server_timestamp":"1785208061501","session_id":"3e519d9098404c15b234d96025eb1a2b","source":"clob_market_ws"},"received_at":"2026-07-28T03:07:46.040991Z","record_id":"f01d007b19d93bba932e039301bbd78f50ad2f179ce5b42eac79b54c63dd4101","schema_fingerprint":"4aa3821a28b0b7c2400bc59aba4bcc0a76e971dadd19610d3ad38c768e124dc7","schema_version":"edge-lab-recorder.raw.v1","sequence":null,"source":"clob_market_ws"}
{"event_at":"2026-07-28T03:07:41.505000Z","event_fingerprint":"3c15da7576288c954659ffcf7e05fb48a0b46315c5784e5133c3054f41016e71","payload":{"connection_id":"a6b55582af5f430fb37ad02bf0922475","event_at":"2026-07-28T03:07:41.505000Z","event_type":"price_change","frame_hash":"caadd9c436cf9845cad7383c97dfab3ba2a817d277bab262dad42f38c99a0f85","frame_index":0,"kind":"data","monotonic_ns":310049076040166,"payload":{"event_type":"price_change","market":"0x779291bef19b6709f61e9764a954aafe9ffae488d50ae674aabdcb4f248006d5","price_changes":[{"asset_id":"8761897749749422724209054078244794145777693856614463256546737399611489089783","best_ask":"0.51","best_bid":"0.5","hash":"df50996b334de2882260c99952ecb270cb16b0da","price":"0.48","side":"BUY","size":"165.6"},{"asset_id":"14965588658799411272385430903075831224615961675357217884735713260981483529984","best_ask":"0.5","best_bid":"0.49","hash":"ca7e809bffd1ba426c5ad2bffc0e388437851a3f","price":"0.52","side":"SELL","size":"165.6"}],"timestamp":"1785208061505"},"payload_hash":"010f04f7dce21ee034098014d2b219c809db6698b365991837489dd04647ea74","raw_frame":"{\"market\":\"0x779291bef19b6709f61e9764a954aafe9ffae488d50ae674aabdcb4f248006d5\", \"price_changes\":[{\"asset_id\":\"8761897749749422724209054078244794145777693856614463256546737399611489089783\", \"price\":\"0.48\", \"size\":\"165.6\", \"side\":\"BUY\", \"hash\":\"df50996b334de2882260c99952ecb270cb16b0da\", \"best_bid\":\"0.5\", \"best_ask\":\"0.51\"}, {\"asset_id\":\"14965588658799411272385430903075831224615961675357217884735713260981483529984\", \"price\":\"0.52\", \"size\":\"165.6\", \"side\":\"SELL\", \"hash\":\"ca7e809bffd1ba426c5ad2bffc0e388437851a3f\", \"best_bid\":\"0.49\", \"best_ask\":\"0.5\"}], \"timestamp\":\"1785208061505\", \"event_type\":\"price_change\"}","received_at":"2026-07-28T03:07:46.043891Z","schema_version":"clob-market-ws.price_change.v1","sequence":null,"server_hash":null,"server_timestamp":"1785208061505","session_id":"3e519d9098404c15b234d96025eb1a2b","source":"clob_market_ws"},"received_at":"2026-07-28T03:07:46.043891Z","record_id":"3574e1bd63c43077a75eecbdf64545d93797538183d4e1453236088e282eeda8","schema_fingerprint":"4aa3821a28b0b7c2400bc59aba4bcc0a76e971dadd19610d3ad38c768e124dc7","schema_version":"edge-lab-recorder.raw.v1","sequence":null,"source":"clob_market_ws"}
{"event_at":"2026-07-28T03:07:41.506000Z","event_fingerprint":"966c9d983b7c5413bdae251c1d69a3a3ec54a8dcc17d51998a81a16bda8a57fd","payload":{"connection_id":"a6b55582af5f430fb37ad02bf0922475","event_at":"2026-07-28T03:07:41.506000Z","event_type":"price_change","frame_hash":"403d14da80b5f2c7cfd565e81637d56262fda28f9c5408778ea2b554597aa510","frame_index":0,"kind":"data","monotonic_ns":310049079052500,"payload":{"event_type":"price_change","market":"0x779291bef19b6709f61e9764a954aafe9ffae488d50ae674aabdcb4f248006d5","price_changes":[{"asset_id":"8761897749749422724209054078244794145777693856614463256546737399611489089783","best_ask":"0.51","best_bid":"0.5","hash":"550b6c6c946b62739d7bdf11dee90cb6ddf64cea","price":"0.5","side":"BUY","size":"52.6"},{"asset_id":"14965588658799411272385430903075831224615961675357217884735713260981483529984","best_ask":"0.5","best_bid":"0.49","hash":"a9d92d4fc8659a18eb2b2cd590706088f8df99bc","price":"0.5","side":"SELL","size":"52.6"}],"timestamp":"1785208061506"},"payload_hash":"09dcf1b79bdf29a9405fb3367ec18962c4e6270eb21ce0d6e965fb9f542202ab","raw_frame":"{\"market\":\"0x779291bef19b6709f61e9764a954aafe9ffae488d50ae674aabdcb4f248006d5\", \"price_changes\":[{\"asset_id\":\"8761897749749422724209054078244794145777693856614463256546737399611489089783\", \"price\":\"0.5\", \"size\":\"52.6\", \"side\":\"BUY\", \"hash\":\"550b6c6c946b62739d7bdf11dee90cb6ddf64cea\", \"best_bid\":\"0.5\", \"best_ask\":\"0.51\"}, {\"asset_id\":\"14965588658799411272385430903075831224615961675357217884735713260981483529984\", \"price\":\"0.5\", \"size\":\"52.6\", \"side\":\"SELL\", \"hash\":\"a9d92d4fc8659a18eb2b2cd590706088f8df99bc\", \"best_bid\":\"0.49\", \"best_ask\":\"0.5\"}], \"timestamp\":\"1785208061506\", \"event_type\":\"price_change\"}","received_at":"2026-07-28T03:07:46.046905Z","schema_version":"clob-market-ws.price_change.v1","sequence":null,"server_hash":null,"server_timestamp":"1785208061506","session_id":"3e519d9098404c15b234d96025eb1a2b","source":"clob_market_ws"},"received_at":"2026-07-28T03:07:46.046905Z","record_id":"486c1d26b595b16a3bacc528a7bf9235fb844e64cc6dc947e00f8cd5466bea93","schema_fingerprint":"4aa3821a28b0b7c2400bc59aba4bcc0a76e971dadd19610d3ad38c768e124dc7","schema_version":"edge-lab-recorder.raw.v1","sequence":null,"source":"clob_market_ws"}
{"event_at":"2026-07-28T03:07:41.507000Z","event_fingerprint":"5af1da7e096db7f96929af7c15560d3c38363df27dea1b14e28bb63e838f1bcf","payload":{"connection_id":"a6b55582af5f430fb37ad02bf0922475","event_at":"2026-07-28T03:07:41.507000Z","event_type":"price_change","frame_hash":"fabe2abd4301c1bf412dcf169bc2361faca98b2c78cb3894f510cf2e8f2ddd82","frame_index":0,"kind":"data","monotonic_ns":310049081997416,"payload":{"event_type":"price_change","market":"0x779291bef19b6709f61e9764a954aafe9ffae488d50ae674aabdcb4f248006d5","price_changes":[{"asset_id":"8761897749749422724209054078244794145777693856614463256546737399611489089783","best_ask":"0.51","best_bid":"0.5","hash":"cb6d1e5f883e6995e6e628222942c2cc2e943c09","price":"0.49","side":"BUY","size":"66"},{"asset_id":"14965588658799411272385430903075831224615961675357217884735713260981483529984","best_ask":"0.5","best_bid":"0.49","hash":"3cc42f6795ab4060802bddcd4f2bd655357c549f","price":"0.51","side":"SELL","size":"66"}],"timestamp":"1785208061507"},"payload_hash":"3a19004a39b329df0e554564f0b257b5392743872fafd21baa9c309fcbed6fa4","raw_frame":"{\"market\":\"0x779291bef19b6709f61e9764a954aafe9ffae488d50ae674aabdcb4f248006d5\", \"price_changes\":[{\"asset_id\":\"8761897749749422724209054078244794145777693856614463256546737399611489089783\", \"price\":\"0.49\", \"size\":\"66\", \"side\":\"BUY\", \"hash\":\"cb6d1e5f883e6995e6e628222942c2cc2e943c09\", \"best_bid\":\"0.5\", \"best_ask\":\"0.51\"}, {\"asset_id\":\"14965588658799411272385430903075831224615961675357217884735713260981483529984\", \"price\":\"0.51\", \"size\":\"66\", \"side\":\"SELL\", \"hash\":\"3cc42f6795ab4060802bddcd4f2bd655357c549f\", \"best_bid\":\"0.49\", \"best_ask\":\"0.5\"}], \"timestamp\":\"1785208061507\", \"event_type\":\"price_change\"}","received_at":"2026-07-28T03:07:46.049850Z","schema_version":"clob-market-ws.price_change.v1","sequence":null,"server_hash":null,"server_timestamp":"1785208061507","session_id":"3e519d9098404c15b234d96025eb1a2b","source":"clob_market_ws"},"received_at":"2026-07-28T03:07:46.049850Z","record_id":"2b69aec189d2966c579a40bc544d6f336eb473826b9d3fed4a933848b3970871","schema_fingerprint":"4aa3821a28b0b7c2400bc59aba4bcc0a76e971dadd19610d3ad38c768e124dc7","schema_version":"edge-lab-recorder.raw.v1","sequence":null,"source":"clob_market_ws"}
{"event_at":"2026-07-28T03:07:41.509000Z","event_fingerprint":"1f5c1941debc20317646dafd7113d6994547a0bd840cba1a375fd3726dddf0ed","payload":{"connection_id":"a6b55582af5f430fb37ad02bf0922475","event_at":"2026-07-28T03:07:41.509000Z","event_type":"price_change","frame_hash":"2accfda7ae8b3e85f342d6e047b4bdd97c3641a56bc5eeb3731f3f2e80486ac5","frame_index":0,"kind":"data","monotonic_ns":310049084929750,"payload":{"event_type":"price_change","market":"0x779291bef19b6709f61e9764a954aafe9ffae488d50ae674aabdcb4f248006d5","price_changes":[{"asset_id":"8761897749749422724209054078244794145777693856614463256546737399611489089783","best_ask":"0.51","best_bid":"0.5","hash":"2a4f4a6d6485c419a611f2cc4f060439f140e428","price":"0.03","side":"BUY","size":"648.1"},{"asset_id":"14965588658799411272385430903075831224615961675357217884735713260981483529984","best_ask":"0.5","best_bid":"0.49","hash":"93efead78bad39102699ae72b72e73e77b3e9ad7","price":"0.97","side":"SELL","size":"648.1"}],"timestamp":"1785208061509"},"payload_hash":"4110109f74966bf347f12c9597f0aee64d075ab36ca8cfdf8918a87a68af16fd","raw_frame":"{\"market\":\"0x779291bef19b6709f61e9764a954aafe9ffae488d50ae674aabdcb4f248006d5\", \"price_changes\":[{\"asset_id\":\"8761897749749422724209054078244794145777693856614463256546737399611489089783\", \"price\":\"0.03\", \"size\":\"648.1\", \"side\":\"BUY\", \"hash\":\"2a4f4a6d6485c419a611f2cc4f060439f140e428\", \"best_bid\":\"0.5\", \"best_ask\":\"0.51\"}, {\"asset_id\":\"14965588658799411272385430903075831224615961675357217884735713260981483529984\", \"price\":\"0.97\", \"size\":\"648.1\", \"side\":\"SELL\", \"hash\":\"93efead78bad39102699ae72b72e73e77b3e9ad7\", \"best_bid\":\"0.49\", \"best_ask\":\"0.5\"}], \"timestamp\":\"1785208061509\", \"event_type\":\"price_change\"}","received_at":"2026-07-28T03:07:46.052782Z","schema_version":"clob-market-ws.price_change.v1","sequence":null,"server_hash":null,"server_timestamp":"1785208061509","session_id":"3e519d9098404c15b234d96025eb1a2b","source":"clob_market_ws"},"received_at":"2026-07-28T03:07:46.052782Z","record_id":"b91b59206d35dba7ed513f51da63874f1acbc0ac4be258f94fc4890626ad3cb9","schema_fingerprint":"4aa3821a28b0b7c2400bc59aba4bcc0a76e971dadd19610d3ad38c768e124dc7","schema_version":"edge-lab-recorder.raw.v1","sequence":null,"source":"clob_market_ws"}
{"event_at":"2026-07-28T03:07:41.514000Z","event_fingerprint":"266b806d2fbe6aaf2cbd999a4bdce75fd775fa9d241ac7c07dec45e228692bbc","payload":{"connection_id":"a6b55582af5f430fb37ad02bf0922475","event_at":"2026-07-28T03:07:41.514000Z","event_type":"price_change","frame_hash":"ce1c164996ce69c1e86b54b2c8b5c8dcb93cefbfc4e74f5e2f04941f1bf2b77f","frame_index":0,"kind":"data","monotonic_ns":310049087831041,"payload":{"event_type":"price_change","market":"0x779291bef19b6709f61e9764a954aafe9ffae488d50ae674aabdcb4f248006d5","price_changes":[{"asset_id":"8761897749749422724209054078244794145777693856614463256546737399611489089783","best_ask":"0.51","best_bid":"0.5","hash":"56a77e8e4f6e662482f952dcc924a8770f3addac","price":"0.47","side":"BUY","size":"112.6"},{"asset_id":"14965588658799411272385430903075831224615961675357217884735713260981483529984","best_ask":"0.5","best_bid":"0.49","hash":"cfac6586b284b85dba0120b3bda20db554e02bb4","price":"0.53","side":"SELL","size":"112.6"}],"timestamp":"1785208061514"},"payload_hash":"2f9aff057984b37d60b09ab9004c351e818dff9fa84b54ef71af93b9a5eba0b3","raw_frame":"{\"market\":\"0x779291bef19b6709f61e9764a954aafe9ffae488d50ae674aabdcb4f248006d5\", \"price_changes\":[{\"asset_id\":\"8761897749749422724209054078244794145777693856614463256546737399611489089783\", \"price\":\"0.47\", \"size\":\"112.6\", \"side\":\"BUY\", \"hash\":\"56a77e8e4f6e662482f952dcc924a8770f3addac\", \"best_bid\":\"0.5\", \"best_ask\":\"0.51\"}, {\"asset_id\":\"14965588658799411272385430903075831224615961675357217884735713260981483529984\", \"price\":\"0.53\", \"size\":\"112.6\", \"side\":\"SELL\", \"hash\":\"cfac6586b284b85dba0120b3bda20db554e02bb4\", \"best_bid\":\"0.49\", \"best_ask\":\"0.5\"}], \"timestamp\":\"1785208061514\", \"event_type\":\"price_change\"}","received_at":"2026-07-28T03:07:46.055683Z","schema_version":"clob-market-ws.price_change.v1","sequence":null,"server_hash":null,"server_timestamp":"1785208061514","session_id":"3e519d9098404c15b234d96025eb1a2b","source":"clob_market_ws"},"received_at":"2026-07-28T03:07:46.055683Z","record_id":"64e34fd6d81c57d108c1fa0966994196b8a1ee89851dca0b9c56e516f85ec4ca","schema_fingerprint":"4aa3821a28b0b7c2400bc59aba4bcc0a76e971dadd19610d3ad38c768e124dc7","schema_version":"edge-lab-recorder.raw.v1","sequence":null,"source":"clob_market_ws"}
{"event_at":"2026-07-28T03:07:41.528000Z","event_fingerprint":"e8355493e29dedd6fdea32febf49171622d8a9468c325ce6ac48baba52fad166","payload":{"connection_id":"a6b55582af5f430fb37ad02bf0922475","event_at":"2026-07-28T03:07:41.528000Z","event_type":"price_change","frame_hash":"825903fccbce0869dddc436820b7b89fc709d6afc9e98ec2fca53b06340f00c2","frame_index":0,"kind":"data","monotonic_ns":310049090756875,"payload":{"event_type":"price_change","market":"0x779291bef19b6709f61e9764a954aafe9ffae488d50ae674aabdcb4f248006d5","price_changes":[{"asset_id":"14965588658799411272385430903075831224615961675357217884735713260981483529984","best_ask":"0.5","best_bid":"0.49","hash":"a9e758958f94a30f8a19a322f9d2215e5950ed98","price":"0.38","side":"BUY","size":"208.7"},{"asset_id":"8761897749749422724209054078244794145777693856614463256546737399611489089783","best_ask":"0.51","best_bid":"0.5","hash":"085d860bfedf4b775b553f0a0cc9e0a86c5fc20f","price":"0.62","side":"SELL","size":"208.7"}],"timestamp":"1785208061528"},"payload_hash":"56f12e8e29272e98363b7254128625209040d6a507ce8e1103ff9ecf164af704","raw_frame":"{\"market\":\"0x779291bef19b6709f61e9764a954aafe9ffae488d50ae674aabdcb4f248006d5\", \"price_changes\":[{\"asset_id\":\"14965588658799411272385430903075831224615961675357217884735713260981483529984\", \"price\":\"0.38\", \"size\":\"208.7\", \"side\":\"BUY\", \"hash\":\"a9e758958f94a30f8a19a322f9d2215e5950ed98\", \"best_bid\":\"0.49\", \"best_ask\":\"0.5\"}, {\"asset_id\":\"8761897749749422724209054078244794145777693856614463256546737399611489089783\", \"price\":\"0.62\", \"size\":\"208.7\", \"side\":\"SELL\", \"hash\":\"085d860bfedf4b775b553f0a0cc9e0a86c5fc20f\", \"best_bid\":\"0.5\", \"best_ask\":\"0.51\"}], \"timestamp\":\"1785208061528\", \"event_type\":\"price_change\"}","received_at":"2026-07-28T03:07:46.058609Z","schema_version":"clob-market-ws.price_change.v1","sequence":null,"server_hash":null,"server_timestamp":"1785208061528","session_id":"3e519d9098404c15b234d96025eb1a2b","source":"clob_market_ws"},"received_at":"2026-07-28T03:07:46.058609Z","record_id":"f795c3a3eeb19392c8abc6196de813ff99ecd53233311921fc3f1ff663404418","schema_fingerprint":"4aa3821a28b0b7c2400bc59aba4bcc0a76e971dadd19610d3ad38c768e124dc7","schema_version":"edge-lab-recorder.raw.v1","sequence":null,"source":"clob_market_ws"}
{"event_at":"2026-07-28T03:07:41.528000Z","event_fingerprint":"28345b5040d73304e19312673d5ccd229584595c6320210c503fbad4dd230c88","payload":{"connection_id":"a6b55582af5f430fb37ad02bf0922475","event_at":"2026-07-28T03:07:41.528000Z","event_type":"price_change","frame_hash":"f4251bb079596b5de227ae5220c69e61ebe5db0e7e554807c342e797f62f17f9","frame_index":0,"kind":"data","monotonic_ns":310049093701791,"payload":{"event_type":"price_change","market":"0x779291bef19b6709f61e9764a954aafe9ffae488d50ae674aabdcb4f248006d5","price_changes":[{"asset_id":"14965588658799411272385430903075831224615961675357217884735713260981483529984","best_ask":"0.5","best_bid":"0.49","hash":"a9e758958f94a30f8a19a322f9d2215e5950ed98","price":"0.37","side":"BUY","size":"238.9"},{"asset_id":"8761897749749422724209054078244794145777693856614463256546737399611489089783","best_ask":"0.51","best_bid":"0.5","hash":"085d860bfedf4b775b553f0a0cc9e0a86c5fc20f","price":"0.63","side":"SELL","size":"238.9"}],"timestamp":"1785208061528"},"payload_hash":"ac799d78eb1d615529c30d72b0de5cb5260895d44800e92562a71506ee7d0ccd","raw_frame":"{\"market\":\"0x779291bef19b6709f61e9764a954aafe9ffae488d50ae674aabdcb4f248006d5\", \"price_changes\":[{\"asset_id\":\"14965588658799411272385430903075831224615961675357217884735713260981483529984\", \"price\":\"0.37\", \"size\":\"238.9\", \"side\":\"BUY\", \"hash\":\"a9e758958f94a30f8a19a322f9d2215e5950ed98\", \"best_bid\":\"0.49\", \"best_ask\":\"0.5\"}, {\"asset_id\":\"8761897749749422724209054078244794145777693856614463256546737399611489089783\", \"price\":\"0.63\", \"size\":\"238.9\", \"side\":\"SELL\", \"hash\":\"085d860bfedf4b775b553f0a0cc9e0a86c5fc20f\", \"best_bid\":\"0.5\", \"best_ask\":\"0.51\"}], \"timestamp\":\"1785208061528\", \"event_type\":\"price_change\"}","received_at":"2026-07-28T03:07:46.061554Z","schema_version":"clob-market-ws.price_change.v1","sequence":null,"server_hash":null,"server_timestamp":"1785208061528","session_id":"3e519d9098404c15b234d96025eb1a2b","source":"clob_market_ws"},"received_at":"2026-07-28T03:07:46.061554Z","record_id":"3f47ee3e2f0ae41d64c430d8d1590556eb38a355220e32810244a0878c9522ad","schema_fingerprint":"4aa3821a28b0b7c2400bc59aba4bcc0a76e971dadd19610d3ad38c768e124dc7","schema_version":"edge-lab-recorder.raw.v1","sequence":null,"source":"clob_market_ws"}
{"event_at":"2026-07-28T03:07:41.528000Z","event_fingerprint":"9dd32e7afb7db60019626aa39c05104897e78d8c46ca10daf00a49dcc13ccdce","payload":{"connection_id":"a6b55582af5f430fb37ad02bf0922475","event_at":"2026-07-28T03:07:41.528000Z","event_type":"price_change","frame_hash":"f93947443025b78259de7c92b438bf580bc6962cc4ec8987225f5b23a9725798","frame_index":0,"kind":"data","monotonic_ns":310049096699166,"payload":{"event_type":"price_change","market":"0x779291bef19b6709f61e9764a954aafe9ffae488d50ae674aabdcb4f248006d5","price_changes":[{"asset_id":"14965588658799411272385430903075831224615961675357217884735713260981483529984","best_ask":"0.5","best_bid":"0.49","hash":"a9e758958f94a30f8a19a322f9d2215e5950ed98","price":"0.36","side":"BUY","size":"251"},{"asset_id":"8761897749749422724209054078244794145777693856614463256546737399611489089783","best_ask":"0.51","best_bid":"0.5","hash":"085d860bfedf4b775b553f0a0cc9e0a86c5fc20f","price":"0.64","side":"SELL","size":"251"}],"timestamp":"1785208061528"},"payload_hash":"87e0397da857028984bc3bf7aaed60c9d22ab95e0164cb0a6d03ad37f64e9ead","raw_frame":"{\"market\":\"0x779291bef19b6709f61e9764a954aafe9ffae488d50ae674aabdcb4f248006d5\", \"price_changes\":[{\"asset_id\":\"14965588658799411272385430903075831224615961675357217884735713260981483529984\", \"price\":\"0.36\", \"size\":\"251\", \"side\":\"BUY\", \"hash\":\"a9e758958f94a30f8a19a322f9d2215e5950ed98\", \"best_bid\":\"0.49\", \"best_ask\":\"0.5\"}, {\"asset_id\":\"8761897749749422724209054078244794145777693856614463256546737399611489089783\", \"price\":\"0.64\", \"size\":\"251\", \"side\":\"SELL\", \"hash\":\"085d860bfedf4b775b553f0a0cc9e0a86c5fc20f\", \"best_bid\":\"0.5\", \"best_ask\":\"0.51\"}], \"timestamp\":\"1785208061528\", \"event_type\":\"price_change\"}","received_at":"2026-07-28T03:07:46.064552Z","schema_version":"clob-market-ws.price_change.v1","sequence":null,"server_hash":null,"server_timestamp":"1785208061528","session_id":"3e519d9098404c15b234d96025eb1a2b","source":"clob_market_ws"},"received_at":"2026-07-28T03:07:46.064552Z","record_id":"9f4f14ecdfbbb64de067b368b57c5d2de8fd77c58e434fd26a41c237a6ee41bb","schema_fingerprint":"4aa3821a28b0b7c2400bc59aba4bcc0a76e971dadd19610d3ad38c768e124dc7","schema_version":"edge-lab-recorder.raw.v1","sequence":null,"source":"clob_market_ws"}
{"event_at":"2026-07-28T03:07:41.528000Z","event_fingerprint":"563449ae20c4708b4f56fbc8d21dcf6dfd65447cd0bea2f263d4b4a91a71e8bb","payload":{"connection_id":"a6b55582af5f430fb37ad02bf0922475","event_at":"2026-07-28T03:07:41.528000Z","event_type":"price_change","frame_hash":"3668e4d4488101a730f401433ec51213a922c23cd0c87b34c95ae42aa95fb140","frame_index":0,"kind":"data","monotonic_ns":310049099597166,"payload":{"event_type":"price_change","market":"0x779291bef19b6709f61e9764a954aafe9ffae488d50ae674aabdcb4f248006d5","price_changes":[{"asset_id":"14965588658799411272385430903075831224615961675357217884735713260981483529984","best_ask":"0.5","best_bid":"0.49","hash":"a9e758958f94a30f8a19a322f9d2215e5950ed98","price":"0.35","side":"BUY","size":"221.2"},{"asset_id":"8761897749749422724209054078244794145777693856614463256546737399611489089783","best_ask":"0.51","best_bid":"0.5","hash":"085d860bfedf4b775b553f0a0cc9e0a86c5fc20f","price":"0.65","side":"SELL","size":"221.2"}],"timestamp":"1785208061528"},"payload_hash":"a9f801ed4ce4b7646e918dafc5a44511d3972f51c73c78a93e6e25b7bab6c1cb","raw_frame":"{\"market\":\"0x779291bef19b6709f61e9764a954aafe9ffae488d50ae674aabdcb4f248006d5\", \"price_changes\":[{\"asset_id\":\"14965588658799411272385430903075831224615961675357217884735713260981483529984\", \"price\":\"0.35\", \"size\":\"221.2\", \"side\":\"BUY\", \"hash\":\"a9e758958f94a30f8a19a322f9d2215e5950ed98\", \"best_bid\":\"0.49\", \"best_ask\":\"0.5\"}, {\"asset_id\":\"8761897749749422724209054078244794145777693856614463256546737399611489089783\", \"price\":\"0.65\", \"size\":\"221.2\", \"side\":\"SELL\", \"hash\":\"085d860bfedf4b775b553f0a0cc9e0a86c5fc20f\", \"best_bid\":\"0.5\", \"best_ask\":\"0.51\"}], \"timestamp\":\"1785208061528\", \"event_type\":\"price_change\"}","received_at":"2026-07-28T03:07:46.067450Z","schema_version":"clob-market-ws.price_change.v1","sequence":null,"server_hash":null,"server_timestamp":"1785208061528","session_id":"3e519d9098404c15b234d96025eb1a2b","source":"clob_market_ws"},"received_at":"2026-07-28T03:07:46.067450Z","record_id":"3052d209fd95a5381548bb0312a2e6ad2967959e496ad941d6e77be5bb26820b","schema_fingerprint":"4aa3821a28b0b7c2400bc59aba4bcc0a76e971dadd19610d3ad38c768e124dc7","schema_version":"edge-lab-recorder.raw.v1","sequence":null,"source":"clob_market_ws"}
{"event_at":"2026-07-28T03:07:41.544000Z","event_fingerprint":"606d59bb0215839711d86c4b8410ce5933cece3c3801d166c942df2b8ba4664e","payload":{"connection_id":"a6b55582af5f430fb37ad02bf0922475","event_at":"2026-07-28T03:07:41.544000Z","event_type":"price_change","frame_hash":"970fbcbce439c142ac4b2f693a4a1f13096d2aa4f84a47cb911bcf0677b9331e","frame_index":0,"kind":"data","monotonic_ns":310049102500500,"payload":{"event_type":"price_change","market":"0x779291bef19b6709f61e9764a954aafe9ffae488d50ae674aabdcb4f248006d5","price_changes":[{"asset_id":"14965588658799411272385430903075831224615961675357217884735713260981483529984","best_ask":"0.5","best_bid":"0.49","hash":"f0463692b9a2e405309270cec26904d1dac1a508","price":"0.43","side":"BUY","size":"110.25"},{"asset_id":"8761897749749422724209054078244794145777693856614463256546737399611489089783","best_ask":"0.51","best_bid":"0.5","hash":"3a9c0b1c734f451f3b2a272f9d10685ba4a0ec6f","price":"0.57","side":"SELL","size":"110.25"}],"timestamp":"1785208061544"},"payload_hash":"860334c63e80797e2235d650377884b68dc7f19c6defa769dbd96522e26cf557","raw_frame":"{\"market\":\"0x779291bef19b6709f61e9764a954aafe9ffae488d50ae674aabdcb4f248006d5\", \"price_changes\":[{\"asset_id\":\"14965588658799411272385430903075831224615961675357217884735713260981483529984\", \"price\":\"0.43\", \"size\":\"110.25\", \"side\":\"BUY\", \"hash\":\"f0463692b9a2e405309270cec26904d1dac1a508\", \"best_bid\":\"0.49\", \"best_ask\":\"0.5\"}, {\"asset_id\":\"8761897749749422724209054078244794145777693856614463256546737399611489089783\", \"price\":\"0.57\", \"size\":\"110.25\", \"side\":\"SELL\", \"hash\":\"3a9c0b1c734f451f3b2a272f9d10685ba4a0ec6f\", \"best_bid\":\"0.5\", \"best_ask\":\"0.51\"}], \"timestamp\":\"1785208061544\", \"event_type\":\"price_change\"}","received_at":"2026-07-28T03:07:46.070353Z","schema_version":"clob-market-ws.price_change.v1","sequence":null,"server_hash":null,"server_timestamp":"1785208061544","session_id":"3e519d9098404c15b234d96025eb1a2b","source":"clob_market_ws"},"received_at":"2026-07-28T03:07:46.070353Z","record_id":"49812cc314b115b08b87004def5de59ddc55686c56788f21bb698b0305fea0e6","schema_fingerprint":"4aa3821a28b0b7c2400bc59aba4bcc0a76e971dadd19610d3ad38c768e124dc7","schema_version":"edge-lab-recorder.raw.v1","sequence":null,"source":"clob_market_ws"}
{"event_at":"2026-07-28T03:07:41.545000Z","event_fingerprint":"81b16b9aa7fbf8cde369c2948e970aa72df8fdb6f37df81c06df1618ae74d949","payload":{"connection_id":"a6b55582af5f430fb37ad02bf0922475","event_at":"2026-07-28T03:07:41.545000Z","event_type":"price_change","frame_hash":"f3eef1335b96ca898385d6983a0cf47edd0c4604a77ea42edcd66f41bf06e389","frame_index":0,"kind":"data","monotonic_ns":310049106305375,"payload":{"event_type":"price_change","market":"0x779291bef19b6709f61e9764a954aafe9ffae488d50ae674aabdcb4f248006d5","price_changes":[{"asset_id":"14965588658799411272385430903075831224615961675357217884735713260981483529984","best_ask":"0.5","best_bid":"0.49","hash":"da0b610d74a588cfab58667a0bc31a607f559c66","price":"0.4","side":"BUY","size":"259.99"},{"asset_id":"8761897749749422724209054078244794145777693856614463256546737399611489089783","best_ask":"0.51","best_bid":"0.5","hash":"6da6c29ece737b2f95a3fcb21a3b0b6431c05d57","price":"0.6","side":"SELL","size":"259.99"}],"timestamp":"1785208061545"},"payload_hash":"2b0445b8439b72db24525c12ba8b2397535475c7ffc11ee80e0c1c72423360e9","raw_frame":"{\"market\":\"0x779291bef19b6709f61e9764a954aafe9ffae488d50ae674aabdcb4f248006d5\", \"price_changes\":[{\"asset_id\":\"14965588658799411272385430903075831224615961675357217884735713260981483529984\", \"price\":\"0.4\", \"size\":\"259.99\", \"side\":\"BUY\", \"hash\":\"da0b610d74a588cfab58667a0bc31a607f559c66\", \"best_bid\":\"0.49\", \"best_ask\":\"0.5\"}, {\"asset_id\":\"8761897749749422724209054078244794145777693856614463256546737399611489089783\", \"price\":\"0.6\", \"size\":\"259.99\", \"side\":\"SELL\", \"hash\":\"6da6c29ece737b2f95a3fcb21a3b0b6431c05d57\", \"best_bid\":\"0.5\", \"best_ask\":\"0.51\"}], \"timestamp\":\"1785208061545\", \"event_type\":\"price_change\"}","received_at":"2026-07-28T03:07:46.074157Z","schema_version":"clob-market-ws.price_change.v1","sequence":null,"server_hash":null,"server_timestamp":"1785208061545","session_id":"3e519d9098404c15b234d96025eb1a2b","source":"clob_market_ws"},"received_at":"2026-07-28T03:07:46.074157Z","record_id":"cd393cd6fc96a20d812a0aad0ebb0c9f608170285c1994776b2b3730b5725883","schema_fingerprint":"4aa3821a28b0b7c2400bc59aba4bcc0a76e971dadd19610d3ad38c768e124dc7","schema_version":"edge-lab-recorder.raw.v1","sequence":null,"source":"clob_market_ws"}
{"event_at":"2026-07-28T03:07:41.546000Z","event_fingerprint":"37389198c4498a35eeb48a4f8af081d2fab55481c8d38e9a774e7463db8ac886","payload":{"connection_id":"a6b55582af5f430fb37ad02bf0922475","event_at":"2026-07-28T03:07:41.546000Z","event_type":"price_change","frame_hash":"961214800b06c5af1be9f69dce1166231dc078447bb3a0067ad952afd65d8fe9","frame_index":0,"kind":"data","monotonic_ns":310049110651750,"payload":{"event_type":"price_change","market":"0x779291bef19b6709f61e9764a954aafe9ffae488d50ae674aabdcb4f248006d5","price_changes":[{"asset_id":"8761897749749422724209054078244794145777693856614463256546737399611489089783","best_ask":"0.51","best_bid":"0.5","hash":"4bc296faf5206f57af30750d1f1e909ecfdb9356","price":"0.45","side":"BUY","size":"241.1"},{"asset_id":"14965588658799411272385430903075831224615961675357217884735713260981483529984","best_ask":"0.5","best_bid":"0.49","hash":"7b161674f5cc823c60cab4284c3c9bff54e2edd0","price":"0.55","side":"SELL","size":"241.1"}],"timestamp":"1785208061546"},"payload_hash":"7cd69439c250304b72876dd50983794b8ef80a4350ac90e2a4d5f05949cdd881","raw_frame":"{\"market\":\"0x779291bef19b6709f61e9764a954aafe9ffae488d50ae674aabdcb4f248006d5\", \"price_changes\":[{\"asset_id\":\"8761897749749422724209054078244794145777693856614463256546737399611489089783\", \"price\":\"0.45\", \"size\":\"241.1\", \"side\":\"BUY\", \"hash\":\"4bc296faf5206f57af30750d1f1e909ecfdb9356\", \"best_bid\":\"0.5\", \"best_ask\":\"0.51\"}, {\"asset_id\":\"14965588658799411272385430903075831224615961675357217884735713260981483529984\", \"price\":\"0.55\", \"size\":\"241.1\", \"side\":\"SELL\", \"hash\":\"7b161674f5cc823c60cab4284c3c9bff54e2edd0\", \"best_bid\":\"0.49\", \"best_ask\":\"0.5\"}], \"timestamp\":\"1785208061546\", \"event_type\":\"price_change\"}","received_at":"2026-07-28T03:07:46.078503Z","schema_version":"clob-market-ws.price_change.v1","sequence":null,"server_hash":null,"server_timestamp":"1785208061546","session_id":"3e519d9098404c15b234d96025eb1a2b","source":"clob_market_ws"},"received_at":"2026-07-28T03:07:46.078503Z","record_id":"4fcfeb0c10d2268dbe90417a8764886cc0a57f81be39fb21bbd7221a99019f70","schema_fingerprint":"4aa3821a28b0b7c2400bc59aba4bcc0a76e971dadd19610d3ad38c768e124dc7","schema_version":"edge-lab-recorder.raw.v1","sequence":null,"source":"clob_market_ws"}
